
#######################################################################
# +-----------------------------------------------------------------+ #
# |                            BO4 object                           | #
# +-----------------------------------------------------------------+ #
#######################################################################

Author: NLBlackEagle

Description: No description given

SettingsMode: WriteDisable


#######################################################################
# +-----------------------------------------------------------------+ #
# |                          Main settings                          | #
# +-----------------------------------------------------------------+ #
#######################################################################

Frequency: 0

SpawnHeight: highestBlock

UseCenterForHighestBlock: true

##############################
# Height Limits for the BO4. #
##############################

MinHeight: 0

MaxHeight: 255

InheritBO3: 

InheritBO3Rotation: NORTH

OverrideChildSettings: true

OverrideParentHeight: false

CanOverride: true

BranchFrequency: 0

BranchFrequencyGroup: 

MustBeBelowOther: false

MustBeInside: 

CannotBeInside: 

ReplacesBO3: L4-M-CrossC0R0, L4-M-CrossC0R1, L4-M-CrossC0R2, L4-M-CrossC0R3, L4-M-CrossC1R0, L4-M-CrossC1R1, L4-M-CrossC1R2, L4-M-CrossC1R3, L4-M-CrossC2R0, L4-M-CrossC2R1, L4-M-CrossC2R2, L4-M-CrossC2R3, L4-M-CrossC3R0, L4-M-CrossC3R1, L4-M-CrossC3R2, L4-M-CrossC3R3, L4-M-Straigth-START_01-C0R0, L4-M-Straigth-START_01-C0R1, L4-M-Straigth-START_01-C1R0, L4-M-Straigth-START_01-C1R1, L4-M-Straigth-START_01-C2R0, L4-M-Straigth-START_01-C2R1, L4-M-Straigth-START_01-C3R0, L4-M-Straigth-START_01-C3R1, L4-M-Straigth-3CC0R0, L4-M-Straigth-3CC0R1, L4-M-Straigth-3CC0R2, L4-M-Straigth-3CC1R0, L4-M-Straigth-3CC1R1, L4-M-Straigth-3CC1R2, L4-M-Straigth-3CC2R0, L4-M-Straigth-3CC2R1, L4-M-Straigth-3CC2R2, L4-M-Straigth-3CC3R0, L4-M-Straigth-3CC3R1, L4-M-Straigth-3CC3R2, L4-M-Cross, skyscraper_2x2_01, skyscraper_2x2_02, skyscraper_2x2_03, skyscraper_2x2_04, skyscraper_2x2_05, skyscraper_3x3_01, skyscraper_3x3_02, skyscraper_3x3_03, L3-M-Straigth-2CC0R0, L3-M-Straigth-2CC0R1, L3-M-Straigth-2CC1R0, L3-M-Straigth-2CC1R1, L3-M-Straigth-2CC2R0, L3-M-Straigth-2CC2R1, L3-M-Straigth-2CC3R0, L3-M-Straigth-2CC3R1, L3-M-Straigth-3CC0R0, L3-M-Straigth-3CC0R1, L3-M-Straigth-3CC0R2, L3-M-Straigth-3CC1R0, L3-M-Straigth-3CC1R1, L3-M-Straigth-3CC1R2, L3-M-Straigth-3CC2R0, L3-M-Straigth-3CC2R1, L3-M-Straigth-3CC2R2, L3-M-Straigth-3CC3R0, L3-M-Straigth-3CC3R1, L3-M-Straigth-3CC3R2L4-M-CrossC0R0, L4-M-CrossC0R1, L4-M-CrossC0R2, L4-M-CrossC0R3, L4-M-CrossC1R0, L4-M-CrossC1R1, L4-M-CrossC1R2, L4-M-CrossC1R3, L4-M-CrossC2R0, L4-M-CrossC2R1, L4-M-CrossC2R2, L4-M-CrossC2R3, L4-M-CrossC3R0, L4-M-CrossC3R1, L4-M-CrossC3R2, L4-M-CrossC3R3, L4-M-Straigth-START_01-C0R0, L4-M-Straigth-START_01-C0R1, L4-M-Straigth-START_01-C1R0, L4-M-Straigth-START_01-C1R1, L4-M-Straigth-START_01-C2R0, L4-M-Straigth-START_01-C2R1, L4-M-Straigth-START_01-C3R0, L4-M-Straigth-START_01-C3R1, L4-M-Straigth-3CC0R0, L4-M-Straigth-3CC0R1, L4-M-Straigth-3CC0R2, L4-M-Straigth-3CC1R0, L4-M-Straigth-3CC1R1, L4-M-Straigth-3CC1R2, L4-M-Straigth-3CC2R0, L4-M-Straigth-3CC2R1, L4-M-Straigth-3CC2R2, L4-M-Straigth-3CC3R0, L4-M-Straigth-3CC3R1, L4-M-Straigth-3CC3R2, L4-M-Cross, skyscraper_2x2_01, skyscraper_2x2_02, skyscraper_2x2_03, skyscraper_2x2_04, skyscraper_2x2_05, skyscraper_3x3_01, skyscraper_3x3_02, skyscraper_3x3_03

MustBeInsideWorldBorders: false

CanSpawnOnWater: true

SpawnOnWaterOnly: false

SpawnUnderWater: false

SpawnAtWaterLevel: false

HeightOffset: 0

RemoveAir: false

ReplaceAbove: 

ReplaceBelow: 

ReplaceWithBiomeBlocks: true

ReplaceWithSurfaceBlock: GRASS

ReplaceWithGroundBlock: DIRT

ReplaceWithStoneBlock: STONE

SmoothRadius: 0

SmoothHeightOffset: 0

SmoothStartTop: false

SmoothStartWood: false

SmoothingSurfaceBlock: 

SmoothingGroundBlock: 

BO3Group: 

IsSpawnPoint: false

DoReplaceBlocks: true


#######################################################################
# +-----------------------------------------------------------------+ #
# |                              Blocks                             | #
# +-----------------------------------------------------------------+ #
#######################################################################

Block(-8,0,-7,CONCRETE:7)
Block(-8,0,-6,CONCRETE:7)
Block(-8,0,-5,CONCRETE:7)
Block(-8,0,-4,CONCRETE:7)
Block(-8,0,-3,CONCRETE:7)
Block(-8,0,-2,CONCRETE:7)
Block(-8,0,-1,CONCRETE:7)
Block(-8,0,0,CONCRETE:7)
Block(-8,0,1,CONCRETE:7)
Block(-8,0,2,CONCRETE:7)
Block(-8,0,3,CONCRETE:7)
Block(-8,0,4,CONCRETE:7)
Block(-8,0,5,CONCRETE:7)
Block(-8,0,6,CONCRETE:7)
Block(-8,0,7,CONCRETE:7)
Block(-8,0,8,CONCRETE:7)
Block(-8,1,-7,CONCRETE:7)
Block(-8,1,-6,CONCRETE:7)
Block(-8,1,-5,CONCRETE:7)
Block(-8,1,-4,CONCRETE:7)
Block(-8,1,-3,CONCRETE:7)
Block(-8,1,-2,STATIONARY_WATER:0)
Block(-8,1,-1,STATIONARY_WATER:0)
Block(-8,1,0,STATIONARY_WATER:0)
Block(-8,1,1,STATIONARY_WATER:0)
Block(-8,1,2,CONCRETE:7)
Block(-8,1,3,CONCRETE:7)
Block(-8,1,4,CONCRETE:7)
Block(-8,1,5,CONCRETE:7)
Block(-8,1,6,CONCRETE:7)
Block(-8,1,8,CONCRETE:7)
Block(-8,2,-7,CONCRETE:7)
Block(-8,2,-6,CONCRETE:7)
Block(-8,2,-5,CONCRETE:7)
Block(-8,2,-4,CONCRETE:7)
Block(-8,2,-3,SMOOTH_STAIRS:3)
Block(-8,2,2,SMOOTH_STAIRS:2)
Block(-8,2,3,CONCRETE:7)
Block(-8,2,4,CONCRETE:7)
Block(-8,2,5,CONCRETE:7)
Block(-8,2,6,CONCRETE:7)
Block(-8,2,7,IRON_TRAPDOOR:8)
Block(-8,2,8,CONCRETE:7)
Block(-8,3,-5,CONCRETE:7)
Block(-8,3,-4,CONCRETE:7)
Block(-8,3,4,CONCRETE:7)
Block(-8,3,5,CONCRETE:7)
Block(-8,3,8,CONCRETE:7)
Block(-8,4,-5,CONCRETE:7)
Block(-8,4,-4,CONCRETE:7)
Block(-8,4,4,CONCRETE:7)
Block(-8,4,5,CONCRETE:7)
Block(-8,4,8,CONCRETE:7)
Block(-8,5,-7,CONCRETE:14)
Block(-8,5,-6,CONCRETE:11)
Block(-8,5,-5,CONCRETE:7)
Block(-8,5,-4,CONCRETE:7)
Block(-8,5,4,CONCRETE:7)
Block(-8,5,5,CONCRETE:7)
Block(-8,5,8,CONCRETE:7)
Block(-8,6,-7,IRON_FENCE:0)
Block(-8,6,-5,CONCRETE:7)
Block(-8,6,-4,CONCRETE:7)
Block(-8,6,4,CONCRETE:7)
Block(-8,6,5,CONCRETE:7)
Block(-8,6,8,CONCRETE:7)
Block(-8,7,-7,CONCRETE:7)
Block(-8,7,-6,CONCRETE:7)
Block(-8,7,-5,CONCRETE:7)
Block(-8,7,-4,CONCRETE:7)
Block(-8,7,-3,CONCRETE:7)
Block(-8,7,-2,CONCRETE:7)
Block(-8,7,-1,CONCRETE:7)
Block(-8,7,0,CONCRETE:7)
Block(-8,7,1,CONCRETE:7)
Block(-8,7,2,CONCRETE:7)
Block(-8,7,3,CONCRETE:7)
Block(-8,7,4,CONCRETE:7)
Block(-8,7,5,CONCRETE:7)
Block(-8,7,6,CONCRETE:7)
Block(-8,7,7,CONCRETE:7)
Block(-8,7,8,CONCRETE:7)
Block(-8,8,-7,CONCRETE:7)
Block(-8,8,-5,IRON_TRAPDOOR:11)
Block(-8,8,-4,CONCRETE:7)
Block(-8,8,-3,CONCRETE:7)
Block(-8,8,-2,CONCRETE:7)
Block(-8,8,-1,CONCRETE:7)
Block(-8,8,0,CONCRETE:7)
Block(-8,8,1,CONCRETE:7)
Block(-8,8,2,CONCRETE:7)
Block(-8,8,3,CONCRETE:7)
Block(-8,8,4,CONCRETE:7)
Block(-8,8,5,CONCRETE:7)
Block(-8,8,6,CONCRETE:7)
Block(-8,8,7,CONCRETE:7)
Block(-8,8,8,CONCRETE:7)
Block(-8,9,-7,CONCRETE:7)
Block(-8,9,-4,CONCRETE:7)
Block(-8,9,-3,CONCRETE:7)
Block(-8,9,-2,CONCRETE:7)
Block(-8,9,-1,CONCRETE:7)
Block(-8,9,0,CONCRETE:7)
Block(-8,9,1,CONCRETE:7)
Block(-8,9,2,CONCRETE:7)
Block(-8,9,3,CONCRETE:7)
Block(-8,9,4,CONCRETE:7)
Block(-8,9,5,CONCRETE:7)
Block(-8,9,6,CONCRETE:7)
Block(-8,9,7,CONCRETE:7)
Block(-8,9,8,CONCRETE:7)
Block(-8,10,-7,CONCRETE:7)
Block(-8,10,-4,CONCRETE:7)
Block(-8,10,-3,CONCRETE:7)
Block(-8,10,-2,CONCRETE:7)
Block(-8,10,-1,CONCRETE:7)
Block(-8,10,0,CONCRETE:7)
Block(-8,10,1,CONCRETE:7)
Block(-8,10,2,CONCRETE:7)
Block(-8,10,3,CONCRETE:7)
Block(-8,10,4,CONCRETE:7)
Block(-8,10,5,CONCRETE:7)
Block(-8,10,6,CONCRETE:7)
Block(-8,10,7,CONCRETE:7)
Block(-8,10,8,CONCRETE:7)
Block(-8,11,-7,CONCRETE:7)
Block(-8,11,-6,CONCRETE:7)
Block(-8,11,-5,CONCRETE:7)
Block(-8,11,-4,CONCRETE:7)
Block(-8,11,-3,DIRT:2)
Block(-8,11,-2,DIRT:2)
Block(-8,11,-1,DIRT:2)
Block(-8,11,0,DIRT:2)
Block(-8,11,1,STATIONARY_WATER:0)
Block(-8,11,2,STATIONARY_WATER:0)
Block(-8,11,3,STATIONARY_WATER:0)
Block(-8,11,4,DIRT:2)
Block(-8,11,5,DIRT:2)
Block(-8,11,6,DIRT:2)
Block(-8,11,7,CONCRETE:7)
Block(-8,11,8,CONCRETE:7)
Block(-8,12,-5,CAULDRON:3)
Block(-8,12,-4,CONCRETE:8)
Block(-8,12,-3,DOUBLE_PLANT:2)
Block(-8,12,-1,LONG_GRASS:1)
Block(-8,12,0,LONG_GRASS:1)
Block(-8,12,4,LONG_GRASS:1)
Block(-8,12,5,DOUBLE_PLANT:2)
Block(-8,12,7,CONCRETE:8)
Block(-8,12,8,CONCRETE:7)
Block(-8,13,-5,TRIPWIRE_HOOK:2)
Block(-8,13,-4,CONCRETE:8)
Block(-8,13,-3,DOUBLE_PLANT:10)
Block(-8,13,5,DOUBLE_PLANT:10)
Block(-8,13,7,CONCRETE:8)
Block(-8,13,8,CONCRETE:7)
Block(-8,14,-4,CONCRETE:8)
Block(-8,14,7,CONCRETE:8)
Block(-8,14,8,CONCRETE:7)
Block(-8,15,-7,STEP:9)
Block(-8,15,-6,STEP:9)
Block(-8,15,-5,IRON_TRAPDOOR:11)
Block(-8,15,-4,CONCRETE:8)
Block(-8,15,7,CONCRETE:8)
Block(-8,15,8,CONCRETE:7)
Block(-8,16,-7,CONCRETE:7)
Block(-8,16,-6,CONCRETE:7)
Block(-8,16,-5,CONCRETE:7)
Block(-8,16,-4,CONCRETE:7)
Block(-8,16,-3,CONCRETE:7)
Block(-8,16,-2,CONCRETE:7)
Block(-8,16,-1,CONCRETE:7)
Block(-8,16,0,CONCRETE:7)
Block(-8,16,1,CONCRETE:7)
Block(-8,16,2,CONCRETE:7)
Block(-8,16,3,CONCRETE:7)
Block(-8,16,4,CONCRETE:7)
Block(-8,16,5,CONCRETE:7)
Block(-8,16,6,CONCRETE:7)
Block(-8,16,7,CONCRETE:7)
Block(-8,16,8,CONCRETE:7)
Block(-8,17,-7,CONCRETE:7)
Block(-8,17,-6,CONCRETE:7)
Block(-8,17,-5,CONCRETE:7)
Block(-8,17,-4,CONCRETE:7)
Block(-8,17,-3,CONCRETE:7)
Block(-8,17,-2,CONCRETE:7)
Block(-8,17,-1,CONCRETE:7)
Block(-8,17,0,CONCRETE:7)
Block(-8,17,1,CONCRETE:7)
Block(-8,17,2,CONCRETE:7)
Block(-8,17,3,CONCRETE:7)
Block(-8,17,4,CONCRETE:7)
Block(-8,17,5,CONCRETE:7)
Block(-8,17,6,CONCRETE:7)
Block(-8,17,7,CONCRETE:7)
Block(-8,17,8,CONCRETE:7)
Block(-8,18,-7,DARK_OAK_STAIRS:0)
Block(-8,18,-6,DARK_OAK_STAIRS:0)
Block(-8,18,-5,DARK_OAK_STAIRS:3)
Block(-8,18,-4,DARK_OAK_STAIRS:0)
Block(-8,18,-3,DARK_OAK_STAIRS:0)
Block(-8,18,-2,DARK_OAK_STAIRS:0)
Block(-8,18,-1,DARK_OAK_STAIRS:3)
Block(-8,18,0,DARK_OAK_STAIRS:0)
Block(-8,18,1,DARK_OAK_STAIRS:0)
Block(-8,18,2,DARK_OAK_STAIRS:2)
Block(-8,18,6,CONCRETE:7)
Block(-8,18,7,CONCRETE:8)
Block(-8,19,6,CONCRETE:7)
Block(-8,19,7,CONCRETE:8)
Block(-8,20,6,CONCRETE:7)
Block(-8,20,7,CONCRETE:8)
Block(-8,21,6,CONCRETE:7)
Block(-8,21,7,CONCRETE:8)
Block(-8,22,6,CONCRETE:7)
Block(-8,22,7,CONCRETE:8)
Block(-8,23,6,CONCRETE:7)
Block(-8,23,7,CONCRETE:8)
Block(-8,24,6,CONCRETE:7)
Block(-8,24,7,CONCRETE:8)
Block(-8,25,6,CONCRETE:7)
Block(-8,25,7,CONCRETE:8)
Block(-8,26,-7,CONCRETE:7)
Block(-8,26,-6,CONCRETE:7)
Block(-8,26,-5,CONCRETE:7)
Block(-8,26,-4,CONCRETE:7)
Block(-8,26,-3,CONCRETE:7)
Block(-8,26,-2,CONCRETE:7)
Block(-8,26,-1,CONCRETE:7)
Block(-8,26,0,CONCRETE:7)
Block(-8,26,1,CONCRETE:7)
Block(-8,26,2,CONCRETE:7)
Block(-8,26,3,CONCRETE:7)
Block(-8,26,4,CONCRETE:7)
Block(-8,26,5,CONCRETE:7)
Block(-8,26,6,CONCRETE:7)
Block(-8,26,7,CONCRETE:8)
Block(-8,27,-4,TRAP_DOOR:15)
Block(-8,27,6,CONCRETE:7)
Block(-8,27,7,CONCRETE:8)
Block(-8,28,-4,TRAP_DOOR:15)
Block(-8,28,6,CONCRETE:7)
Block(-8,28,7,CONCRETE:8)
Block(-8,29,-4,TRAP_DOOR:15)
Block(-8,29,6,CONCRETE:7)
Block(-8,29,7,CONCRETE:8)
Block(-8,30,6,CONCRETE:7)
Block(-8,30,7,CONCRETE:8)
Block(-8,31,6,CONCRETE:7)
Block(-8,31,7,CONCRETE:8)
Block(-8,32,6,CONCRETE:7)
Block(-8,32,7,CONCRETE:8)
Block(-8,33,6,CONCRETE:7)
Block(-8,33,7,CONCRETE:8)
Block(-8,34,6,CONCRETE:7)
Block(-8,34,7,CONCRETE:8)
Block(-8,35,6,CONCRETE:7)
Block(-8,35,7,CONCRETE:8)
Block(-8,36,-7,CONCRETE:7)
Block(-8,36,-6,CONCRETE:7)
Block(-8,36,-5,CONCRETE:7)
Block(-8,36,-4,CONCRETE:7)
Block(-8,36,-3,CONCRETE:7)
Block(-8,36,-2,CONCRETE:7)
Block(-8,36,-1,CONCRETE:7)
Block(-8,36,0,CONCRETE:7)
Block(-8,36,1,CONCRETE:7)
Block(-8,36,2,CONCRETE:7)
Block(-8,36,3,CONCRETE:7)
Block(-8,36,4,CONCRETE:7)
Block(-8,36,5,CONCRETE:7)
Block(-8,36,6,CONCRETE:7)
Block(-8,36,7,CONCRETE:8)
Block(-8,37,-7,CONCRETE:7)
Block(-8,37,-6,CONCRETE:7)
Block(-8,37,-5,CONCRETE:7)
Block(-8,37,-4,CONCRETE:7)
Block(-8,37,-3,CONCRETE:7)
Block(-8,37,-2,CONCRETE:7)
Block(-8,37,-1,CONCRETE:7)
Block(-8,37,0,CONCRETE:7)
Block(-8,37,1,CONCRETE:7)
Block(-8,37,2,CONCRETE:7)
Block(-8,37,3,CONCRETE:7)
Block(-8,37,4,CONCRETE:7)
Block(-8,37,5,CONCRETE:7)
Block(-8,37,6,CONCRETE:7)
Block(-8,37,7,CONCRETE:8)
Block(-8,38,6,CONCRETE:7)
Block(-8,38,7,CONCRETE:8)
Block(-8,39,6,CONCRETE:7)
Block(-8,39,7,CONCRETE:8)
Block(-8,40,6,CONCRETE:7)
Block(-8,40,7,CONCRETE:8)
Block(-8,41,6,CONCRETE:7)
Block(-8,41,7,CONCRETE:8)
Block(-8,42,-7,STAINED_GLASS:15)
Block(-8,42,-6,CONCRETE:7)
Block(-8,42,-5,STAINED_GLASS:15)
Block(-8,42,-4,STAINED_GLASS:15)
Block(-8,42,-3,STAINED_GLASS:15)
Block(-8,42,-2,STAINED_GLASS:15)
Block(-8,42,-1,CONCRETE:7)
Block(-8,42,0,CONCRETE:7)
Block(-8,42,1,CONCRETE:7)
Block(-8,42,2,CONCRETE:7)
Block(-8,42,3,CONCRETE:7)
Block(-8,42,4,CONCRETE:7)
Block(-8,42,5,CONCRETE:7)
Block(-8,42,6,CONCRETE:7)
Block(-8,42,7,CONCRETE:8)
Block(-8,43,-6,STAINED_GLASS:15)
Block(-8,43,-5,PRISMARINE:2)
Block(-8,43,-4,STAINED_GLASS:15)
Block(-8,43,-1,STAINED_GLASS:15)
Block(-8,43,2,WALL_SIGN:4,NBT/skyscraper_2x2_03/316-signC16R16.nbt)
Block(-8,43,4,QUARTZ_STAIRS:5)
Block(-8,43,5,WALL_SIGN:4,NBT/skyscraper_2x2_03/317-signC16R16.nbt)
Block(-8,43,7,CONCRETE:8)
Block(-8,44,-6,STAINED_GLASS:15)
Block(-8,44,-5,STATIONARY_WATER:9)
Block(-8,44,-4,STAINED_GLASS:15)
Block(-8,44,-1,STAINED_GLASS:15)
Block(-8,44,4,IRON_TRAPDOOR:0)
Block(-8,44,7,CONCRETE:8)
Block(-8,45,-6,STAINED_GLASS:15)
Block(-8,45,-5,STATIONARY_WATER:9)
Block(-8,45,-4,STAINED_GLASS:15)
Block(-8,45,-1,STAINED_GLASS:15)
Block(-8,45,7,CONCRETE:8)
Block(-8,46,-6,STAINED_GLASS:15)
Block(-8,46,-5,STATIONARY_WATER:9)
Block(-8,46,-4,STAINED_GLASS:15)
Block(-8,46,-3,STAINED_GLASS:15)
Block(-8,46,-2,STAINED_GLASS:15)
Block(-8,46,-1,STAINED_GLASS:15)
Block(-8,46,0,STAINED_GLASS:15)
Block(-8,46,1,STAINED_GLASS:15)
Block(-8,46,2,STAINED_GLASS:15)
Block(-8,46,3,STAINED_GLASS:15)
Block(-8,46,4,STAINED_GLASS:15)
Block(-8,46,5,STAINED_GLASS:15)
Block(-8,46,6,STAINED_GLASS:15)
Block(-8,46,7,CONCRETE:8)
Block(-8,47,-6,STAINED_GLASS:15)
Block(-8,47,-5,STATIONARY_WATER:1)
Block(-8,47,-4,STAINED_GLASS:15)
Block(-8,47,-2,WALL_SIGN:5,NBT/skyscraper_2x2_03/318-signC16R16.nbt)
Block(-8,47,-1,QUARTZ_STAIRS:4)
Block(-8,47,7,CONCRETE:8)
Block(-8,48,-6,STAINED_GLASS:15)
Block(-8,48,-5,PRISMARINE:2)
Block(-8,48,-4,STAINED_GLASS:15)
Block(-8,48,-1,IRON_TRAPDOOR:3)
Block(-8,48,0,WALL_BANNER:3,NBT/skyscraper_2x2_03/319-bannerC16R16.nbt)
Block(-8,48,7,CONCRETE:8)
Block(-8,49,-6,CONCRETE:7)
Block(-8,49,-5,CONCRETE:7)
Block(-8,49,-4,CONCRETE:8)
Block(-8,49,-3,CONCRETE:8)
Block(-8,49,-2,CONCRETE:8)
Block(-8,49,-1,CONCRETE:7)
Block(-8,49,0,STAINED_GLASS:15)
Block(-8,49,1,STAINED_GLASS:15)
Block(-8,49,2,STAINED_GLASS:15)
Block(-8,49,3,STAINED_GLASS:15)
Block(-8,49,4,STAINED_GLASS:15)
Block(-8,49,5,STAINED_GLASS:15)
Block(-8,49,6,STAINED_GLASS:15)
Block(-8,49,7,CONCRETE:8)
Block(-8,50,-6,CONCRETE:7)
Block(-8,50,-5,STAINED_GLASS_PANE:15)
Block(-8,50,-3,STAINED_GLASS_PANE:7)
Block(-8,50,-2,STAINED_GLASS_PANE:15)
Block(-8,50,-1,CONCRETE:7)
Block(-8,50,7,CONCRETE:8)
Block(-8,51,-6,CONCRETE:7)
Block(-8,51,-5,STAINED_GLASS_PANE:15)
Block(-8,51,-3,STAINED_GLASS_PANE:7)
Block(-8,51,-2,STAINED_GLASS_PANE:15)
Block(-8,51,-1,CONCRETE:7)
Block(-8,51,7,CONCRETE:8)
Block(-8,52,-6,CONCRETE:7)
Block(-8,52,-5,STAINED_GLASS_PANE:15)
Block(-8,52,-3,STAINED_GLASS_PANE:7)
Block(-8,52,-2,STAINED_GLASS_PANE:15)
Block(-8,52,-1,CONCRETE:7)
Block(-8,52,7,CONCRETE:8)
Block(-8,53,-6,CONCRETE:7)
Block(-8,53,-5,STAINED_GLASS_PANE:15)
Block(-8,53,-4,STAINED_GLASS_PANE:15)
Block(-8,53,-3,STAINED_GLASS_PANE:15)
Block(-8,53,-2,STAINED_GLASS_PANE:15)
Block(-8,53,-1,CONCRETE:7)
Block(-8,53,6,CONCRETE:7)
Block(-8,53,7,CONCRETE:8)
Block(-8,54,-7,CONCRETE:8)
Block(-8,54,-6,CONCRETE:8)
Block(-8,54,-5,CONCRETE:8)
Block(-8,54,-4,CONCRETE:8)
Block(-8,54,-3,CONCRETE:8)
Block(-8,54,-2,CONCRETE:8)
Block(-8,54,-1,CONCRETE:8)
Block(-8,54,0,CONCRETE:8)
Block(-8,54,1,CONCRETE:8)
Block(-8,54,2,CONCRETE:8)
Block(-8,54,3,CONCRETE:8)
Block(-8,54,4,CONCRETE:8)
Block(-8,54,5,CONCRETE:8)
Block(-8,54,6,CONCRETE:8)
Block(-8,54,7,CONCRETE:8)
Block(-8,55,-7,CONCRETE:8)
Block(-8,55,-6,CONCRETE:8)
Block(-8,55,-5,CONCRETE:8)
Block(-8,55,-4,CONCRETE:8)
Block(-8,55,-3,CONCRETE:8)
Block(-8,55,-2,CONCRETE:8)
Block(-8,55,-1,CONCRETE:8)
Block(-8,55,0,CONCRETE:8)
Block(-8,55,1,CONCRETE:8)
Block(-8,55,2,CONCRETE:8)
Block(-8,55,3,CONCRETE:8)
Block(-8,55,4,CONCRETE:8)
Block(-8,55,5,CONCRETE:8)
Block(-8,55,6,CONCRETE:8)
Block(-8,55,7,CONCRETE:8)
Block(-8,56,-7,CONCRETE:8)
Block(-8,56,-6,CONCRETE:8)
Block(-8,56,-5,CONCRETE:8)
Block(-8,56,-4,CONCRETE:8)
Block(-8,56,-3,CONCRETE:8)
Block(-8,56,-2,CONCRETE:8)
Block(-8,56,-1,CONCRETE:8)
Block(-8,56,0,CONCRETE:8)
Block(-8,56,1,CONCRETE:8)
Block(-8,56,2,CONCRETE:8)
Block(-8,56,3,CONCRETE:8)
Block(-8,56,4,CONCRETE:8)
Block(-8,56,5,CONCRETE:8)
Block(-8,56,6,CONCRETE:8)
Block(-8,56,7,CONCRETE:8)
Block(-8,57,-7,CONCRETE:8)
Block(-8,57,-6,CONCRETE:8)
Block(-8,57,-5,CONCRETE:8)
Block(-8,57,-4,CONCRETE:8)
Block(-8,57,-3,CONCRETE:8)
Block(-8,57,-2,CONCRETE:8)
Block(-8,57,-1,CONCRETE:8)
Block(-8,57,0,CONCRETE:8)
Block(-8,57,1,CONCRETE:8)
Block(-8,57,2,CONCRETE:8)
Block(-8,57,3,CONCRETE:8)
Block(-8,57,4,CONCRETE:8)
Block(-8,57,5,CONCRETE:8)
Block(-8,57,6,CONCRETE:8)
Block(-8,57,7,CONCRETE:8)
Block(-8,65,-5,CONCRETE:8)
Block(-8,65,-4,CONCRETE:8)
Block(-8,65,-3,CONCRETE:8)
Block(-8,66,-7,CONCRETE:7)
Block(-8,66,-6,STAINED_GLASS:15)
Block(-8,66,-5,CONCRETE:7)
Block(-8,66,-4,STAINED_GLASS:15)
Block(-8,66,-3,CONCRETE:8)
Block(-8,67,-7,WALL_SIGN:5,NBT/skyscraper_2x2_03/320-signC16R16.nbt)
Block(-8,67,-5,CONCRETE:8)
Block(-8,67,-3,CONCRETE:8)
Block(-8,68,-5,CONCRETE:8)
Block(-8,68,-4,CONCRETE:8)
Block(-8,68,-3,CONCRETE:8)
Block(-8,68,1,CONCRETE:7)
Block(-8,68,2,CONCRETE:7)
Block(-8,68,3,CONCRETE:7)
Block(-8,68,4,CONCRETE:7)
Block(-8,68,5,CONCRETE:7)
Block(-8,68,6,CONCRETE:7)
Block(-8,69,-7,CONCRETE:7)
Block(-8,69,-6,CONCRETE:7)
Block(-8,69,1,CONCRETE:7)
Block(-8,69,2,CONCRETE:7)
Block(-8,69,3,CONCRETE:7)
Block(-8,69,6,CONCRETE:7)
Block(-8,70,-7,CONCRETE:7)
Block(-8,70,-6,CONCRETE:7)
Block(-8,70,-5,CONCRETE:7)
Block(-8,70,-4,CONCRETE:7)
Block(-8,70,-3,CONCRETE:7)
Block(-8,70,-2,CONCRETE:7)
Block(-8,70,-1,CONCRETE:7)
Block(-8,70,0,CONCRETE:7)
Block(-8,70,1,CONCRETE:7)
Block(-8,70,2,CONCRETE:7)
Block(-8,70,3,CONCRETE:7)
Block(-8,70,6,CONCRETE:7)
Block(-8,71,-4,QUARTZ_STAIRS:7)
Block(-8,71,-3,STANDING_BANNER:4,NBT/skyscraper_2x2_03/321-bannerC16R16.nbt)
Block(-8,71,-2,STANDING_BANNER:4,NBT/skyscraper_2x2_03/322-bannerC16R16.nbt)
Block(-8,71,-1,STANDING_BANNER:5,NBT/skyscraper_2x2_03/323-bannerC16R16.nbt)
Block(-8,71,0,QUARTZ_STAIRS:6)
Block(-8,71,3,STAINED_GLASS_PANE:15)
Block(-8,71,6,CONCRETE:7)
Block(-8,72,-5,WALL_BANNER:2,NBT/skyscraper_2x2_03/324-bannerC16R16.nbt)
Block(-8,72,-4,IRON_TRAPDOOR:0)
Block(-8,72,-3,IRON_TRAPDOOR:0)
Block(-8,72,-2,IRON_TRAPDOOR:0)
Block(-8,72,-1,IRON_TRAPDOOR:0)
Block(-8,72,0,IRON_TRAPDOOR:3)
Block(-8,72,6,CONCRETE:7)
Block(-8,73,-6,CONCRETE:7)
Block(-8,73,-5,CONCRETE:7)
Block(-8,73,-4,CONCRETE:7)
Block(-8,73,-3,CONCRETE:7)
Block(-8,73,-2,CONCRETE:7)
Block(-8,73,-1,CONCRETE:7)
Block(-8,73,0,CONCRETE:7)
Block(-8,73,1,CONCRETE:7)
Block(-8,73,2,CONCRETE:7)
Block(-8,73,3,CONCRETE:7)
Block(-8,73,4,CONCRETE:7)
Block(-8,73,5,CONCRETE:7)
Block(-8,73,6,CONCRETE:7)
Block(-8,74,-6,STAINED_GLASS_PANE:15)
Block(-8,74,-5,CARPET:0)
Block(-8,74,-4,CARPET:0)
Block(-8,74,-3,STAINED_GLASS_PANE:15)
Block(-8,74,1,STAINED_GLASS_PANE:15)
Block(-8,74,2,STAINED_GLASS_PANE:15)
Block(-8,74,3,WALL_SIGN:5,NBT/skyscraper_2x2_03/325-signC16R16.nbt)
Block(-8,74,4,STAINED_GLASS:15)
Block(-8,75,-3,STAINED_GLASS_PANE:15)
Block(-8,75,1,CARPET:0)
Block(-8,75,2,CARPET:0)
Block(-8,75,4,STAINED_GLASS:15)
Block(-8,76,-3,STAINED_GLASS_PANE:15)
Block(-8,76,4,STAINED_GLASS:15)
Block(-8,77,-7,CONCRETE:7)
Block(-8,77,-6,CONCRETE:7)
Block(-8,77,-5,CONCRETE:7)
Block(-8,77,-4,CONCRETE:7)
Block(-8,77,-3,CONCRETE:7)
Block(-8,77,-2,CONCRETE:7)
Block(-8,77,-1,CONCRETE:7)
Block(-8,77,0,CONCRETE:7)
Block(-8,77,1,CONCRETE:7)
Block(-8,77,2,CONCRETE:7)
Block(-8,77,3,CONCRETE:7)
Block(-8,77,4,CONCRETE:7)
Block(-8,77,5,CONCRETE:7)
Block(-8,77,6,CONCRETE:7)
Block(-8,78,-5,TRAP_DOOR:7)
Block(-8,78,-4,DARK_OAK_STAIRS:1)
Block(-8,78,-3,DARK_OAK_STAIRS:7)
Block(-8,78,-2,CARPET:0)
Block(-8,78,-1,CARPET:0)
Block(-8,78,0,CARPET:0)
Block(-8,78,1,CARPET:0)
Block(-8,78,2,CARPET:0)
Block(-8,78,3,CARPET:0)
Block(-8,78,4,TRAP_DOOR:12)
Block(-8,78,5,DIRT:2)
Block(-8,78,6,CONCRETE:7)
Block(-8,79,-4,TRAP_DOOR:7)
Block(-8,79,-3,DARK_OAK_STAIRS:1)
Block(-8,79,-2,DARK_OAK_STAIRS:7)
Block(-8,79,5,FLOWER_POT:0,NBT/skyscraper_2x2_03/326-flower_potC16R16.nbt)
Block(-8,79,6,CONCRETE:7)
Block(-8,80,-3,TRAP_DOOR:7)
Block(-8,80,-2,DARK_OAK_STAIRS:1)
Block(-8,80,-1,DARK_OAK_STAIRS:7)
Block(-8,80,5,LEAVES:4)
Block(-8,80,6,CONCRETE:7)
Block(-8,81,-2,TRAP_DOOR:7)
Block(-8,81,-1,DARK_OAK_STAIRS:1)
Block(-8,81,0,DARK_OAK_STAIRS:7)
Block(-8,81,3,CONCRETE:7)
Block(-8,81,4,CONCRETE:7)
Block(-8,81,5,CONCRETE:7)
Block(-8,81,6,CONCRETE:7)
Block(-8,82,-1,TRAP_DOOR:7)
Block(-8,82,0,DARK_OAK_STAIRS:1)
Block(-8,82,1,CONCRETE:7)
Block(-8,82,2,CONCRETE:7)
Block(-8,82,3,CONCRETE:7)
Block(-8,83,0,TRAP_DOOR:7)
Block(-8,83,1,TRAP_DOOR:7)
Block(-8,83,2,TRAP_DOOR:7)
Block(-8,83,3,CONCRETE:7)
Block(-8,84,3,CONCRETE:7)
Block(-8,85,3,CONCRETE:7)
Block(-8,86,3,CONCRETE:7)
Block(-8,87,3,CONCRETE:7)
Block(-8,88,3,CONCRETE:7)
Block(-8,89,3,CONCRETE:7)
Block(-8,90,3,CONCRETE:7)
Block(-8,91,3,CONCRETE:7)
Block(-8,92,3,CONCRETE:7)
Block(-8,93,3,CONCRETE:7)
Block(-8,94,-7,CONCRETE:7)
Block(-8,94,-6,CONCRETE:7)
Block(-8,94,-5,CONCRETE:7)
Block(-8,94,-4,CONCRETE:7)
Block(-8,94,-3,CONCRETE:7)
Block(-8,94,-2,CONCRETE:7)
Block(-8,94,-1,CONCRETE:7)
Block(-8,94,0,CONCRETE:7)
Block(-8,94,1,CONCRETE:7)
Block(-8,94,2,CONCRETE:7)
Block(-8,94,3,CONCRETE:7)
Block(-8,95,-7,CONCRETE:7)
Block(-8,95,-6,CONCRETE:7)
Block(-8,95,-5,CONCRETE:7)
Block(-8,95,-4,CONCRETE:7)
Block(-8,95,-3,CONCRETE:7)
Block(-8,95,-2,CONCRETE:7)
Block(-8,95,-1,CONCRETE:7)
Block(-8,95,0,CONCRETE:7)
Block(-8,95,1,CONCRETE:7)
Block(-8,95,2,CONCRETE:7)
Block(-8,95,3,CONCRETE:7)
Block(-8,96,-7,STATIONARY_LAVA:0)
Block(-8,96,-6,STATIONARY_LAVA:0)
Block(-8,96,-5,STATIONARY_LAVA:0)
Block(-8,96,-4,STATIONARY_LAVA:0)
Block(-8,96,-3,STATIONARY_LAVA:0)
Block(-8,96,-2,STATIONARY_LAVA:0)
Block(-8,96,-1,STATIONARY_LAVA:0)
Block(-8,96,0,STATIONARY_LAVA:0)
Block(-8,96,1,STATIONARY_LAVA:0)
Block(-8,96,2,CONCRETE:7)
Block(-8,96,3,CONCRETE:7)
Block(-8,97,-6,STATIONARY_LAVA:8)
Block(-8,97,-5,STATIONARY_LAVA:8)
Block(-8,97,-4,STATIONARY_LAVA:8)
Block(-8,97,-3,STATIONARY_LAVA:8)
Block(-8,97,-2,STATIONARY_LAVA:8)
Block(-8,97,-1,STATIONARY_LAVA:8)
Block(-8,97,0,STATIONARY_LAVA:8)
Block(-8,97,1,STATIONARY_LAVA:8)
Block(-8,97,2,CONCRETE:7)
Block(-8,97,3,CONCRETE:7)
Block(-8,98,-7,CONCRETE:7)
Block(-8,98,-6,STATIONARY_LAVA:8)
Block(-8,98,-5,STATIONARY_LAVA:8)
Block(-8,98,-4,STATIONARY_LAVA:8)
Block(-8,98,-3,STATIONARY_LAVA:8)
Block(-8,98,-2,STATIONARY_LAVA:8)
Block(-8,98,-1,STATIONARY_LAVA:8)
Block(-8,98,0,STATIONARY_LAVA:8)
Block(-8,98,1,STATIONARY_LAVA:8)
Block(-8,98,2,CONCRETE:7)
Block(-8,98,3,CONCRETE:7)
Block(-8,99,-7,CONCRETE:7)
Block(-8,99,-6,STATIONARY_LAVA:8)
Block(-8,99,-5,STATIONARY_LAVA:8)
Block(-8,99,-4,STATIONARY_LAVA:8)
Block(-8,99,-3,STATIONARY_LAVA:8)
Block(-8,99,-2,STATIONARY_LAVA:8)
Block(-8,99,-1,STATIONARY_LAVA:8)
Block(-8,99,0,STATIONARY_LAVA:8)
Block(-8,99,1,STATIONARY_LAVA:8)
Block(-8,99,2,CONCRETE:7)
Block(-8,99,3,CONCRETE:7)
Block(-8,100,-7,STATIONARY_LAVA:8)
Block(-8,100,-6,STATIONARY_LAVA:8)
Block(-8,100,-5,STATIONARY_LAVA:8)
Block(-8,100,-4,STATIONARY_LAVA:8)
Block(-8,100,-3,STATIONARY_LAVA:8)
Block(-8,100,-2,STATIONARY_LAVA:8)
Block(-8,100,-1,STATIONARY_LAVA:8)
Block(-8,100,0,STATIONARY_LAVA:8)
Block(-8,100,1,STATIONARY_LAVA:8)
Block(-8,100,2,CONCRETE:7)
Block(-8,100,3,CONCRETE:7)
Block(-8,101,-7,STATIONARY_LAVA:8)
Block(-8,101,-6,STATIONARY_LAVA:8)
Block(-8,101,-5,STATIONARY_LAVA:8)
Block(-8,101,-4,STATIONARY_LAVA:8)
Block(-8,101,-3,STATIONARY_LAVA:8)
Block(-8,101,-2,STATIONARY_LAVA:8)
Block(-8,101,-1,STATIONARY_LAVA:8)
Block(-8,101,0,STATIONARY_LAVA:8)
Block(-8,101,1,STATIONARY_LAVA:8)
Block(-8,101,2,CONCRETE:7)
Block(-8,101,3,CONCRETE:7)
Block(-8,102,-7,STATIONARY_LAVA:8)
Block(-8,102,-6,STATIONARY_LAVA:8)
Block(-8,102,-5,STATIONARY_LAVA:8)
Block(-8,102,-4,STATIONARY_LAVA:8)
Block(-8,102,-3,STATIONARY_LAVA:8)
Block(-8,102,-2,STATIONARY_LAVA:8)
Block(-8,102,-1,STATIONARY_LAVA:8)
Block(-8,102,0,STATIONARY_LAVA:8)
Block(-8,102,1,STATIONARY_LAVA:8)
Block(-8,102,2,CONCRETE:7)
Block(-8,102,3,CONCRETE:7)
Block(-8,103,-7,STATIONARY_LAVA:0)
Block(-8,103,-6,STATIONARY_LAVA:0)
Block(-8,103,-5,STATIONARY_LAVA:0)
Block(-8,103,-4,STATIONARY_LAVA:0)
Block(-8,103,-3,STATIONARY_LAVA:0)
Block(-8,103,-2,STATIONARY_LAVA:0)
Block(-8,103,-1,STATIONARY_LAVA:0)
Block(-8,103,0,STATIONARY_LAVA:0)
Block(-8,103,1,STATIONARY_LAVA:0)
Block(-8,103,2,CONCRETE:7)
Block(-8,103,3,CONCRETE:7)
Block(-8,104,-7,CONCRETE:7)
Block(-8,104,-6,CONCRETE:7)
Block(-8,104,-5,CONCRETE:7)
Block(-8,104,-4,CONCRETE:7)
Block(-8,104,-3,CONCRETE:7)
Block(-8,104,-2,CONCRETE:7)
Block(-8,104,-1,CONCRETE:7)
Block(-8,104,0,CONCRETE:7)
Block(-8,104,1,CONCRETE:7)
Block(-8,104,2,CONCRETE:7)
Block(-8,104,3,CONCRETE:7)
Block(-8,105,-7,STATIONARY_WATER:0)
Block(-8,105,-6,STATIONARY_WATER:0)
Block(-8,105,-5,STATIONARY_WATER:0)
Block(-8,105,-4,CONCRETE:7)
Block(-8,105,-3,CONCRETE:7)
Block(-8,105,-2,CONCRETE:7)
Block(-8,105,-1,CONCRETE:7)
Block(-8,105,0,CONCRETE:7)
Block(-8,105,1,CONCRETE:7)
Block(-8,105,2,CONCRETE:7)
Block(-8,105,3,CONCRETE:7)
Block(-8,106,-4,STAINED_GLASS:15)
Block(-8,106,-3,CONCRETE:7)
Block(-8,106,-2,CONCRETE:7)
Block(-8,106,-1,CONCRETE:7)
Block(-8,106,0,CONCRETE:7)
Block(-8,106,1,CONCRETE:7)
Block(-8,106,2,CONCRETE:7)
Block(-8,106,3,CONCRETE:7)
Block(-8,107,-4,STAINED_GLASS:15)
Block(-8,107,-3,CONCRETE:7)
Block(-8,107,-2,CONCRETE:7)
Block(-8,107,-1,CONCRETE:7)
Block(-8,107,0,CONCRETE:7)
Block(-8,107,1,CONCRETE:7)
Block(-8,107,2,STAINED_GLASS:15)
Block(-8,107,3,CONCRETE:7)
Block(-8,108,-4,STAINED_GLASS:15)
Block(-8,108,-3,CONCRETE:7)
Block(-8,108,-2,CONCRETE:7)
Block(-8,108,-1,CONCRETE:7)
Block(-8,108,0,CONCRETE:7)
Block(-8,108,3,CONCRETE:7)
Block(-8,109,-4,STAINED_GLASS:15)
Block(-8,109,-3,CONCRETE:7)
Block(-8,109,-2,CONCRETE:7)
Block(-8,109,-1,CONCRETE:7)
Block(-8,109,0,CONCRETE:7)
Block(-8,109,3,CONCRETE:7)
Block(-8,110,-4,STAINED_GLASS:15)
Block(-8,110,-3,CONCRETE:7)
Block(-8,110,-2,CONCRETE:7)
Block(-8,110,-1,CONCRETE:7)
Block(-8,110,0,CONCRETE:7)
Block(-8,110,3,CONCRETE:7)
Block(-8,111,-4,STAINED_GLASS:15)
Block(-8,111,-3,CONCRETE:7)
Block(-8,111,-2,CONCRETE:7)
Block(-8,111,-1,CONCRETE:7)
Block(-8,111,0,CONCRETE:7)
Block(-8,111,3,CONCRETE:7)
Block(-8,112,-7,CONCRETE:7)
Block(-8,112,-6,STAINED_GLASS:15)
Block(-8,112,-5,CONCRETE:7)
Block(-8,112,-4,STAINED_GLASS:15)
Block(-8,112,-3,CONCRETE:7)
Block(-8,112,-2,STAINED_GLASS:15)
Block(-8,112,-1,CONCRETE:7)
Block(-8,112,0,STAINED_GLASS:15)
Block(-8,112,1,CONCRETE:7)
Block(-8,112,2,STAINED_GLASS:15)
Block(-8,112,3,CONCRETE:7)
Block(-8,113,-7,CONCRETE:7)
Block(-8,113,-5,CONCRETE:7)
Block(-8,113,-3,CONCRETE:7)
Block(-8,113,-1,CONCRETE:7)
Block(-8,113,1,CONCRETE:7)
Block(-8,113,3,CONCRETE:7)
Block(-7,0,-7,CONCRETE:7)
Block(-7,0,-6,CONCRETE:7)
Block(-7,0,-5,CONCRETE:7)
Block(-7,0,-4,CONCRETE:7)
Block(-7,0,-3,CONCRETE:7)
Block(-7,0,-2,CONCRETE:7)
Block(-7,0,-1,CONCRETE:7)
Block(-7,0,0,CONCRETE:7)
Block(-7,0,1,CONCRETE:7)
Block(-7,0,2,CONCRETE:7)
Block(-7,0,3,CONCRETE:7)
Block(-7,0,4,CONCRETE:7)
Block(-7,0,5,CONCRETE:7)
Block(-7,0,6,CONCRETE:7)
Block(-7,0,7,CONCRETE:7)
Block(-7,0,8,CONCRETE:7)
Block(-7,1,-7,CONCRETE:7)
Block(-7,1,-6,CONCRETE:7)
Block(-7,1,-5,CONCRETE:7)
Block(-7,1,-4,CONCRETE:7)
Block(-7,1,-3,CONCRETE:7)
Block(-7,1,-2,STATIONARY_WATER:0)
Block(-7,1,-1,STATIONARY_WATER:0)
Block(-7,1,0,STATIONARY_WATER:0)
Block(-7,1,1,STATIONARY_WATER:0)
Block(-7,1,2,CONCRETE:7)
Block(-7,1,3,CONCRETE:7)
Block(-7,1,4,CONCRETE:7)
Block(-7,1,5,SMOOTH_STAIRS:3)
Block(-7,1,8,CONCRETE:7)
Block(-7,2,-7,CONCRETE:7)
Block(-7,2,-6,CONCRETE:7)
Block(-7,2,-5,CONCRETE:7)
Block(-7,2,-4,CONCRETE:7)
Block(-7,2,-3,SMOOTH_STAIRS:3)
Block(-7,2,2,SMOOTH_STAIRS:2)
Block(-7,2,3,CONCRETE:7)
Block(-7,2,4,SMOOTH_STAIRS:3)
Block(-7,2,7,IRON_TRAPDOOR:8)
Block(-7,2,8,CONCRETE:7)
Block(-7,3,-5,CONCRETE:7)
Block(-7,3,-4,CONCRETE:7)
Block(-7,3,8,CONCRETE:7)
Block(-7,4,-5,CONCRETE:7)
Block(-7,4,-4,CONCRETE:7)
Block(-7,4,8,CONCRETE:7)
Block(-7,5,-7,CONCRETE:14)
Block(-7,5,-6,CONCRETE:11)
Block(-7,5,-5,CONCRETE:7)
Block(-7,5,-4,CONCRETE:7)
Block(-7,5,8,CONCRETE:7)
Block(-7,6,-5,CONCRETE:7)
Block(-7,6,-4,CONCRETE:7)
Block(-7,6,8,CONCRETE:7)
Block(-7,7,-7,CONCRETE:7)
Block(-7,7,-6,CONCRETE:7)
Block(-7,7,-5,CONCRETE:7)
Block(-7,7,-4,CONCRETE:7)
Block(-7,7,-3,CONCRETE:7)
Block(-7,7,-2,CONCRETE:7)
Block(-7,7,-1,CONCRETE:7)
Block(-7,7,0,CONCRETE:7)
Block(-7,7,1,CONCRETE:7)
Block(-7,7,2,CONCRETE:7)
Block(-7,7,3,CONCRETE:7)
Block(-7,7,4,CONCRETE:7)
Block(-7,7,5,CONCRETE:7)
Block(-7,7,6,CONCRETE:7)
Block(-7,7,7,CONCRETE:7)
Block(-7,7,8,CONCRETE:7)
Block(-7,8,-5,IRON_TRAPDOOR:8)
Block(-7,8,-4,CONCRETE:7)
Block(-7,8,-3,CONCRETE:7)
Block(-7,8,-2,CONCRETE:7)
Block(-7,8,-1,CONCRETE:7)
Block(-7,8,0,CONCRETE:7)
Block(-7,8,1,CONCRETE:7)
Block(-7,8,2,CONCRETE:7)
Block(-7,8,3,CONCRETE:7)
Block(-7,8,4,CONCRETE:7)
Block(-7,8,5,CONCRETE:7)
Block(-7,8,6,CONCRETE:7)
Block(-7,8,7,CONCRETE:7)
Block(-7,8,8,CONCRETE:7)
#RandomBlock(-7,9,-5,TRAPPED_CHEST:5,../../../../../Chests/Loot/ModernCityJunk_1.nbt,65,CHEST:2,../../../../../Chests/Loot/ModernCityJunk_1.nbt,20,CHEST:2,../../../../../Chests/Loot/ModernCityJunk_2.nbt,15,CHEST:2,../../../../../Chests/Loot/ModernCityJunk_3.nbt,15,CHEST:2,../../../../../Chests/Loot/ModernCityJunk_4.nbt,15,CHEST:2,../../../../../Chests/Loot/ModernCityJunk_5.nbt,15,CHEST:2,../../../../../Chests/Loot/ModernCityCommon_1.nbt,5,CHEST:2,../../../../../Chests/Loot/ModernCityCommon_2.nbt,5,CHEST:2,../../../../../Chests/Loot/ModernCityCommon_3.nbt,5,CHEST:2,../../../../../Chests/Loot/ModernCityCommon_4.nbt,5,CHEST:2,../../../../../Chests/Loot/ModernCityCommon_5.nbt,5,CHEST:2,../../../../../Chests/Loot/ModernCityGood_1.nbt,3,CHEST:2,../../../../../Chests/Loot/ModernCityGood_2.nbt,3,CHEST:2,../../../../../Chests/Loot/ModernCityGood_3.nbt,3,CHEST:2,../../../../../Chests/Loot/ModernCityGood_4.nbt,3,CHEST:2,../../../../../Chests/Loot/ModernCityGood_5.nbt,3,CHEST:2,../../../../../Chests/Loot/ModernCityEpic_1.nbt,1,CHEST:2,../../../../../Chests/Loot/ModernCityEpic_2.nbt,1,CHEST:2,../../../../../Chests/Loot/ModernCityEpic_3.nbt,1,CHEST:2,../../../../../Chests/Loot/ModernCityEpic_4.nbt,1,CHEST:2,../../../../../Chests/Loot/ModernCityEpic_5.nbt,1,CHEST:2,../../../../../Chests/Loot/Common1.nbt,25,CHEST:2,../../../../../Chests/Loot/Common2.nbt,25,CHEST:2,../../../../../Chests/Loot/Common3.nbt,25,CHEST:2,../../../../../Chests/Loot/Common4.nbt,25,CHEST:2,../../../../../Chests/Loot/Common5.nbt,25,CHEST:2,../../../../../Chests/Loot/Common6.nbt,25,CHEST:2,../../../../../Chests/Loot/Common7.nbt,25,CHEST:2,../../../../../Chests/Loot/Common8.nbt,25,CHEST:2,../../../../../Chests/Loot/Common9.nbt,25,CHEST:2,../../../../../Chests/Loot/Common10.nbt,25,CHEST:2,../../../../../Chests/Loot/Common11.nbt,25,CHEST:2,../../../../../Chests/Loot/Common12.nbt,25,CHEST:2,../../../../../Chests/Loot/Common13.nbt,25,CHEST:2,../../../../../Chests/Loot/Common14.nbt,25,CHEST:2,../../../../../Chests/Loot/Common15.nbt,25,CHEST:2,../../../../../Chests/Loot/Rare1.nbt,10,CHEST:2,../../../../../Chests/Loot/Rare2.nbt,10,CHEST:5,../../../../../Chests/Loot/Rare3.nbt,10,CHEST:2,../../../../../Chests/Loot/Rare4.nbt,10,CHEST:2,../../../../../Chests/Loot/Rare5.nbt,10,CHEST:2,../../../../../Chests/Loot/Rare6.nbt,10,CHEST:2,../../../../../Chests/Loot/Rare7.nbt,10,CHEST:2,../../../../../Chests/Loot/Rare8.nbt,10,CHEST:2,../../../../../Chests/Loot/Rare9.nbt,10,CHEST:2,../../../../../Chests/Loot/Rare10.nbt,10,CHEST:2,../../../../../Chests/Loot/Rare11.nbt,10,CHEST:2,../../../../../Chests/Loot/Rare12.nbt,10,CHEST:2,../../../../../Chests/Loot/Rare13.nbt,10,CHEST:2,../../../../../Chests/Loot/Rare14.nbt,10,CHEST:2,../../../../../Chests/Loot/Rare15.nbt,10,CHEST:2,../../../../../Chests/Loot/Epic1.nbt,1,CHEST:2,../../../../../Chests/Loot/Epic2.nbt,1,CHEST:2,../../../../../Chests/Loot/Epic3.nbt,1,CHEST:2,../../../../../Chests/Loot/Epic4.nbt,1,CHEST:2,../../../../../Chests/Loot/Epic5.nbt,1,CHEST:2,../../../../../Chests/Loot/Epic6.nbt,1,CHEST:2,../../../../../Chests/Loot/Epic7.nbt,1,CHEST:2,../../../../../Chests/Loot/Epic8.nbt,1,CHEST:2,../../../../../Chests/Loot/Epic9.nbt,1,CHEST:2,../../../../../Chests/Loot/Epic10.nbt,1,CHEST:2,../../../../../Chests/Loot/Epic11.nbt,1,CHEST:2,../../../../../Chests/Loot/Epic12.nbt,1,CHEST:2,../../../../../Chests/Loot/Epic13.nbt,1,CHEST:2,../../../../../Chests/Loot/Epic14.nbt,1,CHEST:2,../../../../../Chests/Loot/Epic15.nbt,1,CHEST:2,../../../../../Chests/Loot/ModernCityJunk_1.nbt,100)
Block(-7,9,-4,CONCRETE:7)
Block(-7,9,-3,CONCRETE:7)
Block(-7,9,-2,CONCRETE:7)
Block(-7,9,-1,CONCRETE:7)
Block(-7,9,0,CONCRETE:7)
Block(-7,9,1,CONCRETE:7)
Block(-7,9,2,CONCRETE:7)
Block(-7,9,3,CONCRETE:7)
Block(-7,9,4,CONCRETE:7)
Block(-7,9,5,CONCRETE:7)
Block(-7,9,6,CONCRETE:7)
Block(-7,9,7,CONCRETE:7)
Block(-7,9,8,CONCRETE:7)
Block(-7,10,-4,CONCRETE:7)
Block(-7,10,-3,CONCRETE:7)
Block(-7,10,-2,CONCRETE:7)
Block(-7,10,-1,CONCRETE:7)
Block(-7,10,0,CONCRETE:7)
Block(-7,10,1,CONCRETE:7)
Block(-7,10,2,CONCRETE:7)
Block(-7,10,3,CONCRETE:7)
Block(-7,10,4,CONCRETE:7)
Block(-7,10,5,CONCRETE:7)
Block(-7,10,6,CONCRETE:7)
Block(-7,10,7,CONCRETE:7)
Block(-7,10,8,CONCRETE:7)
Block(-7,11,-7,CONCRETE:7)
Block(-7,11,-6,CONCRETE:7)
Block(-7,11,-5,CONCRETE:7)
Block(-7,11,-4,CONCRETE:7)
Block(-7,11,-3,DIRT:2)
Block(-7,11,-2,DIRT:2)
Block(-7,11,-1,STATIONARY_WATER:0)
Block(-7,11,0,STATIONARY_WATER:0)
Block(-7,11,1,STATIONARY_WATER:0)
Block(-7,11,2,DIRT:2)
Block(-7,11,3,DIRT:2)
Block(-7,11,4,DIRT:2)
Block(-7,11,5,STATIONARY_WATER:0)
Block(-7,11,6,DIRT:2)
Block(-7,11,7,CONCRETE:7)
Block(-7,11,8,CONCRETE:7)
Block(-7,12,-5,QUARTZ_STAIRS:6)
Block(-7,12,-4,CONCRETE:8)
Block(-7,12,-3,LEAVES:4)
Block(-7,12,-2,LONG_GRASS:1)
Block(-7,12,2,LONG_GRASS:1)
Block(-7,12,3,SUGAR_CANE_BLOCK:0)
Block(-7,12,6,LONG_GRASS:1)
Block(-7,12,7,CONCRETE:8)
Block(-7,12,8,CONCRETE:7)
Block(-7,13,-4,CONCRETE:8)
Block(-7,13,3,SUGAR_CANE_BLOCK:0)
Block(-7,13,7,CONCRETE:8)
Block(-7,13,8,CONCRETE:7)
Block(-7,14,-7,TRAP_DOOR:5)
Block(-7,14,-5,WALL_BANNER:2,NBT/skyscraper_2x2_03/339-bannerC16R16.nbt)
Block(-7,14,-4,CONCRETE:8)
Block(-7,14,3,SUGAR_CANE_BLOCK:0)
Block(-7,14,7,CONCRETE:8)
Block(-7,14,8,CONCRETE:7)
Block(-7,15,-7,CONCRETE:8)
Block(-7,15,-6,CONCRETE:8)
Block(-7,15,-5,CONCRETE:8)
Block(-7,15,-4,CONCRETE:8)
Block(-7,15,7,CONCRETE:8)
Block(-7,15,8,CONCRETE:7)
Block(-7,16,-7,CONCRETE:7)
Block(-7,16,-6,CONCRETE:7)
Block(-7,16,-5,CONCRETE:7)
Block(-7,16,-4,CONCRETE:7)
Block(-7,16,-3,CONCRETE:7)
Block(-7,16,-2,CONCRETE:7)
Block(-7,16,-1,CONCRETE:7)
Block(-7,16,0,CONCRETE:7)
Block(-7,16,1,CONCRETE:7)
Block(-7,16,2,CONCRETE:7)
Block(-7,16,3,CONCRETE:7)
Block(-7,16,4,CONCRETE:7)
Block(-7,16,5,CONCRETE:7)
Block(-7,16,6,CONCRETE:7)
Block(-7,16,7,CONCRETE:7)
Block(-7,16,8,CONCRETE:7)
Block(-7,17,-7,CONCRETE:7)
Block(-7,17,-6,CONCRETE:7)
Block(-7,17,-5,CONCRETE:7)
Block(-7,17,-4,CONCRETE:7)
Block(-7,17,-3,CONCRETE:7)
Block(-7,17,-2,CONCRETE:7)
Block(-7,17,-1,CONCRETE:7)
Block(-7,17,0,CONCRETE:7)
Block(-7,17,1,CONCRETE:7)
Block(-7,17,2,CONCRETE:7)
Block(-7,17,3,CONCRETE:7)
Block(-7,17,4,CONCRETE:7)
Block(-7,17,5,CONCRETE:7)
Block(-7,17,6,CONCRETE:7)
Block(-7,17,7,CONCRETE:7)
Block(-7,17,8,CONCRETE:7)
Block(-7,18,-7,CONCRETE:8)
Block(-7,18,-6,CONCRETE:8)
Block(-7,18,-5,CONCRETE:8)
Block(-7,18,-4,CONCRETE:8)
Block(-7,18,-3,CONCRETE:8)
Block(-7,18,-2,CONCRETE:8)
Block(-7,18,-1,CONCRETE:8)
Block(-7,18,0,CONCRETE:8)
Block(-7,18,1,CONCRETE:8)
Block(-7,18,2,CONCRETE:8)
Block(-7,18,3,CONCRETE:8)
Block(-7,18,4,CONCRETE:8)
Block(-7,18,6,STAINED_GLASS:15)
Block(-7,19,-7,STANDING_BANNER:4,NBT/skyscraper_2x2_03/341-bannerC16R16.nbt)
Block(-7,19,-6,STANDING_BANNER:4,NBT/skyscraper_2x2_03/342-bannerC16R16.nbt)
Block(-7,19,-5,STANDING_BANNER:4,NBT/skyscraper_2x2_03/343-bannerC16R16.nbt)
Block(-7,19,-4,STANDING_BANNER:4,NBT/skyscraper_2x2_03/344-bannerC16R16.nbt)
Block(-7,19,-3,STANDING_BANNER:4,NBT/skyscraper_2x2_03/345-bannerC16R16.nbt)
Block(-7,19,-2,STANDING_BANNER:4,NBT/skyscraper_2x2_03/346-bannerC16R16.nbt)
Block(-7,19,-1,STANDING_BANNER:4,NBT/skyscraper_2x2_03/347-bannerC16R16.nbt)
Block(-7,19,0,STANDING_BANNER:4,NBT/skyscraper_2x2_03/348-bannerC16R16.nbt)
Block(-7,19,1,STANDING_BANNER:4,NBT/skyscraper_2x2_03/349-bannerC16R16.nbt)
Block(-7,19,2,STANDING_BANNER:4,NBT/skyscraper_2x2_03/350-bannerC16R16.nbt)
Block(-7,19,3,STANDING_BANNER:4,NBT/skyscraper_2x2_03/351-bannerC16R16.nbt)
Block(-7,19,4,CONCRETE:8)
Block(-7,19,6,STAINED_GLASS:15)
Block(-7,20,4,CONCRETE:8)
Block(-7,20,6,STAINED_GLASS:15)
Block(-7,21,-7,WOOD_STEP:5)
Block(-7,21,-6,WOOD_STEP:5)
Block(-7,21,-5,WOOD_STEP:5)
Block(-7,21,-4,WOOD_STEP:5)
Block(-7,21,-3,WOOD_STEP:5)
Block(-7,21,-2,WOOD_STEP:5)
Block(-7,21,-1,WOOD_STEP:5)
Block(-7,21,0,WOOD_STEP:5)
Block(-7,21,1,WOOD_STEP:5)
Block(-7,21,2,WOOD_STEP:5)
Block(-7,21,3,WOOD_STEP:5)
Block(-7,21,4,WOOD_STEP:5)
Block(-7,21,6,STAINED_GLASS:15)
Block(-7,22,6,STAINED_GLASS:15)
Block(-7,23,6,STAINED_GLASS:15)
Block(-7,24,6,STAINED_GLASS:15)
Block(-7,25,6,STAINED_GLASS:15)
Block(-7,26,-7,STAINED_GLASS_PANE:15)
Block(-7,26,-6,STAINED_GLASS_PANE:15)
Block(-7,26,-5,STAINED_GLASS_PANE:15)
Block(-7,26,-4,STAINED_GLASS_PANE:15)
Block(-7,26,-3,STAINED_GLASS_PANE:15)
Block(-7,26,-2,STAINED_GLASS_PANE:15)
Block(-7,26,-1,STAINED_GLASS_PANE:15)
Block(-7,26,0,STAINED_GLASS_PANE:15)
Block(-7,26,1,STAINED_GLASS_PANE:15)
Block(-7,26,2,STAINED_GLASS_PANE:15)
Block(-7,26,3,STAINED_GLASS_PANE:15)
Block(-7,26,4,STAINED_GLASS_PANE:15)
Block(-7,26,5,STAINED_GLASS_PANE:15)
Block(-7,26,6,STAINED_GLASS:15)
Block(-7,27,-7,STAINED_GLASS_PANE:15)
Block(-7,27,-6,STAINED_GLASS_PANE:15)
Block(-7,27,-5,STAINED_GLASS_PANE:15)
Block(-7,27,-4,STAINED_GLASS_PANE:15)
Block(-7,27,-3,STAINED_GLASS_PANE:15)
Block(-7,27,-2,STAINED_GLASS_PANE:15)
Block(-7,27,-1,STAINED_GLASS_PANE:15)
Block(-7,27,0,STAINED_GLASS_PANE:15)
Block(-7,27,1,STAINED_GLASS_PANE:15)
Block(-7,27,2,STAINED_GLASS_PANE:15)
Block(-7,27,3,STAINED_GLASS_PANE:15)
Block(-7,27,4,STAINED_GLASS_PANE:15)
Block(-7,27,5,STAINED_GLASS_PANE:15)
Block(-7,27,6,STAINED_GLASS:15)
Block(-7,28,6,STAINED_GLASS:15)
Block(-7,29,6,STAINED_GLASS:15)
Block(-7,30,6,STAINED_GLASS:15)
Block(-7,31,-7,STAINED_GLASS_PANE:15)
Block(-7,31,-6,STAINED_GLASS_PANE:15)
Block(-7,31,-5,STAINED_GLASS_PANE:15)
Block(-7,31,-4,STAINED_GLASS_PANE:15)
Block(-7,31,-3,STAINED_GLASS_PANE:15)
Block(-7,31,-2,STAINED_GLASS_PANE:15)
Block(-7,31,-1,STAINED_GLASS_PANE:15)
Block(-7,31,0,STAINED_GLASS_PANE:15)
Block(-7,31,1,STAINED_GLASS_PANE:15)
Block(-7,31,2,STAINED_GLASS_PANE:15)
Block(-7,31,3,STAINED_GLASS_PANE:15)
Block(-7,31,4,STAINED_GLASS_PANE:15)
Block(-7,31,5,STAINED_GLASS_PANE:15)
Block(-7,31,6,STAINED_GLASS:15)
Block(-7,32,-7,STAINED_GLASS_PANE:15)
Block(-7,32,-6,STAINED_GLASS_PANE:15)
Block(-7,32,-5,STAINED_GLASS_PANE:15)
Block(-7,32,-4,STAINED_GLASS_PANE:15)
Block(-7,32,-3,STAINED_GLASS_PANE:15)
Block(-7,32,-2,STAINED_GLASS_PANE:15)
Block(-7,32,-1,STAINED_GLASS_PANE:15)
Block(-7,32,0,STAINED_GLASS_PANE:15)
Block(-7,32,1,STAINED_GLASS_PANE:15)
Block(-7,32,2,STAINED_GLASS_PANE:15)
Block(-7,32,3,STAINED_GLASS_PANE:15)
Block(-7,32,4,STAINED_GLASS_PANE:15)
Block(-7,32,5,STAINED_GLASS_PANE:15)
Block(-7,32,6,STAINED_GLASS:15)
Block(-7,33,6,STAINED_GLASS:15)
Block(-7,34,6,STAINED_GLASS:15)
Block(-7,35,6,STAINED_GLASS:15)
Block(-7,36,6,STAINED_GLASS:15)
Block(-7,37,6,STAINED_GLASS:15)
Block(-7,38,6,STAINED_GLASS:15)
Block(-7,39,6,STAINED_GLASS:15)
Block(-7,40,6,STAINED_GLASS:15)
Block(-7,41,6,STAINED_GLASS:15)
Block(-7,42,-7,STAINED_GLASS:15)
Block(-7,42,-6,CONCRETE:7)
Block(-7,42,-5,STAINED_GLASS:15)
Block(-7,42,-4,STAINED_GLASS:15)
Block(-7,42,-3,STAINED_GLASS:15)
Block(-7,42,-2,STAINED_GLASS:15)
Block(-7,42,-1,CONCRETE:7)
Block(-7,42,0,STAINED_GLASS:15)
Block(-7,42,1,STAINED_GLASS:15)
Block(-7,42,2,STAINED_GLASS:15)
Block(-7,42,3,STAINED_GLASS:15)
Block(-7,42,4,STAINED_GLASS:15)
Block(-7,42,5,STAINED_GLASS:15)
Block(-7,42,6,CONCRETE:7)
Block(-7,43,-6,STAINED_GLASS:15)
Block(-7,43,-5,PRISMARINE:2)
Block(-7,43,-4,STAINED_GLASS:15)
Block(-7,43,-1,DARK_OAK_DOOR:3)
Block(-7,43,2,DARK_OAK_STAIRS:3)
Block(-7,43,4,STANDING_BANNER:0,NBT/skyscraper_2x2_03/354-bannerC16R16.nbt)
Block(-7,43,5,DARK_OAK_STAIRS:2)
Block(-7,43,6,CONCRETE:7)
Block(-7,44,-6,STAINED_GLASS:15)
Block(-7,44,-5,STATIONARY_WATER:8)
Block(-7,44,-4,STAINED_GLASS:15)
Block(-7,44,-1,DARK_OAK_DOOR:8)
Block(-7,44,2,TRAP_DOOR:5)
Block(-7,44,4,IRON_TRAPDOOR:3)
Block(-7,44,5,TRAP_DOOR:12)
Block(-7,44,6,CONCRETE:7)
Block(-7,45,-6,STAINED_GLASS:15)
Block(-7,45,-5,STATIONARY_WATER:8)
Block(-7,45,-4,STAINED_GLASS:15)
Block(-7,45,-1,STAINED_GLASS:15)
Block(-7,45,6,CONCRETE:7)
Block(-7,46,-6,STAINED_GLASS:15)
Block(-7,46,-5,STATIONARY_WATER:8)
Block(-7,46,-4,STAINED_GLASS:15)
Block(-7,46,-3,CONCRETE:7)
Block(-7,46,-2,CONCRETE:7)
Block(-7,46,-1,CONCRETE:7)
Block(-7,46,0,CONCRETE:7)
Block(-7,46,1,CONCRETE:7)
Block(-7,46,2,CONCRETE:7)
Block(-7,46,3,CONCRETE:7)
Block(-7,46,4,CONCRETE:7)
Block(-7,46,5,CONCRETE:7)
Block(-7,46,6,CONCRETE:7)
Block(-7,47,-6,STAINED_GLASS:15)
Block(-7,47,-5,STATIONARY_WATER:0)
Block(-7,47,-4,STAINED_GLASS:15)
Block(-7,47,3,TRAP_DOOR:6)
Block(-7,47,6,CONCRETE:7)
Block(-7,48,-6,STAINED_GLASS:15)
Block(-7,48,-5,PRISMARINE:2)
Block(-7,48,-4,STAINED_GLASS:15)
Block(-7,48,-1,WALL_BANNER:5,NBT/skyscraper_2x2_03/355-bannerC16R16.nbt)
Block(-7,48,2,TRAP_DOOR:6)
Block(-7,48,6,CONCRETE:7)
Block(-7,49,-6,CONCRETE:7)
Block(-7,49,-5,CONCRETE:7)
Block(-7,49,-4,CONCRETE:8)
Block(-7,49,-3,CONCRETE:8)
Block(-7,49,-2,CONCRETE:8)
Block(-7,49,-1,CONCRETE:7)
Block(-7,49,0,STAINED_GLASS:15)
Block(-7,49,1,CONCRETE:7)
Block(-7,49,2,CONCRETE:7)
Block(-7,49,3,CONCRETE:7)
Block(-7,49,4,CONCRETE:7)
Block(-7,49,5,CONCRETE:7)
Block(-7,49,6,CONCRETE:7)
Block(-7,50,-6,CONCRETE:7)
Block(-7,50,-5,IRON_TRAPDOOR:6)
Block(-7,50,-3,STAINED_GLASS_PANE:7)
Block(-7,50,-1,CONCRETE:7)
Block(-7,50,1,STAINED_GLASS_PANE:15)
Block(-7,50,2,STAINED_GLASS_PANE:15)
Block(-7,50,3,STAINED_GLASS_PANE:15)
Block(-7,50,4,STAINED_GLASS_PANE:15)
Block(-7,50,5,STAINED_GLASS_PANE:15)
Block(-7,50,6,CONCRETE:7)
Block(-7,51,-6,CONCRETE:7)
Block(-7,51,-3,STAINED_GLASS_PANE:7)
Block(-7,51,-1,CONCRETE:7)
Block(-7,51,6,CONCRETE:7)
Block(-7,52,-6,CONCRETE:7)
Block(-7,52,-3,STAINED_GLASS_PANE:7)
Block(-7,52,-1,CONCRETE:7)
Block(-7,52,6,CONCRETE:7)
Block(-7,53,-7,CONCRETE:7)
Block(-7,53,-6,CONCRETE:7)
Block(-7,53,-1,CONCRETE:7)
Block(-7,53,6,CONCRETE:7)
Block(-7,54,-7,CONCRETE:7)
Block(-7,54,-6,CONCRETE:7)
Block(-7,54,-1,CONCRETE:7)
Block(-7,54,0,CONCRETE:7)
Block(-7,54,1,CONCRETE:7)
Block(-7,54,2,CONCRETE:7)
Block(-7,54,3,CONCRETE:7)
Block(-7,54,4,CONCRETE:7)
Block(-7,54,5,CONCRETE:7)
Block(-7,54,6,CONCRETE:7)
Block(-7,55,-7,CONCRETE:7)
Block(-7,55,-6,CONCRETE:7)
Block(-7,56,-7,CONCRETE:7)
Block(-7,56,-6,CONCRETE:7)
Block(-7,57,-7,CONCRETE:7)
Block(-7,57,-6,CONCRETE:7)
Block(-7,58,-7,CONCRETE:7)
Block(-7,58,-6,CONCRETE:7)
Block(-7,59,-7,CONCRETE:7)
Block(-7,59,-6,CONCRETE:7)
Block(-7,60,-7,CONCRETE:7)
Block(-7,60,-6,CONCRETE:7)
Block(-7,60,-5,CONCRETE:7)
Block(-7,61,-7,CONCRETE:7)
Block(-7,61,-6,CONCRETE:7)
Block(-7,61,-5,CONCRETE:7)
Block(-7,61,-4,CONCRETE:7)
Block(-7,61,-3,CONCRETE:7)
Block(-7,61,-2,CONCRETE:7)
Block(-7,61,-1,CONCRETE:7)
Block(-7,61,0,CONCRETE:7)
Block(-7,61,1,CONCRETE:7)
Block(-7,61,2,CONCRETE:7)
Block(-7,61,3,CONCRETE:7)
Block(-7,61,4,CONCRETE:7)
Block(-7,61,5,CONCRETE:7)
Block(-7,61,6,CONCRETE:7)
Block(-7,61,7,CONCRETE:7)
Block(-7,62,-7,CONCRETE:7)
Block(-7,62,-6,CONCRETE:7)
Block(-7,62,-5,CONCRETE:7)
Block(-7,62,-4,CONCRETE:7)
Block(-7,62,-3,CONCRETE:7)
Block(-7,62,-2,CONCRETE:7)
Block(-7,62,-1,CONCRETE:7)
Block(-7,62,0,STAINED_GLASS:15)
Block(-7,62,1,CONCRETE:7)
Block(-7,62,2,STAINED_GLASS:15)
Block(-7,62,3,CONCRETE:7)
Block(-7,62,4,STAINED_GLASS:15)
Block(-7,62,5,CONCRETE:7)
Block(-7,62,6,STAINED_GLASS:15)
Block(-7,62,7,CONCRETE:7)
Block(-7,63,-7,CONCRETE:7)
Block(-7,63,-6,CONCRETE:7)
Block(-7,63,-5,CONCRETE:7)
Block(-7,63,-4,CONCRETE:7)
Block(-7,63,-3,CONCRETE:7)
Block(-7,63,-2,CONCRETE:7)
Block(-7,63,-1,CONCRETE:7)
Block(-7,63,0,STAINED_GLASS:15)
Block(-7,63,1,CONCRETE:7)
Block(-7,63,2,STAINED_GLASS:15)
Block(-7,63,3,CONCRETE:7)
Block(-7,63,4,STAINED_GLASS:15)
Block(-7,63,5,CONCRETE:7)
Block(-7,63,6,STAINED_GLASS:15)
Block(-7,63,7,CONCRETE:7)
Block(-7,64,-7,CONCRETE:7)
Block(-7,64,-6,CONCRETE:7)
Block(-7,64,-5,CONCRETE:7)
Block(-7,64,-4,CONCRETE:7)
Block(-7,64,-3,CONCRETE:7)
Block(-7,64,-2,CONCRETE:7)
Block(-7,64,-1,CONCRETE:7)
Block(-7,64,0,STAINED_GLASS:15)
Block(-7,64,1,CONCRETE:7)
Block(-7,64,2,STAINED_GLASS:15)
Block(-7,64,3,CONCRETE:7)
Block(-7,64,4,STAINED_GLASS:15)
Block(-7,64,5,CONCRETE:7)
Block(-7,64,6,STAINED_GLASS:15)
Block(-7,64,7,CONCRETE:7)
Block(-7,65,-7,CONCRETE:7)
Block(-7,65,-6,CONCRETE:7)
Block(-7,65,-5,CONCRETE:7)
Block(-7,65,-4,CONCRETE:7)
Block(-7,65,-3,CONCRETE:7)
Block(-7,65,-2,CONCRETE:7)
Block(-7,65,-1,CONCRETE:7)
Block(-7,65,0,STAINED_GLASS:15)
Block(-7,65,1,CONCRETE:7)
Block(-7,65,2,STAINED_GLASS:15)
Block(-7,65,3,CONCRETE:7)
Block(-7,65,4,STAINED_GLASS:15)
Block(-7,65,5,CONCRETE:7)
Block(-7,65,6,STAINED_GLASS:15)
Block(-7,65,7,CONCRETE:7)
Block(-7,66,-7,CONCRETE:7)
Block(-7,66,-6,CONCRETE:7)
Block(-7,66,-5,CONCRETE:7)
Block(-7,66,-4,CONCRETE:7)
Block(-7,66,-3,CONCRETE:7)
Block(-7,66,-2,CONCRETE:7)
Block(-7,66,-1,CONCRETE:7)
Block(-7,66,0,STAINED_GLASS:15)
Block(-7,66,1,CONCRETE:7)
Block(-7,66,2,STAINED_GLASS:15)
Block(-7,66,3,CONCRETE:7)
Block(-7,66,4,STAINED_GLASS:15)
Block(-7,66,5,CONCRETE:7)
Block(-7,66,6,STAINED_GLASS:15)
Block(-7,66,7,CONCRETE:7)
Block(-7,67,-7,STAINED_GLASS_PANE:15)
Block(-7,67,-6,CONCRETE:7)
Block(-7,67,-5,CONCRETE:7)
Block(-7,67,-4,CONCRETE:7)
Block(-7,67,-3,CONCRETE:7)
Block(-7,67,-2,CONCRETE:7)
Block(-7,67,-1,CONCRETE:7)
Block(-7,67,0,CONCRETE:7)
Block(-7,67,1,CONCRETE:7)
Block(-7,67,2,CONCRETE:7)
Block(-7,67,3,CONCRETE:7)
Block(-7,67,4,CONCRETE:7)
Block(-7,67,5,CONCRETE:7)
Block(-7,67,6,CONCRETE:7)
Block(-7,67,7,CONCRETE:7)
Block(-7,68,-6,CONCRETE:7)
Block(-7,68,-5,CONCRETE:8)
Block(-7,68,-4,CONCRETE:8)
Block(-7,68,-3,CONCRETE:8)
Block(-7,68,-2,STAINED_GLASS:15)
Block(-7,68,-1,CONCRETE:7)
Block(-7,68,0,CONCRETE:7)
Block(-7,68,1,CONCRETE:7)
Block(-7,68,2,CONCRETE:7)
Block(-7,68,3,CONCRETE:7)
Block(-7,68,4,CONCRETE:7)
Block(-7,68,5,CONCRETE:7)
Block(-7,68,6,STAINED_GLASS:15)
Block(-7,69,-7,CONCRETE:7)
Block(-7,69,-6,CONCRETE:7)
Block(-7,69,-5,STAINED_GLASS:15)
Block(-7,69,-4,STAINED_GLASS:15)
Block(-7,69,-3,STAINED_GLASS:15)
Block(-7,69,-2,STAINED_GLASS:15)
Block(-7,69,-1,CONCRETE:7)
Block(-7,69,0,CONCRETE:7)
Block(-7,69,1,CONCRETE:7)
Block(-7,69,2,CONCRETE:7)
Block(-7,69,3,CONCRETE:7)
Block(-7,69,6,STAINED_GLASS:15)
Block(-7,70,-7,CONCRETE:7)
Block(-7,70,-6,CONCRETE:7)
Block(-7,70,-5,CONCRETE:7)
Block(-7,70,-4,CONCRETE:7)
Block(-7,70,-3,CONCRETE:7)
Block(-7,70,-2,CONCRETE:7)
Block(-7,70,-1,CONCRETE:7)
Block(-7,70,0,CONCRETE:7)
Block(-7,70,1,CONCRETE:7)
Block(-7,70,2,CONCRETE:7)
Block(-7,70,3,CONCRETE:7)
Block(-7,70,6,STAINED_GLASS:15)
Block(-7,71,-7,DARK_OAK_STAIRS:0)
Block(-7,71,-6,STAINED_GLASS_PANE:15)
Block(-7,71,-5,STAINED_GLASS_PANE:15)
Block(-7,71,-4,STAINED_GLASS_PANE:15)
Block(-7,71,-3,STAINED_GLASS_PANE:15)
Block(-7,71,-2,STAINED_GLASS_PANE:15)
Block(-7,71,-1,STAINED_GLASS_PANE:15)
Block(-7,71,0,STAINED_GLASS_PANE:15)
Block(-7,71,1,STAINED_GLASS_PANE:15)
Block(-7,71,2,STAINED_GLASS_PANE:15)
Block(-7,71,3,STAINED_GLASS_PANE:15)
Block(-7,71,6,STAINED_GLASS:15)
Block(-7,72,6,STAINED_GLASS:15)
Block(-7,73,-6,CONCRETE:7)
Block(-7,73,-5,CONCRETE:7)
Block(-7,73,-4,CONCRETE:7)
Block(-7,73,-3,CONCRETE:7)
Block(-7,73,-2,CONCRETE:7)
Block(-7,73,-1,CONCRETE:7)
Block(-7,73,0,CONCRETE:7)
Block(-7,73,1,CONCRETE:7)
Block(-7,73,2,CONCRETE:7)
Block(-7,73,3,CONCRETE:7)
Block(-7,73,4,CONCRETE:7)
Block(-7,73,5,CONCRETE:7)
Block(-7,73,6,STAINED_GLASS:15)
Block(-7,74,-6,STAINED_GLASS_PANE:15)
Block(-7,74,-5,CARPET:0)
Block(-7,74,-4,CARPET:0)
Block(-7,74,-3,STAINED_GLASS_PANE:15)
Block(-7,74,0,WALL_SIGN:2,NBT/skyscraper_2x2_03/357-signC16R16.nbt)
Block(-7,74,1,DARK_OAK_STAIRS:0)
Block(-7,74,2,WALL_SIGN:3,NBT/skyscraper_2x2_03/358-signC16R16.nbt)
Block(-7,74,4,STAINED_GLASS:15)
Block(-7,75,-3,STAINED_GLASS_PANE:15)
Block(-7,75,4,STAINED_GLASS:15)
Block(-7,76,-3,STAINED_GLASS_PANE:15)
Block(-7,76,4,STAINED_GLASS:15)
Block(-7,77,-7,CONCRETE:7)
Block(-7,77,-6,CONCRETE:7)
Block(-7,77,-5,CONCRETE:7)
Block(-7,77,-4,CONCRETE:7)
Block(-7,77,-3,CONCRETE:7)
Block(-7,77,-2,CONCRETE:7)
Block(-7,77,-1,CONCRETE:7)
Block(-7,77,0,CONCRETE:7)
Block(-7,77,1,CONCRETE:7)
Block(-7,77,2,CONCRETE:7)
Block(-7,77,3,CONCRETE:7)
Block(-7,77,4,CONCRETE:7)
Block(-7,77,5,STAINED_GLASS:15)
Block(-7,77,6,STAINED_GLASS:15)
Block(-7,78,-4,DARK_OAK_STAIRS:2)
Block(-7,78,-3,DARK_OAK_STAIRS:7)
Block(-7,78,5,TRAP_DOOR:15)
Block(-7,78,6,STAINED_GLASS:15)
Block(-7,79,-3,DARK_OAK_STAIRS:2)
Block(-7,79,-2,DARK_OAK_STAIRS:7)
Block(-7,79,6,STAINED_GLASS:15)
Block(-7,80,-2,DARK_OAK_STAIRS:2)
Block(-7,80,-1,DARK_OAK_STAIRS:7)
Block(-7,80,6,STAINED_GLASS:15)
Block(-7,81,-1,DARK_OAK_STAIRS:2)
Block(-7,81,0,DARK_OAK_STAIRS:7)
Block(-7,81,3,CONCRETE:7)
Block(-7,81,4,STAINED_GLASS:15)
Block(-7,81,5,STAINED_GLASS:15)
Block(-7,81,6,STAINED_GLASS:15)
Block(-7,82,-7,TRAP_DOOR:5)
Block(-7,82,0,DARK_OAK_STAIRS:2)
Block(-7,82,1,CONCRETE:7)
Block(-7,82,2,CONCRETE:7)
Block(-7,82,3,STAINED_GLASS:15)
Block(-7,83,3,STAINED_GLASS:15)
Block(-7,84,3,STAINED_GLASS:15)
Block(-7,85,3,STAINED_GLASS:15)
Block(-7,86,3,STAINED_GLASS:15)
Block(-7,87,3,STAINED_GLASS:15)
Block(-7,88,3,STAINED_GLASS:15)
Block(-7,89,-7,TRAP_DOOR:13)
Block(-7,89,3,STAINED_GLASS:15)
Block(-7,90,3,STAINED_GLASS:15)
Block(-7,91,3,STAINED_GLASS:15)
Block(-7,92,3,STAINED_GLASS:15)
Block(-7,93,3,STAINED_GLASS:15)
Block(-7,94,-7,STAINED_GLASS:15)
Block(-7,94,-6,STAINED_GLASS:15)
Block(-7,94,-5,STAINED_GLASS:15)
Block(-7,94,-4,STAINED_GLASS:15)
Block(-7,94,-3,STAINED_GLASS:15)
Block(-7,94,-2,STAINED_GLASS:15)
Block(-7,94,-1,STAINED_GLASS:15)
Block(-7,94,0,STAINED_GLASS:15)
Block(-7,94,1,STAINED_GLASS:15)
Block(-7,94,2,STAINED_GLASS:15)
Block(-7,94,3,STAINED_GLASS:15)
Block(-7,95,-7,CONCRETE:7)
Block(-7,95,-6,CONCRETE:7)
Block(-7,95,-5,CONCRETE:7)
Block(-7,95,-4,CONCRETE:7)
Block(-7,95,-3,CONCRETE:7)
Block(-7,95,-2,CONCRETE:7)
Block(-7,95,-1,CONCRETE:7)
Block(-7,95,0,CONCRETE:7)
Block(-7,95,1,CONCRETE:7)
Block(-7,95,2,CONCRETE:7)
Block(-7,95,3,STAINED_GLASS:15)
Block(-7,96,-7,STATIONARY_LAVA:0)
Block(-7,96,-6,STATIONARY_LAVA:0)
Block(-7,96,-5,STATIONARY_LAVA:0)
Block(-7,96,-4,STATIONARY_LAVA:0)
Block(-7,96,-3,STATIONARY_LAVA:0)
Block(-7,96,-2,STATIONARY_LAVA:0)
Block(-7,96,-1,STATIONARY_LAVA:0)
Block(-7,96,0,STATIONARY_LAVA:0)
Block(-7,96,1,STATIONARY_LAVA:0)
Block(-7,96,2,CONCRETE:7)
Block(-7,96,3,STAINED_GLASS:15)
Block(-7,97,-7,STATIONARY_LAVA:10)
Block(-7,97,-6,OBSIDIAN:0)
Block(-7,97,-5,PISTON_BASE:4)
Block(-7,97,-4,OBSIDIAN:0)
Block(-7,97,-3,OBSIDIAN:0)
Block(-7,97,-2,OBSIDIAN:0)
Block(-7,97,-1,OBSIDIAN:0)
Block(-7,97,0,OBSIDIAN:0)
Block(-7,97,1,STATIONARY_LAVA:8)
Block(-7,97,2,CONCRETE:7)
Block(-7,97,3,STAINED_GLASS:15)
Block(-7,98,-7,STATIONARY_LAVA:10)
Block(-7,98,-6,PISTON_BASE:4)
Block(-7,98,-4,PISTON_BASE:4)
Block(-7,98,-3,OBSIDIAN:0)
Block(-7,98,-2,OBSIDIAN:0)
Block(-7,98,-1,OBSIDIAN:0)
Block(-7,98,0,OBSIDIAN:0)
Block(-7,98,1,STATIONARY_LAVA:8)
Block(-7,98,2,CONCRETE:7)
Block(-7,98,3,STAINED_GLASS:15)
Block(-7,99,-7,STATIONARY_LAVA:10)
Block(-7,99,-6,PISTON_BASE:4)
Block(-7,99,-4,PISTON_BASE:4)
Block(-7,99,-3,OBSIDIAN:0)
Block(-7,99,-2,OBSIDIAN:0)
Block(-7,99,-1,OBSIDIAN:0)
Block(-7,99,0,OBSIDIAN:0)
Block(-7,99,1,STATIONARY_LAVA:8)
Block(-7,99,2,CONCRETE:7)
Block(-7,99,3,STAINED_GLASS:15)
Block(-7,100,-7,STATIONARY_LAVA:2)
Block(-7,100,-6,OBSIDIAN:0)
Block(-7,100,-5,PISTON_BASE:4)
Block(-7,100,-4,OBSIDIAN:0)
Block(-7,100,-3,OBSIDIAN:0)
Block(-7,100,-2,OBSIDIAN:0)
Block(-7,100,-1,OBSIDIAN:0)
Block(-7,100,0,OBSIDIAN:0)
Block(-7,100,1,STATIONARY_LAVA:8)
Block(-7,100,2,CONCRETE:7)
Block(-7,100,3,STAINED_GLASS:15)
Block(-7,101,-6,OBSIDIAN:0)
Block(-7,101,-5,OBSIDIAN:0)
Block(-7,101,-4,OBSIDIAN:0)
Block(-7,101,-3,OBSIDIAN:0)
Block(-7,101,-2,OBSIDIAN:0)
Block(-7,101,-1,OBSIDIAN:0)
Block(-7,101,0,OBSIDIAN:0)
Block(-7,101,1,STATIONARY_LAVA:8)
Block(-7,101,2,CONCRETE:7)
Block(-7,101,3,STAINED_GLASS:15)
Block(-7,102,-7,OBSIDIAN:0)
Block(-7,102,-6,OBSIDIAN:0)
Block(-7,102,-5,OBSIDIAN:0)
Block(-7,102,-4,OBSIDIAN:0)
Block(-7,102,-3,OBSIDIAN:0)
Block(-7,102,-2,OBSIDIAN:0)
Block(-7,102,-1,OBSIDIAN:0)
Block(-7,102,0,OBSIDIAN:0)
Block(-7,102,1,STATIONARY_LAVA:8)
Block(-7,102,2,CONCRETE:7)
Block(-7,102,3,STAINED_GLASS:15)
Block(-7,103,-7,STATIONARY_LAVA:0)
Block(-7,103,-6,STATIONARY_LAVA:0)
Block(-7,103,-5,STATIONARY_LAVA:0)
Block(-7,103,-4,STATIONARY_LAVA:0)
Block(-7,103,-3,STATIONARY_LAVA:0)
Block(-7,103,-2,STATIONARY_LAVA:0)
Block(-7,103,-1,STATIONARY_LAVA:0)
Block(-7,103,0,STATIONARY_LAVA:0)
Block(-7,103,1,STATIONARY_LAVA:0)
Block(-7,103,2,CONCRETE:7)
Block(-7,103,3,STAINED_GLASS:15)
Block(-7,104,-7,CONCRETE:7)
Block(-7,104,-6,CONCRETE:7)
Block(-7,104,-5,CONCRETE:7)
Block(-7,104,-4,CONCRETE:7)
Block(-7,104,-3,CONCRETE:7)
Block(-7,104,-2,CONCRETE:7)
Block(-7,104,-1,CONCRETE:7)
Block(-7,104,0,CONCRETE:7)
Block(-7,104,1,CONCRETE:7)
Block(-7,104,2,CONCRETE:7)
Block(-7,104,3,STAINED_GLASS:15)
Block(-7,105,-7,STATIONARY_WATER:0)
Block(-7,105,-6,STATIONARY_WATER:0)
Block(-7,105,-5,STATIONARY_WATER:0)
Block(-7,105,-4,CONCRETE:7)
Block(-7,105,-3,CONCRETE:7)
Block(-7,105,-2,CONCRETE:7)
Block(-7,105,-1,CONCRETE:7)
Block(-7,105,0,CONCRETE:7)
Block(-7,105,1,CONCRETE:7)
Block(-7,105,2,CONCRETE:7)
Block(-7,105,3,STAINED_GLASS:15)
Block(-7,106,-4,STAINED_GLASS:15)
Block(-7,106,-3,CONCRETE:7)
Block(-7,106,-2,STAINED_GLASS:15)
Block(-7,106,-1,CONCRETE:7)
Block(-7,106,0,STAINED_GLASS:15)
Block(-7,106,1,CONCRETE:7)
Block(-7,106,2,CONCRETE:7)
Block(-7,106,3,STAINED_GLASS:15)
Block(-7,107,-4,STAINED_GLASS:15)
Block(-7,107,-3,CONCRETE:7)
Block(-7,107,-2,STAINED_GLASS:15)
Block(-7,107,-1,CONCRETE:7)
Block(-7,107,0,STAINED_GLASS:15)
Block(-7,107,1,CONCRETE:7)
Block(-7,107,2,STAINED_GLASS:15)
Block(-7,107,3,STAINED_GLASS:15)
Block(-7,108,-4,STAINED_GLASS:15)
Block(-7,108,-3,CONCRETE:7)
Block(-7,108,-2,STAINED_GLASS:15)
Block(-7,108,-1,CONCRETE:7)
Block(-7,108,0,QUARTZ_STAIRS:2)
Block(-7,108,3,STAINED_GLASS:15)
Block(-7,109,-4,STAINED_GLASS:15)
Block(-7,109,-3,CONCRETE:7)
Block(-7,109,-2,STAINED_GLASS:15)
Block(-7,109,-1,CONCRETE:7)
Block(-7,109,0,TRIPWIRE_HOOK:0)
Block(-7,109,3,STAINED_GLASS:15)
Block(-7,110,-4,STAINED_GLASS:15)
Block(-7,110,-3,CONCRETE:7)
Block(-7,110,-2,STAINED_GLASS:15)
Block(-7,110,-1,CONCRETE:7)
Block(-7,110,3,STAINED_GLASS:15)
Block(-7,111,-4,STAINED_GLASS:15)
Block(-7,111,-3,CONCRETE:7)
Block(-7,111,-2,STAINED_GLASS:15)
Block(-7,111,-1,CONCRETE:7)
Block(-7,111,3,STAINED_GLASS:15)
Block(-7,112,-7,CONCRETE:7)
Block(-7,112,-6,STAINED_GLASS:15)
Block(-7,112,-5,CONCRETE:7)
Block(-7,112,-4,STAINED_GLASS:15)
Block(-7,112,-3,CONCRETE:7)
Block(-7,112,-2,STAINED_GLASS:15)
Block(-7,112,-1,CONCRETE:7)
Block(-7,112,0,STAINED_GLASS:15)
Block(-7,112,1,CONCRETE:7)
Block(-7,112,2,STAINED_GLASS:15)
Block(-7,112,3,STAINED_GLASS:15)
Block(-7,113,-7,CONCRETE:7)
Block(-7,113,-5,CONCRETE:7)
Block(-7,113,-3,CONCRETE:7)
Block(-7,113,-1,CONCRETE:7)
Block(-7,113,1,CONCRETE:7)
Block(-6,0,-7,CONCRETE:7)
Block(-6,0,-6,CONCRETE:7)
Block(-6,0,-5,CONCRETE:7)
Block(-6,0,-4,CONCRETE:7)
Block(-6,0,-3,CONCRETE:7)
Block(-6,0,-2,CONCRETE:7)
Block(-6,0,-1,CONCRETE:7)
Block(-6,0,0,CONCRETE:7)
Block(-6,0,1,CONCRETE:7)
Block(-6,0,2,CONCRETE:7)
Block(-6,0,3,CONCRETE:7)
Block(-6,0,4,CONCRETE:7)
Block(-6,0,5,CONCRETE:7)
Block(-6,0,6,CONCRETE:7)
Block(-6,0,7,CONCRETE:7)
Block(-6,0,8,CONCRETE:7)
Block(-6,1,-7,CONCRETE:7)
Block(-6,1,-6,CONCRETE:7)
Block(-6,1,-5,CONCRETE:7)
Block(-6,1,-4,CONCRETE:7)
Block(-6,1,-3,CONCRETE:7)
Block(-6,1,-2,STATIONARY_WATER:0)
Block(-6,1,-1,STATIONARY_WATER:0)
Block(-6,1,0,STATIONARY_WATER:0)
Block(-6,1,1,STATIONARY_WATER:0)
Block(-6,1,2,CONCRETE:7)
Block(-6,1,3,CONCRETE:7)
Block(-6,1,4,CONCRETE:7)
Block(-6,1,5,CONCRETE:7)
Block(-6,1,6,CONCRETE:7)
Block(-6,1,7,CONCRETE:7)
Block(-6,1,8,CONCRETE:7)
Block(-6,2,-7,SMOOTH_STAIRS:1)
Block(-6,2,-6,SMOOTH_STAIRS:1)
Block(-6,2,-5,SMOOTH_STAIRS:1)
Block(-6,2,-4,SMOOTH_STAIRS:1)
Block(-6,2,-3,SMOOTH_STAIRS:1)
Block(-6,2,2,CONCRETE:7)
Block(-6,2,3,CONCRETE:7)
Block(-6,2,4,CONCRETE:7)
Block(-6,2,5,CONCRETE:7)
Block(-6,2,6,CONCRETE:7)
Block(-6,2,7,CONCRETE:7)
Block(-6,2,8,CONCRETE:7)
Block(-6,3,2,CONCRETE:7)
Block(-6,3,3,CONCRETE:7)
Block(-6,3,4,CONCRETE:7)
Block(-6,3,5,CONCRETE:7)
Block(-6,3,6,CONCRETE:7)
Block(-6,3,7,CONCRETE:7)
Block(-6,3,8,CONCRETE:7)
Block(-6,4,2,CONCRETE:7)
Block(-6,4,3,CONCRETE:7)
Block(-6,4,4,CONCRETE:7)
Block(-6,4,5,CONCRETE:7)
Block(-6,4,6,CONCRETE:7)
Block(-6,4,7,CONCRETE:7)
Block(-6,4,8,CONCRETE:7)
Block(-6,5,-7,CONCRETE:14)
Block(-6,5,-6,CONCRETE:11)
Block(-6,5,2,CONCRETE:7)
Block(-6,5,3,CONCRETE:7)
Block(-6,5,4,CONCRETE:7)
Block(-6,5,5,CONCRETE:7)
Block(-6,5,6,CONCRETE:7)
Block(-6,5,7,CONCRETE:7)
Block(-6,5,8,CONCRETE:7)
Block(-6,6,2,CONCRETE:7)
Block(-6,6,3,CONCRETE:7)
Block(-6,6,4,CONCRETE:7)
Block(-6,6,5,CONCRETE:7)
Block(-6,6,6,CONCRETE:7)
Block(-6,6,7,CONCRETE:7)
Block(-6,6,8,CONCRETE:7)
Block(-6,7,-7,CONCRETE:7)
Block(-6,7,-6,CONCRETE:7)
Block(-6,7,-5,CONCRETE:7)
Block(-6,7,-4,CONCRETE:7)
Block(-6,7,-3,CONCRETE:7)
Block(-6,7,-2,CONCRETE:7)
Block(-6,7,-1,CONCRETE:7)
Block(-6,7,0,CONCRETE:7)
Block(-6,7,1,CONCRETE:7)
Block(-6,7,2,CONCRETE:7)
Block(-6,7,3,CONCRETE:7)
Block(-6,7,4,CONCRETE:7)
Block(-6,7,5,CONCRETE:7)
Block(-6,7,6,CONCRETE:7)
Block(-6,7,7,CONCRETE:7)
Block(-6,7,8,CONCRETE:7)
Block(-6,8,-7,CONCRETE:7)
Block(-6,8,-5,IRON_TRAPDOOR:8)
Block(-6,8,-4,CONCRETE:7)
Block(-6,8,-3,CONCRETE:7)
Block(-6,8,-2,CONCRETE:7)
Block(-6,8,-1,CONCRETE:7)
Block(-6,8,0,CONCRETE:7)
Block(-6,8,1,CONCRETE:7)
Block(-6,8,2,CONCRETE:7)
Block(-6,8,3,CONCRETE:7)
Block(-6,8,4,CONCRETE:7)
Block(-6,8,5,CONCRETE:7)
Block(-6,8,6,CONCRETE:7)
Block(-6,8,7,CONCRETE:7)
Block(-6,8,8,CONCRETE:7)
Block(-6,9,-7,CONCRETE:7)
#RandomBlock(-6,9,-5,TRAPPED_CHEST:5,../../../../../Chests/Loot/ModernCityJunk_1.nbt,65,CHEST:2,../../../../../Chests/Loot/ModernCityJunk_1.nbt,20,CHEST:2,../../../../../Chests/Loot/ModernCityJunk_2.nbt,15,CHEST:2,../../../../../Chests/Loot/ModernCityJunk_3.nbt,15,CHEST:2,../../../../../Chests/Loot/ModernCityJunk_4.nbt,15,CHEST:2,../../../../../Chests/Loot/ModernCityJunk_5.nbt,15,CHEST:2,../../../../../Chests/Loot/ModernCityCommon_1.nbt,5,CHEST:2,../../../../../Chests/Loot/ModernCityCommon_2.nbt,5,CHEST:2,../../../../../Chests/Loot/ModernCityCommon_3.nbt,5,CHEST:2,../../../../../Chests/Loot/ModernCityCommon_4.nbt,5,CHEST:2,../../../../../Chests/Loot/ModernCityCommon_5.nbt,5,CHEST:2,../../../../../Chests/Loot/ModernCityGood_1.nbt,3,CHEST:2,../../../../../Chests/Loot/ModernCityGood_2.nbt,3,CHEST:2,../../../../../Chests/Loot/ModernCityGood_3.nbt,3,CHEST:2,../../../../../Chests/Loot/ModernCityGood_4.nbt,3,CHEST:2,../../../../../Chests/Loot/ModernCityGood_5.nbt,3,CHEST:2,../../../../../Chests/Loot/ModernCityEpic_1.nbt,1,CHEST:2,../../../../../Chests/Loot/ModernCityEpic_2.nbt,1,CHEST:2,../../../../../Chests/Loot/ModernCityEpic_3.nbt,1,CHEST:2,../../../../../Chests/Loot/ModernCityEpic_4.nbt,1,CHEST:2,../../../../../Chests/Loot/ModernCityEpic_5.nbt,1,CHEST:2,../../../../../Chests/Loot/Common1.nbt,25,CHEST:2,../../../../../Chests/Loot/Common2.nbt,25,CHEST:2,../../../../../Chests/Loot/Common3.nbt,25,CHEST:2,../../../../../Chests/Loot/Common4.nbt,25,CHEST:2,../../../../../Chests/Loot/Common5.nbt,25,CHEST:2,../../../../../Chests/Loot/Common6.nbt,25,CHEST:2,../../../../../Chests/Loot/Common7.nbt,25,CHEST:2,../../../../../Chests/Loot/Common8.nbt,25,CHEST:2,../../../../../Chests/Loot/Common9.nbt,25,CHEST:2,../../../../../Chests/Loot/Common10.nbt,25,CHEST:2,../../../../../Chests/Loot/Common11.nbt,25,CHEST:2,../../../../../Chests/Loot/Common12.nbt,25,CHEST:2,../../../../../Chests/Loot/Common13.nbt,25,CHEST:2,../../../../../Chests/Loot/Common14.nbt,25,CHEST:2,../../../../../Chests/Loot/Common15.nbt,25,CHEST:2,../../../../../Chests/Loot/Rare1.nbt,10,CHEST:2,../../../../../Chests/Loot/Rare2.nbt,10,CHEST:5,../../../../../Chests/Loot/Rare3.nbt,10,CHEST:2,../../../../../Chests/Loot/Rare4.nbt,10,CHEST:2,../../../../../Chests/Loot/Rare5.nbt,10,CHEST:2,../../../../../Chests/Loot/Rare6.nbt,10,CHEST:2,../../../../../Chests/Loot/Rare7.nbt,10,CHEST:2,../../../../../Chests/Loot/Rare8.nbt,10,CHEST:2,../../../../../Chests/Loot/Rare9.nbt,10,CHEST:2,../../../../../Chests/Loot/Rare10.nbt,10,CHEST:2,../../../../../Chests/Loot/Rare11.nbt,10,CHEST:2,../../../../../Chests/Loot/Rare12.nbt,10,CHEST:2,../../../../../Chests/Loot/Rare13.nbt,10,CHEST:2,../../../../../Chests/Loot/Rare14.nbt,10,CHEST:2,../../../../../Chests/Loot/Rare15.nbt,10,CHEST:2,../../../../../Chests/Loot/Epic1.nbt,1,CHEST:2,../../../../../Chests/Loot/Epic2.nbt,1,CHEST:2,../../../../../Chests/Loot/Epic3.nbt,1,CHEST:2,../../../../../Chests/Loot/Epic4.nbt,1,CHEST:2,../../../../../Chests/Loot/Epic5.nbt,1,CHEST:2,../../../../../Chests/Loot/Epic6.nbt,1,CHEST:2,../../../../../Chests/Loot/Epic7.nbt,1,CHEST:2,../../../../../Chests/Loot/Epic8.nbt,1,CHEST:2,../../../../../Chests/Loot/Epic9.nbt,1,CHEST:2,../../../../../Chests/Loot/Epic10.nbt,1,CHEST:2,../../../../../Chests/Loot/Epic11.nbt,1,CHEST:2,../../../../../Chests/Loot/Epic12.nbt,1,CHEST:2,../../../../../Chests/Loot/Epic13.nbt,1,CHEST:2,../../../../../Chests/Loot/Epic14.nbt,1,CHEST:2,../../../../../Chests/Loot/Epic15.nbt,1,CHEST:2,../../../../../Chests/Loot/ModernCityJunk_1.nbt,100)
Block(-6,9,-4,CONCRETE:7)
Block(-6,9,-3,CONCRETE:7)
Block(-6,9,-2,CONCRETE:7)
Block(-6,9,-1,CONCRETE:7)
Block(-6,9,0,CONCRETE:7)
Block(-6,9,1,CONCRETE:7)
Block(-6,9,2,CONCRETE:7)
Block(-6,9,3,CONCRETE:7)
Block(-6,9,4,CONCRETE:7)
Block(-6,9,5,CONCRETE:7)
Block(-6,9,6,CONCRETE:7)
Block(-6,9,7,CONCRETE:7)
Block(-6,9,8,CONCRETE:7)
Block(-6,10,-7,CONCRETE:7)
Block(-6,10,-4,CONCRETE:7)
Block(-6,10,-3,CONCRETE:7)
Block(-6,10,-2,CONCRETE:7)
Block(-6,10,-1,CONCRETE:7)
Block(-6,10,0,CONCRETE:7)
Block(-6,10,1,CONCRETE:7)
Block(-6,10,2,CONCRETE:7)
Block(-6,10,3,CONCRETE:7)
Block(-6,10,4,CONCRETE:7)
Block(-6,10,5,CONCRETE:7)
Block(-6,10,6,CONCRETE:7)
Block(-6,10,7,CONCRETE:7)
Block(-6,10,8,CONCRETE:7)
Block(-6,11,-7,CONCRETE:7)
Block(-6,11,-6,CONCRETE:7)
Block(-6,11,-5,CONCRETE:7)
Block(-6,11,-4,CONCRETE:7)
Block(-6,11,-3,DIRT:2)
Block(-6,11,-2,DIRT:2)
Block(-6,11,-1,DIRT:2)
Block(-6,11,0,DIRT:2)
Block(-6,11,1,DIRT:2)
Block(-6,11,2,DIRT:2)
Block(-6,11,3,DIRT:2)
Block(-6,11,4,DIRT:2)
Block(-6,11,5,DIRT:2)
Block(-6,11,6,DIRT:2)
Block(-6,11,7,CONCRETE:7)
Block(-6,11,8,CONCRETE:7)
Block(-6,12,-5,CAULDRON:3)
Block(-6,12,-4,CONCRETE:8)
Block(-6,12,-3,LEAVES:4)
Block(-6,12,-1,SUGAR_CANE_BLOCK:0)
Block(-6,12,0,LEAVES:4)
Block(-6,12,1,SUGAR_CANE_BLOCK:0)
Block(-6,12,3,DOUBLE_PLANT:2)
Block(-6,12,4,DOUBLE_PLANT:2)
Block(-6,12,5,SUGAR_CANE_BLOCK:0)
Block(-6,12,7,CONCRETE:8)
Block(-6,12,8,CONCRETE:7)
Block(-6,13,-5,TRIPWIRE_HOOK:2)
Block(-6,13,-4,CONCRETE:8)
Block(-6,13,-3,LEAVES:4)
Block(-6,13,-1,SUGAR_CANE_BLOCK:0)
Block(-6,13,1,SUGAR_CANE_BLOCK:0)
Block(-6,13,3,DOUBLE_PLANT:10)
Block(-6,13,4,DOUBLE_PLANT:10)
Block(-6,13,5,SUGAR_CANE_BLOCK:0)
Block(-6,13,7,CONCRETE:8)
Block(-6,13,8,CONCRETE:7)
Block(-6,14,-4,CONCRETE:8)
Block(-6,14,-3,LEAVES:4)
Block(-6,14,-1,SUGAR_CANE_BLOCK:0)
Block(-6,14,1,SUGAR_CANE_BLOCK:0)
Block(-6,14,5,SUGAR_CANE_BLOCK:0)
Block(-6,14,7,CONCRETE:8)
Block(-6,14,8,CONCRETE:7)
Block(-6,15,-7,STEP:9)
Block(-6,15,-6,STEP:9)
Block(-6,15,-5,IRON_TRAPDOOR:8)
Block(-6,15,-4,CONCRETE:8)
Block(-6,15,7,CONCRETE:8)
Block(-6,15,8,CONCRETE:7)
Block(-6,16,-7,CONCRETE:7)
Block(-6,16,-6,CONCRETE:7)
Block(-6,16,-5,CONCRETE:7)
Block(-6,16,-4,CONCRETE:7)
Block(-6,16,-3,CONCRETE:7)
Block(-6,16,-2,CONCRETE:7)
Block(-6,16,-1,CONCRETE:7)
Block(-6,16,0,CONCRETE:7)
Block(-6,16,1,CONCRETE:7)
Block(-6,16,2,CONCRETE:7)
Block(-6,16,3,CONCRETE:7)
Block(-6,16,4,CONCRETE:7)
Block(-6,16,5,CONCRETE:7)
Block(-6,16,6,CONCRETE:7)
Block(-6,16,7,CONCRETE:7)
Block(-6,16,8,CONCRETE:7)
Block(-6,17,-7,CONCRETE:7)
Block(-6,17,-6,CONCRETE:7)
Block(-6,17,-5,CONCRETE:7)
Block(-6,17,-4,CONCRETE:7)
Block(-6,17,-3,CONCRETE:7)
Block(-6,17,-2,CONCRETE:7)
Block(-6,17,-1,CONCRETE:7)
Block(-6,17,0,CONCRETE:7)
Block(-6,17,1,CONCRETE:7)
Block(-6,17,2,CONCRETE:7)
Block(-6,17,3,CONCRETE:7)
Block(-6,17,4,CONCRETE:7)
Block(-6,17,5,CONCRETE:7)
Block(-6,17,6,CONCRETE:7)
Block(-6,17,7,CONCRETE:7)
Block(-6,17,8,CONCRETE:7)
Block(-6,18,-7,CONCRETE:8)
Block(-6,18,-6,CONCRETE:8)
Block(-6,18,-5,CONCRETE:8)
Block(-6,18,-4,CONCRETE:8)
Block(-6,18,-3,CONCRETE:8)
Block(-6,18,-2,CONCRETE:8)
Block(-6,18,-1,CONCRETE:8)
Block(-6,18,0,CONCRETE:8)
Block(-6,18,1,CONCRETE:8)
Block(-6,18,2,CONCRETE:8)
Block(-6,18,3,CONCRETE:8)
Block(-6,18,4,CONCRETE:8)
Block(-6,18,6,CONCRETE:7)
Block(-6,18,7,CONCRETE:8)
Block(-6,19,-7,STANDING_BANNER:12,NBT/skyscraper_2x2_03/364-bannerC16R16.nbt)
Block(-6,19,-6,STANDING_BANNER:12,NBT/skyscraper_2x2_03/365-bannerC16R16.nbt)
Block(-6,19,-5,STANDING_BANNER:12,NBT/skyscraper_2x2_03/366-bannerC16R16.nbt)
Block(-6,19,-4,STANDING_BANNER:12,NBT/skyscraper_2x2_03/367-bannerC16R16.nbt)
Block(-6,19,-3,STANDING_BANNER:12,NBT/skyscraper_2x2_03/368-bannerC16R16.nbt)
Block(-6,19,-2,STANDING_BANNER:12,NBT/skyscraper_2x2_03/369-bannerC16R16.nbt)
Block(-6,19,-1,STANDING_BANNER:12,NBT/skyscraper_2x2_03/370-bannerC16R16.nbt)
Block(-6,19,0,STANDING_BANNER:12,NBT/skyscraper_2x2_03/371-bannerC16R16.nbt)
Block(-6,19,1,STANDING_BANNER:12,NBT/skyscraper_2x2_03/372-bannerC16R16.nbt)
Block(-6,19,2,STANDING_BANNER:12,NBT/skyscraper_2x2_03/373-bannerC16R16.nbt)
Block(-6,19,3,STANDING_BANNER:12,NBT/skyscraper_2x2_03/374-bannerC16R16.nbt)
Block(-6,19,4,CONCRETE:8)
Block(-6,19,6,CONCRETE:7)
Block(-6,19,7,CONCRETE:8)
Block(-6,20,4,CONCRETE:8)
Block(-6,20,6,CONCRETE:7)
Block(-6,20,7,CONCRETE:8)
Block(-6,21,-7,WOOD_STEP:5)
Block(-6,21,-6,WOOD_STEP:5)
Block(-6,21,-5,WOOD_STEP:5)
Block(-6,21,-4,WOOD_STEP:5)
Block(-6,21,-3,WOOD_STEP:5)
Block(-6,21,-2,WOOD_STEP:5)
Block(-6,21,-1,WOOD_STEP:5)
Block(-6,21,0,WOOD_STEP:5)
Block(-6,21,1,WOOD_STEP:5)
Block(-6,21,2,WOOD_STEP:5)
Block(-6,21,3,WOOD_STEP:5)
Block(-6,21,4,WOOD_STEP:5)
Block(-6,21,6,CONCRETE:7)
Block(-6,21,7,CONCRETE:8)
Block(-6,22,6,CONCRETE:7)
Block(-6,22,7,CONCRETE:8)
Block(-6,23,6,CONCRETE:7)
Block(-6,23,7,CONCRETE:8)
Block(-6,24,6,CONCRETE:7)
Block(-6,24,7,CONCRETE:8)
Block(-6,25,6,CONCRETE:7)
Block(-6,25,7,CONCRETE:8)
Block(-6,26,6,CONCRETE:7)
Block(-6,26,7,CONCRETE:8)
Block(-6,27,6,CONCRETE:7)
Block(-6,27,7,CONCRETE:8)
Block(-6,28,6,CONCRETE:7)
Block(-6,28,7,CONCRETE:8)
Block(-6,29,6,CONCRETE:7)
Block(-6,29,7,CONCRETE:8)
Block(-6,30,6,CONCRETE:7)
Block(-6,30,7,CONCRETE:8)
Block(-6,31,-7,CONCRETE:7)
Block(-6,31,-6,CONCRETE:7)
Block(-6,31,-5,CONCRETE:7)
Block(-6,31,-4,CONCRETE:7)
Block(-6,31,-3,CONCRETE:7)
Block(-6,31,-2,CONCRETE:7)
Block(-6,31,-1,CONCRETE:7)
Block(-6,31,0,CONCRETE:7)
Block(-6,31,1,CONCRETE:7)
Block(-6,31,2,CONCRETE:7)
Block(-6,31,3,CONCRETE:7)
Block(-6,31,4,CONCRETE:7)
Block(-6,31,5,CONCRETE:7)
Block(-6,31,6,CONCRETE:7)
Block(-6,31,7,CONCRETE:8)
Block(-6,32,6,CONCRETE:7)
Block(-6,32,7,CONCRETE:8)
Block(-6,33,6,CONCRETE:7)
Block(-6,33,7,CONCRETE:8)
Block(-6,34,6,CONCRETE:7)
Block(-6,34,7,CONCRETE:8)
Block(-6,35,6,CONCRETE:7)
Block(-6,35,7,CONCRETE:8)
Block(-6,36,6,CONCRETE:7)
Block(-6,36,7,CONCRETE:8)
Block(-6,37,6,CONCRETE:7)
Block(-6,37,7,CONCRETE:8)
Block(-6,38,6,CONCRETE:7)
Block(-6,38,7,CONCRETE:8)
Block(-6,39,6,CONCRETE:7)
Block(-6,39,7,CONCRETE:8)
Block(-6,40,6,CONCRETE:7)
Block(-6,40,7,CONCRETE:8)
Block(-6,41,6,CONCRETE:7)
Block(-6,41,7,CONCRETE:8)
Block(-6,42,-7,STAINED_GLASS:15)
Block(-6,42,-6,CONCRETE:7)
Block(-6,42,-5,CONCRETE:7)
Block(-6,42,-4,CONCRETE:7)
Block(-6,42,-3,CONCRETE:7)
Block(-6,42,-2,STAINED_GLASS:15)
Block(-6,42,-1,CONCRETE:7)
Block(-6,42,0,CONCRETE:7)
Block(-6,42,1,CONCRETE:7)
Block(-6,42,2,CONCRETE:7)
Block(-6,42,3,CONCRETE:7)
Block(-6,42,4,CONCRETE:7)
Block(-6,42,5,CONCRETE:7)
Block(-6,42,6,CONCRETE:7)
Block(-6,42,7,CONCRETE:8)
Block(-6,43,-6,STAINED_GLASS:15)
Block(-6,43,-5,PRISMARINE:2)
Block(-6,43,-4,STAINED_GLASS:15)
Block(-6,43,-1,STAINED_GLASS:15)
Block(-6,43,2,WALL_SIGN:5,NBT/skyscraper_2x2_03/376-signC16R16.nbt)
Block(-6,43,4,QUARTZ_STAIRS:4)
Block(-6,43,5,WALL_SIGN:5,NBT/skyscraper_2x2_03/377-signC16R16.nbt)
Block(-6,43,7,CONCRETE:8)
Block(-6,44,-6,STAINED_GLASS:15)
Block(-6,44,-5,STATIONARY_WATER:8)
Block(-6,44,-4,STAINED_GLASS:15)
Block(-6,44,-1,STAINED_GLASS:15)
Block(-6,44,4,IRON_TRAPDOOR:0)
Block(-6,44,7,CONCRETE:8)
Block(-6,45,-6,STAINED_GLASS:15)
Block(-6,45,-5,STATIONARY_WATER:8)
Block(-6,45,-4,STAINED_GLASS:15)
Block(-6,45,-1,STAINED_GLASS:15)
Block(-6,45,7,CONCRETE:8)
Block(-6,46,-6,STAINED_GLASS:15)
Block(-6,46,-5,STATIONARY_WATER:8)
Block(-6,46,-4,STAINED_GLASS:15)
Block(-6,46,-3,CONCRETE:7)
Block(-6,46,-2,STAINED_GLASS:15)
Block(-6,46,-1,STAINED_GLASS:15)
Block(-6,46,0,STAINED_GLASS:15)
Block(-6,46,1,STAINED_GLASS:15)
Block(-6,46,2,STAINED_GLASS:15)
Block(-6,46,3,STAINED_GLASS:15)
Block(-6,46,4,STAINED_GLASS:15)
Block(-6,46,5,STAINED_GLASS:15)
Block(-6,46,6,STAINED_GLASS:15)
Block(-6,46,7,CONCRETE:8)
Block(-6,47,-6,STAINED_GLASS:15)
Block(-6,47,-5,STATIONARY_WATER:0)
Block(-6,47,-4,STAINED_GLASS:15)
Block(-6,47,-2,WALL_SIGN:4,NBT/skyscraper_2x2_03/381-signC16R16.nbt)
Block(-6,47,-1,QUARTZ_STAIRS:5)
Block(-6,47,2,DARK_OAK_STAIRS:6)
Block(-6,47,3,DARK_OAK_STAIRS:3)
Block(-6,47,6,QUARTZ_STAIRS:5)
Block(-6,47,7,CONCRETE:8)
Block(-6,48,-6,STAINED_GLASS:15)
Block(-6,48,-5,PRISMARINE:2)
Block(-6,48,-4,STAINED_GLASS:15)
Block(-6,48,-1,IRON_TRAPDOOR:2)
Block(-6,48,0,WALL_BANNER:3,NBT/skyscraper_2x2_03/382-bannerC16R16.nbt)
Block(-6,48,1,DARK_OAK_STAIRS:6)
Block(-6,48,2,DARK_OAK_STAIRS:3)
Block(-6,48,7,CONCRETE:8)
Block(-6,49,-6,CONCRETE:7)
Block(-6,49,-5,LEVER:15)
Block(-6,49,-4,CONCRETE:8)
Block(-6,49,-3,CONCRETE:8)
Block(-6,49,-2,CONCRETE:8)
Block(-6,49,-1,CONCRETE:7)
Block(-6,49,0,STAINED_GLASS:15)
Block(-6,49,1,DARK_OAK_STAIRS:3)
Block(-6,49,7,CONCRETE:8)
Block(-6,50,-6,CONCRETE:7)
Block(-6,50,-5,DIRT:2)
Block(-6,50,-4,IRON_TRAPDOOR:5)
Block(-6,50,-2,CONCRETE:8)
Block(-6,50,-1,CONCRETE:7)
Block(-6,50,7,CONCRETE:8)
Block(-6,51,-6,CONCRETE:7)
Block(-6,51,-5,FLOWER_POT:0,NBT/skyscraper_2x2_03/383-flower_potC16R16.nbt)
Block(-6,51,-2,CONCRETE:8)
Block(-6,51,-1,CONCRETE:7)
Block(-6,51,7,CONCRETE:8)
Block(-6,52,-6,CONCRETE:7)
Block(-6,52,-5,LEAVES:4)
Block(-6,52,-2,CONCRETE:8)
Block(-6,52,-1,CONCRETE:7)
Block(-6,52,7,CONCRETE:8)
Block(-6,53,-6,CONCRETE:7)
Block(-6,53,-5,LEAVES:12)
Block(-6,53,-2,CONCRETE:8)
Block(-6,53,-1,CONCRETE:7)
Block(-6,53,6,CONCRETE:7)
Block(-6,53,7,CONCRETE:8)
Block(-6,54,-6,CONCRETE:7)
Block(-6,54,-2,CONCRETE:8)
Block(-6,54,-1,CONCRETE:8)
Block(-6,54,0,CONCRETE:8)
Block(-6,54,1,CONCRETE:8)
Block(-6,54,2,CONCRETE:8)
Block(-6,54,3,CONCRETE:8)
Block(-6,54,4,CONCRETE:8)
Block(-6,54,5,CONCRETE:8)
Block(-6,54,6,CONCRETE:8)
Block(-6,54,7,CONCRETE:8)
Block(-6,55,-6,CONCRETE:7)
Block(-6,55,-2,CONCRETE:8)
Block(-6,55,-1,CONCRETE:8)
Block(-6,55,0,CONCRETE:8)
Block(-6,55,1,CONCRETE:8)
Block(-6,55,2,CONCRETE:8)
Block(-6,55,3,CONCRETE:8)
Block(-6,55,4,CONCRETE:8)
Block(-6,55,5,CONCRETE:8)
Block(-6,55,6,CONCRETE:8)
Block(-6,55,7,CONCRETE:8)
Block(-6,56,-7,CONCRETE:7)
Block(-6,56,-6,CONCRETE:7)
Block(-6,56,-2,CONCRETE:8)
Block(-6,56,-1,CONCRETE:8)
Block(-6,56,0,CONCRETE:8)
Block(-6,56,1,CONCRETE:8)
Block(-6,56,2,CONCRETE:8)
Block(-6,56,3,CONCRETE:8)
Block(-6,56,4,CONCRETE:8)
Block(-6,56,5,CONCRETE:8)
Block(-6,56,6,CONCRETE:8)
Block(-6,56,7,CONCRETE:8)
Block(-6,57,-6,CONCRETE:7)
Block(-6,57,-2,CONCRETE:8)
Block(-6,57,-1,CONCRETE:8)
Block(-6,57,0,CONCRETE:8)
Block(-6,57,1,CONCRETE:8)
Block(-6,57,2,CONCRETE:8)
Block(-6,57,3,CONCRETE:8)
Block(-6,57,4,CONCRETE:8)
Block(-6,57,5,CONCRETE:8)
Block(-6,57,6,CONCRETE:8)
Block(-6,57,7,CONCRETE:8)
Block(-6,58,-6,CONCRETE:7)
Block(-6,59,-6,CONCRETE:7)
Block(-6,60,-6,CONCRETE:7)
Block(-6,61,-7,CONCRETE:7)
Block(-6,61,-6,CONCRETE:7)
Block(-6,61,-5,CONCRETE:7)
Block(-6,61,-4,CONCRETE:7)
Block(-6,61,-3,CONCRETE:7)
Block(-6,61,-2,CONCRETE:7)
Block(-6,61,-1,CONCRETE:7)
Block(-6,61,0,CONCRETE:7)
Block(-6,61,1,CONCRETE:7)
Block(-6,61,2,CONCRETE:7)
Block(-6,61,3,CONCRETE:7)
Block(-6,61,4,CONCRETE:7)
Block(-6,61,5,CONCRETE:7)
Block(-6,61,6,CONCRETE:7)
Block(-6,61,7,CONCRETE:7)
Block(-6,62,-7,CARPET:0)
Block(-6,62,-6,CARPET:0)
Block(-6,62,-5,CARPET:0)
Block(-6,62,-4,CARPET:0)
Block(-6,62,-2,TRAP_DOOR:14)
Block(-6,62,1,QUARTZ_STAIRS:5)
Block(-6,62,2,WALL_SIGN:4,NBT/skyscraper_2x2_03/384-signC16R16.nbt)
Block(-6,62,5,QUARTZ_STAIRS:5)
Block(-6,62,6,WALL_SIGN:4,NBT/skyscraper_2x2_03/385-signC16R16.nbt)
Block(-6,62,7,CONCRETE:7)
Block(-6,63,0,WALL_BANNER:2,NBT/skyscraper_2x2_03/386-bannerC16R16.nbt)
Block(-6,63,1,IRON_TRAPDOOR:3)
Block(-6,63,4,WALL_BANNER:2,NBT/skyscraper_2x2_03/387-bannerC16R16.nbt)
Block(-6,63,5,IRON_TRAPDOOR:0)
Block(-6,63,7,CONCRETE:7)
Block(-6,64,7,CONCRETE:7)
Block(-6,65,7,CONCRETE:7)
Block(-6,66,7,CONCRETE:7)
Block(-6,67,-6,CONCRETE:7)
Block(-6,67,-5,CONCRETE:7)
Block(-6,67,-4,CONCRETE:7)
Block(-6,67,-3,CONCRETE:7)
Block(-6,67,-2,CONCRETE:7)
Block(-6,67,-1,CONCRETE:7)
Block(-6,67,0,CONCRETE:7)
Block(-6,67,1,CONCRETE:7)
Block(-6,67,2,CONCRETE:7)
Block(-6,67,3,CONCRETE:7)
Block(-6,67,4,CONCRETE:7)
Block(-6,67,5,CONCRETE:7)
Block(-6,67,6,CONCRETE:7)
Block(-6,67,7,CONCRETE:7)
Block(-6,68,-6,CONCRETE:7)
Block(-6,68,-5,CONCRETE:8)
Block(-6,68,-4,CONCRETE:8)
Block(-6,68,-3,CONCRETE:8)
Block(-6,68,-2,STAINED_GLASS:15)
Block(-6,68,-1,CONCRETE:7)
Block(-6,68,0,CONCRETE:7)
Block(-6,68,1,CONCRETE:7)
Block(-6,68,2,CONCRETE:7)
Block(-6,68,3,CONCRETE:7)
Block(-6,68,4,CONCRETE:7)
Block(-6,68,5,CONCRETE:7)
Block(-6,68,6,CONCRETE:7)
Block(-6,69,-7,CONCRETE:7)
Block(-6,69,-6,CONCRETE:7)
Block(-6,69,6,CONCRETE:7)
Block(-6,70,-7,CONCRETE:7)
Block(-6,70,-6,CONCRETE:7)
Block(-6,70,6,CONCRETE:7)
Block(-6,71,-7,DARK_OAK_STAIRS:5)
Block(-6,71,-6,STAINED_GLASS_PANE:15)
Block(-6,71,6,CONCRETE:7)
Block(-6,72,-7,DARK_OAK_STAIRS:0)
Block(-6,72,6,CONCRETE:7)
Block(-6,73,-6,CONCRETE:7)
Block(-6,73,-5,CONCRETE:7)
Block(-6,73,-4,CONCRETE:7)
Block(-6,73,-3,CONCRETE:7)
Block(-6,73,-2,CONCRETE:7)
Block(-6,73,-1,CONCRETE:7)
Block(-6,73,0,CONCRETE:7)
Block(-6,73,1,CONCRETE:7)
Block(-6,73,2,CONCRETE:7)
Block(-6,73,3,CONCRETE:7)
Block(-6,73,4,CONCRETE:7)
Block(-6,73,5,CONCRETE:7)
Block(-6,73,6,CONCRETE:7)
Block(-6,74,-6,STAINED_GLASS_PANE:15)
Block(-6,74,-5,CARPET:0)
Block(-6,74,-4,CARPET:0)
Block(-6,74,-3,STAINED_GLASS_PANE:15)
Block(-6,74,-2,STAINED_GLASS_PANE:15)
Block(-6,74,-1,STAINED_GLASS_PANE:15)
Block(-6,74,0,STAINED_GLASS_PANE:15)
Block(-6,74,1,STAINED_GLASS_PANE:15)
Block(-6,74,2,STAINED_GLASS_PANE:15)
Block(-6,74,3,STAINED_GLASS_PANE:15)
Block(-6,74,4,STAINED_GLASS:15)
Block(-6,75,-3,STAINED_GLASS_PANE:15)
Block(-6,75,-2,STAINED_GLASS_PANE:15)
Block(-6,75,-1,STAINED_GLASS_PANE:15)
Block(-6,75,0,STAINED_GLASS_PANE:15)
Block(-6,75,1,STAINED_GLASS_PANE:15)
Block(-6,75,2,STAINED_GLASS_PANE:15)
Block(-6,75,3,STAINED_GLASS_PANE:15)
Block(-6,75,4,STAINED_GLASS:15)
Block(-6,76,-3,STAINED_GLASS_PANE:15)
Block(-6,76,-2,STAINED_GLASS_PANE:15)
Block(-6,76,-1,STAINED_GLASS_PANE:15)
Block(-6,76,0,STAINED_GLASS_PANE:15)
Block(-6,76,1,STAINED_GLASS_PANE:15)
Block(-6,76,2,STAINED_GLASS_PANE:15)
Block(-6,76,3,STAINED_GLASS_PANE:15)
Block(-6,76,4,STAINED_GLASS:15)
Block(-6,77,-7,CONCRETE:7)
Block(-6,77,-6,CONCRETE:7)
Block(-6,77,-5,CONCRETE:7)
Block(-6,77,-4,CONCRETE:7)
Block(-6,77,-3,CONCRETE:7)
Block(-6,77,-2,CONCRETE:7)
Block(-6,77,-1,CONCRETE:7)
Block(-6,77,0,CONCRETE:7)
Block(-6,77,1,CONCRETE:7)
Block(-6,77,2,CONCRETE:7)
Block(-6,77,3,CONCRETE:7)
Block(-6,77,4,CONCRETE:7)
Block(-6,77,5,CONCRETE:7)
Block(-6,77,6,CONCRETE:7)
Block(-6,78,-7,IRON_DOOR_BLOCK:2)
Block(-6,78,-6,STAINED_GLASS:15)
Block(-6,78,-5,STAINED_GLASS:15)
Block(-6,78,-4,STAINED_GLASS:15)
Block(-6,78,-3,STAINED_GLASS:15)
Block(-6,78,-2,STAINED_GLASS:15)
Block(-6,78,-1,STAINED_GLASS:15)
Block(-6,78,0,STAINED_GLASS:15)
Block(-6,78,3,STAINED_GLASS:15)
Block(-6,78,4,STAINED_GLASS:15)
Block(-6,78,5,STAINED_GLASS:15)
Block(-6,78,6,CONCRETE:7)
Block(-6,79,-7,IRON_DOOR_BLOCK:8)
Block(-6,79,-6,STAINED_GLASS:15)
Block(-6,79,-5,CONCRETE:7)
Block(-6,79,-4,CONCRETE:7)
Block(-6,79,-3,CONCRETE:7)
Block(-6,79,-2,CONCRETE:7)
Block(-6,79,-1,CONCRETE:7)
Block(-6,79,0,CONCRETE:7)
Block(-6,79,3,CONCRETE:7)
Block(-6,79,4,CONCRETE:7)
Block(-6,79,5,CONCRETE:7)
Block(-6,79,6,CONCRETE:7)
Block(-6,80,-7,STAINED_GLASS:15)
Block(-6,80,-6,STAINED_GLASS:15)
Block(-6,80,-5,CONCRETE:7)
Block(-6,80,-4,CONCRETE:7)
Block(-6,80,-3,CONCRETE:7)
Block(-6,80,-2,CONCRETE:7)
Block(-6,80,-1,CONCRETE:7)
Block(-6,80,0,CONCRETE:7)
Block(-6,80,3,CONCRETE:7)
Block(-6,80,4,CONCRETE:7)
Block(-6,80,5,CONCRETE:7)
Block(-6,80,6,CONCRETE:7)
Block(-6,81,-7,CONCRETE:7)
Block(-6,81,-6,CONCRETE:7)
Block(-6,81,-5,CONCRETE:7)
Block(-6,81,-4,CONCRETE:7)
Block(-6,81,-3,CONCRETE:7)
Block(-6,81,-2,CONCRETE:7)
Block(-6,81,-1,CONCRETE:7)
Block(-6,81,0,CONCRETE:7)
Block(-6,81,1,CONCRETE:7)
Block(-6,81,2,CONCRETE:7)
Block(-6,81,3,CONCRETE:7)
Block(-6,81,4,CONCRETE:7)
Block(-6,81,5,CONCRETE:7)
Block(-6,81,6,CONCRETE:7)
Block(-6,82,-7,CONCRETE:7)
Block(-6,82,-6,CONCRETE:7)
Block(-6,82,-5,CONCRETE:7)
Block(-6,82,-4,CONCRETE:7)
Block(-6,82,-3,CONCRETE:7)
Block(-6,82,-2,CONCRETE:7)
Block(-6,82,-1,CONCRETE:7)
Block(-6,82,0,CONCRETE:7)
Block(-6,82,1,CONCRETE:7)
Block(-6,82,2,CONCRETE:7)
Block(-6,82,3,CONCRETE:7)
Block(-6,83,-7,STAINED_GLASS_PANE:15)
Block(-6,83,-6,STAINED_GLASS_PANE:15)
Block(-6,83,-5,STAINED_GLASS_PANE:15)
Block(-6,83,-4,STAINED_GLASS_PANE:15)
Block(-6,83,-3,STAINED_GLASS_PANE:15)
Block(-6,83,-2,CONCRETE:7)
Block(-6,83,-1,CONCRETE:7)
Block(-6,83,0,CONCRETE:7)
Block(-6,83,3,CONCRETE:7)
Block(-6,84,-2,CONCRETE:7)
Block(-6,84,-1,CONCRETE:7)
Block(-6,84,0,CONCRETE:7)
Block(-6,84,3,CONCRETE:7)
Block(-6,85,-2,CONCRETE:7)
Block(-6,85,-1,CONCRETE:7)
Block(-6,85,0,CONCRETE:7)
Block(-6,85,3,CONCRETE:7)
Block(-6,86,-7,CONCRETE:7)
Block(-6,86,-6,CONCRETE:7)
Block(-6,86,-5,CONCRETE:7)
Block(-6,86,-4,CONCRETE:7)
Block(-6,86,-3,CONCRETE:7)
Block(-6,86,-2,CONCRETE:7)
Block(-6,86,-1,CONCRETE:7)
Block(-6,86,0,CONCRETE:7)
Block(-6,86,1,CONCRETE:7)
Block(-6,86,2,CONCRETE:7)
Block(-6,86,3,CONCRETE:7)
Block(-6,87,-7,STAINED_GLASS_PANE:15)
Block(-6,87,-6,STAINED_GLASS_PANE:15)
Block(-6,87,-5,STAINED_GLASS_PANE:15)
Block(-6,87,-4,STAINED_GLASS_PANE:15)
Block(-6,87,-3,STAINED_GLASS_PANE:15)
Block(-6,87,-2,CONCRETE:7)
Block(-6,87,-1,CONCRETE:7)
Block(-6,87,0,CONCRETE:7)
Block(-6,87,1,STAINED_GLASS_PANE:15)
Block(-6,87,2,STAINED_GLASS_PANE:15)
Block(-6,87,3,CONCRETE:7)
Block(-6,88,-2,CONCRETE:7)
Block(-6,88,-1,CONCRETE:7)
Block(-6,88,0,CONCRETE:7)
Block(-6,88,3,CONCRETE:7)
Block(-6,89,-2,CONCRETE:7)
Block(-6,89,-1,CONCRETE:7)
Block(-6,89,0,CONCRETE:7)
Block(-6,89,3,CONCRETE:7)
Block(-6,90,-7,CONCRETE:7)
Block(-6,90,-6,CONCRETE:7)
Block(-6,90,-5,CONCRETE:7)
Block(-6,90,-4,CONCRETE:7)
Block(-6,90,-3,CONCRETE:7)
Block(-6,90,-2,CONCRETE:7)
Block(-6,90,-1,CONCRETE:7)
Block(-6,90,0,CONCRETE:7)
Block(-6,90,1,CONCRETE:7)
Block(-6,90,2,CONCRETE:7)
Block(-6,90,3,CONCRETE:7)
Block(-6,91,-7,STAINED_GLASS_PANE:15)
Block(-6,91,-6,STAINED_GLASS_PANE:15)
Block(-6,91,-5,STAINED_GLASS_PANE:15)
Block(-6,91,-4,STAINED_GLASS_PANE:15)
Block(-6,91,-3,STAINED_GLASS_PANE:15)
Block(-6,91,-2,CONCRETE:7)
Block(-6,91,-1,CONCRETE:7)
Block(-6,91,0,CONCRETE:7)
Block(-6,91,1,STAINED_GLASS_PANE:15)
Block(-6,91,2,STAINED_GLASS_PANE:15)
Block(-6,91,3,CONCRETE:7)
Block(-6,92,-2,CONCRETE:7)
Block(-6,92,-1,CONCRETE:7)
Block(-6,92,0,CONCRETE:7)
Block(-6,92,3,CONCRETE:7)
Block(-6,93,-2,CONCRETE:7)
Block(-6,93,-1,CONCRETE:7)
Block(-6,93,0,CONCRETE:7)
Block(-6,93,3,CONCRETE:7)
Block(-6,94,-7,CONCRETE:7)
Block(-6,94,-6,CONCRETE:7)
Block(-6,94,-5,CONCRETE:7)
Block(-6,94,-4,CONCRETE:7)
Block(-6,94,-3,CONCRETE:7)
Block(-6,94,-2,CONCRETE:7)
Block(-6,94,-1,CONCRETE:7)
Block(-6,94,0,CONCRETE:7)
Block(-6,94,1,STAINED_GLASS:15)
Block(-6,94,2,STAINED_GLASS:15)
Block(-6,94,3,CONCRETE:7)
Block(-6,95,-7,CONCRETE:7)
Block(-6,95,-6,CONCRETE:7)
Block(-6,95,-5,CONCRETE:7)
Block(-6,95,-4,CONCRETE:7)
Block(-6,95,-3,CONCRETE:7)
Block(-6,95,-2,CONCRETE:7)
Block(-6,95,-1,CONCRETE:7)
Block(-6,95,0,CONCRETE:7)
Block(-6,95,1,CONCRETE:7)
Block(-6,95,2,CONCRETE:7)
Block(-6,95,3,CONCRETE:7)
Block(-6,96,-7,STATIONARY_LAVA:0)
Block(-6,96,-6,STATIONARY_LAVA:0)
Block(-6,96,-5,STATIONARY_LAVA:0)
Block(-6,96,-4,STATIONARY_LAVA:0)
Block(-6,96,-3,STATIONARY_LAVA:0)
Block(-6,96,-2,STATIONARY_LAVA:0)
Block(-6,96,-1,STATIONARY_LAVA:0)
Block(-6,96,0,STATIONARY_LAVA:0)
Block(-6,96,1,STATIONARY_LAVA:0)
Block(-6,96,2,CONCRETE:7)
Block(-6,96,3,CONCRETE:7)
Block(-6,97,-7,OBSIDIAN:0)
Block(-6,97,-6,OBSIDIAN:0)
Block(-6,97,-5,OBSIDIAN:0)
Block(-6,97,-4,OBSIDIAN:0)
Block(-6,97,-3,OBSIDIAN:0)
Block(-6,97,-2,OBSIDIAN:0)
Block(-6,97,-1,OBSIDIAN:0)
Block(-6,97,0,OBSIDIAN:0)
Block(-6,97,1,STATIONARY_LAVA:8)
Block(-6,97,2,CONCRETE:7)
Block(-6,97,3,CONCRETE:7)
Block(-6,98,-7,OBSIDIAN:0)
Block(-6,98,-6,OBSIDIAN:0)
Block(-6,98,-5,REDSTONE_WIRE:0)
Block(-6,98,-4,OBSIDIAN:0)
Block(-6,98,-3,DIODE_BLOCK_OFF:0)
Block(-6,98,-2,OBSIDIAN:0)
Block(-6,98,-1,REDSTONE_WIRE:0)
Block(-6,98,0,OBSIDIAN:0)
Block(-6,98,1,STATIONARY_LAVA:8)
Block(-6,98,2,CONCRETE:7)
Block(-6,98,3,CONCRETE:7)
Block(-6,99,-7,OBSIDIAN:0)
Block(-6,99,-6,OBSIDIAN:0)
Block(-6,99,-4,OBSIDIAN:0)
Block(-6,99,-3,OBSIDIAN:0)
Block(-6,99,-2,REDSTONE_WIRE:0)
Block(-6,99,0,OBSIDIAN:0)
Block(-6,99,1,STATIONARY_LAVA:8)
Block(-6,99,2,CONCRETE:7)
Block(-6,99,3,CONCRETE:7)
Block(-6,100,-7,OBSIDIAN:0)
Block(-6,100,-6,REDSTONE_WIRE:0)
Block(-6,100,-5,OBSIDIAN:0)
Block(-6,100,-4,REDSTONE_WIRE:0)
Block(-6,100,-3,REDSTONE_WIRE:0)
Block(-6,100,0,OBSIDIAN:0)
Block(-6,100,1,STATIONARY_LAVA:8)
Block(-6,100,2,CONCRETE:7)
Block(-6,100,3,CONCRETE:7)
Block(-6,101,-7,OBSIDIAN:0)
Block(-6,101,-5,REDSTONE_WIRE:0)
Block(-6,101,-3,OBSIDIAN:0)
Block(-6,101,-2,OBSIDIAN:0)
Block(-6,101,0,OBSIDIAN:0)
Block(-6,101,1,STATIONARY_LAVA:8)
Block(-6,101,2,CONCRETE:7)
Block(-6,101,3,CONCRETE:7)
Block(-6,102,-7,OBSIDIAN:0)
Block(-6,102,-6,OBSIDIAN:0)
Block(-6,102,-5,OBSIDIAN:0)
Block(-6,102,-4,OBSIDIAN:0)
Block(-6,102,-3,OBSIDIAN:0)
Block(-6,102,-2,OBSIDIAN:0)
Block(-6,102,-1,OBSIDIAN:0)
Block(-6,102,0,OBSIDIAN:0)
Block(-6,102,1,STATIONARY_LAVA:8)
Block(-6,102,2,CONCRETE:7)
Block(-6,102,3,CONCRETE:7)
Block(-6,103,-7,STATIONARY_LAVA:0)
Block(-6,103,-6,STATIONARY_LAVA:0)
Block(-6,103,-5,STATIONARY_LAVA:0)
Block(-6,103,-4,STATIONARY_LAVA:0)
Block(-6,103,-3,STATIONARY_LAVA:0)
Block(-6,103,-2,STATIONARY_LAVA:0)
Block(-6,103,-1,STATIONARY_LAVA:0)
Block(-6,103,0,STATIONARY_LAVA:0)
Block(-6,103,1,STATIONARY_LAVA:0)
Block(-6,103,2,CONCRETE:7)
Block(-6,103,3,CONCRETE:7)
Block(-6,104,-7,CONCRETE:7)
Block(-6,104,-6,CONCRETE:7)
Block(-6,104,-5,CONCRETE:7)
Block(-6,104,-4,CONCRETE:7)
Block(-6,104,-3,CONCRETE:7)
Block(-6,104,-2,CONCRETE:7)
Block(-6,104,-1,CONCRETE:7)
Block(-6,104,0,CONCRETE:7)
Block(-6,104,1,CONCRETE:7)
Block(-6,104,2,CONCRETE:7)
Block(-6,104,3,CONCRETE:7)
Block(-6,105,-7,STATIONARY_WATER:0)
Block(-6,105,-6,STATIONARY_WATER:0)
Block(-6,105,-5,STATIONARY_WATER:0)
Block(-6,105,-4,STATIONARY_WATER:0)
Block(-6,105,-3,STATIONARY_WATER:0)
Block(-6,105,-2,STATIONARY_WATER:0)
Block(-6,105,-1,STATIONARY_WATER:0)
Block(-6,105,0,STATIONARY_WATER:0)
Block(-6,105,1,STATIONARY_WATER:0)
Block(-6,105,2,CONCRETE:7)
Block(-6,105,3,CONCRETE:7)
Block(-6,106,-1,STEP:8)
Block(-6,106,0,CONCRETE:7)
Block(-6,106,1,CONCRETE:7)
Block(-6,106,2,CONCRETE:7)
Block(-6,106,3,CONCRETE:7)
Block(-6,107,-2,STAINED_GLASS:15)
Block(-6,107,-1,CONCRETE:7)
Block(-6,107,0,STAINED_GLASS:15)
Block(-6,107,1,CONCRETE:7)
Block(-6,107,2,STAINED_GLASS:15)
Block(-6,107,3,CONCRETE:7)
Block(-6,108,-2,STAINED_GLASS:15)
Block(-6,108,-1,CONCRETE:7)
Block(-6,108,0,QUARTZ_STAIRS:2)
Block(-6,108,3,CONCRETE:7)
Block(-6,109,-2,STAINED_GLASS:15)
Block(-6,109,-1,CONCRETE:7)
Block(-6,109,0,TRIPWIRE_HOOK:0)
Block(-6,109,3,CONCRETE:7)
Block(-6,110,-2,STAINED_GLASS:15)
Block(-6,110,-1,CONCRETE:7)
Block(-6,110,3,CONCRETE:7)
Block(-6,111,-2,STAINED_GLASS:15)
Block(-6,111,-1,CONCRETE:7)
Block(-6,111,3,CONCRETE:7)
Block(-6,112,-7,CONCRETE:7)
Block(-6,112,-6,STAINED_GLASS:15)
Block(-6,112,-5,CONCRETE:7)
Block(-6,112,-4,STAINED_GLASS:15)
Block(-6,112,-3,CONCRETE:7)
Block(-6,112,-2,STAINED_GLASS:15)
Block(-6,112,-1,CONCRETE:7)
Block(-6,112,0,STAINED_GLASS:15)
Block(-6,112,1,CONCRETE:7)
Block(-6,112,2,STAINED_GLASS:15)
Block(-6,112,3,CONCRETE:7)
Block(-6,113,-7,CONCRETE:7)
Block(-6,113,-5,CONCRETE:7)
Block(-6,113,-3,CONCRETE:7)
Block(-6,113,-1,CONCRETE:7)
Block(-6,113,1,CONCRETE:7)
Block(-6,113,3,CONCRETE:7)
Block(-5,0,-7,CONCRETE:7)
Block(-5,0,-6,CONCRETE:7)
Block(-5,0,-5,CONCRETE:7)
Block(-5,0,-4,CONCRETE:7)
Block(-5,0,-3,CONCRETE:7)
Block(-5,0,-2,CONCRETE:7)
Block(-5,0,-1,CONCRETE:7)
Block(-5,0,0,CONCRETE:7)
Block(-5,0,1,CONCRETE:7)
Block(-5,0,2,CONCRETE:7)
Block(-5,0,3,CONCRETE:7)
Block(-5,0,4,CONCRETE:7)
Block(-5,0,5,CONCRETE:7)
Block(-5,0,6,CONCRETE:7)
Block(-5,0,7,CONCRETE:7)
Block(-5,0,8,CONCRETE:7)
Block(-5,1,-7,STATIONARY_WATER:0)
Block(-5,1,-6,STATIONARY_WATER:0)
Block(-5,1,-5,STATIONARY_WATER:0)
Block(-5,1,-4,STATIONARY_WATER:0)
Block(-5,1,-3,STATIONARY_WATER:0)
Block(-5,1,-2,STATIONARY_WATER:0)
Block(-5,1,-1,STATIONARY_WATER:0)
Block(-5,1,0,STATIONARY_WATER:0)
Block(-5,1,1,STATIONARY_WATER:0)
Block(-5,1,2,CONCRETE:7)
Block(-5,1,3,CONCRETE:7)
Block(-5,1,4,CONCRETE:7)
Block(-5,1,5,CONCRETE:7)
Block(-5,1,6,CONCRETE:7)
Block(-5,1,7,CONCRETE:7)
Block(-5,1,8,CONCRETE:7)
Block(-5,2,2,CONCRETE:7)
Block(-5,2,3,SMOOTH_STAIRS:1)
Block(-5,2,4,SMOOTH_STAIRS:1)
Block(-5,2,5,SMOOTH_STAIRS:1)
Block(-5,2,6,SMOOTH_STAIRS:1)
Block(-5,2,7,SMOOTH_STAIRS:1)
Block(-5,2,8,SMOOTH_STAIRS:1)
Block(-5,3,2,CONCRETE:7)
Block(-5,4,2,CONCRETE:7)
Block(-5,4,3,STEP:8)
Block(-5,4,4,CONCRETE:7)
Block(-5,4,5,STEP:8)
Block(-5,4,6,STEP:8)
Block(-5,4,7,CONCRETE:7)
Block(-5,4,8,STEP:8)
Block(-5,5,-7,CONCRETE:14)
Block(-5,5,-6,CONCRETE:11)
Block(-5,5,2,CONCRETE:7)
Block(-5,5,3,CONCRETE:7)
Block(-5,5,4,CONCRETE:7)
Block(-5,5,5,CONCRETE:7)
Block(-5,5,6,CONCRETE:7)
Block(-5,5,7,CONCRETE:7)
Block(-5,5,8,CONCRETE:7)
Block(-5,6,-7,IRON_FENCE:0)
Block(-5,6,2,CONCRETE:7)
Block(-5,6,3,CONCRETE:7)
Block(-5,6,4,CONCRETE:7)
Block(-5,6,5,CONCRETE:7)
Block(-5,6,6,CONCRETE:7)
Block(-5,6,7,CONCRETE:7)
Block(-5,6,8,CONCRETE:7)
Block(-5,7,-7,CONCRETE:7)
Block(-5,7,-6,CONCRETE:7)
Block(-5,7,-5,CONCRETE:7)
Block(-5,7,-4,CONCRETE:7)
Block(-5,7,-3,CONCRETE:7)
Block(-5,7,-2,CONCRETE:7)
Block(-5,7,-1,CONCRETE:7)
Block(-5,7,0,CONCRETE:7)
Block(-5,7,1,CONCRETE:7)
Block(-5,7,2,CONCRETE:7)
Block(-5,7,3,CONCRETE:7)
Block(-5,7,4,CONCRETE:7)
Block(-5,7,5,CONCRETE:7)
Block(-5,7,6,CONCRETE:7)
Block(-5,7,7,CONCRETE:7)
Block(-5,7,8,CONCRETE:7)
Block(-5,8,-7,CONCRETE:7)
Block(-5,8,-6,CONCRETE:7)
Block(-5,8,-5,CONCRETE:7)
Block(-5,8,-4,CONCRETE:7)
Block(-5,8,-3,CONCRETE:7)
Block(-5,8,-2,CONCRETE:7)
Block(-5,8,-1,CONCRETE:7)
Block(-5,8,0,CONCRETE:7)
Block(-5,8,1,CONCRETE:7)
Block(-5,8,2,CONCRETE:7)
Block(-5,8,3,CONCRETE:7)
Block(-5,8,4,CONCRETE:7)
Block(-5,8,5,CONCRETE:7)
Block(-5,8,6,CONCRETE:7)
Block(-5,8,7,CONCRETE:7)
Block(-5,8,8,CONCRETE:7)
Block(-5,9,-7,CONCRETE:7)
Block(-5,9,-6,CONCRETE:7)
Block(-5,9,-5,CONCRETE:7)
Block(-5,9,-4,CONCRETE:7)
Block(-5,9,-3,CONCRETE:7)
Block(-5,9,-2,CONCRETE:7)
Block(-5,9,-1,CONCRETE:7)
Block(-5,9,0,CONCRETE:7)
Block(-5,9,1,CONCRETE:7)
Block(-5,9,2,CONCRETE:7)
Block(-5,9,3,CONCRETE:7)
Block(-5,9,4,CONCRETE:7)
Block(-5,9,5,CONCRETE:7)
Block(-5,9,6,CONCRETE:7)
Block(-5,9,7,CONCRETE:7)
Block(-5,9,8,CONCRETE:7)
Block(-5,10,-7,CONCRETE:7)
Block(-5,10,-6,CONCRETE:7)
Block(-5,10,-5,CONCRETE:7)
Block(-5,10,-4,CONCRETE:7)
Block(-5,10,-3,CONCRETE:7)
Block(-5,10,-2,CONCRETE:7)
Block(-5,10,-1,CONCRETE:7)
Block(-5,10,0,CONCRETE:7)
Block(-5,10,1,CONCRETE:7)
Block(-5,10,2,CONCRETE:7)
Block(-5,10,3,CONCRETE:7)
Block(-5,10,4,CONCRETE:7)
Block(-5,10,5,CONCRETE:7)
Block(-5,10,6,CONCRETE:7)
Block(-5,10,7,CONCRETE:7)
Block(-5,10,8,CONCRETE:7)
Block(-5,11,-7,CONCRETE:7)
Block(-5,11,-6,CONCRETE:7)
Block(-5,11,-5,CONCRETE:7)
Block(-5,11,-4,CONCRETE:7)
Block(-5,11,-3,CONCRETE:7)
Block(-5,11,-2,CONCRETE:7)
Block(-5,11,-1,CONCRETE:7)
Block(-5,11,0,CONCRETE:7)
Block(-5,11,1,CONCRETE:7)
Block(-5,11,2,CONCRETE:7)
Block(-5,11,3,CONCRETE:7)
Block(-5,11,4,CONCRETE:7)
Block(-5,11,5,CONCRETE:7)
Block(-5,11,6,CONCRETE:7)
Block(-5,11,7,CONCRETE:7)
Block(-5,11,8,CONCRETE:7)
Block(-5,12,-5,QUARTZ_STAIRS:6)
Block(-5,12,-4,CONCRETE:8)
Block(-5,12,-3,CONCRETE:8)
Block(-5,12,-2,CONCRETE:8)
Block(-5,12,-1,CONCRETE:8)
Block(-5,12,0,CONCRETE:8)
Block(-5,12,1,CONCRETE:8)
Block(-5,12,2,CONCRETE:8)
Block(-5,12,3,CONCRETE:8)
Block(-5,12,4,CONCRETE:8)
Block(-5,12,5,CONCRETE:8)
Block(-5,12,6,SPRUCE_DOOR:2)
Block(-5,12,7,CONCRETE:8)
Block(-5,12,8,CONCRETE:7)
Block(-5,13,-4,CONCRETE:8)
Block(-5,13,-3,CONCRETE:8)
Block(-5,13,-2,CONCRETE:8)
Block(-5,13,-1,CONCRETE:8)
Block(-5,13,0,CONCRETE:8)
Block(-5,13,1,CONCRETE:8)
Block(-5,13,2,CONCRETE:8)
Block(-5,13,3,CONCRETE:8)
Block(-5,13,4,CONCRETE:8)
Block(-5,13,5,CONCRETE:8)
Block(-5,13,6,SPRUCE_DOOR:8)
Block(-5,13,7,CONCRETE:8)
Block(-5,13,8,CONCRETE:7)
Block(-5,14,-7,TRAP_DOOR:5)
Block(-5,14,-5,WALL_BANNER:2,NBT/skyscraper_2x2_03/395-bannerC16R16.nbt)
Block(-5,14,-4,CONCRETE:8)
Block(-5,14,-3,CONCRETE:8)
Block(-5,14,-2,CONCRETE:8)
Block(-5,14,-1,CONCRETE:8)
Block(-5,14,0,CONCRETE:8)
Block(-5,14,1,CONCRETE:8)
Block(-5,14,2,CONCRETE:8)
Block(-5,14,3,CONCRETE:8)
Block(-5,14,4,CONCRETE:8)
Block(-5,14,5,CONCRETE:8)
Block(-5,14,6,CONCRETE:8)
Block(-5,14,7,CONCRETE:8)
Block(-5,14,8,CONCRETE:7)
Block(-5,15,-7,CONCRETE:8)
Block(-5,15,-6,CONCRETE:8)
Block(-5,15,-5,CONCRETE:8)
Block(-5,15,-4,CONCRETE:8)
Block(-5,15,-3,CONCRETE:8)
Block(-5,15,-2,CONCRETE:8)
Block(-5,15,-1,CONCRETE:8)
Block(-5,15,0,CONCRETE:8)
Block(-5,15,1,CONCRETE:8)
Block(-5,15,2,CONCRETE:8)
Block(-5,15,3,CONCRETE:8)
Block(-5,15,4,CONCRETE:8)
Block(-5,15,5,CONCRETE:8)
Block(-5,15,6,CONCRETE:8)
Block(-5,15,7,CONCRETE:8)
Block(-5,15,8,CONCRETE:7)
Block(-5,16,-7,CONCRETE:7)
Block(-5,16,-6,CONCRETE:7)
Block(-5,16,-5,CONCRETE:7)
Block(-5,16,-4,CONCRETE:7)
Block(-5,16,-3,CONCRETE:7)
Block(-5,16,-2,CONCRETE:7)
Block(-5,16,-1,CONCRETE:7)
Block(-5,16,0,CONCRETE:7)
Block(-5,16,1,CONCRETE:7)
Block(-5,16,2,CONCRETE:7)
Block(-5,16,3,CONCRETE:7)
Block(-5,16,4,CONCRETE:7)
Block(-5,16,5,CONCRETE:7)
Block(-5,16,6,CONCRETE:7)
Block(-5,16,7,CONCRETE:7)
Block(-5,16,8,CONCRETE:7)
Block(-5,17,-7,CONCRETE:7)
Block(-5,17,-6,CONCRETE:7)
Block(-5,17,-5,CONCRETE:7)
Block(-5,17,-4,CONCRETE:7)
Block(-5,17,-3,CONCRETE:7)
Block(-5,17,-2,CONCRETE:7)
Block(-5,17,-1,CONCRETE:7)
Block(-5,17,0,CONCRETE:7)
Block(-5,17,1,CONCRETE:7)
Block(-5,17,2,CONCRETE:7)
Block(-5,17,3,CONCRETE:7)
Block(-5,17,4,CONCRETE:7)
Block(-5,17,5,CONCRETE:7)
Block(-5,17,6,CONCRETE:7)
Block(-5,17,7,CONCRETE:7)
Block(-5,17,8,CONCRETE:7)
Block(-5,18,6,CONCRETE:7)
Block(-5,18,7,CONCRETE:8)
Block(-5,19,6,CONCRETE:7)
Block(-5,19,7,CONCRETE:8)
Block(-5,20,6,CONCRETE:7)
Block(-5,20,7,CONCRETE:8)
Block(-5,21,6,CONCRETE:7)
Block(-5,21,7,CONCRETE:8)
Block(-5,22,6,CONCRETE:7)
Block(-5,22,7,CONCRETE:8)
Block(-5,23,6,CONCRETE:7)
Block(-5,23,7,CONCRETE:8)
Block(-5,24,6,CONCRETE:7)
Block(-5,24,7,CONCRETE:8)
Block(-5,25,6,CONCRETE:7)
Block(-5,25,7,CONCRETE:8)
Block(-5,26,6,CONCRETE:7)
Block(-5,26,7,CONCRETE:8)
Block(-5,27,6,CONCRETE:7)
Block(-5,27,7,CONCRETE:8)
Block(-5,28,6,CONCRETE:7)
Block(-5,28,7,CONCRETE:8)
Block(-5,29,6,CONCRETE:7)
Block(-5,29,7,CONCRETE:8)
Block(-5,30,6,CONCRETE:7)
Block(-5,30,7,CONCRETE:8)
Block(-5,31,-7,CONCRETE:7)
Block(-5,31,-6,CONCRETE:7)
Block(-5,31,-5,CONCRETE:7)
Block(-5,31,-4,CONCRETE:7)
Block(-5,31,-3,CONCRETE:7)
Block(-5,31,-2,CONCRETE:7)
Block(-5,31,-1,CONCRETE:7)
Block(-5,31,0,CONCRETE:7)
Block(-5,31,1,CONCRETE:7)
Block(-5,31,2,CONCRETE:7)
Block(-5,31,3,CONCRETE:7)
Block(-5,31,4,CONCRETE:7)
Block(-5,31,5,CONCRETE:7)
Block(-5,31,6,CONCRETE:7)
Block(-5,31,7,CONCRETE:8)
Block(-5,32,-6,TRAP_DOOR:5)
Block(-5,32,-5,QUARTZ_STAIRS:5)
Block(-5,32,-4,WALL_BANNER:3,NBT/skyscraper_2x2_03/396-bannerC16R16.nbt)
Block(-5,32,-2,TRAP_DOOR:5)
Block(-5,32,-1,QUARTZ_STAIRS:5)
Block(-5,32,0,WALL_BANNER:3,NBT/skyscraper_2x2_03/397-bannerC16R16.nbt)
Block(-5,32,2,TRAP_DOOR:5)
Block(-5,32,3,QUARTZ_STAIRS:5)
Block(-5,32,4,WALL_BANNER:3,NBT/skyscraper_2x2_03/398-bannerC16R16.nbt)
Block(-5,32,6,CONCRETE:7)
Block(-5,32,7,CONCRETE:8)
Block(-5,33,-7,WALL_BANNER:2,NBT/skyscraper_2x2_03/399-bannerC16R16.nbt)
Block(-5,33,-6,TRAP_DOOR:5)
Block(-5,33,-5,IRON_TRAPDOOR:0)
Block(-5,33,-3,WALL_BANNER:2,NBT/skyscraper_2x2_03/400-bannerC16R16.nbt)
Block(-5,33,-2,TRAP_DOOR:5)
Block(-5,33,-1,IRON_TRAPDOOR:0)
Block(-5,33,1,WALL_BANNER:2,NBT/skyscraper_2x2_03/401-bannerC16R16.nbt)
Block(-5,33,2,TRAP_DOOR:5)
Block(-5,33,3,IRON_TRAPDOOR:0)
Block(-5,33,6,CONCRETE:7)
Block(-5,33,7,CONCRETE:8)
Block(-5,34,6,CONCRETE:7)
Block(-5,34,7,CONCRETE:8)
Block(-5,35,6,CONCRETE:7)
Block(-5,35,7,CONCRETE:8)
Block(-5,36,6,CONCRETE:7)
Block(-5,36,7,CONCRETE:8)
Block(-5,37,6,CONCRETE:7)
Block(-5,37,7,CONCRETE:8)
Block(-5,38,6,CONCRETE:7)
Block(-5,38,7,CONCRETE:8)
Block(-5,39,6,CONCRETE:7)
Block(-5,39,7,CONCRETE:8)
Block(-5,40,6,CONCRETE:7)
Block(-5,40,7,CONCRETE:8)
Block(-5,41,6,CONCRETE:7)
Block(-5,41,7,CONCRETE:8)
Block(-5,42,-7,STAINED_GLASS:15)
Block(-5,42,-6,STAINED_GLASS:15)
Block(-5,42,-5,STAINED_GLASS:15)
Block(-5,42,-4,STAINED_GLASS:15)
Block(-5,42,-3,CONCRETE:7)
Block(-5,42,-2,STAINED_GLASS:15)
Block(-5,42,-1,STAINED_GLASS:15)
Block(-5,42,0,STAINED_GLASS:15)
Block(-5,42,1,STAINED_GLASS:15)
Block(-5,42,2,STAINED_GLASS:15)
Block(-5,42,3,STAINED_GLASS:15)
Block(-5,42,4,STAINED_GLASS:15)
Block(-5,42,5,STAINED_GLASS:15)
Block(-5,42,6,CONCRETE:7)
Block(-5,42,7,CONCRETE:8)
Block(-5,43,-6,STAINED_GLASS:15)
Block(-5,43,-5,PRISMARINE:2)
Block(-5,43,-4,STAINED_GLASS:15)
Block(-5,43,-1,STAINED_GLASS_PANE:15)
Block(-5,43,7,CONCRETE:8)
Block(-5,44,-6,STAINED_GLASS:15)
Block(-5,44,-5,STATIONARY_WATER:8)
Block(-5,44,-4,STAINED_GLASS:15)
Block(-5,44,-1,STAINED_GLASS_PANE:15)
Block(-5,44,0,WALL_BANNER:4,NBT/skyscraper_2x2_03/402-bannerC16R16.nbt)
Block(-5,44,1,WALL_BANNER:4,NBT/skyscraper_2x2_03/403-bannerC16R16.nbt)
Block(-5,44,2,WALL_BANNER:4,NBT/skyscraper_2x2_03/404-bannerC16R16.nbt)
Block(-5,44,3,WALL_BANNER:4,NBT/skyscraper_2x2_03/405-bannerC16R16.nbt)
Block(-5,44,4,WALL_BANNER:4,NBT/skyscraper_2x2_03/406-bannerC16R16.nbt)
Block(-5,44,5,WALL_BANNER:4,NBT/skyscraper_2x2_03/407-bannerC16R16.nbt)
Block(-5,44,6,WALL_BANNER:4,NBT/skyscraper_2x2_03/408-bannerC16R16.nbt)
Block(-5,44,7,CONCRETE:8)
Block(-5,45,-6,STAINED_GLASS:15)
Block(-5,45,-5,STATIONARY_WATER:8)
Block(-5,45,-4,STAINED_GLASS:15)
Block(-5,45,-1,STAINED_GLASS_PANE:15)
Block(-5,45,7,CONCRETE:8)
Block(-5,46,-6,STAINED_GLASS:15)
Block(-5,46,-5,STATIONARY_WATER:8)
Block(-5,46,-4,STAINED_GLASS:15)
Block(-5,46,-3,CONCRETE:7)
Block(-5,46,-2,STAINED_GLASS:15)
Block(-5,46,-1,STAINED_GLASS:15)
Block(-5,46,0,STAINED_GLASS:15)
Block(-5,46,1,STAINED_GLASS:15)
Block(-5,46,2,STAINED_GLASS:15)
Block(-5,46,3,STAINED_GLASS:15)
Block(-5,46,4,STAINED_GLASS:15)
Block(-5,46,5,STAINED_GLASS:15)
Block(-5,46,6,STAINED_GLASS:15)
Block(-5,46,7,CONCRETE:8)
Block(-5,47,-6,STAINED_GLASS:15)
Block(-5,47,-5,STATIONARY_WATER:0)
Block(-5,47,-4,STAINED_GLASS:15)
Block(-5,47,-2,DARK_OAK_STAIRS:3)
Block(-5,47,-1,STANDING_BANNER:8,NBT/skyscraper_2x2_03/409-bannerC16R16.nbt)
Block(-5,47,2,DARK_OAK_STAIRS:6)
Block(-5,47,3,DARK_OAK_STAIRS:3)
Block(-5,47,6,QUARTZ_STAIRS:4)
Block(-5,47,7,CONCRETE:8)
Block(-5,48,-6,STAINED_GLASS:15)
Block(-5,48,-5,PRISMARINE:2)
Block(-5,48,-4,STAINED_GLASS:15)
Block(-5,48,-2,TRAP_DOOR:5)
Block(-5,48,-1,IRON_TRAPDOOR:2)
Block(-5,48,0,WALL_BANNER:3,NBT/skyscraper_2x2_03/410-bannerC16R16.nbt)
Block(-5,48,1,DARK_OAK_STAIRS:6)
Block(-5,48,2,DARK_OAK_STAIRS:3)
Block(-5,48,7,CONCRETE:8)
Block(-5,49,-6,CONCRETE:7)
Block(-5,49,-5,CONCRETE:7)
Block(-5,49,-4,CONCRETE:8)
Block(-5,49,-3,CONCRETE:8)
Block(-5,49,-2,CONCRETE:8)
Block(-5,49,-1,CONCRETE:7)
Block(-5,49,0,STAINED_GLASS:15)
Block(-5,49,1,DARK_OAK_STAIRS:3)
Block(-5,49,7,CONCRETE:8)
Block(-5,50,-6,CONCRETE:7)
Block(-5,50,-5,IRON_TRAPDOOR:7)
Block(-5,50,-2,CONCRETE:8)
Block(-5,50,-1,CONCRETE:7)
Block(-5,50,7,CONCRETE:8)
Block(-5,51,-6,CONCRETE:7)
Block(-5,51,-2,CONCRETE:8)
Block(-5,51,-1,CONCRETE:7)
Block(-5,51,7,CONCRETE:8)
Block(-5,52,-6,CONCRETE:7)
Block(-5,52,-2,CONCRETE:8)
Block(-5,52,-1,CONCRETE:7)
Block(-5,52,7,CONCRETE:8)
Block(-5,53,-6,CONCRETE:7)
Block(-5,53,-2,CONCRETE:8)
Block(-5,53,-1,CONCRETE:7)
Block(-5,53,6,CONCRETE:7)
Block(-5,53,7,CONCRETE:8)
Block(-5,54,-6,CONCRETE:7)
Block(-5,54,-2,CONCRETE:8)
Block(-5,54,-1,CONCRETE:8)
Block(-5,54,0,CONCRETE:8)
Block(-5,54,1,CONCRETE:8)
Block(-5,54,2,CONCRETE:8)
Block(-5,54,3,CONCRETE:8)
Block(-5,54,4,CONCRETE:8)
Block(-5,54,5,CONCRETE:8)
Block(-5,54,6,CONCRETE:8)
Block(-5,54,7,CONCRETE:8)
Block(-5,55,-6,CONCRETE:7)
Block(-5,55,-2,CONCRETE:8)
Block(-5,55,-1,CONCRETE:8)
Block(-5,55,0,CONCRETE:8)
Block(-5,55,1,CONCRETE:8)
Block(-5,55,2,CONCRETE:8)
Block(-5,55,3,CONCRETE:8)
Block(-5,55,4,CONCRETE:8)
Block(-5,55,5,CONCRETE:8)
Block(-5,55,6,CONCRETE:8)
Block(-5,55,7,CONCRETE:8)
Block(-5,56,-7,CONCRETE:7)
Block(-5,56,-6,CONCRETE:7)
Block(-5,56,-2,CONCRETE:8)
Block(-5,56,-1,CONCRETE:8)
Block(-5,56,0,CONCRETE:8)
Block(-5,56,1,CONCRETE:8)
Block(-5,56,2,CONCRETE:8)
Block(-5,56,3,CONCRETE:8)
Block(-5,56,4,CONCRETE:8)
Block(-5,56,5,CONCRETE:8)
Block(-5,56,6,CONCRETE:8)
Block(-5,56,7,CONCRETE:8)
Block(-5,57,-6,CONCRETE:7)
Block(-5,57,-2,CONCRETE:8)
Block(-5,57,-1,CONCRETE:8)
Block(-5,57,0,CONCRETE:8)
Block(-5,57,1,CONCRETE:8)
Block(-5,57,2,CONCRETE:8)
Block(-5,57,3,CONCRETE:8)
Block(-5,57,4,CONCRETE:8)
Block(-5,57,5,CONCRETE:8)
Block(-5,57,6,CONCRETE:8)
Block(-5,57,7,CONCRETE:8)
Block(-5,58,-6,CONCRETE:7)
Block(-5,59,-6,CONCRETE:7)
Block(-5,60,-6,CONCRETE:7)
Block(-5,61,-7,CONCRETE:7)
Block(-5,61,-6,CONCRETE:7)
Block(-5,61,-5,CONCRETE:7)
Block(-5,61,-4,CONCRETE:7)
Block(-5,61,-3,CONCRETE:7)
Block(-5,61,-2,CONCRETE:7)
Block(-5,61,-1,CONCRETE:7)
Block(-5,61,0,CONCRETE:7)
Block(-5,61,1,CONCRETE:7)
Block(-5,61,2,CONCRETE:7)
Block(-5,61,3,CONCRETE:7)
Block(-5,61,4,CONCRETE:7)
Block(-5,61,5,CONCRETE:7)
Block(-5,61,6,CONCRETE:7)
Block(-5,61,7,STAINED_GLASS:15)
Block(-5,62,-7,CARPET:0)
Block(-5,62,-6,CARPET:0)
Block(-5,62,-5,CARPET:0)
Block(-5,62,-4,CARPET:0)
Block(-5,62,-3,TRAP_DOOR:12)
Block(-5,62,-2,DIRT:2)
Block(-5,62,-1,TRAP_DOOR:13)
Block(-5,62,1,STANDING_BANNER:0,NBT/skyscraper_2x2_03/411-bannerC16R16.nbt)
Block(-5,62,2,DARK_OAK_STAIRS:2)
Block(-5,62,5,STANDING_BANNER:0,NBT/skyscraper_2x2_03/412-bannerC16R16.nbt)
Block(-5,62,6,DARK_OAK_STAIRS:2)
Block(-5,62,7,STAINED_GLASS:15)
Block(-5,63,-2,FLOWER_POT:0,NBT/skyscraper_2x2_03/413-flower_potC16R16.nbt)
Block(-5,63,0,WALL_BANNER:2,NBT/skyscraper_2x2_03/414-bannerC16R16.nbt)
Block(-5,63,1,IRON_TRAPDOOR:3)
Block(-5,63,2,TRAP_DOOR:4)
Block(-5,63,4,WALL_BANNER:2,NBT/skyscraper_2x2_03/415-bannerC16R16.nbt)
Block(-5,63,5,IRON_TRAPDOOR:2)
Block(-5,63,6,TRAP_DOOR:12)
Block(-5,63,7,STAINED_GLASS:15)
Block(-5,64,-2,LEAVES:12)
Block(-5,64,7,STAINED_GLASS:15)
Block(-5,65,7,STAINED_GLASS:15)
Block(-5,66,7,STAINED_GLASS:15)
Block(-5,67,-6,CONCRETE:7)
Block(-5,67,-5,CONCRETE:7)
Block(-5,67,-4,CONCRETE:7)
Block(-5,67,-3,CONCRETE:7)
Block(-5,67,-2,CONCRETE:7)
Block(-5,67,-1,CONCRETE:7)
Block(-5,67,0,CONCRETE:7)
Block(-5,67,1,CONCRETE:7)
Block(-5,67,2,CONCRETE:7)
Block(-5,67,3,CONCRETE:7)
Block(-5,67,4,CONCRETE:7)
Block(-5,67,5,CONCRETE:7)
Block(-5,67,6,CONCRETE:7)
Block(-5,67,7,STAINED_GLASS:15)
Block(-5,68,-6,CONCRETE:7)
Block(-5,68,-5,CONCRETE:8)
Block(-5,68,-4,CONCRETE:8)
Block(-5,68,-3,CONCRETE:8)
Block(-5,68,-2,STAINED_GLASS:15)
Block(-5,68,-1,CONCRETE:7)
Block(-5,68,0,CONCRETE:7)
Block(-5,68,1,CONCRETE:7)
Block(-5,68,2,CONCRETE:7)
Block(-5,68,3,CONCRETE:7)
Block(-5,68,4,CONCRETE:7)
Block(-5,68,5,CONCRETE:7)
Block(-5,68,6,STAINED_GLASS:15)
Block(-5,69,-7,CONCRETE:7)
