
#######################################################################
# +-----------------------------------------------------------------+ #
# |                            BO4 object                           | #
# +-----------------------------------------------------------------+ #
#######################################################################

Author: NLBlackEagle

Description: No description given

SettingsMode: WriteDisable


#######################################################################
# +-----------------------------------------------------------------+ #
# |                          Main settings                          | #
# +-----------------------------------------------------------------+ #
#######################################################################

Frequency: 0

SpawnHeight: highestBlock

UseCenterForHighestBlock: true

##############################
# Height Limits for the BO4. #
##############################

MinHeight: 0

MaxHeight: 255

InheritBO3: 

InheritBO3Rotation: NORTH

OverrideChildSettings: true

OverrideParentHeight: false

CanOverride: true

BranchFrequency: 0

BranchFrequencyGroup: 

MustBeBelowOther: false

MustBeInside: 

CannotBeInside: 

ReplacesBO3: L4-M-CrossC0R0, L4-M-CrossC0R1, L4-M-CrossC0R2, L4-M-CrossC0R3, L4-M-CrossC1R0, L4-M-CrossC1R1, L4-M-CrossC1R2, L4-M-CrossC1R3, L4-M-CrossC2R0, L4-M-CrossC2R1, L4-M-CrossC2R2, L4-M-CrossC2R3, L4-M-CrossC3R0, L4-M-CrossC3R1, L4-M-CrossC3R2, L4-M-CrossC3R3, L4-M-Straigth-START_01-C0R0, L4-M-Straigth-START_01-C0R1, L4-M-Straigth-START_01-C1R0, L4-M-Straigth-START_01-C1R1, L4-M-Straigth-START_01-C2R0, L4-M-Straigth-START_01-C2R1, L4-M-Straigth-START_01-C3R0, L4-M-Straigth-START_01-C3R1, L4-M-Straigth-3CC0R0, L4-M-Straigth-3CC0R1, L4-M-Straigth-3CC0R2, L4-M-Straigth-3CC1R0, L4-M-Straigth-3CC1R1, L4-M-Straigth-3CC1R2, L4-M-Straigth-3CC2R0, L4-M-Straigth-3CC2R1, L4-M-Straigth-3CC2R2, L4-M-Straigth-3CC3R0, L4-M-Straigth-3CC3R1, L4-M-Straigth-3CC3R2, L4-M-Cross, skyscraper_2x2_01, skyscraper_2x2_02, skyscraper_2x2_03, skyscraper_2x2_04, skyscraper_2x2_05, skyscraper_3x3_01, skyscraper_3x3_02, skyscraper_3x3_03, L3-M-Straigth-2CC0R0, L3-M-Straigth-2CC0R1, L3-M-Straigth-2CC1R0, L3-M-Straigth-2CC1R1, L3-M-Straigth-2CC2R0, L3-M-Straigth-2CC2R1, L3-M-Straigth-2CC3R0, L3-M-Straigth-2CC3R1, L3-M-Straigth-3CC0R0, L3-M-Straigth-3CC0R1, L3-M-Straigth-3CC0R2, L3-M-Straigth-3CC1R0, L3-M-Straigth-3CC1R1, L3-M-Straigth-3CC1R2, L3-M-Straigth-3CC2R0, L3-M-Straigth-3CC2R1, L3-M-Straigth-3CC2R2, L3-M-Straigth-3CC3R0, L3-M-Straigth-3CC3R1, L3-M-Straigth-3CC3R2L4-M-CrossC0R0, L4-M-CrossC0R1, L4-M-CrossC0R2, L4-M-CrossC0R3, L4-M-CrossC1R0, L4-M-CrossC1R1, L4-M-CrossC1R2, L4-M-CrossC1R3, L4-M-CrossC2R0, L4-M-CrossC2R1, L4-M-CrossC2R2, L4-M-CrossC2R3, L4-M-CrossC3R0, L4-M-CrossC3R1, L4-M-CrossC3R2, L4-M-CrossC3R3, L4-M-Straigth-START_01-C0R0, L4-M-Straigth-START_01-C0R1, L4-M-Straigth-START_01-C1R0, L4-M-Straigth-START_01-C1R1, L4-M-Straigth-START_01-C2R0, L4-M-Straigth-START_01-C2R1, L4-M-Straigth-START_01-C3R0, L4-M-Straigth-START_01-C3R1, L4-M-Straigth-3CC0R0, L4-M-Straigth-3CC0R1, L4-M-Straigth-3CC0R2, L4-M-Straigth-3CC1R0, L4-M-Straigth-3CC1R1, L4-M-Straigth-3CC1R2, L4-M-Straigth-3CC2R0, L4-M-Straigth-3CC2R1, L4-M-Straigth-3

MustBeInsideWorldBorders: false

CanSpawnOnWater: true

SpawnOnWaterOnly: false

SpawnUnderWater: false

SpawnAtWaterLevel: false

HeightOffset: 0

RemoveAir: false

ReplaceAbove: 

ReplaceBelow: 

ReplaceWithBiomeBlocks: true

ReplaceWithSurfaceBlock: GRASS

ReplaceWithGroundBlock: DIRT

ReplaceWithStoneBlock: STONE

SmoothRadius: 0

SmoothHeightOffset: 0

SmoothStartTop: false

SmoothStartWood: false

SmoothingSurfaceBlock: 

SmoothingGroundBlock: 

BO3Group: 

IsSpawnPoint: false

DoReplaceBlocks: true


#######################################################################
# +-----------------------------------------------------------------+ #
# |                              Blocks                             | #
# +-----------------------------------------------------------------+ #
#######################################################################

Block(-8,0,-7,CONCRETE:7)
Block(-8,0,-6,CONCRETE:7)
Block(-8,0,-5,CONCRETE:7)
Block(-8,0,-4,CONCRETE:7)
Block(-8,0,-3,CONCRETE:7)
Block(-8,0,-2,CONCRETE:7)
Block(-8,0,-1,CONCRETE:7)
Block(-8,0,0,CONCRETE:7)
Block(-8,0,1,CONCRETE:7)
Block(-8,0,2,CONCRETE:7)
Block(-8,0,3,CONCRETE:7)
Block(-8,0,4,CONCRETE:7)
Block(-8,0,5,CONCRETE:7)
Block(-8,0,6,CONCRETE:7)
Block(-8,0,7,CONCRETE:7)
Block(-8,0,8,CONCRETE:7)
Block(-8,1,-7,CONCRETE:7)
Block(-8,1,-6,CONCRETE:7)
Block(-8,1,-5,CONCRETE:7)
Block(-8,1,-4,CONCRETE:7)
Block(-8,1,-3,CONCRETE:7)
Block(-8,1,-2,CONCRETE:7)
Block(-8,1,-1,CONCRETE:7)
Block(-8,1,0,CONCRETE:7)
Block(-8,1,1,CONCRETE:7)
Block(-8,1,2,CONCRETE:7)
Block(-8,1,3,CONCRETE:7)
Block(-8,1,4,CONCRETE:7)
Block(-8,1,5,CONCRETE:7)
Block(-8,1,6,CONCRETE:7)
Block(-8,1,7,CONCRETE:7)
Block(-8,1,8,CONCRETE:7)
Block(-8,2,-7,CONCRETE:7)
Block(-8,2,-6,CONCRETE:7)
Block(-8,2,-5,CONCRETE:7)
Block(-8,2,-4,CONCRETE:7)
Block(-8,2,-3,CONCRETE:7)
Block(-8,2,-2,CONCRETE:7)
Block(-8,2,-1,CONCRETE:7)
Block(-8,2,0,CONCRETE:7)
Block(-8,2,1,CONCRETE:7)
Block(-8,2,2,CONCRETE:7)
Block(-8,2,3,CONCRETE:7)
Block(-8,2,4,CONCRETE:7)
Block(-8,2,5,CONCRETE:7)
Block(-8,2,6,CONCRETE:7)
Block(-8,2,7,CONCRETE:7)
Block(-8,2,8,CONCRETE:7)
Block(-8,3,-7,CONCRETE:7)
Block(-8,3,-6,CONCRETE:7)
Block(-8,3,-5,CONCRETE:7)
Block(-8,3,-4,CONCRETE:7)
Block(-8,3,-3,CONCRETE:7)
Block(-8,3,-2,CONCRETE:7)
Block(-8,3,-1,CONCRETE:7)
Block(-8,3,0,CONCRETE:7)
Block(-8,3,1,CONCRETE:7)
Block(-8,3,2,CONCRETE:7)
Block(-8,3,3,CONCRETE:7)
Block(-8,3,4,CONCRETE:7)
Block(-8,3,5,CONCRETE:7)
Block(-8,3,6,CONCRETE:7)
Block(-8,3,7,CONCRETE:7)
Block(-8,3,8,CONCRETE:7)
Block(-8,4,-7,CONCRETE:7)
Block(-8,4,-6,CONCRETE:7)
Block(-8,4,-5,CONCRETE:7)
Block(-8,4,-4,CONCRETE:7)
Block(-8,4,-3,CONCRETE:7)
Block(-8,4,-2,CONCRETE:7)
Block(-8,4,-1,CONCRETE:7)
Block(-8,4,0,CONCRETE:7)
Block(-8,4,1,CONCRETE:7)
Block(-8,4,2,CONCRETE:7)
Block(-8,4,3,CONCRETE:7)
Block(-8,4,4,CONCRETE:7)
Block(-8,4,5,CONCRETE:7)
Block(-8,4,6,CONCRETE:7)
Block(-8,4,7,CONCRETE:7)
Block(-8,4,8,CONCRETE:7)
Block(-8,5,-7,CONCRETE:7)
Block(-8,5,-6,CONCRETE:7)
Block(-8,5,-5,CONCRETE:7)
Block(-8,5,-4,CONCRETE:7)
Block(-8,5,-3,CONCRETE:7)
Block(-8,5,-2,CONCRETE:7)
Block(-8,5,-1,CONCRETE:7)
Block(-8,5,0,CONCRETE:7)
Block(-8,5,1,CONCRETE:7)
Block(-8,5,2,CONCRETE:7)
Block(-8,5,3,CONCRETE:7)
Block(-8,5,4,CONCRETE:7)
Block(-8,5,5,CONCRETE:7)
Block(-8,5,6,CONCRETE:7)
Block(-8,5,7,CONCRETE:7)
Block(-8,5,8,CONCRETE:7)
Block(-8,6,-7,CONCRETE:7)
Block(-8,6,-6,CONCRETE:7)
Block(-8,6,-5,CONCRETE:7)
Block(-8,6,-4,CONCRETE:7)
Block(-8,6,-3,CONCRETE:7)
Block(-8,6,-2,CONCRETE:7)
Block(-8,6,-1,CONCRETE:7)
Block(-8,6,0,CONCRETE:7)
Block(-8,6,1,CONCRETE:7)
Block(-8,6,2,CONCRETE:7)
Block(-8,6,3,CONCRETE:7)
Block(-8,6,4,CONCRETE:7)
Block(-8,6,5,CONCRETE:7)
Block(-8,6,6,CONCRETE:7)
Block(-8,6,7,CONCRETE:7)
Block(-8,6,8,CONCRETE:7)
Block(-8,7,-7,CONCRETE:7)
Block(-8,7,-6,CONCRETE:7)
Block(-8,7,-5,CONCRETE:7)
Block(-8,7,-4,CONCRETE:7)
Block(-8,7,-3,CONCRETE:7)
Block(-8,7,-2,CONCRETE:7)
Block(-8,7,-1,CONCRETE:7)
Block(-8,7,0,CONCRETE:7)
Block(-8,7,1,CONCRETE:7)
Block(-8,7,2,CONCRETE:7)
Block(-8,7,3,CONCRETE:7)
Block(-8,7,4,CONCRETE:7)
Block(-8,7,5,CONCRETE:7)
Block(-8,7,6,CONCRETE:7)
Block(-8,7,7,CONCRETE:7)
Block(-8,7,8,CONCRETE:7)
Block(-8,8,-7,CONCRETE:7)
Block(-8,8,-6,CONCRETE:7)
Block(-8,8,-5,CONCRETE:7)
Block(-8,8,-4,CONCRETE:7)
Block(-8,8,-3,CONCRETE:7)
Block(-8,8,-2,CONCRETE:7)
Block(-8,8,-1,CONCRETE:7)
Block(-8,8,0,CONCRETE:7)
Block(-8,8,1,CONCRETE:7)
Block(-8,8,2,CONCRETE:7)
Block(-8,8,3,CONCRETE:7)
Block(-8,8,4,CONCRETE:7)
Block(-8,8,5,CONCRETE:7)
Block(-8,8,6,CONCRETE:7)
Block(-8,8,7,CONCRETE:7)
Block(-8,8,8,CONCRETE:7)
Block(-8,9,-7,CONCRETE:7)
Block(-8,9,-6,CONCRETE:7)
Block(-8,9,-5,CONCRETE:7)
Block(-8,9,-4,CONCRETE:7)
Block(-8,9,-3,CONCRETE:7)
Block(-8,9,-2,CONCRETE:7)
Block(-8,9,-1,CONCRETE:7)
Block(-8,9,0,CONCRETE:7)
Block(-8,9,1,CONCRETE:7)
Block(-8,9,2,CONCRETE:7)
Block(-8,9,3,CONCRETE:7)
Block(-8,9,4,CONCRETE:7)
Block(-8,9,5,CONCRETE:7)
Block(-8,9,6,CONCRETE:7)
Block(-8,9,7,CONCRETE:7)
Block(-8,9,8,CONCRETE:7)
Block(-8,10,-7,CONCRETE:7)
Block(-8,10,-6,CONCRETE:7)
Block(-8,10,-5,CONCRETE:7)
Block(-8,10,-4,CONCRETE:7)
Block(-8,10,-3,CONCRETE:7)
Block(-8,10,-2,CONCRETE:7)
Block(-8,10,-1,CONCRETE:7)
Block(-8,10,0,CONCRETE:7)
Block(-8,10,1,CONCRETE:7)
Block(-8,10,2,CONCRETE:7)
Block(-8,10,3,CONCRETE:7)
Block(-8,10,4,CONCRETE:7)
Block(-8,10,5,CONCRETE:7)
Block(-8,10,6,CONCRETE:7)
Block(-8,10,7,CONCRETE:7)
Block(-8,10,8,CONCRETE:7)
Block(-8,11,-7,CONCRETE:7)
Block(-8,11,-6,CONCRETE:7)
Block(-8,11,-5,CONCRETE:7)
Block(-8,11,-4,CONCRETE:7)
Block(-8,11,-3,CONCRETE:7)
Block(-8,11,-2,CONCRETE:7)
Block(-8,11,-1,CONCRETE:7)
Block(-8,11,0,CONCRETE:7)
Block(-8,11,1,CONCRETE:7)
Block(-8,11,2,CONCRETE:7)
Block(-8,11,3,CONCRETE:7)
Block(-8,11,4,CONCRETE:7)
Block(-8,11,5,CONCRETE:7)
Block(-8,11,6,CONCRETE:7)
Block(-8,11,7,CONCRETE:7)
Block(-8,11,8,CONCRETE:7)
Block(-8,12,-7,CONCRETE:7)
Block(-8,12,-6,CONCRETE:7)
Block(-8,12,-5,CONCRETE:7)
Block(-8,12,-4,CONCRETE:7)
Block(-8,12,-3,CONCRETE:7)
Block(-8,12,-2,CONCRETE:7)
Block(-8,12,-1,CONCRETE:7)
Block(-8,12,0,CONCRETE:7)
Block(-8,12,1,CONCRETE:7)
Block(-8,12,2,CONCRETE:7)
Block(-8,12,3,CONCRETE:7)
Block(-8,12,4,CONCRETE:7)
Block(-8,12,5,CONCRETE:7)
Block(-8,12,6,CONCRETE:7)
Block(-8,12,7,CONCRETE:7)
Block(-8,12,8,CONCRETE:7)
Block(-8,13,-7,CONCRETE:7)
Block(-8,13,-6,CONCRETE:7)
Block(-8,13,-5,CONCRETE:7)
Block(-8,13,-4,CONCRETE:7)
Block(-8,13,-3,CONCRETE:7)
Block(-8,13,-2,CONCRETE:7)
Block(-8,13,-1,CONCRETE:7)
Block(-8,13,0,CONCRETE:7)
Block(-8,13,1,CONCRETE:7)
Block(-8,13,2,CONCRETE:7)
Block(-8,13,3,CONCRETE:7)
Block(-8,13,4,CONCRETE:7)
Block(-8,13,5,CONCRETE:7)
Block(-8,13,6,CONCRETE:7)
Block(-8,13,7,CONCRETE:7)
Block(-8,13,8,CONCRETE:7)
Block(-8,14,-7,CONCRETE:7)
Block(-8,14,-6,CONCRETE:7)
Block(-8,14,-5,CONCRETE:7)
Block(-8,14,-4,CONCRETE:7)
Block(-8,14,-3,CONCRETE:7)
Block(-8,14,-2,CONCRETE:7)
Block(-8,14,-1,CONCRETE:7)
Block(-8,14,0,CONCRETE:7)
Block(-8,14,1,CONCRETE:7)
Block(-8,14,2,CONCRETE:7)
Block(-8,14,3,CONCRETE:7)
Block(-8,14,4,CONCRETE:7)
Block(-8,14,5,CONCRETE:7)
Block(-8,14,6,CONCRETE:7)
Block(-8,14,7,CONCRETE:7)
Block(-8,14,8,CONCRETE:7)
Block(-8,15,-7,CONCRETE:7)
Block(-8,15,-6,CONCRETE:7)
Block(-8,15,-5,CONCRETE:7)
Block(-8,15,-4,CONCRETE:7)
Block(-8,15,-3,CONCRETE:7)
Block(-8,15,-2,CONCRETE:7)
Block(-8,15,-1,CONCRETE:7)
Block(-8,15,0,CONCRETE:7)
Block(-8,15,1,CONCRETE:7)
Block(-8,15,2,CONCRETE:7)
Block(-8,15,3,CONCRETE:7)
Block(-8,15,4,CONCRETE:7)
Block(-8,15,5,CONCRETE:7)
Block(-8,15,6,CONCRETE:7)
Block(-8,15,7,CONCRETE:7)
Block(-8,15,8,CONCRETE:7)
Block(-8,16,-7,CONCRETE:7)
Block(-8,16,-6,CONCRETE:7)
Block(-8,16,-5,CONCRETE:7)
Block(-8,16,-4,CONCRETE:7)
Block(-8,16,-3,CONCRETE:7)
Block(-8,16,-2,CONCRETE:7)
Block(-8,16,-1,CONCRETE:7)
Block(-8,16,0,CONCRETE:7)
Block(-8,16,1,CONCRETE:7)
Block(-8,16,2,CONCRETE:7)
Block(-8,16,3,CONCRETE:7)
Block(-8,16,4,CONCRETE:7)
Block(-8,16,5,CONCRETE:7)
Block(-8,16,6,CONCRETE:7)
Block(-8,16,7,CONCRETE:7)
Block(-8,16,8,CONCRETE:7)
Block(-8,17,-7,CONCRETE:7)
Block(-8,17,-6,CONCRETE:7)
Block(-8,17,-5,CONCRETE:7)
Block(-8,17,-4,CONCRETE:7)
Block(-8,17,-3,CONCRETE:7)
Block(-8,17,-2,CONCRETE:7)
Block(-8,17,-1,CONCRETE:7)
Block(-8,17,0,CONCRETE:7)
Block(-8,17,1,CONCRETE:7)
Block(-8,17,2,CONCRETE:7)
Block(-8,17,3,CONCRETE:7)
Block(-8,17,4,CONCRETE:7)
Block(-8,17,5,CONCRETE:7)
Block(-8,17,6,CONCRETE:7)
Block(-8,17,7,CONCRETE:7)
Block(-8,17,8,CONCRETE:7)
Block(-8,18,-7,CONCRETE:8)
Block(-8,18,-6,CONCRETE:8)
Block(-8,18,-5,CONCRETE:8)
Block(-8,18,-4,CONCRETE:8)
Block(-8,18,-3,CONCRETE:8)
Block(-8,18,-2,CONCRETE:8)
Block(-8,19,-7,CONCRETE:15)
Block(-8,19,-6,CONCRETE:8)
Block(-8,19,-5,CONCRETE:8)
Block(-8,19,-4,CONCRETE:8)
Block(-8,19,-3,CONCRETE:15)
Block(-8,19,-2,CONCRETE:8)
Block(-8,20,-7,CONCRETE:15)
Block(-8,20,-6,CONCRETE:8)
Block(-8,20,-5,CONCRETE:8)
Block(-8,20,-4,CONCRETE:8)
Block(-8,20,-3,CONCRETE:15)
Block(-8,20,-2,CONCRETE:8)
Block(-8,21,-7,CONCRETE:15)
Block(-8,21,-6,CONCRETE:8)
Block(-8,21,-5,CONCRETE:8)
Block(-8,21,-4,CONCRETE:8)
Block(-8,21,-3,CONCRETE:15)
Block(-8,21,-2,CONCRETE:8)
Block(-8,22,-7,CONCRETE:8)
Block(-8,22,-6,CONCRETE:8)
Block(-8,22,-5,CONCRETE:8)
Block(-8,22,-4,CONCRETE:8)
Block(-8,22,-3,CONCRETE:15)
Block(-8,22,-2,CONCRETE:8)
Block(-8,23,-7,CONCRETE:8)
Block(-8,23,-6,CONCRETE:8)
Block(-8,23,-5,CONCRETE:8)
Block(-8,23,-4,CONCRETE:8)
Block(-8,23,-3,CONCRETE:15)
Block(-8,23,-2,CONCRETE:8)
Block(-8,24,-7,CONCRETE:15)
Block(-8,24,-6,CONCRETE:15)
Block(-8,24,-5,CONCRETE:15)
Block(-8,24,-4,CONCRETE:15)
Block(-8,24,-3,CONCRETE:15)
Block(-8,24,-2,CONCRETE:8)
Block(-8,25,-7,CONCRETE:8)
Block(-8,25,-6,CONCRETE:8)
Block(-8,25,-5,CONCRETE:8)
Block(-8,25,-4,CONCRETE:8)
Block(-8,25,-3,CONCRETE:8)
Block(-8,25,-2,CONCRETE:8)
Block(-8,26,-7,CONCRETE:8)
Block(-8,26,-6,CONCRETE:8)
Block(-8,26,-5,CONCRETE:8)
Block(-8,26,-4,CONCRETE:8)
Block(-8,26,-3,CONCRETE:8)
Block(-8,26,-2,CONCRETE:8)
Block(-8,27,-7,CONCRETE:15)
Block(-8,27,-6,CONCRETE:15)
Block(-8,27,-5,CONCRETE:15)
Block(-8,27,-4,CONCRETE:15)
Block(-8,27,-3,CONCRETE:15)
Block(-8,27,-2,CONCRETE:8)
Block(-8,28,-7,CONCRETE:15)
Block(-8,28,-6,CONCRETE:8)
Block(-8,28,-5,CONCRETE:8)
Block(-8,28,-4,CONCRETE:8)
Block(-8,28,-3,CONCRETE:8)
Block(-8,28,-2,CONCRETE:8)
Block(-8,29,-7,CONCRETE:15)
Block(-8,29,-6,CONCRETE:8)
Block(-8,29,-5,CONCRETE:8)
Block(-8,29,-4,CONCRETE:8)
Block(-8,29,-3,CONCRETE:8)
Block(-8,29,-2,CONCRETE:8)
Block(-8,30,-7,CONCRETE:15)
Block(-8,30,-6,CONCRETE:8)
Block(-8,30,-5,CONCRETE:8)
Block(-8,30,-4,CONCRETE:8)
Block(-8,30,-3,CONCRETE:8)
Block(-8,30,-2,CONCRETE:8)
Block(-8,31,-7,CONCRETE:15)
Block(-8,31,-6,CONCRETE:8)
Block(-8,31,-5,CONCRETE:15)
Block(-8,31,-4,CONCRETE:15)
Block(-8,31,-3,CONCRETE:15)
Block(-8,31,-2,CONCRETE:8)
Block(-8,32,-7,CONCRETE:15)
Block(-8,32,-6,CONCRETE:8)
Block(-8,32,-5,CONCRETE:15)
Block(-8,32,-4,CONCRETE:8)
Block(-8,32,-3,CONCRETE:8)
Block(-8,32,-2,CONCRETE:8)
Block(-8,33,-7,CONCRETE:8)
Block(-8,33,-6,CONCRETE:8)
Block(-8,33,-5,CONCRETE:15)
Block(-8,33,-4,CONCRETE:8)
Block(-8,33,-3,CONCRETE:8)
Block(-8,33,-2,CONCRETE:8)
Block(-8,34,-7,CONCRETE:8)
Block(-8,34,-6,CONCRETE:8)
Block(-8,34,-5,CONCRETE:15)
Block(-8,34,-4,CONCRETE:8)
Block(-8,34,-3,CONCRETE:8)
Block(-8,34,-2,CONCRETE:8)
Block(-8,35,-7,CONCRETE:8)
Block(-8,35,-6,CONCRETE:8)
Block(-8,35,-5,CONCRETE:15)
Block(-8,35,-4,CONCRETE:8)
Block(-8,35,-3,CONCRETE:8)
Block(-8,35,-2,CONCRETE:8)
Block(-8,36,-7,CONCRETE:8)
Block(-8,36,-6,CONCRETE:8)
Block(-8,36,-5,CONCRETE:15)
Block(-8,36,-4,CONCRETE:8)
Block(-8,36,-3,CONCRETE:8)
Block(-8,36,-2,CONCRETE:8)
Block(-8,37,-7,CONCRETE:8)
Block(-8,37,-6,CONCRETE:8)
Block(-8,37,-5,CONCRETE:15)
Block(-8,37,-4,CONCRETE:8)
Block(-8,37,-3,CONCRETE:8)
Block(-8,37,-2,CONCRETE:8)
Block(-8,38,-7,CONCRETE:15)
Block(-8,38,-6,CONCRETE:8)
Block(-8,38,-5,CONCRETE:15)
Block(-8,38,-4,CONCRETE:8)
Block(-8,38,-3,CONCRETE:8)
Block(-8,38,-2,CONCRETE:8)
Block(-8,39,-7,CONCRETE:15)
Block(-8,39,-6,CONCRETE:8)
Block(-8,39,-5,CONCRETE:15)
Block(-8,39,-4,CONCRETE:8)
Block(-8,39,-3,CONCRETE:8)
Block(-8,39,-2,CONCRETE:8)
Block(-8,40,-7,CONCRETE:15)
Block(-8,40,-6,CONCRETE:8)
Block(-8,40,-5,CONCRETE:15)
Block(-8,40,-4,CONCRETE:8)
Block(-8,40,-3,CONCRETE:8)
Block(-8,40,-2,CONCRETE:8)
Block(-8,41,-7,CONCRETE:15)
Block(-8,41,-6,CONCRETE:8)
Block(-8,41,-5,CONCRETE:15)
Block(-8,41,-4,CONCRETE:8)
Block(-8,41,-3,CONCRETE:8)
Block(-8,41,-2,CONCRETE:8)
Block(-8,42,-7,CONCRETE:15)
Block(-8,42,-6,CONCRETE:8)
Block(-8,42,-5,CONCRETE:15)
Block(-8,42,-4,CONCRETE:8)
Block(-8,42,-3,CONCRETE:8)
Block(-8,42,-2,CONCRETE:8)
Block(-8,43,-7,CONCRETE:15)
Block(-8,43,-6,CONCRETE:8)
Block(-8,43,-5,CONCRETE:15)
Block(-8,43,-4,CONCRETE:8)
Block(-8,43,-3,CONCRETE:8)
Block(-8,43,-2,CONCRETE:8)
Block(-8,44,-7,CONCRETE:15)
Block(-8,44,-6,CONCRETE:8)
Block(-8,44,-5,CONCRETE:15)
Block(-8,44,-4,CONCRETE:8)
Block(-8,44,-3,CONCRETE:8)
Block(-8,44,-2,CONCRETE:8)
Block(-8,45,-7,CONCRETE:15)
Block(-8,45,-6,CONCRETE:8)
Block(-8,45,-5,CONCRETE:8)
Block(-8,45,-4,CONCRETE:8)
Block(-8,45,-3,CONCRETE:15)
Block(-8,45,-2,CONCRETE:8)
Block(-8,46,-7,CONCRETE:15)
Block(-8,46,-6,CONCRETE:8)
Block(-8,46,-5,CONCRETE:8)
Block(-8,46,-4,CONCRETE:8)
Block(-8,46,-3,CONCRETE:15)
Block(-8,46,-2,CONCRETE:8)
Block(-8,47,-7,CONCRETE:15)
Block(-8,47,-6,CONCRETE:15)
Block(-8,47,-5,CONCRETE:15)
Block(-8,47,-4,CONCRETE:15)
Block(-8,47,-3,CONCRETE:15)
Block(-8,47,-2,CONCRETE:8)
Block(-8,48,-7,CONCRETE:8)
Block(-8,48,-6,CONCRETE:8)
Block(-8,48,-5,CONCRETE:8)
Block(-8,48,-4,CONCRETE:8)
Block(-8,48,-3,CONCRETE:8)
Block(-8,48,-2,CONCRETE:8)
Block(-8,49,-7,CONCRETE:8)
Block(-8,49,-6,CONCRETE:8)
Block(-8,49,-5,CONCRETE:15)
Block(-8,49,-4,CONCRETE:15)
Block(-8,49,-3,CONCRETE:15)
Block(-8,49,-2,CONCRETE:8)
Block(-8,50,-7,CONCRETE:8)
Block(-8,50,-6,CONCRETE:8)
Block(-8,50,-5,CONCRETE:15)
Block(-8,50,-4,CONCRETE:8)
Block(-8,50,-3,CONCRETE:15)
Block(-8,50,-2,CONCRETE:8)
Block(-8,51,-7,CONCRETE:15)
Block(-8,51,-6,CONCRETE:8)
Block(-8,51,-5,CONCRETE:15)
Block(-8,51,-4,CONCRETE:8)
Block(-8,51,-3,CONCRETE:15)
Block(-8,51,-2,CONCRETE:8)
Block(-8,52,-7,CONCRETE:8)
Block(-8,52,-6,CONCRETE:8)
Block(-8,52,-5,CONCRETE:15)
Block(-8,52,-4,CONCRETE:8)
Block(-8,52,-3,CONCRETE:15)
Block(-8,52,-2,CONCRETE:8)
Block(-8,53,-7,CONCRETE:8)
Block(-8,53,-6,CONCRETE:8)
Block(-8,53,-5,CONCRETE:15)
Block(-8,53,-4,CONCRETE:8)
Block(-8,53,-3,CONCRETE:15)
Block(-8,53,-2,CONCRETE:8)
Block(-8,54,-7,CONCRETE:15)
Block(-8,54,-6,CONCRETE:8)
Block(-8,54,-5,CONCRETE:15)
Block(-8,54,-4,CONCRETE:8)
Block(-8,54,-3,CONCRETE:8)
Block(-8,54,-2,CONCRETE:8)
Block(-8,55,-7,CONCRETE:15)
Block(-8,55,-6,CONCRETE:8)
Block(-8,55,-5,CONCRETE:15)
Block(-8,55,-4,CONCRETE:8)
Block(-8,55,-3,CONCRETE:8)
Block(-8,55,-2,CONCRETE:8)
Block(-8,56,-7,CONCRETE:15)
Block(-8,56,-6,CONCRETE:8)
Block(-8,56,-5,CONCRETE:15)
Block(-8,56,-4,CONCRETE:8)
Block(-8,56,-3,CONCRETE:8)
Block(-8,56,-2,CONCRETE:8)
Block(-8,57,-7,CONCRETE:15)
Block(-8,57,-6,CONCRETE:8)
Block(-8,57,-5,CONCRETE:15)
Block(-8,57,-4,CONCRETE:8)
Block(-8,57,-3,CONCRETE:8)
Block(-8,57,-2,CONCRETE:8)
Block(-8,58,-7,CONCRETE:15)
Block(-8,58,-6,CONCRETE:8)
Block(-8,58,-5,CONCRETE:15)
Block(-8,58,-4,CONCRETE:8)
Block(-8,58,-3,CONCRETE:8)
Block(-8,58,-2,CONCRETE:8)
Block(-8,59,-7,CONCRETE:15)
Block(-8,59,-6,CONCRETE:8)
Block(-8,59,-5,CONCRETE:15)
Block(-8,59,-4,CONCRETE:8)
Block(-8,59,-3,CONCRETE:8)
Block(-8,59,-2,CONCRETE:8)
Block(-8,60,-7,CONCRETE:15)
Block(-8,60,-6,CONCRETE:8)
Block(-8,60,-5,CONCRETE:15)
Block(-8,60,-4,CONCRETE:8)
Block(-8,60,-3,CONCRETE:15)
Block(-8,60,-2,CONCRETE:8)
Block(-8,61,-7,CONCRETE:15)
Block(-8,61,-6,CONCRETE:8)
Block(-8,61,-5,CONCRETE:15)
Block(-8,61,-4,CONCRETE:8)
Block(-8,61,-3,CONCRETE:15)
Block(-8,61,-2,CONCRETE:8)
Block(-8,62,-7,CONCRETE:15)
Block(-8,62,-6,CONCRETE:8)
Block(-8,62,-5,CONCRETE:15)
Block(-8,62,-4,CONCRETE:8)
Block(-8,62,-3,CONCRETE:15)
Block(-8,62,-2,CONCRETE:8)
Block(-8,63,-7,CONCRETE:15)
Block(-8,63,-6,CONCRETE:8)
Block(-8,63,-5,CONCRETE:15)
Block(-8,63,-4,CONCRETE:8)
Block(-8,63,-3,CONCRETE:15)
Block(-8,63,-2,CONCRETE:8)
Block(-8,64,-7,CONCRETE:15)
Block(-8,64,-6,CONCRETE:8)
Block(-8,64,-5,CONCRETE:15)
Block(-8,64,-4,CONCRETE:8)
Block(-8,64,-3,CONCRETE:15)
Block(-8,64,-2,CONCRETE:8)
Block(-8,65,-7,CONCRETE:8)
Block(-8,65,-6,CONCRETE:8)
Block(-8,65,-5,CONCRETE:8)
Block(-8,65,-4,CONCRETE:8)
Block(-8,65,-3,CONCRETE:15)
Block(-8,65,-2,CONCRETE:8)
Block(-8,66,-7,CONCRETE:8)
Block(-8,66,-6,CONCRETE:8)
Block(-8,66,-5,CONCRETE:8)
Block(-8,66,-4,CONCRETE:8)
Block(-8,66,-3,CONCRETE:15)
Block(-8,66,-2,CONCRETE:8)
Block(-8,67,-7,CONCRETE:15)
Block(-8,67,-6,CONCRETE:15)
Block(-8,67,-5,CONCRETE:15)
Block(-8,67,-4,CONCRETE:8)
Block(-8,67,-3,CONCRETE:15)
Block(-8,67,-2,CONCRETE:8)
Block(-8,68,-7,CONCRETE:8)
Block(-8,68,-6,CONCRETE:8)
Block(-8,68,-5,CONCRETE:15)
Block(-8,68,-4,CONCRETE:8)
Block(-8,68,-3,CONCRETE:15)
Block(-8,68,-2,CONCRETE:8)
Block(-8,69,-7,CONCRETE:8)
Block(-8,69,-6,CONCRETE:8)
Block(-8,69,-5,CONCRETE:15)
Block(-8,69,-4,CONCRETE:8)
Block(-8,69,-3,CONCRETE:15)
Block(-8,69,-2,CONCRETE:8)
Block(-8,70,-7,CONCRETE:15)
Block(-8,70,-6,CONCRETE:8)
Block(-8,70,-5,CONCRETE:15)
Block(-8,70,-4,CONCRETE:8)
Block(-8,70,-3,CONCRETE:15)
Block(-8,70,-2,CONCRETE:8)
Block(-8,71,-7,CONCRETE:15)
Block(-8,71,-6,CONCRETE:8)
Block(-8,71,-5,CONCRETE:15)
Block(-8,71,-4,CONCRETE:8)
Block(-8,71,-3,CONCRETE:15)
Block(-8,71,-2,CONCRETE:8)
Block(-8,72,-7,CONCRETE:15)
Block(-8,72,-6,CONCRETE:8)
Block(-8,72,-5,CONCRETE:8)
Block(-8,72,-4,CONCRETE:8)
Block(-8,72,-3,CONCRETE:15)
Block(-8,72,-2,CONCRETE:8)
Block(-8,73,-7,CONCRETE:15)
Block(-8,73,-6,CONCRETE:8)
Block(-8,73,-5,CONCRETE:8)
Block(-8,73,-4,CONCRETE:8)
Block(-8,73,-3,CONCRETE:15)
Block(-8,73,-2,CONCRETE:8)
Block(-8,74,-7,CONCRETE:15)
Block(-8,74,-6,CONCRETE:8)
Block(-8,74,-5,CONCRETE:8)
Block(-8,74,-4,CONCRETE:8)
Block(-8,74,-3,CONCRETE:15)
Block(-8,74,-2,CONCRETE:8)
Block(-8,75,-7,CONCRETE:15)
Block(-8,75,-6,CONCRETE:8)
Block(-8,75,-5,CONCRETE:15)
Block(-8,75,-4,CONCRETE:15)
Block(-8,75,-3,CONCRETE:15)
Block(-8,75,-2,CONCRETE:8)
Block(-8,76,-7,CONCRETE:15)
Block(-8,76,-6,CONCRETE:8)
Block(-8,76,-5,CONCRETE:8)
Block(-8,76,-4,CONCRETE:8)
Block(-8,76,-3,CONCRETE:8)
Block(-8,76,-2,CONCRETE:8)
Block(-8,77,-7,CONCRETE:15)
Block(-8,77,-6,CONCRETE:15)
Block(-8,77,-5,CONCRETE:15)
Block(-8,77,-4,CONCRETE:15)
Block(-8,77,-3,CONCRETE:8)
Block(-8,77,-2,CONCRETE:8)
Block(-8,78,-7,CONCRETE:8)
Block(-8,78,-6,CONCRETE:8)
Block(-8,78,-5,CONCRETE:8)
Block(-8,78,-4,CONCRETE:15)
Block(-8,78,-3,CONCRETE:8)
Block(-8,78,-2,CONCRETE:8)
Block(-8,79,-7,CONCRETE:15)
Block(-8,79,-6,CONCRETE:8)
Block(-8,79,-5,CONCRETE:8)
Block(-8,79,-4,CONCRETE:15)
Block(-8,79,-3,CONCRETE:8)
Block(-8,79,-2,CONCRETE:8)
Block(-8,80,-7,CONCRETE:15)
Block(-8,80,-6,CONCRETE:8)
Block(-8,80,-5,CONCRETE:8)
Block(-8,80,-4,CONCRETE:15)
Block(-8,80,-3,CONCRETE:8)
Block(-8,80,-2,CONCRETE:8)
Block(-8,81,-7,CONCRETE:15)
Block(-8,81,-6,CONCRETE:8)
Block(-8,81,-5,CONCRETE:8)
Block(-8,81,-4,CONCRETE:15)
Block(-8,81,-3,CONCRETE:8)
Block(-8,81,-2,CONCRETE:8)
Block(-8,82,-7,CONCRETE:15)
Block(-8,82,-6,CONCRETE:8)
Block(-8,82,-5,CONCRETE:8)
Block(-8,82,-4,CONCRETE:15)
Block(-8,82,-3,CONCRETE:8)
Block(-8,82,-2,CONCRETE:8)
Block(-8,83,-7,CONCRETE:15)
Block(-8,83,-6,CONCRETE:8)
Block(-8,83,-5,CONCRETE:8)
Block(-8,83,-4,CONCRETE:8)
Block(-8,83,-3,CONCRETE:8)
Block(-8,83,-2,CONCRETE:8)
Block(-8,84,-7,CONCRETE:15)
Block(-8,84,-6,CONCRETE:8)
Block(-8,84,-5,CONCRETE:8)
Block(-8,84,-4,CONCRETE:8)
Block(-8,84,-3,CONCRETE:8)
Block(-8,84,-2,CONCRETE:8)
Block(-8,85,-7,CONCRETE:15)
Block(-8,85,-6,CONCRETE:8)
Block(-8,85,-5,CONCRETE:15)
Block(-8,85,-4,CONCRETE:15)
Block(-8,85,-3,CONCRETE:15)
Block(-8,85,-2,CONCRETE:8)
Block(-8,86,-7,CONCRETE:15)
Block(-8,86,-6,CONCRETE:8)
Block(-8,86,-5,CONCRETE:15)
Block(-8,86,-4,CONCRETE:8)
Block(-8,86,-3,CONCRETE:15)
Block(-8,86,-2,CONCRETE:8)
Block(-8,87,-7,CONCRETE:15)
Block(-8,87,-6,CONCRETE:8)
Block(-8,87,-5,CONCRETE:8)
Block(-8,87,-4,CONCRETE:8)
Block(-8,87,-3,CONCRETE:15)
Block(-8,87,-2,CONCRETE:8)
Block(-8,88,-7,CONCRETE:15)
Block(-8,88,-6,CONCRETE:8)
Block(-8,88,-5,CONCRETE:8)
Block(-8,88,-4,CONCRETE:8)
Block(-8,88,-3,CONCRETE:15)
Block(-8,88,-2,CONCRETE:8)
Block(-8,89,-7,CONCRETE:15)
Block(-8,89,-6,CONCRETE:8)
Block(-8,89,-5,CONCRETE:15)
Block(-8,89,-4,CONCRETE:8)
Block(-8,89,-3,CONCRETE:15)
Block(-8,89,-2,CONCRETE:8)
Block(-8,90,-7,CONCRETE:15)
Block(-8,90,-6,CONCRETE:8)
Block(-8,90,-5,CONCRETE:15)
Block(-8,90,-4,CONCRETE:8)
Block(-8,90,-3,CONCRETE:15)
Block(-8,90,-2,CONCRETE:8)
Block(-8,91,-7,CONCRETE:15)
Block(-8,91,-6,CONCRETE:8)
Block(-8,91,-5,CONCRETE:15)
Block(-8,91,-4,CONCRETE:8)
Block(-8,91,-3,CONCRETE:15)
Block(-8,91,-2,CONCRETE:8)
Block(-8,92,-7,CONCRETE:15)
Block(-8,92,-6,CONCRETE:8)
Block(-8,92,-5,CONCRETE:15)
Block(-8,92,-4,CONCRETE:8)
Block(-8,92,-3,CONCRETE:15)
Block(-8,92,-2,CONCRETE:8)
Block(-8,93,-7,CONCRETE:15)
Block(-8,93,-6,CONCRETE:8)
Block(-8,93,-5,CONCRETE:15)
Block(-8,93,-4,CONCRETE:8)
Block(-8,93,-3,CONCRETE:15)
Block(-8,93,-2,CONCRETE:8)
Block(-8,94,-7,CONCRETE:8)
Block(-8,94,-6,CONCRETE:8)
Block(-8,94,-5,CONCRETE:15)
Block(-8,94,-4,CONCRETE:8)
Block(-8,94,-3,CONCRETE:15)
Block(-8,94,-2,CONCRETE:8)
Block(-8,95,-7,CONCRETE:8)
Block(-8,95,-6,CONCRETE:8)
Block(-8,95,-5,CONCRETE:15)
Block(-8,95,-4,CONCRETE:8)
Block(-8,95,-3,CONCRETE:15)
Block(-8,95,-2,CONCRETE:8)
Block(-8,96,-7,CONCRETE:15)
Block(-8,96,-6,CONCRETE:8)
Block(-8,96,-5,CONCRETE:15)
Block(-8,96,-4,CONCRETE:8)
Block(-8,96,-3,CONCRETE:15)
Block(-8,96,-2,CONCRETE:8)
Block(-8,97,-7,CONCRETE:8)
Block(-8,97,-6,CONCRETE:8)
Block(-8,97,-5,CONCRETE:15)
Block(-8,97,-4,CONCRETE:8)
Block(-8,97,-3,CONCRETE:8)
Block(-8,97,-2,CONCRETE:8)
Block(-8,98,-7,CONCRETE:8)
Block(-8,98,-6,CONCRETE:8)
Block(-8,98,-5,CONCRETE:15)
Block(-8,98,-4,CONCRETE:8)
Block(-8,98,-3,CONCRETE:8)
Block(-8,98,-2,CONCRETE:8)
Block(-8,99,-7,CONCRETE:8)
Block(-8,99,-6,CONCRETE:8)
Block(-8,99,-5,CONCRETE:15)
Block(-8,99,-4,CONCRETE:8)
Block(-8,99,-3,CONCRETE:8)
Block(-8,99,-2,CONCRETE:8)
Block(-8,100,-7,CONCRETE:8)
Block(-8,100,-6,CONCRETE:8)
Block(-8,100,-5,CONCRETE:15)
Block(-8,100,-4,CONCRETE:8)
Block(-8,100,-3,CONCRETE:8)
Block(-8,100,-2,CONCRETE:8)
Block(-8,101,-7,CONCRETE:8)
Block(-8,101,-6,CONCRETE:8)
Block(-8,101,-5,CONCRETE:15)
Block(-8,101,-4,CONCRETE:8)
Block(-8,101,-3,CONCRETE:8)
Block(-8,101,-2,CONCRETE:8)
Block(-8,102,-7,CONCRETE:8)
Block(-8,102,-6,CONCRETE:8)
Block(-8,102,-5,CONCRETE:15)
Block(-8,102,-4,CONCRETE:8)
Block(-8,102,-3,CONCRETE:8)
Block(-8,102,-2,CONCRETE:8)
Block(-8,103,-7,CONCRETE:15)
Block(-8,103,-6,CONCRETE:8)
Block(-8,103,-5,CONCRETE:15)
Block(-8,103,-4,CONCRETE:8)
Block(-8,103,-3,CONCRETE:8)
Block(-8,103,-2,CONCRETE:8)
Block(-8,104,-7,CONCRETE:15)
Block(-8,104,-6,CONCRETE:8)
Block(-8,104,-5,CONCRETE:15)
Block(-8,104,-4,CONCRETE:8)
Block(-8,104,-3,CONCRETE:8)
Block(-8,104,-2,CONCRETE:8)
Block(-8,105,-7,CONCRETE:15)
Block(-8,105,-6,CONCRETE:8)
Block(-8,105,-5,CONCRETE:15)
Block(-8,105,-4,CONCRETE:8)
Block(-8,105,-3,CONCRETE:8)
Block(-8,105,-2,CONCRETE:8)
Block(-8,106,-7,CONCRETE:15)
Block(-8,106,-6,CONCRETE:8)
Block(-8,106,-5,CONCRETE:15)
Block(-8,106,-4,CONCRETE:8)
Block(-8,106,-3,CONCRETE:8)
Block(-8,106,-2,CONCRETE:8)
Block(-8,107,-7,CONCRETE:15)
Block(-8,107,-6,CONCRETE:8)
Block(-8,107,-5,CONCRETE:15)
Block(-8,107,-4,CONCRETE:8)
Block(-8,107,-3,CONCRETE:8)
Block(-8,107,-2,CONCRETE:8)
Block(-8,108,-7,CONCRETE:15)
Block(-8,108,-6,CONCRETE:8)
Block(-8,108,-5,CONCRETE:8)
Block(-8,108,-4,CONCRETE:8)
Block(-8,108,-3,CONCRETE:8)
Block(-8,108,-2,CONCRETE:8)
Block(-8,109,-7,CONCRETE:15)
Block(-8,109,-6,CONCRETE:8)
Block(-8,109,-5,CONCRETE:8)
Block(-8,109,-4,CONCRETE:8)
Block(-8,109,-3,CONCRETE:8)
Block(-8,109,-2,CONCRETE:8)
Block(-8,110,-7,CONCRETE:15)
Block(-8,110,-6,CONCRETE:8)
Block(-8,110,-5,CONCRETE:8)
Block(-8,110,-4,CONCRETE:15)
Block(-8,110,-3,CONCRETE:8)
Block(-8,110,-2,CONCRETE:8)
Block(-8,111,-7,CONCRETE:15)
Block(-8,111,-6,CONCRETE:8)
Block(-8,111,-5,CONCRETE:8)
Block(-8,111,-4,CONCRETE:15)
Block(-8,111,-3,CONCRETE:8)
Block(-8,111,-2,CONCRETE:8)
Block(-8,112,-7,CONCRETE:15)
Block(-8,112,-6,CONCRETE:8)
Block(-8,112,-5,CONCRETE:8)
Block(-8,112,-4,CONCRETE:15)
Block(-8,112,-3,CONCRETE:8)
Block(-8,112,-2,CONCRETE:8)
Block(-8,113,-7,CONCRETE:15)
Block(-8,113,-6,CONCRETE:8)
Block(-8,113,-5,CONCRETE:8)
Block(-8,113,-4,CONCRETE:15)
Block(-8,113,-3,CONCRETE:8)
Block(-8,113,-2,CONCRETE:8)
Block(-8,114,-7,CONCRETE:15)
Block(-8,114,-6,CONCRETE:8)
Block(-8,114,-5,CONCRETE:8)
Block(-8,114,-4,CONCRETE:15)
Block(-8,114,-3,CONCRETE:8)
Block(-8,114,-2,CONCRETE:8)
Block(-8,115,-7,CONCRETE:8)
Block(-8,115,-6,CONCRETE:8)
Block(-8,115,-5,CONCRETE:8)
Block(-8,115,-4,CONCRETE:15)
Block(-8,115,-3,CONCRETE:8)
Block(-8,115,-2,CONCRETE:8)
Block(-8,116,-7,CONCRETE:8)
Block(-8,116,-6,CONCRETE:8)
Block(-8,116,-5,CONCRETE:8)
Block(-8,116,-4,CONCRETE:15)
Block(-8,116,-3,CONCRETE:15)
Block(-8,116,-2,CONCRETE:8)
Block(-8,117,-7,CONCRETE:8)
Block(-8,117,-6,CONCRETE:8)
Block(-8,117,-5,CONCRETE:8)
Block(-8,117,-4,CONCRETE:8)
Block(-8,117,-3,CONCRETE:8)
Block(-8,117,-2,CONCRETE:8)
Block(-8,118,-7,CONCRETE:8)
Block(-8,118,-6,CONCRETE:8)
Block(-8,118,-5,CONCRETE:8)
Block(-8,118,-4,CONCRETE:8)
Block(-8,118,-3,CONCRETE:8)
Block(-8,118,-2,CONCRETE:8)
Block(-7,0,-7,CONCRETE:7)
Block(-7,0,-6,CONCRETE:7)
Block(-7,0,-5,CONCRETE:7)
Block(-7,0,-4,CONCRETE:7)
Block(-7,0,-3,CONCRETE:7)
Block(-7,0,-2,CONCRETE:7)
Block(-7,0,-1,CONCRETE:7)
Block(-7,0,0,CONCRETE:7)
Block(-7,0,1,CONCRETE:7)
Block(-7,0,2,CONCRETE:7)
Block(-7,0,3,CONCRETE:7)
Block(-7,0,4,CONCRETE:7)
Block(-7,0,5,CONCRETE:7)
Block(-7,0,6,CONCRETE:7)
Block(-7,0,7,CONCRETE:7)
Block(-7,0,8,CONCRETE:7)
Block(-7,1,-7,CONCRETE:7)
Block(-7,1,-6,CONCRETE:7)
Block(-7,1,-5,CONCRETE:7)
Block(-7,1,-4,CONCRETE:7)
Block(-7,1,-3,CONCRETE:7)
Block(-7,1,-2,CONCRETE:7)
Block(-7,1,-1,CONCRETE:7)
Block(-7,1,0,CONCRETE:7)
Block(-7,1,1,CONCRETE:7)
Block(-7,1,2,CONCRETE:7)
Block(-7,1,3,CONCRETE:7)
Block(-7,1,4,CONCRETE:7)
Block(-7,1,5,CONCRETE:7)
Block(-7,1,6,CONCRETE:7)
Block(-7,1,7,CONCRETE:7)
Block(-7,1,8,CONCRETE:7)
Block(-7,2,-7,CONCRETE:7)
Block(-7,2,-6,CONCRETE:7)
Block(-7,2,-5,CONCRETE:7)
Block(-7,2,-4,CONCRETE:7)
Block(-7,2,-3,CONCRETE:7)
Block(-7,2,-2,CONCRETE:7)
Block(-7,2,-1,CONCRETE:7)
Block(-7,2,0,CONCRETE:7)
Block(-7,2,1,CONCRETE:7)
Block(-7,2,2,CONCRETE:7)
Block(-7,2,3,CONCRETE:7)
Block(-7,2,4,CONCRETE:7)
Block(-7,2,5,CONCRETE:7)
Block(-7,2,6,CONCRETE:7)
Block(-7,2,7,CONCRETE:7)
Block(-7,2,8,CONCRETE:7)
Block(-7,3,-7,CONCRETE:7)
Block(-7,3,-6,CONCRETE:7)
Block(-7,3,-5,CONCRETE:7)
Block(-7,3,-4,CONCRETE:7)
Block(-7,3,-3,CONCRETE:7)
Block(-7,3,-2,CONCRETE:7)
Block(-7,3,-1,CONCRETE:7)
Block(-7,3,0,CONCRETE:7)
Block(-7,3,1,CONCRETE:7)
Block(-7,3,2,CONCRETE:7)
Block(-7,3,3,CONCRETE:7)
Block(-7,3,4,CONCRETE:7)
Block(-7,3,5,CONCRETE:7)
Block(-7,3,6,CONCRETE:7)
Block(-7,3,7,CONCRETE:7)
Block(-7,3,8,CONCRETE:7)
Block(-7,4,-7,CONCRETE:7)
Block(-7,4,-6,CONCRETE:7)
Block(-7,4,-5,CONCRETE:7)
Block(-7,4,-4,CONCRETE:7)
Block(-7,4,-3,CONCRETE:7)
Block(-7,4,-2,CONCRETE:7)
Block(-7,4,-1,CONCRETE:7)
Block(-7,4,0,CONCRETE:7)
Block(-7,4,1,CONCRETE:7)
Block(-7,4,2,CONCRETE:7)
Block(-7,4,3,CONCRETE:7)
Block(-7,4,4,CONCRETE:7)
Block(-7,4,5,CONCRETE:7)
Block(-7,4,6,CONCRETE:7)
Block(-7,4,7,CONCRETE:7)
Block(-7,4,8,CONCRETE:7)
Block(-7,5,-7,CONCRETE:7)
Block(-7,5,-6,CONCRETE:7)
Block(-7,5,-5,CONCRETE:7)
Block(-7,5,-4,CONCRETE:7)
Block(-7,5,-3,CONCRETE:7)
Block(-7,5,-2,CONCRETE:7)
Block(-7,5,-1,CONCRETE:7)
Block(-7,5,0,CONCRETE:7)
Block(-7,5,1,CONCRETE:7)
Block(-7,5,2,CONCRETE:7)
Block(-7,5,3,CONCRETE:7)
Block(-7,5,4,CONCRETE:7)
Block(-7,5,5,CONCRETE:7)
Block(-7,5,6,CONCRETE:7)
Block(-7,5,7,CONCRETE:7)
Block(-7,5,8,CONCRETE:7)
Block(-7,6,-7,CONCRETE:7)
Block(-7,6,-6,CONCRETE:7)
Block(-7,6,-5,CONCRETE:7)
Block(-7,6,-4,CONCRETE:7)
Block(-7,6,-3,CONCRETE:7)
Block(-7,6,-2,CONCRETE:7)
Block(-7,6,-1,CONCRETE:7)
Block(-7,6,0,CONCRETE:7)
Block(-7,6,1,CONCRETE:7)
Block(-7,6,2,CONCRETE:7)
Block(-7,6,3,CONCRETE:7)
Block(-7,6,4,CONCRETE:7)
Block(-7,6,5,CONCRETE:7)
Block(-7,6,6,CONCRETE:7)
Block(-7,6,7,CONCRETE:7)
Block(-7,6,8,CONCRETE:7)
Block(-7,7,-7,CONCRETE:7)
Block(-7,7,-6,CONCRETE:7)
Block(-7,7,-5,CONCRETE:7)
Block(-7,7,-4,CONCRETE:7)
Block(-7,7,-3,CONCRETE:7)
Block(-7,7,-2,CONCRETE:7)
Block(-7,7,-1,CONCRETE:7)
Block(-7,7,0,CONCRETE:7)
Block(-7,7,1,CONCRETE:7)
Block(-7,7,2,CONCRETE:7)
Block(-7,7,3,CONCRETE:7)
Block(-7,7,4,CONCRETE:7)
Block(-7,7,5,CONCRETE:7)
Block(-7,7,6,CONCRETE:7)
Block(-7,7,7,CONCRETE:7)
Block(-7,7,8,CONCRETE:7)
Block(-7,8,-7,WORKBENCH:0)
Block(-7,8,-6,AIR:0)
Block(-7,8,-5,AIR:0)
Block(-7,8,-4,AIR:0)
Block(-7,8,-3,AIR:0)
Block(-7,8,-2,AIR:0)
Block(-7,8,-1,TRAP_DOOR:6)
Block(-7,8,0,TRAP_DOOR:14)
Block(-7,8,1,TRAP_DOOR:6)
Block(-7,8,2,TRAP_DOOR:6)
Block(-7,8,3,AIR:0)
Block(-7,8,4,AIR:0)
Block(-7,8,5,AIR:0)
Block(-7,8,6,AIR:0)
Block(-7,8,7,WORKBENCH:0)
Block(-7,8,8,CONCRETE:7)
Block(-7,9,-7,IRON_FENCE:0)
Block(-7,9,-6,AIR:0)
Block(-7,9,-5,AIR:0)
Block(-7,9,-4,AIR:0)
Block(-7,9,-3,AIR:0)
Block(-7,9,-2,AIR:0)
Block(-7,9,-1,AIR:0)
Block(-7,9,0,AIR:0)
Block(-7,9,1,AIR:0)
Block(-7,9,2,AIR:0)
Block(-7,9,3,AIR:0)
Block(-7,9,4,AIR:0)
Block(-7,9,5,AIR:0)
Block(-7,9,6,AIR:0)
Block(-7,9,7,IRON_TRAPDOOR:0)
Block(-7,9,8,CONCRETE:7)
Block(-7,10,-7,IRON_TRAPDOOR:1)
Block(-7,10,-6,AIR:0)
Block(-7,10,-5,AIR:0)
Block(-7,10,-4,AIR:0)
Block(-7,10,-3,AIR:0)
Block(-7,10,-2,AIR:0)
Block(-7,10,-1,AIR:0)
Block(-7,10,0,AIR:0)
Block(-7,10,1,AIR:0)
Block(-7,10,2,AIR:0)
Block(-7,10,3,AIR:0)
Block(-7,10,4,AIR:0)
Block(-7,10,5,AIR:0)
Block(-7,10,6,AIR:0)
Block(-7,10,7,IRON_TRAPDOOR:8)
Block(-7,10,8,CONCRETE:7)
Block(-7,11,-7,AIR:0)
Block(-7,11,-6,AIR:0)
Block(-7,11,-5,AIR:0)
Block(-7,11,-4,CONCRETE:8)
Block(-7,11,-3,CONCRETE:8)
Block(-7,11,-2,CONCRETE:8)
Block(-7,11,-1,CONCRETE:8)
Block(-7,11,0,CONCRETE:8)
Block(-7,11,1,CONCRETE:8)
Block(-7,11,2,CONCRETE:8)
Block(-7,11,3,CONCRETE:8)
Block(-7,11,4,CONCRETE:8)
Block(-7,11,5,CONCRETE:8)
Block(-7,11,6,CONCRETE:8)
Block(-7,11,7,REDSTONE_LAMP_OFF:0)
Block(-7,11,8,CONCRETE:7)
Block(-7,12,-7,CONCRETE:7)
Block(-7,12,-6,CONCRETE:7)
Block(-7,12,-5,CONCRETE:7)
Block(-7,12,-4,CONCRETE:7)
Block(-7,12,-3,CONCRETE:7)
Block(-7,12,-2,CONCRETE:7)
Block(-7,12,-1,CONCRETE:7)
Block(-7,12,0,CONCRETE:7)
Block(-7,12,1,CONCRETE:7)
Block(-7,12,2,CONCRETE:7)
Block(-7,12,3,CONCRETE:7)
Block(-7,12,4,CONCRETE:7)
Block(-7,12,5,CONCRETE:7)
Block(-7,12,6,CONCRETE:7)
Block(-7,12,7,CONCRETE:7)
Block(-7,12,8,CONCRETE:7)
Block(-7,13,-7,CONCRETE:7)
Block(-7,13,-6,CONCRETE:7)
Block(-7,13,-5,CONCRETE:7)
Block(-7,13,-4,CONCRETE:7)
Block(-7,13,-3,CONCRETE:7)
Block(-7,13,-2,CONCRETE:7)
Block(-7,13,-1,CONCRETE:7)
Block(-7,13,0,CONCRETE:7)
Block(-7,13,1,CONCRETE:7)
Block(-7,13,2,CONCRETE:7)
Block(-7,13,3,CONCRETE:7)
Block(-7,13,4,CONCRETE:7)
Block(-7,13,5,CONCRETE:7)
Block(-7,13,6,CONCRETE:7)
Block(-7,13,7,CONCRETE:7)
Block(-7,13,8,CONCRETE:7)
Block(-7,14,-7,CONCRETE:7)
Block(-7,14,-6,CONCRETE:7)
Block(-7,14,-5,CONCRETE:7)
Block(-7,14,-4,CONCRETE:7)
Block(-7,14,-3,CONCRETE:7)
Block(-7,14,-2,CONCRETE:7)
Block(-7,14,-1,CONCRETE:7)
Block(-7,14,0,CONCRETE:7)
Block(-7,14,1,CONCRETE:7)
Block(-7,14,2,CONCRETE:7)
Block(-7,14,3,CONCRETE:7)
Block(-7,14,4,CONCRETE:7)
Block(-7,14,5,CONCRETE:7)
Block(-7,14,6,CONCRETE:7)
Block(-7,14,7,CONCRETE:7)
Block(-7,14,8,CONCRETE:7)
Block(-7,15,-7,CONCRETE:7)
Block(-7,15,-6,CONCRETE:7)
Block(-7,15,-5,CONCRETE:7)
Block(-7,15,-4,CONCRETE:7)
Block(-7,15,-3,CONCRETE:7)
Block(-7,15,-2,CONCRETE:7)
Block(-7,15,-1,CONCRETE:7)
Block(-7,15,0,CONCRETE:7)
Block(-7,15,1,CONCRETE:7)
Block(-7,15,2,CONCRETE:7)
Block(-7,15,3,CONCRETE:7)
Block(-7,15,4,CONCRETE:7)
Block(-7,15,5,CONCRETE:7)
Block(-7,15,6,CONCRETE:7)
Block(-7,15,7,CONCRETE:7)
Block(-7,15,8,CONCRETE:7)
Block(-7,16,-7,CONCRETE:7)
Block(-7,16,-6,CONCRETE:7)
Block(-7,16,-5,CONCRETE:7)
Block(-7,16,-4,CONCRETE:7)
Block(-7,16,-3,CONCRETE:7)
Block(-7,16,-2,CONCRETE:7)
Block(-7,16,-1,CONCRETE:7)
Block(-7,16,0,CONCRETE:7)
Block(-7,16,1,CONCRETE:7)
Block(-7,16,2,CONCRETE:7)
Block(-7,16,3,CONCRETE:7)
Block(-7,16,4,CONCRETE:7)
Block(-7,16,5,CONCRETE:7)
Block(-7,16,6,CONCRETE:7)
Block(-7,16,7,CONCRETE:7)
Block(-7,16,8,CONCRETE:7)
Block(-7,17,-7,CONCRETE:7)
Block(-7,17,-6,CONCRETE:7)
Block(-7,17,-5,CONCRETE:7)
Block(-7,17,-4,CONCRETE:7)
Block(-7,17,-3,CONCRETE:7)
Block(-7,17,-2,CONCRETE:7)
Block(-7,17,-1,CONCRETE:7)
Block(-7,17,0,CONCRETE:7)
Block(-7,17,1,CONCRETE:7)
Block(-7,17,2,CONCRETE:7)
Block(-7,17,3,CONCRETE:7)
Block(-7,17,4,CONCRETE:7)
Block(-7,17,5,CONCRETE:7)
Block(-7,17,6,CONCRETE:7)
Block(-7,17,7,CONCRETE:7)
Block(-7,17,8,CONCRETE:7)
Block(-7,18,-7,CONCRETE:8)
Block(-7,18,-6,CONCRETE:8)
Block(-7,18,-5,CONCRETE:8)
Block(-7,18,-4,CONCRETE:8)
Block(-7,18,-3,CONCRETE:8)
Block(-7,18,-2,CONCRETE:8)
Block(-7,18,1,CONCRETE:15)
Block(-7,18,2,CONCRETE:15)
Block(-7,18,3,CONCRETE:15)
Block(-7,18,4,CONCRETE:15)
Block(-7,19,-7,CONCRETE:8)
Block(-7,19,-6,CONCRETE:8)
Block(-7,19,-5,CONCRETE:8)
Block(-7,19,-4,CONCRETE:8)
Block(-7,19,-3,CONCRETE:8)
Block(-7,19,-2,CONCRETE:8)
Block(-7,19,1,CONCRETE:15)
Block(-7,19,2,CONCRETE:15)
Block(-7,19,3,CONCRETE:15)
Block(-7,19,4,CONCRETE:15)
Block(-7,20,-7,CONCRETE:8)
Block(-7,20,-6,CONCRETE:8)
Block(-7,20,-5,CONCRETE:8)
Block(-7,20,-4,CONCRETE:8)
Block(-7,20,-3,CONCRETE:8)
Block(-7,20,-2,CONCRETE:8)
Block(-7,20,1,CONCRETE:15)
Block(-7,20,2,CONCRETE:15)
Block(-7,20,3,CONCRETE:15)
Block(-7,20,4,CONCRETE:15)
Block(-7,21,-7,CONCRETE:8)
Block(-7,21,-6,CONCRETE:8)
Block(-7,21,-5,CONCRETE:8)
Block(-7,21,-4,CONCRETE:8)
Block(-7,21,-3,CONCRETE:8)
Block(-7,21,-2,CONCRETE:8)
Block(-7,21,1,CONCRETE:15)
Block(-7,21,2,CONCRETE:15)
Block(-7,21,3,CONCRETE:15)
Block(-7,21,4,CONCRETE:15)
Block(-7,22,-7,CONCRETE:8)
Block(-7,22,-6,CONCRETE:8)
Block(-7,22,-5,CONCRETE:8)
Block(-7,22,-4,CONCRETE:8)
Block(-7,22,-3,CONCRETE:8)
Block(-7,22,-2,CONCRETE:8)
Block(-7,22,1,CONCRETE:15)
Block(-7,22,2,CONCRETE:15)
Block(-7,22,3,CONCRETE:15)
Block(-7,22,4,CONCRETE:15)
Block(-7,23,-7,CONCRETE:8)
Block(-7,23,-6,CONCRETE:8)
Block(-7,23,-5,CONCRETE:8)
Block(-7,23,-4,CONCRETE:8)
Block(-7,23,-3,CONCRETE:8)
Block(-7,23,-2,CONCRETE:8)
Block(-7,23,1,CONCRETE:15)
Block(-7,23,2,CONCRETE:15)
Block(-7,23,3,CONCRETE:15)
Block(-7,23,4,CONCRETE:15)
Block(-7,24,-7,CONCRETE:8)
Block(-7,24,-6,CONCRETE:8)
Block(-7,24,-5,CONCRETE:8)
Block(-7,24,-4,CONCRETE:8)
Block(-7,24,-3,CONCRETE:8)
Block(-7,24,-2,CONCRETE:8)
Block(-7,24,1,CONCRETE:15)
Block(-7,24,2,CONCRETE:15)
Block(-7,24,3,CONCRETE:15)
Block(-7,24,4,CONCRETE:15)
Block(-7,25,-7,CONCRETE:8)
Block(-7,25,-6,CONCRETE:8)
Block(-7,25,-5,CONCRETE:8)
Block(-7,25,-4,CONCRETE:8)
Block(-7,25,-3,CONCRETE:8)
Block(-7,25,-2,CONCRETE:8)
Block(-7,25,1,CONCRETE:15)
Block(-7,25,2,CONCRETE:15)
Block(-7,25,3,CONCRETE:15)
Block(-7,25,4,CONCRETE:15)
Block(-7,26,-7,CONCRETE:8)
Block(-7,26,-6,CONCRETE:8)
Block(-7,26,-5,CONCRETE:8)
Block(-7,26,-4,CONCRETE:8)
Block(-7,26,-3,CONCRETE:8)
Block(-7,26,-2,CONCRETE:8)
Block(-7,26,1,CONCRETE:15)
Block(-7,26,2,CONCRETE:15)
Block(-7,26,3,CONCRETE:15)
Block(-7,26,4,CONCRETE:15)
Block(-7,27,-7,CONCRETE:8)
Block(-7,27,-6,CONCRETE:8)
Block(-7,27,-5,CONCRETE:8)
Block(-7,27,-4,CONCRETE:8)
Block(-7,27,-3,CONCRETE:8)
Block(-7,27,-2,CONCRETE:8)
Block(-7,27,1,CONCRETE:15)
Block(-7,27,2,CONCRETE:15)
Block(-7,27,3,CONCRETE:15)
Block(-7,27,4,CONCRETE:15)
Block(-7,28,-7,CONCRETE:8)
Block(-7,28,-6,CONCRETE:8)
Block(-7,28,-5,CONCRETE:8)
Block(-7,28,-4,CONCRETE:8)
Block(-7,28,-3,CONCRETE:8)
Block(-7,28,-2,CONCRETE:8)
Block(-7,28,1,CONCRETE:15)
Block(-7,28,2,CONCRETE:15)
Block(-7,28,3,CONCRETE:15)
Block(-7,28,4,CONCRETE:15)
Block(-7,29,-7,CONCRETE:8)
Block(-7,29,-6,CONCRETE:8)
Block(-7,29,-5,CONCRETE:8)
Block(-7,29,-4,CONCRETE:8)
Block(-7,29,-3,CONCRETE:8)
Block(-7,29,-2,CONCRETE:8)
Block(-7,29,1,CONCRETE:15)
Block(-7,29,2,CONCRETE:15)
Block(-7,29,3,CONCRETE:15)
Block(-7,29,4,CONCRETE:15)
Block(-7,30,-7,CONCRETE:8)
Block(-7,30,-6,CONCRETE:8)
Block(-7,30,-5,CONCRETE:8)
Block(-7,30,-4,CONCRETE:8)
Block(-7,30,-3,CONCRETE:8)
Block(-7,30,-2,CONCRETE:8)
Block(-7,30,1,CONCRETE:15)
Block(-7,30,2,CONCRETE:15)
Block(-7,30,3,CONCRETE:15)
Block(-7,30,4,CONCRETE:15)
Block(-7,31,-7,CONCRETE:8)
Block(-7,31,-6,CONCRETE:8)
Block(-7,31,-5,CONCRETE:8)
Block(-7,31,-4,CONCRETE:8)
Block(-7,31,-3,CONCRETE:8)
Block(-7,31,-2,CONCRETE:8)
Block(-7,31,1,CONCRETE:15)
Block(-7,31,2,CONCRETE:15)
Block(-7,31,3,CONCRETE:15)
Block(-7,31,4,CONCRETE:15)
Block(-7,32,-7,CONCRETE:8)
Block(-7,32,-6,CONCRETE:8)
Block(-7,32,-5,CONCRETE:8)
Block(-7,32,-4,CONCRETE:8)
Block(-7,32,-3,CONCRETE:8)
Block(-7,32,-2,CONCRETE:8)
Block(-7,32,1,CONCRETE:15)
Block(-7,32,2,CONCRETE:15)
Block(-7,32,3,CONCRETE:15)
Block(-7,32,4,CONCRETE:15)
Block(-7,33,-7,CONCRETE:8)
Block(-7,33,-6,CONCRETE:8)
Block(-7,33,-5,CONCRETE:8)
Block(-7,33,-4,CONCRETE:8)
Block(-7,33,-3,CONCRETE:8)
Block(-7,33,-2,CONCRETE:8)
Block(-7,33,1,CONCRETE:15)
Block(-7,33,2,CONCRETE:15)
Block(-7,33,3,CONCRETE:15)
Block(-7,33,4,CONCRETE:15)
Block(-7,34,-7,CONCRETE:8)
Block(-7,34,-6,CONCRETE:8)
Block(-7,34,-5,CONCRETE:8)
Block(-7,34,-4,CONCRETE:8)
Block(-7,34,-3,CONCRETE:8)
Block(-7,34,-2,CONCRETE:8)
Block(-7,34,1,CONCRETE:15)
Block(-7,34,2,CONCRETE:15)
Block(-7,34,3,CONCRETE:15)
Block(-7,34,4,CONCRETE:15)
Block(-7,35,-7,CONCRETE:8)
Block(-7,35,-6,CONCRETE:8)
Block(-7,35,-5,CONCRETE:8)
Block(-7,35,-4,CONCRETE:8)
Block(-7,35,-3,CONCRETE:8)
Block(-7,35,-2,CONCRETE:8)
Block(-7,35,1,CONCRETE:15)
Block(-7,35,2,CONCRETE:15)
Block(-7,35,3,CONCRETE:15)
Block(-7,35,4,CONCRETE:15)
Block(-7,36,-7,CONCRETE:8)
Block(-7,36,-6,CONCRETE:8)
Block(-7,36,-5,CONCRETE:8)
Block(-7,36,-4,CONCRETE:8)
Block(-7,36,-3,CONCRETE:8)
Block(-7,36,-2,CONCRETE:8)
Block(-7,36,1,CONCRETE:15)
Block(-7,36,2,CONCRETE:15)
Block(-7,36,3,CONCRETE:15)
Block(-7,36,4,CONCRETE:15)
Block(-7,37,-7,CONCRETE:8)
Block(-7,37,-6,CONCRETE:8)
Block(-7,37,-5,CONCRETE:8)
Block(-7,37,-4,CONCRETE:8)
Block(-7,37,-3,CONCRETE:8)
Block(-7,37,-2,CONCRETE:8)
Block(-7,37,1,CONCRETE:15)
Block(-7,37,2,CONCRETE:15)
Block(-7,37,3,CONCRETE:15)
Block(-7,37,4,CONCRETE:15)
Block(-7,38,-7,CONCRETE:8)
Block(-7,38,-6,CONCRETE:8)
Block(-7,38,-5,CONCRETE:8)
Block(-7,38,-4,CONCRETE:8)
Block(-7,38,-3,CONCRETE:8)
Block(-7,38,-2,CONCRETE:8)
Block(-7,38,1,CONCRETE:15)
Block(-7,38,2,CONCRETE:15)
Block(-7,38,3,CONCRETE:15)
Block(-7,38,4,CONCRETE:15)
Block(-7,39,-7,CONCRETE:8)
Block(-7,39,-6,CONCRETE:8)
Block(-7,39,-5,CONCRETE:8)
Block(-7,39,-4,CONCRETE:8)
Block(-7,39,-3,CONCRETE:8)
Block(-7,39,-2,CONCRETE:8)
Block(-7,39,1,CONCRETE:15)
Block(-7,39,2,CONCRETE:15)
Block(-7,39,3,CONCRETE:15)
Block(-7,39,4,CONCRETE:15)
Block(-7,40,-7,CONCRETE:8)
Block(-7,40,-6,CONCRETE:8)
Block(-7,40,-5,CONCRETE:8)
Block(-7,40,-4,CONCRETE:8)
Block(-7,40,-3,CONCRETE:8)
Block(-7,40,-2,CONCRETE:8)
Block(-7,40,1,CONCRETE:15)
Block(-7,40,2,CONCRETE:15)
Block(-7,40,3,CONCRETE:15)
Block(-7,40,4,CONCRETE:15)
Block(-7,41,-7,CONCRETE:8)
Block(-7,41,-6,CONCRETE:8)
Block(-7,41,-5,CONCRETE:8)
Block(-7,41,-4,CONCRETE:8)
Block(-7,41,-3,CONCRETE:8)
Block(-7,41,-2,CONCRETE:8)
Block(-7,41,1,CONCRETE:15)
Block(-7,41,2,CONCRETE:15)
Block(-7,41,3,CONCRETE:15)
Block(-7,41,4,CONCRETE:15)
Block(-7,42,-7,CONCRETE:8)
Block(-7,42,-6,CONCRETE:8)
Block(-7,42,-5,CONCRETE:8)
Block(-7,42,-4,CONCRETE:8)
Block(-7,42,-3,CONCRETE:8)
Block(-7,42,-2,CONCRETE:8)
Block(-7,42,1,CONCRETE:15)
Block(-7,42,2,CONCRETE:15)
Block(-7,42,3,CONCRETE:15)
Block(-7,42,4,CONCRETE:15)
Block(-7,43,-7,CONCRETE:8)
Block(-7,43,-6,CONCRETE:8)
Block(-7,43,-5,CONCRETE:8)
Block(-7,43,-4,CONCRETE:8)
Block(-7,43,-3,CONCRETE:8)
Block(-7,43,-2,CONCRETE:8)
Block(-7,43,1,CONCRETE:15)
Block(-7,43,2,CONCRETE:15)
Block(-7,43,3,CONCRETE:15)
Block(-7,43,4,CONCRETE:15)
Block(-7,44,-7,CONCRETE:8)
Block(-7,44,-6,CONCRETE:8)
Block(-7,44,-5,CONCRETE:8)
Block(-7,44,-4,CONCRETE:8)
Block(-7,44,-3,CONCRETE:8)
Block(-7,44,-2,CONCRETE:8)
Block(-7,44,1,CONCRETE:15)
Block(-7,44,2,CONCRETE:15)
Block(-7,44,3,CONCRETE:15)
Block(-7,44,4,CONCRETE:15)
Block(-7,45,-7,CONCRETE:8)
Block(-7,45,-6,CONCRETE:8)
Block(-7,45,-5,CONCRETE:8)
Block(-7,45,-4,CONCRETE:8)
Block(-7,45,-3,CONCRETE:8)
Block(-7,45,-2,CONCRETE:8)
Block(-7,45,1,CONCRETE:15)
Block(-7,45,2,CONCRETE:15)
Block(-7,45,3,CONCRETE:15)
Block(-7,45,4,CONCRETE:15)
Block(-7,46,-7,CONCRETE:8)
Block(-7,46,-6,CONCRETE:8)
Block(-7,46,-5,CONCRETE:8)
Block(-7,46,-4,CONCRETE:8)
Block(-7,46,-3,CONCRETE:8)
Block(-7,46,-2,CONCRETE:8)
Block(-7,46,1,CONCRETE:15)
Block(-7,46,2,CONCRETE:15)
Block(-7,46,3,CONCRETE:15)
Block(-7,46,4,CONCRETE:15)
Block(-7,47,-7,CONCRETE:8)
Block(-7,47,-6,CONCRETE:8)
Block(-7,47,-5,CONCRETE:8)
Block(-7,47,-4,CONCRETE:8)
Block(-7,47,-3,CONCRETE:8)
Block(-7,47,-2,CONCRETE:8)
Block(-7,47,1,CONCRETE:15)
Block(-7,47,2,CONCRETE:15)
Block(-7,47,3,CONCRETE:15)
Block(-7,47,4,CONCRETE:15)
Block(-7,48,-7,CONCRETE:8)
Block(-7,48,-6,CONCRETE:8)
Block(-7,48,-5,CONCRETE:8)
Block(-7,48,-4,CONCRETE:8)
Block(-7,48,-3,CONCRETE:8)
Block(-7,48,-2,CONCRETE:8)
Block(-7,48,1,CONCRETE:15)
Block(-7,48,2,CONCRETE:15)
Block(-7,48,3,CONCRETE:15)
Block(-7,48,4,CONCRETE:15)
Block(-7,49,-7,CONCRETE:8)
Block(-7,49,-6,CONCRETE:8)
Block(-7,49,-5,CONCRETE:8)
Block(-7,49,-4,CONCRETE:8)
Block(-7,49,-3,CONCRETE:8)
Block(-7,49,-2,CONCRETE:8)
Block(-7,49,1,CONCRETE:15)
Block(-7,49,2,CONCRETE:15)
Block(-7,49,3,CONCRETE:15)
Block(-7,49,4,CONCRETE:15)
Block(-7,50,-7,CONCRETE:8)
Block(-7,50,-6,CONCRETE:8)
Block(-7,50,-5,CONCRETE:8)
Block(-7,50,-4,CONCRETE:8)
Block(-7,50,-3,CONCRETE:8)
Block(-7,50,-2,CONCRETE:8)
Block(-7,50,1,CONCRETE:15)
Block(-7,50,2,CONCRETE:15)
Block(-7,50,3,CONCRETE:15)
Block(-7,50,4,CONCRETE:15)
Block(-7,51,-7,CONCRETE:8)
Block(-7,51,-6,CONCRETE:8)
Block(-7,51,-5,CONCRETE:8)
Block(-7,51,-4,CONCRETE:8)
Block(-7,51,-3,CONCRETE:8)
Block(-7,51,-2,CONCRETE:8)
Block(-7,51,1,CONCRETE:15)
Block(-7,51,2,CONCRETE:15)
Block(-7,51,3,CONCRETE:15)
Block(-7,51,4,CONCRETE:15)
Block(-7,52,-7,CONCRETE:8)
Block(-7,52,-6,CONCRETE:8)
Block(-7,52,-5,CONCRETE:8)
Block(-7,52,-4,CONCRETE:8)
Block(-7,52,-3,CONCRETE:8)
Block(-7,52,-2,CONCRETE:8)
Block(-7,52,1,CONCRETE:15)
Block(-7,52,2,CONCRETE:15)
Block(-7,52,3,CONCRETE:15)
Block(-7,52,4,CONCRETE:15)
Block(-7,53,-7,CONCRETE:8)
Block(-7,53,-6,CONCRETE:8)
Block(-7,53,-5,CONCRETE:8)
Block(-7,53,-4,CONCRETE:8)
Block(-7,53,-3,CONCRETE:8)
Block(-7,53,-2,CONCRETE:8)
Block(-7,53,1,CONCRETE:15)
Block(-7,53,2,CONCRETE:15)
Block(-7,53,3,CONCRETE:15)
Block(-7,53,4,CONCRETE:15)
Block(-7,54,-7,CONCRETE:8)
Block(-7,54,-6,CONCRETE:8)
Block(-7,54,-5,CONCRETE:8)
Block(-7,54,-4,CONCRETE:8)
Block(-7,54,-3,CONCRETE:8)
Block(-7,54,-2,CONCRETE:8)
Block(-7,54,1,CONCRETE:15)
Block(-7,54,2,CONCRETE:15)
Block(-7,54,3,CONCRETE:15)
Block(-7,54,4,CONCRETE:15)
Block(-7,55,-7,CONCRETE:8)
Block(-7,55,-6,CONCRETE:8)
Block(-7,55,-5,CONCRETE:8)
Block(-7,55,-4,CONCRETE:8)
Block(-7,55,-3,CONCRETE:8)
Block(-7,55,-2,CONCRETE:8)
Block(-7,55,1,CONCRETE:15)
Block(-7,55,2,CONCRETE:15)
Block(-7,55,3,CONCRETE:15)
Block(-7,55,4,CONCRETE:15)
Block(-7,56,-7,CONCRETE:8)
Block(-7,56,-6,CONCRETE:8)
Block(-7,56,-5,CONCRETE:8)
Block(-7,56,-4,CONCRETE:8)
Block(-7,56,-3,CONCRETE:8)
Block(-7,56,-2,CONCRETE:8)
Block(-7,56,1,CONCRETE:15)
Block(-7,56,2,CONCRETE:15)
Block(-7,56,3,CONCRETE:15)
Block(-7,56,4,CONCRETE:15)
Block(-7,57,-7,CONCRETE:8)
Block(-7,57,-6,CONCRETE:8)
Block(-7,57,-5,CONCRETE:8)
Block(-7,57,-4,CONCRETE:8)
Block(-7,57,-3,CONCRETE:8)
Block(-7,57,-2,CONCRETE:8)
Block(-7,57,1,CONCRETE:15)
Block(-7,57,2,CONCRETE:15)
Block(-7,57,3,CONCRETE:15)
Block(-7,57,4,CONCRETE:15)
Block(-7,58,-7,CONCRETE:8)
Block(-7,58,-6,CONCRETE:8)
Block(-7,58,-5,CONCRETE:8)
Block(-7,58,-4,CONCRETE:8)
Block(-7,58,-3,CONCRETE:8)
Block(-7,58,-2,CONCRETE:8)
Block(-7,58,1,CONCRETE:15)
Block(-7,58,2,CONCRETE:15)
Block(-7,58,3,CONCRETE:15)
Block(-7,58,4,CONCRETE:15)
Block(-7,59,-7,CONCRETE:8)
Block(-7,59,-6,CONCRETE:8)
Block(-7,59,-5,CONCRETE:8)
Block(-7,59,-4,CONCRETE:8)
Block(-7,59,-3,CONCRETE:8)
Block(-7,59,-2,CONCRETE:8)
Block(-7,59,1,CONCRETE:15)
Block(-7,59,2,CONCRETE:15)
Block(-7,59,3,CONCRETE:15)
Block(-7,59,4,CONCRETE:15)
Block(-7,60,-7,CONCRETE:8)
Block(-7,60,-6,CONCRETE:8)
Block(-7,60,-5,CONCRETE:8)
Block(-7,60,-4,CONCRETE:8)
Block(-7,60,-3,CONCRETE:8)
Block(-7,60,-2,CONCRETE:8)
Block(-7,60,1,CONCRETE:15)
Block(-7,60,2,CONCRETE:15)
Block(-7,60,3,CONCRETE:15)
Block(-7,60,4,CONCRETE:15)
Block(-7,61,-7,CONCRETE:8)
Block(-7,61,-6,CONCRETE:8)
Block(-7,61,-5,CONCRETE:8)
Block(-7,61,-4,CONCRETE:8)
Block(-7,61,-3,CONCRETE:8)
Block(-7,61,-2,CONCRETE:8)
Block(-7,61,1,CONCRETE:15)
Block(-7,61,2,CONCRETE:15)
Block(-7,61,3,CONCRETE:15)
Block(-7,61,4,CONCRETE:15)
Block(-7,62,-7,CONCRETE:8)
Block(-7,62,-6,CONCRETE:8)
Block(-7,62,-5,CONCRETE:8)
Block(-7,62,-4,CONCRETE:8)
Block(-7,62,-3,CONCRETE:8)
Block(-7,62,-2,CONCRETE:8)
Block(-7,62,1,CONCRETE:15)
Block(-7,62,2,CONCRETE:15)
Block(-7,62,3,CONCRETE:15)
Block(-7,62,4,CONCRETE:15)
Block(-7,63,-7,CONCRETE:8)
Block(-7,63,-6,CONCRETE:8)
Block(-7,63,-5,CONCRETE:8)
Block(-7,63,-4,CONCRETE:8)
Block(-7,63,-3,CONCRETE:8)
Block(-7,63,-2,CONCRETE:8)
Block(-7,63,1,CONCRETE:15)
Block(-7,63,2,CONCRETE:15)
Block(-7,63,3,CONCRETE:15)
Block(-7,63,4,CONCRETE:15)
Block(-7,64,-7,CONCRETE:8)
Block(-7,64,-6,CONCRETE:8)
Block(-7,64,-5,CONCRETE:8)
Block(-7,64,-4,CONCRETE:8)
Block(-7,64,-3,CONCRETE:8)
Block(-7,64,-2,CONCRETE:8)
Block(-7,64,1,CONCRETE:15)
Block(-7,64,2,CONCRETE:15)
Block(-7,64,3,CONCRETE:15)
Block(-7,64,4,CONCRETE:15)
Block(-7,65,-7,CONCRETE:8)
Block(-7,65,-6,CONCRETE:8)
Block(-7,65,-5,CONCRETE:8)
Block(-7,65,-4,CONCRETE:8)
Block(-7,65,-3,CONCRETE:8)
Block(-7,65,-2,CONCRETE:8)
Block(-7,65,1,CONCRETE:15)
Block(-7,65,2,CONCRETE:15)
Block(-7,65,3,CONCRETE:15)
Block(-7,65,4,CONCRETE:15)
Block(-7,66,-7,CONCRETE:8)
Block(-7,66,-6,CONCRETE:8)
Block(-7,66,-5,CONCRETE:8)
Block(-7,66,-4,CONCRETE:8)
Block(-7,66,-3,CONCRETE:8)
Block(-7,66,-2,CONCRETE:8)
Block(-7,66,1,CONCRETE:15)
Block(-7,66,2,CONCRETE:15)
Block(-7,66,3,CONCRETE:15)
Block(-7,66,4,CONCRETE:15)
Block(-7,67,-7,CONCRETE:8)
Block(-7,67,-6,CONCRETE:8)
Block(-7,67,-5,CONCRETE:8)
Block(-7,67,-4,CONCRETE:8)
Block(-7,67,-3,CONCRETE:8)
Block(-7,67,-2,CONCRETE:8)
Block(-7,67,1,CONCRETE:15)
Block(-7,67,2,CONCRETE:15)
Block(-7,67,3,CONCRETE:15)
Block(-7,67,4,CONCRETE:15)
Block(-7,68,-7,CONCRETE:8)
Block(-7,68,-6,CONCRETE:8)
Block(-7,68,-5,CONCRETE:8)
Block(-7,68,-4,CONCRETE:8)
Block(-7,68,-3,CONCRETE:8)
Block(-7,68,-2,CONCRETE:8)
Block(-7,68,1,CONCRETE:15)
Block(-7,68,2,CONCRETE:15)
Block(-7,68,3,CONCRETE:15)
Block(-7,68,4,CONCRETE:15)
Block(-7,69,-7,CONCRETE:8)
Block(-7,69,-6,CONCRETE:8)
Block(-7,69,-5,CONCRETE:8)
Block(-7,69,-4,CONCRETE:8)
Block(-7,69,-3,CONCRETE:8)
Block(-7,69,-2,CONCRETE:8)
Block(-7,69,1,CONCRETE:15)
Block(-7,69,2,CONCRETE:15)
Block(-7,69,3,CONCRETE:15)
Block(-7,69,4,CONCRETE:15)
Block(-7,70,-7,CONCRETE:8)
Block(-7,70,-6,CONCRETE:8)
Block(-7,70,-5,CONCRETE:8)
Block(-7,70,-4,CONCRETE:8)
Block(-7,70,-3,CONCRETE:8)
Block(-7,70,-2,CONCRETE:8)
Block(-7,70,1,CONCRETE:15)
Block(-7,70,2,CONCRETE:15)
Block(-7,70,3,CONCRETE:15)
Block(-7,70,4,CONCRETE:15)
Block(-7,71,-7,CONCRETE:8)
Block(-7,71,-6,CONCRETE:8)
Block(-7,71,-5,CONCRETE:8)
Block(-7,71,-4,CONCRETE:8)
Block(-7,71,-3,CONCRETE:8)
Block(-7,71,-2,CONCRETE:8)
Block(-7,71,1,CONCRETE:15)
Block(-7,71,2,CONCRETE:15)
Block(-7,71,3,CONCRETE:15)
Block(-7,71,4,CONCRETE:15)
Block(-7,72,-7,CONCRETE:8)
Block(-7,72,-6,CONCRETE:8)
Block(-7,72,-5,CONCRETE:8)
Block(-7,72,-4,CONCRETE:8)
Block(-7,72,-3,CONCRETE:8)
Block(-7,72,-2,CONCRETE:8)
Block(-7,72,1,CONCRETE:15)
Block(-7,72,2,CONCRETE:15)
Block(-7,72,3,CONCRETE:15)
Block(-7,72,4,CONCRETE:15)
Block(-7,73,-7,CONCRETE:8)
Block(-7,73,-6,CONCRETE:8)
Block(-7,73,-5,CONCRETE:8)
Block(-7,73,-4,CONCRETE:8)
Block(-7,73,-3,CONCRETE:8)
Block(-7,73,-2,CONCRETE:8)
Block(-7,73,1,CONCRETE:15)
Block(-7,73,2,CONCRETE:15)
Block(-7,73,3,CONCRETE:15)
Block(-7,73,4,CONCRETE:15)
Block(-7,74,-7,CONCRETE:8)
Block(-7,74,-6,CONCRETE:8)
Block(-7,74,-5,CONCRETE:8)
Block(-7,74,-4,CONCRETE:8)
Block(-7,74,-3,CONCRETE:8)
Block(-7,74,-2,CONCRETE:8)
Block(-7,74,1,CONCRETE:15)
Block(-7,74,2,CONCRETE:15)
Block(-7,74,3,CONCRETE:15)
Block(-7,74,4,CONCRETE:15)
Block(-7,75,-7,CONCRETE:8)
Block(-7,75,-6,CONCRETE:8)
Block(-7,75,-5,CONCRETE:8)
Block(-7,75,-4,CONCRETE:8)
Block(-7,75,-3,CONCRETE:8)
Block(-7,75,-2,CONCRETE:8)
Block(-7,75,1,CONCRETE:15)
Block(-7,75,2,CONCRETE:15)
Block(-7,75,3,CONCRETE:15)
Block(-7,75,4,CONCRETE:15)
Block(-7,76,-7,CONCRETE:8)
Block(-7,76,-6,CONCRETE:8)
Block(-7,76,-5,CONCRETE:8)
Block(-7,76,-4,CONCRETE:8)
Block(-7,76,-3,CONCRETE:8)
Block(-7,76,-2,CONCRETE:8)
Block(-7,76,1,CONCRETE:15)
Block(-7,76,2,CONCRETE:15)
Block(-7,76,3,CONCRETE:15)
Block(-7,76,4,CONCRETE:15)
Block(-7,77,-7,CONCRETE:8)
Block(-7,77,-6,CONCRETE:8)
Block(-7,77,-5,CONCRETE:8)
Block(-7,77,-4,CONCRETE:8)
Block(-7,77,-3,CONCRETE:8)
Block(-7,77,-2,CONCRETE:8)
Block(-7,77,1,CONCRETE:15)
Block(-7,77,2,CONCRETE:15)
Block(-7,77,3,CONCRETE:15)
Block(-7,77,4,CONCRETE:15)
Block(-7,78,-7,CONCRETE:8)
Block(-7,78,-6,CONCRETE:8)
Block(-7,78,-5,CONCRETE:8)
Block(-7,78,-4,CONCRETE:8)
Block(-7,78,-3,CONCRETE:8)
Block(-7,78,-2,CONCRETE:8)
Block(-7,78,1,CONCRETE:15)
Block(-7,78,2,CONCRETE:15)
Block(-7,78,3,CONCRETE:15)
Block(-7,78,4,CONCRETE:15)
Block(-7,79,-7,CONCRETE:8)
Block(-7,79,-6,CONCRETE:8)
Block(-7,79,-5,CONCRETE:8)
Block(-7,79,-4,CONCRETE:8)
Block(-7,79,-3,CONCRETE:8)
Block(-7,79,-2,CONCRETE:8)
Block(-7,79,1,CONCRETE:15)
Block(-7,79,2,CONCRETE:15)
Block(-7,79,3,CONCRETE:15)
Block(-7,79,4,CONCRETE:15)
Block(-7,80,-7,CONCRETE:8)
Block(-7,80,-6,CONCRETE:8)
Block(-7,80,-5,CONCRETE:8)
Block(-7,80,-4,CONCRETE:8)
Block(-7,80,-3,CONCRETE:8)
Block(-7,80,-2,CONCRETE:8)
Block(-7,80,1,CONCRETE:15)
Block(-7,80,2,CONCRETE:15)
Block(-7,80,3,CONCRETE:15)
Block(-7,80,4,CONCRETE:15)
Block(-7,81,-7,CONCRETE:8)
Block(-7,81,-6,CONCRETE:8)
Block(-7,81,-5,CONCRETE:8)
Block(-7,81,-4,CONCRETE:8)
Block(-7,81,-3,CONCRETE:8)
Block(-7,81,-2,CONCRETE:8)
Block(-7,81,1,CONCRETE:15)
Block(-7,81,2,CONCRETE:15)
Block(-7,81,3,CONCRETE:15)
Block(-7,81,4,CONCRETE:15)
Block(-7,82,-7,CONCRETE:8)
Block(-7,82,-6,CONCRETE:8)
Block(-7,82,-5,CONCRETE:8)
Block(-7,82,-4,CONCRETE:8)
Block(-7,82,-3,CONCRETE:8)
Block(-7,82,-2,CONCRETE:8)
Block(-7,82,1,CONCRETE:15)
Block(-7,82,2,CONCRETE:15)
Block(-7,82,3,CONCRETE:15)
Block(-7,82,4,CONCRETE:15)
Block(-7,83,-7,CONCRETE:8)
Block(-7,83,-6,CONCRETE:8)
Block(-7,83,-5,CONCRETE:8)
Block(-7,83,-4,CONCRETE:8)
Block(-7,83,-3,CONCRETE:8)
Block(-7,83,-2,CONCRETE:8)
Block(-7,83,1,CONCRETE:15)
Block(-7,83,2,CONCRETE:15)
Block(-7,83,3,CONCRETE:15)
Block(-7,83,4,CONCRETE:15)
Block(-7,84,-7,CONCRETE:8)
Block(-7,84,-6,CONCRETE:8)
Block(-7,84,-5,CONCRETE:8)
Block(-7,84,-4,CONCRETE:8)
Block(-7,84,-3,CONCRETE:8)
Block(-7,84,-2,CONCRETE:8)
Block(-7,85,-7,CONCRETE:8)
Block(-7,85,-6,CONCRETE:8)
Block(-7,85,-5,CONCRETE:8)
Block(-7,85,-4,CONCRETE:8)
Block(-7,85,-3,CONCRETE:8)
Block(-7,85,-2,CONCRETE:8)
Block(-7,86,-7,CONCRETE:8)
Block(-7,86,-6,CONCRETE:8)
Block(-7,86,-5,CONCRETE:8)
Block(-7,86,-4,CONCRETE:8)
Block(-7,86,-3,CONCRETE:8)
Block(-7,86,-2,CONCRETE:8)
Block(-7,87,-7,CONCRETE:8)
Block(-7,87,-6,CONCRETE:8)
Block(-7,87,-5,CONCRETE:8)
Block(-7,87,-4,CONCRETE:8)
Block(-7,87,-3,CONCRETE:8)
Block(-7,87,-2,CONCRETE:8)
Block(-7,88,-7,CONCRETE:8)
Block(-7,88,-6,CONCRETE:8)
Block(-7,88,-5,CONCRETE:8)
Block(-7,88,-4,CONCRETE:8)
Block(-7,88,-3,CONCRETE:8)
Block(-7,88,-2,CONCRETE:8)
Block(-7,89,-7,CONCRETE:8)
Block(-7,89,-6,CONCRETE:8)
Block(-7,89,-5,CONCRETE:8)
Block(-7,89,-4,CONCRETE:8)
Block(-7,89,-3,CONCRETE:8)
Block(-7,89,-2,CONCRETE:8)
Block(-7,90,-7,CONCRETE:8)
Block(-7,90,-6,CONCRETE:8)
Block(-7,90,-5,CONCRETE:8)
Block(-7,90,-4,CONCRETE:8)
Block(-7,90,-3,CONCRETE:8)
Block(-7,90,-2,CONCRETE:8)
Block(-7,91,-7,CONCRETE:8)
Block(-7,91,-6,CONCRETE:8)
Block(-7,91,-5,CONCRETE:8)
Block(-7,91,-4,CONCRETE:8)
Block(-7,91,-3,CONCRETE:8)
Block(-7,91,-2,CONCRETE:8)
Block(-7,92,-7,CONCRETE:8)
Block(-7,92,-6,CONCRETE:8)
Block(-7,92,-5,CONCRETE:8)
Block(-7,92,-4,CONCRETE:8)
Block(-7,92,-3,CONCRETE:8)
Block(-7,92,-2,CONCRETE:8)
Block(-7,93,-7,CONCRETE:8)
Block(-7,93,-6,CONCRETE:8)
Block(-7,93,-5,CONCRETE:8)
Block(-7,93,-4,CONCRETE:8)
Block(-7,93,-3,CONCRETE:8)
Block(-7,93,-2,CONCRETE:8)
Block(-7,94,-7,CONCRETE:8)
Block(-7,94,-6,CONCRETE:8)
Block(-7,94,-5,CONCRETE:8)
Block(-7,94,-4,CONCRETE:8)
Block(-7,94,-3,CONCRETE:8)
Block(-7,94,-2,CONCRETE:8)
Block(-7,95,-7,CONCRETE:8)
Block(-7,95,-6,CONCRETE:8)
Block(-7,95,-5,CONCRETE:8)
Block(-7,95,-4,CONCRETE:8)
Block(-7,95,-3,CONCRETE:8)
Block(-7,95,-2,CONCRETE:8)
Block(-7,96,-7,CONCRETE:8)
Block(-7,96,-6,CONCRETE:8)
Block(-7,96,-5,CONCRETE:8)
Block(-7,96,-4,CONCRETE:8)
Block(-7,96,-3,CONCRETE:8)
Block(-7,96,-2,CONCRETE:8)
Block(-7,97,-7,CONCRETE:8)
Block(-7,97,-6,CONCRETE:8)
Block(-7,97,-5,CONCRETE:8)
Block(-7,97,-4,CONCRETE:8)
Block(-7,97,-3,CONCRETE:8)
Block(-7,97,-2,CONCRETE:8)
Block(-7,98,-7,CONCRETE:8)
Block(-7,98,-6,CONCRETE:8)
Block(-7,98,-5,CONCRETE:8)
Block(-7,98,-4,CONCRETE:8)
Block(-7,98,-3,CONCRETE:8)
Block(-7,98,-2,CONCRETE:8)
Block(-7,99,-7,CONCRETE:8)
Block(-7,99,-6,CONCRETE:8)
Block(-7,99,-5,CONCRETE:8)
Block(-7,99,-4,CONCRETE:8)
Block(-7,99,-3,CONCRETE:8)
Block(-7,99,-2,CONCRETE:8)
Block(-7,100,-7,CONCRETE:8)
Block(-7,100,-6,CONCRETE:8)
Block(-7,100,-5,CONCRETE:8)
Block(-7,100,-4,CONCRETE:8)
Block(-7,100,-3,CONCRETE:8)
Block(-7,100,-2,CONCRETE:8)
Block(-7,101,-7,CONCRETE:8)
Block(-7,101,-6,CONCRETE:8)
Block(-7,101,-5,CONCRETE:8)
Block(-7,101,-4,CONCRETE:8)
Block(-7,101,-3,CONCRETE:8)
Block(-7,101,-2,CONCRETE:8)
Block(-7,102,-7,CONCRETE:8)
Block(-7,102,-6,CONCRETE:8)
Block(-7,102,-5,CONCRETE:8)
Block(-7,102,-4,CONCRETE:8)
Block(-7,102,-3,CONCRETE:8)
Block(-7,102,-2,CONCRETE:8)
Block(-7,103,-7,CONCRETE:8)
Block(-7,103,-6,CONCRETE:8)
Block(-7,103,-5,CONCRETE:8)
Block(-7,103,-4,CONCRETE:8)
Block(-7,103,-3,CONCRETE:8)
Block(-7,103,-2,CONCRETE:8)
Block(-7,104,-7,CONCRETE:8)
Block(-7,104,-6,CONCRETE:8)
Block(-7,104,-5,CONCRETE:8)
Block(-7,104,-4,CONCRETE:8)
Block(-7,104,-3,CONCRETE:8)
Block(-7,104,-2,CONCRETE:8)
Block(-7,105,-7,CONCRETE:8)
Block(-7,105,-6,CONCRETE:8)
Block(-7,105,-5,CONCRETE:8)
Block(-7,105,-4,CONCRETE:8)
Block(-7,105,-3,CONCRETE:8)
Block(-7,105,-2,CONCRETE:8)
Block(-7,106,-7,CONCRETE:8)
Block(-7,106,-6,CONCRETE:8)
Block(-7,106,-5,CONCRETE:8)
Block(-7,106,-4,CONCRETE:8)
Block(-7,106,-3,CONCRETE:8)
Block(-7,106,-2,CONCRETE:8)
Block(-7,107,-7,CONCRETE:8)
Block(-7,107,-6,CONCRETE:8)
Block(-7,107,-5,CONCRETE:8)
Block(-7,107,-4,CONCRETE:8)
Block(-7,107,-3,CONCRETE:8)
Block(-7,107,-2,CONCRETE:8)
Block(-7,108,-7,CONCRETE:8)
Block(-7,108,-6,CONCRETE:8)
Block(-7,108,-5,CONCRETE:8)
Block(-7,108,-4,CONCRETE:8)
Block(-7,108,-3,CONCRETE:8)
Block(-7,108,-2,CONCRETE:8)
Block(-7,109,-7,CONCRETE:8)
Block(-7,109,-6,CONCRETE:8)
Block(-7,109,-5,CONCRETE:8)
Block(-7,109,-4,CONCRETE:8)
Block(-7,109,-3,CONCRETE:8)
Block(-7,109,-2,CONCRETE:8)
Block(-7,110,-7,CONCRETE:8)
Block(-7,110,-6,CONCRETE:8)
Block(-7,110,-5,CONCRETE:8)
Block(-7,110,-4,CONCRETE:8)
Block(-7,110,-3,CONCRETE:8)
Block(-7,110,-2,CONCRETE:8)
Block(-7,111,-7,CONCRETE:8)
Block(-7,111,-6,CONCRETE:8)
Block(-7,111,-5,CONCRETE:8)
Block(-7,111,-4,CONCRETE:8)
Block(-7,111,-3,CONCRETE:8)
Block(-7,111,-2,CONCRETE:8)
Block(-7,112,-7,CONCRETE:8)
Block(-7,112,-6,CONCRETE:8)
Block(-7,112,-5,CONCRETE:8)
Block(-7,112,-4,CONCRETE:8)
Block(-7,112,-3,CONCRETE:8)
Block(-7,112,-2,CONCRETE:8)
Block(-7,113,-7,CONCRETE:8)
Block(-7,113,-6,CONCRETE:8)
Block(-7,113,-5,CONCRETE:8)
Block(-7,113,-4,CONCRETE:8)
Block(-7,113,-3,CONCRETE:8)
Block(-7,113,-2,CONCRETE:8)
Block(-7,114,-7,CONCRETE:8)
Block(-7,114,-6,CONCRETE:8)
Block(-7,114,-5,CONCRETE:8)
Block(-7,114,-4,CONCRETE:8)
Block(-7,114,-3,CONCRETE:8)
Block(-7,114,-2,CONCRETE:8)
Block(-7,115,-7,CONCRETE:8)
Block(-7,115,-6,CONCRETE:8)
Block(-7,115,-5,CONCRETE:8)
Block(-7,115,-4,CONCRETE:8)
Block(-7,115,-3,CONCRETE:8)
Block(-7,115,-2,CONCRETE:8)
Block(-7,116,-7,CONCRETE:8)
Block(-7,116,-6,CONCRETE:8)
Block(-7,116,-5,CONCRETE:8)
Block(-7,116,-4,CONCRETE:8)
Block(-7,116,-3,CONCRETE:8)
Block(-7,116,-2,CONCRETE:8)
Block(-7,117,-7,CONCRETE:8)
Block(-7,117,-6,CONCRETE:8)
Block(-7,117,-5,CONCRETE:8)
Block(-7,117,-4,CONCRETE:8)
Block(-7,117,-3,CONCRETE:8)
Block(-7,117,-2,CONCRETE:8)
Block(-7,118,-7,CONCRETE:8)
Block(-7,118,-6,CONCRETE:8)
Block(-7,118,-5,CONCRETE:8)
Block(-7,118,-4,CONCRETE:8)
Block(-7,118,-3,CONCRETE:8)
Block(-7,118,-2,CONCRETE:8)
Block(-7,119,-7,CONCRETE:8)
Block(-7,119,-6,CONCRETE:8)
Block(-7,119,-5,CONCRETE:8)
Block(-7,119,-4,CONCRETE:8)
Block(-7,119,-3,CONCRETE:8)
Block(-7,119,-2,CONCRETE:8)
Block(-6,0,-7,CONCRETE:7)
Block(-6,0,-6,CONCRETE:7)
Block(-6,0,-5,CONCRETE:7)
Block(-6,0,-4,CONCRETE:7)
Block(-6,0,-3,CONCRETE:7)
Block(-6,0,-2,CONCRETE:7)
Block(-6,0,-1,CONCRETE:7)
Block(-6,0,0,CONCRETE:7)
Block(-6,0,1,CONCRETE:7)
Block(-6,0,2,CONCRETE:7)
Block(-6,0,3,CONCRETE:7)
Block(-6,0,4,CONCRETE:7)
Block(-6,0,5,CONCRETE:7)
Block(-6,0,6,CONCRETE:7)
Block(-6,0,7,CONCRETE:7)
Block(-6,0,8,CONCRETE:7)
Block(-6,1,-7,CONCRETE:7)
Block(-6,1,-6,CONCRETE:7)
Block(-6,1,-5,CONCRETE:7)
Block(-6,1,-4,CONCRETE:7)
Block(-6,1,-3,CONCRETE:7)
Block(-6,1,-2,CONCRETE:7)
Block(-6,1,-1,CONCRETE:7)
Block(-6,1,0,CONCRETE:7)
Block(-6,1,1,CONCRETE:7)
Block(-6,1,2,CONCRETE:7)
Block(-6,1,3,CONCRETE:7)
Block(-6,1,4,CONCRETE:7)
Block(-6,1,5,CONCRETE:7)
Block(-6,1,6,CONCRETE:7)
Block(-6,1,7,CONCRETE:7)
Block(-6,1,8,CONCRETE:7)
Block(-6,2,-7,CONCRETE:7)
Block(-6,2,-6,CONCRETE:7)
Block(-6,2,-5,CONCRETE:7)
Block(-6,2,-4,CONCRETE:7)
Block(-6,2,-3,CONCRETE:7)
Block(-6,2,-2,CONCRETE:7)
Block(-6,2,-1,CONCRETE:7)
Block(-6,2,0,CONCRETE:7)
Block(-6,2,1,CONCRETE:7)
Block(-6,2,2,CONCRETE:7)
Block(-6,2,3,CONCRETE:7)
Block(-6,2,4,CONCRETE:7)
Block(-6,2,5,CONCRETE:7)
Block(-6,2,6,CONCRETE:7)
Block(-6,2,7,CONCRETE:7)
Block(-6,2,8,CONCRETE:7)
Block(-6,3,-7,CONCRETE:7)
Block(-6,3,-6,CONCRETE:7)
Block(-6,3,-5,CONCRETE:7)
Block(-6,3,-4,CONCRETE:7)
Block(-6,3,-3,CONCRETE:7)
Block(-6,3,-2,CONCRETE:7)
Block(-6,3,-1,CONCRETE:7)
Block(-6,3,0,CONCRETE:7)
Block(-6,3,1,CONCRETE:7)
Block(-6,3,2,CONCRETE:7)
Block(-6,3,3,CONCRETE:7)
Block(-6,3,4,CONCRETE:7)
Block(-6,3,5,CONCRETE:7)
Block(-6,3,6,CONCRETE:7)
Block(-6,3,7,CONCRETE:7)
Block(-6,3,8,CONCRETE:7)
Block(-6,4,-7,CONCRETE:7)
Block(-6,4,-6,CONCRETE:7)
Block(-6,4,-5,CONCRETE:7)
Block(-6,4,-4,CONCRETE:7)
Block(-6,4,-3,CONCRETE:7)
Block(-6,4,-2,CONCRETE:7)
Block(-6,4,-1,CONCRETE:7)
Block(-6,4,0,CONCRETE:7)
Block(-6,4,1,CONCRETE:7)
Block(-6,4,2,CONCRETE:7)
Block(-6,4,3,CONCRETE:7)
Block(-6,4,4,CONCRETE:7)
Block(-6,4,5,CONCRETE:7)
Block(-6,4,6,CONCRETE:7)
Block(-6,4,7,CONCRETE:7)
Block(-6,4,8,CONCRETE:7)
Block(-6,5,-7,CONCRETE:7)
Block(-6,5,-6,CONCRETE:7)
Block(-6,5,-5,CONCRETE:7)
Block(-6,5,-4,CONCRETE:7)
Block(-6,5,-3,CONCRETE:7)
Block(-6,5,-2,CONCRETE:7)
Block(-6,5,-1,CONCRETE:7)
Block(-6,5,0,CONCRETE:7)
Block(-6,5,1,CONCRETE:7)
Block(-6,5,2,CONCRETE:7)
Block(-6,5,3,CONCRETE:7)
Block(-6,5,4,CONCRETE:7)
Block(-6,5,5,CONCRETE:7)
Block(-6,5,6,CONCRETE:7)
Block(-6,5,7,CONCRETE:7)
Block(-6,5,8,CONCRETE:7)
Block(-6,6,-7,CONCRETE:7)
Block(-6,6,-6,CONCRETE:7)
Block(-6,6,-5,CONCRETE:7)
Block(-6,6,-4,CONCRETE:7)
Block(-6,6,-3,CONCRETE:7)
Block(-6,6,-2,CONCRETE:7)
Block(-6,6,-1,CONCRETE:7)
Block(-6,6,0,CONCRETE:7)
Block(-6,6,1,CONCRETE:7)
Block(-6,6,2,CONCRETE:7)
Block(-6,6,3,CONCRETE:7)
Block(-6,6,4,CONCRETE:7)
Block(-6,6,5,CONCRETE:7)
Block(-6,6,6,CONCRETE:7)
Block(-6,6,7,CONCRETE:7)
Block(-6,6,8,CONCRETE:7)
Block(-6,7,-7,CONCRETE:7)
Block(-6,7,-6,CONCRETE:7)
Block(-6,7,-5,CONCRETE:7)
Block(-6,7,-4,CONCRETE:7)
Block(-6,7,-3,CONCRETE:7)
Block(-6,7,-2,CONCRETE:7)
Block(-6,7,-1,CONCRETE:7)
Block(-6,7,0,CONCRETE:7)
Block(-6,7,1,CONCRETE:7)
Block(-6,7,2,CONCRETE:7)
Block(-6,7,3,CONCRETE:7)
Block(-6,7,4,CONCRETE:7)
Block(-6,7,5,CONCRETE:7)
Block(-6,7,6,CONCRETE:7)
Block(-6,7,7,CONCRETE:7)
Block(-6,7,8,CONCRETE:7)
Block(-6,8,-7,IRON_TRAPDOOR:9)
Block(-6,8,-6,AIR:0)
Block(-6,8,-5,AIR:0)
Block(-6,8,-4,ANVIL:9)
Block(-6,8,-3,CONCRETE:7)
Block(-6,8,-2,FURNACE:2,NBT/skyscraper_2x2_04/10-furnaceC0R16.nbt)
Block(-6,8,-1,SIGN_POST:4,NBT/skyscraper_2x2_04/11-signC0R16.nbt)
Block(-6,8,0,ANVIL:8)
Block(-6,8,1,IRON_TRAPDOOR:8)
Block(-6,8,2,IRON_TRAPDOOR:10)
Block(-6,8,3,CONCRETE:7)
Block(-6,8,4,WALL_SIGN:4,NBT/skyscraper_2x2_04/12-signC0R16.nbt)
Block(-6,8,5,AIR:0)
Block(-6,8,6,TRAP_DOOR:4)
Block(-6,8,7,STANDING_BANNER:8,NBT/skyscraper_2x2_04/13-bannerC0R16.nbt)
Block(-6,8,8,CONCRETE:7)
#RandomBlock(-6,9,-7,TRAPPED_CHEST:5,../../../../../Chests/Loot/ModernCityJunk_1.nbt,65,CHEST:3,../../../../../Chests/Loot/ModernCityJunk_1.nbt,20,CHEST:3,../../../../../Chests/Loot/ModernCityJunk_2.nbt,15,CHEST:3,../../../../../Chests/Loot/ModernCityJunk_3.nbt,15,CHEST:3,../../../../../Chests/Loot/ModernCityJunk_4.nbt,15,CHEST:3,../../../../../Chests/Loot/ModernCityJunk_5.nbt,15,CHEST:3,../../../../../Chests/Loot/ModernCityCommon_1.nbt,5,CHEST:3,../../../../../Chests/Loot/ModernCityCommon_2.nbt,5,CHEST:3,../../../../../Chests/Loot/ModernCityCommon_3.nbt,5,CHEST:3,../../../../../Chests/Loot/ModernCityCommon_4.nbt,5,CHEST:3,../../../../../Chests/Loot/ModernCityCommon_5.nbt,5,CHEST:3,../../../../../Chests/Loot/ModernCityGood_1.nbt,3,CHEST:3,../../../../../Chests/Loot/ModernCityGood_2.nbt,3,CHEST:3,../../../../../Chests/Loot/ModernCityGood_3.nbt,3,CHEST:3,../../../../../Chests/Loot/ModernCityGood_4.nbt,3,CHEST:3,../../../../../Chests/Loot/ModernCityGood_5.nbt,3,CHEST:3,../../../../../Chests/Loot/ModernCityEpic_1.nbt,1,CHEST:3,../../../../../Chests/Loot/ModernCityEpic_2.nbt,1,CHEST:3,../../../../../Chests/Loot/ModernCityEpic_3.nbt,1,CHEST:3,../../../../../Chests/Loot/ModernCityEpic_4.nbt,1,CHEST:3,../../../../../Chests/Loot/ModernCityEpic_5.nbt,1,CHEST:3,../../../../../Chests/Loot/Common1.nbt,25,CHEST:3,../../../../../Chests/Loot/Common2.nbt,25,CHEST:3,../../../../../Chests/Loot/Common3.nbt,25,CHEST:3,../../../../../Chests/Loot/Common4.nbt,25,CHEST:3,../../../../../Chests/Loot/Common5.nbt,25,CHEST:3,../../../../../Chests/Loot/Common6.nbt,25,CHEST:3,../../../../../Chests/Loot/Common7.nbt,25,CHEST:3,../../../../../Chests/Loot/Common8.nbt,25,CHEST:3,../../../../../Chests/Loot/Common9.nbt,25,CHEST:3,../../../../../Chests/Loot/Common10.nbt,25,CHEST:3,../../../../../Chests/Loot/Common11.nbt,25,CHEST:3,../../../../../Chests/Loot/Common12.nbt,25,CHEST:3,../../../../../Chests/Loot/Common13.nbt,25,CHEST:3,../../../../../Chests/Loot/Common14.nbt,25,CHEST:3,../../../../../Chests/Loot/Common15.nbt,25,CHEST:3,../../../../../Chests/Loot/Rare1.nbt,10,CHEST:3,../../../../../Chests/Loot/Rare2.nbt,10,CHEST:5,../../../../../Chests/Loot/Rare3.nbt,10,CHEST:3,../../../../../Chests/Loot/Rare4.nbt,10,CHEST:3,../../../../../Chests/Loot/Rare5.nbt,10,CHEST:3,../../../../../Chests/Loot/Rare6.nbt,10,CHEST:3,../../../../../Chests/Loot/Rare7.nbt,10,CHEST:3,../../../../../Chests/Loot/Rare8.nbt,10,CHEST:3,../../../../../Chests/Loot/Rare9.nbt,10,CHEST:3,../../../../../Chests/Loot/Rare10.nbt,10,CHEST:3,../../../../../Chests/Loot/Rare11.nbt,10,CHEST:3,../../../../../Chests/Loot/Rare12.nbt,10,CHEST:3,../../../../../Chests/Loot/Rare13.nbt,10,CHEST:3,../../../../../Chests/Loot/Rare14.nbt,10,CHEST:3,../../../../../Chests/Loot/Rare15.nbt,10,CHEST:3,../../../../../Chests/Loot/Epic1.nbt,1,CHEST:3,../../../../../Chests/Loot/Epic2.nbt,1,CHEST:3,../../../../../Chests/Loot/Epic3.nbt,1,CHEST:3,../../../../../Chests/Loot/Epic4.nbt,1,CHEST:3,../../../../../Chests/Loot/Epic5.nbt,1,CHEST:3,../../../../../Chests/Loot/Epic6.nbt,1,CHEST:3,../../../../../Chests/Loot/Epic7.nbt,1,CHEST:3,../../../../../Chests/Loot/Epic8.nbt,1,CHEST:3,../../../../../Chests/Loot/Epic9.nbt,1,CHEST:3,../../../../../Chests/Loot/Epic10.nbt,1,CHEST:3,../../../../../Chests/Loot/Epic11.nbt,1,CHEST:3,../../../../../Chests/Loot/Epic12.nbt,1,CHEST:3,../../../../../Chests/Loot/Epic13.nbt,1,CHEST:3,../../../../../Chests/Loot/Epic14.nbt,1,CHEST:3,../../../../../Chests/Loot/Epic15.nbt,1,CHEST:3,../../../../../Chests/Loot/ModernCityJunk_1.nbt,100)
Block(-6,9,-6,AIR:0)
Block(-6,9,-5,AIR:0)
Block(-6,9,-4,AIR:0)
Block(-6,9,-3,WOOD_PLATE:0)
Block(-6,9,-2,AIR:0)
Block(-6,9,-1,CARPET:0)
Block(-6,9,0,AIR:0)
Block(-6,9,1,AIR:0)
Block(-6,9,2,AIR:0)
Block(-6,9,3,AIR:0)
Block(-6,9,4,AIR:0)
Block(-6,9,5,AIR:0)
Block(-6,9,6,AIR:0)
Block(-6,9,7,IRON_TRAPDOOR:0)
Block(-6,9,8,CONCRETE:7)
Block(-6,10,-7,IRON_TRAPDOOR:1)
Block(-6,10,-6,AIR:0)
Block(-6,10,-5,AIR:0)
Block(-6,10,-4,AIR:0)
Block(-6,10,-3,AIR:0)
Block(-6,10,-2,AIR:0)
Block(-6,10,-1,AIR:0)
Block(-6,10,0,AIR:0)
Block(-6,10,1,AIR:0)
Block(-6,10,2,AIR:0)
Block(-6,10,3,AIR:0)
Block(-6,10,4,AIR:0)
Block(-6,10,5,AIR:0)
Block(-6,10,6,AIR:0)
Block(-6,10,7,IRON_TRAPDOOR:8)
Block(-6,10,8,CONCRETE:7)
Block(-6,11,-7,AIR:0)
Block(-6,11,-6,AIR:0)
Block(-6,11,-5,AIR:0)
Block(-6,11,-4,CONCRETE:8)
Block(-6,11,-3,AIR:0)
Block(-6,11,-2,AIR:0)
Block(-6,11,-1,AIR:0)
Block(-6,11,0,AIR:0)
Block(-6,11,1,AIR:0)
Block(-6,11,2,AIR:0)
Block(-6,11,3,AIR:0)
Block(-6,11,4,AIR:0)
Block(-6,11,5,AIR:0)
Block(-6,11,6,CONCRETE:8)
Block(-6,11,7,REDSTONE_LAMP_OFF:0)
Block(-6,11,8,CONCRETE:7)
Block(-6,12,-7,CONCRETE:7)
Block(-6,12,-6,CONCRETE:7)
Block(-6,12,-5,CONCRETE:7)
Block(-6,12,-4,CONCRETE:7)
Block(-6,12,-3,CONCRETE:7)
Block(-6,12,-2,CONCRETE:7)
Block(-6,12,-1,CONCRETE:7)
Block(-6,12,0,CONCRETE:7)
Block(-6,12,1,CONCRETE:7)
Block(-6,12,2,CONCRETE:7)
Block(-6,12,3,CONCRETE:7)
Block(-6,12,4,CONCRETE:7)
Block(-6,12,5,CONCRETE:7)
Block(-6,12,6,CONCRETE:7)
Block(-6,12,7,CONCRETE:7)
Block(-6,12,8,CONCRETE:7)
Block(-6,13,-7,CONCRETE:7)
Block(-6,13,-6,CONCRETE:7)
Block(-6,13,-5,CONCRETE:7)
Block(-6,13,-4,CONCRETE:7)
Block(-6,13,-3,CONCRETE:7)
Block(-6,13,-2,CONCRETE:7)
Block(-6,13,-1,CONCRETE:7)
Block(-6,13,0,CONCRETE:7)
Block(-6,13,1,CONCRETE:7)
Block(-6,13,2,CONCRETE:7)
Block(-6,13,3,CONCRETE:7)
Block(-6,13,4,CONCRETE:7)
Block(-6,13,5,CONCRETE:7)
Block(-6,13,6,CONCRETE:7)
Block(-6,13,7,CONCRETE:7)
Block(-6,13,8,CONCRETE:7)
Block(-6,14,-7,CONCRETE:7)
Block(-6,14,-6,CONCRETE:7)
Block(-6,14,-5,CONCRETE:7)
Block(-6,14,-4,CONCRETE:7)
Block(-6,14,-3,CONCRETE:7)
Block(-6,14,-2,CONCRETE:7)
Block(-6,14,-1,CONCRETE:7)
Block(-6,14,0,CONCRETE:7)
Block(-6,14,1,CONCRETE:7)
Block(-6,14,2,CONCRETE:7)
Block(-6,14,3,CONCRETE:7)
Block(-6,14,4,CONCRETE:7)
Block(-6,14,5,CONCRETE:7)
Block(-6,14,6,CONCRETE:7)
Block(-6,14,7,CONCRETE:7)
Block(-6,14,8,CONCRETE:7)
Block(-6,15,-7,CONCRETE:7)
Block(-6,15,-6,CONCRETE:7)
Block(-6,15,-5,CONCRETE:7)
Block(-6,15,-4,CONCRETE:7)
Block(-6,15,-3,CONCRETE:7)
Block(-6,15,-2,CONCRETE:7)
Block(-6,15,-1,CONCRETE:7)
Block(-6,15,0,CONCRETE:7)
Block(-6,15,1,CONCRETE:7)
Block(-6,15,2,CONCRETE:7)
Block(-6,15,3,CONCRETE:7)
Block(-6,15,4,CONCRETE:7)
Block(-6,15,5,CONCRETE:7)
Block(-6,15,6,CONCRETE:7)
Block(-6,15,7,CONCRETE:7)
Block(-6,15,8,CONCRETE:7)
Block(-6,16,-7,CONCRETE:7)
Block(-6,16,-6,CONCRETE:7)
Block(-6,16,-5,CONCRETE:7)
Block(-6,16,-4,CONCRETE:7)
Block(-6,16,-3,CONCRETE:7)
Block(-6,16,-2,CONCRETE:7)
Block(-6,16,-1,CONCRETE:7)
Block(-6,16,0,CONCRETE:7)
Block(-6,16,1,CONCRETE:7)
Block(-6,16,2,CONCRETE:7)
Block(-6,16,3,CONCRETE:7)
Block(-6,16,4,CONCRETE:7)
Block(-6,16,5,CONCRETE:7)
Block(-6,16,6,CONCRETE:7)
Block(-6,16,7,CONCRETE:7)
Block(-6,16,8,CONCRETE:7)
Block(-6,17,-7,CONCRETE:7)
Block(-6,17,-6,CONCRETE:7)
Block(-6,17,-5,CONCRETE:7)
Block(-6,17,-4,CONCRETE:7)
Block(-6,17,-3,CONCRETE:7)
Block(-6,17,-2,CONCRETE:7)
Block(-6,17,-1,CONCRETE:7)
Block(-6,17,0,CONCRETE:7)
Block(-6,17,1,CONCRETE:7)
Block(-6,17,2,CONCRETE:7)
Block(-6,17,3,CONCRETE:7)
Block(-6,17,4,CONCRETE:7)
Block(-6,17,5,CONCRETE:7)
Block(-6,17,6,CONCRETE:7)
Block(-6,17,7,CONCRETE:7)
Block(-6,17,8,CONCRETE:7)
Block(-6,18,-7,CONCRETE:8)
Block(-6,18,-6,CONCRETE:8)
Block(-6,18,-5,CONCRETE:8)
Block(-6,18,-4,CONCRETE:8)
Block(-6,18,-3,CONCRETE:8)
Block(-6,18,-2,CONCRETE:8)
Block(-6,18,1,CONCRETE:15)
Block(-6,18,2,CONCRETE:15)
Block(-6,18,3,CONCRETE:15)
Block(-6,18,4,CONCRETE:15)
Block(-6,18,6,CONCRETE:8)
Block(-6,18,7,CONCRETE:8)
Block(-6,18,8,CONCRETE:8)
Block(-6,19,-7,DROPPER:5,NBT/skyscraper_2x2_04/20-dropperC0R16.nbt)
Block(-6,19,-6,CONCRETE:8)
Block(-6,19,-2,STAINED_GLASS:15)
Block(-6,19,1,STAINED_GLASS:15)
Block(-6,19,2,STAINED_GLASS:15)
Block(-6,19,3,STAINED_GLASS:15)
Block(-6,19,4,STAINED_GLASS:15)
Block(-6,19,6,CONCRETE:8)
Block(-6,19,7,CONCRETE:8)
Block(-6,19,8,CONCRETE:8)
Block(-6,20,-7,DROPPER:5,NBT/skyscraper_2x2_04/23-dropperC0R16.nbt)
Block(-6,20,-6,CONCRETE:8)
Block(-6,20,-2,STAINED_GLASS:15)
Block(-6,20,1,STAINED_GLASS:15)
Block(-6,20,2,STAINED_GLASS:15)
Block(-6,20,3,STAINED_GLASS:15)
Block(-6,20,4,STAINED_GLASS:15)
Block(-6,20,6,CONCRETE:8)
Block(-6,20,7,CONCRETE:8)
Block(-6,20,8,CONCRETE:8)
Block(-6,21,-7,IRON_TRAPDOOR:3)
Block(-6,21,-6,CONCRETE:8)
Block(-6,21,-2,STAINED_GLASS:15)
Block(-6,21,1,STAINED_GLASS:15)
Block(-6,21,2,STAINED_GLASS:15)
Block(-6,21,3,STAINED_GLASS:15)
Block(-6,21,4,STAINED_GLASS:15)
Block(-6,21,6,CONCRETE:8)
Block(-6,21,7,CONCRETE:8)
Block(-6,21,8,CONCRETE:8)
Block(-6,22,-6,CONCRETE:8)
Block(-6,22,-2,STAINED_GLASS:15)
Block(-6,22,1,STAINED_GLASS:15)
Block(-6,22,2,STAINED_GLASS:15)
Block(-6,22,3,STAINED_GLASS:15)
Block(-6,22,4,STAINED_GLASS:15)
Block(-6,22,6,CONCRETE:8)
Block(-6,22,7,CONCRETE:8)
Block(-6,22,8,CONCRETE:8)
Block(-6,23,-7,CONCRETE:8)
Block(-6,23,-6,CONCRETE:8)
Block(-6,23,-5,CONCRETE:8)
Block(-6,23,-4,CONCRETE:8)
Block(-6,23,-3,CONCRETE:8)
Block(-6,23,-2,STAINED_GLASS:15)
Block(-6,23,1,STAINED_GLASS:15)
Block(-6,23,2,STAINED_GLASS:15)
Block(-6,23,3,STAINED_GLASS:15)
Block(-6,23,4,STAINED_GLASS:15)
Block(-6,23,6,CONCRETE:8)
Block(-6,23,7,CONCRETE:8)
Block(-6,23,8,CONCRETE:8)
Block(-6,24,-2,STAINED_GLASS:15)
Block(-6,24,1,STAINED_GLASS:15)
Block(-6,24,2,STAINED_GLASS:15)
Block(-6,24,3,STAINED_GLASS:15)
Block(-6,24,4,STAINED_GLASS:15)
Block(-6,24,6,CONCRETE:8)
Block(-6,24,7,CONCRETE:8)
Block(-6,24,8,CONCRETE:8)
Block(-6,25,-2,STAINED_GLASS:15)
Block(-6,25,1,STAINED_GLASS:15)
Block(-6,25,2,STAINED_GLASS:15)
Block(-6,25,3,STAINED_GLASS:15)
Block(-6,25,4,STAINED_GLASS:15)
Block(-6,25,6,CONCRETE:8)
Block(-6,25,7,CONCRETE:8)
Block(-6,25,8,CONCRETE:8)
Block(-6,26,-2,STAINED_GLASS:15)
Block(-6,26,1,STAINED_GLASS:15)
Block(-6,26,2,STAINED_GLASS:15)
Block(-6,26,3,STAINED_GLASS:15)
Block(-6,26,4,STAINED_GLASS:15)
Block(-6,26,6,CONCRETE:8)
Block(-6,26,7,CONCRETE:8)
Block(-6,26,8,CONCRETE:8)
Block(-6,27,-2,STAINED_GLASS:15)
Block(-6,27,1,STAINED_GLASS:15)
Block(-6,27,2,STAINED_GLASS:15)
Block(-6,27,3,STAINED_GLASS:15)
Block(-6,27,4,STAINED_GLASS:15)
Block(-6,27,6,CONCRETE:8)
Block(-6,27,7,CONCRETE:8)
Block(-6,27,8,CONCRETE:8)
Block(-6,28,-2,STAINED_GLASS:15)
Block(-6,28,1,STAINED_GLASS:15)
Block(-6,28,2,STAINED_GLASS:15)
Block(-6,28,3,STAINED_GLASS:15)
Block(-6,28,4,STAINED_GLASS:15)
Block(-6,28,6,CONCRETE:8)
Block(-6,28,7,CONCRETE:8)
Block(-6,28,8,CONCRETE:8)
Block(-6,29,-2,STAINED_GLASS:15)
Block(-6,29,1,STAINED_GLASS:15)
Block(-6,29,2,STAINED_GLASS:15)
Block(-6,29,3,STAINED_GLASS:15)
Block(-6,29,4,STAINED_GLASS:15)
Block(-6,29,6,CONCRETE:8)
Block(-6,29,7,CONCRETE:8)
Block(-6,29,8,CONCRETE:8)
Block(-6,30,-2,STAINED_GLASS:15)
Block(-6,30,1,STAINED_GLASS:15)
Block(-6,30,2,STAINED_GLASS:15)
Block(-6,30,3,STAINED_GLASS:15)
Block(-6,30,4,STAINED_GLASS:15)
Block(-6,30,6,CONCRETE:8)
Block(-6,30,7,CONCRETE:8)
Block(-6,30,8,CONCRETE:8)
Block(-6,31,-7,CONCRETE:8)
Block(-6,31,-6,CONCRETE:8)
Block(-6,31,-5,CONCRETE:8)
Block(-6,31,-4,CONCRETE:8)
Block(-6,31,-3,CONCRETE:8)
Block(-6,31,-2,STAINED_GLASS:15)
Block(-6,31,1,STAINED_GLASS:15)
Block(-6,31,2,STAINED_GLASS:15)
Block(-6,31,3,STAINED_GLASS:15)
Block(-6,31,4,STAINED_GLASS:15)
Block(-6,31,6,CONCRETE:8)
Block(-6,31,7,CONCRETE:8)
Block(-6,31,8,CONCRETE:8)
Block(-6,32,-2,STAINED_GLASS:15)
Block(-6,32,1,STAINED_GLASS:15)
Block(-6,32,2,STAINED_GLASS:15)
Block(-6,32,3,STAINED_GLASS:15)
Block(-6,32,4,STAINED_GLASS:15)
Block(-6,32,6,CONCRETE:8)
Block(-6,32,7,CONCRETE:8)
Block(-6,32,8,CONCRETE:8)
Block(-6,33,-2,STAINED_GLASS:15)
Block(-6,33,1,STAINED_GLASS:15)
Block(-6,33,2,STAINED_GLASS:15)
Block(-6,33,3,STAINED_GLASS:15)
Block(-6,33,4,STAINED_GLASS:15)
Block(-6,33,6,CONCRETE:8)
Block(-6,33,7,CONCRETE:8)
Block(-6,33,8,CONCRETE:8)
Block(-6,34,-2,STAINED_GLASS:15)
Block(-6,34,1,STAINED_GLASS:15)
Block(-6,34,2,STAINED_GLASS:15)
Block(-6,34,3,STAINED_GLASS:15)
Block(-6,34,4,STAINED_GLASS:15)
Block(-6,34,6,CONCRETE:8)
Block(-6,34,7,CONCRETE:8)
Block(-6,34,8,CONCRETE:8)
Block(-6,35,-2,STAINED_GLASS:15)
Block(-6,35,1,STAINED_GLASS:15)
Block(-6,35,2,STAINED_GLASS:15)
Block(-6,35,3,STAINED_GLASS:15)
Block(-6,35,4,STAINED_GLASS:15)
Block(-6,35,6,CONCRETE:8)
Block(-6,35,7,CONCRETE:8)
Block(-6,35,8,CONCRETE:8)
Block(-6,36,-2,STAINED_GLASS:15)
Block(-6,36,1,STAINED_GLASS:15)
Block(-6,36,2,STAINED_GLASS:15)
Block(-6,36,3,STAINED_GLASS:15)
Block(-6,36,4,STAINED_GLASS:15)
Block(-6,36,6,CONCRETE:8)
Block(-6,36,7,CONCRETE:8)
Block(-6,36,8,CONCRETE:8)
Block(-6,37,-2,STAINED_GLASS:15)
Block(-6,37,1,STAINED_GLASS:15)
Block(-6,37,2,STAINED_GLASS:15)
Block(-6,37,3,STAINED_GLASS:15)
Block(-6,37,4,STAINED_GLASS:15)
Block(-6,37,6,CONCRETE:8)
Block(-6,37,7,CONCRETE:8)
Block(-6,37,8,CONCRETE:8)
Block(-6,38,-2,STAINED_GLASS:15)
Block(-6,38,1,STAINED_GLASS:15)
Block(-6,38,2,STAINED_GLASS:15)
Block(-6,38,3,STAINED_GLASS:15)
Block(-6,38,4,STAINED_GLASS:15)
Block(-6,38,6,CONCRETE:8)
Block(-6,38,7,CONCRETE:8)
Block(-6,38,8,CONCRETE:8)
Block(-6,39,-7,CONCRETE:8)
Block(-6,39,-6,CONCRETE:8)
Block(-6,39,-5,CONCRETE:8)
Block(-6,39,-4,CONCRETE:8)
Block(-6,39,-3,CONCRETE:8)
Block(-6,39,-2,STAINED_GLASS:15)
Block(-6,39,1,STAINED_GLASS:15)
Block(-6,39,2,STAINED_GLASS:15)
Block(-6,39,3,STAINED_GLASS:15)
Block(-6,39,4,STAINED_GLASS:15)
Block(-6,39,6,CONCRETE:8)
Block(-6,39,7,CONCRETE:8)
Block(-6,39,8,CONCRETE:8)
Block(-6,40,-2,STAINED_GLASS:15)
Block(-6,40,1,STAINED_GLASS:15)
Block(-6,40,2,STAINED_GLASS:15)
Block(-6,40,3,STAINED_GLASS:15)
Block(-6,40,4,STAINED_GLASS:15)
Block(-6,40,6,CONCRETE:8)
Block(-6,40,7,CONCRETE:8)
Block(-6,40,8,CONCRETE:8)
Block(-6,41,-2,STAINED_GLASS:15)
Block(-6,41,1,STAINED_GLASS:15)
Block(-6,41,2,STAINED_GLASS:15)
Block(-6,41,3,STAINED_GLASS:15)
Block(-6,41,4,STAINED_GLASS:15)
Block(-6,41,6,CONCRETE:8)
Block(-6,41,7,CONCRETE:8)
Block(-6,41,8,CONCRETE:8)
Block(-6,42,-2,STAINED_GLASS:15)
Block(-6,42,1,STAINED_GLASS:15)
Block(-6,42,2,STAINED_GLASS:15)
Block(-6,42,3,STAINED_GLASS:15)
Block(-6,42,4,STAINED_GLASS:15)
Block(-6,42,6,CONCRETE:8)
Block(-6,42,7,CONCRETE:8)
Block(-6,42,8,CONCRETE:8)
Block(-6,43,-2,STAINED_GLASS:15)
Block(-6,43,1,STAINED_GLASS:15)
Block(-6,43,2,STAINED_GLASS:15)
Block(-6,43,3,STAINED_GLASS:15)
Block(-6,43,4,STAINED_GLASS:15)
Block(-6,43,6,CONCRETE:8)
Block(-6,43,7,CONCRETE:8)
Block(-6,43,8,CONCRETE:8)
Block(-6,44,-2,STAINED_GLASS:15)
Block(-6,44,1,STAINED_GLASS:15)
Block(-6,44,2,STAINED_GLASS:15)
Block(-6,44,3,STAINED_GLASS:15)
Block(-6,44,4,STAINED_GLASS:15)
Block(-6,44,6,CONCRETE:8)
Block(-6,44,7,CONCRETE:8)
Block(-6,44,8,CONCRETE:8)
Block(-6,45,-2,STAINED_GLASS:15)
Block(-6,45,1,STAINED_GLASS:15)
Block(-6,45,2,STAINED_GLASS:15)
Block(-6,45,3,STAINED_GLASS:15)
Block(-6,45,4,STAINED_GLASS:15)
Block(-6,45,6,CONCRETE:8)
Block(-6,45,7,CONCRETE:8)
Block(-6,45,8,CONCRETE:8)
Block(-6,46,-2,STAINED_GLASS:15)
Block(-6,46,1,STAINED_GLASS:15)
Block(-6,46,2,STAINED_GLASS:15)
Block(-6,46,3,STAINED_GLASS:15)
Block(-6,46,4,STAINED_GLASS:15)
Block(-6,46,6,CONCRETE:8)
Block(-6,46,7,CONCRETE:8)
Block(-6,46,8,CONCRETE:8)
Block(-6,47,-7,CONCRETE:8)
Block(-6,47,-6,CONCRETE:8)
Block(-6,47,-5,CONCRETE:8)
Block(-6,47,-4,CONCRETE:8)
Block(-6,47,-3,CONCRETE:8)
Block(-6,47,-2,STAINED_GLASS:15)
Block(-6,47,1,STAINED_GLASS:15)
Block(-6,47,2,STAINED_GLASS:15)
Block(-6,47,3,STAINED_GLASS:15)
Block(-6,47,4,STAINED_GLASS:15)
Block(-6,47,6,CONCRETE:8)
Block(-6,47,7,CONCRETE:8)
Block(-6,47,8,CONCRETE:8)
Block(-6,48,-2,STAINED_GLASS:15)
Block(-6,48,1,STAINED_GLASS:15)
Block(-6,48,2,STAINED_GLASS:15)
Block(-6,48,3,STAINED_GLASS:15)
Block(-6,48,4,STAINED_GLASS:15)
Block(-6,48,6,CONCRETE:8)
Block(-6,48,7,CONCRETE:8)
Block(-6,48,8,CONCRETE:8)
Block(-6,49,-2,STAINED_GLASS:15)
Block(-6,49,1,STAINED_GLASS:15)
Block(-6,49,2,STAINED_GLASS:15)
Block(-6,49,3,STAINED_GLASS:15)
Block(-6,49,4,STAINED_GLASS:15)
Block(-6,49,6,CONCRETE:8)
Block(-6,49,7,CONCRETE:8)
Block(-6,49,8,CONCRETE:8)
Block(-6,50,-2,STAINED_GLASS:15)
Block(-6,50,1,STAINED_GLASS:15)
Block(-6,50,2,STAINED_GLASS:15)
Block(-6,50,3,STAINED_GLASS:15)
Block(-6,50,4,STAINED_GLASS:15)
Block(-6,50,6,CONCRETE:8)
Block(-6,50,7,CONCRETE:8)
Block(-6,50,8,CONCRETE:8)
Block(-6,51,-2,STAINED_GLASS:15)
Block(-6,51,1,STAINED_GLASS:15)
Block(-6,51,2,STAINED_GLASS:15)
Block(-6,51,3,STAINED_GLASS:15)
Block(-6,51,4,STAINED_GLASS:15)
Block(-6,51,6,CONCRETE:8)
Block(-6,51,7,CONCRETE:8)
Block(-6,51,8,CONCRETE:8)
Block(-6,52,-2,STAINED_GLASS:15)
Block(-6,52,1,STAINED_GLASS:15)
Block(-6,52,2,STAINED_GLASS:15)
Block(-6,52,3,STAINED_GLASS:15)
Block(-6,52,4,STAINED_GLASS:15)
Block(-6,52,6,CONCRETE:8)
Block(-6,52,7,CONCRETE:8)
Block(-6,52,8,CONCRETE:8)
Block(-6,53,-2,STAINED_GLASS:15)
Block(-6,53,1,STAINED_GLASS:15)
Block(-6,53,2,STAINED_GLASS:15)
Block(-6,53,3,STAINED_GLASS:15)
Block(-6,53,4,STAINED_GLASS:15)
Block(-6,53,6,CONCRETE:8)
Block(-6,53,7,CONCRETE:8)
Block(-6,53,8,CONCRETE:8)
Block(-6,54,-2,STAINED_GLASS:15)
Block(-6,54,1,STAINED_GLASS:15)
Block(-6,54,2,STAINED_GLASS:15)
Block(-6,54,3,STAINED_GLASS:15)
Block(-6,54,4,STAINED_GLASS:15)
Block(-6,54,6,CONCRETE:8)
Block(-6,54,7,CONCRETE:8)
Block(-6,54,8,CONCRETE:8)
Block(-6,55,-7,CONCRETE:8)
Block(-6,55,-6,CONCRETE:8)
Block(-6,55,-5,CONCRETE:8)
Block(-6,55,-4,CONCRETE:8)
Block(-6,55,-3,CONCRETE:8)
Block(-6,55,-2,STAINED_GLASS:15)
Block(-6,55,1,STAINED_GLASS:15)
Block(-6,55,2,STAINED_GLASS:15)
Block(-6,55,3,STAINED_GLASS:15)
Block(-6,55,4,STAINED_GLASS:15)
Block(-6,55,6,CONCRETE:8)
Block(-6,55,7,CONCRETE:8)
Block(-6,55,8,CONCRETE:8)
Block(-6,56,-2,STAINED_GLASS:15)
Block(-6,56,1,STAINED_GLASS:15)
Block(-6,56,2,STAINED_GLASS:15)
Block(-6,56,3,STAINED_GLASS:15)
Block(-6,56,4,STAINED_GLASS:15)
Block(-6,56,6,CONCRETE:8)
Block(-6,56,7,CONCRETE:8)
Block(-6,56,8,CONCRETE:8)
Block(-6,57,-2,STAINED_GLASS:15)
Block(-6,57,1,STAINED_GLASS:15)
Block(-6,57,2,STAINED_GLASS:15)
Block(-6,57,3,STAINED_GLASS:15)
Block(-6,57,4,STAINED_GLASS:15)
Block(-6,57,6,CONCRETE:8)
Block(-6,57,7,CONCRETE:8)
Block(-6,57,8,CONCRETE:8)
Block(-6,58,-2,STAINED_GLASS:15)
Block(-6,58,1,STAINED_GLASS:15)
Block(-6,58,2,STAINED_GLASS:15)
Block(-6,58,3,STAINED_GLASS:15)
Block(-6,58,4,STAINED_GLASS:15)
Block(-6,58,6,CONCRETE:8)
Block(-6,58,7,CONCRETE:8)
Block(-6,58,8,CONCRETE:8)
Block(-6,59,-2,STAINED_GLASS:15)
Block(-6,59,1,STAINED_GLASS:15)
Block(-6,59,2,STAINED_GLASS:15)
Block(-6,59,3,STAINED_GLASS:15)
Block(-6,59,4,STAINED_GLASS:15)
Block(-6,59,6,CONCRETE:8)
Block(-6,59,7,CONCRETE:8)
Block(-6,59,8,CONCRETE:8)
Block(-6,60,-2,STAINED_GLASS:15)
Block(-6,60,1,STAINED_GLASS:15)
Block(-6,60,2,STAINED_GLASS:15)
Block(-6,60,3,STAINED_GLASS:15)
Block(-6,60,4,STAINED_GLASS:15)
Block(-6,60,6,CONCRETE:8)
Block(-6,60,7,CONCRETE:8)
Block(-6,60,8,CONCRETE:8)
Block(-6,61,-2,STAINED_GLASS:15)
Block(-6,61,1,STAINED_GLASS:15)
Block(-6,61,2,STAINED_GLASS:15)
Block(-6,61,3,STAINED_GLASS:15)
Block(-6,61,4,STAINED_GLASS:15)
Block(-6,62,-2,STAINED_GLASS:15)
Block(-6,62,1,STAINED_GLASS:15)
Block(-6,62,2,STAINED_GLASS:15)
Block(-6,62,3,STAINED_GLASS:15)
Block(-6,62,4,STAINED_GLASS:15)
Block(-6,63,-7,CONCRETE:8)
Block(-6,63,-6,CONCRETE:8)
Block(-6,63,-5,CONCRETE:8)
Block(-6,63,-4,CONCRETE:8)
Block(-6,63,-3,CONCRETE:8)
Block(-6,63,-2,STAINED_GLASS:15)
Block(-6,63,1,STAINED_GLASS:15)
Block(-6,63,2,STAINED_GLASS:15)
Block(-6,63,3,STAINED_GLASS:15)
Block(-6,63,4,STAINED_GLASS:15)
Block(-6,64,-2,STAINED_GLASS:15)
Block(-6,64,1,STAINED_GLASS:15)
Block(-6,64,2,STAINED_GLASS:15)
Block(-6,64,3,STAINED_GLASS:15)
Block(-6,64,4,STAINED_GLASS:15)
Block(-6,65,-2,STAINED_GLASS:15)
Block(-6,65,1,STAINED_GLASS:15)
Block(-6,65,2,STAINED_GLASS:15)
Block(-6,65,3,STAINED_GLASS:15)
Block(-6,65,4,STAINED_GLASS:15)
Block(-6,66,-2,STAINED_GLASS:15)
Block(-6,66,1,STAINED_GLASS:15)
Block(-6,66,2,STAINED_GLASS:15)
Block(-6,66,3,STAINED_GLASS:15)
Block(-6,66,4,STAINED_GLASS:15)
Block(-6,67,-2,STAINED_GLASS:15)
Block(-6,67,1,STAINED_GLASS:15)
Block(-6,67,2,STAINED_GLASS:15)
Block(-6,67,3,STAINED_GLASS:15)
Block(-6,67,4,STAINED_GLASS:15)
Block(-6,68,-2,STAINED_GLASS:15)
Block(-6,68,1,STAINED_GLASS:15)
Block(-6,68,2,STAINED_GLASS:15)
Block(-6,68,3,STAINED_GLASS:15)
Block(-6,68,4,STAINED_GLASS:15)
Block(-6,69,-2,STAINED_GLASS:15)
Block(-6,69,1,STAINED_GLASS:15)
Block(-6,69,2,STAINED_GLASS:15)
Block(-6,69,3,STAINED_GLASS:15)
Block(-6,69,4,STAINED_GLASS:15)
Block(-6,70,-2,STAINED_GLASS:15)
Block(-6,70,1,STAINED_GLASS:15)
Block(-6,70,2,STAINED_GLASS:15)
Block(-6,70,3,STAINED_GLASS:15)
Block(-6,70,4,STAINED_GLASS:15)
Block(-6,71,-7,CONCRETE:8)
Block(-6,71,-6,CONCRETE:8)
Block(-6,71,-5,CONCRETE:8)
Block(-6,71,-4,CONCRETE:8)
Block(-6,71,-3,CONCRETE:8)
Block(-6,71,-2,STAINED_GLASS:15)
Block(-6,71,1,STAINED_GLASS:15)
Block(-6,71,2,STAINED_GLASS:15)
Block(-6,71,3,STAINED_GLASS:15)
Block(-6,71,4,STAINED_GLASS:15)
Block(-6,72,-2,STAINED_GLASS:15)
Block(-6,72,1,STAINED_GLASS:15)
Block(-6,72,2,STAINED_GLASS:15)
Block(-6,72,3,STAINED_GLASS:15)
Block(-6,72,4,STAINED_GLASS:15)
Block(-6,73,-2,STAINED_GLASS:15)
Block(-6,73,1,STAINED_GLASS:15)
Block(-6,73,2,STAINED_GLASS:15)
Block(-6,73,3,STAINED_GLASS:15)
Block(-6,73,4,STAINED_GLASS:15)
Block(-6,74,-2,STAINED_GLASS:15)
Block(-6,74,1,STAINED_GLASS:15)
Block(-6,74,2,STAINED_GLASS:15)
Block(-6,74,3,STAINED_GLASS:15)
Block(-6,74,4,STAINED_GLASS:15)
Block(-6,75,-2,STAINED_GLASS:15)
Block(-6,75,1,STAINED_GLASS:15)
Block(-6,75,2,STAINED_GLASS:15)
Block(-6,75,3,STAINED_GLASS:15)
Block(-6,75,4,STAINED_GLASS:15)
Block(-6,76,-2,STAINED_GLASS:15)
Block(-6,76,1,STAINED_GLASS:15)
Block(-6,76,2,STAINED_GLASS:15)
Block(-6,76,3,STAINED_GLASS:15)
Block(-6,76,4,STAINED_GLASS:15)
Block(-6,77,-2,STAINED_GLASS:15)
Block(-6,77,1,STAINED_GLASS:15)
Block(-6,77,2,STAINED_GLASS:15)
Block(-6,77,3,STAINED_GLASS:15)
Block(-6,77,4,STAINED_GLASS:15)
Block(-6,78,-2,STAINED_GLASS:15)
Block(-6,78,1,STAINED_GLASS:15)
Block(-6,78,2,STAINED_GLASS:15)
Block(-6,78,3,STAINED_GLASS:15)
Block(-6,78,4,STAINED_GLASS:15)
Block(-6,79,-7,CONCRETE:8)
Block(-6,79,-6,CONCRETE:8)
Block(-6,79,-5,CONCRETE:8)
Block(-6,79,-4,CONCRETE:8)
Block(-6,79,-3,CONCRETE:8)
Block(-6,79,-2,STAINED_GLASS:15)
Block(-6,79,1,STAINED_GLASS:15)
Block(-6,79,2,STAINED_GLASS:15)
Block(-6,79,3,STAINED_GLASS:15)
Block(-6,79,4,STAINED_GLASS:15)
Block(-6,80,-2,STAINED_GLASS:15)
Block(-6,80,1,CONCRETE:15)
Block(-6,80,2,CONCRETE:15)
Block(-6,80,3,CONCRETE:15)
Block(-6,80,4,CONCRETE:15)
Block(-6,81,-2,STAINED_GLASS:15)
Block(-6,81,1,CONCRETE:15)
Block(-6,81,2,CONCRETE:15)
Block(-6,81,3,CONCRETE:15)
Block(-6,81,4,CONCRETE:15)
Block(-6,82,-2,STAINED_GLASS:15)
Block(-6,82,1,CONCRETE:15)
Block(-6,82,2,CONCRETE:15)
Block(-6,82,3,CONCRETE:15)
Block(-6,82,4,CONCRETE:15)
Block(-6,83,-2,STAINED_GLASS:15)
Block(-6,84,-2,STAINED_GLASS:15)
Block(-6,85,-2,STAINED_GLASS:15)
Block(-6,86,-2,STAINED_GLASS:15)
Block(-6,87,-7,CONCRETE:8)
Block(-6,87,-6,CONCRETE:8)
Block(-6,87,-5,CONCRETE:8)
Block(-6,87,-4,CONCRETE:8)
Block(-6,87,-3,CONCRETE:8)
Block(-6,87,-2,STAINED_GLASS:15)
Block(-6,88,-2,STAINED_GLASS:15)
Block(-6,89,-2,STAINED_GLASS:15)
Block(-6,90,-2,STAINED_GLASS:15)
Block(-6,91,-2,STAINED_GLASS:15)
Block(-6,92,-2,STAINED_GLASS:15)
Block(-6,93,-2,STAINED_GLASS:15)
Block(-6,94,-2,STAINED_GLASS:15)
Block(-6,95,-7,CONCRETE:8)
Block(-6,95,-6,CONCRETE:8)
Block(-6,95,-5,CONCRETE:8)
Block(-6,95,-4,CONCRETE:8)
Block(-6,95,-3,CONCRETE:8)
Block(-6,95,-2,STAINED_GLASS:15)
Block(-6,96,-2,STAINED_GLASS:15)
Block(-6,97,-2,STAINED_GLASS:15)
Block(-6,98,-2,STAINED_GLASS:15)
Block(-6,99,-2,STAINED_GLASS:15)
Block(-6,100,-2,STAINED_GLASS:15)
Block(-6,101,-2,STAINED_GLASS:15)
Block(-6,102,-2,STAINED_GLASS:15)
Block(-6,103,-7,CONCRETE:8)
Block(-6,103,-6,CONCRETE:8)
Block(-6,103,-5,CONCRETE:8)
Block(-6,103,-4,CONCRETE:8)
Block(-6,103,-3,CONCRETE:8)
Block(-6,103,-2,STAINED_GLASS:15)
Block(-6,104,-2,STAINED_GLASS:15)
Block(-6,105,-2,STAINED_GLASS:15)
Block(-6,106,-2,STAINED_GLASS:15)
Block(-6,107,-2,STAINED_GLASS:15)
Block(-6,108,-2,STAINED_GLASS:15)
Block(-6,109,-2,STAINED_GLASS:15)
Block(-6,110,-2,STAINED_GLASS:15)
Block(-6,111,-7,CONCRETE:8)
Block(-6,111,-6,CONCRETE:8)
Block(-6,111,-5,CONCRETE:8)
Block(-6,111,-4,CONCRETE:8)
Block(-6,111,-3,CONCRETE:8)
Block(-6,111,-2,STAINED_GLASS:15)
Block(-6,112,-2,STAINED_GLASS:15)
Block(-6,113,-2,STAINED_GLASS:15)
Block(-6,114,-2,STAINED_GLASS:15)
Block(-6,115,-2,STAINED_GLASS:15)
Block(-6,116,-2,STAINED_GLASS:15)
Block(-6,117,-2,STAINED_GLASS:15)
Block(-6,118,-2,CONCRETE:8)
Block(-6,119,-7,CONCRETE:8)
Block(-6,119,-6,CONCRETE:8)
Block(-6,119,-5,CONCRETE:8)
Block(-6,119,-4,CONCRETE:8)
Block(-6,119,-3,CONCRETE:8)
Block(-6,119,-2,CONCRETE:8)
Block(-6,120,-7,CONCRETE:8)
Block(-6,120,-6,CONCRETE:8)
Block(-6,120,-5,CONCRETE:8)
Block(-6,120,-4,CONCRETE:8)
Block(-6,120,-3,CONCRETE:8)
Block(-6,120,-2,CONCRETE:8)
Block(-5,0,-7,CONCRETE:7)
Block(-5,0,-6,CONCRETE:7)
Block(-5,0,-5,CONCRETE:7)
Block(-5,0,-4,CONCRETE:7)
Block(-5,0,-3,CONCRETE:7)
Block(-5,0,-2,CONCRETE:7)
Block(-5,0,-1,CONCRETE:7)
Block(-5,0,0,CONCRETE:7)
Block(-5,0,1,CONCRETE:7)
Block(-5,0,2,CONCRETE:7)
Block(-5,0,3,CONCRETE:7)
Block(-5,0,4,CONCRETE:7)
Block(-5,0,5,CONCRETE:7)
Block(-5,0,6,CONCRETE:7)
Block(-5,0,7,CONCRETE:7)
Block(-5,0,8,CONCRETE:7)
Block(-5,1,-7,CONCRETE:7)
Block(-5,1,-6,CONCRETE:7)
Block(-5,1,-5,CONCRETE:7)
Block(-5,1,-4,CONCRETE:7)
Block(-5,1,-3,CONCRETE:7)
Block(-5,1,-2,CONCRETE:7)
Block(-5,1,-1,CONCRETE:7)
Block(-5,1,0,CONCRETE:7)
Block(-5,1,1,CONCRETE:7)
Block(-5,1,2,CONCRETE:7)
Block(-5,1,3,CONCRETE:7)
Block(-5,1,4,CONCRETE:7)
Block(-5,1,5,CONCRETE:7)
Block(-5,1,6,CONCRETE:7)
Block(-5,1,7,CONCRETE:7)
Block(-5,1,8,CONCRETE:7)
Block(-5,2,-7,CONCRETE:7)
Block(-5,2,-6,CONCRETE:7)
Block(-5,2,-5,CONCRETE:7)
Block(-5,2,-4,CONCRETE:7)
Block(-5,2,-3,CONCRETE:7)
Block(-5,2,-2,CONCRETE:7)
Block(-5,2,-1,CONCRETE:7)
Block(-5,2,0,CONCRETE:7)
Block(-5,2,1,CONCRETE:7)
Block(-5,2,2,CONCRETE:7)
Block(-5,2,3,CONCRETE:7)
Block(-5,2,4,CONCRETE:7)
Block(-5,2,5,CONCRETE:7)
Block(-5,2,6,CONCRETE:7)
Block(-5,2,7,CONCRETE:7)
Block(-5,2,8,CONCRETE:7)
Block(-5,3,-7,CONCRETE:7)
Block(-5,3,-6,SMOOTH_STAIRS:1)
Block(-5,3,-5,SMOOTH_STAIRS:1)
Block(-5,3,-4,CONCRETE:7)
Block(-5,3,-3,SMOOTH_STAIRS:1)
Block(-5,3,-2,SMOOTH_STAIRS:1)
Block(-5,3,-1,CONCRETE:7)
Block(-5,3,0,SMOOTH_STAIRS:1)
Block(-5,3,1,SMOOTH_STAIRS:1)
Block(-5,3,2,CONCRETE:7)
Block(-5,3,3,SMOOTH_STAIRS:1)
Block(-5,3,4,SMOOTH_STAIRS:1)
Block(-5,3,5,CONCRETE:7)
Block(-5,3,6,SMOOTH_STAIRS:1)
Block(-5,3,7,SMOOTH_STAIRS:1)
Block(-5,3,8,CONCRETE:7)
Block(-5,4,-7,CONCRETE:7)
Block(-5,4,-6,COBBLE_WALL:0)
Block(-5,4,-5,COBBLE_WALL:0)
Block(-5,4,-4,CONCRETE:7)
Block(-5,4,-3,COBBLE_WALL:0)
Block(-5,4,-2,COBBLE_WALL:0)
Block(-5,4,-1,CONCRETE:7)
Block(-5,4,0,COBBLE_WALL:0)
Block(-5,4,1,COBBLE_WALL:0)
Block(-5,4,2,CONCRETE:7)
Block(-5,4,3,COBBLE_WALL:0)
Block(-5,4,4,COBBLE_WALL:0)
Block(-5,4,5,CONCRETE:7)
Block(-5,4,6,COBBLE_WALL:0)
Block(-5,4,7,COBBLE_WALL:0)
Block(-5,4,8,CONCRETE:7)
Block(-5,5,-7,CONCRETE:7)
Block(-5,5,-6,SMOOTH_STAIRS:5)
Block(-5,5,-5,SMOOTH_STAIRS:5)
Block(-5,5,-4,CONCRETE:7)
Block(-5,5,-3,SMOOTH_STAIRS:5)
Block(-5,5,-2,SMOOTH_STAIRS:5)
Block(-5,5,-1,CONCRETE:7)
Block(-5,5,0,SMOOTH_STAIRS:5)
Block(-5,5,1,SMOOTH_STAIRS:5)
Block(-5,5,2,CONCRETE:7)
Block(-5,5,3,SMOOTH_STAIRS:5)
Block(-5,5,4,SMOOTH_STAIRS:5)
Block(-5,5,5,CONCRETE:7)
Block(-5,5,6,SMOOTH_STAIRS:5)
Block(-5,5,7,SMOOTH_STAIRS:5)
Block(-5,5,8,CONCRETE:7)
Block(-5,6,-7,CONCRETE:7)
Block(-5,6,-6,CONCRETE:7)
Block(-5,6,-5,CONCRETE:7)
Block(-5,6,-4,CONCRETE:7)
Block(-5,6,-3,CONCRETE:7)
Block(-5,6,-2,CONCRETE:7)
Block(-5,6,-1,CONCRETE:7)
Block(-5,6,0,CONCRETE:7)
Block(-5,6,1,CONCRETE:7)
Block(-5,6,2,CONCRETE:7)
Block(-5,6,3,CONCRETE:7)
Block(-5,6,4,CONCRETE:7)
Block(-5,6,5,CONCRETE:7)
Block(-5,6,6,CONCRETE:7)
Block(-5,6,7,CONCRETE:7)
Block(-5,6,8,CONCRETE:7)
Block(-5,7,-7,CONCRETE:7)
Block(-5,7,-6,CONCRETE:7)
Block(-5,7,-5,CONCRETE:7)
Block(-5,7,-4,CONCRETE:7)
Block(-5,7,-3,CONCRETE:7)
Block(-5,7,-2,CONCRETE:7)
Block(-5,7,-1,CONCRETE:7)
Block(-5,7,0,CONCRETE:7)
Block(-5,7,1,CONCRETE:7)
Block(-5,7,2,CONCRETE:7)
Block(-5,7,3,CONCRETE:7)
Block(-5,7,4,CONCRETE:7)
Block(-5,7,5,CONCRETE:7)
Block(-5,7,6,CONCRETE:7)
Block(-5,7,7,CONCRETE:7)
Block(-5,7,8,CONCRETE:7)
Block(-5,8,-7,IRON_TRAPDOOR:9)
Block(-5,8,-6,AIR:0)
Block(-5,8,-5,AIR:0)
Block(-5,8,-4,AIR:0)
Block(-5,8,-3,IRON_TRAPDOOR:8)
Block(-5,8,-2,CONCRETE:7)
Block(-5,8,-1,CONCRETE:7)
Block(-5,8,0,CONCRETE:7)
Block(-5,8,1,STAINED_GLASS_PANE:11)
Block(-5,8,2,CONCRETE:7)
Block(-5,8,3,CONCRETE:7)
Block(-5,8,4,WOOD_STAIRS:3)
Block(-5,8,5,AIR:0)
Block(-5,8,6,TRAP_DOOR:4)
Block(-5,8,7,STANDING_BANNER:8,NBT/skyscraper_2x2_04/24-bannerC0R16.nbt)
Block(-5,8,8,CONCRETE:7)
Block(-5,9,-7,AIR:0)
Block(-5,9,-6,AIR:0)
Block(-5,9,-5,AIR:0)
Block(-5,9,-4,AIR:0)
Block(-5,9,-3,IRON_FENCE:0)
Block(-5,9,-2,CONCRETE:7)
Block(-5,9,-1,CONCRETE:7)
Block(-5,9,0,CONCRETE:7)
Block(-5,9,1,STAINED_GLASS_PANE:11)
Block(-5,9,2,CONCRETE:7)
Block(-5,9,3,CONCRETE:7)
Block(-5,9,4,AIR:0)
Block(-5,9,5,AIR:0)
Block(-5,9,6,AIR:0)
Block(-5,9,7,IRON_TRAPDOOR:0)
Block(-5,9,8,CONCRETE:7)
Block(-5,10,-7,IRON_TRAPDOOR:1)
Block(-5,10,-6,AIR:0)
Block(-5,10,-5,IRON_TRAPDOOR:10)
Block(-5,10,-4,AIR:0)
Block(-5,10,-3,IRON_TRAPDOOR:0)
Block(-5,10,-2,CONCRETE:7)
Block(-5,10,-1,CONCRETE:7)
Block(-5,10,0,CONCRETE:7)
Block(-5,10,1,STAINED_GLASS_PANE:11)
Block(-5,10,2,CONCRETE:7)
Block(-5,10,3,CONCRETE:7)
Block(-5,10,4,IRON_TRAPDOOR:9)
Block(-5,10,5,AIR:0)
Block(-5,10,6,IRON_TRAPDOOR:11)
Block(-5,10,7,IRON_TRAPDOOR:8)
Block(-5,10,8,CONCRETE:7)
Block(-5,11,-7,CONCRETE:8)
Block(-5,11,-6,CONCRETE:8)
Block(-5,11,-5,CONCRETE:8)
Block(-5,11,-4,CONCRETE:8)
Block(-5,11,-3,IRON_TRAPDOOR:0)
Block(-5,11,-2,CONCRETE:7)
Block(-5,11,-1,CONCRETE:7)
Block(-5,11,0,CONCRETE:7)
Block(-5,11,1,CONCRETE:7)
Block(-5,11,2,CONCRETE:7)
Block(-5,11,3,CONCRETE:7)
Block(-5,11,4,IRON_FENCE:0)
Block(-5,11,5,AIR:0)
Block(-5,11,6,CONCRETE:8)
Block(-5,11,7,REDSTONE_LAMP_OFF:0)
Block(-5,11,8,CONCRETE:7)
Block(-5,12,-7,CONCRETE:7)
Block(-5,12,-6,CONCRETE:7)
Block(-5,12,-5,CONCRETE:7)
Block(-5,12,-4,CONCRETE:7)
Block(-5,12,-3,CONCRETE:7)
Block(-5,12,-2,CONCRETE:7)
Block(-5,12,-1,CONCRETE:7)
Block(-5,12,0,CONCRETE:7)
Block(-5,12,1,CONCRETE:7)
Block(-5,12,2,CONCRETE:7)
Block(-5,12,3,CONCRETE:7)
Block(-5,12,4,CONCRETE:7)
Block(-5,12,5,CONCRETE:7)
Block(-5,12,6,CONCRETE:7)
Block(-5,12,7,CONCRETE:7)
Block(-5,12,8,CONCRETE:7)
Block(-5,13,-7,CONCRETE:7)
Block(-5,13,-6,CONCRETE:7)
Block(-5,13,-5,CONCRETE:7)
Block(-5,13,-4,CONCRETE:7)
Block(-5,13,-3,CONCRETE:7)
Block(-5,13,-2,CONCRETE:7)
Block(-5,13,-1,CONCRETE:7)
Block(-5,13,0,CONCRETE:7)
Block(-5,13,1,CONCRETE:7)
Block(-5,13,2,CONCRETE:7)
Block(-5,13,3,CONCRETE:7)
Block(-5,13,4,CONCRETE:7)
Block(-5,13,5,CONCRETE:7)
Block(-5,13,6,CONCRETE:7)
Block(-5,13,7,CONCRETE:7)
Block(-5,13,8,CONCRETE:7)
Block(-5,14,-7,CONCRETE:7)
Block(-5,14,-6,CONCRETE:7)
Block(-5,14,-5,CONCRETE:7)
Block(-5,14,-4,CONCRETE:7)
Block(-5,14,-3,CONCRETE:7)
Block(-5,14,-2,CONCRETE:7)
Block(-5,14,-1,CONCRETE:7)
Block(-5,14,0,CONCRETE:7)
Block(-5,14,1,CONCRETE:7)
Block(-5,14,2,CONCRETE:7)
Block(-5,14,3,CONCRETE:7)
Block(-5,14,4,CONCRETE:7)
Block(-5,14,5,CONCRETE:7)
Block(-5,14,6,CONCRETE:7)
Block(-5,14,7,CONCRETE:7)
Block(-5,14,8,CONCRETE:7)
Block(-5,15,-7,CONCRETE:7)
Block(-5,15,-6,CONCRETE:7)
Block(-5,15,-5,CONCRETE:7)
Block(-5,15,-4,CONCRETE:7)
Block(-5,15,-3,CONCRETE:7)
Block(-5,15,-2,CONCRETE:7)
Block(-5,15,-1,CONCRETE:7)
Block(-5,15,0,CONCRETE:7)
Block(-5,15,1,CONCRETE:7)
Block(-5,15,2,CONCRETE:7)
Block(-5,15,3,CONCRETE:7)
Block(-5,15,4,CONCRETE:7)
Block(-5,15,5,CONCRETE:7)
Block(-5,15,6,CONCRETE:7)
Block(-5,15,7,CONCRETE:7)
Block(-5,15,8,CONCRETE:7)
Block(-5,16,-7,CONCRETE:7)
Block(-5,16,-6,CONCRETE:7)
Block(-5,16,-5,CONCRETE:7)
Block(-5,16,-4,CONCRETE:7)
Block(-5,16,-3,CONCRETE:7)
Block(-5,16,-2,CONCRETE:7)
Block(-5,16,-1,CONCRETE:7)
Block(-5,16,0,CONCRETE:7)
Block(-5,16,1,CONCRETE:7)
Block(-5,16,2,CONCRETE:7)
Block(-5,16,3,CONCRETE:7)
Block(-5,16,4,CONCRETE:7)
Block(-5,16,5,CONCRETE:7)
Block(-5,16,6,CONCRETE:7)
Block(-5,16,7,CONCRETE:7)
Block(-5,16,8,CONCRETE:7)
Block(-5,17,-7,CONCRETE:7)
Block(-5,17,-6,CONCRETE:7)
Block(-5,17,-5,CONCRETE:7)
Block(-5,17,-4,CONCRETE:7)
Block(-5,17,-3,CONCRETE:7)
Block(-5,17,-2,CONCRETE:7)
Block(-5,17,-1,CONCRETE:7)
Block(-5,17,0,CONCRETE:7)
Block(-5,17,1,CONCRETE:7)
Block(-5,17,2,CONCRETE:7)
Block(-5,17,3,CONCRETE:7)
Block(-5,17,4,CONCRETE:7)
Block(-5,17,5,CONCRETE:7)
Block(-5,17,6,CONCRETE:7)
Block(-5,17,7,CONCRETE:7)
Block(-5,17,8,CONCRETE:7)
Block(-5,18,-7,CONCRETE:8)
Block(-5,18,-6,CONCRETE:8)
Block(-5,18,-5,CONCRETE:8)
Block(-5,18,-4,CONCRETE:8)
Block(-5,18,-3,CONCRETE:8)
Block(-5,18,-2,CONCRETE:8)
Block(-5,18,1,CONCRETE:15)
Block(-5,18,2,CONCRETE:15)
Block(-5,18,3,CONCRETE:15)
Block(-5,18,4,CONCRETE:15)
Block(-5,18,6,CONCRETE:8)
Block(-5,18,7,CONCRETE:8)
Block(-5,18,8,CONCRETE:8)
Block(-5,19,-7,TRIPWIRE_HOOK:3)
Block(-5,19,-6,IRON_DOOR_BLOCK:3)
Block(-5,19,-2,STAINED_GLASS:15)
Block(-5,19,1,STAINED_GLASS:15)
Block(-5,19,2,STAINED_GLASS:15)
Block(-5,19,3,STAINED_GLASS:15)
Block(-5,19,4,STAINED_GLASS:15)
Block(-5,19,6,STAINED_GLASS:15)
Block(-5,19,7,STAINED_GLASS:15)
Block(-5,19,8,STAINED_GLASS:15)
Block(-5,20,-7,WALL_BANNER:5,NBT/skyscraper_2x2_04/27-bannerC0R16.nbt)
Block(-5,20,-6,IRON_DOOR_BLOCK:8)
Block(-5,20,-2,STAINED_GLASS:15)
Block(-5,20,1,STAINED_GLASS:15)
Block(-5,20,2,STAINED_GLASS:15)
Block(-5,20,3,STAINED_GLASS:15)
Block(-5,20,4,STAINED_GLASS:15)
Block(-5,20,6,STAINED_GLASS:15)
Block(-5,20,7,STAINED_GLASS:15)
Block(-5,20,8,STAINED_GLASS:15)
Block(-5,21,-6,CONCRETE:8)
Block(-5,21,-2,STAINED_GLASS:15)
Block(-5,21,1,STAINED_GLASS:15)
Block(-5,21,2,STAINED_GLASS:15)
Block(-5,21,3,STAINED_GLASS:15)
Block(-5,21,4,STAINED_GLASS:15)
Block(-5,21,6,STAINED_GLASS:15)
Block(-5,21,7,STAINED_GLASS:15)
Block(-5,21,8,STAINED_GLASS:15)
Block(-5,22,-6,CONCRETE:8)
Block(-5,22,-2,STAINED_GLASS:15)
Block(-5,22,1,STAINED_GLASS:15)
Block(-5,22,2,STAINED_GLASS:15)
Block(-5,22,3,STAINED_GLASS:15)
Block(-5,22,4,STAINED_GLASS:15)
Block(-5,22,6,STAINED_GLASS:15)
Block(-5,22,7,STAINED_GLASS:15)
Block(-5,22,8,STAINED_GLASS:15)
Block(-5,23,-7,CONCRETE:8)
Block(-5,23,-6,CONCRETE:8)
Block(-5,23,-5,CONCRETE:8)
Block(-5,23,-4,CONCRETE:8)
Block(-5,23,-3,CONCRETE:8)
Block(-5,23,-2,STAINED_GLASS:15)
Block(-5,23,1,STAINED_GLASS:15)
Block(-5,23,2,STAINED_GLASS:15)
Block(-5,23,3,STAINED_GLASS:15)
Block(-5,23,4,STAINED_GLASS:15)
Block(-5,23,6,STAINED_GLASS:15)
Block(-5,23,7,STAINED_GLASS:15)
Block(-5,23,8,STAINED_GLASS:15)
Block(-5,24,-2,STAINED_GLASS:15)
Block(-5,24,1,STAINED_GLASS:15)
Block(-5,24,2,STAINED_GLASS:15)
Block(-5,24,3,STAINED_GLASS:15)
Block(-5,24,4,STAINED_GLASS:15)
Block(-5,24,6,STAINED_GLASS:15)
Block(-5,24,7,STAINED_GLASS:15)
Block(-5,24,8,STAINED_GLASS:15)
Block(-5,25,-2,STAINED_GLASS:15)
Block(-5,25,1,STAINED_GLASS:15)
Block(-5,25,2,STAINED_GLASS:15)
Block(-5,25,3,STAINED_GLASS:15)
Block(-5,25,4,STAINED_GLASS:15)
Block(-5,25,6,STAINED_GLASS:15)
Block(-5,25,7,STAINED_GLASS:15)
Block(-5,25,8,STAINED_GLASS:15)
Block(-5,26,-2,STAINED_GLASS:15)
Block(-5,26,1,STAINED_GLASS:15)
Block(-5,26,2,STAINED_GLASS:15)
Block(-5,26,3,STAINED_GLASS:15)
Block(-5,26,4,STAINED_GLASS:15)
Block(-5,26,6,STAINED_GLASS:15)
Block(-5,26,7,STAINED_GLASS:15)
Block(-5,26,8,STAINED_GLASS:15)
Block(-5,27,-2,STAINED_GLASS:15)
Block(-5,27,1,STAINED_GLASS:15)
Block(-5,27,2,STAINED_GLASS:15)
Block(-5,27,3,STAINED_GLASS:15)
Block(-5,27,4,STAINED_GLASS:15)
Block(-5,27,6,STAINED_GLASS:15)
Block(-5,27,7,STAINED_GLASS:15)
Block(-5,27,8,STAINED_GLASS:15)
Block(-5,28,-2,STAINED_GLASS:15)
Block(-5,28,1,STAINED_GLASS:15)
Block(-5,28,2,STAINED_GLASS:15)
Block(-5,28,3,STAINED_GLASS:15)
Block(-5,28,4,STAINED_GLASS:15)
Block(-5,28,6,STAINED_GLASS:15)
Block(-5,28,7,STAINED_GLASS:15)
Block(-5,28,8,STAINED_GLASS:15)
Block(-5,29,-2,STAINED_GLASS:15)
Block(-5,29,1,STAINED_GLASS:15)
Block(-5,29,2,STAINED_GLASS:15)
Block(-5,29,3,STAINED_GLASS:15)
Block(-5,29,4,STAINED_GLASS:15)
Block(-5,29,6,STAINED_GLASS:15)
Block(-5,29,7,STAINED_GLASS:15)
Block(-5,29,8,STAINED_GLASS:15)
Block(-5,30,-2,STAINED_GLASS:15)
Block(-5,30,1,STAINED_GLASS:15)
Block(-5,30,2,STAINED_GLASS:15)
Block(-5,30,3,STAINED_GLASS:15)
Block(-5,30,4,STAINED_GLASS:15)
Block(-5,30,6,STAINED_GLASS:15)
Block(-5,30,7,STAINED_GLASS:15)
Block(-5,30,8,STAINED_GLASS:15)
Block(-5,31,-7,CONCRETE:8)
Block(-5,31,-6,CONCRETE:8)
Block(-5,31,-5,CONCRETE:8)
Block(-5,31,-4,CONCRETE:8)
Block(-5,31,-3,CONCRETE:8)
Block(-5,31,-2,STAINED_GLASS:15)
Block(-5,31,1,STAINED_GLASS:15)
Block(-5,31,2,STAINED_GLASS:15)
Block(-5,31,3,STAINED_GLASS:15)
Block(-5,31,4,STAINED_GLASS:15)
Block(-5,31,6,STAINED_GLASS:15)
Block(-5,31,7,STAINED_GLASS:15)
Block(-5,31,8,STAINED_GLASS:15)
Block(-5,32,-2,STAINED_GLASS:15)
Block(-5,32,1,STAINED_GLASS:15)
Block(-5,32,2,STAINED_GLASS:15)
Block(-5,32,3,STAINED_GLASS:15)
Block(-5,32,4,STAINED_GLASS:15)
Block(-5,32,6,STAINED_GLASS:15)
Block(-5,32,7,STAINED_GLASS:15)
Block(-5,32,8,STAINED_GLASS:15)
Block(-5,33,-2,STAINED_GLASS:15)
Block(-5,33,1,STAINED_GLASS:15)
Block(-5,33,2,STAINED_GLASS:15)
Block(-5,33,3,STAINED_GLASS:15)
Block(-5,33,4,STAINED_GLASS:15)
Block(-5,33,6,STAINED_GLASS:15)
Block(-5,33,7,STAINED_GLASS:15)
Block(-5,33,8,STAINED_GLASS:15)
