
#######################################################################
# +-----------------------------------------------------------------+ #
# |                            BO4 object                           | #
# +-----------------------------------------------------------------+ #
#######################################################################

Author: NLBlackEagle

Description: No description given

SettingsMode: WriteDisable


#######################################################################
# +-----------------------------------------------------------------+ #
# |                          Main settings                          | #
# +-----------------------------------------------------------------+ #
#######################################################################

Frequency: 0

SpawnHeight: highestBlock

UseCenterForHighestBlock: true

##############################
# Height Limits for the BO4. #
##############################

MinHeight: 0

MaxHeight: 255

InheritBO3: 

InheritBO3Rotation: NORTH

OverrideChildSettings: true

OverrideParentHeight: false

CanOverride: true

BranchFrequency: 0

BranchFrequencyGroup: 

MustBeBelowOther: false

MustBeInside: 

CannotBeInside: 

ReplacesBO3: L4-M-CrossC0R0, L4-M-CrossC0R1, L4-M-CrossC0R2, L4-M-CrossC0R3, L4-M-CrossC1R0, L4-M-CrossC1R1, L4-M-CrossC1R2, L4-M-CrossC1R3, L4-M-CrossC2R0, L4-M-CrossC2R1, L4-M-CrossC2R2, L4-M-CrossC2R3, L4-M-CrossC3R0, L4-M-CrossC3R1, L4-M-CrossC3R2, L4-M-CrossC3R3, L4-M-Straigth-START_01-C0R0, L4-M-Straigth-START_01-C0R1, L4-M-Straigth-START_01-C1R0, L4-M-Straigth-START_01-C1R1, L4-M-Straigth-START_01-C2R0, L4-M-Straigth-START_01-C2R1, L4-M-Straigth-START_01-C3R0, L4-M-Straigth-START_01-C3R1, L4-M-Straigth-3CC0R0, L4-M-Straigth-3CC0R1, L4-M-Straigth-3CC0R2, L4-M-Straigth-3CC1R0, L4-M-Straigth-3CC1R1, L4-M-Straigth-3CC1R2, L4-M-Straigth-3CC2R0, L4-M-Straigth-3CC2R1, L4-M-Straigth-3CC2R2, L4-M-Straigth-3CC3R0, L4-M-Straigth-3CC3R1, L4-M-Straigth-3CC3R2, L4-M-Cross, skyscraper_2x2_01, skyscraper_2x2_02, skyscraper_2x2_03, skyscraper_2x2_04, skyscraper_2x2_05, skyscraper_3x3_01, skyscraper_3x3_02, skyscraper_3x3_03, L3-M-Straigth-2CC0R0, L3-M-Straigth-2CC0R1, L3-M-Straigth-2CC1R0, L3-M-Straigth-2CC1R1, L3-M-Straigth-2CC2R0, L3-M-Straigth-2CC2R1, L3-M-Straigth-2CC3R0, L3-M-Straigth-2CC3R1, L3-M-Straigth-3CC0R0, L3-M-Straigth-3CC0R1, L3-M-Straigth-3CC0R2, L3-M-Straigth-3CC1R0, L3-M-Straigth-3CC1R1, L3-M-Straigth-3CC1R2, L3-M-Straigth-3CC2R0, L3-M-Straigth-3CC2R1, L3-M-Straigth-3CC2R2, L3-M-Straigth-3CC3R0, L3-M-Straigth-3CC3R1, L3-M-Straigth-3CC3R2

MustBeInsideWorldBorders: false

CanSpawnOnWater: true

SpawnOnWaterOnly: false

SpawnUnderWater: false

SpawnAtWaterLevel: false

HeightOffset: 0

RemoveAir: false

ReplaceAbove: 

ReplaceBelow: 

ReplaceWithBiomeBlocks: true

ReplaceWithSurfaceBlock: GRASS

ReplaceWithGroundBlock: DIRT

ReplaceWithStoneBlock: STONE

SmoothRadius: 0

SmoothHeightOffset: 0

SmoothStartTop: false

SmoothStartWood: false

SmoothingSurfaceBlock: 

SmoothingGroundBlock: 

BO3Group: 

IsSpawnPoint: false

DoReplaceBlocks: true


#######################################################################
# +-----------------------------------------------------------------+ #
# |                              Blocks                             | #
# +-----------------------------------------------------------------+ #
#######################################################################

Block(-8,0,-7,CONCRETE:7)
Block(-8,0,-6,CONCRETE:7)
Block(-8,0,-5,CONCRETE:7)
Block(-8,0,-4,CONCRETE:7)
Block(-8,0,-3,CONCRETE:7)
Block(-8,0,-2,CONCRETE:7)
Block(-8,0,-1,CONCRETE:7)
Block(-8,0,0,CONCRETE:7)
Block(-8,0,1,CONCRETE:7)
Block(-8,0,2,CONCRETE:7)
Block(-8,0,3,CONCRETE:7)
Block(-8,0,4,CONCRETE:7)
Block(-8,0,5,CONCRETE:7)
Block(-8,0,6,CONCRETE:7)
Block(-8,0,7,CONCRETE:7)
Block(-8,0,8,CONCRETE:7)
Block(-8,1,-7,CONCRETE:7)
Block(-8,1,-6,AIR:0)
Block(-8,1,-5,AIR:0)
Block(-8,1,-4,AIR:0)
Block(-8,1,-3,AIR:0)
Block(-8,1,-2,AIR:0)
Block(-8,1,-1,AIR:0)
Block(-8,1,0,AIR:0)
Block(-8,1,1,AIR:0)
Block(-8,1,2,AIR:0)
Block(-8,1,3,AIR:0)
Block(-8,1,4,AIR:0)
Block(-8,1,5,AIR:0)
Block(-8,1,6,AIR:0)
Block(-8,1,7,AIR:0)
Block(-8,1,8,AIR:0)
Block(-8,2,-7,IRON_TRAPDOOR:8)
Block(-8,2,-6,IRON_TRAPDOOR:11)
Block(-8,2,-5,IRON_TRAPDOOR:11)
Block(-8,2,-4,IRON_TRAPDOOR:11)
Block(-8,2,-3,IRON_TRAPDOOR:9)
Block(-8,2,-2,IRON_TRAPDOOR:11)
Block(-8,2,-1,IRON_TRAPDOOR:11)
Block(-8,2,0,IRON_TRAPDOOR:9)
Block(-8,2,1,IRON_TRAPDOOR:11)
Block(-8,2,2,IRON_TRAPDOOR:11)
Block(-8,2,3,IRON_TRAPDOOR:9)
Block(-8,2,4,IRON_TRAPDOOR:11)
Block(-8,2,5,IRON_TRAPDOOR:11)
Block(-8,2,6,IRON_TRAPDOOR:9)
Block(-8,2,7,IRON_TRAPDOOR:11)
Block(-8,2,8,IRON_TRAPDOOR:11)
Block(-8,3,-7,AIR:0)
Block(-8,3,-6,AIR:0)
Block(-8,3,-5,AIR:0)
Block(-8,3,-4,AIR:0)
Block(-8,3,-3,AIR:0)
Block(-8,3,-2,AIR:0)
Block(-8,3,-1,AIR:0)
Block(-8,3,0,AIR:0)
Block(-8,3,1,AIR:0)
Block(-8,3,2,AIR:0)
Block(-8,3,3,AIR:0)
Block(-8,3,4,AIR:0)
Block(-8,3,5,AIR:0)
Block(-8,3,6,AIR:0)
Block(-8,3,7,AIR:0)
Block(-8,3,8,AIR:0)
Block(-8,4,-7,AIR:0)
Block(-8,4,-6,AIR:0)
Block(-8,4,-5,AIR:0)
Block(-8,4,-4,AIR:0)
Block(-8,4,-3,AIR:0)
Block(-8,4,-2,AIR:0)
Block(-8,4,-1,AIR:0)
Block(-8,4,0,AIR:0)
Block(-8,4,1,AIR:0)
Block(-8,4,2,AIR:0)
Block(-8,4,3,AIR:0)
Block(-8,4,4,AIR:0)
Block(-8,4,5,AIR:0)
Block(-8,4,6,AIR:0)
Block(-8,4,7,AIR:0)
Block(-8,4,8,AIR:0)
Block(-8,5,-7,AIR:0)
Block(-8,5,-6,AIR:0)
Block(-8,5,-5,STEP:8)
Block(-8,5,-4,STEP:8)
Block(-8,5,-3,AIR:0)
Block(-8,5,-2,STEP:8)
Block(-8,5,-1,STEP:8)
Block(-8,5,0,AIR:0)
Block(-8,5,1,STEP:8)
Block(-8,5,2,STEP:8)
Block(-8,5,3,AIR:0)
Block(-8,5,4,STEP:8)
Block(-8,5,5,STEP:8)
Block(-8,5,6,AIR:0)
Block(-8,5,7,STEP:8)
Block(-8,5,8,STEP:8)
Block(-8,6,-7,CONCRETE:7)
Block(-8,6,-6,CONCRETE:7)
Block(-8,6,-5,STEP:8)
Block(-8,6,-4,STEP:8)
Block(-8,6,-3,CONCRETE:7)
Block(-8,6,-2,STEP:8)
Block(-8,6,-1,STEP:8)
Block(-8,6,0,CONCRETE:7)
Block(-8,6,1,STEP:8)
Block(-8,6,2,STEP:8)
Block(-8,6,3,CONCRETE:7)
Block(-8,6,4,STEP:8)
Block(-8,6,5,STEP:8)
Block(-8,6,6,CONCRETE:7)
Block(-8,6,7,STEP:8)
Block(-8,6,8,STEP:8)
Block(-8,7,-7,CONCRETE:7)
Block(-8,7,-6,CONCRETE:7)
Block(-8,7,-5,CONCRETE:7)
Block(-8,7,-4,CONCRETE:7)
Block(-8,7,-3,CONCRETE:7)
Block(-8,7,-2,CONCRETE:7)
Block(-8,7,-1,CONCRETE:7)
Block(-8,7,0,CONCRETE:7)
Block(-8,7,1,CONCRETE:7)
Block(-8,7,2,CONCRETE:7)
Block(-8,7,3,CONCRETE:7)
Block(-8,7,4,CONCRETE:7)
Block(-8,7,5,CONCRETE:7)
Block(-8,7,6,CONCRETE:7)
Block(-8,7,7,CONCRETE:7)
Block(-8,7,8,CONCRETE:7)
Block(-8,8,-7,CONCRETE:7)
Block(-8,8,-6,CONCRETE:7)
Block(-8,8,-5,CONCRETE:7)
Block(-8,8,-4,CONCRETE:7)
Block(-8,8,-3,CONCRETE:7)
Block(-8,8,-2,CONCRETE:7)
Block(-8,8,-1,CONCRETE:7)
Block(-8,8,0,CONCRETE:7)
Block(-8,8,1,CONCRETE:7)
Block(-8,8,2,CONCRETE:7)
Block(-8,8,3,CONCRETE:7)
Block(-8,8,4,CONCRETE:7)
Block(-8,8,5,CONCRETE:7)
Block(-8,8,6,CONCRETE:7)
Block(-8,8,7,CONCRETE:7)
Block(-8,8,8,CONCRETE:7)
Block(-8,9,-7,CONCRETE:7)
Block(-8,9,-6,CONCRETE:8)
Block(-8,9,-5,CONCRETE:8)
Block(-8,9,-4,CONCRETE:15)
Block(-8,9,-3,CONCRETE:15)
Block(-8,9,-2,CONCRETE:8)
Block(-8,9,-1,CONCRETE:8)
Block(-8,9,0,CONCRETE:8)
Block(-8,9,1,CONCRETE:8)
Block(-8,9,2,CONCRETE:8)
Block(-8,9,3,CONCRETE:7)
Block(-8,9,4,CONCRETE:7)
Block(-8,9,5,CONCRETE:7)
Block(-8,9,6,CONCRETE:7)
Block(-8,9,7,CONCRETE:7)
Block(-8,9,8,CONCRETE:7)
Block(-8,10,-7,CONCRETE:7)
Block(-8,10,-6,CONCRETE:8)
Block(-8,10,-5,STAINED_GLASS:15)
Block(-8,10,-4,CONCRETE:15)
Block(-8,10,-3,CONCRETE:15)
Block(-8,10,-2,STAINED_GLASS:15)
Block(-8,10,-1,CONCRETE:8)
Block(-8,10,0,CONCRETE:8)
Block(-8,10,1,STAINED_GLASS:15)
Block(-8,10,2,CONCRETE:8)
Block(-8,10,3,CONCRETE:7)
Block(-8,10,4,CONCRETE:7)
Block(-8,10,5,CONCRETE:7)
Block(-8,10,6,CONCRETE:7)
Block(-8,10,7,CONCRETE:7)
Block(-8,10,8,CONCRETE:7)
Block(-8,11,-7,CONCRETE:7)
Block(-8,11,-6,CONCRETE:8)
Block(-8,11,-5,STATIONARY_WATER:0)
Block(-8,11,-4,STATIONARY_WATER:0)
Block(-8,11,-3,STATIONARY_WATER:0)
Block(-8,11,-2,STATIONARY_WATER:0)
Block(-8,11,-1,CONCRETE:8)
Block(-8,11,0,CONCRETE:8)
Block(-8,11,1,STAINED_GLASS:15)
Block(-8,11,2,CONCRETE:8)
Block(-8,11,3,CONCRETE:7)
Block(-8,11,4,CONCRETE:7)
Block(-8,11,5,CONCRETE:7)
Block(-8,11,6,CONCRETE:7)
Block(-8,11,7,CONCRETE:7)
Block(-8,11,8,CONCRETE:7)
Block(-8,12,-7,CONCRETE:7)
Block(-8,12,-6,CONCRETE:8)
Block(-8,12,-5,STATIONARY_WATER:0)
Block(-8,12,-4,STATIONARY_WATER:0)
Block(-8,12,-3,STATIONARY_WATER:0)
Block(-8,12,-2,STATIONARY_WATER:0)
Block(-8,12,-1,CONCRETE:8)
Block(-8,12,0,CONCRETE:8)
Block(-8,12,1,STAINED_GLASS:15)
Block(-8,12,2,CONCRETE:8)
Block(-8,12,3,CONCRETE:7)
Block(-8,12,4,CONCRETE:7)
Block(-8,12,5,CONCRETE:7)
Block(-8,12,6,CONCRETE:7)
Block(-8,12,7,CONCRETE:7)
Block(-8,12,8,CONCRETE:7)
Block(-8,13,-7,CONCRETE:7)
Block(-8,13,-6,CONCRETE:8)
Block(-8,13,-5,AIR:0)
Block(-8,13,-4,STATIONARY_WATER:10)
Block(-8,13,-3,STATIONARY_WATER:10)
Block(-8,13,-2,AIR:0)
Block(-8,13,-1,CONCRETE:8)
Block(-8,13,0,CONCRETE:8)
Block(-8,13,1,STAINED_GLASS:15)
Block(-8,13,2,CONCRETE:8)
Block(-8,13,3,CONCRETE:7)
Block(-8,13,4,CONCRETE:7)
Block(-8,13,5,CONCRETE:7)
Block(-8,13,6,CONCRETE:7)
Block(-8,13,7,CONCRETE:7)
Block(-8,13,8,CONCRETE:7)
Block(-8,14,-7,CONCRETE:7)
Block(-8,14,-6,CONCRETE:8)
Block(-8,14,-5,AIR:0)
Block(-8,14,-4,STATIONARY_WATER:10)
Block(-8,14,-3,STATIONARY_WATER:10)
Block(-8,14,-2,AIR:0)
Block(-8,14,-1,CONCRETE:8)
Block(-8,14,0,CONCRETE:8)
Block(-8,14,1,STAINED_GLASS:15)
Block(-8,14,2,CONCRETE:8)
Block(-8,14,3,CONCRETE:7)
Block(-8,14,4,CONCRETE:7)
Block(-8,14,5,CONCRETE:7)
Block(-8,14,6,CONCRETE:7)
Block(-8,14,7,CONCRETE:7)
Block(-8,14,8,CONCRETE:7)
Block(-8,15,-7,CONCRETE:7)
Block(-8,15,-6,CONCRETE:8)
Block(-8,15,-5,AIR:0)
Block(-8,15,-4,STATIONARY_WATER:10)
Block(-8,15,-3,STATIONARY_WATER:10)
Block(-8,15,-2,AIR:0)
Block(-8,15,-1,CONCRETE:8)
Block(-8,15,0,CONCRETE:8)
Block(-8,15,1,STAINED_GLASS:15)
Block(-8,15,2,CONCRETE:8)
Block(-8,15,3,CONCRETE:7)
Block(-8,15,4,CONCRETE:7)
Block(-8,15,5,CONCRETE:7)
Block(-8,15,6,CONCRETE:7)
Block(-8,15,7,CONCRETE:7)
Block(-8,15,8,CONCRETE:7)
Block(-8,16,-7,CONCRETE:7)
Block(-8,16,-6,CONCRETE:8)
Block(-8,16,-5,AIR:0)
Block(-8,16,-4,STATIONARY_WATER:2)
Block(-8,16,-3,STATIONARY_WATER:2)
Block(-8,16,-2,AIR:0)
Block(-8,16,-1,CONCRETE:8)
Block(-8,16,0,CONCRETE:8)
Block(-8,16,1,STAINED_GLASS:15)
Block(-8,16,2,CONCRETE:8)
Block(-8,16,3,CONCRETE:7)
Block(-8,16,4,CONCRETE:7)
Block(-8,16,5,CONCRETE:7)
Block(-8,16,6,CONCRETE:7)
Block(-8,16,7,CONCRETE:7)
Block(-8,16,8,CONCRETE:7)
Block(-8,17,-7,CONCRETE:7)
Block(-8,17,-6,CONCRETE:8)
Block(-8,17,-5,AIR:0)
Block(-8,17,-4,AIR:0)
Block(-8,17,-3,AIR:0)
Block(-8,17,-2,AIR:0)
Block(-8,17,-1,CONCRETE:8)
Block(-8,17,0,CONCRETE:8)
Block(-8,17,1,STAINED_GLASS:15)
Block(-8,17,2,CONCRETE:8)
Block(-8,17,3,CONCRETE:7)
Block(-8,17,4,CONCRETE:7)
Block(-8,17,5,CONCRETE:7)
Block(-8,17,6,CONCRETE:7)
Block(-8,17,7,CONCRETE:7)
Block(-8,17,8,CONCRETE:7)
Block(-8,18,-7,CONCRETE:8)
Block(-8,18,-6,CONCRETE:8)
Block(-8,18,-1,CONCRETE:8)
Block(-8,18,0,CONCRETE:8)
Block(-8,18,1,STAINED_GLASS:15)
Block(-8,18,2,CONCRETE:8)
Block(-8,18,3,CONCRETE:8)
Block(-8,18,4,CONCRETE:15)
Block(-8,18,5,CONCRETE:15)
Block(-8,18,6,CONCRETE:15)
Block(-8,18,7,CONCRETE:15)
Block(-8,18,8,CONCRETE:15)
Block(-8,19,-7,CONCRETE:8)
Block(-8,19,-6,CONCRETE:8)
Block(-8,19,-1,CONCRETE:8)
Block(-8,19,0,CONCRETE:8)
Block(-8,19,1,STAINED_GLASS:15)
Block(-8,19,2,CONCRETE:15)
Block(-8,19,6,STAINED_GLASS_PANE:15)
Block(-8,19,7,STAINED_GLASS_PANE:15)
Block(-8,19,8,STAINED_GLASS_PANE:15)
Block(-8,20,-7,CONCRETE:8)
Block(-8,20,-6,CONCRETE:8)
Block(-8,20,-1,CONCRETE:8)
Block(-8,20,0,CONCRETE:8)
Block(-8,20,1,STAINED_GLASS:15)
Block(-8,21,-7,CONCRETE:8)
Block(-8,21,-6,CONCRETE:8)
Block(-8,21,-1,CONCRETE:8)
Block(-8,21,0,CONCRETE:8)
Block(-8,21,1,STAINED_GLASS:15)
Block(-8,22,-7,CONCRETE:8)
Block(-8,22,-6,CONCRETE:8)
Block(-8,22,-1,CONCRETE:8)
Block(-8,22,0,CONCRETE:8)
Block(-8,22,1,STAINED_GLASS:15)
Block(-8,23,-7,CONCRETE:8)
Block(-8,23,-6,CONCRETE:8)
Block(-8,23,-1,CONCRETE:8)
Block(-8,23,0,CONCRETE:8)
Block(-8,23,1,STAINED_GLASS:15)
Block(-8,24,-7,CONCRETE:8)
Block(-8,24,-6,CONCRETE:8)
Block(-8,24,-1,CONCRETE:8)
Block(-8,24,0,CONCRETE:8)
Block(-8,24,1,STAINED_GLASS:15)
Block(-8,24,2,CONCRETE:8)
Block(-8,24,3,CONCRETE:8)
Block(-8,24,4,CONCRETE:15)
Block(-8,24,5,CONCRETE:15)
Block(-8,24,8,CONCRETE:15)
Block(-8,25,-7,CONCRETE:8)
Block(-8,25,-6,CONCRETE:8)
Block(-8,25,-1,CONCRETE:8)
Block(-8,25,0,CONCRETE:8)
Block(-8,25,1,STAINED_GLASS:15)
Block(-8,25,4,STAINED_GLASS_PANE:15)
Block(-8,25,5,STAINED_GLASS_PANE:15)
Block(-8,25,8,STAINED_GLASS_PANE:15)
Block(-8,26,-7,CONCRETE:8)
Block(-8,26,-6,CONCRETE:8)
Block(-8,26,-1,CONCRETE:8)
Block(-8,26,0,CONCRETE:8)
Block(-8,26,1,STAINED_GLASS:15)
Block(-8,27,-7,CONCRETE:8)
Block(-8,27,-6,CONCRETE:8)
Block(-8,27,-1,CONCRETE:8)
Block(-8,27,0,CONCRETE:8)
Block(-8,27,1,STAINED_GLASS:15)
Block(-8,28,-7,CONCRETE:8)
Block(-8,28,-6,CONCRETE:8)
Block(-8,28,-1,CONCRETE:8)
Block(-8,28,0,CONCRETE:8)
Block(-8,28,1,STAINED_GLASS:15)
Block(-8,29,-7,CONCRETE:8)
Block(-8,29,-6,CONCRETE:8)
Block(-8,29,-1,CONCRETE:8)
Block(-8,29,0,CONCRETE:8)
Block(-8,29,1,STAINED_GLASS:15)
Block(-8,29,2,CONCRETE:15)
Block(-8,30,-7,CONCRETE:8)
Block(-8,30,-6,CONCRETE:8)
Block(-8,30,-1,CONCRETE:8)
Block(-8,30,0,CONCRETE:8)
Block(-8,30,1,STAINED_GLASS:15)
Block(-8,30,2,CONCRETE:8)
Block(-8,30,3,CONCRETE:8)
Block(-8,30,4,CONCRETE:15)
Block(-8,30,5,CONCRETE:15)
Block(-8,30,6,CONCRETE:15)
Block(-8,30,7,CONCRETE:15)
Block(-8,30,8,CONCRETE:15)
Block(-8,31,-7,CONCRETE:8)
Block(-8,31,-6,CONCRETE:8)
Block(-8,31,-1,CONCRETE:8)
Block(-8,31,0,CONCRETE:8)
Block(-8,31,1,STAINED_GLASS:15)
Block(-8,31,2,CONCRETE:15)
Block(-8,31,8,CONCRETE:8)
Block(-8,32,-7,CONCRETE:8)
Block(-8,32,-6,CONCRETE:8)
Block(-8,32,-1,CONCRETE:8)
Block(-8,32,0,CONCRETE:8)
Block(-8,32,1,STAINED_GLASS:15)
Block(-8,32,8,CONCRETE:8)
Block(-8,33,-7,CONCRETE:8)
Block(-8,33,-6,CONCRETE:8)
Block(-8,33,-1,CONCRETE:8)
Block(-8,33,0,CONCRETE:8)
Block(-8,33,1,STAINED_GLASS:15)
Block(-8,33,8,CONCRETE:8)
Block(-8,34,-7,CONCRETE:8)
Block(-8,34,-6,CONCRETE:8)
Block(-8,34,-1,CONCRETE:8)
Block(-8,34,0,CONCRETE:8)
Block(-8,34,1,STAINED_GLASS:15)
Block(-8,34,8,CONCRETE:8)
Block(-8,35,-7,CONCRETE:8)
Block(-8,35,-6,CONCRETE:8)
Block(-8,35,-1,CONCRETE:8)
Block(-8,35,0,CONCRETE:8)
Block(-8,35,1,STAINED_GLASS:15)
Block(-8,35,8,CONCRETE:8)
Block(-8,36,-7,CONCRETE:8)
Block(-8,36,-6,CONCRETE:8)
Block(-8,36,-1,CONCRETE:8)
Block(-8,36,0,CONCRETE:8)
Block(-8,36,1,STAINED_GLASS:15)
Block(-8,36,2,CONCRETE:8)
Block(-8,36,3,CONCRETE:8)
Block(-8,36,4,CONCRETE:15)
Block(-8,36,5,CONCRETE:15)
Block(-8,36,6,CONCRETE:15)
Block(-8,36,7,CONCRETE:15)
Block(-8,36,8,CONCRETE:15)
Block(-8,37,-7,CONCRETE:8)
Block(-8,37,-6,CONCRETE:8)
Block(-8,37,-1,CONCRETE:8)
Block(-8,37,0,CONCRETE:8)
Block(-8,37,1,STAINED_GLASS:15)
Block(-8,37,8,CONCRETE:8)
Block(-8,38,-7,CONCRETE:8)
Block(-8,38,-6,CONCRETE:8)
Block(-8,38,-1,CONCRETE:8)
Block(-8,38,0,CONCRETE:8)
Block(-8,38,1,STAINED_GLASS:15)
Block(-8,38,8,CONCRETE:8)
Block(-8,39,-7,CONCRETE:8)
Block(-8,39,-6,CONCRETE:8)
Block(-8,39,-1,CONCRETE:8)
Block(-8,39,0,CONCRETE:8)
Block(-8,39,1,STAINED_GLASS:15)
Block(-8,39,8,CONCRETE:8)
Block(-8,40,-7,CONCRETE:8)
Block(-8,40,-6,CONCRETE:8)
Block(-8,40,-1,CONCRETE:8)
Block(-8,40,0,CONCRETE:8)
Block(-8,40,1,STAINED_GLASS:15)
Block(-8,40,8,CONCRETE:8)
Block(-8,41,-7,CONCRETE:8)
Block(-8,41,-6,CONCRETE:8)
Block(-8,41,-1,CONCRETE:8)
Block(-8,41,0,CONCRETE:8)
Block(-8,41,1,STAINED_GLASS:15)
Block(-8,41,2,CONCRETE:15)
Block(-8,41,8,CONCRETE:8)
Block(-8,42,-7,CONCRETE:8)
Block(-8,42,-6,CONCRETE:8)
Block(-8,42,-1,CONCRETE:8)
Block(-8,42,0,CONCRETE:8)
Block(-8,42,1,STAINED_GLASS:15)
Block(-8,42,2,CONCRETE:8)
Block(-8,42,3,CONCRETE:8)
Block(-8,42,4,CONCRETE:15)
Block(-8,42,5,CONCRETE:15)
Block(-8,42,6,CONCRETE:15)
Block(-8,42,7,CONCRETE:15)
Block(-8,42,8,CONCRETE:15)
Block(-8,43,-7,CONCRETE:8)
Block(-8,43,-6,CONCRETE:8)
Block(-8,43,-1,CONCRETE:8)
Block(-8,43,0,CONCRETE:8)
Block(-8,43,1,STAINED_GLASS:15)
Block(-8,43,2,CONCRETE:15)
Block(-8,43,3,CARPET:0)
Block(-8,43,4,CARPET:0)
Block(-8,43,5,CARPET:0)
Block(-8,43,6,CARPET:0)
Block(-8,43,7,CARPET:0)
Block(-8,43,8,CONCRETE:8)
Block(-8,44,-7,CONCRETE:8)
Block(-8,44,-6,CONCRETE:8)
Block(-8,44,-1,CONCRETE:8)
Block(-8,44,0,CONCRETE:8)
Block(-8,44,1,STAINED_GLASS:15)
Block(-8,44,8,CONCRETE:8)
Block(-8,45,-7,CONCRETE:8)
Block(-8,45,-6,CONCRETE:8)
Block(-8,45,-1,CONCRETE:8)
Block(-8,45,0,CONCRETE:8)
Block(-8,45,1,STAINED_GLASS:15)
Block(-8,45,8,CONCRETE:8)
Block(-8,46,-7,CONCRETE:8)
Block(-8,46,-6,CONCRETE:8)
Block(-8,46,-1,CONCRETE:8)
Block(-8,46,0,CONCRETE:8)
Block(-8,46,1,STAINED_GLASS:15)
Block(-8,46,8,CONCRETE:8)
Block(-8,47,-7,CONCRETE:8)
Block(-8,47,-6,CONCRETE:8)
Block(-8,47,-1,CONCRETE:8)
Block(-8,47,0,CONCRETE:8)
Block(-8,47,1,STAINED_GLASS:15)
Block(-8,47,8,CONCRETE:8)
Block(-8,48,-7,CONCRETE:8)
Block(-8,48,-6,CONCRETE:8)
Block(-8,48,-1,CONCRETE:8)
Block(-8,48,0,CONCRETE:8)
Block(-8,48,1,STAINED_GLASS:15)
Block(-8,48,2,CONCRETE:8)
Block(-8,48,3,CONCRETE:8)
Block(-8,48,4,CONCRETE:15)
Block(-8,48,5,CONCRETE:15)
Block(-8,48,6,CONCRETE:15)
Block(-8,48,7,CONCRETE:15)
Block(-8,48,8,CONCRETE:8)
Block(-8,49,-7,CONCRETE:8)
Block(-8,49,-6,CONCRETE:8)
Block(-8,49,-1,CONCRETE:8)
Block(-8,49,0,CONCRETE:8)
Block(-8,49,1,STAINED_GLASS:15)
Block(-8,49,2,STANDING_BANNER:2,NBT/skyscraper_3x3_01/2564-bannerC16R0.nbt)
Block(-8,49,4,DARK_OAK_STAIRS:7)
Block(-8,49,5,STANDING_BANNER:13,NBT/skyscraper_3x3_01/2565-bannerC16R0.nbt)
Block(-8,49,6,STANDING_BANNER:11,NBT/skyscraper_3x3_01/2566-bannerC16R0.nbt)
Block(-8,49,7,DARK_OAK_STAIRS:6)
Block(-8,49,8,CONCRETE:8)
Block(-8,50,-7,CONCRETE:8)
Block(-8,50,-6,CONCRETE:8)
Block(-8,50,-1,CONCRETE:8)
Block(-8,50,0,CONCRETE:8)
Block(-8,50,1,STAINED_GLASS:15)
Block(-8,50,2,STANDING_BANNER:2,NBT/skyscraper_3x3_01/2567-bannerC16R0.nbt)
Block(-8,50,4,IRON_TRAPDOOR:0)
Block(-8,50,5,IRON_TRAPDOOR:0)
Block(-8,50,6,IRON_TRAPDOOR:0)
Block(-8,50,7,IRON_TRAPDOOR:2)
Block(-8,50,8,CONCRETE:8)
Block(-8,51,-7,CONCRETE:8)
Block(-8,51,-6,CONCRETE:8)
Block(-8,51,-1,CONCRETE:8)
Block(-8,51,0,CONCRETE:8)
Block(-8,51,1,STAINED_GLASS:15)
Block(-8,51,2,STANDING_BANNER:2,NBT/skyscraper_3x3_01/2568-bannerC16R0.nbt)
Block(-8,51,8,CONCRETE:8)
Block(-8,52,-7,CONCRETE:8)
Block(-8,52,-6,CONCRETE:8)
Block(-8,52,-1,CONCRETE:8)
Block(-8,52,0,CONCRETE:8)
Block(-8,52,1,STAINED_GLASS:15)
Block(-8,52,8,CONCRETE:8)
Block(-8,53,-7,CONCRETE:8)
Block(-8,53,-6,CONCRETE:8)
Block(-8,53,-1,CONCRETE:8)
Block(-8,53,0,CONCRETE:8)
Block(-8,53,1,STAINED_GLASS:15)
Block(-8,53,2,CONCRETE:15)
Block(-8,53,8,CONCRETE:8)
Block(-8,54,-7,CONCRETE:8)
Block(-8,54,-6,CONCRETE:8)
Block(-8,54,-1,CONCRETE:8)
Block(-8,54,0,CONCRETE:8)
Block(-8,54,1,STAINED_GLASS:15)
Block(-8,54,2,CONCRETE:8)
Block(-8,54,3,CONCRETE:8)
Block(-8,54,4,CONCRETE:15)
Block(-8,54,5,CONCRETE:15)
Block(-8,54,6,CONCRETE:15)
Block(-8,54,7,CONCRETE:15)
Block(-8,54,8,CONCRETE:8)
Block(-8,55,-7,CONCRETE:8)
Block(-8,55,-6,CONCRETE:8)
Block(-8,55,-1,CONCRETE:8)
Block(-8,55,0,CONCRETE:8)
Block(-8,55,1,STAINED_GLASS:15)
Block(-8,55,2,CONCRETE:15)
Block(-8,55,8,CONCRETE:8)
Block(-8,56,-7,CONCRETE:8)
Block(-8,56,-6,CONCRETE:8)
Block(-8,56,-1,CONCRETE:8)
Block(-8,56,0,CONCRETE:8)
Block(-8,56,1,STAINED_GLASS:15)
Block(-8,56,8,CONCRETE:8)
Block(-8,57,-7,CONCRETE:8)
Block(-8,57,-6,CONCRETE:8)
Block(-8,57,-1,CONCRETE:8)
Block(-8,57,0,CONCRETE:8)
Block(-8,57,1,STAINED_GLASS:15)
Block(-8,57,8,CONCRETE:8)
Block(-8,58,-7,CONCRETE:8)
Block(-8,58,-6,CONCRETE:8)
Block(-8,58,-1,CONCRETE:8)
Block(-8,58,0,CONCRETE:8)
Block(-8,58,1,STAINED_GLASS:15)
Block(-8,58,5,PRISMARINE:0)
Block(-8,58,8,CONCRETE:8)
Block(-8,59,-7,CONCRETE:8)
Block(-8,59,-6,CONCRETE:8)
Block(-8,59,-1,CONCRETE:8)
Block(-8,59,0,CONCRETE:8)
Block(-8,59,1,STAINED_GLASS:15)
Block(-8,59,5,IRON_FENCE:0)
Block(-8,59,8,CONCRETE:8)
Block(-8,60,-7,CONCRETE:8)
Block(-8,60,-6,CONCRETE:8)
Block(-8,60,-1,CONCRETE:8)
Block(-8,60,0,CONCRETE:8)
Block(-8,60,1,STAINED_GLASS:15)
Block(-8,60,2,CONCRETE:8)
Block(-8,60,3,CONCRETE:8)
Block(-8,60,4,CONCRETE:15)
Block(-8,60,5,CONCRETE:15)
Block(-8,60,6,CONCRETE:15)
Block(-8,60,7,CONCRETE:15)
Block(-8,60,8,CONCRETE:15)
Block(-8,61,-7,CONCRETE:8)
Block(-8,61,-6,CONCRETE:8)
Block(-8,61,-1,CONCRETE:8)
Block(-8,61,0,CONCRETE:8)
Block(-8,61,1,STAINED_GLASS:15)
Block(-8,61,3,CARPET:0)
Block(-8,61,4,CARPET:0)
Block(-8,61,5,CARPET:0)
Block(-8,61,6,CARPET:0)
Block(-8,61,7,CARPET:0)
Block(-8,61,8,CONCRETE:8)
Block(-8,62,-7,CONCRETE:8)
Block(-8,62,-6,CONCRETE:8)
Block(-8,62,-1,CONCRETE:8)
Block(-8,62,0,CONCRETE:8)
Block(-8,62,1,STAINED_GLASS:15)
Block(-8,62,8,CONCRETE:8)
Block(-8,63,-7,CONCRETE:8)
Block(-8,63,-6,CONCRETE:8)
Block(-8,63,-1,CONCRETE:8)
Block(-8,63,0,CONCRETE:8)
Block(-8,63,1,STAINED_GLASS:15)
Block(-8,63,8,CONCRETE:8)
Block(-8,64,-7,CONCRETE:8)
Block(-8,64,-6,CONCRETE:8)
Block(-8,64,-1,CONCRETE:8)
Block(-8,64,0,CONCRETE:8)
Block(-8,64,1,STAINED_GLASS:15)
Block(-8,64,8,CONCRETE:8)
Block(-8,65,-7,CONCRETE:8)
Block(-8,65,-6,CONCRETE:8)
Block(-8,65,-1,CONCRETE:8)
Block(-8,65,0,CONCRETE:8)
Block(-8,65,1,STAINED_GLASS:15)
Block(-8,65,2,CONCRETE:15)
Block(-8,65,8,CONCRETE:8)
Block(-8,66,-7,CONCRETE:8)
Block(-8,66,-6,CONCRETE:8)
Block(-8,66,-1,CONCRETE:8)
Block(-8,66,0,CONCRETE:8)
Block(-8,66,1,STAINED_GLASS:15)
Block(-8,66,2,CONCRETE:8)
Block(-8,66,3,CONCRETE:8)
Block(-8,66,4,CONCRETE:15)
Block(-8,66,5,CONCRETE:15)
Block(-8,66,6,CONCRETE:15)
Block(-8,66,7,CONCRETE:15)
Block(-8,66,8,CONCRETE:8)
Block(-8,67,-7,CONCRETE:8)
Block(-8,67,-6,CONCRETE:8)
Block(-8,67,-1,CONCRETE:8)
Block(-8,67,0,CONCRETE:8)
Block(-8,67,1,STAINED_GLASS:15)
Block(-8,67,2,CONCRETE:15)
Block(-8,67,4,DARK_OAK_STAIRS:7)
Block(-8,67,5,STANDING_BANNER:13,NBT/skyscraper_3x3_01/2569-bannerC16R0.nbt)
Block(-8,67,6,STANDING_BANNER:11,NBT/skyscraper_3x3_01/2570-bannerC16R0.nbt)
Block(-8,67,7,DARK_OAK_STAIRS:6)
Block(-8,67,8,CONCRETE:8)
Block(-8,68,-7,CONCRETE:8)
Block(-8,68,-6,CONCRETE:8)
Block(-8,68,-1,CONCRETE:8)
Block(-8,68,0,CONCRETE:8)
Block(-8,68,1,STAINED_GLASS:15)
Block(-8,68,2,STANDING_BANNER:2,NBT/skyscraper_3x3_01/2571-bannerC16R0.nbt)
Block(-8,68,4,IRON_TRAPDOOR:0)
Block(-8,68,5,IRON_TRAPDOOR:0)
Block(-8,68,6,IRON_TRAPDOOR:0)
Block(-8,68,7,IRON_TRAPDOOR:2)
Block(-8,68,8,CONCRETE:8)
Block(-8,69,-7,CONCRETE:8)
Block(-8,69,-6,CONCRETE:8)
Block(-8,69,-1,CONCRETE:8)
Block(-8,69,0,CONCRETE:8)
Block(-8,69,1,STAINED_GLASS:15)
Block(-8,69,2,STANDING_BANNER:2,NBT/skyscraper_3x3_01/2572-bannerC16R0.nbt)
Block(-8,69,8,CONCRETE:8)
Block(-8,70,-7,CONCRETE:8)
Block(-8,70,-6,CONCRETE:8)
Block(-8,70,-1,CONCRETE:8)
Block(-8,70,0,CONCRETE:8)
Block(-8,70,1,STAINED_GLASS:15)
Block(-8,70,2,STANDING_BANNER:2,NBT/skyscraper_3x3_01/2573-bannerC16R0.nbt)
Block(-8,70,8,CONCRETE:8)
Block(-8,71,-7,CONCRETE:8)
Block(-8,71,-6,CONCRETE:8)
Block(-8,71,-1,CONCRETE:8)
Block(-8,71,0,CONCRETE:8)
Block(-8,71,1,STAINED_GLASS:15)
Block(-8,71,8,CONCRETE:8)
Block(-8,72,-7,CONCRETE:8)
Block(-8,72,-6,CONCRETE:8)
Block(-8,72,-1,CONCRETE:8)
Block(-8,72,0,CONCRETE:8)
Block(-8,72,1,STAINED_GLASS:15)
Block(-8,72,2,CONCRETE:8)
Block(-8,72,3,CONCRETE:8)
Block(-8,72,4,CONCRETE:15)
Block(-8,72,5,CONCRETE:15)
Block(-8,72,6,CONCRETE:15)
Block(-8,72,7,CONCRETE:15)
Block(-8,72,8,CONCRETE:8)
Block(-8,73,-7,CONCRETE:8)
Block(-8,73,-6,CONCRETE:8)
Block(-8,73,-1,CONCRETE:8)
Block(-8,73,0,CONCRETE:8)
Block(-8,73,1,STAINED_GLASS:15)
Block(-8,73,8,CONCRETE:8)
Block(-8,74,-7,CONCRETE:8)
Block(-8,74,-6,CONCRETE:8)
Block(-8,74,-1,CONCRETE:8)
Block(-8,74,0,CONCRETE:8)
Block(-8,74,1,STAINED_GLASS:15)
Block(-8,74,8,CONCRETE:8)
Block(-8,75,-7,CONCRETE:8)
Block(-8,75,-6,CONCRETE:8)
Block(-8,75,-1,CONCRETE:8)
Block(-8,75,0,CONCRETE:8)
Block(-8,75,1,STAINED_GLASS:15)
Block(-8,75,8,CONCRETE:8)
Block(-8,76,-7,CONCRETE:8)
Block(-8,76,-6,CONCRETE:8)
Block(-8,76,-1,CONCRETE:8)
Block(-8,76,0,CONCRETE:8)
Block(-8,76,1,STAINED_GLASS:15)
Block(-8,76,5,PRISMARINE:0)
Block(-8,76,8,CONCRETE:8)
Block(-8,77,-7,CONCRETE:8)
Block(-8,77,-6,CONCRETE:8)
Block(-8,77,-1,CONCRETE:8)
Block(-8,77,0,CONCRETE:8)
Block(-8,77,1,STAINED_GLASS:15)
Block(-8,77,2,CONCRETE:15)
Block(-8,77,5,IRON_FENCE:0)
Block(-8,77,8,CONCRETE:8)
Block(-8,78,-7,CONCRETE:8)
Block(-8,78,-6,CONCRETE:8)
Block(-8,78,-1,CONCRETE:8)
Block(-8,78,0,CONCRETE:8)
Block(-8,78,1,STAINED_GLASS:15)
Block(-8,78,2,CONCRETE:8)
Block(-8,78,3,CONCRETE:8)
Block(-8,78,4,CONCRETE:15)
Block(-8,78,5,CONCRETE:15)
Block(-8,78,6,CONCRETE:15)
Block(-8,78,7,CONCRETE:15)
Block(-8,78,8,CONCRETE:15)
Block(-8,79,-7,CONCRETE:8)
Block(-8,79,-6,CONCRETE:8)
Block(-8,79,-1,CONCRETE:8)
Block(-8,79,0,CONCRETE:8)
Block(-8,79,1,STAINED_GLASS:15)
Block(-8,79,2,CONCRETE:15)
Block(-8,79,8,CONCRETE:8)
Block(-8,80,-7,CONCRETE:8)
Block(-8,80,-6,CONCRETE:8)
Block(-8,80,-1,CONCRETE:8)
Block(-8,80,0,CONCRETE:8)
Block(-8,80,1,STAINED_GLASS:15)
Block(-8,80,8,CONCRETE:8)
Block(-8,81,-7,CONCRETE:8)
Block(-8,81,-6,CONCRETE:8)
Block(-8,81,-1,CONCRETE:8)
Block(-8,81,0,CONCRETE:8)
Block(-8,81,1,STAINED_GLASS:15)
Block(-8,81,8,CONCRETE:8)
Block(-8,82,-7,CONCRETE:8)
Block(-8,82,-6,CONCRETE:8)
Block(-8,82,-1,CONCRETE:8)
Block(-8,82,0,CONCRETE:8)
Block(-8,82,1,STAINED_GLASS:15)
Block(-8,82,8,CONCRETE:8)
Block(-8,83,-7,CONCRETE:8)
Block(-8,83,-6,CONCRETE:8)
Block(-8,83,-1,CONCRETE:8)
Block(-8,83,0,CONCRETE:8)
Block(-8,83,1,STAINED_GLASS:15)
Block(-8,83,8,CONCRETE:8)
Block(-8,84,-7,CONCRETE:8)
Block(-8,84,-6,CONCRETE:8)
Block(-8,84,-1,CONCRETE:8)
Block(-8,84,0,CONCRETE:8)
Block(-8,84,1,STAINED_GLASS:15)
Block(-8,84,2,CONCRETE:8)
Block(-8,84,3,CONCRETE:8)
Block(-8,84,4,CONCRETE:15)
Block(-8,84,5,CONCRETE:15)
Block(-8,84,6,CONCRETE:15)
Block(-8,84,7,CONCRETE:15)
Block(-8,84,8,CONCRETE:15)
Block(-8,85,-7,CONCRETE:8)
Block(-8,85,-6,CONCRETE:8)
Block(-8,85,-1,CONCRETE:8)
Block(-8,85,0,CONCRETE:8)
Block(-8,85,1,STAINED_GLASS:15)
Block(-8,85,8,CONCRETE:8)
Block(-8,86,-7,CONCRETE:8)
Block(-8,86,-6,CONCRETE:8)
Block(-8,86,-1,CONCRETE:8)
Block(-8,86,0,CONCRETE:8)
Block(-8,86,1,STAINED_GLASS:15)
Block(-8,86,8,CONCRETE:8)
Block(-8,87,-7,CONCRETE:8)
Block(-8,87,-6,CONCRETE:8)
Block(-8,87,-1,CONCRETE:8)
Block(-8,87,0,CONCRETE:8)
Block(-8,87,1,STAINED_GLASS:15)
Block(-8,87,8,CONCRETE:8)
Block(-8,88,-7,CONCRETE:8)
Block(-8,88,-6,CONCRETE:8)
Block(-8,88,-1,CONCRETE:8)
Block(-8,88,0,CONCRETE:8)
Block(-8,88,1,STAINED_GLASS:15)
Block(-8,88,8,CONCRETE:8)
Block(-8,89,-7,CONCRETE:8)
Block(-8,89,-6,CONCRETE:8)
Block(-8,89,-1,CONCRETE:8)
Block(-8,89,0,CONCRETE:8)
Block(-8,89,1,STAINED_GLASS:15)
Block(-8,89,2,CONCRETE:15)
Block(-8,89,8,CONCRETE:8)
Block(-8,90,-7,CONCRETE:8)
Block(-8,90,-6,CONCRETE:8)
Block(-8,90,-1,CONCRETE:8)
Block(-8,90,0,CONCRETE:8)
Block(-8,90,1,STAINED_GLASS:15)
Block(-8,90,2,CONCRETE:8)
Block(-8,90,3,CONCRETE:8)
Block(-8,90,4,CONCRETE:15)
Block(-8,90,5,CONCRETE:15)
Block(-8,90,6,CONCRETE:15)
Block(-8,90,7,CONCRETE:15)
Block(-8,90,8,CONCRETE:15)
Block(-8,91,-7,CONCRETE:8)
Block(-8,91,-6,CONCRETE:8)
Block(-8,91,-1,CONCRETE:8)
Block(-8,91,0,CONCRETE:8)
Block(-8,91,1,STAINED_GLASS:15)
Block(-8,91,2,CONCRETE:15)
Block(-8,91,3,CARPET:0)
Block(-8,91,4,CARPET:0)
Block(-8,91,5,CARPET:0)
Block(-8,91,6,CARPET:0)
Block(-8,91,7,CARPET:0)
Block(-8,91,8,CONCRETE:8)
Block(-8,92,-7,CONCRETE:8)
Block(-8,92,-6,CONCRETE:8)
Block(-8,92,-1,CONCRETE:8)
Block(-8,92,0,CONCRETE:8)
Block(-8,92,1,STAINED_GLASS:15)
Block(-8,92,8,CONCRETE:8)
Block(-8,93,-7,CONCRETE:8)
Block(-8,93,-6,CONCRETE:8)
Block(-8,93,-1,CONCRETE:8)
Block(-8,93,0,CONCRETE:8)
Block(-8,93,1,STAINED_GLASS:15)
Block(-8,93,8,CONCRETE:8)
Block(-8,94,-7,CONCRETE:8)
Block(-8,94,-6,CONCRETE:8)
Block(-8,94,-1,CONCRETE:8)
Block(-8,94,0,CONCRETE:8)
Block(-8,94,1,STAINED_GLASS:15)
Block(-8,94,8,CONCRETE:8)
Block(-8,95,-7,CONCRETE:8)
Block(-8,95,-6,CONCRETE:8)
Block(-8,95,-1,CONCRETE:8)
Block(-8,95,0,CONCRETE:8)
Block(-8,95,1,STAINED_GLASS:15)
Block(-8,95,8,CONCRETE:8)
Block(-8,96,-7,CONCRETE:8)
Block(-8,96,-6,CONCRETE:8)
Block(-8,96,-1,CONCRETE:8)
Block(-8,96,0,CONCRETE:8)
Block(-8,96,1,STAINED_GLASS:15)
Block(-8,96,2,CONCRETE:8)
Block(-8,96,3,CONCRETE:8)
Block(-8,96,4,CONCRETE:15)
Block(-8,96,5,CONCRETE:15)
Block(-8,96,6,CONCRETE:15)
Block(-8,96,7,CONCRETE:15)
Block(-8,96,8,CONCRETE:15)
Block(-8,97,-7,CONCRETE:8)
Block(-8,97,-6,CONCRETE:8)
Block(-8,97,-1,CONCRETE:8)
Block(-8,97,0,CONCRETE:8)
Block(-8,97,1,STAINED_GLASS:15)
Block(-8,98,-7,CONCRETE:8)
Block(-8,98,-6,CONCRETE:8)
Block(-8,98,-1,CONCRETE:8)
Block(-8,98,0,CONCRETE:8)
Block(-8,98,1,STAINED_GLASS:15)
Block(-8,99,-7,CONCRETE:8)
Block(-8,99,-6,CONCRETE:8)
Block(-8,99,-1,CONCRETE:8)
Block(-8,99,0,CONCRETE:8)
Block(-8,99,1,STAINED_GLASS:15)
Block(-8,100,-7,CONCRETE:8)
Block(-8,100,-6,CONCRETE:8)
Block(-8,100,-1,CONCRETE:8)
Block(-8,100,0,CONCRETE:8)
Block(-8,100,1,STAINED_GLASS:15)
Block(-8,100,5,QUARTZ_STAIRS:4)
Block(-8,101,-7,CONCRETE:8)
Block(-8,101,-6,CONCRETE:8)
Block(-8,101,-1,CONCRETE:8)
Block(-8,101,0,CONCRETE:8)
Block(-8,101,1,STAINED_GLASS:15)
Block(-8,101,2,CONCRETE:15)
Block(-8,101,5,STEP:7)
Block(-8,102,-7,CONCRETE:8)
Block(-8,102,-6,CONCRETE:8)
Block(-8,102,-1,CONCRETE:8)
Block(-8,102,0,CONCRETE:8)
Block(-8,102,1,STAINED_GLASS:15)
Block(-8,102,2,CONCRETE:8)
Block(-8,102,3,CONCRETE:8)
Block(-8,102,4,CONCRETE:15)
Block(-8,102,5,CONCRETE:15)
Block(-8,102,6,CONCRETE:15)
Block(-8,102,7,CONCRETE:15)
Block(-8,102,8,CONCRETE:8)
Block(-8,103,-7,CONCRETE:8)
Block(-8,103,-6,CONCRETE:8)
Block(-8,103,-1,CONCRETE:8)
Block(-8,103,0,CONCRETE:8)
Block(-8,103,1,STAINED_GLASS:15)
Block(-8,103,2,CONCRETE:15)
Block(-8,103,3,WOOD_STEP:13)
Block(-8,103,4,WOOD_STEP:13)
Block(-8,103,5,WOOD_STEP:13)
Block(-8,103,6,WOOD_STEP:13)
Block(-8,103,7,WOOD_STEP:13)
Block(-8,103,8,DARK_OAK_STAIRS:3)
Block(-8,104,-7,CONCRETE:8)
Block(-8,104,-6,CONCRETE:8)
Block(-8,104,-1,CONCRETE:8)
Block(-8,104,0,CONCRETE:8)
Block(-8,104,1,STAINED_GLASS:15)
Block(-8,105,-7,CONCRETE:8)
Block(-8,105,-6,CONCRETE:8)
Block(-8,105,-1,CONCRETE:8)
Block(-8,105,0,CONCRETE:8)
Block(-8,105,1,STAINED_GLASS:15)
Block(-8,106,-7,CONCRETE:8)
Block(-8,106,-6,CONCRETE:8)
Block(-8,106,-1,CONCRETE:8)
Block(-8,106,0,CONCRETE:8)
Block(-8,106,1,STAINED_GLASS:15)
Block(-8,107,-7,CONCRETE:8)
Block(-8,107,-6,CONCRETE:8)
Block(-8,107,-1,CONCRETE:8)
Block(-8,107,0,CONCRETE:8)
Block(-8,107,1,STAINED_GLASS:15)
Block(-8,108,-7,CONCRETE:8)
Block(-8,108,-6,CONCRETE:8)
Block(-8,108,-1,CONCRETE:8)
Block(-8,108,0,CONCRETE:8)
Block(-8,108,1,STAINED_GLASS:15)
Block(-8,108,2,CONCRETE:8)
Block(-8,108,3,CONCRETE:8)
Block(-8,108,4,CONCRETE:15)
Block(-8,108,5,CONCRETE:15)
Block(-8,108,6,STAINED_GLASS:15)
Block(-8,108,7,STAINED_GLASS:15)
Block(-8,108,8,CONCRETE:15)
Block(-8,109,-7,CONCRETE:8)
Block(-8,109,-6,CONCRETE:8)
Block(-8,109,-1,CONCRETE:8)
Block(-8,109,0,CONCRETE:8)
Block(-8,109,1,STAINED_GLASS:15)
Block(-8,109,3,DROPPER:3,NBT/skyscraper_3x3_01/2581-dropperC16R0.nbt)
Block(-8,109,4,IRON_DOOR_BLOCK:1)
Block(-8,109,6,CONCRETE:8)
Block(-8,110,-7,CONCRETE:8)
Block(-8,110,-6,CONCRETE:8)
Block(-8,110,-1,CONCRETE:8)
Block(-8,110,0,CONCRETE:8)
Block(-8,110,1,STAINED_GLASS:15)
Block(-8,110,3,DROPPER:3,NBT/skyscraper_3x3_01/2582-dropperC16R0.nbt)
Block(-8,110,4,IRON_DOOR_BLOCK:9)
Block(-8,111,-7,CONCRETE:8)
Block(-8,111,-6,CONCRETE:8)
Block(-8,111,-1,CONCRETE:8)
Block(-8,111,0,CONCRETE:8)
Block(-8,111,1,STAINED_GLASS:15)
Block(-8,111,6,STEP:0)
Block(-8,112,-7,CONCRETE:8)
Block(-8,112,-6,CONCRETE:8)
Block(-8,112,-1,CONCRETE:8)
Block(-8,112,0,CONCRETE:8)
Block(-8,112,1,STAINED_GLASS:15)
Block(-8,113,-7,CONCRETE:8)
Block(-8,113,-6,CONCRETE:8)
Block(-8,113,-1,CONCRETE:8)
Block(-8,113,0,CONCRETE:8)
Block(-8,113,1,STAINED_GLASS:15)
Block(-8,113,2,CONCRETE:15)
Block(-8,114,-7,CONCRETE:8)
Block(-8,114,-6,CONCRETE:8)
Block(-8,114,-1,CONCRETE:8)
Block(-8,114,0,CONCRETE:8)
Block(-8,114,1,STAINED_GLASS:15)
Block(-8,114,7,STAINED_GLASS_PANE:15)
Block(-8,114,8,STAINED_GLASS_PANE:15)
Block(-8,115,-7,CONCRETE:8)
Block(-8,115,-6,CONCRETE:8)
Block(-8,115,-1,CONCRETE:8)
Block(-8,115,0,CONCRETE:8)
Block(-8,115,1,STAINED_GLASS:15)
Block(-8,115,2,CONCRETE:15)
Block(-8,115,7,STAINED_GLASS_PANE:15)
Block(-8,115,8,STAINED_GLASS_PANE:15)
Block(-8,116,-7,CONCRETE:8)
Block(-8,116,-6,CONCRETE:8)
Block(-8,116,-1,CONCRETE:8)
Block(-8,116,0,CONCRETE:8)
Block(-8,116,1,STAINED_GLASS:15)
Block(-8,117,-7,CONCRETE:8)
Block(-8,117,-6,CONCRETE:8)
Block(-8,117,-1,CONCRETE:8)
Block(-8,117,0,CONCRETE:8)
Block(-8,117,1,STAINED_GLASS:15)
Block(-8,118,-7,CONCRETE:8)
Block(-8,118,-6,CONCRETE:8)
Block(-8,118,-1,CONCRETE:8)
Block(-8,118,0,CONCRETE:8)
Block(-8,118,1,STAINED_GLASS:15)
Block(-8,119,-7,CONCRETE:8)
Block(-8,119,-6,CONCRETE:8)
Block(-8,119,-1,CONCRETE:8)
Block(-8,119,0,CONCRETE:8)
Block(-8,119,1,STAINED_GLASS:15)
Block(-8,120,-7,CONCRETE:8)
Block(-8,120,-6,CONCRETE:8)
Block(-8,120,-1,CONCRETE:8)
Block(-8,120,0,CONCRETE:8)
Block(-8,120,1,STAINED_GLASS:15)
Block(-8,120,2,CONCRETE:8)
Block(-8,120,3,CONCRETE:8)
Block(-8,120,4,CONCRETE:15)
Block(-8,120,5,CONCRETE:15)
Block(-8,120,6,CONCRETE:15)
Block(-8,120,7,CONCRETE:15)
Block(-8,120,8,CONCRETE:8)
Block(-8,121,-7,CONCRETE:8)
Block(-8,121,-6,CONCRETE:8)
Block(-8,121,-1,CONCRETE:8)
Block(-8,121,0,CONCRETE:8)
Block(-8,121,1,STAINED_GLASS:15)
Block(-8,121,2,STANDING_BANNER:2,NBT/skyscraper_3x3_01/2583-bannerC16R0.nbt)
Block(-8,121,4,DARK_OAK_STAIRS:7)
Block(-8,121,5,STANDING_BANNER:13,NBT/skyscraper_3x3_01/2584-bannerC16R0.nbt)
Block(-8,121,6,STANDING_BANNER:11,NBT/skyscraper_3x3_01/2585-bannerC16R0.nbt)
Block(-8,121,7,DARK_OAK_STAIRS:6)
Block(-8,121,8,CONCRETE:8)
Block(-8,122,-7,CONCRETE:8)
Block(-8,122,-6,CONCRETE:8)
Block(-8,122,-1,CONCRETE:8)
Block(-8,122,0,CONCRETE:8)
Block(-8,122,1,STAINED_GLASS:15)
Block(-8,122,2,STANDING_BANNER:2,NBT/skyscraper_3x3_01/2586-bannerC16R0.nbt)
Block(-8,122,4,IRON_TRAPDOOR:0)
Block(-8,122,5,IRON_TRAPDOOR:0)
Block(-8,122,6,IRON_TRAPDOOR:0)
Block(-8,122,7,IRON_TRAPDOOR:2)
Block(-8,122,8,CONCRETE:8)
Block(-8,123,-7,CONCRETE:8)
Block(-8,123,-6,CONCRETE:8)
Block(-8,123,-1,CONCRETE:8)
Block(-8,123,0,CONCRETE:8)
Block(-8,123,1,STAINED_GLASS:15)
Block(-8,123,2,STANDING_BANNER:2,NBT/skyscraper_3x3_01/2587-bannerC16R0.nbt)
Block(-8,123,8,CONCRETE:8)
Block(-8,124,-7,CONCRETE:8)
Block(-8,124,-6,CONCRETE:8)
Block(-8,124,-1,CONCRETE:8)
Block(-8,124,0,CONCRETE:8)
Block(-8,124,1,STAINED_GLASS:15)
Block(-8,124,8,CONCRETE:8)
Block(-8,125,-7,CONCRETE:8)
Block(-8,125,-6,CONCRETE:8)
Block(-8,125,-1,CONCRETE:8)
Block(-8,125,0,CONCRETE:8)
Block(-8,125,1,STAINED_GLASS:15)
Block(-8,125,2,CONCRETE:15)
Block(-8,125,8,CONCRETE:8)
Block(-8,126,-7,CONCRETE:8)
Block(-8,126,-6,CONCRETE:8)
Block(-8,126,-1,CONCRETE:8)
Block(-8,126,0,CONCRETE:8)
Block(-8,126,1,STAINED_GLASS:15)
Block(-8,126,2,CONCRETE:8)
Block(-8,126,3,CONCRETE:8)
Block(-8,126,4,CONCRETE:15)
Block(-8,126,5,CONCRETE:15)
Block(-8,126,6,CONCRETE:15)
Block(-8,126,7,CONCRETE:15)
Block(-8,126,8,CONCRETE:15)
Block(-8,127,-7,CONCRETE:8)
Block(-8,127,-6,CONCRETE:8)
Block(-8,127,-1,CONCRETE:8)
Block(-8,127,0,CONCRETE:8)
Block(-8,127,1,STAINED_GLASS:15)
Block(-8,127,2,CONCRETE:15)
Block(-8,127,8,CONCRETE:8)
Block(-8,128,-7,CONCRETE:8)
Block(-8,128,-6,CONCRETE:8)
Block(-8,128,-1,CONCRETE:8)
Block(-8,128,0,CONCRETE:8)
Block(-8,128,1,STAINED_GLASS:15)
Block(-8,128,8,CONCRETE:8)
Block(-8,129,-7,CONCRETE:8)
Block(-8,129,-6,CONCRETE:8)
Block(-8,129,-1,CONCRETE:8)
Block(-8,129,0,CONCRETE:8)
Block(-8,129,1,STAINED_GLASS:15)
Block(-8,129,8,CONCRETE:8)
Block(-8,130,-7,CONCRETE:8)
Block(-8,130,-6,CONCRETE:8)
Block(-8,130,-1,CONCRETE:8)
Block(-8,130,0,CONCRETE:8)
Block(-8,130,1,STAINED_GLASS:15)
Block(-8,130,8,CONCRETE:8)
Block(-8,131,-7,CONCRETE:8)
Block(-8,131,-6,CONCRETE:8)
Block(-8,131,-1,CONCRETE:8)
Block(-8,131,0,CONCRETE:8)
Block(-8,131,1,STAINED_GLASS:15)
Block(-8,131,8,CONCRETE:8)
Block(-8,132,-7,CONCRETE:8)
Block(-8,132,-6,CONCRETE:8)
Block(-8,132,-1,CONCRETE:8)
Block(-8,132,0,CONCRETE:8)
Block(-8,132,1,STAINED_GLASS:15)
Block(-8,132,2,CONCRETE:8)
Block(-8,132,3,CONCRETE:8)
Block(-8,132,4,CONCRETE:15)
Block(-8,132,5,CONCRETE:15)
Block(-8,132,6,CONCRETE:15)
Block(-8,132,7,CONCRETE:15)
Block(-8,132,8,CONCRETE:15)
Block(-8,133,-7,CONCRETE:8)
Block(-8,133,-6,CONCRETE:8)
Block(-8,133,-1,CONCRETE:8)
Block(-8,133,0,CONCRETE:8)
Block(-8,133,1,STAINED_GLASS:15)
Block(-8,133,8,CONCRETE:8)
Block(-8,134,-7,CONCRETE:8)
Block(-8,134,-6,CONCRETE:8)
Block(-8,134,-1,CONCRETE:8)
Block(-8,134,0,CONCRETE:8)
Block(-8,134,1,STAINED_GLASS:15)
Block(-8,134,8,CONCRETE:8)
Block(-8,135,-7,CONCRETE:8)
Block(-8,135,-6,CONCRETE:8)
Block(-8,135,-1,CONCRETE:8)
Block(-8,135,0,CONCRETE:8)
Block(-8,135,1,STAINED_GLASS:15)
Block(-8,135,8,CONCRETE:8)
Block(-8,136,-7,CONCRETE:8)
Block(-8,136,-6,CONCRETE:8)
Block(-8,136,-1,CONCRETE:8)
Block(-8,136,0,CONCRETE:8)
Block(-8,136,1,STAINED_GLASS:15)
Block(-8,136,8,CONCRETE:8)
Block(-8,137,-7,CONCRETE:8)
Block(-8,137,-6,CONCRETE:8)
Block(-8,137,-1,CONCRETE:8)
Block(-8,137,0,CONCRETE:8)
Block(-8,137,1,STAINED_GLASS:15)
Block(-8,137,2,CONCRETE:15)
Block(-8,137,8,CONCRETE:8)
Block(-8,138,-7,CONCRETE:8)
Block(-8,138,-6,CONCRETE:8)
Block(-8,138,-1,CONCRETE:8)
Block(-8,138,0,CONCRETE:8)
Block(-8,138,1,STAINED_GLASS:15)
Block(-8,138,2,CONCRETE:8)
Block(-8,138,3,CONCRETE:8)
Block(-8,138,4,CONCRETE:15)
Block(-8,138,5,CONCRETE:15)
Block(-8,138,6,CONCRETE:15)
Block(-8,138,7,CONCRETE:15)
Block(-8,138,8,CONCRETE:15)
Block(-8,139,-7,CONCRETE:8)
Block(-8,139,-6,CONCRETE:8)
Block(-8,139,-1,CONCRETE:8)
Block(-8,139,0,CONCRETE:8)
Block(-8,139,1,STAINED_GLASS:15)
Block(-8,139,2,CONCRETE:15)
Block(-8,139,3,CARPET:0)
Block(-8,139,4,CARPET:0)
Block(-8,139,5,CARPET:0)
Block(-8,139,6,CARPET:0)
Block(-8,139,7,CARPET:0)
Block(-8,139,8,CONCRETE:8)
Block(-8,140,-7,CONCRETE:8)
Block(-8,140,-6,CONCRETE:8)
Block(-8,140,-1,CONCRETE:8)
Block(-8,140,0,CONCRETE:8)
Block(-8,140,1,STAINED_GLASS:15)
Block(-8,140,8,CONCRETE:8)
Block(-8,141,-7,CONCRETE:8)
Block(-8,141,-6,CONCRETE:8)
Block(-8,141,-1,CONCRETE:8)
Block(-8,141,0,CONCRETE:8)
Block(-8,141,1,STAINED_GLASS:15)
Block(-8,141,8,CONCRETE:8)
Block(-8,142,-7,CONCRETE:8)
Block(-8,142,-6,CONCRETE:8)
Block(-8,142,-1,CONCRETE:8)
Block(-8,142,0,CONCRETE:8)
Block(-8,142,1,STAINED_GLASS:15)
Block(-8,142,8,CONCRETE:8)
Block(-8,143,-7,CONCRETE:8)
Block(-8,143,-6,CONCRETE:8)
Block(-8,143,-1,CONCRETE:8)
Block(-8,143,0,CONCRETE:8)
Block(-8,143,1,STAINED_GLASS:15)
Block(-8,143,8,CONCRETE:8)
Block(-8,144,-7,CONCRETE:8)
Block(-8,144,-6,CONCRETE:8)
Block(-8,144,-1,CONCRETE:8)
Block(-8,144,0,CONCRETE:8)
Block(-8,144,1,STAINED_GLASS:15)
Block(-8,144,2,CONCRETE:8)
Block(-8,144,3,CONCRETE:8)
Block(-8,144,4,CONCRETE:15)
Block(-8,144,5,CONCRETE:15)
Block(-8,144,6,CONCRETE:15)
Block(-8,144,7,CONCRETE:15)
Block(-8,144,8,CONCRETE:8)
Block(-8,145,-7,CONCRETE:8)
Block(-8,145,-6,CONCRETE:8)
Block(-8,145,-1,CONCRETE:8)
Block(-8,145,0,CONCRETE:8)
Block(-8,145,1,STAINED_GLASS:15)
Block(-8,145,2,STANDING_BANNER:2,NBT/skyscraper_3x3_01/2588-bannerC16R0.nbt)
Block(-8,145,4,DARK_OAK_STAIRS:7)
Block(-8,145,5,STANDING_BANNER:13,NBT/skyscraper_3x3_01/2589-bannerC16R0.nbt)
Block(-8,145,6,STANDING_BANNER:11,NBT/skyscraper_3x3_01/2590-bannerC16R0.nbt)
Block(-8,145,7,DARK_OAK_STAIRS:6)
Block(-8,145,8,CONCRETE:8)
Block(-8,146,-7,CONCRETE:8)
Block(-8,146,-6,CONCRETE:8)
Block(-8,146,-1,CONCRETE:8)
Block(-8,146,0,CONCRETE:8)
Block(-8,146,1,STAINED_GLASS:15)
Block(-8,146,2,STANDING_BANNER:2,NBT/skyscraper_3x3_01/2591-bannerC16R0.nbt)
Block(-8,146,4,IRON_TRAPDOOR:0)
Block(-8,146,5,IRON_TRAPDOOR:0)
Block(-8,146,6,IRON_TRAPDOOR:0)
Block(-8,146,7,IRON_TRAPDOOR:2)
Block(-8,146,8,CONCRETE:8)
Block(-8,147,-7,CONCRETE:8)
Block(-8,147,-6,CONCRETE:8)
Block(-8,147,-1,CONCRETE:8)
Block(-8,147,0,CONCRETE:8)
Block(-8,147,1,STAINED_GLASS:15)
Block(-8,147,2,STANDING_BANNER:2,NBT/skyscraper_3x3_01/2592-bannerC16R0.nbt)
Block(-8,147,8,CONCRETE:8)
Block(-8,148,-7,CONCRETE:8)
Block(-8,148,-6,CONCRETE:8)
Block(-8,148,-1,CONCRETE:8)
Block(-8,148,0,CONCRETE:8)
Block(-8,148,1,STAINED_GLASS:15)
Block(-8,148,8,CONCRETE:8)
Block(-8,149,-7,CONCRETE:8)
Block(-8,149,-6,CONCRETE:8)
Block(-8,149,-1,CONCRETE:8)
Block(-8,149,0,CONCRETE:8)
Block(-8,149,1,STAINED_GLASS:15)
Block(-8,149,2,CONCRETE:15)
Block(-8,149,8,CONCRETE:8)
Block(-8,150,-7,CONCRETE:8)
Block(-8,150,-6,CONCRETE:8)
Block(-8,150,-1,CONCRETE:8)
Block(-8,150,0,CONCRETE:8)
Block(-8,150,1,STAINED_GLASS:15)
Block(-8,150,2,CONCRETE:8)
Block(-8,150,3,CONCRETE:8)
Block(-8,150,4,CONCRETE:15)
Block(-8,150,5,CONCRETE:15)
Block(-8,150,6,CONCRETE:15)
Block(-8,150,7,CONCRETE:15)
Block(-8,150,8,CONCRETE:15)
Block(-8,151,-7,CONCRETE:8)
Block(-8,151,-6,CONCRETE:8)
Block(-8,151,-1,CONCRETE:8)
Block(-8,151,0,CONCRETE:8)
Block(-8,151,1,STAINED_GLASS:15)
Block(-8,151,2,CONCRETE:15)
Block(-8,151,8,CONCRETE:8)
Block(-8,152,-7,CONCRETE:8)
Block(-8,152,-6,CONCRETE:8)
Block(-8,152,-1,CONCRETE:8)
Block(-8,152,0,CONCRETE:8)
Block(-8,152,1,STAINED_GLASS:15)
Block(-8,152,8,CONCRETE:8)
Block(-8,153,-7,CONCRETE:8)
Block(-8,153,-6,CONCRETE:8)
Block(-8,153,-1,CONCRETE:8)
Block(-8,153,0,CONCRETE:8)
Block(-8,153,1,STAINED_GLASS:15)
Block(-8,153,8,CONCRETE:8)
Block(-8,154,-7,CONCRETE:8)
Block(-8,154,-6,CONCRETE:8)
Block(-8,154,-1,CONCRETE:8)
Block(-8,154,0,CONCRETE:8)
Block(-8,154,1,STAINED_GLASS:15)
Block(-8,154,8,CONCRETE:8)
Block(-8,155,-7,CONCRETE:8)
Block(-8,155,-6,CONCRETE:8)
Block(-8,155,-1,CONCRETE:8)
Block(-8,155,0,CONCRETE:8)
Block(-8,155,1,STAINED_GLASS:15)
Block(-8,155,8,CONCRETE:8)
Block(-8,156,-7,CONCRETE:8)
Block(-8,156,-6,CONCRETE:8)
Block(-8,156,-1,CONCRETE:8)
Block(-8,156,0,CONCRETE:8)
Block(-8,156,1,STAINED_GLASS:15)
Block(-8,156,2,CONCRETE:8)
Block(-8,156,3,CONCRETE:8)
Block(-8,156,4,CONCRETE:15)
Block(-8,156,5,CONCRETE:15)
Block(-8,156,6,CONCRETE:15)
Block(-8,156,7,CONCRETE:15)
Block(-8,156,8,CONCRETE:15)
Block(-8,157,-7,CONCRETE:8)
Block(-8,157,-6,CONCRETE:8)
Block(-8,157,-1,CONCRETE:8)
Block(-8,157,0,CONCRETE:8)
Block(-8,157,1,STAINED_GLASS:15)
Block(-8,157,3,CARPET:0)
Block(-8,157,4,CARPET:0)
Block(-8,157,5,CARPET:0)
Block(-8,157,6,CARPET:0)
Block(-8,157,7,CARPET:0)
Block(-8,157,8,CONCRETE:8)
Block(-8,158,-7,CONCRETE:8)
Block(-8,158,-6,CONCRETE:8)
Block(-8,158,-1,CONCRETE:8)
Block(-8,158,0,CONCRETE:8)
Block(-8,158,1,STAINED_GLASS:15)
Block(-8,158,8,CONCRETE:8)
Block(-8,159,-7,CONCRETE:8)
Block(-8,159,-6,CONCRETE:8)
Block(-8,159,-1,CONCRETE:8)
Block(-8,159,0,CONCRETE:8)
Block(-8,159,1,STAINED_GLASS:15)
Block(-8,159,8,CONCRETE:8)
Block(-8,160,-7,CONCRETE:8)
Block(-8,160,-6,CONCRETE:8)
Block(-8,160,-1,CONCRETE:8)
Block(-8,160,0,CONCRETE:8)
Block(-8,160,1,STAINED_GLASS:15)
Block(-8,160,8,CONCRETE:8)
Block(-8,161,-7,CONCRETE:8)
Block(-8,161,-6,CONCRETE:8)
Block(-8,161,-1,CONCRETE:8)
Block(-8,161,0,CONCRETE:8)
Block(-8,161,1,STAINED_GLASS:15)
Block(-8,161,2,CONCRETE:15)
Block(-8,161,8,CONCRETE:8)
Block(-8,162,-7,CONCRETE:8)
Block(-8,162,-6,CONCRETE:8)
Block(-8,162,-1,CONCRETE:8)
Block(-8,162,0,CONCRETE:8)
Block(-8,162,1,STAINED_GLASS:15)
Block(-8,162,2,CONCRETE:8)
Block(-8,162,3,CONCRETE:8)
Block(-8,162,4,CONCRETE:15)
Block(-8,162,5,CONCRETE:15)
Block(-8,162,6,CONCRETE:15)
Block(-8,162,7,CONCRETE:15)
Block(-8,162,8,CONCRETE:8)
Block(-8,163,-7,CONCRETE:8)
Block(-8,163,-6,CONCRETE:8)
Block(-8,163,-1,CONCRETE:8)
Block(-8,163,0,CONCRETE:8)
Block(-8,163,1,STAINED_GLASS:15)
Block(-8,163,2,CONCRETE:15)
Block(-8,163,4,DARK_OAK_STAIRS:7)
Block(-8,163,5,STANDING_BANNER:13,NBT/skyscraper_3x3_01/2593-bannerC16R0.nbt)
Block(-8,163,6,STANDING_BANNER:11,NBT/skyscraper_3x3_01/2594-bannerC16R0.nbt)
Block(-8,163,7,DARK_OAK_STAIRS:6)
Block(-8,163,8,CONCRETE:8)
Block(-8,164,-7,CONCRETE:8)
Block(-8,164,-6,CONCRETE:8)
Block(-8,164,-1,CONCRETE:8)
Block(-8,164,0,CONCRETE:8)
Block(-8,164,1,STAINED_GLASS:15)
Block(-8,164,2,STANDING_BANNER:2,NBT/skyscraper_3x3_01/2595-bannerC16R0.nbt)
Block(-8,164,4,IRON_TRAPDOOR:0)
Block(-8,164,5,IRON_TRAPDOOR:0)
Block(-8,164,6,IRON_TRAPDOOR:0)
Block(-8,164,7,IRON_TRAPDOOR:2)
Block(-8,164,8,CONCRETE:8)
Block(-8,165,-7,CONCRETE:8)
Block(-8,165,-6,CONCRETE:8)
Block(-8,165,-1,CONCRETE:8)
Block(-8,165,0,CONCRETE:8)
Block(-8,165,1,STAINED_GLASS:15)
Block(-8,165,2,STANDING_BANNER:2,NBT/skyscraper_3x3_01/2596-bannerC16R0.nbt)
Block(-8,165,8,CONCRETE:8)
Block(-8,166,-7,CONCRETE:8)
Block(-8,166,-6,CONCRETE:8)
Block(-8,166,-1,CONCRETE:8)
Block(-8,166,0,CONCRETE:8)
Block(-8,166,1,STAINED_GLASS:15)
Block(-8,166,2,STANDING_BANNER:2,NBT/skyscraper_3x3_01/2597-bannerC16R0.nbt)
Block(-8,166,8,CONCRETE:8)
Block(-8,167,-7,CONCRETE:8)
Block(-8,167,-6,CONCRETE:8)
Block(-8,167,-1,CONCRETE:8)
Block(-8,167,0,CONCRETE:8)
Block(-8,167,1,STAINED_GLASS:15)
Block(-8,167,8,CONCRETE:8)
Block(-8,168,-7,CONCRETE:8)
Block(-8,168,-6,CONCRETE:8)
Block(-8,168,-1,CONCRETE:8)
Block(-8,168,0,CONCRETE:8)
Block(-8,168,1,STAINED_GLASS:15)
Block(-8,168,2,CONCRETE:8)
Block(-8,168,3,CONCRETE:8)
Block(-8,168,4,CONCRETE:15)
Block(-8,168,5,CONCRETE:15)
Block(-8,168,6,CONCRETE:15)
Block(-8,168,7,CONCRETE:15)
Block(-8,168,8,CONCRETE:8)
Block(-8,169,-7,CONCRETE:8)
Block(-8,169,-6,CONCRETE:8)
Block(-8,169,-1,CONCRETE:8)
Block(-8,169,0,CONCRETE:8)
Block(-8,169,1,STAINED_GLASS:15)
Block(-8,169,8,CONCRETE:8)
Block(-8,170,-7,CONCRETE:8)
Block(-8,170,-6,CONCRETE:8)
Block(-8,170,-1,CONCRETE:8)
Block(-8,170,0,CONCRETE:8)
Block(-8,170,1,STAINED_GLASS:15)
Block(-8,170,8,CONCRETE:8)
Block(-8,171,-7,CONCRETE:8)
Block(-8,171,-6,CONCRETE:8)
Block(-8,171,-1,CONCRETE:8)
Block(-8,171,0,CONCRETE:8)
Block(-8,171,1,STAINED_GLASS:15)
Block(-8,171,8,CONCRETE:8)
Block(-8,172,-7,CONCRETE:8)
Block(-8,172,-6,CONCRETE:8)
Block(-8,172,-1,CONCRETE:8)
Block(-8,172,0,CONCRETE:8)
Block(-8,172,1,STAINED_GLASS:15)
Block(-8,172,5,PRISMARINE:0)
Block(-8,172,8,CONCRETE:8)
Block(-8,173,-7,CONCRETE:8)
Block(-8,173,-6,CONCRETE:8)
Block(-8,173,-1,CONCRETE:8)
Block(-8,173,0,CONCRETE:8)
Block(-8,173,1,STAINED_GLASS:15)
Block(-8,173,2,CONCRETE:15)
Block(-8,173,5,IRON_FENCE:0)
Block(-8,173,8,CONCRETE:8)
Block(-8,174,-7,CONCRETE:8)
Block(-8,174,-6,CONCRETE:8)
Block(-8,174,-1,CONCRETE:8)
Block(-8,174,0,CONCRETE:8)
Block(-8,174,1,STAINED_GLASS:15)
Block(-8,174,2,CONCRETE:8)
Block(-8,174,3,CONCRETE:8)
Block(-8,174,4,CONCRETE:15)
Block(-8,174,5,CONCRETE:15)
Block(-8,174,6,CONCRETE:15)
Block(-8,174,7,CONCRETE:15)
Block(-8,174,8,CONCRETE:15)
Block(-8,175,-7,CONCRETE:8)
Block(-8,175,-6,CONCRETE:8)
Block(-8,175,-1,CONCRETE:8)
Block(-8,175,0,CONCRETE:8)
Block(-8,175,1,STAINED_GLASS:15)
Block(-8,175,2,CONCRETE:15)
Block(-8,175,8,CONCRETE:8)
Block(-8,176,-7,CONCRETE:8)
Block(-8,176,-6,CONCRETE:8)
Block(-8,176,-1,CONCRETE:8)
Block(-8,176,0,CONCRETE:8)
Block(-8,176,1,STAINED_GLASS:15)
Block(-8,176,8,CONCRETE:8)
Block(-8,177,-7,CONCRETE:8)
Block(-8,177,-6,CONCRETE:8)
Block(-8,177,-1,CONCRETE:8)
Block(-8,177,0,CONCRETE:8)
Block(-8,177,1,STAINED_GLASS:15)
Block(-8,177,8,CONCRETE:8)
Block(-8,178,-7,CONCRETE:8)
Block(-8,178,-6,CONCRETE:8)
Block(-8,178,-1,CONCRETE:8)
Block(-8,178,0,CONCRETE:8)
Block(-8,178,1,STAINED_GLASS:15)
Block(-8,178,8,CONCRETE:8)
Block(-8,179,-7,CONCRETE:8)
Block(-8,179,-6,CONCRETE:8)
Block(-8,179,-1,CONCRETE:8)
Block(-8,179,0,CONCRETE:8)
Block(-8,179,1,STAINED_GLASS:15)
Block(-8,179,8,CONCRETE:8)
Block(-8,180,-7,CONCRETE:8)
Block(-8,180,-6,CONCRETE:8)
Block(-8,180,-1,CONCRETE:8)
Block(-8,180,0,CONCRETE:8)
Block(-8,180,1,STAINED_GLASS:15)
Block(-8,180,2,CONCRETE:8)
Block(-8,180,3,CONCRETE:8)
Block(-8,180,4,CONCRETE:15)
Block(-8,180,5,CONCRETE:15)
Block(-8,180,6,CONCRETE:15)
Block(-8,180,7,CONCRETE:15)
Block(-8,180,8,CONCRETE:15)
Block(-8,181,-7,CONCRETE:8)
Block(-8,181,-6,CONCRETE:8)
Block(-8,181,-1,CONCRETE:8)
Block(-8,181,0,CONCRETE:8)
Block(-8,181,1,STAINED_GLASS:15)
Block(-8,181,8,CONCRETE:8)
Block(-8,182,-7,CONCRETE:8)
Block(-8,182,-6,CONCRETE:8)
Block(-8,182,-1,CONCRETE:8)
Block(-8,182,0,CONCRETE:8)
Block(-8,182,1,STAINED_GLASS:15)
Block(-8,182,8,CONCRETE:8)
Block(-8,183,-7,CONCRETE:8)
Block(-8,183,-6,CONCRETE:8)
Block(-8,183,-1,CONCRETE:8)
Block(-8,183,0,CONCRETE:8)
Block(-8,183,1,STAINED_GLASS:15)
Block(-8,183,8,CONCRETE:8)
Block(-8,184,-7,CONCRETE:8)
Block(-8,184,-6,CONCRETE:8)
Block(-8,184,-1,CONCRETE:8)
Block(-8,184,0,CONCRETE:8)
Block(-8,184,1,STAINED_GLASS:15)
Block(-8,184,8,CONCRETE:8)
Block(-8,185,-7,CONCRETE:8)
Block(-8,185,-6,CONCRETE:8)
Block(-8,185,-1,CONCRETE:8)
Block(-8,185,0,CONCRETE:8)
Block(-8,185,1,STAINED_GLASS:15)
Block(-8,185,2,CONCRETE:15)
Block(-8,185,8,CONCRETE:8)
Block(-8,186,-7,CONCRETE:8)
Block(-8,186,-6,CONCRETE:8)
Block(-8,186,-1,CONCRETE:8)
Block(-8,186,0,CONCRETE:8)
Block(-8,186,1,STAINED_GLASS:15)
Block(-8,186,2,CONCRETE:8)
Block(-8,186,3,CONCRETE:8)
Block(-8,186,4,CONCRETE:15)
Block(-8,186,5,CONCRETE:15)
Block(-8,186,6,CONCRETE:15)
Block(-8,186,7,CONCRETE:15)
Block(-8,186,8,CONCRETE:15)
Block(-8,187,-7,CONCRETE:8)
Block(-8,187,-6,CONCRETE:8)
Block(-8,187,-1,CONCRETE:8)
Block(-8,187,0,CONCRETE:8)
Block(-8,187,1,STAINED_GLASS:15)
Block(-8,187,2,CONCRETE:15)
Block(-8,187,3,CARPET:0)
Block(-8,187,4,CARPET:0)
Block(-8,187,5,CARPET:0)
Block(-8,187,6,CARPET:0)
Block(-8,187,7,CARPET:0)
Block(-8,187,8,CONCRETE:8)
Block(-8,188,-7,CONCRETE:8)
Block(-8,188,-6,CONCRETE:8)
Block(-8,188,-1,CONCRETE:8)
Block(-8,188,0,CONCRETE:8)
Block(-8,188,1,STAINED_GLASS:15)
Block(-8,188,8,CONCRETE:8)
Block(-8,189,-7,CONCRETE:8)
Block(-8,189,-6,CONCRETE:8)
Block(-8,189,-1,CONCRETE:8)
Block(-8,189,0,CONCRETE:8)
Block(-8,189,1,STAINED_GLASS:15)
Block(-8,189,8,CONCRETE:8)
Block(-8,190,-7,CONCRETE:8)
Block(-8,190,-6,CONCRETE:8)
Block(-8,190,-1,CONCRETE:8)
Block(-8,190,0,CONCRETE:8)
Block(-8,190,1,STAINED_GLASS:15)
Block(-8,190,8,CONCRETE:8)
Block(-8,191,-7,CONCRETE:8)
Block(-8,191,-6,CONCRETE:8)
Block(-8,191,-1,CONCRETE:8)
Block(-8,191,0,CONCRETE:8)
Block(-8,191,1,STAINED_GLASS:15)
Block(-8,191,8,CONCRETE:8)
Block(-8,192,-7,CONCRETE:8)
Block(-8,192,-6,CONCRETE:8)
Block(-8,192,-1,CONCRETE:8)
Block(-8,192,0,CONCRETE:8)
Block(-8,192,1,STAINED_GLASS:15)
Block(-8,192,2,CONCRETE:8)
Block(-8,192,3,CONCRETE:8)
Block(-8,192,4,CONCRETE:8)
Block(-8,192,5,CONCRETE:8)
Block(-8,192,6,CONCRETE:8)
Block(-8,192,7,CONCRETE:8)
Block(-8,192,8,CONCRETE:8)
Block(-8,193,-7,CONCRETE:8)
Block(-8,193,-6,CONCRETE:8)
Block(-8,193,-1,CONCRETE:8)
Block(-8,193,0,CONCRETE:8)
Block(-8,193,1,STAINED_GLASS:15)
Block(-8,193,4,BOOKSHELF:0)
Block(-8,193,5,BOOKSHELF:0)
Block(-8,193,6,BOOKSHELF:0)
Block(-8,193,7,BOOKSHELF:0)
Block(-8,194,-7,CONCRETE:8)
Block(-8,194,-6,CONCRETE:8)
Block(-8,194,-1,CONCRETE:8)
Block(-8,194,0,CONCRETE:8)
Block(-8,194,1,STAINED_GLASS:15)
Block(-8,194,4,BOOKSHELF:0)
Block(-8,194,5,BOOKSHELF:0)
Block(-8,194,6,BOOKSHELF:0)
Block(-8,194,7,BOOKSHELF:0)
Block(-8,195,-7,CONCRETE:8)
Block(-8,195,-6,CONCRETE:8)
Block(-8,195,-1,CONCRETE:8)
Block(-8,195,0,CONCRETE:8)
Block(-8,195,1,STAINED_GLASS:15)
Block(-8,195,4,BOOKSHELF:0)
Block(-8,195,5,BOOKSHELF:0)
Block(-8,195,6,BOOKSHELF:0)
Block(-8,195,7,BOOKSHELF:0)
Block(-8,196,-7,CONCRETE:8)
Block(-8,196,-6,CONCRETE:8)
Block(-8,196,-1,CONCRETE:8)
Block(-8,196,0,CONCRETE:8)
Block(-8,196,1,STAINED_GLASS:15)
Block(-8,196,4,BOOKSHELF:0)
Block(-8,196,5,BOOKSHELF:0)
Block(-8,196,6,BOOKSHELF:0)
Block(-8,196,7,BOOKSHELF:0)
Block(-8,197,-7,CONCRETE:8)
Block(-8,197,-6,CONCRETE:8)
Block(-8,197,-1,CONCRETE:8)
Block(-8,197,0,CONCRETE:8)
Block(-8,197,1,STAINED_GLASS:15)
Block(-8,197,2,CONCRETE:15)
Block(-8,197,4,WOOD_STEP:5)
Block(-8,197,5,WOOD_STEP:5)
Block(-8,197,6,WOOD_STEP:5)
Block(-8,197,7,WOOD_STEP:5)
Block(-8,198,-7,CONCRETE:8)
Block(-8,198,-6,CONCRETE:8)
Block(-8,198,-1,CONCRETE:8)
Block(-8,198,0,CONCRETE:8)
Block(-8,198,1,STAINED_GLASS:15)
Block(-8,198,2,CONCRETE:8)
Block(-8,198,3,CONCRETE:8)
Block(-8,198,4,CONCRETE:8)
Block(-8,198,5,CONCRETE:8)
Block(-8,198,6,CONCRETE:8)
Block(-8,198,7,CONCRETE:8)
Block(-8,198,8,CONCRETE:8)
Block(-8,199,-7,CONCRETE:8)
Block(-8,199,-6,CONCRETE:8)
Block(-8,199,-1,CONCRETE:8)
Block(-8,199,0,CONCRETE:8)
Block(-8,199,1,STAINED_GLASS:15)
Block(-8,199,2,CONCRETE:8)
Block(-8,199,3,CONCRETE:8)
Block(-8,199,4,CONCRETE:8)
Block(-8,199,5,CONCRETE:8)
Block(-8,199,6,CONCRETE:8)
Block(-8,199,7,CONCRETE:8)
Block(-8,199,8,CONCRETE:8)
Block(-8,200,-7,CONCRETE:8)
Block(-8,200,-6,CONCRETE:8)
Block(-8,200,-1,CONCRETE:8)
Block(-8,200,0,CONCRETE:8)
Block(-8,200,1,STAINED_GLASS_PANE:15)
Block(-8,200,2,STAINED_GLASS_PANE:15)
Block(-8,200,5,DAYLIGHT_DETECTOR_INVERTED:1,NBT/skyscraper_3x3_01/2608-daylight_detectorC16R0.nbt)
Block(-8,200,6,STEP:7)
Block(-8,200,7,DAYLIGHT_DETECTOR_INVERTED:1,NBT/skyscraper_3x3_01/2609-daylight_detectorC16R0.nbt)
Block(-8,201,-7,CONCRETE:8)
Block(-8,201,-6,CONCRETE:8)
Block(-8,201,-1,CONCRETE:8)
Block(-8,201,0,CONCRETE:8)
Block(-8,201,1,STAINED_GLASS_PANE:15)
Block(-8,201,2,STAINED_GLASS_PANE:15)
Block(-8,202,-7,STEP:0)
Block(-8,202,-6,STEP:0)
Block(-8,202,-1,STEP:0)
Block(-8,202,0,STEP:0)
Block(-7,0,-7,CONCRETE:7)
Block(-7,0,-6,CONCRETE:7)
Block(-7,0,-5,CONCRETE:7)
Block(-7,0,-4,CONCRETE:7)
Block(-7,0,-3,CONCRETE:7)
Block(-7,0,-2,CONCRETE:7)
Block(-7,0,-1,CONCRETE:7)
Block(-7,0,0,CONCRETE:7)
Block(-7,0,1,CONCRETE:7)
Block(-7,0,2,CONCRETE:7)
Block(-7,0,3,CONCRETE:7)
Block(-7,0,4,CONCRETE:7)
Block(-7,0,5,CONCRETE:7)
Block(-7,0,6,CONCRETE:7)
Block(-7,0,7,CONCRETE:7)
Block(-7,0,8,CONCRETE:7)
Block(-7,1,-7,CONCRETE:7)
Block(-7,1,-6,CONCRETE:7)
Block(-7,1,-5,CONCRETE:7)
Block(-7,1,-4,CONCRETE:7)
Block(-7,1,-3,CONCRETE:7)
Block(-7,1,-2,CONCRETE:7)
Block(-7,1,-1,CONCRETE:7)
Block(-7,1,0,CONCRETE:7)
Block(-7,1,1,CONCRETE:7)
Block(-7,1,2,CONCRETE:7)
Block(-7,1,3,CONCRETE:7)
Block(-7,1,4,CONCRETE:7)
Block(-7,1,5,CONCRETE:7)
Block(-7,1,6,CONCRETE:7)
Block(-7,1,7,CONCRETE:7)
Block(-7,1,8,CONCRETE:7)
Block(-7,2,-7,CONCRETE:7)
Block(-7,2,-6,CONCRETE:7)
Block(-7,2,-5,CONCRETE:7)
Block(-7,2,-4,CONCRETE:7)
Block(-7,2,-3,CONCRETE:7)
Block(-7,2,-2,CONCRETE:7)
Block(-7,2,-1,CONCRETE:7)
Block(-7,2,0,CONCRETE:7)
Block(-7,2,1,CONCRETE:7)
Block(-7,2,2,CONCRETE:7)
Block(-7,2,3,CONCRETE:7)
Block(-7,2,4,CONCRETE:7)
Block(-7,2,5,CONCRETE:7)
Block(-7,2,6,CONCRETE:7)
Block(-7,2,7,CONCRETE:7)
Block(-7,2,8,CONCRETE:7)
Block(-7,3,-7,AIR:0)
Block(-7,3,-6,AIR:0)
Block(-7,3,-5,AIR:0)
Block(-7,3,-4,AIR:0)
Block(-7,3,-3,AIR:0)
Block(-7,3,-2,AIR:0)
Block(-7,3,-1,AIR:0)
Block(-7,3,0,AIR:0)
Block(-7,3,1,AIR:0)
Block(-7,3,2,AIR:0)
Block(-7,3,3,AIR:0)
Block(-7,3,4,AIR:0)
Block(-7,3,5,AIR:0)
Block(-7,3,6,AIR:0)
Block(-7,3,7,AIR:0)
Block(-7,3,8,AIR:0)
Block(-7,4,-7,AIR:0)
Block(-7,4,-6,AIR:0)
Block(-7,4,-5,AIR:0)
Block(-7,4,-4,AIR:0)
Block(-7,4,-3,AIR:0)
Block(-7,4,-2,AIR:0)
Block(-7,4,-1,AIR:0)
Block(-7,4,0,AIR:0)
Block(-7,4,1,AIR:0)
Block(-7,4,2,AIR:0)
Block(-7,4,3,AIR:0)
Block(-7,4,4,AIR:0)
Block(-7,4,5,AIR:0)
Block(-7,4,6,AIR:0)
Block(-7,4,7,AIR:0)
Block(-7,4,8,AIR:0)
Block(-7,5,-7,AIR:0)
Block(-7,5,-6,AIR:0)
Block(-7,5,-5,AIR:0)
Block(-7,5,-4,AIR:0)
Block(-7,5,-3,AIR:0)
Block(-7,5,-2,AIR:0)
Block(-7,5,-1,AIR:0)
Block(-7,5,0,AIR:0)
Block(-7,5,1,AIR:0)
Block(-7,5,2,AIR:0)
Block(-7,5,3,AIR:0)
Block(-7,5,4,AIR:0)
Block(-7,5,5,AIR:0)
Block(-7,5,6,AIR:0)
Block(-7,5,7,AIR:0)
Block(-7,5,8,AIR:0)
Block(-7,6,-7,CONCRETE:7)
Block(-7,6,-6,CONCRETE:7)
Block(-7,6,-5,STEP:8)
Block(-7,6,-4,STEP:8)
Block(-7,6,-3,CONCRETE:7)
Block(-7,6,-2,STEP:8)
Block(-7,6,-1,STEP:8)
Block(-7,6,0,CONCRETE:7)
Block(-7,6,1,STEP:8)
Block(-7,6,2,STEP:8)
Block(-7,6,3,CONCRETE:7)
Block(-7,6,4,STEP:8)
Block(-7,6,5,STEP:8)
Block(-7,6,6,CONCRETE:7)
Block(-7,6,7,STEP:8)
Block(-7,6,8,STEP:8)
Block(-7,7,-7,CONCRETE:7)
Block(-7,7,-6,CONCRETE:7)
Block(-7,7,-5,CONCRETE:7)
Block(-7,7,-4,CONCRETE:7)
Block(-7,7,-3,CONCRETE:7)
Block(-7,7,-2,CONCRETE:7)
Block(-7,7,-1,CONCRETE:7)
Block(-7,7,0,CONCRETE:7)
Block(-7,7,1,CONCRETE:7)
Block(-7,7,2,CONCRETE:7)
Block(-7,7,3,CONCRETE:7)
Block(-7,7,4,CONCRETE:7)
Block(-7,7,5,CONCRETE:7)
Block(-7,7,6,CONCRETE:7)
Block(-7,7,7,CONCRETE:7)
Block(-7,7,8,CONCRETE:7)
Block(-7,8,-7,CONCRETE:7)
Block(-7,8,-6,CONCRETE:7)
Block(-7,8,-5,CONCRETE:7)
Block(-7,8,-4,CONCRETE:7)
Block(-7,8,-3,CONCRETE:7)
Block(-7,8,-2,CONCRETE:7)
Block(-7,8,-1,CONCRETE:7)
Block(-7,8,0,CONCRETE:7)
Block(-7,8,1,CONCRETE:7)
Block(-7,8,2,CONCRETE:7)
Block(-7,8,3,CONCRETE:7)
Block(-7,8,4,CONCRETE:7)
Block(-7,8,5,CONCRETE:7)
Block(-7,8,6,CONCRETE:7)
Block(-7,8,7,CONCRETE:7)
Block(-7,8,8,CONCRETE:7)
Block(-7,9,-7,CONCRETE:7)
Block(-7,9,-6,CONCRETE:8)
Block(-7,9,-5,CONCRETE:8)
Block(-7,9,-4,CONCRETE:15)
Block(-7,9,-3,CONCRETE:15)
Block(-7,9,-2,CONCRETE:8)
Block(-7,9,-1,CONCRETE:8)
Block(-7,9,0,CONCRETE:8)
Block(-7,9,1,CONCRETE:8)
Block(-7,9,2,CONCRETE:8)
Block(-7,9,3,CONCRETE:8)
Block(-7,9,4,CONCRETE:7)
Block(-7,9,5,CONCRETE:7)
Block(-7,9,6,CONCRETE:7)
Block(-7,9,7,CONCRETE:7)
Block(-7,9,8,CONCRETE:7)
Block(-7,10,-7,CONCRETE:7)
Block(-7,10,-6,CONCRETE:8)
Block(-7,10,-5,STAINED_GLASS:15)
Block(-7,10,-4,CONCRETE:15)
Block(-7,10,-3,CONCRETE:15)
Block(-7,10,-2,STAINED_GLASS:15)
Block(-7,10,-1,CONCRETE:8)
Block(-7,10,0,CONCRETE:8)
Block(-7,10,1,STAINED_GLASS:15)
Block(-7,10,2,STAINED_GLASS:15)
Block(-7,10,3,CONCRETE:8)
Block(-7,10,4,CONCRETE:7)
Block(-7,10,5,CONCRETE:7)
Block(-7,10,6,CONCRETE:7)
Block(-7,10,7,CONCRETE:7)
Block(-7,10,8,CONCRETE:7)
Block(-7,11,-7,CONCRETE:7)
Block(-7,11,-6,CONCRETE:8)
Block(-7,11,-5,STATIONARY_WATER:0)
Block(-7,11,-4,STATIONARY_WATER:0)
Block(-7,11,-3,STATIONARY_WATER:0)
Block(-7,11,-2,STATIONARY_WATER:0)
Block(-7,11,-1,CONCRETE:8)
Block(-7,11,0,CONCRETE:8)
Block(-7,11,1,STATIONARY_WATER:0)
Block(-7,11,2,STAINED_GLASS:15)
Block(-7,11,3,CONCRETE:8)
Block(-7,11,4,CONCRETE:7)
Block(-7,11,5,CONCRETE:7)
Block(-7,11,6,CONCRETE:7)
Block(-7,11,7,CONCRETE:7)
Block(-7,11,8,CONCRETE:7)
Block(-7,12,-7,CONCRETE:7)
Block(-7,12,-6,STATIONARY_WATER:0)
Block(-7,12,-5,STATIONARY_WATER:0)
Block(-7,12,-4,STATIONARY_WATER:0)
Block(-7,12,-3,STATIONARY_WATER:0)
Block(-7,12,-2,STATIONARY_WATER:0)
Block(-7,12,-1,STATIONARY_WATER:0)
Block(-7,12,0,STATIONARY_WATER:0)
Block(-7,12,1,STATIONARY_WATER:0)
Block(-7,12,2,STAINED_GLASS:15)
Block(-7,12,3,CONCRETE:8)
Block(-7,12,4,CONCRETE:7)
Block(-7,12,5,CONCRETE:7)
Block(-7,12,6,CONCRETE:7)
Block(-7,12,7,CONCRETE:7)
Block(-7,12,8,CONCRETE:7)
Block(-7,13,-7,CONCRETE:7)
Block(-7,13,-6,AIR:0)
Block(-7,13,-5,AIR:0)
Block(-7,13,-4,AIR:0)
Block(-7,13,-3,AIR:0)
Block(-7,13,-2,AIR:0)
Block(-7,13,-1,AIR:0)
Block(-7,13,0,AIR:0)
Block(-7,13,1,AIR:0)
Block(-7,13,2,STAINED_GLASS:15)
Block(-7,13,3,CONCRETE:8)
Block(-7,13,4,CONCRETE:7)
Block(-7,13,5,CONCRETE:7)
Block(-7,13,6,CONCRETE:7)
Block(-7,13,7,CONCRETE:7)
Block(-7,13,8,CONCRETE:7)
Block(-7,14,-7,CONCRETE:7)
Block(-7,14,-6,AIR:0)
Block(-7,14,-5,AIR:0)
Block(-7,14,-4,AIR:0)
Block(-7,14,-3,AIR:0)
Block(-7,14,-2,AIR:0)
Block(-7,14,-1,AIR:0)
Block(-7,14,0,AIR:0)
Block(-7,14,1,AIR:0)
Block(-7,14,2,STAINED_GLASS:15)
Block(-7,14,3,CONCRETE:8)
Block(-7,14,4,CONCRETE:7)
Block(-7,14,5,CONCRETE:7)
Block(-7,14,6,CONCRETE:7)
Block(-7,14,7,CONCRETE:7)
Block(-7,14,8,CONCRETE:7)
Block(-7,15,-7,CONCRETE:7)
Block(-7,15,-6,AIR:0)
Block(-7,15,-5,AIR:0)
Block(-7,15,-4,AIR:0)
Block(-7,15,-3,AIR:0)
Block(-7,15,-2,AIR:0)
Block(-7,15,-1,AIR:0)
Block(-7,15,0,AIR:0)
Block(-7,15,1,AIR:0)
Block(-7,15,2,STAINED_GLASS:15)
Block(-7,15,3,CONCRETE:8)
Block(-7,15,4,CONCRETE:7)
Block(-7,15,5,CONCRETE:7)
Block(-7,15,6,CONCRETE:7)
Block(-7,15,7,CONCRETE:7)
Block(-7,15,8,CONCRETE:7)
Block(-7,16,-7,CONCRETE:7)
Block(-7,16,-6,AIR:0)
Block(-7,16,-5,AIR:0)
Block(-7,16,-4,AIR:0)
Block(-7,16,-3,AIR:0)
Block(-7,16,-2,AIR:0)
Block(-7,16,-1,AIR:0)
Block(-7,16,0,AIR:0)
Block(-7,16,1,AIR:0)
Block(-7,16,2,STAINED_GLASS:15)
Block(-7,16,3,CONCRETE:8)
Block(-7,16,4,CONCRETE:7)
Block(-7,16,5,CONCRETE:7)
Block(-7,16,6,CONCRETE:7)
Block(-7,16,7,CONCRETE:7)
Block(-7,16,8,CONCRETE:7)
Block(-7,17,-7,CONCRETE:7)
Block(-7,17,-6,AIR:0)
Block(-7,17,-5,AIR:0)
Block(-7,17,-4,AIR:0)
Block(-7,17,-3,AIR:0)
Block(-7,17,-2,AIR:0)
Block(-7,17,-1,AIR:0)
Block(-7,17,0,AIR:0)
Block(-7,17,1,AIR:0)
Block(-7,17,2,STAINED_GLASS:15)
Block(-7,17,3,CONCRETE:8)
Block(-7,17,4,CONCRETE:7)
Block(-7,17,5,CONCRETE:7)
Block(-7,17,6,CONCRETE:7)
Block(-7,17,7,CONCRETE:7)
Block(-7,17,8,CONCRETE:7)
Block(-7,18,-7,STAINED_GLASS_PANE:15)
Block(-7,18,2,STAINED_GLASS:15)
Block(-7,18,3,CONCRETE:8)
Block(-7,18,4,CONCRETE:8)
Block(-7,18,5,CONCRETE:15)
Block(-7,18,6,CONCRETE:15)
Block(-7,18,7,CONCRETE:15)
Block(-7,18,8,CONCRETE:15)
Block(-7,19,2,STAINED_GLASS:15)
Block(-7,20,2,STAINED_GLASS:15)
Block(-7,20,3,CONCRETE:15)
Block(-7,21,2,STAINED_GLASS:15)
Block(-7,22,2,STAINED_GLASS:15)
Block(-7,23,2,STAINED_GLASS:15)
Block(-7,24,2,STAINED_GLASS:15)
Block(-7,24,3,CONCRETE:8)
Block(-7,24,4,CONCRETE:8)
Block(-7,24,5,CONCRETE:15)
Block(-7,24,6,CONCRETE:15)
Block(-7,24,8,CONCRETE:15)
Block(-7,25,2,STAINED_GLASS:15)
Block(-7,25,5,STAINED_GLASS_PANE:15)
Block(-7,25,6,STAINED_GLASS_PANE:15)
Block(-7,25,8,STAINED_GLASS_PANE:15)
Block(-7,26,2,STAINED_GLASS:15)
Block(-7,27,2,STAINED_GLASS:15)
Block(-7,28,2,STAINED_GLASS:15)
Block(-7,28,3,CONCRETE:15)
Block(-7,29,2,STAINED_GLASS:15)
Block(-7,30,2,STAINED_GLASS:15)
Block(-7,30,3,CONCRETE:8)
Block(-7,30,4,CONCRETE:8)
Block(-7,30,5,CONCRETE:15)
Block(-7,30,6,CONCRETE:15)
Block(-7,30,7,CONCRETE:15)
Block(-7,30,8,CONCRETE:15)
Block(-7,31,2,STAINED_GLASS:15)
Block(-7,31,8,DARK_OAK_DOOR:1)
Block(-7,32,2,STAINED_GLASS:15)
Block(-7,32,3,CONCRETE:15)
Block(-7,32,8,DARK_OAK_DOOR:9)
Block(-7,33,2,STAINED_GLASS:15)
Block(-7,33,8,CONCRETE:8)
Block(-7,34,2,STAINED_GLASS:15)
Block(-7,34,8,CONCRETE:8)
Block(-7,35,2,STAINED_GLASS:15)
Block(-7,35,8,CONCRETE:8)
Block(-7,36,2,STAINED_GLASS:15)
Block(-7,36,3,CONCRETE:8)
Block(-7,36,4,CONCRETE:8)
Block(-7,36,5,CONCRETE:15)
Block(-7,36,6,CONCRETE:15)
Block(-7,36,7,CONCRETE:15)
Block(-7,36,8,CONCRETE:15)
Block(-7,37,2,STAINED_GLASS:15)
Block(-7,37,8,DARK_OAK_DOOR:1)
Block(-7,38,2,STAINED_GLASS:15)
Block(-7,38,8,DARK_OAK_DOOR:9)
Block(-7,39,2,STAINED_GLASS:15)
Block(-7,39,8,CONCRETE:8)
Block(-7,40,2,STAINED_GLASS:15)
Block(-7,40,3,CONCRETE:15)
Block(-7,40,8,CONCRETE:8)
Block(-7,41,2,STAINED_GLASS:15)
Block(-7,41,5,IRON_TRAPDOOR:8)
Block(-7,41,6,IRON_TRAPDOOR:8)
Block(-7,41,8,CONCRETE:8)
Block(-7,42,2,STAINED_GLASS:15)
Block(-7,42,3,CONCRETE:8)
Block(-7,42,4,CONCRETE:8)
Block(-7,42,5,CONCRETE:15)
Block(-7,42,6,CONCRETE:15)
Block(-7,42,7,CONCRETE:15)
Block(-7,42,8,CONCRETE:15)
Block(-7,43,2,STAINED_GLASS:15)
Block(-7,43,3,CARPET:0)
Block(-7,43,4,CARPET:0)
Block(-7,43,5,CARPET:0)
Block(-7,43,6,CARPET:0)
Block(-7,43,7,CARPET:0)
Block(-7,43,8,DARK_OAK_DOOR:1)
Block(-7,44,2,STAINED_GLASS:15)
Block(-7,44,3,CONCRETE:15)
Block(-7,44,8,DARK_OAK_DOOR:9)
Block(-7,45,2,STAINED_GLASS:15)
Block(-7,45,8,CONCRETE:8)
Block(-7,46,2,STAINED_GLASS:15)
Block(-7,46,8,CONCRETE:8)
Block(-7,47,2,STAINED_GLASS:15)
Block(-7,47,8,CONCRETE:8)
Block(-7,48,2,STAINED_GLASS:15)
Block(-7,48,3,CONCRETE:8)
Block(-7,48,4,CONCRETE:8)
Block(-7,48,5,CONCRETE:15)
Block(-7,48,6,CONCRETE:15)
Block(-7,48,7,CONCRETE:15)
Block(-7,48,8,CONCRETE:8)
Block(-7,49,2,STAINED_GLASS:15)
Block(-7,49,3,STANDING_BANNER:2,NBT/skyscraper_3x3_01/2613-bannerC16R0.nbt)
Block(-7,49,5,WALL_SIGN:2,NBT/skyscraper_3x3_01/2614-signC16R0.nbt)
Block(-7,49,6,DARK_OAK_STAIRS:0)
Block(-7,49,7,WALL_SIGN:3,NBT/skyscraper_3x3_01/2615-signC16R0.nbt)
Block(-7,49,8,CONCRETE:8)
Block(-7,50,2,STAINED_GLASS:15)
Block(-7,50,3,STANDING_BANNER:2,NBT/skyscraper_3x3_01/2616-bannerC16R0.nbt)
Block(-7,50,6,WALL_BANNER:4,NBT/skyscraper_3x3_01/2617-bannerC16R0.nbt)
Block(-7,50,8,CONCRETE:8)
Block(-7,51,2,STAINED_GLASS:15)
Block(-7,51,8,CONCRETE:8)
Block(-7,52,2,STAINED_GLASS:15)
Block(-7,52,3,CONCRETE:15)
Block(-7,52,8,CONCRETE:8)
Block(-7,53,2,STAINED_GLASS:15)
Block(-7,53,3,STANDING_BANNER:2,NBT/skyscraper_3x3_01/2618-bannerC16R0.nbt)
Block(-7,53,8,CONCRETE:8)
Block(-7,54,2,STAINED_GLASS:15)
Block(-7,54,3,CONCRETE:8)
Block(-7,54,4,CONCRETE:8)
Block(-7,54,5,CONCRETE:15)
Block(-7,54,6,CONCRETE:15)
Block(-7,54,7,CONCRETE:15)
Block(-7,54,8,CONCRETE:8)
Block(-7,55,2,STAINED_GLASS:15)
Block(-7,55,8,DARK_OAK_DOOR:1)
Block(-7,56,2,STAINED_GLASS:15)
Block(-7,56,3,CONCRETE:15)
Block(-7,56,8,DARK_OAK_DOOR:9)
Block(-7,57,2,STAINED_GLASS:15)
Block(-7,57,8,CONCRETE:8)
Block(-7,58,2,STAINED_GLASS:15)
Block(-7,58,8,CONCRETE:8)
Block(-7,59,2,STAINED_GLASS:15)
Block(-7,59,8,CONCRETE:8)
Block(-7,60,2,STAINED_GLASS:15)
Block(-7,60,3,CONCRETE:8)
Block(-7,60,4,CONCRETE:8)
Block(-7,60,5,CONCRETE:15)
Block(-7,60,6,CONCRETE:15)
Block(-7,60,7,CONCRETE:15)
Block(-7,60,8,CONCRETE:15)
Block(-7,61,2,STAINED_GLASS:15)
Block(-7,61,3,CARPET:0)
Block(-7,61,4,CARPET:0)
Block(-7,61,5,CARPET:0)
Block(-7,61,6,CARPET:0)
Block(-7,61,7,CARPET:0)
Block(-7,61,8,DARK_OAK_DOOR:1)
Block(-7,62,2,STAINED_GLASS:15)
Block(-7,62,8,DARK_OAK_DOOR:9)
Block(-7,63,2,STAINED_GLASS:15)
Block(-7,63,8,CONCRETE:8)
Block(-7,64,2,STAINED_GLASS:15)
Block(-7,64,3,CONCRETE:15)
Block(-7,64,8,CONCRETE:8)
Block(-7,65,2,STAINED_GLASS:15)
Block(-7,65,8,CONCRETE:8)
Block(-7,66,2,STAINED_GLASS:15)
Block(-7,66,3,CONCRETE:8)
Block(-7,66,4,CONCRETE:8)
Block(-7,66,5,CONCRETE:15)
Block(-7,66,6,CONCRETE:15)
Block(-7,66,7,CONCRETE:15)
Block(-7,66,8,CONCRETE:8)
Block(-7,67,2,STAINED_GLASS:15)
Block(-7,67,3,STANDING_BANNER:2,NBT/skyscraper_3x3_01/2619-bannerC16R0.nbt)
Block(-7,67,5,WALL_SIGN:2,NBT/skyscraper_3x3_01/2620-signC16R0.nbt)
Block(-7,67,6,DARK_OAK_STAIRS:0)
Block(-7,67,7,WALL_SIGN:3,NBT/skyscraper_3x3_01/2621-signC16R0.nbt)
Block(-7,67,8,CONCRETE:8)
Block(-7,68,2,STAINED_GLASS:15)
Block(-7,68,3,CONCRETE:15)
Block(-7,68,6,WALL_BANNER:4,NBT/skyscraper_3x3_01/2622-bannerC16R0.nbt)
Block(-7,68,8,CONCRETE:8)
Block(-7,69,2,STAINED_GLASS:15)
Block(-7,69,3,STANDING_BANNER:2,NBT/skyscraper_3x3_01/2623-bannerC16R0.nbt)
Block(-7,69,8,CONCRETE:8)
Block(-7,70,2,STAINED_GLASS:15)
Block(-7,70,3,STANDING_BANNER:2,NBT/skyscraper_3x3_01/2624-bannerC16R0.nbt)
Block(-7,70,8,CONCRETE:8)
Block(-7,71,2,STAINED_GLASS:15)
Block(-7,71,3,STANDING_BANNER:2,NBT/skyscraper_3x3_01/2625-bannerC16R0.nbt)
Block(-7,71,8,CONCRETE:8)
Block(-7,72,2,STAINED_GLASS:15)
Block(-7,72,3,CONCRETE:8)
Block(-7,72,4,CONCRETE:8)
Block(-7,72,5,CONCRETE:15)
Block(-7,72,6,CONCRETE:15)
Block(-7,72,7,CONCRETE:15)
Block(-7,72,8,CONCRETE:8)
Block(-7,73,2,STAINED_GLASS:15)
Block(-7,73,8,DARK_OAK_DOOR:1)
Block(-7,74,2,STAINED_GLASS:15)
Block(-7,74,8,DARK_OAK_DOOR:9)
Block(-7,75,2,STAINED_GLASS:15)
Block(-7,75,8,CONCRETE:8)
Block(-7,76,2,STAINED_GLASS:15)
Block(-7,76,3,CONCRETE:15)
Block(-7,76,8,CONCRETE:8)
Block(-7,77,2,STAINED_GLASS:15)
Block(-7,77,8,CONCRETE:8)
Block(-7,78,2,STAINED_GLASS:15)
Block(-7,78,3,CONCRETE:8)
Block(-7,78,4,CONCRETE:8)
Block(-7,78,5,CONCRETE:15)
Block(-7,78,6,CONCRETE:15)
Block(-7,78,7,CONCRETE:15)
Block(-7,78,8,CONCRETE:15)
Block(-7,79,2,STAINED_GLASS:15)
Block(-7,79,8,DARK_OAK_DOOR:1)
Block(-7,80,2,STAINED_GLASS:15)
Block(-7,80,3,CONCRETE:15)
Block(-7,80,8,DARK_OAK_DOOR:9)
Block(-7,81,2,STAINED_GLASS:15)
Block(-7,81,8,CONCRETE:8)
Block(-7,82,2,STAINED_GLASS:15)
Block(-7,82,8,CONCRETE:8)
Block(-7,83,2,STAINED_GLASS:15)
Block(-7,83,8,CONCRETE:8)
Block(-7,84,2,STAINED_GLASS:15)
Block(-7,84,3,CONCRETE:8)
Block(-7,84,4,CONCRETE:8)
Block(-7,84,5,CONCRETE:15)
Block(-7,84,6,CONCRETE:15)
Block(-7,84,7,CONCRETE:15)
Block(-7,84,8,CONCRETE:15)
Block(-7,85,2,STAINED_GLASS:15)
Block(-7,85,8,DARK_OAK_DOOR:1)
Block(-7,86,2,STAINED_GLASS:15)
Block(-7,86,8,DARK_OAK_DOOR:9)
Block(-7,87,2,STAINED_GLASS:15)
Block(-7,87,8,CONCRETE:8)
Block(-7,88,2,STAINED_GLASS:15)
Block(-7,88,3,CONCRETE:15)
Block(-7,88,8,CONCRETE:8)
Block(-7,89,2,STAINED_GLASS:15)
Block(-7,89,5,IRON_TRAPDOOR:8)
Block(-7,89,6,IRON_TRAPDOOR:8)
Block(-7,89,8,CONCRETE:8)
Block(-7,90,2,STAINED_GLASS:15)
Block(-7,90,3,CONCRETE:8)
Block(-7,90,4,CONCRETE:8)
Block(-7,90,5,CONCRETE:15)
Block(-7,90,6,CONCRETE:15)
Block(-7,90,7,CONCRETE:15)
Block(-7,90,8,CONCRETE:15)
Block(-7,91,2,STAINED_GLASS:15)
Block(-7,91,3,CARPET:0)
Block(-7,91,4,CARPET:0)
Block(-7,91,5,CARPET:0)
Block(-7,91,6,CARPET:0)
Block(-7,91,7,CARPET:0)
Block(-7,91,8,DARK_OAK_DOOR:1)
Block(-7,92,2,STAINED_GLASS:15)
Block(-7,92,3,CONCRETE:15)
Block(-7,92,8,DARK_OAK_DOOR:9)
Block(-7,93,2,STAINED_GLASS:15)
Block(-7,93,8,CONCRETE:8)
Block(-7,94,2,STAINED_GLASS:15)
Block(-7,94,8,CONCRETE:8)
Block(-7,95,2,STAINED_GLASS:15)
Block(-7,95,8,CONCRETE:8)
Block(-7,96,2,STAINED_GLASS:15)
Block(-7,96,3,CONCRETE:8)
Block(-7,96,4,CONCRETE:8)
Block(-7,96,5,CONCRETE:15)
Block(-7,96,6,CONCRETE:15)
Block(-7,96,7,CONCRETE:15)
Block(-7,96,8,CONCRETE:15)
Block(-7,97,2,STAINED_GLASS:15)
Block(-7,97,5,CONCRETE:8)
Block(-7,98,2,STAINED_GLASS:15)
Block(-7,98,5,CONCRETE:8)
Block(-7,98,7,WOOL:12)
Block(-7,99,2,STAINED_GLASS:15)
Block(-7,99,5,CONCRETE:8)
Block(-7,99,7,WOOL:12)
Block(-7,100,2,STAINED_GLASS:15)
Block(-7,100,3,CONCRETE:15)
Block(-7,100,5,CONCRETE:8)
Block(-7,100,6,QUARTZ_STAIRS:7)
Block(-7,100,7,IRON_FENCE:0)
Block(-7,101,2,STAINED_GLASS:15)
Block(-7,101,5,CONCRETE:8)
Block(-7,101,6,STEP:7)
Block(-7,101,7,STEP:7)
Block(-7,102,2,STAINED_GLASS:15)
Block(-7,102,3,CONCRETE:8)
Block(-7,102,4,CONCRETE:8)
Block(-7,102,5,CONCRETE:15)
Block(-7,102,6,CONCRETE:15)
Block(-7,102,7,CONCRETE:15)
Block(-7,102,8,CONCRETE:8)
Block(-7,103,2,STAINED_GLASS:15)
Block(-7,103,3,WOOD_STEP:13)
Block(-7,103,4,WOOD_STEP:13)
Block(-7,103,5,WOOD_STEP:13)
Block(-7,103,6,WOOD_STEP:13)
Block(-7,103,7,WOOD_STEP:13)
Block(-7,103,8,DARK_OAK_STAIRS:3)
Block(-7,104,2,STAINED_GLASS:15)
Block(-7,104,3,CONCRETE:15)
Block(-7,105,2,STAINED_GLASS:15)
Block(-7,106,2,STAINED_GLASS:15)
Block(-7,107,2,STAINED_GLASS:15)
Block(-7,108,2,STAINED_GLASS:15)
Block(-7,108,3,CONCRETE:8)
Block(-7,108,4,CONCRETE:8)
Block(-7,108,5,CONCRETE:15)
Block(-7,108,6,CONCRETE:15)
Block(-7,108,7,STAINED_GLASS:15)
Block(-7,108,8,CONCRETE:15)
Block(-7,109,2,STAINED_GLASS:15)
Block(-7,109,3,DROPPER:3,NBT/skyscraper_3x3_01/2632-dropperC16R0.nbt)
Block(-7,109,4,IRON_DOOR_BLOCK:1)
Block(-7,109,7,CONCRETE:8)
Block(-7,110,2,STAINED_GLASS:15)
Block(-7,110,3,DROPPER:3,NBT/skyscraper_3x3_01/2633-dropperC16R0.nbt)
Block(-7,110,4,IRON_DOOR_BLOCK:9)
Block(-7,110,7,IRON_FENCE:0)
Block(-7,111,2,STAINED_GLASS:15)
Block(-7,111,7,STEP:0)
Block(-7,112,2,STAINED_GLASS:15)
Block(-7,112,3,CONCRETE:15)
Block(-7,113,2,STAINED_GLASS:15)
Block(-7,114,2,STAINED_GLASS:15)
Block(-7,114,6,STAINED_GLASS_PANE:15)
Block(-7,114,7,STAINED_GLASS_PANE:15)
Block(-7,114,8,CONCRETE:8)
Block(-7,115,2,STAINED_GLASS:15)
Block(-7,115,6,STAINED_GLASS_PANE:15)
Block(-7,115,7,STAINED_GLASS_PANE:15)
Block(-7,116,2,STAINED_GLASS:15)
Block(-7,116,3,CONCRETE:15)
Block(-7,117,2,STAINED_GLASS:15)
Block(-7,118,2,STAINED_GLASS:15)
Block(-7,119,2,STAINED_GLASS:15)
Block(-7,120,2,STAINED_GLASS:15)
Block(-7,120,3,CONCRETE:8)
Block(-7,120,4,CONCRETE:8)
Block(-7,120,5,CONCRETE:15)
Block(-7,120,6,CONCRETE:15)
Block(-7,120,7,CONCRETE:15)
Block(-7,120,8,CONCRETE:8)
Block(-7,121,2,STAINED_GLASS:15)
Block(-7,121,3,STANDING_BANNER:2,NBT/skyscraper_3x3_01/2634-bannerC16R0.nbt)
Block(-7,121,5,WALL_SIGN:2,NBT/skyscraper_3x3_01/2635-signC16R0.nbt)
Block(-7,121,6,DARK_OAK_STAIRS:0)
Block(-7,121,7,WALL_SIGN:3,NBT/skyscraper_3x3_01/2636-signC16R0.nbt)
Block(-7,121,8,CONCRETE:8)
Block(-7,122,2,STAINED_GLASS:15)
Block(-7,122,3,STANDING_BANNER:2,NBT/skyscraper_3x3_01/2637-bannerC16R0.nbt)
Block(-7,122,6,WALL_BANNER:4,NBT/skyscraper_3x3_01/2638-bannerC16R0.nbt)
Block(-7,122,8,CONCRETE:8)
Block(-7,123,2,STAINED_GLASS:15)
Block(-7,123,8,CONCRETE:8)
Block(-7,124,2,STAINED_GLASS:15)
Block(-7,124,3,CONCRETE:15)
Block(-7,124,8,CONCRETE:8)
Block(-7,125,2,STAINED_GLASS:15)
Block(-7,125,3,STANDING_BANNER:2,NBT/skyscraper_3x3_01/2639-bannerC16R0.nbt)
Block(-7,125,8,CONCRETE:8)
Block(-7,126,2,STAINED_GLASS:15)
Block(-7,126,3,CONCRETE:8)
Block(-7,126,4,CONCRETE:8)
Block(-7,126,5,CONCRETE:15)
Block(-7,126,6,CONCRETE:15)
Block(-7,126,7,CONCRETE:15)
Block(-7,126,8,CONCRETE:15)
Block(-7,127,2,STAINED_GLASS:15)
Block(-7,127,8,DARK_OAK_DOOR:1)
Block(-7,128,2,STAINED_GLASS:15)
Block(-7,128,3,CONCRETE:15)
Block(-7,128,8,DARK_OAK_DOOR:8)
Block(-7,129,2,STAINED_GLASS:15)
Block(-7,129,8,CONCRETE:8)
Block(-7,130,2,STAINED_GLASS:15)
Block(-7,130,8,CONCRETE:8)
Block(-7,131,2,STAINED_GLASS:15)
Block(-7,131,8,CONCRETE:8)
Block(-7,132,2,STAINED_GLASS:15)
Block(-7,132,3,CONCRETE:8)
Block(-7,132,4,CONCRETE:8)
Block(-7,132,5,CONCRETE:15)
Block(-7,132,6,CONCRETE:15)
Block(-7,132,7,CONCRETE:15)
Block(-7,132,8,CONCRETE:15)
Block(-7,133,2,STAINED_GLASS:15)
Block(-7,133,8,DARK_OAK_DOOR:1)
Block(-7,134,2,STAINED_GLASS:15)
Block(-7,134,8,DARK_OAK_DOOR:8)
Block(-7,135,2,STAINED_GLASS:15)
Block(-7,135,8,CONCRETE:8)
Block(-7,136,2,STAINED_GLASS:15)
Block(-7,136,3,CONCRETE:15)
Block(-7,136,8,CONCRETE:8)
Block(-7,137,2,STAINED_GLASS:15)
Block(-7,137,5,IRON_TRAPDOOR:8)
Block(-7,137,6,IRON_TRAPDOOR:8)
Block(-7,137,8,CONCRETE:8)
Block(-7,138,2,STAINED_GLASS:15)
Block(-7,138,3,CONCRETE:8)
Block(-7,138,4,CONCRETE:8)
Block(-7,138,5,CONCRETE:15)
Block(-7,138,6,CONCRETE:15)
Block(-7,138,7,CONCRETE:15)
Block(-7,138,8,CONCRETE:15)
Block(-7,139,2,STAINED_GLASS:15)
Block(-7,139,3,CARPET:0)
Block(-7,139,4,CARPET:0)
Block(-7,139,5,CARPET:0)
Block(-7,139,6,CARPET:0)
Block(-7,139,7,CARPET:0)
Block(-7,139,8,DARK_OAK_DOOR:1)
Block(-7,140,2,STAINED_GLASS:15)
Block(-7,140,3,CONCRETE:15)
Block(-7,140,8,DARK_OAK_DOOR:8)
Block(-7,141,2,STAINED_GLASS:15)
Block(-7,141,8,CONCRETE:8)
Block(-7,142,2,STAINED_GLASS:15)
Block(-7,142,8,CONCRETE:8)
Block(-7,143,2,STAINED_GLASS:15)
Block(-7,143,8,CONCRETE:8)
Block(-7,144,2,STAINED_GLASS:15)
Block(-7,144,3,CONCRETE:8)
Block(-7,144,4,CONCRETE:8)
Block(-7,144,5,CONCRETE:15)
Block(-7,144,6,CONCRETE:15)
Block(-7,144,7,CONCRETE:15)
Block(-7,144,8,CONCRETE:8)
Block(-7,145,2,STAINED_GLASS:15)
Block(-7,145,3,STANDING_BANNER:2,NBT/skyscraper_3x3_01/2641-bannerC16R0.nbt)
Block(-7,145,5,WALL_SIGN:2,NBT/skyscraper_3x3_01/2642-signC16R0.nbt)
Block(-7,145,6,DARK_OAK_STAIRS:0)
Block(-7,145,7,WALL_SIGN:3,NBT/skyscraper_3x3_01/2643-signC16R0.nbt)
Block(-7,145,8,CONCRETE:8)
Block(-7,146,2,STAINED_GLASS:15)
Block(-7,146,3,STANDING_BANNER:2,NBT/skyscraper_3x3_01/2644-bannerC16R0.nbt)
Block(-7,146,6,WALL_BANNER:4,NBT/skyscraper_3x3_01/2645-bannerC16R0.nbt)
Block(-7,146,8,CONCRETE:8)
Block(-7,147,2,STAINED_GLASS:15)
Block(-7,147,8,CONCRETE:8)
Block(-7,148,2,STAINED_GLASS:15)
Block(-7,148,3,CONCRETE:15)
Block(-7,148,8,CONCRETE:8)
Block(-7,149,2,STAINED_GLASS:15)
Block(-7,149,3,STANDING_BANNER:2,NBT/skyscraper_3x3_01/2646-bannerC16R0.nbt)
Block(-7,149,8,CONCRETE:8)
Block(-7,150,2,STAINED_GLASS:15)
Block(-7,150,3,CONCRETE:8)
Block(-7,150,4,CONCRETE:8)
Block(-7,150,5,CONCRETE:15)
Block(-7,150,6,CONCRETE:15)
Block(-7,150,7,CONCRETE:15)
Block(-7,150,8,CONCRETE:15)
Block(-7,151,2,STAINED_GLASS:15)
Block(-7,151,8,DARK_OAK_DOOR:1)
Block(-7,152,2,STAINED_GLASS:15)
Block(-7,152,3,CONCRETE:15)
Block(-7,152,8,DARK_OAK_DOOR:9)
Block(-7,153,2,STAINED_GLASS:15)
Block(-7,153,8,CONCRETE:8)
Block(-7,154,2,STAINED_GLASS:15)
Block(-7,154,8,CONCRETE:8)
Block(-7,155,2,STAINED_GLASS:15)
Block(-7,155,5,IRON_TRAPDOOR:8)
Block(-7,155,6,IRON_TRAPDOOR:8)
Block(-7,155,8,CONCRETE:8)
Block(-7,156,2,STAINED_GLASS:15)
Block(-7,156,3,CONCRETE:8)
Block(-7,156,4,CONCRETE:8)
Block(-7,156,5,CONCRETE:15)
Block(-7,156,6,CONCRETE:15)
Block(-7,156,7,CONCRETE:15)
Block(-7,156,8,CONCRETE:15)
Block(-7,157,2,STAINED_GLASS:15)
Block(-7,157,3,CARPET:0)
Block(-7,157,4,CARPET:0)
Block(-7,157,5,CARPET:0)
Block(-7,157,6,CARPET:0)
Block(-7,157,7,CARPET:0)
Block(-7,157,8,DARK_OAK_DOOR:1)
Block(-7,158,2,STAINED_GLASS:15)
Block(-7,158,8,DARK_OAK_DOOR:9)
Block(-7,159,2,STAINED_GLASS:15)
Block(-7,159,8,CONCRETE:8)
Block(-7,160,2,STAINED_GLASS:15)
Block(-7,160,3,CONCRETE:15)
Block(-7,160,8,CONCRETE:8)
Block(-7,161,2,STAINED_GLASS:15)
Block(-7,161,8,CONCRETE:8)
Block(-7,162,2,STAINED_GLASS:15)
Block(-7,162,3,CONCRETE:8)
Block(-7,162,4,CONCRETE:8)
Block(-7,162,5,CONCRETE:15)
Block(-7,162,6,CONCRETE:15)
Block(-7,162,7,CONCRETE:15)
Block(-7,162,8,CONCRETE:8)
Block(-7,163,2,STAINED_GLASS:15)
Block(-7,163,3,STANDING_BANNER:2,NBT/skyscraper_3x3_01/2649-bannerC16R0.nbt)
Block(-7,163,5,WALL_SIGN:2,NBT/skyscraper_3x3_01/2650-signC16R0.nbt)
Block(-7,163,6,DARK_OAK_STAIRS:0)
Block(-7,163,7,WALL_SIGN:3,NBT/skyscraper_3x3_01/2651-signC16R0.nbt)
Block(-7,163,8,CONCRETE:8)
Block(-7,164,2,STAINED_GLASS:15)
Block(-7,164,3,CONCRETE:15)
Block(-7,164,6,WALL_BANNER:4,NBT/skyscraper_3x3_01/2652-bannerC16R0.nbt)
Block(-7,164,8,CONCRETE:8)
Block(-7,165,2,STAINED_GLASS:15)
Block(-7,165,3,STANDING_BANNER:2,NBT/skyscraper_3x3_01/2653-bannerC16R0.nbt)
Block(-7,165,8,CONCRETE:8)
Block(-7,166,2,STAINED_GLASS:15)
Block(-7,166,3,STANDING_BANNER:2,NBT/skyscraper_3x3_01/2654-bannerC16R0.nbt)
Block(-7,166,8,CONCRETE:8)
Block(-7,167,2,STAINED_GLASS:15)
Block(-7,167,3,STANDING_BANNER:2,NBT/skyscraper_3x3_01/2655-bannerC16R0.nbt)
Block(-7,167,8,CONCRETE:8)
Block(-7,168,2,STAINED_GLASS:15)
Block(-7,168,3,CONCRETE:8)
Block(-7,168,4,CONCRETE:8)
Block(-7,168,5,CONCRETE:15)
Block(-7,168,6,CONCRETE:15)
Block(-7,168,7,CONCRETE:15)
Block(-7,168,8,CONCRETE:8)
Block(-7,169,2,STAINED_GLASS:15)
Block(-7,169,8,DARK_OAK_DOOR:1)
Block(-7,170,2,STAINED_GLASS:15)
Block(-7,170,8,DARK_OAK_DOOR:9)
Block(-7,171,2,STAINED_GLASS:15)
Block(-7,171,8,CONCRETE:8)
Block(-7,172,2,STAINED_GLASS:15)
Block(-7,172,3,CONCRETE:15)
Block(-7,172,8,CONCRETE:8)
Block(-7,173,2,STAINED_GLASS:15)
Block(-7,173,8,CONCRETE:8)
Block(-7,174,2,STAINED_GLASS:15)
Block(-7,174,3,CONCRETE:8)
Block(-7,174,4,CONCRETE:8)
Block(-7,174,5,CONCRETE:15)
Block(-7,174,6,CONCRETE:15)
Block(-7,174,7,CONCRETE:15)
Block(-7,174,8,CONCRETE:15)
Block(-7,175,2,STAINED_GLASS:15)
Block(-7,175,8,DARK_OAK_DOOR:1)
Block(-7,176,2,STAINED_GLASS:15)
Block(-7,176,3,CONCRETE:15)
Block(-7,176,8,DARK_OAK_DOOR:9)
Block(-7,177,2,STAINED_GLASS:15)
Block(-7,177,8,CONCRETE:8)
Block(-7,178,2,STAINED_GLASS:15)
Block(-7,178,8,CONCRETE:8)
Block(-7,179,2,STAINED_GLASS:15)
Block(-7,179,8,CONCRETE:8)
Block(-7,180,2,STAINED_GLASS:15)
Block(-7,180,3,CONCRETE:8)
Block(-7,180,4,CONCRETE:8)
Block(-7,180,5,CONCRETE:15)
Block(-7,180,6,CONCRETE:15)
Block(-7,180,7,CONCRETE:15)
Block(-7,180,8,CONCRETE:15)
Block(-7,181,2,STAINED_GLASS:15)
Block(-7,181,8,DARK_OAK_DOOR:1)
Block(-7,182,2,STAINED_GLASS:15)
Block(-7,182,8,DARK_OAK_DOOR:9)
Block(-7,183,2,STAINED_GLASS:15)
Block(-7,183,8,CONCRETE:8)
Block(-7,184,2,STAINED_GLASS:15)
Block(-7,184,3,CONCRETE:15)
Block(-7,184,8,CONCRETE:8)
Block(-7,185,2,STAINED_GLASS:15)
Block(-7,185,5,IRON_TRAPDOOR:8)
Block(-7,185,6,IRON_TRAPDOOR:8)
Block(-7,185,8,CONCRETE:8)
Block(-7,186,2,STAINED_GLASS:15)
Block(-7,186,3,CONCRETE:8)
Block(-7,186,4,CONCRETE:8)
Block(-7,186,5,CONCRETE:15)
Block(-7,186,6,CONCRETE:15)
Block(-7,186,7,CONCRETE:15)
Block(-7,186,8,CONCRETE:15)
Block(-7,187,2,STAINED_GLASS:15)
Block(-7,187,3,CARPET:0)
Block(-7,187,4,CARPET:0)
Block(-7,187,5,CARPET:0)
Block(-7,187,6,CARPET:0)
Block(-7,187,7,CARPET:0)
Block(-7,187,8,DARK_OAK_DOOR:1)
Block(-7,188,2,STAINED_GLASS:15)
Block(-7,188,3,CONCRETE:15)
Block(-7,188,8,DARK_OAK_DOOR:9)
Block(-7,189,2,STAINED_GLASS:15)
Block(-7,189,8,CONCRETE:8)
Block(-7,190,2,STAINED_GLASS:15)
Block(-7,190,8,CONCRETE:8)
Block(-7,191,2,STAINED_GLASS:15)
Block(-7,191,8,CONCRETE:8)
Block(-7,192,2,STAINED_GLASS:15)
Block(-7,192,3,CONCRETE:8)
Block(-7,192,4,CONCRETE:8)
Block(-7,192,5,CONCRETE:8)
Block(-7,192,6,CONCRETE:8)
Block(-7,192,7,CONCRETE:8)
Block(-7,192,8,CONCRETE:8)
Block(-7,193,2,STAINED_GLASS:15)
Block(-7,193,6,BOOKSHELF:0)
Block(-7,193,7,STANDING_BANNER:15,NBT/skyscraper_3x3_01/2662-bannerC16R0.nbt)
Block(-7,193,8,WALL_SIGN:4,NBT/skyscraper_3x3_01/2663-signC16R0.nbt)
Block(-7,194,2,STAINED_GLASS:15)
Block(-7,194,6,BOOKSHELF:0)
Block(-7,194,7,IRON_TRAPDOOR:1)
Block(-7,195,2,STAINED_GLASS:15)
Block(-7,195,6,BOOKSHELF:0)
Block(-7,196,2,STAINED_GLASS:15)
Block(-7,196,3,CONCRETE:15)
Block(-7,196,6,WOOD_STEP:5)
Block(-7,197,2,STAINED_GLASS:15)
Block(-7,198,2,STAINED_GLASS:15)
Block(-7,198,3,CONCRETE:8)
Block(-7,198,4,CONCRETE:8)
Block(-7,198,5,CONCRETE:8)
Block(-7,198,6,CONCRETE:8)
Block(-7,198,7,CONCRETE:8)
Block(-7,198,8,CONCRETE:8)
Block(-7,199,2,STAINED_GLASS:15)
Block(-7,199,3,CONCRETE:8)
Block(-7,199,4,CONCRETE:8)
Block(-7,199,5,CONCRETE:8)
Block(-7,199,6,CONCRETE:8)
Block(-7,199,7,CONCRETE:8)
Block(-7,199,8,CONCRETE:8)
Block(-7,200,2,STAINED_GLASS_PANE:15)
Block(-7,200,3,STAINED_GLASS_PANE:15)
Block(-7,200,6,DAYLIGHT_DETECTOR_INVERTED:1,NBT/skyscraper_3x3_01/2666-daylight_detectorC16R0.nbt)
Block(-7,200,8,IRON_TRAPDOOR:0)
Block(-7,201,2,STAINED_GLASS_PANE:15)
Block(-7,201,3,STAINED_GLASS_PANE:15)
Block(-6,0,-7,CONCRETE:7)
Block(-6,0,-6,CONCRETE:7)
Block(-6,0,-5,CONCRETE:7)
Block(-6,0,-4,CONCRETE:7)
Block(-6,0,-3,CONCRETE:7)
Block(-6,0,-2,CONCRETE:7)
Block(-6,0,-1,CONCRETE:7)
Block(-6,0,0,CONCRETE:7)
Block(-6,0,1,CONCRETE:7)
Block(-6,0,2,CONCRETE:7)
Block(-6,0,3,CONCRETE:7)
Block(-6,0,4,CONCRETE:7)
Block(-6,0,5,CONCRETE:7)
Block(-6,0,6,CONCRETE:7)
Block(-6,0,7,CONCRETE:7)
Block(-6,0,8,CONCRETE:7)
Block(-6,1,-7,CONCRETE:7)
Block(-6,1,-6,CONCRETE:7)
Block(-6,1,-5,CONCRETE:7)
Block(-6,1,-4,CONCRETE:7)
Block(-6,1,-3,CONCRETE:7)
Block(-6,1,-2,CONCRETE:7)
Block(-6,1,-1,CONCRETE:7)
Block(-6,1,0,CONCRETE:7)
Block(-6,1,1,CONCRETE:7)
Block(-6,1,2,CONCRETE:7)
Block(-6,1,3,CONCRETE:7)
Block(-6,1,4,CONCRETE:7)
Block(-6,1,5,CONCRETE:7)
Block(-6,1,6,CONCRETE:7)
Block(-6,1,7,CONCRETE:7)
Block(-6,1,8,CONCRETE:7)
Block(-6,2,-7,SMOOTH_STAIRS:1)
Block(-6,2,-6,SMOOTH_STAIRS:1)
Block(-6,2,-5,SMOOTH_STAIRS:1)
Block(-6,2,-4,SMOOTH_STAIRS:1)
Block(-6,2,-3,SMOOTH_STAIRS:1)
Block(-6,2,-2,SMOOTH_STAIRS:1)
Block(-6,2,-1,SMOOTH_STAIRS:1)
Block(-6,2,0,SMOOTH_STAIRS:1)
Block(-6,2,1,SMOOTH_STAIRS:1)
Block(-6,2,2,SMOOTH_STAIRS:1)
Block(-6,2,3,SMOOTH_STAIRS:1)
Block(-6,2,4,SMOOTH_STAIRS:1)
Block(-6,2,5,SMOOTH_STAIRS:1)
Block(-6,2,6,SMOOTH_STAIRS:1)
Block(-6,2,7,SMOOTH_STAIRS:1)
Block(-6,2,8,SMOOTH_STAIRS:1)
Block(-6,3,-7,AIR:0)
Block(-6,3,-6,AIR:0)
Block(-6,3,-5,AIR:0)
Block(-6,3,-4,AIR:0)
Block(-6,3,-3,AIR:0)
Block(-6,3,-2,AIR:0)
Block(-6,3,-1,AIR:0)
Block(-6,3,0,AIR:0)
Block(-6,3,1,AIR:0)
Block(-6,3,2,AIR:0)
Block(-6,3,3,AIR:0)
Block(-6,3,4,AIR:0)
Block(-6,3,5,AIR:0)
Block(-6,3,6,AIR:0)
Block(-6,3,7,AIR:0)
Block(-6,3,8,AIR:0)
Block(-6,4,-7,AIR:0)
Block(-6,4,-6,AIR:0)
Block(-6,4,-5,AIR:0)
Block(-6,4,-4,AIR:0)
Block(-6,4,-3,AIR:0)
Block(-6,4,-2,AIR:0)
Block(-6,4,-1,AIR:0)
Block(-6,4,0,AIR:0)
Block(-6,4,1,AIR:0)
Block(-6,4,2,AIR:0)
Block(-6,4,3,AIR:0)
Block(-6,4,4,AIR:0)
Block(-6,4,5,AIR:0)
Block(-6,4,6,AIR:0)
Block(-6,4,7,AIR:0)
Block(-6,4,8,AIR:0)
Block(-6,5,-7,AIR:0)
Block(-6,5,-6,AIR:0)
Block(-6,5,-5,AIR:0)
Block(-6,5,-4,AIR:0)
Block(-6,5,-3,AIR:0)
Block(-6,5,-2,AIR:0)
Block(-6,5,-1,AIR:0)
Block(-6,5,0,AIR:0)
Block(-6,5,1,AIR:0)
Block(-6,5,2,AIR:0)
Block(-6,5,3,AIR:0)
Block(-6,5,4,AIR:0)
Block(-6,5,5,AIR:0)
Block(-6,5,6,AIR:0)
Block(-6,5,7,AIR:0)
Block(-6,5,8,AIR:0)
Block(-6,6,-7,CONCRETE:7)
Block(-6,6,-6,CONCRETE:7)
Block(-6,6,-5,STEP:8)
Block(-6,6,-4,STEP:8)
Block(-6,6,-3,CONCRETE:7)
Block(-6,6,-2,STEP:8)
Block(-6,6,-1,STEP:8)
Block(-6,6,0,CONCRETE:7)
Block(-6,6,1,STEP:8)
Block(-6,6,2,STEP:8)
Block(-6,6,3,CONCRETE:7)
Block(-6,6,4,STEP:8)
Block(-6,6,5,STEP:8)
Block(-6,6,6,CONCRETE:7)
Block(-6,6,7,STEP:8)
Block(-6,6,8,STEP:8)
Block(-6,7,-7,CONCRETE:7)
Block(-6,7,-6,CONCRETE:7)
Block(-6,7,-5,CONCRETE:7)
Block(-6,7,-4,CONCRETE:7)
Block(-6,7,-3,CONCRETE:7)
Block(-6,7,-2,CONCRETE:7)
Block(-6,7,-1,CONCRETE:7)
Block(-6,7,0,CONCRETE:7)
Block(-6,7,1,CONCRETE:7)
Block(-6,7,2,CONCRETE:7)
Block(-6,7,3,CONCRETE:7)
Block(-6,7,4,CONCRETE:7)
Block(-6,7,5,CONCRETE:7)
Block(-6,7,6,CONCRETE:7)
Block(-6,7,7,CONCRETE:7)
Block(-6,7,8,CONCRETE:7)
Block(-6,8,-7,CONCRETE:7)
Block(-6,8,-6,CONCRETE:7)
Block(-6,8,-5,CONCRETE:7)
Block(-6,8,-4,CONCRETE:7)
Block(-6,8,-3,CONCRETE:7)
Block(-6,8,-2,CONCRETE:7)
Block(-6,8,-1,CONCRETE:7)
Block(-6,8,0,CONCRETE:7)
Block(-6,8,1,CONCRETE:7)
Block(-6,8,2,CONCRETE:7)
Block(-6,8,3,CONCRETE:7)
Block(-6,8,4,CONCRETE:7)
Block(-6,8,5,CONCRETE:7)
Block(-6,8,6,CONCRETE:7)
Block(-6,8,7,CONCRETE:7)
Block(-6,8,8,CONCRETE:7)
Block(-6,9,-7,CONCRETE:7)
Block(-6,9,-6,CONCRETE:8)
Block(-6,9,-5,CONCRETE:8)
Block(-6,9,-4,CONCRETE:15)
Block(-6,9,-3,CONCRETE:15)
Block(-6,9,-2,CONCRETE:8)
Block(-6,9,-1,CONCRETE:8)
Block(-6,9,0,CONCRETE:8)
Block(-6,9,1,CONCRETE:8)
Block(-6,9,2,CONCRETE:8)
Block(-6,9,3,CONCRETE:8)
Block(-6,9,4,CONCRETE:8)
Block(-6,9,5,CONCRETE:7)
Block(-6,9,6,CONCRETE:7)
Block(-6,9,7,CONCRETE:7)
Block(-6,9,8,CONCRETE:7)
Block(-6,10,-7,CONCRETE:7)
Block(-6,10,-6,CONCRETE:8)
Block(-6,10,-5,STAINED_GLASS:15)
Block(-6,10,-4,CONCRETE:15)
Block(-6,10,-3,CONCRETE:15)
Block(-6,10,-2,STAINED_GLASS:15)
Block(-6,10,-1,CONCRETE:8)
Block(-6,10,0,CONCRETE:8)
Block(-6,10,1,STAINED_GLASS:15)
Block(-6,10,2,STAINED_GLASS:15)
Block(-6,10,3,STAINED_GLASS:15)
Block(-6,10,4,CONCRETE:8)
Block(-6,10,5,CONCRETE:7)
Block(-6,10,6,CONCRETE:7)
Block(-6,10,7,CONCRETE:7)
Block(-6,10,8,CONCRETE:7)
Block(-6,11,-7,CONCRETE:7)
Block(-6,11,-6,CONCRETE:8)
Block(-6,11,-5,STATIONARY_WATER:0)
Block(-6,11,-4,STATIONARY_WATER:0)
Block(-6,11,-3,STATIONARY_WATER:0)
Block(-6,11,-2,STATIONARY_WATER:0)
Block(-6,11,-1,CONCRETE:8)
Block(-6,11,0,CONCRETE:8)
Block(-6,11,1,STATIONARY_WATER:0)
Block(-6,11,2,STATIONARY_WATER:0)
Block(-6,11,3,STAINED_GLASS:15)
Block(-6,11,4,CONCRETE:8)
Block(-6,11,5,CONCRETE:7)
Block(-6,11,6,CONCRETE:7)
Block(-6,11,7,CONCRETE:7)
Block(-6,11,8,CONCRETE:7)
Block(-6,12,-7,CONCRETE:7)
Block(-6,12,-6,STATIONARY_WATER:0)
Block(-6,12,-5,STATIONARY_WATER:0)
Block(-6,12,-4,STATIONARY_WATER:0)
Block(-6,12,-3,STATIONARY_WATER:0)
Block(-6,12,-2,STATIONARY_WATER:0)
Block(-6,12,-1,STATIONARY_WATER:0)
Block(-6,12,0,STATIONARY_WATER:0)
Block(-6,12,1,STATIONARY_WATER:0)
Block(-6,12,2,STATIONARY_WATER:0)
Block(-6,12,3,STAINED_GLASS:15)
Block(-6,12,4,CONCRETE:8)
Block(-6,12,5,CONCRETE:7)
Block(-6,12,6,CONCRETE:7)
Block(-6,12,7,CONCRETE:7)
Block(-6,12,8,CONCRETE:7)
Block(-6,13,-7,CONCRETE:7)
Block(-6,13,-6,AIR:0)
Block(-6,13,-5,AIR:0)
Block(-6,13,-4,AIR:0)
Block(-6,13,-3,AIR:0)
Block(-6,13,-2,AIR:0)
Block(-6,13,-1,AIR:0)
Block(-6,13,0,AIR:0)
Block(-6,13,1,AIR:0)
Block(-6,13,2,AIR:0)
Block(-6,13,3,STAINED_GLASS:15)
Block(-6,13,4,CONCRETE:8)
Block(-6,13,5,CONCRETE:7)
Block(-6,13,6,CONCRETE:7)
Block(-6,13,7,CONCRETE:7)
Block(-6,13,8,CONCRETE:15)
Block(-6,14,-7,CONCRETE:7)
Block(-6,14,-6,AIR:0)
Block(-6,14,-5,AIR:0)
Block(-6,14,-4,AIR:0)
Block(-6,14,-3,AIR:0)
Block(-6,14,-2,AIR:0)
Block(-6,14,-1,AIR:0)
Block(-6,14,0,AIR:0)
Block(-6,14,1,AIR:0)
Block(-6,14,2,AIR:0)
Block(-6,14,3,STAINED_GLASS:15)
Block(-6,14,4,CONCRETE:8)
Block(-6,14,5,CONCRETE:7)
Block(-6,14,6,CONCRETE:7)
Block(-6,14,7,CONCRETE:7)
Block(-6,14,8,CONCRETE:15)
Block(-6,15,-7,CONCRETE:7)
Block(-6,15,-6,AIR:0)
Block(-6,15,-5,AIR:0)
Block(-6,15,-4,AIR:0)
Block(-6,15,-3,AIR:0)
Block(-6,15,-2,AIR:0)
Block(-6,15,-1,AIR:0)
Block(-6,15,0,AIR:0)
Block(-6,15,1,AIR:0)
Block(-6,15,2,AIR:0)
Block(-6,15,3,STAINED_GLASS:15)
Block(-6,15,4,CONCRETE:8)
Block(-6,15,5,CONCRETE:7)
Block(-6,15,6,CONCRETE:7)
Block(-6,15,7,CONCRETE:7)
Block(-6,15,8,CONCRETE:15)
Block(-6,16,-7,CONCRETE:7)
Block(-6,16,-6,AIR:0)
Block(-6,16,-5,AIR:0)
Block(-6,16,-4,AIR:0)
Block(-6,16,-3,AIR:0)
Block(-6,16,-2,AIR:0)
Block(-6,16,-1,AIR:0)
Block(-6,16,0,AIR:0)
Block(-6,16,1,AIR:0)
Block(-6,16,2,AIR:0)
Block(-6,16,3,STAINED_GLASS:15)
Block(-6,16,4,CONCRETE:8)
Block(-6,16,5,CONCRETE:7)
Block(-6,16,6,CONCRETE:7)
Block(-6,16,7,CONCRETE:7)
Block(-6,16,8,CONCRETE:15)
Block(-6,17,-7,CONCRETE:7)
Block(-6,17,-6,AIR:0)
Block(-6,17,-5,AIR:0)
Block(-6,17,-4,AIR:0)
Block(-6,17,-3,AIR:0)
Block(-6,17,-2,AIR:0)
Block(-6,17,-1,AIR:0)
Block(-6,17,0,AIR:0)
Block(-6,17,1,AIR:0)
Block(-6,17,2,AIR:0)
Block(-6,17,3,STAINED_GLASS:15)
Block(-6,17,4,CONCRETE:8)
Block(-6,17,5,CONCRETE:7)
Block(-6,17,6,CONCRETE:7)
Block(-6,17,7,CONCRETE:7)
Block(-6,17,8,CONCRETE:7)
Block(-6,18,-7,STAINED_GLASS_PANE:15)
Block(-6,18,3,STAINED_GLASS:15)
Block(-6,18,4,CONCRETE:8)
Block(-6,18,5,CONCRETE:8)
Block(-6,18,6,CONCRETE:15)
Block(-6,18,7,CONCRETE:15)
Block(-6,18,8,CONCRETE:15)
Block(-6,19,3,STAINED_GLASS:15)
Block(-6,20,3,STAINED_GLASS:15)
Block(-6,21,3,STAINED_GLASS:15)
Block(-6,21,4,CONCRETE:15)
Block(-6,22,3,STAINED_GLASS:15)
Block(-6,23,3,STAINED_GLASS:15)
Block(-6,24,3,STAINED_GLASS:15)
Block(-6,24,4,CONCRETE:8)
Block(-6,24,5,CONCRETE:8)
Block(-6,24,6,CONCRETE:15)
Block(-6,24,7,CONCRETE:15)
Block(-6,24,8,CONCRETE:15)
Block(-6,25,3,STAINED_GLASS:15)
Block(-6,25,6,STAINED_GLASS_PANE:15)
Block(-6,25,7,STAINED_GLASS_PANE:15)
Block(-6,25,8,STAINED_GLASS_PANE:15)
Block(-6,26,3,STAINED_GLASS:15)
Block(-6,27,3,STAINED_GLASS:15)
Block(-6,27,4,CONCRETE:15)
Block(-6,28,3,STAINED_GLASS:15)
Block(-6,29,3,STAINED_GLASS:15)
Block(-6,30,3,STAINED_GLASS:15)
Block(-6,30,4,CONCRETE:8)
Block(-6,30,5,CONCRETE:8)
Block(-6,30,6,CONCRETE:15)
Block(-6,30,7,CONCRETE:15)
Block(-6,30,8,CONCRETE:15)
Block(-6,31,3,STAINED_GLASS:15)
Block(-6,31,8,DARK_OAK_DOOR:1)
Block(-6,32,3,STAINED_GLASS:15)
Block(-6,32,8,DARK_OAK_DOOR:8)
Block(-6,33,3,STAINED_GLASS:15)
Block(-6,33,4,CONCRETE:15)
Block(-6,33,8,CONCRETE:8)
Block(-6,34,3,STAINED_GLASS:15)
Block(-6,34,8,CONCRETE:8)
Block(-6,35,3,STAINED_GLASS:15)
Block(-6,35,8,CONCRETE:8)
Block(-6,36,3,STAINED_GLASS:15)
Block(-6,36,4,CONCRETE:8)
Block(-6,36,5,CONCRETE:8)
Block(-6,36,6,CONCRETE:15)
Block(-6,36,7,CONCRETE:15)
Block(-6,36,8,CONCRETE:15)
Block(-6,37,3,STAINED_GLASS:15)
Block(-6,37,8,DARK_OAK_DOOR:1)
Block(-6,38,3,STAINED_GLASS:15)
Block(-6,38,8,DARK_OAK_DOOR:8)
Block(-6,39,3,STAINED_GLASS:15)
Block(-6,39,4,CONCRETE:15)
Block(-6,39,8,CONCRETE:8)
Block(-6,40,3,STAINED_GLASS:15)
Block(-6,40,8,CONCRETE:8)
Block(-6,41,3,STAINED_GLASS:15)
Block(-6,41,5,IRON_TRAPDOOR:10)
Block(-6,41,6,IRON_TRAPDOOR:8)
Block(-6,41,8,CONCRETE:8)
Block(-6,42,3,STAINED_GLASS:15)
Block(-6,42,4,CONCRETE:8)
Block(-6,42,5,CONCRETE:8)
Block(-6,42,6,CONCRETE:15)
Block(-6,42,7,CONCRETE:15)
Block(-6,42,8,CONCRETE:15)
Block(-6,43,3,STAINED_GLASS:15)
Block(-6,43,4,CARPET:0)
Block(-6,43,5,CARPET:0)
Block(-6,43,6,CARPET:0)
Block(-6,43,7,CARPET:0)
Block(-6,43,8,DARK_OAK_DOOR:1)
Block(-6,44,3,STAINED_GLASS:15)
Block(-6,44,8,DARK_OAK_DOOR:8)
Block(-6,45,3,STAINED_GLASS:15)
Block(-6,45,4,CONCRETE:15)
Block(-6,45,8,CONCRETE:8)
Block(-6,46,3,STAINED_GLASS:15)
Block(-6,46,8,CONCRETE:8)
Block(-6,47,3,STAINED_GLASS:15)
Block(-6,47,8,CONCRETE:8)
Block(-6,48,3,STAINED_GLASS:15)
Block(-6,48,4,CONCRETE:8)
Block(-6,48,5,CONCRETE:8)
Block(-6,48,6,CONCRETE:15)
Block(-6,48,7,CONCRETE:15)
Block(-6,48,8,CONCRETE:8)
Block(-6,49,3,STAINED_GLASS:15)
Block(-6,49,4,STANDING_BANNER:2,NBT/skyscraper_3x3_01/2669-bannerC16R0.nbt)
Block(-6,49,6,TRAP_DOOR:7)
Block(-6,49,8,DARK_OAK_DOOR:1)
Block(-6,50,3,STAINED_GLASS:15)
Block(-6,50,4,STANDING_BANNER:2,NBT/skyscraper_3x3_01/2670-bannerC16R0.nbt)
Block(-6,50,6,TRAP_DOOR:7)
Block(-6,50,8,DARK_OAK_DOOR:8)
Block(-6,51,3,STAINED_GLASS:15)
Block(-6,51,4,CONCRETE:15)
Block(-6,51,8,CONCRETE:8)
Block(-6,52,3,STAINED_GLASS:15)
Block(-6,52,4,STANDING_BANNER:2,NBT/skyscraper_3x3_01/2671-bannerC16R0.nbt)
Block(-6,52,8,CONCRETE:8)
Block(-6,53,3,STAINED_GLASS:15)
Block(-6,53,4,STANDING_BANNER:2,NBT/skyscraper_3x3_01/2672-bannerC16R0.nbt)
Block(-6,53,8,CONCRETE:8)
Block(-6,54,3,STAINED_GLASS:15)
Block(-6,54,4,CONCRETE:8)
Block(-6,54,5,CONCRETE:8)
Block(-6,54,6,CONCRETE:15)
Block(-6,54,7,CONCRETE:15)
Block(-6,54,8,CONCRETE:8)
Block(-6,55,3,STAINED_GLASS:15)
Block(-6,55,8,DARK_OAK_DOOR:1)
Block(-6,56,3,STAINED_GLASS:15)
Block(-6,56,8,DARK_OAK_DOOR:8)
Block(-6,57,3,STAINED_GLASS:15)
Block(-6,57,4,CONCRETE:15)
Block(-6,57,8,CONCRETE:8)
Block(-6,58,3,STAINED_GLASS:15)
Block(-6,58,8,CONCRETE:8)
Block(-6,59,3,STAINED_GLASS:15)
Block(-6,59,8,CONCRETE:8)
Block(-6,60,3,STAINED_GLASS:15)
Block(-6,60,4,CONCRETE:8)
Block(-6,60,5,CONCRETE:8)
Block(-6,60,6,CONCRETE:15)
Block(-6,60,7,CONCRETE:15)
Block(-6,60,8,CONCRETE:15)
Block(-6,61,3,STAINED_GLASS:15)
Block(-6,61,4,CARPET:0)
Block(-6,61,5,CARPET:0)
Block(-6,61,6,CARPET:0)
Block(-6,61,7,CARPET:0)
Block(-6,61,8,DARK_OAK_DOOR:1)
Block(-6,62,3,STAINED_GLASS:15)
Block(-6,62,8,DARK_OAK_DOOR:8)
Block(-6,63,3,STAINED_GLASS:15)
Block(-6,63,4,CONCRETE:15)
Block(-6,63,8,CONCRETE:8)
Block(-6,64,3,STAINED_GLASS:15)
Block(-6,64,8,CONCRETE:8)
Block(-6,65,3,STAINED_GLASS:15)
Block(-6,65,8,CONCRETE:8)
Block(-6,66,3,STAINED_GLASS:15)
Block(-6,66,4,CONCRETE:8)
Block(-6,66,5,CONCRETE:8)
Block(-6,66,6,CONCRETE:15)
Block(-6,66,7,CONCRETE:15)
Block(-6,66,8,CONCRETE:8)
Block(-6,67,3,STAINED_GLASS:15)
Block(-6,67,4,STANDING_BANNER:2,NBT/skyscraper_3x3_01/2673-bannerC16R0.nbt)
Block(-6,67,6,TRAP_DOOR:7)
Block(-6,67,8,DARK_OAK_DOOR:1)
Block(-6,68,3,STAINED_GLASS:15)
Block(-6,68,4,STANDING_BANNER:2,NBT/skyscraper_3x3_01/2674-bannerC16R0.nbt)
Block(-6,68,6,TRAP_DOOR:7)
Block(-6,68,8,DARK_OAK_DOOR:8)
Block(-6,69,3,STAINED_GLASS:15)
Block(-6,69,4,CONCRETE:15)
Block(-6,69,8,CONCRETE:8)
Block(-6,70,3,STAINED_GLASS:15)
Block(-6,70,4,STANDING_BANNER:2,NBT/skyscraper_3x3_01/2675-bannerC16R0.nbt)
Block(-6,70,8,CONCRETE:8)
Block(-6,71,3,STAINED_GLASS:15)
Block(-6,71,4,STANDING_BANNER:2,NBT/skyscraper_3x3_01/2676-bannerC16R0.nbt)
Block(-6,71,8,CONCRETE:8)
Block(-6,72,3,STAINED_GLASS:15)
Block(-6,72,4,CONCRETE:8)
Block(-6,72,5,CONCRETE:8)
Block(-6,72,6,CONCRETE:15)
Block(-6,72,7,CONCRETE:15)
Block(-6,72,8,CONCRETE:8)
Block(-6,73,3,STAINED_GLASS:15)
Block(-6,73,8,DARK_OAK_DOOR:1)
Block(-6,74,3,STAINED_GLASS:15)
Block(-6,74,8,DARK_OAK_DOOR:8)
Block(-6,75,3,STAINED_GLASS:15)
Block(-6,75,4,CONCRETE:15)
Block(-6,75,8,CONCRETE:8)
Block(-6,76,3,STAINED_GLASS:15)
Block(-6,76,8,CONCRETE:8)
Block(-6,77,3,STAINED_GLASS:15)
Block(-6,77,8,CONCRETE:8)
Block(-6,78,3,STAINED_GLASS:15)
Block(-6,78,4,CONCRETE:8)
Block(-6,78,5,CONCRETE:8)
Block(-6,78,6,CONCRETE:15)
Block(-6,78,7,CONCRETE:15)
Block(-6,78,8,CONCRETE:15)
Block(-6,79,3,STAINED_GLASS:15)
Block(-6,79,8,DARK_OAK_DOOR:1)
Block(-6,80,3,STAINED_GLASS:15)
Block(-6,80,8,DARK_OAK_DOOR:8)
Block(-6,81,3,STAINED_GLASS:15)
Block(-6,81,4,CONCRETE:15)
Block(-6,81,8,CONCRETE:8)
Block(-6,82,3,STAINED_GLASS:15)
Block(-6,82,8,CONCRETE:8)
Block(-6,83,3,STAINED_GLASS:15)
Block(-6,83,8,CONCRETE:8)
Block(-6,84,3,STAINED_GLASS:15)
Block(-6,84,4,CONCRETE:8)
Block(-6,84,5,CONCRETE:8)
Block(-6,84,6,CONCRETE:15)
Block(-6,84,7,CONCRETE:15)
Block(-6,84,8,CONCRETE:15)
Block(-6,85,3,STAINED_GLASS:15)
Block(-6,85,8,DARK_OAK_DOOR:1)
Block(-6,86,3,STAINED_GLASS:15)
Block(-6,86,8,DARK_OAK_DOOR:8)
Block(-6,87,3,STAINED_GLASS:15)
Block(-6,87,4,CONCRETE:15)
Block(-6,87,8,CONCRETE:8)
Block(-6,88,3,STAINED_GLASS:15)
Block(-6,88,8,CONCRETE:8)
Block(-6,89,3,STAINED_GLASS:15)
Block(-6,89,5,IRON_TRAPDOOR:10)
Block(-6,89,6,IRON_TRAPDOOR:8)
Block(-6,89,8,CONCRETE:8)
Block(-6,90,3,STAINED_GLASS:15)
Block(-6,90,4,CONCRETE:8)
Block(-6,90,5,CONCRETE:8)
Block(-6,90,6,CONCRETE:15)
Block(-6,90,7,CONCRETE:15)
Block(-6,90,8,CONCRETE:15)
Block(-6,91,3,STAINED_GLASS:15)
Block(-6,91,4,CARPET:0)
Block(-6,91,5,CARPET:0)
Block(-6,91,6,CARPET:0)
Block(-6,91,7,CARPET:0)
Block(-6,91,8,DARK_OAK_DOOR:1)
Block(-6,92,3,STAINED_GLASS:15)
Block(-6,92,8,DARK_OAK_DOOR:8)
Block(-6,93,3,STAINED_GLASS:15)
Block(-6,93,4,CONCRETE:15)
Block(-6,93,8,CONCRETE:8)
Block(-6,94,3,STAINED_GLASS:15)
Block(-6,94,8,CONCRETE:8)
Block(-6,95,3,STAINED_GLASS:15)
Block(-6,95,8,CONCRETE:8)
Block(-6,96,3,STAINED_GLASS:15)
Block(-6,96,4,CONCRETE:8)
Block(-6,96,5,CONCRETE:8)
Block(-6,96,6,CONCRETE:15)
Block(-6,96,7,CONCRETE:15)
Block(-6,96,8,CONCRETE:15)
Block(-6,97,3,STAINED_GLASS:15)
Block(-6,98,3,STAINED_GLASS:15)
Block(-6,99,3,STAINED_GLASS:15)
Block(-6,99,4,CONCRETE:15)
Block(-6,100,3,STAINED_GLASS:15)
Block(-6,101,3,STAINED_GLASS:15)
Block(-6,102,3,STAINED_GLASS:15)
Block(-6,102,4,CONCRETE:8)
Block(-6,102,5,CONCRETE:8)
Block(-6,102,6,CONCRETE:15)
Block(-6,102,7,CONCRETE:15)
Block(-6,102,8,CONCRETE:8)
Block(-6,103,3,STAINED_GLASS:15)
Block(-6,103,4,WOOD_STEP:13)
Block(-6,103,5,WOOD_STEP:13)
Block(-6,103,6,WOOD_STEP:13)
Block(-6,103,7,WOOD_STEP:13)
Block(-6,103,8,DARK_OAK_STAIRS:3)
Block(-6,104,3,STAINED_GLASS:15)
Block(-6,105,3,STAINED_GLASS:15)
Block(-6,105,4,CONCRETE:15)
Block(-6,106,3,STAINED_GLASS:15)
Block(-6,107,3,STAINED_GLASS:15)
Block(-6,108,3,STAINED_GLASS:15)
Block(-6,108,4,CONCRETE:8)
Block(-6,108,5,CONCRETE:8)
Block(-6,108,6,CONCRETE:15)
Block(-6,108,7,CONCRETE:15)
Block(-6,108,8,CONCRETE:15)
Block(-6,109,3,STAINED_GLASS:15)
Block(-6,109,7,DARK_OAK_STAIRS:7)
Block(-6,110,3,STAINED_GLASS:15)
Block(-6,111,3,STAINED_GLASS:15)
Block(-6,111,4,CONCRETE:15)
Block(-6,111,7,STEP:0)
Block(-6,112,3,STAINED_GLASS:15)
Block(-6,113,3,STAINED_GLASS:15)
Block(-6,114,3,STAINED_GLASS:15)
Block(-6,114,5,STAINED_GLASS_PANE:15)
Block(-6,114,6,STAINED_GLASS_PANE:15)
Block(-6,114,7,CONCRETE:8)
Block(-6,114,8,CONCRETE:8)
Block(-6,115,3,STAINED_GLASS:15)
Block(-6,115,5,STAINED_GLASS_PANE:15)
Block(-6,115,6,STAINED_GLASS_PANE:15)
Block(-6,116,3,STAINED_GLASS:15)
Block(-6,117,3,STAINED_GLASS:15)
Block(-6,117,4,CONCRETE:15)
Block(-6,118,3,STAINED_GLASS:15)
Block(-6,119,3,STAINED_GLASS:15)
Block(-6,120,3,STAINED_GLASS:15)
Block(-6,120,4,CONCRETE:8)
Block(-6,120,5,CONCRETE:8)
Block(-6,120,6,CONCRETE:15)
Block(-6,120,7,CONCRETE:15)
Block(-6,120,8,CONCRETE:8)
Block(-6,121,3,STAINED_GLASS:15)
Block(-6,121,4,STANDING_BANNER:2,NBT/skyscraper_3x3_01/2681-bannerC16R0.nbt)
Block(-6,121,6,TRAP_DOOR:7)
Block(-6,121,8,DARK_OAK_DOOR:1)
Block(-6,122,3,STAINED_GLASS:15)
Block(-6,122,4,STANDING_BANNER:2,NBT/skyscraper_3x3_01/2682-bannerC16R0.nbt)
Block(-6,122,6,TRAP_DOOR:7)
Block(-6,122,8,DARK_OAK_DOOR:11)
Block(-6,123,3,STAINED_GLASS:15)
Block(-6,123,4,CONCRETE:15)
Block(-6,123,8,CONCRETE:8)
Block(-6,124,3,STAINED_GLASS:15)
Block(-6,124,4,STANDING_BANNER:2,NBT/skyscraper_3x3_01/2683-bannerC16R0.nbt)
Block(-6,124,8,CONCRETE:8)
Block(-6,125,3,STAINED_GLASS:15)
Block(-6,125,4,STANDING_BANNER:2,NBT/skyscraper_3x3_01/2684-bannerC16R0.nbt)
Block(-6,125,8,CONCRETE:8)
Block(-6,126,3,STAINED_GLASS:15)
Block(-6,126,4,CONCRETE:8)
Block(-6,126,5,CONCRETE:8)
Block(-6,126,6,CONCRETE:15)
Block(-6,126,7,CONCRETE:15)
Block(-6,126,8,CONCRETE:15)
Block(-6,127,3,STAINED_GLASS:15)
Block(-6,127,8,DARK_OAK_DOOR:1)
Block(-6,128,3,STAINED_GLASS:15)
Block(-6,128,8,DARK_OAK_DOOR:11)
Block(-6,129,3,STAINED_GLASS:15)
Block(-6,129,4,CONCRETE:15)
Block(-6,129,8,CONCRETE:8)
Block(-6,130,3,STAINED_GLASS:15)
Block(-6,130,8,CONCRETE:8)
Block(-6,131,3,STAINED_GLASS:15)
Block(-6,131,8,CONCRETE:8)
Block(-6,132,3,STAINED_GLASS:15)
Block(-6,132,4,CONCRETE:8)
Block(-6,132,5,CONCRETE:8)
Block(-6,132,6,CONCRETE:15)
Block(-6,132,7,CONCRETE:15)
Block(-6,132,8,CONCRETE:15)
Block(-6,133,3,STAINED_GLASS:15)
Block(-6,133,8,DARK_OAK_DOOR:1)
Block(-6,134,3,STAINED_GLASS:15)
Block(-6,134,8,DARK_OAK_DOOR:11)
Block(-6,135,3,STAINED_GLASS:15)
Block(-6,135,4,CONCRETE:15)
Block(-6,135,8,CONCRETE:8)
Block(-6,136,3,STAINED_GLASS:15)
Block(-6,136,8,CONCRETE:8)
Block(-6,137,3,STAINED_GLASS:15)
Block(-6,137,5,IRON_TRAPDOOR:10)
Block(-6,137,6,IRON_TRAPDOOR:8)
Block(-6,137,8,CONCRETE:8)
Block(-6,138,3,STAINED_GLASS:15)
Block(-6,138,4,CONCRETE:8)
Block(-6,138,5,CONCRETE:8)
Block(-6,138,6,CONCRETE:15)
Block(-6,138,7,CONCRETE:15)
Block(-6,138,8,CONCRETE:15)
Block(-6,139,3,STAINED_GLASS:15)
Block(-6,139,4,CARPET:0)
Block(-6,139,5,CARPET:0)
Block(-6,139,6,CARPET:0)
Block(-6,139,7,CARPET:0)
Block(-6,139,8,DARK_OAK_DOOR:1)
Block(-6,140,3,STAINED_GLASS:15)
Block(-6,140,8,DARK_OAK_DOOR:11)
Block(-6,141,3,STAINED_GLASS:15)
Block(-6,141,4,CONCRETE:15)
Block(-6,141,8,CONCRETE:8)
Block(-6,142,3,STAINED_GLASS:15)
Block(-6,142,8,CONCRETE:8)
Block(-6,143,3,STAINED_GLASS:15)
Block(-6,143,8,CONCRETE:8)
Block(-6,144,3,STAINED_GLASS:15)
Block(-6,144,4,CONCRETE:8)
Block(-6,144,5,CONCRETE:8)
Block(-6,144,6,CONCRETE:15)
Block(-6,144,7,CONCRETE:15)
Block(-6,144,8,CONCRETE:8)
Block(-6,145,3,STAINED_GLASS:15)
Block(-6,145,4,STANDING_BANNER:2,NBT/skyscraper_3x3_01/2686-bannerC16R0.nbt)
Block(-6,145,6,TRAP_DOOR:7)
Block(-6,145,8,DARK_OAK_DOOR:1)
Block(-6,146,3,STAINED_GLASS:15)
Block(-6,146,4,STANDING_BANNER:2,NBT/skyscraper_3x3_01/2687-bannerC16R0.nbt)
Block(-6,146,6,TRAP_DOOR:7)
Block(-6,146,8,DARK_OAK_DOOR:11)
Block(-6,147,3,STAINED_GLASS:15)
Block(-6,147,4,CONCRETE:15)
Block(-6,147,8,CONCRETE:8)
Block(-6,148,3,STAINED_GLASS:15)
Block(-6,148,4,STANDING_BANNER:2,NBT/skyscraper_3x3_01/2688-bannerC16R0.nbt)
Block(-6,148,8,CONCRETE:8)
Block(-6,149,3,STAINED_GLASS:15)
Block(-6,149,4,STANDING_BANNER:2,NBT/skyscraper_3x3_01/2689-bannerC16R0.nbt)
Block(-6,149,8,CONCRETE:8)
Block(-6,150,3,STAINED_GLASS:15)
Block(-6,150,4,CONCRETE:8)
Block(-6,150,5,CONCRETE:8)
Block(-6,150,6,CONCRETE:15)
Block(-6,150,7,CONCRETE:15)
Block(-6,150,8,CONCRETE:15)
Block(-6,151,3,STAINED_GLASS:15)
Block(-6,151,8,DARK_OAK_DOOR:1)
Block(-6,152,3,STAINED_GLASS:15)
Block(-6,152,8,DARK_OAK_DOOR:8)
Block(-6,153,3,STAINED_GLASS:15)
Block(-6,153,4,CONCRETE:15)
Block(-6,153,8,CONCRETE:8)
Block(-6,154,3,STAINED_GLASS:15)
Block(-6,154,8,CONCRETE:8)
Block(-6,155,3,STAINED_GLASS:15)
Block(-6,155,5,IRON_TRAPDOOR:10)
Block(-6,155,6,IRON_TRAPDOOR:8)
Block(-6,155,8,CONCRETE:8)
