
#######################################################################
# +-----------------------------------------------------------------+ #
# |                            BO4 object                           | #
# +-----------------------------------------------------------------+ #
#######################################################################

Author: NLBlackEagle

Description: No description given

SettingsMode: WriteDisable


#######################################################################
# +-----------------------------------------------------------------+ #
# |                          Main settings                          | #
# +-----------------------------------------------------------------+ #
#######################################################################

Frequency: 0

SpawnHeight: highestBlock

UseCenterForHighestBlock: true

##############################
# Height Limits for the BO4. #
##############################

MinHeight: 0

MaxHeight: 255

InheritBO3: 

InheritBO3Rotation: NORTH

OverrideChildSettings: true

OverrideParentHeight: false

CanOverride: true

BranchFrequency: 0

BranchFrequencyGroup: 

MustBeBelowOther: false

MustBeInside: 

CannotBeInside: 

ReplacesBO3: L4-M-CrossC0R0, L4-M-CrossC0R1, L4-M-CrossC0R2, L4-M-CrossC0R3, L4-M-CrossC1R0, L4-M-CrossC1R1, L4-M-CrossC1R2, L4-M-CrossC1R3, L4-M-CrossC2R0, L4-M-CrossC2R1, L4-M-CrossC2R2, L4-M-CrossC2R3, L4-M-CrossC3R0, L4-M-CrossC3R1, L4-M-CrossC3R2, L4-M-CrossC3R3, L4-M-Straigth-START_01-C0R0, L4-M-Straigth-START_01-C0R1, L4-M-Straigth-START_01-C1R0, L4-M-Straigth-START_01-C1R1, L4-M-Straigth-START_01-C2R0, L4-M-Straigth-START_01-C2R1, L4-M-Straigth-START_01-C3R0, L4-M-Straigth-START_01-C3R1, L4-M-Straigth-3CC0R0, L4-M-Straigth-3CC0R1, L4-M-Straigth-3CC0R2, L4-M-Straigth-3CC1R0, L4-M-Straigth-3CC1R1, L4-M-Straigth-3CC1R2, L4-M-Straigth-3CC2R0, L4-M-Straigth-3CC2R1, L4-M-Straigth-3CC2R2, L4-M-Straigth-3CC3R0, L4-M-Straigth-3CC3R1, L4-M-Straigth-3CC3R2, L4-M-Cross, skyscraper_2x2_01, skyscraper_2x2_02, skyscraper_2x2_03, skyscraper_2x2_04, skyscraper_2x2_05, skyscraper_3x3_01, skyscraper_3x3_02, skyscraper_3x3_03, L3-M-Straigth-2CC0R0, L3-M-Straigth-2CC0R1, L3-M-Straigth-2CC1R0, L3-M-Straigth-2CC1R1, L3-M-Straigth-2CC2R0, L3-M-Straigth-2CC2R1, L3-M-Straigth-2CC3R0, L3-M-Straigth-2CC3R1, L3-M-Straigth-3CC0R0, L3-M-Straigth-3CC0R1, L3-M-Straigth-3CC0R2, L3-M-Straigth-3CC1R0, L3-M-Straigth-3CC1R1, L3-M-Straigth-3CC1R2, L3-M-Straigth-3CC2R0, L3-M-Straigth-3CC2R1, L3-M-Straigth-3CC2R2, L3-M-Straigth-3CC3R0, L3-M-Straigth-3CC3R1, L3-M-Straigth-3CC3R2L4-M-CrossC0R0, L4-M-CrossC0R1, L4-M-CrossC0R2, L4-M-CrossC0R3, L4-M-CrossC1R0, L4-M-CrossC1R1, L4-M-CrossC1R2, L4-M-CrossC1R3, L4-M-CrossC2R0, L4-M-CrossC2R1, L4-M-CrossC2R2, L4-M-CrossC2R3, L4-M-CrossC3R0, L4-M-CrossC3R1, L4-M-CrossC3R2, L4-M-CrossC3R3, L4-M-Straigth-START_01-C0R0, L4-M-Straigth-START_01-C0R1, L4-M-Straigth-START_01-C1R0, L4-M-Straigth-START_01-C1R1, L4-M-Straigth-START_01-C2R0, L4-M-Straigth-START_01-C2R1, L4-M-Straigth-START_01-C3R0, L4-M-Straigth-START_01-C3R1, L4-M-Straigth-3CC0R0, L4-M-Straigth-3CC0R1, L4-M-Straigth-3CC0R2, L4-M-Straigth-3CC1R0, L4-M-Straigth-3CC1R1, L4-M-Straigth-3CC1R2, L4-M-Straigth-3CC2R0, L4-M-Straigth-3CC2R1, L4-M-Straigth-3CC2R2, L4-M-Straigth-3CC3R0, L4-M-Straigth-3CC3R1, L4-M-Straigth-3CC3R2, L4-M-Cross, skyscraper_2x2_01, skyscraper_2x2_02, skyscraper_2x2_03, skyscraper_2x2_04, skyscraper_2x2_05, skyscraper_3x3_01, skyscraper_3x3_02, skyscraper_3x3_03

MustBeInsideWorldBorders: false

CanSpawnOnWater: true

SpawnOnWaterOnly: false

SpawnUnderWater: false

SpawnAtWaterLevel: false

HeightOffset: 0

RemoveAir: false

ReplaceAbove: 

ReplaceBelow: 

ReplaceWithBiomeBlocks: true

ReplaceWithSurfaceBlock: GRASS

ReplaceWithGroundBlock: DIRT

ReplaceWithStoneBlock: STONE

SmoothRadius: 0

SmoothHeightOffset: 0

SmoothStartTop: false

SmoothStartWood: false

SmoothingSurfaceBlock: 

SmoothingGroundBlock: 

BO3Group: 

IsSpawnPoint: false

DoReplaceBlocks: true


#######################################################################
# +-----------------------------------------------------------------+ #
# |                              Blocks                             | #
# +-----------------------------------------------------------------+ #
#######################################################################

Block(-8,0,-7,CONCRETE:7)
Block(-8,0,-6,CONCRETE:7)
Block(-8,0,-5,CONCRETE:7)
Block(-8,0,-4,CONCRETE:7)
Block(-8,0,-3,CONCRETE:7)
Block(-8,0,-2,CONCRETE:7)
Block(-8,0,-1,CONCRETE:7)
Block(-8,0,0,CONCRETE:7)
Block(-8,0,1,CONCRETE:7)
Block(-8,0,2,CONCRETE:7)
Block(-8,0,3,CONCRETE:7)
Block(-8,0,4,CONCRETE:7)
Block(-8,0,5,CONCRETE:7)
Block(-8,0,6,CONCRETE:7)
Block(-8,0,7,CONCRETE:7)
Block(-8,0,8,CONCRETE:7)
Block(-8,1,-7,CONCRETE:7)
Block(-8,1,-6,CONCRETE:7)
Block(-8,1,-5,CONCRETE:7)
Block(-8,1,-4,CONCRETE:7)
Block(-8,1,-3,CONCRETE:7)
Block(-8,1,-2,CONCRETE:7)
Block(-8,1,-1,CONCRETE:7)
Block(-8,1,0,CONCRETE:7)
Block(-8,1,1,CONCRETE:7)
Block(-8,1,2,CONCRETE:7)
Block(-8,1,3,CONCRETE:7)
Block(-8,1,4,CONCRETE:7)
Block(-8,1,5,CONCRETE:7)
Block(-8,1,6,CONCRETE:7)
Block(-8,1,7,CONCRETE:7)
Block(-8,1,8,CONCRETE:7)
Block(-8,2,-7,CONCRETE:7)
Block(-8,2,-6,CONCRETE:7)
Block(-8,2,-5,CONCRETE:7)
Block(-8,2,-4,CONCRETE:7)
Block(-8,2,-3,CONCRETE:7)
Block(-8,2,-2,CONCRETE:7)
Block(-8,2,-1,CONCRETE:7)
Block(-8,2,0,CONCRETE:7)
Block(-8,2,1,CONCRETE:7)
Block(-8,2,2,CONCRETE:7)
Block(-8,2,3,CONCRETE:7)
Block(-8,2,4,CONCRETE:7)
Block(-8,2,5,CONCRETE:7)
Block(-8,2,6,CONCRETE:7)
Block(-8,2,7,CONCRETE:7)
Block(-8,2,8,CONCRETE:7)
Block(-8,3,-7,CONCRETE:7)
Block(-8,3,-6,CONCRETE:7)
Block(-8,3,-5,CONCRETE:7)
Block(-8,3,-4,CONCRETE:7)
Block(-8,3,-3,CONCRETE:7)
Block(-8,3,-2,CONCRETE:7)
Block(-8,3,-1,CONCRETE:7)
Block(-8,3,0,CONCRETE:7)
Block(-8,3,1,CONCRETE:7)
Block(-8,3,2,CONCRETE:7)
Block(-8,3,3,CONCRETE:7)
Block(-8,3,4,CONCRETE:7)
Block(-8,3,5,CONCRETE:7)
Block(-8,3,6,CONCRETE:7)
Block(-8,3,7,CONCRETE:7)
Block(-8,3,8,CONCRETE:7)
Block(-8,4,-7,CONCRETE:7)
Block(-8,4,-6,CONCRETE:7)
Block(-8,4,-5,CONCRETE:7)
Block(-8,4,-4,CONCRETE:7)
Block(-8,4,-3,CONCRETE:7)
Block(-8,4,-2,CONCRETE:7)
Block(-8,4,-1,CONCRETE:7)
Block(-8,4,0,CONCRETE:7)
Block(-8,4,1,CONCRETE:7)
Block(-8,4,2,CONCRETE:7)
Block(-8,4,3,CONCRETE:7)
Block(-8,4,4,CONCRETE:7)
Block(-8,4,5,CONCRETE:7)
Block(-8,4,6,CONCRETE:7)
Block(-8,4,7,CONCRETE:7)
Block(-8,4,8,CONCRETE:7)
Block(-8,5,-7,CONCRETE:7)
Block(-8,5,-6,CONCRETE:7)
Block(-8,5,-5,CONCRETE:7)
Block(-8,5,-4,CONCRETE:7)
Block(-8,5,-3,CONCRETE:7)
Block(-8,5,-2,CONCRETE:7)
Block(-8,5,-1,CONCRETE:7)
Block(-8,5,0,CONCRETE:7)
Block(-8,5,1,CONCRETE:7)
Block(-8,5,2,CONCRETE:7)
Block(-8,5,3,CONCRETE:7)
Block(-8,5,4,CONCRETE:7)
Block(-8,5,5,CONCRETE:7)
Block(-8,5,6,CONCRETE:7)
Block(-8,5,7,CONCRETE:7)
Block(-8,5,8,CONCRETE:7)
Block(-8,6,-7,CONCRETE:7)
Block(-8,6,-6,CONCRETE:7)
Block(-8,6,-5,CONCRETE:7)
Block(-8,6,-4,CONCRETE:7)
Block(-8,6,-3,CONCRETE:7)
Block(-8,6,-2,CONCRETE:7)
Block(-8,6,-1,CONCRETE:7)
Block(-8,6,0,CONCRETE:7)
Block(-8,6,1,CONCRETE:7)
Block(-8,6,2,CONCRETE:7)
Block(-8,6,3,CONCRETE:7)
Block(-8,6,4,CONCRETE:7)
Block(-8,6,5,CONCRETE:7)
Block(-8,6,6,CONCRETE:7)
Block(-8,6,7,CONCRETE:7)
Block(-8,6,8,CONCRETE:7)
Block(-8,7,-7,CONCRETE:7)
Block(-8,7,-6,CONCRETE:7)
Block(-8,7,-5,CONCRETE:7)
Block(-8,7,-4,CONCRETE:7)
Block(-8,7,-3,CONCRETE:7)
Block(-8,7,-2,CONCRETE:7)
Block(-8,7,-1,CONCRETE:7)
Block(-8,7,0,CONCRETE:7)
Block(-8,7,1,CONCRETE:7)
Block(-8,7,2,CONCRETE:7)
Block(-8,7,3,CONCRETE:7)
Block(-8,7,4,CONCRETE:7)
Block(-8,7,5,CONCRETE:7)
Block(-8,7,6,CONCRETE:7)
Block(-8,7,7,CONCRETE:7)
Block(-8,7,8,CONCRETE:7)
Block(-8,8,-7,CONCRETE:7)
Block(-8,8,-6,CONCRETE:7)
Block(-8,8,-5,CONCRETE:7)
Block(-8,8,-4,CONCRETE:7)
Block(-8,8,-3,CONCRETE:7)
Block(-8,8,-2,CONCRETE:7)
Block(-8,8,-1,CONCRETE:7)
Block(-8,8,0,CONCRETE:7)
Block(-8,8,1,CONCRETE:7)
Block(-8,8,2,CONCRETE:7)
Block(-8,8,3,CONCRETE:7)
Block(-8,8,4,CONCRETE:7)
Block(-8,8,5,CONCRETE:7)
Block(-8,8,6,CONCRETE:7)
Block(-8,8,7,CONCRETE:7)
Block(-8,8,8,CONCRETE:7)
Block(-8,9,-7,CONCRETE:7)
Block(-8,9,-6,CONCRETE:7)
Block(-8,9,-5,CONCRETE:7)
Block(-8,9,-4,CONCRETE:7)
Block(-8,9,-3,CONCRETE:7)
Block(-8,9,-2,CONCRETE:7)
Block(-8,9,-1,CONCRETE:7)
Block(-8,9,0,CONCRETE:7)
Block(-8,9,1,CONCRETE:7)
Block(-8,9,2,CONCRETE:7)
Block(-8,9,3,CONCRETE:7)
Block(-8,9,4,CONCRETE:7)
Block(-8,9,5,CONCRETE:7)
Block(-8,9,6,CONCRETE:7)
Block(-8,9,7,CONCRETE:7)
Block(-8,9,8,CONCRETE:7)
Block(-8,10,-7,CONCRETE:7)
Block(-8,10,-6,CONCRETE:7)
Block(-8,10,-5,CONCRETE:7)
Block(-8,10,-4,CONCRETE:7)
Block(-8,10,-3,CONCRETE:7)
Block(-8,10,-2,CONCRETE:7)
Block(-8,10,-1,CONCRETE:7)
Block(-8,10,0,CONCRETE:7)
Block(-8,10,1,CONCRETE:7)
Block(-8,10,2,CONCRETE:7)
Block(-8,10,3,CONCRETE:7)
Block(-8,10,4,CONCRETE:7)
Block(-8,10,5,CONCRETE:7)
Block(-8,10,6,CONCRETE:7)
Block(-8,10,7,CONCRETE:7)
Block(-8,10,8,CONCRETE:7)
Block(-8,11,-7,CONCRETE:7)
Block(-8,11,-6,CONCRETE:7)
Block(-8,11,-5,CONCRETE:7)
Block(-8,11,-4,CONCRETE:7)
Block(-8,11,-3,CONCRETE:7)
Block(-8,11,-2,CONCRETE:7)
Block(-8,11,-1,CONCRETE:7)
Block(-8,11,0,CONCRETE:7)
Block(-8,11,1,CONCRETE:7)
Block(-8,11,2,CONCRETE:7)
Block(-8,11,3,CONCRETE:7)
Block(-8,11,4,CONCRETE:7)
Block(-8,11,5,CONCRETE:7)
Block(-8,11,6,CONCRETE:7)
Block(-8,11,7,CONCRETE:7)
Block(-8,11,8,CONCRETE:7)
Block(-8,12,-7,CONCRETE:7)
Block(-8,12,-6,CONCRETE:7)
Block(-8,12,-5,CONCRETE:7)
Block(-8,12,-4,CONCRETE:7)
Block(-8,12,-3,CONCRETE:7)
Block(-8,12,-2,CONCRETE:7)
Block(-8,12,-1,CONCRETE:7)
Block(-8,12,0,CONCRETE:7)
Block(-8,12,1,CONCRETE:7)
Block(-8,12,2,CONCRETE:7)
Block(-8,12,3,CONCRETE:7)
Block(-8,12,4,CONCRETE:7)
Block(-8,12,5,CONCRETE:7)
Block(-8,12,6,CONCRETE:7)
Block(-8,12,7,CONCRETE:7)
Block(-8,12,8,CONCRETE:7)
Block(-8,13,-7,CONCRETE:7)
Block(-8,13,-6,CONCRETE:7)
Block(-8,13,-5,CONCRETE:7)
Block(-8,13,-4,CONCRETE:7)
Block(-8,13,-3,CONCRETE:7)
Block(-8,13,-2,CONCRETE:7)
Block(-8,13,-1,CONCRETE:7)
Block(-8,13,0,CONCRETE:7)
Block(-8,13,1,CONCRETE:7)
Block(-8,13,2,CONCRETE:7)
Block(-8,13,3,CONCRETE:7)
Block(-8,13,4,CONCRETE:7)
Block(-8,13,5,CONCRETE:7)
Block(-8,13,6,CONCRETE:7)
Block(-8,13,7,CONCRETE:7)
Block(-8,13,8,CONCRETE:7)
Block(-8,14,-7,CONCRETE:7)
Block(-8,14,-6,CONCRETE:7)
Block(-8,14,-5,CONCRETE:7)
Block(-8,14,-4,CONCRETE:7)
Block(-8,14,-3,CONCRETE:7)
Block(-8,14,-2,CONCRETE:7)
Block(-8,14,-1,CONCRETE:7)
Block(-8,14,0,CONCRETE:7)
Block(-8,14,1,CONCRETE:7)
Block(-8,14,2,CONCRETE:7)
Block(-8,14,3,CONCRETE:7)
Block(-8,14,4,CONCRETE:7)
Block(-8,14,5,CONCRETE:7)
Block(-8,14,6,CONCRETE:7)
Block(-8,14,7,CONCRETE:7)
Block(-8,14,8,CONCRETE:7)
Block(-8,15,-7,CONCRETE:7)
Block(-8,15,-6,CONCRETE:7)
Block(-8,15,-5,CONCRETE:7)
Block(-8,15,-4,CONCRETE:7)
Block(-8,15,-3,CONCRETE:7)
Block(-8,15,-2,CONCRETE:7)
Block(-8,15,-1,CONCRETE:7)
Block(-8,15,0,CONCRETE:7)
Block(-8,15,1,CONCRETE:7)
Block(-8,15,2,CONCRETE:7)
Block(-8,15,3,CONCRETE:7)
Block(-8,15,4,CONCRETE:7)
Block(-8,15,5,CONCRETE:7)
Block(-8,15,6,CONCRETE:7)
Block(-8,15,7,CONCRETE:7)
Block(-8,15,8,CONCRETE:7)
Block(-8,16,-7,CONCRETE:7)
Block(-8,16,-6,CONCRETE:7)
Block(-8,16,-5,CONCRETE:7)
Block(-8,16,-4,CONCRETE:7)
Block(-8,16,-3,CONCRETE:7)
Block(-8,16,-2,CONCRETE:7)
Block(-8,16,-1,CONCRETE:7)
Block(-8,16,0,CONCRETE:7)
Block(-8,16,1,CONCRETE:7)
Block(-8,16,2,CONCRETE:7)
Block(-8,16,3,CONCRETE:7)
Block(-8,16,4,CONCRETE:7)
Block(-8,16,5,CONCRETE:7)
Block(-8,16,6,CONCRETE:7)
Block(-8,16,7,CONCRETE:7)
Block(-8,16,8,CONCRETE:7)
Block(-8,17,-7,CONCRETE:7)
Block(-8,17,-6,CONCRETE:7)
Block(-8,17,-5,CONCRETE:7)
Block(-8,17,-4,CONCRETE:7)
Block(-8,17,-3,CONCRETE:7)
Block(-8,17,-2,CONCRETE:7)
Block(-8,17,-1,CONCRETE:7)
Block(-8,17,0,CONCRETE:7)
Block(-8,17,1,CONCRETE:7)
Block(-8,17,2,CONCRETE:7)
Block(-8,17,3,CONCRETE:7)
Block(-8,17,4,CONCRETE:7)
Block(-8,17,5,CONCRETE:7)
Block(-8,17,6,CONCRETE:7)
Block(-8,17,7,CONCRETE:7)
Block(-8,17,8,CONCRETE:7)
Block(-8,18,-7,STAINED_GLASS:15)
Block(-8,18,-6,CONCRETE:7)
Block(-8,18,-5,STAINED_GLASS:15)
Block(-8,18,-4,CONCRETE:7)
Block(-8,18,-3,STAINED_GLASS:15)
Block(-8,18,-2,CONCRETE:7)
Block(-8,19,-7,STAINED_GLASS:15)
Block(-8,19,-6,CONCRETE:7)
Block(-8,19,-5,STAINED_GLASS:15)
Block(-8,19,-4,CONCRETE:7)
Block(-8,19,-3,STAINED_GLASS:15)
Block(-8,19,-2,CONCRETE:7)
Block(-8,20,-7,STAINED_GLASS:15)
Block(-8,20,-6,CONCRETE:7)
Block(-8,20,-5,STAINED_GLASS:15)
Block(-8,20,-4,CONCRETE:7)
Block(-8,20,-3,STAINED_GLASS:15)
Block(-8,20,-2,CONCRETE:7)
Block(-8,21,-7,STAINED_GLASS:15)
Block(-8,21,-6,CONCRETE:7)
Block(-8,21,-5,STAINED_GLASS:15)
Block(-8,21,-4,CONCRETE:7)
Block(-8,21,-3,STAINED_GLASS:15)
Block(-8,21,-2,CONCRETE:7)
Block(-8,22,-7,STAINED_GLASS:15)
Block(-8,22,-6,CONCRETE:7)
Block(-8,22,-5,STAINED_GLASS:15)
Block(-8,22,-4,CONCRETE:7)
Block(-8,22,-3,STAINED_GLASS:15)
Block(-8,22,-2,CONCRETE:7)
Block(-8,23,-7,STAINED_GLASS:15)
Block(-8,23,-6,CONCRETE:7)
Block(-8,23,-5,STAINED_GLASS:15)
Block(-8,23,-4,CONCRETE:7)
Block(-8,23,-3,STAINED_GLASS:15)
Block(-8,23,-2,CONCRETE:7)
Block(-8,24,-7,STAINED_GLASS:15)
Block(-8,24,-6,CONCRETE:7)
Block(-8,24,-5,STAINED_GLASS:15)
Block(-8,24,-4,CONCRETE:7)
Block(-8,24,-3,STAINED_GLASS:15)
Block(-8,24,-2,CONCRETE:7)
Block(-8,25,-7,STAINED_GLASS:15)
Block(-8,25,-6,CONCRETE:7)
Block(-8,25,-5,STAINED_GLASS:15)
Block(-8,25,-4,CONCRETE:7)
Block(-8,25,-3,STAINED_GLASS:15)
Block(-8,25,-2,CONCRETE:7)
Block(-8,26,-7,STAINED_GLASS:15)
Block(-8,26,-6,CONCRETE:7)
Block(-8,26,-5,STAINED_GLASS:15)
Block(-8,26,-4,CONCRETE:7)
Block(-8,26,-3,STAINED_GLASS:15)
Block(-8,26,-2,CONCRETE:7)
Block(-8,27,-7,STAINED_GLASS:15)
Block(-8,27,-6,CONCRETE:7)
Block(-8,27,-5,STAINED_GLASS:15)
Block(-8,27,-4,CONCRETE:7)
Block(-8,27,-3,STAINED_GLASS:15)
Block(-8,27,-2,CONCRETE:7)
Block(-8,28,-7,STAINED_GLASS:15)
Block(-8,28,-6,CONCRETE:7)
Block(-8,28,-5,STAINED_GLASS:15)
Block(-8,28,-4,CONCRETE:7)
Block(-8,28,-3,STAINED_GLASS:15)
Block(-8,28,-2,CONCRETE:7)
Block(-8,29,-7,STAINED_GLASS:15)
Block(-8,29,-6,CONCRETE:7)
Block(-8,29,-5,STAINED_GLASS:15)
Block(-8,29,-4,CONCRETE:7)
Block(-8,29,-3,STAINED_GLASS:15)
Block(-8,29,-2,CONCRETE:7)
Block(-8,30,-7,STAINED_GLASS:15)
Block(-8,30,-6,CONCRETE:7)
Block(-8,30,-5,STAINED_GLASS:15)
Block(-8,30,-4,CONCRETE:7)
Block(-8,30,-3,STAINED_GLASS:15)
Block(-8,30,-2,CONCRETE:7)
Block(-8,31,-7,STAINED_GLASS:15)
Block(-8,31,-6,CONCRETE:7)
Block(-8,31,-5,STAINED_GLASS:15)
Block(-8,31,-4,CONCRETE:7)
Block(-8,31,-3,STAINED_GLASS:15)
Block(-8,31,-2,CONCRETE:7)
Block(-8,32,-7,STAINED_GLASS:15)
Block(-8,32,-6,CONCRETE:7)
Block(-8,32,-5,STAINED_GLASS:15)
Block(-8,32,-4,CONCRETE:7)
Block(-8,32,-3,STAINED_GLASS:15)
Block(-8,32,-2,CONCRETE:7)
Block(-8,33,-7,STAINED_GLASS:15)
Block(-8,33,-6,CONCRETE:7)
Block(-8,33,-5,STAINED_GLASS:15)
Block(-8,33,-4,CONCRETE:7)
Block(-8,33,-3,STAINED_GLASS:15)
Block(-8,33,-2,CONCRETE:7)
Block(-8,34,-7,STAINED_GLASS:15)
Block(-8,34,-6,CONCRETE:7)
Block(-8,34,-5,STAINED_GLASS:15)
Block(-8,34,-4,CONCRETE:7)
Block(-8,34,-3,STAINED_GLASS:15)
Block(-8,34,-2,CONCRETE:7)
Block(-8,35,-7,STAINED_GLASS:15)
Block(-8,35,-6,CONCRETE:7)
Block(-8,35,-5,STAINED_GLASS:15)
Block(-8,35,-4,CONCRETE:7)
Block(-8,35,-3,STAINED_GLASS:15)
Block(-8,35,-2,CONCRETE:7)
Block(-8,36,-7,STAINED_GLASS:15)
Block(-8,36,-6,CONCRETE:7)
Block(-8,36,-5,STAINED_GLASS:15)
Block(-8,36,-4,CONCRETE:7)
Block(-8,36,-3,STAINED_GLASS:15)
Block(-8,36,-2,CONCRETE:7)
Block(-8,37,-7,STAINED_GLASS:15)
Block(-8,37,-6,CONCRETE:7)
Block(-8,37,-5,STAINED_GLASS:15)
Block(-8,37,-4,CONCRETE:7)
Block(-8,37,-3,STAINED_GLASS:15)
Block(-8,37,-2,CONCRETE:7)
Block(-8,38,-7,STAINED_GLASS:15)
Block(-8,38,-6,CONCRETE:7)
Block(-8,38,-5,STAINED_GLASS:15)
Block(-8,38,-4,CONCRETE:7)
Block(-8,38,-3,STAINED_GLASS:15)
Block(-8,38,-2,CONCRETE:7)
Block(-8,39,-7,STAINED_GLASS:15)
Block(-8,39,-6,CONCRETE:7)
Block(-8,39,-5,STAINED_GLASS:15)
Block(-8,39,-4,CONCRETE:7)
Block(-8,39,-3,STAINED_GLASS:15)
Block(-8,39,-2,CONCRETE:7)
Block(-8,40,-7,STAINED_GLASS:15)
Block(-8,40,-6,CONCRETE:7)
Block(-8,40,-5,STAINED_GLASS:15)
Block(-8,40,-4,CONCRETE:7)
Block(-8,40,-3,STAINED_GLASS:15)
Block(-8,40,-2,CONCRETE:7)
Block(-8,41,-7,STAINED_GLASS:15)
Block(-8,41,-6,CONCRETE:7)
Block(-8,41,-5,STAINED_GLASS:15)
Block(-8,41,-4,CONCRETE:7)
Block(-8,41,-3,STAINED_GLASS:15)
Block(-8,41,-2,CONCRETE:7)
Block(-8,42,-7,STAINED_GLASS:15)
Block(-8,42,-6,CONCRETE:7)
Block(-8,42,-5,STAINED_GLASS:15)
Block(-8,42,-4,CONCRETE:7)
Block(-8,42,-3,STAINED_GLASS:15)
Block(-8,42,-2,CONCRETE:7)
Block(-8,43,-7,STAINED_GLASS:15)
Block(-8,43,-6,CONCRETE:7)
Block(-8,43,-5,STAINED_GLASS:15)
Block(-8,43,-4,CONCRETE:7)
Block(-8,43,-3,STAINED_GLASS:15)
Block(-8,43,-2,CONCRETE:7)
Block(-8,44,-7,STAINED_GLASS:15)
Block(-8,44,-6,CONCRETE:7)
Block(-8,44,-5,STAINED_GLASS:15)
Block(-8,44,-4,CONCRETE:7)
Block(-8,44,-3,STAINED_GLASS:15)
Block(-8,44,-2,CONCRETE:7)
Block(-8,45,-7,STAINED_GLASS:15)
Block(-8,45,-6,CONCRETE:7)
Block(-8,45,-5,STAINED_GLASS:15)
Block(-8,45,-4,CONCRETE:7)
Block(-8,45,-3,STAINED_GLASS:15)
Block(-8,45,-2,CONCRETE:7)
Block(-8,46,-7,STAINED_GLASS:15)
Block(-8,46,-6,CONCRETE:7)
Block(-8,46,-5,STAINED_GLASS:15)
Block(-8,46,-4,CONCRETE:7)
Block(-8,46,-3,STAINED_GLASS:15)
Block(-8,46,-2,CONCRETE:7)
Block(-8,47,-7,STAINED_GLASS:15)
Block(-8,47,-6,CONCRETE:7)
Block(-8,47,-5,STAINED_GLASS:15)
Block(-8,47,-4,CONCRETE:7)
Block(-8,47,-3,STAINED_GLASS:15)
Block(-8,47,-2,CONCRETE:7)
Block(-8,48,-7,STAINED_GLASS:15)
Block(-8,48,-6,CONCRETE:7)
Block(-8,48,-5,STAINED_GLASS:15)
Block(-8,48,-4,CONCRETE:7)
Block(-8,48,-3,STAINED_GLASS:15)
Block(-8,48,-2,CONCRETE:7)
Block(-8,77,-7,CONCRETE:7)
Block(-8,77,-6,STAINED_GLASS:15)
Block(-8,77,-5,CONCRETE:7)
Block(-8,77,-4,STAINED_GLASS:15)
Block(-8,77,-3,CONCRETE:7)
Block(-8,77,-2,STAINED_GLASS:15)
Block(-8,77,-1,CONCRETE:7)
Block(-8,77,0,STAINED_GLASS:15)
Block(-8,77,1,CONCRETE:7)
Block(-8,77,2,STAINED_GLASS:15)
Block(-8,77,3,CONCRETE:7)
Block(-8,78,-7,CONCRETE:7)
Block(-8,78,-6,STAINED_GLASS:15)
Block(-8,78,-5,CONCRETE:7)
Block(-8,78,-4,STAINED_GLASS:15)
Block(-8,78,-3,CONCRETE:7)
Block(-8,78,-2,STAINED_GLASS:15)
Block(-8,78,-1,CONCRETE:7)
Block(-8,78,0,STAINED_GLASS:15)
Block(-8,78,1,CONCRETE:7)
Block(-8,78,2,STAINED_GLASS:15)
Block(-8,78,3,CONCRETE:7)
Block(-8,79,-7,CONCRETE:7)
Block(-8,79,-6,STAINED_GLASS:15)
Block(-8,79,-5,CONCRETE:7)
Block(-8,79,-4,STAINED_GLASS:15)
Block(-8,79,-3,CONCRETE:7)
Block(-8,79,-2,STAINED_GLASS:15)
Block(-8,79,-1,CONCRETE:7)
Block(-8,79,0,STAINED_GLASS:15)
Block(-8,79,1,CONCRETE:7)
Block(-8,79,2,STAINED_GLASS:15)
Block(-8,79,3,CONCRETE:7)
Block(-8,80,-7,CONCRETE:7)
Block(-8,80,-6,STAINED_GLASS:15)
Block(-8,80,-5,CONCRETE:7)
Block(-8,80,-4,STAINED_GLASS:15)
Block(-8,80,-3,CONCRETE:7)
Block(-8,80,-2,STAINED_GLASS:15)
Block(-8,80,-1,CONCRETE:7)
Block(-8,80,0,STAINED_GLASS:15)
Block(-8,80,1,CONCRETE:7)
Block(-8,80,2,STAINED_GLASS:15)
Block(-8,80,3,CONCRETE:7)
Block(-8,81,-7,CONCRETE:7)
Block(-8,81,-6,STAINED_GLASS:15)
Block(-8,81,-5,CONCRETE:7)
Block(-8,81,-4,STAINED_GLASS:15)
Block(-8,81,-3,CONCRETE:7)
Block(-8,81,-2,STAINED_GLASS:15)
Block(-8,81,-1,CONCRETE:7)
Block(-8,81,0,STAINED_GLASS:15)
Block(-8,81,1,CONCRETE:7)
Block(-8,81,2,STAINED_GLASS:15)
Block(-8,81,3,CONCRETE:7)
Block(-7,0,-7,CONCRETE:7)
Block(-7,0,-6,CONCRETE:7)
Block(-7,0,-5,CONCRETE:7)
Block(-7,0,-4,CONCRETE:7)
Block(-7,0,-3,CONCRETE:7)
Block(-7,0,-2,CONCRETE:7)
Block(-7,0,-1,CONCRETE:7)
Block(-7,0,0,CONCRETE:7)
Block(-7,0,1,CONCRETE:7)
Block(-7,0,2,CONCRETE:7)
Block(-7,0,3,CONCRETE:7)
Block(-7,0,4,CONCRETE:7)
Block(-7,0,5,CONCRETE:7)
Block(-7,0,6,CONCRETE:7)
Block(-7,0,7,CONCRETE:7)
Block(-7,0,8,CONCRETE:7)
Block(-7,1,-7,CONCRETE:7)
Block(-7,1,-6,CONCRETE:7)
Block(-7,1,-5,CONCRETE:7)
Block(-7,1,-4,CONCRETE:7)
Block(-7,1,-3,CONCRETE:7)
Block(-7,1,-2,CONCRETE:7)
Block(-7,1,-1,CONCRETE:7)
Block(-7,1,0,CONCRETE:7)
Block(-7,1,1,CONCRETE:7)
Block(-7,1,2,CONCRETE:7)
Block(-7,1,3,CONCRETE:7)
Block(-7,1,4,CONCRETE:7)
Block(-7,1,5,CONCRETE:7)
Block(-7,1,6,CONCRETE:7)
Block(-7,1,7,CONCRETE:7)
Block(-7,1,8,CONCRETE:7)
Block(-7,2,-7,CONCRETE:7)
Block(-7,2,-6,CONCRETE:7)
Block(-7,2,-5,CONCRETE:7)
Block(-7,2,-4,CONCRETE:7)
Block(-7,2,-3,CONCRETE:7)
Block(-7,2,-2,CONCRETE:7)
Block(-7,2,-1,CONCRETE:7)
Block(-7,2,0,CONCRETE:7)
Block(-7,2,1,CONCRETE:7)
Block(-7,2,2,CONCRETE:7)
Block(-7,2,3,CONCRETE:7)
Block(-7,2,4,CONCRETE:7)
Block(-7,2,5,CONCRETE:7)
Block(-7,2,6,CONCRETE:7)
Block(-7,2,7,CONCRETE:7)
Block(-7,2,8,CONCRETE:7)
Block(-7,3,-7,CONCRETE:7)
Block(-7,3,-6,CONCRETE:7)
Block(-7,3,-5,CONCRETE:7)
Block(-7,3,-4,CONCRETE:7)
Block(-7,3,-3,CONCRETE:7)
Block(-7,3,-2,CONCRETE:7)
Block(-7,3,-1,CONCRETE:7)
Block(-7,3,0,CONCRETE:7)
Block(-7,3,1,CONCRETE:7)
Block(-7,3,2,CONCRETE:7)
Block(-7,3,3,CONCRETE:7)
Block(-7,3,4,CONCRETE:7)
Block(-7,3,5,CONCRETE:7)
Block(-7,3,6,CONCRETE:7)
Block(-7,3,7,CONCRETE:7)
Block(-7,3,8,CONCRETE:7)
Block(-7,4,-7,CONCRETE:7)
Block(-7,4,-6,CONCRETE:7)
Block(-7,4,-5,CONCRETE:7)
Block(-7,4,-4,CONCRETE:7)
Block(-7,4,-3,CONCRETE:7)
Block(-7,4,-2,CONCRETE:7)
Block(-7,4,-1,CONCRETE:7)
Block(-7,4,0,CONCRETE:7)
Block(-7,4,1,CONCRETE:7)
Block(-7,4,2,CONCRETE:7)
Block(-7,4,3,CONCRETE:7)
Block(-7,4,4,CONCRETE:7)
Block(-7,4,5,CONCRETE:7)
Block(-7,4,6,CONCRETE:7)
Block(-7,4,7,CONCRETE:7)
Block(-7,4,8,CONCRETE:7)
Block(-7,5,-7,CONCRETE:7)
Block(-7,5,-6,CONCRETE:7)
Block(-7,5,-5,CONCRETE:7)
Block(-7,5,-4,CONCRETE:7)
Block(-7,5,-3,CONCRETE:7)
Block(-7,5,-2,CONCRETE:7)
Block(-7,5,-1,CONCRETE:7)
Block(-7,5,0,CONCRETE:7)
Block(-7,5,1,CONCRETE:7)
Block(-7,5,2,CONCRETE:7)
Block(-7,5,3,CONCRETE:7)
Block(-7,5,4,CONCRETE:7)
Block(-7,5,5,CONCRETE:7)
Block(-7,5,6,CONCRETE:7)
Block(-7,5,7,CONCRETE:7)
Block(-7,5,8,CONCRETE:7)
Block(-7,6,-7,CONCRETE:7)
Block(-7,6,-6,CONCRETE:7)
Block(-7,6,-5,CONCRETE:7)
Block(-7,6,-4,CONCRETE:7)
Block(-7,6,-3,CONCRETE:7)
Block(-7,6,-2,CONCRETE:7)
Block(-7,6,-1,CONCRETE:7)
Block(-7,6,0,CONCRETE:7)
Block(-7,6,1,CONCRETE:7)
Block(-7,6,2,CONCRETE:7)
Block(-7,6,3,CONCRETE:7)
Block(-7,6,4,CONCRETE:7)
Block(-7,6,5,CONCRETE:7)
Block(-7,6,6,CONCRETE:7)
Block(-7,6,7,CONCRETE:7)
Block(-7,6,8,CONCRETE:7)
Block(-7,7,-7,CONCRETE:7)
Block(-7,7,-6,CONCRETE:7)
Block(-7,7,-5,CONCRETE:7)
Block(-7,7,-4,CONCRETE:7)
Block(-7,7,-3,CONCRETE:7)
Block(-7,7,-2,CONCRETE:7)
Block(-7,7,-1,CONCRETE:7)
Block(-7,7,0,CONCRETE:7)
Block(-7,7,1,CONCRETE:7)
Block(-7,7,2,CONCRETE:7)
Block(-7,7,3,CONCRETE:7)
Block(-7,7,4,CONCRETE:7)
Block(-7,7,5,CONCRETE:7)
Block(-7,7,6,CONCRETE:7)
Block(-7,7,7,CONCRETE:7)
Block(-7,7,8,CONCRETE:7)
Block(-7,8,-7,CONCRETE:7)
Block(-7,8,-6,CONCRETE:7)
Block(-7,8,-5,CONCRETE:7)
Block(-7,8,-4,CONCRETE:7)
Block(-7,8,-3,CONCRETE:7)
Block(-7,8,-2,CONCRETE:7)
Block(-7,8,-1,CONCRETE:7)
Block(-7,8,0,CONCRETE:7)
Block(-7,8,1,CONCRETE:7)
Block(-7,8,2,CONCRETE:7)
Block(-7,8,3,CONCRETE:7)
Block(-7,8,4,CONCRETE:7)
Block(-7,8,5,CONCRETE:7)
Block(-7,8,6,CONCRETE:7)
Block(-7,8,7,CONCRETE:7)
Block(-7,8,8,CONCRETE:7)
Block(-7,9,-7,CONCRETE:7)
Block(-7,9,-6,CONCRETE:7)
Block(-7,9,-5,CONCRETE:7)
Block(-7,9,-4,CONCRETE:7)
Block(-7,9,-3,CONCRETE:7)
Block(-7,9,-2,CONCRETE:7)
Block(-7,9,-1,CONCRETE:7)
Block(-7,9,0,CONCRETE:7)
Block(-7,9,1,CONCRETE:7)
Block(-7,9,2,CONCRETE:7)
Block(-7,9,3,CONCRETE:7)
Block(-7,9,4,CONCRETE:7)
Block(-7,9,5,CONCRETE:7)
Block(-7,9,6,CONCRETE:7)
Block(-7,9,7,CONCRETE:7)
Block(-7,9,8,CONCRETE:7)
Block(-7,10,-7,CONCRETE:7)
Block(-7,10,-6,CONCRETE:7)
Block(-7,10,-5,CONCRETE:7)
Block(-7,10,-4,CONCRETE:7)
Block(-7,10,-3,CONCRETE:7)
Block(-7,10,-2,CONCRETE:7)
Block(-7,10,-1,CONCRETE:7)
Block(-7,10,0,CONCRETE:7)
Block(-7,10,1,CONCRETE:7)
Block(-7,10,2,CONCRETE:7)
Block(-7,10,3,CONCRETE:7)
Block(-7,10,4,CONCRETE:7)
Block(-7,10,5,CONCRETE:7)
Block(-7,10,6,CONCRETE:7)
Block(-7,10,7,CONCRETE:7)
Block(-7,10,8,CONCRETE:7)
Block(-7,11,-7,CONCRETE:7)
Block(-7,11,-6,CONCRETE:7)
Block(-7,11,-5,CONCRETE:7)
Block(-7,11,-4,CONCRETE:7)
Block(-7,11,-3,CONCRETE:7)
Block(-7,11,-2,CONCRETE:7)
Block(-7,11,-1,CONCRETE:7)
Block(-7,11,0,CONCRETE:7)
Block(-7,11,1,CONCRETE:7)
Block(-7,11,2,CONCRETE:7)
Block(-7,11,3,CONCRETE:7)
Block(-7,11,4,CONCRETE:7)
Block(-7,11,5,CONCRETE:7)
Block(-7,11,6,CONCRETE:7)
Block(-7,11,7,CONCRETE:7)
Block(-7,11,8,CONCRETE:7)
Block(-7,12,-7,CONCRETE:7)
Block(-7,12,-6,CONCRETE:7)
Block(-7,12,-5,CONCRETE:7)
Block(-7,12,-4,CONCRETE:7)
Block(-7,12,-3,CONCRETE:7)
Block(-7,12,-2,CONCRETE:7)
Block(-7,12,-1,CONCRETE:7)
Block(-7,12,0,CONCRETE:7)
Block(-7,12,1,CONCRETE:7)
Block(-7,12,2,CONCRETE:7)
Block(-7,12,3,CONCRETE:7)
Block(-7,12,4,CONCRETE:7)
Block(-7,12,5,CONCRETE:7)
Block(-7,12,6,CONCRETE:7)
Block(-7,12,7,CONCRETE:7)
Block(-7,12,8,CONCRETE:7)
Block(-7,13,-7,CONCRETE:7)
Block(-7,13,-6,CONCRETE:7)
Block(-7,13,-5,CONCRETE:7)
Block(-7,13,-4,CONCRETE:7)
Block(-7,13,-3,CONCRETE:7)
Block(-7,13,-2,CONCRETE:7)
Block(-7,13,-1,CONCRETE:7)
Block(-7,13,0,CONCRETE:7)
Block(-7,13,1,CONCRETE:7)
Block(-7,13,2,CONCRETE:7)
Block(-7,13,3,CONCRETE:7)
Block(-7,13,4,CONCRETE:7)
Block(-7,13,5,CONCRETE:7)
Block(-7,13,6,CONCRETE:7)
Block(-7,13,7,CONCRETE:7)
Block(-7,13,8,CONCRETE:7)
Block(-7,14,-7,CONCRETE:7)
Block(-7,14,-6,CONCRETE:7)
Block(-7,14,-5,CONCRETE:7)
Block(-7,14,-4,CONCRETE:7)
Block(-7,14,-3,CONCRETE:7)
Block(-7,14,-2,CONCRETE:7)
Block(-7,14,-1,CONCRETE:7)
Block(-7,14,0,CONCRETE:7)
Block(-7,14,1,CONCRETE:7)
Block(-7,14,2,CONCRETE:7)
Block(-7,14,3,CONCRETE:7)
Block(-7,14,4,CONCRETE:7)
Block(-7,14,5,CONCRETE:7)
Block(-7,14,6,CONCRETE:7)
Block(-7,14,7,CONCRETE:7)
Block(-7,14,8,CONCRETE:7)
Block(-7,15,-7,CONCRETE:7)
Block(-7,15,-6,CONCRETE:7)
Block(-7,15,-5,CONCRETE:7)
Block(-7,15,-4,CONCRETE:7)
Block(-7,15,-3,CONCRETE:7)
Block(-7,15,-2,CONCRETE:7)
Block(-7,15,-1,CONCRETE:7)
Block(-7,15,0,CONCRETE:7)
Block(-7,15,1,CONCRETE:7)
Block(-7,15,2,CONCRETE:7)
Block(-7,15,3,CONCRETE:7)
Block(-7,15,4,CONCRETE:7)
Block(-7,15,5,CONCRETE:7)
Block(-7,15,6,CONCRETE:7)
Block(-7,15,7,CONCRETE:7)
Block(-7,15,8,CONCRETE:7)
Block(-7,16,-7,CONCRETE:7)
Block(-7,16,-6,CONCRETE:7)
Block(-7,16,-5,CONCRETE:7)
Block(-7,16,-4,CONCRETE:7)
Block(-7,16,-3,CONCRETE:7)
Block(-7,16,-2,CONCRETE:7)
Block(-7,16,-1,CONCRETE:7)
Block(-7,16,0,CONCRETE:7)
Block(-7,16,1,CONCRETE:7)
Block(-7,16,2,CONCRETE:7)
Block(-7,16,3,CONCRETE:7)
Block(-7,16,4,CONCRETE:7)
Block(-7,16,5,CONCRETE:7)
Block(-7,16,6,CONCRETE:7)
Block(-7,16,7,CONCRETE:7)
Block(-7,16,8,CONCRETE:7)
Block(-7,17,-7,DIRT:2)
Block(-7,17,-6,DIRT:2)
Block(-7,17,-5,DIRT:2)
Block(-7,17,-4,DIRT:2)
Block(-7,17,-3,CONCRETE:8)
Block(-7,17,-2,CONCRETE:7)
Block(-7,17,-1,CONCRETE:7)
Block(-7,17,0,CONCRETE:7)
Block(-7,17,1,CONCRETE:7)
Block(-7,17,2,CONCRETE:7)
Block(-7,17,3,CONCRETE:7)
Block(-7,17,4,CONCRETE:7)
Block(-7,17,5,CONCRETE:7)
Block(-7,17,6,CONCRETE:7)
Block(-7,17,7,CONCRETE:7)
Block(-7,17,8,CONCRETE:7)
Block(-7,18,-7,DOUBLE_PLANT:3)
Block(-7,18,-6,LEAVES_2:5)
Block(-7,18,-5,DOUBLE_PLANT:2)
Block(-7,18,-4,LEAVES_2:5)
Block(-7,18,-2,CONCRETE:7)
Block(-7,19,-7,DOUBLE_PLANT:10)
Block(-7,19,-6,LEAVES_2:5)
Block(-7,19,-5,DOUBLE_PLANT:10)
Block(-7,19,-4,LEAVES_2:5)
Block(-7,19,-2,CONCRETE:7)
Block(-7,20,-4,LEAVES_2:5)
Block(-7,20,-2,CONCRETE:7)
Block(-7,21,-2,CONCRETE:7)
Block(-7,22,-2,CONCRETE:7)
Block(-7,23,-2,CONCRETE:7)
Block(-7,24,-2,CONCRETE:7)
Block(-7,25,-2,CONCRETE:7)
Block(-7,26,-7,STAINED_GLASS:15)
Block(-7,26,-6,CONCRETE:7)
Block(-7,26,-5,STAINED_GLASS:15)
Block(-7,26,-4,CONCRETE:7)
Block(-7,26,-3,STAINED_GLASS:15)
Block(-7,26,-2,CONCRETE:7)
Block(-7,27,-2,CONCRETE:7)
Block(-7,28,-2,CONCRETE:7)
Block(-7,29,-2,CONCRETE:7)
Block(-7,30,-2,CONCRETE:7)
Block(-7,31,-2,CONCRETE:7)
Block(-7,32,-2,CONCRETE:7)
Block(-7,33,-2,CONCRETE:7)
Block(-7,34,-2,CONCRETE:7)
Block(-7,35,-2,CONCRETE:7)
Block(-7,36,-2,CONCRETE:7)
Block(-7,37,-7,STAINED_GLASS:15)
Block(-7,37,-6,CONCRETE:7)
Block(-7,37,-5,STAINED_GLASS:15)
Block(-7,37,-4,CONCRETE:7)
Block(-7,37,-3,STAINED_GLASS:15)
Block(-7,37,-2,CONCRETE:7)
Block(-7,38,-2,CONCRETE:7)
Block(-7,39,-2,CONCRETE:7)
Block(-7,40,-2,CONCRETE:7)
Block(-7,41,-2,CONCRETE:7)
Block(-7,42,-7,STAINED_GLASS:15)
Block(-7,42,-6,CONCRETE:7)
Block(-7,42,-5,STAINED_GLASS:15)
Block(-7,42,-4,CONCRETE:7)
Block(-7,42,-3,STAINED_GLASS:15)
Block(-7,42,-2,CONCRETE:7)
Block(-7,42,3,CONCRETE:7)
Block(-7,42,4,CONCRETE:7)
Block(-7,42,5,CONCRETE:7)
Block(-7,42,6,CONCRETE:7)
Block(-7,42,7,CONCRETE:7)
Block(-7,42,8,CONCRETE:7)
Block(-7,43,-7,STANDING_BANNER:0,NBT/skyscraper_2x2_03/4-bannerC0R16.nbt)
Block(-7,43,-6,DARK_OAK_STAIRS:2)
Block(-7,43,-4,STANDING_BANNER:0,NBT/skyscraper_2x2_03/5-bannerC0R16.nbt)
Block(-7,43,-3,DARK_OAK_STAIRS:2)
Block(-7,43,-2,CONCRETE:7)
Block(-7,43,3,CONCRETE:7)
Block(-7,43,4,CONCRETE:7)
Block(-7,43,5,CONCRETE:7)
Block(-7,43,6,CONCRETE:7)
Block(-7,43,7,CONCRETE:7)
Block(-7,43,8,CONCRETE:7)
Block(-7,44,-7,IRON_TRAPDOOR:3)
Block(-7,44,-6,TRAP_DOOR:4)
Block(-7,44,-5,WALL_BANNER:2,NBT/skyscraper_2x2_03/8-bannerC0R16.nbt)
Block(-7,44,-4,IRON_TRAPDOOR:3)
Block(-7,44,-3,TRAP_DOOR:4)
Block(-7,44,-2,CONCRETE:7)
Block(-7,44,3,CONCRETE:7)
Block(-7,44,4,CONCRETE:7)
Block(-7,44,5,CONCRETE:7)
Block(-7,44,6,CONCRETE:7)
Block(-7,44,7,CONCRETE:7)
Block(-7,44,8,CONCRETE:7)
Block(-7,45,-2,CONCRETE:7)
Block(-7,45,3,CONCRETE:7)
Block(-7,45,4,CONCRETE:7)
Block(-7,45,5,CONCRETE:7)
Block(-7,45,6,CONCRETE:7)
Block(-7,45,7,CONCRETE:7)
Block(-7,45,8,CONCRETE:7)
Block(-7,46,-2,CONCRETE:7)
Block(-7,46,3,CONCRETE:7)
Block(-7,46,4,CONCRETE:7)
Block(-7,46,5,CONCRETE:7)
Block(-7,46,6,CONCRETE:7)
Block(-7,46,7,CONCRETE:7)
Block(-7,46,8,CONCRETE:7)
Block(-7,47,-2,CONCRETE:7)
Block(-7,47,3,CONCRETE:7)
Block(-7,47,4,CONCRETE:7)
Block(-7,47,5,CONCRETE:7)
Block(-7,47,6,CONCRETE:7)
Block(-7,47,7,CONCRETE:7)
Block(-7,47,8,CONCRETE:7)
Block(-7,48,-7,STAINED_GLASS:15)
Block(-7,48,-6,CONCRETE:7)
Block(-7,48,-5,STAINED_GLASS:15)
Block(-7,48,-4,CONCRETE:7)
Block(-7,48,-3,STAINED_GLASS:15)
Block(-7,48,-2,CONCRETE:7)
Block(-7,48,3,CONCRETE:7)
Block(-7,48,4,CONCRETE:7)
Block(-7,48,5,CONCRETE:7)
Block(-7,48,6,CONCRETE:7)
Block(-7,48,7,CONCRETE:7)
Block(-7,48,8,CONCRETE:7)
Block(-7,49,3,CONCRETE:7)
Block(-7,49,4,CONCRETE:7)
Block(-7,49,5,CONCRETE:7)
Block(-7,49,6,CONCRETE:7)
Block(-7,49,7,CONCRETE:7)
Block(-7,49,8,CONCRETE:7)
Block(-7,50,3,CONCRETE:7)
Block(-7,50,4,CONCRETE:7)
Block(-7,50,5,CONCRETE:7)
Block(-7,50,6,CONCRETE:7)
Block(-7,50,7,CONCRETE:7)
Block(-7,50,8,CONCRETE:7)
Block(-7,51,3,CONCRETE:7)
Block(-7,51,4,CONCRETE:7)
Block(-7,51,5,CONCRETE:7)
Block(-7,51,6,CONCRETE:7)
Block(-7,51,7,CONCRETE:7)
Block(-7,51,8,CONCRETE:7)
Block(-7,52,3,CONCRETE:7)
Block(-7,52,4,CONCRETE:7)
Block(-7,52,5,CONCRETE:7)
Block(-7,52,6,CONCRETE:7)
Block(-7,52,7,CONCRETE:7)
Block(-7,52,8,CONCRETE:7)
Block(-7,53,3,CONCRETE:7)
Block(-7,53,4,CONCRETE:7)
Block(-7,53,5,CONCRETE:7)
Block(-7,53,6,CONCRETE:7)
Block(-7,53,7,CONCRETE:7)
Block(-7,53,8,CONCRETE:7)
Block(-7,73,-7,CONCRETE:7)
Block(-7,73,-6,STAINED_GLASS:15)
Block(-7,73,-5,CONCRETE:7)
Block(-7,73,-4,STAINED_GLASS:15)
Block(-7,73,-3,CONCRETE:7)
Block(-7,73,-2,STAINED_GLASS:15)
Block(-7,73,-1,CONCRETE:7)
Block(-7,73,0,STAINED_GLASS:15)
Block(-7,73,1,CONCRETE:7)
Block(-7,74,-7,CONCRETE:7)
Block(-7,74,-6,STAINED_GLASS:15)
Block(-7,74,-5,CONCRETE:7)
Block(-7,74,-4,STAINED_GLASS:15)
Block(-7,74,-3,CONCRETE:7)
Block(-7,74,-2,STAINED_GLASS:15)
Block(-7,74,-1,CONCRETE:7)
Block(-7,74,0,STAINED_GLASS:15)
Block(-7,74,1,CONCRETE:7)
Block(-7,75,-7,CONCRETE:7)
Block(-7,75,-6,STAINED_GLASS:15)
Block(-7,75,-5,CONCRETE:7)
Block(-7,75,-4,STAINED_GLASS:15)
Block(-7,75,-3,CONCRETE:7)
Block(-7,75,-2,STAINED_GLASS:15)
Block(-7,75,-1,CONCRETE:7)
Block(-7,75,0,STAINED_GLASS:15)
Block(-7,75,1,CONCRETE:7)
Block(-7,76,-7,CONCRETE:7)
Block(-7,76,-6,STAINED_GLASS:15)
Block(-7,76,-5,CONCRETE:7)
Block(-7,76,-4,STAINED_GLASS:15)
Block(-7,76,-3,CONCRETE:7)
Block(-7,76,-2,STAINED_GLASS:15)
Block(-7,76,-1,CONCRETE:7)
Block(-7,76,0,STAINED_GLASS:15)
Block(-7,76,1,CONCRETE:7)
Block(-7,77,-7,CONCRETE:7)
Block(-7,77,-6,CONCRETE:7)
Block(-7,77,-5,CONCRETE:7)
Block(-7,77,-4,CONCRETE:7)
Block(-7,77,-3,CONCRETE:7)
Block(-7,77,-2,CONCRETE:7)
Block(-7,77,-1,CONCRETE:7)
Block(-7,77,0,CONCRETE:7)
Block(-7,77,1,CONCRETE:7)
Block(-7,77,2,STAINED_GLASS:15)
Block(-7,77,3,CONCRETE:7)
Block(-7,78,-7,TRAP_DOOR:12)
Block(-7,78,-6,DIRT:2)
Block(-7,78,-5,TRAP_DOOR:13)
Block(-7,78,-3,STAINED_GLASS:15)
Block(-7,78,-1,BIRCH_DOOR:3)
Block(-7,78,1,STEP:0)
Block(-7,78,2,DROPPER:1,NBT/skyscraper_2x2_03/12-dropperC0R16.nbt)
Block(-7,78,3,CONCRETE:7)
Block(-7,79,-6,FLOWER_POT:0,NBT/skyscraper_2x2_03/15-flower_potC0R16.nbt)
Block(-7,79,-3,STAINED_GLASS:15)
Block(-7,79,-1,BIRCH_DOOR:8)
Block(-7,79,0,WALL_BANNER:5,NBT/skyscraper_2x2_03/16-bannerC0R16.nbt)
Block(-7,79,2,TRAP_DOOR:0)
Block(-7,79,3,CONCRETE:7)
Block(-7,80,-6,LEAVES:4)
Block(-7,80,-3,STAINED_GLASS:15)
Block(-7,80,-1,TRAP_DOOR:12)
Block(-7,80,0,WALL_BANNER:5,NBT/skyscraper_2x2_03/17-bannerC0R16.nbt)
Block(-7,80,2,WALL_BANNER:5,NBT/skyscraper_2x2_03/18-bannerC0R16.nbt)
Block(-7,80,3,CONCRETE:7)
Block(-7,81,-7,CONCRETE:7)
Block(-7,81,-6,STAINED_GLASS:15)
Block(-7,81,-5,CONCRETE:7)
Block(-7,81,-4,STAINED_GLASS:15)
Block(-7,81,-3,CONCRETE:7)
Block(-7,81,-2,STAINED_GLASS:15)
Block(-7,81,-1,CONCRETE:7)
Block(-7,81,0,STAINED_GLASS:15)
Block(-7,81,1,CONCRETE:7)
Block(-7,81,2,STAINED_GLASS:15)
Block(-7,81,3,CONCRETE:7)
Block(-6,0,-7,CONCRETE:7)
Block(-6,0,-6,CONCRETE:7)
Block(-6,0,-5,CONCRETE:7)
Block(-6,0,-4,CONCRETE:7)
Block(-6,0,-3,CONCRETE:7)
Block(-6,0,-2,CONCRETE:7)
Block(-6,0,-1,CONCRETE:7)
Block(-6,0,0,CONCRETE:7)
Block(-6,0,1,CONCRETE:7)
Block(-6,0,2,CONCRETE:7)
Block(-6,0,3,CONCRETE:7)
Block(-6,0,4,CONCRETE:7)
Block(-6,0,5,CONCRETE:7)
Block(-6,0,6,CONCRETE:7)
Block(-6,0,7,CONCRETE:7)
Block(-6,0,8,CONCRETE:7)
Block(-6,1,-7,CONCRETE:7)
Block(-6,1,-6,CONCRETE:7)
Block(-6,1,-5,CONCRETE:7)
Block(-6,1,-4,CONCRETE:7)
Block(-6,1,-3,CONCRETE:7)
Block(-6,1,-2,CONCRETE:7)
Block(-6,1,-1,CONCRETE:7)
Block(-6,1,0,CONCRETE:7)
Block(-6,1,1,CONCRETE:7)
Block(-6,1,2,CONCRETE:7)
Block(-6,1,3,CONCRETE:7)
Block(-6,1,4,CONCRETE:7)
Block(-6,1,5,CONCRETE:7)
Block(-6,1,6,CONCRETE:7)
Block(-6,1,7,CONCRETE:7)
Block(-6,1,8,CONCRETE:7)
Block(-6,2,-7,CONCRETE:7)
Block(-6,2,-6,CONCRETE:7)
Block(-6,2,-5,CONCRETE:7)
Block(-6,2,-4,CONCRETE:7)
Block(-6,2,-3,CONCRETE:7)
Block(-6,2,-2,CONCRETE:7)
Block(-6,2,-1,CONCRETE:7)
Block(-6,2,0,CONCRETE:7)
Block(-6,2,1,CONCRETE:7)
Block(-6,2,2,CONCRETE:7)
Block(-6,2,3,CONCRETE:7)
Block(-6,2,4,CONCRETE:7)
Block(-6,2,5,CONCRETE:7)
Block(-6,2,6,CONCRETE:7)
Block(-6,2,7,CONCRETE:7)
Block(-6,2,8,CONCRETE:7)
Block(-6,3,-7,CONCRETE:7)
Block(-6,3,-6,CONCRETE:7)
Block(-6,3,-5,CONCRETE:7)
Block(-6,3,-4,CONCRETE:7)
Block(-6,3,-3,CONCRETE:7)
Block(-6,3,-2,CONCRETE:7)
Block(-6,3,-1,CONCRETE:7)
Block(-6,3,0,CONCRETE:7)
Block(-6,3,1,CONCRETE:7)
Block(-6,3,2,CONCRETE:7)
Block(-6,3,3,CONCRETE:7)
Block(-6,3,4,CONCRETE:7)
Block(-6,3,5,CONCRETE:7)
Block(-6,3,6,CONCRETE:7)
Block(-6,3,7,CONCRETE:7)
Block(-6,3,8,CONCRETE:7)
Block(-6,4,-7,CONCRETE:7)
Block(-6,4,-6,CONCRETE:7)
Block(-6,4,-5,CONCRETE:7)
Block(-6,4,-4,CONCRETE:7)
Block(-6,4,-3,CONCRETE:7)
Block(-6,4,-2,CONCRETE:7)
Block(-6,4,-1,CONCRETE:7)
Block(-6,4,0,CONCRETE:7)
Block(-6,4,1,CONCRETE:7)
Block(-6,4,2,CONCRETE:7)
Block(-6,4,3,CONCRETE:7)
Block(-6,4,4,CONCRETE:7)
Block(-6,4,5,CONCRETE:7)
Block(-6,4,6,CONCRETE:7)
Block(-6,4,7,CONCRETE:7)
Block(-6,4,8,CONCRETE:7)
Block(-6,5,-7,CONCRETE:7)
Block(-6,5,-6,CONCRETE:7)
Block(-6,5,-5,CONCRETE:7)
Block(-6,5,-4,CONCRETE:7)
Block(-6,5,-3,CONCRETE:7)
Block(-6,5,-2,CONCRETE:7)
Block(-6,5,-1,CONCRETE:7)
Block(-6,5,0,CONCRETE:7)
Block(-6,5,1,CONCRETE:7)
Block(-6,5,2,CONCRETE:7)
Block(-6,5,3,CONCRETE:7)
Block(-6,5,4,CONCRETE:7)
Block(-6,5,5,CONCRETE:7)
Block(-6,5,6,CONCRETE:7)
Block(-6,5,7,CONCRETE:7)
Block(-6,5,8,CONCRETE:7)
Block(-6,6,-7,CONCRETE:7)
Block(-6,6,-6,CONCRETE:7)
Block(-6,6,-5,CONCRETE:7)
Block(-6,6,-4,CONCRETE:7)
Block(-6,6,-3,CONCRETE:7)
Block(-6,6,-2,CONCRETE:7)
Block(-6,6,-1,CONCRETE:7)
Block(-6,6,0,CONCRETE:7)
Block(-6,6,1,CONCRETE:7)
Block(-6,6,2,CONCRETE:7)
Block(-6,6,3,CONCRETE:7)
Block(-6,6,4,CONCRETE:7)
Block(-6,6,5,CONCRETE:7)
Block(-6,6,6,CONCRETE:7)
Block(-6,6,7,CONCRETE:7)
Block(-6,6,8,CONCRETE:7)
Block(-6,7,-7,CONCRETE:7)
Block(-6,7,-6,CONCRETE:7)
Block(-6,7,-5,CONCRETE:7)
Block(-6,7,-4,CONCRETE:7)
Block(-6,7,-3,CONCRETE:7)
Block(-6,7,-2,CONCRETE:7)
Block(-6,7,-1,CONCRETE:7)
Block(-6,7,0,CONCRETE:7)
Block(-6,7,1,CONCRETE:7)
Block(-6,7,2,CONCRETE:7)
Block(-6,7,3,CONCRETE:7)
Block(-6,7,4,CONCRETE:7)
Block(-6,7,5,CONCRETE:7)
Block(-6,7,6,CONCRETE:7)
Block(-6,7,7,CONCRETE:7)
Block(-6,7,8,CONCRETE:7)
Block(-6,8,-7,CONCRETE:7)
Block(-6,8,-6,CONCRETE:7)
Block(-6,8,-5,CONCRETE:7)
Block(-6,8,-4,CONCRETE:7)
Block(-6,8,-3,CONCRETE:7)
Block(-6,8,-2,CONCRETE:7)
Block(-6,8,-1,CONCRETE:7)
Block(-6,8,0,CONCRETE:7)
Block(-6,8,1,CONCRETE:7)
Block(-6,8,2,CONCRETE:7)
Block(-6,8,3,CONCRETE:7)
Block(-6,8,4,CONCRETE:7)
Block(-6,8,5,CONCRETE:7)
Block(-6,8,6,CONCRETE:7)
Block(-6,8,7,CONCRETE:7)
Block(-6,8,8,CONCRETE:7)
Block(-6,9,-7,CONCRETE:7)
Block(-6,9,-6,CONCRETE:7)
Block(-6,9,-5,CONCRETE:7)
Block(-6,9,-4,CONCRETE:7)
Block(-6,9,-3,CONCRETE:7)
Block(-6,9,-2,CONCRETE:7)
Block(-6,9,-1,CONCRETE:7)
Block(-6,9,0,CONCRETE:7)
Block(-6,9,1,CONCRETE:7)
Block(-6,9,2,CONCRETE:7)
Block(-6,9,3,CONCRETE:7)
Block(-6,9,4,CONCRETE:7)
Block(-6,9,5,CONCRETE:7)
Block(-6,9,6,CONCRETE:7)
Block(-6,9,7,CONCRETE:7)
Block(-6,9,8,CONCRETE:7)
Block(-6,10,-7,CONCRETE:7)
Block(-6,10,-6,CONCRETE:7)
Block(-6,10,-5,CONCRETE:7)
Block(-6,10,-4,CONCRETE:7)
Block(-6,10,-3,CONCRETE:7)
Block(-6,10,-2,CONCRETE:7)
Block(-6,10,-1,CONCRETE:7)
Block(-6,10,0,CONCRETE:7)
Block(-6,10,1,CONCRETE:7)
Block(-6,10,2,CONCRETE:7)
Block(-6,10,3,CONCRETE:7)
Block(-6,10,4,CONCRETE:7)
Block(-6,10,5,CONCRETE:7)
Block(-6,10,6,CONCRETE:7)
Block(-6,10,7,CONCRETE:7)
Block(-6,10,8,CONCRETE:7)
Block(-6,11,-7,CONCRETE:7)
Block(-6,11,-6,CONCRETE:7)
Block(-6,11,-5,CONCRETE:7)
Block(-6,11,-4,CONCRETE:7)
Block(-6,11,-3,CONCRETE:7)
Block(-6,11,-2,CONCRETE:7)
Block(-6,11,-1,CONCRETE:7)
Block(-6,11,0,CONCRETE:7)
Block(-6,11,1,CONCRETE:7)
Block(-6,11,2,CONCRETE:7)
Block(-6,11,3,CONCRETE:7)
Block(-6,11,4,CONCRETE:7)
Block(-6,11,5,CONCRETE:7)
Block(-6,11,6,CONCRETE:7)
Block(-6,11,7,CONCRETE:7)
Block(-6,11,8,CONCRETE:7)
Block(-6,12,-7,CONCRETE:7)
Block(-6,12,-6,CONCRETE:7)
Block(-6,12,-5,CONCRETE:7)
Block(-6,12,-4,CONCRETE:7)
Block(-6,12,-3,CONCRETE:7)
Block(-6,12,-2,CONCRETE:7)
Block(-6,12,-1,CONCRETE:7)
Block(-6,12,0,CONCRETE:7)
Block(-6,12,1,CONCRETE:7)
Block(-6,12,2,CONCRETE:7)
Block(-6,12,3,CONCRETE:7)
Block(-6,12,4,CONCRETE:7)
Block(-6,12,5,CONCRETE:7)
Block(-6,12,6,CONCRETE:7)
Block(-6,12,7,CONCRETE:7)
Block(-6,12,8,CONCRETE:7)
Block(-6,13,-7,CONCRETE:7)
Block(-6,13,-6,CONCRETE:7)
Block(-6,13,-5,CONCRETE:7)
Block(-6,13,-4,CONCRETE:7)
Block(-6,13,-3,CONCRETE:7)
Block(-6,13,-2,CONCRETE:7)
Block(-6,13,-1,CONCRETE:7)
Block(-6,13,0,CONCRETE:7)
Block(-6,13,1,CONCRETE:7)
Block(-6,13,2,CONCRETE:7)
Block(-6,13,3,CONCRETE:7)
Block(-6,13,4,CONCRETE:7)
Block(-6,13,5,CONCRETE:7)
Block(-6,13,6,CONCRETE:7)
Block(-6,13,7,CONCRETE:7)
Block(-6,13,8,CONCRETE:7)
Block(-6,14,-7,CONCRETE:7)
Block(-6,14,-6,CONCRETE:7)
Block(-6,14,-5,CONCRETE:7)
Block(-6,14,-4,CONCRETE:7)
Block(-6,14,-3,CONCRETE:7)
Block(-6,14,-2,CONCRETE:7)
Block(-6,14,-1,CONCRETE:7)
Block(-6,14,0,CONCRETE:7)
Block(-6,14,1,CONCRETE:7)
Block(-6,14,2,CONCRETE:7)
Block(-6,14,3,CONCRETE:7)
Block(-6,14,4,CONCRETE:7)
Block(-6,14,5,CONCRETE:7)
Block(-6,14,6,CONCRETE:7)
Block(-6,14,7,CONCRETE:7)
Block(-6,14,8,CONCRETE:7)
Block(-6,15,-7,CONCRETE:7)
Block(-6,15,-6,CONCRETE:7)
Block(-6,15,-5,CONCRETE:7)
Block(-6,15,-4,CONCRETE:7)
Block(-6,15,-3,CONCRETE:7)
Block(-6,15,-2,CONCRETE:7)
Block(-6,15,-1,CONCRETE:7)
Block(-6,15,0,CONCRETE:7)
Block(-6,15,1,CONCRETE:7)
Block(-6,15,2,CONCRETE:7)
Block(-6,15,3,CONCRETE:7)
Block(-6,15,4,CONCRETE:7)
Block(-6,15,5,CONCRETE:7)
Block(-6,15,6,CONCRETE:7)
Block(-6,15,7,CONCRETE:7)
Block(-6,15,8,CONCRETE:7)
Block(-6,16,-7,CONCRETE:7)
Block(-6,16,-6,CONCRETE:7)
Block(-6,16,-5,CONCRETE:7)
Block(-6,16,-4,CONCRETE:7)
Block(-6,16,-3,CONCRETE:7)
Block(-6,16,-2,CONCRETE:7)
Block(-6,16,-1,CONCRETE:7)
Block(-6,16,0,CONCRETE:7)
Block(-6,16,1,CONCRETE:7)
Block(-6,16,2,CONCRETE:7)
Block(-6,16,3,CONCRETE:7)
Block(-6,16,4,CONCRETE:7)
Block(-6,16,5,CONCRETE:7)
Block(-6,16,6,CONCRETE:7)
Block(-6,16,7,CONCRETE:7)
Block(-6,16,8,CONCRETE:7)
Block(-6,17,-7,DIRT:2)
Block(-6,17,-6,DIRT:2)
Block(-6,17,-5,DIRT:2)
Block(-6,17,-4,DIRT:2)
Block(-6,17,-3,CONCRETE:8)
Block(-6,17,-2,CONCRETE:7)
Block(-6,17,-1,CONCRETE:7)
Block(-6,17,0,CONCRETE:7)
Block(-6,17,1,CONCRETE:7)
Block(-6,17,2,CONCRETE:7)
Block(-6,17,3,CONCRETE:7)
Block(-6,17,4,CONCRETE:7)
Block(-6,17,5,CONCRETE:7)
Block(-6,17,6,CONCRETE:7)
Block(-6,17,7,CONCRETE:7)
Block(-6,17,8,CONCRETE:7)
Block(-6,18,-7,LONG_GRASS:1)
Block(-6,18,-6,DEAD_BUSH:0)
Block(-6,18,-5,LONG_GRASS:1)
Block(-6,18,-4,DOUBLE_PLANT:3)
Block(-6,18,-3,STAINED_GLASS_PANE:15)
Block(-6,18,-2,CONCRETE:7)
Block(-6,18,-1,CONCRETE:8)
Block(-6,18,0,CONCRETE:8)
Block(-6,18,1,CONCRETE:8)
Block(-6,18,2,CONCRETE:8)
Block(-6,18,3,CONCRETE:8)
Block(-6,19,-4,DOUBLE_PLANT:10)
Block(-6,19,-3,STAINED_GLASS_PANE:15)
Block(-6,19,-2,CONCRETE:7)
Block(-6,19,-1,CONCRETE:8)
Block(-6,19,0,CONCRETE:8)
Block(-6,19,1,CONCRETE:8)
Block(-6,19,2,CONCRETE:8)
Block(-6,19,3,CONCRETE:8)
Block(-6,20,-2,CONCRETE:7)
Block(-6,20,-1,CONCRETE:8)
Block(-6,20,0,CONCRETE:8)
Block(-6,20,1,CONCRETE:8)
Block(-6,20,2,CONCRETE:8)
Block(-6,20,3,CONCRETE:8)
Block(-6,21,-2,CONCRETE:7)
Block(-6,21,-1,CONCRETE:8)
Block(-6,21,0,CONCRETE:8)
Block(-6,21,1,CONCRETE:8)
Block(-6,21,2,CONCRETE:8)
Block(-6,21,3,CONCRETE:8)
Block(-6,22,-7,IRON_TRAPDOOR:11)
Block(-6,22,-5,IRON_TRAPDOOR:11)
Block(-6,22,-2,CONCRETE:7)
Block(-6,22,-1,CONCRETE:8)
Block(-6,22,0,CONCRETE:8)
Block(-6,22,1,CONCRETE:8)
Block(-6,22,2,CONCRETE:8)
Block(-6,22,3,CONCRETE:8)
Block(-6,23,-7,SEA_LANTERN:0)
Block(-6,23,-6,STEP:8)
Block(-6,23,-5,PRISMARINE:0)
Block(-6,23,-4,STEP:8)
Block(-6,23,-2,CONCRETE:7)
Block(-6,23,-1,CONCRETE:8)
Block(-6,23,0,CONCRETE:8)
Block(-6,23,1,CONCRETE:8)
Block(-6,23,2,CONCRETE:8)
Block(-6,23,3,CONCRETE:8)
Block(-6,24,-7,IRON_TRAPDOOR:3)
Block(-6,24,-5,IRON_TRAPDOOR:3)
Block(-6,24,-4,IRON_FENCE:0)
Block(-6,24,-2,CONCRETE:7)
Block(-6,24,-1,CONCRETE:8)
Block(-6,24,0,CONCRETE:8)
Block(-6,24,1,CONCRETE:8)
Block(-6,24,2,CONCRETE:8)
Block(-6,24,3,CONCRETE:8)
Block(-6,25,-4,IRON_FENCE:0)
Block(-6,25,-2,CONCRETE:7)
Block(-6,25,-1,CONCRETE:8)
Block(-6,25,0,CONCRETE:8)
Block(-6,25,1,CONCRETE:8)
Block(-6,25,2,CONCRETE:8)
Block(-6,25,3,CONCRETE:8)
Block(-6,26,-7,STAINED_GLASS:15)
Block(-6,26,-6,CONCRETE:7)
Block(-6,26,-5,STAINED_GLASS:15)
Block(-6,26,-4,CONCRETE:7)
Block(-6,26,-3,STAINED_GLASS:15)
Block(-6,26,-2,CONCRETE:7)
Block(-6,26,-1,CONCRETE:8)
Block(-6,26,0,CONCRETE:8)
Block(-6,26,1,CONCRETE:8)
Block(-6,26,2,CONCRETE:8)
Block(-6,26,3,CONCRETE:8)
Block(-6,27,-7,WALL_SIGN:3,NBT/skyscraper_2x2_03/22-signC0R16.nbt)
Block(-6,27,-5,WALL_SIGN:2,NBT/skyscraper_2x2_03/23-signC0R16.nbt)
Block(-6,27,-4,DARK_OAK_STAIRS:1)
Block(-6,27,-3,WALL_SIGN:3,NBT/skyscraper_2x2_03/24-signC0R16.nbt)
Block(-6,27,-2,CONCRETE:7)
Block(-6,27,-1,CONCRETE:8)
Block(-6,27,0,CONCRETE:8)
Block(-6,27,1,CONCRETE:8)
Block(-6,27,2,CONCRETE:8)
Block(-6,27,3,CONCRETE:8)
Block(-6,28,-4,TRAP_DOOR:7)
Block(-6,28,-2,CONCRETE:7)
Block(-6,28,-1,CONCRETE:8)
Block(-6,28,0,CONCRETE:8)
Block(-6,28,1,CONCRETE:8)
Block(-6,28,2,CONCRETE:8)
Block(-6,28,3,CONCRETE:8)
Block(-6,29,-2,CONCRETE:7)
Block(-6,29,-1,CONCRETE:8)
Block(-6,29,0,CONCRETE:8)
Block(-6,29,1,CONCRETE:8)
Block(-6,29,2,CONCRETE:8)
Block(-6,29,3,CONCRETE:8)
Block(-6,30,-2,CONCRETE:7)
Block(-6,30,-1,CONCRETE:8)
Block(-6,30,0,CONCRETE:8)
Block(-6,30,1,CONCRETE:8)
Block(-6,30,2,CONCRETE:8)
Block(-6,30,3,CONCRETE:8)
Block(-6,31,-2,CONCRETE:7)
Block(-6,31,-1,CONCRETE:8)
Block(-6,31,0,CONCRETE:8)
Block(-6,31,1,CONCRETE:8)
Block(-6,31,2,CONCRETE:8)
Block(-6,31,3,CONCRETE:8)
Block(-6,32,-2,CONCRETE:7)
Block(-6,32,-1,CONCRETE:8)
Block(-6,32,0,CONCRETE:8)
Block(-6,32,1,CONCRETE:8)
Block(-6,32,2,CONCRETE:8)
Block(-6,32,3,CONCRETE:8)
Block(-6,33,-2,CONCRETE:7)
Block(-6,33,-1,CONCRETE:8)
Block(-6,33,0,CONCRETE:8)
Block(-6,33,1,CONCRETE:8)
Block(-6,33,2,CONCRETE:8)
Block(-6,33,3,CONCRETE:8)
Block(-6,34,-2,CONCRETE:7)
Block(-6,34,-1,CONCRETE:8)
Block(-6,34,0,CONCRETE:8)
Block(-6,34,1,CONCRETE:8)
Block(-6,34,2,CONCRETE:8)
Block(-6,34,3,CONCRETE:8)
Block(-6,35,-2,CONCRETE:7)
Block(-6,35,-1,CONCRETE:8)
Block(-6,35,0,CONCRETE:8)
Block(-6,35,1,CONCRETE:8)
Block(-6,35,2,CONCRETE:8)
Block(-6,35,3,CONCRETE:8)
Block(-6,36,-2,CONCRETE:7)
Block(-6,36,-1,CONCRETE:8)
Block(-6,36,0,CONCRETE:8)
Block(-6,36,1,CONCRETE:8)
Block(-6,36,2,CONCRETE:8)
Block(-6,36,3,CONCRETE:8)
Block(-6,37,-7,STAINED_GLASS:15)
Block(-6,37,-6,CONCRETE:7)
Block(-6,37,-5,STAINED_GLASS:15)
Block(-6,37,-4,CONCRETE:7)
Block(-6,37,-3,STAINED_GLASS:15)
Block(-6,37,-2,CONCRETE:7)
Block(-6,37,-1,CONCRETE:8)
Block(-6,37,0,CONCRETE:8)
Block(-6,37,1,CONCRETE:8)
Block(-6,37,2,CONCRETE:8)
Block(-6,37,3,CONCRETE:8)
Block(-6,38,-7,WALL_SIGN:3,NBT/skyscraper_2x2_03/28-signC0R16.nbt)
Block(-6,38,-2,CONCRETE:7)
Block(-6,38,-1,CONCRETE:8)
Block(-6,38,0,CONCRETE:8)
Block(-6,38,1,CONCRETE:8)
Block(-6,38,2,CONCRETE:8)
Block(-6,38,3,CONCRETE:8)
Block(-6,39,-2,CONCRETE:7)
Block(-6,39,-1,CONCRETE:8)
Block(-6,39,0,CONCRETE:8)
Block(-6,39,1,CONCRETE:8)
Block(-6,39,2,CONCRETE:8)
Block(-6,39,3,CONCRETE:8)
Block(-6,40,-2,CONCRETE:7)
Block(-6,40,-1,CONCRETE:8)
Block(-6,40,0,CONCRETE:8)
Block(-6,40,1,CONCRETE:8)
Block(-6,40,2,CONCRETE:8)
Block(-6,40,3,CONCRETE:8)
Block(-6,41,-2,CONCRETE:7)
Block(-6,41,-1,CONCRETE:8)
Block(-6,41,0,CONCRETE:8)
Block(-6,41,1,CONCRETE:8)
Block(-6,41,2,CONCRETE:8)
Block(-6,41,3,CONCRETE:8)
Block(-6,42,-7,STAINED_GLASS:15)
Block(-6,42,-6,CONCRETE:7)
Block(-6,42,-5,STAINED_GLASS:15)
Block(-6,42,-4,CONCRETE:7)
Block(-6,42,-3,STAINED_GLASS:15)
Block(-6,42,-2,CONCRETE:7)
Block(-6,42,-1,CONCRETE:7)
Block(-6,42,0,CONCRETE:7)
Block(-6,42,1,CONCRETE:7)
Block(-6,42,2,CONCRETE:7)
Block(-6,42,3,CONCRETE:7)
Block(-6,42,4,CONCRETE:7)
Block(-6,42,5,CONCRETE:7)
Block(-6,42,6,CONCRETE:7)
Block(-6,42,7,CONCRETE:7)
Block(-6,42,8,STAINED_GLASS:15)
Block(-6,43,-7,QUARTZ_STAIRS:4)
Block(-6,43,-6,WALL_SIGN:5,NBT/skyscraper_2x2_03/30-signC0R16.nbt)
Block(-6,43,-4,QUARTZ_STAIRS:4)
Block(-6,43,-3,WALL_SIGN:5,NBT/skyscraper_2x2_03/31-signC0R16.nbt)
Block(-6,43,-2,CONCRETE:7)
Block(-6,43,-1,STAINED_GLASS_PANE:15)
Block(-6,43,0,STAINED_GLASS_PANE:15)
Block(-6,43,1,STAINED_GLASS_PANE:15)
Block(-6,43,2,STAINED_GLASS_PANE:15)
Block(-6,43,3,STAINED_GLASS:15)
Block(-6,43,5,WALL_SIGN:2,NBT/skyscraper_2x2_03/32-signC0R16.nbt)
Block(-6,43,6,DARK_OAK_STAIRS:1)
Block(-6,43,7,WALL_SIGN:3,NBT/skyscraper_2x2_03/33-signC0R16.nbt)
Block(-6,43,8,STAINED_GLASS:15)
Block(-6,44,-7,IRON_TRAPDOOR:3)
Block(-6,44,-6,IRON_TRAPDOOR:1)
Block(-6,44,-5,WALL_BANNER:2,NBT/skyscraper_2x2_03/36-bannerC0R16.nbt)
Block(-6,44,-4,IRON_TRAPDOOR:3)
Block(-6,44,-2,CONCRETE:7)
Block(-6,44,-1,STAINED_GLASS_PANE:15)
Block(-6,44,0,STAINED_GLASS_PANE:15)
Block(-6,44,1,STAINED_GLASS_PANE:15)
Block(-6,44,2,STAINED_GLASS_PANE:15)
Block(-6,44,3,STAINED_GLASS:15)
Block(-6,44,6,TRAP_DOOR:7)
Block(-6,44,8,STAINED_GLASS:15)
Block(-6,45,-2,CONCRETE:7)
Block(-6,45,-1,STAINED_GLASS:15)
Block(-6,45,0,STAINED_GLASS:15)
Block(-6,45,1,STAINED_GLASS:15)
Block(-6,45,2,STAINED_GLASS:15)
Block(-6,45,3,STAINED_GLASS:15)
Block(-6,45,8,STAINED_GLASS:15)
Block(-6,46,-2,CONCRETE:7)
Block(-6,46,3,STAINED_GLASS:15)
Block(-6,46,4,STAINED_GLASS:15)
Block(-6,46,5,STAINED_GLASS:15)
Block(-6,46,6,STAINED_GLASS:15)
Block(-6,46,7,STAINED_GLASS:15)
Block(-6,46,8,STAINED_GLASS:15)
Block(-6,47,-2,CONCRETE:7)
Block(-6,47,3,STAINED_GLASS:15)
Block(-6,47,5,WALL_SIGN:2,NBT/skyscraper_2x2_03/37-signC0R16.nbt)
Block(-6,47,6,DARK_OAK_STAIRS:1)
Block(-6,47,7,WALL_SIGN:3,NBT/skyscraper_2x2_03/38-signC0R16.nbt)
Block(-6,47,8,STAINED_GLASS:15)
Block(-6,48,-7,STAINED_GLASS:15)
Block(-6,48,-6,CONCRETE:7)
Block(-6,48,-5,STAINED_GLASS:15)
Block(-6,48,-4,CONCRETE:7)
Block(-6,48,-3,STAINED_GLASS:15)
Block(-6,48,-2,CONCRETE:7)
Block(-6,48,3,STAINED_GLASS:15)
Block(-6,48,6,TRAP_DOOR:7)
Block(-6,48,8,STAINED_GLASS:15)
Block(-6,49,3,STAINED_GLASS:15)
Block(-6,49,8,STAINED_GLASS:15)
Block(-6,50,3,STAINED_GLASS:15)
Block(-6,50,8,STAINED_GLASS:15)
Block(-6,51,3,STAINED_GLASS:15)
Block(-6,51,8,STAINED_GLASS:15)
Block(-6,52,3,STAINED_GLASS:15)
Block(-6,52,8,STAINED_GLASS:15)
Block(-6,53,3,STAINED_GLASS:15)
Block(-6,53,4,STAINED_GLASS:15)
Block(-6,53,5,STAINED_GLASS:15)
Block(-6,53,6,STAINED_GLASS:15)
Block(-6,53,7,STAINED_GLASS:15)
Block(-6,53,8,STAINED_GLASS:15)
Block(-6,57,-2,CONCRETE:7)
Block(-6,57,-1,STAINED_GLASS:15)
Block(-6,57,0,CONCRETE:7)
Block(-6,57,1,CONCRETE:7)
Block(-6,57,2,STAINED_GLASS:15)
Block(-6,57,3,CONCRETE:7)
Block(-6,58,-2,CONCRETE:7)
Block(-6,58,-1,STAINED_GLASS:15)
Block(-6,58,0,CONCRETE:7)
Block(-6,58,1,CONCRETE:7)
Block(-6,58,2,STAINED_GLASS:15)
Block(-6,58,3,CONCRETE:7)
Block(-6,59,-2,CONCRETE:7)
Block(-6,59,-1,STAINED_GLASS:15)
Block(-6,59,0,CONCRETE:7)
Block(-6,59,1,CONCRETE:7)
Block(-6,59,2,STAINED_GLASS:15)
Block(-6,59,3,CONCRETE:7)
Block(-6,60,-2,CONCRETE:7)
Block(-6,60,-1,STAINED_GLASS:15)
Block(-6,60,0,CONCRETE:7)
Block(-6,60,1,CONCRETE:7)
Block(-6,60,2,STAINED_GLASS:15)
Block(-6,60,3,CONCRETE:7)
Block(-6,61,-2,CONCRETE:7)
Block(-6,61,-1,STAINED_GLASS:15)
Block(-6,61,0,CONCRETE:7)
Block(-6,61,1,CONCRETE:7)
Block(-6,61,2,STAINED_GLASS:15)
Block(-6,61,3,CONCRETE:7)
Block(-6,62,-2,CONCRETE:7)
Block(-6,62,-1,STAINED_GLASS:15)
Block(-6,62,0,CONCRETE:7)
Block(-6,62,1,CONCRETE:7)
Block(-6,62,2,STAINED_GLASS:15)
Block(-6,62,3,CONCRETE:7)
Block(-6,63,-2,CONCRETE:7)
Block(-6,63,-1,STAINED_GLASS:15)
Block(-6,63,0,CONCRETE:7)
Block(-6,63,1,CONCRETE:7)
Block(-6,63,2,STAINED_GLASS:15)
Block(-6,63,3,CONCRETE:7)
Block(-6,64,-2,CONCRETE:7)
Block(-6,64,-1,STAINED_GLASS:15)
Block(-6,64,0,CONCRETE:7)
Block(-6,64,1,CONCRETE:7)
Block(-6,64,2,STAINED_GLASS:15)
Block(-6,64,3,CONCRETE:7)
Block(-6,73,-7,CONCRETE:7)
Block(-6,73,-6,STAINED_GLASS:15)
Block(-6,73,-5,CONCRETE:7)
Block(-6,73,-4,STAINED_GLASS:15)
Block(-6,73,-3,CONCRETE:7)
Block(-6,73,-2,STAINED_GLASS:15)
Block(-6,73,-1,CONCRETE:7)
Block(-6,73,0,STAINED_GLASS:15)
Block(-6,73,1,CONCRETE:7)
Block(-6,74,-7,DARK_OAK_STAIRS:1)
Block(-6,74,-6,WALL_SIGN:3,NBT/skyscraper_2x2_03/42-signC0R16.nbt)
Block(-6,74,1,CONCRETE:7)
Block(-6,75,1,CONCRETE:7)
Block(-6,76,1,CONCRETE:7)
Block(-6,77,-7,CONCRETE:7)
Block(-6,77,-6,CONCRETE:7)
Block(-6,77,-5,CONCRETE:7)
Block(-6,77,-4,CONCRETE:7)
Block(-6,77,-3,CONCRETE:7)
Block(-6,77,-2,CONCRETE:7)
Block(-6,77,-1,CONCRETE:7)
Block(-6,77,0,CONCRETE:7)
Block(-6,77,1,CONCRETE:7)
Block(-6,77,2,STAINED_GLASS:15)
Block(-6,77,3,CONCRETE:7)
Block(-6,78,-6,DARK_OAK_STAIRS:1)
Block(-6,78,-1,CAULDRON:0)
Block(-6,78,0,CONCRETE:7)
Block(-6,78,1,CONCRETE:7)
Block(-6,78,2,CONCRETE:7)
Block(-6,78,3,CONCRETE:7)
Block(-6,79,-1,TRIPWIRE_HOOK:2)
Block(-6,79,0,CONCRETE:7)
Block(-6,79,1,CONCRETE:7)
Block(-6,79,2,CONCRETE:7)
Block(-6,79,3,CONCRETE:7)
Block(-6,80,-3,STAINED_GLASS:15)
Block(-6,80,-1,TRAP_DOOR:12)
Block(-6,80,0,CONCRETE:7)
Block(-6,80,1,CONCRETE:7)
Block(-6,80,2,CONCRETE:7)
Block(-6,80,3,CONCRETE:7)
Block(-6,81,-7,CONCRETE:7)
Block(-6,81,-6,STAINED_GLASS:15)
Block(-6,81,-5,CONCRETE:7)
Block(-6,81,-4,STAINED_GLASS:15)
Block(-6,81,-3,CONCRETE:7)
Block(-6,81,-2,STAINED_GLASS:15)
Block(-6,81,-1,CONCRETE:7)
Block(-6,81,0,STAINED_GLASS:15)
Block(-6,81,1,CONCRETE:7)
Block(-6,81,2,STAINED_GLASS:15)
Block(-6,81,3,CONCRETE:7)
Block(-5,0,-7,CONCRETE:7)
Block(-5,0,-6,CONCRETE:7)
Block(-5,0,-5,CONCRETE:7)
Block(-5,0,-4,CONCRETE:7)
Block(-5,0,-3,CONCRETE:7)
Block(-5,0,-2,CONCRETE:7)
Block(-5,0,-1,CONCRETE:7)
Block(-5,0,0,CONCRETE:7)
Block(-5,0,1,CONCRETE:7)
Block(-5,0,2,CONCRETE:7)
Block(-5,0,3,CONCRETE:7)
Block(-5,0,4,CONCRETE:7)
Block(-5,0,5,CONCRETE:7)
Block(-5,0,6,CONCRETE:7)
Block(-5,0,7,CONCRETE:7)
Block(-5,0,8,CONCRETE:7)
Block(-5,1,-7,CONCRETE:7)
Block(-5,1,-6,CONCRETE:7)
Block(-5,1,-5,CONCRETE:7)
Block(-5,1,-4,CONCRETE:7)
Block(-5,1,-3,CONCRETE:7)
Block(-5,1,-2,CONCRETE:7)
Block(-5,1,-1,CONCRETE:7)
Block(-5,1,0,CONCRETE:7)
Block(-5,1,1,CONCRETE:7)
Block(-5,1,2,CONCRETE:7)
Block(-5,1,3,CONCRETE:7)
Block(-5,1,4,CONCRETE:7)
Block(-5,1,5,CONCRETE:7)
Block(-5,1,6,CONCRETE:7)
Block(-5,1,7,CONCRETE:7)
Block(-5,1,8,CONCRETE:7)
Block(-5,2,-7,CONCRETE:7)
Block(-5,2,-6,CONCRETE:7)
Block(-5,2,-5,CONCRETE:7)
Block(-5,2,-4,CONCRETE:7)
Block(-5,2,-3,CONCRETE:7)
Block(-5,2,-2,CONCRETE:7)
Block(-5,2,-1,CONCRETE:7)
Block(-5,2,0,CONCRETE:7)
Block(-5,2,1,CONCRETE:7)
Block(-5,2,2,CONCRETE:7)
Block(-5,2,3,CONCRETE:7)
Block(-5,2,4,CONCRETE:7)
Block(-5,2,5,CONCRETE:7)
Block(-5,2,6,CONCRETE:7)
Block(-5,2,7,CONCRETE:7)
Block(-5,2,8,CONCRETE:7)
Block(-5,3,-7,CONCRETE:7)
Block(-5,3,-6,SMOOTH_STAIRS:1)
Block(-5,3,-5,SMOOTH_STAIRS:1)
Block(-5,3,-4,CONCRETE:7)
Block(-5,3,-3,SMOOTH_STAIRS:1)
Block(-5,3,-2,SMOOTH_STAIRS:1)
Block(-5,3,-1,CONCRETE:7)
Block(-5,3,0,SMOOTH_STAIRS:1)
Block(-5,3,1,SMOOTH_STAIRS:1)
Block(-5,3,2,CONCRETE:7)
Block(-5,3,3,SMOOTH_STAIRS:1)
Block(-5,3,4,SMOOTH_STAIRS:1)
Block(-5,3,5,CONCRETE:7)
Block(-5,3,6,SMOOTH_STAIRS:1)
Block(-5,3,7,SMOOTH_STAIRS:1)
Block(-5,3,8,CONCRETE:7)
Block(-5,4,-7,CONCRETE:7)
Block(-5,4,-6,COBBLE_WALL:0)
Block(-5,4,-5,COBBLE_WALL:0)
Block(-5,4,-4,CONCRETE:7)
Block(-5,4,-3,COBBLE_WALL:0)
Block(-5,4,-2,COBBLE_WALL:0)
Block(-5,4,-1,CONCRETE:7)
Block(-5,4,0,COBBLE_WALL:0)
Block(-5,4,1,COBBLE_WALL:0)
Block(-5,4,2,CONCRETE:7)
Block(-5,4,3,COBBLE_WALL:0)
Block(-5,4,4,COBBLE_WALL:0)
Block(-5,4,5,CONCRETE:7)
Block(-5,4,6,COBBLE_WALL:0)
Block(-5,4,7,COBBLE_WALL:0)
Block(-5,4,8,CONCRETE:7)
Block(-5,5,-7,CONCRETE:7)
Block(-5,5,-6,SMOOTH_STAIRS:5)
Block(-5,5,-5,SMOOTH_STAIRS:5)
Block(-5,5,-4,CONCRETE:7)
Block(-5,5,-3,SMOOTH_STAIRS:5)
Block(-5,5,-2,SMOOTH_STAIRS:5)
Block(-5,5,-1,CONCRETE:7)
Block(-5,5,0,SMOOTH_STAIRS:5)
Block(-5,5,1,SMOOTH_STAIRS:5)
Block(-5,5,2,CONCRETE:7)
Block(-5,5,3,SMOOTH_STAIRS:5)
Block(-5,5,4,SMOOTH_STAIRS:5)
Block(-5,5,5,CONCRETE:7)
Block(-5,5,6,SMOOTH_STAIRS:5)
Block(-5,5,7,SMOOTH_STAIRS:5)
Block(-5,5,8,CONCRETE:7)
Block(-5,6,-7,CONCRETE:7)
Block(-5,6,-6,CONCRETE:7)
Block(-5,6,-5,CONCRETE:7)
Block(-5,6,-4,CONCRETE:7)
Block(-5,6,-3,CONCRETE:7)
Block(-5,6,-2,CONCRETE:7)
Block(-5,6,-1,CONCRETE:7)
Block(-5,6,0,CONCRETE:7)
Block(-5,6,1,CONCRETE:7)
Block(-5,6,2,CONCRETE:7)
Block(-5,6,3,CONCRETE:7)
Block(-5,6,4,CONCRETE:7)
Block(-5,6,5,CONCRETE:7)
Block(-5,6,6,CONCRETE:7)
Block(-5,6,7,CONCRETE:7)
Block(-5,6,8,CONCRETE:7)
Block(-5,7,-7,CONCRETE:7)
Block(-5,7,-6,CONCRETE:7)
Block(-5,7,-5,CONCRETE:7)
Block(-5,7,-4,CONCRETE:7)
Block(-5,7,-3,CONCRETE:7)
Block(-5,7,-2,CONCRETE:7)
Block(-5,7,-1,CONCRETE:7)
Block(-5,7,0,CONCRETE:7)
Block(-5,7,1,CONCRETE:7)
Block(-5,7,2,CONCRETE:7)
Block(-5,7,3,CONCRETE:7)
Block(-5,7,4,CONCRETE:7)
Block(-5,7,5,CONCRETE:7)
Block(-5,7,6,CONCRETE:7)
Block(-5,7,7,CONCRETE:7)
Block(-5,7,8,CONCRETE:7)
Block(-5,8,-7,CONCRETE:7)
Block(-5,8,-6,CONCRETE:7)
Block(-5,8,-5,CONCRETE:7)
Block(-5,8,-4,CONCRETE:7)
Block(-5,8,-3,CONCRETE:7)
Block(-5,8,-2,CONCRETE:7)
Block(-5,8,-1,CONCRETE:7)
Block(-5,8,0,CONCRETE:7)
Block(-5,8,1,CONCRETE:7)
Block(-5,8,2,CONCRETE:7)
Block(-5,8,3,CONCRETE:7)
Block(-5,8,4,CONCRETE:7)
Block(-5,8,5,CONCRETE:7)
Block(-5,8,6,CONCRETE:7)
Block(-5,8,7,CONCRETE:7)
Block(-5,8,8,CONCRETE:7)
Block(-5,9,-7,CONCRETE:7)
Block(-5,9,-6,CONCRETE:7)
Block(-5,9,-5,CONCRETE:7)
Block(-5,9,-4,CONCRETE:7)
Block(-5,9,-3,CONCRETE:7)
Block(-5,9,-2,CONCRETE:7)
Block(-5,9,-1,CONCRETE:7)
Block(-5,9,0,CONCRETE:7)
Block(-5,9,1,CONCRETE:7)
Block(-5,9,2,CONCRETE:7)
Block(-5,9,3,CONCRETE:7)
Block(-5,9,4,CONCRETE:7)
Block(-5,9,5,CONCRETE:7)
Block(-5,9,6,CONCRETE:7)
Block(-5,9,7,CONCRETE:7)
Block(-5,9,8,CONCRETE:7)
Block(-5,10,-7,CONCRETE:7)
Block(-5,10,-6,CONCRETE:7)
Block(-5,10,-5,CONCRETE:7)
Block(-5,10,-4,CONCRETE:7)
Block(-5,10,-3,CONCRETE:7)
Block(-5,10,-2,CONCRETE:7)
Block(-5,10,-1,CONCRETE:7)
Block(-5,10,0,CONCRETE:7)
Block(-5,10,1,CONCRETE:7)
Block(-5,10,2,CONCRETE:7)
Block(-5,10,3,CONCRETE:7)
Block(-5,10,4,CONCRETE:7)
Block(-5,10,5,CONCRETE:7)
Block(-5,10,6,CONCRETE:7)
Block(-5,10,7,CONCRETE:7)
Block(-5,10,8,CONCRETE:7)
Block(-5,11,-7,CONCRETE:7)
Block(-5,11,-6,CONCRETE:7)
Block(-5,11,-5,CONCRETE:7)
Block(-5,11,-4,CONCRETE:7)
Block(-5,11,-3,CONCRETE:7)
Block(-5,11,-2,CONCRETE:7)
Block(-5,11,-1,CONCRETE:7)
Block(-5,11,0,CONCRETE:7)
Block(-5,11,1,CONCRETE:7)
Block(-5,11,2,CONCRETE:7)
Block(-5,11,3,CONCRETE:7)
Block(-5,11,4,CONCRETE:7)
Block(-5,11,5,CONCRETE:7)
Block(-5,11,6,CONCRETE:7)
Block(-5,11,7,CONCRETE:7)
Block(-5,11,8,CONCRETE:7)
Block(-5,12,-7,CONCRETE:7)
Block(-5,12,-6,CONCRETE:7)
Block(-5,12,-5,CONCRETE:8)
Block(-5,12,-4,CONCRETE:8)
Block(-5,12,-3,CONCRETE:8)
Block(-5,12,-2,CONCRETE:8)
Block(-5,12,-1,CONCRETE:8)
Block(-5,12,0,CONCRETE:8)
Block(-5,12,1,CONCRETE:8)
Block(-5,12,2,CONCRETE:8)
Block(-5,12,3,CONCRETE:8)
Block(-5,12,4,CONCRETE:8)
Block(-5,12,5,CONCRETE:8)
Block(-5,12,6,CONCRETE:8)
Block(-5,12,7,CONCRETE:8)
Block(-5,12,8,CONCRETE:7)
Block(-5,13,-7,CONCRETE:7)
Block(-5,13,-6,CONCRETE:7)
Block(-5,13,-5,CONCRETE:8)
Block(-5,13,-4,CONCRETE:8)
Block(-5,13,-3,CONCRETE:8)
Block(-5,13,-2,CONCRETE:8)
Block(-5,13,-1,CONCRETE:8)
Block(-5,13,0,CONCRETE:8)
Block(-5,13,1,CONCRETE:8)
Block(-5,13,2,CONCRETE:8)
Block(-5,13,3,CONCRETE:8)
Block(-5,13,4,CONCRETE:8)
Block(-5,13,5,CONCRETE:8)
Block(-5,13,6,CONCRETE:8)
Block(-5,13,7,CONCRETE:8)
Block(-5,13,8,CONCRETE:7)
Block(-5,14,-7,CONCRETE:7)
Block(-5,14,-6,CONCRETE:7)
Block(-5,14,-5,CONCRETE:8)
Block(-5,14,-4,CONCRETE:8)
Block(-5,14,-3,CONCRETE:8)
Block(-5,14,-2,CONCRETE:8)
Block(-5,14,-1,CONCRETE:8)
Block(-5,14,0,CONCRETE:8)
Block(-5,14,1,CONCRETE:8)
Block(-5,14,2,CONCRETE:8)
Block(-5,14,3,CONCRETE:8)
Block(-5,14,4,CONCRETE:8)
Block(-5,14,5,CONCRETE:8)
Block(-5,14,6,CONCRETE:8)
Block(-5,14,7,CONCRETE:8)
Block(-5,14,8,CONCRETE:7)
Block(-5,15,-7,CONCRETE:7)
Block(-5,15,-6,CONCRETE:7)
Block(-5,15,-5,CONCRETE:8)
Block(-5,15,-4,CONCRETE:8)
Block(-5,15,-3,CONCRETE:8)
Block(-5,15,-2,CONCRETE:8)
Block(-5,15,-1,CONCRETE:8)
Block(-5,15,0,CONCRETE:8)
Block(-5,15,1,CONCRETE:8)
Block(-5,15,2,CONCRETE:8)
Block(-5,15,3,CONCRETE:8)
Block(-5,15,4,CONCRETE:8)
Block(-5,15,5,CONCRETE:8)
Block(-5,15,6,CONCRETE:8)
Block(-5,15,7,CONCRETE:8)
Block(-5,15,8,CONCRETE:7)
Block(-5,16,-7,CONCRETE:7)
Block(-5,16,-6,CONCRETE:7)
Block(-5,16,-5,CONCRETE:7)
Block(-5,16,-4,CONCRETE:7)
Block(-5,16,-3,CONCRETE:7)
Block(-5,16,-2,CONCRETE:7)
Block(-5,16,-1,CONCRETE:7)
Block(-5,16,0,CONCRETE:7)
Block(-5,16,1,CONCRETE:7)
Block(-5,16,2,CONCRETE:7)
Block(-5,16,3,CONCRETE:7)
Block(-5,16,4,CONCRETE:7)
Block(-5,16,5,CONCRETE:7)
Block(-5,16,6,CONCRETE:7)
Block(-5,16,7,CONCRETE:7)
Block(-5,16,8,CONCRETE:7)
Block(-5,17,-7,CONCRETE:8)
Block(-5,17,-6,CONCRETE:8)
Block(-5,17,-5,CONCRETE:8)
Block(-5,17,-4,CONCRETE:8)
Block(-5,17,-3,CONCRETE:8)
Block(-5,17,-2,CONCRETE:7)
Block(-5,17,-1,CONCRETE:7)
Block(-5,17,0,CONCRETE:7)
Block(-5,17,1,CONCRETE:7)
Block(-5,17,2,CONCRETE:7)
Block(-5,17,3,CONCRETE:7)
Block(-5,17,4,CONCRETE:7)
Block(-5,17,5,CONCRETE:7)
Block(-5,17,6,CONCRETE:7)
Block(-5,17,7,CONCRETE:7)
Block(-5,17,8,CONCRETE:7)
Block(-5,18,-7,STAINED_GLASS_PANE:15)
Block(-5,18,-6,STAINED_GLASS_PANE:15)
Block(-5,18,-5,STAINED_GLASS_PANE:15)
Block(-5,18,-4,STAINED_GLASS_PANE:15)
Block(-5,18,-3,STAINED_GLASS_PANE:15)
Block(-5,18,4,CONCRETE:8)
Block(-5,18,5,CONCRETE:8)
Block(-5,19,-7,STAINED_GLASS_PANE:15)
Block(-5,19,-6,STAINED_GLASS_PANE:15)
Block(-5,19,-5,STAINED_GLASS_PANE:15)
Block(-5,19,-4,STAINED_GLASS_PANE:15)
Block(-5,19,-3,STAINED_GLASS_PANE:15)
Block(-5,19,4,CONCRETE:8)
Block(-5,19,5,CONCRETE:8)
Block(-5,20,4,CONCRETE:8)
Block(-5,20,5,CONCRETE:8)
Block(-5,21,4,CONCRETE:8)
Block(-5,21,5,CONCRETE:8)
Block(-5,22,4,CONCRETE:8)
Block(-5,22,5,CONCRETE:8)
Block(-5,23,4,CONCRETE:8)
Block(-5,23,5,CONCRETE:8)
Block(-5,24,4,CONCRETE:8)
Block(-5,24,5,CONCRETE:8)
Block(-5,25,4,CONCRETE:8)
Block(-5,25,5,CONCRETE:8)
Block(-5,26,-7,STAINED_GLASS:15)
Block(-5,26,-6,CONCRETE:7)
Block(-5,26,-5,STAINED_GLASS:15)
Block(-5,26,-4,CONCRETE:7)
Block(-5,26,-3,STAINED_GLASS:15)
Block(-5,26,-2,CONCRETE:7)
Block(-5,26,-1,STAINED_GLASS:15)
Block(-5,26,0,STAINED_GLASS:15)
Block(-5,26,1,STAINED_GLASS:15)
Block(-5,26,2,STAINED_GLASS:15)
Block(-5,26,3,STAINED_GLASS:15)
Block(-5,26,4,CONCRETE:8)
Block(-5,26,5,CONCRETE:8)
Block(-5,27,-7,QUARTZ_STAIRS:6)
Block(-5,27,-5,QUARTZ_STAIRS:7)
Block(-5,27,-4,STANDING_BANNER:4,NBT/skyscraper_2x2_03/46-bannerC0R16.nbt)
Block(-5,27,-3,QUARTZ_STAIRS:6)
Block(-5,27,4,CONCRETE:8)
Block(-5,27,5,CONCRETE:8)
Block(-5,28,-7,IRON_TRAPDOOR:2)
Block(-5,28,-6,WALL_BANNER:3,NBT/skyscraper_2x2_03/47-bannerC0R16.nbt)
Block(-5,28,-5,IRON_TRAPDOOR:0)
Block(-5,28,-4,IRON_TRAPDOOR:0)
Block(-5,28,-3,IRON_TRAPDOOR:2)
Block(-5,28,-2,WALL_BANNER:3,NBT/skyscraper_2x2_03/48-bannerC0R16.nbt)
Block(-5,28,4,CONCRETE:8)
Block(-5,28,5,CONCRETE:8)
Block(-5,29,4,CONCRETE:8)
Block(-5,29,5,CONCRETE:8)
Block(-5,30,4,CONCRETE:8)
Block(-5,30,5,CONCRETE:8)
Block(-5,31,4,CONCRETE:8)
Block(-5,31,5,CONCRETE:8)
Block(-5,32,4,CONCRETE:8)
Block(-5,32,5,CONCRETE:8)
Block(-5,33,4,CONCRETE:8)
Block(-5,33,5,CONCRETE:8)
Block(-5,34,4,CONCRETE:8)
Block(-5,34,5,CONCRETE:8)
Block(-5,35,4,CONCRETE:8)
Block(-5,35,5,CONCRETE:8)
Block(-5,36,4,CONCRETE:8)
Block(-5,36,5,CONCRETE:8)
Block(-5,37,-7,CONCRETE:7)
Block(-5,37,-6,CONCRETE:7)
Block(-5,37,-5,STAINED_GLASS:15)
Block(-5,37,-4,CONCRETE:7)
Block(-5,37,-3,STAINED_GLASS:15)
Block(-5,37,-2,CONCRETE:7)
Block(-5,37,-1,CONCRETE:7)
Block(-5,37,0,CONCRETE:7)
Block(-5,37,1,CONCRETE:7)
Block(-5,37,2,CONCRETE:7)
Block(-5,37,4,CONCRETE:8)
Block(-5,37,5,CONCRETE:8)
Block(-5,38,-7,STANDING_BANNER:5,NBT/skyscraper_2x2_03/53-bannerC0R16.nbt)
Block(-5,38,-6,QUARTZ_STAIRS:6)
Block(-5,38,1,CONCRETE:7)
Block(-5,38,2,CONCRETE:7)
Block(-5,38,4,CONCRETE:8)
Block(-5,38,5,CONCRETE:8)
Block(-5,39,-7,IRON_TRAPDOOR:1)
Block(-5,39,-6,IRON_TRAPDOOR:2)
Block(-5,39,1,CONCRETE:7)
Block(-5,39,2,CONCRETE:7)
Block(-5,39,4,CONCRETE:8)
Block(-5,39,5,CONCRETE:8)
Block(-5,40,0,DARK_OAK_STAIRS:6)
Block(-5,40,1,CONCRETE:7)
Block(-5,40,2,CONCRETE:7)
Block(-5,40,3,CONCRETE:7)
Block(-5,40,4,CONCRETE:8)
Block(-5,40,5,CONCRETE:8)
Block(-5,41,-1,DARK_OAK_STAIRS:6)
Block(-5,41,0,DARK_OAK_STAIRS:3)
Block(-5,41,3,CONCRETE:7)
Block(-5,41,4,CONCRETE:8)
Block(-5,41,5,CONCRETE:8)
Block(-5,42,-7,STAINED_GLASS:15)
Block(-5,42,-6,CONCRETE:7)
Block(-5,42,-5,STAINED_GLASS:15)
Block(-5,42,-4,CONCRETE:7)
Block(-5,42,-3,STAINED_GLASS:15)
Block(-5,42,-2,CONCRETE:7)
Block(-5,42,-1,DARK_OAK_STAIRS:3)
Block(-5,42,3,CONCRETE:7)
Block(-5,42,4,CONCRETE:7)
Block(-5,42,5,CONCRETE:7)
Block(-5,42,6,CONCRETE:7)
Block(-5,42,7,CONCRETE:7)
Block(-5,42,8,CONCRETE:7)
Block(-5,43,3,CONCRETE:7)
Block(-5,43,5,QUARTZ_STAIRS:7)
Block(-5,43,6,STANDING_BANNER:4,NBT/skyscraper_2x2_03/54-bannerC0R16.nbt)
Block(-5,43,7,QUARTZ_STAIRS:6)
Block(-5,43,8,CONCRETE:7)
Block(-5,44,-7,WALL_BANNER:5,NBT/skyscraper_2x2_03/59-bannerC0R16.nbt)
Block(-5,44,-6,WALL_BANNER:5,NBT/skyscraper_2x2_03/60-bannerC0R16.nbt)
Block(-5,44,-4,WALL_BANNER:5,NBT/skyscraper_2x2_03/61-bannerC0R16.nbt)
Block(-5,44,3,CONCRETE:7)
Block(-5,44,4,WALL_BANNER:2,NBT/skyscraper_2x2_03/62-bannerC0R16.nbt)
Block(-5,44,5,IRON_TRAPDOOR:0)
Block(-5,44,6,IRON_TRAPDOOR:0)
Block(-5,44,7,IRON_TRAPDOOR:0)
Block(-5,44,8,CONCRETE:7)
Block(-5,45,-2,CONCRETE:7)
Block(-5,45,-1,STAINED_GLASS:15)
Block(-5,45,0,STAINED_GLASS:15)
Block(-5,45,1,STAINED_GLASS:15)
Block(-5,45,2,STAINED_GLASS:15)
Block(-5,45,3,CONCRETE:7)
Block(-5,45,8,CONCRETE:7)
Block(-5,46,-2,CONCRETE:7)
Block(-5,46,3,CONCRETE:7)
Block(-5,46,4,CONCRETE:7)
Block(-5,46,5,CONCRETE:7)
Block(-5,46,6,CONCRETE:7)
Block(-5,46,7,CONCRETE:7)
Block(-5,46,8,CONCRETE:7)
Block(-5,47,-2,CONCRETE:7)
Block(-5,47,3,CONCRETE:7)
Block(-5,47,5,QUARTZ_STAIRS:7)
Block(-5,47,6,STANDING_BANNER:4,NBT/skyscraper_2x2_03/65-bannerC0R16.nbt)
Block(-5,47,7,QUARTZ_STAIRS:6)
Block(-5,47,8,CONCRETE:7)
Block(-5,48,-7,STAINED_GLASS:15)
Block(-5,48,-6,CONCRETE:7)
Block(-5,48,-5,STAINED_GLASS:15)
Block(-5,48,-4,CONCRETE:7)
Block(-5,48,-3,STAINED_GLASS:15)
Block(-5,48,-2,CONCRETE:7)
Block(-5,48,3,CONCRETE:7)
Block(-5,48,4,WALL_BANNER:2,NBT/skyscraper_2x2_03/69-bannerC0R16.nbt)
Block(-5,48,5,IRON_TRAPDOOR:0)
Block(-5,48,6,IRON_TRAPDOOR:0)
Block(-5,48,7,IRON_TRAPDOOR:0)
Block(-5,48,8,CONCRETE:7)
Block(-5,49,3,CONCRETE:7)
Block(-5,49,8,CONCRETE:7)
Block(-5,50,3,CONCRETE:7)
Block(-5,50,8,CONCRETE:7)
Block(-5,51,3,CONCRETE:7)
Block(-5,51,8,CONCRETE:7)
Block(-5,52,3,CONCRETE:7)
Block(-5,52,8,CONCRETE:7)
Block(-5,53,3,CONCRETE:7)
Block(-5,53,4,CONCRETE:7)
Block(-5,53,5,CONCRETE:7)
Block(-5,53,6,CONCRETE:7)
Block(-5,53,7,CONCRETE:7)
Block(-5,53,8,CONCRETE:7)
Block(-5,57,-2,CONCRETE:7)
Block(-5,57,-1,CONCRETE:7)
Block(-5,57,0,CONCRETE:7)
Block(-5,57,1,CONCRETE:7)
Block(-5,57,2,CONCRETE:7)
Block(-5,57,3,STAINED_GLASS:15)
Block(-5,58,-2,CONCRETE:7)
Block(-5,58,-1,STAINED_GLASS:15)
Block(-5,58,0,STAINED_GLASS:15)
Block(-5,58,1,STAINED_GLASS:15)
Block(-5,58,2,STAINED_GLASS:15)
Block(-5,58,3,STAINED_GLASS:15)
Block(-5,59,-2,CONCRETE:7)
Block(-5,59,3,STAINED_GLASS:15)
Block(-5,60,-2,CONCRETE:7)
Block(-5,60,3,STAINED_GLASS:15)
Block(-5,61,-2,CONCRETE:7)
Block(-5,61,3,STAINED_GLASS:15)
Block(-5,62,-2,CONCRETE:7)
Block(-5,62,3,STAINED_GLASS:15)
Block(-5,63,-2,CONCRETE:7)
Block(-5,63,3,STAINED_GLASS:15)
Block(-5,64,-2,CONCRETE:7)
Block(-5,64,-1,CONCRETE:7)
Block(-5,64,0,CONCRETE:7)
Block(-5,64,1,CONCRETE:7)
Block(-5,64,2,CONCRETE:7)
Block(-5,64,3,STAINED_GLASS:15)
Block(-5,65,-1,CONCRETE:7)
Block(-5,65,0,CONCRETE:7)
Block(-5,66,-1,CONCRETE:7)
Block(-5,66,0,CONCRETE:7)
Block(-5,67,-1,CONCRETE:7)
Block(-5,67,0,CONCRETE:7)
Block(-5,68,-1,CONCRETE:7)
Block(-5,68,0,CONCRETE:7)
Block(-5,69,-1,CONCRETE:7)
Block(-5,69,0,CONCRETE:7)
Block(-5,70,-1,CONCRETE:7)
Block(-5,70,0,CONCRETE:7)
Block(-5,71,-1,CONCRETE:7)
Block(-5,71,0,CONCRETE:7)
Block(-5,72,-1,CONCRETE:7)
Block(-5,72,0,CONCRETE:7)
Block(-5,73,-7,CONCRETE:7)
Block(-5,73,-6,STAINED_GLASS:15)
Block(-5,73,-5,CONCRETE:7)
Block(-5,73,-4,STAINED_GLASS:15)
Block(-5,73,-3,CONCRETE:7)
Block(-5,73,-2,STAINED_GLASS:15)
Block(-5,73,-1,CONCRETE:7)
Block(-5,73,0,STAINED_GLASS:15)
Block(-5,73,1,CONCRETE:7)
Block(-5,74,-4,DARK_OAK_STAIRS:2)
Block(-5,74,-3,DARK_OAK_STAIRS:0)
Block(-5,74,-2,DARK_OAK_STAIRS:0)
Block(-5,74,-1,DARK_OAK_STAIRS:0)
Block(-5,74,0,DARK_OAK_STAIRS:0)
Block(-5,74,1,CONCRETE:7)
Block(-5,75,1,CONCRETE:7)
Block(-5,76,1,CONCRETE:7)
Block(-5,77,-7,CONCRETE:7)
Block(-5,77,-6,CONCRETE:7)
Block(-5,77,-5,CONCRETE:7)
Block(-5,77,-4,CONCRETE:7)
Block(-5,77,-3,CONCRETE:7)
Block(-5,77,-2,CONCRETE:7)
Block(-5,77,-1,CONCRETE:7)
Block(-5,77,0,CONCRETE:7)
Block(-5,77,1,CONCRETE:7)
Block(-5,77,2,STAINED_GLASS:15)
Block(-5,77,3,CONCRETE:7)
Block(-5,78,-6,DARK_OAK_STAIRS:2)
Block(-5,78,-3,STAINED_GLASS:15)
Block(-5,78,-1,BIRCH_DOOR:3)
Block(-5,78,1,STEP:0)
Block(-5,78,2,DROPPER:1,NBT/skyscraper_2x2_03/73-dropperC0R16.nbt)
Block(-5,78,3,CONCRETE:7)
Block(-5,79,-3,STAINED_GLASS:15)
Block(-5,79,-1,BIRCH_DOOR:9)
Block(-5,79,0,WALL_BANNER:4,NBT/skyscraper_2x2_03/74-bannerC0R16.nbt)
Block(-5,79,2,TRAP_DOOR:4)
Block(-5,79,3,CONCRETE:7)
Block(-5,80,-5,IRON_TRAPDOOR:11)
Block(-5,80,-3,STAINED_GLASS:15)
Block(-5,80,-1,TRAP_DOOR:12)
Block(-5,80,0,WALL_BANNER:4,NBT/skyscraper_2x2_03/75-bannerC0R16.nbt)
Block(-5,80,2,WALL_BANNER:4,NBT/skyscraper_2x2_03/76-bannerC0R16.nbt)
Block(-5,80,3,CONCRETE:7)
Block(-5,81,-7,CONCRETE:7)
Block(-5,81,-6,STAINED_GLASS:15)
Block(-5,81,-5,CONCRETE:7)
Block(-5,81,-4,STAINED_GLASS:15)
Block(-5,81,-3,CONCRETE:7)
Block(-5,81,-2,STAINED_GLASS:15)
Block(-5,81,-1,CONCRETE:7)
Block(-5,81,0,STAINED_GLASS:15)
Block(-5,81,1,CONCRETE:7)
Block(-5,81,2,STAINED_GLASS:15)
Block(-5,81,3,CONCRETE:7)
Block(-4,0,-7,CONCRETE:7)
Block(-4,0,-6,CONCRETE:7)
Block(-4,0,-5,CONCRETE:7)
Block(-4,0,-4,CONCRETE:7)
Block(-4,0,-3,CONCRETE:7)
Block(-4,0,-2,CONCRETE:7)
Block(-4,0,-1,CONCRETE:7)
Block(-4,0,0,CONCRETE:7)
Block(-4,0,1,CONCRETE:7)
Block(-4,0,2,CONCRETE:7)
Block(-4,0,3,CONCRETE:7)
Block(-4,0,4,CONCRETE:7)
Block(-4,0,5,CONCRETE:7)
Block(-4,0,6,CONCRETE:7)
Block(-4,0,7,CONCRETE:7)
Block(-4,0,8,CONCRETE:7)
Block(-4,2,-7,IRON_TRAPDOOR:9)
Block(-4,2,-6,IRON_TRAPDOOR:9)
Block(-4,2,-5,IRON_TRAPDOOR:9)
Block(-4,2,-4,IRON_TRAPDOOR:9)
Block(-4,2,-3,IRON_TRAPDOOR:9)
Block(-4,2,-2,IRON_TRAPDOOR:9)
Block(-4,2,-1,IRON_TRAPDOOR:9)
Block(-4,2,0,IRON_TRAPDOOR:9)
Block(-4,2,1,IRON_TRAPDOOR:9)
Block(-4,2,2,IRON_TRAPDOOR:9)
Block(-4,2,3,IRON_TRAPDOOR:9)
Block(-4,2,4,IRON_TRAPDOOR:9)
Block(-4,2,5,IRON_TRAPDOOR:9)
Block(-4,2,6,IRON_TRAPDOOR:9)
Block(-4,2,7,IRON_TRAPDOOR:9)
Block(-4,2,8,IRON_TRAPDOOR:9)
Block(-4,3,-7,CONCRETE:4)
Block(-4,3,-6,CONCRETE:4)
Block(-4,3,-5,CONCRETE:4)
Block(-4,3,-4,CONCRETE:4)
Block(-4,3,-3,CONCRETE:4)
Block(-4,3,-2,CONCRETE:4)
Block(-4,3,-1,CONCRETE:4)
Block(-4,3,0,CONCRETE:4)
Block(-4,3,1,CONCRETE:4)
Block(-4,3,2,CONCRETE:4)
Block(-4,3,3,CONCRETE:4)
Block(-4,3,4,CONCRETE:4)
Block(-4,3,5,CONCRETE:4)
Block(-4,3,6,CONCRETE:4)
Block(-4,3,7,CONCRETE:4)
Block(-4,3,8,CONCRETE:4)
Block(-4,5,-7,SMOOTH_STAIRS:5)
Block(-4,5,-4,SMOOTH_STAIRS:5)
Block(-4,5,-1,SMOOTH_STAIRS:5)
Block(-4,5,2,SMOOTH_STAIRS:5)
Block(-4,5,5,SMOOTH_STAIRS:5)
Block(-4,5,8,SMOOTH_STAIRS:5)
Block(-4,6,-7,CONCRETE:7)
Block(-4,6,-6,CONCRETE:7)
Block(-4,6,-5,CONCRETE:7)
Block(-4,6,-4,CONCRETE:7)
Block(-4,6,-3,CONCRETE:7)
Block(-4,6,-2,CONCRETE:7)
Block(-4,6,-1,CONCRETE:7)
Block(-4,6,0,CONCRETE:7)
Block(-4,6,1,CONCRETE:7)
Block(-4,6,2,CONCRETE:7)
Block(-4,6,3,CONCRETE:7)
Block(-4,6,4,CONCRETE:7)
Block(-4,6,5,CONCRETE:7)
Block(-4,6,6,CONCRETE:7)
Block(-4,6,7,CONCRETE:7)
Block(-4,6,8,CONCRETE:7)
Block(-4,7,-7,CONCRETE:7)
Block(-4,7,-6,CONCRETE:7)
Block(-4,7,-5,CONCRETE:7)
Block(-4,7,-4,CONCRETE:7)
Block(-4,7,-3,CONCRETE:7)
Block(-4,7,-2,CONCRETE:7)
Block(-4,7,-1,CONCRETE:7)
Block(-4,7,0,CONCRETE:7)
Block(-4,7,1,CONCRETE:7)
Block(-4,7,2,CONCRETE:7)
Block(-4,7,3,CONCRETE:7)
Block(-4,7,4,CONCRETE:7)
Block(-4,7,5,CONCRETE:7)
Block(-4,7,6,CONCRETE:7)
Block(-4,7,7,CONCRETE:7)
Block(-4,7,8,CONCRETE:7)
Block(-4,8,-6,CONCRETE:7)
Block(-4,8,-5,CONCRETE:7)
Block(-4,8,-4,CONCRETE:7)
Block(-4,8,-3,CONCRETE:7)
Block(-4,8,-2,CONCRETE:7)
Block(-4,8,-1,CONCRETE:7)
Block(-4,8,0,CONCRETE:7)
Block(-4,8,1,CONCRETE:7)
Block(-4,8,2,CONCRETE:7)
Block(-4,8,3,CONCRETE:7)
Block(-4,8,4,CONCRETE:7)
Block(-4,8,5,CONCRETE:7)
Block(-4,8,6,CONCRETE:7)
Block(-4,8,7,CONCRETE:7)
Block(-4,8,8,CONCRETE:7)
Block(-4,9,-6,CONCRETE:7)
Block(-4,9,-5,CONCRETE:7)
Block(-4,9,-4,CONCRETE:7)
Block(-4,9,-3,CONCRETE:7)
Block(-4,9,-2,CONCRETE:7)
Block(-4,9,-1,CONCRETE:7)
Block(-4,9,0,CONCRETE:7)
Block(-4,9,1,CONCRETE:7)
Block(-4,9,2,CONCRETE:7)
Block(-4,9,3,CONCRETE:7)
Block(-4,9,4,CONCRETE:7)
Block(-4,9,5,CONCRETE:7)
Block(-4,9,6,CONCRETE:7)
Block(-4,9,7,CONCRETE:7)
Block(-4,9,8,CONCRETE:7)
Block(-4,10,-6,CONCRETE:7)
Block(-4,10,-5,CONCRETE:7)
Block(-4,10,-4,CONCRETE:7)
Block(-4,10,-3,CONCRETE:7)
Block(-4,10,-2,CONCRETE:7)
Block(-4,10,-1,CONCRETE:7)
Block(-4,10,0,CONCRETE:7)
Block(-4,10,1,CONCRETE:7)
Block(-4,10,2,CONCRETE:7)
Block(-4,10,3,CONCRETE:7)
Block(-4,10,4,CONCRETE:7)
Block(-4,10,5,CONCRETE:7)
Block(-4,10,6,CONCRETE:7)
Block(-4,10,7,CONCRETE:7)
Block(-4,10,8,CONCRETE:7)
Block(-4,11,-7,CONCRETE:7)
Block(-4,11,-6,CONCRETE:7)
Block(-4,11,-5,CONCRETE:7)
Block(-4,11,-4,CONCRETE:7)
Block(-4,11,-3,CONCRETE:7)
Block(-4,11,-2,CONCRETE:7)
Block(-4,11,-1,CONCRETE:7)
Block(-4,11,0,CONCRETE:7)
Block(-4,11,1,CONCRETE:7)
Block(-4,11,2,CONCRETE:7)
Block(-4,11,3,CONCRETE:7)
Block(-4,11,4,CONCRETE:7)
Block(-4,11,5,CONCRETE:7)
Block(-4,11,6,CONCRETE:7)
Block(-4,11,7,CONCRETE:7)
Block(-4,11,8,CONCRETE:7)
Block(-4,12,-7,CONCRETE:7)
Block(-4,12,-6,CONCRETE:7)
Block(-4,12,-5,CONCRETE:8)
Block(-4,12,-4,DARK_OAK_STAIRS:3)
Block(-4,12,-3,DARK_OAK_STAIRS:1)
Block(-4,12,-2,WALL_SIGN:3,NBT/skyscraper_2x2_03/77-signC0R16.nbt)
Block(-4,12,-1,SMOOTH_BRICK:3)
Block(-4,12,2,SMOOTH_BRICK:3)
Block(-4,12,3,WALL_SIGN:2,NBT/skyscraper_2x2_03/78-signC0R16.nbt)
Block(-4,12,4,DARK_OAK_STAIRS:1)
Block(-4,12,5,DARK_OAK_STAIRS:1)
Block(-4,12,6,DARK_OAK_STAIRS:2)
Block(-4,12,7,CONCRETE:8)
Block(-4,12,8,CONCRETE:7)
Block(-4,13,-7,CONCRETE:7)
Block(-4,13,-6,CONCRETE:7)
Block(-4,13,-5,CONCRETE:8)
Block(-4,13,-1,FLOWER_POT:0,NBT/skyscraper_2x2_03/79-flower_potC0R16.nbt)
Block(-4,13,2,FLOWER_POT:0,NBT/skyscraper_2x2_03/80-flower_potC0R16.nbt)
Block(-4,13,7,CONCRETE:8)
Block(-4,13,8,CONCRETE:7)
Block(-4,14,-7,CONCRETE:7)
Block(-4,14,-6,CONCRETE:7)
Block(-4,14,-5,CONCRETE:8)
Block(-4,14,-1,LEAVES:12)
Block(-4,14,2,LEAVES:12)
Block(-4,14,7,CONCRETE:8)
Block(-4,14,8,CONCRETE:7)
Block(-4,15,-7,CONCRETE:7)
Block(-4,15,-6,CONCRETE:7)
Block(-4,15,-5,CONCRETE:8)
Block(-4,15,7,CONCRETE:8)
Block(-4,15,8,CONCRETE:7)
Block(-4,16,-7,CONCRETE:7)
Block(-4,16,-6,CONCRETE:7)
Block(-4,16,-5,CONCRETE:7)
Block(-4,16,-4,CONCRETE:7)
Block(-4,16,-3,CONCRETE:7)
Block(-4,16,-2,CONCRETE:7)
Block(-4,16,-1,CONCRETE:7)
Block(-4,16,0,CONCRETE:7)
Block(-4,16,1,CONCRETE:7)
Block(-4,16,2,CONCRETE:7)
Block(-4,16,3,CONCRETE:7)
Block(-4,16,4,CONCRETE:7)
Block(-4,16,5,CONCRETE:7)
Block(-4,16,6,CONCRETE:7)
Block(-4,16,7,CONCRETE:7)
Block(-4,16,8,CONCRETE:7)
Block(-4,17,-7,CONCRETE:7)
Block(-4,17,-6,CONCRETE:7)
Block(-4,17,-5,CONCRETE:7)
Block(-4,17,-4,CONCRETE:7)
Block(-4,17,-3,CONCRETE:7)
Block(-4,17,-2,CONCRETE:7)
Block(-4,17,-1,CONCRETE:7)
Block(-4,17,0,CONCRETE:7)
Block(-4,17,1,CONCRETE:7)
Block(-4,17,2,CONCRETE:7)
Block(-4,17,3,CONCRETE:7)
Block(-4,17,4,CONCRETE:7)
Block(-4,17,5,CONCRETE:7)
Block(-4,17,6,CONCRETE:7)
Block(-4,17,7,CONCRETE:7)
Block(-4,17,8,CONCRETE:7)
Block(-4,18,6,CONCRETE:8)
Block(-4,19,6,CONCRETE:8)
Block(-4,20,6,CONCRETE:8)
Block(-4,21,6,CONCRETE:8)
Block(-4,22,6,CONCRETE:8)
Block(-4,23,6,CONCRETE:8)
Block(-4,24,6,CONCRETE:8)
Block(-4,25,6,CONCRETE:8)
Block(-4,26,-7,STAINED_GLASS:15)
Block(-4,26,-6,CONCRETE:7)
Block(-4,26,-5,STAINED_GLASS:15)
Block(-4,26,-4,CONCRETE:7)
Block(-4,26,-3,STAINED_GLASS:15)
Block(-4,26,-2,CONCRETE:7)
Block(-4,26,-1,STAINED_GLASS:15)
Block(-4,26,0,STAINED_GLASS:15)
Block(-4,26,1,STAINED_GLASS:15)
Block(-4,26,2,STAINED_GLASS:15)
Block(-4,26,3,STAINED_GLASS:15)
Block(-4,26,4,STAINED_GLASS:15)
Block(-4,26,5,STAINED_GLASS:15)
Block(-4,26,6,CONCRETE:8)
Block(-4,27,6,CONCRETE:8)
Block(-4,28,-7,WALL_BANNER:5,NBT/skyscraper_2x2_03/83-bannerC0R16.nbt)
Block(-4,28,-5,WALL_BANNER:5,NBT/skyscraper_2x2_03/84-bannerC0R16.nbt)
Block(-4,28,-4,WALL_BANNER:5,NBT/skyscraper_2x2_03/85-bannerC0R16.nbt)
Block(-4,28,-3,WALL_BANNER:5,NBT/skyscraper_2x2_03/86-bannerC0R16.nbt)
Block(-4,28,6,CONCRETE:8)
Block(-4,29,6,CONCRETE:8)
Block(-4,30,6,CONCRETE:8)
Block(-4,31,6,CONCRETE:8)
Block(-4,32,6,CONCRETE:8)
Block(-4,33,6,CONCRETE:8)
Block(-4,34,6,CONCRETE:8)
Block(-4,35,6,CONCRETE:8)
Block(-4,36,6,CONCRETE:8)
Block(-4,37,-7,STAINED_GLASS_PANE:15)
Block(-4,37,-6,STAINED_GLASS_PANE:15)
Block(-4,37,-5,STAINED_GLASS_PANE:15)
Block(-4,37,-4,CONCRETE:7)
Block(-4,37,-3,STAINED_GLASS:15)
Block(-4,37,-2,CONCRETE:7)
Block(-4,37,-1,STAINED_GLASS:15)
Block(-4,37,0,STAINED_GLASS:15)
Block(-4,37,1,STAINED_GLASS:15)
Block(-4,37,2,STAINED_GLASS:15)
Block(-4,37,6,CONCRETE:8)
Block(-4,38,-7,STAINED_GLASS_PANE:15)
Block(-4,38,-6,STAINED_GLASS_PANE:15)
Block(-4,38,-5,STAINED_GLASS_PANE:15)
Block(-4,38,-2,STAINED_GLASS_PANE:15)
Block(-4,38,-1,STAINED_GLASS_PANE:15)
Block(-4,38,0,STAINED_GLASS_PANE:15)
Block(-4,38,1,STAINED_GLASS_PANE:15)
Block(-4,38,2,STAINED_GLASS:15)
Block(-4,38,6,CONCRETE:8)
Block(-4,39,-2,STAINED_GLASS_PANE:15)
Block(-4,39,-1,STAINED_GLASS_PANE:15)
Block(-4,39,0,STAINED_GLASS_PANE:15)
Block(-4,39,1,STAINED_GLASS_PANE:15)
Block(-4,39,2,STAINED_GLASS:15)
Block(-4,39,6,CONCRETE:8)
Block(-4,40,-2,STAINED_GLASS_PANE:15)
Block(-4,40,-1,STAINED_GLASS_PANE:15)
Block(-4,40,0,STAINED_GLASS_PANE:15)
Block(-4,40,1,STAINED_GLASS_PANE:15)
Block(-4,40,2,STAINED_GLASS:15)
Block(-4,40,3,STAINED_GLASS:15)
Block(-4,40,6,CONCRETE:8)
Block(-4,41,-2,STAINED_GLASS_PANE:15)
Block(-4,41,-1,STAINED_GLASS_PANE:15)
Block(-4,41,0,STAINED_GLASS_PANE:15)
Block(-4,41,1,STAINED_GLASS_PANE:15)
Block(-4,41,3,STAINED_GLASS:15)
Block(-4,41,6,CONCRETE:8)
Block(-4,42,-7,STAINED_GLASS:15)
Block(-4,42,-6,CONCRETE:7)
Block(-4,42,-5,STAINED_GLASS:15)
Block(-4,42,-4,CONCRETE:7)
Block(-4,42,-3,STAINED_GLASS:15)
Block(-4,42,-2,CONCRETE:7)
Block(-4,42,-1,STAINED_GLASS_PANE:15)
Block(-4,42,0,STAINED_GLASS_PANE:15)
Block(-4,42,1,STAINED_GLASS_PANE:15)
Block(-4,42,3,STAINED_GLASS:15)
Block(-4,42,4,CONCRETE:7)
Block(-4,42,5,CONCRETE:7)
Block(-4,42,6,CONCRETE:7)
Block(-4,42,7,CONCRETE:7)
Block(-4,42,8,STAINED_GLASS:15)
Block(-4,43,-7,CARPET:15)
Block(-4,43,-6,CARPET:15)
Block(-4,43,-5,CARPET:15)
Block(-4,43,-4,CARPET:15)
Block(-4,43,-2,STAINED_GLASS_PANE:15)
Block(-4,43,-1,STAINED_GLASS_PANE:15)
Block(-4,43,0,STAINED_GLASS_PANE:15)
Block(-4,43,1,STAINED_GLASS_PANE:15)
Block(-4,43,3,STAINED_GLASS:15)
Block(-4,43,8,STAINED_GLASS:15)
Block(-4,44,-2,STAINED_GLASS_PANE:15)
Block(-4,44,-1,STAINED_GLASS_PANE:15)
Block(-4,44,0,STAINED_GLASS_PANE:15)
Block(-4,44,1,STAINED_GLASS_PANE:15)
Block(-4,44,3,STAINED_GLASS:15)
Block(-4,44,5,WALL_BANNER:5,NBT/skyscraper_2x2_03/87-bannerC0R16.nbt)
Block(-4,44,6,WALL_BANNER:5,NBT/skyscraper_2x2_03/88-bannerC0R16.nbt)
Block(-4,44,7,WALL_BANNER:5,NBT/skyscraper_2x2_03/89-bannerC0R16.nbt)
Block(-4,44,8,STAINED_GLASS:15)
Block(-4,45,-2,CONCRETE:7)
Block(-4,45,-1,STAINED_GLASS:15)
Block(-4,45,0,STAINED_GLASS:15)
Block(-4,45,1,STAINED_GLASS:15)
Block(-4,45,2,STAINED_GLASS:15)
Block(-4,45,3,STAINED_GLASS:15)
Block(-4,45,8,STAINED_GLASS:15)
Block(-4,46,-2,CONCRETE:7)
Block(-4,46,3,STAINED_GLASS:15)
Block(-4,46,4,STAINED_GLASS:15)
Block(-4,46,5,STAINED_GLASS:15)
Block(-4,46,6,STAINED_GLASS:15)
Block(-4,46,7,STAINED_GLASS:15)
Block(-4,46,8,STAINED_GLASS:15)
Block(-4,47,-2,CONCRETE:7)
Block(-4,47,3,STAINED_GLASS:15)
Block(-4,47,8,STAINED_GLASS:15)
Block(-4,48,-7,STAINED_GLASS:15)
Block(-4,48,-6,CONCRETE:7)
Block(-4,48,-5,STAINED_GLASS:15)
Block(-4,48,-4,CONCRETE:7)
Block(-4,48,-3,STAINED_GLASS:15)
Block(-4,48,-2,CONCRETE:7)
Block(-4,48,3,STAINED_GLASS:15)
Block(-4,48,5,WALL_BANNER:5,NBT/skyscraper_2x2_03/90-bannerC0R16.nbt)
Block(-4,48,6,WALL_BANNER:5,NBT/skyscraper_2x2_03/91-bannerC0R16.nbt)
Block(-4,48,7,WALL_BANNER:5,NBT/skyscraper_2x2_03/92-bannerC0R16.nbt)
Block(-4,48,8,STAINED_GLASS:15)
Block(-4,49,3,STAINED_GLASS:15)
Block(-4,49,8,STAINED_GLASS:15)
Block(-4,50,3,STAINED_GLASS:15)
Block(-4,50,8,STAINED_GLASS:15)
Block(-4,51,3,STAINED_GLASS:15)
Block(-4,51,8,STAINED_GLASS:15)
Block(-4,52,3,STAINED_GLASS:15)
Block(-4,52,8,STAINED_GLASS:15)
Block(-4,53,3,STAINED_GLASS:15)
Block(-4,53,4,STAINED_GLASS:15)
Block(-4,53,5,STAINED_GLASS:15)
Block(-4,53,6,STAINED_GLASS:15)
Block(-4,53,7,STAINED_GLASS:15)
Block(-4,53,8,STAINED_GLASS:15)
Block(-4,57,-2,CONCRETE:7)
Block(-4,57,-1,CONCRETE:7)
Block(-4,57,0,CONCRETE:7)
Block(-4,57,1,CONCRETE:7)
Block(-4,57,2,CONCRETE:7)
Block(-4,57,3,CONCRETE:7)
Block(-4,58,-2,CONCRETE:7)
Block(-4,58,-1,STAINED_GLASS:15)
Block(-4,58,0,STAINED_GLASS:15)
Block(-4,58,1,STAINED_GLASS:15)
Block(-4,58,2,STAINED_GLASS:15)
Block(-4,58,3,CONCRETE:7)
Block(-4,59,-2,CONCRETE:7)
Block(-4,59,3,CONCRETE:7)
Block(-4,60,-2,CONCRETE:7)
Block(-4,60,3,CONCRETE:7)
Block(-4,61,-2,CONCRETE:7)
Block(-4,61,3,CONCRETE:7)
Block(-4,62,-2,CONCRETE:7)
Block(-4,62,3,CONCRETE:7)
Block(-4,63,-2,CONCRETE:7)
Block(-4,63,3,CONCRETE:7)
Block(-4,64,-2,CONCRETE:7)
Block(-4,64,-1,CONCRETE:7)
Block(-4,64,0,CONCRETE:7)
Block(-4,64,1,CONCRETE:7)
Block(-4,64,2,CONCRETE:7)
Block(-4,64,3,CONCRETE:7)
Block(-4,65,-1,CONCRETE:7)
Block(-4,65,0,CONCRETE:7)
Block(-4,66,-1,CONCRETE:7)
Block(-4,66,0,CONCRETE:7)
Block(-4,67,-1,CONCRETE:7)
Block(-4,67,0,CONCRETE:7)
Block(-4,68,-1,CONCRETE:7)
Block(-4,68,0,CONCRETE:7)
Block(-4,69,-1,CONCRETE:7)
Block(-4,69,0,CONCRETE:7)
Block(-4,70,-1,CONCRETE:7)
Block(-4,70,0,CONCRETE:7)
Block(-4,71,-1,CONCRETE:7)
Block(-4,71,0,CONCRETE:7)
Block(-4,72,-1,CONCRETE:7)
Block(-4,72,0,CONCRETE:7)
Block(-4,73,-7,CONCRETE:7)
Block(-4,73,-6,STAINED_GLASS:15)
Block(-4,73,-5,CONCRETE:7)
Block(-4,73,-4,STAINED_GLASS:15)
Block(-4,73,-3,CONCRETE:7)
Block(-4,73,-2,STAINED_GLASS:15)
Block(-4,73,-1,CONCRETE:7)
Block(-4,73,0,STAINED_GLASS:15)
Block(-4,73,1,CONCRETE:7)
Block(-4,74,-4,DARK_OAK_STAIRS:2)
Block(-4,74,-3,CONCRETE:7)
Block(-4,74,-2,STAINED_GLASS:15)
Block(-4,74,-1,CONCRETE:7)
Block(-4,74,0,STAINED_GLASS:15)
Block(-4,74,1,CONCRETE:7)
Block(-4,75,-3,CONCRETE:7)
Block(-4,75,-2,STAINED_GLASS:15)
Block(-4,75,-1,CONCRETE:7)
Block(-4,75,0,STAINED_GLASS:15)
Block(-4,75,1,CONCRETE:7)
Block(-4,76,-3,CONCRETE:7)
Block(-4,76,-2,STAINED_GLASS:15)
Block(-4,76,-1,CONCRETE:7)
Block(-4,76,0,STAINED_GLASS:15)
Block(-4,76,1,CONCRETE:7)
Block(-4,77,-7,CONCRETE:7)
Block(-4,77,-6,CONCRETE:7)
Block(-4,77,-5,CONCRETE:7)
Block(-4,77,-4,CONCRETE:7)
Block(-4,77,-3,CONCRETE:7)
Block(-4,77,-2,STAINED_GLASS:15)
Block(-4,77,-1,CONCRETE:7)
Block(-4,77,0,STAINED_GLASS:15)
Block(-4,77,1,CONCRETE:7)
Block(-4,77,2,STAINED_GLASS:15)
Block(-4,77,3,CONCRETE:7)
Block(-4,78,-6,WALL_SIGN:5,NBT/skyscraper_2x2_03/97-signC0R16.nbt)
Block(-4,78,-3,CONCRETE:7)
Block(-4,78,-2,STAINED_GLASS:15)
Block(-4,78,-1,CONCRETE:7)
Block(-4,78,0,STAINED_GLASS:15)
Block(-4,78,1,CONCRETE:7)
Block(-4,78,2,STAINED_GLASS:15)
Block(-4,78,3,CONCRETE:7)
Block(-4,79,-3,CONCRETE:7)
Block(-4,79,-2,STAINED_GLASS:15)
Block(-4,79,-1,CONCRETE:7)
Block(-4,79,0,STAINED_GLASS:15)
Block(-4,79,1,CONCRETE:7)
Block(-4,79,2,STAINED_GLASS:15)
Block(-4,79,3,CONCRETE:7)
Block(-4,80,-3,CONCRETE:7)
Block(-4,80,-2,STAINED_GLASS:15)
Block(-4,80,-1,CONCRETE:7)
Block(-4,80,0,STAINED_GLASS:15)
Block(-4,80,1,CONCRETE:7)
Block(-4,80,2,STAINED_GLASS:15)
Block(-4,80,3,CONCRETE:7)
Block(-4,81,-7,CONCRETE:7)
Block(-4,81,-6,CONCRETE:7)
Block(-4,81,-5,CONCRETE:7)
Block(-4,81,-4,CONCRETE:7)
Block(-4,81,-3,CONCRETE:7)
Block(-4,81,-2,STAINED_GLASS:15)
Block(-4,81,-1,CONCRETE:7)
Block(-4,81,0,STAINED_GLASS:15)
Block(-4,81,1,CONCRETE:7)
Block(-4,81,2,STAINED_GLASS:15)
Block(-4,81,3,CONCRETE:7)
Block(-4,82,-7,CONCRETE:7)
Block(-4,82,-6,STAINED_GLASS:15)
Block(-4,82,-5,CONCRETE:7)
Block(-4,82,-4,STAINED_GLASS:15)
Block(-4,82,-3,CONCRETE:7)
Block(-4,83,-7,CONCRETE:7)
Block(-4,83,-6,STAINED_GLASS:15)
Block(-4,83,-5,CONCRETE:7)
Block(-4,83,-4,STAINED_GLASS:15)
Block(-4,83,-3,CONCRETE:7)
Block(-4,84,-7,CONCRETE:7)
Block(-4,84,-6,STAINED_GLASS:15)
Block(-4,84,-5,CONCRETE:7)
Block(-4,84,-4,STAINED_GLASS:15)
Block(-4,84,-3,CONCRETE:7)
Block(-4,85,-7,CONCRETE:7)
Block(-4,85,-6,STAINED_GLASS:15)
Block(-4,85,-5,CONCRETE:7)
Block(-4,85,-4,STAINED_GLASS:15)
Block(-4,85,-3,CONCRETE:7)
Block(-4,86,-7,CONCRETE:7)
Block(-4,86,-6,STAINED_GLASS:15)
Block(-4,86,-5,CONCRETE:7)
Block(-4,86,-4,STAINED_GLASS:15)
Block(-4,86,-3,CONCRETE:7)
Block(-4,87,-7,CONCRETE:7)
Block(-4,87,-6,STAINED_GLASS:15)
Block(-4,87,-5,CONCRETE:7)
Block(-4,87,-4,STAINED_GLASS:15)
Block(-4,87,-3,CONCRETE:7)
Block(-4,88,-7,CONCRETE:7)
Block(-4,88,-6,STAINED_GLASS:15)
Block(-4,88,-5,CONCRETE:7)
Block(-4,88,-4,STAINED_GLASS:15)
Block(-4,88,-3,CONCRETE:7)
Block(-4,89,-7,CONCRETE:7)
Block(-4,89,-6,STAINED_GLASS:15)
Block(-4,89,-5,CONCRETE:7)
Block(-4,89,-4,STAINED_GLASS:15)
Block(-4,89,-3,CONCRETE:7)
Block(-4,90,-7,CONCRETE:7)
Block(-4,90,-6,STAINED_GLASS:15)
Block(-4,90,-5,CONCRETE:7)
Block(-4,90,-4,STAINED_GLASS:15)
Block(-4,90,-3,CONCRETE:7)
Block(-4,91,-7,CONCRETE:7)
Block(-4,91,-6,STAINED_GLASS:15)
Block(-4,91,-5,CONCRETE:7)
Block(-4,91,-4,STAINED_GLASS:15)
Block(-4,91,-3,CONCRETE:7)
Block(-4,92,-7,CONCRETE:7)
Block(-4,92,-6,STAINED_GLASS:15)
Block(-4,92,-5,CONCRETE:7)
Block(-4,92,-4,STAINED_GLASS:15)
Block(-4,92,-3,CONCRETE:7)
Block(-4,93,-7,CONCRETE:7)
Block(-4,93,-6,STAINED_GLASS:15)
Block(-4,93,-5,CONCRETE:7)
Block(-4,93,-4,STAINED_GLASS:15)
Block(-4,93,-3,CONCRETE:7)
Block(-4,94,-7,CONCRETE:7)
Block(-4,94,-6,STAINED_GLASS:15)
Block(-4,94,-5,CONCRETE:7)
Block(-4,94,-4,STAINED_GLASS:15)
Block(-4,94,-3,CONCRETE:7)
Block(-4,95,-7,CONCRETE:7)
Block(-4,95,-6,STAINED_GLASS:15)
Block(-4,95,-5,CONCRETE:7)
Block(-4,95,-4,STAINED_GLASS:15)
Block(-4,95,-3,CONCRETE:7)
Block(-4,96,-7,CONCRETE:7)
Block(-4,96,-6,STAINED_GLASS:15)
Block(-4,96,-5,CONCRETE:7)
Block(-4,96,-4,STAINED_GLASS:15)
Block(-4,96,-3,CONCRETE:7)
Block(-4,97,-7,CONCRETE:7)
Block(-4,97,-6,STAINED_GLASS:15)
Block(-4,97,-5,CONCRETE:7)
Block(-4,97,-4,STAINED_GLASS:15)
Block(-4,97,-3,CONCRETE:7)
Block(-4,98,-7,CONCRETE:7)
Block(-4,98,-6,STAINED_GLASS:15)
Block(-4,98,-5,CONCRETE:7)
Block(-4,98,-4,STAINED_GLASS:15)
Block(-4,98,-3,CONCRETE:7)
Block(-4,99,-7,CONCRETE:7)
Block(-4,99,-6,STAINED_GLASS:15)
Block(-4,99,-5,CONCRETE:7)
Block(-4,99,-4,STAINED_GLASS:15)
Block(-4,99,-3,CONCRETE:7)
Block(-4,100,-7,CONCRETE:7)
Block(-4,100,-6,STAINED_GLASS:15)
Block(-4,100,-5,CONCRETE:7)
Block(-4,100,-4,STAINED_GLASS:15)
Block(-4,100,-3,CONCRETE:7)
Block(-4,101,-7,CONCRETE:7)
Block(-4,101,-6,STAINED_GLASS:15)
Block(-4,101,-5,CONCRETE:7)
Block(-4,101,-4,STAINED_GLASS:15)
Block(-4,101,-3,CONCRETE:7)
Block(-4,102,-7,CONCRETE:7)
Block(-4,102,-6,STAINED_GLASS:15)
Block(-4,102,-5,CONCRETE:7)
Block(-4,102,-4,STAINED_GLASS:15)
Block(-4,102,-3,CONCRETE:7)
Block(-4,103,-7,CONCRETE:7)
Block(-4,103,-6,STAINED_GLASS:15)
Block(-4,103,-5,CONCRETE:7)
Block(-4,103,-4,STAINED_GLASS:15)
Block(-4,103,-3,CONCRETE:7)
Block(-4,104,-7,CONCRETE:7)
Block(-4,104,-6,STAINED_GLASS:15)
Block(-4,104,-5,CONCRETE:7)
Block(-4,104,-4,STAINED_GLASS:15)
Block(-4,104,-3,CONCRETE:7)
Block(-4,105,-7,CONCRETE:7)
Block(-4,105,-6,STAINED_GLASS:15)
Block(-4,105,-5,CONCRETE:7)
Block(-4,105,-4,STAINED_GLASS:15)
Block(-4,105,-3,CONCRETE:7)
Block(-4,106,-7,CONCRETE:7)
Block(-4,106,-6,STAINED_GLASS:15)
Block(-4,106,-5,CONCRETE:7)
Block(-4,106,-4,STAINED_GLASS:15)
Block(-4,106,-3,CONCRETE:7)
Block(-4,107,-7,CONCRETE:7)
Block(-4,107,-6,STAINED_GLASS:15)
Block(-4,107,-5,CONCRETE:7)
Block(-4,107,-4,STAINED_GLASS:15)
Block(-4,107,-3,CONCRETE:7)
Block(-4,108,-7,CONCRETE:7)
Block(-4,108,-6,STAINED_GLASS:15)
Block(-4,108,-5,CONCRETE:7)
Block(-4,108,-4,STAINED_GLASS:15)
Block(-4,108,-3,CONCRETE:7)
Block(-4,109,-7,CONCRETE:7)
Block(-4,109,-6,STAINED_GLASS:15)
Block(-4,109,-5,CONCRETE:7)
Block(-4,109,-4,STAINED_GLASS:15)
Block(-4,109,-3,CONCRETE:7)
Block(-4,110,-7,CONCRETE:7)
Block(-4,110,-6,STAINED_GLASS:15)
Block(-4,110,-5,CONCRETE:7)
Block(-4,110,-4,STAINED_GLASS:15)
Block(-4,110,-3,CONCRETE:7)
Block(-4,111,-7,CONCRETE:7)
Block(-4,111,-6,STAINED_GLASS:15)
Block(-4,111,-5,CONCRETE:7)
Block(-4,111,-4,STAINED_GLASS:15)
Block(-4,111,-3,CONCRETE:7)
Block(-4,112,-7,CONCRETE:7)
Block(-4,112,-6,STAINED_GLASS:15)
Block(-4,112,-5,CONCRETE:7)
Block(-4,112,-4,STAINED_GLASS:15)
Block(-4,112,-3,CONCRETE:7)
Block(-4,113,-7,CONCRETE:7)
Block(-4,113,-5,CONCRETE:7)
Block(-4,113,-3,CONCRETE:7)
Block(-3,0,-7,CONCRETE:7)
Block(-3,0,-6,CONCRETE:7)
Block(-3,0,-5,CONCRETE:7)
Block(-3,0,-4,CONCRETE:7)
Block(-3,0,-3,CONCRETE:7)
Block(-3,0,-2,CONCRETE:7)
Block(-3,0,-1,CONCRETE:7)
Block(-3,0,0,CONCRETE:7)
Block(-3,0,1,CONCRETE:7)
Block(-3,0,2,CONCRETE:7)
Block(-3,0,3,CONCRETE:7)
Block(-3,0,4,CONCRETE:7)
Block(-3,0,5,CONCRETE:7)
Block(-3,0,6,CONCRETE:7)
Block(-3,0,7,CONCRETE:7)
Block(-3,0,8,CONCRETE:7)
Block(-3,1,-6,CONCRETE:7)
Block(-3,1,-5,CONCRETE:7)
Block(-3,1,-4,CONCRETE:7)
Block(-3,1,-3,CONCRETE:7)
Block(-3,1,-2,CONCRETE:7)
Block(-3,1,-1,CONCRETE:7)
Block(-3,1,0,CONCRETE:7)
Block(-3,1,1,CONCRETE:7)
Block(-3,1,2,CONCRETE:7)
Block(-3,1,3,CONCRETE:7)
Block(-3,1,4,CONCRETE:7)
Block(-3,1,5,CONCRETE:7)
Block(-3,1,6,CONCRETE:7)
Block(-3,1,7,CONCRETE:7)
Block(-3,1,8,CONCRETE:7)
Block(-3,2,-6,CONCRETE:7)
Block(-3,2,-5,CONCRETE:7)
Block(-3,2,-4,CONCRETE:7)
Block(-3,2,-3,CONCRETE:7)
Block(-3,2,-2,CONCRETE:7)
Block(-3,2,-1,CONCRETE:7)
Block(-3,2,0,CONCRETE:7)
Block(-3,2,1,CONCRETE:7)
Block(-3,2,2,CONCRETE:7)
Block(-3,2,3,CONCRETE:7)
Block(-3,2,4,CONCRETE:7)
Block(-3,2,5,CONCRETE:7)
Block(-3,2,6,CONCRETE:7)
Block(-3,2,7,CONCRETE:7)
Block(-3,2,8,CONCRETE:7)
Block(-3,5,-6,CONCRETE:11)
Block(-3,5,-5,CONCRETE:11)
Block(-3,5,-4,CONCRETE:11)
Block(-3,5,-3,CONCRETE:11)
Block(-3,5,-2,CONCRETE:11)
Block(-3,5,-1,CONCRETE:11)
Block(-3,5,0,CONCRETE:11)
Block(-3,5,1,CONCRETE:11)
Block(-3,5,2,CONCRETE:11)
Block(-3,5,3,CONCRETE:11)
Block(-3,5,4,CONCRETE:11)
Block(-3,5,5,CONCRETE:11)
Block(-3,5,6,CONCRETE:11)
Block(-3,5,7,CONCRETE:11)
Block(-3,5,8,CONCRETE:11)
Block(-3,6,-7,CONCRETE:7)
Block(-3,6,-6,CONCRETE:7)
Block(-3,6,-5,CONCRETE:7)
Block(-3,6,-4,CONCRETE:7)
Block(-3,6,-3,CONCRETE:7)
Block(-3,6,-2,CONCRETE:7)
Block(-3,6,-1,CONCRETE:7)
Block(-3,6,0,CONCRETE:7)
Block(-3,6,1,CONCRETE:7)
Block(-3,6,2,CONCRETE:7)
Block(-3,6,3,CONCRETE:7)
Block(-3,6,4,CONCRETE:7)
Block(-3,6,5,CONCRETE:7)
Block(-3,6,6,CONCRETE:7)
Block(-3,6,7,CONCRETE:7)
Block(-3,6,8,CONCRETE:7)
Block(-3,7,-7,CONCRETE:7)
Block(-3,7,-6,CONCRETE:7)
Block(-3,7,-5,CONCRETE:7)
Block(-3,7,-4,CONCRETE:7)
Block(-3,7,-3,CONCRETE:7)
Block(-3,7,-2,CONCRETE:7)
Block(-3,7,-1,CONCRETE:7)
Block(-3,7,0,CONCRETE:7)
Block(-3,7,1,CONCRETE:7)
Block(-3,7,2,CONCRETE:7)
Block(-3,7,3,CONCRETE:7)
Block(-3,7,4,CONCRETE:7)
Block(-3,7,5,CONCRETE:7)
Block(-3,7,6,CONCRETE:7)
Block(-3,7,7,CONCRETE:7)
Block(-3,7,8,CONCRETE:7)
Block(-3,8,-6,CONCRETE:7)
Block(-3,8,-5,CONCRETE:7)
Block(-3,8,-4,CONCRETE:7)
Block(-3,8,-3,CONCRETE:7)
Block(-3,8,-2,CONCRETE:7)
Block(-3,8,-1,CONCRETE:7)
Block(-3,8,0,CONCRETE:7)
Block(-3,8,1,CONCRETE:7)
Block(-3,8,2,CONCRETE:7)
Block(-3,8,3,CONCRETE:7)
Block(-3,8,4,CONCRETE:7)
Block(-3,8,5,CONCRETE:7)
Block(-3,8,6,CONCRETE:7)
Block(-3,8,7,CONCRETE:7)
Block(-3,8,8,CONCRETE:7)
Block(-3,9,-6,CONCRETE:7)
Block(-3,9,-5,CONCRETE:7)
Block(-3,9,-4,CONCRETE:7)
Block(-3,9,-3,CONCRETE:7)
Block(-3,9,-2,CONCRETE:7)
Block(-3,9,-1,CONCRETE:7)
Block(-3,9,0,CONCRETE:7)
Block(-3,9,1,CONCRETE:7)
Block(-3,9,2,CONCRETE:7)
Block(-3,9,3,CONCRETE:7)
Block(-3,9,4,CONCRETE:7)
Block(-3,9,5,CONCRETE:7)
Block(-3,9,6,CONCRETE:7)
Block(-3,9,7,CONCRETE:7)
Block(-3,9,8,CONCRETE:7)
Block(-3,10,-6,CONCRETE:7)
Block(-3,10,-5,CONCRETE:7)
Block(-3,10,-4,CONCRETE:7)
Block(-3,10,-3,CONCRETE:7)
Block(-3,10,-2,CONCRETE:7)
Block(-3,10,-1,CONCRETE:7)
Block(-3,10,0,CONCRETE:7)
Block(-3,10,1,CONCRETE:7)
Block(-3,10,2,CONCRETE:7)
Block(-3,10,3,CONCRETE:7)
Block(-3,10,4,CONCRETE:7)
Block(-3,10,5,CONCRETE:7)
Block(-3,10,6,CONCRETE:7)
Block(-3,10,7,CONCRETE:7)
Block(-3,10,8,CONCRETE:7)
Block(-3,11,-7,CONCRETE:7)
Block(-3,11,-6,CONCRETE:7)
Block(-3,11,-5,CONCRETE:7)
Block(-3,11,-4,CONCRETE:7)
Block(-3,11,-3,CONCRETE:7)
Block(-3,11,-2,CONCRETE:7)
Block(-3,11,-1,CONCRETE:7)
Block(-3,11,0,CONCRETE:7)
Block(-3,11,1,CONCRETE:7)
Block(-3,11,2,CONCRETE:7)
Block(-3,11,3,CONCRETE:7)
Block(-3,11,4,CONCRETE:7)
Block(-3,11,5,CONCRETE:7)
Block(-3,11,6,CONCRETE:7)
Block(-3,11,7,CONCRETE:7)
Block(-3,11,8,CONCRETE:7)
Block(-3,12,-7,CONCRETE:7)
Block(-3,12,-6,CONCRETE:7)
Block(-3,12,-5,CONCRETE:8)
Block(-3,12,-4,DARK_OAK_STAIRS:3)
Block(-3,12,6,DARK_OAK_STAIRS:2)
Block(-3,12,7,CONCRETE:8)
Block(-3,12,8,CONCRETE:7)
Block(-3,13,-7,CONCRETE:7)
Block(-3,13,-6,CONCRETE:7)
Block(-3,13,-5,CONCRETE:8)
Block(-3,13,7,CONCRETE:8)
Block(-3,13,8,CONCRETE:7)
Block(-3,14,-7,CONCRETE:7)
Block(-3,14,-6,CONCRETE:7)
Block(-3,14,-5,CONCRETE:8)
Block(-3,14,7,CONCRETE:8)
Block(-3,14,8,CONCRETE:7)
Block(-3,15,-7,CONCRETE:7)
Block(-3,15,-6,CONCRETE:7)
Block(-3,15,-5,CONCRETE:8)
Block(-3,15,7,CONCRETE:8)
Block(-3,15,8,CONCRETE:7)
Block(-3,16,-7,CONCRETE:7)
Block(-3,16,-6,CONCRETE:7)
Block(-3,16,-5,CONCRETE:7)
Block(-3,16,-4,CONCRETE:7)
Block(-3,16,-3,CONCRETE:7)
Block(-3,16,-2,CONCRETE:7)
Block(-3,16,-1,CONCRETE:7)
Block(-3,16,0,CONCRETE:7)
Block(-3,16,1,CONCRETE:7)
Block(-3,16,2,CONCRETE:7)
Block(-3,16,3,CONCRETE:7)
Block(-3,16,4,CONCRETE:7)
Block(-3,16,5,CONCRETE:7)
Block(-3,16,6,CONCRETE:7)
Block(-3,16,7,CONCRETE:7)
Block(-3,16,8,CONCRETE:7)
Block(-3,17,-7,CONCRETE:7)
Block(-3,17,-6,CONCRETE:7)
Block(-3,17,-5,CONCRETE:7)
Block(-3,17,-4,CONCRETE:7)
Block(-3,17,-3,CONCRETE:7)
Block(-3,17,-2,CONCRETE:7)
Block(-3,17,-1,CONCRETE:7)
Block(-3,17,0,CONCRETE:7)
Block(-3,17,1,CONCRETE:7)
Block(-3,17,2,CONCRETE:7)
Block(-3,17,3,CONCRETE:7)
Block(-3,17,4,CONCRETE:7)
Block(-3,17,5,CONCRETE:7)
Block(-3,17,6,CONCRETE:7)
Block(-3,17,7,CONCRETE:7)
Block(-3,17,8,CONCRETE:7)
Block(-3,18,-7,DARK_OAK_STAIRS:1)
Block(-3,18,6,CONCRETE:8)
Block(-3,19,-7,TRAP_DOOR:7)
Block(-3,19,6,CONCRETE:8)
Block(-3,20,6,CONCRETE:8)
Block(-3,21,6,CONCRETE:8)
Block(-3,22,6,CONCRETE:8)
Block(-3,23,6,CONCRETE:8)
Block(-3,24,6,CONCRETE:8)
Block(-3,25,6,CONCRETE:8)
Block(-3,26,-7,STAINED_GLASS:15)
Block(-3,26,-6,CONCRETE:7)
Block(-3,26,-5,STAINED_GLASS:15)
Block(-3,26,-4,CONCRETE:7)
Block(-3,26,-3,STAINED_GLASS:15)
Block(-3,26,-2,CONCRETE:7)
Block(-3,26,-1,STAINED_GLASS:15)
Block(-3,26,0,STAINED_GLASS:15)
Block(-3,26,1,STAINED_GLASS:15)
Block(-3,26,2,STAINED_GLASS:15)
Block(-3,26,3,STAINED_GLASS:15)
Block(-3,26,4,STAINED_GLASS:15)
Block(-3,26,5,STAINED_GLASS:15)
Block(-3,26,6,CONCRETE:8)
Block(-3,27,6,CONCRETE:8)
Block(-3,28,6,CONCRETE:8)
Block(-3,29,6,CONCRETE:8)
Block(-3,30,6,CONCRETE:8)
Block(-3,31,6,CONCRETE:8)
Block(-3,32,6,CONCRETE:8)
Block(-3,33,6,CONCRETE:8)
Block(-3,34,6,CONCRETE:8)
Block(-3,35,6,CONCRETE:8)
Block(-3,36,6,CONCRETE:8)
Block(-3,37,-5,STAINED_GLASS_PANE:15)
Block(-3,37,-4,CONCRETE:7)
Block(-3,37,-3,STAINED_GLASS:15)
Block(-3,37,-2,CONCRETE:7)
Block(-3,37,-1,DARK_OAK_STAIRS:7)
Block(-3,37,6,CONCRETE:8)
Block(-3,38,-5,STAINED_GLASS_PANE:15)
Block(-3,38,-1,DARK_OAK_STAIRS:2)
Block(-3,38,0,DARK_OAK_STAIRS:7)
Block(-3,38,6,CONCRETE:8)
Block(-3,39,0,DARK_OAK_STAIRS:2)
Block(-3,39,1,DARK_OAK_STAIRS:7)
Block(-3,39,6,CONCRETE:8)
Block(-3,40,1,DARK_OAK_STAIRS:2)
Block(-3,40,2,CONCRETE:7)
Block(-3,40,3,CONCRETE:7)
Block(-3,40,6,CONCRETE:8)
Block(-3,41,3,CONCRETE:7)
Block(-3,41,6,CONCRETE:8)
Block(-3,42,-7,STAINED_GLASS:15)
Block(-3,42,-6,CONCRETE:7)
Block(-3,42,-5,STAINED_GLASS:15)
Block(-3,42,-4,CONCRETE:7)
Block(-3,42,-3,STAINED_GLASS:15)
Block(-3,42,-2,CONCRETE:7)
Block(-3,42,3,CONCRETE:7)
Block(-3,42,4,CONCRETE:7)
Block(-3,42,5,CONCRETE:7)
Block(-3,42,6,CONCRETE:7)
Block(-3,42,7,CONCRETE:7)
Block(-3,42,8,CONCRETE:7)
Block(-3,43,-7,CARPET:0)
Block(-3,43,-6,CARPET:0)
Block(-3,43,-5,CARPET:0)
Block(-3,43,-4,CARPET:15)
Block(-3,43,-2,CONCRETE:7)
Block(-3,43,3,CONCRETE:7)
Block(-3,43,5,WALL_SIGN:2,NBT/skyscraper_2x2_03/101-signC0R16.nbt)
Block(-3,43,6,DARK_OAK_STAIRS:1)
Block(-3,43,7,WALL_SIGN:3,NBT/skyscraper_2x2_03/102-signC0R16.nbt)
Block(-3,43,8,CONCRETE:7)
Block(-3,44,-2,CONCRETE:7)
Block(-3,44,3,CONCRETE:7)
Block(-3,44,6,TRAP_DOOR:7)
Block(-3,44,8,CONCRETE:7)
Block(-3,45,-2,CONCRETE:7)
Block(-3,45,-1,STAINED_GLASS:15)
Block(-3,45,0,STAINED_GLASS:15)
Block(-3,45,1,STAINED_GLASS:15)
Block(-3,45,2,STAINED_GLASS:15)
Block(-3,45,3,CONCRETE:7)
Block(-3,45,8,CONCRETE:7)
Block(-3,46,-2,CONCRETE:7)
Block(-3,46,3,CONCRETE:7)
Block(-3,46,4,CONCRETE:7)
Block(-3,46,5,CONCRETE:7)
Block(-3,46,6,CONCRETE:7)
Block(-3,46,7,CONCRETE:7)
Block(-3,46,8,CONCRETE:7)
Block(-3,47,-2,CONCRETE:7)
Block(-3,47,3,CONCRETE:7)
Block(-3,47,5,WALL_SIGN:2,NBT/skyscraper_2x2_03/104-signC0R16.nbt)
Block(-3,47,6,DARK_OAK_STAIRS:1)
Block(-3,47,7,WALL_SIGN:3,NBT/skyscraper_2x2_03/105-signC0R16.nbt)
Block(-3,47,8,CONCRETE:7)
Block(-3,48,-7,STAINED_GLASS:15)
Block(-3,48,-6,CONCRETE:7)
Block(-3,48,-5,STAINED_GLASS:15)
Block(-3,48,-4,CONCRETE:7)
Block(-3,48,-3,STAINED_GLASS:15)
Block(-3,48,-2,CONCRETE:7)
Block(-3,48,3,CONCRETE:7)
Block(-3,48,6,TRAP_DOOR:7)
Block(-3,48,8,CONCRETE:7)
Block(-3,49,3,CONCRETE:7)
Block(-3,49,8,CONCRETE:7)
Block(-3,50,3,CONCRETE:7)
Block(-3,50,8,CONCRETE:7)
Block(-3,51,3,CONCRETE:7)
Block(-3,51,8,CONCRETE:7)
Block(-3,52,3,CONCRETE:7)
Block(-3,52,8,CONCRETE:7)
Block(-3,53,3,CONCRETE:7)
Block(-3,53,4,CONCRETE:7)
Block(-3,53,5,CONCRETE:7)
Block(-3,53,6,CONCRETE:7)
Block(-3,53,7,CONCRETE:7)
Block(-3,53,8,CONCRETE:7)
Block(-3,57,-2,CONCRETE:7)
Block(-3,57,-1,CONCRETE:7)
Block(-3,57,0,CONCRETE:7)
Block(-3,57,1,CONCRETE:7)
Block(-3,57,2,CONCRETE:7)
Block(-3,57,3,STAINED_GLASS:15)
Block(-3,58,-7,CONCRETE:8)
Block(-3,58,-6,CONCRETE:8)
Block(-3,58,-5,CONCRETE:8)
Block(-3,58,-4,CONCRETE:8)
Block(-3,58,-3,CONCRETE:8)
Block(-3,58,-2,CONCRETE:7)
Block(-3,58,-1,STAINED_GLASS:15)
Block(-3,58,0,STAINED_GLASS:15)
Block(-3,58,1,STAINED_GLASS:15)
Block(-3,58,2,STAINED_GLASS:15)
Block(-3,58,3,STAINED_GLASS:15)
Block(-3,59,-7,CONCRETE:8)
Block(-3,59,-6,CONCRETE:8)
Block(-3,59,-5,CONCRETE:8)
Block(-3,59,-4,CONCRETE:8)
Block(-3,59,-3,CONCRETE:8)
Block(-3,59,-2,CONCRETE:7)
Block(-3,59,3,STAINED_GLASS:15)
Block(-3,60,-7,CONCRETE:8)
Block(-3,60,-6,CONCRETE:8)
Block(-3,60,-5,CONCRETE:8)
Block(-3,60,-4,CONCRETE:8)
Block(-3,60,-3,CONCRETE:8)
Block(-3,60,-2,CONCRETE:7)
Block(-3,60,3,STAINED_GLASS:15)
Block(-3,61,-7,CONCRETE:8)
Block(-3,61,-6,CONCRETE:8)
Block(-3,61,-5,CONCRETE:8)
Block(-3,61,-4,CONCRETE:8)
Block(-3,61,-3,CONCRETE:8)
Block(-3,61,-2,CONCRETE:7)
Block(-3,61,3,STAINED_GLASS:15)
Block(-3,62,-7,CONCRETE:8)
Block(-3,62,-6,CONCRETE:8)
Block(-3,62,-5,CONCRETE:8)
Block(-3,62,-4,CONCRETE:8)
Block(-3,62,-3,CONCRETE:8)
Block(-3,62,-2,CONCRETE:7)
Block(-3,62,3,STAINED_GLASS:15)
Block(-3,63,-2,CONCRETE:7)
Block(-3,63,3,STAINED_GLASS:15)
Block(-3,64,-2,CONCRETE:7)
Block(-3,64,-1,CONCRETE:7)
Block(-3,64,0,CONCRETE:7)
Block(-3,64,1,CONCRETE:7)
Block(-3,64,2,CONCRETE:7)
Block(-3,64,3,STAINED_GLASS:15)
Block(-3,73,-7,CONCRETE:7)
Block(-3,73,-6,STAINED_GLASS:15)
Block(-3,73,-5,CONCRETE:7)
Block(-3,73,-4,STAINED_GLASS:15)
Block(-3,73,-3,CONCRETE:7)
Block(-3,74,-6,WALL_SIGN:2,NBT/skyscraper_2x2_03/109-signC0R16.nbt)
Block(-3,74,-5,DARK_OAK_STAIRS:0)
Block(-3,74,-4,DARK_OAK_STAIRS:0)
Block(-3,74,-3,STAINED_GLASS:15)
Block(-3,75,-3,STAINED_GLASS:15)
Block(-3,76,-3,STAINED_GLASS:15)
Block(-3,77,-7,CONCRETE:7)
Block(-3,77,-6,CONCRETE:7)
Block(-3,77,-5,CONCRETE:7)
Block(-3,77,-4,CONCRETE:7)
Block(-3,77,-3,CONCRETE:7)
Block(-3,78,-7,CARPET:0)
Block(-3,78,-6,CARPET:0)
Block(-3,78,-5,CARPET:0)
Block(-3,78,-3,STAINED_GLASS:15)
Block(-3,79,-3,STAINED_GLASS:15)
Block(-3,80,-3,STAINED_GLASS:15)
Block(-3,81,-3,CONCRETE:7)
Block(-3,82,-3,STAINED_GLASS:15)
Block(-3,83,-3,STAINED_GLASS:15)
Block(-3,84,-3,STAINED_GLASS:15)
Block(-3,85,-3,STAINED_GLASS:15)
Block(-3,86,-3,STAINED_GLASS:15)
Block(-3,87,-3,STAINED_GLASS:15)
Block(-3,88,-3,STAINED_GLASS:15)
Block(-3,89,-3,STAINED_GLASS:15)
Block(-3,90,-3,STAINED_GLASS:15)
Block(-3,91,-3,STAINED_GLASS:15)
Block(-3,92,-3,STAINED_GLASS:15)
Block(-3,93,-3,STAINED_GLASS:15)
Block(-3,94,-3,STAINED_GLASS:15)
Block(-3,95,-3,STAINED_GLASS:15)
Block(-3,96,-3,STAINED_GLASS:15)
Block(-3,97,-3,STAINED_GLASS:15)
Block(-3,98,-3,STAINED_GLASS:15)
Block(-3,99,-3,STAINED_GLASS:15)
Block(-3,100,-3,STAINED_GLASS:15)
Block(-3,101,-3,STAINED_GLASS:15)
Block(-3,102,-3,STAINED_GLASS:15)
Block(-3,103,-3,STAINED_GLASS:15)
Block(-3,104,-3,STAINED_GLASS:15)
Block(-3,105,-3,STAINED_GLASS:15)
Block(-3,106,-3,STAINED_GLASS:15)
Block(-3,107,-3,STAINED_GLASS:15)
Block(-3,108,-3,STAINED_GLASS:15)
Block(-3,109,-3,STAINED_GLASS:15)
Block(-3,110,-3,STAINED_GLASS:15)
Block(-3,111,-3,STAINED_GLASS:15)
Block(-3,112,-7,CONCRETE:7)
Block(-3,112,-6,STAINED_GLASS:15)
Block(-3,112,-5,CONCRETE:7)
Block(-3,112,-4,STAINED_GLASS:15)
Block(-3,112,-3,STAINED_GLASS:15)
Block(-3,113,-7,CONCRETE:7)
Block(-3,113,-5,CONCRETE:7)
Block(-2,0,-7,CONCRETE:7)
Block(-2,0,-6,CONCRETE:7)
Block(-2,0,-5,CONCRETE:7)
Block(-2,0,-4,CONCRETE:7)
Block(-2,0,-3,CONCRETE:7)
Block(-2,0,-2,CONCRETE:7)
Block(-2,0,-1,CONCRETE:7)
Block(-2,0,0,CONCRETE:7)
Block(-2,0,1,CONCRETE:7)
Block(-2,0,2,CONCRETE:7)
Block(-2,0,3,CONCRETE:7)
Block(-2,0,4,CONCRETE:7)
Block(-2,0,5,CONCRETE:7)
Block(-2,0,6,CONCRETE:7)
Block(-2,0,7,CONCRETE:7)
Block(-2,0,8,CONCRETE:7)
Block(-2,1,-6,CONCRETE:7)
Block(-2,2,-7,IRON_TRAPDOOR:11)
Block(-2,2,-6,CONCRETE:7)
Block(-2,2,-5,IRON_TRAPDOOR:8)
Block(-2,2,-4,IRON_TRAPDOOR:8)
Block(-2,2,-3,IRON_TRAPDOOR:8)
Block(-2,2,-2,IRON_TRAPDOOR:8)
Block(-2,2,-1,IRON_TRAPDOOR:8)
Block(-2,2,0,IRON_TRAPDOOR:8)
Block(-2,2,1,IRON_TRAPDOOR:8)
Block(-2,2,2,IRON_TRAPDOOR:8)
Block(-2,2,3,IRON_TRAPDOOR:8)
Block(-2,2,4,IRON_TRAPDOOR:8)
Block(-2,2,5,IRON_TRAPDOOR:8)
Block(-2,2,6,IRON_TRAPDOOR:8)
Block(-2,2,7,IRON_TRAPDOOR:8)
Block(-2,2,8,IRON_TRAPDOOR:9)
Block(-2,3,-7,CONCRETE:12)
Block(-2,3,-6,CONCRETE:12)
Block(-2,3,-5,CONCRETE:12)
Block(-2,3,-4,CONCRETE:12)
Block(-2,3,-3,CONCRETE:12)
Block(-2,3,-2,CONCRETE:12)
Block(-2,3,-1,CONCRETE:12)
Block(-2,3,0,CONCRETE:12)
Block(-2,3,1,CONCRETE:12)
Block(-2,3,2,CONCRETE:12)
Block(-2,3,3,CONCRETE:12)
Block(-2,3,4,CONCRETE:12)
Block(-2,3,5,CONCRETE:12)
Block(-2,3,6,CONCRETE:12)
Block(-2,3,7,CONCRETE:12)
Block(-2,3,8,CONCRETE:12)
Block(-2,4,-7,CONCRETE:14)
Block(-2,4,-6,CONCRETE:14)
Block(-2,4,-5,CONCRETE:14)
Block(-2,5,-7,CONCRETE:14)
Block(-2,5,-6,CONCRETE:11)
