
#######################################################################
# +-----------------------------------------------------------------+ #
# |                            BO4 object                           | #
# +-----------------------------------------------------------------+ #
#######################################################################

Author: NLBlackEagle

Description: No description given

SettingsMode: WriteDisable


#######################################################################
# +-----------------------------------------------------------------+ #
# |                          Main settings                          | #
# +-----------------------------------------------------------------+ #
#######################################################################

Frequency: 0

SpawnHeight: highestBlock

UseCenterForHighestBlock: true

##############################
# Height Limits for the BO4. #
##############################

MinHeight: 0

MaxHeight: 255

InheritBO3: 

InheritBO3Rotation: NORTH

OverrideChildSettings: true

OverrideParentHeight: false

CanOverride: true

BranchFrequency: 0

BranchFrequencyGroup: 

MustBeBelowOther: false

MustBeInside: 

CannotBeInside: 

ReplacesBO3: L4-M-CrossC0R0, L4-M-CrossC0R1, L4-M-CrossC0R2, L4-M-CrossC0R3, L4-M-CrossC1R0, L4-M-CrossC1R1, L4-M-CrossC1R2, L4-M-CrossC1R3, L4-M-CrossC2R0, L4-M-CrossC2R1, L4-M-CrossC2R2, L4-M-CrossC2R3, L4-M-CrossC3R0, L4-M-CrossC3R1, L4-M-CrossC3R2, L4-M-CrossC3R3, L4-M-Straigth-START_01-C0R0, L4-M-Straigth-START_01-C0R1, L4-M-Straigth-START_01-C1R0, L4-M-Straigth-START_01-C1R1, L4-M-Straigth-START_01-C2R0, L4-M-Straigth-START_01-C2R1, L4-M-Straigth-START_01-C3R0, L4-M-Straigth-START_01-C3R1, L4-M-Straigth-3CC0R0, L4-M-Straigth-3CC0R1, L4-M-Straigth-3CC0R2, L4-M-Straigth-3CC1R0, L4-M-Straigth-3CC1R1, L4-M-Straigth-3CC1R2, L4-M-Straigth-3CC2R0, L4-M-Straigth-3CC2R1, L4-M-Straigth-3CC2R2, L4-M-Straigth-3CC3R0, L4-M-Straigth-3CC3R1, L4-M-Straigth-3CC3R2, L4-M-Cross, skyscraper_2x2_01, skyscraper_2x2_02, skyscraper_2x2_03, skyscraper_2x2_04, skyscraper_2x2_05, skyscraper_3x3_01, skyscraper_3x3_02, skyscraper_3x3_03, L3-M-Straigth-2CC0R0, L3-M-Straigth-2CC0R1, L3-M-Straigth-2CC1R0, L3-M-Straigth-2CC1R1, L3-M-Straigth-2CC2R0, L3-M-Straigth-2CC2R1, L3-M-Straigth-2CC3R0, L3-M-Straigth-2CC3R1, L3-M-Straigth-3CC0R0, L3-M-Straigth-3CC0R1, L3-M-Straigth-3CC0R2, L3-M-Straigth-3CC1R0, L3-M-Straigth-3CC1R1, L3-M-Straigth-3CC1R2, L3-M-Straigth-3CC2R0, L3-M-Straigth-3CC2R1, L3-M-Straigth-3CC2R2, L3-M-Straigth-3CC3R0, L3-M-Straigth-3CC3R1, L3-M-Straigth-3CC3R2L4-M-CrossC0R0, L4-M-CrossC0R1, L4-M-CrossC0R2, L4-M-CrossC0R3, L4-M-CrossC1R0, L4-M-CrossC1R1, L4-M-CrossC1R2, L4-M-CrossC1R3, L4-M-CrossC2R0, L4-M-CrossC2R1, L4-M-CrossC2R2, L4-M-CrossC2R3, L4-M-CrossC3R0, L4-M-CrossC3R1, L4-M-CrossC3R2, L4-M-CrossC3R3, L4-M-Straigth-START_01-C0R0, L4-M-Straigth-START_01-C0R1, L4-M-Straigth-START_01-C1R0, L4-M-Straigth-START_01-C1R1, L4-M-Straigth-START_01-C2R0, L4-M-Straigth-START_01-C2R1, L4-M-Straigth-START_01-C3R0, L4-M-Straigth-START_01-C3R1, L4-M-Straigth-3CC0R0, L4-M-Straigth-3CC0R1, L4-M-Straigth-3CC0R2, L4-M-Straigth-3CC1R0, L4-M-Straigth-3CC1R1, L4-M-Straigth-3CC1R2, L4-M-Straigth-3CC2R0, L4-M-Straigth-3CC2R1, L4-M-Straigth-3CC2R2, L4-M-Straigth-3CC3R0, L4-M-Straigth-3CC3R1, L4-M-Straigth-3CC3R2, L4-M-Cross, skyscraper_2x2_01, skyscraper_2x2_02, skyscraper_2x2_03, skyscraper_2x2_04, skyscraper_2x2_05, skyscraper_3x3_01, skyscraper_3x3_02, skyscraper_3x3_03

MustBeInsideWorldBorders: false

CanSpawnOnWater: true

SpawnOnWaterOnly: false

SpawnUnderWater: false

SpawnAtWaterLevel: false

HeightOffset: 0

RemoveAir: false

ReplaceAbove: 

ReplaceBelow: 

ReplaceWithBiomeBlocks: true

ReplaceWithSurfaceBlock: GRASS

ReplaceWithGroundBlock: DIRT

ReplaceWithStoneBlock: STONE

SmoothRadius: 0

SmoothHeightOffset: 0

SmoothStartTop: false

SmoothStartWood: false

SmoothingSurfaceBlock: 

SmoothingGroundBlock: 

BO3Group: 

IsSpawnPoint: false

DoReplaceBlocks: true


#######################################################################
# +-----------------------------------------------------------------+ #
# |                              Blocks                             | #
# +-----------------------------------------------------------------+ #
#######################################################################

Block(-8,0,-7,CONCRETE:7)
Block(-8,0,-6,CONCRETE:7)
Block(-8,0,-5,CONCRETE:7)
Block(-8,0,-4,CONCRETE:7)
Block(-8,0,-3,CONCRETE:7)
Block(-8,0,-2,CONCRETE:7)
Block(-8,0,-1,CONCRETE:7)
Block(-8,0,0,CONCRETE:7)
Block(-8,0,1,CONCRETE:7)
Block(-8,0,2,CONCRETE:7)
Block(-8,0,3,CONCRETE:7)
Block(-8,0,4,CONCRETE:7)
Block(-8,0,5,CONCRETE:7)
Block(-8,0,6,CONCRETE:7)
Block(-8,0,7,CONCRETE:7)
Block(-8,0,8,CONCRETE:7)
Block(-8,1,-7,CONCRETE:7)
Block(-8,1,-6,CONCRETE:7)
Block(-8,1,-5,CONCRETE:7)
Block(-8,1,-4,CONCRETE:7)
Block(-8,1,-3,CONCRETE:7)
Block(-8,1,-2,CONCRETE:7)
Block(-8,1,-1,CONCRETE:7)
Block(-8,1,0,CONCRETE:7)
Block(-8,1,1,CONCRETE:7)
Block(-8,1,2,CONCRETE:7)
Block(-8,1,3,CONCRETE:7)
Block(-8,1,4,CONCRETE:7)
Block(-8,1,5,CONCRETE:7)
Block(-8,1,6,CONCRETE:7)
Block(-8,1,7,CONCRETE:7)
Block(-8,1,8,CONCRETE:7)
Block(-8,2,-7,CONCRETE:7)
Block(-8,2,-6,CONCRETE:7)
Block(-8,2,-5,CONCRETE:7)
Block(-8,2,-4,CONCRETE:7)
Block(-8,2,-3,CONCRETE:7)
Block(-8,2,-2,CONCRETE:7)
Block(-8,2,-1,CONCRETE:7)
Block(-8,2,0,CONCRETE:7)
Block(-8,2,1,CONCRETE:7)
Block(-8,2,2,CONCRETE:7)
Block(-8,2,3,CONCRETE:7)
Block(-8,2,4,CONCRETE:7)
Block(-8,2,5,CONCRETE:7)
Block(-8,2,6,CONCRETE:7)
Block(-8,2,7,CONCRETE:7)
Block(-8,2,8,CONCRETE:7)
Block(-8,3,-7,CONCRETE:7)
Block(-8,3,-6,CONCRETE:7)
Block(-8,3,-5,CONCRETE:7)
Block(-8,3,-4,CONCRETE:7)
Block(-8,3,-3,CONCRETE:7)
Block(-8,3,-2,CONCRETE:7)
Block(-8,3,-1,CONCRETE:7)
Block(-8,3,0,CONCRETE:7)
Block(-8,3,1,CONCRETE:7)
Block(-8,3,2,CONCRETE:7)
Block(-8,3,3,CONCRETE:7)
Block(-8,3,4,CONCRETE:7)
Block(-8,3,5,CONCRETE:7)
Block(-8,3,6,CONCRETE:7)
Block(-8,3,7,CONCRETE:7)
Block(-8,3,8,CONCRETE:7)
Block(-8,4,-7,CONCRETE:7)
Block(-8,4,-6,CONCRETE:7)
Block(-8,4,-5,CONCRETE:7)
Block(-8,4,-4,CONCRETE:7)
Block(-8,4,-3,CONCRETE:7)
Block(-8,4,-2,CONCRETE:7)
Block(-8,4,-1,CONCRETE:7)
Block(-8,4,0,CONCRETE:7)
Block(-8,4,1,CONCRETE:7)
Block(-8,4,2,CONCRETE:7)
Block(-8,4,3,CONCRETE:7)
Block(-8,4,4,CONCRETE:7)
Block(-8,4,5,CONCRETE:7)
Block(-8,4,6,CONCRETE:7)
Block(-8,4,7,CONCRETE:7)
Block(-8,4,8,CONCRETE:7)
Block(-8,5,-7,CONCRETE:7)
Block(-8,5,-6,CONCRETE:7)
Block(-8,5,-5,CONCRETE:7)
Block(-8,5,-4,CONCRETE:7)
Block(-8,5,-3,CONCRETE:7)
Block(-8,5,-2,CONCRETE:7)
Block(-8,5,-1,CONCRETE:7)
Block(-8,5,0,CONCRETE:7)
Block(-8,5,1,CONCRETE:7)
Block(-8,5,2,CONCRETE:7)
Block(-8,5,3,CONCRETE:7)
Block(-8,5,4,CONCRETE:7)
Block(-8,5,5,CONCRETE:7)
Block(-8,5,6,CONCRETE:7)
Block(-8,5,7,CONCRETE:7)
Block(-8,5,8,CONCRETE:7)
Block(-8,6,-7,CONCRETE:7)
Block(-8,6,-6,CONCRETE:7)
Block(-8,6,-5,CONCRETE:7)
Block(-8,6,-4,CONCRETE:7)
Block(-8,6,-3,CONCRETE:7)
Block(-8,6,-2,CONCRETE:7)
Block(-8,6,-1,CONCRETE:7)
Block(-8,6,0,CONCRETE:7)
Block(-8,6,1,CONCRETE:7)
Block(-8,6,2,CONCRETE:7)
Block(-8,6,3,CONCRETE:7)
Block(-8,6,4,CONCRETE:7)
Block(-8,6,5,CONCRETE:7)
Block(-8,6,6,CONCRETE:7)
Block(-8,6,7,CONCRETE:7)
Block(-8,6,8,CONCRETE:7)
Block(-8,7,-7,CONCRETE:7)
Block(-8,7,-6,CONCRETE:7)
Block(-8,7,-5,CONCRETE:7)
Block(-8,7,-4,CONCRETE:7)
Block(-8,7,-3,CONCRETE:7)
Block(-8,7,-2,CONCRETE:7)
Block(-8,7,-1,CONCRETE:7)
Block(-8,7,0,CONCRETE:7)
Block(-8,7,1,CONCRETE:7)
Block(-8,7,2,CONCRETE:7)
Block(-8,7,3,CONCRETE:7)
Block(-8,7,4,CONCRETE:7)
Block(-8,7,5,CONCRETE:7)
Block(-8,7,6,CONCRETE:7)
Block(-8,7,7,CONCRETE:7)
Block(-8,7,8,CONCRETE:7)
Block(-8,8,-7,CONCRETE:7)
Block(-8,8,-6,CONCRETE:7)
Block(-8,8,-5,BRICK:0)
Block(-8,8,-4,CONCRETE:7)
Block(-8,8,-3,CONCRETE:7)
Block(-8,8,-2,CONCRETE:7)
Block(-8,8,-1,CONCRETE:7)
Block(-8,8,0,BRICK_STAIRS:5)
Block(-8,8,1,CONCRETE:7)
Block(-8,8,2,CONCRETE:7)
Block(-8,8,3,CONCRETE:7)
Block(-8,8,4,BRICK:0)
Block(-8,8,5,CONCRETE:7)
Block(-8,8,6,CONCRETE:7)
Block(-8,8,7,CONCRETE:7)
Block(-8,8,8,BRICK:0)
Block(-8,9,-7,CONCRETE:7)
Block(-8,9,-6,BRICK_STAIRS:1)
Block(-8,9,-5,BRICK_STAIRS:1)
Block(-8,9,-4,BRICK:0)
Block(-8,9,-3,CONCRETE:7)
Block(-8,9,-2,CONCRETE:7)
Block(-8,9,-1,BRICK_STAIRS:1)
Block(-8,9,0,CONCRETE:7)
Block(-8,9,1,CONCRETE:7)
Block(-8,9,2,CONCRETE:7)
Block(-8,9,3,CONCRETE:7)
Block(-8,9,4,CONCRETE:7)
Block(-8,9,5,CONCRETE:7)
Block(-8,9,6,CONCRETE:7)
Block(-8,9,7,BRICK:0)
Block(-8,9,8,BRICK:0)
Block(-8,10,-7,CONCRETE:7)
Block(-8,10,-6,CONCRETE:7)
Block(-8,10,-5,BRICK_STAIRS:5)
Block(-8,10,-4,BRICK:0)
Block(-8,10,-3,BRICK:0)
Block(-8,10,-2,CONCRETE:7)
Block(-8,10,-1,BRICK_STAIRS:5)
Block(-8,10,0,CONCRETE:7)
Block(-8,10,1,CONCRETE:7)
Block(-8,10,2,CONCRETE:7)
Block(-8,10,3,BRICK:0)
Block(-8,10,4,BRICK:0)
Block(-8,10,5,CONCRETE:7)
Block(-8,10,6,CONCRETE:7)
Block(-8,10,7,CONCRETE:7)
Block(-8,10,8,CONCRETE:7)
Block(-8,11,-7,BRICK_STAIRS:1)
Block(-8,11,-6,BRICK_STAIRS:2)
Block(-8,11,-5,BRICK:0)
Block(-8,11,-4,BRICK_STAIRS:7)
Block(-8,11,-3,BRICK_STAIRS:5)
Block(-8,11,-2,CONCRETE:7)
Block(-8,11,-1,CONCRETE:7)
Block(-8,11,0,CONCRETE:7)
Block(-8,11,1,BRICK_STAIRS:1)
Block(-8,11,2,BRICK:0)
Block(-8,11,3,BRICK:0)
Block(-8,11,4,BRICK:0)
Block(-8,11,5,CONCRETE:7)
Block(-8,11,6,CONCRETE:7)
Block(-8,11,7,CONCRETE:7)
Block(-8,11,8,CONCRETE:7)
Block(-8,12,-7,BRICK_STAIRS:7)
Block(-8,12,-6,BRICK_STAIRS:5)
Block(-8,12,-5,BRICK_STAIRS:1)
Block(-8,12,-4,BRICK_STAIRS:5)
Block(-8,12,-3,CONCRETE:7)
Block(-8,12,-2,CONCRETE:7)
Block(-8,12,-1,CONCRETE:7)
Block(-8,12,0,BRICK_STAIRS:5)
Block(-8,12,1,BRICK_STAIRS:5)
Block(-8,12,2,BRICK:0)
Block(-8,12,3,BRICK:0)
Block(-8,12,4,BRICK:0)
Block(-8,12,5,CONCRETE:7)
Block(-8,12,6,CONCRETE:7)
Block(-8,12,7,CONCRETE:7)
Block(-8,12,8,CONCRETE:7)
Block(-8,13,-7,CONCRETE:7)
Block(-8,13,-6,BRICK:0)
Block(-8,13,-5,BRICK:0)
Block(-8,13,-4,CONCRETE:7)
Block(-8,13,-3,CONCRETE:7)
Block(-8,13,-2,CONCRETE:7)
Block(-8,13,-1,CONCRETE:7)
Block(-8,13,0,CONCRETE:7)
Block(-8,13,1,BRICK:0)
Block(-8,13,2,CONCRETE:7)
Block(-8,13,3,CONCRETE:7)
Block(-8,13,4,BRICK:0)
Block(-8,13,5,BRICK:0)
Block(-8,13,6,CONCRETE:7)
Block(-8,13,7,CONCRETE:7)
Block(-8,13,8,BRICK:0)
Block(-8,14,-7,CONCRETE:7)
Block(-8,14,-6,CONCRETE:7)
Block(-8,14,-5,CONCRETE:7)
Block(-8,14,-4,CONCRETE:7)
Block(-8,14,-3,CONCRETE:7)
Block(-8,14,-2,CONCRETE:7)
Block(-8,14,-1,CONCRETE:7)
Block(-8,14,0,CONCRETE:7)
Block(-8,14,1,CONCRETE:7)
Block(-8,14,2,BRICK:0)
Block(-8,14,3,CONCRETE:7)
Block(-8,14,4,BRICK:0)
Block(-8,14,5,BRICK:0)
Block(-8,14,6,CONCRETE:7)
Block(-8,14,7,CONCRETE:7)
Block(-8,14,8,CONCRETE:7)
Block(-8,15,-7,CONCRETE:7)
Block(-8,15,-6,CONCRETE:7)
Block(-8,15,-5,CONCRETE:7)
Block(-8,15,-4,CONCRETE:7)
Block(-8,15,-3,CONCRETE:7)
Block(-8,15,-2,CONCRETE:7)
Block(-8,15,-1,CONCRETE:7)
Block(-8,15,0,CONCRETE:7)
Block(-8,15,1,CONCRETE:7)
Block(-8,15,2,CONCRETE:7)
Block(-8,15,3,BRICK:0)
Block(-8,15,4,BRICK:0)
Block(-8,15,5,CONCRETE:7)
Block(-8,15,6,CONCRETE:7)
Block(-8,15,7,CONCRETE:7)
Block(-8,15,8,CONCRETE:7)
Block(-8,16,-7,CONCRETE:7)
Block(-8,16,-6,CONCRETE:7)
Block(-8,16,-5,CONCRETE:7)
Block(-8,16,-4,CONCRETE:7)
Block(-8,16,-3,CONCRETE:7)
Block(-8,16,-2,CONCRETE:7)
Block(-8,16,-1,CONCRETE:7)
Block(-8,16,0,CONCRETE:7)
Block(-8,16,1,CONCRETE:7)
Block(-8,16,2,CONCRETE:7)
Block(-8,16,3,CONCRETE:7)
Block(-8,16,4,CONCRETE:7)
Block(-8,16,5,CONCRETE:7)
Block(-8,16,6,CONCRETE:7)
Block(-8,16,7,CONCRETE:7)
Block(-8,16,8,CONCRETE:7)
Block(-8,17,-7,SMOOTH_STAIRS:0)
Block(-8,17,-6,SMOOTH_STAIRS:0)
Block(-8,17,-5,SMOOTH_STAIRS:0)
Block(-8,17,-4,CONCRETE:15)
Block(-8,17,-3,CONCRETE:15)
Block(-8,17,-2,CONCRETE:15)
Block(-8,17,-1,CONCRETE:15)
Block(-8,17,0,CONCRETE:15)
Block(-8,17,1,CONCRETE:15)
Block(-8,17,2,SMOOTH_STAIRS:0)
Block(-8,17,3,SMOOTH_STAIRS:0)
Block(-8,17,4,SMOOTH_STAIRS:0)
Block(-8,17,5,SMOOTH_STAIRS:0)
Block(-8,17,6,CONCRETE:15)
Block(-8,17,7,CONCRETE:15)
Block(-8,17,8,CONCRETE:15)
Block(-8,28,-7,SMOOTH_STAIRS:4)
Block(-8,28,-6,SMOOTH_STAIRS:4)
Block(-8,28,-5,SMOOTH_STAIRS:4)
Block(-8,29,-7,CONCRETE:15)
Block(-8,29,-6,CONCRETE:7)
Block(-8,29,-5,CONCRETE:7)
Block(-8,29,-4,SMOOTH_STAIRS:4)
Block(-8,29,-3,SMOOTH_STAIRS:4)
Block(-8,29,-2,STEP:8)
Block(-8,29,-1,SMOOTH_STAIRS:4)
Block(-8,29,0,STEP:8)
Block(-8,29,1,SMOOTH_STAIRS:4)
Block(-8,29,2,STEP:8)
Block(-8,29,3,SMOOTH_STAIRS:4)
Block(-8,29,4,SMOOTH_STAIRS:4)
Block(-8,29,5,SMOOTH_STAIRS:4)
Block(-8,29,6,STEP:8)
Block(-8,29,7,STEP:8)
Block(-8,30,-7,STAINED_GLASS_PANE:7)
Block(-8,30,-6,STAINED_GLASS_PANE:7)
Block(-8,30,-5,CONCRETE:15)
Block(-8,30,-4,CONCRETE:7)
Block(-8,30,-3,CONCRETE:7)
Block(-8,30,-2,SMOOTH_STAIRS:7)
Block(-8,30,-1,IRON_FENCE:0)
Block(-8,30,1,IRON_FENCE:0)
Block(-8,30,3,IRON_FENCE:0)
Block(-8,30,5,COBBLE_WALL:0)
Block(-8,31,-7,STAINED_GLASS_PANE:7)
Block(-8,31,-6,STAINED_GLASS_PANE:7)
Block(-8,31,-5,STAINED_GLASS_PANE:7)
Block(-8,31,-4,STAINED_GLASS_PANE:7)
Block(-8,31,-3,CONCRETE:15)
Block(-8,31,-2,CONCRETE:7)
Block(-8,32,-7,STAINED_GLASS_PANE:7)
Block(-8,32,-6,STAINED_GLASS_PANE:7)
Block(-8,32,-5,STAINED_GLASS_PANE:7)
Block(-8,32,-4,STAINED_GLASS_PANE:7)
Block(-8,32,-3,STAINED_GLASS_PANE:7)
Block(-8,32,-2,CONCRETE:7)
Block(-8,32,-1,SMOOTH_STAIRS:7)
Block(-8,33,-7,STAINED_GLASS_PANE:7)
Block(-8,33,-6,STAINED_GLASS_PANE:7)
Block(-8,33,-5,STAINED_GLASS_PANE:7)
Block(-8,33,-4,STAINED_GLASS_PANE:7)
Block(-8,33,-3,STAINED_GLASS_PANE:7)
Block(-8,33,-2,CONCRETE:15)
Block(-8,33,-1,CONCRETE:7)
Block(-8,34,-7,STAINED_GLASS_PANE:7)
Block(-8,34,-6,STAINED_GLASS_PANE:7)
Block(-8,34,-5,STAINED_GLASS_PANE:7)
Block(-8,34,-4,STAINED_GLASS_PANE:7)
Block(-8,34,-3,STAINED_GLASS_PANE:7)
Block(-8,34,-2,STAINED_GLASS_PANE:7)
Block(-8,34,-1,CONCRETE:7)
Block(-8,34,0,SMOOTH_STAIRS:7)
Block(-8,35,-7,STAINED_GLASS_PANE:7)
Block(-8,35,-6,STAINED_GLASS_PANE:7)
Block(-8,35,-5,STAINED_GLASS_PANE:7)
Block(-8,35,-4,STAINED_GLASS_PANE:7)
Block(-8,35,-3,STAINED_GLASS_PANE:7)
Block(-8,35,-2,STAINED_GLASS_PANE:7)
Block(-8,35,-1,CONCRETE:15)
Block(-8,35,0,COBBLE_WALL:0)
Block(-8,36,-7,STAINED_GLASS_PANE:7)
Block(-8,36,-6,STAINED_GLASS_PANE:7)
Block(-8,36,-5,STAINED_GLASS_PANE:7)
Block(-8,36,-4,STAINED_GLASS_PANE:7)
Block(-8,36,-3,STAINED_GLASS_PANE:7)
Block(-8,36,-2,STAINED_GLASS_PANE:7)
Block(-8,36,-1,CONCRETE:15)
Block(-8,36,0,COBBLE_WALL:0)
Block(-8,37,-7,STAINED_GLASS_PANE:7)
Block(-8,37,-6,STAINED_GLASS_PANE:7)
Block(-8,37,-5,STAINED_GLASS_PANE:7)
Block(-8,37,-4,STAINED_GLASS_PANE:7)
Block(-8,37,-3,STAINED_GLASS_PANE:7)
Block(-8,37,-2,STAINED_GLASS_PANE:7)
Block(-8,37,-1,CONCRETE:7)
Block(-8,37,0,SMOOTH_STAIRS:3)
Block(-8,38,-7,STAINED_GLASS_PANE:7)
Block(-8,38,-6,STAINED_GLASS_PANE:7)
Block(-8,38,-5,STAINED_GLASS_PANE:7)
Block(-8,38,-4,STAINED_GLASS_PANE:7)
Block(-8,38,-3,STAINED_GLASS_PANE:7)
Block(-8,38,-2,CONCRETE:15)
Block(-8,38,-1,CONCRETE:7)
Block(-8,39,-7,STAINED_GLASS_PANE:7)
Block(-8,39,-6,STAINED_GLASS_PANE:7)
Block(-8,39,-5,STAINED_GLASS_PANE:7)
Block(-8,39,-4,STAINED_GLASS_PANE:7)
Block(-8,39,-3,STAINED_GLASS_PANE:7)
Block(-8,39,-2,CONCRETE:7)
Block(-8,39,-1,SMOOTH_STAIRS:3)
Block(-8,40,-7,STAINED_GLASS_PANE:7)
Block(-8,40,-6,STAINED_GLASS_PANE:7)
Block(-8,40,-5,STAINED_GLASS_PANE:7)
Block(-8,40,-4,STAINED_GLASS_PANE:7)
Block(-8,40,-3,CONCRETE:15)
Block(-8,40,-2,CONCRETE:7)
Block(-8,41,-7,STAINED_GLASS_PANE:7)
Block(-8,41,-6,STAINED_GLASS_PANE:7)
Block(-8,41,-5,CONCRETE:15)
Block(-8,41,-4,CONCRETE:7)
Block(-8,41,-3,CONCRETE:7)
Block(-8,41,-2,SMOOTH_STAIRS:3)
Block(-8,42,-7,CONCRETE:15)
Block(-8,42,-6,CONCRETE:7)
Block(-8,42,-5,CONCRETE:7)
Block(-8,42,-4,SMOOTH_STAIRS:3)
Block(-8,43,-7,SMOOTH_STAIRS:0)
Block(-8,43,-6,SMOOTH_STAIRS:3)
Block(-8,77,-4,IRON_TRAPDOOR:6)
Block(-8,78,-4,IRON_TRAPDOOR:14)
Block(-8,116,-1,IRON_TRAPDOOR:6)
Block(-8,117,-1,IRON_TRAPDOOR:14)
Block(-8,126,-6,IRON_FENCE:0)
Block(-8,127,-6,IRON_FENCE:0)
Block(-8,128,-6,IRON_FENCE:0)
Block(-8,129,-6,IRON_FENCE:0)
Block(-8,130,-6,IRON_FENCE:0)
Block(-8,131,-6,IRON_FENCE:0)
Block(-8,132,-6,IRON_FENCE:0)
Block(-8,133,-6,COBBLE_WALL:0)
Block(-8,134,-6,CONCRETE:8)
Block(-8,139,-4,SMOOTH_STAIRS:4)
Block(-8,140,-5,STEP:0)
Block(-8,140,-4,SMOOTH_STAIRS:1)
Block(-8,140,-3,STEP:0)
Block(-8,141,-4,SKULL:1,NBT/skyscraper_2x2_02/2-skullC0R16.nbt)
Block(-7,0,-7,CONCRETE:7)
Block(-7,0,-6,CONCRETE:7)
Block(-7,0,-5,CONCRETE:7)
Block(-7,0,-4,CONCRETE:7)
Block(-7,0,-3,CONCRETE:7)
Block(-7,0,-2,CONCRETE:7)
Block(-7,0,-1,CONCRETE:7)
Block(-7,0,0,CONCRETE:7)
Block(-7,0,1,CONCRETE:7)
Block(-7,0,2,CONCRETE:7)
Block(-7,0,3,CONCRETE:7)
Block(-7,0,4,CONCRETE:7)
Block(-7,0,5,CONCRETE:7)
Block(-7,0,6,CONCRETE:7)
Block(-7,0,7,CONCRETE:7)
Block(-7,0,8,CONCRETE:7)
Block(-7,1,-7,CONCRETE:7)
Block(-7,1,-6,CONCRETE:7)
Block(-7,1,-5,CONCRETE:7)
Block(-7,1,-4,CONCRETE:7)
Block(-7,1,-3,CONCRETE:7)
Block(-7,1,-2,CONCRETE:7)
Block(-7,1,-1,CONCRETE:7)
Block(-7,1,0,CONCRETE:7)
Block(-7,1,1,CONCRETE:7)
Block(-7,1,2,CONCRETE:7)
Block(-7,1,3,CONCRETE:7)
Block(-7,1,4,CONCRETE:7)
Block(-7,1,5,CONCRETE:7)
Block(-7,1,6,CONCRETE:7)
Block(-7,1,7,CONCRETE:7)
Block(-7,1,8,CONCRETE:7)
Block(-7,2,-7,CONCRETE:7)
Block(-7,2,-6,CONCRETE:7)
Block(-7,2,-5,CONCRETE:7)
Block(-7,2,-4,CONCRETE:7)
Block(-7,2,-3,CONCRETE:7)
Block(-7,2,-2,CONCRETE:7)
Block(-7,2,-1,CONCRETE:7)
Block(-7,2,0,CONCRETE:7)
Block(-7,2,1,CONCRETE:7)
Block(-7,2,2,CONCRETE:7)
Block(-7,2,3,CONCRETE:7)
Block(-7,2,4,CONCRETE:7)
Block(-7,2,5,CONCRETE:7)
Block(-7,2,6,CONCRETE:7)
Block(-7,2,7,CONCRETE:7)
Block(-7,2,8,CONCRETE:7)
Block(-7,3,-7,CONCRETE:7)
Block(-7,3,-6,CONCRETE:7)
Block(-7,3,-5,CONCRETE:7)
Block(-7,3,-4,CONCRETE:7)
Block(-7,3,-3,CONCRETE:7)
Block(-7,3,-2,CONCRETE:7)
Block(-7,3,-1,CONCRETE:7)
Block(-7,3,0,CONCRETE:7)
Block(-7,3,1,CONCRETE:7)
Block(-7,3,2,CONCRETE:7)
Block(-7,3,3,CONCRETE:7)
Block(-7,3,4,CONCRETE:7)
Block(-7,3,5,CONCRETE:7)
Block(-7,3,6,CONCRETE:7)
Block(-7,3,7,CONCRETE:7)
Block(-7,3,8,CONCRETE:7)
Block(-7,4,-7,CONCRETE:7)
Block(-7,4,-6,CONCRETE:7)
Block(-7,4,-5,CONCRETE:7)
Block(-7,4,-4,CONCRETE:7)
Block(-7,4,-3,CONCRETE:7)
Block(-7,4,-2,CONCRETE:7)
Block(-7,4,-1,CONCRETE:7)
Block(-7,4,0,CONCRETE:7)
Block(-7,4,1,CONCRETE:7)
Block(-7,4,2,CONCRETE:7)
Block(-7,4,3,CONCRETE:7)
Block(-7,4,4,CONCRETE:7)
Block(-7,4,5,CONCRETE:7)
Block(-7,4,6,CONCRETE:7)
Block(-7,4,7,CONCRETE:7)
Block(-7,4,8,CONCRETE:7)
Block(-7,5,-7,CONCRETE:7)
Block(-7,5,-6,CONCRETE:7)
Block(-7,5,-5,CONCRETE:7)
Block(-7,5,-4,CONCRETE:7)
Block(-7,5,-3,CONCRETE:7)
Block(-7,5,-2,CONCRETE:7)
Block(-7,5,-1,CONCRETE:7)
Block(-7,5,0,CONCRETE:7)
Block(-7,5,1,CONCRETE:7)
Block(-7,5,2,CONCRETE:7)
Block(-7,5,3,CONCRETE:7)
Block(-7,5,4,CONCRETE:7)
Block(-7,5,5,CONCRETE:7)
Block(-7,5,6,CONCRETE:7)
Block(-7,5,7,CONCRETE:7)
Block(-7,5,8,CONCRETE:7)
Block(-7,6,-7,CONCRETE:7)
Block(-7,6,-6,CONCRETE:7)
Block(-7,6,-5,CONCRETE:7)
Block(-7,6,-4,CONCRETE:7)
Block(-7,6,-3,CONCRETE:7)
Block(-7,6,-2,CONCRETE:7)
Block(-7,6,-1,CONCRETE:7)
Block(-7,6,0,CONCRETE:7)
Block(-7,6,1,CONCRETE:7)
Block(-7,6,2,CONCRETE:7)
Block(-7,6,3,CONCRETE:7)
Block(-7,6,4,CONCRETE:7)
Block(-7,6,5,CONCRETE:7)
Block(-7,6,6,CONCRETE:7)
Block(-7,6,7,CONCRETE:7)
Block(-7,6,8,CONCRETE:7)
Block(-7,7,-7,CONCRETE:15)
Block(-7,7,-6,CONCRETE:15)
Block(-7,7,-5,CONCRETE:15)
Block(-7,7,-4,CONCRETE:15)
Block(-7,7,-3,CONCRETE:15)
Block(-7,7,-2,CONCRETE:15)
Block(-7,7,-1,CONCRETE:15)
Block(-7,7,0,CONCRETE:15)
Block(-7,7,1,CONCRETE:15)
Block(-7,7,2,CONCRETE:15)
Block(-7,7,3,CONCRETE:15)
Block(-7,7,4,CONCRETE:15)
Block(-7,7,5,CONCRETE:15)
Block(-7,7,6,CONCRETE:7)
Block(-7,7,7,CONCRETE:15)
Block(-7,7,8,CONCRETE:7)
Block(-7,8,-2,QUARTZ_STAIRS:2)
Block(-7,8,-1,QUARTZ_STAIRS:7)
Block(-7,8,0,CONCRETE:15)
Block(-7,8,1,CONCRETE:15)
Block(-7,8,2,CONCRETE:7)
Block(-7,8,3,BRICK:0)
Block(-7,8,4,BRICK_STAIRS:5)
Block(-7,8,5,BRICK:0)
Block(-7,8,6,CONCRETE:7)
Block(-7,8,7,CONCRETE:7)
Block(-7,8,8,BRICK:0)
Block(-7,9,-1,QUARTZ_STAIRS:2)
Block(-7,9,0,CONCRETE:7)
Block(-7,9,1,CONCRETE:7)
Block(-7,9,2,CONCRETE:7)
Block(-7,9,3,CONCRETE:7)
Block(-7,9,4,BRICK:0)
Block(-7,9,5,CONCRETE:7)
Block(-7,9,6,CONCRETE:7)
Block(-7,9,7,CONCRETE:7)
Block(-7,9,8,CONCRETE:7)
Block(-7,10,2,BRICK_STAIRS:2)
Block(-7,10,3,CONCRETE:7)
Block(-7,10,4,CONCRETE:7)
Block(-7,10,5,CONCRETE:7)
Block(-7,10,8,CONCRETE:7)
Block(-7,11,2,BRICK:0)
Block(-7,11,3,CONCRETE:7)
Block(-7,11,4,CONCRETE:7)
Block(-7,11,5,PRISMARINE:0)
Block(-7,11,8,CONCRETE:7)
Block(-7,12,2,CONCRETE:7)
Block(-7,12,3,CONCRETE:7)
Block(-7,12,4,CONCRETE:7)
Block(-7,12,5,CONCRETE:7)
Block(-7,12,8,CONCRETE:7)
Block(-7,13,-6,SMOOTH_STAIRS:5)
Block(-7,13,-3,SMOOTH_STAIRS:5)
Block(-7,13,-1,SMOOTH_STAIRS:5)
Block(-7,13,2,BRICK:0)
Block(-7,13,3,CONCRETE:7)
Block(-7,13,4,CONCRETE:7)
Block(-7,13,5,CONCRETE:7)
Block(-7,13,6,CONCRETE:7)
Block(-7,13,7,CONCRETE:7)
Block(-7,13,8,CONCRETE:7)
Block(-7,14,-7,SMOOTH_STAIRS:5)
Block(-7,14,-6,BRICK:0)
Block(-7,14,-5,SMOOTH_STAIRS:5)
Block(-7,14,-4,SMOOTH_STAIRS:5)
Block(-7,14,-3,CONCRETE:7)
Block(-7,14,-2,SMOOTH_STAIRS:5)
Block(-7,14,-1,CONCRETE:7)
Block(-7,14,0,SMOOTH_STAIRS:5)
Block(-7,14,1,SMOOTH_STAIRS:5)
Block(-7,14,2,CONCRETE:7)
Block(-7,14,3,CONCRETE:7)
Block(-7,14,4,STAINED_GLASS_PANE:0)
Block(-7,14,5,STAINED_GLASS_PANE:0)
Block(-7,14,8,CONCRETE:7)
Block(-7,15,-7,CONCRETE:7)
Block(-7,15,-6,CONCRETE:7)
Block(-7,15,-5,CONCRETE:7)
Block(-7,15,-4,CONCRETE:7)
Block(-7,15,-3,CONCRETE:7)
Block(-7,15,-2,CONCRETE:7)
Block(-7,15,-1,CONCRETE:7)
Block(-7,15,0,CONCRETE:7)
Block(-7,15,1,CONCRETE:7)
Block(-7,15,2,CONCRETE:7)
Block(-7,15,3,CONCRETE:7)
Block(-7,15,4,CONCRETE:7)
Block(-7,15,5,CONCRETE:7)
Block(-7,15,6,CONCRETE:7)
Block(-7,15,7,CONCRETE:7)
Block(-7,15,8,CONCRETE:7)
Block(-7,16,-7,CONCRETE:7)
Block(-7,16,-6,CONCRETE:7)
Block(-7,16,-5,CONCRETE:7)
Block(-7,16,-4,CONCRETE:7)
Block(-7,16,-3,CONCRETE:7)
Block(-7,16,-2,CONCRETE:7)
Block(-7,16,-1,CONCRETE:7)
Block(-7,16,0,CONCRETE:7)
Block(-7,16,1,CONCRETE:7)
Block(-7,16,2,CONCRETE:7)
Block(-7,16,3,CONCRETE:7)
Block(-7,16,4,CONCRETE:7)
Block(-7,16,5,CONCRETE:7)
Block(-7,16,6,CONCRETE:7)
Block(-7,16,7,CONCRETE:7)
Block(-7,16,8,CONCRETE:7)
Block(-7,17,-7,CONCRETE:7)
Block(-7,17,-6,CONCRETE:7)
Block(-7,17,-5,CONCRETE:7)
Block(-7,17,-4,CONCRETE:7)
Block(-7,17,-3,CONCRETE:7)
Block(-7,17,-2,CONCRETE:7)
Block(-7,17,-1,CONCRETE:7)
Block(-7,17,0,CONCRETE:7)
Block(-7,17,1,CONCRETE:7)
Block(-7,17,2,CONCRETE:7)
Block(-7,17,3,CONCRETE:7)
Block(-7,17,4,CONCRETE:7)
Block(-7,17,5,CONCRETE:7)
Block(-7,17,6,CONCRETE:7)
Block(-7,17,7,CONCRETE:7)
Block(-7,17,8,CONCRETE:15)
Block(-7,18,-7,CONCRETE:7)
Block(-7,18,-6,CONCRETE:8)
Block(-7,18,-5,CONCRETE:7)
Block(-7,18,-4,SMOOTH_STAIRS:0)
Block(-7,18,-3,SMOOTH_STAIRS:3)
Block(-7,18,3,SMOOTH_STAIRS:0)
Block(-7,18,4,CONCRETE:0)
Block(-7,18,5,SMOOTH_STAIRS:0)
Block(-7,19,-7,STAINED_GLASS_PANE:7)
Block(-7,19,-6,STAINED_GLASS_PANE:7)
Block(-7,19,-5,CONCRETE:7)
Block(-7,19,4,SMOOTH_STAIRS:0)
Block(-7,20,-7,STAINED_GLASS_PANE:7)
Block(-7,20,-6,STAINED_GLASS_PANE:7)
Block(-7,20,-5,STEP:0)
Block(-7,21,-7,STAINED_GLASS_PANE:7)
Block(-7,21,-6,STAINED_GLASS_PANE:7)
Block(-7,22,-7,STAINED_GLASS_PANE:7)
Block(-7,22,-6,STAINED_GLASS_PANE:7)
Block(-7,23,-7,STAINED_GLASS_PANE:7)
Block(-7,23,-6,STAINED_GLASS_PANE:7)
Block(-7,24,-7,STAINED_GLASS_PANE:7)
Block(-7,24,-6,STAINED_GLASS_PANE:7)
Block(-7,25,-7,STAINED_GLASS_PANE:7)
Block(-7,25,-6,STAINED_GLASS_PANE:7)
Block(-7,25,-5,STEP:8)
Block(-7,26,-7,STAINED_GLASS_PANE:7)
Block(-7,26,-6,STAINED_GLASS_PANE:7)
Block(-7,26,-5,CONCRETE:7)
Block(-7,26,4,SMOOTH_STAIRS:4)
Block(-7,27,-7,CONCRETE:7)
Block(-7,27,-6,CONCRETE:8)
Block(-7,27,-5,CONCRETE:7)
Block(-7,27,-4,SMOOTH_STAIRS:4)
Block(-7,27,-3,SMOOTH_STAIRS:7)
Block(-7,27,3,SMOOTH_STAIRS:4)
Block(-7,27,4,CONCRETE:0)
Block(-7,27,5,SMOOTH_STAIRS:4)
Block(-7,28,-7,CONCRETE:7)
Block(-7,28,-6,CONCRETE:7)
Block(-7,28,-5,CONCRETE:7)
Block(-7,28,-4,CONCRETE:15)
Block(-7,28,-3,CONCRETE:15)
Block(-7,28,-2,SMOOTH_STAIRS:4)
Block(-7,28,-1,CONCRETE:15)
Block(-7,28,0,SMOOTH_STAIRS:4)
Block(-7,28,1,CONCRETE:15)
Block(-7,28,2,SMOOTH_STAIRS:4)
Block(-7,28,3,CONCRETE:7)
Block(-7,28,4,CONCRETE:7)
Block(-7,28,5,CONCRETE:15)
Block(-7,28,6,SMOOTH_STAIRS:4)
Block(-7,28,7,CONCRETE:15)
Block(-7,29,-7,CONCRETE:7)
Block(-7,29,-6,CONCRETE:7)
Block(-7,29,-5,CONCRETE:7)
Block(-7,29,-4,CONCRETE:7)
Block(-7,29,-3,CONCRETE:7)
Block(-7,29,-2,CONCRETE:7)
Block(-7,29,-1,CONCRETE:7)
Block(-7,29,0,CONCRETE:7)
Block(-7,29,1,CONCRETE:7)
Block(-7,29,2,CONCRETE:7)
Block(-7,29,3,CONCRETE:7)
Block(-7,29,4,CONCRETE:7)
Block(-7,29,5,CONCRETE:7)
Block(-7,29,6,CONCRETE:7)
Block(-7,29,7,CONCRETE:7)
Block(-7,29,8,STEP:8)
Block(-7,30,-5,CONCRETE:15)
Block(-7,30,-4,CONCRETE:15)
Block(-7,30,-3,CONCRETE:7)
Block(-7,30,-2,CONCRETE:7)
Block(-7,30,-1,CONCRETE:7)
Block(-7,30,0,STEP:0)
Block(-7,30,1,CONCRETE:7)
Block(-7,30,2,SMOOTH_STAIRS:4)
Block(-7,30,3,CONCRETE:7)
Block(-7,30,4,CONCRETE:15)
Block(-7,30,5,CONCRETE:15)
Block(-7,30,6,CONCRETE:8)
Block(-7,30,7,STEP:0)
Block(-7,31,-3,CONCRETE:15)
Block(-7,31,-2,CONCRETE:7)
Block(-7,31,-1,CONCRETE:7)
Block(-7,31,0,SMOOTH_STAIRS:4)
Block(-7,31,1,CONCRETE:7)
Block(-7,31,2,CONCRETE:7)
Block(-7,31,3,CONCRETE:15)
Block(-7,31,4,CONCRETE:8)
Block(-7,31,5,CONCRETE:8)
Block(-7,32,-2,CONCRETE:15)
Block(-7,32,-1,CONCRETE:7)
Block(-7,32,0,CONCRETE:7)
Block(-7,32,1,CONCRETE:7)
Block(-7,32,2,CONCRETE:15)
Block(-7,32,3,CONCRETE:8)
Block(-7,32,4,SMOOTH_STAIRS:3)
Block(-7,33,-2,CONCRETE:15)
Block(-7,33,-1,CONCRETE:7)
Block(-7,33,0,CONCRETE:7)
Block(-7,33,1,CONCRETE:15)
Block(-7,33,2,CONCRETE:8)
Block(-7,33,3,SMOOTH_STAIRS:0)
Block(-7,34,-1,CONCRETE:15)
Block(-7,34,0,CONCRETE:7)
Block(-7,34,1,CONCRETE:15)
Block(-7,34,2,CONCRETE:8)
Block(-7,35,-7,CONCRETE:15)
Block(-7,35,-1,CONCRETE:15)
Block(-7,35,0,CONCRETE:15)
Block(-7,35,1,CONCRETE:8)
Block(-7,35,2,SMOOTH_STAIRS:3)
Block(-7,36,-7,CONCRETE:15)
Block(-7,36,-1,CONCRETE:15)
Block(-7,36,0,CONCRETE:15)
Block(-7,36,1,CONCRETE:8)
Block(-7,37,-1,CONCRETE:15)
Block(-7,37,0,CONCRETE:15)
Block(-7,37,1,CONCRETE:8)
Block(-7,38,-2,CONCRETE:15)
Block(-7,38,-1,CONCRETE:7)
Block(-7,38,0,STEP:0)
Block(-7,38,1,CONCRETE:8)
Block(-7,38,2,SMOOTH_STAIRS:7)
Block(-7,39,-2,CONCRETE:15)
Block(-7,39,-1,CONCRETE:7)
Block(-7,39,1,STEP:0)
Block(-7,39,2,CONCRETE:8)
Block(-7,40,-3,CONCRETE:15)
Block(-7,40,-2,CONCRETE:7)
Block(-7,40,2,CONCRETE:8)
Block(-7,40,3,SMOOTH_STAIRS:4)
Block(-7,40,7,SEA_LANTERN:0)
Block(-7,41,-5,CONCRETE:15)
Block(-7,41,-4,CONCRETE:15)
Block(-7,41,-3,CONCRETE:7)
Block(-7,41,-2,CONCRETE:7)
Block(-7,41,2,STEP:0)
Block(-7,41,3,CONCRETE:8)
Block(-7,41,4,SMOOTH_STAIRS:7)
Block(-7,41,7,IRON_FENCE:0)
Block(-7,42,-7,CONCRETE:15)
Block(-7,42,-6,CONCRETE:15)
Block(-7,42,-5,CONCRETE:7)
Block(-7,42,-4,CONCRETE:7)
Block(-7,42,-3,STEP:0)
Block(-7,42,3,STEP:0)
Block(-7,42,4,CONCRETE:8)
Block(-7,42,5,CONCRETE:8)
Block(-7,42,7,IRON_FENCE:0)
Block(-7,43,-7,CONCRETE:7)
Block(-7,43,-6,CONCRETE:7)
Block(-7,43,-5,STEP:0)
Block(-7,43,4,STEP:0)
Block(-7,43,5,STEP:0)
Block(-7,43,6,CONCRETE:8)
Block(-7,43,7,IRON_FENCE:0)
Block(-7,44,-7,IRON_FENCE:0)
Block(-7,44,-6,CONCRETE:7)
Block(-7,44,6,STEP:0)
Block(-7,44,7,CONCRETE:8)
Block(-7,45,-6,CONCRETE:7)
Block(-7,45,7,CONCRETE:8)
Block(-7,46,-6,COBBLE_WALL:0)
Block(-7,46,7,STEP:0)
Block(-7,47,-4,SMOOTH_STAIRS:4)
Block(-7,48,-4,CONCRETE:15)
Block(-7,49,-4,CONCRETE:15)
Block(-7,70,-6,IRON_FENCE:0)
Block(-7,71,-6,IRON_FENCE:0)
Block(-7,72,-6,IRON_FENCE:0)
Block(-7,73,-6,IRON_FENCE:0)
Block(-7,74,-6,IRON_FENCE:0)
Block(-7,75,-6,IRON_FENCE:0)
Block(-7,75,-4,IRON_FENCE:0)
Block(-7,76,-6,IRON_FENCE:0)
Block(-7,76,-4,SMOOTH_STAIRS:6)
Block(-7,77,-6,IRON_FENCE:0)
Block(-7,77,-5,IRON_TRAPDOOR:12)
Block(-7,77,-4,LEVER:13)
Block(-7,78,-6,IRON_FENCE:0)
Block(-7,78,-5,IRON_TRAPDOOR:12)
Block(-7,78,-4,LEVER:15)
Block(-7,78,-1,IRON_FENCE:0)
Block(-7,79,-6,IRON_FENCE:0)
Block(-7,79,-4,SMOOTH_STAIRS:2)
Block(-7,79,-1,IRON_FENCE:0)
Block(-7,80,-6,IRON_FENCE:0)
Block(-7,80,-4,IRON_FENCE:0)
Block(-7,80,-1,IRON_FENCE:0)
Block(-7,81,-6,COBBLE_WALL:0)
Block(-7,81,-4,IRON_FENCE:0)
Block(-7,81,-1,IRON_FENCE:0)
Block(-7,82,-6,CONCRETE:8)
Block(-7,82,-4,IRON_FENCE:0)
Block(-7,82,-1,IRON_FENCE:0)
Block(-7,83,-6,SMOOTH_STAIRS:0)
Block(-7,83,-4,IRON_FENCE:0)
Block(-7,83,-1,IRON_FENCE:0)
Block(-7,84,-5,SMOOTH_STAIRS:4)
Block(-7,84,-4,COBBLE_WALL:0)
Block(-7,84,-1,COBBLE_WALL:0)
Block(-7,85,-7,SMOOTH_STAIRS:4)
Block(-7,85,-5,CONCRETE:7)
Block(-7,85,-4,CONCRETE:8)
Block(-7,85,-1,CONCRETE:8)
Block(-7,86,-7,CONCRETE:7)
Block(-7,86,-5,CONCRETE:7)
Block(-7,86,-4,SMOOTH_STAIRS:4)
Block(-7,86,-1,SMOOTH_STAIRS:0)
Block(-7,87,-7,SMOOTH_STAIRS:0)
Block(-7,87,-5,LAPIS_BLOCK:0)
Block(-7,87,-4,CONCRETE:7)
Block(-7,87,-3,SMOOTH_STAIRS:7)
Block(-7,87,-2,STEP:8)
Block(-7,87,-1,SMOOTH_STAIRS:4)
Block(-7,88,-5,SMOOTH_STAIRS:0)
Block(-7,88,-4,SMOOTH_STAIRS:0)
Block(-7,88,-3,CONCRETE:7)
Block(-7,88,-2,CONCRETE:7)
Block(-7,88,-1,CONCRETE:7)
Block(-7,88,0,SMOOTH_STAIRS:7)
Block(-7,89,-2,STEP:0)
Block(-7,89,-1,SMOOTH_STAIRS:0)
Block(-7,89,0,CONCRETE:7)
Block(-7,89,1,CONCRETE:7)
Block(-7,89,2,SMOOTH_STAIRS:4)
Block(-7,90,-6,PRISMARINE:0)
Block(-7,90,-3,PRISMARINE:0)
Block(-7,90,-2,SEA_LANTERN:0)
Block(-7,90,0,PRISMARINE:0)
Block(-7,90,1,SMOOTH_STAIRS:2)
Block(-7,90,2,CONCRETE:7)
Block(-7,91,-6,PRISMARINE:0)
Block(-7,91,-3,PRISMARINE:0)
Block(-7,91,0,PRISMARINE:0)
Block(-7,91,2,SEA_LANTERN:0)
Block(-7,92,-7,PRISMARINE:0)
Block(-7,92,-6,SEA_LANTERN:0)
Block(-7,92,-5,PRISMARINE:0)
Block(-7,92,-3,PRISMARINE:0)
Block(-7,92,-2,PRISMARINE:0)
Block(-7,92,0,PRISMARINE:0)
Block(-7,92,1,SMOOTH_STAIRS:6)
Block(-7,92,2,CONCRETE:7)
Block(-7,93,-2,STEP:8)
Block(-7,93,-1,SMOOTH_STAIRS:4)
Block(-7,93,0,CONCRETE:7)
Block(-7,93,1,CONCRETE:7)
Block(-7,93,2,SMOOTH_STAIRS:0)
Block(-7,94,-5,SMOOTH_STAIRS:4)
Block(-7,94,-4,SMOOTH_STAIRS:4)
Block(-7,94,-3,CONCRETE:7)
Block(-7,94,-2,CONCRETE:7)
Block(-7,94,-1,CONCRETE:7)
Block(-7,94,0,SMOOTH_STAIRS:3)
Block(-7,95,-7,SMOOTH_STAIRS:4)
Block(-7,95,-5,LAPIS_BLOCK:0)
Block(-7,95,-4,CONCRETE:7)
Block(-7,95,-3,SMOOTH_STAIRS:3)
Block(-7,95,-2,STEP:0)
Block(-7,95,-1,SMOOTH_STAIRS:0)
Block(-7,96,-7,CONCRETE:7)
Block(-7,96,-5,CONCRETE:7)
Block(-7,96,-4,SMOOTH_STAIRS:0)
Block(-7,97,-7,SMOOTH_STAIRS:0)
Block(-7,97,-5,CONCRETE:7)
Block(-7,98,-5,SMOOTH_STAIRS:0)
Block(-7,114,-1,IRON_FENCE:0)
Block(-7,115,-1,SMOOTH_STAIRS:7)
Block(-7,116,-1,LEVER:13)
Block(-7,116,0,IRON_TRAPDOOR:5)
Block(-7,117,-1,LEVER:15)
Block(-7,117,0,IRON_TRAPDOOR:5)
Block(-7,118,-4,IRON_FENCE:0)
Block(-7,118,-1,SMOOTH_STAIRS:3)
Block(-7,119,-4,IRON_FENCE:0)
Block(-7,119,-1,IRON_FENCE:0)
Block(-7,120,-4,IRON_FENCE:0)
Block(-7,120,-1,IRON_FENCE:0)
Block(-7,121,-4,IRON_FENCE:0)
Block(-7,121,-1,IRON_FENCE:0)
Block(-7,122,-4,IRON_FENCE:0)
Block(-7,122,-1,IRON_FENCE:0)
Block(-7,123,-4,IRON_FENCE:0)
Block(-7,123,-1,IRON_FENCE:0)
Block(-7,124,-4,IRON_FENCE:0)
Block(-7,124,-1,IRON_FENCE:0)
Block(-7,125,-4,IRON_FENCE:0)
Block(-7,125,-1,IRON_FENCE:0)
Block(-7,126,-4,IRON_FENCE:0)
Block(-7,126,-1,IRON_FENCE:0)
Block(-7,127,-4,IRON_FENCE:0)
Block(-7,127,-1,IRON_FENCE:0)
Block(-7,128,-4,IRON_FENCE:0)
Block(-7,128,-1,IRON_FENCE:0)
Block(-7,129,-4,IRON_FENCE:0)
Block(-7,129,-1,IRON_FENCE:0)
Block(-7,130,-4,COBBLE_WALL:0)
Block(-7,130,-1,COBBLE_WALL:0)
Block(-7,131,-4,CONCRETE:8)
Block(-7,131,-1,CONCRETE:8)
Block(-7,132,-4,SMOOTH_STAIRS:0)
Block(-7,133,-6,SMOOTH_STAIRS:4)
Block(-7,134,-6,CONCRETE:8)
Block(-7,134,2,SMOOTH_STAIRS:4)
Block(-7,135,0,SMOOTH_STAIRS:4)
Block(-7,135,1,SMOOTH_STAIRS:4)
Block(-7,135,2,CONCRETE:7)
Block(-7,136,-2,SMOOTH_STAIRS:4)
Block(-7,136,-1,SMOOTH_STAIRS:4)
Block(-7,136,0,CONCRETE:7)
Block(-7,136,1,CONCRETE:7)
Block(-7,136,2,CONCRETE:7)
Block(-7,137,-3,SMOOTH_STAIRS:4)
Block(-7,137,-2,CONCRETE:7)
Block(-7,137,-1,CONCRETE:7)
Block(-7,137,0,CONCRETE:7)
Block(-7,137,1,CONCRETE:15)
Block(-7,137,2,CONCRETE:15)
Block(-7,137,4,SMOOTH_STAIRS:4)
Block(-7,138,-4,SMOOTH_STAIRS:4)
Block(-7,138,-3,CONCRETE:7)
Block(-7,138,-2,CONCRETE:7)
Block(-7,138,-1,CONCRETE:15)
Block(-7,138,0,CONCRETE:15)
Block(-7,138,1,CONCRETE:15)
Block(-7,138,2,CONCRETE:15)
Block(-7,138,3,SMOOTH_STAIRS:4)
Block(-7,138,4,CONCRETE:7)
Block(-7,138,5,SMOOTH_STAIRS:4)
Block(-7,138,6,STEP:8)
Block(-7,139,-7,SMOOTH_STAIRS:4)
Block(-7,139,-6,SMOOTH_STAIRS:4)
Block(-7,139,-5,SMOOTH_STAIRS:4)
Block(-7,139,-4,CONCRETE:7)
Block(-7,139,-3,CONCRETE:7)
Block(-7,139,-2,CONCRETE:15)
Block(-7,139,-1,CONCRETE:15)
Block(-7,139,0,CONCRETE:7)
Block(-7,139,1,CONCRETE:7)
Block(-7,139,2,CONCRETE:7)
Block(-7,139,3,CONCRETE:7)
Block(-7,139,4,CONCRETE:7)
Block(-7,139,5,CONCRETE:8)
Block(-7,139,6,SMOOTH_STAIRS:3)
Block(-7,140,-7,STEP:0)
Block(-7,140,-6,STEP:0)
Block(-7,140,-5,SMOOTH_STAIRS:2)
Block(-7,140,-4,CONCRETE:7)
Block(-7,140,-3,CONCRETE:7)
Block(-7,140,-2,SMOOTH_STAIRS:3)
Block(-7,140,-1,STEP:0)
Block(-7,140,0,CONCRETE:7)
Block(-7,140,1,STEP:0)
Block(-7,140,2,SMOOTH_STAIRS:2)
Block(-7,140,3,CONCRETE:7)
Block(-7,140,4,CONCRETE:7)
Block(-7,140,5,SMOOTH_STAIRS:3)
Block(-7,141,-4,CONCRETE:7)
Block(-7,141,-3,STEP:0)
Block(-7,141,0,COBBLE_WALL:0)
Block(-7,141,3,STEP:0)
Block(-7,141,4,CONCRETE:7)
Block(-7,142,-4,STEP:0)
Block(-7,142,4,STEP:0)
Block(-7,142,6,SMOOTH_STAIRS:4)
Block(-7,143,-7,STEP:8)
Block(-7,143,-6,STEP:8)
Block(-7,143,-5,STEP:8)
Block(-7,143,-4,SMOOTH_STAIRS:4)
Block(-7,143,-3,STEP:8)
Block(-7,143,-2,STEP:8)
Block(-7,143,-1,STEP:8)
Block(-7,143,0,STEP:8)
Block(-7,143,1,STEP:8)
Block(-7,143,2,STEP:8)
Block(-7,143,3,STEP:8)
Block(-7,143,4,STEP:8)
Block(-7,143,5,SMOOTH_STAIRS:6)
Block(-7,143,6,CONCRETE:7)
Block(-7,144,-4,COBBLE_WALL:0)
Block(-7,144,0,COBBLE_WALL:0)
Block(-7,144,4,SMOOTH_STAIRS:2)
Block(-7,144,5,SMOOTH_STAIRS:0)
Block(-7,144,6,STEP:0)
Block(-6,0,-7,CONCRETE:7)
Block(-6,0,-6,CONCRETE:7)
Block(-6,0,-5,CONCRETE:7)
Block(-6,0,-4,CONCRETE:7)
Block(-6,0,-3,CONCRETE:7)
Block(-6,0,-2,CONCRETE:7)
Block(-6,0,-1,CONCRETE:7)
Block(-6,0,0,CONCRETE:7)
Block(-6,0,1,CONCRETE:7)
Block(-6,0,2,CONCRETE:7)
Block(-6,0,3,CONCRETE:7)
Block(-6,0,4,CONCRETE:7)
Block(-6,0,5,CONCRETE:7)
Block(-6,0,6,CONCRETE:7)
Block(-6,0,7,CONCRETE:7)
Block(-6,0,8,CONCRETE:7)
Block(-6,1,-7,CONCRETE:7)
Block(-6,1,-6,CONCRETE:7)
Block(-6,1,-5,CONCRETE:7)
Block(-6,1,-4,CONCRETE:7)
Block(-6,1,-3,CONCRETE:7)
Block(-6,1,-2,CONCRETE:7)
Block(-6,1,-1,CONCRETE:7)
Block(-6,1,0,CONCRETE:7)
Block(-6,1,1,CONCRETE:7)
Block(-6,1,2,CONCRETE:7)
Block(-6,1,3,CONCRETE:7)
Block(-6,1,4,CONCRETE:7)
Block(-6,1,5,CONCRETE:7)
Block(-6,1,6,CONCRETE:7)
Block(-6,1,7,CONCRETE:7)
Block(-6,1,8,CONCRETE:7)
Block(-6,2,-7,CONCRETE:7)
Block(-6,2,-6,CONCRETE:7)
Block(-6,2,-5,CONCRETE:7)
Block(-6,2,-4,CONCRETE:7)
Block(-6,2,-3,CONCRETE:7)
Block(-6,2,-2,CONCRETE:7)
Block(-6,2,-1,CONCRETE:7)
Block(-6,2,0,CONCRETE:7)
Block(-6,2,1,CONCRETE:7)
Block(-6,2,2,CONCRETE:7)
Block(-6,2,3,CONCRETE:7)
Block(-6,2,4,CONCRETE:7)
Block(-6,2,5,CONCRETE:7)
Block(-6,2,6,CONCRETE:7)
Block(-6,2,7,CONCRETE:7)
Block(-6,2,8,CONCRETE:7)
Block(-6,3,-7,CONCRETE:7)
Block(-6,3,-6,CONCRETE:7)
Block(-6,3,-5,CONCRETE:7)
Block(-6,3,-4,CONCRETE:7)
Block(-6,3,-3,CONCRETE:7)
Block(-6,3,-2,CONCRETE:7)
Block(-6,3,-1,CONCRETE:7)
Block(-6,3,0,CONCRETE:7)
Block(-6,3,1,CONCRETE:7)
Block(-6,3,2,CONCRETE:7)
Block(-6,3,3,CONCRETE:7)
Block(-6,3,4,CONCRETE:7)
Block(-6,3,5,CONCRETE:7)
Block(-6,3,6,CONCRETE:7)
Block(-6,3,7,CONCRETE:7)
Block(-6,3,8,CONCRETE:7)
Block(-6,4,-7,CONCRETE:7)
Block(-6,4,-6,CONCRETE:7)
Block(-6,4,-5,CONCRETE:7)
Block(-6,4,-4,CONCRETE:7)
Block(-6,4,-3,CONCRETE:7)
Block(-6,4,-2,CONCRETE:7)
Block(-6,4,-1,CONCRETE:7)
Block(-6,4,0,CONCRETE:7)
Block(-6,4,1,CONCRETE:7)
Block(-6,4,2,CONCRETE:7)
Block(-6,4,3,CONCRETE:7)
Block(-6,4,4,CONCRETE:7)
Block(-6,4,5,CONCRETE:7)
Block(-6,4,6,CONCRETE:7)
Block(-6,4,7,CONCRETE:7)
Block(-6,4,8,CONCRETE:7)
Block(-6,5,-7,CONCRETE:7)
Block(-6,5,-6,CONCRETE:7)
Block(-6,5,-5,CONCRETE:7)
Block(-6,5,-4,CONCRETE:7)
Block(-6,5,-3,CONCRETE:7)
Block(-6,5,-2,CONCRETE:7)
Block(-6,5,-1,CONCRETE:7)
Block(-6,5,0,CONCRETE:7)
Block(-6,5,1,CONCRETE:7)
Block(-6,5,2,CONCRETE:7)
Block(-6,5,3,CONCRETE:7)
Block(-6,5,4,CONCRETE:7)
Block(-6,5,5,CONCRETE:7)
Block(-6,5,6,CONCRETE:7)
Block(-6,5,7,CONCRETE:7)
Block(-6,5,8,CONCRETE:7)
Block(-6,6,-7,CONCRETE:7)
Block(-6,6,-6,CONCRETE:7)
Block(-6,6,-5,CONCRETE:7)
Block(-6,6,-4,CONCRETE:7)
Block(-6,6,-3,CONCRETE:7)
Block(-6,6,-2,CONCRETE:7)
Block(-6,6,-1,CONCRETE:7)
Block(-6,6,0,CONCRETE:7)
Block(-6,6,1,CONCRETE:7)
Block(-6,6,2,CONCRETE:7)
Block(-6,6,3,CONCRETE:7)
Block(-6,6,4,CONCRETE:7)
Block(-6,6,5,CONCRETE:7)
Block(-6,6,6,CONCRETE:7)
Block(-6,6,7,CONCRETE:7)
Block(-6,6,8,CONCRETE:7)
Block(-6,7,-7,CONCRETE:15)
Block(-6,7,-6,CONCRETE:15)
Block(-6,7,-5,CONCRETE:15)
Block(-6,7,-4,CONCRETE:15)
Block(-6,7,-3,CONCRETE:15)
Block(-6,7,-2,CONCRETE:15)
Block(-6,7,-1,CONCRETE:15)
Block(-6,7,0,CONCRETE:15)
Block(-6,7,1,CONCRETE:15)
Block(-6,7,2,CONCRETE:15)
Block(-6,7,3,CONCRETE:15)
Block(-6,7,4,CONCRETE:15)
Block(-6,7,5,CONCRETE:15)
Block(-6,7,6,CONCRETE:15)
Block(-6,7,7,CONCRETE:7)
Block(-6,7,8,CONCRETE:7)
Block(-6,8,-2,QUARTZ_STAIRS:2)
Block(-6,8,-1,QUARTZ_STAIRS:7)
Block(-6,8,0,CONCRETE:15)
Block(-6,8,1,CONCRETE:15)
Block(-6,8,2,CONCRETE:7)
Block(-6,8,3,CONCRETE:12)
Block(-6,8,4,BRICK_STAIRS:5)
Block(-6,8,5,CONCRETE:7)
Block(-6,8,6,BRICK_STAIRS:5)
Block(-6,8,7,BRICK:0)
Block(-6,8,8,BRICK:0)
Block(-6,9,-1,QUARTZ_STAIRS:2)
Block(-6,9,0,CONCRETE:7)
Block(-6,9,1,BRICK_STAIRS:2)
Block(-6,9,2,CONCRETE:7)
Block(-6,9,3,CONCRETE:12)
Block(-6,9,4,CONCRETE:7)
Block(-6,9,5,CONCRETE:7)
Block(-6,9,6,CONCRETE:7)
Block(-6,9,7,CONCRETE:7)
Block(-6,9,8,BRICK:0)
Block(-6,10,2,CONCRETE:7)
Block(-6,10,3,DROPPER:1,NBT/skyscraper_2x2_02/7-dropperC0R16.nbt)
Block(-6,10,4,STEP:0)
Block(-6,10,5,SPRUCE_DOOR:2)
Block(-6,10,8,CONCRETE:7)
Block(-6,11,2,CONCRETE:7)
Block(-6,11,3,TRAP_DOOR:5)
Block(-6,11,5,SPRUCE_DOOR:9)
Block(-6,11,8,CONCRETE:7)
Block(-6,12,2,CONCRETE:7)
Block(-6,12,3,STONE_BUTTON:3)
Block(-6,12,8,CONCRETE:7)
Block(-6,13,2,CONCRETE:7)
Block(-6,13,5,SMOOTH_STAIRS:7)
Block(-6,13,6,WALL_BANNER:3,NBT/skyscraper_2x2_02/8-bannerC0R16.nbt)
Block(-6,13,7,SMOOTH_STAIRS:6)
Block(-6,13,8,CONCRETE:7)
Block(-6,14,-6,BRICK_STAIRS:6)
Block(-6,14,-5,STEP:12)
Block(-6,14,-3,CONCRETE:7)
Block(-6,14,-1,CONCRETE:7)
Block(-6,14,2,CONCRETE:7)
Block(-6,14,5,IRON_FENCE:0)
Block(-6,14,8,CONCRETE:7)
Block(-6,15,-7,STEP:12)
Block(-6,15,-6,CONCRETE:7)
Block(-6,15,-5,CONCRETE:7)
Block(-6,15,-4,BRICK_STAIRS:5)
Block(-6,15,-3,CONCRETE:7)
Block(-6,15,-2,CONCRETE:7)
Block(-6,15,-1,CONCRETE:7)
Block(-6,15,0,CONCRETE:7)
Block(-6,15,1,STEP:12)
Block(-6,15,2,CONCRETE:7)
Block(-6,15,3,CONCRETE:7)
Block(-6,15,4,CONCRETE:7)
Block(-6,15,5,CONCRETE:7)
Block(-6,15,6,CONCRETE:7)
Block(-6,15,7,CONCRETE:7)
Block(-6,15,8,CONCRETE:7)
Block(-6,16,-7,CONCRETE:7)
Block(-6,16,-6,CONCRETE:7)
Block(-6,16,-5,CONCRETE:7)
Block(-6,16,-4,CONCRETE:7)
Block(-6,16,-3,CONCRETE:7)
Block(-6,16,-2,CONCRETE:7)
Block(-6,16,-1,CONCRETE:7)
Block(-6,16,0,CONCRETE:7)
Block(-6,16,1,CONCRETE:7)
Block(-6,16,2,CONCRETE:7)
Block(-6,16,3,CONCRETE:7)
Block(-6,16,4,CONCRETE:7)
Block(-6,16,5,CONCRETE:7)
Block(-6,16,6,CONCRETE:7)
Block(-6,16,7,CONCRETE:7)
Block(-6,16,8,CONCRETE:7)
Block(-6,17,-7,CONCRETE:7)
Block(-6,17,-6,CONCRETE:7)
Block(-6,17,-5,CONCRETE:7)
Block(-6,17,-4,CONCRETE:7)
Block(-6,17,-3,CONCRETE:7)
Block(-6,17,-2,CONCRETE:7)
Block(-6,17,-1,CONCRETE:7)
Block(-6,17,0,CONCRETE:7)
Block(-6,17,1,CONCRETE:7)
Block(-6,17,2,CONCRETE:7)
Block(-6,17,3,CONCRETE:7)
Block(-6,17,4,CONCRETE:7)
Block(-6,17,5,CONCRETE:7)
Block(-6,17,6,CONCRETE:7)
Block(-6,17,7,CONCRETE:7)
Block(-6,17,8,CONCRETE:15)
Block(-6,18,-7,SMOOTH_STAIRS:1)
Block(-6,18,-6,CONCRETE:8)
Block(-6,18,-5,CONCRETE:8)
Block(-6,18,-4,CONCRETE:8)
Block(-6,18,-3,CONCRETE:8)
Block(-6,18,-2,CONCRETE:7)
Block(-6,18,-1,SMOOTH_STAIRS:0)
Block(-6,18,2,CONCRETE:8)
Block(-6,18,3,CONCRETE:8)
Block(-6,18,4,CONCRETE:0)
Block(-6,18,5,CONCRETE:8)
Block(-6,18,6,CONCRETE:7)
Block(-6,19,-6,CONCRETE:8)
Block(-6,19,-5,STAINED_GLASS_PANE:7)
Block(-6,19,-4,STAINED_GLASS_PANE:7)
Block(-6,19,-3,STAINED_GLASS_PANE:7)
Block(-6,19,-2,CONCRETE:7)
Block(-6,19,2,SMOOTH_STAIRS:2)
Block(-6,19,3,CONCRETE:8)
Block(-6,19,4,CONCRETE:0)
Block(-6,19,5,CONCRETE:8)
Block(-6,19,6,CONCRETE:7)
Block(-6,20,-6,CONCRETE:8)
Block(-6,20,-5,STAINED_GLASS_PANE:7)
Block(-6,20,-4,STAINED_GLASS_PANE:7)
Block(-6,20,-3,STAINED_GLASS_PANE:7)
Block(-6,20,-2,CONCRETE:7)
Block(-6,20,3,SMOOTH_STAIRS:0)
Block(-6,20,4,CONCRETE:0)
Block(-6,20,5,CONCRETE:8)
Block(-6,20,6,STEP:0)
Block(-6,21,-6,CONCRETE:8)
Block(-6,21,-5,STAINED_GLASS_PANE:7)
Block(-6,21,-4,STAINED_GLASS_PANE:7)
Block(-6,21,-3,STAINED_GLASS_PANE:7)
Block(-6,21,-2,STEP:0)
Block(-6,21,4,CONCRETE:0)
Block(-6,21,5,CONCRETE:8)
Block(-6,22,-6,CONCRETE:8)
Block(-6,22,-5,STAINED_GLASS_PANE:7)
Block(-6,22,-4,STAINED_GLASS_PANE:7)
Block(-6,22,-3,STAINED_GLASS_PANE:7)
Block(-6,22,4,CONCRETE:0)
Block(-6,22,5,SMOOTH_STAIRS:0)
Block(-6,23,-6,CONCRETE:8)
Block(-6,23,-5,STAINED_GLASS_PANE:7)
Block(-6,23,-4,STAINED_GLASS_PANE:7)
Block(-6,23,-3,STAINED_GLASS_PANE:7)
Block(-6,23,4,CONCRETE:0)
Block(-6,23,5,SMOOTH_STAIRS:4)
Block(-6,24,-6,CONCRETE:8)
Block(-6,24,-5,STAINED_GLASS_PANE:7)
Block(-6,24,-4,STAINED_GLASS_PANE:7)
Block(-6,24,-3,STAINED_GLASS_PANE:7)
Block(-6,24,-2,STEP:8)
Block(-6,24,4,CONCRETE:0)
Block(-6,24,5,CONCRETE:8)
Block(-6,25,-6,CONCRETE:8)
Block(-6,25,-5,STAINED_GLASS_PANE:7)
Block(-6,25,-4,STAINED_GLASS_PANE:7)
Block(-6,25,-3,STAINED_GLASS_PANE:7)
Block(-6,25,-2,CONCRETE:7)
Block(-6,25,3,SMOOTH_STAIRS:4)
Block(-6,25,4,CONCRETE:0)
Block(-6,25,5,CONCRETE:8)
Block(-6,25,6,STEP:8)
Block(-6,26,-6,CONCRETE:8)
Block(-6,26,-5,STAINED_GLASS_PANE:7)
Block(-6,26,-4,STAINED_GLASS_PANE:7)
Block(-6,26,-3,STAINED_GLASS_PANE:7)
Block(-6,26,-2,CONCRETE:7)
Block(-6,26,2,SMOOTH_STAIRS:6)
Block(-6,26,3,CONCRETE:8)
Block(-6,26,4,CONCRETE:0)
Block(-6,26,5,CONCRETE:8)
Block(-6,26,6,CONCRETE:7)
Block(-6,27,-7,SMOOTH_STAIRS:5)
Block(-6,27,-6,CONCRETE:8)
Block(-6,27,-5,CONCRETE:8)
Block(-6,27,-4,CONCRETE:8)
Block(-6,27,-3,CONCRETE:8)
Block(-6,27,-2,CONCRETE:7)
Block(-6,27,-1,SMOOTH_STAIRS:4)
Block(-6,27,2,CONCRETE:8)
Block(-6,27,3,CONCRETE:8)
Block(-6,27,4,CONCRETE:0)
Block(-6,27,5,CONCRETE:8)
Block(-6,27,6,CONCRETE:7)
Block(-6,28,-7,CONCRETE:7)
Block(-6,28,-6,CONCRETE:7)
Block(-6,28,-5,CONCRETE:7)
Block(-6,28,-4,CONCRETE:7)
Block(-6,28,-3,CONCRETE:7)
Block(-6,28,-2,CONCRETE:7)
Block(-6,28,-1,CONCRETE:7)
Block(-6,28,0,CONCRETE:7)
Block(-6,28,1,CONCRETE:7)
Block(-6,28,2,CONCRETE:7)
Block(-6,28,3,CONCRETE:7)
Block(-6,28,4,CONCRETE:7)
Block(-6,28,5,CONCRETE:7)
Block(-6,28,6,CONCRETE:7)
Block(-6,28,7,SMOOTH_STAIRS:7)
Block(-6,29,-7,CONCRETE:7)
Block(-6,29,-6,CONCRETE:7)
Block(-6,29,-5,CONCRETE:7)
Block(-6,29,-4,CONCRETE:7)
Block(-6,29,-3,CONCRETE:7)
Block(-6,29,-2,CONCRETE:7)
Block(-6,29,-1,CONCRETE:7)
Block(-6,29,0,CONCRETE:7)
Block(-6,29,1,CONCRETE:7)
Block(-6,29,2,CONCRETE:7)
Block(-6,29,3,CONCRETE:7)
Block(-6,29,4,CONCRETE:7)
Block(-6,29,5,CONCRETE:7)
Block(-6,29,6,CONCRETE:7)
Block(-6,29,7,CONCRETE:7)
Block(-6,29,8,STEP:8)
Block(-6,30,-7,PRISMARINE:0)
Block(-6,30,-6,PRISMARINE:0)
Block(-6,30,-5,CONCRETE:15)
Block(-6,30,-4,CONCRETE:15)
Block(-6,30,-3,CONCRETE:7)
Block(-6,30,-2,CONCRETE:7)
Block(-6,30,-1,CONCRETE:7)
Block(-6,30,0,CONCRETE:7)
Block(-6,30,1,CONCRETE:7)
Block(-6,30,2,CONCRETE:7)
Block(-6,30,3,CONCRETE:7)
Block(-6,30,4,CONCRETE:7)
Block(-6,30,5,CONCRETE:7)
Block(-6,30,6,CONCRETE:7)
Block(-6,30,7,CONCRETE:8)
Block(-6,31,-7,PRISMARINE:0)
Block(-6,31,-6,PRISMARINE:0)
Block(-6,31,-5,PRISMARINE:0)
Block(-6,31,-4,PRISMARINE:0)
Block(-6,31,-3,CONCRETE:15)
Block(-6,31,-2,CONCRETE:7)
Block(-6,31,-1,CONCRETE:7)
Block(-6,31,0,CONCRETE:7)
Block(-6,31,1,CONCRETE:7)
Block(-6,31,2,CONCRETE:7)
Block(-6,31,3,CONCRETE:7)
Block(-6,31,4,CONCRETE:7)
Block(-6,31,5,CONCRETE:7)
Block(-6,31,6,CONCRETE:7)
Block(-6,32,-7,PRISMARINE:0)
Block(-6,32,-6,PRISMARINE:0)
Block(-6,32,-5,PRISMARINE:0)
Block(-6,32,-4,PRISMARINE:0)
Block(-6,32,-3,PRISMARINE:0)
Block(-6,32,-2,CONCRETE:15)
Block(-6,32,-1,CONCRETE:7)
Block(-6,32,0,CONCRETE:7)
Block(-6,32,1,CONCRETE:7)
Block(-6,32,2,CONCRETE:7)
Block(-6,32,3,CONCRETE:7)
Block(-6,32,4,CONCRETE:7)
Block(-6,32,5,CONCRETE:7)
Block(-6,32,6,STEP:0)
Block(-6,33,-7,PRISMARINE:0)
Block(-6,33,-6,PRISMARINE:0)
Block(-6,33,-5,PRISMARINE:0)
Block(-6,33,-4,PRISMARINE:0)
Block(-6,33,-3,PRISMARINE:0)
Block(-6,33,-2,CONCRETE:15)
Block(-6,33,-1,CONCRETE:7)
Block(-6,33,0,CONCRETE:7)
Block(-6,33,1,CONCRETE:7)
Block(-6,33,2,CONCRETE:7)
Block(-6,33,3,CONCRETE:7)
Block(-6,33,4,CONCRETE:7)
Block(-6,33,5,SMOOTH_STAIRS:3)
Block(-6,34,-7,PRISMARINE:0)
Block(-6,34,-6,PRISMARINE:0)
Block(-6,34,-5,PRISMARINE:0)
Block(-6,34,-4,PRISMARINE:0)
Block(-6,34,-3,PRISMARINE:0)
Block(-6,34,-2,PRISMARINE:0)
Block(-6,34,-1,CONCRETE:15)
Block(-6,34,0,CONCRETE:7)
Block(-6,34,1,CONCRETE:7)
Block(-6,34,2,CONCRETE:7)
Block(-6,34,3,CONCRETE:7)
Block(-6,35,-7,PRISMARINE:0)
Block(-6,35,-6,PRISMARINE:0)
Block(-6,35,-5,PRISMARINE:0)
Block(-6,35,-4,PRISMARINE:0)
Block(-6,35,-3,PRISMARINE:0)
Block(-6,35,-2,PRISMARINE:0)
Block(-6,35,-1,CONCRETE:15)
Block(-6,35,0,CONCRETE:7)
Block(-6,35,1,CONCRETE:7)
Block(-6,35,2,CONCRETE:7)
Block(-6,35,3,CONCRETE:7)
Block(-6,36,-7,PRISMARINE:0)
Block(-6,36,-6,PRISMARINE:0)
Block(-6,36,-5,PRISMARINE:0)
Block(-6,36,-4,SEA_LANTERN:0)
Block(-6,36,-3,PRISMARINE:0)
Block(-6,36,-2,PRISMARINE:0)
Block(-6,36,-1,CONCRETE:15)
Block(-6,36,0,CONCRETE:7)
Block(-6,36,1,CONCRETE:7)
Block(-6,36,2,CONCRETE:7)
Block(-6,36,3,SMOOTH_STAIRS:3)
Block(-6,36,6,SEA_LANTERN:0)
Block(-6,37,-7,PRISMARINE:0)
Block(-6,37,-6,PRISMARINE:0)
Block(-6,37,-5,PRISMARINE:0)
Block(-6,37,-4,PRISMARINE:0)
Block(-6,37,-3,PRISMARINE:0)
Block(-6,37,-2,PRISMARINE:0)
Block(-6,37,-1,CONCRETE:15)
Block(-6,37,0,CONCRETE:7)
Block(-6,37,1,CONCRETE:7)
Block(-6,37,2,CONCRETE:7)
Block(-6,37,3,SMOOTH_STAIRS:7)
Block(-6,37,6,IRON_FENCE:0)
Block(-6,38,-7,PRISMARINE:0)
Block(-6,38,-6,PRISMARINE:0)
Block(-6,38,-5,PRISMARINE:0)
Block(-6,38,-4,PRISMARINE:0)
Block(-6,38,-3,PRISMARINE:0)
Block(-6,38,-2,CONCRETE:15)
Block(-6,38,-1,CONCRETE:7)
Block(-6,38,0,CONCRETE:0)
Block(-6,38,1,CONCRETE:7)
Block(-6,38,2,CONCRETE:7)
Block(-6,38,3,CONCRETE:7)
Block(-6,38,6,IRON_FENCE:0)
Block(-6,39,-7,PRISMARINE:0)
Block(-6,39,-6,PRISMARINE:0)
Block(-6,39,-5,PRISMARINE:0)
Block(-6,39,-4,PRISMARINE:0)
Block(-6,39,-3,PRISMARINE:0)
Block(-6,39,-2,CONCRETE:15)
Block(-6,39,-1,CONCRETE:7)
Block(-6,39,0,STEP:0)
Block(-6,39,1,CONCRETE:0)
Block(-6,39,2,CONCRETE:7)
Block(-6,39,3,CONCRETE:7)
Block(-6,39,4,SMOOTH_STAIRS:7)
Block(-6,39,6,IRON_FENCE:0)
Block(-6,40,-7,PRISMARINE:0)
Block(-6,40,-6,PRISMARINE:0)
Block(-6,40,-5,PRISMARINE:0)
Block(-6,40,-4,PRISMARINE:0)
Block(-6,40,-3,CONCRETE:15)
Block(-6,40,-2,CONCRETE:7)
Block(-6,40,-1,STEP:0)
Block(-6,40,1,CONCRETE:0)
Block(-6,40,2,CONCRETE:7)
Block(-6,40,3,CONCRETE:7)
Block(-6,40,4,CONCRETE:7)
Block(-6,40,5,STEP:8)
Block(-6,40,6,IRON_FENCE:0)
Block(-6,41,-7,PRISMARINE:0)
Block(-6,41,-6,PRISMARINE:0)
Block(-6,41,-5,CONCRETE:15)
Block(-6,41,-4,CONCRETE:15)
Block(-6,41,-3,CONCRETE:7)
Block(-6,41,-2,CONCRETE:7)
Block(-6,41,1,STEP:0)
Block(-6,41,2,CONCRETE:0)
Block(-6,41,3,CONCRETE:7)
Block(-6,41,4,CONCRETE:7)
Block(-6,41,5,CONCRETE:7)
Block(-6,41,6,IRON_FENCE:0)
Block(-6,42,-7,CONCRETE:15)
Block(-6,42,-6,CONCRETE:15)
Block(-6,42,-5,CONCRETE:7)
Block(-6,42,-4,CONCRETE:7)
Block(-6,42,-3,STEP:0)
Block(-6,42,-2,COBBLE_WALL:0)
Block(-6,42,2,STEP:0)
Block(-6,42,3,CONCRETE:0)
Block(-6,42,4,CONCRETE:7)
Block(-6,42,5,CONCRETE:7)
Block(-6,42,6,CONCRETE:7)
Block(-6,43,-7,CONCRETE:7)
Block(-6,43,-6,CONCRETE:7)
Block(-6,43,-5,STEP:0)
Block(-6,43,-4,COBBLE_WALL:0)
Block(-6,43,3,STEP:0)
Block(-6,43,4,CONCRETE:0)
Block(-6,43,5,CONCRETE:0)
Block(-6,43,6,CONCRETE:8)
Block(-6,43,7,CONCRETE:8)
Block(-6,44,4,STEP:0)
Block(-6,44,5,CONCRETE:8)
Block(-6,44,6,CONCRETE:8)
Block(-6,44,7,STEP:0)
Block(-6,45,-6,SMOOTH_STAIRS:5)
Block(-6,45,6,STEP:0)
Block(-6,46,-6,SMOOTH_STAIRS:0)
Block(-6,46,-5,STEP:8)
Block(-6,46,-4,SMOOTH_STAIRS:4)
Block(-6,47,-7,STEP:8)
Block(-6,47,-5,CONCRETE:8)
Block(-6,47,-4,CONCRETE:15)
Block(-6,48,-7,CONCRETE:8)
Block(-6,48,-6,SMOOTH_STAIRS:4)
Block(-6,48,-5,CONCRETE:8)
Block(-6,48,-4,CONCRETE:8)
Block(-6,48,-3,SMOOTH_STAIRS:4)
Block(-6,48,-2,COBBLE_WALL:0)
Block(-6,49,-7,CONCRETE:8)
Block(-6,49,-6,CONCRETE:8)
Block(-6,49,-5,CONCRETE:8)
Block(-6,49,-4,CONCRETE:8)
Block(-6,49,-3,CONCRETE:8)
Block(-6,49,-2,CONCRETE:8)
Block(-6,49,-1,SMOOTH_STAIRS:4)
Block(-6,50,-7,CONCRETE:8)
Block(-6,50,-6,SMOOTH_STAIRS:0)
Block(-6,50,-5,CONCRETE:8)
Block(-6,50,-4,CONCRETE:8)
Block(-6,50,-3,SMOOTH_STAIRS:0)
Block(-6,50,-2,SMOOTH_STAIRS:0)
Block(-6,50,-1,CONCRETE:8)
Block(-6,50,0,SMOOTH_STAIRS:4)
Block(-6,50,1,SMOOTH_STAIRS:4)
Block(-6,51,-7,CONCRETE:8)
Block(-6,51,-6,STAINED_GLASS_PANE:7)
Block(-6,51,-5,CONCRETE:8)
Block(-6,51,-4,CONCRETE:8)
Block(-6,51,-3,STAINED_GLASS_PANE:7)
Block(-6,51,-2,STAINED_GLASS_PANE:7)
Block(-6,51,-1,CONCRETE:8)
Block(-6,51,0,CONCRETE:8)
Block(-6,51,1,CONCRETE:8)
Block(-6,51,2,SMOOTH_STAIRS:4)
Block(-6,52,-7,CONCRETE:8)
Block(-6,52,-6,STAINED_GLASS_PANE:7)
Block(-6,52,-5,CONCRETE:8)
Block(-6,52,-4,CONCRETE:8)
Block(-6,52,-3,STAINED_GLASS_PANE:7)
Block(-6,52,-2,STAINED_GLASS_PANE:7)
Block(-6,52,-1,CONCRETE:8)
Block(-6,52,0,STAINED_GLASS_PANE:7)
Block(-6,52,1,STAINED_GLASS_PANE:7)
Block(-6,52,2,CONCRETE:8)
Block(-6,53,-7,CONCRETE:8)
Block(-6,53,-6,STAINED_GLASS_PANE:7)
Block(-6,53,-5,CONCRETE:8)
Block(-6,53,-4,CONCRETE:8)
Block(-6,53,-3,STAINED_GLASS_PANE:7)
Block(-6,53,-2,STAINED_GLASS_PANE:7)
Block(-6,53,-1,CONCRETE:8)
Block(-6,53,0,STAINED_GLASS_PANE:7)
Block(-6,53,1,STAINED_GLASS_PANE:7)
Block(-6,53,2,CONCRETE:8)
Block(-6,54,-7,CONCRETE:8)
Block(-6,54,-6,STAINED_GLASS_PANE:7)
Block(-6,54,-5,CONCRETE:8)
Block(-6,54,-4,CONCRETE:8)
Block(-6,54,-3,STAINED_GLASS_PANE:7)
Block(-6,54,-2,STAINED_GLASS_PANE:7)
Block(-6,54,-1,CONCRETE:8)
Block(-6,54,0,STAINED_GLASS_PANE:7)
Block(-6,54,1,STAINED_GLASS_PANE:7)
Block(-6,54,2,CONCRETE:8)
Block(-6,55,-7,CONCRETE:8)
Block(-6,55,-6,STAINED_GLASS_PANE:7)
Block(-6,55,-5,CONCRETE:8)
Block(-6,55,-4,CONCRETE:8)
Block(-6,55,-3,STAINED_GLASS_PANE:7)
Block(-6,55,-2,STAINED_GLASS_PANE:7)
Block(-6,55,-1,CONCRETE:8)
Block(-6,55,0,STAINED_GLASS_PANE:7)
Block(-6,55,1,STAINED_GLASS_PANE:7)
Block(-6,55,2,CONCRETE:8)
Block(-6,56,-7,CONCRETE:8)
Block(-6,56,-6,STAINED_GLASS_PANE:7)
Block(-6,56,-5,CONCRETE:8)
Block(-6,56,-4,CONCRETE:8)
Block(-6,56,-3,STAINED_GLASS_PANE:7)
Block(-6,56,-2,STAINED_GLASS_PANE:7)
Block(-6,56,-1,CONCRETE:8)
Block(-6,56,0,STAINED_GLASS_PANE:7)
Block(-6,56,1,STAINED_GLASS_PANE:7)
Block(-6,56,2,CONCRETE:8)
Block(-6,57,-7,CONCRETE:8)
Block(-6,57,-6,STAINED_GLASS_PANE:7)
Block(-6,57,-5,CONCRETE:8)
Block(-6,57,-4,CONCRETE:8)
Block(-6,57,-3,STAINED_GLASS_PANE:7)
Block(-6,57,-2,STAINED_GLASS_PANE:7)
Block(-6,57,-1,CONCRETE:8)
Block(-6,57,0,STAINED_GLASS_PANE:7)
Block(-6,57,1,STAINED_GLASS_PANE:7)
Block(-6,57,2,CONCRETE:8)
Block(-6,58,-7,CONCRETE:8)
Block(-6,58,-6,STAINED_GLASS_PANE:7)
Block(-6,58,-5,CONCRETE:8)
Block(-6,58,-4,CONCRETE:8)
Block(-6,58,-3,STAINED_GLASS_PANE:7)
Block(-6,58,-2,STAINED_GLASS_PANE:7)
Block(-6,58,-1,CONCRETE:8)
Block(-6,58,0,STAINED_GLASS_PANE:7)
Block(-6,58,1,STAINED_GLASS_PANE:7)
Block(-6,58,2,CONCRETE:8)
Block(-6,59,-7,CONCRETE:8)
Block(-6,59,-6,STAINED_GLASS_PANE:7)
Block(-6,59,-5,CONCRETE:8)
Block(-6,59,-4,CONCRETE:8)
Block(-6,59,-3,STAINED_GLASS_PANE:7)
Block(-6,59,-2,STAINED_GLASS_PANE:7)
Block(-6,59,-1,CONCRETE:8)
Block(-6,59,0,STAINED_GLASS_PANE:7)
Block(-6,59,1,STAINED_GLASS_PANE:7)
Block(-6,59,2,CONCRETE:8)
Block(-6,60,-7,CONCRETE:8)
Block(-6,60,-6,STAINED_GLASS_PANE:7)
Block(-6,60,-5,CONCRETE:8)
Block(-6,60,-4,CONCRETE:8)
Block(-6,60,-3,STAINED_GLASS_PANE:7)
Block(-6,60,-2,STAINED_GLASS_PANE:7)
Block(-6,60,-1,CONCRETE:8)
Block(-6,60,0,STAINED_GLASS_PANE:7)
Block(-6,60,1,STAINED_GLASS_PANE:7)
Block(-6,60,2,CONCRETE:8)
Block(-6,61,-7,CONCRETE:8)
Block(-6,61,-6,STAINED_GLASS_PANE:7)
Block(-6,61,-5,CONCRETE:8)
Block(-6,61,-4,CONCRETE:8)
Block(-6,61,-3,STAINED_GLASS_PANE:7)
Block(-6,61,-2,STAINED_GLASS_PANE:7)
Block(-6,61,-1,CONCRETE:8)
Block(-6,61,0,STAINED_GLASS_PANE:7)
Block(-6,61,1,STAINED_GLASS_PANE:7)
Block(-6,61,2,CONCRETE:8)
Block(-6,62,-7,CONCRETE:8)
Block(-6,62,-6,STAINED_GLASS_PANE:7)
Block(-6,62,-5,CONCRETE:8)
Block(-6,62,-4,CONCRETE:8)
Block(-6,62,-3,STAINED_GLASS_PANE:7)
Block(-6,62,-2,STAINED_GLASS_PANE:7)
Block(-6,62,-1,CONCRETE:8)
Block(-6,62,0,STAINED_GLASS_PANE:7)
Block(-6,62,1,STAINED_GLASS_PANE:7)
Block(-6,62,2,CONCRETE:8)
Block(-6,63,-7,CONCRETE:8)
Block(-6,63,-6,STAINED_GLASS_PANE:7)
Block(-6,63,-5,CONCRETE:8)
Block(-6,63,-4,CONCRETE:8)
Block(-6,63,-3,STAINED_GLASS_PANE:7)
Block(-6,63,-2,STAINED_GLASS_PANE:7)
Block(-6,63,-1,CONCRETE:8)
Block(-6,63,0,STAINED_GLASS_PANE:7)
Block(-6,63,1,STAINED_GLASS_PANE:7)
Block(-6,63,2,CONCRETE:8)
Block(-6,64,-7,CONCRETE:8)
Block(-6,64,-6,STAINED_GLASS_PANE:7)
Block(-6,64,-5,CONCRETE:8)
Block(-6,64,-4,CONCRETE:8)
Block(-6,64,-3,STAINED_GLASS_PANE:7)
Block(-6,64,-2,STAINED_GLASS_PANE:7)
Block(-6,64,-1,CONCRETE:8)
Block(-6,64,0,STAINED_GLASS_PANE:7)
Block(-6,64,1,STAINED_GLASS_PANE:7)
Block(-6,64,2,CONCRETE:8)
Block(-6,65,-7,CONCRETE:8)
Block(-6,65,-6,STAINED_GLASS_PANE:7)
Block(-6,65,-5,CONCRETE:8)
Block(-6,65,-4,CONCRETE:8)
Block(-6,65,-3,STAINED_GLASS_PANE:7)
Block(-6,65,-2,STAINED_GLASS_PANE:7)
Block(-6,65,-1,CONCRETE:8)
Block(-6,65,0,STAINED_GLASS_PANE:7)
Block(-6,65,1,STAINED_GLASS_PANE:7)
Block(-6,65,2,CONCRETE:8)
Block(-6,66,-7,CONCRETE:8)
Block(-6,66,-6,STAINED_GLASS_PANE:7)
Block(-6,66,-5,CONCRETE:8)
Block(-6,66,-4,CONCRETE:8)
Block(-6,66,-3,STAINED_GLASS_PANE:7)
Block(-6,66,-2,STAINED_GLASS_PANE:7)
Block(-6,66,-1,CONCRETE:8)
Block(-6,66,0,STAINED_GLASS_PANE:7)
Block(-6,66,1,STAINED_GLASS_PANE:7)
Block(-6,66,2,CONCRETE:8)
Block(-6,67,-7,CONCRETE:8)
Block(-6,67,-6,STAINED_GLASS_PANE:7)
Block(-6,67,-5,CONCRETE:8)
Block(-6,67,-4,CONCRETE:8)
Block(-6,67,-3,STAINED_GLASS_PANE:7)
Block(-6,67,-2,STAINED_GLASS_PANE:7)
Block(-6,67,-1,CONCRETE:8)
Block(-6,67,0,STAINED_GLASS_PANE:7)
Block(-6,67,1,STAINED_GLASS_PANE:7)
Block(-6,67,2,CONCRETE:8)
Block(-6,68,-7,CONCRETE:8)
Block(-6,68,-6,STAINED_GLASS_PANE:7)
Block(-6,68,-5,CONCRETE:8)
Block(-6,68,-4,CONCRETE:8)
Block(-6,68,-3,STAINED_GLASS_PANE:7)
Block(-6,68,-2,STAINED_GLASS_PANE:7)
Block(-6,68,-1,CONCRETE:8)
Block(-6,68,0,STAINED_GLASS_PANE:7)
Block(-6,68,1,STAINED_GLASS_PANE:7)
Block(-6,68,2,CONCRETE:8)
Block(-6,69,-7,CONCRETE:8)
Block(-6,69,-6,STAINED_GLASS_PANE:7)
Block(-6,69,-5,CONCRETE:8)
Block(-6,69,-4,CONCRETE:8)
Block(-6,69,-3,STAINED_GLASS_PANE:7)
Block(-6,69,-2,STAINED_GLASS_PANE:7)
Block(-6,69,-1,CONCRETE:8)
Block(-6,69,0,STAINED_GLASS_PANE:7)
Block(-6,69,1,STAINED_GLASS_PANE:7)
Block(-6,69,2,CONCRETE:8)
Block(-6,70,-7,CONCRETE:8)
Block(-6,70,-6,STAINED_GLASS_PANE:7)
Block(-6,70,-5,CONCRETE:8)
Block(-6,70,-4,CONCRETE:8)
Block(-6,70,-3,STAINED_GLASS_PANE:7)
Block(-6,70,-2,STAINED_GLASS_PANE:7)
Block(-6,70,-1,CONCRETE:8)
Block(-6,70,0,STAINED_GLASS_PANE:7)
Block(-6,70,1,STAINED_GLASS_PANE:7)
Block(-6,70,2,CONCRETE:8)
Block(-6,71,-7,CONCRETE:8)
Block(-6,71,-6,STAINED_GLASS_PANE:7)
Block(-6,71,-5,CONCRETE:8)
Block(-6,71,-4,CONCRETE:8)
Block(-6,71,-3,STAINED_GLASS_PANE:7)
Block(-6,71,-2,STAINED_GLASS_PANE:7)
Block(-6,71,-1,CONCRETE:8)
Block(-6,71,0,STAINED_GLASS_PANE:7)
Block(-6,71,1,STAINED_GLASS_PANE:7)
Block(-6,71,2,CONCRETE:8)
Block(-6,72,-7,CONCRETE:8)
Block(-6,72,-6,STAINED_GLASS_PANE:7)
Block(-6,72,-5,CONCRETE:8)
Block(-6,72,-4,CONCRETE:8)
Block(-6,72,-3,STAINED_GLASS_PANE:7)
Block(-6,72,-2,STAINED_GLASS_PANE:7)
Block(-6,72,-1,CONCRETE:8)
Block(-6,72,0,STAINED_GLASS_PANE:7)
Block(-6,72,1,STAINED_GLASS_PANE:7)
Block(-6,72,2,CONCRETE:8)
Block(-6,73,-7,CONCRETE:8)
Block(-6,73,-6,STAINED_GLASS_PANE:7)
Block(-6,73,-5,CONCRETE:8)
Block(-6,73,-4,CONCRETE:8)
Block(-6,73,-3,STAINED_GLASS_PANE:7)
Block(-6,73,-2,STAINED_GLASS_PANE:7)
Block(-6,73,-1,CONCRETE:8)
Block(-6,73,0,STAINED_GLASS_PANE:7)
Block(-6,73,1,STAINED_GLASS_PANE:7)
Block(-6,73,2,CONCRETE:8)
Block(-6,74,-7,CONCRETE:8)
Block(-6,74,-6,STAINED_GLASS_PANE:7)
Block(-6,74,-5,CONCRETE:8)
Block(-6,74,-4,CONCRETE:8)
Block(-6,74,-3,STAINED_GLASS_PANE:7)
Block(-6,74,-2,STAINED_GLASS_PANE:7)
Block(-6,74,-1,CONCRETE:8)
Block(-6,74,0,STAINED_GLASS_PANE:7)
Block(-6,74,1,STAINED_GLASS_PANE:7)
Block(-6,74,2,CONCRETE:8)
Block(-6,75,-7,CONCRETE:8)
Block(-6,75,-6,STAINED_GLASS_PANE:7)
Block(-6,75,-5,CONCRETE:8)
Block(-6,75,-4,CONCRETE:8)
Block(-6,75,-3,STAINED_GLASS_PANE:7)
Block(-6,75,-2,STAINED_GLASS_PANE:7)
Block(-6,75,-1,CONCRETE:8)
Block(-6,75,0,STAINED_GLASS_PANE:7)
Block(-6,75,1,STAINED_GLASS_PANE:7)
Block(-6,75,2,CONCRETE:8)
Block(-6,76,-7,CONCRETE:8)
Block(-6,76,-6,STAINED_GLASS_PANE:7)
Block(-6,76,-5,CONCRETE:8)
Block(-6,76,-4,CONCRETE:8)
Block(-6,76,-3,STAINED_GLASS_PANE:7)
Block(-6,76,-2,STAINED_GLASS_PANE:7)
Block(-6,76,-1,CONCRETE:8)
Block(-6,76,0,STAINED_GLASS_PANE:7)
Block(-6,76,1,STAINED_GLASS_PANE:7)
Block(-6,76,2,CONCRETE:8)
Block(-6,77,-7,CONCRETE:8)
Block(-6,77,-6,STAINED_GLASS_PANE:7)
Block(-6,77,-5,CONCRETE:8)
Block(-6,77,-4,CONCRETE:8)
Block(-6,77,-3,STAINED_GLASS_PANE:7)
Block(-6,77,-2,STAINED_GLASS_PANE:7)
Block(-6,77,-1,CONCRETE:8)
Block(-6,77,0,STAINED_GLASS_PANE:7)
Block(-6,77,1,STAINED_GLASS_PANE:7)
Block(-6,77,2,CONCRETE:8)
Block(-6,78,-7,CONCRETE:8)
Block(-6,78,-6,STAINED_GLASS_PANE:7)
Block(-6,78,-5,CONCRETE:8)
Block(-6,78,-4,CONCRETE:8)
Block(-6,78,-3,STAINED_GLASS_PANE:7)
Block(-6,78,-2,STAINED_GLASS_PANE:7)
Block(-6,78,-1,CONCRETE:8)
Block(-6,78,0,STAINED_GLASS_PANE:7)
Block(-6,78,1,STAINED_GLASS_PANE:7)
Block(-6,78,2,CONCRETE:8)
Block(-6,79,-7,CONCRETE:8)
Block(-6,79,-6,STAINED_GLASS_PANE:7)
Block(-6,79,-5,CONCRETE:8)
Block(-6,79,-4,CONCRETE:8)
Block(-6,79,-3,STAINED_GLASS_PANE:7)
Block(-6,79,-2,STAINED_GLASS_PANE:7)
Block(-6,79,-1,CONCRETE:8)
Block(-6,79,0,STAINED_GLASS_PANE:7)
Block(-6,79,1,STAINED_GLASS_PANE:7)
Block(-6,79,2,CONCRETE:8)
Block(-6,80,-7,CONCRETE:8)
Block(-6,80,-6,STAINED_GLASS_PANE:7)
Block(-6,80,-5,CONCRETE:8)
Block(-6,80,-4,CONCRETE:8)
Block(-6,80,-3,STAINED_GLASS_PANE:7)
Block(-6,80,-2,STAINED_GLASS_PANE:7)
Block(-6,80,-1,CONCRETE:8)
Block(-6,80,0,STAINED_GLASS_PANE:7)
Block(-6,80,1,STAINED_GLASS_PANE:7)
Block(-6,80,2,CONCRETE:8)
Block(-6,81,-7,CONCRETE:8)
Block(-6,81,-6,STAINED_GLASS_PANE:7)
Block(-6,81,-5,CONCRETE:8)
Block(-6,81,-4,CONCRETE:8)
Block(-6,81,-3,STAINED_GLASS_PANE:7)
Block(-6,81,-2,STAINED_GLASS_PANE:7)
Block(-6,81,-1,CONCRETE:8)
Block(-6,81,0,STAINED_GLASS_PANE:7)
Block(-6,81,1,STAINED_GLASS_PANE:7)
Block(-6,81,2,CONCRETE:8)
Block(-6,82,-7,CONCRETE:8)
Block(-6,82,-6,CONCRETE:8)
Block(-6,82,-5,CONCRETE:8)
Block(-6,82,-4,CONCRETE:8)
Block(-6,82,-3,STAINED_GLASS_PANE:7)
Block(-6,82,-2,STAINED_GLASS_PANE:7)
Block(-6,82,-1,CONCRETE:8)
Block(-6,82,0,STAINED_GLASS_PANE:7)
Block(-6,82,1,STAINED_GLASS_PANE:7)
Block(-6,82,2,CONCRETE:8)
Block(-6,83,-7,CONCRETE:8)
Block(-6,83,-6,CONCRETE:8)
Block(-6,83,-5,CONCRETE:8)
Block(-6,83,-4,CONCRETE:8)
Block(-6,83,-3,STAINED_GLASS_PANE:7)
Block(-6,83,-2,STAINED_GLASS_PANE:7)
Block(-6,83,-1,CONCRETE:8)
Block(-6,83,0,STAINED_GLASS_PANE:7)
Block(-6,83,1,STAINED_GLASS_PANE:7)
Block(-6,83,2,CONCRETE:8)
Block(-6,84,-7,CONCRETE:8)
Block(-6,84,-6,STEP:0)
Block(-6,84,-5,CONCRETE:8)
Block(-6,84,-4,CONCRETE:8)
Block(-6,84,-3,STAINED_GLASS_PANE:7)
Block(-6,84,-2,STAINED_GLASS_PANE:7)
Block(-6,84,-1,CONCRETE:8)
Block(-6,84,0,STAINED_GLASS_PANE:7)
Block(-6,84,1,STAINED_GLASS_PANE:7)
Block(-6,84,2,CONCRETE:8)
Block(-6,85,-7,CONCRETE:8)
Block(-6,85,-6,STEP:0)
Block(-6,85,-5,CONCRETE:7)
Block(-6,85,-4,CONCRETE:8)
Block(-6,85,-3,STAINED_GLASS_PANE:7)
Block(-6,85,-2,STAINED_GLASS_PANE:7)
Block(-6,85,-1,CONCRETE:8)
Block(-6,85,0,STAINED_GLASS_PANE:7)
Block(-6,85,1,STAINED_GLASS_PANE:7)
Block(-6,85,2,CONCRETE:8)
Block(-6,86,-7,CONCRETE:7)
Block(-6,86,-6,STEP:0)
Block(-6,86,-5,CONCRETE:7)
Block(-6,86,-4,CONCRETE:8)
Block(-6,86,-3,STAINED_GLASS_PANE:7)
Block(-6,86,-2,STAINED_GLASS_PANE:7)
Block(-6,86,-1,CONCRETE:8)
Block(-6,86,0,STAINED_GLASS_PANE:7)
Block(-6,86,1,STAINED_GLASS_PANE:7)
Block(-6,86,2,CONCRETE:8)
Block(-6,87,-7,CONCRETE:8)
Block(-6,87,-6,STEP:0)
Block(-6,87,-5,CONCRETE:7)
Block(-6,87,-4,CONCRETE:7)
Block(-6,87,-3,STAINED_GLASS_PANE:7)
Block(-6,87,-2,STAINED_GLASS_PANE:7)
Block(-6,87,-1,CONCRETE:8)
Block(-6,87,0,STAINED_GLASS_PANE:7)
Block(-6,87,1,STAINED_GLASS_PANE:7)
Block(-6,87,2,CONCRETE:8)
Block(-6,88,-7,CONCRETE:8)
Block(-6,88,-6,STEP:0)
Block(-6,88,-5,CONCRETE:8)
Block(-6,88,-4,CONCRETE:8)
Block(-6,88,-3,CONCRETE:7)
Block(-6,88,-2,CONCRETE:7)
Block(-6,88,-1,CONCRETE:7)
Block(-6,88,0,STAINED_GLASS_PANE:7)
Block(-6,88,1,STAINED_GLASS_PANE:7)
Block(-6,88,2,CONCRETE:8)
Block(-6,89,-7,SMOOTH_STAIRS:0)
Block(-6,89,-6,STEP:0)
Block(-6,89,-5,CONCRETE:8)
Block(-6,89,-4,CONCRETE:8)
Block(-6,89,-3,STEP:0)
Block(-6,89,-2,STEP:0)
Block(-6,89,-1,CONCRETE:8)
Block(-6,89,0,CONCRETE:7)
Block(-6,89,1,CONCRETE:7)
Block(-6,89,2,CONCRETE:8)
Block(-6,89,4,SMOOTH_STAIRS:4)
Block(-6,90,-7,STEP:0)
Block(-6,90,-6,STEP:0)
Block(-6,90,-5,SMOOTH_STAIRS:0)
Block(-6,90,-4,SMOOTH_STAIRS:0)
Block(-6,90,-3,STEP:0)
Block(-6,90,-2,STEP:0)
Block(-6,90,-1,STEP:0)
Block(-6,90,0,STEP:0)
Block(-6,90,1,STEP:0)
Block(-6,90,2,CONCRETE:7)
Block(-6,90,3,SMOOTH_STAIRS:7)
Block(-6,90,4,CONCRETE:7)
Block(-6,91,-7,STEP:0)
Block(-6,91,-6,STEP:0)
Block(-6,91,-5,STEP:0)
Block(-6,91,-4,STEP:0)
Block(-6,91,-3,STEP:0)
Block(-6,91,-2,STEP:0)
Block(-6,91,-1,STEP:0)
Block(-6,91,0,STEP:0)
Block(-6,91,1,STEP:0)
Block(-6,91,2,CONCRETE:8)
Block(-6,91,3,CONCRETE:7)
Block(-6,91,4,IRON_FENCE:0)
Block(-6,92,-7,STEP:8)
Block(-6,92,-6,STEP:8)
Block(-6,92,-5,SMOOTH_STAIRS:4)
Block(-6,92,-4,SMOOTH_STAIRS:4)
Block(-6,92,-3,STEP:8)
Block(-6,92,-2,STEP:8)
Block(-6,92,-1,STEP:8)
Block(-6,92,0,STEP:8)
Block(-6,92,1,STEP:8)
Block(-6,92,2,CONCRETE:7)
Block(-6,92,3,SMOOTH_STAIRS:3)
Block(-6,92,4,CONCRETE:7)
Block(-6,93,-7,SMOOTH_STAIRS:4)
Block(-6,93,-6,STEP:8)
Block(-6,93,-5,CONCRETE:8)
Block(-6,93,-4,CONCRETE:8)
Block(-6,93,-3,STEP:8)
Block(-6,93,-2,STEP:8)
Block(-6,93,-1,CONCRETE:8)
Block(-6,93,0,CONCRETE:7)
Block(-6,93,1,CONCRETE:7)
Block(-6,93,2,CONCRETE:8)
Block(-6,93,4,SMOOTH_STAIRS:0)
Block(-6,94,-7,CONCRETE:8)
Block(-6,94,-6,STEP:8)
Block(-6,94,-5,CONCRETE:8)
Block(-6,94,-4,CONCRETE:8)
Block(-6,94,-3,CONCRETE:7)
Block(-6,94,-2,CONCRETE:7)
Block(-6,94,-1,CONCRETE:7)
Block(-6,94,0,STAINED_GLASS_PANE:7)
Block(-6,94,1,STAINED_GLASS_PANE:7)
Block(-6,94,2,CONCRETE:8)
Block(-6,95,-7,CONCRETE:8)
Block(-6,95,-6,STEP:8)
Block(-6,95,-5,CONCRETE:7)
Block(-6,95,-4,CONCRETE:7)
Block(-6,95,-3,STAINED_GLASS_PANE:7)
Block(-6,95,-2,STAINED_GLASS_PANE:7)
Block(-6,95,-1,CONCRETE:8)
Block(-6,95,0,STAINED_GLASS_PANE:7)
Block(-6,95,1,STAINED_GLASS_PANE:7)
Block(-6,95,2,CONCRETE:8)
Block(-6,96,-7,CONCRETE:7)
Block(-6,96,-6,STEP:8)
Block(-6,96,-5,CONCRETE:7)
Block(-6,96,-4,CONCRETE:8)
Block(-6,96,-3,STAINED_GLASS_PANE:7)
Block(-6,96,-2,STAINED_GLASS_PANE:7)
Block(-6,96,-1,CONCRETE:8)
Block(-6,96,0,STAINED_GLASS_PANE:7)
Block(-6,96,1,STAINED_GLASS_PANE:7)
Block(-6,96,2,CONCRETE:8)
Block(-6,97,-7,CONCRETE:8)
Block(-6,97,-6,STEP:8)
Block(-6,97,-5,CONCRETE:7)
Block(-6,97,-4,CONCRETE:8)
Block(-6,97,-3,STAINED_GLASS_PANE:7)
Block(-6,97,-2,STAINED_GLASS_PANE:7)
Block(-6,97,-1,CONCRETE:8)
Block(-6,97,0,STAINED_GLASS_PANE:7)
Block(-6,97,1,STAINED_GLASS_PANE:7)
Block(-6,97,2,CONCRETE:8)
Block(-6,98,-7,CONCRETE:8)
Block(-6,98,-6,STAINED_GLASS_PANE:7)
Block(-6,98,-5,CONCRETE:8)
Block(-6,98,-4,CONCRETE:8)
Block(-6,98,-3,STAINED_GLASS_PANE:7)
Block(-6,98,-2,STAINED_GLASS_PANE:7)
Block(-6,98,-1,CONCRETE:8)
Block(-6,98,0,STAINED_GLASS_PANE:7)
Block(-6,98,1,STAINED_GLASS_PANE:7)
Block(-6,98,2,CONCRETE:8)
Block(-6,99,-7,CONCRETE:8)
Block(-6,99,-6,STAINED_GLASS_PANE:7)
Block(-6,99,-5,CONCRETE:8)
Block(-6,99,-4,CONCRETE:8)
Block(-6,99,-3,STAINED_GLASS_PANE:7)
Block(-6,99,-2,STAINED_GLASS_PANE:7)
Block(-6,99,-1,CONCRETE:8)
Block(-6,99,0,STAINED_GLASS_PANE:7)
Block(-6,99,1,STAINED_GLASS_PANE:7)
Block(-6,99,2,CONCRETE:8)
Block(-6,100,-7,CONCRETE:8)
Block(-6,100,-6,STAINED_GLASS_PANE:7)
Block(-6,100,-5,CONCRETE:8)
Block(-6,100,-4,CONCRETE:8)
Block(-6,100,-3,STAINED_GLASS_PANE:7)
Block(-6,100,-2,STAINED_GLASS_PANE:7)
Block(-6,100,-1,CONCRETE:8)
Block(-6,100,0,STAINED_GLASS_PANE:7)
Block(-6,100,1,STAINED_GLASS_PANE:7)
Block(-6,100,2,CONCRETE:8)
Block(-6,101,-7,CONCRETE:8)
Block(-6,101,-6,STAINED_GLASS_PANE:7)
Block(-6,101,-5,CONCRETE:8)
Block(-6,101,-4,CONCRETE:8)
Block(-6,101,-3,STAINED_GLASS_PANE:7)
Block(-6,101,-2,STAINED_GLASS_PANE:7)
Block(-6,101,-1,CONCRETE:8)
Block(-6,101,0,STAINED_GLASS_PANE:7)
Block(-6,101,1,STAINED_GLASS_PANE:7)
Block(-6,101,2,CONCRETE:8)
Block(-6,102,-7,CONCRETE:8)
Block(-6,102,-6,STAINED_GLASS_PANE:7)
Block(-6,102,-5,CONCRETE:8)
Block(-6,102,-4,CONCRETE:8)
Block(-6,102,-3,STAINED_GLASS_PANE:7)
Block(-6,102,-2,STAINED_GLASS_PANE:7)
Block(-6,102,-1,CONCRETE:8)
Block(-6,102,0,STAINED_GLASS_PANE:7)
Block(-6,102,1,STAINED_GLASS_PANE:7)
Block(-6,102,2,CONCRETE:8)
Block(-6,103,-7,CONCRETE:8)
Block(-6,103,-6,STAINED_GLASS_PANE:7)
Block(-6,103,-5,CONCRETE:8)
Block(-6,103,-4,CONCRETE:8)
Block(-6,103,-3,STAINED_GLASS_PANE:7)
Block(-6,103,-2,STAINED_GLASS_PANE:7)
Block(-6,103,-1,CONCRETE:8)
Block(-6,103,0,STAINED_GLASS_PANE:7)
Block(-6,103,1,STAINED_GLASS_PANE:7)
Block(-6,103,2,CONCRETE:8)
Block(-6,104,-7,CONCRETE:8)
Block(-6,104,-6,STAINED_GLASS_PANE:7)
Block(-6,104,-5,CONCRETE:8)
Block(-6,104,-4,CONCRETE:8)
Block(-6,104,-3,STAINED_GLASS_PANE:7)
Block(-6,104,-2,STAINED_GLASS_PANE:7)
Block(-6,104,-1,CONCRETE:8)
Block(-6,104,0,STAINED_GLASS_PANE:7)
Block(-6,104,1,STAINED_GLASS_PANE:7)
Block(-6,104,2,CONCRETE:8)
Block(-6,105,-7,CONCRETE:8)
Block(-6,105,-6,STAINED_GLASS_PANE:7)
Block(-6,105,-5,CONCRETE:8)
Block(-6,105,-4,CONCRETE:8)
Block(-6,105,-3,STAINED_GLASS_PANE:7)
Block(-6,105,-2,STAINED_GLASS_PANE:7)
Block(-6,105,-1,CONCRETE:8)
Block(-6,105,0,STAINED_GLASS_PANE:7)
Block(-6,105,1,STAINED_GLASS_PANE:7)
Block(-6,105,2,CONCRETE:8)
Block(-6,106,-7,CONCRETE:8)
Block(-6,106,-6,STAINED_GLASS_PANE:7)
Block(-6,106,-5,CONCRETE:8)
Block(-6,106,-4,CONCRETE:8)
Block(-6,106,-3,STAINED_GLASS_PANE:7)
Block(-6,106,-2,STAINED_GLASS_PANE:7)
Block(-6,106,-1,CONCRETE:8)
Block(-6,106,0,STAINED_GLASS_PANE:7)
Block(-6,106,1,STAINED_GLASS_PANE:7)
Block(-6,106,2,CONCRETE:8)
Block(-6,107,-7,CONCRETE:8)
Block(-6,107,-6,STAINED_GLASS_PANE:7)
Block(-6,107,-5,CONCRETE:8)
Block(-6,107,-4,CONCRETE:8)
Block(-6,107,-3,STAINED_GLASS_PANE:7)
Block(-6,107,-2,STAINED_GLASS_PANE:7)
Block(-6,107,-1,CONCRETE:8)
Block(-6,107,0,STAINED_GLASS_PANE:7)
Block(-6,107,1,STAINED_GLASS_PANE:7)
Block(-6,107,2,CONCRETE:8)
Block(-6,108,-7,CONCRETE:8)
Block(-6,108,-6,STAINED_GLASS_PANE:7)
Block(-6,108,-5,CONCRETE:8)
Block(-6,108,-4,CONCRETE:8)
Block(-6,108,-3,STAINED_GLASS_PANE:7)
Block(-6,108,-2,STAINED_GLASS_PANE:7)
Block(-6,108,-1,CONCRETE:8)
Block(-6,108,0,STAINED_GLASS_PANE:7)
Block(-6,108,1,STAINED_GLASS_PANE:7)
Block(-6,108,2,CONCRETE:8)
Block(-6,109,-7,CONCRETE:8)
Block(-6,109,-6,STAINED_GLASS_PANE:7)
Block(-6,109,-5,CONCRETE:8)
Block(-6,109,-4,CONCRETE:8)
Block(-6,109,-3,STAINED_GLASS_PANE:7)
Block(-6,109,-2,STAINED_GLASS_PANE:7)
Block(-6,109,-1,CONCRETE:8)
Block(-6,109,0,STAINED_GLASS_PANE:7)
Block(-6,109,1,STAINED_GLASS_PANE:7)
Block(-6,109,2,CONCRETE:8)
Block(-6,110,-7,CONCRETE:8)
Block(-6,110,-6,STAINED_GLASS_PANE:7)
Block(-6,110,-5,CONCRETE:8)
Block(-6,110,-4,CONCRETE:8)
Block(-6,110,-3,STAINED_GLASS_PANE:7)
Block(-6,110,-2,STAINED_GLASS_PANE:7)
Block(-6,110,-1,CONCRETE:8)
Block(-6,110,0,STAINED_GLASS_PANE:7)
Block(-6,110,1,STAINED_GLASS_PANE:7)
Block(-6,110,2,CONCRETE:8)
Block(-6,111,-7,CONCRETE:8)
Block(-6,111,-6,STAINED_GLASS_PANE:7)
Block(-6,111,-5,CONCRETE:8)
Block(-6,111,-4,CONCRETE:8)
Block(-6,111,-3,STAINED_GLASS_PANE:7)
Block(-6,111,-2,STAINED_GLASS_PANE:7)
Block(-6,111,-1,CONCRETE:8)
Block(-6,111,0,STAINED_GLASS_PANE:7)
Block(-6,111,1,STAINED_GLASS_PANE:7)
Block(-6,111,2,CONCRETE:8)
Block(-6,112,-7,CONCRETE:8)
Block(-6,112,-6,STAINED_GLASS_PANE:7)
Block(-6,112,-5,CONCRETE:8)
Block(-6,112,-4,CONCRETE:8)
Block(-6,112,-3,STAINED_GLASS_PANE:7)
Block(-6,112,-2,STAINED_GLASS_PANE:7)
Block(-6,112,-1,CONCRETE:8)
Block(-6,112,0,STAINED_GLASS_PANE:7)
Block(-6,112,1,STAINED_GLASS_PANE:7)
Block(-6,112,2,CONCRETE:8)
Block(-6,113,-7,CONCRETE:8)
Block(-6,113,-6,STAINED_GLASS_PANE:7)
Block(-6,113,-5,CONCRETE:8)
Block(-6,113,-4,CONCRETE:8)
Block(-6,113,-3,STAINED_GLASS_PANE:7)
Block(-6,113,-2,STAINED_GLASS_PANE:7)
Block(-6,113,-1,CONCRETE:8)
Block(-6,113,0,STAINED_GLASS_PANE:7)
Block(-6,113,1,STAINED_GLASS_PANE:7)
Block(-6,113,2,CONCRETE:8)
Block(-6,114,-7,CONCRETE:8)
Block(-6,114,-6,STAINED_GLASS_PANE:7)
Block(-6,114,-5,CONCRETE:8)
Block(-6,114,-4,CONCRETE:8)
Block(-6,114,-3,STAINED_GLASS_PANE:7)
Block(-6,114,-2,STAINED_GLASS_PANE:7)
Block(-6,114,-1,CONCRETE:8)
Block(-6,114,0,STAINED_GLASS_PANE:7)
Block(-6,114,1,STAINED_GLASS_PANE:7)
Block(-6,114,2,CONCRETE:8)
Block(-6,115,-7,CONCRETE:8)
Block(-6,115,-6,STAINED_GLASS_PANE:7)
Block(-6,115,-5,CONCRETE:8)
Block(-6,115,-4,CONCRETE:8)
Block(-6,115,-3,STAINED_GLASS_PANE:7)
Block(-6,115,-2,STAINED_GLASS_PANE:7)
Block(-6,115,-1,CONCRETE:8)
Block(-6,115,0,STAINED_GLASS_PANE:7)
Block(-6,115,1,STAINED_GLASS_PANE:7)
Block(-6,115,2,CONCRETE:8)
Block(-6,116,-7,CONCRETE:8)
Block(-6,116,-6,STAINED_GLASS_PANE:7)
Block(-6,116,-5,CONCRETE:8)
Block(-6,116,-4,CONCRETE:8)
Block(-6,116,-3,STAINED_GLASS_PANE:7)
Block(-6,116,-2,STAINED_GLASS_PANE:7)
Block(-6,116,-1,CONCRETE:8)
Block(-6,116,0,STAINED_GLASS_PANE:7)
Block(-6,116,1,STAINED_GLASS_PANE:7)
Block(-6,116,2,CONCRETE:8)
Block(-6,117,-7,CONCRETE:8)
Block(-6,117,-6,STAINED_GLASS_PANE:7)
Block(-6,117,-5,CONCRETE:8)
Block(-6,117,-4,CONCRETE:8)
Block(-6,117,-3,STAINED_GLASS_PANE:7)
Block(-6,117,-2,STAINED_GLASS_PANE:7)
Block(-6,117,-1,CONCRETE:8)
Block(-6,117,0,STAINED_GLASS_PANE:7)
Block(-6,117,1,STAINED_GLASS_PANE:7)
Block(-6,117,2,CONCRETE:8)
Block(-6,118,-7,CONCRETE:8)
Block(-6,118,-6,STAINED_GLASS_PANE:7)
Block(-6,118,-5,CONCRETE:8)
Block(-6,118,-4,CONCRETE:8)
Block(-6,118,-3,STAINED_GLASS_PANE:7)
Block(-6,118,-2,STAINED_GLASS_PANE:7)
Block(-6,118,-1,CONCRETE:8)
Block(-6,118,0,STAINED_GLASS_PANE:7)
Block(-6,118,1,STAINED_GLASS_PANE:7)
Block(-6,118,2,CONCRETE:8)
Block(-6,119,-7,CONCRETE:8)
Block(-6,119,-6,STAINED_GLASS_PANE:7)
Block(-6,119,-5,CONCRETE:8)
Block(-6,119,-4,CONCRETE:8)
Block(-6,119,-3,STAINED_GLASS_PANE:7)
Block(-6,119,-2,STAINED_GLASS_PANE:7)
Block(-6,119,-1,CONCRETE:8)
Block(-6,119,0,STAINED_GLASS_PANE:7)
Block(-6,119,1,STAINED_GLASS_PANE:7)
Block(-6,119,2,CONCRETE:8)
Block(-6,120,-7,CONCRETE:8)
Block(-6,120,-6,STAINED_GLASS_PANE:7)
Block(-6,120,-5,CONCRETE:8)
Block(-6,120,-4,CONCRETE:8)
Block(-6,120,-3,STAINED_GLASS_PANE:7)
Block(-6,120,-2,STAINED_GLASS_PANE:7)
Block(-6,120,-1,CONCRETE:8)
Block(-6,120,0,STAINED_GLASS_PANE:7)
Block(-6,120,1,STAINED_GLASS_PANE:7)
Block(-6,120,2,CONCRETE:8)
Block(-6,121,-7,CONCRETE:8)
Block(-6,121,-6,STAINED_GLASS_PANE:7)
Block(-6,121,-5,CONCRETE:8)
Block(-6,121,-4,CONCRETE:8)
Block(-6,121,-3,STAINED_GLASS_PANE:7)
Block(-6,121,-2,STAINED_GLASS_PANE:7)
Block(-6,121,-1,CONCRETE:8)
Block(-6,121,0,STAINED_GLASS_PANE:7)
Block(-6,121,1,STAINED_GLASS_PANE:7)
Block(-6,121,2,CONCRETE:8)
Block(-6,122,-7,CONCRETE:8)
Block(-6,122,-6,STAINED_GLASS_PANE:7)
Block(-6,122,-5,CONCRETE:8)
Block(-6,122,-4,CONCRETE:8)
Block(-6,122,-3,STAINED_GLASS_PANE:7)
Block(-6,122,-2,STAINED_GLASS_PANE:7)
Block(-6,122,-1,CONCRETE:8)
Block(-6,122,0,STAINED_GLASS_PANE:7)
Block(-6,122,1,STAINED_GLASS_PANE:7)
Block(-6,122,2,CONCRETE:8)
Block(-6,123,-7,CONCRETE:8)
Block(-6,123,-6,STAINED_GLASS_PANE:7)
Block(-6,123,-5,CONCRETE:8)
Block(-6,123,-4,CONCRETE:8)
Block(-6,123,-3,STAINED_GLASS_PANE:7)
Block(-6,123,-2,STAINED_GLASS_PANE:7)
Block(-6,123,-1,CONCRETE:8)
Block(-6,123,0,STAINED_GLASS_PANE:7)
Block(-6,123,1,STAINED_GLASS_PANE:7)
Block(-6,123,2,CONCRETE:8)
Block(-6,124,-7,CONCRETE:8)
Block(-6,124,-6,STAINED_GLASS_PANE:7)
Block(-6,124,-5,CONCRETE:8)
Block(-6,124,-4,CONCRETE:8)
Block(-6,124,-3,STAINED_GLASS_PANE:7)
Block(-6,124,-2,STAINED_GLASS_PANE:7)
Block(-6,124,-1,CONCRETE:8)
Block(-6,124,0,STAINED_GLASS_PANE:7)
Block(-6,124,1,STAINED_GLASS_PANE:7)
Block(-6,124,2,CONCRETE:8)
Block(-6,125,-7,CONCRETE:8)
Block(-6,125,-6,STAINED_GLASS_PANE:7)
Block(-6,125,-5,CONCRETE:8)
Block(-6,125,-4,CONCRETE:8)
Block(-6,125,-3,STAINED_GLASS_PANE:7)
Block(-6,125,-2,STAINED_GLASS_PANE:7)
Block(-6,125,-1,CONCRETE:8)
Block(-6,125,0,STAINED_GLASS_PANE:7)
Block(-6,125,1,STAINED_GLASS_PANE:7)
Block(-6,125,2,CONCRETE:8)
Block(-6,126,-7,CONCRETE:8)
Block(-6,126,-6,STAINED_GLASS_PANE:7)
Block(-6,126,-5,CONCRETE:8)
Block(-6,126,-4,CONCRETE:8)
Block(-6,126,-3,STAINED_GLASS_PANE:7)
Block(-6,126,-2,STAINED_GLASS_PANE:7)
Block(-6,126,-1,CONCRETE:8)
Block(-6,126,0,STAINED_GLASS_PANE:7)
Block(-6,126,1,STAINED_GLASS_PANE:7)
Block(-6,126,2,CONCRETE:8)
Block(-6,127,-7,CONCRETE:8)
Block(-6,127,-6,STAINED_GLASS_PANE:7)
Block(-6,127,-5,CONCRETE:8)
Block(-6,127,-4,CONCRETE:8)
Block(-6,127,-3,STAINED_GLASS_PANE:7)
Block(-6,127,-2,STAINED_GLASS_PANE:7)
Block(-6,127,-1,CONCRETE:8)
Block(-6,127,0,STAINED_GLASS_PANE:7)
Block(-6,127,1,STAINED_GLASS_PANE:7)
Block(-6,127,2,CONCRETE:8)
Block(-6,128,-7,CONCRETE:8)
Block(-6,128,-6,STAINED_GLASS_PANE:7)
Block(-6,128,-5,CONCRETE:8)
Block(-6,128,-4,CONCRETE:8)
Block(-6,128,-3,STAINED_GLASS_PANE:7)
Block(-6,128,-2,STAINED_GLASS_PANE:7)
Block(-6,128,-1,CONCRETE:8)
Block(-6,128,0,STAINED_GLASS_PANE:7)
Block(-6,128,1,STAINED_GLASS_PANE:7)
Block(-6,128,2,CONCRETE:8)
Block(-6,129,-7,CONCRETE:8)
Block(-6,129,-6,STAINED_GLASS_PANE:7)
Block(-6,129,-5,CONCRETE:8)
Block(-6,129,-4,CONCRETE:8)
Block(-6,129,-3,STAINED_GLASS_PANE:7)
Block(-6,129,-2,STAINED_GLASS_PANE:7)
Block(-6,129,-1,CONCRETE:8)
Block(-6,129,0,STAINED_GLASS_PANE:7)
Block(-6,129,1,STAINED_GLASS_PANE:7)
Block(-6,129,2,CONCRETE:8)
Block(-6,130,-7,CONCRETE:8)
Block(-6,130,-6,STAINED_GLASS_PANE:7)
Block(-6,130,-5,CONCRETE:8)
Block(-6,130,-4,CONCRETE:8)
Block(-6,130,-3,STAINED_GLASS_PANE:7)
Block(-6,130,-2,STAINED_GLASS_PANE:7)
Block(-6,130,-1,CONCRETE:8)
Block(-6,130,0,SMOOTH_STAIRS:4)
Block(-6,130,1,SMOOTH_STAIRS:4)
Block(-6,130,2,CONCRETE:8)
Block(-6,131,-7,CONCRETE:8)
Block(-6,131,-6,STAINED_GLASS_PANE:7)
Block(-6,131,-5,CONCRETE:8)
Block(-6,131,-4,CONCRETE:8)
Block(-6,131,-3,STAINED_GLASS_PANE:7)
Block(-6,131,-2,STAINED_GLASS_PANE:7)
Block(-6,131,-1,CONCRETE:8)
Block(-6,131,0,CONCRETE:8)
Block(-6,131,1,CONCRETE:8)
Block(-6,131,2,SMOOTH_STAIRS:0)
Block(-6,132,-7,CONCRETE:8)
Block(-6,132,-6,SMOOTH_STAIRS:4)
Block(-6,132,-5,CONCRETE:8)
Block(-6,132,-4,CONCRETE:8)
Block(-6,132,-3,SMOOTH_STAIRS:4)
Block(-6,132,-2,SMOOTH_STAIRS:4)
Block(-6,132,-1,CONCRETE:8)
Block(-6,132,0,SMOOTH_STAIRS:0)
Block(-6,132,1,SMOOTH_STAIRS:0)
Block(-6,132,2,SMOOTH_STAIRS:4)
Block(-6,133,-7,CONCRETE:8)
Block(-6,133,-6,CONCRETE:8)
Block(-6,133,-5,CONCRETE:8)
Block(-6,133,-4,CONCRETE:8)
Block(-6,133,-3,CONCRETE:8)
Block(-6,133,-2,CONCRETE:8)
Block(-6,133,-1,SMOOTH_STAIRS:0)
Block(-6,133,0,SMOOTH_STAIRS:4)
Block(-6,133,1,SMOOTH_STAIRS:4)
Block(-6,133,2,CONCRETE:8)
Block(-6,133,3,STEP:8)
Block(-6,133,4,SMOOTH_STAIRS:4)
Block(-6,134,-7,CONCRETE:8)
Block(-6,134,-6,CONCRETE:8)
Block(-6,134,-5,CONCRETE:8)
Block(-6,134,-4,CONCRETE:8)
Block(-6,134,-3,SMOOTH_STAIRS:0)
Block(-6,134,-2,COBBLE_WALL:0)
Block(-6,134,-1,SMOOTH_STAIRS:4)
Block(-6,134,0,CONCRETE:8)
Block(-6,134,1,CONCRETE:8)
Block(-6,134,2,CONCRETE:7)
Block(-6,134,3,CONCRETE:7)
Block(-6,134,4,CONCRETE:7)
Block(-6,135,-7,STEP:0)
Block(-6,135,-5,CONCRETE:8)
Block(-6,135,-4,STEP:0)
Block(-6,135,-3,SMOOTH_STAIRS:4)
Block(-6,135,-2,CONCRETE:8)
Block(-6,135,-1,CONCRETE:8)
Block(-6,135,0,CONCRETE:7)
Block(-6,135,1,CONCRETE:7)
Block(-6,135,2,CONCRETE:7)
Block(-6,135,3,CONCRETE:7)
Block(-6,135,4,CONCRETE:15)
Block(-6,136,-7,SMOOTH_STAIRS:4)
Block(-6,136,-5,STEP:0)
Block(-6,136,-4,SMOOTH_STAIRS:4)
Block(-6,136,-3,CONCRETE:8)
Block(-6,136,-2,CONCRETE:7)
Block(-6,136,-1,CONCRETE:7)
Block(-6,136,0,CONCRETE:7)
Block(-6,136,1,CONCRETE:7)
Block(-6,136,2,CONCRETE:7)
Block(-6,136,3,CONCRETE:15)
Block(-6,136,4,CONCRETE:15)
Block(-6,136,5,SMOOTH_STAIRS:4)
Block(-6,137,-7,CONCRETE:8)
Block(-6,137,-6,STONE_BUTTON:2)
Block(-6,137,-5,SMOOTH_STAIRS:4)
Block(-6,137,-4,CONCRETE:8)
Block(-6,137,-3,CONCRETE:7)
Block(-6,137,-2,CONCRETE:7)
Block(-6,137,-1,CONCRETE:7)
Block(-6,137,0,CONCRETE:7)
Block(-6,137,1,CONCRETE:7)
Block(-6,137,2,CONCRETE:7)
Block(-6,137,3,CONCRETE:15)
Block(-6,137,4,CONCRETE:15)
Block(-6,137,5,CONCRETE:7)
Block(-6,137,6,STEP:8)
Block(-6,138,-7,CONCRETE:8)
Block(-6,138,-6,CONCRETE:8)
Block(-6,138,-5,CONCRETE:8)
Block(-6,138,-4,CONCRETE:7)
Block(-6,138,-3,CONCRETE:7)
Block(-6,138,-2,CONCRETE:7)
Block(-6,138,-1,CONCRETE:7)
Block(-6,138,0,CONCRETE:7)
Block(-6,138,1,CONCRETE:7)
Block(-6,138,2,CONCRETE:7)
Block(-6,138,3,CONCRETE:15)
Block(-6,138,4,CONCRETE:15)
Block(-6,138,5,CONCRETE:7)
Block(-6,138,6,CONCRETE:8)
Block(-6,138,7,STEP:8)
Block(-6,139,-7,CONCRETE:7)
Block(-6,139,-6,CONCRETE:7)
Block(-6,139,-5,CONCRETE:7)
Block(-6,139,-4,CONCRETE:7)
Block(-6,139,-3,CONCRETE:7)
Block(-6,139,-2,CONCRETE:7)
Block(-6,139,-1,CONCRETE:7)
Block(-6,139,0,CONCRETE:7)
Block(-6,139,1,CONCRETE:7)
Block(-6,139,2,CONCRETE:7)
Block(-6,139,3,CONCRETE:15)
Block(-6,139,4,CONCRETE:15)
Block(-6,139,5,CONCRETE:7)
Block(-6,139,6,CONCRETE:7)
Block(-6,139,7,SMOOTH_STAIRS:0)
Block(-6,140,-7,STAINED_GLASS:15)
Block(-6,140,-6,STAINED_GLASS:15)
Block(-6,140,-5,STAINED_GLASS:15)
Block(-6,140,-4,CONCRETE:7)
Block(-6,140,-3,CONCRETE:7)
Block(-6,140,-2,STAINED_GLASS:15)
Block(-6,140,-1,STAINED_GLASS:15)
Block(-6,140,0,STAINED_GLASS:15)
Block(-6,140,1,STAINED_GLASS:15)
Block(-6,140,2,STAINED_GLASS:15)
Block(-6,140,3,CONCRETE:7)
Block(-6,140,4,CONCRETE:7)
Block(-6,140,5,CONCRETE:7)
Block(-6,140,6,CONCRETE:7)
Block(-6,141,-7,STAINED_GLASS:15)
Block(-6,141,-6,STAINED_GLASS:15)
Block(-6,141,-5,STAINED_GLASS:15)
Block(-6,141,-4,CONCRETE:7)
Block(-6,141,-3,STAINED_GLASS:15)
Block(-6,141,-2,STAINED_GLASS:15)
Block(-6,141,-1,STAINED_GLASS:15)
Block(-6,141,0,STAINED_GLASS:15)
Block(-6,141,1,STAINED_GLASS:15)
Block(-6,141,2,STAINED_GLASS:15)
Block(-6,141,3,STAINED_GLASS:15)
Block(-6,141,4,CONCRETE:7)
Block(-6,141,5,STAINED_GLASS:15)
Block(-6,141,6,CONCRETE:7)
Block(-6,142,-7,STAINED_GLASS:15)
Block(-6,142,-6,STAINED_GLASS:15)
Block(-6,142,-5,STAINED_GLASS:15)
Block(-6,142,-4,CONCRETE:7)
Block(-6,142,-3,STAINED_GLASS:15)
Block(-6,142,-2,STAINED_GLASS:15)
Block(-6,142,-1,STAINED_GLASS:15)
Block(-6,142,0,STAINED_GLASS:15)
Block(-6,142,1,STAINED_GLASS:15)
Block(-6,142,2,STAINED_GLASS:15)
Block(-6,142,3,STAINED_GLASS:15)
Block(-6,142,4,CONCRETE:7)
Block(-6,142,5,STAINED_GLASS:15)
Block(-6,142,6,CONCRETE:7)
Block(-6,142,7,SMOOTH_STAIRS:7)
Block(-6,143,-7,CONCRETE:7)
Block(-6,143,-6,CONCRETE:7)
Block(-6,143,-5,CONCRETE:7)
Block(-6,143,-4,CONCRETE:7)
Block(-6,143,-3,CONCRETE:7)
Block(-6,143,-2,CONCRETE:7)
Block(-6,143,-1,CONCRETE:7)
Block(-6,143,0,CONCRETE:7)
Block(-6,143,1,CONCRETE:7)
Block(-6,143,2,CONCRETE:7)
Block(-6,143,3,CONCRETE:7)
Block(-6,143,4,CONCRETE:7)
Block(-6,143,5,CONCRETE:7)
Block(-6,143,6,CONCRETE:7)
Block(-6,143,7,CONCRETE:7)
Block(-6,144,-7,CONCRETE:7)
Block(-6,144,-6,CONCRETE:7)
Block(-6,144,-5,CONCRETE:7)
Block(-6,144,-4,CONCRETE:7)
Block(-6,144,-3,CONCRETE:7)
Block(-6,144,-2,CONCRETE:7)
Block(-6,144,-1,STAINED_GLASS:15)
Block(-6,144,0,CONCRETE:7)
Block(-6,144,1,STAINED_GLASS:15)
Block(-6,144,2,CONCRETE:7)
Block(-6,144,3,STAINED_GLASS:15)
Block(-6,144,4,CONCRETE:7)
Block(-6,144,5,CONCRETE:7)
Block(-6,144,6,CONCRETE:7)
Block(-6,144,7,STEP:0)
Block(-6,145,-7,IRON_FENCE:0)
Block(-6,145,-6,IRON_FENCE:0)
Block(-6,145,-5,IRON_FENCE:0)
Block(-6,145,-4,CONCRETE:7)
Block(-6,145,-3,IRON_FENCE:0)
Block(-6,145,-2,CONCRETE:7)
Block(-6,145,-1,STAINED_GLASS:15)
Block(-6,145,0,STAINED_GLASS_PANE:15)
Block(-6,145,1,STAINED_GLASS:15)
Block(-6,145,2,STAINED_GLASS_PANE:15)
Block(-6,145,3,STAINED_GLASS:15)
Block(-6,145,4,CONCRETE:7)
Block(-6,145,5,CONCRETE:7)
Block(-6,145,6,STEP:0)
Block(-6,146,-4,STEP:0)
Block(-6,146,-2,CONCRETE:7)
Block(-6,146,-1,STAINED_GLASS:15)
Block(-6,146,0,STAINED_GLASS_PANE:15)
Block(-6,146,1,STAINED_GLASS:15)
Block(-6,146,2,STAINED_GLASS_PANE:15)
Block(-6,146,3,STAINED_GLASS:15)
Block(-6,146,4,CONCRETE:7)
Block(-6,146,5,SMOOTH_STAIRS:0)
Block(-6,147,-2,CONCRETE:7)
Block(-6,147,-1,STAINED_GLASS:15)
Block(-6,147,0,STAINED_GLASS_PANE:15)
Block(-6,147,1,STAINED_GLASS:15)
Block(-6,147,2,STAINED_GLASS_PANE:15)
Block(-6,147,3,STAINED_GLASS:15)
Block(-6,147,4,CONCRETE:7)
Block(-6,148,-2,CONCRETE:7)
Block(-6,148,-1,STAINED_GLASS:15)
Block(-6,148,0,STAINED_GLASS_PANE:15)
Block(-6,148,1,STAINED_GLASS:15)
Block(-6,148,2,STAINED_GLASS_PANE:15)
Block(-6,148,3,STAINED_GLASS:15)
Block(-6,148,4,CONCRETE:7)
Block(-6,149,-4,SMOOTH_STAIRS:4)
Block(-6,149,-3,SMOOTH_STAIRS:4)
Block(-6,149,-2,CONCRETE:7)
Block(-6,149,-1,STAINED_GLASS:15)
Block(-6,149,0,CONCRETE:7)
Block(-6,149,1,STAINED_GLASS:15)
Block(-6,149,2,CONCRETE:7)
Block(-6,149,3,STAINED_GLASS:15)
Block(-6,149,4,CONCRETE:7)
Block(-6,150,-4,IRON_FENCE:0)
Block(-6,150,-3,IRON_FENCE:0)
Block(-6,150,-2,CONCRETE:7)
Block(-6,150,-1,IRON_FENCE:0)
Block(-6,150,0,CONCRETE:7)
Block(-6,150,1,IRON_FENCE:0)
Block(-6,150,2,CONCRETE:7)
Block(-6,150,3,IRON_FENCE:0)
Block(-6,150,4,CONCRETE:7)
Block(-6,151,-2,STEP:0)
Block(-6,151,0,STEP:0)
Block(-6,151,2,STEP:0)
Block(-6,151,4,STEP:0)
Block(-5,0,-7,CONCRETE:7)
Block(-5,0,-6,CONCRETE:7)
Block(-5,0,-5,CONCRETE:7)
Block(-5,0,-4,CONCRETE:7)
Block(-5,0,-3,CONCRETE:7)
Block(-5,0,-2,CONCRETE:7)
Block(-5,0,-1,CONCRETE:7)
Block(-5,0,0,CONCRETE:7)
Block(-5,0,1,CONCRETE:7)
Block(-5,0,2,CONCRETE:7)
Block(-5,0,3,CONCRETE:7)
Block(-5,0,4,CONCRETE:7)
Block(-5,0,5,CONCRETE:7)
Block(-5,0,6,CONCRETE:7)
Block(-5,0,7,CONCRETE:7)
Block(-5,0,8,CONCRETE:7)
Block(-5,1,-7,CONCRETE:7)
Block(-5,1,-6,CONCRETE:7)
Block(-5,1,-5,CONCRETE:7)
Block(-5,1,-4,CONCRETE:7)
Block(-5,1,-3,CONCRETE:7)
Block(-5,1,-2,CONCRETE:7)
Block(-5,1,-1,CONCRETE:7)
Block(-5,1,0,CONCRETE:7)
Block(-5,1,1,CONCRETE:7)
Block(-5,1,2,CONCRETE:7)
Block(-5,1,3,CONCRETE:7)
Block(-5,1,4,CONCRETE:7)
Block(-5,1,5,CONCRETE:7)
Block(-5,1,6,CONCRETE:7)
Block(-5,1,7,CONCRETE:7)
Block(-5,1,8,CONCRETE:7)
Block(-5,2,-7,CONCRETE:7)
Block(-5,2,-6,CONCRETE:7)
Block(-5,2,-5,CONCRETE:7)
Block(-5,2,-4,CONCRETE:7)
Block(-5,2,-3,CONCRETE:7)
Block(-5,2,-2,CONCRETE:7)
Block(-5,2,-1,CONCRETE:7)
Block(-5,2,0,CONCRETE:7)
Block(-5,2,1,CONCRETE:7)
Block(-5,2,2,CONCRETE:7)
Block(-5,2,3,CONCRETE:7)
Block(-5,2,4,CONCRETE:7)
Block(-5,2,5,CONCRETE:7)
Block(-5,2,6,CONCRETE:7)
Block(-5,2,7,CONCRETE:7)
Block(-5,2,8,CONCRETE:7)
Block(-5,3,-7,CONCRETE:7)
Block(-5,3,-6,SMOOTH_STAIRS:1)
Block(-5,3,-5,SMOOTH_STAIRS:1)
Block(-5,3,-4,CONCRETE:7)
Block(-5,3,-3,SMOOTH_STAIRS:1)
Block(-5,3,-2,SMOOTH_STAIRS:1)
Block(-5,3,-1,CONCRETE:7)
Block(-5,3,0,SMOOTH_STAIRS:1)
Block(-5,3,1,SMOOTH_STAIRS:1)
Block(-5,3,2,CONCRETE:7)
Block(-5,3,3,SMOOTH_STAIRS:1)
Block(-5,3,4,SMOOTH_STAIRS:1)
Block(-5,3,5,CONCRETE:7)
Block(-5,3,6,SMOOTH_STAIRS:1)
Block(-5,3,7,SMOOTH_STAIRS:1)
Block(-5,3,8,CONCRETE:7)
Block(-5,4,-7,CONCRETE:7)
Block(-5,4,-6,COBBLE_WALL:0)
Block(-5,4,-5,COBBLE_WALL:0)
Block(-5,4,-4,CONCRETE:7)
Block(-5,4,-3,COBBLE_WALL:0)
Block(-5,4,-2,COBBLE_WALL:0)
Block(-5,4,-1,CONCRETE:7)
Block(-5,4,0,COBBLE_WALL:0)
Block(-5,4,1,COBBLE_WALL:0)
Block(-5,4,2,CONCRETE:7)
Block(-5,4,3,COBBLE_WALL:0)
Block(-5,4,4,COBBLE_WALL:0)
Block(-5,4,5,CONCRETE:7)
Block(-5,4,6,COBBLE_WALL:0)
Block(-5,4,7,COBBLE_WALL:0)
Block(-5,4,8,CONCRETE:7)
Block(-5,5,-7,CONCRETE:7)
Block(-5,5,-6,SMOOTH_STAIRS:5)
Block(-5,5,-5,SMOOTH_STAIRS:5)
Block(-5,5,-4,CONCRETE:7)
Block(-5,5,-3,SMOOTH_STAIRS:5)
Block(-5,5,-2,SMOOTH_STAIRS:5)
Block(-5,5,-1,CONCRETE:7)
Block(-5,5,0,SMOOTH_STAIRS:5)
Block(-5,5,1,SMOOTH_STAIRS:5)
Block(-5,5,2,CONCRETE:7)
Block(-5,5,3,SMOOTH_STAIRS:5)
Block(-5,5,4,SMOOTH_STAIRS:5)
Block(-5,5,5,CONCRETE:7)
Block(-5,5,6,SMOOTH_STAIRS:5)
Block(-5,5,7,SMOOTH_STAIRS:5)
Block(-5,5,8,CONCRETE:7)
Block(-5,6,-7,CONCRETE:7)
Block(-5,6,-6,CONCRETE:7)
Block(-5,6,-5,CONCRETE:7)
Block(-5,6,-4,CONCRETE:7)
Block(-5,6,-3,CONCRETE:7)
Block(-5,6,-2,CONCRETE:7)
Block(-5,6,-1,CONCRETE:7)
Block(-5,6,0,CONCRETE:7)
Block(-5,6,1,CONCRETE:7)
Block(-5,6,2,CONCRETE:7)
Block(-5,6,3,CONCRETE:7)
Block(-5,6,4,CONCRETE:7)
Block(-5,6,5,CONCRETE:7)
Block(-5,6,6,CONCRETE:7)
Block(-5,6,7,CONCRETE:7)
Block(-5,6,8,CONCRETE:7)
Block(-5,7,-7,CONCRETE:15)
Block(-5,7,-6,CONCRETE:15)
Block(-5,7,-5,CONCRETE:15)
Block(-5,7,-4,CONCRETE:15)
Block(-5,7,-3,CONCRETE:15)
Block(-5,7,-2,CONCRETE:15)
Block(-5,7,-1,CONCRETE:15)
Block(-5,7,0,CONCRETE:15)
Block(-5,7,1,CONCRETE:15)
Block(-5,7,2,CONCRETE:15)
Block(-5,7,3,CONCRETE:15)
Block(-5,7,4,CONCRETE:15)
Block(-5,7,5,CONCRETE:15)
Block(-5,7,6,CONCRETE:15)
Block(-5,7,7,CONCRETE:15)
Block(-5,7,8,CONCRETE:7)
Block(-5,8,-3,CONCRETE:7)
Block(-5,8,-2,CONCRETE:7)
Block(-5,8,-1,CONCRETE:7)
Block(-5,8,0,CONCRETE:15)
Block(-5,8,1,CONCRETE:15)
Block(-5,8,2,CONCRETE:7)
Block(-5,8,3,BRICK:0)
Block(-5,8,4,BRICK_STAIRS:6)
Block(-5,8,5,BRICK_STAIRS:7)
Block(-5,8,6,STEP:12)
Block(-5,8,7,BRICK_STAIRS:6)
Block(-5,8,8,BRICK:0)
Block(-5,9,-3,CONCRETE:7)
Block(-5,9,-2,CONCRETE:7)
Block(-5,9,-1,CONCRETE:7)
Block(-5,9,0,STEP:4)
Block(-5,9,1,BRICK_STAIRS:6)
Block(-5,9,2,CONCRETE:7)
Block(-5,9,3,CONCRETE:7)
Block(-5,9,4,BRICK:0)
Block(-5,9,5,CONCRETE:7)
Block(-5,9,6,CONCRETE:7)
Block(-5,9,7,CONCRETE:7)
Block(-5,9,8,BRICK:0)
Block(-5,10,-3,CONCRETE:7)
Block(-5,10,-2,CONCRETE:7)
Block(-5,10,-1,CONCRETE:7)
Block(-5,10,2,BRICK_STAIRS:2)
Block(-5,10,3,CONCRETE:7)
Block(-5,10,4,CONCRETE:7)
Block(-5,10,5,CONCRETE:7)
Block(-5,10,8,CONCRETE:7)
Block(-5,11,-3,CONCRETE:7)
Block(-5,11,-2,CONCRETE:7)
Block(-5,11,-1,CONCRETE:7)
Block(-5,11,2,BRICK_STAIRS:6)
Block(-5,11,3,CONCRETE:7)
Block(-5,11,4,CONCRETE:7)
Block(-5,11,5,PRISMARINE:0)
Block(-5,11,8,CONCRETE:7)
Block(-5,12,-3,CONCRETE:7)
Block(-5,12,-2,CONCRETE:7)
Block(-5,12,-1,CONCRETE:7)
Block(-5,12,2,CONCRETE:7)
Block(-5,12,3,CONCRETE:7)
Block(-5,12,4,CONCRETE:7)
Block(-5,12,5,CONCRETE:7)
Block(-5,12,8,CONCRETE:7)
Block(-5,13,-3,CONCRETE:7)
Block(-5,13,-2,CONCRETE:7)
Block(-5,13,-1,CONCRETE:7)
Block(-5,13,2,CONCRETE:7)
Block(-5,13,3,CONCRETE:7)
Block(-5,13,4,CONCRETE:7)
Block(-5,13,5,CONCRETE:7)
Block(-5,13,6,CONCRETE:7)
Block(-5,13,7,CONCRETE:7)
Block(-5,13,8,CONCRETE:7)
Block(-5,14,-6,STEP:12)
Block(-5,14,-3,CONCRETE:7)
Block(-5,14,-2,CONCRETE:7)
Block(-5,14,-1,CONCRETE:7)
Block(-5,14,0,SMOOTH_STAIRS:7)
Block(-5,14,2,CONCRETE:7)
Block(-5,14,3,CONCRETE:7)
Block(-5,14,4,STAINED_GLASS_PANE:0)
Block(-5,14,5,STAINED_GLASS_PANE:0)
Block(-5,14,8,CONCRETE:7)
Block(-5,15,-7,BRICK_STAIRS:4)
Block(-5,15,-6,CONCRETE:7)
Block(-5,15,-5,CONCRETE:7)
Block(-5,15,-4,BRICK_STAIRS:6)
Block(-5,15,-3,CONCRETE:7)
Block(-5,15,-2,CONCRETE:7)
Block(-5,15,-1,CONCRETE:7)
Block(-5,15,0,CONCRETE:7)
Block(-5,15,1,CONCRETE:7)
Block(-5,15,2,CONCRETE:7)
Block(-5,15,3,CONCRETE:7)
Block(-5,15,4,CONCRETE:7)
Block(-5,15,5,CONCRETE:7)
Block(-5,15,6,CONCRETE:7)
Block(-5,15,7,CONCRETE:7)
Block(-5,15,8,CONCRETE:7)
Block(-5,16,-7,CONCRETE:7)
Block(-5,16,-6,CONCRETE:7)
Block(-5,16,-5,CONCRETE:7)
Block(-5,16,-4,CONCRETE:7)
Block(-5,16,-3,CONCRETE:7)
Block(-5,16,-2,CONCRETE:7)
Block(-5,16,-1,CONCRETE:7)
Block(-5,16,0,CONCRETE:7)
Block(-5,16,1,CONCRETE:7)
Block(-5,16,2,CONCRETE:7)
Block(-5,16,3,CONCRETE:7)
Block(-5,16,4,CONCRETE:7)
Block(-5,16,5,CONCRETE:7)
Block(-5,16,6,CONCRETE:7)
Block(-5,16,7,CONCRETE:7)
Block(-5,16,8,CONCRETE:7)
Block(-5,17,-7,CONCRETE:15)
Block(-5,17,-6,CONCRETE:15)
Block(-5,17,-5,CONCRETE:15)
Block(-5,17,-4,CONCRETE:15)
Block(-5,17,-3,CONCRETE:7)
Block(-5,17,-2,CONCRETE:7)
Block(-5,17,-1,CONCRETE:7)
Block(-5,17,0,CONCRETE:7)
Block(-5,17,1,CONCRETE:7)
Block(-5,17,2,CONCRETE:7)
Block(-5,17,3,CONCRETE:7)
Block(-5,17,4,CONCRETE:7)
Block(-5,17,5,CONCRETE:7)
Block(-5,17,6,CONCRETE:7)
Block(-5,17,7,CONCRETE:7)
Block(-5,17,8,SMOOTH_STAIRS:3)
Block(-5,18,-6,QUARTZ_STAIRS:1)
Block(-5,18,-5,QUARTZ_STAIRS:1)
Block(-5,18,-4,QUARTZ_STAIRS:1)
Block(-5,18,-3,CONCRETE:8)
Block(-5,18,-2,CONCRETE:8)
Block(-5,18,-1,CONCRETE:8)
Block(-5,18,0,CONCRETE:7)
Block(-5,18,1,SMOOTH_STAIRS:0)
Block(-5,18,2,CONCRETE:7)
Block(-5,18,3,CONCRETE:7)
Block(-5,18,4,CONCRETE:7)
Block(-5,18,5,CONCRETE:7)
Block(-5,18,6,CONCRETE:8)
Block(-5,18,7,SMOOTH_STAIRS:3)
Block(-5,19,-3,CONCRETE:8)
Block(-5,19,-2,STAINED_GLASS_PANE:7)
Block(-5,19,-1,STAINED_GLASS_PANE:7)
Block(-5,19,0,CONCRETE:7)
Block(-5,19,2,CONCRETE:7)
Block(-5,19,3,CONCRETE:7)
Block(-5,19,4,CONCRETE:7)
Block(-5,19,5,CONCRETE:7)
Block(-5,19,6,CONCRETE:8)
Block(-5,20,-3,CONCRETE:8)
Block(-5,20,-2,STAINED_GLASS_PANE:7)
Block(-5,20,-1,STAINED_GLASS_PANE:7)
Block(-5,20,0,CONCRETE:7)
Block(-5,20,2,CONCRETE:7)
Block(-5,20,3,CONCRETE:7)
Block(-5,20,4,CONCRETE:7)
Block(-5,20,5,CONCRETE:7)
Block(-5,20,6,CONCRETE:8)
Block(-5,21,-3,CONCRETE:8)
Block(-5,21,-2,STAINED_GLASS_PANE:7)
Block(-5,21,-1,STAINED_GLASS_PANE:7)
Block(-5,21,0,CONCRETE:7)
Block(-5,21,2,SMOOTH_STAIRS:0)
Block(-5,21,3,CONCRETE:7)
Block(-5,21,4,CONCRETE:7)
Block(-5,21,5,CONCRETE:7)
Block(-5,21,6,CONCRETE:8)
Block(-5,22,-6,SMOOTH_STAIRS:5)
Block(-5,22,-3,CONCRETE:8)
Block(-5,22,-2,STAINED_GLASS_PANE:7)
Block(-5,22,-1,STAINED_GLASS_PANE:7)
Block(-5,22,0,STEP:0)
Block(-5,22,3,CONCRETE:7)
Block(-5,22,4,CONCRETE:7)
Block(-5,22,5,CONCRETE:7)
Block(-5,22,6,SMOOTH_STAIRS:3)
Block(-5,23,-7,TRAP_DOOR:4)
Block(-5,23,-6,DIRT:2)
Block(-5,23,-5,TRAP_DOOR:5)
Block(-5,23,-3,CONCRETE:8)
Block(-5,23,-2,STAINED_GLASS_PANE:7)
Block(-5,23,-1,STAINED_GLASS_PANE:7)
Block(-5,23,0,STEP:8)
Block(-5,23,3,CONCRETE:7)
Block(-5,23,4,CONCRETE:7)
Block(-5,23,5,CONCRETE:7)
Block(-5,23,6,SMOOTH_STAIRS:7)
Block(-5,24,-6,DOUBLE_PLANT:2)
Block(-5,24,-3,CONCRETE:8)
Block(-5,24,-2,STAINED_GLASS_PANE:7)
Block(-5,24,-1,STAINED_GLASS_PANE:7)
Block(-5,24,0,CONCRETE:7)
Block(-5,24,2,SMOOTH_STAIRS:4)
Block(-5,24,3,CONCRETE:7)
Block(-5,24,4,CONCRETE:7)
Block(-5,24,5,CONCRETE:7)
Block(-5,24,6,CONCRETE:8)
Block(-5,25,-6,DOUBLE_PLANT:10)
Block(-5,25,-3,CONCRETE:8)
Block(-5,25,-2,STAINED_GLASS_PANE:7)
Block(-5,25,-1,STAINED_GLASS_PANE:7)
Block(-5,25,0,CONCRETE:7)
Block(-5,25,2,CONCRETE:7)
Block(-5,25,3,CONCRETE:7)
Block(-5,25,4,CONCRETE:7)
Block(-5,25,5,CONCRETE:7)
Block(-5,25,6,CONCRETE:8)
Block(-5,26,-3,CONCRETE:8)
Block(-5,26,-2,STAINED_GLASS_PANE:7)
Block(-5,26,-1,STAINED_GLASS_PANE:7)
Block(-5,26,0,CONCRETE:7)
Block(-5,26,2,CONCRETE:7)
Block(-5,26,3,CONCRETE:7)
Block(-5,26,4,CONCRETE:7)
Block(-5,26,5,CONCRETE:7)
Block(-5,26,6,CONCRETE:8)
Block(-5,27,-3,CONCRETE:8)
Block(-5,27,-2,CONCRETE:8)
Block(-5,27,-1,CONCRETE:8)
Block(-5,27,0,CONCRETE:7)
Block(-5,27,1,SMOOTH_STAIRS:4)
Block(-5,27,2,CONCRETE:7)
Block(-5,27,3,CONCRETE:7)
Block(-5,27,4,CONCRETE:7)
Block(-5,27,5,CONCRETE:7)
Block(-5,27,6,CONCRETE:8)
Block(-5,27,7,SMOOTH_STAIRS:7)
Block(-5,28,-7,CONCRETE:7)
Block(-5,28,-6,CONCRETE:7)
Block(-5,28,-5,CONCRETE:7)
Block(-5,28,-4,CONCRETE:7)
Block(-5,28,-3,CONCRETE:7)
Block(-5,28,-2,CONCRETE:7)
Block(-5,28,-1,CONCRETE:7)
Block(-5,28,0,CONCRETE:7)
Block(-5,28,1,CONCRETE:7)
Block(-5,28,2,CONCRETE:7)
Block(-5,28,3,CONCRETE:7)
Block(-5,28,4,CONCRETE:7)
Block(-5,28,5,CONCRETE:7)
Block(-5,28,6,CONCRETE:7)
Block(-5,28,7,CONCRETE:15)
Block(-5,29,-7,CONCRETE:7)
Block(-5,29,-6,CONCRETE:7)
Block(-5,29,-5,CONCRETE:7)
Block(-5,29,-4,CONCRETE:7)
Block(-5,29,-3,CONCRETE:7)
Block(-5,29,-2,CONCRETE:7)
Block(-5,29,-1,CONCRETE:7)
Block(-5,29,0,CONCRETE:7)
Block(-5,29,1,CONCRETE:7)
Block(-5,29,2,CONCRETE:7)
Block(-5,29,3,CONCRETE:7)
Block(-5,29,4,CONCRETE:7)
Block(-5,29,5,CONCRETE:7)
Block(-5,29,6,CONCRETE:7)
Block(-5,29,7,CONCRETE:7)
Block(-5,29,8,SMOOTH_STAIRS:7)
Block(-5,30,-7,CONCRETE:7)
Block(-5,30,-6,CONCRETE:7)
Block(-5,30,-5,CONCRETE:7)
Block(-5,30,-4,CONCRETE:7)
Block(-5,30,-3,CONCRETE:7)
Block(-5,30,-2,CONCRETE:7)
Block(-5,30,-1,CONCRETE:7)
Block(-5,30,0,CONCRETE:7)
Block(-5,30,1,CONCRETE:7)
Block(-5,30,2,CONCRETE:7)
Block(-5,30,3,CONCRETE:7)
Block(-5,30,4,CONCRETE:7)
Block(-5,30,5,CONCRETE:7)
Block(-5,30,6,CONCRETE:7)
Block(-5,30,7,CONCRETE:15)
Block(-5,30,8,COBBLE_WALL:0)
Block(-5,31,-7,PRISMARINE:0)
Block(-5,31,-6,CONCRETE:7)
Block(-5,31,-5,CONCRETE:7)
Block(-5,31,-4,PRISMARINE:0)
Block(-5,31,-3,CONCRETE:7)
Block(-5,31,-2,CONCRETE:7)
Block(-5,31,-1,PRISMARINE:0)
Block(-5,31,0,CONCRETE:7)
Block(-5,31,1,CONCRETE:7)
Block(-5,31,2,PRISMARINE:0)
Block(-5,31,3,CONCRETE:7)
Block(-5,31,4,CONCRETE:7)
Block(-5,31,5,CONCRETE:7)
Block(-5,31,6,CONCRETE:7)
Block(-5,31,7,CONCRETE:8)
Block(-5,32,-7,CONCRETE:7)
Block(-5,32,-6,CONCRETE:7)
Block(-5,32,-5,CONCRETE:7)
Block(-5,32,-4,CONCRETE:7)
Block(-5,32,-3,CONCRETE:7)
Block(-5,32,-2,CONCRETE:7)
Block(-5,32,-1,CONCRETE:7)
Block(-5,32,0,CONCRETE:7)
Block(-5,32,1,CONCRETE:7)
Block(-5,32,2,CONCRETE:7)
Block(-5,32,3,CONCRETE:7)
Block(-5,32,4,CONCRETE:15)
Block(-5,32,5,CONCRETE:7)
Block(-5,32,6,CONCRETE:7)
Block(-5,33,-7,CONCRETE:7)
Block(-5,33,-6,CONCRETE:7)
Block(-5,33,-5,CONCRETE:7)
Block(-5,33,-4,CONCRETE:7)
Block(-5,33,-3,CONCRETE:7)
Block(-5,33,-2,CONCRETE:7)
Block(-5,33,-1,CONCRETE:7)
Block(-5,33,0,CONCRETE:7)
Block(-5,33,1,CONCRETE:7)
Block(-5,33,2,CONCRETE:7)
Block(-5,33,3,CONCRETE:15)
Block(-5,33,4,SMOOTH_STAIRS:5)
Block(-5,33,5,CONCRETE:7)
Block(-5,33,6,SMOOTH_STAIRS:0)
Block(-5,34,-7,CONCRETE:7)
Block(-5,34,-6,CONCRETE:7)
Block(-5,34,-5,CONCRETE:7)
Block(-5,34,-4,CONCRETE:7)
Block(-5,34,-3,CONCRETE:7)
Block(-5,34,-2,CONCRETE:7)
Block(-5,34,-1,CONCRETE:7)
Block(-5,34,0,CONCRETE:7)
Block(-5,34,1,CONCRETE:7)
Block(-5,34,2,CONCRETE:15)
Block(-5,34,3,SMOOTH_STAIRS:1)
Block(-5,34,4,STAINED_GLASS:7)
Block(-5,34,5,CONCRETE:7)
Block(-5,35,-7,CONCRETE:15)
Block(-5,35,-6,CONCRETE:7)
Block(-5,35,-5,CONCRETE:7)
Block(-5,35,-4,CONCRETE:7)
Block(-5,35,-3,CONCRETE:7)
Block(-5,35,-2,CONCRETE:7)
Block(-5,35,-1,CONCRETE:7)
Block(-5,35,0,CONCRETE:7)
Block(-5,35,1,CONCRETE:7)
Block(-5,35,2,CONCRETE:15)
Block(-5,35,3,SMOOTH_STAIRS:5)
Block(-5,35,4,STAINED_GLASS:7)
Block(-5,35,5,COBBLE_WALL:0)
Block(-5,36,-7,CONCRETE:15)
Block(-5,36,-6,CONCRETE:7)
Block(-5,36,-5,CONCRETE:7)
Block(-5,36,-4,CONCRETE:7)
Block(-5,36,-3,CONCRETE:7)
Block(-5,36,-2,CONCRETE:7)
Block(-5,36,-1,CONCRETE:7)
Block(-5,36,0,CONCRETE:7)
Block(-5,36,1,CONCRETE:15)
Block(-5,36,2,SMOOTH_STAIRS:1)
Block(-5,36,3,STAINED_GLASS:7)
Block(-5,37,-7,CONCRETE:7)
Block(-5,37,-6,CONCRETE:7)
Block(-5,37,-5,CONCRETE:7)
Block(-5,37,-4,CONCRETE:7)
Block(-5,37,-3,CONCRETE:7)
Block(-5,37,-2,CONCRETE:7)
Block(-5,37,-1,CONCRETE:7)
Block(-5,37,0,CONCRETE:7)
Block(-5,37,1,CONCRETE:15)
Block(-5,37,2,SMOOTH_STAIRS:5)
Block(-5,37,3,STAINED_GLASS:7)
Block(-5,38,-7,CONCRETE:7)
Block(-5,38,-6,CONCRETE:7)
Block(-5,38,-5,CONCRETE:7)
Block(-5,38,-4,CONCRETE:7)
Block(-5,38,-3,CONCRETE:7)
Block(-5,38,-2,CONCRETE:7)
Block(-5,38,-1,CONCRETE:7)
Block(-5,38,0,CONCRETE:7)
Block(-5,38,1,CONCRETE:7)
Block(-5,38,2,CONCRETE:15)
Block(-5,38,3,SMOOTH_STAIRS:1)
Block(-5,38,4,STAINED_GLASS:7)
Block(-5,38,5,COBBLE_WALL:0)
Block(-5,39,-7,CONCRETE:7)
Block(-5,39,-6,CONCRETE:7)
Block(-5,39,-5,CONCRETE:7)
Block(-5,39,-4,CONCRETE:7)
Block(-5,39,-3,CONCRETE:7)
Block(-5,39,-2,CONCRETE:7)
Block(-5,39,-1,CONCRETE:7)
Block(-5,39,0,CONCRETE:8)
Block(-5,39,1,CONCRETE:7)
Block(-5,39,2,CONCRETE:15)
Block(-5,39,3,SMOOTH_STAIRS:5)
Block(-5,39,4,STAINED_GLASS:7)
Block(-5,39,5,CONCRETE:7)
Block(-5,40,-7,CONCRETE:7)
Block(-5,40,-6,CONCRETE:7)
Block(-5,40,-5,CONCRETE:7)
Block(-5,40,-4,CONCRETE:7)
Block(-5,40,-3,CONCRETE:7)
Block(-5,40,-2,CONCRETE:7)
Block(-5,40,-1,CONCRETE:7)
Block(-5,40,0,CONCRETE:8)
Block(-5,40,1,CONCRETE:7)
Block(-5,40,2,CONCRETE:7)
Block(-5,40,3,CONCRETE:15)
Block(-5,40,4,SMOOTH_STAIRS:1)
Block(-5,40,5,CONCRETE:7)
Block(-5,40,6,STEP:8)
Block(-5,41,-7,CONCRETE:7)
Block(-5,41,-6,CONCRETE:7)
Block(-5,41,-5,CONCRETE:7)
Block(-5,41,-4,CONCRETE:7)
Block(-5,41,-3,CONCRETE:7)
Block(-5,41,-2,CONCRETE:7)
Block(-5,41,-1,CONCRETE:7)
Block(-5,41,0,CONCRETE:7)
Block(-5,41,1,CONCRETE:8)
Block(-5,41,2,CONCRETE:7)
Block(-5,41,3,CONCRETE:7)
Block(-5,41,4,CONCRETE:15)
Block(-5,41,5,CONCRETE:7)
Block(-5,41,6,CONCRETE:7)
Block(-5,42,-7,CONCRETE:7)
Block(-5,42,-6,CONCRETE:7)
Block(-5,42,-5,CONCRETE:7)
Block(-5,42,-4,CONCRETE:7)
Block(-5,42,-3,CONCRETE:7)
Block(-5,42,-2,CONCRETE:7)
Block(-5,42,-1,CONCRETE:7)
Block(-5,42,0,CONCRETE:7)
Block(-5,42,1,CONCRETE:7)
Block(-5,42,2,CONCRETE:8)
Block(-5,42,3,CONCRETE:7)
Block(-5,42,4,CONCRETE:7)
Block(-5,42,5,CONCRETE:7)
Block(-5,42,6,CONCRETE:7)
Block(-5,42,7,CONCRETE:8)
Block(-5,43,-7,CONCRETE:7)
Block(-5,43,-6,CONCRETE:7)
Block(-5,43,-5,CONCRETE:7)
Block(-5,43,-4,CONCRETE:7)
Block(-5,43,-3,CONCRETE:7)
Block(-5,43,-2,IRON_FENCE:0)
Block(-5,43,-1,IRON_FENCE:0)
Block(-5,43,0,CONCRETE:7)
Block(-5,43,1,CONCRETE:7)
Block(-5,43,2,CONCRETE:7)
Block(-5,43,3,CONCRETE:8)
Block(-5,43,4,CONCRETE:8)
Block(-5,43,5,CONCRETE:8)
Block(-5,43,6,CONCRETE:0)
Block(-5,43,7,STEP:0)
Block(-5,44,-7,STAINED_GLASS_PANE:7)
Block(-5,44,-6,CONCRETE:7)
Block(-5,44,-5,STAINED_GLASS_PANE:7)
Block(-5,44,-4,STAINED_GLASS_PANE:7)
Block(-5,44,-3,CONCRETE:7)
Block(-5,44,0,IRON_FENCE:0)
Block(-5,44,1,IRON_FENCE:0)
Block(-5,44,2,CONCRETE:7)
Block(-5,44,3,CONCRETE:7)
Block(-5,44,4,CONCRETE:8)
Block(-5,44,5,CONCRETE:8)
Block(-5,44,6,CONCRETE:8)
Block(-5,45,-7,STAINED_GLASS_PANE:7)
Block(-5,45,-6,CONCRETE:7)
Block(-5,45,-5,STAINED_GLASS_PANE:7)
Block(-5,45,-4,STAINED_GLASS_PANE:7)
Block(-5,45,-3,CONCRETE:7)
Block(-5,45,2,IRON_FENCE:0)
Block(-5,45,3,IRON_FENCE:0)
Block(-5,45,4,IRON_FENCE:0)
Block(-5,46,-7,STAINED_GLASS_PANE:7)
Block(-5,46,-6,CONCRETE:7)
Block(-5,46,-5,CONCRETE:15)
Block(-5,46,-4,CONCRETE:15)
Block(-5,46,-3,CONCRETE:7)
Block(-5,47,-7,CONCRETE:7)
Block(-5,47,-6,CONCRETE:7)
Block(-5,47,-5,CONCRETE:7)
Block(-5,47,-4,CONCRETE:7)
Block(-5,47,-3,CONCRETE:7)
Block(-5,47,0,STEP:8)
Block(-5,48,-7,CONCRETE:7)
Block(-5,48,-6,CONCRETE:7)
Block(-5,48,-5,CONCRETE:7)
Block(-5,48,-4,CONCRETE:7)
Block(-5,48,-3,CONCRETE:7)
Block(-5,48,-2,SMOOTH_STAIRS:4)
Block(-5,48,-1,SMOOTH_STAIRS:4)
Block(-5,48,0,COBBLE_WALL:0)
Block(-5,49,-7,CONCRETE:7)
Block(-5,49,-6,CONCRETE:7)
Block(-5,49,-5,CONCRETE:7)
Block(-5,49,-4,CONCRETE:7)
Block(-5,49,-3,CONCRETE:7)
Block(-5,49,-2,CONCRETE:7)
Block(-5,49,-1,CONCRETE:7)
Block(-5,49,0,CONCRETE:7)
Block(-5,49,1,CONCRETE:7)
Block(-5,49,2,STEP:8)
Block(-5,50,-7,CONCRETE:7)
Block(-5,50,-6,CONCRETE:7)
Block(-5,50,-5,CONCRETE:7)
Block(-5,50,-4,CONCRETE:7)
Block(-5,50,-3,CONCRETE:7)
Block(-5,50,-2,CONCRETE:7)
Block(-5,50,-1,CONCRETE:7)
Block(-5,50,0,CONCRETE:7)
Block(-5,50,1,CONCRETE:7)
Block(-5,50,2,CONCRETE:7)
Block(-5,51,-7,CONCRETE:7)
Block(-5,51,-5,CONCRETE:7)
Block(-5,51,-4,CONCRETE:7)
Block(-5,51,-2,FLOWER_POT:0,NBT/skyscraper_2x2_02/9-flower_potC0R16.nbt)
Block(-5,51,-1,CONCRETE:7)
Block(-5,51,0,CONCRETE:7)
Block(-5,51,1,CONCRETE:7)
Block(-5,51,2,CONCRETE:7)
Block(-5,51,3,SMOOTH_STAIRS:4)
Block(-5,52,-7,CONCRETE:7)
Block(-5,52,-6,WALL_BANNER:5,NBT/skyscraper_2x2_02/13-bannerC0R16.nbt)
Block(-5,52,-5,CONCRETE:7)
Block(-5,52,-4,CONCRETE:7)
Block(-5,52,-3,WALL_BANNER:5,NBT/skyscraper_2x2_02/14-bannerC0R16.nbt)
Block(-5,52,-2,WALL_BANNER:2,NBT/skyscraper_2x2_02/15-bannerC0R16.nbt)
Block(-5,52,-1,CONCRETE:7)
Block(-5,52,0,WALL_BANNER:5,NBT/skyscraper_2x2_02/16-bannerC0R16.nbt)
Block(-5,52,1,WALL_BANNER:5,NBT/skyscraper_2x2_02/17-bannerC0R16.nbt)
Block(-5,52,2,CONCRETE:7)
Block(-5,52,3,CONCRETE:8)
Block(-5,52,4,SMOOTH_STAIRS:4)
Block(-5,53,-7,CONCRETE:7)
Block(-5,53,-6,CONCRETE:7)
Block(-5,53,-5,CONCRETE:7)
Block(-5,53,-4,CONCRETE:7)
Block(-5,53,-3,CONCRETE:7)
Block(-5,53,-2,CONCRETE:7)
Block(-5,53,-1,CONCRETE:7)
Block(-5,53,0,CONCRETE:7)
Block(-5,53,1,CONCRETE:7)
Block(-5,53,2,CONCRETE:7)
Block(-5,53,3,STAINED_GLASS_PANE:7)
Block(-5,53,4,CONCRETE:8)
Block(-5,54,-7,CONCRETE:7)
Block(-5,54,-6,JUKEBOX:0,NBT/skyscraper_2x2_02/19-jukeboxC0R16.nbt)
Block(-5,54,-5,CONCRETE:7)
Block(-5,54,-4,CONCRETE:7)
Block(-5,54,-1,CONCRETE:7)
Block(-5,54,0,TRAP_DOOR:6)
Block(-5,54,1,TRAP_DOOR:6)
Block(-5,54,2,CONCRETE:7)
Block(-5,54,3,STAINED_GLASS_PANE:7)
Block(-5,54,4,CONCRETE:8)
Block(-5,55,-7,CONCRETE:7)
Block(-5,55,-5,CONCRETE:7)
Block(-5,55,-4,CONCRETE:7)
Block(-5,55,-1,CONCRETE:7)
Block(-5,55,2,CONCRETE:7)
Block(-5,55,3,STAINED_GLASS_PANE:7)
Block(-5,55,4,CONCRETE:8)
Block(-5,56,-7,CONCRETE:7)
Block(-5,56,-6,WALL_BANNER:5,NBT/skyscraper_2x2_02/24-bannerC0R16.nbt)
Block(-5,56,-5,CONCRETE:7)
Block(-5,56,-4,CONCRETE:7)
Block(-5,56,-3,WALL_BANNER:5,NBT/skyscraper_2x2_02/25-bannerC0R16.nbt)
Block(-5,56,-2,WALL_BANNER:5,NBT/skyscraper_2x2_02/26-bannerC0R16.nbt)
Block(-5,56,-1,CONCRETE:7)
Block(-5,56,2,CONCRETE:7)
Block(-5,56,3,STAINED_GLASS_PANE:7)
Block(-5,56,4,CONCRETE:8)
Block(-5,57,-7,CONCRETE:7)
Block(-5,57,-6,WALL_BANNER:5,NBT/skyscraper_2x2_02/32-bannerC0R16.nbt)
Block(-5,57,-5,CONCRETE:7)
