
#######################################################################
# +-----------------------------------------------------------------+ #
# |                            BO4 object                           | #
# +-----------------------------------------------------------------+ #
#######################################################################

Author: NLBlackEagle

Description: No description given

SettingsMode: WriteDisable


#######################################################################
# +-----------------------------------------------------------------+ #
# |                          Main settings                          | #
# +-----------------------------------------------------------------+ #
#######################################################################

Frequency: 0

SpawnHeight: highestBlock

UseCenterForHighestBlock: true

##############################
# Height Limits for the BO4. #
##############################

MinHeight: 0

MaxHeight: 255

InheritBO3: 

InheritBO3Rotation: NORTH

OverrideChildSettings: true

OverrideParentHeight: false

CanOverride: true

BranchFrequency: 0

BranchFrequencyGroup: 

MustBeBelowOther: false

MustBeInside: 

CannotBeInside: 

ReplacesBO3: L4-M-CrossC0R0, L4-M-CrossC0R1, L4-M-CrossC0R2, L4-M-CrossC0R3, L4-M-CrossC1R0, L4-M-CrossC1R1, L4-M-CrossC1R2, L4-M-CrossC1R3, L4-M-CrossC2R0, L4-M-CrossC2R1, L4-M-CrossC2R2, L4-M-CrossC2R3, L4-M-CrossC3R0, L4-M-CrossC3R1, L4-M-CrossC3R2, L4-M-CrossC3R3, L4-M-Straigth-START_01-C0R0, L4-M-Straigth-START_01-C0R1, L4-M-Straigth-START_01-C1R0, L4-M-Straigth-START_01-C1R1, L4-M-Straigth-START_01-C2R0, L4-M-Straigth-START_01-C2R1, L4-M-Straigth-START_01-C3R0, L4-M-Straigth-START_01-C3R1, L4-M-Straigth-3CC0R0, L4-M-Straigth-3CC0R1, L4-M-Straigth-3CC0R2, L4-M-Straigth-3CC1R0, L4-M-Straigth-3CC1R1, L4-M-Straigth-3CC1R2, L4-M-Straigth-3CC2R0, L4-M-Straigth-3CC2R1, L4-M-Straigth-3CC2R2, L4-M-Straigth-3CC3R0, L4-M-Straigth-3CC3R1, L4-M-Straigth-3CC3R2, L4-M-Cross, skyscraper_2x2_01, skyscraper_2x2_02, skyscraper_2x2_03, skyscraper_2x2_04, skyscraper_2x2_05, skyscraper_3x3_01, skyscraper_3x3_02, skyscraper_3x3_03, L3-M-Straigth-2CC0R0, L3-M-Straigth-2CC0R1, L3-M-Straigth-2CC1R0, L3-M-Straigth-2CC1R1, L3-M-Straigth-2CC2R0, L3-M-Straigth-2CC2R1, L3-M-Straigth-2CC3R0, L3-M-Straigth-2CC3R1, L3-M-Straigth-3CC0R0, L3-M-Straigth-3CC0R1, L3-M-Straigth-3CC0R2, L3-M-Straigth-3CC1R0, L3-M-Straigth-3CC1R1, L3-M-Straigth-3CC1R2, L3-M-Straigth-3CC2R0, L3-M-Straigth-3CC2R1, L3-M-Straigth-3CC2R2, L3-M-Straigth-3CC3R0, L3-M-Straigth-3CC3R1, L3-M-Straigth-3CC3R2L4-M-CrossC0R0, L4-M-CrossC0R1, L4-M-CrossC0R2, L4-M-CrossC0R3, L4-M-CrossC1R0, L4-M-CrossC1R1, L4-M-CrossC1R2, L4-M-CrossC1R3, L4-M-CrossC2R0, L4-M-CrossC2R1, L4-M-CrossC2R2, L4-M-CrossC2R3, L4-M-CrossC3R0, L4-M-CrossC3R1, L4-M-CrossC3R2, L4-M-CrossC3R3, L4-M-Straigth-START_01-C0R0, L4-M-Straigth-START_01-C0R1, L4-M-Straigth-START_01-C1R0, L4-M-Straigth-START_01-C1R1, L4-M-Straigth-START_01-C2R0, L4-M-Straigth-START_01-C2R1, L4-M-Straigth-START_01-C3R0, L4-M-Straigth-START_01-C3R1, L4-M-Straigth-3CC0R0, L4-M-Straigth-3CC0R1, L4-M-Straigth-3CC0R2, L4-M-Straigth-3CC1R0, L4-M-Straigth-3CC1R1, L4-M-Straigth-3CC1R2, L4-M-Straigth-3CC2R0, L4-M-Straigth-3CC2R1, L4-M-Straigth-3CC2R2, L4-M-Straigth-3CC3R0, L4-M-Straigth-3CC3R1, L4-M-Straigth-3CC3R2, L4-M-Cross, skyscraper_2x2_01, skyscraper_2x2_02, skyscraper_2x2_03, skyscraper_2x2_04, skyscraper_2x2_05, skyscraper_3x3_01, skyscraper_3x3_02, skyscraper_3x3_03

MustBeInsideWorldBorders: false

CanSpawnOnWater: true

SpawnOnWaterOnly: false

SpawnUnderWater: false

SpawnAtWaterLevel: false

HeightOffset: 0

RemoveAir: false

ReplaceAbove: 

ReplaceBelow: 

ReplaceWithBiomeBlocks: true

ReplaceWithSurfaceBlock: GRASS

ReplaceWithGroundBlock: DIRT

ReplaceWithStoneBlock: STONE

SmoothRadius: 0

SmoothHeightOffset: 0

SmoothStartTop: false

SmoothStartWood: false

SmoothingSurfaceBlock: 

SmoothingGroundBlock: 

BO3Group: 

IsSpawnPoint: false

DoReplaceBlocks: true


#######################################################################
# +-----------------------------------------------------------------+ #
# |                              Blocks                             | #
# +-----------------------------------------------------------------+ #
#######################################################################

Block(-8,0,-7,CONCRETE:7)
Block(-8,0,-6,CONCRETE:7)
Block(-8,0,-5,CONCRETE:7)
Block(-8,0,-4,CONCRETE:7)
Block(-8,0,-3,CONCRETE:7)
Block(-8,0,-2,CONCRETE:7)
Block(-8,0,-1,CONCRETE:7)
Block(-8,0,0,CONCRETE:7)
Block(-8,0,1,CONCRETE:7)
Block(-8,0,2,CONCRETE:7)
Block(-8,0,3,CONCRETE:7)
Block(-8,0,4,CONCRETE:7)
Block(-8,0,5,CONCRETE:7)
Block(-8,0,6,CONCRETE:7)
Block(-8,0,7,CONCRETE:7)
Block(-8,0,8,CONCRETE:7)
Block(-8,1,-7,CONCRETE:7)
Block(-8,1,-6,CONCRETE:7)
Block(-8,1,-5,CONCRETE:7)
Block(-8,1,-4,CONCRETE:7)
Block(-8,1,-3,CONCRETE:7)
Block(-8,1,-2,CONCRETE:7)
Block(-8,1,-1,CONCRETE:7)
Block(-8,1,0,CONCRETE:7)
Block(-8,1,1,CONCRETE:7)
Block(-8,1,2,CONCRETE:7)
Block(-8,1,3,CONCRETE:7)
Block(-8,1,4,CONCRETE:7)
Block(-8,1,5,CONCRETE:7)
Block(-8,1,6,CONCRETE:7)
Block(-8,1,7,CONCRETE:7)
Block(-8,1,8,CONCRETE:7)
Block(-8,2,-7,CONCRETE:7)
Block(-8,2,-6,CONCRETE:7)
Block(-8,2,-5,CONCRETE:7)
Block(-8,2,-4,CONCRETE:7)
Block(-8,2,-3,CONCRETE:7)
Block(-8,2,-2,CONCRETE:7)
Block(-8,2,-1,CONCRETE:7)
Block(-8,2,0,CONCRETE:7)
Block(-8,2,1,CONCRETE:7)
Block(-8,2,2,CONCRETE:7)
Block(-8,2,3,CONCRETE:7)
Block(-8,2,4,CONCRETE:7)
Block(-8,2,5,CONCRETE:7)
Block(-8,2,6,CONCRETE:7)
Block(-8,2,7,CONCRETE:7)
Block(-8,2,8,CONCRETE:7)
Block(-8,3,-7,CONCRETE:7)
Block(-8,3,-6,CONCRETE:7)
Block(-8,3,-5,CONCRETE:7)
Block(-8,3,-4,CONCRETE:7)
Block(-8,3,-3,CONCRETE:7)
Block(-8,3,-2,CONCRETE:7)
Block(-8,3,-1,CONCRETE:7)
Block(-8,3,0,CONCRETE:7)
Block(-8,3,1,CONCRETE:7)
Block(-8,3,2,CONCRETE:7)
Block(-8,3,3,CONCRETE:7)
Block(-8,3,4,CONCRETE:7)
Block(-8,3,5,CONCRETE:7)
Block(-8,3,6,CONCRETE:7)
Block(-8,3,7,CONCRETE:7)
Block(-8,3,8,CONCRETE:7)
Block(-8,4,-7,CONCRETE:7)
Block(-8,4,-6,CONCRETE:7)
Block(-8,4,-5,CONCRETE:7)
Block(-8,4,-4,CONCRETE:7)
Block(-8,4,-3,CONCRETE:7)
Block(-8,4,-2,CONCRETE:7)
Block(-8,4,-1,CONCRETE:7)
Block(-8,4,0,CONCRETE:7)
Block(-8,4,1,CONCRETE:7)
Block(-8,4,2,CONCRETE:7)
Block(-8,4,3,CONCRETE:7)
Block(-8,4,4,CONCRETE:7)
Block(-8,4,5,CONCRETE:7)
Block(-8,4,6,CONCRETE:7)
Block(-8,4,7,CONCRETE:7)
Block(-8,4,8,CONCRETE:7)
Block(-8,5,-7,CONCRETE:7)
Block(-8,5,-6,CONCRETE:7)
Block(-8,5,-5,CONCRETE:7)
Block(-8,5,-4,CONCRETE:7)
Block(-8,5,-3,CONCRETE:7)
Block(-8,5,-2,CONCRETE:7)
Block(-8,5,-1,CONCRETE:7)
Block(-8,5,0,CONCRETE:7)
Block(-8,5,1,CONCRETE:7)
Block(-8,5,2,CONCRETE:7)
Block(-8,5,3,CONCRETE:7)
Block(-8,5,4,CONCRETE:7)
Block(-8,5,5,CONCRETE:7)
Block(-8,5,6,CONCRETE:7)
Block(-8,5,7,CONCRETE:7)
Block(-8,5,8,CONCRETE:7)
Block(-8,6,-7,CONCRETE:7)
Block(-8,6,-6,CONCRETE:7)
Block(-8,6,-5,CONCRETE:7)
Block(-8,6,-4,CONCRETE:7)
Block(-8,6,-3,CONCRETE:7)
Block(-8,6,-2,CONCRETE:7)
Block(-8,6,-1,CONCRETE:7)
Block(-8,6,0,CONCRETE:7)
Block(-8,6,1,CONCRETE:7)
Block(-8,6,2,CONCRETE:7)
Block(-8,6,3,CONCRETE:7)
Block(-8,6,4,CONCRETE:7)
Block(-8,6,5,CONCRETE:7)
Block(-8,6,6,CONCRETE:7)
Block(-8,6,7,CONCRETE:7)
Block(-8,6,8,CONCRETE:7)
Block(-8,7,-7,CONCRETE:7)
Block(-8,7,-6,CONCRETE:7)
Block(-8,7,-5,CONCRETE:7)
Block(-8,7,-4,CONCRETE:7)
Block(-8,7,-3,CONCRETE:7)
Block(-8,7,-2,CONCRETE:7)
Block(-8,7,-1,CONCRETE:7)
Block(-8,7,0,CONCRETE:7)
Block(-8,7,1,CONCRETE:7)
Block(-8,7,2,CONCRETE:7)
Block(-8,7,3,CONCRETE:7)
Block(-8,7,4,CONCRETE:7)
Block(-8,7,5,CONCRETE:7)
Block(-8,7,6,CONCRETE:7)
Block(-8,7,7,CONCRETE:7)
Block(-8,7,8,CONCRETE:7)
Block(-8,8,-7,CONCRETE:7)
Block(-8,8,-6,CONCRETE:7)
Block(-8,8,-5,CONCRETE:7)
Block(-8,8,-4,CONCRETE:7)
Block(-8,8,-3,CONCRETE:7)
Block(-8,8,-2,CONCRETE:7)
Block(-8,8,-1,CONCRETE:7)
Block(-8,8,0,CONCRETE:7)
Block(-8,8,1,CONCRETE:7)
Block(-8,8,2,CONCRETE:7)
Block(-8,8,3,CONCRETE:7)
Block(-8,8,4,CONCRETE:7)
Block(-8,8,5,CONCRETE:7)
Block(-8,8,6,CONCRETE:7)
Block(-8,8,7,CONCRETE:7)
Block(-8,8,8,CONCRETE:7)
Block(-8,9,-7,CONCRETE:7)
Block(-8,9,-6,CONCRETE:7)
Block(-8,9,-5,CONCRETE:7)
Block(-8,9,-4,CONCRETE:7)
Block(-8,9,-3,CONCRETE:7)
Block(-8,9,-2,CONCRETE:7)
Block(-8,9,-1,CONCRETE:7)
Block(-8,9,0,CONCRETE:7)
Block(-8,9,1,CONCRETE:7)
Block(-8,9,2,CONCRETE:7)
Block(-8,9,3,CONCRETE:7)
Block(-8,9,4,CONCRETE:7)
Block(-8,9,5,CONCRETE:7)
Block(-8,9,6,CONCRETE:7)
Block(-8,9,7,CONCRETE:7)
Block(-8,9,8,CONCRETE:7)
Block(-8,10,-7,CONCRETE:7)
Block(-8,10,-6,CONCRETE:7)
Block(-8,10,-5,CONCRETE:7)
Block(-8,10,-4,CONCRETE:7)
Block(-8,10,-3,CONCRETE:7)
Block(-8,10,-2,CONCRETE:7)
Block(-8,10,-1,CONCRETE:7)
Block(-8,10,0,CONCRETE:7)
Block(-8,10,1,CONCRETE:7)
Block(-8,10,2,CONCRETE:7)
Block(-8,10,3,CONCRETE:7)
Block(-8,10,4,CONCRETE:7)
Block(-8,10,5,CONCRETE:7)
Block(-8,10,6,CONCRETE:7)
Block(-8,10,7,CONCRETE:7)
Block(-8,10,8,CONCRETE:7)
Block(-8,11,-7,CONCRETE:7)
Block(-8,11,-6,CONCRETE:7)
Block(-8,11,-5,CONCRETE:7)
Block(-8,11,-4,CONCRETE:7)
Block(-8,11,-3,CONCRETE:7)
Block(-8,11,-2,CONCRETE:7)
Block(-8,11,-1,CONCRETE:7)
Block(-8,11,0,CONCRETE:7)
Block(-8,11,1,CONCRETE:7)
Block(-8,11,2,CONCRETE:7)
Block(-8,11,3,CONCRETE:7)
Block(-8,11,4,CONCRETE:7)
Block(-8,11,5,CONCRETE:7)
Block(-8,11,6,CONCRETE:7)
Block(-8,11,7,CONCRETE:7)
Block(-8,11,8,CONCRETE:7)
Block(-8,12,-7,CONCRETE:7)
Block(-8,12,-6,CONCRETE:7)
Block(-8,12,-5,CONCRETE:7)
Block(-8,12,-4,CONCRETE:7)
Block(-8,12,-3,CONCRETE:7)
Block(-8,12,-2,CONCRETE:7)
Block(-8,12,-1,CONCRETE:7)
Block(-8,12,0,CONCRETE:7)
Block(-8,12,1,CONCRETE:7)
Block(-8,12,2,CONCRETE:7)
Block(-8,12,3,CONCRETE:7)
Block(-8,12,4,CONCRETE:7)
Block(-8,12,5,CONCRETE:7)
Block(-8,12,6,CONCRETE:7)
Block(-8,12,7,CONCRETE:7)
Block(-8,12,8,CONCRETE:7)
Block(-8,13,-7,CONCRETE:7)
Block(-8,13,-6,CONCRETE:7)
Block(-8,13,-5,CONCRETE:7)
Block(-8,13,-4,CONCRETE:7)
Block(-8,13,-3,CONCRETE:7)
Block(-8,13,-2,CONCRETE:7)
Block(-8,13,-1,CONCRETE:7)
Block(-8,13,0,CONCRETE:7)
Block(-8,13,1,CONCRETE:7)
Block(-8,13,2,CONCRETE:7)
Block(-8,13,3,CONCRETE:7)
Block(-8,13,4,CONCRETE:7)
Block(-8,13,5,CONCRETE:7)
Block(-8,13,6,CONCRETE:7)
Block(-8,13,7,CONCRETE:7)
Block(-8,13,8,CONCRETE:7)
Block(-8,14,-7,CONCRETE:7)
Block(-8,14,-6,CONCRETE:7)
Block(-8,14,-5,CONCRETE:7)
Block(-8,14,-4,CONCRETE:7)
Block(-8,14,-3,CONCRETE:7)
Block(-8,14,-2,CONCRETE:7)
Block(-8,14,-1,CONCRETE:7)
Block(-8,14,0,CONCRETE:7)
Block(-8,14,1,CONCRETE:7)
Block(-8,14,2,CONCRETE:7)
Block(-8,14,3,CONCRETE:7)
Block(-8,14,4,CONCRETE:7)
Block(-8,14,5,CONCRETE:7)
Block(-8,14,6,CONCRETE:7)
Block(-8,14,7,CONCRETE:7)
Block(-8,14,8,CONCRETE:7)
Block(-8,15,-7,CONCRETE:7)
Block(-8,15,-6,CONCRETE:7)
Block(-8,15,-5,CONCRETE:7)
Block(-8,15,-4,CONCRETE:7)
Block(-8,15,-3,CONCRETE:7)
Block(-8,15,-2,CONCRETE:7)
Block(-8,15,-1,CONCRETE:7)
Block(-8,15,0,CONCRETE:7)
Block(-8,15,1,CONCRETE:7)
Block(-8,15,2,CONCRETE:7)
Block(-8,15,3,CONCRETE:7)
Block(-8,15,4,CONCRETE:7)
Block(-8,15,5,CONCRETE:7)
Block(-8,15,6,CONCRETE:7)
Block(-8,15,7,CONCRETE:7)
Block(-8,15,8,CONCRETE:7)
Block(-8,16,-7,CONCRETE:7)
Block(-8,16,-6,CONCRETE:7)
Block(-8,16,-5,CONCRETE:7)
Block(-8,16,-4,CONCRETE:7)
Block(-8,16,-3,CONCRETE:7)
Block(-8,16,-2,CONCRETE:7)
Block(-8,16,-1,CONCRETE:7)
Block(-8,16,0,CONCRETE:7)
Block(-8,16,1,CONCRETE:7)
Block(-8,16,2,CONCRETE:7)
Block(-8,16,3,CONCRETE:7)
Block(-8,16,4,CONCRETE:7)
Block(-8,16,5,CONCRETE:7)
Block(-8,16,6,CONCRETE:7)
Block(-8,16,7,CONCRETE:7)
Block(-8,16,8,CONCRETE:7)
Block(-8,17,-7,CONCRETE:7)
Block(-8,17,-6,CONCRETE:7)
Block(-8,17,-5,CONCRETE:7)
Block(-8,17,-4,CONCRETE:7)
Block(-8,17,-3,CONCRETE:7)
Block(-8,17,-2,CONCRETE:7)
Block(-8,17,-1,CONCRETE:7)
Block(-8,17,0,CONCRETE:7)
Block(-8,17,1,CONCRETE:7)
Block(-8,17,2,CONCRETE:7)
Block(-8,17,3,CONCRETE:7)
Block(-8,17,4,CONCRETE:7)
Block(-8,17,5,CONCRETE:7)
Block(-8,17,6,CONCRETE:7)
Block(-8,17,7,CONCRETE:7)
Block(-8,17,8,CONCRETE:7)
Block(-8,18,-7,CONCRETE:15)
Block(-8,18,-6,CONCRETE:15)
Block(-8,18,-5,CONCRETE:15)
Block(-8,19,-7,CONCRETE:15)
Block(-8,19,-6,CONCRETE:15)
Block(-8,19,-5,CONCRETE:15)
Block(-8,20,-7,CONCRETE:15)
Block(-8,20,-6,CONCRETE:15)
Block(-8,20,-5,CONCRETE:15)
Block(-8,21,-7,CONCRETE:15)
Block(-8,21,-6,CONCRETE:15)
Block(-8,21,-5,CONCRETE:15)
Block(-8,22,-7,CONCRETE:15)
Block(-8,22,-6,CONCRETE:15)
Block(-8,22,-5,CONCRETE:15)
Block(-8,23,-7,CONCRETE:15)
Block(-8,23,-6,CONCRETE:15)
Block(-8,23,-5,CONCRETE:15)
Block(-8,24,-7,CONCRETE:15)
Block(-8,24,-6,CONCRETE:15)
Block(-8,24,-5,CONCRETE:15)
Block(-8,25,-7,CONCRETE:15)
Block(-8,25,-6,CONCRETE:15)
Block(-8,25,-5,CONCRETE:15)
Block(-8,25,3,CONCRETE:8)
Block(-8,25,4,CONCRETE:8)
Block(-8,25,5,CONCRETE:8)
Block(-8,25,6,CONCRETE:8)
Block(-8,25,7,CONCRETE:8)
Block(-8,25,8,CONCRETE:8)
Block(-8,26,-7,CONCRETE:15)
Block(-8,26,-6,CONCRETE:15)
Block(-8,26,-5,CONCRETE:15)
Block(-8,26,3,STAINED_GLASS_PANE:15)
Block(-8,26,4,STAINED_GLASS_PANE:15)
Block(-8,26,5,STAINED_GLASS_PANE:15)
Block(-8,26,6,STAINED_GLASS_PANE:15)
Block(-8,26,7,STAINED_GLASS_PANE:15)
Block(-8,26,8,STAINED_GLASS_PANE:15)
Block(-8,27,-7,CONCRETE:15)
Block(-8,27,-6,CONCRETE:15)
Block(-8,27,-5,CONCRETE:15)
Block(-8,28,-7,CONCRETE:15)
Block(-8,28,-6,CONCRETE:15)
Block(-8,28,-5,CONCRETE:15)
Block(-8,29,-7,CONCRETE:15)
Block(-8,29,-6,CONCRETE:15)
Block(-8,29,-5,CONCRETE:15)
Block(-8,29,3,CONCRETE:8)
Block(-8,29,4,CONCRETE:8)
Block(-8,29,5,CONCRETE:8)
Block(-8,29,6,CONCRETE:8)
Block(-8,29,7,CONCRETE:8)
Block(-8,29,8,CONCRETE:8)
Block(-8,30,-7,CONCRETE:15)
Block(-8,30,-6,CONCRETE:15)
Block(-8,30,-5,CONCRETE:15)
Block(-8,30,3,STAINED_GLASS_PANE:15)
Block(-8,30,4,STAINED_GLASS_PANE:15)
Block(-8,30,5,STAINED_GLASS_PANE:15)
Block(-8,30,6,STAINED_GLASS_PANE:15)
Block(-8,30,7,STAINED_GLASS_PANE:15)
Block(-8,30,8,STAINED_GLASS_PANE:15)
Block(-8,31,-7,CONCRETE:15)
Block(-8,31,-6,CONCRETE:15)
Block(-8,31,-5,CONCRETE:15)
Block(-8,32,-7,CONCRETE:15)
Block(-8,32,-6,CONCRETE:15)
Block(-8,32,-5,CONCRETE:15)
Block(-8,33,-7,CONCRETE:15)
Block(-8,33,-6,CONCRETE:15)
Block(-8,33,-5,CONCRETE:15)
Block(-8,33,3,CONCRETE:8)
Block(-8,33,4,CONCRETE:8)
Block(-8,33,5,CONCRETE:8)
Block(-8,33,6,CONCRETE:8)
Block(-8,33,7,CONCRETE:8)
Block(-8,33,8,CONCRETE:8)
Block(-8,34,-7,CONCRETE:15)
Block(-8,34,-6,CONCRETE:15)
Block(-8,34,-5,CONCRETE:15)
Block(-8,34,3,STAINED_GLASS_PANE:15)
Block(-8,34,4,STAINED_GLASS_PANE:15)
Block(-8,34,5,STAINED_GLASS_PANE:15)
Block(-8,34,6,STAINED_GLASS_PANE:15)
Block(-8,34,7,STAINED_GLASS_PANE:15)
Block(-8,34,8,STAINED_GLASS_PANE:15)
Block(-8,35,-7,CONCRETE:15)
Block(-8,35,-6,CONCRETE:15)
Block(-8,35,-5,CONCRETE:15)
Block(-8,36,-7,CONCRETE:15)
Block(-8,36,-6,CONCRETE:15)
Block(-8,36,-5,CONCRETE:15)
Block(-8,37,-7,CONCRETE:15)
Block(-8,37,-6,CONCRETE:15)
Block(-8,37,-5,CONCRETE:15)
Block(-8,37,3,CONCRETE:8)
Block(-8,37,4,CONCRETE:8)
Block(-8,37,5,CONCRETE:8)
Block(-8,37,6,CONCRETE:8)
Block(-8,37,7,CONCRETE:8)
Block(-8,37,8,CONCRETE:8)
Block(-8,38,-7,CONCRETE:15)
Block(-8,38,-6,CONCRETE:15)
Block(-8,38,-5,CONCRETE:15)
Block(-8,38,3,STAINED_GLASS_PANE:15)
Block(-8,38,4,STAINED_GLASS_PANE:15)
Block(-8,38,5,STAINED_GLASS_PANE:15)
Block(-8,38,6,STAINED_GLASS_PANE:15)
Block(-8,38,7,STAINED_GLASS_PANE:15)
Block(-8,38,8,STAINED_GLASS_PANE:15)
Block(-8,39,-7,CONCRETE:15)
Block(-8,39,-6,CONCRETE:15)
Block(-8,39,-5,CONCRETE:15)
Block(-8,40,-7,CONCRETE:15)
Block(-8,40,-6,CONCRETE:15)
Block(-8,40,-5,CONCRETE:15)
Block(-8,41,-7,CONCRETE:15)
Block(-8,41,-6,CONCRETE:15)
Block(-8,41,-5,CONCRETE:15)
Block(-8,41,3,CONCRETE:8)
Block(-8,41,4,CONCRETE:8)
Block(-8,41,5,CONCRETE:8)
Block(-8,41,6,CONCRETE:8)
Block(-8,41,7,CONCRETE:8)
Block(-8,41,8,CONCRETE:8)
Block(-8,42,-7,CONCRETE:15)
Block(-8,42,-6,CONCRETE:15)
Block(-8,42,-5,CONCRETE:15)
Block(-8,42,3,STAINED_GLASS_PANE:15)
Block(-8,42,4,STAINED_GLASS_PANE:15)
Block(-8,42,5,STAINED_GLASS_PANE:15)
Block(-8,42,6,STAINED_GLASS_PANE:15)
Block(-8,42,7,STAINED_GLASS_PANE:15)
Block(-8,42,8,STAINED_GLASS_PANE:15)
Block(-8,43,-7,CONCRETE:15)
Block(-8,43,-6,CONCRETE:15)
Block(-8,43,-5,CONCRETE:15)
Block(-8,44,-7,CONCRETE:15)
Block(-8,44,-6,CONCRETE:15)
Block(-8,44,-5,CONCRETE:15)
Block(-8,45,-7,CONCRETE:15)
Block(-8,45,-6,CONCRETE:15)
Block(-8,45,-5,CONCRETE:15)
Block(-8,45,3,CONCRETE:8)
Block(-8,45,4,CONCRETE:8)
Block(-8,45,5,CONCRETE:8)
Block(-8,45,6,CONCRETE:8)
Block(-8,45,7,CONCRETE:8)
Block(-8,45,8,CONCRETE:8)
Block(-8,46,-7,CONCRETE:15)
Block(-8,46,-6,CONCRETE:15)
Block(-8,46,-5,CONCRETE:15)
Block(-8,46,3,STAINED_GLASS_PANE:15)
Block(-8,46,4,STAINED_GLASS_PANE:15)
Block(-8,46,5,STAINED_GLASS_PANE:15)
Block(-8,46,6,STAINED_GLASS_PANE:15)
Block(-8,46,7,STAINED_GLASS_PANE:15)
Block(-8,46,8,STAINED_GLASS_PANE:15)
Block(-8,47,-7,CONCRETE:15)
Block(-8,47,-6,CONCRETE:15)
Block(-8,47,-5,CONCRETE:15)
Block(-8,48,-7,CONCRETE:15)
Block(-8,48,-6,CONCRETE:15)
Block(-8,48,-5,CONCRETE:15)
Block(-8,49,-7,CONCRETE:15)
Block(-8,49,-6,CONCRETE:15)
Block(-8,49,-5,CONCRETE:15)
Block(-8,49,3,CONCRETE:8)
Block(-8,49,4,CONCRETE:8)
Block(-8,49,5,CONCRETE:8)
Block(-8,49,6,CONCRETE:8)
Block(-8,49,7,CONCRETE:8)
Block(-8,49,8,CONCRETE:8)
Block(-8,50,-7,CONCRETE:15)
Block(-8,50,-6,CONCRETE:15)
Block(-8,50,-5,CONCRETE:15)
Block(-8,50,3,STAINED_GLASS_PANE:15)
Block(-8,50,4,STAINED_GLASS_PANE:15)
Block(-8,50,5,STAINED_GLASS_PANE:15)
Block(-8,50,6,STAINED_GLASS_PANE:15)
Block(-8,50,7,STAINED_GLASS_PANE:15)
Block(-8,50,8,STAINED_GLASS_PANE:15)
Block(-8,51,-7,CONCRETE:15)
Block(-8,51,-6,CONCRETE:15)
Block(-8,51,-5,CONCRETE:15)
Block(-8,52,-7,CONCRETE:15)
Block(-8,52,-6,CONCRETE:15)
Block(-8,52,-5,CONCRETE:15)
Block(-8,53,-7,CONCRETE:15)
Block(-8,53,-6,CONCRETE:15)
Block(-8,53,-5,CONCRETE:15)
Block(-8,53,3,CONCRETE:8)
Block(-8,53,4,CONCRETE:8)
Block(-8,53,5,CONCRETE:8)
Block(-8,53,6,CONCRETE:8)
Block(-8,53,7,CONCRETE:8)
Block(-8,53,8,CONCRETE:8)
Block(-8,54,-7,CONCRETE:15)
Block(-8,54,-6,CONCRETE:15)
Block(-8,54,-5,CONCRETE:15)
Block(-8,54,3,STAINED_GLASS_PANE:15)
Block(-8,54,4,STAINED_GLASS_PANE:15)
Block(-8,54,5,STAINED_GLASS_PANE:15)
Block(-8,54,6,STAINED_GLASS_PANE:15)
Block(-8,54,7,STAINED_GLASS_PANE:15)
Block(-8,54,8,STAINED_GLASS_PANE:15)
Block(-8,55,-7,CONCRETE:15)
Block(-8,55,-6,CONCRETE:15)
Block(-8,55,-5,CONCRETE:15)
Block(-8,56,-7,CONCRETE:15)
Block(-8,56,-6,CONCRETE:15)
Block(-8,56,-5,CONCRETE:15)
Block(-8,57,-7,CONCRETE:15)
Block(-8,57,-6,CONCRETE:15)
Block(-8,57,-5,CONCRETE:15)
Block(-8,57,3,CONCRETE:8)
Block(-8,57,4,CONCRETE:8)
Block(-8,57,5,CONCRETE:8)
Block(-8,57,6,CONCRETE:8)
Block(-8,57,7,CONCRETE:8)
Block(-8,57,8,CONCRETE:8)
Block(-8,58,-7,CONCRETE:15)
Block(-8,58,-6,CONCRETE:15)
Block(-8,58,-5,CONCRETE:15)
Block(-8,58,3,STAINED_GLASS_PANE:15)
Block(-8,58,4,STAINED_GLASS_PANE:15)
Block(-8,58,5,STAINED_GLASS_PANE:15)
Block(-8,58,6,STAINED_GLASS_PANE:15)
Block(-8,58,7,STAINED_GLASS_PANE:15)
Block(-8,58,8,STAINED_GLASS_PANE:15)
Block(-8,59,-7,CONCRETE:15)
Block(-8,59,-6,CONCRETE:15)
Block(-8,59,-5,CONCRETE:15)
Block(-8,60,-7,CONCRETE:15)
Block(-8,60,-6,CONCRETE:15)
Block(-8,60,-5,CONCRETE:15)
Block(-8,61,-7,CONCRETE:15)
Block(-8,61,-6,CONCRETE:15)
Block(-8,61,-5,CONCRETE:15)
Block(-8,61,3,CONCRETE:8)
Block(-8,61,4,CONCRETE:8)
Block(-8,61,5,CONCRETE:8)
Block(-8,61,6,CONCRETE:8)
Block(-8,61,7,CONCRETE:8)
Block(-8,61,8,CONCRETE:8)
Block(-8,62,-7,CONCRETE:15)
Block(-8,62,-6,CONCRETE:15)
Block(-8,62,-5,CONCRETE:15)
Block(-8,62,3,STAINED_GLASS_PANE:15)
Block(-8,62,4,STAINED_GLASS_PANE:15)
Block(-8,62,5,STAINED_GLASS_PANE:15)
Block(-8,62,6,STAINED_GLASS_PANE:15)
Block(-8,62,7,STAINED_GLASS_PANE:15)
Block(-8,62,8,STAINED_GLASS_PANE:15)
Block(-8,63,-7,CONCRETE:15)
Block(-8,63,-6,CONCRETE:15)
Block(-8,63,-5,CONCRETE:15)
Block(-8,64,-7,CONCRETE:15)
Block(-8,64,-6,CONCRETE:15)
Block(-8,64,-5,CONCRETE:15)
Block(-8,65,-7,CONCRETE:15)
Block(-8,65,-6,CONCRETE:15)
Block(-8,65,-5,CONCRETE:15)
Block(-8,65,3,CONCRETE:8)
Block(-8,65,4,CONCRETE:8)
Block(-8,65,5,CONCRETE:8)
Block(-8,65,6,CONCRETE:8)
Block(-8,65,7,CONCRETE:8)
Block(-8,65,8,CONCRETE:8)
Block(-8,66,-7,CONCRETE:15)
Block(-8,66,-6,CONCRETE:15)
Block(-8,66,-5,CONCRETE:15)
Block(-8,66,3,STAINED_GLASS_PANE:15)
Block(-8,66,4,STAINED_GLASS_PANE:15)
Block(-8,66,5,STAINED_GLASS_PANE:15)
Block(-8,66,6,STAINED_GLASS_PANE:15)
Block(-8,66,7,STAINED_GLASS_PANE:15)
Block(-8,66,8,STAINED_GLASS_PANE:15)
Block(-8,67,-7,CONCRETE:15)
Block(-8,67,-6,CONCRETE:15)
Block(-8,67,-5,CONCRETE:15)
Block(-8,68,-7,CONCRETE:15)
Block(-8,68,-6,CONCRETE:15)
Block(-8,68,-5,CONCRETE:15)
Block(-8,69,-7,CONCRETE:15)
Block(-8,69,-6,CONCRETE:15)
Block(-8,69,-5,CONCRETE:15)
Block(-8,69,3,CONCRETE:8)
Block(-8,69,4,CONCRETE:8)
Block(-8,69,5,CONCRETE:8)
Block(-8,69,6,CONCRETE:8)
Block(-8,69,7,CONCRETE:8)
Block(-8,69,8,CONCRETE:8)
Block(-8,70,-7,CONCRETE:15)
Block(-8,70,-6,CONCRETE:15)
Block(-8,70,-5,CONCRETE:15)
Block(-8,70,3,STAINED_GLASS_PANE:15)
Block(-8,70,4,STAINED_GLASS_PANE:15)
Block(-8,70,5,STAINED_GLASS_PANE:15)
Block(-8,70,6,STAINED_GLASS_PANE:15)
Block(-8,70,7,STAINED_GLASS_PANE:15)
Block(-8,70,8,STAINED_GLASS_PANE:15)
Block(-8,71,-7,CONCRETE:15)
Block(-8,71,-6,CONCRETE:15)
Block(-8,71,-5,CONCRETE:15)
Block(-8,72,-7,CONCRETE:15)
Block(-8,72,-6,CONCRETE:15)
Block(-8,72,-5,CONCRETE:15)
Block(-8,73,-7,CONCRETE:15)
Block(-8,73,-6,CONCRETE:15)
Block(-8,73,-5,CONCRETE:15)
Block(-8,73,3,CONCRETE:8)
Block(-8,73,4,CONCRETE:8)
Block(-8,73,5,CONCRETE:8)
Block(-8,73,6,CONCRETE:8)
Block(-8,73,7,CONCRETE:8)
Block(-8,73,8,CONCRETE:8)
Block(-8,74,-7,CONCRETE:15)
Block(-8,74,-6,CONCRETE:15)
Block(-8,74,-5,CONCRETE:15)
Block(-8,74,3,STAINED_GLASS_PANE:15)
Block(-8,74,4,STAINED_GLASS_PANE:15)
Block(-8,74,5,STAINED_GLASS_PANE:15)
Block(-8,74,6,STAINED_GLASS_PANE:15)
Block(-8,74,7,STAINED_GLASS_PANE:15)
Block(-8,74,8,STAINED_GLASS_PANE:15)
Block(-8,75,-7,CONCRETE:15)
Block(-8,75,-6,CONCRETE:15)
Block(-8,75,-5,CONCRETE:15)
Block(-8,76,-7,CONCRETE:15)
Block(-8,76,-6,CONCRETE:15)
Block(-8,76,-5,CONCRETE:15)
Block(-8,77,-7,CONCRETE:15)
Block(-8,77,-6,CONCRETE:15)
Block(-8,77,-5,CONCRETE:15)
Block(-8,77,3,CONCRETE:8)
Block(-8,77,4,CONCRETE:8)
Block(-8,77,5,CONCRETE:8)
Block(-8,77,6,CONCRETE:8)
Block(-8,77,7,CONCRETE:8)
Block(-8,77,8,CONCRETE:8)
Block(-8,78,-7,CONCRETE:15)
Block(-8,78,-6,CONCRETE:15)
Block(-8,78,-5,CONCRETE:15)
Block(-8,78,3,STAINED_GLASS_PANE:15)
Block(-8,78,4,STAINED_GLASS_PANE:15)
Block(-8,78,5,STAINED_GLASS_PANE:15)
Block(-8,78,6,STAINED_GLASS_PANE:15)
Block(-8,78,7,STAINED_GLASS_PANE:15)
Block(-8,78,8,STAINED_GLASS_PANE:15)
Block(-8,79,-7,CONCRETE:15)
Block(-8,79,-6,CONCRETE:15)
Block(-8,79,-5,CONCRETE:15)
Block(-8,80,-7,CONCRETE:15)
Block(-8,80,-6,CONCRETE:15)
Block(-8,80,-5,CONCRETE:15)
Block(-8,81,-7,CONCRETE:15)
Block(-8,81,-6,CONCRETE:15)
Block(-8,81,-5,CONCRETE:15)
Block(-8,81,3,CONCRETE:8)
Block(-8,81,4,CONCRETE:8)
Block(-8,81,5,CONCRETE:8)
Block(-8,81,6,CONCRETE:8)
Block(-8,81,7,CONCRETE:8)
Block(-8,81,8,CONCRETE:8)
Block(-8,82,-7,CONCRETE:15)
Block(-8,82,-6,CONCRETE:15)
Block(-8,82,-5,CONCRETE:15)
Block(-8,82,3,STAINED_GLASS_PANE:15)
Block(-8,82,4,STAINED_GLASS_PANE:15)
Block(-8,82,5,STAINED_GLASS_PANE:15)
Block(-8,82,6,STAINED_GLASS_PANE:15)
Block(-8,82,7,STAINED_GLASS_PANE:15)
Block(-8,82,8,STAINED_GLASS_PANE:15)
Block(-8,83,-7,CONCRETE:15)
Block(-8,83,-6,CONCRETE:15)
Block(-8,83,-5,CONCRETE:15)
Block(-8,84,-7,CONCRETE:15)
Block(-8,84,-6,CONCRETE:15)
Block(-8,84,-5,CONCRETE:15)
Block(-8,85,-7,CONCRETE:15)
Block(-8,85,-6,CONCRETE:15)
Block(-8,85,-5,CONCRETE:15)
Block(-8,85,3,CONCRETE:8)
Block(-8,85,4,CONCRETE:8)
Block(-8,85,5,CONCRETE:8)
Block(-8,85,6,CONCRETE:8)
Block(-8,85,7,CONCRETE:8)
Block(-8,85,8,CONCRETE:8)
Block(-8,86,-7,CONCRETE:15)
Block(-8,86,-6,CONCRETE:15)
Block(-8,86,-5,CONCRETE:15)
Block(-8,86,3,STAINED_GLASS_PANE:15)
Block(-8,86,4,STAINED_GLASS_PANE:15)
Block(-8,86,5,STAINED_GLASS_PANE:15)
Block(-8,86,6,STAINED_GLASS_PANE:15)
Block(-8,86,7,STAINED_GLASS_PANE:15)
Block(-8,86,8,STAINED_GLASS_PANE:15)
Block(-8,87,-7,CONCRETE:15)
Block(-8,87,-6,CONCRETE:15)
Block(-8,87,-5,CONCRETE:15)
Block(-8,88,-7,CONCRETE:15)
Block(-8,88,-6,CONCRETE:15)
Block(-8,88,-5,CONCRETE:15)
Block(-8,89,-7,CONCRETE:15)
Block(-8,89,-6,CONCRETE:15)
Block(-8,89,-5,CONCRETE:15)
Block(-8,89,3,CONCRETE:8)
Block(-8,89,4,CONCRETE:8)
Block(-8,89,5,CONCRETE:8)
Block(-8,89,6,CONCRETE:8)
Block(-8,89,7,CONCRETE:8)
Block(-8,89,8,CONCRETE:8)
Block(-8,90,-7,CONCRETE:15)
Block(-8,90,-6,CONCRETE:15)
Block(-8,90,-5,CONCRETE:15)
Block(-8,90,3,STAINED_GLASS_PANE:15)
Block(-8,90,4,STAINED_GLASS_PANE:15)
Block(-8,90,5,STAINED_GLASS_PANE:15)
Block(-8,90,6,STAINED_GLASS_PANE:15)
Block(-8,90,7,STAINED_GLASS_PANE:15)
Block(-8,90,8,STAINED_GLASS_PANE:15)
Block(-8,91,-7,CONCRETE:15)
Block(-8,91,-6,CONCRETE:15)
Block(-8,91,-5,CONCRETE:15)
Block(-8,92,-7,CONCRETE:15)
Block(-8,92,-6,CONCRETE:15)
Block(-8,92,-5,CONCRETE:15)
Block(-8,93,-7,CONCRETE:15)
Block(-8,93,-6,CONCRETE:15)
Block(-8,93,-5,CONCRETE:15)
Block(-8,93,3,CONCRETE:8)
Block(-8,93,4,CONCRETE:8)
Block(-8,93,5,CONCRETE:8)
Block(-8,93,6,CONCRETE:8)
Block(-8,93,7,CONCRETE:8)
Block(-8,93,8,CONCRETE:8)
Block(-8,94,-7,CONCRETE:15)
Block(-8,94,-6,CONCRETE:15)
Block(-8,94,-5,CONCRETE:15)
Block(-8,94,3,STAINED_GLASS_PANE:15)
Block(-8,94,4,STAINED_GLASS_PANE:15)
Block(-8,94,5,STAINED_GLASS_PANE:15)
Block(-8,94,6,STAINED_GLASS_PANE:15)
Block(-8,94,7,STAINED_GLASS_PANE:15)
Block(-8,94,8,STAINED_GLASS_PANE:15)
Block(-8,95,-7,CONCRETE:15)
Block(-8,95,-6,CONCRETE:15)
Block(-8,95,-5,CONCRETE:15)
Block(-8,96,-7,CONCRETE:15)
Block(-8,96,-6,CONCRETE:15)
Block(-8,96,-5,CONCRETE:15)
Block(-8,97,-7,CONCRETE:15)
Block(-8,97,-6,CONCRETE:15)
Block(-8,97,-5,CONCRETE:15)
Block(-8,97,3,CONCRETE:8)
Block(-8,97,4,CONCRETE:8)
Block(-8,97,5,CONCRETE:8)
Block(-8,97,6,CONCRETE:8)
Block(-8,97,7,CONCRETE:8)
Block(-8,97,8,CONCRETE:8)
Block(-8,98,-7,CONCRETE:15)
Block(-8,98,-6,CONCRETE:15)
Block(-8,98,-5,CONCRETE:15)
Block(-8,98,3,STAINED_GLASS_PANE:15)
Block(-8,98,4,STAINED_GLASS_PANE:15)
Block(-8,98,5,STAINED_GLASS_PANE:15)
Block(-8,98,6,STAINED_GLASS_PANE:15)
Block(-8,98,7,STAINED_GLASS_PANE:15)
Block(-8,98,8,STAINED_GLASS_PANE:15)
Block(-8,99,-7,CONCRETE:15)
Block(-8,99,-6,CONCRETE:15)
Block(-8,99,-5,CONCRETE:15)
Block(-8,100,-7,CONCRETE:15)
Block(-8,100,-6,CONCRETE:15)
Block(-8,100,-5,CONCRETE:15)
Block(-8,101,-7,CONCRETE:15)
Block(-8,101,-6,CONCRETE:15)
Block(-8,101,-5,CONCRETE:15)
Block(-8,101,3,CONCRETE:8)
Block(-8,101,4,CONCRETE:8)
Block(-8,101,5,CONCRETE:8)
Block(-8,101,6,CONCRETE:8)
Block(-8,101,7,CONCRETE:8)
Block(-8,101,8,CONCRETE:8)
Block(-8,102,-7,CONCRETE:15)
Block(-8,102,-6,CONCRETE:15)
Block(-8,102,-5,CONCRETE:15)
Block(-8,102,3,STAINED_GLASS_PANE:15)
Block(-8,102,4,STAINED_GLASS_PANE:15)
Block(-8,102,5,STAINED_GLASS_PANE:15)
Block(-8,102,6,STAINED_GLASS_PANE:15)
Block(-8,102,7,STAINED_GLASS_PANE:15)
Block(-8,102,8,STAINED_GLASS_PANE:15)
Block(-8,103,-7,CONCRETE:15)
Block(-8,103,-6,CONCRETE:15)
Block(-8,103,-5,CONCRETE:15)
Block(-8,104,-7,CONCRETE:15)
Block(-8,104,-6,CONCRETE:15)
Block(-8,104,-5,CONCRETE:15)
Block(-8,105,-7,CONCRETE:15)
Block(-8,105,-6,CONCRETE:15)
Block(-8,105,-5,CONCRETE:15)
Block(-8,105,3,CONCRETE:8)
Block(-8,105,4,CONCRETE:8)
Block(-8,105,5,CONCRETE:8)
Block(-8,105,6,CONCRETE:8)
Block(-8,105,7,CONCRETE:8)
Block(-8,105,8,CONCRETE:8)
Block(-8,106,-7,CONCRETE:15)
Block(-8,106,-6,CONCRETE:15)
Block(-8,106,-5,CONCRETE:15)
Block(-8,106,3,STAINED_GLASS_PANE:15)
Block(-8,106,4,STAINED_GLASS_PANE:15)
Block(-8,106,5,STAINED_GLASS_PANE:15)
Block(-8,106,6,STAINED_GLASS_PANE:15)
Block(-8,106,7,STAINED_GLASS_PANE:15)
Block(-8,106,8,STAINED_GLASS_PANE:15)
Block(-8,107,-7,CONCRETE:15)
Block(-8,107,-6,CONCRETE:15)
Block(-8,107,-5,CONCRETE:15)
Block(-8,108,-7,CONCRETE:15)
Block(-8,108,-6,CONCRETE:15)
Block(-8,108,-5,CONCRETE:15)
Block(-8,109,-7,CONCRETE:15)
Block(-8,109,-6,CONCRETE:15)
Block(-8,109,-5,CONCRETE:15)
Block(-8,109,3,CONCRETE:8)
Block(-8,109,4,CONCRETE:8)
Block(-8,109,5,CONCRETE:8)
Block(-8,109,6,CONCRETE:8)
Block(-8,109,7,CONCRETE:8)
Block(-8,109,8,CONCRETE:8)
Block(-8,110,-7,CONCRETE:15)
Block(-8,110,-6,CONCRETE:15)
Block(-8,110,-5,CONCRETE:15)
Block(-8,110,3,STAINED_GLASS_PANE:15)
Block(-8,110,4,STAINED_GLASS_PANE:15)
Block(-8,110,5,STAINED_GLASS_PANE:15)
Block(-8,110,6,STAINED_GLASS_PANE:15)
Block(-8,110,7,STAINED_GLASS_PANE:15)
Block(-8,110,8,STAINED_GLASS_PANE:15)
Block(-8,111,-7,CONCRETE:15)
Block(-8,111,-6,CONCRETE:15)
Block(-8,111,-5,CONCRETE:15)
Block(-8,112,-7,CONCRETE:15)
Block(-8,112,-6,CONCRETE:15)
Block(-8,112,-5,CONCRETE:15)
Block(-8,113,-7,CONCRETE:15)
Block(-8,113,-6,CONCRETE:15)
Block(-8,113,-5,CONCRETE:15)
Block(-8,114,-7,CONCRETE:15)
Block(-8,114,-6,CONCRETE:15)
Block(-8,114,-5,CONCRETE:15)
Block(-8,115,-7,CONCRETE:15)
Block(-8,115,-6,CONCRETE:15)
Block(-8,115,-5,CONCRETE:15)
Block(-8,116,-7,CONCRETE:15)
Block(-8,116,-6,CONCRETE:15)
Block(-8,116,-5,CONCRETE:15)
Block(-8,117,-7,CONCRETE:15)
Block(-8,117,-6,CONCRETE:15)
Block(-8,117,-5,CONCRETE:15)
Block(-8,117,-4,CONCRETE:15)
Block(-8,117,-3,CONCRETE:15)
Block(-8,117,-2,CONCRETE:15)
Block(-8,117,-1,CONCRETE:15)
Block(-8,117,0,CONCRETE:15)
Block(-8,117,1,CONCRETE:15)
Block(-8,117,2,CONCRETE:15)
Block(-8,117,3,CONCRETE:15)
Block(-8,117,4,CONCRETE:15)
Block(-8,117,5,CONCRETE:15)
Block(-8,117,6,CONCRETE:15)
Block(-8,117,7,CONCRETE:15)
Block(-8,117,8,CONCRETE:15)
Block(-8,118,-7,CONCRETE:15)
Block(-8,118,-6,CONCRETE:15)
Block(-8,118,-5,CONCRETE:15)
Block(-8,118,-4,CONCRETE:15)
Block(-8,118,-3,CONCRETE:15)
Block(-8,118,-2,CONCRETE:15)
Block(-8,118,-1,CONCRETE:15)
Block(-8,118,0,CONCRETE:15)
Block(-8,118,1,CONCRETE:15)
Block(-8,118,2,CONCRETE:15)
Block(-8,118,3,CONCRETE:15)
Block(-8,118,4,CONCRETE:15)
Block(-8,118,5,CONCRETE:15)
Block(-8,118,6,CONCRETE:15)
Block(-8,118,7,CONCRETE:15)
Block(-8,118,8,CONCRETE:15)
Block(-8,119,-7,CONCRETE:15)
Block(-8,119,-6,CONCRETE:15)
Block(-8,119,-5,CONCRETE:15)
Block(-8,119,-4,CONCRETE:15)
Block(-8,119,-3,CONCRETE:15)
Block(-8,119,-2,CONCRETE:15)
Block(-8,119,-1,CONCRETE:15)
Block(-8,119,0,CONCRETE:15)
Block(-8,119,1,CONCRETE:15)
Block(-8,119,2,CONCRETE:15)
Block(-8,119,3,CONCRETE:15)
Block(-8,119,4,CONCRETE:15)
Block(-8,119,5,CONCRETE:15)
Block(-8,119,6,CONCRETE:15)
Block(-8,119,7,CONCRETE:15)
Block(-8,119,8,CONCRETE:15)
Block(-8,120,-7,STEP:7)
Block(-8,120,-6,STEP:7)
Block(-8,120,-5,STEP:7)
Block(-7,0,-7,CONCRETE:7)
Block(-7,0,-6,CONCRETE:7)
Block(-7,0,-5,CONCRETE:7)
Block(-7,0,-4,CONCRETE:7)
Block(-7,0,-3,CONCRETE:7)
Block(-7,0,-2,CONCRETE:7)
Block(-7,0,-1,CONCRETE:7)
Block(-7,0,0,CONCRETE:7)
Block(-7,0,1,CONCRETE:7)
Block(-7,0,2,CONCRETE:7)
Block(-7,0,3,CONCRETE:7)
Block(-7,0,4,CONCRETE:7)
Block(-7,0,5,CONCRETE:7)
Block(-7,0,6,CONCRETE:7)
Block(-7,0,7,CONCRETE:7)
Block(-7,0,8,CONCRETE:7)
Block(-7,1,-7,CONCRETE:7)
Block(-7,1,-6,CONCRETE:7)
Block(-7,1,-5,CONCRETE:7)
Block(-7,1,-4,CONCRETE:7)
Block(-7,1,-3,CONCRETE:7)
Block(-7,1,-2,CONCRETE:7)
Block(-7,1,-1,CONCRETE:7)
Block(-7,1,0,CONCRETE:7)
Block(-7,1,1,CONCRETE:7)
Block(-7,1,2,CONCRETE:7)
Block(-7,1,3,CONCRETE:7)
Block(-7,1,4,CONCRETE:7)
Block(-7,1,5,CONCRETE:7)
Block(-7,1,6,CONCRETE:7)
Block(-7,1,7,CONCRETE:7)
Block(-7,1,8,CONCRETE:7)
Block(-7,2,-7,CONCRETE:7)
Block(-7,2,-6,CONCRETE:7)
Block(-7,2,-5,CONCRETE:7)
Block(-7,2,-4,CONCRETE:7)
Block(-7,2,-3,CONCRETE:7)
Block(-7,2,-2,CONCRETE:7)
Block(-7,2,-1,CONCRETE:7)
Block(-7,2,0,CONCRETE:7)
Block(-7,2,1,CONCRETE:7)
Block(-7,2,2,CONCRETE:7)
Block(-7,2,3,CONCRETE:7)
Block(-7,2,4,CONCRETE:7)
Block(-7,2,5,CONCRETE:7)
Block(-7,2,6,CONCRETE:7)
Block(-7,2,7,CONCRETE:7)
Block(-7,2,8,CONCRETE:7)
Block(-7,3,-7,CONCRETE:7)
Block(-7,3,-6,CONCRETE:7)
Block(-7,3,-5,CONCRETE:7)
Block(-7,3,-4,CONCRETE:7)
Block(-7,3,-3,CONCRETE:7)
Block(-7,3,-2,CONCRETE:7)
Block(-7,3,-1,CONCRETE:7)
Block(-7,3,0,CONCRETE:7)
Block(-7,3,1,CONCRETE:7)
Block(-7,3,2,CONCRETE:7)
Block(-7,3,3,CONCRETE:7)
Block(-7,3,4,CONCRETE:7)
Block(-7,3,5,CONCRETE:7)
Block(-7,3,6,CONCRETE:7)
Block(-7,3,7,CONCRETE:7)
Block(-7,3,8,CONCRETE:7)
Block(-7,4,-7,CONCRETE:7)
Block(-7,4,-6,CONCRETE:7)
Block(-7,4,-5,CONCRETE:7)
Block(-7,4,-4,CONCRETE:7)
Block(-7,4,-3,CONCRETE:7)
Block(-7,4,-2,CONCRETE:7)
Block(-7,4,-1,CONCRETE:7)
Block(-7,4,0,CONCRETE:7)
Block(-7,4,1,CONCRETE:7)
Block(-7,4,2,CONCRETE:7)
Block(-7,4,3,CONCRETE:7)
Block(-7,4,4,CONCRETE:7)
Block(-7,4,5,CONCRETE:7)
Block(-7,4,6,CONCRETE:7)
Block(-7,4,7,CONCRETE:7)
Block(-7,4,8,CONCRETE:7)
Block(-7,5,-7,CONCRETE:7)
Block(-7,5,-6,CONCRETE:7)
Block(-7,5,-5,CONCRETE:7)
Block(-7,5,-4,CONCRETE:7)
Block(-7,5,-3,CONCRETE:7)
Block(-7,5,-2,CONCRETE:7)
Block(-7,5,-1,CONCRETE:7)
Block(-7,5,0,CONCRETE:7)
Block(-7,5,1,CONCRETE:7)
Block(-7,5,2,CONCRETE:7)
Block(-7,5,3,CONCRETE:7)
Block(-7,5,4,CONCRETE:7)
Block(-7,5,5,CONCRETE:7)
Block(-7,5,6,CONCRETE:7)
Block(-7,5,7,CONCRETE:7)
Block(-7,5,8,CONCRETE:7)
Block(-7,6,-7,CONCRETE:7)
Block(-7,6,-6,CONCRETE:7)
Block(-7,6,-5,CONCRETE:7)
Block(-7,6,-4,CONCRETE:7)
Block(-7,6,-3,CONCRETE:7)
Block(-7,6,-2,CONCRETE:7)
Block(-7,6,-1,CONCRETE:7)
Block(-7,6,0,CONCRETE:7)
Block(-7,6,1,CONCRETE:7)
Block(-7,6,2,CONCRETE:7)
Block(-7,6,3,CONCRETE:7)
Block(-7,6,4,CONCRETE:7)
Block(-7,6,5,CONCRETE:7)
Block(-7,6,6,CONCRETE:7)
Block(-7,6,7,CONCRETE:7)
Block(-7,6,8,CONCRETE:7)
Block(-7,7,-7,CONCRETE:7)
Block(-7,7,-6,CONCRETE:7)
Block(-7,7,-5,CONCRETE:7)
Block(-7,7,-4,CONCRETE:7)
Block(-7,7,-3,CONCRETE:7)
Block(-7,7,-2,CONCRETE:7)
Block(-7,7,-1,CONCRETE:7)
Block(-7,7,0,CONCRETE:7)
Block(-7,7,1,CONCRETE:7)
Block(-7,7,2,CONCRETE:7)
Block(-7,7,3,CONCRETE:7)
Block(-7,7,4,CONCRETE:7)
Block(-7,7,5,CONCRETE:7)
Block(-7,7,6,CONCRETE:7)
Block(-7,7,7,CONCRETE:7)
Block(-7,7,8,CONCRETE:7)
Block(-7,8,-7,CONCRETE:7)
Block(-7,8,-6,CONCRETE:7)
Block(-7,8,-5,CONCRETE:7)
Block(-7,8,-4,CONCRETE:7)
Block(-7,8,-3,CONCRETE:7)
Block(-7,8,-2,CONCRETE:7)
Block(-7,8,-1,CONCRETE:7)
Block(-7,8,0,CONCRETE:7)
Block(-7,8,1,CONCRETE:7)
Block(-7,8,2,CONCRETE:7)
Block(-7,8,3,CONCRETE:7)
Block(-7,8,4,CONCRETE:7)
Block(-7,8,5,CONCRETE:7)
Block(-7,8,6,CONCRETE:7)
Block(-7,8,7,CONCRETE:7)
Block(-7,8,8,CONCRETE:7)
Block(-7,9,-7,CONCRETE:7)
Block(-7,9,-6,CONCRETE:7)
Block(-7,9,-5,CONCRETE:7)
Block(-7,9,-4,CONCRETE:7)
Block(-7,9,-3,CONCRETE:7)
Block(-7,9,-2,CONCRETE:7)
Block(-7,9,-1,CONCRETE:7)
Block(-7,9,0,CONCRETE:7)
Block(-7,9,1,CONCRETE:7)
Block(-7,9,2,CONCRETE:7)
Block(-7,9,3,CONCRETE:7)
Block(-7,9,4,CONCRETE:7)
Block(-7,9,5,CONCRETE:7)
Block(-7,9,6,CONCRETE:7)
Block(-7,9,7,CONCRETE:7)
Block(-7,9,8,CONCRETE:7)
Block(-7,10,-7,CONCRETE:7)
Block(-7,10,-6,CONCRETE:8)
Block(-7,10,-5,CONCRETE:8)
Block(-7,10,-4,CONCRETE:8)
Block(-7,10,-3,CONCRETE:8)
Block(-7,10,-2,CONCRETE:8)
Block(-7,10,-1,CONCRETE:8)
Block(-7,10,0,CONCRETE:8)
Block(-7,10,1,CONCRETE:8)
Block(-7,10,2,CONCRETE:8)
Block(-7,10,3,CONCRETE:8)
Block(-7,10,4,CONCRETE:8)
Block(-7,10,5,CONCRETE:8)
Block(-7,10,6,CONCRETE:8)
Block(-7,10,7,CONCRETE:8)
Block(-7,10,8,CONCRETE:8)
Block(-7,11,-7,CONCRETE:7)
Block(-7,11,-6,CONCRETE:8)
Block(-7,11,-5,CONCRETE:8)
Block(-7,11,-4,CONCRETE:8)
Block(-7,11,-3,CONCRETE:8)
Block(-7,11,-2,CONCRETE:8)
Block(-7,11,-1,CONCRETE:8)
Block(-7,11,0,CONCRETE:8)
Block(-7,11,1,CONCRETE:8)
Block(-7,11,2,CONCRETE:8)
Block(-7,11,3,CONCRETE:8)
Block(-7,11,4,CONCRETE:8)
Block(-7,11,5,CONCRETE:8)
Block(-7,11,6,CONCRETE:8)
Block(-7,11,7,CONCRETE:8)
Block(-7,11,8,CONCRETE:8)
Block(-7,12,-7,CONCRETE:7)
Block(-7,12,-6,CONCRETE:8)
Block(-7,12,-5,CONCRETE:8)
Block(-7,12,-4,CONCRETE:8)
Block(-7,12,-3,CONCRETE:8)
Block(-7,12,-2,CONCRETE:8)
Block(-7,12,-1,CONCRETE:8)
Block(-7,12,0,CONCRETE:8)
Block(-7,12,1,CONCRETE:8)
Block(-7,12,2,CONCRETE:8)
Block(-7,12,3,CONCRETE:8)
Block(-7,12,4,CONCRETE:8)
Block(-7,12,5,CONCRETE:8)
Block(-7,12,6,CONCRETE:8)
Block(-7,12,7,CONCRETE:8)
Block(-7,12,8,CONCRETE:8)
Block(-7,13,-7,CONCRETE:7)
Block(-7,13,-6,CONCRETE:8)
Block(-7,13,-5,CONCRETE:8)
Block(-7,13,-4,CONCRETE:8)
Block(-7,13,-3,CONCRETE:8)
Block(-7,13,-2,CONCRETE:8)
Block(-7,13,-1,CONCRETE:8)
Block(-7,13,0,CONCRETE:8)
Block(-7,13,1,CONCRETE:8)
Block(-7,13,2,CONCRETE:8)
Block(-7,13,3,CONCRETE:8)
Block(-7,13,4,CONCRETE:8)
Block(-7,13,5,CONCRETE:8)
Block(-7,13,6,CONCRETE:8)
Block(-7,13,7,CONCRETE:8)
Block(-7,13,8,CONCRETE:8)
Block(-7,14,-7,CONCRETE:7)
Block(-7,14,-6,CONCRETE:8)
Block(-7,14,-5,CONCRETE:8)
Block(-7,14,-4,CONCRETE:8)
Block(-7,14,-3,CONCRETE:8)
Block(-7,14,-2,CONCRETE:8)
Block(-7,14,-1,CONCRETE:8)
Block(-7,14,0,CONCRETE:8)
Block(-7,14,1,CONCRETE:8)
Block(-7,14,2,CONCRETE:8)
Block(-7,14,3,CONCRETE:8)
Block(-7,14,4,CONCRETE:8)
Block(-7,14,5,CONCRETE:8)
Block(-7,14,6,CONCRETE:8)
Block(-7,14,7,CONCRETE:8)
Block(-7,14,8,CONCRETE:8)
Block(-7,15,-7,CONCRETE:7)
Block(-7,15,-6,CONCRETE:7)
Block(-7,15,-5,CONCRETE:7)
Block(-7,15,-4,CONCRETE:7)
Block(-7,15,-3,CONCRETE:7)
Block(-7,15,-2,CONCRETE:7)
Block(-7,15,-1,CONCRETE:7)
Block(-7,15,0,CONCRETE:7)
Block(-7,15,1,CONCRETE:7)
Block(-7,15,2,CONCRETE:7)
Block(-7,15,3,CONCRETE:7)
Block(-7,15,4,CONCRETE:7)
Block(-7,15,5,CONCRETE:7)
Block(-7,15,6,CONCRETE:7)
Block(-7,15,7,CONCRETE:7)
Block(-7,15,8,CONCRETE:7)
Block(-7,16,-7,CONCRETE:7)
Block(-7,16,-6,CONCRETE:15)
Block(-7,16,-5,CONCRETE:15)
Block(-7,16,-4,CONCRETE:15)
Block(-7,16,-3,CONCRETE:15)
Block(-7,16,-2,CONCRETE:15)
Block(-7,16,-1,CONCRETE:15)
Block(-7,16,0,CONCRETE:15)
Block(-7,16,1,CONCRETE:15)
Block(-7,16,2,CONCRETE:15)
Block(-7,16,3,CONCRETE:15)
Block(-7,16,4,CONCRETE:15)
Block(-7,16,5,CONCRETE:15)
Block(-7,16,6,CONCRETE:15)
Block(-7,16,7,CONCRETE:15)
Block(-7,16,8,CONCRETE:15)
Block(-7,17,-7,CONCRETE:7)
Block(-7,17,-6,SMOOTH_BRICK:0)
Block(-7,17,-5,CONCRETE:7)
Block(-7,17,-4,GRASS:0)
Block(-7,17,-3,DIRT:1)
Block(-7,17,-2,DIRT:1)
Block(-7,17,-1,GRASS:0)
Block(-7,17,0,DIRT:1)
Block(-7,17,1,DIRT:1)
Block(-7,17,2,GRASS:0)
Block(-7,17,3,GRASS:0)
Block(-7,17,4,GRASS:0)
Block(-7,17,5,DIRT:1)
Block(-7,17,6,GRASS:0)
Block(-7,17,7,DIRT:1)
Block(-7,17,8,DIRT:1)
Block(-7,18,-7,CONCRETE:15)
Block(-7,18,-6,CONCRETE:15)
Block(-7,18,-5,CONCRETE:15)
Block(-7,19,-7,CONCRETE:15)
Block(-7,19,-6,CONCRETE:15)
Block(-7,19,-5,CONCRETE:15)
Block(-7,20,-7,CONCRETE:15)
Block(-7,20,-6,CONCRETE:15)
Block(-7,20,-5,CONCRETE:15)
Block(-7,21,-7,CONCRETE:15)
Block(-7,21,-6,CONCRETE:15)
Block(-7,21,-5,CONCRETE:15)
Block(-7,22,-7,CONCRETE:15)
Block(-7,22,-6,CONCRETE:15)
Block(-7,22,-5,CONCRETE:15)
Block(-7,23,-7,CONCRETE:15)
Block(-7,23,-6,CONCRETE:15)
Block(-7,23,-5,CONCRETE:15)
Block(-7,24,-7,CONCRETE:15)
Block(-7,24,-6,CONCRETE:15)
Block(-7,24,-5,CONCRETE:15)
Block(-7,25,-7,CONCRETE:15)
Block(-7,25,-6,CONCRETE:15)
Block(-7,25,-5,CONCRETE:15)
Block(-7,25,3,CONCRETE:8)
Block(-7,25,4,CONCRETE:8)
Block(-7,25,5,CONCRETE:8)
Block(-7,25,6,CONCRETE:8)
Block(-7,25,7,CONCRETE:8)
Block(-7,25,8,CONCRETE:8)
Block(-7,26,-7,CONCRETE:15)
Block(-7,26,-6,CONCRETE:15)
Block(-7,26,-5,CONCRETE:15)
Block(-7,26,3,STAINED_GLASS_PANE:15)
Block(-7,27,-7,CONCRETE:15)
Block(-7,27,-6,CONCRETE:15)
Block(-7,27,-5,CONCRETE:15)
Block(-7,28,-7,CONCRETE:15)
Block(-7,28,-6,CONCRETE:15)
Block(-7,28,-5,CONCRETE:15)
Block(-7,29,-7,CONCRETE:15)
Block(-7,29,-6,CONCRETE:15)
Block(-7,29,-5,CONCRETE:15)
Block(-7,29,3,CONCRETE:8)
Block(-7,29,4,CONCRETE:8)
Block(-7,29,5,CONCRETE:8)
Block(-7,29,6,CONCRETE:8)
Block(-7,29,7,CONCRETE:8)
Block(-7,29,8,CONCRETE:8)
Block(-7,30,-7,CONCRETE:15)
Block(-7,30,-6,CONCRETE:15)
Block(-7,30,-5,CONCRETE:15)
Block(-7,30,3,STAINED_GLASS_PANE:15)
Block(-7,31,-7,CONCRETE:15)
Block(-7,31,-6,CONCRETE:15)
Block(-7,31,-5,CONCRETE:15)
Block(-7,32,-7,CONCRETE:15)
Block(-7,32,-6,CONCRETE:15)
Block(-7,32,-5,CONCRETE:15)
Block(-7,33,-7,CONCRETE:15)
Block(-7,33,-6,CONCRETE:15)
Block(-7,33,-5,CONCRETE:15)
Block(-7,33,3,CONCRETE:8)
Block(-7,33,4,CONCRETE:8)
Block(-7,33,5,CONCRETE:8)
Block(-7,33,6,CONCRETE:8)
Block(-7,33,7,CONCRETE:8)
Block(-7,33,8,CONCRETE:8)
Block(-7,34,-7,CONCRETE:15)
Block(-7,34,-6,CONCRETE:15)
Block(-7,34,-5,CONCRETE:15)
Block(-7,34,3,STAINED_GLASS_PANE:15)
Block(-7,35,-7,CONCRETE:15)
Block(-7,35,-6,CONCRETE:15)
Block(-7,35,-5,CONCRETE:15)
Block(-7,36,-7,CONCRETE:15)
Block(-7,36,-6,CONCRETE:15)
Block(-7,36,-5,CONCRETE:15)
Block(-7,37,-7,CONCRETE:15)
Block(-7,37,-6,CONCRETE:15)
Block(-7,37,-5,CONCRETE:15)
Block(-7,37,3,CONCRETE:8)
Block(-7,37,4,CONCRETE:8)
Block(-7,37,5,CONCRETE:8)
Block(-7,37,6,CONCRETE:8)
Block(-7,37,7,CONCRETE:8)
Block(-7,37,8,CONCRETE:8)
Block(-7,38,-7,CONCRETE:15)
Block(-7,38,-6,CONCRETE:15)
Block(-7,38,-5,CONCRETE:15)
Block(-7,38,3,STAINED_GLASS_PANE:15)
Block(-7,39,-7,CONCRETE:15)
Block(-7,39,-6,CONCRETE:15)
Block(-7,39,-5,CONCRETE:15)
Block(-7,40,-7,CONCRETE:15)
Block(-7,40,-6,CONCRETE:15)
Block(-7,40,-5,CONCRETE:15)
Block(-7,41,-7,CONCRETE:15)
Block(-7,41,-6,CONCRETE:15)
Block(-7,41,-5,CONCRETE:15)
Block(-7,41,3,CONCRETE:8)
Block(-7,41,4,CONCRETE:8)
Block(-7,41,5,CONCRETE:8)
Block(-7,41,6,CONCRETE:8)
Block(-7,41,7,CONCRETE:8)
Block(-7,41,8,CONCRETE:8)
Block(-7,42,-7,CONCRETE:15)
Block(-7,42,-6,CONCRETE:15)
Block(-7,42,-5,CONCRETE:15)
Block(-7,42,3,STAINED_GLASS_PANE:15)
Block(-7,43,-7,CONCRETE:15)
Block(-7,43,-6,CONCRETE:15)
Block(-7,43,-5,CONCRETE:15)
Block(-7,44,-7,CONCRETE:15)
Block(-7,44,-6,CONCRETE:15)
Block(-7,44,-5,CONCRETE:15)
Block(-7,45,-7,CONCRETE:15)
Block(-7,45,-6,CONCRETE:15)
Block(-7,45,-5,CONCRETE:15)
Block(-7,45,3,CONCRETE:8)
Block(-7,45,4,CONCRETE:8)
Block(-7,45,5,CONCRETE:8)
Block(-7,45,6,CONCRETE:8)
Block(-7,45,7,CONCRETE:8)
Block(-7,45,8,CONCRETE:8)
Block(-7,46,-7,CONCRETE:15)
Block(-7,46,-6,CONCRETE:15)
Block(-7,46,-5,CONCRETE:15)
Block(-7,46,3,STAINED_GLASS_PANE:15)
Block(-7,47,-7,CONCRETE:15)
Block(-7,47,-6,CONCRETE:15)
Block(-7,47,-5,CONCRETE:15)
Block(-7,48,-7,CONCRETE:15)
Block(-7,48,-6,CONCRETE:15)
Block(-7,48,-5,CONCRETE:15)
Block(-7,49,-7,CONCRETE:15)
Block(-7,49,-6,CONCRETE:15)
Block(-7,49,-5,CONCRETE:15)
Block(-7,49,3,CONCRETE:8)
Block(-7,49,4,CONCRETE:8)
Block(-7,49,5,CONCRETE:8)
Block(-7,49,6,CONCRETE:8)
Block(-7,49,7,CONCRETE:8)
Block(-7,49,8,CONCRETE:8)
Block(-7,50,-7,CONCRETE:15)
Block(-7,50,-6,CONCRETE:15)
Block(-7,50,-5,CONCRETE:15)
Block(-7,50,3,STAINED_GLASS_PANE:15)
Block(-7,51,-7,CONCRETE:15)
Block(-7,51,-6,CONCRETE:15)
Block(-7,51,-5,CONCRETE:15)
Block(-7,52,-7,CONCRETE:15)
Block(-7,52,-6,CONCRETE:15)
Block(-7,52,-5,CONCRETE:15)
Block(-7,53,-7,CONCRETE:15)
Block(-7,53,-6,CONCRETE:15)
Block(-7,53,-5,CONCRETE:15)
Block(-7,53,3,CONCRETE:8)
Block(-7,53,4,CONCRETE:8)
Block(-7,53,5,CONCRETE:8)
Block(-7,53,6,CONCRETE:8)
Block(-7,53,7,CONCRETE:8)
Block(-7,53,8,CONCRETE:8)
Block(-7,54,-7,CONCRETE:15)
Block(-7,54,-6,CONCRETE:15)
Block(-7,54,-5,CONCRETE:15)
Block(-7,54,3,STAINED_GLASS_PANE:15)
Block(-7,55,-7,CONCRETE:15)
Block(-7,55,-6,CONCRETE:15)
Block(-7,55,-5,CONCRETE:15)
Block(-7,56,-7,CONCRETE:15)
Block(-7,56,-6,CONCRETE:15)
Block(-7,56,-5,CONCRETE:15)
Block(-7,57,-7,CONCRETE:15)
Block(-7,57,-6,CONCRETE:15)
Block(-7,57,-5,CONCRETE:15)
Block(-7,57,3,CONCRETE:8)
Block(-7,57,4,CONCRETE:8)
Block(-7,57,5,CONCRETE:8)
Block(-7,57,6,CONCRETE:8)
Block(-7,57,7,CONCRETE:8)
Block(-7,57,8,CONCRETE:8)
Block(-7,58,-7,CONCRETE:15)
Block(-7,58,-6,CONCRETE:15)
Block(-7,58,-5,CONCRETE:15)
Block(-7,58,3,STAINED_GLASS_PANE:15)
Block(-7,59,-7,CONCRETE:15)
Block(-7,59,-6,CONCRETE:15)
Block(-7,59,-5,CONCRETE:15)
Block(-7,60,-7,CONCRETE:15)
Block(-7,60,-6,CONCRETE:15)
Block(-7,60,-5,CONCRETE:15)
Block(-7,61,-7,CONCRETE:15)
Block(-7,61,-6,CONCRETE:15)
Block(-7,61,-5,CONCRETE:15)
Block(-7,61,3,CONCRETE:8)
Block(-7,61,4,CONCRETE:8)
Block(-7,61,5,CONCRETE:8)
Block(-7,61,6,CONCRETE:8)
Block(-7,61,7,CONCRETE:8)
Block(-7,61,8,CONCRETE:8)
Block(-7,62,-7,CONCRETE:15)
Block(-7,62,-6,CONCRETE:15)
Block(-7,62,-5,CONCRETE:15)
Block(-7,62,3,STAINED_GLASS_PANE:15)
Block(-7,63,-7,CONCRETE:15)
Block(-7,63,-6,CONCRETE:15)
Block(-7,63,-5,CONCRETE:15)
Block(-7,64,-7,CONCRETE:15)
Block(-7,64,-6,CONCRETE:15)
Block(-7,64,-5,CONCRETE:15)
Block(-7,65,-7,CONCRETE:15)
Block(-7,65,-6,CONCRETE:15)
Block(-7,65,-5,CONCRETE:15)
Block(-7,65,3,CONCRETE:8)
Block(-7,65,4,CONCRETE:8)
Block(-7,65,5,CONCRETE:8)
Block(-7,65,6,CONCRETE:8)
Block(-7,65,7,CONCRETE:8)
Block(-7,65,8,CONCRETE:8)
Block(-7,66,-7,CONCRETE:15)
Block(-7,66,-6,CONCRETE:15)
Block(-7,66,-5,CONCRETE:15)
Block(-7,66,3,STAINED_GLASS_PANE:15)
Block(-7,67,-7,CONCRETE:15)
Block(-7,67,-6,CONCRETE:15)
Block(-7,67,-5,CONCRETE:15)
Block(-7,68,-7,CONCRETE:15)
Block(-7,68,-6,CONCRETE:15)
Block(-7,68,-5,CONCRETE:15)
Block(-7,69,-7,CONCRETE:15)
Block(-7,69,-6,CONCRETE:15)
Block(-7,69,-5,CONCRETE:15)
Block(-7,69,3,CONCRETE:8)
Block(-7,69,4,CONCRETE:8)
Block(-7,69,5,CONCRETE:8)
Block(-7,69,6,CONCRETE:8)
Block(-7,69,7,CONCRETE:8)
Block(-7,69,8,CONCRETE:8)
Block(-7,70,-7,CONCRETE:15)
Block(-7,70,-6,CONCRETE:15)
Block(-7,70,-5,CONCRETE:15)
Block(-7,70,3,STAINED_GLASS_PANE:15)
Block(-7,71,-7,CONCRETE:15)
Block(-7,71,-6,CONCRETE:15)
Block(-7,71,-5,CONCRETE:15)
Block(-7,72,-7,CONCRETE:15)
Block(-7,72,-6,CONCRETE:15)
Block(-7,72,-5,CONCRETE:15)
Block(-7,73,-7,CONCRETE:15)
Block(-7,73,-6,CONCRETE:15)
Block(-7,73,-5,CONCRETE:15)
Block(-7,73,3,CONCRETE:8)
Block(-7,73,4,CONCRETE:8)
Block(-7,73,5,CONCRETE:8)
Block(-7,73,6,CONCRETE:8)
Block(-7,73,7,CONCRETE:8)
Block(-7,73,8,CONCRETE:8)
Block(-7,74,-7,CONCRETE:15)
Block(-7,74,-6,CONCRETE:15)
Block(-7,74,-5,CONCRETE:15)
Block(-7,74,3,STAINED_GLASS_PANE:15)
Block(-7,75,-7,CONCRETE:15)
Block(-7,75,-6,CONCRETE:15)
Block(-7,75,-5,CONCRETE:15)
Block(-7,76,-7,CONCRETE:15)
Block(-7,76,-6,CONCRETE:15)
Block(-7,76,-5,CONCRETE:15)
Block(-7,77,-7,CONCRETE:15)
Block(-7,77,-6,CONCRETE:15)
Block(-7,77,-5,CONCRETE:15)
Block(-7,77,3,CONCRETE:8)
Block(-7,77,4,CONCRETE:8)
Block(-7,77,5,CONCRETE:8)
Block(-7,77,6,CONCRETE:8)
Block(-7,77,7,CONCRETE:8)
Block(-7,77,8,CONCRETE:8)
Block(-7,78,-7,CONCRETE:15)
Block(-7,78,-6,CONCRETE:15)
Block(-7,78,-5,CONCRETE:15)
Block(-7,78,3,STAINED_GLASS_PANE:15)
Block(-7,79,-7,CONCRETE:15)
Block(-7,79,-6,CONCRETE:15)
Block(-7,79,-5,CONCRETE:15)
Block(-7,80,-7,CONCRETE:15)
Block(-7,80,-6,CONCRETE:15)
Block(-7,80,-5,CONCRETE:15)
Block(-7,81,-7,CONCRETE:15)
Block(-7,81,-6,CONCRETE:15)
Block(-7,81,-5,CONCRETE:15)
Block(-7,81,3,CONCRETE:8)
Block(-7,81,4,CONCRETE:8)
Block(-7,81,5,CONCRETE:8)
Block(-7,81,6,CONCRETE:8)
Block(-7,81,7,CONCRETE:8)
Block(-7,81,8,CONCRETE:8)
Block(-7,82,-7,CONCRETE:15)
Block(-7,82,-6,CONCRETE:15)
Block(-7,82,-5,CONCRETE:15)
Block(-7,82,3,STAINED_GLASS_PANE:15)
Block(-7,83,-7,CONCRETE:15)
Block(-7,83,-6,CONCRETE:15)
Block(-7,83,-5,CONCRETE:15)
Block(-7,84,-7,CONCRETE:15)
Block(-7,84,-6,CONCRETE:15)
Block(-7,84,-5,CONCRETE:15)
Block(-7,85,-7,CONCRETE:15)
Block(-7,85,-6,CONCRETE:15)
Block(-7,85,-5,CONCRETE:15)
Block(-7,85,3,CONCRETE:8)
Block(-7,85,4,CONCRETE:8)
Block(-7,85,5,CONCRETE:8)
Block(-7,85,6,CONCRETE:8)
Block(-7,85,7,CONCRETE:8)
Block(-7,85,8,CONCRETE:8)
Block(-7,86,-7,CONCRETE:15)
Block(-7,86,-6,CONCRETE:15)
Block(-7,86,-5,CONCRETE:15)
Block(-7,86,3,STAINED_GLASS_PANE:15)
Block(-7,87,-7,CONCRETE:15)
Block(-7,87,-6,CONCRETE:15)
Block(-7,87,-5,CONCRETE:15)
Block(-7,88,-7,CONCRETE:15)
Block(-7,88,-6,CONCRETE:15)
Block(-7,88,-5,CONCRETE:15)
Block(-7,89,-7,CONCRETE:15)
Block(-7,89,-6,CONCRETE:15)
Block(-7,89,-5,CONCRETE:15)
Block(-7,89,3,CONCRETE:8)
Block(-7,89,4,CONCRETE:8)
Block(-7,89,5,CONCRETE:8)
Block(-7,89,6,CONCRETE:8)
Block(-7,89,7,CONCRETE:8)
Block(-7,89,8,CONCRETE:8)
Block(-7,90,-7,CONCRETE:15)
Block(-7,90,-6,CONCRETE:15)
Block(-7,90,-5,CONCRETE:15)
Block(-7,90,3,STAINED_GLASS_PANE:15)
Block(-7,91,-7,CONCRETE:15)
Block(-7,91,-6,CONCRETE:15)
Block(-7,91,-5,CONCRETE:15)
Block(-7,92,-7,CONCRETE:15)
Block(-7,92,-6,CONCRETE:15)
Block(-7,92,-5,CONCRETE:15)
Block(-7,93,-7,CONCRETE:15)
Block(-7,93,-6,CONCRETE:15)
Block(-7,93,-5,CONCRETE:15)
Block(-7,93,3,CONCRETE:8)
Block(-7,93,4,CONCRETE:8)
Block(-7,93,5,CONCRETE:8)
Block(-7,93,6,CONCRETE:8)
Block(-7,93,7,CONCRETE:8)
Block(-7,93,8,CONCRETE:8)
Block(-7,94,-7,CONCRETE:15)
Block(-7,94,-6,CONCRETE:15)
Block(-7,94,-5,CONCRETE:15)
Block(-7,94,3,STAINED_GLASS_PANE:15)
Block(-7,95,-7,CONCRETE:15)
Block(-7,95,-6,CONCRETE:15)
Block(-7,95,-5,CONCRETE:15)
Block(-7,96,-7,CONCRETE:15)
Block(-7,96,-6,CONCRETE:15)
Block(-7,96,-5,CONCRETE:15)
Block(-7,97,-7,CONCRETE:15)
Block(-7,97,-6,CONCRETE:15)
Block(-7,97,-5,CONCRETE:15)
Block(-7,97,3,CONCRETE:8)
Block(-7,97,4,CONCRETE:8)
Block(-7,97,5,CONCRETE:8)
Block(-7,97,6,CONCRETE:8)
Block(-7,97,7,CONCRETE:8)
Block(-7,97,8,CONCRETE:8)
Block(-7,98,-7,CONCRETE:15)
Block(-7,98,-6,CONCRETE:15)
Block(-7,98,-5,CONCRETE:15)
Block(-7,98,3,STAINED_GLASS_PANE:15)
Block(-7,99,-7,CONCRETE:15)
Block(-7,99,-6,CONCRETE:15)
Block(-7,99,-5,CONCRETE:15)
Block(-7,100,-7,CONCRETE:15)
Block(-7,100,-6,CONCRETE:15)
Block(-7,100,-5,CONCRETE:15)
Block(-7,101,-7,CONCRETE:15)
Block(-7,101,-6,CONCRETE:15)
Block(-7,101,-5,CONCRETE:15)
Block(-7,101,3,CONCRETE:8)
Block(-7,101,4,CONCRETE:8)
Block(-7,101,5,CONCRETE:8)
Block(-7,101,6,CONCRETE:8)
Block(-7,101,7,CONCRETE:8)
Block(-7,101,8,CONCRETE:8)
Block(-7,102,-7,CONCRETE:15)
Block(-7,102,-6,CONCRETE:15)
Block(-7,102,-5,CONCRETE:15)
Block(-7,102,3,STAINED_GLASS_PANE:15)
Block(-7,103,-7,CONCRETE:15)
Block(-7,103,-6,CONCRETE:15)
Block(-7,103,-5,CONCRETE:15)
Block(-7,104,-7,CONCRETE:15)
Block(-7,104,-6,CONCRETE:15)
Block(-7,104,-5,CONCRETE:15)
Block(-7,105,-7,CONCRETE:15)
Block(-7,105,-6,CONCRETE:15)
Block(-7,105,-5,CONCRETE:15)
Block(-7,105,3,CONCRETE:8)
Block(-7,105,4,CONCRETE:8)
Block(-7,105,5,CONCRETE:8)
Block(-7,105,6,CONCRETE:8)
Block(-7,105,7,CONCRETE:8)
Block(-7,105,8,CONCRETE:8)
Block(-7,106,-7,CONCRETE:15)
Block(-7,106,-6,CONCRETE:15)
Block(-7,106,-5,CONCRETE:15)
Block(-7,106,3,STAINED_GLASS_PANE:15)
Block(-7,107,-7,CONCRETE:15)
Block(-7,107,-6,CONCRETE:15)
Block(-7,107,-5,CONCRETE:15)
Block(-7,108,-7,CONCRETE:15)
Block(-7,108,-6,CONCRETE:15)
Block(-7,108,-5,CONCRETE:15)
Block(-7,109,-7,CONCRETE:15)
Block(-7,109,-6,CONCRETE:15)
Block(-7,109,-5,CONCRETE:15)
Block(-7,109,3,CONCRETE:8)
Block(-7,109,4,CONCRETE:8)
Block(-7,109,5,CONCRETE:8)
Block(-7,109,6,CONCRETE:8)
Block(-7,109,7,CONCRETE:8)
Block(-7,109,8,CONCRETE:8)
Block(-7,110,-7,CONCRETE:15)
Block(-7,110,-6,CONCRETE:15)
Block(-7,110,-5,CONCRETE:15)
Block(-7,110,3,STAINED_GLASS_PANE:15)
Block(-7,111,-7,CONCRETE:15)
Block(-7,111,-6,CONCRETE:15)
Block(-7,111,-5,CONCRETE:15)
Block(-7,112,-7,CONCRETE:15)
Block(-7,112,-6,CONCRETE:15)
Block(-7,112,-5,CONCRETE:15)
Block(-7,113,-7,CONCRETE:15)
Block(-7,113,-6,CONCRETE:15)
Block(-7,113,-5,CONCRETE:15)
Block(-7,114,-7,CONCRETE:15)
Block(-7,114,-6,CONCRETE:15)
Block(-7,114,-5,CONCRETE:15)
Block(-7,115,-7,CONCRETE:15)
Block(-7,115,-6,CONCRETE:15)
Block(-7,115,-5,CONCRETE:15)
Block(-7,116,-7,CONCRETE:15)
Block(-7,116,-6,CONCRETE:15)
Block(-7,116,-5,CONCRETE:15)
Block(-7,117,-7,CONCRETE:15)
Block(-7,117,-6,CONCRETE:15)
Block(-7,117,-5,CONCRETE:8)
Block(-7,117,-4,CONCRETE:8)
Block(-7,117,-3,CONCRETE:8)
Block(-7,117,-2,CONCRETE:8)
Block(-7,117,-1,CONCRETE:8)
Block(-7,117,0,CONCRETE:8)
Block(-7,117,1,CONCRETE:8)
Block(-7,117,2,CONCRETE:8)
Block(-7,117,3,CONCRETE:8)
Block(-7,117,4,CONCRETE:8)
Block(-7,117,5,CONCRETE:8)
Block(-7,117,6,CONCRETE:8)
Block(-7,117,7,CONCRETE:8)
Block(-7,117,8,CONCRETE:8)
Block(-7,118,-7,CONCRETE:15)
Block(-7,118,-6,CONCRETE:15)
Block(-7,118,-5,CONCRETE:15)
Block(-7,119,-7,CONCRETE:15)
Block(-7,119,-6,CONCRETE:15)
Block(-7,119,-5,CONCRETE:15)
Block(-7,120,-7,STEP:7)
Block(-7,120,-6,IRON_TRAPDOOR:1)
Block(-7,120,-5,STEP:7)
Block(-6,0,-7,CONCRETE:7)
Block(-6,0,-6,CONCRETE:7)
Block(-6,0,-5,CONCRETE:7)
Block(-6,0,-4,CONCRETE:7)
Block(-6,0,-3,CONCRETE:7)
Block(-6,0,-2,CONCRETE:7)
Block(-6,0,-1,CONCRETE:7)
Block(-6,0,0,CONCRETE:7)
Block(-6,0,1,CONCRETE:7)
Block(-6,0,2,CONCRETE:7)
Block(-6,0,3,CONCRETE:7)
Block(-6,0,4,CONCRETE:7)
Block(-6,0,5,CONCRETE:7)
Block(-6,0,6,CONCRETE:7)
Block(-6,0,7,CONCRETE:7)
Block(-6,0,8,CONCRETE:7)
Block(-6,1,-7,CONCRETE:7)
Block(-6,1,-6,CONCRETE:7)
Block(-6,1,-5,CONCRETE:7)
Block(-6,1,-4,CONCRETE:7)
Block(-6,1,-3,CONCRETE:7)
Block(-6,1,-2,CONCRETE:7)
Block(-6,1,-1,CONCRETE:7)
Block(-6,1,0,CONCRETE:7)
Block(-6,1,1,CONCRETE:7)
Block(-6,1,2,CONCRETE:7)
Block(-6,1,3,CONCRETE:7)
Block(-6,1,4,CONCRETE:7)
Block(-6,1,5,CONCRETE:7)
Block(-6,1,6,CONCRETE:7)
Block(-6,1,7,CONCRETE:7)
Block(-6,1,8,CONCRETE:7)
Block(-6,2,-7,CONCRETE:7)
Block(-6,2,-6,CONCRETE:7)
Block(-6,2,-5,CONCRETE:7)
Block(-6,2,-4,CONCRETE:7)
Block(-6,2,-3,CONCRETE:7)
Block(-6,2,-2,CONCRETE:7)
Block(-6,2,-1,CONCRETE:7)
Block(-6,2,0,CONCRETE:7)
Block(-6,2,1,CONCRETE:7)
Block(-6,2,2,CONCRETE:7)
Block(-6,2,3,CONCRETE:7)
Block(-6,2,4,CONCRETE:7)
Block(-6,2,5,CONCRETE:7)
Block(-6,2,6,CONCRETE:7)
Block(-6,2,7,CONCRETE:7)
Block(-6,2,8,CONCRETE:7)
Block(-6,3,-7,CONCRETE:7)
Block(-6,3,-6,CONCRETE:7)
Block(-6,3,-5,CONCRETE:7)
Block(-6,3,-4,CONCRETE:7)
Block(-6,3,-3,CONCRETE:7)
Block(-6,3,-2,CONCRETE:7)
Block(-6,3,-1,CONCRETE:7)
Block(-6,3,0,CONCRETE:7)
Block(-6,3,1,CONCRETE:7)
Block(-6,3,2,CONCRETE:7)
Block(-6,3,3,CONCRETE:7)
Block(-6,3,4,CONCRETE:7)
Block(-6,3,5,CONCRETE:7)
Block(-6,3,6,CONCRETE:7)
Block(-6,3,7,CONCRETE:7)
Block(-6,3,8,CONCRETE:7)
Block(-6,4,-7,CONCRETE:7)
Block(-6,4,-6,CONCRETE:7)
Block(-6,4,-5,CONCRETE:7)
Block(-6,4,-4,CONCRETE:7)
Block(-6,4,-3,CONCRETE:7)
Block(-6,4,-2,CONCRETE:7)
Block(-6,4,-1,CONCRETE:7)
Block(-6,4,0,CONCRETE:7)
Block(-6,4,1,CONCRETE:7)
Block(-6,4,2,CONCRETE:7)
Block(-6,4,3,CONCRETE:7)
Block(-6,4,4,CONCRETE:7)
Block(-6,4,5,CONCRETE:7)
Block(-6,4,6,CONCRETE:7)
Block(-6,4,7,CONCRETE:7)
Block(-6,4,8,CONCRETE:7)
Block(-6,5,-7,CONCRETE:7)
Block(-6,5,-6,CONCRETE:7)
Block(-6,5,-5,CONCRETE:7)
Block(-6,5,-4,CONCRETE:7)
Block(-6,5,-3,CONCRETE:7)
Block(-6,5,-2,CONCRETE:7)
Block(-6,5,-1,CONCRETE:7)
Block(-6,5,0,CONCRETE:7)
Block(-6,5,1,CONCRETE:7)
Block(-6,5,2,CONCRETE:7)
Block(-6,5,3,CONCRETE:7)
Block(-6,5,4,CONCRETE:7)
Block(-6,5,5,CONCRETE:7)
Block(-6,5,6,CONCRETE:7)
Block(-6,5,7,CONCRETE:7)
Block(-6,5,8,CONCRETE:7)
Block(-6,6,-7,CONCRETE:7)
Block(-6,6,-6,CONCRETE:7)
Block(-6,6,-5,CONCRETE:7)
Block(-6,6,-4,CONCRETE:7)
Block(-6,6,-3,CONCRETE:7)
Block(-6,6,-2,CONCRETE:7)
Block(-6,6,-1,CONCRETE:7)
Block(-6,6,0,CONCRETE:7)
Block(-6,6,1,CONCRETE:7)
Block(-6,6,2,CONCRETE:7)
Block(-6,6,3,CONCRETE:7)
Block(-6,6,4,CONCRETE:7)
Block(-6,6,5,CONCRETE:7)
Block(-6,6,6,CONCRETE:7)
Block(-6,6,7,CONCRETE:7)
Block(-6,6,8,CONCRETE:7)
Block(-6,7,-7,CONCRETE:7)
Block(-6,7,-6,CONCRETE:7)
Block(-6,7,-5,CONCRETE:7)
Block(-6,7,-4,CONCRETE:7)
Block(-6,7,-3,CONCRETE:7)
Block(-6,7,-2,CONCRETE:7)
Block(-6,7,-1,CONCRETE:7)
Block(-6,7,0,CONCRETE:7)
Block(-6,7,1,CONCRETE:7)
Block(-6,7,2,CONCRETE:7)
Block(-6,7,3,CONCRETE:7)
Block(-6,7,4,CONCRETE:7)
Block(-6,7,5,CONCRETE:7)
Block(-6,7,6,CONCRETE:7)
Block(-6,7,7,CONCRETE:7)
Block(-6,7,8,CONCRETE:7)
Block(-6,8,-7,CONCRETE:7)
Block(-6,8,-6,CONCRETE:7)
Block(-6,8,-5,CONCRETE:7)
Block(-6,8,-4,CONCRETE:7)
Block(-6,8,-3,CONCRETE:7)
Block(-6,8,-2,CONCRETE:7)
Block(-6,8,-1,CONCRETE:7)
Block(-6,8,0,CONCRETE:7)
Block(-6,8,1,CONCRETE:7)
Block(-6,8,2,CONCRETE:7)
Block(-6,8,3,CONCRETE:7)
Block(-6,8,4,CONCRETE:7)
Block(-6,8,5,CONCRETE:7)
Block(-6,8,6,CONCRETE:7)
Block(-6,8,7,CONCRETE:7)
Block(-6,8,8,CONCRETE:7)
Block(-6,9,-7,CONCRETE:7)
Block(-6,9,-6,CONCRETE:7)
Block(-6,9,-5,CONCRETE:7)
Block(-6,9,-4,CONCRETE:7)
Block(-6,9,-3,CONCRETE:7)
Block(-6,9,-2,CONCRETE:7)
Block(-6,9,-1,CONCRETE:7)
Block(-6,9,0,CONCRETE:7)
Block(-6,9,1,CONCRETE:7)
Block(-6,9,2,CONCRETE:7)
Block(-6,9,3,CONCRETE:4)
Block(-6,9,4,SMOOTH_STAIRS:2)
Block(-6,9,5,CONCRETE:7)
Block(-6,9,6,CONCRETE:7)
Block(-6,9,7,CONCRETE:7)
Block(-6,9,8,CONCRETE:7)
Block(-6,10,-7,CONCRETE:7)
Block(-6,10,-6,CONCRETE:8)
Block(-6,10,-5,CONCRETE:8)
Block(-6,10,-4,CONCRETE:8)
Block(-6,10,-3,CONCRETE:8)
Block(-6,10,-2,CONCRETE:8)
Block(-6,10,-1,CONCRETE:8)
Block(-6,10,0,CONCRETE:8)
Block(-6,10,1,CONCRETE:8)
Block(-6,10,2,CONCRETE:8)
Block(-6,10,3,CONCRETE:4)
Block(-6,10,4,AIR:0)
Block(-6,10,5,IRON_FENCE:0)
Block(-6,10,6,AIR:0)
Block(-6,10,7,IRON_TRAPDOOR:11)
Block(-6,10,8,CONCRETE:8)
Block(-6,11,-7,CONCRETE:7)
Block(-6,11,-6,CONCRETE:8)
Block(-6,11,-5,CONCRETE:8)
Block(-6,11,-4,CONCRETE:8)
Block(-6,11,-3,CONCRETE:8)
Block(-6,11,-2,CONCRETE:8)
Block(-6,11,-1,CONCRETE:8)
Block(-6,11,0,CONCRETE:8)
Block(-6,11,1,CONCRETE:8)
Block(-6,11,2,CONCRETE:8)
Block(-6,11,3,CONCRETE:4)
Block(-6,11,4,AIR:0)
Block(-6,11,5,IRON_FENCE:0)
Block(-6,11,6,AIR:0)
Block(-6,11,7,AIR:0)
Block(-6,11,8,CONCRETE:8)
Block(-6,12,-7,CONCRETE:7)
Block(-6,12,-6,CONCRETE:8)
Block(-6,12,-5,CONCRETE:8)
Block(-6,12,-4,CONCRETE:8)
Block(-6,12,-3,CONCRETE:8)
Block(-6,12,-2,CONCRETE:8)
Block(-6,12,-1,CONCRETE:8)
Block(-6,12,0,CONCRETE:8)
Block(-6,12,1,CONCRETE:8)
Block(-6,12,2,CONCRETE:8)
Block(-6,12,3,CONCRETE:4)
Block(-6,12,4,AIR:0)
Block(-6,12,5,IRON_FENCE:0)
Block(-6,12,6,AIR:0)
Block(-6,12,7,IRON_TRAPDOOR:0)
Block(-6,12,8,CONCRETE:8)
Block(-6,13,-7,CONCRETE:7)
Block(-6,13,-6,CONCRETE:8)
Block(-6,13,-5,CONCRETE:8)
Block(-6,13,-4,CONCRETE:8)
Block(-6,13,-3,CONCRETE:8)
Block(-6,13,-2,CONCRETE:8)
Block(-6,13,-1,CONCRETE:8)
Block(-6,13,0,CONCRETE:8)
Block(-6,13,1,CONCRETE:8)
Block(-6,13,2,CONCRETE:8)
Block(-6,13,3,CONCRETE:4)
Block(-6,13,4,AIR:0)
Block(-6,13,5,IRON_FENCE:0)
Block(-6,13,6,AIR:0)
Block(-6,13,7,AIR:0)
Block(-6,13,8,CONCRETE:8)
Block(-6,14,-7,CONCRETE:7)
Block(-6,14,-6,CONCRETE:8)
Block(-6,14,-5,CONCRETE:8)
Block(-6,14,-4,CONCRETE:8)
Block(-6,14,-3,CONCRETE:8)
Block(-6,14,-2,CONCRETE:8)
Block(-6,14,-1,CONCRETE:8)
Block(-6,14,0,CONCRETE:8)
Block(-6,14,1,CONCRETE:8)
Block(-6,14,2,CONCRETE:8)
Block(-6,14,3,CONCRETE:4)
Block(-6,14,4,SMOOTH_STAIRS:6)
Block(-6,14,5,CONCRETE:8)
Block(-6,14,6,CONCRETE:8)
Block(-6,14,7,CONCRETE:8)
Block(-6,14,8,CONCRETE:8)
Block(-6,15,-7,CONCRETE:7)
Block(-6,15,-6,CONCRETE:7)
Block(-6,15,-5,CONCRETE:7)
Block(-6,15,-4,CONCRETE:7)
Block(-6,15,-3,CONCRETE:7)
Block(-6,15,-2,CONCRETE:7)
Block(-6,15,-1,CONCRETE:7)
Block(-6,15,0,CONCRETE:7)
Block(-6,15,1,CONCRETE:7)
Block(-6,15,2,CONCRETE:7)
Block(-6,15,3,CONCRETE:7)
Block(-6,15,4,CONCRETE:7)
Block(-6,15,5,CONCRETE:7)
Block(-6,15,6,CONCRETE:7)
Block(-6,15,7,CONCRETE:7)
Block(-6,15,8,CONCRETE:7)
Block(-6,16,-7,CONCRETE:7)
Block(-6,16,-6,CONCRETE:15)
Block(-6,16,-5,CONCRETE:15)
Block(-6,16,-4,CONCRETE:15)
Block(-6,16,-3,CONCRETE:15)
Block(-6,16,-2,CONCRETE:15)
Block(-6,16,-1,CONCRETE:15)
Block(-6,16,0,CONCRETE:15)
Block(-6,16,1,CONCRETE:15)
Block(-6,16,2,CONCRETE:15)
Block(-6,16,3,CONCRETE:15)
Block(-6,16,4,CONCRETE:15)
Block(-6,16,5,CONCRETE:15)
Block(-6,16,6,CONCRETE:15)
Block(-6,16,7,CONCRETE:15)
Block(-6,16,8,CONCRETE:15)
Block(-6,17,-7,CONCRETE:7)
Block(-6,17,-6,STAINED_CLAY:9)
Block(-6,17,-5,CONCRETE:7)
Block(-6,17,-4,DIRT:1)
Block(-6,17,-3,DIRT:1)
Block(-6,17,-2,GRASS:0)
Block(-6,17,-1,GRASS:0)
Block(-6,17,0,DIRT:1)
Block(-6,17,1,GRASS:0)
Block(-6,17,2,GRASS:0)
Block(-6,17,3,DIRT:1)
Block(-6,17,4,DIRT:1)
Block(-6,17,5,DIRT:1)
Block(-6,17,6,DIRT:1)
Block(-6,17,7,GRASS:0)
Block(-6,17,8,GRASS:0)
Block(-6,18,-7,CONCRETE:15)
Block(-6,18,-6,CONCRETE:15)
Block(-6,18,-5,CONCRETE:15)
Block(-6,19,-7,CONCRETE:15)
Block(-6,19,-6,CONCRETE:15)
Block(-6,19,-5,CONCRETE:15)
Block(-6,20,-7,CONCRETE:15)
Block(-6,20,-6,CONCRETE:15)
Block(-6,20,-5,CONCRETE:15)
Block(-6,21,-7,CONCRETE:15)
Block(-6,21,-6,CONCRETE:15)
Block(-6,21,-5,CONCRETE:15)
Block(-6,22,-7,CONCRETE:15)
Block(-6,22,-6,CONCRETE:15)
Block(-6,22,-5,CONCRETE:15)
Block(-6,23,-7,CONCRETE:15)
Block(-6,23,-6,CONCRETE:15)
Block(-6,23,-5,CONCRETE:15)
Block(-6,24,-7,CONCRETE:15)
Block(-6,24,-6,CONCRETE:15)
Block(-6,24,-5,CONCRETE:15)
Block(-6,25,-7,CONCRETE:15)
Block(-6,25,-6,CONCRETE:15)
Block(-6,25,-5,CONCRETE:15)
Block(-6,25,3,CONCRETE:8)
Block(-6,25,4,CONCRETE:8)
Block(-6,25,5,CONCRETE:8)
Block(-6,25,6,CONCRETE:8)
Block(-6,25,7,CONCRETE:8)
Block(-6,25,8,CONCRETE:8)
Block(-6,26,-7,CONCRETE:15)
Block(-6,26,-6,CONCRETE:15)
Block(-6,26,-5,CONCRETE:15)
Block(-6,26,3,STAINED_GLASS_PANE:15)
Block(-6,26,5,STAINED_GLASS_PANE:0)
Block(-6,26,7,STAINED_GLASS_PANE:0)
Block(-6,27,-7,CONCRETE:15)
Block(-6,27,-6,CONCRETE:15)
Block(-6,27,-5,CONCRETE:15)
Block(-6,27,5,STAINED_GLASS_PANE:0)
Block(-6,27,7,STAINED_GLASS_PANE:0)
Block(-6,28,-7,CONCRETE:15)
Block(-6,28,-6,CONCRETE:15)
Block(-6,28,-5,CONCRETE:15)
Block(-6,29,-7,CONCRETE:15)
Block(-6,29,-6,CONCRETE:15)
Block(-6,29,-5,CONCRETE:15)
Block(-6,29,3,CONCRETE:8)
Block(-6,29,4,CONCRETE:8)
Block(-6,29,5,CONCRETE:8)
Block(-6,29,6,CONCRETE:8)
Block(-6,29,7,CONCRETE:8)
Block(-6,29,8,CONCRETE:8)
Block(-6,30,-7,CONCRETE:15)
Block(-6,30,-6,CONCRETE:15)
Block(-6,30,-5,CONCRETE:15)
Block(-6,30,3,STAINED_GLASS_PANE:15)
Block(-6,30,5,STAINED_GLASS_PANE:0)
Block(-6,30,7,STAINED_GLASS_PANE:0)
Block(-6,31,-7,CONCRETE:15)
Block(-6,31,-6,CONCRETE:15)
Block(-6,31,-5,CONCRETE:15)
Block(-6,31,5,STAINED_GLASS_PANE:0)
Block(-6,31,7,STAINED_GLASS_PANE:0)
Block(-6,32,-7,CONCRETE:15)
Block(-6,32,-6,CONCRETE:15)
Block(-6,32,-5,CONCRETE:15)
Block(-6,33,-7,CONCRETE:15)
Block(-6,33,-6,CONCRETE:15)
Block(-6,33,-5,CONCRETE:15)
Block(-6,33,3,CONCRETE:8)
Block(-6,33,4,CONCRETE:8)
Block(-6,33,5,CONCRETE:8)
Block(-6,33,6,CONCRETE:8)
Block(-6,33,7,CONCRETE:8)
Block(-6,33,8,CONCRETE:8)
Block(-6,34,-7,CONCRETE:15)
Block(-6,34,-6,CONCRETE:15)
Block(-6,34,-5,CONCRETE:15)
Block(-6,34,3,STAINED_GLASS_PANE:15)
Block(-6,34,5,STAINED_GLASS_PANE:0)
Block(-6,34,7,STAINED_GLASS_PANE:0)
Block(-6,35,-7,CONCRETE:15)
Block(-6,35,-6,CONCRETE:15)
Block(-6,35,-5,CONCRETE:15)
Block(-6,35,5,STAINED_GLASS_PANE:0)
Block(-6,35,7,STAINED_GLASS_PANE:0)
Block(-6,36,-7,CONCRETE:15)
Block(-6,36,-6,CONCRETE:15)
Block(-6,36,-5,CONCRETE:15)
Block(-6,37,-7,CONCRETE:15)
Block(-6,37,-6,CONCRETE:15)
Block(-6,37,-5,CONCRETE:15)
Block(-6,37,3,CONCRETE:8)
Block(-6,37,4,CONCRETE:8)
Block(-6,37,5,CONCRETE:8)
Block(-6,37,6,CONCRETE:8)
Block(-6,37,7,CONCRETE:8)
Block(-6,37,8,CONCRETE:8)
Block(-6,38,-7,CONCRETE:15)
Block(-6,38,-6,CONCRETE:15)
Block(-6,38,-5,CONCRETE:15)
Block(-6,38,3,STAINED_GLASS_PANE:15)
Block(-6,38,5,STAINED_GLASS_PANE:0)
Block(-6,38,7,STAINED_GLASS_PANE:0)
Block(-6,39,-7,CONCRETE:15)
Block(-6,39,-6,CONCRETE:15)
Block(-6,39,-5,CONCRETE:15)
Block(-6,39,5,STAINED_GLASS_PANE:0)
Block(-6,39,7,STAINED_GLASS_PANE:0)
Block(-6,40,-7,CONCRETE:15)
Block(-6,40,-6,CONCRETE:15)
Block(-6,40,-5,CONCRETE:15)
Block(-6,41,-7,CONCRETE:15)
Block(-6,41,-6,CONCRETE:15)
Block(-6,41,-5,CONCRETE:15)
Block(-6,41,3,CONCRETE:8)
Block(-6,41,4,CONCRETE:8)
Block(-6,41,5,CONCRETE:8)
Block(-6,41,6,CONCRETE:8)
Block(-6,41,7,CONCRETE:8)
Block(-6,41,8,CONCRETE:8)
Block(-6,42,-7,CONCRETE:15)
Block(-6,42,-6,CONCRETE:15)
Block(-6,42,-5,CONCRETE:15)
Block(-6,42,3,STAINED_GLASS_PANE:15)
Block(-6,42,5,STAINED_GLASS_PANE:0)
Block(-6,42,7,STAINED_GLASS_PANE:0)
Block(-6,43,-7,CONCRETE:15)
Block(-6,43,-6,CONCRETE:15)
Block(-6,43,-5,CONCRETE:15)
Block(-6,43,5,STAINED_GLASS_PANE:0)
Block(-6,43,7,STAINED_GLASS_PANE:0)
Block(-6,44,-7,CONCRETE:15)
Block(-6,44,-6,CONCRETE:15)
Block(-6,44,-5,CONCRETE:15)
Block(-6,45,-7,CONCRETE:15)
Block(-6,45,-6,CONCRETE:15)
Block(-6,45,-5,CONCRETE:15)
Block(-6,45,3,CONCRETE:8)
Block(-6,45,4,CONCRETE:8)
Block(-6,45,5,CONCRETE:8)
Block(-6,45,6,CONCRETE:8)
Block(-6,45,7,CONCRETE:8)
Block(-6,45,8,CONCRETE:8)
Block(-6,46,-7,CONCRETE:15)
Block(-6,46,-6,CONCRETE:15)
Block(-6,46,-5,CONCRETE:15)
Block(-6,46,3,STAINED_GLASS_PANE:15)
Block(-6,46,5,STAINED_GLASS_PANE:0)
Block(-6,46,7,STAINED_GLASS_PANE:0)
Block(-6,47,-7,CONCRETE:15)
Block(-6,47,-6,CONCRETE:15)
Block(-6,47,-5,CONCRETE:15)
Block(-6,47,5,STAINED_GLASS_PANE:0)
Block(-6,47,7,STAINED_GLASS_PANE:0)
Block(-6,48,-7,CONCRETE:15)
Block(-6,48,-6,CONCRETE:15)
Block(-6,48,-5,CONCRETE:15)
Block(-6,49,-7,CONCRETE:15)
Block(-6,49,-6,CONCRETE:15)
Block(-6,49,-5,CONCRETE:15)
Block(-6,49,3,CONCRETE:8)
Block(-6,49,4,CONCRETE:8)
Block(-6,49,5,CONCRETE:8)
Block(-6,49,6,CONCRETE:8)
Block(-6,49,7,CONCRETE:8)
Block(-6,49,8,CONCRETE:8)
Block(-6,50,-7,CONCRETE:15)
Block(-6,50,-6,CONCRETE:15)
Block(-6,50,-5,CONCRETE:15)
Block(-6,50,3,STAINED_GLASS_PANE:15)
Block(-6,50,5,STAINED_GLASS_PANE:0)
Block(-6,50,7,STAINED_GLASS_PANE:0)
Block(-6,51,-7,CONCRETE:15)
Block(-6,51,-6,CONCRETE:15)
Block(-6,51,-5,CONCRETE:15)
Block(-6,51,5,STAINED_GLASS_PANE:0)
Block(-6,51,7,STAINED_GLASS_PANE:0)
Block(-6,52,-7,CONCRETE:15)
Block(-6,52,-6,CONCRETE:15)
Block(-6,52,-5,CONCRETE:15)
Block(-6,53,-7,CONCRETE:15)
Block(-6,53,-6,CONCRETE:15)
Block(-6,53,-5,CONCRETE:15)
Block(-6,53,3,CONCRETE:8)
Block(-6,53,4,CONCRETE:8)
Block(-6,53,5,CONCRETE:8)
Block(-6,53,6,CONCRETE:8)
Block(-6,53,7,CONCRETE:8)
Block(-6,53,8,CONCRETE:8)
Block(-6,54,-7,CONCRETE:15)
Block(-6,54,-6,CONCRETE:15)
Block(-6,54,-5,CONCRETE:15)
Block(-6,54,3,STAINED_GLASS_PANE:15)
Block(-6,54,5,STAINED_GLASS_PANE:0)
Block(-6,54,7,STAINED_GLASS_PANE:0)
Block(-6,55,-7,CONCRETE:15)
Block(-6,55,-6,CONCRETE:15)
Block(-6,55,-5,CONCRETE:15)
Block(-6,55,5,STAINED_GLASS_PANE:0)
Block(-6,55,7,STAINED_GLASS_PANE:0)
Block(-6,56,-7,CONCRETE:15)
Block(-6,56,-6,CONCRETE:15)
Block(-6,56,-5,CONCRETE:15)
Block(-6,57,-7,CONCRETE:15)
Block(-6,57,-6,CONCRETE:15)
Block(-6,57,-5,CONCRETE:15)
Block(-6,57,3,CONCRETE:8)
Block(-6,57,4,CONCRETE:8)
Block(-6,57,5,CONCRETE:8)
Block(-6,57,6,CONCRETE:8)
Block(-6,57,7,CONCRETE:8)
Block(-6,57,8,CONCRETE:8)
Block(-6,58,-7,CONCRETE:15)
Block(-6,58,-6,CONCRETE:15)
Block(-6,58,-5,CONCRETE:15)
Block(-6,58,3,STAINED_GLASS_PANE:15)
Block(-6,58,5,STAINED_GLASS_PANE:0)
Block(-6,58,7,STAINED_GLASS_PANE:0)
Block(-6,59,-7,CONCRETE:15)
Block(-6,59,-6,CONCRETE:15)
Block(-6,59,-5,CONCRETE:15)
Block(-6,59,5,STAINED_GLASS_PANE:0)
Block(-6,59,7,STAINED_GLASS_PANE:0)
Block(-6,60,-7,CONCRETE:15)
Block(-6,60,-6,CONCRETE:15)
Block(-6,60,-5,CONCRETE:15)
Block(-6,61,-7,CONCRETE:15)
Block(-6,61,-6,CONCRETE:15)
Block(-6,61,-5,CONCRETE:15)
Block(-6,61,3,CONCRETE:8)
Block(-6,61,4,CONCRETE:8)
Block(-6,61,5,CONCRETE:8)
Block(-6,61,6,CONCRETE:8)
Block(-6,61,7,CONCRETE:8)
Block(-6,61,8,CONCRETE:8)
Block(-6,62,-7,CONCRETE:15)
Block(-6,62,-6,CONCRETE:15)
Block(-6,62,-5,CONCRETE:15)
Block(-6,62,3,STAINED_GLASS_PANE:15)
Block(-6,62,5,STAINED_GLASS_PANE:0)
Block(-6,62,7,STAINED_GLASS_PANE:0)
Block(-6,63,-7,CONCRETE:15)
Block(-6,63,-6,CONCRETE:15)
Block(-6,63,-5,CONCRETE:15)
Block(-6,63,5,STAINED_GLASS_PANE:0)
Block(-6,63,7,STAINED_GLASS_PANE:0)
Block(-6,64,-7,CONCRETE:15)
Block(-6,64,-6,CONCRETE:15)
Block(-6,64,-5,CONCRETE:15)
Block(-6,65,-7,CONCRETE:15)
Block(-6,65,-6,CONCRETE:15)
Block(-6,65,-5,CONCRETE:15)
Block(-6,65,3,CONCRETE:8)
Block(-6,65,4,CONCRETE:8)
Block(-6,65,5,CONCRETE:8)
Block(-6,65,6,CONCRETE:8)
Block(-6,65,7,CONCRETE:8)
Block(-6,65,8,CONCRETE:8)
Block(-6,66,-7,CONCRETE:15)
Block(-6,66,-6,CONCRETE:15)
Block(-6,66,-5,CONCRETE:15)
Block(-6,66,3,STAINED_GLASS_PANE:15)
Block(-6,66,5,STAINED_GLASS_PANE:0)
Block(-6,66,7,STAINED_GLASS_PANE:0)
Block(-6,67,-7,CONCRETE:15)
Block(-6,67,-6,CONCRETE:15)
Block(-6,67,-5,CONCRETE:15)
Block(-6,67,5,STAINED_GLASS_PANE:0)
Block(-6,67,7,STAINED_GLASS_PANE:0)
Block(-6,68,-7,CONCRETE:15)
Block(-6,68,-6,CONCRETE:15)
Block(-6,68,-5,CONCRETE:15)
Block(-6,69,-7,CONCRETE:15)
Block(-6,69,-6,CONCRETE:15)
Block(-6,69,-5,CONCRETE:15)
Block(-6,69,3,CONCRETE:8)
Block(-6,69,4,CONCRETE:8)
Block(-6,69,5,CONCRETE:8)
Block(-6,69,6,CONCRETE:8)
Block(-6,69,7,CONCRETE:8)
Block(-6,69,8,CONCRETE:8)
Block(-6,70,-7,CONCRETE:15)
Block(-6,70,-6,CONCRETE:15)
Block(-6,70,-5,CONCRETE:15)
Block(-6,70,3,STAINED_GLASS_PANE:15)
Block(-6,70,5,STAINED_GLASS_PANE:0)
Block(-6,70,7,STAINED_GLASS_PANE:0)
Block(-6,71,-7,CONCRETE:15)
Block(-6,71,-6,CONCRETE:15)
Block(-6,71,-5,CONCRETE:15)
Block(-6,71,5,STAINED_GLASS_PANE:0)
Block(-6,71,7,STAINED_GLASS_PANE:0)
Block(-6,72,-7,CONCRETE:15)
Block(-6,72,-6,CONCRETE:15)
Block(-6,72,-5,CONCRETE:15)
Block(-6,73,-7,CONCRETE:15)
Block(-6,73,-6,CONCRETE:15)
Block(-6,73,-5,CONCRETE:15)
Block(-6,73,3,CONCRETE:8)
Block(-6,73,4,CONCRETE:8)
Block(-6,73,5,CONCRETE:8)
Block(-6,73,6,CONCRETE:8)
Block(-6,73,7,CONCRETE:8)
Block(-6,73,8,CONCRETE:8)
Block(-6,74,-7,CONCRETE:15)
Block(-6,74,-6,CONCRETE:15)
Block(-6,74,-5,CONCRETE:15)
Block(-6,74,3,STAINED_GLASS_PANE:15)
Block(-6,74,5,STAINED_GLASS_PANE:0)
Block(-6,74,7,STAINED_GLASS_PANE:0)
Block(-6,75,-7,CONCRETE:15)
Block(-6,75,-6,CONCRETE:15)
Block(-6,75,-5,CONCRETE:15)
Block(-6,75,5,STAINED_GLASS_PANE:0)
Block(-6,75,7,STAINED_GLASS_PANE:0)
Block(-6,76,-7,CONCRETE:15)
Block(-6,76,-6,CONCRETE:15)
Block(-6,76,-5,CONCRETE:15)
Block(-6,77,-7,CONCRETE:15)
Block(-6,77,-6,CONCRETE:15)
Block(-6,77,-5,CONCRETE:15)
Block(-6,77,3,CONCRETE:8)
Block(-6,77,4,CONCRETE:8)
Block(-6,77,5,CONCRETE:8)
Block(-6,77,6,CONCRETE:8)
Block(-6,77,7,CONCRETE:8)
Block(-6,77,8,CONCRETE:8)
Block(-6,78,-7,CONCRETE:15)
Block(-6,78,-6,CONCRETE:15)
Block(-6,78,-5,CONCRETE:15)
Block(-6,78,3,STAINED_GLASS_PANE:15)
Block(-6,78,5,STAINED_GLASS_PANE:0)
Block(-6,78,7,STAINED_GLASS_PANE:0)
Block(-6,79,-7,CONCRETE:15)
Block(-6,79,-6,CONCRETE:15)
Block(-6,79,-5,CONCRETE:15)
Block(-6,79,5,STAINED_GLASS_PANE:0)
Block(-6,79,7,STAINED_GLASS_PANE:0)
Block(-6,80,-7,CONCRETE:15)
Block(-6,80,-6,CONCRETE:15)
Block(-6,80,-5,CONCRETE:15)
Block(-6,81,-7,CONCRETE:15)
Block(-6,81,-6,CONCRETE:15)
Block(-6,81,-5,CONCRETE:15)
Block(-6,81,3,CONCRETE:8)
Block(-6,81,4,CONCRETE:8)
Block(-6,81,5,CONCRETE:8)
Block(-6,81,6,CONCRETE:8)
Block(-6,81,7,CONCRETE:8)
Block(-6,81,8,CONCRETE:8)
Block(-6,82,-7,CONCRETE:15)
Block(-6,82,-6,CONCRETE:15)
Block(-6,82,-5,CONCRETE:15)
Block(-6,82,3,STAINED_GLASS_PANE:15)
Block(-6,82,5,STAINED_GLASS_PANE:0)
Block(-6,82,7,STAINED_GLASS_PANE:0)
Block(-6,83,-7,CONCRETE:15)
Block(-6,83,-6,CONCRETE:15)
Block(-6,83,-5,CONCRETE:15)
Block(-6,83,5,STAINED_GLASS_PANE:0)
Block(-6,83,7,STAINED_GLASS_PANE:0)
Block(-6,84,-7,CONCRETE:15)
Block(-6,84,-6,CONCRETE:15)
Block(-6,84,-5,CONCRETE:15)
Block(-6,85,-7,CONCRETE:15)
Block(-6,85,-6,CONCRETE:15)
Block(-6,85,-5,CONCRETE:15)
Block(-6,85,3,CONCRETE:8)
Block(-6,85,4,CONCRETE:8)
Block(-6,85,5,CONCRETE:8)
Block(-6,85,6,CONCRETE:8)
Block(-6,85,7,CONCRETE:8)
Block(-6,85,8,CONCRETE:8)
Block(-6,86,-7,CONCRETE:15)
Block(-6,86,-6,CONCRETE:15)
Block(-6,86,-5,CONCRETE:15)
Block(-6,86,3,STAINED_GLASS_PANE:15)
Block(-6,86,5,STAINED_GLASS_PANE:0)
Block(-6,86,7,STAINED_GLASS_PANE:0)
Block(-6,87,-7,CONCRETE:15)
Block(-6,87,-6,CONCRETE:15)
Block(-6,87,-5,CONCRETE:15)
Block(-6,87,5,STAINED_GLASS_PANE:0)
Block(-6,87,7,STAINED_GLASS_PANE:0)
Block(-6,88,-7,CONCRETE:15)
Block(-6,88,-6,CONCRETE:15)
Block(-6,88,-5,CONCRETE:15)
Block(-6,89,-7,CONCRETE:15)
Block(-6,89,-6,CONCRETE:15)
Block(-6,89,-5,CONCRETE:15)
Block(-6,89,3,CONCRETE:8)
Block(-6,89,4,CONCRETE:8)
Block(-6,89,5,CONCRETE:8)
Block(-6,89,6,CONCRETE:8)
Block(-6,89,7,CONCRETE:8)
Block(-6,89,8,CONCRETE:8)
Block(-6,90,-7,CONCRETE:15)
Block(-6,90,-6,CONCRETE:15)
Block(-6,90,-5,CONCRETE:15)
Block(-6,90,3,STAINED_GLASS_PANE:15)
Block(-6,90,5,STAINED_GLASS_PANE:0)
Block(-6,90,7,STAINED_GLASS_PANE:0)
Block(-6,91,-7,CONCRETE:15)
Block(-6,91,-6,CONCRETE:15)
Block(-6,91,-5,CONCRETE:15)
Block(-6,91,5,STAINED_GLASS_PANE:0)
Block(-6,91,7,STAINED_GLASS_PANE:0)
Block(-6,92,-7,CONCRETE:15)
Block(-6,92,-6,CONCRETE:15)
Block(-6,92,-5,CONCRETE:15)
Block(-6,93,-7,CONCRETE:15)
Block(-6,93,-6,CONCRETE:15)
Block(-6,93,-5,CONCRETE:15)
Block(-6,93,3,CONCRETE:8)
Block(-6,93,4,CONCRETE:8)
Block(-6,93,5,CONCRETE:8)
Block(-6,93,6,CONCRETE:8)
Block(-6,93,7,CONCRETE:8)
Block(-6,93,8,CONCRETE:8)
Block(-6,94,-7,CONCRETE:15)
Block(-6,94,-6,CONCRETE:15)
Block(-6,94,-5,CONCRETE:15)
Block(-6,94,3,STAINED_GLASS_PANE:15)
Block(-6,94,5,STAINED_GLASS_PANE:0)
Block(-6,94,7,STAINED_GLASS_PANE:0)
Block(-6,95,-7,CONCRETE:15)
Block(-6,95,-6,CONCRETE:15)
Block(-6,95,-5,CONCRETE:15)
Block(-6,95,5,STAINED_GLASS_PANE:0)
Block(-6,95,7,STAINED_GLASS_PANE:0)
Block(-6,96,-7,CONCRETE:15)
Block(-6,96,-6,CONCRETE:15)
Block(-6,96,-5,CONCRETE:15)
Block(-6,97,-7,CONCRETE:15)
Block(-6,97,-6,CONCRETE:15)
Block(-6,97,-5,CONCRETE:15)
Block(-6,97,3,CONCRETE:8)
Block(-6,97,4,CONCRETE:8)
Block(-6,97,5,CONCRETE:8)
Block(-6,97,6,CONCRETE:8)
Block(-6,97,7,CONCRETE:8)
Block(-6,97,8,CONCRETE:8)
Block(-6,98,-7,CONCRETE:15)
Block(-6,98,-6,CONCRETE:15)
Block(-6,98,-5,CONCRETE:15)
Block(-6,98,3,STAINED_GLASS_PANE:15)
Block(-6,98,5,STAINED_GLASS_PANE:0)
Block(-6,98,7,STAINED_GLASS_PANE:0)
Block(-6,99,-7,CONCRETE:15)
Block(-6,99,-6,CONCRETE:15)
Block(-6,99,-5,CONCRETE:15)
Block(-6,99,5,STAINED_GLASS_PANE:0)
Block(-6,99,7,STAINED_GLASS_PANE:0)
Block(-6,100,-7,CONCRETE:15)
Block(-6,100,-6,CONCRETE:15)
Block(-6,100,-5,CONCRETE:15)
Block(-6,101,-7,CONCRETE:15)
Block(-6,101,-6,CONCRETE:15)
Block(-6,101,-5,CONCRETE:15)
Block(-6,101,3,CONCRETE:8)
Block(-6,101,4,CONCRETE:8)
Block(-6,101,5,CONCRETE:8)
Block(-6,101,6,CONCRETE:8)
Block(-6,101,7,CONCRETE:8)
Block(-6,101,8,CONCRETE:8)
Block(-6,102,-7,CONCRETE:15)
Block(-6,102,-6,CONCRETE:15)
Block(-6,102,-5,CONCRETE:15)
Block(-6,102,3,STAINED_GLASS_PANE:15)
Block(-6,102,5,STAINED_GLASS_PANE:0)
Block(-6,102,7,STAINED_GLASS_PANE:0)
Block(-6,103,-7,CONCRETE:15)
Block(-6,103,-6,CONCRETE:15)
Block(-6,103,-5,CONCRETE:15)
Block(-6,103,5,STAINED_GLASS_PANE:0)
Block(-6,103,7,STAINED_GLASS_PANE:0)
Block(-6,104,-7,CONCRETE:15)
Block(-6,104,-6,CONCRETE:15)
Block(-6,104,-5,CONCRETE:15)
Block(-6,105,-7,CONCRETE:15)
Block(-6,105,-6,CONCRETE:15)
Block(-6,105,-5,CONCRETE:15)
Block(-6,105,3,CONCRETE:8)
Block(-6,105,4,CONCRETE:8)
Block(-6,105,5,CONCRETE:8)
Block(-6,105,6,CONCRETE:8)
Block(-6,105,7,CONCRETE:8)
Block(-6,105,8,CONCRETE:8)
Block(-6,106,-7,CONCRETE:15)
Block(-6,106,-6,CONCRETE:15)
Block(-6,106,-5,CONCRETE:15)
Block(-6,106,3,STAINED_GLASS_PANE:15)
Block(-6,106,5,STAINED_GLASS_PANE:0)
Block(-6,106,7,STAINED_GLASS_PANE:0)
Block(-6,107,-7,CONCRETE:15)
Block(-6,107,-6,CONCRETE:15)
Block(-6,107,-5,CONCRETE:15)
Block(-6,107,5,STAINED_GLASS_PANE:0)
Block(-6,107,7,STAINED_GLASS_PANE:0)
Block(-6,108,-7,CONCRETE:15)
Block(-6,108,-6,CONCRETE:15)
Block(-6,108,-5,CONCRETE:15)
Block(-6,109,-7,CONCRETE:15)
Block(-6,109,-6,CONCRETE:15)
Block(-6,109,-5,CONCRETE:15)
Block(-6,109,3,CONCRETE:8)
Block(-6,109,4,CONCRETE:8)
Block(-6,109,5,CONCRETE:8)
Block(-6,109,6,CONCRETE:8)
Block(-6,109,7,CONCRETE:8)
Block(-6,109,8,CONCRETE:8)
Block(-6,110,-7,CONCRETE:15)
Block(-6,110,-6,CONCRETE:15)
Block(-6,110,-5,CONCRETE:15)
Block(-6,110,3,STAINED_GLASS_PANE:15)
Block(-6,111,-7,CONCRETE:15)
Block(-6,111,-6,CONCRETE:15)
Block(-6,111,-5,CONCRETE:15)
Block(-6,112,-7,CONCRETE:15)
Block(-6,112,-6,CONCRETE:15)
Block(-6,112,-5,CONCRETE:15)
Block(-6,113,-7,CONCRETE:15)
Block(-6,113,-6,CONCRETE:15)
Block(-6,113,-5,CONCRETE:15)
Block(-6,114,-7,CONCRETE:15)
Block(-6,114,-6,CONCRETE:15)
Block(-6,114,-5,CONCRETE:15)
Block(-6,115,-7,CONCRETE:15)
Block(-6,115,-6,CONCRETE:15)
Block(-6,115,-5,CONCRETE:15)
Block(-6,116,-7,CONCRETE:15)
Block(-6,116,-6,CONCRETE:15)
Block(-6,116,-5,CONCRETE:15)
Block(-6,117,-7,CONCRETE:15)
Block(-6,117,-6,CONCRETE:8)
Block(-6,117,-5,CONCRETE:8)
Block(-6,117,-4,CONCRETE:8)
Block(-6,117,-3,CONCRETE:8)
Block(-6,117,-2,CONCRETE:8)
Block(-6,117,-1,CONCRETE:8)
Block(-6,117,0,CONCRETE:8)
Block(-6,117,1,CONCRETE:8)
Block(-6,117,2,CONCRETE:8)
Block(-6,117,3,CONCRETE:8)
Block(-6,117,4,CONCRETE:8)
Block(-6,117,5,CONCRETE:8)
Block(-6,117,6,CONCRETE:8)
Block(-6,117,7,CONCRETE:8)
Block(-6,117,8,CONCRETE:8)
Block(-6,118,-7,CONCRETE:15)
Block(-6,118,-6,CONCRETE:15)
Block(-6,118,-5,CONCRETE:15)
Block(-6,119,-7,CONCRETE:15)
Block(-6,119,-6,CONCRETE:15)
Block(-6,119,-5,CONCRETE:15)
Block(-6,120,-7,STEP:7)
Block(-6,120,-6,STEP:7)
Block(-6,120,-5,STEP:7)
Block(-5,0,-7,CONCRETE:7)
Block(-5,0,-6,CONCRETE:7)
Block(-5,0,-5,CONCRETE:7)
Block(-5,0,-4,CONCRETE:7)
Block(-5,0,-3,CONCRETE:7)
Block(-5,0,-2,CONCRETE:7)
Block(-5,0,-1,CONCRETE:7)
Block(-5,0,0,CONCRETE:7)
Block(-5,0,1,CONCRETE:7)
Block(-5,0,2,CONCRETE:7)
Block(-5,0,3,CONCRETE:7)
Block(-5,0,4,CONCRETE:7)
Block(-5,0,5,CONCRETE:7)
Block(-5,0,6,CONCRETE:7)
Block(-5,0,7,CONCRETE:7)
Block(-5,0,8,CONCRETE:7)
Block(-5,1,-7,CONCRETE:7)
Block(-5,1,-6,CONCRETE:7)
Block(-5,1,-5,CONCRETE:7)
Block(-5,1,-4,CONCRETE:7)
Block(-5,1,-3,CONCRETE:7)
Block(-5,1,-2,CONCRETE:7)
Block(-5,1,-1,CONCRETE:7)
Block(-5,1,0,CONCRETE:7)
Block(-5,1,1,CONCRETE:7)
Block(-5,1,2,CONCRETE:7)
Block(-5,1,3,CONCRETE:7)
Block(-5,1,4,CONCRETE:7)
Block(-5,1,5,CONCRETE:7)
Block(-5,1,6,CONCRETE:7)
Block(-5,1,7,CONCRETE:7)
Block(-5,1,8,CONCRETE:7)
Block(-5,2,-7,CONCRETE:7)
Block(-5,2,-6,CONCRETE:7)
Block(-5,2,-5,CONCRETE:7)
Block(-5,2,-4,CONCRETE:7)
Block(-5,2,-3,CONCRETE:7)
Block(-5,2,-2,CONCRETE:7)
Block(-5,2,-1,CONCRETE:7)
Block(-5,2,0,CONCRETE:7)
Block(-5,2,1,CONCRETE:7)
Block(-5,2,2,CONCRETE:7)
Block(-5,2,3,CONCRETE:7)
Block(-5,2,4,CONCRETE:7)
Block(-5,2,5,CONCRETE:7)
Block(-5,2,6,CONCRETE:7)
Block(-5,2,7,CONCRETE:7)
Block(-5,2,8,CONCRETE:7)
Block(-5,3,-7,CONCRETE:7)
Block(-5,3,-6,CONCRETE:7)
Block(-5,3,-5,CONCRETE:7)
Block(-5,3,-4,CONCRETE:7)
Block(-5,3,-3,CONCRETE:7)
Block(-5,3,-2,CONCRETE:7)
Block(-5,3,-1,CONCRETE:7)
Block(-5,3,0,CONCRETE:7)
Block(-5,3,1,CONCRETE:7)
Block(-5,3,2,CONCRETE:7)
Block(-5,3,3,CONCRETE:7)
Block(-5,3,4,CONCRETE:7)
Block(-5,3,5,CONCRETE:7)
Block(-5,3,6,CONCRETE:7)
Block(-5,3,7,CONCRETE:7)
Block(-5,3,8,CONCRETE:7)
Block(-5,4,-7,CONCRETE:7)
Block(-5,4,-6,CONCRETE:7)
Block(-5,4,-5,CONCRETE:7)
Block(-5,4,-4,CONCRETE:7)
Block(-5,4,-3,CONCRETE:7)
Block(-5,4,-2,CONCRETE:7)
Block(-5,4,-1,CONCRETE:7)
Block(-5,4,0,CONCRETE:7)
Block(-5,4,1,CONCRETE:7)
Block(-5,4,2,CONCRETE:7)
Block(-5,4,3,CONCRETE:7)
Block(-5,4,4,CONCRETE:7)
Block(-5,4,5,CONCRETE:7)
Block(-5,4,6,CONCRETE:7)
Block(-5,4,7,CONCRETE:7)
Block(-5,4,8,CONCRETE:7)
Block(-5,5,-7,CONCRETE:7)
Block(-5,5,-6,CONCRETE:7)
Block(-5,5,-5,CONCRETE:7)
Block(-5,5,-4,CONCRETE:7)
Block(-5,5,-3,CONCRETE:7)
Block(-5,5,-2,CONCRETE:7)
Block(-5,5,-1,CONCRETE:7)
Block(-5,5,0,CONCRETE:7)
Block(-5,5,1,CONCRETE:7)
Block(-5,5,2,CONCRETE:7)
Block(-5,5,3,CONCRETE:7)
Block(-5,5,4,CONCRETE:7)
Block(-5,5,5,CONCRETE:7)
Block(-5,5,6,CONCRETE:7)
Block(-5,5,7,CONCRETE:7)
Block(-5,5,8,CONCRETE:7)
Block(-5,6,-7,CONCRETE:7)
Block(-5,6,-6,CONCRETE:7)
Block(-5,6,-5,CONCRETE:7)
Block(-5,6,-4,CONCRETE:7)
Block(-5,6,-3,CONCRETE:7)
Block(-5,6,-2,CONCRETE:7)
Block(-5,6,-1,CONCRETE:7)
Block(-5,6,0,CONCRETE:7)
Block(-5,6,1,CONCRETE:7)
Block(-5,6,2,CONCRETE:7)
Block(-5,6,3,CONCRETE:7)
Block(-5,6,4,CONCRETE:7)
Block(-5,6,5,CONCRETE:7)
Block(-5,6,6,CONCRETE:7)
Block(-5,6,7,CONCRETE:7)
Block(-5,6,8,CONCRETE:7)
Block(-5,7,-7,CONCRETE:7)
Block(-5,7,-6,CONCRETE:7)
Block(-5,7,-5,CONCRETE:7)
Block(-5,7,-4,CONCRETE:7)
Block(-5,7,-3,CONCRETE:7)
Block(-5,7,-2,CONCRETE:7)
Block(-5,7,-1,CONCRETE:7)
Block(-5,7,0,CONCRETE:7)
Block(-5,7,1,CONCRETE:7)
Block(-5,7,2,CONCRETE:7)
Block(-5,7,3,CONCRETE:7)
Block(-5,7,4,CONCRETE:7)
Block(-5,7,5,CONCRETE:7)
Block(-5,7,6,CONCRETE:7)
Block(-5,7,7,CONCRETE:7)
Block(-5,7,8,CONCRETE:7)
Block(-5,8,-7,CONCRETE:7)
Block(-5,8,-6,CONCRETE:7)
Block(-5,8,-5,CONCRETE:7)
Block(-5,8,-4,CONCRETE:7)
Block(-5,8,-3,CONCRETE:7)
Block(-5,8,-2,CONCRETE:7)
Block(-5,8,-1,CONCRETE:7)
Block(-5,8,0,CONCRETE:7)
Block(-5,8,1,CONCRETE:7)
Block(-5,8,2,CONCRETE:7)
Block(-5,8,3,CONCRETE:7)
Block(-5,8,4,CONCRETE:7)
Block(-5,8,5,CONCRETE:7)
Block(-5,8,6,CONCRETE:7)
Block(-5,8,7,CONCRETE:7)
Block(-5,8,8,CONCRETE:7)
Block(-5,9,-7,CONCRETE:7)
Block(-5,9,-6,CONCRETE:7)
Block(-5,9,-5,CONCRETE:7)
Block(-5,9,-4,CONCRETE:7)
Block(-5,9,-3,CONCRETE:7)
Block(-5,9,-2,CONCRETE:7)
Block(-5,9,-1,CONCRETE:7)
Block(-5,9,0,CONCRETE:7)
Block(-5,9,1,CONCRETE:7)
Block(-5,9,2,CONCRETE:7)
Block(-5,9,3,SMOOTH_STAIRS:0)
Block(-5,9,4,SMOOTH_STAIRS:2)
Block(-5,9,5,CONCRETE:7)
Block(-5,9,6,CONCRETE:7)
Block(-5,9,7,CONCRETE:7)
Block(-5,9,8,CONCRETE:7)
Block(-5,10,-7,CONCRETE:7)
Block(-5,10,-6,CONCRETE:8)
Block(-5,10,-5,CONCRETE:8)
Block(-5,10,-4,CONCRETE:8)
Block(-5,10,-3,CONCRETE:8)
Block(-5,10,-2,CONCRETE:8)
Block(-5,10,-1,CONCRETE:8)
Block(-5,10,0,CONCRETE:8)
Block(-5,10,1,CONCRETE:8)
Block(-5,10,2,CONCRETE:8)
Block(-5,10,3,AIR:0)
Block(-5,10,4,IRON_FENCE:0)
Block(-5,10,5,IRON_FENCE:0)
Block(-5,10,6,AIR:0)
Block(-5,10,7,IRON_TRAPDOOR:8)
Block(-5,10,8,CONCRETE:8)
Block(-5,11,-7,CONCRETE:7)
Block(-5,11,-6,CONCRETE:8)
Block(-5,11,-5,CONCRETE:8)
Block(-5,11,-4,CONCRETE:8)
Block(-5,11,-3,CONCRETE:8)
Block(-5,11,-2,CONCRETE:8)
Block(-5,11,-1,CONCRETE:8)
Block(-5,11,0,CONCRETE:8)
Block(-5,11,1,CONCRETE:8)
Block(-5,11,2,CONCRETE:8)
Block(-5,11,3,AIR:0)
Block(-5,11,4,IRON_FENCE:0)
Block(-5,11,5,IRON_FENCE:0)
Block(-5,11,6,AIR:0)
Block(-5,11,7,AIR:0)
Block(-5,11,8,CONCRETE:8)
Block(-5,12,-7,CONCRETE:7)
Block(-5,12,-6,CONCRETE:8)
Block(-5,12,-5,CONCRETE:8)
Block(-5,12,-4,CONCRETE:8)
Block(-5,12,-3,CONCRETE:8)
Block(-5,12,-2,CONCRETE:8)
Block(-5,12,-1,CONCRETE:8)
Block(-5,12,0,CONCRETE:8)
Block(-5,12,1,CONCRETE:8)
Block(-5,12,2,CONCRETE:8)
Block(-5,12,3,CONCRETE:4)
Block(-5,12,4,IRON_FENCE:0)
Block(-5,12,5,IRON_FENCE:0)
Block(-5,12,6,AIR:0)
Block(-5,12,7,IRON_TRAPDOOR:0)
Block(-5,12,8,CONCRETE:8)
Block(-5,13,-7,CONCRETE:7)
Block(-5,13,-6,CONCRETE:8)
Block(-5,13,-5,CONCRETE:8)
Block(-5,13,-4,CONCRETE:8)
Block(-5,13,-3,CONCRETE:8)
Block(-5,13,-2,CONCRETE:8)
Block(-5,13,-1,CONCRETE:8)
Block(-5,13,0,CONCRETE:8)
Block(-5,13,1,CONCRETE:8)
Block(-5,13,2,CONCRETE:8)
Block(-5,13,3,AIR:0)
Block(-5,13,4,AIR:0)
Block(-5,13,5,IRON_FENCE:0)
Block(-5,13,6,AIR:0)
Block(-5,13,7,AIR:0)
Block(-5,13,8,CONCRETE:8)
Block(-5,14,-7,CONCRETE:7)
Block(-5,14,-6,CONCRETE:8)
Block(-5,14,-5,CONCRETE:8)
Block(-5,14,-4,CONCRETE:8)
Block(-5,14,-3,CONCRETE:8)
Block(-5,14,-2,CONCRETE:8)
Block(-5,14,-1,CONCRETE:8)
Block(-5,14,0,CONCRETE:8)
Block(-5,14,1,CONCRETE:8)
Block(-5,14,2,CONCRETE:8)
Block(-5,14,3,SMOOTH_STAIRS:4)
Block(-5,14,4,SMOOTH_STAIRS:4)
Block(-5,14,5,CONCRETE:8)
Block(-5,14,6,CONCRETE:8)
Block(-5,14,7,CONCRETE:8)
Block(-5,14,8,CONCRETE:8)
Block(-5,15,-7,CONCRETE:7)
Block(-5,15,-6,CONCRETE:7)
Block(-5,15,-5,CONCRETE:7)
Block(-5,15,-4,CONCRETE:7)
Block(-5,15,-3,CONCRETE:7)
Block(-5,15,-2,CONCRETE:7)
Block(-5,15,-1,CONCRETE:7)
Block(-5,15,0,CONCRETE:7)
Block(-5,15,1,CONCRETE:7)
Block(-5,15,2,CONCRETE:7)
Block(-5,15,3,CONCRETE:7)
Block(-5,15,4,CONCRETE:7)
Block(-5,15,5,CONCRETE:7)
Block(-5,15,6,CONCRETE:7)
Block(-5,15,7,CONCRETE:7)
Block(-5,15,8,CONCRETE:7)
Block(-5,16,-7,CONCRETE:7)
Block(-5,16,-6,CONCRETE:15)
Block(-5,16,-5,CONCRETE:15)
Block(-5,16,-4,CONCRETE:15)
Block(-5,16,-3,CONCRETE:15)
Block(-5,16,-2,CONCRETE:15)
Block(-5,16,-1,CONCRETE:15)
Block(-5,16,0,CONCRETE:15)
Block(-5,16,1,CONCRETE:15)
Block(-5,16,2,CONCRETE:15)
Block(-5,16,3,CONCRETE:15)
Block(-5,16,4,CONCRETE:15)
Block(-5,16,5,CONCRETE:15)
Block(-5,16,6,CONCRETE:15)
Block(-5,16,7,CONCRETE:15)
Block(-5,16,8,CONCRETE:15)
Block(-5,17,-7,CONCRETE:7)
Block(-5,17,-6,SMOOTH_BRICK:0)
Block(-5,17,-5,CONCRETE:7)
Block(-5,17,-4,SEA_LANTERN:0)
Block(-5,17,-3,CONCRETE:8)
Block(-5,17,-2,CONCRETE:8)
Block(-5,17,-1,CONCRETE:8)
Block(-5,17,0,CONCRETE:8)
Block(-5,17,1,CONCRETE:8)
Block(-5,17,2,CONCRETE:8)
Block(-5,17,3,CONCRETE:8)
Block(-5,17,4,CONCRETE:8)
Block(-5,17,5,CONCRETE:8)
Block(-5,17,6,CONCRETE:8)
Block(-5,17,7,CONCRETE:8)
Block(-5,17,8,CONCRETE:8)
Block(-5,18,-4,STAINED_GLASS:15)
Block(-5,18,-3,STAINED_GLASS:15)
Block(-5,18,-2,STAINED_GLASS:15)
Block(-5,18,-1,STAINED_GLASS:15)
Block(-5,18,0,STAINED_GLASS:15)
Block(-5,18,1,STAINED_GLASS:15)
Block(-5,18,2,STAINED_GLASS:15)
Block(-5,18,3,STAINED_GLASS:15)
Block(-5,18,4,STAINED_GLASS:15)
Block(-5,18,5,STAINED_GLASS:15)
Block(-5,18,6,STAINED_GLASS:15)
Block(-5,18,7,STAINED_GLASS:15)
Block(-5,18,8,STAINED_GLASS:15)
Block(-5,19,-4,STAINED_GLASS:15)
Block(-5,19,-3,STAINED_GLASS:15)
Block(-5,19,-2,STAINED_GLASS:15)
Block(-5,19,-1,STAINED_GLASS:15)
Block(-5,19,0,STAINED_GLASS:15)
Block(-5,19,1,STAINED_GLASS:15)
Block(-5,19,2,STAINED_GLASS:15)
Block(-5,19,3,STAINED_GLASS:15)
Block(-5,19,4,STAINED_GLASS:15)
Block(-5,19,5,STAINED_GLASS:15)
Block(-5,19,6,STAINED_GLASS:15)
Block(-5,19,7,STAINED_GLASS:15)
Block(-5,19,8,STAINED_GLASS:15)
Block(-5,20,-4,STAINED_GLASS:15)
Block(-5,20,-3,STAINED_GLASS:15)
Block(-5,20,-2,STAINED_GLASS:15)
Block(-5,20,-1,STAINED_GLASS:15)
Block(-5,20,0,STAINED_GLASS:15)
Block(-5,20,1,STAINED_GLASS:15)
Block(-5,20,2,STAINED_GLASS:15)
Block(-5,20,3,STAINED_GLASS:15)
Block(-5,20,4,STAINED_GLASS:15)
Block(-5,20,5,STAINED_GLASS:15)
Block(-5,20,6,STAINED_GLASS:15)
Block(-5,20,7,STAINED_GLASS:15)
Block(-5,20,8,STAINED_GLASS:15)
Block(-5,21,-4,STAINED_GLASS:15)
Block(-5,21,-3,STAINED_GLASS:15)
Block(-5,21,-2,STAINED_GLASS:15)
Block(-5,21,-1,STAINED_GLASS:15)
Block(-5,21,0,STAINED_GLASS:15)
Block(-5,21,1,STAINED_GLASS:15)
Block(-5,21,2,STAINED_GLASS:15)
Block(-5,21,3,STAINED_GLASS:15)
Block(-5,21,4,STAINED_GLASS:15)
Block(-5,21,5,STAINED_GLASS:15)
Block(-5,21,6,STAINED_GLASS:15)
Block(-5,21,7,STAINED_GLASS:15)
Block(-5,21,8,STAINED_GLASS:15)
Block(-5,22,-4,STAINED_GLASS:15)
Block(-5,22,-3,STAINED_GLASS:15)
Block(-5,22,-2,STAINED_GLASS:15)
Block(-5,22,-1,STAINED_GLASS:15)
Block(-5,22,0,STAINED_GLASS:15)
Block(-5,22,1,STAINED_GLASS:15)
Block(-5,22,2,STAINED_GLASS:15)
Block(-5,22,3,STAINED_GLASS:15)
Block(-5,22,4,STAINED_GLASS:15)
Block(-5,22,5,STAINED_GLASS:15)
Block(-5,22,6,STAINED_GLASS:15)
Block(-5,22,7,STAINED_GLASS:15)
Block(-5,22,8,STAINED_GLASS:15)
Block(-5,23,-4,STAINED_GLASS:15)
Block(-5,23,-3,STAINED_GLASS:15)
Block(-5,23,-2,STAINED_GLASS:15)
Block(-5,23,-1,STAINED_GLASS:15)
Block(-5,23,0,STAINED_GLASS:15)
Block(-5,23,1,STAINED_GLASS:15)
Block(-5,23,2,STAINED_GLASS:15)
Block(-5,23,3,STAINED_GLASS:15)
Block(-5,23,4,STAINED_GLASS:15)
Block(-5,23,5,STAINED_GLASS:15)
Block(-5,23,6,STAINED_GLASS:15)
Block(-5,23,7,STAINED_GLASS:15)
Block(-5,23,8,STAINED_GLASS:15)
Block(-5,24,-4,STAINED_GLASS:15)
Block(-5,24,-3,STAINED_GLASS:15)
Block(-5,24,-2,STAINED_GLASS:15)
Block(-5,24,-1,STAINED_GLASS:15)
Block(-5,24,0,STAINED_GLASS:15)
Block(-5,24,1,STAINED_GLASS:15)
Block(-5,24,2,STAINED_GLASS:15)
Block(-5,24,3,STAINED_GLASS:15)
Block(-5,24,4,STAINED_GLASS:15)
Block(-5,24,5,STAINED_GLASS:15)
Block(-5,24,6,STAINED_GLASS:15)
Block(-5,24,7,STAINED_GLASS:15)
Block(-5,24,8,STAINED_GLASS:15)
Block(-5,25,-4,STAINED_GLASS:15)
Block(-5,25,-3,STAINED_GLASS:15)
Block(-5,25,-2,STAINED_GLASS:15)
Block(-5,25,-1,STAINED_GLASS:15)
Block(-5,25,0,STAINED_GLASS:15)
Block(-5,25,1,STAINED_GLASS:15)
Block(-5,25,2,STAINED_GLASS:15)
Block(-5,25,3,CONCRETE:8)
Block(-5,25,4,CONCRETE:8)
Block(-5,25,5,CONCRETE:8)
Block(-5,25,6,CONCRETE:8)
Block(-5,25,7,CONCRETE:8)
Block(-5,25,8,CONCRETE:8)
Block(-5,26,-4,STAINED_GLASS:15)
Block(-5,26,-3,STAINED_GLASS:15)
Block(-5,26,-2,STAINED_GLASS:15)
Block(-5,26,-1,STAINED_GLASS:15)
Block(-5,26,0,STAINED_GLASS:15)
Block(-5,26,1,STAINED_GLASS:15)
Block(-5,26,2,STAINED_GLASS:15)
Block(-5,26,3,STAINED_GLASS:15)
Block(-5,26,4,STAINED_GLASS_PANE:15)
Block(-5,26,5,STAINED_GLASS_PANE:15)
Block(-5,26,7,STAINED_GLASS_PANE:15)
Block(-5,26,8,STAINED_GLASS:15)
Block(-5,27,-4,STAINED_GLASS:15)
Block(-5,27,-3,STAINED_GLASS:15)
Block(-5,27,-2,STAINED_GLASS:15)
Block(-5,27,-1,STAINED_GLASS:15)
Block(-5,27,0,STAINED_GLASS:15)
Block(-5,27,1,STAINED_GLASS:15)
Block(-5,27,2,STAINED_GLASS:15)
Block(-5,27,3,STAINED_GLASS:15)
Block(-5,27,4,STAINED_GLASS_PANE:15)
Block(-5,27,5,STAINED_GLASS_PANE:15)
Block(-5,27,7,STAINED_GLASS_PANE:15)
Block(-5,27,8,STAINED_GLASS:15)
Block(-5,28,-4,STAINED_GLASS:15)
Block(-5,28,-3,STAINED_GLASS:15)
Block(-5,28,-2,STAINED_GLASS:15)
Block(-5,28,-1,STAINED_GLASS:15)
Block(-5,28,0,STAINED_GLASS:15)
Block(-5,28,1,STAINED_GLASS:15)
Block(-5,28,2,STAINED_GLASS:15)
Block(-5,28,3,STAINED_GLASS:15)
Block(-5,28,4,STAINED_GLASS:15)
Block(-5,28,5,STAINED_GLASS:15)
Block(-5,28,6,STAINED_GLASS:15)
Block(-5,28,7,STAINED_GLASS:15)
Block(-5,28,8,STAINED_GLASS:15)
Block(-5,29,-4,STAINED_GLASS:15)
Block(-5,29,-3,STAINED_GLASS:15)
Block(-5,29,-2,STAINED_GLASS:15)
Block(-5,29,-1,STAINED_GLASS:15)
Block(-5,29,0,STAINED_GLASS:15)
Block(-5,29,1,STAINED_GLASS:15)
Block(-5,29,2,STAINED_GLASS:15)
Block(-5,29,3,CONCRETE:8)
Block(-5,29,4,CONCRETE:8)
Block(-5,29,5,CONCRETE:8)
Block(-5,29,6,CONCRETE:8)
Block(-5,29,7,CONCRETE:8)
Block(-5,29,8,CONCRETE:8)
Block(-5,30,-4,STAINED_GLASS:15)
Block(-5,30,-3,STAINED_GLASS:15)
Block(-5,30,-2,STAINED_GLASS:15)
Block(-5,30,-1,STAINED_GLASS:15)
Block(-5,30,0,STAINED_GLASS:15)
Block(-5,30,1,STAINED_GLASS:15)
Block(-5,30,2,STAINED_GLASS:15)
Block(-5,30,3,STAINED_GLASS:15)
Block(-5,30,4,STAINED_GLASS_PANE:15)
Block(-5,30,5,STAINED_GLASS_PANE:15)
Block(-5,30,7,STAINED_GLASS_PANE:15)
Block(-5,30,8,STAINED_GLASS:15)
Block(-5,31,-4,STAINED_GLASS:15)
Block(-5,31,-3,STAINED_GLASS:15)
Block(-5,31,-2,STAINED_GLASS:15)
Block(-5,31,-1,STAINED_GLASS:15)
Block(-5,31,0,STAINED_GLASS:15)
Block(-5,31,1,STAINED_GLASS:15)
Block(-5,31,2,STAINED_GLASS:15)
Block(-5,31,3,STAINED_GLASS:15)
Block(-5,31,4,STAINED_GLASS_PANE:15)
Block(-5,31,5,STAINED_GLASS_PANE:15)
Block(-5,31,7,STAINED_GLASS_PANE:15)
Block(-5,31,8,STAINED_GLASS:15)
Block(-5,32,-4,STAINED_GLASS:15)
Block(-5,32,-3,STAINED_GLASS:15)
Block(-5,32,-2,STAINED_GLASS:15)
Block(-5,32,-1,STAINED_GLASS:15)
Block(-5,32,0,STAINED_GLASS:15)
Block(-5,32,1,STAINED_GLASS:15)
Block(-5,32,2,STAINED_GLASS:15)
Block(-5,32,3,STAINED_GLASS:15)
Block(-5,32,4,STAINED_GLASS:15)
Block(-5,32,5,STAINED_GLASS:15)
Block(-5,32,6,STAINED_GLASS:15)
Block(-5,32,7,STAINED_GLASS:15)
Block(-5,32,8,STAINED_GLASS:15)
Block(-5,33,-4,STAINED_GLASS:15)
Block(-5,33,-3,STAINED_GLASS:15)
Block(-5,33,-2,STAINED_GLASS:15)
Block(-5,33,-1,STAINED_GLASS:15)
Block(-5,33,0,STAINED_GLASS:15)
Block(-5,33,1,STAINED_GLASS:15)
Block(-5,33,2,STAINED_GLASS:15)
Block(-5,33,3,CONCRETE:8)
Block(-5,33,4,CONCRETE:8)
Block(-5,33,5,CONCRETE:8)
Block(-5,33,6,CONCRETE:8)
Block(-5,33,7,CONCRETE:8)
Block(-5,33,8,CONCRETE:8)
Block(-5,34,-4,STAINED_GLASS:15)
Block(-5,34,-3,STAINED_GLASS:15)
Block(-5,34,-2,STAINED_GLASS:15)
Block(-5,34,-1,STAINED_GLASS:15)
Block(-5,34,0,STAINED_GLASS:15)
Block(-5,34,1,STAINED_GLASS:15)
Block(-5,34,2,STAINED_GLASS:15)
Block(-5,34,3,STAINED_GLASS:15)
Block(-5,34,4,STAINED_GLASS_PANE:15)
Block(-5,34,5,STAINED_GLASS_PANE:15)
Block(-5,34,7,STAINED_GLASS_PANE:15)
Block(-5,34,8,STAINED_GLASS:15)
Block(-5,35,-4,STAINED_GLASS:15)
Block(-5,35,-3,STAINED_GLASS:15)
Block(-5,35,-2,STAINED_GLASS:15)
Block(-5,35,-1,STAINED_GLASS:15)
Block(-5,35,0,STAINED_GLASS:15)
Block(-5,35,1,STAINED_GLASS:15)
Block(-5,35,2,STAINED_GLASS:15)
Block(-5,35,3,STAINED_GLASS:15)
Block(-5,35,4,STAINED_GLASS_PANE:15)
Block(-5,35,5,STAINED_GLASS_PANE:15)
Block(-5,35,7,STAINED_GLASS_PANE:15)
Block(-5,35,8,STAINED_GLASS:15)
Block(-5,36,-4,STAINED_GLASS:15)
Block(-5,36,-3,STAINED_GLASS:15)
Block(-5,36,-2,STAINED_GLASS:15)
Block(-5,36,-1,STAINED_GLASS:15)
Block(-5,36,0,STAINED_GLASS:15)
Block(-5,36,1,STAINED_GLASS:15)
Block(-5,36,2,STAINED_GLASS:15)
Block(-5,36,3,STAINED_GLASS:15)
Block(-5,36,4,STAINED_GLASS:15)
Block(-5,36,5,STAINED_GLASS:15)
Block(-5,36,6,STAINED_GLASS:15)
Block(-5,36,7,STAINED_GLASS:15)
Block(-5,36,8,STAINED_GLASS:15)
Block(-5,37,-4,STAINED_GLASS:15)
Block(-5,37,-3,STAINED_GLASS:15)
Block(-5,37,-2,STAINED_GLASS:15)
Block(-5,37,-1,STAINED_GLASS:15)
Block(-5,37,0,STAINED_GLASS:15)
Block(-5,37,1,STAINED_GLASS:15)
Block(-5,37,2,STAINED_GLASS:15)
Block(-5,37,3,CONCRETE:8)
Block(-5,37,4,CONCRETE:8)
Block(-5,37,5,CONCRETE:8)
Block(-5,37,6,CONCRETE:8)
Block(-5,37,7,CONCRETE:8)
Block(-5,37,8,CONCRETE:8)
Block(-5,38,-4,STAINED_GLASS:15)
Block(-5,38,-3,STAINED_GLASS:15)
Block(-5,38,-2,STAINED_GLASS:15)
Block(-5,38,-1,STAINED_GLASS:15)
Block(-5,38,0,STAINED_GLASS:15)
Block(-5,38,1,STAINED_GLASS:15)
Block(-5,38,2,STAINED_GLASS:15)
Block(-5,38,3,STAINED_GLASS:15)
Block(-5,38,4,STAINED_GLASS_PANE:15)
Block(-5,38,5,STAINED_GLASS_PANE:15)
Block(-5,38,7,STAINED_GLASS_PANE:15)
Block(-5,38,8,STAINED_GLASS:15)
Block(-5,39,-4,STAINED_GLASS:15)
Block(-5,39,-3,STAINED_GLASS:15)
Block(-5,39,-2,STAINED_GLASS:15)
Block(-5,39,-1,STAINED_GLASS:15)
Block(-5,39,0,STAINED_GLASS:15)
Block(-5,39,1,STAINED_GLASS:15)
Block(-5,39,2,STAINED_GLASS:15)
Block(-5,39,3,STAINED_GLASS:15)
Block(-5,39,4,STAINED_GLASS_PANE:15)
Block(-5,39,5,STAINED_GLASS_PANE:15)
Block(-5,39,7,STAINED_GLASS_PANE:15)
Block(-5,39,8,STAINED_GLASS:15)
Block(-5,40,-4,STAINED_GLASS:15)
Block(-5,40,-3,STAINED_GLASS:15)
Block(-5,40,-2,STAINED_GLASS:15)
Block(-5,40,-1,STAINED_GLASS:15)
Block(-5,40,0,STAINED_GLASS:15)
Block(-5,40,1,STAINED_GLASS:15)
Block(-5,40,2,STAINED_GLASS:15)
Block(-5,40,3,STAINED_GLASS:15)
Block(-5,40,4,STAINED_GLASS:15)
Block(-5,40,5,STAINED_GLASS:15)
Block(-5,40,6,STAINED_GLASS:15)
Block(-5,40,7,STAINED_GLASS:15)
Block(-5,40,8,STAINED_GLASS:15)
Block(-5,41,-4,STAINED_GLASS:15)
Block(-5,41,-3,STAINED_GLASS:15)
Block(-5,41,-2,STAINED_GLASS:15)
Block(-5,41,-1,STAINED_GLASS:15)
Block(-5,41,0,STAINED_GLASS:15)
Block(-5,41,1,STAINED_GLASS:15)
Block(-5,41,2,STAINED_GLASS:15)
Block(-5,41,3,CONCRETE:8)
Block(-5,41,4,CONCRETE:8)
Block(-5,41,5,CONCRETE:8)
Block(-5,41,6,CONCRETE:8)
Block(-5,41,7,CONCRETE:8)
Block(-5,41,8,CONCRETE:8)
Block(-5,42,-4,STAINED_GLASS:15)
Block(-5,42,-3,STAINED_GLASS:15)
Block(-5,42,-2,STAINED_GLASS:15)
Block(-5,42,-1,STAINED_GLASS:15)
Block(-5,42,0,STAINED_GLASS:15)
Block(-5,42,1,STAINED_GLASS:15)
Block(-5,42,2,STAINED_GLASS:15)
Block(-5,42,3,STAINED_GLASS:15)
Block(-5,42,4,STAINED_GLASS_PANE:15)
Block(-5,42,5,STAINED_GLASS_PANE:15)
Block(-5,42,7,STAINED_GLASS_PANE:15)
Block(-5,42,8,STAINED_GLASS:15)
Block(-5,43,-4,STAINED_GLASS:15)
Block(-5,43,-3,STAINED_GLASS:15)
Block(-5,43,-2,STAINED_GLASS:15)
Block(-5,43,-1,STAINED_GLASS:15)
Block(-5,43,0,STAINED_GLASS:15)
Block(-5,43,1,STAINED_GLASS:15)
Block(-5,43,2,STAINED_GLASS:15)
Block(-5,43,3,STAINED_GLASS:15)
Block(-5,43,4,STAINED_GLASS_PANE:15)
Block(-5,43,5,STAINED_GLASS_PANE:15)
Block(-5,43,7,STAINED_GLASS_PANE:15)
Block(-5,43,8,STAINED_GLASS:15)
Block(-5,44,-4,STAINED_GLASS:15)
Block(-5,44,-3,STAINED_GLASS:15)
Block(-5,44,-2,STAINED_GLASS:15)
Block(-5,44,-1,STAINED_GLASS:15)
Block(-5,44,0,STAINED_GLASS:15)
Block(-5,44,1,STAINED_GLASS:15)
Block(-5,44,2,STAINED_GLASS:15)
Block(-5,44,3,STAINED_GLASS:15)
Block(-5,44,4,STAINED_GLASS:15)
Block(-5,44,5,STAINED_GLASS:15)
Block(-5,44,6,STAINED_GLASS:15)
Block(-5,44,7,STAINED_GLASS:15)
Block(-5,44,8,STAINED_GLASS:15)
Block(-5,45,-4,STAINED_GLASS:15)
Block(-5,45,-3,STAINED_GLASS:15)
Block(-5,45,-2,STAINED_GLASS:15)
Block(-5,45,-1,STAINED_GLASS:15)
Block(-5,45,0,STAINED_GLASS:15)
Block(-5,45,1,STAINED_GLASS:15)
Block(-5,45,2,STAINED_GLASS:15)
Block(-5,45,3,CONCRETE:8)
Block(-5,45,4,CONCRETE:8)
Block(-5,45,5,CONCRETE:8)
Block(-5,45,6,CONCRETE:8)
Block(-5,45,7,CONCRETE:8)
Block(-5,45,8,CONCRETE:8)
Block(-5,46,-4,STAINED_GLASS:15)
Block(-5,46,-3,STAINED_GLASS:15)
Block(-5,46,-2,STAINED_GLASS:15)
Block(-5,46,-1,STAINED_GLASS:15)
Block(-5,46,0,STAINED_GLASS:15)
Block(-5,46,1,STAINED_GLASS:15)
Block(-5,46,2,STAINED_GLASS:15)
Block(-5,46,3,STAINED_GLASS:15)
Block(-5,46,4,STAINED_GLASS_PANE:15)
Block(-5,46,5,STAINED_GLASS_PANE:15)
Block(-5,46,7,STAINED_GLASS_PANE:15)
Block(-5,46,8,STAINED_GLASS:15)
Block(-5,47,-4,STAINED_GLASS:15)
Block(-5,47,-3,STAINED_GLASS:15)
Block(-5,47,-2,STAINED_GLASS:15)
Block(-5,47,-1,STAINED_GLASS:15)
Block(-5,47,0,STAINED_GLASS:15)
Block(-5,47,1,STAINED_GLASS:15)
Block(-5,47,2,STAINED_GLASS:15)
Block(-5,47,3,STAINED_GLASS:15)
Block(-5,47,4,STAINED_GLASS_PANE:15)
Block(-5,47,5,STAINED_GLASS_PANE:15)
Block(-5,47,7,STAINED_GLASS_PANE:15)
Block(-5,47,8,STAINED_GLASS:15)
Block(-5,48,-4,STAINED_GLASS:15)
Block(-5,48,-3,STAINED_GLASS:15)
Block(-5,48,-2,STAINED_GLASS:15)
Block(-5,48,-1,STAINED_GLASS:15)
Block(-5,48,0,STAINED_GLASS:15)
Block(-5,48,1,STAINED_GLASS:15)
Block(-5,48,2,STAINED_GLASS:15)
Block(-5,48,3,STAINED_GLASS:15)
Block(-5,48,4,STAINED_GLASS:15)
Block(-5,48,5,STAINED_GLASS:15)
Block(-5,48,6,STAINED_GLASS:15)
Block(-5,48,7,STAINED_GLASS:15)
Block(-5,48,8,STAINED_GLASS:15)
Block(-5,49,-4,STAINED_GLASS:15)
Block(-5,49,-3,STAINED_GLASS:15)
Block(-5,49,-2,STAINED_GLASS:15)
Block(-5,49,-1,STAINED_GLASS:15)
Block(-5,49,0,STAINED_GLASS:15)
Block(-5,49,1,STAINED_GLASS:15)
Block(-5,49,2,STAINED_GLASS:15)
Block(-5,49,3,CONCRETE:8)
Block(-5,49,4,CONCRETE:8)
Block(-5,49,5,CONCRETE:8)
Block(-5,49,6,CONCRETE:8)
Block(-5,49,7,CONCRETE:8)
Block(-5,49,8,CONCRETE:8)
Block(-5,50,-4,STAINED_GLASS:15)
Block(-5,50,-3,STAINED_GLASS:15)
Block(-5,50,-2,STAINED_GLASS:15)
Block(-5,50,-1,STAINED_GLASS:15)
Block(-5,50,0,STAINED_GLASS:15)
Block(-5,50,1,STAINED_GLASS:15)
Block(-5,50,2,STAINED_GLASS:15)
Block(-5,50,3,STAINED_GLASS:15)
Block(-5,50,4,STAINED_GLASS_PANE:15)
Block(-5,50,5,STAINED_GLASS_PANE:15)
Block(-5,50,7,STAINED_GLASS_PANE:15)
Block(-5,50,8,STAINED_GLASS:15)
Block(-5,51,-4,STAINED_GLASS:15)
Block(-5,51,-3,STAINED_GLASS:15)
Block(-5,51,-2,STAINED_GLASS:15)
Block(-5,51,-1,STAINED_GLASS:15)
Block(-5,51,0,STAINED_GLASS:15)
Block(-5,51,1,STAINED_GLASS:15)
Block(-5,51,2,STAINED_GLASS:15)
Block(-5,51,3,STAINED_GLASS:15)
Block(-5,51,4,STAINED_GLASS_PANE:15)
Block(-5,51,5,STAINED_GLASS_PANE:15)
Block(-5,51,7,STAINED_GLASS_PANE:15)
Block(-5,51,8,STAINED_GLASS:15)
Block(-5,52,-4,STAINED_GLASS:15)
Block(-5,52,-3,STAINED_GLASS:15)
Block(-5,52,-2,STAINED_GLASS:15)
Block(-5,52,-1,STAINED_GLASS:15)
Block(-5,52,0,STAINED_GLASS:15)
Block(-5,52,1,STAINED_GLASS:15)
Block(-5,52,2,STAINED_GLASS:15)
Block(-5,52,3,STAINED_GLASS:15)
Block(-5,52,4,STAINED_GLASS:15)
Block(-5,52,5,STAINED_GLASS:15)
Block(-5,52,6,STAINED_GLASS:15)
Block(-5,52,7,STAINED_GLASS:15)
Block(-5,52,8,STAINED_GLASS:15)
Block(-5,53,-4,STAINED_GLASS:15)
Block(-5,53,-3,STAINED_GLASS:15)
Block(-5,53,-2,STAINED_GLASS:15)
Block(-5,53,-1,STAINED_GLASS:15)
Block(-5,53,0,STAINED_GLASS:15)
Block(-5,53,1,STAINED_GLASS:15)
Block(-5,53,2,STAINED_GLASS:15)
Block(-5,53,3,CONCRETE:8)
Block(-5,53,4,CONCRETE:8)
Block(-5,53,5,CONCRETE:8)
Block(-5,53,6,CONCRETE:8)
Block(-5,53,7,CONCRETE:8)
Block(-5,53,8,CONCRETE:8)
Block(-5,54,-4,STAINED_GLASS:15)
Block(-5,54,-3,STAINED_GLASS:15)
Block(-5,54,-2,STAINED_GLASS:15)
Block(-5,54,-1,STAINED_GLASS:15)
Block(-5,54,0,STAINED_GLASS:15)
Block(-5,54,1,STAINED_GLASS:15)
Block(-5,54,2,STAINED_GLASS:15)
Block(-5,54,3,STAINED_GLASS:15)
Block(-5,54,4,STAINED_GLASS_PANE:15)
Block(-5,54,5,STAINED_GLASS_PANE:15)
Block(-5,54,7,STAINED_GLASS_PANE:15)
Block(-5,54,8,STAINED_GLASS:15)
Block(-5,55,-4,STAINED_GLASS:15)
Block(-5,55,-3,STAINED_GLASS:15)
Block(-5,55,-2,STAINED_GLASS:15)
Block(-5,55,-1,STAINED_GLASS:15)
Block(-5,55,0,STAINED_GLASS:15)
Block(-5,55,1,STAINED_GLASS:15)
Block(-5,55,2,STAINED_GLASS:15)
Block(-5,55,3,STAINED_GLASS:15)
Block(-5,55,4,STAINED_GLASS_PANE:15)
Block(-5,55,5,STAINED_GLASS_PANE:15)
Block(-5,55,7,STAINED_GLASS_PANE:15)
Block(-5,55,8,STAINED_GLASS:15)
Block(-5,56,-4,STAINED_GLASS:15)
Block(-5,56,-3,STAINED_GLASS:15)
Block(-5,56,-2,STAINED_GLASS:15)
Block(-5,56,-1,STAINED_GLASS:15)
Block(-5,56,0,STAINED_GLASS:15)
Block(-5,56,1,STAINED_GLASS:15)
Block(-5,56,2,STAINED_GLASS:15)
Block(-5,56,3,STAINED_GLASS:15)
Block(-5,56,4,STAINED_GLASS:15)
Block(-5,56,5,STAINED_GLASS:15)
Block(-5,56,6,STAINED_GLASS:15)
Block(-5,56,7,STAINED_GLASS:15)
Block(-5,56,8,STAINED_GLASS:15)
Block(-5,57,-4,STAINED_GLASS:15)
Block(-5,57,-3,STAINED_GLASS:15)
Block(-5,57,-2,STAINED_GLASS:15)
Block(-5,57,-1,STAINED_GLASS:15)
Block(-5,57,0,STAINED_GLASS:15)
Block(-5,57,1,STAINED_GLASS:15)
Block(-5,57,2,STAINED_GLASS:15)
Block(-5,57,3,CONCRETE:8)
Block(-5,57,4,CONCRETE:8)
Block(-5,57,5,CONCRETE:8)
Block(-5,57,6,CONCRETE:8)
Block(-5,57,7,CONCRETE:8)
Block(-5,57,8,CONCRETE:8)
Block(-5,58,-4,STAINED_GLASS:15)
Block(-5,58,-3,STAINED_GLASS:15)
Block(-5,58,-2,STAINED_GLASS:15)
Block(-5,58,-1,STAINED_GLASS:15)
Block(-5,58,0,STAINED_GLASS:15)
Block(-5,58,1,STAINED_GLASS:15)
Block(-5,58,2,STAINED_GLASS:15)
Block(-5,58,3,STAINED_GLASS:15)
Block(-5,58,4,STAINED_GLASS_PANE:15)
Block(-5,58,5,STAINED_GLASS_PANE:15)
Block(-5,58,7,STAINED_GLASS_PANE:15)
Block(-5,58,8,STAINED_GLASS:15)
Block(-5,59,-4,STAINED_GLASS:15)
Block(-5,59,-3,STAINED_GLASS:15)
Block(-5,59,-2,STAINED_GLASS:15)
Block(-5,59,-1,STAINED_GLASS:15)
Block(-5,59,0,STAINED_GLASS:15)
Block(-5,59,1,STAINED_GLASS:15)
Block(-5,59,2,STAINED_GLASS:15)
Block(-5,59,3,STAINED_GLASS:15)
Block(-5,59,4,STAINED_GLASS_PANE:15)
Block(-5,59,5,STAINED_GLASS_PANE:15)
Block(-5,59,7,STAINED_GLASS_PANE:15)
Block(-5,59,8,STAINED_GLASS:15)
Block(-5,60,-4,STAINED_GLASS:15)
Block(-5,60,-3,STAINED_GLASS:15)
Block(-5,60,-2,STAINED_GLASS:15)
Block(-5,60,-1,STAINED_GLASS:15)
Block(-5,60,0,STAINED_GLASS:15)
Block(-5,60,1,STAINED_GLASS:15)
Block(-5,60,2,STAINED_GLASS:15)
Block(-5,60,3,STAINED_GLASS:15)
Block(-5,60,4,STAINED_GLASS:15)
Block(-5,60,5,STAINED_GLASS:15)
Block(-5,60,6,STAINED_GLASS:15)
Block(-5,60,7,STAINED_GLASS:15)
Block(-5,60,8,STAINED_GLASS:15)
Block(-5,61,-4,STAINED_GLASS:15)
Block(-5,61,-3,STAINED_GLASS:15)
Block(-5,61,-2,STAINED_GLASS:15)
Block(-5,61,-1,STAINED_GLASS:15)
Block(-5,61,0,STAINED_GLASS:15)
Block(-5,61,1,STAINED_GLASS:15)
Block(-5,61,2,STAINED_GLASS:15)
Block(-5,61,3,CONCRETE:8)
Block(-5,61,4,CONCRETE:8)
Block(-5,61,5,CONCRETE:8)
Block(-5,61,6,CONCRETE:8)
Block(-5,61,7,CONCRETE:8)
Block(-5,61,8,CONCRETE:8)
Block(-5,62,-4,STAINED_GLASS:15)
Block(-5,62,-3,STAINED_GLASS:15)
Block(-5,62,-2,STAINED_GLASS:15)
Block(-5,62,-1,STAINED_GLASS:15)
Block(-5,62,0,STAINED_GLASS:15)
Block(-5,62,1,STAINED_GLASS:15)
