
#######################################################################
# +-----------------------------------------------------------------+ #
# |                            BO4 object                           | #
# +-----------------------------------------------------------------+ #
#######################################################################

Author: NLBlackEagle

Description: No description given

SettingsMode: WriteDisable


#######################################################################
# +-----------------------------------------------------------------+ #
# |                          Main settings                          | #
# +-----------------------------------------------------------------+ #
#######################################################################

Frequency: 0

SpawnHeight: highestBlock

UseCenterForHighestBlock: true

##############################
# Height Limits for the BO4. #
##############################

MinHeight: 0

MaxHeight: 255

InheritBO3: 

InheritBO3Rotation: NORTH

OverrideChildSettings: true

OverrideParentHeight: false

CanOverride: true

BranchFrequency: 0

BranchFrequencyGroup: 

MustBeBelowOther: false

MustBeInside: 

CannotBeInside: 

ReplacesBO3: L4-M-CrossC0R0, L4-M-CrossC0R1, L4-M-CrossC0R2, L4-M-CrossC0R3, L4-M-CrossC1R0, L4-M-CrossC1R1, L4-M-CrossC1R2, L4-M-CrossC1R3, L4-M-CrossC2R0, L4-M-CrossC2R1, L4-M-CrossC2R2, L4-M-CrossC2R3, L4-M-CrossC3R0, L4-M-CrossC3R1, L4-M-CrossC3R2, L4-M-CrossC3R3, L4-M-Straigth-START_01-C0R0, L4-M-Straigth-START_01-C0R1, L4-M-Straigth-START_01-C1R0, L4-M-Straigth-START_01-C1R1, L4-M-Straigth-START_01-C2R0, L4-M-Straigth-START_01-C2R1, L4-M-Straigth-START_01-C3R0, L4-M-Straigth-START_01-C3R1, L4-M-Straigth-3CC0R0, L4-M-Straigth-3CC0R1, L4-M-Straigth-3CC0R2, L4-M-Straigth-3CC1R0, L4-M-Straigth-3CC1R1, L4-M-Straigth-3CC1R2, L4-M-Straigth-3CC2R0, L4-M-Straigth-3CC2R1, L4-M-Straigth-3CC2R2, L4-M-Straigth-3CC3R0, L4-M-Straigth-3CC3R1, L4-M-Straigth-3CC3R2, L4-M-Cross, skyscraper_2x2_01, skyscraper_2x2_02, skyscraper_2x2_03, skyscraper_2x2_04, skyscraper_2x2_05, skyscraper_3x3_01, skyscraper_3x3_02, skyscraper_3x3_03, L3-M-Straigth-2CC0R0, L3-M-Straigth-2CC0R1, L3-M-Straigth-2CC1R0, L3-M-Straigth-2CC1R1, L3-M-Straigth-2CC2R0, L3-M-Straigth-2CC2R1, L3-M-Straigth-2CC3R0, L3-M-Straigth-2CC3R1, L3-M-Straigth-3CC0R0, L3-M-Straigth-3CC0R1, L3-M-Straigth-3CC0R2, L3-M-Straigth-3CC1R0, L3-M-Straigth-3CC1R1, L3-M-Straigth-3CC1R2, L3-M-Straigth-3CC2R0, L3-M-Straigth-3CC2R1, L3-M-Straigth-3CC2R2, L3-M-Straigth-3CC3R0, L3-M-Straigth-3CC3R1, L3-M-Straigth-3CC3R2L4-M-CrossC0R0, L4-M-CrossC0R1, L4-M-CrossC0R2, L4-M-CrossC0R3, L4-M-CrossC1R0, L4-M-CrossC1R1, L4-M-CrossC1R2, L4-M-CrossC1R3, L4-M-CrossC2R0, L4-M-CrossC2R1, L4-M-CrossC2R2, L4-M-CrossC2R3, L4-M-CrossC3R0, L4-M-CrossC3R1, L4-M-CrossC3R2, L4-M-CrossC3R3, L4-M-Straigth-START_01-C0R0, L4-M-Straigth-START_01-C0R1, L4-M-Straigth-START_01-C1R0, L4-M-Straigth-START_01-C1R1, L4-M-Straigth-START_01-C2R0, L4-M-Straigth-START_01-C2R1, L4-M-Straigth-START_01-C3R0, L4-M-Straigth-START_01-C3R1, L4-M-Straigth-3CC0R0, L4-M-Straigth-3CC0R1, L4-M-Straigth-3CC0R2, L4-M-Straigth-3CC1R0, L4-M-Straigth-3CC1R1, L4-M-Straigth-3CC1R2, L4-M-Straigth-3CC2R0, L4-M-Straigth-3CC2R1, L4-M-Straigth-3CC2R2, L4-M-Straigth-3CC3R0, L4-M-Straigth-3CC3R1, L4-M-Straigth-3CC3R2, L4-M-Cross, skyscraper_2x2_01, skyscraper_2x2_02, skyscraper_2x2_03, skyscraper_2x2_04, skyscraper_2x2_05, skyscraper_3x3_01, skyscraper_3x3_02, skyscraper_3x3_03

MustBeInsideWorldBorders: false

CanSpawnOnWater: true

SpawnOnWaterOnly: false

SpawnUnderWater: false

SpawnAtWaterLevel: false

HeightOffset: 0

RemoveAir: false

ReplaceAbove: 

ReplaceBelow: 

ReplaceWithBiomeBlocks: true

ReplaceWithSurfaceBlock: GRASS

ReplaceWithGroundBlock: DIRT

ReplaceWithStoneBlock: STONE

SmoothRadius: 0

SmoothHeightOffset: 0

SmoothStartTop: false

SmoothStartWood: false

SmoothingSurfaceBlock: 

SmoothingGroundBlock: 

BO3Group: 

IsSpawnPoint: false

DoReplaceBlocks: true


#######################################################################
# +-----------------------------------------------------------------+ #
# |                              Blocks                             | #
# +-----------------------------------------------------------------+ #
#######################################################################

Block(-8,0,-7,CONCRETE:7)
Block(-8,0,-6,CONCRETE:7)
Block(-8,0,-5,CONCRETE:7)
Block(-8,0,-4,CONCRETE:7)
Block(-8,0,-3,CONCRETE:7)
Block(-8,0,-2,CONCRETE:7)
Block(-8,0,-1,CONCRETE:7)
Block(-8,0,0,CONCRETE:7)
Block(-8,0,1,CONCRETE:7)
Block(-8,0,2,CONCRETE:7)
Block(-8,0,3,CONCRETE:7)
Block(-8,0,4,CONCRETE:7)
Block(-8,0,5,CONCRETE:7)
Block(-8,0,6,CONCRETE:7)
Block(-8,0,7,CONCRETE:7)
Block(-8,0,8,CONCRETE:7)
Block(-8,1,-7,CONCRETE:7)
Block(-8,1,-6,CONCRETE:7)
Block(-8,1,-5,CONCRETE:7)
Block(-8,1,-4,CONCRETE:7)
Block(-8,1,-3,CONCRETE:7)
Block(-8,1,-2,CONCRETE:7)
Block(-8,1,-1,CONCRETE:7)
Block(-8,1,0,CONCRETE:7)
Block(-8,1,1,CONCRETE:7)
Block(-8,1,2,CONCRETE:7)
Block(-8,1,3,CONCRETE:7)
Block(-8,1,4,CONCRETE:7)
Block(-8,1,5,CONCRETE:7)
Block(-8,1,6,CONCRETE:7)
Block(-8,1,7,CONCRETE:7)
Block(-8,1,8,CONCRETE:7)
Block(-8,2,-7,CONCRETE:7)
Block(-8,2,-6,CONCRETE:7)
Block(-8,2,-5,CONCRETE:7)
Block(-8,2,-4,CONCRETE:7)
Block(-8,2,-3,CONCRETE:7)
Block(-8,2,-2,CONCRETE:7)
Block(-8,2,-1,CONCRETE:7)
Block(-8,2,0,CONCRETE:7)
Block(-8,2,1,CONCRETE:7)
Block(-8,2,2,CONCRETE:7)
Block(-8,2,3,CONCRETE:7)
Block(-8,2,4,CONCRETE:7)
Block(-8,2,5,CONCRETE:7)
Block(-8,2,6,CONCRETE:7)
Block(-8,2,7,CONCRETE:7)
Block(-8,2,8,CONCRETE:7)
Block(-8,3,-7,CONCRETE:7)
Block(-8,3,-6,CONCRETE:7)
Block(-8,3,-5,CONCRETE:7)
Block(-8,3,-4,CONCRETE:7)
Block(-8,3,-3,CONCRETE:7)
Block(-8,3,-2,CONCRETE:7)
Block(-8,3,-1,CONCRETE:7)
Block(-8,3,0,CONCRETE:7)
Block(-8,3,1,CONCRETE:7)
Block(-8,3,2,CONCRETE:7)
Block(-8,3,3,CONCRETE:7)
Block(-8,3,4,CONCRETE:7)
Block(-8,3,5,CONCRETE:7)
Block(-8,3,6,CONCRETE:7)
Block(-8,3,7,CONCRETE:7)
Block(-8,3,8,CONCRETE:7)
Block(-8,4,-7,CONCRETE:7)
Block(-8,4,-6,CONCRETE:7)
Block(-8,4,-5,CONCRETE:7)
Block(-8,4,-4,CONCRETE:7)
Block(-8,4,-3,CONCRETE:7)
Block(-8,4,-2,CONCRETE:7)
Block(-8,4,-1,CONCRETE:7)
Block(-8,4,0,CONCRETE:7)
Block(-8,4,1,CONCRETE:7)
Block(-8,4,2,CONCRETE:7)
Block(-8,4,3,CONCRETE:7)
Block(-8,4,4,CONCRETE:7)
Block(-8,4,5,CONCRETE:7)
Block(-8,4,6,CONCRETE:7)
Block(-8,4,7,CONCRETE:7)
Block(-8,4,8,CONCRETE:7)
Block(-8,5,-7,CONCRETE:7)
Block(-8,5,-6,CONCRETE:7)
Block(-8,5,-5,CONCRETE:7)
Block(-8,5,-4,CONCRETE:7)
Block(-8,5,-3,CONCRETE:7)
Block(-8,5,-2,CONCRETE:7)
Block(-8,5,-1,CONCRETE:7)
Block(-8,5,0,CONCRETE:7)
Block(-8,5,1,CONCRETE:7)
Block(-8,5,2,CONCRETE:7)
Block(-8,5,3,CONCRETE:7)
Block(-8,5,4,CONCRETE:7)
Block(-8,5,5,CONCRETE:7)
Block(-8,5,6,CONCRETE:7)
Block(-8,5,7,CONCRETE:7)
Block(-8,5,8,CONCRETE:7)
Block(-8,6,-7,CONCRETE:7)
Block(-8,6,-6,CONCRETE:7)
Block(-8,6,-5,CONCRETE:7)
Block(-8,6,-4,CONCRETE:7)
Block(-8,6,-3,CONCRETE:7)
Block(-8,6,-2,CONCRETE:7)
Block(-8,6,-1,CONCRETE:7)
Block(-8,6,0,CONCRETE:7)
Block(-8,6,1,CONCRETE:7)
Block(-8,6,2,CONCRETE:7)
Block(-8,6,3,CONCRETE:7)
Block(-8,6,4,CONCRETE:7)
Block(-8,6,5,CONCRETE:7)
Block(-8,6,6,CONCRETE:7)
Block(-8,6,7,CONCRETE:7)
Block(-8,6,8,CONCRETE:7)
Block(-8,7,-7,CONCRETE:7)
Block(-8,7,-6,CONCRETE:7)
Block(-8,7,-5,CONCRETE:7)
Block(-8,7,-4,CONCRETE:7)
Block(-8,7,-3,CONCRETE:7)
Block(-8,7,-2,CONCRETE:7)
Block(-8,7,-1,CONCRETE:7)
Block(-8,7,0,CONCRETE:7)
Block(-8,7,1,CONCRETE:7)
Block(-8,7,2,CONCRETE:7)
Block(-8,7,3,CONCRETE:7)
Block(-8,7,4,CONCRETE:7)
Block(-8,7,5,CONCRETE:7)
Block(-8,7,6,CONCRETE:7)
Block(-8,7,7,CONCRETE:7)
Block(-8,7,8,CONCRETE:7)
Block(-8,8,-7,CONCRETE:7)
Block(-8,8,-6,CONCRETE:7)
Block(-8,8,-5,CONCRETE:7)
Block(-8,8,-4,CONCRETE:7)
Block(-8,8,-3,CONCRETE:7)
Block(-8,8,-2,CONCRETE:7)
Block(-8,8,-1,CONCRETE:7)
Block(-8,8,0,CONCRETE:7)
Block(-8,8,1,CONCRETE:7)
Block(-8,8,2,CONCRETE:7)
Block(-8,8,3,CONCRETE:7)
Block(-8,8,4,CONCRETE:7)
Block(-8,8,5,CONCRETE:7)
Block(-8,8,6,CONCRETE:7)
Block(-8,8,7,CONCRETE:7)
Block(-8,8,8,CONCRETE:7)
Block(-8,9,-7,CONCRETE:7)
Block(-8,9,-6,CONCRETE:7)
Block(-8,9,-5,CONCRETE:7)
Block(-8,9,-4,CONCRETE:7)
Block(-8,9,-3,CONCRETE:7)
Block(-8,9,-2,CONCRETE:7)
Block(-8,9,-1,CONCRETE:7)
Block(-8,9,0,CONCRETE:7)
Block(-8,9,1,CONCRETE:7)
Block(-8,9,2,CONCRETE:7)
Block(-8,9,3,CONCRETE:7)
Block(-8,9,4,CONCRETE:7)
Block(-8,9,5,CONCRETE:7)
Block(-8,9,6,CONCRETE:7)
Block(-8,9,7,CONCRETE:7)
Block(-8,9,8,CONCRETE:7)
Block(-8,10,-7,CONCRETE:7)
Block(-8,10,-6,CONCRETE:7)
Block(-8,10,-5,CONCRETE:7)
Block(-8,10,-4,CONCRETE:7)
Block(-8,10,-3,CONCRETE:7)
Block(-8,10,-2,CONCRETE:7)
Block(-8,10,-1,CONCRETE:7)
Block(-8,10,0,CONCRETE:7)
Block(-8,10,1,CONCRETE:7)
Block(-8,10,2,CONCRETE:7)
Block(-8,10,3,CONCRETE:7)
Block(-8,10,4,CONCRETE:7)
Block(-8,10,5,CONCRETE:7)
Block(-8,10,6,CONCRETE:7)
Block(-8,10,7,CONCRETE:7)
Block(-8,10,8,CONCRETE:7)
Block(-8,11,-7,CONCRETE:7)
Block(-8,11,-6,CONCRETE:7)
Block(-8,11,-5,CONCRETE:7)
Block(-8,11,-4,CONCRETE:7)
Block(-8,11,-3,CONCRETE:7)
Block(-8,11,-2,CONCRETE:7)
Block(-8,11,-1,CONCRETE:7)
Block(-8,11,0,CONCRETE:7)
Block(-8,11,1,CONCRETE:7)
Block(-8,11,2,CONCRETE:7)
Block(-8,11,3,CONCRETE:7)
Block(-8,11,4,CONCRETE:7)
Block(-8,11,5,CONCRETE:7)
Block(-8,11,6,CONCRETE:7)
Block(-8,11,7,CONCRETE:7)
Block(-8,11,8,CONCRETE:7)
Block(-8,12,-7,CONCRETE:7)
Block(-8,12,-6,CONCRETE:7)
Block(-8,12,-5,CONCRETE:7)
Block(-8,12,-4,CONCRETE:7)
Block(-8,12,-3,CONCRETE:7)
Block(-8,12,-2,CONCRETE:7)
Block(-8,12,-1,CONCRETE:7)
Block(-8,12,0,CONCRETE:7)
Block(-8,12,1,CONCRETE:7)
Block(-8,12,2,CONCRETE:7)
Block(-8,12,3,CONCRETE:7)
Block(-8,12,4,CONCRETE:7)
Block(-8,12,5,CONCRETE:7)
Block(-8,12,6,CONCRETE:7)
Block(-8,12,7,CONCRETE:7)
Block(-8,12,8,CONCRETE:7)
Block(-8,13,-7,CONCRETE:7)
Block(-8,13,-6,CONCRETE:7)
Block(-8,13,-5,CONCRETE:7)
Block(-8,13,-4,CONCRETE:7)
Block(-8,13,-3,CONCRETE:7)
Block(-8,13,-2,CONCRETE:7)
Block(-8,13,-1,CONCRETE:7)
Block(-8,13,0,CONCRETE:7)
Block(-8,13,1,CONCRETE:7)
Block(-8,13,2,CONCRETE:7)
Block(-8,13,3,CONCRETE:7)
Block(-8,13,4,CONCRETE:7)
Block(-8,13,5,CONCRETE:7)
Block(-8,13,6,CONCRETE:7)
Block(-8,13,7,CONCRETE:7)
Block(-8,13,8,CONCRETE:7)
Block(-8,14,-7,CONCRETE:7)
Block(-8,14,-6,CONCRETE:7)
Block(-8,14,-5,CONCRETE:7)
Block(-8,14,-4,CONCRETE:7)
Block(-8,14,-3,CONCRETE:7)
Block(-8,14,-2,CONCRETE:7)
Block(-8,14,-1,CONCRETE:7)
Block(-8,14,0,CONCRETE:7)
Block(-8,14,1,CONCRETE:7)
Block(-8,14,2,CONCRETE:7)
Block(-8,14,3,CONCRETE:7)
Block(-8,14,4,CONCRETE:7)
Block(-8,14,5,CONCRETE:7)
Block(-8,14,6,CONCRETE:7)
Block(-8,14,7,CONCRETE:7)
Block(-8,14,8,CONCRETE:7)
Block(-8,15,-7,CONCRETE:7)
Block(-8,15,-6,CONCRETE:7)
Block(-8,15,-5,CONCRETE:7)
Block(-8,15,-4,CONCRETE:7)
Block(-8,15,-3,CONCRETE:7)
Block(-8,15,-2,CONCRETE:7)
Block(-8,15,-1,CONCRETE:7)
Block(-8,15,0,CONCRETE:7)
Block(-8,15,1,CONCRETE:7)
Block(-8,15,2,CONCRETE:7)
Block(-8,15,3,CONCRETE:7)
Block(-8,15,4,CONCRETE:7)
Block(-8,15,5,CONCRETE:7)
Block(-8,15,6,CONCRETE:7)
Block(-8,15,7,CONCRETE:7)
Block(-8,15,8,CONCRETE:7)
Block(-8,16,-7,CONCRETE:7)
Block(-8,16,-6,CONCRETE:7)
Block(-8,16,-5,CONCRETE:7)
Block(-8,16,-4,CONCRETE:7)
Block(-8,16,-3,CONCRETE:7)
Block(-8,16,-2,CONCRETE:7)
Block(-8,16,-1,CONCRETE:7)
Block(-8,16,0,CONCRETE:7)
Block(-8,16,1,CONCRETE:7)
Block(-8,16,2,CONCRETE:7)
Block(-8,16,3,CONCRETE:7)
Block(-8,16,4,CONCRETE:7)
Block(-8,16,5,CONCRETE:7)
Block(-8,16,6,CONCRETE:7)
Block(-8,16,7,CONCRETE:7)
Block(-8,16,8,CONCRETE:7)
Block(-8,17,-7,DOUBLE_STEP:0)
Block(-8,17,-6,DOUBLE_STEP:0)
Block(-8,17,-5,DOUBLE_STEP:0)
Block(-8,17,-4,DOUBLE_STEP:0)
Block(-8,17,-3,DOUBLE_STEP:0)
Block(-8,17,-2,DOUBLE_STEP:0)
Block(-8,17,-1,DOUBLE_STEP:0)
Block(-8,17,0,DOUBLE_STEP:0)
Block(-8,17,1,DOUBLE_STEP:0)
Block(-8,17,2,DOUBLE_STEP:0)
Block(-8,17,3,DOUBLE_STEP:0)
Block(-8,17,4,DOUBLE_STEP:0)
Block(-8,17,5,DOUBLE_STEP:0)
Block(-8,17,6,DOUBLE_STEP:0)
Block(-8,17,7,DOUBLE_STEP:0)
Block(-8,17,8,DOUBLE_STEP:0)
Block(-8,18,-7,QUARTZ_STAIRS:4)
Block(-8,18,-6,QUARTZ_STAIRS:4)
Block(-8,18,-5,QUARTZ_STAIRS:4)
Block(-8,18,-4,QUARTZ_STAIRS:4)
Block(-8,18,-2,VINE:8)
Block(-8,18,-1,VINE:8)
Block(-8,18,0,VINE:8)
Block(-8,18,1,VINE:8)
Block(-8,18,2,VINE:8)
Block(-8,18,3,VINE:8)
Block(-8,18,5,QUARTZ_STAIRS:4)
Block(-8,18,6,QUARTZ_STAIRS:4)
Block(-8,18,7,QUARTZ_STAIRS:4)
Block(-8,18,8,QUARTZ_STAIRS:4)
Block(-8,19,-7,STEP:0)
Block(-8,19,-6,STEP:0)
Block(-8,19,-5,STEP:0)
Block(-8,19,-4,STEP:0)
Block(-8,19,-2,VINE:8)
Block(-8,19,3,VINE:8)
Block(-8,19,5,STEP:0)
Block(-8,19,6,STEP:0)
Block(-8,19,7,STEP:0)
Block(-8,19,8,STEP:0)
Block(-7,0,-7,CONCRETE:7)
Block(-7,0,-6,CONCRETE:7)
Block(-7,0,-5,CONCRETE:7)
Block(-7,0,-4,CONCRETE:7)
Block(-7,0,-3,CONCRETE:7)
Block(-7,0,-2,CONCRETE:7)
Block(-7,0,-1,CONCRETE:7)
Block(-7,0,0,CONCRETE:7)
Block(-7,0,1,CONCRETE:7)
Block(-7,0,2,CONCRETE:7)
Block(-7,0,3,CONCRETE:7)
Block(-7,0,4,CONCRETE:7)
Block(-7,0,5,CONCRETE:7)
Block(-7,0,6,CONCRETE:7)
Block(-7,0,7,CONCRETE:7)
Block(-7,0,8,CONCRETE:7)
Block(-7,1,-7,CONCRETE:7)
Block(-7,1,-6,CONCRETE:7)
Block(-7,1,-5,CONCRETE:7)
Block(-7,1,-4,CONCRETE:7)
Block(-7,1,-3,CONCRETE:7)
Block(-7,1,-2,CONCRETE:7)
Block(-7,1,-1,CONCRETE:7)
Block(-7,1,0,CONCRETE:7)
Block(-7,1,1,CONCRETE:7)
Block(-7,1,2,CONCRETE:7)
Block(-7,1,3,CONCRETE:7)
Block(-7,1,4,CONCRETE:7)
Block(-7,1,5,CONCRETE:7)
Block(-7,1,6,CONCRETE:7)
Block(-7,1,7,CONCRETE:7)
Block(-7,1,8,CONCRETE:7)
Block(-7,2,-7,CONCRETE:7)
Block(-7,2,-6,CONCRETE:7)
Block(-7,2,-5,CONCRETE:7)
Block(-7,2,-4,CONCRETE:7)
Block(-7,2,-3,CONCRETE:7)
Block(-7,2,-2,CONCRETE:7)
Block(-7,2,-1,CONCRETE:7)
Block(-7,2,0,CONCRETE:7)
Block(-7,2,1,CONCRETE:7)
Block(-7,2,2,CONCRETE:7)
Block(-7,2,3,CONCRETE:7)
Block(-7,2,4,CONCRETE:7)
Block(-7,2,5,CONCRETE:7)
Block(-7,2,6,CONCRETE:7)
Block(-7,2,7,CONCRETE:7)
Block(-7,2,8,CONCRETE:7)
Block(-7,3,-7,CONCRETE:7)
Block(-7,3,-6,CONCRETE:7)
Block(-7,3,-5,CONCRETE:7)
Block(-7,3,-4,CONCRETE:7)
Block(-7,3,-3,CONCRETE:7)
Block(-7,3,-2,CONCRETE:7)
Block(-7,3,-1,CONCRETE:7)
Block(-7,3,0,CONCRETE:7)
Block(-7,3,1,CONCRETE:7)
Block(-7,3,2,CONCRETE:7)
Block(-7,3,3,CONCRETE:7)
Block(-7,3,4,CONCRETE:7)
Block(-7,3,5,CONCRETE:7)
Block(-7,3,6,CONCRETE:7)
Block(-7,3,7,CONCRETE:7)
Block(-7,3,8,CONCRETE:7)
Block(-7,4,-7,CONCRETE:7)
Block(-7,4,-6,CONCRETE:7)
Block(-7,4,-5,CONCRETE:7)
Block(-7,4,-4,CONCRETE:7)
Block(-7,4,-3,CONCRETE:7)
Block(-7,4,-2,CONCRETE:7)
Block(-7,4,-1,CONCRETE:7)
Block(-7,4,0,CONCRETE:7)
Block(-7,4,1,CONCRETE:7)
Block(-7,4,2,CONCRETE:7)
Block(-7,4,3,CONCRETE:7)
Block(-7,4,4,CONCRETE:7)
Block(-7,4,5,CONCRETE:7)
Block(-7,4,6,CONCRETE:7)
Block(-7,4,7,CONCRETE:7)
Block(-7,4,8,CONCRETE:7)
Block(-7,5,-7,CONCRETE:7)
Block(-7,5,-6,CONCRETE:7)
Block(-7,5,-5,CONCRETE:7)
Block(-7,5,-4,CONCRETE:7)
Block(-7,5,-3,CONCRETE:7)
Block(-7,5,-2,CONCRETE:7)
Block(-7,5,-1,CONCRETE:7)
Block(-7,5,0,CONCRETE:7)
Block(-7,5,1,CONCRETE:7)
Block(-7,5,2,CONCRETE:7)
Block(-7,5,3,CONCRETE:7)
Block(-7,5,4,CONCRETE:7)
Block(-7,5,5,CONCRETE:7)
Block(-7,5,6,CONCRETE:7)
Block(-7,5,7,CONCRETE:7)
Block(-7,5,8,CONCRETE:7)
Block(-7,6,-7,CONCRETE:7)
Block(-7,6,-6,CONCRETE:7)
Block(-7,6,-5,CONCRETE:7)
Block(-7,6,-4,CONCRETE:7)
Block(-7,6,-3,CONCRETE:7)
Block(-7,6,-2,CONCRETE:7)
Block(-7,6,-1,CONCRETE:7)
Block(-7,6,0,CONCRETE:7)
Block(-7,6,1,CONCRETE:7)
Block(-7,6,2,CONCRETE:7)
Block(-7,6,3,CONCRETE:7)
Block(-7,6,4,CONCRETE:7)
Block(-7,6,5,CONCRETE:7)
Block(-7,6,6,CONCRETE:7)
Block(-7,6,7,CONCRETE:7)
Block(-7,6,8,CONCRETE:7)
Block(-7,7,-7,CONCRETE:7)
Block(-7,7,-6,CONCRETE:7)
Block(-7,7,-5,CONCRETE:7)
Block(-7,7,-4,CONCRETE:7)
Block(-7,7,-3,CONCRETE:7)
Block(-7,7,-2,CONCRETE:7)
Block(-7,7,-1,CONCRETE:7)
Block(-7,7,0,CONCRETE:7)
Block(-7,7,1,CONCRETE:7)
Block(-7,7,2,CONCRETE:7)
Block(-7,7,3,CONCRETE:7)
Block(-7,7,4,CONCRETE:7)
Block(-7,7,5,CONCRETE:7)
Block(-7,7,6,CONCRETE:7)
Block(-7,7,7,CONCRETE:7)
Block(-7,7,8,CONCRETE:7)
Block(-7,8,-7,CONCRETE:7)
Block(-7,8,-6,CONCRETE:7)
Block(-7,8,-5,CONCRETE:7)
Block(-7,8,-4,CONCRETE:7)
Block(-7,8,-3,CONCRETE:7)
Block(-7,8,-2,CONCRETE:7)
Block(-7,8,-1,CONCRETE:7)
Block(-7,8,0,CONCRETE:7)
Block(-7,8,1,CONCRETE:7)
Block(-7,8,2,CONCRETE:7)
Block(-7,8,3,CONCRETE:7)
Block(-7,8,4,CONCRETE:7)
Block(-7,8,5,CONCRETE:7)
Block(-7,8,6,CONCRETE:7)
Block(-7,8,7,CONCRETE:7)
Block(-7,8,8,CONCRETE:7)
Block(-7,9,-7,CONCRETE:7)
Block(-7,9,-6,CONCRETE:7)
Block(-7,9,-5,CONCRETE:7)
Block(-7,9,-4,CONCRETE:7)
Block(-7,9,-3,CONCRETE:7)
Block(-7,9,-2,CONCRETE:7)
Block(-7,9,-1,CONCRETE:7)
Block(-7,9,0,CONCRETE:7)
Block(-7,9,1,CONCRETE:7)
Block(-7,9,2,CONCRETE:7)
Block(-7,9,3,CONCRETE:7)
Block(-7,9,4,CONCRETE:7)
Block(-7,9,5,CONCRETE:7)
Block(-7,9,6,CONCRETE:7)
Block(-7,9,7,CONCRETE:7)
Block(-7,9,8,CONCRETE:7)
Block(-7,10,-7,CONCRETE:7)
Block(-7,10,-6,CONCRETE:7)
Block(-7,10,-5,CONCRETE:7)
Block(-7,10,-4,CONCRETE:7)
Block(-7,10,-3,CONCRETE:7)
Block(-7,10,-2,CONCRETE:7)
Block(-7,10,-1,CONCRETE:7)
Block(-7,10,0,CONCRETE:7)
Block(-7,10,1,CONCRETE:7)
Block(-7,10,2,CONCRETE:7)
Block(-7,10,3,CONCRETE:7)
Block(-7,10,4,CONCRETE:7)
Block(-7,10,5,CONCRETE:7)
Block(-7,10,6,CONCRETE:7)
Block(-7,10,7,CONCRETE:7)
Block(-7,10,8,CONCRETE:7)
Block(-7,11,-7,CONCRETE:7)
Block(-7,11,-6,CONCRETE:7)
Block(-7,11,-5,CONCRETE:7)
Block(-7,11,-4,CONCRETE:7)
Block(-7,11,-3,CONCRETE:7)
Block(-7,11,-2,CONCRETE:7)
Block(-7,11,-1,CONCRETE:7)
Block(-7,11,0,CONCRETE:7)
Block(-7,11,1,CONCRETE:7)
Block(-7,11,2,CONCRETE:7)
Block(-7,11,3,CONCRETE:7)
Block(-7,11,4,CONCRETE:7)
Block(-7,11,5,CONCRETE:7)
Block(-7,11,6,CONCRETE:7)
Block(-7,11,7,CONCRETE:7)
Block(-7,11,8,CONCRETE:7)
Block(-7,12,-7,CONCRETE:7)
Block(-7,12,-6,CONCRETE:7)
Block(-7,12,-5,CONCRETE:7)
Block(-7,12,-4,CONCRETE:7)
Block(-7,12,-3,CONCRETE:7)
Block(-7,12,-2,CONCRETE:7)
Block(-7,12,-1,CONCRETE:7)
Block(-7,12,0,CONCRETE:7)
Block(-7,12,1,CONCRETE:7)
Block(-7,12,2,CONCRETE:7)
Block(-7,12,3,CONCRETE:7)
Block(-7,12,4,CONCRETE:7)
Block(-7,12,5,CONCRETE:7)
Block(-7,12,6,CONCRETE:7)
Block(-7,12,7,CONCRETE:7)
Block(-7,12,8,CONCRETE:7)
Block(-7,13,-7,CONCRETE:7)
Block(-7,13,-6,CONCRETE:7)
Block(-7,13,-5,CONCRETE:7)
Block(-7,13,-4,CONCRETE:7)
Block(-7,13,-3,CONCRETE:7)
Block(-7,13,-2,CONCRETE:7)
Block(-7,13,-1,CONCRETE:7)
Block(-7,13,0,CONCRETE:7)
Block(-7,13,1,CONCRETE:7)
Block(-7,13,2,CONCRETE:7)
Block(-7,13,3,CONCRETE:7)
Block(-7,13,4,CONCRETE:7)
Block(-7,13,5,CONCRETE:7)
Block(-7,13,6,CONCRETE:7)
Block(-7,13,7,CONCRETE:7)
Block(-7,13,8,CONCRETE:7)
Block(-7,14,-7,CONCRETE:7)
Block(-7,14,-6,CONCRETE:7)
Block(-7,14,-5,CONCRETE:7)
Block(-7,14,-4,CONCRETE:7)
Block(-7,14,-3,CONCRETE:7)
Block(-7,14,-2,CONCRETE:7)
Block(-7,14,-1,CONCRETE:7)
Block(-7,14,0,CONCRETE:7)
Block(-7,14,1,CONCRETE:7)
Block(-7,14,2,CONCRETE:7)
Block(-7,14,3,CONCRETE:7)
Block(-7,14,4,CONCRETE:7)
Block(-7,14,5,CONCRETE:7)
Block(-7,14,6,CONCRETE:7)
Block(-7,14,7,CONCRETE:7)
Block(-7,14,8,CONCRETE:7)
Block(-7,15,-7,CONCRETE:7)
Block(-7,15,-6,CONCRETE:7)
Block(-7,15,-5,CONCRETE:7)
Block(-7,15,-4,CONCRETE:7)
Block(-7,15,-3,CONCRETE:7)
Block(-7,15,-2,CONCRETE:7)
Block(-7,15,-1,CONCRETE:7)
Block(-7,15,0,CONCRETE:7)
Block(-7,15,1,CONCRETE:7)
Block(-7,15,2,CONCRETE:7)
Block(-7,15,3,CONCRETE:7)
Block(-7,15,4,CONCRETE:7)
Block(-7,15,5,CONCRETE:7)
Block(-7,15,6,CONCRETE:7)
Block(-7,15,7,CONCRETE:7)
Block(-7,15,8,CONCRETE:7)
Block(-7,16,-7,CONCRETE:7)
Block(-7,16,-6,CONCRETE:7)
Block(-7,16,-5,CONCRETE:7)
Block(-7,16,-4,CONCRETE:7)
Block(-7,16,-3,CONCRETE:7)
Block(-7,16,-2,CONCRETE:7)
Block(-7,16,-1,CONCRETE:7)
Block(-7,16,0,CONCRETE:7)
Block(-7,16,1,CONCRETE:7)
Block(-7,16,2,CONCRETE:7)
Block(-7,16,3,CONCRETE:7)
Block(-7,16,4,CONCRETE:7)
Block(-7,16,5,CONCRETE:7)
Block(-7,16,6,CONCRETE:7)
Block(-7,16,7,CONCRETE:7)
Block(-7,16,8,CONCRETE:7)
Block(-7,17,-7,DOUBLE_STEP:0)
Block(-7,17,-6,DOUBLE_STEP:0)
Block(-7,17,-5,DOUBLE_STEP:0)
Block(-7,17,-4,DOUBLE_STEP:0)
Block(-7,17,-3,DOUBLE_STEP:0)
Block(-7,17,-2,DOUBLE_STEP:0)
Block(-7,17,-1,DOUBLE_STEP:0)
Block(-7,17,0,DOUBLE_STEP:0)
Block(-7,17,1,DOUBLE_STEP:0)
Block(-7,17,2,DOUBLE_STEP:0)
Block(-7,17,3,DOUBLE_STEP:0)
Block(-7,17,4,DOUBLE_STEP:0)
Block(-7,17,5,DOUBLE_STEP:0)
Block(-7,17,6,DOUBLE_STEP:0)
Block(-7,17,7,DOUBLE_STEP:0)
Block(-7,17,8,DOUBLE_STEP:0)
Block(-7,18,-7,GRASS:0)
Block(-7,18,-6,GRASS:0)
Block(-7,18,-5,GRASS:0)
Block(-7,18,-4,QUARTZ_STAIRS:7)
Block(-7,18,-3,VINE:1)
Block(-7,18,-2,LOG:3)
Block(-7,18,-1,QUARTZ_STAIRS:3)
Block(-7,18,0,QUARTZ_STAIRS:1)
Block(-7,18,1,QUARTZ_STAIRS:1)
Block(-7,18,2,QUARTZ_STAIRS:2)
Block(-7,18,3,LOG:3)
Block(-7,18,4,VINE:4)
Block(-7,18,5,QUARTZ_STAIRS:6)
Block(-7,18,6,GRASS:0)
Block(-7,18,7,GRASS:0)
Block(-7,18,8,GRASS:0)
Block(-7,19,-7,LEAVES:7)
Block(-7,19,-6,LEAVES:7)
Block(-7,19,-5,LEAVES:7)
Block(-7,19,-4,STEP:0)
Block(-7,19,-3,VINE:1)
Block(-7,19,-2,LEAVES:15)
Block(-7,19,-1,VINE:4)
Block(-7,19,2,VINE:1)
Block(-7,19,3,LEAVES:15)
Block(-7,19,4,VINE:4)
Block(-7,19,5,STEP:0)
Block(-7,19,6,LEAVES:15)
Block(-7,19,7,LEAVES:15)
Block(-7,19,8,LEAVES:15)
Block(-7,20,-6,LEAVES:7)
Block(-7,20,-5,LEAVES:7)
Block(-7,20,7,LEAVES:15)
Block(-7,21,-5,LEAVES:7)
Block(-6,0,-7,CONCRETE:7)
Block(-6,0,-6,CONCRETE:7)
Block(-6,0,-5,CONCRETE:7)
Block(-6,0,-4,CONCRETE:7)
Block(-6,0,-3,CONCRETE:7)
Block(-6,0,-2,CONCRETE:7)
Block(-6,0,-1,CONCRETE:7)
Block(-6,0,0,CONCRETE:7)
Block(-6,0,1,CONCRETE:7)
Block(-6,0,2,CONCRETE:7)
Block(-6,0,3,CONCRETE:7)
Block(-6,0,4,CONCRETE:7)
Block(-6,0,5,CONCRETE:7)
Block(-6,0,6,CONCRETE:7)
Block(-6,0,7,CONCRETE:7)
Block(-6,0,8,CONCRETE:7)
Block(-6,1,-7,CONCRETE:7)
Block(-6,1,-6,CONCRETE:7)
Block(-6,1,-5,CONCRETE:7)
Block(-6,1,-4,CONCRETE:7)
Block(-6,1,-3,CONCRETE:7)
Block(-6,1,-2,CONCRETE:7)
Block(-6,1,-1,CONCRETE:7)
Block(-6,1,0,CONCRETE:7)
Block(-6,1,1,CONCRETE:7)
Block(-6,1,2,CONCRETE:7)
Block(-6,1,3,CONCRETE:7)
Block(-6,1,4,CONCRETE:7)
Block(-6,1,5,CONCRETE:7)
Block(-6,1,6,CONCRETE:7)
Block(-6,1,7,CONCRETE:7)
Block(-6,1,8,CONCRETE:7)
Block(-6,2,-7,CONCRETE:7)
Block(-6,2,-6,CONCRETE:7)
Block(-6,2,-5,CONCRETE:7)
Block(-6,2,-4,CONCRETE:7)
Block(-6,2,-3,CONCRETE:7)
Block(-6,2,-2,CONCRETE:7)
Block(-6,2,-1,CONCRETE:7)
Block(-6,2,0,CONCRETE:7)
Block(-6,2,1,CONCRETE:7)
Block(-6,2,2,CONCRETE:7)
Block(-6,2,3,CONCRETE:7)
Block(-6,2,4,CONCRETE:7)
Block(-6,2,5,CONCRETE:7)
Block(-6,2,6,CONCRETE:7)
Block(-6,2,7,CONCRETE:7)
Block(-6,2,8,CONCRETE:7)
Block(-6,3,-7,CONCRETE:7)
Block(-6,3,-6,CONCRETE:7)
Block(-6,3,-5,CONCRETE:7)
Block(-6,3,-4,CONCRETE:7)
Block(-6,3,-3,CONCRETE:7)
Block(-6,3,-2,CONCRETE:7)
Block(-6,3,-1,CONCRETE:7)
Block(-6,3,0,CONCRETE:7)
Block(-6,3,1,CONCRETE:7)
Block(-6,3,2,CONCRETE:7)
Block(-6,3,3,CONCRETE:7)
Block(-6,3,4,CONCRETE:7)
Block(-6,3,5,CONCRETE:7)
Block(-6,3,6,CONCRETE:7)
Block(-6,3,7,CONCRETE:7)
Block(-6,3,8,CONCRETE:7)
Block(-6,4,-7,CONCRETE:7)
Block(-6,4,-6,CONCRETE:7)
Block(-6,4,-5,CONCRETE:7)
Block(-6,4,-4,CONCRETE:7)
Block(-6,4,-3,CONCRETE:7)
Block(-6,4,-2,CONCRETE:7)
Block(-6,4,-1,CONCRETE:7)
Block(-6,4,0,CONCRETE:7)
Block(-6,4,1,CONCRETE:7)
Block(-6,4,2,CONCRETE:7)
Block(-6,4,3,CONCRETE:7)
Block(-6,4,4,CONCRETE:7)
Block(-6,4,5,CONCRETE:7)
Block(-6,4,6,CONCRETE:7)
Block(-6,4,7,CONCRETE:7)
Block(-6,4,8,CONCRETE:7)
Block(-6,5,-7,CONCRETE:7)
Block(-6,5,-6,CONCRETE:7)
Block(-6,5,-5,CONCRETE:7)
Block(-6,5,-4,CONCRETE:7)
Block(-6,5,-3,CONCRETE:7)
Block(-6,5,-2,CONCRETE:7)
Block(-6,5,-1,CONCRETE:7)
Block(-6,5,0,CONCRETE:7)
Block(-6,5,1,CONCRETE:7)
Block(-6,5,2,CONCRETE:7)
Block(-6,5,3,CONCRETE:7)
Block(-6,5,4,CONCRETE:7)
Block(-6,5,5,CONCRETE:7)
Block(-6,5,6,CONCRETE:7)
Block(-6,5,7,CONCRETE:7)
Block(-6,5,8,CONCRETE:7)
Block(-6,6,-7,CONCRETE:7)
Block(-6,6,-6,CONCRETE:7)
Block(-6,6,-5,CONCRETE:7)
Block(-6,6,-4,CONCRETE:7)
Block(-6,6,-3,CONCRETE:7)
Block(-6,6,-2,CONCRETE:7)
Block(-6,6,-1,CONCRETE:7)
Block(-6,6,0,CONCRETE:7)
Block(-6,6,1,CONCRETE:7)
Block(-6,6,2,CONCRETE:7)
Block(-6,6,3,CONCRETE:7)
Block(-6,6,4,CONCRETE:7)
Block(-6,6,5,CONCRETE:7)
Block(-6,6,6,CONCRETE:7)
Block(-6,6,7,CONCRETE:7)
Block(-6,6,8,CONCRETE:7)
Block(-6,7,-7,CONCRETE:7)
Block(-6,7,-6,CONCRETE:7)
Block(-6,7,-5,CONCRETE:7)
Block(-6,7,-4,CONCRETE:7)
Block(-6,7,-3,CONCRETE:7)
Block(-6,7,-2,CONCRETE:7)
Block(-6,7,-1,CONCRETE:7)
Block(-6,7,0,CONCRETE:7)
Block(-6,7,1,CONCRETE:7)
Block(-6,7,2,CONCRETE:7)
Block(-6,7,3,CONCRETE:7)
Block(-6,7,4,CONCRETE:7)
Block(-6,7,5,CONCRETE:7)
Block(-6,7,6,CONCRETE:7)
Block(-6,7,7,CONCRETE:7)
Block(-6,7,8,CONCRETE:7)
Block(-6,8,-7,CONCRETE:7)
Block(-6,8,-6,CONCRETE:7)
Block(-6,8,-5,CONCRETE:7)
Block(-6,8,-4,CONCRETE:7)
Block(-6,8,-3,CONCRETE:7)
Block(-6,8,-2,CONCRETE:7)
Block(-6,8,-1,CONCRETE:7)
Block(-6,8,0,CONCRETE:7)
Block(-6,8,1,CONCRETE:7)
Block(-6,8,2,CONCRETE:7)
Block(-6,8,3,CONCRETE:7)
Block(-6,8,4,CONCRETE:7)
Block(-6,8,5,CONCRETE:7)
Block(-6,8,6,CONCRETE:7)
Block(-6,8,7,CONCRETE:7)
Block(-6,8,8,CONCRETE:7)
Block(-6,9,-7,CONCRETE:7)
Block(-6,9,-6,CONCRETE:7)
Block(-6,9,-5,CONCRETE:7)
Block(-6,9,-4,CONCRETE:7)
Block(-6,9,-3,CONCRETE:7)
Block(-6,9,-2,CONCRETE:7)
Block(-6,9,-1,CONCRETE:7)
Block(-6,9,0,CONCRETE:7)
Block(-6,9,1,CONCRETE:7)
Block(-6,9,2,CONCRETE:7)
Block(-6,9,3,CONCRETE:7)
Block(-6,9,4,CONCRETE:7)
Block(-6,9,5,CONCRETE:7)
Block(-6,9,6,CONCRETE:7)
Block(-6,9,7,CONCRETE:7)
Block(-6,9,8,CONCRETE:7)
Block(-6,10,-7,CONCRETE:7)
Block(-6,10,-6,CONCRETE:7)
Block(-6,10,-5,CONCRETE:7)
Block(-6,10,-4,CONCRETE:7)
Block(-6,10,-3,CONCRETE:7)
Block(-6,10,-2,CONCRETE:7)
Block(-6,10,-1,CONCRETE:7)
Block(-6,10,0,CONCRETE:7)
Block(-6,10,1,CONCRETE:7)
Block(-6,10,2,CONCRETE:7)
Block(-6,10,3,CONCRETE:7)
Block(-6,10,4,CONCRETE:7)
Block(-6,10,5,CONCRETE:7)
Block(-6,10,6,CONCRETE:7)
Block(-6,10,7,CONCRETE:7)
Block(-6,10,8,CONCRETE:7)
Block(-6,11,-7,CONCRETE:7)
Block(-6,11,-6,CONCRETE:7)
Block(-6,11,-5,CONCRETE:7)
Block(-6,11,-4,CONCRETE:7)
Block(-6,11,-3,CONCRETE:7)
Block(-6,11,-2,CONCRETE:7)
Block(-6,11,-1,CONCRETE:7)
Block(-6,11,0,CONCRETE:7)
Block(-6,11,1,CONCRETE:7)
Block(-6,11,2,CONCRETE:7)
Block(-6,11,3,CONCRETE:7)
Block(-6,11,4,CONCRETE:7)
Block(-6,11,5,CONCRETE:7)
Block(-6,11,6,CONCRETE:7)
Block(-6,11,7,CONCRETE:7)
Block(-6,11,8,CONCRETE:7)
Block(-6,12,-7,CONCRETE:7)
Block(-6,12,-6,CONCRETE:7)
Block(-6,12,-5,CONCRETE:7)
Block(-6,12,-4,CONCRETE:7)
Block(-6,12,-3,CONCRETE:7)
Block(-6,12,-2,CONCRETE:7)
Block(-6,12,-1,CONCRETE:7)
Block(-6,12,0,CONCRETE:7)
Block(-6,12,1,CONCRETE:7)
Block(-6,12,2,CONCRETE:7)
Block(-6,12,3,CONCRETE:7)
Block(-6,12,4,CONCRETE:7)
Block(-6,12,5,CONCRETE:7)
Block(-6,12,6,CONCRETE:7)
Block(-6,12,7,CONCRETE:7)
Block(-6,12,8,CONCRETE:7)
Block(-6,13,-7,CONCRETE:7)
Block(-6,13,-6,CONCRETE:7)
Block(-6,13,-5,CONCRETE:7)
Block(-6,13,-4,CONCRETE:7)
Block(-6,13,-3,CONCRETE:7)
Block(-6,13,-2,CONCRETE:7)
Block(-6,13,-1,CONCRETE:7)
Block(-6,13,0,CONCRETE:7)
Block(-6,13,1,CONCRETE:7)
Block(-6,13,2,CONCRETE:7)
Block(-6,13,3,CONCRETE:7)
Block(-6,13,4,CONCRETE:7)
Block(-6,13,5,CONCRETE:7)
Block(-6,13,6,CONCRETE:7)
Block(-6,13,7,CONCRETE:7)
Block(-6,13,8,CONCRETE:7)
Block(-6,14,-7,CONCRETE:7)
Block(-6,14,-6,CONCRETE:7)
Block(-6,14,-5,CONCRETE:7)
Block(-6,14,-4,CONCRETE:7)
Block(-6,14,-3,CONCRETE:7)
Block(-6,14,-2,CONCRETE:7)
Block(-6,14,-1,CONCRETE:7)
Block(-6,14,0,CONCRETE:7)
Block(-6,14,1,CONCRETE:7)
Block(-6,14,2,CONCRETE:7)
Block(-6,14,3,CONCRETE:7)
Block(-6,14,4,CONCRETE:7)
Block(-6,14,5,CONCRETE:7)
Block(-6,14,6,CONCRETE:7)
Block(-6,14,7,CONCRETE:7)
Block(-6,14,8,CONCRETE:7)
Block(-6,15,-7,CONCRETE:7)
Block(-6,15,-6,CONCRETE:7)
Block(-6,15,-5,CONCRETE:7)
Block(-6,15,-4,CONCRETE:7)
Block(-6,15,-3,CONCRETE:7)
Block(-6,15,-2,CONCRETE:7)
Block(-6,15,-1,CONCRETE:7)
Block(-6,15,0,CONCRETE:7)
Block(-6,15,1,CONCRETE:7)
Block(-6,15,2,CONCRETE:7)
Block(-6,15,3,CONCRETE:7)
Block(-6,15,4,CONCRETE:7)
Block(-6,15,5,CONCRETE:7)
Block(-6,15,6,CONCRETE:7)
Block(-6,15,7,CONCRETE:7)
Block(-6,15,8,CONCRETE:7)
Block(-6,16,-7,CONCRETE:7)
Block(-6,16,-6,CONCRETE:7)
Block(-6,16,-5,CONCRETE:7)
Block(-6,16,-4,CONCRETE:7)
Block(-6,16,-3,CONCRETE:7)
Block(-6,16,-2,CONCRETE:7)
Block(-6,16,-1,CONCRETE:7)
Block(-6,16,0,CONCRETE:7)
Block(-6,16,1,CONCRETE:7)
Block(-6,16,2,CONCRETE:7)
Block(-6,16,3,CONCRETE:7)
Block(-6,16,4,CONCRETE:7)
Block(-6,16,5,CONCRETE:7)
Block(-6,16,6,CONCRETE:7)
Block(-6,16,7,CONCRETE:7)
Block(-6,16,8,CONCRETE:7)
Block(-6,17,-7,DOUBLE_STEP:0)
Block(-6,17,-6,DOUBLE_STEP:0)
Block(-6,17,-5,DOUBLE_STEP:0)
Block(-6,17,-4,DOUBLE_STEP:0)
Block(-6,17,-3,DOUBLE_STEP:0)
Block(-6,17,-2,DOUBLE_STEP:0)
Block(-6,17,-1,DOUBLE_STEP:0)
Block(-6,17,0,DOUBLE_STEP:0)
Block(-6,17,1,DOUBLE_STEP:0)
Block(-6,17,2,DOUBLE_STEP:0)
Block(-6,17,3,DOUBLE_STEP:0)
Block(-6,17,4,DOUBLE_STEP:0)
Block(-6,17,5,DOUBLE_STEP:0)
Block(-6,17,6,DOUBLE_STEP:0)
Block(-6,17,7,DOUBLE_STEP:0)
Block(-6,17,8,DOUBLE_STEP:0)
Block(-6,18,-7,GRASS:0)
Block(-6,18,-6,GRASS:0)
Block(-6,18,-5,GRASS:0)
Block(-6,18,-4,QUARTZ_STAIRS:7)
Block(-6,18,-2,VINE:2)
Block(-6,18,3,VINE:2)
Block(-6,18,5,QUARTZ_STAIRS:6)
Block(-6,18,6,GRASS:0)
Block(-6,18,7,GRASS:0)
Block(-6,18,8,GRASS:0)
Block(-6,19,-7,LEAVES:7)
Block(-6,19,-6,LEAVES:7)
Block(-6,19,-5,LEAVES:7)
Block(-6,19,-4,STEP:0)
Block(-6,19,-2,VINE:2)
Block(-6,19,3,VINE:2)
Block(-6,19,5,STEP:0)
Block(-6,19,6,LEAVES:15)
Block(-6,19,7,LEAVES:15)
Block(-6,19,8,LEAVES:15)
Block(-6,20,-5,LEAVES:7)
Block(-6,20,-4,LEAVES:7)
Block(-6,20,6,LEAVES:15)
Block(-6,21,6,LEAVES:15)
Block(-5,0,-7,CONCRETE:7)
Block(-5,0,-6,CONCRETE:7)
Block(-5,0,-5,CONCRETE:7)
Block(-5,0,-4,CONCRETE:7)
Block(-5,0,-3,CONCRETE:7)
Block(-5,0,-2,CONCRETE:7)
Block(-5,0,-1,CONCRETE:7)
Block(-5,0,0,CONCRETE:7)
Block(-5,0,1,CONCRETE:7)
Block(-5,0,2,CONCRETE:7)
Block(-5,0,3,CONCRETE:7)
Block(-5,0,4,CONCRETE:7)
Block(-5,0,5,CONCRETE:7)
Block(-5,0,6,CONCRETE:7)
Block(-5,0,7,CONCRETE:7)
Block(-5,0,8,CONCRETE:7)
Block(-5,1,-7,CONCRETE:7)
Block(-5,1,-6,CONCRETE:7)
Block(-5,1,-5,CONCRETE:7)
Block(-5,1,-4,CONCRETE:7)
Block(-5,1,-3,CONCRETE:7)
Block(-5,1,-2,CONCRETE:7)
Block(-5,1,-1,CONCRETE:7)
Block(-5,1,0,CONCRETE:7)
Block(-5,1,1,CONCRETE:7)
Block(-5,1,2,CONCRETE:7)
Block(-5,1,3,CONCRETE:7)
Block(-5,1,4,CONCRETE:7)
Block(-5,1,5,CONCRETE:7)
Block(-5,1,6,CONCRETE:7)
Block(-5,1,7,CONCRETE:7)
Block(-5,1,8,CONCRETE:7)
Block(-5,2,-7,CONCRETE:7)
Block(-5,2,-6,CONCRETE:7)
Block(-5,2,-5,CONCRETE:7)
Block(-5,2,-4,CONCRETE:7)
Block(-5,2,-3,CONCRETE:7)
Block(-5,2,-2,CONCRETE:7)
Block(-5,2,-1,CONCRETE:7)
Block(-5,2,0,CONCRETE:7)
Block(-5,2,1,CONCRETE:7)
Block(-5,2,2,CONCRETE:7)
Block(-5,2,3,CONCRETE:7)
Block(-5,2,4,CONCRETE:7)
Block(-5,2,5,CONCRETE:7)
Block(-5,2,6,CONCRETE:7)
Block(-5,2,7,CONCRETE:7)
Block(-5,2,8,CONCRETE:7)
Block(-5,3,-7,CONCRETE:7)
Block(-5,3,-6,CONCRETE:7)
Block(-5,3,-5,CONCRETE:7)
Block(-5,3,-4,CONCRETE:7)
Block(-5,3,-3,CONCRETE:7)
Block(-5,3,-2,CONCRETE:7)
Block(-5,3,-1,CONCRETE:7)
Block(-5,3,0,CONCRETE:7)
Block(-5,3,1,CONCRETE:7)
Block(-5,3,2,CONCRETE:7)
Block(-5,3,3,CONCRETE:7)
Block(-5,3,4,CONCRETE:7)
Block(-5,3,5,CONCRETE:7)
Block(-5,3,6,CONCRETE:7)
Block(-5,3,7,CONCRETE:7)
Block(-5,3,8,CONCRETE:7)
Block(-5,4,-7,CONCRETE:7)
Block(-5,4,-6,CONCRETE:7)
Block(-5,4,-5,CONCRETE:7)
Block(-5,4,-4,CONCRETE:7)
Block(-5,4,-3,CONCRETE:7)
Block(-5,4,-2,CONCRETE:7)
Block(-5,4,-1,CONCRETE:7)
Block(-5,4,0,CONCRETE:7)
Block(-5,4,1,CONCRETE:7)
Block(-5,4,2,CONCRETE:7)
Block(-5,4,3,CONCRETE:7)
Block(-5,4,4,CONCRETE:7)
Block(-5,4,5,CONCRETE:7)
Block(-5,4,6,CONCRETE:7)
Block(-5,4,7,CONCRETE:7)
Block(-5,4,8,CONCRETE:7)
Block(-5,5,-7,CONCRETE:7)
Block(-5,5,-6,CONCRETE:7)
Block(-5,5,-5,CONCRETE:7)
Block(-5,5,-4,CONCRETE:7)
Block(-5,5,-3,CONCRETE:7)
Block(-5,5,-2,CONCRETE:7)
Block(-5,5,-1,CONCRETE:7)
Block(-5,5,0,CONCRETE:7)
Block(-5,5,1,CONCRETE:7)
Block(-5,5,2,CONCRETE:7)
Block(-5,5,3,CONCRETE:7)
Block(-5,5,4,CONCRETE:7)
Block(-5,5,5,CONCRETE:7)
Block(-5,5,6,CONCRETE:7)
Block(-5,5,7,CONCRETE:7)
Block(-5,5,8,CONCRETE:7)
Block(-5,6,-7,CONCRETE:7)
Block(-5,6,-6,CONCRETE:7)
Block(-5,6,-5,CONCRETE:7)
Block(-5,6,-4,CONCRETE:7)
Block(-5,6,-3,CONCRETE:7)
Block(-5,6,-2,CONCRETE:7)
Block(-5,6,-1,CONCRETE:7)
Block(-5,6,0,CONCRETE:7)
Block(-5,6,1,CONCRETE:7)
Block(-5,6,2,CONCRETE:7)
Block(-5,6,3,CONCRETE:7)
Block(-5,6,4,CONCRETE:7)
Block(-5,6,5,CONCRETE:7)
Block(-5,6,6,CONCRETE:7)
Block(-5,6,7,CONCRETE:7)
Block(-5,6,8,CONCRETE:7)
Block(-5,7,-7,CONCRETE:7)
Block(-5,7,-6,CONCRETE:7)
Block(-5,7,-5,CONCRETE:7)
Block(-5,7,-4,CONCRETE:7)
Block(-5,7,-3,CONCRETE:7)
Block(-5,7,-2,CONCRETE:7)
Block(-5,7,-1,CONCRETE:7)
Block(-5,7,0,CONCRETE:7)
Block(-5,7,1,CONCRETE:7)
Block(-5,7,2,CONCRETE:7)
Block(-5,7,3,CONCRETE:7)
Block(-5,7,4,CONCRETE:7)
Block(-5,7,5,CONCRETE:7)
Block(-5,7,6,CONCRETE:7)
Block(-5,7,7,CONCRETE:7)
Block(-5,7,8,CONCRETE:7)
Block(-5,8,-7,CONCRETE:7)
Block(-5,8,-6,CONCRETE:7)
Block(-5,8,-5,CONCRETE:7)
Block(-5,8,-4,CONCRETE:7)
Block(-5,8,-3,CONCRETE:7)
Block(-5,8,-2,CONCRETE:7)
Block(-5,8,-1,CONCRETE:7)
Block(-5,8,0,CONCRETE:7)
Block(-5,8,1,CONCRETE:7)
Block(-5,8,2,CONCRETE:7)
Block(-5,8,3,CONCRETE:7)
Block(-5,8,4,CONCRETE:7)
Block(-5,8,5,CONCRETE:7)
Block(-5,8,6,CONCRETE:7)
Block(-5,8,7,CONCRETE:7)
Block(-5,8,8,CONCRETE:7)
Block(-5,9,-7,CONCRETE:7)
Block(-5,9,-6,CONCRETE:7)
Block(-5,9,-5,CONCRETE:7)
Block(-5,9,-4,CONCRETE:7)
Block(-5,9,-3,CONCRETE:7)
Block(-5,9,-2,CONCRETE:7)
Block(-5,9,-1,CONCRETE:7)
Block(-5,9,0,CONCRETE:7)
Block(-5,9,1,CONCRETE:7)
Block(-5,9,2,CONCRETE:7)
Block(-5,9,3,CONCRETE:7)
Block(-5,9,4,CONCRETE:7)
Block(-5,9,5,CONCRETE:7)
Block(-5,9,6,CONCRETE:7)
Block(-5,9,7,CONCRETE:7)
Block(-5,9,8,CONCRETE:7)
Block(-5,10,-7,CONCRETE:7)
Block(-5,10,-6,CONCRETE:7)
Block(-5,10,-5,CONCRETE:7)
Block(-5,10,-4,CONCRETE:7)
Block(-5,10,-3,CONCRETE:7)
Block(-5,10,-2,CONCRETE:7)
Block(-5,10,-1,CONCRETE:7)
Block(-5,10,0,CONCRETE:7)
Block(-5,10,1,CONCRETE:7)
Block(-5,10,2,CONCRETE:7)
Block(-5,10,3,CONCRETE:7)
Block(-5,10,4,CONCRETE:7)
Block(-5,10,5,CONCRETE:7)
Block(-5,10,6,CONCRETE:7)
Block(-5,10,7,CONCRETE:7)
Block(-5,10,8,CONCRETE:7)
Block(-5,11,-7,CONCRETE:7)
Block(-5,11,-6,CONCRETE:7)
Block(-5,11,-5,CONCRETE:7)
Block(-5,11,-4,CONCRETE:7)
Block(-5,11,-3,CONCRETE:7)
Block(-5,11,-2,CONCRETE:7)
Block(-5,11,-1,CONCRETE:7)
Block(-5,11,0,CONCRETE:7)
Block(-5,11,1,CONCRETE:7)
Block(-5,11,2,CONCRETE:7)
Block(-5,11,3,CONCRETE:7)
Block(-5,11,4,CONCRETE:7)
Block(-5,11,5,CONCRETE:7)
Block(-5,11,6,CONCRETE:7)
Block(-5,11,7,CONCRETE:7)
Block(-5,11,8,CONCRETE:7)
Block(-5,12,-7,CONCRETE:7)
Block(-5,12,-6,CONCRETE:7)
Block(-5,12,-5,CONCRETE:7)
Block(-5,12,-4,CONCRETE:7)
Block(-5,12,-3,CONCRETE:7)
Block(-5,12,-2,CONCRETE:7)
Block(-5,12,-1,CONCRETE:7)
Block(-5,12,0,CONCRETE:7)
Block(-5,12,1,CONCRETE:7)
Block(-5,12,2,CONCRETE:7)
Block(-5,12,3,CONCRETE:7)
Block(-5,12,4,CONCRETE:7)
Block(-5,12,5,CONCRETE:7)
Block(-5,12,6,CONCRETE:7)
Block(-5,12,7,CONCRETE:7)
Block(-5,12,8,CONCRETE:7)
Block(-5,13,-7,CONCRETE:7)
Block(-5,13,-6,CONCRETE:7)
Block(-5,13,-5,CONCRETE:7)
Block(-5,13,-4,CONCRETE:7)
Block(-5,13,-3,CONCRETE:7)
Block(-5,13,-2,CONCRETE:7)
Block(-5,13,-1,CONCRETE:7)
Block(-5,13,0,CONCRETE:7)
Block(-5,13,1,CONCRETE:7)
Block(-5,13,2,CONCRETE:7)
Block(-5,13,3,CONCRETE:7)
Block(-5,13,4,CONCRETE:7)
Block(-5,13,5,CONCRETE:7)
Block(-5,13,6,CONCRETE:7)
Block(-5,13,7,CONCRETE:7)
Block(-5,13,8,CONCRETE:7)
Block(-5,14,-7,CONCRETE:7)
Block(-5,14,-6,CONCRETE:7)
Block(-5,14,-5,CONCRETE:7)
Block(-5,14,-4,CONCRETE:7)
Block(-5,14,-3,CONCRETE:7)
Block(-5,14,-2,CONCRETE:7)
Block(-5,14,-1,CONCRETE:7)
Block(-5,14,0,CONCRETE:7)
Block(-5,14,1,CONCRETE:7)
Block(-5,14,2,CONCRETE:7)
Block(-5,14,3,CONCRETE:7)
Block(-5,14,4,CONCRETE:7)
Block(-5,14,5,CONCRETE:7)
Block(-5,14,6,CONCRETE:7)
Block(-5,14,7,CONCRETE:7)
Block(-5,14,8,CONCRETE:7)
Block(-5,15,-7,CONCRETE:7)
Block(-5,15,-6,CONCRETE:7)
Block(-5,15,-5,CONCRETE:7)
Block(-5,15,-4,CONCRETE:7)
Block(-5,15,-3,CONCRETE:7)
Block(-5,15,-2,CONCRETE:7)
Block(-5,15,-1,CONCRETE:7)
Block(-5,15,0,CONCRETE:7)
Block(-5,15,1,CONCRETE:7)
Block(-5,15,2,CONCRETE:7)
Block(-5,15,3,CONCRETE:7)
Block(-5,15,4,CONCRETE:7)
Block(-5,15,5,CONCRETE:7)
Block(-5,15,6,CONCRETE:7)
Block(-5,15,7,CONCRETE:7)
Block(-5,15,8,CONCRETE:7)
Block(-5,16,-7,CONCRETE:7)
Block(-5,16,-6,CONCRETE:7)
Block(-5,16,-5,CONCRETE:7)
Block(-5,16,-4,CONCRETE:7)
Block(-5,16,-3,CONCRETE:7)
Block(-5,16,-2,CONCRETE:7)
Block(-5,16,-1,CONCRETE:7)
Block(-5,16,0,CONCRETE:7)
Block(-5,16,1,CONCRETE:7)
Block(-5,16,2,CONCRETE:7)
Block(-5,16,3,CONCRETE:7)
Block(-5,16,4,CONCRETE:7)
Block(-5,16,5,CONCRETE:7)
Block(-5,16,6,CONCRETE:7)
Block(-5,16,7,CONCRETE:7)
Block(-5,16,8,CONCRETE:7)
Block(-5,17,-7,STAINED_CLAY:9)
Block(-5,17,-6,SMOOTH_BRICK:0)
Block(-5,17,-5,CONCRETE:7)
Block(-5,17,-4,SMOOTH_BRICK:0)
Block(-5,17,-3,CONCRETE:7)
Block(-5,17,-2,SMOOTH_BRICK:0)
Block(-5,17,-1,STAINED_CLAY:9)
Block(-5,17,0,SMOOTH_BRICK:0)
Block(-5,17,1,CONCRETE:7)
Block(-5,17,2,SMOOTH_BRICK:0)
Block(-5,17,3,STAINED_CLAY:9)
Block(-5,17,4,CONCRETE:7)
Block(-5,17,5,CONCRETE:7)
Block(-5,17,6,CONCRETE:7)
Block(-5,17,7,CONCRETE:7)
Block(-5,17,8,SMOOTH_BRICK:0)
Block(-5,18,-7,QUARTZ_STAIRS:5)
Block(-5,18,-6,QUARTZ_STAIRS:5)
Block(-5,18,-5,QUARTZ_STAIRS:5)
Block(-5,18,-4,QUARTZ_STAIRS:5)
Block(-5,18,5,QUARTZ_STAIRS:6)
Block(-5,18,6,QUARTZ_STAIRS:5)
Block(-5,18,7,QUARTZ_STAIRS:5)
Block(-5,18,8,QUARTZ_STAIRS:5)
Block(-5,19,-7,STEP:0)
Block(-5,19,-6,STEP:0)
Block(-5,19,-5,STEP:0)
Block(-5,19,-4,STEP:0)
Block(-5,19,5,STEP:0)
Block(-5,19,6,STEP:0)
Block(-5,19,7,STEP:0)
Block(-5,19,8,STEP:0)
Block(-4,0,-7,CONCRETE:7)
Block(-4,0,-6,CONCRETE:7)
Block(-4,0,-5,CONCRETE:7)
Block(-4,0,-4,CONCRETE:7)
Block(-4,0,-3,CONCRETE:7)
Block(-4,0,-2,CONCRETE:7)
Block(-4,0,-1,CONCRETE:7)
Block(-4,0,0,CONCRETE:7)
Block(-4,0,1,CONCRETE:7)
Block(-4,0,2,CONCRETE:7)
Block(-4,0,3,CONCRETE:7)
Block(-4,0,4,CONCRETE:7)
Block(-4,0,5,CONCRETE:7)
Block(-4,0,6,CONCRETE:7)
Block(-4,0,7,CONCRETE:7)
Block(-4,0,8,CONCRETE:7)
Block(-4,1,-7,CONCRETE:7)
Block(-4,1,-6,CONCRETE:7)
Block(-4,1,-5,CONCRETE:7)
Block(-4,1,-4,CONCRETE:7)
Block(-4,1,-3,CONCRETE:7)
Block(-4,1,-2,CONCRETE:7)
Block(-4,1,-1,CONCRETE:7)
Block(-4,1,0,CONCRETE:7)
Block(-4,1,1,CONCRETE:7)
Block(-4,1,2,CONCRETE:7)
Block(-4,1,3,CONCRETE:7)
Block(-4,1,4,CONCRETE:7)
Block(-4,1,5,CONCRETE:7)
Block(-4,1,6,CONCRETE:7)
Block(-4,1,7,CONCRETE:7)
Block(-4,1,8,CONCRETE:7)
Block(-4,2,-7,CONCRETE:7)
Block(-4,2,-6,CONCRETE:7)
Block(-4,2,-5,CONCRETE:7)
Block(-4,2,-4,CONCRETE:7)
Block(-4,2,-3,CONCRETE:7)
Block(-4,2,-2,CONCRETE:7)
Block(-4,2,-1,CONCRETE:7)
Block(-4,2,0,CONCRETE:7)
Block(-4,2,1,CONCRETE:7)
Block(-4,2,2,CONCRETE:7)
Block(-4,2,3,CONCRETE:7)
Block(-4,2,4,CONCRETE:7)
Block(-4,2,5,CONCRETE:7)
Block(-4,2,6,CONCRETE:7)
Block(-4,2,7,CONCRETE:7)
Block(-4,2,8,CONCRETE:7)
Block(-4,3,-7,CONCRETE:7)
Block(-4,3,-6,SMOOTH_STAIRS:1)
Block(-4,3,-5,SMOOTH_STAIRS:1)
Block(-4,3,-4,CONCRETE:7)
Block(-4,3,-3,SMOOTH_STAIRS:1)
Block(-4,3,-2,SMOOTH_STAIRS:1)
Block(-4,3,-1,CONCRETE:7)
Block(-4,3,0,SMOOTH_STAIRS:1)
Block(-4,3,1,SMOOTH_STAIRS:1)
Block(-4,3,2,CONCRETE:7)
Block(-4,3,3,SMOOTH_STAIRS:1)
Block(-4,3,4,SMOOTH_STAIRS:1)
Block(-4,3,5,CONCRETE:7)
Block(-4,3,6,SMOOTH_STAIRS:1)
Block(-4,3,7,SMOOTH_STAIRS:1)
Block(-4,3,8,CONCRETE:7)
Block(-4,4,-7,CONCRETE:7)
Block(-4,4,-6,COBBLE_WALL:0)
Block(-4,4,-5,COBBLE_WALL:0)
Block(-4,4,-4,CONCRETE:7)
Block(-4,4,-3,COBBLE_WALL:0)
Block(-4,4,-2,COBBLE_WALL:0)
Block(-4,4,-1,CONCRETE:7)
Block(-4,4,0,COBBLE_WALL:0)
Block(-4,4,1,COBBLE_WALL:0)
Block(-4,4,2,CONCRETE:7)
Block(-4,4,3,COBBLE_WALL:0)
Block(-4,4,4,COBBLE_WALL:0)
Block(-4,4,5,CONCRETE:7)
Block(-4,4,6,COBBLE_WALL:0)
Block(-4,4,7,COBBLE_WALL:0)
Block(-4,4,8,CONCRETE:7)
Block(-4,5,-7,CONCRETE:7)
Block(-4,5,-6,SMOOTH_STAIRS:5)
Block(-4,5,-5,SMOOTH_STAIRS:5)
Block(-4,5,-4,CONCRETE:7)
Block(-4,5,-3,SMOOTH_STAIRS:5)
Block(-4,5,-2,SMOOTH_STAIRS:5)
Block(-4,5,-1,CONCRETE:7)
Block(-4,5,0,SMOOTH_STAIRS:5)
Block(-4,5,1,SMOOTH_STAIRS:5)
Block(-4,5,2,CONCRETE:7)
Block(-4,5,3,SMOOTH_STAIRS:5)
Block(-4,5,4,SMOOTH_STAIRS:5)
Block(-4,5,5,CONCRETE:7)
Block(-4,5,6,SMOOTH_STAIRS:5)
Block(-4,5,7,SMOOTH_STAIRS:5)
Block(-4,5,8,CONCRETE:7)
Block(-4,6,-7,CONCRETE:7)
Block(-4,6,-6,CONCRETE:7)
Block(-4,6,-5,CONCRETE:7)
Block(-4,6,-4,CONCRETE:7)
Block(-4,6,-3,CONCRETE:7)
Block(-4,6,-2,CONCRETE:7)
Block(-4,6,-1,CONCRETE:7)
Block(-4,6,0,CONCRETE:7)
Block(-4,6,1,CONCRETE:7)
Block(-4,6,2,CONCRETE:7)
Block(-4,6,3,CONCRETE:7)
Block(-4,6,4,CONCRETE:7)
Block(-4,6,5,CONCRETE:7)
Block(-4,6,6,CONCRETE:7)
Block(-4,6,7,CONCRETE:7)
Block(-4,6,8,CONCRETE:7)
Block(-4,7,-7,CONCRETE:7)
Block(-4,7,-6,CONCRETE:7)
Block(-4,7,-5,CONCRETE:7)
Block(-4,7,-4,CONCRETE:7)
Block(-4,7,-3,CONCRETE:7)
Block(-4,7,-2,CONCRETE:7)
Block(-4,7,-1,CONCRETE:7)
Block(-4,7,0,CONCRETE:7)
Block(-4,7,1,CONCRETE:7)
Block(-4,7,2,CONCRETE:7)
Block(-4,7,3,CONCRETE:7)
Block(-4,7,4,CONCRETE:7)
Block(-4,7,5,CONCRETE:7)
Block(-4,7,6,CONCRETE:7)
Block(-4,7,7,CONCRETE:7)
Block(-4,7,8,CONCRETE:7)
Block(-4,8,-7,CONCRETE:7)
Block(-4,8,-6,CONCRETE:7)
Block(-4,8,-5,CONCRETE:7)
Block(-4,8,-4,CONCRETE:7)
Block(-4,8,-3,CONCRETE:7)
Block(-4,8,-2,CONCRETE:7)
Block(-4,8,-1,CONCRETE:7)
Block(-4,8,0,CONCRETE:7)
Block(-4,8,1,CONCRETE:7)
Block(-4,8,2,CONCRETE:7)
Block(-4,8,3,CONCRETE:7)
Block(-4,8,4,CONCRETE:7)
Block(-4,8,5,CONCRETE:7)
Block(-4,8,6,CONCRETE:7)
Block(-4,8,7,CONCRETE:7)
Block(-4,8,8,CONCRETE:7)
Block(-4,9,-7,CONCRETE:7)
Block(-4,9,-6,CONCRETE:7)
Block(-4,9,-5,CONCRETE:7)
Block(-4,9,-4,CONCRETE:7)
Block(-4,9,-3,CONCRETE:7)
Block(-4,9,-2,CONCRETE:7)
Block(-4,9,-1,CONCRETE:7)
Block(-4,9,0,CONCRETE:7)
Block(-4,9,1,CONCRETE:7)
Block(-4,9,2,CONCRETE:7)
Block(-4,9,3,CONCRETE:7)
Block(-4,9,4,CONCRETE:7)
Block(-4,9,5,CONCRETE:7)
Block(-4,9,6,CONCRETE:7)
Block(-4,9,7,CONCRETE:7)
Block(-4,9,8,CONCRETE:7)
Block(-4,10,-7,CONCRETE:7)
Block(-4,10,-6,CONCRETE:7)
Block(-4,10,-5,CONCRETE:7)
Block(-4,10,-4,CONCRETE:7)
Block(-4,10,-3,CONCRETE:7)
Block(-4,10,-2,CONCRETE:7)
Block(-4,10,-1,CONCRETE:7)
Block(-4,10,0,CONCRETE:7)
Block(-4,10,1,CONCRETE:7)
Block(-4,10,2,CONCRETE:7)
Block(-4,10,3,CONCRETE:7)
Block(-4,10,4,CONCRETE:7)
Block(-4,10,5,CONCRETE:7)
Block(-4,10,6,CONCRETE:7)
Block(-4,10,7,CONCRETE:7)
Block(-4,10,8,CONCRETE:7)
Block(-4,11,-7,CONCRETE:7)
Block(-4,11,-6,CONCRETE:7)
Block(-4,11,-5,CONCRETE:7)
Block(-4,11,-4,CONCRETE:7)
Block(-4,11,-3,CONCRETE:7)
Block(-4,11,-2,CONCRETE:7)
Block(-4,11,-1,CONCRETE:7)
Block(-4,11,0,CONCRETE:7)
Block(-4,11,1,CONCRETE:7)
Block(-4,11,2,CONCRETE:7)
Block(-4,11,3,CONCRETE:7)
Block(-4,11,4,CONCRETE:7)
Block(-4,11,5,CONCRETE:7)
Block(-4,11,6,CONCRETE:7)
Block(-4,11,7,CONCRETE:7)
Block(-4,11,8,CONCRETE:7)
Block(-4,12,-7,CONCRETE:7)
Block(-4,12,-6,CONCRETE:7)
Block(-4,12,-5,CONCRETE:7)
Block(-4,12,-4,CONCRETE:7)
Block(-4,12,-3,CONCRETE:7)
Block(-4,12,-2,CONCRETE:7)
Block(-4,12,-1,CONCRETE:7)
Block(-4,12,0,CONCRETE:7)
Block(-4,12,1,CONCRETE:7)
Block(-4,12,2,CONCRETE:7)
Block(-4,12,3,CONCRETE:7)
Block(-4,12,4,CONCRETE:7)
Block(-4,12,5,CONCRETE:7)
Block(-4,12,6,CONCRETE:7)
Block(-4,12,7,CONCRETE:7)
Block(-4,12,8,CONCRETE:7)
Block(-4,13,-7,CONCRETE:7)
Block(-4,13,-6,CONCRETE:7)
Block(-4,13,-5,CONCRETE:7)
Block(-4,13,-4,CONCRETE:7)
Block(-4,13,-3,CONCRETE:7)
Block(-4,13,-2,CONCRETE:7)
Block(-4,13,-1,CONCRETE:7)
Block(-4,13,0,CONCRETE:7)
Block(-4,13,1,CONCRETE:7)
Block(-4,13,2,CONCRETE:7)
Block(-4,13,3,CONCRETE:7)
Block(-4,13,4,CONCRETE:7)
Block(-4,13,5,CONCRETE:7)
Block(-4,13,6,CONCRETE:7)
Block(-4,13,7,CONCRETE:7)
Block(-4,13,8,CONCRETE:7)
Block(-4,14,-7,CONCRETE:7)
Block(-4,14,-6,CONCRETE:7)
Block(-4,14,-5,CONCRETE:7)
Block(-4,14,-4,CONCRETE:7)
Block(-4,14,-3,CONCRETE:7)
Block(-4,14,-2,CONCRETE:7)
Block(-4,14,-1,CONCRETE:7)
Block(-4,14,0,CONCRETE:7)
Block(-4,14,1,CONCRETE:7)
Block(-4,14,2,CONCRETE:7)
Block(-4,14,3,CONCRETE:7)
Block(-4,14,4,CONCRETE:7)
Block(-4,14,5,CONCRETE:7)
Block(-4,14,6,CONCRETE:7)
Block(-4,14,7,CONCRETE:7)
Block(-4,14,8,CONCRETE:7)
Block(-4,15,-7,CONCRETE:7)
Block(-4,15,-6,CONCRETE:7)
Block(-4,15,-5,CONCRETE:7)
Block(-4,15,-4,CONCRETE:7)
Block(-4,15,-3,CONCRETE:7)
Block(-4,15,-2,CONCRETE:7)
Block(-4,15,-1,CONCRETE:7)
Block(-4,15,0,CONCRETE:7)
Block(-4,15,1,CONCRETE:7)
Block(-4,15,2,CONCRETE:7)
Block(-4,15,3,CONCRETE:7)
Block(-4,15,4,CONCRETE:7)
Block(-4,15,5,CONCRETE:7)
Block(-4,15,6,CONCRETE:7)
Block(-4,15,7,CONCRETE:7)
Block(-4,15,8,CONCRETE:7)
Block(-4,16,-7,CONCRETE:7)
Block(-4,16,-6,CONCRETE:7)
Block(-4,16,-5,CONCRETE:7)
Block(-4,16,-4,CONCRETE:7)
Block(-4,16,-3,CONCRETE:7)
Block(-4,16,-2,CONCRETE:7)
Block(-4,16,-1,CONCRETE:7)
Block(-4,16,0,CONCRETE:7)
Block(-4,16,1,CONCRETE:7)
Block(-4,16,2,CONCRETE:7)
Block(-4,16,3,CONCRETE:7)
Block(-4,16,4,CONCRETE:7)
Block(-4,16,5,CONCRETE:7)
Block(-4,16,6,CONCRETE:7)
Block(-4,16,7,CONCRETE:7)
Block(-4,16,8,CONCRETE:7)
Block(-4,17,-7,STAINED_CLAY:9)
Block(-4,17,-6,SMOOTH_BRICK:0)
Block(-4,17,-5,CONCRETE:7)
Block(-4,17,-4,CONCRETE:7)
Block(-4,17,-3,CONCRETE:7)
Block(-4,17,-2,CONCRETE:7)
Block(-4,17,-1,SMOOTH_BRICK:0)
Block(-4,17,0,SMOOTH_BRICK:0)
Block(-4,17,1,CONCRETE:7)
Block(-4,17,2,CONCRETE:7)
Block(-4,17,3,STAINED_CLAY:9)
Block(-4,17,4,CONCRETE:7)
Block(-4,17,5,SMOOTH_BRICK:0)
Block(-4,17,6,SMOOTH_BRICK:0)
Block(-4,17,7,SMOOTH_BRICK:0)
Block(-4,17,8,SMOOTH_BRICK:0)
Block(-3,0,-7,CONCRETE:7)
Block(-3,0,-6,CONCRETE:7)
Block(-3,0,-5,CONCRETE:7)
Block(-3,0,-4,CONCRETE:7)
Block(-3,0,-3,CONCRETE:7)
Block(-3,0,-2,CONCRETE:7)
Block(-3,0,-1,CONCRETE:7)
Block(-3,0,0,CONCRETE:7)
Block(-3,0,1,CONCRETE:7)
Block(-3,0,2,CONCRETE:7)
Block(-3,0,3,CONCRETE:7)
Block(-3,0,4,CONCRETE:7)
Block(-3,0,5,CONCRETE:7)
Block(-3,0,6,CONCRETE:7)
Block(-3,0,7,CONCRETE:7)
Block(-3,0,8,CONCRETE:7)
Block(-3,1,-7,AIR:0)
Block(-3,1,-6,AIR:0)
Block(-3,1,-5,AIR:0)
Block(-3,1,-4,AIR:0)
Block(-3,1,-3,AIR:0)
Block(-3,1,-2,AIR:0)
Block(-3,1,-1,AIR:0)
Block(-3,1,0,AIR:0)
Block(-3,1,1,AIR:0)
Block(-3,1,2,AIR:0)
Block(-3,1,3,AIR:0)
Block(-3,1,4,AIR:0)
Block(-3,1,5,AIR:0)
Block(-3,1,6,AIR:0)
Block(-3,1,7,AIR:0)
Block(-3,1,8,AIR:0)
Block(-3,2,-7,AIR:0)
Block(-3,2,-6,IRON_TRAPDOOR:8)
Block(-3,2,-5,IRON_TRAPDOOR:8)
Block(-3,2,-4,IRON_TRAPDOOR:8)
Block(-3,2,-3,IRON_TRAPDOOR:8)
Block(-3,2,-2,IRON_TRAPDOOR:8)
Block(-3,2,-1,IRON_TRAPDOOR:8)
Block(-3,2,0,IRON_TRAPDOOR:8)
Block(-3,2,1,IRON_TRAPDOOR:8)
Block(-3,2,2,IRON_TRAPDOOR:8)
Block(-3,2,3,IRON_TRAPDOOR:8)
Block(-3,2,4,IRON_TRAPDOOR:8)
Block(-3,2,5,IRON_TRAPDOOR:8)
Block(-3,2,6,IRON_TRAPDOOR:8)
Block(-3,2,7,IRON_TRAPDOOR:8)
Block(-3,2,8,IRON_TRAPDOOR:9)
Block(-3,3,-7,AIR:0)
Block(-3,3,-6,CONCRETE:4)
Block(-3,3,-5,CONCRETE:4)
Block(-3,3,-4,CONCRETE:4)
Block(-3,3,-3,CONCRETE:4)
Block(-3,3,-2,CONCRETE:4)
Block(-3,3,-1,CONCRETE:4)
Block(-3,3,0,CONCRETE:4)
Block(-3,3,1,CONCRETE:4)
Block(-3,3,2,CONCRETE:4)
Block(-3,3,3,CONCRETE:4)
Block(-3,3,4,CONCRETE:4)
Block(-3,3,5,CONCRETE:4)
Block(-3,3,6,CONCRETE:4)
Block(-3,3,7,CONCRETE:4)
Block(-3,3,8,CONCRETE:4)
Block(-3,4,-7,AIR:0)
Block(-3,4,-6,AIR:0)
Block(-3,4,-5,AIR:0)
Block(-3,4,-4,AIR:0)
Block(-3,4,-3,AIR:0)
Block(-3,4,-2,AIR:0)
Block(-3,4,-1,AIR:0)
Block(-3,4,0,AIR:0)
Block(-3,4,1,AIR:0)
Block(-3,4,2,AIR:0)
Block(-3,4,3,AIR:0)
Block(-3,4,4,AIR:0)
Block(-3,4,5,AIR:0)
Block(-3,4,6,AIR:0)
Block(-3,4,7,AIR:0)
Block(-3,4,8,AIR:0)
Block(-3,5,-7,SMOOTH_STAIRS:5)
Block(-3,5,-6,AIR:0)
Block(-3,5,-5,AIR:0)
Block(-3,5,-4,SMOOTH_STAIRS:5)
Block(-3,5,-3,AIR:0)
Block(-3,5,-2,AIR:0)
Block(-3,5,-1,SMOOTH_STAIRS:5)
Block(-3,5,0,AIR:0)
Block(-3,5,1,AIR:0)
Block(-3,5,2,SMOOTH_STAIRS:5)
Block(-3,5,3,AIR:0)
Block(-3,5,4,AIR:0)
Block(-3,5,5,SMOOTH_STAIRS:5)
Block(-3,5,6,AIR:0)
Block(-3,5,7,AIR:0)
Block(-3,5,8,SMOOTH_STAIRS:5)
Block(-3,6,-7,CONCRETE:7)
Block(-3,6,-6,CONCRETE:7)
Block(-3,6,-5,CONCRETE:7)
Block(-3,6,-4,CONCRETE:7)
Block(-3,6,-3,CONCRETE:7)
Block(-3,6,-2,CONCRETE:7)
Block(-3,6,-1,CONCRETE:7)
Block(-3,6,0,CONCRETE:7)
Block(-3,6,1,CONCRETE:7)
Block(-3,6,2,CONCRETE:7)
Block(-3,6,3,CONCRETE:7)
Block(-3,6,4,CONCRETE:7)
Block(-3,6,5,CONCRETE:7)
Block(-3,6,6,CONCRETE:7)
Block(-3,6,7,CONCRETE:7)
Block(-3,6,8,CONCRETE:7)
Block(-3,7,-7,CONCRETE:7)
Block(-3,7,-6,CONCRETE:7)
Block(-3,7,-5,CONCRETE:7)
Block(-3,7,-4,CONCRETE:7)
Block(-3,7,-3,CONCRETE:7)
Block(-3,7,-2,CONCRETE:7)
Block(-3,7,-1,CONCRETE:7)
Block(-3,7,0,CONCRETE:7)
Block(-3,7,1,CONCRETE:7)
Block(-3,7,2,CONCRETE:7)
Block(-3,7,3,CONCRETE:7)
Block(-3,7,4,CONCRETE:7)
Block(-3,7,5,CONCRETE:7)
Block(-3,7,6,CONCRETE:7)
Block(-3,7,7,CONCRETE:7)
Block(-3,7,8,CONCRETE:7)
Block(-3,8,-7,CONCRETE:7)
Block(-3,8,-6,CONCRETE:7)
Block(-3,8,-5,CONCRETE:7)
Block(-3,8,-4,CONCRETE:7)
Block(-3,8,-3,CONCRETE:7)
Block(-3,8,-2,CONCRETE:7)
Block(-3,8,-1,CONCRETE:7)
Block(-3,8,0,CONCRETE:7)
Block(-3,8,1,CONCRETE:7)
Block(-3,8,2,CONCRETE:7)
Block(-3,8,3,CONCRETE:7)
Block(-3,8,4,CONCRETE:7)
Block(-3,8,5,CONCRETE:7)
Block(-3,8,6,CONCRETE:7)
Block(-3,8,7,CONCRETE:7)
Block(-3,8,8,CONCRETE:7)
Block(-3,9,-7,CONCRETE:7)
Block(-3,9,-6,CONCRETE:7)
Block(-3,9,-5,CONCRETE:7)
Block(-3,9,-4,CONCRETE:7)
Block(-3,9,-3,CONCRETE:7)
Block(-3,9,-2,CONCRETE:7)
Block(-3,9,-1,CONCRETE:7)
Block(-3,9,0,CONCRETE:7)
Block(-3,9,1,CONCRETE:7)
Block(-3,9,2,CONCRETE:7)
Block(-3,9,3,CONCRETE:7)
Block(-3,9,4,CONCRETE:7)
Block(-3,9,5,CONCRETE:7)
Block(-3,9,6,CONCRETE:7)
Block(-3,9,7,CONCRETE:7)
Block(-3,9,8,CONCRETE:7)
Block(-3,10,-7,CONCRETE:7)
Block(-3,10,-6,CONCRETE:7)
Block(-3,10,-5,CONCRETE:7)
Block(-3,10,-4,CONCRETE:7)
Block(-3,10,-3,CONCRETE:7)
Block(-3,10,-2,CONCRETE:7)
Block(-3,10,-1,CONCRETE:7)
Block(-3,10,0,CONCRETE:7)
Block(-3,10,1,CONCRETE:7)
Block(-3,10,2,CONCRETE:7)
Block(-3,10,3,CONCRETE:7)
Block(-3,10,4,CONCRETE:7)
Block(-3,10,5,CONCRETE:7)
Block(-3,10,6,CONCRETE:7)
Block(-3,10,7,CONCRETE:7)
Block(-3,10,8,CONCRETE:7)
Block(-3,11,-7,CONCRETE:7)
Block(-3,11,-6,CONCRETE:7)
Block(-3,11,-5,CONCRETE:7)
Block(-3,11,-4,CONCRETE:7)
Block(-3,11,-3,CONCRETE:7)
Block(-3,11,-2,CONCRETE:7)
Block(-3,11,-1,CONCRETE:7)
Block(-3,11,0,CONCRETE:7)
Block(-3,11,1,CONCRETE:7)
Block(-3,11,2,CONCRETE:7)
Block(-3,11,3,CONCRETE:7)
Block(-3,11,4,CONCRETE:7)
Block(-3,11,5,CONCRETE:7)
Block(-3,11,6,CONCRETE:7)
Block(-3,11,7,CONCRETE:7)
Block(-3,11,8,CONCRETE:7)
Block(-3,12,-7,CONCRETE:7)
Block(-3,12,-6,CONCRETE:7)
Block(-3,12,-5,CONCRETE:7)
Block(-3,12,-4,CONCRETE:7)
Block(-3,12,-3,CONCRETE:7)
Block(-3,12,-2,CONCRETE:7)
Block(-3,12,-1,CONCRETE:7)
Block(-3,12,0,CONCRETE:7)
Block(-3,12,1,CONCRETE:7)
Block(-3,12,2,CONCRETE:7)
Block(-3,12,3,CONCRETE:7)
Block(-3,12,4,CONCRETE:7)
Block(-3,12,5,CONCRETE:7)
Block(-3,12,6,CONCRETE:7)
Block(-3,12,7,CONCRETE:7)
Block(-3,12,8,CONCRETE:7)
Block(-3,13,-7,CONCRETE:7)
Block(-3,13,-6,CONCRETE:7)
Block(-3,13,-5,CONCRETE:7)
Block(-3,13,-4,CONCRETE:7)
Block(-3,13,-3,CONCRETE:7)
Block(-3,13,-2,CONCRETE:7)
Block(-3,13,-1,CONCRETE:7)
Block(-3,13,0,CONCRETE:7)
Block(-3,13,1,CONCRETE:7)
Block(-3,13,2,CONCRETE:7)
Block(-3,13,3,CONCRETE:7)
Block(-3,13,4,CONCRETE:7)
Block(-3,13,5,CONCRETE:7)
Block(-3,13,6,CONCRETE:7)
Block(-3,13,7,CONCRETE:7)
Block(-3,13,8,CONCRETE:7)
Block(-3,14,-7,CONCRETE:7)
Block(-3,14,-6,CONCRETE:7)
Block(-3,14,-5,CONCRETE:7)
Block(-3,14,-4,CONCRETE:7)
Block(-3,14,-3,CONCRETE:7)
Block(-3,14,-2,CONCRETE:7)
Block(-3,14,-1,CONCRETE:7)
Block(-3,14,0,CONCRETE:7)
Block(-3,14,1,CONCRETE:7)
Block(-3,14,2,CONCRETE:7)
Block(-3,14,3,CONCRETE:7)
Block(-3,14,4,CONCRETE:7)
Block(-3,14,5,CONCRETE:7)
Block(-3,14,6,CONCRETE:7)
Block(-3,14,7,CONCRETE:7)
Block(-3,14,8,CONCRETE:7)
Block(-3,15,-7,CONCRETE:7)
Block(-3,15,-6,CONCRETE:7)
Block(-3,15,-5,CONCRETE:7)
Block(-3,15,-4,CONCRETE:7)
Block(-3,15,-3,CONCRETE:7)
Block(-3,15,-2,CONCRETE:7)
Block(-3,15,-1,CONCRETE:7)
Block(-3,15,0,CONCRETE:7)
Block(-3,15,1,CONCRETE:7)
Block(-3,15,2,CONCRETE:7)
Block(-3,15,3,CONCRETE:7)
Block(-3,15,4,CONCRETE:7)
Block(-3,15,5,CONCRETE:7)
Block(-3,15,6,CONCRETE:7)
Block(-3,15,7,CONCRETE:7)
Block(-3,15,8,CONCRETE:7)
Block(-3,16,-7,CONCRETE:7)
Block(-3,16,-6,CONCRETE:7)
Block(-3,16,-5,CONCRETE:7)
Block(-3,16,-4,CONCRETE:7)
Block(-3,16,-3,CONCRETE:7)
Block(-3,16,-2,CONCRETE:7)
Block(-3,16,-1,CONCRETE:7)
Block(-3,16,0,CONCRETE:7)
Block(-3,16,1,CONCRETE:7)
Block(-3,16,2,CONCRETE:7)
Block(-3,16,3,CONCRETE:7)
Block(-3,16,4,CONCRETE:7)
Block(-3,16,5,CONCRETE:7)
Block(-3,16,6,CONCRETE:7)
Block(-3,16,7,CONCRETE:7)
Block(-3,16,8,CONCRETE:7)
Block(-3,17,-7,STAINED_CLAY:9)
Block(-3,17,-6,CONCRETE:7)
Block(-3,17,-5,STAINED_CLAY:9)
Block(-3,17,-4,SMOOTH_BRICK:0)
Block(-3,17,-3,CONCRETE:7)
Block(-3,17,-2,SMOOTH_BRICK:0)
Block(-3,17,-1,STAINED_CLAY:9)
Block(-3,17,0,SMOOTH_BRICK:0)
Block(-3,17,1,SMOOTH_BRICK:0)
Block(-3,17,2,STAINED_CLAY:9)
Block(-3,17,3,SMOOTH_BRICK:0)
Block(-3,17,4,STAINED_CLAY:9)
Block(-3,17,5,SMOOTH_BRICK:0)
Block(-3,17,6,STAINED_CLAY:9)
Block(-3,17,7,CONCRETE:7)
Block(-3,17,8,SMOOTH_BRICK:0)
Block(-2,0,-7,CONCRETE:7)
Block(-2,0,-6,CONCRETE:7)
Block(-2,0,-5,CONCRETE:7)
Block(-2,0,-4,CONCRETE:7)
Block(-2,0,-3,CONCRETE:7)
Block(-2,0,-2,CONCRETE:7)
Block(-2,0,-1,CONCRETE:7)
Block(-2,0,0,CONCRETE:7)
Block(-2,0,1,CONCRETE:7)
Block(-2,0,2,CONCRETE:7)
Block(-2,0,3,CONCRETE:7)
Block(-2,0,4,CONCRETE:7)
Block(-2,0,5,CONCRETE:7)
Block(-2,0,6,CONCRETE:7)
Block(-2,0,7,CONCRETE:7)
Block(-2,0,8,CONCRETE:7)
Block(-2,1,-7,CONCRETE:7)
Block(-2,1,-6,CONCRETE:7)
Block(-2,1,-5,CONCRETE:7)
Block(-2,1,-4,CONCRETE:7)
Block(-2,1,-3,CONCRETE:7)
Block(-2,1,-2,CONCRETE:7)
Block(-2,1,-1,CONCRETE:7)
Block(-2,1,0,CONCRETE:7)
Block(-2,1,1,CONCRETE:7)
Block(-2,1,2,CONCRETE:7)
Block(-2,1,3,CONCRETE:7)
Block(-2,1,4,CONCRETE:7)
Block(-2,1,5,CONCRETE:7)
Block(-2,1,6,CONCRETE:7)
Block(-2,1,7,CONCRETE:7)
Block(-2,1,8,CONCRETE:7)
Block(-2,2,-7,CONCRETE:7)
Block(-2,2,-6,CONCRETE:7)
Block(-2,2,-5,CONCRETE:7)
Block(-2,2,-4,CONCRETE:7)
Block(-2,2,-3,CONCRETE:7)
Block(-2,2,-2,CONCRETE:7)
Block(-2,2,-1,CONCRETE:7)
Block(-2,2,0,CONCRETE:7)
Block(-2,2,1,CONCRETE:7)
Block(-2,2,2,CONCRETE:7)
Block(-2,2,3,CONCRETE:7)
Block(-2,2,4,CONCRETE:7)
Block(-2,2,5,CONCRETE:7)
Block(-2,2,6,CONCRETE:7)
Block(-2,2,7,CONCRETE:7)
Block(-2,2,8,CONCRETE:7)
Block(-2,3,-7,AIR:0)
Block(-2,3,-6,CONCRETE:4)
Block(-2,3,-5,AIR:0)
Block(-2,3,-4,AIR:0)
Block(-2,3,-3,AIR:0)
Block(-2,3,-2,AIR:0)
Block(-2,3,-1,AIR:0)
Block(-2,3,0,AIR:0)
Block(-2,3,1,AIR:0)
Block(-2,3,2,AIR:0)
Block(-2,3,3,AIR:0)
Block(-2,3,4,AIR:0)
Block(-2,3,5,AIR:0)
Block(-2,3,6,AIR:0)
Block(-2,3,7,AIR:0)
Block(-2,3,8,AIR:0)
Block(-2,4,-7,CONCRETE:14)
Block(-2,4,-6,CONCRETE:14)
Block(-2,4,-5,CONCRETE:14)
Block(-2,4,-4,CONCRETE:14)
Block(-2,4,-3,AIR:0)
Block(-2,4,-2,AIR:0)
Block(-2,4,-1,AIR:0)
Block(-2,4,0,AIR:0)
Block(-2,4,1,AIR:0)
Block(-2,4,2,AIR:0)
Block(-2,4,3,AIR:0)
Block(-2,4,4,AIR:0)
Block(-2,4,5,AIR:0)
Block(-2,4,6,AIR:0)
Block(-2,4,7,AIR:0)
Block(-2,4,8,AIR:0)
Block(-2,5,-7,CONCRETE:11)
Block(-2,5,-6,CONCRETE:11)
Block(-2,5,-5,CONCRETE:11)
Block(-2,5,-4,CONCRETE:11)
Block(-2,5,-3,CONCRETE:11)
Block(-2,5,-2,CONCRETE:11)
Block(-2,5,-1,CONCRETE:11)
Block(-2,5,0,CONCRETE:11)
Block(-2,5,1,CONCRETE:11)
Block(-2,5,2,CONCRETE:11)
Block(-2,5,3,CONCRETE:11)
Block(-2,5,4,CONCRETE:11)
Block(-2,5,5,CONCRETE:11)
Block(-2,5,6,CONCRETE:11)
Block(-2,5,7,CONCRETE:11)
Block(-2,5,8,CONCRETE:11)
Block(-2,6,-7,CONCRETE:7)
Block(-2,6,-6,CONCRETE:7)
Block(-2,6,-5,CONCRETE:7)
Block(-2,6,-4,CONCRETE:7)
Block(-2,6,-3,CONCRETE:7)
Block(-2,6,-2,CONCRETE:7)
Block(-2,6,-1,CONCRETE:7)
Block(-2,6,0,CONCRETE:7)
Block(-2,6,1,CONCRETE:7)
Block(-2,6,2,CONCRETE:7)
Block(-2,6,3,CONCRETE:7)
Block(-2,6,4,CONCRETE:7)
Block(-2,6,5,CONCRETE:7)
Block(-2,6,6,CONCRETE:7)
Block(-2,6,7,CONCRETE:7)
Block(-2,6,8,CONCRETE:7)
Block(-2,7,-7,CONCRETE:7)
Block(-2,7,-6,CONCRETE:7)
Block(-2,7,-5,CONCRETE:7)
Block(-2,7,-4,CONCRETE:7)
Block(-2,7,-3,CONCRETE:7)
Block(-2,7,-2,CONCRETE:7)
Block(-2,7,-1,CONCRETE:7)
Block(-2,7,0,CONCRETE:7)
Block(-2,7,1,CONCRETE:7)
Block(-2,7,2,CONCRETE:7)
Block(-2,7,3,CONCRETE:7)
Block(-2,7,4,CONCRETE:7)
Block(-2,7,5,CONCRETE:7)
Block(-2,7,6,CONCRETE:7)
Block(-2,7,7,CONCRETE:7)
Block(-2,7,8,CONCRETE:7)
Block(-2,8,-7,CONCRETE:7)
Block(-2,8,-6,CONCRETE:7)
Block(-2,8,-5,CONCRETE:7)
Block(-2,8,-4,CONCRETE:7)
Block(-2,8,-3,CONCRETE:7)
Block(-2,8,-2,CONCRETE:7)
Block(-2,8,-1,CONCRETE:7)
Block(-2,8,0,CONCRETE:7)
Block(-2,8,1,CONCRETE:7)
Block(-2,8,2,CONCRETE:7)
Block(-2,8,3,CONCRETE:7)
Block(-2,8,4,CONCRETE:7)
Block(-2,8,5,CONCRETE:7)
Block(-2,8,6,CONCRETE:7)
Block(-2,8,7,CONCRETE:7)
Block(-2,8,8,CONCRETE:7)
Block(-2,9,-7,CONCRETE:7)
Block(-2,9,-6,CONCRETE:7)
Block(-2,9,-5,CONCRETE:7)
Block(-2,9,-4,CONCRETE:7)
Block(-2,9,-3,CONCRETE:7)
Block(-2,9,-2,CONCRETE:7)
Block(-2,9,-1,CONCRETE:7)
Block(-2,9,0,CONCRETE:7)
Block(-2,9,1,CONCRETE:7)
Block(-2,9,2,CONCRETE:7)
Block(-2,9,3,CONCRETE:7)
Block(-2,9,4,CONCRETE:7)
Block(-2,9,5,CONCRETE:7)
Block(-2,9,6,CONCRETE:7)
Block(-2,9,7,CONCRETE:7)
Block(-2,9,8,CONCRETE:7)
Block(-2,10,-7,CONCRETE:7)
Block(-2,10,-6,CONCRETE:7)
Block(-2,10,-5,CONCRETE:7)
Block(-2,10,-4,CONCRETE:7)
Block(-2,10,-3,CONCRETE:7)
Block(-2,10,-2,CONCRETE:7)
Block(-2,10,-1,CONCRETE:7)
Block(-2,10,0,CONCRETE:7)
Block(-2,10,1,CONCRETE:7)
Block(-2,10,2,CONCRETE:7)
Block(-2,10,3,CONCRETE:7)
Block(-2,10,4,CONCRETE:7)
Block(-2,10,5,CONCRETE:7)
Block(-2,10,6,CONCRETE:7)
Block(-2,10,7,CONCRETE:7)
Block(-2,10,8,CONCRETE:7)
Block(-2,11,-7,CONCRETE:7)
Block(-2,11,-6,CONCRETE:7)
Block(-2,11,-5,CONCRETE:7)
Block(-2,11,-4,CONCRETE:7)
Block(-2,11,-3,CONCRETE:7)
Block(-2,11,-2,CONCRETE:7)
Block(-2,11,-1,CONCRETE:7)
Block(-2,11,0,CONCRETE:7)
Block(-2,11,1,CONCRETE:7)
Block(-2,11,2,CONCRETE:7)
Block(-2,11,3,CONCRETE:7)
Block(-2,11,4,CONCRETE:7)
Block(-2,11,5,CONCRETE:7)
Block(-2,11,6,CONCRETE:7)
Block(-2,11,7,CONCRETE:7)
Block(-2,11,8,CONCRETE:7)
Block(-2,12,-7,CONCRETE:7)
Block(-2,12,-6,CONCRETE:7)
Block(-2,12,-5,CONCRETE:7)
Block(-2,12,-4,CONCRETE:7)
Block(-2,12,-3,CONCRETE:7)
Block(-2,12,-2,CONCRETE:7)
Block(-2,12,-1,CONCRETE:7)
Block(-2,12,0,CONCRETE:7)
Block(-2,12,1,CONCRETE:7)
Block(-2,12,2,CONCRETE:7)
Block(-2,12,3,CONCRETE:7)
Block(-2,12,4,CONCRETE:7)
Block(-2,12,5,CONCRETE:7)
Block(-2,12,6,CONCRETE:7)
Block(-2,12,7,CONCRETE:7)
Block(-2,12,8,CONCRETE:7)
Block(-2,13,-7,CONCRETE:7)
Block(-2,13,-6,CONCRETE:7)
Block(-2,13,-5,CONCRETE:7)
Block(-2,13,-4,CONCRETE:7)
Block(-2,13,-3,CONCRETE:7)
Block(-2,13,-2,CONCRETE:7)
Block(-2,13,-1,CONCRETE:7)
Block(-2,13,0,CONCRETE:7)
Block(-2,13,1,CONCRETE:7)
Block(-2,13,2,CONCRETE:7)
Block(-2,13,3,CONCRETE:7)
Block(-2,13,4,CONCRETE:7)
Block(-2,13,5,CONCRETE:7)
Block(-2,13,6,CONCRETE:7)
Block(-2,13,7,CONCRETE:7)
Block(-2,13,8,CONCRETE:7)
Block(-2,14,-7,CONCRETE:7)
Block(-2,14,-6,CONCRETE:7)
Block(-2,14,-5,CONCRETE:7)
Block(-2,14,-4,CONCRETE:7)
Block(-2,14,-3,CONCRETE:7)
Block(-2,14,-2,CONCRETE:7)
Block(-2,14,-1,CONCRETE:7)
Block(-2,14,0,CONCRETE:7)
Block(-2,14,1,CONCRETE:7)
Block(-2,14,2,CONCRETE:7)
Block(-2,14,3,CONCRETE:7)
Block(-2,14,4,CONCRETE:7)
Block(-2,14,5,CONCRETE:7)
Block(-2,14,6,CONCRETE:7)
Block(-2,14,7,CONCRETE:7)
Block(-2,14,8,CONCRETE:7)
Block(-2,15,-7,CONCRETE:7)
Block(-2,15,-6,CONCRETE:7)
Block(-2,15,-5,CONCRETE:7)
Block(-2,15,-4,CONCRETE:7)
Block(-2,15,-3,CONCRETE:7)
Block(-2,15,-2,CONCRETE:7)
Block(-2,15,-1,CONCRETE:7)
Block(-2,15,0,CONCRETE:7)
Block(-2,15,1,CONCRETE:7)
Block(-2,15,2,CONCRETE:7)
Block(-2,15,3,CONCRETE:7)
Block(-2,15,4,CONCRETE:7)
Block(-2,15,5,CONCRETE:7)
Block(-2,15,6,CONCRETE:7)
Block(-2,15,7,CONCRETE:7)
Block(-2,15,8,CONCRETE:7)
Block(-2,16,-7,CONCRETE:7)
Block(-2,16,-6,CONCRETE:7)
Block(-2,16,-5,CONCRETE:7)
Block(-2,16,-4,CONCRETE:7)
Block(-2,16,-3,CONCRETE:7)
Block(-2,16,-2,CONCRETE:7)
Block(-2,16,-1,CONCRETE:7)
Block(-2,16,0,CONCRETE:7)
Block(-2,16,1,CONCRETE:7)
Block(-2,16,2,CONCRETE:7)
Block(-2,16,3,CONCRETE:7)
Block(-2,16,4,CONCRETE:7)
Block(-2,16,5,CONCRETE:7)
Block(-2,16,6,CONCRETE:7)
Block(-2,16,7,CONCRETE:7)
Block(-2,16,8,CONCRETE:7)
Block(-2,17,-7,CONCRETE:7)
Block(-2,17,-6,STAINED_CLAY:9)
Block(-2,17,-5,SMOOTH_BRICK:0)
Block(-2,17,-4,STAINED_CLAY:9)
Block(-2,17,-3,CONCRETE:7)
Block(-2,17,-2,CONCRETE:7)
Block(-2,17,-1,SMOOTH_BRICK:0)
Block(-2,17,0,STAINED_CLAY:9)
Block(-2,17,1,STAINED_CLAY:9)
Block(-2,17,2,STAINED_CLAY:9)
Block(-2,17,3,CONCRETE:7)
Block(-2,17,4,SMOOTH_BRICK:0)
Block(-2,17,5,CONCRETE:7)
Block(-2,17,6,SMOOTH_BRICK:0)
Block(-2,17,7,SMOOTH_BRICK:0)
Block(-2,17,8,CONCRETE:7)
Block(-1,0,-7,CONCRETE:7)
Block(-1,0,-6,CONCRETE:7)
Block(-1,0,-5,CONCRETE:7)
Block(-1,0,-4,CONCRETE:7)
Block(-1,0,-3,CONCRETE:7)
Block(-1,0,-2,CONCRETE:7)
Block(-1,0,-1,CONCRETE:7)
Block(-1,0,0,CONCRETE:7)
Block(-1,0,1,CONCRETE:7)
Block(-1,0,2,CONCRETE:7)
Block(-1,0,3,CONCRETE:7)
Block(-1,0,4,CONCRETE:7)
Block(-1,0,5,CONCRETE:7)
Block(-1,0,6,CONCRETE:7)
Block(-1,0,7,CONCRETE:7)
Block(-1,0,8,CONCRETE:7)
Block(-1,1,-7,AIR:0)
Block(-1,1,-6,AIR:0)
Block(-1,1,-5,AIR:0)
Block(-1,1,-4,AIR:0)
Block(-1,1,-3,AIR:0)
Block(-1,1,-2,AIR:0)
Block(-1,1,-1,AIR:0)
Block(-1,1,0,AIR:0)
Block(-1,1,1,AIR:0)
Block(-1,1,2,AIR:0)
Block(-1,1,3,AIR:0)
Block(-1,1,4,AIR:0)
Block(-1,1,5,AIR:0)
Block(-1,1,6,AIR:0)
Block(-1,1,7,AIR:0)
Block(-1,1,8,AIR:0)
Block(-1,2,-7,AIR:0)
Block(-1,2,-6,IRON_TRAPDOOR:8)
Block(-1,2,-5,IRON_TRAPDOOR:8)
Block(-1,2,-4,IRON_TRAPDOOR:8)
Block(-1,2,-3,IRON_TRAPDOOR:8)
Block(-1,2,-2,IRON_TRAPDOOR:8)
Block(-1,2,-1,IRON_TRAPDOOR:8)
Block(-1,2,0,IRON_TRAPDOOR:8)
Block(-1,2,1,IRON_TRAPDOOR:8)
Block(-1,2,2,IRON_TRAPDOOR:8)
Block(-1,2,3,IRON_TRAPDOOR:8)
Block(-1,2,4,IRON_TRAPDOOR:8)
Block(-1,2,5,IRON_TRAPDOOR:8)
Block(-1,2,6,IRON_TRAPDOOR:8)
Block(-1,2,7,IRON_TRAPDOOR:8)
Block(-1,2,8,IRON_TRAPDOOR:9)
Block(-1,3,-7,AIR:0)
Block(-1,3,-6,CONCRETE:4)
Block(-1,3,-5,CONCRETE:12)
Block(-1,3,-4,CONCRETE:12)
Block(-1,3,-3,CONCRETE:12)
Block(-1,3,-2,CONCRETE:12)
Block(-1,3,-1,CONCRETE:12)
Block(-1,3,0,CONCRETE:12)
Block(-1,3,1,CONCRETE:12)
Block(-1,3,2,CONCRETE:12)
Block(-1,3,3,CONCRETE:12)
Block(-1,3,4,CONCRETE:12)
Block(-1,3,5,CONCRETE:12)
Block(-1,3,6,CONCRETE:12)
Block(-1,3,7,CONCRETE:12)
Block(-1,3,8,CONCRETE:12)
Block(-1,4,-7,AIR:0)
Block(-1,4,-6,CONCRETE:4)
Block(-1,4,-5,CONCRETE:12)
Block(-1,4,-4,CONCRETE:14)
Block(-1,4,-3,AIR:0)
Block(-1,4,-2,AIR:0)
Block(-1,4,-1,AIR:0)
Block(-1,4,0,AIR:0)
Block(-1,4,1,AIR:0)
Block(-1,4,2,AIR:0)
Block(-1,4,3,AIR:0)
Block(-1,4,4,AIR:0)
Block(-1,4,5,AIR:0)
Block(-1,4,6,AIR:0)
Block(-1,4,7,AIR:0)
Block(-1,4,8,AIR:0)
Block(-1,5,-7,AIR:0)
Block(-1,5,-6,CONCRETE:4)
Block(-1,5,-5,CONCRETE:12)
Block(-1,5,-4,CONCRETE:14)
Block(-1,5,-3,CONCRETE:14)
Block(-1,5,-2,CONCRETE:14)
Block(-1,5,-1,CONCRETE:14)
Block(-1,5,0,CONCRETE:14)
Block(-1,5,1,CONCRETE:14)
Block(-1,5,2,CONCRETE:14)
Block(-1,5,3,CONCRETE:14)
Block(-1,5,4,CONCRETE:14)
Block(-1,5,5,CONCRETE:14)
Block(-1,5,6,CONCRETE:14)
Block(-1,5,7,CONCRETE:14)
Block(-1,5,8,CONCRETE:14)
Block(-1,6,-7,CONCRETE:7)
Block(-1,6,-6,CONCRETE:7)
Block(-1,6,-5,CONCRETE:12)
Block(-1,6,-4,CONCRETE:7)
Block(-1,6,-3,CONCRETE:7)
Block(-1,6,-2,CONCRETE:7)
Block(-1,6,-1,CONCRETE:7)
Block(-1,6,0,CONCRETE:7)
Block(-1,6,1,CONCRETE:7)
Block(-1,6,2,CONCRETE:7)
Block(-1,6,3,CONCRETE:7)
Block(-1,6,4,CONCRETE:7)
Block(-1,6,5,CONCRETE:7)
Block(-1,6,6,CONCRETE:7)
Block(-1,6,7,CONCRETE:7)
Block(-1,6,8,CONCRETE:7)
Block(-1,7,-7,DROPPER:1,NBT/skyscraper_3x3_03/1-dropperC0R16.nbt)
Block(-1,7,-6,DROPPER:1,NBT/skyscraper_3x3_03/2-dropperC0R16.nbt)
Block(-1,7,-5,CONCRETE:12)
Block(-1,7,-4,CONCRETE:7)
Block(-1,7,-3,CONCRETE:7)
Block(-1,7,-2,CONCRETE:7)
Block(-1,7,-1,CONCRETE:7)
Block(-1,7,0,CONCRETE:7)
Block(-1,7,1,CONCRETE:7)
Block(-1,7,2,CONCRETE:7)
Block(-1,7,3,CONCRETE:7)
Block(-1,7,4,CONCRETE:7)
Block(-1,7,5,CONCRETE:7)
Block(-1,7,6,CONCRETE:7)
Block(-1,7,7,CONCRETE:7)
Block(-1,7,8,CONCRETE:7)
Block(-1,8,-7,CONCRETE:7)
Block(-1,8,-6,CONCRETE:7)
Block(-1,8,-5,CONCRETE:7)
Block(-1,8,-4,CONCRETE:7)
Block(-1,8,-3,CONCRETE:7)
Block(-1,8,-2,CONCRETE:7)
Block(-1,8,-1,CONCRETE:7)
Block(-1,8,0,CONCRETE:7)
Block(-1,8,1,CONCRETE:7)
Block(-1,8,2,CONCRETE:7)
Block(-1,8,3,CONCRETE:7)
Block(-1,8,4,CONCRETE:7)
Block(-1,8,5,CONCRETE:7)
Block(-1,8,6,CONCRETE:7)
Block(-1,8,7,CONCRETE:7)
Block(-1,8,8,CONCRETE:7)
Block(-1,9,-7,CONCRETE:7)
Block(-1,9,-6,CONCRETE:7)
Block(-1,9,-5,CONCRETE:7)
Block(-1,9,-4,CONCRETE:7)
Block(-1,9,-3,CONCRETE:7)
Block(-1,9,-2,CONCRETE:7)
Block(-1,9,-1,CONCRETE:7)
Block(-1,9,0,CONCRETE:7)
Block(-1,9,1,CONCRETE:7)
Block(-1,9,2,CONCRETE:7)
Block(-1,9,3,CONCRETE:7)
Block(-1,9,4,CONCRETE:7)
Block(-1,9,5,CONCRETE:7)
Block(-1,9,6,CONCRETE:7)
Block(-1,9,7,CONCRETE:7)
Block(-1,9,8,CONCRETE:7)
Block(-1,10,-7,CONCRETE:7)
Block(-1,10,-6,CONCRETE:7)
Block(-1,10,-5,CONCRETE:7)
Block(-1,10,-4,CONCRETE:7)
Block(-1,10,-3,CONCRETE:7)
Block(-1,10,-2,CONCRETE:7)
Block(-1,10,-1,CONCRETE:7)
Block(-1,10,0,CONCRETE:7)
Block(-1,10,1,CONCRETE:7)
Block(-1,10,2,CONCRETE:7)
Block(-1,10,3,CONCRETE:7)
Block(-1,10,4,CONCRETE:7)
Block(-1,10,5,CONCRETE:7)
Block(-1,10,6,CONCRETE:7)
Block(-1,10,7,CONCRETE:7)
Block(-1,10,8,CONCRETE:7)
Block(-1,11,-7,CONCRETE:7)
Block(-1,11,-6,CONCRETE:7)
Block(-1,11,-5,CONCRETE:7)
Block(-1,11,-4,CONCRETE:7)
Block(-1,11,-3,CONCRETE:7)
Block(-1,11,-2,CONCRETE:7)
Block(-1,11,-1,CONCRETE:7)
Block(-1,11,0,CONCRETE:7)
Block(-1,11,1,CONCRETE:7)
Block(-1,11,2,CONCRETE:7)
Block(-1,11,3,CONCRETE:7)
Block(-1,11,4,CONCRETE:7)
Block(-1,11,5,CONCRETE:7)
Block(-1,11,6,CONCRETE:7)
Block(-1,11,7,CONCRETE:7)
Block(-1,11,8,CONCRETE:7)
Block(-1,12,-7,CONCRETE:7)
Block(-1,12,-6,CONCRETE:7)
Block(-1,12,-5,CONCRETE:7)
Block(-1,12,-4,CONCRETE:7)
Block(-1,12,-3,CONCRETE:7)
Block(-1,12,-2,CONCRETE:7)
Block(-1,12,-1,CONCRETE:7)
Block(-1,12,0,CONCRETE:7)
Block(-1,12,1,CONCRETE:7)
Block(-1,12,2,CONCRETE:7)
Block(-1,12,3,CONCRETE:7)
Block(-1,12,4,CONCRETE:7)
Block(-1,12,5,CONCRETE:7)
Block(-1,12,6,CONCRETE:7)
Block(-1,12,7,CONCRETE:7)
Block(-1,12,8,CONCRETE:7)
Block(-1,13,-7,CONCRETE:7)
Block(-1,13,-6,CONCRETE:7)
Block(-1,13,-5,CONCRETE:7)
Block(-1,13,-4,CONCRETE:7)
Block(-1,13,-3,CONCRETE:7)
Block(-1,13,-2,CONCRETE:7)
Block(-1,13,-1,CONCRETE:7)
Block(-1,13,0,CONCRETE:7)
Block(-1,13,1,CONCRETE:7)
Block(-1,13,2,CONCRETE:7)
Block(-1,13,3,CONCRETE:7)
Block(-1,13,4,CONCRETE:7)
Block(-1,13,5,CONCRETE:7)
Block(-1,13,6,CONCRETE:7)
Block(-1,13,7,CONCRETE:7)
Block(-1,13,8,CONCRETE:7)
Block(-1,14,-7,CONCRETE:7)
Block(-1,14,-6,CONCRETE:7)
Block(-1,14,-5,CONCRETE:7)
Block(-1,14,-4,CONCRETE:7)
Block(-1,14,-3,CONCRETE:7)
Block(-1,14,-2,CONCRETE:7)
Block(-1,14,-1,CONCRETE:7)
Block(-1,14,0,CONCRETE:7)
Block(-1,14,1,CONCRETE:7)
Block(-1,14,2,CONCRETE:7)
Block(-1,14,3,CONCRETE:7)
Block(-1,14,4,CONCRETE:7)
Block(-1,14,5,CONCRETE:7)
Block(-1,14,6,CONCRETE:7)
Block(-1,14,7,CONCRETE:7)
Block(-1,14,8,CONCRETE:7)
Block(-1,15,-7,CONCRETE:7)
Block(-1,15,-6,CONCRETE:7)
Block(-1,15,-5,CONCRETE:7)
Block(-1,15,-4,CONCRETE:7)
Block(-1,15,-3,CONCRETE:7)
Block(-1,15,-2,CONCRETE:7)
Block(-1,15,-1,CONCRETE:7)
Block(-1,15,0,CONCRETE:7)
Block(-1,15,1,CONCRETE:7)
Block(-1,15,2,CONCRETE:7)
Block(-1,15,3,CONCRETE:7)
Block(-1,15,4,CONCRETE:7)
Block(-1,15,5,CONCRETE:7)
Block(-1,15,6,CONCRETE:7)
Block(-1,15,7,CONCRETE:7)
Block(-1,15,8,CONCRETE:7)
Block(-1,16,-7,CONCRETE:7)
Block(-1,16,-6,CONCRETE:7)
Block(-1,16,-5,CONCRETE:7)
Block(-1,16,-4,CONCRETE:7)
Block(-1,16,-3,CONCRETE:7)
Block(-1,16,-2,CONCRETE:7)
Block(-1,16,-1,CONCRETE:7)
Block(-1,16,0,CONCRETE:7)
Block(-1,16,1,CONCRETE:7)
Block(-1,16,2,CONCRETE:7)
Block(-1,16,3,CONCRETE:7)
Block(-1,16,4,CONCRETE:7)
Block(-1,16,5,CONCRETE:7)
Block(-1,16,6,CONCRETE:7)
Block(-1,16,7,CONCRETE:7)
Block(-1,16,8,CONCRETE:7)
Block(-1,17,-7,DOUBLE_STEP:0)
Block(-1,17,-6,DOUBLE_STEP:0)
Block(-1,17,-5,DOUBLE_STEP:0)
Block(-1,17,-4,DOUBLE_STEP:0)
Block(-1,17,-3,DOUBLE_STEP:0)
Block(-1,17,-2,DOUBLE_STEP:0)
Block(-1,17,-1,DOUBLE_STEP:0)
Block(-1,17,0,DOUBLE_STEP:0)
Block(-1,17,1,DOUBLE_STEP:0)
Block(-1,17,2,DOUBLE_STEP:0)
Block(-1,17,3,DOUBLE_STEP:0)
Block(-1,17,4,DOUBLE_STEP:0)
Block(-1,17,5,DOUBLE_STEP:0)
Block(-1,17,6,DOUBLE_STEP:0)
Block(-1,17,7,DOUBLE_STEP:0)
Block(-1,17,8,DOUBLE_STEP:0)
Block(0,0,-7,CONCRETE:7)
Block(0,0,-6,CONCRETE:7)
Block(0,0,-5,CONCRETE:7)
Block(0,0,-4,CONCRETE:7)
Block(0,0,-3,CONCRETE:7)
Block(0,0,-2,CONCRETE:7)
Block(0,0,-1,CONCRETE:7)
Block(0,0,0,CONCRETE:7)
Block(0,0,1,CONCRETE:7)
Block(0,0,2,CONCRETE:7)
Block(0,0,3,CONCRETE:7)
Block(0,0,4,CONCRETE:7)
Block(0,0,5,CONCRETE:7)
Block(0,0,6,CONCRETE:7)
Block(0,0,7,CONCRETE:7)
Block(0,0,8,CONCRETE:7)
Block(0,1,-7,CONCRETE:7)
Block(0,1,-6,CONCRETE:7)
Block(0,1,-5,CONCRETE:7)
Block(0,1,-4,CONCRETE:7)
Block(0,1,-3,CONCRETE:7)
Block(0,1,-2,CONCRETE:7)
Block(0,1,-1,CONCRETE:7)
Block(0,1,0,CONCRETE:7)
Block(0,1,1,CONCRETE:7)
Block(0,1,2,CONCRETE:7)
Block(0,1,3,CONCRETE:7)
Block(0,1,4,CONCRETE:7)
Block(0,1,5,CONCRETE:7)
Block(0,1,6,CONCRETE:7)
Block(0,1,7,CONCRETE:7)
Block(0,1,8,CONCRETE:7)
Block(0,2,-7,CONCRETE:7)
Block(0,2,-6,CONCRETE:7)
Block(0,2,-5,CONCRETE:7)
Block(0,2,-4,CONCRETE:7)
Block(0,2,-3,CONCRETE:7)
Block(0,2,-2,CONCRETE:7)
Block(0,2,-1,CONCRETE:7)
Block(0,2,0,CONCRETE:7)
Block(0,2,1,CONCRETE:7)
Block(0,2,2,CONCRETE:7)
Block(0,2,3,CONCRETE:7)
Block(0,2,4,CONCRETE:7)
Block(0,2,5,CONCRETE:7)
Block(0,2,6,CONCRETE:7)
Block(0,2,7,CONCRETE:7)
Block(0,2,8,CONCRETE:7)
Block(0,3,-7,CONCRETE:7)
Block(0,3,-6,IRON_FENCE:0)
Block(0,3,-5,IRON_FENCE:0)
Block(0,3,-4,CONCRETE:7)
Block(0,3,-3,IRON_FENCE:0)
Block(0,3,-2,IRON_FENCE:0)
Block(0,3,-1,CONCRETE:7)
Block(0,3,0,IRON_FENCE:0)
Block(0,3,1,IRON_FENCE:0)
Block(0,3,2,CONCRETE:7)
Block(0,3,3,IRON_FENCE:0)
Block(0,3,4,IRON_FENCE:0)
Block(0,3,5,CONCRETE:7)
Block(0,3,6,IRON_FENCE:0)
Block(0,3,7,IRON_FENCE:0)
Block(0,3,8,CONCRETE:7)
Block(0,4,-7,CONCRETE:7)
Block(0,4,-6,IRON_FENCE:0)
Block(0,4,-5,IRON_FENCE:0)
Block(0,4,-4,CONCRETE:7)
Block(0,4,-3,IRON_FENCE:0)
Block(0,4,-2,IRON_FENCE:0)
Block(0,4,-1,CONCRETE:7)
Block(0,4,0,IRON_FENCE:0)
Block(0,4,1,IRON_FENCE:0)
Block(0,4,2,CONCRETE:7)
Block(0,4,3,IRON_FENCE:0)
Block(0,4,4,IRON_FENCE:0)
Block(0,4,5,CONCRETE:7)
Block(0,4,6,IRON_FENCE:0)
Block(0,4,7,IRON_FENCE:0)
Block(0,4,8,CONCRETE:7)
Block(0,5,-7,CONCRETE:7)
Block(0,5,-6,CONCRETE:4)
Block(0,5,-5,CONCRETE:12)
Block(0,5,-4,CONCRETE:7)
Block(0,5,-3,IRON_FENCE:0)
Block(0,5,-2,IRON_FENCE:0)
Block(0,5,-1,CONCRETE:7)
Block(0,5,0,IRON_FENCE:0)
Block(0,5,1,IRON_FENCE:0)
Block(0,5,2,CONCRETE:7)
Block(0,5,3,IRON_FENCE:0)
Block(0,5,4,IRON_FENCE:0)
Block(0,5,5,CONCRETE:7)
Block(0,5,6,IRON_FENCE:0)
Block(0,5,7,IRON_FENCE:0)
Block(0,5,8,CONCRETE:7)
Block(0,6,-7,CONCRETE:7)
Block(0,6,-6,CONCRETE:7)
Block(0,6,-5,CONCRETE:7)
Block(0,6,-4,CONCRETE:7)
Block(0,6,-3,CONCRETE:7)
Block(0,6,-2,CONCRETE:7)
Block(0,6,-1,CONCRETE:7)
Block(0,6,0,CONCRETE:7)
Block(0,6,1,CONCRETE:7)
Block(0,6,2,CONCRETE:7)
Block(0,6,3,CONCRETE:7)
Block(0,6,4,CONCRETE:7)
Block(0,6,5,CONCRETE:7)
Block(0,6,6,CONCRETE:7)
Block(0,6,7,CONCRETE:7)
Block(0,6,8,CONCRETE:7)
Block(0,7,-7,CONCRETE:7)
Block(0,7,-6,CONCRETE:7)
Block(0,7,-5,CONCRETE:7)
Block(0,7,-4,CONCRETE:7)
Block(0,7,-3,CONCRETE:7)
Block(0,7,-2,CONCRETE:7)
Block(0,7,-1,CONCRETE:7)
Block(0,7,0,CONCRETE:7)
Block(0,7,1,CONCRETE:7)
Block(0,7,2,CONCRETE:7)
Block(0,7,3,CONCRETE:7)
Block(0,7,4,CONCRETE:7)
Block(0,7,5,CONCRETE:7)
Block(0,7,6,CONCRETE:7)
Block(0,7,7,CONCRETE:7)
Block(0,7,8,CONCRETE:7)
Block(0,8,-7,CONCRETE:7)
Block(0,8,-6,CONCRETE:7)
Block(0,8,-5,CONCRETE:7)
Block(0,8,-4,CONCRETE:7)
Block(0,8,-3,CONCRETE:7)
Block(0,8,-2,CONCRETE:7)
Block(0,8,-1,CONCRETE:7)
Block(0,8,0,CONCRETE:7)
Block(0,8,1,CONCRETE:7)
Block(0,8,2,CONCRETE:7)
Block(0,8,3,CONCRETE:7)
Block(0,8,4,CONCRETE:7)
Block(0,8,5,CONCRETE:7)
Block(0,8,6,CONCRETE:7)
Block(0,8,7,CONCRETE:7)
Block(0,8,8,CONCRETE:7)
Block(0,9,-7,CONCRETE:7)
Block(0,9,-6,CONCRETE:7)
Block(0,9,-5,CONCRETE:7)
Block(0,9,-4,CONCRETE:7)
Block(0,9,-3,CONCRETE:7)
Block(0,9,-2,CONCRETE:7)
Block(0,9,-1,CONCRETE:7)
Block(0,9,0,CONCRETE:7)
Block(0,9,1,CONCRETE:7)
Block(0,9,2,CONCRETE:7)
Block(0,9,3,CONCRETE:7)
Block(0,9,4,CONCRETE:7)
Block(0,9,5,CONCRETE:7)
Block(0,9,6,CONCRETE:7)
Block(0,9,7,CONCRETE:7)
Block(0,9,8,CONCRETE:7)
Block(0,10,-7,CONCRETE:7)
Block(0,10,-6,CONCRETE:7)
Block(0,10,-5,CONCRETE:7)
Block(0,10,-4,CONCRETE:7)
Block(0,10,-3,CONCRETE:7)
Block(0,10,-2,CONCRETE:7)
Block(0,10,-1,CONCRETE:7)
Block(0,10,0,CONCRETE:7)
Block(0,10,1,CONCRETE:7)
Block(0,10,2,CONCRETE:7)
Block(0,10,3,CONCRETE:7)
Block(0,10,4,CONCRETE:7)
Block(0,10,5,CONCRETE:7)
Block(0,10,6,CONCRETE:7)
Block(0,10,7,CONCRETE:7)
Block(0,10,8,CONCRETE:7)
Block(0,11,-7,CONCRETE:7)
Block(0,11,-6,CONCRETE:7)
Block(0,11,-5,CONCRETE:7)
Block(0,11,-4,CONCRETE:7)
Block(0,11,-3,CONCRETE:7)
Block(0,11,-2,CONCRETE:7)
Block(0,11,-1,CONCRETE:7)
Block(0,11,0,CONCRETE:7)
Block(0,11,1,CONCRETE:7)
Block(0,11,2,CONCRETE:7)
Block(0,11,3,CONCRETE:7)
Block(0,11,4,CONCRETE:7)
Block(0,11,5,CONCRETE:7)
Block(0,11,6,CONCRETE:7)
Block(0,11,7,CONCRETE:7)
Block(0,11,8,CONCRETE:7)
Block(0,12,-7,CONCRETE:7)
Block(0,12,-6,CONCRETE:7)
Block(0,12,-5,CONCRETE:7)
Block(0,12,-4,CONCRETE:7)
Block(0,12,-3,CONCRETE:7)
Block(0,12,-2,CONCRETE:7)
Block(0,12,-1,CONCRETE:7)
Block(0,12,0,CONCRETE:7)
Block(0,12,1,CONCRETE:7)
Block(0,12,2,CONCRETE:7)
Block(0,12,3,CONCRETE:7)
Block(0,12,4,CONCRETE:7)
Block(0,12,5,CONCRETE:7)
Block(0,12,6,CONCRETE:7)
Block(0,12,7,CONCRETE:7)
Block(0,12,8,CONCRETE:7)
Block(0,13,-7,CONCRETE:7)
Block(0,13,-6,CONCRETE:7)
Block(0,13,-5,CONCRETE:7)
Block(0,13,-4,CONCRETE:7)
Block(0,13,-3,CONCRETE:7)
Block(0,13,-2,CONCRETE:7)
Block(0,13,-1,CONCRETE:7)
Block(0,13,0,CONCRETE:7)
Block(0,13,1,CONCRETE:7)
Block(0,13,2,CONCRETE:7)
Block(0,13,3,CONCRETE:7)
Block(0,13,4,CONCRETE:7)
Block(0,13,5,CONCRETE:7)
Block(0,13,6,CONCRETE:7)
Block(0,13,7,CONCRETE:7)
Block(0,13,8,CONCRETE:7)
Block(0,14,-7,CONCRETE:7)
Block(0,14,-6,CONCRETE:7)
Block(0,14,-5,CONCRETE:7)
Block(0,14,-4,CONCRETE:7)
Block(0,14,-3,CONCRETE:7)
Block(0,14,-2,CONCRETE:7)
Block(0,14,-1,CONCRETE:7)
Block(0,14,0,CONCRETE:7)
Block(0,14,1,CONCRETE:7)
Block(0,14,2,CONCRETE:7)
Block(0,14,3,CONCRETE:7)
Block(0,14,4,CONCRETE:7)
Block(0,14,5,CONCRETE:7)
Block(0,14,6,CONCRETE:7)
Block(0,14,7,CONCRETE:7)
Block(0,14,8,CONCRETE:7)
Block(0,15,-7,CONCRETE:7)
Block(0,15,-6,CONCRETE:7)
Block(0,15,-5,CONCRETE:7)
Block(0,15,-4,CONCRETE:7)
Block(0,15,-3,CONCRETE:7)
Block(0,15,-2,CONCRETE:7)
Block(0,15,-1,CONCRETE:7)
Block(0,15,0,CONCRETE:7)
Block(0,15,1,CONCRETE:7)
Block(0,15,2,CONCRETE:7)
Block(0,15,3,CONCRETE:7)
Block(0,15,4,CONCRETE:7)
Block(0,15,5,CONCRETE:7)
Block(0,15,6,CONCRETE:7)
Block(0,15,7,CONCRETE:7)
Block(0,15,8,CONCRETE:7)
Block(0,16,-7,CONCRETE:7)
Block(0,16,-6,CONCRETE:7)
Block(0,16,-5,CONCRETE:7)
Block(0,16,-4,CONCRETE:7)
Block(0,16,-3,CONCRETE:7)
Block(0,16,-2,CONCRETE:7)
Block(0,16,-1,CONCRETE:7)
Block(0,16,0,CONCRETE:7)
Block(0,16,1,CONCRETE:7)
Block(0,16,2,CONCRETE:7)
Block(0,16,3,CONCRETE:7)
Block(0,16,4,CONCRETE:7)
Block(0,16,5,CONCRETE:7)
Block(0,16,6,CONCRETE:7)
Block(0,16,7,CONCRETE:7)
Block(0,16,8,CONCRETE:7)
Block(0,17,-7,CONCRETE:7)
Block(0,17,-6,CONCRETE:7)
Block(0,17,-5,CONCRETE:7)
Block(0,17,-4,CONCRETE:7)
Block(0,17,-3,CONCRETE:7)
Block(0,17,-2,CONCRETE:7)
Block(0,17,-1,CONCRETE:7)
Block(0,17,0,CONCRETE:7)
Block(0,17,1,CONCRETE:7)
Block(0,17,2,CONCRETE:7)
Block(0,17,3,CONCRETE:7)
Block(0,17,4,CONCRETE:7)
Block(0,17,5,CONCRETE:7)
Block(0,17,6,CONCRETE:7)
Block(0,17,7,CONCRETE:7)
Block(0,17,8,CONCRETE:7)
Block(0,18,-6,CONCRETE:0)
Block(0,18,-5,CONCRETE:0)
Block(0,18,-4,CONCRETE:0)
Block(0,18,6,minecraft:black_glazed_terracotta)
Block(0,18,7,minecraft:black_glazed_terracotta)
Block(0,18,8,minecraft:black_glazed_terracotta)
Block(0,19,-6,CONCRETE:0)
Block(0,19,-5,CONCRETE:0)
Block(0,19,-4,CONCRETE:0)
Block(0,19,6,minecraft:black_glazed_terracotta)
Block(0,19,7,minecraft:black_glazed_terracotta)
Block(0,19,8,minecraft:black_glazed_terracotta)
Block(0,20,-6,CONCRETE:0)
Block(0,20,-5,CONCRETE:0)
Block(0,20,-4,CONCRETE:0)
Block(0,20,6,minecraft:black_glazed_terracotta)
Block(0,20,7,minecraft:black_glazed_terracotta)
Block(0,20,8,minecraft:black_glazed_terracotta)
Block(0,21,-6,CONCRETE:0)
Block(0,21,-5,CONCRETE:0)
Block(0,21,-4,CONCRETE:0)
Block(0,22,-6,CONCRETE:0)
Block(0,22,-5,CONCRETE:0)
Block(0,22,-4,CONCRETE:0)
Block(0,22,-2,minecraft:black_glazed_terracotta)
Block(0,22,-1,minecraft:black_glazed_terracotta)
Block(0,22,0,minecraft:black_glazed_terracotta)
Block(0,22,2,CONCRETE:0)
Block(0,22,3,CONCRETE:0)
Block(0,22,4,CONCRETE:0)
Block(0,22,6,CONCRETE:15)
Block(0,22,7,CONCRETE:15)
Block(0,22,8,CONCRETE:15)
Block(0,23,-6,CONCRETE:0)
Block(0,23,-5,CONCRETE:0)
Block(0,23,-4,CONCRETE:0)
Block(0,23,-2,minecraft:black_glazed_terracotta)
Block(0,23,-1,minecraft:black_glazed_terracotta)
Block(0,23,0,minecraft:black_glazed_terracotta)
Block(0,23,2,CONCRETE:0)
Block(0,23,3,CONCRETE:0)
Block(0,23,4,CONCRETE:0)
Block(0,23,6,CONCRETE:15)
Block(0,23,7,CONCRETE:15)
Block(0,23,8,CONCRETE:15)
Block(0,24,-6,CONCRETE:0)
Block(0,24,-5,CONCRETE:0)
Block(0,24,-4,CONCRETE:0)
Block(0,24,-2,minecraft:black_glazed_terracotta)
Block(0,24,-1,minecraft:black_glazed_terracotta)
Block(0,24,0,minecraft:black_glazed_terracotta)
Block(0,24,2,CONCRETE:0)
Block(0,24,3,CONCRETE:0)
Block(0,24,4,CONCRETE:0)
Block(0,24,6,CONCRETE:15)
Block(0,24,7,CONCRETE:15)
Block(0,24,8,CONCRETE:15)
Block(0,25,-6,CONCRETE:0)
Block(0,25,-5,CONCRETE:0)
Block(0,25,-4,CONCRETE:0)
Block(0,25,2,CONCRETE:0)
Block(0,25,3,CONCRETE:0)
Block(0,25,4,CONCRETE:0)
Block(0,26,-6,CONCRETE:0)
Block(0,26,-5,CONCRETE:0)
Block(0,26,-4,CONCRETE:0)
Block(0,26,-3,CONCRETE:0)
Block(0,26,-2,CONCRETE:0)
Block(0,26,-1,CONCRETE:0)
Block(0,26,0,CONCRETE:0)
Block(0,26,2,CONCRETE:0)
Block(0,26,3,CONCRETE:0)
Block(0,26,4,CONCRETE:0)
Block(0,27,-6,CONCRETE:0)
Block(0,27,-5,CONCRETE:0)
Block(0,27,-4,CONCRETE:0)
Block(0,27,-3,CONCRETE:0)
Block(0,27,-2,CONCRETE:0)
Block(0,27,-1,CONCRETE:0)
Block(0,27,0,CONCRETE:0)
Block(0,27,2,CONCRETE:0)
Block(0,27,3,CONCRETE:0)
Block(0,27,4,CONCRETE:0)
Block(0,28,-6,CONCRETE:0)
Block(0,28,-5,CONCRETE:0)
Block(0,28,-4,CONCRETE:0)
Block(0,28,-3,CONCRETE:0)
Block(0,28,-2,CONCRETE:0)
Block(0,28,-1,CONCRETE:0)
Block(0,28,0,CONCRETE:0)
Block(0,28,2,CONCRETE:0)
Block(0,28,3,CONCRETE:0)
Block(0,28,4,CONCRETE:0)
Block(0,29,2,CONCRETE:0)
Block(0,29,3,CONCRETE:0)
Block(0,29,4,CONCRETE:0)
Block(0,30,-6,CONCRETE:10)
Block(0,30,-5,CONCRETE:10)
Block(0,30,-4,CONCRETE:10)
Block(0,30,2,CONCRETE:0)
Block(0,30,3,CONCRETE:0)
Block(0,30,4,CONCRETE:0)
Block(0,30,5,CONCRETE:0)
Block(0,30,6,CONCRETE:0)
Block(0,30,7,CONCRETE:0)
Block(0,30,8,CONCRETE:0)
Block(0,31,-6,CONCRETE:10)
Block(0,31,-5,CONCRETE:10)
Block(0,31,-4,CONCRETE:10)
Block(0,31,2,CONCRETE:0)
Block(0,31,3,CONCRETE:0)
Block(0,31,4,CONCRETE:0)
Block(0,31,5,CONCRETE:0)
Block(0,31,6,CONCRETE:0)
Block(0,31,7,CONCRETE:0)
Block(0,31,8,CONCRETE:0)
Block(0,32,-6,CONCRETE:10)
Block(0,32,-5,CONCRETE:10)
Block(0,32,-4,CONCRETE:10)
Block(0,32,2,CONCRETE:0)
Block(0,32,3,CONCRETE:0)
Block(0,32,4,CONCRETE:0)
Block(0,32,5,CONCRETE:0)
Block(0,32,6,CONCRETE:0)
Block(0,32,7,CONCRETE:0)
Block(0,32,8,CONCRETE:0)
Block(0,34,-6,CONCRETE:0)
Block(0,34,-5,CONCRETE:0)
Block(0,34,-4,CONCRETE:0)
Block(0,34,-2,minecraft:purple_glazed_terracotta)
Block(0,34,-1,minecraft:purple_glazed_terracotta)
Block(0,34,0,minecraft:purple_glazed_terracotta)
Block(0,34,2,minecraft:black_glazed_terracotta)
Block(0,34,3,minecraft:black_glazed_terracotta)
Block(0,34,4,minecraft:black_glazed_terracotta)
Block(0,34,6,CONCRETE:15)
Block(0,34,7,CONCRETE:15)
Block(0,34,8,CONCRETE:15)
Block(0,35,-6,CONCRETE:0)
Block(0,35,-5,CONCRETE:0)
Block(0,35,-4,CONCRETE:0)
Block(0,35,-2,minecraft:purple_glazed_terracotta)
Block(0,35,-1,minecraft:purple_glazed_terracotta)
Block(0,35,0,minecraft:purple_glazed_terracotta)
Block(0,35,2,minecraft:black_glazed_terracotta)
Block(0,35,3,minecraft:black_glazed_terracotta)
Block(0,35,4,minecraft:black_glazed_terracotta)
Block(0,35,6,CONCRETE:15)
Block(0,35,7,CONCRETE:15)
Block(0,35,8,CONCRETE:15)
Block(0,36,-6,CONCRETE:0)
Block(0,36,-5,CONCRETE:0)
Block(0,36,-4,CONCRETE:0)
Block(0,36,-2,minecraft:purple_glazed_terracotta)
Block(0,36,-1,minecraft:purple_glazed_terracotta)
Block(0,36,0,minecraft:purple_glazed_terracotta)
Block(0,36,2,minecraft:black_glazed_terracotta)
Block(0,36,3,minecraft:black_glazed_terracotta)
Block(0,36,4,minecraft:black_glazed_terracotta)
Block(0,36,6,CONCRETE:15)
Block(0,36,7,CONCRETE:15)
Block(0,36,8,CONCRETE:15)
Block(0,38,-6,CONCRETE:0)
Block(0,38,-5,CONCRETE:0)
Block(0,38,-4,CONCRETE:0)
Block(0,38,-2,CONCRETE:0)
Block(0,38,-1,CONCRETE:0)
Block(0,38,0,CONCRETE:0)
Block(0,38,6,minecraft:black_glazed_terracotta)
Block(0,38,7,minecraft:black_glazed_terracotta)
Block(0,38,8,minecraft:black_glazed_terracotta)
Block(0,39,-6,CONCRETE:0)
Block(0,39,-5,CONCRETE:0)
Block(0,39,-4,CONCRETE:0)
Block(0,39,-2,CONCRETE:0)
Block(0,39,-1,CONCRETE:0)
Block(0,39,0,CONCRETE:0)
Block(0,39,6,minecraft:black_glazed_terracotta)
Block(0,39,7,minecraft:black_glazed_terracotta)
Block(0,39,8,minecraft:black_glazed_terracotta)
Block(0,40,-6,CONCRETE:0)
Block(0,40,-5,CONCRETE:0)
Block(0,40,-4,CONCRETE:0)
Block(0,40,-2,CONCRETE:0)
Block(0,40,-1,CONCRETE:0)
Block(0,40,0,CONCRETE:0)
Block(0,40,6,minecraft:black_glazed_terracotta)
Block(0,40,7,minecraft:black_glazed_terracotta)
Block(0,40,8,minecraft:black_glazed_terracotta)
Block(0,42,-2,minecraft:black_glazed_terracotta)
Block(0,42,-1,minecraft:black_glazed_terracotta)
Block(0,42,0,minecraft:black_glazed_terracotta)
Block(0,42,2,CONCRETE:0)
Block(0,42,3,CONCRETE:0)
Block(0,42,4,CONCRETE:0)
Block(0,42,6,minecraft:purple_glazed_terracotta)
Block(0,42,7,minecraft:purple_glazed_terracotta)
Block(0,42,8,minecraft:purple_glazed_terracotta)
Block(0,43,-2,minecraft:black_glazed_terracotta)
Block(0,43,-1,minecraft:black_glazed_terracotta)
Block(0,43,0,minecraft:black_glazed_terracotta)
Block(0,43,2,CONCRETE:0)
Block(0,43,3,CONCRETE:0)
Block(0,43,4,CONCRETE:0)
Block(0,43,6,minecraft:purple_glazed_terracotta)
Block(0,43,7,minecraft:purple_glazed_terracotta)
Block(0,43,8,minecraft:purple_glazed_terracotta)
Block(0,44,-2,minecraft:black_glazed_terracotta)
Block(0,44,-1,minecraft:black_glazed_terracotta)
Block(0,44,0,minecraft:black_glazed_terracotta)
Block(0,44,2,CONCRETE:0)
Block(0,44,3,CONCRETE:0)
Block(0,44,4,CONCRETE:0)
Block(0,44,6,minecraft:purple_glazed_terracotta)
Block(0,44,7,minecraft:purple_glazed_terracotta)
Block(0,44,8,minecraft:purple_glazed_terracotta)
Block(0,45,2,CONCRETE:0)
Block(0,45,3,CONCRETE:0)
Block(0,45,4,CONCRETE:0)
Block(0,46,-6,minecraft:black_glazed_terracotta)
Block(0,46,-5,minecraft:black_glazed_terracotta)
Block(0,46,-4,minecraft:black_glazed_terracotta)
Block(0,46,-2,CONCRETE:0)
Block(0,46,-1,CONCRETE:0)
Block(0,46,0,CONCRETE:0)
Block(0,46,1,CONCRETE:0)
Block(0,46,2,CONCRETE:0)
Block(0,46,3,CONCRETE:0)
Block(0,46,4,CONCRETE:0)
Block(0,47,-6,minecraft:black_glazed_terracotta)
Block(0,47,-5,minecraft:black_glazed_terracotta)
Block(0,47,-4,minecraft:black_glazed_terracotta)
Block(0,47,-2,CONCRETE:0)
Block(0,47,-1,CONCRETE:0)
Block(0,47,0,CONCRETE:0)
Block(0,47,1,CONCRETE:0)
Block(0,47,2,CONCRETE:0)
Block(0,47,3,CONCRETE:0)
Block(0,47,4,CONCRETE:0)
Block(0,48,-6,minecraft:black_glazed_terracotta)
Block(0,48,-5,minecraft:black_glazed_terracotta)
Block(0,48,-4,minecraft:black_glazed_terracotta)
Block(0,48,-2,CONCRETE:0)
Block(0,48,-1,CONCRETE:0)
Block(0,48,0,CONCRETE:0)
Block(0,48,1,CONCRETE:0)
Block(0,48,2,CONCRETE:0)
Block(0,48,3,CONCRETE:0)
Block(0,48,4,CONCRETE:0)
Block(0,50,-6,CONCRETE:15)
Block(0,50,-5,CONCRETE:15)
Block(0,50,-4,CONCRETE:15)
Block(0,50,-3,CONCRETE:15)
Block(0,50,-2,CONCRETE:15)
Block(0,50,-1,CONCRETE:15)
Block(0,50,0,CONCRETE:15)
Block(0,50,1,CONCRETE:15)
Block(0,50,2,CONCRETE:15)
Block(0,50,3,CONCRETE:15)
Block(0,50,4,CONCRETE:15)
Block(0,50,5,CONCRETE:15)
Block(0,50,6,CONCRETE:15)
Block(0,50,7,CONCRETE:15)
Block(0,50,8,CONCRETE:15)
Block(0,51,-6,CONCRETE:15)
Block(0,51,-5,CONCRETE:15)
Block(0,51,-4,CONCRETE:15)
Block(0,51,-3,CONCRETE:15)
Block(0,51,-2,CONCRETE:15)
Block(0,51,-1,CONCRETE:15)
Block(0,51,0,CONCRETE:15)
Block(0,51,1,CONCRETE:15)
Block(0,51,2,CONCRETE:15)
Block(0,51,3,CONCRETE:15)
Block(0,51,4,CONCRETE:15)
Block(0,51,5,CONCRETE:15)
Block(0,51,6,CONCRETE:15)
Block(0,51,7,CONCRETE:15)
Block(0,51,8,CONCRETE:15)
Block(0,52,-6,CONCRETE:15)
Block(0,52,-5,CONCRETE:15)
Block(0,52,-4,CONCRETE:15)
Block(0,52,-3,CONCRETE:15)
Block(0,52,-2,CONCRETE:15)
Block(0,52,-1,CONCRETE:15)
Block(0,52,0,CONCRETE:15)
Block(0,52,1,CONCRETE:15)
Block(0,52,2,CONCRETE:15)
Block(0,52,3,CONCRETE:15)
Block(0,52,4,CONCRETE:15)
Block(0,52,5,CONCRETE:15)
Block(0,52,6,CONCRETE:15)
Block(0,52,7,CONCRETE:15)
Block(0,52,8,CONCRETE:15)
Block(0,54,-6,CONCRETE:15)
Block(0,54,-5,CONCRETE:15)
Block(0,54,-4,CONCRETE:15)
Block(0,54,-2,minecraft:black_glazed_terracotta)
Block(0,54,-1,minecraft:black_glazed_terracotta)
Block(0,54,0,minecraft:black_glazed_terracotta)
Block(0,54,2,CONCRETE:0)
Block(0,54,3,CONCRETE:0)
Block(0,54,4,CONCRETE:0)
Block(0,54,5,CONCRETE:0)
Block(0,54,6,CONCRETE:0)
Block(0,54,7,CONCRETE:0)
Block(0,54,8,CONCRETE:0)
Block(0,55,-6,CONCRETE:15)
Block(0,55,-5,CONCRETE:15)
Block(0,55,-4,CONCRETE:15)
Block(0,55,-2,minecraft:black_glazed_terracotta)
Block(0,55,-1,minecraft:black_glazed_terracotta)
Block(0,55,0,minecraft:black_glazed_terracotta)
Block(0,55,2,CONCRETE:0)
Block(0,55,3,CONCRETE:0)
Block(0,55,4,CONCRETE:0)
Block(0,55,5,CONCRETE:0)
Block(0,55,6,CONCRETE:0)
Block(0,55,7,CONCRETE:0)
Block(0,55,8,CONCRETE:0)
Block(0,56,-6,CONCRETE:15)
Block(0,56,-5,CONCRETE:15)
Block(0,56,-4,CONCRETE:15)
Block(0,56,-2,minecraft:black_glazed_terracotta)
Block(0,56,-1,minecraft:black_glazed_terracotta)
Block(0,56,0,minecraft:black_glazed_terracotta)
Block(0,56,2,CONCRETE:0)
Block(0,56,3,CONCRETE:0)
Block(0,56,4,CONCRETE:0)
Block(0,56,5,CONCRETE:0)
Block(0,56,6,CONCRETE:0)
Block(0,56,7,CONCRETE:0)
Block(0,56,8,CONCRETE:0)
Block(0,57,2,CONCRETE:0)
Block(0,57,3,CONCRETE:0)
Block(0,57,4,CONCRETE:0)
Block(0,58,-6,CONCRETE:10)
Block(0,58,-5,CONCRETE:10)
Block(0,58,-4,CONCRETE:10)
Block(0,58,-2,CONCRETE:0)
Block(0,58,-1,CONCRETE:0)
Block(0,58,0,CONCRETE:0)
Block(0,58,2,CONCRETE:0)
Block(0,58,3,CONCRETE:0)
Block(0,58,4,CONCRETE:0)
Block(0,59,-6,CONCRETE:10)
Block(0,59,-5,CONCRETE:10)
Block(0,59,-4,CONCRETE:10)
Block(0,59,-2,CONCRETE:0)
Block(0,59,-1,CONCRETE:0)
Block(0,59,0,CONCRETE:0)
Block(0,59,2,CONCRETE:0)
Block(0,59,3,CONCRETE:0)
Block(0,59,4,CONCRETE:0)
Block(0,60,-6,CONCRETE:10)
Block(0,60,-5,CONCRETE:10)
Block(0,60,-4,CONCRETE:10)
Block(0,60,-2,CONCRETE:0)
Block(0,60,-1,CONCRETE:0)
Block(0,60,0,CONCRETE:0)
Block(0,60,2,CONCRETE:0)
Block(0,60,3,CONCRETE:0)
Block(0,60,4,CONCRETE:0)
Block(0,61,2,CONCRETE:0)
Block(0,61,3,CONCRETE:0)
Block(0,61,4,CONCRETE:0)
Block(0,62,-6,CONCRETE:0)
Block(0,62,-5,CONCRETE:0)
Block(0,62,-4,CONCRETE:0)
Block(0,62,-3,CONCRETE:0)
Block(0,62,-2,CONCRETE:0)
Block(0,62,-1,CONCRETE:0)
Block(0,62,0,CONCRETE:0)
Block(0,62,2,CONCRETE:0)
Block(0,62,3,CONCRETE:0)
Block(0,62,4,CONCRETE:0)
Block(0,62,6,minecraft:black_glazed_terracotta)
Block(0,62,7,minecraft:black_glazed_terracotta)
Block(0,62,8,minecraft:black_glazed_terracotta)
Block(0,63,-6,CONCRETE:0)
Block(0,63,-5,CONCRETE:0)
Block(0,63,-4,CONCRETE:0)
Block(0,63,-3,CONCRETE:0)
Block(0,63,-2,CONCRETE:0)
Block(0,63,-1,CONCRETE:0)
Block(0,63,0,CONCRETE:0)
Block(0,63,2,CONCRETE:0)
Block(0,63,3,CONCRETE:0)
Block(0,63,4,CONCRETE:0)
Block(0,63,6,minecraft:black_glazed_terracotta)
Block(0,63,7,minecraft:black_glazed_terracotta)
Block(0,63,8,minecraft:black_glazed_terracotta)
Block(0,64,-6,CONCRETE:0)
Block(0,64,-5,CONCRETE:0)
Block(0,64,-4,CONCRETE:0)
Block(0,64,-3,CONCRETE:0)
Block(0,64,-2,CONCRETE:0)
Block(0,64,-1,CONCRETE:0)
Block(0,64,0,CONCRETE:0)
Block(0,64,2,CONCRETE:0)
Block(0,64,3,CONCRETE:0)
Block(0,64,4,CONCRETE:0)
Block(0,64,6,minecraft:black_glazed_terracotta)
Block(0,64,7,minecraft:black_glazed_terracotta)
Block(0,64,8,minecraft:black_glazed_terracotta)
Block(0,65,-2,CONCRETE:0)
Block(0,65,-1,CONCRETE:0)
Block(0,65,0,CONCRETE:0)
Block(0,66,-6,minecraft:black_glazed_terracotta)
Block(0,66,-5,minecraft:black_glazed_terracotta)
Block(0,66,-4,minecraft:black_glazed_terracotta)
Block(0,66,-2,CONCRETE:0)
Block(0,66,-1,CONCRETE:0)
Block(0,66,0,CONCRETE:0)
Block(0,66,2,minecraft:purple_glazed_terracotta)
Block(0,66,3,minecraft:purple_glazed_terracotta)
Block(0,66,4,minecraft:purple_glazed_terracotta)
Block(0,66,6,CONCRETE:15)
Block(0,66,7,CONCRETE:15)
Block(0,66,8,CONCRETE:15)
Block(0,67,-6,minecraft:black_glazed_terracotta)
Block(0,67,-5,minecraft:black_glazed_terracotta)
Block(0,67,-4,minecraft:black_glazed_terracotta)
Block(0,67,-2,CONCRETE:0)
Block(0,67,-1,CONCRETE:0)
Block(0,67,0,CONCRETE:0)
Block(0,67,2,minecraft:purple_glazed_terracotta)
Block(0,67,3,minecraft:purple_glazed_terracotta)
Block(0,67,4,minecraft:purple_glazed_terracotta)
Block(0,67,6,CONCRETE:15)
Block(0,67,7,CONCRETE:15)
Block(0,67,8,CONCRETE:15)
Block(0,68,-6,minecraft:black_glazed_terracotta)
Block(0,68,-5,minecraft:black_glazed_terracotta)
Block(0,68,-4,minecraft:black_glazed_terracotta)
Block(0,68,-2,CONCRETE:0)
Block(0,68,-1,CONCRETE:0)
Block(0,68,0,CONCRETE:0)
Block(0,68,2,minecraft:purple_glazed_terracotta)
Block(0,68,3,minecraft:purple_glazed_terracotta)
Block(0,68,4,minecraft:purple_glazed_terracotta)
Block(0,68,6,CONCRETE:15)
Block(0,68,7,CONCRETE:15)
Block(0,68,8,CONCRETE:15)
Block(0,70,-6,CONCRETE:15)
Block(0,70,-5,CONCRETE:15)
Block(0,70,-4,CONCRETE:15)
Block(0,70,-2,CONCRETE:15)
Block(0,70,-1,CONCRETE:15)
Block(0,70,0,CONCRETE:15)
Block(0,70,6,minecraft:purple_glazed_terracotta)
Block(0,70,7,minecraft:purple_glazed_terracotta)
Block(0,70,8,minecraft:purple_glazed_terracotta)
Block(0,71,-6,CONCRETE:15)
Block(0,71,-5,CONCRETE:15)
Block(0,71,-4,CONCRETE:15)
Block(0,71,-2,CONCRETE:15)
Block(0,71,-1,CONCRETE:15)
Block(0,71,0,CONCRETE:15)
Block(0,71,6,minecraft:purple_glazed_terracotta)
Block(0,71,7,minecraft:purple_glazed_terracotta)
Block(0,71,8,minecraft:purple_glazed_terracotta)
Block(0,72,-6,CONCRETE:15)
Block(0,72,-5,CONCRETE:15)
Block(0,72,-4,CONCRETE:15)
Block(0,72,-2,CONCRETE:15)
Block(0,72,-1,CONCRETE:15)
Block(0,72,0,CONCRETE:15)
Block(0,72,6,minecraft:purple_glazed_terracotta)
Block(0,72,7,minecraft:purple_glazed_terracotta)
Block(0,72,8,minecraft:purple_glazed_terracotta)
Block(0,73,-2,CONCRETE:15)
Block(0,73,-1,CONCRETE:15)
Block(0,73,0,CONCRETE:15)
Block(0,74,-2,CONCRETE:15)
Block(0,74,-1,CONCRETE:15)
Block(0,74,0,CONCRETE:15)
Block(0,74,2,CONCRETE:15)
Block(0,74,3,CONCRETE:15)
Block(0,74,4,CONCRETE:15)
Block(0,74,6,CONCRETE:15)
Block(0,74,7,CONCRETE:15)
Block(0,74,8,CONCRETE:15)
Block(0,75,-2,CONCRETE:15)
Block(0,75,-1,CONCRETE:15)
Block(0,75,0,CONCRETE:15)
Block(0,75,2,CONCRETE:15)
Block(0,75,3,CONCRETE:15)
Block(0,75,4,CONCRETE:15)
Block(0,75,6,CONCRETE:15)
Block(0,75,7,CONCRETE:15)
Block(0,75,8,CONCRETE:15)
Block(0,76,-2,CONCRETE:15)
Block(0,76,-1,CONCRETE:15)
Block(0,76,0,CONCRETE:15)
Block(0,76,2,CONCRETE:15)
Block(0,76,3,CONCRETE:15)
Block(0,76,4,CONCRETE:15)
Block(0,76,6,CONCRETE:15)
Block(0,76,7,CONCRETE:15)
Block(0,76,8,CONCRETE:15)
Block(0,78,-7,CONCRETE:15)
Block(0,78,-6,CONCRETE:15)
Block(0,78,-5,CONCRETE:15)
Block(0,78,-4,CONCRETE:15)
Block(0,78,-2,CONCRETE:0)
Block(0,78,-1,CONCRETE:0)
Block(0,78,0,CONCRETE:0)
Block(0,78,2,minecraft:black_glazed_terracotta)
Block(0,78,3,minecraft:black_glazed_terracotta)
Block(0,78,4,minecraft:black_glazed_terracotta)
Block(0,79,-7,CONCRETE:15)
Block(0,79,-6,CONCRETE:15)
Block(0,79,-5,CONCRETE:15)
Block(0,79,-4,CONCRETE:15)
Block(0,79,-2,CONCRETE:0)
Block(0,79,-1,CONCRETE:0)
Block(0,79,0,CONCRETE:0)
Block(0,79,2,minecraft:black_glazed_terracotta)
Block(0,79,3,minecraft:black_glazed_terracotta)
Block(0,79,4,minecraft:black_glazed_terracotta)
Block(0,80,-7,CONCRETE:15)
Block(0,80,-6,CONCRETE:15)
Block(0,80,-5,CONCRETE:15)
Block(0,80,-4,CONCRETE:15)
Block(0,80,-2,CONCRETE:0)
Block(0,80,-1,CONCRETE:0)
Block(0,80,0,CONCRETE:0)
Block(0,80,2,minecraft:black_glazed_terracotta)
Block(0,80,3,minecraft:black_glazed_terracotta)
Block(0,80,4,minecraft:black_glazed_terracotta)
Block(0,81,-2,CONCRETE:0)
Block(0,81,-1,CONCRETE:0)
Block(0,81,0,CONCRETE:0)
Block(0,82,-6,minecraft:black_glazed_terracotta)
Block(0,82,-5,minecraft:black_glazed_terracotta)
Block(0,82,-4,minecraft:black_glazed_terracotta)
Block(0,82,-2,CONCRETE:0)
Block(0,82,-1,CONCRETE:0)
Block(0,82,0,CONCRETE:0)
Block(0,82,2,CONCRETE:15)
Block(0,82,3,CONCRETE:15)
Block(0,82,4,CONCRETE:15)
Block(0,82,6,CONCRETE:15)
Block(0,82,7,CONCRETE:15)
Block(0,82,8,CONCRETE:15)
Block(0,83,-6,minecraft:black_glazed_terracotta)
Block(0,83,-5,minecraft:black_glazed_terracotta)
Block(0,83,-4,minecraft:black_glazed_terracotta)
Block(0,83,-2,CONCRETE:0)
Block(0,83,-1,CONCRETE:0)
Block(0,83,0,CONCRETE:0)
Block(0,83,2,CONCRETE:15)
Block(0,83,3,CONCRETE:15)
Block(0,83,4,CONCRETE:15)
Block(0,83,6,CONCRETE:15)
Block(0,83,7,CONCRETE:15)
Block(0,83,8,CONCRETE:15)
Block(0,84,-6,minecraft:black_glazed_terracotta)
Block(0,84,-5,minecraft:black_glazed_terracotta)
Block(0,84,-4,minecraft:black_glazed_terracotta)
Block(0,84,-2,CONCRETE:0)
Block(0,84,-1,CONCRETE:0)
Block(0,84,0,CONCRETE:0)
Block(0,84,2,CONCRETE:15)
Block(0,84,3,CONCRETE:15)
Block(0,84,4,CONCRETE:15)
Block(0,84,6,CONCRETE:15)
Block(0,84,7,CONCRETE:15)
Block(0,84,8,CONCRETE:15)
Block(1,0,-7,CONCRETE:7)
Block(1,0,-6,CONCRETE:7)
Block(1,0,-5,CONCRETE:7)
Block(1,0,-4,CONCRETE:7)
Block(1,0,-3,CONCRETE:7)
Block(1,0,-2,CONCRETE:7)
Block(1,0,-1,CONCRETE:7)
Block(1,0,0,CONCRETE:7)
Block(1,0,1,CONCRETE:7)
Block(1,0,2,CONCRETE:7)
Block(1,0,3,CONCRETE:7)
Block(1,0,4,CONCRETE:7)
Block(1,0,5,CONCRETE:7)
Block(1,0,6,CONCRETE:7)
Block(1,0,7,CONCRETE:7)
Block(1,0,8,CONCRETE:7)
Block(1,1,-7,CONCRETE:7)
Block(1,1,-6,CONCRETE:7)
Block(1,1,-5,CONCRETE:7)
Block(1,1,-4,CONCRETE:7)
Block(1,1,-3,CONCRETE:7)
Block(1,1,-2,CONCRETE:7)
Block(1,1,-1,CONCRETE:7)
Block(1,1,0,CONCRETE:7)
Block(1,1,1,CONCRETE:7)
Block(1,1,2,CONCRETE:7)
Block(1,1,3,CONCRETE:7)
Block(1,1,4,CONCRETE:7)
Block(1,1,5,CONCRETE:7)
Block(1,1,6,CONCRETE:7)
Block(1,1,7,CONCRETE:7)
Block(1,1,8,CONCRETE:7)
Block(1,2,-7,SMOOTH_STAIRS:1)
Block(1,2,-6,SMOOTH_STAIRS:1)
Block(1,2,-5,SMOOTH_STAIRS:1)
Block(1,2,-4,SMOOTH_STAIRS:1)
Block(1,2,-3,SMOOTH_STAIRS:1)
Block(1,2,-2,SMOOTH_STAIRS:1)
Block(1,2,-1,SMOOTH_STAIRS:1)
Block(1,2,0,CONCRETE:7)
Block(1,2,1,CONCRETE:7)
Block(1,2,2,CONCRETE:7)
Block(1,2,3,CONCRETE:7)
Block(1,2,4,CONCRETE:7)
Block(1,2,5,CONCRETE:7)
Block(1,2,6,CONCRETE:7)
Block(1,2,7,CONCRETE:7)
Block(1,2,8,CONCRETE:7)
Block(1,3,-7,AIR:0)
Block(1,3,-6,AIR:0)
Block(1,3,-5,AIR:0)
Block(1,3,-4,AIR:0)
Block(1,3,-3,AIR:0)
Block(1,3,-2,AIR:0)
Block(1,3,-1,AIR:0)
Block(1,3,0,AIR:0)
Block(1,3,1,AIR:0)
Block(1,3,2,AIR:0)
Block(1,3,3,AIR:0)
Block(1,3,4,AIR:0)
Block(1,3,5,AIR:0)
Block(1,3,6,AIR:0)
Block(1,3,7,AIR:0)
Block(1,3,8,AIR:0)
Block(1,4,-7,AIR:0)
Block(1,4,-6,AIR:0)
Block(1,4,-5,AIR:0)
Block(1,4,-4,AIR:0)
Block(1,4,-3,AIR:0)
Block(1,4,-2,AIR:0)
Block(1,4,-1,AIR:0)
Block(1,4,0,AIR:0)
Block(1,4,1,AIR:0)
Block(1,4,2,AIR:0)
Block(1,4,3,AIR:0)
Block(1,4,4,AIR:0)
Block(1,4,5,AIR:0)
Block(1,4,6,AIR:0)
Block(1,4,7,AIR:0)
Block(1,4,8,AIR:0)
Block(1,5,-7,AIR:0)
Block(1,5,-6,CONCRETE:4)
Block(1,5,-5,CONCRETE:12)
Block(1,5,-4,AIR:0)
Block(1,5,-3,AIR:0)
Block(1,5,-2,AIR:0)
Block(1,5,-1,AIR:0)
Block(1,5,0,AIR:0)
Block(1,5,1,AIR:0)
Block(1,5,2,AIR:0)
Block(1,5,3,AIR:0)
Block(1,5,4,AIR:0)
Block(1,5,5,AIR:0)
Block(1,5,6,AIR:0)
Block(1,5,7,AIR:0)
Block(1,5,8,AIR:0)
Block(1,6,-7,AIR:0)
Block(1,6,-6,AIR:0)
Block(1,6,-5,AIR:0)
Block(1,6,-4,AIR:0)
Block(1,6,-3,AIR:0)
Block(1,6,-2,AIR:0)
Block(1,6,-1,AIR:0)
Block(1,6,0,AIR:0)
Block(1,6,1,AIR:0)
Block(1,6,2,AIR:0)
Block(1,6,3,AIR:0)
Block(1,6,4,AIR:0)
Block(1,6,5,AIR:0)
Block(1,6,6,AIR:0)
Block(1,6,7,AIR:0)
Block(1,6,8,CONCRETE:7)
Block(1,7,-7,CONCRETE:7)
Block(1,7,-6,CONCRETE:7)
Block(1,7,-5,CONCRETE:7)
Block(1,7,-4,CONCRETE:7)
Block(1,7,-3,CONCRETE:7)
Block(1,7,-2,CONCRETE:7)
Block(1,7,-1,CONCRETE:7)
Block(1,7,0,CONCRETE:7)
Block(1,7,1,CONCRETE:7)
Block(1,7,2,CONCRETE:7)
Block(1,7,3,CONCRETE:7)
Block(1,7,4,CONCRETE:7)
Block(1,7,5,CONCRETE:7)
Block(1,7,6,CONCRETE:7)
Block(1,7,7,CONCRETE:7)
Block(1,7,8,CONCRETE:7)
Block(1,8,-7,CONCRETE:7)
Block(1,8,-6,CONCRETE:7)
Block(1,8,-5,CONCRETE:7)
Block(1,8,-4,CONCRETE:7)
Block(1,8,-3,CONCRETE:7)
Block(1,8,-2,CONCRETE:7)
Block(1,8,-1,CONCRETE:7)
Block(1,8,0,CONCRETE:7)
Block(1,8,1,CONCRETE:7)
Block(1,8,2,CONCRETE:7)
Block(1,8,3,CONCRETE:7)
Block(1,8,4,CONCRETE:7)
Block(1,8,5,CONCRETE:7)
Block(1,8,6,CONCRETE:7)
Block(1,8,7,CONCRETE:7)
Block(1,8,8,CONCRETE:7)
Block(1,9,-7,CONCRETE:7)
Block(1,9,-6,CONCRETE:7)
Block(1,9,-5,CONCRETE:7)
Block(1,9,-4,CONCRETE:7)
Block(1,9,-3,CONCRETE:7)
Block(1,9,-2,CONCRETE:7)
Block(1,9,-1,CONCRETE:7)
Block(1,9,0,CONCRETE:7)
Block(1,9,1,CONCRETE:7)
Block(1,9,2,CONCRETE:7)
Block(1,9,3,CONCRETE:7)
Block(1,9,4,CONCRETE:7)
Block(1,9,5,CONCRETE:7)
Block(1,9,6,CONCRETE:7)
Block(1,9,7,CONCRETE:7)
Block(1,9,8,CONCRETE:7)
Block(1,10,-7,CONCRETE:7)
Block(1,10,-6,CONCRETE:7)
Block(1,10,-5,CONCRETE:7)
Block(1,10,-4,CONCRETE:7)
Block(1,10,-3,CONCRETE:7)
Block(1,10,-2,CONCRETE:7)
Block(1,10,-1,CONCRETE:7)
Block(1,10,0,CONCRETE:7)
Block(1,10,1,CONCRETE:7)
Block(1,10,2,CONCRETE:7)
Block(1,10,3,CONCRETE:7)
Block(1,10,4,CONCRETE:7)
Block(1,10,5,CONCRETE:7)
Block(1,10,6,CONCRETE:7)
Block(1,10,7,CONCRETE:7)
Block(1,10,8,CONCRETE:7)
Block(1,11,-7,CONCRETE:7)
Block(1,11,-6,CONCRETE:7)
Block(1,11,-5,CONCRETE:7)
Block(1,11,-4,CONCRETE:7)
Block(1,11,-3,CONCRETE:7)
Block(1,11,-2,CONCRETE:7)
Block(1,11,-1,CONCRETE:7)
Block(1,11,0,CONCRETE:7)
Block(1,11,1,CONCRETE:7)
Block(1,11,2,CONCRETE:7)
Block(1,11,3,CONCRETE:7)
Block(1,11,4,CONCRETE:7)
Block(1,11,5,CONCRETE:7)
Block(1,11,6,CONCRETE:7)
Block(1,11,7,CONCRETE:7)
Block(1,11,8,CONCRETE:7)
Block(1,12,-7,CONCRETE:7)
Block(1,12,-6,CONCRETE:7)
Block(1,12,-5,CONCRETE:7)
Block(1,12,-4,CONCRETE:7)
Block(1,12,-3,CONCRETE:7)
Block(1,12,-2,CONCRETE:7)
Block(1,12,-1,CONCRETE:7)
Block(1,12,0,CONCRETE:7)
Block(1,12,1,CONCRETE:7)
Block(1,12,2,CONCRETE:7)
Block(1,12,3,CONCRETE:7)
Block(1,12,4,CONCRETE:7)
Block(1,12,5,CONCRETE:7)
Block(1,12,6,CONCRETE:7)
Block(1,12,7,CONCRETE:7)
Block(1,12,8,CONCRETE:7)
Block(1,13,-7,CONCRETE:7)
Block(1,13,-6,CONCRETE:7)
Block(1,13,-5,CONCRETE:7)
Block(1,13,-4,CONCRETE:7)
Block(1,13,-3,CONCRETE:7)
Block(1,13,-2,CONCRETE:7)
Block(1,13,-1,CONCRETE:7)
Block(1,13,0,CONCRETE:7)
Block(1,13,1,CONCRETE:7)
Block(1,13,2,CONCRETE:7)
Block(1,13,3,CONCRETE:7)
Block(1,13,4,CONCRETE:7)
Block(1,13,5,CONCRETE:7)
Block(1,13,6,CONCRETE:7)
Block(1,13,7,CONCRETE:7)
Block(1,13,8,CONCRETE:7)
Block(1,14,-7,CONCRETE:7)
Block(1,14,-6,CONCRETE:7)
Block(1,14,-5,CONCRETE:7)
Block(1,14,-4,CONCRETE:7)
Block(1,14,-3,CONCRETE:7)
Block(1,14,-2,CONCRETE:7)
Block(1,14,-1,CONCRETE:7)
Block(1,14,0,CONCRETE:7)
Block(1,14,1,CONCRETE:7)
Block(1,14,2,CONCRETE:7)
Block(1,14,3,CONCRETE:7)
Block(1,14,4,CONCRETE:7)
Block(1,14,5,CONCRETE:7)
Block(1,14,6,CONCRETE:7)
Block(1,14,7,CONCRETE:7)
Block(1,14,8,CONCRETE:7)
Block(1,15,-7,CONCRETE:7)
Block(1,15,-6,CONCRETE:7)
Block(1,15,-5,CONCRETE:7)
Block(1,15,-4,CONCRETE:7)
Block(1,15,-3,CONCRETE:7)
Block(1,15,-2,CONCRETE:7)
Block(1,15,-1,CONCRETE:7)
Block(1,15,0,CONCRETE:7)
Block(1,15,1,CONCRETE:7)
Block(1,15,2,CONCRETE:7)
Block(1,15,3,CONCRETE:7)
Block(1,15,4,CONCRETE:7)
Block(1,15,5,CONCRETE:7)
Block(1,15,6,CONCRETE:7)
Block(1,15,7,CONCRETE:7)
Block(1,15,8,CONCRETE:7)
Block(1,16,-7,CONCRETE:7)
Block(1,16,-6,CONCRETE:7)
Block(1,16,-5,CONCRETE:7)
Block(1,16,-4,CONCRETE:7)
Block(1,16,-3,CONCRETE:7)
Block(1,16,-2,CONCRETE:7)
Block(1,16,-1,CONCRETE:7)
Block(1,16,0,CONCRETE:7)
Block(1,16,1,CONCRETE:7)
Block(1,16,2,CONCRETE:7)
Block(1,16,3,CONCRETE:7)
Block(1,16,4,CONCRETE:7)
Block(1,16,5,CONCRETE:7)
Block(1,16,6,CONCRETE:7)
Block(1,16,7,CONCRETE:7)
Block(1,16,8,CONCRETE:7)
Block(1,17,-7,CONCRETE:7)
Block(1,17,-6,CONCRETE:7)
Block(1,17,-5,CONCRETE:7)
Block(1,17,-4,CONCRETE:7)
Block(1,17,-3,CONCRETE:7)
Block(1,17,-2,CONCRETE:7)
Block(1,17,-1,CONCRETE:7)
Block(1,17,0,CONCRETE:7)
Block(1,17,1,CONCRETE:7)
Block(1,17,2,CONCRETE:7)
Block(1,17,3,CONCRETE:7)
Block(1,17,4,CONCRETE:7)
Block(1,17,5,CONCRETE:7)
Block(1,17,6,CONCRETE:7)
Block(1,17,7,CONCRETE:7)
Block(1,17,8,CONCRETE:7)
Block(1,18,-7,STAINED_GLASS:10)
Block(1,18,-6,STAINED_GLASS:10)
Block(1,18,-5,STAINED_GLASS:10)
Block(1,18,-4,STAINED_GLASS:10)
Block(1,18,-3,STAINED_GLASS:10)
Block(1,18,-2,STAINED_GLASS:10)
Block(1,18,-1,STAINED_GLASS:10)
Block(1,18,0,STAINED_GLASS_PANE:7)
Block(1,18,2,STAINED_GLASS_PANE:7)
Block(1,18,3,STAINED_GLASS:10)
Block(1,18,4,STAINED_GLASS:10)
Block(1,18,5,STAINED_GLASS:10)
Block(1,18,6,STAINED_GLASS:10)
Block(1,18,7,STAINED_GLASS:10)
Block(1,18,8,STAINED_GLASS:10)
Block(1,19,-7,STAINED_GLASS:10)
Block(1,19,-6,STAINED_GLASS:10)
Block(1,19,-5,STAINED_GLASS:10)
Block(1,19,-4,STAINED_GLASS:10)
Block(1,19,-3,STAINED_GLASS:10)
Block(1,19,-2,STAINED_GLASS:10)
Block(1,19,-1,STAINED_GLASS:10)
Block(1,19,0,STAINED_GLASS_PANE:7)
Block(1,19,2,STAINED_GLASS_PANE:7)
Block(1,19,3,STAINED_GLASS:10)
Block(1,19,4,STAINED_GLASS:10)
Block(1,19,5,STAINED_GLASS:10)
Block(1,19,6,STAINED_GLASS:10)
Block(1,19,7,STAINED_GLASS:10)
Block(1,19,8,STAINED_GLASS:10)
Block(1,20,-7,STAINED_GLASS:10)
Block(1,20,-6,STAINED_GLASS:10)
Block(1,20,-5,STAINED_GLASS:10)
Block(1,20,-4,STAINED_GLASS:10)
Block(1,20,-3,STAINED_GLASS:10)
Block(1,20,-2,STAINED_GLASS:10)
Block(1,20,-1,STAINED_GLASS:10)
Block(1,20,0,STAINED_GLASS_PANE:7)
Block(1,20,2,STAINED_GLASS_PANE:7)
