
#######################################################################
# +-----------------------------------------------------------------+ #
# |                            BO4 object                           | #
# +-----------------------------------------------------------------+ #
#######################################################################

Author: NLBlackEagle

Description: No description given

SettingsMode: WriteDisable


#######################################################################
# +-----------------------------------------------------------------+ #
# |                          Main settings                          | #
# +-----------------------------------------------------------------+ #
#######################################################################

Frequency: 0

SpawnHeight: highestBlock

UseCenterForHighestBlock: true

##############################
# Height Limits for the BO4. #
##############################

MinHeight: 0

MaxHeight: 255

InheritBO3: 

InheritBO3Rotation: NORTH

OverrideChildSettings: true

OverrideParentHeight: false

CanOverride: true

BranchFrequency: 0

BranchFrequencyGroup: 

MustBeBelowOther: false

MustBeInside: 

CannotBeInside: 

ReplacesBO3: L4-M-CrossC0R0, L4-M-CrossC0R1, L4-M-CrossC0R2, L4-M-CrossC0R3, L4-M-CrossC1R0, L4-M-CrossC1R1, L4-M-CrossC1R2, L4-M-CrossC1R3, L4-M-CrossC2R0, L4-M-CrossC2R1, L4-M-CrossC2R2, L4-M-CrossC2R3, L4-M-CrossC3R0, L4-M-CrossC3R1, L4-M-CrossC3R2, L4-M-CrossC3R3, L4-M-Straigth-START_01-C0R0, L4-M-Straigth-START_01-C0R1, L4-M-Straigth-START_01-C1R0, L4-M-Straigth-START_01-C1R1, L4-M-Straigth-START_01-C2R0, L4-M-Straigth-START_01-C2R1, L4-M-Straigth-START_01-C3R0, L4-M-Straigth-START_01-C3R1, L4-M-Straigth-3CC0R0, L4-M-Straigth-3CC0R1, L4-M-Straigth-3CC0R2, L4-M-Straigth-3CC1R0, L4-M-Straigth-3CC1R1, L4-M-Straigth-3CC1R2, L4-M-Straigth-3CC2R0, L4-M-Straigth-3CC2R1, L4-M-Straigth-3CC2R2, L4-M-Straigth-3CC3R0, L4-M-Straigth-3CC3R1, L4-M-Straigth-3CC3R2, L4-M-Cross, skyscraper_2x2_01, skyscraper_2x2_02, skyscraper_2x2_03, skyscraper_2x2_04, skyscraper_2x2_05, skyscraper_3x3_01, skyscraper_3x3_02, skyscraper_3x3_03, L3-M-Straigth-2CC0R0, L3-M-Straigth-2CC0R1, L3-M-Straigth-2CC1R0, L3-M-Straigth-2CC1R1, L3-M-Straigth-2CC2R0, L3-M-Straigth-2CC2R1, L3-M-Straigth-2CC3R0, L3-M-Straigth-2CC3R1, L3-M-Straigth-3CC0R0, L3-M-Straigth-3CC0R1, L3-M-Straigth-3CC0R2, L3-M-Straigth-3CC1R0, L3-M-Straigth-3CC1R1, L3-M-Straigth-3CC1R2, L3-M-Straigth-3CC2R0, L3-M-Straigth-3CC2R1, L3-M-Straigth-3CC2R2, L3-M-Straigth-3CC3R0, L3-M-Straigth-3CC3R1, L3-M-Straigth-3CC3R2

MustBeInsideWorldBorders: false

CanSpawnOnWater: true

SpawnOnWaterOnly: false

SpawnUnderWater: false

SpawnAtWaterLevel: false

HeightOffset: 0

RemoveAir: false

ReplaceAbove: 

ReplaceBelow: 

ReplaceWithBiomeBlocks: true

ReplaceWithSurfaceBlock: GRASS

ReplaceWithGroundBlock: DIRT

ReplaceWithStoneBlock: STONE

SmoothRadius: 0

SmoothHeightOffset: 0

SmoothStartTop: false

SmoothStartWood: false

SmoothingSurfaceBlock: 

SmoothingGroundBlock: 

BO3Group: 

IsSpawnPoint: false

DoReplaceBlocks: true


#######################################################################
# +-----------------------------------------------------------------+ #
# |                              Blocks                             | #
# +-----------------------------------------------------------------+ #
#######################################################################

Block(-8,0,-7,CONCRETE:7)
Block(-8,0,-6,CONCRETE:7)
Block(-8,0,-5,CONCRETE:7)
Block(-8,0,-4,CONCRETE:7)
Block(-8,0,-3,CONCRETE:7)
Block(-8,0,-2,CONCRETE:7)
Block(-8,0,-1,CONCRETE:7)
Block(-8,0,0,CONCRETE:7)
Block(-8,0,1,CONCRETE:7)
Block(-8,0,2,CONCRETE:7)
Block(-8,0,3,CONCRETE:7)
Block(-8,0,4,CONCRETE:7)
Block(-8,0,5,CONCRETE:7)
Block(-8,0,6,CONCRETE:7)
Block(-8,0,7,CONCRETE:7)
Block(-8,0,8,CONCRETE:7)
Block(-8,1,-7,CONCRETE:7)
Block(-8,1,-6,CONCRETE:7)
Block(-8,1,-5,CONCRETE:7)
Block(-8,1,-4,CONCRETE:7)
Block(-8,1,-3,CONCRETE:7)
Block(-8,1,-2,CONCRETE:7)
Block(-8,1,-1,CONCRETE:7)
Block(-8,1,0,CONCRETE:7)
Block(-8,1,1,CONCRETE:7)
Block(-8,1,2,CONCRETE:7)
Block(-8,1,3,CONCRETE:7)
Block(-8,1,4,CONCRETE:7)
Block(-8,1,5,CONCRETE:7)
Block(-8,1,6,CONCRETE:7)
Block(-8,1,7,CONCRETE:7)
Block(-8,1,8,CONCRETE:7)
Block(-8,2,-7,CONCRETE:7)
Block(-8,2,-6,CONCRETE:7)
Block(-8,2,-5,CONCRETE:7)
Block(-8,2,-4,CONCRETE:7)
Block(-8,2,-3,CONCRETE:7)
Block(-8,2,-2,CONCRETE:7)
Block(-8,2,-1,CONCRETE:7)
Block(-8,2,0,CONCRETE:7)
Block(-8,2,1,CONCRETE:7)
Block(-8,2,2,CONCRETE:7)
Block(-8,2,3,CONCRETE:7)
Block(-8,2,4,CONCRETE:7)
Block(-8,2,5,CONCRETE:7)
Block(-8,2,6,CONCRETE:7)
Block(-8,2,7,CONCRETE:7)
Block(-8,2,8,CONCRETE:7)
Block(-8,3,-7,CONCRETE:7)
Block(-8,3,-6,CONCRETE:7)
Block(-8,3,-5,CONCRETE:7)
Block(-8,3,-4,CONCRETE:7)
Block(-8,3,-3,CONCRETE:7)
Block(-8,3,-2,CONCRETE:7)
Block(-8,3,-1,CONCRETE:7)
Block(-8,3,0,CONCRETE:7)
Block(-8,3,1,CONCRETE:7)
Block(-8,3,2,CONCRETE:7)
Block(-8,3,3,CONCRETE:7)
Block(-8,3,4,CONCRETE:7)
Block(-8,3,5,CONCRETE:7)
Block(-8,3,6,CONCRETE:7)
Block(-8,3,7,CONCRETE:7)
Block(-8,3,8,CONCRETE:7)
Block(-8,4,-7,CONCRETE:7)
Block(-8,4,-6,CONCRETE:7)
Block(-8,4,-5,CONCRETE:7)
Block(-8,4,-4,CONCRETE:7)
Block(-8,4,-3,CONCRETE:7)
Block(-8,4,-2,CONCRETE:7)
Block(-8,4,-1,CONCRETE:7)
Block(-8,4,0,CONCRETE:7)
Block(-8,4,1,CONCRETE:7)
Block(-8,4,2,CONCRETE:7)
Block(-8,4,3,CONCRETE:7)
Block(-8,4,4,CONCRETE:7)
Block(-8,4,5,CONCRETE:7)
Block(-8,4,6,CONCRETE:7)
Block(-8,4,7,CONCRETE:7)
Block(-8,4,8,CONCRETE:7)
Block(-8,5,-7,CONCRETE:7)
Block(-8,5,-6,CONCRETE:7)
Block(-8,5,-5,CONCRETE:7)
Block(-8,5,-4,CONCRETE:7)
Block(-8,5,-3,CONCRETE:7)
Block(-8,5,-2,CONCRETE:7)
Block(-8,5,-1,CONCRETE:7)
Block(-8,5,0,CONCRETE:7)
Block(-8,5,1,CONCRETE:7)
Block(-8,5,2,CONCRETE:7)
Block(-8,5,3,CONCRETE:7)
Block(-8,5,4,CONCRETE:7)
Block(-8,5,5,CONCRETE:7)
Block(-8,5,6,CONCRETE:7)
Block(-8,5,7,CONCRETE:7)
Block(-8,5,8,CONCRETE:7)
Block(-8,6,-7,CONCRETE:7)
Block(-8,6,-6,CONCRETE:7)
Block(-8,6,-5,CONCRETE:7)
Block(-8,6,-4,CONCRETE:7)
Block(-8,6,-3,CONCRETE:7)
Block(-8,6,-2,CONCRETE:7)
Block(-8,6,-1,CONCRETE:7)
Block(-8,6,0,CONCRETE:7)
Block(-8,6,1,CONCRETE:7)
Block(-8,6,2,CONCRETE:7)
Block(-8,6,3,CONCRETE:7)
Block(-8,6,4,CONCRETE:7)
Block(-8,6,5,CONCRETE:7)
Block(-8,6,6,CONCRETE:7)
Block(-8,6,7,CONCRETE:7)
Block(-8,6,8,CONCRETE:7)
Block(-8,7,-7,CONCRETE:7)
Block(-8,7,-6,CONCRETE:7)
Block(-8,7,-5,CONCRETE:7)
Block(-8,7,-4,CONCRETE:7)
Block(-8,7,-3,CONCRETE:7)
Block(-8,7,-2,CONCRETE:7)
Block(-8,7,-1,CONCRETE:7)
Block(-8,7,0,CONCRETE:7)
Block(-8,7,1,CONCRETE:7)
Block(-8,7,2,CONCRETE:7)
Block(-8,7,3,CONCRETE:7)
Block(-8,7,4,CONCRETE:7)
Block(-8,7,5,CONCRETE:7)
Block(-8,7,6,CONCRETE:7)
Block(-8,7,7,CONCRETE:7)
Block(-8,7,8,CONCRETE:7)
Block(-8,8,-7,CONCRETE:7)
Block(-8,8,-6,CONCRETE:7)
Block(-8,8,-5,CONCRETE:7)
Block(-8,8,-4,CONCRETE:7)
Block(-8,8,-3,CONCRETE:7)
Block(-8,8,-2,CONCRETE:7)
Block(-8,8,-1,CONCRETE:7)
Block(-8,8,0,CONCRETE:7)
Block(-8,8,1,CONCRETE:7)
Block(-8,8,2,CONCRETE:7)
Block(-8,8,3,CONCRETE:7)
Block(-8,8,4,CONCRETE:7)
Block(-8,8,5,CONCRETE:7)
Block(-8,8,6,CONCRETE:7)
Block(-8,8,7,CONCRETE:7)
Block(-8,8,8,CONCRETE:7)
Block(-8,9,-7,CONCRETE:7)
Block(-8,9,-6,CONCRETE:7)
Block(-8,9,-5,CONCRETE:7)
Block(-8,9,-4,CONCRETE:7)
Block(-8,9,-3,CONCRETE:7)
Block(-8,9,-2,CONCRETE:7)
Block(-8,9,-1,CONCRETE:7)
Block(-8,9,0,CONCRETE:7)
Block(-8,9,1,CONCRETE:7)
Block(-8,9,2,CONCRETE:7)
Block(-8,9,3,CONCRETE:7)
Block(-8,9,4,CONCRETE:7)
Block(-8,9,5,CONCRETE:7)
Block(-8,9,6,CONCRETE:7)
Block(-8,9,7,CONCRETE:7)
Block(-8,9,8,CONCRETE:7)
Block(-8,10,-7,CONCRETE:7)
Block(-8,10,-6,CONCRETE:7)
Block(-8,10,-5,CONCRETE:7)
Block(-8,10,-4,CONCRETE:7)
Block(-8,10,-3,CONCRETE:7)
Block(-8,10,-2,CONCRETE:7)
Block(-8,10,-1,CONCRETE:7)
Block(-8,10,0,CONCRETE:7)
Block(-8,10,1,CONCRETE:7)
Block(-8,10,2,CONCRETE:7)
Block(-8,10,3,CONCRETE:7)
Block(-8,10,4,CONCRETE:7)
Block(-8,10,5,CONCRETE:7)
Block(-8,10,6,CONCRETE:7)
Block(-8,10,7,CONCRETE:7)
Block(-8,10,8,CONCRETE:7)
Block(-8,11,-7,CONCRETE:7)
Block(-8,11,-6,CONCRETE:7)
Block(-8,11,-5,CONCRETE:7)
Block(-8,11,-4,CONCRETE:7)
Block(-8,11,-3,CONCRETE:7)
Block(-8,11,-2,CONCRETE:7)
Block(-8,11,-1,CONCRETE:7)
Block(-8,11,0,CONCRETE:7)
Block(-8,11,1,CONCRETE:7)
Block(-8,11,2,CONCRETE:7)
Block(-8,11,3,CONCRETE:7)
Block(-8,11,4,CONCRETE:7)
Block(-8,11,5,CONCRETE:7)
Block(-8,11,6,CONCRETE:7)
Block(-8,11,7,CONCRETE:7)
Block(-8,11,8,CONCRETE:7)
Block(-8,12,-7,CONCRETE:7)
Block(-8,12,-6,CONCRETE:7)
Block(-8,12,-5,CONCRETE:7)
Block(-8,12,-4,CONCRETE:7)
Block(-8,12,-3,CONCRETE:7)
Block(-8,12,-2,CONCRETE:7)
Block(-8,12,-1,CONCRETE:7)
Block(-8,12,0,CONCRETE:7)
Block(-8,12,1,CONCRETE:7)
Block(-8,12,2,CONCRETE:7)
Block(-8,12,3,CONCRETE:7)
Block(-8,12,4,CONCRETE:7)
Block(-8,12,5,CONCRETE:7)
Block(-8,12,6,CONCRETE:7)
Block(-8,12,7,CONCRETE:7)
Block(-8,12,8,CONCRETE:7)
Block(-8,13,-7,CONCRETE:7)
Block(-8,13,-6,CONCRETE:7)
Block(-8,13,-5,CONCRETE:7)
Block(-8,13,-4,CONCRETE:7)
Block(-8,13,-3,CONCRETE:7)
Block(-8,13,-2,CONCRETE:7)
Block(-8,13,-1,CONCRETE:7)
Block(-8,13,0,CONCRETE:7)
Block(-8,13,1,CONCRETE:7)
Block(-8,13,2,CONCRETE:7)
Block(-8,13,3,CONCRETE:7)
Block(-8,13,4,CONCRETE:7)
Block(-8,13,5,CONCRETE:7)
Block(-8,13,6,CONCRETE:7)
Block(-8,13,7,CONCRETE:7)
Block(-8,13,8,CONCRETE:7)
Block(-8,14,-7,CONCRETE:7)
Block(-8,14,-6,CONCRETE:7)
Block(-8,14,-5,CONCRETE:7)
Block(-8,14,-4,CONCRETE:7)
Block(-8,14,-3,CONCRETE:7)
Block(-8,14,-2,CONCRETE:7)
Block(-8,14,-1,CONCRETE:7)
Block(-8,14,0,CONCRETE:7)
Block(-8,14,1,CONCRETE:7)
Block(-8,14,2,CONCRETE:7)
Block(-8,14,3,CONCRETE:7)
Block(-8,14,4,CONCRETE:7)
Block(-8,14,5,CONCRETE:7)
Block(-8,14,6,CONCRETE:7)
Block(-8,14,7,CONCRETE:7)
Block(-8,14,8,CONCRETE:7)
Block(-8,15,-7,CONCRETE:7)
Block(-8,15,-6,CONCRETE:7)
Block(-8,15,-5,CONCRETE:7)
Block(-8,15,-4,CONCRETE:7)
Block(-8,15,-3,CONCRETE:7)
Block(-8,15,-2,CONCRETE:7)
Block(-8,15,-1,CONCRETE:7)
Block(-8,15,0,CONCRETE:7)
Block(-8,15,1,CONCRETE:7)
Block(-8,15,2,CONCRETE:7)
Block(-8,15,3,CONCRETE:7)
Block(-8,15,4,CONCRETE:7)
Block(-8,15,5,CONCRETE:7)
Block(-8,15,6,CONCRETE:7)
Block(-8,15,7,CONCRETE:7)
Block(-8,15,8,CONCRETE:7)
Block(-8,16,-7,CONCRETE:7)
Block(-8,16,-6,CONCRETE:7)
Block(-8,16,-5,CONCRETE:7)
Block(-8,16,-4,CONCRETE:7)
Block(-8,16,-3,CONCRETE:7)
Block(-8,16,-2,CONCRETE:7)
Block(-8,16,-1,CONCRETE:7)
Block(-8,16,0,CONCRETE:7)
Block(-8,16,1,CONCRETE:7)
Block(-8,16,2,CONCRETE:7)
Block(-8,16,3,CONCRETE:7)
Block(-8,16,4,CONCRETE:7)
Block(-8,16,5,CONCRETE:7)
Block(-8,16,6,CONCRETE:7)
Block(-8,16,7,CONCRETE:7)
Block(-8,16,8,CONCRETE:7)
Block(-8,17,-7,CONCRETE:7)
Block(-8,17,-6,CONCRETE:7)
Block(-8,17,-5,CONCRETE:7)
Block(-8,17,-4,CONCRETE:7)
Block(-8,17,-3,CONCRETE:7)
Block(-8,17,-2,CONCRETE:7)
Block(-8,17,-1,CONCRETE:7)
Block(-8,17,0,CONCRETE:7)
Block(-8,17,1,CONCRETE:7)
Block(-8,17,2,CONCRETE:7)
Block(-8,17,3,CONCRETE:7)
Block(-8,17,4,CONCRETE:7)
Block(-8,17,5,CONCRETE:7)
Block(-8,17,6,CONCRETE:7)
Block(-8,17,7,CONCRETE:7)
Block(-8,17,8,CONCRETE:7)
Block(-8,18,-7,CONCRETE:8)
Block(-8,18,-6,STAINED_GLASS_PANE:15)
Block(-8,18,-5,STAINED_GLASS_PANE:15)
Block(-8,18,-4,STAINED_GLASS_PANE:15)
Block(-8,18,-3,STAINED_GLASS_PANE:15)
Block(-8,18,-2,STAINED_GLASS_PANE:15)
Block(-8,18,-1,STAINED_GLASS_PANE:15)
Block(-8,18,2,STAINED_GLASS_PANE:15)
Block(-8,18,3,STAINED_GLASS_PANE:15)
Block(-8,18,4,STAINED_GLASS_PANE:15)
Block(-8,18,5,STAINED_GLASS_PANE:15)
Block(-8,18,6,STAINED_GLASS_PANE:15)
Block(-8,18,7,STAINED_GLASS_PANE:15)
Block(-8,18,8,CONCRETE:8)
Block(-8,19,-7,CONCRETE:8)
Block(-8,19,8,CONCRETE:8)
Block(-8,20,-7,CONCRETE:8)
Block(-8,20,8,CONCRETE:8)
Block(-8,21,-7,CONCRETE:8)
Block(-8,21,8,CONCRETE:8)
Block(-8,22,-7,CONCRETE:8)
Block(-8,22,8,CONCRETE:8)
Block(-8,23,-7,CONCRETE:8)
Block(-8,23,8,CONCRETE:8)
Block(-8,24,-7,CONCRETE:8)
Block(-8,24,8,CONCRETE:8)
Block(-8,25,-7,CONCRETE:8)
Block(-8,25,8,CONCRETE:8)
Block(-8,26,-7,CONCRETE:8)
Block(-8,26,8,CONCRETE:8)
Block(-8,27,-7,CONCRETE:8)
Block(-8,27,8,CONCRETE:8)
Block(-8,28,-7,CONCRETE:8)
Block(-8,28,8,CONCRETE:8)
Block(-8,29,-7,CONCRETE:8)
Block(-8,29,8,CONCRETE:8)
Block(-8,30,-7,CONCRETE:8)
Block(-8,30,8,CONCRETE:8)
Block(-8,31,-7,CONCRETE:8)
Block(-8,31,8,CONCRETE:8)
Block(-8,32,-7,CONCRETE:8)
Block(-8,32,8,CONCRETE:8)
Block(-8,33,-7,CONCRETE:8)
Block(-8,33,8,CONCRETE:8)
Block(-8,34,-7,CONCRETE:8)
Block(-8,34,8,CONCRETE:8)
Block(-8,35,-7,CONCRETE:8)
Block(-8,35,8,CONCRETE:8)
Block(-8,36,-7,CONCRETE:8)
Block(-8,36,8,CONCRETE:8)
Block(-8,37,-7,CONCRETE:8)
Block(-8,37,8,CONCRETE:8)
Block(-8,38,-7,CONCRETE:8)
Block(-8,38,8,CONCRETE:8)
Block(-8,39,-7,CONCRETE:8)
Block(-8,39,8,CONCRETE:8)
Block(-8,40,-7,CONCRETE:8)
Block(-8,40,8,CONCRETE:8)
Block(-8,41,-7,CONCRETE:8)
Block(-8,41,8,CONCRETE:8)
Block(-8,42,-7,CONCRETE:8)
Block(-8,42,8,CONCRETE:8)
Block(-8,43,-7,CONCRETE:8)
Block(-8,43,8,CONCRETE:8)
Block(-8,44,-7,CONCRETE:8)
Block(-8,44,8,CONCRETE:8)
Block(-8,45,-7,CONCRETE:8)
Block(-8,45,8,CONCRETE:8)
Block(-8,46,-7,CONCRETE:8)
Block(-8,46,8,CONCRETE:8)
Block(-8,47,-7,CONCRETE:8)
Block(-8,47,8,CONCRETE:8)
Block(-8,48,-7,CONCRETE:8)
Block(-8,48,8,CONCRETE:8)
Block(-8,49,-7,CONCRETE:8)
Block(-8,49,8,CONCRETE:8)
Block(-8,50,-7,CONCRETE:8)
Block(-8,50,8,CONCRETE:8)
Block(-8,51,-7,CONCRETE:8)
Block(-8,51,8,CONCRETE:8)
Block(-8,52,-7,CONCRETE:8)
Block(-8,52,8,CONCRETE:8)
Block(-8,53,-7,CONCRETE:8)
Block(-8,53,8,CONCRETE:8)
Block(-8,54,-7,CONCRETE:8)
Block(-8,54,8,CONCRETE:8)
Block(-8,55,-7,CONCRETE:8)
Block(-8,55,8,CONCRETE:8)
Block(-8,56,-7,CONCRETE:8)
Block(-8,56,8,CONCRETE:8)
Block(-8,57,-7,CONCRETE:8)
Block(-8,57,8,CONCRETE:8)
Block(-8,58,-7,CONCRETE:8)
Block(-8,58,8,CONCRETE:8)
Block(-8,59,-7,CONCRETE:8)
Block(-8,59,8,CONCRETE:8)
Block(-8,60,-7,CONCRETE:8)
Block(-8,60,8,CONCRETE:8)
Block(-8,61,-7,CONCRETE:8)
Block(-8,61,8,CONCRETE:8)
Block(-8,62,-7,CONCRETE:8)
Block(-8,62,8,CONCRETE:8)
Block(-8,63,-7,CONCRETE:8)
Block(-8,63,8,CONCRETE:8)
Block(-8,64,-7,CONCRETE:8)
Block(-8,64,8,CONCRETE:8)
Block(-8,65,-7,CONCRETE:8)
Block(-8,65,8,CONCRETE:8)
Block(-8,66,-7,CONCRETE:8)
Block(-8,66,8,CONCRETE:8)
Block(-8,67,-7,CONCRETE:8)
Block(-8,67,8,CONCRETE:8)
Block(-8,68,-7,CONCRETE:8)
Block(-8,68,8,CONCRETE:8)
Block(-8,69,-7,CONCRETE:8)
Block(-8,69,8,CONCRETE:8)
Block(-8,70,-7,CONCRETE:8)
Block(-8,70,8,CONCRETE:8)
Block(-8,71,-7,CONCRETE:8)
Block(-8,71,8,CONCRETE:8)
Block(-8,72,-7,CONCRETE:8)
Block(-8,72,8,CONCRETE:8)
Block(-8,73,-7,CONCRETE:8)
Block(-8,73,8,CONCRETE:8)
Block(-8,74,-7,CONCRETE:8)
Block(-8,74,8,CONCRETE:8)
Block(-8,75,-7,CONCRETE:8)
Block(-8,75,8,CONCRETE:8)
Block(-8,76,-7,CONCRETE:8)
Block(-8,76,8,CONCRETE:8)
Block(-8,77,-7,CONCRETE:8)
Block(-8,77,8,CONCRETE:8)
Block(-8,78,-7,CONCRETE:8)
Block(-8,78,8,CONCRETE:8)
Block(-8,79,-7,CONCRETE:8)
Block(-8,79,8,CONCRETE:8)
Block(-8,80,-7,CONCRETE:8)
Block(-8,80,8,CONCRETE:8)
Block(-8,81,-7,CONCRETE:8)
Block(-8,81,8,CONCRETE:8)
Block(-8,82,-7,CONCRETE:8)
Block(-8,82,8,CONCRETE:8)
Block(-8,83,-7,CONCRETE:8)
Block(-8,83,8,CONCRETE:8)
Block(-8,84,-7,CONCRETE:8)
Block(-8,84,8,CONCRETE:8)
Block(-8,85,-7,CONCRETE:8)
Block(-8,85,8,CONCRETE:8)
Block(-8,86,-7,CONCRETE:8)
Block(-8,86,8,CONCRETE:8)
Block(-8,87,-7,CONCRETE:8)
Block(-8,87,8,CONCRETE:8)
Block(-8,88,-7,CONCRETE:8)
Block(-8,88,8,CONCRETE:8)
Block(-8,89,-7,CONCRETE:8)
Block(-8,89,8,CONCRETE:8)
Block(-8,90,-7,CONCRETE:8)
Block(-8,90,8,CONCRETE:8)
Block(-8,91,-7,CONCRETE:8)
Block(-8,91,8,CONCRETE:8)
Block(-8,92,-7,CONCRETE:8)
Block(-8,92,8,CONCRETE:8)
Block(-8,93,-7,CONCRETE:8)
Block(-8,93,8,CONCRETE:8)
Block(-8,94,-7,CONCRETE:8)
Block(-8,94,8,CONCRETE:8)
Block(-8,95,-7,CONCRETE:8)
Block(-8,95,8,CONCRETE:8)
Block(-8,96,-7,CONCRETE:8)
Block(-8,96,8,CONCRETE:8)
Block(-8,97,-7,CONCRETE:8)
Block(-8,97,8,CONCRETE:8)
Block(-8,98,-7,CONCRETE:8)
Block(-8,98,8,CONCRETE:8)
Block(-8,99,-7,CONCRETE:8)
Block(-8,99,8,CONCRETE:8)
Block(-8,100,-7,CONCRETE:8)
Block(-8,100,8,CONCRETE:8)
Block(-8,101,-7,CONCRETE:8)
Block(-8,101,8,CONCRETE:8)
Block(-8,102,-7,CONCRETE:8)
Block(-8,102,8,CONCRETE:8)
Block(-8,103,-7,CONCRETE:8)
Block(-8,103,8,CONCRETE:8)
Block(-8,104,-7,CONCRETE:8)
Block(-8,104,8,CONCRETE:8)
Block(-8,105,-7,CONCRETE:8)
Block(-8,105,8,CONCRETE:8)
Block(-8,106,-7,CONCRETE:8)
Block(-8,106,8,CONCRETE:8)
Block(-8,107,-7,CONCRETE:8)
Block(-8,107,8,CONCRETE:8)
Block(-8,108,-7,CONCRETE:8)
Block(-8,108,8,CONCRETE:8)
Block(-8,109,-7,CONCRETE:8)
Block(-8,109,8,CONCRETE:8)
Block(-8,110,-7,CONCRETE:8)
Block(-8,110,8,CONCRETE:8)
Block(-8,111,-7,CONCRETE:8)
Block(-8,111,8,CONCRETE:8)
Block(-8,112,-7,CONCRETE:8)
Block(-8,112,8,CONCRETE:8)
Block(-8,113,-7,CONCRETE:8)
Block(-8,113,8,CONCRETE:8)
Block(-8,114,-7,CONCRETE:8)
Block(-8,114,8,CONCRETE:8)
Block(-8,115,-7,CONCRETE:8)
Block(-8,115,8,CONCRETE:8)
Block(-8,116,-7,CONCRETE:8)
Block(-8,116,8,CONCRETE:8)
Block(-8,117,-7,CONCRETE:8)
Block(-8,117,8,CONCRETE:8)
Block(-8,118,-7,CONCRETE:8)
Block(-8,118,8,CONCRETE:8)
Block(-8,119,-7,CONCRETE:8)
Block(-8,119,8,CONCRETE:8)
Block(-8,120,-7,CONCRETE:8)
Block(-8,120,8,CONCRETE:8)
Block(-8,121,-7,CONCRETE:8)
Block(-8,121,8,CONCRETE:8)
Block(-8,122,-7,CONCRETE:8)
Block(-8,122,8,CONCRETE:8)
Block(-8,123,-7,CONCRETE:8)
Block(-8,123,8,CONCRETE:8)
Block(-8,124,-7,CONCRETE:8)
Block(-8,124,8,CONCRETE:8)
Block(-8,125,-7,CONCRETE:8)
Block(-8,125,8,CONCRETE:8)
Block(-8,126,-7,CONCRETE:8)
Block(-8,126,8,CONCRETE:8)
Block(-8,127,-7,CONCRETE:8)
Block(-8,127,8,CONCRETE:8)
Block(-8,128,-7,CONCRETE:8)
Block(-8,128,8,CONCRETE:8)
Block(-8,129,-7,CONCRETE:8)
Block(-8,129,8,CONCRETE:8)
Block(-8,130,-7,CONCRETE:8)
Block(-8,130,8,CONCRETE:8)
Block(-8,131,-7,CONCRETE:8)
Block(-8,131,8,CONCRETE:8)
Block(-8,132,-7,CONCRETE:8)
Block(-8,132,8,CONCRETE:8)
Block(-8,133,-7,CONCRETE:8)
Block(-8,133,8,CONCRETE:8)
Block(-8,134,-7,CONCRETE:8)
Block(-8,134,8,CONCRETE:8)
Block(-8,135,-7,CONCRETE:8)
Block(-8,135,8,CONCRETE:8)
Block(-8,136,-7,CONCRETE:8)
Block(-8,136,8,CONCRETE:8)
Block(-8,137,-7,CONCRETE:8)
Block(-8,137,8,CONCRETE:8)
Block(-8,138,-7,CONCRETE:8)
Block(-8,138,8,CONCRETE:8)
Block(-8,139,-7,CONCRETE:8)
Block(-8,139,8,CONCRETE:8)
Block(-8,140,-7,CONCRETE:8)
Block(-8,140,8,CONCRETE:8)
Block(-8,141,-7,CONCRETE:8)
Block(-8,141,8,CONCRETE:8)
Block(-8,142,-7,CONCRETE:8)
Block(-8,142,8,CONCRETE:8)
Block(-8,143,-7,CONCRETE:8)
Block(-8,143,8,CONCRETE:8)
Block(-8,144,-7,CONCRETE:8)
Block(-8,144,8,CONCRETE:8)
Block(-8,145,-7,CONCRETE:8)
Block(-8,145,8,CONCRETE:8)
Block(-8,146,-7,CONCRETE:8)
Block(-8,146,8,CONCRETE:8)
Block(-8,147,-7,CONCRETE:8)
Block(-8,147,8,CONCRETE:8)
Block(-8,148,-7,CONCRETE:8)
Block(-8,148,8,CONCRETE:8)
Block(-8,149,-7,CONCRETE:8)
Block(-8,149,8,CONCRETE:8)
Block(-8,150,-7,CONCRETE:8)
Block(-8,150,8,CONCRETE:8)
Block(-8,151,-7,CONCRETE:8)
Block(-8,151,8,CONCRETE:8)
Block(-8,152,-7,CONCRETE:8)
Block(-8,152,8,CONCRETE:8)
Block(-8,153,-7,CONCRETE:8)
Block(-8,153,8,CONCRETE:8)
Block(-8,154,-7,CONCRETE:8)
Block(-8,154,8,CONCRETE:8)
Block(-8,155,-7,CONCRETE:8)
Block(-8,155,8,CONCRETE:8)
Block(-8,156,-7,CONCRETE:8)
Block(-8,156,8,CONCRETE:8)
Block(-8,157,-7,CONCRETE:8)
Block(-8,157,8,CONCRETE:8)
Block(-8,158,-7,CONCRETE:8)
Block(-8,158,8,CONCRETE:8)
Block(-8,159,-7,CONCRETE:8)
Block(-8,159,8,CONCRETE:8)
Block(-8,160,-7,CONCRETE:8)
Block(-8,160,8,CONCRETE:8)
Block(-8,161,-7,CONCRETE:8)
Block(-8,161,8,CONCRETE:8)
Block(-8,162,-7,CONCRETE:8)
Block(-8,162,8,CONCRETE:8)
Block(-8,163,-7,CONCRETE:8)
Block(-8,163,8,CONCRETE:8)
Block(-8,164,-7,CONCRETE:8)
Block(-8,164,8,CONCRETE:8)
Block(-8,165,-7,CONCRETE:8)
Block(-8,165,8,CONCRETE:8)
Block(-8,166,-7,CONCRETE:8)
Block(-8,166,8,CONCRETE:8)
Block(-8,167,-7,CONCRETE:8)
Block(-8,167,8,CONCRETE:8)
Block(-8,168,-7,CONCRETE:8)
Block(-8,168,8,CONCRETE:8)
Block(-8,169,-7,CONCRETE:8)
Block(-8,169,8,CONCRETE:8)
Block(-8,170,-7,CONCRETE:8)
Block(-8,170,8,CONCRETE:8)
Block(-8,171,-7,CONCRETE:8)
Block(-8,171,8,CONCRETE:8)
Block(-8,172,-7,CONCRETE:8)
Block(-8,172,8,CONCRETE:8)
Block(-8,173,-7,CONCRETE:8)
Block(-8,173,8,CONCRETE:8)
Block(-8,174,-7,CONCRETE:8)
Block(-8,174,8,CONCRETE:8)
Block(-8,175,-7,CONCRETE:8)
Block(-8,175,8,CONCRETE:8)
Block(-8,176,-7,CONCRETE:8)
Block(-8,176,8,CONCRETE:8)
Block(-8,177,-7,CONCRETE:8)
Block(-8,177,8,CONCRETE:8)
Block(-8,178,-7,CONCRETE:8)
Block(-8,178,8,CONCRETE:8)
Block(-8,179,-7,CONCRETE:8)
Block(-8,179,8,CONCRETE:8)
Block(-8,180,-7,CONCRETE:8)
Block(-8,180,8,CONCRETE:8)
Block(-8,181,-7,CONCRETE:8)
Block(-8,181,8,CONCRETE:8)
Block(-8,182,-7,CONCRETE:8)
Block(-8,182,8,CONCRETE:8)
Block(-8,183,-7,CONCRETE:8)
Block(-8,183,8,CONCRETE:8)
Block(-8,184,-7,CONCRETE:8)
Block(-8,184,8,CONCRETE:8)
Block(-8,185,-7,CONCRETE:8)
Block(-8,185,8,CONCRETE:8)
Block(-8,186,-7,CONCRETE:8)
Block(-8,186,8,CONCRETE:8)
Block(-8,187,-7,CONCRETE:8)
Block(-8,187,8,CONCRETE:8)
Block(-8,188,-7,CONCRETE:8)
Block(-8,188,8,CONCRETE:8)
Block(-8,189,-7,CONCRETE:8)
Block(-8,189,8,CONCRETE:8)
Block(-8,190,-7,CONCRETE:8)
Block(-8,190,8,CONCRETE:8)
Block(-8,191,-7,CONCRETE:8)
Block(-8,191,8,CONCRETE:8)
Block(-8,192,-7,CONCRETE:8)
Block(-8,192,8,CONCRETE:8)
Block(-8,193,-7,CONCRETE:8)
Block(-8,193,8,CONCRETE:8)
Block(-8,194,-7,CONCRETE:8)
Block(-8,194,8,CONCRETE:8)
Block(-8,195,-7,CONCRETE:8)
Block(-8,195,8,CONCRETE:8)
Block(-8,196,-7,CONCRETE:8)
Block(-8,196,8,CONCRETE:8)
Block(-8,197,-7,CONCRETE:8)
Block(-8,197,8,CONCRETE:8)
Block(-8,198,-7,CONCRETE:8)
Block(-8,198,8,CONCRETE:8)
Block(-8,199,-7,CONCRETE:8)
Block(-8,199,8,CONCRETE:8)
Block(-8,200,-7,CONCRETE:8)
Block(-8,200,8,CONCRETE:8)
Block(-8,201,-7,CONCRETE:8)
Block(-8,201,8,CONCRETE:8)
Block(-8,202,-7,STEP:0)
Block(-8,202,8,STEP:0)
Block(-7,0,-7,CONCRETE:7)
Block(-7,0,-6,CONCRETE:7)
Block(-7,0,-5,CONCRETE:7)
Block(-7,0,-4,CONCRETE:7)
Block(-7,0,-3,CONCRETE:7)
Block(-7,0,-2,CONCRETE:7)
Block(-7,0,-1,CONCRETE:7)
Block(-7,0,0,CONCRETE:7)
Block(-7,0,1,CONCRETE:7)
Block(-7,0,2,CONCRETE:7)
Block(-7,0,3,CONCRETE:7)
Block(-7,0,4,CONCRETE:7)
Block(-7,0,5,CONCRETE:7)
Block(-7,0,6,CONCRETE:7)
Block(-7,0,7,CONCRETE:7)
Block(-7,0,8,CONCRETE:7)
Block(-7,1,-7,CONCRETE:7)
Block(-7,1,-6,CONCRETE:7)
Block(-7,1,-5,CONCRETE:7)
Block(-7,1,-4,CONCRETE:7)
Block(-7,1,-3,CONCRETE:7)
Block(-7,1,-2,CONCRETE:7)
Block(-7,1,-1,CONCRETE:7)
Block(-7,1,0,CONCRETE:7)
Block(-7,1,1,CONCRETE:7)
Block(-7,1,2,CONCRETE:7)
Block(-7,1,3,CONCRETE:7)
Block(-7,1,4,CONCRETE:7)
Block(-7,1,5,CONCRETE:7)
Block(-7,1,6,CONCRETE:7)
Block(-7,1,7,CONCRETE:7)
Block(-7,1,8,CONCRETE:7)
Block(-7,2,-7,CONCRETE:7)
Block(-7,2,-6,CONCRETE:7)
Block(-7,2,-5,CONCRETE:7)
Block(-7,2,-4,CONCRETE:7)
Block(-7,2,-3,CONCRETE:7)
Block(-7,2,-2,CONCRETE:7)
Block(-7,2,-1,CONCRETE:7)
Block(-7,2,0,CONCRETE:7)
Block(-7,2,1,CONCRETE:7)
Block(-7,2,2,CONCRETE:7)
Block(-7,2,3,CONCRETE:7)
Block(-7,2,4,CONCRETE:7)
Block(-7,2,5,CONCRETE:7)
Block(-7,2,6,CONCRETE:7)
Block(-7,2,7,CONCRETE:7)
Block(-7,2,8,CONCRETE:7)
Block(-7,3,-7,CONCRETE:7)
Block(-7,3,-6,CONCRETE:7)
Block(-7,3,-5,CONCRETE:7)
Block(-7,3,-4,CONCRETE:7)
Block(-7,3,-3,CONCRETE:7)
Block(-7,3,-2,CONCRETE:7)
Block(-7,3,-1,CONCRETE:7)
Block(-7,3,0,CONCRETE:7)
Block(-7,3,1,CONCRETE:7)
Block(-7,3,2,CONCRETE:7)
Block(-7,3,3,CONCRETE:7)
Block(-7,3,4,CONCRETE:7)
Block(-7,3,5,CONCRETE:7)
Block(-7,3,6,CONCRETE:7)
Block(-7,3,7,CONCRETE:7)
Block(-7,3,8,CONCRETE:7)
Block(-7,4,-7,CONCRETE:7)
Block(-7,4,-6,CONCRETE:7)
Block(-7,4,-5,CONCRETE:7)
Block(-7,4,-4,CONCRETE:7)
Block(-7,4,-3,CONCRETE:7)
Block(-7,4,-2,CONCRETE:7)
Block(-7,4,-1,CONCRETE:7)
Block(-7,4,0,CONCRETE:7)
Block(-7,4,1,CONCRETE:7)
Block(-7,4,2,CONCRETE:7)
Block(-7,4,3,CONCRETE:7)
Block(-7,4,4,CONCRETE:7)
Block(-7,4,5,CONCRETE:7)
Block(-7,4,6,CONCRETE:7)
Block(-7,4,7,CONCRETE:7)
Block(-7,4,8,CONCRETE:7)
Block(-7,5,-7,CONCRETE:7)
Block(-7,5,-6,CONCRETE:7)
Block(-7,5,-5,CONCRETE:7)
Block(-7,5,-4,CONCRETE:7)
Block(-7,5,-3,CONCRETE:7)
Block(-7,5,-2,CONCRETE:7)
Block(-7,5,-1,CONCRETE:7)
Block(-7,5,0,CONCRETE:7)
Block(-7,5,1,CONCRETE:7)
Block(-7,5,2,CONCRETE:7)
Block(-7,5,3,CONCRETE:7)
Block(-7,5,4,CONCRETE:7)
Block(-7,5,5,CONCRETE:7)
Block(-7,5,6,CONCRETE:7)
Block(-7,5,7,CONCRETE:7)
Block(-7,5,8,CONCRETE:7)
Block(-7,6,-7,CONCRETE:7)
Block(-7,6,-6,CONCRETE:7)
Block(-7,6,-5,CONCRETE:7)
Block(-7,6,-4,CONCRETE:7)
Block(-7,6,-3,CONCRETE:7)
Block(-7,6,-2,CONCRETE:7)
Block(-7,6,-1,CONCRETE:7)
Block(-7,6,0,CONCRETE:7)
Block(-7,6,1,CONCRETE:7)
Block(-7,6,2,CONCRETE:7)
Block(-7,6,3,CONCRETE:7)
Block(-7,6,4,CONCRETE:7)
Block(-7,6,5,CONCRETE:7)
Block(-7,6,6,CONCRETE:7)
Block(-7,6,7,CONCRETE:7)
Block(-7,6,8,CONCRETE:7)
Block(-7,7,-7,CONCRETE:7)
Block(-7,7,-6,CONCRETE:7)
Block(-7,7,-5,CONCRETE:7)
Block(-7,7,-4,CONCRETE:7)
Block(-7,7,-3,CONCRETE:7)
Block(-7,7,-2,CONCRETE:7)
Block(-7,7,-1,CONCRETE:7)
Block(-7,7,0,CONCRETE:7)
Block(-7,7,1,CONCRETE:7)
Block(-7,7,2,CONCRETE:7)
Block(-7,7,3,CONCRETE:7)
Block(-7,7,4,CONCRETE:7)
Block(-7,7,5,CONCRETE:7)
Block(-7,7,6,CONCRETE:7)
Block(-7,7,7,CONCRETE:7)
Block(-7,7,8,CONCRETE:7)
Block(-7,8,-7,CONCRETE:7)
Block(-7,8,-6,CONCRETE:7)
Block(-7,8,-5,CONCRETE:7)
Block(-7,8,-4,CONCRETE:7)
Block(-7,8,-3,CONCRETE:7)
Block(-7,8,-2,CONCRETE:7)
Block(-7,8,-1,CONCRETE:7)
Block(-7,8,0,CONCRETE:7)
Block(-7,8,1,CONCRETE:7)
Block(-7,8,2,CONCRETE:7)
Block(-7,8,3,CONCRETE:7)
Block(-7,8,4,CONCRETE:7)
Block(-7,8,5,CONCRETE:7)
Block(-7,8,6,CONCRETE:7)
Block(-7,8,7,CONCRETE:7)
Block(-7,8,8,CONCRETE:7)
Block(-7,9,-7,CONCRETE:8)
Block(-7,9,-6,CONCRETE:8)
Block(-7,9,-5,CONCRETE:8)
Block(-7,9,-4,CONCRETE:8)
Block(-7,9,-3,CONCRETE:8)
Block(-7,9,-2,CONCRETE:8)
Block(-7,9,-1,CONCRETE:8)
Block(-7,9,0,CONCRETE:8)
Block(-7,9,1,CONCRETE:8)
Block(-7,9,2,CONCRETE:8)
Block(-7,9,3,CONCRETE:8)
Block(-7,9,4,CONCRETE:8)
Block(-7,9,5,CONCRETE:8)
Block(-7,9,6,CONCRETE:8)
Block(-7,9,7,CONCRETE:8)
Block(-7,9,8,CONCRETE:8)
Block(-7,10,-7,CONCRETE:8)
Block(-7,10,-6,CONCRETE:8)
Block(-7,10,-5,CONCRETE:8)
Block(-7,10,-4,CONCRETE:8)
Block(-7,10,-3,CONCRETE:8)
Block(-7,10,-2,CONCRETE:8)
Block(-7,10,-1,CONCRETE:8)
Block(-7,10,0,CONCRETE:8)
Block(-7,10,1,CONCRETE:8)
Block(-7,10,2,CONCRETE:8)
Block(-7,10,3,CONCRETE:8)
Block(-7,10,4,CONCRETE:8)
Block(-7,10,5,CONCRETE:8)
Block(-7,10,6,CONCRETE:8)
Block(-7,10,7,CONCRETE:8)
Block(-7,10,8,CONCRETE:8)
Block(-7,11,-7,CONCRETE:8)
Block(-7,11,-6,CONCRETE:8)
Block(-7,11,-5,CONCRETE:8)
Block(-7,11,-4,CONCRETE:8)
Block(-7,11,-3,CONCRETE:8)
Block(-7,11,-2,CONCRETE:8)
Block(-7,11,-1,CONCRETE:8)
Block(-7,11,0,CONCRETE:8)
Block(-7,11,1,CONCRETE:8)
Block(-7,11,2,CONCRETE:8)
Block(-7,11,3,CONCRETE:8)
Block(-7,11,4,CONCRETE:8)
Block(-7,11,5,CONCRETE:8)
Block(-7,11,6,CONCRETE:8)
Block(-7,11,7,CONCRETE:8)
Block(-7,11,8,CONCRETE:8)
Block(-7,12,-7,CONCRETE:8)
Block(-7,12,-6,STATIONARY_WATER:0)
Block(-7,12,-5,STATIONARY_WATER:0)
Block(-7,12,-4,STATIONARY_WATER:0)
Block(-7,12,-3,STATIONARY_WATER:0)
Block(-7,12,-2,STATIONARY_WATER:0)
Block(-7,12,-1,STATIONARY_WATER:0)
Block(-7,12,0,STATIONARY_WATER:0)
Block(-7,12,1,STATIONARY_WATER:0)
Block(-7,12,2,STATIONARY_WATER:0)
Block(-7,12,3,STATIONARY_WATER:0)
Block(-7,12,4,STATIONARY_WATER:0)
Block(-7,12,5,STATIONARY_WATER:0)
Block(-7,12,6,STATIONARY_WATER:0)
Block(-7,12,7,STATIONARY_WATER:0)
Block(-7,12,8,CONCRETE:8)
Block(-7,13,-7,CONCRETE:8)
Block(-7,13,-6,AIR:0)
Block(-7,13,-5,AIR:0)
Block(-7,13,-4,AIR:0)
Block(-7,13,-3,AIR:0)
Block(-7,13,-2,AIR:0)
Block(-7,13,-1,AIR:0)
Block(-7,13,0,AIR:0)
Block(-7,13,1,AIR:0)
Block(-7,13,2,AIR:0)
Block(-7,13,3,AIR:0)
Block(-7,13,4,AIR:0)
Block(-7,13,5,AIR:0)
Block(-7,13,6,AIR:0)
Block(-7,13,7,AIR:0)
Block(-7,13,8,CONCRETE:8)
Block(-7,14,-7,CONCRETE:8)
Block(-7,14,-6,AIR:0)
Block(-7,14,-5,AIR:0)
Block(-7,14,-4,AIR:0)
Block(-7,14,-3,AIR:0)
Block(-7,14,-2,AIR:0)
Block(-7,14,-1,AIR:0)
Block(-7,14,0,AIR:0)
Block(-7,14,1,AIR:0)
Block(-7,14,2,AIR:0)
Block(-7,14,3,AIR:0)
Block(-7,14,4,AIR:0)
Block(-7,14,5,AIR:0)
Block(-7,14,6,AIR:0)
Block(-7,14,7,AIR:0)
Block(-7,14,8,CONCRETE:8)
Block(-7,15,-7,CONCRETE:8)
Block(-7,15,-6,AIR:0)
Block(-7,15,-5,AIR:0)
Block(-7,15,-4,AIR:0)
Block(-7,15,-3,AIR:0)
Block(-7,15,-2,AIR:0)
Block(-7,15,-1,AIR:0)
Block(-7,15,0,AIR:0)
Block(-7,15,1,AIR:0)
Block(-7,15,2,AIR:0)
Block(-7,15,3,AIR:0)
Block(-7,15,4,AIR:0)
Block(-7,15,5,AIR:0)
Block(-7,15,6,AIR:0)
Block(-7,15,7,AIR:0)
Block(-7,15,8,CONCRETE:8)
Block(-7,16,-7,CONCRETE:8)
Block(-7,16,-6,AIR:0)
Block(-7,16,-5,AIR:0)
Block(-7,16,-4,AIR:0)
Block(-7,16,-3,AIR:0)
Block(-7,16,-2,AIR:0)
Block(-7,16,-1,AIR:0)
Block(-7,16,0,AIR:0)
Block(-7,16,1,AIR:0)
Block(-7,16,2,AIR:0)
Block(-7,16,3,AIR:0)
Block(-7,16,4,AIR:0)
Block(-7,16,5,AIR:0)
Block(-7,16,6,AIR:0)
Block(-7,16,7,AIR:0)
Block(-7,16,8,CONCRETE:8)
Block(-7,17,-7,CONCRETE:8)
Block(-7,17,-6,AIR:0)
Block(-7,17,-5,AIR:0)
Block(-7,17,-4,AIR:0)
Block(-7,17,-3,AIR:0)
Block(-7,17,-2,AIR:0)
Block(-7,17,-1,STAINED_GLASS:15)
Block(-7,17,0,CONCRETE:8)
Block(-7,17,1,CONCRETE:8)
Block(-7,17,2,STAINED_GLASS:15)
Block(-7,17,3,AIR:0)
Block(-7,17,4,AIR:0)
Block(-7,17,5,AIR:0)
Block(-7,17,6,AIR:0)
Block(-7,17,7,AIR:0)
Block(-7,17,8,CONCRETE:8)
Block(-7,18,-7,CONCRETE:8)
Block(-7,18,-1,STAINED_GLASS_PANE:15)
Block(-7,18,2,STAINED_GLASS_PANE:15)
Block(-7,18,8,CONCRETE:8)
Block(-7,19,-7,CONCRETE:8)
Block(-7,19,8,CONCRETE:8)
Block(-7,20,-7,CONCRETE:8)
Block(-7,20,8,CONCRETE:8)
Block(-7,21,-7,CONCRETE:8)
Block(-7,21,8,CONCRETE:8)
Block(-7,22,-7,CONCRETE:8)
Block(-7,22,8,CONCRETE:8)
Block(-7,23,-7,CONCRETE:8)
Block(-7,23,8,CONCRETE:8)
Block(-7,24,-7,CONCRETE:8)
Block(-7,24,8,CONCRETE:8)
Block(-7,25,-7,CONCRETE:8)
Block(-7,25,8,CONCRETE:8)
Block(-7,26,-7,CONCRETE:8)
Block(-7,26,8,CONCRETE:8)
Block(-7,27,-7,CONCRETE:8)
Block(-7,27,8,CONCRETE:8)
Block(-7,28,-7,CONCRETE:8)
Block(-7,28,8,CONCRETE:8)
Block(-7,29,-7,CONCRETE:8)
Block(-7,29,8,CONCRETE:8)
Block(-7,30,-7,CONCRETE:8)
Block(-7,30,8,CONCRETE:8)
Block(-7,31,-7,CONCRETE:8)
Block(-7,31,8,CONCRETE:8)
Block(-7,32,-7,CONCRETE:8)
Block(-7,32,8,CONCRETE:8)
Block(-7,33,-7,CONCRETE:8)
Block(-7,33,8,CONCRETE:8)
Block(-7,34,-7,CONCRETE:8)
Block(-7,34,8,CONCRETE:8)
Block(-7,35,-7,CONCRETE:8)
Block(-7,35,8,CONCRETE:8)
Block(-7,36,-7,CONCRETE:8)
Block(-7,36,8,CONCRETE:8)
Block(-7,37,-7,CONCRETE:8)
Block(-7,37,8,CONCRETE:8)
Block(-7,38,-7,CONCRETE:8)
Block(-7,38,8,CONCRETE:8)
Block(-7,39,-7,CONCRETE:8)
Block(-7,39,8,CONCRETE:8)
Block(-7,40,-7,CONCRETE:8)
Block(-7,40,8,CONCRETE:8)
Block(-7,41,-7,CONCRETE:8)
Block(-7,41,8,CONCRETE:8)
Block(-7,42,-7,CONCRETE:8)
Block(-7,42,8,CONCRETE:8)
Block(-7,43,-7,CONCRETE:8)
Block(-7,43,8,CONCRETE:8)
Block(-7,44,-7,CONCRETE:8)
Block(-7,44,8,CONCRETE:8)
Block(-7,45,-7,CONCRETE:8)
Block(-7,45,8,CONCRETE:8)
Block(-7,46,-7,CONCRETE:8)
Block(-7,46,8,CONCRETE:8)
Block(-7,47,-7,CONCRETE:8)
Block(-7,47,8,CONCRETE:8)
Block(-7,48,-7,CONCRETE:8)
Block(-7,48,8,CONCRETE:8)
Block(-7,49,-7,CONCRETE:8)
Block(-7,49,8,CONCRETE:8)
Block(-7,50,-7,CONCRETE:8)
Block(-7,50,8,CONCRETE:8)
Block(-7,51,-7,CONCRETE:8)
Block(-7,51,8,CONCRETE:8)
Block(-7,52,-7,CONCRETE:8)
Block(-7,52,8,CONCRETE:8)
Block(-7,53,-7,CONCRETE:8)
Block(-7,53,8,CONCRETE:8)
Block(-7,54,-7,CONCRETE:8)
Block(-7,54,8,CONCRETE:8)
Block(-7,55,-7,CONCRETE:8)
Block(-7,55,8,CONCRETE:8)
Block(-7,56,-7,CONCRETE:8)
Block(-7,56,8,CONCRETE:8)
Block(-7,57,-7,CONCRETE:8)
Block(-7,57,8,CONCRETE:8)
Block(-7,58,-7,CONCRETE:8)
Block(-7,58,8,CONCRETE:8)
Block(-7,59,-7,CONCRETE:8)
Block(-7,59,8,CONCRETE:8)
Block(-7,60,-7,CONCRETE:8)
Block(-7,60,8,CONCRETE:8)
Block(-7,61,-7,CONCRETE:8)
Block(-7,61,8,CONCRETE:8)
Block(-7,62,-7,CONCRETE:8)
Block(-7,62,8,CONCRETE:8)
Block(-7,63,-7,CONCRETE:8)
Block(-7,63,8,CONCRETE:8)
Block(-7,64,-7,CONCRETE:8)
Block(-7,64,8,CONCRETE:8)
Block(-7,65,-7,CONCRETE:8)
Block(-7,65,8,CONCRETE:8)
Block(-7,66,-7,CONCRETE:8)
Block(-7,66,8,CONCRETE:8)
Block(-7,67,-7,CONCRETE:8)
Block(-7,67,8,CONCRETE:8)
Block(-7,68,-7,CONCRETE:8)
Block(-7,68,8,CONCRETE:8)
Block(-7,69,-7,CONCRETE:8)
Block(-7,69,8,CONCRETE:8)
Block(-7,70,-7,CONCRETE:8)
Block(-7,70,8,CONCRETE:8)
Block(-7,71,-7,CONCRETE:8)
Block(-7,71,8,CONCRETE:8)
Block(-7,72,-7,CONCRETE:8)
Block(-7,72,8,CONCRETE:8)
Block(-7,73,-7,CONCRETE:8)
Block(-7,73,8,CONCRETE:8)
Block(-7,74,-7,CONCRETE:8)
Block(-7,74,8,CONCRETE:8)
Block(-7,75,-7,CONCRETE:8)
Block(-7,75,8,CONCRETE:8)
Block(-7,76,-7,CONCRETE:8)
Block(-7,76,8,CONCRETE:8)
Block(-7,77,-7,CONCRETE:8)
Block(-7,77,8,CONCRETE:8)
Block(-7,78,-7,CONCRETE:8)
Block(-7,78,8,CONCRETE:8)
Block(-7,79,-7,CONCRETE:8)
Block(-7,79,8,CONCRETE:8)
Block(-7,80,-7,CONCRETE:8)
Block(-7,80,8,CONCRETE:8)
Block(-7,81,-7,CONCRETE:8)
Block(-7,81,8,CONCRETE:8)
Block(-7,82,-7,CONCRETE:8)
Block(-7,82,8,CONCRETE:8)
Block(-7,83,-7,CONCRETE:8)
Block(-7,83,8,CONCRETE:8)
Block(-7,84,-7,CONCRETE:8)
Block(-7,84,8,CONCRETE:8)
Block(-7,85,-7,CONCRETE:8)
Block(-7,85,8,CONCRETE:8)
Block(-7,86,-7,CONCRETE:8)
Block(-7,86,8,CONCRETE:8)
Block(-7,87,-7,CONCRETE:8)
Block(-7,87,8,CONCRETE:8)
Block(-7,88,-7,CONCRETE:8)
Block(-7,88,8,CONCRETE:8)
Block(-7,89,-7,CONCRETE:8)
Block(-7,89,8,CONCRETE:8)
Block(-7,90,-7,CONCRETE:8)
Block(-7,90,8,CONCRETE:8)
Block(-7,91,-7,CONCRETE:8)
Block(-7,91,8,CONCRETE:8)
Block(-7,92,-7,CONCRETE:8)
Block(-7,92,8,CONCRETE:8)
Block(-7,93,-7,CONCRETE:8)
Block(-7,93,8,CONCRETE:8)
Block(-7,94,-7,CONCRETE:8)
Block(-7,94,8,CONCRETE:8)
Block(-7,95,-7,CONCRETE:8)
Block(-7,95,8,CONCRETE:8)
Block(-7,96,-7,CONCRETE:8)
Block(-7,96,8,CONCRETE:8)
Block(-7,97,-7,CONCRETE:8)
Block(-7,97,8,CONCRETE:8)
Block(-7,98,-7,CONCRETE:8)
Block(-7,98,8,CONCRETE:8)
Block(-7,99,-7,CONCRETE:8)
Block(-7,99,8,CONCRETE:8)
Block(-7,100,-7,CONCRETE:8)
Block(-7,100,8,CONCRETE:8)
Block(-7,101,-7,CONCRETE:8)
Block(-7,101,8,CONCRETE:8)
Block(-7,102,-7,CONCRETE:8)
Block(-7,102,8,CONCRETE:8)
Block(-7,103,-7,CONCRETE:8)
Block(-7,103,8,CONCRETE:8)
Block(-7,104,-7,CONCRETE:8)
Block(-7,104,8,CONCRETE:8)
Block(-7,105,-7,CONCRETE:8)
Block(-7,105,8,CONCRETE:8)
Block(-7,106,-7,CONCRETE:8)
Block(-7,106,8,CONCRETE:8)
Block(-7,107,-7,CONCRETE:8)
Block(-7,107,8,CONCRETE:8)
Block(-7,108,-7,CONCRETE:8)
Block(-7,108,8,CONCRETE:8)
Block(-7,109,-7,CONCRETE:8)
Block(-7,109,8,CONCRETE:8)
Block(-7,110,-7,CONCRETE:8)
Block(-7,110,8,CONCRETE:8)
Block(-7,111,-7,CONCRETE:8)
Block(-7,111,8,CONCRETE:8)
Block(-7,112,-7,CONCRETE:8)
Block(-7,112,8,CONCRETE:8)
Block(-7,113,-7,CONCRETE:8)
Block(-7,113,8,CONCRETE:8)
Block(-7,114,-7,CONCRETE:8)
Block(-7,114,8,CONCRETE:8)
Block(-7,115,-7,CONCRETE:8)
Block(-7,115,8,CONCRETE:8)
Block(-7,116,-7,CONCRETE:8)
Block(-7,116,8,CONCRETE:8)
Block(-7,117,-7,CONCRETE:8)
Block(-7,117,8,CONCRETE:8)
Block(-7,118,-7,CONCRETE:8)
Block(-7,118,8,CONCRETE:8)
Block(-7,119,-7,CONCRETE:8)
Block(-7,119,8,CONCRETE:8)
Block(-7,120,-7,CONCRETE:8)
Block(-7,120,8,CONCRETE:8)
Block(-7,121,-7,CONCRETE:8)
Block(-7,121,8,CONCRETE:8)
Block(-7,122,-7,CONCRETE:8)
Block(-7,122,8,CONCRETE:8)
Block(-7,123,-7,CONCRETE:8)
Block(-7,123,8,CONCRETE:8)
Block(-7,124,-7,CONCRETE:8)
Block(-7,124,8,CONCRETE:8)
Block(-7,125,-7,CONCRETE:8)
Block(-7,125,8,CONCRETE:8)
Block(-7,126,-7,CONCRETE:8)
Block(-7,126,8,CONCRETE:8)
Block(-7,127,-7,CONCRETE:8)
Block(-7,127,8,CONCRETE:8)
Block(-7,128,-7,CONCRETE:8)
Block(-7,128,8,CONCRETE:8)
Block(-7,129,-7,CONCRETE:8)
Block(-7,129,8,CONCRETE:8)
Block(-7,130,-7,CONCRETE:8)
Block(-7,130,8,CONCRETE:8)
Block(-7,131,-7,CONCRETE:8)
Block(-7,131,8,CONCRETE:8)
Block(-7,132,-7,CONCRETE:8)
Block(-7,132,8,CONCRETE:8)
Block(-7,133,-7,CONCRETE:8)
Block(-7,133,8,CONCRETE:8)
Block(-7,134,-7,CONCRETE:8)
Block(-7,134,8,CONCRETE:8)
Block(-7,135,-7,CONCRETE:8)
Block(-7,135,8,CONCRETE:8)
Block(-7,136,-7,CONCRETE:8)
Block(-7,136,8,CONCRETE:8)
Block(-7,137,-7,CONCRETE:8)
Block(-7,137,8,CONCRETE:8)
Block(-7,138,-7,CONCRETE:8)
Block(-7,138,8,CONCRETE:8)
Block(-7,139,-7,CONCRETE:8)
Block(-7,139,8,CONCRETE:8)
Block(-7,140,-7,CONCRETE:8)
Block(-7,140,8,CONCRETE:8)
Block(-7,141,-7,CONCRETE:8)
Block(-7,141,8,CONCRETE:8)
Block(-7,142,-7,CONCRETE:8)
Block(-7,142,8,CONCRETE:8)
Block(-7,143,-7,CONCRETE:8)
Block(-7,143,8,CONCRETE:8)
Block(-7,144,-7,CONCRETE:8)
Block(-7,144,8,CONCRETE:8)
Block(-7,145,-7,CONCRETE:8)
Block(-7,145,8,CONCRETE:8)
Block(-7,146,-7,CONCRETE:8)
Block(-7,146,8,CONCRETE:8)
Block(-7,147,-7,CONCRETE:8)
Block(-7,147,8,CONCRETE:8)
Block(-7,148,-7,CONCRETE:8)
Block(-7,148,8,CONCRETE:8)
Block(-7,149,-7,CONCRETE:8)
Block(-7,149,8,CONCRETE:8)
Block(-7,150,-7,CONCRETE:8)
Block(-7,150,8,CONCRETE:8)
Block(-7,151,-7,CONCRETE:8)
Block(-7,151,8,CONCRETE:8)
Block(-7,152,-7,CONCRETE:8)
Block(-7,152,8,CONCRETE:8)
Block(-7,153,-7,CONCRETE:8)
Block(-7,153,8,CONCRETE:8)
Block(-7,154,-7,CONCRETE:8)
Block(-7,154,8,CONCRETE:8)
Block(-7,155,-7,CONCRETE:8)
Block(-7,155,8,CONCRETE:8)
Block(-7,156,-7,CONCRETE:8)
Block(-7,156,8,CONCRETE:8)
Block(-7,157,-7,CONCRETE:8)
Block(-7,157,8,CONCRETE:8)
Block(-7,158,-7,CONCRETE:8)
Block(-7,158,8,CONCRETE:8)
Block(-7,159,-7,CONCRETE:8)
Block(-7,159,8,CONCRETE:8)
Block(-7,160,-7,CONCRETE:8)
Block(-7,160,8,CONCRETE:8)
Block(-7,161,-7,CONCRETE:8)
Block(-7,161,8,CONCRETE:8)
Block(-7,162,-7,CONCRETE:8)
Block(-7,162,8,CONCRETE:8)
Block(-7,163,-7,CONCRETE:8)
Block(-7,163,8,CONCRETE:8)
Block(-7,164,-7,CONCRETE:8)
Block(-7,164,8,CONCRETE:8)
Block(-7,165,-7,CONCRETE:8)
Block(-7,165,8,CONCRETE:8)
Block(-7,166,-7,CONCRETE:8)
Block(-7,166,8,CONCRETE:8)
Block(-7,167,-7,CONCRETE:8)
Block(-7,167,8,CONCRETE:8)
Block(-7,168,-7,CONCRETE:8)
Block(-7,168,8,CONCRETE:8)
Block(-7,169,-7,CONCRETE:8)
Block(-7,169,8,CONCRETE:8)
Block(-7,170,-7,CONCRETE:8)
Block(-7,170,8,CONCRETE:8)
Block(-7,171,-7,CONCRETE:8)
Block(-7,171,8,CONCRETE:8)
Block(-7,172,-7,CONCRETE:8)
Block(-7,172,8,CONCRETE:8)
Block(-7,173,-7,CONCRETE:8)
Block(-7,173,8,CONCRETE:8)
Block(-7,174,-7,CONCRETE:8)
Block(-7,174,8,CONCRETE:8)
Block(-7,175,-7,CONCRETE:8)
Block(-7,175,8,CONCRETE:8)
Block(-7,176,-7,CONCRETE:8)
Block(-7,176,8,CONCRETE:8)
Block(-7,177,-7,CONCRETE:8)
Block(-7,177,8,CONCRETE:8)
Block(-7,178,-7,CONCRETE:8)
Block(-7,178,8,CONCRETE:8)
Block(-7,179,-7,CONCRETE:8)
Block(-7,179,8,CONCRETE:8)
Block(-7,180,-7,CONCRETE:8)
Block(-7,180,8,CONCRETE:8)
Block(-7,181,-7,CONCRETE:8)
Block(-7,181,8,CONCRETE:8)
Block(-7,182,-7,CONCRETE:8)
Block(-7,182,8,CONCRETE:8)
Block(-7,183,-7,CONCRETE:8)
Block(-7,183,8,CONCRETE:8)
Block(-7,184,-7,CONCRETE:8)
Block(-7,184,8,CONCRETE:8)
Block(-7,185,-7,CONCRETE:8)
Block(-7,185,8,CONCRETE:8)
Block(-7,186,-7,CONCRETE:8)
Block(-7,186,8,CONCRETE:8)
Block(-7,187,-7,CONCRETE:8)
Block(-7,187,8,CONCRETE:8)
Block(-7,188,-7,CONCRETE:8)
Block(-7,188,8,CONCRETE:8)
Block(-7,189,-7,CONCRETE:8)
Block(-7,189,8,CONCRETE:8)
Block(-7,190,-7,CONCRETE:8)
Block(-7,190,8,CONCRETE:8)
Block(-7,191,-7,CONCRETE:8)
Block(-7,191,8,CONCRETE:8)
Block(-7,192,-7,CONCRETE:8)
Block(-7,192,8,CONCRETE:8)
Block(-7,193,-7,CONCRETE:8)
Block(-7,193,8,CONCRETE:8)
Block(-7,194,-7,CONCRETE:8)
Block(-7,194,8,CONCRETE:8)
Block(-7,195,-7,CONCRETE:8)
Block(-7,195,8,CONCRETE:8)
Block(-7,196,-7,CONCRETE:8)
Block(-7,196,8,CONCRETE:8)
Block(-7,197,-7,CONCRETE:8)
Block(-7,197,8,CONCRETE:8)
Block(-7,198,-7,CONCRETE:8)
Block(-7,198,8,CONCRETE:8)
Block(-7,199,-7,CONCRETE:8)
Block(-7,199,8,CONCRETE:8)
Block(-7,200,-7,CONCRETE:8)
Block(-7,200,8,CONCRETE:8)
Block(-7,201,-7,CONCRETE:8)
Block(-7,201,8,CONCRETE:8)
Block(-7,202,-7,STEP:0)
Block(-7,202,8,STEP:0)
Block(-6,0,-7,CONCRETE:7)
Block(-6,0,-6,CONCRETE:7)
Block(-6,0,-5,CONCRETE:7)
Block(-6,0,-4,CONCRETE:7)
Block(-6,0,-3,CONCRETE:7)
Block(-6,0,-2,CONCRETE:7)
Block(-6,0,-1,CONCRETE:7)
Block(-6,0,0,CONCRETE:7)
Block(-6,0,1,CONCRETE:7)
Block(-6,0,2,CONCRETE:7)
Block(-6,0,3,CONCRETE:7)
Block(-6,0,4,CONCRETE:7)
Block(-6,0,5,CONCRETE:7)
Block(-6,0,6,CONCRETE:7)
Block(-6,0,7,CONCRETE:7)
Block(-6,0,8,CONCRETE:7)
Block(-6,1,-7,CONCRETE:7)
Block(-6,1,-6,CONCRETE:7)
Block(-6,1,-5,CONCRETE:7)
Block(-6,1,-4,CONCRETE:7)
Block(-6,1,-3,CONCRETE:7)
Block(-6,1,-2,CONCRETE:7)
Block(-6,1,-1,CONCRETE:7)
Block(-6,1,0,CONCRETE:7)
Block(-6,1,1,CONCRETE:7)
Block(-6,1,2,CONCRETE:7)
Block(-6,1,3,CONCRETE:7)
Block(-6,1,4,CONCRETE:7)
Block(-6,1,5,CONCRETE:7)
Block(-6,1,6,CONCRETE:7)
Block(-6,1,7,CONCRETE:7)
Block(-6,1,8,CONCRETE:7)
Block(-6,2,-7,CONCRETE:7)
Block(-6,2,-6,CONCRETE:7)
Block(-6,2,-5,CONCRETE:7)
Block(-6,2,-4,CONCRETE:7)
Block(-6,2,-3,CONCRETE:7)
Block(-6,2,-2,CONCRETE:7)
Block(-6,2,-1,CONCRETE:7)
Block(-6,2,0,CONCRETE:7)
Block(-6,2,1,CONCRETE:7)
Block(-6,2,2,CONCRETE:7)
Block(-6,2,3,CONCRETE:7)
Block(-6,2,4,CONCRETE:7)
Block(-6,2,5,CONCRETE:7)
Block(-6,2,6,CONCRETE:7)
Block(-6,2,7,CONCRETE:7)
Block(-6,2,8,CONCRETE:7)
Block(-6,3,-7,CONCRETE:7)
Block(-6,3,-6,CONCRETE:7)
Block(-6,3,-5,CONCRETE:7)
Block(-6,3,-4,CONCRETE:7)
Block(-6,3,-3,CONCRETE:7)
Block(-6,3,-2,CONCRETE:7)
Block(-6,3,-1,CONCRETE:7)
Block(-6,3,0,CONCRETE:7)
Block(-6,3,1,CONCRETE:7)
Block(-6,3,2,CONCRETE:7)
Block(-6,3,3,CONCRETE:7)
Block(-6,3,4,CONCRETE:7)
Block(-6,3,5,CONCRETE:7)
Block(-6,3,6,CONCRETE:7)
Block(-6,3,7,CONCRETE:7)
Block(-6,3,8,CONCRETE:7)
Block(-6,4,-7,CONCRETE:7)
Block(-6,4,-6,CONCRETE:7)
Block(-6,4,-5,CONCRETE:7)
Block(-6,4,-4,CONCRETE:7)
Block(-6,4,-3,CONCRETE:7)
Block(-6,4,-2,CONCRETE:7)
Block(-6,4,-1,CONCRETE:7)
Block(-6,4,0,CONCRETE:7)
Block(-6,4,1,CONCRETE:7)
Block(-6,4,2,CONCRETE:7)
Block(-6,4,3,CONCRETE:7)
Block(-6,4,4,CONCRETE:7)
Block(-6,4,5,CONCRETE:7)
Block(-6,4,6,CONCRETE:7)
Block(-6,4,7,CONCRETE:7)
Block(-6,4,8,CONCRETE:7)
Block(-6,5,-7,CONCRETE:7)
Block(-6,5,-6,CONCRETE:7)
Block(-6,5,-5,CONCRETE:7)
Block(-6,5,-4,CONCRETE:7)
Block(-6,5,-3,CONCRETE:7)
Block(-6,5,-2,CONCRETE:7)
Block(-6,5,-1,CONCRETE:7)
Block(-6,5,0,CONCRETE:7)
Block(-6,5,1,CONCRETE:7)
Block(-6,5,2,CONCRETE:7)
Block(-6,5,3,CONCRETE:7)
Block(-6,5,4,CONCRETE:7)
Block(-6,5,5,CONCRETE:7)
Block(-6,5,6,CONCRETE:7)
Block(-6,5,7,CONCRETE:7)
Block(-6,5,8,CONCRETE:7)
Block(-6,6,-7,CONCRETE:7)
Block(-6,6,-6,CONCRETE:7)
Block(-6,6,-5,CONCRETE:7)
Block(-6,6,-4,CONCRETE:7)
Block(-6,6,-3,CONCRETE:7)
Block(-6,6,-2,CONCRETE:7)
Block(-6,6,-1,CONCRETE:7)
Block(-6,6,0,CONCRETE:7)
Block(-6,6,1,CONCRETE:7)
Block(-6,6,2,CONCRETE:7)
Block(-6,6,3,CONCRETE:7)
Block(-6,6,4,CONCRETE:7)
Block(-6,6,5,CONCRETE:7)
Block(-6,6,6,CONCRETE:7)
Block(-6,6,7,CONCRETE:7)
Block(-6,6,8,CONCRETE:7)
Block(-6,7,-7,CONCRETE:7)
Block(-6,7,-6,CONCRETE:7)
Block(-6,7,-5,CONCRETE:7)
Block(-6,7,-4,CONCRETE:7)
Block(-6,7,-3,CONCRETE:7)
Block(-6,7,-2,CONCRETE:7)
Block(-6,7,-1,CONCRETE:7)
Block(-6,7,0,CONCRETE:7)
Block(-6,7,1,CONCRETE:7)
Block(-6,7,2,CONCRETE:7)
Block(-6,7,3,CONCRETE:7)
Block(-6,7,4,CONCRETE:7)
Block(-6,7,5,CONCRETE:7)
Block(-6,7,6,CONCRETE:7)
Block(-6,7,7,CONCRETE:7)
Block(-6,7,8,CONCRETE:7)
Block(-6,8,-7,CONCRETE:7)
Block(-6,8,-6,CONCRETE:7)
Block(-6,8,-5,CONCRETE:7)
Block(-6,8,-4,CONCRETE:7)
Block(-6,8,-3,CONCRETE:7)
Block(-6,8,-2,CONCRETE:7)
Block(-6,8,-1,CONCRETE:7)
Block(-6,8,0,CONCRETE:7)
Block(-6,8,1,CONCRETE:7)
Block(-6,8,2,CONCRETE:7)
Block(-6,8,3,CONCRETE:7)
Block(-6,8,4,CONCRETE:7)
Block(-6,8,5,CONCRETE:7)
Block(-6,8,6,CONCRETE:7)
Block(-6,8,7,CONCRETE:7)
Block(-6,8,8,CONCRETE:7)
Block(-6,9,-7,CONCRETE:8)
Block(-6,9,-6,CONCRETE:8)
Block(-6,9,-5,CONCRETE:8)
Block(-6,9,-4,CONCRETE:8)
Block(-6,9,-3,CONCRETE:8)
Block(-6,9,-2,CONCRETE:8)
Block(-6,9,-1,CONCRETE:8)
Block(-6,9,0,CONCRETE:8)
Block(-6,9,1,CONCRETE:8)
Block(-6,9,2,CONCRETE:8)
Block(-6,9,3,CONCRETE:8)
Block(-6,9,4,CONCRETE:8)
Block(-6,9,5,CONCRETE:8)
Block(-6,9,6,CONCRETE:8)
Block(-6,9,7,CONCRETE:8)
Block(-6,9,8,CONCRETE:8)
Block(-6,10,-7,STAINED_GLASS:15)
Block(-6,10,-6,STAINED_GLASS:15)
Block(-6,10,-5,STAINED_GLASS:15)
Block(-6,10,-4,STAINED_GLASS:15)
Block(-6,10,-3,STAINED_GLASS:15)
Block(-6,10,-2,STAINED_GLASS:15)
Block(-6,10,-1,STAINED_GLASS:15)
Block(-6,10,0,STAINED_GLASS:15)
Block(-6,10,1,STAINED_GLASS:15)
Block(-6,10,2,STAINED_GLASS:15)
Block(-6,10,3,STAINED_GLASS:15)
Block(-6,10,4,STAINED_GLASS:15)
Block(-6,10,5,STAINED_GLASS:15)
Block(-6,10,6,STAINED_GLASS:15)
Block(-6,10,7,STAINED_GLASS:15)
Block(-6,10,8,STAINED_GLASS:15)
Block(-6,11,-7,STATIONARY_WATER:0)
Block(-6,11,-6,STATIONARY_WATER:0)
Block(-6,11,-5,STATIONARY_WATER:0)
Block(-6,11,-4,STATIONARY_WATER:0)
Block(-6,11,-3,STATIONARY_WATER:0)
Block(-6,11,-2,STATIONARY_WATER:0)
Block(-6,11,-1,STATIONARY_WATER:0)
Block(-6,11,0,STATIONARY_WATER:0)
Block(-6,11,1,STATIONARY_WATER:0)
Block(-6,11,2,STATIONARY_WATER:0)
Block(-6,11,3,STATIONARY_WATER:0)
Block(-6,11,4,STATIONARY_WATER:0)
Block(-6,11,5,STATIONARY_WATER:0)
Block(-6,11,6,STATIONARY_WATER:0)
Block(-6,11,7,STATIONARY_WATER:0)
Block(-6,11,8,STATIONARY_WATER:0)
Block(-6,12,-7,STATIONARY_WATER:0)
Block(-6,12,-6,STATIONARY_WATER:0)
Block(-6,12,-5,STATIONARY_WATER:0)
Block(-6,12,-4,STATIONARY_WATER:0)
Block(-6,12,-3,STATIONARY_WATER:0)
Block(-6,12,-2,STATIONARY_WATER:0)
Block(-6,12,-1,STATIONARY_WATER:0)
Block(-6,12,0,STATIONARY_WATER:0)
Block(-6,12,1,STATIONARY_WATER:0)
Block(-6,12,2,STATIONARY_WATER:0)
Block(-6,12,3,STATIONARY_WATER:0)
Block(-6,12,4,STATIONARY_WATER:0)
Block(-6,12,5,STATIONARY_WATER:0)
Block(-6,12,6,STATIONARY_WATER:0)
Block(-6,12,7,STATIONARY_WATER:0)
Block(-6,12,8,STATIONARY_WATER:0)
Block(-6,13,-7,AIR:0)
Block(-6,13,-6,AIR:0)
Block(-6,13,-5,AIR:0)
Block(-6,13,-4,AIR:0)
Block(-6,13,-3,AIR:0)
Block(-6,13,-2,AIR:0)
Block(-6,13,-1,AIR:0)
Block(-6,13,0,AIR:0)
Block(-6,13,1,AIR:0)
Block(-6,13,2,AIR:0)
Block(-6,13,3,AIR:0)
Block(-6,13,4,AIR:0)
Block(-6,13,5,AIR:0)
Block(-6,13,6,AIR:0)
Block(-6,13,7,AIR:0)
Block(-6,13,8,AIR:0)
Block(-6,14,-7,AIR:0)
Block(-6,14,-6,AIR:0)
Block(-6,14,-5,AIR:0)
Block(-6,14,-4,AIR:0)
Block(-6,14,-3,AIR:0)
Block(-6,14,-2,AIR:0)
Block(-6,14,-1,AIR:0)
Block(-6,14,0,AIR:0)
Block(-6,14,1,AIR:0)
Block(-6,14,2,AIR:0)
Block(-6,14,3,AIR:0)
Block(-6,14,4,AIR:0)
Block(-6,14,5,AIR:0)
Block(-6,14,6,AIR:0)
Block(-6,14,7,AIR:0)
Block(-6,14,8,AIR:0)
Block(-6,15,-7,AIR:0)
Block(-6,15,-6,AIR:0)
Block(-6,15,-5,AIR:0)
Block(-6,15,-4,AIR:0)
Block(-6,15,-3,AIR:0)
Block(-6,15,-2,AIR:0)
Block(-6,15,-1,AIR:0)
Block(-6,15,0,AIR:0)
Block(-6,15,1,AIR:0)
Block(-6,15,2,AIR:0)
Block(-6,15,3,AIR:0)
Block(-6,15,4,AIR:0)
Block(-6,15,5,AIR:0)
Block(-6,15,6,AIR:0)
Block(-6,15,7,AIR:0)
Block(-6,15,8,AIR:0)
Block(-6,16,-7,AIR:0)
Block(-6,16,-6,AIR:0)
Block(-6,16,-5,AIR:0)
Block(-6,16,-4,AIR:0)
Block(-6,16,-3,AIR:0)
Block(-6,16,-2,AIR:0)
Block(-6,16,-1,AIR:0)
Block(-6,16,0,AIR:0)
Block(-6,16,1,AIR:0)
Block(-6,16,2,AIR:0)
Block(-6,16,3,AIR:0)
Block(-6,16,4,AIR:0)
Block(-6,16,5,AIR:0)
Block(-6,16,6,AIR:0)
Block(-6,16,7,AIR:0)
Block(-6,16,8,AIR:0)
Block(-6,17,-7,AIR:0)
Block(-6,17,-6,AIR:0)
Block(-6,17,-5,AIR:0)
Block(-6,17,-4,AIR:0)
Block(-6,17,-3,AIR:0)
Block(-6,17,-2,AIR:0)
Block(-6,17,-1,STAINED_GLASS:15)
Block(-6,17,0,CONCRETE:8)
Block(-6,17,1,CONCRETE:8)
Block(-6,17,2,STAINED_GLASS:15)
Block(-6,17,3,AIR:0)
Block(-6,17,4,AIR:0)
Block(-6,17,5,AIR:0)
Block(-6,17,6,AIR:0)
Block(-6,17,7,AIR:0)
Block(-6,17,8,AIR:0)
Block(-6,18,-1,STAINED_GLASS_PANE:15)
Block(-6,18,2,STAINED_GLASS_PANE:15)
Block(-5,0,-7,CONCRETE:7)
Block(-5,0,-6,CONCRETE:7)
Block(-5,0,-5,CONCRETE:7)
Block(-5,0,-4,CONCRETE:7)
Block(-5,0,-3,CONCRETE:7)
Block(-5,0,-2,CONCRETE:7)
Block(-5,0,-1,CONCRETE:7)
Block(-5,0,0,CONCRETE:7)
Block(-5,0,1,CONCRETE:7)
Block(-5,0,2,CONCRETE:7)
Block(-5,0,3,CONCRETE:7)
Block(-5,0,4,CONCRETE:7)
Block(-5,0,5,CONCRETE:7)
Block(-5,0,6,CONCRETE:7)
Block(-5,0,7,CONCRETE:7)
Block(-5,0,8,CONCRETE:7)
Block(-5,1,-7,CONCRETE:7)
Block(-5,1,-6,CONCRETE:7)
Block(-5,1,-5,CONCRETE:7)
Block(-5,1,-4,CONCRETE:7)
Block(-5,1,-3,CONCRETE:7)
Block(-5,1,-2,CONCRETE:7)
Block(-5,1,-1,CONCRETE:7)
Block(-5,1,0,CONCRETE:7)
Block(-5,1,1,CONCRETE:7)
Block(-5,1,2,CONCRETE:7)
Block(-5,1,3,CONCRETE:7)
Block(-5,1,4,CONCRETE:7)
Block(-5,1,5,CONCRETE:7)
Block(-5,1,6,CONCRETE:7)
Block(-5,1,7,CONCRETE:7)
Block(-5,1,8,CONCRETE:7)
Block(-5,2,-7,CONCRETE:7)
Block(-5,2,-6,CONCRETE:7)
Block(-5,2,-5,CONCRETE:7)
Block(-5,2,-4,CONCRETE:7)
Block(-5,2,-3,CONCRETE:7)
Block(-5,2,-2,CONCRETE:7)
Block(-5,2,-1,CONCRETE:7)
Block(-5,2,0,CONCRETE:7)
Block(-5,2,1,CONCRETE:7)
Block(-5,2,2,CONCRETE:7)
Block(-5,2,3,CONCRETE:7)
Block(-5,2,4,CONCRETE:7)
Block(-5,2,5,CONCRETE:7)
Block(-5,2,6,CONCRETE:7)
Block(-5,2,7,CONCRETE:7)
Block(-5,2,8,CONCRETE:7)
Block(-5,3,-7,CONCRETE:7)
Block(-5,3,-6,CONCRETE:7)
Block(-5,3,-5,CONCRETE:7)
Block(-5,3,-4,CONCRETE:7)
Block(-5,3,-3,CONCRETE:7)
Block(-5,3,-2,CONCRETE:7)
Block(-5,3,-1,CONCRETE:7)
Block(-5,3,0,CONCRETE:7)
Block(-5,3,1,CONCRETE:7)
Block(-5,3,2,CONCRETE:7)
Block(-5,3,3,CONCRETE:7)
Block(-5,3,4,CONCRETE:7)
Block(-5,3,5,CONCRETE:7)
Block(-5,3,6,CONCRETE:7)
Block(-5,3,7,SMOOTH_STAIRS:1)
Block(-5,3,8,SMOOTH_STAIRS:1)
Block(-5,4,-7,CONCRETE:7)
Block(-5,4,-6,CONCRETE:7)
Block(-5,4,-5,CONCRETE:7)
Block(-5,4,-4,CONCRETE:7)
Block(-5,4,-3,CONCRETE:7)
Block(-5,4,-2,CONCRETE:7)
Block(-5,4,-1,CONCRETE:7)
Block(-5,4,0,CONCRETE:7)
Block(-5,4,1,CONCRETE:7)
Block(-5,4,2,CONCRETE:7)
Block(-5,4,3,CONCRETE:7)
Block(-5,4,4,CONCRETE:7)
Block(-5,4,5,CONCRETE:7)
Block(-5,4,6,CONCRETE:7)
Block(-5,4,7,COBBLE_WALL:0)
Block(-5,4,8,COBBLE_WALL:0)
Block(-5,5,-7,CONCRETE:7)
Block(-5,5,-6,CONCRETE:7)
Block(-5,5,-5,CONCRETE:7)
Block(-5,5,-4,CONCRETE:7)
Block(-5,5,-3,CONCRETE:7)
Block(-5,5,-2,CONCRETE:7)
Block(-5,5,-1,CONCRETE:7)
Block(-5,5,0,CONCRETE:7)
Block(-5,5,1,CONCRETE:7)
Block(-5,5,2,CONCRETE:7)
Block(-5,5,3,CONCRETE:7)
Block(-5,5,4,CONCRETE:7)
Block(-5,5,5,CONCRETE:7)
Block(-5,5,6,CONCRETE:7)
Block(-5,5,7,SMOOTH_STAIRS:5)
Block(-5,5,8,SMOOTH_STAIRS:5)
Block(-5,6,-7,CONCRETE:7)
Block(-5,6,-6,CONCRETE:7)
Block(-5,6,-5,CONCRETE:7)
Block(-5,6,-4,CONCRETE:7)
Block(-5,6,-3,CONCRETE:7)
Block(-5,6,-2,CONCRETE:7)
Block(-5,6,-1,CONCRETE:7)
Block(-5,6,0,CONCRETE:7)
Block(-5,6,1,CONCRETE:7)
Block(-5,6,2,CONCRETE:7)
Block(-5,6,3,CONCRETE:7)
Block(-5,6,4,CONCRETE:7)
Block(-5,6,5,CONCRETE:7)
Block(-5,6,6,CONCRETE:7)
Block(-5,6,7,CONCRETE:7)
Block(-5,6,8,CONCRETE:7)
Block(-5,7,-7,CONCRETE:7)
Block(-5,7,-6,CONCRETE:7)
Block(-5,7,-5,CONCRETE:7)
Block(-5,7,-4,CONCRETE:7)
Block(-5,7,-3,CONCRETE:7)
Block(-5,7,-2,CONCRETE:7)
Block(-5,7,-1,CONCRETE:7)
Block(-5,7,0,CONCRETE:7)
Block(-5,7,1,CONCRETE:7)
Block(-5,7,2,CONCRETE:7)
Block(-5,7,3,CONCRETE:7)
Block(-5,7,4,CONCRETE:7)
Block(-5,7,5,CONCRETE:7)
Block(-5,7,6,CONCRETE:7)
Block(-5,7,7,CONCRETE:7)
Block(-5,7,8,CONCRETE:7)
Block(-5,8,-7,CONCRETE:7)
Block(-5,8,-6,CONCRETE:7)
Block(-5,8,-5,CONCRETE:7)
Block(-5,8,-4,CONCRETE:7)
Block(-5,8,-3,CONCRETE:7)
Block(-5,8,-2,CONCRETE:7)
Block(-5,8,-1,CONCRETE:7)
Block(-5,8,0,CONCRETE:7)
Block(-5,8,1,CONCRETE:7)
Block(-5,8,2,CONCRETE:7)
Block(-5,8,3,CONCRETE:7)
Block(-5,8,4,CONCRETE:7)
Block(-5,8,5,CONCRETE:7)
Block(-5,8,6,CONCRETE:7)
Block(-5,8,7,CONCRETE:7)
Block(-5,8,8,CONCRETE:7)
Block(-5,9,-7,CONCRETE:15)
Block(-5,9,-6,CONCRETE:15)
Block(-5,9,-5,CONCRETE:15)
Block(-5,9,-4,CONCRETE:15)
Block(-5,9,-3,CONCRETE:15)
Block(-5,9,-2,CONCRETE:15)
Block(-5,9,-1,CONCRETE:15)
Block(-5,9,0,CONCRETE:15)
Block(-5,9,1,CONCRETE:15)
Block(-5,9,2,CONCRETE:15)
Block(-5,9,3,CONCRETE:15)
Block(-5,9,4,CONCRETE:15)
Block(-5,9,5,CONCRETE:15)
Block(-5,9,6,CONCRETE:15)
Block(-5,9,7,CONCRETE:15)
Block(-5,9,8,CONCRETE:15)
Block(-5,10,-7,CONCRETE:15)
Block(-5,10,-6,CONCRETE:15)
Block(-5,10,-5,CONCRETE:15)
Block(-5,10,-4,CONCRETE:15)
Block(-5,10,-3,CONCRETE:15)
Block(-5,10,-2,CONCRETE:15)
Block(-5,10,-1,CONCRETE:15)
Block(-5,10,0,CONCRETE:15)
Block(-5,10,1,CONCRETE:15)
Block(-5,10,2,CONCRETE:15)
Block(-5,10,3,CONCRETE:15)
Block(-5,10,4,CONCRETE:15)
Block(-5,10,5,CONCRETE:15)
Block(-5,10,6,CONCRETE:15)
Block(-5,10,7,CONCRETE:15)
Block(-5,10,8,CONCRETE:15)
Block(-5,11,-7,STATIONARY_WATER:0)
Block(-5,11,-6,STATIONARY_WATER:0)
Block(-5,11,-5,STATIONARY_WATER:0)
Block(-5,11,-4,STATIONARY_WATER:0)
Block(-5,11,-3,STATIONARY_WATER:0)
Block(-5,11,-2,STATIONARY_WATER:0)
Block(-5,11,-1,STATIONARY_WATER:0)
Block(-5,11,0,STATIONARY_WATER:0)
Block(-5,11,1,STATIONARY_WATER:0)
Block(-5,11,2,STATIONARY_WATER:0)
Block(-5,11,3,STATIONARY_WATER:0)
Block(-5,11,4,STATIONARY_WATER:0)
Block(-5,11,5,STATIONARY_WATER:0)
Block(-5,11,6,STATIONARY_WATER:0)
Block(-5,11,7,STATIONARY_WATER:0)
Block(-5,11,8,STATIONARY_WATER:0)
Block(-5,12,-7,STATIONARY_WATER:0)
Block(-5,12,-6,STATIONARY_WATER:0)
Block(-5,12,-5,STATIONARY_WATER:0)
Block(-5,12,-4,STATIONARY_WATER:0)
Block(-5,12,-3,STATIONARY_WATER:0)
Block(-5,12,-2,STATIONARY_WATER:0)
Block(-5,12,-1,STATIONARY_WATER:0)
Block(-5,12,0,STATIONARY_WATER:0)
Block(-5,12,1,STATIONARY_WATER:0)
Block(-5,12,2,STATIONARY_WATER:0)
Block(-5,12,3,STATIONARY_WATER:0)
Block(-5,12,4,STATIONARY_WATER:0)
Block(-5,12,5,STATIONARY_WATER:0)
Block(-5,12,6,STATIONARY_WATER:0)
Block(-5,12,7,STATIONARY_WATER:0)
Block(-5,12,8,STATIONARY_WATER:0)
Block(-5,13,-7,STATIONARY_WATER:10)
Block(-5,13,-6,AIR:0)
Block(-5,13,-5,AIR:0)
Block(-5,13,-4,AIR:0)
Block(-5,13,-3,AIR:0)
Block(-5,13,-2,AIR:0)
Block(-5,13,-1,AIR:0)
Block(-5,13,0,AIR:0)
Block(-5,13,1,AIR:0)
Block(-5,13,2,AIR:0)
Block(-5,13,3,AIR:0)
Block(-5,13,4,AIR:0)
Block(-5,13,5,AIR:0)
Block(-5,13,6,AIR:0)
Block(-5,13,7,AIR:0)
Block(-5,13,8,STATIONARY_WATER:10)
Block(-5,14,-7,STATIONARY_WATER:10)
Block(-5,14,-6,AIR:0)
Block(-5,14,-5,AIR:0)
Block(-5,14,-4,AIR:0)
Block(-5,14,-3,AIR:0)
Block(-5,14,-2,AIR:0)
Block(-5,14,-1,AIR:0)
Block(-5,14,0,AIR:0)
Block(-5,14,1,AIR:0)
Block(-5,14,2,AIR:0)
Block(-5,14,3,AIR:0)
Block(-5,14,4,AIR:0)
Block(-5,14,5,AIR:0)
Block(-5,14,6,AIR:0)
Block(-5,14,7,AIR:0)
Block(-5,14,8,STATIONARY_WATER:10)
Block(-5,15,-7,STATIONARY_WATER:10)
Block(-5,15,-6,AIR:0)
Block(-5,15,-5,AIR:0)
Block(-5,15,-4,AIR:0)
Block(-5,15,-3,AIR:0)
Block(-5,15,-2,AIR:0)
Block(-5,15,-1,AIR:0)
Block(-5,15,0,AIR:0)
Block(-5,15,1,AIR:0)
Block(-5,15,2,AIR:0)
Block(-5,15,3,AIR:0)
Block(-5,15,4,AIR:0)
Block(-5,15,5,AIR:0)
Block(-5,15,6,AIR:0)
Block(-5,15,7,AIR:0)
Block(-5,15,8,STATIONARY_WATER:10)
Block(-5,16,-7,STATIONARY_WATER:2)
Block(-5,16,-6,AIR:0)
Block(-5,16,-5,AIR:0)
Block(-5,16,-4,AIR:0)
Block(-5,16,-3,AIR:0)
Block(-5,16,-2,AIR:0)
Block(-5,16,-1,AIR:0)
Block(-5,16,0,AIR:0)
Block(-5,16,1,AIR:0)
Block(-5,16,2,AIR:0)
Block(-5,16,3,AIR:0)
Block(-5,16,4,AIR:0)
Block(-5,16,5,AIR:0)
Block(-5,16,6,AIR:0)
Block(-5,16,7,AIR:0)
Block(-5,16,8,STATIONARY_WATER:2)
Block(-5,17,-7,AIR:0)
Block(-5,17,-6,AIR:0)
Block(-5,17,-5,AIR:0)
Block(-5,17,-4,AIR:0)
Block(-5,17,-3,AIR:0)
Block(-5,17,-2,AIR:0)
Block(-5,17,-1,STAINED_GLASS:15)
Block(-5,17,0,CONCRETE:8)
Block(-5,17,1,CONCRETE:8)
Block(-5,17,2,STAINED_GLASS:15)
Block(-5,17,3,AIR:0)
Block(-5,17,4,AIR:0)
Block(-5,17,5,AIR:0)
Block(-5,17,6,AIR:0)
Block(-5,17,7,AIR:0)
Block(-5,17,8,AIR:0)
Block(-5,18,-1,STAINED_GLASS_PANE:15)
Block(-5,18,2,STAINED_GLASS_PANE:15)
Block(-4,0,-7,CONCRETE:7)
Block(-4,0,-6,CONCRETE:7)
Block(-4,0,-5,CONCRETE:7)
Block(-4,0,-4,CONCRETE:7)
Block(-4,0,-3,CONCRETE:7)
Block(-4,0,-2,CONCRETE:7)
Block(-4,0,-1,CONCRETE:7)
Block(-4,0,0,CONCRETE:7)
Block(-4,0,1,CONCRETE:7)
Block(-4,0,2,CONCRETE:7)
Block(-4,0,3,CONCRETE:7)
Block(-4,0,4,CONCRETE:7)
Block(-4,0,5,CONCRETE:7)
Block(-4,0,6,CONCRETE:7)
Block(-4,0,7,CONCRETE:7)
Block(-4,0,8,CONCRETE:7)
Block(-4,1,-7,CONCRETE:7)
Block(-4,1,-6,CONCRETE:7)
Block(-4,1,-5,CONCRETE:7)
Block(-4,1,-4,CONCRETE:7)
Block(-4,1,-3,CONCRETE:7)
Block(-4,1,-2,CONCRETE:7)
Block(-4,1,-1,CONCRETE:7)
Block(-4,1,0,CONCRETE:7)
Block(-4,1,1,CONCRETE:7)
Block(-4,1,2,CONCRETE:7)
Block(-4,1,3,CONCRETE:7)
Block(-4,1,4,CONCRETE:7)
Block(-4,1,5,AIR:0)
Block(-4,1,6,AIR:0)
Block(-4,1,7,AIR:0)
Block(-4,1,8,AIR:0)
Block(-4,2,-7,CONCRETE:7)
Block(-4,2,-6,CONCRETE:7)
Block(-4,2,-5,CONCRETE:7)
Block(-4,2,-4,CONCRETE:7)
Block(-4,2,-3,CONCRETE:7)
Block(-4,2,-2,CONCRETE:7)
Block(-4,2,-1,CONCRETE:7)
Block(-4,2,0,CONCRETE:7)
Block(-4,2,1,CONCRETE:7)
Block(-4,2,2,CONCRETE:7)
Block(-4,2,3,CONCRETE:7)
Block(-4,2,4,CONCRETE:7)
Block(-4,2,5,IRON_TRAPDOOR:8)
Block(-4,2,6,IRON_TRAPDOOR:8)
Block(-4,2,7,IRON_TRAPDOOR:8)
Block(-4,2,8,IRON_TRAPDOOR:8)
Block(-4,3,-7,CONCRETE:7)
Block(-4,3,-6,CONCRETE:7)
Block(-4,3,-5,CONCRETE:7)
Block(-4,3,-4,CONCRETE:7)
Block(-4,3,-3,CONCRETE:7)
Block(-4,3,-2,CONCRETE:7)
Block(-4,3,-1,CONCRETE:7)
Block(-4,3,0,CONCRETE:7)
Block(-4,3,1,CONCRETE:7)
Block(-4,3,2,CONCRETE:7)
Block(-4,3,3,CONCRETE:7)
Block(-4,3,4,CONCRETE:7)
Block(-4,3,5,AIR:0)
Block(-4,3,6,AIR:0)
Block(-4,3,7,CONCRETE:4)
Block(-4,3,8,CONCRETE:4)
Block(-4,4,-7,CONCRETE:7)
Block(-4,4,-6,CONCRETE:7)
Block(-4,4,-5,CONCRETE:7)
Block(-4,4,-4,CONCRETE:7)
Block(-4,4,-3,CONCRETE:7)
Block(-4,4,-2,CONCRETE:7)
Block(-4,4,-1,CONCRETE:7)
Block(-4,4,0,CONCRETE:7)
Block(-4,4,1,CONCRETE:7)
Block(-4,4,2,CONCRETE:7)
Block(-4,4,3,CONCRETE:7)
Block(-4,4,4,CONCRETE:7)
Block(-4,4,5,AIR:0)
Block(-4,4,6,AIR:0)
Block(-4,4,7,CONCRETE:4)
Block(-4,4,8,AIR:0)
Block(-4,5,-7,CONCRETE:7)
Block(-4,5,-6,CONCRETE:7)
Block(-4,5,-5,CONCRETE:7)
Block(-4,5,-4,CONCRETE:7)
Block(-4,5,-3,CONCRETE:7)
Block(-4,5,-2,CONCRETE:7)
Block(-4,5,-1,CONCRETE:7)
Block(-4,5,0,CONCRETE:7)
Block(-4,5,1,CONCRETE:7)
Block(-4,5,2,CONCRETE:7)
Block(-4,5,3,CONCRETE:7)
Block(-4,5,4,CONCRETE:7)
Block(-4,5,5,AIR:0)
Block(-4,5,6,SMOOTH_STAIRS:5)
Block(-4,5,7,CONCRETE:4)
Block(-4,5,8,AIR:0)
Block(-4,6,-7,CONCRETE:7)
Block(-4,6,-6,CONCRETE:7)
Block(-4,6,-5,CONCRETE:7)
Block(-4,6,-4,CONCRETE:7)
Block(-4,6,-3,CONCRETE:7)
Block(-4,6,-2,CONCRETE:7)
Block(-4,6,-1,CONCRETE:7)
Block(-4,6,0,CONCRETE:7)
Block(-4,6,1,CONCRETE:7)
Block(-4,6,2,CONCRETE:7)
Block(-4,6,3,CONCRETE:7)
Block(-4,6,4,CONCRETE:7)
Block(-4,6,5,CONCRETE:7)
Block(-4,6,6,CONCRETE:7)
Block(-4,6,7,CONCRETE:7)
Block(-4,6,8,CONCRETE:7)
Block(-4,7,-7,CONCRETE:7)
Block(-4,7,-6,CONCRETE:7)
Block(-4,7,-5,CONCRETE:7)
Block(-4,7,-4,CONCRETE:7)
Block(-4,7,-3,CONCRETE:7)
Block(-4,7,-2,CONCRETE:7)
Block(-4,7,-1,CONCRETE:7)
Block(-4,7,0,CONCRETE:7)
Block(-4,7,1,CONCRETE:7)
Block(-4,7,2,CONCRETE:7)
Block(-4,7,3,CONCRETE:7)
Block(-4,7,4,CONCRETE:7)
Block(-4,7,5,CONCRETE:7)
Block(-4,7,6,CONCRETE:7)
Block(-4,7,7,CONCRETE:7)
Block(-4,7,8,CONCRETE:7)
Block(-4,8,-7,CONCRETE:7)
Block(-4,8,-6,CONCRETE:7)
Block(-4,8,-5,CONCRETE:7)
Block(-4,8,-4,CONCRETE:7)
Block(-4,8,-3,CONCRETE:7)
Block(-4,8,-2,CONCRETE:7)
Block(-4,8,-1,CONCRETE:7)
Block(-4,8,0,CONCRETE:7)
Block(-4,8,1,CONCRETE:7)
Block(-4,8,2,CONCRETE:7)
Block(-4,8,3,CONCRETE:7)
Block(-4,8,4,CONCRETE:7)
Block(-4,8,5,CONCRETE:7)
Block(-4,8,6,CONCRETE:7)
Block(-4,8,7,CONCRETE:7)
Block(-4,8,8,CONCRETE:7)
Block(-4,9,-7,CONCRETE:15)
Block(-4,9,-6,CONCRETE:15)
Block(-4,9,-5,CONCRETE:15)
Block(-4,9,-4,CONCRETE:15)
Block(-4,9,-3,CONCRETE:15)
Block(-4,9,-2,CONCRETE:15)
Block(-4,9,-1,CONCRETE:15)
Block(-4,9,0,CONCRETE:15)
Block(-4,9,1,CONCRETE:15)
Block(-4,9,2,CONCRETE:15)
Block(-4,9,3,CONCRETE:15)
Block(-4,9,4,CONCRETE:15)
Block(-4,9,5,CONCRETE:15)
Block(-4,9,6,CONCRETE:15)
Block(-4,9,7,CONCRETE:15)
Block(-4,9,8,CONCRETE:15)
Block(-4,10,-7,CONCRETE:15)
Block(-4,10,-6,CONCRETE:15)
Block(-4,10,-5,CONCRETE:15)
Block(-4,10,-4,CONCRETE:15)
Block(-4,10,-3,CONCRETE:15)
Block(-4,10,-2,CONCRETE:15)
Block(-4,10,-1,CONCRETE:15)
Block(-4,10,0,CONCRETE:15)
Block(-4,10,1,CONCRETE:15)
Block(-4,10,2,CONCRETE:15)
Block(-4,10,3,CONCRETE:15)
Block(-4,10,4,CONCRETE:15)
Block(-4,10,5,CONCRETE:15)
Block(-4,10,6,CONCRETE:15)
Block(-4,10,7,CONCRETE:15)
Block(-4,10,8,CONCRETE:15)
Block(-4,11,-7,STATIONARY_WATER:0)
Block(-4,11,-6,STATIONARY_WATER:0)
Block(-4,11,-5,STATIONARY_WATER:0)
Block(-4,11,-4,STATIONARY_WATER:0)
Block(-4,11,-3,STATIONARY_WATER:0)
Block(-4,11,-2,STATIONARY_WATER:0)
Block(-4,11,-1,STATIONARY_WATER:0)
Block(-4,11,0,STATIONARY_WATER:0)
Block(-4,11,1,STATIONARY_WATER:0)
Block(-4,11,2,STATIONARY_WATER:0)
Block(-4,11,3,STATIONARY_WATER:0)
Block(-4,11,4,STATIONARY_WATER:0)
Block(-4,11,5,STATIONARY_WATER:0)
Block(-4,11,6,STATIONARY_WATER:0)
Block(-4,11,7,STATIONARY_WATER:0)
Block(-4,11,8,STATIONARY_WATER:0)
Block(-4,12,-7,STATIONARY_WATER:0)
Block(-4,12,-6,STATIONARY_WATER:0)
Block(-4,12,-5,STATIONARY_WATER:0)
Block(-4,12,-4,STATIONARY_WATER:0)
Block(-4,12,-3,STATIONARY_WATER:0)
Block(-4,12,-2,STATIONARY_WATER:0)
Block(-4,12,-1,STATIONARY_WATER:0)
Block(-4,12,0,STATIONARY_WATER:0)
Block(-4,12,1,STATIONARY_WATER:0)
Block(-4,12,2,STATIONARY_WATER:0)
Block(-4,12,3,STATIONARY_WATER:0)
Block(-4,12,4,STATIONARY_WATER:0)
Block(-4,12,5,STATIONARY_WATER:0)
Block(-4,12,6,STATIONARY_WATER:0)
Block(-4,12,7,STATIONARY_WATER:0)
Block(-4,12,8,STATIONARY_WATER:0)
Block(-4,13,-7,STATIONARY_WATER:10)
Block(-4,13,-6,AIR:0)
Block(-4,13,-5,AIR:0)
Block(-4,13,-4,AIR:0)
Block(-4,13,-3,AIR:0)
Block(-4,13,-2,AIR:0)
Block(-4,13,-1,AIR:0)
Block(-4,13,0,AIR:0)
Block(-4,13,1,AIR:0)
Block(-4,13,2,AIR:0)
Block(-4,13,3,AIR:0)
Block(-4,13,4,AIR:0)
Block(-4,13,5,AIR:0)
Block(-4,13,6,AIR:0)
Block(-4,13,7,AIR:0)
Block(-4,13,8,STATIONARY_WATER:10)
Block(-4,14,-7,STATIONARY_WATER:10)
Block(-4,14,-6,AIR:0)
Block(-4,14,-5,AIR:0)
Block(-4,14,-4,AIR:0)
Block(-4,14,-3,AIR:0)
Block(-4,14,-2,AIR:0)
Block(-4,14,-1,AIR:0)
Block(-4,14,0,AIR:0)
Block(-4,14,1,AIR:0)
Block(-4,14,2,AIR:0)
Block(-4,14,3,AIR:0)
Block(-4,14,4,AIR:0)
Block(-4,14,5,AIR:0)
Block(-4,14,6,AIR:0)
Block(-4,14,7,AIR:0)
Block(-4,14,8,STATIONARY_WATER:10)
Block(-4,15,-7,STATIONARY_WATER:10)
Block(-4,15,-6,AIR:0)
Block(-4,15,-5,AIR:0)
Block(-4,15,-4,AIR:0)
Block(-4,15,-3,AIR:0)
Block(-4,15,-2,AIR:0)
Block(-4,15,-1,AIR:0)
Block(-4,15,0,AIR:0)
Block(-4,15,1,AIR:0)
Block(-4,15,2,AIR:0)
Block(-4,15,3,AIR:0)
Block(-4,15,4,AIR:0)
Block(-4,15,5,AIR:0)
Block(-4,15,6,AIR:0)
Block(-4,15,7,AIR:0)
Block(-4,15,8,STATIONARY_WATER:10)
Block(-4,16,-7,STATIONARY_WATER:2)
Block(-4,16,-6,AIR:0)
Block(-4,16,-5,AIR:0)
Block(-4,16,-4,AIR:0)
Block(-4,16,-3,AIR:0)
Block(-4,16,-2,AIR:0)
Block(-4,16,-1,AIR:0)
Block(-4,16,0,AIR:0)
Block(-4,16,1,AIR:0)
Block(-4,16,2,AIR:0)
Block(-4,16,3,AIR:0)
Block(-4,16,4,AIR:0)
Block(-4,16,5,AIR:0)
Block(-4,16,6,AIR:0)
Block(-4,16,7,AIR:0)
Block(-4,16,8,STATIONARY_WATER:2)
Block(-4,17,-7,AIR:0)
Block(-4,17,-6,AIR:0)
Block(-4,17,-5,AIR:0)
Block(-4,17,-4,AIR:0)
Block(-4,17,-3,AIR:0)
Block(-4,17,-2,AIR:0)
Block(-4,17,-1,STAINED_GLASS:15)
Block(-4,17,0,CONCRETE:8)
Block(-4,17,1,CONCRETE:8)
Block(-4,17,2,STAINED_GLASS:15)
Block(-4,17,3,AIR:0)
Block(-4,17,4,AIR:0)
Block(-4,17,5,AIR:0)
Block(-4,17,6,AIR:0)
Block(-4,17,7,AIR:0)
Block(-4,17,8,AIR:0)
Block(-4,18,-1,STAINED_GLASS_PANE:15)
Block(-4,18,2,STAINED_GLASS_PANE:15)
Block(-3,0,-7,CONCRETE:7)
Block(-3,0,-6,CONCRETE:7)
Block(-3,0,-5,CONCRETE:7)
Block(-3,0,-4,CONCRETE:7)
Block(-3,0,-3,CONCRETE:7)
Block(-3,0,-2,CONCRETE:7)
Block(-3,0,-1,CONCRETE:7)
Block(-3,0,0,CONCRETE:7)
Block(-3,0,1,CONCRETE:7)
Block(-3,0,2,CONCRETE:7)
Block(-3,0,3,CONCRETE:7)
Block(-3,0,4,CONCRETE:7)
Block(-3,0,5,CONCRETE:7)
Block(-3,0,6,CONCRETE:7)
Block(-3,0,7,CONCRETE:7)
Block(-3,0,8,CONCRETE:7)
Block(-3,1,-7,CONCRETE:7)
Block(-3,1,-6,CONCRETE:7)
Block(-3,1,-5,CONCRETE:7)
Block(-3,1,-4,CONCRETE:7)
Block(-3,1,-3,CONCRETE:7)
Block(-3,1,-2,CONCRETE:7)
Block(-3,1,-1,CONCRETE:7)
Block(-3,1,0,CONCRETE:7)
Block(-3,1,1,CONCRETE:7)
Block(-3,1,2,CONCRETE:7)
Block(-3,1,3,CONCRETE:7)
Block(-3,1,4,CONCRETE:7)
Block(-3,1,5,CONCRETE:7)
Block(-3,1,6,CONCRETE:7)
Block(-3,1,7,CONCRETE:7)
Block(-3,1,8,CONCRETE:7)
Block(-3,2,-7,CONCRETE:7)
Block(-3,2,-6,CONCRETE:7)
Block(-3,2,-5,CONCRETE:7)
Block(-3,2,-4,CONCRETE:7)
Block(-3,2,-3,CONCRETE:7)
Block(-3,2,-2,CONCRETE:7)
Block(-3,2,-1,CONCRETE:7)
Block(-3,2,0,CONCRETE:7)
Block(-3,2,1,CONCRETE:7)
Block(-3,2,2,CONCRETE:7)
Block(-3,2,3,CONCRETE:7)
Block(-3,2,4,CONCRETE:7)
Block(-3,2,5,CONCRETE:7)
Block(-3,2,6,CONCRETE:7)
Block(-3,2,7,CONCRETE:7)
Block(-3,2,8,CONCRETE:7)
Block(-3,3,-7,CONCRETE:7)
Block(-3,3,-6,CONCRETE:7)
Block(-3,3,-5,CONCRETE:7)
Block(-3,3,-4,CONCRETE:7)
Block(-3,3,-3,CONCRETE:7)
Block(-3,3,-2,CONCRETE:7)
Block(-3,3,-1,CONCRETE:7)
Block(-3,3,0,CONCRETE:7)
Block(-3,3,1,CONCRETE:7)
Block(-3,3,2,CONCRETE:7)
Block(-3,3,3,CONCRETE:7)
Block(-3,3,4,CONCRETE:7)
Block(-3,3,5,AIR:0)
Block(-3,3,6,AIR:0)
Block(-3,3,7,AIR:0)
Block(-3,3,8,AIR:0)
Block(-3,4,-7,CONCRETE:7)
Block(-3,4,-6,CONCRETE:7)
Block(-3,4,-5,CONCRETE:7)
Block(-3,4,-4,CONCRETE:7)
Block(-3,4,-3,CONCRETE:7)
Block(-3,4,-2,CONCRETE:7)
Block(-3,4,-1,CONCRETE:7)
Block(-3,4,0,CONCRETE:7)
Block(-3,4,1,CONCRETE:7)
Block(-3,4,2,CONCRETE:7)
Block(-3,4,3,CONCRETE:7)
Block(-3,4,4,CONCRETE:7)
Block(-3,4,5,AIR:0)
Block(-3,4,6,AIR:0)
Block(-3,4,7,AIR:0)
Block(-3,4,8,AIR:0)
Block(-3,5,-7,CONCRETE:7)
Block(-3,5,-6,CONCRETE:7)
Block(-3,5,-5,CONCRETE:7)
Block(-3,5,-4,CONCRETE:7)
Block(-3,5,-3,CONCRETE:7)
Block(-3,5,-2,CONCRETE:7)
Block(-3,5,-1,CONCRETE:7)
Block(-3,5,0,CONCRETE:7)
Block(-3,5,1,CONCRETE:7)
Block(-3,5,2,CONCRETE:7)
Block(-3,5,3,CONCRETE:7)
Block(-3,5,4,CONCRETE:7)
Block(-3,5,5,AIR:0)
Block(-3,5,6,AIR:0)
Block(-3,5,7,CONCRETE:4)
Block(-3,5,8,AIR:0)
Block(-3,6,-7,CONCRETE:7)
Block(-3,6,-6,CONCRETE:7)
Block(-3,6,-5,CONCRETE:7)
Block(-3,6,-4,CONCRETE:7)
Block(-3,6,-3,CONCRETE:7)
Block(-3,6,-2,CONCRETE:7)
Block(-3,6,-1,CONCRETE:7)
Block(-3,6,0,CONCRETE:7)
Block(-3,6,1,CONCRETE:7)
Block(-3,6,2,CONCRETE:7)
Block(-3,6,3,CONCRETE:7)
Block(-3,6,4,CONCRETE:7)
Block(-3,6,5,CONCRETE:7)
Block(-3,6,6,CONCRETE:7)
Block(-3,6,7,CONCRETE:7)
Block(-3,6,8,CONCRETE:7)
Block(-3,7,-7,CONCRETE:7)
Block(-3,7,-6,CONCRETE:7)
Block(-3,7,-5,CONCRETE:7)
Block(-3,7,-4,CONCRETE:7)
Block(-3,7,-3,CONCRETE:7)
Block(-3,7,-2,CONCRETE:7)
Block(-3,7,-1,CONCRETE:7)
Block(-3,7,0,CONCRETE:7)
Block(-3,7,1,CONCRETE:7)
Block(-3,7,2,CONCRETE:7)
Block(-3,7,3,CONCRETE:7)
Block(-3,7,4,CONCRETE:7)
Block(-3,7,5,CONCRETE:7)
Block(-3,7,6,CONCRETE:7)
Block(-3,7,7,CONCRETE:7)
Block(-3,7,8,CONCRETE:7)
Block(-3,8,-7,CONCRETE:7)
Block(-3,8,-6,CONCRETE:7)
Block(-3,8,-5,CONCRETE:7)
Block(-3,8,-4,CONCRETE:7)
Block(-3,8,-3,CONCRETE:7)
Block(-3,8,-2,CONCRETE:7)
Block(-3,8,-1,CONCRETE:7)
Block(-3,8,0,CONCRETE:7)
Block(-3,8,1,CONCRETE:7)
Block(-3,8,2,CONCRETE:7)
Block(-3,8,3,CONCRETE:7)
Block(-3,8,4,CONCRETE:7)
Block(-3,8,5,CONCRETE:7)
Block(-3,8,6,CONCRETE:7)
Block(-3,8,7,CONCRETE:7)
Block(-3,8,8,CONCRETE:7)
Block(-3,9,-7,CONCRETE:8)
Block(-3,9,-6,CONCRETE:8)
Block(-3,9,-5,CONCRETE:8)
Block(-3,9,-4,CONCRETE:8)
Block(-3,9,-3,CONCRETE:8)
Block(-3,9,-2,CONCRETE:8)
Block(-3,9,-1,CONCRETE:8)
Block(-3,9,0,CONCRETE:8)
Block(-3,9,1,CONCRETE:8)
Block(-3,9,2,CONCRETE:8)
Block(-3,9,3,CONCRETE:8)
Block(-3,9,4,CONCRETE:8)
Block(-3,9,5,CONCRETE:8)
Block(-3,9,6,CONCRETE:8)
Block(-3,9,7,CONCRETE:8)
Block(-3,9,8,CONCRETE:8)
Block(-3,10,-7,STAINED_GLASS:15)
Block(-3,10,-6,STAINED_GLASS:15)
Block(-3,10,-5,STAINED_GLASS:15)
Block(-3,10,-4,STAINED_GLASS:15)
Block(-3,10,-3,STAINED_GLASS:15)
Block(-3,10,-2,STAINED_GLASS:15)
Block(-3,10,-1,STAINED_GLASS:15)
Block(-3,10,0,STAINED_GLASS:15)
Block(-3,10,1,STAINED_GLASS:15)
Block(-3,10,2,STAINED_GLASS:15)
Block(-3,10,3,STAINED_GLASS:15)
Block(-3,10,4,STAINED_GLASS:15)
Block(-3,10,5,STAINED_GLASS:15)
Block(-3,10,6,STAINED_GLASS:15)
Block(-3,10,7,STAINED_GLASS:15)
Block(-3,10,8,STAINED_GLASS:15)
Block(-3,11,-7,STATIONARY_WATER:0)
Block(-3,11,-6,STATIONARY_WATER:0)
Block(-3,11,-5,STATIONARY_WATER:0)
Block(-3,11,-4,STATIONARY_WATER:0)
Block(-3,11,-3,STATIONARY_WATER:0)
Block(-3,11,-2,STATIONARY_WATER:0)
Block(-3,11,-1,STATIONARY_WATER:0)
Block(-3,11,0,STATIONARY_WATER:0)
Block(-3,11,1,STATIONARY_WATER:0)
Block(-3,11,2,STATIONARY_WATER:0)
Block(-3,11,3,STATIONARY_WATER:0)
Block(-3,11,4,STATIONARY_WATER:0)
Block(-3,11,5,STATIONARY_WATER:0)
Block(-3,11,6,STATIONARY_WATER:0)
Block(-3,11,7,STATIONARY_WATER:0)
Block(-3,11,8,STATIONARY_WATER:0)
Block(-3,12,-7,STATIONARY_WATER:0)
Block(-3,12,-6,STATIONARY_WATER:0)
Block(-3,12,-5,STATIONARY_WATER:0)
Block(-3,12,-4,STATIONARY_WATER:0)
Block(-3,12,-3,STATIONARY_WATER:0)
Block(-3,12,-2,STATIONARY_WATER:0)
Block(-3,12,-1,STATIONARY_WATER:0)
Block(-3,12,0,STATIONARY_WATER:0)
Block(-3,12,1,STATIONARY_WATER:0)
Block(-3,12,2,STATIONARY_WATER:0)
Block(-3,12,3,STATIONARY_WATER:0)
Block(-3,12,4,STATIONARY_WATER:0)
Block(-3,12,5,STATIONARY_WATER:0)
Block(-3,12,6,STATIONARY_WATER:0)
Block(-3,12,7,STATIONARY_WATER:0)
Block(-3,12,8,STATIONARY_WATER:0)
Block(-3,13,-7,AIR:0)
Block(-3,13,-6,AIR:0)
Block(-3,13,-5,AIR:0)
Block(-3,13,-4,AIR:0)
Block(-3,13,-3,AIR:0)
Block(-3,13,-2,AIR:0)
Block(-3,13,-1,AIR:0)
Block(-3,13,0,AIR:0)
Block(-3,13,1,AIR:0)
Block(-3,13,2,AIR:0)
Block(-3,13,3,AIR:0)
Block(-3,13,4,AIR:0)
Block(-3,13,5,AIR:0)
Block(-3,13,6,AIR:0)
Block(-3,13,7,AIR:0)
Block(-3,13,8,AIR:0)
Block(-3,14,-7,AIR:0)
Block(-3,14,-6,AIR:0)
Block(-3,14,-5,AIR:0)
Block(-3,14,-4,AIR:0)
Block(-3,14,-3,AIR:0)
Block(-3,14,-2,AIR:0)
Block(-3,14,-1,AIR:0)
Block(-3,14,0,AIR:0)
Block(-3,14,1,AIR:0)
Block(-3,14,2,AIR:0)
Block(-3,14,3,AIR:0)
Block(-3,14,4,AIR:0)
Block(-3,14,5,AIR:0)
Block(-3,14,6,AIR:0)
Block(-3,14,7,AIR:0)
Block(-3,14,8,AIR:0)
Block(-3,15,-7,AIR:0)
Block(-3,15,-6,AIR:0)
Block(-3,15,-5,AIR:0)
Block(-3,15,-4,AIR:0)
Block(-3,15,-3,AIR:0)
Block(-3,15,-2,AIR:0)
Block(-3,15,-1,AIR:0)
Block(-3,15,0,AIR:0)
Block(-3,15,1,AIR:0)
Block(-3,15,2,AIR:0)
Block(-3,15,3,AIR:0)
Block(-3,15,4,AIR:0)
Block(-3,15,5,AIR:0)
Block(-3,15,6,AIR:0)
Block(-3,15,7,AIR:0)
Block(-3,15,8,AIR:0)
Block(-3,16,-7,AIR:0)
Block(-3,16,-6,AIR:0)
Block(-3,16,-5,AIR:0)
Block(-3,16,-4,AIR:0)
Block(-3,16,-3,AIR:0)
Block(-3,16,-2,AIR:0)
Block(-3,16,-1,AIR:0)
Block(-3,16,0,AIR:0)
Block(-3,16,1,AIR:0)
Block(-3,16,2,AIR:0)
Block(-3,16,3,AIR:0)
Block(-3,16,4,AIR:0)
Block(-3,16,5,AIR:0)
Block(-3,16,6,AIR:0)
Block(-3,16,7,AIR:0)
Block(-3,16,8,AIR:0)
Block(-3,17,-7,AIR:0)
Block(-3,17,-6,AIR:0)
Block(-3,17,-5,AIR:0)
Block(-3,17,-4,AIR:0)
Block(-3,17,-3,AIR:0)
Block(-3,17,-2,AIR:0)
Block(-3,17,-1,STAINED_GLASS:15)
Block(-3,17,0,CONCRETE:8)
Block(-3,17,1,CONCRETE:8)
Block(-3,17,2,STAINED_GLASS:15)
Block(-3,17,3,AIR:0)
Block(-3,17,4,AIR:0)
Block(-3,17,5,AIR:0)
Block(-3,17,6,AIR:0)
Block(-3,17,7,AIR:0)
Block(-3,17,8,AIR:0)
Block(-3,18,-1,STAINED_GLASS_PANE:15)
Block(-3,18,2,STAINED_GLASS_PANE:15)
Block(-2,0,-7,CONCRETE:7)
Block(-2,0,-6,CONCRETE:7)
Block(-2,0,-5,CONCRETE:7)
Block(-2,0,-4,CONCRETE:7)
Block(-2,0,-3,CONCRETE:7)
Block(-2,0,-2,CONCRETE:7)
Block(-2,0,-1,CONCRETE:7)
Block(-2,0,0,CONCRETE:7)
Block(-2,0,1,CONCRETE:7)
Block(-2,0,2,CONCRETE:7)
Block(-2,0,3,CONCRETE:7)
Block(-2,0,4,CONCRETE:7)
Block(-2,0,5,CONCRETE:7)
Block(-2,0,6,CONCRETE:7)
Block(-2,0,7,CONCRETE:7)
Block(-2,0,8,CONCRETE:7)
Block(-2,1,-7,CONCRETE:7)
Block(-2,1,-6,CONCRETE:7)
Block(-2,1,-5,CONCRETE:7)
Block(-2,1,-4,CONCRETE:7)
Block(-2,1,-3,CONCRETE:7)
Block(-2,1,-2,CONCRETE:7)
Block(-2,1,-1,CONCRETE:7)
Block(-2,1,0,CONCRETE:7)
Block(-2,1,1,CONCRETE:7)
Block(-2,1,2,CONCRETE:7)
Block(-2,1,3,CONCRETE:7)
Block(-2,1,4,CONCRETE:7)
Block(-2,1,5,AIR:0)
Block(-2,1,6,AIR:0)
Block(-2,1,7,AIR:0)
Block(-2,1,8,AIR:0)
Block(-2,2,-7,CONCRETE:7)
Block(-2,2,-6,CONCRETE:7)
Block(-2,2,-5,CONCRETE:7)
Block(-2,2,-4,CONCRETE:7)
Block(-2,2,-3,CONCRETE:7)
Block(-2,2,-2,CONCRETE:7)
Block(-2,2,-1,CONCRETE:7)
Block(-2,2,0,CONCRETE:7)
Block(-2,2,1,CONCRETE:7)
Block(-2,2,2,CONCRETE:7)
Block(-2,2,3,CONCRETE:7)
Block(-2,2,4,CONCRETE:7)
Block(-2,2,5,IRON_TRAPDOOR:8)
Block(-2,2,6,IRON_TRAPDOOR:8)
Block(-2,2,7,IRON_TRAPDOOR:8)
Block(-2,2,8,IRON_TRAPDOOR:8)
Block(-2,3,-7,CONCRETE:7)
Block(-2,3,-6,CONCRETE:7)
Block(-2,3,-5,CONCRETE:7)
Block(-2,3,-4,CONCRETE:7)
Block(-2,3,-3,CONCRETE:7)
Block(-2,3,-2,CONCRETE:7)
Block(-2,3,-1,CONCRETE:7)
Block(-2,3,0,CONCRETE:7)
Block(-2,3,1,CONCRETE:7)
Block(-2,3,2,CONCRETE:7)
Block(-2,3,3,CONCRETE:7)
Block(-2,3,4,CONCRETE:7)
Block(-2,3,5,AIR:0)
Block(-2,3,6,CONCRETE:12)
Block(-2,3,7,CONCRETE:12)
Block(-2,3,8,CONCRETE:12)
Block(-2,4,-7,CONCRETE:7)
Block(-2,4,-6,CONCRETE:7)
Block(-2,4,-5,CONCRETE:7)
Block(-2,4,-4,CONCRETE:7)
Block(-2,4,-3,CONCRETE:7)
Block(-2,4,-2,CONCRETE:7)
Block(-2,4,-1,CONCRETE:7)
Block(-2,4,0,CONCRETE:7)
Block(-2,4,1,CONCRETE:7)
Block(-2,4,2,CONCRETE:7)
Block(-2,4,3,CONCRETE:7)
Block(-2,4,4,CONCRETE:7)
Block(-2,4,5,AIR:0)
Block(-2,4,6,CONCRETE:12)
Block(-2,4,7,AIR:0)
Block(-2,4,8,AIR:0)
Block(-2,5,-7,CONCRETE:7)
Block(-2,5,-6,CONCRETE:7)
Block(-2,5,-5,CONCRETE:7)
Block(-2,5,-4,CONCRETE:7)
Block(-2,5,-3,CONCRETE:7)
Block(-2,5,-2,CONCRETE:7)
Block(-2,5,-1,CONCRETE:7)
Block(-2,5,0,CONCRETE:7)
Block(-2,5,1,CONCRETE:7)
Block(-2,5,2,CONCRETE:7)
Block(-2,5,3,CONCRETE:7)
Block(-2,5,4,CONCRETE:7)
Block(-2,5,5,AIR:0)
Block(-2,5,6,CONCRETE:12)
Block(-2,5,7,CONCRETE:4)
Block(-2,5,8,AIR:0)
Block(-2,6,-7,CONCRETE:7)
Block(-2,6,-6,CONCRETE:7)
Block(-2,6,-5,CONCRETE:7)
Block(-2,6,-4,CONCRETE:7)
Block(-2,6,-3,CONCRETE:7)
Block(-2,6,-2,CONCRETE:7)
Block(-2,6,-1,CONCRETE:7)
Block(-2,6,0,CONCRETE:7)
Block(-2,6,1,CONCRETE:7)
Block(-2,6,2,CONCRETE:7)
Block(-2,6,3,CONCRETE:7)
Block(-2,6,4,CONCRETE:7)
Block(-2,6,5,CONCRETE:7)
Block(-2,6,6,CONCRETE:7)
Block(-2,6,7,CONCRETE:7)
Block(-2,6,8,CONCRETE:7)
Block(-2,7,-7,CONCRETE:7)
Block(-2,7,-6,CONCRETE:7)
Block(-2,7,-5,CONCRETE:7)
Block(-2,7,-4,CONCRETE:7)
Block(-2,7,-3,CONCRETE:7)
Block(-2,7,-2,CONCRETE:7)
Block(-2,7,-1,CONCRETE:7)
Block(-2,7,0,CONCRETE:7)
Block(-2,7,1,CONCRETE:7)
Block(-2,7,2,CONCRETE:7)
Block(-2,7,3,CONCRETE:7)
Block(-2,7,4,CONCRETE:7)
Block(-2,7,5,CONCRETE:7)
Block(-2,7,6,CONCRETE:7)
Block(-2,7,7,CONCRETE:7)
Block(-2,7,8,CONCRETE:7)
Block(-2,8,-7,CONCRETE:7)
Block(-2,8,-6,CONCRETE:7)
Block(-2,8,-5,CONCRETE:7)
Block(-2,8,-4,CONCRETE:7)
Block(-2,8,-3,CONCRETE:7)
Block(-2,8,-2,CONCRETE:7)
Block(-2,8,-1,CONCRETE:7)
Block(-2,8,0,CONCRETE:7)
Block(-2,8,1,CONCRETE:7)
Block(-2,8,2,CONCRETE:7)
Block(-2,8,3,CONCRETE:7)
Block(-2,8,4,CONCRETE:7)
Block(-2,8,5,CONCRETE:7)
Block(-2,8,6,CONCRETE:7)
Block(-2,8,7,CONCRETE:7)
Block(-2,8,8,CONCRETE:7)
Block(-2,9,-7,CONCRETE:8)
Block(-2,9,-6,CONCRETE:8)
Block(-2,9,-5,CONCRETE:8)
Block(-2,9,-4,CONCRETE:8)
Block(-2,9,-3,CONCRETE:8)
Block(-2,9,-2,CONCRETE:8)
Block(-2,9,-1,CONCRETE:8)
Block(-2,9,0,CONCRETE:8)
Block(-2,9,1,CONCRETE:8)
Block(-2,9,2,CONCRETE:8)
Block(-2,9,3,CONCRETE:8)
Block(-2,9,4,CONCRETE:8)
Block(-2,9,5,CONCRETE:8)
Block(-2,9,6,CONCRETE:8)
Block(-2,9,7,CONCRETE:8)
Block(-2,9,8,CONCRETE:8)
Block(-2,10,-7,CONCRETE:8)
Block(-2,10,-6,CONCRETE:8)
Block(-2,10,-5,CONCRETE:8)
Block(-2,10,-4,CONCRETE:8)
Block(-2,10,-3,CONCRETE:8)
Block(-2,10,-2,CONCRETE:8)
Block(-2,10,-1,CONCRETE:8)
Block(-2,10,0,CONCRETE:8)
Block(-2,10,1,CONCRETE:8)
Block(-2,10,2,CONCRETE:8)
Block(-2,10,3,CONCRETE:8)
Block(-2,10,4,CONCRETE:8)
Block(-2,10,5,CONCRETE:8)
Block(-2,10,6,CONCRETE:8)
Block(-2,10,7,CONCRETE:8)
Block(-2,10,8,CONCRETE:8)
Block(-2,11,-7,CONCRETE:8)
Block(-2,11,-6,CONCRETE:8)
Block(-2,11,-5,CONCRETE:8)
Block(-2,11,-4,CONCRETE:8)
Block(-2,11,-3,CONCRETE:8)
Block(-2,11,-2,CONCRETE:8)
Block(-2,11,-1,CONCRETE:8)
Block(-2,11,0,CONCRETE:8)
Block(-2,11,1,CONCRETE:8)
Block(-2,11,2,CONCRETE:8)
Block(-2,11,3,CONCRETE:8)
Block(-2,11,4,CONCRETE:8)
Block(-2,11,5,CONCRETE:8)
Block(-2,11,6,CONCRETE:8)
Block(-2,11,7,CONCRETE:8)
Block(-2,11,8,CONCRETE:8)
Block(-2,12,-7,CONCRETE:8)
Block(-2,12,-6,STATIONARY_WATER:0)
Block(-2,12,-5,STATIONARY_WATER:0)
Block(-2,12,-4,STATIONARY_WATER:0)
Block(-2,12,-3,STATIONARY_WATER:0)
Block(-2,12,-2,STATIONARY_WATER:0)
Block(-2,12,-1,STATIONARY_WATER:0)
Block(-2,12,0,STATIONARY_WATER:0)
Block(-2,12,1,STATIONARY_WATER:0)
Block(-2,12,2,STATIONARY_WATER:0)
Block(-2,12,3,STATIONARY_WATER:0)
Block(-2,12,4,STATIONARY_WATER:0)
Block(-2,12,5,STATIONARY_WATER:0)
Block(-2,12,6,STATIONARY_WATER:0)
Block(-2,12,7,STATIONARY_WATER:0)
Block(-2,12,8,CONCRETE:8)
Block(-2,13,-7,CONCRETE:8)
Block(-2,13,-6,AIR:0)
Block(-2,13,-5,AIR:0)
Block(-2,13,-4,AIR:0)
Block(-2,13,-3,AIR:0)
Block(-2,13,-2,AIR:0)
Block(-2,13,-1,AIR:0)
Block(-2,13,0,AIR:0)
Block(-2,13,1,AIR:0)
Block(-2,13,2,AIR:0)
Block(-2,13,3,AIR:0)
Block(-2,13,4,AIR:0)
Block(-2,13,5,AIR:0)
Block(-2,13,6,AIR:0)
Block(-2,13,7,AIR:0)
Block(-2,13,8,CONCRETE:8)
Block(-2,14,-7,CONCRETE:8)
Block(-2,14,-6,AIR:0)
Block(-2,14,-5,AIR:0)
Block(-2,14,-4,AIR:0)
Block(-2,14,-3,AIR:0)
Block(-2,14,-2,AIR:0)
Block(-2,14,-1,AIR:0)
Block(-2,14,0,AIR:0)
Block(-2,14,1,AIR:0)
Block(-2,14,2,AIR:0)
Block(-2,14,3,AIR:0)
Block(-2,14,4,AIR:0)
Block(-2,14,5,AIR:0)
Block(-2,14,6,AIR:0)
Block(-2,14,7,AIR:0)
Block(-2,14,8,CONCRETE:8)
Block(-2,15,-7,CONCRETE:8)
Block(-2,15,-6,AIR:0)
Block(-2,15,-5,AIR:0)
Block(-2,15,-4,AIR:0)
Block(-2,15,-3,AIR:0)
Block(-2,15,-2,AIR:0)
Block(-2,15,-1,AIR:0)
Block(-2,15,0,AIR:0)
Block(-2,15,1,AIR:0)
Block(-2,15,2,AIR:0)
Block(-2,15,3,AIR:0)
Block(-2,15,4,AIR:0)
Block(-2,15,5,AIR:0)
Block(-2,15,6,AIR:0)
Block(-2,15,7,AIR:0)
Block(-2,15,8,CONCRETE:8)
Block(-2,16,-7,CONCRETE:8)
Block(-2,16,-6,AIR:0)
Block(-2,16,-5,AIR:0)
Block(-2,16,-4,AIR:0)
Block(-2,16,-3,AIR:0)
Block(-2,16,-2,AIR:0)
Block(-2,16,-1,AIR:0)
Block(-2,16,0,AIR:0)
Block(-2,16,1,AIR:0)
Block(-2,16,2,AIR:0)
Block(-2,16,3,AIR:0)
Block(-2,16,4,AIR:0)
Block(-2,16,5,AIR:0)
Block(-2,16,6,AIR:0)
Block(-2,16,7,AIR:0)
Block(-2,16,8,CONCRETE:8)
Block(-2,17,-7,CONCRETE:8)
Block(-2,17,-6,AIR:0)
Block(-2,17,-5,AIR:0)
Block(-2,17,-4,AIR:0)
Block(-2,17,-3,AIR:0)
Block(-2,17,-2,AIR:0)
Block(-2,17,-1,STAINED_GLASS:15)
Block(-2,17,0,CONCRETE:8)
Block(-2,17,1,CONCRETE:8)
Block(-2,17,2,STAINED_GLASS:15)
Block(-2,17,3,AIR:0)
Block(-2,17,4,AIR:0)
Block(-2,17,5,AIR:0)
Block(-2,17,6,AIR:0)
Block(-2,17,7,AIR:0)
Block(-2,17,8,CONCRETE:8)
Block(-2,18,-7,CONCRETE:8)
Block(-2,18,-1,STAINED_GLASS_PANE:15)
Block(-2,18,2,STAINED_GLASS_PANE:15)
Block(-2,18,8,CONCRETE:8)
Block(-2,19,-7,CONCRETE:8)
Block(-2,19,8,CONCRETE:8)
Block(-2,20,-7,CONCRETE:8)
Block(-2,20,8,CONCRETE:8)
Block(-2,21,-7,CONCRETE:8)
Block(-2,21,8,CONCRETE:8)
Block(-2,22,-7,CONCRETE:8)
Block(-2,22,8,CONCRETE:8)
Block(-2,23,-7,CONCRETE:8)
Block(-2,23,8,CONCRETE:8)
Block(-2,24,-7,CONCRETE:8)
Block(-2,24,8,CONCRETE:8)
Block(-2,25,-7,CONCRETE:8)
Block(-2,25,8,CONCRETE:8)
Block(-2,26,-7,CONCRETE:8)
Block(-2,26,8,CONCRETE:8)
Block(-2,27,-7,CONCRETE:8)
Block(-2,27,8,CONCRETE:8)
Block(-2,28,-7,CONCRETE:8)
Block(-2,28,8,CONCRETE:8)
Block(-2,29,-7,CONCRETE:8)
Block(-2,29,8,CONCRETE:8)
Block(-2,30,-7,CONCRETE:8)
Block(-2,30,8,CONCRETE:8)
Block(-2,31,-7,CONCRETE:8)
Block(-2,31,8,CONCRETE:8)
Block(-2,32,-7,CONCRETE:8)
Block(-2,32,8,CONCRETE:8)
Block(-2,33,-7,CONCRETE:8)
Block(-2,33,8,CONCRETE:8)
Block(-2,34,-7,CONCRETE:8)
Block(-2,34,8,CONCRETE:8)
Block(-2,35,-7,CONCRETE:8)
Block(-2,35,8,CONCRETE:8)
Block(-2,36,-7,CONCRETE:8)
Block(-2,36,8,CONCRETE:8)
Block(-2,37,-7,CONCRETE:8)
Block(-2,37,8,CONCRETE:8)
Block(-2,38,-7,CONCRETE:8)
Block(-2,38,8,CONCRETE:8)
Block(-2,39,-7,CONCRETE:8)
Block(-2,39,8,CONCRETE:8)
Block(-2,40,-7,CONCRETE:8)
Block(-2,40,8,CONCRETE:8)
Block(-2,41,-7,CONCRETE:8)
Block(-2,41,8,CONCRETE:8)
Block(-2,42,-7,CONCRETE:8)
Block(-2,42,8,CONCRETE:8)
Block(-2,43,-7,CONCRETE:8)
Block(-2,43,8,CONCRETE:8)
Block(-2,44,-7,CONCRETE:8)
Block(-2,44,8,CONCRETE:8)
Block(-2,45,-7,CONCRETE:8)
Block(-2,45,8,CONCRETE:8)
Block(-2,46,-7,CONCRETE:8)
Block(-2,46,8,CONCRETE:8)
Block(-2,47,-7,CONCRETE:8)
Block(-2,47,8,CONCRETE:8)
Block(-2,48,-7,CONCRETE:8)
Block(-2,48,8,CONCRETE:8)
Block(-2,49,-7,CONCRETE:8)
Block(-2,49,8,CONCRETE:8)
Block(-2,50,-7,CONCRETE:8)
Block(-2,50,8,CONCRETE:8)
Block(-2,51,-7,CONCRETE:8)
Block(-2,51,8,CONCRETE:8)
Block(-2,52,-7,CONCRETE:8)
Block(-2,52,8,CONCRETE:8)
Block(-2,53,-7,CONCRETE:8)
Block(-2,53,8,CONCRETE:8)
Block(-2,54,-7,CONCRETE:8)
Block(-2,54,8,CONCRETE:8)
Block(-2,55,-7,CONCRETE:8)
Block(-2,55,8,CONCRETE:8)
Block(-2,56,-7,CONCRETE:8)
Block(-2,56,8,CONCRETE:8)
Block(-2,57,-7,CONCRETE:8)
Block(-2,57,8,CONCRETE:8)
Block(-2,58,-7,CONCRETE:8)
Block(-2,58,8,CONCRETE:8)
Block(-2,59,-7,CONCRETE:8)
Block(-2,59,8,CONCRETE:8)
Block(-2,60,-7,CONCRETE:8)
Block(-2,60,8,CONCRETE:8)
Block(-2,61,-7,CONCRETE:8)
Block(-2,61,8,CONCRETE:8)
Block(-2,62,-7,CONCRETE:8)
Block(-2,62,8,CONCRETE:8)
Block(-2,63,-7,CONCRETE:8)
Block(-2,63,8,CONCRETE:8)
Block(-2,64,-7,CONCRETE:8)
Block(-2,64,8,CONCRETE:8)
Block(-2,65,-7,CONCRETE:8)
Block(-2,65,8,CONCRETE:8)
Block(-2,66,-7,CONCRETE:8)
Block(-2,66,8,CONCRETE:8)
Block(-2,67,-7,CONCRETE:8)
Block(-2,67,8,CONCRETE:8)
Block(-2,68,-7,CONCRETE:8)
Block(-2,68,8,CONCRETE:8)
Block(-2,69,-7,CONCRETE:8)
Block(-2,69,8,CONCRETE:8)
Block(-2,70,-7,CONCRETE:8)
Block(-2,70,8,CONCRETE:8)
Block(-2,71,-7,CONCRETE:8)
Block(-2,71,8,CONCRETE:8)
Block(-2,72,-7,CONCRETE:8)
Block(-2,72,8,CONCRETE:8)
Block(-2,73,-7,CONCRETE:8)
Block(-2,73,8,CONCRETE:8)
Block(-2,74,-7,CONCRETE:8)
Block(-2,74,8,CONCRETE:8)
Block(-2,75,-7,CONCRETE:8)
Block(-2,75,8,CONCRETE:8)
Block(-2,76,-7,CONCRETE:8)
Block(-2,76,8,CONCRETE:8)
Block(-2,77,-7,CONCRETE:8)
Block(-2,77,8,CONCRETE:8)
Block(-2,78,-7,CONCRETE:8)
Block(-2,78,8,CONCRETE:8)
Block(-2,79,-7,CONCRETE:8)
Block(-2,79,8,CONCRETE:8)
Block(-2,80,-7,CONCRETE:8)
Block(-2,80,8,CONCRETE:8)
Block(-2,81,-7,CONCRETE:8)
Block(-2,81,8,CONCRETE:8)
Block(-2,82,-7,CONCRETE:8)
Block(-2,82,8,CONCRETE:8)
Block(-2,83,-7,CONCRETE:8)
Block(-2,83,8,CONCRETE:8)
Block(-2,84,-7,CONCRETE:8)
Block(-2,84,8,CONCRETE:8)
Block(-2,85,-7,CONCRETE:8)
Block(-2,85,8,CONCRETE:8)
Block(-2,86,-7,CONCRETE:8)
Block(-2,86,8,CONCRETE:8)
Block(-2,87,-7,CONCRETE:8)
Block(-2,87,8,CONCRETE:8)
Block(-2,88,-7,CONCRETE:8)
Block(-2,88,8,CONCRETE:8)
Block(-2,89,-7,CONCRETE:8)
Block(-2,89,8,CONCRETE:8)
Block(-2,90,-7,CONCRETE:8)
Block(-2,90,8,CONCRETE:8)
Block(-2,91,-7,CONCRETE:8)
Block(-2,91,8,CONCRETE:8)
Block(-2,92,-7,CONCRETE:8)
Block(-2,92,8,CONCRETE:8)
Block(-2,93,-7,CONCRETE:8)
Block(-2,93,8,CONCRETE:8)
Block(-2,94,-7,CONCRETE:8)
Block(-2,94,8,CONCRETE:8)
Block(-2,95,-7,CONCRETE:8)
Block(-2,95,8,CONCRETE:8)
Block(-2,96,-7,CONCRETE:8)
Block(-2,96,8,CONCRETE:8)
Block(-2,97,-7,CONCRETE:8)
Block(-2,97,8,CONCRETE:8)
Block(-2,98,-7,CONCRETE:8)
Block(-2,98,8,CONCRETE:8)
Block(-2,99,-7,CONCRETE:8)
Block(-2,99,8,CONCRETE:8)
Block(-2,100,-7,CONCRETE:8)
Block(-2,100,8,CONCRETE:8)
Block(-2,101,-7,CONCRETE:8)
Block(-2,101,8,CONCRETE:8)
Block(-2,102,-7,CONCRETE:8)
Block(-2,102,8,CONCRETE:8)
Block(-2,103,-7,CONCRETE:8)
Block(-2,103,8,CONCRETE:8)
Block(-2,104,-7,CONCRETE:8)
Block(-2,104,8,CONCRETE:8)
Block(-2,105,-7,CONCRETE:8)
Block(-2,105,8,CONCRETE:8)
Block(-2,106,-7,CONCRETE:8)
Block(-2,106,8,CONCRETE:8)
Block(-2,107,-7,CONCRETE:8)
Block(-2,107,8,CONCRETE:8)
Block(-2,108,-7,CONCRETE:8)
Block(-2,108,8,CONCRETE:8)
Block(-2,109,-7,CONCRETE:8)
Block(-2,109,8,CONCRETE:8)
Block(-2,110,-7,CONCRETE:8)
Block(-2,110,8,CONCRETE:8)
Block(-2,111,-7,CONCRETE:8)
Block(-2,111,8,CONCRETE:8)
Block(-2,112,-7,CONCRETE:8)
Block(-2,112,8,CONCRETE:8)
Block(-2,113,-7,CONCRETE:8)
Block(-2,113,8,CONCRETE:8)
Block(-2,114,-7,CONCRETE:8)
Block(-2,114,8,CONCRETE:8)
Block(-2,115,-7,CONCRETE:8)
Block(-2,115,8,CONCRETE:8)
Block(-2,116,-7,CONCRETE:8)
Block(-2,116,8,CONCRETE:8)
Block(-2,117,-7,CONCRETE:8)
Block(-2,117,8,CONCRETE:8)
Block(-2,118,-7,CONCRETE:8)
Block(-2,118,8,CONCRETE:8)
Block(-2,119,-7,CONCRETE:8)
Block(-2,119,8,CONCRETE:8)
Block(-2,120,-7,CONCRETE:8)
Block(-2,120,8,CONCRETE:8)
Block(-2,121,-7,CONCRETE:8)
Block(-2,121,8,CONCRETE:8)
Block(-2,122,-7,CONCRETE:8)
Block(-2,122,8,CONCRETE:8)
Block(-2,123,-7,CONCRETE:8)
Block(-2,123,8,CONCRETE:8)
Block(-2,124,-7,CONCRETE:8)
Block(-2,124,8,CONCRETE:8)
Block(-2,125,-7,CONCRETE:8)
Block(-2,125,8,CONCRETE:8)
Block(-2,126,-7,CONCRETE:8)
Block(-2,126,8,CONCRETE:8)
Block(-2,127,-7,CONCRETE:8)
Block(-2,127,8,CONCRETE:8)
Block(-2,128,-7,CONCRETE:8)
Block(-2,128,8,CONCRETE:8)
Block(-2,129,-7,CONCRETE:8)
Block(-2,129,8,CONCRETE:8)
Block(-2,130,-7,CONCRETE:8)
Block(-2,130,8,CONCRETE:8)
Block(-2,131,-7,CONCRETE:8)
Block(-2,131,8,CONCRETE:8)
Block(-2,132,-7,CONCRETE:8)
Block(-2,132,8,CONCRETE:8)
Block(-2,133,-7,CONCRETE:8)
Block(-2,133,8,CONCRETE:8)
Block(-2,134,-7,CONCRETE:8)
Block(-2,134,8,CONCRETE:8)
Block(-2,135,-7,CONCRETE:8)
Block(-2,135,8,CONCRETE:8)
Block(-2,136,-7,CONCRETE:8)
Block(-2,136,8,CONCRETE:8)
Block(-2,137,-7,CONCRETE:8)
Block(-2,137,8,CONCRETE:8)
Block(-2,138,-7,CONCRETE:8)
Block(-2,138,8,CONCRETE:8)
Block(-2,139,-7,CONCRETE:8)
Block(-2,139,8,CONCRETE:8)
Block(-2,140,-7,CONCRETE:8)
Block(-2,140,8,CONCRETE:8)
Block(-2,141,-7,CONCRETE:8)
Block(-2,141,8,CONCRETE:8)
Block(-2,142,-7,CONCRETE:8)
Block(-2,142,8,CONCRETE:8)
Block(-2,143,-7,CONCRETE:8)
Block(-2,143,8,CONCRETE:8)
Block(-2,144,-7,CONCRETE:8)
Block(-2,144,8,CONCRETE:8)
Block(-2,145,-7,CONCRETE:8)
Block(-2,145,8,CONCRETE:8)
Block(-2,146,-7,CONCRETE:8)
Block(-2,146,8,CONCRETE:8)
Block(-2,147,-7,CONCRETE:8)
Block(-2,147,8,CONCRETE:8)
Block(-2,148,-7,CONCRETE:8)
Block(-2,148,8,CONCRETE:8)
Block(-2,149,-7,CONCRETE:8)
Block(-2,149,8,CONCRETE:8)
Block(-2,150,-7,CONCRETE:8)
Block(-2,150,8,CONCRETE:8)
Block(-2,151,-7,CONCRETE:8)
Block(-2,151,8,CONCRETE:8)
Block(-2,152,-7,CONCRETE:8)
Block(-2,152,8,CONCRETE:8)
Block(-2,153,-7,CONCRETE:8)
Block(-2,153,8,CONCRETE:8)
Block(-2,154,-7,CONCRETE:8)
Block(-2,154,8,CONCRETE:8)
Block(-2,155,-7,CONCRETE:8)
Block(-2,155,8,CONCRETE:8)
Block(-2,156,-7,CONCRETE:8)
Block(-2,156,8,CONCRETE:8)
Block(-2,157,-7,CONCRETE:8)
Block(-2,157,8,CONCRETE:8)
Block(-2,158,-7,CONCRETE:8)
Block(-2,158,8,CONCRETE:8)
Block(-2,159,-7,CONCRETE:8)
Block(-2,159,8,CONCRETE:8)
Block(-2,160,-7,CONCRETE:8)
Block(-2,160,8,CONCRETE:8)
Block(-2,161,-7,CONCRETE:8)
Block(-2,161,8,CONCRETE:8)
Block(-2,162,-7,CONCRETE:8)
Block(-2,162,8,CONCRETE:8)
Block(-2,163,-7,CONCRETE:8)
Block(-2,163,8,CONCRETE:8)
Block(-2,164,-7,CONCRETE:8)
Block(-2,164,8,CONCRETE:8)
Block(-2,165,-7,CONCRETE:8)
Block(-2,165,8,CONCRETE:8)
Block(-2,166,-7,CONCRETE:8)
Block(-2,166,8,CONCRETE:8)
Block(-2,167,-7,CONCRETE:8)
Block(-2,167,8,CONCRETE:8)
Block(-2,168,-7,CONCRETE:8)
Block(-2,168,8,CONCRETE:8)
Block(-2,169,-7,CONCRETE:8)
Block(-2,169,8,CONCRETE:8)
Block(-2,170,-7,CONCRETE:8)
Block(-2,170,8,CONCRETE:8)
Block(-2,171,-7,CONCRETE:8)
Block(-2,171,8,CONCRETE:8)
Block(-2,172,-7,CONCRETE:8)
Block(-2,172,8,CONCRETE:8)
Block(-2,173,-7,CONCRETE:8)
Block(-2,173,8,CONCRETE:8)
Block(-2,174,-7,CONCRETE:8)
Block(-2,174,8,CONCRETE:8)
Block(-2,175,-7,CONCRETE:8)
Block(-2,175,8,CONCRETE:8)
Block(-2,176,-7,CONCRETE:8)
Block(-2,176,8,CONCRETE:8)
Block(-2,177,-7,CONCRETE:8)
Block(-2,177,8,CONCRETE:8)
Block(-2,178,-7,CONCRETE:8)
Block(-2,178,8,CONCRETE:8)
Block(-2,179,-7,CONCRETE:8)
Block(-2,179,8,CONCRETE:8)
Block(-2,180,-7,CONCRETE:8)
Block(-2,180,8,CONCRETE:8)
Block(-2,181,-7,CONCRETE:8)
Block(-2,181,8,CONCRETE:8)
Block(-2,182,-7,CONCRETE:8)
Block(-2,182,8,CONCRETE:8)
Block(-2,183,-7,CONCRETE:8)
Block(-2,183,8,CONCRETE:8)
Block(-2,184,-7,CONCRETE:8)
Block(-2,184,8,CONCRETE:8)
Block(-2,185,-7,CONCRETE:8)
Block(-2,185,8,CONCRETE:8)
Block(-2,186,-7,CONCRETE:8)
Block(-2,186,8,CONCRETE:8)
Block(-2,187,-7,CONCRETE:8)
Block(-2,187,8,CONCRETE:8)
Block(-2,188,-7,CONCRETE:8)
Block(-2,188,8,CONCRETE:8)
Block(-2,189,-7,CONCRETE:8)
Block(-2,189,8,CONCRETE:8)
Block(-2,190,-7,CONCRETE:8)
Block(-2,190,8,CONCRETE:8)
Block(-2,191,-7,CONCRETE:8)
Block(-2,191,8,CONCRETE:8)
Block(-2,192,-7,CONCRETE:8)
Block(-2,192,8,CONCRETE:8)
Block(-2,193,-7,CONCRETE:8)
Block(-2,193,8,CONCRETE:8)
Block(-2,194,-7,CONCRETE:8)
Block(-2,194,8,CONCRETE:8)
Block(-2,195,-7,CONCRETE:8)
Block(-2,195,8,CONCRETE:8)
Block(-2,196,-7,CONCRETE:8)
Block(-2,196,8,CONCRETE:8)
Block(-2,197,-7,CONCRETE:8)
Block(-2,197,8,CONCRETE:8)
Block(-2,198,-7,CONCRETE:8)
Block(-2,198,8,CONCRETE:8)
Block(-2,199,-7,CONCRETE:8)
Block(-2,199,8,CONCRETE:8)
Block(-2,200,-7,CONCRETE:8)
Block(-2,200,8,CONCRETE:8)
Block(-2,201,-7,CONCRETE:8)
Block(-2,201,8,CONCRETE:8)
Block(-2,202,-7,STEP:0)
Block(-2,202,8,STEP:0)
Block(-1,0,-7,CONCRETE:7)
Block(-1,0,-6,CONCRETE:7)
Block(-1,0,-5,CONCRETE:7)
Block(-1,0,-4,CONCRETE:7)
Block(-1,0,-3,CONCRETE:7)
Block(-1,0,-2,CONCRETE:7)
Block(-1,0,-1,CONCRETE:7)
Block(-1,0,0,CONCRETE:7)
Block(-1,0,1,CONCRETE:7)
Block(-1,0,2,CONCRETE:7)
Block(-1,0,3,CONCRETE:7)
Block(-1,0,4,CONCRETE:7)
Block(-1,0,5,CONCRETE:7)
Block(-1,0,6,CONCRETE:7)
Block(-1,0,7,CONCRETE:7)
Block(-1,0,8,CONCRETE:7)
Block(-1,1,-7,CONCRETE:7)
Block(-1,1,-6,CONCRETE:7)
Block(-1,1,-5,CONCRETE:7)
Block(-1,1,-4,CONCRETE:7)
Block(-1,1,-3,CONCRETE:7)
Block(-1,1,-2,CONCRETE:7)
Block(-1,1,-1,CONCRETE:7)
Block(-1,1,0,CONCRETE:7)
Block(-1,1,1,CONCRETE:7)
Block(-1,1,2,CONCRETE:7)
Block(-1,1,3,CONCRETE:7)
Block(-1,1,4,CONCRETE:7)
Block(-1,1,5,CONCRETE:7)
Block(-1,1,6,CONCRETE:7)
Block(-1,1,7,CONCRETE:7)
Block(-1,1,8,CONCRETE:7)
Block(-1,2,-7,CONCRETE:7)
Block(-1,2,-6,CONCRETE:7)
Block(-1,2,-5,CONCRETE:7)
Block(-1,2,-4,CONCRETE:7)
Block(-1,2,-3,CONCRETE:7)
Block(-1,2,-2,CONCRETE:7)
Block(-1,2,-1,CONCRETE:7)
Block(-1,2,0,CONCRETE:7)
Block(-1,2,1,CONCRETE:7)
Block(-1,2,2,CONCRETE:7)
Block(-1,2,3,CONCRETE:7)
Block(-1,2,4,CONCRETE:7)
Block(-1,2,5,CONCRETE:7)
Block(-1,2,6,CONCRETE:7)
Block(-1,2,7,CONCRETE:7)
Block(-1,2,8,CONCRETE:7)
Block(-1,3,-7,CONCRETE:7)
Block(-1,3,-6,CONCRETE:7)
Block(-1,3,-5,CONCRETE:7)
Block(-1,3,-4,CONCRETE:7)
Block(-1,3,-3,CONCRETE:7)
Block(-1,3,-2,CONCRETE:7)
Block(-1,3,-1,CONCRETE:7)
Block(-1,3,0,CONCRETE:7)
Block(-1,3,1,CONCRETE:7)
Block(-1,3,2,CONCRETE:7)
Block(-1,3,3,CONCRETE:7)
Block(-1,3,4,CONCRETE:7)
Block(-1,3,5,IRON_FENCE:0)
Block(-1,3,6,IRON_FENCE:0)
Block(-1,3,7,IRON_FENCE:0)
Block(-1,3,8,IRON_FENCE:0)
Block(-1,4,-7,CONCRETE:7)
Block(-1,4,-6,CONCRETE:7)
Block(-1,4,-5,CONCRETE:7)
Block(-1,4,-4,CONCRETE:7)
Block(-1,4,-3,CONCRETE:7)
Block(-1,4,-2,CONCRETE:7)
Block(-1,4,-1,CONCRETE:7)
Block(-1,4,0,CONCRETE:7)
Block(-1,4,1,CONCRETE:7)
Block(-1,4,2,CONCRETE:7)
Block(-1,4,3,CONCRETE:7)
Block(-1,4,4,CONCRETE:7)
Block(-1,4,5,IRON_FENCE:0)
Block(-1,4,6,IRON_FENCE:0)
Block(-1,4,7,IRON_FENCE:0)
Block(-1,4,8,IRON_FENCE:0)
Block(-1,5,-7,CONCRETE:7)
Block(-1,5,-6,CONCRETE:7)
Block(-1,5,-5,CONCRETE:7)
Block(-1,5,-4,CONCRETE:7)
Block(-1,5,-3,CONCRETE:7)
Block(-1,5,-2,CONCRETE:7)
Block(-1,5,-1,CONCRETE:7)
Block(-1,5,0,CONCRETE:7)
Block(-1,5,1,CONCRETE:7)
Block(-1,5,2,CONCRETE:7)
Block(-1,5,3,CONCRETE:7)
Block(-1,5,4,CONCRETE:7)
Block(-1,5,5,AIR:0)
Block(-1,5,6,CONCRETE:12)
Block(-1,5,7,CONCRETE:4)
Block(-1,5,8,AIR:0)
Block(-1,6,-7,CONCRETE:7)
Block(-1,6,-6,CONCRETE:7)
Block(-1,6,-5,CONCRETE:7)
Block(-1,6,-4,CONCRETE:7)
Block(-1,6,-3,CONCRETE:7)
Block(-1,6,-2,CONCRETE:7)
Block(-1,6,-1,CONCRETE:7)
Block(-1,6,0,CONCRETE:7)
Block(-1,6,1,CONCRETE:7)
Block(-1,6,2,CONCRETE:7)
Block(-1,6,3,CONCRETE:7)
Block(-1,6,4,CONCRETE:7)
Block(-1,6,5,CONCRETE:7)
Block(-1,6,6,CONCRETE:7)
Block(-1,6,7,CONCRETE:7)
Block(-1,6,8,CONCRETE:7)
Block(-1,7,-7,CONCRETE:7)
Block(-1,7,-6,CONCRETE:7)
Block(-1,7,-5,CONCRETE:7)
Block(-1,7,-4,CONCRETE:7)
Block(-1,7,-3,CONCRETE:7)
Block(-1,7,-2,CONCRETE:7)
Block(-1,7,-1,CONCRETE:7)
Block(-1,7,0,CONCRETE:7)
Block(-1,7,1,CONCRETE:7)
Block(-1,7,2,CONCRETE:7)
Block(-1,7,3,CONCRETE:7)
Block(-1,7,4,CONCRETE:7)
Block(-1,7,5,CONCRETE:7)
Block(-1,7,6,CONCRETE:7)
Block(-1,7,7,CONCRETE:7)
Block(-1,7,8,CONCRETE:7)
Block(-1,8,-7,CONCRETE:7)
Block(-1,8,-6,CONCRETE:7)
Block(-1,8,-5,CONCRETE:7)
Block(-1,8,-4,CONCRETE:7)
Block(-1,8,-3,CONCRETE:7)
Block(-1,8,-2,CONCRETE:7)
Block(-1,8,-1,CONCRETE:7)
Block(-1,8,0,CONCRETE:7)
Block(-1,8,1,CONCRETE:7)
Block(-1,8,2,CONCRETE:7)
Block(-1,8,3,CONCRETE:7)
Block(-1,8,4,CONCRETE:7)
Block(-1,8,5,CONCRETE:7)
Block(-1,8,6,CONCRETE:7)
Block(-1,8,7,CONCRETE:7)
Block(-1,8,8,CONCRETE:7)
Block(-1,9,-7,CONCRETE:8)
Block(-1,9,-6,CONCRETE:8)
Block(-1,9,-5,CONCRETE:8)
Block(-1,9,-4,CONCRETE:8)
Block(-1,9,-3,CONCRETE:8)
Block(-1,9,-2,CONCRETE:8)
Block(-1,9,-1,CONCRETE:8)
Block(-1,9,0,CONCRETE:8)
Block(-1,9,1,CONCRETE:8)
Block(-1,9,2,CONCRETE:8)
Block(-1,9,3,CONCRETE:8)
Block(-1,9,4,CONCRETE:8)
Block(-1,9,5,CONCRETE:8)
Block(-1,9,6,CONCRETE:8)
Block(-1,9,7,CONCRETE:8)
Block(-1,9,8,CONCRETE:8)
Block(-1,10,-7,CONCRETE:8)
Block(-1,10,-6,CONCRETE:8)
Block(-1,10,-5,CONCRETE:8)
Block(-1,10,-4,CONCRETE:8)
Block(-1,10,-3,CONCRETE:8)
Block(-1,10,-2,CONCRETE:8)
Block(-1,10,-1,CONCRETE:8)
Block(-1,10,0,CONCRETE:8)
Block(-1,10,1,CONCRETE:8)
Block(-1,10,2,CONCRETE:8)
Block(-1,10,3,CONCRETE:8)
Block(-1,10,4,CONCRETE:8)
Block(-1,10,5,CONCRETE:8)
Block(-1,10,6,CONCRETE:8)
Block(-1,10,7,CONCRETE:8)
Block(-1,10,8,CONCRETE:8)
Block(-1,11,-7,CONCRETE:8)
Block(-1,11,-6,CONCRETE:8)
Block(-1,11,-5,CONCRETE:8)
Block(-1,11,-4,CONCRETE:8)
Block(-1,11,-3,CONCRETE:8)
Block(-1,11,-2,CONCRETE:8)
Block(-1,11,-1,CONCRETE:8)
Block(-1,11,0,CONCRETE:8)
Block(-1,11,1,CONCRETE:8)
Block(-1,11,2,CONCRETE:8)
Block(-1,11,3,CONCRETE:8)
Block(-1,11,4,CONCRETE:8)
Block(-1,11,5,CONCRETE:8)
Block(-1,11,6,CONCRETE:8)
Block(-1,11,7,CONCRETE:8)
Block(-1,11,8,CONCRETE:8)
Block(-1,12,-7,CONCRETE:8)
Block(-1,12,-6,STATIONARY_WATER:0)
Block(-1,12,-5,STATIONARY_WATER:0)
Block(-1,12,-4,STATIONARY_WATER:0)
Block(-1,12,-3,STATIONARY_WATER:0)
Block(-1,12,-2,STATIONARY_WATER:0)
Block(-1,12,-1,STATIONARY_WATER:0)
Block(-1,12,0,STATIONARY_WATER:0)
Block(-1,12,1,STATIONARY_WATER:0)
Block(-1,12,2,STATIONARY_WATER:0)
Block(-1,12,3,STATIONARY_WATER:0)
Block(-1,12,4,STATIONARY_WATER:0)
Block(-1,12,5,STATIONARY_WATER:0)
Block(-1,12,6,STATIONARY_WATER:0)
Block(-1,12,7,STATIONARY_WATER:0)
Block(-1,12,8,CONCRETE:8)
Block(-1,13,-7,CONCRETE:8)
Block(-1,13,-6,AIR:0)
Block(-1,13,-5,AIR:0)
Block(-1,13,-4,AIR:0)
Block(-1,13,-3,AIR:0)
Block(-1,13,-2,AIR:0)
Block(-1,13,-1,AIR:0)
Block(-1,13,0,AIR:0)
Block(-1,13,1,AIR:0)
Block(-1,13,2,AIR:0)
Block(-1,13,3,AIR:0)
Block(-1,13,4,AIR:0)
Block(-1,13,5,AIR:0)
Block(-1,13,6,AIR:0)
Block(-1,13,7,AIR:0)
Block(-1,13,8,CONCRETE:8)
Block(-1,14,-7,CONCRETE:8)
Block(-1,14,-6,AIR:0)
Block(-1,14,-5,AIR:0)
Block(-1,14,-4,AIR:0)
Block(-1,14,-3,AIR:0)
Block(-1,14,-2,AIR:0)
Block(-1,14,-1,AIR:0)
Block(-1,14,0,AIR:0)
Block(-1,14,1,AIR:0)
Block(-1,14,2,AIR:0)
Block(-1,14,3,AIR:0)
Block(-1,14,4,AIR:0)
Block(-1,14,5,AIR:0)
Block(-1,14,6,AIR:0)
Block(-1,14,7,AIR:0)
Block(-1,14,8,CONCRETE:8)
Block(-1,15,-7,CONCRETE:8)
Block(-1,15,-6,AIR:0)
Block(-1,15,-5,AIR:0)
Block(-1,15,-4,AIR:0)
Block(-1,15,-3,AIR:0)
Block(-1,15,-2,AIR:0)
Block(-1,15,-1,AIR:0)
Block(-1,15,0,AIR:0)
Block(-1,15,1,AIR:0)
Block(-1,15,2,AIR:0)
Block(-1,15,3,AIR:0)
Block(-1,15,4,AIR:0)
Block(-1,15,5,AIR:0)
Block(-1,15,6,AIR:0)
Block(-1,15,7,AIR:0)
Block(-1,15,8,CONCRETE:8)
Block(-1,16,-7,CONCRETE:8)
Block(-1,16,-6,AIR:0)
Block(-1,16,-5,AIR:0)
Block(-1,16,-4,AIR:0)
Block(-1,16,-3,AIR:0)
Block(-1,16,-2,AIR:0)
Block(-1,16,-1,AIR:0)
Block(-1,16,0,AIR:0)
Block(-1,16,1,AIR:0)
Block(-1,16,2,AIR:0)
Block(-1,16,3,AIR:0)
Block(-1,16,4,AIR:0)
Block(-1,16,5,AIR:0)
Block(-1,16,6,AIR:0)
Block(-1,16,7,AIR:0)
Block(-1,16,8,CONCRETE:8)
Block(-1,17,-7,CONCRETE:8)
Block(-1,17,-6,AIR:0)
Block(-1,17,-5,AIR:0)
Block(-1,17,-4,AIR:0)
Block(-1,17,-3,AIR:0)
Block(-1,17,-2,AIR:0)
Block(-1,17,-1,STAINED_GLASS:15)
Block(-1,17,0,CONCRETE:8)
Block(-1,17,1,CONCRETE:8)
Block(-1,17,2,STAINED_GLASS:15)
Block(-1,17,3,AIR:0)
Block(-1,17,4,AIR:0)
Block(-1,17,5,AIR:0)
Block(-1,17,6,AIR:0)
Block(-1,17,7,AIR:0)
Block(-1,17,8,CONCRETE:8)
Block(-1,18,-7,CONCRETE:8)
Block(-1,18,-1,STAINED_GLASS_PANE:15)
Block(-1,18,2,STAINED_GLASS_PANE:15)
Block(-1,18,8,CONCRETE:8)
Block(-1,19,-7,CONCRETE:8)
Block(-1,19,8,CONCRETE:8)
Block(-1,20,-7,CONCRETE:8)
Block(-1,20,8,CONCRETE:8)
Block(-1,21,-7,CONCRETE:8)
Block(-1,21,8,CONCRETE:8)
Block(-1,22,-7,CONCRETE:8)
Block(-1,22,8,CONCRETE:8)
Block(-1,23,-7,CONCRETE:8)
Block(-1,23,8,CONCRETE:8)
Block(-1,24,-7,CONCRETE:8)
Block(-1,24,8,CONCRETE:8)
Block(-1,25,-7,CONCRETE:8)
Block(-1,25,8,CONCRETE:8)
Block(-1,26,-7,CONCRETE:8)
Block(-1,26,8,CONCRETE:8)
Block(-1,27,-7,CONCRETE:8)
Block(-1,27,8,CONCRETE:8)
Block(-1,28,-7,CONCRETE:8)
Block(-1,28,8,CONCRETE:8)
Block(-1,29,-7,CONCRETE:8)
Block(-1,29,8,CONCRETE:8)
Block(-1,30,-7,CONCRETE:8)
Block(-1,30,8,CONCRETE:8)
Block(-1,31,-7,CONCRETE:8)
Block(-1,31,8,CONCRETE:8)
Block(-1,32,-7,CONCRETE:8)
Block(-1,32,8,CONCRETE:8)
Block(-1,33,-7,CONCRETE:8)
Block(-1,33,8,CONCRETE:8)
Block(-1,34,-7,CONCRETE:8)
Block(-1,34,8,CONCRETE:8)
Block(-1,35,-7,CONCRETE:8)
Block(-1,35,8,CONCRETE:8)
Block(-1,36,-7,CONCRETE:8)
Block(-1,36,8,CONCRETE:8)
Block(-1,37,-7,CONCRETE:8)
Block(-1,37,8,CONCRETE:8)
Block(-1,38,-7,CONCRETE:8)
Block(-1,38,8,CONCRETE:8)
Block(-1,39,-7,CONCRETE:8)
Block(-1,39,8,CONCRETE:8)
Block(-1,40,-7,CONCRETE:8)
Block(-1,40,8,CONCRETE:8)
Block(-1,41,-7,CONCRETE:8)
Block(-1,41,8,CONCRETE:8)
Block(-1,42,-7,CONCRETE:8)
Block(-1,42,8,CONCRETE:8)
Block(-1,43,-7,CONCRETE:8)
Block(-1,43,8,CONCRETE:8)
Block(-1,44,-7,CONCRETE:8)
Block(-1,44,8,CONCRETE:8)
Block(-1,45,-7,CONCRETE:8)
Block(-1,45,8,CONCRETE:8)
Block(-1,46,-7,CONCRETE:8)
Block(-1,46,8,CONCRETE:8)
Block(-1,47,-7,CONCRETE:8)
Block(-1,47,8,CONCRETE:8)
Block(-1,48,-7,CONCRETE:8)
Block(-1,48,8,CONCRETE:8)
Block(-1,49,-7,CONCRETE:8)
Block(-1,49,8,CONCRETE:8)
Block(-1,50,-7,CONCRETE:8)
Block(-1,50,8,CONCRETE:8)
Block(-1,51,-7,CONCRETE:8)
Block(-1,51,8,CONCRETE:8)
Block(-1,52,-7,CONCRETE:8)
Block(-1,52,8,CONCRETE:8)
Block(-1,53,-7,CONCRETE:8)
Block(-1,53,8,CONCRETE:8)
Block(-1,54,-7,CONCRETE:8)
Block(-1,54,8,CONCRETE:8)
Block(-1,55,-7,CONCRETE:8)
Block(-1,55,8,CONCRETE:8)
Block(-1,56,-7,CONCRETE:8)
Block(-1,56,8,CONCRETE:8)
Block(-1,57,-7,CONCRETE:8)
Block(-1,57,8,CONCRETE:8)
Block(-1,58,-7,CONCRETE:8)
Block(-1,58,8,CONCRETE:8)
Block(-1,59,-7,CONCRETE:8)
Block(-1,59,8,CONCRETE:8)
Block(-1,60,-7,CONCRETE:8)
Block(-1,60,8,CONCRETE:8)
Block(-1,61,-7,CONCRETE:8)
Block(-1,61,8,CONCRETE:8)
Block(-1,62,-7,CONCRETE:8)
Block(-1,62,8,CONCRETE:8)
Block(-1,63,-7,CONCRETE:8)
Block(-1,63,8,CONCRETE:8)
Block(-1,64,-7,CONCRETE:8)
Block(-1,64,8,CONCRETE:8)
Block(-1,65,-7,CONCRETE:8)
Block(-1,65,8,CONCRETE:8)
Block(-1,66,-7,CONCRETE:8)
Block(-1,66,8,CONCRETE:8)
Block(-1,67,-7,CONCRETE:8)
Block(-1,67,8,CONCRETE:8)
Block(-1,68,-7,CONCRETE:8)
Block(-1,68,8,CONCRETE:8)
Block(-1,69,-7,CONCRETE:8)
Block(-1,69,8,CONCRETE:8)
Block(-1,70,-7,CONCRETE:8)
Block(-1,70,8,CONCRETE:8)
Block(-1,71,-7,CONCRETE:8)
Block(-1,71,8,CONCRETE:8)
Block(-1,72,-7,CONCRETE:8)
Block(-1,72,8,CONCRETE:8)
Block(-1,73,-7,CONCRETE:8)
Block(-1,73,8,CONCRETE:8)
Block(-1,74,-7,CONCRETE:8)
Block(-1,74,8,CONCRETE:8)
Block(-1,75,-7,CONCRETE:8)
Block(-1,75,8,CONCRETE:8)
Block(-1,76,-7,CONCRETE:8)
Block(-1,76,8,CONCRETE:8)
Block(-1,77,-7,CONCRETE:8)
Block(-1,77,8,CONCRETE:8)
Block(-1,78,-7,CONCRETE:8)
Block(-1,78,8,CONCRETE:8)
Block(-1,79,-7,CONCRETE:8)
Block(-1,79,8,CONCRETE:8)
Block(-1,80,-7,CONCRETE:8)
Block(-1,80,8,CONCRETE:8)
Block(-1,81,-7,CONCRETE:8)
Block(-1,81,8,CONCRETE:8)
Block(-1,82,-7,CONCRETE:8)
Block(-1,82,8,CONCRETE:8)
Block(-1,83,-7,CONCRETE:8)
Block(-1,83,8,CONCRETE:8)
Block(-1,84,-7,CONCRETE:8)
Block(-1,84,8,CONCRETE:8)
Block(-1,85,-7,CONCRETE:8)
Block(-1,85,8,CONCRETE:8)
Block(-1,86,-7,CONCRETE:8)
Block(-1,86,8,CONCRETE:8)
Block(-1,87,-7,CONCRETE:8)
Block(-1,87,8,CONCRETE:8)
Block(-1,88,-7,CONCRETE:8)
Block(-1,88,8,CONCRETE:8)
Block(-1,89,-7,CONCRETE:8)
Block(-1,89,8,CONCRETE:8)
Block(-1,90,-7,CONCRETE:8)
Block(-1,90,8,CONCRETE:8)
Block(-1,91,-7,CONCRETE:8)
Block(-1,91,8,CONCRETE:8)
Block(-1,92,-7,CONCRETE:8)
Block(-1,92,8,CONCRETE:8)
Block(-1,93,-7,CONCRETE:8)
Block(-1,93,8,CONCRETE:8)
Block(-1,94,-7,CONCRETE:8)
Block(-1,94,8,CONCRETE:8)
Block(-1,95,-7,CONCRETE:8)
Block(-1,95,8,CONCRETE:8)
Block(-1,96,-7,CONCRETE:8)
Block(-1,96,8,CONCRETE:8)
Block(-1,97,-7,CONCRETE:8)
Block(-1,97,8,CONCRETE:8)
Block(-1,98,-7,CONCRETE:8)
Block(-1,98,8,CONCRETE:8)
Block(-1,99,-7,CONCRETE:8)
Block(-1,99,8,CONCRETE:8)
Block(-1,100,-7,CONCRETE:8)
Block(-1,100,8,CONCRETE:8)
Block(-1,101,-7,CONCRETE:8)
Block(-1,101,8,CONCRETE:8)
Block(-1,102,-7,CONCRETE:8)
Block(-1,102,8,CONCRETE:8)
Block(-1,103,-7,CONCRETE:8)
Block(-1,103,8,CONCRETE:8)
Block(-1,104,-7,CONCRETE:8)
Block(-1,104,8,CONCRETE:8)
Block(-1,105,-7,CONCRETE:8)
Block(-1,105,8,CONCRETE:8)
Block(-1,106,-7,CONCRETE:8)
Block(-1,106,8,CONCRETE:8)
Block(-1,107,-7,CONCRETE:8)
Block(-1,107,8,CONCRETE:8)
Block(-1,108,-7,CONCRETE:8)
Block(-1,108,8,CONCRETE:8)
Block(-1,109,-7,CONCRETE:8)
Block(-1,109,8,CONCRETE:8)
Block(-1,110,-7,CONCRETE:8)
Block(-1,110,8,CONCRETE:8)
Block(-1,111,-7,CONCRETE:8)
Block(-1,111,8,CONCRETE:8)
Block(-1,112,-7,CONCRETE:8)
Block(-1,112,8,CONCRETE:8)
Block(-1,113,-7,CONCRETE:8)
Block(-1,113,8,CONCRETE:8)
Block(-1,114,-7,CONCRETE:8)
Block(-1,114,8,CONCRETE:8)
Block(-1,115,-7,CONCRETE:8)
Block(-1,115,8,CONCRETE:8)
Block(-1,116,-7,CONCRETE:8)
Block(-1,116,8,CONCRETE:8)
Block(-1,117,-7,CONCRETE:8)
Block(-1,117,8,CONCRETE:8)
Block(-1,118,-7,CONCRETE:8)
Block(-1,118,8,CONCRETE:8)
Block(-1,119,-7,CONCRETE:8)
Block(-1,119,8,CONCRETE:8)
Block(-1,120,-7,CONCRETE:8)
Block(-1,120,8,CONCRETE:8)
Block(-1,121,-7,CONCRETE:8)
Block(-1,121,8,CONCRETE:8)
Block(-1,122,-7,CONCRETE:8)
Block(-1,122,8,CONCRETE:8)
Block(-1,123,-7,CONCRETE:8)
Block(-1,123,8,CONCRETE:8)
Block(-1,124,-7,CONCRETE:8)
Block(-1,124,8,CONCRETE:8)
Block(-1,125,-7,CONCRETE:8)
Block(-1,125,8,CONCRETE:8)
Block(-1,126,-7,CONCRETE:8)
Block(-1,126,8,CONCRETE:8)
Block(-1,127,-7,CONCRETE:8)
Block(-1,127,8,CONCRETE:8)
Block(-1,128,-7,CONCRETE:8)
Block(-1,128,8,CONCRETE:8)
Block(-1,129,-7,CONCRETE:8)
Block(-1,129,8,CONCRETE:8)
Block(-1,130,-7,CONCRETE:8)
Block(-1,130,8,CONCRETE:8)
Block(-1,131,-7,CONCRETE:8)
Block(-1,131,8,CONCRETE:8)
Block(-1,132,-7,CONCRETE:8)
Block(-1,132,8,CONCRETE:8)
Block(-1,133,-7,CONCRETE:8)
Block(-1,133,8,CONCRETE:8)
Block(-1,134,-7,CONCRETE:8)
Block(-1,134,8,CONCRETE:8)
Block(-1,135,-7,CONCRETE:8)
Block(-1,135,8,CONCRETE:8)
Block(-1,136,-7,CONCRETE:8)
Block(-1,136,8,CONCRETE:8)
Block(-1,137,-7,CONCRETE:8)
Block(-1,137,8,CONCRETE:8)
Block(-1,138,-7,CONCRETE:8)
Block(-1,138,8,CONCRETE:8)
Block(-1,139,-7,CONCRETE:8)
Block(-1,139,8,CONCRETE:8)
Block(-1,140,-7,CONCRETE:8)
