
#######################################################################
# +-----------------------------------------------------------------+ #
# |                            BO4 object                           | #
# +-----------------------------------------------------------------+ #
#######################################################################

Author: NLBlackEagle

Description: No description given

SettingsMode: WriteDisable


#######################################################################
# +-----------------------------------------------------------------+ #
# |                          Main settings                          | #
# +-----------------------------------------------------------------+ #
#######################################################################

Frequency: 0

SpawnHeight: highestBlock

UseCenterForHighestBlock: true

##############################
# Height Limits for the BO4. #
##############################

MinHeight: 0

MaxHeight: 255

InheritBO3: 

InheritBO3Rotation: NORTH

OverrideChildSettings: true

OverrideParentHeight: false

CanOverride: true

BranchFrequency: 0

BranchFrequencyGroup: 

MustBeBelowOther: false

MustBeInside: 

CannotBeInside: 

ReplacesBO3: L4-M-CrossC0R0, L4-M-CrossC0R1, L4-M-CrossC0R2, L4-M-CrossC0R3, L4-M-CrossC1R0, L4-M-CrossC1R1, L4-M-CrossC1R2, L4-M-CrossC1R3, L4-M-CrossC2R0, L4-M-CrossC2R1, L4-M-CrossC2R2, L4-M-CrossC2R3, L4-M-CrossC3R0, L4-M-CrossC3R1, L4-M-CrossC3R2, L4-M-CrossC3R3, L4-M-Straigth-START_01-C0R0, L4-M-Straigth-START_01-C0R1, L4-M-Straigth-START_01-C1R0, L4-M-Straigth-START_01-C1R1, L4-M-Straigth-START_01-C2R0, L4-M-Straigth-START_01-C2R1, L4-M-Straigth-START_01-C3R0, L4-M-Straigth-START_01-C3R1, L4-M-Straigth-3CC0R0, L4-M-Straigth-3CC0R1, L4-M-Straigth-3CC0R2, L4-M-Straigth-3CC1R0, L4-M-Straigth-3CC1R1, L4-M-Straigth-3CC1R2, L4-M-Straigth-3CC2R0, L4-M-Straigth-3CC2R1, L4-M-Straigth-3CC2R2, L4-M-Straigth-3CC3R0, L4-M-Straigth-3CC3R1, L4-M-Straigth-3CC3R2, L4-M-Cross, skyscraper_2x2_01, skyscraper_2x2_02, skyscraper_2x2_03, skyscraper_2x2_04, skyscraper_2x2_05, skyscraper_3x3_01, skyscraper_3x3_02, skyscraper_3x3_03, L3-M-Straigth-2CC0R0, L3-M-Straigth-2CC0R1, L3-M-Straigth-2CC1R0, L3-M-Straigth-2CC1R1, L3-M-Straigth-2CC2R0, L3-M-Straigth-2CC2R1, L3-M-Straigth-2CC3R0, L3-M-Straigth-2CC3R1, L3-M-Straigth-3CC0R0, L3-M-Straigth-3CC0R1, L3-M-Straigth-3CC0R2, L3-M-Straigth-3CC1R0, L3-M-Straigth-3CC1R1, L3-M-Straigth-3CC1R2, L3-M-Straigth-3CC2R0, L3-M-Straigth-3CC2R1, L3-M-Straigth-3CC2R2, L3-M-Straigth-3CC3R0, L3-M-Straigth-3CC3R1, L3-M-Straigth-3CC3R2L4-M-CrossC0R0, L4-M-CrossC0R1, L4-M-CrossC0R2, L4-M-CrossC0R3, L4-M-CrossC1R0, L4-M-CrossC1R1, L4-M-CrossC1R2, L4-M-CrossC1R3, L4-M-CrossC2R0, L4-M-CrossC2R1, L4-M-CrossC2R2, L4-M-CrossC2R3, L4-M-CrossC3R0, L4-M-CrossC3R1, L4-M-CrossC3R2, L4-M-CrossC3R3, L4-M-Straigth-START_01-C0R0, L4-M-Straigth-START_01-C0R1, L4-M-Straigth-START_01-C1R0, L4-M-Straigth-START_01-C1R1, L4-M-Straigth-START_01-C2R0, L4-M-Straigth-START_01-C2R1, L4-M-Straigth-START_01-C3R0, L4-M-Straigth-START_01-C3R1, L4-M-Straigth-3CC0R0, L4-M-Straigth-3CC0R1, L4-M-Straigth-3CC0R2, L4-M-Straigth-3CC1R0, L4-M-Straigth-3CC1R1, L4-M-Straigth-3CC1R2, L4-M-Straigth-3CC2R0, L4-M-Straigth-3CC2R1, L4-M-Straigth-3CC2R2, L4-M-Straigth-3CC3R0, L4-M-Straigth-3CC3R1, L4-M-Straigth-3CC3R2, L4-M-Cross, skyscraper_2x2_01, skyscraper_2x2_02, skyscraper_2x2_03, skyscraper_2x2_04, skyscraper_2x2_05, skyscraper_3x3_01, skyscraper_3x3_02, skyscraper_3x3_03

MustBeInsideWorldBorders: false

CanSpawnOnWater: true

SpawnOnWaterOnly: false

SpawnUnderWater: false

SpawnAtWaterLevel: false

HeightOffset: 0

RemoveAir: false

ReplaceAbove: 

ReplaceBelow: 

ReplaceWithBiomeBlocks: true

ReplaceWithSurfaceBlock: GRASS

ReplaceWithGroundBlock: DIRT

ReplaceWithStoneBlock: STONE

SmoothRadius: 0

SmoothHeightOffset: 0

SmoothStartTop: false

SmoothStartWood: false

SmoothingSurfaceBlock: 

SmoothingGroundBlock: 

BO3Group: 

IsSpawnPoint: false

DoReplaceBlocks: true


#######################################################################
# +-----------------------------------------------------------------+ #
# |                              Blocks                             | #
# +-----------------------------------------------------------------+ #
#######################################################################

Block(-8,0,-7,CONCRETE:7)
Block(-8,0,-6,CONCRETE:7)
Block(-8,0,-5,CONCRETE:7)
Block(-8,0,-4,CONCRETE:7)
Block(-8,0,-3,CONCRETE:7)
Block(-8,0,-2,CONCRETE:7)
Block(-8,0,-1,CONCRETE:7)
Block(-8,0,0,CONCRETE:7)
Block(-8,0,1,CONCRETE:7)
Block(-8,0,2,CONCRETE:7)
Block(-8,0,3,CONCRETE:7)
Block(-8,0,4,CONCRETE:7)
Block(-8,0,5,CONCRETE:7)
Block(-8,0,6,CONCRETE:7)
Block(-8,0,7,CONCRETE:7)
Block(-8,0,8,CONCRETE:7)
Block(-8,1,-7,CONCRETE:7)
Block(-8,1,-6,CONCRETE:7)
Block(-8,1,-5,CONCRETE:7)
Block(-8,1,-4,CONCRETE:7)
Block(-8,1,-3,CONCRETE:7)
Block(-8,1,-2,CONCRETE:7)
Block(-8,1,-1,CONCRETE:7)
Block(-8,1,0,CONCRETE:7)
Block(-8,1,1,CONCRETE:7)
Block(-8,1,2,CONCRETE:7)
Block(-8,1,3,CONCRETE:7)
Block(-8,1,4,CONCRETE:7)
Block(-8,1,5,CONCRETE:7)
Block(-8,1,6,CONCRETE:7)
Block(-8,1,7,CONCRETE:7)
Block(-8,1,8,CONCRETE:7)
Block(-8,2,-7,CONCRETE:7)
Block(-8,2,-6,CONCRETE:7)
Block(-8,2,-5,CONCRETE:7)
Block(-8,2,-4,CONCRETE:7)
Block(-8,2,-3,CONCRETE:7)
Block(-8,2,-2,CONCRETE:7)
Block(-8,2,-1,CONCRETE:7)
Block(-8,2,0,CONCRETE:7)
Block(-8,2,1,CONCRETE:7)
Block(-8,2,2,CONCRETE:7)
Block(-8,2,3,CONCRETE:7)
Block(-8,2,4,CONCRETE:7)
Block(-8,2,5,CONCRETE:7)
Block(-8,2,6,CONCRETE:7)
Block(-8,2,7,CONCRETE:7)
Block(-8,2,8,CONCRETE:7)
Block(-8,3,-7,CONCRETE:7)
Block(-8,3,-6,CONCRETE:7)
Block(-8,3,-5,CONCRETE:7)
Block(-8,3,-4,CONCRETE:7)
Block(-8,3,-3,CONCRETE:7)
Block(-8,3,-2,CONCRETE:7)
Block(-8,3,-1,CONCRETE:7)
Block(-8,3,0,CONCRETE:7)
Block(-8,3,1,CONCRETE:7)
Block(-8,3,2,CONCRETE:7)
Block(-8,3,3,CONCRETE:7)
Block(-8,3,4,CONCRETE:7)
Block(-8,3,5,CONCRETE:7)
Block(-8,3,6,CONCRETE:7)
Block(-8,3,7,CONCRETE:7)
Block(-8,3,8,CONCRETE:7)
Block(-8,4,-7,CONCRETE:7)
Block(-8,4,-6,CONCRETE:7)
Block(-8,4,-5,CONCRETE:7)
Block(-8,4,-4,CONCRETE:7)
Block(-8,4,-3,CONCRETE:7)
Block(-8,4,-2,CONCRETE:7)
Block(-8,4,-1,CONCRETE:7)
Block(-8,4,0,CONCRETE:7)
Block(-8,4,1,CONCRETE:7)
Block(-8,4,2,CONCRETE:7)
Block(-8,4,3,CONCRETE:7)
Block(-8,4,4,CONCRETE:7)
Block(-8,4,5,CONCRETE:7)
Block(-8,4,6,CONCRETE:7)
Block(-8,4,7,CONCRETE:7)
Block(-8,4,8,CONCRETE:7)
Block(-8,5,-7,CONCRETE:7)
Block(-8,5,-6,CONCRETE:7)
Block(-8,5,-5,CONCRETE:7)
Block(-8,5,-4,CONCRETE:7)
Block(-8,5,-3,CONCRETE:7)
Block(-8,5,-2,CONCRETE:7)
Block(-8,5,-1,CONCRETE:7)
Block(-8,5,0,CONCRETE:7)
Block(-8,5,1,CONCRETE:7)
Block(-8,5,2,CONCRETE:7)
Block(-8,5,3,CONCRETE:7)
Block(-8,5,4,CONCRETE:7)
Block(-8,5,5,CONCRETE:7)
Block(-8,5,6,CONCRETE:7)
Block(-8,5,7,CONCRETE:7)
Block(-8,5,8,CONCRETE:7)
Block(-8,6,-7,CONCRETE:7)
Block(-8,6,-6,CONCRETE:7)
Block(-8,6,-5,CONCRETE:7)
Block(-8,6,-4,CONCRETE:7)
Block(-8,6,-3,CONCRETE:7)
Block(-8,6,-2,CONCRETE:7)
Block(-8,6,-1,CONCRETE:7)
Block(-8,6,0,CONCRETE:7)
Block(-8,6,1,CONCRETE:7)
Block(-8,6,2,CONCRETE:7)
Block(-8,6,3,CONCRETE:7)
Block(-8,6,4,CONCRETE:7)
Block(-8,6,5,CONCRETE:7)
Block(-8,6,6,CONCRETE:7)
Block(-8,6,7,CONCRETE:7)
Block(-8,6,8,CONCRETE:7)
Block(-8,7,-7,CONCRETE:7)
Block(-8,7,-6,CONCRETE:7)
Block(-8,7,-5,CONCRETE:7)
Block(-8,7,-4,CONCRETE:7)
Block(-8,7,-3,CONCRETE:7)
Block(-8,7,-2,CONCRETE:7)
Block(-8,7,-1,CONCRETE:7)
Block(-8,7,0,CONCRETE:7)
Block(-8,7,1,CONCRETE:7)
Block(-8,7,2,CONCRETE:7)
Block(-8,7,3,CONCRETE:7)
Block(-8,7,4,CONCRETE:7)
Block(-8,7,5,CONCRETE:7)
Block(-8,7,6,CONCRETE:7)
Block(-8,7,7,CONCRETE:7)
Block(-8,7,8,CONCRETE:7)
Block(-8,8,-7,CONCRETE:7)
Block(-8,8,-6,CONCRETE:7)
Block(-8,8,-5,CONCRETE:7)
Block(-8,8,-4,CONCRETE:7)
Block(-8,8,-3,CONCRETE:7)
Block(-8,8,-2,CONCRETE:7)
Block(-8,8,-1,CONCRETE:7)
Block(-8,8,0,CONCRETE:7)
Block(-8,8,1,CONCRETE:7)
Block(-8,8,2,CONCRETE:7)
Block(-8,8,3,CONCRETE:7)
Block(-8,8,4,CONCRETE:7)
Block(-8,8,5,CONCRETE:7)
Block(-8,8,6,CONCRETE:7)
Block(-8,8,7,CONCRETE:7)
Block(-8,8,8,CONCRETE:7)
Block(-8,9,-7,CONCRETE:7)
Block(-8,9,-6,CONCRETE:7)
Block(-8,9,-5,CONCRETE:7)
Block(-8,9,-4,CONCRETE:7)
Block(-8,9,-3,CONCRETE:7)
Block(-8,9,-2,CONCRETE:7)
Block(-8,9,-1,CONCRETE:7)
Block(-8,9,0,CONCRETE:7)
Block(-8,9,1,CONCRETE:7)
Block(-8,9,2,CONCRETE:7)
Block(-8,9,3,CONCRETE:7)
Block(-8,9,4,CONCRETE:7)
Block(-8,9,5,CONCRETE:7)
Block(-8,9,6,CONCRETE:7)
Block(-8,9,7,CONCRETE:7)
Block(-8,9,8,CONCRETE:7)
Block(-8,10,-7,CONCRETE:7)
Block(-8,10,-6,CONCRETE:7)
Block(-8,10,-5,CONCRETE:7)
Block(-8,10,-4,CONCRETE:7)
Block(-8,10,-3,CONCRETE:7)
Block(-8,10,-2,CONCRETE:7)
Block(-8,10,-1,CONCRETE:7)
Block(-8,10,0,CONCRETE:7)
Block(-8,10,1,CONCRETE:7)
Block(-8,10,2,CONCRETE:7)
Block(-8,10,3,CONCRETE:7)
Block(-8,10,4,CONCRETE:7)
Block(-8,10,5,CONCRETE:7)
Block(-8,10,6,CONCRETE:7)
Block(-8,10,7,CONCRETE:7)
Block(-8,10,8,CONCRETE:7)
Block(-8,11,-7,CONCRETE:7)
Block(-8,11,-6,CONCRETE:7)
Block(-8,11,-5,CONCRETE:7)
Block(-8,11,-4,CONCRETE:7)
Block(-8,11,-3,CONCRETE:7)
Block(-8,11,-2,CONCRETE:7)
Block(-8,11,-1,CONCRETE:7)
Block(-8,11,0,CONCRETE:7)
Block(-8,11,1,CONCRETE:7)
Block(-8,11,2,CONCRETE:7)
Block(-8,11,3,CONCRETE:7)
Block(-8,11,4,CONCRETE:7)
Block(-8,11,5,CONCRETE:7)
Block(-8,11,6,CONCRETE:7)
Block(-8,11,7,CONCRETE:7)
Block(-8,11,8,CONCRETE:7)
Block(-8,12,-7,CONCRETE:7)
Block(-8,12,-6,CONCRETE:7)
Block(-8,12,-5,CONCRETE:7)
Block(-8,12,-4,CONCRETE:7)
Block(-8,12,-3,CONCRETE:7)
Block(-8,12,-2,CONCRETE:7)
Block(-8,12,-1,CONCRETE:7)
Block(-8,12,0,CONCRETE:7)
Block(-8,12,1,CONCRETE:7)
Block(-8,12,2,CONCRETE:7)
Block(-8,12,3,CONCRETE:7)
Block(-8,12,4,CONCRETE:7)
Block(-8,12,5,CONCRETE:7)
Block(-8,12,6,CONCRETE:7)
Block(-8,12,7,CONCRETE:7)
Block(-8,12,8,CONCRETE:7)
Block(-8,13,-7,CONCRETE:8)
Block(-8,13,-6,CONCRETE:8)
Block(-8,13,-5,CONCRETE:8)
Block(-8,13,-4,CONCRETE:8)
Block(-8,13,-3,CONCRETE:8)
Block(-8,13,-2,CONCRETE:8)
Block(-8,13,-1,CONCRETE:8)
Block(-8,13,0,CONCRETE:8)
Block(-8,13,1,CONCRETE:8)
Block(-8,13,2,CONCRETE:8)
Block(-8,13,3,CONCRETE:8)
Block(-8,13,4,CONCRETE:8)
Block(-8,13,5,CONCRETE:8)
Block(-8,13,6,CONCRETE:8)
Block(-8,13,7,CONCRETE:8)
Block(-8,13,8,CONCRETE:8)
Block(-8,14,-7,CONCRETE:8)
Block(-8,14,-6,CONCRETE:8)
Block(-8,14,-5,AIR:0)
Block(-8,14,-4,AIR:0)
Block(-8,14,-3,AIR:0)
Block(-8,14,-2,CONCRETE:8)
Block(-8,14,-1,CONCRETE:8)
Block(-8,14,0,CONCRETE:8)
Block(-8,14,1,CONCRETE:8)
Block(-8,14,2,CONCRETE:8)
Block(-8,14,3,CONCRETE:8)
Block(-8,14,4,CONCRETE:8)
Block(-8,14,5,CONCRETE:8)
Block(-8,14,6,AIR:0)
Block(-8,14,7,CONCRETE:8)
Block(-8,14,8,IRON_TRAPDOOR:9)
Block(-8,15,-7,CONCRETE:7)
Block(-8,15,-6,CONCRETE:7)
Block(-8,15,-5,AIR:0)
Block(-8,15,-4,AIR:0)
Block(-8,15,-3,AIR:0)
Block(-8,15,-2,CONCRETE:7)
Block(-8,15,-1,CONCRETE:7)
Block(-8,15,0,CONCRETE:7)
Block(-8,15,1,CONCRETE:7)
Block(-8,15,2,CONCRETE:7)
Block(-8,15,3,CONCRETE:7)
Block(-8,15,4,CONCRETE:7)
Block(-8,15,5,CONCRETE:7)
Block(-8,15,6,AIR:0)
Block(-8,15,7,CONCRETE:7)
Block(-8,15,8,IRON_TRAPDOOR:9)
Block(-8,16,-7,CONCRETE:7)
Block(-8,16,-6,CONCRETE:7)
Block(-8,16,-5,AIR:0)
Block(-8,16,-4,AIR:0)
Block(-8,16,-3,AIR:0)
Block(-8,16,-2,CONCRETE:7)
Block(-8,16,-1,CONCRETE:7)
Block(-8,16,0,CONCRETE:7)
Block(-8,16,1,CONCRETE:7)
Block(-8,16,2,CONCRETE:7)
Block(-8,16,3,CONCRETE:7)
Block(-8,16,4,CONCRETE:7)
Block(-8,16,5,CONCRETE:7)
Block(-8,16,6,AIR:0)
Block(-8,16,7,CONCRETE:7)
Block(-8,16,8,AIR:0)
Block(-8,17,-7,CONCRETE:7)
Block(-8,17,-6,CONCRETE:7)
Block(-8,17,-5,CONCRETE:7)
Block(-8,17,-4,CONCRETE:7)
Block(-8,17,-3,CONCRETE:7)
Block(-8,17,-2,CONCRETE:7)
Block(-8,17,-1,CONCRETE:7)
Block(-8,17,0,CONCRETE:7)
Block(-8,17,1,CONCRETE:7)
Block(-8,17,2,CONCRETE:7)
Block(-8,17,3,CONCRETE:7)
Block(-8,17,4,CONCRETE:7)
Block(-8,17,5,CONCRETE:7)
Block(-8,17,6,CONCRETE:7)
Block(-8,17,7,CONCRETE:7)
Block(-8,17,8,CONCRETE:7)
Block(-8,18,0,CARPET:8)
Block(-8,18,1,CARPET:8)
Block(-8,18,2,CARPET:8)
Block(-8,21,6,TRAP_DOOR:6)
Block(-8,25,-7,CONCRETE:15)
Block(-8,25,-6,CONCRETE:15)
Block(-8,25,-5,CONCRETE:15)
Block(-8,25,-4,CONCRETE:15)
Block(-8,25,-3,CONCRETE:15)
Block(-8,25,-2,CONCRETE:15)
Block(-8,25,-1,CONCRETE:15)
Block(-8,25,0,CONCRETE:15)
Block(-8,25,1,CONCRETE:15)
Block(-8,25,2,CONCRETE:15)
Block(-8,25,3,CONCRETE:15)
Block(-8,25,4,CONCRETE:15)
Block(-8,25,5,CONCRETE:15)
Block(-8,25,6,CONCRETE:15)
Block(-8,25,7,CONCRETE:15)
Block(-8,25,8,CONCRETE:15)
Block(-8,26,-6,CARPET:13)
Block(-8,26,-4,CONCRETE:0)
Block(-8,26,-3,BOOKSHELF:0)
Block(-8,26,-2,BOOKSHELF:0)
Block(-8,26,-1,BOOKSHELF:0)
Block(-8,26,0,BOOKSHELF:0)
Block(-8,26,1,CONCRETE:0)
#RandomBlock(-8,26,2,TRAPPED_CHEST:5,../../../../../Chests/Loot/ModernCityJunk_1.nbt,65,CHEST:5,../../../../../Chests/Loot/ModernCityJunk_1.nbt,20,CHEST:5,../../../../../Chests/Loot/ModernCityJunk_2.nbt,15,CHEST:5,../../../../../Chests/Loot/ModernCityJunk_3.nbt,15,CHEST:5,../../../../../Chests/Loot/ModernCityJunk_4.nbt,15,CHEST:5,../../../../../Chests/Loot/ModernCityJunk_5.nbt,15,CHEST:5,../../../../../Chests/Loot/ModernCityCommon_1.nbt,5,CHEST:5,../../../../../Chests/Loot/ModernCityCommon_2.nbt,5,CHEST:5,../../../../../Chests/Loot/ModernCityCommon_3.nbt,5,CHEST:5,../../../../../Chests/Loot/ModernCityCommon_4.nbt,5,CHEST:5,../../../../../Chests/Loot/ModernCityCommon_5.nbt,5,CHEST:5,../../../../../Chests/Loot/ModernCityGood_1.nbt,3,CHEST:5,../../../../../Chests/Loot/ModernCityGood_2.nbt,3,CHEST:5,../../../../../Chests/Loot/ModernCityGood_3.nbt,3,CHEST:5,../../../../../Chests/Loot/ModernCityGood_4.nbt,3,CHEST:5,../../../../../Chests/Loot/ModernCityGood_5.nbt,3,CHEST:5,../../../../../Chests/Loot/ModernCityEpic_1.nbt,1,CHEST:5,../../../../../Chests/Loot/ModernCityEpic_2.nbt,1,CHEST:5,../../../../../Chests/Loot/ModernCityEpic_3.nbt,1,CHEST:5,../../../../../Chests/Loot/ModernCityEpic_4.nbt,1,CHEST:5,../../../../../Chests/Loot/ModernCityEpic_5.nbt,1,CHEST:5,../../../../../Chests/Loot/Common1.nbt,25,CHEST:5,../../../../../Chests/Loot/Common2.nbt,25,CHEST:5,../../../../../Chests/Loot/Common3.nbt,25,CHEST:5,../../../../../Chests/Loot/Common4.nbt,25,CHEST:5,../../../../../Chests/Loot/Common5.nbt,25,CHEST:5,../../../../../Chests/Loot/Common6.nbt,25,CHEST:5,../../../../../Chests/Loot/Common7.nbt,25,CHEST:5,../../../../../Chests/Loot/Common8.nbt,25,CHEST:5,../../../../../Chests/Loot/Common9.nbt,25,CHEST:5,../../../../../Chests/Loot/Common10.nbt,25,CHEST:5,../../../../../Chests/Loot/Common11.nbt,25,CHEST:5,../../../../../Chests/Loot/Common12.nbt,25,CHEST:5,../../../../../Chests/Loot/Common13.nbt,25,CHEST:5,../../../../../Chests/Loot/Common14.nbt,25,CHEST:5,../../../../../Chests/Loot/Common15.nbt,25,CHEST:5,../../../../../Chests/Loot/Rare1.nbt,10,CHEST:5,../../../../../Chests/Loot/Rare2.nbt,10,CHEST:5,../../../../../Chests/Loot/Rare3.nbt,10,CHEST:5,../../../../../Chests/Loot/Rare4.nbt,10,CHEST:5,../../../../../Chests/Loot/Rare5.nbt,10,CHEST:5,../../../../../Chests/Loot/Rare6.nbt,10,CHEST:5,../../../../../Chests/Loot/Rare7.nbt,10,CHEST:5,../../../../../Chests/Loot/Rare8.nbt,10,CHEST:5,../../../../../Chests/Loot/Rare9.nbt,10,CHEST:5,../../../../../Chests/Loot/Rare10.nbt,10,CHEST:5,../../../../../Chests/Loot/Rare11.nbt,10,CHEST:5,../../../../../Chests/Loot/Rare12.nbt,10,CHEST:5,../../../../../Chests/Loot/Rare13.nbt,10,CHEST:5,../../../../../Chests/Loot/Rare14.nbt,10,CHEST:5,../../../../../Chests/Loot/Rare15.nbt,10,CHEST:5,../../../../../Chests/Loot/Epic1.nbt,1,CHEST:5,../../../../../Chests/Loot/Epic2.nbt,1,CHEST:5,../../../../../Chests/Loot/Epic3.nbt,1,CHEST:5,../../../../../Chests/Loot/Epic4.nbt,1,CHEST:5,../../../../../Chests/Loot/Epic5.nbt,1,CHEST:5,../../../../../Chests/Loot/Epic6.nbt,1,CHEST:5,../../../../../Chests/Loot/Epic7.nbt,1,CHEST:5,../../../../../Chests/Loot/Epic8.nbt,1,CHEST:5,../../../../../Chests/Loot/Epic9.nbt,1,CHEST:5,../../../../../Chests/Loot/Epic10.nbt,1,CHEST:5,../../../../../Chests/Loot/Epic11.nbt,1,CHEST:5,../../../../../Chests/Loot/Epic12.nbt,1,CHEST:5,../../../../../Chests/Loot/Epic13.nbt,1,CHEST:5,../../../../../Chests/Loot/Epic14.nbt,1,CHEST:5,../../../../../Chests/Loot/Epic15.nbt,1,CHEST:5,../../../../../Chests/Loot/ModernCityJunk_1.nbt,100)
Block(-8,26,3,BOOKSHELF:0)
Block(-8,26,4,BOOKSHELF:0)
Block(-8,26,5,BOOKSHELF:0)
Block(-8,26,6,CONCRETE:0)
Block(-8,26,8,CARPET:13)
Block(-8,27,-4,CONCRETE:0)
Block(-8,27,-3,TRAP_DOOR:3)
Block(-8,27,-2,TRAP_DOOR:3)
Block(-8,27,-1,TRAP_DOOR:3)
Block(-8,27,0,TRAP_DOOR:3)
Block(-8,27,1,CONCRETE:0)
Block(-8,27,2,TRAP_DOOR:1)
Block(-8,27,3,TRAP_DOOR:3)
Block(-8,27,4,TRAP_DOOR:3)
Block(-8,27,5,TRAP_DOOR:3)
Block(-8,27,6,CONCRETE:0)
Block(-8,28,-4,CONCRETE:0)
Block(-8,28,1,CONCRETE:0)
Block(-8,28,6,CONCRETE:0)
Block(-8,29,-7,CONCRETE:15)
Block(-8,29,-6,CONCRETE:15)
Block(-8,29,-5,CONCRETE:15)
Block(-8,29,-4,CONCRETE:15)
Block(-8,29,-3,CONCRETE:15)
Block(-8,29,-2,CONCRETE:15)
Block(-8,29,-1,CONCRETE:15)
Block(-8,29,0,CONCRETE:15)
Block(-8,29,1,CONCRETE:15)
Block(-8,29,2,CONCRETE:15)
Block(-8,29,3,CONCRETE:15)
Block(-8,29,4,CONCRETE:15)
Block(-8,29,5,CONCRETE:15)
Block(-8,29,6,CONCRETE:15)
Block(-8,29,7,CONCRETE:15)
Block(-8,29,8,CONCRETE:15)
Block(-8,30,-7,CARPET:0)
Block(-8,30,-6,CARPET:11)
Block(-8,30,-5,CARPET:11)
Block(-8,30,-4,CARPET:0)
Block(-8,30,0,TRAP_DOOR:4)
Block(-8,30,1,BIRCH_WOOD_STAIRS:0)
Block(-8,30,2,TRAP_DOOR:5)
Block(-8,33,-7,CONCRETE:15)
Block(-8,33,-6,CONCRETE:15)
Block(-8,33,-5,CONCRETE:15)
Block(-8,33,-4,CONCRETE:15)
Block(-8,33,-3,CONCRETE:15)
Block(-8,33,-2,CONCRETE:15)
Block(-8,33,-1,CONCRETE:15)
Block(-8,33,0,CONCRETE:15)
Block(-8,33,1,CONCRETE:15)
Block(-8,33,2,CONCRETE:15)
Block(-8,33,3,CONCRETE:15)
Block(-8,33,4,CONCRETE:15)
Block(-8,33,5,CONCRETE:15)
Block(-8,33,6,CONCRETE:15)
Block(-8,33,7,CONCRETE:15)
Block(-8,33,8,CONCRETE:15)
Block(-8,37,-7,CONCRETE:15)
Block(-8,37,-6,CONCRETE:15)
Block(-8,37,-5,CONCRETE:15)
Block(-8,37,-4,CONCRETE:15)
Block(-8,37,-3,CONCRETE:15)
Block(-8,37,-2,CONCRETE:15)
Block(-8,37,-1,CONCRETE:15)
Block(-8,37,0,CONCRETE:15)
Block(-8,37,1,CONCRETE:15)
Block(-8,37,2,CONCRETE:15)
Block(-8,37,3,CONCRETE:15)
Block(-8,37,4,CONCRETE:15)
Block(-8,37,5,CONCRETE:15)
Block(-8,37,6,CONCRETE:15)
Block(-8,37,7,CONCRETE:15)
Block(-8,37,8,CONCRETE:15)
Block(-8,38,-2,CARPET:0)
Block(-8,38,-1,CARPET:9)
Block(-8,38,0,CARPET:0)
Block(-8,38,1,CARPET:9)
Block(-8,38,2,CARPET:0)
Block(-8,38,3,CARPET:9)
Block(-8,38,4,CARPET:0)
Block(-8,41,-7,CONCRETE:15)
Block(-8,41,-6,CONCRETE:15)
Block(-8,41,-5,CONCRETE:15)
Block(-8,41,-4,CONCRETE:15)
Block(-8,41,-3,CONCRETE:15)
Block(-8,41,-2,CONCRETE:15)
Block(-8,41,-1,CONCRETE:15)
Block(-8,41,0,CONCRETE:15)
Block(-8,41,1,CONCRETE:15)
Block(-8,41,2,CONCRETE:15)
Block(-8,41,3,CONCRETE:15)
Block(-8,41,4,CONCRETE:15)
Block(-8,41,5,CONCRETE:15)
Block(-8,41,6,CONCRETE:15)
Block(-8,41,7,CONCRETE:15)
Block(-8,41,8,CONCRETE:15)
Block(-8,45,-7,CONCRETE:15)
Block(-8,45,-6,CONCRETE:15)
Block(-8,45,-5,CONCRETE:15)
Block(-8,45,-4,CONCRETE:15)
Block(-8,45,-3,CONCRETE:15)
Block(-8,45,-2,CONCRETE:15)
Block(-8,45,-1,CONCRETE:15)
Block(-8,45,0,CONCRETE:15)
Block(-8,45,1,CONCRETE:15)
Block(-8,45,2,CONCRETE:15)
Block(-8,45,3,CONCRETE:15)
Block(-8,45,4,CONCRETE:15)
Block(-8,45,5,CONCRETE:15)
Block(-8,45,6,CONCRETE:15)
Block(-8,45,7,CONCRETE:15)
Block(-8,45,8,CONCRETE:15)
Block(-8,46,-2,CARPET:0)
Block(-8,46,-1,CARPET:9)
Block(-8,46,0,CARPET:0)
Block(-8,46,1,CARPET:9)
Block(-8,46,2,CARPET:0)
Block(-8,46,3,CARPET:9)
Block(-8,46,4,CARPET:0)
Block(-8,49,-7,CONCRETE:15)
Block(-8,49,-6,CONCRETE:15)
Block(-8,49,-5,CONCRETE:15)
Block(-8,49,-4,CONCRETE:15)
Block(-8,49,-3,CONCRETE:15)
Block(-8,49,-2,CONCRETE:15)
Block(-8,49,-1,CONCRETE:15)
Block(-8,49,0,CONCRETE:15)
Block(-8,49,1,CONCRETE:15)
Block(-8,49,2,CONCRETE:15)
Block(-8,49,3,CONCRETE:15)
Block(-8,49,4,CONCRETE:15)
Block(-8,49,5,CONCRETE:15)
Block(-8,49,6,CONCRETE:15)
Block(-8,49,7,CONCRETE:15)
Block(-8,49,8,CONCRETE:15)
Block(-8,50,-7,CARPET:0)
Block(-8,50,-6,CARPET:11)
Block(-8,50,-5,CARPET:11)
Block(-8,50,-4,CARPET:0)
Block(-8,50,0,TRAP_DOOR:4)
Block(-8,50,1,BIRCH_WOOD_STAIRS:0)
Block(-8,50,2,TRAP_DOOR:5)
Block(-8,53,-7,CONCRETE:15)
Block(-8,53,-6,CONCRETE:15)
Block(-8,53,-5,CONCRETE:15)
Block(-8,53,-4,CONCRETE:15)
Block(-8,53,-3,CONCRETE:15)
Block(-8,53,-2,CONCRETE:15)
Block(-8,53,-1,CONCRETE:15)
Block(-8,53,0,CONCRETE:15)
Block(-8,53,1,CONCRETE:15)
Block(-8,53,2,CONCRETE:15)
Block(-8,53,3,CONCRETE:15)
Block(-8,53,4,CONCRETE:15)
Block(-8,53,5,CONCRETE:15)
Block(-8,53,6,CONCRETE:15)
Block(-8,53,7,CONCRETE:15)
Block(-8,53,8,CONCRETE:15)
Block(-8,57,-7,CONCRETE:15)
Block(-8,57,-6,CONCRETE:15)
Block(-8,57,-5,CONCRETE:15)
Block(-8,57,-4,CONCRETE:15)
Block(-8,57,-3,CONCRETE:15)
Block(-8,57,-2,CONCRETE:15)
Block(-8,57,-1,CONCRETE:15)
Block(-8,57,0,CONCRETE:15)
Block(-8,57,1,CONCRETE:15)
Block(-8,57,2,CONCRETE:15)
Block(-8,57,3,CONCRETE:15)
Block(-8,57,4,CONCRETE:15)
Block(-8,57,5,CONCRETE:15)
Block(-8,57,6,CONCRETE:15)
Block(-8,57,7,CONCRETE:15)
Block(-8,57,8,CONCRETE:15)
Block(-8,58,-2,CARPET:0)
Block(-8,58,-1,CARPET:9)
Block(-8,58,0,CARPET:0)
Block(-8,58,1,CARPET:9)
Block(-8,58,2,CARPET:0)
Block(-8,58,3,CARPET:9)
Block(-8,58,4,CARPET:0)
Block(-8,61,-7,CONCRETE:15)
Block(-8,61,-6,CONCRETE:15)
Block(-8,61,-5,CONCRETE:15)
Block(-8,61,-4,CONCRETE:15)
Block(-8,61,-3,CONCRETE:15)
Block(-8,61,-2,CONCRETE:15)
Block(-8,61,-1,CONCRETE:15)
Block(-8,61,0,CONCRETE:15)
Block(-8,61,1,CONCRETE:15)
Block(-8,61,2,CONCRETE:15)
Block(-8,61,3,CONCRETE:15)
Block(-8,61,4,CONCRETE:15)
Block(-8,61,5,CONCRETE:15)
Block(-8,61,6,CONCRETE:15)
Block(-8,61,7,CONCRETE:15)
Block(-8,61,8,CONCRETE:15)
Block(-8,65,-7,CONCRETE:15)
Block(-8,65,-6,CONCRETE:15)
Block(-8,65,-5,CONCRETE:15)
Block(-8,65,-4,CONCRETE:15)
Block(-8,65,-3,CONCRETE:15)
Block(-8,65,-2,CONCRETE:15)
Block(-8,65,-1,CONCRETE:15)
Block(-8,65,0,CONCRETE:15)
Block(-8,65,1,CONCRETE:15)
Block(-8,65,2,CONCRETE:15)
Block(-8,65,3,CONCRETE:15)
Block(-8,65,4,CONCRETE:15)
Block(-8,65,5,CONCRETE:15)
Block(-8,65,6,CONCRETE:15)
Block(-8,65,7,CONCRETE:15)
Block(-8,65,8,CONCRETE:15)
Block(-8,66,-2,CARPET:0)
Block(-8,66,-1,CARPET:9)
Block(-8,66,0,CARPET:0)
Block(-8,66,1,CARPET:9)
Block(-8,66,2,CARPET:0)
Block(-8,66,3,CARPET:9)
Block(-8,66,4,CARPET:0)
Block(-8,69,-7,CONCRETE:15)
Block(-8,69,-6,CONCRETE:15)
Block(-8,69,-5,CONCRETE:15)
Block(-8,69,-4,CONCRETE:15)
Block(-8,69,-3,CONCRETE:15)
Block(-8,69,-2,CONCRETE:15)
Block(-8,69,-1,CONCRETE:15)
Block(-8,69,0,CONCRETE:15)
Block(-8,69,1,CONCRETE:15)
Block(-8,69,2,CONCRETE:15)
Block(-8,69,3,CONCRETE:15)
Block(-8,69,4,CONCRETE:15)
Block(-8,69,5,CONCRETE:15)
Block(-8,69,6,CONCRETE:15)
Block(-8,69,7,CONCRETE:15)
Block(-8,69,8,CONCRETE:15)
Block(-8,70,-7,CARPET:0)
Block(-8,70,-6,CARPET:11)
Block(-8,70,-5,CARPET:11)
Block(-8,70,-4,CARPET:0)
Block(-8,70,0,TRAP_DOOR:4)
Block(-8,70,1,BIRCH_WOOD_STAIRS:0)
Block(-8,70,2,TRAP_DOOR:5)
Block(-8,73,-7,CONCRETE:15)
Block(-8,73,-6,CONCRETE:15)
Block(-8,73,-5,CONCRETE:15)
Block(-8,73,-4,CONCRETE:15)
Block(-8,73,-3,CONCRETE:15)
Block(-8,73,-2,CONCRETE:15)
Block(-8,73,-1,CONCRETE:15)
Block(-8,73,0,CONCRETE:15)
Block(-8,73,1,CONCRETE:15)
Block(-8,73,2,CONCRETE:15)
Block(-8,73,3,CONCRETE:15)
Block(-8,73,4,CONCRETE:15)
Block(-8,73,5,CONCRETE:15)
Block(-8,73,6,CONCRETE:15)
Block(-8,73,7,CONCRETE:15)
Block(-8,73,8,CONCRETE:15)
Block(-8,74,-2,CARPET:0)
Block(-8,74,-1,CARPET:9)
Block(-8,74,0,CARPET:0)
Block(-8,74,1,CARPET:9)
Block(-8,74,2,CARPET:0)
Block(-8,74,3,CARPET:9)
Block(-8,74,4,CARPET:0)
Block(-8,77,-7,CONCRETE:15)
Block(-8,77,-6,CONCRETE:15)
Block(-8,77,-5,CONCRETE:15)
Block(-8,77,-4,CONCRETE:15)
Block(-8,77,-3,CONCRETE:15)
Block(-8,77,-2,CONCRETE:15)
Block(-8,77,-1,CONCRETE:15)
Block(-8,77,0,CONCRETE:15)
Block(-8,77,1,CONCRETE:15)
Block(-8,77,2,CONCRETE:15)
Block(-8,77,3,CONCRETE:15)
Block(-8,77,4,CONCRETE:15)
Block(-8,77,5,CONCRETE:15)
Block(-8,77,6,CONCRETE:15)
Block(-8,77,7,CONCRETE:15)
Block(-8,77,8,CONCRETE:15)
Block(-8,81,-7,CONCRETE:15)
Block(-8,81,-6,CONCRETE:15)
Block(-8,81,-5,CONCRETE:15)
Block(-8,81,-4,CONCRETE:15)
Block(-8,81,-3,CONCRETE:15)
Block(-8,81,-2,CONCRETE:15)
Block(-8,81,-1,CONCRETE:15)
Block(-8,81,0,CONCRETE:15)
Block(-8,81,1,CONCRETE:15)
Block(-8,81,2,CONCRETE:15)
Block(-8,81,3,CONCRETE:15)
Block(-8,81,4,CONCRETE:15)
Block(-8,81,5,CONCRETE:15)
Block(-8,81,6,CONCRETE:15)
Block(-8,81,7,CONCRETE:15)
Block(-8,81,8,CONCRETE:15)
Block(-8,82,-2,CARPET:0)
Block(-8,82,-1,CARPET:9)
Block(-8,82,0,CARPET:0)
Block(-8,82,1,CARPET:9)
Block(-8,82,2,CARPET:0)
Block(-8,82,3,CARPET:9)
Block(-8,82,4,CARPET:0)
Block(-8,85,-7,CONCRETE:15)
Block(-8,85,-6,CONCRETE:15)
Block(-8,85,-5,CONCRETE:15)
Block(-8,85,-4,CONCRETE:15)
Block(-8,85,-3,CONCRETE:15)
Block(-8,85,-2,CONCRETE:15)
Block(-8,85,-1,CONCRETE:15)
Block(-8,85,0,CONCRETE:15)
Block(-8,85,1,CONCRETE:15)
Block(-8,85,2,CONCRETE:15)
Block(-8,85,3,CONCRETE:15)
Block(-8,85,4,CONCRETE:15)
Block(-8,85,5,CONCRETE:15)
Block(-8,85,6,CONCRETE:15)
Block(-8,85,7,CONCRETE:15)
Block(-8,85,8,CONCRETE:15)
Block(-7,0,-7,CONCRETE:7)
Block(-7,0,-6,CONCRETE:7)
Block(-7,0,-5,CONCRETE:7)
Block(-7,0,-4,CONCRETE:7)
Block(-7,0,-3,CONCRETE:7)
Block(-7,0,-2,CONCRETE:7)
Block(-7,0,-1,CONCRETE:7)
Block(-7,0,0,CONCRETE:7)
Block(-7,0,1,CONCRETE:7)
Block(-7,0,2,CONCRETE:7)
Block(-7,0,3,CONCRETE:7)
Block(-7,0,4,CONCRETE:7)
Block(-7,0,5,CONCRETE:7)
Block(-7,0,6,CONCRETE:7)
Block(-7,0,7,CONCRETE:7)
Block(-7,0,8,CONCRETE:7)
Block(-7,1,-7,CONCRETE:7)
Block(-7,1,-6,CONCRETE:7)
Block(-7,1,-5,CONCRETE:7)
Block(-7,1,-4,CONCRETE:7)
Block(-7,1,-3,CONCRETE:7)
Block(-7,1,-2,CONCRETE:7)
Block(-7,1,-1,CONCRETE:7)
Block(-7,1,0,CONCRETE:7)
Block(-7,1,1,CONCRETE:7)
Block(-7,1,2,CONCRETE:7)
Block(-7,1,3,CONCRETE:7)
Block(-7,1,4,CONCRETE:7)
Block(-7,1,5,CONCRETE:7)
Block(-7,1,6,CONCRETE:7)
Block(-7,1,7,CONCRETE:7)
Block(-7,1,8,CONCRETE:7)
Block(-7,2,-7,CONCRETE:7)
Block(-7,2,-6,CONCRETE:7)
Block(-7,2,-5,CONCRETE:7)
Block(-7,2,-4,CONCRETE:7)
Block(-7,2,-3,CONCRETE:7)
Block(-7,2,-2,CONCRETE:7)
Block(-7,2,-1,CONCRETE:7)
Block(-7,2,0,CONCRETE:7)
Block(-7,2,1,CONCRETE:7)
Block(-7,2,2,CONCRETE:7)
Block(-7,2,3,CONCRETE:7)
Block(-7,2,4,CONCRETE:7)
Block(-7,2,5,CONCRETE:7)
Block(-7,2,6,CONCRETE:7)
Block(-7,2,7,CONCRETE:7)
Block(-7,2,8,CONCRETE:7)
Block(-7,3,-7,CONCRETE:7)
Block(-7,3,-6,CONCRETE:7)
Block(-7,3,-5,CONCRETE:7)
Block(-7,3,-4,CONCRETE:7)
Block(-7,3,-3,CONCRETE:7)
Block(-7,3,-2,CONCRETE:7)
Block(-7,3,-1,CONCRETE:7)
Block(-7,3,0,CONCRETE:7)
Block(-7,3,1,CONCRETE:7)
Block(-7,3,2,CONCRETE:7)
Block(-7,3,3,CONCRETE:7)
Block(-7,3,4,CONCRETE:7)
Block(-7,3,5,CONCRETE:7)
Block(-7,3,6,CONCRETE:7)
Block(-7,3,7,CONCRETE:7)
Block(-7,3,8,CONCRETE:7)
Block(-7,4,-7,CONCRETE:7)
Block(-7,4,-6,CONCRETE:7)
Block(-7,4,-5,CONCRETE:7)
Block(-7,4,-4,CONCRETE:7)
Block(-7,4,-3,CONCRETE:7)
Block(-7,4,-2,CONCRETE:7)
Block(-7,4,-1,CONCRETE:7)
Block(-7,4,0,CONCRETE:7)
Block(-7,4,1,CONCRETE:7)
Block(-7,4,2,CONCRETE:7)
Block(-7,4,3,CONCRETE:7)
Block(-7,4,4,CONCRETE:7)
Block(-7,4,5,CONCRETE:7)
Block(-7,4,6,CONCRETE:7)
Block(-7,4,7,CONCRETE:7)
Block(-7,4,8,CONCRETE:7)
Block(-7,5,-7,CONCRETE:7)
Block(-7,5,-6,CONCRETE:7)
Block(-7,5,-5,CONCRETE:7)
Block(-7,5,-4,CONCRETE:7)
Block(-7,5,-3,CONCRETE:7)
Block(-7,5,-2,CONCRETE:7)
Block(-7,5,-1,CONCRETE:7)
Block(-7,5,0,CONCRETE:7)
Block(-7,5,1,CONCRETE:7)
Block(-7,5,2,CONCRETE:7)
Block(-7,5,3,CONCRETE:7)
Block(-7,5,4,CONCRETE:7)
Block(-7,5,5,CONCRETE:7)
Block(-7,5,6,CONCRETE:7)
Block(-7,5,7,CONCRETE:7)
Block(-7,5,8,CONCRETE:7)
Block(-7,6,-7,CONCRETE:7)
Block(-7,6,-6,CONCRETE:7)
Block(-7,6,-5,CONCRETE:7)
Block(-7,6,-4,CONCRETE:7)
Block(-7,6,-3,CONCRETE:7)
Block(-7,6,-2,CONCRETE:7)
Block(-7,6,-1,CONCRETE:7)
Block(-7,6,0,CONCRETE:7)
Block(-7,6,1,CONCRETE:7)
Block(-7,6,2,CONCRETE:7)
Block(-7,6,3,CONCRETE:7)
Block(-7,6,4,CONCRETE:7)
Block(-7,6,5,CONCRETE:7)
Block(-7,6,6,CONCRETE:7)
Block(-7,6,7,CONCRETE:7)
Block(-7,6,8,CONCRETE:7)
Block(-7,7,-7,CONCRETE:7)
Block(-7,7,-6,CONCRETE:7)
Block(-7,7,-5,CONCRETE:7)
Block(-7,7,-4,CONCRETE:7)
Block(-7,7,-3,CONCRETE:7)
Block(-7,7,-2,CONCRETE:7)
Block(-7,7,-1,CONCRETE:7)
Block(-7,7,0,CONCRETE:7)
Block(-7,7,1,CONCRETE:7)
Block(-7,7,2,CONCRETE:7)
Block(-7,7,3,CONCRETE:7)
Block(-7,7,4,CONCRETE:7)
Block(-7,7,5,CONCRETE:7)
Block(-7,7,6,CONCRETE:7)
Block(-7,7,7,CONCRETE:7)
Block(-7,7,8,CONCRETE:7)
Block(-7,8,-7,CONCRETE:7)
Block(-7,8,-6,CONCRETE:7)
Block(-7,8,-5,CONCRETE:7)
Block(-7,8,-4,CONCRETE:7)
Block(-7,8,-3,CONCRETE:7)
Block(-7,8,-2,CONCRETE:7)
Block(-7,8,-1,CONCRETE:7)
Block(-7,8,0,CONCRETE:7)
Block(-7,8,1,CONCRETE:7)
Block(-7,8,2,CONCRETE:7)
Block(-7,8,3,CONCRETE:7)
Block(-7,8,4,CONCRETE:7)
Block(-7,8,5,CONCRETE:7)
Block(-7,8,6,CONCRETE:7)
Block(-7,8,7,CONCRETE:7)
Block(-7,8,8,CONCRETE:7)
Block(-7,9,-7,CONCRETE:7)
Block(-7,9,-6,CONCRETE:7)
Block(-7,9,-5,CONCRETE:7)
Block(-7,9,-4,CONCRETE:7)
Block(-7,9,-3,CONCRETE:7)
Block(-7,9,-2,CONCRETE:7)
Block(-7,9,-1,CONCRETE:7)
Block(-7,9,0,CONCRETE:7)
Block(-7,9,1,CONCRETE:7)
Block(-7,9,2,CONCRETE:7)
Block(-7,9,3,CONCRETE:7)
Block(-7,9,4,CONCRETE:7)
Block(-7,9,5,CONCRETE:7)
Block(-7,9,6,CONCRETE:7)
Block(-7,9,7,CONCRETE:7)
Block(-7,9,8,CONCRETE:7)
Block(-7,10,-7,CONCRETE:7)
Block(-7,10,-6,CONCRETE:7)
Block(-7,10,-5,CONCRETE:7)
Block(-7,10,-4,CONCRETE:7)
Block(-7,10,-3,CONCRETE:7)
Block(-7,10,-2,CONCRETE:7)
Block(-7,10,-1,CONCRETE:7)
Block(-7,10,0,CONCRETE:7)
Block(-7,10,1,CONCRETE:7)
Block(-7,10,2,CONCRETE:7)
Block(-7,10,3,CONCRETE:7)
Block(-7,10,4,CONCRETE:7)
Block(-7,10,5,CONCRETE:7)
Block(-7,10,6,CONCRETE:7)
Block(-7,10,7,CONCRETE:7)
Block(-7,10,8,CONCRETE:7)
Block(-7,11,-7,CONCRETE:7)
Block(-7,11,-6,CONCRETE:7)
Block(-7,11,-5,CONCRETE:7)
Block(-7,11,-4,CONCRETE:7)
Block(-7,11,-3,CONCRETE:7)
Block(-7,11,-2,CONCRETE:7)
Block(-7,11,-1,CONCRETE:7)
Block(-7,11,0,CONCRETE:7)
Block(-7,11,1,CONCRETE:7)
Block(-7,11,2,CONCRETE:7)
Block(-7,11,3,CONCRETE:7)
Block(-7,11,4,CONCRETE:7)
Block(-7,11,5,CONCRETE:7)
Block(-7,11,6,CONCRETE:7)
Block(-7,11,7,CONCRETE:7)
Block(-7,11,8,CONCRETE:7)
Block(-7,12,-7,CONCRETE:7)
Block(-7,12,-6,CONCRETE:7)
Block(-7,12,-5,CONCRETE:7)
Block(-7,12,-4,CONCRETE:7)
Block(-7,12,-3,CONCRETE:7)
Block(-7,12,-2,CONCRETE:7)
Block(-7,12,-1,CONCRETE:7)
Block(-7,12,0,CONCRETE:7)
Block(-7,12,1,CONCRETE:7)
Block(-7,12,2,CONCRETE:7)
Block(-7,12,3,CONCRETE:7)
Block(-7,12,4,CONCRETE:7)
Block(-7,12,5,CONCRETE:7)
Block(-7,12,6,CONCRETE:7)
Block(-7,12,7,CONCRETE:7)
Block(-7,12,8,CONCRETE:7)
Block(-7,13,-7,CONCRETE:8)
Block(-7,13,-6,CONCRETE:8)
Block(-7,13,-5,CONCRETE:8)
Block(-7,13,-4,CONCRETE:8)
Block(-7,13,-3,CONCRETE:8)
Block(-7,13,-2,CONCRETE:8)
Block(-7,13,-1,CONCRETE:8)
Block(-7,13,0,CONCRETE:8)
Block(-7,13,1,CONCRETE:8)
Block(-7,13,2,CONCRETE:8)
Block(-7,13,3,CONCRETE:8)
Block(-7,13,4,CONCRETE:8)
Block(-7,13,5,CONCRETE:8)
Block(-7,13,6,CONCRETE:8)
Block(-7,13,7,CONCRETE:8)
Block(-7,13,8,CONCRETE:8)
Block(-7,14,-7,CONCRETE:8)
Block(-7,14,-6,CONCRETE:8)
Block(-7,14,-5,AIR:0)
Block(-7,14,-4,AIR:0)
Block(-7,14,-3,AIR:0)
Block(-7,14,-2,CONCRETE:8)
Block(-7,14,-1,CONCRETE:8)
Block(-7,14,0,CONCRETE:8)
Block(-7,14,1,CONCRETE:8)
Block(-7,14,2,CONCRETE:8)
Block(-7,14,3,CONCRETE:8)
Block(-7,14,4,CONCRETE:8)
Block(-7,14,5,CONCRETE:8)
Block(-7,14,6,AIR:0)
Block(-7,14,7,CONCRETE:8)
Block(-7,14,8,IRON_TRAPDOOR:9)
Block(-7,15,-7,CONCRETE:7)
Block(-7,15,-6,CONCRETE:7)
Block(-7,15,-5,AIR:0)
Block(-7,15,-4,AIR:0)
Block(-7,15,-3,AIR:0)
Block(-7,15,-2,CONCRETE:7)
Block(-7,15,-1,CONCRETE:7)
Block(-7,15,0,CONCRETE:7)
Block(-7,15,1,CONCRETE:7)
Block(-7,15,2,CONCRETE:7)
Block(-7,15,3,CONCRETE:7)
Block(-7,15,4,CONCRETE:7)
Block(-7,15,5,CONCRETE:7)
Block(-7,15,6,AIR:0)
Block(-7,15,7,CONCRETE:7)
Block(-7,15,8,IRON_TRAPDOOR:9)
Block(-7,16,-7,CONCRETE:7)
Block(-7,16,-6,CONCRETE:7)
Block(-7,16,-5,STEP:15)
Block(-7,16,-4,STEP:15)
Block(-7,16,-3,STEP:15)
Block(-7,16,-2,CONCRETE:7)
Block(-7,16,-1,CONCRETE:7)
Block(-7,16,0,CONCRETE:7)
Block(-7,16,1,CONCRETE:7)
Block(-7,16,2,CONCRETE:7)
Block(-7,16,3,CONCRETE:7)
Block(-7,16,4,CONCRETE:7)
Block(-7,16,5,CONCRETE:7)
Block(-7,16,6,STEP:15)
Block(-7,16,7,CONCRETE:7)
#RandomBlock(-7,16,8,TRAPPED_CHEST:5,../../../../../Chests/Loot/ModernCityJunk_1.nbt,65,CHEST:3,../../../../../Chests/Loot/ModernCityJunk_1.nbt,20,CHEST:3,../../../../../Chests/Loot/ModernCityJunk_2.nbt,15,CHEST:3,../../../../../Chests/Loot/ModernCityJunk_3.nbt,15,CHEST:3,../../../../../Chests/Loot/ModernCityJunk_4.nbt,15,CHEST:3,../../../../../Chests/Loot/ModernCityJunk_5.nbt,15,CHEST:3,../../../../../Chests/Loot/ModernCityCommon_1.nbt,5,CHEST:3,../../../../../Chests/Loot/ModernCityCommon_2.nbt,5,CHEST:3,../../../../../Chests/Loot/ModernCityCommon_3.nbt,5,CHEST:3,../../../../../Chests/Loot/ModernCityCommon_4.nbt,5,CHEST:3,../../../../../Chests/Loot/ModernCityCommon_5.nbt,5,CHEST:3,../../../../../Chests/Loot/ModernCityGood_1.nbt,3,CHEST:3,../../../../../Chests/Loot/ModernCityGood_2.nbt,3,CHEST:3,../../../../../Chests/Loot/ModernCityGood_3.nbt,3,CHEST:3,../../../../../Chests/Loot/ModernCityGood_4.nbt,3,CHEST:3,../../../../../Chests/Loot/ModernCityGood_5.nbt,3,CHEST:3,../../../../../Chests/Loot/ModernCityEpic_1.nbt,1,CHEST:3,../../../../../Chests/Loot/ModernCityEpic_2.nbt,1,CHEST:3,../../../../../Chests/Loot/ModernCityEpic_3.nbt,1,CHEST:3,../../../../../Chests/Loot/ModernCityEpic_4.nbt,1,CHEST:3,../../../../../Chests/Loot/ModernCityEpic_5.nbt,1,CHEST:3,../../../../../Chests/Loot/Common1.nbt,25,CHEST:3,../../../../../Chests/Loot/Common2.nbt,25,CHEST:3,../../../../../Chests/Loot/Common3.nbt,25,CHEST:3,../../../../../Chests/Loot/Common4.nbt,25,CHEST:3,../../../../../Chests/Loot/Common5.nbt,25,CHEST:3,../../../../../Chests/Loot/Common6.nbt,25,CHEST:3,../../../../../Chests/Loot/Common7.nbt,25,CHEST:3,../../../../../Chests/Loot/Common8.nbt,25,CHEST:3,../../../../../Chests/Loot/Common9.nbt,25,CHEST:3,../../../../../Chests/Loot/Common10.nbt,25,CHEST:3,../../../../../Chests/Loot/Common11.nbt,25,CHEST:3,../../../../../Chests/Loot/Common12.nbt,25,CHEST:3,../../../../../Chests/Loot/Common13.nbt,25,CHEST:3,../../../../../Chests/Loot/Common14.nbt,25,CHEST:3,../../../../../Chests/Loot/Common15.nbt,25,CHEST:3,../../../../../Chests/Loot/Rare1.nbt,10,CHEST:3,../../../../../Chests/Loot/Rare2.nbt,10,CHEST:5,../../../../../Chests/Loot/Rare3.nbt,10,CHEST:3,../../../../../Chests/Loot/Rare4.nbt,10,CHEST:3,../../../../../Chests/Loot/Rare5.nbt,10,CHEST:3,../../../../../Chests/Loot/Rare6.nbt,10,CHEST:3,../../../../../Chests/Loot/Rare7.nbt,10,CHEST:3,../../../../../Chests/Loot/Rare8.nbt,10,CHEST:3,../../../../../Chests/Loot/Rare9.nbt,10,CHEST:3,../../../../../Chests/Loot/Rare10.nbt,10,CHEST:3,../../../../../Chests/Loot/Rare11.nbt,10,CHEST:3,../../../../../Chests/Loot/Rare12.nbt,10,CHEST:3,../../../../../Chests/Loot/Rare13.nbt,10,CHEST:3,../../../../../Chests/Loot/Rare14.nbt,10,CHEST:3,../../../../../Chests/Loot/Rare15.nbt,10,CHEST:3,../../../../../Chests/Loot/Epic1.nbt,1,CHEST:3,../../../../../Chests/Loot/Epic2.nbt,1,CHEST:3,../../../../../Chests/Loot/Epic3.nbt,1,CHEST:3,../../../../../Chests/Loot/Epic4.nbt,1,CHEST:3,../../../../../Chests/Loot/Epic5.nbt,1,CHEST:3,../../../../../Chests/Loot/Epic6.nbt,1,CHEST:3,../../../../../Chests/Loot/Epic7.nbt,1,CHEST:3,../../../../../Chests/Loot/Epic8.nbt,1,CHEST:3,../../../../../Chests/Loot/Epic9.nbt,1,CHEST:3,../../../../../Chests/Loot/Epic10.nbt,1,CHEST:3,../../../../../Chests/Loot/Epic11.nbt,1,CHEST:3,../../../../../Chests/Loot/Epic12.nbt,1,CHEST:3,../../../../../Chests/Loot/Epic13.nbt,1,CHEST:3,../../../../../Chests/Loot/Epic14.nbt,1,CHEST:3,../../../../../Chests/Loot/Epic15.nbt,1,CHEST:3,../../../../../Chests/Loot/ModernCityJunk_1.nbt,100)
Block(-7,17,-7,CONCRETE:7)
Block(-7,17,-6,CONCRETE:7)
Block(-7,17,-5,CONCRETE:7)
Block(-7,17,-4,CONCRETE:7)
Block(-7,17,-3,CONCRETE:7)
Block(-7,17,-2,CONCRETE:7)
Block(-7,17,-1,CONCRETE:7)
Block(-7,17,0,CONCRETE:7)
Block(-7,17,1,CONCRETE:7)
Block(-7,17,2,CONCRETE:7)
Block(-7,17,3,CONCRETE:7)
Block(-7,17,4,CONCRETE:7)
Block(-7,17,5,CONCRETE:7)
Block(-7,17,6,CONCRETE:7)
Block(-7,17,7,CONCRETE:7)
Block(-7,17,8,CONCRETE:7)
Block(-7,18,-7,minecraft:purple_glazed_terracotta)
Block(-7,18,-6,minecraft:purple_glazed_terracotta)
Block(-7,18,-5,minecraft:purple_glazed_terracotta)
Block(-7,18,-4,minecraft:purple_glazed_terracotta)
Block(-7,18,0,CARPET:8)
Block(-7,18,1,CARPET:8)
Block(-7,18,2,CARPET:8)
Block(-7,19,-7,minecraft:purple_glazed_terracotta)
Block(-7,19,-6,minecraft:purple_glazed_terracotta)
Block(-7,19,-5,minecraft:purple_glazed_terracotta)
Block(-7,19,-4,minecraft:purple_glazed_terracotta:1)
Block(-7,20,-7,STEP:7)
Block(-7,20,-6,STEP:7)
Block(-7,20,-5,STEP:7)
Block(-7,20,-4,STEP:7)
Block(-7,20,6,TRAP_DOOR:8)
Block(-7,21,5,TRAP_DOOR:4)
Block(-7,21,6,SEA_LANTERN:0)
Block(-7,21,7,TRAP_DOOR:5)
Block(-7,22,6,IRON_FENCE:0)
Block(-7,23,-6,minecraft:black_glazed_terracotta)
Block(-7,23,-4,CONCRETE:0)
Block(-7,23,0,CONCRETE:15)
Block(-7,23,6,minecraft:black_glazed_terracotta)
Block(-7,24,-6,minecraft:black_glazed_terracotta)
Block(-7,24,-4,CONCRETE:0)
Block(-7,24,-2,minecraft:black_glazed_terracotta)
Block(-7,24,0,CONCRETE:15)
Block(-7,24,2,CONCRETE:0)
Block(-7,24,4,CONCRETE:0)
Block(-7,24,6,minecraft:black_glazed_terracotta)
Block(-7,24,8,CONCRETE:15)
Block(-7,25,-7,CONCRETE:15)
Block(-7,25,-6,CONCRETE:15)
Block(-7,25,-5,CONCRETE:15)
Block(-7,25,-4,CONCRETE:15)
Block(-7,25,-3,CONCRETE:15)
Block(-7,25,-2,CONCRETE:15)
Block(-7,25,-1,CONCRETE:15)
Block(-7,25,0,CONCRETE:15)
Block(-7,25,1,CONCRETE:15)
Block(-7,25,2,CONCRETE:15)
Block(-7,25,3,CONCRETE:15)
Block(-7,25,4,CONCRETE:15)
Block(-7,25,5,CONCRETE:15)
Block(-7,25,6,CONCRETE:15)
Block(-7,25,7,CONCRETE:15)
Block(-7,25,8,CONCRETE:15)
Block(-7,26,-6,CARPET:13)
Block(-7,26,-4,DARK_OAK_DOOR:3)
Block(-7,26,1,CONCRETE:0)
Block(-7,26,3,TRAP_DOOR:6)
Block(-7,26,6,DARK_OAK_DOOR:1)
Block(-7,26,8,CARPET:13)
Block(-7,27,-4,DARK_OAK_DOOR:8)
Block(-7,27,1,CONCRETE:0)
Block(-7,27,3,TRAP_DOOR:6)
Block(-7,27,6,DARK_OAK_DOOR:9)
Block(-7,28,-4,WOOD_STEP:5)
Block(-7,28,1,CONCRETE:0)
Block(-7,28,6,WOOD_STEP:5)
Block(-7,29,-7,CONCRETE:15)
Block(-7,29,-6,CONCRETE:15)
Block(-7,29,-5,CONCRETE:15)
Block(-7,29,-4,CONCRETE:15)
Block(-7,29,-3,CONCRETE:15)
Block(-7,29,-2,CONCRETE:15)
Block(-7,29,-1,CONCRETE:15)
Block(-7,29,0,CONCRETE:15)
Block(-7,29,1,CONCRETE:15)
Block(-7,29,2,CONCRETE:15)
Block(-7,29,3,CONCRETE:15)
Block(-7,29,4,CONCRETE:15)
Block(-7,29,5,CONCRETE:15)
Block(-7,29,6,CONCRETE:15)
Block(-7,29,7,CONCRETE:15)
Block(-7,29,8,CONCRETE:15)
Block(-7,30,1,BIRCH_DOOR:0)
Block(-7,31,1,BIRCH_DOOR:10)
Block(-7,33,-7,CONCRETE:15)
Block(-7,33,-6,CONCRETE:15)
Block(-7,33,-5,CONCRETE:15)
Block(-7,33,-4,CONCRETE:15)
Block(-7,33,-3,CONCRETE:15)
Block(-7,33,-2,CONCRETE:15)
Block(-7,33,-1,CONCRETE:15)
Block(-7,33,0,CONCRETE:15)
Block(-7,33,1,CONCRETE:15)
Block(-7,33,2,CONCRETE:15)
Block(-7,33,3,CONCRETE:15)
Block(-7,33,4,CONCRETE:15)
Block(-7,33,5,CONCRETE:15)
Block(-7,33,6,CONCRETE:15)
Block(-7,33,7,CONCRETE:15)
Block(-7,33,8,CONCRETE:15)
Block(-7,34,-1,FLOWER_POT:0,NBT/skyscraper_3x3_03/887-flower_potC32R16.nbt)
Block(-7,37,-7,CONCRETE:15)
Block(-7,37,-6,CONCRETE:15)
Block(-7,37,-5,CONCRETE:15)
Block(-7,37,-4,CONCRETE:15)
Block(-7,37,-3,CONCRETE:15)
Block(-7,37,-2,CONCRETE:15)
Block(-7,37,-1,CONCRETE:15)
Block(-7,37,0,CONCRETE:15)
Block(-7,37,1,CONCRETE:15)
Block(-7,37,2,CONCRETE:15)
Block(-7,37,3,CONCRETE:15)
Block(-7,37,4,CONCRETE:15)
Block(-7,37,5,CONCRETE:15)
Block(-7,37,6,CONCRETE:15)
Block(-7,37,7,CONCRETE:15)
Block(-7,37,8,CONCRETE:15)
Block(-7,41,-7,CONCRETE:15)
Block(-7,41,-6,CONCRETE:15)
Block(-7,41,-5,CONCRETE:15)
Block(-7,41,-4,CONCRETE:15)
Block(-7,41,-3,CONCRETE:15)
Block(-7,41,-2,CONCRETE:15)
Block(-7,41,-1,CONCRETE:15)
Block(-7,41,0,CONCRETE:15)
Block(-7,41,1,CONCRETE:15)
Block(-7,41,2,CONCRETE:15)
Block(-7,41,3,CONCRETE:15)
Block(-7,41,4,CONCRETE:15)
Block(-7,41,5,CONCRETE:15)
Block(-7,41,6,CONCRETE:15)
Block(-7,41,7,CONCRETE:15)
Block(-7,41,8,CONCRETE:15)
Block(-7,42,-1,FLOWER_POT:0,NBT/skyscraper_3x3_03/889-flower_potC32R16.nbt)
Block(-7,45,-7,CONCRETE:15)
Block(-7,45,-6,CONCRETE:15)
Block(-7,45,-5,CONCRETE:15)
Block(-7,45,-4,CONCRETE:15)
Block(-7,45,-3,CONCRETE:15)
Block(-7,45,-2,CONCRETE:15)
Block(-7,45,-1,CONCRETE:15)
Block(-7,45,0,CONCRETE:15)
Block(-7,45,1,CONCRETE:15)
Block(-7,45,2,CONCRETE:15)
Block(-7,45,3,CONCRETE:15)
Block(-7,45,4,CONCRETE:15)
Block(-7,45,5,CONCRETE:15)
Block(-7,45,6,CONCRETE:15)
Block(-7,45,7,CONCRETE:15)
Block(-7,45,8,CONCRETE:15)
Block(-7,49,-7,CONCRETE:15)
Block(-7,49,-6,CONCRETE:15)
Block(-7,49,-5,CONCRETE:15)
Block(-7,49,-4,CONCRETE:15)
Block(-7,49,-3,CONCRETE:15)
Block(-7,49,-2,CONCRETE:15)
Block(-7,49,-1,CONCRETE:15)
Block(-7,49,0,CONCRETE:15)
Block(-7,49,1,CONCRETE:15)
Block(-7,49,2,CONCRETE:15)
Block(-7,49,3,CONCRETE:15)
Block(-7,49,4,CONCRETE:15)
Block(-7,49,5,CONCRETE:15)
Block(-7,49,6,CONCRETE:15)
Block(-7,49,7,CONCRETE:15)
Block(-7,49,8,CONCRETE:15)
Block(-7,50,1,BIRCH_DOOR:0)
Block(-7,51,1,BIRCH_DOOR:10)
Block(-7,53,-7,CONCRETE:15)
Block(-7,53,-6,CONCRETE:15)
Block(-7,53,-5,CONCRETE:15)
Block(-7,53,-4,CONCRETE:15)
Block(-7,53,-3,CONCRETE:15)
Block(-7,53,-2,CONCRETE:15)
Block(-7,53,-1,CONCRETE:15)
Block(-7,53,0,CONCRETE:15)
Block(-7,53,1,CONCRETE:15)
Block(-7,53,2,CONCRETE:15)
Block(-7,53,3,CONCRETE:15)
Block(-7,53,4,CONCRETE:15)
Block(-7,53,5,CONCRETE:15)
Block(-7,53,6,CONCRETE:15)
Block(-7,53,7,CONCRETE:15)
Block(-7,53,8,CONCRETE:15)
Block(-7,54,-1,FLOWER_POT:0,NBT/skyscraper_3x3_03/892-flower_potC32R16.nbt)
Block(-7,57,-7,CONCRETE:15)
Block(-7,57,-6,CONCRETE:15)
Block(-7,57,-5,CONCRETE:15)
Block(-7,57,-4,CONCRETE:15)
Block(-7,57,-3,CONCRETE:15)
Block(-7,57,-2,CONCRETE:15)
Block(-7,57,-1,CONCRETE:15)
Block(-7,57,0,CONCRETE:15)
Block(-7,57,1,CONCRETE:15)
Block(-7,57,2,CONCRETE:15)
Block(-7,57,3,CONCRETE:15)
Block(-7,57,4,CONCRETE:15)
Block(-7,57,5,CONCRETE:15)
Block(-7,57,6,CONCRETE:15)
Block(-7,57,7,CONCRETE:15)
Block(-7,57,8,CONCRETE:15)
Block(-7,61,-7,CONCRETE:15)
Block(-7,61,-6,CONCRETE:15)
Block(-7,61,-5,CONCRETE:15)
Block(-7,61,-4,CONCRETE:15)
Block(-7,61,-3,CONCRETE:15)
Block(-7,61,-2,CONCRETE:15)
Block(-7,61,-1,CONCRETE:15)
Block(-7,61,0,CONCRETE:15)
Block(-7,61,1,CONCRETE:15)
Block(-7,61,2,CONCRETE:15)
Block(-7,61,3,CONCRETE:15)
Block(-7,61,4,CONCRETE:15)
Block(-7,61,5,CONCRETE:15)
Block(-7,61,6,CONCRETE:15)
Block(-7,61,7,CONCRETE:15)
Block(-7,61,8,CONCRETE:15)
Block(-7,62,-1,FLOWER_POT:0,NBT/skyscraper_3x3_03/894-flower_potC32R16.nbt)
Block(-7,65,-7,CONCRETE:15)
Block(-7,65,-6,CONCRETE:15)
Block(-7,65,-5,CONCRETE:15)
Block(-7,65,-4,CONCRETE:15)
Block(-7,65,-3,CONCRETE:15)
Block(-7,65,-2,CONCRETE:15)
Block(-7,65,-1,CONCRETE:15)
Block(-7,65,0,CONCRETE:15)
Block(-7,65,1,CONCRETE:15)
Block(-7,65,2,CONCRETE:15)
Block(-7,65,3,CONCRETE:15)
Block(-7,65,4,CONCRETE:15)
Block(-7,65,5,CONCRETE:15)
Block(-7,65,6,CONCRETE:15)
Block(-7,65,7,CONCRETE:15)
Block(-7,65,8,CONCRETE:15)
Block(-7,69,-7,CONCRETE:15)
Block(-7,69,-6,CONCRETE:15)
Block(-7,69,-5,CONCRETE:15)
Block(-7,69,-4,CONCRETE:15)
Block(-7,69,-3,CONCRETE:15)
Block(-7,69,-2,CONCRETE:15)
Block(-7,69,-1,CONCRETE:15)
Block(-7,69,0,CONCRETE:15)
Block(-7,69,1,CONCRETE:15)
Block(-7,69,2,CONCRETE:15)
Block(-7,69,3,CONCRETE:15)
Block(-7,69,4,CONCRETE:15)
Block(-7,69,5,CONCRETE:15)
Block(-7,69,6,CONCRETE:15)
Block(-7,69,7,CONCRETE:15)
Block(-7,69,8,CONCRETE:15)
Block(-7,70,1,BIRCH_DOOR:0)
Block(-7,71,1,BIRCH_DOOR:10)
Block(-7,73,-7,CONCRETE:15)
Block(-7,73,-6,CONCRETE:15)
Block(-7,73,-5,CONCRETE:15)
Block(-7,73,-4,CONCRETE:15)
Block(-7,73,-3,CONCRETE:15)
Block(-7,73,-2,CONCRETE:15)
Block(-7,73,-1,CONCRETE:15)
Block(-7,73,0,CONCRETE:15)
Block(-7,73,1,CONCRETE:15)
Block(-7,73,2,CONCRETE:15)
Block(-7,73,3,CONCRETE:15)
Block(-7,73,4,CONCRETE:15)
Block(-7,73,5,CONCRETE:15)
Block(-7,73,6,CONCRETE:15)
Block(-7,73,7,CONCRETE:15)
Block(-7,73,8,CONCRETE:15)
Block(-7,77,-7,CONCRETE:15)
Block(-7,77,-6,CONCRETE:15)
Block(-7,77,-5,CONCRETE:15)
Block(-7,77,-4,CONCRETE:15)
Block(-7,77,-3,CONCRETE:15)
Block(-7,77,-2,CONCRETE:15)
Block(-7,77,-1,CONCRETE:15)
Block(-7,77,0,CONCRETE:15)
Block(-7,77,1,CONCRETE:15)
Block(-7,77,2,CONCRETE:15)
Block(-7,77,3,CONCRETE:15)
Block(-7,77,4,CONCRETE:15)
Block(-7,77,5,CONCRETE:15)
Block(-7,77,6,CONCRETE:15)
Block(-7,77,7,CONCRETE:15)
Block(-7,77,8,CONCRETE:15)
Block(-7,78,-1,FLOWER_POT:0,NBT/skyscraper_3x3_03/898-flower_potC32R16.nbt)
Block(-7,81,-7,CONCRETE:15)
Block(-7,81,-6,CONCRETE:15)
Block(-7,81,-5,CONCRETE:15)
Block(-7,81,-4,CONCRETE:15)
Block(-7,81,-3,CONCRETE:15)
Block(-7,81,-2,CONCRETE:15)
Block(-7,81,-1,CONCRETE:15)
Block(-7,81,0,CONCRETE:15)
Block(-7,81,1,CONCRETE:15)
Block(-7,81,2,CONCRETE:15)
Block(-7,81,3,CONCRETE:15)
Block(-7,81,4,CONCRETE:15)
Block(-7,81,5,CONCRETE:15)
Block(-7,81,6,CONCRETE:15)
Block(-7,81,7,CONCRETE:15)
Block(-7,81,8,CONCRETE:15)
Block(-7,85,-7,CONCRETE:15)
Block(-7,85,-6,CONCRETE:15)
Block(-7,85,-5,CONCRETE:15)
Block(-7,85,-4,CONCRETE:15)
Block(-7,85,-3,CONCRETE:15)
Block(-7,85,-2,CONCRETE:15)
Block(-7,85,-1,CONCRETE:15)
Block(-7,85,0,CONCRETE:15)
Block(-7,85,1,CONCRETE:15)
Block(-7,85,2,CONCRETE:15)
Block(-7,85,3,CONCRETE:15)
Block(-7,85,4,CONCRETE:15)
Block(-7,85,5,CONCRETE:15)
Block(-7,85,6,CONCRETE:15)
Block(-7,85,7,CONCRETE:15)
Block(-7,85,8,CONCRETE:15)
Block(-7,86,-7,STEP:7)
Block(-7,86,-6,STEP:7)
Block(-7,86,-5,STEP:7)
Block(-7,86,-4,STEP:7)
Block(-7,86,-3,STEP:7)
Block(-7,86,-2,STEP:7)
Block(-7,86,-1,STEP:7)
Block(-7,86,0,STEP:7)
Block(-7,86,1,STEP:7)
Block(-7,86,2,STEP:7)
Block(-7,86,3,STEP:7)
Block(-7,86,4,STEP:7)
Block(-7,86,5,STEP:7)
Block(-7,86,6,STEP:7)
Block(-7,86,7,STEP:7)
Block(-7,86,8,STEP:7)
Block(-6,0,-7,CONCRETE:7)
Block(-6,0,-6,CONCRETE:7)
Block(-6,0,-5,CONCRETE:7)
Block(-6,0,-4,CONCRETE:7)
Block(-6,0,-3,CONCRETE:7)
Block(-6,0,-2,CONCRETE:7)
Block(-6,0,-1,CONCRETE:7)
Block(-6,0,0,CONCRETE:7)
Block(-6,0,1,CONCRETE:7)
Block(-6,0,2,CONCRETE:7)
Block(-6,0,3,CONCRETE:7)
Block(-6,0,4,CONCRETE:7)
Block(-6,0,5,CONCRETE:7)
Block(-6,0,6,CONCRETE:7)
Block(-6,0,7,CONCRETE:7)
Block(-6,0,8,CONCRETE:7)
Block(-6,1,-7,CONCRETE:7)
Block(-6,1,-6,CONCRETE:7)
Block(-6,1,-5,CONCRETE:7)
Block(-6,1,-4,CONCRETE:7)
Block(-6,1,-3,CONCRETE:7)
Block(-6,1,-2,CONCRETE:7)
Block(-6,1,-1,CONCRETE:7)
Block(-6,1,0,CONCRETE:7)
Block(-6,1,1,CONCRETE:7)
Block(-6,1,2,CONCRETE:7)
Block(-6,1,3,CONCRETE:7)
Block(-6,1,4,CONCRETE:7)
Block(-6,1,5,CONCRETE:7)
Block(-6,1,6,CONCRETE:7)
Block(-6,1,7,CONCRETE:7)
Block(-6,1,8,CONCRETE:7)
Block(-6,2,-7,CONCRETE:7)
Block(-6,2,-6,CONCRETE:7)
Block(-6,2,-5,CONCRETE:7)
Block(-6,2,-4,CONCRETE:7)
Block(-6,2,-3,CONCRETE:7)
Block(-6,2,-2,CONCRETE:7)
Block(-6,2,-1,CONCRETE:7)
Block(-6,2,0,CONCRETE:7)
Block(-6,2,1,CONCRETE:7)
Block(-6,2,2,CONCRETE:7)
Block(-6,2,3,CONCRETE:7)
Block(-6,2,4,CONCRETE:7)
Block(-6,2,5,CONCRETE:7)
Block(-6,2,6,CONCRETE:7)
Block(-6,2,7,CONCRETE:7)
Block(-6,2,8,CONCRETE:7)
Block(-6,3,-7,CONCRETE:7)
Block(-6,3,-6,CONCRETE:7)
Block(-6,3,-5,CONCRETE:7)
Block(-6,3,-4,CONCRETE:7)
Block(-6,3,-3,CONCRETE:7)
Block(-6,3,-2,CONCRETE:7)
Block(-6,3,-1,CONCRETE:7)
Block(-6,3,0,CONCRETE:7)
Block(-6,3,1,CONCRETE:7)
Block(-6,3,2,CONCRETE:7)
Block(-6,3,3,CONCRETE:7)
Block(-6,3,4,CONCRETE:7)
Block(-6,3,5,CONCRETE:7)
Block(-6,3,6,CONCRETE:7)
Block(-6,3,7,CONCRETE:7)
Block(-6,3,8,CONCRETE:7)
Block(-6,4,-7,CONCRETE:7)
Block(-6,4,-6,CONCRETE:7)
Block(-6,4,-5,CONCRETE:7)
Block(-6,4,-4,CONCRETE:7)
Block(-6,4,-3,CONCRETE:7)
Block(-6,4,-2,CONCRETE:7)
Block(-6,4,-1,CONCRETE:7)
Block(-6,4,0,CONCRETE:7)
Block(-6,4,1,CONCRETE:7)
Block(-6,4,2,CONCRETE:7)
Block(-6,4,3,CONCRETE:7)
Block(-6,4,4,CONCRETE:7)
Block(-6,4,5,CONCRETE:7)
Block(-6,4,6,CONCRETE:7)
Block(-6,4,7,CONCRETE:7)
Block(-6,4,8,CONCRETE:7)
Block(-6,5,-7,CONCRETE:7)
Block(-6,5,-6,CONCRETE:7)
Block(-6,5,-5,CONCRETE:7)
Block(-6,5,-4,CONCRETE:7)
Block(-6,5,-3,CONCRETE:7)
Block(-6,5,-2,CONCRETE:7)
Block(-6,5,-1,CONCRETE:7)
Block(-6,5,0,CONCRETE:7)
Block(-6,5,1,CONCRETE:7)
Block(-6,5,2,CONCRETE:7)
Block(-6,5,3,CONCRETE:7)
Block(-6,5,4,CONCRETE:7)
Block(-6,5,5,CONCRETE:7)
Block(-6,5,6,CONCRETE:7)
Block(-6,5,7,CONCRETE:7)
Block(-6,5,8,CONCRETE:7)
Block(-6,6,-7,CONCRETE:7)
Block(-6,6,-6,CONCRETE:7)
Block(-6,6,-5,CONCRETE:7)
Block(-6,6,-4,CONCRETE:7)
Block(-6,6,-3,CONCRETE:7)
Block(-6,6,-2,CONCRETE:7)
Block(-6,6,-1,CONCRETE:7)
Block(-6,6,0,CONCRETE:7)
Block(-6,6,1,CONCRETE:7)
Block(-6,6,2,CONCRETE:7)
Block(-6,6,3,CONCRETE:7)
Block(-6,6,4,CONCRETE:7)
Block(-6,6,5,CONCRETE:7)
Block(-6,6,6,CONCRETE:7)
Block(-6,6,7,CONCRETE:7)
Block(-6,6,8,CONCRETE:7)
Block(-6,7,-7,CONCRETE:7)
Block(-6,7,-6,CONCRETE:7)
Block(-6,7,-5,CONCRETE:7)
Block(-6,7,-4,CONCRETE:7)
Block(-6,7,-3,CONCRETE:7)
Block(-6,7,-2,CONCRETE:7)
Block(-6,7,-1,CONCRETE:7)
Block(-6,7,0,CONCRETE:7)
Block(-6,7,1,CONCRETE:7)
Block(-6,7,2,CONCRETE:7)
Block(-6,7,3,CONCRETE:7)
Block(-6,7,4,CONCRETE:7)
Block(-6,7,5,CONCRETE:7)
Block(-6,7,6,CONCRETE:7)
Block(-6,7,7,CONCRETE:7)
Block(-6,7,8,CONCRETE:7)
Block(-6,8,-7,CONCRETE:7)
Block(-6,8,-6,CONCRETE:7)
Block(-6,8,-5,CONCRETE:7)
Block(-6,8,-4,CONCRETE:7)
Block(-6,8,-3,CONCRETE:7)
Block(-6,8,-2,CONCRETE:7)
Block(-6,8,-1,CONCRETE:7)
Block(-6,8,0,CONCRETE:7)
Block(-6,8,1,CONCRETE:7)
Block(-6,8,2,CONCRETE:7)
Block(-6,8,3,CONCRETE:7)
Block(-6,8,4,CONCRETE:7)
Block(-6,8,5,CONCRETE:7)
Block(-6,8,6,CONCRETE:7)
Block(-6,8,7,CONCRETE:7)
Block(-6,8,8,CONCRETE:7)
Block(-6,9,-7,CONCRETE:7)
Block(-6,9,-6,CONCRETE:7)
Block(-6,9,-5,CONCRETE:7)
Block(-6,9,-4,CONCRETE:7)
Block(-6,9,-3,CONCRETE:7)
Block(-6,9,-2,CONCRETE:7)
Block(-6,9,-1,CONCRETE:7)
Block(-6,9,0,CONCRETE:7)
Block(-6,9,1,CONCRETE:7)
Block(-6,9,2,CONCRETE:7)
Block(-6,9,3,CONCRETE:7)
Block(-6,9,4,CONCRETE:7)
Block(-6,9,5,CONCRETE:7)
Block(-6,9,6,CONCRETE:7)
Block(-6,9,7,CONCRETE:7)
Block(-6,9,8,CONCRETE:7)
Block(-6,10,-7,CONCRETE:7)
Block(-6,10,-6,CONCRETE:7)
Block(-6,10,-5,CONCRETE:7)
Block(-6,10,-4,CONCRETE:7)
Block(-6,10,-3,CONCRETE:7)
Block(-6,10,-2,CONCRETE:7)
Block(-6,10,-1,CONCRETE:7)
Block(-6,10,0,CONCRETE:7)
Block(-6,10,1,CONCRETE:7)
Block(-6,10,2,CONCRETE:7)
Block(-6,10,3,CONCRETE:7)
Block(-6,10,4,CONCRETE:7)
Block(-6,10,5,CONCRETE:7)
Block(-6,10,6,CONCRETE:7)
Block(-6,10,7,CONCRETE:7)
Block(-6,10,8,CONCRETE:7)
Block(-6,11,-7,CONCRETE:7)
Block(-6,11,-6,CONCRETE:7)
Block(-6,11,-5,CONCRETE:7)
Block(-6,11,-4,CONCRETE:7)
Block(-6,11,-3,CONCRETE:7)
Block(-6,11,-2,CONCRETE:7)
Block(-6,11,-1,CONCRETE:7)
Block(-6,11,0,CONCRETE:7)
Block(-6,11,1,CONCRETE:7)
Block(-6,11,2,CONCRETE:7)
Block(-6,11,3,CONCRETE:7)
Block(-6,11,4,CONCRETE:7)
Block(-6,11,5,CONCRETE:7)
Block(-6,11,6,CONCRETE:7)
Block(-6,11,7,CONCRETE:7)
Block(-6,11,8,CONCRETE:7)
Block(-6,12,-7,CONCRETE:7)
Block(-6,12,-6,CONCRETE:7)
Block(-6,12,-5,CONCRETE:7)
Block(-6,12,-4,CONCRETE:7)
Block(-6,12,-3,CONCRETE:7)
Block(-6,12,-2,CONCRETE:7)
Block(-6,12,-1,CONCRETE:7)
Block(-6,12,0,CONCRETE:7)
Block(-6,12,1,CONCRETE:7)
Block(-6,12,2,CONCRETE:7)
Block(-6,12,3,CONCRETE:7)
Block(-6,12,4,CONCRETE:7)
Block(-6,12,5,CONCRETE:7)
Block(-6,12,6,CONCRETE:7)
Block(-6,12,7,CONCRETE:7)
Block(-6,12,8,CONCRETE:7)
Block(-6,13,-7,CONCRETE:8)
Block(-6,13,-6,CONCRETE:8)
Block(-6,13,-5,CONCRETE:8)
Block(-6,13,-4,CONCRETE:8)
Block(-6,13,-3,CONCRETE:8)
Block(-6,13,-2,CONCRETE:8)
Block(-6,13,-1,CONCRETE:8)
Block(-6,13,0,CONCRETE:8)
Block(-6,13,1,CONCRETE:8)
Block(-6,13,2,CONCRETE:8)
Block(-6,13,3,CONCRETE:8)
Block(-6,13,4,CONCRETE:8)
Block(-6,13,5,CONCRETE:8)
Block(-6,13,6,CONCRETE:8)
Block(-6,13,7,CONCRETE:8)
Block(-6,13,8,CONCRETE:8)
Block(-6,14,-7,CONCRETE:8)
Block(-6,14,-6,CONCRETE:8)
Block(-6,14,-5,AIR:0)
Block(-6,14,-4,AIR:0)
Block(-6,14,-3,AIR:0)
Block(-6,14,-2,CONCRETE:8)
Block(-6,14,-1,CONCRETE:8)
Block(-6,14,0,CONCRETE:8)
Block(-6,14,1,CONCRETE:8)
Block(-6,14,2,CONCRETE:8)
Block(-6,14,3,CONCRETE:8)
Block(-6,14,4,CONCRETE:8)
Block(-6,14,5,CONCRETE:8)
Block(-6,14,6,AIR:0)
Block(-6,14,7,CONCRETE:8)
Block(-6,14,8,IRON_TRAPDOOR:9)
Block(-6,15,-7,CONCRETE:7)
Block(-6,15,-6,CONCRETE:7)
Block(-6,15,-5,AIR:0)
Block(-6,15,-4,AIR:0)
Block(-6,15,-3,AIR:0)
Block(-6,15,-2,CONCRETE:7)
Block(-6,15,-1,CONCRETE:7)
Block(-6,15,0,CONCRETE:7)
Block(-6,15,1,CONCRETE:7)
Block(-6,15,2,CONCRETE:7)
Block(-6,15,3,CONCRETE:7)
Block(-6,15,4,CONCRETE:7)
Block(-6,15,5,CONCRETE:7)
Block(-6,15,6,AIR:0)
Block(-6,15,7,CONCRETE:7)
Block(-6,15,8,IRON_TRAPDOOR:9)
Block(-6,16,-7,CONCRETE:7)
Block(-6,16,-6,CONCRETE:7)
Block(-6,16,-5,AIR:0)
Block(-6,16,-4,AIR:0)
Block(-6,16,-3,AIR:0)
Block(-6,16,-2,CONCRETE:7)
Block(-6,16,-1,CONCRETE:7)
Block(-6,16,0,CONCRETE:7)
Block(-6,16,1,CONCRETE:7)
Block(-6,16,2,CONCRETE:7)
Block(-6,16,3,CONCRETE:7)
Block(-6,16,4,CONCRETE:7)
Block(-6,16,5,CONCRETE:7)
Block(-6,16,6,AIR:0)
Block(-6,16,7,CONCRETE:7)
#RandomBlock(-6,16,8,TRAPPED_CHEST:5,../../../../../Chests/Loot/ModernCityJunk_1.nbt,65,CHEST:3,../../../../../Chests/Loot/ModernCityJunk_1.nbt,20,CHEST:3,../../../../../Chests/Loot/ModernCityJunk_2.nbt,15,CHEST:3,../../../../../Chests/Loot/ModernCityJunk_3.nbt,15,CHEST:3,../../../../../Chests/Loot/ModernCityJunk_4.nbt,15,CHEST:3,../../../../../Chests/Loot/ModernCityJunk_5.nbt,15,CHEST:3,../../../../../Chests/Loot/ModernCityCommon_1.nbt,5,CHEST:3,../../../../../Chests/Loot/ModernCityCommon_2.nbt,5,CHEST:3,../../../../../Chests/Loot/ModernCityCommon_3.nbt,5,CHEST:3,../../../../../Chests/Loot/ModernCityCommon_4.nbt,5,CHEST:3,../../../../../Chests/Loot/ModernCityCommon_5.nbt,5,CHEST:3,../../../../../Chests/Loot/ModernCityGood_1.nbt,3,CHEST:3,../../../../../Chests/Loot/ModernCityGood_2.nbt,3,CHEST:3,../../../../../Chests/Loot/ModernCityGood_3.nbt,3,CHEST:3,../../../../../Chests/Loot/ModernCityGood_4.nbt,3,CHEST:3,../../../../../Chests/Loot/ModernCityGood_5.nbt,3,CHEST:3,../../../../../Chests/Loot/ModernCityEpic_1.nbt,1,CHEST:3,../../../../../Chests/Loot/ModernCityEpic_2.nbt,1,CHEST:3,../../../../../Chests/Loot/ModernCityEpic_3.nbt,1,CHEST:3,../../../../../Chests/Loot/ModernCityEpic_4.nbt,1,CHEST:3,../../../../../Chests/Loot/ModernCityEpic_5.nbt,1,CHEST:3,../../../../../Chests/Loot/Common1.nbt,25,CHEST:3,../../../../../Chests/Loot/Common2.nbt,25,CHEST:3,../../../../../Chests/Loot/Common3.nbt,25,CHEST:3,../../../../../Chests/Loot/Common4.nbt,25,CHEST:3,../../../../../Chests/Loot/Common5.nbt,25,CHEST:3,../../../../../Chests/Loot/Common6.nbt,25,CHEST:3,../../../../../Chests/Loot/Common7.nbt,25,CHEST:3,../../../../../Chests/Loot/Common8.nbt,25,CHEST:3,../../../../../Chests/Loot/Common9.nbt,25,CHEST:3,../../../../../Chests/Loot/Common10.nbt,25,CHEST:3,../../../../../Chests/Loot/Common11.nbt,25,CHEST:3,../../../../../Chests/Loot/Common12.nbt,25,CHEST:3,../../../../../Chests/Loot/Common13.nbt,25,CHEST:3,../../../../../Chests/Loot/Common14.nbt,25,CHEST:3,../../../../../Chests/Loot/Common15.nbt,25,CHEST:3,../../../../../Chests/Loot/Rare1.nbt,10,CHEST:3,../../../../../Chests/Loot/Rare2.nbt,10,CHEST:5,../../../../../Chests/Loot/Rare3.nbt,10,CHEST:3,../../../../../Chests/Loot/Rare4.nbt,10,CHEST:3,../../../../../Chests/Loot/Rare5.nbt,10,CHEST:3,../../../../../Chests/Loot/Rare6.nbt,10,CHEST:3,../../../../../Chests/Loot/Rare7.nbt,10,CHEST:3,../../../../../Chests/Loot/Rare8.nbt,10,CHEST:3,../../../../../Chests/Loot/Rare9.nbt,10,CHEST:3,../../../../../Chests/Loot/Rare10.nbt,10,CHEST:3,../../../../../Chests/Loot/Rare11.nbt,10,CHEST:3,../../../../../Chests/Loot/Rare12.nbt,10,CHEST:3,../../../../../Chests/Loot/Rare13.nbt,10,CHEST:3,../../../../../Chests/Loot/Rare14.nbt,10,CHEST:3,../../../../../Chests/Loot/Rare15.nbt,10,CHEST:3,../../../../../Chests/Loot/Epic1.nbt,1,CHEST:3,../../../../../Chests/Loot/Epic2.nbt,1,CHEST:3,../../../../../Chests/Loot/Epic3.nbt,1,CHEST:3,../../../../../Chests/Loot/Epic4.nbt,1,CHEST:3,../../../../../Chests/Loot/Epic5.nbt,1,CHEST:3,../../../../../Chests/Loot/Epic6.nbt,1,CHEST:3,../../../../../Chests/Loot/Epic7.nbt,1,CHEST:3,../../../../../Chests/Loot/Epic8.nbt,1,CHEST:3,../../../../../Chests/Loot/Epic9.nbt,1,CHEST:3,../../../../../Chests/Loot/Epic10.nbt,1,CHEST:3,../../../../../Chests/Loot/Epic11.nbt,1,CHEST:3,../../../../../Chests/Loot/Epic12.nbt,1,CHEST:3,../../../../../Chests/Loot/Epic13.nbt,1,CHEST:3,../../../../../Chests/Loot/Epic14.nbt,1,CHEST:3,../../../../../Chests/Loot/Epic15.nbt,1,CHEST:3,../../../../../Chests/Loot/ModernCityJunk_1.nbt,100)
Block(-6,17,-7,CONCRETE:7)
Block(-6,17,-6,CONCRETE:7)
Block(-6,17,-5,CONCRETE:7)
Block(-6,17,-4,CONCRETE:7)
Block(-6,17,-3,CONCRETE:7)
Block(-6,17,-2,CONCRETE:7)
Block(-6,17,-1,CONCRETE:7)
Block(-6,17,0,CONCRETE:7)
Block(-6,17,1,CONCRETE:7)
Block(-6,17,2,CONCRETE:7)
Block(-6,17,3,CONCRETE:7)
Block(-6,17,4,CONCRETE:7)
Block(-6,17,5,CONCRETE:7)
Block(-6,17,6,CONCRETE:7)
Block(-6,17,7,CONCRETE:7)
Block(-6,17,8,CONCRETE:7)
Block(-6,18,-4,minecraft:purple_glazed_terracotta:1)
Block(-6,18,0,CARPET:8)
Block(-6,18,1,CARPET:8)
Block(-6,18,2,CARPET:8)
Block(-6,19,-4,minecraft:purple_glazed_terracotta:1)
Block(-6,20,-4,STEP:7)
Block(-6,21,6,TRAP_DOOR:7)
Block(-6,25,-7,CONCRETE:15)
Block(-6,25,-6,CONCRETE:15)
Block(-6,25,-5,CONCRETE:15)
Block(-6,25,-4,CONCRETE:15)
Block(-6,25,-3,CONCRETE:15)
Block(-6,25,-2,CONCRETE:15)
Block(-6,25,-1,CONCRETE:15)
Block(-6,25,0,CONCRETE:15)
Block(-6,25,1,CONCRETE:15)
Block(-6,25,2,CONCRETE:15)
Block(-6,25,3,CONCRETE:15)
Block(-6,25,4,CONCRETE:15)
Block(-6,25,5,CONCRETE:15)
Block(-6,25,6,CONCRETE:15)
Block(-6,25,7,CONCRETE:15)
Block(-6,25,8,CONCRETE:15)
Block(-6,26,-6,CARPET:13)
Block(-6,26,-4,DARK_OAK_DOOR:7)
Block(-6,26,-3,TRAP_DOOR:6)
Block(-6,26,-1,TRAP_DOOR:6)
Block(-6,26,1,CONCRETE:0)
Block(-6,26,3,DARK_OAK_STAIRS:1)
Block(-6,26,5,TRAP_DOOR:6)
Block(-6,26,6,DARK_OAK_DOOR:1)
Block(-6,26,8,CARPET:13)
Block(-6,27,-4,DARK_OAK_DOOR:9)
Block(-6,27,-3,TRAP_DOOR:6)
Block(-6,27,-1,TRAP_DOOR:6)
Block(-6,27,1,CONCRETE:0)
Block(-6,27,3,WALL_BANNER:5,NBT/skyscraper_3x3_03/906-bannerC32R16.nbt)
Block(-6,27,5,TRAP_DOOR:6)
Block(-6,27,6,DARK_OAK_DOOR:8)
Block(-6,28,-4,WOOD_STEP:5)
Block(-6,28,1,CONCRETE:0)
Block(-6,28,6,WOOD_STEP:5)
Block(-6,29,-7,CONCRETE:15)
Block(-6,29,-6,CONCRETE:15)
Block(-6,29,-5,CONCRETE:15)
Block(-6,29,-4,CONCRETE:15)
Block(-6,29,-3,CONCRETE:15)
Block(-6,29,-2,CONCRETE:15)
Block(-6,29,-1,CONCRETE:15)
Block(-6,29,0,CONCRETE:15)
Block(-6,29,1,CONCRETE:15)
Block(-6,29,2,CONCRETE:15)
Block(-6,29,3,CONCRETE:15)
Block(-6,29,4,CONCRETE:15)
Block(-6,29,5,CONCRETE:15)
Block(-6,29,6,CONCRETE:15)
Block(-6,29,7,CONCRETE:15)
Block(-6,29,8,CONCRETE:15)
Block(-6,30,3,BIRCH_DOOR:2)
Block(-6,30,5,BIRCH_DOOR:2)
Block(-6,30,7,BIRCH_DOOR:2)
Block(-6,31,3,BIRCH_DOOR:11)
Block(-6,31,5,BIRCH_DOOR:11)
Block(-6,31,7,BIRCH_DOOR:10)
Block(-6,33,-7,CONCRETE:15)
Block(-6,33,-6,CONCRETE:15)
Block(-6,33,-5,CONCRETE:15)
Block(-6,33,-4,CONCRETE:15)
Block(-6,33,-3,CONCRETE:15)
Block(-6,33,-2,CONCRETE:15)
Block(-6,33,-1,CONCRETE:15)
Block(-6,33,0,CONCRETE:15)
Block(-6,33,1,CONCRETE:15)
Block(-6,33,2,CONCRETE:15)
Block(-6,33,3,CONCRETE:15)
Block(-6,33,4,CONCRETE:15)
Block(-6,33,5,CONCRETE:15)
Block(-6,33,6,CONCRETE:15)
Block(-6,33,7,CONCRETE:15)
Block(-6,33,8,CONCRETE:15)
Block(-6,34,-7,TRAP_DOOR:6)
Block(-6,34,-5,CONCRETE:10)
Block(-6,34,-3,TRAP_DOOR:6)
Block(-6,34,-1,CONCRETE:10)
Block(-6,34,1,TRAP_DOOR:6)
Block(-6,34,3,CONCRETE:10)
Block(-6,34,5,TRAP_DOOR:6)
Block(-6,34,7,CONCRETE:10)
Block(-6,35,-5,CONCRETE:10)
Block(-6,35,-1,CONCRETE:10)
Block(-6,35,3,CONCRETE:10)
Block(-6,35,7,CONCRETE:10)
Block(-6,36,-5,STEP:7)
Block(-6,36,-1,STEP:7)
Block(-6,36,3,STEP:7)
Block(-6,36,7,STEP:7)
Block(-6,37,-7,CONCRETE:15)
Block(-6,37,-6,CONCRETE:15)
Block(-6,37,-5,CONCRETE:15)
Block(-6,37,-4,CONCRETE:15)
Block(-6,37,-3,CONCRETE:15)
Block(-6,37,-2,CONCRETE:15)
Block(-6,37,-1,CONCRETE:15)
Block(-6,37,0,CONCRETE:15)
Block(-6,37,1,CONCRETE:15)
Block(-6,37,2,CONCRETE:15)
Block(-6,37,3,CONCRETE:15)
Block(-6,37,4,CONCRETE:15)
Block(-6,37,5,CONCRETE:15)
Block(-6,37,6,CONCRETE:15)
Block(-6,37,7,CONCRETE:15)
Block(-6,37,8,CONCRETE:15)
Block(-6,38,-7,TRAP_DOOR:6)
Block(-6,38,-3,TRAP_DOOR:6)
Block(-6,38,1,TRAP_DOOR:6)
Block(-6,38,5,TRAP_DOOR:6)
Block(-6,41,-7,CONCRETE:15)
Block(-6,41,-6,CONCRETE:15)
Block(-6,41,-5,CONCRETE:15)
Block(-6,41,-4,CONCRETE:15)
Block(-6,41,-3,CONCRETE:15)
Block(-6,41,-2,CONCRETE:15)
Block(-6,41,-1,CONCRETE:15)
Block(-6,41,0,CONCRETE:15)
Block(-6,41,1,CONCRETE:15)
Block(-6,41,2,CONCRETE:15)
Block(-6,41,3,CONCRETE:15)
Block(-6,41,4,CONCRETE:15)
Block(-6,41,5,CONCRETE:15)
Block(-6,41,6,CONCRETE:15)
Block(-6,41,7,CONCRETE:15)
Block(-6,41,8,CONCRETE:15)
Block(-6,42,-7,TRAP_DOOR:6)
Block(-6,42,-5,CONCRETE:10)
Block(-6,42,-3,TRAP_DOOR:6)
Block(-6,42,-1,CONCRETE:10)
Block(-6,42,1,TRAP_DOOR:6)
Block(-6,42,3,CONCRETE:10)
Block(-6,42,5,TRAP_DOOR:6)
Block(-6,42,7,CONCRETE:10)
Block(-6,43,-5,CONCRETE:10)
Block(-6,43,-1,CONCRETE:10)
Block(-6,43,3,CONCRETE:10)
Block(-6,43,7,CONCRETE:10)
Block(-6,44,-5,STEP:7)
Block(-6,44,-1,STEP:7)
Block(-6,44,3,STEP:7)
Block(-6,44,7,STEP:7)
Block(-6,45,-7,CONCRETE:15)
Block(-6,45,-6,CONCRETE:15)
Block(-6,45,-5,CONCRETE:15)
Block(-6,45,-4,CONCRETE:15)
Block(-6,45,-3,CONCRETE:15)
Block(-6,45,-2,CONCRETE:15)
Block(-6,45,-1,CONCRETE:15)
Block(-6,45,0,CONCRETE:15)
Block(-6,45,1,CONCRETE:15)
Block(-6,45,2,CONCRETE:15)
Block(-6,45,3,CONCRETE:15)
Block(-6,45,4,CONCRETE:15)
Block(-6,45,5,CONCRETE:15)
Block(-6,45,6,CONCRETE:15)
Block(-6,45,7,CONCRETE:15)
Block(-6,45,8,CONCRETE:15)
Block(-6,46,-7,TRAP_DOOR:6)
Block(-6,46,-3,TRAP_DOOR:6)
Block(-6,46,1,TRAP_DOOR:6)
Block(-6,46,5,TRAP_DOOR:6)
Block(-6,49,-7,CONCRETE:15)
Block(-6,49,-6,CONCRETE:15)
Block(-6,49,-5,CONCRETE:15)
Block(-6,49,-4,CONCRETE:15)
Block(-6,49,-3,CONCRETE:15)
Block(-6,49,-2,CONCRETE:15)
Block(-6,49,-1,CONCRETE:15)
Block(-6,49,0,CONCRETE:15)
Block(-6,49,1,CONCRETE:15)
Block(-6,49,2,CONCRETE:15)
Block(-6,49,3,CONCRETE:15)
Block(-6,49,4,CONCRETE:15)
Block(-6,49,5,CONCRETE:15)
Block(-6,49,6,CONCRETE:15)
Block(-6,49,7,CONCRETE:15)
Block(-6,49,8,CONCRETE:15)
Block(-6,50,3,BIRCH_DOOR:2)
Block(-6,50,5,BIRCH_DOOR:2)
Block(-6,50,7,BIRCH_DOOR:2)
Block(-6,51,3,BIRCH_DOOR:11)
Block(-6,51,5,BIRCH_DOOR:11)
Block(-6,51,7,BIRCH_DOOR:10)
Block(-6,53,-7,CONCRETE:15)
Block(-6,53,-6,CONCRETE:15)
Block(-6,53,-5,CONCRETE:15)
Block(-6,53,-4,CONCRETE:15)
Block(-6,53,-3,CONCRETE:15)
Block(-6,53,-2,CONCRETE:15)
Block(-6,53,-1,CONCRETE:15)
Block(-6,53,0,CONCRETE:15)
Block(-6,53,1,CONCRETE:15)
Block(-6,53,2,CONCRETE:15)
Block(-6,53,3,CONCRETE:15)
Block(-6,53,4,CONCRETE:15)
Block(-6,53,5,CONCRETE:15)
Block(-6,53,6,CONCRETE:15)
Block(-6,53,7,CONCRETE:15)
Block(-6,53,8,CONCRETE:15)
Block(-6,54,-7,TRAP_DOOR:6)
Block(-6,54,-5,CONCRETE:10)
Block(-6,54,-3,TRAP_DOOR:6)
Block(-6,54,-1,CONCRETE:10)
Block(-6,54,1,TRAP_DOOR:6)
Block(-6,54,3,CONCRETE:10)
Block(-6,54,5,TRAP_DOOR:6)
Block(-6,54,7,CONCRETE:10)
Block(-6,55,-5,CONCRETE:10)
Block(-6,55,-1,CONCRETE:10)
Block(-6,55,3,CONCRETE:10)
Block(-6,55,7,CONCRETE:10)
Block(-6,56,-5,STEP:7)
Block(-6,56,-1,STEP:7)
Block(-6,56,3,STEP:7)
Block(-6,56,7,STEP:7)
Block(-6,57,-7,CONCRETE:15)
Block(-6,57,-6,CONCRETE:15)
Block(-6,57,-5,CONCRETE:15)
Block(-6,57,-4,CONCRETE:15)
Block(-6,57,-3,CONCRETE:15)
Block(-6,57,-2,CONCRETE:15)
Block(-6,57,-1,CONCRETE:15)
Block(-6,57,0,CONCRETE:15)
Block(-6,57,1,CONCRETE:15)
Block(-6,57,2,CONCRETE:15)
Block(-6,57,3,CONCRETE:15)
Block(-6,57,4,CONCRETE:15)
Block(-6,57,5,CONCRETE:15)
Block(-6,57,6,CONCRETE:15)
Block(-6,57,7,CONCRETE:15)
Block(-6,57,8,CONCRETE:15)
Block(-6,58,-7,TRAP_DOOR:6)
Block(-6,58,-3,TRAP_DOOR:6)
Block(-6,58,1,TRAP_DOOR:6)
Block(-6,58,5,TRAP_DOOR:6)
Block(-6,61,-7,CONCRETE:15)
Block(-6,61,-6,CONCRETE:15)
Block(-6,61,-5,CONCRETE:15)
Block(-6,61,-4,CONCRETE:15)
Block(-6,61,-3,CONCRETE:15)
Block(-6,61,-2,CONCRETE:15)
Block(-6,61,-1,CONCRETE:15)
Block(-6,61,0,CONCRETE:15)
Block(-6,61,1,CONCRETE:15)
Block(-6,61,2,CONCRETE:15)
Block(-6,61,3,CONCRETE:15)
Block(-6,61,4,CONCRETE:15)
Block(-6,61,5,CONCRETE:15)
Block(-6,61,6,CONCRETE:15)
Block(-6,61,7,CONCRETE:15)
Block(-6,61,8,CONCRETE:15)
Block(-6,62,-7,TRAP_DOOR:6)
Block(-6,62,-5,CONCRETE:10)
Block(-6,62,-3,TRAP_DOOR:6)
Block(-6,62,-1,CONCRETE:10)
Block(-6,62,1,TRAP_DOOR:6)
Block(-6,62,3,CONCRETE:10)
Block(-6,62,5,TRAP_DOOR:6)
Block(-6,62,7,CONCRETE:10)
Block(-6,63,-5,CONCRETE:10)
Block(-6,63,-1,CONCRETE:10)
Block(-6,63,3,CONCRETE:10)
Block(-6,63,7,CONCRETE:10)
Block(-6,64,-5,STEP:7)
Block(-6,64,-1,STEP:7)
Block(-6,64,3,STEP:7)
Block(-6,64,7,STEP:7)
Block(-6,65,-7,CONCRETE:15)
Block(-6,65,-6,CONCRETE:15)
Block(-6,65,-5,CONCRETE:15)
Block(-6,65,-4,CONCRETE:15)
Block(-6,65,-3,CONCRETE:15)
Block(-6,65,-2,CONCRETE:15)
Block(-6,65,-1,CONCRETE:15)
Block(-6,65,0,CONCRETE:15)
Block(-6,65,1,CONCRETE:15)
Block(-6,65,2,CONCRETE:15)
Block(-6,65,3,CONCRETE:15)
Block(-6,65,4,CONCRETE:15)
Block(-6,65,5,CONCRETE:15)
Block(-6,65,6,CONCRETE:15)
Block(-6,65,7,CONCRETE:15)
Block(-6,65,8,CONCRETE:15)
Block(-6,66,-7,TRAP_DOOR:6)
Block(-6,66,-3,TRAP_DOOR:6)
Block(-6,66,1,TRAP_DOOR:6)
Block(-6,66,5,TRAP_DOOR:6)
Block(-6,69,-7,CONCRETE:15)
Block(-6,69,-6,CONCRETE:15)
Block(-6,69,-5,CONCRETE:15)
Block(-6,69,-4,CONCRETE:15)
Block(-6,69,-3,CONCRETE:15)
Block(-6,69,-2,CONCRETE:15)
Block(-6,69,-1,CONCRETE:15)
Block(-6,69,0,CONCRETE:15)
Block(-6,69,1,CONCRETE:15)
Block(-6,69,2,CONCRETE:15)
Block(-6,69,3,CONCRETE:15)
Block(-6,69,4,CONCRETE:15)
Block(-6,69,5,CONCRETE:15)
Block(-6,69,6,CONCRETE:15)
Block(-6,69,7,CONCRETE:15)
Block(-6,69,8,CONCRETE:15)
Block(-6,70,3,BIRCH_DOOR:2)
Block(-6,70,5,BIRCH_DOOR:2)
Block(-6,70,7,BIRCH_DOOR:2)
Block(-6,71,3,BIRCH_DOOR:11)
Block(-6,71,5,BIRCH_DOOR:11)
Block(-6,71,7,BIRCH_DOOR:10)
Block(-6,73,-7,CONCRETE:15)
Block(-6,73,-6,CONCRETE:15)
Block(-6,73,-5,CONCRETE:15)
Block(-6,73,-4,CONCRETE:15)
Block(-6,73,-3,CONCRETE:15)
Block(-6,73,-2,CONCRETE:15)
Block(-6,73,-1,CONCRETE:15)
Block(-6,73,0,CONCRETE:15)
Block(-6,73,1,CONCRETE:15)
Block(-6,73,2,CONCRETE:15)
Block(-6,73,3,CONCRETE:15)
Block(-6,73,4,CONCRETE:15)
Block(-6,73,5,CONCRETE:15)
Block(-6,73,6,CONCRETE:15)
Block(-6,73,7,CONCRETE:15)
Block(-6,73,8,CONCRETE:15)
Block(-6,74,-7,TRAP_DOOR:6)
Block(-6,74,-3,TRAP_DOOR:6)
Block(-6,74,1,TRAP_DOOR:6)
Block(-6,74,5,TRAP_DOOR:6)
Block(-6,77,-7,CONCRETE:15)
Block(-6,77,-6,CONCRETE:15)
Block(-6,77,-5,CONCRETE:15)
Block(-6,77,-4,CONCRETE:15)
Block(-6,77,-3,CONCRETE:15)
Block(-6,77,-2,CONCRETE:15)
Block(-6,77,-1,CONCRETE:15)
Block(-6,77,0,CONCRETE:15)
Block(-6,77,1,CONCRETE:15)
Block(-6,77,2,CONCRETE:15)
Block(-6,77,3,CONCRETE:15)
Block(-6,77,4,CONCRETE:15)
Block(-6,77,5,CONCRETE:15)
Block(-6,77,6,CONCRETE:15)
Block(-6,77,7,CONCRETE:15)
Block(-6,77,8,CONCRETE:15)
Block(-6,78,-7,TRAP_DOOR:6)
Block(-6,78,-5,CONCRETE:10)
Block(-6,78,-3,TRAP_DOOR:6)
Block(-6,78,-1,CONCRETE:10)
Block(-6,78,1,TRAP_DOOR:6)
Block(-6,78,3,CONCRETE:10)
Block(-6,78,5,TRAP_DOOR:6)
Block(-6,78,7,CONCRETE:10)
Block(-6,79,-5,CONCRETE:10)
Block(-6,79,-1,CONCRETE:10)
Block(-6,79,3,CONCRETE:10)
Block(-6,79,7,CONCRETE:10)
Block(-6,80,-5,STEP:7)
Block(-6,80,-1,STEP:7)
Block(-6,80,3,STEP:7)
Block(-6,80,7,STEP:7)
Block(-6,81,-7,CONCRETE:15)
Block(-6,81,-6,CONCRETE:15)
Block(-6,81,-5,CONCRETE:15)
Block(-6,81,-4,CONCRETE:15)
Block(-6,81,-3,CONCRETE:15)
Block(-6,81,-2,CONCRETE:15)
Block(-6,81,-1,CONCRETE:15)
Block(-6,81,0,CONCRETE:15)
Block(-6,81,1,CONCRETE:15)
Block(-6,81,2,CONCRETE:15)
Block(-6,81,3,CONCRETE:15)
Block(-6,81,4,CONCRETE:15)
Block(-6,81,5,CONCRETE:15)
Block(-6,81,6,CONCRETE:15)
Block(-6,81,7,CONCRETE:15)
Block(-6,81,8,CONCRETE:15)
Block(-6,82,-7,TRAP_DOOR:6)
Block(-6,82,-3,TRAP_DOOR:6)
Block(-6,82,1,TRAP_DOOR:6)
Block(-6,82,5,TRAP_DOOR:6)
Block(-6,85,-7,CONCRETE:15)
Block(-6,85,-6,CONCRETE:15)
Block(-6,85,-5,CONCRETE:15)
Block(-6,85,-4,CONCRETE:15)
Block(-6,85,-3,CONCRETE:15)
Block(-6,85,-2,CONCRETE:15)
Block(-6,85,-1,CONCRETE:15)
Block(-6,85,0,CONCRETE:15)
Block(-6,85,1,CONCRETE:15)
Block(-6,85,2,CONCRETE:15)
Block(-6,85,3,CONCRETE:15)
Block(-6,85,4,CONCRETE:15)
Block(-6,85,5,CONCRETE:15)
Block(-6,85,6,CONCRETE:15)
Block(-6,85,7,CONCRETE:15)
Block(-6,85,8,CONCRETE:15)
Block(-6,86,-7,DAYLIGHT_DETECTOR_INVERTED:1,NBT/skyscraper_3x3_03/907-daylight_detectorC32R16.nbt)
Block(-6,86,-6,DAYLIGHT_DETECTOR_INVERTED:1,NBT/skyscraper_3x3_03/908-daylight_detectorC32R16.nbt)
Block(-6,86,-5,DAYLIGHT_DETECTOR_INVERTED:1,NBT/skyscraper_3x3_03/909-daylight_detectorC32R16.nbt)
Block(-6,86,-4,DAYLIGHT_DETECTOR_INVERTED:1,NBT/skyscraper_3x3_03/910-daylight_detectorC32R16.nbt)
Block(-6,86,-3,DAYLIGHT_DETECTOR_INVERTED:1,NBT/skyscraper_3x3_03/911-daylight_detectorC32R16.nbt)
Block(-6,86,-2,DAYLIGHT_DETECTOR_INVERTED:1,NBT/skyscraper_3x3_03/912-daylight_detectorC32R16.nbt)
Block(-6,86,-1,DAYLIGHT_DETECTOR_INVERTED:1,NBT/skyscraper_3x3_03/913-daylight_detectorC32R16.nbt)
Block(-6,86,0,DAYLIGHT_DETECTOR_INVERTED:1,NBT/skyscraper_3x3_03/914-daylight_detectorC32R16.nbt)
Block(-6,86,1,DAYLIGHT_DETECTOR_INVERTED:1,NBT/skyscraper_3x3_03/915-daylight_detectorC32R16.nbt)
Block(-6,86,2,DAYLIGHT_DETECTOR_INVERTED:1,NBT/skyscraper_3x3_03/916-daylight_detectorC32R16.nbt)
Block(-6,86,3,DAYLIGHT_DETECTOR_INVERTED:1,NBT/skyscraper_3x3_03/917-daylight_detectorC32R16.nbt)
Block(-6,86,4,DAYLIGHT_DETECTOR_INVERTED:1,NBT/skyscraper_3x3_03/918-daylight_detectorC32R16.nbt)
Block(-6,86,5,DAYLIGHT_DETECTOR_INVERTED:1,NBT/skyscraper_3x3_03/919-daylight_detectorC32R16.nbt)
Block(-6,86,6,DAYLIGHT_DETECTOR_INVERTED:1,NBT/skyscraper_3x3_03/920-daylight_detectorC32R16.nbt)
Block(-6,86,7,DAYLIGHT_DETECTOR_INVERTED:1,NBT/skyscraper_3x3_03/921-daylight_detectorC32R16.nbt)
Block(-6,86,8,DAYLIGHT_DETECTOR_INVERTED:1,NBT/skyscraper_3x3_03/922-daylight_detectorC32R16.nbt)
Block(-5,0,-7,CONCRETE:7)
Block(-5,0,-6,CONCRETE:7)
Block(-5,0,-5,CONCRETE:7)
Block(-5,0,-4,CONCRETE:7)
Block(-5,0,-3,CONCRETE:7)
Block(-5,0,-2,CONCRETE:7)
Block(-5,0,-1,CONCRETE:7)
Block(-5,0,0,CONCRETE:7)
Block(-5,0,1,CONCRETE:7)
Block(-5,0,2,CONCRETE:7)
Block(-5,0,3,CONCRETE:7)
Block(-5,0,4,CONCRETE:7)
Block(-5,0,5,CONCRETE:7)
Block(-5,0,6,CONCRETE:7)
Block(-5,0,7,CONCRETE:7)
Block(-5,0,8,CONCRETE:7)
Block(-5,1,-7,CONCRETE:7)
Block(-5,1,-6,CONCRETE:7)
Block(-5,1,-5,CONCRETE:7)
Block(-5,1,-4,CONCRETE:7)
Block(-5,1,-3,CONCRETE:7)
Block(-5,1,-2,CONCRETE:7)
Block(-5,1,-1,CONCRETE:7)
Block(-5,1,0,CONCRETE:7)
Block(-5,1,1,CONCRETE:7)
Block(-5,1,2,CONCRETE:7)
Block(-5,1,3,CONCRETE:7)
Block(-5,1,4,CONCRETE:7)
Block(-5,1,5,CONCRETE:7)
Block(-5,1,6,CONCRETE:7)
Block(-5,1,7,CONCRETE:7)
Block(-5,1,8,CONCRETE:7)
Block(-5,2,-7,CONCRETE:7)
Block(-5,2,-6,CONCRETE:7)
Block(-5,2,-5,CONCRETE:7)
Block(-5,2,-4,CONCRETE:7)
Block(-5,2,-3,CONCRETE:7)
Block(-5,2,-2,CONCRETE:7)
Block(-5,2,-1,CONCRETE:7)
Block(-5,2,0,CONCRETE:7)
Block(-5,2,1,CONCRETE:7)
Block(-5,2,2,CONCRETE:7)
Block(-5,2,3,CONCRETE:7)
Block(-5,2,4,CONCRETE:7)
Block(-5,2,5,CONCRETE:7)
Block(-5,2,6,CONCRETE:7)
Block(-5,2,7,CONCRETE:7)
Block(-5,2,8,CONCRETE:7)
Block(-5,3,-7,CONCRETE:7)
Block(-5,3,-6,CONCRETE:7)
Block(-5,3,-5,CONCRETE:7)
Block(-5,3,-4,CONCRETE:7)
Block(-5,3,-3,CONCRETE:7)
Block(-5,3,-2,CONCRETE:7)
Block(-5,3,-1,CONCRETE:7)
Block(-5,3,0,CONCRETE:7)
Block(-5,3,1,CONCRETE:7)
Block(-5,3,2,CONCRETE:7)
Block(-5,3,3,CONCRETE:7)
Block(-5,3,4,CONCRETE:7)
Block(-5,3,5,CONCRETE:7)
Block(-5,3,6,CONCRETE:7)
Block(-5,3,7,CONCRETE:7)
Block(-5,3,8,CONCRETE:7)
Block(-5,4,-7,CONCRETE:7)
Block(-5,4,-6,CONCRETE:7)
Block(-5,4,-5,CONCRETE:7)
Block(-5,4,-4,CONCRETE:7)
Block(-5,4,-3,CONCRETE:7)
Block(-5,4,-2,CONCRETE:7)
Block(-5,4,-1,CONCRETE:7)
Block(-5,4,0,CONCRETE:7)
Block(-5,4,1,CONCRETE:7)
Block(-5,4,2,CONCRETE:7)
Block(-5,4,3,CONCRETE:7)
Block(-5,4,4,CONCRETE:7)
Block(-5,4,5,CONCRETE:7)
Block(-5,4,6,CONCRETE:7)
Block(-5,4,7,CONCRETE:7)
Block(-5,4,8,CONCRETE:7)
Block(-5,5,-7,CONCRETE:7)
Block(-5,5,-6,CONCRETE:7)
Block(-5,5,-5,CONCRETE:7)
Block(-5,5,-4,CONCRETE:7)
Block(-5,5,-3,CONCRETE:7)
Block(-5,5,-2,CONCRETE:7)
Block(-5,5,-1,CONCRETE:7)
Block(-5,5,0,CONCRETE:7)
Block(-5,5,1,CONCRETE:7)
Block(-5,5,2,CONCRETE:7)
Block(-5,5,3,CONCRETE:7)
Block(-5,5,4,CONCRETE:7)
Block(-5,5,5,CONCRETE:7)
Block(-5,5,6,CONCRETE:7)
Block(-5,5,7,CONCRETE:7)
Block(-5,5,8,CONCRETE:7)
Block(-5,6,-7,CONCRETE:7)
Block(-5,6,-6,CONCRETE:7)
Block(-5,6,-5,CONCRETE:7)
Block(-5,6,-4,CONCRETE:7)
Block(-5,6,-3,CONCRETE:7)
Block(-5,6,-2,CONCRETE:7)
Block(-5,6,-1,CONCRETE:7)
Block(-5,6,0,CONCRETE:7)
Block(-5,6,1,CONCRETE:7)
Block(-5,6,2,CONCRETE:7)
Block(-5,6,3,CONCRETE:7)
Block(-5,6,4,CONCRETE:7)
Block(-5,6,5,CONCRETE:7)
Block(-5,6,6,CONCRETE:7)
Block(-5,6,7,CONCRETE:7)
Block(-5,6,8,CONCRETE:7)
Block(-5,7,-7,CONCRETE:7)
Block(-5,7,-6,CONCRETE:7)
Block(-5,7,-5,CONCRETE:7)
Block(-5,7,-4,CONCRETE:7)
Block(-5,7,-3,CONCRETE:7)
Block(-5,7,-2,CONCRETE:7)
Block(-5,7,-1,CONCRETE:7)
Block(-5,7,0,CONCRETE:7)
Block(-5,7,1,CONCRETE:7)
Block(-5,7,2,CONCRETE:7)
Block(-5,7,3,CONCRETE:7)
Block(-5,7,4,CONCRETE:7)
Block(-5,7,5,CONCRETE:7)
Block(-5,7,6,CONCRETE:7)
Block(-5,7,7,CONCRETE:7)
Block(-5,7,8,CONCRETE:7)
Block(-5,8,-7,CONCRETE:7)
Block(-5,8,-6,CONCRETE:7)
Block(-5,8,-5,CONCRETE:7)
Block(-5,8,-4,CONCRETE:7)
Block(-5,8,-3,CONCRETE:7)
Block(-5,8,-2,CONCRETE:7)
Block(-5,8,-1,CONCRETE:7)
Block(-5,8,0,CONCRETE:7)
Block(-5,8,1,CONCRETE:7)
Block(-5,8,2,CONCRETE:7)
Block(-5,8,3,CONCRETE:7)
Block(-5,8,4,CONCRETE:7)
Block(-5,8,5,CONCRETE:7)
Block(-5,8,6,CONCRETE:7)
Block(-5,8,7,CONCRETE:7)
Block(-5,8,8,CONCRETE:7)
Block(-5,9,-7,CONCRETE:7)
Block(-5,9,-6,CONCRETE:7)
Block(-5,9,-5,CONCRETE:7)
Block(-5,9,-4,CONCRETE:7)
Block(-5,9,-3,CONCRETE:7)
Block(-5,9,-2,CONCRETE:7)
Block(-5,9,-1,CONCRETE:7)
Block(-5,9,0,CONCRETE:7)
Block(-5,9,1,CONCRETE:7)
Block(-5,9,2,CONCRETE:7)
Block(-5,9,3,CONCRETE:7)
Block(-5,9,4,CONCRETE:7)
Block(-5,9,5,CONCRETE:7)
Block(-5,9,6,CONCRETE:7)
Block(-5,9,7,CONCRETE:7)
Block(-5,9,8,CONCRETE:7)
Block(-5,10,-7,CONCRETE:7)
Block(-5,10,-6,CONCRETE:7)
Block(-5,10,-5,CONCRETE:7)
Block(-5,10,-4,CONCRETE:7)
Block(-5,10,-3,CONCRETE:7)
Block(-5,10,-2,CONCRETE:7)
Block(-5,10,-1,CONCRETE:7)
Block(-5,10,0,CONCRETE:7)
Block(-5,10,1,CONCRETE:7)
Block(-5,10,2,CONCRETE:7)
Block(-5,10,3,CONCRETE:7)
Block(-5,10,4,CONCRETE:7)
Block(-5,10,5,CONCRETE:7)
Block(-5,10,6,CONCRETE:7)
Block(-5,10,7,CONCRETE:7)
Block(-5,10,8,CONCRETE:7)
Block(-5,11,-7,CONCRETE:7)
Block(-5,11,-6,CONCRETE:7)
Block(-5,11,-5,CONCRETE:7)
Block(-5,11,-4,CONCRETE:7)
Block(-5,11,-3,CONCRETE:7)
Block(-5,11,-2,CONCRETE:7)
Block(-5,11,-1,CONCRETE:7)
Block(-5,11,0,CONCRETE:7)
Block(-5,11,1,CONCRETE:7)
Block(-5,11,2,CONCRETE:7)
Block(-5,11,3,CONCRETE:7)
Block(-5,11,4,CONCRETE:7)
Block(-5,11,5,CONCRETE:7)
Block(-5,11,6,CONCRETE:7)
Block(-5,11,7,CONCRETE:7)
Block(-5,11,8,CONCRETE:7)
Block(-5,12,-7,CONCRETE:7)
Block(-5,12,-6,CONCRETE:7)
Block(-5,12,-5,CONCRETE:7)
Block(-5,12,-4,CONCRETE:7)
Block(-5,12,-3,CONCRETE:7)
Block(-5,12,-2,CONCRETE:7)
Block(-5,12,-1,CONCRETE:7)
Block(-5,12,0,CONCRETE:7)
Block(-5,12,1,CONCRETE:7)
Block(-5,12,2,CONCRETE:7)
Block(-5,12,3,CONCRETE:7)
Block(-5,12,4,CONCRETE:7)
Block(-5,12,5,CONCRETE:7)
Block(-5,12,6,CONCRETE:7)
Block(-5,12,7,CONCRETE:7)
Block(-5,12,8,CONCRETE:7)
Block(-5,13,-7,CONCRETE:8)
Block(-5,13,-6,CONCRETE:8)
Block(-5,13,-5,CONCRETE:8)
Block(-5,13,-4,CONCRETE:8)
Block(-5,13,-3,CONCRETE:8)
Block(-5,13,-2,CONCRETE:8)
Block(-5,13,-1,CONCRETE:8)
Block(-5,13,0,CONCRETE:8)
Block(-5,13,1,CONCRETE:8)
Block(-5,13,2,CONCRETE:8)
Block(-5,13,3,CONCRETE:8)
Block(-5,13,4,CONCRETE:8)
Block(-5,13,5,CONCRETE:8)
Block(-5,13,6,CONCRETE:8)
Block(-5,13,7,CONCRETE:8)
Block(-5,13,8,CONCRETE:8)
Block(-5,14,-7,CONCRETE:8)
Block(-5,14,-6,CONCRETE:8)
Block(-5,14,-5,AIR:0)
Block(-5,14,-4,AIR:0)
Block(-5,14,-3,AIR:0)
Block(-5,14,-2,CONCRETE:8)
Block(-5,14,-1,CONCRETE:8)
Block(-5,14,0,CONCRETE:8)
Block(-5,14,1,CONCRETE:8)
Block(-5,14,2,CONCRETE:8)
Block(-5,14,3,CONCRETE:8)
Block(-5,14,4,CONCRETE:8)
Block(-5,14,5,CONCRETE:8)
Block(-5,14,6,AIR:0)
Block(-5,14,7,CONCRETE:8)
Block(-5,14,8,IRON_TRAPDOOR:9)
Block(-5,15,-7,CONCRETE:7)
Block(-5,15,-6,CONCRETE:7)
Block(-5,15,-5,AIR:0)
Block(-5,15,-4,AIR:0)
Block(-5,15,-3,AIR:0)
Block(-5,15,-2,CONCRETE:7)
Block(-5,15,-1,CONCRETE:7)
Block(-5,15,0,CONCRETE:7)
Block(-5,15,1,CONCRETE:7)
Block(-5,15,2,CONCRETE:7)
Block(-5,15,3,CONCRETE:7)
Block(-5,15,4,CONCRETE:7)
Block(-5,15,5,CONCRETE:7)
Block(-5,15,6,AIR:0)
Block(-5,15,7,CONCRETE:7)
Block(-5,15,8,IRON_TRAPDOOR:9)
Block(-5,16,-7,CONCRETE:7)
Block(-5,16,-6,CONCRETE:7)
Block(-5,16,-5,STEP:15)
Block(-5,16,-4,STEP:15)
Block(-5,16,-3,STEP:15)
Block(-5,16,-2,CONCRETE:7)
Block(-5,16,-1,CONCRETE:7)
Block(-5,16,0,CONCRETE:7)
Block(-5,16,1,CONCRETE:7)
Block(-5,16,2,CONCRETE:7)
Block(-5,16,3,CONCRETE:7)
Block(-5,16,4,CONCRETE:7)
Block(-5,16,5,CONCRETE:7)
Block(-5,16,6,STEP:15)
Block(-5,16,7,CONCRETE:7)
Block(-5,16,8,AIR:0)
Block(-5,17,-7,CONCRETE:7)
Block(-5,17,-6,CONCRETE:7)
Block(-5,17,-5,CONCRETE:7)
Block(-5,17,-4,CONCRETE:7)
Block(-5,17,-3,CONCRETE:7)
Block(-5,17,-2,CONCRETE:7)
Block(-5,17,-1,CONCRETE:7)
Block(-5,17,0,CONCRETE:7)
Block(-5,17,1,CONCRETE:7)
Block(-5,17,2,CONCRETE:7)
Block(-5,17,3,CONCRETE:7)
Block(-5,17,4,CONCRETE:7)
Block(-5,17,5,CONCRETE:7)
Block(-5,17,6,CONCRETE:7)
Block(-5,17,7,CONCRETE:7)
Block(-5,17,8,CONCRETE:7)
Block(-5,18,-7,STAINED_GLASS_PANE:15)
Block(-5,18,-6,STAINED_GLASS_PANE:15)
Block(-5,18,-4,minecraft:purple_glazed_terracotta:1)
Block(-5,18,0,CARPET:8)
Block(-5,18,1,CARPET:8)
Block(-5,18,2,CARPET:8)
Block(-5,19,-4,minecraft:purple_glazed_terracotta:1)
Block(-5,20,-4,STEP:7)
Block(-5,23,0,minecraft:black_glazed_terracotta)
Block(-5,23,2,CONCRETE:0)
Block(-5,24,-6,CONCRETE:0)
Block(-5,24,-4,CONCRETE:15)
Block(-5,24,-2,CONCRETE:0)
Block(-5,24,0,minecraft:black_glazed_terracotta)
Block(-5,24,2,CONCRETE:0)
Block(-5,24,4,CONCRETE:15)
Block(-5,24,6,CONCRETE:0)
Block(-5,24,8,minecraft:black_glazed_terracotta)
Block(-5,25,-7,CONCRETE:15)
Block(-5,25,-6,CONCRETE:15)
Block(-5,25,-5,CONCRETE:15)
Block(-5,25,-4,CONCRETE:15)
Block(-5,25,-3,CONCRETE:15)
Block(-5,25,-2,CONCRETE:15)
Block(-5,25,-1,CONCRETE:15)
Block(-5,25,0,CONCRETE:15)
Block(-5,25,1,CONCRETE:15)
Block(-5,25,2,CONCRETE:15)
Block(-5,25,3,CONCRETE:15)
Block(-5,25,4,CONCRETE:15)
Block(-5,25,5,CONCRETE:15)
Block(-5,25,6,CONCRETE:15)
Block(-5,25,7,CONCRETE:15)
Block(-5,25,8,CONCRETE:15)
Block(-5,26,-6,CARPET:13)
Block(-5,26,-4,CONCRETE:0)
Block(-5,26,-3,DARK_OAK_STAIRS:1)
Block(-5,26,-1,DARK_OAK_STAIRS:1)
Block(-5,26,1,CONCRETE:0)
Block(-5,26,5,DARK_OAK_STAIRS:1)
Block(-5,26,6,CONCRETE:0)
Block(-5,26,8,CARPET:13)
Block(-5,27,-4,CONCRETE:0)
Block(-5,27,-3,WALL_BANNER:5,NBT/skyscraper_3x3_03/929-bannerC32R16.nbt)
Block(-5,27,-1,WALL_BANNER:5,NBT/skyscraper_3x3_03/930-bannerC32R16.nbt)
Block(-5,27,1,CONCRETE:0)
Block(-5,27,5,WALL_BANNER:5,NBT/skyscraper_3x3_03/931-bannerC32R16.nbt)
Block(-5,27,6,CONCRETE:0)
Block(-5,28,-4,CONCRETE:0)
Block(-5,28,1,CONCRETE:0)
Block(-5,28,6,CONCRETE:0)
Block(-5,29,-7,CONCRETE:15)
Block(-5,29,-6,CONCRETE:15)
Block(-5,29,-5,CONCRETE:15)
Block(-5,29,-4,CONCRETE:15)
Block(-5,29,-3,CONCRETE:15)
Block(-5,29,-2,CONCRETE:15)
Block(-5,29,-1,CONCRETE:15)
Block(-5,29,0,CONCRETE:15)
Block(-5,29,1,CONCRETE:15)
Block(-5,29,2,CONCRETE:15)
Block(-5,29,3,CONCRETE:15)
Block(-5,29,4,CONCRETE:15)
Block(-5,29,5,CONCRETE:15)
Block(-5,29,6,CONCRETE:15)
Block(-5,29,7,CONCRETE:15)
Block(-5,29,8,CONCRETE:15)
Block(-5,30,-6,TRAP_DOOR:6)
Block(-5,30,2,WALL_SIGN:2,NBT/skyscraper_3x3_03/935-signC32R16.nbt)
Block(-5,30,3,BIRCH_WOOD_STAIRS:1)
Block(-5,30,4,FENCE_GATE:7)
Block(-5,30,5,BIRCH_WOOD_STAIRS:1)
Block(-5,30,6,FENCE_GATE:7)
Block(-5,30,7,BIRCH_WOOD_STAIRS:1)
Block(-5,30,8,WALL_SIGN:3,NBT/skyscraper_3x3_03/936-signC32R16.nbt)
Block(-5,31,3,WALL_BANNER:5,NBT/skyscraper_3x3_03/937-bannerC32R16.nbt)
Block(-5,31,5,WALL_BANNER:5,NBT/skyscraper_3x3_03/938-bannerC32R16.nbt)
Block(-5,31,7,WALL_BANNER:5,NBT/skyscraper_3x3_03/939-bannerC32R16.nbt)
Block(-5,33,-7,CONCRETE:15)
Block(-5,33,-6,CONCRETE:15)
Block(-5,33,-5,CONCRETE:15)
Block(-5,33,-4,CONCRETE:15)
Block(-5,33,-3,CONCRETE:15)
Block(-5,33,-2,CONCRETE:15)
Block(-5,33,-1,CONCRETE:15)
Block(-5,33,0,CONCRETE:15)
Block(-5,33,1,CONCRETE:15)
Block(-5,33,2,CONCRETE:15)
Block(-5,33,3,CONCRETE:15)
Block(-5,33,4,CONCRETE:15)
Block(-5,33,5,CONCRETE:15)
Block(-5,33,6,CONCRETE:15)
Block(-5,33,7,CONCRETE:15)
Block(-5,33,8,CONCRETE:15)
Block(-5,34,-7,WOOD_STEP:1)
Block(-5,34,-6,TRAP_DOOR:5)
Block(-5,34,-5,CONCRETE:10)
Block(-5,34,-4,TRAP_DOOR:4)
Block(-5,34,-3,WOOD_STEP:1)
Block(-5,34,-2,TRAP_DOOR:5)
Block(-5,34,-1,CONCRETE:10)
Block(-5,34,0,TRAP_DOOR:4)
Block(-5,34,1,WOOD_STEP:1)
Block(-5,34,2,TRAP_DOOR:5)
Block(-5,34,3,CONCRETE:10)
Block(-5,34,4,TRAP_DOOR:4)
Block(-5,34,5,WOOD_STEP:1)
Block(-5,34,6,TRAP_DOOR:5)
Block(-5,34,7,CONCRETE:10)
Block(-5,34,8,TRAP_DOOR:4)
Block(-5,35,-5,CONCRETE:10)
Block(-5,35,-1,CONCRETE:10)
Block(-5,35,3,CONCRETE:10)
Block(-5,35,7,CONCRETE:10)
Block(-5,36,-5,STEP:7)
Block(-5,36,-1,STEP:7)
Block(-5,36,3,STEP:7)
Block(-5,36,7,STEP:7)
Block(-5,37,-7,CONCRETE:15)
Block(-5,37,-6,CONCRETE:15)
Block(-5,37,-5,CONCRETE:15)
Block(-5,37,-4,CONCRETE:15)
Block(-5,37,-3,CONCRETE:15)
Block(-5,37,-2,CONCRETE:15)
Block(-5,37,-1,CONCRETE:15)
Block(-5,37,0,CONCRETE:15)
Block(-5,37,1,CONCRETE:15)
Block(-5,37,2,CONCRETE:15)
Block(-5,37,3,CONCRETE:15)
Block(-5,37,4,CONCRETE:15)
Block(-5,37,5,CONCRETE:15)
Block(-5,37,6,CONCRETE:15)
Block(-5,37,7,CONCRETE:15)
Block(-5,37,8,CONCRETE:15)
Block(-5,38,-7,WOOD_STEP:1)
Block(-5,38,-6,TRAP_DOOR:5)
Block(-5,38,-5,CONCRETE:10)
Block(-5,38,-4,TRAP_DOOR:4)
Block(-5,38,-3,WOOD_STEP:1)
Block(-5,38,-2,TRAP_DOOR:5)
Block(-5,38,-1,CONCRETE:10)
Block(-5,38,0,TRAP_DOOR:4)
Block(-5,38,1,WOOD_STEP:1)
Block(-5,38,2,TRAP_DOOR:5)
Block(-5,38,3,CONCRETE:10)
Block(-5,38,4,TRAP_DOOR:4)
Block(-5,38,5,WOOD_STEP:1)
Block(-5,38,6,TRAP_DOOR:5)
Block(-5,38,7,CONCRETE:10)
Block(-5,38,8,TRAP_DOOR:4)
Block(-5,39,-5,CONCRETE:10)
Block(-5,39,-1,CONCRETE:10)
Block(-5,39,3,CONCRETE:10)
Block(-5,39,7,CONCRETE:10)
Block(-5,40,-5,STEP:7)
Block(-5,40,-1,STEP:7)
Block(-5,40,3,STEP:7)
Block(-5,40,7,STEP:7)
Block(-5,41,-7,CONCRETE:15)
Block(-5,41,-6,CONCRETE:15)
Block(-5,41,-5,CONCRETE:15)
Block(-5,41,-4,CONCRETE:15)
Block(-5,41,-3,CONCRETE:15)
Block(-5,41,-2,CONCRETE:15)
Block(-5,41,-1,CONCRETE:15)
Block(-5,41,0,CONCRETE:15)
Block(-5,41,1,CONCRETE:15)
Block(-5,41,2,CONCRETE:15)
Block(-5,41,3,CONCRETE:15)
Block(-5,41,4,CONCRETE:15)
Block(-5,41,5,CONCRETE:15)
Block(-5,41,6,CONCRETE:15)
Block(-5,41,7,CONCRETE:15)
Block(-5,41,8,CONCRETE:15)
Block(-5,42,-7,WOOD_STEP:1)
Block(-5,42,-6,TRAP_DOOR:5)
Block(-5,42,-5,CONCRETE:10)
Block(-5,42,-4,TRAP_DOOR:4)
Block(-5,42,-3,WOOD_STEP:1)
Block(-5,42,-2,TRAP_DOOR:5)
Block(-5,42,-1,CONCRETE:10)
Block(-5,42,0,TRAP_DOOR:4)
Block(-5,42,1,WOOD_STEP:1)
Block(-5,42,2,TRAP_DOOR:5)
Block(-5,42,3,CONCRETE:10)
Block(-5,42,4,TRAP_DOOR:4)
Block(-5,42,5,WOOD_STEP:1)
Block(-5,42,6,TRAP_DOOR:5)
Block(-5,42,7,CONCRETE:10)
Block(-5,42,8,TRAP_DOOR:4)
Block(-5,43,-5,CONCRETE:10)
Block(-5,43,-1,CONCRETE:10)
Block(-5,43,3,CONCRETE:10)
Block(-5,43,7,CONCRETE:10)
Block(-5,44,-5,STEP:7)
Block(-5,44,-1,STEP:7)
Block(-5,44,3,STEP:7)
Block(-5,44,7,STEP:7)
Block(-5,45,-7,CONCRETE:15)
Block(-5,45,-6,CONCRETE:15)
Block(-5,45,-5,CONCRETE:15)
Block(-5,45,-4,CONCRETE:15)
Block(-5,45,-3,CONCRETE:15)
Block(-5,45,-2,CONCRETE:15)
Block(-5,45,-1,CONCRETE:15)
Block(-5,45,0,CONCRETE:15)
Block(-5,45,1,CONCRETE:15)
Block(-5,45,2,CONCRETE:15)
Block(-5,45,3,CONCRETE:15)
Block(-5,45,4,CONCRETE:15)
Block(-5,45,5,CONCRETE:15)
Block(-5,45,6,CONCRETE:15)
Block(-5,45,7,CONCRETE:15)
Block(-5,45,8,CONCRETE:15)
Block(-5,46,-7,WOOD_STEP:1)
Block(-5,46,-6,TRAP_DOOR:5)
Block(-5,46,-5,CONCRETE:10)
Block(-5,46,-4,TRAP_DOOR:4)
Block(-5,46,-3,WOOD_STEP:1)
Block(-5,46,-2,TRAP_DOOR:5)
Block(-5,46,-1,CONCRETE:10)
Block(-5,46,0,TRAP_DOOR:4)
Block(-5,46,1,WOOD_STEP:1)
Block(-5,46,2,TRAP_DOOR:5)
Block(-5,46,3,CONCRETE:10)
Block(-5,46,4,TRAP_DOOR:4)
Block(-5,46,5,WOOD_STEP:1)
Block(-5,46,6,TRAP_DOOR:5)
Block(-5,46,7,CONCRETE:10)
Block(-5,46,8,TRAP_DOOR:4)
Block(-5,47,-5,CONCRETE:10)
Block(-5,47,-1,CONCRETE:10)
Block(-5,47,3,CONCRETE:10)
Block(-5,47,7,CONCRETE:10)
Block(-5,48,-5,STEP:7)
Block(-5,48,-1,STEP:7)
Block(-5,48,3,STEP:7)
Block(-5,48,7,STEP:7)
Block(-5,49,-7,CONCRETE:15)
Block(-5,49,-6,CONCRETE:15)
Block(-5,49,-5,CONCRETE:15)
Block(-5,49,-4,CONCRETE:15)
Block(-5,49,-3,CONCRETE:15)
Block(-5,49,-2,CONCRETE:15)
Block(-5,49,-1,CONCRETE:15)
Block(-5,49,0,CONCRETE:15)
Block(-5,49,1,CONCRETE:15)
Block(-5,49,2,CONCRETE:15)
Block(-5,49,3,CONCRETE:15)
Block(-5,49,4,CONCRETE:15)
Block(-5,49,5,CONCRETE:15)
Block(-5,49,6,CONCRETE:15)
Block(-5,49,7,CONCRETE:15)
Block(-5,49,8,CONCRETE:15)
Block(-5,50,-6,TRAP_DOOR:6)
Block(-5,50,2,WALL_SIGN:2,NBT/skyscraper_3x3_03/942-signC32R16.nbt)
Block(-5,50,3,BIRCH_WOOD_STAIRS:1)
Block(-5,50,4,FENCE_GATE:7)
Block(-5,50,5,BIRCH_WOOD_STAIRS:1)
Block(-5,50,6,FENCE_GATE:7)
Block(-5,50,7,BIRCH_WOOD_STAIRS:1)
Block(-5,50,8,WALL_SIGN:3,NBT/skyscraper_3x3_03/943-signC32R16.nbt)
Block(-5,51,3,WALL_BANNER:5,NBT/skyscraper_3x3_03/944-bannerC32R16.nbt)
Block(-5,51,5,WALL_BANNER:5,NBT/skyscraper_3x3_03/945-bannerC32R16.nbt)
Block(-5,51,7,WALL_BANNER:5,NBT/skyscraper_3x3_03/946-bannerC32R16.nbt)
Block(-5,53,-7,CONCRETE:15)
Block(-5,53,-6,CONCRETE:15)
Block(-5,53,-5,CONCRETE:15)
Block(-5,53,-4,CONCRETE:15)
Block(-5,53,-3,CONCRETE:15)
Block(-5,53,-2,CONCRETE:15)
Block(-5,53,-1,CONCRETE:15)
Block(-5,53,0,CONCRETE:15)
Block(-5,53,1,CONCRETE:15)
Block(-5,53,2,CONCRETE:15)
Block(-5,53,3,CONCRETE:15)
Block(-5,53,4,CONCRETE:15)
Block(-5,53,5,CONCRETE:15)
Block(-5,53,6,CONCRETE:15)
Block(-5,53,7,CONCRETE:15)
Block(-5,53,8,CONCRETE:15)
Block(-5,54,-7,WOOD_STEP:1)
Block(-5,54,-6,TRAP_DOOR:5)
Block(-5,54,-5,CONCRETE:10)
Block(-5,54,-4,TRAP_DOOR:4)
Block(-5,54,-3,WOOD_STEP:1)
Block(-5,54,-2,TRAP_DOOR:5)
Block(-5,54,-1,CONCRETE:10)
Block(-5,54,0,TRAP_DOOR:4)
Block(-5,54,1,WOOD_STEP:1)
Block(-5,54,2,TRAP_DOOR:5)
Block(-5,54,3,CONCRETE:10)
Block(-5,54,4,TRAP_DOOR:4)
Block(-5,54,5,WOOD_STEP:1)
Block(-5,54,6,TRAP_DOOR:5)
Block(-5,54,7,CONCRETE:10)
Block(-5,54,8,TRAP_DOOR:4)
Block(-5,55,-5,CONCRETE:10)
Block(-5,55,-1,CONCRETE:10)
Block(-5,55,3,CONCRETE:10)
Block(-5,55,7,CONCRETE:10)
Block(-5,56,-5,STEP:7)
Block(-5,56,-1,STEP:7)
Block(-5,56,3,STEP:7)
Block(-5,56,7,STEP:7)
Block(-5,57,-7,CONCRETE:15)
Block(-5,57,-6,CONCRETE:15)
Block(-5,57,-5,CONCRETE:15)
Block(-5,57,-4,CONCRETE:15)
Block(-5,57,-3,CONCRETE:15)
Block(-5,57,-2,CONCRETE:15)
Block(-5,57,-1,CONCRETE:15)
Block(-5,57,0,CONCRETE:15)
Block(-5,57,1,CONCRETE:15)
Block(-5,57,2,CONCRETE:15)
Block(-5,57,3,CONCRETE:15)
Block(-5,57,4,CONCRETE:15)
Block(-5,57,5,CONCRETE:15)
Block(-5,57,6,CONCRETE:15)
Block(-5,57,7,CONCRETE:15)
Block(-5,57,8,CONCRETE:15)
Block(-5,58,-7,WOOD_STEP:1)
Block(-5,58,-6,TRAP_DOOR:5)
Block(-5,58,-5,CONCRETE:10)
Block(-5,58,-4,TRAP_DOOR:4)
Block(-5,58,-3,WOOD_STEP:1)
Block(-5,58,-2,TRAP_DOOR:5)
Block(-5,58,-1,CONCRETE:10)
Block(-5,58,0,TRAP_DOOR:4)
Block(-5,58,1,WOOD_STEP:1)
Block(-5,58,2,TRAP_DOOR:5)
Block(-5,58,3,CONCRETE:10)
Block(-5,58,4,TRAP_DOOR:4)
Block(-5,58,5,WOOD_STEP:1)
Block(-5,58,6,TRAP_DOOR:5)
Block(-5,58,7,CONCRETE:10)
Block(-5,58,8,TRAP_DOOR:4)
Block(-5,59,-5,CONCRETE:10)
Block(-5,59,-1,CONCRETE:10)
Block(-5,59,3,CONCRETE:10)
Block(-5,59,7,CONCRETE:10)
Block(-5,60,-5,STEP:7)
Block(-5,60,-1,STEP:7)
Block(-5,60,3,STEP:7)
Block(-5,60,7,STEP:7)
Block(-5,61,-7,CONCRETE:15)
Block(-5,61,-6,CONCRETE:15)
Block(-5,61,-5,CONCRETE:15)
Block(-5,61,-4,CONCRETE:15)
Block(-5,61,-3,CONCRETE:15)
Block(-5,61,-2,CONCRETE:15)
Block(-5,61,-1,CONCRETE:15)
Block(-5,61,0,CONCRETE:15)
Block(-5,61,1,CONCRETE:15)
Block(-5,61,2,CONCRETE:15)
Block(-5,61,3,CONCRETE:15)
Block(-5,61,4,CONCRETE:15)
Block(-5,61,5,CONCRETE:15)
Block(-5,61,6,CONCRETE:15)
Block(-5,61,7,CONCRETE:15)
Block(-5,61,8,CONCRETE:15)
Block(-5,62,-7,WOOD_STEP:1)
Block(-5,62,-6,TRAP_DOOR:5)
Block(-5,62,-5,CONCRETE:10)
Block(-5,62,-4,TRAP_DOOR:4)
Block(-5,62,-3,WOOD_STEP:1)
Block(-5,62,-2,TRAP_DOOR:5)
Block(-5,62,-1,CONCRETE:10)
Block(-5,62,0,TRAP_DOOR:4)
Block(-5,62,1,WOOD_STEP:1)
Block(-5,62,2,TRAP_DOOR:5)
Block(-5,62,3,CONCRETE:10)
Block(-5,62,4,TRAP_DOOR:4)
Block(-5,62,5,WOOD_STEP:1)
Block(-5,62,6,TRAP_DOOR:5)
Block(-5,62,7,CONCRETE:10)
Block(-5,62,8,TRAP_DOOR:4)
Block(-5,63,-5,CONCRETE:10)
Block(-5,63,-1,CONCRETE:10)
Block(-5,63,3,CONCRETE:10)
Block(-5,63,7,CONCRETE:10)
Block(-5,64,-5,STEP:7)
Block(-5,64,-1,STEP:7)
Block(-5,64,3,STEP:7)
Block(-5,64,7,STEP:7)
Block(-5,65,-7,CONCRETE:15)
Block(-5,65,-6,CONCRETE:15)
Block(-5,65,-5,CONCRETE:15)
Block(-5,65,-4,CONCRETE:15)
Block(-5,65,-3,CONCRETE:15)
Block(-5,65,-2,CONCRETE:15)
Block(-5,65,-1,CONCRETE:15)
Block(-5,65,0,CONCRETE:15)
Block(-5,65,1,CONCRETE:15)
Block(-5,65,2,CONCRETE:15)
Block(-5,65,3,CONCRETE:15)
Block(-5,65,4,CONCRETE:15)
Block(-5,65,5,CONCRETE:15)
Block(-5,65,6,CONCRETE:15)
Block(-5,65,7,CONCRETE:15)
Block(-5,65,8,CONCRETE:15)
Block(-5,66,-7,WOOD_STEP:1)
Block(-5,66,-6,TRAP_DOOR:5)
Block(-5,66,-5,CONCRETE:10)
Block(-5,66,-4,TRAP_DOOR:4)
Block(-5,66,-3,WOOD_STEP:1)
Block(-5,66,-2,TRAP_DOOR:5)
Block(-5,66,-1,CONCRETE:10)
Block(-5,66,0,TRAP_DOOR:4)
Block(-5,66,1,WOOD_STEP:1)
Block(-5,66,2,TRAP_DOOR:5)
Block(-5,66,3,CONCRETE:10)
Block(-5,66,4,TRAP_DOOR:4)
Block(-5,66,5,WOOD_STEP:1)
Block(-5,66,6,TRAP_DOOR:5)
Block(-5,66,7,CONCRETE:10)
Block(-5,66,8,TRAP_DOOR:4)
Block(-5,67,-5,CONCRETE:10)
Block(-5,67,-1,CONCRETE:10)
Block(-5,67,3,CONCRETE:10)
Block(-5,67,7,CONCRETE:10)
Block(-5,68,-5,STEP:7)
Block(-5,68,-1,STEP:7)
Block(-5,68,3,STEP:7)
Block(-5,68,7,STEP:7)
Block(-5,69,-7,CONCRETE:15)
Block(-5,69,-6,CONCRETE:15)
Block(-5,69,-5,CONCRETE:15)
Block(-5,69,-4,CONCRETE:15)
Block(-5,69,-3,CONCRETE:15)
Block(-5,69,-2,CONCRETE:15)
Block(-5,69,-1,CONCRETE:15)
Block(-5,69,0,CONCRETE:15)
Block(-5,69,1,CONCRETE:15)
Block(-5,69,2,CONCRETE:15)
Block(-5,69,3,CONCRETE:15)
Block(-5,69,4,CONCRETE:15)
Block(-5,69,5,CONCRETE:15)
Block(-5,69,6,CONCRETE:15)
Block(-5,69,7,CONCRETE:15)
Block(-5,69,8,CONCRETE:15)
Block(-5,70,-6,TRAP_DOOR:6)
Block(-5,70,2,WALL_SIGN:2,NBT/skyscraper_3x3_03/949-signC32R16.nbt)
Block(-5,70,3,BIRCH_WOOD_STAIRS:1)
Block(-5,70,4,FENCE_GATE:7)
Block(-5,70,5,BIRCH_WOOD_STAIRS:1)
Block(-5,70,6,FENCE_GATE:7)
Block(-5,70,7,BIRCH_WOOD_STAIRS:1)
Block(-5,70,8,WALL_SIGN:3,NBT/skyscraper_3x3_03/950-signC32R16.nbt)
Block(-5,71,3,WALL_BANNER:5,NBT/skyscraper_3x3_03/951-bannerC32R16.nbt)
Block(-5,71,5,WALL_BANNER:5,NBT/skyscraper_3x3_03/952-bannerC32R16.nbt)
Block(-5,71,7,WALL_BANNER:5,NBT/skyscraper_3x3_03/953-bannerC32R16.nbt)
Block(-5,73,-7,CONCRETE:15)
Block(-5,73,-6,CONCRETE:15)
Block(-5,73,-5,CONCRETE:15)
Block(-5,73,-4,CONCRETE:15)
Block(-5,73,-3,CONCRETE:15)
Block(-5,73,-2,CONCRETE:15)
Block(-5,73,-1,CONCRETE:15)
Block(-5,73,0,CONCRETE:15)
Block(-5,73,1,CONCRETE:15)
Block(-5,73,2,CONCRETE:15)
Block(-5,73,3,CONCRETE:15)
Block(-5,73,4,CONCRETE:15)
Block(-5,73,5,CONCRETE:15)
Block(-5,73,6,CONCRETE:15)
Block(-5,73,7,CONCRETE:15)
Block(-5,73,8,CONCRETE:15)
Block(-5,74,-7,WOOD_STEP:1)
Block(-5,74,-6,TRAP_DOOR:5)
Block(-5,74,-5,CONCRETE:10)
Block(-5,74,-4,TRAP_DOOR:4)
Block(-5,74,-3,WOOD_STEP:1)
Block(-5,74,-2,TRAP_DOOR:5)
Block(-5,74,-1,CONCRETE:10)
Block(-5,74,0,TRAP_DOOR:4)
Block(-5,74,1,WOOD_STEP:1)
Block(-5,74,2,TRAP_DOOR:5)
Block(-5,74,3,CONCRETE:10)
Block(-5,74,4,TRAP_DOOR:4)
Block(-5,74,5,WOOD_STEP:1)
Block(-5,74,6,TRAP_DOOR:5)
Block(-5,74,7,CONCRETE:10)
Block(-5,74,8,TRAP_DOOR:4)
Block(-5,75,-5,CONCRETE:10)
Block(-5,75,-1,CONCRETE:10)
Block(-5,75,3,CONCRETE:10)
Block(-5,75,7,CONCRETE:10)
Block(-5,76,-5,STEP:7)
Block(-5,76,-1,STEP:7)
Block(-5,76,3,STEP:7)
Block(-5,76,7,STEP:7)
Block(-5,77,-7,CONCRETE:15)
Block(-5,77,-6,CONCRETE:15)
Block(-5,77,-5,CONCRETE:15)
Block(-5,77,-4,CONCRETE:15)
Block(-5,77,-3,CONCRETE:15)
Block(-5,77,-2,CONCRETE:15)
Block(-5,77,-1,CONCRETE:15)
Block(-5,77,0,CONCRETE:15)
Block(-5,77,1,CONCRETE:15)
Block(-5,77,2,CONCRETE:15)
Block(-5,77,3,CONCRETE:15)
Block(-5,77,4,CONCRETE:15)
Block(-5,77,5,CONCRETE:15)
Block(-5,77,6,CONCRETE:15)
Block(-5,77,7,CONCRETE:15)
Block(-5,77,8,CONCRETE:15)
Block(-5,78,-7,WOOD_STEP:1)
Block(-5,78,-6,TRAP_DOOR:5)
Block(-5,78,-5,CONCRETE:10)
Block(-5,78,-4,TRAP_DOOR:4)
Block(-5,78,-3,WOOD_STEP:1)
Block(-5,78,-2,TRAP_DOOR:5)
Block(-5,78,-1,CONCRETE:10)
Block(-5,78,0,TRAP_DOOR:4)
Block(-5,78,1,WOOD_STEP:1)
Block(-5,78,2,TRAP_DOOR:5)
Block(-5,78,3,CONCRETE:10)
Block(-5,78,4,TRAP_DOOR:4)
Block(-5,78,5,WOOD_STEP:1)
Block(-5,78,6,TRAP_DOOR:5)
Block(-5,78,7,CONCRETE:10)
Block(-5,78,8,TRAP_DOOR:4)
Block(-5,79,-5,CONCRETE:10)
Block(-5,79,-1,CONCRETE:10)
Block(-5,79,3,CONCRETE:10)
Block(-5,79,7,CONCRETE:10)
Block(-5,80,-5,STEP:7)
Block(-5,80,-1,STEP:7)
Block(-5,80,3,STEP:7)
Block(-5,80,7,STEP:7)
Block(-5,81,-7,CONCRETE:15)
Block(-5,81,-6,CONCRETE:15)
Block(-5,81,-5,CONCRETE:15)
Block(-5,81,-4,CONCRETE:15)
Block(-5,81,-3,CONCRETE:15)
Block(-5,81,-2,CONCRETE:15)
Block(-5,81,-1,CONCRETE:15)
Block(-5,81,0,CONCRETE:15)
Block(-5,81,1,CONCRETE:15)
Block(-5,81,2,CONCRETE:15)
Block(-5,81,3,CONCRETE:15)
Block(-5,81,4,CONCRETE:15)
Block(-5,81,5,CONCRETE:15)
Block(-5,81,6,CONCRETE:15)
Block(-5,81,7,CONCRETE:15)
Block(-5,81,8,CONCRETE:15)
Block(-5,82,-7,WOOD_STEP:1)
Block(-5,82,-6,TRAP_DOOR:5)
Block(-5,82,-5,CONCRETE:10)
Block(-5,82,-4,TRAP_DOOR:4)
Block(-5,82,-3,WOOD_STEP:1)
Block(-5,82,-2,TRAP_DOOR:5)
Block(-5,82,-1,CONCRETE:10)
Block(-5,82,0,TRAP_DOOR:4)
Block(-5,82,1,WOOD_STEP:1)
Block(-5,82,2,TRAP_DOOR:5)
Block(-5,82,3,CONCRETE:10)
Block(-5,82,4,TRAP_DOOR:4)
Block(-5,82,5,WOOD_STEP:1)
Block(-5,82,6,TRAP_DOOR:5)
Block(-5,82,7,CONCRETE:10)
Block(-5,82,8,TRAP_DOOR:4)
Block(-5,83,-5,CONCRETE:10)
Block(-5,83,-1,CONCRETE:10)
Block(-5,83,3,CONCRETE:10)
Block(-5,83,7,CONCRETE:10)
Block(-5,84,-5,STEP:7)
Block(-5,84,-1,STEP:7)
Block(-5,84,3,STEP:7)
Block(-5,84,7,STEP:7)
Block(-5,85,-7,CONCRETE:15)
Block(-5,85,-6,CONCRETE:15)
Block(-5,85,-5,CONCRETE:15)
Block(-5,85,-4,CONCRETE:15)
Block(-5,85,-3,CONCRETE:15)
Block(-5,85,-2,CONCRETE:15)
Block(-5,85,-1,CONCRETE:15)
Block(-5,85,0,CONCRETE:15)
Block(-5,85,1,CONCRETE:15)
Block(-5,85,2,CONCRETE:15)
Block(-5,85,3,CONCRETE:15)
Block(-5,85,4,CONCRETE:15)
Block(-5,85,5,CONCRETE:15)
Block(-5,85,6,CONCRETE:15)
Block(-5,85,7,CONCRETE:15)
Block(-5,85,8,CONCRETE:15)
Block(-5,86,-7,DAYLIGHT_DETECTOR_INVERTED:1,NBT/skyscraper_3x3_03/955-daylight_detectorC32R16.nbt)
Block(-5,86,-6,DAYLIGHT_DETECTOR_INVERTED:1,NBT/skyscraper_3x3_03/956-daylight_detectorC32R16.nbt)
Block(-5,86,-5,DAYLIGHT_DETECTOR_INVERTED:1,NBT/skyscraper_3x3_03/957-daylight_detectorC32R16.nbt)
Block(-5,86,-4,DAYLIGHT_DETECTOR_INVERTED:1,NBT/skyscraper_3x3_03/958-daylight_detectorC32R16.nbt)
Block(-5,86,-3,DAYLIGHT_DETECTOR_INVERTED:1,NBT/skyscraper_3x3_03/959-daylight_detectorC32R16.nbt)
Block(-5,86,-2,DAYLIGHT_DETECTOR_INVERTED:1,NBT/skyscraper_3x3_03/960-daylight_detectorC32R16.nbt)
Block(-5,86,-1,DAYLIGHT_DETECTOR_INVERTED:1,NBT/skyscraper_3x3_03/961-daylight_detectorC32R16.nbt)
Block(-5,86,0,DAYLIGHT_DETECTOR_INVERTED:1,NBT/skyscraper_3x3_03/962-daylight_detectorC32R16.nbt)
Block(-5,86,1,DAYLIGHT_DETECTOR_INVERTED:1,NBT/skyscraper_3x3_03/963-daylight_detectorC32R16.nbt)
Block(-5,86,2,DAYLIGHT_DETECTOR_INVERTED:1,NBT/skyscraper_3x3_03/964-daylight_detectorC32R16.nbt)
Block(-5,86,3,DAYLIGHT_DETECTOR_INVERTED:1,NBT/skyscraper_3x3_03/965-daylight_detectorC32R16.nbt)
Block(-5,86,4,DAYLIGHT_DETECTOR_INVERTED:1,NBT/skyscraper_3x3_03/966-daylight_detectorC32R16.nbt)
Block(-5,86,5,DAYLIGHT_DETECTOR_INVERTED:1,NBT/skyscraper_3x3_03/967-daylight_detectorC32R16.nbt)
Block(-5,86,6,DAYLIGHT_DETECTOR_INVERTED:1,NBT/skyscraper_3x3_03/968-daylight_detectorC32R16.nbt)
Block(-5,86,7,DAYLIGHT_DETECTOR_INVERTED:1,NBT/skyscraper_3x3_03/969-daylight_detectorC32R16.nbt)
Block(-5,86,8,DAYLIGHT_DETECTOR_INVERTED:1,NBT/skyscraper_3x3_03/970-daylight_detectorC32R16.nbt)
Block(-4,0,-7,CONCRETE:7)
Block(-4,0,-6,CONCRETE:7)
Block(-4,0,-5,CONCRETE:7)
Block(-4,0,-4,CONCRETE:7)
Block(-4,0,-3,CONCRETE:7)
Block(-4,0,-2,CONCRETE:7)
Block(-4,0,-1,CONCRETE:7)
Block(-4,0,0,CONCRETE:7)
Block(-4,0,1,CONCRETE:7)
Block(-4,0,2,CONCRETE:7)
Block(-4,0,3,CONCRETE:7)
Block(-4,0,4,CONCRETE:7)
Block(-4,0,5,CONCRETE:7)
Block(-4,0,6,CONCRETE:7)
Block(-4,0,7,CONCRETE:7)
Block(-4,0,8,CONCRETE:7)
Block(-4,1,-7,CONCRETE:7)
Block(-4,1,-6,CONCRETE:7)
Block(-4,1,-5,CONCRETE:7)
Block(-4,1,-4,CONCRETE:7)
Block(-4,1,-3,CONCRETE:7)
Block(-4,1,-2,CONCRETE:7)
Block(-4,1,-1,CONCRETE:7)
Block(-4,1,0,CONCRETE:7)
Block(-4,1,1,CONCRETE:7)
Block(-4,1,2,CONCRETE:7)
Block(-4,1,3,CONCRETE:7)
Block(-4,1,4,CONCRETE:7)
Block(-4,1,5,CONCRETE:7)
Block(-4,1,6,CONCRETE:7)
Block(-4,1,7,CONCRETE:7)
Block(-4,1,8,CONCRETE:7)
Block(-4,2,-7,CONCRETE:7)
Block(-4,2,-6,CONCRETE:7)
Block(-4,2,-5,CONCRETE:7)
Block(-4,2,-4,CONCRETE:7)
Block(-4,2,-3,CONCRETE:7)
Block(-4,2,-2,CONCRETE:7)
Block(-4,2,-1,CONCRETE:7)
Block(-4,2,0,CONCRETE:7)
Block(-4,2,1,CONCRETE:7)
Block(-4,2,2,CONCRETE:7)
Block(-4,2,3,CONCRETE:7)
Block(-4,2,4,CONCRETE:7)
Block(-4,2,5,CONCRETE:7)
Block(-4,2,6,CONCRETE:7)
Block(-4,2,7,CONCRETE:7)
Block(-4,2,8,CONCRETE:7)
Block(-4,3,-7,CONCRETE:7)
Block(-4,3,-6,CONCRETE:7)
Block(-4,3,-5,CONCRETE:7)
Block(-4,3,-4,CONCRETE:7)
Block(-4,3,-3,CONCRETE:7)
Block(-4,3,-2,CONCRETE:7)
Block(-4,3,-1,CONCRETE:7)
Block(-4,3,0,CONCRETE:7)
Block(-4,3,1,CONCRETE:7)
Block(-4,3,2,CONCRETE:7)
Block(-4,3,3,CONCRETE:7)
Block(-4,3,4,CONCRETE:7)
Block(-4,3,5,CONCRETE:7)
Block(-4,3,6,CONCRETE:7)
Block(-4,3,7,CONCRETE:7)
Block(-4,3,8,CONCRETE:7)
Block(-4,4,-7,CONCRETE:7)
Block(-4,4,-6,CONCRETE:7)
Block(-4,4,-5,CONCRETE:7)
Block(-4,4,-4,CONCRETE:7)
Block(-4,4,-3,CONCRETE:7)
Block(-4,4,-2,CONCRETE:7)
Block(-4,4,-1,CONCRETE:7)
Block(-4,4,0,CONCRETE:7)
Block(-4,4,1,CONCRETE:7)
Block(-4,4,2,CONCRETE:7)
Block(-4,4,3,CONCRETE:7)
Block(-4,4,4,CONCRETE:7)
Block(-4,4,5,CONCRETE:7)
Block(-4,4,6,CONCRETE:7)
Block(-4,4,7,CONCRETE:7)
Block(-4,4,8,CONCRETE:7)
Block(-4,5,-7,CONCRETE:7)
Block(-4,5,-6,CONCRETE:7)
Block(-4,5,-5,CONCRETE:7)
Block(-4,5,-4,CONCRETE:7)
Block(-4,5,-3,CONCRETE:7)
Block(-4,5,-2,CONCRETE:7)
Block(-4,5,-1,CONCRETE:7)
Block(-4,5,0,CONCRETE:7)
Block(-4,5,1,CONCRETE:7)
Block(-4,5,2,CONCRETE:7)
Block(-4,5,3,CONCRETE:7)
Block(-4,5,4,CONCRETE:7)
Block(-4,5,5,CONCRETE:7)
Block(-4,5,6,CONCRETE:7)
Block(-4,5,7,CONCRETE:7)
Block(-4,5,8,CONCRETE:7)
Block(-4,6,-7,CONCRETE:7)
Block(-4,6,-6,CONCRETE:7)
Block(-4,6,-5,CONCRETE:7)
Block(-4,6,-4,CONCRETE:7)
Block(-4,6,-3,CONCRETE:7)
Block(-4,6,-2,CONCRETE:7)
Block(-4,6,-1,CONCRETE:7)
Block(-4,6,0,CONCRETE:7)
Block(-4,6,1,CONCRETE:7)
Block(-4,6,2,CONCRETE:7)
Block(-4,6,3,CONCRETE:7)
Block(-4,6,4,CONCRETE:7)
Block(-4,6,5,CONCRETE:7)
Block(-4,6,6,CONCRETE:7)
Block(-4,6,7,CONCRETE:7)
Block(-4,6,8,CONCRETE:7)
Block(-4,7,-7,CONCRETE:7)
Block(-4,7,-6,CONCRETE:7)
Block(-4,7,-5,CONCRETE:7)
Block(-4,7,-4,CONCRETE:7)
Block(-4,7,-3,CONCRETE:7)
Block(-4,7,-2,CONCRETE:7)
Block(-4,7,-1,CONCRETE:7)
Block(-4,7,0,CONCRETE:7)
Block(-4,7,1,CONCRETE:7)
Block(-4,7,2,CONCRETE:7)
Block(-4,7,3,CONCRETE:7)
Block(-4,7,4,CONCRETE:7)
Block(-4,7,5,CONCRETE:7)
Block(-4,7,6,CONCRETE:7)
Block(-4,7,7,CONCRETE:7)
Block(-4,7,8,CONCRETE:7)
Block(-4,8,-7,CONCRETE:7)
Block(-4,8,-6,CONCRETE:7)
Block(-4,8,-5,CONCRETE:7)
Block(-4,8,-4,CONCRETE:7)
Block(-4,8,-3,CONCRETE:7)
Block(-4,8,-2,CONCRETE:7)
Block(-4,8,-1,CONCRETE:7)
Block(-4,8,0,CONCRETE:7)
Block(-4,8,1,CONCRETE:7)
Block(-4,8,2,CONCRETE:7)
Block(-4,8,3,CONCRETE:7)
Block(-4,8,4,CONCRETE:7)
Block(-4,8,5,CONCRETE:7)
Block(-4,8,6,CONCRETE:7)
Block(-4,8,7,CONCRETE:7)
Block(-4,8,8,CONCRETE:7)
Block(-4,9,-7,CONCRETE:7)
Block(-4,9,-6,CONCRETE:7)
Block(-4,9,-5,CONCRETE:7)
Block(-4,9,-4,CONCRETE:7)
Block(-4,9,-3,CONCRETE:7)
Block(-4,9,-2,CONCRETE:7)
Block(-4,9,-1,CONCRETE:7)
Block(-4,9,0,CONCRETE:7)
Block(-4,9,1,CONCRETE:7)
Block(-4,9,2,CONCRETE:7)
Block(-4,9,3,CONCRETE:7)
Block(-4,9,4,CONCRETE:7)
Block(-4,9,5,CONCRETE:7)
Block(-4,9,6,CONCRETE:7)
Block(-4,9,7,CONCRETE:7)
Block(-4,9,8,CONCRETE:7)
Block(-4,10,-7,CONCRETE:7)
Block(-4,10,-6,CONCRETE:7)
Block(-4,10,-5,CONCRETE:7)
Block(-4,10,-4,CONCRETE:7)
Block(-4,10,-3,CONCRETE:7)
Block(-4,10,-2,CONCRETE:7)
Block(-4,10,-1,CONCRETE:7)
Block(-4,10,0,CONCRETE:7)
Block(-4,10,1,CONCRETE:7)
Block(-4,10,2,CONCRETE:7)
Block(-4,10,3,CONCRETE:7)
Block(-4,10,4,CONCRETE:7)
Block(-4,10,5,CONCRETE:7)
Block(-4,10,6,CONCRETE:7)
Block(-4,10,7,CONCRETE:7)
Block(-4,10,8,CONCRETE:7)
Block(-4,11,-7,CONCRETE:7)
Block(-4,11,-6,CONCRETE:7)
Block(-4,11,-5,CONCRETE:7)
Block(-4,11,-4,CONCRETE:7)
Block(-4,11,-3,CONCRETE:7)
Block(-4,11,-2,CONCRETE:7)
Block(-4,11,-1,CONCRETE:7)
Block(-4,11,0,CONCRETE:7)
Block(-4,11,1,CONCRETE:7)
Block(-4,11,2,CONCRETE:7)
Block(-4,11,3,CONCRETE:7)
Block(-4,11,4,CONCRETE:7)
Block(-4,11,5,CONCRETE:7)
Block(-4,11,6,CONCRETE:7)
Block(-4,11,7,CONCRETE:7)
Block(-4,11,8,CONCRETE:7)
Block(-4,12,-7,CONCRETE:7)
Block(-4,12,-6,CONCRETE:7)
Block(-4,12,-5,CONCRETE:7)
Block(-4,12,-4,CONCRETE:7)
Block(-4,12,-3,CONCRETE:7)
Block(-4,12,-2,CONCRETE:7)
Block(-4,12,-1,CONCRETE:7)
Block(-4,12,0,CONCRETE:7)
Block(-4,12,1,CONCRETE:7)
Block(-4,12,2,CONCRETE:7)
Block(-4,12,3,CONCRETE:7)
Block(-4,12,4,CONCRETE:7)
Block(-4,12,5,CONCRETE:7)
Block(-4,12,6,CONCRETE:7)
Block(-4,12,7,CONCRETE:7)
Block(-4,12,8,CONCRETE:7)
Block(-4,13,-7,CONCRETE:8)
Block(-4,13,-6,CONCRETE:8)
Block(-4,13,-5,CONCRETE:8)
Block(-4,13,-4,CONCRETE:8)
Block(-4,13,-3,CONCRETE:8)
