
#######################################################################
# +-----------------------------------------------------------------+ #
# |                            BO4 object                           | #
# +-----------------------------------------------------------------+ #
#######################################################################

Author: NLBlackEagle

Description: No description given

SettingsMode: WriteDisable


#######################################################################
# +-----------------------------------------------------------------+ #
# |                          Main settings                          | #
# +-----------------------------------------------------------------+ #
#######################################################################

Frequency: 0

SpawnHeight: highestBlock

UseCenterForHighestBlock: true

##############################
# Height Limits for the BO4. #
##############################

MinHeight: 0

MaxHeight: 255

InheritBO3: 

InheritBO3Rotation: NORTH

OverrideChildSettings: true

OverrideParentHeight: false

CanOverride: true

BranchFrequency: 0

BranchFrequencyGroup: 

MustBeBelowOther: false

MustBeInside: 

CannotBeInside: 

ReplacesBO3: L4-M-CrossC0R0, L4-M-CrossC0R1, L4-M-CrossC0R2, L4-M-CrossC0R3, L4-M-CrossC1R0, L4-M-CrossC1R1, L4-M-CrossC1R2, L4-M-CrossC1R3, L4-M-CrossC2R0, L4-M-CrossC2R1, L4-M-CrossC2R2, L4-M-CrossC2R3, L4-M-CrossC3R0, L4-M-CrossC3R1, L4-M-CrossC3R2, L4-M-CrossC3R3, L4-M-Straigth-START_01-C0R0, L4-M-Straigth-START_01-C0R1, L4-M-Straigth-START_01-C1R0, L4-M-Straigth-START_01-C1R1, L4-M-Straigth-START_01-C2R0, L4-M-Straigth-START_01-C2R1, L4-M-Straigth-START_01-C3R0, L4-M-Straigth-START_01-C3R1, L4-M-Straigth-3CC0R0, L4-M-Straigth-3CC0R1, L4-M-Straigth-3CC0R2, L4-M-Straigth-3CC1R0, L4-M-Straigth-3CC1R1, L4-M-Straigth-3CC1R2, L4-M-Straigth-3CC2R0, L4-M-Straigth-3CC2R1, L4-M-Straigth-3CC2R2, L4-M-Straigth-3CC3R0, L4-M-Straigth-3CC3R1, L4-M-Straigth-3CC3R2, L4-M-Cross, skyscraper_2x2_01, skyscraper_2x2_02, skyscraper_2x2_03, skyscraper_2x2_04, skyscraper_2x2_05, skyscraper_3x3_01, skyscraper_3x3_02, skyscraper_3x3_03, L3-M-Straigth-2CC0R0, L3-M-Straigth-2CC0R1, L3-M-Straigth-2CC1R0, L3-M-Straigth-2CC1R1, L3-M-Straigth-2CC2R0, L3-M-Straigth-2CC2R1, L3-M-Straigth-2CC3R0, L3-M-Straigth-2CC3R1, L3-M-Straigth-3CC0R0, L3-M-Straigth-3CC0R1, L3-M-Straigth-3CC0R2, L3-M-Straigth-3CC1R0, L3-M-Straigth-3CC1R1, L3-M-Straigth-3CC1R2, L3-M-Straigth-3CC2R0, L3-M-Straigth-3CC2R1, L3-M-Straigth-3CC2R2, L3-M-Straigth-3CC3R0, L3-M-Straigth-3CC3R1, L3-M-Straigth-3CC3R2

MustBeInsideWorldBorders: false

CanSpawnOnWater: true

SpawnOnWaterOnly: false

SpawnUnderWater: false

SpawnAtWaterLevel: false

HeightOffset: 0

RemoveAir: false

ReplaceAbove: 

ReplaceBelow: 

ReplaceWithBiomeBlocks: true

ReplaceWithSurfaceBlock: GRASS

ReplaceWithGroundBlock: DIRT

ReplaceWithStoneBlock: STONE

SmoothRadius: 0

SmoothHeightOffset: 0

SmoothStartTop: false

SmoothStartWood: false

SmoothingSurfaceBlock: 

SmoothingGroundBlock: 

BO3Group: 

IsSpawnPoint: false

DoReplaceBlocks: true


#######################################################################
# +-----------------------------------------------------------------+ #
# |                              Blocks                             | #
# +-----------------------------------------------------------------+ #
#######################################################################

Block(-8,0,-7,CONCRETE:7)
Block(-8,0,-6,CONCRETE:7)
Block(-8,0,-5,CONCRETE:7)
Block(-8,0,-4,CONCRETE:7)
Block(-8,0,-3,CONCRETE:7)
Block(-8,0,-2,CONCRETE:7)
Block(-8,0,-1,CONCRETE:7)
Block(-8,0,0,CONCRETE:7)
Block(-8,0,1,CONCRETE:7)
Block(-8,0,2,CONCRETE:7)
Block(-8,0,3,CONCRETE:7)
Block(-8,0,4,CONCRETE:7)
Block(-8,0,5,CONCRETE:7)
Block(-8,0,6,CONCRETE:7)
Block(-8,0,7,CONCRETE:7)
Block(-8,0,8,CONCRETE:7)
Block(-8,1,-7,AIR:0)
Block(-8,1,-6,AIR:0)
Block(-8,1,-5,AIR:0)
Block(-8,1,-4,SMOOTH_STAIRS:2)
Block(-8,1,-3,CONCRETE:7)
Block(-8,1,-2,CONCRETE:7)
Block(-8,1,-1,CONCRETE:7)
Block(-8,1,0,CONCRETE:7)
Block(-8,1,1,CONCRETE:7)
Block(-8,1,2,CONCRETE:7)
Block(-8,1,3,STATIONARY_WATER:0)
Block(-8,1,4,STATIONARY_WATER:0)
Block(-8,1,5,CONCRETE:7)
Block(-8,1,6,CONCRETE:7)
Block(-8,1,7,CONCRETE:7)
Block(-8,1,8,CONCRETE:7)
Block(-8,2,-7,IRON_TRAPDOOR:9)
Block(-8,2,-6,IRON_TRAPDOOR:11)
Block(-8,2,-5,AIR:0)
Block(-8,2,-4,AIR:0)
Block(-8,2,-3,SMOOTH_STAIRS:2)
Block(-8,2,-2,CONCRETE:7)
Block(-8,2,-1,CONCRETE:7)
Block(-8,2,0,CONCRETE:7)
Block(-8,2,1,CONCRETE:7)
Block(-8,2,2,SMOOTH_STAIRS:3)
Block(-8,2,3,AIR:0)
Block(-8,2,4,AIR:0)
Block(-8,2,5,SMOOTH_STAIRS:2)
Block(-8,2,6,CONCRETE:7)
Block(-8,2,7,CONCRETE:7)
Block(-8,2,8,CONCRETE:7)
Block(-8,3,-7,AIR:0)
Block(-8,3,-6,AIR:0)
Block(-8,3,-5,AIR:0)
Block(-8,3,-4,AIR:0)
Block(-8,3,-3,AIR:0)
Block(-8,3,-2,AIR:0)
Block(-8,3,-1,AIR:0)
Block(-8,3,0,AIR:0)
Block(-8,3,1,AIR:0)
Block(-8,3,2,AIR:0)
Block(-8,3,3,AIR:0)
Block(-8,3,4,AIR:0)
Block(-8,3,5,AIR:0)
Block(-8,3,6,AIR:0)
Block(-8,3,7,AIR:0)
Block(-8,3,8,CONCRETE:7)
Block(-8,4,-7,AIR:0)
Block(-8,4,-6,AIR:0)
Block(-8,4,-5,AIR:0)
Block(-8,4,-4,AIR:0)
Block(-8,4,-3,AIR:0)
Block(-8,4,-2,AIR:0)
Block(-8,4,-1,AIR:0)
Block(-8,4,0,AIR:0)
Block(-8,4,1,AIR:0)
Block(-8,4,2,AIR:0)
Block(-8,4,3,AIR:0)
Block(-8,4,4,AIR:0)
Block(-8,4,5,AIR:0)
Block(-8,4,6,AIR:0)
Block(-8,4,7,AIR:0)
Block(-8,4,8,CONCRETE:7)
Block(-8,5,-7,AIR:0)
Block(-8,5,-6,AIR:0)
Block(-8,5,-5,AIR:0)
Block(-8,5,-4,AIR:0)
Block(-8,5,-3,AIR:0)
Block(-8,5,-2,AIR:0)
Block(-8,5,-1,AIR:0)
Block(-8,5,0,AIR:0)
Block(-8,5,1,AIR:0)
Block(-8,5,2,AIR:0)
Block(-8,5,3,AIR:0)
Block(-8,5,4,AIR:0)
Block(-8,5,5,AIR:0)
Block(-8,5,6,CONCRETE:12)
Block(-8,5,7,CONCRETE:4)
Block(-8,5,8,CONCRETE:7)
Block(-8,6,-7,CONCRETE:7)
Block(-8,6,-6,AIR:0)
Block(-8,6,-5,AIR:0)
Block(-8,6,-4,AIR:0)
Block(-8,6,-3,AIR:0)
Block(-8,6,-2,AIR:0)
Block(-8,6,-1,AIR:0)
Block(-8,6,0,AIR:0)
Block(-8,6,1,AIR:0)
Block(-8,6,2,AIR:0)
Block(-8,6,3,AIR:0)
Block(-8,6,4,AIR:0)
Block(-8,6,5,AIR:0)
Block(-8,6,6,AIR:0)
Block(-8,6,7,AIR:0)
Block(-8,6,8,CONCRETE:7)
Block(-8,7,-7,CONCRETE:7)
Block(-8,7,-6,CONCRETE:7)
Block(-8,7,-5,CONCRETE:7)
Block(-8,7,-4,CONCRETE:7)
Block(-8,7,-3,CONCRETE:7)
Block(-8,7,-2,CONCRETE:7)
Block(-8,7,-1,CONCRETE:7)
Block(-8,7,0,CONCRETE:7)
Block(-8,7,1,CONCRETE:7)
Block(-8,7,2,CONCRETE:7)
Block(-8,7,3,CONCRETE:7)
Block(-8,7,4,CONCRETE:7)
Block(-8,7,5,CONCRETE:7)
Block(-8,7,6,CONCRETE:7)
Block(-8,7,7,CONCRETE:7)
Block(-8,7,8,CONCRETE:7)
Block(-8,8,-7,CONCRETE:7)
Block(-8,8,-6,CONCRETE:7)
Block(-8,8,-5,CONCRETE:7)
Block(-8,8,-4,CONCRETE:7)
Block(-8,8,-3,CONCRETE:7)
Block(-8,8,-2,CONCRETE:7)
Block(-8,8,-1,CONCRETE:7)
Block(-8,8,0,AIR:0)
Block(-8,8,1,CONCRETE:12)
Block(-8,8,2,AIR:0)
Block(-8,8,3,CONCRETE:7)
Block(-8,8,4,AIR:0)
Block(-8,8,5,AIR:0)
Block(-8,8,6,CONCRETE:7)
Block(-8,8,7,CONCRETE:7)
Block(-8,8,8,CONCRETE:7)
Block(-8,9,-7,AIR:0)
Block(-8,9,-6,AIR:0)
Block(-8,9,-5,AIR:0)
Block(-8,9,-4,AIR:0)
Block(-8,9,-3,AIR:0)
Block(-8,9,-2,CONCRETE:7)
Block(-8,9,-1,CONCRETE:7)
Block(-8,9,0,AIR:0)
Block(-8,9,1,AIR:0)
Block(-8,9,2,AIR:0)
Block(-8,9,3,CONCRETE:7)
Block(-8,9,4,AIR:0)
Block(-8,9,5,AIR:0)
Block(-8,9,6,CONCRETE:7)
Block(-8,9,7,CONCRETE:7)
Block(-8,9,8,CONCRETE:7)
Block(-8,10,-7,AIR:0)
Block(-8,10,-6,AIR:0)
Block(-8,10,-5,AIR:0)
Block(-8,10,-4,AIR:0)
Block(-8,10,-3,AIR:0)
Block(-8,10,-2,CONCRETE:7)
Block(-8,10,-1,CONCRETE:7)
Block(-8,10,0,AIR:0)
Block(-8,10,1,AIR:0)
Block(-8,10,2,AIR:0)
Block(-8,10,3,CONCRETE:7)
Block(-8,10,4,AIR:0)
Block(-8,10,5,AIR:0)
Block(-8,10,6,CONCRETE:7)
Block(-8,10,7,CONCRETE:7)
Block(-8,10,8,CONCRETE:7)
Block(-8,11,-7,AIR:0)
Block(-8,11,-6,AIR:0)
Block(-8,11,-5,AIR:0)
Block(-8,11,-4,AIR:0)
Block(-8,11,-3,AIR:0)
Block(-8,11,-2,CONCRETE:7)
Block(-8,11,-1,CONCRETE:7)
Block(-8,11,0,AIR:0)
Block(-8,11,1,AIR:0)
Block(-8,11,2,AIR:0)
Block(-8,11,3,CONCRETE:7)
Block(-8,11,4,AIR:0)
Block(-8,11,5,AIR:0)
Block(-8,11,6,CONCRETE:7)
Block(-8,11,7,CONCRETE:7)
Block(-8,11,8,CONCRETE:7)
Block(-8,12,-7,AIR:0)
Block(-8,12,-6,AIR:0)
Block(-8,12,-5,CONCRETE:7)
Block(-8,12,-4,CONCRETE:7)
Block(-8,12,-3,CONCRETE:7)
Block(-8,12,-2,CONCRETE:7)
Block(-8,12,-1,CONCRETE:7)
Block(-8,12,0,CONCRETE:7)
Block(-8,12,1,CONCRETE:7)
Block(-8,12,2,CONCRETE:7)
Block(-8,12,3,CONCRETE:7)
Block(-8,12,4,CONCRETE:7)
Block(-8,12,5,CONCRETE:7)
Block(-8,12,6,CONCRETE:7)
Block(-8,12,7,CONCRETE:7)
Block(-8,12,8,CONCRETE:7)
Block(-8,13,-7,AIR:0)
Block(-8,13,-6,AIR:0)
Block(-8,13,-5,IRON_FENCE:0)
Block(-8,13,-4,AIR:0)
Block(-8,13,-3,AIR:0)
Block(-8,13,-2,STEP:5)
Block(-8,13,-1,CONCRETE:7)
Block(-8,13,0,CONCRETE:11)
Block(-8,13,1,CONCRETE:11)
Block(-8,13,2,CONCRETE:7)
Block(-8,13,3,STEP:5)
Block(-8,13,4,AIR:0)
Block(-8,13,5,STONE:6)
Block(-8,13,6,STATIONARY_WATER:0)
Block(-8,13,7,STATIONARY_WATER:0)
Block(-8,13,8,STATIONARY_WATER:0)
Block(-8,14,-7,AIR:0)
Block(-8,14,-6,AIR:0)
Block(-8,14,-5,AIR:0)
Block(-8,14,-4,AIR:0)
Block(-8,14,-3,AIR:0)
Block(-8,14,-2,AIR:0)
Block(-8,14,-1,STONE:6)
Block(-8,14,0,STATIONARY_WATER:8)
Block(-8,14,1,STATIONARY_WATER:8)
Block(-8,14,2,STONE:6)
Block(-8,14,3,AIR:0)
Block(-8,14,4,AIR:0)
Block(-8,14,5,CONCRETE:15)
Block(-8,14,6,STATIONARY_WATER:0)
Block(-8,14,7,STATIONARY_WATER:0)
Block(-8,14,8,STATIONARY_WATER:0)
Block(-8,15,-7,AIR:0)
Block(-8,15,-6,AIR:0)
Block(-8,15,-5,AIR:0)
Block(-8,15,-4,AIR:0)
Block(-8,15,-3,AIR:0)
Block(-8,15,-2,AIR:0)
Block(-8,15,-1,STONE:6)
Block(-8,15,0,STATIONARY_WATER:8)
Block(-8,15,1,STATIONARY_WATER:8)
Block(-8,15,2,STONE:6)
Block(-8,15,3,AIR:0)
Block(-8,15,4,AIR:0)
Block(-8,15,5,CONCRETE:15)
Block(-8,15,6,STATIONARY_WATER:0)
Block(-8,15,7,STATIONARY_WATER:0)
Block(-8,15,8,STATIONARY_WATER:0)
Block(-8,16,-7,AIR:0)
Block(-8,16,-6,AIR:0)
Block(-8,16,-5,AIR:0)
Block(-8,16,-4,AIR:0)
Block(-8,16,-3,AIR:0)
Block(-8,16,-2,AIR:0)
Block(-8,16,-1,STONE:6)
Block(-8,16,0,STATIONARY_WATER:0)
Block(-8,16,1,STATIONARY_WATER:0)
Block(-8,16,2,STONE:6)
Block(-8,16,3,AIR:0)
Block(-8,16,4,AIR:0)
Block(-8,16,5,STONE:6)
Block(-8,16,6,STATIONARY_WATER:0)
Block(-8,16,7,STATIONARY_WATER:0)
Block(-8,16,8,STATIONARY_WATER:0)
Block(-8,17,-7,CONCRETE:7)
Block(-8,17,-6,CONCRETE:7)
Block(-8,17,-5,CONCRETE:7)
Block(-8,17,-4,CONCRETE:7)
Block(-8,17,-3,CONCRETE:7)
Block(-8,17,-2,CONCRETE:7)
Block(-8,17,-1,CONCRETE:7)
Block(-8,17,0,CONCRETE:7)
Block(-8,17,1,CONCRETE:7)
Block(-8,17,2,CONCRETE:7)
Block(-8,17,3,CONCRETE:7)
Block(-8,17,4,CONCRETE:7)
Block(-8,17,5,CONCRETE:7)
Block(-8,17,6,CONCRETE:7)
Block(-8,17,7,CONCRETE:7)
Block(-8,17,8,CONCRETE:7)
Block(-8,18,-7,CONCRETE:15)
Block(-8,18,-6,CONCRETE:15)
Block(-8,18,-5,CONCRETE:15)
Block(-8,18,-4,CONCRETE:15)
Block(-8,18,-3,CONCRETE:15)
Block(-8,18,-2,CONCRETE:8)
Block(-8,18,-1,CONCRETE:8)
Block(-8,18,0,CONCRETE:8)
Block(-8,18,1,CONCRETE:8)
Block(-8,18,2,CONCRETE:8)
Block(-8,18,3,CONCRETE:8)
Block(-8,18,4,CONCRETE:15)
Block(-8,18,5,CONCRETE:15)
Block(-8,18,6,CONCRETE:15)
Block(-8,18,7,CONCRETE:15)
Block(-8,18,8,CONCRETE:15)
Block(-8,19,-7,STAINED_GLASS_PANE:15)
Block(-8,19,8,STAINED_GLASS_PANE:15)
Block(-8,24,-7,CONCRETE:15)
Block(-8,24,-6,CONCRETE:15)
Block(-8,24,-5,CONCRETE:15)
Block(-8,24,-4,CONCRETE:15)
Block(-8,24,-3,CONCRETE:15)
Block(-8,24,-2,CONCRETE:8)
Block(-8,24,-1,CONCRETE:8)
Block(-8,24,0,CONCRETE:8)
Block(-8,24,1,CONCRETE:8)
Block(-8,24,2,CONCRETE:8)
Block(-8,24,3,CONCRETE:8)
Block(-8,24,4,CONCRETE:15)
Block(-8,24,5,CONCRETE:15)
Block(-8,24,6,CONCRETE:15)
Block(-8,24,7,CONCRETE:15)
Block(-8,24,8,CONCRETE:15)
Block(-8,25,-7,STAINED_GLASS_PANE:15)
Block(-8,25,8,STAINED_GLASS_PANE:15)
Block(-8,30,-7,CONCRETE:15)
Block(-8,30,-6,CONCRETE:15)
Block(-8,30,-5,CONCRETE:15)
Block(-8,30,-4,CONCRETE:15)
Block(-8,30,-3,CONCRETE:15)
Block(-8,30,-2,CONCRETE:8)
Block(-8,30,-1,CONCRETE:8)
Block(-8,30,0,CONCRETE:8)
Block(-8,30,1,CONCRETE:8)
Block(-8,30,2,CONCRETE:8)
Block(-8,30,3,CONCRETE:8)
Block(-8,30,4,CONCRETE:15)
Block(-8,30,5,CONCRETE:15)
Block(-8,30,6,CONCRETE:15)
Block(-8,30,7,CONCRETE:15)
Block(-8,30,8,CONCRETE:15)
Block(-8,36,-7,CONCRETE:8)
Block(-8,36,-6,CONCRETE:8)
Block(-8,36,-5,CONCRETE:8)
Block(-8,36,-4,CONCRETE:8)
Block(-8,36,-3,CONCRETE:8)
Block(-8,36,-2,CONCRETE:8)
Block(-8,36,-1,CONCRETE:8)
Block(-8,36,0,CONCRETE:8)
Block(-8,36,1,CONCRETE:8)
Block(-8,36,2,CONCRETE:8)
Block(-8,36,3,CONCRETE:8)
Block(-8,36,4,CONCRETE:8)
Block(-8,36,5,CONCRETE:8)
Block(-8,36,6,CONCRETE:8)
Block(-8,36,7,CONCRETE:8)
Block(-8,36,8,CONCRETE:8)
Block(-8,42,-7,CONCRETE:8)
Block(-8,42,-6,CONCRETE:8)
Block(-8,42,-5,CONCRETE:8)
Block(-8,42,-4,CONCRETE:8)
Block(-8,42,-3,CONCRETE:8)
Block(-8,42,-2,CONCRETE:8)
Block(-8,42,-1,CONCRETE:8)
Block(-8,42,0,CONCRETE:8)
Block(-8,42,1,CONCRETE:8)
Block(-8,42,2,CONCRETE:8)
Block(-8,42,3,CONCRETE:8)
Block(-8,42,4,CONCRETE:8)
Block(-8,42,5,CONCRETE:8)
Block(-8,42,6,CONCRETE:8)
Block(-8,42,7,CONCRETE:8)
Block(-8,42,8,CONCRETE:8)
Block(-8,48,-7,CONCRETE:8)
Block(-8,48,-6,CONCRETE:8)
Block(-8,48,-5,CONCRETE:8)
Block(-8,48,-4,CONCRETE:8)
Block(-8,48,-3,CONCRETE:8)
Block(-8,48,-2,CONCRETE:8)
Block(-8,48,-1,CONCRETE:8)
Block(-8,48,0,CONCRETE:8)
Block(-8,48,1,CONCRETE:8)
Block(-8,48,2,CONCRETE:8)
Block(-8,48,3,CONCRETE:8)
Block(-8,48,4,CONCRETE:8)
Block(-8,48,5,CONCRETE:8)
Block(-8,48,6,CONCRETE:8)
Block(-8,48,7,CONCRETE:8)
Block(-8,48,8,CONCRETE:8)
Block(-8,54,-7,CONCRETE:8)
Block(-8,54,-6,CONCRETE:8)
Block(-8,54,-5,CONCRETE:8)
Block(-8,54,-4,CONCRETE:8)
Block(-8,54,-3,CONCRETE:8)
Block(-8,54,-2,CONCRETE:8)
Block(-8,54,-1,CONCRETE:8)
Block(-8,54,0,CONCRETE:8)
Block(-8,54,1,CONCRETE:8)
Block(-8,54,2,CONCRETE:8)
Block(-8,54,3,CONCRETE:8)
Block(-8,54,4,CONCRETE:8)
Block(-8,54,5,CONCRETE:8)
Block(-8,54,6,CONCRETE:8)
Block(-8,54,7,CONCRETE:8)
Block(-8,54,8,CONCRETE:8)
Block(-8,60,-7,CONCRETE:8)
Block(-8,60,-6,CONCRETE:8)
Block(-8,60,-5,CONCRETE:8)
Block(-8,60,-4,CONCRETE:8)
Block(-8,60,-3,CONCRETE:8)
Block(-8,60,-2,CONCRETE:8)
Block(-8,60,-1,CONCRETE:8)
Block(-8,60,0,CONCRETE:8)
Block(-8,60,1,CONCRETE:8)
Block(-8,60,2,CONCRETE:8)
Block(-8,60,3,CONCRETE:8)
Block(-8,60,4,CONCRETE:8)
Block(-8,60,5,CONCRETE:8)
Block(-8,60,6,CONCRETE:8)
Block(-8,60,7,CONCRETE:8)
Block(-8,60,8,CONCRETE:8)
Block(-8,66,-7,CONCRETE:8)
Block(-8,66,-6,CONCRETE:8)
Block(-8,66,-5,CONCRETE:8)
Block(-8,66,-4,CONCRETE:8)
Block(-8,66,-3,CONCRETE:8)
Block(-8,66,-2,CONCRETE:8)
Block(-8,66,-1,CONCRETE:8)
Block(-8,66,0,CONCRETE:8)
Block(-8,66,1,CONCRETE:8)
Block(-8,66,2,CONCRETE:8)
Block(-8,66,3,CONCRETE:8)
Block(-8,66,4,CONCRETE:8)
Block(-8,66,5,CONCRETE:8)
Block(-8,66,6,CONCRETE:8)
Block(-8,66,7,CONCRETE:8)
Block(-8,66,8,CONCRETE:8)
Block(-8,72,-7,CONCRETE:8)
Block(-8,72,-6,CONCRETE:8)
Block(-8,72,-5,CONCRETE:8)
Block(-8,72,-4,CONCRETE:8)
Block(-8,72,-3,CONCRETE:8)
Block(-8,72,-2,CONCRETE:8)
Block(-8,72,-1,CONCRETE:8)
Block(-8,72,0,CONCRETE:8)
Block(-8,72,1,CONCRETE:8)
Block(-8,72,2,CONCRETE:8)
Block(-8,72,3,CONCRETE:8)
Block(-8,72,4,CONCRETE:8)
Block(-8,72,5,CONCRETE:8)
Block(-8,72,6,CONCRETE:8)
Block(-8,72,7,CONCRETE:8)
Block(-8,72,8,CONCRETE:8)
Block(-8,78,-7,CONCRETE:15)
Block(-8,78,-6,CONCRETE:15)
Block(-8,78,-5,CONCRETE:15)
Block(-8,78,-4,CONCRETE:15)
Block(-8,78,-3,CONCRETE:15)
Block(-8,78,-2,CONCRETE:8)
Block(-8,78,-1,CONCRETE:8)
Block(-8,78,0,CONCRETE:8)
Block(-8,78,1,CONCRETE:8)
Block(-8,78,2,CONCRETE:8)
Block(-8,78,3,CONCRETE:8)
Block(-8,78,4,CONCRETE:15)
Block(-8,78,5,CONCRETE:15)
Block(-8,78,6,CONCRETE:15)
Block(-8,78,7,CONCRETE:15)
Block(-8,78,8,CONCRETE:15)
Block(-8,84,-7,CONCRETE:8)
Block(-8,84,-6,CONCRETE:8)
Block(-8,84,-5,CONCRETE:8)
Block(-8,84,-4,CONCRETE:8)
Block(-8,84,-3,CONCRETE:8)
Block(-8,84,-2,CONCRETE:8)
Block(-8,84,-1,CONCRETE:8)
Block(-8,84,0,CONCRETE:8)
Block(-8,84,1,CONCRETE:8)
Block(-8,84,2,CONCRETE:8)
Block(-8,84,3,CONCRETE:8)
Block(-8,84,4,CONCRETE:8)
Block(-8,84,5,CONCRETE:8)
Block(-8,84,6,CONCRETE:8)
Block(-8,84,7,CONCRETE:8)
Block(-8,84,8,CONCRETE:8)
Block(-8,90,-7,CONCRETE:8)
Block(-8,90,-6,CONCRETE:8)
Block(-8,90,-5,CONCRETE:8)
Block(-8,90,-4,CONCRETE:8)
Block(-8,90,-3,CONCRETE:8)
Block(-8,90,-2,CONCRETE:8)
Block(-8,90,-1,CONCRETE:8)
Block(-8,90,0,CONCRETE:8)
Block(-8,90,1,CONCRETE:8)
Block(-8,90,2,CONCRETE:8)
Block(-8,90,3,CONCRETE:8)
Block(-8,90,4,CONCRETE:8)
Block(-8,90,5,CONCRETE:8)
Block(-8,90,6,CONCRETE:8)
Block(-8,90,7,CONCRETE:8)
Block(-8,90,8,CONCRETE:8)
Block(-8,96,-7,CONCRETE:15)
Block(-8,96,-6,CONCRETE:15)
Block(-8,96,-5,CONCRETE:15)
Block(-8,96,-4,CONCRETE:15)
Block(-8,96,-3,CONCRETE:15)
Block(-8,96,-2,CONCRETE:8)
Block(-8,96,-1,CONCRETE:8)
Block(-8,96,0,CONCRETE:8)
Block(-8,96,1,CONCRETE:8)
Block(-8,96,2,CONCRETE:8)
Block(-8,96,3,CONCRETE:8)
Block(-8,96,4,CONCRETE:8)
Block(-8,96,5,CONCRETE:8)
Block(-8,96,6,CONCRETE:8)
Block(-8,96,7,CONCRETE:8)
Block(-8,96,8,CONCRETE:8)
Block(-8,102,-7,CONCRETE:8)
Block(-8,102,-6,CONCRETE:8)
Block(-8,102,-5,CONCRETE:8)
Block(-8,102,-4,CONCRETE:8)
Block(-8,102,-3,CONCRETE:8)
Block(-8,102,-2,CONCRETE:8)
Block(-8,102,-1,CONCRETE:8)
Block(-8,102,0,CONCRETE:8)
Block(-8,102,1,CONCRETE:8)
Block(-8,102,2,CONCRETE:8)
Block(-8,102,3,CONCRETE:8)
Block(-8,102,4,CONCRETE:8)
Block(-8,102,5,CONCRETE:8)
Block(-8,102,6,CONCRETE:8)
Block(-8,102,7,CONCRETE:8)
Block(-8,102,8,CONCRETE:8)
Block(-8,108,-7,CONCRETE:8)
Block(-8,108,-6,CONCRETE:8)
Block(-8,108,-5,CONCRETE:8)
Block(-8,108,-4,CONCRETE:8)
Block(-8,108,-3,CONCRETE:8)
Block(-8,108,-2,CONCRETE:8)
Block(-8,108,-1,CONCRETE:8)
Block(-8,108,0,CONCRETE:8)
Block(-8,108,1,CONCRETE:8)
Block(-8,108,2,CONCRETE:8)
Block(-8,108,3,CONCRETE:8)
Block(-8,108,4,CONCRETE:8)
Block(-8,108,5,CONCRETE:8)
Block(-8,108,6,CONCRETE:8)
Block(-8,108,7,CONCRETE:8)
Block(-8,108,8,CONCRETE:8)
Block(-8,114,-7,CONCRETE:8)
Block(-8,114,-6,CONCRETE:8)
Block(-8,114,-5,CONCRETE:8)
Block(-8,114,-4,CONCRETE:8)
Block(-8,114,-3,CONCRETE:8)
Block(-8,114,-2,CONCRETE:8)
Block(-8,114,-1,CONCRETE:8)
Block(-8,114,0,CONCRETE:8)
Block(-8,114,1,CONCRETE:8)
Block(-8,114,2,CONCRETE:8)
Block(-8,114,3,CONCRETE:8)
Block(-8,114,4,CONCRETE:8)
Block(-8,114,5,CONCRETE:8)
Block(-8,114,6,CONCRETE:8)
Block(-8,114,7,CONCRETE:8)
Block(-8,114,8,CONCRETE:8)
Block(-8,120,-7,CONCRETE:8)
Block(-8,120,-6,CONCRETE:8)
Block(-8,120,-5,CONCRETE:8)
Block(-8,120,-4,CONCRETE:8)
Block(-8,120,-3,CONCRETE:8)
Block(-8,120,-2,CONCRETE:8)
Block(-8,120,-1,CONCRETE:8)
Block(-8,120,0,CONCRETE:8)
Block(-8,120,1,CONCRETE:8)
Block(-8,120,2,CONCRETE:8)
Block(-8,120,3,CONCRETE:8)
Block(-8,120,4,CONCRETE:8)
Block(-8,120,5,CONCRETE:8)
Block(-8,120,6,CONCRETE:8)
Block(-8,120,7,CONCRETE:8)
Block(-8,120,8,CONCRETE:8)
Block(-8,126,-7,CONCRETE:8)
Block(-8,126,-6,CONCRETE:8)
Block(-8,126,-5,CONCRETE:8)
Block(-8,126,-4,CONCRETE:8)
Block(-8,126,-3,CONCRETE:8)
Block(-8,126,-2,CONCRETE:8)
Block(-8,126,-1,CONCRETE:8)
Block(-8,126,0,CONCRETE:8)
Block(-8,126,1,CONCRETE:8)
Block(-8,126,2,CONCRETE:8)
Block(-8,126,3,CONCRETE:8)
Block(-8,126,4,CONCRETE:8)
Block(-8,126,5,CONCRETE:8)
Block(-8,126,6,CONCRETE:8)
Block(-8,126,7,CONCRETE:8)
Block(-8,126,8,CONCRETE:8)
Block(-8,132,-7,CONCRETE:8)
Block(-8,132,-6,CONCRETE:8)
Block(-8,132,-5,CONCRETE:8)
Block(-8,132,-4,CONCRETE:8)
Block(-8,132,-3,CONCRETE:8)
Block(-8,132,-2,CONCRETE:8)
Block(-8,132,-1,CONCRETE:8)
Block(-8,132,0,CONCRETE:8)
Block(-8,132,1,CONCRETE:8)
Block(-8,132,2,CONCRETE:8)
Block(-8,132,3,CONCRETE:8)
Block(-8,132,4,CONCRETE:8)
Block(-8,132,5,CONCRETE:8)
Block(-8,132,6,CONCRETE:8)
Block(-8,132,7,CONCRETE:8)
Block(-8,132,8,CONCRETE:8)
Block(-8,138,-7,CONCRETE:8)
Block(-8,138,-6,CONCRETE:8)
Block(-8,138,-5,CONCRETE:8)
Block(-8,138,-4,CONCRETE:8)
Block(-8,138,-3,CONCRETE:8)
Block(-8,138,-2,CONCRETE:8)
Block(-8,138,-1,CONCRETE:8)
Block(-8,138,0,CONCRETE:8)
Block(-8,138,1,CONCRETE:8)
Block(-8,138,2,CONCRETE:8)
Block(-8,138,3,CONCRETE:8)
Block(-8,138,4,CONCRETE:8)
Block(-8,138,5,CONCRETE:8)
Block(-8,138,6,CONCRETE:8)
Block(-8,138,7,CONCRETE:8)
Block(-8,138,8,CONCRETE:8)
Block(-8,144,-7,CONCRETE:8)
Block(-8,144,-6,CONCRETE:8)
Block(-8,144,-5,CONCRETE:8)
Block(-8,144,-4,CONCRETE:8)
Block(-8,144,-3,CONCRETE:8)
Block(-8,144,-2,CONCRETE:8)
Block(-8,144,-1,CONCRETE:8)
Block(-8,144,0,CONCRETE:8)
Block(-8,144,1,CONCRETE:8)
Block(-8,144,2,CONCRETE:8)
Block(-8,144,3,CONCRETE:8)
Block(-8,144,4,CONCRETE:8)
Block(-8,144,5,CONCRETE:8)
Block(-8,144,6,CONCRETE:8)
Block(-8,144,7,CONCRETE:8)
Block(-8,144,8,CONCRETE:8)
Block(-8,150,-7,CONCRETE:8)
Block(-8,150,-6,CONCRETE:8)
Block(-8,150,-5,CONCRETE:8)
Block(-8,150,-4,CONCRETE:8)
Block(-8,150,-3,CONCRETE:8)
Block(-8,150,-2,CONCRETE:8)
Block(-8,150,-1,CONCRETE:8)
Block(-8,150,0,CONCRETE:8)
Block(-8,150,1,CONCRETE:8)
Block(-8,150,2,CONCRETE:8)
Block(-8,150,3,CONCRETE:8)
Block(-8,150,4,CONCRETE:8)
Block(-8,150,5,CONCRETE:8)
Block(-8,150,6,CONCRETE:8)
Block(-8,150,7,CONCRETE:8)
Block(-8,150,8,CONCRETE:8)
Block(-8,156,-7,CONCRETE:8)
Block(-8,156,-6,CONCRETE:8)
Block(-8,156,-5,CONCRETE:8)
Block(-8,156,-4,CONCRETE:8)
Block(-8,156,-3,CONCRETE:8)
Block(-8,156,-2,CONCRETE:8)
Block(-8,156,-1,CONCRETE:8)
Block(-8,156,0,CONCRETE:8)
Block(-8,156,1,CONCRETE:8)
Block(-8,156,2,CONCRETE:8)
Block(-8,156,3,CONCRETE:8)
Block(-8,156,4,CONCRETE:8)
Block(-8,156,5,CONCRETE:8)
Block(-8,156,6,CONCRETE:8)
Block(-8,156,7,CONCRETE:8)
Block(-8,156,8,CONCRETE:8)
Block(-8,162,-7,CONCRETE:8)
Block(-8,162,-6,CONCRETE:8)
Block(-8,162,-5,CONCRETE:8)
Block(-8,162,-4,CONCRETE:8)
Block(-8,162,-3,CONCRETE:8)
Block(-8,162,-2,CONCRETE:8)
Block(-8,162,-1,CONCRETE:8)
Block(-8,162,0,CONCRETE:8)
Block(-8,162,1,CONCRETE:8)
Block(-8,162,2,CONCRETE:8)
Block(-8,162,3,CONCRETE:8)
Block(-8,162,4,CONCRETE:8)
Block(-8,162,5,CONCRETE:8)
Block(-8,162,6,CONCRETE:8)
Block(-8,162,7,CONCRETE:8)
Block(-8,162,8,CONCRETE:8)
Block(-8,168,-7,CONCRETE:8)
Block(-8,168,-6,CONCRETE:8)
Block(-8,168,-5,CONCRETE:8)
Block(-8,168,-4,CONCRETE:8)
Block(-8,168,-3,CONCRETE:8)
Block(-8,168,-2,CONCRETE:8)
Block(-8,168,-1,CONCRETE:8)
Block(-8,168,0,CONCRETE:8)
Block(-8,168,1,CONCRETE:8)
Block(-8,168,2,CONCRETE:8)
Block(-8,168,3,CONCRETE:8)
Block(-8,168,4,CONCRETE:8)
Block(-8,168,5,CONCRETE:8)
Block(-8,168,6,CONCRETE:8)
Block(-8,168,7,CONCRETE:8)
Block(-8,168,8,CONCRETE:8)
Block(-8,174,-7,CONCRETE:8)
Block(-8,174,-6,CONCRETE:8)
Block(-8,174,-5,CONCRETE:8)
Block(-8,174,-4,CONCRETE:8)
Block(-8,174,-3,CONCRETE:8)
Block(-8,174,-2,CONCRETE:8)
Block(-8,174,-1,CONCRETE:8)
Block(-8,174,0,CONCRETE:8)
Block(-8,174,1,CONCRETE:8)
Block(-8,174,2,CONCRETE:8)
Block(-8,174,3,CONCRETE:8)
Block(-8,174,4,CONCRETE:8)
Block(-8,174,5,CONCRETE:8)
Block(-8,174,6,CONCRETE:8)
Block(-8,174,7,CONCRETE:8)
Block(-8,174,8,CONCRETE:8)
Block(-8,180,-7,CONCRETE:8)
Block(-8,180,-6,CONCRETE:8)
Block(-8,180,-5,CONCRETE:8)
Block(-8,180,-4,CONCRETE:8)
Block(-8,180,-3,CONCRETE:8)
Block(-8,180,-2,CONCRETE:8)
Block(-8,180,-1,CONCRETE:8)
Block(-8,180,0,CONCRETE:8)
Block(-8,180,1,CONCRETE:8)
Block(-8,180,2,CONCRETE:8)
Block(-8,180,3,CONCRETE:8)
Block(-8,180,4,CONCRETE:8)
Block(-8,180,5,CONCRETE:8)
Block(-8,180,6,CONCRETE:8)
Block(-8,180,7,CONCRETE:8)
Block(-8,180,8,CONCRETE:8)
Block(-8,186,-7,CONCRETE:8)
Block(-8,186,-6,CONCRETE:8)
Block(-8,186,-5,CONCRETE:8)
Block(-8,186,-4,CONCRETE:8)
Block(-8,186,-3,CONCRETE:8)
Block(-8,186,-2,CONCRETE:8)
Block(-8,186,-1,CONCRETE:8)
Block(-8,186,0,CONCRETE:8)
Block(-8,186,1,CONCRETE:8)
Block(-8,186,2,CONCRETE:8)
Block(-8,186,3,CONCRETE:8)
Block(-8,186,4,CONCRETE:8)
Block(-8,186,5,CONCRETE:8)
Block(-8,186,6,CONCRETE:8)
Block(-8,186,7,CONCRETE:8)
Block(-8,186,8,CONCRETE:8)
Block(-8,192,-7,CONCRETE:8)
Block(-8,192,-6,CONCRETE:8)
Block(-8,192,-5,CONCRETE:8)
Block(-8,192,-4,CONCRETE:8)
Block(-8,192,-3,CONCRETE:8)
Block(-8,192,-2,CONCRETE:8)
Block(-8,192,-1,CONCRETE:8)
Block(-8,192,0,CONCRETE:8)
Block(-8,192,1,CONCRETE:8)
Block(-8,192,2,CONCRETE:8)
Block(-8,192,3,CONCRETE:8)
Block(-8,192,4,CONCRETE:8)
Block(-8,192,5,CONCRETE:8)
Block(-8,192,6,CONCRETE:8)
Block(-8,192,7,CONCRETE:8)
Block(-8,192,8,CONCRETE:8)
Block(-8,193,-2,PRISMARINE:2)
Block(-8,193,-1,CARPET:15)
Block(-8,193,0,CARPET:10)
Block(-8,193,1,CARPET:15)
Block(-8,193,2,CARPET:10)
Block(-8,193,3,CARPET:15)
Block(-8,193,4,CARPET:10)
Block(-8,193,5,COBBLE_WALL:0)
Block(-8,193,6,PRISMARINE:2)
Block(-8,193,8,STAINED_GLASS_PANE:15)
Block(-8,194,-2,PRISMARINE:2)
Block(-8,194,5,CONCRETE:15)
Block(-8,194,6,PRISMARINE:2)
Block(-8,195,-3,WALL_BANNER:2,NBT/skyscraper_3x3_01/2606-bannerC16R16.nbt)
Block(-8,195,-2,PRISMARINE:2)
Block(-8,195,4,WALL_BANNER:2,NBT/skyscraper_3x3_01/2607-bannerC16R16.nbt)
Block(-8,195,5,CONCRETE:15)
Block(-8,195,6,PRISMARINE:2)
Block(-8,196,-2,WOOD_STEP:5)
Block(-8,196,5,IRON_TRAPDOOR:0)
Block(-8,196,6,PRISMARINE:2)
Block(-8,197,-1,QUARTZ_STAIRS:6)
Block(-8,197,0,STAINED_GLASS:15)
Block(-8,197,1,STAINED_GLASS:15)
Block(-8,197,2,QUARTZ_STAIRS:7)
Block(-8,197,6,PRISMARINE:2)
Block(-8,198,-7,CONCRETE:8)
Block(-8,198,-6,CONCRETE:8)
Block(-8,198,-5,CONCRETE:8)
Block(-8,198,-4,CONCRETE:8)
Block(-8,198,-3,CONCRETE:8)
Block(-8,198,-2,CONCRETE:8)
Block(-8,198,-1,QUARTZ_STAIRS:3)
Block(-8,198,2,QUARTZ_STAIRS:2)
Block(-8,198,3,CONCRETE:8)
Block(-8,198,4,CONCRETE:8)
Block(-8,198,5,CONCRETE:8)
Block(-8,198,6,CONCRETE:8)
Block(-8,198,7,CONCRETE:8)
Block(-8,198,8,CONCRETE:8)
Block(-8,199,-7,CONCRETE:8)
Block(-8,199,-6,CONCRETE:8)
Block(-8,199,-5,CONCRETE:8)
Block(-8,199,-4,CONCRETE:8)
Block(-8,199,-3,CONCRETE:8)
Block(-8,199,-2,QUARTZ_STAIRS:3)
Block(-8,199,3,QUARTZ_STAIRS:2)
Block(-8,199,4,CONCRETE:8)
Block(-8,199,5,CONCRETE:8)
Block(-8,199,6,CONCRETE:8)
Block(-8,199,7,CONCRETE:8)
Block(-8,199,8,CONCRETE:8)
Block(-8,200,-7,IRON_TRAPDOOR:2)
Block(-8,200,-3,IRON_DOOR_BLOCK:3)
Block(-8,200,4,IRON_DOOR_BLOCK:1)
Block(-8,200,8,IRON_TRAPDOOR:1)
Block(-8,201,-3,IRON_DOOR_BLOCK:8)
Block(-8,201,4,IRON_DOOR_BLOCK:9)
Block(-8,202,-3,STAINED_GLASS:15)
Block(-8,202,-2,STAINED_GLASS:15)
Block(-8,202,-1,STAINED_GLASS:15)
Block(-8,202,0,STAINED_GLASS:15)
Block(-8,202,1,STAINED_GLASS:15)
Block(-8,202,2,STAINED_GLASS:15)
Block(-8,202,3,STAINED_GLASS:15)
Block(-8,202,4,STAINED_GLASS:15)
Block(-7,0,-7,CONCRETE:7)
Block(-7,0,-6,CONCRETE:7)
Block(-7,0,-5,CONCRETE:7)
Block(-7,0,-4,CONCRETE:7)
Block(-7,0,-3,CONCRETE:7)
Block(-7,0,-2,CONCRETE:7)
Block(-7,0,-1,CONCRETE:7)
Block(-7,0,0,CONCRETE:7)
Block(-7,0,1,CONCRETE:7)
Block(-7,0,2,CONCRETE:7)
Block(-7,0,3,CONCRETE:7)
Block(-7,0,4,CONCRETE:7)
Block(-7,0,5,CONCRETE:7)
Block(-7,0,6,CONCRETE:7)
Block(-7,0,7,CONCRETE:7)
Block(-7,0,8,CONCRETE:7)
Block(-7,1,-7,CONCRETE:7)
Block(-7,1,-6,CONCRETE:7)
Block(-7,1,-5,CONCRETE:7)
Block(-7,1,-4,CONCRETE:7)
Block(-7,1,-3,CONCRETE:7)
Block(-7,1,-2,CONCRETE:7)
Block(-7,1,-1,CONCRETE:7)
Block(-7,1,0,CONCRETE:7)
Block(-7,1,1,CONCRETE:7)
Block(-7,1,2,CONCRETE:7)
Block(-7,1,3,STATIONARY_WATER:0)
Block(-7,1,4,STATIONARY_WATER:0)
Block(-7,1,5,CONCRETE:7)
Block(-7,1,6,CONCRETE:7)
Block(-7,1,7,CONCRETE:7)
Block(-7,1,8,CONCRETE:7)
Block(-7,2,-7,CONCRETE:7)
Block(-7,2,-6,CONCRETE:7)
Block(-7,2,-5,CONCRETE:7)
Block(-7,2,-4,CONCRETE:7)
Block(-7,2,-3,CONCRETE:7)
Block(-7,2,-2,CONCRETE:7)
Block(-7,2,-1,CONCRETE:7)
Block(-7,2,0,CONCRETE:7)
Block(-7,2,1,CONCRETE:7)
Block(-7,2,2,SMOOTH_STAIRS:3)
Block(-7,2,3,AIR:0)
Block(-7,2,4,AIR:0)
Block(-7,2,5,SMOOTH_STAIRS:2)
Block(-7,2,6,CONCRETE:7)
Block(-7,2,7,CONCRETE:7)
Block(-7,2,8,CONCRETE:7)
Block(-7,3,-7,AIR:0)
Block(-7,3,-6,AIR:0)
Block(-7,3,-5,AIR:0)
Block(-7,3,-4,AIR:0)
Block(-7,3,-3,AIR:0)
Block(-7,3,-2,AIR:0)
Block(-7,3,-1,AIR:0)
Block(-7,3,0,AIR:0)
Block(-7,3,1,AIR:0)
Block(-7,3,2,AIR:0)
Block(-7,3,3,AIR:0)
Block(-7,3,4,AIR:0)
Block(-7,3,5,AIR:0)
Block(-7,3,6,AIR:0)
Block(-7,3,7,AIR:0)
Block(-7,3,8,CONCRETE:7)
Block(-7,4,-7,AIR:0)
Block(-7,4,-6,AIR:0)
Block(-7,4,-5,AIR:0)
Block(-7,4,-4,AIR:0)
Block(-7,4,-3,AIR:0)
Block(-7,4,-2,AIR:0)
Block(-7,4,-1,AIR:0)
Block(-7,4,0,AIR:0)
Block(-7,4,1,AIR:0)
Block(-7,4,2,AIR:0)
Block(-7,4,3,AIR:0)
Block(-7,4,4,AIR:0)
Block(-7,4,5,AIR:0)
Block(-7,4,6,AIR:0)
Block(-7,4,7,AIR:0)
Block(-7,4,8,CONCRETE:7)
Block(-7,5,-7,AIR:0)
Block(-7,5,-6,AIR:0)
Block(-7,5,-5,AIR:0)
Block(-7,5,-4,AIR:0)
Block(-7,5,-3,AIR:0)
Block(-7,5,-2,AIR:0)
Block(-7,5,-1,AIR:0)
Block(-7,5,0,AIR:0)
Block(-7,5,1,AIR:0)
Block(-7,5,2,AIR:0)
Block(-7,5,3,AIR:0)
Block(-7,5,4,AIR:0)
Block(-7,5,5,AIR:0)
Block(-7,5,6,CONCRETE:12)
Block(-7,5,7,CONCRETE:4)
Block(-7,5,8,CONCRETE:7)
Block(-7,6,-7,CONCRETE:7)
Block(-7,6,-6,AIR:0)
Block(-7,6,-5,AIR:0)
Block(-7,6,-4,AIR:0)
Block(-7,6,-3,AIR:0)
Block(-7,6,-2,AIR:0)
Block(-7,6,-1,AIR:0)
Block(-7,6,0,AIR:0)
Block(-7,6,1,AIR:0)
Block(-7,6,2,AIR:0)
Block(-7,6,3,AIR:0)
Block(-7,6,4,AIR:0)
Block(-7,6,5,AIR:0)
Block(-7,6,6,IRON_FENCE:0)
Block(-7,6,7,AIR:0)
Block(-7,6,8,CONCRETE:7)
Block(-7,7,-7,CONCRETE:7)
Block(-7,7,-6,CONCRETE:7)
Block(-7,7,-5,CONCRETE:7)
Block(-7,7,-4,CONCRETE:7)
Block(-7,7,-3,CONCRETE:7)
Block(-7,7,-2,CONCRETE:7)
Block(-7,7,-1,CONCRETE:7)
Block(-7,7,0,CONCRETE:7)
Block(-7,7,1,CONCRETE:7)
Block(-7,7,2,CONCRETE:7)
Block(-7,7,3,CONCRETE:7)
Block(-7,7,4,CONCRETE:7)
Block(-7,7,5,CONCRETE:7)
Block(-7,7,6,CONCRETE:7)
Block(-7,7,7,CONCRETE:7)
Block(-7,7,8,CONCRETE:7)
Block(-7,8,-7,CONCRETE:7)
Block(-7,8,-6,CONCRETE:7)
Block(-7,8,-5,CONCRETE:7)
Block(-7,8,-4,CONCRETE:7)
Block(-7,8,-3,CONCRETE:7)
Block(-7,8,-2,CONCRETE:7)
Block(-7,8,-1,AIR:0)
Block(-7,8,0,AIR:0)
Block(-7,8,1,CONCRETE:12)
Block(-7,8,2,AIR:0)
Block(-7,8,3,AIR:0)
Block(-7,8,4,AIR:0)
Block(-7,8,5,AIR:0)
Block(-7,8,6,AIR:0)
Block(-7,8,7,CONCRETE:7)
Block(-7,8,8,CONCRETE:7)
Block(-7,9,-7,SMOOTH_STAIRS:0)
Block(-7,9,-6,SMOOTH_STAIRS:0)
Block(-7,9,-5,CONCRETE:7)
Block(-7,9,-4,AIR:0)
Block(-7,9,-3,AIR:0)
Block(-7,9,-2,CONCRETE:7)
Block(-7,9,-1,AIR:0)
Block(-7,9,0,AIR:0)
Block(-7,9,1,AIR:0)
Block(-7,9,2,AIR:0)
Block(-7,9,3,AIR:0)
Block(-7,9,4,AIR:0)
Block(-7,9,5,AIR:0)
Block(-7,9,6,AIR:0)
Block(-7,9,7,CONCRETE:7)
Block(-7,9,8,CONCRETE:7)
Block(-7,10,-7,AIR:0)
Block(-7,10,-6,AIR:0)
Block(-7,10,-5,CONCRETE:7)
Block(-7,10,-4,AIR:0)
Block(-7,10,-3,AIR:0)
Block(-7,10,-2,CONCRETE:7)
Block(-7,10,-1,AIR:0)
Block(-7,10,0,AIR:0)
Block(-7,10,1,AIR:0)
Block(-7,10,2,AIR:0)
Block(-7,10,3,AIR:0)
Block(-7,10,4,AIR:0)
Block(-7,10,5,AIR:0)
Block(-7,10,6,AIR:0)
Block(-7,10,7,CONCRETE:7)
Block(-7,10,8,CONCRETE:7)
Block(-7,11,-7,AIR:0)
Block(-7,11,-6,AIR:0)
Block(-7,11,-5,CONCRETE:7)
Block(-7,11,-4,AIR:0)
Block(-7,11,-3,AIR:0)
Block(-7,11,-2,CONCRETE:7)
Block(-7,11,-1,AIR:0)
Block(-7,11,0,AIR:0)
Block(-7,11,1,AIR:0)
Block(-7,11,2,AIR:0)
Block(-7,11,3,AIR:0)
Block(-7,11,4,AIR:0)
Block(-7,11,5,AIR:0)
Block(-7,11,6,AIR:0)
Block(-7,11,7,CONCRETE:7)
Block(-7,11,8,CONCRETE:7)
Block(-7,12,-7,AIR:0)
Block(-7,12,-6,AIR:0)
Block(-7,12,-5,CONCRETE:7)
Block(-7,12,-4,CONCRETE:7)
Block(-7,12,-3,CONCRETE:7)
Block(-7,12,-2,CONCRETE:7)
Block(-7,12,-1,CONCRETE:7)
Block(-7,12,0,CONCRETE:7)
Block(-7,12,1,CONCRETE:7)
Block(-7,12,2,CONCRETE:7)
Block(-7,12,3,CONCRETE:7)
Block(-7,12,4,CONCRETE:7)
Block(-7,12,5,CONCRETE:7)
Block(-7,12,6,CONCRETE:7)
Block(-7,12,7,CONCRETE:7)
Block(-7,12,8,CONCRETE:7)
Block(-7,13,-7,AIR:0)
Block(-7,13,-6,AIR:0)
Block(-7,13,-5,IRON_FENCE:0)
Block(-7,13,-4,AIR:0)
Block(-7,13,-3,CONCRETE:11)
Block(-7,13,-2,CONCRETE:11)
Block(-7,13,-1,CONCRETE:7)
Block(-7,13,0,CONCRETE:11)
Block(-7,13,1,CONCRETE:11)
Block(-7,13,2,CONCRETE:7)
Block(-7,13,3,CONCRETE:11)
Block(-7,13,4,CONCRETE:11)
Block(-7,13,5,CONCRETE:11)
Block(-7,13,6,STATIONARY_WATER:0)
Block(-7,13,7,STATIONARY_WATER:0)
Block(-7,13,8,STATIONARY_WATER:0)
Block(-7,14,-7,AIR:0)
Block(-7,14,-6,AIR:0)
Block(-7,14,-5,AIR:0)
Block(-7,14,-4,AIR:0)
Block(-7,14,-3,AIR:0)
Block(-7,14,-2,COBBLE_WALL:0)
Block(-7,14,-1,STONE:6)
Block(-7,14,0,STATIONARY_WATER:8)
Block(-7,14,1,STATIONARY_WATER:8)
Block(-7,14,2,STONE:6)
Block(-7,14,3,COBBLE_WALL:0)
Block(-7,14,4,AIR:0)
Block(-7,14,5,CONCRETE:15)
Block(-7,14,6,STATIONARY_WATER:0)
Block(-7,14,7,STATIONARY_WATER:0)
Block(-7,14,8,STATIONARY_WATER:0)
Block(-7,15,-7,AIR:0)
Block(-7,15,-6,AIR:0)
Block(-7,15,-5,AIR:0)
Block(-7,15,-4,AIR:0)
Block(-7,15,-3,AIR:0)
Block(-7,15,-2,COBBLE_WALL:0)
Block(-7,15,-1,STONE:6)
Block(-7,15,0,STATIONARY_WATER:8)
Block(-7,15,1,STATIONARY_WATER:8)
Block(-7,15,2,STONE:6)
Block(-7,15,3,COBBLE_WALL:0)
Block(-7,15,4,AIR:0)
Block(-7,15,5,CONCRETE:15)
Block(-7,15,6,STATIONARY_WATER:0)
Block(-7,15,7,STATIONARY_WATER:0)
Block(-7,15,8,STATIONARY_WATER:0)
Block(-7,16,-7,AIR:0)
Block(-7,16,-6,AIR:0)
Block(-7,16,-5,AIR:0)
Block(-7,16,-4,AIR:0)
Block(-7,16,-3,AIR:0)
Block(-7,16,-2,SMOOTH_STAIRS:2)
Block(-7,16,-1,CONCRETE:11)
Block(-7,16,0,STATIONARY_WATER:0)
Block(-7,16,1,STATIONARY_WATER:0)
Block(-7,16,2,CONCRETE:11)
Block(-7,16,3,SMOOTH_STAIRS:3)
Block(-7,16,4,AIR:0)
Block(-7,16,5,STONE:6)
Block(-7,16,6,STATIONARY_WATER:0)
Block(-7,16,7,STATIONARY_WATER:0)
Block(-7,16,8,STATIONARY_WATER:0)
Block(-7,17,-7,CONCRETE:7)
Block(-7,17,-6,CONCRETE:7)
Block(-7,17,-5,CONCRETE:7)
Block(-7,17,-4,CONCRETE:7)
Block(-7,17,-3,CONCRETE:7)
Block(-7,17,-2,CONCRETE:7)
Block(-7,17,-1,CONCRETE:7)
Block(-7,17,0,CONCRETE:7)
Block(-7,17,1,CONCRETE:7)
Block(-7,17,2,CONCRETE:7)
Block(-7,17,3,CONCRETE:7)
Block(-7,17,4,CONCRETE:7)
Block(-7,17,5,CONCRETE:7)
Block(-7,17,6,CONCRETE:7)
Block(-7,17,7,CONCRETE:7)
Block(-7,17,8,CONCRETE:7)
Block(-7,18,-7,CONCRETE:15)
Block(-7,18,-6,CONCRETE:15)
Block(-7,18,-5,CONCRETE:15)
Block(-7,18,-4,CONCRETE:15)
Block(-7,18,-3,CONCRETE:15)
Block(-7,18,-2,CONCRETE:15)
Block(-7,18,-1,CONCRETE:15)
Block(-7,18,0,CONCRETE:8)
Block(-7,18,1,CONCRETE:8)
Block(-7,18,2,CONCRETE:15)
Block(-7,18,3,CONCRETE:15)
Block(-7,18,4,CONCRETE:15)
Block(-7,18,5,CONCRETE:15)
Block(-7,18,6,CONCRETE:15)
Block(-7,18,7,CONCRETE:15)
Block(-7,18,8,CONCRETE:15)
Block(-7,24,-7,CONCRETE:15)
Block(-7,24,-6,STAINED_GLASS:15)
Block(-7,24,-5,STAINED_GLASS:15)
Block(-7,24,-4,STAINED_GLASS:15)
Block(-7,24,-3,STAINED_GLASS:15)
Block(-7,24,-2,STAINED_GLASS:15)
Block(-7,24,-1,STAINED_GLASS:15)
Block(-7,24,0,STAINED_GLASS:15)
Block(-7,24,1,STAINED_GLASS:15)
Block(-7,24,2,STAINED_GLASS:15)
Block(-7,24,3,STAINED_GLASS:15)
Block(-7,24,4,STAINED_GLASS:15)
Block(-7,24,5,STAINED_GLASS:15)
Block(-7,24,6,STAINED_GLASS:15)
Block(-7,24,7,STAINED_GLASS:15)
Block(-7,24,8,CONCRETE:15)
Block(-7,30,-7,CONCRETE:15)
Block(-7,30,-6,STAINED_GLASS:15)
Block(-7,30,-5,STAINED_GLASS:15)
Block(-7,30,-4,STAINED_GLASS:15)
Block(-7,30,-3,STAINED_GLASS:15)
Block(-7,30,-2,STAINED_GLASS:15)
Block(-7,30,-1,STAINED_GLASS:15)
Block(-7,30,0,STAINED_GLASS:15)
Block(-7,30,1,STAINED_GLASS:15)
Block(-7,30,2,STAINED_GLASS:15)
Block(-7,30,3,STAINED_GLASS:15)
Block(-7,30,4,STAINED_GLASS:15)
Block(-7,30,5,STAINED_GLASS:15)
Block(-7,30,6,STAINED_GLASS:15)
Block(-7,30,7,STAINED_GLASS:15)
Block(-7,30,8,CONCRETE:15)
Block(-7,36,-7,CONCRETE:8)
Block(-7,36,-6,STAINED_GLASS:15)
Block(-7,36,-5,STAINED_GLASS:15)
Block(-7,36,-4,STAINED_GLASS:15)
Block(-7,36,-3,STAINED_GLASS:15)
Block(-7,36,-2,STAINED_GLASS:15)
Block(-7,36,-1,STAINED_GLASS:15)
Block(-7,36,0,STAINED_GLASS:15)
Block(-7,36,1,STAINED_GLASS:15)
Block(-7,36,2,STAINED_GLASS:15)
Block(-7,36,3,STAINED_GLASS:15)
Block(-7,36,4,STAINED_GLASS:15)
Block(-7,36,5,STAINED_GLASS:15)
Block(-7,36,6,STAINED_GLASS:15)
Block(-7,36,7,STAINED_GLASS:15)
Block(-7,36,8,CONCRETE:8)
Block(-7,42,-7,CONCRETE:8)
Block(-7,42,-6,STAINED_GLASS:15)
Block(-7,42,-5,STAINED_GLASS:15)
Block(-7,42,-4,STAINED_GLASS:15)
Block(-7,42,-3,STAINED_GLASS:15)
Block(-7,42,-2,STAINED_GLASS:15)
Block(-7,42,-1,STAINED_GLASS:15)
Block(-7,42,0,STAINED_GLASS:15)
Block(-7,42,1,STAINED_GLASS:15)
Block(-7,42,2,STAINED_GLASS:15)
Block(-7,42,3,STAINED_GLASS:15)
Block(-7,42,4,STAINED_GLASS:15)
Block(-7,42,5,STAINED_GLASS:15)
Block(-7,42,6,STAINED_GLASS:15)
Block(-7,42,7,STAINED_GLASS:15)
Block(-7,42,8,CONCRETE:8)
Block(-7,48,-7,CONCRETE:8)
Block(-7,48,-6,STAINED_GLASS:15)
Block(-7,48,-5,STAINED_GLASS:15)
Block(-7,48,-4,STAINED_GLASS:15)
Block(-7,48,-3,STAINED_GLASS:15)
Block(-7,48,-2,STAINED_GLASS:15)
Block(-7,48,-1,STAINED_GLASS:15)
Block(-7,48,0,STAINED_GLASS:15)
Block(-7,48,1,STAINED_GLASS:15)
Block(-7,48,2,STAINED_GLASS:15)
Block(-7,48,3,STAINED_GLASS:15)
Block(-7,48,4,STAINED_GLASS:15)
Block(-7,48,5,STAINED_GLASS:15)
Block(-7,48,6,STAINED_GLASS:15)
Block(-7,48,7,STAINED_GLASS:15)
Block(-7,48,8,CONCRETE:8)
Block(-7,54,-7,CONCRETE:8)
Block(-7,54,-6,STAINED_GLASS:15)
Block(-7,54,-5,STAINED_GLASS:15)
Block(-7,54,-4,STAINED_GLASS:15)
Block(-7,54,-3,STAINED_GLASS:15)
Block(-7,54,-2,STAINED_GLASS:15)
Block(-7,54,-1,STAINED_GLASS:15)
Block(-7,54,0,STAINED_GLASS:15)
Block(-7,54,1,STAINED_GLASS:15)
Block(-7,54,2,STAINED_GLASS:15)
Block(-7,54,3,STAINED_GLASS:15)
Block(-7,54,4,STAINED_GLASS:15)
Block(-7,54,5,STAINED_GLASS:15)
Block(-7,54,6,STAINED_GLASS:15)
Block(-7,54,7,STAINED_GLASS:15)
Block(-7,54,8,CONCRETE:8)
Block(-7,60,-7,CONCRETE:8)
Block(-7,60,-6,STAINED_GLASS:15)
Block(-7,60,-5,STAINED_GLASS:15)
Block(-7,60,-4,STAINED_GLASS:15)
Block(-7,60,-3,STAINED_GLASS:15)
Block(-7,60,-2,STAINED_GLASS:15)
Block(-7,60,-1,STAINED_GLASS:15)
Block(-7,60,0,STAINED_GLASS:15)
Block(-7,60,1,STAINED_GLASS:15)
Block(-7,60,2,STAINED_GLASS:15)
Block(-7,60,3,STAINED_GLASS:15)
Block(-7,60,4,STAINED_GLASS:15)
Block(-7,60,5,STAINED_GLASS:15)
Block(-7,60,6,STAINED_GLASS:15)
Block(-7,60,7,STAINED_GLASS:15)
Block(-7,60,8,CONCRETE:8)
Block(-7,66,-7,CONCRETE:8)
Block(-7,66,-6,STAINED_GLASS:15)
Block(-7,66,-5,STAINED_GLASS:15)
Block(-7,66,-4,STAINED_GLASS:15)
Block(-7,66,-3,STAINED_GLASS:15)
Block(-7,66,-2,STAINED_GLASS:15)
Block(-7,66,-1,STAINED_GLASS:15)
Block(-7,66,0,STAINED_GLASS:15)
Block(-7,66,1,STAINED_GLASS:15)
Block(-7,66,2,STAINED_GLASS:15)
Block(-7,66,3,STAINED_GLASS:15)
Block(-7,66,4,STAINED_GLASS:15)
Block(-7,66,5,STAINED_GLASS:15)
Block(-7,66,6,STAINED_GLASS:15)
Block(-7,66,7,STAINED_GLASS:15)
Block(-7,66,8,CONCRETE:8)
Block(-7,67,2,STAINED_GLASS_PANE:15)
Block(-7,72,-7,CONCRETE:8)
Block(-7,72,-6,STAINED_GLASS:15)
Block(-7,72,-5,STAINED_GLASS:15)
Block(-7,72,-4,STAINED_GLASS:15)
Block(-7,72,-3,STAINED_GLASS:15)
Block(-7,72,-2,STAINED_GLASS:15)
Block(-7,72,-1,STAINED_GLASS:15)
Block(-7,72,0,STAINED_GLASS:15)
Block(-7,72,1,STAINED_GLASS:15)
Block(-7,72,2,STAINED_GLASS:15)
Block(-7,72,3,STAINED_GLASS:15)
Block(-7,72,4,STAINED_GLASS:15)
Block(-7,72,5,STAINED_GLASS:15)
Block(-7,72,6,STAINED_GLASS:15)
Block(-7,72,7,STAINED_GLASS:15)
Block(-7,72,8,CONCRETE:8)
Block(-7,78,-7,CONCRETE:15)
Block(-7,78,-6,STAINED_GLASS:15)
Block(-7,78,-5,STAINED_GLASS:15)
Block(-7,78,-4,STAINED_GLASS:15)
Block(-7,78,-3,STAINED_GLASS:15)
Block(-7,78,-2,STAINED_GLASS:15)
Block(-7,78,-1,STAINED_GLASS:15)
Block(-7,78,0,STAINED_GLASS:15)
Block(-7,78,1,STAINED_GLASS:15)
Block(-7,78,2,STAINED_GLASS:15)
Block(-7,78,3,STAINED_GLASS:15)
Block(-7,78,4,STAINED_GLASS:15)
Block(-7,78,5,STAINED_GLASS:15)
Block(-7,78,6,STAINED_GLASS:15)
Block(-7,78,7,STAINED_GLASS:15)
Block(-7,78,8,CONCRETE:15)
Block(-7,84,-7,CONCRETE:8)
Block(-7,84,-6,STAINED_GLASS:15)
Block(-7,84,-5,STAINED_GLASS:15)
Block(-7,84,-4,STAINED_GLASS:15)
Block(-7,84,-3,STAINED_GLASS:15)
Block(-7,84,-2,STAINED_GLASS:15)
Block(-7,84,-1,STAINED_GLASS:15)
Block(-7,84,0,STAINED_GLASS:15)
Block(-7,84,1,STAINED_GLASS:15)
Block(-7,84,2,STAINED_GLASS:15)
Block(-7,84,3,STAINED_GLASS:15)
Block(-7,84,4,STAINED_GLASS:15)
Block(-7,84,5,STAINED_GLASS:15)
Block(-7,84,6,STAINED_GLASS:15)
Block(-7,84,7,STAINED_GLASS:15)
Block(-7,84,8,CONCRETE:8)
Block(-7,85,2,STAINED_GLASS_PANE:15)
Block(-7,90,-7,CONCRETE:8)
Block(-7,90,-6,STAINED_GLASS:15)
Block(-7,90,-5,STAINED_GLASS:15)
Block(-7,90,-4,STAINED_GLASS:15)
Block(-7,90,-3,STAINED_GLASS:15)
Block(-7,90,-2,STAINED_GLASS:15)
Block(-7,90,-1,STAINED_GLASS:15)
Block(-7,90,0,STAINED_GLASS:15)
Block(-7,90,1,STAINED_GLASS:15)
Block(-7,90,2,STAINED_GLASS:15)
Block(-7,90,3,STAINED_GLASS:15)
Block(-7,90,4,STAINED_GLASS:15)
Block(-7,90,5,STAINED_GLASS:15)
Block(-7,90,6,STAINED_GLASS:15)
Block(-7,90,7,STAINED_GLASS:15)
Block(-7,90,8,CONCRETE:8)
Block(-7,96,-7,CONCRETE:15)
Block(-7,96,-6,STAINED_GLASS:15)
Block(-7,96,-5,STAINED_GLASS:15)
Block(-7,96,-4,STAINED_GLASS:15)
Block(-7,96,-3,STAINED_GLASS:15)
Block(-7,96,-2,STAINED_GLASS:15)
Block(-7,96,-1,STAINED_GLASS:15)
Block(-7,96,0,STAINED_GLASS:15)
Block(-7,96,1,STAINED_GLASS:15)
Block(-7,96,2,STAINED_GLASS:15)
Block(-7,96,3,STAINED_GLASS:15)
Block(-7,96,4,STAINED_GLASS:15)
Block(-7,96,5,STAINED_GLASS:15)
Block(-7,96,6,STAINED_GLASS:15)
Block(-7,96,7,STAINED_GLASS:15)
Block(-7,96,8,CONCRETE:8)
Block(-7,102,-7,CONCRETE:8)
Block(-7,102,-6,STAINED_GLASS:15)
Block(-7,102,-5,STAINED_GLASS:15)
Block(-7,102,-4,STAINED_GLASS:15)
Block(-7,102,-3,STAINED_GLASS:15)
Block(-7,102,-2,STAINED_GLASS:15)
Block(-7,102,-1,STAINED_GLASS:15)
Block(-7,102,0,STAINED_GLASS:15)
Block(-7,102,1,STAINED_GLASS:15)
Block(-7,102,2,STAINED_GLASS:15)
Block(-7,102,3,STAINED_GLASS:15)
Block(-7,102,4,STAINED_GLASS:15)
Block(-7,102,5,STAINED_GLASS:15)
Block(-7,102,6,STAINED_GLASS:15)
Block(-7,102,7,STAINED_GLASS:15)
Block(-7,102,8,CONCRETE:8)
Block(-7,108,-7,CONCRETE:8)
Block(-7,108,-6,STAINED_GLASS:15)
Block(-7,108,-5,STAINED_GLASS:15)
Block(-7,108,-4,STAINED_GLASS:15)
Block(-7,108,-3,STAINED_GLASS:15)
Block(-7,108,-2,STAINED_GLASS:15)
Block(-7,108,-1,STAINED_GLASS:15)
Block(-7,108,0,STAINED_GLASS:15)
Block(-7,108,1,STAINED_GLASS:15)
Block(-7,108,2,STAINED_GLASS:15)
Block(-7,108,3,STAINED_GLASS:15)
Block(-7,108,4,STAINED_GLASS:15)
Block(-7,108,5,STAINED_GLASS:15)
Block(-7,108,6,STAINED_GLASS:15)
Block(-7,108,7,STAINED_GLASS:15)
Block(-7,108,8,CONCRETE:8)
Block(-7,114,-7,CONCRETE:8)
Block(-7,114,-6,STAINED_GLASS:15)
Block(-7,114,-5,STAINED_GLASS:15)
Block(-7,114,-4,STAINED_GLASS:15)
Block(-7,114,-3,STAINED_GLASS:15)
Block(-7,114,-2,STAINED_GLASS:15)
Block(-7,114,-1,STAINED_GLASS:15)
Block(-7,114,0,STAINED_GLASS:15)
Block(-7,114,1,STAINED_GLASS:15)
Block(-7,114,2,STAINED_GLASS:15)
Block(-7,114,3,STAINED_GLASS:15)
Block(-7,114,4,STAINED_GLASS:15)
Block(-7,114,5,STAINED_GLASS:15)
Block(-7,114,6,STAINED_GLASS:15)
Block(-7,114,7,STAINED_GLASS:15)
Block(-7,114,8,CONCRETE:8)
Block(-7,120,-7,CONCRETE:8)
Block(-7,120,-6,STAINED_GLASS:15)
Block(-7,120,-5,STAINED_GLASS:15)
Block(-7,120,-4,STAINED_GLASS:15)
Block(-7,120,-3,STAINED_GLASS:15)
Block(-7,120,-2,STAINED_GLASS:15)
Block(-7,120,-1,STAINED_GLASS:15)
Block(-7,120,0,STAINED_GLASS:15)
Block(-7,120,1,STAINED_GLASS:15)
Block(-7,120,2,STAINED_GLASS:15)
Block(-7,120,3,STAINED_GLASS:15)
Block(-7,120,4,STAINED_GLASS:15)
Block(-7,120,5,STAINED_GLASS:15)
Block(-7,120,6,STAINED_GLASS:15)
Block(-7,120,7,STAINED_GLASS:15)
Block(-7,120,8,CONCRETE:8)
Block(-7,126,-7,CONCRETE:8)
Block(-7,126,-6,STAINED_GLASS:15)
Block(-7,126,-5,STAINED_GLASS:15)
Block(-7,126,-4,STAINED_GLASS:15)
Block(-7,126,-3,STAINED_GLASS:15)
Block(-7,126,-2,STAINED_GLASS:15)
Block(-7,126,-1,STAINED_GLASS:15)
Block(-7,126,0,STAINED_GLASS:15)
Block(-7,126,1,STAINED_GLASS:15)
Block(-7,126,2,STAINED_GLASS:15)
Block(-7,126,3,STAINED_GLASS:15)
Block(-7,126,4,STAINED_GLASS:15)
Block(-7,126,5,STAINED_GLASS:15)
Block(-7,126,6,STAINED_GLASS:15)
Block(-7,126,7,STAINED_GLASS:15)
Block(-7,126,8,CONCRETE:8)
Block(-7,132,-7,CONCRETE:8)
Block(-7,132,-6,STAINED_GLASS:15)
Block(-7,132,-5,STAINED_GLASS:15)
Block(-7,132,-4,STAINED_GLASS:15)
Block(-7,132,-3,STAINED_GLASS:15)
Block(-7,132,-2,STAINED_GLASS:15)
Block(-7,132,-1,STAINED_GLASS:15)
Block(-7,132,0,STAINED_GLASS:15)
Block(-7,132,1,STAINED_GLASS:15)
Block(-7,132,2,STAINED_GLASS:15)
Block(-7,132,3,STAINED_GLASS:15)
Block(-7,132,4,STAINED_GLASS:15)
Block(-7,132,5,STAINED_GLASS:15)
Block(-7,132,6,STAINED_GLASS:15)
Block(-7,132,7,STAINED_GLASS:15)
Block(-7,132,8,CONCRETE:8)
Block(-7,138,-7,CONCRETE:8)
Block(-7,138,-6,STAINED_GLASS:15)
Block(-7,138,-5,STAINED_GLASS:15)
Block(-7,138,-4,STAINED_GLASS:15)
Block(-7,138,-3,STAINED_GLASS:15)
Block(-7,138,-2,STAINED_GLASS:15)
Block(-7,138,-1,STAINED_GLASS:15)
Block(-7,138,0,STAINED_GLASS:15)
Block(-7,138,1,STAINED_GLASS:15)
Block(-7,138,2,STAINED_GLASS:15)
Block(-7,138,3,STAINED_GLASS:15)
Block(-7,138,4,STAINED_GLASS:15)
Block(-7,138,5,STAINED_GLASS:15)
Block(-7,138,6,STAINED_GLASS:15)
Block(-7,138,7,STAINED_GLASS:15)
Block(-7,138,8,CONCRETE:8)
Block(-7,144,-7,CONCRETE:8)
Block(-7,144,-6,STAINED_GLASS:15)
Block(-7,144,-5,STAINED_GLASS:15)
Block(-7,144,-4,STAINED_GLASS:15)
Block(-7,144,-3,STAINED_GLASS:15)
Block(-7,144,-2,STAINED_GLASS:15)
Block(-7,144,-1,STAINED_GLASS:15)
Block(-7,144,0,STAINED_GLASS:15)
Block(-7,144,1,STAINED_GLASS:15)
Block(-7,144,2,STAINED_GLASS:15)
Block(-7,144,3,STAINED_GLASS:15)
Block(-7,144,4,STAINED_GLASS:15)
Block(-7,144,5,STAINED_GLASS:15)
Block(-7,144,6,STAINED_GLASS:15)
Block(-7,144,7,STAINED_GLASS:15)
Block(-7,144,8,CONCRETE:8)
Block(-7,150,-7,CONCRETE:8)
Block(-7,150,-6,STAINED_GLASS:15)
Block(-7,150,-5,STAINED_GLASS:15)
Block(-7,150,-4,STAINED_GLASS:15)
Block(-7,150,-3,STAINED_GLASS:15)
Block(-7,150,-2,STAINED_GLASS:15)
Block(-7,150,-1,STAINED_GLASS:15)
Block(-7,150,0,STAINED_GLASS:15)
Block(-7,150,1,STAINED_GLASS:15)
Block(-7,150,2,STAINED_GLASS:15)
Block(-7,150,3,STAINED_GLASS:15)
Block(-7,150,4,STAINED_GLASS:15)
Block(-7,150,5,STAINED_GLASS:15)
Block(-7,150,6,STAINED_GLASS:15)
Block(-7,150,7,STAINED_GLASS:15)
Block(-7,150,8,CONCRETE:8)
Block(-7,156,-7,CONCRETE:8)
Block(-7,156,-6,STAINED_GLASS:15)
Block(-7,156,-5,STAINED_GLASS:15)
Block(-7,156,-4,STAINED_GLASS:15)
Block(-7,156,-3,STAINED_GLASS:15)
Block(-7,156,-2,STAINED_GLASS:15)
Block(-7,156,-1,STAINED_GLASS:15)
Block(-7,156,0,STAINED_GLASS:15)
Block(-7,156,1,STAINED_GLASS:15)
Block(-7,156,2,STAINED_GLASS:15)
Block(-7,156,3,STAINED_GLASS:15)
Block(-7,156,4,STAINED_GLASS:15)
Block(-7,156,5,STAINED_GLASS:15)
Block(-7,156,6,STAINED_GLASS:15)
Block(-7,156,7,STAINED_GLASS:15)
Block(-7,156,8,CONCRETE:8)
Block(-7,162,-7,CONCRETE:8)
Block(-7,162,-6,STAINED_GLASS:15)
Block(-7,162,-5,STAINED_GLASS:15)
Block(-7,162,-4,STAINED_GLASS:15)
Block(-7,162,-3,STAINED_GLASS:15)
Block(-7,162,-2,STAINED_GLASS:15)
Block(-7,162,-1,STAINED_GLASS:15)
Block(-7,162,0,STAINED_GLASS:15)
Block(-7,162,1,STAINED_GLASS:15)
Block(-7,162,2,STAINED_GLASS:15)
Block(-7,162,3,STAINED_GLASS:15)
Block(-7,162,4,STAINED_GLASS:15)
Block(-7,162,5,STAINED_GLASS:15)
Block(-7,162,6,STAINED_GLASS:15)
Block(-7,162,7,STAINED_GLASS:15)
Block(-7,162,8,CONCRETE:8)
Block(-7,168,-7,CONCRETE:8)
Block(-7,168,-6,STAINED_GLASS:15)
Block(-7,168,-5,STAINED_GLASS:15)
Block(-7,168,-4,STAINED_GLASS:15)
Block(-7,168,-3,STAINED_GLASS:15)
Block(-7,168,-2,STAINED_GLASS:15)
Block(-7,168,-1,STAINED_GLASS:15)
Block(-7,168,0,STAINED_GLASS:15)
Block(-7,168,1,STAINED_GLASS:15)
Block(-7,168,2,STAINED_GLASS:15)
Block(-7,168,3,STAINED_GLASS:15)
Block(-7,168,4,STAINED_GLASS:15)
Block(-7,168,5,STAINED_GLASS:15)
Block(-7,168,6,STAINED_GLASS:15)
Block(-7,168,7,STAINED_GLASS:15)
Block(-7,168,8,CONCRETE:8)
Block(-7,174,-7,CONCRETE:8)
Block(-7,174,-6,STAINED_GLASS:15)
Block(-7,174,-5,STAINED_GLASS:15)
Block(-7,174,-4,STAINED_GLASS:15)
Block(-7,174,-3,STAINED_GLASS:15)
Block(-7,174,-2,STAINED_GLASS:15)
Block(-7,174,-1,STAINED_GLASS:15)
Block(-7,174,0,STAINED_GLASS:15)
Block(-7,174,1,STAINED_GLASS:15)
Block(-7,174,2,STAINED_GLASS:15)
Block(-7,174,3,STAINED_GLASS:15)
Block(-7,174,4,STAINED_GLASS:15)
Block(-7,174,5,STAINED_GLASS:15)
Block(-7,174,6,STAINED_GLASS:15)
Block(-7,174,7,STAINED_GLASS:15)
Block(-7,174,8,CONCRETE:8)
Block(-7,180,-7,CONCRETE:8)
Block(-7,180,-6,STAINED_GLASS:15)
Block(-7,180,-5,STAINED_GLASS:15)
Block(-7,180,-4,STAINED_GLASS:15)
Block(-7,180,-3,STAINED_GLASS:15)
Block(-7,180,-2,STAINED_GLASS:15)
Block(-7,180,-1,STAINED_GLASS:15)
Block(-7,180,0,STAINED_GLASS:15)
Block(-7,180,1,STAINED_GLASS:15)
Block(-7,180,2,STAINED_GLASS:15)
Block(-7,180,3,STAINED_GLASS:15)
Block(-7,180,4,STAINED_GLASS:15)
Block(-7,180,5,STAINED_GLASS:15)
Block(-7,180,6,STAINED_GLASS:15)
Block(-7,180,7,STAINED_GLASS:15)
Block(-7,180,8,CONCRETE:8)
Block(-7,186,-7,CONCRETE:8)
Block(-7,186,-6,STAINED_GLASS:15)
Block(-7,186,-5,STAINED_GLASS:15)
Block(-7,186,-4,STAINED_GLASS:15)
Block(-7,186,-3,STAINED_GLASS:15)
Block(-7,186,-2,STAINED_GLASS:15)
Block(-7,186,-1,STAINED_GLASS:15)
Block(-7,186,0,STAINED_GLASS:15)
Block(-7,186,1,STAINED_GLASS:15)
Block(-7,186,2,STAINED_GLASS:15)
Block(-7,186,3,STAINED_GLASS:15)
Block(-7,186,4,STAINED_GLASS:15)
Block(-7,186,5,STAINED_GLASS:15)
Block(-7,186,6,STAINED_GLASS:15)
Block(-7,186,7,STAINED_GLASS:15)
Block(-7,186,8,CONCRETE:8)
Block(-7,192,-7,CONCRETE:8)
Block(-7,192,-6,CONCRETE:8)
Block(-7,192,-5,CONCRETE:8)
Block(-7,192,-4,CONCRETE:8)
Block(-7,192,-3,CONCRETE:8)
Block(-7,192,-2,CONCRETE:8)
Block(-7,192,-1,CONCRETE:8)
Block(-7,192,0,CONCRETE:8)
Block(-7,192,1,CONCRETE:8)
Block(-7,192,2,CONCRETE:8)
Block(-7,192,3,CONCRETE:8)
Block(-7,192,4,CONCRETE:8)
Block(-7,192,5,CONCRETE:8)
Block(-7,192,6,CONCRETE:8)
Block(-7,192,7,CONCRETE:8)
Block(-7,192,8,CONCRETE:8)
Block(-7,193,-2,PRISMARINE:2)
Block(-7,193,-1,CARPET:10)
Block(-7,193,0,CARPET:15)
Block(-7,193,1,CARPET:10)
Block(-7,193,2,CARPET:15)
Block(-7,193,3,CARPET:10)
Block(-7,193,4,CARPET:15)
Block(-7,193,6,QUARTZ_BLOCK:1)
Block(-7,193,8,STAINED_GLASS_PANE:15)
Block(-7,194,-2,PRISMARINE:2)
Block(-7,194,6,QUARTZ_STAIRS:6)
Block(-7,195,-3,WALL_BANNER:2,NBT/skyscraper_3x3_01/2665-bannerC16R16.nbt)
Block(-7,195,-2,PRISMARINE:2)
Block(-7,195,6,QUARTZ_STAIRS:6)
Block(-7,196,-2,WOOD_STEP:5)
Block(-7,196,6,QUARTZ_STAIRS:6)
Block(-7,197,-1,QUARTZ_STAIRS:6)
Block(-7,197,0,STAINED_GLASS:15)
Block(-7,197,1,STAINED_GLASS:15)
Block(-7,197,2,QUARTZ_STAIRS:7)
Block(-7,197,6,QUARTZ_STAIRS:6)
Block(-7,198,-7,CONCRETE:8)
Block(-7,198,-6,CONCRETE:8)
Block(-7,198,-5,CONCRETE:8)
Block(-7,198,-4,CONCRETE:8)
Block(-7,198,-3,CONCRETE:8)
Block(-7,198,-2,CONCRETE:8)
Block(-7,198,-1,QUARTZ_STAIRS:3)
Block(-7,198,2,QUARTZ_STAIRS:2)
Block(-7,198,3,CONCRETE:8)
Block(-7,198,4,CONCRETE:8)
Block(-7,198,5,CONCRETE:8)
Block(-7,198,6,CONCRETE:8)
Block(-7,198,7,CONCRETE:8)
Block(-7,198,8,CONCRETE:8)
Block(-7,199,-7,CONCRETE:8)
Block(-7,199,-6,CONCRETE:8)
Block(-7,199,-5,CONCRETE:8)
Block(-7,199,-4,CONCRETE:8)
Block(-7,199,-3,CONCRETE:8)
Block(-7,199,-2,QUARTZ_STAIRS:3)
Block(-7,199,3,QUARTZ_STAIRS:2)
Block(-7,199,4,CONCRETE:8)
Block(-7,199,5,CONCRETE:8)
Block(-7,199,6,CONCRETE:8)
Block(-7,199,7,CONCRETE:8)
Block(-7,199,8,CONCRETE:8)
Block(-7,200,-3,IRON_DOOR_BLOCK:3)
Block(-7,200,4,IRON_DOOR_BLOCK:1)
Block(-7,201,-3,IRON_DOOR_BLOCK:9)
Block(-7,201,4,IRON_DOOR_BLOCK:8)
Block(-7,202,-3,STAINED_GLASS:15)
Block(-7,202,-2,STAINED_GLASS:15)
Block(-7,202,-1,STAINED_GLASS:15)
Block(-7,202,0,STAINED_GLASS:15)
Block(-7,202,1,STAINED_GLASS:15)
Block(-7,202,2,STAINED_GLASS:15)
Block(-7,202,3,STAINED_GLASS:15)
Block(-7,202,4,STAINED_GLASS:15)
Block(-6,0,-7,CONCRETE:7)
Block(-6,0,-6,CONCRETE:7)
Block(-6,0,-5,CONCRETE:7)
Block(-6,0,-4,CONCRETE:7)
Block(-6,0,-3,CONCRETE:7)
Block(-6,0,-2,CONCRETE:7)
Block(-6,0,-1,CONCRETE:7)
Block(-6,0,0,CONCRETE:7)
Block(-6,0,1,CONCRETE:7)
Block(-6,0,2,CONCRETE:7)
Block(-6,0,3,CONCRETE:7)
Block(-6,0,4,CONCRETE:7)
Block(-6,0,5,CONCRETE:7)
Block(-6,0,6,CONCRETE:7)
Block(-6,0,7,CONCRETE:7)
Block(-6,0,8,CONCRETE:7)
Block(-6,1,-7,CONCRETE:7)
Block(-6,1,-6,CONCRETE:7)
Block(-6,1,-5,CONCRETE:7)
Block(-6,1,-4,CONCRETE:7)
Block(-6,1,-3,CONCRETE:7)
Block(-6,1,-2,CONCRETE:7)
Block(-6,1,-1,CONCRETE:7)
Block(-6,1,0,CONCRETE:7)
Block(-6,1,1,CONCRETE:7)
Block(-6,1,2,CONCRETE:7)
Block(-6,1,3,STATIONARY_WATER:0)
Block(-6,1,4,STATIONARY_WATER:0)
Block(-6,1,5,CONCRETE:7)
Block(-6,1,6,CONCRETE:7)
Block(-6,1,7,CONCRETE:7)
Block(-6,1,8,CONCRETE:7)
Block(-6,2,-7,SMOOTH_STAIRS:1)
Block(-6,2,-6,SMOOTH_STAIRS:1)
Block(-6,2,-5,SMOOTH_STAIRS:1)
Block(-6,2,-4,SMOOTH_STAIRS:1)
Block(-6,2,-3,SMOOTH_STAIRS:1)
Block(-6,2,-2,SMOOTH_STAIRS:1)
Block(-6,2,-1,SMOOTH_STAIRS:1)
Block(-6,2,0,SMOOTH_STAIRS:1)
Block(-6,2,1,SMOOTH_STAIRS:1)
Block(-6,2,2,SMOOTH_STAIRS:1)
Block(-6,2,3,AIR:0)
Block(-6,2,4,AIR:0)
Block(-6,2,5,SMOOTH_STAIRS:1)
Block(-6,2,6,SMOOTH_STAIRS:1)
Block(-6,2,7,SMOOTH_STAIRS:1)
Block(-6,2,8,SMOOTH_STAIRS:1)
Block(-6,3,-7,AIR:0)
Block(-6,3,-6,AIR:0)
Block(-6,3,-5,AIR:0)
Block(-6,3,-4,AIR:0)
Block(-6,3,-3,AIR:0)
Block(-6,3,-2,AIR:0)
Block(-6,3,-1,AIR:0)
Block(-6,3,0,AIR:0)
Block(-6,3,1,AIR:0)
Block(-6,3,2,AIR:0)
Block(-6,3,3,AIR:0)
Block(-6,3,4,AIR:0)
Block(-6,3,5,AIR:0)
Block(-6,3,6,AIR:0)
Block(-6,3,7,AIR:0)
Block(-6,3,8,AIR:0)
Block(-6,4,-7,AIR:0)
Block(-6,4,-6,AIR:0)
Block(-6,4,-5,AIR:0)
Block(-6,4,-4,AIR:0)
Block(-6,4,-3,AIR:0)
Block(-6,4,-2,AIR:0)
Block(-6,4,-1,AIR:0)
Block(-6,4,0,AIR:0)
Block(-6,4,1,AIR:0)
Block(-6,4,2,AIR:0)
Block(-6,4,3,AIR:0)
Block(-6,4,4,AIR:0)
Block(-6,4,5,AIR:0)
Block(-6,4,6,AIR:0)
Block(-6,4,7,AIR:0)
Block(-6,4,8,AIR:0)
Block(-6,5,-7,AIR:0)
Block(-6,5,-6,AIR:0)
Block(-6,5,-5,AIR:0)
Block(-6,5,-4,AIR:0)
Block(-6,5,-3,AIR:0)
Block(-6,5,-2,AIR:0)
Block(-6,5,-1,AIR:0)
Block(-6,5,0,AIR:0)
Block(-6,5,1,AIR:0)
Block(-6,5,2,AIR:0)
Block(-6,5,3,AIR:0)
Block(-6,5,4,AIR:0)
Block(-6,5,5,AIR:0)
Block(-6,5,6,CONCRETE:12)
Block(-6,5,7,CONCRETE:4)
Block(-6,5,8,AIR:0)
Block(-6,6,-7,CONCRETE:7)
Block(-6,6,-6,AIR:0)
Block(-6,6,-5,AIR:0)
Block(-6,6,-4,AIR:0)
Block(-6,6,-3,AIR:0)
Block(-6,6,-2,AIR:0)
Block(-6,6,-1,AIR:0)
Block(-6,6,0,AIR:0)
Block(-6,6,1,AIR:0)
Block(-6,6,2,AIR:0)
Block(-6,6,3,AIR:0)
Block(-6,6,4,AIR:0)
Block(-6,6,5,AIR:0)
Block(-6,6,6,AIR:0)
Block(-6,6,7,AIR:0)
Block(-6,6,8,AIR:0)
Block(-6,7,-7,CONCRETE:7)
Block(-6,7,-6,CONCRETE:7)
Block(-6,7,-5,CONCRETE:7)
Block(-6,7,-4,CONCRETE:7)
Block(-6,7,-3,CONCRETE:7)
Block(-6,7,-2,CONCRETE:7)
Block(-6,7,-1,CONCRETE:7)
Block(-6,7,0,CONCRETE:7)
Block(-6,7,1,CONCRETE:7)
Block(-6,7,2,CONCRETE:7)
Block(-6,7,3,CONCRETE:7)
Block(-6,7,4,CONCRETE:7)
Block(-6,7,5,CONCRETE:7)
Block(-6,7,6,CONCRETE:7)
Block(-6,7,7,CONCRETE:7)
Block(-6,7,8,CONCRETE:7)
Block(-6,8,-7,CONCRETE:7)
Block(-6,8,-6,CONCRETE:7)
Block(-6,8,-5,CONCRETE:7)
Block(-6,8,-4,SMOOTH_STAIRS:1)
Block(-6,8,-3,SMOOTH_STAIRS:1)
Block(-6,8,-2,CONCRETE:7)
Block(-6,8,-1,AIR:0)
Block(-6,8,0,AIR:0)
Block(-6,8,1,CONCRETE:12)
Block(-6,8,2,AIR:0)
Block(-6,8,3,AIR:0)
Block(-6,8,4,AIR:0)
Block(-6,8,5,AIR:0)
Block(-6,8,6,AIR:0)
Block(-6,8,7,CONCRETE:7)
Block(-6,8,8,CONCRETE:7)
Block(-6,9,-7,CONCRETE:7)
Block(-6,9,-6,CONCRETE:7)
Block(-6,9,-5,CONCRETE:7)
Block(-6,9,-4,AIR:0)
Block(-6,9,-3,AIR:0)
Block(-6,9,-2,CONCRETE:7)
Block(-6,9,-1,AIR:0)
Block(-6,9,0,AIR:0)
Block(-6,9,1,AIR:0)
Block(-6,9,2,AIR:0)
Block(-6,9,3,AIR:0)
Block(-6,9,4,AIR:0)
Block(-6,9,5,AIR:0)
Block(-6,9,6,AIR:0)
Block(-6,9,7,CONCRETE:7)
Block(-6,9,8,CONCRETE:7)
Block(-6,10,-7,SMOOTH_STAIRS:0)
Block(-6,10,-6,SMOOTH_STAIRS:0)
Block(-6,10,-5,CONCRETE:7)
Block(-6,10,-4,AIR:0)
Block(-6,10,-3,AIR:0)
Block(-6,10,-2,CONCRETE:7)
Block(-6,10,-1,AIR:0)
Block(-6,10,0,AIR:0)
Block(-6,10,1,AIR:0)
Block(-6,10,2,AIR:0)
Block(-6,10,3,AIR:0)
Block(-6,10,4,AIR:0)
Block(-6,10,5,AIR:0)
Block(-6,10,6,AIR:0)
Block(-6,10,7,CONCRETE:7)
Block(-6,10,8,CONCRETE:7)
Block(-6,11,-7,AIR:0)
Block(-6,11,-6,AIR:0)
Block(-6,11,-5,CONCRETE:7)
Block(-6,11,-4,AIR:0)
Block(-6,11,-3,AIR:0)
Block(-6,11,-2,CONCRETE:7)
Block(-6,11,-1,AIR:0)
Block(-6,11,0,AIR:0)
Block(-6,11,1,AIR:0)
Block(-6,11,2,AIR:0)
Block(-6,11,3,AIR:0)
Block(-6,11,4,AIR:0)
Block(-6,11,5,AIR:0)
Block(-6,11,6,AIR:0)
Block(-6,11,7,CONCRETE:7)
Block(-6,11,8,CONCRETE:7)
Block(-6,12,-7,AIR:0)
Block(-6,12,-6,AIR:0)
Block(-6,12,-5,CONCRETE:7)
Block(-6,12,-4,CONCRETE:7)
Block(-6,12,-3,CONCRETE:7)
Block(-6,12,-2,CONCRETE:7)
Block(-6,12,-1,CONCRETE:7)
Block(-6,12,0,CONCRETE:7)
Block(-6,12,1,CONCRETE:7)
Block(-6,12,2,CONCRETE:7)
Block(-6,12,3,CONCRETE:7)
Block(-6,12,4,CONCRETE:7)
Block(-6,12,5,CONCRETE:7)
Block(-6,12,6,CONCRETE:7)
Block(-6,12,7,CONCRETE:7)
Block(-6,12,8,CONCRETE:7)
Block(-6,13,-7,AIR:0)
Block(-6,13,-6,AIR:0)
Block(-6,13,-5,IRON_FENCE:0)
Block(-6,13,-4,AIR:0)
Block(-6,13,-3,CONCRETE:11)
Block(-6,13,-2,AIR:0)
Block(-6,13,-1,CONCRETE:7)
Block(-6,13,0,CONCRETE:11)
Block(-6,13,1,CONCRETE:11)
Block(-6,13,2,CONCRETE:7)
Block(-6,13,3,LEVER:1)
Block(-6,13,4,AIR:0)
Block(-6,13,5,STONE:6)
Block(-6,13,6,CONCRETE:15)
Block(-6,13,7,CONCRETE:15)
Block(-6,13,8,CONCRETE:15)
Block(-6,14,-7,AIR:0)
Block(-6,14,-6,AIR:0)
Block(-6,14,-5,AIR:0)
Block(-6,14,-4,AIR:0)
Block(-6,14,-3,AIR:0)
Block(-6,14,-2,AIR:0)
Block(-6,14,-1,STONE:6)
Block(-6,14,0,STATIONARY_WATER:1)
Block(-6,14,1,STATIONARY_WATER:1)
Block(-6,14,2,STONE:6)
Block(-6,14,3,AIR:0)
Block(-6,14,4,AIR:0)
Block(-6,14,5,STONE:6)
Block(-6,14,6,CONCRETE:15)
Block(-6,14,7,CONCRETE:15)
Block(-6,14,8,CONCRETE:15)
Block(-6,15,-7,AIR:0)
Block(-6,15,-6,AIR:0)
Block(-6,15,-5,AIR:0)
Block(-6,15,-4,AIR:0)
Block(-6,15,-3,AIR:0)
Block(-6,15,-2,AIR:0)
Block(-6,15,-1,STONE:6)
Block(-6,15,0,AIR:0)
Block(-6,15,1,AIR:0)
Block(-6,15,2,STONE:6)
Block(-6,15,3,AIR:0)
Block(-6,15,4,AIR:0)
Block(-6,15,5,STONE:6)
Block(-6,15,6,CONCRETE:15)
Block(-6,15,7,CONCRETE:15)
Block(-6,15,8,CONCRETE:11)
Block(-6,16,-7,AIR:0)
Block(-6,16,-6,AIR:0)
Block(-6,16,-5,AIR:0)
Block(-6,16,-4,AIR:0)
Block(-6,16,-3,AIR:0)
Block(-6,16,-2,AIR:0)
Block(-6,16,-1,STONE:6)
Block(-6,16,0,STONE:6)
Block(-6,16,1,STONE:6)
Block(-6,16,2,STONE:6)
Block(-6,16,3,AIR:0)
Block(-6,16,4,AIR:0)
Block(-6,16,5,STONE:6)
Block(-6,16,6,STONE:6)
Block(-6,16,7,STONE:6)
Block(-6,16,8,SMOOTH_STAIRS:1)
Block(-6,17,-7,CONCRETE:7)
Block(-6,17,-6,CONCRETE:7)
Block(-6,17,-5,CONCRETE:7)
Block(-6,17,-4,CONCRETE:7)
Block(-6,17,-3,CONCRETE:7)
Block(-6,17,-2,CONCRETE:7)
Block(-6,17,-1,CONCRETE:7)
Block(-6,17,0,CONCRETE:7)
Block(-6,17,1,CONCRETE:7)
Block(-6,17,2,CONCRETE:7)
Block(-6,17,3,CONCRETE:7)
Block(-6,17,4,CONCRETE:7)
Block(-6,17,5,CONCRETE:7)
Block(-6,17,6,CONCRETE:7)
Block(-6,17,7,CONCRETE:7)
Block(-6,17,8,CONCRETE:7)
Block(-6,18,-7,CONCRETE:15)
Block(-6,18,-6,CONCRETE:15)
Block(-6,18,-5,CONCRETE:15)
Block(-6,18,-4,CONCRETE:15)
Block(-6,18,-3,CONCRETE:15)
Block(-6,18,-2,CONCRETE:15)
Block(-6,18,-1,CONCRETE:15)
Block(-6,18,0,CONCRETE:8)
Block(-6,18,1,CONCRETE:8)
Block(-6,18,2,CONCRETE:15)
Block(-6,18,3,CONCRETE:15)
Block(-6,18,4,CONCRETE:15)
Block(-6,18,5,CONCRETE:15)
Block(-6,18,6,CONCRETE:15)
Block(-6,18,7,CONCRETE:15)
Block(-6,18,8,CONCRETE:15)
Block(-6,19,-5,CONCRETE:15)
Block(-6,19,-4,CONCRETE:15)
Block(-6,19,-3,CONCRETE:15)
Block(-6,19,-2,CONCRETE:15)
Block(-6,19,-1,CONCRETE:15)
Block(-6,19,2,CONCRETE:15)
Block(-6,19,3,CONCRETE:15)
Block(-6,19,4,CONCRETE:15)
Block(-6,19,5,CONCRETE:15)
Block(-6,19,6,CONCRETE:15)
Block(-6,20,-5,CONCRETE:15)
Block(-6,20,-4,CONCRETE:15)
Block(-6,20,-3,CONCRETE:15)
Block(-6,20,-2,CONCRETE:15)
Block(-6,20,-1,CONCRETE:15)
Block(-6,20,2,CONCRETE:15)
Block(-6,20,3,CONCRETE:15)
Block(-6,20,4,CONCRETE:15)
Block(-6,20,5,CONCRETE:15)
Block(-6,20,6,CONCRETE:15)
Block(-6,21,-5,CONCRETE:15)
Block(-6,21,-4,CONCRETE:15)
Block(-6,21,-3,CONCRETE:15)
Block(-6,21,-2,CONCRETE:15)
Block(-6,21,-1,CONCRETE:15)
Block(-6,21,2,CONCRETE:15)
Block(-6,21,3,CONCRETE:15)
Block(-6,21,4,CONCRETE:15)
Block(-6,21,5,CONCRETE:15)
Block(-6,21,6,CONCRETE:15)
Block(-6,22,-5,CONCRETE:15)
Block(-6,22,-4,CONCRETE:15)
Block(-6,22,-3,CONCRETE:15)
Block(-6,22,-2,CONCRETE:15)
Block(-6,22,-1,CONCRETE:15)
Block(-6,22,2,CONCRETE:15)
Block(-6,22,3,CONCRETE:15)
Block(-6,22,4,CONCRETE:15)
Block(-6,22,5,CONCRETE:15)
Block(-6,22,6,CONCRETE:15)
Block(-6,23,-5,CONCRETE:15)
Block(-6,23,-4,CONCRETE:15)
Block(-6,23,-3,CONCRETE:15)
Block(-6,23,-2,CONCRETE:15)
Block(-6,23,-1,CONCRETE:15)
Block(-6,23,0,STAINED_GLASS:15)
Block(-6,23,1,STAINED_GLASS:15)
Block(-6,23,2,CONCRETE:15)
Block(-6,23,3,CONCRETE:15)
Block(-6,23,4,CONCRETE:15)
Block(-6,23,5,CONCRETE:15)
Block(-6,23,6,CONCRETE:15)
Block(-6,24,-7,CONCRETE:15)
Block(-6,24,-6,STAINED_GLASS:15)
Block(-6,24,-5,CONCRETE:15)
Block(-6,24,-4,CONCRETE:15)
Block(-6,24,-3,CONCRETE:15)
Block(-6,24,-2,CONCRETE:15)
Block(-6,24,-1,CONCRETE:15)
Block(-6,24,0,QUARTZ_STAIRS:1)
Block(-6,24,1,QUARTZ_STAIRS:1)
Block(-6,24,2,CONCRETE:15)
Block(-6,24,3,CONCRETE:15)
Block(-6,24,4,CONCRETE:15)
Block(-6,24,5,CONCRETE:15)
Block(-6,24,6,CONCRETE:15)
Block(-6,24,7,STAINED_GLASS:15)
Block(-6,24,8,CONCRETE:15)
Block(-6,25,-5,CONCRETE:15)
Block(-6,25,-4,CONCRETE:15)
Block(-6,25,-3,CONCRETE:15)
Block(-6,25,-2,CONCRETE:15)
Block(-6,25,-1,CONCRETE:15)
Block(-6,25,2,CONCRETE:15)
Block(-6,25,3,CONCRETE:15)
Block(-6,25,4,CONCRETE:15)
Block(-6,25,5,CONCRETE:15)
Block(-6,25,6,CONCRETE:15)
Block(-6,26,-5,CONCRETE:15)
Block(-6,26,-4,CONCRETE:15)
Block(-6,26,-3,CONCRETE:15)
Block(-6,26,-2,CONCRETE:15)
Block(-6,26,-1,CONCRETE:15)
Block(-6,26,2,CONCRETE:15)
Block(-6,26,3,CONCRETE:15)
Block(-6,26,4,CONCRETE:15)
Block(-6,26,5,CONCRETE:15)
Block(-6,26,6,CONCRETE:15)
Block(-6,27,-5,CONCRETE:15)
Block(-6,27,-4,CONCRETE:15)
Block(-6,27,-3,CONCRETE:15)
Block(-6,27,-2,CONCRETE:15)
Block(-6,27,-1,CONCRETE:15)
Block(-6,27,2,CONCRETE:15)
Block(-6,27,3,CONCRETE:15)
Block(-6,27,4,CONCRETE:15)
Block(-6,27,5,CONCRETE:15)
Block(-6,27,6,CONCRETE:15)
Block(-6,28,-5,CONCRETE:15)
Block(-6,28,-4,CONCRETE:15)
Block(-6,28,-3,CONCRETE:15)
Block(-6,28,-2,CONCRETE:15)
Block(-6,28,-1,CONCRETE:15)
Block(-6,28,2,CONCRETE:15)
Block(-6,28,3,CONCRETE:15)
Block(-6,28,4,CONCRETE:15)
Block(-6,28,5,CONCRETE:15)
Block(-6,28,6,CONCRETE:15)
Block(-6,29,-5,CONCRETE:15)
Block(-6,29,-4,CONCRETE:15)
Block(-6,29,-3,CONCRETE:15)
Block(-6,29,-2,CONCRETE:15)
Block(-6,29,-1,CONCRETE:15)
Block(-6,29,0,STAINED_GLASS:15)
Block(-6,29,1,STAINED_GLASS:15)
Block(-6,29,2,CONCRETE:15)
Block(-6,29,3,CONCRETE:15)
Block(-6,29,4,CONCRETE:15)
Block(-6,29,5,CONCRETE:15)
Block(-6,29,6,CONCRETE:15)
Block(-6,30,-7,CONCRETE:15)
Block(-6,30,-6,STAINED_GLASS:15)
Block(-6,30,-5,CONCRETE:15)
Block(-6,30,-4,CONCRETE:15)
Block(-6,30,-3,CONCRETE:15)
Block(-6,30,-2,CONCRETE:15)
Block(-6,30,-1,CONCRETE:15)
Block(-6,30,0,QUARTZ_STAIRS:1)
Block(-6,30,1,QUARTZ_STAIRS:1)
Block(-6,30,2,CONCRETE:15)
Block(-6,30,3,CONCRETE:15)
Block(-6,30,4,CONCRETE:15)
Block(-6,30,5,CONCRETE:15)
Block(-6,30,6,CONCRETE:15)
Block(-6,30,7,STAINED_GLASS:15)
Block(-6,30,8,CONCRETE:15)
Block(-6,31,-5,CONCRETE:15)
Block(-6,31,-4,CONCRETE:15)
Block(-6,31,-3,CONCRETE:15)
Block(-6,31,-2,CONCRETE:15)
Block(-6,31,-1,CONCRETE:15)
Block(-6,31,2,CONCRETE:15)
Block(-6,31,3,CONCRETE:15)
Block(-6,31,4,CONCRETE:15)
Block(-6,31,5,CONCRETE:15)
Block(-6,31,6,CONCRETE:15)
Block(-6,32,-5,CONCRETE:15)
Block(-6,32,-4,CONCRETE:15)
Block(-6,32,-3,CONCRETE:15)
Block(-6,32,-2,CONCRETE:15)
Block(-6,32,-1,CONCRETE:15)
Block(-6,32,2,CONCRETE:15)
Block(-6,32,3,CONCRETE:15)
Block(-6,32,4,CONCRETE:15)
Block(-6,32,5,CONCRETE:15)
Block(-6,32,6,CONCRETE:15)
Block(-6,33,-5,CONCRETE:15)
Block(-6,33,-4,CONCRETE:15)
Block(-6,33,-3,CONCRETE:15)
Block(-6,33,-2,CONCRETE:15)
Block(-6,33,-1,CONCRETE:15)
Block(-6,33,2,CONCRETE:15)
Block(-6,33,3,CONCRETE:15)
Block(-6,33,4,CONCRETE:15)
Block(-6,33,5,CONCRETE:15)
Block(-6,33,6,CONCRETE:15)
Block(-6,34,-5,CONCRETE:15)
Block(-6,34,-4,CONCRETE:15)
Block(-6,34,-3,CONCRETE:15)
Block(-6,34,-2,CONCRETE:15)
Block(-6,34,-1,CONCRETE:15)
Block(-6,34,2,CONCRETE:15)
Block(-6,34,3,CONCRETE:15)
Block(-6,34,4,CONCRETE:15)
Block(-6,34,5,CONCRETE:15)
Block(-6,34,6,CONCRETE:15)
Block(-6,35,-5,CONCRETE:15)
Block(-6,35,-4,CONCRETE:15)
Block(-6,35,-3,CONCRETE:15)
Block(-6,35,-2,CONCRETE:15)
Block(-6,35,-1,CONCRETE:15)
Block(-6,35,0,STAINED_GLASS:15)
Block(-6,35,1,STAINED_GLASS:15)
Block(-6,35,2,CONCRETE:15)
Block(-6,35,3,CONCRETE:15)
Block(-6,35,4,CONCRETE:15)
Block(-6,35,5,CONCRETE:15)
Block(-6,35,6,CONCRETE:15)
Block(-6,36,-7,CONCRETE:8)
Block(-6,36,-6,STAINED_GLASS:15)
Block(-6,36,-5,CONCRETE:15)
Block(-6,36,-4,CONCRETE:15)
Block(-6,36,-3,CONCRETE:15)
Block(-6,36,-2,CONCRETE:15)
Block(-6,36,-1,CONCRETE:15)
Block(-6,36,0,QUARTZ_STAIRS:1)
Block(-6,36,1,QUARTZ_STAIRS:1)
Block(-6,36,2,CONCRETE:15)
Block(-6,36,3,CONCRETE:15)
Block(-6,36,4,CONCRETE:15)
Block(-6,36,5,CONCRETE:15)
Block(-6,36,6,CONCRETE:15)
Block(-6,36,7,STAINED_GLASS:15)
Block(-6,36,8,CONCRETE:8)
Block(-6,37,-5,CONCRETE:15)
Block(-6,37,-4,CONCRETE:15)
Block(-6,37,-3,CONCRETE:15)
Block(-6,37,-2,CONCRETE:15)
Block(-6,37,-1,CONCRETE:15)
Block(-6,37,2,CONCRETE:15)
Block(-6,37,3,CONCRETE:15)
Block(-6,37,4,CONCRETE:15)
Block(-6,37,5,CONCRETE:15)
Block(-6,37,6,CONCRETE:15)
Block(-6,38,-5,CONCRETE:15)
Block(-6,38,-4,CONCRETE:15)
Block(-6,38,-3,CONCRETE:15)
Block(-6,38,-2,CONCRETE:15)
Block(-6,38,-1,CONCRETE:15)
Block(-6,38,2,CONCRETE:15)
Block(-6,38,3,CONCRETE:15)
Block(-6,38,4,CONCRETE:15)
Block(-6,38,5,CONCRETE:15)
Block(-6,38,6,CONCRETE:15)
Block(-6,39,-5,CONCRETE:15)
Block(-6,39,-4,CONCRETE:15)
Block(-6,39,-3,CONCRETE:15)
Block(-6,39,-2,CONCRETE:15)
Block(-6,39,-1,CONCRETE:15)
Block(-6,39,2,CONCRETE:15)
Block(-6,39,3,CONCRETE:15)
Block(-6,39,4,CONCRETE:15)
Block(-6,39,5,CONCRETE:15)
Block(-6,39,6,CONCRETE:15)
Block(-6,40,-5,CONCRETE:15)
Block(-6,40,-4,CONCRETE:15)
Block(-6,40,-3,CONCRETE:15)
Block(-6,40,-2,CONCRETE:15)
Block(-6,40,-1,CONCRETE:15)
Block(-6,40,2,CONCRETE:15)
Block(-6,40,3,CONCRETE:15)
Block(-6,40,4,CONCRETE:15)
Block(-6,40,5,CONCRETE:15)
Block(-6,40,6,CONCRETE:15)
Block(-6,41,-5,CONCRETE:15)
Block(-6,41,-4,CONCRETE:15)
Block(-6,41,-3,CONCRETE:15)
Block(-6,41,-2,CONCRETE:15)
Block(-6,41,-1,CONCRETE:15)
Block(-6,41,0,STAINED_GLASS:15)
Block(-6,41,1,STAINED_GLASS:15)
Block(-6,41,2,CONCRETE:15)
Block(-6,41,3,CONCRETE:15)
Block(-6,41,4,CONCRETE:15)
Block(-6,41,5,CONCRETE:15)
Block(-6,41,6,CONCRETE:15)
Block(-6,42,-7,CONCRETE:8)
Block(-6,42,-6,STAINED_GLASS:15)
Block(-6,42,-5,CONCRETE:15)
Block(-6,42,-4,CONCRETE:15)
Block(-6,42,-3,CONCRETE:15)
Block(-6,42,-2,CONCRETE:15)
Block(-6,42,-1,CONCRETE:15)
Block(-6,42,0,QUARTZ_STAIRS:1)
Block(-6,42,1,QUARTZ_STAIRS:1)
Block(-6,42,2,CONCRETE:15)
Block(-6,42,3,CONCRETE:15)
Block(-6,42,4,CONCRETE:15)
Block(-6,42,5,CONCRETE:15)
Block(-6,42,6,CONCRETE:15)
Block(-6,42,7,STAINED_GLASS:15)
Block(-6,42,8,CONCRETE:8)
Block(-6,43,-5,CONCRETE:15)
Block(-6,43,-4,CONCRETE:15)
Block(-6,43,-3,CONCRETE:15)
Block(-6,43,-2,CONCRETE:15)
Block(-6,43,-1,CONCRETE:15)
Block(-6,43,2,CONCRETE:15)
Block(-6,43,3,CONCRETE:15)
Block(-6,43,4,CONCRETE:15)
Block(-6,43,5,CONCRETE:15)
Block(-6,43,6,CONCRETE:15)
Block(-6,44,-5,CONCRETE:15)
Block(-6,44,-4,CONCRETE:15)
Block(-6,44,-3,CONCRETE:15)
Block(-6,44,-2,CONCRETE:15)
Block(-6,44,-1,CONCRETE:15)
Block(-6,44,2,CONCRETE:15)
Block(-6,44,3,CONCRETE:15)
Block(-6,44,4,CONCRETE:15)
Block(-6,44,5,CONCRETE:15)
Block(-6,44,6,CONCRETE:15)
Block(-6,45,-5,CONCRETE:15)
Block(-6,45,-4,CONCRETE:15)
Block(-6,45,-3,CONCRETE:15)
Block(-6,45,-2,CONCRETE:15)
Block(-6,45,-1,CONCRETE:15)
Block(-6,45,2,CONCRETE:15)
Block(-6,45,3,CONCRETE:15)
Block(-6,45,4,CONCRETE:15)
Block(-6,45,5,CONCRETE:15)
Block(-6,45,6,CONCRETE:15)
Block(-6,46,-5,CONCRETE:15)
Block(-6,46,-4,CONCRETE:15)
Block(-6,46,-3,CONCRETE:15)
Block(-6,46,-2,CONCRETE:15)
Block(-6,46,-1,CONCRETE:15)
Block(-6,46,2,CONCRETE:15)
Block(-6,46,3,CONCRETE:15)
Block(-6,46,4,CONCRETE:15)
Block(-6,46,5,CONCRETE:15)
Block(-6,46,6,CONCRETE:15)
Block(-6,47,-5,CONCRETE:15)
Block(-6,47,-4,CONCRETE:15)
Block(-6,47,-3,CONCRETE:15)
Block(-6,47,-2,CONCRETE:15)
Block(-6,47,-1,CONCRETE:15)
Block(-6,47,0,STAINED_GLASS:15)
Block(-6,47,1,STAINED_GLASS:15)
Block(-6,47,2,CONCRETE:15)
Block(-6,47,3,CONCRETE:15)
Block(-6,47,4,CONCRETE:15)
Block(-6,47,5,CONCRETE:15)
Block(-6,47,6,CONCRETE:15)
Block(-6,48,-7,CONCRETE:8)
Block(-6,48,-6,STAINED_GLASS:15)
Block(-6,48,-5,CONCRETE:15)
Block(-6,48,-4,CONCRETE:15)
Block(-6,48,-3,CONCRETE:15)
Block(-6,48,-2,CONCRETE:15)
Block(-6,48,-1,CONCRETE:15)
Block(-6,48,0,QUARTZ_STAIRS:1)
Block(-6,48,1,QUARTZ_STAIRS:1)
Block(-6,48,2,CONCRETE:15)
Block(-6,48,3,CONCRETE:15)
Block(-6,48,4,CONCRETE:15)
Block(-6,48,5,CONCRETE:15)
Block(-6,48,6,CONCRETE:15)
Block(-6,48,7,STAINED_GLASS:15)
Block(-6,48,8,CONCRETE:8)
Block(-6,49,-5,CONCRETE:15)
Block(-6,49,-4,CONCRETE:15)
Block(-6,49,-3,CONCRETE:15)
Block(-6,49,-2,CONCRETE:15)
Block(-6,49,-1,CONCRETE:15)
Block(-6,49,2,CONCRETE:15)
Block(-6,49,3,CONCRETE:15)
Block(-6,49,4,CONCRETE:15)
Block(-6,49,5,CONCRETE:15)
Block(-6,49,6,CONCRETE:15)
Block(-6,50,-5,CONCRETE:15)
Block(-6,50,-4,CONCRETE:15)
Block(-6,50,-3,CONCRETE:15)
Block(-6,50,-2,CONCRETE:15)
Block(-6,50,-1,CONCRETE:15)
Block(-6,50,2,CONCRETE:15)
Block(-6,50,3,CONCRETE:15)
Block(-6,50,4,CONCRETE:15)
Block(-6,50,5,CONCRETE:15)
Block(-6,50,6,CONCRETE:15)
Block(-6,51,-5,CONCRETE:15)
Block(-6,51,-4,CONCRETE:15)
Block(-6,51,-3,CONCRETE:15)
Block(-6,51,-2,CONCRETE:15)
Block(-6,51,-1,CONCRETE:15)
Block(-6,51,2,CONCRETE:15)
Block(-6,51,3,CONCRETE:15)
Block(-6,51,4,CONCRETE:15)
Block(-6,51,5,CONCRETE:15)
Block(-6,51,6,CONCRETE:15)
Block(-6,52,-5,CONCRETE:15)
Block(-6,52,-4,CONCRETE:15)
Block(-6,52,-3,CONCRETE:15)
Block(-6,52,-2,CONCRETE:15)
Block(-6,52,-1,CONCRETE:15)
Block(-6,52,2,CONCRETE:15)
Block(-6,52,3,CONCRETE:15)
Block(-6,52,4,CONCRETE:15)
Block(-6,52,5,CONCRETE:15)
Block(-6,52,6,CONCRETE:15)
Block(-6,53,-5,CONCRETE:15)
Block(-6,53,-4,CONCRETE:15)
Block(-6,53,-3,CONCRETE:15)
Block(-6,53,-2,CONCRETE:15)
Block(-6,53,-1,CONCRETE:15)
Block(-6,53,0,STAINED_GLASS:15)
Block(-6,53,1,STAINED_GLASS:15)
Block(-6,53,2,CONCRETE:15)
Block(-6,53,3,CONCRETE:15)
Block(-6,53,4,CONCRETE:15)
Block(-6,53,5,CONCRETE:15)
Block(-6,53,6,CONCRETE:15)
Block(-6,54,-7,CONCRETE:8)
Block(-6,54,-6,STAINED_GLASS:15)
Block(-6,54,-5,CONCRETE:15)
Block(-6,54,-4,CONCRETE:15)
Block(-6,54,-3,CONCRETE:15)
Block(-6,54,-2,CONCRETE:15)
Block(-6,54,-1,CONCRETE:15)
Block(-6,54,0,QUARTZ_STAIRS:1)
Block(-6,54,1,QUARTZ_STAIRS:1)
Block(-6,54,2,CONCRETE:15)
Block(-6,54,3,CONCRETE:15)
Block(-6,54,4,CONCRETE:15)
Block(-6,54,5,CONCRETE:15)
Block(-6,54,6,CONCRETE:15)
Block(-6,54,7,STAINED_GLASS:15)
Block(-6,54,8,CONCRETE:8)
Block(-6,55,-5,CONCRETE:15)
Block(-6,55,-4,CONCRETE:15)
Block(-6,55,-3,CONCRETE:15)
Block(-6,55,-2,CONCRETE:15)
Block(-6,55,-1,CONCRETE:15)
Block(-6,55,2,CONCRETE:15)
Block(-6,55,3,CONCRETE:15)
Block(-6,55,4,CONCRETE:15)
Block(-6,55,5,CONCRETE:15)
Block(-6,55,6,CONCRETE:15)
Block(-6,56,-5,CONCRETE:15)
Block(-6,56,-4,CONCRETE:15)
Block(-6,56,-3,CONCRETE:15)
Block(-6,56,-2,CONCRETE:15)
Block(-6,56,-1,CONCRETE:15)
Block(-6,56,2,CONCRETE:15)
Block(-6,56,3,CONCRETE:15)
Block(-6,56,4,CONCRETE:15)
Block(-6,56,5,CONCRETE:15)
Block(-6,56,6,CONCRETE:15)
Block(-6,57,-5,CONCRETE:15)
Block(-6,57,-4,CONCRETE:15)
Block(-6,57,-3,CONCRETE:15)
Block(-6,57,-2,CONCRETE:15)
Block(-6,57,-1,CONCRETE:15)
Block(-6,57,2,CONCRETE:15)
Block(-6,57,3,CONCRETE:15)
Block(-6,57,4,CONCRETE:15)
Block(-6,57,5,CONCRETE:15)
Block(-6,57,6,CONCRETE:15)
Block(-6,58,-5,CONCRETE:15)
Block(-6,58,-4,CONCRETE:15)
Block(-6,58,-3,CONCRETE:15)
Block(-6,58,-2,CONCRETE:15)
Block(-6,58,-1,CONCRETE:15)
Block(-6,58,2,CONCRETE:15)
Block(-6,58,3,CONCRETE:15)
Block(-6,58,4,CONCRETE:15)
Block(-6,58,5,CONCRETE:15)
Block(-6,58,6,CONCRETE:15)
Block(-6,59,-5,CONCRETE:15)
Block(-6,59,-4,CONCRETE:15)
Block(-6,59,-3,CONCRETE:15)
Block(-6,59,-2,CONCRETE:15)
Block(-6,59,-1,CONCRETE:15)
Block(-6,59,0,STAINED_GLASS:15)
Block(-6,59,1,STAINED_GLASS:15)
Block(-6,59,2,CONCRETE:15)
Block(-6,59,3,CONCRETE:15)
Block(-6,59,4,CONCRETE:15)
Block(-6,59,5,CONCRETE:15)
Block(-6,59,6,CONCRETE:15)
Block(-6,60,-7,CONCRETE:8)
Block(-6,60,-6,STAINED_GLASS:15)
Block(-6,60,-5,CONCRETE:15)
Block(-6,60,-4,CONCRETE:15)
Block(-6,60,-3,CONCRETE:15)
Block(-6,60,-2,CONCRETE:15)
Block(-6,60,-1,CONCRETE:15)
Block(-6,60,0,QUARTZ_STAIRS:1)
Block(-6,60,1,QUARTZ_STAIRS:1)
Block(-6,60,2,CONCRETE:15)
Block(-6,60,3,CONCRETE:15)
Block(-6,60,4,CONCRETE:15)
Block(-6,60,5,CONCRETE:15)
Block(-6,60,6,CONCRETE:15)
Block(-6,60,7,STAINED_GLASS:15)
Block(-6,60,8,CONCRETE:8)
Block(-6,61,-5,CONCRETE:15)
Block(-6,61,-4,CONCRETE:15)
Block(-6,61,-3,CONCRETE:15)
Block(-6,61,-2,CONCRETE:15)
Block(-6,61,-1,CONCRETE:15)
Block(-6,61,2,CONCRETE:15)
Block(-6,61,3,CONCRETE:15)
Block(-6,61,4,CONCRETE:15)
Block(-6,61,5,CONCRETE:15)
Block(-6,61,6,CONCRETE:15)
Block(-6,62,-5,CONCRETE:15)
Block(-6,62,-4,CONCRETE:15)
Block(-6,62,-3,CONCRETE:15)
Block(-6,62,-2,CONCRETE:15)
Block(-6,62,-1,CONCRETE:15)
Block(-6,62,2,CONCRETE:15)
Block(-6,62,3,CONCRETE:15)
Block(-6,62,4,CONCRETE:15)
Block(-6,62,5,CONCRETE:15)
Block(-6,62,6,CONCRETE:15)
Block(-6,63,-5,CONCRETE:15)
Block(-6,63,-4,CONCRETE:15)
Block(-6,63,-3,CONCRETE:15)
Block(-6,63,-2,CONCRETE:15)
Block(-6,63,-1,CONCRETE:15)
Block(-6,63,2,CONCRETE:15)
Block(-6,63,3,CONCRETE:15)
Block(-6,63,4,CONCRETE:15)
Block(-6,63,5,CONCRETE:15)
Block(-6,63,6,CONCRETE:15)
Block(-6,64,-5,CONCRETE:15)
Block(-6,64,-4,CONCRETE:15)
Block(-6,64,-3,CONCRETE:15)
Block(-6,64,-2,CONCRETE:15)
Block(-6,64,-1,CONCRETE:15)
Block(-6,64,2,CONCRETE:15)
Block(-6,64,3,CONCRETE:15)
Block(-6,64,4,CONCRETE:15)
Block(-6,64,5,CONCRETE:15)
Block(-6,64,6,CONCRETE:15)
Block(-6,65,-5,CONCRETE:15)
Block(-6,65,-4,CONCRETE:15)
Block(-6,65,-3,CONCRETE:15)
Block(-6,65,-2,CONCRETE:15)
Block(-6,65,-1,CONCRETE:15)
Block(-6,65,0,STAINED_GLASS:15)
Block(-6,65,1,STAINED_GLASS:15)
Block(-6,65,2,CONCRETE:15)
Block(-6,65,3,CONCRETE:15)
Block(-6,65,4,CONCRETE:15)
Block(-6,65,5,CONCRETE:15)
Block(-6,65,6,CONCRETE:15)
Block(-6,66,-7,CONCRETE:8)
Block(-6,66,-6,STAINED_GLASS:15)
Block(-6,66,-5,CONCRETE:15)
Block(-6,66,-4,CONCRETE:15)
Block(-6,66,-3,CONCRETE:15)
Block(-6,66,-2,CONCRETE:15)
Block(-6,66,-1,CONCRETE:15)
Block(-6,66,0,QUARTZ_STAIRS:1)
Block(-6,66,1,QUARTZ_STAIRS:1)
Block(-6,66,2,CONCRETE:15)
Block(-6,66,3,CONCRETE:15)
Block(-6,66,4,CONCRETE:15)
Block(-6,66,5,CONCRETE:15)
Block(-6,66,6,CONCRETE:15)
Block(-6,66,7,STAINED_GLASS:15)
Block(-6,66,8,CONCRETE:8)
Block(-6,67,-5,CONCRETE:15)
Block(-6,67,-4,CONCRETE:15)
Block(-6,67,-3,CONCRETE:15)
Block(-6,67,-2,CONCRETE:15)
Block(-6,67,-1,CONCRETE:15)
Block(-6,67,2,CONCRETE:15)
Block(-6,67,3,CONCRETE:15)
Block(-6,67,4,CONCRETE:15)
Block(-6,67,5,CONCRETE:15)
Block(-6,67,6,CONCRETE:15)
Block(-6,68,-5,CONCRETE:15)
Block(-6,68,-4,CONCRETE:15)
Block(-6,68,-3,CONCRETE:15)
Block(-6,68,-2,CONCRETE:15)
Block(-6,68,-1,CONCRETE:15)
Block(-6,68,2,CONCRETE:15)
Block(-6,68,3,CONCRETE:15)
Block(-6,68,4,CONCRETE:15)
Block(-6,68,5,CONCRETE:15)
Block(-6,68,6,CONCRETE:15)
Block(-6,69,-5,CONCRETE:15)
Block(-6,69,-4,CONCRETE:15)
Block(-6,69,-3,CONCRETE:15)
Block(-6,69,-2,CONCRETE:15)
Block(-6,69,-1,CONCRETE:15)
Block(-6,69,2,CONCRETE:15)
Block(-6,69,3,CONCRETE:15)
Block(-6,69,4,CONCRETE:15)
Block(-6,69,5,CONCRETE:15)
Block(-6,69,6,CONCRETE:15)
Block(-6,70,-5,CONCRETE:15)
Block(-6,70,-4,CONCRETE:15)
Block(-6,70,-3,CONCRETE:15)
Block(-6,70,-2,CONCRETE:15)
Block(-6,70,-1,CONCRETE:15)
Block(-6,70,2,CONCRETE:15)
Block(-6,70,3,CONCRETE:15)
Block(-6,70,4,CONCRETE:15)
Block(-6,70,5,CONCRETE:15)
Block(-6,70,6,CONCRETE:15)
Block(-6,71,-5,CONCRETE:15)
Block(-6,71,-4,CONCRETE:15)
Block(-6,71,-3,CONCRETE:15)
Block(-6,71,-2,CONCRETE:15)
Block(-6,71,-1,CONCRETE:15)
Block(-6,71,0,STAINED_GLASS:15)
Block(-6,71,1,STAINED_GLASS:15)
Block(-6,71,2,CONCRETE:15)
Block(-6,71,3,CONCRETE:15)
Block(-6,71,4,CONCRETE:15)
Block(-6,71,5,CONCRETE:15)
Block(-6,71,6,CONCRETE:15)
Block(-6,72,-7,CONCRETE:8)
Block(-6,72,-6,STAINED_GLASS:15)
Block(-6,72,-5,CONCRETE:15)
Block(-6,72,-4,CONCRETE:15)
Block(-6,72,-3,CONCRETE:15)
Block(-6,72,-2,CONCRETE:15)
Block(-6,72,-1,CONCRETE:15)
Block(-6,72,0,QUARTZ_STAIRS:1)
Block(-6,72,1,QUARTZ_STAIRS:1)
Block(-6,72,2,CONCRETE:15)
Block(-6,72,3,CONCRETE:15)
Block(-6,72,4,CONCRETE:15)
Block(-6,72,5,CONCRETE:15)
Block(-6,72,6,CONCRETE:15)
Block(-6,72,7,STAINED_GLASS:15)
Block(-6,72,8,CONCRETE:8)
Block(-6,73,-5,CONCRETE:15)
Block(-6,73,-4,CONCRETE:15)
Block(-6,73,-3,CONCRETE:15)
Block(-6,73,-2,CONCRETE:15)
Block(-6,73,-1,CONCRETE:15)
Block(-6,73,2,CONCRETE:15)
Block(-6,73,3,CONCRETE:15)
Block(-6,73,4,CONCRETE:15)
Block(-6,73,5,CONCRETE:15)
Block(-6,73,6,CONCRETE:15)
Block(-6,74,-5,CONCRETE:15)
Block(-6,74,-4,CONCRETE:15)
Block(-6,74,-3,CONCRETE:15)
Block(-6,74,-2,CONCRETE:15)
Block(-6,74,-1,CONCRETE:15)
Block(-6,74,2,CONCRETE:15)
Block(-6,74,3,CONCRETE:15)
Block(-6,74,4,CONCRETE:15)
Block(-6,74,5,CONCRETE:15)
Block(-6,74,6,CONCRETE:15)
Block(-6,75,-5,CONCRETE:15)
Block(-6,75,-4,CONCRETE:15)
Block(-6,75,-3,CONCRETE:15)
Block(-6,75,-2,CONCRETE:15)
Block(-6,75,-1,CONCRETE:15)
Block(-6,75,2,CONCRETE:15)
Block(-6,75,3,CONCRETE:15)
Block(-6,75,4,CONCRETE:15)
Block(-6,75,5,CONCRETE:15)
Block(-6,75,6,CONCRETE:15)
Block(-6,76,-5,CONCRETE:15)
Block(-6,76,-4,CONCRETE:15)
Block(-6,76,-3,CONCRETE:15)
Block(-6,76,-2,CONCRETE:15)
Block(-6,76,-1,CONCRETE:15)
Block(-6,76,2,CONCRETE:15)
Block(-6,76,3,CONCRETE:15)
Block(-6,76,4,CONCRETE:15)
Block(-6,76,5,CONCRETE:15)
Block(-6,76,6,CONCRETE:15)
Block(-6,77,-5,CONCRETE:15)
Block(-6,77,-4,CONCRETE:15)
Block(-6,77,-3,CONCRETE:15)
Block(-6,77,-2,CONCRETE:15)
Block(-6,77,-1,CONCRETE:15)
Block(-6,77,0,STAINED_GLASS:15)
Block(-6,77,1,STAINED_GLASS:15)
Block(-6,77,2,CONCRETE:15)
Block(-6,77,3,CONCRETE:15)
Block(-6,77,4,CONCRETE:15)
Block(-6,77,5,CONCRETE:15)
Block(-6,77,6,CONCRETE:15)
Block(-6,78,-7,CONCRETE:15)
Block(-6,78,-6,STAINED_GLASS:15)
Block(-6,78,-5,CONCRETE:15)
Block(-6,78,-4,CONCRETE:15)
Block(-6,78,-3,CONCRETE:15)
Block(-6,78,-2,CONCRETE:15)
Block(-6,78,-1,CONCRETE:15)
Block(-6,78,0,QUARTZ_STAIRS:1)
Block(-6,78,1,QUARTZ_STAIRS:1)
Block(-6,78,2,CONCRETE:15)
Block(-6,78,3,CONCRETE:15)
Block(-6,78,4,CONCRETE:15)
Block(-6,78,5,CONCRETE:15)
Block(-6,78,6,CONCRETE:15)
Block(-6,78,7,STAINED_GLASS:15)
Block(-6,78,8,CONCRETE:15)
Block(-6,79,-5,CONCRETE:15)
Block(-6,79,-4,CONCRETE:15)
Block(-6,79,-3,CONCRETE:15)
Block(-6,79,-2,CONCRETE:15)
Block(-6,79,-1,CONCRETE:15)
Block(-6,79,2,CONCRETE:15)
Block(-6,79,3,CONCRETE:15)
Block(-6,79,4,CONCRETE:15)
Block(-6,79,5,CONCRETE:15)
Block(-6,79,6,CONCRETE:15)
Block(-6,80,-5,CONCRETE:15)
Block(-6,80,-4,CONCRETE:15)
Block(-6,80,-3,CONCRETE:15)
Block(-6,80,-2,CONCRETE:15)
Block(-6,80,-1,CONCRETE:15)
Block(-6,80,2,CONCRETE:15)
Block(-6,80,3,CONCRETE:15)
Block(-6,80,4,CONCRETE:15)
Block(-6,80,5,CONCRETE:15)
Block(-6,80,6,CONCRETE:15)
Block(-6,81,-5,CONCRETE:15)
Block(-6,81,-4,CONCRETE:15)
Block(-6,81,-3,CONCRETE:15)
Block(-6,81,-2,CONCRETE:15)
Block(-6,81,-1,CONCRETE:15)
Block(-6,81,2,CONCRETE:15)
Block(-6,81,3,CONCRETE:15)
Block(-6,81,4,CONCRETE:15)
Block(-6,81,5,CONCRETE:15)
Block(-6,81,6,CONCRETE:15)
Block(-6,82,-5,CONCRETE:15)
Block(-6,82,-4,CONCRETE:15)
Block(-6,82,-3,CONCRETE:15)
Block(-6,82,-2,CONCRETE:15)
Block(-6,82,-1,CONCRETE:15)
Block(-6,82,2,CONCRETE:15)
Block(-6,82,3,CONCRETE:15)
Block(-6,82,4,CONCRETE:15)
Block(-6,82,5,CONCRETE:15)
Block(-6,82,6,CONCRETE:15)
Block(-6,83,-5,CONCRETE:15)
Block(-6,83,-4,CONCRETE:15)
Block(-6,83,-3,CONCRETE:15)
Block(-6,83,-2,CONCRETE:15)
Block(-6,83,-1,CONCRETE:15)
Block(-6,83,0,STAINED_GLASS:15)
Block(-6,83,1,STAINED_GLASS:15)
Block(-6,83,2,CONCRETE:15)
Block(-6,83,3,CONCRETE:15)
Block(-6,83,4,CONCRETE:15)
Block(-6,83,5,CONCRETE:15)
Block(-6,83,6,CONCRETE:15)
Block(-6,84,-7,CONCRETE:8)
Block(-6,84,-6,STAINED_GLASS:15)
Block(-6,84,-5,CONCRETE:15)
Block(-6,84,-4,CONCRETE:15)
Block(-6,84,-3,CONCRETE:15)
Block(-6,84,-2,CONCRETE:15)
Block(-6,84,-1,CONCRETE:15)
Block(-6,84,0,QUARTZ_STAIRS:1)
Block(-6,84,1,QUARTZ_STAIRS:1)
Block(-6,84,2,CONCRETE:15)
Block(-6,84,3,CONCRETE:15)
Block(-6,84,4,CONCRETE:15)
Block(-6,84,5,CONCRETE:15)
Block(-6,84,6,CONCRETE:15)
Block(-6,84,7,STAINED_GLASS:15)
Block(-6,84,8,CONCRETE:8)
Block(-6,85,-5,CONCRETE:15)
Block(-6,85,-4,CONCRETE:15)
Block(-6,85,-3,CONCRETE:15)
Block(-6,85,-2,CONCRETE:15)
Block(-6,85,-1,CONCRETE:15)
Block(-6,85,2,CONCRETE:15)
Block(-6,85,3,CONCRETE:15)
Block(-6,85,4,CONCRETE:15)
Block(-6,85,5,CONCRETE:15)
Block(-6,85,6,CONCRETE:15)
Block(-6,86,-5,CONCRETE:15)
Block(-6,86,-4,CONCRETE:15)
Block(-6,86,-3,CONCRETE:15)
Block(-6,86,-2,CONCRETE:15)
Block(-6,86,-1,CONCRETE:15)
Block(-6,86,2,CONCRETE:15)
Block(-6,86,3,CONCRETE:15)
Block(-6,86,4,CONCRETE:15)
Block(-6,86,5,CONCRETE:15)
Block(-6,86,6,CONCRETE:15)
Block(-6,87,-5,CONCRETE:15)
Block(-6,87,-4,CONCRETE:15)
Block(-6,87,-3,CONCRETE:15)
Block(-6,87,-2,CONCRETE:15)
Block(-6,87,-1,CONCRETE:15)
Block(-6,87,2,CONCRETE:15)
Block(-6,87,3,CONCRETE:15)
Block(-6,87,4,CONCRETE:15)
Block(-6,87,5,CONCRETE:15)
Block(-6,87,6,CONCRETE:15)
Block(-6,88,-5,CONCRETE:15)
Block(-6,88,-4,CONCRETE:15)
Block(-6,88,-3,CONCRETE:15)
Block(-6,88,-2,CONCRETE:15)
Block(-6,88,-1,CONCRETE:15)
Block(-6,88,2,CONCRETE:15)
Block(-6,88,3,CONCRETE:15)
Block(-6,88,4,CONCRETE:15)
Block(-6,88,5,CONCRETE:15)
Block(-6,88,6,CONCRETE:15)
Block(-6,89,-5,CONCRETE:15)
Block(-6,89,-4,CONCRETE:15)
Block(-6,89,-3,CONCRETE:15)
Block(-6,89,-2,CONCRETE:15)
Block(-6,89,-1,CONCRETE:15)
Block(-6,89,0,STAINED_GLASS:15)
Block(-6,89,1,STAINED_GLASS:15)
Block(-6,89,2,CONCRETE:15)
Block(-6,89,3,CONCRETE:15)
Block(-6,89,4,CONCRETE:15)
Block(-6,89,5,CONCRETE:15)
Block(-6,89,6,CONCRETE:15)
Block(-6,90,-7,CONCRETE:8)
Block(-6,90,-6,STAINED_GLASS:15)
Block(-6,90,-5,CONCRETE:15)
Block(-6,90,-4,CONCRETE:15)
Block(-6,90,-3,CONCRETE:15)
Block(-6,90,-2,CONCRETE:15)
Block(-6,90,-1,CONCRETE:15)
Block(-6,90,0,QUARTZ_STAIRS:1)
Block(-6,90,1,QUARTZ_STAIRS:1)
Block(-6,90,2,CONCRETE:15)
Block(-6,90,3,CONCRETE:15)
Block(-6,90,4,CONCRETE:15)
Block(-6,90,5,CONCRETE:15)
Block(-6,90,6,CONCRETE:15)
Block(-6,90,7,STAINED_GLASS:15)
Block(-6,90,8,CONCRETE:8)
Block(-6,91,-5,CONCRETE:15)
Block(-6,91,-4,CONCRETE:15)
Block(-6,91,-3,CONCRETE:15)
Block(-6,91,-2,CONCRETE:15)
Block(-6,91,-1,CONCRETE:15)
Block(-6,91,2,CONCRETE:15)
Block(-6,91,3,CONCRETE:15)
Block(-6,91,4,CONCRETE:15)
Block(-6,91,5,CONCRETE:15)
Block(-6,91,6,CONCRETE:15)
Block(-6,92,-5,CONCRETE:15)
Block(-6,92,-4,CONCRETE:15)
Block(-6,92,-3,CONCRETE:15)
Block(-6,92,-2,CONCRETE:15)
Block(-6,92,-1,CONCRETE:15)
Block(-6,92,2,CONCRETE:15)
Block(-6,92,3,CONCRETE:15)
Block(-6,92,4,CONCRETE:15)
Block(-6,92,5,CONCRETE:15)
Block(-6,92,6,CONCRETE:15)
Block(-6,93,-5,CONCRETE:15)
Block(-6,93,-4,CONCRETE:15)
Block(-6,93,-3,CONCRETE:15)
Block(-6,93,-2,CONCRETE:15)
Block(-6,93,-1,CONCRETE:15)
Block(-6,93,2,CONCRETE:15)
Block(-6,93,3,CONCRETE:15)
Block(-6,93,4,CONCRETE:15)
Block(-6,93,5,CONCRETE:15)
Block(-6,93,6,CONCRETE:15)
Block(-6,94,-5,CONCRETE:15)
Block(-6,94,-4,CONCRETE:15)
Block(-6,94,-3,CONCRETE:15)
Block(-6,94,-2,CONCRETE:15)
Block(-6,94,-1,CONCRETE:15)
Block(-6,94,2,CONCRETE:15)
Block(-6,94,3,CONCRETE:15)
Block(-6,94,4,CONCRETE:15)
Block(-6,94,5,CONCRETE:15)
Block(-6,94,6,CONCRETE:15)
Block(-6,95,-5,CONCRETE:15)
Block(-6,95,-4,CONCRETE:15)
Block(-6,95,-3,CONCRETE:15)
Block(-6,95,-2,CONCRETE:15)
Block(-6,95,-1,CONCRETE:15)
Block(-6,95,0,STAINED_GLASS:15)
Block(-6,95,1,STAINED_GLASS:15)
Block(-6,95,2,CONCRETE:15)
Block(-6,95,3,CONCRETE:15)
Block(-6,95,4,CONCRETE:15)
Block(-6,95,5,CONCRETE:15)
Block(-6,95,6,CONCRETE:15)
Block(-6,96,-7,CONCRETE:15)
Block(-6,96,-6,STAINED_GLASS:15)
Block(-6,96,-5,CONCRETE:15)
Block(-6,96,-4,CONCRETE:15)
Block(-6,96,-3,CONCRETE:15)
Block(-6,96,-2,CONCRETE:15)
Block(-6,96,-1,CONCRETE:15)
Block(-6,96,0,QUARTZ_STAIRS:1)
Block(-6,96,1,QUARTZ_STAIRS:1)
Block(-6,96,2,CONCRETE:15)
Block(-6,96,3,CONCRETE:15)
Block(-6,96,4,CONCRETE:15)
Block(-6,96,5,CONCRETE:15)
Block(-6,96,6,CONCRETE:15)
Block(-6,96,7,STAINED_GLASS:15)
Block(-6,96,8,CONCRETE:8)
Block(-6,97,-5,CONCRETE:15)
Block(-6,97,-4,CONCRETE:15)
Block(-6,97,-3,CONCRETE:15)
Block(-6,97,-2,CONCRETE:15)
Block(-6,97,-1,CONCRETE:15)
Block(-6,97,2,CONCRETE:15)
Block(-6,97,3,CONCRETE:15)
Block(-6,97,4,CONCRETE:15)
Block(-6,97,5,CONCRETE:15)
Block(-6,97,6,CONCRETE:15)
Block(-6,98,-5,CONCRETE:15)
Block(-6,98,-4,CONCRETE:15)
Block(-6,98,-3,CONCRETE:15)
Block(-6,98,-2,CONCRETE:15)
Block(-6,98,-1,CONCRETE:15)
Block(-6,98,2,CONCRETE:15)
Block(-6,98,3,CONCRETE:15)
Block(-6,98,4,CONCRETE:15)
Block(-6,98,5,CONCRETE:15)
Block(-6,98,6,CONCRETE:15)
Block(-6,99,-5,CONCRETE:15)
Block(-6,99,-4,CONCRETE:15)
Block(-6,99,-3,CONCRETE:15)
Block(-6,99,-2,CONCRETE:15)
Block(-6,99,-1,CONCRETE:15)
Block(-6,99,2,CONCRETE:15)
Block(-6,99,3,CONCRETE:15)
Block(-6,99,4,CONCRETE:15)
Block(-6,99,5,CONCRETE:15)
Block(-6,99,6,CONCRETE:15)
Block(-6,100,-5,CONCRETE:15)
Block(-6,100,-4,CONCRETE:15)
Block(-6,100,-3,CONCRETE:15)
Block(-6,100,-2,CONCRETE:15)
Block(-6,100,-1,CONCRETE:15)
Block(-6,100,2,CONCRETE:15)
Block(-6,100,3,CONCRETE:15)
Block(-6,100,4,CONCRETE:15)
Block(-6,100,5,CONCRETE:15)
Block(-6,100,6,CONCRETE:15)
Block(-6,101,-5,CONCRETE:15)
Block(-6,101,-4,CONCRETE:15)
Block(-6,101,-3,CONCRETE:15)
Block(-6,101,-2,CONCRETE:15)
Block(-6,101,-1,CONCRETE:15)
Block(-6,101,0,STAINED_GLASS:15)
Block(-6,101,1,STAINED_GLASS:15)
Block(-6,101,2,CONCRETE:15)
Block(-6,101,3,CONCRETE:15)
Block(-6,101,4,CONCRETE:15)
Block(-6,101,5,CONCRETE:15)
Block(-6,101,6,CONCRETE:15)
Block(-6,102,-7,CONCRETE:8)
Block(-6,102,-6,STAINED_GLASS:15)
Block(-6,102,-5,CONCRETE:15)
Block(-6,102,-4,CONCRETE:15)
Block(-6,102,-3,CONCRETE:15)
Block(-6,102,-2,CONCRETE:15)
Block(-6,102,-1,CONCRETE:15)
Block(-6,102,0,QUARTZ_STAIRS:1)
Block(-6,102,1,QUARTZ_STAIRS:1)
Block(-6,102,2,CONCRETE:15)
Block(-6,102,3,CONCRETE:15)
Block(-6,102,4,CONCRETE:15)
Block(-6,102,5,CONCRETE:15)
Block(-6,102,6,CONCRETE:15)
Block(-6,102,7,STAINED_GLASS:15)
Block(-6,102,8,CONCRETE:8)
Block(-6,103,-5,CONCRETE:15)
Block(-6,103,-4,CONCRETE:15)
Block(-6,103,-3,CONCRETE:15)
Block(-6,103,-2,CONCRETE:15)
Block(-6,103,-1,CONCRETE:15)
Block(-6,103,2,CONCRETE:15)
Block(-6,103,3,CONCRETE:15)
Block(-6,103,4,CONCRETE:15)
Block(-6,103,5,CONCRETE:15)
Block(-6,103,6,CONCRETE:15)
Block(-6,104,-5,CONCRETE:15)
Block(-6,104,-4,CONCRETE:15)
Block(-6,104,-3,CONCRETE:15)
Block(-6,104,-2,CONCRETE:15)
Block(-6,104,-1,CONCRETE:15)
Block(-6,104,2,CONCRETE:15)
Block(-6,104,3,CONCRETE:15)
Block(-6,104,4,CONCRETE:15)
Block(-6,104,5,CONCRETE:15)
Block(-6,104,6,CONCRETE:15)
Block(-6,105,-5,CONCRETE:15)
Block(-6,105,-4,CONCRETE:15)
Block(-6,105,-3,CONCRETE:15)
Block(-6,105,-2,CONCRETE:15)
Block(-6,105,-1,CONCRETE:15)
Block(-6,105,2,CONCRETE:15)
Block(-6,105,3,CONCRETE:15)
Block(-6,105,4,CONCRETE:15)
Block(-6,105,5,CONCRETE:15)
Block(-6,105,6,CONCRETE:15)
Block(-6,106,-5,CONCRETE:15)
Block(-6,106,-4,CONCRETE:15)
Block(-6,106,-3,CONCRETE:15)
Block(-6,106,-2,CONCRETE:15)
Block(-6,106,-1,CONCRETE:15)
Block(-6,106,2,CONCRETE:15)
Block(-6,106,3,CONCRETE:15)
Block(-6,106,4,CONCRETE:15)
Block(-6,106,5,CONCRETE:15)
Block(-6,106,6,CONCRETE:15)
Block(-6,107,-5,CONCRETE:15)
Block(-6,107,-4,CONCRETE:15)
Block(-6,107,-3,CONCRETE:15)
Block(-6,107,-2,CONCRETE:15)
Block(-6,107,-1,CONCRETE:15)
Block(-6,107,0,STAINED_GLASS:15)
Block(-6,107,1,STAINED_GLASS:15)
Block(-6,107,2,CONCRETE:15)
Block(-6,107,3,CONCRETE:15)
Block(-6,107,4,CONCRETE:15)
Block(-6,107,5,CONCRETE:15)
Block(-6,107,6,CONCRETE:15)
Block(-6,108,-7,CONCRETE:8)
Block(-6,108,-6,STAINED_GLASS:15)
Block(-6,108,-5,CONCRETE:15)
Block(-6,108,-4,CONCRETE:15)
Block(-6,108,-3,CONCRETE:15)
Block(-6,108,-2,CONCRETE:15)
Block(-6,108,-1,CONCRETE:15)
Block(-6,108,0,QUARTZ_STAIRS:1)
Block(-6,108,1,QUARTZ_STAIRS:1)
Block(-6,108,2,CONCRETE:15)
Block(-6,108,3,CONCRETE:15)
Block(-6,108,4,CONCRETE:15)
Block(-6,108,5,CONCRETE:15)
Block(-6,108,6,CONCRETE:15)
Block(-6,108,7,STAINED_GLASS:15)
Block(-6,108,8,CONCRETE:8)
Block(-6,109,-5,CONCRETE:15)
Block(-6,109,-4,CONCRETE:15)
Block(-6,109,-3,CONCRETE:15)
Block(-6,109,-2,CONCRETE:15)
Block(-6,109,-1,CONCRETE:15)
Block(-6,109,2,CONCRETE:15)
Block(-6,109,3,CONCRETE:15)
Block(-6,109,4,CONCRETE:15)
Block(-6,109,5,CONCRETE:15)
Block(-6,109,6,CONCRETE:15)
Block(-6,110,-5,CONCRETE:15)
Block(-6,110,-4,CONCRETE:15)
Block(-6,110,-3,CONCRETE:15)
Block(-6,110,-2,CONCRETE:15)
Block(-6,110,-1,CONCRETE:15)
Block(-6,110,2,CONCRETE:15)
Block(-6,110,3,CONCRETE:15)
Block(-6,110,4,CONCRETE:15)
Block(-6,110,5,CONCRETE:15)
Block(-6,110,6,CONCRETE:15)
Block(-6,111,-5,CONCRETE:15)
Block(-6,111,-4,CONCRETE:15)
Block(-6,111,-3,CONCRETE:15)
Block(-6,111,-2,CONCRETE:15)
Block(-6,111,-1,CONCRETE:15)
Block(-6,111,2,CONCRETE:15)
Block(-6,111,3,CONCRETE:15)
Block(-6,111,4,CONCRETE:15)
Block(-6,111,5,CONCRETE:15)
Block(-6,111,6,CONCRETE:15)
Block(-6,112,-5,CONCRETE:15)
Block(-6,112,-4,CONCRETE:15)
Block(-6,112,-3,CONCRETE:15)
Block(-6,112,-2,CONCRETE:15)
Block(-6,112,-1,CONCRETE:15)
Block(-6,112,2,CONCRETE:15)
Block(-6,112,3,CONCRETE:15)
Block(-6,112,4,CONCRETE:15)
Block(-6,112,5,CONCRETE:15)
Block(-6,112,6,CONCRETE:15)
Block(-6,113,-5,CONCRETE:15)
Block(-6,113,-4,CONCRETE:15)
Block(-6,113,-3,CONCRETE:15)
Block(-6,113,-2,CONCRETE:15)
Block(-6,113,-1,CONCRETE:15)
Block(-6,113,0,STAINED_GLASS:15)
Block(-6,113,1,STAINED_GLASS:15)
Block(-6,113,2,CONCRETE:15)
Block(-6,113,3,CONCRETE:15)
Block(-6,113,4,CONCRETE:15)
Block(-6,113,5,CONCRETE:15)
Block(-6,113,6,CONCRETE:15)
Block(-6,114,-7,CONCRETE:8)
Block(-6,114,-6,STAINED_GLASS:15)
Block(-6,114,-5,CONCRETE:15)
Block(-6,114,-4,CONCRETE:15)
Block(-6,114,-3,CONCRETE:15)
Block(-6,114,-2,CONCRETE:15)
Block(-6,114,-1,CONCRETE:15)
Block(-6,114,0,QUARTZ_STAIRS:1)
Block(-6,114,1,QUARTZ_STAIRS:1)
Block(-6,114,2,CONCRETE:15)
Block(-6,114,3,CONCRETE:15)
Block(-6,114,4,CONCRETE:15)
Block(-6,114,5,CONCRETE:15)
Block(-6,114,6,CONCRETE:15)
Block(-6,114,7,STAINED_GLASS:15)
Block(-6,114,8,CONCRETE:8)
Block(-6,115,-5,CONCRETE:15)
Block(-6,115,-4,CONCRETE:15)
Block(-6,115,-3,CONCRETE:15)
Block(-6,115,-2,CONCRETE:15)
Block(-6,115,-1,CONCRETE:15)
Block(-6,115,2,CONCRETE:15)
Block(-6,115,3,CONCRETE:15)
Block(-6,115,4,CONCRETE:15)
Block(-6,115,5,CONCRETE:15)
Block(-6,115,6,CONCRETE:15)
Block(-6,116,-5,CONCRETE:15)
Block(-6,116,-4,CONCRETE:15)
Block(-6,116,-3,CONCRETE:15)
Block(-6,116,-2,CONCRETE:15)
Block(-6,116,-1,CONCRETE:15)
Block(-6,116,2,CONCRETE:15)
Block(-6,116,3,CONCRETE:15)
Block(-6,116,4,CONCRETE:15)
Block(-6,116,5,CONCRETE:15)
Block(-6,116,6,CONCRETE:15)
Block(-6,117,-5,CONCRETE:15)
Block(-6,117,-4,CONCRETE:15)
Block(-6,117,-3,CONCRETE:15)
Block(-6,117,-2,CONCRETE:15)
Block(-6,117,-1,CONCRETE:15)
Block(-6,117,2,CONCRETE:15)
Block(-6,117,3,CONCRETE:15)
Block(-6,117,4,CONCRETE:15)
Block(-6,117,5,CONCRETE:15)
Block(-6,117,6,CONCRETE:15)
Block(-6,118,-5,CONCRETE:15)
Block(-6,118,-4,CONCRETE:15)
Block(-6,118,-3,CONCRETE:15)
Block(-6,118,-2,CONCRETE:15)
Block(-6,118,-1,CONCRETE:15)
Block(-6,118,2,CONCRETE:15)
Block(-6,118,3,CONCRETE:15)
Block(-6,118,4,CONCRETE:15)
Block(-6,118,5,CONCRETE:15)
Block(-6,118,6,CONCRETE:15)
Block(-6,119,-5,CONCRETE:15)
Block(-6,119,-4,CONCRETE:15)
Block(-6,119,-3,CONCRETE:15)
Block(-6,119,-2,CONCRETE:15)
Block(-6,119,-1,CONCRETE:15)
Block(-6,119,0,STAINED_GLASS:15)
Block(-6,119,1,STAINED_GLASS:15)
Block(-6,119,2,CONCRETE:15)
Block(-6,119,3,CONCRETE:15)
Block(-6,119,4,CONCRETE:15)
Block(-6,119,5,CONCRETE:15)
Block(-6,119,6,CONCRETE:15)
Block(-6,120,-7,CONCRETE:8)
Block(-6,120,-6,STAINED_GLASS:15)
Block(-6,120,-5,CONCRETE:15)
Block(-6,120,-4,CONCRETE:15)
Block(-6,120,-3,CONCRETE:15)
Block(-6,120,-2,CONCRETE:15)
Block(-6,120,-1,CONCRETE:15)
Block(-6,120,0,QUARTZ_STAIRS:1)
Block(-6,120,1,QUARTZ_STAIRS:1)
Block(-6,120,2,CONCRETE:15)
Block(-6,120,3,CONCRETE:15)
Block(-6,120,4,CONCRETE:15)
Block(-6,120,5,CONCRETE:15)
Block(-6,120,6,CONCRETE:15)
Block(-6,120,7,STAINED_GLASS:15)
Block(-6,120,8,CONCRETE:8)
Block(-6,121,-5,CONCRETE:15)
Block(-6,121,-4,CONCRETE:15)
Block(-6,121,-3,CONCRETE:15)
Block(-6,121,-2,CONCRETE:15)
Block(-6,121,-1,CONCRETE:15)
Block(-6,121,2,CONCRETE:15)
Block(-6,121,3,CONCRETE:15)
Block(-6,121,4,CONCRETE:15)
Block(-6,121,5,CONCRETE:15)
Block(-6,121,6,CONCRETE:15)
Block(-6,122,-5,CONCRETE:15)
Block(-6,122,-4,CONCRETE:15)
Block(-6,122,-3,CONCRETE:15)
Block(-6,122,-2,CONCRETE:15)
Block(-6,122,-1,CONCRETE:15)
Block(-6,122,2,CONCRETE:15)
Block(-6,122,3,CONCRETE:15)
Block(-6,122,4,CONCRETE:15)
Block(-6,122,5,CONCRETE:15)
Block(-6,122,6,CONCRETE:15)
Block(-6,123,-5,CONCRETE:15)
Block(-6,123,-4,CONCRETE:15)
Block(-6,123,-3,CONCRETE:15)
Block(-6,123,-2,CONCRETE:15)
Block(-6,123,-1,CONCRETE:15)
Block(-6,123,2,CONCRETE:15)
Block(-6,123,3,CONCRETE:15)
Block(-6,123,4,CONCRETE:15)
Block(-6,123,5,CONCRETE:15)
Block(-6,123,6,CONCRETE:15)
Block(-6,124,-5,CONCRETE:15)
Block(-6,124,-4,CONCRETE:15)
Block(-6,124,-3,CONCRETE:15)
Block(-6,124,-2,CONCRETE:15)
Block(-6,124,-1,CONCRETE:15)
Block(-6,124,2,CONCRETE:15)
Block(-6,124,3,CONCRETE:15)
Block(-6,124,4,CONCRETE:15)
Block(-6,124,5,CONCRETE:15)
Block(-6,124,6,CONCRETE:15)
Block(-6,125,-5,CONCRETE:15)
Block(-6,125,-4,CONCRETE:15)
Block(-6,125,-3,CONCRETE:15)
Block(-6,125,-2,CONCRETE:15)
Block(-6,125,-1,CONCRETE:15)
Block(-6,125,0,STAINED_GLASS:15)
Block(-6,125,1,STAINED_GLASS:15)
Block(-6,125,2,CONCRETE:15)
Block(-6,125,3,CONCRETE:15)
Block(-6,125,4,CONCRETE:15)
Block(-6,125,5,CONCRETE:15)
Block(-6,125,6,CONCRETE:15)
Block(-6,126,-7,CONCRETE:8)
Block(-6,126,-6,STAINED_GLASS:15)
Block(-6,126,-5,CONCRETE:15)
Block(-6,126,-4,CONCRETE:15)
Block(-6,126,-3,CONCRETE:15)
Block(-6,126,-2,CONCRETE:15)
Block(-6,126,-1,CONCRETE:15)
Block(-6,126,0,QUARTZ_STAIRS:1)
Block(-6,126,1,QUARTZ_STAIRS:1)
Block(-6,126,2,CONCRETE:15)
Block(-6,126,3,CONCRETE:15)
Block(-6,126,4,CONCRETE:15)
Block(-6,126,5,CONCRETE:15)
Block(-6,126,6,CONCRETE:15)
Block(-6,126,7,STAINED_GLASS:15)
Block(-6,126,8,CONCRETE:8)
Block(-6,127,-5,CONCRETE:15)
Block(-6,127,-4,CONCRETE:15)
Block(-6,127,-3,CONCRETE:15)
Block(-6,127,-2,CONCRETE:15)
Block(-6,127,-1,CONCRETE:15)
Block(-6,127,2,CONCRETE:15)
Block(-6,127,3,CONCRETE:15)
Block(-6,127,4,CONCRETE:15)
Block(-6,127,5,CONCRETE:15)
Block(-6,127,6,CONCRETE:15)
Block(-6,128,-5,CONCRETE:15)
Block(-6,128,-4,CONCRETE:15)
Block(-6,128,-3,CONCRETE:15)
Block(-6,128,-2,CONCRETE:15)
Block(-6,128,-1,CONCRETE:15)
Block(-6,128,2,CONCRETE:15)
Block(-6,128,3,CONCRETE:15)
Block(-6,128,4,CONCRETE:15)
Block(-6,128,5,CONCRETE:15)
Block(-6,128,6,CONCRETE:15)
Block(-6,129,-5,CONCRETE:15)
Block(-6,129,-4,CONCRETE:15)
Block(-6,129,-3,CONCRETE:15)
Block(-6,129,-2,CONCRETE:15)
Block(-6,129,-1,CONCRETE:15)
Block(-6,129,2,CONCRETE:15)
Block(-6,129,3,CONCRETE:15)
Block(-6,129,4,CONCRETE:15)
Block(-6,129,5,CONCRETE:15)
Block(-6,129,6,CONCRETE:15)
Block(-6,130,-5,CONCRETE:15)
Block(-6,130,-4,CONCRETE:15)
Block(-6,130,-3,CONCRETE:15)
Block(-6,130,-2,CONCRETE:15)
Block(-6,130,-1,CONCRETE:15)
Block(-6,130,2,CONCRETE:15)
Block(-6,130,3,CONCRETE:15)
Block(-6,130,4,CONCRETE:15)
Block(-6,130,5,CONCRETE:15)
Block(-6,130,6,CONCRETE:15)
Block(-6,131,-5,CONCRETE:15)
Block(-6,131,-4,CONCRETE:15)
Block(-6,131,-3,CONCRETE:15)
Block(-6,131,-2,CONCRETE:15)
Block(-6,131,-1,CONCRETE:15)
Block(-6,131,0,STAINED_GLASS:15)
Block(-6,131,1,STAINED_GLASS:15)
Block(-6,131,2,CONCRETE:15)
Block(-6,131,3,CONCRETE:15)
Block(-6,131,4,CONCRETE:15)
Block(-6,131,5,CONCRETE:15)
Block(-6,131,6,CONCRETE:15)
Block(-6,132,-7,CONCRETE:8)
Block(-6,132,-6,STAINED_GLASS:15)
Block(-6,132,-5,CONCRETE:15)
Block(-6,132,-4,CONCRETE:15)
Block(-6,132,-3,CONCRETE:15)
Block(-6,132,-2,CONCRETE:15)
Block(-6,132,-1,CONCRETE:15)
Block(-6,132,0,QUARTZ_STAIRS:1)
Block(-6,132,1,QUARTZ_STAIRS:1)
Block(-6,132,2,CONCRETE:15)
Block(-6,132,3,CONCRETE:15)
Block(-6,132,4,CONCRETE:15)
Block(-6,132,5,CONCRETE:15)
Block(-6,132,6,CONCRETE:15)
Block(-6,132,7,STAINED_GLASS:15)
Block(-6,132,8,CONCRETE:8)
Block(-6,133,-5,CONCRETE:15)
Block(-6,133,-4,CONCRETE:15)
Block(-6,133,-3,CONCRETE:15)
Block(-6,133,-2,CONCRETE:15)
Block(-6,133,-1,CONCRETE:15)
Block(-6,133,2,CONCRETE:15)
Block(-6,133,3,CONCRETE:15)
Block(-6,133,4,CONCRETE:15)
Block(-6,133,5,CONCRETE:15)
Block(-6,133,6,CONCRETE:15)
Block(-6,134,-5,CONCRETE:15)
Block(-6,134,-4,CONCRETE:15)
Block(-6,134,-3,CONCRETE:15)
Block(-6,134,-2,CONCRETE:15)
Block(-6,134,-1,CONCRETE:15)
Block(-6,134,2,CONCRETE:15)
Block(-6,134,3,CONCRETE:15)
Block(-6,134,4,CONCRETE:15)
Block(-6,134,5,CONCRETE:15)
Block(-6,134,6,CONCRETE:15)
Block(-6,135,-5,CONCRETE:15)
Block(-6,135,-4,CONCRETE:15)
Block(-6,135,-3,CONCRETE:15)
Block(-6,135,-2,CONCRETE:15)
Block(-6,135,-1,CONCRETE:15)
Block(-6,135,2,CONCRETE:15)
Block(-6,135,3,CONCRETE:15)
Block(-6,135,4,CONCRETE:15)
Block(-6,135,5,CONCRETE:15)
Block(-6,135,6,CONCRETE:15)
Block(-6,136,-5,CONCRETE:15)
Block(-6,136,-4,CONCRETE:15)
Block(-6,136,-3,CONCRETE:15)
Block(-6,136,-2,CONCRETE:15)
Block(-6,136,-1,CONCRETE:15)
Block(-6,136,2,CONCRETE:15)
Block(-6,136,3,CONCRETE:15)
Block(-6,136,4,CONCRETE:15)
Block(-6,136,5,CONCRETE:15)
Block(-6,136,6,CONCRETE:15)
Block(-6,137,-5,CONCRETE:15)
Block(-6,137,-4,CONCRETE:15)
Block(-6,137,-3,CONCRETE:15)
Block(-6,137,-2,CONCRETE:15)
Block(-6,137,-1,CONCRETE:15)
Block(-6,137,0,STAINED_GLASS:15)
Block(-6,137,1,STAINED_GLASS:15)
Block(-6,137,2,CONCRETE:15)
Block(-6,137,3,CONCRETE:15)
Block(-6,137,4,CONCRETE:15)
Block(-6,137,5,CONCRETE:15)
Block(-6,137,6,CONCRETE:15)
Block(-6,138,-7,CONCRETE:8)
Block(-6,138,-6,STAINED_GLASS:15)
Block(-6,138,-5,CONCRETE:15)
Block(-6,138,-4,CONCRETE:15)
Block(-6,138,-3,CONCRETE:15)
Block(-6,138,-2,CONCRETE:15)
Block(-6,138,-1,CONCRETE:15)
Block(-6,138,0,QUARTZ_STAIRS:1)
Block(-6,138,1,QUARTZ_STAIRS:1)
Block(-6,138,2,CONCRETE:15)
Block(-6,138,3,CONCRETE:15)
Block(-6,138,4,CONCRETE:15)
Block(-6,138,5,CONCRETE:15)
Block(-6,138,6,CONCRETE:15)
Block(-6,138,7,STAINED_GLASS:15)
Block(-6,138,8,CONCRETE:8)
Block(-6,139,-5,CONCRETE:15)
Block(-6,139,-4,CONCRETE:15)
Block(-6,139,-3,CONCRETE:15)
Block(-6,139,-2,CONCRETE:15)
Block(-6,139,-1,CONCRETE:15)
Block(-6,139,2,CONCRETE:15)
Block(-6,139,3,CONCRETE:15)
Block(-6,139,4,CONCRETE:15)
Block(-6,139,5,CONCRETE:15)
Block(-6,139,6,CONCRETE:15)
Block(-6,140,-5,CONCRETE:15)
Block(-6,140,-4,CONCRETE:15)
Block(-6,140,-3,CONCRETE:15)
Block(-6,140,-2,CONCRETE:15)
Block(-6,140,-1,CONCRETE:15)
Block(-6,140,2,CONCRETE:15)
Block(-6,140,3,CONCRETE:15)
Block(-6,140,4,CONCRETE:15)
Block(-6,140,5,CONCRETE:15)
Block(-6,140,6,CONCRETE:15)
Block(-6,141,-5,CONCRETE:15)
Block(-6,141,-4,CONCRETE:15)
Block(-6,141,-3,CONCRETE:15)
Block(-6,141,-2,CONCRETE:15)
Block(-6,141,-1,CONCRETE:15)
Block(-6,141,2,CONCRETE:15)
Block(-6,141,3,CONCRETE:15)
Block(-6,141,4,CONCRETE:15)
Block(-6,141,5,CONCRETE:15)
Block(-6,141,6,CONCRETE:15)
Block(-6,142,-5,CONCRETE:15)
Block(-6,142,-4,CONCRETE:15)
Block(-6,142,-3,CONCRETE:15)
Block(-6,142,-2,CONCRETE:15)
Block(-6,142,-1,CONCRETE:15)
Block(-6,142,2,CONCRETE:15)
Block(-6,142,3,CONCRETE:15)
Block(-6,142,4,CONCRETE:15)
Block(-6,142,5,CONCRETE:15)
Block(-6,142,6,CONCRETE:15)
Block(-6,143,-5,CONCRETE:15)
Block(-6,143,-4,CONCRETE:15)
Block(-6,143,-3,CONCRETE:15)
Block(-6,143,-2,CONCRETE:15)
Block(-6,143,-1,CONCRETE:15)
Block(-6,143,0,STAINED_GLASS:15)
Block(-6,143,1,STAINED_GLASS:15)
Block(-6,143,2,CONCRETE:15)
Block(-6,143,3,CONCRETE:15)
Block(-6,143,4,CONCRETE:15)
Block(-6,143,5,CONCRETE:15)
Block(-6,143,6,CONCRETE:15)
Block(-6,144,-7,CONCRETE:8)
Block(-6,144,-6,STAINED_GLASS:15)
Block(-6,144,-5,CONCRETE:15)
Block(-6,144,-4,CONCRETE:15)
Block(-6,144,-3,CONCRETE:15)
Block(-6,144,-2,CONCRETE:15)
Block(-6,144,-1,CONCRETE:15)
Block(-6,144,0,QUARTZ_STAIRS:1)
Block(-6,144,1,QUARTZ_STAIRS:1)
Block(-6,144,2,CONCRETE:15)
Block(-6,144,3,CONCRETE:15)
Block(-6,144,4,CONCRETE:15)
Block(-6,144,5,CONCRETE:15)
Block(-6,144,6,CONCRETE:15)
Block(-6,144,7,STAINED_GLASS:15)
Block(-6,144,8,CONCRETE:8)
Block(-6,145,-5,CONCRETE:15)
Block(-6,145,-4,CONCRETE:15)
Block(-6,145,-3,CONCRETE:15)
Block(-6,145,-2,CONCRETE:15)
Block(-6,145,-1,CONCRETE:15)
Block(-6,145,2,CONCRETE:15)
Block(-6,145,3,CONCRETE:15)
Block(-6,145,4,CONCRETE:15)
Block(-6,145,5,CONCRETE:15)
Block(-6,145,6,CONCRETE:15)
Block(-6,146,-5,CONCRETE:15)
Block(-6,146,-4,CONCRETE:15)
Block(-6,146,-3,CONCRETE:15)
Block(-6,146,-2,CONCRETE:15)
Block(-6,146,-1,CONCRETE:15)
Block(-6,146,2,CONCRETE:15)
Block(-6,146,3,CONCRETE:15)
Block(-6,146,4,CONCRETE:15)
Block(-6,146,5,CONCRETE:15)
Block(-6,146,6,CONCRETE:15)
Block(-6,147,-5,CONCRETE:15)
Block(-6,147,-4,CONCRETE:15)
Block(-6,147,-3,CONCRETE:15)
Block(-6,147,-2,CONCRETE:15)
Block(-6,147,-1,CONCRETE:15)
Block(-6,147,2,CONCRETE:15)
Block(-6,147,3,CONCRETE:15)
Block(-6,147,4,CONCRETE:15)
Block(-6,147,5,CONCRETE:15)
Block(-6,147,6,CONCRETE:15)
Block(-6,148,-5,CONCRETE:15)
Block(-6,148,-4,CONCRETE:15)
Block(-6,148,-3,CONCRETE:15)
Block(-6,148,-2,CONCRETE:15)
Block(-6,148,-1,CONCRETE:15)
Block(-6,148,2,CONCRETE:15)
Block(-6,148,3,CONCRETE:15)
Block(-6,148,4,CONCRETE:15)
Block(-6,148,5,CONCRETE:15)
Block(-6,148,6,CONCRETE:15)
Block(-6,149,-5,CONCRETE:15)
Block(-6,149,-4,CONCRETE:15)
Block(-6,149,-3,CONCRETE:15)
Block(-6,149,-2,CONCRETE:15)
Block(-6,149,-1,CONCRETE:15)
Block(-6,149,0,STAINED_GLASS:15)
Block(-6,149,1,STAINED_GLASS:15)
Block(-6,149,2,CONCRETE:15)
Block(-6,149,3,CONCRETE:15)
Block(-6,149,4,CONCRETE:15)
Block(-6,149,5,CONCRETE:15)
Block(-6,149,6,CONCRETE:15)
Block(-6,150,-7,CONCRETE:8)
Block(-6,150,-6,STAINED_GLASS:15)
Block(-6,150,-5,CONCRETE:15)
Block(-6,150,-4,CONCRETE:15)
Block(-6,150,-3,CONCRETE:15)
Block(-6,150,-2,CONCRETE:15)
Block(-6,150,-1,CONCRETE:15)
Block(-6,150,0,QUARTZ_STAIRS:1)
Block(-6,150,1,QUARTZ_STAIRS:1)
Block(-6,150,2,CONCRETE:15)
Block(-6,150,3,CONCRETE:15)
Block(-6,150,4,CONCRETE:15)
Block(-6,150,5,CONCRETE:15)
Block(-6,150,6,CONCRETE:15)
Block(-6,150,7,STAINED_GLASS:15)
Block(-6,150,8,CONCRETE:8)
Block(-6,151,-5,CONCRETE:15)
Block(-6,151,-4,CONCRETE:15)
Block(-6,151,-3,CONCRETE:15)
Block(-6,151,-2,CONCRETE:15)
Block(-6,151,-1,CONCRETE:15)
Block(-6,151,2,CONCRETE:15)
Block(-6,151,3,CONCRETE:15)
Block(-6,151,4,CONCRETE:15)
Block(-6,151,5,CONCRETE:15)
Block(-6,151,6,CONCRETE:15)
Block(-6,152,-5,CONCRETE:15)
Block(-6,152,-4,CONCRETE:15)
Block(-6,152,-3,CONCRETE:15)
Block(-6,152,-2,CONCRETE:15)
Block(-6,152,-1,CONCRETE:15)
Block(-6,152,2,CONCRETE:15)
Block(-6,152,3,CONCRETE:15)
Block(-6,152,4,CONCRETE:15)
