Author: NLBlackEagle
Description: No description given
SettingsMode: WriteDisable
Frequency: 10
SpawnHeight: highestBlock
UseCenterForHighestBlock: true
MinHeight: 63
MaxHeight: 255
InheritBO3: 
InheritBO3Rotation: NORTH
OverrideChildSettings: true
OverrideParentHeight: false
CanOverride: true
BranchFrequency: 5
BranchFrequencyGroup: 
MustBeBelowOther: false
MustBeInside: 
CannotBeInside: 
ReplacesBO3: 
MustBeInsideWorldBorders: false
CanSpawnOnWater: false
SpawnOnWaterOnly: false
SpawnUnderWater: false
SpawnAtWaterLevel: false
HeightOffset: -2
RemoveAir: false
ReplaceAbove: 
ReplaceBelow: cobblestone
ReplaceWithBiomeBlocks: true
ReplaceWithSurfaceBlock: GRASS
ReplaceWithGroundBlock: DIRT
ReplaceWithStoneBlock: STONE
SmoothRadius: 0
SmoothHeightOffset: 0
SmoothStartTop: false
SmoothStartWood: false
SmoothingSurfaceBlock: 
SmoothingGroundBlock: 
BO3Group: 
IsSpawnPoint: false
DoReplaceBlocks: true
Block(-7,8,-1,WOOD_BUTTON:2)
Block(-6,8,-1,LOG:5)
Block(-5,0,-5,WOOD:1)
Block(-5,0,-4,LOG:1)
Block(-5,0,1,LOG:1)
Block(-5,0,3,LOG:1)
Block(-5,1,-5,WOOD:1)
Block(-5,1,-4,LOG:1)
Block(-5,1,1,LOG:1)
Block(-5,1,3,LOG:1)
Block(-5,2,-4,LOG:1)
Block(-5,2,1,LOG:1)
Block(-5,2,3,LOG:1)
Block(-5,3,-5,SPRUCE_FENCE:0)
Block(-5,3,-4,LOG:1)
Block(-5,3,-3,WOOD:1)
Block(-5,3,-2,WOOD:1)
Block(-5,3,-1,WOOD:1)
Block(-5,3,0,WOOD:1)
Block(-5,3,1,LOG:1)
Block(-5,3,2,WOOD:1)
Block(-5,3,3,LOG:1)
Block(-5,4,-5,SPRUCE_FENCE:0)
Block(-5,4,-4,LOG:1)
Block(-5,4,-3,WOOD:1)
Block(-5,4,-2,WOOD:1)
Block(-5,4,-1,WOOD:1)
Block(-5,4,0,WOOD:1)
Block(-5,4,1,LOG:1)
Block(-5,4,2,WOOD:1)
Block(-5,4,3,LOG:1)
Block(-5,5,-4,LOG:1)
Block(-5,5,-3,WOOD:1)
Block(-5,5,-2,WOOD:1)
Block(-5,5,-1,WOOD:1)
Block(-5,5,0,WOOD:1)
Block(-5,5,1,LOG:1)
Block(-5,5,2,WOOD:1)
Block(-5,6,-3,WOOD:1)
Block(-5,6,-2,WOOD:1)
Block(-5,6,-1,WOOD:1)
Block(-5,6,0,WOOD:1)
Block(-5,6,1,LOG:1)
Block(-5,7,-2,WOOD:1)
Block(-5,7,-1,WOOD:1)
Block(-5,7,0,WOOD:1)
Block(-5,8,-1,LOG:5)
Block(-4,3,-4,WOOD:1)
Block(-4,3,-3,WORKBENCH:0)
Block(-4,3,-2,WOOD_STEP:13)
Block(-4,3,-1,WOOD_STEP:13)
Block(-4,3,0,WOOD_STEP:13)
Block(-4,3,1,WOOD_STEP:13)
Block(-4,3,2,WOOD_STEP:13)
Block(-4,3,3,WOOD:1)
Block(-4,4,-4,WOOD:1)
RandomBlock(-4,4,0,SKULL:1,../../../../Skulls/dungeon_skull_01.nbt,6,AIR,9,SKULL:1,../../../../Skulls/dungeon_skull_02.nbt,12,AIR,15,SKULL:1,../../../../Skulls/dungeon_skull_03.nbt,18,AIR,21,SKULL:1,../../../../Skulls/dungeon_skull_04.nbt,24,AIR,27,SKULL:1,../../../../Skulls/dungeon_skull_05.nbt,30,AIR,33,SKULL:1,../../../../Skulls/dungeon_skull_06.nbt,36,AIR,39,SKULL:1,../../../../Skulls/dungeon_skull_07.nbt,42,AIR,45,SKULL:1,../../../../Skulls/dungeon_skull_08.nbt,48,AIR,51,SKULL:1,../../../../Skulls/dungeon_skull_09.nbt,54,AIR,57,SKULL:1,../../../../Skulls/dungeon_skull_10.nbt,60,AIR,63,SKULL:1,../../../../Skulls/dungeon_skull_11.nbt,66,AIR,69,SKULL:1,../../../../Skulls/dungeon_skull_12.nbt,72,AIR,75,SKULL:1,../../../../Skulls/dungeon_skull_13.nbt,78,AIR,81,SKULL:1,../../../../Skulls/dungeon_skull_14.nbt,84,AIR,87,SKULL:1,../../../../Skulls/dungeon_skull_15.nbt,90,AIR,93,SKULL:1,../../../../Skulls/dungeon_skull_16.nbt,96,AIR,100)
RandomBlock(-4,4,2,AIR:0,20,CHEST:2,../../../../Chests/Loot/JunkChest_1.nbt,10,CHEST:2,../../../../Chests/Loot/JunkChest_2.nbt,10,CHEST:2,../../../../Chests/Loot/JunkChest_3.nbt,10,CHEST:2,../../../../Chests/Loot/JunkChest_4.nbt,10,CHEST:2,../../../../Chests/Loot/JunkChest_5.nbt,10,CHEST:2,../../../../Chests/Lore/Viking_1.nbt,1,CHEST:2,../../../../Chests/Lore/Viking_2.nbt,1,CHEST:2,../../../../Chests/Lore/Viking_3.nbt,1,CHEST:2,../../../../Chests/Lore/Viking_4.nbt,1,CHEST:2,../../../../Chests/Lore/Viking_5.nbt,1,CHEST:2,../../../../Chests/Loot/Common1.nbt,10,CHEST:2,../../../../Chests/Loot/Common2.nbt,10,CHEST:2,../../../../Chests/Loot/Common3.nbt,10,CHEST:2,../../../../Chests/Loot/Common4.nbt,10,CHEST:2,../../../../Chests/Loot/Common5.nbt,10,CHEST:2,../../../../Chests/Loot/Common6.nbt,10,CHEST:2,../../../../Chests/Loot/Common7.nbt,10,CHEST:2,../../../../Chests/Loot/Common8.nbt,10,CHEST:2,../../../../Chests/Loot/Common9.nbt,10,CHEST:2,../../../../Chests/Loot/Common10.nbt,10,CHEST:2,../../../../Chests/Loot/Common10.nbt,11,CHEST:2,../../../../Chests/Loot/Common12.nbt,10,CHEST:2,../../../../Chests/Loot/Common13.nbt,10,CHEST:2,../../../../Chests/Loot/Common14.nbt,10,CHEST:2,../../../../Chests/Loot/Common15.nbt,10,CHEST:2,../../../../Chests/Lore/Viking_1.nbt,2,CHEST:2,../../../../Chests/Lore/Viking_3.nbt,2,CHEST:2,../../../../Chests/Lore/Viking_4.nbt,2,CHEST:2,../../../../Chests/Lore/Viking_5.nbt,2,CHEST:2,../../../../Chests/Lore/Viking_5.nbt,2,CHEST:2,../../../../Chests/Loot/Rare1.nbt,5,CHEST:2,../../../../Chests/Loot/Rare2.nbt,5,CHEST:2,../../../../Chests/Loot/Rare3.nbt,5,CHEST:2,../../../../Chests/Loot/Rare4.nbt,5,CHEST:2,../../../../Chests/Loot/Rare5.nbt,5,CHEST:2,../../../../Chests/Loot/Rare6.nbt,5,CHEST:2,../../../../Chests/Loot/Rare7.nbt,5,CHEST:2,../../../../Chests/Loot/Rare8.nbt,5,CHEST:2,../../../../Chests/Loot/Rare9.nbt,5,CHEST:2,../../../../Chests/Loot/Rare10.nbt,5,CHEST:2,../../../../Chests/Loot/Rare11.nbt,5,CHEST:2,../../../../Chests/Loot/Rare12.nbt,5,CHEST:2,../../../../Chests/Loot/Rare13.nbt,5,CHEST:2,../../../../Chests/Loot/Rare14.nbt,5,CHEST:2,../../../../Chests/Loot/Rare15.nbt,5,CHEST:2,../../../../Chests/Loot/Epic1.nbt,2,CHEST:2,../../../../Chests/Loot/Epic2.nbt,2,CHEST:2,../../../../Chests/Loot/Epic3.nbt,2,CHEST:2,../../../../Chests/Loot/Epic4.nbt,2,CHEST:2,../../../../Chests/Loot/Epic5.nbt,2,CHEST:2,../../../../Chests/Loot/Epic6.nbt,2,CHEST:2,../../../../Chests/Loot/Epic7.nbt,2,CHEST:2,../../../../Chests/Loot/Epic8.nbt,2,CHEST:2,../../../../Chests/Loot/Epic9.nbt,2,CHEST:2,../../../../Chests/Loot/Epic10.nbt,2,CHEST:2,../../../../Chests/Loot/Epic11.nbt,2,CHEST:2,../../../../Chests/Loot/Epic12.nbt,2,CHEST:2,../../../../Chests/Loot/Epic13.nbt,2,CHEST:2,../../../../Chests/Loot/Epic14.nbt,2,CHEST:2,../../../../Chests/Loot/Epic15.nbt,5,CHEST:2,../../../../Chests/Loot/Rare1.nbt,5,CHEST:2,../../../../Chests/Loot/Rare2.nbt,5,CHEST:2,../../../../Chests/Loot/Rare3.nbt,5,CHEST:2,../../../../Chests/Loot/Rare4.nbt,5,CHEST:2,../../../../Chests/Loot/Rare5.nbt,10,CHEST:2,../../../../Chests/Loot/Rare6.nbt,10,CHEST:2,../../../../Chests/Loot/Rare7.nbt,10,CHEST:2,../../../../Chests/Loot/Rare8.nbt,10,CHEST:2,../../../../Chests/Loot/Rare9.nbt,10,CHEST:2,../../../../Chests/Loot/Rare10.nbt,15,CHEST:2,../../../../Chests/Loot/Rare11.nbt,15,CHEST:2,../../../../Chests/Loot/Rare12.nbt,15,CHEST:2,../../../../Chests/Loot/Rare13.nbt,15,CHEST:2,../../../../Chests/Loot/Rare14.nbt,15,CHEST:2,../../../../Chests/Loot/Rare15.nbt,15,CHEST:2,../../../../Chests/Loot/Epic15.nbt,100)
Block(-4,4,3,WOOD:1)
Block(-4,5,-4,LOG:5)
RandomBlock(-4,5,-1,WALL_BANNER:5,../../NBT/Banners/viking_wealthy_1.nbt,20,WALL_BANNER:5,../../NBT/Banners/viking_wealthy_2.nbt,20,WALL_BANNER:5,../../NBT/Banners/viking_wealthy_3.nbt,20,WALL_BANNER:5,../../NBT/Banners/viking_wealthy_4.nbt,20,WALL_BANNER:5,../../NBT/Banners/viking_wealthy_5.nbt,20,WALL_BANNER:5,../../NBT/Banners/viking_wealthy_6.nbt,20,WALL_BANNER:5,../../NBT/Banners/viking_wealthy_7.nbt,20,WALL_BANNER:5,../../NBT/Banners/viking_wealthy_8.nbt,20,WALL_BANNER:5,../../NBT/Banners/viking_wealthy_9.nbt,100)
RandomBlock(-4,5,1,WALL_BANNER:5,../../NBT/Banners/viking_wealthy_1.nbt,20,WALL_BANNER:5,../../NBT/Banners/viking_wealthy_2.nbt,20,WALL_BANNER:5,../../NBT/Banners/viking_wealthy_3.nbt,20,WALL_BANNER:5,../../NBT/Banners/viking_wealthy_4.nbt,20,WALL_BANNER:5,../../NBT/Banners/viking_wealthy_5.nbt,20,WALL_BANNER:5,../../NBT/Banners/viking_wealthy_6.nbt,20,WALL_BANNER:5,../../NBT/Banners/viking_wealthy_7.nbt,20,WALL_BANNER:5,../../NBT/Banners/viking_wealthy_8.nbt,20,WALL_BANNER:5,../../NBT/Banners/viking_wealthy_9.nbt,100)
RandomBlock(-4,6,0,WALL_BANNER:5,../../NBT/Banners/viking_wealthy_1.nbt,20,WALL_BANNER:5,../../NBT/Banners/viking_wealthy_2.nbt,20,WALL_BANNER:5,../../NBT/Banners/viking_wealthy_3.nbt,20,WALL_BANNER:5,../../NBT/Banners/viking_wealthy_4.nbt,20,WALL_BANNER:5,../../NBT/Banners/viking_wealthy_5.nbt,20,WALL_BANNER:5,../../NBT/Banners/viking_wealthy_6.nbt,20,WALL_BANNER:5,../../NBT/Banners/viking_wealthy_7.nbt,20,WALL_BANNER:5,../../NBT/Banners/viking_wealthy_8.nbt,20,WALL_BANNER:5,../../NBT/Banners/viking_wealthy_9.nbt,100)
Block(-4,6,1,LOG:5)
Block(-4,8,-1,LOG:5)
Block(-3,3,-4,WOOD:1)
Block(-3,3,-3,WALL_SIGN:4)
Block(-3,3,-2,WALL_SIGN:4)
Block(-3,3,-1,CARPET:12)
Block(-3,3,0,CARPET:12)
Block(-3,3,1,CARPET:12)
Block(-3,3,2,WOOD_STEP:13)
Block(-3,3,3,WOOD:1)
Block(-3,4,-4,WOOD:1)
RandomBlock(-3,4,2,AIR:0,20,CHEST:2,../../../../Chests/Loot/JunkChest_1.nbt,10,CHEST:2,../../../../Chests/Loot/JunkChest_2.nbt,10,CHEST:2,../../../../Chests/Loot/JunkChest_3.nbt,10,CHEST:2,../../../../Chests/Loot/JunkChest_4.nbt,10,CHEST:2,../../../../Chests/Loot/JunkChest_5.nbt,10,CHEST:2,../../../../Chests/Lore/Viking_1.nbt,1,CHEST:2,../../../../Chests/Lore/Viking_2.nbt,1,CHEST:2,../../../../Chests/Lore/Viking_3.nbt,1,CHEST:2,../../../../Chests/Lore/Viking_4.nbt,1,CHEST:2,../../../../Chests/Lore/Viking_5.nbt,1,CHEST:2,../../../../Chests/Loot/Common1.nbt,10,CHEST:2,../../../../Chests/Loot/Common2.nbt,10,CHEST:2,../../../../Chests/Loot/Common3.nbt,10,CHEST:2,../../../../Chests/Loot/Common4.nbt,10,CHEST:2,../../../../Chests/Loot/Common5.nbt,10,CHEST:2,../../../../Chests/Loot/Common6.nbt,10,CHEST:2,../../../../Chests/Loot/Common7.nbt,10,CHEST:2,../../../../Chests/Loot/Common8.nbt,10,CHEST:2,../../../../Chests/Loot/Common9.nbt,10,CHEST:2,../../../../Chests/Loot/Common10.nbt,10,CHEST:2,../../../../Chests/Loot/Common10.nbt,11,CHEST:2,../../../../Chests/Loot/Common12.nbt,10,CHEST:2,../../../../Chests/Loot/Common13.nbt,10,CHEST:2,../../../../Chests/Loot/Common14.nbt,10,CHEST:2,../../../../Chests/Loot/Common15.nbt,10,CHEST:2,../../../../Chests/Lore/Viking_1.nbt,2,CHEST:2,../../../../Chests/Lore/Viking_3.nbt,2,CHEST:2,../../../../Chests/Lore/Viking_4.nbt,2,CHEST:2,../../../../Chests/Lore/Viking_5.nbt,2,CHEST:2,../../../../Chests/Lore/Viking_5.nbt,2,CHEST:2,../../../../Chests/Loot/Rare1.nbt,5,CHEST:2,../../../../Chests/Loot/Rare2.nbt,5,CHEST:2,../../../../Chests/Loot/Rare3.nbt,5,CHEST:2,../../../../Chests/Loot/Rare4.nbt,5,CHEST:2,../../../../Chests/Loot/Rare5.nbt,5,CHEST:2,../../../../Chests/Loot/Rare6.nbt,5,CHEST:2,../../../../Chests/Loot/Rare7.nbt,5,CHEST:2,../../../../Chests/Loot/Rare8.nbt,5,CHEST:2,../../../../Chests/Loot/Rare9.nbt,5,CHEST:2,../../../../Chests/Loot/Rare10.nbt,5,CHEST:2,../../../../Chests/Loot/Rare11.nbt,5,CHEST:2,../../../../Chests/Loot/Rare12.nbt,5,CHEST:2,../../../../Chests/Loot/Rare13.nbt,5,CHEST:2,../../../../Chests/Loot/Rare14.nbt,5,CHEST:2,../../../../Chests/Loot/Rare15.nbt,5,CHEST:2,../../../../Chests/Loot/Epic1.nbt,2,CHEST:2,../../../../Chests/Loot/Epic2.nbt,2,CHEST:2,../../../../Chests/Loot/Epic3.nbt,2,CHEST:2,../../../../Chests/Loot/Epic4.nbt,2,CHEST:2,../../../../Chests/Loot/Epic5.nbt,2,CHEST:2,../../../../Chests/Loot/Epic6.nbt,2,CHEST:2,../../../../Chests/Loot/Epic7.nbt,2,CHEST:2,../../../../Chests/Loot/Epic8.nbt,2,CHEST:2,../../../../Chests/Loot/Epic9.nbt,2,CHEST:2,../../../../Chests/Loot/Epic10.nbt,2,CHEST:2,../../../../Chests/Loot/Epic11.nbt,2,CHEST:2,../../../../Chests/Loot/Epic12.nbt,2,CHEST:2,../../../../Chests/Loot/Epic13.nbt,2,CHEST:2,../../../../Chests/Loot/Epic14.nbt,2,CHEST:2,../../../../Chests/Loot/Epic15.nbt,5,CHEST:2,../../../../Chests/Loot/Rare1.nbt,5,CHEST:2,../../../../Chests/Loot/Rare2.nbt,5,CHEST:2,../../../../Chests/Loot/Rare3.nbt,5,CHEST:2,../../../../Chests/Loot/Rare4.nbt,5,CHEST:2,../../../../Chests/Loot/Rare5.nbt,10,CHEST:2,../../../../Chests/Loot/Rare6.nbt,10,CHEST:2,../../../../Chests/Loot/Rare7.nbt,10,CHEST:2,../../../../Chests/Loot/Rare8.nbt,10,CHEST:2,../../../../Chests/Loot/Rare9.nbt,10,CHEST:2,../../../../Chests/Loot/Rare10.nbt,15,CHEST:2,../../../../Chests/Loot/Rare11.nbt,15,CHEST:2,../../../../Chests/Loot/Rare12.nbt,15,CHEST:2,../../../../Chests/Loot/Rare13.nbt,15,CHEST:2,../../../../Chests/Loot/Rare14.nbt,15,CHEST:2,../../../../Chests/Loot/Rare15.nbt,15,CHEST:2,../../../../Chests/Loot/Epic15.nbt,100)
Block(-3,4,3,WOOD:1)
Block(-3,5,-4,LOG:5)
RandomBlock(-3,5,2,WALL_BANNER:2,../../NBT/Banners/viking_wealthy_1.nbt,20,WALL_BANNER:2,../../NBT/Banners/viking_wealthy_2.nbt,20,WALL_BANNER:2,../../NBT/Banners/viking_wealthy_3.nbt,20,WALL_BANNER:2,../../NBT/Banners/viking_wealthy_4.nbt,20,WALL_BANNER:2,../../NBT/Banners/viking_wealthy_5.nbt,20,WALL_BANNER:2,../../NBT/Banners/viking_wealthy_6.nbt,20,WALL_BANNER:2,../../NBT/Banners/viking_wealthy_7.nbt,20,WALL_BANNER:2,../../NBT/Banners/viking_wealthy_8.nbt,20,WALL_BANNER:2,../../NBT/Banners/viking_wealthy_9.nbt,100)
Block(-3,6,1,LOG:5)
Block(-3,8,-1,LOG:5)
Block(-2,0,-5,WOOD:1)
Block(-2,0,-4,LOG:1)
Block(-2,0,1,LOG:1)
Block(-2,0,3,LOG:1)
Block(-2,1,-5,WOOD:1)
Block(-2,1,-4,LOG:1)
Block(-2,1,1,LOG:1)
Block(-2,1,3,LOG:1)
Block(-2,2,-4,LOG:1)
Block(-2,2,1,LOG:1)
Block(-2,2,3,LOG:1)
Block(-2,3,-5,SPRUCE_FENCE:0)
Block(-2,3,-4,LOG:1)
Block(-2,3,-3,BED_BLOCK:10)
Block(-2,3,-2,BED_BLOCK:2)
Block(-2,3,-1,WALL_SIGN:3)
Block(-2,3,0,CARPET:12)
Block(-2,3,1,LOG:1)
Block(-2,3,2,WOOD:1)
Block(-2,3,3,LOG:1)
Block(-2,4,-5,SPRUCE_FENCE:0)
Block(-2,4,-4,LOG:1)
RandomBlock(-2,4,-3,WALL_BANNER:3,../../NBT/Banners/viking_regular_1.nbt,20,WALL_BANNER:3,../../NBT/Banners/viking_regular_2.nbt,20,WALL_BANNER:3,../../NBT/Banners/viking_regular_3.nbt,20,WALL_BANNER:3,../../NBT/Banners/viking_regular_4.nbt,20,WALL_BANNER:3,../../NBT/Banners/viking_regular_5.nbt,20,WALL_BANNER:3,../../NBT/Banners/viking_regular_6.nbt,20,WALL_BANNER:3,../../NBT/Banners/viking_regular_7.nbt,20,WALL_BANNER:3,../../NBT/Banners/viking_regular_8.nbt,100)
Block(-2,4,1,LOG:1)
Block(-2,4,2,WOOD:1)
Block(-2,4,3,LOG:1)
Block(-2,5,-4,LOG:5)
Block(-2,5,1,LOG:1)
Block(-2,5,2,WOOD:1)
Block(-2,6,-3,LOG:9)
Block(-2,6,-2,LOG:9)
Block(-2,6,-1,LOG:9)
Block(-2,6,0,LOG:9)
Block(-2,6,1,LOG:1)
Block(-2,8,-1,LOG:5)
Block(-1,3,-4,WOOD:1)
Block(-1,3,-3,BED_BLOCK:10)
Block(-1,3,-2,BED_BLOCK:2)
Block(-1,3,-1,WALL_SIGN:3)
Block(-1,3,0,CARPET:12)
Block(-1,3,1,WOOD:1)
Block(-1,4,-4,WOOD:1)
RandomBlock(-1,4,-3,WALL_BANNER:3,../../NBT/Banners/viking_wealthy_1.nbt,20,WALL_BANNER:3,../../NBT/Banners/viking_wealthy_2.nbt,20,WALL_BANNER:3,../../NBT/Banners/viking_wealthy_3.nbt,20,WALL_BANNER:3,../../NBT/Banners/viking_wealthy_4.nbt,20,WALL_BANNER:3,../../NBT/Banners/viking_wealthy_5.nbt,20,WALL_BANNER:3,../../NBT/Banners/viking_wealthy_6.nbt,20,WALL_BANNER:3,../../NBT/Banners/viking_wealthy_7.nbt,20,WALL_BANNER:3,../../NBT/Banners/viking_wealthy_8.nbt,20,WALL_BANNER:3,../../NBT/Banners/viking_wealthy_9.nbt,100)
Block(-1,4,1,WOOD:1)
Block(-1,5,-4,LOG:5)
RandomBlock(-1,5,-3,WALL_BANNER:3,../../NBT/Banners/viking_regular_1.nbt,20,WALL_BANNER:3,../../NBT/Banners/viking_regular_2.nbt,20,WALL_BANNER:3,../../NBT/Banners/viking_regular_3.nbt,20,WALL_BANNER:3,../../NBT/Banners/viking_regular_4.nbt,20,WALL_BANNER:3,../../NBT/Banners/viking_regular_5.nbt,20,WALL_BANNER:3,../../NBT/Banners/viking_regular_6.nbt,20,WALL_BANNER:3,../../NBT/Banners/viking_regular_7.nbt,20,WALL_BANNER:3,../../NBT/Banners/viking_regular_8.nbt,100)
Block(-1,5,1,WOOD:1)
Block(-1,6,1,LOG:5)
Block(-1,8,-1,LOG:5)
Block(0,3,-4,WOOD:1)
Block(0,3,-3,WALL_SIGN:5)
Block(0,3,-2,WALL_SIGN:5)
Block(0,3,-1,CARPET:12)
Block(0,3,1,SPRUCE_DOOR:5)
Block(0,4,-4,WOOD:1)
RandomBlock(0,4,-3,WALL_BANNER:3,../../NBT/Banners/viking_regular_1.nbt,20,WALL_BANNER:3,../../NBT/Banners/viking_regular_2.nbt,20,WALL_BANNER:3,../../NBT/Banners/viking_regular_3.nbt,20,WALL_BANNER:3,../../NBT/Banners/viking_regular_4.nbt,20,WALL_BANNER:3,../../NBT/Banners/viking_regular_5.nbt,20,WALL_BANNER:3,../../NBT/Banners/viking_regular_6.nbt,20,WALL_BANNER:3,../../NBT/Banners/viking_regular_7.nbt,20,WALL_BANNER:3,../../NBT/Banners/viking_regular_8.nbt,100)
Block(0,4,1,SPRUCE_DOOR:8)
Block(0,5,-4,LOG:5)
RandomBlock(0,5,-3,WALL_BANNER:3,../../NBT/Banners/viking_regular_1.nbt,20,WALL_BANNER:3,../../NBT/Banners/viking_regular_2.nbt,20,WALL_BANNER:3,../../NBT/Banners/viking_regular_3.nbt,20,WALL_BANNER:3,../../NBT/Banners/viking_regular_4.nbt,20,WALL_BANNER:3,../../NBT/Banners/viking_regular_5.nbt,20,WALL_BANNER:3,../../NBT/Banners/viking_regular_6.nbt,20,WALL_BANNER:3,../../NBT/Banners/viking_regular_7.nbt,20,WALL_BANNER:3,../../NBT/Banners/viking_regular_8.nbt,100)
Block(0,5,1,WOOD:1)
Block(0,5,2,SPRUCE_FENCE:0)
Block(0,5,3,WALL_SIGN:3)
Block(0,6,1,LOG:5)
Block(0,8,-1,LOG:5)
Block(1,0,-5,WOOD:1)
Block(1,0,-4,LOG:1)
Block(1,0,1,LOG:1)
Block(1,1,-5,WOOD:1)
Block(1,1,-4,LOG:1)
Block(1,1,1,LOG:1)
Block(1,2,-4,LOG:1)
Block(1,2,1,LOG:1)
Block(1,3,-5,SPRUCE_FENCE:0)
Block(1,3,-4,LOG:1)
Block(1,3,-3,SPRUCE_FENCE:0)
Block(1,3,-2,AIR:0)
Block(1,3,1,LOG:1)
Block(1,3,2,SPRUCE_FENCE:0)
Block(1,4,-5,SPRUCE_FENCE:0)
Block(1,4,-4,LOG:1)
Block(1,4,-3,SPRUCE_FENCE:0)
RandomBlock(1,4,0,WALL_BANNER:2,../../NBT/Banners/viking_wealthy_1.nbt,20,WALL_BANNER:2,../../NBT/Banners/viking_wealthy_2.nbt,20,WALL_BANNER:2,../../NBT/Banners/viking_wealthy_3.nbt,20,WALL_BANNER:2,../../NBT/Banners/viking_wealthy_4.nbt,20,WALL_BANNER:2,../../NBT/Banners/viking_wealthy_5.nbt,20,WALL_BANNER:2,../../NBT/Banners/viking_wealthy_6.nbt,20,WALL_BANNER:2,../../NBT/Banners/viking_wealthy_7.nbt,20,WALL_BANNER:2,../../NBT/Banners/viking_wealthy_8.nbt,20,WALL_BANNER:2,../../NBT/Banners/viking_wealthy_9.nbt,100)
Block(1,4,1,LOG:1)
Block(1,4,2,SPRUCE_FENCE:0)
Block(1,5,-4,LOG:5)
Block(1,5,-3,SPRUCE_FENCE:0)
Block(1,5,-2,SPRUCE_FENCE:0)
Block(1,5,-1,SPRUCE_FENCE:0)
Block(1,5,0,SPRUCE_FENCE:0)
Block(1,5,1,LOG:1)
Block(1,5,2,SPRUCE_FENCE:0)
Block(1,5,3,WALL_SIGN:3)
Block(1,6,-3,LOG:9)
Block(1,6,-2,LOG:9)
Block(1,6,-1,LOG:9)
Block(1,6,0,LOG:9)
Block(1,6,1,LOG:5)
Block(1,8,-1,LOG:5)
Block(2,0,1,DIRT:1)
Block(2,0,2,DIRT:1)
Block(2,1,1,DIRT:1)
Block(2,1,2,DIRT:1)
Block(2,2,2,DIRT:1)
Block(2,3,-4,WOOD:1)
Block(2,3,1,WOOD:1)
Block(2,3,2,DARK_OAK_STAIRS:5)
Block(2,4,-4,WOOD:1)
RandomBlock(2,4,-3,WALL_BANNER:3,../../NBT/Banners/viking_wealthy_1.nbt,20,WALL_BANNER:3,../../NBT/Banners/viking_wealthy_2.nbt,20,WALL_BANNER:3,../../NBT/Banners/viking_wealthy_3.nbt,20,WALL_BANNER:3,../../NBT/Banners/viking_wealthy_4.nbt,20,WALL_BANNER:3,../../NBT/Banners/viking_wealthy_5.nbt,20,WALL_BANNER:3,../../NBT/Banners/viking_wealthy_6.nbt,20,WALL_BANNER:3,../../NBT/Banners/viking_wealthy_7.nbt,20,WALL_BANNER:3,../../NBT/Banners/viking_wealthy_8.nbt,20,WALL_BANNER:3,../../NBT/Banners/viking_wealthy_9.nbt,100)
Block(2,4,1,WOOD:1)
Block(2,4,2,CARPET:12)
Block(2,5,-4,LOG:5)
RandomBlock(2,5,0,WALL_BANNER:2,../../NBT/Banners/viking_regular_1.nbt,20,WALL_BANNER:2,../../NBT/Banners/viking_regular_2.nbt,20,WALL_BANNER:2,../../NBT/Banners/viking_regular_3.nbt,20,WALL_BANNER:2,../../NBT/Banners/viking_regular_4.nbt,20,WALL_BANNER:2,../../NBT/Banners/viking_regular_5.nbt,20,WALL_BANNER:2,../../NBT/Banners/viking_regular_6.nbt,20,WALL_BANNER:2,../../NBT/Banners/viking_regular_7.nbt,20,WALL_BANNER:2,../../NBT/Banners/viking_regular_8.nbt,100)
Block(2,5,1,WOOD:1)
Block(2,5,2,SPRUCE_FENCE:0)
Block(2,5,3,WALL_SIGN:3)
Block(2,6,1,LOG:5)
Block(2,8,-1,LOG:5)
Block(3,0,-1,MAGMA:0)
Block(3,0,1,DIRT:1)
Block(3,0,2,DIRT:1)
Block(3,0,5,DIRT:1)
Block(3,1,-1,MAGMA:0)
Block(3,1,1,DIRT:1)
Block(3,1,2,DIRT:1)
Block(3,1,5,DIRT:1)
Block(3,2,-1,IRON_TRAPDOOR:10)
Block(3,2,2,DIRT:1)
Block(3,2,5,DIRT:1)
Block(3,3,-4,WOOD:1)
Block(3,3,1,WOOD:1)
Block(3,3,2,WOOD_STEP:13)
Block(3,3,5,DARK_OAK_STAIRS:3)
Block(3,4,-4,WOOD:1)
RandomBlock(3,4,-3,WALL_BANNER:3,../../NBT/Banners/viking_wealthy_1.nbt,20,WALL_BANNER:3,../../NBT/Banners/viking_wealthy_2.nbt,20,WALL_BANNER:3,../../NBT/Banners/viking_wealthy_3.nbt,20,WALL_BANNER:3,../../NBT/Banners/viking_wealthy_4.nbt,20,WALL_BANNER:3,../../NBT/Banners/viking_wealthy_5.nbt,20,WALL_BANNER:3,../../NBT/Banners/viking_wealthy_6.nbt,20,WALL_BANNER:3,../../NBT/Banners/viking_wealthy_7.nbt,20,WALL_BANNER:3,../../NBT/Banners/viking_wealthy_8.nbt,20,WALL_BANNER:3,../../NBT/Banners/viking_wealthy_9.nbt,100)
Block(3,4,1,WOOD:1)
Block(3,4,2,CARPET:12)
RandomBlock(3,4,4,WALL_BANNER:2,../../NBT/Banners/viking_tannery_1.nbt,20,WALL_BANNER:2,../../NBT/Banners/viking_tannery_2.nbt,20,WALL_BANNER:2,../../NBT/Banners/viking_tannery_3.nbt,20,WALL_BANNER:2,../../NBT/Banners/viking_tannery_4.nbt,20,WALL_BANNER:2,../../NBT/Banners/viking_tannery_5.nbt,100)
Block(3,4,5,TRAP_DOOR:5)
Block(3,5,-4,LOG:5)
RandomBlock(3,5,-3,WALL_BANNER:3,../../NBT/Banners/viking_wealthy_1.nbt,20,WALL_BANNER:3,../../NBT/Banners/viking_wealthy_2.nbt,20,WALL_BANNER:3,../../NBT/Banners/viking_wealthy_3.nbt,20,WALL_BANNER:3,../../NBT/Banners/viking_wealthy_4.nbt,20,WALL_BANNER:3,../../NBT/Banners/viking_wealthy_5.nbt,20,WALL_BANNER:3,../../NBT/Banners/viking_wealthy_6.nbt,20,WALL_BANNER:3,../../NBT/Banners/viking_wealthy_7.nbt,20,WALL_BANNER:3,../../NBT/Banners/viking_wealthy_8.nbt,20,WALL_BANNER:3,../../NBT/Banners/viking_wealthy_9.nbt,100)
Block(3,5,1,WOOD:1)
Block(3,5,2,SPRUCE_FENCE:0)
Block(3,5,3,WALL_SIGN:3)
RandomBlock(3,6,0,WALL_BANNER:2,../../NBT/Banners/viking_regular_1.nbt,20,WALL_BANNER:2,../../NBT/Banners/viking_regular_2.nbt,20,WALL_BANNER:2,../../NBT/Banners/viking_regular_3.nbt,20,WALL_BANNER:2,../../NBT/Banners/viking_regular_4.nbt,20,WALL_BANNER:2,../../NBT/Banners/viking_regular_5.nbt,20,WALL_BANNER:2,../../NBT/Banners/viking_regular_6.nbt,20,WALL_BANNER:2,../../NBT/Banners/viking_regular_7.nbt,20,WALL_BANNER:2,../../NBT/Banners/viking_regular_8.nbt,100)
Block(3,6,1,LOG:5)
Block(3,8,-3,TRAP_DOOR:12)
Block(3,8,-1,LOG:5)
Block(3,8,1,TRAP_DOOR:13)
Block(4,0,-1,MAGMA:0)
Block(4,0,1,DIRT:1)
Block(4,0,2,DIRT:1)
Block(4,0,5,DIRT:1)
Block(4,1,-1,MAGMA:0)
Block(4,1,1,DIRT:1)
Block(4,1,2,DIRT:1)
Block(4,1,5,DIRT:1)
Block(4,2,-1,IRON_TRAPDOOR:10)
Block(4,2,2,DIRT:1)
Block(4,2,5,DIRT:1)
Block(4,3,-4,WOOD:1)
RandomBlock(4,3,-3,SKULL:1,../../../../Skulls/dungeon_skull_01.nbt,6,AIR,9,SKULL:1,../../../../Skulls/dungeon_skull_02.nbt,12,AIR,15,SKULL:1,../../../../Skulls/dungeon_skull_03.nbt,18,AIR,21,SKULL:1,../../../../Skulls/dungeon_skull_04.nbt,24,AIR,27,SKULL:1,../../../../Skulls/dungeon_skull_05.nbt,30,AIR,33,SKULL:1,../../../../Skulls/dungeon_skull_06.nbt,36,AIR,39,SKULL:1,../../../../Skulls/dungeon_skull_07.nbt,42,AIR,45,SKULL:1,../../../../Skulls/dungeon_skull_08.nbt,48,AIR,51,SKULL:1,../../../../Skulls/dungeon_skull_09.nbt,54,AIR,57,SKULL:1,../../../../Skulls/dungeon_skull_10.nbt,60,AIR,63,SKULL:1,../../../../Skulls/dungeon_skull_11.nbt,66,AIR,69,SKULL:1,../../../../Skulls/dungeon_skull_12.nbt,72,AIR,75,SKULL:1,../../../../Skulls/dungeon_skull_13.nbt,78,AIR,81,SKULL:1,../../../../Skulls/dungeon_skull_14.nbt,84,AIR,87,SKULL:1,../../../../Skulls/dungeon_skull_15.nbt,90,AIR,93,SKULL:1,../../../../Skulls/dungeon_skull_16.nbt,96,AIR,100)
Block(4,3,1,WOOD:1)
Block(4,3,2,DARK_OAK_STAIRS:4)
Block(4,3,5,TRAP_DOOR:5)
Block(4,4,-5,TRAP_DOOR:8)
Block(4,4,-4,DARK_OAK_FENCE:0)
Block(4,4,1,WOOD:1)
Block(4,4,2,CARPET:12)
RandomBlock(4,4,4,WALL_BANNER:2,../../NBT/Banners/viking_tannery_1.nbt,20,WALL_BANNER:2,../../NBT/Banners/viking_tannery_2.nbt,20,WALL_BANNER:2,../../NBT/Banners/viking_tannery_3.nbt,20,WALL_BANNER:2,../../NBT/Banners/viking_tannery_4.nbt,20,WALL_BANNER:2,../../NBT/Banners/viking_tannery_5.nbt,100)
Block(4,4,5,TRAP_DOOR:5)
Block(4,5,-4,LOG:5)
RandomBlock(4,5,-3,WALL_BANNER:3,../../NBT/Banners/viking_regular_1.nbt,20,WALL_BANNER:3,../../NBT/Banners/viking_regular_2.nbt,20,WALL_BANNER:3,../../NBT/Banners/viking_regular_3.nbt,20,WALL_BANNER:3,../../NBT/Banners/viking_regular_4.nbt,20,WALL_BANNER:3,../../NBT/Banners/viking_regular_5.nbt,20,WALL_BANNER:3,../../NBT/Banners/viking_regular_6.nbt,20,WALL_BANNER:3,../../NBT/Banners/viking_regular_7.nbt,20,WALL_BANNER:3,../../NBT/Banners/viking_regular_8.nbt,100)
RandomBlock(4,5,0,WALL_BANNER:2,../../NBT/Banners/viking_wealthy_1.nbt,20,WALL_BANNER:2,../../NBT/Banners/viking_wealthy_2.nbt,20,WALL_BANNER:2,../../NBT/Banners/viking_wealthy_3.nbt,20,WALL_BANNER:2,../../NBT/Banners/viking_wealthy_4.nbt,20,WALL_BANNER:2,../../NBT/Banners/viking_wealthy_5.nbt,20,WALL_BANNER:2,../../NBT/Banners/viking_wealthy_6.nbt,20,WALL_BANNER:2,../../NBT/Banners/viking_wealthy_7.nbt,20,WALL_BANNER:2,../../NBT/Banners/viking_wealthy_8.nbt,20,WALL_BANNER:2,../../NBT/Banners/viking_wealthy_9.nbt,100)
Block(4,5,1,WOOD:1)
Block(4,5,2,SPRUCE_FENCE:0)
Block(4,5,3,WALL_SIGN:3)
RandomBlock(4,6,0,WALL_BANNER:2,../../NBT/Banners/viking_regular_1.nbt,20,WALL_BANNER:2,../../NBT/Banners/viking_regular_2.nbt,20,WALL_BANNER:2,../../NBT/Banners/viking_regular_3.nbt,20,WALL_BANNER:2,../../NBT/Banners/viking_regular_4.nbt,20,WALL_BANNER:2,../../NBT/Banners/viking_regular_5.nbt,20,WALL_BANNER:2,../../NBT/Banners/viking_regular_6.nbt,20,WALL_BANNER:2,../../NBT/Banners/viking_regular_7.nbt,20,WALL_BANNER:2,../../NBT/Banners/viking_regular_8.nbt,100)
Block(4,6,1,LOG:5)
Block(4,8,-3,TRAP_DOOR:12)
Block(4,8,-1,LOG:5)
Block(4,8,1,TRAP_DOOR:13)
Block(5,0,1,DIRT:1)
Block(5,0,5,DIRT:1)
Block(5,1,1,DIRT:1)
Block(5,1,5,DIRT:1)
Block(5,2,5,DIRT:1)
Block(5,3,-4,WOOD:1)
Block(5,3,1,WOOD:1)
Block(5,3,5,DARK_OAK_STAIRS:3)
Block(5,4,-4,WOOD:1)
RandomBlock(5,4,-3,WALL_BANNER:3,../../NBT/Banners/viking_regular_1.nbt,20,WALL_BANNER:3,../../NBT/Banners/viking_regular_2.nbt,20,WALL_BANNER:3,../../NBT/Banners/viking_regular_3.nbt,20,WALL_BANNER:3,../../NBT/Banners/viking_regular_4.nbt,20,WALL_BANNER:3,../../NBT/Banners/viking_regular_5.nbt,20,WALL_BANNER:3,../../NBT/Banners/viking_regular_6.nbt,20,WALL_BANNER:3,../../NBT/Banners/viking_regular_7.nbt,20,WALL_BANNER:3,../../NBT/Banners/viking_regular_8.nbt,100)
RandomBlock(5,4,-2,WALL_BANNER:4,../../NBT/Banners/viking_wealthy_1.nbt,20,WALL_BANNER:4,../../NBT/Banners/viking_wealthy_2.nbt,20,WALL_BANNER:4,../../NBT/Banners/viking_wealthy_3.nbt,20,WALL_BANNER:4,../../NBT/Banners/viking_wealthy_4.nbt,20,WALL_BANNER:4,../../NBT/Banners/viking_wealthy_5.nbt,20,WALL_BANNER:4,../../NBT/Banners/viking_wealthy_6.nbt,20,WALL_BANNER:4,../../NBT/Banners/viking_wealthy_7.nbt,20,WALL_BANNER:4,../../NBT/Banners/viking_wealthy_8.nbt,20,WALL_BANNER:4,../../NBT/Banners/viking_wealthy_9.nbt,100)
Block(5,4,1,WOOD:1)
RandomBlock(5,4,2,WALL_BANNER:3,../../NBT/Banners/viking_regular_1.nbt,20,WALL_BANNER:3,../../NBT/Banners/viking_regular_2.nbt,20,WALL_BANNER:3,../../NBT/Banners/viking_regular_3.nbt,20,WALL_BANNER:3,../../NBT/Banners/viking_regular_4.nbt,20,WALL_BANNER:3,../../NBT/Banners/viking_regular_5.nbt,20,WALL_BANNER:3,../../NBT/Banners/viking_regular_6.nbt,20,WALL_BANNER:3,../../NBT/Banners/viking_regular_7.nbt,20,WALL_BANNER:3,../../NBT/Banners/viking_regular_8.nbt,100)
RandomBlock(5,4,4,WALL_BANNER:2,../../NBT/Banners/viking_tannery_1.nbt,20,WALL_BANNER:2,../../NBT/Banners/viking_tannery_2.nbt,20,WALL_BANNER:2,../../NBT/Banners/viking_tannery_3.nbt,20,WALL_BANNER:2,../../NBT/Banners/viking_tannery_4.nbt,20,WALL_BANNER:2,../../NBT/Banners/viking_tannery_5.nbt,100)
Block(5,4,5,TRAP_DOOR:5)
Block(5,5,-4,LOG:5)
RandomBlock(5,5,-2,WALL_BANNER:4,../../NBT/Banners/viking_regular_1.nbt,20,WALL_BANNER:4,../../NBT/Banners/viking_regular_2.nbt,20,WALL_BANNER:4,../../NBT/Banners/viking_regular_3.nbt,20,WALL_BANNER:4,../../NBT/Banners/viking_regular_4.nbt,20,WALL_BANNER:4,../../NBT/Banners/viking_regular_5.nbt,20,WALL_BANNER:4,../../NBT/Banners/viking_regular_6.nbt,20,WALL_BANNER:4,../../NBT/Banners/viking_regular_7.nbt,20,WALL_BANNER:4,../../NBT/Banners/viking_regular_8.nbt,100)
RandomBlock(5,5,-1,WALL_BANNER:4,../../NBT/Banners/viking_regular_1.nbt,20,WALL_BANNER:4,../../NBT/Banners/viking_regular_2.nbt,20,WALL_BANNER:4,../../NBT/Banners/viking_regular_3.nbt,20,WALL_BANNER:4,../../NBT/Banners/viking_regular_4.nbt,20,WALL_BANNER:4,../../NBT/Banners/viking_regular_5.nbt,20,WALL_BANNER:4,../../NBT/Banners/viking_regular_6.nbt,20,WALL_BANNER:4,../../NBT/Banners/viking_regular_7.nbt,20,WALL_BANNER:4,../../NBT/Banners/viking_regular_8.nbt,100)
RandomBlock(5,5,0,WALL_BANNER:2,../../NBT/Banners/viking_wealthy_1.nbt,20,WALL_BANNER:2,../../NBT/Banners/viking_wealthy_2.nbt,20,WALL_BANNER:2,../../NBT/Banners/viking_wealthy_3.nbt,20,WALL_BANNER:2,../../NBT/Banners/viking_wealthy_4.nbt,20,WALL_BANNER:2,../../NBT/Banners/viking_wealthy_5.nbt,20,WALL_BANNER:2,../../NBT/Banners/viking_wealthy_6.nbt,20,WALL_BANNER:2,../../NBT/Banners/viking_wealthy_7.nbt,20,WALL_BANNER:2,../../NBT/Banners/viking_wealthy_8.nbt,20,WALL_BANNER:2,../../NBT/Banners/viking_wealthy_9.nbt,100)
Block(5,5,1,WOOD:1)
Block(5,5,2,SPRUCE_FENCE:0)
Block(5,5,3,WALL_SIGN:3)
RandomBlock(5,6,0,WALL_BANNER:4,../../NBT/Banners/viking_regular_1.nbt,20,WALL_BANNER:4,../../NBT/Banners/viking_regular_2.nbt,20,WALL_BANNER:4,../../NBT/Banners/viking_regular_3.nbt,20,WALL_BANNER:4,../../NBT/Banners/viking_regular_4.nbt,20,WALL_BANNER:4,../../NBT/Banners/viking_regular_5.nbt,20,WALL_BANNER:4,../../NBT/Banners/viking_regular_6.nbt,20,WALL_BANNER:4,../../NBT/Banners/viking_regular_7.nbt,20,WALL_BANNER:4,../../NBT/Banners/viking_regular_8.nbt,100)
Block(5,6,1,LOG:5)
Block(5,8,-1,LOG:5)
Block(6,0,-5,WOOD:1)
Block(6,0,-4,LOG:1)
Block(6,0,1,LOG:1)
Block(6,1,-5,WOOD:1)
Block(6,1,-4,LOG:1)
Block(6,1,1,LOG:1)
Block(6,2,-4,LOG:1)
Block(6,2,1,LOG:1)
Block(6,3,-5,SPRUCE_FENCE:0)
Block(6,3,-4,LOG:1)
Block(6,3,-3,WOOD:1)
Block(6,3,-2,WOOD:1)
Block(6,3,-1,WOOD:1)
Block(6,3,0,WOOD:1)
Block(6,3,1,LOG:1)
Block(6,3,2,SPRUCE_FENCE:0)
Block(6,4,-5,SPRUCE_FENCE:0)
Block(6,4,-4,LOG:1)
Block(6,4,-3,WOOD:1)
Block(6,4,-2,WOOD:1)
Block(6,4,-1,WOOD:1)
Block(6,4,0,WOOD:1)
Block(6,4,1,LOG:1)
Block(6,4,2,SPRUCE_FENCE:0)
Block(6,5,-4,LOG:1)
Block(6,5,-3,WOOD:1)
Block(6,5,-2,WOOD:1)
Block(6,5,-1,WOOD:1)
Block(6,5,0,WOOD:1)
Block(6,5,1,LOG:1)
Block(6,5,2,SPRUCE_FENCE:0)
Block(6,5,3,WALL_SIGN:3)
Block(6,6,-3,WOOD:1)
Block(6,6,-2,WOOD:1)
Block(6,6,-1,WOOD:1)
Block(6,6,0,WOOD:1)
Block(6,6,1,LOG:1)
Block(6,7,-2,WOOD:1)
Block(6,7,-1,WOOD:1)
Block(6,7,0,WOOD:1)
Block(6,8,-1,LOG:5)
Block(7,5,1,WALL_SIGN:5)
Block(7,5,2,WALL_SIGN:5)
Block(7,8,-1,LOG:5)
Block(8,8,-1,WOOD_BUTTON:1)



Block(-6,4,3,SPRUCE_WOOD_STAIRS:6)
Block(-6,4,4,SPRUCE_WOOD_STAIRS:3)
Block(-6,5,-5,SPRUCE_WOOD_STAIRS:2)
Block(-6,5,-4,SPRUCE_WOOD_STAIRS:7)
Block(-6,5,2,SPRUCE_WOOD_STAIRS:6)
Block(-6,5,3,SPRUCE_WOOD_STAIRS:3)
Block(-6,6,-4,SPRUCE_WOOD_STAIRS:2)
Block(-6,6,-3,SPRUCE_WOOD_STAIRS:7)
Block(-6,6,1,SPRUCE_WOOD_STAIRS:6)
Block(-6,6,2,SPRUCE_WOOD_STAIRS:3)
Block(-6,7,-3,SPRUCE_WOOD_STAIRS:2)
Block(-6,7,-2,SPRUCE_WOOD_STAIRS:7)
Block(-6,7,0,SPRUCE_WOOD_STAIRS:6)
Block(-6,7,1,SPRUCE_WOOD_STAIRS:3)
Block(-6,8,-2,SPRUCE_WOOD_STAIRS:2)
Block(-6,8,0,SPRUCE_WOOD_STAIRS:3)
Block(-6,9,-2,SPRUCE_WOOD_STAIRS:6)
Block(-6,9,0,SPRUCE_WOOD_STAIRS:7)
Block(-5,2,-5,COBBLESTONE:0)
Block(-5,2,-3,COBBLESTONE:0)
Block(-5,2,-2,COBBLESTONE:0)
Block(-5,2,-1,COBBLESTONE:0)
Block(-5,2,0,COBBLESTONE:0)
Block(-5,2,2,COBBLESTONE:0)
Block(-5,4,4,SPRUCE_WOOD_STAIRS:3)
Block(-5,5,-5,SPRUCE_WOOD_STAIRS:2)
Block(-5,5,3,SPRUCE_WOOD_STAIRS:3)
Block(-5,6,-4,SPRUCE_WOOD_STAIRS:2)
Block(-5,6,2,SPRUCE_WOOD_STAIRS:3)
Block(-5,7,-3,SPRUCE_WOOD_STAIRS:2)
Block(-5,7,1,SPRUCE_WOOD_STAIRS:3)
Block(-5,8,-2,SPRUCE_WOOD_STAIRS:2)
Block(-5,8,0,SPRUCE_WOOD_STAIRS:3)
Block(-4,2,-4,COBBLESTONE:0)
Block(-4,2,3,COBBLESTONE:0)
Block(-4,4,4,SPRUCE_WOOD_STAIRS:3)
Block(-4,5,-5,SPRUCE_WOOD_STAIRS:2)
Block(-4,5,3,SPRUCE_WOOD_STAIRS:3)
Block(-4,6,-4,SPRUCE_WOOD_STAIRS:2)
Block(-4,6,-3,SPRUCE_WOOD_STAIRS:7)
Block(-4,6,2,SPRUCE_WOOD_STAIRS:3)
Block(-4,7,-3,SPRUCE_WOOD_STAIRS:2)
Block(-4,7,-2,SPRUCE_WOOD_STAIRS:7)
Block(-4,7,0,SPRUCE_WOOD_STAIRS:6)
Block(-4,7,1,SPRUCE_WOOD_STAIRS:3)
Block(-4,8,-2,SPRUCE_WOOD_STAIRS:2)
Block(-4,8,0,SPRUCE_WOOD_STAIRS:3)
Block(-3,2,-4,COBBLESTONE:0)
Block(-3,2,3,COBBLESTONE:0)
Block(-3,4,4,SPRUCE_WOOD_STAIRS:3)
Block(-3,5,-5,SPRUCE_WOOD_STAIRS:2)
Block(-3,5,3,SPRUCE_WOOD_STAIRS:3)
Block(-3,6,-4,SPRUCE_WOOD_STAIRS:2)
Block(-3,6,-3,SPRUCE_WOOD_STAIRS:7)
Block(-3,6,2,SPRUCE_WOOD_STAIRS:3)
Block(-3,7,-3,SPRUCE_WOOD_STAIRS:2)
Block(-3,7,-2,SPRUCE_WOOD_STAIRS:7)
Block(-3,7,0,SPRUCE_WOOD_STAIRS:6)
Block(-3,7,1,SPRUCE_WOOD_STAIRS:3)
Block(-3,8,-2,SPRUCE_WOOD_STAIRS:2)
Block(-3,8,0,SPRUCE_WOOD_STAIRS:3)
Block(-2,2,-5,COBBLESTONE:0)
Block(-2,2,2,COBBLESTONE:0)
Block(-2,4,4,SPRUCE_WOOD_STAIRS:3)
Block(-2,5,-5,SPRUCE_WOOD_STAIRS:2)
Block(-2,5,3,SPRUCE_WOOD_STAIRS:3)
Block(-2,6,-4,SPRUCE_WOOD_STAIRS:2)
Block(-2,6,2,SPRUCE_WOOD_STAIRS:3)
Block(-2,7,-3,SPRUCE_WOOD_STAIRS:2)
Block(-2,7,-2,SPRUCE_WOOD_STAIRS:7)
Block(-2,7,0,SPRUCE_WOOD_STAIRS:6)
Block(-2,7,1,SPRUCE_WOOD_STAIRS:3)
Block(-2,8,-2,SPRUCE_WOOD_STAIRS:2)
Block(-2,8,0,SPRUCE_WOOD_STAIRS:3)
Block(-1,2,-4,COBBLESTONE:0)
Block(-1,2,1,COBBLESTONE:0)
Block(-1,4,3,SPRUCE_WOOD_STAIRS:6)
Block(-1,4,4,SPRUCE_WOOD_STAIRS:3)
Block(-1,5,-5,SPRUCE_WOOD_STAIRS:2)
Block(-1,5,2,SPRUCE_WOOD_STAIRS:6)
Block(-1,5,3,SPRUCE_WOOD_STAIRS:3)
Block(-1,6,-4,SPRUCE_WOOD_STAIRS:2)
Block(-1,6,-3,SPRUCE_WOOD_STAIRS:7)
Block(-1,6,2,SPRUCE_WOOD_STAIRS:3)
Block(-1,7,-3,SPRUCE_WOOD_STAIRS:2)
Block(-1,7,-2,SPRUCE_WOOD_STAIRS:7)
Block(-1,7,0,SPRUCE_WOOD_STAIRS:6)
Block(-1,7,1,SPRUCE_WOOD_STAIRS:3)
Block(-1,8,-2,SPRUCE_WOOD_STAIRS:2)
Block(-1,8,0,SPRUCE_WOOD_STAIRS:3)
Block(0,2,-4,COBBLESTONE:0)
Block(0,2,1,COBBLESTONE:0)
Block(0,5,-5,SPRUCE_WOOD_STAIRS:2)
Block(0,6,-4,SPRUCE_WOOD_STAIRS:2)
Block(0,6,-3,SPRUCE_WOOD_STAIRS:7)
Block(0,6,2,SPRUCE_WOOD_STAIRS:3)
Block(0,7,-3,SPRUCE_WOOD_STAIRS:2)
Block(0,7,-2,SPRUCE_WOOD_STAIRS:7)
Block(0,7,0,SPRUCE_WOOD_STAIRS:6)
Block(0,7,1,SPRUCE_WOOD_STAIRS:3)
Block(0,8,-2,SPRUCE_WOOD_STAIRS:2)
Block(0,8,0,SPRUCE_WOOD_STAIRS:3)
Block(1,0,2,COBBLESTONE:0)
Block(1,1,2,COBBLESTONE:0)
Block(1,2,-5,COBBLESTONE:0)
Block(1,2,2,COBBLESTONE:0)
Block(1,5,-5,SPRUCE_WOOD_STAIRS:2)
Block(1,6,-4,SPRUCE_WOOD_STAIRS:2)
Block(1,6,2,SPRUCE_WOOD_STAIRS:3)
Block(1,7,-3,SPRUCE_WOOD_STAIRS:2)
Block(1,7,-2,SPRUCE_WOOD_STAIRS:7)
Block(1,7,0,SPRUCE_WOOD_STAIRS:6)
Block(1,7,1,SPRUCE_WOOD_STAIRS:3)
Block(1,8,-2,SPRUCE_WOOD_STAIRS:2)
Block(1,8,0,SPRUCE_WOOD_STAIRS:3)
Block(2,0,-2,COBBLESTONE:0)
Block(2,0,-1,COBBLESTONE:0)
Block(2,0,0,COBBLESTONE:0)
Block(2,1,-2,COBBLESTONE:0)
Block(2,1,-1,COBBLESTONE:0)
Block(2,1,0,COBBLESTONE:0)
Block(2,2,-4,COBBLESTONE:0)
Block(2,2,-2,COBBLESTONE_STAIRS:1)
Block(2,2,-1,COBBLESTONE:0)
Block(2,2,0,COBBLESTONE_STAIRS:2)
Block(2,2,1,COBBLESTONE:0)
Block(2,5,-5,SPRUCE_WOOD_STAIRS:2)
Block(2,6,-4,SPRUCE_WOOD_STAIRS:2)
Block(2,6,-3,SPRUCE_WOOD_STAIRS:7)
Block(2,6,2,SPRUCE_WOOD_STAIRS:3)
Block(2,7,-3,SPRUCE_WOOD_STAIRS:2)
Block(2,7,-2,SPRUCE_WOOD_STAIRS:7)
Block(2,7,0,SPRUCE_WOOD_STAIRS:6)
Block(2,7,1,SPRUCE_WOOD_STAIRS:3)
Block(2,8,-2,SPRUCE_WOOD_STAIRS:2)
Block(2,8,0,SPRUCE_WOOD_STAIRS:3)
Block(3,0,-2,COBBLESTONE:0)
Block(3,0,0,COBBLESTONE:0)
Block(3,1,-2,COBBLESTONE:0)
Block(3,1,0,COBBLESTONE:0)
Block(3,2,-4,COBBLESTONE:0)
Block(3,2,-2,COBBLESTONE_STAIRS:3)
Block(3,2,0,COBBLESTONE_STAIRS:2)
Block(3,2,1,COBBLESTONE:0)
Block(3,5,-5,SPRUCE_WOOD_STAIRS:2)
Block(3,6,-4,SPRUCE_WOOD_STAIRS:2)
Block(3,6,-3,SPRUCE_WOOD_STAIRS:7)
Block(3,6,2,SPRUCE_WOOD_STAIRS:3)
Block(3,7,-3,SPRUCE_WOOD_STAIRS:2)
Block(3,7,1,SPRUCE_WOOD_STAIRS:3)
Block(4,0,-2,COBBLESTONE:0)
Block(4,0,0,COBBLESTONE:0)
Block(4,1,-2,COBBLESTONE:0)
Block(4,1,0,COBBLESTONE:0)
Block(4,2,-4,COBBLESTONE:0)
Block(4,2,-2,COBBLESTONE_STAIRS:3)
Block(4,2,0,COBBLESTONE_STAIRS:2)
Block(4,2,1,COBBLESTONE:0)
Block(4,5,-5,SPRUCE_WOOD_STAIRS:2)
Block(4,6,-4,SPRUCE_WOOD_STAIRS:2)
Block(4,6,-3,SPRUCE_WOOD_STAIRS:7)
Block(4,6,2,SPRUCE_WOOD_STAIRS:3)
Block(4,7,-3,SPRUCE_WOOD_STAIRS:2)
Block(4,7,1,SPRUCE_WOOD_STAIRS:3)
Block(5,0,-2,COBBLESTONE:0)
Block(5,0,-1,COBBLESTONE:0)
Block(5,0,0,COBBLESTONE:0)
Block(5,1,-2,COBBLESTONE:0)
Block(5,1,-1,COBBLESTONE:0)
Block(5,1,0,COBBLESTONE:0)
Block(5,2,-4,COBBLESTONE:0)
Block(5,2,-2,COBBLESTONE_STAIRS:3)
Block(5,2,-1,COBBLESTONE:0)
Block(5,2,0,COBBLESTONE_STAIRS:2)
Block(5,2,1,COBBLESTONE:0)
Block(5,5,-5,SPRUCE_WOOD_STAIRS:2)
Block(5,6,-4,SPRUCE_WOOD_STAIRS:2)
Block(5,6,-3,SPRUCE_WOOD_STAIRS:7)
Block(5,6,2,SPRUCE_WOOD_STAIRS:3)
Block(5,7,-3,SPRUCE_WOOD_STAIRS:2)
Block(5,7,-2,SPRUCE_WOOD_STAIRS:7)
Block(5,7,0,SPRUCE_WOOD_STAIRS:6)
Block(5,7,1,SPRUCE_WOOD_STAIRS:3)
Block(5,8,-2,SPRUCE_WOOD_STAIRS:2)
Block(5,8,0,SPRUCE_WOOD_STAIRS:3)
Block(6,0,2,COBBLESTONE:0)
Block(6,1,2,COBBLESTONE:0)
Block(6,2,-5,COBBLESTONE:0)
Block(6,2,-3,COBBLESTONE:0)
Block(6,2,-2,COBBLESTONE:0)
Block(6,2,-1,COBBLESTONE:0)
Block(6,2,0,COBBLESTONE:0)
Block(6,2,2,COBBLESTONE:0)
Block(6,5,-5,SPRUCE_WOOD_STAIRS:2)
Block(6,6,-4,SPRUCE_WOOD_STAIRS:2)
Block(6,6,2,SPRUCE_WOOD_STAIRS:3)
Block(6,7,-3,SPRUCE_WOOD_STAIRS:2)
Block(6,7,1,SPRUCE_WOOD_STAIRS:3)
Block(6,8,-2,SPRUCE_WOOD_STAIRS:2)
Block(6,8,0,SPRUCE_WOOD_STAIRS:3)
Block(7,5,-5,SPRUCE_WOOD_STAIRS:2)
Block(7,5,-4,SPRUCE_WOOD_STAIRS:7)
Block(7,6,-4,SPRUCE_WOOD_STAIRS:2)
Block(7,6,-3,SPRUCE_WOOD_STAIRS:7)
Block(7,6,1,SPRUCE_WOOD_STAIRS:6)
Block(7,6,2,SPRUCE_WOOD_STAIRS:3)
Block(7,7,-3,SPRUCE_WOOD_STAIRS:2)
Block(7,7,-2,SPRUCE_WOOD_STAIRS:7)
Block(7,7,0,SPRUCE_WOOD_STAIRS:6)
Block(7,7,1,SPRUCE_WOOD_STAIRS:3)
Block(7,8,-2,SPRUCE_WOOD_STAIRS:2)
Block(7,8,0,SPRUCE_WOOD_STAIRS:3)
Block(7,9,-2,SPRUCE_WOOD_STAIRS:6)
Block(7,9,0,SPRUCE_WOOD_STAIRS:7)

Block(-6,9,-1,WOOD_STEP:1)
Block(-4,2,-3,WOOD_STEP:9)
Block(-4,2,-2,WOOD_STEP:9)
Block(-4,2,-1,WOOD_STEP:9)
Block(-4,2,0,WOOD_STEP:9)
Block(-4,2,1,WOOD_STEP:9)
Block(-4,2,2,WOOD_STEP:9)
Block(-3,2,-3,WOOD_STEP:9)
Block(-3,2,-2,WOOD_STEP:9)
Block(-3,2,-1,WOOD_STEP:9)
Block(-3,2,0,WOOD_STEP:9)
Block(-3,2,1,WOOD_STEP:9)
Block(-3,2,2,WOOD_STEP:9)
Block(-2,2,-3,WOOD_STEP:9)
Block(-2,2,-2,WOOD_STEP:9)
Block(-2,2,-1,WOOD_STEP:9)
Block(-2,2,0,WOOD_STEP:9)
Block(-1,2,-3,WOOD_STEP:9)
Block(-1,2,-2,WOOD_STEP:9)
Block(-1,2,-1,WOOD_STEP:9)
Block(-1,2,0,WOOD_STEP:9)
Block(0,2,-3,WOOD_STEP:9)
Block(0,2,-2,WOOD_STEP:9)
Block(0,2,-1,WOOD_STEP:9)
Block(0,2,0,WOOD_STEP:9)
Block(1,2,-3,WOOD_STEP:9)
Block(1,2,-2,WOOD_STEP:9)
Block(1,2,-1,WOOD_STEP:9)
Block(1,2,0,WOOD_STEP:9)
Block(2,2,-3,WOOD_STEP:9)
Block(3,2,-3,WOOD_STEP:9)
Block(3,8,-2,WOOD_STEP:9)
Block(3,8,0,WOOD_STEP:9)
Block(3,9,-1,WOOD_STEP:1)
Block(4,2,-3,WOOD_STEP:9)
Block(4,8,-2,WOOD_STEP:9)
Block(4,8,0,WOOD_STEP:9)
Block(4,9,-1,WOOD_STEP:1)
Block(5,2,-3,WOOD_STEP:9)
Block(7,9,-1,WOOD_STEP:1)

Entity(1,3,-2,minecraft:villager,1)