Author: NLBlackEagle
Description: No description given
SettingsMode: WriteDisable
Frequency: 10
SpawnHeight: highestBlock
UseCenterForHighestBlock: true
MinHeight: 63
MaxHeight: 255
InheritBO3: 
InheritBO3Rotation: NORTH
OverrideChildSettings: true
OverrideParentHeight: false
CanOverride: true
BranchFrequency: 5
BranchFrequencyGroup: 
MustBeBelowOther: false
MustBeInside: 
CannotBeInside: 
ReplacesBO3: 
MustBeInsideWorldBorders: false
CanSpawnOnWater: false
SpawnOnWaterOnly: false
SpawnUnderWater: false
SpawnAtWaterLevel: false
HeightOffset: -2
RemoveAir: false
ReplaceAbove: 
ReplaceBelow: cobblestone
ReplaceWithBiomeBlocks: true
ReplaceWithSurfaceBlock: GRASS
ReplaceWithGroundBlock: DIRT
ReplaceWithStoneBlock: STONE
SmoothRadius: 0
SmoothHeightOffset: 0
SmoothStartTop: false
SmoothStartWood: false
SmoothingSurfaceBlock: 
SmoothingGroundBlock: 
BO3Group: 
IsSpawnPoint: false
DoReplaceBlocks: true
Block(-4,0,-3,LOG:1)
Block(-4,0,6,LOG:1)
Block(-4,1,-3,LOG:1)
Block(-4,1,6,LOG:1)
Block(-4,2,-3,LOG:1)
Block(-4,2,6,LOG:1)
Block(-4,3,-3,LOG:1)
Block(-4,3,-2,LOG:9)
Block(-4,3,-1,LOG:9)
Block(-4,3,0,LOG:9)
Block(-4,3,1,LOG:9)
Block(-4,3,2,LOG:9)
Block(-4,3,3,LOG:9)
Block(-4,3,4,LOG:9)
Block(-4,3,5,LOG:9)
Block(-4,3,6,LOG:1)
Block(-4,4,-3,LOG:1)
Block(-4,4,-2,WOOD:1)
Block(-4,4,-1,WOOD:1)
Block(-4,4,0,WOOD:1)
Block(-4,4,1,WOOD:1)
Block(-4,4,2,WOOD:1)
Block(-4,4,3,WOOD:1)
Block(-4,4,4,WOOD:1)
Block(-4,4,5,WOOD:1)
Block(-4,4,6,LOG:1)
Block(-3,3,-3,LOG:5)
Block(-3,3,4,FLOWER_POT:0)
Block(-3,3,5,FLOWER_POT:0)
Block(-3,3,6,LOG:5)
RandomBlock(-3,4,-1,WALL_BANNER:5,../../NBT/Banners/viking_tannery_1.nbt,20,WALL_BANNER:5,../../NBT/Banners/viking_tannery_2.nbt,20,WALL_BANNER:5,../../NBT/Banners/viking_tannery_3.nbt,20,WALL_BANNER:5,../../NBT/Banners/viking_tannery_4.nbt,20,WALL_BANNER:5,../../NBT/Banners/viking_tannery_5.nbt,100)
RandomBlock(-3,4,0,WALL_BANNER:5,../../NBT/Banners/viking_regular_1.nbt,20,WALL_BANNER:5,../../NBT/Banners/viking_regular_2.nbt,20,WALL_BANNER:5,../../NBT/Banners/viking_regular_3.nbt,20,WALL_BANNER:5,../../NBT/Banners/viking_regular_4.nbt,20,WALL_BANNER:5,../../NBT/Banners/viking_regular_5.nbt,20,WALL_BANNER:5,../../NBT/Banners/viking_regular_6.nbt,20,WALL_BANNER:5,../../NBT/Banners/viking_regular_7.nbt,20,WALL_BANNER:5,../../NBT/Banners/viking_regular_8.nbt,100)
RandomBlock(-3,4,1,WALL_BANNER:5,../../NBT/Banners/viking_regular_1.nbt,20,WALL_BANNER:5,../../NBT/Banners/viking_regular_2.nbt,20,WALL_BANNER:5,../../NBT/Banners/viking_regular_3.nbt,20,WALL_BANNER:5,../../NBT/Banners/viking_regular_4.nbt,20,WALL_BANNER:5,../../NBT/Banners/viking_regular_5.nbt,20,WALL_BANNER:5,../../NBT/Banners/viking_regular_6.nbt,20,WALL_BANNER:5,../../NBT/Banners/viking_regular_7.nbt,20,WALL_BANNER:5,../../NBT/Banners/viking_regular_8.nbt,100)
RandomBlock(-3,4,2,WALL_BANNER:5,../../NBT/Banners/viking_tannery_1.nbt,20,WALL_BANNER:5,../../NBT/Banners/viking_tannery_2.nbt,20,WALL_BANNER:5,../../NBT/Banners/viking_tannery_3.nbt,20,WALL_BANNER:5,../../NBT/Banners/viking_tannery_4.nbt,20,WALL_BANNER:5,../../NBT/Banners/viking_tannery_5.nbt,100)
RandomBlock(-3,4,3,WALL_BANNER:5,../../NBT/Banners/viking_tannery_1.nbt,20,WALL_BANNER:5,../../NBT/Banners/viking_tannery_2.nbt,20,WALL_BANNER:5,../../NBT/Banners/viking_tannery_3.nbt,20,WALL_BANNER:5,../../NBT/Banners/viking_tannery_4.nbt,20,WALL_BANNER:5,../../NBT/Banners/viking_tannery_5.nbt,100)
RandomBlock(-3,4,5,WALL_BANNER:2,../../NBT/Banners/viking_tannery_1.nbt,20,WALL_BANNER:2,../../NBT/Banners/viking_tannery_2.nbt,20,WALL_BANNER:2,../../NBT/Banners/viking_tannery_3.nbt,20,WALL_BANNER:2,../../NBT/Banners/viking_tannery_4.nbt,20,WALL_BANNER:2,../../NBT/Banners/viking_tannery_5.nbt,100)
Block(-3,5,-3,WOOD:1)
Block(-3,5,6,WOOD:1)
Block(-2,3,-3,LOG:5)
Block(-2,3,-1,FLOWER_POT:0)
Block(-2,3,5,FLOWER_POT:0)
Block(-2,3,6,LOG:5)
Block(-2,5,-3,WOOD:1)
Block(-2,5,6,WOOD:1)
Block(-2,6,-3,DARK_OAK_FENCE:0)
Block(-2,6,-2,HAY_BLOCK:0)
Block(-2,6,-1,HAY_BLOCK:0)
Block(-2,6,0,HAY_BLOCK:0)
Block(-2,6,1,HAY_BLOCK:0)
Block(-2,6,3,HAY_BLOCK:0)
Block(-2,6,4,HAY_BLOCK:0)
Block(-2,6,5,HAY_BLOCK:0)
Block(-2,6,6,DARK_OAK_FENCE:0)
Block(-1,3,-3,LOG:5)
Block(-1,3,6,LOG:5)
RandomBlock(-1,4,5,WALL_BANNER:2,../../NBT/Banners/viking_tannery_1.nbt,20,WALL_BANNER:2,../../NBT/Banners/viking_tannery_2.nbt,20,WALL_BANNER:2,../../NBT/Banners/viking_tannery_3.nbt,20,WALL_BANNER:2,../../NBT/Banners/viking_tannery_4.nbt,20,WALL_BANNER:2,../../NBT/Banners/viking_tannery_5.nbt,100)
Block(-1,5,-3,WOOD:1)
Block(-1,5,6,WOOD:1)
Block(-1,6,-3,WOOD:1)
Block(-1,6,-2,HAY_BLOCK:0)
Block(-1,6,1,HAY_BLOCK:0)
Block(-1,6,2,HAY_BLOCK:0)
Block(-1,6,4,HAY_BLOCK:4)
Block(-1,6,5,HAY_BLOCK:4)
Block(-1,6,6,WOOD:1)
Block(-1,7,-3,DARK_OAK_FENCE:0)
Block(-1,7,5,HAY_BLOCK:4)
Block(-1,7,6,DARK_OAK_FENCE:0)
Block(0,3,-3,LOG:5)
Block(0,3,6,LOG:5)
Block(0,5,-3,WOOD:1)
RandomBlock(0,5,-2,WALL_BANNER:5,../../NBT/Banners/viking_regular_1.nbt,20,WALL_BANNER:5,../../NBT/Banners/viking_regular_2.nbt,20,WALL_BANNER:5,../../NBT/Banners/viking_regular_3.nbt,20,WALL_BANNER:5,../../NBT/Banners/viking_regular_4.nbt,20,WALL_BANNER:5,../../NBT/Banners/viking_regular_5.nbt,20,WALL_BANNER:5,../../NBT/Banners/viking_regular_6.nbt,20,WALL_BANNER:5,../../NBT/Banners/viking_regular_7.nbt,20,WALL_BANNER:5,../../NBT/Banners/viking_regular_8.nbt,100)
RandomBlock(0,5,-1,WALL_BANNER:5,../../NBT/Banners/viking_regular_1.nbt,20,WALL_BANNER:5,../../NBT/Banners/viking_regular_2.nbt,20,WALL_BANNER:5,../../NBT/Banners/viking_regular_3.nbt,20,WALL_BANNER:5,../../NBT/Banners/viking_regular_4.nbt,20,WALL_BANNER:5,../../NBT/Banners/viking_regular_5.nbt,20,WALL_BANNER:5,../../NBT/Banners/viking_regular_6.nbt,20,WALL_BANNER:5,../../NBT/Banners/viking_regular_7.nbt,20,WALL_BANNER:5,../../NBT/Banners/viking_regular_8.nbt,100)
RandomBlock(0,5,0,WALL_BANNER:5,../../NBT/Banners/viking_regular_1.nbt,20,WALL_BANNER:5,../../NBT/Banners/viking_regular_2.nbt,20,WALL_BANNER:5,../../NBT/Banners/viking_regular_3.nbt,20,WALL_BANNER:5,../../NBT/Banners/viking_regular_4.nbt,20,WALL_BANNER:5,../../NBT/Banners/viking_regular_5.nbt,20,WALL_BANNER:5,../../NBT/Banners/viking_regular_6.nbt,20,WALL_BANNER:5,../../NBT/Banners/viking_regular_7.nbt,20,WALL_BANNER:5,../../NBT/Banners/viking_regular_8.nbt,100)
Block(0,5,6,WOOD:1)
Block(0,6,-3,WOOD:1)
Block(0,6,5,HAY_BLOCK:4)
Block(0,6,6,WOOD:1)
Block(0,7,-3,WOOD:1)
Block(0,7,6,WOOD:1)
Block(0,8,-3,DARK_OAK_FENCE:0)
RandomBlock(0,8,0,WALL_BANNER:5,../../NBT/Banners/viking_regular_1.nbt,20,WALL_BANNER:5,../../NBT/Banners/viking_regular_2.nbt,20,WALL_BANNER:5,../../NBT/Banners/viking_regular_3.nbt,20,WALL_BANNER:5,../../NBT/Banners/viking_regular_4.nbt,20,WALL_BANNER:5,../../NBT/Banners/viking_regular_5.nbt,20,WALL_BANNER:5,../../NBT/Banners/viking_regular_6.nbt,20,WALL_BANNER:5,../../NBT/Banners/viking_regular_7.nbt,20,WALL_BANNER:5,../../NBT/Banners/viking_regular_8.nbt,100)
RandomBlock(0,8,1,WALL_BANNER:5,../../NBT/Banners/viking_regular_1.nbt,20,WALL_BANNER:5,../../NBT/Banners/viking_regular_2.nbt,20,WALL_BANNER:5,../../NBT/Banners/viking_regular_3.nbt,20,WALL_BANNER:5,../../NBT/Banners/viking_regular_4.nbt,20,WALL_BANNER:5,../../NBT/Banners/viking_regular_5.nbt,20,WALL_BANNER:5,../../NBT/Banners/viking_regular_6.nbt,20,WALL_BANNER:5,../../NBT/Banners/viking_regular_7.nbt,20,WALL_BANNER:5,../../NBT/Banners/viking_regular_8.nbt,100)
RandomBlock(0,8,2,WALL_BANNER:5,../../NBT/Banners/viking_regular_1.nbt,20,WALL_BANNER:5,../../NBT/Banners/viking_regular_2.nbt,20,WALL_BANNER:5,../../NBT/Banners/viking_regular_3.nbt,20,WALL_BANNER:5,../../NBT/Banners/viking_regular_4.nbt,20,WALL_BANNER:5,../../NBT/Banners/viking_regular_5.nbt,20,WALL_BANNER:5,../../NBT/Banners/viking_regular_6.nbt,20,WALL_BANNER:5,../../NBT/Banners/viking_regular_7.nbt,20,WALL_BANNER:5,../../NBT/Banners/viking_regular_8.nbt,100)
RandomBlock(0,8,3,WALL_BANNER:5,../../NBT/Banners/viking_regular_1.nbt,20,WALL_BANNER:5,../../NBT/Banners/viking_regular_2.nbt,20,WALL_BANNER:5,../../NBT/Banners/viking_regular_3.nbt,20,WALL_BANNER:5,../../NBT/Banners/viking_regular_4.nbt,20,WALL_BANNER:5,../../NBT/Banners/viking_regular_5.nbt,20,WALL_BANNER:5,../../NBT/Banners/viking_regular_6.nbt,20,WALL_BANNER:5,../../NBT/Banners/viking_regular_7.nbt,20,WALL_BANNER:5,../../NBT/Banners/viking_regular_8.nbt,100)
Block(0,8,6,DARK_OAK_FENCE:0)
Block(0,9,-1,WOOD_DOUBLE_STEP:1)
Block(0,9,0,TRAP_DOOR:15)
Block(0,9,1,TRAP_DOOR:15)
Block(0,9,2,WOOD_DOUBLE_STEP:1)
Block(1,0,0,MAGMA:0)
Block(1,0,1,MAGMA:0)
Block(1,1,0,MAGMA:0)
Block(1,1,1,MAGMA:0)
Block(1,2,-1,STONE:6)
Block(1,2,0,IRON_TRAPDOOR:8)
Block(1,2,1,IRON_TRAPDOOR:9)
Block(1,2,2,STONE:6)
Block(1,3,-4,WOOD_BUTTON:4)
Block(1,3,-3,LOG:1)
Block(1,3,-1,COBBLE_WALL:0)
Block(1,3,2,COBBLE_WALL:0)
Block(1,3,5,LADDER:2)
Block(1,3,6,LOG:1)
Block(1,4,-4,WOOD_BUTTON:4)
Block(1,4,-3,LOG:1)
Block(1,4,-1,IRON_FENCE:0)
Block(1,4,2,IRON_FENCE:0)
Block(1,4,5,LADDER:2)
Block(1,4,6,LOG:1)
Block(1,4,7,WOOD_BUTTON:3)
Block(1,5,-4,WOOD_BUTTON:4)
Block(1,5,-3,LOG:1)
RandomBlock(1,5,2,WALL_BANNER:2,../../NBT/Banners/viking_regular_1.nbt,20,WALL_BANNER:2,../../NBT/Banners/viking_regular_2.nbt,20,WALL_BANNER:2,../../NBT/Banners/viking_regular_3.nbt,20,WALL_BANNER:2,../../NBT/Banners/viking_regular_4.nbt,20,WALL_BANNER:2,../../NBT/Banners/viking_regular_5.nbt,20,WALL_BANNER:2,../../NBT/Banners/viking_regular_6.nbt,20,WALL_BANNER:2,../../NBT/Banners/viking_regular_7.nbt,20,WALL_BANNER:2,../../NBT/Banners/viking_regular_8.nbt,100)
Block(1,5,5,LADDER:2)
Block(1,5,6,LOG:1)
Block(1,5,7,WOOD_BUTTON:3)
Block(1,6,-4,WOOD_BUTTON:4)
Block(1,6,-3,LOG:1)
RandomBlock(1,6,-2,WALL_BANNER:3,../../NBT/Banners/viking_tannery_1.nbt,20,WALL_BANNER:3,../../NBT/Banners/viking_tannery_2.nbt,20,WALL_BANNER:3,../../NBT/Banners/viking_tannery_3.nbt,20,WALL_BANNER:3,../../NBT/Banners/viking_tannery_4.nbt,20,WALL_BANNER:3,../../NBT/Banners/viking_tannery_5.nbt,100)
Block(1,6,5,LADDER:2)
Block(1,6,6,LOG:1)
Block(1,6,7,WOOD_BUTTON:3)
Block(1,7,-4,WOOD_BUTTON:4)
Block(1,7,-3,LOG:1)
Block(1,7,6,LOG:1)
Block(1,7,7,WOOD_BUTTON:3)
Block(1,8,-4,WOOD_BUTTON:4)
Block(1,8,-3,LOG:1)
Block(1,8,6,LOG:1)
Block(1,8,7,WOOD_BUTTON:3)
Block(1,9,-6,WOOD_BUTTON:4)
Block(1,9,-5,LOG:9)
Block(1,9,-4,LOG:9)
Block(1,9,-3,LOG:9)
Block(1,9,-2,LOG:9)
Block(1,9,-1,LOG:9)
Block(1,9,0,LOG:9)
Block(1,9,1,LOG:9)
Block(1,9,2,LOG:9)
Block(1,9,3,LOG:9)
Block(1,9,4,LOG:9)
Block(1,9,5,LOG:9)
Block(1,9,6,LOG:9)
Block(1,9,7,LOG:9)
Block(1,9,8,LOG:9)
Block(1,9,9,WOOD_BUTTON:3)
Block(1,10,0,WOOD_DOUBLE_STEP:1)
Block(1,10,1,WOOD_DOUBLE_STEP:1)
Block(2,3,-3,SPRUCE_DOOR:3)
Block(2,3,6,LOG:5)
Block(2,4,-3,SPRUCE_DOOR:8)
Block(2,5,-3,WOOD:1)
RandomBlock(2,5,2,WALL_BANNER:2,../../NBT/Banners/viking_regular_1.nbt,20,WALL_BANNER:2,../../NBT/Banners/viking_regular_2.nbt,20,WALL_BANNER:2,../../NBT/Banners/viking_regular_3.nbt,20,WALL_BANNER:2,../../NBT/Banners/viking_regular_4.nbt,20,WALL_BANNER:2,../../NBT/Banners/viking_regular_5.nbt,20,WALL_BANNER:2,../../NBT/Banners/viking_regular_6.nbt,20,WALL_BANNER:2,../../NBT/Banners/viking_regular_7.nbt,20,WALL_BANNER:2,../../NBT/Banners/viking_regular_8.nbt,100)
Block(2,5,6,WOOD:1)
Block(2,6,-3,WOOD:1)
Block(2,6,3,HAY_BLOCK:0)
Block(2,6,6,WOOD:1)
Block(2,7,-3,WOOD:1)
RandomBlock(2,7,-2,WALL_BANNER:3,../../NBT/Banners/viking_tannery_1.nbt,20,WALL_BANNER:3,../../NBT/Banners/viking_tannery_2.nbt,20,WALL_BANNER:3,../../NBT/Banners/viking_tannery_3.nbt,20,WALL_BANNER:3,../../NBT/Banners/viking_tannery_4.nbt,20,WALL_BANNER:3,../../NBT/Banners/viking_tannery_5.nbt,100)
Block(2,7,6,WOOD:1)
Block(2,8,-3,DARK_OAK_FENCE:0)
RandomBlock(2,8,-1,WALL_BANNER:4,../../NBT/Banners/viking_tannery_1.nbt,20,WALL_BANNER:4,../../NBT/Banners/viking_tannery_2.nbt,20,WALL_BANNER:4,../../NBT/Banners/viking_tannery_3.nbt,20,WALL_BANNER:4,../../NBT/Banners/viking_tannery_4.nbt,20,WALL_BANNER:4,../../NBT/Banners/viking_tannery_5.nbt,100)
RandomBlock(2,8,4,WALL_BANNER:4,../../NBT/Banners/viking_tannery_1.nbt,20,WALL_BANNER:4,../../NBT/Banners/viking_tannery_2.nbt,20,WALL_BANNER:4,../../NBT/Banners/viking_tannery_3.nbt,20,WALL_BANNER:4,../../NBT/Banners/viking_tannery_4.nbt,20,WALL_BANNER:4,../../NBT/Banners/viking_tannery_5.nbt,100)
Block(2,8,6,DARK_OAK_FENCE:0)
Block(2,9,-1,WOOD_DOUBLE_STEP:1)
Block(2,9,0,TRAP_DOOR:14)
Block(2,9,1,TRAP_DOOR:14)
Block(2,9,2,WOOD_DOUBLE_STEP:1)
Block(3,3,-3,LOG:5)
Block(3,3,2,DARK_OAK_FENCE:0)
Block(3,3,5,FLOWER_POT:0)
Block(3,3,6,LOG:5)
Block(3,4,2,DARK_OAK_FENCE:0)
RandomBlock(3,4,5,WALL_BANNER:2,../../NBT/Banners/viking_tannery_1.nbt,20,WALL_BANNER:2,../../NBT/Banners/viking_tannery_2.nbt,20,WALL_BANNER:2,../../NBT/Banners/viking_tannery_3.nbt,20,WALL_BANNER:2,../../NBT/Banners/viking_tannery_4.nbt,20,WALL_BANNER:2,../../NBT/Banners/viking_tannery_5.nbt,100)
Block(3,5,-3,WOOD:1)
Block(3,5,2,DARK_OAK_FENCE:0)
Block(3,5,6,WOOD:1)
Block(3,6,-3,WOOD:1)
RandomBlock(3,6,1,WALL_BANNER:2,../../NBT/Banners/viking_regular_1.nbt,20,WALL_BANNER:2,../../NBT/Banners/viking_regular_2.nbt,20,WALL_BANNER:2,../../NBT/Banners/viking_regular_3.nbt,20,WALL_BANNER:2,../../NBT/Banners/viking_regular_4.nbt,20,WALL_BANNER:2,../../NBT/Banners/viking_regular_5.nbt,20,WALL_BANNER:2,../../NBT/Banners/viking_regular_6.nbt,20,WALL_BANNER:2,../../NBT/Banners/viking_regular_7.nbt,20,WALL_BANNER:2,../../NBT/Banners/viking_regular_8.nbt,100)
Block(3,6,2,DARK_OAK_FENCE:0)
Block(3,6,3,HAY_BLOCK:0)
Block(3,6,4,HAY_BLOCK:0)
Block(3,6,6,WOOD:1)
Block(3,7,-3,DARK_OAK_FENCE:0)
Block(3,7,2,DARK_OAK_FENCE:0)
Block(3,7,3,HAY_BLOCK:0)
Block(3,7,6,DARK_OAK_FENCE:0)
Block(4,3,-3,LOG:5)
Block(4,3,-2,HAY_BLOCK:4)
Block(4,3,-1,HAY_BLOCK:0)
Block(4,3,0,HAY_BLOCK:8)
Block(4,3,1,HAY_BLOCK:4)
Block(4,3,2,DARK_OAK_FENCE:0)
Block(4,3,4,BED_BLOCK:0)
Block(4,3,5,BED_BLOCK:8)
Block(4,3,6,LOG:5)
Block(4,4,-2,HAY_BLOCK:4)
Block(4,4,2,DARK_OAK_FENCE:0)
Block(4,5,-3,WOOD:1)
RandomBlock(4,5,1,WALL_BANNER:2,../../NBT/Banners/viking_regular_1.nbt,20,WALL_BANNER:2,../../NBT/Banners/viking_regular_2.nbt,20,WALL_BANNER:2,../../NBT/Banners/viking_regular_3.nbt,20,WALL_BANNER:2,../../NBT/Banners/viking_regular_4.nbt,20,WALL_BANNER:2,../../NBT/Banners/viking_regular_5.nbt,20,WALL_BANNER:2,../../NBT/Banners/viking_regular_6.nbt,20,WALL_BANNER:2,../../NBT/Banners/viking_regular_7.nbt,20,WALL_BANNER:2,../../NBT/Banners/viking_regular_8.nbt,100)
Block(4,5,2,DARK_OAK_FENCE:0)
Block(4,5,6,WOOD:1)
Block(4,6,-3,DARK_OAK_FENCE:0)
RandomBlock(4,6,1,WALL_BANNER:2,../../NBT/Banners/viking_wealthy_1.nbt,20,WALL_BANNER:2,../../NBT/Banners/viking_wealthy_2.nbt,20,WALL_BANNER:2,../../NBT/Banners/viking_wealthy_3.nbt,20,WALL_BANNER:2,../../NBT/Banners/viking_wealthy_4.nbt,20,WALL_BANNER:2,../../NBT/Banners/viking_wealthy_5.nbt,20,WALL_BANNER:2,../../NBT/Banners/viking_wealthy_6.nbt,20,WALL_BANNER:2,../../NBT/Banners/viking_wealthy_7.nbt,20,WALL_BANNER:2,../../NBT/Banners/viking_wealthy_8.nbt,20,WALL_BANNER:2,../../NBT/Banners/viking_wealthy_9.nbt,100)
Block(4,6,2,DARK_OAK_FENCE:0)
Block(4,6,3,HAY_BLOCK:0)
Block(4,6,4,HAY_BLOCK:0)
Block(4,6,6,DARK_OAK_FENCE:0)
Block(5,3,-3,LOG:5)
Block(5,3,-2,HAY_BLOCK:4)
Block(5,3,-1,HAY_BLOCK:4)
Block(5,3,0,HAY_BLOCK:4)
Block(5,3,1,HAY_BLOCK:4)
Block(5,3,2,DARK_OAK_FENCE:0)
Block(5,3,4,BED_BLOCK:0)
Block(5,3,5,BED_BLOCK:8)
Block(5,3,6,LOG:5)
Block(5,4,-2,HAY_BLOCK:0)
Block(5,4,-1,HAY_BLOCK:4)
RandomBlock(5,4,1,WALL_BANNER:2,../../NBT/Banners/viking_wealthy_1.nbt,20,WALL_BANNER:2,../../NBT/Banners/viking_wealthy_2.nbt,20,WALL_BANNER:2,../../NBT/Banners/viking_wealthy_3.nbt,20,WALL_BANNER:2,../../NBT/Banners/viking_wealthy_4.nbt,20,WALL_BANNER:2,../../NBT/Banners/viking_wealthy_5.nbt,20,WALL_BANNER:2,../../NBT/Banners/viking_wealthy_6.nbt,20,WALL_BANNER:2,../../NBT/Banners/viking_wealthy_7.nbt,20,WALL_BANNER:2,../../NBT/Banners/viking_wealthy_8.nbt,20,WALL_BANNER:2,../../NBT/Banners/viking_wealthy_9.nbt,100)
Block(5,4,2,DARK_OAK_FENCE:0)
RandomBlock(5,4,4,WALL_BANNER:4,../../NBT/Banners/viking_tannery_1.nbt,20,WALL_BANNER:4,../../NBT/Banners/viking_tannery_2.nbt,20,WALL_BANNER:4,../../NBT/Banners/viking_tannery_3.nbt,20,WALL_BANNER:4,../../NBT/Banners/viking_tannery_4.nbt,20,WALL_BANNER:4,../../NBT/Banners/viking_tannery_5.nbt,100)
Block(5,5,-3,WOOD:1)
Block(5,5,-2,HAY_BLOCK:4)
Block(5,5,-1,HAY_BLOCK:4)
RandomBlock(5,5,1,WALL_BANNER:2,../../NBT/Banners/viking_regular_1.nbt,20,WALL_BANNER:2,../../NBT/Banners/viking_regular_2.nbt,20,WALL_BANNER:2,../../NBT/Banners/viking_regular_3.nbt,20,WALL_BANNER:2,../../NBT/Banners/viking_regular_4.nbt,20,WALL_BANNER:2,../../NBT/Banners/viking_regular_5.nbt,20,WALL_BANNER:2,../../NBT/Banners/viking_regular_6.nbt,20,WALL_BANNER:2,../../NBT/Banners/viking_regular_7.nbt,20,WALL_BANNER:2,../../NBT/Banners/viking_regular_8.nbt,100)
Block(5,5,2,DARK_OAK_FENCE:0)
Block(5,5,6,WOOD:1)
Block(6,0,-3,LOG:1)
Block(6,0,6,LOG:1)
Block(6,1,-3,LOG:1)
Block(6,1,6,LOG:1)
Block(6,2,-3,LOG:1)
Block(6,2,6,LOG:1)
Block(6,3,-3,LOG:1)
Block(6,3,-2,LOG:9)
Block(6,3,-1,LOG:9)
Block(6,3,0,LOG:9)
Block(6,3,1,LOG:9)
Block(6,3,2,LOG:9)
Block(6,3,3,LOG:9)
Block(6,3,4,LOG:9)
Block(6,3,5,LOG:9)
Block(6,3,6,LOG:1)
Block(6,4,-3,LOG:1)
Block(6,4,-2,WOOD:1)
Block(6,4,-1,WOOD:1)
Block(6,4,0,WOOD:1)
Block(6,4,1,WOOD:1)
Block(6,4,2,WOOD:1)
Block(6,4,3,WOOD:1)
Block(6,4,4,WOOD:1)
Block(6,4,5,WOOD:1)
Block(6,4,6,LOG:1)


Block(-6,0,-4,COBBLESTONE:0)
Block(-6,0,7,COBBLESTONE:0)
Block(-6,1,-4,COBBLESTONE:0)
Block(-6,1,7,COBBLESTONE:0)
Block(-6,2,-4,COBBLESTONE:0)
Block(-6,2,7,COBBLESTONE:0)
Block(-6,3,-4,SPRUCE_WOOD_STAIRS:0)
Block(-6,3,-3,SPRUCE_WOOD_STAIRS:0)
Block(-6,3,-2,SPRUCE_WOOD_STAIRS:0)
Block(-6,3,-1,SPRUCE_WOOD_STAIRS:0)
Block(-6,3,0,SPRUCE_WOOD_STAIRS:0)
Block(-6,3,1,SPRUCE_WOOD_STAIRS:0)
Block(-6,3,2,SPRUCE_WOOD_STAIRS:0)
Block(-6,3,3,SPRUCE_WOOD_STAIRS:0)
Block(-6,3,4,SPRUCE_WOOD_STAIRS:0)
Block(-6,3,5,SPRUCE_WOOD_STAIRS:0)
Block(-6,3,6,SPRUCE_WOOD_STAIRS:0)
Block(-6,3,7,SPRUCE_WOOD_STAIRS:0)
Block(-5,3,-4,SPRUCE_WOOD_STAIRS:5)
Block(-5,3,7,SPRUCE_WOOD_STAIRS:5)
Block(-5,4,-4,SPRUCE_WOOD_STAIRS:0)
Block(-5,4,-3,SPRUCE_WOOD_STAIRS:0)
Block(-5,4,-2,SPRUCE_WOOD_STAIRS:0)
Block(-5,4,-1,SPRUCE_WOOD_STAIRS:0)
Block(-5,4,0,SPRUCE_WOOD_STAIRS:0)
Block(-5,4,1,SPRUCE_WOOD_STAIRS:0)
Block(-5,4,2,SPRUCE_WOOD_STAIRS:0)
Block(-5,4,3,SPRUCE_WOOD_STAIRS:0)
Block(-5,4,4,SPRUCE_WOOD_STAIRS:0)
Block(-5,4,5,SPRUCE_WOOD_STAIRS:0)
Block(-5,4,6,SPRUCE_WOOD_STAIRS:0)
Block(-5,4,7,SPRUCE_WOOD_STAIRS:0)
Block(-4,0,-2,COBBLESTONE:0)
Block(-4,0,-1,COBBLESTONE:0)
Block(-4,0,0,COBBLESTONE:0)
Block(-4,0,1,COBBLESTONE:0)
Block(-4,0,2,COBBLESTONE:0)
Block(-4,0,3,COBBLESTONE:0)
Block(-4,0,4,COBBLESTONE:0)
Block(-4,0,5,COBBLESTONE:0)
Block(-4,1,-2,COBBLESTONE:0)
Block(-4,1,-1,COBBLESTONE:0)
Block(-4,1,0,COBBLESTONE:0)
Block(-4,1,1,COBBLESTONE:0)
Block(-4,1,2,COBBLESTONE:0)
Block(-4,1,3,COBBLESTONE:0)
Block(-4,1,4,COBBLESTONE:0)
Block(-4,1,5,COBBLESTONE:0)
Block(-4,2,-2,COBBLESTONE:0)
Block(-4,2,-1,COBBLESTONE:0)
Block(-4,2,0,COBBLESTONE:0)
Block(-4,2,1,COBBLESTONE:0)
Block(-4,2,2,COBBLESTONE:0)
Block(-4,2,3,COBBLESTONE:0)
Block(-4,2,4,COBBLESTONE:0)
Block(-4,2,5,COBBLESTONE:0)
Block(-4,4,-4,SPRUCE_WOOD_STAIRS:5)
Block(-4,4,7,SPRUCE_WOOD_STAIRS:5)
Block(-4,5,-4,SPRUCE_WOOD_STAIRS:0)
Block(-4,5,-3,SPRUCE_WOOD_STAIRS:0)
Block(-4,5,-2,SPRUCE_WOOD_STAIRS:0)
Block(-4,5,-1,SPRUCE_WOOD_STAIRS:0)
Block(-4,5,0,SPRUCE_WOOD_STAIRS:0)
Block(-4,5,1,SPRUCE_WOOD_STAIRS:0)
Block(-4,5,2,SPRUCE_WOOD_STAIRS:0)
Block(-4,5,3,SPRUCE_WOOD_STAIRS:0)
Block(-4,5,4,SPRUCE_WOOD_STAIRS:0)
Block(-4,5,5,SPRUCE_WOOD_STAIRS:0)
Block(-4,5,6,SPRUCE_WOOD_STAIRS:0)
Block(-4,5,7,SPRUCE_WOOD_STAIRS:0)
Block(-3,0,-3,COBBLESTONE:0)
Block(-3,0,-2,COBBLESTONE:0)
Block(-3,0,-1,COBBLESTONE:0)
Block(-3,0,0,COBBLESTONE:0)
Block(-3,0,1,COBBLESTONE:0)
Block(-3,0,2,COBBLESTONE:0)
Block(-3,0,3,COBBLESTONE:0)
Block(-3,0,4,COBBLESTONE:0)
Block(-3,0,5,COBBLESTONE:0)
Block(-3,0,6,COBBLESTONE:0)
Block(-3,1,-3,COBBLESTONE:0)
Block(-3,1,-2,COBBLESTONE:0)
Block(-3,1,-1,COBBLESTONE:0)
Block(-3,1,0,COBBLESTONE:0)
Block(-3,1,1,COBBLESTONE:0)
Block(-3,1,2,COBBLESTONE:0)
Block(-3,1,3,COBBLESTONE:0)
Block(-3,1,4,COBBLESTONE:0)
Block(-3,1,5,COBBLESTONE:0)
Block(-3,1,6,COBBLESTONE:0)
Block(-3,2,-3,COBBLESTONE:0)
Block(-3,2,-2,COBBLESTONE:0)
Block(-3,2,-1,COBBLESTONE:0)
Block(-3,2,0,COBBLESTONE:0)
Block(-3,2,1,COBBLESTONE:0)
Block(-3,2,2,COBBLESTONE:0)
Block(-3,2,3,COBBLESTONE:0)
Block(-3,2,4,COBBLESTONE:0)
Block(-3,2,5,COBBLESTONE:0)
Block(-3,2,6,COBBLESTONE:0)
Block(-3,3,-2,WOOD_STEP:5)
Block(-3,3,-1,WOOD_STEP:5)
Block(-3,3,0,WOOD_STEP:5)
Block(-3,3,1,WOOD_STEP:5)
Block(-3,3,2,WOOD_STEP:5)
Block(-3,3,3,WOOD_STEP:5)
Block(-3,4,-3,SPRUCE_WOOD_STAIRS:6)
Block(-3,4,6,SPRUCE_WOOD_STAIRS:7)
Block(-3,5,-4,SPRUCE_WOOD_STAIRS:5)
Block(-3,5,-2,WOOD_STEP:9)
Block(-3,5,-1,WOOD_STEP:9)
Block(-3,5,0,WOOD_STEP:9)
Block(-3,5,1,WOOD_STEP:9)
Block(-3,5,2,WOOD_STEP:9)
Block(-3,5,3,WOOD_STEP:9)
Block(-3,5,4,WOOD_STEP:9)
Block(-3,5,5,WOOD_STEP:9)
Block(-3,5,7,SPRUCE_WOOD_STAIRS:5)
Block(-3,6,-4,SPRUCE_WOOD_STAIRS:0)
Block(-3,6,-3,SPRUCE_WOOD_STAIRS:0)
Block(-3,6,-2,SPRUCE_WOOD_STAIRS:0)
Block(-3,6,-1,SPRUCE_WOOD_STAIRS:0)
Block(-3,6,0,SPRUCE_WOOD_STAIRS:0)
Block(-3,6,1,SPRUCE_WOOD_STAIRS:0)
Block(-3,6,2,SPRUCE_WOOD_STAIRS:0)
Block(-3,6,3,SPRUCE_WOOD_STAIRS:0)
Block(-3,6,4,SPRUCE_WOOD_STAIRS:0)
Block(-3,6,5,SPRUCE_WOOD_STAIRS:0)
Block(-3,6,6,SPRUCE_WOOD_STAIRS:0)
Block(-3,6,7,SPRUCE_WOOD_STAIRS:0)
Block(-2,0,-3,COBBLESTONE:0)
Block(-2,0,-2,COBBLESTONE:0)
Block(-2,0,-1,COBBLESTONE:0)
Block(-2,0,0,COBBLESTONE:0)
Block(-2,0,1,COBBLESTONE:0)
Block(-2,0,2,COBBLESTONE:0)
Block(-2,0,3,COBBLESTONE:0)
Block(-2,0,4,COBBLESTONE:0)
Block(-2,0,5,COBBLESTONE:0)
Block(-2,0,6,COBBLESTONE:0)
Block(-2,1,-3,COBBLESTONE:0)
Block(-2,1,-2,COBBLESTONE:0)
Block(-2,1,-1,COBBLESTONE:0)
Block(-2,1,0,COBBLESTONE:0)
Block(-2,1,1,COBBLESTONE:0)
Block(-2,1,2,COBBLESTONE:0)
Block(-2,1,3,COBBLESTONE:0)
Block(-2,1,4,COBBLESTONE:0)
Block(-2,1,5,COBBLESTONE:0)
Block(-2,1,6,COBBLESTONE:0)
Block(-2,2,-3,COBBLESTONE:0)
Block(-2,2,-2,COBBLESTONE:0)
Block(-2,2,-1,COBBLESTONE:0)
Block(-2,2,0,COBBLESTONE:0)
Block(-2,2,1,COBBLESTONE:0)
Block(-2,2,2,COBBLESTONE:0)
Block(-2,2,3,COBBLESTONE:0)
Block(-2,2,4,COBBLESTONE:0)
Block(-2,2,5,COBBLESTONE:0)
Block(-2,2,6,COBBLESTONE:0)
Block(-2,3,-2,WOOD_STEP:5)
Block(-2,4,-3,SPRUCE_WOOD_STAIRS:6)
Block(-2,4,6,SPRUCE_WOOD_STAIRS:7)
Block(-2,5,-2,WOOD_STEP:9)
Block(-2,5,-1,WOOD_STEP:9)
Block(-2,5,0,WOOD_STEP:9)
Block(-2,5,1,WOOD_STEP:9)
Block(-2,5,2,WOOD_STEP:9)
Block(-2,5,3,WOOD_STEP:9)
Block(-2,5,4,WOOD_STEP:9)
Block(-2,5,5,WOOD_STEP:9)
Block(-2,6,-4,SPRUCE_WOOD_STAIRS:5)
Block(-2,6,7,SPRUCE_WOOD_STAIRS:5)
Block(-2,7,-4,SPRUCE_WOOD_STAIRS:0)
Block(-2,7,-3,SPRUCE_WOOD_STAIRS:0)
Block(-2,7,-2,SPRUCE_WOOD_STAIRS:0)
Block(-2,7,-1,SPRUCE_WOOD_STAIRS:0)
Block(-2,7,0,SPRUCE_WOOD_STAIRS:0)
Block(-2,7,1,SPRUCE_WOOD_STAIRS:0)
Block(-2,7,2,SPRUCE_WOOD_STAIRS:0)
Block(-2,7,3,SPRUCE_WOOD_STAIRS:0)
Block(-2,7,4,SPRUCE_WOOD_STAIRS:0)
Block(-2,7,5,SPRUCE_WOOD_STAIRS:0)
Block(-2,7,6,SPRUCE_WOOD_STAIRS:0)
Block(-2,7,7,SPRUCE_WOOD_STAIRS:0)
Block(-1,0,-3,COBBLESTONE:0)
Block(-1,0,-2,COBBLESTONE:0)
Block(-1,0,-1,COBBLESTONE:0)
Block(-1,0,0,COBBLESTONE:0)
Block(-1,0,1,COBBLESTONE:0)
Block(-1,0,2,COBBLESTONE:0)
Block(-1,0,3,COBBLESTONE:0)
Block(-1,0,4,COBBLESTONE:0)
Block(-1,0,5,COBBLESTONE:0)
Block(-1,0,6,COBBLESTONE:0)
Block(-1,1,-3,COBBLESTONE:0)
Block(-1,1,-2,COBBLESTONE:0)
Block(-1,1,-1,COBBLESTONE:0)
Block(-1,1,0,COBBLESTONE:0)
Block(-1,1,1,COBBLESTONE:0)
Block(-1,1,2,COBBLESTONE:0)
Block(-1,1,3,COBBLESTONE:0)
Block(-1,1,4,COBBLESTONE:0)
Block(-1,1,5,COBBLESTONE:0)
Block(-1,1,6,COBBLESTONE:0)
Block(-1,2,-3,COBBLESTONE:0)
Block(-1,2,-2,COBBLESTONE:0)
Block(-1,2,-1,COBBLESTONE:0)
Block(-1,2,0,COBBLESTONE:0)
Block(-1,2,1,COBBLESTONE:0)
Block(-1,2,2,COBBLESTONE:0)
Block(-1,2,3,COBBLESTONE:0)
Block(-1,2,4,COBBLESTONE:0)
Block(-1,2,5,COBBLESTONE:0)
Block(-1,2,6,COBBLESTONE:0)
Block(-1,3,-2,WOOD_STEP:5)
Block(-1,3,4,WOOD_STEP:5)
Block(-1,4,-3,SPRUCE_WOOD_STAIRS:6)
Block(-1,4,6,SPRUCE_WOOD_STAIRS:7)
Block(-1,5,-2,WOOD_STEP:9)
Block(-1,5,-1,WOOD_STEP:9)
Block(-1,5,0,WOOD_STEP:9)
Block(-1,5,1,WOOD_STEP:9)
Block(-1,5,2,WOOD_STEP:9)
Block(-1,5,3,WOOD_STEP:9)
Block(-1,5,4,WOOD_STEP:9)
Block(-1,5,5,WOOD_STEP:9)
Block(-1,7,-4,SPRUCE_WOOD_STAIRS:5)
Block(-1,7,7,SPRUCE_WOOD_STAIRS:5)
Block(-1,8,-4,SPRUCE_WOOD_STAIRS:0)
Block(-1,8,-3,SPRUCE_WOOD_STAIRS:0)
Block(-1,8,-2,SPRUCE_WOOD_STAIRS:0)
Block(-1,8,-1,SPRUCE_WOOD_STAIRS:0)
Block(-1,8,0,SPRUCE_WOOD_STAIRS:0)
Block(-1,8,1,SPRUCE_WOOD_STAIRS:0)
Block(-1,8,2,SPRUCE_WOOD_STAIRS:0)
Block(-1,8,3,SPRUCE_WOOD_STAIRS:0)
Block(-1,8,4,SPRUCE_WOOD_STAIRS:0)
Block(-1,8,5,SPRUCE_WOOD_STAIRS:0)
Block(-1,8,6,SPRUCE_WOOD_STAIRS:0)
Block(-1,8,7,SPRUCE_WOOD_STAIRS:0)
Block(-1,9,-1,SPRUCE_WOOD_STAIRS:0)
Block(-1,9,2,SPRUCE_WOOD_STAIRS:0)
Block(0,0,-3,COBBLESTONE:0)
Block(0,0,-2,COBBLESTONE:0)
Block(0,0,-1,COBBLESTONE:0)
Block(0,0,0,COBBLESTONE:0)
Block(0,0,1,COBBLESTONE:0)
Block(0,0,2,COBBLESTONE:0)
Block(0,0,3,COBBLESTONE:0)
Block(0,0,4,COBBLESTONE:0)
Block(0,0,5,COBBLESTONE:0)
Block(0,0,6,COBBLESTONE:0)
Block(0,1,-3,COBBLESTONE:0)
Block(0,1,-2,COBBLESTONE:0)
Block(0,1,-1,COBBLESTONE:0)
Block(0,1,0,COBBLESTONE:0)
Block(0,1,1,COBBLESTONE:0)
Block(0,1,2,COBBLESTONE:0)
Block(0,1,3,COBBLESTONE:0)
Block(0,1,4,COBBLESTONE:0)
Block(0,1,5,COBBLESTONE:0)
Block(0,1,6,COBBLESTONE:0)
Block(0,2,-3,COBBLESTONE:0)
Block(0,2,-2,COBBLESTONE:0)
Block(0,2,-1,COBBLESTONE_STAIRS:3)
Block(0,2,0,COBBLESTONE_STAIRS:1)
Block(0,2,1,COBBLESTONE_STAIRS:1)
Block(0,2,2,COBBLESTONE_STAIRS:2)
Block(0,2,3,COBBLESTONE:0)
Block(0,2,4,COBBLESTONE:0)
Block(0,2,5,COBBLESTONE:0)
Block(0,2,6,COBBLESTONE:0)
Block(0,3,4,WOOD_STEP:5)
Block(0,4,-3,SPRUCE_WOOD_STAIRS:6)
Block(0,4,6,SPRUCE_WOOD_STAIRS:7)
Block(0,5,3,WOOD_STEP:9)
Block(0,5,4,WOOD_STEP:9)
Block(0,5,5,WOOD_STEP:9)
Block(0,8,-4,SPRUCE_WOOD_STAIRS:5)
Block(0,8,7,SPRUCE_WOOD_STAIRS:5)
Block(0,9,-4,SPRUCE_WOOD_STAIRS:0)
Block(0,9,-3,WOOD_STEP:1)
Block(0,9,-2,WOOD_STEP:1)
Block(0,9,3,WOOD_STEP:1)
Block(0,9,4,WOOD_STEP:1)
Block(0,9,5,WOOD_STEP:1)
Block(0,9,6,WOOD_STEP:1)
Block(0,9,7,SPRUCE_WOOD_STAIRS:0)
Block(0,10,-4,WOOD_STEP:1)
Block(0,10,-1,SPRUCE_WOOD_STAIRS:0)
Block(0,10,0,SPRUCE_WOOD_STAIRS:0)
Block(0,10,1,SPRUCE_WOOD_STAIRS:0)
Block(0,10,2,SPRUCE_WOOD_STAIRS:0)
Block(0,10,7,WOOD_STEP:1)
Block(1,0,-3,COBBLESTONE:0)
Block(1,0,-2,COBBLESTONE:0)
Block(1,0,-1,COBBLESTONE:0)
Block(1,0,2,COBBLESTONE:0)
Block(1,0,3,COBBLESTONE:0)
Block(1,0,4,COBBLESTONE:0)
Block(1,0,5,COBBLESTONE:0)
Block(1,0,6,COBBLESTONE:0)
Block(1,1,-3,COBBLESTONE:0)
Block(1,1,-2,COBBLESTONE:0)
Block(1,1,-1,COBBLESTONE:0)
Block(1,1,2,COBBLESTONE:0)
Block(1,1,3,COBBLESTONE:0)
Block(1,1,4,COBBLESTONE:0)
Block(1,1,5,COBBLESTONE:0)
Block(1,1,6,COBBLESTONE:0)
Block(1,2,-3,COBBLESTONE:0)
Block(1,2,-2,COBBLESTONE:0)
Block(1,2,3,COBBLESTONE:0)
Block(1,2,4,COBBLESTONE:0)
Block(1,2,5,COBBLESTONE:0)
Block(1,2,6,COBBLESTONE:0)
Block(1,5,3,WOOD_STEP:9)
Block(1,5,4,WOOD_STEP:9)
Block(1,10,-1,SPRUCE_WOOD_STAIRS:6)
Block(1,10,2,SPRUCE_WOOD_STAIRS:7)
Block(1,11,-1,WOOD_STEP:1)
Block(1,11,0,WOOD_STEP:1)
Block(1,11,1,WOOD_STEP:1)
Block(1,11,2,WOOD_STEP:1)
Block(2,0,-3,COBBLESTONE:0)
Block(2,0,-2,COBBLESTONE:0)
Block(2,0,-1,COBBLESTONE:0)
Block(2,0,0,COBBLESTONE:0)
Block(2,0,1,COBBLESTONE:0)
Block(2,0,2,COBBLESTONE:0)
Block(2,0,3,COBBLESTONE:0)
Block(2,0,4,COBBLESTONE:0)
Block(2,0,5,COBBLESTONE:0)
Block(2,0,6,COBBLESTONE:0)
Block(2,1,-3,COBBLESTONE:0)
Block(2,1,-2,COBBLESTONE:0)
Block(2,1,-1,COBBLESTONE:0)
Block(2,1,0,COBBLESTONE:0)
Block(2,1,1,COBBLESTONE:0)
Block(2,1,2,COBBLESTONE:0)
Block(2,1,3,COBBLESTONE:0)
Block(2,1,4,COBBLESTONE:0)
Block(2,1,5,COBBLESTONE:0)
Block(2,1,6,COBBLESTONE:0)
Block(2,2,-3,COBBLESTONE:0)
Block(2,2,-2,COBBLESTONE:0)
Block(2,2,-1,COBBLESTONE_STAIRS:3)
Block(2,2,0,COBBLESTONE_STAIRS:0)
Block(2,2,1,COBBLESTONE_STAIRS:0)
Block(2,2,2,COBBLESTONE_STAIRS:2)
Block(2,2,3,COBBLESTONE:0)
Block(2,2,4,COBBLESTONE:0)
Block(2,2,5,COBBLESTONE:0)
Block(2,2,6,COBBLESTONE:0)
Block(2,4,6,SPRUCE_WOOD_STAIRS:7)
Block(2,5,3,WOOD_STEP:9)
Block(2,5,4,WOOD_STEP:9)
Block(2,5,5,WOOD_STEP:9)
Block(2,8,-4,SPRUCE_WOOD_STAIRS:4)
Block(2,8,7,SPRUCE_WOOD_STAIRS:4)
Block(2,9,-4,SPRUCE_WOOD_STAIRS:1)
Block(2,9,-3,WOOD_STEP:1)
Block(2,9,-2,WOOD_STEP:1)
Block(2,9,3,WOOD_STEP:1)
Block(2,9,4,WOOD_STEP:1)
Block(2,9,5,WOOD_STEP:1)
Block(2,9,6,WOOD_STEP:1)
Block(2,9,7,SPRUCE_WOOD_STAIRS:1)
Block(2,10,-4,WOOD_STEP:1)
Block(2,10,-1,SPRUCE_WOOD_STAIRS:1)
Block(2,10,0,SPRUCE_WOOD_STAIRS:1)
Block(2,10,1,SPRUCE_WOOD_STAIRS:1)
Block(2,10,2,SPRUCE_WOOD_STAIRS:1)
Block(2,10,7,WOOD_STEP:1)
Block(3,0,-3,COBBLESTONE:0)
Block(3,0,-2,COBBLESTONE:0)
Block(3,0,-1,COBBLESTONE:0)
Block(3,0,0,COBBLESTONE:0)
Block(3,0,1,COBBLESTONE:0)
Block(3,0,2,COBBLESTONE:0)
Block(3,0,3,COBBLESTONE:0)
Block(3,0,4,COBBLESTONE:0)
Block(3,0,5,COBBLESTONE:0)
Block(3,0,6,COBBLESTONE:0)
Block(3,1,-3,COBBLESTONE:0)
Block(3,1,-2,COBBLESTONE:0)
Block(3,1,-1,COBBLESTONE:0)
Block(3,1,0,COBBLESTONE:0)
Block(3,1,1,COBBLESTONE:0)
Block(3,1,2,COBBLESTONE:0)
Block(3,1,3,COBBLESTONE:0)
Block(3,1,4,COBBLESTONE:0)
Block(3,1,5,COBBLESTONE:0)
Block(3,1,6,COBBLESTONE:0)
Block(3,2,-3,COBBLESTONE:0)
Block(3,2,-2,COBBLESTONE:0)
Block(3,2,-1,COBBLESTONE:0)
Block(3,2,0,COBBLESTONE:0)
Block(3,2,1,COBBLESTONE:0)
Block(3,2,2,COBBLESTONE:0)
Block(3,2,3,COBBLESTONE:0)
Block(3,2,4,COBBLESTONE:0)
Block(3,2,5,COBBLESTONE:0)
Block(3,2,6,COBBLESTONE:0)
Block(3,3,-2,COBBLESTONE_STAIRS:0)
Block(3,3,-1,COBBLESTONE_STAIRS:0)
Block(3,3,0,COBBLESTONE_STAIRS:0)
Block(3,3,1,COBBLESTONE_STAIRS:0)
Block(3,4,-3,SPRUCE_WOOD_STAIRS:6)
Block(3,4,6,SPRUCE_WOOD_STAIRS:7)
Block(3,5,3,WOOD_STEP:9)
Block(3,5,4,WOOD_STEP:9)
Block(3,5,5,WOOD_STEP:9)
Block(3,7,-4,SPRUCE_WOOD_STAIRS:4)
Block(3,7,7,SPRUCE_WOOD_STAIRS:4)
Block(3,8,-4,SPRUCE_WOOD_STAIRS:1)
Block(3,8,-3,SPRUCE_WOOD_STAIRS:1)
Block(3,8,-2,SPRUCE_WOOD_STAIRS:1)
Block(3,8,-1,SPRUCE_WOOD_STAIRS:1)
Block(3,8,0,SPRUCE_WOOD_STAIRS:1)
Block(3,8,1,SPRUCE_WOOD_STAIRS:1)
Block(3,8,2,SPRUCE_WOOD_STAIRS:1)
Block(3,8,3,SPRUCE_WOOD_STAIRS:1)
Block(3,8,4,SPRUCE_WOOD_STAIRS:1)
Block(3,8,5,SPRUCE_WOOD_STAIRS:1)
Block(3,8,6,SPRUCE_WOOD_STAIRS:1)
Block(3,8,7,SPRUCE_WOOD_STAIRS:1)
Block(3,9,-1,SPRUCE_WOOD_STAIRS:1)
Block(3,9,2,SPRUCE_WOOD_STAIRS:1)
Block(4,0,-3,COBBLESTONE:0)
Block(4,0,-2,COBBLESTONE:0)
Block(4,0,-1,COBBLESTONE:0)
Block(4,0,0,COBBLESTONE:0)
Block(4,0,1,COBBLESTONE:0)
Block(4,0,2,COBBLESTONE:0)
Block(4,0,3,COBBLESTONE:0)
Block(4,0,4,COBBLESTONE:0)
Block(4,0,5,COBBLESTONE:0)
Block(4,0,6,COBBLESTONE:0)
Block(4,1,-3,COBBLESTONE:0)
Block(4,1,-2,COBBLESTONE:0)
Block(4,1,-1,COBBLESTONE:0)
Block(4,1,0,COBBLESTONE:0)
Block(4,1,1,COBBLESTONE:0)
Block(4,1,2,COBBLESTONE:0)
Block(4,1,3,COBBLESTONE:0)
Block(4,1,4,COBBLESTONE:0)
Block(4,1,5,COBBLESTONE:0)
Block(4,1,6,COBBLESTONE:0)
Block(4,2,-3,COBBLESTONE:0)
Block(4,2,-2,COBBLESTONE:0)
Block(4,2,-1,COBBLESTONE:0)
Block(4,2,0,COBBLESTONE:0)
Block(4,2,1,COBBLESTONE:0)
Block(4,2,2,COBBLESTONE:0)
Block(4,2,3,COBBLESTONE:0)
Block(4,2,4,COBBLESTONE:0)
Block(4,2,5,COBBLESTONE:0)
Block(4,2,6,COBBLESTONE:0)
Block(4,4,-3,SPRUCE_WOOD_STAIRS:6)
Block(4,4,6,SPRUCE_WOOD_STAIRS:7)
Block(4,5,3,WOOD_STEP:9)
Block(4,5,4,WOOD_STEP:9)
Block(4,5,5,WOOD_STEP:9)
Block(4,6,-4,SPRUCE_WOOD_STAIRS:4)
Block(4,6,7,SPRUCE_WOOD_STAIRS:4)
Block(4,7,-4,SPRUCE_WOOD_STAIRS:1)
Block(4,7,-3,SPRUCE_WOOD_STAIRS:1)
Block(4,7,-2,SPRUCE_WOOD_STAIRS:1)
Block(4,7,-1,SPRUCE_WOOD_STAIRS:1)
Block(4,7,0,SPRUCE_WOOD_STAIRS:1)
Block(4,7,1,SPRUCE_WOOD_STAIRS:1)
Block(4,7,2,SPRUCE_WOOD_STAIRS:1)
Block(4,7,3,SPRUCE_WOOD_STAIRS:1)
Block(4,7,4,SPRUCE_WOOD_STAIRS:1)
Block(4,7,5,SPRUCE_WOOD_STAIRS:1)
Block(4,7,6,SPRUCE_WOOD_STAIRS:1)
Block(4,7,7,SPRUCE_WOOD_STAIRS:1)
Block(5,0,-3,COBBLESTONE:0)
Block(5,0,-2,COBBLESTONE:0)
Block(5,0,-1,COBBLESTONE:0)
Block(5,0,0,COBBLESTONE:0)
Block(5,0,1,COBBLESTONE:0)
Block(5,0,2,COBBLESTONE:0)
Block(5,0,3,COBBLESTONE:0)
Block(5,0,4,COBBLESTONE:0)
Block(5,0,5,COBBLESTONE:0)
Block(5,0,6,COBBLESTONE:0)
Block(5,1,-3,COBBLESTONE:0)
Block(5,1,-2,COBBLESTONE:0)
Block(5,1,-1,COBBLESTONE:0)
Block(5,1,0,COBBLESTONE:0)
Block(5,1,1,COBBLESTONE:0)
Block(5,1,2,COBBLESTONE:0)
Block(5,1,3,COBBLESTONE:0)
Block(5,1,4,COBBLESTONE:0)
Block(5,1,5,COBBLESTONE:0)
Block(5,1,6,COBBLESTONE:0)
Block(5,2,-3,COBBLESTONE:0)
Block(5,2,-2,COBBLESTONE:0)
Block(5,2,-1,COBBLESTONE:0)
Block(5,2,0,COBBLESTONE:0)
Block(5,2,1,COBBLESTONE:0)
Block(5,2,2,COBBLESTONE:0)
Block(5,2,3,COBBLESTONE:0)
Block(5,2,4,COBBLESTONE:0)
Block(5,2,5,COBBLESTONE:0)
Block(5,2,6,COBBLESTONE:0)
Block(5,4,-3,SPRUCE_WOOD_STAIRS:6)
Block(5,4,6,SPRUCE_WOOD_STAIRS:7)
Block(5,5,-4,SPRUCE_WOOD_STAIRS:4)
Block(5,5,3,WOOD_STEP:9)
Block(5,5,4,WOOD_STEP:9)
Block(5,5,5,WOOD_STEP:9)
Block(5,5,7,SPRUCE_WOOD_STAIRS:4)
Block(5,6,-4,SPRUCE_WOOD_STAIRS:1)
Block(5,6,-3,SPRUCE_WOOD_STAIRS:1)
Block(5,6,-2,SPRUCE_WOOD_STAIRS:1)
Block(5,6,-1,SPRUCE_WOOD_STAIRS:1)
Block(5,6,0,SPRUCE_WOOD_STAIRS:1)
Block(5,6,1,SPRUCE_WOOD_STAIRS:1)
Block(5,6,2,SPRUCE_WOOD_STAIRS:1)
Block(5,6,3,SPRUCE_WOOD_STAIRS:1)
Block(5,6,4,SPRUCE_WOOD_STAIRS:1)
Block(5,6,5,SPRUCE_WOOD_STAIRS:1)
Block(5,6,6,SPRUCE_WOOD_STAIRS:1)
Block(5,6,7,SPRUCE_WOOD_STAIRS:1)
Block(6,0,-2,COBBLESTONE:0)
Block(6,0,-1,COBBLESTONE:0)
Block(6,0,0,COBBLESTONE:0)
Block(6,0,1,COBBLESTONE:0)
Block(6,0,2,COBBLESTONE:0)
Block(6,0,3,COBBLESTONE:0)
Block(6,0,4,COBBLESTONE:0)
Block(6,0,5,COBBLESTONE:0)
Block(6,1,-2,COBBLESTONE:0)
Block(6,1,-1,COBBLESTONE:0)
Block(6,1,0,COBBLESTONE:0)
Block(6,1,1,COBBLESTONE:0)
Block(6,1,2,COBBLESTONE:0)
Block(6,1,3,COBBLESTONE:0)
Block(6,1,4,COBBLESTONE:0)
Block(6,1,5,COBBLESTONE:0)
Block(6,2,-2,COBBLESTONE:0)
Block(6,2,-1,COBBLESTONE:0)
Block(6,2,0,COBBLESTONE:0)
Block(6,2,1,COBBLESTONE:0)
Block(6,2,2,COBBLESTONE:0)
Block(6,2,3,COBBLESTONE:0)
Block(6,2,4,COBBLESTONE:0)
Block(6,2,5,COBBLESTONE:0)
Block(6,4,-4,SPRUCE_WOOD_STAIRS:4)
Block(6,4,7,SPRUCE_WOOD_STAIRS:4)
Block(6,5,-4,SPRUCE_WOOD_STAIRS:1)
Block(6,5,-3,SPRUCE_WOOD_STAIRS:1)
Block(6,5,-2,SPRUCE_WOOD_STAIRS:1)
Block(6,5,-1,SPRUCE_WOOD_STAIRS:1)
Block(6,5,0,SPRUCE_WOOD_STAIRS:1)
Block(6,5,1,SPRUCE_WOOD_STAIRS:1)
Block(6,5,2,SPRUCE_WOOD_STAIRS:1)
Block(6,5,3,SPRUCE_WOOD_STAIRS:1)
Block(6,5,4,SPRUCE_WOOD_STAIRS:1)
Block(6,5,5,SPRUCE_WOOD_STAIRS:1)
Block(6,5,6,SPRUCE_WOOD_STAIRS:1)
Block(6,5,7,SPRUCE_WOOD_STAIRS:1)
Block(7,3,-4,SPRUCE_WOOD_STAIRS:4)
Block(7,3,7,SPRUCE_WOOD_STAIRS:4)
Block(7,4,-4,SPRUCE_WOOD_STAIRS:1)
Block(7,4,-3,SPRUCE_WOOD_STAIRS:1)
Block(7,4,-2,SPRUCE_WOOD_STAIRS:1)
Block(7,4,-1,SPRUCE_WOOD_STAIRS:1)
Block(7,4,0,SPRUCE_WOOD_STAIRS:1)
Block(7,4,1,SPRUCE_WOOD_STAIRS:1)
Block(7,4,2,SPRUCE_WOOD_STAIRS:1)
Block(7,4,3,SPRUCE_WOOD_STAIRS:1)
Block(7,4,4,SPRUCE_WOOD_STAIRS:1)
Block(7,4,5,SPRUCE_WOOD_STAIRS:1)
Block(7,4,6,SPRUCE_WOOD_STAIRS:1)
Block(7,4,7,SPRUCE_WOOD_STAIRS:1)
Block(8,0,-4,COBBLESTONE:0)
Block(8,0,7,COBBLESTONE:0)
Block(8,1,-4,COBBLESTONE:0)
Block(8,1,7,COBBLESTONE:0)
Block(8,2,-4,COBBLESTONE:0)
Block(8,2,7,COBBLESTONE:0)
Block(8,3,-4,SPRUCE_WOOD_STAIRS:1)
Block(8,3,-3,SPRUCE_WOOD_STAIRS:1)
Block(8,3,-2,SPRUCE_WOOD_STAIRS:1)
Block(8,3,-1,SPRUCE_WOOD_STAIRS:1)
Block(8,3,0,SPRUCE_WOOD_STAIRS:1)
Block(8,3,1,SPRUCE_WOOD_STAIRS:1)
Block(8,3,2,SPRUCE_WOOD_STAIRS:1)
Block(8,3,3,SPRUCE_WOOD_STAIRS:1)
Block(8,3,4,SPRUCE_WOOD_STAIRS:1)
Block(8,3,5,SPRUCE_WOOD_STAIRS:1)
Block(8,3,6,SPRUCE_WOOD_STAIRS:1)
Block(8,3,7,SPRUCE_WOOD_STAIRS:1)

Entity(-1,2,1,minecraft:villager,1,../../NBT/Entities/VikingVillage/villager_farmer.txt)
Entity(2,2,3,minecraft:villager,1,../../NBT/Entities/VikingVillage/villager_farmer.txt)
