#######################################################################
# +-----------------------------------------------------------------+ #
# |                            BO3 object                           | #
# +-----------------------------------------------------------------+ #
#######################################################################

Author: Bo3 BulkEdit

Description: Converted Schematic - Modified by Bo3BulkEdit

Version: 3

SettingsMode: WriteDisable

#######################################################################
# +-----------------------------------------------------------------+ #
# |                          Main settings                          | #
# +-----------------------------------------------------------------+ #
#######################################################################

IsOTGPlus: true
Tree: false
Frequency: 1
Rarity: 100
RotateRandomly: false
SpawnHeight: randomY
SpawnHeightOffset: 0
SpawnHeightVariance: 0
MaxBranchDepth: 10
ExcludedBiomes: All

##############################
# Height Limits for the BO3. #
##############################

MinHeight: 0
MaxHeight: 256

#######################################################################
# +-----------------------------------------------------------------+ #
# |                      Source block settings                      | #
# +-----------------------------------------------------------------+ #
#######################################################################

SourceBlocks: AIR
MaxPercentageOutsideSourceBlock: 100
OutsideSourceBlock: placeAnyway

#######################################################################
# +-----------------------------------------------------------------+ #
# |                               OTG+                              | #
# +-----------------------------------------------------------------+ #
#######################################################################

BranchFrequency: 2
ReplaceWithBiomeBlocks: true
ReplaceWithGroundBlock: DIRT
ReplaceWithSurfaceBlock: GRASS
ReplaceWithStoneBlock: STONE
SmoothRadius: 0
SmoothHeightOffset: 0
IsSpawnPoint: true

#######################################################################
# +-----------------------------------------------------------------+ #
# |                              Blocks                             | #
# +-----------------------------------------------------------------+ #
#######################################################################

Block(0,750,0,AIR)
Block(15,750,15,AIR)
RandomBlock(8,11,13,SKULL:1,../../../Skulls/dungeon_skull_01.nbt,6,AIR,9,SKULL:1,../../../Skulls/dungeon_skull_02.nbt,12,AIR,15,SKULL:1,../../../Skulls/dungeon_skull_03.nbt,18,AIR,21,SKULL:1,../../../Skulls/dungeon_skull_04.nbt,24,AIR,27,SKULL:1,../../../Skulls/dungeon_skull_05.nbt,30,AIR,33,SKULL:1,../../../Skulls/dungeon_skull_06.nbt,36,AIR,39,SKULL:1,../../../Skulls/dungeon_skull_07.nbt,42,AIR,45,SKULL:1,../../../Skulls/dungeon_skull_08.nbt,48,AIR,51,SKULL:1,../../../Skulls/dungeon_skull_09.nbt,54,AIR,57,SKULL:1,../../../Skulls/dungeon_skull_10.nbt,60,AIR,63,SKULL:1,../../../Skulls/dungeon_skull_11.nbt,66,AIR,69,SKULL:1,../../../Skulls/dungeon_skull_12.nbt,72,AIR,75,SKULL:1,../../../Skulls/dungeon_skull_13.nbt,78,AIR,81,SKULL:1,../../../Skulls/dungeon_skull_14.nbt,84,AIR,87,SKULL:1,../../../Skulls/dungeon_skull_15.nbt,90,AIR,93,SKULL:1,../../../Skulls/dungeon_skull_16.nbt,96,AIR,100)
RandomBlock(5,11,15,SKULL:1,../../../Skulls/dungeon_skull_01.nbt,6,AIR,9,SKULL:1,../../../Skulls/dungeon_skull_02.nbt,12,AIR,15,SKULL:1,../../../Skulls/dungeon_skull_03.nbt,18,AIR,21,SKULL:1,../../../Skulls/dungeon_skull_04.nbt,24,AIR,27,SKULL:1,../../../Skulls/dungeon_skull_05.nbt,30,AIR,33,SKULL:1,../../../Skulls/dungeon_skull_06.nbt,36,AIR,39,SKULL:1,../../../Skulls/dungeon_skull_07.nbt,42,AIR,45,SKULL:1,../../../Skulls/dungeon_skull_08.nbt,48,AIR,51,SKULL:1,../../../Skulls/dungeon_skull_09.nbt,54,AIR,57,SKULL:1,../../../Skulls/dungeon_skull_10.nbt,60,AIR,63,SKULL:1,../../../Skulls/dungeon_skull_11.nbt,66,AIR,69,SKULL:1,../../../Skulls/dungeon_skull_12.nbt,72,AIR,75,SKULL:1,../../../Skulls/dungeon_skull_13.nbt,78,AIR,81,SKULL:1,../../../Skulls/dungeon_skull_14.nbt,84,AIR,87,SKULL:1,../../../Skulls/dungeon_skull_15.nbt,90,AIR,93,SKULL:1,../../../Skulls/dungeon_skull_16.nbt,96,AIR,100)
RandomBlock(5,16,12,WALL_BANNER:5,../NBT/Banners/Banner1.nbt,25,WALL_BANNER:5,../NBT/Banners/Banner2.nbt,25,WALL_BANNER:5,../NBT/Banners/Banner3.nbt,100)
RandomBlock(2,20,15,CHEST:4,../../../Chests/Loot/BoneChest_1.nbt,10,CHEST:4,../../../Chests/Loot/BoneChest_2.nbt,10,CHEST:4,../../../Chests/Loot/BoneChest_3.nbt,10,CHEST:4,../../../Chests/Loot/BoneChest_4.nbt,10,CHEST:4,../../../Chests/Loot/BoneChest_5.nbt,10,CHEST:4,../../../Chests/Lore/Witch_1.nbt,1,CHEST:4,../../../Chests/Lore/Witch_2.nbt,1,CHEST:4,../../../Chests/Lore/Witch_3.nbt,1,CHEST:4,../../../Chests/Lore/Witch_4.nbt,1,CHEST:4,../../../Chests/Lore/Witch_5.nbt,1,CHEST:4,../../../Chests/Loot/Common1.nbt,5,CHEST:4,../../../Chests/Loot/Common2.nbt,5,CHEST:4,../../../Chests/Loot/Common3.nbt,5,CHEST:4,../../../Chests/Loot/Common4.nbt,5,CHEST:4,../../../Chests/Loot/Common5.nbt,5,CHEST:4,../../../Chests/Loot/Common6.nbt,5,CHEST:4,../../../Chests/Loot/Common7.nbt,5,CHEST:4,../../../Chests/Loot/Common8.nbt,5,CHEST:4,../../../Chests/Loot/Common9.nbt,5,CHEST:4,../../../Chests/Loot/Common10.nbt,5,CHEST:4,../../../Chests/Loot/Common11.nbt,5,CHEST:4,../../../Chests/Loot/Common12.nbt,5,CHEST:4,../../../Chests/Loot/Common13.nbt,5,CHEST:4,../../../Chests/Loot/Common14.nbt,5,CHEST:4,../../../Chests/Loot/Common15.nbt,5,CHEST:4,../../../Chests/Lore/Witch_1.nbt,2,CHEST:4,../../../Chests/Lore/Witch_2.nbt,2,CHEST:4,../../../Chests/Lore/Witch_3.nbt,2,CHEST:4,../../../Chests/Lore/Witch_4.nbt,2,CHEST:4,../../../Chests/Lore/Witch_5.nbt,2,CHEST:4,../../../Chests/Loot/Rare1.nbt,5,CHEST:4,../../../Chests/Loot/Rare2.nbt,5,CHEST:4,../../../Chests/Loot/Rare3.nbt,5,CHEST:4,../../../Chests/Loot/Rare4.nbt,5,CHEST:4,../../../Chests/Loot/Rare5.nbt,5,CHEST:4,../../../Chests/Loot/Rare6.nbt,5,CHEST:4,../../../Chests/Loot/Rare7.nbt,5,CHEST:4,../../../Chests/Loot/Rare8.nbt,5,CHEST:4,../../../Chests/Loot/Rare9.nbt,5,CHEST:4,../../../Chests/Loot/Rare10.nbt,5,CHEST:4,../../../Chests/Loot/Rare11.nbt,5,CHEST:4,../../../Chests/Loot/Rare12.nbt,5,CHEST:4,../../../Chests/Loot/Rare13.nbt,5,CHEST:4,../../../Chests/Loot/Rare14.nbt,5,CHEST:4,../../../Chests/Loot/Rare15.nbt,5,CHEST:4,../../../Chests/Loot/Epic1.nbt,2,CHEST:4,../../../Chests/Loot/Epic2.nbt,2,CHEST:4,../../../Chests/Loot/Epic3.nbt,2,CHEST:4,../../../Chests/Loot/Epic4.nbt,2,CHEST:4,../../../Chests/Loot/Epic5.nbt,2,CHEST:4,../../../Chests/Loot/Epic6.nbt,2,CHEST:4,../../../Chests/Loot/Epic7.nbt,2,CHEST:4,../../../Chests/Loot/Epic8.nbt,2,CHEST:4,../../../Chests/Loot/Epic9.nbt,2,CHEST:4,../../../Chests/Loot/Epic10.nbt,2,CHEST:4,../../../Chests/Loot/Epic11.nbt,2,CHEST:4,../../../Chests/Loot/Epic12.nbt,2,CHEST:4,../../../Chests/Loot/Epic13.nbt,2,CHEST:4,../../../Chests/Loot/Epic14.nbt,2,CHEST:4,../../../Chests/Loot/Epic15.nbt,5,CHEST:4,../../../Chests/Loot/Rare1.nbt,5,CHEST:4,../../../Chests/Loot/Rare2.nbt,5,CHEST:4,../../../Chests/Loot/Rare3.nbt,5,CHEST:4,../../../Chests/Loot/Rare4.nbt,5,CHEST:4,../../../Chests/Loot/Rare5.nbt,10,CHEST:4,../../../Chests/Loot/Rare6.nbt,10,CHEST:4,../../../Chests/Loot/Rare7.nbt,10,CHEST:4,../../../Chests/Loot/Rare8.nbt,10,CHEST:4,../../../Chests/Loot/Rare9.nbt,10,CHEST:4,../../../Chests/Loot/Rare10.nbt,15,CHEST:4,../../../Chests/Loot/Rare11.nbt,15,CHEST:4,../../../Chests/Loot/Rare12.nbt,15,CHEST:4,../../../Chests/Loot/Rare13.nbt,15,CHEST:4,../../../Chests/Loot/Rare14.nbt,15,CHEST:4,../../../Chests/Loot/Rare15.nbt,15,CHEST:4,../../../Chests/Loot/Epic15.nbt,100)
Block(4,7,11,LOG:1)
Block(9,7,11,LOG:1)
Block(4,0,11,LOG:1)
Block(9,0,11,LOG:1)
Block(4,1,11,LOG:1)
Block(9,1,11,LOG:1)
Block(4,2,11,LOG:1)
Block(9,2,11,LOG:1)
Block(4,3,11,LOG:1)
Block(9,3,11,LOG:1)
Block(4,4,11,LOG:1)
Block(9,4,11,LOG:1)
Block(4,5,11,LOG:1)
Block(9,5,11,LOG:1)
Block(4,6,11,LOG:1)
Block(9,6,11,LOG:1)
Block(4,8,11,LOG:1)
Block(9,8,11,LOG:1)
Block(0,9,11,FENCE:0)
Block(1,9,11,FENCE:0)
Block(2,9,11,FENCE:0)
Block(3,9,11,FENCE:0)
Block(4,9,11,LOG:1)
Block(5,9,11,FENCE:0)
Block(6,9,11,FENCE:0)
Block(7,9,11,FENCE:0)
Block(8,9,11,FENCE:0)
Block(9,9,11,LOG:1)
Block(4,9,12,FENCE:0)
Block(9,9,12,FENCE:0)
Block(4,9,13,FENCE:0)
Block(9,9,13,FENCE:0)
Block(4,9,14,FENCE:0)
Block(9,9,14,FENCE:0)
Block(4,9,15,FENCE:0)
Block(9,9,15,FENCE:0)
Block(0,10,11,LOG:5)
Block(1,10,11,LOG:5)
Block(2,10,11,LOG:5)
Block(3,10,11,LOG:5)
Block(4,10,11,LOG:1)
Block(5,10,11,LOG:5)
Block(6,10,11,LOG:5)
Block(7,10,11,LOG:5)
Block(8,10,11,LOG:5)
Block(9,10,11,LOG:1)
Block(0,10,12,WOODEN_SLAB:9)
Block(1,10,12,WOODEN_SLAB:9)
Block(2,10,12,WOODEN_SLAB:9)
Block(3,10,12,WOODEN_SLAB:9)
Block(4,10,12,LOG:9)
Block(5,10,12,DIRT:2)
Block(6,10,12,DIRT:2)
Block(7,10,12,DIRT:0)
Block(8,10,12,DIRT:0)
Block(9,10,12,LOG:9)
Block(0,10,13,WOODEN_SLAB:9)
Block(1,10,13,WOODEN_SLAB:9)
Block(2,10,13,WOODEN_SLAB:9)
Block(3,10,13,WOODEN_SLAB:9)
Block(4,10,13,LOG:9)
Block(5,10,13,DIRT:2)
Block(6,10,13,MYCELIUM:0)
Block(7,10,13,DIRT:2)
Block(8,10,13,MYCELIUM:0)
Block(9,10,13,LOG:9)
Block(0,10,14,WOODEN_SLAB:9)
Block(1,10,14,WOODEN_SLAB:9)
Block(2,10,14,WOODEN_SLAB:9)
Block(3,10,14,WOODEN_SLAB:9)
Block(4,10,14,LOG:9)
Block(5,10,14,MYCELIUM:0)
Block(6,10,14,DIRT:2)
Block(7,10,14,MYCELIUM:0)
Block(8,10,14,MYCELIUM:0)
Block(9,10,14,LOG:9)
Block(0,10,15,WOODEN_SLAB:9)
Block(1,10,15,WOODEN_SLAB:9)
Block(2,10,15,WOODEN_SLAB:9)
Block(3,10,15,WOODEN_SLAB:9)
Block(4,10,15,LOG:9)
Block(5,10,15,MYCELIUM:0)
Block(6,10,15,DIRT:0)
Block(7,10,15,DIRT:2)
Block(8,10,15,DIRT:2)
Block(9,10,15,LOG:9)
Block(0,11,11,FENCE:0)
Block(1,11,11,FENCE:0)
Block(2,11,11,FENCE:0)
Block(3,11,11,STONE_BRICK_STAIRS:2)
Block(4,11,11,LOG:1)
Block(5,11,11,FENCE:0)
Block(6,11,11,FENCE:0)
Block(7,11,11,FENCE:0)
Block(8,11,11,FENCE:0)
Block(9,11,11,LOG:1)
Block(0,11,12,STONE_BRICK_STAIRS:2)
Block(1,11,12,STONE_BRICK_STAIRS:2)
Block(2,11,12,STONE_BRICK_STAIRS:2)
Block(3,11,12,STONE_BRICK_STAIRS:3)
Block(4,11,12,STONE_BRICK_STAIRS:1)
Block(5,11,12,BROWN_MUSHROOM:0)
Block(6,11,12,BROWN_MUSHROOM:0)
Block(7,11,12,WEB:0)
Block(8,11,12,DOUBLE_PLANT:2)
Block(9,11,12,FENCE:0)
Block(0,11,13,STONEBRICK:0)
Block(1,11,13,STONEBRICK:0)
Block(2,11,13,STONEBRICK:0)
Block(3,11,13,STONE_BRICK_STAIRS:1)
Block(4,11,13,FENCE:0)
Block(5,11,13,BROWN_MUSHROOM:0)
Block(6,11,13,RED_MUSHROOM:0)
Block(9,11,13,FENCE:0)
Block(0,11,14,STONEBRICK:0)
Block(1,11,14,STONEBRICK:0)
Block(2,11,14,STONEBRICK:0)
Block(3,11,14,STONE_BRICK_STAIRS:1)
Block(4,11,14,FENCE:0)
Block(5,11,14,RED_MUSHROOM:0)
Block(6,11,14,WEB:0)
Block(7,11,14,BROWN_MUSHROOM:0)
Block(8,11,14,BROWN_MUSHROOM:0)
Block(9,11,14,FENCE:0)
Block(0,11,15,STONEBRICK:0)
Block(1,11,15,STONEBRICK:0)
Block(2,11,15,STONEBRICK:0)
Block(3,11,15,STONE_BRICK_STAIRS:1)
Block(4,11,15,FENCE:0)
Block(6,11,15,DOUBLE_PLANT:2)
Block(7,11,15,DOUBLE_PLANT:3)
Block(8,11,15,DEADBUSH:0)
Block(9,11,15,FENCE:0)
Block(0,12,11,STONE_SLAB:13)
Block(1,12,11,STONE_SLAB:13)
Block(2,12,11,STONE_SLAB:13)
Block(3,12,11,STONE_BRICK_STAIRS:6)
Block(4,12,11,COBBLESTONE_WALL:0)
Block(9,12,11,COBBLESTONE_WALL:0)
Block(0,12,12,LOG_2:5)
Block(1,12,12,LOG_2:5)
Block(2,12,12,LOG_2:5)
Block(3,12,12,LOG:1)
Block(4,12,12,STONE_BRICK_STAIRS:5)
Block(8,12,12,DOUBLE_PLANT:10)
Block(0,12,13,WOODEN_SLAB:10)
Block(1,12,13,WOODEN_SLAB:10)
Block(2,12,13,WOODEN_SLAB:10)
Block(3,12,13,LOG_2:9)
Block(4,12,13,STONE_SLAB:13)
Block(0,12,14,WOODEN_SLAB:10)
Block(1,12,14,WOODEN_SLAB:10)
Block(2,12,14,WOODEN_SLAB:10)
Block(3,12,14,LOG_2:9)
Block(4,12,14,STONE_SLAB:13)
Block(0,12,15,STONE_SLAB:8)
Block(1,12,15,WOODEN_SLAB:10)
Block(2,12,15,WOODEN_SLAB:10)
Block(3,12,15,LOG_2:9)
Block(4,12,15,STONE_SLAB:13)
Block(6,12,15,DOUBLE_PLANT:10)
Block(7,12,15,DOUBLE_PLANT:10)
Block(0,13,11,COBBLESTONE_WALL:0)
Block(1,13,11,STONE_BUTTON:4)
Block(2,13,11,COBBLESTONE_WALL:0)
Block(3,13,11,STONE_BRICK_STAIRS:6)
Block(0,13,12,MONSTER_EGG:2)
Block(1,13,12,STONEBRICK:3)
Block(2,13,12,MONSTER_EGG:2)
Block(3,13,12,LOG:1)
Block(4,13,12,STONE_BRICK_STAIRS:5)
Block(0,13,13,WALL_SIGN:5)
Block(3,13,13,MONSTER_EGG:2)
Block(4,13,13,COBBLESTONE_WALL:0)
Block(1,13,14,LOG:1)
Block(2,13,14,DARK_OAK_STAIRS:6)
Block(3,13,14,STONEBRICK:3)
Block(4,13,14,STONE_BUTTON:1)
Block(0,13,15,WALL_SIGN:5)
Block(1,13,15,JUKEBOX:0)
Block(2,13,15,DARK_OAK_STAIRS:3)
Block(3,13,15,MONSTER_EGG:2)
Block(4,13,15,COBBLESTONE_WALL:0)
Block(0,14,11,STONE_SLAB:13)
Block(2,14,11,STONE_SLAB:13)
Block(3,14,11,STONE_SLAB:5)
Block(0,14,12,MONSTER_EGG:1)
Block(1,14,12,STAINED_GLASS_PANE:0)
Block(2,14,12,MONSTER_EGG:1)
Block(3,14,12,LOG:1)
Block(4,14,12,STONE_SLAB:5)
Block(1,14,13,DARK_OAK_STAIRS:4)
Block(2,14,13,DARK_OAK_STAIRS:6)
Block(3,14,13,MONSTER_EGG:1)
Block(4,14,13,STONE_SLAB:13)
Block(1,14,14,LOG:1)
Block(2,14,14,DARK_OAK_STAIRS:3)
Block(3,14,14,STAINED_GLASS_PANE:0)
Block(3,14,15,MONSTER_EGG:1)
Block(4,14,15,STONE_SLAB:13)
Block(1,15,11,STONE_SLAB:5)
Block(3,15,11,TRAPDOOR:4)
Block(0,15,12,STONE_STAIRS:2)
Block(1,15,12,STONE_STAIRS:2)
Block(2,15,12,STONE_STAIRS:2)
Block(3,15,12,LOG:1)
Block(4,15,12,TRAPDOOR:7)
Block(0,15,13,DARK_OAK_STAIRS:4)
Block(1,15,13,DARK_OAK_STAIRS:1)
Block(3,15,13,STONE_STAIRS:1)
Block(0,15,14,DARK_OAK_STAIRS:7)
Block(1,15,14,LOG:1)
Block(3,15,14,STONE_STAIRS:1)
Block(4,15,14,STONE_SLAB:5)
Block(3,15,15,STONE_STAIRS:1)
Block(1,16,10,SPRUCE_STAIRS:4)
Block(2,16,10,SPRUCE_STAIRS:1)
Block(3,16,10,SPRUCE_STAIRS:2)
Block(0,16,11,STONE_BUTTON:4)
Block(1,16,11,STONE_BUTTON:4)
Block(2,16,11,STONE_BUTTON:4)
Block(3,16,11,LOG_2:9)
Block(4,16,11,SPRUCE_STAIRS:5)
Block(0,16,12,LOG_2:5)
Block(1,16,12,LOG_2:5)
Block(2,16,12,LOG_2:5)
Block(3,16,12,LOG:1)
Block(4,16,12,LOG_2:5)
Block(3,16,13,LOG_2:9)
Block(4,16,13,STONE_BUTTON:1)
Block(0,16,14,DARK_OAK_STAIRS:2)
Block(1,16,14,LOG:1)
Block(3,16,14,LOG_2:9)
Block(4,16,14,STONE_BUTTON:1)
Block(0,16,15,DARK_OAK_STAIRS:7)
Block(1,16,15,DARK_OAK_STAIRS:5)
Block(3,16,15,LOG_2:9)
Block(4,16,15,STONE_BUTTON:1)
Block(0,17,10,SPRUCE_STAIRS:2)
Block(1,17,10,SPRUCE_STAIRS:1)
Block(0,17,11,PLANKS:0)
Block(1,17,11,PLANKS:0)
Block(2,17,11,OAK_STAIRS:1)
Block(3,17,11,OAK_STAIRS:2)
Block(4,17,11,SPRUCE_STAIRS:2)
Block(0,17,12,HAY_BLOCK:4)
Block(1,17,12,HAY_BLOCK:0)
Block(2,17,12,HAY_BLOCK:8)
Block(3,17,12,LOG:1)
Block(4,17,12,SPRUCE_STAIRS:7)
Block(3,17,13,SPRUCE_STAIRS:1)
Block(1,17,14,LOG:1)
Block(3,17,14,SPRUCE_STAIRS:1)
Block(1,17,15,DARK_OAK_FENCE:0)
Block(3,17,15,SPRUCE_STAIRS:1)
Block(0,18,11,OAK_STAIRS:2)
Block(1,18,11,OAK_STAIRS:1)
Block(0,18,12,HAY_BLOCK:8)
Block(1,18,12,OAK_STAIRS:4)
Block(2,18,12,OAK_STAIRS:1)
Block(3,18,12,OAK_STAIRS:2)
Block(4,18,12,SPRUCE_STAIRS:2)
Block(2,18,13,WEB:0)
Block(3,18,13,LOG:1)
Block(4,18,13,SPRUCE_STAIRS:7)
Block(5,18,13,SPRUCE_STAIRS:5)
Block(1,18,14,LOG:1)
Block(3,18,14,SPRUCE_STAIRS:5)
Block(3,18,15,PLANKS:1)
Block(6,18,15,TRAPDOOR:4)
Block(0,19,12,OAK_STAIRS:2)
Block(1,19,12,OAK_STAIRS:1)
Block(0,19,13,WOODEN_SLAB:9)
Block(1,19,13,OAK_STAIRS:4)
Block(2,19,13,PLANKS:0)
Block(3,19,13,PLANKS:0)
Block(4,19,13,PLANKS:0)
Block(5,19,13,PLANKS:1)
Block(1,19,14,LOG:1)
Block(2,19,14,WOODEN_SLAB:10)
Block(3,19,14,LOG:1)
Block(4,19,14,STONE_BUTTON:1)
Block(0,19,15,WOODEN_SLAB:10)
Block(1,19,15,WOODEN_SLAB:10)
Block(2,19,15,WOODEN_SLAB:10)
Block(3,19,15,PLANKS:1)
Block(0,20,13,SPRUCE_STAIRS:3)
Block(1,20,13,DOUBLE_WOODEN_SLAB:1)
Block(2,20,13,OAK_STAIRS:1)
Block(3,20,13,OAK_STAIRS:2)
Block(4,20,13,OAK_STAIRS:2)
Block(5,20,13,SPRUCE_STAIRS:2)
Block(0,20,14,PLANKS:5)
Block(1,20,14,PLANKS:0)
Block(2,20,14,PLANKS:0)
Block(3,20,14,LOG:1)
Block(4,20,14,STONE_BUTTON:1)
Block(5,20,14,SPRUCE_STAIRS:7)
Block(6,20,14,SPRUCE_STAIRS:5)
Block(3,20,15,SPRUCE_STAIRS:5)
Block(0,21,13,WOODEN_SLAB:9)
Block(1,21,13,WOODEN_SLAB:1)
Block(0,21,14,PLANKS:5)
Block(1,21,14,OAK_STAIRS:4)
Block(2,21,14,OAK_STAIRS:1)
Block(3,21,14,OAK_STAIRS:2)
Block(4,21,14,OAK_STAIRS:2)
Block(5,21,14,OAK_STAIRS:2)
Block(6,21,14,SPRUCE_STAIRS:2)
Block(3,21,15,LOG:1)
Block(4,21,15,STONE_BUTTON:1)
Block(6,21,15,SPRUCE_STAIRS:7)
Block(7,21,15,SPRUCE_STAIRS:5)
Block(0,22,14,OAK_STAIRS:2)
Block(1,22,14,OAK_STAIRS:1)
Block(1,22,15,OAK_STAIRS:4)
Block(2,22,15,OAK_STAIRS:1)
Block(3,22,15,OAK_STAIRS:2)
Block(4,22,15,OAK_STAIRS:2)
Block(5,22,15,OAK_STAIRS:2)
Block(6,22,15,OAK_STAIRS:2)
Block(7,22,15,SPRUCE_STAIRS:2)
Block(0,23,15,OAK_STAIRS:2)
Block(1,23,15,OAK_STAIRS:1)

#######################################################################
# +-----------------------------------------------------------------+ #
# |                             Branches                            | #
# +-----------------------------------------------------------------+ #
#######################################################################

Branch(-16,0,0,true,SwampHouseBig_1x1,NORTH,100,0)
