Author: NLBlackEagle
Description: No description given
SettingsMode: WriteDisable
Frequency: 0
SpawnHeight: highestBlock
UseCenterForHighestBlock: true
MinHeight: 0
MaxHeight: 255
InheritBO3: 
InheritBO3Rotation: NORTH
OverrideChildSettings: true
OverrideParentHeight: false
CanOverride: false
BranchFrequency: 0
BranchFrequencyGroup: 
MustBeBelowOther: false
MustBeInside: 
CannotBeInside: 
ReplacesBO3: 
MustBeInsideWorldBorders: false
CanSpawnOnWater: true
SpawnOnWaterOnly: false
SpawnUnderWater: false
SpawnAtWaterLevel: false
HeightOffset: 0
RemoveAir: true
ReplaceAbove: 
ReplaceBelow: 
ReplaceWithBiomeBlocks: true
ReplaceWithSurfaceBlock: GRASS
ReplaceWithGroundBlock: DIRT
ReplaceWithStoneBlock: STONE
SmoothRadius: 0
SmoothHeightOffset: 0
SmoothStartTop: false
SmoothStartWood: false
SmoothingSurfaceBlock: 
SmoothingGroundBlock: 
BO3Group: 
IsSpawnPoint: false
DoReplaceBlocks: true
Block(-8,6,-7,TRAP_DOOR:14)
Block(-8,6,-5,TRAP_DOOR:14)
Block(-7,5,-7,DARK_OAK_STAIRS:4)
Block(-7,5,-6,DARK_OAK_STAIRS:4)
Block(-7,5,-5,DARK_OAK_STAIRS:7)
Block(-7,6,-7,WOOD:0)
Block(-7,6,-6,STAINED_GLASS_PANE:15)
Block(-7,6,-5,WOOD:0)
Block(-7,6,-4,TRAP_DOOR:13)
Block(-7,7,-7,DARK_OAK_STAIRS:2)
Block(-7,7,-6,DARK_OAK_STAIRS:0)
Block(-7,7,-5,WOOD:5)
Block(-7,8,-5,ANVIL:2)
Block(-6,4,-7,WOOD:1)
RandomBlock(-6,5,-7,AIR:0,20,CHEST:5,../../../../Chests/Loot/ShipJunk_1.nbt,10,CHEST:5,../../../../Chests/Loot/ShipJunk_2.nbt,10,CHEST:5,../../../../Chests/Loot/ShipJunk_3.nbt,10,CHEST:5,../../../../Chests/Loot/ShipJunk_4.nbt,10,CHEST:5,../../../../Chests/Loot/ShipJunk_5.nbt,10,CHEST:5,../../../../Chests/Traveler/Travelers_Castle.nbt,1,CHEST:5,../../../../Chests/Traveler/Travelers_Church.nbt,1,CHEST:5,../../../../Chests/Traveler/Travelers_Daeroc.nbt,1,CHEST:5,../../../../Chests/Traveler/Travelers_Farmsteads.nbt,1,CHEST:5,../../../../Chests/Traveler/Travelers_GreenDungeon.nbt,1,CHEST:5,../../../../Chests/Traveler/Travelers_IceShips.nbt,1,CHEST:5,../../../../Chests/Traveler/Travelers_IceTemple.nbt,1,CHEST:5,../../../../Chests/Traveler/Travelers_LegacySpawn.nbt,1,CHEST:5,../../../../Chests/Traveler/Travelers_Mineshafts.nbt,1,CHEST:5,../../../../Chests/Traveler/Travelers_Mountains.nbt,1,CHEST:5,../../../../Chests/Traveler/Travelers_Origin.nbt,1,CHEST:5,../../../../Chests/Traveler/Travelers_Pirate.nbt,1,CHEST:5,../../../../Chests/Traveler/Travelers_Quarry.nbt,1,CHEST:5,../../../../Chests/Traveler/Travelers_Spook.nbt,1,CHEST:5,../../../../Chests/Traveler/Travelers_Tribal.nbt,1,CHEST:5,../../../../Chests/Lore/ShipSunk_1.nbt,1,CHEST:5,../../../../Chests/Lore/ShipSunk_2.nbt,1,CHEST:5,../../../../Chests/Lore/ShipSunk_3.nbt,1,CHEST:5,../../../../Chests/Lore/ShipSunk_4.nbt,1,CHEST:5,../../../../Chests/Lore/ShipSunk_5.nbt,1,CHEST:5,../../../../Chests/Loot/Common1.nbt,10,CHEST:5,../../../../Chests/Loot/Common2.nbt,10,CHEST:5,../../../../Chests/Loot/Common3.nbt,10,CHEST:5,../../../../Chests/Loot/Common4.nbt,10,CHEST:5,../../../../Chests/Loot/Common5.nbt,10,CHEST:5,../../../../Chests/Loot/Common6.nbt,10,CHEST:5,../../../../Chests/Loot/Common7.nbt,10,CHEST:5,../../../../Chests/Loot/Common8.nbt,10,CHEST:5,../../../../Chests/Loot/Common9.nbt,10,CHEST:5,../../../../Chests/Loot/Common10.nbt,10,CHEST:5,../../../../Chests/Loot/Common10.nbt,11,CHEST:5,../../../../Chests/Loot/Common12.nbt,10,CHEST:5,../../../../Chests/Loot/Common13.nbt,10,CHEST:5,../../../../Chests/Loot/Common14.nbt,10,CHEST:5,../../../../Chests/Loot/Common15.nbt,10,CHEST:5,../../../../Chests/Lore/ShipSunk_1.nbt,2,CHEST:5,../../../../Chests/Lore/ShipSunk_3.nbt,2,CHEST:5,../../../../Chests/Lore/ShipSunk_4.nbt,2,CHEST:5,../../../../Chests/Lore/ShipSunk_5.nbt,2,CHEST:5,../../../../Chests/Lore/ShipSunk_5.nbt,2,CHEST:5,../../../../Chests/Loot/Rare1.nbt,5,CHEST:5,../../../../Chests/Loot/Rare2.nbt,5,CHEST:5,../../../../Chests/Loot/Rare3.nbt,5,CHEST:5,../../../../Chests/Loot/Rare4.nbt,5,CHEST:5,../../../../Chests/Loot/Rare5.nbt,5,CHEST:5,../../../../Chests/Loot/Rare6.nbt,5,CHEST:5,../../../../Chests/Loot/Rare7.nbt,5,CHEST:5,../../../../Chests/Loot/Rare8.nbt,5,CHEST:5,../../../../Chests/Loot/Rare9.nbt,5,CHEST:5,../../../../Chests/Loot/Rare10.nbt,5,CHEST:5,../../../../Chests/Loot/Rare11.nbt,5,CHEST:5,../../../../Chests/Loot/Rare12.nbt,5,CHEST:5,../../../../Chests/Loot/Rare13.nbt,5,CHEST:5,../../../../Chests/Loot/Rare14.nbt,5,CHEST:5,../../../../Chests/Loot/Rare15.nbt,5,CHEST:5,../../../../Chests/Loot/Epic1.nbt,2,CHEST:5,../../../../Chests/Loot/Epic2.nbt,2,CHEST:5,../../../../Chests/Loot/Epic3.nbt,2,CHEST:5,../../../../Chests/Loot/Epic4.nbt,2,CHEST:5,../../../../Chests/Loot/Epic5.nbt,2,CHEST:5,../../../../Chests/Loot/Epic6.nbt,2,CHEST:5,../../../../Chests/Loot/Epic7.nbt,2,CHEST:5,../../../../Chests/Loot/Epic8.nbt,2,CHEST:5,../../../../Chests/Loot/Epic9.nbt,2,CHEST:5,../../../../Chests/Loot/Epic10.nbt,2,CHEST:5,../../../../Chests/Loot/Epic11.nbt,2,CHEST:5,../../../../Chests/Loot/Epic12.nbt,2,CHEST:5,../../../../Chests/Loot/Epic13.nbt,2,CHEST:5,../../../../Chests/Loot/Epic14.nbt,2,CHEST:5,../../../../Chests/Loot/Epic15.nbt,5,CHEST:5,../../../../Chests/Loot/Rare1.nbt,5,CHEST:5,../../../../Chests/Loot/Rare2.nbt,5,CHEST:5,../../../../Chests/Loot/Rare3.nbt,5,CHEST:5,../../../../Chests/Loot/Rare4.nbt,5,CHEST:5,../../../../Chests/Loot/Rare5.nbt,10,CHEST:5,../../../../Chests/Loot/Rare6.nbt,10,CHEST:5,../../../../Chests/Loot/Rare7.nbt,10,CHEST:5,../../../../Chests/Loot/Rare8.nbt,10,CHEST:5,../../../../Chests/Loot/Rare9.nbt,10,CHEST:5,../../../../Chests/Loot/Rare10.nbt,15,CHEST:5,../../../../Chests/Loot/Rare11.nbt,15,CHEST:5,../../../../Chests/Loot/Rare12.nbt,15,CHEST:5,../../../../Chests/Loot/Rare13.nbt,15,CHEST:5,../../../../Chests/Loot/Rare14.nbt,15,CHEST:5,../../../../Chests/Loot/Rare15.nbt,15,CHEST:5,../../../../Chests/Loot/Epic15.nbt,100)
Block(-6,5,-6,WOOD:5)
Block(-6,5,-5,DARK_OAK_STAIRS:7)
Block(-6,6,-7,AIR:0)
Block(-6,6,-6,AIR:0)
Block(-6,6,-5,STAINED_GLASS_PANE:15)
Block(-6,7,-7,WOOD_STEP:13)
Block(-6,7,-6,AIR:0)
Block(-6,7,-5,WOOD:5)
Block(-6,8,-7,DARK_OAK_STAIRS:6)
Block(-6,8,-6,WOOD:5)
Block(-6,8,-5,DARK_OAK_STAIRS:0)
Block(-6,9,-7,WOOD_STEP:13)
Block(-6,9,-6,DARK_OAK_STAIRS:6)
Block(-6,9,-5,LEVER:10)
Block(-5,3,-7,WOOD:1)
Block(-5,4,-7,WOOD:1)
Block(-5,4,-6,WOOD_STEP:9)
Block(-5,5,-7,AIR:0)
Block(-5,5,-6,AIR:0)
Block(-5,5,-5,DARK_OAK_STAIRS:7)
Block(-5,6,-7,AIR:0)
Block(-5,6,-6,AIR:0)
Block(-5,6,-5,WOOD:0)
Block(-5,6,-4,DARK_OAK_FENCE:0)
Block(-5,7,-7,AIR:0)
Block(-5,7,-6,AIR:0)
Block(-5,7,-5,WOOD:5)
Block(-5,8,-7,WOOD_DOUBLE_STEP:0)
Block(-5,8,-6,WOOD_STEP:8)
Block(-5,8,-5,WOOD:5)
Block(-5,8,-4,DARK_OAK_STAIRS:3)
Block(-5,9,-5,WOOD:5)
Block(-5,9,-4,LEVER:10)
Block(-5,10,-3,TRAP_DOOR:6)
Block(-4,2,-7,WOOD:1)
Block(-4,3,-7,WOOD:1)
Block(-4,3,-6,WOOD:1)
Block(-4,4,-7,STATIONARY_WATER:0)
Block(-4,4,-6,WOOD:1)
Block(-4,5,-7,AIR:0)
Block(-4,5,-6,AIR:0)
Block(-4,5,-5,DARK_OAK_STAIRS:7)
Block(-4,6,-7,AIR:0)
Block(-4,6,-6,AIR:0)
Block(-4,6,-5,STAINED_GLASS_PANE:15)
Block(-4,7,-7,AIR:0)
Block(-4,7,-6,AIR:0)
Block(-4,7,-5,WOOD:5)
Block(-4,7,-4,DARK_OAK_STAIRS:4)
Block(-4,8,-7,WOOD_STEP:8)
Block(-4,8,-6,WOOD_STEP:8)
Block(-4,8,-5,WOOD_DOUBLE_STEP:0)
Block(-4,8,-4,WOOD:5)
Block(-4,9,-4,WOOD:5)
Block(-4,9,-3,COBBLE_WALL:0)
Block(-4,10,-4,TRAP_DOOR:4)
Block(-4,10,-3,REDSTONE_LAMP_OFF:0)
Block(-4,10,-2,TRAP_DOOR:5)
Block(-4,11,-3,WOOD_STEP:5)
Block(-3,2,-7,WOOD:1)
Block(-3,2,-6,WOOD:1)
Block(-3,3,-7,STATIONARY_WATER:0)
Block(-3,3,-6,WOOD:1)
Block(-3,4,-7,STATIONARY_WATER:0)
Block(-3,4,-6,WOOD:1)
Block(-3,5,-7,AIR:0)
Block(-3,5,-6,AIR:0)
Block(-3,5,-5,DARK_OAK_STAIRS:7)
Block(-3,6,-7,AIR:0)
Block(-3,6,-6,AIR:0)
Block(-3,6,-5,WOOD:0)
Block(-3,6,-4,DARK_OAK_FENCE:0)
Block(-3,7,-7,AIR:0)
Block(-3,7,-6,AIR:0)
Block(-3,7,-5,WOOD:5)
Block(-3,7,-4,ANVIL:1)
Block(-3,8,-7,WOOD_STEP:8)
Block(-3,8,-6,WOOD_STEP:8)
Block(-3,8,-5,WOOD_DOUBLE_STEP:0)
Block(-3,8,-4,DARK_OAK_STAIRS:5)
Block(-3,9,-4,DARK_OAK_STAIRS:5)
Block(-3,10,-4,WOOD_STEP:5)
Block(-3,10,-3,TRAP_DOOR:7)
Block(-2,0,-7,WOOD:1)
Block(-2,0,-6,DARK_OAK_FENCE:0)
Block(-2,0,-5,WOOD:1)
Block(-2,0,-4,WOOD:1)
Block(-2,1,-7,WOOD:1)
Block(-2,1,-6,DARK_OAK_FENCE:0)
Block(-2,1,-5,WOOD:1)
Block(-2,1,-4,WOOD:1)
Block(-2,2,-7,WOOD:1)
Block(-2,2,-6,WOOD:1)
Block(-2,2,-5,WOOD:1)
Block(-2,2,-4,WOOD:1)
Block(-2,3,-7,STATIONARY_WATER:0)
Block(-2,3,-6,WOOD:1)
Block(-2,3,-5,WOOD:1)
Block(-2,3,-4,SPRUCE_WOOD_STAIRS:3)
Block(-2,4,-7,WOOD_STEP:8)
Block(-2,4,-6,WOOD:1)
Block(-2,4,-5,ANVIL:2)
Block(-2,5,-7,AIR:0)
Block(-2,5,-6,AIR:0)
Block(-2,5,-5,DARK_OAK_STAIRS:7)
Block(-2,6,-7,AIR:0)
Block(-2,6,-6,AIR:0)
Block(-2,6,-5,STAINED_GLASS_PANE:15)
Block(-2,7,-7,AIR:0)
Block(-2,7,-6,AIR:0)
Block(-2,7,-5,WOOD:5)
Block(-2,7,-4,WOOD_STEP:13)
Block(-2,8,-7,WOOD_STEP:8)
Block(-2,8,-6,WOOD_STEP:8)
Block(-2,8,-5,WOOD_DOUBLE_STEP:0)
Block(-2,8,-4,WOOD_STEP:13)
Block(-2,9,-4,ANVIL:1)
Block(-2,10,-4,WOOD_STEP:5)
Block(-1,2,-7,WOOD:1)
Block(-1,2,-6,WOOD:1)
Block(-1,3,-7,STATIONARY_WATER:0)
Block(-1,3,-6,WOOD:1)
Block(-1,4,-7,WOOD_STEP:8)
Block(-1,4,-6,WOOD:1)
Block(-1,5,-7,DARK_OAK_STAIRS:5)
Block(-1,5,-6,AIR:0)
Block(-1,5,-5,DARK_OAK_STAIRS:7)
Block(-1,6,-7,AIR:0)
Block(-1,6,-6,AIR:0)
Block(-1,6,-5,WOOD:0)
Block(-1,6,-4,DARK_OAK_FENCE:0)
Block(-1,7,-7,AIR:0)
Block(-1,7,-6,AIR:0)
Block(-1,7,-5,WOOD:5)
Block(-1,7,-4,ANVIL:1)
Block(-1,8,-7,WOOD_STEP:8)
Block(-1,8,-6,WOOD_STEP:8)
Block(-1,8,-5,WOOD_DOUBLE_STEP:0)
Block(-1,8,-4,DARK_OAK_STAIRS:4)
Block(-1,9,-7,WOOD:2)
Block(-1,9,-6,WOOD:2)
Block(-1,9,-4,DARK_OAK_STAIRS:4)
Block(-1,10,-7,WOOD:2)
Block(-1,10,-6,WOOD:2)
Block(-1,10,-4,WOOD_STEP:5)
Block(-1,10,-3,TRAP_DOOR:6)
Block(0,2,-7,WOOD:1)
Block(0,3,-7,STATIONARY_WATER:0)
Block(0,3,-6,WOOD:1)
Block(0,4,-7,WOOD_STEP:8)
Block(0,4,-6,WOOD:1)
Block(0,5,-7,DARK_OAK_STAIRS:4)
Block(0,5,-6,AIR:0)
Block(0,5,-5,DARK_OAK_STAIRS:7)
Block(0,6,-7,AIR:0)
Block(0,6,-6,AIR:0)
Block(0,6,-5,STAINED_GLASS_PANE:15)
Block(0,7,-7,AIR:0)
Block(0,7,-6,AIR:0)
Block(0,7,-5,WOOD:5)
Block(0,7,-4,DARK_OAK_STAIRS:5)
Block(0,8,-7,WOOD_STEP:8)
Block(0,8,-6,WOOD_STEP:8)
Block(0,8,-5,WOOD_DOUBLE_STEP:0)
Block(0,8,-4,WOOD:5)
Block(0,9,-7,WOOD:2)
Block(0,9,-6,WOOD:2)
Block(0,9,-4,WOOD:5)
Block(0,9,-3,COBBLE_WALL:0)
Block(0,10,-7,WOOD:2)
Block(0,10,-6,WOOD:2)
Block(0,10,-4,TRAP_DOOR:4)
Block(0,10,-3,REDSTONE_LAMP_OFF:0)
Block(0,10,-2,TRAP_DOOR:5)
Block(0,11,-3,WOOD_STEP:5)
Block(1,3,-7,WOOD:1)
Block(1,4,-7,WOOD:1)
Block(1,4,-6,WOOD_STEP:9)
Block(1,5,-7,AIR:0)
Block(1,5,-6,AIR:0)
Block(1,5,-5,DARK_OAK_STAIRS:7)
Block(1,6,-7,AIR:0)
Block(1,6,-6,AIR:0)
Block(1,6,-5,WOOD:0)
Block(1,6,-4,DARK_OAK_FENCE:0)
Block(1,7,-7,AIR:0)
Block(1,7,-6,AIR:0)
Block(1,7,-5,WOOD:5)
Block(1,8,-7,WOOD_DOUBLE_STEP:0)
Block(1,8,-6,WOOD_STEP:8)
Block(1,8,-5,WOOD:5)
Block(1,8,-4,DARK_OAK_STAIRS:3)
Block(1,9,-5,WOOD:5)
Block(1,9,-4,LEVER:9)
Block(1,10,-3,TRAP_DOOR:7)
Block(2,4,-7,WOOD:1)
RandomBlock(2,5,-7,CHEST:4,../../../../Chests/Traveler/Travelers_Castle.nbt,1,CHEST:4,../../../../Chests/Traveler/Travelers_Church.nbt,1,CHEST:4,../../../../Chests/Traveler/Travelers_Daeroc.nbt,1,CHEST:4,../../../../Chests/Traveler/Travelers_Farmsteads.nbt,1,CHEST:4,../../../../Chests/Traveler/Travelers_GreenDungeon.nbt,1,CHEST:4,../../../../Chests/Traveler/Travelers_IceShips.nbt,1,CHEST:4,../../../../Chests/Traveler/Travelers_IceTemple.nbt,1,CHEST:4,../../../../Chests/Traveler/Travelers_LegacySpawn.nbt,1,CHEST:4,../../../../Chests/Traveler/Travelers_Mineshafts.nbt,1,CHEST:4,../../../../Chests/Traveler/Travelers_Mountains.nbt,1,CHEST:4,../../../../Chests/Traveler/Travelers_Origin.nbt,1,CHEST:4,../../../../Chests/Traveler/Travelers_Pirate.nbt,1,CHEST:4,../../../../Chests/Traveler/Travelers_Quarry.nbt,1,CHEST:4,../../../../Chests/Traveler/Travelers_Spook.nbt,1,CHEST:4,../../../../Chests/Traveler/Travelers_Tribal.nbt,1,CHEST:4,../../../../Chests/Lore/ShipSunk_1.nbt,1,CHEST:4,../../../../Chests/Lore/ShipSunk_2.nbt,1,CHEST:4,../../../../Chests/Lore/ShipSunk_3.nbt,1,CHEST:4,../../../../Chests/Lore/ShipSunk_4.nbt,1,CHEST:4,../../../../Chests/Lore/ShipSunk_5.nbt,1,CHEST:4,../../../../Chests/Loot/Common1.nbt,5,CHEST:4,../../../../Chests/Loot/Common2.nbt,5,CHEST:4,../../../../Chests/Loot/Common3.nbt,5,CHEST:4,../../../../Chests/Loot/Common4.nbt,5,CHEST:4,../../../../Chests/Loot/Common5.nbt,5,CHEST:4,../../../../Chests/Loot/Common6.nbt,5,CHEST:4,../../../../Chests/Loot/Common7.nbt,5,CHEST:4,../../../../Chests/Loot/Common8.nbt,5,CHEST:4,../../../../Chests/Loot/Common9.nbt,5,CHEST:4,../../../../Chests/Loot/Common10.nbt,5,CHEST:4,../../../../Chests/Loot/Common11.nbt,5,CHEST:4,../../../../Chests/Loot/Common12.nbt,5,CHEST:4,../../../../Chests/Loot/Common13.nbt,5,CHEST:4,../../../../Chests/Loot/Common14.nbt,5,CHEST:4,../../../../Chests/Loot/Common15.nbt,5,CHEST:4,../../../../Chests/Lore/ShipSunk_1.nbt,2,CHEST:4,../../../../Chests/Lore/ShipSunk_2.nbt,2,CHEST:4,../../../../Chests/Lore/ShipSunk_3.nbt,2,CHEST:4,../../../../Chests/Lore/ShipSunk_4.nbt,2,CHEST:4,../../../../Chests/Lore/ShipSunk_5.nbt,2,CHEST:4,../../../../Chests/Loot/Rare1.nbt,5,CHEST:4,../../../../Chests/Loot/Rare2.nbt,5,CHEST:4,../../../../Chests/Loot/Rare3.nbt,5,CHEST:4,../../../../Chests/Loot/Rare4.nbt,5,CHEST:4,../../../../Chests/Loot/Rare5.nbt,5,CHEST:4,../../../../Chests/Loot/Rare6.nbt,5,CHEST:4,../../../../Chests/Loot/Rare7.nbt,5,CHEST:4,../../../../Chests/Loot/Rare8.nbt,5,CHEST:4,../../../../Chests/Loot/Rare9.nbt,5,CHEST:4,../../../../Chests/Loot/Rare10.nbt,5,CHEST:4,../../../../Chests/Loot/Rare11.nbt,5,CHEST:4,../../../../Chests/Loot/Rare12.nbt,5,CHEST:4,../../../../Chests/Loot/Rare13.nbt,5,CHEST:4,../../../../Chests/Loot/Rare14.nbt,5,CHEST:4,../../../../Chests/Loot/Rare15.nbt,5,CHEST:4,../../../../Chests/Loot/Epic1.nbt,2,CHEST:4,../../../../Chests/Loot/Epic2.nbt,2,CHEST:4,../../../../Chests/Loot/Epic3.nbt,2,CHEST:4,../../../../Chests/Loot/Epic4.nbt,2,CHEST:4,../../../../Chests/Loot/Epic5.nbt,2,CHEST:4,../../../../Chests/Loot/Epic6.nbt,2,CHEST:4,../../../../Chests/Loot/Epic7.nbt,2,CHEST:4,../../../../Chests/Loot/Epic8.nbt,2,CHEST:4,../../../../Chests/Loot/Epic9.nbt,2,CHEST:4,../../../../Chests/Loot/Epic10.nbt,2,CHEST:4,../../../../Chests/Loot/Epic11.nbt,2,CHEST:4,../../../../Chests/Loot/Epic12.nbt,2,CHEST:4,../../../../Chests/Loot/Epic13.nbt,2,CHEST:4,../../../../Chests/Loot/Epic14.nbt,2,CHEST:4,../../../../Chests/Loot/Epic15.nbt,5,CHEST:4,../../../../Chests/Loot/Rare1.nbt,5,CHEST:4,../../../../Chests/Loot/Rare2.nbt,5,CHEST:4,../../../../Chests/Loot/Rare3.nbt,5,CHEST:4,../../../../Chests/Loot/Rare4.nbt,5,CHEST:4,../../../../Chests/Loot/Rare5.nbt,10,CHEST:4,../../../../Chests/Loot/Rare6.nbt,10,CHEST:4,../../../../Chests/Loot/Rare7.nbt,10,CHEST:4,../../../../Chests/Loot/Rare8.nbt,10,CHEST:4,../../../../Chests/Loot/Rare9.nbt,10,CHEST:4,../../../../Chests/Loot/Rare10.nbt,15,CHEST:4,../../../../Chests/Loot/Rare11.nbt,15,CHEST:4,../../../../Chests/Loot/Rare12.nbt,15,CHEST:4,../../../../Chests/Loot/Rare13.nbt,15,CHEST:4,../../../../Chests/Loot/Rare14.nbt,15,CHEST:4,../../../../Chests/Loot/Rare15.nbt,15,CHEST:4,../../../../Chests/Loot/Epic15.nbt,100)
Block(2,5,-6,WOOD:5)
Block(2,5,-5,DARK_OAK_STAIRS:7)
Block(2,6,-7,AIR:0)
Block(2,6,-6,AIR:0)
Block(2,6,-5,STAINED_GLASS_PANE:15)
Block(2,7,-7,WOOD_STEP:13)
Block(2,7,-6,AIR:0)
Block(2,7,-5,WOOD:5)
Block(2,8,-7,DARK_OAK_STAIRS:6)
Block(2,8,-6,WOOD:5)
Block(2,8,-5,DARK_OAK_STAIRS:1)
Block(2,9,-7,WOOD_STEP:13)
Block(2,9,-6,DARK_OAK_STAIRS:6)
Block(2,9,-5,LEVER:9)
Block(3,5,-7,DARK_OAK_STAIRS:5)
Block(3,5,-6,DARK_OAK_STAIRS:5)
Block(3,5,-5,DARK_OAK_STAIRS:7)
Block(3,6,-7,WOOD:0)
Block(3,6,-6,STAINED_GLASS_PANE:15)
Block(3,6,-5,WOOD:0)
Block(3,6,-4,TRAP_DOOR:13)
Block(3,7,-7,DARK_OAK_STAIRS:2)
Block(3,7,-6,DARK_OAK_STAIRS:1)
Block(3,7,-5,WOOD:5)
Block(3,8,-5,ANVIL:0)
Block(4,6,-7,TRAP_DOOR:15)
Block(4,6,-5,TRAP_DOOR:15)
