Author: NLBlackEagle
Description: No description given
SettingsMode: WriteDisable
Frequency: 0
SpawnHeight: highestBlock
UseCenterForHighestBlock: true
MinHeight: 0
MaxHeight: 255
InheritBO3: 
InheritBO3Rotation: NORTH
OverrideChildSettings: true
OverrideParentHeight: false
CanOverride: false
BranchFrequency: 0
BranchFrequencyGroup: 
MustBeBelowOther: false
MustBeInside: 
CannotBeInside: 
ReplacesBO3: 
MustBeInsideWorldBorders: false
CanSpawnOnWater: true
SpawnOnWaterOnly: false
SpawnUnderWater: false
SpawnAtWaterLevel: false
HeightOffset: 0
RemoveAir: true
ReplaceAbove: 
ReplaceBelow: 
ReplaceWithBiomeBlocks: false
ReplaceWithSurfaceBlock: GRASS
ReplaceWithGroundBlock: DIRT
ReplaceWithStoneBlock: STONE
SmoothRadius: 0
SmoothHeightOffset: 0
SmoothStartTop: false
SmoothStartWood: false
SmoothingSurfaceBlock: 
SmoothingGroundBlock: 
BO3Group: 
IsSpawnPoint: false
DoReplaceBlocks: false
Block(-8,7,-1,WOOD_STEP:5)
Block(-8,7,0,WOOD_STEP:5)
Block(-8,7,1,WOOD_STEP:5)
Block(-8,7,2,WOOD_STEP:5)
Block(-8,8,-2,WOOD_STEP:0)
Block(-8,8,1,WOOD_STEP:0)
Block(-8,8,7,TRAP_DOOR:6)
Block(-7,6,-4,DARK_OAK_STAIRS:3)
Block(-7,6,-3,DARK_OAK_STAIRS:0)
Block(-7,6,-2,DARK_OAK_STAIRS:2)
Block(-7,6,-1,WOOD:5)
Block(-7,6,0,WOOD:5)
Block(-7,6,1,WOOD:5)
Block(-7,6,2,WOOD:5)
Block(-7,7,-4,DARK_OAK_STAIRS:7)
Block(-7,7,-3,WOOD_STEP:13)
Block(-7,7,-2,DARK_OAK_STAIRS:6)
Block(-7,7,-1,WOOD:5)
Block(-7,7,0,WOOD:5)
Block(-7,7,1,WOOD:5)
Block(-7,7,2,WOOD:5)
Block(-7,7,3,WOOD:5)
Block(-7,7,7,WOOD_STEP:13)
Block(-7,7,8,WOOD_STEP:13)
Block(-7,8,-4,WOOD:0)
Block(-7,8,-3,WOOD:0)
Block(-7,8,-1,WOOD:0)
Block(-7,8,0,WOOD:0)
Block(-7,8,1,STATIONARY_WATER:0)
Block(-7,8,2,WOOD:0)
Block(-7,8,3,WOOD:0)
Block(-7,8,4,WOOD_STEP:0)
Block(-7,8,6,TRAP_DOOR:4)
Block(-7,8,7,WOOD:0)
Block(-7,8,8,STATIONARY_WATER:0)
Block(-7,9,-4,WOOD:5)
Block(-7,9,-3,WOOD:5)
Block(-7,9,-1,WOOD:5)
Block(-7,9,0,WOOD:5)
Block(-7,9,1,STATIONARY_WATER:0)
Block(-7,9,2,WOOD:5)
Block(-7,9,3,WOOD:5)
Block(-7,9,7,DARK_OAK_STAIRS:2)
Block(-7,9,8,DARK_OAK_STAIRS:0)
Block(-7,10,-6,WOOD:5)
Block(-7,10,-5,WOOD:5)
Block(-7,10,-4,WOOD:5)
Block(-7,10,-3,WOOD:5)
Block(-7,10,-2,WOOD:5)
Block(-7,10,-1,WOOD:5)
Block(-7,10,0,WOOD:5)
Block(-7,10,1,WOOD:5)
Block(-7,10,2,WOOD:5)
Block(-7,11,-7,WOOD:1)
Block(-7,11,-6,WOOD:1)
Block(-7,11,-5,WOOD:1)
Block(-7,11,-4,WOOD:1)
Block(-7,11,-3,WOOD:1)
Block(-7,11,-2,WOOD:1)
Block(-7,11,-1,WOOD:1)
Block(-7,11,0,WOOD:1)
Block(-7,11,1,WOOD:1)
Block(-7,11,2,WOOD:1)
Block(-7,12,-7,WOOD:1)
Block(-7,12,-6,WOOD:1)
Block(-7,12,-5,WOOD:1)
Block(-7,12,-4,WOOD:1)
Block(-7,12,-3,WOOD:1)
Block(-7,12,-2,WOOD:1)
Block(-6,5,4,WOOD_STEP:13)
Block(-6,5,5,WOOD_STEP:13)
Block(-6,5,6,WOOD:5)
Block(-6,5,7,DARK_OAK_STAIRS:3)
Block(-6,5,8,WOOD_STEP:5)
Block(-6,6,3,WOOD:5)
Block(-6,6,4,DARK_OAK_STAIRS:3)
Block(-6,6,5,WOOD_DOUBLE_STEP:5)
Block(-6,6,6,DARK_OAK_STAIRS:3)
Block(-6,6,7,WOOD_STEP:5)
Block(-6,6,8,WOOD_STEP:5)
Block(-6,7,1,WOOD_DOUBLE_STEP:0)
Block(-6,7,2,WOOD_DOUBLE_STEP:0)
Block(-6,7,3,WOOD_DOUBLE_STEP:0)
Block(-6,7,4,DARK_OAK_STAIRS:7)
Block(-6,7,5,DARK_OAK_STAIRS:6)
Block(-6,7,6,WOOD:5)
Block(-6,7,7,WOOD_STEP:5)
Block(-6,7,8,WOOD_STEP:5)
Block(-6,8,0,STATIONARY_WATER:0)
Block(-6,8,1,STATIONARY_WATER:0)
Block(-6,8,2,STATIONARY_WATER:0)
Block(-6,8,3,STATIONARY_WATER:0)
Block(-6,8,4,STATIONARY_WATER:0)
Block(-6,8,5,WOOD:0)
Block(-6,8,6,WOOD:0)
Block(-6,8,7,STATIONARY_WATER:0)
Block(-6,8,8,STATIONARY_WATER:0)
Block(-6,9,-7,STATIONARY_WATER:0)
Block(-6,9,-6,STATIONARY_WATER:0)
Block(-6,9,-5,STATIONARY_WATER:0)
Block(-6,9,-1,STATIONARY_WATER:0)
Block(-6,9,0,STATIONARY_WATER:0)
Block(-6,9,1,STATIONARY_WATER:0)
Block(-6,9,2,STATIONARY_WATER:0)
Block(-6,9,3,STATIONARY_WATER:0)
Block(-6,9,4,STATIONARY_WATER:0)
Block(-6,9,5,WOOD:5)
Block(-6,9,6,WOOD:5)
Block(-6,9,7,WOOD:5)
Block(-6,9,8,STATIONARY_WATER:0)
Block(-6,10,-7,STATIONARY_WATER:0)
Block(-6,10,-6,STATIONARY_WATER:0)
Block(-6,10,-5,WOOD_STEP:0)
Block(-6,10,-4,WOOD_DOUBLE_STEP:0)
Block(-6,10,-3,WOOD_DOUBLE_STEP:0)
Block(-6,10,-2,WOOD_DOUBLE_STEP:0)
Block(-6,10,-1,WOOD_DOUBLE_STEP:0)
Block(-6,10,0,WOOD_DOUBLE_STEP:0)
Block(-6,10,1,WOOD_DOUBLE_STEP:0)
Block(-6,10,2,WOOD_DOUBLE_STEP:0)
Block(-6,10,3,WOOD:5)
Block(-6,10,4,WOOD:5)
Block(-6,10,5,WOOD:5)
Block(-6,10,6,WOOD:1)
Block(-6,10,7,WOOD:1)
Block(-6,10,8,WOOD:1)
Block(-6,11,-7,STATIONARY_WATER:0)
Block(-6,11,-6,STATIONARY_WATER:0)
Block(-6,11,-5,STATIONARY_WATER:0)
Block(-6,11,-4,WOOD:1)
Block(-6,11,-3,AIR:0)
Block(-6,11,-2,AIR:0)
Block(-6,11,-1,AIR:0)
Block(-6,11,0,AIR:0)
Block(-6,11,1,AIR:0)
Block(-6,11,2,AIR:0)
Block(-6,11,3,WOOD:1)
Block(-6,11,4,WOOD:1)
Block(-6,11,5,WOOD:1)
Block(-6,11,6,WOOD:1)
Block(-6,11,7,WOOD:1)
Block(-6,11,8,WOOD:1)
Block(-6,12,-7,STATIONARY_WATER:0)
Block(-6,12,-6,STATIONARY_WATER:0)
Block(-6,12,-5,STATIONARY_WATER:0)
Block(-6,12,-4,WOOD:1)
Block(-6,12,-3,AIR:0)
Block(-6,12,-2,AIR:0)
Block(-6,12,-1,WOOD:1)
Block(-6,12,0,WOOD:1)
Block(-6,12,1,WOOD:1)
Block(-6,12,2,WOOD:1)
Block(-6,12,3,WOOD:1)
Block(-6,12,4,WOOD:1)
Block(-6,12,5,WOOD:1)
Block(-6,13,-7,WOOD:1)
Block(-6,13,-6,WOOD:1)
Block(-6,13,-5,WOOD:1)
Block(-6,13,-4,WOOD:1)
Block(-6,13,-3,WOOD:1)
Block(-6,13,-2,WOOD:1)
Block(-6,13,-1,WOOD:1)
Block(-6,13,0,WOOD:1)
Block(-5,6,4,WOOD_STEP:8)
Block(-5,6,5,WOOD_STEP:8)
Block(-5,6,6,WOOD_STEP:8)
Block(-5,6,7,WOOD_DOUBLE_STEP:0)
Block(-5,6,8,WOOD_DOUBLE_STEP:0)
Block(-5,7,1,WOOD_STEP:0)
Block(-5,7,2,WOOD_STEP:0)
Block(-5,7,3,WOOD_STEP:0)
Block(-5,7,4,WOOD_STEP:0)
Block(-5,7,5,WOOD_DOUBLE_STEP:0)
Block(-5,7,6,STATIONARY_WATER:0)
Block(-5,7,7,STATIONARY_WATER:0)
Block(-5,7,8,STATIONARY_WATER:0)
Block(-5,8,-7,STATIONARY_WATER:0)
Block(-5,8,-6,STATIONARY_WATER:0)
Block(-5,8,-5,STATIONARY_WATER:0)
Block(-5,8,0,STATIONARY_WATER:0)
Block(-5,8,1,STATIONARY_WATER:0)
Block(-5,8,2,STATIONARY_WATER:0)
Block(-5,8,3,STATIONARY_WATER:0)
Block(-5,8,4,STATIONARY_WATER:0)
Block(-5,8,5,WOOD:1)
Block(-5,8,6,STATIONARY_WATER:0)
Block(-5,8,7,STATIONARY_WATER:0)
Block(-5,8,8,STATIONARY_WATER:0)
Block(-5,9,-7,STATIONARY_WATER:0)
Block(-5,9,-6,STATIONARY_WATER:0)
Block(-5,9,-5,STATIONARY_WATER:0)
Block(-5,9,-4,STATIONARY_WATER:0)
Block(-5,9,-3,STATIONARY_WATER:0)
Block(-5,9,-2,STATIONARY_WATER:0)
Block(-5,9,-1,STATIONARY_WATER:0)
Block(-5,9,0,STATIONARY_WATER:0)
Block(-5,9,1,STATIONARY_WATER:0)
Block(-5,9,2,STATIONARY_WATER:0)
Block(-5,9,3,STATIONARY_WATER:0)
Block(-5,9,4,STATIONARY_WATER:0)
Block(-5,9,5,WOOD:1)
Block(-5,9,6,STATIONARY_WATER:0)
Block(-5,9,7,STATIONARY_WATER:0)
Block(-5,9,8,STATIONARY_WATER:0)
Block(-5,10,-7,STATIONARY_WATER:0)
Block(-5,10,-6,STATIONARY_WATER:0)
Block(-5,10,-5,WOOD_STEP:0)
Block(-5,10,-4,WOOD_DOUBLE_STEP:0)
Block(-5,10,-3,WOOD_DOUBLE_STEP:0)
Block(-5,10,-2,WOOD_DOUBLE_STEP:0)
Block(-5,10,-1,WOOD_DOUBLE_STEP:0)
Block(-5,10,0,WOOD_DOUBLE_STEP:0)
Block(-5,10,1,WOOD_DOUBLE_STEP:0)
Block(-5,10,2,WOOD_DOUBLE_STEP:0)
Block(-5,10,3,WOOD_DOUBLE_STEP:0)
Block(-5,10,4,WOOD_STEP:0)
Block(-5,10,5,WOOD_STEP:0)
Block(-5,10,6,WOOD_STEP:0)
Block(-5,10,7,WOOD_STEP:0)
Block(-5,10,8,WOOD_STEP:0)
Block(-5,11,-7,STATIONARY_WATER:0)
Block(-5,11,-6,STATIONARY_WATER:0)
Block(-5,11,-5,STATIONARY_WATER:0)
Block(-5,11,-4,WOOD:1)
Block(-5,11,-3,AIR:0)
Block(-5,11,-2,AIR:0)
Block(-5,11,-1,AIR:0)
Block(-5,11,0,AIR:0)
Block(-5,11,1,AIR:0)
Block(-5,11,2,AIR:0)
Block(-5,11,3,WOOD:1)
Block(-5,11,4,AIR:0)
Block(-5,11,5,AIR:0)
Block(-5,11,6,AIR:0)
Block(-5,11,7,AIR:0)
Block(-5,11,8,WOOD:1)
Block(-5,12,-7,STATIONARY_WATER:0)
Block(-5,12,-6,SPRUCE_FENCE:0)
Block(-5,12,-5,STATIONARY_WATER:0)
Block(-5,12,-4,WOOD:1)
Block(-5,12,-3,AIR:0)
Block(-5,12,-2,AIR:0)
Block(-5,12,-1,AIR:0)
Block(-5,12,0,AIR:0)
Block(-5,12,1,AIR:0)
Block(-5,12,2,AIR:0)
Block(-5,12,3,WOOD:1)
Block(-5,12,4,WOOD:1)
Block(-5,12,5,WOOD:1)
Block(-5,12,6,WOOD:1)
Block(-5,12,7,WOOD:1)
Block(-5,13,-7,WOOD:1)
Block(-5,13,-6,WOOD:1)
Block(-5,13,-5,WOOD:1)
Block(-5,13,-4,WOOD:1)
Block(-5,13,-3,WOOD:1)
Block(-5,13,-2,WOOD:1)
Block(-5,13,-1,WOOD:1)
Block(-5,13,0,WOOD:1)
Block(-5,13,1,WOOD:1)
Block(-5,13,2,WOOD:1)
Block(-4,5,-2,STATIONARY_WATER:0)
Block(-4,6,-2,STATIONARY_WATER:0)
Block(-4,6,5,WOOD_STEP:8)
Block(-4,6,6,WOOD_STEP:8)
Block(-4,6,7,WOOD_STEP:0)
Block(-4,6,8,WOOD_STEP:0)
Block(-4,7,-7,WOOD_DOUBLE_STEP:0)
Block(-4,7,-6,WOOD_DOUBLE_STEP:0)
Block(-4,7,-5,STATIONARY_WATER:0)
Block(-4,7,-2,STATIONARY_WATER:0)
Block(-4,7,-1,STATIONARY_WATER:0)
Block(-4,7,0,WOOD_STEP:0)
Block(-4,7,1,WOOD_STEP:0)
Block(-4,7,2,WOOD_STEP:0)
Block(-4,7,3,WOOD_DOUBLE_STEP:0)
Block(-4,7,4,WOOD_DOUBLE_STEP:0)
Block(-4,7,5,WOOD:1)
Block(-4,7,6,STATIONARY_WATER:0)
Block(-4,7,7,STATIONARY_WATER:0)
Block(-4,7,8,STATIONARY_WATER:0)
Block(-4,8,-7,STATIONARY_WATER:0)
Block(-4,8,-6,STATIONARY_WATER:0)
Block(-4,8,-5,STATIONARY_WATER:0)
Block(-4,8,-4,STATIONARY_WATER:0)
Block(-4,8,-3,STATIONARY_WATER:0)
Block(-4,8,-2,STATIONARY_WATER:0)
Block(-4,8,-1,STATIONARY_WATER:0)
Block(-4,8,0,STATIONARY_WATER:0)
Block(-4,8,1,STATIONARY_WATER:0)
Block(-4,8,2,STATIONARY_WATER:0)
Block(-4,8,3,STATIONARY_WATER:0)
Block(-4,8,4,STATIONARY_WATER:0)
Block(-4,8,5,WOOD:1)
Block(-4,8,6,STATIONARY_WATER:0)
Block(-4,8,7,STATIONARY_WATER:0)
Block(-4,8,8,STATIONARY_WATER:0)
Block(-4,9,-7,STATIONARY_WATER:0)
Block(-4,9,-6,STATIONARY_WATER:0)
Block(-4,9,-5,STATIONARY_WATER:0)
Block(-4,9,-4,STATIONARY_WATER:0)
Block(-4,9,-3,STATIONARY_WATER:0)
Block(-4,9,-2,STATIONARY_WATER:0)
Block(-4,9,-1,STATIONARY_WATER:0)
Block(-4,9,0,STATIONARY_WATER:0)
Block(-4,9,1,STATIONARY_WATER:0)
Block(-4,9,2,STATIONARY_WATER:0)
Block(-4,9,3,STATIONARY_WATER:0)
Block(-4,9,4,STATIONARY_WATER:0)
Block(-4,9,5,WOOD:1)
Block(-4,9,6,STATIONARY_WATER:0)
Block(-4,9,7,STATIONARY_WATER:0)
Block(-4,9,8,STATIONARY_WATER:0)
Block(-4,10,-7,STATIONARY_WATER:0)
Block(-4,10,-6,WOOD_STEP:0)
Block(-4,10,-5,WOOD_STEP:0)
Block(-4,10,-4,WOOD_DOUBLE_STEP:0)
Block(-4,10,-3,WOOD_DOUBLE_STEP:0)
Block(-4,10,-2,WOOD_DOUBLE_STEP:0)
Block(-4,10,-1,WOOD_DOUBLE_STEP:0)
Block(-4,10,0,WOOD_DOUBLE_STEP:0)
Block(-4,10,1,WOOD_DOUBLE_STEP:0)
Block(-4,10,2,WOOD_DOUBLE_STEP:0)
Block(-4,10,3,WOOD_DOUBLE_STEP:0)
Block(-4,10,4,WOOD_STEP:0)
Block(-4,10,5,WOOD_STEP:0)
Block(-4,10,6,WOOD_STEP:0)
Block(-4,10,7,WOOD_STEP:0)
Block(-4,10,8,WOOD_STEP:0)
Block(-4,11,-7,STATIONARY_WATER:0)
Block(-4,11,-6,STATIONARY_WATER:0)
Block(-4,11,-5,STATIONARY_WATER:0)
Block(-4,11,-4,WOOD:1)
RandomBlock(-4,11,-3,AIR:0,20,CHEST:3,../../../../Chests/Loot/ShipJunk_1.nbt,10,CHEST:3,../../../../Chests/Loot/ShipJunk_2.nbt,10,CHEST:3,../../../../Chests/Loot/ShipJunk_3.nbt,10,CHEST:3,../../../../Chests/Loot/ShipJunk_4.nbt,10,CHEST:3,../../../../Chests/Loot/ShipJunk_5.nbt,10,CHEST:3,../../../../Chests/Traveler/Travelers_Castle.nbt,1,CHEST:3,../../../../Chests/Traveler/Travelers_Church.nbt,1,CHEST:3,../../../../Chests/Traveler/Travelers_Daeroc.nbt,1,CHEST:3,../../../../Chests/Traveler/Travelers_Farmsteads.nbt,1,CHEST:3,../../../../Chests/Traveler/Travelers_GreenDungeon.nbt,1,CHEST:3,../../../../Chests/Traveler/Travelers_IceShips.nbt,1,CHEST:3,../../../../Chests/Traveler/Travelers_IceTemple.nbt,1,CHEST:3,../../../../Chests/Traveler/Travelers_LegacySpawn.nbt,1,CHEST:3,../../../../Chests/Traveler/Travelers_Mineshafts.nbt,1,CHEST:3,../../../../Chests/Traveler/Travelers_Mountains.nbt,1,CHEST:3,../../../../Chests/Traveler/Travelers_Origin.nbt,1,CHEST:3,../../../../Chests/Traveler/Travelers_Pirate.nbt,1,CHEST:3,../../../../Chests/Traveler/Travelers_Quarry.nbt,1,CHEST:3,../../../../Chests/Traveler/Travelers_Spook.nbt,1,CHEST:3,../../../../Chests/Traveler/Travelers_Tribal.nbt,1,CHEST:3,../../../../Chests/Lore/ShipSunk_1.nbt,1,CHEST:3,../../../../Chests/Lore/ShipSunk_2.nbt,1,CHEST:3,../../../../Chests/Lore/ShipSunk_3.nbt,1,CHEST:3,../../../../Chests/Lore/ShipSunk_4.nbt,1,CHEST:3,../../../../Chests/Lore/ShipSunk_5.nbt,1,CHEST:3,../../../../Chests/Loot/Common1.nbt,10,CHEST:3,../../../../Chests/Loot/Common2.nbt,10,CHEST:3,../../../../Chests/Loot/Common3.nbt,10,CHEST:3,../../../../Chests/Loot/Common4.nbt,10,CHEST:3,../../../../Chests/Loot/Common5.nbt,10,CHEST:3,../../../../Chests/Loot/Common6.nbt,10,CHEST:3,../../../../Chests/Loot/Common7.nbt,10,CHEST:3,../../../../Chests/Loot/Common8.nbt,10,CHEST:3,../../../../Chests/Loot/Common9.nbt,10,CHEST:3,../../../../Chests/Loot/Common10.nbt,10,CHEST:3,../../../../Chests/Loot/Common10.nbt,11,CHEST:3,../../../../Chests/Loot/Common12.nbt,10,CHEST:3,../../../../Chests/Loot/Common13.nbt,10,CHEST:3,../../../../Chests/Loot/Common14.nbt,10,CHEST:3,../../../../Chests/Loot/Common15.nbt,10,CHEST:3,../../../../Chests/Lore/ShipSunk_1.nbt,2,CHEST:3,../../../../Chests/Lore/ShipSunk_3.nbt,2,CHEST:3,../../../../Chests/Lore/ShipSunk_4.nbt,2,CHEST:3,../../../../Chests/Lore/ShipSunk_5.nbt,2,CHEST:3,../../../../Chests/Lore/ShipSunk_5.nbt,2,CHEST:3,../../../../Chests/Loot/Rare1.nbt,5,CHEST:3,../../../../Chests/Loot/Rare2.nbt,5,CHEST:3,../../../../Chests/Loot/Rare3.nbt,5,CHEST:3,../../../../Chests/Loot/Rare4.nbt,5,CHEST:3,../../../../Chests/Loot/Rare5.nbt,5,CHEST:3,../../../../Chests/Loot/Rare6.nbt,5,CHEST:3,../../../../Chests/Loot/Rare7.nbt,5,CHEST:3,../../../../Chests/Loot/Rare8.nbt,5,CHEST:3,../../../../Chests/Loot/Rare9.nbt,5,CHEST:3,../../../../Chests/Loot/Rare10.nbt,5,CHEST:3,../../../../Chests/Loot/Rare11.nbt,5,CHEST:3,../../../../Chests/Loot/Rare12.nbt,5,CHEST:3,../../../../Chests/Loot/Rare13.nbt,5,CHEST:3,../../../../Chests/Loot/Rare14.nbt,5,CHEST:3,../../../../Chests/Loot/Rare15.nbt,5,CHEST:3,../../../../Chests/Loot/Epic1.nbt,2,CHEST:3,../../../../Chests/Loot/Epic2.nbt,2,CHEST:3,../../../../Chests/Loot/Epic3.nbt,2,CHEST:3,../../../../Chests/Loot/Epic4.nbt,2,CHEST:3,../../../../Chests/Loot/Epic5.nbt,2,CHEST:3,../../../../Chests/Loot/Epic6.nbt,2,CHEST:3,../../../../Chests/Loot/Epic7.nbt,2,CHEST:3,../../../../Chests/Loot/Epic8.nbt,2,CHEST:3,../../../../Chests/Loot/Epic9.nbt,2,CHEST:3,../../../../Chests/Loot/Epic10.nbt,2,CHEST:3,../../../../Chests/Loot/Epic11.nbt,2,CHEST:3,../../../../Chests/Loot/Epic12.nbt,2,CHEST:3,../../../../Chests/Loot/Epic13.nbt,2,CHEST:3,../../../../Chests/Loot/Epic14.nbt,2,CHEST:3,../../../../Chests/Loot/Epic15.nbt,5,CHEST:3,../../../../Chests/Loot/Rare1.nbt,5,CHEST:3,../../../../Chests/Loot/Rare2.nbt,5,CHEST:3,../../../../Chests/Loot/Rare3.nbt,5,CHEST:3,../../../../Chests/Loot/Rare4.nbt,5,CHEST:3,../../../../Chests/Loot/Rare5.nbt,10,CHEST:3,../../../../Chests/Loot/Rare6.nbt,10,CHEST:3,../../../../Chests/Loot/Rare7.nbt,10,CHEST:3,../../../../Chests/Loot/Rare8.nbt,10,CHEST:3,../../../../Chests/Loot/Rare9.nbt,10,CHEST:3,../../../../Chests/Loot/Rare10.nbt,15,CHEST:3,../../../../Chests/Loot/Rare11.nbt,15,CHEST:3,../../../../Chests/Loot/Rare12.nbt,15,CHEST:3,../../../../Chests/Loot/Rare13.nbt,15,CHEST:3,../../../../Chests/Loot/Rare14.nbt,15,CHEST:3,../../../../Chests/Loot/Rare15.nbt,15,CHEST:3,../../../../Chests/Loot/Epic15.nbt,100)
Block(-4,11,-2,AIR:0)
Block(-4,11,-1,AIR:0)
Block(-4,11,0,AIR:0)
Block(-4,11,1,AIR:0)
RandomBlock(-4,11,2,CHEST:2,../../../../Chests/Traveler/Travelers_Castle.nbt,1,CHEST:2,../../../../Chests/Traveler/Travelers_Church.nbt,1,CHEST:2,../../../../Chests/Traveler/Travelers_Daeroc.nbt,1,CHEST:2,../../../../Chests/Traveler/Travelers_Farmsteads.nbt,1,CHEST:2,../../../../Chests/Traveler/Travelers_GreenDungeon.nbt,1,CHEST:2,../../../../Chests/Traveler/Travelers_IceShips.nbt,1,CHEST:2,../../../../Chests/Traveler/Travelers_IceTemple.nbt,1,CHEST:2,../../../../Chests/Traveler/Travelers_LegacySpawn.nbt,1,CHEST:2,../../../../Chests/Traveler/Travelers_Mineshafts.nbt,1,CHEST:2,../../../../Chests/Traveler/Travelers_Mountains.nbt,1,CHEST:2,../../../../Chests/Traveler/Travelers_Origin.nbt,1,CHEST:2,../../../../Chests/Traveler/Travelers_Pirate.nbt,1,CHEST:2,../../../../Chests/Traveler/Travelers_Quarry.nbt,1,CHEST:2,../../../../Chests/Traveler/Travelers_Spook.nbt,1,CHEST:2,../../../../Chests/Traveler/Travelers_Tribal.nbt,1,CHEST:2,../../../../Chests/Lore/ShipSunk_1.nbt,1,CHEST:2,../../../../Chests/Lore/ShipSunk_2.nbt,1,CHEST:2,../../../../Chests/Lore/ShipSunk_3.nbt,1,CHEST:2,../../../../Chests/Lore/ShipSunk_4.nbt,1,CHEST:2,../../../../Chests/Lore/ShipSunk_5.nbt,1,CHEST:2,../../../../Chests/Loot/Common1.nbt,5,CHEST:2,../../../../Chests/Loot/Common2.nbt,5,CHEST:2,../../../../Chests/Loot/Common3.nbt,5,CHEST:2,../../../../Chests/Loot/Common4.nbt,5,CHEST:2,../../../../Chests/Loot/Common5.nbt,5,CHEST:2,../../../../Chests/Loot/Common6.nbt,5,CHEST:2,../../../../Chests/Loot/Common7.nbt,5,CHEST:2,../../../../Chests/Loot/Common8.nbt,5,CHEST:2,../../../../Chests/Loot/Common9.nbt,5,CHEST:2,../../../../Chests/Loot/Common10.nbt,5,CHEST:2,../../../../Chests/Loot/Common11.nbt,5,CHEST:2,../../../../Chests/Loot/Common12.nbt,5,CHEST:2,../../../../Chests/Loot/Common13.nbt,5,CHEST:2,../../../../Chests/Loot/Common14.nbt,5,CHEST:2,../../../../Chests/Loot/Common15.nbt,5,CHEST:2,../../../../Chests/Lore/ShipSunk_1.nbt,2,CHEST:2,../../../../Chests/Lore/ShipSunk_2.nbt,2,CHEST:2,../../../../Chests/Lore/ShipSunk_3.nbt,2,CHEST:2,../../../../Chests/Lore/ShipSunk_4.nbt,2,CHEST:2,../../../../Chests/Lore/ShipSunk_5.nbt,2,CHEST:2,../../../../Chests/Loot/Rare1.nbt,5,CHEST:2,../../../../Chests/Loot/Rare2.nbt,5,CHEST:2,../../../../Chests/Loot/Rare3.nbt,5,CHEST:2,../../../../Chests/Loot/Rare4.nbt,5,CHEST:2,../../../../Chests/Loot/Rare5.nbt,5,CHEST:2,../../../../Chests/Loot/Rare6.nbt,5,CHEST:2,../../../../Chests/Loot/Rare7.nbt,5,CHEST:2,../../../../Chests/Loot/Rare8.nbt,5,CHEST:2,../../../../Chests/Loot/Rare9.nbt,5,CHEST:2,../../../../Chests/Loot/Rare10.nbt,5,CHEST:2,../../../../Chests/Loot/Rare11.nbt,5,CHEST:2,../../../../Chests/Loot/Rare12.nbt,5,CHEST:2,../../../../Chests/Loot/Rare13.nbt,5,CHEST:2,../../../../Chests/Loot/Rare14.nbt,5,CHEST:2,../../../../Chests/Loot/Rare15.nbt,5,CHEST:2,../../../../Chests/Loot/Epic1.nbt,2,CHEST:2,../../../../Chests/Loot/Epic2.nbt,2,CHEST:2,../../../../Chests/Loot/Epic3.nbt,2,CHEST:2,../../../../Chests/Loot/Epic4.nbt,2,CHEST:2,../../../../Chests/Loot/Epic5.nbt,2,CHEST:2,../../../../Chests/Loot/Epic6.nbt,2,CHEST:2,../../../../Chests/Loot/Epic7.nbt,2,CHEST:2,../../../../Chests/Loot/Epic8.nbt,2,CHEST:2,../../../../Chests/Loot/Epic9.nbt,2,CHEST:2,../../../../Chests/Loot/Epic10.nbt,2,CHEST:2,../../../../Chests/Loot/Epic11.nbt,2,CHEST:2,../../../../Chests/Loot/Epic12.nbt,2,CHEST:2,../../../../Chests/Loot/Epic13.nbt,2,CHEST:2,../../../../Chests/Loot/Epic14.nbt,2,CHEST:2,../../../../Chests/Loot/Epic15.nbt,5,CHEST:2,../../../../Chests/Loot/Rare1.nbt,5,CHEST:2,../../../../Chests/Loot/Rare2.nbt,5,CHEST:2,../../../../Chests/Loot/Rare3.nbt,5,CHEST:2,../../../../Chests/Loot/Rare4.nbt,5,CHEST:2,../../../../Chests/Loot/Rare5.nbt,10,CHEST:2,../../../../Chests/Loot/Rare6.nbt,10,CHEST:2,../../../../Chests/Loot/Rare7.nbt,10,CHEST:2,../../../../Chests/Loot/Rare8.nbt,10,CHEST:2,../../../../Chests/Loot/Rare9.nbt,10,CHEST:2,../../../../Chests/Loot/Rare10.nbt,15,CHEST:2,../../../../Chests/Loot/Rare11.nbt,15,CHEST:2,../../../../Chests/Loot/Rare12.nbt,15,CHEST:2,../../../../Chests/Loot/Rare13.nbt,15,CHEST:2,../../../../Chests/Loot/Rare14.nbt,15,CHEST:2,../../../../Chests/Loot/Rare15.nbt,15,CHEST:2,../../../../Chests/Loot/Epic15.nbt,100)
Block(-4,11,3,WOOD:1)
Block(-4,11,4,AIR:0)
Block(-4,11,5,AIR:0)
Block(-4,11,6,AIR:0)
Block(-4,11,7,AIR:0)
Block(-4,11,8,AIR:0)
Block(-4,12,-7,STATIONARY_WATER:0)
Block(-4,12,-6,STATIONARY_WATER:0)
Block(-4,12,-5,STATIONARY_WATER:0)
Block(-4,12,-4,WOOD:1)
Block(-4,12,-3,AIR:0)
Block(-4,12,-2,AIR:0)
Block(-4,12,-1,AIR:0)
Block(-4,12,0,AIR:0)
Block(-4,12,1,AIR:0)
Block(-4,12,2,AIR:0)
Block(-4,12,3,WOOD:1)
Block(-4,12,4,AIR:0)
Block(-4,12,5,AIR:0)
Block(-4,12,6,WOOD:1)
Block(-4,12,7,WOOD:1)
Block(-4,12,8,WOOD:1)
Block(-4,13,-7,AIR:0)
Block(-4,13,-6,AIR:0)
Block(-4,13,-5,WOOD:1)
Block(-4,13,-4,WOOD:1)
Block(-4,13,-3,WOOD:1)
Block(-4,13,-2,WOOD:1)
Block(-4,13,-1,WOOD:1)
Block(-4,13,0,WOOD:1)
Block(-4,13,1,WOOD:1)
Block(-4,13,2,WOOD:1)
Block(-4,13,3,WOOD:1)
Block(-4,13,4,WOOD:1)
Block(-4,13,5,WOOD:1)
Block(-4,14,-7,WOOD:1)
Block(-4,14,-6,WOOD:1)
Block(-3,4,-7,WOOD_STEP:9)
Block(-3,4,-6,WOOD_STEP:9)
Block(-3,4,-5,WOOD_STEP:9)
Block(-3,4,-4,WOOD_STEP:9)
Block(-3,4,-3,WOOD_STEP:9)
Block(-3,4,-2,SPRUCE_WOOD_STAIRS:4)
Block(-3,4,-1,WOOD_STEP:9)
Block(-3,5,-7,SPRUCE_WOOD_STAIRS:0)
Block(-3,5,-6,SPRUCE_WOOD_STAIRS:0)
Block(-3,5,-5,SPRUCE_WOOD_STAIRS:0)
Block(-3,5,-4,WOOD_STEP:1)
Block(-3,5,-3,STATIONARY_WATER:0)
Block(-3,5,-2,STATIONARY_WATER:0)
Block(-3,5,-1,STATIONARY_WATER:0)
Block(-3,5,3,LEVER:2)
Block(-3,6,-7,TRAP_DOOR:10)
Block(-3,6,-6,TRAP_DOOR:10)
Block(-3,6,-5,SPRUCE_WOOD_STAIRS:4)
Block(-3,6,-3,COBBLE_WALL:0)
Block(-3,6,-2,STATIONARY_WATER:0)
Block(-3,6,-1,COBBLE_WALL:0)
Block(-3,6,5,WOOD_STEP:8)
Block(-3,6,6,WOOD_STEP:8)
Block(-3,6,7,WOOD_STEP:8)
Block(-3,6,8,WOOD_STEP:0)
Block(-3,7,-5,WOOD_STEP:0)
Block(-3,7,-4,WOOD_DOUBLE_STEP:0)
Block(-3,7,-3,WOOD_DOUBLE_STEP:0)
Block(-3,7,-2,WOOD_DOUBLE_STEP:0)
Block(-3,7,-1,WOOD_STEP:0)
Block(-3,7,0,WOOD_STEP:0)
Block(-3,7,1,WOOD_DOUBLE_STEP:0)
Block(-3,7,2,WOOD_DOUBLE_STEP:0)
Block(-3,7,3,WOOD_DOUBLE_STEP:0)
Block(-3,7,4,WOOD_DOUBLE_STEP:0)
Block(-3,7,5,WOOD:1)
Block(-3,7,6,STATIONARY_WATER:0)
Block(-3,7,7,STATIONARY_WATER:0)
Block(-3,7,8,STATIONARY_WATER:0)
Block(-3,8,-7,STATIONARY_WATER:0)
Block(-3,8,-6,STATIONARY_WATER:0)
Block(-3,8,-5,STATIONARY_WATER:0)
Block(-3,8,-4,STATIONARY_WATER:0)
Block(-3,8,-3,STATIONARY_WATER:0)
Block(-3,8,-2,STATIONARY_WATER:0)
Block(-3,8,-1,STATIONARY_WATER:0)
Block(-3,8,0,STATIONARY_WATER:0)
Block(-3,8,1,STATIONARY_WATER:0)
Block(-3,8,2,STATIONARY_WATER:0)
Block(-3,8,3,STATIONARY_WATER:0)
Block(-3,8,4,STATIONARY_WATER:0)
Block(-3,8,5,WOOD:1)
Block(-3,8,6,STATIONARY_WATER:0)
Block(-3,8,7,STATIONARY_WATER:0)
Block(-3,8,8,STATIONARY_WATER:0)
Block(-3,9,-7,STATIONARY_WATER:0)
Block(-3,9,-6,STATIONARY_WATER:0)
Block(-3,9,-5,STATIONARY_WATER:0)
Block(-3,9,-4,STATIONARY_WATER:0)
Block(-3,9,-3,STATIONARY_WATER:0)
Block(-3,9,-2,STATIONARY_WATER:0)
Block(-3,9,-1,STATIONARY_WATER:0)
Block(-3,9,0,STATIONARY_WATER:0)
Block(-3,9,1,STATIONARY_WATER:0)
Block(-3,9,2,STATIONARY_WATER:0)
Block(-3,9,3,STATIONARY_WATER:0)
Block(-3,9,4,STATIONARY_WATER:0)
Block(-3,9,5,WOOD:1)
Block(-3,9,6,STATIONARY_WATER:0)
Block(-3,9,7,STATIONARY_WATER:0)
Block(-3,9,8,STATIONARY_WATER:0)
Block(-3,10,-7,WOOD_STEP:0)
Block(-3,10,-6,WOOD_STEP:0)
Block(-3,10,-5,WOOD_STEP:0)
Block(-3,10,-4,WOOD_DOUBLE_STEP:0)
Block(-3,10,-3,WOOD_DOUBLE_STEP:0)
Block(-3,10,-2,WOOD_DOUBLE_STEP:0)
Block(-3,10,-1,WOOD_DOUBLE_STEP:0)
Block(-3,10,0,WOOD_DOUBLE_STEP:0)
Block(-3,10,1,WOOD_DOUBLE_STEP:0)
Block(-3,10,2,WOOD_DOUBLE_STEP:0)
Block(-3,10,3,WOOD_DOUBLE_STEP:0)
Block(-3,10,4,WOOD_STEP:0)
Block(-3,10,5,WOOD_STEP:0)
Block(-3,10,6,WOOD_STEP:0)
Block(-3,10,7,WOOD_STEP:0)
Block(-3,10,8,WOOD_STEP:0)
Block(-3,11,-7,STATIONARY_WATER:0)
Block(-3,11,-6,STATIONARY_WATER:0)
Block(-3,11,-5,STATIONARY_WATER:0)
Block(-3,11,-4,WOOD:1)
RandomBlock(-3,11,-3,AIR:0,20,CHEST:3,../../../../Chests/Loot/ShipJunk_1.nbt,10,CHEST:3,../../../../Chests/Loot/ShipJunk_2.nbt,10,CHEST:3,../../../../Chests/Loot/ShipJunk_3.nbt,10,CHEST:3,../../../../Chests/Loot/ShipJunk_4.nbt,10,CHEST:3,../../../../Chests/Loot/ShipJunk_5.nbt,10,CHEST:3,../../../../Chests/Traveler/Travelers_Castle.nbt,1,CHEST:3,../../../../Chests/Traveler/Travelers_Church.nbt,1,CHEST:3,../../../../Chests/Traveler/Travelers_Daeroc.nbt,1,CHEST:3,../../../../Chests/Traveler/Travelers_Farmsteads.nbt,1,CHEST:3,../../../../Chests/Traveler/Travelers_GreenDungeon.nbt,1,CHEST:3,../../../../Chests/Traveler/Travelers_IceShips.nbt,1,CHEST:3,../../../../Chests/Traveler/Travelers_IceTemple.nbt,1,CHEST:3,../../../../Chests/Traveler/Travelers_LegacySpawn.nbt,1,CHEST:3,../../../../Chests/Traveler/Travelers_Mineshafts.nbt,1,CHEST:3,../../../../Chests/Traveler/Travelers_Mountains.nbt,1,CHEST:3,../../../../Chests/Traveler/Travelers_Origin.nbt,1,CHEST:3,../../../../Chests/Traveler/Travelers_Pirate.nbt,1,CHEST:3,../../../../Chests/Traveler/Travelers_Quarry.nbt,1,CHEST:3,../../../../Chests/Traveler/Travelers_Spook.nbt,1,CHEST:3,../../../../Chests/Traveler/Travelers_Tribal.nbt,1,CHEST:3,../../../../Chests/Lore/ShipSunk_1.nbt,1,CHEST:3,../../../../Chests/Lore/ShipSunk_2.nbt,1,CHEST:3,../../../../Chests/Lore/ShipSunk_3.nbt,1,CHEST:3,../../../../Chests/Lore/ShipSunk_4.nbt,1,CHEST:3,../../../../Chests/Lore/ShipSunk_5.nbt,1,CHEST:3,../../../../Chests/Loot/Common1.nbt,10,CHEST:3,../../../../Chests/Loot/Common2.nbt,10,CHEST:3,../../../../Chests/Loot/Common3.nbt,10,CHEST:3,../../../../Chests/Loot/Common4.nbt,10,CHEST:3,../../../../Chests/Loot/Common5.nbt,10,CHEST:3,../../../../Chests/Loot/Common6.nbt,10,CHEST:3,../../../../Chests/Loot/Common7.nbt,10,CHEST:3,../../../../Chests/Loot/Common8.nbt,10,CHEST:3,../../../../Chests/Loot/Common9.nbt,10,CHEST:3,../../../../Chests/Loot/Common10.nbt,10,CHEST:3,../../../../Chests/Loot/Common10.nbt,11,CHEST:3,../../../../Chests/Loot/Common12.nbt,10,CHEST:3,../../../../Chests/Loot/Common13.nbt,10,CHEST:3,../../../../Chests/Loot/Common14.nbt,10,CHEST:3,../../../../Chests/Loot/Common15.nbt,10,CHEST:3,../../../../Chests/Lore/ShipSunk_1.nbt,2,CHEST:3,../../../../Chests/Lore/ShipSunk_3.nbt,2,CHEST:3,../../../../Chests/Lore/ShipSunk_4.nbt,2,CHEST:3,../../../../Chests/Lore/ShipSunk_5.nbt,2,CHEST:3,../../../../Chests/Lore/ShipSunk_5.nbt,2,CHEST:3,../../../../Chests/Loot/Rare1.nbt,5,CHEST:3,../../../../Chests/Loot/Rare2.nbt,5,CHEST:3,../../../../Chests/Loot/Rare3.nbt,5,CHEST:3,../../../../Chests/Loot/Rare4.nbt,5,CHEST:3,../../../../Chests/Loot/Rare5.nbt,5,CHEST:3,../../../../Chests/Loot/Rare6.nbt,5,CHEST:3,../../../../Chests/Loot/Rare7.nbt,5,CHEST:3,../../../../Chests/Loot/Rare8.nbt,5,CHEST:3,../../../../Chests/Loot/Rare9.nbt,5,CHEST:3,../../../../Chests/Loot/Rare10.nbt,5,CHEST:3,../../../../Chests/Loot/Rare11.nbt,5,CHEST:3,../../../../Chests/Loot/Rare12.nbt,5,CHEST:3,../../../../Chests/Loot/Rare13.nbt,5,CHEST:3,../../../../Chests/Loot/Rare14.nbt,5,CHEST:3,../../../../Chests/Loot/Rare15.nbt,5,CHEST:3,../../../../Chests/Loot/Epic1.nbt,2,CHEST:3,../../../../Chests/Loot/Epic2.nbt,2,CHEST:3,../../../../Chests/Loot/Epic3.nbt,2,CHEST:3,../../../../Chests/Loot/Epic4.nbt,2,CHEST:3,../../../../Chests/Loot/Epic5.nbt,2,CHEST:3,../../../../Chests/Loot/Epic6.nbt,2,CHEST:3,../../../../Chests/Loot/Epic7.nbt,2,CHEST:3,../../../../Chests/Loot/Epic8.nbt,2,CHEST:3,../../../../Chests/Loot/Epic9.nbt,2,CHEST:3,../../../../Chests/Loot/Epic10.nbt,2,CHEST:3,../../../../Chests/Loot/Epic11.nbt,2,CHEST:3,../../../../Chests/Loot/Epic12.nbt,2,CHEST:3,../../../../Chests/Loot/Epic13.nbt,2,CHEST:3,../../../../Chests/Loot/Epic14.nbt,2,CHEST:3,../../../../Chests/Loot/Epic15.nbt,5,CHEST:3,../../../../Chests/Loot/Rare1.nbt,5,CHEST:3,../../../../Chests/Loot/Rare2.nbt,5,CHEST:3,../../../../Chests/Loot/Rare3.nbt,5,CHEST:3,../../../../Chests/Loot/Rare4.nbt,5,CHEST:3,../../../../Chests/Loot/Rare5.nbt,10,CHEST:3,../../../../Chests/Loot/Rare6.nbt,10,CHEST:3,../../../../Chests/Loot/Rare7.nbt,10,CHEST:3,../../../../Chests/Loot/Rare8.nbt,10,CHEST:3,../../../../Chests/Loot/Rare9.nbt,10,CHEST:3,../../../../Chests/Loot/Rare10.nbt,15,CHEST:3,../../../../Chests/Loot/Rare11.nbt,15,CHEST:3,../../../../Chests/Loot/Rare12.nbt,15,CHEST:3,../../../../Chests/Loot/Rare13.nbt,15,CHEST:3,../../../../Chests/Loot/Rare14.nbt,15,CHEST:3,../../../../Chests/Loot/Rare15.nbt,15,CHEST:3,../../../../Chests/Loot/Epic15.nbt,100)
Block(-3,11,-2,AIR:0)
Block(-3,11,-1,AIR:0)
Block(-3,11,0,AIR:0)
Block(-3,11,1,AIR:0)
Block(-3,11,2,AIR:0)
Block(-3,11,3,WOOD:1)
Block(-3,11,4,AIR:0)
Block(-3,11,5,AIR:0)
Block(-3,11,6,AIR:0)
Block(-3,11,7,AIR:0)
Block(-3,11,8,AIR:0)
Block(-3,12,-7,STATIONARY_WATER:0)
Block(-3,12,-6,STATIONARY_WATER:0)
Block(-3,12,-5,STATIONARY_WATER:0)
Block(-3,12,-4,WOOD:1)
Block(-3,12,-3,AIR:0)
Block(-3,12,-2,AIR:0)
Block(-3,12,-1,AIR:0)
Block(-3,12,0,AIR:0)
Block(-3,12,1,AIR:0)
Block(-3,12,2,AIR:0)
Block(-3,12,3,WOOD:1)
Block(-3,12,4,AIR:0)
Block(-3,12,5,AIR:0)
Block(-3,12,6,AIR:0)
Block(-3,12,7,AIR:0)
Block(-3,12,8,AIR:0)
Block(-3,13,-7,AIR:0)
Block(-3,13,-6,AIR:0)
Block(-3,13,-5,AIR:0)
Block(-3,13,-4,WOOD:1)
Block(-3,13,-3,AIR:0)
Block(-3,13,-2,AIR:0)
Block(-3,13,-1,WOOD:1)
Block(-3,13,0,WOOD:1)
Block(-3,13,1,WOOD:1)
Block(-3,13,2,WOOD:1)
Block(-3,13,3,WOOD:1)
Block(-3,13,4,WOOD:1)
Block(-3,13,5,WOOD:1)
Block(-3,13,6,WOOD:1)
Block(-3,13,7,WOOD:1)
Block(-3,13,8,WOOD:1)
Block(-3,14,-7,WOOD:1)
Block(-3,14,-6,WOOD:1)
Block(-3,14,-5,WOOD:1)
Block(-3,14,-4,WOOD:1)
Block(-3,14,-3,WOOD:1)
Block(-3,14,-2,WOOD:1)
Block(-3,14,-1,WOOD:1)
Block(-3,14,0,WOOD:1)
Block(-3,15,-7,WOOD:1)
Block(-2,1,0,LOG_2:1)
Block(-2,2,0,LOG_2:1)
Block(-2,3,0,WOOD:5)
Block(-2,4,-6,TRAP_DOOR:10)
Block(-2,4,-3,SPRUCE_WOOD_STAIRS:6)
Block(-2,4,-2,WOOD:5)
Block(-2,4,-1,SPRUCE_WOOD_STAIRS:7)
Block(-2,4,0,LOG_2:1)
Block(-2,4,3,LEVER:15)
Block(-2,5,-7,WOOD_STEP:9)
Block(-2,5,-6,WOOD_STEP:9)
Block(-2,5,-5,WOOD_STEP:9)
Block(-2,5,-4,SPRUCE_WOOD_STAIRS:3)
RandomBlock(-2,5,-2,AIR:0,20,CHEST:4,../../../../Chests/Loot/ShipJunk_1.nbt,10,CHEST:4,../../../../Chests/Loot/ShipJunk_2.nbt,10,CHEST:4,../../../../Chests/Loot/ShipJunk_3.nbt,10,CHEST:4,../../../../Chests/Loot/ShipJunk_4.nbt,10,CHEST:4,../../../../Chests/Loot/ShipJunk_5.nbt,10,CHEST:4,../../../../Chests/Traveler/Travelers_Castle.nbt,1,CHEST:4,../../../../Chests/Traveler/Travelers_Church.nbt,1,CHEST:4,../../../../Chests/Traveler/Travelers_Daeroc.nbt,1,CHEST:4,../../../../Chests/Traveler/Travelers_Farmsteads.nbt,1,CHEST:4,../../../../Chests/Traveler/Travelers_GreenDungeon.nbt,1,CHEST:4,../../../../Chests/Traveler/Travelers_IceShips.nbt,1,CHEST:4,../../../../Chests/Traveler/Travelers_IceTemple.nbt,1,CHEST:4,../../../../Chests/Traveler/Travelers_LegacySpawn.nbt,1,CHEST:4,../../../../Chests/Traveler/Travelers_Mineshafts.nbt,1,CHEST:4,../../../../Chests/Traveler/Travelers_Mountains.nbt,1,CHEST:4,../../../../Chests/Traveler/Travelers_Origin.nbt,1,CHEST:4,../../../../Chests/Traveler/Travelers_Pirate.nbt,1,CHEST:4,../../../../Chests/Traveler/Travelers_Quarry.nbt,1,CHEST:4,../../../../Chests/Traveler/Travelers_Spook.nbt,1,CHEST:4,../../../../Chests/Traveler/Travelers_Tribal.nbt,1,CHEST:4,../../../../Chests/Lore/ShipSunk_1.nbt,1,CHEST:4,../../../../Chests/Lore/ShipSunk_2.nbt,1,CHEST:4,../../../../Chests/Lore/ShipSunk_3.nbt,1,CHEST:4,../../../../Chests/Lore/ShipSunk_4.nbt,1,CHEST:4,../../../../Chests/Lore/ShipSunk_5.nbt,1,CHEST:4,../../../../Chests/Loot/Common1.nbt,10,CHEST:4,../../../../Chests/Loot/Common2.nbt,10,CHEST:4,../../../../Chests/Loot/Common3.nbt,10,CHEST:4,../../../../Chests/Loot/Common4.nbt,10,CHEST:4,../../../../Chests/Loot/Common5.nbt,10,CHEST:4,../../../../Chests/Loot/Common6.nbt,10,CHEST:4,../../../../Chests/Loot/Common7.nbt,10,CHEST:4,../../../../Chests/Loot/Common8.nbt,10,CHEST:4,../../../../Chests/Loot/Common9.nbt,10,CHEST:4,../../../../Chests/Loot/Common10.nbt,10,CHEST:4,../../../../Chests/Loot/Common10.nbt,11,CHEST:4,../../../../Chests/Loot/Common12.nbt,10,CHEST:4,../../../../Chests/Loot/Common13.nbt,10,CHEST:4,../../../../Chests/Loot/Common14.nbt,10,CHEST:4,../../../../Chests/Loot/Common15.nbt,10,CHEST:4,../../../../Chests/Lore/ShipSunk_1.nbt,2,CHEST:4,../../../../Chests/Lore/ShipSunk_3.nbt,2,CHEST:4,../../../../Chests/Lore/ShipSunk_4.nbt,2,CHEST:4,../../../../Chests/Lore/ShipSunk_5.nbt,2,CHEST:4,../../../../Chests/Lore/ShipSunk_5.nbt,2,CHEST:4,../../../../Chests/Loot/Rare1.nbt,5,CHEST:4,../../../../Chests/Loot/Rare2.nbt,5,CHEST:4,../../../../Chests/Loot/Rare3.nbt,5,CHEST:4,../../../../Chests/Loot/Rare4.nbt,5,CHEST:4,../../../../Chests/Loot/Rare5.nbt,5,CHEST:4,../../../../Chests/Loot/Rare6.nbt,5,CHEST:4,../../../../Chests/Loot/Rare7.nbt,5,CHEST:4,../../../../Chests/Loot/Rare8.nbt,5,CHEST:4,../../../../Chests/Loot/Rare9.nbt,5,CHEST:4,../../../../Chests/Loot/Rare10.nbt,5,CHEST:4,../../../../Chests/Loot/Rare11.nbt,5,CHEST:4,../../../../Chests/Loot/Rare12.nbt,5,CHEST:4,../../../../Chests/Loot/Rare13.nbt,5,CHEST:4,../../../../Chests/Loot/Rare14.nbt,5,CHEST:4,../../../../Chests/Loot/Rare15.nbt,5,CHEST:4,../../../../Chests/Loot/Epic1.nbt,2,CHEST:4,../../../../Chests/Loot/Epic2.nbt,2,CHEST:4,../../../../Chests/Loot/Epic3.nbt,2,CHEST:4,../../../../Chests/Loot/Epic4.nbt,2,CHEST:4,../../../../Chests/Loot/Epic5.nbt,2,CHEST:4,../../../../Chests/Loot/Epic6.nbt,2,CHEST:4,../../../../Chests/Loot/Epic7.nbt,2,CHEST:4,../../../../Chests/Loot/Epic8.nbt,2,CHEST:4,../../../../Chests/Loot/Epic9.nbt,2,CHEST:4,../../../../Chests/Loot/Epic10.nbt,2,CHEST:4,../../../../Chests/Loot/Epic11.nbt,2,CHEST:4,../../../../Chests/Loot/Epic12.nbt,2,CHEST:4,../../../../Chests/Loot/Epic13.nbt,2,CHEST:4,../../../../Chests/Loot/Epic14.nbt,2,CHEST:4,../../../../Chests/Loot/Epic15.nbt,5,CHEST:4,../../../../Chests/Loot/Rare1.nbt,5,CHEST:4,../../../../Chests/Loot/Rare2.nbt,5,CHEST:4,../../../../Chests/Loot/Rare3.nbt,5,CHEST:4,../../../../Chests/Loot/Rare4.nbt,5,CHEST:4,../../../../Chests/Loot/Rare5.nbt,10,CHEST:4,../../../../Chests/Loot/Rare6.nbt,10,CHEST:4,../../../../Chests/Loot/Rare7.nbt,10,CHEST:4,../../../../Chests/Loot/Rare8.nbt,10,CHEST:4,../../../../Chests/Loot/Rare9.nbt,10,CHEST:4,../../../../Chests/Loot/Rare10.nbt,15,CHEST:4,../../../../Chests/Loot/Rare11.nbt,15,CHEST:4,../../../../Chests/Loot/Rare12.nbt,15,CHEST:4,../../../../Chests/Loot/Rare13.nbt,15,CHEST:4,../../../../Chests/Loot/Rare14.nbt,15,CHEST:4,../../../../Chests/Loot/Rare15.nbt,15,CHEST:4,../../../../Chests/Loot/Epic15.nbt,100)
Block(-2,5,0,WOOD:5)
Block(-2,5,2,TRAP_DOOR:12)
Block(-2,5,3,LOG_2:9)
Block(-2,6,-7,WOOD_STEP:9)
Block(-2,6,-6,WOOD_STEP:9)
Block(-2,6,0,WOOD:5)
Block(-2,6,3,COBBLE_WALL:0)
Block(-2,6,5,WOOD_STEP:8)
Block(-2,6,6,WOOD_STEP:8)
Block(-2,6,7,WOOD_STEP:8)
Block(-2,6,8,WOOD_STEP:0)
Block(-2,7,-7,WOOD_STEP:1)
Block(-2,7,-6,WOOD_STEP:1)
Block(-2,7,-5,WOOD_DOUBLE_STEP:0)
Block(-2,7,-4,WOOD_STEP:0)
Block(-2,7,-3,WOOD_STEP:0)
Block(-2,7,-2,WOOD_STEP:0)
Block(-2,7,-1,WOOD_STEP:0)
Block(-2,7,0,LOG:1)
Block(-2,7,1,WOOD_STEP:0)
Block(-2,7,2,WOOD_DOUBLE_STEP:0)
Block(-2,7,3,WOOD_DOUBLE_STEP:0)
Block(-2,7,4,WOOD_DOUBLE_STEP:0)
Block(-2,7,5,WOOD:1)
Block(-2,7,6,STATIONARY_WATER:0)
Block(-2,7,7,STATIONARY_WATER:0)
Block(-2,7,8,STATIONARY_WATER:0)
Block(-2,8,-7,STATIONARY_WATER:0)
Block(-2,8,-6,STATIONARY_WATER:0)
Block(-2,8,-5,SPRUCE_WOOD_STAIRS:4)
Block(-2,8,-4,STATIONARY_WATER:0)
Block(-2,8,-3,STATIONARY_WATER:0)
Block(-2,8,-2,STATIONARY_WATER:0)
Block(-2,8,-1,STATIONARY_WATER:0)
Block(-2,8,0,LOG:1)
Block(-2,8,1,STATIONARY_WATER:0)
Block(-2,8,2,STATIONARY_WATER:0)
Block(-2,8,3,STATIONARY_WATER:0)
Block(-2,8,4,STATIONARY_WATER:0)
Block(-2,8,5,STATIONARY_WATER:0)
Block(-2,8,6,STATIONARY_WATER:0)
Block(-2,8,7,STATIONARY_WATER:0)
Block(-2,8,8,AIR:0)
Block(-2,9,-7,STATIONARY_WATER:0)
Block(-2,9,-6,STATIONARY_WATER:0)
Block(-2,9,-5,STATIONARY_WATER:0)
Block(-2,9,-4,STATIONARY_WATER:0)
Block(-2,9,-3,STATIONARY_WATER:0)
Block(-2,9,-2,STATIONARY_WATER:0)
Block(-2,9,-1,STATIONARY_WATER:0)
Block(-2,9,0,LOG:1)
Block(-2,9,1,STATIONARY_WATER:0)
Block(-2,9,2,STATIONARY_WATER:0)
Block(-2,9,3,STATIONARY_WATER:0)
Block(-2,9,4,STATIONARY_WATER:0)
Block(-2,9,5,STATIONARY_WATER:0)
Block(-2,9,6,STATIONARY_WATER:0)
Block(-2,9,7,STATIONARY_WATER:0)
Block(-2,9,8,STATIONARY_WATER:0)
Block(-2,10,-7,STATIONARY_WATER:0)
Block(-2,10,-6,WOOD_STEP:0)
Block(-2,10,-5,WOOD_STEP:0)
Block(-2,10,-4,WOOD_DOUBLE_STEP:0)
Block(-2,10,-3,WOOD_DOUBLE_STEP:0)
Block(-2,10,-2,WOOD_DOUBLE_STEP:0)
Block(-2,10,-1,WOOD_DOUBLE_STEP:0)
Block(-2,10,0,LOG:1)
Block(-2,10,1,WOOD_DOUBLE_STEP:0)
Block(-2,10,2,WOOD_DOUBLE_STEP:0)
Block(-2,10,3,WOOD_DOUBLE_STEP:0)
Block(-2,10,4,WOOD_STEP:0)
Block(-2,10,5,WOOD_STEP:0)
Block(-2,10,6,WOOD_STEP:0)
Block(-2,10,7,WOOD_STEP:0)
Block(-2,10,8,AIR:0)
Block(-2,11,-7,STATIONARY_WATER:0)
Block(-2,11,-6,STATIONARY_WATER:0)
Block(-2,11,-5,STATIONARY_WATER:0)
Block(-2,11,-4,WOOD:1)
Block(-2,11,-3,AIR:0)
Block(-2,11,-2,AIR:0)
Block(-2,11,-1,AIR:0)
Block(-2,11,0,LOG:1)
Block(-2,11,1,AIR:0)
Block(-2,11,2,AIR:0)
Block(-2,11,3,AIR:0)
Block(-2,11,4,AIR:0)
Block(-2,11,5,AIR:0)
Block(-2,11,6,AIR:0)
Block(-2,11,7,AIR:0)
Block(-2,11,8,AIR:0)
Block(-2,12,-7,STATIONARY_WATER:0)
Block(-2,12,-6,STATIONARY_WATER:0)
Block(-2,12,-5,STATIONARY_WATER:0)
Block(-2,12,-4,WOOD:1)
Block(-2,12,-3,AIR:0)
Block(-2,12,-2,AIR:0)
Block(-2,12,-1,AIR:0)
Block(-2,12,0,LOG:1)
Block(-2,12,1,AIR:0)
Block(-2,12,2,AIR:0)
Block(-2,12,3,AIR:0)
Block(-2,12,4,AIR:0)
Block(-2,12,5,AIR:0)
Block(-2,12,6,AIR:0)
Block(-2,12,7,AIR:0)
Block(-2,12,8,AIR:0)
Block(-2,13,-7,AIR:0)
Block(-2,13,-6,AIR:0)
Block(-2,13,-5,AIR:0)
Block(-2,13,-4,WOOD:1)
Block(-2,13,-3,AIR:0)
Block(-2,13,-2,AIR:0)
Block(-2,13,-1,WOOD:1)
Block(-2,13,0,LOG:1)
Block(-2,13,1,WOOD:1)
Block(-2,13,2,WOOD:1)
Block(-2,13,3,WOOD:1)
Block(-2,13,4,WOOD:1)
Block(-2,13,5,WOOD:1)
Block(-2,13,6,WOOD:1)
Block(-2,13,7,WOOD:1)
Block(-2,13,8,WOOD:1)
Block(-2,14,-7,WOOD:1)
Block(-2,14,-6,WOOD:1)
Block(-2,14,-5,WOOD:1)
Block(-2,14,-4,WOOD:1)
Block(-2,14,-3,WOOD:1)
Block(-2,14,-2,WOOD:1)
Block(-2,14,-1,WOOD:1)
Block(-2,14,0,WOOD:1)
Block(-2,14,1,WOOD:1)
Block(-2,14,2,WOOD:1)
Block(-2,14,3,WOOD:1)
Block(-2,14,4,WOOD:1)
Block(-2,14,5,WOOD:1)
Block(-2,14,6,WOOD:1)
Block(-2,14,7,WOOD:1)
Block(-2,14,8,WOOD:1)
Block(-2,15,-7,LOG_2:1)
Block(-2,15,-6,WOOD:1)
Block(-2,15,-5,LOG_2:1)
Block(-2,15,-4,WOOD:1)
Block(-2,15,-3,LOG_2:1)
Block(-2,15,-2,WOOD:1)
Block(-2,15,-1,LOG_2:1)
Block(-2,15,0,WOOD:5)
Block(-2,15,1,WOOD:5)
Block(-2,15,2,WOOD:5)
Block(-2,15,3,WOOD:5)
Block(-2,15,4,WOOD:5)
Block(-2,16,-7,WOOD:5)
Block(-2,16,-6,WOOD:5)
Block(-2,16,-5,WOOD:5)
Block(-2,16,-4,WOOD:5)
Block(-2,16,-3,WOOD:5)
Block(-2,16,-2,WOOD:5)
Block(-2,16,-1,WOOD:5)
Block(-2,16,0,WOOD:5)
Block(-1,4,-7,WOOD_STEP:9)
Block(-1,4,-6,WOOD_STEP:9)
Block(-1,4,-5,WOOD_STEP:9)
Block(-1,4,-4,WOOD_STEP:9)
Block(-1,4,-3,WOOD_STEP:9)
Block(-1,4,-2,SPRUCE_WOOD_STAIRS:5)
Block(-1,4,-1,WOOD_STEP:9)
Block(-1,5,-7,SPRUCE_WOOD_STAIRS:1)
Block(-1,5,-6,SPRUCE_WOOD_STAIRS:1)
Block(-1,5,-5,SPRUCE_WOOD_STAIRS:1)
Block(-1,5,-4,WOOD_STEP:1)
Block(-1,5,3,LEVER:9)
Block(-1,6,-7,TRAP_DOOR:11)
Block(-1,6,-6,TRAP_DOOR:11)
Block(-1,6,-5,SPRUCE_WOOD_STAIRS:5)
Block(-1,6,-3,COBBLE_WALL:0)
Block(-1,6,-1,COBBLE_WALL:0)
Block(-1,6,5,WOOD_STEP:8)
Block(-1,6,6,WOOD_STEP:8)
Block(-1,6,7,WOOD_STEP:8)
Block(-1,6,8,WOOD_STEP:0)
Block(-1,7,-5,WOOD_STEP:0)
Block(-1,7,-4,WOOD_STEP:0)
Block(-1,7,-3,WOOD_STEP:0)
Block(-1,7,-2,WOOD_DOUBLE_STEP:0)
Block(-1,7,-1,WOOD_DOUBLE_STEP:0)
Block(-1,7,0,WOOD_STEP:0)
Block(-1,7,1,WOOD_DOUBLE_STEP:0)
Block(-1,7,2,WOOD_DOUBLE_STEP:0)
Block(-1,7,3,WOOD_DOUBLE_STEP:0)
Block(-1,7,4,WOOD_DOUBLE_STEP:0)
Block(-1,7,5,WOOD:1)
Block(-1,7,6,STATIONARY_WATER:0)
Block(-1,7,7,STATIONARY_WATER:0)
Block(-1,7,8,STATIONARY_WATER:0)
Block(-1,8,-7,STATIONARY_WATER:0)
Block(-1,8,-6,STATIONARY_WATER:0)
Block(-1,8,-5,DISPENSER:4)
Block(-1,8,-4,STATIONARY_WATER:0)
Block(-1,8,-3,STATIONARY_WATER:0)
Block(-1,8,-2,STATIONARY_WATER:0)
Block(-1,8,-1,STATIONARY_WATER:0)
Block(-1,8,0,STATIONARY_WATER:0)
Block(-1,8,1,STATIONARY_WATER:0)
Block(-1,8,2,STATIONARY_WATER:0)
Block(-1,8,3,STATIONARY_WATER:0)
Block(-1,8,4,STATIONARY_WATER:0)
Block(-1,8,5,WOOD:1)
Block(-1,8,6,STATIONARY_WATER:0)
Block(-1,8,7,STATIONARY_WATER:0)
Block(-1,8,8,STATIONARY_WATER:0)
Block(-1,9,-7,STATIONARY_WATER:0)
Block(-1,9,-6,STATIONARY_WATER:0)
Block(-1,9,-5,STATIONARY_WATER:0)
Block(-1,9,-4,STATIONARY_WATER:0)
Block(-1,9,-3,STATIONARY_WATER:0)
Block(-1,9,-2,STATIONARY_WATER:0)
Block(-1,9,-1,STATIONARY_WATER:0)
Block(-1,9,0,STATIONARY_WATER:0)
Block(-1,9,1,STATIONARY_WATER:0)
Block(-1,9,2,STATIONARY_WATER:0)
Block(-1,9,3,STATIONARY_WATER:0)
Block(-1,9,4,STATIONARY_WATER:0)
Block(-1,9,5,WOOD:1)
Block(-1,9,6,STATIONARY_WATER:0)
Block(-1,9,7,STATIONARY_WATER:0)
Block(-1,9,8,STATIONARY_WATER:0)
Block(-1,10,-7,WOOD_STEP:0)
Block(-1,10,-6,WOOD_STEP:0)
Block(-1,10,-5,WOOD_STEP:0)
Block(-1,10,-4,WOOD_DOUBLE_STEP:0)
Block(-1,10,-3,WOOD_DOUBLE_STEP:0)
Block(-1,10,-2,WOOD_DOUBLE_STEP:0)
Block(-1,10,-1,WOOD_DOUBLE_STEP:0)
Block(-1,10,0,WOOD_DOUBLE_STEP:0)
Block(-1,10,1,WOOD_DOUBLE_STEP:0)
Block(-1,10,2,WOOD_DOUBLE_STEP:0)
Block(-1,10,3,WOOD_DOUBLE_STEP:0)
Block(-1,10,4,WOOD_STEP:0)
Block(-1,10,5,WOOD_STEP:0)
Block(-1,10,6,WOOD_STEP:0)
Block(-1,10,7,AIR:0)
Block(-1,10,8,AIR:0)
Block(-1,11,-7,STATIONARY_WATER:0)
Block(-1,11,-6,STATIONARY_WATER:0)
Block(-1,11,-5,STATIONARY_WATER:0)
Block(-1,11,-4,WOOD:1)
Block(-1,11,-3,AIR:0)
Block(-1,11,-2,AIR:0)
Block(-1,11,-1,AIR:0)
Block(-1,11,0,AIR:0)
Block(-1,11,1,AIR:0)
Block(-1,11,2,AIR:0)
Block(-1,11,3,WOOD:1)
Block(-1,11,4,AIR:0)
Block(-1,11,5,AIR:0)
Block(-1,11,6,AIR:0)
Block(-1,11,7,AIR:0)
Block(-1,11,8,AIR:0)
Block(-1,12,-7,STATIONARY_WATER:0)
Block(-1,12,-6,STATIONARY_WATER:0)
Block(-1,12,-5,STATIONARY_WATER:0)
Block(-1,12,-4,WOOD:1)
Block(-1,12,-3,AIR:0)
Block(-1,12,-2,AIR:0)
Block(-1,12,-1,AIR:0)
Block(-1,12,0,AIR:0)
Block(-1,12,1,AIR:0)
Block(-1,12,2,AIR:0)
Block(-1,12,3,WOOD:1)
Block(-1,12,4,AIR:0)
Block(-1,12,5,AIR:0)
Block(-1,12,6,AIR:0)
Block(-1,12,7,AIR:0)
Block(-1,12,8,AIR:0)
Block(-1,13,-7,AIR:0)
Block(-1,13,-6,AIR:0)
Block(-1,13,-5,AIR:0)
Block(-1,13,-4,WOOD:1)
Block(-1,13,-3,AIR:0)
Block(-1,13,-2,AIR:0)
Block(-1,13,-1,WOOD:1)
Block(-1,13,0,WOOD:1)
Block(-1,13,1,WOOD:1)
Block(-1,13,2,WOOD:1)
Block(-1,13,3,WOOD:1)
Block(-1,13,4,WOOD:1)
Block(-1,13,5,WOOD:1)
Block(-1,13,6,WOOD:1)
Block(-1,13,7,WOOD:1)
Block(-1,13,8,WOOD:1)
Block(-1,14,-7,WOOD:1)
Block(-1,14,-6,WOOD:1)
Block(-1,14,-5,WOOD:1)
Block(-1,14,-4,WOOD:1)
Block(-1,14,-3,WOOD:1)
Block(-1,14,-2,WOOD:1)
Block(-1,14,-1,WOOD:1)
Block(-1,14,0,WOOD:1)
Block(-1,15,-7,WOOD:1)
Block(0,5,0,WOOD:2)
Block(0,5,1,WOOD:2)
Block(0,6,0,WOOD:2)
Block(0,6,1,WOOD:2)
Block(0,6,5,WOOD_STEP:8)
Block(0,6,6,WOOD_STEP:8)
Block(0,6,7,WOOD_STEP:0)
Block(0,6,8,WOOD_STEP:0)
Block(0,7,-7,WOOD_STEP:0)
Block(0,7,-6,WOOD_STEP:0)
Block(0,7,-5,WOOD_DOUBLE_STEP:0)
Block(0,7,-4,WOOD_STEP:0)
Block(0,7,-3,WOOD_STEP:0)
Block(0,7,-2,WOOD_DOUBLE_STEP:0)
Block(0,7,-1,WOOD_DOUBLE_STEP:0)
Block(0,7,0,WOOD_DOUBLE_STEP:0)
Block(0,7,1,WOOD_DOUBLE_STEP:0)
Block(0,7,2,WOOD_DOUBLE_STEP:0)
Block(0,7,3,WOOD_DOUBLE_STEP:0)
Block(0,7,4,WOOD_DOUBLE_STEP:0)
Block(0,7,5,WOOD:1)
Block(0,7,6,STATIONARY_WATER:0)
Block(0,7,7,STATIONARY_WATER:0)
Block(0,7,8,STATIONARY_WATER:0)
Block(0,8,-7,STATIONARY_WATER:0)
Block(0,8,-6,STATIONARY_WATER:0)
Block(0,8,-5,CONCRETE:15)
Block(0,8,-4,STATIONARY_WATER:0)
Block(0,8,-3,STATIONARY_WATER:0)
Block(0,8,-2,STATIONARY_WATER:0)
Block(0,8,-1,DISPENSER:2)
Block(0,8,0,CONCRETE:15)
Block(0,8,1,DISPENSER:3)
Block(0,8,2,SPRUCE_WOOD_STAIRS:7)
Block(0,8,3,STATIONARY_WATER:0)
Block(0,8,4,STATIONARY_WATER:0)
Block(0,8,5,WOOD:1)
Block(0,8,6,STATIONARY_WATER:0)
Block(0,8,7,STATIONARY_WATER:0)
Block(0,8,8,STATIONARY_WATER:0)
Block(0,9,-7,STATIONARY_WATER:0)
Block(0,9,-6,STATIONARY_WATER:0)
Block(0,9,-5,STATIONARY_WATER:0)
Block(0,9,-4,STATIONARY_WATER:0)
Block(0,9,-3,STATIONARY_WATER:0)
Block(0,9,-2,STATIONARY_WATER:0)
Block(0,9,-1,STATIONARY_WATER:0)
Block(0,9,0,STATIONARY_WATER:0)
Block(0,9,1,STATIONARY_WATER:0)
Block(0,9,2,STATIONARY_WATER:0)
Block(0,9,3,STATIONARY_WATER:0)
Block(0,9,4,STATIONARY_WATER:0)
Block(0,9,5,WOOD:1)
Block(0,9,6,STATIONARY_WATER:0)
Block(0,9,7,STATIONARY_WATER:0)
Block(0,9,8,STATIONARY_WATER:0)
Block(0,10,-7,WOOD_STEP:0)
Block(0,10,-6,WOOD_STEP:0)
Block(0,10,-5,WOOD_STEP:0)
Block(0,10,-4,WOOD_DOUBLE_STEP:0)
Block(0,10,-3,WOOD_DOUBLE_STEP:0)
Block(0,10,-2,WOOD_DOUBLE_STEP:0)
Block(0,10,-1,WOOD_DOUBLE_STEP:0)
Block(0,10,0,WOOD_DOUBLE_STEP:0)
Block(0,10,1,WOOD_DOUBLE_STEP:0)
Block(0,10,2,WOOD_DOUBLE_STEP:0)
Block(0,10,3,WOOD_DOUBLE_STEP:0)
Block(0,10,4,WOOD_STEP:0)
Block(0,10,5,WOOD_STEP:0)
Block(0,10,6,WOOD_STEP:0)
Block(0,10,7,WOOD_STEP:0)
Block(0,10,8,AIR:0)
Block(0,11,-7,STATIONARY_WATER:0)
Block(0,11,-6,STATIONARY_WATER:0)
Block(0,11,-5,STATIONARY_WATER:0)
Block(0,11,-4,WOOD:1)
Block(0,11,-3,AIR:0)
Block(0,11,-2,AIR:0)
Block(0,11,-1,AIR:0)
Block(0,11,0,AIR:0)
Block(0,11,1,AIR:0)
Block(0,11,2,AIR:0)
Block(0,11,3,WOOD:1)
Block(0,11,4,AIR:0)
Block(0,11,5,AIR:0)
Block(0,11,6,AIR:0)
Block(0,11,7,AIR:0)
Block(0,11,8,AIR:0)
Block(0,12,-7,STATIONARY_WATER:0)
Block(0,12,-6,STATIONARY_WATER:0)
Block(0,12,-5,STATIONARY_WATER:0)
Block(0,12,-4,WOOD:1)
Block(0,12,-3,AIR:0)
Block(0,12,-2,AIR:0)
Block(0,12,-1,AIR:0)
Block(0,12,0,AIR:0)
Block(0,12,1,AIR:0)
Block(0,12,2,AIR:0)
Block(0,12,3,WOOD:1)
Block(0,12,4,AIR:0)
Block(0,12,5,AIR:0)
Block(0,12,6,WOOD:1)
Block(0,12,7,WOOD:1)
Block(0,12,8,WOOD:1)
Block(0,13,-7,AIR:0)
Block(0,13,-6,AIR:0)
Block(0,13,-5,WOOD:1)
Block(0,13,-4,WOOD:1)
Block(0,13,-3,WOOD:1)
Block(0,13,-2,WOOD:1)
Block(0,13,-1,WOOD:1)
Block(0,13,0,WOOD:1)
Block(0,13,1,WOOD:1)
Block(0,13,2,WOOD:1)
Block(0,13,3,WOOD:1)
Block(0,13,4,WOOD:1)
Block(0,13,5,WOOD:1)
Block(0,14,-7,WOOD:1)
Block(0,14,-6,WOOD:1)
Block(1,5,0,WOOD:2)
Block(1,5,1,WOOD:2)
Block(1,6,0,WOOD:2)
Block(1,6,1,WOOD:2)
Block(1,6,4,WOOD_STEP:8)
Block(1,6,5,WOOD_STEP:8)
Block(1,6,6,WOOD_STEP:8)
Block(1,6,7,WOOD_DOUBLE_STEP:0)
Block(1,6,8,WOOD_DOUBLE_STEP:0)
Block(1,7,-7,WOOD_DOUBLE_STEP:0)
Block(1,7,-6,WOOD_STEP:0)
Block(1,7,-5,WOOD_DOUBLE_STEP:0)
Block(1,7,-4,WOOD_STEP:0)
Block(1,7,-3,WOOD_DOUBLE_STEP:0)
Block(1,7,-2,WOOD_STEP:0)
Block(1,7,-1,WOOD_STEP:0)
Block(1,7,0,WOOD_DOUBLE_STEP:0)
Block(1,7,1,WOOD_DOUBLE_STEP:0)
Block(1,7,2,WOOD_STEP:0)
Block(1,7,3,WOOD_STEP:0)
Block(1,7,4,WOOD_DOUBLE_STEP:0)
Block(1,7,5,WOOD_DOUBLE_STEP:0)
RandomBlock(1,7,6,SKULL:1,../../../../Skulls/dungeon_skull_01.nbt,6,AIR,9,SKULL:1,../../../../Skulls/dungeon_skull_02.nbt,12,AIR,15,SKULL:1,../../../../Skulls/dungeon_skull_03.nbt,18,AIR,21,SKULL:1,../../../../Skulls/dungeon_skull_04.nbt,24,AIR,27,SKULL:1,../../../../Skulls/dungeon_skull_05.nbt,30,AIR,33,SKULL:1,../../../../Skulls/dungeon_skull_06.nbt,36,AIR,39,SKULL:1,../../../../Skulls/dungeon_skull_07.nbt,42,AIR,45,SKULL:1,../../../../Skulls/dungeon_skull_08.nbt,48,AIR,51,SKULL:1,../../../../Skulls/dungeon_skull_09.nbt,54,AIR,57,SKULL:1,../../../../Skulls/dungeon_skull_10.nbt,60,AIR,63,SKULL:1,../../../../Skulls/dungeon_skull_11.nbt,66,AIR,69,SKULL:1,../../../../Skulls/dungeon_skull_12.nbt,72,AIR,75,SKULL:1,../../../../Skulls/dungeon_skull_13.nbt,78,AIR,81,SKULL:1,../../../../Skulls/dungeon_skull_14.nbt,84,AIR,87,SKULL:1,../../../../Skulls/dungeon_skull_15.nbt,90,AIR,93,SKULL:1,../../../../Skulls/dungeon_skull_16.nbt,96,AIR,100)
Block(1,7,7,STATIONARY_WATER:0)
Block(1,7,8,STATIONARY_WATER:0)
Block(1,8,-7,STATIONARY_WATER:0)
Block(1,8,-6,STATIONARY_WATER:0)
Block(1,8,-5,DISPENSER:5)
Block(1,8,-4,STATIONARY_WATER:0)
Block(1,8,-3,STATIONARY_WATER:0)
Block(1,8,-2,STATIONARY_WATER:0)
Block(1,8,-1,STATIONARY_WATER:0)
Block(1,8,0,STATIONARY_WATER:0)
Block(1,8,1,STATIONARY_WATER:0)
Block(1,8,2,STATIONARY_WATER:0)
Block(1,8,3,STATIONARY_WATER:0)
Block(1,8,4,STATIONARY_WATER:0)
Block(1,8,5,WOOD:1)
Block(1,8,6,STATIONARY_WATER:0)
Block(1,8,7,STATIONARY_WATER:0)
Block(1,8,8,STATIONARY_WATER:0)
Block(1,9,-7,STATIONARY_WATER:0)
Block(1,9,-6,STATIONARY_WATER:0)
Block(1,9,-5,STATIONARY_WATER:0)
Block(1,9,-4,STATIONARY_WATER:0)
Block(1,9,-3,STATIONARY_WATER:0)
Block(1,9,-2,STATIONARY_WATER:0)
Block(1,9,-1,STATIONARY_WATER:0)
Block(1,9,0,STATIONARY_WATER:0)
Block(1,9,1,STATIONARY_WATER:0)
Block(1,9,2,STATIONARY_WATER:0)
Block(1,9,3,STATIONARY_WATER:0)
Block(1,9,4,STATIONARY_WATER:0)
Block(1,9,5,WOOD:1)
Block(1,9,6,STATIONARY_WATER:0)
Block(1,9,7,STATIONARY_WATER:0)
Block(1,9,8,STATIONARY_WATER:0)
Block(1,10,-5,WOOD_STEP:0)
Block(1,10,-4,WOOD_DOUBLE_STEP:0)
Block(1,10,-3,WOOD_DOUBLE_STEP:0)
Block(1,10,-2,WOOD_DOUBLE_STEP:0)
Block(1,10,-1,WOOD_DOUBLE_STEP:0)
Block(1,10,0,WOOD_DOUBLE_STEP:0)
Block(1,10,1,WOOD_DOUBLE_STEP:0)
Block(1,10,2,WOOD_DOUBLE_STEP:0)
Block(1,10,3,WOOD_DOUBLE_STEP:0)
Block(1,10,4,WOOD_STEP:0)
Block(1,10,5,WOOD_STEP:0)
Block(1,10,6,WOOD_STEP:0)
Block(1,10,7,WOOD_STEP:0)
Block(1,10,8,WOOD_STEP:0)
Block(1,11,-7,STATIONARY_WATER:0)
Block(1,11,-6,STATIONARY_WATER:0)
Block(1,11,-5,STATIONARY_WATER:0)
Block(1,11,-4,WOOD:1)
Block(1,11,-3,AIR:0)
Block(1,11,-2,AIR:0)
Block(1,11,-1,AIR:0)
Block(1,11,0,AIR:0)
Block(1,11,1,AIR:0)
RandomBlock(1,11,2,CHEST:2,../../../../Chests/Traveler/Travelers_Castle.nbt,1,CHEST:2,../../../../Chests/Traveler/Travelers_Church.nbt,1,CHEST:2,../../../../Chests/Traveler/Travelers_Daeroc.nbt,1,CHEST:2,../../../../Chests/Traveler/Travelers_Farmsteads.nbt,1,CHEST:2,../../../../Chests/Traveler/Travelers_GreenDungeon.nbt,1,CHEST:2,../../../../Chests/Traveler/Travelers_IceShips.nbt,1,CHEST:2,../../../../Chests/Traveler/Travelers_IceTemple.nbt,1,CHEST:2,../../../../Chests/Traveler/Travelers_LegacySpawn.nbt,1,CHEST:2,../../../../Chests/Traveler/Travelers_Mineshafts.nbt,1,CHEST:2,../../../../Chests/Traveler/Travelers_Mountains.nbt,1,CHEST:2,../../../../Chests/Traveler/Travelers_Origin.nbt,1,CHEST:2,../../../../Chests/Traveler/Travelers_Pirate.nbt,1,CHEST:2,../../../../Chests/Traveler/Travelers_Quarry.nbt,1,CHEST:2,../../../../Chests/Traveler/Travelers_Spook.nbt,1,CHEST:2,../../../../Chests/Traveler/Travelers_Tribal.nbt,1,CHEST:2,../../../../Chests/Lore/ShipSunk_1.nbt,1,CHEST:2,../../../../Chests/Lore/ShipSunk_2.nbt,1,CHEST:2,../../../../Chests/Lore/ShipSunk_3.nbt,1,CHEST:2,../../../../Chests/Lore/ShipSunk_4.nbt,1,CHEST:2,../../../../Chests/Lore/ShipSunk_5.nbt,1,CHEST:2,../../../../Chests/Loot/Common1.nbt,5,CHEST:2,../../../../Chests/Loot/Common2.nbt,5,CHEST:2,../../../../Chests/Loot/Common3.nbt,5,CHEST:2,../../../../Chests/Loot/Common4.nbt,5,CHEST:2,../../../../Chests/Loot/Common5.nbt,5,CHEST:2,../../../../Chests/Loot/Common6.nbt,5,CHEST:2,../../../../Chests/Loot/Common7.nbt,5,CHEST:2,../../../../Chests/Loot/Common8.nbt,5,CHEST:2,../../../../Chests/Loot/Common9.nbt,5,CHEST:2,../../../../Chests/Loot/Common10.nbt,5,CHEST:2,../../../../Chests/Loot/Common11.nbt,5,CHEST:2,../../../../Chests/Loot/Common12.nbt,5,CHEST:2,../../../../Chests/Loot/Common13.nbt,5,CHEST:2,../../../../Chests/Loot/Common14.nbt,5,CHEST:2,../../../../Chests/Loot/Common15.nbt,5,CHEST:2,../../../../Chests/Lore/ShipSunk_1.nbt,2,CHEST:2,../../../../Chests/Lore/ShipSunk_2.nbt,2,CHEST:2,../../../../Chests/Lore/ShipSunk_3.nbt,2,CHEST:2,../../../../Chests/Lore/ShipSunk_4.nbt,2,CHEST:2,../../../../Chests/Lore/ShipSunk_5.nbt,2,CHEST:2,../../../../Chests/Loot/Rare1.nbt,5,CHEST:2,../../../../Chests/Loot/Rare2.nbt,5,CHEST:2,../../../../Chests/Loot/Rare3.nbt,5,CHEST:2,../../../../Chests/Loot/Rare4.nbt,5,CHEST:2,../../../../Chests/Loot/Rare5.nbt,5,CHEST:2,../../../../Chests/Loot/Rare6.nbt,5,CHEST:2,../../../../Chests/Loot/Rare7.nbt,5,CHEST:2,../../../../Chests/Loot/Rare8.nbt,5,CHEST:2,../../../../Chests/Loot/Rare9.nbt,5,CHEST:2,../../../../Chests/Loot/Rare10.nbt,5,CHEST:2,../../../../Chests/Loot/Rare11.nbt,5,CHEST:2,../../../../Chests/Loot/Rare12.nbt,5,CHEST:2,../../../../Chests/Loot/Rare13.nbt,5,CHEST:2,../../../../Chests/Loot/Rare14.nbt,5,CHEST:2,../../../../Chests/Loot/Rare15.nbt,5,CHEST:2,../../../../Chests/Loot/Epic1.nbt,2,CHEST:2,../../../../Chests/Loot/Epic2.nbt,2,CHEST:2,../../../../Chests/Loot/Epic3.nbt,2,CHEST:2,../../../../Chests/Loot/Epic4.nbt,2,CHEST:2,../../../../Chests/Loot/Epic5.nbt,2,CHEST:2,../../../../Chests/Loot/Epic6.nbt,2,CHEST:2,../../../../Chests/Loot/Epic7.nbt,2,CHEST:2,../../../../Chests/Loot/Epic8.nbt,2,CHEST:2,../../../../Chests/Loot/Epic9.nbt,2,CHEST:2,../../../../Chests/Loot/Epic10.nbt,2,CHEST:2,../../../../Chests/Loot/Epic11.nbt,2,CHEST:2,../../../../Chests/Loot/Epic12.nbt,2,CHEST:2,../../../../Chests/Loot/Epic13.nbt,2,CHEST:2,../../../../Chests/Loot/Epic14.nbt,2,CHEST:2,../../../../Chests/Loot/Epic15.nbt,5,CHEST:2,../../../../Chests/Loot/Rare1.nbt,5,CHEST:2,../../../../Chests/Loot/Rare2.nbt,5,CHEST:2,../../../../Chests/Loot/Rare3.nbt,5,CHEST:2,../../../../Chests/Loot/Rare4.nbt,5,CHEST:2,../../../../Chests/Loot/Rare5.nbt,10,CHEST:2,../../../../Chests/Loot/Rare6.nbt,10,CHEST:2,../../../../Chests/Loot/Rare7.nbt,10,CHEST:2,../../../../Chests/Loot/Rare8.nbt,10,CHEST:2,../../../../Chests/Loot/Rare9.nbt,10,CHEST:2,../../../../Chests/Loot/Rare10.nbt,15,CHEST:2,../../../../Chests/Loot/Rare11.nbt,15,CHEST:2,../../../../Chests/Loot/Rare12.nbt,15,CHEST:2,../../../../Chests/Loot/Rare13.nbt,15,CHEST:2,../../../../Chests/Loot/Rare14.nbt,15,CHEST:2,../../../../Chests/Loot/Rare15.nbt,15,CHEST:2,../../../../Chests/Loot/Epic15.nbt,100)
Block(1,11,3,WOOD:1)
Block(1,11,4,AIR:0)
Block(1,11,5,AIR:0)
Block(1,11,6,AIR:0)
Block(1,11,7,AIR:0)
Block(1,11,8,WOOD:1)
Block(1,12,-7,STATIONARY_WATER:0)
Block(1,12,-6,STATIONARY_WATER:0)
Block(1,12,-5,STATIONARY_WATER:0)
Block(1,12,-4,WOOD:1)
Block(1,12,-3,AIR:0)
Block(1,12,-2,AIR:0)
Block(1,12,-1,AIR:0)
Block(1,12,0,AIR:0)
Block(1,12,1,AIR:0)
Block(1,12,2,AIR:0)
Block(1,12,3,WOOD:1)
Block(1,12,4,WOOD:1)
Block(1,12,5,WOOD:1)
Block(1,12,6,WOOD:1)
Block(1,12,7,WOOD:1)
Block(1,13,-7,WOOD:1)
Block(1,13,-6,WOOD:1)
Block(1,13,-5,WOOD:1)
Block(1,13,-4,WOOD:1)
Block(1,13,-3,WOOD:1)
Block(1,13,-2,WOOD:1)
Block(1,13,-1,WOOD:1)
Block(1,13,0,WOOD:1)
Block(1,13,1,WOOD:1)
Block(1,13,2,WOOD:1)
Block(2,5,4,WOOD_STEP:13)
Block(2,5,5,WOOD_STEP:13)
Block(2,5,6,WOOD:5)
Block(2,5,7,DARK_OAK_STAIRS:3)
Block(2,5,8,WOOD_STEP:5)
Block(2,6,3,WOOD:5)
Block(2,6,4,DARK_OAK_STAIRS:3)
Block(2,6,5,WOOD_DOUBLE_STEP:5)
Block(2,6,6,DARK_OAK_STAIRS:3)
Block(2,6,7,WOOD_STEP:5)
Block(2,6,8,WOOD_STEP:5)
Block(2,7,-7,WOOD_STEP:0)
Block(2,7,-6,WOOD_STEP:0)
Block(2,7,-5,WOOD_STEP:0)
Block(2,7,-4,WOOD_STEP:0)
Block(2,7,-3,WOOD_STEP:0)
Block(2,7,-2,WOOD_DOUBLE_STEP:0)
Block(2,7,-1,WOOD_DOUBLE_STEP:0)
Block(2,7,0,WOOD_DOUBLE_STEP:0)
Block(2,7,1,WOOD_STEP:0)
Block(2,7,2,WOOD_DOUBLE_STEP:0)
Block(2,7,3,WOOD_DOUBLE_STEP:0)
Block(2,7,4,DARK_OAK_STAIRS:7)
Block(2,7,5,DARK_OAK_STAIRS:6)
Block(2,7,6,WOOD:5)
Block(2,7,7,WOOD_STEP:5)
Block(2,7,8,WOOD_STEP:5)
Block(2,8,-7,STATIONARY_WATER:0)
Block(2,8,-6,STATIONARY_WATER:0)
Block(2,8,-4,STATIONARY_WATER:0)
Block(2,8,-3,STATIONARY_WATER:0)
Block(2,8,-2,STATIONARY_WATER:0)
Block(2,8,-1,STATIONARY_WATER:0)
Block(2,8,0,STATIONARY_WATER:0)
Block(2,8,1,STATIONARY_WATER:0)
Block(2,8,2,STATIONARY_WATER:0)
Block(2,8,3,STATIONARY_WATER:0)
Block(2,8,4,STATIONARY_WATER:0)
Block(2,8,5,WOOD:0)
Block(2,8,6,WOOD:0)
Block(2,8,7,STATIONARY_WATER:0)
Block(2,8,8,STATIONARY_WATER:0)
Block(2,9,-7,STATIONARY_WATER:0)
Block(2,9,-6,STATIONARY_WATER:0)
Block(2,9,-5,STATIONARY_WATER:0)
Block(2,9,-4,STATIONARY_WATER:0)
Block(2,9,-3,STATIONARY_WATER:0)
Block(2,9,-2,STATIONARY_WATER:0)
Block(2,9,-1,STATIONARY_WATER:0)
Block(2,9,0,STATIONARY_WATER:0)
Block(2,9,1,STATIONARY_WATER:0)
Block(2,9,2,STATIONARY_WATER:0)
Block(2,9,3,STATIONARY_WATER:0)
Block(2,9,4,STATIONARY_WATER:0)
Block(2,9,5,WOOD:5)
Block(2,9,6,WOOD:5)
Block(2,9,7,WOOD:5)
Block(2,9,8,STATIONARY_WATER:0)
Block(2,10,-7,STATIONARY_WATER:0)
Block(2,10,-6,STATIONARY_WATER:0)
Block(2,10,-5,WOOD_STEP:0)
Block(2,10,-4,WOOD_DOUBLE_STEP:0)
Block(2,10,-3,WOOD_DOUBLE_STEP:0)
Block(2,10,-2,WOOD_DOUBLE_STEP:0)
Block(2,10,-1,WOOD_DOUBLE_STEP:0)
Block(2,10,0,WOOD_DOUBLE_STEP:0)
Block(2,10,1,WOOD_DOUBLE_STEP:0)
Block(2,10,2,WOOD_DOUBLE_STEP:0)
Block(2,10,3,WOOD:5)
Block(2,10,4,WOOD:5)
Block(2,10,5,WOOD:5)
Block(2,10,6,WOOD:1)
Block(2,10,7,WOOD:1)
Block(2,10,8,WOOD:1)
Block(2,11,-7,STATIONARY_WATER:0)
Block(2,11,-6,STATIONARY_WATER:0)
Block(2,11,-5,STATIONARY_WATER:0)
Block(2,11,-4,WOOD:1)
RandomBlock(2,11,-3,AIR:0,20,CHEST:4,../../../../Chests/Loot/ShipJunk_1.nbt,10,CHEST:4,../../../../Chests/Loot/ShipJunk_2.nbt,10,CHEST:4,../../../../Chests/Loot/ShipJunk_3.nbt,10,CHEST:4,../../../../Chests/Loot/ShipJunk_4.nbt,10,CHEST:4,../../../../Chests/Loot/ShipJunk_5.nbt,10,CHEST:4,../../../../Chests/Traveler/Travelers_Castle.nbt,1,CHEST:4,../../../../Chests/Traveler/Travelers_Church.nbt,1,CHEST:4,../../../../Chests/Traveler/Travelers_Daeroc.nbt,1,CHEST:4,../../../../Chests/Traveler/Travelers_Farmsteads.nbt,1,CHEST:4,../../../../Chests/Traveler/Travelers_GreenDungeon.nbt,1,CHEST:4,../../../../Chests/Traveler/Travelers_IceShips.nbt,1,CHEST:4,../../../../Chests/Traveler/Travelers_IceTemple.nbt,1,CHEST:4,../../../../Chests/Traveler/Travelers_LegacySpawn.nbt,1,CHEST:4,../../../../Chests/Traveler/Travelers_Mineshafts.nbt,1,CHEST:4,../../../../Chests/Traveler/Travelers_Mountains.nbt,1,CHEST:4,../../../../Chests/Traveler/Travelers_Origin.nbt,1,CHEST:4,../../../../Chests/Traveler/Travelers_Pirate.nbt,1,CHEST:4,../../../../Chests/Traveler/Travelers_Quarry.nbt,1,CHEST:4,../../../../Chests/Traveler/Travelers_Spook.nbt,1,CHEST:4,../../../../Chests/Traveler/Travelers_Tribal.nbt,1,CHEST:4,../../../../Chests/Lore/ShipSunk_1.nbt,1,CHEST:4,../../../../Chests/Lore/ShipSunk_2.nbt,1,CHEST:4,../../../../Chests/Lore/ShipSunk_3.nbt,1,CHEST:4,../../../../Chests/Lore/ShipSunk_4.nbt,1,CHEST:4,../../../../Chests/Lore/ShipSunk_5.nbt,1,CHEST:4,../../../../Chests/Loot/Common1.nbt,10,CHEST:4,../../../../Chests/Loot/Common2.nbt,10,CHEST:4,../../../../Chests/Loot/Common3.nbt,10,CHEST:4,../../../../Chests/Loot/Common4.nbt,10,CHEST:4,../../../../Chests/Loot/Common5.nbt,10,CHEST:4,../../../../Chests/Loot/Common6.nbt,10,CHEST:4,../../../../Chests/Loot/Common7.nbt,10,CHEST:4,../../../../Chests/Loot/Common8.nbt,10,CHEST:4,../../../../Chests/Loot/Common9.nbt,10,CHEST:4,../../../../Chests/Loot/Common10.nbt,10,CHEST:4,../../../../Chests/Loot/Common10.nbt,11,CHEST:4,../../../../Chests/Loot/Common12.nbt,10,CHEST:4,../../../../Chests/Loot/Common13.nbt,10,CHEST:4,../../../../Chests/Loot/Common14.nbt,10,CHEST:4,../../../../Chests/Loot/Common15.nbt,10,CHEST:4,../../../../Chests/Lore/ShipSunk_1.nbt,2,CHEST:4,../../../../Chests/Lore/ShipSunk_3.nbt,2,CHEST:4,../../../../Chests/Lore/ShipSunk_4.nbt,2,CHEST:4,../../../../Chests/Lore/ShipSunk_5.nbt,2,CHEST:4,../../../../Chests/Lore/ShipSunk_5.nbt,2,CHEST:4,../../../../Chests/Loot/Rare1.nbt,5,CHEST:4,../../../../Chests/Loot/Rare2.nbt,5,CHEST:4,../../../../Chests/Loot/Rare3.nbt,5,CHEST:4,../../../../Chests/Loot/Rare4.nbt,5,CHEST:4,../../../../Chests/Loot/Rare5.nbt,5,CHEST:4,../../../../Chests/Loot/Rare6.nbt,5,CHEST:4,../../../../Chests/Loot/Rare7.nbt,5,CHEST:4,../../../../Chests/Loot/Rare8.nbt,5,CHEST:4,../../../../Chests/Loot/Rare9.nbt,5,CHEST:4,../../../../Chests/Loot/Rare10.nbt,5,CHEST:4,../../../../Chests/Loot/Rare11.nbt,5,CHEST:4,../../../../Chests/Loot/Rare12.nbt,5,CHEST:4,../../../../Chests/Loot/Rare13.nbt,5,CHEST:4,../../../../Chests/Loot/Rare14.nbt,5,CHEST:4,../../../../Chests/Loot/Rare15.nbt,5,CHEST:4,../../../../Chests/Loot/Epic1.nbt,2,CHEST:4,../../../../Chests/Loot/Epic2.nbt,2,CHEST:4,../../../../Chests/Loot/Epic3.nbt,2,CHEST:4,../../../../Chests/Loot/Epic4.nbt,2,CHEST:4,../../../../Chests/Loot/Epic5.nbt,2,CHEST:4,../../../../Chests/Loot/Epic6.nbt,2,CHEST:4,../../../../Chests/Loot/Epic7.nbt,2,CHEST:4,../../../../Chests/Loot/Epic8.nbt,2,CHEST:4,../../../../Chests/Loot/Epic9.nbt,2,CHEST:4,../../../../Chests/Loot/Epic10.nbt,2,CHEST:4,../../../../Chests/Loot/Epic11.nbt,2,CHEST:4,../../../../Chests/Loot/Epic12.nbt,2,CHEST:4,../../../../Chests/Loot/Epic13.nbt,2,CHEST:4,../../../../Chests/Loot/Epic14.nbt,2,CHEST:4,../../../../Chests/Loot/Epic15.nbt,5,CHEST:4,../../../../Chests/Loot/Rare1.nbt,5,CHEST:4,../../../../Chests/Loot/Rare2.nbt,5,CHEST:4,../../../../Chests/Loot/Rare3.nbt,5,CHEST:4,../../../../Chests/Loot/Rare4.nbt,5,CHEST:4,../../../../Chests/Loot/Rare5.nbt,10,CHEST:4,../../../../Chests/Loot/Rare6.nbt,10,CHEST:4,../../../../Chests/Loot/Rare7.nbt,10,CHEST:4,../../../../Chests/Loot/Rare8.nbt,10,CHEST:4,../../../../Chests/Loot/Rare9.nbt,10,CHEST:4,../../../../Chests/Loot/Rare10.nbt,15,CHEST:4,../../../../Chests/Loot/Rare11.nbt,15,CHEST:4,../../../../Chests/Loot/Rare12.nbt,15,CHEST:4,../../../../Chests/Loot/Rare13.nbt,15,CHEST:4,../../../../Chests/Loot/Rare14.nbt,15,CHEST:4,../../../../Chests/Loot/Rare15.nbt,15,CHEST:4,../../../../Chests/Loot/Epic15.nbt,100)
RandomBlock(2,11,-2,AIR:0,20,CHEST:4,../../../../Chests/Loot/ShipJunk_1.nbt,10,CHEST:4,../../../../Chests/Loot/ShipJunk_2.nbt,10,CHEST:4,../../../../Chests/Loot/ShipJunk_3.nbt,10,CHEST:4,../../../../Chests/Loot/ShipJunk_4.nbt,10,CHEST:4,../../../../Chests/Loot/ShipJunk_5.nbt,10,CHEST:4,../../../../Chests/Traveler/Travelers_Castle.nbt,1,CHEST:4,../../../../Chests/Traveler/Travelers_Church.nbt,1,CHEST:4,../../../../Chests/Traveler/Travelers_Daeroc.nbt,1,CHEST:4,../../../../Chests/Traveler/Travelers_Farmsteads.nbt,1,CHEST:4,../../../../Chests/Traveler/Travelers_GreenDungeon.nbt,1,CHEST:4,../../../../Chests/Traveler/Travelers_IceShips.nbt,1,CHEST:4,../../../../Chests/Traveler/Travelers_IceTemple.nbt,1,CHEST:4,../../../../Chests/Traveler/Travelers_LegacySpawn.nbt,1,CHEST:4,../../../../Chests/Traveler/Travelers_Mineshafts.nbt,1,CHEST:4,../../../../Chests/Traveler/Travelers_Mountains.nbt,1,CHEST:4,../../../../Chests/Traveler/Travelers_Origin.nbt,1,CHEST:4,../../../../Chests/Traveler/Travelers_Pirate.nbt,1,CHEST:4,../../../../Chests/Traveler/Travelers_Quarry.nbt,1,CHEST:4,../../../../Chests/Traveler/Travelers_Spook.nbt,1,CHEST:4,../../../../Chests/Traveler/Travelers_Tribal.nbt,1,CHEST:4,../../../../Chests/Lore/ShipSunk_1.nbt,1,CHEST:4,../../../../Chests/Lore/ShipSunk_2.nbt,1,CHEST:4,../../../../Chests/Lore/ShipSunk_3.nbt,1,CHEST:4,../../../../Chests/Lore/ShipSunk_4.nbt,1,CHEST:4,../../../../Chests/Lore/ShipSunk_5.nbt,1,CHEST:4,../../../../Chests/Loot/Common1.nbt,10,CHEST:4,../../../../Chests/Loot/Common2.nbt,10,CHEST:4,../../../../Chests/Loot/Common3.nbt,10,CHEST:4,../../../../Chests/Loot/Common4.nbt,10,CHEST:4,../../../../Chests/Loot/Common5.nbt,10,CHEST:4,../../../../Chests/Loot/Common6.nbt,10,CHEST:4,../../../../Chests/Loot/Common7.nbt,10,CHEST:4,../../../../Chests/Loot/Common8.nbt,10,CHEST:4,../../../../Chests/Loot/Common9.nbt,10,CHEST:4,../../../../Chests/Loot/Common10.nbt,10,CHEST:4,../../../../Chests/Loot/Common10.nbt,11,CHEST:4,../../../../Chests/Loot/Common12.nbt,10,CHEST:4,../../../../Chests/Loot/Common13.nbt,10,CHEST:4,../../../../Chests/Loot/Common14.nbt,10,CHEST:4,../../../../Chests/Loot/Common15.nbt,10,CHEST:4,../../../../Chests/Lore/ShipSunk_1.nbt,2,CHEST:4,../../../../Chests/Lore/ShipSunk_3.nbt,2,CHEST:4,../../../../Chests/Lore/ShipSunk_4.nbt,2,CHEST:4,../../../../Chests/Lore/ShipSunk_5.nbt,2,CHEST:4,../../../../Chests/Lore/ShipSunk_5.nbt,2,CHEST:4,../../../../Chests/Loot/Rare1.nbt,5,CHEST:4,../../../../Chests/Loot/Rare2.nbt,5,CHEST:4,../../../../Chests/Loot/Rare3.nbt,5,CHEST:4,../../../../Chests/Loot/Rare4.nbt,5,CHEST:4,../../../../Chests/Loot/Rare5.nbt,5,CHEST:4,../../../../Chests/Loot/Rare6.nbt,5,CHEST:4,../../../../Chests/Loot/Rare7.nbt,5,CHEST:4,../../../../Chests/Loot/Rare8.nbt,5,CHEST:4,../../../../Chests/Loot/Rare9.nbt,5,CHEST:4,../../../../Chests/Loot/Rare10.nbt,5,CHEST:4,../../../../Chests/Loot/Rare11.nbt,5,CHEST:4,../../../../Chests/Loot/Rare12.nbt,5,CHEST:4,../../../../Chests/Loot/Rare13.nbt,5,CHEST:4,../../../../Chests/Loot/Rare14.nbt,5,CHEST:4,../../../../Chests/Loot/Rare15.nbt,5,CHEST:4,../../../../Chests/Loot/Epic1.nbt,2,CHEST:4,../../../../Chests/Loot/Epic2.nbt,2,CHEST:4,../../../../Chests/Loot/Epic3.nbt,2,CHEST:4,../../../../Chests/Loot/Epic4.nbt,2,CHEST:4,../../../../Chests/Loot/Epic5.nbt,2,CHEST:4,../../../../Chests/Loot/Epic6.nbt,2,CHEST:4,../../../../Chests/Loot/Epic7.nbt,2,CHEST:4,../../../../Chests/Loot/Epic8.nbt,2,CHEST:4,../../../../Chests/Loot/Epic9.nbt,2,CHEST:4,../../../../Chests/Loot/Epic10.nbt,2,CHEST:4,../../../../Chests/Loot/Epic11.nbt,2,CHEST:4,../../../../Chests/Loot/Epic12.nbt,2,CHEST:4,../../../../Chests/Loot/Epic13.nbt,2,CHEST:4,../../../../Chests/Loot/Epic14.nbt,2,CHEST:4,../../../../Chests/Loot/Epic15.nbt,5,CHEST:4,../../../../Chests/Loot/Rare1.nbt,5,CHEST:4,../../../../Chests/Loot/Rare2.nbt,5,CHEST:4,../../../../Chests/Loot/Rare3.nbt,5,CHEST:4,../../../../Chests/Loot/Rare4.nbt,5,CHEST:4,../../../../Chests/Loot/Rare5.nbt,10,CHEST:4,../../../../Chests/Loot/Rare6.nbt,10,CHEST:4,../../../../Chests/Loot/Rare7.nbt,10,CHEST:4,../../../../Chests/Loot/Rare8.nbt,10,CHEST:4,../../../../Chests/Loot/Rare9.nbt,10,CHEST:4,../../../../Chests/Loot/Rare10.nbt,15,CHEST:4,../../../../Chests/Loot/Rare11.nbt,15,CHEST:4,../../../../Chests/Loot/Rare12.nbt,15,CHEST:4,../../../../Chests/Loot/Rare13.nbt,15,CHEST:4,../../../../Chests/Loot/Rare14.nbt,15,CHEST:4,../../../../Chests/Loot/Rare15.nbt,15,CHEST:4,../../../../Chests/Loot/Epic15.nbt,100)
Block(2,11,-1,AIR:0)
Block(2,11,0,AIR:0)
Block(2,11,1,AIR:0)
Block(2,11,2,AIR:0)
Block(2,11,3,WOOD:1)
Block(2,11,4,WOOD:1)
Block(2,11,5,WOOD:1)
Block(2,11,6,WOOD:1)
Block(2,11,7,WOOD:1)
Block(2,11,8,WOOD:1)
Block(2,12,-7,STATIONARY_WATER:0)
Block(2,12,-6,STATIONARY_WATER:0)
Block(2,12,-5,STATIONARY_WATER:0)
Block(2,12,-4,WOOD:1)
Block(2,12,-3,AIR:0)
Block(2,12,-2,AIR:0)
Block(2,12,-1,WOOD:1)
Block(2,12,0,WOOD:1)
Block(2,12,1,WOOD:1)
Block(2,12,2,WOOD:1)
Block(2,12,3,WOOD:1)
Block(2,12,4,WOOD:1)
Block(2,12,5,WOOD:1)
Block(2,13,-7,WOOD:1)
Block(2,13,-6,WOOD:1)
Block(2,13,-5,WOOD:1)
Block(2,13,-4,WOOD:1)
Block(2,13,-3,WOOD:1)
Block(2,13,-2,WOOD:1)
Block(2,13,-1,WOOD:1)
Block(2,13,0,WOOD:1)
Block(3,6,-1,WOOD:5)
Block(3,6,0,WOOD:5)
Block(3,6,1,WOOD:5)
Block(3,6,2,WOOD:5)
Block(3,7,-3,WOOD_STEP:13)
Block(3,7,-2,DARK_OAK_STAIRS:6)
Block(3,7,-1,WOOD:5)
Block(3,7,0,WOOD:5)
Block(3,7,1,WOOD:5)
Block(3,7,2,WOOD:5)
Block(3,7,3,WOOD:5)
Block(3,7,7,WOOD_STEP:13)
Block(3,7,8,WOOD_STEP:13)
Block(3,8,-4,WOOD:0)
Block(3,8,-3,WOOD:0)
Block(3,8,-2,STATIONARY_WATER:0)
Block(3,8,-1,WOOD:0)
Block(3,8,0,WOOD:0)
Block(3,8,1,STATIONARY_WATER:0)
Block(3,8,2,WOOD:0)
Block(3,8,3,WOOD:0)
Block(3,8,4,WOOD_STEP:0)
Block(3,8,6,TRAP_DOOR:4)
Block(3,8,7,WOOD:0)
Block(3,8,8,STAINED_GLASS_PANE:15)
Block(3,9,-6,STATIONARY_WATER:0)
Block(3,9,-4,WOOD:5)
Block(3,9,-3,WOOD:5)
Block(3,9,-2,STATIONARY_WATER:0)
Block(3,9,-1,WOOD:5)
Block(3,9,0,WOOD:5)
Block(3,9,1,STATIONARY_WATER:0)
Block(3,9,2,WOOD:5)
Block(3,9,3,WOOD:5)
Block(3,9,4,STATIONARY_WATER:0)
Block(3,9,7,DARK_OAK_STAIRS:2)
Block(3,9,8,DARK_OAK_STAIRS:1)
Block(3,10,-5,WOOD:5)
Block(3,10,-4,WOOD:5)
Block(3,10,-3,WOOD:5)
Block(3,10,-2,WOOD:5)
Block(3,10,-1,WOOD:5)
Block(3,10,0,WOOD:5)
Block(3,10,1,WOOD:5)
Block(3,10,2,WOOD:5)
Block(3,11,-5,WOOD:1)
Block(3,11,-4,WOOD:1)
Block(3,11,-3,WOOD:1)
Block(3,11,-2,WOOD:1)
Block(3,11,-1,WOOD:1)
Block(3,11,0,WOOD:1)
Block(3,11,1,WOOD:1)
Block(3,11,2,WOOD:1)
Block(3,12,-7,WOOD:1)
Block(3,12,-6,WOOD:1)
Block(3,12,-5,WOOD:1)
Block(3,12,-4,WOOD:1)
Block(3,12,-3,WOOD:1)
Block(3,12,-2,WOOD:1)
Block(4,7,-1,WOOD_STEP:5)
Block(4,7,0,WOOD_STEP:5)
Block(4,7,1,WOOD_STEP:5)
Block(4,7,2,WOOD_STEP:5)
Block(4,8,-2,WOOD_STEP:0)
Block(4,8,1,WOOD_STEP:0)
Block(4,8,7,TRAP_DOOR:7)
Block(-2,8,8,STATIONARY_WATER:0)
Branch(0,0,16,true,agil_degraded_updownC0R3,NORTH,100.0,0)
Entity(-2,8,8,minecraft:guardian,1)
