Author: Bo3 BulkEdit
Description: Converted Schematic - Modified by Bo3BulkEdit - Bo3 Created by NLBlackEagle for Dregora
SettingsMode: WriteDisable
Frequency: 1
SpawnHeight: highestSolidBlock
UseCenterForHighestBlock: false
MinHeight: 0
MaxHeight: 255
InheritBO3: 
InheritBO3Rotation: NORTH
OverrideChildSettings: true
OverrideParentHeight: true
CanOverride: false
BranchFrequency: 0
BranchFrequencyGroup: 
MustBeBelowOther: false
MustBeInside: 
CannotBeInside: 
ReplacesBO3: 
MustBeInsideWorldBorders: false
CanSpawnOnWater: true
SpawnOnWaterOnly: false
SpawnUnderWater: true
SpawnAtWaterLevel: false
HeightOffset: 0
RemoveAir: true
ReplaceAbove: 
ReplaceBelow: GRAVEL
ReplaceWithBiomeBlocks: true
ReplaceWithSurfaceBlock: GRASS
ReplaceWithGroundBlock: DIRT
ReplaceWithStoneBlock: STONE
SmoothRadius: 10
SmoothHeightOffset: 0
SmoothStartTop: false
SmoothStartWood: false
SmoothingSurfaceBlock: GRAVEL
SmoothingGroundBlock: GRAVEL
BO3Group: 
IsSpawnPoint: false
DoReplaceBlocks: true
Block(-2,0,-3,GRAVEL:0)
Block(-1,0,-3,GRAVEL:0)
Block(0,0,-3,GRAVEL:0)
Block(-3,0,-2,GRAVEL:0)
Block(-2,0,-2,GRAVEL:0)
Block(-1,0,-2,GRAVEL:0)
Block(0,0,-2,GRAVEL:0)
Block(1,0,-2,GRAVEL:0)
Block(-3,0,-1,GRAVEL:0)
Block(-2,0,-1,GRAVEL:0)
Block(-1,0,-1,MOSSY_COBBLESTONE:0)
Block(0,0,-1,MOSSY_COBBLESTONE:0)
Block(1,0,-1,GRAVEL:0)
Block(2,0,-1,GRAVEL:0)
Block(-3,0,0,GRAVEL:0)
RandomBlock(-2,0,0,CHEST:3,../../../Chests/Loot/oceanruin_small.nbt,50,CHEST:3,../../../Chests/Traveler/Travelers_Castle.nbt,1,CHEST:3,../../../Chests/Traveler/Travelers_Church.nbt,1,CHEST:3,../../../Chests/Traveler/Travelers_Daeroc.nbt,1,CHEST:3,../../../Chests/Traveler/Travelers_Farmsteads.nbt,1,CHEST:3,../../../Chests/Traveler/Travelers_GreenDungeon.nbt,1,CHEST:3,../../../Chests/Traveler/Travelers_IceShips.nbt,1,CHEST:3,../../../Chests/Traveler/Travelers_IceTemple.nbt,1,CHEST:3,../../../Chests/Traveler/Travelers_LegacySpawn.nbt,1,CHEST:3,../../../Chests/Traveler/Travelers_Mineshafts.nbt,1,CHEST:3,../../../Chests/Traveler/Travelers_Mountains.nbt,1,CHEST:3,../../../Chests/Traveler/Travelers_Origin.nbt,1,CHEST:3,../../../Chests/Traveler/Travelers_Pirate.nbt,1,CHEST:3,../../../Chests/Traveler/Travelers_Quarry.nbt,1,CHEST:3,../../../Chests/Traveler/Travelers_Spook.nbt,1,CHEST:3,../../../Chests/Traveler/Travelers_Tribal.nbt,1)
Block(-1,0,0,MOSSY_COBBLESTONE:0)
Block(0,0,0,MOSSY_COBBLESTONE:0)
Block(1,0,0,GRAVEL:0)
Block(2,0,0,GRAVEL:0)
Block(-3,0,1,GRAVEL:0)
Block(-2,0,1,MOSSY_COBBLESTONE:0)
Block(-1,0,1,GRAVEL:0)
Block(0,0,1,MOSSY_COBBLESTONE:0)
Block(1,0,1,GRAVEL:0)
Block(2,0,1,GRAVEL:0)
Block(-3,0,2,GRAVEL:0)
Block(-2,0,2,GRAVEL:0)
Block(-1,0,2,GRAVEL:0)
Block(0,0,2,GRAVEL:0)
RandomBlock(1,0,2,SMOOTH_BRICK:1,10,SMOOTH_BRICK:2,10,COBBLESTONE,10,MOSSY_COBBLESTONE,10,SMOOTH_BRICK:0,100)
Block(2,0,2,GRAVEL:0)
Block(-1,0,3,GRAVEL:0)
Block(0,0,3,GRAVEL:0)
Block(1,0,3,GRAVEL:0)
RandomBlock(-2,1,-2,SMOOTH_BRICK:1,10,SMOOTH_BRICK:2,10,COBBLESTONE,10,MOSSY_COBBLESTONE,10,SMOOTH_BRICK:0,100)
RandomBlock(0,1,-2,SMOOTH_BRICK:1,10,SMOOTH_BRICK:2,10,COBBLESTONE,10,MOSSY_COBBLESTONE,10,SMOOTH_BRICK:0,100)
RandomBlock(-3,1,-1,SMOOTH_BRICK:1,10,SMOOTH_BRICK:2,10,COBBLESTONE,10,MOSSY_COBBLESTONE,10,SMOOTH_BRICK:0,100)
Block(-2,1,-1,GRAVEL:0)
Block(0,1,-1,GRAVEL:0)
RandomBlock(1,1,-1,SMOOTH_BRICK:1,10,SMOOTH_BRICK:2,10,COBBLESTONE,10,MOSSY_COBBLESTONE,10,SMOOTH_BRICK:0,100)
RandomBlock(-3,1,0,SMOOTH_BRICK:1,10,SMOOTH_BRICK:2,10,COBBLESTONE,10,MOSSY_COBBLESTONE,10,SMOOTH_BRICK:0,100)
Block(-2,1,0,GRAVEL:0)
RandomBlock(1,1,0,SMOOTH_BRICK:1,10,SMOOTH_BRICK:2,10,COBBLESTONE,10,MOSSY_COBBLESTONE,10,SMOOTH_BRICK:0,100)
RandomBlock(-3,1,1,SMOOTH_BRICK:1,10,SMOOTH_BRICK:2,10,COBBLESTONE,10,MOSSY_COBBLESTONE,10,SMOOTH_BRICK:0,100)
Block(-2,1,1,GRAVEL:0)
Block(-1,1,1,GRAVEL:0)
Block(0,1,1,GRAVEL:0)
RandomBlock(1,1,1,SMOOTH_BRICK:1,10,SMOOTH_BRICK:2,10,COBBLESTONE,10,MOSSY_COBBLESTONE,10,SMOOTH_BRICK:0,100)
RandomBlock(-2,1,2,SMOOTH_BRICK:1,10,SMOOTH_BRICK:2,10,COBBLESTONE,10,MOSSY_COBBLESTONE,10,SMOOTH_BRICK:0,100)
RandomBlock(-1,1,2,SMOOTH_BRICK:1,10,SMOOTH_BRICK:2,10,COBBLESTONE,10,MOSSY_COBBLESTONE,10,SMOOTH_BRICK:0,100)
RandomBlock(0,1,2,SMOOTH_BRICK:1,10,SMOOTH_BRICK:2,10,COBBLESTONE,10,MOSSY_COBBLESTONE,10,SMOOTH_BRICK:0,100)
RandomBlock(-2,2,-2,SMOOTH_BRICK:1,10,SMOOTH_BRICK:2,10,COBBLESTONE,10,MOSSY_COBBLESTONE,10,SMOOTH_BRICK:0,100)
RandomBlock(0,2,-2,SMOOTH_BRICK:1,10,SMOOTH_BRICK:2,10,COBBLESTONE,10,MOSSY_COBBLESTONE,10,SMOOTH_BRICK:0,100)
RandomBlock(-3,2,-1,SMOOTH_BRICK:1,10,SMOOTH_BRICK:2,10,COBBLESTONE,10,MOSSY_COBBLESTONE,10,SMOOTH_BRICK:0,100)
Block(-2,2,-1,GRAVEL:0)
RandomBlock(1,2,-1,SMOOTH_BRICK:1,10,SMOOTH_BRICK:2,10,COBBLESTONE,10,MOSSY_COBBLESTONE,10,SMOOTH_BRICK:0,100)
RandomBlock(-3,2,1,SMOOTH_BRICK:1,10,SMOOTH_BRICK:2,10,COBBLESTONE,10,MOSSY_COBBLESTONE,10,SMOOTH_BRICK:0,100)
Block(0,2,1,GRAVEL:0)
RandomBlock(1,2,1,SMOOTH_BRICK:1,10,SMOOTH_BRICK:2,10,COBBLESTONE,10,MOSSY_COBBLESTONE,10,SMOOTH_BRICK:0,100)
RandomBlock(-2,2,2,SMOOTH_BRICK:1,10,SMOOTH_BRICK:2,10,COBBLESTONE,10,MOSSY_COBBLESTONE,10,SMOOTH_BRICK:0,100)
RandomBlock(0,2,2,SMOOTH_BRICK:1,10,SMOOTH_BRICK:2,10,COBBLESTONE,10,MOSSY_COBBLESTONE,10,SMOOTH_BRICK:0,100)
RandomBlock(-2,3,-2,SMOOTH_BRICK:1,10,SMOOTH_BRICK:2,10,COBBLESTONE,10,MOSSY_COBBLESTONE,10,SMOOTH_BRICK:0,100)
RandomBlock(-1,3,-2,SMOOTH_BRICK:1,10,SMOOTH_BRICK:2,10,COBBLESTONE,10,MOSSY_COBBLESTONE,10,SMOOTH_BRICK:0,100)
RandomBlock(0,3,-2,SMOOTH_BRICK:1,10,SMOOTH_BRICK:2,10,COBBLESTONE,10,MOSSY_COBBLESTONE,10,SMOOTH_BRICK:0,100)
RandomBlock(-3,3,-1,SMOOTH_BRICK:1,10,SMOOTH_BRICK:2,10,COBBLESTONE,10,MOSSY_COBBLESTONE,10,SMOOTH_BRICK:0,100)
RandomBlock(1,3,-1,SMOOTH_BRICK:1,10,SMOOTH_BRICK:2,10,COBBLESTONE,10,MOSSY_COBBLESTONE,10,SMOOTH_BRICK:0,100)
RandomBlock(-3,3,0,SMOOTH_BRICK:1,10,SMOOTH_BRICK:2,10,COBBLESTONE,10,MOSSY_COBBLESTONE,10,SMOOTH_BRICK:0,100)
RandomBlock(1,3,0,SMOOTH_BRICK:1,10,SMOOTH_BRICK:2,10,COBBLESTONE,10,MOSSY_COBBLESTONE,10,SMOOTH_BRICK:0,100)
RandomBlock(-3,3,1,SMOOTH_BRICK:1,10,SMOOTH_BRICK:2,10,COBBLESTONE,10,MOSSY_COBBLESTONE,10,SMOOTH_BRICK:0,100)
RandomBlock(1,3,1,SMOOTH_BRICK:1,10,SMOOTH_BRICK:2,10,COBBLESTONE,10,MOSSY_COBBLESTONE,10,SMOOTH_BRICK:0,100)
RandomBlock(-2,3,2,SMOOTH_BRICK:1,10,SMOOTH_BRICK:2,10,COBBLESTONE,10,MOSSY_COBBLESTONE,10,SMOOTH_BRICK:0,100)
RandomBlock(-1,3,2,SMOOTH_BRICK:1,10,SMOOTH_BRICK:2,10,COBBLESTONE,10,MOSSY_COBBLESTONE,10,SMOOTH_BRICK:0,100)
RandomBlock(0,3,2,SMOOTH_BRICK:1,10,SMOOTH_BRICK:2,10,COBBLESTONE,10,MOSSY_COBBLESTONE,10,SMOOTH_BRICK:0,100)
RandomBlock(-2,4,-1,SMOOTH_BRICK:1,10,SMOOTH_BRICK:2,10,COBBLESTONE,10,MOSSY_COBBLESTONE,10,SMOOTH_BRICK:0,100)
RandomBlock(-1,4,-1,SMOOTH_BRICK:1,10,SMOOTH_BRICK:2,10,COBBLESTONE,10,MOSSY_COBBLESTONE,10,SMOOTH_BRICK:0,100)
RandomBlock(0,4,-1,SMOOTH_BRICK:1,10,SMOOTH_BRICK:2,10,COBBLESTONE,10,MOSSY_COBBLESTONE,10,SMOOTH_BRICK:0,100)
RandomBlock(-2,4,0,SMOOTH_BRICK:1,10,SMOOTH_BRICK:2,10,COBBLESTONE,10,MOSSY_COBBLESTONE,10,SMOOTH_BRICK:0,100)
RandomBlock(-1,4,0,SMOOTH_BRICK:1,10,SMOOTH_BRICK:2,10,COBBLESTONE,10,MOSSY_COBBLESTONE,10,SMOOTH_BRICK:0,100)
RandomBlock(0,4,0,SMOOTH_BRICK:1,10,SMOOTH_BRICK:2,10,COBBLESTONE,10,MOSSY_COBBLESTONE,10,SMOOTH_BRICK:0,100)
RandomBlock(-2,4,1,SMOOTH_BRICK:1,10,SMOOTH_BRICK:2,10,COBBLESTONE,10,MOSSY_COBBLESTONE,10,SMOOTH_BRICK:0,100)
RandomBlock(-1,4,1,SMOOTH_BRICK:1,10,SMOOTH_BRICK:2,10,COBBLESTONE,10,MOSSY_COBBLESTONE,10,SMOOTH_BRICK:0,100)
RandomBlock(0,4,1,SMOOTH_BRICK:1,10,SMOOTH_BRICK:2,10,COBBLESTONE,10,MOSSY_COBBLESTONE,10,SMOOTH_BRICK:0,100)
RandomBlock(-1,5,-1,SMOOTH_BRICK:1,10,SMOOTH_BRICK:2,10,COBBLESTONE,10,MOSSY_COBBLESTONE,10,SMOOTH_BRICK:0,100)
RandomBlock(-2,5,0,SMOOTH_BRICK:1,10,SMOOTH_BRICK:2,10,COBBLESTONE,10,MOSSY_COBBLESTONE,10,SMOOTH_BRICK:0,100)
RandomBlock(-1,5,0,SMOOTH_BRICK:1,10,SMOOTH_BRICK:2,10,COBBLESTONE,10,MOSSY_COBBLESTONE,10,SMOOTH_BRICK:0,100)
RandomBlock(0,5,0,SMOOTH_BRICK:1,10,SMOOTH_BRICK:2,10,COBBLESTONE,10,MOSSY_COBBLESTONE,10,SMOOTH_BRICK:0,100)
RandomBlock(-1,5,1,SMOOTH_BRICK:1,10,SMOOTH_BRICK:2,10,COBBLESTONE,10,MOSSY_COBBLESTONE,10,SMOOTH_BRICK:0,100)
