Author: Bo3 BulkEdit
Description: Converted Schematic - Modified by Bo3BulkEdit - Bo3 Created by NLBlackEagle for Dregora
SettingsMode: WriteDisable
Frequency: 1
SpawnHeight: highestSolidBlock
UseCenterForHighestBlock: true
MinHeight: 0
MaxHeight: 255
InheritBO3: 
InheritBO3Rotation: NORTH
OverrideChildSettings: true
OverrideParentHeight: true
CanOverride: false
BranchFrequency: 0
BranchFrequencyGroup: 
MustBeBelowOther: false
MustBeInside: 
CannotBeInside: 
ReplacesBO3: 
MustBeInsideWorldBorders: false
CanSpawnOnWater: true
SpawnOnWaterOnly: false
SpawnUnderWater: false
SpawnAtWaterLevel: false
HeightOffset: 0
RemoveAir: true
ReplaceAbove: 
ReplaceBelow: 
ReplaceWithBiomeBlocks: true
ReplaceWithSurfaceBlock: GRASS
ReplaceWithGroundBlock: DIRT
ReplaceWithStoneBlock: STONE
SmoothRadius: 0
SmoothHeightOffset: 0
SmoothStartTop: false
SmoothStartWood: false
SmoothingSurfaceBlock: 
SmoothingGroundBlock: 
BO3Group: 
IsSpawnPoint: false
DoReplaceBlocks: true
Block(-6,0,-8,SAND:0)
Block(-5,0,-8,SAND:0)
Block(3,0,-8,SAND:0)
Block(4,0,-8,SAND:0)
Block(-7,0,-7,SAND:0)
Block(-6,0,-7,SAND:0)
Block(-5,0,-7,SAND:0)
Block(-4,0,-7,SAND:0)
Block(-3,0,-7,SAND:0)
Block(1,0,-7,SAND:0)
Block(2,0,-7,SAND:0)
Block(3,0,-7,SAND:0)
Block(4,0,-7,SAND:0)
Block(5,0,-7,SAND:0)
Block(6,0,-7,SAND:0)
Block(-7,0,-6,SAND:0)
Block(-6,0,-6,SAND:0)
Block(-5,0,-6,SAND:0)
Block(-4,0,-6,SAND:0)
Block(-3,0,-6,SAND:0)
Block(-2,0,-6,SAND:0)
Block(-1,0,-6,SAND:0)
Block(0,0,-6,SAND:0)
Block(1,0,-6,SAND:0)
Block(2,0,-6,SAND:0)
Block(3,0,-6,SAND:0)
Block(4,0,-6,SAND:0)
Block(5,0,-6,SAND:0)
Block(6,0,-6,SAND:0)
Block(-6,0,-5,SAND:0)
Block(-5,0,-5,SAND:0)
Block(-4,0,-5,SAND:0)
Block(-3,0,-5,SAND:0)
Block(-2,0,-5,SAND:0)
Block(-1,0,-5,SAND:0)
Block(0,0,-5,SAND:0)
Block(1,0,-5,SAND:0)
Block(2,0,-5,SAND:0)
Block(3,0,-5,SAND:0)
Block(4,0,-5,SAND:0)
Block(5,0,-5,SAND:0)
Block(6,0,-5,SAND:0)
Block(7,0,-5,SAND:0)
Block(-6,0,-4,SAND:0)
Block(-5,0,-4,SAND:0)
Block(-4,0,-4,SAND:0)
Block(-3,0,-4,SAND:0)
Block(-2,0,-4,SAND:0)
Block(-1,0,-4,SAND:0)
Block(0,0,-4,SAND:0)
Block(1,0,-4,SAND:0)
Block(2,0,-4,RED_SANDSTONE:0)
Block(3,0,-4,SAND:0)
Block(4,0,-4,SAND:0)
Block(5,0,-4,SAND:0)
Block(6,0,-4,SAND:0)
Block(-7,0,-3,SAND:0)
Block(-6,0,-3,SAND:0)
Block(-5,0,-3,SAND:0)
Block(-4,0,-3,SAND:0)
Block(-3,0,-3,SAND:0)
Block(-2,0,-3,SAND:0)
Block(-1,0,-3,SAND:0)
Block(0,0,-3,SAND:0)
Block(1,0,-3,SAND:0)
Block(2,0,-3,SAND:0)
Block(3,0,-3,SAND:0)
Block(4,0,-3,SAND:0)
Block(5,0,-3,SAND:0)
Block(6,0,-3,SAND:0)
Block(7,0,-3,SAND:0)
Block(-8,0,-2,SAND:0)
Block(-7,0,-2,SAND:0)
Block(-6,0,-2,SAND:0)
Block(-5,0,-2,SAND:0)
Block(-4,0,-2,SAND:0)
Block(-3,0,-2,SAND:0)
Block(-2,0,-2,SAND:0)
Block(-1,0,-2,SAND:0)
Block(0,0,-2,SAND:0)
Block(1,0,-2,SAND:0)
Block(2,0,-2,SAND:0)
Block(3,0,-2,SAND:0)
Block(4,0,-2,SAND:0)
Block(5,0,-2,SAND:0)
Block(6,0,-2,SAND:0)
Block(-7,0,-1,SAND:0)
Block(-6,0,-1,SAND:0)
Block(-5,0,-1,SAND:0)
Block(-4,0,-1,SAND:0)
Block(-3,0,-1,SAND:0)
Block(-2,0,-1,SAND:0)
Block(-1,0,-1,SAND:0)
Block(0,0,-1,SAND:0)
Block(1,0,-1,SAND:0)
Block(2,0,-1,SAND:0)
Block(3,0,-1,SAND:0)
Block(4,0,-1,SAND:0)
Block(5,0,-1,SAND:0)
Block(6,0,-1,SAND:0)
Block(-7,0,0,SAND:0)
Block(-6,0,0,SAND:0)
Block(-5,0,0,SAND:0)
Block(-4,0,0,SAND:0)
Block(-3,0,0,SAND:0)
Block(-2,0,0,SAND:0)
Block(-1,0,0,SAND:0)
Block(0,0,0,SAND:0)
Block(1,0,0,SAND:0)
Block(2,0,0,SAND:0)
RandomBlock(3,0,0,CHEST:3,../../../Chests/Loot/oceanruin_big.nbt,50,CHEST:3,../../../Chests/Traveler/Travelers_Castle.nbt,1,CHEST:3,../../../Chests/Traveler/Travelers_Church.nbt,1,CHEST:3,../../../Chests/Traveler/Travelers_Daeroc.nbt,1,CHEST:3,../../../Chests/Traveler/Travelers_Farmsteads.nbt,1,CHEST:3,../../../Chests/Traveler/Travelers_GreenDungeon.nbt,1,CHEST:3,../../../Chests/Traveler/Travelers_IceShips.nbt,1,CHEST:3,../../../Chests/Traveler/Travelers_IceTemple.nbt,1,CHEST:3,../../../Chests/Traveler/Travelers_LegacySpawn.nbt,1,CHEST:3,../../../Chests/Traveler/Travelers_Mineshafts.nbt,1,CHEST:3,../../../Chests/Traveler/Travelers_Mountains.nbt,1,CHEST:3,../../../Chests/Traveler/Travelers_Origin.nbt,1,CHEST:3,../../../Chests/Traveler/Travelers_Pirate.nbt,1,CHEST:3,../../../Chests/Traveler/Travelers_Quarry.nbt,1,CHEST:3,../../../Chests/Traveler/Travelers_Spook.nbt,1,CHEST:3,../../../Chests/Traveler/Travelers_Tribal.nbt,1)
Block(4,0,0,SAND:0)
Block(5,0,0,SAND:0)
Block(6,0,0,SAND:0)
Block(7,0,0,SAND:0)
Block(-7,0,1,SAND:0)
Block(-6,0,1,SAND:0)
Block(-5,0,1,SAND:0)
Block(-4,0,1,SAND:0)
Block(-3,0,1,SAND:0)
Block(-2,0,1,SAND:0)
Block(-1,0,1,SAND:0)
Block(0,0,1,SAND:0)
Block(1,0,1,SAND:0)
Block(2,0,1,SAND:0)
Block(3,0,1,SAND:0)
Block(4,0,1,SAND:0)
Block(5,0,1,SAND:0)
Block(6,0,1,SAND:0)
Block(-7,0,2,SAND:0)
Block(-6,0,2,SAND:0)
Block(-5,0,2,SAND:0)
Block(-4,0,2,SAND:0)
Block(-3,0,2,SAND:0)
Block(-2,0,2,SAND:0)
Block(-1,0,2,SAND:0)
Block(0,0,2,SAND:0)
Block(1,0,2,SAND:0)
Block(2,0,2,SAND:0)
Block(3,0,2,SAND:0)
Block(4,0,2,SAND:0)
Block(5,0,2,SAND:0)
Block(6,0,2,SAND:0)
Block(-7,0,3,SAND:0)
Block(-6,0,3,SAND:0)
Block(-5,0,3,SAND:0)
Block(-4,0,3,SAND:0)
Block(-3,0,3,RED_SANDSTONE:0)
Block(-2,0,3,SAND:0)
Block(-1,0,3,SAND:0)
Block(0,0,3,SAND:0)
Block(1,0,3,SAND:0)
Block(2,0,3,SAND:0)
Block(3,0,3,SAND:0)
Block(4,0,3,SAND:0)
Block(5,0,3,SAND:0)
Block(6,0,3,SAND:0)
Block(7,0,3,SAND:0)
Block(-8,0,4,SAND:0)
Block(-7,0,4,SAND:0)
Block(-6,0,4,SAND:0)
Block(-5,0,4,SAND:0)
Block(-4,0,4,SAND:0)
Block(-3,0,4,SAND:0)
Block(-2,0,4,SAND:0)
Block(-1,0,4,RED_SANDSTONE:0)
Block(0,0,4,SAND:0)
Block(1,0,4,SAND:0)
Block(2,0,4,SAND:0)
Block(3,0,4,SAND:0)
Block(4,0,4,SAND:0)
Block(5,0,4,SAND:0)
Block(6,0,4,SAND:0)
Block(7,0,4,SAND:0)
Block(-8,0,5,SAND:0)
Block(-7,0,5,SAND:0)
Block(-6,0,5,SAND:0)
Block(-5,0,5,SAND:0)
Block(-4,0,5,SAND:0)
Block(-3,0,5,SAND:0)
Block(-2,0,5,SAND:0)
Block(-1,0,5,SAND:0)
Block(0,0,5,SAND:0)
Block(1,0,5,SAND:0)
Block(2,0,5,SAND:0)
Block(3,0,5,SAND:0)
Block(4,0,5,SAND:0)
Block(5,0,5,SAND:0)
Block(6,0,5,SAND:0)
Block(-7,0,6,SAND:0)
Block(-6,0,6,SAND:0)
Block(-5,0,6,SAND:0)
Block(-4,0,6,SAND:0)
Block(-3,0,6,SAND:0)
Block(-1,0,6,SAND:0)
Block(0,0,6,SAND:0)
Block(1,0,6,SAND:0)
Block(2,0,6,SAND:0)
Block(3,0,6,SAND:0)
Block(4,0,6,SAND:0)
Block(5,0,6,SAND:0)
Block(-6,0,7,SAND:0)
Block(-5,0,7,SAND:0)
Block(-3,0,7,SAND:0)
Block(1,0,7,SAND:0)
Block(4,0,7,SAND:0)
Block(-7,1,-7,RED_SANDSTONE:0)
Block(-6,1,-6,SANDSTONE:1)
Block(-3,1,-6,SANDSTONE:1)
Block(2,1,-6,SANDSTONE:1)
Block(5,1,-6,SANDSTONE:1)
Block(-5,1,-5,SAND:0)
Block(1,1,-5,SAND:0)
Block(-6,1,-4,SAND:0)
Block(-3,1,-4,SAND:0)
Block(0,1,-4,SAND:0)
RandomBlock(-5,1,-3,CHEST:3,../../../Chests/Loot/oceanruin_big.nbt,50,CHEST:3,../../../Chests/Traveler/Travelers_Castle.nbt,1,CHEST:3,../../../Chests/Traveler/Travelers_Church.nbt,1,CHEST:3,../../../Chests/Traveler/Travelers_Daeroc.nbt,1,CHEST:3,../../../Chests/Traveler/Travelers_Farmsteads.nbt,1,CHEST:3,../../../Chests/Traveler/Travelers_GreenDungeon.nbt,1,CHEST:3,../../../Chests/Traveler/Travelers_IceShips.nbt,1,CHEST:3,../../../Chests/Traveler/Travelers_IceTemple.nbt,1,CHEST:3,../../../Chests/Traveler/Travelers_LegacySpawn.nbt,1,CHEST:3,../../../Chests/Traveler/Travelers_Mineshafts.nbt,1,CHEST:3,../../../Chests/Traveler/Travelers_Mountains.nbt,1,CHEST:3,../../../Chests/Traveler/Travelers_Origin.nbt,1,CHEST:3,../../../Chests/Traveler/Travelers_Pirate.nbt,1,CHEST:3,../../../Chests/Traveler/Travelers_Quarry.nbt,1,CHEST:3,../../../Chests/Traveler/Travelers_Spook.nbt,1,CHEST:3,../../../Chests/Traveler/Travelers_Tribal.nbt,1)
Block(-4,1,-3,SAND:0)
Block(-3,1,-3,SAND:0)
Block(0,1,-3,SAND:0)
Block(6,1,-3,RED_SANDSTONE:0)
Block(-6,1,-2,SANDSTONE:1)
Block(-5,1,-2,SANDSTONE:1)
Block(-4,1,-2,SANDSTONE:1)
Block(-3,1,-2,SANDSTONE:1)
Block(2,1,-2,SANDSTONE:1)
Block(3,1,-2,SANDSTONE:1)
Block(4,1,-2,SANDSTONE:1)
Block(5,1,-2,SANDSTONE:1)
Block(-5,1,-1,SANDSTONE:1)
Block(-3,1,-1,SANDSTONE:1)
Block(-2,1,-1,SAND:0)
Block(2,1,-1,SANDSTONE:1)
Block(3,1,-1,SANDSTONE:1)
Block(4,1,-1,SANDSTONE:1)
Block(-5,1,0,SANDSTONE:1)
Block(-3,1,0,SANDSTONE:1)
Block(-1,1,0,SAND:0)
Block(2,1,0,SANDSTONE:1)
Block(3,1,0,SANDSTONE:1)
Block(4,1,0,SANDSTONE:1)
Block(-6,1,1,SANDSTONE:1)
Block(-5,1,1,SANDSTONE:1)
Block(-4,1,1,SANDSTONE:1)
Block(-3,1,1,SANDSTONE:1)
Block(2,1,1,SANDSTONE:1)
Block(3,1,1,SANDSTONE:1)
Block(4,1,1,SANDSTONE:1)
Block(5,1,1,SANDSTONE:1)
Block(-6,1,3,SAND:0)
Block(-7,1,4,SAND:0)
Block(-2,1,4,RED_SANDSTONE:0)
Block(-6,1,5,SANDSTONE:1)
Block(-3,1,5,SANDSTONE:1)
Block(-1,1,5,SAND:0)
Block(2,1,5,SANDSTONE:1)
Block(5,1,5,SANDSTONE:1)
Block(-5,1,6,RED_SANDSTONE:0)
Block(-4,1,6,SAND:0)
Block(-1,1,6,SAND:0)
Block(0,1,6,SAND:0)
Block(3,1,6,SAND:0)
Block(-6,2,-6,SANDSTONE:1)
Block(-3,2,-6,SANDSTONE:1)
Block(2,2,-6,SANDSTONE:1)
Block(5,2,-6,SANDSTONE:1)
Block(-3,2,-4,SAND:0)
Block(-6,2,-2,SANDSTONE:1)
Block(-5,2,-2,SANDSTONE:1)
RandomBlock(-4,2,-2,CHEST:3,../../../Chests/Loot/oceanruin_big.nbt,50,CHEST:3,../../../Chests/Traveler/Travelers_Castle.nbt,1,CHEST:3,../../../Chests/Traveler/Travelers_Church.nbt,1,CHEST:3,../../../Chests/Traveler/Travelers_Daeroc.nbt,1,CHEST:3,../../../Chests/Traveler/Travelers_Farmsteads.nbt,1,CHEST:3,../../../Chests/Traveler/Travelers_GreenDungeon.nbt,1,CHEST:3,../../../Chests/Traveler/Travelers_IceShips.nbt,1,CHEST:3,../../../Chests/Traveler/Travelers_IceTemple.nbt,1,CHEST:3,../../../Chests/Traveler/Travelers_LegacySpawn.nbt,1,CHEST:3,../../../Chests/Traveler/Travelers_Mineshafts.nbt,1,CHEST:3,../../../Chests/Traveler/Travelers_Mountains.nbt,1,CHEST:3,../../../Chests/Traveler/Travelers_Origin.nbt,1,CHEST:3,../../../Chests/Traveler/Travelers_Pirate.nbt,1,CHEST:3,../../../Chests/Traveler/Travelers_Quarry.nbt,1,CHEST:3,../../../Chests/Traveler/Travelers_Spook.nbt,1,CHEST:3,../../../Chests/Traveler/Travelers_Tribal.nbt,1)
Block(-3,2,-2,SANDSTONE:1)
Block(2,2,-2,SANDSTONE:1)
Block(4,2,-2,SANDSTONE:1)
Block(5,2,-2,SANDSTONE:1)
Block(-4,2,-1,SANDSTONE:1)
Block(3,2,-1,SANDSTONE:1)
Block(-4,2,0,SANDSTONE:1)
Block(3,2,0,SANDSTONE:1)
Block(-6,2,1,SANDSTONE:1)
Block(-5,2,1,SANDSTONE:1)
Block(-3,2,1,SANDSTONE:1)
Block(2,2,1,SANDSTONE:1)
Block(4,2,1,SANDSTONE:1)
Block(5,2,1,SANDSTONE:1)
Block(-6,2,5,SANDSTONE:1)
Block(-3,2,5,SANDSTONE:1)
Block(2,2,5,SANDSTONE:1)
Block(5,2,5,SANDSTONE:1)
Block(-3,3,-6,RED_SANDSTONE:0)
Block(2,3,-6,RED_SANDSTONE:0)
Block(5,3,-6,RED_SANDSTONE:0)
Block(-6,3,-2,RED_SANDSTONE:0)
Block(-5,3,-2,SANDSTONE:1)
Block(-3,3,-2,SANDSTONE:1)
Block(2,3,-2,SANDSTONE:1)
Block(4,3,-2,SANDSTONE:1)
Block(-4,3,-1,SANDSTONE:1)
Block(3,3,-1,SANDSTONE:1)
Block(-4,3,0,SANDSTONE:1)
Block(3,3,0,SANDSTONE:1)
Block(-6,3,1,RED_SANDSTONE:0)
Block(-5,3,1,SANDSTONE:1)
Block(-3,3,1,SANDSTONE:1)
Block(2,3,1,SANDSTONE:1)
Block(4,3,1,SANDSTONE:1)
Block(5,3,1,RED_SANDSTONE:0)
Block(2,3,5,RED_SANDSTONE:0)
Block(5,3,5,RED_SANDSTONE:0)
Block(-5,4,-2,SANDSTONE:1)
Block(-3,4,-2,SANDSTONE:1)
Block(2,4,-2,SANDSTONE:1)
Block(4,4,-2,SANDSTONE:1)
Block(-4,4,-1,SANDSTONE:1)
Block(3,4,-1,SANDSTONE:1)
Block(-4,4,0,SANDSTONE:1)
Block(3,4,0,SANDSTONE:1)
Block(-5,4,1,SANDSTONE:1)
Block(-3,4,1,SANDSTONE:1)
Block(2,4,1,SANDSTONE:1)
Block(4,4,1,SANDSTONE:1)
Block(-5,5,-2,SANDSTONE:1)
Block(-3,5,-2,SANDSTONE:1)
Block(2,5,-2,SANDSTONE:1)
Block(4,5,-2,SANDSTONE:1)
Block(-4,5,-1,SANDSTONE:1)
Block(3,5,-1,SANDSTONE:1)
Block(-4,5,0,SANDSTONE:1)
Block(3,5,0,SANDSTONE:1)
Block(-5,5,1,SANDSTONE:1)
Block(-3,5,1,SANDSTONE:1)
Block(2,5,1,SANDSTONE:1)
Block(4,5,1,SANDSTONE:1)
Block(-5,6,-2,SANDSTONE:1)
Block(-4,6,-2,SANDSTONE:1)
Block(-3,6,-2,SANDSTONE:1)
Block(-2,6,-2,SANDSTONE:1)
Block(1,6,-2,SANDSTONE:1)
Block(2,6,-2,SANDSTONE:1)
Block(3,6,-2,SANDSTONE:1)
Block(4,6,-2,SANDSTONE:1)
Block(-5,6,-1,SANDSTONE:1)
Block(-4,6,-1,SANDSTONE:1)
Block(-3,6,-1,SEA_LANTERN:0)
Block(-2,6,-1,SANDSTONE:1)
Block(1,6,-1,SANDSTONE:1)
Block(2,6,-1,SEA_LANTERN:0)
Block(3,6,-1,SANDSTONE:1)
Block(4,6,-1,SANDSTONE:1)
Block(-5,6,0,SANDSTONE:1)
Block(-4,6,0,SANDSTONE:1)
Block(-3,6,0,SEA_LANTERN:0)
Block(-2,6,0,SANDSTONE:1)
Block(1,6,0,SANDSTONE:1)
Block(2,6,0,SEA_LANTERN:0)
Block(3,6,0,SANDSTONE:1)
Block(4,6,0,SANDSTONE:1)
Block(-5,6,1,SANDSTONE:1)
Block(-4,6,1,SANDSTONE:1)
Block(-3,6,1,SANDSTONE:1)
Block(-2,6,1,SANDSTONE:1)
Block(1,6,1,SANDSTONE:1)
Block(2,6,1,SANDSTONE:1)
Block(3,6,1,SANDSTONE:1)
Block(4,6,1,SANDSTONE:1)
Block(-4,7,-2,SANDSTONE:1)
Block(-3,7,-2,SANDSTONE:1)
Block(-2,7,-2,SANDSTONE:1)
Block(-1,7,-2,SANDSTONE:1)
Block(0,7,-2,SANDSTONE:1)
Block(1,7,-2,SANDSTONE:1)
Block(2,7,-2,SANDSTONE:1)
Block(3,7,-2,SANDSTONE:1)
Block(-5,7,-1,RED_SANDSTONE:0)
Block(-4,7,-1,SANDSTONE:1)
Block(-3,7,-1,SANDSTONE:1)
Block(-2,7,-1,SANDSTONE:1)
Block(-1,7,-1,SANDSTONE:1)
Block(0,7,-1,SANDSTONE:1)
Block(1,7,-1,SANDSTONE:1)
Block(2,7,-1,SANDSTONE:1)
Block(3,7,-1,SANDSTONE:1)
Block(4,7,-1,RED_SANDSTONE:0)
Block(-5,7,0,RED_SANDSTONE:0)
Block(-4,7,0,SANDSTONE:1)
Block(-3,7,0,SANDSTONE:1)
Block(-2,7,0,SANDSTONE:1)
Block(-1,7,0,SANDSTONE:1)
Block(0,7,0,SANDSTONE:1)
Block(1,7,0,SANDSTONE:1)
Block(2,7,0,SANDSTONE:1)
Block(3,7,0,SANDSTONE:1)
Block(4,7,0,RED_SANDSTONE:0)
Block(-4,7,1,SANDSTONE:1)
Block(-3,7,1,SANDSTONE:1)
Block(-2,7,1,SANDSTONE:1)
Block(-1,7,1,SANDSTONE:1)
Block(0,7,1,SANDSTONE:1)
Block(1,7,1,SANDSTONE:1)
Block(2,7,1,SANDSTONE:1)
Block(3,7,1,SANDSTONE:1)
Block(-2,8,-2,SANDSTONE:1)
Block(-1,8,-2,SANDSTONE:1)
Block(0,8,-2,SANDSTONE:1)
Block(1,8,-2,SANDSTONE:1)
Block(-3,8,-1,RED_SANDSTONE:0)
Block(-2,8,-1,SANDSTONE:1)
Block(-1,8,-1,SANDSTONE:1)
Block(0,8,-1,SANDSTONE:1)
Block(1,8,-1,SANDSTONE:1)
Block(2,8,-1,RED_SANDSTONE:0)
Block(-3,8,0,RED_SANDSTONE:0)
Block(-2,8,0,SANDSTONE:1)
Block(-1,8,0,SANDSTONE:1)
Block(0,8,0,SANDSTONE:1)
Block(1,8,0,SANDSTONE:1)
Block(2,8,0,RED_SANDSTONE:0)
Block(-2,8,1,SANDSTONE:1)
Block(-1,8,1,SANDSTONE:1)
Block(0,8,1,SANDSTONE:1)
Block(1,8,1,SANDSTONE:1)
Block(-1,9,-1,RED_SANDSTONE:0)
Block(0,9,-1,RED_SANDSTONE:0)
Block(-1,9,0,RED_SANDSTONE:0)
Block(0,9,0,RED_SANDSTONE:0)
