Author: NLBlackEagle
Description: No description given
SettingsMode: WriteDisable
Frequency: 0
SpawnHeight: highestBlock
UseCenterForHighestBlock: true
MinHeight: 0
MaxHeight: 255
InheritBO3: 
InheritBO3Rotation: NORTH
OverrideChildSettings: true
OverrideParentHeight: false
CanOverride: false
BranchFrequency: 0
BranchFrequencyGroup: 
MustBeBelowOther: false
MustBeInside: 
CannotBeInside: 
ReplacesBO3: 
MustBeInsideWorldBorders: false
CanSpawnOnWater: true
SpawnOnWaterOnly: false
SpawnUnderWater: false
SpawnAtWaterLevel: false
HeightOffset: 0
RemoveAir: true
ReplaceAbove: 
ReplaceBelow: 
ReplaceWithBiomeBlocks: false
ReplaceWithSurfaceBlock: GRASS
ReplaceWithGroundBlock: DIRT
ReplaceWithStoneBlock: STONE
SmoothRadius: 0
SmoothHeightOffset: 0
SmoothStartTop: false
SmoothStartWood: false
SmoothingSurfaceBlock: 
SmoothingGroundBlock: 
BO3Group: 
IsSpawnPoint: false
DoReplaceBlocks: false
Block(-8,10,6,WOOD:5)
Block(-8,10,7,WOOD:5)
Block(-8,10,8,WOOD:5)
Block(-8,11,6,WOOD:5)
Block(-8,11,7,WOOD:5)
Block(-8,11,8,DISPENSER:4)
Block(-8,12,6,WOOD:5)
Block(-8,12,7,WOOD:5)
Block(-8,12,8,WOOD:5)
Block(-8,13,1,WOOD_STEP:13)
Block(-8,13,5,STAINED_CLAY:9)
Block(-8,13,6,STAINED_CLAY:9)
Block(-8,13,7,STAINED_CLAY:9)
Block(-8,13,8,STAINED_CLAY:9)
Block(-8,14,6,STAINED_CLAY:9)
Block(-8,14,7,DISPENSER:4)
Block(-8,14,8,STAINED_CLAY:9)
Block(-8,15,6,WOOD_STEP:5)
Block(-8,15,8,WOOD_STEP:5)
Block(-7,8,5,LOG_2:1)
Block(-7,8,6,LOG_2:1)
Block(-7,8,7,LOG_2:1)
Block(-7,8,8,LOG_2:1)
Block(-7,9,4,LOG_2:1)
Block(-7,9,5,LOG_2:1)
Block(-7,9,6,LOG_2:1)
Block(-7,9,7,LOG_2:1)
Block(-7,9,8,LOG_2:1)
Block(-7,10,1,WOOD:5)
Block(-7,10,5,WOOD:5)
Block(-7,10,6,WOOD:5)
Block(-7,10,7,WOOD:5)
Block(-7,10,8,WOOD:5)
Block(-7,11,0,WOOD:5)
Block(-7,11,1,WOOD:5)
Block(-7,11,5,STATIONARY_WATER:0)
Block(-7,11,6,STATIONARY_WATER:0)
RandomBlock(-7,11,7,SKULL:1,../../../../Skulls/dungeon_skull_01.nbt,6,AIR,9,SKULL:1,../../../../Skulls/dungeon_skull_02.nbt,12,AIR,15,SKULL:1,../../../../Skulls/dungeon_skull_03.nbt,18,AIR,21,SKULL:1,../../../../Skulls/dungeon_skull_04.nbt,24,AIR,27,SKULL:1,../../../../Skulls/dungeon_skull_05.nbt,30,AIR,33,SKULL:1,../../../../Skulls/dungeon_skull_06.nbt,36,AIR,39,SKULL:1,../../../../Skulls/dungeon_skull_07.nbt,42,AIR,45,SKULL:1,../../../../Skulls/dungeon_skull_08.nbt,48,AIR,51,SKULL:1,../../../../Skulls/dungeon_skull_09.nbt,54,AIR,57,SKULL:1,../../../../Skulls/dungeon_skull_10.nbt,60,AIR,63,SKULL:1,../../../../Skulls/dungeon_skull_11.nbt,66,AIR,69,SKULL:1,../../../../Skulls/dungeon_skull_12.nbt,72,AIR,75,SKULL:1,../../../../Skulls/dungeon_skull_13.nbt,78,AIR,81,SKULL:1,../../../../Skulls/dungeon_skull_14.nbt,84,AIR,87,SKULL:1,../../../../Skulls/dungeon_skull_15.nbt,90,AIR,93,SKULL:1,../../../../Skulls/dungeon_skull_16.nbt,96,AIR,100)
Block(-7,11,8,CONCRETE:15)
Block(-7,12,0,WOOD:5)
Block(-7,12,1,WOOD:5)
Block(-7,12,5,STATIONARY_WATER:0)
Block(-7,12,6,WOOD_STEP:5)
Block(-7,12,7,WOOD_STEP:5)
Block(-7,12,8,STATIONARY_WATER:0)
Block(-7,13,-1,DARK_OAK_STAIRS:4)
Block(-7,13,0,WOOD_STEP:13)
Block(-7,13,1,STAINED_CLAY:9)
Block(-7,13,5,WOOD_STEP:13)
Block(-7,13,6,WOOD_STEP:13)
Block(-7,13,7,WOOD_STEP:13)
Block(-7,13,8,WOOD_STEP:13)
Block(-7,14,1,STAINED_CLAY:9)
Block(-7,14,5,STAINED_CLAY:9)
Block(-7,14,7,CONCRETE:15)
Block(-7,15,5,WOOD_STEP:5)
Block(-6,7,5,LOG_2:1)
Block(-6,7,6,LOG_2:1)
Block(-6,7,7,LOG_2:1)
Block(-6,7,8,LOG_2:1)
Block(-6,8,1,LOG_2:1)
Block(-6,8,2,LOG_2:1)
Block(-6,8,3,LOG_2:1)
Block(-6,8,4,LOG_2:1)
Block(-6,8,5,MELON_BLOCK:0)
Block(-6,8,6,WOOD:5)
Block(-6,8,7,LAPIS_ORE:0)
Block(-6,8,8,LAPIS_ORE:0)
Block(-6,9,-1,LOG_2:1)
Block(-6,9,0,LOG_2:1)
Block(-6,9,1,LOG_2:1)
Block(-6,9,2,LOG_2:1)
Block(-6,9,3,LOG_2:1)
Block(-6,9,4,LOG_2:1)
Block(-6,9,5,PUMPKIN:3)
Block(-6,9,6,WOOD:5)
Block(-6,9,7,LAPIS_ORE:0)
Block(-6,9,8,LAPIS_ORE:0)
Block(-6,10,-2,WOOD:5)
Block(-6,10,-1,WOOD:5)
Block(-6,10,0,WOOD:5)
Block(-6,10,1,WOOD:5)
Block(-6,10,2,WOOD:5)
Block(-6,10,3,WOOD:5)
Block(-6,10,4,WOOD:5)
Block(-6,10,5,WOOD:5)
Block(-6,10,6,WOOD:5)
Block(-6,10,7,WOOD:5)
Block(-6,10,8,WOOD:5)
Block(-6,11,-2,WOOD:5)
Block(-6,11,-1,WOOD:5)
Block(-6,11,0,STAINED_CLAY:9)
Block(-6,11,1,STATIONARY_WATER:0)
Block(-6,11,2,CONCRETE:15)
Block(-6,11,3,STATIONARY_WATER:0)
Block(-6,11,4,STATIONARY_WATER:0)
Block(-6,11,5,STATIONARY_WATER:0)
Block(-6,11,6,STATIONARY_WATER:0)
Block(-6,11,7,STATIONARY_WATER:0)
Block(-6,11,8,DARK_OAK_STAIRS:1)
Block(-6,12,-2,WOOD:5)
Block(-6,12,-1,WOOD:5)
Block(-6,12,0,STAINED_CLAY:9)
Block(-6,12,1,WOOD_STEP:5)
Block(-6,12,2,STATIONARY_WATER:0)
Block(-6,12,3,STATIONARY_WATER:0)
Block(-6,12,4,STATIONARY_WATER:0)
Block(-6,12,5,STATIONARY_WATER:0)
Block(-6,12,6,STATIONARY_WATER:0)
Block(-6,12,7,STATIONARY_WATER:0)
Block(-6,12,8,STATIONARY_WATER:0)
Block(-6,13,-2,STAINED_CLAY:9)
Block(-6,13,-1,STAINED_CLAY:9)
Block(-6,13,0,STAINED_CLAY:9)
Block(-6,13,1,WOOD_STEP:13)
Block(-6,13,2,WOOD_STEP:13)
Block(-6,13,3,WOOD_STEP:13)
Block(-6,13,4,WOOD_STEP:13)
Block(-6,13,5,WOOD_STEP:13)
Block(-6,13,6,WOOD_STEP:13)
Block(-6,13,7,WOOD_STEP:13)
Block(-6,13,8,WOOD_STEP:13)
Block(-6,14,-1,STAINED_CLAY:9)
Block(-6,14,0,STAINED_CLAY:9)
Block(-6,14,7,DISPENSER:1)
Block(-6,15,-1,WOOD_STEP:5)
Block(-6,15,0,WOOD_STEP:5)
Block(-5,7,2,LOG_2:1)
Block(-5,7,3,LOG_2:1)
Block(-5,7,4,LOG_2:1)
Block(-5,7,5,LOG_2:1)
Block(-5,7,6,LOG_2:1)
Block(-5,7,7,LOG_2:1)
Block(-5,7,8,LOG_2:1)
Block(-5,8,-1,LOG_2:1)
Block(-5,8,0,LOG_2:1)
Block(-5,8,1,LOG_2:1)
Block(-5,8,2,STATIONARY_WATER:0)
Block(-5,8,3,STATIONARY_WATER:0)
Block(-5,8,4,HAY_BLOCK:8)
Block(-5,8,5,MELON_BLOCK:0)
Block(-5,8,6,WOOD:5)
Block(-5,8,7,LAPIS_ORE:0)
Block(-5,8,8,LAPIS_ORE:0)
Block(-5,9,-3,LOG_2:1)
Block(-5,9,-2,LOG_2:1)
Block(-5,9,-1,WOOD:5)
Block(-5,9,0,WOOD:5)
Block(-5,9,1,STATIONARY_WATER:0)
Block(-5,9,2,STATIONARY_WATER:0)
Block(-5,9,3,STATIONARY_WATER:0)
Block(-5,9,4,STATIONARY_WATER:0)
Block(-5,9,5,STATIONARY_WATER:0)
Block(-5,9,6,WOOD:5)
Block(-5,9,7,STATIONARY_WATER:0)
Block(-5,9,8,STATIONARY_WATER:0)
Block(-5,10,-3,WOOD:5)
Block(-5,10,-2,WOOD:5)
Block(-5,10,-1,WOOD:5)
Block(-5,10,0,WOOD:5)
Block(-5,10,1,WOOD:5)
Block(-5,10,2,WOOD:5)
Block(-5,10,3,WOOD:5)
Block(-5,10,4,WOOD:5)
Block(-5,10,5,WOOD:5)
Block(-5,10,6,WOOD:5)
Block(-5,10,7,WOOD:5)
Block(-5,10,8,WOOD:5)
Block(-5,11,-4,WOOD:5)
Block(-5,11,-3,WOOD:5)
Block(-5,11,-2,BRICK:0)
Block(-5,11,-1,BRICK:0)
Block(-5,11,0,STAINED_CLAY:9)
Block(-5,11,1,STATIONARY_WATER:0)
Block(-5,11,2,DARK_OAK_STAIRS:1)
Block(-5,11,3,STATIONARY_WATER:0)
Block(-5,11,4,STATIONARY_WATER:0)
Block(-5,11,5,STATIONARY_WATER:0)
Block(-5,11,6,STATIONARY_WATER:0)
Block(-5,11,7,STATIONARY_WATER:0)
Block(-5,11,8,STATIONARY_WATER:0)
Block(-5,12,-4,WOOD:5)
Block(-5,12,-3,WOOD:5)
Block(-5,12,-2,BRICK:0)
Block(-5,12,-1,BRICK:0)
Block(-5,12,0,STAINED_CLAY:9)
Block(-5,12,1,STATIONARY_WATER:0)
Block(-5,12,2,STATIONARY_WATER:0)
Block(-5,12,3,STATIONARY_WATER:0)
Block(-5,12,4,STATIONARY_WATER:0)
Block(-5,12,5,STATIONARY_WATER:0)
Block(-5,12,6,STATIONARY_WATER:0)
Block(-5,12,7,STATIONARY_WATER:0)
Block(-5,12,8,STATIONARY_WATER:0)
Block(-5,13,-3,STAINED_CLAY:9)
Block(-5,13,-2,BRICK:0)
Block(-5,13,-1,BRICK:0)
Block(-5,13,0,WOOD_DOUBLE_STEP:5)
Block(-5,13,1,WOOD_STEP:13)
Block(-5,13,2,WOOD_STEP:13)
Block(-5,13,3,WOOD_STEP:13)
Block(-5,13,4,WOOD_STEP:13)
Block(-5,13,5,STATIONARY_WATER:0)
Block(-5,13,6,WOOD_STEP:13)
Block(-5,13,7,WOOD_STEP:13)
Block(-5,13,8,WOOD_STEP:13)
Block(-5,14,-3,STAINED_CLAY:9)
Block(-5,14,-2,STAINED_CLAY:9)
Block(-5,14,-1,WOOD_STEP:1)
Block(-5,14,3,SPRUCE_WOOD_STAIRS:1)
Block(-5,14,5,WOOD:2)
Block(-5,14,6,WOOD:2)
Block(-5,14,7,SPRUCE_WOOD_STAIRS:1)
Block(-5,15,-3,STAINED_CLAY:9)
Block(-5,15,-2,STAINED_CLAY:9)
Block(-5,15,5,WOOD:2)
Block(-5,15,6,WOOD:2)
Block(-5,16,-3,WOOD_STEP:5)
Block(-5,16,-2,WOOD_STEP:5)
Block(-5,16,5,WOOD:2)
Block(-5,16,6,WOOD:2)
Block(-4,6,6,LOG_2:1)
Block(-4,6,7,LOG_2:1)
Block(-4,6,8,LOG_2:1)
Block(-4,7,0,LOG_2:1)
Block(-4,7,1,LOG_2:1)
Block(-4,7,2,LOG_2:1)
Block(-4,7,3,LOG_2:1)
Block(-4,7,4,LOG_2:1)
Block(-4,7,5,LOG_2:1)
Block(-4,7,6,WOOD:5)
Block(-4,7,7,LAPIS_ORE:0)
Block(-4,7,8,STATIONARY_WATER:0)
Block(-4,8,-2,LOG_2:1)
Block(-4,8,-1,LOG_2:1)
Block(-4,8,0,WOOD:5)
Block(-4,8,1,HAY_BLOCK:4)
Block(-4,8,2,STATIONARY_WATER:0)
Block(-4,8,3,STATIONARY_WATER:0)
Block(-4,8,4,STATIONARY_WATER:0)
Block(-4,8,5,HAY_BLOCK:8)
Block(-4,8,6,WOOD:5)
Block(-4,8,7,STATIONARY_WATER:0)
Block(-4,8,8,STATIONARY_WATER:0)
Block(-4,9,-4,LOG_2:1)
Block(-4,9,-3,LOG_2:1)
Block(-4,9,-2,BRICK:0)
Block(-4,9,-1,BRICK:0)
Block(-4,9,0,WOOD:5)
Block(-4,9,1,STATIONARY_WATER:0)
Block(-4,9,2,STATIONARY_WATER:0)
Block(-4,9,3,STATIONARY_WATER:0)
Block(-4,9,4,STATIONARY_WATER:0)
Block(-4,9,5,STATIONARY_WATER:0)
Block(-4,9,6,WOOD:5)
Block(-4,9,7,STATIONARY_WATER:0)
Block(-4,9,8,STATIONARY_WATER:0)
Block(-4,10,-5,WOOD:5)
Block(-4,10,-4,WOOD:5)
Block(-4,10,-3,BRICK:0)
Block(-4,10,-2,BRICK:0)
Block(-4,10,-1,BRICK:0)
Block(-4,10,0,WOOD:5)
Block(-4,10,1,WOOD:5)
Block(-4,10,2,WOOD:5)
Block(-4,10,3,WOOD:5)
Block(-4,10,4,WOOD:5)
Block(-4,10,5,WOOD:5)
Block(-4,10,6,WOOD:5)
Block(-4,10,7,WOOD:5)
Block(-4,10,8,WOOD:5)
Block(-4,11,-5,WOOD:5)
RandomBlock(-4,11,-4,AIR:0,20,CHEST:5,../../../../Chests/Loot/PirateJunk_1.nbt,10,CHEST:5,../../../../Chests/Loot/PirateJunk_2.nbt,10,CHEST:5,../../../../Chests/Loot/PirateJunk_3.nbt,10,CHEST:5,../../../../Chests/Loot/PirateJunk_4.nbt,10,CHEST:5,../../../../Chests/Loot/PirateJunk_5.nbt,10,CHEST:5,../../../../Chests/Traveler/Travelers_Castle.nbt,1,CHEST:5,../../../../Chests/Traveler/Travelers_Church.nbt,1,CHEST:5,../../../../Chests/Traveler/Travelers_Daeroc.nbt,1,CHEST:5,../../../../Chests/Traveler/Travelers_Farmsteads.nbt,1,CHEST:5,../../../../Chests/Traveler/Travelers_GreenDungeon.nbt,1,CHEST:5,../../../../Chests/Traveler/Travelers_IceShips.nbt,1,CHEST:5,../../../../Chests/Traveler/Travelers_IceTemple.nbt,1,CHEST:5,../../../../Chests/Traveler/Travelers_LegacySpawn.nbt,1,CHEST:5,../../../../Chests/Traveler/Travelers_Mineshafts.nbt,1,CHEST:5,../../../../Chests/Traveler/Travelers_Mountains.nbt,1,CHEST:5,../../../../Chests/Traveler/Travelers_Origin.nbt,1,CHEST:5,../../../../Chests/Traveler/Travelers_Pirate.nbt,1,CHEST:5,../../../../Chests/Traveler/Travelers_Quarry.nbt,1,CHEST:5,../../../../Chests/Traveler/Travelers_Spook.nbt,1,CHEST:5,../../../../Chests/Traveler/Travelers_Tribal.nbt,1,CHEST:5,../../../../Chests/Lore/ShipSunk_1.nbt,1,CHEST:5,../../../../Chests/Lore/ShipSunk_2.nbt,1,CHEST:5,../../../../Chests/Lore/ShipSunk_3.nbt,1,CHEST:5,../../../../Chests/Lore/ShipSunk_4.nbt,1,CHEST:5,../../../../Chests/Lore/ShipSunk_5.nbt,1,CHEST:5,../../../../Chests/Loot/Common1.nbt,10,CHEST:5,../../../../Chests/Loot/Common2.nbt,10,CHEST:5,../../../../Chests/Loot/Common3.nbt,10,CHEST:5,../../../../Chests/Loot/Common4.nbt,10,CHEST:5,../../../../Chests/Loot/Common5.nbt,10,CHEST:5,../../../../Chests/Loot/Common6.nbt,10,CHEST:5,../../../../Chests/Loot/Common7.nbt,10,CHEST:5,../../../../Chests/Loot/Common8.nbt,10,CHEST:5,../../../../Chests/Loot/Common9.nbt,10,CHEST:5,../../../../Chests/Loot/Common10.nbt,10,CHEST:5,../../../../Chests/Loot/Common10.nbt,11,CHEST:5,../../../../Chests/Loot/Common12.nbt,10,CHEST:5,../../../../Chests/Loot/Common13.nbt,10,CHEST:5,../../../../Chests/Loot/Common14.nbt,10,CHEST:5,../../../../Chests/Loot/Common15.nbt,10,CHEST:5,../../../../Chests/Lore/ShipSunk_1.nbt,2,CHEST:5,../../../../Chests/Lore/ShipSunk_3.nbt,2,CHEST:5,../../../../Chests/Lore/ShipSunk_4.nbt,2,CHEST:5,../../../../Chests/Lore/ShipSunk_5.nbt,2,CHEST:5,../../../../Chests/Lore/ShipSunk_5.nbt,2,CHEST:5,../../../../Chests/Loot/Rare1.nbt,5,CHEST:5,../../../../Chests/Loot/Rare2.nbt,5,CHEST:5,../../../../Chests/Loot/Rare3.nbt,5,CHEST:5,../../../../Chests/Loot/Rare4.nbt,5,CHEST:5,../../../../Chests/Loot/Rare5.nbt,5,CHEST:5,../../../../Chests/Loot/Rare6.nbt,5,CHEST:5,../../../../Chests/Loot/Rare7.nbt,5,CHEST:5,../../../../Chests/Loot/Rare8.nbt,5,CHEST:5,../../../../Chests/Loot/Rare9.nbt,5,CHEST:5,../../../../Chests/Loot/Rare10.nbt,5,CHEST:5,../../../../Chests/Loot/Rare11.nbt,5,CHEST:5,../../../../Chests/Loot/Rare12.nbt,5,CHEST:5,../../../../Chests/Loot/Rare13.nbt,5,CHEST:5,../../../../Chests/Loot/Rare14.nbt,5,CHEST:5,../../../../Chests/Loot/Rare15.nbt,5,CHEST:5,../../../../Chests/Loot/Epic1.nbt,2,CHEST:5,../../../../Chests/Loot/Epic2.nbt,2,CHEST:5,../../../../Chests/Loot/Epic3.nbt,2,CHEST:5,../../../../Chests/Loot/Epic4.nbt,2,CHEST:5,../../../../Chests/Loot/Epic5.nbt,2,CHEST:5,../../../../Chests/Loot/Epic6.nbt,2,CHEST:5,../../../../Chests/Loot/Epic7.nbt,2,CHEST:5,../../../../Chests/Loot/Epic8.nbt,2,CHEST:5,../../../../Chests/Loot/Epic9.nbt,2,CHEST:5,../../../../Chests/Loot/Epic10.nbt,2,CHEST:5,../../../../Chests/Loot/Epic11.nbt,2,CHEST:5,../../../../Chests/Loot/Epic12.nbt,2,CHEST:5,../../../../Chests/Loot/Epic13.nbt,2,CHEST:5,../../../../Chests/Loot/Epic14.nbt,2,CHEST:5,../../../../Chests/Loot/Epic15.nbt,5,CHEST:5,../../../../Chests/Loot/Rare1.nbt,5,CHEST:5,../../../../Chests/Loot/Rare2.nbt,5,CHEST:5,../../../../Chests/Loot/Rare3.nbt,5,CHEST:5,../../../../Chests/Loot/Rare4.nbt,5,CHEST:5,../../../../Chests/Loot/Rare5.nbt,10,CHEST:5,../../../../Chests/Loot/Rare6.nbt,10,CHEST:5,../../../../Chests/Loot/Rare7.nbt,10,CHEST:5,../../../../Chests/Loot/Rare8.nbt,10,CHEST:5,../../../../Chests/Loot/Rare9.nbt,10,CHEST:5,../../../../Chests/Loot/Rare10.nbt,15,CHEST:5,../../../../Chests/Loot/Rare11.nbt,15,CHEST:5,../../../../Chests/Loot/Rare12.nbt,15,CHEST:5,../../../../Chests/Loot/Rare13.nbt,15,CHEST:5,../../../../Chests/Loot/Rare14.nbt,15,CHEST:5,../../../../Chests/Loot/Rare15.nbt,15,CHEST:5,../../../../Chests/Loot/Epic15.nbt,100)
Block(-4,11,-3,BRICK:0)
Block(-4,11,-2,BRICK:0)
Block(-4,11,-1,BRICK:0)
Block(-4,11,0,STAINED_CLAY:9)
Block(-4,11,1,STATIONARY_WATER:0)
Block(-4,11,2,STATIONARY_WATER:0)
Block(-4,11,3,STATIONARY_WATER:0)
Block(-4,11,4,STATIONARY_WATER:0)
Block(-4,11,5,STATIONARY_WATER:0)
Block(-4,11,6,STATIONARY_WATER:0)
Block(-4,11,7,STATIONARY_WATER:0)
Block(-4,11,8,STATIONARY_WATER:0)
Block(-4,12,-5,WOOD:5)
Block(-4,12,-4,STATIONARY_WATER:0)
Block(-4,12,-3,BRICK:0)
Block(-4,12,-2,BRICK:0)
Block(-4,12,-1,BRICK:0)
Block(-4,12,0,STAINED_CLAY:9)
Block(-4,12,1,STATIONARY_WATER:0)
Block(-4,12,2,STATIONARY_WATER:0)
Block(-4,12,3,STATIONARY_WATER:0)
Block(-4,12,4,STATIONARY_WATER:0)
Block(-4,12,5,STATIONARY_WATER:0)
Block(-4,12,6,STATIONARY_WATER:0)
Block(-4,12,7,STATIONARY_WATER:0)
Block(-4,12,8,STATIONARY_WATER:0)
Block(-4,13,-6,STAINED_CLAY:9)
Block(-4,13,-5,STAINED_CLAY:9)
Block(-4,13,-4,STAINED_CLAY:9)
Block(-4,13,-3,BRICK:0)
Block(-4,13,-2,BRICK:0)
Block(-4,13,-1,BRICK:0)
Block(-4,13,0,WOOD_DOUBLE_STEP:5)
Block(-4,13,1,WOOD_STEP:13)
Block(-4,13,2,WOOD_STEP:13)
Block(-4,13,3,WOOD_STEP:13)
Block(-4,13,4,WOOD_STEP:13)
Block(-4,13,5,STATIONARY_WATER:0)
Block(-4,13,6,STATIONARY_WATER:0)
Block(-4,13,7,WOOD_STEP:13)
Block(-4,13,8,WOOD_STEP:13)
Block(-4,14,-7,WOOD_STEP:5)
Block(-4,14,-6,WOOD_STEP:5)
Block(-4,14,-5,WOOD_STEP:13)
Block(-4,14,-4,STAINED_CLAY:9)
Block(-4,14,-3,STAINED_CLAY:9)
Block(-4,14,-2,STAINED_CLAY:9)
Block(-4,14,-1,WOOD_STEP:1)
Block(-4,14,3,WOOD:2)
Block(-4,14,4,WOOD:2)
Block(-4,14,5,WOOD:2)
Block(-4,14,6,WOOD:2)
Block(-4,14,7,WOOD:2)
Block(-4,14,8,WOOD:2)
Block(-4,15,-7,WOOD_STEP:5)
Block(-4,15,-6,WOOD_STEP:13)
Block(-4,15,-5,DARK_OAK_STAIRS:6)
Block(-4,15,-4,STAINED_CLAY:9)
Block(-4,15,1,AIR:0)
Block(-4,15,3,WOOD:2)
Block(-4,15,4,WOOD:2)
Block(-4,15,5,WOOD:2)
Block(-4,15,6,WOOD:2)
Block(-4,15,7,WOOD:2)
Block(-4,15,8,WOOD:2)
Block(-4,16,-4,WOOD_STEP:5)
Block(-4,16,5,WOOD:2)
Block(-4,16,6,WOOD:2)
Block(-3,6,2,LOG_2:1)
Block(-3,6,3,LOG_2:1)
Block(-3,6,4,LOG_2:1)
Block(-3,6,5,LOG_2:1)
Block(-3,6,6,LOG_2:1)
Block(-3,6,7,LOG_2:1)
Block(-3,6,8,LOG_2:1)
Block(-3,7,-2,LOG_2:1)
Block(-3,7,-1,LOG_2:1)
Block(-3,7,0,LOG_2:1)
Block(-3,7,1,LOG_2:1)
Block(-3,7,2,STATIONARY_WATER:0)
Block(-3,7,3,HAY_BLOCK:8)
Block(-3,7,4,STATIONARY_WATER:0)
Block(-3,7,5,MELON_BLOCK:0)
Block(-3,7,6,WOOD:5)
Block(-3,7,7,STATIONARY_WATER:0)
Block(-3,7,8,STATIONARY_WATER:0)
Block(-3,8,-3,LOG_2:1)
Block(-3,8,-2,BRICK:0)
Block(-3,8,-1,BRICK:0)
Block(-3,8,0,WOOD:5)
Block(-3,8,1,STATIONARY_WATER:0)
Block(-3,8,2,STATIONARY_WATER:0)
Block(-3,8,3,STATIONARY_WATER:0)
Block(-3,8,4,STATIONARY_WATER:0)
Block(-3,8,5,STATIONARY_WATER:0)
Block(-3,8,6,WOOD:5)
Block(-3,8,7,STATIONARY_WATER:0)
Block(-3,8,8,STATIONARY_WATER:0)
Block(-3,9,-5,LOG_2:1)
Block(-3,9,-4,LOG_2:1)
Block(-3,9,-3,BRICK:0)
Block(-3,9,-2,BRICK:0)
Block(-3,9,-1,BRICK:0)
Block(-3,9,0,WOOD:5)
Block(-3,9,1,STATIONARY_WATER:0)
Block(-3,9,2,STATIONARY_WATER:0)
Block(-3,9,3,STATIONARY_WATER:0)
Block(-3,9,4,STATIONARY_WATER:0)
Block(-3,9,5,STATIONARY_WATER:0)
Block(-3,9,6,WOOD:5)
Block(-3,9,7,STATIONARY_WATER:0)
Block(-3,9,8,STATIONARY_WATER:0)
Block(-3,10,-5,WOOD:5)
Block(-3,10,-4,WOOD:5)
Block(-3,10,-3,BRICK:0)
Block(-3,10,-2,BRICK:0)
Block(-3,10,-1,BRICK:0)
Block(-3,10,0,WOOD:5)
Block(-3,10,1,WOOD:5)
Block(-3,10,2,WOOD:5)
Block(-3,10,3,WOOD:5)
Block(-3,10,4,WOOD:5)
Block(-3,10,5,WOOD:5)
Block(-3,10,6,WOOD:5)
Block(-3,10,7,WOOD:5)
Block(-3,10,8,WOOD:5)
Block(-3,11,-6,WOOD:5)
Block(-3,11,-5,FURNACE:3)
Block(-3,11,-4,STATIONARY_WATER:0)
Block(-3,11,-3,BRICK:0)
Block(-3,11,-1,BRICK:0)
Block(-3,11,0,STAINED_CLAY:9)
Block(-3,11,1,STATIONARY_WATER:0)
Block(-3,11,2,STATIONARY_WATER:0)
Block(-3,11,3,STATIONARY_WATER:0)
Block(-3,11,4,STATIONARY_WATER:0)
Block(-3,11,5,STATIONARY_WATER:0)
Block(-3,11,6,WOOD:2)
Block(-3,11,7,WOOD:2)
Block(-3,11,8,WOOD:2)
Block(-3,12,-7,WOOD:5)
Block(-3,12,-6,WOOD:5)
Block(-3,12,-5,STATIONARY_WATER:0)
Block(-3,12,-4,STATIONARY_WATER:0)
Block(-3,12,-3,STEP:12)
Block(-3,12,-2,IRON_TRAPDOOR:1)
Block(-3,12,-1,BRICK:0)
Block(-3,12,0,STAINED_CLAY:9)
Block(-3,12,1,STATIONARY_WATER:0)
Block(-3,12,2,STATIONARY_WATER:0)
Block(-3,12,3,STATIONARY_WATER:0)
Block(-3,12,4,STATIONARY_WATER:0)
Block(-3,12,5,STATIONARY_WATER:0)
Block(-3,12,6,STATIONARY_WATER:0)
Block(-3,12,7,STATIONARY_WATER:0)
Block(-3,12,8,STATIONARY_WATER:0)
Block(-3,13,-7,STAINED_CLAY:9)
Block(-3,13,-6,STAINED_CLAY:9)
Block(-3,13,-5,STAINED_CLAY:9)
Block(-3,13,-4,STAINED_CLAY:9)
Block(-3,13,-3,BRICK:0)
Block(-3,13,-2,BRICK:0)
Block(-3,13,-1,BRICK:0)
Block(-3,13,0,WOOD_DOUBLE_STEP:5)
Block(-3,13,1,WOOD_STEP:13)
Block(-3,13,2,WOOD_STEP:13)
Block(-3,13,3,WOOD_STEP:13)
Block(-3,13,4,WOOD_STEP:13)
Block(-3,13,5,STATIONARY_WATER:0)
Block(-3,13,6,STATIONARY_WATER:0)
Block(-3,13,7,STATIONARY_WATER:0)
Block(-3,13,8,WOOD_STEP:13)
Block(-3,14,-4,STAINED_CLAY:9)
Block(-3,14,-3,STAINED_CLAY:9)
Block(-3,14,-2,STAINED_CLAY:9)
Block(-3,14,-1,WOOD_STEP:1)
Block(-3,14,3,WOOD:2)
Block(-3,14,4,WOOD:2)
Block(-3,14,5,WOOD:2)
Block(-3,14,6,WOOD:2)
Block(-3,14,7,WOOD:2)
Block(-3,14,8,WOOD:2)
Block(-3,15,-4,STAINED_CLAY:9)
Block(-3,15,-3,SPRUCE_WOOD_STAIRS:3)
Block(-3,15,3,WOOD:2)
Block(-3,15,4,WOOD:2)
Block(-3,15,5,WOOD:2)
Block(-3,15,6,WOOD:2)
Block(-3,15,7,WOOD:2)
Block(-3,15,8,WOOD:2)
Block(-2,5,3,LOG_2:1)
Block(-2,5,4,LOG_2:1)
Block(-2,5,5,LOG_2:1)
Block(-2,5,6,LOG_2:1)
Block(-2,5,7,LOG_2:1)
Block(-2,5,8,LOG_2:1)
Block(-2,6,-1,LOG_2:1)
Block(-2,6,0,LOG_2:1)
Block(-2,6,1,LOG_2:1)
Block(-2,6,2,LOG_2:1)
Block(-2,6,3,LOG_2:1)
Block(-2,6,4,LOG_2:1)
Block(-2,6,5,LOG_2:1)
Block(-2,6,6,LOG_2:1)
Block(-2,6,7,LOG_2:1)
Block(-2,6,8,STATIONARY_WATER:0)
Block(-2,7,-3,LOG_2:1)
Block(-2,7,-2,LOG_2:1)
Block(-2,7,-1,WOOD:5)
Block(-2,7,0,WOOD:5)
Block(-2,7,1,STATIONARY_WATER:0)
Block(-2,7,2,STATIONARY_WATER:0)
Block(-2,7,3,STATIONARY_WATER:0)
Block(-2,7,4,STATIONARY_WATER:0)
Block(-2,7,5,STATIONARY_WATER:0)
Block(-2,7,6,WOOD:5)
Block(-2,7,7,STATIONARY_WATER:0)
Block(-2,7,8,STATIONARY_WATER:0)
Block(-2,8,-4,LOG_2:1)
Block(-2,8,-3,BRICK:0)
Block(-2,8,-2,BRICK:0)
Block(-2,8,-1,BRICK:0)
Block(-2,8,0,WOOD:5)
Block(-2,8,1,STATIONARY_WATER:0)
Block(-2,8,2,STATIONARY_WATER:0)
Block(-2,8,3,STATIONARY_WATER:0)
Block(-2,8,4,STATIONARY_WATER:0)
Block(-2,8,5,STATIONARY_WATER:0)
Block(-2,8,6,WOOD:5)
Block(-2,8,7,STATIONARY_WATER:0)
Block(-2,8,8,STATIONARY_WATER:0)
Block(-2,9,-5,LOG_2:1)
Block(-2,9,-4,BRICK:0)
Block(-2,9,-3,BRICK:0)
Block(-2,9,-2,BRICK:0)
Block(-2,9,-1,BRICK:0)
Block(-2,9,0,WOOD:5)
Block(-2,9,1,STATIONARY_WATER:0)
Block(-2,9,2,STATIONARY_WATER:0)
Block(-2,9,3,STATIONARY_WATER:0)
Block(-2,9,4,STATIONARY_WATER:0)
Block(-2,9,5,STATIONARY_WATER:0)
Block(-2,9,6,WOOD:5)
Block(-2,9,7,STATIONARY_WATER:0)
Block(-2,9,8,STATIONARY_WATER:0)
Block(-2,10,-5,WOOD:5)
Block(-2,10,-4,WOOD:5)
Block(-2,10,-3,BRICK:0)
Block(-2,10,-2,BRICK:0)
Block(-2,10,-1,BRICK:0)
Block(-2,10,0,WOOD:5)
Block(-2,10,1,WOOD:5)
Block(-2,10,2,STATIONARY_WATER:0)
Block(-2,10,3,STATIONARY_WATER:0)
Block(-2,10,4,STATIONARY_WATER:0)
Block(-2,10,5,STATIONARY_WATER:0)
Block(-2,10,6,WOOD_DOUBLE_STEP:1)
Block(-2,10,7,STATIONARY_WATER:0)
Block(-2,10,8,STATIONARY_WATER:0)
Block(-2,11,-7,WOOD:5)
Block(-2,11,-6,WOOD:5)
Block(-2,11,-5,WORKBENCH:0)
Block(-2,11,-4,STATIONARY_WATER:0)
Block(-2,11,-3,BRICK:0)
Block(-2,11,-2,BRICK:0)
Block(-2,11,-1,BRICK:0)
Block(-2,11,0,STAINED_CLAY:9)
Block(-2,11,1,STATIONARY_WATER:0)
Block(-2,11,2,STATIONARY_WATER:0)
Block(-2,11,3,STATIONARY_WATER:0)
Block(-2,11,4,STATIONARY_WATER:0)
Block(-2,11,5,STATIONARY_WATER:0)
Block(-2,11,6,STATIONARY_WATER:0)
Block(-2,11,7,STATIONARY_WATER:0)
Block(-2,11,8,STATIONARY_WATER:0)
Block(-2,12,-7,WOOD:5)
Block(-2,12,-6,WOOD:5)
Block(-2,12,-5,STATIONARY_WATER:0)
Block(-2,12,-4,STATIONARY_WATER:0)
Block(-2,12,-3,BRICK:0)
Block(-2,12,-2,DOUBLE_STEP:4)
Block(-2,12,-1,BRICK:0)
Block(-2,12,0,STAINED_CLAY:9)
Block(-2,12,1,STATIONARY_WATER:0)
Block(-2,12,2,STATIONARY_WATER:0)
Block(-2,12,3,STATIONARY_WATER:0)
Block(-2,12,4,STATIONARY_WATER:0)
Block(-2,12,5,STATIONARY_WATER:0)
Block(-2,12,6,STATIONARY_WATER:0)
Block(-2,12,7,STATIONARY_WATER:0)
Block(-2,12,8,STATIONARY_WATER:0)
Block(-2,13,-7,STAINED_CLAY:9)
Block(-2,13,-6,STAINED_CLAY:9)
Block(-2,13,-5,STAINED_CLAY:9)
Block(-2,13,-4,STAINED_CLAY:9)
Block(-2,13,-3,BRICK:0)
Block(-2,13,-2,BRICK:0)
Block(-2,13,-1,BRICK:0)
Block(-2,13,0,WOOD_DOUBLE_STEP:5)
Block(-2,13,1,WOOD_STEP:13)
Block(-2,13,2,WOOD_STEP:13)
Block(-2,13,3,STATIONARY_WATER:0)
Block(-2,13,4,STATIONARY_WATER:0)
Block(-2,13,5,STATIONARY_WATER:0)
Block(-2,13,6,STATIONARY_WATER:0)
Block(-2,13,7,STATIONARY_WATER:0)
Block(-2,13,8,STATIONARY_WATER:0)
Block(-2,14,-4,STAINED_CLAY:9)
Block(-2,14,-3,STAINED_CLAY:9)
Block(-2,14,-2,STAINED_CLAY:9)
Block(-2,14,-1,WOOD_STEP:1)
Block(-2,14,0,WOOD:2)
Block(-2,14,1,WOOD:2)
Block(-2,14,3,WOOD:2)
Block(-2,14,4,WOOD:2)
Block(-2,14,5,WOOD:2)
Block(-2,14,6,WOOD:2)
Block(-2,14,7,WOOD:2)
Block(-2,14,8,WOOD:2)
Block(-2,15,-4,STAINED_CLAY:9)
Block(-2,15,0,WOOD:2)
Block(-2,15,3,WOOD:2)
Block(-2,15,4,WOOD:2)
Block(-2,15,5,WOOD:2)
Block(-2,15,6,WOOD:2)
Block(-2,15,7,WOOD:2)
Block(-2,15,8,WOOD:2)
Block(-2,16,-4,WOOD_STEP:5)
Block(-1,3,3,WOOD:5)
Block(-1,3,4,WOOD:5)
Block(-1,3,5,WOOD:5)
Block(-1,3,6,WOOD:5)
Block(-1,3,7,WOOD:5)
Block(-1,3,8,WOOD:5)
Block(-1,4,-1,WOOD:5)
Block(-1,4,0,WOOD:5)
Block(-1,4,1,WOOD:5)
Block(-1,4,2,WOOD:5)
Block(-1,4,3,LOG_2:1)
Block(-1,4,4,LOG_2:1)
Block(-1,4,5,LOG_2:1)
Block(-1,4,6,LOG_2:1)
Block(-1,4,7,LOG_2:1)
Block(-1,4,8,LOG_2:1)
Block(-1,5,-3,WOOD:5)
Block(-1,5,-2,WOOD:5)
Block(-1,5,-1,LOG_2:1)
Block(-1,5,0,LOG_2:1)
Block(-1,5,1,LOG_2:1)
Block(-1,5,2,LOG_2:1)
Block(-1,5,3,LOG_2:1)
Block(-1,5,4,LOG_2:1)
Block(-1,5,5,LOG_2:1)
Block(-1,5,6,LOG_2:1)
Block(-1,5,7,LOG_2:1)
Block(-1,5,8,LOG_2:1)
Block(-1,6,-4,WOOD:5)
Block(-1,6,-3,LOG_2:1)
Block(-1,6,-2,LOG_2:1)
Block(-1,6,-1,LOG_2:1)
Block(-1,6,0,LOG_2:1)
Block(-1,6,1,LOG_2:1)
Block(-1,6,2,LOG_2:1)
Block(-1,6,3,LOG_2:1)
Block(-1,6,4,LOG_2:1)
Block(-1,6,5,LOG_2:1)
Block(-1,6,6,LOG_2:1)
Block(-1,6,7,LOG_2:1)
Block(-1,6,8,STATIONARY_WATER:0)
Block(-1,7,-5,WOOD:5)
Block(-1,7,-4,LOG_2:1)
Block(-1,7,-3,WOOD:5)
Block(-1,7,-2,WOOD:5)
Block(-1,7,-1,LOG:1)
Block(-1,7,0,WOOD:5)
Block(-1,7,1,STATIONARY_WATER:0)
Block(-1,7,2,STATIONARY_WATER:0)
Block(-1,7,3,STATIONARY_WATER:0)
Block(-1,7,4,STATIONARY_WATER:0)
Block(-1,7,5,STATIONARY_WATER:0)
Block(-1,7,6,WOOD:5)
Block(-1,7,7,STATIONARY_WATER:0)
Block(-1,7,8,STATIONARY_WATER:0)
Block(-1,8,-6,WOOD:5)
Block(-1,8,-5,LOG_2:1)
Block(-1,8,-4,WOOD:5)
Block(-1,8,-3,STATIONARY_WATER:0)
Block(-1,8,-2,STATIONARY_WATER:0)
Block(-1,8,-1,LOG:1)
Block(-1,8,0,WOOD:5)
Block(-1,8,1,STATIONARY_WATER:0)
Block(-1,8,2,STATIONARY_WATER:0)
Block(-1,8,3,STATIONARY_WATER:0)
Block(-1,8,4,STATIONARY_WATER:0)
Block(-1,8,5,STATIONARY_WATER:0)
Block(-1,8,6,WOOD:5)
Block(-1,8,7,STATIONARY_WATER:0)
Block(-1,8,8,STATIONARY_WATER:0)
Block(-1,9,-7,WOOD:5)
Block(-1,9,-6,LOG_2:1)
Block(-1,9,-5,WOOD:5)
Block(-1,9,-4,WOOD:5)
Block(-1,9,-3,STATIONARY_WATER:0)
Block(-1,9,-2,STATIONARY_WATER:0)
Block(-1,9,-1,LOG:1)
Block(-1,9,0,STATIONARY_WATER:0)
Block(-1,9,1,STATIONARY_WATER:0)
Block(-1,9,2,STATIONARY_WATER:0)
Block(-1,9,3,STATIONARY_WATER:0)
Block(-1,9,4,STATIONARY_WATER:0)
Block(-1,9,5,STATIONARY_WATER:0)
Block(-1,9,6,WOOD:5)
Block(-1,9,7,STATIONARY_WATER:0)
Block(-1,9,8,STATIONARY_WATER:0)
Block(-1,10,-7,WOOD:5)
Block(-1,10,-6,WOOD:5)
Block(-1,10,-5,WOOD:5)
Block(-1,10,-4,WOOD:5)
Block(-1,10,-3,WOOD:5)
Block(-1,10,-2,WOOD:5)
Block(-1,10,-1,LOG:1)
Block(-1,10,0,WOOD:5)
Block(-1,10,1,WOOD:5)
Block(-1,10,2,WOOD_STEP:9)
Block(-1,10,3,WOOD_STEP:9)
Block(-1,10,4,WOOD_STEP:9)
Block(-1,10,5,WOOD_STEP:9)
Block(-1,10,6,WOOD_DOUBLE_STEP:1)
Block(-1,10,7,WOOD_STEP:9)
Block(-1,10,8,WOOD_STEP:9)
Block(-1,11,-7,WOOD:5)
Block(-1,11,-6,WOOD:5)
Block(-1,11,-5,WOOD:5)
Block(-1,11,-4,STATIONARY_WATER:0)
Block(-1,11,-3,WOOD:5)
Block(-1,11,-2,WOOD:5)
Block(-1,11,-1,LOG:1)
Block(-1,11,0,STAINED_CLAY:9)
Block(-1,11,1,WOOD:5)
Block(-1,11,2,STATIONARY_WATER:0)
Block(-1,11,3,STATIONARY_WATER:0)
Block(-1,11,4,STATIONARY_WATER:0)
Block(-1,11,5,STATIONARY_WATER:0)
Block(-1,11,6,STATIONARY_WATER:0)
Block(-1,11,7,STATIONARY_WATER:0)
Block(-1,11,8,STATIONARY_WATER:0)
Block(-1,12,-7,WOOD:5)
Block(-1,12,-6,WOOD:5)
Block(-1,12,-5,WOOD:5)
Block(-1,12,-4,STATIONARY_WATER:0)
Block(-1,12,-3,WOOD:5)
Block(-1,12,-2,WOOD:5)
Block(-1,12,-1,LOG:1)
Block(-1,12,0,STAINED_CLAY:9)
Block(-1,12,1,STATIONARY_WATER:0)
Block(-1,12,2,STATIONARY_WATER:0)
Block(-1,12,3,STATIONARY_WATER:0)
Block(-1,12,4,STATIONARY_WATER:0)
Block(-1,12,5,STATIONARY_WATER:0)
Block(-1,12,6,AIR:0)
Block(-1,12,7,STATIONARY_WATER:0)
Block(-1,12,8,STATIONARY_WATER:0)
Block(-1,13,-7,STAINED_CLAY:9)
Block(-1,13,-6,STAINED_CLAY:9)
Block(-1,13,-5,WOOD_DOUBLE_STEP:1)
Block(-1,13,-4,WOOD_DOUBLE_STEP:1)
Block(-1,13,-3,WOOD_DOUBLE_STEP:1)
Block(-1,13,-2,WOOD_DOUBLE_STEP:1)
Block(-1,13,-1,LOG:1)
Block(-1,13,0,WOOD_DOUBLE_STEP:5)
Block(-1,13,1,WOOD_STEP:13)
Block(-1,13,2,WOOD_STEP:13)
Block(-1,13,3,STATIONARY_WATER:0)
Block(-1,13,4,STATIONARY_WATER:0)
Block(-1,13,5,STATIONARY_WATER:0)
Block(-1,13,6,STATIONARY_WATER:0)
Block(-1,13,7,STATIONARY_WATER:0)
Block(-1,13,8,STATIONARY_WATER:0)
Block(-1,14,-7,WOOD_STEP:9)
Block(-1,14,-6,WOOD_DOUBLE_STEP:1)
Block(-1,14,-5,WOOD_DOUBLE_STEP:1)
Block(-1,14,-4,STAINED_CLAY:9)
Block(-1,14,-3,STAINED_CLAY:9)
Block(-1,14,-2,STAINED_CLAY:9)
Block(-1,14,-1,LOG:1)
Block(-1,14,0,WOOD:2)
Block(-1,14,1,WOOD:2)
Block(-1,14,3,WOOD_STEP:5)
Block(-1,14,4,WOOD_STEP:5)
Block(-1,14,5,WOOD_STEP:5)
Block(-1,14,6,WOOD_STEP:5)
Block(-1,14,7,WOOD_STEP:1)
Block(-1,14,8,WOOD_STEP:1)
Block(-1,15,-7,WOOD_DOUBLE_STEP:1)
Block(-1,15,-6,WOOD_STEP:1)
Block(-1,15,-4,STAINED_CLAY:9)
Block(-1,15,-1,LOG:1)
Block(-1,15,0,WOOD:2)
Block(-1,16,-4,WOOD_STEP:5)
Block(-1,16,-1,LOG:1)
Block(-1,16,0,WOOD:2)
Block(0,5,3,LOG_2:1)
Block(0,5,4,LOG_2:1)
Block(0,5,5,LOG_2:1)
Block(0,5,6,LOG_2:1)
Block(0,5,7,LOG_2:1)
Block(0,5,8,LOG_2:1)
Block(0,6,-1,LOG_2:1)
Block(0,6,0,LOG_2:1)
Block(0,6,1,LOG_2:1)
Block(0,6,2,LOG_2:1)
Block(0,6,3,LOG_2:1)
Block(0,6,4,LOG_2:1)
Block(0,6,5,LOG_2:1)
Block(0,6,6,LOG_2:1)
Block(0,6,7,LOG_2:1)
Block(0,6,8,STATIONARY_WATER:0)
Block(0,7,-3,LOG_2:1)
Block(0,7,-2,LOG_2:1)
Block(0,7,-1,WOOD:5)
Block(0,7,0,WOOD:5)
Block(0,7,1,STATIONARY_WATER:0)
Block(0,7,2,STATIONARY_WATER:0)
Block(0,7,3,STATIONARY_WATER:0)
Block(0,7,4,STATIONARY_WATER:0)
Block(0,7,5,STATIONARY_WATER:0)
Block(0,7,6,WOOD:5)
Block(0,7,7,STATIONARY_WATER:0)
Block(0,7,8,STATIONARY_WATER:0)
Block(0,8,-4,LOG_2:1)
Block(0,8,-3,STATIONARY_WATER:0)
Block(0,8,-2,STATIONARY_WATER:0)
Block(0,8,-1,STATIONARY_WATER:0)
Block(0,8,0,WOOD:5)
Block(0,8,1,STATIONARY_WATER:0)
Block(0,8,2,STATIONARY_WATER:0)
Block(0,8,3,STATIONARY_WATER:0)
Block(0,8,4,STATIONARY_WATER:0)
Block(0,8,5,STATIONARY_WATER:0)
Block(0,8,6,WOOD:5)
Block(0,8,7,STATIONARY_WATER:0)
Block(0,8,8,STATIONARY_WATER:0)
Block(0,9,-5,LOG_2:1)
Block(0,9,-4,WOOD:5)
Block(0,9,-3,STATIONARY_WATER:0)
Block(0,9,-2,STATIONARY_WATER:0)
Block(0,9,-1,STATIONARY_WATER:0)
Block(0,9,0,WOOD:5)
Block(0,9,1,STATIONARY_WATER:0)
Block(0,9,2,STATIONARY_WATER:0)
Block(0,9,3,STATIONARY_WATER:0)
Block(0,9,4,STATIONARY_WATER:0)
Block(0,9,5,STATIONARY_WATER:0)
Block(0,9,6,WOOD:5)
Block(0,9,7,STATIONARY_WATER:0)
Block(0,9,8,STATIONARY_WATER:0)
Block(0,10,-6,WOOD:5)
Block(0,10,-5,WOOD:5)
Block(0,10,-4,WOOD:5)
Block(0,10,-3,WOOD:5)
Block(0,10,-2,WOOD:5)
Block(0,10,-1,STATIONARY_WATER:0)
Block(0,10,0,WOOD:5)
Block(0,10,1,WOOD:5)
Block(0,10,2,STATIONARY_WATER:0)
Block(0,10,3,STATIONARY_WATER:0)
Block(0,10,4,STATIONARY_WATER:0)
Block(0,10,5,STATIONARY_WATER:0)
Block(0,10,6,WOOD_DOUBLE_STEP:1)
Block(0,10,7,STATIONARY_WATER:0)
Block(0,10,8,STATIONARY_WATER:0)
Block(0,11,-7,WOOD:5)
Block(0,11,-6,WOOD:5)
RandomBlock(0,11,-5,SKULL:1,../../../../Skulls/dungeon_skull_01.nbt,6,AIR,9,SKULL:1,../../../../Skulls/dungeon_skull_02.nbt,12,AIR,15,SKULL:1,../../../../Skulls/dungeon_skull_03.nbt,18,AIR,21,SKULL:1,../../../../Skulls/dungeon_skull_04.nbt,24,AIR,27,SKULL:1,../../../../Skulls/dungeon_skull_05.nbt,30,AIR,33,SKULL:1,../../../../Skulls/dungeon_skull_06.nbt,36,AIR,39,SKULL:1,../../../../Skulls/dungeon_skull_07.nbt,42,AIR,45,SKULL:1,../../../../Skulls/dungeon_skull_08.nbt,48,AIR,51,SKULL:1,../../../../Skulls/dungeon_skull_09.nbt,54,AIR,57,SKULL:1,../../../../Skulls/dungeon_skull_10.nbt,60,AIR,63,SKULL:1,../../../../Skulls/dungeon_skull_11.nbt,66,AIR,69,SKULL:1,../../../../Skulls/dungeon_skull_12.nbt,72,AIR,75,SKULL:1,../../../../Skulls/dungeon_skull_13.nbt,78,AIR,81,SKULL:1,../../../../Skulls/dungeon_skull_14.nbt,84,AIR,87,SKULL:1,../../../../Skulls/dungeon_skull_15.nbt,90,AIR,93,SKULL:1,../../../../Skulls/dungeon_skull_16.nbt,96,AIR,100)
Block(0,11,-4,STATIONARY_WATER:0)
Block(0,11,-3,STATIONARY_WATER:0)
Block(0,11,-2,STATIONARY_WATER:0)
Block(0,11,-1,STATIONARY_WATER:0)
Block(0,11,0,STAINED_CLAY:9)
Block(0,11,1,STATIONARY_WATER:0)
Block(0,11,2,STATIONARY_WATER:0)
Block(0,11,3,STATIONARY_WATER:0)
Block(0,11,4,STATIONARY_WATER:0)
Block(0,11,5,STATIONARY_WATER:0)
Block(0,11,6,STATIONARY_WATER:0)
Block(0,11,7,STATIONARY_WATER:0)
Block(0,11,8,STATIONARY_WATER:0)
Block(0,12,-7,WOOD:5)
Block(0,12,-6,WOOD:5)
Block(0,12,-5,STATIONARY_WATER:0)
Block(0,12,-4,STATIONARY_WATER:0)
Block(0,12,-3,STATIONARY_WATER:0)
Block(0,12,-2,STATIONARY_WATER:0)
Block(0,12,-1,STATIONARY_WATER:0)
Block(0,12,0,STAINED_CLAY:9)
Block(0,12,1,STATIONARY_WATER:0)
Block(0,12,2,STATIONARY_WATER:0)
Block(0,12,3,STATIONARY_WATER:0)
Block(0,12,4,STATIONARY_WATER:0)
Block(0,12,5,STATIONARY_WATER:0)
Block(0,12,6,STATIONARY_WATER:0)
Block(0,12,7,STATIONARY_WATER:0)
Block(0,12,8,STATIONARY_WATER:0)
Block(0,13,-7,STAINED_CLAY:9)
Block(0,13,-6,STAINED_CLAY:9)
Block(0,13,-5,STATIONARY_WATER:0)
Block(0,13,-4,WOOD_STEP:13)
Block(0,13,-3,WOOD_STEP:13)
Block(0,13,-2,WOOD_STEP:13)
Block(0,13,-1,WOOD_STEP:13)
Block(0,13,0,WOOD_DOUBLE_STEP:5)
Block(0,13,1,WOOD_STEP:13)
Block(0,13,2,WOOD_STEP:13)
Block(0,13,3,STATIONARY_WATER:0)
Block(0,13,4,STATIONARY_WATER:0)
Block(0,13,5,STATIONARY_WATER:0)
Block(0,13,6,STATIONARY_WATER:0)
Block(0,13,7,STATIONARY_WATER:0)
Block(0,13,8,STATIONARY_WATER:0)
Block(0,14,-4,STAINED_CLAY:9)
Block(0,14,-3,STAINED_CLAY:9)
Block(0,14,-2,STAINED_CLAY:9)
Block(0,14,-1,WOOD_STEP:1)
Block(0,14,0,WOOD:2)
Block(0,14,1,WOOD:2)
Block(0,14,3,WOOD_STEP:5)
Block(0,14,4,WOOD_STEP:5)
Block(0,14,5,WOOD_STEP:5)
Block(0,14,6,WOOD_STEP:5)
Block(0,14,7,WOOD_STEP:1)
Block(0,14,8,WOOD_STEP:1)
Block(0,15,-7,AIR:0)
Block(0,15,-4,STAINED_CLAY:9)
Block(0,16,-4,WOOD_STEP:5)
Block(1,6,2,LOG_2:1)
Block(1,6,3,LOG_2:1)
Block(1,6,4,LOG_2:1)
Block(1,6,5,LOG_2:1)
Block(1,6,6,LOG_2:1)
Block(1,6,7,LOG_2:1)
Block(1,6,8,LOG_2:1)
Block(1,7,-2,LOG_2:1)
Block(1,7,-1,LOG_2:1)
Block(1,7,0,LOG_2:1)
Block(1,7,1,LOG_2:1)
Block(1,7,2,PUMPKIN:3)
Block(1,7,3,MELON_BLOCK:0)
Block(1,7,4,STATIONARY_WATER:0)
Block(1,7,5,STATIONARY_WATER:0)
Block(1,7,6,WOOD:5)
Block(1,7,7,LAPIS_ORE:0)
Block(1,7,8,STATIONARY_WATER:0)
Block(1,8,-3,LOG_2:1)
Block(1,8,-2,STATIONARY_WATER:0)
Block(1,8,-1,STATIONARY_WATER:0)
Block(1,8,0,WOOD:5)
Block(1,8,1,STATIONARY_WATER:0)
Block(1,8,2,STATIONARY_WATER:0)
Block(1,8,3,STATIONARY_WATER:0)
Block(1,8,4,STATIONARY_WATER:0)
Block(1,8,5,STATIONARY_WATER:0)
Block(1,8,6,WOOD:5)
Block(1,8,7,STATIONARY_WATER:0)
Block(1,8,8,STATIONARY_WATER:0)
Block(1,9,-5,LOG_2:1)
Block(1,9,-4,LOG_2:1)
Block(1,9,-3,WOOD:5)
Block(1,9,-2,STATIONARY_WATER:0)
Block(1,9,-1,STATIONARY_WATER:0)
Block(1,9,0,WOOD:5)
Block(1,9,1,STATIONARY_WATER:0)
Block(1,9,2,STATIONARY_WATER:0)
Block(1,9,3,STATIONARY_WATER:0)
Block(1,9,4,STATIONARY_WATER:0)
Block(1,9,5,STATIONARY_WATER:0)
Block(1,9,6,WOOD:5)
Block(1,9,7,STATIONARY_WATER:0)
Block(1,9,8,STATIONARY_WATER:0)
Block(1,10,-5,WOOD:5)
Block(1,10,-4,WOOD:5)
Block(1,10,-3,WOOD:5)
Block(1,10,-2,WOOD:5)
Block(1,10,-1,WOOD:5)
Block(1,10,0,WOOD:5)
Block(1,10,1,WOOD:5)
Block(1,10,2,WOOD:5)
Block(1,10,3,WOOD:5)
Block(1,10,4,WOOD:5)
Block(1,10,5,WOOD:5)
Block(1,10,6,WOOD:5)
Block(1,10,7,WOOD:5)
Block(1,10,8,WOOD:5)
Block(1,11,-6,WOOD:5)
Block(1,11,-5,WOOD:5)
Block(1,11,-4,STATIONARY_WATER:0)
Block(1,11,-3,STATIONARY_WATER:0)
Block(1,11,-2,STATIONARY_WATER:0)
Block(1,11,-1,STATIONARY_WATER:0)
Block(1,11,0,STATIONARY_WATER:0)
Block(1,11,1,STATIONARY_WATER:0)
Block(1,11,2,STATIONARY_WATER:0)
Block(1,11,3,STATIONARY_WATER:0)
Block(1,11,4,STATIONARY_WATER:0)
Block(1,11,5,WOOD:2)
Block(1,11,6,WOOD:2)
Block(1,11,7,WOOD:2)
Block(1,11,8,STATIONARY_WATER:0)
Block(1,12,-7,WOOD:5)
Block(1,12,-6,WOOD:5)
Block(1,12,-5,WOOD:5)
Block(1,12,-4,STATIONARY_WATER:0)
Block(1,12,-3,STATIONARY_WATER:0)
Block(1,12,-2,AIR:0)
Block(1,12,-1,STATIONARY_WATER:0)
Block(1,12,0,STATIONARY_WATER:0)
Block(1,12,1,STATIONARY_WATER:0)
Block(1,12,2,STATIONARY_WATER:0)
Block(1,12,3,STATIONARY_WATER:0)
Block(1,12,4,STATIONARY_WATER:0)
Block(1,12,5,STATIONARY_WATER:0)
Block(1,12,6,STATIONARY_WATER:0)
Block(1,12,7,STATIONARY_WATER:0)
Block(1,12,8,STATIONARY_WATER:0)
Block(1,13,-7,STAINED_CLAY:9)
Block(1,13,-6,STAINED_CLAY:9)
Block(1,13,-5,STAINED_CLAY:9)
Block(1,13,-4,WOOD_STEP:13)
Block(1,13,-3,WOOD_STEP:13)
Block(1,13,-2,WOOD_STEP:13)
Block(1,13,-1,WOOD_STEP:13)
Block(1,13,0,WOOD_DOUBLE_STEP:5)
Block(1,13,1,WOOD_STEP:13)
Block(1,13,2,WOOD_STEP:13)
Block(1,13,3,WOOD_STEP:13)
Block(1,13,4,WOOD_STEP:13)
Block(1,13,5,WOOD_STEP:13)
Block(1,13,6,WOOD_STEP:13)
Block(1,13,7,WOOD_STEP:13)
Block(1,13,8,WOOD_STEP:13)
Block(1,14,-4,STAINED_CLAY:9)
Block(1,14,-3,STAINED_CLAY:9)
Block(1,14,-2,STAINED_CLAY:9)
Block(1,14,-1,WOOD_STEP:1)
Block(1,14,1,WOOD:2)
Block(1,14,3,WOOD_STEP:5)
Block(1,14,4,WOOD_STEP:5)
Block(1,14,5,WOOD_STEP:5)
Block(1,14,6,WOOD_STEP:5)
Block(1,15,-4,STAINED_CLAY:9)
Block(1,15,-3,SPRUCE_WOOD_STAIRS:3)
Block(1,20,-1,AIR:0)
Block(2,6,6,LOG_2:1)
Block(2,6,7,LOG_2:1)
Block(2,6,8,LOG_2:1)
Block(2,7,0,LOG_2:1)
Block(2,7,1,LOG_2:1)
Block(2,7,2,LOG_2:1)
Block(2,7,3,LOG_2:1)
Block(2,7,4,LOG_2:1)
Block(2,7,5,LOG_2:1)
Block(2,7,6,WOOD:5)
Block(2,7,7,GOLD_ORE:0)
Block(2,7,8,IRON_ORE:0)
Block(2,8,-2,LOG_2:1)
Block(2,8,-1,LOG_2:1)
Block(2,8,0,WOOD:5)
Block(2,8,1,HAY_BLOCK:4)
Block(2,8,2,HAY_BLOCK:8)
Block(2,8,3,STATIONARY_WATER:0)
Block(2,8,4,STATIONARY_WATER:0)
Block(2,8,5,STATIONARY_WATER:0)
Block(2,8,6,WOOD:5)
Block(2,8,7,LAPIS_ORE:0)
Block(2,8,8,STATIONARY_WATER:0)
Block(2,9,-4,LOG_2:1)
Block(2,9,-3,LOG_2:1)
Block(2,9,-2,WOOD:5)
Block(2,9,-1,WOOD:5)
Block(2,9,0,WOOD:5)
Block(2,9,1,STATIONARY_WATER:0)
Block(2,9,2,STATIONARY_WATER:0)
Block(2,9,3,STATIONARY_WATER:0)
Block(2,9,4,STATIONARY_WATER:0)
Block(2,9,5,STATIONARY_WATER:0)
Block(2,9,6,WOOD:5)
Block(2,9,7,STATIONARY_WATER:0)
Block(2,9,8,STATIONARY_WATER:0)
Block(2,10,-5,WOOD:5)
Block(2,10,-4,WOOD:5)
Block(2,10,-3,WOOD:5)
Block(2,10,-2,WOOD:5)
Block(2,10,-1,WOOD:5)
Block(2,10,0,WOOD:5)
Block(2,10,1,WOOD:5)
Block(2,10,2,WOOD:5)
Block(2,10,3,WOOD:5)
Block(2,10,4,WOOD:5)
Block(2,10,5,WOOD:5)
Block(2,10,6,WOOD:5)
Block(2,10,7,WOOD:5)
Block(2,10,8,WOOD:5)
Block(2,11,-5,WOOD:5)
Block(2,11,-4,WOOD:5)
Block(2,11,-3,STATIONARY_WATER:0)
Block(2,11,-2,STATIONARY_WATER:0)
Block(2,11,-1,STATIONARY_WATER:0)
Block(2,11,0,STAINED_CLAY:9)
Block(2,11,1,STATIONARY_WATER:0)
Block(2,11,2,STATIONARY_WATER:0)
Block(2,11,3,STATIONARY_WATER:0)
Block(2,11,4,STATIONARY_WATER:0)
Block(2,11,5,STATIONARY_WATER:0)
Block(2,11,6,STATIONARY_WATER:0)
Block(2,11,7,STATIONARY_WATER:0)
Block(2,11,8,STATIONARY_WATER:0)
Block(2,12,-5,WOOD:5)
Block(2,12,-4,WOOD:5)
Block(2,12,-3,STATIONARY_WATER:0)
Block(2,12,-2,STATIONARY_WATER:0)
Block(2,12,-1,STATIONARY_WATER:0)
Block(2,12,0,STAINED_CLAY:9)
Block(2,12,1,STATIONARY_WATER:0)
Block(2,12,2,STATIONARY_WATER:0)
Block(2,12,3,STATIONARY_WATER:0)
Block(2,12,4,STATIONARY_WATER:0)
Block(2,12,5,STATIONARY_WATER:0)
Block(2,12,6,STATIONARY_WATER:0)
Block(2,12,7,STATIONARY_WATER:0)
Block(2,12,8,STATIONARY_WATER:0)
Block(2,13,-6,STAINED_CLAY:9)
Block(2,13,-5,STAINED_CLAY:9)
Block(2,13,-4,STAINED_CLAY:9)
Block(2,13,-3,WOOD_STEP:13)
Block(2,13,-2,WOOD_STEP:13)
Block(2,13,-1,WOOD_STEP:13)
Block(2,13,0,WOOD_DOUBLE_STEP:5)
Block(2,13,1,WOOD_STEP:13)
Block(2,13,2,WOOD_STEP:13)
Block(2,13,3,WOOD_STEP:13)
Block(2,13,4,WOOD_STEP:13)
Block(2,13,5,WOOD_STEP:13)
Block(2,13,6,WOOD_STEP:13)
Block(2,13,7,WOOD_STEP:13)
Block(2,13,8,WOOD_STEP:13)
Block(2,14,-7,WOOD_STEP:5)
Block(2,14,-6,WOOD_STEP:5)
Block(2,14,-5,WOOD_STEP:13)
Block(2,14,-4,STAINED_CLAY:9)
Block(2,14,-3,STAINED_CLAY:9)
Block(2,14,-2,STAINED_CLAY:9)
Block(2,14,-1,WOOD_STEP:1)
Block(2,14,6,WOOD:2)
Block(2,14,7,WOOD:2)
Block(2,14,8,WOOD:2)
Block(2,15,-7,WOOD_STEP:5)
Block(2,15,-6,WOOD_STEP:13)
Block(2,15,-5,DARK_OAK_STAIRS:6)
Block(2,15,-4,STAINED_CLAY:9)
RandomBlock(2,15,-3,AIR:0,20,CHEST:3,../../../../Chests/Loot/PirateJunk_1.nbt,10,CHEST:3,../../../../Chests/Loot/PirateJunk_2.nbt,10,CHEST:3,../../../../Chests/Loot/PirateJunk_3.nbt,10,CHEST:3,../../../../Chests/Loot/PirateJunk_4.nbt,10,CHEST:3,../../../../Chests/Loot/PirateJunk_5.nbt,10,CHEST:3,../../../../Chests/Traveler/Travelers_Castle.nbt,1,CHEST:3,../../../../Chests/Traveler/Travelers_Church.nbt,1,CHEST:3,../../../../Chests/Traveler/Travelers_Daeroc.nbt,1,CHEST:3,../../../../Chests/Traveler/Travelers_Farmsteads.nbt,1,CHEST:3,../../../../Chests/Traveler/Travelers_GreenDungeon.nbt,1,CHEST:3,../../../../Chests/Traveler/Travelers_IceShips.nbt,1,CHEST:3,../../../../Chests/Traveler/Travelers_IceTemple.nbt,1,CHEST:3,../../../../Chests/Traveler/Travelers_LegacySpawn.nbt,1,CHEST:3,../../../../Chests/Traveler/Travelers_Mineshafts.nbt,1,CHEST:3,../../../../Chests/Traveler/Travelers_Mountains.nbt,1,CHEST:3,../../../../Chests/Traveler/Travelers_Origin.nbt,1,CHEST:3,../../../../Chests/Traveler/Travelers_Pirate.nbt,1,CHEST:3,../../../../Chests/Traveler/Travelers_Quarry.nbt,1,CHEST:3,../../../../Chests/Traveler/Travelers_Spook.nbt,1,CHEST:3,../../../../Chests/Traveler/Travelers_Tribal.nbt,1,CHEST:3,../../../../Chests/Lore/ShipSunk_1.nbt,1,CHEST:3,../../../../Chests/Lore/ShipSunk_2.nbt,1,CHEST:3,../../../../Chests/Lore/ShipSunk_3.nbt,1,CHEST:3,../../../../Chests/Lore/ShipSunk_4.nbt,1,CHEST:3,../../../../Chests/Lore/ShipSunk_5.nbt,1,CHEST:3,../../../../Chests/Loot/Common1.nbt,10,CHEST:3,../../../../Chests/Loot/Common2.nbt,10,CHEST:3,../../../../Chests/Loot/Common3.nbt,10,CHEST:3,../../../../Chests/Loot/Common4.nbt,10,CHEST:3,../../../../Chests/Loot/Common5.nbt,10,CHEST:3,../../../../Chests/Loot/Common6.nbt,10,CHEST:3,../../../../Chests/Loot/Common7.nbt,10,CHEST:3,../../../../Chests/Loot/Common8.nbt,10,CHEST:3,../../../../Chests/Loot/Common9.nbt,10,CHEST:3,../../../../Chests/Loot/Common10.nbt,10,CHEST:3,../../../../Chests/Loot/Common10.nbt,11,CHEST:3,../../../../Chests/Loot/Common12.nbt,10,CHEST:3,../../../../Chests/Loot/Common13.nbt,10,CHEST:3,../../../../Chests/Loot/Common14.nbt,10,CHEST:3,../../../../Chests/Loot/Common15.nbt,10,CHEST:3,../../../../Chests/Lore/ShipSunk_1.nbt,2,CHEST:3,../../../../Chests/Lore/ShipSunk_3.nbt,2,CHEST:3,../../../../Chests/Lore/ShipSunk_4.nbt,2,CHEST:3,../../../../Chests/Lore/ShipSunk_5.nbt,2,CHEST:3,../../../../Chests/Lore/ShipSunk_5.nbt,2,CHEST:3,../../../../Chests/Loot/Rare1.nbt,5,CHEST:3,../../../../Chests/Loot/Rare2.nbt,5,CHEST:3,../../../../Chests/Loot/Rare3.nbt,5,CHEST:3,../../../../Chests/Loot/Rare4.nbt,5,CHEST:3,../../../../Chests/Loot/Rare5.nbt,5,CHEST:3,../../../../Chests/Loot/Rare6.nbt,5,CHEST:3,../../../../Chests/Loot/Rare7.nbt,5,CHEST:3,../../../../Chests/Loot/Rare8.nbt,5,CHEST:3,../../../../Chests/Loot/Rare9.nbt,5,CHEST:3,../../../../Chests/Loot/Rare10.nbt,5,CHEST:3,../../../../Chests/Loot/Rare11.nbt,5,CHEST:3,../../../../Chests/Loot/Rare12.nbt,5,CHEST:3,../../../../Chests/Loot/Rare13.nbt,5,CHEST:3,../../../../Chests/Loot/Rare14.nbt,5,CHEST:3,../../../../Chests/Loot/Rare15.nbt,5,CHEST:3,../../../../Chests/Loot/Epic1.nbt,2,CHEST:3,../../../../Chests/Loot/Epic2.nbt,2,CHEST:3,../../../../Chests/Loot/Epic3.nbt,2,CHEST:3,../../../../Chests/Loot/Epic4.nbt,2,CHEST:3,../../../../Chests/Loot/Epic5.nbt,2,CHEST:3,../../../../Chests/Loot/Epic6.nbt,2,CHEST:3,../../../../Chests/Loot/Epic7.nbt,2,CHEST:3,../../../../Chests/Loot/Epic8.nbt,2,CHEST:3,../../../../Chests/Loot/Epic9.nbt,2,CHEST:3,../../../../Chests/Loot/Epic10.nbt,2,CHEST:3,../../../../Chests/Loot/Epic11.nbt,2,CHEST:3,../../../../Chests/Loot/Epic12.nbt,2,CHEST:3,../../../../Chests/Loot/Epic13.nbt,2,CHEST:3,../../../../Chests/Loot/Epic14.nbt,2,CHEST:3,../../../../Chests/Loot/Epic15.nbt,5,CHEST:3,../../../../Chests/Loot/Rare1.nbt,5,CHEST:3,../../../../Chests/Loot/Rare2.nbt,5,CHEST:3,../../../../Chests/Loot/Rare3.nbt,5,CHEST:3,../../../../Chests/Loot/Rare4.nbt,5,CHEST:3,../../../../Chests/Loot/Rare5.nbt,10,CHEST:3,../../../../Chests/Loot/Rare6.nbt,10,CHEST:3,../../../../Chests/Loot/Rare7.nbt,10,CHEST:3,../../../../Chests/Loot/Rare8.nbt,10,CHEST:3,../../../../Chests/Loot/Rare9.nbt,10,CHEST:3,../../../../Chests/Loot/Rare10.nbt,15,CHEST:3,../../../../Chests/Loot/Rare11.nbt,15,CHEST:3,../../../../Chests/Loot/Rare12.nbt,15,CHEST:3,../../../../Chests/Loot/Rare13.nbt,15,CHEST:3,../../../../Chests/Loot/Rare14.nbt,15,CHEST:3,../../../../Chests/Loot/Rare15.nbt,15,CHEST:3,../../../../Chests/Loot/Epic15.nbt,100)
Block(2,16,-4,WOOD_STEP:5)
Block(2,16,7,AIR:0)
Block(3,7,2,LOG_2:1)
Block(3,7,3,LOG_2:1)
Block(3,7,4,LOG_2:1)
Block(3,7,5,LOG_2:1)
Block(3,7,6,LOG_2:1)
Block(3,7,7,LOG_2:1)
Block(3,7,8,LOG_2:1)
Block(3,8,-1,LOG_2:1)
Block(3,8,0,LOG_2:1)
Block(3,8,1,LOG_2:1)
Block(3,8,2,PUMPKIN:1)
Block(3,8,3,MELON_BLOCK:0)
Block(3,8,4,STATIONARY_WATER:0)
Block(3,8,5,HAY_BLOCK:0)
Block(3,8,6,WOOD:5)
Block(3,8,7,REDSTONE_ORE:0)
Block(3,8,8,REDSTONE_ORE:0)
Block(3,9,-3,LOG_2:1)
Block(3,9,-2,LOG_2:1)
Block(3,9,-1,WOOD:5)
Block(3,9,0,WOOD:5)
Block(3,9,1,PUMPKIN:1)
Block(3,9,2,STATIONARY_WATER:0)
Block(3,9,3,STATIONARY_WATER:0)
Block(3,9,4,STATIONARY_WATER:0)
Block(3,9,5,STATIONARY_WATER:0)
Block(3,9,6,WOOD:5)
Block(3,9,7,REDSTONE_ORE:0)
Block(3,9,8,STATIONARY_WATER:0)
Block(3,10,-3,WOOD:5)
Block(3,10,-2,WOOD:5)
Block(3,10,-1,WOOD:5)
Block(3,10,0,WOOD:5)
Block(3,10,1,WOOD:5)
Block(3,10,2,WOOD:5)
Block(3,10,3,WOOD:5)
Block(3,10,4,WOOD:5)
Block(3,10,5,WOOD:5)
Block(3,10,6,WOOD:5)
Block(3,10,7,WOOD:5)
Block(3,10,8,WOOD:5)
Block(3,11,-4,WOOD:5)
Block(3,11,-3,WOOD:5)
Block(3,11,-2,STATIONARY_WATER:0)
Block(3,11,-1,STATIONARY_WATER:0)
Block(3,11,0,STAINED_CLAY:9)
Block(3,11,1,STATIONARY_WATER:0)
Block(3,11,2,DARK_OAK_STAIRS:0)
Block(3,11,3,STATIONARY_WATER:0)
Block(3,11,4,STATIONARY_WATER:0)
Block(3,11,5,STATIONARY_WATER:0)
Block(3,11,6,STATIONARY_WATER:0)
Block(3,11,7,STATIONARY_WATER:0)
Block(3,11,8,STATIONARY_WATER:0)
Block(3,12,-4,WOOD:5)
Block(3,12,-3,WOOD:5)
Block(3,12,-2,STATIONARY_WATER:0)
Block(3,12,-1,STATIONARY_WATER:0)
Block(3,12,0,STAINED_CLAY:9)
Block(3,12,1,STATIONARY_WATER:0)
Block(3,12,2,STATIONARY_WATER:0)
Block(3,12,3,STATIONARY_WATER:0)
Block(3,12,4,STATIONARY_WATER:0)
Block(3,12,5,STATIONARY_WATER:0)
Block(3,12,6,STATIONARY_WATER:0)
Block(3,12,7,STATIONARY_WATER:0)
Block(3,12,8,STATIONARY_WATER:0)
Block(3,13,-3,STAINED_CLAY:9)
Block(3,13,-2,WOOD_STEP:13)
Block(3,13,-1,WOOD_STEP:13)
Block(3,13,0,WOOD_DOUBLE_STEP:5)
Block(3,13,1,WOOD_STEP:13)
Block(3,13,2,WOOD_STEP:13)
Block(3,13,3,WOOD_STEP:13)
Block(3,13,4,WOOD_STEP:13)
Block(3,13,5,WOOD_STEP:13)
Block(3,13,6,WOOD_STEP:13)
Block(3,13,7,WOOD_STEP:13)
Block(3,13,8,WOOD_STEP:13)
Block(3,14,-3,STAINED_CLAY:9)
Block(3,14,-2,STAINED_CLAY:9)
Block(3,14,-1,WOOD_STEP:1)
Block(3,14,3,SPRUCE_WOOD_STAIRS:0)
Block(3,14,7,SPRUCE_WOOD_STAIRS:0)
Block(3,15,-3,STAINED_CLAY:9)
Block(3,15,-2,STAINED_CLAY:9)
Block(3,16,-3,WOOD_STEP:5)
Block(3,16,-2,WOOD_STEP:5)
Block(4,7,5,LOG_2:1)
Block(4,7,6,LOG_2:1)
Block(4,7,7,LOG_2:1)
Block(4,7,8,LOG_2:1)
Block(4,8,1,LOG_2:1)
Block(4,8,2,LOG_2:1)
Block(4,8,3,LOG_2:1)
Block(4,8,4,LOG_2:1)
Block(4,8,5,MELON_BLOCK:0)
Block(4,8,6,WOOD:5)
Block(4,8,7,REDSTONE_ORE:0)
Block(4,8,8,IRON_ORE:0)
Block(4,9,-1,LOG_2:1)
Block(4,9,0,LOG_2:1)
Block(4,9,1,LOG_2:1)
Block(4,9,2,PUMPKIN:1)
Block(4,9,3,MELON_BLOCK:0)
Block(4,9,4,STATIONARY_WATER:0)
Block(4,9,5,STATIONARY_WATER:0)
Block(4,9,6,WOOD:5)
Block(4,9,7,LAPIS_ORE:0)
Block(4,9,8,LAPIS_ORE:0)
Block(4,10,-2,WOOD:5)
Block(4,10,-1,WOOD:5)
Block(4,10,0,WOOD:5)
Block(4,10,1,WOOD:5)
Block(4,10,2,WOOD:5)
Block(4,10,3,WOOD:5)
Block(4,10,4,WOOD:5)
Block(4,10,5,WOOD:5)
Block(4,10,6,WOOD:5)
Block(4,10,7,WOOD:5)
Block(4,10,8,WOOD:5)
Block(4,11,-2,WOOD:5)
Block(4,11,-1,WOOD:5)
Block(4,11,0,STAINED_CLAY:9)
Block(4,11,1,STATIONARY_WATER:0)
Block(4,11,2,CONCRETE:15)
RandomBlock(4,11,3,SKULL:1,../../../../Skulls/dungeon_skull_01.nbt,6,AIR,9,SKULL:1,../../../../Skulls/dungeon_skull_02.nbt,12,AIR,15,SKULL:1,../../../../Skulls/dungeon_skull_03.nbt,18,AIR,21,SKULL:1,../../../../Skulls/dungeon_skull_04.nbt,24,AIR,27,SKULL:1,../../../../Skulls/dungeon_skull_05.nbt,30,AIR,33,SKULL:1,../../../../Skulls/dungeon_skull_06.nbt,36,AIR,39,SKULL:1,../../../../Skulls/dungeon_skull_07.nbt,42,AIR,45,SKULL:1,../../../../Skulls/dungeon_skull_08.nbt,48,AIR,51,SKULL:1,../../../../Skulls/dungeon_skull_09.nbt,54,AIR,57,SKULL:1,../../../../Skulls/dungeon_skull_10.nbt,60,AIR,63,SKULL:1,../../../../Skulls/dungeon_skull_11.nbt,66,AIR,69,SKULL:1,../../../../Skulls/dungeon_skull_12.nbt,72,AIR,75,SKULL:1,../../../../Skulls/dungeon_skull_13.nbt,78,AIR,81,SKULL:1,../../../../Skulls/dungeon_skull_14.nbt,84,AIR,87,SKULL:1,../../../../Skulls/dungeon_skull_15.nbt,90,AIR,93,SKULL:1,../../../../Skulls/dungeon_skull_16.nbt,96,AIR,100)
Block(4,11,4,STATIONARY_WATER:0)
Block(4,11,5,DARK_OAK_STAIRS:0)
Block(4,11,6,STATIONARY_WATER:0)
Block(4,11,7,STATIONARY_WATER:0)
Block(4,11,8,DARK_OAK_STAIRS:0)
Block(4,12,-2,WOOD:5)
Block(4,12,-1,WOOD:5)
Block(4,12,0,STAINED_CLAY:9)
Block(4,12,1,WOOD_STEP:5)
Block(4,12,2,STATIONARY_WATER:0)
Block(4,12,3,WOOD_STEP:5)
Block(4,12,4,STATIONARY_WATER:0)
Block(4,12,5,STATIONARY_WATER:0)
Block(4,12,6,STATIONARY_WATER:0)
Block(4,12,7,STATIONARY_WATER:0)
Block(4,12,8,STATIONARY_WATER:0)
Block(4,13,-2,STAINED_CLAY:9)
Block(4,13,-1,STAINED_CLAY:9)
Block(4,13,0,STAINED_CLAY:9)
Block(4,13,1,WOOD_STEP:13)
Block(4,13,2,WOOD_STEP:13)
Block(4,13,3,WOOD_STEP:13)
Block(4,13,4,WOOD_STEP:13)
Block(4,13,5,WOOD_STEP:13)
Block(4,13,6,WOOD_STEP:13)
Block(4,13,7,WOOD_STEP:13)
Block(4,13,8,WOOD_STEP:13)
Block(4,14,-1,STAINED_CLAY:9)
Block(4,14,0,STAINED_CLAY:9)
Block(4,14,3,DISPENSER:1)
Block(4,14,7,DISPENSER:1)
Block(4,15,-1,WOOD_STEP:5)
Block(4,15,0,WOOD_STEP:5)
Block(5,8,5,LOG_2:1)
Block(5,8,6,LOG_2:1)
Block(5,8,7,LOG_2:1)
Block(5,8,8,LOG_2:1)
Block(5,9,2,LOG_2:1)
Block(5,9,3,LOG_2:1)
Block(5,9,4,LOG_2:1)
Block(5,9,5,LOG_2:1)
Block(5,9,6,LOG_2:1)
Block(5,9,7,LOG_2:1)
Block(5,9,8,LOG_2:1)
Block(5,10,1,WOOD:5)
Block(5,10,2,WOOD:5)
Block(5,10,3,WOOD:5)
Block(5,10,4,WOOD:5)
Block(5,10,5,WOOD:5)
Block(5,10,6,WOOD:5)
Block(5,10,7,WOOD:5)
Block(5,10,8,WOOD:5)
Block(5,11,0,WOOD:5)
Block(5,11,1,WOOD:5)
Block(5,11,2,DISPENSER:5)
Block(5,11,3,WOOD:5)
Block(5,11,4,STATIONARY_WATER:0)
Block(5,11,5,CONCRETE:15)
Block(5,11,6,STATIONARY_WATER:0)
Block(5,11,7,STATIONARY_WATER:0)
Block(5,11,8,CONCRETE:15)
Block(5,12,0,WOOD:5)
Block(5,12,1,WOOD:5)
Block(5,12,2,WOOD:5)
Block(5,12,3,WOOD:5)
Block(5,12,4,WOOD_STEP:5)
Block(5,12,5,STATIONARY_WATER:0)
Block(5,12,6,WOOD_STEP:5)
Block(5,12,7,WOOD_STEP:5)
Block(5,12,8,STATIONARY_WATER:0)
Block(5,13,-1,DARK_OAK_STAIRS:5)
Block(5,13,0,WOOD_STEP:13)
Block(5,13,1,STAINED_CLAY:9)
Block(5,13,2,STAINED_CLAY:9)
Block(5,13,3,STAINED_CLAY:9)
Block(5,13,4,STAINED_CLAY:9)
Block(5,13,5,WOOD_STEP:13)
Block(5,13,6,WOOD_STEP:13)
Block(5,13,7,WOOD_STEP:13)
Block(5,13,8,WOOD_STEP:13)
Block(5,14,1,STAINED_CLAY:9)
Block(5,14,2,STAINED_CLAY:9)
Block(5,14,3,CONCRETE:15)
Block(5,14,4,STAINED_CLAY:9)
Block(5,14,5,STAINED_CLAY:9)
Block(5,14,7,CONCRETE:15)
Block(5,15,4,WOOD_STEP:5)
Block(5,15,5,WOOD_STEP:5)
Block(6,10,5,WOOD:5)
Block(6,10,6,WOOD:5)
Block(6,10,7,WOOD:5)
Block(6,10,8,WOOD:5)
Block(6,11,4,WOOD:5)
Block(6,11,5,DISPENSER:5)
Block(6,11,6,WOOD:5)
Block(6,11,7,WOOD:5)
Block(6,11,8,DISPENSER:5)
Block(6,12,4,WOOD:5)
Block(6,12,5,WOOD:5)
Block(6,12,6,WOOD:5)
Block(6,12,7,WOOD:5)
Block(6,12,8,WOOD:5)
Block(6,13,1,WOOD_STEP:13)
Block(6,13,2,DARK_OAK_STAIRS:5)
Block(6,13,5,STAINED_CLAY:9)
Block(6,13,6,STAINED_CLAY:9)
Block(6,13,7,STAINED_CLAY:9)
Block(6,13,8,STAINED_CLAY:9)
Block(6,14,3,DISPENSER:5)
Block(6,14,6,STAINED_CLAY:9)
Block(6,14,7,DISPENSER:5)
Block(6,14,8,STAINED_CLAY:9)
Block(6,15,6,WOOD_STEP:5)
Block(6,15,8,WOOD_STEP:5)
Block(7,10,5,WOOD:5)
Block(7,10,6,WOOD:5)
Block(7,10,7,WOOD:5)
Block(7,10,8,WOOD:5)
Block(7,11,4,WOOD:5)
Block(7,11,5,DISPENSER:5)
Block(7,11,6,WOOD:5)
Block(7,11,7,WOOD:5)
Block(7,11,8,DISPENSER:5)
Block(7,12,4,WOOD:5)
Block(7,12,5,WOOD:5)
Block(7,12,6,WOOD:5)
Block(7,12,7,WOOD:5)
Block(7,12,8,WOOD:5)
Block(7,13,1,WOOD_STEP:13)
Block(7,13,2,DARK_OAK_STAIRS:5)
Block(7,13,5,STAINED_CLAY:9)
Block(7,13,6,STAINED_CLAY:9)
Block(7,13,7,STAINED_CLAY:9)
Block(7,13,8,STAINED_CLAY:9)
Block(7,14,3,DISPENSER:5)
Block(7,14,6,STAINED_CLAY:9)
Block(7,14,7,DISPENSER:5)
Block(7,14,8,STAINED_CLAY:9)
Block(7,15,6,WOOD_STEP:5)
Block(7,15,8,WOOD_STEP:5)
Block(-4,15,1,WATER:0)
Block(-1,12,6,WATER:0)
Block(0,15,-7,WATER:0)
Block(1,12,-2,WATER:0)
Block(1,20,-1,WATER:0)
Block(2,16,7,WATER:0)
Branch(0,0,16,true,pillager_degradedC0R2,NORTH,100.0,0)
WBR(0,16,0,true,pillager_degraded_mast_1,NORTH,10.0,0,pillager_degraded_mast_2,NORTH,10.0,0,pillager_degraded_mast_none,NORTH,10.0,0,30.0)
Entity(-4,15,1,minecraft:guardian,1)
Entity(-1,12,6,minecraft:guardian,1)
Entity(0,15,-7,minecraft:guardian,1)
Entity(1,12,-2,minecraft:guardian,1)
Entity(1,20,-1,minecraft:guardian,1)
Entity(2,16,7,minecraft:guardian,1)
