Author: NLBlackEagle
Description: No description given
SettingsMode: WriteDisable
Frequency: 0
SpawnHeight: highestBlock
UseCenterForHighestBlock: true
MinHeight: 0
MaxHeight: 255
InheritBO3: 
InheritBO3Rotation: NORTH
OverrideChildSettings: true
OverrideParentHeight: false
CanOverride: false
BranchFrequency: 0
BranchFrequencyGroup: 
MustBeBelowOther: false
MustBeInside: 
CannotBeInside: 
ReplacesBO3: 
MustBeInsideWorldBorders: false
CanSpawnOnWater: true
SpawnOnWaterOnly: false
SpawnUnderWater: false
SpawnAtWaterLevel: false
HeightOffset: 0
RemoveAir: true
ReplaceAbove: 
ReplaceBelow: 
ReplaceWithBiomeBlocks: true
ReplaceWithSurfaceBlock: GRASS
ReplaceWithGroundBlock: DIRT
ReplaceWithStoneBlock: STONE
SmoothRadius: 0
SmoothHeightOffset: 0
SmoothStartTop: false
SmoothStartWood: false
SmoothingSurfaceBlock: 
SmoothingGroundBlock: 
BO3Group: 
IsSpawnPoint: false
DoReplaceBlocks: true
Block(-8,0,-7,STONE:0)
Block(-8,0,-6,STONE:0)
Block(-8,0,-5,STONE:0)
Block(-8,0,-4,STONE:0)
Block(-8,0,-3,STONE:0)
Block(-8,0,-2,STONE:0)
Block(-8,0,-1,STONE:0)
Block(-8,0,0,STONE:0)
Block(-8,0,1,STONE:0)
Block(-8,0,2,STONE:0)
Block(-8,0,3,STONE:0)
Block(-8,0,4,STONE:0)
Block(-8,0,5,STONE:0)
Block(-8,0,6,STONE:0)
Block(-8,0,7,STONE:0)
Block(-8,0,8,STONE:0)
Block(-8,1,-7,STONE:0)
Block(-8,1,-6,STONE:0)
Block(-8,1,-5,STONE:0)
Block(-8,1,-4,STONE:0)
Block(-8,1,-3,STONE:0)
Block(-8,1,-2,STONE:0)
Block(-8,1,-1,STONE:0)
Block(-8,1,0,STONE:0)
Block(-8,1,1,STONE:0)
Block(-8,1,2,STONE:0)
Block(-8,1,3,STONE:0)
Block(-8,1,4,STONE:0)
Block(-8,1,5,STONE:0)
Block(-8,1,6,STONE:0)
Block(-8,1,7,STONE:0)
Block(-8,1,8,STONE:0)
Block(-8,2,-7,STONE:0)
Block(-8,2,-6,STONE:0)
Block(-8,2,-5,STONE:0)
Block(-8,2,-4,STONE:0)
Block(-8,2,-3,STONE:0)
Block(-8,2,-2,STONE:0)
Block(-8,2,-1,STONE:0)
Block(-8,2,0,STONE:0)
Block(-8,2,1,STONE:0)
Block(-8,2,2,STONE:0)
Block(-8,2,3,STONE:0)
Block(-8,2,4,STONE:0)
Block(-8,2,5,STONE:0)
Block(-8,2,6,STONE:0)
Block(-8,2,7,STONE:0)
Block(-8,2,8,STONE:0)
Block(-8,3,-7,GRASS:0)
Block(-8,3,-6,GRASS:0)
Block(-8,3,-5,GRASS:0)
Block(-8,3,-4,DIRT:0)
Block(-8,3,-3,STONE:0)
Block(-8,3,-2,STONE:0)
Block(-8,3,-1,STONE:0)
Block(-8,3,0,STONE:0)
Block(-8,3,1,STONE:0)
Block(-8,3,2,STONE:0)
Block(-8,3,3,STONE:0)
Block(-8,3,4,STONE:0)
Block(-8,3,5,STONE:0)
Block(-8,3,6,STONE:0)
Block(-8,3,7,STONE:0)
Block(-8,3,8,STONE:0)
Block(-8,4,-6,LONG_GRASS:1)
Block(-8,4,-5,LONG_GRASS:1)
Block(-8,4,-4,SMOOTH_BRICK:0)
Block(-8,4,-3,COBBLESTONE:0)
Block(-8,4,-2,DIRT:0)
Block(-8,4,-1,GRASS:0)
Block(-8,4,0,GRASS:0)
Block(-8,4,1,GRASS:0)
Block(-8,4,2,GRASS:0)
Block(-8,4,3,GRASS:0)
Block(-8,4,4,GRASS:0)
Block(-8,4,5,STONE:0)
Block(-8,4,6,STONE:0)
Block(-8,4,7,STONE:0)
Block(-8,4,8,STONE:0)
Block(-8,5,-5,VINE:1)
Block(-8,5,-4,SMOOTH_STAIRS:0)
Block(-8,5,-3,COBBLESTONE:0)
Block(-8,5,-2,SMOOTH_BRICK:0)
Block(-8,5,-1,LEAVES:4)
Block(-8,5,0,LEAVES:4)
Block(-8,5,2,LONG_GRASS:1)
Block(-8,5,3,LONG_GRASS:1)
Block(-8,5,4,LONG_GRASS:1)
Block(-8,5,5,GRASS:0)
Block(-8,5,6,GRASS:0)
Block(-8,5,7,GRASS:0)
Block(-8,5,8,DIRT:0)
Block(-8,6,-5,VINE:1)
Block(-8,6,-4,SMOOTH_STAIRS:6)
Block(-8,6,-3,MOSSY_COBBLESTONE:0)
Block(-8,6,-2,SMOOTH_BRICK:2)
Block(-8,6,-1,LEAVES:4)
Block(-8,6,5,VINE:9)
Block(-8,6,6,VINE:12)
Block(-8,6,7,LONG_GRASS:1)
Block(-8,6,8,SMOOTH_BRICK:0)
Block(-8,7,-5,VINE:1)
Block(-8,7,-4,SMOOTH_BRICK:2)
Block(-8,7,-3,MOSSY_COBBLESTONE:0)
Block(-8,7,-2,SMOOTH_STAIRS:0)
Block(-8,7,5,VINE:9)
Block(-8,7,6,VINE:12)
Block(-8,7,8,SMOOTH_BRICK:1)
Block(-8,8,-5,VINE:1)
Block(-8,8,-4,SMOOTH_BRICK:2)
Block(-8,8,-3,COBBLESTONE_STAIRS:2)
Block(-8,8,-2,SMOOTH_STAIRS:7)
Block(-8,8,5,VINE:9)
Block(-8,8,6,VINE:12)
Block(-8,8,8,SMOOTH_STAIRS:0)
Block(-8,9,-5,VINE:1)
Block(-8,9,-4,SMOOTH_BRICK:2)
Block(-8,9,-2,SMOOTH_STAIRS:0)
Block(-8,9,5,VINE:9)
Block(-8,9,6,VINE:12)
Block(-8,10,-5,VINE:1)
Block(-8,10,-4,SMOOTH_STAIRS:2)
Block(-8,10,-3,COBBLESTONE_STAIRS:4)
Block(-8,10,-2,SMOOTH_STAIRS:4)
Block(-8,10,5,VINE:9)
Block(-8,10,6,VINE:12)
Block(-8,11,-5,VINE:1)
Block(-8,11,-4,SMOOTH_STAIRS:6)
Block(-8,11,-3,COBBLESTONE:0)
Block(-8,11,5,VINE:9)
Block(-8,11,6,VINE:12)
Block(-8,12,-5,VINE:1)
Block(-8,12,-4,SMOOTH_STAIRS:0)
Block(-8,12,-3,COBBLESTONE:0)
Block(-8,12,-2,SMOOTH_STAIRS:7)
Block(-8,12,5,VINE:9)
Block(-8,12,6,VINE:12)
Block(-8,13,-5,VINE:1)
Block(-8,13,-4,SMOOTH_BRICK:0)
Block(-8,13,-3,COBBLESTONE:0)
Block(-8,13,-2,SMOOTH_BRICK:2)
Block(-8,13,5,VINE:9)
Block(-8,13,6,VINE:12)
Block(-8,14,-5,VINE:1)
Block(-8,14,-4,COBBLESTONE:0)
Block(-8,14,-2,COBBLESTONE:0)
Block(-8,14,5,VINE:9)
Block(-8,14,6,VINE:12)
Block(-8,15,-5,VINE:1)
Block(-8,15,-4,COBBLESTONE:0)
Block(-8,15,-2,MOSSY_COBBLESTONE:0)
Block(-8,15,5,VINE:9)
Block(-8,15,6,VINE:12)
Block(-8,16,-5,SMOOTH_STAIRS:6)
Block(-8,16,-4,COBBLESTONE:0)
Block(-8,16,-2,COBBLESTONE:0)
Block(-8,16,5,VINE:9)
Block(-8,16,6,VINE:12)
Block(-8,17,-5,COBBLE_WALL:0)
Block(-8,17,-4,COBBLESTONE:0)
Block(-8,17,-2,COBBLESTONE:0)
Block(-8,17,5,VINE:9)
Block(-8,17,6,VINE:12)
Block(-8,17,8,SMOOTH_BRICK:0)
Block(-8,18,-5,COBBLE_WALL:0)
Block(-8,18,-4,COBBLESTONE:0)
Block(-8,18,-2,COBBLESTONE:0)
Block(-8,18,-1,SMOOTH_STAIRS:7)
Block(-8,18,5,VINE:9)
Block(-8,18,6,VINE:12)
Block(-8,18,8,STEP:5)
Block(-8,19,-5,COBBLE_WALL:0)
Block(-8,19,-4,SMOOTH_BRICK:1)
Block(-8,19,-3,COBBLESTONE:0)
Block(-8,19,-2,SMOOTH_BRICK:0)
Block(-8,19,-1,SMOOTH_BRICK:0)
Block(-8,19,0,SMOOTH_STAIRS:4)
Block(-8,19,5,VINE:9)
Block(-8,19,6,VINE:12)
Block(-8,20,-5,SMOOTH_BRICK:1)
Block(-8,20,-4,SMOOTH_STAIRS:0)
Block(-8,20,5,VINE:9)
Block(-8,20,6,VINE:12)
Block(-8,21,5,VINE:9)
Block(-8,21,6,VINE:12)
Block(-8,22,5,VINE:9)
Block(-8,22,6,VINE:12)
Block(-8,23,5,VINE:9)
Block(-8,23,6,VINE:8)
Block(-8,24,-4,SMOOTH_STAIRS:4)
Block(-8,24,5,VINE:9)
Block(-8,24,6,VINE:8)
Block(-8,25,5,VINE:9)
Block(-8,25,6,VINE:8)
Block(-8,26,5,VINE:9)
Block(-8,26,6,VINE:8)
Block(-8,27,5,VINE:9)
Block(-8,27,6,VINE:8)
Block(-8,28,5,VINE:1)
Block(-8,29,7,STONE_BUTTON:2)
Block(-7,0,-7,STONE:0)
Block(-7,0,-6,STONE:0)
Block(-7,0,-5,STONE:0)
Block(-7,0,-4,STONE:0)
Block(-7,0,-3,STONE:0)
Block(-7,0,-2,STONE:0)
Block(-7,0,-1,STONE:0)
Block(-7,0,0,STONE:0)
Block(-7,0,1,STONE:0)
Block(-7,0,2,STONE:0)
Block(-7,0,3,STONE:0)
Block(-7,0,4,STONE:0)
Block(-7,0,5,STONE:0)
Block(-7,0,6,STONE:0)
Block(-7,0,7,STONE:0)
Block(-7,0,8,STONE:0)
Block(-7,1,-7,STONE:0)
Block(-7,1,-6,STONE:0)
Block(-7,1,-5,STONE:0)
Block(-7,1,-4,STONE:0)
Block(-7,1,-3,STONE:0)
Block(-7,1,-2,STONE:0)
Block(-7,1,-1,STONE:0)
Block(-7,1,0,STONE:0)
Block(-7,1,1,STONE:0)
Block(-7,1,2,STONE:0)
Block(-7,1,3,STONE:0)
Block(-7,1,4,STONE:0)
Block(-7,1,5,STONE:0)
Block(-7,1,6,STONE:0)
Block(-7,1,7,STONE:0)
Block(-7,1,8,STONE:0)
Block(-7,2,-7,STONE:0)
Block(-7,2,-6,STONE:0)
Block(-7,2,-5,STONE:0)
Block(-7,2,-4,STONE:0)
Block(-7,2,-3,STONE:0)
Block(-7,2,-2,STONE:0)
Block(-7,2,-1,STONE:0)
Block(-7,2,0,STONE:0)
Block(-7,2,1,STONE:0)
Block(-7,2,2,STONE:0)
Block(-7,2,3,STONE:0)
Block(-7,2,4,STONE:0)
Block(-7,2,5,STONE:0)
Block(-7,2,6,STONE:0)
Block(-7,2,7,STONE:0)
Block(-7,2,8,STONE:0)
Block(-7,3,-7,GRASS:0)
Block(-7,3,-6,GRASS:0)
Block(-7,3,-5,GRASS:0)
Block(-7,3,-4,STONE:0)
Block(-7,3,-3,STONE:0)
Block(-7,3,-2,STONE:0)
Block(-7,3,-1,STONE:0)
Block(-7,3,0,STONE:0)
Block(-7,3,1,STONE:0)
Block(-7,3,2,STONE:0)
Block(-7,3,3,STONE:0)
Block(-7,3,4,STONE:0)
Block(-7,3,5,STONE:0)
Block(-7,3,6,STONE:0)
Block(-7,3,7,STONE:0)
Block(-7,3,8,STONE:0)
Block(-7,4,-6,VINE:1)
Block(-7,4,-5,VINE:9)
Block(-7,4,-4,COBBLESTONE:0)
Block(-7,4,-3,GRASS:0)
Block(-7,4,-2,DIRT:0)
Block(-7,4,-1,GRASS:0)
Block(-7,4,0,GRASS:0)
Block(-7,4,1,GRASS:0)
Block(-7,4,2,GRASS:0)
Block(-7,4,3,GRASS:0)
Block(-7,4,4,GRASS:0)
Block(-7,4,5,GRASS:0)
Block(-7,4,6,GRASS:0)
Block(-7,4,7,STONE:0)
Block(-7,4,8,STONE:0)
Block(-7,5,-6,VINE:1)
Block(-7,5,-5,VINE:1)
Block(-7,5,-4,COBBLESTONE:0)
Block(-7,5,-2,COBBLESTONE:0)
Block(-7,5,-1,LEAVES:4)
Block(-7,5,0,LEAVES:4)
Block(-7,5,1,LEAVES:4)
Block(-7,5,2,LONG_GRASS:1)
Block(-7,5,3,VINE:8)
Block(-7,5,4,LEAVES:4)
Block(-7,5,5,LONG_GRASS:1)
Block(-7,5,7,GRASS:0)
Block(-7,5,8,DIRT:0)
Block(-7,6,-6,VINE:1)
Block(-7,6,-5,VINE:1)
Block(-7,6,-4,COBBLESTONE:0)
Block(-7,6,-2,COBBLESTONE:0)
Block(-7,6,-1,LEAVES:4)
Block(-7,6,0,LEAVES:4)
Block(-7,6,3,VINE:8)
Block(-7,6,4,VINE:9)
Block(-7,6,8,SMOOTH_BRICK:1)
Block(-7,7,-6,VINE:1)
Block(-7,7,-5,VINE:1)
Block(-7,7,-4,COBBLESTONE:0)
Block(-7,7,-2,COBBLESTONE:0)
Block(-7,7,-1,LEAVES:4)
Block(-7,7,3,VINE:8)
Block(-7,7,4,VINE:9)
Block(-7,7,8,SMOOTH_BRICK:2)
Block(-7,8,-6,VINE:1)
Block(-7,8,-5,VINE:1)
Block(-7,8,-4,COBBLESTONE:0)
Block(-7,8,-3,COBBLESTONE:0)
Block(-7,8,-2,COBBLESTONE:0)
Block(-7,8,3,VINE:8)
Block(-7,8,4,VINE:9)
Block(-7,8,8,SMOOTH_BRICK:2)
Block(-7,9,-6,VINE:1)
Block(-7,9,-5,VINE:1)
Block(-7,9,-4,COBBLESTONE:0)
Block(-7,9,-3,MOSSY_COBBLESTONE:0)
Block(-7,9,-2,COBBLESTONE:0)
Block(-7,9,3,VINE:8)
Block(-7,9,4,VINE:9)
Block(-7,9,8,SMOOTH_BRICK:0)
Block(-7,10,-6,VINE:1)
Block(-7,10,-5,VINE:1)
Block(-7,10,-4,COBBLESTONE:0)
Block(-7,10,-2,COBBLESTONE:0)
Block(-7,10,3,VINE:8)
Block(-7,10,4,VINE:9)
Block(-7,11,-6,VINE:1)
Block(-7,11,-4,COBBLESTONE:0)
Block(-7,11,-2,COBBLESTONE:0)
Block(-7,11,3,VINE:8)
Block(-7,11,4,VINE:9)
Block(-7,12,-6,VINE:1)
Block(-7,12,-4,COBBLESTONE:0)
Block(-7,12,-2,COBBLESTONE:0)
Block(-7,12,3,VINE:8)
Block(-7,12,4,VINE:9)
Block(-7,13,-6,VINE:1)
Block(-7,13,-4,COBBLESTONE:0)
Block(-7,13,-2,COBBLESTONE:0)
Block(-7,13,3,VINE:8)
Block(-7,13,4,VINE:9)
Block(-7,14,-6,VINE:1)
Block(-7,14,-4,COBBLESTONE:0)
Block(-7,14,-2,COBBLESTONE:0)
Block(-7,14,3,VINE:8)
Block(-7,14,4,VINE:9)
Block(-7,15,-6,VINE:1)
Block(-7,15,-5,SMOOTH_STAIRS:6)
Block(-7,15,-4,COBBLESTONE:0)
Block(-7,15,-2,COBBLESTONE:0)
Block(-7,15,3,VINE:8)
Block(-7,15,4,VINE:9)
Block(-7,16,-6,VINE:1)
Block(-7,16,-5,COBBLE_WALL:0)
Block(-7,16,-4,COBBLESTONE:0)
Block(-7,16,-2,COBBLESTONE:0)
Block(-7,16,-1,SMOOTH_STAIRS:7)
Block(-7,16,3,VINE:8)
Block(-7,16,4,VINE:9)
Block(-7,16,8,STEP:13)
Block(-7,17,-6,VINE:1)
Block(-7,17,-5,COBBLE_WALL:0)
Block(-7,17,-4,COBBLESTONE:0)
Block(-7,17,-2,COBBLESTONE:0)
Block(-7,17,-1,SMOOTH_BRICK:2)
Block(-7,17,3,VINE:8)
Block(-7,17,4,VINE:9)
Block(-7,17,8,SMOOTH_BRICK:1)
Block(-7,18,-6,VINE:1)
Block(-7,18,-5,SMOOTH_BRICK:2)
Block(-7,18,-4,MOSSY_COBBLESTONE:0)
Block(-7,18,-2,COBBLESTONE:0)
Block(-7,18,-1,SMOOTH_BRICK:0)
Block(-7,18,3,VINE:8)
Block(-7,18,4,VINE:9)
Block(-7,18,7,COBBLE_WALL:0)
Block(-7,19,-5,COBBLE_WALL:0)
Block(-7,19,-4,SMOOTH_BRICK:1)
Block(-7,19,-3,COBBLESTONE:0)
Block(-7,19,-2,SMOOTH_BRICK:2)
Block(-7,19,-1,SMOOTH_BRICK:0)
Block(-7,19,0,SMOOTH_BRICK:0)
Block(-7,19,1,SMOOTH_BRICK:0)
Block(-7,19,2,SMOOTH_STAIRS:0)
Block(-7,19,3,VINE:8)
Block(-7,19,4,VINE:9)
Block(-7,19,6,STEP:8)
Block(-7,19,7,DOUBLE_STEP:0)
Block(-7,19,8,STEP:8)
Block(-7,20,-4,SMOOTH_BRICK:1)
Block(-7,20,0,SMOOTH_STAIRS:0)
Block(-7,20,4,VINE:1)
Block(-7,20,6,COBBLE_WALL:1)
Block(-7,21,-4,SMOOTH_BRICK:1)
Block(-7,21,4,VINE:1)
Block(-7,21,6,COBBLE_WALL:1)
Block(-7,22,-4,SMOOTH_BRICK:3)
Block(-7,22,4,VINE:1)
Block(-7,22,6,COBBLE_WALL:0)
Block(-7,23,-4,SMOOTH_BRICK:0)
Block(-7,23,4,VINE:1)
Block(-7,23,6,COBBLE_WALL:1)
Block(-7,24,-4,MOSSY_COBBLESTONE:0)
Block(-7,24,4,VINE:1)
Block(-7,24,6,STEP:0)
Block(-7,24,7,STEP:8)
Block(-7,25,-4,COBBLESTONE:0)
Block(-7,25,4,VINE:1)
Block(-7,25,6,LEAVES:4)
Block(-7,25,8,STEP:0)
Block(-7,26,4,VINE:1)
Block(-7,26,5,LEAVES:4)
Block(-7,26,6,LEAVES:4)
Block(-7,27,5,LEAVES:4)
Block(-7,27,6,LEAVES:4)
Block(-7,27,7,COBBLESTONE_STAIRS:4)
Block(-7,28,5,LEAVES:4)
Block(-7,28,7,SMOOTH_BRICK:3)
Block(-7,29,5,LEAVES:4)
Block(-7,29,6,COBBLESTONE_STAIRS:4)
Block(-7,29,7,DOUBLE_STEP:8)
Block(-7,29,8,COBBLESTONE_STAIRS:4)
Block(-7,30,5,LEAVES:4)
Block(-7,30,6,DOUBLE_STEP:8)
Block(-7,30,7,STEP:0)
Block(-7,30,8,DOUBLE_STEP:8)
Block(-6,0,-7,STONE:0)
Block(-6,0,-6,STONE:0)
Block(-6,0,-5,STONE:0)
Block(-6,0,-4,STONE:0)
Block(-6,0,-3,STONE:0)
Block(-6,0,-2,STONE:0)
Block(-6,0,-1,STONE:0)
Block(-6,0,0,STONE:0)
Block(-6,0,1,STONE:0)
Block(-6,0,2,STONE:0)
Block(-6,0,3,STONE:0)
Block(-6,0,4,STONE:0)
Block(-6,0,5,STONE:0)
Block(-6,0,6,STONE:0)
Block(-6,0,7,STONE:0)
Block(-6,0,8,STONE:0)
Block(-6,1,-7,STONE:0)
Block(-6,1,-6,STONE:0)
Block(-6,1,-5,STONE:0)
Block(-6,1,-4,STONE:0)
Block(-6,1,-3,STONE:0)
Block(-6,1,-2,STONE:0)
Block(-6,1,-1,STONE:0)
Block(-6,1,0,STONE:0)
Block(-6,1,1,STONE:0)
Block(-6,1,2,STONE:0)
Block(-6,1,3,STONE:0)
Block(-6,1,4,STONE:0)
Block(-6,1,5,STONE:0)
Block(-6,1,6,STONE:0)
Block(-6,1,7,STONE:0)
Block(-6,1,8,STONE:0)
Block(-6,2,-7,STONE:0)
Block(-6,2,-6,STONE:0)
Block(-6,2,-5,STONE:0)
Block(-6,2,-4,STONE:0)
Block(-6,2,-3,STONE:0)
Block(-6,2,-2,STONE:0)
Block(-6,2,-1,STONE:0)
Block(-6,2,0,STONE:0)
Block(-6,2,1,STONE:0)
Block(-6,2,2,STONE:0)
Block(-6,2,3,STONE:0)
Block(-6,2,4,STONE:0)
Block(-6,2,5,STONE:0)
Block(-6,2,6,STONE:0)
Block(-6,2,7,STONE:0)
Block(-6,2,8,STONE:0)
Block(-6,3,-7,GRASS:0)
Block(-6,3,-6,GRASS:0)
Block(-6,3,-5,STONE:0)
Block(-6,3,-4,STONE:0)
Block(-6,3,-3,STONE:0)
Block(-6,3,-2,STONE:0)
Block(-6,3,-1,STONE:0)
Block(-6,3,0,STONE:0)
Block(-6,3,1,STONE:0)
Block(-6,3,2,STONE:0)
Block(-6,3,3,STONE:0)
Block(-6,3,4,STONE:0)
Block(-6,3,5,STONE:0)
Block(-6,3,6,SMOOTH_BRICK:1)
Block(-6,3,7,SMOOTH_BRICK:0)
Block(-6,3,8,SMOOTH_BRICK:2)
Block(-6,4,-6,LONG_GRASS:1)
Block(-6,4,-5,GRASS:0)
Block(-6,4,-4,DIRT:0)
Block(-6,4,-3,DIRT:0)
Block(-6,4,-2,DIRT:0)
Block(-6,4,-1,GRASS:0)
Block(-6,4,0,GRASS:0)
Block(-6,4,1,GRASS:0)
Block(-6,4,2,GRASS:0)
Block(-6,4,3,GRASS:0)
Block(-6,4,4,GRASS:0)
Block(-6,4,5,GRASS:0)
Block(-6,4,6,SMOOTH_BRICK:1)
Block(-6,4,7,SMOOTH_BRICK:0)
Block(-6,4,8,SMOOTH_BRICK:1)
Block(-6,5,-5,VINE:1)
Block(-6,5,-4,SMOOTH_BRICK:1)
Block(-6,5,-3,MOSSY_COBBLESTONE:0)
Block(-6,5,-2,SMOOTH_BRICK:1)
Block(-6,5,-1,LEAVES:4)
Block(-6,5,0,LEAVES:4)
Block(-6,5,2,LEAVES:4)
Block(-6,5,3,LEAVES:4)
Block(-6,5,4,LEAVES:4)
Block(-6,5,5,LONG_GRASS:1)
Block(-6,5,6,SMOOTH_BRICK:1)
Block(-6,5,7,SMOOTH_BRICK:0)
Block(-6,5,8,SMOOTH_BRICK:2)
Block(-6,6,-5,VINE:1)
Block(-6,6,-4,SMOOTH_BRICK:2)
Block(-6,6,-3,COBBLESTONE:0)
Block(-6,6,-2,SMOOTH_BRICK:2)
Block(-6,6,3,VINE:1)
Block(-6,6,4,LEAVES:4)
Block(-6,6,5,VINE:12)
Block(-6,6,6,SMOOTH_BRICK:1)
Block(-6,6,7,SMOOTH_STAIRS:0)
Block(-6,6,8,SMOOTH_BRICK:0)
Block(-6,7,-5,VINE:1)
Block(-6,7,-4,SMOOTH_BRICK:2)
Block(-6,7,-3,COBBLESTONE:0)
Block(-6,7,-2,SMOOTH_BRICK:1)
Block(-6,7,6,SMOOTH_STAIRS:0)
Block(-6,7,8,SMOOTH_BRICK:0)
Block(-6,8,-5,VINE:1)
Block(-6,8,-4,SMOOTH_BRICK:1)
Block(-6,8,-3,COBBLESTONE:0)
Block(-6,8,-2,SMOOTH_BRICK:1)
Block(-6,8,7,SMOOTH_STAIRS:4)
Block(-6,8,8,SMOOTH_BRICK:1)
Block(-6,9,-5,VINE:1)
Block(-6,9,-4,SMOOTH_BRICK:2)
Block(-6,9,-3,COBBLESTONE:0)
Block(-6,9,-2,SMOOTH_BRICK:2)
Block(-6,9,6,SMOOTH_STAIRS:4)
Block(-6,9,7,SMOOTH_BRICK:1)
Block(-6,9,8,SMOOTH_BRICK:0)
Block(-6,10,-5,VINE:1)
Block(-6,10,-4,SMOOTH_BRICK:2)
Block(-6,10,-3,COBBLESTONE:0)
Block(-6,10,-2,SMOOTH_BRICK:0)
Block(-6,10,6,SMOOTH_BRICK:1)
Block(-6,10,7,SMOOTH_BRICK:2)
Block(-6,10,8,SMOOTH_BRICK:0)
Block(-6,11,-5,VINE:1)
Block(-6,11,-4,SMOOTH_BRICK:1)
Block(-6,11,-3,COBBLESTONE:0)
Block(-6,11,-2,SMOOTH_BRICK:0)
Block(-6,11,6,SMOOTH_STAIRS:4)
Block(-6,11,7,SMOOTH_STAIRS:0)
Block(-6,11,8,SMOOTH_BRICK:2)
Block(-6,12,-5,VINE:1)
Block(-6,12,-4,SMOOTH_BRICK:2)
Block(-6,12,-3,COBBLESTONE:0)
Block(-6,12,-2,SMOOTH_BRICK:2)
Block(-6,12,6,SMOOTH_BRICK:1)
Block(-6,12,7,SMOOTH_BRICK:2)
Block(-6,12,8,SMOOTH_BRICK:2)
Block(-6,13,-4,SMOOTH_BRICK:2)
Block(-6,13,-3,COBBLESTONE:0)
Block(-6,13,-2,SMOOTH_BRICK:2)
Block(-6,13,6,SMOOTH_BRICK:2)
Block(-6,13,7,SMOOTH_BRICK:0)
Block(-6,13,8,SMOOTH_BRICK:0)
Block(-6,14,-4,COBBLESTONE:0)
Block(-6,14,-2,COBBLESTONE:0)
Block(-6,14,6,SMOOTH_BRICK:1)
Block(-6,14,7,SMOOTH_BRICK:0)
Block(-6,14,8,SMOOTH_BRICK:1)
Block(-6,15,-4,COBBLESTONE:0)
Block(-6,15,-3,COBBLESTONE:0)
Block(-6,15,-2,COBBLESTONE:0)
Block(-6,15,6,SMOOTH_BRICK:1)
Block(-6,15,7,SMOOTH_BRICK:1)
Block(-6,15,8,SMOOTH_BRICK:0)
Block(-6,16,-5,SMOOTH_STAIRS:6)
Block(-6,16,-4,COBBLESTONE:0)
Block(-6,16,-2,COBBLESTONE:0)
Block(-6,16,3,LEAVES:4)
Block(-6,16,6,SMOOTH_BRICK:0)
Block(-6,16,7,SMOOTH_BRICK:1)
Block(-6,16,8,SMOOTH_BRICK:1)
Block(-6,17,-5,COBBLE_WALL:0)
Block(-6,17,-4,COBBLESTONE:0)
Block(-6,17,-2,COBBLESTONE:0)
Block(-6,17,4,LEAVES:4)
Block(-6,17,6,SMOOTH_BRICK:1)
Block(-6,17,7,SMOOTH_BRICK:2)
Block(-6,17,8,SMOOTH_BRICK:0)
Block(-6,18,-5,COBBLE_WALL:0)
Block(-6,18,-4,COBBLESTONE:0)
Block(-6,18,-2,COBBLESTONE:0)
Block(-6,18,-1,SMOOTH_STAIRS:7)
Block(-6,18,4,LEAVES:4)
Block(-6,18,6,SMOOTH_BRICK:1)
Block(-6,18,7,SMOOTH_BRICK:1)
Block(-6,18,8,SMOOTH_BRICK:2)
Block(-6,19,-5,COBBLE_WALL:0)
Block(-6,19,-4,SMOOTH_BRICK:0)
Block(-6,19,-3,COBBLESTONE:0)
Block(-6,19,-2,SMOOTH_BRICK:0)
Block(-6,19,-1,SMOOTH_BRICK:2)
Block(-6,19,0,SMOOTH_BRICK:1)
Block(-6,19,1,SMOOTH_BRICK:1)
Block(-6,19,2,SMOOTH_BRICK:1)
Block(-6,19,3,SMOOTH_BRICK:1)
Block(-6,19,4,SMOOTH_BRICK:0)
Block(-6,19,5,SMOOTH_STAIRS:0)
Block(-6,19,6,SMOOTH_BRICK:0)
Block(-6,19,7,SMOOTH_BRICK:1)
Block(-6,19,8,SMOOTH_BRICK:2)
Block(-6,20,-5,SMOOTH_BRICK:2)
Block(-6,20,-4,SMOOTH_STAIRS:1)
Block(-6,20,1,SMOOTH_STAIRS:2)
Block(-6,20,2,SMOOTH_BRICK:2)
Block(-6,20,3,STEP:5)
Block(-6,20,4,VINE:9)
Block(-6,20,6,SMOOTH_BRICK:2)
Block(-6,20,7,STEP:0)
Block(-6,20,8,STEP:0)
Block(-6,21,-5,VINE:1)
Block(-6,21,2,SMOOTH_BRICK:1)
Block(-6,21,4,VINE:9)
Block(-6,21,6,SMOOTH_BRICK:2)
Block(-6,22,-5,VINE:1)
Block(-6,22,4,VINE:9)
Block(-6,22,5,LEAVES:4)
Block(-6,22,6,SMOOTH_BRICK:0)
Block(-6,23,-5,VINE:1)
Block(-6,23,4,VINE:9)
Block(-6,23,5,LEAVES:4)
Block(-6,23,6,SMOOTH_BRICK:0)
Block(-6,24,-5,VINE:1)
Block(-6,24,-4,SMOOTH_BRICK:2)
Block(-6,24,4,VINE:9)
Block(-6,24,5,LEAVES:4)
Block(-6,24,6,SMOOTH_BRICK:1)
Block(-6,24,7,DOUBLE_STEP:8)
Block(-6,24,8,STEP:15)
Block(-6,25,-4,COBBLESTONE:0)
Block(-6,25,4,VINE:1)
Block(-6,25,5,LEAVES:4)
Block(-6,25,6,SMOOTH_BRICK:1)
Block(-6,25,7,SMOOTH_BRICK:2)
Block(-6,25,8,DOUBLE_STEP:8)
Block(-6,26,-4,COBBLESTONE_STAIRS:2)
Block(-6,26,5,VINE:2)
Block(-6,26,6,SMOOTH_BRICK:2)
Block(-6,26,8,SMOOTH_BRICK:1)
Block(-6,27,6,SMOOTH_BRICK:2)
Block(-6,27,7,SMOOTH_BRICK:0)
Block(-6,27,8,SMOOTH_BRICK:2)
Block(-6,28,5,COBBLESTONE_STAIRS:4)
Block(-6,28,6,SMOOTH_BRICK:0)
Block(-6,28,7,SMOOTH_BRICK:0)
Block(-6,28,8,SMOOTH_BRICK:1)
Block(-6,29,4,COBBLESTONE_STAIRS:4)
Block(-6,29,5,DOUBLE_STEP:8)
Block(-6,29,6,SMOOTH_BRICK:1)
Block(-6,29,7,SMOOTH_BRICK:2)
Block(-6,29,8,SMOOTH_BRICK:0)
Block(-6,30,4,DOUBLE_STEP:8)
Block(-6,30,5,STEP:0)
Block(-6,30,6,LEAVES:4)
Block(-6,30,7,LEAVES:4)
Block(-6,31,5,LEAVES:4)
Block(-6,31,6,LEAVES:4)
Block(-6,32,6,LEAVES:4)
Block(-6,36,8,STONE_BUTTON:2)
Block(-5,0,-7,STONE:0)
Block(-5,0,-6,STONE:0)
Block(-5,0,-5,STONE:0)
Block(-5,0,-4,STONE:0)
Block(-5,0,-3,STONE:0)
Block(-5,0,-2,STONE:0)
Block(-5,0,-1,STONE:0)
Block(-5,0,0,STONE:0)
Block(-5,0,1,STONE:0)
Block(-5,0,2,STONE:0)
Block(-5,0,3,STONE:0)
Block(-5,0,4,STONE:0)
Block(-5,0,5,STONE:0)
Block(-5,0,6,STONE:0)
Block(-5,0,7,STONE:0)
Block(-5,0,8,STONE:0)
Block(-5,1,-7,STONE:0)
Block(-5,1,-6,STONE:0)
Block(-5,1,-5,STONE:0)
Block(-5,1,-4,STONE:0)
Block(-5,1,-3,STONE:0)
Block(-5,1,-2,STONE:0)
Block(-5,1,-1,STONE:0)
Block(-5,1,0,STONE:0)
Block(-5,1,1,STONE:0)
Block(-5,1,2,STONE:0)
Block(-5,1,3,STONE:0)
Block(-5,1,4,STONE:0)
Block(-5,1,5,STONE:0)
Block(-5,1,6,STONE:0)
Block(-5,1,7,STONE:0)
Block(-5,1,8,STONE:0)
Block(-5,2,-7,STONE:0)
Block(-5,2,-6,STONE:0)
Block(-5,2,-5,STONE:0)
Block(-5,2,-4,STONE:0)
Block(-5,2,-3,STONE:0)
Block(-5,2,-2,STONE:0)
Block(-5,2,-1,STONE:0)
Block(-5,2,0,STONE:0)
Block(-5,2,1,STONE:0)
Block(-5,2,2,STONE:0)
Block(-5,2,3,STONE:0)
Block(-5,2,4,STONE:0)
Block(-5,2,5,STONE:0)
Block(-5,2,6,STONE:0)
Block(-5,2,7,STONE:0)
Block(-5,2,8,STONE:0)
Block(-5,3,-7,GRASS:0)
Block(-5,3,-6,GRASS:0)
Block(-5,3,-5,STONE:0)
Block(-5,3,-4,STONE:0)
Block(-5,3,-3,STONE:0)
Block(-5,3,-2,STONE:0)
Block(-5,3,-1,STONE:0)
Block(-5,3,0,STONE:0)
Block(-5,3,1,STONE:0)
Block(-5,3,2,STONE:0)
Block(-5,3,3,STONE:0)
Block(-5,3,4,SMOOTH_BRICK:1)
Block(-5,3,5,SMOOTH_BRICK:2)
Block(-5,3,6,STONE:0)
Block(-5,3,7,STONE:0)
Block(-5,3,8,STONE:0)
Block(-5,4,-6,LONG_GRASS:1)
Block(-5,4,-5,GRASS:0)
Block(-5,4,-4,GRASS:0)
Block(-5,4,-3,GRASS:0)
Block(-5,4,-2,STONE:0)
Block(-5,4,-1,STONE:0)
Block(-5,4,0,GRASS:0)
Block(-5,4,1,GRASS:0)
Block(-5,4,2,GRASS:0)
Block(-5,4,3,GRASS:0)
Block(-5,4,4,SMOOTH_BRICK:1)
Block(-5,4,5,SMOOTH_BRICK:0)
Block(-5,4,6,GRASS:0)
Block(-5,4,7,GRASS:0)
Block(-5,4,8,STONE:0)
Block(-5,5,-5,LONG_GRASS:1)
Block(-5,5,-2,GRASS:0)
Block(-5,5,-1,GRASS:0)
Block(-5,5,1,LEAVES:4)
Block(-5,5,2,LEAVES:4)
Block(-5,5,3,LEAVES:4)
Block(-5,5,4,SMOOTH_BRICK:2)
Block(-5,5,5,SMOOTH_BRICK:2)
Block(-5,5,8,GRASS:0)
Block(-5,6,2,LEAVES:4)
Block(-5,6,3,VINE:1)
Block(-5,6,4,LEAVES:4)
Block(-5,6,5,SMOOTH_BRICK:1)
Block(-5,7,4,SMOOTH_BRICK:1)
Block(-5,7,5,SMOOTH_BRICK:1)
Block(-5,8,3,LEAVES:4)
Block(-5,8,4,SMOOTH_STAIRS:4)
Block(-5,8,5,SMOOTH_STAIRS:0)
Block(-5,9,3,LEAVES:4)
Block(-5,9,4,SMOOTH_BRICK:0)
Block(-5,9,5,SMOOTH_BRICK:2)
Block(-5,10,4,SMOOTH_BRICK:0)
Block(-5,10,5,SMOOTH_STAIRS:0)
Block(-5,11,4,SMOOTH_BRICK:2)
Block(-5,11,5,SMOOTH_BRICK:1)
Block(-5,11,6,SMOOTH_BRICK:2)
Block(-5,11,7,SMOOTH_BRICK:0)
Block(-5,11,8,SMOOTH_BRICK:2)
Block(-5,12,4,SMOOTH_STAIRS:0)
Block(-5,12,5,SMOOTH_BRICK:2)
Block(-5,12,6,SMOOTH_BRICK:1)
Block(-5,12,7,SMOOTH_BRICK:1)
Block(-5,13,4,SMOOTH_STAIRS:4)
Block(-5,13,5,SMOOTH_BRICK:1)
Block(-5,13,6,SMOOTH_BRICK:1)
Block(-5,13,7,STEP:5)
Block(-5,14,-4,SMOOTH_BRICK:1)
Block(-5,14,-3,COBBLESTONE:0)
Block(-5,14,-2,SMOOTH_BRICK:2)
Block(-5,14,3,LEAVES:4)
Block(-5,14,4,SMOOTH_BRICK:0)
Block(-5,14,5,SMOOTH_BRICK:0)
Block(-5,14,6,SMOOTH_STAIRS:1)
Block(-5,15,-4,SMOOTH_BRICK:0)
Block(-5,15,-3,COBBLESTONE:0)
Block(-5,15,-2,SMOOTH_BRICK:2)
Block(-5,15,3,LEAVES:4)
Block(-5,15,4,SMOOTH_BRICK:1)
Block(-5,15,5,SMOOTH_BRICK:0)
Block(-5,16,-4,COBBLESTONE:0)
Block(-5,16,-2,COBBLESTONE:0)
Block(-5,16,3,LEAVES:4)
Block(-5,16,4,SMOOTH_BRICK:2)
Block(-5,16,5,SMOOTH_BRICK:0)
Block(-5,17,-4,COBBLESTONE:0)
Block(-5,17,-2,MOSSY_COBBLESTONE:0)
Block(-5,17,4,SMOOTH_BRICK:1)
Block(-5,17,5,SMOOTH_BRICK:1)
Block(-5,18,-5,SMOOTH_STAIRS:1)
Block(-5,18,-4,COBBLESTONE:0)
Block(-5,18,-2,COBBLESTONE:0)
Block(-5,18,3,LEAVES:4)
Block(-5,18,4,SMOOTH_BRICK:2)
Block(-5,18,5,SMOOTH_BRICK:1)
Block(-5,19,-5,COBBLE_WALL:0)
Block(-5,19,-4,SMOOTH_BRICK:2)
Block(-5,19,-3,COBBLESTONE:0)
Block(-5,19,-2,SMOOTH_BRICK:2)
Block(-5,19,-1,SMOOTH_BRICK:0)
Block(-5,19,0,SMOOTH_BRICK:0)
Block(-5,19,1,SMOOTH_BRICK:2)
Block(-5,19,2,SMOOTH_BRICK:2)
Block(-5,19,3,SMOOTH_BRICK:1)
Block(-5,19,4,SMOOTH_BRICK:2)
Block(-5,19,5,SMOOTH_BRICK:0)
Block(-5,20,-5,COBBLE_WALL:0)
Block(-5,20,-4,VINE:2)
Block(-5,20,-2,LEAVES:4)
Block(-5,20,-1,SMOOTH_STAIRS:1)
Block(-5,20,1,SMOOTH_BRICK:2)
Block(-5,20,3,SMOOTH_BRICK:2)
Block(-5,20,4,SMOOTH_BRICK:1)
Block(-5,20,5,SMOOTH_BRICK:1)
Block(-5,21,-5,VINE:1)
Block(-5,21,-4,VINE:2)
Block(-5,21,-2,LEAVES:4)
Block(-5,21,3,VINE:9)
Block(-5,21,4,SMOOTH_BRICK:2)
Block(-5,21,5,SMOOTH_STAIRS:0)
Block(-5,22,-5,VINE:1)
Block(-5,22,-4,VINE:2)
Block(-5,22,3,VINE:1)
Block(-5,22,4,SMOOTH_STAIRS:0)
Block(-5,22,5,SMOOTH_STAIRS:4)
Block(-5,23,-5,VINE:1)
Block(-5,23,-4,VINE:2)
Block(-5,23,3,VINE:1)
Block(-5,23,4,SMOOTH_BRICK:1)
Block(-5,23,5,SMOOTH_BRICK:2)
Block(-5,24,-5,VINE:1)
Block(-5,24,-4,VINE:2)
Block(-5,24,3,VINE:1)
Block(-5,24,4,SMOOTH_BRICK:2)
Block(-5,24,5,SMOOTH_BRICK:1)
Block(-5,24,6,SMOOTH_STAIRS:5)
Block(-5,25,-5,VINE:1)
Block(-5,25,-4,SMOOTH_BRICK:0)
Block(-5,25,4,SMOOTH_STAIRS:2)
Block(-5,25,5,SMOOTH_BRICK:1)
Block(-5,25,6,SMOOTH_BRICK:0)
Block(-5,25,8,SMOOTH_STAIRS:5)
Block(-5,26,-5,VINE:1)
Block(-5,26,-4,COBBLESTONE:0)
Block(-5,26,4,SMOOTH_STAIRS:4)
Block(-5,26,5,SMOOTH_BRICK:0)
Block(-5,26,6,SMOOTH_BRICK:0)
Block(-5,26,8,SMOOTH_BRICK:0)
Block(-5,27,4,SMOOTH_STAIRS:2)
Block(-5,27,5,SMOOTH_BRICK:0)
Block(-5,27,6,SMOOTH_BRICK:0)
Block(-5,27,8,SMOOTH_BRICK:0)
Block(-5,28,5,SMOOTH_BRICK:1)
Block(-5,28,6,SMOOTH_BRICK:0)
Block(-5,28,8,SMOOTH_BRICK:0)
Block(-5,29,5,SMOOTH_BRICK:1)
Block(-5,29,6,SMOOTH_BRICK:1)
Block(-5,29,7,SMOOTH_BRICK:1)
Block(-5,29,8,SMOOTH_BRICK:1)
Block(-5,30,5,LEAVES:4)
Block(-5,30,6,LEAVES:4)
Block(-5,31,5,LEAVES:4)
Block(-5,31,6,LEAVES:4)
Block(-5,36,7,STONE_BUTTON:4)
Block(-5,36,8,DOUBLE_STEP:8)
Block(-4,0,-7,STONE:0)
Block(-4,0,-6,STONE:0)
Block(-4,0,-5,STONE:0)
Block(-4,0,-4,STONE:0)
Block(-4,0,-3,STONE:0)
Block(-4,0,-2,STONE:0)
Block(-4,0,-1,STONE:0)
Block(-4,0,0,STONE:0)
Block(-4,0,1,STONE:0)
Block(-4,0,2,STONE:0)
Block(-4,0,3,STONE:0)
Block(-4,0,4,STONE:0)
Block(-4,0,5,STONE:0)
Block(-4,0,6,STONE:0)
Block(-4,0,7,STONE:0)
Block(-4,0,8,STONE:0)
Block(-4,1,-7,STONE:0)
Block(-4,1,-6,STONE:0)
Block(-4,1,-5,STONE:0)
Block(-4,1,-4,STONE:0)
Block(-4,1,-3,STONE:0)
Block(-4,1,-2,STONE:0)
Block(-4,1,-1,STONE:0)
Block(-4,1,0,STONE:0)
Block(-4,1,1,STONE:0)
Block(-4,1,2,STONE:0)
Block(-4,1,3,STONE:0)
Block(-4,1,4,STONE:0)
Block(-4,1,5,STONE:0)
Block(-4,1,6,STONE:0)
Block(-4,1,7,STONE:0)
Block(-4,1,8,STONE:0)
Block(-4,2,-7,STONE:0)
Block(-4,2,-6,STONE:0)
Block(-4,2,-5,STONE:0)
Block(-4,2,-4,STONE:0)
Block(-4,2,-3,STONE:0)
Block(-4,2,-2,STONE:0)
Block(-4,2,-1,STONE:0)
Block(-4,2,0,STONE:0)
Block(-4,2,1,STONE:0)
Block(-4,2,2,STONE:0)
Block(-4,2,3,STONE:0)
Block(-4,2,4,STONE:0)
Block(-4,2,5,STONE:0)
Block(-4,2,6,STONE:0)
Block(-4,2,7,STONE:0)
Block(-4,2,8,STONE:0)
Block(-4,3,-7,GRASS:0)
Block(-4,3,-6,STONE:0)
Block(-4,3,-5,STONE:0)
Block(-4,3,-4,STONE:0)
Block(-4,3,-3,STONE:0)
Block(-4,3,-2,STONE:0)
Block(-4,3,-1,STONE:0)
Block(-4,3,0,STONE:0)
Block(-4,3,1,STONE:0)
Block(-4,3,2,STONE:0)
Block(-4,3,3,SMOOTH_BRICK:2)
Block(-4,3,4,STONE:0)
Block(-4,3,5,STONE:0)
Block(-4,3,6,STONE:0)
Block(-4,3,7,STONE:0)
Block(-4,3,8,STONE:0)
Block(-4,4,-6,GRASS:0)
Block(-4,4,-5,GRASS:0)
Block(-4,4,-4,GRASS:0)
Block(-4,4,-3,STONE:0)
Block(-4,4,-2,STONE:0)
Block(-4,4,-1,STONE:0)
Block(-4,4,0,STONE:0)
Block(-4,4,1,GRASS:0)
Block(-4,4,2,GRASS:0)
Block(-4,4,3,SMOOTH_BRICK:0)
Block(-4,4,4,GRASS:0)
Block(-4,4,5,GRASS:0)
Block(-4,4,6,GRASS:0)
Block(-4,4,7,STONE:0)
Block(-4,4,8,STONE:0)
Block(-4,5,-6,VINE:1)
Block(-4,5,-3,GRASS:0)
Block(-4,5,-2,GRASS:0)
Block(-4,5,-1,GRASS:0)
Block(-4,5,0,GRASS:0)
Block(-4,5,1,LEAVES:4)
Block(-4,5,2,LEAVES:4)
Block(-4,5,3,SMOOTH_BRICK:2)
Block(-4,5,7,GRASS:0)
Block(-4,5,8,GRASS:0)
Block(-4,6,-6,VINE:1)
Block(-4,6,-2,LONG_GRASS:1)
Block(-4,6,0,LONG_GRASS:1)
Block(-4,6,1,LEAVES:4)
Block(-4,6,2,LEAVES:4)
Block(-4,6,3,SMOOTH_STAIRS:0)
Block(-4,7,-6,VINE:1)
Block(-4,7,2,LEAVES:4)
Block(-4,7,3,SMOOTH_STAIRS:4)
Block(-4,8,-6,VINE:1)
Block(-4,8,0,LEAVES:4)
Block(-4,8,1,LEAVES:4)
Block(-4,8,2,LEAVES:4)
Block(-4,8,3,SMOOTH_BRICK:0)
Block(-4,9,-6,VINE:1)
Block(-4,9,1,LEAVES:4)
Block(-4,9,2,LEAVES:4)
Block(-4,9,3,SMOOTH_BRICK:1)
Block(-4,10,-6,VINE:1)
Block(-4,10,3,SMOOTH_BRICK:1)
Block(-4,11,-6,VINE:1)
Block(-4,11,3,SMOOTH_BRICK:1)
Block(-4,11,4,SMOOTH_BRICK:1)
Block(-4,11,6,SMOOTH_BRICK:1)
Block(-4,11,7,SMOOTH_BRICK:0)
Block(-4,11,8,SMOOTH_BRICK:0)
Block(-4,12,-6,VINE:1)
Block(-4,12,2,LEAVES:4)
Block(-4,12,3,SMOOTH_BRICK:1)
Block(-4,12,4,SMOOTH_STAIRS:0)
Block(-4,12,6,SMOOTH_STAIRS:1)
Block(-4,12,8,STEP:5)
Block(-4,13,-6,VINE:1)
Block(-4,13,2,LEAVES:4)
Block(-4,13,3,SMOOTH_BRICK:0)
Block(-4,14,-6,VINE:1)
Block(-4,14,1,LEAVES:4)
Block(-4,14,2,LEAVES:4)
Block(-4,14,3,SMOOTH_BRICK:2)
Block(-4,15,-6,VINE:1)
Block(-4,15,2,LEAVES:4)
Block(-4,15,3,SMOOTH_BRICK:1)
Block(-4,16,-6,VINE:1)
Block(-4,16,-4,SMOOTH_BRICK:1)
Block(-4,16,-3,COBBLESTONE:0)
Block(-4,16,-2,SMOOTH_BRICK:0)
Block(-4,16,3,SMOOTH_BRICK:0)
Block(-4,17,-6,VINE:1)
Block(-4,17,-4,COBBLESTONE:0)
Block(-4,17,-2,COBBLESTONE:0)
Block(-4,17,3,SMOOTH_BRICK:0)
Block(-4,18,-6,VINE:1)
Block(-4,18,-4,COBBLESTONE:0)
Block(-4,18,-2,COBBLESTONE:0)
Block(-4,18,3,SMOOTH_BRICK:1)
Block(-4,19,-6,VINE:1)
Block(-4,19,-5,COBBLE_WALL:0)
Block(-4,19,-4,SMOOTH_BRICK:0)
Block(-4,19,-3,COBBLESTONE:0)
Block(-4,19,-2,SMOOTH_BRICK:1)
Block(-4,19,-1,SMOOTH_BRICK:0)
Block(-4,19,0,SMOOTH_BRICK:0)
Block(-4,19,1,SMOOTH_BRICK:1)
Block(-4,19,2,SMOOTH_BRICK:1)
Block(-4,19,3,SMOOTH_BRICK:2)
Block(-4,20,-6,VINE:1)
Block(-4,20,-5,SMOOTH_BRICK:2)
Block(-4,20,-4,SMOOTH_STAIRS:0)
Block(-4,20,-3,LEAVES:4)
Block(-4,20,-2,SMOOTH_BRICK:0)
Block(-4,20,2,VINE:1)
Block(-4,20,3,SMOOTH_BRICK:1)
Block(-4,21,-5,VINE:8)
Block(-4,21,-4,LEAVES:4)
Block(-4,21,-3,LEAVES:4)
Block(-4,21,2,VINE:1)
Block(-4,21,3,SMOOTH_BRICK:0)
Block(-4,22,-5,VINE:8)
Block(-4,22,3,SMOOTH_STAIRS:6)
Block(-4,23,-5,VINE:8)
Block(-4,23,3,SMOOTH_BRICK:0)
Block(-4,24,-5,VINE:8)
Block(-4,24,-4,SMOOTH_STAIRS:6)
Block(-4,24,3,SMOOTH_STAIRS:2)
Block(-4,25,-4,COBBLESTONE:0)
Block(-4,25,6,SMOOTH_STAIRS:5)
Block(-4,26,-4,STEP:3)
Block(-4,26,6,SMOOTH_BRICK:0)
Block(-4,26,8,SMOOTH_STAIRS:5)
Block(-4,27,6,SMOOTH_BRICK:0)
Block(-4,27,8,SMOOTH_BRICK:0)
Block(-4,28,6,SMOOTH_BRICK:0)
Block(-4,28,8,SMOOTH_BRICK:0)
Block(-4,29,5,SMOOTH_STAIRS:2)
Block(-4,29,6,SMOOTH_BRICK:2)
Block(-4,29,7,SMOOTH_BRICK:0)
Block(-4,29,8,SMOOTH_BRICK:0)
Block(-4,30,6,LEAVES:4)
Block(-4,30,8,STEP:5)
Block(-4,35,8,COBBLESTONE_STAIRS:6)
Block(-4,36,8,STEP:0)
Block(-3,0,-7,STONE:0)
Block(-3,0,-6,STONE:0)
Block(-3,0,-5,STONE:0)
Block(-3,0,-4,STONE:0)
Block(-3,0,-3,STONE:0)
Block(-3,0,-2,STONE:0)
Block(-3,0,-1,STONE:0)
Block(-3,0,0,STONE:0)
Block(-3,0,1,STONE:0)
Block(-3,0,2,STONE:0)
Block(-3,0,3,STONE:0)
Block(-3,0,4,STONE:0)
Block(-3,0,5,STONE:0)
Block(-3,0,6,STONE:0)
Block(-3,0,7,STONE:0)
Block(-3,0,8,STONE:0)
Block(-3,1,-7,STONE:0)
Block(-3,1,-6,STONE:0)
Block(-3,1,-5,STONE:0)
Block(-3,1,-4,STONE:0)
Block(-3,1,-3,STONE:0)
Block(-3,1,-2,STONE:0)
Block(-3,1,-1,STONE:0)
Block(-3,1,0,STONE:0)
Block(-3,1,1,STONE:0)
Block(-3,1,2,STONE:0)
Block(-3,1,3,STONE:0)
Block(-3,1,4,STONE:0)
Block(-3,1,5,STONE:0)
Block(-3,1,6,STONE:0)
Block(-3,1,7,STONE:0)
Block(-3,1,8,STONE:0)
Block(-3,2,-7,STONE:0)
Block(-3,2,-6,STONE:0)
Block(-3,2,-5,STONE:0)
Block(-3,2,-4,STONE:0)
Block(-3,2,-3,STONE:0)
Block(-3,2,-2,STONE:0)
Block(-3,2,-1,STONE:0)
Block(-3,2,0,STONE:0)
Block(-3,2,1,STONE:0)
Block(-3,2,2,STONE:0)
Block(-3,2,3,STONE:0)
Block(-3,2,4,STONE:0)
Block(-3,2,5,STONE:0)
Block(-3,2,6,STONE:0)
Block(-3,2,7,STONE:0)
Block(-3,2,8,STONE:0)
Block(-3,3,-7,STONE:0)
Block(-3,3,-6,STONE:0)
Block(-3,3,-5,STONE:0)
Block(-3,3,-4,STONE:0)
Block(-3,3,-3,STONE:0)
Block(-3,3,-2,STONE:0)
Block(-3,3,-1,STONE:0)
Block(-3,3,0,STONE:0)
Block(-3,3,1,STONE:0)
Block(-3,3,2,SMOOTH_BRICK:2)
Block(-3,3,3,STONE:0)
Block(-3,3,4,STONE:0)
Block(-3,3,5,STONE:0)
Block(-3,3,6,STONE:0)
Block(-3,3,7,STONE:0)
Block(-3,3,8,STONE:0)
Block(-3,4,-7,GRASS:0)
Block(-3,4,-6,GRASS:0)
Block(-3,4,-5,GRASS:0)
Block(-3,4,-4,STONE:0)
Block(-3,4,-3,STONE:0)
Block(-3,4,-2,STONE:0)
Block(-3,4,-1,STONE:0)
Block(-3,4,0,STONE:0)
Block(-3,4,1,STONE:0)
Block(-3,4,2,SMOOTH_BRICK:2)
Block(-3,4,3,GRASS:0)
Block(-3,4,4,GRASS:0)
Block(-3,4,5,GRASS:0)
Block(-3,4,6,STONE:0)
Block(-3,4,7,STONE:0)
Block(-3,4,8,STONE:0)
Block(-3,5,-7,LONG_GRASS:1)
Block(-3,5,-6,LONG_GRASS:1)
Block(-3,5,-4,GRASS:0)
Block(-3,5,-3,GRASS:0)
Block(-3,5,-2,GRASS:0)
Block(-3,5,-1,GRASS:0)
Block(-3,5,0,GRASS:0)
Block(-3,5,1,GRASS:0)
Block(-3,5,2,SMOOTH_BRICK:1)
Block(-3,5,6,GRASS:0)
Block(-3,5,7,GRASS:0)
Block(-3,5,8,STONE:0)
Block(-3,6,-6,VINE:1)
Block(-3,6,1,LONG_GRASS:1)
Block(-3,6,2,SMOOTH_BRICK:1)
Block(-3,6,8,GRASS:0)
Block(-3,7,-6,VINE:1)
Block(-3,7,2,SMOOTH_BRICK:0)
Block(-3,8,-6,VINE:1)
Block(-3,8,2,SMOOTH_BRICK:1)
Block(-3,9,-6,VINE:1)
Block(-3,9,1,LEAVES:4)
Block(-3,9,2,SMOOTH_BRICK:2)
Block(-3,10,-6,VINE:1)
Block(-3,10,1,LEAVES:4)
Block(-3,10,2,SMOOTH_BRICK:1)
Block(-3,11,-6,VINE:1)
Block(-3,11,2,SMOOTH_BRICK:1)
Block(-3,11,3,SMOOTH_BRICK:0)
Block(-3,11,4,SMOOTH_STAIRS:1)
Block(-3,11,5,SMOOTH_BRICK:2)
Block(-3,11,7,SMOOTH_STAIRS:1)
Block(-3,11,8,SMOOTH_BRICK:2)
Block(-3,12,-6,VINE:1)
Block(-3,12,1,LEAVES:4)
Block(-3,12,2,SMOOTH_BRICK:1)
Block(-3,12,3,COBBLE_WALL:0)
Block(-3,12,5,COBBLE_WALL:0)
Block(-3,13,-6,VINE:1)
Block(-3,13,1,LEAVES:4)
Block(-3,13,2,SMOOTH_BRICK:0)
Block(-3,14,-6,VINE:1)
Block(-3,14,1,LEAVES:4)
Block(-3,14,2,SMOOTH_BRICK:1)
Block(-3,15,-6,VINE:1)
Block(-3,15,1,LEAVES:4)
Block(-3,15,2,SMOOTH_BRICK:1)
Block(-3,15,3,COBBLE_WALL:0)
Block(-3,16,-6,VINE:1)
Block(-3,16,1,LEAVES:4)
Block(-3,16,2,SMOOTH_BRICK:0)
Block(-3,17,-6,VINE:1)
Block(-3,17,-4,SMOOTH_BRICK:0)
Block(-3,17,-3,COBBLESTONE:0)
Block(-3,17,-2,SMOOTH_BRICK:0)
Block(-3,17,0,LEAVES:4)
Block(-3,17,1,LEAVES:4)
Block(-3,17,2,SMOOTH_BRICK:1)
Block(-3,18,-6,VINE:1)
Block(-3,18,-4,COBBLESTONE:0)
Block(-3,18,-2,COBBLESTONE:0)
Block(-3,18,1,LEAVES:4)
Block(-3,18,2,SMOOTH_BRICK:1)
Block(-3,19,-6,VINE:1)
Block(-3,19,-4,SMOOTH_BRICK:2)
Block(-3,19,-3,COBBLESTONE:0)
Block(-3,19,-2,SMOOTH_BRICK:0)
Block(-3,19,-1,SMOOTH_BRICK:2)
Block(-3,19,0,SMOOTH_BRICK:0)
Block(-3,19,1,SMOOTH_BRICK:2)
Block(-3,19,2,SMOOTH_BRICK:1)
Block(-3,20,-6,VINE:1)
Block(-3,20,-5,COBBLE_WALL:0)
Block(-3,20,-4,SMOOTH_BRICK:2)
Block(-3,20,-3,LEAVES:4)
Block(-3,20,-2,LEAVES:4)
Block(-3,20,2,SMOOTH_BRICK:2)
Block(-3,21,-6,VINE:1)
Block(-3,21,-4,SMOOTH_BRICK:2)
Block(-3,21,-3,LEAVES:4)
Block(-3,21,2,SMOOTH_STAIRS:0)
Block(-3,22,-6,VINE:1)
Block(-3,22,-4,SMOOTH_BRICK:3)
Block(-3,22,-3,LEAVES:4)
Block(-3,22,2,SMOOTH_STAIRS:6)
Block(-3,23,-6,VINE:1)
Block(-3,23,-4,SMOOTH_BRICK:0)
Block(-3,23,-3,LEAVES:4)
Block(-3,23,2,SMOOTH_STAIRS:0)
Block(-3,24,-6,VINE:1)
Block(-3,24,-5,LEAVES:4)
Block(-3,24,-4,COBBLESTONE:0)
Block(-3,24,-3,LEAVES:4)
Block(-3,25,-6,VINE:1)
Block(-3,25,-5,LEAVES:4)
Block(-3,25,-4,COBBLESTONE_STAIRS:2)
Block(-3,25,-3,LEAVES:4)
Block(-3,26,-4,LEAVES:4)
Block(-3,26,6,SMOOTH_STAIRS:5)
Block(-3,27,-4,LEAVES:4)
Block(-3,27,6,SMOOTH_BRICK:0)
Block(-3,27,8,SMOOTH_STAIRS:5)
Block(-3,28,6,SMOOTH_BRICK:0)
Block(-3,28,8,SMOOTH_BRICK:0)
Block(-3,29,4,STEP:5)
Block(-3,29,5,SMOOTH_BRICK:1)
Block(-3,29,6,SMOOTH_BRICK:2)
Block(-3,29,7,SMOOTH_BRICK:0)
Block(-3,29,8,SMOOTH_BRICK:1)
Block(-3,30,8,STEP:5)
Block(-3,35,8,SMOOTH_BRICK:0)
Block(-3,36,7,STONE_BUTTON:4)
Block(-3,36,8,DOUBLE_STEP:8)
Block(-3,37,8,COBBLESTONE_STAIRS:2)
Block(-2,0,-7,STONE:0)
Block(-2,0,-6,STONE:0)
Block(-2,0,-5,STONE:0)
Block(-2,0,-4,STONE:0)
Block(-2,0,-3,STONE:0)
Block(-2,0,-2,STONE:0)
Block(-2,0,-1,STONE:0)
Block(-2,0,0,STONE:0)
Block(-2,0,1,STONE:0)
Block(-2,0,2,STONE:0)
Block(-2,0,3,STONE:0)
Block(-2,0,4,STONE:0)
Block(-2,0,5,STONE:0)
Block(-2,0,6,STONE:0)
Block(-2,0,7,STONE:0)
Block(-2,0,8,STONE:0)
Block(-2,1,-7,STONE:0)
Block(-2,1,-6,STONE:0)
Block(-2,1,-5,STONE:0)
Block(-2,1,-4,STONE:0)
Block(-2,1,-3,STONE:0)
Block(-2,1,-2,STONE:0)
Block(-2,1,-1,STONE:0)
Block(-2,1,0,STONE:0)
Block(-2,1,1,STONE:0)
Block(-2,1,2,STONE:0)
Block(-2,1,3,STONE:0)
Block(-2,1,4,STONE:0)
Block(-2,1,5,STONE:0)
Block(-2,1,6,STONE:0)
Block(-2,1,7,STONE:0)
Block(-2,1,8,STONE:0)
Block(-2,2,-7,STONE:0)
Block(-2,2,-6,STONE:0)
Block(-2,2,-5,STONE:0)
Block(-2,2,-4,STONE:0)
Block(-2,2,-3,STONE:0)
Block(-2,2,-2,STONE:0)
Block(-2,2,-1,STONE:0)
Block(-2,2,0,STONE:0)
Block(-2,2,1,STONE:0)
Block(-2,2,2,STONE:0)
Block(-2,2,3,STONE:0)
Block(-2,2,4,STONE:0)
Block(-2,2,5,STONE:0)
Block(-2,2,6,STONE:0)
Block(-2,2,7,STONE:0)
Block(-2,2,8,STONE:0)
Block(-2,3,-7,STONE:0)
Block(-2,3,-6,STONE:0)
Block(-2,3,-5,STONE:0)
Block(-2,3,-4,STONE:0)
Block(-2,3,-3,STONE:0)
Block(-2,3,-2,STONE:0)
Block(-2,3,-1,STONE:0)
Block(-2,3,0,STONE:0)
Block(-2,3,1,STONE:0)
Block(-2,3,2,SMOOTH_BRICK:0)
Block(-2,3,3,STONE:0)
Block(-2,3,4,STONE:0)
Block(-2,3,5,STONE:0)
Block(-2,3,6,STONE:0)
Block(-2,3,7,STONE:0)
Block(-2,3,8,STONE:0)
Block(-2,4,-7,GRASS:0)
Block(-2,4,-6,GRASS:0)
Block(-2,4,-5,STONE:0)
Block(-2,4,-4,STONE:0)
Block(-2,4,-3,STONE:0)
Block(-2,4,-2,STONE:0)
Block(-2,4,-1,STONE:0)
Block(-2,4,0,STONE:0)
Block(-2,4,1,STONE:0)
Block(-2,4,2,SMOOTH_BRICK:2)
Block(-2,4,3,GRASS:0)
Block(-2,4,4,GRASS:0)
Block(-2,4,5,STONE:0)
Block(-2,4,6,STONE:0)
Block(-2,4,7,STONE:0)
Block(-2,4,8,STONE:0)
Block(-2,5,-6,LONG_GRASS:1)
Block(-2,5,-5,GRASS:0)
Block(-2,5,-4,GRASS:0)
Block(-2,5,-3,GRASS:0)
Block(-2,5,-2,GRASS:0)
Block(-2,5,-1,GRASS:0)
Block(-2,5,0,GRASS:0)
Block(-2,5,1,GRASS:0)
Block(-2,5,2,SMOOTH_BRICK:2)
Block(-2,5,5,GRASS:0)
Block(-2,5,6,GRASS:0)
Block(-2,5,7,STONE:0)
Block(-2,5,8,STONE:0)
Block(-2,6,-6,VINE:1)
Block(-2,6,-3,VINE:8)
Block(-2,6,2,SMOOTH_BRICK:2)
Block(-2,6,7,GRASS:0)
Block(-2,6,8,GRASS:0)
Block(-2,7,-6,VINE:1)
Block(-2,7,-3,VINE:8)
Block(-2,7,2,SMOOTH_BRICK:2)
Block(-2,8,-6,VINE:1)
Block(-2,8,-3,VINE:8)
Block(-2,8,2,SMOOTH_BRICK:1)
Block(-2,9,-6,VINE:1)
Block(-2,9,-3,VINE:8)
Block(-2,9,2,SMOOTH_BRICK:0)
Block(-2,10,-6,VINE:1)
Block(-2,10,-3,VINE:8)
Block(-2,10,2,SMOOTH_BRICK:1)
Block(-2,11,-6,VINE:1)
Block(-2,11,-3,VINE:8)
Block(-2,11,1,LEAVES:4)
Block(-2,11,2,SMOOTH_BRICK:2)
Block(-2,11,3,SMOOTH_BRICK:1)
Block(-2,11,5,STEP:5)
Block(-2,11,7,SMOOTH_BRICK:1)
Block(-2,11,8,SMOOTH_BRICK:0)
Block(-2,12,-6,VINE:1)
Block(-2,12,-3,VINE:8)
Block(-2,12,1,LEAVES:4)
Block(-2,12,2,SMOOTH_BRICK:1)
Block(-2,12,3,COBBLE_WALL:0)
Block(-2,13,-6,VINE:1)
Block(-2,13,-3,VINE:8)
Block(-2,13,0,LEAVES:4)
Block(-2,13,1,LEAVES:4)
Block(-2,13,2,SMOOTH_BRICK:2)
Block(-2,13,3,COBBLE_WALL:0)
Block(-2,14,-6,VINE:1)
Block(-2,14,-3,VINE:8)
Block(-2,14,2,SMOOTH_BRICK:2)
Block(-2,14,3,COBBLE_WALL:0)
Block(-2,15,-6,VINE:1)
Block(-2,15,0,LEAVES:4)
Block(-2,15,1,LEAVES:4)
Block(-2,15,2,SMOOTH_BRICK:1)
Block(-2,15,3,COBBLE_WALL:0)
Block(-2,16,-6,VINE:1)
Block(-2,16,-4,SMOOTH_BRICK:1)
Block(-2,16,-3,COBBLESTONE:0)
Block(-2,16,-2,SMOOTH_BRICK:2)
Block(-2,16,1,LEAVES:4)
Block(-2,16,2,SMOOTH_BRICK:0)
Block(-2,16,3,COBBLE_WALL:0)
Block(-2,17,-6,VINE:1)
Block(-2,17,-4,COBBLESTONE:0)
Block(-2,17,-2,MOSSY_COBBLESTONE:0)
Block(-2,17,2,SMOOTH_BRICK:2)
Block(-2,17,3,DOUBLE_STEP:5)
Block(-2,17,4,STEP:5)
Block(-2,18,-6,VINE:1)
Block(-2,18,-4,COBBLESTONE:0)
Block(-2,18,-2,COBBLESTONE:0)
Block(-2,18,1,LEAVES:4)
Block(-2,18,2,SMOOTH_BRICK:0)
Block(-2,19,-6,VINE:1)
Block(-2,19,-5,COBBLE_WALL:0)
Block(-2,19,-4,SMOOTH_BRICK:0)
Block(-2,19,-3,COBBLESTONE:0)
Block(-2,19,-2,SMOOTH_BRICK:2)
Block(-2,19,-1,SMOOTH_BRICK:1)
Block(-2,19,0,SMOOTH_BRICK:2)
Block(-2,19,1,SMOOTH_BRICK:0)
Block(-2,19,2,SMOOTH_BRICK:1)
Block(-2,20,-6,VINE:1)
Block(-2,20,-5,SMOOTH_BRICK:2)
Block(-2,20,-4,SMOOTH_STAIRS:1)
Block(-2,20,-3,LEAVES:4)
Block(-2,20,-2,STEP:3)
Block(-2,20,1,VINE:8)
Block(-2,20,2,SMOOTH_BRICK:2)
Block(-2,21,-5,VINE:1)
Block(-2,21,-3,LEAVES:4)
Block(-2,21,1,VINE:8)
Block(-2,21,2,SMOOTH_BRICK:1)
Block(-2,22,-5,VINE:1)
Block(-2,22,1,VINE:8)
Block(-2,22,2,SMOOTH_BRICK:2)
Block(-2,23,-5,VINE:1)
Block(-2,23,1,VINE:8)
Block(-2,23,2,SMOOTH_BRICK:1)
Block(-2,24,-5,VINE:1)
Block(-2,24,-4,SMOOTH_BRICK:0)
Block(-2,24,1,VINE:8)
Block(-2,24,2,SMOOTH_STAIRS:4)
Block(-2,25,-5,VINE:1)
Block(-2,25,-4,COBBLESTONE:0)
Block(-2,25,-3,LEAVES:4)
Block(-2,25,1,VINE:8)
Block(-2,25,2,SMOOTH_STAIRS:2)
Block(-2,26,-4,LEAVES:4)
Block(-2,27,6,SMOOTH_STAIRS:5)
Block(-2,28,6,SMOOTH_BRICK:0)
Block(-2,28,8,SMOOTH_STAIRS:5)
Block(-2,29,3,SMOOTH_BRICK:2)
Block(-2,29,4,SMOOTH_STAIRS:4)
Block(-2,29,5,SMOOTH_BRICK:2)
Block(-2,29,6,SMOOTH_BRICK:2)
Block(-2,29,7,SMOOTH_BRICK:1)
Block(-2,29,8,SMOOTH_BRICK:2)
Block(-2,30,8,STEP:5)
Block(-2,35,8,COBBLESTONE_STAIRS:6)
Block(-2,36,8,STEP:0)
Block(-1,0,-7,STONE:0)
Block(-1,0,-6,STONE:0)
Block(-1,0,-5,STONE:0)
Block(-1,0,-4,STONE:0)
Block(-1,0,-3,STONE:0)
Block(-1,0,-2,STONE:0)
Block(-1,0,-1,STONE:0)
Block(-1,0,0,STONE:0)
Block(-1,0,1,STONE:0)
Block(-1,0,2,STONE:0)
Block(-1,0,3,STONE:0)
Block(-1,0,4,STONE:0)
Block(-1,0,5,STONE:0)
Block(-1,0,6,STONE:0)
Block(-1,0,7,STONE:0)
Block(-1,0,8,STONE:0)
Block(-1,1,-7,STONE:0)
Block(-1,1,-6,STONE:0)
Block(-1,1,-5,STONE:0)
Block(-1,1,-4,STONE:0)
Block(-1,1,-3,STONE:0)
Block(-1,1,-2,STONE:0)
Block(-1,1,-1,STONE:0)
Block(-1,1,0,STONE:0)
Block(-1,1,1,STONE:0)
Block(-1,1,2,STONE:0)
Block(-1,1,3,STONE:0)
Block(-1,1,4,STONE:0)
Block(-1,1,5,STONE:0)
Block(-1,1,6,STONE:0)
Block(-1,1,7,STONE:0)
Block(-1,1,8,STONE:0)
Block(-1,2,-7,STONE:0)
Block(-1,2,-6,STONE:0)
Block(-1,2,-5,STONE:0)
Block(-1,2,-4,STONE:0)
Block(-1,2,-3,STONE:0)
Block(-1,2,-2,STONE:0)
Block(-1,2,-1,STONE:0)
Block(-1,2,0,STONE:0)
Block(-1,2,1,STONE:0)
Block(-1,2,2,STONE:0)
Block(-1,2,3,STONE:0)
Block(-1,2,4,STONE:0)
Block(-1,2,5,STONE:0)
Block(-1,2,6,STONE:0)
Block(-1,2,7,STONE:0)
Block(-1,2,8,STONE:0)
Block(-1,3,-7,STONE:0)
Block(-1,3,-6,STONE:0)
Block(-1,3,-5,STONE:0)
Block(-1,3,-4,STONE:0)
Block(-1,3,-3,STONE:0)
Block(-1,3,-2,STONE:0)
Block(-1,3,-1,STONE:0)
Block(-1,3,0,STONE:0)
Block(-1,3,1,SMOOTH_BRICK:2)
Block(-1,3,2,STONE:0)
Block(-1,3,3,STONE:0)
Block(-1,3,4,STONE:0)
Block(-1,3,5,STONE:0)
Block(-1,3,6,STONE:0)
Block(-1,3,7,STONE:0)
Block(-1,3,8,STONE:0)
Block(-1,4,-7,STONE:0)
Block(-1,4,-6,STONE:0)
Block(-1,4,-5,STONE:0)
Block(-1,4,-4,STONE:0)
Block(-1,4,-3,STONE:0)
Block(-1,4,-2,STONE:0)
Block(-1,4,-1,STONE:0)
Block(-1,4,0,STONE:0)
Block(-1,4,1,SMOOTH_BRICK:2)
Block(-1,4,2,STONE:0)
Block(-1,4,3,STONE:0)
Block(-1,4,4,STONE:0)
Block(-1,4,5,STONE:0)
Block(-1,4,6,STONE:0)
Block(-1,4,7,STONE:0)
Block(-1,4,8,STONE:0)
Block(-1,5,-7,GRASS:0)
Block(-1,5,-6,GRASS:0)
Block(-1,5,-5,STONE:0)
Block(-1,5,-4,STONE:0)
Block(-1,5,-3,GRASS:0)
Block(-1,5,-2,DIRT:0)
Block(-1,5,-1,GRASS:0)
Block(-1,5,0,DIRT:0)
Block(-1,5,1,SMOOTH_BRICK:1)
Block(-1,5,2,GRASS:0)
Block(-1,5,3,GRASS:0)
Block(-1,5,4,GRASS:0)
Block(-1,5,5,GRASS:0)
Block(-1,5,6,STONE:0)
Block(-1,5,7,STONE:0)
Block(-1,5,8,STONE:0)
Block(-1,6,-7,LONG_GRASS:1)
Block(-1,6,-5,GRASS:0)
Block(-1,6,-4,GRASS:0)
Block(-1,6,-3,LONG_GRASS:1)
Block(-1,6,-2,SMOOTH_STAIRS:0)
Block(-1,6,0,STEP:0)
Block(-1,6,1,SMOOTH_BRICK:1)
Block(-1,6,6,GRASS:0)
Block(-1,6,7,GRASS:0)
Block(-1,6,8,STONE:0)
Block(-1,7,-4,RED_ROSE:0)
Block(-1,7,-2,VINE:8)
Block(-1,7,1,SMOOTH_BRICK:2)
Block(-1,7,8,GRASS:0)
Block(-1,8,-4,VINE:8)
Block(-1,8,-2,VINE:8)
Block(-1,8,1,SMOOTH_BRICK:1)
Block(-1,9,-4,VINE:8)
Block(-1,9,-2,VINE:8)
Block(-1,9,1,SMOOTH_BRICK:2)
Block(-1,10,-2,VINE:8)
Block(-1,10,1,SMOOTH_BRICK:1)
Block(-1,11,-2,VINE:8)
Block(-1,11,1,SMOOTH_BRICK:2)
Block(-1,11,2,SMOOTH_BRICK:0)
Block(-1,11,3,STEP:13)
Block(-1,11,6,SMOOTH_BRICK:2)
Block(-1,11,7,SMOOTH_BRICK:2)
Block(-1,11,8,SMOOTH_BRICK:2)
Block(-1,12,-2,VINE:8)
Block(-1,12,1,SMOOTH_BRICK:0)
Block(-1,12,2,COBBLE_WALL:0)
Block(-1,12,3,COBBLE_WALL:0)
Block(-1,12,8,STEP:5)
Block(-1,13,-2,VINE:8)
Block(-1,13,1,SMOOTH_BRICK:0)
Block(-1,13,2,COBBLE_WALL:0)
Block(-1,13,3,COBBLE_WALL:0)
Block(-1,14,-4,SMOOTH_BRICK:1)
Block(-1,14,-3,COBBLESTONE:0)
Block(-1,14,-2,SMOOTH_BRICK:0)
Block(-1,14,1,SMOOTH_BRICK:2)
Block(-1,14,2,COBBLE_WALL:0)
Block(-1,15,-4,SMOOTH_BRICK:0)
Block(-1,15,-3,MOSSY_COBBLESTONE:0)
Block(-1,15,-2,SMOOTH_BRICK:0)
Block(-1,15,1,SMOOTH_BRICK:1)
Block(-1,15,2,COBBLE_WALL:0)
Block(-1,16,-4,COBBLESTONE:0)
Block(-1,16,-2,COBBLESTONE:0)
Block(-1,16,1,SMOOTH_BRICK:1)
Block(-1,16,2,COBBLE_WALL:0)
Block(-1,17,-4,COBBLESTONE:0)
Block(-1,17,-2,COBBLESTONE:0)
Block(-1,17,0,STEP:0)
Block(-1,17,1,SMOOTH_BRICK:1)
Block(-1,17,2,STEP:5)
Block(-1,17,3,STEP:5)
Block(-1,18,-5,SMOOTH_STAIRS:0)
Block(-1,18,-4,COBBLESTONE:0)
Block(-1,18,-2,COBBLESTONE:0)
Block(-1,18,1,SMOOTH_BRICK:0)
Block(-1,19,-5,COBBLE_WALL:0)
Block(-1,19,-4,SMOOTH_BRICK:0)
Block(-1,19,-3,COBBLESTONE:0)
Block(-1,19,-2,SMOOTH_BRICK:1)
Block(-1,19,-1,SMOOTH_BRICK:1)
Block(-1,19,0,SMOOTH_BRICK:2)
Block(-1,19,1,SMOOTH_BRICK:2)
Block(-1,20,-5,COBBLE_WALL:0)
Block(-1,20,-4,LEAVES:4)
Block(-1,20,-3,LEAVES:4)
Block(-1,20,0,VINE:1)
Block(-1,20,1,SMOOTH_BRICK:0)
Block(-1,21,0,VINE:1)
Block(-1,21,1,SMOOTH_BRICK:2)
Block(-1,22,0,VINE:1)
Block(-1,22,1,SMOOTH_BRICK:1)
Block(-1,23,0,VINE:1)
Block(-1,23,1,SMOOTH_STAIRS:1)
Block(-1,24,0,VINE:1)
Block(-1,24,1,SMOOTH_BRICK:2)
Block(-1,24,2,SMOOTH_STAIRS:7)
Block(-1,25,-4,SMOOTH_BRICK:0)
Block(-1,25,0,VINE:1)
Block(-1,25,1,SMOOTH_BRICK:1)
Block(-1,26,-4,COBBLESTONE_STAIRS:2)
Block(-1,26,1,SMOOTH_STAIRS:0)
Block(-1,27,1,SMOOTH_STAIRS:4)
Block(-1,27,4,SMOOTH_BRICK:0)
Block(-1,27,5,SMOOTH_STAIRS:7)
Block(-1,28,1,SMOOTH_BRICK:0)
Block(-1,28,2,SMOOTH_BRICK:0)
Block(-1,28,3,SMOOTH_BRICK:0)
Block(-1,28,4,SMOOTH_BRICK:0)
Block(-1,28,5,SMOOTH_BRICK:0)
Block(-1,28,6,STEP:13)
Block(-1,28,8,STEP:13)
Block(-1,29,0,COBBLESTONE_STAIRS:6)
Block(-1,29,1,SMOOTH_BRICK:0)
Block(-1,29,2,SMOOTH_STAIRS:0)
Block(-1,29,3,SMOOTH_BRICK:2)
Block(-1,29,4,SMOOTH_BRICK:0)
Block(-1,29,5,SMOOTH_BRICK:0)
Block(-1,29,6,SMOOTH_BRICK:2)
Block(-1,29,7,SMOOTH_BRICK:1)
Block(-1,29,8,SMOOTH_BRICK:0)
Block(-1,30,0,DOUBLE_STEP:8)
Block(-1,30,8,LEAVES:4)
Block(-1,31,8,LEAVES:4)
Block(-1,36,7,STONE_BUTTON:4)
Block(-1,36,8,DOUBLE_STEP:8)
Block(0,0,-7,STONE:0)
Block(0,0,-6,STONE:0)
Block(0,0,-5,STONE:0)
Block(0,0,-4,STONE:0)
Block(0,0,-3,STONE:0)
Block(0,0,-2,STONE:0)
Block(0,0,-1,STONE:0)
Block(0,0,0,STONE:0)
Block(0,0,1,STONE:0)
Block(0,0,2,STONE:0)
Block(0,0,3,STONE:0)
Block(0,0,4,STONE:0)
Block(0,0,5,STONE:0)
Block(0,0,6,STONE:0)
Block(0,0,7,STONE:0)
Block(0,0,8,STONE:0)
Block(0,1,-7,STONE:0)
Block(0,1,-6,STONE:0)
Block(0,1,-5,STONE:0)
Block(0,1,-4,STONE:0)
Block(0,1,-3,STONE:0)
Block(0,1,-2,STONE:0)
Block(0,1,-1,STONE:0)
Block(0,1,0,STONE:0)
Block(0,1,1,STONE:0)
Block(0,1,2,STONE:0)
Block(0,1,3,STONE:0)
Block(0,1,4,STONE:0)
Block(0,1,5,STONE:0)
Block(0,1,6,STONE:0)
Block(0,1,7,STONE:0)
Block(0,1,8,STONE:0)
Block(0,2,-7,STONE:0)
Block(0,2,-6,STONE:0)
Block(0,2,-5,STONE:0)
Block(0,2,-4,STONE:0)
Block(0,2,-3,STONE:0)
Block(0,2,-2,STONE:0)
Block(0,2,-1,STONE:0)
Block(0,2,0,STONE:0)
Block(0,2,1,STONE:0)
Block(0,2,2,STONE:0)
Block(0,2,3,STONE:0)
Block(0,2,4,STONE:0)
Block(0,2,5,STONE:0)
Block(0,2,6,STONE:0)
Block(0,2,7,STONE:0)
Block(0,2,8,STONE:0)
Block(0,3,-7,STONE:0)
Block(0,3,-6,STONE:0)
Block(0,3,-5,STONE:0)
Block(0,3,-4,STONE:0)
Block(0,3,-3,STONE:0)
Block(0,3,-2,STONE:0)
Block(0,3,-1,STONE:0)
Block(0,3,0,STONE:0)
Block(0,3,1,SMOOTH_BRICK:0)
Block(0,3,2,STONE:0)
Block(0,3,3,STONE:0)
Block(0,3,4,STONE:0)
Block(0,3,5,STONE:0)
Block(0,3,6,STONE:0)
Block(0,3,7,STONE:0)
Block(0,3,8,STONE:0)
Block(0,4,-7,STONE:0)
Block(0,4,-6,STONE:0)
Block(0,4,-5,STONE:0)
Block(0,4,-4,STONE:0)
Block(0,4,-3,STONE:0)
Block(0,4,-2,STONE:0)
Block(0,4,-1,STONE:0)
Block(0,4,0,STONE:0)
Block(0,4,1,SMOOTH_BRICK:1)
Block(0,4,2,STONE:0)
Block(0,4,3,STONE:0)
Block(0,4,4,STONE:0)
Block(0,4,5,STONE:0)
Block(0,4,6,STONE:0)
Block(0,4,7,STONE:0)
Block(0,4,8,STONE:0)
Block(0,5,-7,STONE:0)
Block(0,5,-6,STONE:0)
Block(0,5,-5,STONE:0)
Block(0,5,-4,STONE:0)
Block(0,5,-3,STONE:0)
Block(0,5,-2,STONE:0)
Block(0,5,-1,GRASS:0)
Block(0,5,0,GRASS:0)
Block(0,5,1,SMOOTH_BRICK:0)
Block(0,5,2,GRASS:0)
Block(0,5,3,GRASS:0)
Block(0,5,4,GRASS:0)
Block(0,5,5,STONE:0)
Block(0,5,6,STONE:0)
Block(0,5,7,STONE:0)
Block(0,5,8,STONE:0)
Block(0,6,-7,GRASS:0)
Block(0,6,-6,GRASS:0)
Block(0,6,-5,GRASS:0)
Block(0,6,-4,DIRT:0)
Block(0,6,-3,COBBLESTONE:0)
Block(0,6,-2,SMOOTH_BRICK:1)
Block(0,6,-1,YELLOW_FLOWER:0)
Block(0,6,1,SMOOTH_BRICK:0)
Block(0,6,5,GRASS:0)
Block(0,6,6,GRASS:0)
Block(0,6,7,STONE:0)
Block(0,6,8,STONE:0)
Block(0,7,-5,VINE:1)
Block(0,7,-4,SMOOTH_STAIRS:0)
Block(0,7,-3,COBBLESTONE:0)
Block(0,7,-2,SMOOTH_BRICK:2)
Block(0,7,-1,VINE:4)
Block(0,7,1,SMOOTH_BRICK:2)
Block(0,7,7,GRASS:0)
Block(0,7,8,GRASS:0)
Block(0,8,-5,VINE:1)
Block(0,8,-4,SMOOTH_STAIRS:6)
Block(0,8,-3,COBBLESTONE:0)
Block(0,8,-2,SMOOTH_BRICK:1)
Block(0,8,-1,VINE:4)
Block(0,8,1,SMOOTH_BRICK:1)
Block(0,9,-5,VINE:1)
Block(0,9,-4,SMOOTH_BRICK:1)
Block(0,9,-3,COBBLESTONE:0)
Block(0,9,-2,SMOOTH_BRICK:1)
Block(0,9,-1,VINE:4)
Block(0,9,1,SMOOTH_BRICK:2)
Block(0,10,-5,VINE:1)
Block(0,10,-4,SMOOTH_BRICK:2)
Block(0,10,-3,COBBLESTONE:0)
Block(0,10,-2,SMOOTH_BRICK:0)
Block(0,10,-1,VINE:4)
Block(0,10,1,SMOOTH_BRICK:1)
Block(0,10,2,STEP:13)
Block(0,11,-5,VINE:1)
Block(0,11,-4,SMOOTH_BRICK:0)
Block(0,11,-3,COBBLESTONE:0)
Block(0,11,-2,SMOOTH_BRICK:1)
Block(0,11,1,SMOOTH_BRICK:1)
Block(0,11,4,STEP:5)
Block(0,11,5,SMOOTH_STAIRS:0)
Block(0,11,6,SMOOTH_BRICK:2)
Block(0,11,7,SMOOTH_BRICK:1)
Block(0,11,8,SMOOTH_BRICK:0)
Block(0,12,-5,VINE:1)
Block(0,12,-4,SMOOTH_BRICK:2)
Block(0,12,-3,COBBLESTONE:0)
Block(0,12,-2,SMOOTH_BRICK:2)
Block(0,12,1,SMOOTH_BRICK:2)
Block(0,13,-5,VINE:1)
Block(0,13,-4,SMOOTH_BRICK:2)
Block(0,13,-3,COBBLESTONE:0)
Block(0,13,-2,SMOOTH_BRICK:1)
Block(0,13,-1,SMOOTH_STAIRS:7)
Block(0,13,1,SMOOTH_BRICK:0)
Block(0,14,-5,VINE:1)
Block(0,14,-4,COBBLESTONE:0)
Block(0,14,-3,COBBLE_WALL:0)
Block(0,14,-2,SMOOTH_BRICK:1)
Block(0,14,-1,SMOOTH_STAIRS:2)
Block(0,14,0,SMOOTH_STAIRS:7)
Block(0,14,1,SMOOTH_BRICK:0)
Block(0,14,2,COBBLE_WALL:0)
Block(0,15,-4,COBBLESTONE:0)
Block(0,15,-3,COBBLE_WALL:0)
Block(0,15,-2,SMOOTH_BRICK:2)
Block(0,15,0,SMOOTH_STAIRS:2)
Block(0,15,1,SMOOTH_BRICK:2)
Block(0,16,-5,SMOOTH_STAIRS:6)
Block(0,16,-4,COBBLESTONE:0)
Block(0,16,-3,COBBLE_WALL:0)
Block(0,16,-2,SMOOTH_BRICK:2)
Block(0,16,1,SMOOTH_BRICK:0)
Block(0,16,2,STEP:13)
Block(0,16,3,STEP:13)
Block(0,17,-5,COBBLE_WALL:0)
Block(0,17,-4,COBBLESTONE:0)
Block(0,17,-3,COBBLE_WALL:0)
Block(0,17,-2,SMOOTH_BRICK:0)
Block(0,17,0,STEP:0)
Block(0,17,1,SMOOTH_BRICK:0)
Block(0,18,-5,COBBLE_WALL:0)
Block(0,18,-4,COBBLESTONE:0)
Block(0,18,-3,COBBLE_WALL:0)
Block(0,18,-2,SMOOTH_BRICK:2)
Block(0,18,1,SMOOTH_BRICK:0)
Block(0,19,-5,COBBLE_WALL:0)
Block(0,19,-4,SMOOTH_BRICK:0)
Block(0,19,-3,SMOOTH_BRICK:0)
Block(0,19,-2,SMOOTH_BRICK:0)
Block(0,19,-1,SMOOTH_BRICK:2)
Block(0,19,0,SMOOTH_BRICK:2)
Block(0,19,1,SMOOTH_BRICK:0)
Block(0,20,-5,SMOOTH_BRICK:2)
Block(0,20,-4,SMOOTH_STAIRS:0)
Block(0,20,1,SMOOTH_BRICK:0)
Block(0,21,1,SMOOTH_BRICK:2)
Block(0,22,1,SMOOTH_BRICK:2)
Block(0,23,1,SMOOTH_BRICK:1)
Block(0,24,-4,SMOOTH_STAIRS:4)
Block(0,24,1,SMOOTH_STAIRS:6)
Block(0,25,-4,COBBLESTONE:0)
Block(0,25,1,SMOOTH_BRICK:0)
Block(0,26,-4,COBBLESTONE:0)
Block(0,26,1,SMOOTH_BRICK:1)
Block(0,27,0,COBBLESTONE_STAIRS:6)
Block(0,27,1,SMOOTH_BRICK:1)
Block(0,28,0,SMOOTH_BRICK:3)
Block(0,28,1,SMOOTH_BRICK:1)
Block(0,29,-1,STONE_BUTTON:4)
Block(0,29,0,DOUBLE_STEP:8)
Block(0,29,1,SMOOTH_BRICK:2)
Block(0,29,2,SMOOTH_BRICK:0)
Block(0,29,3,SMOOTH_BRICK:2)
Block(0,29,4,SMOOTH_BRICK:0)
Block(0,29,5,SMOOTH_BRICK:2)
Block(0,29,6,SMOOTH_BRICK:0)
Block(0,29,7,SMOOTH_BRICK:0)
Block(0,29,8,SMOOTH_BRICK:0)
Block(0,30,0,STEP:0)
Block(0,30,7,LEAVES:4)
Block(0,30,8,LEAVES:4)
Block(0,31,8,LEAVES:4)
Block(0,36,8,STONE_BUTTON:1)
Block(1,0,-7,STONE:0)
Block(1,0,-6,STONE:0)
Block(1,0,-5,STONE:0)
Block(1,0,-4,STONE:0)
Block(1,0,-3,STONE:0)
Block(1,0,-2,STONE:0)
Block(1,0,-1,STONE:0)
Block(1,0,0,STONE:0)
Block(1,0,1,STONE:0)
Block(1,0,2,STONE:0)
Block(1,0,3,STONE:0)
Block(1,0,4,STONE:0)
Block(1,0,5,STONE:0)
Block(1,0,6,STONE:0)
Block(1,0,7,STONE:0)
Block(1,0,8,STONE:0)
Block(1,1,-7,STONE:0)
Block(1,1,-6,STONE:0)
Block(1,1,-5,STONE:0)
Block(1,1,-4,STONE:0)
Block(1,1,-3,STONE:0)
Block(1,1,-2,STONE:0)
Block(1,1,-1,STONE:0)
Block(1,1,0,STONE:0)
Block(1,1,1,STONE:0)
Block(1,1,2,STONE:0)
Block(1,1,3,STONE:0)
Block(1,1,4,STONE:0)
Block(1,1,5,STONE:0)
Block(1,1,6,STONE:0)
Block(1,1,7,STONE:0)
Block(1,1,8,STONE:0)
Block(1,2,-7,STONE:0)
Block(1,2,-6,STONE:0)
Block(1,2,-5,STONE:0)
Block(1,2,-4,STONE:0)
Block(1,2,-3,STONE:0)
Block(1,2,-2,STONE:0)
Block(1,2,-1,STONE:0)
Block(1,2,0,STONE:0)
Block(1,2,1,STONE:0)
Block(1,2,2,STONE:0)
Block(1,2,3,STONE:0)
Block(1,2,4,STONE:0)
Block(1,2,5,STONE:0)
Block(1,2,6,STONE:0)
Block(1,2,7,STONE:0)
Block(1,2,8,STONE:0)
Block(1,3,-7,STONE:0)
Block(1,3,-6,STONE:0)
Block(1,3,-5,STONE:0)
Block(1,3,-4,STONE:0)
Block(1,3,-3,STONE:0)
Block(1,3,-2,STONE:0)
Block(1,3,-1,STONE:0)
Block(1,3,0,STONE:0)
Block(1,3,1,SMOOTH_BRICK:0)
Block(1,3,2,STONE:0)
Block(1,3,3,STONE:0)
Block(1,3,4,STONE:0)
Block(1,3,5,STONE:0)
Block(1,3,6,STONE:0)
Block(1,3,7,STONE:0)
Block(1,3,8,STONE:0)
Block(1,4,-7,STONE:0)
Block(1,4,-6,STONE:0)
Block(1,4,-5,STONE:0)
Block(1,4,-4,STONE:0)
Block(1,4,-3,STONE:0)
Block(1,4,-2,STONE:0)
Block(1,4,-1,STONE:0)
Block(1,4,0,STONE:0)
Block(1,4,1,SMOOTH_BRICK:1)
Block(1,4,2,STONE:0)
Block(1,4,3,STONE:0)
Block(1,4,4,STONE:0)
Block(1,4,5,STONE:0)
Block(1,4,6,STONE:0)
Block(1,4,7,STONE:0)
Block(1,4,8,STONE:0)
Block(1,5,-7,STONE:0)
Block(1,5,-6,STONE:0)
Block(1,5,-5,STONE:0)
Block(1,5,-4,STONE:0)
Block(1,5,-3,STONE:0)
Block(1,5,-2,STONE:0)
Block(1,5,-1,STONE:0)
Block(1,5,0,DIRT:0)
Block(1,5,1,SMOOTH_BRICK:1)
Block(1,5,2,GRASS:0)
Block(1,5,3,GRASS:0)
Block(1,5,4,GRASS:0)
Block(1,5,5,STONE:0)
Block(1,5,6,STONE:0)
Block(1,5,7,STONE:0)
Block(1,5,8,STONE:0)
Block(1,6,-7,GRASS:0)
Block(1,6,-6,GRASS:0)
Block(1,6,-5,STONE:0)
Block(1,6,-4,DIRT:0)
Block(1,6,-3,GRASS:0)
Block(1,6,-2,COBBLE_WALL:0)
Block(1,6,0,COBBLESTONE:0)
Block(1,6,1,SMOOTH_BRICK:1)
Block(1,6,5,GRASS:0)
Block(1,6,6,GRASS:0)
Block(1,6,7,STONE:0)
Block(1,6,8,STONE:0)
Block(1,7,-7,LONG_GRASS:1)
Block(1,7,-5,GRASS:0)
Block(1,7,-4,COBBLESTONE:0)
Block(1,7,-2,COBBLESTONE:0)
Block(1,7,1,SMOOTH_BRICK:0)
Block(1,7,7,GRASS:0)
Block(1,7,8,GRASS:0)
Block(1,8,-5,VINE:1)
Block(1,8,-4,COBBLESTONE:0)
Block(1,8,-2,COBBLESTONE:0)
Block(1,8,1,SMOOTH_BRICK:1)
Block(1,9,-5,VINE:1)
Block(1,9,-4,COBBLESTONE:0)
Block(1,9,-2,COBBLESTONE:0)
Block(1,9,1,SMOOTH_BRICK:0)
Block(1,10,-5,VINE:1)
Block(1,10,-3,COBBLESTONE:0)
Block(1,10,-2,COBBLESTONE:0)
Block(1,10,1,SMOOTH_BRICK:1)
Block(1,11,-5,VINE:1)
Block(1,11,-4,COBBLESTONE:0)
Block(1,11,-3,COBBLESTONE:0)
Block(1,11,-2,COBBLESTONE:0)
Block(1,11,1,SMOOTH_BRICK:1)
Block(1,11,2,SMOOTH_BRICK:2)
Block(1,11,3,STEP:5)
Block(1,11,4,SMOOTH_BRICK:1)
Block(1,11,5,SMOOTH_BRICK:0)
Block(1,11,6,SMOOTH_STAIRS:0)
Block(1,11,7,SMOOTH_BRICK:1)
Block(1,11,8,SMOOTH_BRICK:1)
Block(1,12,-5,VINE:1)
Block(1,12,-4,COBBLESTONE:0)
Block(1,12,-3,SMOOTH_BRICK:2)
Block(1,12,-2,COBBLESTONE:0)
Block(1,12,1,SMOOTH_BRICK:1)
Block(1,13,-5,VINE:1)
Block(1,13,-4,COBBLESTONE:0)
Block(1,13,-2,COBBLESTONE:0)
Block(1,13,1,SMOOTH_BRICK:1)
Block(1,14,-5,VINE:1)
Block(1,14,-4,COBBLESTONE:0)
Block(1,14,-2,COBBLESTONE:0)
Block(1,14,1,SMOOTH_BRICK:0)
Block(1,15,-5,SMOOTH_STAIRS:6)
Block(1,15,-4,COBBLESTONE:0)
Block(1,15,-2,COBBLESTONE:0)
Block(1,15,1,SMOOTH_BRICK:0)
Block(1,16,-5,COBBLE_WALL:0)
Block(1,16,-4,COBBLESTONE:0)
Block(1,16,-2,COBBLESTONE:0)
Block(1,16,1,SMOOTH_BRICK:1)
Block(1,16,2,STEP:5)
Block(1,16,3,STEP:5)
Block(1,17,-5,COBBLE_WALL:0)
Block(1,17,-4,MOSSY_COBBLESTONE:0)
Block(1,17,-2,COBBLESTONE:0)
Block(1,17,1,SMOOTH_BRICK:0)
Block(1,18,-5,SMOOTH_BRICK:2)
Block(1,18,-4,COBBLESTONE:0)
Block(1,18,-2,COBBLESTONE:0)
Block(1,18,1,SMOOTH_BRICK:0)
Block(1,19,-5,COBBLE_WALL:0)
Block(1,19,-4,SMOOTH_BRICK:2)
Block(1,19,-3,COBBLESTONE:0)
Block(1,19,-2,SMOOTH_BRICK:1)
Block(1,19,-1,SMOOTH_BRICK:2)
Block(1,19,0,SMOOTH_BRICK:1)
Block(1,19,1,SMOOTH_BRICK:2)
Block(1,20,-5,STEP:3)
Block(1,20,-4,SMOOTH_BRICK:2)
Block(1,20,-3,STEP:3)
Block(1,20,-1,VINE:1)
Block(1,20,1,DOUBLE_STEP:0)
Block(1,21,-5,VINE:1)
Block(1,21,-4,SMOOTH_STAIRS:6)
Block(1,21,-1,VINE:1)
Block(1,21,1,SMOOTH_BRICK:1)
Block(1,22,-5,VINE:1)
Block(1,22,-4,SMOOTH_BRICK:3)
Block(1,22,-1,VINE:1)
Block(1,22,1,SMOOTH_BRICK:1)
Block(1,23,-5,VINE:1)
Block(1,23,-4,SMOOTH_BRICK:0)
Block(1,23,-1,VINE:1)
Block(1,23,1,SMOOTH_BRICK:2)
Block(1,24,-5,VINE:1)
Block(1,24,-4,COBBLESTONE:0)
Block(1,24,-1,VINE:1)
Block(1,24,1,SMOOTH_BRICK:2)
Block(1,25,-4,COBBLESTONE_STAIRS:1)
Block(1,25,-1,VINE:1)
Block(1,25,1,SMOOTH_BRICK:2)
Block(1,25,2,SMOOTH_STAIRS:7)
Block(1,26,-1,VINE:1)
Block(1,26,1,SMOOTH_BRICK:1)
Block(1,26,2,SMOOTH_BRICK:0)
Block(1,26,3,SMOOTH_STAIRS:7)
Block(1,27,-1,VINE:1)
Block(1,27,1,SMOOTH_BRICK:1)
Block(1,27,2,SMOOTH_BRICK:0)
Block(1,27,3,SMOOTH_BRICK:0)
Block(1,27,4,SMOOTH_STAIRS:7)
Block(1,28,-1,VINE:1)
Block(1,28,1,SMOOTH_BRICK:1)
Block(1,28,2,SMOOTH_BRICK:0)
Block(1,28,3,SMOOTH_BRICK:0)
Block(1,28,4,SMOOTH_BRICK:0)
Block(1,28,5,SMOOTH_STAIRS:7)
Block(1,28,6,STEP:13)
Block(1,29,-1,VINE:1)
Block(1,29,0,COBBLESTONE_STAIRS:6)
Block(1,29,1,SMOOTH_BRICK:1)
Block(1,29,2,SMOOTH_BRICK:2)
Block(1,29,3,SMOOTH_BRICK:2)
Block(1,29,4,SMOOTH_BRICK:1)
Block(1,29,5,SMOOTH_BRICK:2)
Block(1,29,6,SMOOTH_BRICK:1)
Block(1,29,7,SMOOTH_BRICK:1)
Block(1,29,8,SMOOTH_BRICK:1)
Block(1,30,-1,VINE:1)
Block(1,30,0,DOUBLE_STEP:8)
Block(1,30,8,LEAVES:4)
Block(2,0,-7,STONE:0)
Block(2,0,-6,STONE:0)
Block(2,0,-5,STONE:0)
Block(2,0,-4,STONE:0)
Block(2,0,-3,STONE:0)
Block(2,0,-2,STONE:0)
Block(2,0,-1,STONE:0)
Block(2,0,0,STONE:0)
Block(2,0,1,STONE:0)
Block(2,0,2,STONE:0)
Block(2,0,3,STONE:0)
Block(2,0,4,STONE:0)
Block(2,0,5,STONE:0)
Block(2,0,6,STONE:0)
Block(2,0,7,STONE:0)
Block(2,0,8,STONE:0)
Block(2,1,-7,STONE:0)
Block(2,1,-6,STONE:0)
Block(2,1,-5,STONE:0)
Block(2,1,-4,STONE:0)
Block(2,1,-3,STONE:0)
Block(2,1,-2,STONE:0)
Block(2,1,-1,STONE:0)
Block(2,1,0,STONE:0)
Block(2,1,1,STONE:0)
Block(2,1,2,STONE:0)
Block(2,1,3,STONE:0)
Block(2,1,4,STONE:0)
Block(2,1,5,STONE:0)
Block(2,1,6,STONE:0)
Block(2,1,7,STONE:0)
Block(2,1,8,STONE:0)
Block(2,2,-7,STONE:0)
Block(2,2,-6,STONE:0)
Block(2,2,-5,STONE:0)
Block(2,2,-4,STONE:0)
Block(2,2,-3,STONE:0)
Block(2,2,-2,STONE:0)
Block(2,2,-1,STONE:0)
Block(2,2,0,STONE:0)
Block(2,2,1,STONE:0)
Block(2,2,2,STONE:0)
Block(2,2,3,STONE:0)
Block(2,2,4,STONE:0)
Block(2,2,5,STONE:0)
Block(2,2,6,STONE:0)
Block(2,2,7,STONE:0)
Block(2,2,8,STONE:0)
Block(2,3,-7,STONE:0)
Block(2,3,-6,STONE:0)
Block(2,3,-5,STONE:0)
Block(2,3,-4,STONE:0)
Block(2,3,-3,STONE:0)
Block(2,3,-2,STONE:0)
Block(2,3,-1,STONE:0)
Block(2,3,0,STONE:0)
Block(2,3,1,SMOOTH_BRICK:1)
Block(2,3,2,STONE:0)
Block(2,3,3,STONE:0)
Block(2,3,4,STONE:0)
Block(2,3,5,STONE:0)
Block(2,3,6,STONE:0)
Block(2,3,7,STONE:0)
Block(2,3,8,STONE:0)
Block(2,4,-7,STONE:0)
Block(2,4,-6,STONE:0)
Block(2,4,-5,STONE:0)
Block(2,4,-4,STONE:0)
Block(2,4,-3,STONE:0)
Block(2,4,-2,STONE:0)
Block(2,4,-1,STONE:0)
Block(2,4,0,STONE:0)
Block(2,4,1,SMOOTH_BRICK:1)
Block(2,4,2,STONE:0)
Block(2,4,3,STONE:0)
Block(2,4,4,STONE:0)
Block(2,4,5,STONE:0)
Block(2,4,6,STONE:0)
Block(2,4,7,STONE:0)
Block(2,4,8,STONE:0)
Block(2,5,-7,STONE:0)
Block(2,5,-6,STONE:0)
Block(2,5,-5,STONE:0)
Block(2,5,-4,STONE:0)
Block(2,5,-3,STONE:0)
Block(2,5,-2,STONE:0)
Block(2,5,-1,STONE:0)
Block(2,5,0,GRASS:0)
Block(2,5,1,SMOOTH_BRICK:0)
Block(2,5,2,GRASS:0)
Block(2,5,3,GRASS:0)
Block(2,5,4,GRASS:0)
Block(2,5,5,STONE:0)
Block(2,5,6,STONE:0)
Block(2,5,7,STONE:0)
Block(2,5,8,STONE:0)
Block(2,6,-7,STONE:0)
Block(2,6,-6,STONE:0)
Block(2,6,-5,STONE:0)
Block(2,6,-4,STONE:0)
Block(2,6,-3,STONE:0)
Block(2,6,-2,DIRT:0)
Block(2,6,-1,GRASS:0)
Block(2,6,0,LONG_GRASS:1)
Block(2,6,1,SMOOTH_BRICK:0)
RandomBlock(2,6,2,CHEST:3,../../../Chests/Loot/GildedBone_1.nbt,2,CHEST:3,../../../Chests/Loot/GildedBone_2.nbt,2,CHEST:3,../../../Chests/Loot/GildedBone_3.nbt,2,CHEST:3,../../../Chests/Loot/GildedBone_4.nbt,2,CHEST:3,../../../Chests/Loot/GildedBone_5.nbt,2,CHEST:3,../../../Chests/Lore/Ancient_1.nbt,1,CHEST:3,../../../Chests/Lore/Ancient_2.nbt,1,CHEST:3,../../../Chests/Lore/Ancient_3.nbt,1,CHEST:3,../../../Chests/Lore/Ancient_4.nbt,1,CHEST:3,../../../Chests/Lore/Ancient_5.nbt,1,CHEST:3,../../../Chests/Loot/Common1.nbt,5,CHEST:3,../../../Chests/Loot/Common2.nbt,5,CHEST:3,../../../Chests/Loot/Common3.nbt,5,CHEST:3,../../../Chests/Loot/Common4.nbt,5,CHEST:3,../../../Chests/Loot/Common5.nbt,5,CHEST:3,../../../Chests/Loot/Common6.nbt,5,CHEST:3,../../../Chests/Loot/Common7.nbt,5,CHEST:3,../../../Chests/Loot/Common8.nbt,5,CHEST:3,../../../Chests/Loot/Common9.nbt,5,CHEST:3,../../../Chests/Loot/Common10.nbt,5,CHEST:3,../../../Chests/Loot/Common11.nbt,5,CHEST:3,../../../Chests/Loot/Common12.nbt,5,CHEST:3,../../../Chests/Loot/Common13.nbt,5,CHEST:3,../../../Chests/Loot/Common14.nbt,5,CHEST:3,../../../Chests/Loot/Common15.nbt,5,CHEST:3,../../../Chests/Lore/Ancient_1.nbt,2,CHEST:3,../../../Chests/Lore/Ancient_2.nbt,2,CHEST:3,../../../Chests/Lore/Ancient_3.nbt,2,CHEST:3,../../../Chests/Lore/Ancient_4.nbt,2,CHEST:3,../../../Chests/Lore/Ancient_5.nbt,2,CHEST:3,../../../Chests/Loot/Rare1.nbt,5,CHEST:3,../../../Chests/Loot/Rare2.nbt,5,CHEST:3,../../../Chests/Loot/Rare3.nbt,5,CHEST:3,../../../Chests/Loot/Rare4.nbt,5,CHEST:3,../../../Chests/Loot/Rare5.nbt,5,CHEST:3,../../../Chests/Loot/Rare6.nbt,5,CHEST:3,../../../Chests/Loot/Rare7.nbt,5,CHEST:3,../../../Chests/Loot/Rare8.nbt,5,CHEST:3,../../../Chests/Loot/Rare9.nbt,5,CHEST:3,../../../Chests/Loot/Rare10.nbt,5,CHEST:3,../../../Chests/Loot/Rare11.nbt,5,CHEST:3,../../../Chests/Loot/Rare12.nbt,5,CHEST:3,../../../Chests/Loot/Rare13.nbt,5,CHEST:3,../../../Chests/Loot/Rare14.nbt,5,CHEST:3,../../../Chests/Loot/Rare15.nbt,5,CHEST:3,../../../Chests/Loot/Epic1.nbt,2,CHEST:3,../../../Chests/Loot/Epic2.nbt,2,CHEST:3,../../../Chests/Loot/Epic3.nbt,2,CHEST:3,../../../Chests/Loot/Epic4.nbt,2,CHEST:3,../../../Chests/Loot/Epic5.nbt,2,CHEST:3,../../../Chests/Loot/Epic6.nbt,2,CHEST:3,../../../Chests/Loot/Epic7.nbt,2,CHEST:3,../../../Chests/Loot/Epic8.nbt,2,CHEST:3,../../../Chests/Loot/Epic9.nbt,2,CHEST:3,../../../Chests/Loot/Epic10.nbt,2,CHEST:3,../../../Chests/Loot/Epic11.nbt,2,CHEST:3,../../../Chests/Loot/Epic12.nbt,2,CHEST:3,../../../Chests/Loot/Epic13.nbt,2,CHEST:3,../../../Chests/Loot/Epic14.nbt,2,CHEST:3,../../../Chests/Loot/Epic15.nbt,5,CHEST:3,../../../Chests/Loot/Rare1.nbt,5,CHEST:3,../../../Chests/Loot/Rare2.nbt,5,CHEST:3,../../../Chests/Loot/Rare3.nbt,5,CHEST:3,../../../Chests/Loot/Rare4.nbt,5,CHEST:3,../../../Chests/Loot/Rare5.nbt,10,CHEST:3,../../../Chests/Loot/Rare6.nbt,10,CHEST:3,../../../Chests/Loot/Rare7.nbt,10,CHEST:3,../../../Chests/Loot/Rare8.nbt,10,CHEST:3,../../../Chests/Loot/Rare9.nbt,10,CHEST:3,../../../Chests/Loot/Rare10.nbt,15,CHEST:3,../../../Chests/Loot/Rare11.nbt,15,CHEST:3,../../../Chests/Loot/Rare12.nbt,15,CHEST:3,../../../Chests/Loot/Rare13.nbt,15,CHEST:3,../../../Chests/Loot/Rare14.nbt,15,CHEST:3,../../../Chests/Loot/Rare15.nbt,15,CHEST:3,../../../Chests/Loot/Epic15.nbt,100)
Block(2,6,5,GRASS:0)
Block(2,6,6,STONE:0)
Block(2,6,7,STONE:0)
Block(2,6,8,STONE:0)
Block(2,7,-7,GRASS:0)
Block(2,7,-6,GRASS:0)
Block(2,7,-5,GRASS:0)
Block(2,7,-4,DIRT:0)
Block(2,7,-3,DIRT:0)
Block(2,7,-2,SMOOTH_BRICK:0)
Block(2,7,1,SMOOTH_BRICK:0)
Block(2,7,6,GRASS:0)
Block(2,7,7,GRASS:0)
Block(2,7,8,STONE:0)
Block(2,8,-5,LONG_GRASS:1)
Block(2,8,-4,SMOOTH_BRICK:2)
Block(2,8,-3,MOSSY_COBBLESTONE:0)
Block(2,8,-2,SMOOTH_BRICK:0)
Block(2,8,1,SMOOTH_BRICK:1)
Block(2,8,8,GRASS:0)
Block(2,9,-4,SMOOTH_BRICK:0)
Block(2,9,-3,COBBLESTONE:0)
Block(2,9,-2,SMOOTH_BRICK:1)
Block(2,9,1,SMOOTH_BRICK:0)
Block(2,10,-4,SMOOTH_BRICK:2)
Block(2,10,-3,COBBLESTONE:0)
Block(2,10,-2,SMOOTH_BRICK:1)
Block(2,10,1,SMOOTH_BRICK:0)
Block(2,11,-4,SMOOTH_STAIRS:2)
Block(2,11,-3,MOSSY_COBBLESTONE:0)
Block(2,11,-2,SMOOTH_BRICK:1)
Block(2,11,1,SMOOTH_BRICK:2)
Block(2,11,2,SMOOTH_BRICK:0)
Block(2,11,3,SMOOTH_BRICK:0)
Block(2,11,5,SMOOTH_BRICK:1)
Block(2,11,6,SMOOTH_STAIRS:0)
Block(2,11,7,STEP:5)
Block(2,11,8,SMOOTH_BRICK:1)
Block(2,12,-4,SMOOTH_STAIRS:5)
Block(2,12,-3,COBBLESTONE:0)
Block(2,12,-2,SMOOTH_BRICK:0)
Block(2,12,1,SMOOTH_BRICK:1)
Block(2,12,3,COBBLE_WALL:0)
Block(2,13,-4,SMOOTH_BRICK:0)
Block(2,13,-3,COBBLESTONE:0)
Block(2,13,-2,SMOOTH_BRICK:2)
Block(2,13,-1,SMOOTH_STAIRS:7)
Block(2,13,1,SMOOTH_BRICK:2)
Block(2,13,3,COBBLE_WALL:0)
Block(2,14,-4,COBBLESTONE:0)
Block(2,14,-2,SMOOTH_BRICK:0)
Block(2,14,-1,SMOOTH_STAIRS:2)
Block(2,14,0,SMOOTH_STAIRS:7)
Block(2,14,1,SMOOTH_BRICK:1)
Block(2,14,3,COBBLE_WALL:0)
Block(2,15,-4,COBBLESTONE:0)
Block(2,15,-2,SMOOTH_BRICK:2)
Block(2,15,0,SMOOTH_STAIRS:2)
Block(2,15,1,SMOOTH_BRICK:2)
Block(2,15,2,STEP:13)
Block(2,15,3,DOUBLE_STEP:5)
Block(2,16,-5,SMOOTH_STAIRS:6)
Block(2,16,-4,COBBLESTONE:0)
Block(2,16,-2,SMOOTH_BRICK:0)
Block(2,16,1,SMOOTH_BRICK:0)
Block(2,17,-5,COBBLE_WALL:0)
Block(2,17,-4,COBBLESTONE:0)
Block(2,17,-2,SMOOTH_BRICK:2)
Block(2,17,0,STEP:0)
Block(2,17,1,SMOOTH_BRICK:1)
Block(2,18,-5,COBBLE_WALL:0)
Block(2,18,-4,COBBLESTONE:0)
Block(2,18,-3,COBBLESTONE:0)
Block(2,18,-2,SMOOTH_BRICK:2)
Block(2,18,1,SMOOTH_BRICK:0)
Block(2,19,-4,SMOOTH_BRICK:2)
Block(2,19,-3,COBBLESTONE:0)
Block(2,19,-2,SMOOTH_STAIRS:1)
Block(2,19,-1,SMOOTH_STAIRS:7)
Block(2,19,0,SMOOTH_BRICK:0)
Block(2,19,1,SMOOTH_BRICK:0)
Block(2,20,-5,COBBLE_WALL:0)
Block(2,20,-4,SMOOTH_STAIRS:1)
Block(2,20,1,SMOOTH_BRICK:0)
Block(2,21,-4,VINE:2)
Block(2,21,1,SMOOTH_BRICK:1)
Block(2,22,-4,VINE:2)
Block(2,22,1,SMOOTH_BRICK:2)
Block(2,23,-4,VINE:2)
Block(2,23,1,SMOOTH_BRICK:0)
Block(2,24,-4,SMOOTH_STAIRS:1)
Block(2,24,1,SMOOTH_BRICK:1)
Block(2,25,1,SMOOTH_BRICK:1)
Block(2,26,1,SMOOTH_BRICK:0)
Block(2,27,0,COBBLESTONE_STAIRS:6)
Block(2,27,1,SMOOTH_BRICK:0)
Block(2,28,0,SMOOTH_BRICK:3)
Block(2,28,1,SMOOTH_BRICK:0)
Block(2,29,-1,STONE_BUTTON:4)
Block(2,29,0,DOUBLE_STEP:8)
Block(2,29,1,SMOOTH_BRICK:2)
Block(2,29,2,SMOOTH_BRICK:1)
Block(2,29,3,SMOOTH_BRICK:1)
Block(2,29,4,SMOOTH_BRICK:1)
Block(2,29,5,SMOOTH_BRICK:0)
Block(2,29,6,SMOOTH_BRICK:2)
Block(2,29,7,SMOOTH_BRICK:0)
Block(2,29,8,SMOOTH_BRICK:2)
Block(2,30,0,STEP:0)
Block(3,0,-7,STONE:0)
Block(3,0,-6,STONE:0)
Block(3,0,-5,STONE:0)
Block(3,0,-4,STONE:0)
Block(3,0,-3,STONE:0)
Block(3,0,-2,STONE:0)
Block(3,0,-1,STONE:0)
Block(3,0,0,STONE:0)
Block(3,0,1,STONE:0)
Block(3,0,2,STONE:0)
Block(3,0,3,STONE:0)
Block(3,0,4,STONE:0)
Block(3,0,5,STONE:0)
Block(3,0,6,STONE:0)
Block(3,0,7,STONE:0)
Block(3,0,8,STONE:0)
Block(3,1,-7,STONE:0)
Block(3,1,-6,STONE:0)
Block(3,1,-5,STONE:0)
Block(3,1,-4,STONE:0)
Block(3,1,-3,STONE:0)
Block(3,1,-2,STONE:0)
Block(3,1,-1,STONE:0)
Block(3,1,0,STONE:0)
Block(3,1,1,STONE:0)
Block(3,1,2,STONE:0)
Block(3,1,3,STONE:0)
Block(3,1,4,STONE:0)
Block(3,1,5,STONE:0)
Block(3,1,6,STONE:0)
Block(3,1,7,STONE:0)
Block(3,1,8,STONE:0)
Block(3,2,-7,STONE:0)
Block(3,2,-6,STONE:0)
Block(3,2,-5,STONE:0)
Block(3,2,-4,STONE:0)
Block(3,2,-3,STONE:0)
Block(3,2,-2,STONE:0)
Block(3,2,-1,STONE:0)
Block(3,2,0,STONE:0)
Block(3,2,1,STONE:0)
Block(3,2,2,STONE:0)
Block(3,2,3,STONE:0)
Block(3,2,4,STONE:0)
Block(3,2,5,STONE:0)
Block(3,2,6,STONE:0)
Block(3,2,7,STONE:0)
Block(3,2,8,STONE:0)
Block(3,3,-7,STONE:0)
Block(3,3,-6,STONE:0)
Block(3,3,-5,STONE:0)
Block(3,3,-4,STONE:0)
Block(3,3,-3,STONE:0)
Block(3,3,-2,STONE:0)
Block(3,3,-1,STONE:0)
Block(3,3,0,STONE:0)
Block(3,3,1,SMOOTH_BRICK:0)
Block(3,3,2,STONE:0)
Block(3,3,3,STONE:0)
Block(3,3,4,STONE:0)
Block(3,3,5,STONE:0)
Block(3,3,6,STONE:0)
Block(3,3,7,STONE:0)
Block(3,3,8,STONE:0)
Block(3,4,-7,STONE:0)
Block(3,4,-6,STONE:0)
Block(3,4,-5,STONE:0)
Block(3,4,-4,STONE:0)
Block(3,4,-3,STONE:0)
Block(3,4,-2,STONE:0)
Block(3,4,-1,STONE:0)
Block(3,4,0,STONE:0)
Block(3,4,1,SMOOTH_BRICK:2)
Block(3,4,2,STONE:0)
Block(3,4,3,STONE:0)
Block(3,4,4,STONE:0)
Block(3,4,5,STONE:0)
Block(3,4,6,STONE:0)
Block(3,4,7,STONE:0)
Block(3,4,8,STONE:0)
Block(3,5,-7,STONE:0)
Block(3,5,-6,STONE:0)
Block(3,5,-5,STONE:0)
Block(3,5,-4,STONE:0)
Block(3,5,-3,STONE:0)
Block(3,5,-2,STONE:0)
Block(3,5,-1,STONE:0)
Block(3,5,0,GRASS:0)
Block(3,5,1,SMOOTH_BRICK:1)
Block(3,5,2,GRASS:0)
Block(3,5,3,GRASS:0)
Block(3,5,4,GRASS:0)
Block(3,5,5,STONE:0)
Block(3,5,6,STONE:0)
Block(3,5,7,STONE:0)
Block(3,5,8,STONE:0)
Block(3,6,-7,STONE:0)
Block(3,6,-6,STONE:0)
Block(3,6,-5,STONE:0)
Block(3,6,-4,STONE:0)
Block(3,6,-3,STONE:0)
Block(3,6,-2,STONE:0)
Block(3,6,-1,GRASS:0)
Block(3,6,1,SMOOTH_BRICK:1)
Block(3,6,5,GRASS:0)
Block(3,6,6,STONE:0)
Block(3,6,7,STONE:0)
Block(3,6,8,STONE:0)
Block(3,7,-7,STONE:0)
Block(3,7,-6,STONE:0)
Block(3,7,-5,STONE:0)
Block(3,7,-4,STONE:0)
Block(3,7,-3,GRASS:0)
Block(3,7,-2,GRASS:0)
Block(3,7,1,SMOOTH_BRICK:0)
Block(3,7,6,GRASS:0)
Block(3,7,7,GRASS:0)
Block(3,7,8,STONE:0)
Block(3,8,-7,GRASS:0)
Block(3,8,-6,GRASS:0)
Block(3,8,-5,GRASS:0)
Block(3,8,-4,GRASS:0)
Block(3,8,1,SMOOTH_BRICK:1)
Block(3,8,8,GRASS:0)
Block(3,9,-6,LONG_GRASS:1)
Block(3,9,1,SMOOTH_BRICK:0)
Block(3,10,1,SMOOTH_BRICK:1)
Block(3,11,1,SMOOTH_BRICK:0)
Block(3,11,2,SMOOTH_BRICK:2)
Block(3,11,3,SMOOTH_BRICK:1)
Block(3,11,4,SMOOTH_BRICK:0)
Block(3,11,5,SMOOTH_BRICK:1)
Block(3,11,6,SMOOTH_BRICK:0)
Block(3,11,7,SMOOTH_BRICK:0)
Block(3,11,8,SMOOTH_BRICK:0)
Block(3,12,1,SMOOTH_BRICK:0)
Block(3,12,3,COBBLE_WALL:0)
Block(3,13,1,SMOOTH_BRICK:2)
Block(3,13,3,COBBLE_WALL:0)
Block(3,13,4,COBBLE_WALL:0)
Block(3,14,-4,SMOOTH_BRICK:1)
Block(3,14,-3,MOSSY_COBBLESTONE:0)
Block(3,14,-2,SMOOTH_BRICK:0)
Block(3,14,1,SMOOTH_BRICK:1)
Block(3,14,3,STEP:13)
Block(3,14,4,COBBLE_WALL:0)
Block(3,15,-4,SMOOTH_BRICK:2)
Block(3,15,-3,COBBLESTONE:0)
Block(3,15,-2,SMOOTH_BRICK:1)
Block(3,15,1,SMOOTH_BRICK:0)
Block(3,15,2,STEP:13)
Block(3,15,3,STEP:5)
Block(3,15,4,STEP:5)
Block(3,16,-4,COBBLESTONE:0)
Block(3,16,-2,COBBLESTONE:0)
Block(3,16,0,SMOOTH_STAIRS:6)
Block(3,16,1,SMOOTH_BRICK:0)
Block(3,17,-4,COBBLESTONE:0)
Block(3,17,-2,COBBLESTONE:0)
Block(3,17,0,STEP:0)
Block(3,17,1,SMOOTH_BRICK:2)
Block(3,18,-4,COBBLESTONE:0)
Block(3,18,-3,COBBLESTONE:0)
Block(3,18,-2,COBBLESTONE:0)
Block(3,18,1,SMOOTH_BRICK:2)
Block(3,19,-5,COBBLE_WALL:0)
Block(3,19,-4,STEP:3)
Block(3,19,-3,SMOOTH_STAIRS:1)
Block(3,19,1,SMOOTH_BRICK:2)
Block(3,20,0,LEAVES:4)
Block(3,20,1,DOUBLE_STEP:0)
Block(3,21,0,LEAVES:4)
Block(3,21,1,SMOOTH_BRICK:0)
Block(3,22,1,SMOOTH_BRICK:1)
Block(3,23,1,SMOOTH_BRICK:0)
Block(3,24,0,LEAVES:4)
Block(3,24,1,SMOOTH_BRICK:1)
Block(3,24,2,SMOOTH_STAIRS:7)
Block(3,25,0,LEAVES:4)
Block(3,25,1,SMOOTH_BRICK:1)
Block(3,25,2,SMOOTH_BRICK:0)
Block(3,25,3,SMOOTH_STAIRS:7)
Block(3,26,0,VINE:3)
Block(3,26,1,SMOOTH_BRICK:1)
Block(3,26,2,SMOOTH_BRICK:0)
Block(3,26,3,SMOOTH_BRICK:0)
Block(3,26,4,SMOOTH_STAIRS:7)
Block(3,27,0,VINE:3)
Block(3,27,1,SMOOTH_BRICK:1)
Block(3,27,2,SMOOTH_BRICK:0)
Block(3,27,3,SMOOTH_BRICK:0)
Block(3,27,4,SMOOTH_BRICK:0)
Block(3,27,5,SMOOTH_STAIRS:7)
Block(3,28,0,VINE:3)
Block(3,28,1,SMOOTH_BRICK:2)
Block(3,28,2,SMOOTH_BRICK:0)
Block(3,28,3,SMOOTH_BRICK:0)
Block(3,28,4,SMOOTH_BRICK:0)
Block(3,28,5,SMOOTH_BRICK:0)
Block(3,28,6,STEP:13)
Block(3,29,0,COBBLESTONE_STAIRS:6)
Block(3,29,1,SMOOTH_BRICK:0)
Block(3,29,2,SMOOTH_BRICK:2)
Block(3,29,3,SMOOTH_BRICK:2)
Block(3,29,4,SMOOTH_BRICK:0)
Block(3,29,5,SMOOTH_BRICK:2)
Block(3,29,6,SMOOTH_BRICK:0)
Block(3,29,7,SMOOTH_BRICK:0)
Block(3,29,8,SMOOTH_BRICK:1)
Block(3,30,0,DOUBLE_STEP:8)
Block(4,0,-7,STONE:0)
Block(4,0,-6,STONE:0)
Block(4,0,-5,STONE:0)
Block(4,0,-4,STONE:0)
Block(4,0,-3,STONE:0)
Block(4,0,-2,STONE:0)
Block(4,0,-1,STONE:0)
Block(4,0,0,STONE:0)
Block(4,0,1,STONE:0)
Block(4,0,2,STONE:0)
Block(4,0,3,STONE:0)
Block(4,0,4,STONE:0)
Block(4,0,5,STONE:0)
Block(4,0,6,STONE:0)
Block(4,0,7,STONE:0)
Block(4,0,8,STONE:0)
Block(4,1,-7,STONE:0)
Block(4,1,-6,STONE:0)
Block(4,1,-5,STONE:0)
Block(4,1,-4,STONE:0)
Block(4,1,-3,STONE:0)
Block(4,1,-2,STONE:0)
Block(4,1,-1,STONE:0)
Block(4,1,0,STONE:0)
Block(4,1,1,STONE:0)
Block(4,1,2,STONE:0)
Block(4,1,3,STONE:0)
Block(4,1,4,STONE:0)
Block(4,1,5,STONE:0)
Block(4,1,6,STONE:0)
Block(4,1,7,STONE:0)
Block(4,1,8,STONE:0)
Block(4,2,-7,STONE:0)
Block(4,2,-6,STONE:0)
Block(4,2,-5,STONE:0)
Block(4,2,-4,STONE:0)
Block(4,2,-3,STONE:0)
Block(4,2,-2,STONE:0)
Block(4,2,-1,STONE:0)
Block(4,2,0,STONE:0)
Block(4,2,1,STONE:0)
Block(4,2,2,STONE:0)
Block(4,2,3,STONE:0)
Block(4,2,4,STONE:0)
Block(4,2,5,STONE:0)
Block(4,2,6,STONE:0)
Block(4,2,7,STONE:0)
Block(4,2,8,STONE:0)
Block(4,3,-7,STONE:0)
Block(4,3,-6,STONE:0)
Block(4,3,-5,STONE:0)
Block(4,3,-4,STONE:0)
Block(4,3,-3,STONE:0)
Block(4,3,-2,STONE:0)
Block(4,3,-1,STONE:0)
Block(4,3,0,STONE:0)
Block(4,3,1,STONE:0)
Block(4,3,2,SMOOTH_BRICK:1)
Block(4,3,3,STONE:0)
Block(4,3,4,STONE:0)
Block(4,3,5,STONE:0)
Block(4,3,6,STONE:0)
Block(4,3,7,STONE:0)
Block(4,3,8,STONE:0)
Block(4,4,-7,STONE:0)
Block(4,4,-6,STONE:0)
Block(4,4,-5,STONE:0)
Block(4,4,-4,STONE:0)
Block(4,4,-3,STONE:0)
Block(4,4,-2,STONE:0)
Block(4,4,-1,STONE:0)
Block(4,4,0,STONE:0)
Block(4,4,1,STONE:0)
Block(4,4,2,SMOOTH_BRICK:0)
Block(4,4,3,STONE:0)
Block(4,4,4,STONE:0)
Block(4,4,5,STONE:0)
Block(4,4,6,STONE:0)
Block(4,4,7,STONE:0)
Block(4,4,8,STONE:0)
Block(4,5,-7,STONE:0)
Block(4,5,-6,STONE:0)
Block(4,5,-5,STONE:0)
Block(4,5,-4,STONE:0)
Block(4,5,-3,STONE:0)
Block(4,5,-2,STONE:0)
Block(4,5,-1,STONE:0)
Block(4,5,0,STONE:0)
Block(4,5,1,GRASS:0)
Block(4,5,2,SMOOTH_BRICK:0)
Block(4,5,3,GRASS:0)
Block(4,5,4,GRASS:0)
Block(4,5,5,STONE:0)
Block(4,5,6,STONE:0)
Block(4,5,7,STONE:0)
Block(4,5,8,STONE:0)
Block(4,6,-7,STONE:0)
Block(4,6,-6,STONE:0)
Block(4,6,-5,STONE:0)
Block(4,6,-4,STONE:0)
Block(4,6,-3,STONE:0)
Block(4,6,-2,STONE:0)
Block(4,6,-1,GRASS:0)
Block(4,6,0,GRASS:0)
Block(4,6,1,LONG_GRASS:1)
Block(4,6,2,SMOOTH_BRICK:0)
Block(4,6,5,GRASS:0)
Block(4,6,6,STONE:0)
Block(4,6,7,STONE:0)
Block(4,6,8,STONE:0)
Block(4,7,-7,STONE:0)
Block(4,7,-6,STONE:0)
Block(4,7,-5,STONE:0)
Block(4,7,-4,STONE:0)
Block(4,7,-3,GRASS:0)
Block(4,7,-2,GRASS:0)
Block(4,7,2,SMOOTH_BRICK:2)
Block(4,7,6,GRASS:0)
Block(4,7,7,GRASS:0)
Block(4,7,8,GRASS:0)
Block(4,8,-7,GRASS:0)
Block(4,8,-6,GRASS:0)
Block(4,8,-5,GRASS:0)
Block(4,8,-4,GRASS:0)
Block(4,8,-3,LONG_GRASS:1)
Block(4,8,2,SMOOTH_BRICK:2)
Block(4,9,-4,LONG_GRASS:1)
Block(4,9,2,SMOOTH_BRICK:2)
Block(4,10,2,SMOOTH_BRICK:1)
Block(4,11,2,SMOOTH_BRICK:1)
Block(4,11,3,SMOOTH_BRICK:0)
Block(4,11,4,STEP:5)
Block(4,11,5,SMOOTH_BRICK:0)
Block(4,11,6,SMOOTH_BRICK:2)
Block(4,11,7,SMOOTH_BRICK:0)
Block(4,11,8,SMOOTH_BRICK:0)
Block(4,12,2,SMOOTH_BRICK:2)
Block(4,12,4,COBBLE_WALL:0)
Block(4,13,2,SMOOTH_BRICK:0)
Block(4,13,4,COBBLE_WALL:0)
Block(4,14,2,SMOOTH_BRICK:0)
Block(4,14,3,STEP:13)
Block(4,14,4,DOUBLE_STEP:5)
Block(4,15,2,SMOOTH_BRICK:2)
Block(4,15,3,STEP:5)
Block(4,16,-4,SMOOTH_BRICK:1)
Block(4,16,-3,COBBLESTONE:0)
Block(4,16,-2,SMOOTH_STAIRS:7)
Block(4,16,2,SMOOTH_BRICK:1)
Block(4,17,-4,COBBLESTONE:0)
Block(4,17,-3,COBBLESTONE:0)
Block(4,17,-2,COBBLESTONE:0)
Block(4,17,1,STEP:0)
Block(4,17,2,SMOOTH_BRICK:1)
Block(4,18,-4,COBBLESTONE_STAIRS:1)
Block(4,18,2,SMOOTH_BRICK:1)
Block(4,19,2,DOUBLE_STEP:0)
Block(4,20,2,SMOOTH_BRICK:1)
Block(4,21,1,LEAVES:4)
Block(4,21,2,SMOOTH_BRICK:2)
Block(4,22,1,LEAVES:4)
Block(4,22,2,SMOOTH_BRICK:2)
Block(4,23,1,LEAVES:4)
Block(4,23,2,SMOOTH_BRICK:0)
Block(4,24,1,LEAVES:4)
Block(4,24,2,SMOOTH_BRICK:1)
Block(4,25,0,LEAVES:4)
Block(4,25,1,LEAVES:4)
Block(4,25,2,SMOOTH_BRICK:1)
Block(4,26,0,LEAVES:4)
Block(4,26,1,LEAVES:4)
Block(4,26,2,SMOOTH_BRICK:1)
Block(4,27,0,VINE:1)
Block(4,27,1,LEAVES:4)
Block(4,27,2,SMOOTH_BRICK:1)
Block(4,27,6,SMOOTH_STAIRS:4)
Block(4,28,1,COBBLESTONE_STAIRS:6)
Block(4,28,2,SMOOTH_BRICK:2)
Block(4,28,6,SMOOTH_BRICK:0)
Block(4,28,8,SMOOTH_STAIRS:4)
Block(4,29,0,STONE_BUTTON:4)
Block(4,29,1,DOUBLE_STEP:8)
Block(4,29,2,SMOOTH_BRICK:2)
Block(4,29,3,SMOOTH_BRICK:1)
Block(4,29,4,SMOOTH_BRICK:0)
Block(4,29,5,SMOOTH_BRICK:1)
Block(4,29,6,SMOOTH_BRICK:2)
Block(4,29,7,SMOOTH_BRICK:1)
Block(4,29,8,SMOOTH_BRICK:1)
Block(4,30,1,STEP:0)
Block(5,0,-7,STONE:0)
Block(5,0,-6,STONE:0)
Block(5,0,-5,STONE:0)
Block(5,0,-4,STONE:0)
Block(5,0,-3,STONE:0)
Block(5,0,-2,STONE:0)
Block(5,0,-1,STONE:0)
Block(5,0,0,STONE:0)
Block(5,0,1,STONE:0)
Block(5,0,2,STONE:0)
Block(5,0,3,STONE:0)
Block(5,0,4,STONE:0)
Block(5,0,5,STONE:0)
Block(5,0,6,STONE:0)
Block(5,0,7,STONE:0)
Block(5,0,8,STONE:0)
Block(5,1,-7,STONE:0)
Block(5,1,-6,STONE:0)
Block(5,1,-5,STONE:0)
Block(5,1,-4,STONE:0)
Block(5,1,-3,STONE:0)
Block(5,1,-2,STONE:0)
Block(5,1,-1,STONE:0)
Block(5,1,0,STONE:0)
Block(5,1,1,STONE:0)
Block(5,1,2,STONE:0)
Block(5,1,3,STONE:0)
Block(5,1,4,STONE:0)
Block(5,1,5,STONE:0)
Block(5,1,6,STONE:0)
Block(5,1,7,STONE:0)
Block(5,1,8,STONE:0)
Block(5,2,-7,STONE:0)
Block(5,2,-6,STONE:0)
Block(5,2,-5,STONE:0)
Block(5,2,-4,STONE:0)
Block(5,2,-3,STONE:0)
Block(5,2,-2,STONE:0)
Block(5,2,-1,STONE:0)
Block(5,2,0,STONE:0)
Block(5,2,1,STONE:0)
Block(5,2,2,STONE:0)
Block(5,2,3,STONE:0)
Block(5,2,4,STONE:0)
Block(5,2,5,STONE:0)
Block(5,2,6,STONE:0)
Block(5,2,7,STONE:0)
Block(5,2,8,STONE:0)
Block(5,3,-7,STONE:0)
Block(5,3,-6,STONE:0)
Block(5,3,-5,STONE:0)
Block(5,3,-4,STONE:0)
Block(5,3,-3,STONE:0)
Block(5,3,-2,STONE:0)
Block(5,3,-1,STONE:0)
Block(5,3,0,STONE:0)
Block(5,3,1,STONE:0)
Block(5,3,2,SMOOTH_BRICK:1)
Block(5,3,3,STONE:0)
Block(5,3,4,STONE:0)
Block(5,3,5,STONE:0)
Block(5,3,6,STONE:0)
Block(5,3,7,STONE:0)
Block(5,3,8,STONE:0)
Block(5,4,-7,STONE:0)
Block(5,4,-6,STONE:0)
Block(5,4,-5,STONE:0)
Block(5,4,-4,STONE:0)
Block(5,4,-3,STONE:0)
Block(5,4,-2,STONE:0)
Block(5,4,-1,STONE:0)
Block(5,4,0,STONE:0)
Block(5,4,1,STONE:0)
Block(5,4,2,SMOOTH_BRICK:2)
Block(5,4,3,STONE:0)
Block(5,4,4,STONE:0)
Block(5,4,5,STONE:0)
Block(5,4,6,STONE:0)
Block(5,4,7,STONE:0)
Block(5,4,8,STONE:0)
Block(5,5,-7,STONE:0)
Block(5,5,-6,STONE:0)
Block(5,5,-5,STONE:0)
Block(5,5,-4,STONE:0)
Block(5,5,-3,STONE:0)
Block(5,5,-2,STONE:0)
Block(5,5,-1,STONE:0)
Block(5,5,0,STONE:0)
Block(5,5,1,GRASS:0)
Block(5,5,2,SMOOTH_BRICK:1)
Block(5,5,3,GRASS:0)
Block(5,5,4,GRASS:0)
Block(5,5,5,STONE:0)
Block(5,5,6,STONE:0)
Block(5,5,7,STONE:0)
Block(5,5,8,STONE:0)
Block(5,6,-7,STONE:0)
Block(5,6,-6,STONE:0)
Block(5,6,-5,STONE:0)
Block(5,6,-4,STONE:0)
Block(5,6,-3,STONE:0)
Block(5,6,-2,STONE:0)
Block(5,6,-1,STONE:0)
Block(5,6,0,GRASS:0)
Block(5,6,1,LONG_GRASS:1)
Block(5,6,2,SMOOTH_BRICK:2)
Block(5,6,5,GRASS:0)
Block(5,6,6,GRASS:0)
Block(5,6,7,STONE:0)
Block(5,6,8,STONE:0)
Block(5,7,-7,STONE:0)
Block(5,7,-6,STONE:0)
Block(5,7,-5,STONE:0)
Block(5,7,-4,STONE:0)
Block(5,7,-3,STONE:0)
Block(5,7,-2,GRASS:0)
Block(5,7,-1,GRASS:0)
Block(5,7,2,SMOOTH_BRICK:2)
Block(5,7,7,GRASS:0)
Block(5,8,-7,GRASS:0)
Block(5,8,-6,GRASS:0)
Block(5,8,-5,GRASS:0)
Block(5,8,-4,GRASS:0)
Block(5,8,-3,GRASS:0)
Block(5,8,-1,LONG_GRASS:1)
Block(5,8,2,SMOOTH_BRICK:2)
Block(5,9,-7,LONG_GRASS:1)
Block(5,9,-5,LONG_GRASS:1)
Block(5,9,-4,LONG_GRASS:1)
Block(5,9,2,SMOOTH_BRICK:1)
Block(5,10,2,SMOOTH_BRICK:0)
Block(5,11,2,SMOOTH_BRICK:1)
Block(5,11,3,SMOOTH_BRICK:2)
Block(5,11,4,SMOOTH_BRICK:0)
Block(5,11,5,SMOOTH_BRICK:1)
Block(5,11,6,SMOOTH_BRICK:0)
Block(5,11,7,SMOOTH_BRICK:1)
Block(5,11,8,SMOOTH_BRICK:2)
Block(5,12,2,SMOOTH_BRICK:2)
Block(5,12,5,COBBLE_WALL:0)
Block(5,13,2,SMOOTH_BRICK:1)
Block(5,13,5,STEP:13)
Block(5,14,2,SMOOTH_BRICK:2)
Block(5,14,3,DOUBLE_STEP:5)
Block(5,14,4,STEP:5)
Block(5,15,2,SMOOTH_BRICK:0)
Block(5,16,1,SMOOTH_STAIRS:6)
Block(5,16,2,SMOOTH_BRICK:1)
Block(5,17,-4,SMOOTH_BRICK:0)
Block(5,17,-3,COBBLESTONE:0)
Block(5,17,-2,SMOOTH_BRICK:2)
Block(5,17,1,STEP:0)
Block(5,17,2,SMOOTH_BRICK:2)
Block(5,18,1,LEAVES:4)
Block(5,18,2,SMOOTH_BRICK:2)
Block(5,19,0,LEAVES:4)
Block(5,19,1,LEAVES:4)
Block(5,19,2,SMOOTH_BRICK:0)
Block(5,20,0,VINE:3)
Block(5,20,1,LEAVES:4)
Block(5,20,2,DOUBLE_STEP:0)
Block(5,21,0,VINE:3)
Block(5,21,1,LEAVES:4)
Block(5,21,2,SMOOTH_BRICK:1)
Block(5,22,0,VINE:3)
Block(5,22,1,LEAVES:4)
Block(5,22,2,SMOOTH_BRICK:2)
Block(5,23,0,VINE:3)
Block(5,23,1,VINE:1)
Block(5,23,2,SMOOTH_BRICK:0)
Block(5,24,0,VINE:3)
Block(5,24,1,VINE:1)
Block(5,24,2,SMOOTH_BRICK:0)
Block(5,25,0,VINE:3)
Block(5,25,1,LEAVES:4)
Block(5,25,2,SMOOTH_BRICK:2)
Block(5,26,1,VINE:0)
Block(5,26,2,SMOOTH_BRICK:1)
Block(5,26,6,SMOOTH_STAIRS:4)
Block(5,27,1,LEAVES:4)
Block(5,27,2,SMOOTH_BRICK:2)
Block(5,27,6,SMOOTH_BRICK:0)
Block(5,27,8,SMOOTH_STAIRS:4)
Block(5,28,1,LEAVES:4)
Block(5,28,2,SMOOTH_BRICK:1)
Block(5,28,6,SMOOTH_BRICK:0)
Block(5,28,8,SMOOTH_BRICK:0)
Block(5,29,1,COBBLESTONE_STAIRS:6)
Block(5,29,2,SMOOTH_BRICK:2)
Block(5,29,3,SMOOTH_BRICK:2)
Block(5,29,4,SMOOTH_BRICK:2)
Block(5,29,5,SMOOTH_BRICK:1)
Block(5,29,6,SMOOTH_BRICK:1)
Block(5,29,7,SMOOTH_BRICK:0)
Block(5,29,8,SMOOTH_BRICK:0)
Block(5,30,1,DOUBLE_STEP:8)
Block(5,30,3,LEAVES:4)
Block(6,0,-7,STONE:0)
Block(6,0,-6,STONE:0)
Block(6,0,-5,STONE:0)
Block(6,0,-4,STONE:0)
Block(6,0,-3,STONE:0)
Block(6,0,-2,STONE:0)
Block(6,0,-1,STONE:0)
Block(6,0,0,STONE:0)
Block(6,0,1,STONE:0)
Block(6,0,2,STONE:0)
Block(6,0,3,STONE:0)
Block(6,0,4,STONE:0)
Block(6,0,5,STONE:0)
Block(6,0,6,STONE:0)
Block(6,0,7,STONE:0)
Block(6,0,8,STONE:0)
Block(6,1,-7,STONE:0)
Block(6,1,-6,STONE:0)
Block(6,1,-5,STONE:0)
Block(6,1,-4,STONE:0)
Block(6,1,-3,STONE:0)
Block(6,1,-2,STONE:0)
Block(6,1,-1,STONE:0)
Block(6,1,0,STONE:0)
Block(6,1,1,STONE:0)
Block(6,1,2,STONE:0)
Block(6,1,3,STONE:0)
Block(6,1,4,STONE:0)
Block(6,1,5,STONE:0)
Block(6,1,6,STONE:0)
Block(6,1,7,STONE:0)
Block(6,1,8,STONE:0)
Block(6,2,-7,STONE:0)
Block(6,2,-6,STONE:0)
Block(6,2,-5,STONE:0)
Block(6,2,-4,STONE:0)
Block(6,2,-3,STONE:0)
Block(6,2,-2,STONE:0)
Block(6,2,-1,STONE:0)
Block(6,2,0,STONE:0)
Block(6,2,1,STONE:0)
Block(6,2,2,STONE:0)
Block(6,2,3,STONE:0)
Block(6,2,4,STONE:0)
Block(6,2,5,STONE:0)
Block(6,2,6,STONE:0)
Block(6,2,7,STONE:0)
Block(6,2,8,STONE:0)
Block(6,3,-7,STONE:0)
Block(6,3,-6,STONE:0)
Block(6,3,-5,STONE:0)
Block(6,3,-4,STONE:0)
Block(6,3,-3,STONE:0)
Block(6,3,-2,STONE:0)
Block(6,3,-1,STONE:0)
Block(6,3,0,STONE:0)
Block(6,3,1,STONE:0)
Block(6,3,2,STONE:0)
Block(6,3,3,SMOOTH_BRICK:1)
Block(6,3,4,STONE:0)
Block(6,3,5,STONE:0)
Block(6,3,6,STONE:0)
Block(6,3,7,STONE:0)
Block(6,3,8,STONE:0)
Block(6,4,-7,STONE:0)
Block(6,4,-6,STONE:0)
Block(6,4,-5,STONE:0)
Block(6,4,-4,STONE:0)
Block(6,4,-3,STONE:0)
Block(6,4,-2,STONE:0)
Block(6,4,-1,STONE:0)
Block(6,4,0,STONE:0)
Block(6,4,1,STONE:0)
Block(6,4,2,STONE:0)
Block(6,4,3,SMOOTH_BRICK:0)
Block(6,4,4,STONE:0)
Block(6,4,5,STONE:0)
Block(6,4,6,STONE:0)
Block(6,4,7,STONE:0)
Block(6,4,8,STONE:0)
Block(6,5,-7,STONE:0)
Block(6,5,-6,STONE:0)
Block(6,5,-5,STONE:0)
Block(6,5,-4,STONE:0)
Block(6,5,-3,STONE:0)
Block(6,5,-2,STONE:0)
Block(6,5,-1,STONE:0)
Block(6,5,0,STONE:0)
Block(6,5,1,GRASS:0)
Block(6,5,2,GRASS:0)
Block(6,5,3,SMOOTH_BRICK:2)
Block(6,5,4,GRASS:0)
Block(6,5,5,GRASS:0)
Block(6,5,6,STONE:0)
Block(6,5,7,STONE:0)
Block(6,5,8,STONE:0)
Block(6,6,-7,STONE:0)
Block(6,6,-6,STONE:0)
Block(6,6,-5,STONE:0)
Block(6,6,-4,STONE:0)
Block(6,6,-3,STONE:0)
Block(6,6,-2,STONE:0)
Block(6,6,-1,STONE:0)
Block(6,6,0,GRASS:0)
Block(6,6,2,LEAVES:4)
Block(6,6,3,SMOOTH_BRICK:0)
Block(6,6,6,GRASS:0)
Block(6,6,7,GRASS:0)
Block(6,6,8,GRASS:0)
Block(6,7,-7,STONE:0)
Block(6,7,-6,STONE:0)
Block(6,7,-5,STONE:0)
Block(6,7,-4,STONE:0)
Block(6,7,-3,GRASS:0)
Block(6,7,-2,GRASS:0)
Block(6,7,-1,GRASS:0)
Block(6,7,3,SMOOTH_BRICK:2)
Block(6,8,-7,GRASS:0)
Block(6,8,-6,GRASS:0)
Block(6,8,-5,GRASS:0)
Block(6,8,-4,GRASS:0)
Block(6,8,-1,LONG_GRASS:1)
Block(6,8,3,SMOOTH_BRICK:2)
Block(6,9,-7,YELLOW_FLOWER:0)
Block(6,9,3,SMOOTH_BRICK:2)
Block(6,10,2,LEAVES:4)
Block(6,10,3,SMOOTH_BRICK:0)
Block(6,11,2,LEAVES:4)
Block(6,11,3,SMOOTH_BRICK:1)
Block(6,11,4,SMOOTH_BRICK:1)
Block(6,11,5,SMOOTH_BRICK:2)
Block(6,11,6,SMOOTH_BRICK:2)
Block(6,11,7,SMOOTH_BRICK:0)
Block(6,11,8,SMOOTH_BRICK:2)
Block(6,12,2,LEAVES:4)
Block(6,12,3,SMOOTH_BRICK:2)
Block(6,12,5,COBBLE_WALL:0)
Block(6,12,6,COBBLE_WALL:0)
Block(6,12,7,COBBLE_WALL:0)
Block(6,12,8,STEP:13)
Block(6,13,3,SMOOTH_BRICK:2)
Block(6,13,4,STEP:13)
Block(6,13,5,STEP:13)
Block(6,13,6,STEP:13)
Block(6,13,7,STEP:5)
Block(6,14,3,SMOOTH_BRICK:1)
Block(6,14,4,STEP:5)
Block(6,15,1,LEAVES:4)
Block(6,15,3,SMOOTH_BRICK:0)
Block(6,16,-4,SMOOTH_BRICK:0)
Block(6,16,-3,COBBLESTONE:0)
Block(6,16,-2,SMOOTH_BRICK:2)
Block(6,16,1,LEAVES:4)
Block(6,16,3,SMOOTH_BRICK:1)
Block(6,17,1,LEAVES:4)
Block(6,17,2,STEP:0)
Block(6,17,3,SMOOTH_BRICK:2)
Block(6,18,1,VINE:2)
Block(6,18,2,VINE:3)
Block(6,18,3,SMOOTH_BRICK:1)
Block(6,19,1,VINE:2)
Block(6,19,2,VINE:3)
Block(6,19,3,DOUBLE_STEP:0)
Block(6,20,1,VINE:2)
Block(6,20,2,VINE:3)
Block(6,20,3,SMOOTH_BRICK:1)
Block(6,21,1,VINE:2)
Block(6,21,2,VINE:1)
Block(6,21,3,SMOOTH_BRICK:1)
Block(6,22,1,VINE:2)
Block(6,22,2,VINE:1)
Block(6,22,3,SMOOTH_BRICK:0)
Block(6,23,1,VINE:2)
Block(6,23,3,SMOOTH_BRICK:1)
Block(6,24,1,VINE:2)
Block(6,24,3,SMOOTH_BRICK:2)
Block(6,25,1,VINE:2)
Block(6,25,3,SMOOTH_BRICK:0)
Block(6,25,6,SMOOTH_STAIRS:4)
Block(6,26,3,SMOOTH_BRICK:0)
Block(6,26,6,SMOOTH_BRICK:0)
Block(6,26,8,SMOOTH_STAIRS:4)
Block(6,27,2,COBBLESTONE_STAIRS:6)
Block(6,27,3,SMOOTH_BRICK:2)
Block(6,27,6,SMOOTH_BRICK:0)
Block(6,27,8,SMOOTH_BRICK:0)
Block(6,28,1,LEAVES:4)
Block(6,28,2,SMOOTH_BRICK:3)
Block(6,28,3,SMOOTH_BRICK:1)
Block(6,28,6,SMOOTH_BRICK:0)
Block(6,28,8,SMOOTH_BRICK:0)
Block(6,29,1,STONE_BUTTON:4)
Block(6,29,2,DOUBLE_STEP:8)
Block(6,29,3,SMOOTH_BRICK:2)
Block(6,29,4,SMOOTH_BRICK:0)
Block(6,29,5,SMOOTH_BRICK:0)
Block(6,29,6,SMOOTH_BRICK:1)
Block(6,29,7,SMOOTH_BRICK:0)
Block(6,29,8,SMOOTH_BRICK:0)
Block(6,30,2,STEP:0)
Block(6,30,3,LEAVES:4)
Block(6,31,3,LEAVES:4)
Block(6,32,3,LEAVES:4)
Block(7,0,-7,STONE:0)
Block(7,0,-6,STONE:0)
Block(7,0,-5,STONE:0)
Block(7,0,-4,STONE:0)
Block(7,0,-3,STONE:0)
Block(7,0,-2,STONE:0)
Block(7,0,-1,STONE:0)
Block(7,0,0,STONE:0)
Block(7,0,1,STONE:0)
Block(7,0,2,STONE:0)
Block(7,0,3,STONE:0)
Block(7,0,4,STONE:0)
Block(7,0,5,STONE:0)
Block(7,0,6,STONE:0)
Block(7,0,7,STONE:0)
Block(7,0,8,STONE:0)
Block(7,1,-7,STONE:0)
Block(7,1,-6,STONE:0)
Block(7,1,-5,STONE:0)
Block(7,1,-4,STONE:0)
Block(7,1,-3,STONE:0)
Block(7,1,-2,STONE:0)
Block(7,1,-1,STONE:0)
Block(7,1,0,STONE:0)
Block(7,1,1,STONE:0)
Block(7,1,2,STONE:0)
Block(7,1,3,STONE:0)
Block(7,1,4,STONE:0)
Block(7,1,5,STONE:0)
Block(7,1,6,STONE:0)
Block(7,1,7,STONE:0)
Block(7,1,8,STONE:0)
Block(7,2,-7,STONE:0)
Block(7,2,-6,STONE:0)
Block(7,2,-5,STONE:0)
Block(7,2,-4,STONE:0)
Block(7,2,-3,STONE:0)
Block(7,2,-2,STONE:0)
Block(7,2,-1,STONE:0)
Block(7,2,0,STONE:0)
Block(7,2,1,STONE:0)
Block(7,2,2,STONE:0)
Block(7,2,3,STONE:0)
Block(7,2,4,STONE:0)
Block(7,2,5,STONE:0)
Block(7,2,6,STONE:0)
Block(7,2,7,STONE:0)
Block(7,2,8,STONE:0)
Block(7,3,-7,STONE:0)
Block(7,3,-6,STONE:0)
Block(7,3,-5,STONE:0)
Block(7,3,-4,STONE:0)
Block(7,3,-3,STONE:0)
Block(7,3,-2,STONE:0)
Block(7,3,-1,STONE:0)
Block(7,3,0,STONE:0)
Block(7,3,1,STONE:0)
Block(7,3,2,STONE:0)
Block(7,3,3,STONE:0)
Block(7,3,4,SMOOTH_BRICK:1)
Block(7,3,5,SMOOTH_BRICK:2)
Block(7,3,6,STONE:0)
Block(7,3,7,STONE:0)
Block(7,3,8,STONE:0)
Block(7,4,-7,STONE:0)
Block(7,4,-6,STONE:0)
Block(7,4,-5,STONE:0)
Block(7,4,-4,STONE:0)
Block(7,4,-3,STONE:0)
Block(7,4,-2,STONE:0)
Block(7,4,-1,STONE:0)
Block(7,4,0,STONE:0)
Block(7,4,1,STONE:0)
Block(7,4,2,STONE:0)
Block(7,4,3,STONE:0)
Block(7,4,4,SMOOTH_BRICK:1)
Block(7,4,5,SMOOTH_BRICK:2)
Block(7,4,6,STONE:0)
Block(7,4,7,STONE:0)
Block(7,4,8,STONE:0)
Block(7,5,-7,STONE:0)
Block(7,5,-6,STONE:0)
Block(7,5,-5,STONE:0)
Block(7,5,-4,STONE:0)
Block(7,5,-3,STONE:0)
Block(7,5,-2,STONE:0)
Block(7,5,-1,STONE:0)
Block(7,5,0,STONE:0)
Block(7,5,1,GRASS:0)
Block(7,5,2,GRASS:0)
Block(7,5,3,GRASS:0)
Block(7,5,4,SMOOTH_BRICK:2)
Block(7,5,5,SMOOTH_BRICK:2)
Block(7,5,6,GRASS:0)
Block(7,5,7,STONE:0)
Block(7,5,8,STONE:0)
Block(7,6,-7,STONE:0)
Block(7,6,-6,STONE:0)
Block(7,6,-5,STONE:0)
Block(7,6,-4,STONE:0)
Block(7,6,-3,STONE:0)
Block(7,6,-2,STONE:0)
Block(7,6,-1,STONE:0)
Block(7,6,0,GRASS:0)
Block(7,6,1,YELLOW_FLOWER:0)
Block(7,6,2,LEAVES:4)
Block(7,6,3,LEAVES:4)
Block(7,6,4,SMOOTH_BRICK:0)
Block(7,6,5,SMOOTH_BRICK:1)
Block(7,6,7,GRASS:0)
Block(7,6,8,GRASS:0)
Block(7,7,-7,STONE:0)
Block(7,7,-6,STONE:0)
Block(7,7,-5,STONE:0)
Block(7,7,-4,STONE:0)
Block(7,7,-3,GRASS:0)
Block(7,7,-2,GRASS:0)
Block(7,7,-1,GRASS:0)
Block(7,7,3,LEAVES:4)
Block(7,7,4,SMOOTH_BRICK:2)
Block(7,7,5,SMOOTH_BRICK:2)
Block(7,8,-7,GRASS:0)
Block(7,8,-6,GRASS:0)
Block(7,8,-5,GRASS:0)
Block(7,8,-4,GRASS:0)
Block(7,8,-3,LONG_GRASS:1)
Block(7,8,3,LEAVES:4)
Block(7,8,4,SMOOTH_BRICK:2)
Block(7,8,5,SMOOTH_BRICK:1)
Block(7,9,-7,LONG_GRASS:1)
Block(7,9,-5,VINE:1)
Block(7,9,-4,VINE:8)
Block(7,9,-3,VINE:8)
Block(7,9,4,SMOOTH_BRICK:2)
Block(7,9,5,SMOOTH_BRICK:2)
Block(7,10,-5,VINE:1)
Block(7,10,-4,VINE:8)
Block(7,10,-3,VINE:8)
Block(7,10,4,SMOOTH_BRICK:2)
Block(7,10,5,SMOOTH_BRICK:2)
Block(7,11,-5,VINE:1)
Block(7,11,-4,VINE:8)
Block(7,11,-3,VINE:8)
Block(7,11,3,LEAVES:4)
Block(7,11,4,SMOOTH_BRICK:2)
Block(7,11,5,SMOOTH_BRICK:1)
Block(7,11,6,SMOOTH_BRICK:0)
Block(7,11,7,SMOOTH_BRICK:0)
Block(7,11,8,SMOOTH_BRICK:0)
Block(7,12,-5,VINE:1)
Block(7,12,-4,VINE:8)
Block(7,12,-3,VINE:8)
Block(7,12,2,LEAVES:4)
Block(7,12,3,LEAVES:4)
Block(7,12,4,SMOOTH_BRICK:0)
Block(7,12,5,SMOOTH_BRICK:2)
Block(7,12,8,STEP:13)
Block(7,13,-5,VINE:1)
Block(7,13,3,LEAVES:4)
Block(7,13,4,SMOOTH_BRICK:2)
Block(7,13,5,SMOOTH_BRICK:2)
Block(7,13,6,DOUBLE_STEP:5)
Block(7,13,7,STEP:5)
Block(7,14,-5,VINE:1)
Block(7,14,-4,SMOOTH_BRICK:0)
Block(7,14,-3,COBBLESTONE:0)
Block(7,14,-2,SMOOTH_BRICK:1)
Block(7,14,3,LEAVES:4)
Block(7,14,4,SMOOTH_BRICK:1)
Block(7,14,5,SMOOTH_BRICK:2)
Block(7,15,-5,VINE:1)
Block(7,15,-4,SMOOTH_BRICK:2)
Block(7,15,-3,COBBLESTONE:0)
Block(7,15,-2,SMOOTH_STAIRS:1)
Block(7,15,3,LEAVES:4)
Block(7,15,4,SMOOTH_BRICK:2)
Block(7,15,5,SMOOTH_BRICK:2)
Block(7,16,-5,VINE:1)
Block(7,16,-4,COBBLESTONE:0)
Block(7,16,1,LEAVES:4)
Block(7,16,2,LEAVES:4)
Block(7,16,3,SMOOTH_STAIRS:5)
Block(7,16,4,SMOOTH_BRICK:2)
Block(7,16,5,SMOOTH_BRICK:2)
Block(7,17,1,LEAVES:4)
Block(7,17,2,LEAVES:4)
Block(7,17,3,STEP:0)
Block(7,17,4,SMOOTH_BRICK:2)
Block(7,17,5,SMOOTH_BRICK:1)
Block(7,18,1,LEAVES:4)
Block(7,18,3,VINE:2)
Block(7,18,4,SMOOTH_BRICK:1)
Block(7,18,5,SMOOTH_BRICK:2)
Block(7,19,3,VINE:2)
Block(7,19,4,SMOOTH_BRICK:2)
Block(7,19,5,DOUBLE_STEP:0)
Block(7,20,3,VINE:2)
Block(7,20,4,DOUBLE_STEP:0)
Block(7,20,5,SMOOTH_BRICK:1)
Block(7,21,3,VINE:2)
Block(7,21,4,SMOOTH_BRICK:0)
Block(7,21,5,SMOOTH_BRICK:2)
Block(7,22,3,VINE:2)
Block(7,22,4,SMOOTH_BRICK:1)
Block(7,22,5,SMOOTH_BRICK:1)
Block(7,23,4,SMOOTH_BRICK:1)
Block(7,23,5,SMOOTH_BRICK:1)
Block(7,24,4,SMOOTH_BRICK:2)
Block(7,24,5,SMOOTH_BRICK:2)
Block(7,24,6,SMOOTH_STAIRS:4)
Block(7,25,4,SMOOTH_BRICK:0)
Block(7,25,5,SMOOTH_BRICK:1)
Block(7,25,6,SMOOTH_BRICK:0)
Block(7,25,8,SMOOTH_STAIRS:4)
Block(7,26,4,SMOOTH_BRICK:0)
Block(7,26,5,SMOOTH_BRICK:1)
Block(7,26,6,SMOOTH_BRICK:0)
Block(7,26,8,SMOOTH_BRICK:0)
Block(7,27,3,COBBLESTONE_STAIRS:5)
Block(7,27,4,SMOOTH_BRICK:0)
Block(7,27,5,SMOOTH_BRICK:1)
Block(7,27,6,SMOOTH_BRICK:0)
Block(7,27,8,SMOOTH_BRICK:0)
Block(7,28,1,LEAVES:4)
Block(7,28,3,SMOOTH_BRICK:3)
Block(7,28,4,SMOOTH_BRICK:2)
Block(7,28,5,SMOOTH_BRICK:0)
Block(7,28,6,SMOOTH_BRICK:0)
Block(7,28,8,SMOOTH_BRICK:0)
Block(7,29,2,LEAVES:4)
Block(7,29,3,DOUBLE_STEP:8)
Block(7,29,4,SMOOTH_BRICK:1)
Block(7,29,5,SMOOTH_BRICK:2)
Block(7,29,6,SMOOTH_BRICK:2)
Block(7,29,7,SMOOTH_BRICK:2)
Block(7,29,8,SMOOTH_BRICK:0)
Block(7,30,2,LEAVES:4)
Block(7,30,3,STEP:0)
Block(7,30,4,LEAVES:4)
Block(7,31,3,LEAVES:4)
Block(7,31,4,LEAVES:4)
Block(7,32,3,LEAVES:4)
Block(7,32,4,LEAVES:4)
Block(7,33,3,LEAVES:4)
Branch(0,0,16,true,CastleRuinsC2R3,NORTH,100.0,0)
