Author: NLBlackEagle
Description: No description given
SettingsMode: WriteDisable
Frequency: 0
SpawnHeight: randomY
UseCenterForHighestBlock: true
MinHeight: 0
MaxHeight: 255
InheritBO3: 
InheritBO3Rotation: NORTH
OverrideChildSettings: true
OverrideParentHeight: false
CanOverride: false
BranchFrequency: 0
BranchFrequencyGroup: 
MustBeBelowOther: false
MustBeInside: 
CannotBeInside: 
ReplacesBO3: 
MustBeInsideWorldBorders: false
CanSpawnOnWater: true
SpawnOnWaterOnly: false
SpawnUnderWater: false
SpawnAtWaterLevel: false
HeightOffset: 0
RemoveAir: true
ReplaceAbove: 
ReplaceBelow: 
ReplaceWithBiomeBlocks: true
ReplaceWithSurfaceBlock: GRASS
ReplaceWithGroundBlock: DIRT
ReplaceWithStoneBlock: STONE
SmoothRadius: 0
SmoothHeightOffset: 0
SmoothStartTop: false
SmoothStartWood: false
SmoothingSurfaceBlock: 
SmoothingGroundBlock: 
BO3Group: 
IsSpawnPoint: false
DoReplaceBlocks: true
Block(-8,0,-7,DIRT:0)
Block(-8,0,-6,DIRT:0)
Block(-8,0,-5,DIRT:0)
Block(-8,0,-4,DIRT:0)
Block(-8,0,-3,DIRT:0)
Block(-8,0,-2,DIRT:0)
Block(-8,0,-1,DIRT:0)
Block(-8,0,0,DIRT:0)
Block(-8,0,1,DIRT:0)
Block(-8,0,2,DIRT:0)
Block(-8,0,3,DIRT:0)
Block(-8,0,4,GRASS:0)
Block(-8,0,5,GRASS:0)
Block(-8,1,-7,DIRT:0)
Block(-8,1,-6,DIRT:0)
Block(-8,1,-5,DIRT:0)
Block(-8,1,-4,DIRT:0)
Block(-8,1,-3,DIRT:0)
Block(-8,1,-2,DIRT:0)
Block(-8,1,-1,DIRT:0)
Block(-8,1,0,GRASS:0)
Block(-8,1,1,GRASS:0)
Block(-8,1,2,GRASS:0)
Block(-8,1,3,GRASS:0)
Block(-8,2,-7,DIRT:0)
Block(-8,2,-6,DIRT:0)
Block(-8,2,-5,DIRT:0)
Block(-8,2,-4,DIRT:0)
Block(-8,2,-3,GRASS:0)
Block(-8,2,-2,GRASS:0)
Block(-8,2,-1,GRASS:0)
Block(-8,3,-7,GRASS:0)
Block(-8,3,-6,GRASS:0)
Block(-8,3,-5,GRASS:0)
Block(-8,3,-4,GRASS:0)
Block(-7,0,-7,DIRT:0)
Block(-7,0,-6,DIRT:0)
Block(-7,0,-5,DIRT:0)
Block(-7,0,-4,DIRT:0)
Block(-7,0,-3,DIRT:0)
Block(-7,0,-2,DIRT:0)
Block(-7,0,-1,DIRT:0)
Block(-7,0,0,DIRT:0)
Block(-7,0,1,DIRT:0)
Block(-7,0,2,DIRT:0)
Block(-7,0,3,DIRT:0)
Block(-7,0,4,DIRT:0)
Block(-7,0,5,GRASS:0)
Block(-7,0,6,GRASS:0)
Block(-7,1,-7,DIRT:0)
Block(-7,1,-6,DIRT:0)
Block(-7,1,-5,DIRT:0)
Block(-7,1,-4,DIRT:0)
Block(-7,1,-3,DIRT:0)
Block(-7,1,-2,DIRT:0)
Block(-7,1,-1,DIRT:0)
Block(-7,1,0,DIRT:0)
Block(-7,1,1,DIRT:0)
Block(-7,1,2,DIRT:0)
Block(-7,1,3,GRASS:0)
Block(-7,1,4,GRASS:0)
Block(-7,2,-7,DIRT:0)
Block(-7,2,-6,DIRT:0)
Block(-7,2,-5,DIRT:0)
Block(-7,2,-4,DIRT:0)
Block(-7,2,-3,DIRT:0)
Block(-7,2,-2,DIRT:0)
Block(-7,2,-1,DIRT:0)
Block(-7,2,0,GRASS:0)
Block(-7,2,1,GRASS:0)
Block(-7,2,2,GRASS:0)
Block(-7,3,-7,DIRT:0)
Block(-7,3,-6,GRASS:0)
Block(-7,3,-5,DIRT:0)
Block(-7,3,-4,DIRT:0)
Block(-7,3,-3,GRASS:0)
Block(-7,3,-2,GRASS:0)
Block(-7,3,-1,GRASS:0)
Block(-7,4,-7,GRASS:0)
Block(-7,4,-5,GRASS:0)
Block(-7,4,-4,GRASS:0)
Block(-6,0,-7,DIRT:0)
Block(-6,0,-6,DIRT:0)
Block(-6,0,-5,DIRT:0)
Block(-6,0,-4,DIRT:0)
Block(-6,0,-3,DIRT:0)
Block(-6,0,-2,DIRT:0)
Block(-6,0,-1,DIRT:0)
Block(-6,0,0,DIRT:0)
Block(-6,0,1,DIRT:0)
Block(-6,0,2,DIRT:0)
Block(-6,0,3,DIRT:0)
Block(-6,0,4,DIRT:0)
Block(-6,0,5,DIRT:0)
Block(-6,0,6,GRASS:0)
Block(-6,0,7,GRASS:0)
Block(-6,1,-7,DIRT:0)
Block(-6,1,-6,DIRT:0)
Block(-6,1,-5,DIRT:0)
Block(-6,1,-4,DIRT:0)
Block(-6,1,-3,DIRT:0)
Block(-6,1,-2,DIRT:0)
Block(-6,1,-1,DIRT:0)
Block(-6,1,0,DIRT:0)
Block(-6,1,1,DIRT:0)
Block(-6,1,2,DIRT:0)
Block(-6,1,3,DIRT:0)
Block(-6,1,4,DIRT:0)
Block(-6,1,5,GRASS:0)
Block(-6,2,-7,DIRT:0)
Block(-6,2,-6,DIRT:0)
Block(-6,2,-5,DIRT:0)
Block(-6,2,-4,DIRT:0)
Block(-6,2,-3,DIRT:0)
Block(-6,2,-2,DIRT:0)
Block(-6,2,-1,DIRT:0)
Block(-6,2,0,DIRT:0)
Block(-6,2,1,DIRT:0)
Block(-6,2,2,GRASS:0)
Block(-6,2,3,GRASS:0)
Block(-6,2,4,GRASS:0)
Block(-6,3,-7,DIRT:0)
Block(-6,3,-6,DIRT:0)
Block(-6,3,-5,DIRT:0)
Block(-6,3,-4,DIRT:0)
Block(-6,3,-3,DIRT:0)
Block(-6,3,-2,DIRT:0)
Block(-6,3,-1,DIRT:0)
Block(-6,3,0,GRASS:0)
Block(-6,3,1,GRASS:0)
Block(-6,4,-7,GRASS:0)
Block(-6,4,-6,GRASS:0)
Block(-6,4,-5,GRASS:0)
Block(-6,4,-4,GRASS:0)
Block(-6,4,-3,GRASS:0)
Block(-6,4,-2,GRASS:0)
Block(-6,4,-1,GRASS:0)
Block(-5,0,-7,DIRT:0)
Block(-5,0,-6,DIRT:0)
Block(-5,0,-5,DIRT:0)
Block(-5,0,-4,DIRT:0)
Block(-5,0,-3,DIRT:0)
Block(-5,0,-2,DIRT:0)
Block(-5,0,-1,DIRT:0)
Block(-5,0,0,DIRT:0)
Block(-5,0,1,DIRT:0)
Block(-5,0,2,DIRT:0)
Block(-5,0,3,DIRT:0)
Block(-5,0,4,DIRT:0)
Block(-5,0,5,DIRT:0)
Block(-5,0,6,DIRT:0)
Block(-5,0,7,GRASS:0)
Block(-5,0,8,GRASS:0)
Block(-5,1,-7,DIRT:0)
Block(-5,1,-6,DIRT:0)
Block(-5,1,-5,DIRT:0)
Block(-5,1,-4,DIRT:0)
Block(-5,1,-3,DIRT:0)
Block(-5,1,-2,DIRT:0)
Block(-5,1,-1,DIRT:0)
Block(-5,1,0,DIRT:0)
Block(-5,1,1,DIRT:0)
Block(-5,1,2,DIRT:0)
Block(-5,1,3,DIRT:0)
Block(-5,1,4,DIRT:0)
Block(-5,1,5,DIRT:0)
Block(-5,1,6,GRASS:0)
Block(-5,2,-7,DIRT:0)
Block(-5,2,-6,DIRT:0)
Block(-5,2,-5,DIRT:0)
Block(-5,2,-4,DIRT:0)
Block(-5,2,-3,DIRT:0)
Block(-5,2,-2,DIRT:0)
Block(-5,2,-1,DIRT:0)
Block(-5,2,0,DIRT:0)
Block(-5,2,1,DIRT:0)
Block(-5,2,2,DIRT:0)
Block(-5,2,3,DIRT:0)
Block(-5,2,4,GRASS:0)
Block(-5,2,5,GRASS:0)
Block(-5,3,-7,DIRT:0)
Block(-5,3,-6,DIRT:0)
Block(-5,3,-5,DIRT:0)
Block(-5,3,-4,DIRT:0)
Block(-5,3,-3,DIRT:0)
Block(-5,3,-2,DIRT:0)
Block(-5,3,-1,DIRT:0)
Block(-5,3,0,GRASS:0)
Block(-5,3,1,GRASS:0)
Block(-5,3,2,GRASS:0)
Block(-5,3,3,GRASS:0)
Block(-5,4,-7,GRASS:0)
Block(-5,4,-6,GRASS:0)
Block(-5,4,-5,GRASS:0)
Block(-5,4,-4,GRASS:0)
Block(-5,4,-3,GRASS:0)
Block(-5,4,-2,GRASS:0)
Block(-5,4,-1,GRASS:0)
Block(-5,5,-7,SOIL:0)
Block(-5,6,-7,CROPS:7)
Block(-4,0,-7,DIRT:0)
Block(-4,0,-6,DIRT:0)
Block(-4,0,-5,DIRT:0)
Block(-4,0,-4,DIRT:0)
Block(-4,0,-3,DIRT:0)
Block(-4,0,-2,DIRT:0)
Block(-4,0,-1,DIRT:0)
Block(-4,0,0,DIRT:0)
Block(-4,0,1,DIRT:0)
Block(-4,0,2,DIRT:0)
Block(-4,0,3,DIRT:0)
Block(-4,0,4,DIRT:0)
Block(-4,0,5,DIRT:0)
Block(-4,0,6,DIRT:0)
Block(-4,0,7,DIRT:0)
Block(-4,0,8,DIRT:0)
Block(-4,1,-7,DIRT:0)
Block(-4,1,-6,DIRT:0)
Block(-4,1,-5,DIRT:0)
Block(-4,1,-4,DIRT:0)
Block(-4,1,-3,DIRT:0)
Block(-4,1,-2,DIRT:0)
Block(-4,1,-1,DIRT:0)
Block(-4,1,0,DIRT:0)
Block(-4,1,1,DIRT:0)
Block(-4,1,2,DIRT:0)
Block(-4,1,3,DIRT:0)
Block(-4,1,4,DIRT:0)
Block(-4,1,5,DIRT:0)
Block(-4,1,6,GRASS:0)
Block(-4,1,7,GRASS:0)
Block(-4,1,8,GRASS:0)
Block(-4,2,-7,DIRT:0)
Block(-4,2,-6,DIRT:0)
Block(-4,2,-5,DIRT:0)
Block(-4,2,-4,DIRT:0)
Block(-4,2,-3,DIRT:0)
Block(-4,2,-2,DIRT:0)
Block(-4,2,-1,DIRT:0)
Block(-4,2,0,DIRT:0)
Block(-4,2,1,DIRT:0)
Block(-4,2,2,DIRT:0)
Block(-4,2,3,DIRT:0)
Block(-4,2,4,DIRT:0)
Block(-4,2,5,GRASS:0)
Block(-4,3,-7,DIRT:0)
Block(-4,3,-6,DIRT:0)
Block(-4,3,-5,DIRT:0)
Block(-4,3,-4,DIRT:0)
Block(-4,3,-3,DIRT:0)
Block(-4,3,-2,DIRT:0)
Block(-4,3,-1,DIRT:0)
Block(-4,3,0,DIRT:0)
Block(-4,3,1,DIRT:0)
Block(-4,3,2,DIRT:0)
Block(-4,3,3,GRASS:0)
Block(-4,3,4,GRASS:0)
Block(-4,4,-7,DIRT:0)
Block(-4,4,-6,GRASS:0)
Block(-4,4,-5,GRASS:0)
Block(-4,4,-4,GRASS:0)
Block(-4,4,-3,GRASS:0)
Block(-4,4,-2,GRASS:0)
Block(-4,4,-1,GRASS:0)
Block(-4,4,0,GRASS:0)
Block(-4,4,1,GRASS:0)
Block(-4,4,2,GRASS:0)
Block(-4,5,-7,GRASS:0)
Block(-4,5,-6,SOIL:0)
Block(-4,5,-5,SOIL:0)
Block(-4,5,-4,SOIL:0)
Block(-4,5,-3,SOIL:0)
Block(-4,5,-2,SOIL:0)
Block(-4,6,-7,DARK_OAK_FENCE:0)
Block(-4,6,-6,CROPS:7)
Block(-4,6,-5,CROPS:7)
Block(-4,6,-4,CROPS:7)
Block(-4,6,-3,CROPS:7)
Block(-4,6,-2,CROPS:7)
Block(-3,0,-7,DIRT:0)
Block(-3,0,-6,DIRT:0)
Block(-3,0,-5,DIRT:0)
Block(-3,0,-4,DIRT:0)
Block(-3,0,-3,DIRT:0)
Block(-3,0,-2,DIRT:0)
Block(-3,0,-1,DIRT:0)
Block(-3,0,0,DIRT:0)
Block(-3,0,1,DIRT:0)
Block(-3,0,2,DIRT:0)
Block(-3,0,3,DIRT:0)
Block(-3,0,4,DIRT:0)
Block(-3,0,5,DIRT:0)
Block(-3,0,6,DIRT:0)
Block(-3,0,7,DIRT:0)
Block(-3,0,8,DIRT:0)
Block(-3,1,-7,DIRT:0)
Block(-3,1,-6,DIRT:0)
Block(-3,1,-5,DIRT:0)
Block(-3,1,-4,DIRT:0)
Block(-3,1,-3,DIRT:0)
Block(-3,1,-2,DIRT:0)
Block(-3,1,-1,DIRT:0)
Block(-3,1,0,DIRT:0)
Block(-3,1,1,DIRT:0)
Block(-3,1,2,DIRT:0)
Block(-3,1,3,DIRT:0)
Block(-3,1,4,DIRT:0)
Block(-3,1,5,DIRT:0)
Block(-3,1,6,DIRT:0)
Block(-3,1,7,DIRT:0)
Block(-3,1,8,GRASS:0)
Block(-3,2,-7,DIRT:0)
Block(-3,2,-6,DIRT:0)
Block(-3,2,-5,DIRT:0)
Block(-3,2,-4,DIRT:0)
Block(-3,2,-3,DIRT:0)
Block(-3,2,-2,DIRT:0)
Block(-3,2,-1,DIRT:0)
Block(-3,2,0,DIRT:0)
Block(-3,2,1,DIRT:0)
Block(-3,2,2,DIRT:0)
Block(-3,2,3,DIRT:0)
Block(-3,2,4,DIRT:0)
Block(-3,2,5,DIRT:0)
Block(-3,2,6,GRASS:0)
Block(-3,2,7,GRASS:0)
Block(-3,3,-7,DIRT:0)
Block(-3,3,-6,DIRT:0)
Block(-3,3,-5,DIRT:0)
Block(-3,3,-4,DIRT:0)
Block(-3,3,-3,DIRT:0)
Block(-3,3,-2,DIRT:0)
Block(-3,3,-1,DIRT:0)
Block(-3,3,0,DIRT:0)
Block(-3,3,1,DIRT:0)
Block(-3,3,2,DIRT:0)
Block(-3,3,3,DIRT:0)
Block(-3,3,4,DIRT:0)
Block(-3,3,5,GRASS:0)
Block(-3,4,-7,GRASS:0)
Block(-3,4,-6,GRASS:0)
Block(-3,4,-5,DIRT:0)
Block(-3,4,-4,DIRT:0)
Block(-3,4,-3,DIRT:0)
Block(-3,4,-2,DIRT:0)
Block(-3,4,-1,DIRT:0)
Block(-3,4,0,GRASS:0)
Block(-3,4,1,GRASS:0)
Block(-3,4,2,GRASS:0)
Block(-3,4,3,GRASS:0)
Block(-3,4,4,GRASS:0)
Block(-3,5,-7,SOIL:0)
Block(-3,5,-6,SOIL:0)
Block(-3,5,-5,GRASS:0)
Block(-3,5,-4,GRASS:0)
Block(-3,5,-3,GRASS:0)
Block(-3,5,-2,GRASS:0)
Block(-3,5,-1,GRASS:0)
Block(-3,5,0,SOIL:0)
Block(-3,6,-7,CROPS:7)
Block(-3,6,-6,CROPS:7)
Block(-3,6,-5,DARK_OAK_FENCE:0)
Block(-3,6,-4,DARK_OAK_FENCE:0)
Block(-3,6,-3,DARK_OAK_FENCE:0)
Block(-3,6,-2,DARK_OAK_FENCE:0)
Block(-3,6,-1,DARK_OAK_FENCE:0)
Block(-3,6,0,CROPS:7)
Block(-2,0,-7,DIRT:0)
Block(-2,0,-6,DIRT:0)
Block(-2,0,-5,DIRT:0)
Block(-2,0,-4,DIRT:0)
Block(-2,0,-3,DIRT:0)
Block(-2,0,-2,DIRT:0)
Block(-2,0,-1,DIRT:0)
Block(-2,0,0,DIRT:0)
Block(-2,0,1,DIRT:0)
Block(-2,0,2,DIRT:0)
Block(-2,0,3,DIRT:0)
Block(-2,0,4,DIRT:0)
Block(-2,0,5,DIRT:0)
Block(-2,0,6,DIRT:0)
Block(-2,0,7,DIRT:0)
Block(-2,0,8,DIRT:0)
Block(-2,1,-7,DIRT:0)
Block(-2,1,-6,DIRT:0)
Block(-2,1,-5,DIRT:0)
Block(-2,1,-4,DIRT:0)
Block(-2,1,-3,DIRT:0)
Block(-2,1,-2,DIRT:0)
Block(-2,1,-1,DIRT:0)
Block(-2,1,0,DIRT:0)
Block(-2,1,1,DIRT:0)
Block(-2,1,2,DIRT:0)
Block(-2,1,3,DIRT:0)
Block(-2,1,4,DIRT:0)
Block(-2,1,5,DIRT:0)
Block(-2,1,6,DIRT:0)
Block(-2,1,7,DIRT:0)
Block(-2,1,8,DIRT:0)
Block(-2,2,-7,DIRT:0)
Block(-2,2,-6,DIRT:0)
Block(-2,2,-5,DIRT:0)
Block(-2,2,-4,DIRT:0)
Block(-2,2,-3,DIRT:0)
Block(-2,2,-2,DIRT:0)
Block(-2,2,-1,DIRT:0)
Block(-2,2,0,DIRT:0)
Block(-2,2,1,DIRT:0)
Block(-2,2,2,DIRT:0)
Block(-2,2,3,DIRT:0)
Block(-2,2,4,DIRT:0)
Block(-2,2,5,DIRT:0)
Block(-2,2,6,DIRT:0)
Block(-2,2,7,GRASS:0)
Block(-2,2,8,GRASS:0)
Block(-2,3,-7,DIRT:0)
Block(-2,3,-6,DIRT:0)
Block(-2,3,-5,DIRT:0)
Block(-2,3,-4,DIRT:0)
Block(-2,3,-3,DIRT:0)
Block(-2,3,-2,DIRT:0)
Block(-2,3,-1,DIRT:0)
Block(-2,3,0,DIRT:0)
Block(-2,3,1,DIRT:0)
Block(-2,3,2,DIRT:0)
Block(-2,3,3,DIRT:0)
Block(-2,3,4,DIRT:0)
Block(-2,3,5,GRASS:0)
Block(-2,3,6,GRASS:0)
Block(-2,4,-7,GRASS:0)
Block(-2,4,-6,GRASS:0)
Block(-2,4,-5,GRASS:0)
Block(-2,4,-4,GRASS:0)
Block(-2,4,-3,GRASS:0)
Block(-2,4,-2,GRASS:0)
Block(-2,4,-1,COBBLESTONE:0)
Block(-2,4,0,GRASS:0)
Block(-2,4,1,GRASS:0)
Block(-2,4,2,GRASS:0)
Block(-2,4,3,GRASS:0)
Block(-2,4,4,GRASS:0)
Block(-2,5,-7,SOIL:0)
Block(-2,5,-6,SOIL:0)
Block(-2,5,-5,SOIL:0)
Block(-2,5,-4,SOIL:0)
Block(-2,5,-3,SOIL:0)
Block(-2,5,-2,SOIL:0)
Block(-2,5,-1,DIRT:0)
Block(-2,5,0,SOIL:0)
Block(-2,5,1,SOIL:0)
Block(-2,6,-7,CROPS:7)
Block(-2,6,-6,CROPS:7)
Block(-2,6,-5,CROPS:7)
Block(-2,6,-4,CROPS:7)
Block(-2,6,-3,CROPS:7)
Block(-2,6,-2,CROPS:7)
Block(-2,6,-1,HAY_BLOCK:0)
Block(-2,6,0,CROPS:7)
Block(-2,6,1,CROPS:7)
Block(-1,0,-7,DIRT:0)
Block(-1,0,-6,DIRT:0)
Block(-1,0,-5,DIRT:0)
Block(-1,0,-4,DIRT:0)
Block(-1,0,-3,DIRT:0)
Block(-1,0,-2,DIRT:0)
Block(-1,0,-1,DIRT:0)
Block(-1,0,0,DIRT:0)
Block(-1,0,1,DIRT:0)
Block(-1,0,2,DIRT:0)
Block(-1,0,3,DIRT:0)
Block(-1,0,4,DIRT:0)
Block(-1,0,5,DIRT:0)
Block(-1,0,6,DIRT:0)
Block(-1,0,7,DIRT:0)
Block(-1,0,8,DIRT:0)
Block(-1,1,-7,DIRT:0)
Block(-1,1,-6,DIRT:0)
Block(-1,1,-5,DIRT:0)
Block(-1,1,-4,DIRT:0)
Block(-1,1,-3,DIRT:0)
Block(-1,1,-2,DIRT:0)
Block(-1,1,-1,DIRT:0)
Block(-1,1,0,DIRT:0)
Block(-1,1,1,DIRT:0)
Block(-1,1,2,DIRT:0)
Block(-1,1,3,DIRT:0)
Block(-1,1,4,DIRT:0)
Block(-1,1,5,DIRT:0)
Block(-1,1,6,DIRT:0)
Block(-1,1,7,DIRT:0)
Block(-1,1,8,DIRT:0)
Block(-1,2,-7,DIRT:0)
Block(-1,2,-6,DIRT:0)
Block(-1,2,-5,DIRT:0)
Block(-1,2,-4,DIRT:0)
Block(-1,2,-3,DIRT:0)
Block(-1,2,-2,DIRT:0)
Block(-1,2,-1,DIRT:0)
Block(-1,2,0,DIRT:0)
Block(-1,2,1,DIRT:0)
Block(-1,2,2,DIRT:0)
Block(-1,2,3,DIRT:0)
Block(-1,2,4,DIRT:0)
Block(-1,2,5,DIRT:0)
Block(-1,2,6,DIRT:0)
Block(-1,2,7,DIRT:0)
Block(-1,2,8,GRASS:0)
Block(-1,3,-7,DIRT:0)
Block(-1,3,-6,DIRT:0)
Block(-1,3,-5,DIRT:0)
Block(-1,3,-4,DIRT:0)
Block(-1,3,-3,DIRT:0)
Block(-1,3,-2,DIRT:0)
Block(-1,3,-1,DIRT:0)
Block(-1,3,0,DIRT:0)
Block(-1,3,1,DIRT:0)
Block(-1,3,2,DIRT:0)
Block(-1,3,3,DIRT:0)
Block(-1,3,4,DIRT:0)
Block(-1,3,5,DIRT:0)
Block(-1,3,6,DIRT:0)
Block(-1,3,7,GRASS:0)
Block(-1,4,-7,DIRT:0)
Block(-1,4,-6,DIRT:0)
Block(-1,4,-5,DIRT:0)
Block(-1,4,-4,DIRT:0)
Block(-1,4,-3,DIRT:0)
Block(-1,4,-2,GRASS:0)
Block(-1,4,-1,GRASS:0)
Block(-1,4,0,GRASS:0)
Block(-1,4,1,GRASS:0)
Block(-1,4,2,GRASS:0)
Block(-1,4,3,GRASS:0)
Block(-1,4,4,GRASS:0)
Block(-1,4,5,GRASS:0)
Block(-1,4,6,GRASS:0)
Block(-1,5,-7,DIRT:0)
Block(-1,5,-6,GRASS:0)
Block(-1,5,-5,DIRT:0)
Block(-1,5,-4,DIRT:0)
Block(-1,5,-3,DIRT:0)
Block(-1,5,-2,SOIL:0)
Block(-1,5,-1,SOIL:0)
Block(-1,5,0,SOIL:0)
Block(-1,5,1,SOIL:0)
Block(-1,5,2,SOIL:0)
Block(-1,5,3,SOIL:0)
Block(-1,6,-7,COBBLESTONE:0)
Block(-1,6,-6,COBBLESTONE_STAIRS:0)
Block(-1,6,-5,COBBLESTONE:0)
Block(-1,6,-4,LOG:1)
Block(-1,6,-3,HAY_BLOCK:0)
Block(-1,6,-2,CROPS:7)
Block(-1,6,-1,CROPS:7)
Block(-1,6,0,CROPS:7)
Block(-1,6,1,CROPS:7)
Block(-1,6,2,CROPS:7)
Block(-1,6,3,CROPS:7)
Block(-1,7,-7,COBBLESTONE:0)
Block(-1,7,-6,COBBLESTONE_STAIRS:4)
Block(-1,7,-5,COBBLESTONE:0)
Block(-1,7,-4,LOG:1)
Block(-1,8,-7,COBBLESTONE:0)
Block(-1,8,-6,COBBLESTONE_STAIRS:0)
Block(-1,8,-5,COBBLESTONE:0)
Block(-1,8,-4,LOG:1)
Block(-1,9,-7,SMOOTH_STAIRS:0)
Block(-1,9,-5,SMOOTH_STAIRS:0)
Block(-1,9,-4,DARK_OAK_STAIRS:3)
Block(-1,12,-5,LOG:5)
Block(-1,13,-7,WOOD_STEP:1)
Block(-1,13,-6,WOOD_STEP:1)
Block(-1,13,-5,WOOD_STEP:1)
Block(0,0,-7,DIRT:0)
Block(0,0,-6,DIRT:0)
Block(0,0,-5,DIRT:0)
Block(0,0,-4,DIRT:0)
Block(0,0,-3,DIRT:0)
Block(0,0,-2,DIRT:0)
Block(0,0,-1,DIRT:0)
Block(0,0,0,DIRT:0)
Block(0,0,1,DIRT:0)
Block(0,0,2,DIRT:0)
Block(0,0,3,DIRT:0)
Block(0,0,4,DIRT:0)
Block(0,0,5,DIRT:0)
Block(0,0,6,DIRT:0)
Block(0,0,7,DIRT:0)
Block(0,0,8,DIRT:0)
Block(0,1,-7,DIRT:0)
Block(0,1,-6,DIRT:0)
Block(0,1,-5,DIRT:0)
Block(0,1,-4,DIRT:0)
Block(0,1,-3,DIRT:0)
Block(0,1,-2,DIRT:0)
Block(0,1,-1,DIRT:0)
Block(0,1,0,DIRT:0)
Block(0,1,1,DIRT:0)
Block(0,1,2,DIRT:0)
Block(0,1,3,DIRT:0)
Block(0,1,4,DIRT:0)
Block(0,1,5,DIRT:0)
Block(0,1,6,DIRT:0)
Block(0,1,7,DIRT:0)
Block(0,1,8,DIRT:0)
Block(0,2,-7,DIRT:0)
Block(0,2,-6,DIRT:0)
Block(0,2,-5,DIRT:0)
Block(0,2,-4,DIRT:0)
Block(0,2,-3,DIRT:0)
Block(0,2,-2,DIRT:0)
Block(0,2,-1,DIRT:0)
Block(0,2,0,DIRT:0)
Block(0,2,1,DIRT:0)
Block(0,2,2,DIRT:0)
Block(0,2,3,DIRT:0)
Block(0,2,4,DIRT:0)
Block(0,2,5,DIRT:0)
Block(0,2,6,DIRT:0)
Block(0,2,7,DIRT:0)
Block(0,2,8,GRASS:0)
Block(0,3,-7,DIRT:0)
Block(0,3,-6,DIRT:0)
Block(0,3,-5,DIRT:0)
Block(0,3,-4,DIRT:0)
Block(0,3,-3,DIRT:0)
Block(0,3,-2,DIRT:0)
Block(0,3,-1,DIRT:0)
Block(0,3,0,DIRT:0)
Block(0,3,1,DIRT:0)
Block(0,3,2,DIRT:0)
Block(0,3,3,DIRT:0)
Block(0,3,4,DIRT:0)
Block(0,3,5,DIRT:0)
Block(0,3,6,DIRT:0)
Block(0,3,7,GRASS:0)
Block(0,4,-7,DIRT:0)
Block(0,4,-6,DIRT:0)
Block(0,4,-5,DIRT:0)
Block(0,4,-4,DIRT:0)
Block(0,4,-3,DIRT:0)
Block(0,4,-2,DIRT:0)
Block(0,4,-1,GRASS:0)
Block(0,4,0,GRASS:0)
Block(0,4,1,GRASS:0)
Block(0,4,2,GRASS:0)
Block(0,4,3,GRASS:0)
Block(0,4,4,GRASS:0)
Block(0,4,5,GRASS:0)
Block(0,4,6,GRASS:0)
Block(0,5,-7,COBBLESTONE:0)
Block(0,5,-6,COBBLESTONE:0)
Block(0,5,-5,LOG:1)
Block(0,5,-4,DIRT:0)
Block(0,5,-3,DIRT:0)
Block(0,5,-2,DIRT:0)
Block(0,5,-1,SOIL:0)
Block(0,5,0,SOIL:0)
Block(0,5,1,SOIL:0)
Block(0,5,2,SOIL:0)
Block(0,5,3,SOIL:0)
Block(0,6,-7,STONE:0)
Block(0,6,-6,COBBLESTONE:0)
Block(0,6,-5,LOG:1)
Block(0,6,-4,STONE:0)
Block(0,6,-3,LOG:1)
Block(0,6,-2,HAY_BLOCK:0)
Block(0,6,-1,CROPS:7)
Block(0,6,0,CROPS:7)
Block(0,6,1,CROPS:7)
Block(0,6,2,CROPS:7)
Block(0,6,3,CROPS:7)
Block(0,7,-7,COBBLESTONE:0)
Block(0,7,-6,COBBLESTONE:0)
Block(0,7,-5,LOG:1)
Block(0,7,-4,STONE:6)
Block(0,7,-3,LOG:1)
Block(0,8,-7,COBBLESTONE:0)
Block(0,8,-6,COBBLESTONE:0)
Block(0,8,-5,LOG:1)
Block(0,8,-4,STONE:6)
Block(0,8,-3,LOG:1)
Block(0,9,-7,COBBLESTONE:0)
Block(0,9,-6,COBBLESTONE:0)
Block(0,9,-5,LOG:1)
Block(0,9,-4,SMOOTH_STAIRS:0)
Block(0,9,-3,DARK_OAK_STAIRS:3)
Block(0,10,-7,WOOD:0)
Block(0,10,-6,WOOD:5)
Block(0,10,-5,LOG:1)
Block(0,11,-7,WOOD:0)
Block(0,11,-6,WOOD:5)
Block(0,11,-5,LOG:1)
Block(0,12,-7,WOOD:0)
Block(0,12,-6,WOOD:5)
Block(0,12,-5,LOG:5)
Block(0,13,-7,WOOD_DOUBLE_STEP:1)
Block(0,13,-6,WOOD_DOUBLE_STEP:1)
Block(0,13,-5,WOOD_DOUBLE_STEP:1)
Block(0,13,-4,WOOD_STEP:1)
Block(1,0,-7,DIRT:0)
Block(1,0,-6,DIRT:0)
Block(1,0,-5,DIRT:0)
Block(1,0,-4,DIRT:0)
Block(1,0,-3,DIRT:0)
Block(1,0,-2,DIRT:0)
Block(1,0,-1,DIRT:0)
Block(1,0,0,DIRT:0)
Block(1,0,1,DIRT:0)
Block(1,0,2,DIRT:0)
Block(1,0,3,DIRT:0)
Block(1,0,4,DIRT:0)
Block(1,0,5,DIRT:0)
Block(1,0,6,DIRT:0)
Block(1,0,7,DIRT:0)
Block(1,0,8,DIRT:0)
Block(1,1,-7,DIRT:0)
Block(1,1,-6,DIRT:0)
Block(1,1,-5,DIRT:0)
Block(1,1,-4,DIRT:0)
Block(1,1,-3,DIRT:0)
Block(1,1,-2,DIRT:0)
Block(1,1,-1,DIRT:0)
Block(1,1,0,DIRT:0)
Block(1,1,1,DIRT:0)
Block(1,1,2,DIRT:0)
Block(1,1,3,DIRT:0)
Block(1,1,4,DIRT:0)
Block(1,1,5,DIRT:0)
Block(1,1,6,DIRT:0)
Block(1,1,7,DIRT:0)
Block(1,1,8,DIRT:0)
Block(1,2,-7,DIRT:0)
Block(1,2,-6,DIRT:0)
Block(1,2,-5,DIRT:0)
Block(1,2,-4,DIRT:0)
Block(1,2,-3,DIRT:0)
Block(1,2,-2,DIRT:0)
Block(1,2,-1,DIRT:0)
Block(1,2,0,DIRT:0)
Block(1,2,1,DIRT:0)
Block(1,2,2,DIRT:0)
Block(1,2,3,DIRT:0)
Block(1,2,4,DIRT:0)
Block(1,2,5,DIRT:0)
Block(1,2,6,DIRT:0)
Block(1,2,7,DIRT:0)
Block(1,2,8,GRASS:0)
Block(1,3,-7,GRASS:0)
Block(1,3,-6,DIRT:0)
Block(1,3,-5,DIRT:0)
Block(1,3,-4,DIRT:0)
Block(1,3,-3,DIRT:0)
Block(1,3,-2,DIRT:0)
Block(1,3,-1,DIRT:0)
Block(1,3,0,DIRT:0)
Block(1,3,1,DIRT:0)
Block(1,3,2,DIRT:0)
Block(1,3,3,DIRT:0)
Block(1,3,4,DIRT:0)
Block(1,3,5,DIRT:0)
Block(1,3,6,GRASS:0)
Block(1,3,7,GRASS:0)
#Block(1,4,-7,REDSTONE_LAMP_OFF:0)
Block(1,4,-6,COBBLESTONE:0)
Block(1,4,-5,COBBLESTONE:0)
Block(1,4,-4,DIRT:0)
Block(1,4,-3,DIRT:0)
Block(1,4,-2,DIRT:0)
Block(1,4,-1,DIRT:0)
Block(1,4,0,DIRT:0)
Block(1,4,1,DIRT:0)
Block(1,4,2,DIRT:0)
Block(1,4,3,DIRT:0)
Block(1,4,4,GRASS:0)
Block(1,4,5,GRASS:0)
Block(1,5,-7,WOOD_STEP:5)
Block(1,5,-6,WOOD_STEP:5)
Block(1,5,-5,WOOD_STEP:5)
Block(1,5,-4,COBBLESTONE:0)
Block(1,5,-3,DIRT:0)
Block(1,5,-2,DIRT:0)
Block(1,5,-1,GRASS:0)
Block(1,5,0,GRASS:0)
Block(1,5,1,DIRT:0)
Block(1,5,2,GRASS:0)
Block(1,5,3,DIRT:0)
Block(1,5,4,SOIL:0)
Block(1,6,-7,LOG:5)
Block(1,6,-5,LADDER:2)
Block(1,6,-4,COBBLESTONE:0)
Block(1,6,-3,STONE:0)
Block(1,6,-2,LOG:1)
Block(1,6,1,LOG:1)
Block(1,6,3,LOG:1)
Block(1,6,4,CROPS:7)
Block(1,7,-5,LADDER:2)
Block(1,7,-4,COBBLESTONE:0)
Block(1,7,-3,STONE:6)
Block(1,7,-2,LOG:1)
Block(1,7,1,LOG:1)
Block(1,7,2,WOOD_STEP:9)
Block(1,7,3,WOOD_STEP:1)
Block(1,8,-5,LADDER:2)
Block(1,8,-4,COBBLESTONE:0)
Block(1,8,-3,STONE:6)
Block(1,8,-2,LOG:1)
Block(1,8,0,WOOD_STEP:9)
Block(1,8,1,WOOD_STEP:1)
Block(1,9,-5,LADDER:2)
Block(1,9,-4,COBBLESTONE:0)
Block(1,9,-3,SMOOTH_STAIRS:0)
Block(1,9,-2,DARK_OAK_STAIRS:3)
Block(1,9,-1,WOOD_STEP:1)
Block(1,10,-5,LADDER:2)
Block(1,10,-4,WOOD:0)
Block(1,11,-4,WOOD:0)
Block(1,12,-5,LOG:5)
Block(1,12,-4,WOOD:0)
Block(1,13,-7,WOOD:0)
Block(1,13,-6,WOOD:5)
Block(1,13,-5,WOOD:0)
Block(1,13,-4,WOOD_DOUBLE_STEP:1)
Block(1,13,-3,WOOD_STEP:1)
Block(1,14,-7,SPRUCE_WOOD_STAIRS:0)
Block(1,14,-6,SPRUCE_WOOD_STAIRS:0)
Block(1,14,-5,SPRUCE_WOOD_STAIRS:3)
Block(1,18,-5,LOG:5)
Block(1,25,-5,DARK_OAK_STAIRS:6)
Block(1,25,-4,DARK_OAK_STAIRS:7)
Block(1,26,-5,LOG:5)
Block(1,26,-4,DARK_OAK_STAIRS:3)
Block(1,27,-5,WOOD:5)
Block(1,28,-6,SPRUCE_WOOD_STAIRS:6)
Block(1,28,-5,DARK_OAK_STAIRS:3)
Block(1,29,-7,DARK_OAK_STAIRS:4)
Block(1,29,-6,WOOD:5)
Block(1,30,-7,WOOD:1)
Block(1,30,-6,DARK_OAK_STAIRS:3)
Block(1,31,-7,WOOD_STEP:5)
Block(2,0,-7,DIRT:0)
Block(2,0,-6,DIRT:0)
Block(2,0,-5,DIRT:0)
Block(2,0,-4,DIRT:0)
Block(2,0,-3,DIRT:0)
Block(2,0,-2,DIRT:0)
Block(2,0,-1,DIRT:0)
Block(2,0,0,DIRT:0)
Block(2,0,1,DIRT:0)
Block(2,0,2,DIRT:0)
Block(2,0,3,DIRT:0)
Block(2,0,4,DIRT:0)
Block(2,0,5,DIRT:0)
Block(2,0,6,DIRT:0)
Block(2,0,7,DIRT:0)
Block(2,0,8,DIRT:0)
Block(2,1,-7,DIRT:0)
Block(2,1,-6,DIRT:0)
Block(2,1,-5,DIRT:0)
Block(2,1,-4,DIRT:0)
Block(2,1,-3,DIRT:0)
Block(2,1,-2,DIRT:0)
Block(2,1,-1,DIRT:0)
Block(2,1,0,DIRT:0)
Block(2,1,1,DIRT:0)
Block(2,1,2,DIRT:0)
Block(2,1,3,DIRT:0)
Block(2,1,4,DIRT:0)
Block(2,1,5,DIRT:0)
Block(2,1,6,DIRT:0)
Block(2,1,7,DIRT:0)
Block(2,1,8,DIRT:0)
Block(2,2,-7,DIRT:0)
Block(2,2,-6,DIRT:0)
Block(2,2,-5,DIRT:0)
Block(2,2,-4,DIRT:0)
Block(2,2,-3,DIRT:0)
Block(2,2,-2,DIRT:0)
Block(2,2,-1,DIRT:0)
Block(2,2,0,DIRT:0)
Block(2,2,1,DIRT:0)
Block(2,2,2,DIRT:0)
Block(2,2,3,DIRT:0)
Block(2,2,4,DIRT:0)
Block(2,2,5,DIRT:0)
Block(2,2,6,DIRT:0)
Block(2,2,7,DIRT:0)
Block(2,2,8,GRASS:0)
Block(2,3,-7,GRASS:0)
Block(2,3,-6,GRASS:0)
Block(2,3,-5,GRASS:0)
Block(2,3,-4,DIRT:0)
Block(2,3,-3,DIRT:0)
Block(2,3,-2,DIRT:0)
Block(2,3,-1,DIRT:0)
Block(2,3,0,DIRT:0)
Block(2,3,1,DIRT:0)
Block(2,3,2,DIRT:0)
Block(2,3,3,DIRT:0)
Block(2,3,4,DIRT:0)
Block(2,3,5,DIRT:0)
Block(2,3,6,DIRT:0)
Block(2,3,7,GRASS:0)
Block(2,4,-7,HOPPER:5)
Block(2,4,-6,HOPPER:2)
Block(2,4,-5,HOPPER:2)
Block(2,4,-4,DIRT:0)
Block(2,4,-3,DIRT:0)
Block(2,4,-2,DIRT:0)
Block(2,4,-1,DIRT:0)
Block(2,4,0,DIRT:0)
Block(2,4,1,DIRT:0)
Block(2,4,2,DIRT:0)
Block(2,4,3,DIRT:0)
Block(2,4,4,GRASS:0)
Block(2,4,5,GRASS:0)
Block(2,4,6,GRASS:0)
Block(2,5,-4,COBBLESTONE:0)
Block(2,5,-3,DIRT:0)
Block(2,5,-2,DIRT:0)
Block(2,5,-1,DIRT:0)
Block(2,5,0,DIRT:0)
Block(2,5,1,GRASS:0)
Block(2,5,2,DIRT:0)
Block(2,5,3,GRASS:0)
Block(2,5,4,SOIL:0)
Block(2,6,-7,LOG:5)
Block(2,6,-5,COBBLESTONE_STAIRS:6)
Block(2,6,-4,COBBLESTONE:0)
Block(2,6,-3,STONE:0)
Block(2,6,-2,COBBLESTONE:0)
Block(2,6,-1,HAY_BLOCK:0)
Block(2,6,0,HAY_BLOCK:0)
Block(2,6,2,HAY_BLOCK:0)
Block(2,6,3,DARK_OAK_FENCE:0)
Block(2,6,4,CROPS:7)
Block(2,7,-7,WOOD_STEP:5)
Block(2,7,-6,WOOD_STEP:5)
Block(2,7,-5,WOOD_STEP:5)
Block(2,7,-4,WOOD_STEP:5)
Block(2,7,-3,LOG:1)
Block(2,7,-2,COBBLESTONE:0)
Block(2,7,2,WOOD_STEP:9)
Block(2,7,3,WOOD_STEP:1)
Block(2,8,-3,LOG:1)
Block(2,8,-2,COBBLESTONE:0)
Block(2,8,0,WOOD_STEP:9)
Block(2,8,1,WOOD_STEP:1)
Block(2,9,-4,DARK_OAK_STAIRS:6)
Block(2,9,-3,LOG:1)
Block(2,9,-2,SMOOTH_STAIRS:3)
Block(2,9,-1,WOOD_STEP:1)
Block(2,10,-4,HAY_BLOCK:8)
Block(2,10,-3,LOG:1)
Block(2,11,-3,LOG:1)
Block(2,12,-7,LOG:9)
Block(2,12,-6,LOG:9)
Block(2,12,-5,LOG:9)
Block(2,12,-4,LOG:9)
Block(2,12,-3,LOG:9)
Block(2,12,-2,LOG:9)
Block(2,13,-7,WOOD:0)
Block(2,13,-6,WOOD:5)
Block(2,13,-5,LOG:1)
Block(2,13,-4,WOOD:0)
Block(2,13,-3,WOOD_DOUBLE_STEP:1)
Block(2,13,-2,WOOD_STEP:1)
Block(2,14,-7,WOOD:0)
Block(2,14,-6,WOOD:5)
Block(2,14,-5,LOG:1)
Block(2,14,-4,SPRUCE_WOOD_STAIRS:0)
Block(2,15,-7,WOOD_STEP:1)
Block(2,15,-6,WOOD:5)
Block(2,15,-5,LOG:1)
Block(2,16,-7,SPRUCE_WOOD_STAIRS:4)
Block(2,16,-6,WOOD:5)
Block(2,16,-5,LOG:1)
Block(2,17,-7,WOOD:0)
Block(2,17,-6,WOOD:5)
Block(2,17,-5,LOG:1)
Block(2,18,-7,LOG:9)
Block(2,18,-6,LOG:9)
Block(2,18,-5,LOG:1)
Block(2,18,-4,LOG:9)
Block(2,19,-7,WOOD:0)
Block(2,19,-6,WOOD:5)
Block(2,19,-5,LOG:1)
Block(2,20,-7,WOOD_STEP:1)
Block(2,20,-6,WOOD:5)
Block(2,20,-5,LOG:1)
Block(2,21,-7,SPRUCE_WOOD_STAIRS:0)
Block(2,21,-6,WOOD:5)
Block(2,21,-5,LOG:1)
Block(2,22,-7,FENCE:0)
Block(2,22,-6,WOOD:5)
Block(2,22,-5,LOG:1)
Block(2,23,-7,SPRUCE_WOOD_STAIRS:4)
Block(2,23,-6,WOOD:5)
Block(2,23,-5,LOG:1)
Block(2,24,-7,WOOD:0)
Block(2,24,-6,WOOD:5)
Block(2,24,-5,LOG:1)
Block(2,25,-7,WOOD:0)
Block(2,25,-6,WOOD:5)
Block(2,25,-5,LOG:1)
Block(2,25,-4,SPRUCE_WOOD_STAIRS:7)
Block(2,26,-7,LOG:9)
Block(2,26,-6,LOG:9)
Block(2,26,-5,LOG:1)
Block(2,26,-4,LOG:9)
Block(2,27,-7,WOOD:0)
Block(2,27,-6,WOOD:5)
Block(2,27,-5,WOOD:1)
Block(2,28,-7,WOOD:0)
Block(2,28,-6,WOOD:5)
Block(2,28,-5,SPRUCE_WOOD_STAIRS:3)
Block(2,29,-7,WOOD:0)
Block(2,29,-6,WOOD:1)
Block(2,30,-7,WOOD:1)
Block(2,30,-6,SPRUCE_WOOD_STAIRS:3)
Block(2,31,-7,WOOD_STEP:5)
Block(3,0,-7,DIRT:0)
Block(3,0,-6,DIRT:0)
Block(3,0,-5,DIRT:0)
Block(3,0,-4,DIRT:0)
Block(3,0,-3,DIRT:0)
Block(3,0,-2,DIRT:0)
Block(3,0,-1,DIRT:0)
Block(3,0,0,DIRT:0)
Block(3,0,1,DIRT:0)
Block(3,0,2,DIRT:0)
Block(3,0,3,DIRT:0)
Block(3,0,4,DIRT:0)
Block(3,0,5,DIRT:0)
Block(3,0,6,DIRT:0)
Block(3,0,7,DIRT:0)
Block(3,0,8,DIRT:0)
Block(3,1,-7,DIRT:0)
Block(3,1,-6,DIRT:0)
Block(3,1,-5,DIRT:0)
Block(3,1,-4,DIRT:0)
Block(3,1,-3,DIRT:0)
Block(3,1,-2,DIRT:0)
Block(3,1,-1,DIRT:0)
Block(3,1,0,DIRT:0)
Block(3,1,1,DIRT:0)
Block(3,1,2,DIRT:0)
Block(3,1,3,DIRT:0)
Block(3,1,4,DIRT:0)
Block(3,1,5,DIRT:0)
Block(3,1,6,DIRT:0)
Block(3,1,7,DIRT:0)
Block(3,1,8,DIRT:0)
Block(3,2,-7,DIRT:0)
Block(3,2,-6,DIRT:0)
Block(3,2,-5,DIRT:0)
Block(3,2,-4,DIRT:0)
Block(3,2,-3,DIRT:0)
Block(3,2,-2,DIRT:0)
Block(3,2,-1,DIRT:0)
Block(3,2,0,DIRT:0)
Block(3,2,1,DIRT:0)
Block(3,2,2,DIRT:0)
Block(3,2,3,DIRT:0)
Block(3,2,4,DIRT:0)
Block(3,2,5,DIRT:0)
Block(3,2,6,DIRT:0)
Block(3,2,7,DIRT:0)
Block(3,2,8,GRASS:0)
Block(3,3,-7,GRASS:0)
Block(3,3,-6,DIRT:0)
Block(3,3,-5,DIRT:0)
Block(3,3,-4,DIRT:0)
Block(3,3,-3,DIRT:0)
Block(3,3,-2,DIRT:0)
Block(3,3,-1,DIRT:0)
Block(3,3,0,DIRT:0)
Block(3,3,1,DIRT:0)
Block(3,3,2,DIRT:0)
Block(3,3,3,DIRT:0)
Block(3,3,4,DIRT:0)
Block(3,3,5,DIRT:0)
Block(3,3,6,DIRT:0)
Block(3,3,7,GRASS:0)
Block(3,4,-7,HOPPER:0)
Block(3,4,-6,COBBLESTONE:0)
Block(3,4,-5,COBBLESTONE:0)
Block(3,4,-4,DIRT:0)
Block(3,4,-3,DIRT:0)
Block(3,4,-2,DIRT:0)
Block(3,4,-1,DIRT:0)
Block(3,4,0,DIRT:0)
Block(3,4,1,DIRT:0)
Block(3,4,2,DIRT:0)
Block(3,4,3,DIRT:0)
Block(3,4,4,GRASS:0)
Block(3,4,5,GRASS:0)
Block(3,4,6,GRASS:0)
Block(3,5,-7,WOOD_STEP:5)
Block(3,5,-6,WOOD_STEP:5)
Block(3,5,-5,WOOD_STEP:5)
Block(3,5,-4,COBBLESTONE:0)
Block(3,5,-3,DIRT:0)
Block(3,5,-2,DIRT:0)
Block(3,5,-1,DIRT:0)
Block(3,5,0,DIRT:0)
Block(3,5,1,DIRT:0)
Block(3,5,2,GRASS:0)
Block(3,5,3,GRASS:0)
Block(3,5,4,SOIL:0)
Block(3,5,5,SOIL:0)
Block(3,6,-7,LOG:5)
Block(3,6,-4,COBBLESTONE:0)
Block(3,6,-3,STONE:0)
Block(3,6,-2,COBBLESTONE_STAIRS:3)
Block(3,6,-1,HAY_BLOCK:4)
Block(3,6,0,HAY_BLOCK:4)
Block(3,6,1,HAY_BLOCK:0)
Block(3,6,3,DARK_OAK_FENCE:0)
Block(3,6,4,CROPS:7)
Block(3,6,5,CROPS:7)
Block(3,7,-7,LOG:1)
Block(3,7,-4,HAY_BLOCK:8)
Block(3,7,-3,COBBLESTONE:0)
Block(3,7,-2,COBBLESTONE_STAIRS:7)
Block(3,7,-1,HAY_BLOCK:8)
Block(3,7,0,HAY_BLOCK:0)
Block(3,7,2,WOOD_STEP:9)
Block(3,7,3,WOOD_STEP:1)
Block(3,8,-7,LOG:1)
Block(3,8,-3,COBBLESTONE:0)
Block(3,8,-2,COBBLESTONE_STAIRS:3)
Block(3,8,-1,HAY_BLOCK:8)
Block(3,8,0,WOOD_STEP:9)
Block(3,8,1,WOOD_STEP:1)
Block(3,9,-7,LOG:1)
Block(3,9,-4,DARK_OAK_STAIRS:6)
Block(3,9,-3,COBBLESTONE:0)
Block(3,9,-1,WOOD_STEP:1)
Block(3,10,-7,LOG:1)
Block(3,10,-4,HAY_BLOCK:0)
Block(3,10,-3,WOOD:5)
Block(3,11,-7,LOG:1)
Block(3,11,-4,HAY_BLOCK:4)
Block(3,11,-3,WOOD:5)
Block(3,12,-7,LOG:9)
Block(3,12,-6,LOG:9)
Block(3,12,-5,LOG:5)
Block(3,12,-3,WOOD:5)
Block(3,13,-7,LOG:1)
RandomBlock(3,13,-6,AIR:0,20,CHEST:5,../../../Chests//Loot/JunkChest_1.nbt,10,CHEST:5,../../../Chests//Loot/JunkChest_2.nbt,10,CHEST:5,../../../Chests//Loot/JunkChest_3.nbt,10,CHEST:5,../../../Chests//Loot/JunkChest_4.nbt,10,CHEST:5,../../../Chests//Loot/JunkChest_5.nbt,10,CHEST:5,../../../Chests//Lore/Farmland_1.nbt,1,CHEST:5,../../../Chests//Lore/Farmland_2.nbt,1,CHEST:5,../../../Chests//Lore/Farmland_3.nbt,1,CHEST:5,../../../Chests//Lore/Farmland_4.nbt,1,CHEST:5,../../../Chests//Lore/Farmland_5.nbt,1,CHEST:5,../../../Chests//Loot/Common1.nbt,10,CHEST:5,../../../Chests//Loot/Common2.nbt,10,CHEST:5,../../../Chests//Loot/Common3.nbt,10,CHEST:5,../../../Chests//Loot/Common4.nbt,10,CHEST:5,../../../Chests//Loot/Common5.nbt,10,CHEST:5,../../../Chests//Loot/Common6.nbt,10,CHEST:5,../../../Chests//Loot/Common7.nbt,10,CHEST:5,../../../Chests//Loot/Common8.nbt,10,CHEST:5,../../../Chests//Loot/Common9.nbt,10,CHEST:5,../../../Chests//Loot/Common10.nbt,10,CHEST:5,../../../Chests//Loot/Common10.nbt,11,CHEST:5,../../../Chests//Loot/Common12.nbt,10,CHEST:5,../../../Chests//Loot/Common13.nbt,10,CHEST:5,../../../Chests//Loot/Common14.nbt,10,CHEST:5,../../../Chests//Loot/Common15.nbt,10,CHEST:5,../../../Chests//Lore/Farmland_1.nbt,2,CHEST:5,../../../Chests//Lore/Farmland_3.nbt,2,CHEST:5,../../../Chests//Lore/Farmland_4.nbt,2,CHEST:5,../../../Chests//Lore/Farmland_5.nbt,2,CHEST:5,../../../Chests//Lore/Farmland_5.nbt,2,CHEST:5,../../../Chests//Loot/Rare1.nbt,5,CHEST:5,../../../Chests//Loot/Rare2.nbt,5,CHEST:5,../../../Chests//Loot/Rare3.nbt,5,CHEST:5,../../../Chests//Loot/Rare4.nbt,5,CHEST:5,../../../Chests//Loot/Rare5.nbt,5,CHEST:5,../../../Chests//Loot/Rare6.nbt,5,CHEST:5,../../../Chests//Loot/Rare7.nbt,5,CHEST:5,../../../Chests//Loot/Rare8.nbt,5,CHEST:5,../../../Chests//Loot/Rare9.nbt,5,CHEST:5,../../../Chests//Loot/Rare10.nbt,5,CHEST:5,../../../Chests//Loot/Rare11.nbt,5,CHEST:5,../../../Chests//Loot/Rare12.nbt,5,CHEST:5,../../../Chests//Loot/Rare13.nbt,5,CHEST:5,../../../Chests//Loot/Rare14.nbt,5,CHEST:5,../../../Chests//Loot/Rare15.nbt,5,CHEST:5,../../../Chests//Loot/Epic1.nbt,2,CHEST:5,../../../Chests//Loot/Epic2.nbt,2,CHEST:5,../../../Chests//Loot/Epic3.nbt,2,CHEST:5,../../../Chests//Loot/Epic4.nbt,2,CHEST:5,../../../Chests//Loot/Epic5.nbt,2,CHEST:5,../../../Chests//Loot/Epic6.nbt,2,CHEST:5,../../../Chests//Loot/Epic7.nbt,2,CHEST:5,../../../Chests//Loot/Epic8.nbt,2,CHEST:5,../../../Chests//Loot/Epic9.nbt,2,CHEST:5,../../../Chests//Loot/Epic10.nbt,2,CHEST:5,../../../Chests//Loot/Epic11.nbt,2,CHEST:5,../../../Chests//Loot/Epic12.nbt,2,CHEST:5,../../../Chests//Loot/Epic13.nbt,2,CHEST:5,../../../Chests//Loot/Epic14.nbt,2,CHEST:5,../../../Chests//Loot/Epic15.nbt,5,CHEST:5,../../../Chests//Loot/Rare1.nbt,5,CHEST:5,../../../Chests//Loot/Rare2.nbt,5,CHEST:5,../../../Chests//Loot/Rare3.nbt,5,CHEST:5,../../../Chests//Loot/Rare4.nbt,5,CHEST:5,../../../Chests//Loot/Rare5.nbt,10,CHEST:5,../../../Chests//Loot/Rare6.nbt,10,CHEST:5,../../../Chests//Loot/Rare7.nbt,10,CHEST:5,../../../Chests//Loot/Rare8.nbt,10,CHEST:5,../../../Chests//Loot/Rare9.nbt,10,CHEST:5,../../../Chests//Loot/Rare10.nbt,15,CHEST:5,../../../Chests//Loot/Rare11.nbt,15,CHEST:5,../../../Chests//Loot/Rare12.nbt,15,CHEST:5,../../../Chests//Loot/Rare13.nbt,15,CHEST:5,../../../Chests//Loot/Rare14.nbt,15,CHEST:5,../../../Chests//Loot/Rare15.nbt,15,CHEST:5,../../../Chests//Loot/Epic15.nbt,100)
Block(3,13,-5,WOOD:0)
Block(3,13,-4,WOOD:0)
Block(3,13,-3,WOOD_DOUBLE_STEP:1)
Block(3,13,-2,WOOD_STEP:1)
Block(3,14,-7,LOG:1)
Block(3,14,-5,WOOD:0)
Block(3,14,-4,SPRUCE_WOOD_STAIRS:3)
Block(3,15,-7,LOG:1)
Block(3,15,-5,WOOD:5)
Block(3,16,-7,LOG:1)
Block(3,16,-5,WOOD:5)
Block(3,17,-7,LOG:1)
Block(3,17,-5,WOOD:5)
Block(3,18,-7,LOG:1)
Block(3,18,-6,COBBLE_WALL:0)
Block(3,18,-5,LOG:5)
Block(3,19,-7,LOG:1)
Block(3,19,-6,TORCH:5)
Block(3,19,-5,WOOD:5)
Block(3,20,-7,LOG:1)
Block(3,20,-5,WOOD:5)
Block(3,21,-7,LOG:1)
Block(3,21,-6,WOOD_STEP:13)
Block(3,21,-5,WOOD:5)
Block(3,22,-6,LADDER:2)
Block(3,22,-5,WOOD:5)
Block(3,23,-6,LADDER:2)
Block(3,23,-5,WOOD:5)
Block(3,24,-6,LADDER:2)
Block(3,24,-5,WOOD:5)
Block(3,25,-6,LADDER:2)
Block(3,25,-5,WOOD:5)
Block(3,25,-4,SPRUCE_WOOD_STAIRS:7)
Block(3,26,-7,LOG:5)
Block(3,26,-6,LADDER:2)
Block(3,26,-5,LOG:5)
Block(3,26,-4,WOOD:5)
Block(3,27,-6,LADDER:2)
Block(3,27,-5,WOOD:5)
Block(3,27,-4,WOOD:5)
Block(3,28,-5,SPRUCE_WOOD_STAIRS:0)
Block(3,28,-4,SPRUCE_WOOD_STAIRS:0)
Block(3,29,-7,TRAP_DOOR:9)
Block(3,29,-6,WOOD:1)
Block(3,30,-7,WOOD:1)
Block(3,30,-6,SPRUCE_WOOD_STAIRS:3)
Block(3,31,-7,WOOD_STEP:5)
Block(4,0,-7,DIRT:0)
Block(4,0,-6,DIRT:0)
Block(4,0,-5,DIRT:0)
Block(4,0,-4,DIRT:0)
Block(4,0,-3,DIRT:0)
Block(4,0,-2,DIRT:0)
Block(4,0,-1,DIRT:0)
Block(4,0,0,DIRT:0)
Block(4,0,1,DIRT:0)
Block(4,0,2,DIRT:0)
Block(4,0,3,DIRT:0)
Block(4,0,4,DIRT:0)
Block(4,0,5,DIRT:0)
Block(4,0,6,DIRT:0)
Block(4,0,7,DIRT:0)
Block(4,0,8,DIRT:0)
Block(4,1,-7,DIRT:0)
Block(4,1,-6,DIRT:0)
Block(4,1,-5,DIRT:0)
Block(4,1,-4,DIRT:0)
Block(4,1,-3,DIRT:0)
Block(4,1,-2,DIRT:0)
Block(4,1,-1,DIRT:0)
Block(4,1,0,DIRT:0)
Block(4,1,1,DIRT:0)
Block(4,1,2,DIRT:0)
Block(4,1,3,DIRT:0)
Block(4,1,4,DIRT:0)
Block(4,1,5,DIRT:0)
Block(4,1,6,DIRT:0)
Block(4,1,7,DIRT:0)
Block(4,1,8,DIRT:0)
Block(4,2,-7,DIRT:0)
Block(4,2,-6,DIRT:0)
Block(4,2,-5,DIRT:0)
Block(4,2,-4,DIRT:0)
Block(4,2,-3,DIRT:0)
Block(4,2,-2,DIRT:0)
Block(4,2,-1,DIRT:0)
Block(4,2,0,DIRT:0)
Block(4,2,1,DIRT:0)
Block(4,2,2,DIRT:0)
Block(4,2,3,DIRT:0)
Block(4,2,4,DIRT:0)
Block(4,2,5,DIRT:0)
Block(4,2,6,DIRT:0)
Block(4,2,7,DIRT:0)
Block(4,2,8,DIRT:0)
Block(4,3,-7,GRASS:0)
Block(4,3,-6,DIRT:0)
Block(4,3,-5,GRASS:0)
Block(4,3,-4,DIRT:0)
Block(4,3,-3,DIRT:0)
Block(4,3,-2,DIRT:0)
Block(4,3,-1,DIRT:0)
Block(4,3,0,DIRT:0)
Block(4,3,1,DIRT:0)
Block(4,3,2,DIRT:0)
Block(4,3,3,DIRT:0)
Block(4,3,4,DIRT:0)
Block(4,3,5,DIRT:0)
Block(4,3,6,DIRT:0)
Block(4,3,7,DIRT:0)
Block(4,3,8,GRASS:0)
Block(4,4,-7,WOOD_STEP:5)
Block(4,4,-6,WOOD_STEP:5)
Block(4,4,-5,SMOOTH_STAIRS:2)
Block(4,4,-4,COBBLESTONE:0)
Block(4,4,-3,DIRT:0)
Block(4,4,-2,DIRT:0)
Block(4,4,-1,DIRT:0)
Block(4,4,0,DIRT:0)
Block(4,4,1,DIRT:0)
Block(4,4,2,DIRT:0)
Block(4,4,3,DIRT:0)
Block(4,4,4,GRASS:0)
Block(4,4,5,GRASS:0)
Block(4,4,6,GRASS:0)
Block(4,4,7,GRASS:0)
Block(4,5,-7,WOOD_DOUBLE_STEP:5)
Block(4,5,-6,SMOOTH_STAIRS:7)
Block(4,5,-4,COBBLESTONE:0)
Block(4,5,-3,DIRT:0)
Block(4,5,-2,DIRT:0)
Block(4,5,-1,DIRT:0)
Block(4,5,0,DIRT:0)
Block(4,5,1,DIRT:0)
Block(4,5,2,GRASS:0)
Block(4,5,3,DIRT:0)
Block(4,5,4,SOIL:0)
Block(4,5,5,SOIL:0)
Block(4,6,-7,LOG:5)
Block(4,6,-6,WOOD_DOUBLE_STEP:5)
Block(4,6,-4,COBBLESTONE:0)
Block(4,6,-3,STONE:0)
Block(4,6,-2,COBBLESTONE:0)
Block(4,6,-1,HAY_BLOCK:0)
Block(4,6,0,HAY_BLOCK:0)
Block(4,6,1,HAY_BLOCK:0)
Block(4,6,3,LOG:1)
Block(4,6,4,CROPS:7)
Block(4,6,5,CROPS:7)
Block(4,7,-7,WOOD_DOUBLE_STEP:5)
Block(4,7,-6,SMOOTH_STAIRS:3)
Block(4,7,-4,HAY_BLOCK:4)
Block(4,7,-3,COBBLESTONE:0)
Block(4,7,-2,COBBLESTONE:0)
Block(4,7,2,WOOD_STEP:9)
Block(4,7,3,WOOD_STEP:1)
Block(4,8,-4,HAY_BLOCK:0)
Block(4,8,-3,COBBLESTONE:0)
Block(4,8,-2,COBBLESTONE:0)
Block(4,8,0,WOOD_STEP:9)
Block(4,8,1,WOOD_STEP:1)
Block(4,9,-7,DARK_OAK_STAIRS:5)
Block(4,9,-4,DARK_OAK_STAIRS:6)
Block(4,9,-3,COBBLESTONE:0)
Block(4,9,-2,SMOOTH_STAIRS:3)
Block(4,9,-1,WOOD_STEP:1)
Block(4,10,-7,LADDER:5)
Block(4,10,-4,HAY_BLOCK:4)
Block(4,10,-3,WOOD:0)
Block(4,11,-7,LADDER:5)
Block(4,11,-4,HAY_BLOCK:8)
Block(4,11,-3,WOOD:0)
Block(4,12,-7,LADDER:5)
Block(4,12,-5,LOG:5)
Block(4,12,-4,HAY_BLOCK:0)
Block(4,12,-3,WOOD:0)
Block(4,13,-7,LADDER:5)
Block(4,13,-5,WOOD:0)
Block(4,13,-4,WOOD:0)
Block(4,13,-3,WOOD_DOUBLE_STEP:1)
Block(4,13,-2,WOOD_STEP:1)
Block(4,14,-7,LADDER:5)
Block(4,14,-5,WOOD:0)
Block(4,14,-4,SPRUCE_WOOD_STAIRS:3)
Block(4,15,-7,LADDER:5)
Block(4,15,-5,WOOD_STEP:1)
Block(4,16,-7,LADDER:5)
Block(4,16,-5,SPRUCE_WOOD_STAIRS:7)
Block(4,17,-7,LADDER:5)
Block(4,17,-5,WOOD:0)
Block(4,18,-7,LADDER:5)
Block(4,18,-5,LOG:5)
Block(4,19,-7,LADDER:5)
Block(4,19,-5,WOOD:0)
Block(4,20,-7,LADDER:5)
Block(4,20,-5,WOOD_STEP:1)
Block(4,21,-7,LADDER:5)
Block(4,21,-5,SPRUCE_WOOD_STAIRS:3)
Block(4,22,-5,FENCE:0)
Block(4,23,-5,SPRUCE_WOOD_STAIRS:7)
Block(4,24,-5,WOOD:0)
Block(4,25,-7,WOOD:5)
Block(4,25,-6,COBBLESTONE_STAIRS:7)
Block(4,25,-5,WOOD:0)
Block(4,25,-4,SPRUCE_WOOD_STAIRS:7)
Block(4,26,-7,LOG:5)
Block(4,26,-6,WOOD:5)
Block(4,26,-4,WOOD_STEP:1)
Block(4,27,-7,WOOD:5)
Block(4,27,-6,COBBLESTONE_STAIRS:3)
Block(4,28,-5,WOOD_STEP:9)
Block(4,28,-4,WOOD_STEP:9)
Block(4,29,-7,TRAP_DOOR:9)
Block(4,29,-6,WOOD:1)
Block(4,29,-5,WOOD_STEP:1)
Block(4,29,-4,WOOD_STEP:1)
#Block(4,30,-7,REDSTONE_LAMP_OFF:0)
Block(4,30,-6,SPRUCE_WOOD_STAIRS:3)
Block(4,31,-7,WOOD_STEP:5)
Block(5,0,-7,DIRT:0)
Block(5,0,-6,DIRT:0)
Block(5,0,-5,DIRT:0)
Block(5,0,-4,DIRT:0)
Block(5,0,-3,DIRT:0)
Block(5,0,-2,DIRT:0)
Block(5,0,-1,DIRT:0)
Block(5,0,0,DIRT:0)
Block(5,0,1,DIRT:0)
Block(5,0,2,DIRT:0)
Block(5,0,3,DIRT:0)
Block(5,0,4,DIRT:0)
Block(5,0,5,DIRT:0)
Block(5,0,6,DIRT:0)
Block(5,0,7,DIRT:0)
Block(5,0,8,DIRT:0)
Block(5,1,-7,DIRT:0)
Block(5,1,-6,DIRT:0)
Block(5,1,-5,DIRT:0)
Block(5,1,-4,DIRT:0)
Block(5,1,-3,DIRT:0)
Block(5,1,-2,DIRT:0)
Block(5,1,-1,DIRT:0)
Block(5,1,0,DIRT:0)
Block(5,1,1,DIRT:0)
Block(5,1,2,DIRT:0)
Block(5,1,3,DIRT:0)
Block(5,1,4,DIRT:0)
Block(5,1,5,DIRT:0)
Block(5,1,6,DIRT:0)
Block(5,1,7,DIRT:0)
Block(5,1,8,DIRT:0)
Block(5,2,-7,DIRT:0)
Block(5,2,-6,DIRT:0)
Block(5,2,-5,DIRT:0)
Block(5,2,-4,DIRT:0)
Block(5,2,-3,DIRT:0)
Block(5,2,-2,DIRT:0)
Block(5,2,-1,DIRT:0)
Block(5,2,0,DIRT:0)
Block(5,2,1,DIRT:0)
Block(5,2,2,DIRT:0)
Block(5,2,3,DIRT:0)
Block(5,2,4,DIRT:0)
Block(5,2,5,DIRT:0)
Block(5,2,6,DIRT:0)
Block(5,2,7,DIRT:0)
Block(5,2,8,DIRT:0)
Block(5,3,-7,DIRT:0)
Block(5,3,-6,DIRT:0)
Block(5,3,-5,DIRT:0)
Block(5,3,-4,DIRT:0)
Block(5,3,-3,DIRT:0)
Block(5,3,-2,DIRT:0)
Block(5,3,-1,DIRT:0)
Block(5,3,0,DIRT:0)
Block(5,3,1,DIRT:0)
Block(5,3,2,DIRT:0)
Block(5,3,3,DIRT:0)
Block(5,3,4,DIRT:0)
Block(5,3,5,DIRT:0)
Block(5,3,6,DIRT:0)
Block(5,3,7,DIRT:0)
Block(5,3,8,DIRT:0)
Block(5,4,-7,COBBLESTONE:0)
Block(5,4,-6,COBBLESTONE:0)
Block(5,4,-5,COBBLESTONE:0)
Block(5,4,-4,DIRT:0)
Block(5,4,-3,DIRT:0)
Block(5,4,-2,DIRT:0)
Block(5,4,-1,DIRT:0)
Block(5,4,0,DIRT:0)
Block(5,4,1,DIRT:0)
Block(5,4,2,DIRT:0)
Block(5,4,3,DIRT:0)
Block(5,4,4,GRASS:0)
Block(5,4,5,GRASS:0)
Block(5,4,6,DIRT:0)
Block(5,4,7,GRASS:0)
Block(5,4,8,GRASS:0)
Block(5,5,-7,IRON_FENCE:0)
Block(5,5,-6,IRON_FENCE:0)
Block(5,5,-5,SMOOTH_STAIRS:2)
Block(5,5,-4,DIRT:0)
Block(5,5,-3,DIRT:0)
Block(5,5,-2,DIRT:0)
Block(5,5,-1,DIRT:0)
Block(5,5,0,DIRT:0)
Block(5,5,1,GRASS:0)
Block(5,5,2,DIRT:0)
Block(5,5,3,GRASS:0)
Block(5,5,4,SOIL:0)
Block(5,5,5,SOIL:0)
Block(5,5,6,GRASS:0)
Block(5,6,-7,LOG:5)
Block(5,6,-6,IRON_FENCE:0)
Block(5,6,-4,COBBLESTONE:0)
Block(5,6,-3,STONE:0)
Block(5,6,-2,COBBLESTONE_STAIRS:3)
Block(5,6,-1,HAY_BLOCK:8)
Block(5,6,0,HAY_BLOCK:0)
Block(5,6,2,HAY_BLOCK:0)
Block(5,6,3,DARK_OAK_FENCE:0)
Block(5,6,4,CROPS:7)
Block(5,6,5,CROPS:7)
Block(5,6,6,DARK_OAK_FENCE:0)
Block(5,7,-6,IRON_FENCE:0)
Block(5,7,-4,HAY_BLOCK:0)
Block(5,7,-3,COBBLESTONE:0)
Block(5,7,-2,COBBLESTONE_STAIRS:7)
Block(5,7,2,WOOD_STEP:9)
Block(5,7,3,WOOD_STEP:1)
Block(5,8,-6,IRON_FENCE:0)
Block(5,8,-3,COBBLESTONE:0)
Block(5,8,-2,COBBLESTONE_STAIRS:3)
Block(5,8,0,WOOD_STEP:9)
Block(5,8,1,WOOD_STEP:1)
Block(5,9,-7,WOOD_STEP:13)
Block(5,9,-6,IRON_FENCE:0)
Block(5,9,-4,DARK_OAK_STAIRS:6)
Block(5,9,-3,COBBLESTONE:0)
Block(5,9,-1,WOOD_STEP:1)
Block(5,10,-6,IRON_FENCE:0)
Block(5,10,-4,HAY_BLOCK:0)
Block(5,10,-3,WOOD:5)
Block(5,11,-6,IRON_FENCE:0)
Block(5,11,-3,WOOD:5)
Block(5,12,-6,IRON_FENCE:0)
Block(5,12,-5,LOG:5)
Block(5,12,-3,WOOD:5)
Block(5,13,-6,IRON_FENCE:0)
Block(5,13,-5,WOOD:0)
Block(5,13,-4,WOOD:0)
Block(5,13,-3,WOOD_DOUBLE_STEP:1)
Block(5,13,-2,WOOD_STEP:1)
Block(5,14,-6,IRON_FENCE:0)
Block(5,14,-5,WOOD:0)
Block(5,14,-4,SPRUCE_WOOD_STAIRS:3)
Block(5,15,-6,IRON_FENCE:0)
Block(5,15,-5,WOOD:5)
Block(5,16,-6,IRON_FENCE:0)
Block(5,16,-5,WOOD:5)
Block(5,17,-6,IRON_FENCE:0)
Block(5,17,-5,WOOD:5)
Block(5,18,-6,IRON_FENCE:0)
Block(5,18,-5,LOG:5)
Block(5,19,-6,IRON_FENCE:0)
Block(5,19,-5,WOOD:5)
Block(5,20,-6,IRON_FENCE:0)
Block(5,20,-5,WOOD:5)
Block(5,21,-6,IRON_FENCE:0)
Block(5,21,-5,WOOD:5)
Block(5,22,-6,IRON_FENCE:0)
Block(5,22,-5,WOOD:5)
Block(5,23,-6,IRON_FENCE:0)
Block(5,23,-5,WOOD:5)
Block(5,24,-6,IRON_FENCE:0)
Block(5,24,-5,WOOD:5)
Block(5,25,-6,IRON_FENCE:0)
Block(5,25,-5,WOOD:5)
Block(5,25,-4,SPRUCE_WOOD_STAIRS:7)
Block(5,26,-7,LOG:5)
Block(5,26,-6,IRON_FENCE:0)
Block(5,26,-5,LOG:5)
Block(5,26,-4,WOOD:5)
Block(5,27,-7,IRON_FENCE:0)
Block(5,27,-6,IRON_FENCE:0)
Block(5,27,-5,WOOD:5)
Block(5,27,-4,WOOD:5)
Block(5,28,-5,SPRUCE_WOOD_STAIRS:1)
Block(5,28,-4,SPRUCE_WOOD_STAIRS:1)
Block(5,29,-7,TRAP_DOOR:10)
Block(5,29,-6,WOOD:1)
Block(5,30,-7,WOOD:1)
Block(5,30,-6,SPRUCE_WOOD_STAIRS:3)
Block(5,31,-7,WOOD_STEP:5)
Block(6,0,-7,DIRT:0)
Block(6,0,-6,DIRT:0)
Block(6,0,-5,DIRT:0)
Block(6,0,-4,DIRT:0)
Block(6,0,-3,DIRT:0)
Block(6,0,-2,DIRT:0)
Block(6,0,-1,DIRT:0)
Block(6,0,0,DIRT:0)
Block(6,0,1,DIRT:0)
Block(6,0,2,DIRT:0)
Block(6,0,3,DIRT:0)
Block(6,0,4,DIRT:0)
Block(6,0,5,DIRT:0)
Block(6,0,6,DIRT:0)
Block(6,0,7,DIRT:0)
Block(6,0,8,DIRT:0)
Block(6,1,-7,DIRT:0)
Block(6,1,-6,DIRT:0)
Block(6,1,-5,DIRT:0)
Block(6,1,-4,DIRT:0)
Block(6,1,-3,DIRT:0)
Block(6,1,-2,DIRT:0)
Block(6,1,-1,DIRT:0)
Block(6,1,0,DIRT:0)
Block(6,1,1,DIRT:0)
Block(6,1,2,DIRT:0)
Block(6,1,3,DIRT:0)
Block(6,1,4,DIRT:0)
Block(6,1,5,DIRT:0)
Block(6,1,6,DIRT:0)
Block(6,1,7,DIRT:0)
Block(6,1,8,DIRT:0)
Block(6,2,-7,DIRT:0)
Block(6,2,-6,DIRT:0)
Block(6,2,-5,DIRT:0)
Block(6,2,-4,DIRT:0)
Block(6,2,-3,DIRT:0)
Block(6,2,-2,DIRT:0)
Block(6,2,-1,DIRT:0)
Block(6,2,0,DIRT:0)
Block(6,2,1,DIRT:0)
Block(6,2,2,DIRT:0)
Block(6,2,3,DIRT:0)
Block(6,2,4,DIRT:0)
Block(6,2,5,DIRT:0)
Block(6,2,6,DIRT:0)
Block(6,2,7,DIRT:0)
Block(6,2,8,DIRT:0)
Block(6,3,-7,DIRT:0)
Block(6,3,-6,DIRT:0)
Block(6,3,-5,DIRT:0)
Block(6,3,-4,DIRT:0)
Block(6,3,-3,DIRT:0)
Block(6,3,-2,DIRT:0)
Block(6,3,-1,DIRT:0)
Block(6,3,0,DIRT:0)
Block(6,3,1,DIRT:0)
Block(6,3,2,DIRT:0)
Block(6,3,3,DIRT:0)
Block(6,3,4,DIRT:0)
Block(6,3,5,DIRT:0)
Block(6,3,6,DIRT:0)
Block(6,3,7,DIRT:0)
Block(6,3,8,DIRT:0)
Block(6,4,-7,DIRT:0)
Block(6,4,-6,DIRT:0)
Block(6,4,-5,DIRT:0)
Block(6,4,-4,DIRT:0)
Block(6,4,-3,DIRT:0)
Block(6,4,-2,DIRT:0)
Block(6,4,-1,DIRT:0)
Block(6,4,0,DIRT:0)
Block(6,4,1,DIRT:0)
Block(6,4,2,DIRT:0)
Block(6,4,3,DIRT:0)
Block(6,4,4,GRASS:0)
Block(6,4,5,GRASS:0)
Block(6,4,6,DIRT:0)
Block(6,4,7,GRASS:0)
Block(6,4,8,GRASS:0)
Block(6,5,-7,COBBLESTONE:0)
Block(6,5,-6,COBBLESTONE:0)
Block(6,5,-5,COBBLESTONE:0)
Block(6,5,-4,DIRT:0)
Block(6,5,-3,DIRT:0)
Block(6,5,-2,DIRT:0)
Block(6,5,-1,DIRT:0)
Block(6,5,0,GRASS:0)
Block(6,5,1,DIRT:0)
Block(6,5,2,GRASS:0)
Block(6,5,3,GRASS:0)
Block(6,5,4,SOIL:0)
Block(6,5,5,SOIL:0)
Block(6,5,6,GRASS:0)
Block(6,6,-7,LOG:5)
Block(6,6,-6,COBBLESTONE:0)
Block(6,6,-5,COBBLESTONE:0)
Block(6,6,-4,COBBLESTONE:0)
Block(6,6,-3,STONE:0)
Block(6,6,-2,COBBLESTONE:0)
Block(6,6,-1,HAY_BLOCK:4)
Block(6,6,1,HAY_BLOCK:0)
Block(6,6,3,DARK_OAK_FENCE:0)
Block(6,6,4,CROPS:7)
Block(6,6,5,CROPS:7)
Block(6,6,6,DARK_OAK_FENCE:0)
Block(6,7,-5,HAY_BLOCK:8)
Block(6,7,-4,HAY_BLOCK:8)
Block(6,7,-3,LOG:1)
Block(6,7,-2,COBBLESTONE:0)
Block(6,7,-1,HAY_BLOCK:0)
Block(6,7,1,HAY_BLOCK:0)
Block(6,7,2,WOOD_STEP:9)
Block(6,7,3,WOOD_STEP:1)
Block(6,8,-3,LOG:1)
Block(6,8,-2,COBBLESTONE:0)
Block(6,8,0,WOOD_STEP:9)
Block(6,8,1,WOOD_STEP:1)
Block(6,9,-7,DARK_OAK_STAIRS:4)
Block(6,9,-6,WOOD_STEP:13)
Block(6,9,-5,WOOD_STEP:13)
Block(6,9,-4,DARK_OAK_STAIRS:6)
Block(6,9,-3,LOG:1)
Block(6,9,-2,SMOOTH_STAIRS:3)
Block(6,9,-1,WOOD_STEP:1)
Block(6,10,-4,HAY_BLOCK:0)
Block(6,10,-3,LOG:1)
Block(6,11,-3,LOG:1)
Block(6,12,-7,LOG:9)
Block(6,12,-6,LOG:9)
Block(6,12,-5,LOG:9)
Block(6,12,-4,LOG:9)
Block(6,12,-3,LOG:9)
Block(6,12,-2,LOG:9)
Block(6,13,-7,WOOD:0)
Block(6,13,-6,WOOD:0)
Block(6,13,-5,LOG:1)
Block(6,13,-4,WOOD:0)
Block(6,13,-3,WOOD_DOUBLE_STEP:1)
Block(6,13,-2,WOOD_STEP:1)
Block(6,14,-7,WOOD:0)
Block(6,14,-6,WOOD:0)
Block(6,14,-5,LOG:1)
Block(6,14,-4,SPRUCE_WOOD_STAIRS:1)
Block(6,15,-7,WOOD_STEP:1)
Block(6,15,-6,WOOD:5)
Block(6,15,-5,LOG:1)
Block(6,16,-7,SPRUCE_WOOD_STAIRS:5)
Block(6,16,-6,WOOD:5)
Block(6,16,-5,LOG:1)
Block(6,17,-7,WOOD:0)
Block(6,17,-6,WOOD:5)
Block(6,17,-5,LOG:1)
Block(6,18,-7,LOG:9)
Block(6,18,-6,LOG:9)
Block(6,18,-5,LOG:1)
Block(6,18,-4,LOG:9)
Block(6,19,-7,WOOD:0)
Block(6,19,-6,WOOD:5)
Block(6,19,-5,LOG:1)
Block(6,20,-7,WOOD:0)
Block(6,20,-6,WOOD:5)
Block(6,20,-5,LOG:1)
Block(6,21,-7,WOOD:0)
Block(6,21,-6,WOOD:5)
Block(6,21,-5,LOG:1)
Block(6,22,-7,WOOD:0)
Block(6,22,-6,WOOD:5)
Block(6,22,-5,LOG:1)
Block(6,23,-7,WOOD:0)
Block(6,23,-6,WOOD:5)
Block(6,23,-5,LOG:1)
Block(6,24,-7,WOOD:0)
Block(6,24,-6,WOOD:5)
Block(6,24,-5,LOG:1)
Block(6,25,-7,WOOD:0)
Block(6,25,-6,WOOD:0)
Block(6,25,-5,LOG:1)
Block(6,25,-4,SPRUCE_WOOD_STAIRS:7)
Block(6,26,-7,LOG:5)
Block(6,26,-6,LOG:9)
Block(6,26,-5,LOG:1)
Block(6,26,-4,LOG:9)
Block(6,27,-7,WOOD:0)
Block(6,27,-6,WOOD:0)
Block(6,27,-5,WOOD:1)
Block(6,28,-7,WOOD:0)
Block(6,28,-6,WOOD:0)
Block(6,28,-5,SPRUCE_WOOD_STAIRS:3)
Block(6,29,-7,WOOD:0)
Block(6,29,-6,WOOD:1)
Block(6,30,-7,WOOD:1)
Block(6,30,-6,SPRUCE_WOOD_STAIRS:3)
Block(6,31,-7,WOOD_STEP:5)
Block(7,0,-7,DIRT:0)
Block(7,0,-6,DIRT:0)
Block(7,0,-5,DIRT:0)
Block(7,0,-4,DIRT:0)
Block(7,0,-3,DIRT:0)
Block(7,0,-2,DIRT:0)
Block(7,0,-1,DIRT:0)
Block(7,0,0,DIRT:0)
Block(7,0,1,DIRT:0)
Block(7,0,2,DIRT:0)
Block(7,0,3,DIRT:0)
Block(7,0,4,DIRT:0)
Block(7,0,5,DIRT:0)
Block(7,0,6,DIRT:0)
Block(7,0,7,DIRT:0)
Block(7,0,8,DIRT:0)
Block(7,1,-7,DIRT:0)
Block(7,1,-6,DIRT:0)
Block(7,1,-5,DIRT:0)
Block(7,1,-4,DIRT:0)
Block(7,1,-3,DIRT:0)
Block(7,1,-2,DIRT:0)
Block(7,1,-1,DIRT:0)
Block(7,1,0,DIRT:0)
Block(7,1,1,DIRT:0)
Block(7,1,2,DIRT:0)
Block(7,1,3,DIRT:0)
Block(7,1,4,DIRT:0)
Block(7,1,5,DIRT:0)
Block(7,1,6,DIRT:0)
Block(7,1,7,DIRT:0)
Block(7,1,8,DIRT:0)
Block(7,2,-7,DIRT:0)
Block(7,2,-6,DIRT:0)
Block(7,2,-5,DIRT:0)
Block(7,2,-4,DIRT:0)
Block(7,2,-3,DIRT:0)
Block(7,2,-2,DIRT:0)
Block(7,2,-1,DIRT:0)
Block(7,2,0,DIRT:0)
Block(7,2,1,DIRT:0)
Block(7,2,2,DIRT:0)
Block(7,2,3,DIRT:0)
Block(7,2,4,DIRT:0)
Block(7,2,5,DIRT:0)
Block(7,2,6,DIRT:0)
Block(7,2,7,DIRT:0)
Block(7,2,8,DIRT:0)
Block(7,3,-7,DIRT:0)
Block(7,3,-6,DIRT:0)
Block(7,3,-5,DIRT:0)
Block(7,3,-4,DIRT:0)
Block(7,3,-3,DIRT:0)
Block(7,3,-2,DIRT:0)
Block(7,3,-1,DIRT:0)
Block(7,3,0,DIRT:0)
Block(7,3,1,DIRT:0)
Block(7,3,2,DIRT:0)
Block(7,3,3,DIRT:0)
Block(7,3,4,DIRT:0)
Block(7,3,5,DIRT:0)
Block(7,3,6,DIRT:0)
Block(7,3,7,DIRT:0)
Block(7,3,8,GRASS:0)
Block(7,4,-7,DIRT:0)
Block(7,4,-6,DIRT:0)
Block(7,4,-5,DIRT:0)
Block(7,4,-4,DIRT:0)
Block(7,4,-3,DIRT:0)
Block(7,4,-2,DIRT:0)
Block(7,4,-1,DIRT:0)
Block(7,4,0,DIRT:0)
Block(7,4,1,DIRT:0)
Block(7,4,2,DIRT:0)
Block(7,4,3,DIRT:0)
Block(7,4,4,GRASS:0)
Block(7,4,5,DIRT:0)
Block(7,4,6,DIRT:0)
Block(7,4,7,GRASS:0)
Block(7,5,-7,DIRT:0)
Block(7,5,-6,DIRT:0)
Block(7,5,-5,DIRT:0)
Block(7,5,-4,DIRT:0)
Block(7,5,-3,DIRT:0)
Block(7,5,-2,DIRT:0)
Block(7,5,-1,GRASS:0)
Block(7,5,0,GRASS:0)
Block(7,5,1,DIRT:0)
Block(7,5,2,GRASS:0)
Block(7,5,3,DIRT:0)
Block(7,5,4,SOIL:0)
Block(7,5,5,DIRT:0)
Block(7,5,6,GRASS:0)
Block(7,6,-7,LOG:5)
Block(7,6,-6,COBBLESTONE:0)
Block(7,6,-5,COBBLESTONE:0)
Block(7,6,-4,STONE:0)
Block(7,6,-3,COBBLESTONE:0)
Block(7,6,-2,LOG:1)
Block(7,6,1,LOG:1)
Block(7,6,3,LOG:1)
Block(7,6,4,CROPS:7)
Block(7,6,5,HAY_BLOCK:0)
Block(7,6,6,DARK_OAK_FENCE:0)
Block(7,7,-7,LOG:1)
Block(7,7,-6,HAY_BLOCK:8)
Block(7,7,-5,HAY_BLOCK:0)
Block(7,7,-4,COBBLESTONE:0)
Block(7,7,-3,COBBLESTONE:0)
Block(7,7,-2,LOG:1)
Block(7,7,1,LOG:1)
Block(7,7,2,WOOD_STEP:9)
Block(7,7,3,WOOD_STEP:1)
Block(7,8,-7,LOG:1)
Block(7,8,-5,HAY_BLOCK:8)
Block(7,8,-4,COBBLESTONE:0)
Block(7,8,-3,COBBLESTONE:0)
Block(7,8,-2,LOG:1)
Block(7,8,0,WOOD_STEP:9)
Block(7,8,1,WOOD_STEP:1)
Block(7,9,-7,LOG:1)
Block(7,9,-4,COBBLESTONE:0)
Block(7,9,-3,SMOOTH_STAIRS:3)
Block(7,9,-2,DARK_OAK_STAIRS:1)
Block(7,9,-1,WOOD_STEP:1)
Block(7,10,-7,LOG:1)
Block(7,10,-4,WOOD:0)
Block(7,11,-7,LOG:1)
Block(7,11,-4,WOOD:0)
Block(7,12,-7,LOG:1)
Block(7,12,-5,LOG:5)
Block(7,12,-4,WOOD:0)
Block(7,13,-7,WOOD:0)
Block(7,13,-6,WOOD:0)
Block(7,13,-5,WOOD:0)
Block(7,13,-4,WOOD_DOUBLE_STEP:1)
Block(7,13,-3,WOOD_STEP:1)
Block(7,14,-7,SPRUCE_WOOD_STAIRS:1)
Block(7,14,-6,SPRUCE_WOOD_STAIRS:1)
Block(7,14,-5,SPRUCE_WOOD_STAIRS:3)
Block(7,18,-5,LOG:5)
Block(7,25,-7,COBBLESTONE_STAIRS:5)
Block(7,25,-6,COBBLESTONE_STAIRS:5)
Block(7,25,-5,DARK_OAK_STAIRS:6)
Block(7,25,-4,DARK_OAK_STAIRS:7)
Block(7,26,-7,LOG:5)
Block(7,26,-6,COBBLESTONE:0)
Block(7,26,-5,LOG:5)
Block(7,26,-4,DARK_OAK_STAIRS:3)
Block(7,27,-7,COBBLESTONE_STAIRS:1)
Block(7,27,-6,COBBLESTONE_STAIRS:1)
Block(7,27,-5,WOOD:5)
Block(7,28,-6,SPRUCE_WOOD_STAIRS:6)
Block(7,28,-5,DARK_OAK_STAIRS:3)
Block(7,29,-7,DARK_OAK_STAIRS:5)
Block(7,29,-6,WOOD:5)
Block(7,30,-7,WOOD:1)
Block(7,30,-6,DARK_OAK_STAIRS:3)
Block(7,31,-7,WOOD_STEP:5)
