Author: NLBlackEagle
Description: No description given
SettingsMode: WriteDisable
Frequency: 0
SpawnHeight: randomY
UseCenterForHighestBlock: true
MinHeight: 0
MaxHeight: 255
InheritBO3: 
InheritBO3Rotation: NORTH
OverrideChildSettings: true
OverrideParentHeight: false
CanOverride: false
BranchFrequency: 0
BranchFrequencyGroup: 
MustBeBelowOther: false
MustBeInside: 
CannotBeInside: 
ReplacesBO3: 
MustBeInsideWorldBorders: false
CanSpawnOnWater: true
SpawnOnWaterOnly: false
SpawnUnderWater: false
SpawnAtWaterLevel: false
HeightOffset: 0
RemoveAir: true
ReplaceAbove: 
ReplaceBelow: 
ReplaceWithBiomeBlocks: true
ReplaceWithSurfaceBlock: GRASS
ReplaceWithGroundBlock: DIRT
ReplaceWithStoneBlock: STONE
SmoothRadius: 0
SmoothHeightOffset: 0
SmoothStartTop: false
SmoothStartWood: false
SmoothingSurfaceBlock: 
SmoothingGroundBlock: 
BO3Group: 
IsSpawnPoint: false
DoReplaceBlocks: true
Block(-8,0,-4,GRASS:0)
Block(-8,0,-3,GRASS:0)
Block(-8,0,-2,DIRT:0)
Block(-8,0,-1,DIRT:0)
Block(-8,0,0,DIRT:0)
Block(-8,0,1,DIRT:0)
Block(-8,0,2,DIRT:0)
Block(-8,0,3,DIRT:0)
Block(-8,0,4,DIRT:0)
Block(-8,0,5,DIRT:0)
Block(-8,0,6,DIRT:0)
Block(-8,0,7,DIRT:0)
Block(-8,0,8,DIRT:0)
Block(-8,1,-2,GRASS:0)
Block(-8,1,-1,GRASS:0)
Block(-8,1,0,DIRT:0)
Block(-8,1,1,DIRT:0)
Block(-8,1,2,DIRT:0)
Block(-8,1,3,DIRT:0)
Block(-8,1,4,DIRT:0)
Block(-8,1,5,DIRT:0)
Block(-8,1,6,DIRT:0)
Block(-8,1,7,DIRT:0)
Block(-8,1,8,DIRT:0)
Block(-8,2,0,GRASS:0)
Block(-8,2,1,GRASS:0)
Block(-8,2,2,GRASS:0)
Block(-8,2,3,GRASS:0)
Block(-8,2,4,GRASS:0)
Block(-8,2,5,GRASS:0)
Block(-8,2,6,DIRT:0)
Block(-8,2,7,DIRT:0)
Block(-8,2,8,DIRT:0)
Block(-8,3,6,GRASS:0)
Block(-8,3,7,GRASS:0)
Block(-8,3,8,GRASS:0)
Block(-7,0,-5,GRASS:0)
Block(-7,0,-4,DIRT:0)
Block(-7,0,-3,DIRT:0)
Block(-7,0,-2,DIRT:0)
Block(-7,0,-1,DIRT:0)
Block(-7,0,0,DIRT:0)
Block(-7,0,1,DIRT:0)
Block(-7,0,2,DIRT:0)
Block(-7,0,3,DIRT:0)
Block(-7,0,4,DIRT:0)
Block(-7,0,5,DIRT:0)
Block(-7,0,6,DIRT:0)
Block(-7,0,7,DIRT:0)
Block(-7,0,8,DIRT:0)
Block(-7,1,-4,GRASS:0)
Block(-7,1,-3,GRASS:0)
Block(-7,1,-2,GRASS:0)
Block(-7,1,-1,DIRT:0)
Block(-7,1,0,DIRT:0)
Block(-7,1,1,DIRT:0)
Block(-7,1,2,DIRT:0)
Block(-7,1,3,DIRT:0)
Block(-7,1,4,DIRT:0)
Block(-7,1,5,DIRT:0)
Block(-7,1,6,DIRT:0)
Block(-7,1,7,DIRT:0)
Block(-7,1,8,DIRT:0)
Block(-7,2,-1,GRASS:0)
Block(-7,2,0,GRASS:0)
Block(-7,2,1,GRASS:0)
Block(-7,2,2,GRASS:0)
Block(-7,2,3,DIRT:0)
Block(-7,2,4,DIRT:0)
Block(-7,2,5,DIRT:0)
Block(-7,2,6,DIRT:0)
Block(-7,2,7,DIRT:0)
Block(-7,2,8,DIRT:0)
Block(-7,3,3,GRASS:0)
Block(-7,3,4,GRASS:0)
Block(-7,3,5,GRASS:0)
Block(-7,3,6,GRASS:0)
Block(-7,3,7,DIRT:0)
Block(-7,3,8,DIRT:0)
Block(-7,4,7,GRASS:0)
Block(-7,4,8,GRASS:0)
Block(-6,0,-6,GRASS:0)
Block(-6,0,-5,DIRT:0)
Block(-6,0,-4,DIRT:0)
Block(-6,0,-3,DIRT:0)
Block(-6,0,-2,DIRT:0)
Block(-6,0,-1,DIRT:0)
Block(-6,0,0,DIRT:0)
Block(-6,0,1,DIRT:0)
Block(-6,0,2,DIRT:0)
Block(-6,0,3,DIRT:0)
Block(-6,0,4,DIRT:0)
Block(-6,0,5,DIRT:0)
Block(-6,0,6,DIRT:0)
Block(-6,0,7,DIRT:0)
Block(-6,0,8,DIRT:0)
Block(-6,1,-5,GRASS:0)
Block(-6,1,-4,GRASS:0)
Block(-6,1,-3,DIRT:0)
Block(-6,1,-2,DIRT:0)
Block(-6,1,-1,DIRT:0)
Block(-6,1,0,DIRT:0)
Block(-6,1,1,DIRT:0)
Block(-6,1,2,DIRT:0)
Block(-6,1,3,DIRT:0)
Block(-6,1,4,DIRT:0)
Block(-6,1,5,DIRT:0)
Block(-6,1,6,DIRT:0)
Block(-6,1,7,DIRT:0)
Block(-6,1,8,DIRT:0)
Block(-6,2,-3,GRASS:0)
Block(-6,2,-2,GRASS:0)
Block(-6,2,-1,GRASS:0)
Block(-6,2,0,DIRT:0)
Block(-6,2,1,DIRT:0)
Block(-6,2,2,DIRT:0)
Block(-6,2,3,DIRT:0)
Block(-6,2,4,DIRT:0)
Block(-6,2,5,DIRT:0)
Block(-6,2,6,DIRT:0)
Block(-6,2,7,DIRT:0)
Block(-6,2,8,DIRT:0)
Block(-6,3,0,GRASS:0)
Block(-6,3,1,GRASS:0)
Block(-6,3,2,GRASS:0)
Block(-6,3,3,GRASS:0)
Block(-6,3,4,DIRT:0)
Block(-6,3,5,DIRT:0)
Block(-6,3,6,DIRT:0)
Block(-6,3,7,DIRT:0)
Block(-6,3,8,DIRT:0)
Block(-6,4,4,GRASS:0)
Block(-6,4,5,GRASS:0)
Block(-6,4,6,GRASS:0)
Block(-6,4,7,GRASS:0)
Block(-6,4,8,GRASS:0)
Block(-5,0,-7,GRASS:0)
Block(-5,0,-6,GRASS:0)
Block(-5,0,-5,DIRT:0)
Block(-5,0,-4,DIRT:0)
Block(-5,0,-3,DIRT:0)
Block(-5,0,-2,DIRT:0)
Block(-5,0,-1,DIRT:0)
Block(-5,0,0,DIRT:0)
Block(-5,0,1,DIRT:0)
Block(-5,0,2,DIRT:0)
Block(-5,0,3,DIRT:0)
Block(-5,0,4,DIRT:0)
Block(-5,0,5,DIRT:0)
Block(-5,0,6,DIRT:0)
Block(-5,0,7,DIRT:0)
Block(-5,0,8,DIRT:0)
Block(-5,1,-5,GRASS:0)
Block(-5,1,-4,DIRT:0)
Block(-5,1,-3,DIRT:0)
Block(-5,1,-2,DIRT:0)
Block(-5,1,-1,DIRT:0)
Block(-5,1,0,DIRT:0)
Block(-5,1,1,DIRT:0)
Block(-5,1,2,DIRT:0)
Block(-5,1,3,DIRT:0)
Block(-5,1,4,DIRT:0)
Block(-5,1,5,DIRT:0)
Block(-5,1,6,DIRT:0)
Block(-5,1,7,DIRT:0)
Block(-5,1,8,DIRT:0)
Block(-5,2,-4,GRASS:0)
Block(-5,2,-3,GRASS:0)
Block(-5,2,-2,GRASS:0)
Block(-5,2,-1,DIRT:0)
Block(-5,2,0,DIRT:0)
Block(-5,2,1,DIRT:0)
Block(-5,2,2,DIRT:0)
Block(-5,2,3,DIRT:0)
Block(-5,2,4,DIRT:0)
Block(-5,2,5,DIRT:0)
Block(-5,2,6,DIRT:0)
Block(-5,2,7,DIRT:0)
Block(-5,2,8,DIRT:0)
Block(-5,3,-1,GRASS:0)
Block(-5,3,0,GRASS:0)
Block(-5,3,1,GRASS:0)
Block(-5,3,2,DIRT:0)
Block(-5,3,3,DIRT:0)
Block(-5,3,4,DIRT:0)
Block(-5,3,5,DIRT:0)
Block(-5,3,6,DIRT:0)
Block(-5,3,7,DIRT:0)
Block(-5,3,8,DIRT:0)
Block(-5,4,2,GRASS:0)
Block(-5,4,3,GRASS:0)
Block(-5,4,4,GRASS:0)
Block(-5,4,5,GRASS:0)
Block(-5,4,6,GRASS:0)
Block(-5,4,7,GRASS:0)
Block(-5,4,8,DIRT:0)
Block(-5,5,8,GRASS:0)
Block(-5,6,8,DARK_OAK_FENCE:0)
Block(-4,0,-7,DIRT:0)
Block(-4,0,-6,DIRT:0)
Block(-4,0,-5,DIRT:0)
Block(-4,0,-4,DIRT:0)
Block(-4,0,-3,DIRT:0)
Block(-4,0,-2,DIRT:0)
Block(-4,0,-1,DIRT:0)
Block(-4,0,0,DIRT:0)
Block(-4,0,1,DIRT:0)
Block(-4,0,2,DIRT:0)
Block(-4,0,3,DIRT:0)
Block(-4,0,4,DIRT:0)
Block(-4,0,5,DIRT:0)
Block(-4,0,6,DIRT:0)
Block(-4,0,7,DIRT:0)
Block(-4,0,8,DIRT:0)
Block(-4,1,-7,GRASS:0)
Block(-4,1,-6,GRASS:0)
Block(-4,1,-5,DIRT:0)
Block(-4,1,-4,DIRT:0)
Block(-4,1,-3,DIRT:0)
Block(-4,1,-2,DIRT:0)
Block(-4,1,-1,DIRT:0)
Block(-4,1,0,DIRT:0)
Block(-4,1,1,DIRT:0)
Block(-4,1,2,DIRT:0)
Block(-4,1,3,DIRT:0)
Block(-4,1,4,DIRT:0)
Block(-4,1,5,DIRT:0)
Block(-4,1,6,DIRT:0)
Block(-4,1,7,DIRT:0)
Block(-4,1,8,DIRT:0)
Block(-4,2,-5,GRASS:0)
Block(-4,2,-4,GRASS:0)
Block(-4,2,-3,DIRT:0)
Block(-4,2,-2,DIRT:0)
Block(-4,2,-1,DIRT:0)
Block(-4,2,0,DIRT:0)
Block(-4,2,1,DIRT:0)
Block(-4,2,2,DIRT:0)
Block(-4,2,3,DIRT:0)
Block(-4,2,4,DIRT:0)
Block(-4,2,5,DIRT:0)
Block(-4,2,6,DIRT:0)
Block(-4,2,7,DIRT:0)
Block(-4,2,8,DIRT:0)
Block(-4,3,-3,GRASS:0)
Block(-4,3,-2,GRASS:0)
Block(-4,3,-1,DIRT:0)
Block(-4,3,0,DIRT:0)
Block(-4,3,1,DIRT:0)
Block(-4,3,2,DIRT:0)
Block(-4,3,3,DIRT:0)
Block(-4,3,4,DIRT:0)
Block(-4,3,5,DIRT:0)
Block(-4,3,6,DIRT:0)
Block(-4,3,7,DIRT:0)
Block(-4,3,8,DIRT:0)
Block(-4,4,-1,GRASS:0)
Block(-4,4,0,GRASS:0)
Block(-4,4,1,GRASS:0)
Block(-4,4,2,GRASS:0)
Block(-4,4,3,GRASS:0)
Block(-4,4,4,GRASS:0)
Block(-4,4,5,GRASS:0)
Block(-4,4,6,GRASS:0)
Block(-4,4,7,GRASS:0)
Block(-4,4,8,GRASS:0)
Block(-4,5,5,SOIL:0)
Block(-4,5,6,SOIL:0)
Block(-4,5,7,SOIL:0)
Block(-4,5,8,SOIL:0)
Block(-4,6,5,CROPS:7)
Block(-4,6,6,CROPS:7)
Block(-4,6,7,CROPS:7)
Block(-4,6,8,CROPS:7)
Block(-3,0,-7,DIRT:0)
Block(-3,0,-6,DIRT:0)
Block(-3,0,-5,DIRT:0)
Block(-3,0,-4,DIRT:0)
Block(-3,0,-3,DIRT:0)
Block(-3,0,-2,DIRT:0)
Block(-3,0,-1,DIRT:0)
Block(-3,0,0,DIRT:0)
Block(-3,0,1,DIRT:0)
Block(-3,0,2,DIRT:0)
Block(-3,0,3,DIRT:0)
Block(-3,0,4,DIRT:0)
Block(-3,0,5,DIRT:0)
Block(-3,0,6,DIRT:0)
Block(-3,0,7,DIRT:0)
Block(-3,0,8,DIRT:0)
Block(-3,1,-7,GRASS:0)
Block(-3,1,-6,DIRT:0)
Block(-3,1,-5,DIRT:0)
Block(-3,1,-4,DIRT:0)
Block(-3,1,-3,DIRT:0)
Block(-3,1,-2,DIRT:0)
Block(-3,1,-1,DIRT:0)
Block(-3,1,0,DIRT:0)
Block(-3,1,1,DIRT:0)
Block(-3,1,2,DIRT:0)
Block(-3,1,3,DIRT:0)
Block(-3,1,4,DIRT:0)
Block(-3,1,5,DIRT:0)
Block(-3,1,6,DIRT:0)
Block(-3,1,7,DIRT:0)
Block(-3,1,8,DIRT:0)
Block(-3,2,-6,GRASS:0)
Block(-3,2,-5,GRASS:0)
Block(-3,2,-4,DIRT:0)
Block(-3,2,-3,DIRT:0)
Block(-3,2,-2,DIRT:0)
Block(-3,2,-1,DIRT:0)
Block(-3,2,0,DIRT:0)
Block(-3,2,1,DIRT:0)
Block(-3,2,2,DIRT:0)
Block(-3,2,3,DIRT:0)
Block(-3,2,4,DIRT:0)
Block(-3,2,5,DIRT:0)
Block(-3,2,6,DIRT:0)
Block(-3,2,7,DIRT:0)
Block(-3,2,8,DIRT:0)
Block(-3,3,-4,GRASS:0)
Block(-3,3,-3,GRASS:0)
Block(-3,3,-2,DIRT:0)
Block(-3,3,-1,DIRT:0)
Block(-3,3,0,DIRT:0)
Block(-3,3,1,DIRT:0)
Block(-3,3,2,DIRT:0)
Block(-3,3,3,DIRT:0)
Block(-3,3,4,DIRT:0)
Block(-3,3,5,DIRT:0)
Block(-3,3,6,DIRT:0)
Block(-3,3,7,DIRT:0)
Block(-3,3,8,DIRT:0)
Block(-3,4,-2,GRASS:0)
Block(-3,4,-1,GRASS:0)
Block(-3,4,0,GRASS:0)
Block(-3,4,1,GRASS:0)
Block(-3,4,2,GRASS:0)
Block(-3,4,3,GRASS:0)
Block(-3,4,4,GRASS:0)
Block(-3,4,5,GRASS:0)
Block(-3,4,6,GRASS:0)
Block(-3,4,7,GRASS:0)
Block(-3,4,8,GRASS:0)
Block(-3,5,0,SOIL:0)
Block(-3,5,1,SOIL:0)
Block(-3,5,2,SOIL:0)
Block(-3,5,3,SOIL:0)
Block(-3,5,4,SOIL:0)
Block(-3,5,5,SOIL:0)
Block(-3,5,6,SOIL:0)
Block(-3,5,7,SOIL:0)
Block(-3,5,8,SOIL:0)
Block(-3,6,0,CROPS:7)
Block(-3,6,1,CROPS:7)
Block(-3,6,2,CROPS:7)
Block(-3,6,3,CROPS:7)
Block(-3,6,4,CROPS:7)
Block(-3,6,5,CROPS:7)
Block(-3,6,6,CROPS:7)
Block(-3,6,7,CROPS:7)
Block(-3,6,8,CROPS:7)
Block(-2,0,-7,DIRT:0)
Block(-2,0,-6,DIRT:0)
Block(-2,0,-5,DIRT:0)
Block(-2,0,-4,DIRT:0)
Block(-2,0,-3,DIRT:0)
Block(-2,0,-2,DIRT:0)
Block(-2,0,-1,DIRT:0)
Block(-2,0,0,DIRT:0)
Block(-2,0,1,DIRT:0)
Block(-2,0,2,DIRT:0)
Block(-2,0,3,DIRT:0)
Block(-2,0,4,DIRT:0)
Block(-2,0,5,DIRT:0)
Block(-2,0,6,DIRT:0)
Block(-2,0,7,DIRT:0)
Block(-2,0,8,DIRT:0)
Block(-2,1,-7,GRASS:0)
Block(-2,1,-6,DIRT:0)
Block(-2,1,-5,DIRT:0)
Block(-2,1,-4,DIRT:0)
Block(-2,1,-3,DIRT:0)
Block(-2,1,-2,DIRT:0)
Block(-2,1,-1,DIRT:0)
Block(-2,1,0,DIRT:0)
Block(-2,1,1,DIRT:0)
Block(-2,1,2,DIRT:0)
Block(-2,1,3,DIRT:0)
Block(-2,1,4,DIRT:0)
Block(-2,1,5,DIRT:0)
Block(-2,1,6,DIRT:0)
Block(-2,1,7,DIRT:0)
Block(-2,1,8,DIRT:0)
Block(-2,2,-6,GRASS:0)
Block(-2,2,-5,GRASS:0)
Block(-2,2,-4,DIRT:0)
Block(-2,2,-3,DIRT:0)
Block(-2,2,-2,DIRT:0)
Block(-2,2,-1,DIRT:0)
Block(-2,2,0,DIRT:0)
Block(-2,2,1,DIRT:0)
Block(-2,2,2,DIRT:0)
Block(-2,2,3,DIRT:0)
Block(-2,2,4,DIRT:0)
Block(-2,2,5,DIRT:0)
Block(-2,2,6,DIRT:0)
Block(-2,2,7,DIRT:0)
Block(-2,2,8,DIRT:0)
Block(-2,3,-4,GRASS:0)
Block(-2,3,-3,DIRT:0)
Block(-2,3,-2,DIRT:0)
Block(-2,3,-1,DIRT:0)
Block(-2,3,0,DIRT:0)
Block(-2,3,1,DIRT:0)
Block(-2,3,2,DIRT:0)
Block(-2,3,3,DIRT:0)
Block(-2,3,4,DIRT:0)
Block(-2,3,5,DIRT:0)
Block(-2,3,6,DIRT:0)
Block(-2,3,7,DIRT:0)
Block(-2,3,8,DIRT:0)
Block(-2,4,-3,GRASS:0)
Block(-2,4,-2,GRASS:0)
Block(-2,4,-1,GRASS:0)
Block(-2,4,0,GRASS:0)
Block(-2,4,1,GRASS:0)
Block(-2,4,2,GRASS:0)
Block(-2,4,3,GRASS:0)
Block(-2,4,4,DIRT:0)
Block(-2,4,5,DIRT:0)
Block(-2,4,6,DIRT:0)
Block(-2,4,7,DIRT:0)
Block(-2,4,8,DIRT:0)
Block(-2,5,0,SOIL:0)
Block(-2,5,1,SOIL:0)
Block(-2,5,2,SOIL:0)
Block(-2,5,3,SOIL:0)
Block(-2,5,4,DIRT:0)
Block(-2,5,5,DIRT:0)
Block(-2,5,6,DIRT:0)
Block(-2,5,7,DIRT:0)
Block(-2,5,8,GRASS:0)
Block(-2,6,0,CROPS:7)
Block(-2,6,1,CROPS:7)
Block(-2,6,2,CROPS:7)
Block(-2,6,3,CROPS:7)
Block(-2,6,4,HAY_BLOCK:0)
Block(-2,6,5,HAY_BLOCK:4)
Block(-2,6,6,LOG:1)
Block(-2,6,7,COBBLESTONE:0)
Block(-2,6,8,COBBLESTONE_STAIRS:0)
Block(-2,7,6,LOG:1)
Block(-2,7,7,COBBLESTONE:0)
Block(-2,7,8,COBBLESTONE_STAIRS:4)
Block(-2,8,6,LOG:1)
Block(-2,8,7,COBBLESTONE:0)
Block(-2,8,8,COBBLESTONE_STAIRS:0)
Block(-2,9,6,DARK_OAK_STAIRS:2)
Block(-2,9,7,SMOOTH_STAIRS:0)
Block(-2,12,7,LOG:5)
Block(-2,13,7,WOOD_STEP:1)
Block(-2,13,8,WOOD_STEP:1)
Block(-1,0,-7,DIRT:0)
Block(-1,0,-6,DIRT:0)
Block(-1,0,-5,DIRT:0)
Block(-1,0,-4,DIRT:0)
Block(-1,0,-3,DIRT:0)
Block(-1,0,-2,DIRT:0)
Block(-1,0,-1,DIRT:0)
Block(-1,0,0,DIRT:0)
Block(-1,0,1,DIRT:0)
Block(-1,0,2,DIRT:0)
Block(-1,0,3,DIRT:0)
Block(-1,0,4,DIRT:0)
Block(-1,0,5,DIRT:0)
Block(-1,0,6,DIRT:0)
Block(-1,0,7,DIRT:0)
Block(-1,0,8,DIRT:0)
Block(-1,1,-7,DIRT:0)
Block(-1,1,-6,DIRT:0)
Block(-1,1,-5,DIRT:0)
Block(-1,1,-4,DIRT:0)
Block(-1,1,-3,DIRT:0)
Block(-1,1,-2,DIRT:0)
Block(-1,1,-1,DIRT:0)
Block(-1,1,0,DIRT:0)
Block(-1,1,1,DIRT:0)
Block(-1,1,2,DIRT:0)
Block(-1,1,3,DIRT:0)
Block(-1,1,4,DIRT:0)
Block(-1,1,5,DIRT:0)
Block(-1,1,6,DIRT:0)
Block(-1,1,7,DIRT:0)
Block(-1,1,8,DIRT:0)
Block(-1,2,-7,GRASS:0)
Block(-1,2,-6,GRASS:0)
Block(-1,2,-5,DIRT:0)
Block(-1,2,-4,DIRT:0)
Block(-1,2,-3,DIRT:0)
Block(-1,2,-2,DIRT:0)
Block(-1,2,-1,DIRT:0)
Block(-1,2,0,DIRT:0)
Block(-1,2,1,DIRT:0)
Block(-1,2,2,DIRT:0)
Block(-1,2,3,DIRT:0)
Block(-1,2,4,DIRT:0)
Block(-1,2,5,DIRT:0)
Block(-1,2,6,DIRT:0)
Block(-1,2,7,DIRT:0)
Block(-1,2,8,DIRT:0)
Block(-1,3,-5,GRASS:0)
Block(-1,3,-4,DIRT:0)
Block(-1,3,-3,DIRT:0)
Block(-1,3,-2,DIRT:0)
Block(-1,3,-1,DIRT:0)
Block(-1,3,0,DIRT:0)
Block(-1,3,1,DIRT:0)
Block(-1,3,2,DIRT:0)
Block(-1,3,3,DIRT:0)
Block(-1,3,4,DIRT:0)
Block(-1,3,5,DIRT:0)
Block(-1,3,6,DIRT:0)
Block(-1,3,7,DIRT:0)
Block(-1,3,8,DIRT:0)
Block(-1,4,-4,GRASS:0)
Block(-1,4,-3,GRASS:0)
Block(-1,4,-2,GRASS:0)
Block(-1,4,-1,GRASS:0)
Block(-1,4,0,DIRT:0)
Block(-1,4,1,GRASS:0)
Block(-1,4,2,GRASS:0)
Block(-1,4,3,GRASS:0)
Block(-1,4,4,DIRT:0)
Block(-1,4,5,DIRT:0)
Block(-1,4,6,DIRT:0)
Block(-1,4,7,DIRT:0)
Block(-1,4,8,DIRT:0)
Block(-1,5,0,GRASS:0)
Block(-1,5,1,SOIL:0)
Block(-1,5,2,SOIL:0)
Block(-1,5,3,SOIL:0)
Block(-1,5,4,DIRT:0)
Block(-1,5,5,DIRT:0)
Block(-1,5,6,DIRT:0)
Block(-1,5,7,LOG:1)
Block(-1,5,8,COBBLESTONE:0)
Block(-1,6,0,DARK_OAK_FENCE:0)
Block(-1,6,1,CROPS:7)
Block(-1,6,2,CROPS:7)
Block(-1,6,3,CROPS:7)
Block(-1,6,4,HAY_BLOCK:0)
Block(-1,6,5,LOG:1)
Block(-1,6,6,DIRT:0)
Block(-1,6,7,LOG:1)
Block(-1,6,8,COBBLESTONE:0)
Block(-1,7,4,HAY_BLOCK:0)
Block(-1,7,5,LOG:1)
Block(-1,7,6,COBBLESTONE:0)
Block(-1,7,7,LOG:1)
Block(-1,7,8,COBBLESTONE:0)
Block(-1,8,5,LOG:1)
Block(-1,8,6,COBBLESTONE:0)
Block(-1,8,7,LOG:1)
Block(-1,8,8,COBBLESTONE:0)
Block(-1,9,5,DARK_OAK_STAIRS:2)
Block(-1,9,6,SMOOTH_STAIRS:0)
Block(-1,9,7,LOG:1)
Block(-1,9,8,COBBLESTONE:0)
Block(-1,10,7,LOG:1)
Block(-1,10,8,WOOD:5)
Block(-1,11,7,LOG:1)
Block(-1,11,8,WOOD:5)
Block(-1,12,7,LOG:5)
Block(-1,12,8,WOOD:5)
Block(-1,13,6,WOOD_STEP:1)
Block(-1,13,7,WOOD_DOUBLE_STEP:1)
Block(-1,13,8,WOOD_DOUBLE_STEP:1)
Block(0,0,-7,DIRT:0)
Block(0,0,-6,DIRT:0)
Block(0,0,-5,DIRT:0)
Block(0,0,-4,DIRT:0)
Block(0,0,-3,DIRT:0)
Block(0,0,-2,DIRT:0)
Block(0,0,-1,DIRT:0)
Block(0,0,0,DIRT:0)
Block(0,0,1,DIRT:0)
Block(0,0,2,DIRT:0)
Block(0,0,3,DIRT:0)
Block(0,0,4,DIRT:0)
Block(0,0,5,DIRT:0)
Block(0,0,6,DIRT:0)
Block(0,0,7,DIRT:0)
Block(0,0,8,DIRT:0)
Block(0,1,-7,DIRT:0)
Block(0,1,-6,DIRT:0)
Block(0,1,-5,DIRT:0)
Block(0,1,-4,DIRT:0)
Block(0,1,-3,DIRT:0)
Block(0,1,-2,DIRT:0)
Block(0,1,-1,DIRT:0)
Block(0,1,0,DIRT:0)
Block(0,1,1,DIRT:0)
Block(0,1,2,DIRT:0)
Block(0,1,3,DIRT:0)
Block(0,1,4,DIRT:0)
Block(0,1,5,DIRT:0)
Block(0,1,6,DIRT:0)
Block(0,1,7,DIRT:0)
Block(0,1,8,DIRT:0)
Block(0,2,-7,GRASS:0)
Block(0,2,-6,DIRT:0)
Block(0,2,-5,DIRT:0)
Block(0,2,-4,DIRT:0)
Block(0,2,-3,DIRT:0)
Block(0,2,-2,DIRT:0)
Block(0,2,-1,DIRT:0)
Block(0,2,0,DIRT:0)
Block(0,2,1,DIRT:0)
Block(0,2,2,DIRT:0)
Block(0,2,3,DIRT:0)
Block(0,2,4,DIRT:0)
Block(0,2,5,DIRT:0)
Block(0,2,6,DIRT:0)
Block(0,2,7,DIRT:0)
Block(0,2,8,DIRT:0)
Block(0,3,-6,GRASS:0)
Block(0,3,-5,GRASS:0)
Block(0,3,-4,DIRT:0)
Block(0,3,-3,DIRT:0)
Block(0,3,-2,DIRT:0)
Block(0,3,-1,DIRT:0)
Block(0,3,0,DIRT:0)
Block(0,3,1,DIRT:0)
Block(0,3,2,DIRT:0)
Block(0,3,3,DIRT:0)
Block(0,3,4,DIRT:0)
Block(0,3,5,DIRT:0)
Block(0,3,6,DIRT:0)
Block(0,3,7,DIRT:0)
Block(0,3,8,DIRT:0)
Block(0,4,-4,GRASS:0)
Block(0,4,-3,GRASS:0)
Block(0,4,-2,DIRT:0)
Block(0,4,-1,DIRT:0)
Block(0,4,0,DIRT:0)
Block(0,4,1,GRASS:0)
Block(0,4,2,GRASS:0)
Block(0,4,3,GRASS:0)
Block(0,4,4,DIRT:0)
Block(0,4,5,DIRT:0)
Block(0,4,6,DIRT:0)
Block(0,4,7,COBBLESTONE:0)
Block(0,4,8,COBBLESTONE:0)
Block(0,5,-2,GRASS:0)
Block(0,5,-1,GRASS:0)
Block(0,5,0,GRASS:0)
Block(0,5,1,SOIL:0)
Block(0,5,2,SOIL:0)
Block(0,5,3,SOIL:0)
Block(0,5,4,DIRT:0)
Block(0,5,5,DIRT:0)
Block(0,5,6,COBBLESTONE:0)
Block(0,5,7,WOOD_STEP:5)
Block(0,5,8,WOOD_STEP:5)
Block(0,6,-2,DARK_OAK_FENCE:0)
Block(0,6,-1,DARK_OAK_FENCE:0)
Block(0,6,0,DARK_OAK_FENCE:0)
Block(0,6,1,CROPS:7)
Block(0,6,2,CROPS:7)
Block(0,6,3,CROPS:7)
Block(0,6,4,LOG:1)
Block(0,6,5,COBBLESTONE:0)
Block(0,6,6,COBBLESTONE:0)
Block(0,6,7,LADDER:3)
Block(0,7,4,LOG:1)
Block(0,7,5,COBBLESTONE:0)
Block(0,7,6,COBBLESTONE:0)
Block(0,7,7,LADDER:3)
Block(0,8,4,LOG:1)
Block(0,8,5,COBBLESTONE:0)
Block(0,8,6,COBBLESTONE:0)
Block(0,8,7,LADDER:3)
Block(0,9,4,DARK_OAK_STAIRS:2)
Block(0,9,5,SMOOTH_STAIRS:0)
Block(0,9,6,COBBLESTONE:0)
Block(0,9,7,LADDER:3)
Block(0,10,6,WOOD:0)
Block(0,10,7,LADDER:3)
Block(0,11,6,WOOD:0)
Block(0,12,6,WOOD:0)
Block(0,12,7,LOG:5)
Block(0,13,5,WOOD_STEP:1)
Block(0,13,6,WOOD_DOUBLE_STEP:1)
Block(0,13,7,WOOD:0)
Block(0,13,8,WOOD:5)
Block(0,14,7,SPRUCE_WOOD_STAIRS:2)
Block(0,14,8,SPRUCE_WOOD_STAIRS:0)
Block(0,18,7,LOG:5)
Block(0,25,6,DARK_OAK_STAIRS:6)
Block(0,25,7,DARK_OAK_STAIRS:7)
Block(0,26,6,DARK_OAK_STAIRS:2)
Block(0,26,7,LOG:5)
Block(0,27,7,WOOD:5)
Block(0,28,7,DARK_OAK_STAIRS:2)
Block(0,28,8,SPRUCE_WOOD_STAIRS:7)
Block(0,29,8,WOOD:5)
Block(0,30,8,DARK_OAK_STAIRS:2)
Block(1,0,-7,DIRT:0)
Block(1,0,-6,DIRT:0)
Block(1,0,-5,DIRT:0)
Block(1,0,-4,DIRT:0)
Block(1,0,-3,DIRT:0)
Block(1,0,-2,DIRT:0)
Block(1,0,-1,DIRT:0)
Block(1,0,0,DIRT:0)
Block(1,0,1,DIRT:0)
Block(1,0,2,DIRT:0)
Block(1,0,3,DIRT:0)
Block(1,0,4,DIRT:0)
Block(1,0,5,DIRT:0)
Block(1,0,6,DIRT:0)
Block(1,0,7,DIRT:0)
Block(1,0,8,DIRT:0)
Block(1,1,-7,DIRT:0)
Block(1,1,-6,DIRT:0)
Block(1,1,-5,DIRT:0)
Block(1,1,-4,DIRT:0)
Block(1,1,-3,DIRT:0)
Block(1,1,-2,DIRT:0)
Block(1,1,-1,DIRT:0)
Block(1,1,0,DIRT:0)
Block(1,1,1,DIRT:0)
Block(1,1,2,DIRT:0)
Block(1,1,3,DIRT:0)
Block(1,1,4,DIRT:0)
Block(1,1,5,DIRT:0)
Block(1,1,6,DIRT:0)
Block(1,1,7,DIRT:0)
Block(1,1,8,DIRT:0)
Block(1,2,-7,GRASS:0)
Block(1,2,-6,DIRT:0)
Block(1,2,-5,DIRT:0)
Block(1,2,-4,DIRT:0)
Block(1,2,-3,DIRT:0)
Block(1,2,-2,DIRT:0)
Block(1,2,-1,DIRT:0)
Block(1,2,0,DIRT:0)
Block(1,2,1,DIRT:0)
Block(1,2,2,DIRT:0)
Block(1,2,3,DIRT:0)
Block(1,2,4,DIRT:0)
Block(1,2,5,DIRT:0)
Block(1,2,6,DIRT:0)
Block(1,2,7,DIRT:0)
Block(1,2,8,DIRT:0)
Block(1,3,-6,GRASS:0)
Block(1,3,-5,GRASS:0)
Block(1,3,-4,GRASS:0)
Block(1,3,-3,DIRT:0)
Block(1,3,-2,DIRT:0)
Block(1,3,-1,DIRT:0)
Block(1,3,0,DIRT:0)
Block(1,3,1,DIRT:0)
Block(1,3,2,DIRT:0)
Block(1,3,3,DIRT:0)
Block(1,3,4,DIRT:0)
Block(1,3,5,DIRT:0)
Block(1,3,6,DIRT:0)
Block(1,3,7,GRASS:0)
Block(1,3,8,GRASS:0)
Block(1,4,-3,GRASS:0)
Block(1,4,-2,GRASS:0)
Block(1,4,-1,GRASS:0)
Block(1,4,0,GRASS:0)
Block(1,4,1,GRASS:0)
Block(1,4,2,DIRT:0)
Block(1,4,3,DIRT:0)
Block(1,4,4,DIRT:0)
Block(1,4,5,DIRT:0)
Block(1,4,6,COBBLESTONE:0)
Block(1,4,7,HOPPER:3)
Block(1,4,8,HOPPER:3)
Block(1,5,-2,SOIL:0)
Block(1,5,-1,SOIL:0)
Block(1,5,0,SOIL:0)
Block(1,5,1,SOIL:0)
Block(1,5,2,DIRT:0)
Block(1,5,3,GRASS:0)
Block(1,5,4,DIRT:0)
Block(1,5,5,DIRT:0)
Block(1,5,6,COBBLESTONE:0)
Block(1,6,-2,CROPS:7)
Block(1,6,-1,CROPS:7)
Block(1,6,0,CROPS:7)
Block(1,6,1,CROPS:7)
Block(1,6,2,SMOOTH_BRICK:0)
Block(1,6,3,DARK_OAK_STAIRS:0)
Block(1,6,4,COBBLESTONE:0)
Block(1,6,5,LOG:1)
Block(1,6,6,COBBLESTONE:0)
Block(1,6,7,COBBLESTONE_STAIRS:7)
Block(1,7,2,SPRUCE_FENCE:0)
Block(1,7,4,COBBLESTONE:0)
Block(1,7,5,LOG:1)
Block(1,7,6,WOOD_STEP:5)
Block(1,7,7,WOOD_STEP:5)
Block(1,7,8,WOOD_STEP:5)
Block(1,8,4,COBBLESTONE:0)
Block(1,8,5,LOG:1)
Block(1,9,4,SMOOTH_STAIRS:2)
Block(1,9,5,LOG:1)
Block(1,9,6,DARK_OAK_STAIRS:7)
Block(1,10,5,LOG:1)
Block(1,10,6,HAY_BLOCK:0)
Block(1,11,5,LOG:1)
Block(1,12,4,LOG:9)
Block(1,12,5,LOG:9)
Block(1,12,6,LOG:9)
Block(1,12,7,LOG:9)
Block(1,12,8,LOG:9)
Block(1,13,4,WOOD_STEP:1)
Block(1,13,5,WOOD_DOUBLE_STEP:1)
Block(1,13,6,WOOD:0)
Block(1,13,7,LOG:1)
Block(1,13,8,WOOD:5)
Block(1,14,6,SPRUCE_WOOD_STAIRS:0)
Block(1,14,7,LOG:1)
Block(1,14,8,WOOD:5)
Block(1,15,7,LOG:1)
Block(1,15,8,WOOD:5)
Block(1,16,7,LOG:1)
Block(1,16,8,WOOD:5)
Block(1,17,7,LOG:1)
Block(1,17,8,WOOD:5)
Block(1,18,6,LOG:9)
Block(1,18,7,LOG:1)
Block(1,18,8,LOG:9)
Block(1,19,7,LOG:1)
Block(1,19,8,WOOD:5)
Block(1,20,7,LOG:1)
Block(1,20,8,WOOD:5)
Block(1,21,7,LOG:1)
Block(1,21,8,WOOD:5)
Block(1,22,7,LOG:1)
Block(1,22,8,WOOD:5)
Block(1,23,7,LOG:1)
Block(1,23,8,WOOD:5)
Block(1,24,7,LOG:1)
Block(1,24,8,WOOD:5)
Block(1,25,6,SPRUCE_WOOD_STAIRS:6)
Block(1,25,7,LOG:1)
Block(1,25,8,WOOD:5)
Block(1,26,6,LOG:9)
Block(1,26,7,LOG:1)
Block(1,26,8,LOG:9)
Block(1,27,7,WOOD:1)
Block(1,27,8,WOOD:5)
Block(1,28,7,SPRUCE_WOOD_STAIRS:2)
Block(1,28,8,WOOD:5)
Block(1,29,8,WOOD:1)
Block(1,30,8,SPRUCE_WOOD_STAIRS:2)
Block(2,0,-7,DIRT:0)
Block(2,0,-6,DIRT:0)
Block(2,0,-5,DIRT:0)
Block(2,0,-4,DIRT:0)
Block(2,0,-3,DIRT:0)
Block(2,0,-2,DIRT:0)
Block(2,0,-1,DIRT:0)
Block(2,0,0,DIRT:0)
Block(2,0,1,DIRT:0)
Block(2,0,2,DIRT:0)
Block(2,0,3,DIRT:0)
Block(2,0,4,DIRT:0)
Block(2,0,5,DIRT:0)
Block(2,0,6,DIRT:0)
Block(2,0,7,DIRT:0)
Block(2,0,8,DIRT:0)
Block(2,1,-7,DIRT:0)
Block(2,1,-6,DIRT:0)
Block(2,1,-5,DIRT:0)
Block(2,1,-4,DIRT:0)
Block(2,1,-3,DIRT:0)
Block(2,1,-2,DIRT:0)
Block(2,1,-1,DIRT:0)
Block(2,1,0,DIRT:0)
Block(2,1,1,DIRT:0)
Block(2,1,2,DIRT:0)
Block(2,1,3,DIRT:0)
Block(2,1,4,DIRT:0)
Block(2,1,5,DIRT:0)
Block(2,1,6,DIRT:0)
Block(2,1,7,DIRT:0)
Block(2,1,8,DIRT:0)
Block(2,2,-7,GRASS:0)
Block(2,2,-6,DIRT:0)
Block(2,2,-5,DIRT:0)
Block(2,2,-4,DIRT:0)
Block(2,2,-3,DIRT:0)
Block(2,2,-2,DIRT:0)
Block(2,2,-1,DIRT:0)
Block(2,2,0,DIRT:0)
Block(2,2,1,DIRT:0)
Block(2,2,2,DIRT:0)
Block(2,2,3,DIRT:0)
Block(2,2,4,DIRT:0)
Block(2,2,5,DIRT:0)
Block(2,2,6,DIRT:0)
Block(2,2,7,DIRT:0)
Block(2,2,8,DIRT:0)
Block(2,3,-6,GRASS:0)
Block(2,3,-5,GRASS:0)
Block(2,3,-4,DIRT:0)
Block(2,3,-3,DIRT:0)
Block(2,3,-2,DIRT:0)
Block(2,3,-1,DIRT:0)
Block(2,3,0,DIRT:0)
Block(2,3,1,DIRT:0)
Block(2,3,2,DIRT:0)
Block(2,3,3,DIRT:0)
Block(2,3,4,DIRT:0)
Block(2,3,5,DIRT:0)
Block(2,3,6,DIRT:0)
Block(2,3,7,DIRT:0)
Block(2,3,8,DIRT:0)
Block(2,4,-4,GRASS:0)
Block(2,4,-3,GRASS:0)
Block(2,4,-2,GRASS:0)
Block(2,4,-1,GRASS:0)
Block(2,4,0,GRASS:0)
Block(2,4,1,GRASS:0)
Block(2,4,2,DIRT:0)
Block(2,4,3,DIRT:0)
Block(2,4,4,DIRT:0)
Block(2,4,5,DIRT:0)
Block(2,4,6,DIRT:0)
Block(2,4,7,COBBLESTONE:0)
Block(2,4,8,COBBLESTONE:0)
Block(2,5,-4,SOIL:0)
Block(2,5,-3,SOIL:0)
Block(2,5,-2,SOIL:0)
Block(2,5,-1,SOIL:0)
Block(2,5,0,SOIL:0)
Block(2,5,1,SOIL:0)
Block(2,5,2,GRASS:0)
Block(2,5,3,DIRT:0)
Block(2,5,4,DIRT:0)
Block(2,5,5,DIRT:0)
Block(2,5,6,COBBLESTONE:0)
Block(2,5,7,WOOD_STEP:5)
Block(2,5,8,WOOD_STEP:5)
Block(2,6,-4,CROPS:7)
Block(2,6,-3,CROPS:7)
Block(2,6,-2,CROPS:7)
Block(2,6,-1,CROPS:7)
Block(2,6,0,CROPS:7)
Block(2,6,1,CROPS:7)
Block(2,6,2,SMOOTH_STAIRS:6)
Block(2,6,3,WOOD:5)
Block(2,6,4,WOOD:5)
Block(2,6,5,COBBLESTONE:0)
Block(2,6,6,COBBLESTONE:0)
Block(2,7,2,SPRUCE_FENCE:0)
Block(2,7,4,COBBLESTONE_STAIRS:2)
Block(2,7,5,COBBLESTONE:0)
Block(2,8,4,COBBLESTONE_STAIRS:6)
Block(2,8,5,COBBLESTONE:0)
Block(2,9,4,WOOD_STEP:5)
Block(2,9,5,LOG:5)
Block(2,9,6,DARK_OAK_STAIRS:7)
Block(2,10,5,WOOD:5)
Block(2,10,6,HAY_BLOCK:4)
Block(2,11,5,WOOD:5)
Block(2,11,6,HAY_BLOCK:0)
Block(2,12,5,WOOD:5)
Block(2,12,6,HAY_BLOCK:0)
Block(2,12,7,LOG:5)
Block(2,12,8,LOG:9)
Block(2,13,4,WOOD_STEP:1)
Block(2,13,5,WOOD_DOUBLE_STEP:1)
Block(2,13,6,WOOD:0)
Block(2,13,7,WOOD:0)
RandomBlock(2,13,8,AIR:0,20,CHEST:5,../../../Chests//Loot/JunkChest_1.nbt,10,CHEST:5,../../../Chests//Loot/JunkChest_2.nbt,10,CHEST:5,../../../Chests//Loot/JunkChest_3.nbt,10,CHEST:5,../../../Chests//Loot/JunkChest_4.nbt,10,CHEST:5,../../../Chests//Loot/JunkChest_5.nbt,10,CHEST:5,../../../Chests//Lore/Farmland_1.nbt,1,CHEST:5,../../../Chests//Lore/Farmland_2.nbt,1,CHEST:5,../../../Chests//Lore/Farmland_3.nbt,1,CHEST:5,../../../Chests//Lore/Farmland_4.nbt,1,CHEST:5,../../../Chests//Lore/Farmland_5.nbt,1,CHEST:5,../../../Chests//Loot/Common1.nbt,10,CHEST:5,../../../Chests//Loot/Common2.nbt,10,CHEST:5,../../../Chests//Loot/Common3.nbt,10,CHEST:5,../../../Chests//Loot/Common4.nbt,10,CHEST:5,../../../Chests//Loot/Common5.nbt,10,CHEST:5,../../../Chests//Loot/Common6.nbt,10,CHEST:5,../../../Chests//Loot/Common7.nbt,10,CHEST:5,../../../Chests//Loot/Common8.nbt,10,CHEST:5,../../../Chests//Loot/Common9.nbt,10,CHEST:5,../../../Chests//Loot/Common10.nbt,10,CHEST:5,../../../Chests//Loot/Common10.nbt,11,CHEST:5,../../../Chests//Loot/Common12.nbt,10,CHEST:5,../../../Chests//Loot/Common13.nbt,10,CHEST:5,../../../Chests//Loot/Common14.nbt,10,CHEST:5,../../../Chests//Loot/Common15.nbt,10,CHEST:5,../../../Chests//Lore/Farmland_1.nbt,2,CHEST:5,../../../Chests//Lore/Farmland_3.nbt,2,CHEST:5,../../../Chests//Lore/Farmland_4.nbt,2,CHEST:5,../../../Chests//Lore/Farmland_5.nbt,2,CHEST:5,../../../Chests//Lore/Farmland_5.nbt,2,CHEST:5,../../../Chests//Loot/Rare1.nbt,5,CHEST:5,../../../Chests//Loot/Rare2.nbt,5,CHEST:5,../../../Chests//Loot/Rare3.nbt,5,CHEST:5,../../../Chests//Loot/Rare4.nbt,5,CHEST:5,../../../Chests//Loot/Rare5.nbt,5,CHEST:5,../../../Chests//Loot/Rare6.nbt,5,CHEST:5,../../../Chests//Loot/Rare7.nbt,5,CHEST:5,../../../Chests//Loot/Rare8.nbt,5,CHEST:5,../../../Chests//Loot/Rare9.nbt,5,CHEST:5,../../../Chests//Loot/Rare10.nbt,5,CHEST:5,../../../Chests//Loot/Rare11.nbt,5,CHEST:5,../../../Chests//Loot/Rare12.nbt,5,CHEST:5,../../../Chests//Loot/Rare13.nbt,5,CHEST:5,../../../Chests//Loot/Rare14.nbt,5,CHEST:5,../../../Chests//Loot/Rare15.nbt,5,CHEST:5,../../../Chests//Loot/Epic1.nbt,2,CHEST:5,../../../Chests//Loot/Epic2.nbt,2,CHEST:5,../../../Chests//Loot/Epic3.nbt,2,CHEST:5,../../../Chests//Loot/Epic4.nbt,2,CHEST:5,../../../Chests//Loot/Epic5.nbt,2,CHEST:5,../../../Chests//Loot/Epic6.nbt,2,CHEST:5,../../../Chests//Loot/Epic7.nbt,2,CHEST:5,../../../Chests//Loot/Epic8.nbt,2,CHEST:5,../../../Chests//Loot/Epic9.nbt,2,CHEST:5,../../../Chests//Loot/Epic10.nbt,2,CHEST:5,../../../Chests//Loot/Epic11.nbt,2,CHEST:5,../../../Chests//Loot/Epic12.nbt,2,CHEST:5,../../../Chests//Loot/Epic13.nbt,2,CHEST:5,../../../Chests//Loot/Epic14.nbt,2,CHEST:5,../../../Chests//Loot/Epic15.nbt,5,CHEST:5,../../../Chests//Loot/Rare1.nbt,5,CHEST:5,../../../Chests//Loot/Rare2.nbt,5,CHEST:5,../../../Chests//Loot/Rare3.nbt,5,CHEST:5,../../../Chests//Loot/Rare4.nbt,5,CHEST:5,../../../Chests//Loot/Rare5.nbt,10,CHEST:5,../../../Chests//Loot/Rare6.nbt,10,CHEST:5,../../../Chests//Loot/Rare7.nbt,10,CHEST:5,../../../Chests//Loot/Rare8.nbt,10,CHEST:5,../../../Chests//Loot/Rare9.nbt,10,CHEST:5,../../../Chests//Loot/Rare10.nbt,15,CHEST:5,../../../Chests//Loot/Rare11.nbt,15,CHEST:5,../../../Chests//Loot/Rare12.nbt,15,CHEST:5,../../../Chests//Loot/Rare13.nbt,15,CHEST:5,../../../Chests//Loot/Rare14.nbt,15,CHEST:5,../../../Chests//Loot/Rare15.nbt,15,CHEST:5,../../../Chests//Loot/Epic15.nbt,100)
Block(2,14,6,SPRUCE_WOOD_STAIRS:2)
Block(2,14,7,WOOD:0)
Block(2,15,7,WOOD:5)
Block(2,16,7,WOOD:5)
Block(2,17,7,WOOD:5)
Block(2,18,7,LOG:5)
Block(2,18,8,COBBLE_WALL:0)
Block(2,19,7,WOOD:5)
Block(2,19,8,TORCH:5)
Block(2,20,7,WOOD:5)
Block(2,21,7,WOOD:5)
Block(2,21,8,WOOD_STEP:13)
Block(2,22,7,WOOD:5)
Block(2,22,8,LADDER:3)
Block(2,23,7,WOOD:5)
Block(2,23,8,LADDER:3)
Block(2,24,7,WOOD:5)
Block(2,24,8,LADDER:3)
Block(2,25,6,SPRUCE_WOOD_STAIRS:6)
Block(2,25,7,WOOD:5)
Block(2,25,8,LADDER:3)
Block(2,26,6,WOOD:5)
Block(2,26,7,LOG:5)
Block(2,26,8,LADDER:3)
Block(2,27,6,WOOD:5)
Block(2,27,7,WOOD:5)
Block(2,27,8,LADDER:3)
Block(2,28,6,SPRUCE_WOOD_STAIRS:0)
Block(2,28,7,SPRUCE_WOOD_STAIRS:0)
Block(2,29,8,WOOD:1)
Block(2,30,8,SPRUCE_WOOD_STAIRS:2)
Block(3,0,-7,DIRT:0)
Block(3,0,-6,DIRT:0)
Block(3,0,-5,DIRT:0)
Block(3,0,-4,DIRT:0)
Block(3,0,-3,DIRT:0)
Block(3,0,-2,DIRT:0)
Block(3,0,-1,DIRT:0)
Block(3,0,0,DIRT:0)
Block(3,0,1,DIRT:0)
Block(3,0,2,DIRT:0)
Block(3,0,3,DIRT:0)
Block(3,0,4,DIRT:0)
Block(3,0,5,DIRT:0)
Block(3,0,6,DIRT:0)
Block(3,0,7,DIRT:0)
Block(3,0,8,DIRT:0)
Block(3,1,-7,DIRT:0)
Block(3,1,-6,DIRT:0)
Block(3,1,-5,DIRT:0)
Block(3,1,-4,DIRT:0)
Block(3,1,-3,DIRT:0)
Block(3,1,-2,DIRT:0)
Block(3,1,-1,DIRT:0)
Block(3,1,0,DIRT:0)
Block(3,1,1,DIRT:0)
Block(3,1,2,DIRT:0)
Block(3,1,3,DIRT:0)
Block(3,1,4,DIRT:0)
Block(3,1,5,DIRT:0)
Block(3,1,6,DIRT:0)
Block(3,1,7,DIRT:0)
Block(3,1,8,DIRT:0)
Block(3,2,-7,DIRT:0)
Block(3,2,-6,DIRT:0)
Block(3,2,-5,DIRT:0)
Block(3,2,-4,DIRT:0)
Block(3,2,-3,DIRT:0)
Block(3,2,-2,DIRT:0)
Block(3,2,-1,DIRT:0)
Block(3,2,0,DIRT:0)
Block(3,2,1,DIRT:0)
Block(3,2,2,DIRT:0)
Block(3,2,3,DIRT:0)
Block(3,2,4,DIRT:0)
Block(3,2,5,DIRT:0)
Block(3,2,6,DIRT:0)
Block(3,2,7,DIRT:0)
Block(3,2,8,DIRT:0)
Block(3,3,-7,GRASS:0)
Block(3,3,-6,GRASS:0)
Block(3,3,-5,DIRT:0)
Block(3,3,-4,DIRT:0)
Block(3,3,-3,DIRT:0)
Block(3,3,-2,DIRT:0)
Block(3,3,-1,DIRT:0)
Block(3,3,0,DIRT:0)
Block(3,3,1,DIRT:0)
Block(3,3,2,DIRT:0)
Block(3,3,3,DIRT:0)
Block(3,3,4,DIRT:0)
Block(3,3,5,DIRT:0)
Block(3,3,6,DIRT:0)
Block(3,3,7,GRASS:0)
Block(3,3,8,DIRT:0)
Block(3,4,-5,GRASS:0)
Block(3,4,-4,GRASS:0)
Block(3,4,-3,GRASS:0)
Block(3,4,-2,GRASS:0)
Block(3,4,-1,GRASS:0)
Block(3,4,0,GRASS:0)
Block(3,4,1,GRASS:0)
Block(3,4,2,DIRT:0)
Block(3,4,3,DIRT:0)
Block(3,4,4,DIRT:0)
Block(3,4,5,DIRT:0)
Block(3,4,6,COBBLESTONE:0)
Block(3,4,7,SMOOTH_STAIRS:3)
Block(3,4,8,WOOD_STEP:5)
Block(3,5,-4,SOIL:0)
Block(3,5,-3,SOIL:0)
Block(3,5,-2,SOIL:0)
Block(3,5,-1,SOIL:0)
Block(3,5,0,SOIL:0)
Block(3,5,1,SOIL:0)
Block(3,5,2,GRASS:0)
Block(3,5,3,DIRT:0)
Block(3,5,4,DIRT:0)
Block(3,5,5,DIRT:0)
Block(3,5,6,COBBLESTONE:0)
Block(3,5,8,SMOOTH_STAIRS:6)
Block(3,6,-4,CROPS:7)
Block(3,6,-3,CROPS:7)
Block(3,6,-2,CROPS:7)
Block(3,6,-1,CROPS:7)
Block(3,6,0,CROPS:7)
Block(3,6,1,CROPS:7)
Block(3,6,2,SMOOTH_STAIRS:6)
Block(3,6,3,WOOD:5)
Block(3,6,4,COBBLESTONE:0)
Block(3,6,5,COBBLESTONE:0)
Block(3,6,6,COBBLESTONE:0)
Block(3,6,8,WOOD_DOUBLE_STEP:5)
Block(3,7,2,SPRUCE_FENCE:0)
Block(3,7,5,DARK_OAK_DOOR:1)
Block(3,7,8,SMOOTH_STAIRS:2)
Block(3,8,5,DARK_OAK_DOOR:8)
Block(3,9,4,SMOOTH_STAIRS:2)
Block(3,9,5,LOG:5)
Block(3,9,6,DARK_OAK_STAIRS:7)
Block(3,10,5,WOOD:0)
Block(3,10,6,HAY_BLOCK:4)
Block(3,11,5,WOOD:0)
Block(3,11,6,HAY_BLOCK:8)
Block(3,12,5,WOOD:0)
Block(3,12,7,LOG:5)
Block(3,13,4,WOOD_STEP:1)
Block(3,13,5,WOOD_DOUBLE_STEP:1)
Block(3,13,6,WOOD:0)
Block(3,13,7,WOOD:0)
Block(3,14,6,SPRUCE_WOOD_STAIRS:2)
Block(3,14,7,WOOD:0)
Block(3,15,7,WOOD_STEP:1)
Block(3,16,7,SPRUCE_WOOD_STAIRS:6)
Block(3,17,7,WOOD:0)
Block(3,18,7,LOG:5)
Block(3,19,7,WOOD:0)
Block(3,20,7,WOOD_STEP:1)
Block(3,21,7,SPRUCE_WOOD_STAIRS:2)
Block(3,22,7,FENCE:0)
Block(3,23,7,SPRUCE_WOOD_STAIRS:6)
Block(3,24,7,WOOD:0)
Block(3,25,6,SPRUCE_WOOD_STAIRS:6)
Block(3,25,7,WOOD:0)
Block(3,25,8,COBBLESTONE_STAIRS:6)
Block(3,26,6,WOOD_STEP:1)
Block(3,26,8,WOOD:5)
Block(3,27,8,COBBLESTONE_STAIRS:2)
Block(3,28,6,WOOD_STEP:9)
Block(3,28,7,WOOD_STEP:9)
Block(3,29,6,WOOD_STEP:1)
Block(3,29,7,WOOD_STEP:1)
Block(3,29,8,WOOD:1)
Block(3,30,8,SPRUCE_WOOD_STAIRS:2)
Block(4,0,-7,DIRT:0)
Block(4,0,-6,DIRT:0)
Block(4,0,-5,DIRT:0)
Block(4,0,-4,DIRT:0)
Block(4,0,-3,DIRT:0)
Block(4,0,-2,DIRT:0)
Block(4,0,-1,DIRT:0)
Block(4,0,0,DIRT:0)
Block(4,0,1,DIRT:0)
Block(4,0,2,DIRT:0)
Block(4,0,3,DIRT:0)
Block(4,0,4,DIRT:0)
Block(4,0,5,DIRT:0)
Block(4,0,6,DIRT:0)
Block(4,0,7,DIRT:0)
Block(4,0,8,DIRT:0)
Block(4,1,-7,DIRT:0)
Block(4,1,-6,DIRT:0)
Block(4,1,-5,DIRT:0)
Block(4,1,-4,DIRT:0)
Block(4,1,-3,DIRT:0)
Block(4,1,-2,DIRT:0)
Block(4,1,-1,DIRT:0)
Block(4,1,0,DIRT:0)
Block(4,1,1,DIRT:0)
Block(4,1,2,DIRT:0)
Block(4,1,3,DIRT:0)
Block(4,1,4,DIRT:0)
Block(4,1,5,DIRT:0)
Block(4,1,6,DIRT:0)
Block(4,1,7,DIRT:0)
Block(4,1,8,DIRT:0)
Block(4,2,-7,DIRT:0)
Block(4,2,-6,DIRT:0)
Block(4,2,-5,DIRT:0)
Block(4,2,-4,DIRT:0)
Block(4,2,-3,DIRT:0)
Block(4,2,-2,DIRT:0)
Block(4,2,-1,DIRT:0)
Block(4,2,0,DIRT:0)
Block(4,2,1,DIRT:0)
Block(4,2,2,DIRT:0)
Block(4,2,3,DIRT:0)
Block(4,2,4,DIRT:0)
Block(4,2,5,DIRT:0)
Block(4,2,6,DIRT:0)
Block(4,2,7,DIRT:0)
Block(4,2,8,DIRT:0)
Block(4,3,-7,GRASS:0)
Block(4,3,-6,DIRT:0)
Block(4,3,-5,DIRT:0)
Block(4,3,-4,DIRT:0)
Block(4,3,-3,DIRT:0)
Block(4,3,-2,DIRT:0)
Block(4,3,-1,DIRT:0)
Block(4,3,0,DIRT:0)
Block(4,3,1,DIRT:0)
Block(4,3,2,DIRT:0)
Block(4,3,3,DIRT:0)
Block(4,3,4,DIRT:0)
Block(4,3,5,DIRT:0)
Block(4,3,6,DIRT:0)
Block(4,3,7,DIRT:0)
Block(4,3,8,DIRT:0)
Block(4,4,-6,GRASS:0)
Block(4,4,-5,GRASS:0)
Block(4,4,-4,DIRT:0)
Block(4,4,-3,DIRT:0)
Block(4,4,-2,GRASS:0)
Block(4,4,-1,DIRT:0)
Block(4,4,0,GRASS:0)
Block(4,4,1,GRASS:0)
Block(4,4,2,DIRT:0)
Block(4,4,3,DIRT:0)
Block(4,4,4,DIRT:0)
Block(4,4,5,DIRT:0)
Block(4,4,6,DIRT:0)
Block(4,4,7,COBBLESTONE:0)
Block(4,4,8,COBBLESTONE:0)
Block(4,5,-4,GRASS:0)
Block(4,5,-3,DIRT:0)
Block(4,5,-2,SOIL:0)
Block(4,5,-1,GRASS:0)
Block(4,5,0,SOIL:0)
Block(4,5,1,SOIL:0)
Block(4,5,2,GRASS:0)
Block(4,5,3,DIRT:0)
Block(4,5,4,DIRT:0)
Block(4,5,5,DIRT:0)
Block(4,5,6,COBBLESTONE:0)
Block(4,5,7,SMOOTH_STAIRS:3)
Block(4,5,8,IRON_FENCE:0)
Block(4,6,-4,DARK_OAK_FENCE:0)
Block(4,6,-3,HAY_BLOCK:4)
Block(4,6,-2,CROPS:7)
Block(4,6,-1,DARK_OAK_FENCE:0)
Block(4,6,0,CROPS:7)
Block(4,6,1,CROPS:7)
Block(4,6,2,SMOOTH_STAIRS:6)
Block(4,6,3,WOOD:5)
Block(4,6,4,WOOD:5)
Block(4,6,5,COBBLESTONE:0)
Block(4,6,6,COBBLESTONE:0)
Block(4,6,8,IRON_FENCE:0)
Block(4,7,-4,DARK_OAK_FENCE:0)
Block(4,7,-1,DARK_OAK_FENCE:0)
Block(4,7,2,SPRUCE_FENCE:0)
Block(4,7,4,COBBLESTONE_STAIRS:2)
Block(4,7,5,COBBLESTONE:0)
Block(4,7,8,IRON_FENCE:0)
Block(4,8,-4,DARK_OAK_FENCE:0)
Block(4,8,-3,DARK_OAK_FENCE:0)
Block(4,8,-2,DARK_OAK_FENCE:0)
Block(4,8,-1,DARK_OAK_FENCE:0)
Block(4,8,4,COBBLESTONE_STAIRS:6)
Block(4,8,5,COBBLESTONE:0)
Block(4,8,8,IRON_FENCE:0)
Block(4,9,4,WOOD_STEP:5)
Block(4,9,5,LOG:5)
Block(4,9,6,DARK_OAK_STAIRS:7)
Block(4,9,8,IRON_FENCE:0)
Block(4,10,5,WOOD:5)
Block(4,10,6,HAY_BLOCK:8)
Block(4,10,8,IRON_FENCE:0)
Block(4,11,5,WOOD:5)
Block(4,11,8,IRON_FENCE:0)
Block(4,12,5,WOOD:5)
Block(4,12,7,LOG:5)
Block(4,12,8,IRON_FENCE:0)
Block(4,13,4,WOOD_STEP:1)
Block(4,13,5,WOOD_DOUBLE_STEP:1)
Block(4,13,6,WOOD:0)
Block(4,13,7,WOOD:0)
Block(4,13,8,IRON_FENCE:0)
Block(4,14,6,SPRUCE_WOOD_STAIRS:2)
Block(4,14,7,WOOD:0)
Block(4,14,8,IRON_FENCE:0)
Block(4,15,7,WOOD:5)
Block(4,15,8,IRON_FENCE:0)
Block(4,16,7,WOOD:5)
Block(4,16,8,IRON_FENCE:0)
Block(4,17,7,WOOD:5)
Block(4,17,8,IRON_FENCE:0)
Block(4,18,7,LOG:5)
Block(4,18,8,IRON_FENCE:0)
Block(4,19,7,WOOD:5)
Block(4,19,8,IRON_FENCE:0)
Block(4,20,7,WOOD:5)
Block(4,20,8,IRON_FENCE:0)
Block(4,21,7,WOOD:5)
Block(4,21,8,IRON_FENCE:0)
Block(4,22,7,WOOD:5)
Block(4,22,8,IRON_FENCE:0)
Block(4,23,7,WOOD:5)
Block(4,23,8,IRON_FENCE:0)
Block(4,24,7,WOOD:5)
Block(4,24,8,IRON_FENCE:0)
Block(4,25,6,SPRUCE_WOOD_STAIRS:6)
Block(4,25,7,WOOD:5)
Block(4,25,8,IRON_FENCE:0)
Block(4,26,6,WOOD:5)
Block(4,26,7,LOG:5)
Block(4,26,8,IRON_FENCE:0)
Block(4,27,6,WOOD:5)
Block(4,27,7,WOOD:5)
Block(4,27,8,IRON_FENCE:0)
Block(4,28,6,SPRUCE_WOOD_STAIRS:1)
Block(4,28,7,SPRUCE_WOOD_STAIRS:1)
Block(4,29,8,WOOD:1)
Block(4,30,8,SPRUCE_WOOD_STAIRS:2)
Block(5,0,-7,DIRT:0)
Block(5,0,-6,DIRT:0)
Block(5,0,-5,DIRT:0)
Block(5,0,-4,DIRT:0)
Block(5,0,-3,DIRT:0)
Block(5,0,-2,DIRT:0)
Block(5,0,-1,DIRT:0)
Block(5,0,0,DIRT:0)
Block(5,0,1,DIRT:0)
Block(5,0,2,DIRT:0)
Block(5,0,3,DIRT:0)
Block(5,0,4,DIRT:0)
Block(5,0,5,DIRT:0)
Block(5,0,6,DIRT:0)
Block(5,0,7,DIRT:0)
Block(5,0,8,DIRT:0)
Block(5,1,-7,DIRT:0)
Block(5,1,-6,DIRT:0)
Block(5,1,-5,DIRT:0)
Block(5,1,-4,DIRT:0)
Block(5,1,-3,DIRT:0)
Block(5,1,-2,DIRT:0)
Block(5,1,-1,DIRT:0)
Block(5,1,0,DIRT:0)
Block(5,1,1,DIRT:0)
Block(5,1,2,DIRT:0)
Block(5,1,3,DIRT:0)
Block(5,1,4,DIRT:0)
Block(5,1,5,DIRT:0)
Block(5,1,6,DIRT:0)
Block(5,1,7,DIRT:0)
Block(5,1,8,DIRT:0)
Block(5,2,-7,DIRT:0)
Block(5,2,-6,DIRT:0)
Block(5,2,-5,DIRT:0)
Block(5,2,-4,DIRT:0)
Block(5,2,-3,DIRT:0)
Block(5,2,-2,DIRT:0)
Block(5,2,-1,DIRT:0)
Block(5,2,0,DIRT:0)
Block(5,2,1,DIRT:0)
Block(5,2,2,DIRT:0)
Block(5,2,3,DIRT:0)
Block(5,2,4,DIRT:0)
Block(5,2,5,DIRT:0)
Block(5,2,6,DIRT:0)
Block(5,2,7,DIRT:0)
Block(5,2,8,DIRT:0)
Block(5,3,-7,GRASS:0)
Block(5,3,-6,DIRT:0)
Block(5,3,-5,DIRT:0)
Block(5,3,-4,DIRT:0)
Block(5,3,-3,DIRT:0)
Block(5,3,-2,DIRT:0)
Block(5,3,-1,DIRT:0)
Block(5,3,0,DIRT:0)
Block(5,3,1,DIRT:0)
Block(5,3,2,DIRT:0)
Block(5,3,3,DIRT:0)
Block(5,3,4,DIRT:0)
Block(5,3,5,DIRT:0)
Block(5,3,6,DIRT:0)
Block(5,3,7,DIRT:0)
Block(5,3,8,DIRT:0)
Block(5,4,-6,GRASS:0)
Block(5,4,-5,GRASS:0)
Block(5,4,-4,GRASS:0)
Block(5,4,-3,DIRT:0)
Block(5,4,-2,DIRT:0)
Block(5,4,-1,GRASS:0)
Block(5,4,0,GRASS:0)
Block(5,4,1,GRASS:0)
Block(5,4,2,DIRT:0)
Block(5,4,3,DIRT:0)
Block(5,4,4,DIRT:0)
Block(5,4,5,DIRT:0)
Block(5,4,6,DIRT:0)
Block(5,4,7,DIRT:0)
Block(5,4,8,DIRT:0)
Block(5,5,-5,SOIL:0)
Block(5,5,-4,SOIL:0)
Block(5,5,-3,DIRT:0)
Block(5,5,-2,DIRT:0)
Block(5,5,-1,SOIL:0)
Block(5,5,0,SOIL:0)
Block(5,5,1,SOIL:0)
Block(5,5,2,DIRT:0)
Block(5,5,3,GRASS:0)
Block(5,5,4,DIRT:0)
Block(5,5,5,DIRT:0)
Block(5,5,6,DIRT:0)
Block(5,5,7,COBBLESTONE:0)
Block(5,5,8,COBBLESTONE:0)
Block(5,6,-5,CROPS:7)
Block(5,6,-4,CROPS:7)
Block(5,6,-3,HAY_BLOCK:0)
Block(5,6,-2,HAY_BLOCK:4)
Block(5,6,-1,CROPS:7)
Block(5,6,0,CROPS:7)
Block(5,6,1,CROPS:7)
Block(5,6,2,SMOOTH_BRICK:0)
Block(5,6,3,SMOOTH_STAIRS:5)
Block(5,6,4,COBBLESTONE:0)
Block(5,6,5,LOG:1)
Block(5,6,6,COBBLESTONE:0)
Block(5,6,7,COBBLESTONE:0)
Block(5,6,8,COBBLESTONE:0)
Block(5,7,-3,HAY_BLOCK:0)
Block(5,7,2,SPRUCE_FENCE:0)
Block(5,7,3,SPRUCE_FENCE:0)
Block(5,7,4,COBBLESTONE:0)
Block(5,7,5,LOG:1)
Block(5,8,-4,DARK_OAK_FENCE:0)
Block(5,8,-3,WOOD_DOUBLE_STEP:5)
Block(5,8,-2,WOOD_DOUBLE_STEP:5)
Block(5,8,-1,DARK_OAK_FENCE:0)
Block(5,8,4,COBBLESTONE:0)
Block(5,8,5,LOG:1)
Block(5,9,4,SMOOTH_STAIRS:2)
Block(5,9,5,LOG:1)
Block(5,9,6,DARK_OAK_STAIRS:7)
Block(5,9,7,WOOD_STEP:13)
Block(5,9,8,WOOD_STEP:13)
Block(5,10,5,LOG:1)
Block(5,10,6,HAY_BLOCK:8)
Block(5,10,7,HAY_BLOCK:8)
Block(5,11,5,LOG:1)
Block(5,11,6,HAY_BLOCK:0)
Block(5,12,4,LOG:9)
Block(5,12,5,LOG:9)
Block(5,12,6,LOG:9)
Block(5,12,7,LOG:5)
Block(5,12,8,LOG:9)
Block(5,13,4,WOOD_STEP:1)
Block(5,13,5,WOOD_DOUBLE_STEP:1)
Block(5,13,6,WOOD:0)
Block(5,13,7,LOG:1)
Block(5,13,8,WOOD:0)
Block(5,14,6,SPRUCE_WOOD_STAIRS:1)
Block(5,14,7,LOG:1)
Block(5,14,8,WOOD:0)
Block(5,15,7,LOG:1)
Block(5,15,8,WOOD:5)
Block(5,16,7,LOG:1)
Block(5,16,8,WOOD:5)
Block(5,17,7,LOG:1)
Block(5,17,8,WOOD:5)
Block(5,18,6,LOG:9)
Block(5,18,7,LOG:1)
Block(5,18,8,LOG:9)
Block(5,19,7,LOG:1)
Block(5,19,8,WOOD:5)
Block(5,20,7,LOG:1)
Block(5,20,8,WOOD:5)
Block(5,21,7,LOG:1)
Block(5,21,8,WOOD:5)
Block(5,22,7,LOG:1)
Block(5,22,8,WOOD:5)
Block(5,23,7,LOG:1)
Block(5,23,8,WOOD:5)
Block(5,24,7,LOG:1)
Block(5,24,8,WOOD:5)
Block(5,25,6,SPRUCE_WOOD_STAIRS:6)
Block(5,25,7,LOG:1)
Block(5,25,8,WOOD:0)
Block(5,26,6,LOG:9)
Block(5,26,7,LOG:1)
Block(5,26,8,LOG:9)
Block(5,27,7,WOOD:1)
Block(5,27,8,WOOD:0)
Block(5,28,7,SPRUCE_WOOD_STAIRS:2)
Block(5,28,8,WOOD:0)
Block(5,29,8,WOOD:1)
Block(5,30,8,SPRUCE_WOOD_STAIRS:2)
Block(6,0,-7,DIRT:0)
Block(6,0,-6,DIRT:0)
Block(6,0,-5,DIRT:0)
Block(6,0,-4,DIRT:0)
Block(6,0,-3,DIRT:0)
Block(6,0,-2,DIRT:0)
Block(6,0,-1,DIRT:0)
Block(6,0,0,DIRT:0)
Block(6,0,1,DIRT:0)
Block(6,0,2,DIRT:0)
Block(6,0,3,DIRT:0)
Block(6,0,4,DIRT:0)
Block(6,0,5,DIRT:0)
Block(6,0,6,DIRT:0)
Block(6,0,7,DIRT:0)
Block(6,0,8,DIRT:0)
Block(6,1,-7,DIRT:0)
Block(6,1,-6,DIRT:0)
Block(6,1,-5,DIRT:0)
Block(6,1,-4,DIRT:0)
Block(6,1,-3,DIRT:0)
Block(6,1,-2,DIRT:0)
Block(6,1,-1,DIRT:0)
Block(6,1,0,DIRT:0)
Block(6,1,1,DIRT:0)
Block(6,1,2,DIRT:0)
Block(6,1,3,DIRT:0)
Block(6,1,4,DIRT:0)
Block(6,1,5,DIRT:0)
Block(6,1,6,DIRT:0)
Block(6,1,7,DIRT:0)
Block(6,1,8,DIRT:0)
Block(6,2,-7,DIRT:0)
Block(6,2,-6,DIRT:0)
Block(6,2,-5,DIRT:0)
Block(6,2,-4,DIRT:0)
Block(6,2,-3,DIRT:0)
Block(6,2,-2,DIRT:0)
Block(6,2,-1,DIRT:0)
Block(6,2,0,DIRT:0)
Block(6,2,1,DIRT:0)
Block(6,2,2,DIRT:0)
Block(6,2,3,DIRT:0)
Block(6,2,4,DIRT:0)
Block(6,2,5,DIRT:0)
Block(6,2,6,DIRT:0)
Block(6,2,7,DIRT:0)
Block(6,2,8,DIRT:0)
Block(6,3,-7,GRASS:0)
Block(6,3,-6,DIRT:0)
Block(6,3,-5,DIRT:0)
Block(6,3,-4,DIRT:0)
Block(6,3,-3,DIRT:0)
Block(6,3,-2,DIRT:0)
Block(6,3,-1,DIRT:0)
Block(6,3,0,DIRT:0)
Block(6,3,1,DIRT:0)
Block(6,3,2,DIRT:0)
Block(6,3,3,DIRT:0)
Block(6,3,4,DIRT:0)
Block(6,3,5,DIRT:0)
Block(6,3,6,DIRT:0)
Block(6,3,7,DIRT:0)
Block(6,3,8,DIRT:0)
Block(6,4,-6,GRASS:0)
Block(6,4,-5,GRASS:0)
Block(6,4,-4,DIRT:0)
Block(6,4,-3,DIRT:0)
Block(6,4,-2,DIRT:0)
Block(6,4,-1,GRASS:0)
Block(6,4,0,GRASS:0)
Block(6,4,1,GRASS:0)
Block(6,4,2,GRASS:0)
Block(6,4,3,DIRT:0)
Block(6,4,4,DIRT:0)
Block(6,4,5,DIRT:0)
Block(6,4,6,DIRT:0)
Block(6,4,7,DIRT:0)
Block(6,4,8,DIRT:0)
Block(6,5,-5,SOIL:0)
Block(6,5,-4,DIRT:0)
Block(6,5,-3,DIRT:0)
Block(6,5,-2,DIRT:0)
Block(6,5,-1,SOIL:0)
Block(6,5,0,SOIL:0)
Block(6,5,1,SOIL:0)
Block(6,5,2,SOIL:0)
Block(6,5,3,DIRT:0)
Block(6,5,4,DIRT:0)
Block(6,5,5,DIRT:0)
Block(6,5,6,DIRT:0)
Block(6,5,7,DIRT:0)
Block(6,5,8,DIRT:0)
Block(6,6,-5,CROPS:7)
Block(6,6,-4,HAY_BLOCK:0)
Block(6,6,-3,HAY_BLOCK:0)
Block(6,6,-2,HAY_BLOCK:0)
Block(6,6,-1,CROPS:7)
Block(6,6,0,CROPS:7)
Block(6,6,1,CROPS:7)
Block(6,6,2,CROPS:7)
Block(6,6,3,HAY_BLOCK:0)
Block(6,6,4,LOG:1)
Block(6,6,5,COBBLESTONE:0)
Block(6,6,6,COBBLESTONE:0)
Block(6,6,7,COBBLESTONE:0)
Block(6,6,8,COBBLESTONE:0)
Block(6,7,-2,HAY_BLOCK:0)
Block(6,7,4,LOG:1)
Block(6,7,5,COBBLESTONE:0)
Block(6,7,6,COBBLESTONE:0)
Block(6,7,8,LADDER:2)
Block(6,8,-4,DARK_OAK_FENCE:0)
Block(6,8,-3,WOOD_STEP:5)
Block(6,8,-2,WOOD_STEP:5)
Block(6,8,-1,DARK_OAK_FENCE:0)
Block(6,8,4,LOG:1)
Block(6,8,5,COBBLESTONE:0)
Block(6,8,6,COBBLESTONE:0)
Block(6,8,8,LADDER:2)
Block(6,9,4,DARK_OAK_STAIRS:1)
Block(6,9,5,SMOOTH_STAIRS:2)
Block(6,9,6,COBBLESTONE:0)
Block(6,9,8,LADDER:2)
Block(6,10,6,WOOD:0)
Block(6,10,8,LADDER:2)
Block(6,11,6,WOOD:0)
Block(6,12,6,WOOD:0)
Block(6,12,7,LOG:5)
Block(6,13,5,WOOD_STEP:1)
Block(6,13,6,WOOD_DOUBLE_STEP:1)
Block(6,13,7,WOOD:0)
Block(6,13,8,WOOD:0)
Block(6,14,7,SPRUCE_WOOD_STAIRS:2)
Block(6,14,8,SPRUCE_WOOD_STAIRS:1)
Block(6,18,7,LOG:5)
Block(6,25,6,DARK_OAK_STAIRS:6)
Block(6,25,7,DARK_OAK_STAIRS:7)
Block(6,25,8,COBBLESTONE_STAIRS:5)
Block(6,26,6,DARK_OAK_STAIRS:2)
Block(6,26,7,LOG:5)
Block(6,26,8,COBBLESTONE:0)
Block(6,27,7,WOOD:5)
Block(6,27,8,COBBLESTONE_STAIRS:1)
Block(6,28,7,DARK_OAK_STAIRS:2)
Block(6,28,8,SPRUCE_WOOD_STAIRS:7)
Block(6,29,8,WOOD:5)
Block(6,30,8,DARK_OAK_STAIRS:2)
Block(7,0,-7,DIRT:0)
Block(7,0,-6,DIRT:0)
Block(7,0,-5,DIRT:0)
Block(7,0,-4,DIRT:0)
Block(7,0,-3,DIRT:0)
Block(7,0,-2,DIRT:0)
Block(7,0,-1,DIRT:0)
Block(7,0,0,DIRT:0)
Block(7,0,1,DIRT:0)
Block(7,0,2,DIRT:0)
Block(7,0,3,DIRT:0)
Block(7,0,4,DIRT:0)
Block(7,0,5,DIRT:0)
Block(7,0,6,DIRT:0)
Block(7,0,7,DIRT:0)
Block(7,0,8,DIRT:0)
Block(7,1,-7,DIRT:0)
Block(7,1,-6,DIRT:0)
Block(7,1,-5,DIRT:0)
Block(7,1,-4,DIRT:0)
Block(7,1,-3,DIRT:0)
Block(7,1,-2,DIRT:0)
Block(7,1,-1,DIRT:0)
Block(7,1,0,DIRT:0)
Block(7,1,1,DIRT:0)
Block(7,1,2,DIRT:0)
Block(7,1,3,DIRT:0)
Block(7,1,4,DIRT:0)
Block(7,1,5,DIRT:0)
Block(7,1,6,DIRT:0)
Block(7,1,7,DIRT:0)
Block(7,1,8,DIRT:0)
Block(7,2,-7,DIRT:0)
Block(7,2,-6,DIRT:0)
Block(7,2,-5,DIRT:0)
Block(7,2,-4,DIRT:0)
Block(7,2,-3,DIRT:0)
Block(7,2,-2,DIRT:0)
Block(7,2,-1,DIRT:0)
Block(7,2,0,DIRT:0)
Block(7,2,1,DIRT:0)
Block(7,2,2,DIRT:0)
Block(7,2,3,DIRT:0)
Block(7,2,4,DIRT:0)
Block(7,2,5,DIRT:0)
Block(7,2,6,DIRT:0)
Block(7,2,7,DIRT:0)
Block(7,2,8,DIRT:0)
Block(7,3,-7,GRASS:0)
Block(7,3,-6,GRASS:0)
Block(7,3,-5,DIRT:0)
Block(7,3,-4,DIRT:0)
Block(7,3,-3,DIRT:0)
Block(7,3,-2,DIRT:0)
Block(7,3,-1,DIRT:0)
Block(7,3,0,DIRT:0)
Block(7,3,1,DIRT:0)
Block(7,3,2,DIRT:0)
Block(7,3,3,DIRT:0)
Block(7,3,4,DIRT:0)
Block(7,3,5,DIRT:0)
Block(7,3,6,DIRT:0)
Block(7,3,7,DIRT:0)
Block(7,3,8,DIRT:0)
Block(7,4,-5,GRASS:0)
Block(7,4,-4,GRASS:0)
Block(7,4,-3,DIRT:0)
Block(7,4,-2,DIRT:0)
Block(7,4,-1,GRASS:0)
Block(7,4,0,GRASS:0)
Block(7,4,1,GRASS:0)
Block(7,4,2,GRASS:0)
Block(7,4,3,GRASS:0)
Block(7,4,4,DIRT:0)
Block(7,4,5,DIRT:0)
Block(7,4,6,DIRT:0)
Block(7,4,7,DIRT:0)
Block(7,4,8,DIRT:0)
Block(7,5,-4,SOIL:0)
Block(7,5,-3,DIRT:0)
Block(7,5,-2,DIRT:0)
Block(7,5,-1,SOIL:0)
Block(7,5,0,SOIL:0)
Block(7,5,1,SOIL:0)
Block(7,5,2,SOIL:0)
Block(7,5,3,SOIL:0)
Block(7,5,4,DIRT:0)
Block(7,5,5,DIRT:0)
Block(7,5,6,DIRT:0)
Block(7,5,7,DIRT:0)
Block(7,5,8,DIRT:0)
Block(7,6,-4,CROPS:7)
Block(7,6,-3,HAY_BLOCK:0)
Block(7,6,-2,HAY_BLOCK:0)
Block(7,6,-1,CROPS:7)
Block(7,6,0,CROPS:7)
Block(7,6,1,CROPS:7)
Block(7,6,2,CROPS:7)
Block(7,6,3,CROPS:7)
Block(7,6,4,HAY_BLOCK:0)
Block(7,6,5,LOG:1)
Block(7,6,6,DIRT:0)
Block(7,6,7,DIRT:0)
Block(7,6,8,DIRT:0)
Block(7,7,4,HAY_BLOCK:8)
Block(7,7,5,LOG:1)
Block(7,7,6,COBBLESTONE:0)
Block(7,7,7,LOG:1)
Block(7,7,8,COBBLESTONE:0)
Block(7,8,-4,DARK_OAK_FENCE:0)
Block(7,8,-3,WOOD_DOUBLE_STEP:5)
Block(7,8,-2,WOOD_DOUBLE_STEP:5)
Block(7,8,-1,DARK_OAK_FENCE:0)
Block(7,8,5,LOG:1)
Block(7,8,6,COBBLESTONE:0)
Block(7,8,7,LOG:1)
Block(7,8,8,COBBLESTONE:0)
Block(7,9,5,DARK_OAK_STAIRS:1)
Block(7,9,6,SMOOTH_STAIRS:1)
Block(7,9,7,LOG:1)
Block(7,9,8,COBBLESTONE:0)
Block(7,10,7,LOG:1)
Block(7,10,8,WOOD:5)
Block(7,11,7,LOG:1)
Block(7,11,8,WOOD:5)
Block(7,12,7,LOG:5)
Block(7,12,8,WOOD:5)
Block(7,13,6,WOOD_STEP:1)
Block(7,13,7,WOOD_DOUBLE_STEP:1)
Block(7,13,8,WOOD_DOUBLE_STEP:1)
Branch(16,0,0,true,WindMill_02C1R0,NORTH,100.0,0)
