Author: Bo3 BulkEdit
Description: Converted Schematic - Modified by Bo3BulkEdit - Bo3 Created by NLBlackEagle for Dregora
SettingsMode: WriteDisable
Frequency: 1
SpawnHeight: highestSolidBlock
UseCenterForHighestBlock: false
MinHeight: 0
MaxHeight: 255
InheritBO3: 
InheritBO3Rotation: NORTH
OverrideChildSettings: true
OverrideParentHeight: true
CanOverride: false
BranchFrequency: 0
BranchFrequencyGroup: 
MustBeBelowOther: false
MustBeInside: 
CannotBeInside: 
ReplacesBO3: 
MustBeInsideWorldBorders: false
CanSpawnOnWater: true
SpawnOnWaterOnly: false
SpawnUnderWater: true
SpawnAtWaterLevel: false
HeightOffset: 0
RemoveAir: true
ReplaceAbove: 
ReplaceBelow: GRAVEL
ReplaceWithBiomeBlocks: true
ReplaceWithSurfaceBlock: GRASS
ReplaceWithGroundBlock: DIRT
ReplaceWithStoneBlock: STONE
SmoothRadius: 10
SmoothHeightOffset: 0
SmoothStartTop: false
SmoothStartWood: false
SmoothingSurfaceBlock: GRAVEL
SmoothingGroundBlock: GRAVEL
BO3Group: 
IsSpawnPoint: false
DoReplaceBlocks: true
Block(-4,0,-8,GRAVEL:0)
Block(0,0,-8,GRAVEL:0)
Block(2,0,-8,GRAVEL:0)
Block(3,0,-8,GRAVEL:0)
Block(4,0,-8,GRAVEL:0)
Block(5,0,-8,GRAVEL:0)
Block(-7,0,-7,GRAVEL:0)
RandomBlock(-6,0,-7,SMOOTH_BRICK:1,10,SMOOTH_BRICK:2,10,COBBLESTONE,10,MOSSY_COBBLESTONE,10,SMOOTH_BRICK:0,100)
Block(-5,0,-7,GRAVEL:0)
Block(-4,0,-7,GRAVEL:0)
Block(-3,0,-7,GRAVEL:0)
RandomBlock(-2,0,-7,SMOOTH_BRICK:1,10,SMOOTH_BRICK:2,10,COBBLESTONE,10,MOSSY_COBBLESTONE,10,SMOOTH_BRICK:0,100)
Block(-1,0,-7,GRAVEL:0)
Block(0,0,-7,GRAVEL:0)
RandomBlock(1,0,-7,SMOOTH_BRICK:1,10,SMOOTH_BRICK:2,10,COBBLESTONE,10,MOSSY_COBBLESTONE,10,SMOOTH_BRICK:0,100)
Block(2,0,-7,GRAVEL:0)
Block(3,0,-7,GRAVEL:0)
Block(4,0,-7,GRAVEL:0)
RandomBlock(5,0,-7,SMOOTH_BRICK:1,10,SMOOTH_BRICK:2,10,COBBLESTONE,10,MOSSY_COBBLESTONE,10,SMOOTH_BRICK:0,100)
Block(6,0,-7,GRAVEL:0)
Block(-8,0,-6,GRAVEL:0)
RandomBlock(-7,0,-6,SMOOTH_BRICK:1,10,SMOOTH_BRICK:2,10,COBBLESTONE,10,MOSSY_COBBLESTONE,10,SMOOTH_BRICK:0,100)
RandomBlock(-6,0,-6,SMOOTH_BRICK:1,10,SMOOTH_BRICK:2,10,COBBLESTONE,10,MOSSY_COBBLESTONE,10,SMOOTH_BRICK:0,100)
Block(-5,0,-6,GRAVEL:0)
Block(-4,0,-6,GRAVEL:0)
Block(-3,0,-6,GRAVEL:0)
RandomBlock(-2,0,-6,SMOOTH_BRICK:1,10,SMOOTH_BRICK:2,10,COBBLESTONE,10,MOSSY_COBBLESTONE,10,SMOOTH_BRICK:0,100)
Block(-1,0,-6,GRAVEL:0)
Block(0,0,-6,GRAVEL:0)
RandomBlock(1,0,-6,SMOOTH_BRICK:1,10,SMOOTH_BRICK:2,10,COBBLESTONE,10,MOSSY_COBBLESTONE,10,SMOOTH_BRICK:0,100)
Block(2,0,-6,GRAVEL:0)
Block(3,0,-6,GRAVEL:0)
Block(4,0,-6,GRAVEL:0)
RandomBlock(5,0,-6,SMOOTH_BRICK:1,10,SMOOTH_BRICK:2,10,COBBLESTONE,10,MOSSY_COBBLESTONE,10,SMOOTH_BRICK:0,100)
RandomBlock(6,0,-6,SMOOTH_BRICK:1,10,SMOOTH_BRICK:2,10,COBBLESTONE,10,MOSSY_COBBLESTONE,10,SMOOTH_BRICK:0,100)
Block(-7,0,-5,GRAVEL:0)
Block(-6,0,-5,GRAVEL:0)
Block(-5,0,-5,GRAVEL:0)
Block(-4,0,-5,GRAVEL:0)
Block(-3,0,-5,GRAVEL:0)
Block(-2,0,-5,GRAVEL:0)
Block(-1,0,-5,GRAVEL:0)
Block(0,0,-5,GRAVEL:0)
Block(1,0,-5,GRAVEL:0)
Block(3,0,-5,GRAVEL:0)
Block(4,0,-5,GRAVEL:0)
Block(5,0,-5,GRAVEL:0)
Block(6,0,-5,GRAVEL:0)
Block(7,0,-5,GRAVEL:0)
Block(-8,0,-4,GRAVEL:0)
Block(-7,0,-4,GRAVEL:0)
Block(-6,0,-4,GRAVEL:0)
RandomBlock(-5,0,-4,SMOOTH_BRICK:1,10,SMOOTH_BRICK:2,10,COBBLESTONE,10,MOSSY_COBBLESTONE,10,SMOOTH_BRICK:0,100)
Block(-4,0,-4,GRAVEL:0)
RandomBlock(-3,0,-4,CHEST:3,../../../Chests/Loot/oceanruin_big.nbt,50,CHEST:3,../../../Chests/Traveler/Travelers_Castle.nbt,1,CHEST:3,../../../Chests/Traveler/Travelers_Church.nbt,1,CHEST:3,../../../Chests/Traveler/Travelers_Daeroc.nbt,1,CHEST:3,../../../Chests/Traveler/Travelers_Farmsteads.nbt,1,CHEST:3,../../../Chests/Traveler/Travelers_GreenDungeon.nbt,1,CHEST:3,../../../Chests/Traveler/Travelers_IceShips.nbt,1,CHEST:3,../../../Chests/Traveler/Travelers_IceTemple.nbt,1,CHEST:3,../../../Chests/Traveler/Travelers_LegacySpawn.nbt,1,CHEST:3,../../../Chests/Traveler/Travelers_Mineshafts.nbt,1,CHEST:3,../../../Chests/Traveler/Travelers_Mountains.nbt,1,CHEST:3,../../../Chests/Traveler/Travelers_Origin.nbt,1,CHEST:3,../../../Chests/Traveler/Travelers_Pirate.nbt,1,CHEST:3,../../../Chests/Traveler/Travelers_Quarry.nbt,1,CHEST:3,../../../Chests/Traveler/Travelers_Spook.nbt,1,CHEST:3,../../../Chests/Traveler/Travelers_Tribal.nbt,1)
Block(-2,0,-4,GRAVEL:0)
Block(-1,0,-4,GRAVEL:0)
Block(0,0,-4,GRAVEL:0)
Block(1,0,-4,GRAVEL:0)
Block(2,0,-4,GRAVEL:0)
Block(3,0,-4,PRISMARINE:0)
Block(4,0,-4,GRAVEL:0)
Block(5,0,-4,GRAVEL:0)
Block(6,0,-4,GRAVEL:0)
Block(7,0,-4,GRAVEL:0)
Block(-8,0,-3,GRAVEL:0)
Block(-7,0,-3,GRAVEL:0)
Block(-6,0,-3,PRISMARINE:0)
Block(-5,0,-3,GRAVEL:0)
Block(-4,0,-3,GRAVEL:0)
Block(-3,0,-3,GRAVEL:0)
Block(-2,0,-3,GRAVEL:0)
Block(-1,0,-3,GRAVEL:0)
Block(0,0,-3,GRAVEL:0)
Block(1,0,-3,GRAVEL:0)
Block(2,0,-3,GRAVEL:0)
Block(3,0,-3,GRAVEL:0)
Block(4,0,-3,GRAVEL:0)
Block(5,0,-3,GRAVEL:0)
Block(6,0,-3,GRAVEL:0)
Block(7,0,-3,GRAVEL:0)
Block(-7,0,-2,GRAVEL:0)
Block(-6,0,-2,GRAVEL:0)
Block(-5,0,-2,GRAVEL:0)
Block(-4,0,-2,GRAVEL:0)
Block(-3,0,-2,GRAVEL:0)
Block(-2,0,-2,GRAVEL:0)
Block(-1,0,-2,GRAVEL:0)
Block(0,0,-2,GRAVEL:0)
Block(1,0,-2,GRAVEL:0)
Block(2,0,-2,GRAVEL:0)
Block(3,0,-2,SAND:0)
Block(4,0,-2,GRAVEL:0)
RandomBlock(5,0,-2,SMOOTH_BRICK:1,10,SMOOTH_BRICK:2,10,COBBLESTONE,10,MOSSY_COBBLESTONE,10,SMOOTH_BRICK:0,100)
RandomBlock(6,0,-2,SMOOTH_BRICK:1,10,SMOOTH_BRICK:2,10,COBBLESTONE,10,MOSSY_COBBLESTONE,10,SMOOTH_BRICK:0,100)
Block(-7,0,-1,GRAVEL:0)
Block(-6,0,-1,GRAVEL:0)
Block(-5,0,-1,GRAVEL:0)
Block(-4,0,-1,GRAVEL:0)
Block(-3,0,-1,GRAVEL:0)
Block(-2,0,-1,GRAVEL:0)
Block(-1,0,-1,GRAVEL:0)
Block(0,0,-1,GRAVEL:0)
Block(1,0,-1,GRAVEL:0)
Block(2,0,-1,GRAVEL:0)
Block(3,0,-1,GRAVEL:0)
Block(4,0,-1,GRAVEL:0)
Block(5,0,-1,GRAVEL:0)
Block(6,0,-1,GRAVEL:0)
Block(-7,0,0,GRAVEL:0)
Block(-6,0,0,GRAVEL:0)
Block(-5,0,0,GRAVEL:0)
Block(-4,0,0,GRAVEL:0)
Block(-3,0,0,GRAVEL:0)
Block(-2,0,0,GRAVEL:0)
Block(-1,0,0,GRAVEL:0)
RandomBlock(0,0,0,SMOOTH_BRICK:1,10,SMOOTH_BRICK:2,10,COBBLESTONE,10,MOSSY_COBBLESTONE,10,SMOOTH_BRICK:0,100)
Block(1,0,0,GRAVEL:0)
Block(2,0,0,PRISMARINE:0)
Block(3,0,0,GRAVEL:0)
Block(4,0,0,GRAVEL:0)
Block(5,0,0,GRAVEL:0)
Block(-8,0,1,GRAVEL:0)
Block(-7,0,1,GRAVEL:0)
RandomBlock(-6,0,1,SMOOTH_BRICK:1,10,SMOOTH_BRICK:2,10,COBBLESTONE,10,MOSSY_COBBLESTONE,10,SMOOTH_BRICK:0,100)
Block(-5,0,1,GRAVEL:0)
Block(-4,0,1,GRAVEL:0)
Block(-3,0,1,GRAVEL:0)
Block(-2,0,1,GRAVEL:0)
Block(-1,0,1,GRAVEL:0)
Block(0,0,1,GRAVEL:0)
Block(1,0,1,GRAVEL:0)
Block(2,0,1,GRAVEL:0)
Block(3,0,1,GRAVEL:0)
Block(4,0,1,GRAVEL:0)
Block(5,0,1,GRAVEL:0)
RandomBlock(6,0,1,SMOOTH_BRICK:1,10,SMOOTH_BRICK:2,10,COBBLESTONE,10,MOSSY_COBBLESTONE,10,SMOOTH_BRICK:0,100)
Block(-7,0,2,GRAVEL:0)
Block(-6,0,2,GRAVEL:0)
Block(-5,0,2,GRAVEL:0)
Block(-4,0,2,GRAVEL:0)
Block(-3,0,2,GRAVEL:0)
Block(-2,0,2,GRAVEL:0)
Block(-1,0,2,GRAVEL:0)
Block(0,0,2,GRAVEL:0)
Block(1,0,2,GRAVEL:0)
Block(2,0,2,GRAVEL:0)
Block(3,0,2,GRAVEL:0)
Block(4,0,2,GRAVEL:0)
Block(5,0,2,GRAVEL:0)
Block(6,0,2,GRAVEL:0)
Block(7,0,2,GRAVEL:0)
Block(-5,0,3,GRAVEL:0)
RandomBlock(-4,0,3,SMOOTH_BRICK:1,10,SMOOTH_BRICK:2,10,COBBLESTONE,10,MOSSY_COBBLESTONE,10,SMOOTH_BRICK:0,100)
Block(-3,0,3,GRAVEL:0)
Block(-2,0,3,GRAVEL:0)
Block(-1,0,3,GRAVEL:0)
Block(0,0,3,GRAVEL:0)
Block(1,0,3,GRAVEL:0)
Block(2,0,3,GRAVEL:0)
Block(3,0,3,PRISMARINE:0)
Block(4,0,3,GRAVEL:0)
Block(5,0,3,GRAVEL:0)
Block(6,0,3,GRAVEL:0)
Block(7,0,3,GRAVEL:0)
Block(-6,0,4,GRAVEL:0)
Block(-5,0,4,GRAVEL:0)
Block(-4,0,4,GRAVEL:0)
Block(-3,0,4,GRAVEL:0)
Block(-2,0,4,GRAVEL:0)
Block(-1,0,4,GRAVEL:0)
Block(0,0,4,GRAVEL:0)
RandomBlock(1,0,4,SMOOTH_BRICK:1,10,SMOOTH_BRICK:2,10,COBBLESTONE,10,MOSSY_COBBLESTONE,10,SMOOTH_BRICK:0,100)
Block(2,0,4,GRAVEL:0)
Block(3,0,4,GRAVEL:0)
Block(4,0,4,GRAVEL:0)
Block(5,0,4,GRAVEL:0)
RandomBlock(6,0,4,SMOOTH_BRICK:1,10,SMOOTH_BRICK:2,10,COBBLESTONE,10,MOSSY_COBBLESTONE,10,SMOOTH_BRICK:0,100)
Block(7,0,4,GRAVEL:0)
Block(-7,0,5,GRAVEL:0)
Block(-6,0,5,GRAVEL:0)
Block(-5,0,5,GRAVEL:0)
Block(-4,0,5,GRAVEL:0)
Block(-3,0,5,GRAVEL:0)
RandomBlock(-2,0,5,SMOOTH_BRICK:1,10,SMOOTH_BRICK:2,10,COBBLESTONE,10,MOSSY_COBBLESTONE,10,SMOOTH_BRICK:0,100)
Block(-1,0,5,GRAVEL:0)
Block(0,0,5,GRAVEL:0)
RandomBlock(1,0,5,SMOOTH_BRICK:1,10,SMOOTH_BRICK:2,10,COBBLESTONE,10,MOSSY_COBBLESTONE,10,SMOOTH_BRICK:0,100)
Block(2,0,5,GRAVEL:0)
Block(3,0,5,GRAVEL:0)
RandomBlock(4,0,5,SMOOTH_BRICK:1,10,SMOOTH_BRICK:2,10,COBBLESTONE,10,MOSSY_COBBLESTONE,10,SMOOTH_BRICK:0,100)
RandomBlock(5,0,5,SMOOTH_BRICK:1,10,SMOOTH_BRICK:2,10,COBBLESTONE,10,MOSSY_COBBLESTONE,10,SMOOTH_BRICK:0,100)
RandomBlock(6,0,5,SMOOTH_BRICK:1,10,SMOOTH_BRICK:2,10,COBBLESTONE,10,MOSSY_COBBLESTONE,10,SMOOTH_BRICK:0,100)
Block(7,0,5,GRAVEL:0)
Block(-7,0,6,GRAVEL:0)
Block(-6,0,6,GRAVEL:0)
Block(-5,0,6,GRAVEL:0)
Block(-4,0,6,GRAVEL:0)
Block(-3,0,6,GRAVEL:0)
RandomBlock(-2,0,6,SMOOTH_BRICK:1,10,SMOOTH_BRICK:2,10,COBBLESTONE,10,MOSSY_COBBLESTONE,10,SMOOTH_BRICK:0,100)
Block(-1,0,6,GRAVEL:0)
RandomBlock(1,0,6,SMOOTH_BRICK:1,10,SMOOTH_BRICK:2,10,COBBLESTONE,10,MOSSY_COBBLESTONE,10,SMOOTH_BRICK:0,100)
Block(2,0,6,GRAVEL:0)
Block(3,0,6,GRAVEL:0)
Block(4,0,6,GRAVEL:0)
RandomBlock(5,0,6,SMOOTH_BRICK:1,10,SMOOTH_BRICK:2,10,COBBLESTONE,10,MOSSY_COBBLESTONE,10,SMOOTH_BRICK:0,100)
Block(6,0,6,GRAVEL:0)
Block(-6,0,7,GRAVEL:0)
Block(-5,0,7,GRAVEL:0)
Block(-4,0,7,GRAVEL:0)
Block(-3,0,7,GRAVEL:0)
Block(1,0,7,GRAVEL:0)
Block(2,0,7,GRAVEL:0)
Block(3,0,7,GRAVEL:0)
Block(4,0,7,GRAVEL:0)
Block(5,0,7,GRAVEL:0)
Block(3,1,-8,GRAVEL:0)
RandomBlock(-6,1,-7,SMOOTH_BRICK:1,10,SMOOTH_BRICK:2,10,COBBLESTONE,10,MOSSY_COBBLESTONE,10,SMOOTH_BRICK:0,100)
Block(-4,1,-7,GRAVEL:0)
RandomBlock(-2,1,-7,SMOOTH_BRICK:1,10,SMOOTH_BRICK:2,10,COBBLESTONE,10,MOSSY_COBBLESTONE,10,SMOOTH_BRICK:0,100)
Block(0,1,-7,GRAVEL:0)
RandomBlock(1,1,-7,SMOOTH_BRICK:1,10,SMOOTH_BRICK:2,10,COBBLESTONE,10,MOSSY_COBBLESTONE,10,SMOOTH_BRICK:0,100)
Block(4,1,-7,GRAVEL:0)
RandomBlock(5,1,-7,SMOOTH_BRICK:1,10,SMOOTH_BRICK:2,10,COBBLESTONE,10,MOSSY_COBBLESTONE,10,SMOOTH_BRICK:0,100)
RandomBlock(-7,1,-6,SMOOTH_BRICK:1,10,SMOOTH_BRICK:2,10,COBBLESTONE,10,MOSSY_COBBLESTONE,10,SMOOTH_BRICK:0,100)
RandomBlock(-6,1,-6,SMOOTH_BRICK:1,10,SMOOTH_BRICK:2,10,COBBLESTONE,10,MOSSY_COBBLESTONE,10,SMOOTH_BRICK:0,100)
Block(-5,1,-6,GRAVEL:0)
Block(-4,1,-6,GRAVEL:0)
Block(-3,1,-6,GRAVEL:0)
RandomBlock(-2,1,-6,SMOOTH_BRICK:1,10,SMOOTH_BRICK:2,10,COBBLESTONE,10,MOSSY_COBBLESTONE,10,SMOOTH_BRICK:0,100)
RandomBlock(1,1,-6,SMOOTH_BRICK:1,10,SMOOTH_BRICK:2,10,COBBLESTONE,10,MOSSY_COBBLESTONE,10,SMOOTH_BRICK:0,100)
RandomBlock(5,1,-6,SMOOTH_BRICK:1,10,SMOOTH_BRICK:2,10,COBBLESTONE,10,MOSSY_COBBLESTONE,10,SMOOTH_BRICK:0,100)
RandomBlock(6,1,-6,SMOOTH_BRICK:1,10,SMOOTH_BRICK:2,10,COBBLESTONE,10,MOSSY_COBBLESTONE,10,SMOOTH_BRICK:0,100)
Block(-7,1,-5,GRAVEL:0)
Block(-6,1,-5,GRAVEL:0)
Block(-4,1,-5,GRAVEL:0)
Block(-6,1,-4,GRAVEL:0)
RandomBlock(-4,1,-4,SMOOTH_BRICK:1,10,SMOOTH_BRICK:2,10,COBBLESTONE,10,MOSSY_COBBLESTONE,10,SMOOTH_BRICK:0,100)
Block(-3,1,-4,GRAVEL:0)
RandomBlock(-2,1,-4,CHEST:3,../../../Chests/Loot/oceanruin_big.nbt,50,CHEST:3,../../../Chests/Traveler/Travelers_Castle.nbt,1,CHEST:3,../../../Chests/Traveler/Travelers_Church.nbt,1,CHEST:3,../../../Chests/Traveler/Travelers_Daeroc.nbt,1,CHEST:3,../../../Chests/Traveler/Travelers_Farmsteads.nbt,1,CHEST:3,../../../Chests/Traveler/Travelers_GreenDungeon.nbt,1,CHEST:3,../../../Chests/Traveler/Travelers_IceShips.nbt,1,CHEST:3,../../../Chests/Traveler/Travelers_IceTemple.nbt,1,CHEST:3,../../../Chests/Traveler/Travelers_LegacySpawn.nbt,1,CHEST:3,../../../Chests/Traveler/Travelers_Mineshafts.nbt,1,CHEST:3,../../../Chests/Traveler/Travelers_Mountains.nbt,1,CHEST:3,../../../Chests/Traveler/Travelers_Origin.nbt,1,CHEST:3,../../../Chests/Traveler/Travelers_Pirate.nbt,1,CHEST:3,../../../Chests/Traveler/Travelers_Quarry.nbt,1,CHEST:3,../../../Chests/Traveler/Travelers_Spook.nbt,1,CHEST:3,../../../Chests/Traveler/Travelers_Tribal.nbt,1)
Block(-1,1,-4,GRAVEL:0)
RandomBlock(3,1,-4,SMOOTH_BRICK:1,10,SMOOTH_BRICK:2,10,COBBLESTONE,10,MOSSY_COBBLESTONE,10,SMOOTH_BRICK:0,100)
Block(6,1,-4,GRAVEL:0)
Block(-7,1,-3,GRAVEL:0)
Block(-5,1,-3,GRAVEL:0)
Block(-4,1,-3,GRAVEL:0)
Block(-2,1,-3,GRAVEL:0)
Block(3,1,-3,GRAVEL:0)
RandomBlock(-7,1,-2,SMOOTH_BRICK:1,10,SMOOTH_BRICK:2,10,COBBLESTONE,10,MOSSY_COBBLESTONE,10,SMOOTH_BRICK:0,100)
RandomBlock(-6,1,-2,SMOOTH_BRICK:1,10,SMOOTH_BRICK:2,10,COBBLESTONE,10,MOSSY_COBBLESTONE,10,SMOOTH_BRICK:0,100)
Block(-4,1,-2,GRAVEL:0)
Block(3,1,-2,GRAVEL:0)
Block(4,1,-2,GRAVEL:0)
RandomBlock(5,1,-2,SMOOTH_BRICK:1,10,SMOOTH_BRICK:2,10,COBBLESTONE,10,MOSSY_COBBLESTONE,10,SMOOTH_BRICK:0,100)
RandomBlock(6,1,-2,SMOOTH_BRICK:1,10,SMOOTH_BRICK:2,10,COBBLESTONE,10,MOSSY_COBBLESTONE,10,SMOOTH_BRICK:0,100)
Block(-5,1,-1,GRAVEL:0)
Block(1,1,-1,GRAVEL:0)
Block(2,1,-1,GRAVEL:0)
Block(-1,1,0,GRAVEL:0)
Block(1,1,0,GRAVEL:0)
Block(2,1,0,GRAVEL:0)
RandomBlock(-7,1,1,SMOOTH_BRICK:1,10,SMOOTH_BRICK:2,10,COBBLESTONE,10,MOSSY_COBBLESTONE,10,SMOOTH_BRICK:0,100)
RandomBlock(-6,1,1,SMOOTH_BRICK:1,10,SMOOTH_BRICK:2,10,COBBLESTONE,10,MOSSY_COBBLESTONE,10,SMOOTH_BRICK:0,100)
Block(0,1,1,GRAVEL:0)
RandomBlock(5,1,1,SMOOTH_BRICK:1,10,SMOOTH_BRICK:2,10,COBBLESTONE,10,MOSSY_COBBLESTONE,10,SMOOTH_BRICK:0,100)
RandomBlock(6,1,1,SMOOTH_BRICK:1,10,SMOOTH_BRICK:2,10,COBBLESTONE,10,MOSSY_COBBLESTONE,10,SMOOTH_BRICK:0,100)
Block(-4,1,2,GRAVEL:0)
Block(2,1,2,GRAVEL:0)
RandomBlock(-4,1,3,SMOOTH_BRICK:1,10,SMOOTH_BRICK:2,10,COBBLESTONE,10,MOSSY_COBBLESTONE,10,SMOOTH_BRICK:0,100)
Block(-3,1,3,GRAVEL:0)
RandomBlock(0,1,3,CHEST:3,../../../Chests/Loot/oceanruin_big.nbt,50,CHEST:3,../../../Chests/Traveler/Travelers_Castle.nbt,1,CHEST:3,../../../Chests/Traveler/Travelers_Church.nbt,1,CHEST:3,../../../Chests/Traveler/Travelers_Daeroc.nbt,1,CHEST:3,../../../Chests/Traveler/Travelers_Farmsteads.nbt,1,CHEST:3,../../../Chests/Traveler/Travelers_GreenDungeon.nbt,1,CHEST:3,../../../Chests/Traveler/Travelers_IceShips.nbt,1,CHEST:3,../../../Chests/Traveler/Travelers_IceTemple.nbt,1,CHEST:3,../../../Chests/Traveler/Travelers_LegacySpawn.nbt,1,CHEST:3,../../../Chests/Traveler/Travelers_Mineshafts.nbt,1,CHEST:3,../../../Chests/Traveler/Travelers_Mountains.nbt,1,CHEST:3,../../../Chests/Traveler/Travelers_Origin.nbt,1,CHEST:3,../../../Chests/Traveler/Travelers_Pirate.nbt,1,CHEST:3,../../../Chests/Traveler/Travelers_Quarry.nbt,1,CHEST:3,../../../Chests/Traveler/Travelers_Spook.nbt,1,CHEST:3,../../../Chests/Traveler/Travelers_Tribal.nbt,1)
Block(1,1,3,GRAVEL:0)
Block(2,1,3,GRAVEL:0)
RandomBlock(3,1,3,SMOOTH_BRICK:1,10,SMOOTH_BRICK:2,10,COBBLESTONE,10,MOSSY_COBBLESTONE,10,SMOOTH_BRICK:0,100)
Block(6,1,3,GRAVEL:0)
Block(4,1,4,GRAVEL:0)
Block(5,1,4,GRAVEL:0)
Block(7,1,4,GRAVEL:0)
RandomBlock(-7,1,5,SMOOTH_BRICK:1,10,SMOOTH_BRICK:2,10,COBBLESTONE,10,MOSSY_COBBLESTONE,10,SMOOTH_BRICK:0,100)
RandomBlock(-6,1,5,SMOOTH_BRICK:1,10,SMOOTH_BRICK:2,10,COBBLESTONE,10,MOSSY_COBBLESTONE,10,SMOOTH_BRICK:0,100)
Block(-3,1,5,GRAVEL:0)
RandomBlock(-2,1,5,SMOOTH_BRICK:1,10,SMOOTH_BRICK:2,10,COBBLESTONE,10,MOSSY_COBBLESTONE,10,SMOOTH_BRICK:0,100)
RandomBlock(1,1,5,SMOOTH_BRICK:1,10,SMOOTH_BRICK:2,10,COBBLESTONE,10,MOSSY_COBBLESTONE,10,SMOOTH_BRICK:0,100)
Block(2,1,5,GRAVEL:0)
Block(3,1,5,GRAVEL:0)
RandomBlock(5,1,5,SMOOTH_BRICK:1,10,SMOOTH_BRICK:2,10,COBBLESTONE,10,MOSSY_COBBLESTONE,10,SMOOTH_BRICK:0,100)
RandomBlock(6,1,5,SMOOTH_BRICK:1,10,SMOOTH_BRICK:2,10,COBBLESTONE,10,MOSSY_COBBLESTONE,10,SMOOTH_BRICK:0,100)
RandomBlock(-6,1,6,SMOOTH_BRICK:1,10,SMOOTH_BRICK:2,10,COBBLESTONE,10,MOSSY_COBBLESTONE,10,SMOOTH_BRICK:0,100)
Block(-5,1,6,GRAVEL:0)
Block(-4,1,6,GRAVEL:0)
RandomBlock(-2,1,6,SMOOTH_BRICK:1,10,SMOOTH_BRICK:2,10,COBBLESTONE,10,MOSSY_COBBLESTONE,10,SMOOTH_BRICK:0,100)
RandomBlock(1,1,6,SMOOTH_BRICK:1,10,SMOOTH_BRICK:2,10,COBBLESTONE,10,MOSSY_COBBLESTONE,10,SMOOTH_BRICK:0,100)
Block(2,1,6,GRAVEL:0)
RandomBlock(5,1,6,SMOOTH_BRICK:1,10,SMOOTH_BRICK:2,10,COBBLESTONE,10,MOSSY_COBBLESTONE,10,SMOOTH_BRICK:0,100)
Block(-5,1,7,GRAVEL:0)
Block(4,1,7,GRAVEL:0)
Block(4,2,-7,GRAVEL:0)
RandomBlock(-6,2,-6,SMOOTH_BRICK:1,10,SMOOTH_BRICK:2,10,COBBLESTONE,10,MOSSY_COBBLESTONE,10,SMOOTH_BRICK:0,100)
Block(-4,2,-6,GRAVEL:0)
RandomBlock(-2,2,-6,SMOOTH_BRICK:1,10,SMOOTH_BRICK:2,10,COBBLESTONE,10,MOSSY_COBBLESTONE,10,SMOOTH_BRICK:0,100)
RandomBlock(1,2,-6,SMOOTH_BRICK:1,10,SMOOTH_BRICK:2,10,COBBLESTONE,10,MOSSY_COBBLESTONE,10,SMOOTH_BRICK:0,100)
RandomBlock(5,2,-6,SMOOTH_BRICK:1,10,SMOOTH_BRICK:2,10,COBBLESTONE,10,MOSSY_COBBLESTONE,10,SMOOTH_BRICK:0,100)
Block(-6,2,-4,GRAVEL:0)
RandomBlock(-4,2,-4,SMOOTH_BRICK:1,10,SMOOTH_BRICK:2,10,COBBLESTONE,10,MOSSY_COBBLESTONE,10,SMOOTH_BRICK:0,100)
RandomBlock(3,2,-4,SMOOTH_BRICK:1,10,SMOOTH_BRICK:2,10,COBBLESTONE,10,MOSSY_COBBLESTONE,10,SMOOTH_BRICK:0,100)
Block(-5,2,-3,GRAVEL:0)
RandomBlock(-6,2,-2,SMOOTH_BRICK:1,10,SMOOTH_BRICK:2,10,COBBLESTONE,10,MOSSY_COBBLESTONE,10,SMOOTH_BRICK:0,100)
RandomBlock(5,2,-2,SMOOTH_BRICK:1,10,SMOOTH_BRICK:2,10,COBBLESTONE,10,MOSSY_COBBLESTONE,10,SMOOTH_BRICK:0,100)
Block(1,2,-1,GRAVEL:0)
RandomBlock(-6,2,1,SMOOTH_BRICK:1,10,SMOOTH_BRICK:2,10,COBBLESTONE,10,MOSSY_COBBLESTONE,10,SMOOTH_BRICK:0,100)
RandomBlock(5,2,1,SMOOTH_BRICK:1,10,SMOOTH_BRICK:2,10,COBBLESTONE,10,MOSSY_COBBLESTONE,10,SMOOTH_BRICK:0,100)
Block(-4,2,2,GRAVEL:0)
RandomBlock(-4,2,3,SMOOTH_BRICK:1,10,SMOOTH_BRICK:2,10,COBBLESTONE,10,MOSSY_COBBLESTONE,10,SMOOTH_BRICK:0,100)
Block(2,2,3,GRAVEL:0)
RandomBlock(3,2,3,SMOOTH_BRICK:1,10,SMOOTH_BRICK:2,10,COBBLESTONE,10,MOSSY_COBBLESTONE,10,SMOOTH_BRICK:0,100)
Block(5,2,4,GRAVEL:0)
RandomBlock(-6,2,5,SMOOTH_BRICK:1,10,SMOOTH_BRICK:2,10,COBBLESTONE,10,MOSSY_COBBLESTONE,10,SMOOTH_BRICK:0,100)
RandomBlock(-2,2,5,SMOOTH_BRICK:1,10,SMOOTH_BRICK:2,10,COBBLESTONE,10,MOSSY_COBBLESTONE,10,SMOOTH_BRICK:0,100)
RandomBlock(1,2,5,SMOOTH_BRICK:1,10,SMOOTH_BRICK:2,10,COBBLESTONE,10,MOSSY_COBBLESTONE,10,SMOOTH_BRICK:0,100)
Block(3,2,5,GRAVEL:0)
RandomBlock(5,2,5,SMOOTH_BRICK:1,10,SMOOTH_BRICK:2,10,COBBLESTONE,10,MOSSY_COBBLESTONE,10,SMOOTH_BRICK:0,100)
Block(-4,2,6,GRAVEL:0)
RandomBlock(-2,3,-6,SMOOTH_BRICK:1,10,SMOOTH_BRICK:2,10,COBBLESTONE,10,MOSSY_COBBLESTONE,10,SMOOTH_BRICK:0,100)
RandomBlock(1,3,-6,SMOOTH_BRICK:1,10,SMOOTH_BRICK:2,10,COBBLESTONE,10,MOSSY_COBBLESTONE,10,SMOOTH_BRICK:0,100)
RandomBlock(5,3,-6,SMOOTH_BRICK:1,10,SMOOTH_BRICK:2,10,COBBLESTONE,10,MOSSY_COBBLESTONE,10,SMOOTH_BRICK:0,100)
RandomBlock(-4,3,-4,SMOOTH_BRICK:1,10,SMOOTH_BRICK:2,10,COBBLESTONE,10,MOSSY_COBBLESTONE,10,SMOOTH_BRICK:0,100)
RandomBlock(3,3,-4,SMOOTH_BRICK:1,10,SMOOTH_BRICK:2,10,COBBLESTONE,10,MOSSY_COBBLESTONE,10,SMOOTH_BRICK:0,100)
RandomBlock(-6,3,-2,SMOOTH_BRICK:1,10,SMOOTH_BRICK:2,10,COBBLESTONE,10,MOSSY_COBBLESTONE,10,SMOOTH_BRICK:0,100)
RandomBlock(-6,3,1,SMOOTH_BRICK:1,10,SMOOTH_BRICK:2,10,COBBLESTONE,10,MOSSY_COBBLESTONE,10,SMOOTH_BRICK:0,100)
RandomBlock(5,3,1,SMOOTH_BRICK:1,10,SMOOTH_BRICK:2,10,COBBLESTONE,10,MOSSY_COBBLESTONE,10,SMOOTH_BRICK:0,100)
RandomBlock(-4,3,3,SMOOTH_BRICK:1,10,SMOOTH_BRICK:2,10,COBBLESTONE,10,MOSSY_COBBLESTONE,10,SMOOTH_BRICK:0,100)
RandomBlock(3,3,3,SMOOTH_BRICK:1,10,SMOOTH_BRICK:2,10,COBBLESTONE,10,MOSSY_COBBLESTONE,10,SMOOTH_BRICK:0,100)
RandomBlock(-6,3,5,SMOOTH_BRICK:1,10,SMOOTH_BRICK:2,10,COBBLESTONE,10,MOSSY_COBBLESTONE,10,SMOOTH_BRICK:0,100)
RandomBlock(-2,3,5,SMOOTH_BRICK:1,10,SMOOTH_BRICK:2,10,COBBLESTONE,10,MOSSY_COBBLESTONE,10,SMOOTH_BRICK:0,100)
RandomBlock(1,3,5,SMOOTH_BRICK:1,10,SMOOTH_BRICK:2,10,COBBLESTONE,10,MOSSY_COBBLESTONE,10,SMOOTH_BRICK:0,100)
RandomBlock(5,3,5,SMOOTH_BRICK:1,10,SMOOTH_BRICK:2,10,COBBLESTONE,10,MOSSY_COBBLESTONE,10,SMOOTH_BRICK:0,100)
RandomBlock(-3,4,-3,SMOOTH_BRICK:1,10,SMOOTH_BRICK:2,10,COBBLESTONE,10,MOSSY_COBBLESTONE,10,SMOOTH_BRICK:0,100)
RandomBlock(2,4,-3,SMOOTH_BRICK:1,10,SMOOTH_BRICK:2,10,COBBLESTONE,10,MOSSY_COBBLESTONE,10,SMOOTH_BRICK:0,100)
RandomBlock(-2,4,-2,SMOOTH_BRICK:1,10,SMOOTH_BRICK:2,10,COBBLESTONE,10,MOSSY_COBBLESTONE,10,SMOOTH_BRICK:0,100)
RandomBlock(1,4,-2,SMOOTH_BRICK:1,10,SMOOTH_BRICK:2,10,COBBLESTONE,10,MOSSY_COBBLESTONE,10,SMOOTH_BRICK:0,100)
RandomBlock(-2,4,1,SMOOTH_BRICK:1,10,SMOOTH_BRICK:2,10,COBBLESTONE,10,MOSSY_COBBLESTONE,10,SMOOTH_BRICK:0,100)
RandomBlock(1,4,1,SMOOTH_BRICK:1,10,SMOOTH_BRICK:2,10,COBBLESTONE,10,MOSSY_COBBLESTONE,10,SMOOTH_BRICK:0,100)
RandomBlock(-3,4,2,SMOOTH_BRICK:1,10,SMOOTH_BRICK:2,10,COBBLESTONE,10,MOSSY_COBBLESTONE,10,SMOOTH_BRICK:0,100)
RandomBlock(2,4,2,SMOOTH_BRICK:1,10,SMOOTH_BRICK:2,10,COBBLESTONE,10,MOSSY_COBBLESTONE,10,SMOOTH_BRICK:0,100)
RandomBlock(-2,5,-2,SMOOTH_BRICK:1,10,SMOOTH_BRICK:2,10,COBBLESTONE,10,MOSSY_COBBLESTONE,10,SMOOTH_BRICK:0,100)
RandomBlock(1,5,-2,SMOOTH_BRICK:1,10,SMOOTH_BRICK:2,10,COBBLESTONE,10,MOSSY_COBBLESTONE,10,SMOOTH_BRICK:0,100)
RandomBlock(-2,5,1,SMOOTH_BRICK:1,10,SMOOTH_BRICK:2,10,COBBLESTONE,10,MOSSY_COBBLESTONE,10,SMOOTH_BRICK:0,100)
RandomBlock(1,5,1,SMOOTH_BRICK:1,10,SMOOTH_BRICK:2,10,COBBLESTONE,10,MOSSY_COBBLESTONE,10,SMOOTH_BRICK:0,100)
RandomBlock(-1,6,-2,SMOOTH_BRICK:1,10,SMOOTH_BRICK:2,10,COBBLESTONE,10,MOSSY_COBBLESTONE,10,SMOOTH_BRICK:0,100)
RandomBlock(0,6,-2,SMOOTH_BRICK:1,10,SMOOTH_BRICK:2,10,COBBLESTONE,10,MOSSY_COBBLESTONE,10,SMOOTH_BRICK:0,100)
RandomBlock(-2,6,-1,SMOOTH_BRICK:1,10,SMOOTH_BRICK:2,10,COBBLESTONE,10,MOSSY_COBBLESTONE,10,SMOOTH_BRICK:0,100)
RandomBlock(1,6,-1,SMOOTH_BRICK:1,10,SMOOTH_BRICK:2,10,COBBLESTONE,10,MOSSY_COBBLESTONE,10,SMOOTH_BRICK:0,100)
RandomBlock(-2,6,0,SMOOTH_BRICK:1,10,SMOOTH_BRICK:2,10,COBBLESTONE,10,MOSSY_COBBLESTONE,10,SMOOTH_BRICK:0,100)
RandomBlock(1,6,0,SMOOTH_BRICK:1,10,SMOOTH_BRICK:2,10,COBBLESTONE,10,MOSSY_COBBLESTONE,10,SMOOTH_BRICK:0,100)
RandomBlock(-1,6,1,SMOOTH_BRICK:1,10,SMOOTH_BRICK:2,10,COBBLESTONE,10,MOSSY_COBBLESTONE,10,SMOOTH_BRICK:0,100)
RandomBlock(0,6,1,SMOOTH_BRICK:1,10,SMOOTH_BRICK:2,10,COBBLESTONE,10,MOSSY_COBBLESTONE,10,SMOOTH_BRICK:0,100)
