Author: Bo3 BulkEdit
Description: Converted Schematic - Modified by Bo3BulkEdit - Bo3 Created by NLBlackEagle for Dregora
SettingsMode: WriteDisable
Frequency: 1
SpawnHeight: highestSolidBlock
UseCenterForHighestBlock: true
MinHeight: 0
MaxHeight: 255
InheritBO3: 
InheritBO3Rotation: NORTH
OverrideChildSettings: true
OverrideParentHeight: true
CanOverride: false
BranchFrequency: 0
BranchFrequencyGroup: 
MustBeBelowOther: false
MustBeInside: 
CannotBeInside: 
ReplacesBO3: 
MustBeInsideWorldBorders: false
CanSpawnOnWater: true
SpawnOnWaterOnly: false
SpawnUnderWater: false
SpawnAtWaterLevel: false
HeightOffset: 0
RemoveAir: true
ReplaceAbove: 
ReplaceBelow: 
ReplaceWithBiomeBlocks: true
ReplaceWithSurfaceBlock: GRASS
ReplaceWithGroundBlock: DIRT
ReplaceWithStoneBlock: STONE
SmoothRadius: 0
SmoothHeightOffset: 0
SmoothStartTop: false
SmoothStartWood: false
SmoothingSurfaceBlock: 
SmoothingGroundBlock: 
BO3Group: 
IsSpawnPoint: false
DoReplaceBlocks: true
Block(-2,0,-3,SAND:0)
Block(-1,0,-3,SAND:0)
Block(0,0,-3,SAND:0)
Block(-3,0,-2,SAND:0)
Block(-2,0,-2,SAND:0)
Block(-1,0,-2,SAND:0)
Block(0,0,-2,SAND:0)
Block(1,0,-2,SAND:0)
Block(-3,0,-1,SAND:0)
Block(-2,0,-1,SAND:0)
Block(-1,0,-1,SAND:0)
Block(0,0,-1,SAND:0)
Block(1,0,-1,SAND:0)
Block(2,0,-1,SAND:0)
Block(-2,0,0,SAND:0)
Block(-1,0,0,SAND:0)
Block(0,0,0,SAND:0)
Block(1,0,0,SAND:0)
Block(2,0,0,SAND:0)
Block(-2,0,1,SAND:0)
Block(-1,0,1,RED_SANDSTONE:0)
Block(0,0,1,SAND:0)
Block(1,0,1,SAND:0)
Block(2,0,1,SAND:0)
Block(-3,0,2,SAND:0)
Block(-2,0,2,SAND:0)
Block(-1,0,2,SAND:0)
Block(0,0,2,SAND:0)
Block(1,0,2,SAND:0)
Block(2,0,2,SAND:0)
Block(-3,0,3,SAND:0)
Block(-2,0,3,SAND:0)
Block(-1,0,3,SAND:0)
Block(0,0,3,SAND:0)
Block(-2,1,-2,SAND:0)
Block(-1,1,-2,SANDSTONE:1)
Block(1,1,-2,SANDSTONE:1)
Block(-2,1,-1,SANDSTONE:1)
Block(0,1,-1,SAND:0)
Block(1,1,-1,SAND:0)
Block(2,1,-1,SANDSTONE:1)
Block(-2,1,0,SANDSTONE:1)
Block(-1,1,0,SAND:0)
Block(0,1,0,SAND:0)
Block(1,1,0,SAND:0)
Block(2,1,0,SANDSTONE:1)
Block(-2,1,1,SANDSTONE:1)
Block(0,1,1,SAND:0)
RandomBlock(1,1,1,CHEST:3,../../../Chests/Loot/oceanruin_small.nbt,50,CHEST:3,../../../Chests/Traveler/Travelers_Castle.nbt,1,CHEST:3,../../../Chests/Traveler/Travelers_Church.nbt,1,CHEST:3,../../../Chests/Traveler/Travelers_Daeroc.nbt,1,CHEST:3,../../../Chests/Traveler/Travelers_Farmsteads.nbt,1,CHEST:3,../../../Chests/Traveler/Travelers_GreenDungeon.nbt,1,CHEST:3,../../../Chests/Traveler/Travelers_IceShips.nbt,1,CHEST:3,../../../Chests/Traveler/Travelers_IceTemple.nbt,1,CHEST:3,../../../Chests/Traveler/Travelers_LegacySpawn.nbt,1,CHEST:3,../../../Chests/Traveler/Travelers_Mineshafts.nbt,1,CHEST:3,../../../Chests/Traveler/Travelers_Mountains.nbt,1,CHEST:3,../../../Chests/Traveler/Travelers_Origin.nbt,1,CHEST:3,../../../Chests/Traveler/Travelers_Pirate.nbt,1,CHEST:3,../../../Chests/Traveler/Travelers_Quarry.nbt,1,CHEST:3,../../../Chests/Traveler/Travelers_Spook.nbt,1,CHEST:3,../../../Chests/Traveler/Travelers_Tribal.nbt,1)
Block(2,1,1,SANDSTONE:1)
Block(-2,1,2,SAND:0)
Block(-1,1,2,SANDSTONE:1)
Block(0,1,2,SANDSTONE:1)
Block(1,1,2,SANDSTONE:1)
Block(-2,1,3,SAND:0)
Block(-1,2,-2,SANDSTONE:1)
Block(1,2,-2,SANDSTONE:1)
Block(-2,2,-1,SANDSTONE:1)
Block(0,2,-1,SAND:0)
Block(2,2,-1,SANDSTONE:1)
Block(-2,2,0,RED_SANDSTONE:0)
Block(1,2,0,SAND:0)
Block(2,2,0,RED_SANDSTONE:0)
Block(-2,2,1,SANDSTONE:1)
Block(0,2,1,SAND:0)
Block(1,2,1,SAND:0)
Block(2,2,1,SANDSTONE:1)
Block(-2,2,2,SAND:0)
Block(-1,2,2,SANDSTONE:1)
Block(0,2,2,RED_SANDSTONE:0)
Block(1,2,2,SANDSTONE:1)
Block(-1,3,-2,SANDSTONE:1)
Block(0,3,-2,SANDSTONE:1)
Block(1,3,-2,SANDSTONE:1)
Block(-2,3,-1,SANDSTONE:1)
Block(2,3,-1,SANDSTONE:1)
Block(-2,3,0,SANDSTONE:1)
Block(2,3,0,SANDSTONE:1)
Block(-2,3,1,SANDSTONE:1)
Block(1,3,1,SAND:0)
Block(2,3,1,SANDSTONE:1)
Block(-1,3,2,SANDSTONE:1)
Block(0,3,2,SANDSTONE:1)
Block(1,3,2,SANDSTONE:1)
Block(-1,4,-1,SANDSTONE:1)
Block(0,4,-1,SANDSTONE:1)
Block(1,4,-1,SANDSTONE:1)
Block(-1,4,0,SANDSTONE:1)
Block(0,4,0,RED_SANDSTONE:0)
Block(1,4,0,SANDSTONE:1)
Block(-1,4,1,SANDSTONE:1)
Block(0,4,1,SANDSTONE:1)
Block(1,4,1,SANDSTONE:1)
