Author: NLBlackEagle
Description: No description given
SettingsMode: WriteDisable
Frequency: 0
SpawnHeight: highestBlock
UseCenterForHighestBlock: true
MinHeight: 0
MaxHeight: 255
InheritBO3: 
InheritBO3Rotation: NORTH
OverrideChildSettings: true
OverrideParentHeight: false
CanOverride: false
BranchFrequency: 0
BranchFrequencyGroup: 
MustBeBelowOther: false
MustBeInside: 
CannotBeInside: 
ReplacesBO3: 
MustBeInsideWorldBorders: false
CanSpawnOnWater: true
SpawnOnWaterOnly: false
SpawnUnderWater: false
SpawnAtWaterLevel: false
HeightOffset: 0
RemoveAir: false
ReplaceAbove: 
ReplaceBelow: 
ReplaceWithBiomeBlocks: false
ReplaceWithSurfaceBlock: GRASS
ReplaceWithGroundBlock: DIRT
ReplaceWithStoneBlock: STONE
SmoothRadius: 0
SmoothHeightOffset: 0
SmoothStartTop: false
SmoothStartWood: false
SmoothingSurfaceBlock: 
SmoothingGroundBlock: 
BO3Group: 
IsSpawnPoint: false
DoReplaceBlocks: false
Block(-8,-50,-7,STONE:5)
Block(-8,-50,-6,STONE:5)
Block(-8,-50,-5,STONE:5)
Block(-8,-50,-4,COBBLESTONE:0)
Block(-8,-50,-3,SMOOTH_BRICK:2)
Block(-8,-50,-2,STONE:5)
Block(-8,-49,-7,STONE:5)
Block(-8,-49,-6,STONE:5)
Block(-8,-49,-5,STONE:5)
Block(-8,-49,-4,COBBLESTONE:0)
Block(-8,-49,-3,SMOOTH_BRICK:2)
Block(-8,-49,-2,STONE:5)
Block(-8,-48,-7,STONE:5)
Block(-8,-48,-6,STONE:5)
Block(-8,-48,-5,STONE:5)
Block(-8,-48,-4,COBBLESTONE:0)
Block(-8,-48,-3,SMOOTH_BRICK:2)
Block(-8,-48,-2,STONE:5)
Block(-8,-47,-7,STONE:5)
Block(-8,-47,-6,STONE:5)
Block(-8,-47,-5,STONE:5)
Block(-8,-47,-4,COBBLESTONE:0)
Block(-8,-47,-3,SMOOTH_BRICK:2)
Block(-8,-47,-2,STONE:5)
Block(-8,-46,-7,STONE:5)
Block(-8,-46,-6,STONE:5)
Block(-8,-46,-5,STONE:5)
Block(-8,-46,-4,COBBLESTONE:0)
Block(-8,-46,-3,SMOOTH_BRICK:2)
Block(-8,-46,-2,STONE:5)
Block(-8,-45,-7,STONE:5)
Block(-8,-45,-6,STONE:5)
Block(-8,-45,-5,STONE:5)
Block(-8,-45,-4,COBBLESTONE:0)
Block(-8,-45,-3,SMOOTH_BRICK:2)
Block(-8,-45,-2,STONE:5)
Block(-8,-44,-7,STONE:5)
Block(-8,-44,-6,STONE:5)
Block(-8,-44,-5,STONE:5)
Block(-8,-44,-4,COBBLESTONE:0)
Block(-8,-44,-3,SMOOTH_BRICK:2)
Block(-8,-44,-2,STONE:5)
Block(-8,-43,-7,STONE:5)
Block(-8,-43,-6,STONE:5)
Block(-8,-43,-5,STONE:5)
Block(-8,-43,-4,COBBLESTONE:0)
Block(-8,-43,-3,SMOOTH_BRICK:2)
Block(-8,-43,-2,STONE:5)
Block(-8,-42,-7,STONE:5)
Block(-8,-42,-6,STONE:5)
Block(-8,-42,-5,STONE:5)
Block(-8,-42,-4,COBBLESTONE:0)
Block(-8,-42,-3,SMOOTH_BRICK:2)
Block(-8,-42,-2,STONE:5)
Block(-8,-41,-7,STONE:5)
Block(-8,-41,-6,STONE:5)
Block(-8,-41,-5,STONE:5)
Block(-8,-41,-4,COBBLESTONE:0)
Block(-8,-41,-3,SMOOTH_BRICK:2)
Block(-8,-41,-2,STONE:5)
Block(-8,-40,-7,STONE:5)
Block(-8,-40,-6,STONE:5)
Block(-8,-40,-5,STONE:5)
Block(-8,-40,-4,COBBLESTONE:0)
Block(-8,-40,-3,SMOOTH_BRICK:2)
Block(-8,-40,-2,STONE:5)
Block(-8,-39,-7,STONE:5)
Block(-8,-39,-6,STONE:5)
Block(-8,-39,-5,STONE:5)
Block(-8,-39,-4,COBBLESTONE:0)
Block(-8,-39,-3,SMOOTH_BRICK:2)
Block(-8,-39,-2,STONE:5)
Block(-8,-38,-7,STONE:5)
Block(-8,-38,-6,STONE:5)
Block(-8,-38,-5,STONE:5)
Block(-8,-38,-4,COBBLESTONE:0)
Block(-8,-38,-3,SMOOTH_BRICK:2)
Block(-8,-38,-2,STONE:5)
Block(-8,-37,-7,STONE:5)
Block(-8,-37,-6,STONE:5)
Block(-8,-37,-5,STONE:5)
Block(-8,-37,-4,COBBLESTONE:0)
Block(-8,-37,-3,SMOOTH_BRICK:2)
Block(-8,-37,-2,STONE:5)
Block(-8,-36,-7,STONE:5)
Block(-8,-36,-6,STONE:5)
Block(-8,-36,-5,STONE:5)
Block(-8,-36,-4,COBBLESTONE:0)
Block(-8,-36,-3,SMOOTH_BRICK:2)
Block(-8,-36,-2,STONE:5)
Block(-8,-35,-7,STONE:5)
Block(-8,-35,-6,STONE:5)
Block(-8,-35,-5,STONE:5)
Block(-8,-35,-4,COBBLESTONE:0)
Block(-8,-35,-3,SMOOTH_BRICK:2)
Block(-8,-35,-2,STONE:5)
Block(-8,-34,-7,STONE:5)
Block(-8,-34,-6,STONE:5)
Block(-8,-34,-5,STONE:5)
Block(-8,-34,-4,COBBLESTONE:0)
Block(-8,-34,-3,SMOOTH_BRICK:2)
Block(-8,-34,-2,STONE:5)
Block(-8,-33,-7,STONE:5)
Block(-8,-33,-6,STONE:5)
Block(-8,-33,-5,STONE:5)
Block(-8,-33,-4,COBBLESTONE:0)
Block(-8,-33,-3,SMOOTH_BRICK:2)
Block(-8,-33,-2,STONE:5)
Block(-8,-32,-7,STONE:5)
Block(-8,-32,-6,STONE:5)
Block(-8,-32,-5,STONE:5)
Block(-8,-32,-4,COBBLESTONE:0)
Block(-8,-32,-3,SMOOTH_BRICK:2)
Block(-8,-32,-2,STONE:5)
Block(-8,-31,-7,STONE:5)
Block(-8,-31,-6,STONE:5)
Block(-8,-31,-5,STONE:5)
Block(-8,-31,-4,COBBLESTONE:0)
Block(-8,-31,-3,SMOOTH_BRICK:2)
Block(-8,-31,-2,STONE:5)
Block(-8,-30,-7,STONE:5)
Block(-8,-30,-6,STONE:5)
Block(-8,-30,-5,STONE:5)
Block(-8,-30,-4,COBBLESTONE:0)
Block(-8,-30,-3,SMOOTH_BRICK:2)
Block(-8,-30,-2,STONE:5)
Block(-8,-29,-7,STONE:5)
Block(-8,-29,-6,STONE:5)
Block(-8,-29,-5,STONE:5)
Block(-8,-29,-4,COBBLESTONE:0)
Block(-8,-29,-3,SMOOTH_BRICK:2)
Block(-8,-29,-2,STONE:5)
Block(-8,-28,-7,STONE:5)
Block(-8,-28,-6,STONE:5)
Block(-8,-28,-5,STONE:5)
Block(-8,-28,-4,COBBLESTONE:0)
Block(-8,-28,-3,SMOOTH_BRICK:2)
Block(-8,-28,-2,STONE:5)
Block(-8,-27,-7,STONE:5)
Block(-8,-27,-6,STONE:5)
Block(-8,-27,-5,STONE:5)
Block(-8,-27,-4,COBBLESTONE:0)
Block(-8,-27,-3,SMOOTH_BRICK:2)
Block(-8,-27,-2,STONE:5)
Block(-8,-26,-7,STONE:5)
Block(-8,-26,-6,STONE:5)
Block(-8,-26,-5,STONE:5)
Block(-8,-26,-4,COBBLESTONE:0)
Block(-8,-26,-3,SMOOTH_BRICK:2)
Block(-8,-26,-2,STONE:5)
Block(-8,-25,-7,STONE:5)
Block(-8,-25,-6,STONE:5)
Block(-8,-25,-5,STONE:5)
Block(-8,-25,-4,COBBLESTONE:0)
Block(-8,-25,-3,SMOOTH_BRICK:2)
Block(-8,-25,-2,STONE:5)
Block(-8,-24,-7,STONE:5)
Block(-8,-24,-6,STONE:5)
Block(-8,-24,-5,STONE:5)
Block(-8,-24,-4,COBBLESTONE:0)
Block(-8,-24,-3,SMOOTH_BRICK:2)
Block(-8,-24,-2,STONE:5)
Block(-8,-23,-7,STONE:5)
Block(-8,-23,-6,STONE:5)
Block(-8,-23,-5,STONE:5)
Block(-8,-23,-4,COBBLESTONE:0)
Block(-8,-23,-3,SMOOTH_BRICK:2)
Block(-8,-23,-2,STONE:5)
Block(-8,-22,-7,STONE:5)
Block(-8,-22,-6,STONE:5)
Block(-8,-22,-5,STONE:5)
Block(-8,-22,-4,COBBLESTONE:0)
Block(-8,-22,-3,SMOOTH_BRICK:2)
Block(-8,-22,-2,STONE:5)
Block(-8,-21,-7,STONE:5)
Block(-8,-21,-6,STONE:5)
Block(-8,-21,-5,STONE:5)
Block(-8,-21,-4,COBBLESTONE:0)
Block(-8,-21,-3,SMOOTH_BRICK:2)
Block(-8,-21,-2,STONE:5)
Block(-8,-20,-7,STONE:5)
Block(-8,-20,-6,STONE:5)
Block(-8,-20,-5,STONE:5)
Block(-8,-20,-4,COBBLESTONE:0)
Block(-8,-20,-3,SMOOTH_BRICK:2)
Block(-8,-20,-2,STONE:5)
Block(-8,-19,-7,STONE:5)
Block(-8,-19,-6,COBBLESTONE:0)
Block(-8,-19,-5,STONE:5)
Block(-8,-19,-4,STONE:5)
Block(-8,-19,-3,COBBLESTONE:0)
Block(-8,-19,-2,SMOOTH_BRICK:1)
Block(-8,-18,-7,COBBLESTONE:0)
Block(-8,-18,-6,STONE:5)
Block(-8,-18,-5,COBBLESTONE:0)
Block(-8,-18,-4,COBBLESTONE:0)
Block(-8,-18,-3,STONE:5)
Block(-8,-18,-2,COBBLESTONE:0)
Block(-8,-17,-7,STONE:5)
Block(-8,-17,-6,COBBLESTONE:0)
Block(-8,-17,-5,SMOOTH_BRICK:2)
Block(-8,-17,-4,STONE:5)
Block(-8,-17,-3,SMOOTH_BRICK:1)
Block(-8,-17,-2,COBBLESTONE:0)
Block(-8,-16,-7,STONE:5)
Block(-8,-16,-6,COBBLESTONE:0)
Block(-8,-16,-5,COBBLESTONE:0)
Block(-8,-16,-4,COBBLESTONE:0)
Block(-8,-16,-3,COBBLESTONE:0)
Block(-8,-16,-2,COBBLESTONE:0)
Block(-8,-15,-7,SMOOTH_BRICK:1)
Block(-8,-15,-6,STONE:5)
Block(-8,-15,-5,SMOOTH_BRICK:1)
Block(-8,-15,-4,COBBLESTONE:0)
Block(-8,-15,-3,COBBLESTONE:0)
Block(-8,-15,-2,COBBLESTONE:0)
Block(-8,-14,-7,COBBLESTONE:0)
Block(-8,-14,-6,COBBLESTONE:0)
Block(-8,-14,-5,COBBLESTONE:0)
Block(-8,-14,-4,STONE:5)
Block(-8,-14,-3,STAINED_CLAY:9)
Block(-8,-14,-2,STONE:5)
Block(-8,-13,-7,COBBLESTONE:0)
Block(-8,-13,-6,STONE:5)
Block(-8,-13,-5,STAINED_CLAY:9)
Block(-8,-13,-4,STONE:5)
Block(-8,-13,-3,SMOOTH_BRICK:2)
Block(-8,-13,-2,STONE:5)
Block(-8,-12,-7,SMOOTH_BRICK:2)
Block(-8,-12,-6,STONE:5)
Block(-8,-12,-5,STONE:5)
Block(-8,-12,-4,STAINED_CLAY:9)
Block(-8,-12,-3,STONE:5)
Block(-8,-12,-2,COBBLESTONE:0)
Block(-8,-11,-7,COBBLESTONE:0)
Block(-8,-11,-6,COBBLESTONE:0)
Block(-8,-11,-5,STONE:5)
Block(-8,-11,-4,COBBLESTONE:0)
Block(-8,-11,-3,STONE:5)
Block(-8,-11,-2,SMOOTH_BRICK:0)
Block(-8,-10,-7,SMOOTH_BRICK:0)
Block(-8,-10,-6,STONE:5)
Block(-8,-10,-5,STONE:5)
Block(-8,-10,-4,COBBLESTONE:0)
Block(-8,-10,-3,COBBLESTONE:0)
Block(-8,-10,-2,STONE:5)
Block(-8,-9,-7,STONE:6)
Block(-8,-9,-6,STONE:6)
Block(-8,-9,-5,STONE:6)
Block(-8,-9,-4,STONE:6)
Block(-8,-9,-3,STONE:6)
Block(-8,-9,-2,COBBLESTONE_STAIRS:3)
Block(-8,-8,-7,STONE:6)
Block(-8,-8,-6,STONE:6)
Block(-8,-8,-5,STONE:6)
Block(-8,-8,-4,STONE:6)
Block(-8,-8,-3,STONE:6)
Block(-8,-7,-7,STONE:6)
Block(-8,-7,-6,STONE:6)
Block(-8,-7,-5,STONE:6)
Block(-8,-7,-4,STONE:6)
Block(-8,-7,-3,STONE:6)
Block(-8,-6,-7,STONE:6)
Block(-8,-6,-6,STONE:6)
Block(-8,-6,-5,STONE:6)
Block(-8,-6,-4,STONE:6)
Block(-8,-6,-3,STONE:6)
Block(-8,-5,-7,STONE:5)
Block(-8,-5,-6,STONE:5)
Block(-8,-5,-5,STONE:5)
Block(-8,-5,-4,STONE:5)
Block(-8,-5,-3,COBBLESTONE_STAIRS:3)
Block(-8,-4,-7,STONE:6)
Block(-8,-4,-6,STONE:6)
Block(-8,-4,-5,STONE:6)
Block(-8,-4,-4,STONE:6)
Block(-8,-3,-7,STONE:6)
Block(-8,-3,-6,STONE:6)
Block(-8,-3,-5,STONE:6)
Block(-8,-3,-4,STONE:6)
Block(-8,-2,-7,STONE:6)
Block(-8,-2,-6,STONE:6)
Block(-8,-2,-5,STONE:6)
Block(-8,-2,-4,STONE:6)
Block(-8,-1,-7,STONE:6)
Block(-8,-1,-6,STONE:6)
Block(-8,-1,-5,STONE:6)
Block(-8,-1,-4,STONE:6)
Block(-8,0,-7,STONE:6)
Block(-8,0,-6,STONE:6)
Block(-8,0,-5,STONE:6)
Block(-8,0,-4,STONE:6)
Block(-8,1,-7,COBBLESTONE:0)
Block(-8,1,-6,SMOOTH_BRICK:1)
Block(-8,1,-5,COBBLESTONE:0)
Block(-8,1,-4,STONE:5)
Block(-8,2,-7,SMOOTH_BRICK:0)
Block(-8,2,-6,SMOOTH_BRICK:0)
Block(-8,2,-5,SMOOTH_BRICK:0)
Block(-8,2,-4,SMOOTH_BRICK:0)
Block(-8,3,-7,COBBLESTONE:0)
Block(-8,3,-6,STONE:5)
Block(-8,3,-5,SMOOTH_BRICK:2)
Block(-8,3,-4,COBBLESTONE_STAIRS:3)
Block(-8,4,-7,STONE:6)
Block(-8,4,-6,STONE:6)
Block(-8,4,-5,STONE:6)
Block(-8,4,-4,AIR:0)
Block(-8,5,-7,STONE:6)
Block(-8,5,-6,STONE:6)
Block(-8,5,-5,STONE:6)
Block(-8,5,-4,AIR:0)
Block(-8,6,-7,STONE:5)
Block(-8,6,-6,COBBLESTONE:0)
Block(-8,6,-5,STONE:6)
Block(-8,6,-4,AIR:0)
Block(-8,7,-7,CARPET:8)
Block(-8,7,-6,SPRUCE_WOOD_STAIRS:6)
Block(-8,7,-5,STONE:6)
Block(-8,7,-4,AIR:0)
Block(-8,8,-7,AIR:0)
RandomBlock(-8,8,-6,AIR:0,20,CHEST:2,../../../Chests/Loot/JunkChest_1.nbt,10,CHEST:2,../../../Chests/Loot/JunkChest_2.nbt,10,CHEST:2,../../../Chests/Loot/JunkChest_3.nbt,10,CHEST:2,../../../Chests/Loot/JunkChest_4.nbt,10,CHEST:2,../../../Chests/Loot/JunkChest_5.nbt,10,CHEST:2,../../../Chests/Lore/medievalcity_1.nbt,1,CHEST:2,../../../Chests/Lore/medievalcity_2.nbt,1,CHEST:2,../../../Chests/Lore/medievalcity_3.nbt,1,CHEST:2,../../../Chests/Lore/medievalcity_4.nbt,1,CHEST:2,../../../Chests/Lore/medievalcity_5.nbt,1,CHEST:2,../../../Chests/Loot/Common1.nbt,10,CHEST:2,../../../Chests/Loot/Common2.nbt,10,CHEST:2,../../../Chests/Loot/Common3.nbt,10,CHEST:2,../../../Chests/Loot/Common4.nbt,10,CHEST:2,../../../Chests/Loot/Common5.nbt,10,CHEST:2,../../../Chests/Loot/Common6.nbt,10,CHEST:2,../../../Chests/Loot/Common7.nbt,10,CHEST:2,../../../Chests/Loot/Common8.nbt,10,CHEST:2,../../../Chests/Loot/Common9.nbt,10,CHEST:2,../../../Chests/Loot/Common10.nbt,10,CHEST:2,../../../Chests/Loot/Common10.nbt,11,CHEST:2,../../../Chests/Loot/Common12.nbt,10,CHEST:2,../../../Chests/Loot/Common13.nbt,10,CHEST:2,../../../Chests/Loot/Common14.nbt,10,CHEST:2,../../../Chests/Loot/Common15.nbt,10,CHEST:2,../../../Chests/Lore/medievalcity_1.nbt,2,CHEST:2,../../../Chests/Lore/medievalcity_3.nbt,2,CHEST:2,../../../Chests/Lore/medievalcity_4.nbt,2,CHEST:2,../../../Chests/Lore/medievalcity_5.nbt,2,CHEST:2,../../../Chests/Lore/medievalcity_5.nbt,2,CHEST:2,../../../Chests/Loot/Rare1.nbt,5,CHEST:2,../../../Chests/Loot/Rare2.nbt,5,CHEST:2,../../../Chests/Loot/Rare3.nbt,5,CHEST:2,../../../Chests/Loot/Rare4.nbt,5,CHEST:2,../../../Chests/Loot/Rare5.nbt,5,CHEST:2,../../../Chests/Loot/Rare6.nbt,5,CHEST:2,../../../Chests/Loot/Rare7.nbt,5,CHEST:2,../../../Chests/Loot/Rare8.nbt,5,CHEST:2,../../../Chests/Loot/Rare9.nbt,5,CHEST:2,../../../Chests/Loot/Rare10.nbt,5,CHEST:2,../../../Chests/Loot/Rare11.nbt,5,CHEST:2,../../../Chests/Loot/Rare12.nbt,5,CHEST:2,../../../Chests/Loot/Rare13.nbt,5,CHEST:2,../../../Chests/Loot/Rare14.nbt,5,CHEST:2,../../../Chests/Loot/Rare15.nbt,5,CHEST:2,../../../Chests/Loot/Epic1.nbt,2,CHEST:2,../../../Chests/Loot/Epic2.nbt,2,CHEST:2,../../../Chests/Loot/Epic3.nbt,2,CHEST:2,../../../Chests/Loot/Epic4.nbt,2,CHEST:2,../../../Chests/Loot/Epic5.nbt,2,CHEST:2,../../../Chests/Loot/Epic6.nbt,2,CHEST:2,../../../Chests/Loot/Epic7.nbt,2,CHEST:2,../../../Chests/Loot/Epic8.nbt,2,CHEST:2,../../../Chests/Loot/Epic9.nbt,2,CHEST:2,../../../Chests/Loot/Epic10.nbt,2,CHEST:2,../../../Chests/Loot/Epic11.nbt,2,CHEST:2,../../../Chests/Loot/Epic12.nbt,2,CHEST:2,../../../Chests/Loot/Epic13.nbt,2,CHEST:2,../../../Chests/Loot/Epic14.nbt,2,CHEST:2,../../../Chests/Loot/Epic15.nbt,5,CHEST:2,../../../Chests/Loot/Rare1.nbt,5,CHEST:2,../../../Chests/Loot/Rare2.nbt,5,CHEST:2,../../../Chests/Loot/Rare3.nbt,5,CHEST:2,../../../Chests/Loot/Rare4.nbt,5,CHEST:2,../../../Chests/Loot/Rare5.nbt,10,CHEST:2,../../../Chests/Loot/Rare6.nbt,10,CHEST:2,../../../Chests/Loot/Rare7.nbt,10,CHEST:2,../../../Chests/Loot/Rare8.nbt,10,CHEST:2,../../../Chests/Loot/Rare9.nbt,10,CHEST:2,../../../Chests/Loot/Rare10.nbt,15,CHEST:2,../../../Chests/Loot/Rare11.nbt,15,CHEST:2,../../../Chests/Loot/Rare12.nbt,15,CHEST:2,../../../Chests/Loot/Rare13.nbt,15,CHEST:2,../../../Chests/Loot/Rare14.nbt,15,CHEST:2,../../../Chests/Loot/Rare15.nbt,15,CHEST:2,../../../Chests/Loot/Epic15.nbt,100)
Block(-8,8,-5,STONE:6)
Block(-8,8,-4,AIR:0)
Block(-8,9,-7,AIR:0)
Block(-8,9,-6,AIR:0)
Block(-8,9,-5,STONE:6)
Block(-8,9,-4,AIR:0)
Block(-8,10,-7,AIR:0)
Block(-8,10,-6,AIR:0)
Block(-8,10,-5,COBBLESTONE:0)
Block(-8,10,-4,AIR:0)
Block(-8,11,-7,LOG:4)
Block(-8,11,-6,WOOD_STEP:13)
Block(-8,11,-5,COBBLESTONE:0)
Block(-8,11,-4,AIR:0)
Block(-8,12,-7,AIR:0)
Block(-8,12,-6,WORKBENCH:0)
Block(-8,12,-5,COBBLESTONE:0)
Block(-8,12,-4,AIR:0)
Block(-8,13,-7,AIR:0)
Block(-8,13,-6,AIR:0)
Block(-8,13,-5,COBBLESTONE:0)
Block(-8,13,-4,AIR:0)
Block(-8,14,-7,AIR:0)
Block(-8,14,-6,COBBLESTONE_STAIRS:4)
Block(-8,14,-5,LOG:4)
Block(-8,14,-4,AIR:0)
Block(-8,15,-7,LOG:4)
Block(-8,15,-6,COBBLESTONE:0)
Block(-8,15,-5,SMOOTH_STAIRS:7)
Block(-8,15,-4,AIR:0)
Block(-8,16,-7,STONE:6)
Block(-8,16,-6,COBBLESTONE:0)
Block(-8,16,-5,WOOD:5)
Block(-8,16,-4,AIR:0)
Block(-8,17,-7,LOG:4)
Block(-8,17,-6,WOOD_STEP:13)
Block(-8,17,-5,SMOOTH_BRICK:0)
Block(-8,17,-4,AIR:0)
Block(-8,18,-7,AIR:0)
Block(-8,18,-6,AIR:0)
Block(-8,18,-5,SMOOTH_BRICK:0)
Block(-8,18,-4,AIR:0)
Block(-8,19,-7,AIR:0)
Block(-8,19,-6,AIR:0)
Block(-8,19,-5,SMOOTH_BRICK:0)
Block(-8,19,-4,AIR:0)
Block(-8,20,-7,AIR:0)
Block(-8,20,-6,AIR:0)
Block(-8,20,-5,SMOOTH_BRICK:0)
Block(-8,20,-4,AIR:0)
Block(-8,21,-7,WOOD_STEP:13)
Block(-8,21,-6,LOG:4)
Block(-8,21,-5,COBBLESTONE:0)
Block(-8,21,-4,COBBLESTONE_STAIRS:7)
Block(-8,22,-7,AIR:0)
Block(-8,22,-6,AIR:0)
Block(-8,22,-5,COBBLESTONE:0)
Block(-8,22,-4,WOOD:5)
Block(-8,23,-7,AIR:0)
Block(-8,23,-6,AIR:0)
Block(-8,23,-5,STEP:0)
Block(-8,23,-4,STEP:0)
Block(-8,24,-7,DARK_OAK_STAIRS:3)
Block(-8,24,-6,AIR:0)
Block(-8,24,-5,AIR:0)
Block(-8,24,-4,AIR:0)
Block(-8,25,-7,AIR:0)
Block(-8,25,-6,AIR:0)
Block(-8,25,-5,AIR:0)
Block(-8,25,-4,AIR:0)
Block(-8,26,-7,AIR:0)
Block(-8,26,-6,AIR:0)
Block(-8,26,-5,AIR:0)
Block(-8,26,-4,AIR:0)
Block(-8,27,-7,AIR:0)
Block(-8,27,-6,AIR:0)
Block(-8,27,-5,AIR:0)
Block(-8,27,-4,AIR:0)
Block(-8,28,-7,AIR:0)
Block(-8,28,-6,AIR:0)
Block(-8,28,-5,AIR:0)
Block(-8,28,-4,AIR:0)
Block(-8,29,-7,AIR:0)
Block(-8,29,-6,AIR:0)
Block(-8,29,-5,AIR:0)
Block(-8,29,-4,AIR:0)
Block(-8,30,-7,AIR:0)
Block(-8,30,-6,AIR:0)
Block(-8,30,-5,AIR:0)
Block(-8,30,-4,AIR:0)
Block(-8,31,-7,AIR:0)
Block(-8,31,-6,AIR:0)
Block(-8,31,-5,AIR:0)
Block(-8,31,-4,AIR:0)
Block(-8,32,-7,AIR:0)
Block(-8,32,-6,AIR:0)
Block(-8,32,-5,AIR:0)
Block(-8,32,-4,AIR:0)
Block(-8,33,-7,AIR:0)
Block(-8,33,-6,AIR:0)
Block(-8,33,-5,AIR:0)
Block(-8,33,-4,AIR:0)
Block(-8,34,-7,AIR:0)
Block(-8,34,-6,AIR:0)
Block(-8,34,-5,AIR:0)
Block(-8,34,-4,AIR:0)
Block(-8,35,-7,AIR:0)
Block(-8,35,-6,AIR:0)
Block(-8,35,-5,AIR:0)
Block(-8,35,-4,AIR:0)
Block(-8,36,-7,AIR:0)
Block(-8,36,-6,AIR:0)
Block(-8,36,-5,AIR:0)
Block(-8,36,-4,AIR:0)
Block(-8,37,-7,AIR:0)
Block(-8,37,-6,AIR:0)
Block(-8,37,-5,AIR:0)
Block(-8,37,-4,AIR:0)
Block(-8,38,-7,AIR:0)
Block(-8,38,-6,AIR:0)
Block(-8,38,-5,AIR:0)
Block(-8,38,-4,AIR:0)
Block(-8,39,-7,AIR:0)
Block(-8,39,-6,AIR:0)
Block(-8,39,-5,AIR:0)
Block(-8,39,-4,AIR:0)
Block(-8,40,-7,AIR:0)
Block(-8,40,-6,AIR:0)
Block(-8,40,-5,AIR:0)
Block(-8,40,-4,AIR:0)
Block(-8,41,-7,AIR:0)
Block(-8,41,-6,AIR:0)
Block(-8,41,-5,AIR:0)
Block(-8,41,-4,AIR:0)
Block(-8,42,-7,AIR:0)
Block(-8,42,-6,AIR:0)
Block(-8,42,-5,AIR:0)
Block(-8,42,-4,AIR:0)
Block(-8,43,-7,AIR:0)
Block(-8,43,-6,AIR:0)
Block(-8,43,-5,AIR:0)
Block(-8,43,-4,AIR:0)
Block(-8,44,-7,AIR:0)
Block(-8,44,-6,AIR:0)
Block(-8,44,-5,AIR:0)
Block(-8,44,-4,AIR:0)
Block(-8,45,-7,AIR:0)
Block(-8,45,-6,AIR:0)
Block(-8,45,-5,AIR:0)
Block(-8,45,-4,AIR:0)
Block(-8,46,-7,AIR:0)
Block(-8,46,-6,AIR:0)
Block(-8,46,-5,AIR:0)
Block(-8,46,-4,AIR:0)
Block(-8,47,-7,AIR:0)
Block(-8,47,-6,AIR:0)
Block(-8,47,-5,AIR:0)
Block(-8,47,-4,AIR:0)
Block(-8,48,-7,AIR:0)
Block(-8,48,-6,AIR:0)
Block(-8,48,-5,AIR:0)
Block(-8,48,-4,AIR:0)
Block(-8,49,-7,AIR:0)
Block(-8,49,-6,AIR:0)
Block(-8,49,-5,AIR:0)
Block(-8,49,-4,AIR:0)
Block(-8,50,-7,AIR:0)
Block(-8,50,-6,AIR:0)
Block(-8,50,-5,AIR:0)
Block(-8,50,-4,AIR:0)
Block(-8,51,-7,AIR:0)
Block(-8,51,-6,AIR:0)
Block(-8,51,-5,AIR:0)
Block(-8,51,-4,AIR:0)
Block(-8,52,-7,AIR:0)
Block(-8,52,-6,AIR:0)
Block(-8,52,-5,AIR:0)
Block(-8,52,-4,AIR:0)
Block(-8,53,-7,AIR:0)
Block(-8,53,-6,AIR:0)
Block(-8,53,-5,AIR:0)
Block(-8,53,-4,AIR:0)
Block(-8,54,-7,AIR:0)
Block(-8,54,-6,AIR:0)
Block(-8,54,-5,AIR:0)
Block(-8,54,-4,AIR:0)
Block(-8,55,-7,AIR:0)
Block(-8,55,-6,AIR:0)
Block(-8,55,-5,AIR:0)
Block(-8,55,-4,AIR:0)
Block(-8,56,-7,AIR:0)
Block(-8,56,-6,AIR:0)
Block(-8,56,-5,AIR:0)
Block(-8,56,-4,AIR:0)
Block(-8,57,-7,AIR:0)
Block(-8,57,-6,AIR:0)
Block(-8,57,-5,AIR:0)
Block(-8,57,-4,AIR:0)
Block(-8,58,-7,AIR:0)
Block(-8,58,-6,AIR:0)
Block(-8,58,-5,AIR:0)
Block(-8,58,-4,AIR:0)
Block(-8,59,-7,AIR:0)
Block(-8,59,-6,AIR:0)
Block(-8,59,-5,AIR:0)
Block(-8,59,-4,AIR:0)
Block(-8,60,-7,AIR:0)
Block(-8,60,-6,AIR:0)
Block(-8,60,-5,AIR:0)
Block(-8,60,-4,AIR:0)
Block(-8,61,-7,AIR:0)
Block(-8,61,-6,AIR:0)
Block(-8,61,-5,AIR:0)
Block(-8,61,-4,AIR:0)
Block(-8,62,-7,AIR:0)
Block(-8,62,-6,AIR:0)
Block(-8,62,-5,AIR:0)
Block(-8,62,-4,AIR:0)
Block(-8,63,-7,AIR:0)
Block(-8,63,-6,AIR:0)
Block(-8,63,-5,AIR:0)
Block(-8,63,-4,AIR:0)
Block(-7,-50,-7,STONE:5)
Block(-7,-50,-6,STONE:5)
Block(-7,-50,-5,COBBLESTONE:0)
Block(-7,-50,-4,STONE:5)
Block(-7,-50,-3,COBBLESTONE:0)
Block(-7,-50,-2,LOG:0)
Block(-7,-49,-7,STONE:5)
Block(-7,-49,-6,STONE:5)
Block(-7,-49,-5,COBBLESTONE:0)
Block(-7,-49,-4,STONE:5)
Block(-7,-49,-3,COBBLESTONE:0)
Block(-7,-49,-2,LOG:0)
Block(-7,-48,-7,STONE:5)
Block(-7,-48,-6,STONE:5)
Block(-7,-48,-5,COBBLESTONE:0)
Block(-7,-48,-4,STONE:5)
Block(-7,-48,-3,COBBLESTONE:0)
Block(-7,-48,-2,LOG:0)
Block(-7,-47,-7,STONE:5)
Block(-7,-47,-6,STONE:5)
Block(-7,-47,-5,COBBLESTONE:0)
Block(-7,-47,-4,STONE:5)
Block(-7,-47,-3,COBBLESTONE:0)
Block(-7,-47,-2,LOG:0)
Block(-7,-46,-7,STONE:5)
Block(-7,-46,-6,STONE:5)
Block(-7,-46,-5,COBBLESTONE:0)
Block(-7,-46,-4,STONE:5)
Block(-7,-46,-3,COBBLESTONE:0)
Block(-7,-46,-2,LOG:0)
Block(-7,-45,-7,STONE:5)
Block(-7,-45,-6,STONE:5)
Block(-7,-45,-5,COBBLESTONE:0)
Block(-7,-45,-4,STONE:5)
Block(-7,-45,-3,COBBLESTONE:0)
Block(-7,-45,-2,LOG:0)
Block(-7,-44,-7,STONE:5)
Block(-7,-44,-6,STONE:5)
Block(-7,-44,-5,COBBLESTONE:0)
Block(-7,-44,-4,STONE:5)
Block(-7,-44,-3,COBBLESTONE:0)
Block(-7,-44,-2,LOG:0)
Block(-7,-43,-7,STONE:5)
Block(-7,-43,-6,STONE:5)
Block(-7,-43,-5,COBBLESTONE:0)
Block(-7,-43,-4,STONE:5)
Block(-7,-43,-3,COBBLESTONE:0)
Block(-7,-43,-2,LOG:0)
Block(-7,-42,-7,STONE:5)
Block(-7,-42,-6,STONE:5)
Block(-7,-42,-5,COBBLESTONE:0)
Block(-7,-42,-4,STONE:5)
Block(-7,-42,-3,COBBLESTONE:0)
Block(-7,-42,-2,LOG:0)
Block(-7,-41,-7,STONE:5)
Block(-7,-41,-6,STONE:5)
Block(-7,-41,-5,COBBLESTONE:0)
Block(-7,-41,-4,STONE:5)
Block(-7,-41,-3,COBBLESTONE:0)
Block(-7,-41,-2,LOG:0)
Block(-7,-40,-7,STONE:5)
Block(-7,-40,-6,STONE:5)
Block(-7,-40,-5,COBBLESTONE:0)
Block(-7,-40,-4,STONE:5)
Block(-7,-40,-3,COBBLESTONE:0)
Block(-7,-40,-2,LOG:0)
Block(-7,-39,-7,STONE:5)
Block(-7,-39,-6,STONE:5)
Block(-7,-39,-5,COBBLESTONE:0)
Block(-7,-39,-4,STONE:5)
Block(-7,-39,-3,COBBLESTONE:0)
Block(-7,-39,-2,LOG:0)
Block(-7,-38,-7,STONE:5)
Block(-7,-38,-6,STONE:5)
Block(-7,-38,-5,COBBLESTONE:0)
Block(-7,-38,-4,STONE:5)
Block(-7,-38,-3,COBBLESTONE:0)
Block(-7,-38,-2,LOG:0)
Block(-7,-37,-7,STONE:5)
Block(-7,-37,-6,STONE:5)
Block(-7,-37,-5,COBBLESTONE:0)
Block(-7,-37,-4,STONE:5)
Block(-7,-37,-3,COBBLESTONE:0)
Block(-7,-37,-2,LOG:0)
Block(-7,-36,-7,STONE:5)
Block(-7,-36,-6,STONE:5)
Block(-7,-36,-5,COBBLESTONE:0)
Block(-7,-36,-4,STONE:5)
Block(-7,-36,-3,COBBLESTONE:0)
Block(-7,-36,-2,LOG:0)
Block(-7,-35,-7,STONE:5)
Block(-7,-35,-6,STONE:5)
Block(-7,-35,-5,COBBLESTONE:0)
Block(-7,-35,-4,STONE:5)
Block(-7,-35,-3,COBBLESTONE:0)
Block(-7,-35,-2,LOG:0)
Block(-7,-34,-7,STONE:5)
Block(-7,-34,-6,STONE:5)
Block(-7,-34,-5,COBBLESTONE:0)
Block(-7,-34,-4,STONE:5)
Block(-7,-34,-3,COBBLESTONE:0)
Block(-7,-34,-2,LOG:0)
Block(-7,-33,-7,STONE:5)
Block(-7,-33,-6,STONE:5)
Block(-7,-33,-5,COBBLESTONE:0)
Block(-7,-33,-4,STONE:5)
Block(-7,-33,-3,COBBLESTONE:0)
Block(-7,-33,-2,LOG:0)
Block(-7,-32,-7,STONE:5)
Block(-7,-32,-6,STONE:5)
Block(-7,-32,-5,COBBLESTONE:0)
Block(-7,-32,-4,STONE:5)
Block(-7,-32,-3,COBBLESTONE:0)
Block(-7,-32,-2,LOG:0)
Block(-7,-31,-7,STONE:5)
Block(-7,-31,-6,STONE:5)
Block(-7,-31,-5,COBBLESTONE:0)
Block(-7,-31,-4,STONE:5)
Block(-7,-31,-3,COBBLESTONE:0)
Block(-7,-31,-2,LOG:0)
Block(-7,-30,-7,STONE:5)
Block(-7,-30,-6,STONE:5)
Block(-7,-30,-5,COBBLESTONE:0)
Block(-7,-30,-4,STONE:5)
Block(-7,-30,-3,COBBLESTONE:0)
Block(-7,-30,-2,LOG:0)
Block(-7,-29,-7,STONE:5)
Block(-7,-29,-6,STONE:5)
Block(-7,-29,-5,COBBLESTONE:0)
Block(-7,-29,-4,STONE:5)
Block(-7,-29,-3,COBBLESTONE:0)
Block(-7,-29,-2,LOG:0)
Block(-7,-28,-7,STONE:5)
Block(-7,-28,-6,STONE:5)
Block(-7,-28,-5,COBBLESTONE:0)
Block(-7,-28,-4,STONE:5)
Block(-7,-28,-3,COBBLESTONE:0)
Block(-7,-28,-2,LOG:0)
Block(-7,-27,-7,STONE:5)
Block(-7,-27,-6,STONE:5)
Block(-7,-27,-5,COBBLESTONE:0)
Block(-7,-27,-4,STONE:5)
Block(-7,-27,-3,COBBLESTONE:0)
Block(-7,-27,-2,LOG:0)
Block(-7,-26,-7,STONE:5)
Block(-7,-26,-6,STONE:5)
Block(-7,-26,-5,COBBLESTONE:0)
Block(-7,-26,-4,STONE:5)
Block(-7,-26,-3,COBBLESTONE:0)
Block(-7,-26,-2,LOG:0)
Block(-7,-25,-7,STONE:5)
Block(-7,-25,-6,STONE:5)
Block(-7,-25,-5,COBBLESTONE:0)
Block(-7,-25,-4,STONE:5)
Block(-7,-25,-3,COBBLESTONE:0)
Block(-7,-25,-2,LOG:0)
Block(-7,-24,-7,STONE:5)
Block(-7,-24,-6,STONE:5)
Block(-7,-24,-5,COBBLESTONE:0)
Block(-7,-24,-4,STONE:5)
Block(-7,-24,-3,COBBLESTONE:0)
Block(-7,-24,-2,LOG:0)
Block(-7,-23,-7,STONE:5)
Block(-7,-23,-6,STONE:5)
Block(-7,-23,-5,COBBLESTONE:0)
Block(-7,-23,-4,STONE:5)
Block(-7,-23,-3,COBBLESTONE:0)
Block(-7,-23,-2,LOG:0)
Block(-7,-22,-7,STONE:5)
Block(-7,-22,-6,STONE:5)
Block(-7,-22,-5,COBBLESTONE:0)
Block(-7,-22,-4,STONE:5)
Block(-7,-22,-3,COBBLESTONE:0)
Block(-7,-22,-2,LOG:0)
Block(-7,-21,-7,STONE:5)
Block(-7,-21,-6,STONE:5)
Block(-7,-21,-5,COBBLESTONE:0)
Block(-7,-21,-4,STONE:5)
Block(-7,-21,-3,COBBLESTONE:0)
Block(-7,-21,-2,LOG:0)
Block(-7,-20,-7,STONE:5)
Block(-7,-20,-6,STONE:5)
Block(-7,-20,-5,COBBLESTONE:0)
Block(-7,-20,-4,STONE:5)
Block(-7,-20,-3,COBBLESTONE:0)
Block(-7,-20,-2,LOG:0)
Block(-7,-19,-7,STONE:5)
Block(-7,-19,-6,SMOOTH_BRICK:2)
Block(-7,-19,-5,COBBLESTONE:0)
Block(-7,-19,-4,SMOOTH_BRICK:2)
Block(-7,-19,-3,STONE:5)
Block(-7,-19,-2,LOG:0)
Block(-7,-18,-7,STONE:5)
Block(-7,-18,-6,COBBLESTONE:0)
Block(-7,-18,-5,COBBLESTONE:0)
Block(-7,-18,-4,STONE:5)
Block(-7,-18,-3,STONE:5)
Block(-7,-18,-2,LOG:0)
Block(-7,-17,-7,SMOOTH_BRICK:1)
Block(-7,-17,-6,STONE:5)
Block(-7,-17,-5,COBBLESTONE:0)
Block(-7,-17,-4,SMOOTH_BRICK:1)
Block(-7,-17,-3,SMOOTH_BRICK:1)
Block(-7,-17,-2,LOG:0)
Block(-7,-16,-7,COBBLESTONE:0)
Block(-7,-16,-6,COBBLESTONE:0)
Block(-7,-16,-5,COBBLESTONE:0)
Block(-7,-16,-4,STONE:5)
Block(-7,-16,-3,STONE:5)
Block(-7,-16,-2,LOG:0)
Block(-7,-15,-7,STONE:5)
Block(-7,-15,-6,COBBLESTONE:0)
Block(-7,-15,-5,STONE:5)
Block(-7,-15,-4,STONE:5)
Block(-7,-15,-3,SMOOTH_BRICK:2)
Block(-7,-15,-2,LOG:0)
Block(-7,-14,-7,STONE:5)
Block(-7,-14,-6,COBBLESTONE:0)
Block(-7,-14,-5,COBBLESTONE:0)
Block(-7,-14,-4,STONE:5)
Block(-7,-14,-3,STONE:5)
Block(-7,-14,-2,LOG:0)
Block(-7,-13,-7,SMOOTH_BRICK:1)
Block(-7,-13,-6,STONE:5)
Block(-7,-13,-5,COBBLESTONE:0)
Block(-7,-13,-4,STONE:5)
Block(-7,-13,-3,STONE:5)
Block(-7,-13,-2,LOG:0)
Block(-7,-12,-7,STONE:5)
Block(-7,-12,-6,COBBLESTONE:0)
Block(-7,-12,-5,COBBLESTONE:0)
Block(-7,-12,-4,STONE:5)
Block(-7,-12,-3,STONE:5)
Block(-7,-12,-2,LOG:0)
Block(-7,-11,-7,COBBLESTONE:0)
Block(-7,-11,-6,SMOOTH_BRICK:2)
Block(-7,-11,-5,SMOOTH_BRICK:1)
Block(-7,-11,-4,COBBLESTONE:0)
Block(-7,-11,-3,COBBLESTONE:0)
Block(-7,-11,-2,LOG:0)
Block(-7,-10,-7,SMOOTH_BRICK:1)
Block(-7,-10,-6,COBBLESTONE:0)
Block(-7,-10,-5,COBBLESTONE:0)
Block(-7,-10,-4,COBBLESTONE:0)
Block(-7,-10,-3,SMOOTH_BRICK:0)
Block(-7,-10,-2,LOG:0)
Block(-7,-9,-7,STONE:6)
Block(-7,-9,-6,STONE:6)
Block(-7,-9,-5,STONE:6)
Block(-7,-9,-4,STONE:6)
Block(-7,-9,-3,LOG:0)
Block(-7,-9,-2,SMOOTH_STAIRS:3)
Block(-7,-8,-7,STONE:6)
Block(-7,-8,-6,STONE:6)
Block(-7,-8,-5,STONE:6)
Block(-7,-8,-4,STONE:6)
Block(-7,-8,-3,LOG:0)
Block(-7,-7,-7,STONE:6)
Block(-7,-7,-6,STONE:6)
Block(-7,-7,-5,STONE:6)
Block(-7,-7,-4,STONE:6)
Block(-7,-7,-3,LOG:0)
Block(-7,-6,-7,STONE:6)
Block(-7,-6,-6,STONE:6)
Block(-7,-6,-5,STONE:6)
Block(-7,-6,-4,STONE:6)
Block(-7,-6,-3,LOG:0)
Block(-7,-5,-7,COBBLESTONE:0)
Block(-7,-5,-6,COBBLESTONE:0)
Block(-7,-5,-5,STONE:5)
Block(-7,-5,-4,COBBLESTONE:0)
Block(-7,-5,-3,LOG:0)
Block(-7,-4,-7,STONE:6)
Block(-7,-4,-6,STONE:6)
Block(-7,-4,-5,STONE:6)
Block(-7,-4,-4,LOG:0)
Block(-7,-4,-3,COBBLESTONE_STAIRS:3)
Block(-7,-3,-7,STONE:6)
Block(-7,-3,-6,STONE:6)
Block(-7,-3,-5,STONE:6)
Block(-7,-3,-4,LOG:0)
Block(-7,-2,-7,STONE:6)
Block(-7,-2,-6,STONE:6)
Block(-7,-2,-5,STONE:6)
Block(-7,-2,-4,LOG:0)
Block(-7,-1,-7,STONE:6)
Block(-7,-1,-6,STONE:6)
Block(-7,-1,-5,STONE:6)
Block(-7,-1,-4,LOG:0)
Block(-7,0,-7,STONE:6)
Block(-7,0,-6,STONE:6)
Block(-7,0,-5,STONE:6)
Block(-7,0,-4,LOG:0)
Block(-7,1,-7,STONE:5)
Block(-7,1,-6,STONE:5)
Block(-7,1,-5,STONE:5)
Block(-7,1,-4,LOG:0)
Block(-7,2,-7,SMOOTH_BRICK:0)
Block(-7,2,-6,SMOOTH_BRICK:0)
Block(-7,2,-5,SMOOTH_BRICK:0)
Block(-7,2,-4,LOG:0)
Block(-7,3,-7,COBBLESTONE:0)
Block(-7,3,-6,STAINED_CLAY:9)
Block(-7,3,-5,SMOOTH_BRICK:2)
Block(-7,3,-4,LOG:0)
Block(-7,4,-7,STONE:6)
Block(-7,4,-6,STONE:6)
Block(-7,4,-5,STONE:6)
Block(-7,4,-4,LOG:0)
Block(-7,5,-7,STONE:6)
Block(-7,5,-6,STONE:6)
Block(-7,5,-5,STONE:6)
Block(-7,5,-4,LOG:0)
Block(-7,6,-7,COBBLESTONE:0)
Block(-7,6,-6,SMOOTH_BRICK:2)
Block(-7,6,-5,SMOOTH_BRICK:0)
Block(-7,6,-4,LOG:0)
Block(-7,7,-7,CARPET:8)
Block(-7,7,-6,AIR:0)
Block(-7,7,-5,SMOOTH_BRICK:0)
Block(-7,7,-4,LOG:0)
Block(-7,8,-7,AIR:0)
Block(-7,8,-6,AIR:0)
Block(-7,8,-5,SMOOTH_BRICK:0)
Block(-7,8,-4,LOG:0)
Block(-7,9,-7,AIR:0)
Block(-7,9,-6,AIR:0)
Block(-7,9,-5,SMOOTH_BRICK:0)
Block(-7,9,-4,LOG:0)
Block(-7,10,-7,AIR:0)
Block(-7,10,-6,WALL_BANNER:2,origin/11156-bannerC352R112.nbt)
Block(-7,10,-5,SMOOTH_BRICK:0)
Block(-7,10,-4,LOG:0)
Block(-7,11,-7,LOG:4)
Block(-7,11,-6,LOG:8)
Block(-7,11,-5,LOG:8)
Block(-7,11,-4,LOG:0)
Block(-7,12,-7,AIR:0)
Block(-7,12,-6,COBBLESTONE:0)
Block(-7,12,-5,SMOOTH_BRICK:0)
Block(-7,12,-4,LOG:0)
Block(-7,13,-7,AIR:0)
Block(-7,13,-6,COBBLESTONE:0)
Block(-7,13,-5,SMOOTH_BRICK:0)
Block(-7,13,-4,LOG:0)
Block(-7,14,-7,AIR:0)
Block(-7,14,-6,COBBLESTONE:0)
Block(-7,14,-5,LOG:4)
Block(-7,14,-4,LOG:0)
Block(-7,15,-7,LOG:8)
Block(-7,15,-6,LOG:8)
Block(-7,15,-5,LOG:8)
Block(-7,15,-4,SMOOTH_STAIRS:3)
Block(-7,16,-7,STONE:6)
Block(-7,16,-6,COBBLESTONE:0)
Block(-7,16,-5,STONE:6)
Block(-7,16,-4,AIR:0)
Block(-7,17,-7,LOG:8)
Block(-7,17,-6,LOG:8)
Block(-7,17,-5,STONE:6)
Block(-7,17,-4,AIR:0)
Block(-7,18,-7,AIR:0)
Block(-7,18,-6,AIR:0)
Block(-7,18,-5,SMOOTH_STAIRS:1)
Block(-7,18,-4,AIR:0)
Block(-7,19,-7,AIR:0)
Block(-7,19,-6,AIR:0)
Block(-7,19,-5,SMOOTH_STAIRS:5)
Block(-7,19,-4,AIR:0)
Block(-7,20,-7,AIR:0)
Block(-7,20,-6,AIR:0)
Block(-7,20,-5,STONE:6)
Block(-7,20,-4,AIR:0)
Block(-7,21,-7,WOOD_STEP:13)
Block(-7,21,-6,LOG:4)
Block(-7,21,-5,COBBLESTONE:0)
Block(-7,21,-4,AIR:0)
Block(-7,22,-7,DARK_OAK_FENCE:0)
Block(-7,22,-6,AIR:0)
Block(-7,22,-5,WOOD:5)
Block(-7,22,-4,AIR:0)
Block(-7,23,-7,DARK_OAK_FENCE:0)
Block(-7,23,-6,AIR:0)
Block(-7,23,-5,AIR:0)
Block(-7,23,-4,AIR:0)
Block(-7,24,-7,DARK_OAK_STAIRS:3)
Block(-7,24,-6,AIR:0)
Block(-7,24,-5,AIR:0)
Block(-7,24,-4,AIR:0)
Block(-7,25,-7,AIR:0)
Block(-7,25,-6,AIR:0)
Block(-7,25,-5,AIR:0)
Block(-7,25,-4,AIR:0)
Block(-7,26,-7,AIR:0)
Block(-7,26,-6,AIR:0)
Block(-7,26,-5,AIR:0)
Block(-7,26,-4,AIR:0)
Block(-7,27,-7,AIR:0)
Block(-7,27,-6,AIR:0)
Block(-7,27,-5,AIR:0)
Block(-7,27,-4,AIR:0)
Block(-7,28,-7,AIR:0)
Block(-7,28,-6,AIR:0)
Block(-7,28,-5,AIR:0)
Block(-7,28,-4,AIR:0)
Block(-7,29,-7,AIR:0)
Block(-7,29,-6,AIR:0)
Block(-7,29,-5,AIR:0)
Block(-7,29,-4,AIR:0)
Block(-7,30,-7,AIR:0)
Block(-7,30,-6,AIR:0)
Block(-7,30,-5,AIR:0)
Block(-7,30,-4,AIR:0)
Block(-7,31,-7,AIR:0)
Block(-7,31,-6,AIR:0)
Block(-7,31,-5,AIR:0)
Block(-7,31,-4,AIR:0)
Block(-7,32,-7,AIR:0)
Block(-7,32,-6,AIR:0)
Block(-7,32,-5,AIR:0)
Block(-7,32,-4,AIR:0)
Block(-7,33,-7,AIR:0)
Block(-7,33,-6,AIR:0)
Block(-7,33,-5,AIR:0)
Block(-7,33,-4,AIR:0)
Block(-7,34,-7,AIR:0)
Block(-7,34,-6,AIR:0)
Block(-7,34,-5,AIR:0)
Block(-7,34,-4,AIR:0)
Block(-7,35,-7,AIR:0)
Block(-7,35,-6,AIR:0)
Block(-7,35,-5,AIR:0)
Block(-7,35,-4,AIR:0)
Block(-7,36,-7,AIR:0)
Block(-7,36,-6,AIR:0)
Block(-7,36,-5,AIR:0)
Block(-7,36,-4,AIR:0)
Block(-7,37,-7,AIR:0)
Block(-7,37,-6,AIR:0)
Block(-7,37,-5,AIR:0)
Block(-7,37,-4,AIR:0)
Block(-7,38,-7,AIR:0)
Block(-7,38,-6,AIR:0)
Block(-7,38,-5,AIR:0)
Block(-7,38,-4,AIR:0)
Block(-7,39,-7,AIR:0)
Block(-7,39,-6,AIR:0)
Block(-7,39,-5,AIR:0)
Block(-7,39,-4,AIR:0)
Block(-7,40,-7,AIR:0)
Block(-7,40,-6,AIR:0)
Block(-7,40,-5,AIR:0)
Block(-7,40,-4,AIR:0)
Block(-7,41,-7,AIR:0)
Block(-7,41,-6,AIR:0)
Block(-7,41,-5,AIR:0)
Block(-7,41,-4,AIR:0)
Block(-7,42,-7,AIR:0)
Block(-7,42,-6,AIR:0)
Block(-7,42,-5,AIR:0)
Block(-7,42,-4,AIR:0)
Block(-7,43,-7,AIR:0)
Block(-7,43,-6,AIR:0)
Block(-7,43,-5,AIR:0)
Block(-7,43,-4,AIR:0)
Block(-7,44,-7,AIR:0)
Block(-7,44,-6,AIR:0)
Block(-7,44,-5,AIR:0)
Block(-7,44,-4,AIR:0)
Block(-7,45,-7,AIR:0)
Block(-7,45,-6,AIR:0)
Block(-7,45,-5,AIR:0)
Block(-7,45,-4,AIR:0)
Block(-7,46,-7,AIR:0)
Block(-7,46,-6,AIR:0)
Block(-7,46,-5,AIR:0)
Block(-7,46,-4,AIR:0)
Block(-7,47,-7,AIR:0)
Block(-7,47,-6,AIR:0)
Block(-7,47,-5,AIR:0)
Block(-7,47,-4,AIR:0)
Block(-7,48,-7,AIR:0)
Block(-7,48,-6,AIR:0)
Block(-7,48,-5,AIR:0)
Block(-7,48,-4,AIR:0)
Block(-7,49,-7,AIR:0)
Block(-7,49,-6,AIR:0)
Block(-7,49,-5,AIR:0)
Block(-7,49,-4,AIR:0)
Block(-7,50,-7,AIR:0)
Block(-7,50,-6,AIR:0)
Block(-7,50,-5,AIR:0)
Block(-7,50,-4,AIR:0)
Block(-7,51,-7,AIR:0)
Block(-7,51,-6,AIR:0)
Block(-7,51,-5,AIR:0)
Block(-7,51,-4,AIR:0)
Block(-7,52,-7,AIR:0)
Block(-7,52,-6,AIR:0)
Block(-7,52,-5,AIR:0)
Block(-7,52,-4,AIR:0)
Block(-7,53,-7,AIR:0)
Block(-7,53,-6,AIR:0)
Block(-7,53,-5,AIR:0)
Block(-7,53,-4,AIR:0)
Block(-7,54,-7,AIR:0)
Block(-7,54,-6,AIR:0)
Block(-7,54,-5,AIR:0)
Block(-7,54,-4,AIR:0)
Block(-7,55,-7,AIR:0)
Block(-7,55,-6,AIR:0)
Block(-7,55,-5,AIR:0)
Block(-7,55,-4,AIR:0)
Block(-7,56,-7,AIR:0)
Block(-7,56,-6,AIR:0)
Block(-7,56,-5,AIR:0)
Block(-7,56,-4,AIR:0)
Block(-7,57,-7,AIR:0)
Block(-7,57,-6,AIR:0)
Block(-7,57,-5,AIR:0)
Block(-7,57,-4,AIR:0)
Block(-7,58,-7,AIR:0)
Block(-7,58,-6,AIR:0)
Block(-7,58,-5,AIR:0)
Block(-7,58,-4,AIR:0)
Block(-7,59,-7,AIR:0)
Block(-7,59,-6,AIR:0)
Block(-7,59,-5,AIR:0)
Block(-7,59,-4,AIR:0)
Block(-7,60,-7,AIR:0)
Block(-7,60,-6,AIR:0)
Block(-7,60,-5,AIR:0)
Block(-7,60,-4,AIR:0)
Block(-7,61,-7,AIR:0)
Block(-7,61,-6,AIR:0)
Block(-7,61,-5,AIR:0)
Block(-7,61,-4,AIR:0)
Block(-7,62,-7,AIR:0)
Block(-7,62,-6,AIR:0)
Block(-7,62,-5,AIR:0)
Block(-7,62,-4,AIR:0)
Block(-7,63,-7,AIR:0)
Block(-7,63,-6,AIR:0)
Block(-7,63,-5,AIR:0)
Block(-7,63,-4,AIR:0)
Block(-6,-50,-7,COBBLESTONE:0)
Block(-6,-50,-6,COBBLESTONE:0)
Block(-6,-50,-5,STAINED_CLAY:9)
Block(-6,-50,-4,COBBLESTONE:0)
Block(-6,-50,-3,COBBLESTONE:0)
Block(-6,-49,-7,COBBLESTONE:0)
Block(-6,-49,-6,COBBLESTONE:0)
Block(-6,-49,-5,STAINED_CLAY:9)
Block(-6,-49,-4,COBBLESTONE:0)
Block(-6,-49,-3,COBBLESTONE:0)
Block(-6,-48,-7,COBBLESTONE:0)
Block(-6,-48,-6,COBBLESTONE:0)
Block(-6,-48,-5,STAINED_CLAY:9)
Block(-6,-48,-4,COBBLESTONE:0)
Block(-6,-48,-3,COBBLESTONE:0)
Block(-6,-47,-7,COBBLESTONE:0)
Block(-6,-47,-6,COBBLESTONE:0)
Block(-6,-47,-5,STAINED_CLAY:9)
Block(-6,-47,-4,COBBLESTONE:0)
Block(-6,-47,-3,COBBLESTONE:0)
Block(-6,-46,-7,COBBLESTONE:0)
Block(-6,-46,-6,COBBLESTONE:0)
Block(-6,-46,-5,STAINED_CLAY:9)
Block(-6,-46,-4,COBBLESTONE:0)
Block(-6,-46,-3,COBBLESTONE:0)
Block(-6,-45,-7,COBBLESTONE:0)
Block(-6,-45,-6,COBBLESTONE:0)
Block(-6,-45,-5,STAINED_CLAY:9)
Block(-6,-45,-4,COBBLESTONE:0)
Block(-6,-45,-3,COBBLESTONE:0)
Block(-6,-44,-7,COBBLESTONE:0)
Block(-6,-44,-6,COBBLESTONE:0)
Block(-6,-44,-5,STAINED_CLAY:9)
Block(-6,-44,-4,COBBLESTONE:0)
Block(-6,-44,-3,COBBLESTONE:0)
Block(-6,-43,-7,COBBLESTONE:0)
Block(-6,-43,-6,COBBLESTONE:0)
Block(-6,-43,-5,STAINED_CLAY:9)
Block(-6,-43,-4,COBBLESTONE:0)
Block(-6,-43,-3,COBBLESTONE:0)
Block(-6,-42,-7,COBBLESTONE:0)
Block(-6,-42,-6,COBBLESTONE:0)
Block(-6,-42,-5,STAINED_CLAY:9)
Block(-6,-42,-4,COBBLESTONE:0)
Block(-6,-42,-3,COBBLESTONE:0)
Block(-6,-41,-7,COBBLESTONE:0)
Block(-6,-41,-6,COBBLESTONE:0)
Block(-6,-41,-5,STAINED_CLAY:9)
Block(-6,-41,-4,COBBLESTONE:0)
Block(-6,-41,-3,COBBLESTONE:0)
Block(-6,-40,-7,COBBLESTONE:0)
Block(-6,-40,-6,COBBLESTONE:0)
Block(-6,-40,-5,STAINED_CLAY:9)
Block(-6,-40,-4,COBBLESTONE:0)
Block(-6,-40,-3,COBBLESTONE:0)
Block(-6,-39,-7,COBBLESTONE:0)
Block(-6,-39,-6,COBBLESTONE:0)
Block(-6,-39,-5,STAINED_CLAY:9)
Block(-6,-39,-4,COBBLESTONE:0)
Block(-6,-39,-3,COBBLESTONE:0)
Block(-6,-38,-7,COBBLESTONE:0)
Block(-6,-38,-6,COBBLESTONE:0)
Block(-6,-38,-5,STAINED_CLAY:9)
Block(-6,-38,-4,COBBLESTONE:0)
Block(-6,-38,-3,COBBLESTONE:0)
Block(-6,-37,-7,COBBLESTONE:0)
Block(-6,-37,-6,COBBLESTONE:0)
Block(-6,-37,-5,STAINED_CLAY:9)
Block(-6,-37,-4,COBBLESTONE:0)
Block(-6,-37,-3,COBBLESTONE:0)
Block(-6,-36,-7,COBBLESTONE:0)
Block(-6,-36,-6,COBBLESTONE:0)
Block(-6,-36,-5,STAINED_CLAY:9)
Block(-6,-36,-4,COBBLESTONE:0)
Block(-6,-36,-3,COBBLESTONE:0)
Block(-6,-35,-7,COBBLESTONE:0)
Block(-6,-35,-6,COBBLESTONE:0)
Block(-6,-35,-5,STAINED_CLAY:9)
Block(-6,-35,-4,COBBLESTONE:0)
Block(-6,-35,-3,COBBLESTONE:0)
Block(-6,-34,-7,COBBLESTONE:0)
Block(-6,-34,-6,COBBLESTONE:0)
Block(-6,-34,-5,STAINED_CLAY:9)
Block(-6,-34,-4,COBBLESTONE:0)
Block(-6,-34,-3,COBBLESTONE:0)
Block(-6,-33,-7,COBBLESTONE:0)
Block(-6,-33,-6,COBBLESTONE:0)
Block(-6,-33,-5,STAINED_CLAY:9)
Block(-6,-33,-4,COBBLESTONE:0)
Block(-6,-33,-3,COBBLESTONE:0)
Block(-6,-32,-7,COBBLESTONE:0)
Block(-6,-32,-6,COBBLESTONE:0)
Block(-6,-32,-5,STAINED_CLAY:9)
Block(-6,-32,-4,COBBLESTONE:0)
Block(-6,-32,-3,COBBLESTONE:0)
Block(-6,-31,-7,COBBLESTONE:0)
Block(-6,-31,-6,COBBLESTONE:0)
Block(-6,-31,-5,STAINED_CLAY:9)
Block(-6,-31,-4,COBBLESTONE:0)
Block(-6,-31,-3,COBBLESTONE:0)
Block(-6,-30,-7,COBBLESTONE:0)
Block(-6,-30,-6,COBBLESTONE:0)
Block(-6,-30,-5,STAINED_CLAY:9)
Block(-6,-30,-4,COBBLESTONE:0)
Block(-6,-30,-3,COBBLESTONE:0)
Block(-6,-29,-7,COBBLESTONE:0)
Block(-6,-29,-6,COBBLESTONE:0)
Block(-6,-29,-5,STAINED_CLAY:9)
Block(-6,-29,-4,COBBLESTONE:0)
Block(-6,-29,-3,COBBLESTONE:0)
Block(-6,-28,-7,COBBLESTONE:0)
Block(-6,-28,-6,COBBLESTONE:0)
Block(-6,-28,-5,STAINED_CLAY:9)
Block(-6,-28,-4,COBBLESTONE:0)
Block(-6,-28,-3,COBBLESTONE:0)
Block(-6,-27,-7,COBBLESTONE:0)
Block(-6,-27,-6,COBBLESTONE:0)
Block(-6,-27,-5,STAINED_CLAY:9)
Block(-6,-27,-4,COBBLESTONE:0)
Block(-6,-27,-3,COBBLESTONE:0)
Block(-6,-26,-7,COBBLESTONE:0)
Block(-6,-26,-6,COBBLESTONE:0)
Block(-6,-26,-5,STAINED_CLAY:9)
Block(-6,-26,-4,COBBLESTONE:0)
Block(-6,-26,-3,COBBLESTONE:0)
Block(-6,-25,-7,COBBLESTONE:0)
Block(-6,-25,-6,COBBLESTONE:0)
Block(-6,-25,-5,STAINED_CLAY:9)
Block(-6,-25,-4,COBBLESTONE:0)
Block(-6,-25,-3,COBBLESTONE:0)
Block(-6,-24,-7,COBBLESTONE:0)
Block(-6,-24,-6,COBBLESTONE:0)
Block(-6,-24,-5,STAINED_CLAY:9)
Block(-6,-24,-4,COBBLESTONE:0)
Block(-6,-24,-3,COBBLESTONE:0)
Block(-6,-23,-7,COBBLESTONE:0)
Block(-6,-23,-6,COBBLESTONE:0)
Block(-6,-23,-5,STAINED_CLAY:9)
Block(-6,-23,-4,COBBLESTONE:0)
Block(-6,-23,-3,COBBLESTONE:0)
Block(-6,-22,-7,COBBLESTONE:0)
Block(-6,-22,-6,COBBLESTONE:0)
Block(-6,-22,-5,STAINED_CLAY:9)
Block(-6,-22,-4,COBBLESTONE:0)
Block(-6,-22,-3,COBBLESTONE:0)
Block(-6,-21,-7,COBBLESTONE:0)
Block(-6,-21,-6,COBBLESTONE:0)
Block(-6,-21,-5,STAINED_CLAY:9)
Block(-6,-21,-4,COBBLESTONE:0)
Block(-6,-21,-3,COBBLESTONE:0)
Block(-6,-20,-7,COBBLESTONE:0)
Block(-6,-20,-6,COBBLESTONE:0)
Block(-6,-20,-5,STAINED_CLAY:9)
Block(-6,-20,-4,COBBLESTONE:0)
Block(-6,-20,-3,COBBLESTONE:0)
Block(-6,-19,-7,STONE:5)
Block(-6,-19,-6,SMOOTH_BRICK:1)
Block(-6,-19,-5,COBBLESTONE:0)
Block(-6,-19,-4,SMOOTH_BRICK:2)
Block(-6,-19,-3,STONE:5)
Block(-6,-18,-7,COBBLESTONE:0)
Block(-6,-18,-6,SMOOTH_BRICK:0)
Block(-6,-18,-5,COBBLESTONE:0)
Block(-6,-18,-4,STONE:5)
Block(-6,-18,-3,SMOOTH_BRICK:1)
Block(-6,-17,-7,STONE:5)
Block(-6,-17,-6,COBBLESTONE:0)
Block(-6,-17,-5,COBBLESTONE:0)
Block(-6,-17,-4,STONE:5)
Block(-6,-17,-3,COBBLESTONE:0)
Block(-6,-16,-7,COBBLESTONE:0)
Block(-6,-16,-6,SMOOTH_BRICK:1)
Block(-6,-16,-5,SMOOTH_BRICK:2)
Block(-6,-16,-4,COBBLESTONE:0)
Block(-6,-16,-3,SMOOTH_BRICK:1)
Block(-6,-15,-7,STONE:5)
Block(-6,-15,-6,STONE:5)
Block(-6,-15,-5,COBBLESTONE:0)
Block(-6,-15,-4,STONE:5)
Block(-6,-15,-3,STONE:5)
Block(-6,-14,-7,COBBLESTONE:0)
Block(-6,-14,-6,SMOOTH_BRICK:0)
Block(-6,-14,-5,COBBLESTONE:0)
Block(-6,-14,-4,COBBLESTONE:0)
Block(-6,-14,-3,COBBLESTONE:0)
Block(-6,-13,-7,COBBLESTONE:0)
Block(-6,-13,-6,STONE:5)
Block(-6,-13,-5,STONE:5)
Block(-6,-13,-4,COBBLESTONE:0)
Block(-6,-13,-3,COBBLESTONE:0)
Block(-6,-12,-7,COBBLESTONE:0)
Block(-6,-12,-6,SMOOTH_BRICK:2)
Block(-6,-12,-5,SMOOTH_BRICK:1)
Block(-6,-12,-4,COBBLESTONE:0)
Block(-6,-12,-3,STONE:5)
Block(-6,-11,-7,STONE:5)
Block(-6,-11,-6,COBBLESTONE:0)
Block(-6,-11,-5,STONE:5)
Block(-6,-11,-4,STONE:5)
Block(-6,-11,-3,SMOOTH_BRICK:0)
Block(-6,-10,-7,COBBLESTONE:0)
Block(-6,-10,-6,STONE:5)
Block(-6,-10,-5,COBBLESTONE:0)
Block(-6,-10,-4,STONE:5)
Block(-6,-10,-3,COBBLESTONE:0)
Block(-6,-9,-7,STONE:6)
Block(-6,-9,-6,STONE:6)
Block(-6,-9,-5,STONE:6)
Block(-6,-9,-4,STONE:6)
Block(-6,-9,-3,COBBLESTONE_STAIRS:3)
Block(-6,-8,-7,STONE:6)
Block(-6,-8,-6,STONE:6)
Block(-6,-8,-5,STONE:6)
Block(-6,-8,-4,STONE:6)
Block(-6,-7,-7,STONE:6)
Block(-6,-7,-6,STONE:6)
Block(-6,-7,-5,STONE:6)
Block(-6,-7,-4,STONE:6)
Block(-6,-6,-7,STONE:6)
Block(-6,-6,-6,STONE:6)
Block(-6,-6,-5,STONE:6)
Block(-6,-6,-4,STONE:6)
Block(-6,-5,-7,SMOOTH_BRICK:1)
Block(-6,-5,-6,COBBLESTONE:0)
Block(-6,-5,-5,COBBLESTONE:0)
Block(-6,-5,-4,COBBLESTONE_STAIRS:3)
Block(-6,-4,-7,STONE:6)
Block(-6,-4,-6,STONE:6)
Block(-6,-4,-5,STONE:6)
Block(-6,-3,-7,STONE:6)
Block(-6,-3,-6,STONE:6)
Block(-6,-3,-5,STONE:6)
Block(-6,-2,-7,STONE:6)
Block(-6,-2,-6,STONE:6)
Block(-6,-2,-5,STONE:6)
Block(-6,-1,-7,STONE:6)
Block(-6,-1,-6,STONE:6)
Block(-6,-1,-5,STONE:6)
Block(-6,0,-7,STONE:6)
Block(-6,0,-6,STONE:6)
Block(-6,0,-5,STONE:6)
Block(-6,1,-7,COBBLESTONE:0)
Block(-6,1,-6,SMOOTH_BRICK:2)
Block(-6,1,-5,SMOOTH_BRICK:0)
Block(-6,2,-7,SMOOTH_BRICK:0)
Block(-6,2,-6,SMOOTH_BRICK:0)
Block(-6,2,-5,SMOOTH_BRICK:0)
Block(-6,3,-7,STONE:5)
Block(-6,3,-6,STONE:5)
Block(-6,3,-5,COBBLESTONE_STAIRS:3)
Block(-6,4,-7,STONE:6)
Block(-6,4,-6,STONE:6)
Block(-6,4,-5,AIR:0)
Block(-6,5,-7,STONE:6)
Block(-6,5,-6,STONE:6)
Block(-6,5,-5,AIR:0)
Block(-6,6,-7,STONE:5)
Block(-6,6,-6,STONE:5)
Block(-6,6,-5,AIR:0)
Block(-6,7,-7,AIR:0)
Block(-6,7,-6,STONE:5)
Block(-6,7,-5,AIR:0)
Block(-6,8,-7,AIR:0)
Block(-6,8,-6,COBBLESTONE:0)
Block(-6,8,-5,AIR:0)
Block(-6,9,-7,AIR:0)
Block(-6,9,-6,COBBLESTONE:0)
Block(-6,9,-5,AIR:0)
Block(-6,10,-7,WALL_BANNER:4,origin/11158-bannerC352R112.nbt)
Block(-6,10,-6,COBBLESTONE:0)
Block(-6,10,-5,AIR:0)
Block(-6,11,-7,LOG:4)
Block(-6,11,-6,COBBLESTONE:0)
Block(-6,11,-5,AIR:0)
Block(-6,12,-7,COBBLESTONE:0)
Block(-6,12,-6,LOG:0)
Block(-6,12,-5,AIR:0)
Block(-6,13,-7,COBBLESTONE:0)
Block(-6,13,-6,LOG:0)
Block(-6,13,-5,AIR:0)
Block(-6,14,-7,COBBLESTONE:0)
Block(-6,14,-6,LOG:0)
Block(-6,14,-5,AIR:0)
Block(-6,15,-7,LOG:4)
Block(-6,15,-6,LOG:0)
Block(-6,15,-5,AIR:0)
Block(-6,16,-7,COBBLESTONE:0)
Block(-6,16,-6,LOG:0)
Block(-6,16,-5,AIR:0)
Block(-6,17,-7,LOG:4)
Block(-6,17,-6,LOG:0)
Block(-6,17,-5,AIR:0)
Block(-6,18,-7,AIR:0)
Block(-6,18,-6,LOG:0)
Block(-6,18,-5,AIR:0)
Block(-6,19,-7,AIR:0)
Block(-6,19,-6,LOG:0)
Block(-6,19,-5,AIR:0)
Block(-6,20,-7,AIR:0)
Block(-6,20,-6,LOG:0)
Block(-6,20,-5,AIR:0)
Block(-6,21,-7,LOG:8)
Block(-6,21,-6,LOG:0)
Block(-6,21,-5,COBBLESTONE_STAIRS:5)
Block(-6,22,-7,AIR:0)
Block(-6,22,-6,STONE_PLATE:0)
Block(-6,22,-5,COBBLESTONE:0)
Block(-6,23,-7,AIR:0)
Block(-6,23,-6,AIR:0)
Block(-6,23,-5,STEP:0)
Block(-6,24,-7,AIR:0)
Block(-6,24,-6,AIR:0)
Block(-6,24,-5,AIR:0)
Block(-6,25,-7,AIR:0)
Block(-6,25,-6,AIR:0)
Block(-6,25,-5,AIR:0)
Block(-6,26,-7,AIR:0)
Block(-6,26,-6,AIR:0)
Block(-6,26,-5,AIR:0)
Block(-6,27,-7,AIR:0)
Block(-6,27,-6,AIR:0)
Block(-6,27,-5,AIR:0)
Block(-6,28,-7,AIR:0)
Block(-6,28,-6,AIR:0)
Block(-6,28,-5,AIR:0)
Block(-6,29,-7,AIR:0)
Block(-6,29,-6,AIR:0)
Block(-6,29,-5,AIR:0)
Block(-6,30,-7,AIR:0)
Block(-6,30,-6,AIR:0)
Block(-6,30,-5,AIR:0)
Block(-6,31,-7,AIR:0)
Block(-6,31,-6,AIR:0)
Block(-6,31,-5,AIR:0)
Block(-6,32,-7,AIR:0)
Block(-6,32,-6,AIR:0)
Block(-6,32,-5,AIR:0)
Block(-6,33,-7,AIR:0)
Block(-6,33,-6,AIR:0)
Block(-6,33,-5,AIR:0)
Block(-6,34,-7,AIR:0)
Block(-6,34,-6,AIR:0)
Block(-6,34,-5,AIR:0)
Block(-6,35,-7,AIR:0)
Block(-6,35,-6,AIR:0)
Block(-6,35,-5,AIR:0)
Block(-6,36,-7,AIR:0)
Block(-6,36,-6,AIR:0)
Block(-6,36,-5,AIR:0)
Block(-6,37,-7,AIR:0)
Block(-6,37,-6,AIR:0)
Block(-6,37,-5,AIR:0)
Block(-6,38,-7,AIR:0)
Block(-6,38,-6,AIR:0)
Block(-6,38,-5,AIR:0)
Block(-6,39,-7,AIR:0)
Block(-6,39,-6,AIR:0)
Block(-6,39,-5,AIR:0)
Block(-6,40,-7,AIR:0)
Block(-6,40,-6,AIR:0)
Block(-6,40,-5,AIR:0)
Block(-6,41,-7,AIR:0)
Block(-6,41,-6,AIR:0)
Block(-6,41,-5,AIR:0)
Block(-6,42,-7,AIR:0)
Block(-6,42,-6,AIR:0)
Block(-6,42,-5,AIR:0)
Block(-6,43,-7,AIR:0)
Block(-6,43,-6,AIR:0)
Block(-6,43,-5,AIR:0)
Block(-6,44,-7,AIR:0)
Block(-6,44,-6,AIR:0)
Block(-6,44,-5,AIR:0)
Block(-6,45,-7,AIR:0)
Block(-6,45,-6,AIR:0)
Block(-6,45,-5,AIR:0)
Block(-6,46,-7,AIR:0)
Block(-6,46,-6,AIR:0)
Block(-6,46,-5,AIR:0)
Block(-6,47,-7,AIR:0)
Block(-6,47,-6,AIR:0)
Block(-6,47,-5,AIR:0)
Block(-6,48,-7,AIR:0)
Block(-6,48,-6,AIR:0)
Block(-6,48,-5,AIR:0)
Block(-6,49,-7,AIR:0)
Block(-6,49,-6,AIR:0)
Block(-6,49,-5,AIR:0)
Block(-6,50,-7,AIR:0)
Block(-6,50,-6,AIR:0)
Block(-6,50,-5,AIR:0)
Block(-6,51,-7,AIR:0)
Block(-6,51,-6,AIR:0)
Block(-6,51,-5,AIR:0)
Block(-6,52,-7,AIR:0)
Block(-6,52,-6,AIR:0)
Block(-6,52,-5,AIR:0)
Block(-6,53,-7,AIR:0)
Block(-6,53,-6,AIR:0)
Block(-6,53,-5,AIR:0)
Block(-6,54,-7,AIR:0)
Block(-6,54,-6,AIR:0)
Block(-6,54,-5,AIR:0)
Block(-6,55,-7,AIR:0)
Block(-6,55,-6,AIR:0)
Block(-6,55,-5,AIR:0)
Block(-6,56,-7,AIR:0)
Block(-6,56,-6,AIR:0)
Block(-6,56,-5,AIR:0)
Block(-6,57,-7,AIR:0)
Block(-6,57,-6,AIR:0)
Block(-6,57,-5,AIR:0)
Block(-6,58,-7,AIR:0)
Block(-6,58,-6,AIR:0)
Block(-6,58,-5,AIR:0)
Block(-6,59,-7,AIR:0)
Block(-6,59,-6,AIR:0)
Block(-6,59,-5,AIR:0)
Block(-6,60,-7,AIR:0)
Block(-6,60,-6,AIR:0)
Block(-6,60,-5,AIR:0)
Block(-6,61,-7,AIR:0)
Block(-6,61,-6,AIR:0)
Block(-6,61,-5,AIR:0)
Block(-6,62,-7,AIR:0)
Block(-6,62,-6,AIR:0)
Block(-6,62,-5,AIR:0)
Block(-6,63,-7,AIR:0)
Block(-6,63,-6,AIR:0)
Block(-6,63,-5,AIR:0)
Block(-5,-50,-7,STAINED_CLAY:9)
Block(-5,-50,-6,COBBLESTONE:0)
Block(-5,-50,-5,COBBLESTONE:0)
Block(-5,-50,-4,STONE:5)
Block(-5,-50,-3,STAINED_CLAY:9)
Block(-5,-49,-7,STAINED_CLAY:9)
Block(-5,-49,-6,COBBLESTONE:0)
Block(-5,-49,-5,COBBLESTONE:0)
Block(-5,-49,-4,STONE:5)
Block(-5,-49,-3,STAINED_CLAY:9)
Block(-5,-48,-7,STAINED_CLAY:9)
Block(-5,-48,-6,COBBLESTONE:0)
Block(-5,-48,-5,COBBLESTONE:0)
Block(-5,-48,-4,STONE:5)
Block(-5,-48,-3,STAINED_CLAY:9)
Block(-5,-47,-7,STAINED_CLAY:9)
Block(-5,-47,-6,COBBLESTONE:0)
Block(-5,-47,-5,COBBLESTONE:0)
Block(-5,-47,-4,STONE:5)
Block(-5,-47,-3,STAINED_CLAY:9)
Block(-5,-46,-7,STAINED_CLAY:9)
Block(-5,-46,-6,COBBLESTONE:0)
Block(-5,-46,-5,COBBLESTONE:0)
Block(-5,-46,-4,STONE:5)
Block(-5,-46,-3,STAINED_CLAY:9)
Block(-5,-45,-7,STAINED_CLAY:9)
Block(-5,-45,-6,COBBLESTONE:0)
Block(-5,-45,-5,COBBLESTONE:0)
Block(-5,-45,-4,STONE:5)
Block(-5,-45,-3,STAINED_CLAY:9)
Block(-5,-44,-7,STAINED_CLAY:9)
Block(-5,-44,-6,COBBLESTONE:0)
Block(-5,-44,-5,COBBLESTONE:0)
Block(-5,-44,-4,STONE:5)
Block(-5,-44,-3,STAINED_CLAY:9)
Block(-5,-43,-7,STAINED_CLAY:9)
Block(-5,-43,-6,COBBLESTONE:0)
Block(-5,-43,-5,COBBLESTONE:0)
Block(-5,-43,-4,STONE:5)
Block(-5,-43,-3,STAINED_CLAY:9)
Block(-5,-42,-7,STAINED_CLAY:9)
Block(-5,-42,-6,COBBLESTONE:0)
Block(-5,-42,-5,COBBLESTONE:0)
Block(-5,-42,-4,STONE:5)
Block(-5,-42,-3,STAINED_CLAY:9)
Block(-5,-41,-7,STAINED_CLAY:9)
Block(-5,-41,-6,COBBLESTONE:0)
Block(-5,-41,-5,COBBLESTONE:0)
Block(-5,-41,-4,STONE:5)
Block(-5,-41,-3,STAINED_CLAY:9)
Block(-5,-40,-7,STAINED_CLAY:9)
Block(-5,-40,-6,COBBLESTONE:0)
Block(-5,-40,-5,COBBLESTONE:0)
Block(-5,-40,-4,STONE:5)
Block(-5,-40,-3,STAINED_CLAY:9)
Block(-5,-39,-7,STAINED_CLAY:9)
Block(-5,-39,-6,COBBLESTONE:0)
Block(-5,-39,-5,COBBLESTONE:0)
Block(-5,-39,-4,STONE:5)
Block(-5,-39,-3,STAINED_CLAY:9)
Block(-5,-38,-7,STAINED_CLAY:9)
Block(-5,-38,-6,COBBLESTONE:0)
Block(-5,-38,-5,COBBLESTONE:0)
Block(-5,-38,-4,STONE:5)
Block(-5,-38,-3,STAINED_CLAY:9)
Block(-5,-37,-7,STAINED_CLAY:9)
Block(-5,-37,-6,COBBLESTONE:0)
Block(-5,-37,-5,COBBLESTONE:0)
Block(-5,-37,-4,STONE:5)
Block(-5,-37,-3,STAINED_CLAY:9)
Block(-5,-36,-7,STAINED_CLAY:9)
Block(-5,-36,-6,COBBLESTONE:0)
Block(-5,-36,-5,COBBLESTONE:0)
Block(-5,-36,-4,STONE:5)
Block(-5,-36,-3,STAINED_CLAY:9)
Block(-5,-35,-7,STAINED_CLAY:9)
Block(-5,-35,-6,COBBLESTONE:0)
Block(-5,-35,-5,COBBLESTONE:0)
Block(-5,-35,-4,STONE:5)
Block(-5,-35,-3,STAINED_CLAY:9)
Block(-5,-34,-7,STAINED_CLAY:9)
Block(-5,-34,-6,COBBLESTONE:0)
Block(-5,-34,-5,COBBLESTONE:0)
Block(-5,-34,-4,STONE:5)
Block(-5,-34,-3,STAINED_CLAY:9)
Block(-5,-33,-7,STAINED_CLAY:9)
Block(-5,-33,-6,COBBLESTONE:0)
Block(-5,-33,-5,COBBLESTONE:0)
Block(-5,-33,-4,STONE:5)
Block(-5,-33,-3,STAINED_CLAY:9)
Block(-5,-32,-7,STAINED_CLAY:9)
Block(-5,-32,-6,COBBLESTONE:0)
Block(-5,-32,-5,COBBLESTONE:0)
Block(-5,-32,-4,STONE:5)
Block(-5,-32,-3,STAINED_CLAY:9)
Block(-5,-31,-7,STAINED_CLAY:9)
Block(-5,-31,-6,COBBLESTONE:0)
Block(-5,-31,-5,COBBLESTONE:0)
Block(-5,-31,-4,STONE:5)
Block(-5,-31,-3,STAINED_CLAY:9)
Block(-5,-30,-7,STAINED_CLAY:9)
Block(-5,-30,-6,COBBLESTONE:0)
Block(-5,-30,-5,COBBLESTONE:0)
Block(-5,-30,-4,STONE:5)
Block(-5,-30,-3,STAINED_CLAY:9)
Block(-5,-29,-7,STAINED_CLAY:9)
Block(-5,-29,-6,COBBLESTONE:0)
Block(-5,-29,-5,COBBLESTONE:0)
Block(-5,-29,-4,STONE:5)
Block(-5,-29,-3,STAINED_CLAY:9)
Block(-5,-28,-7,STAINED_CLAY:9)
Block(-5,-28,-6,COBBLESTONE:0)
Block(-5,-28,-5,COBBLESTONE:0)
Block(-5,-28,-4,STONE:5)
Block(-5,-28,-3,STAINED_CLAY:9)
Block(-5,-27,-7,STAINED_CLAY:9)
Block(-5,-27,-6,COBBLESTONE:0)
Block(-5,-27,-5,COBBLESTONE:0)
Block(-5,-27,-4,STONE:5)
Block(-5,-27,-3,STAINED_CLAY:9)
Block(-5,-26,-7,STAINED_CLAY:9)
Block(-5,-26,-6,COBBLESTONE:0)
Block(-5,-26,-5,COBBLESTONE:0)
Block(-5,-26,-4,STONE:5)
Block(-5,-26,-3,STAINED_CLAY:9)
Block(-5,-25,-7,STAINED_CLAY:9)
Block(-5,-25,-6,COBBLESTONE:0)
Block(-5,-25,-5,COBBLESTONE:0)
Block(-5,-25,-4,STONE:5)
Block(-5,-25,-3,STAINED_CLAY:9)
Block(-5,-24,-7,STAINED_CLAY:9)
Block(-5,-24,-6,COBBLESTONE:0)
Block(-5,-24,-5,COBBLESTONE:0)
Block(-5,-24,-4,STONE:5)
Block(-5,-24,-3,STAINED_CLAY:9)
Block(-5,-23,-7,STAINED_CLAY:9)
Block(-5,-23,-6,COBBLESTONE:0)
Block(-5,-23,-5,COBBLESTONE:0)
Block(-5,-23,-4,STONE:5)
Block(-5,-23,-3,STAINED_CLAY:9)
Block(-5,-22,-7,STAINED_CLAY:9)
Block(-5,-22,-6,COBBLESTONE:0)
Block(-5,-22,-5,COBBLESTONE:0)
Block(-5,-22,-4,STONE:5)
Block(-5,-22,-3,STAINED_CLAY:9)
Block(-5,-21,-7,STAINED_CLAY:9)
Block(-5,-21,-6,COBBLESTONE:0)
Block(-5,-21,-5,COBBLESTONE:0)
Block(-5,-21,-4,STONE:5)
Block(-5,-21,-3,STAINED_CLAY:9)
Block(-5,-20,-7,STAINED_CLAY:9)
Block(-5,-20,-6,COBBLESTONE:0)
Block(-5,-20,-5,COBBLESTONE:0)
Block(-5,-20,-4,STONE:5)
Block(-5,-20,-3,STAINED_CLAY:9)
Block(-5,-19,-7,COBBLESTONE:0)
Block(-5,-19,-6,COBBLESTONE:0)
Block(-5,-19,-5,STONE:5)
Block(-5,-19,-4,STONE:5)
Block(-5,-19,-3,STONE:5)
Block(-5,-18,-7,COBBLESTONE:0)
Block(-5,-18,-6,COBBLESTONE:0)
Block(-5,-18,-5,COBBLESTONE:0)
Block(-5,-18,-4,COBBLESTONE:0)
Block(-5,-18,-3,STONE:5)
Block(-5,-17,-7,SMOOTH_BRICK:1)
Block(-5,-17,-6,STONE:5)
Block(-5,-17,-5,COBBLESTONE:0)
Block(-5,-17,-4,STONE:5)
Block(-5,-17,-3,COBBLESTONE:0)
Block(-5,-16,-7,COBBLESTONE:0)
Block(-5,-16,-6,COBBLESTONE:0)
Block(-5,-16,-5,COBBLESTONE:0)
Block(-5,-16,-4,COBBLESTONE:0)
Block(-5,-16,-3,COBBLESTONE:0)
Block(-5,-15,-7,COBBLESTONE:0)
Block(-5,-15,-6,COBBLESTONE:0)
Block(-5,-15,-5,COBBLESTONE:0)
Block(-5,-15,-4,COBBLESTONE:0)
Block(-5,-15,-3,COBBLESTONE:0)
Block(-5,-14,-7,STAINED_CLAY:9)
Block(-5,-14,-6,STONE:5)
Block(-5,-14,-5,STONE:5)
Block(-5,-14,-4,COBBLESTONE:0)
Block(-5,-14,-3,COBBLESTONE:0)
Block(-5,-13,-7,SMOOTH_BRICK:1)
Block(-5,-13,-6,COBBLESTONE:0)
Block(-5,-13,-5,COBBLESTONE:0)
Block(-5,-13,-4,STONE:5)
Block(-5,-13,-3,STONE:5)
Block(-5,-12,-7,STONE:5)
Block(-5,-12,-6,STAINED_CLAY:9)
Block(-5,-12,-5,SMOOTH_BRICK:1)
Block(-5,-12,-4,COBBLESTONE:0)
Block(-5,-12,-3,COBBLESTONE:0)
Block(-5,-11,-7,COBBLESTONE:0)
Block(-5,-11,-6,STONE:5)
Block(-5,-11,-5,STONE:5)
Block(-5,-11,-4,COBBLESTONE:0)
Block(-5,-11,-3,STONE:5)
Block(-5,-10,-7,STONE:5)
Block(-5,-10,-6,COBBLESTONE:0)
Block(-5,-10,-5,COBBLESTONE:0)
Block(-5,-10,-4,STONE:5)
Block(-5,-10,-3,STONE:5)
Block(-5,-9,-7,STONE:6)
Block(-5,-9,-6,STONE:6)
Block(-5,-9,-5,LOG:0)
Block(-5,-9,-4,COBBLESTONE_STAIRS:3)
Block(-5,-9,-3,COBBLESTONE_STAIRS:1)
Block(-5,-8,-7,STONE:6)
Block(-5,-8,-6,STONE:6)
Block(-5,-8,-5,LOG:0)
Block(-5,-7,-7,STONE:6)
Block(-5,-7,-6,STONE:6)
Block(-5,-7,-5,LOG:0)
Block(-5,-6,-7,STONE:6)
Block(-5,-6,-6,STONE:6)
Block(-5,-6,-5,LOG:0)
Block(-5,-5,-7,SMOOTH_BRICK:1)
Block(-5,-5,-6,COBBLESTONE:0)
Block(-5,-5,-5,LOG:0)
Block(-5,-4,-7,STONE:6)
Block(-5,-4,-6,STONE:6)
Block(-5,-4,-5,LOG:0)
Block(-5,-3,-7,STONE:6)
Block(-5,-3,-6,STONE:6)
Block(-5,-3,-5,LOG:0)
Block(-5,-2,-7,STONE:6)
Block(-5,-2,-6,STONE:6)
Block(-5,-2,-5,LOG:0)
Block(-5,-1,-7,STONE:6)
Block(-5,-1,-6,STONE:6)
Block(-5,-1,-5,LOG:0)
Block(-5,0,-7,STONE:6)
Block(-5,0,-6,STONE:6)
Block(-5,0,-5,LOG:0)
Block(-5,1,-7,COBBLESTONE:0)
Block(-5,1,-6,STONE:5)
Block(-5,1,-5,LOG:0)
Block(-5,2,-7,SMOOTH_BRICK:0)
Block(-5,2,-6,SMOOTH_BRICK:0)
Block(-5,2,-5,LOG:0)
Block(-5,3,-7,STAINED_CLAY:9)
Block(-5,3,-6,COBBLESTONE_STAIRS:1)
Block(-5,3,-5,LOG:0)
Block(-5,4,-7,STONE:6)
Block(-5,4,-6,AIR:0)
Block(-5,4,-5,LOG:0)
Block(-5,5,-7,STONE:6)
Block(-5,5,-6,AIR:0)
Block(-5,5,-5,LOG:0)
Block(-5,6,-7,SMOOTH_BRICK:0)
Block(-5,6,-6,AIR:0)
Block(-5,6,-5,LOG:0)
Block(-5,7,-7,SMOOTH_BRICK:0)
Block(-5,7,-6,AIR:0)
Block(-5,7,-5,LOG:0)
Block(-5,8,-7,SMOOTH_BRICK:0)
Block(-5,8,-6,AIR:0)
Block(-5,8,-5,LOG:0)
Block(-5,9,-7,SMOOTH_BRICK:0)
Block(-5,9,-6,AIR:0)
Block(-5,9,-5,LOG:0)
Block(-5,10,-7,SMOOTH_BRICK:0)
Block(-5,10,-6,AIR:0)
Block(-5,10,-5,LOG:0)
Block(-5,11,-7,LOG:4)
Block(-5,11,-6,AIR:0)
Block(-5,11,-5,LOG:0)
Block(-5,12,-7,SMOOTH_BRICK:0)
Block(-5,12,-6,AIR:0)
Block(-5,12,-5,STEP:0)
Block(-5,13,-7,SMOOTH_BRICK:0)
Block(-5,13,-6,AIR:0)
Block(-5,13,-5,AIR:0)
Block(-5,14,-7,LOG:8)
Block(-5,14,-6,AIR:0)
Block(-5,14,-5,AIR:0)
Block(-5,15,-7,LOG:4)
Block(-5,15,-6,AIR:0)
Block(-5,15,-5,AIR:0)
Block(-5,16,-7,STONE:6)
Block(-5,16,-6,AIR:0)
Block(-5,16,-5,AIR:0)
Block(-5,17,-7,STONE:6)
Block(-5,17,-6,AIR:0)
Block(-5,17,-5,AIR:0)
Block(-5,18,-7,SMOOTH_STAIRS:3)
Block(-5,18,-6,AIR:0)
Block(-5,18,-5,AIR:0)
Block(-5,19,-7,SMOOTH_STAIRS:7)
Block(-5,19,-6,AIR:0)
Block(-5,19,-5,AIR:0)
Block(-5,20,-7,STONE:6)
Block(-5,20,-6,AIR:0)
Block(-5,20,-5,AIR:0)
Block(-5,21,-7,COBBLESTONE:0)
Block(-5,21,-6,COBBLESTONE_STAIRS:7)
Block(-5,21,-5,AIR:0)
Block(-5,22,-7,WOOD:5)
Block(-5,22,-6,COBBLESTONE:0)
Block(-5,22,-5,AIR:0)
Block(-5,23,-7,AIR:0)
Block(-5,23,-6,STEP:0)
Block(-5,23,-5,AIR:0)
Block(-5,24,-7,AIR:0)
Block(-5,24,-6,AIR:0)
Block(-5,24,-5,AIR:0)
Block(-5,25,-7,AIR:0)
Block(-5,25,-6,AIR:0)
Block(-5,25,-5,AIR:0)
Block(-5,26,-7,AIR:0)
Block(-5,26,-6,AIR:0)
Block(-5,26,-5,AIR:0)
Block(-5,27,-7,AIR:0)
Block(-5,27,-6,AIR:0)
Block(-5,27,-5,AIR:0)
Block(-5,28,-7,AIR:0)
Block(-5,28,-6,AIR:0)
Block(-5,28,-5,AIR:0)
Block(-5,29,-7,AIR:0)
Block(-5,29,-6,AIR:0)
Block(-5,29,-5,AIR:0)
Block(-5,30,-7,AIR:0)
Block(-5,30,-6,AIR:0)
Block(-5,30,-5,AIR:0)
Block(-5,31,-7,AIR:0)
Block(-5,31,-6,AIR:0)
Block(-5,31,-5,AIR:0)
Block(-5,32,-7,AIR:0)
Block(-5,32,-6,AIR:0)
Block(-5,32,-5,AIR:0)
Block(-5,33,-7,AIR:0)
Block(-5,33,-6,AIR:0)
Block(-5,33,-5,AIR:0)
Block(-5,34,-7,AIR:0)
Block(-5,34,-6,AIR:0)
Block(-5,34,-5,AIR:0)
Block(-5,35,-7,AIR:0)
Block(-5,35,-6,AIR:0)
Block(-5,35,-5,AIR:0)
Block(-5,36,-7,AIR:0)
Block(-5,36,-6,AIR:0)
Block(-5,36,-5,AIR:0)
Block(-5,37,-7,AIR:0)
Block(-5,37,-6,AIR:0)
Block(-5,37,-5,AIR:0)
Block(-5,38,-7,AIR:0)
Block(-5,38,-6,AIR:0)
Block(-5,38,-5,AIR:0)
Block(-5,39,-7,AIR:0)
Block(-5,39,-6,AIR:0)
Block(-5,39,-5,AIR:0)
Block(-5,40,-7,AIR:0)
Block(-5,40,-6,AIR:0)
Block(-5,40,-5,AIR:0)
Block(-5,41,-7,AIR:0)
Block(-5,41,-6,AIR:0)
Block(-5,41,-5,AIR:0)
Block(-5,42,-7,AIR:0)
Block(-5,42,-6,AIR:0)
Block(-5,42,-5,AIR:0)
Block(-5,43,-7,AIR:0)
Block(-5,43,-6,AIR:0)
Block(-5,43,-5,AIR:0)
Block(-5,44,-7,AIR:0)
Block(-5,44,-6,AIR:0)
Block(-5,44,-5,AIR:0)
Block(-5,45,-7,AIR:0)
Block(-5,45,-6,AIR:0)
Block(-5,45,-5,AIR:0)
Block(-5,46,-7,AIR:0)
Block(-5,46,-6,AIR:0)
Block(-5,46,-5,AIR:0)
Block(-5,47,-7,AIR:0)
Block(-5,47,-6,AIR:0)
Block(-5,47,-5,AIR:0)
Block(-5,48,-7,AIR:0)
Block(-5,48,-6,AIR:0)
Block(-5,48,-5,AIR:0)
Block(-5,49,-7,AIR:0)
Block(-5,49,-6,AIR:0)
Block(-5,49,-5,AIR:0)
Block(-5,50,-7,AIR:0)
Block(-5,50,-6,AIR:0)
Block(-5,50,-5,AIR:0)
Block(-5,51,-7,AIR:0)
Block(-5,51,-6,AIR:0)
Block(-5,51,-5,AIR:0)
Block(-5,52,-7,AIR:0)
Block(-5,52,-6,AIR:0)
Block(-5,52,-5,AIR:0)
Block(-5,53,-7,AIR:0)
Block(-5,53,-6,AIR:0)
Block(-5,53,-5,AIR:0)
Block(-5,54,-7,AIR:0)
Block(-5,54,-6,AIR:0)
Block(-5,54,-5,AIR:0)
Block(-5,55,-7,AIR:0)
Block(-5,55,-6,AIR:0)
Block(-5,55,-5,AIR:0)
Block(-5,56,-7,AIR:0)
Block(-5,56,-6,AIR:0)
Block(-5,56,-5,AIR:0)
Block(-5,57,-7,AIR:0)
Block(-5,57,-6,AIR:0)
Block(-5,57,-5,AIR:0)
Block(-5,58,-7,AIR:0)
Block(-5,58,-6,AIR:0)
Block(-5,58,-5,AIR:0)
Block(-5,59,-7,AIR:0)
Block(-5,59,-6,AIR:0)
Block(-5,59,-5,AIR:0)
Block(-5,60,-7,AIR:0)
Block(-5,60,-6,AIR:0)
Block(-5,60,-5,AIR:0)
Block(-5,61,-7,AIR:0)
Block(-5,61,-6,AIR:0)
Block(-5,61,-5,AIR:0)
Block(-5,62,-7,AIR:0)
Block(-5,62,-6,AIR:0)
Block(-5,62,-5,AIR:0)
Block(-5,63,-7,AIR:0)
Block(-5,63,-6,AIR:0)
Block(-5,63,-5,AIR:0)
Block(-4,-50,-7,COBBLESTONE:0)
Block(-4,-50,-6,COBBLESTONE:0)
Block(-4,-50,-5,COBBLESTONE:0)
Block(-4,-50,-4,LOG:0)
Block(-4,-49,-7,COBBLESTONE:0)
Block(-4,-49,-6,COBBLESTONE:0)
Block(-4,-49,-5,COBBLESTONE:0)
Block(-4,-49,-4,LOG:0)
Block(-4,-48,-7,COBBLESTONE:0)
Block(-4,-48,-6,COBBLESTONE:0)
Block(-4,-48,-5,COBBLESTONE:0)
Block(-4,-48,-4,LOG:0)
Block(-4,-47,-7,COBBLESTONE:0)
Block(-4,-47,-6,COBBLESTONE:0)
Block(-4,-47,-5,COBBLESTONE:0)
Block(-4,-47,-4,LOG:0)
Block(-4,-46,-7,COBBLESTONE:0)
Block(-4,-46,-6,COBBLESTONE:0)
Block(-4,-46,-5,COBBLESTONE:0)
Block(-4,-46,-4,LOG:0)
Block(-4,-45,-7,COBBLESTONE:0)
Block(-4,-45,-6,COBBLESTONE:0)
Block(-4,-45,-5,COBBLESTONE:0)
Block(-4,-45,-4,LOG:0)
Block(-4,-44,-7,COBBLESTONE:0)
Block(-4,-44,-6,COBBLESTONE:0)
Block(-4,-44,-5,COBBLESTONE:0)
Block(-4,-44,-4,LOG:0)
Block(-4,-43,-7,COBBLESTONE:0)
Block(-4,-43,-6,COBBLESTONE:0)
Block(-4,-43,-5,COBBLESTONE:0)
Block(-4,-43,-4,LOG:0)
Block(-4,-42,-7,COBBLESTONE:0)
Block(-4,-42,-6,COBBLESTONE:0)
Block(-4,-42,-5,COBBLESTONE:0)
Block(-4,-42,-4,LOG:0)
Block(-4,-41,-7,COBBLESTONE:0)
Block(-4,-41,-6,COBBLESTONE:0)
Block(-4,-41,-5,COBBLESTONE:0)
Block(-4,-41,-4,LOG:0)
Block(-4,-40,-7,COBBLESTONE:0)
Block(-4,-40,-6,COBBLESTONE:0)
Block(-4,-40,-5,COBBLESTONE:0)
Block(-4,-40,-4,LOG:0)
Block(-4,-39,-7,COBBLESTONE:0)
Block(-4,-39,-6,COBBLESTONE:0)
Block(-4,-39,-5,COBBLESTONE:0)
Block(-4,-39,-4,LOG:0)
Block(-4,-38,-7,COBBLESTONE:0)
Block(-4,-38,-6,COBBLESTONE:0)
Block(-4,-38,-5,COBBLESTONE:0)
Block(-4,-38,-4,LOG:0)
Block(-4,-37,-7,COBBLESTONE:0)
Block(-4,-37,-6,COBBLESTONE:0)
Block(-4,-37,-5,COBBLESTONE:0)
Block(-4,-37,-4,LOG:0)
Block(-4,-36,-7,COBBLESTONE:0)
Block(-4,-36,-6,COBBLESTONE:0)
Block(-4,-36,-5,COBBLESTONE:0)
Block(-4,-36,-4,LOG:0)
Block(-4,-35,-7,COBBLESTONE:0)
Block(-4,-35,-6,COBBLESTONE:0)
Block(-4,-35,-5,COBBLESTONE:0)
Block(-4,-35,-4,LOG:0)
Block(-4,-34,-7,COBBLESTONE:0)
Block(-4,-34,-6,COBBLESTONE:0)
Block(-4,-34,-5,COBBLESTONE:0)
Block(-4,-34,-4,LOG:0)
Block(-4,-33,-7,COBBLESTONE:0)
Block(-4,-33,-6,COBBLESTONE:0)
Block(-4,-33,-5,COBBLESTONE:0)
Block(-4,-33,-4,LOG:0)
Block(-4,-32,-7,COBBLESTONE:0)
Block(-4,-32,-6,COBBLESTONE:0)
Block(-4,-32,-5,COBBLESTONE:0)
Block(-4,-32,-4,LOG:0)
Block(-4,-31,-7,COBBLESTONE:0)
Block(-4,-31,-6,COBBLESTONE:0)
Block(-4,-31,-5,COBBLESTONE:0)
Block(-4,-31,-4,LOG:0)
Block(-4,-30,-7,COBBLESTONE:0)
Block(-4,-30,-6,COBBLESTONE:0)
Block(-4,-30,-5,COBBLESTONE:0)
Block(-4,-30,-4,LOG:0)
Block(-4,-29,-7,COBBLESTONE:0)
Block(-4,-29,-6,COBBLESTONE:0)
Block(-4,-29,-5,COBBLESTONE:0)
Block(-4,-29,-4,LOG:0)
Block(-4,-28,-7,COBBLESTONE:0)
Block(-4,-28,-6,COBBLESTONE:0)
Block(-4,-28,-5,COBBLESTONE:0)
Block(-4,-28,-4,LOG:0)
Block(-4,-27,-7,COBBLESTONE:0)
Block(-4,-27,-6,COBBLESTONE:0)
Block(-4,-27,-5,COBBLESTONE:0)
Block(-4,-27,-4,LOG:0)
Block(-4,-26,-7,COBBLESTONE:0)
Block(-4,-26,-6,COBBLESTONE:0)
Block(-4,-26,-5,COBBLESTONE:0)
Block(-4,-26,-4,LOG:0)
Block(-4,-25,-7,COBBLESTONE:0)
Block(-4,-25,-6,COBBLESTONE:0)
Block(-4,-25,-5,COBBLESTONE:0)
Block(-4,-25,-4,LOG:0)
Block(-4,-24,-7,COBBLESTONE:0)
Block(-4,-24,-6,COBBLESTONE:0)
Block(-4,-24,-5,COBBLESTONE:0)
Block(-4,-24,-4,LOG:0)
Block(-4,-23,-7,COBBLESTONE:0)
Block(-4,-23,-6,COBBLESTONE:0)
Block(-4,-23,-5,COBBLESTONE:0)
Block(-4,-23,-4,LOG:0)
Block(-4,-22,-7,COBBLESTONE:0)
Block(-4,-22,-6,COBBLESTONE:0)
Block(-4,-22,-5,COBBLESTONE:0)
Block(-4,-22,-4,LOG:0)
Block(-4,-21,-7,COBBLESTONE:0)
Block(-4,-21,-6,COBBLESTONE:0)
Block(-4,-21,-5,COBBLESTONE:0)
Block(-4,-21,-4,LOG:0)
Block(-4,-20,-7,COBBLESTONE:0)
Block(-4,-20,-6,COBBLESTONE:0)
Block(-4,-20,-5,COBBLESTONE:0)
Block(-4,-20,-4,LOG:0)
Block(-4,-19,-7,COBBLESTONE:0)
Block(-4,-19,-6,COBBLESTONE:0)
Block(-4,-19,-5,COBBLESTONE:0)
Block(-4,-19,-4,LOG:0)
Block(-4,-18,-7,STONE:5)
Block(-4,-18,-6,COBBLESTONE:0)
Block(-4,-18,-5,COBBLESTONE:0)
Block(-4,-18,-4,LOG:0)
Block(-4,-17,-7,STONE:5)
Block(-4,-17,-6,SMOOTH_BRICK:2)
Block(-4,-17,-5,STONE:5)
Block(-4,-17,-4,LOG:0)
Block(-4,-16,-7,COBBLESTONE:0)
Block(-4,-16,-6,COBBLESTONE:0)
Block(-4,-16,-5,STONE:5)
Block(-4,-16,-4,LOG:0)
Block(-4,-15,-7,STONE:5)
Block(-4,-15,-6,COBBLESTONE:0)
Block(-4,-15,-5,COBBLESTONE:0)
Block(-4,-15,-4,LOG:0)
Block(-4,-14,-7,SMOOTH_BRICK:2)
Block(-4,-14,-6,COBBLESTONE:0)
Block(-4,-14,-5,COBBLESTONE:0)
Block(-4,-14,-4,LOG:0)
Block(-4,-13,-7,COBBLESTONE:0)
Block(-4,-13,-6,STONE:5)
Block(-4,-13,-5,COBBLESTONE:0)
Block(-4,-13,-4,LOG:0)
Block(-4,-12,-7,COBBLESTONE:0)
Block(-4,-12,-6,STONE:5)
Block(-4,-12,-5,STONE:5)
Block(-4,-12,-4,LOG:0)
Block(-4,-11,-7,STONE:5)
Block(-4,-11,-6,STONE:5)
Block(-4,-11,-5,STONE:5)
Block(-4,-11,-4,LOG:0)
Block(-4,-10,-7,STONE:5)
Block(-4,-10,-6,COBBLESTONE:0)
Block(-4,-10,-5,COBBLESTONE:0)
Block(-4,-10,-4,LOG:0)
Block(-4,-9,-7,STONE:6)
Block(-4,-9,-6,STONE:6)
Block(-4,-9,-5,COBBLESTONE_STAIRS:1)
Block(-4,-9,-4,SMOOTH_STAIRS:1)
Block(-4,-8,-7,STONE:6)
Block(-4,-8,-6,STONE:6)
Block(-4,-7,-7,STONE:6)
Block(-4,-7,-6,STONE:6)
Block(-4,-6,-7,STONE:6)
Block(-4,-6,-6,STONE:6)
Block(-4,-5,-7,SMOOTH_BRICK:0)
Block(-4,-5,-6,COBBLESTONE_STAIRS:1)
Block(-4,-4,-7,LOG:0)
Block(-4,-3,-7,LOG:0)
Block(-4,-2,-7,LOG:0)
Block(-4,-1,-7,LOG:0)
Block(-4,0,-7,LOG:0)
Block(-4,1,-7,LOG:0)
Block(-4,2,-7,LOG:0)
Block(-4,3,-7,LOG:0)
Block(-4,4,-7,LOG:0)
Block(-4,5,-7,LOG:0)
Block(-4,6,-7,LOG:0)
Block(-4,7,-7,LOG:0)
Block(-4,8,-7,LOG:0)
Block(-4,9,-7,LOG:0)
Block(-4,10,-7,LOG:0)
Block(-4,11,-7,LOG:0)
Block(-4,12,-7,LOG:0)
Block(-4,13,-7,LOG:0)
Block(-4,14,-7,LOG:0)
Block(-4,15,-7,SMOOTH_STAIRS:1)
Block(-4,16,-7,AIR:0)
Block(-4,17,-7,AIR:0)
Block(-4,18,-7,AIR:0)
Block(-4,19,-7,AIR:0)
Block(-4,20,-7,AIR:0)
Block(-4,21,-7,AIR:0)
Block(-4,22,-7,AIR:0)
Block(-4,23,-7,AIR:0)
Block(-4,24,-7,AIR:0)
Block(-4,25,-7,AIR:0)
Block(-4,26,-7,AIR:0)
Block(-4,27,-7,AIR:0)
Block(-4,28,-7,AIR:0)
Block(-4,29,-7,AIR:0)
Block(-4,30,-7,AIR:0)
Block(-4,31,-7,AIR:0)
Block(-4,32,-7,AIR:0)
Block(-4,33,-7,AIR:0)
Block(-4,34,-7,AIR:0)
Block(-4,35,-7,AIR:0)
Block(-4,36,-7,AIR:0)
Block(-4,37,-7,AIR:0)
Block(-4,38,-7,AIR:0)
Block(-4,39,-7,AIR:0)
Block(-4,40,-7,AIR:0)
Block(-4,41,-7,AIR:0)
Block(-4,42,-7,AIR:0)
Block(-4,43,-7,AIR:0)
Block(-4,44,-7,AIR:0)
Block(-4,45,-7,AIR:0)
Block(-4,46,-7,AIR:0)
Block(-4,47,-7,AIR:0)
Block(-4,48,-7,AIR:0)
Block(-4,49,-7,AIR:0)
Block(-4,50,-7,AIR:0)
Block(-4,51,-7,AIR:0)
Block(-4,52,-7,AIR:0)
Block(-4,53,-7,AIR:0)
Block(-4,54,-7,AIR:0)
Block(-4,55,-7,AIR:0)
Block(-4,56,-7,AIR:0)
Block(-4,57,-7,AIR:0)
Block(-4,58,-7,AIR:0)
Block(-4,59,-7,AIR:0)
Block(-4,60,-7,AIR:0)
Block(-4,61,-7,AIR:0)
Block(-4,62,-7,AIR:0)
Block(-4,63,-7,AIR:0)
Block(-3,-50,-7,COBBLESTONE:0)
Block(-3,-50,-6,STAINED_CLAY:9)
Block(-3,-50,-5,COBBLESTONE:0)
Block(-3,-49,-7,COBBLESTONE:0)
Block(-3,-49,-6,STAINED_CLAY:9)
Block(-3,-49,-5,COBBLESTONE:0)
Block(-3,-48,-7,COBBLESTONE:0)
Block(-3,-48,-6,STAINED_CLAY:9)
Block(-3,-48,-5,COBBLESTONE:0)
Block(-3,-47,-7,COBBLESTONE:0)
Block(-3,-47,-6,STAINED_CLAY:9)
Block(-3,-47,-5,COBBLESTONE:0)
Block(-3,-46,-7,COBBLESTONE:0)
Block(-3,-46,-6,STAINED_CLAY:9)
Block(-3,-46,-5,COBBLESTONE:0)
Block(-3,-45,-7,COBBLESTONE:0)
Block(-3,-45,-6,STAINED_CLAY:9)
Block(-3,-45,-5,COBBLESTONE:0)
Block(-3,-44,-7,COBBLESTONE:0)
Block(-3,-44,-6,STAINED_CLAY:9)
Block(-3,-44,-5,COBBLESTONE:0)
Block(-3,-43,-7,COBBLESTONE:0)
Block(-3,-43,-6,STAINED_CLAY:9)
Block(-3,-43,-5,COBBLESTONE:0)
Block(-3,-42,-7,COBBLESTONE:0)
Block(-3,-42,-6,STAINED_CLAY:9)
Block(-3,-42,-5,COBBLESTONE:0)
Block(-3,-41,-7,COBBLESTONE:0)
Block(-3,-41,-6,STAINED_CLAY:9)
Block(-3,-41,-5,COBBLESTONE:0)
Block(-3,-40,-7,COBBLESTONE:0)
Block(-3,-40,-6,STAINED_CLAY:9)
Block(-3,-40,-5,COBBLESTONE:0)
Block(-3,-39,-7,COBBLESTONE:0)
Block(-3,-39,-6,STAINED_CLAY:9)
Block(-3,-39,-5,COBBLESTONE:0)
Block(-3,-38,-7,COBBLESTONE:0)
Block(-3,-38,-6,STAINED_CLAY:9)
Block(-3,-38,-5,COBBLESTONE:0)
Block(-3,-37,-7,COBBLESTONE:0)
Block(-3,-37,-6,STAINED_CLAY:9)
Block(-3,-37,-5,COBBLESTONE:0)
Block(-3,-36,-7,COBBLESTONE:0)
Block(-3,-36,-6,STAINED_CLAY:9)
Block(-3,-36,-5,COBBLESTONE:0)
Block(-3,-35,-7,COBBLESTONE:0)
Block(-3,-35,-6,STAINED_CLAY:9)
Block(-3,-35,-5,COBBLESTONE:0)
Block(-3,-34,-7,COBBLESTONE:0)
Block(-3,-34,-6,STAINED_CLAY:9)
Block(-3,-34,-5,COBBLESTONE:0)
Block(-3,-33,-7,COBBLESTONE:0)
Block(-3,-33,-6,STAINED_CLAY:9)
Block(-3,-33,-5,COBBLESTONE:0)
Block(-3,-32,-7,COBBLESTONE:0)
Block(-3,-32,-6,STAINED_CLAY:9)
Block(-3,-32,-5,COBBLESTONE:0)
Block(-3,-31,-7,COBBLESTONE:0)
Block(-3,-31,-6,STAINED_CLAY:9)
Block(-3,-31,-5,COBBLESTONE:0)
Block(-3,-30,-7,COBBLESTONE:0)
Block(-3,-30,-6,STAINED_CLAY:9)
Block(-3,-30,-5,COBBLESTONE:0)
Block(-3,-29,-7,COBBLESTONE:0)
Block(-3,-29,-6,STAINED_CLAY:9)
Block(-3,-29,-5,COBBLESTONE:0)
Block(-3,-28,-7,COBBLESTONE:0)
Block(-3,-28,-6,STAINED_CLAY:9)
Block(-3,-28,-5,COBBLESTONE:0)
Block(-3,-27,-7,COBBLESTONE:0)
Block(-3,-27,-6,STAINED_CLAY:9)
Block(-3,-27,-5,COBBLESTONE:0)
Block(-3,-26,-7,COBBLESTONE:0)
Block(-3,-26,-6,STAINED_CLAY:9)
Block(-3,-26,-5,COBBLESTONE:0)
Block(-3,-25,-7,COBBLESTONE:0)
Block(-3,-25,-6,STAINED_CLAY:9)
Block(-3,-25,-5,COBBLESTONE:0)
Block(-3,-24,-7,COBBLESTONE:0)
Block(-3,-24,-6,STAINED_CLAY:9)
Block(-3,-24,-5,COBBLESTONE:0)
Block(-3,-23,-7,COBBLESTONE:0)
Block(-3,-23,-6,STAINED_CLAY:9)
Block(-3,-23,-5,COBBLESTONE:0)
Block(-3,-22,-7,COBBLESTONE:0)
Block(-3,-22,-6,STAINED_CLAY:9)
Block(-3,-22,-5,COBBLESTONE:0)
Block(-3,-21,-7,COBBLESTONE:0)
Block(-3,-21,-6,STAINED_CLAY:9)
Block(-3,-21,-5,COBBLESTONE:0)
Block(-3,-20,-7,COBBLESTONE:0)
Block(-3,-20,-6,STAINED_CLAY:9)
Block(-3,-20,-5,COBBLESTONE:0)
Block(-3,-19,-7,STONE:5)
Block(-3,-19,-6,COBBLESTONE:0)
Block(-3,-19,-5,COBBLESTONE:0)
Block(-3,-18,-7,STONE:5)
Block(-3,-18,-6,STONE:5)
Block(-3,-18,-5,COBBLESTONE:0)
Block(-3,-17,-7,STAINED_CLAY:9)
Block(-3,-17,-6,SMOOTH_BRICK:1)
Block(-3,-17,-5,STONE:5)
Block(-3,-16,-7,COBBLESTONE:0)
Block(-3,-16,-6,STONE:5)
Block(-3,-16,-5,STONE:5)
Block(-3,-15,-7,STONE:5)
Block(-3,-15,-6,COBBLESTONE:0)
Block(-3,-15,-5,STONE:5)
Block(-3,-14,-7,COBBLESTONE:0)
Block(-3,-14,-6,COBBLESTONE:0)
Block(-3,-14,-5,STONE:5)
Block(-3,-13,-7,COBBLESTONE:0)
Block(-3,-13,-6,COBBLESTONE:0)
Block(-3,-13,-5,SMOOTH_BRICK:1)
Block(-3,-12,-7,SMOOTH_BRICK:1)
Block(-3,-12,-6,COBBLESTONE:0)
Block(-3,-12,-5,STONE:5)
Block(-3,-11,-7,SMOOTH_BRICK:1)
Block(-3,-11,-6,COBBLESTONE:0)
Block(-3,-11,-5,STAINED_CLAY:9)
Block(-3,-10,-7,COBBLESTONE:0)
Block(-3,-10,-6,COBBLESTONE:0)
Block(-3,-10,-5,COBBLESTONE:0)
Block(-3,-9,-7,LOG:0)
Block(-3,-9,-6,COBBLESTONE_STAIRS:1)
Block(-3,-9,-5,COBBLESTONE_STAIRS:3)
Block(-3,-8,-7,LOG:0)
Block(-3,-7,-7,LOG:0)
Block(-3,-6,-7,LOG:0)
Block(-3,-5,-7,LOG:0)
Block(-3,-4,-7,COBBLESTONE_STAIRS:1)
Block(-2,-50,-7,LOG:0)
Block(-2,-49,-7,LOG:0)
Block(-2,-48,-7,LOG:0)
Block(-2,-47,-7,LOG:0)
Block(-2,-46,-7,LOG:0)
Block(-2,-45,-7,LOG:0)
Block(-2,-44,-7,LOG:0)
Block(-2,-43,-7,LOG:0)
Block(-2,-42,-7,LOG:0)
Block(-2,-41,-7,LOG:0)
Block(-2,-40,-7,LOG:0)
Block(-2,-39,-7,LOG:0)
Block(-2,-38,-7,LOG:0)
Block(-2,-37,-7,LOG:0)
Block(-2,-36,-7,LOG:0)
Block(-2,-35,-7,LOG:0)
Block(-2,-34,-7,LOG:0)
Block(-2,-33,-7,LOG:0)
Block(-2,-32,-7,LOG:0)
Block(-2,-31,-7,LOG:0)
Block(-2,-30,-7,LOG:0)
Block(-2,-29,-7,LOG:0)
Block(-2,-28,-7,LOG:0)
Block(-2,-27,-7,LOG:0)
Block(-2,-26,-7,LOG:0)
Block(-2,-25,-7,LOG:0)
Block(-2,-24,-7,LOG:0)
Block(-2,-23,-7,LOG:0)
Block(-2,-22,-7,LOG:0)
Block(-2,-21,-7,LOG:0)
Block(-2,-20,-7,LOG:0)
Block(-2,-19,-7,LOG:0)
Block(-2,-18,-7,LOG:0)
Block(-2,-17,-7,LOG:0)
Block(-2,-16,-7,LOG:0)
Block(-2,-15,-7,LOG:0)
Block(-2,-14,-7,LOG:0)
Block(-2,-13,-7,LOG:0)
Block(-2,-12,-7,LOG:0)
Block(-2,-11,-7,LOG:0)
Block(-2,-10,-7,LOG:0)
Block(-2,-9,-7,SMOOTH_STAIRS:1)
Branch(0,0,16,true,originC22R8,NORTH,100.0,0)
