Author: BO3 BulkEdit (by LanToaster)
Description: This Object was Created with BO3_BulkEdit
SettingsMode: WriteDisable
Frequency: 100
SpawnHeight: highestBlock
UseCenterForHighestBlock: true
MinHeight: 0
MaxHeight: 255
InheritBO3: 
InheritBO3Rotation: NORTH
OverrideChildSettings: true
OverrideParentHeight: false
CanOverride: true
BranchFrequency: 0
BranchFrequencyGroup: 
MustBeBelowOther: false
MustBeInside: 
CannotBeInside: 
ReplacesBO3: 
MustBeInsideWorldBorders: false
CanSpawnOnWater: false
SpawnOnWaterOnly: false
SpawnUnderWater: false
SpawnAtWaterLevel: false
HeightOffset: 0
RemoveAir: true
ReplaceAbove: 
ReplaceBelow: cobblestone
ReplaceWithBiomeBlocks: true
ReplaceWithSurfaceBlock: GRASS
ReplaceWithGroundBlock: DIRT
ReplaceWithStoneBlock: STONE
SmoothRadius: 0
SmoothHeightOffset: 0
SmoothStartTop: false
SmoothStartWood: false
SmoothingSurfaceBlock: 
SmoothingGroundBlock: 
BO3Group: 
IsSpawnPoint: false
DoReplaceBlocks: true
Block(-2,-1,-7,GRAVEL:0)
Block(-1,-1,-7,GRAVEL:0)
Block(0,-1,-7,GRAVEL:0)
Block(-4,-1,-6,GRAVEL:0)
Block(-3,-1,-6,GRAVEL:0)
Block(-2,-1,-6,GRAVEL:0)
Block(-1,-1,-6,HARD_CLAY:0)
Block(0,-1,-6,HARD_CLAY:0)
Block(1,-1,-6,HARD_CLAY:0)
Block(2,-1,-6,HARD_CLAY:0)
Block(3,-1,-6,HARD_CLAY:0)
Block(4,-1,-6,HARD_CLAY:0)
Block(5,-1,-6,HARD_CLAY:0)
Block(-6,-1,-5,GRAVEL:0)
Block(-5,-1,-5,GRAVEL:0)
Block(-4,-1,-5,GRAVEL:0)
Block(-3,-1,-5,DIRT:0)
Block(-2,-1,-5,COBBLESTONE:0)
Block(-1,-1,-5,COBBLESTONE:0)
Block(0,-1,-5,FURNACE:3)
Block(1,-1,-5,COBBLESTONE:0)
Block(2,-1,-5,DIRT:1)
Block(3,-1,-5,GRAVEL:0)
Block(4,-1,-5,GRAVEL:0)
Block(5,-1,-5,HARD_CLAY:0)
Block(-6,-1,-4,GRASS_PATH:0)
Block(-5,-1,-4,LOG_2:1)
Block(-4,-1,-4,GRASS_PATH:0)
Block(-3,-1,-4,DIRT:0)
Block(-2,-1,-4,DIRT:0)
Block(-1,-1,-4,COBBLESTONE:0)
Block(0,-1,-4,LOG_2:8)
Block(1,-1,-4,COBBLESTONE_STAIRS:0)
Block(2,-1,-4,GRAVEL:0)
Block(3,-1,-4,DIRT:1)
Block(4,-1,-4,COBBLESTONE:0)
Block(5,-1,-4,HARD_CLAY:0)
Block(-6,-1,-3,GRASS_PATH:0)
Block(-5,-1,-3,COBBLESTONE:0)
Block(-4,-1,-3,GRAVEL:0)
Block(-3,-1,-3,DIRT:0)
Block(-2,-1,-3,DIRT:0)
Block(-1,-1,-3,COBBLESTONE:0)
Block(0,-1,-3,LOG_2:8)
Block(1,-1,-3,COBBLESTONE_STAIRS:0)
Block(2,-1,-3,GRAVEL:0)
Block(3,-1,-3,COBBLESTONE:0)
Block(4,-1,-3,GRAVEL:0)
Block(5,-1,-3,HARD_CLAY:0)
Block(-6,-1,-2,GRASS_PATH:0)
Block(-5,-1,-2,GRAVEL:0)
Block(-4,-1,-2,GRASS_PATH:0)
Block(-3,-1,-2,GRASS:0)
Block(-2,-1,-2,GRASS:0)
Block(-1,-1,-2,HARD_CLAY:0)
Block(0,-1,-2,HARD_CLAY:0)
Block(1,-1,-2,HARD_CLAY:0)
Block(2,-1,-2,HARD_CLAY:0)
Block(3,-1,-2,HARD_CLAY:0)
Block(4,-1,-2,HARD_CLAY:0)
Block(5,-1,-2,HARD_CLAY:0)
Block(-5,-1,-1,DIRT:1)
Block(-4,-1,-1,DIRT:1)
Block(-3,-1,-1,GRAVEL:0)
Block(-2,-1,-1,COBBLESTONE:0)
Block(-1,-1,-1,GRASS:0)
Block(0,-1,-1,GRASS:0)
Block(1,-1,-1,GRASS:0)
Block(2,-1,-1,GRASS:0)
Block(3,-1,-1,DIRT:1)
Block(4,-1,-1,GRASS_PATH:0)
Block(5,-1,-1,GRASS_PATH:0)
Block(-6,-1,0,DIRT:1)
Block(-5,-1,0,GRASS_PATH:0)
Block(-4,-1,0,GRASS_PATH:0)
Block(-3,-1,0,GRASS_PATH:0)
Block(-2,-1,0,DIRT:1)
Block(-1,-1,0,GRASS:0)
Block(0,-1,0,GRASS:0)
Block(1,-1,0,GRASS:0)
Block(2,-1,0,DIRT:1)
Block(3,-1,0,GRASS_PATH:0)
Block(-4,-1,1,GRASS_PATH:0)
Block(-3,-1,1,DIRT:1)
Block(-2,-1,1,GRASS_PATH:0)
Block(-1,-1,1,DIRT:1)
Block(0,-1,1,GRASS:0)
Block(1,-1,1,GRASS:0)
Block(2,-1,1,GRASS_PATH:0)
Block(3,-1,1,GRASS_PATH:0)
Block(4,-1,1,GRASS_PATH:0)
Block(-3,-1,2,GRASS_PATH:0)
Block(0,-1,2,DIRT:1)
Block(1,-1,2,DIRT:1)
Block(2,-1,2,GRASS_PATH:0)
Block(-2,-1,3,GRASS_PATH:0)
Block(-2,0,-7,TRAP_DOOR:4)
Block(-3,0,-6,TRAP_DOOR:6)
Block(-2,0,-6,STATIONARY_WATER:0)
Block(-1,0,-6,STAINED_CLAY:15)
Block(0,0,-6,STAINED_CLAY:7)
Block(1,0,-6,STAINED_CLAY:15)
Block(2,0,-6,STAINED_CLAY:7)
Block(3,0,-6,BRICK:0)
Block(4,0,-6,BRICK:0)
Block(5,0,-6,STAINED_CLAY:15)
Block(-3,0,-5,COBBLESTONE:0)
Block(-2,0,-5,COBBLESTONE:0)
Block(-1,0,-5,COBBLESTONE:0)
Block(1,0,-5,TRAP_DOOR:6)
Block(2,0,-5,WOOD_STEP:3)
Block(3,0,-5,LOG:11)
Block(4,0,-5,LADDER:3)
Block(5,0,-5,STAINED_CLAY:7)
Block(-5,0,-4,ANVIL:0)
Block(-3,0,-4,COBBLESTONE_STAIRS:0)
Block(-2,0,-4,MAGMA:0)
Block(-1,0,-4,COBBLESTONE:0)
Block(5,0,-4,BRICK:0)
Block(-3,0,-3,COBBLESTONE_STAIRS:3)
Block(-2,0,-3,COBBLESTONE:0)
Block(-1,0,-3,COBBLESTONE:0)
Block(5,0,-3,BRICK:0)
Block(-1,0,-2,STAINED_CLAY:7)
Block(0,0,-2,STAINED_CLAY:15)
Block(1,0,-2,BRICK:0)
Block(2,0,-2,STAINED_CLAY:15)
Block(3,0,-2,STAINED_CLAY:7)
Block(4,0,-2,JUNGLE_DOOR:5)
Block(5,0,-2,BRICK:0)
Block(-3,0,-1,COBBLE_WALL:0)
Block(-2,0,-1,WOOD_STAIRS:5)
Block(-1,0,-1,TRAP_DOOR:7)
Block(0,0,-1,DOUBLE_PLANT:1)
Block(1,0,-1,LONG_GRASS:1)
Block(2,0,-1,LONG_GRASS:1)
Block(3,0,-1,TRAP_DOOR:7)
Block(-2,0,0,TRAP_DOOR:6)
Block(-1,0,0,TRAP_DOOR:4)
Block(0,0,0,RED_ROSE:5)
Block(1,0,0,TRAP_DOOR:6)
Block(2,0,0,TRAP_DOOR:5)
Block(0,0,1,TRAP_DOOR:5)
Block(1,0,1,TRAP_DOOR:5)
Block(0,0,2,AIR)
Block(-1,1,-6,HARD_CLAY:0)
Block(0,1,-6,BRICK:0)
Block(1,1,-6,BRICK:0)
Block(2,1,-6,HARD_CLAY:0)
Block(3,1,-6,FENCE:0)
Block(4,1,-6,HARD_CLAY:0)
Block(5,1,-6,BRICK_STAIRS:1)
Block(-2,1,-5,COBBLESTONE:0)
Block(-1,1,-5,COBBLESTONE:0)
Block(4,1,-5,LADDER:3)
Block(5,1,-5,HARD_CLAY:0)
Block(-1,1,-4,COBBLESTONE:0)
Block(5,1,-4,FENCE:0)
RandomBlock(-2,1,-3,SMOOTH_BRICK:1,10,SMOOTH_BRICK:2,10,COBBLESTONE,10,MOSSY_COBBLESTONE,10,SMOOTH_BRICK,100)
Block(-1,1,-3,COBBLESTONE:0)
Block(5,1,-3,HARD_CLAY:0)
Block(-1,1,-2,HARD_CLAY:0)
Block(0,1,-2,BRICK:0)
Block(1,1,-2,HARD_CLAY:0)
Block(2,1,-2,FENCE:0)
Block(3,1,-2,HARD_CLAY:0)
Block(4,1,-2,JUNGLE_DOOR:9)
Block(5,1,-2,STAINED_CLAY:15)
Block(0,1,-1,DOUBLE_PLANT:10)
Block(0,2,-7,WOOD_STEP:8)
Block(4,2,-7,WOOD_STEP:11)
Block(-1,2,-6,BRICK:0)
Block(0,2,-6,HARD_CLAY:0)
Block(1,2,-6,HARD_CLAY:0)
Block(2,2,-6,HARD_CLAY:0)
Block(3,2,-6,HARD_CLAY:0)
Block(4,2,-6,HARD_CLAY:0)
Block(5,2,-6,BRICK:0)
Block(-2,2,-5,COBBLESTONE_STAIRS:2)
Block(-1,2,-5,HARD_CLAY:0)
Block(0,2,-5,WOOD_STEP:11)
Block(1,2,-5,LOG:11)
Block(2,2,-5,WOOD_STEP:11)
Block(3,2,-5,LOG:11)
Block(4,2,-5,LADDER:3)
Block(5,2,-5,STAINED_CLAY:15)
Block(-2,2,-4,COBBLESTONE_STAIRS:4)
Block(-1,2,-4,COBBLESTONE:0)
Block(0,2,-4,WOOD_STEP:11)
Block(1,2,-4,LOG:11)
Block(2,2,-4,WOOD_STEP:11)
Block(3,2,-4,LOG:11)
Block(4,2,-4,WOOD_STEP:11)
Block(5,2,-4,HARD_CLAY:0)
Block(-2,2,-3,COBBLESTONE_STAIRS:3)
Block(-1,2,-3,HARD_CLAY:0)
Block(0,2,-3,WOOD_STEP:11)
Block(1,2,-3,LOG:11)
Block(2,2,-3,WOOD_STEP:11)
Block(3,2,-3,LOG:11)
Block(4,2,-3,WOOD_STEP:11)
Block(5,2,-3,BRICK_STAIRS:5)
Block(-1,2,-2,STAINED_CLAY:7)
Block(0,2,-2,BRICK:0)
Block(1,2,-2,HARD_CLAY:0)
Block(2,2,-2,HARD_CLAY:0)
Block(3,2,-2,HARD_CLAY:0)
Block(4,2,-2,BRICK_STAIRS:7)
Block(5,2,-2,HARD_CLAY:0)
Block(0,2,-1,WOOD_STEP:8)
Block(1,2,-1,WOOD_STEP:11)
Block(5,2,-1,WOOD_STEP:11)
Block(-2,3,-7,WOOD_STEP:8)
Block(-1,3,-7,JUNGLE_WOOD_STAIRS:2)
Block(1,3,-7,WOOD_STEP:0)
Block(2,3,-7,WOOD_DOUBLE_STEP:0)
Block(3,3,-7,WOOD_STEP:3)
Block(5,3,-7,JUNGLE_WOOD_STAIRS:2)
Block(6,3,-7,WOOD_STEP:3)
Block(-1,3,-6,WOOD:0)
Block(0,3,-6,HAY_BLOCK:0)
Block(1,3,-6,HAY_BLOCK:4)
Block(2,3,-6,WOOD:3)
Block(3,3,-6,WOOD:3)
Block(4,3,-6,WOOD:3)
Block(5,3,-6,LOG:3)
Block(6,3,-6,JUNGLE_WOOD_STAIRS:7)
Block(-1,3,-5,WOOD:0)
Block(0,3,-5,BED_BLOCK:9)
RandomBlock(1,3,-5,BED_BLOCK:1,../../NBT/beds/JungleBed01.nbt,10,BED_BLOCK:1,../../NBT/beds/JungleBed02.nbt,10,BED_BLOCK:1,../../NBT/beds/JungleBed03.nbt,10,BED_BLOCK:1,../../NBT/beds/JungleBed04.nbt,10,BED_BLOCK:1,../../NBT/beds/JungleBed05.nbt,10,BED_BLOCK:1,../../NBT/beds/JungleBed06.nbt,10,BED_BLOCK:1,../../NBT/beds/JungleBed07.nbt,100)
Block(4,3,-5,LADDER:3)
Block(5,3,-5,WOOD:0)
RandomBlock(-2,3,-4,SMOOTH_BRICK:1,10,SMOOTH_BRICK:2,10,COBBLESTONE,10,MOSSY_COBBLESTONE,10,SMOOTH_BRICK,100)
Block(-1,3,-4,LOG:3)
Block(0,3,-4,WORKBENCH:0)
Block(5,3,-4,WOOD:0)
Block(-1,3,-3,WOOD:0)
RandomBlock(0,3,-3,AIR:0,20,CHEST:5,../../../../Chests/Loot/JunkChest_1.nbt,10,CHEST:5,../../../../Chests/Loot/JunkChest_2.nbt,10,CHEST:5,../../../../Chests/Loot/JunkChest_3.nbt,10,CHEST:5,../../../../Chests/Loot/JunkChest_4.nbt,10,CHEST:5,../../../../Chests/Loot/JunkChest_5.nbt,10,CHEST:5,../../../../Chests/Lore/JungleLore_1.nbt,1,CHEST:5,../../../../Chests/Lore/JungleLore_2.nbt,1,CHEST:5,../../../../Chests/Lore/JungleLore_3.nbt,1,CHEST:5,../../../../Chests/Lore/JungleLore_4.nbt,1,CHEST:5,../../../../Chests/Lore/JungleLore_5.nbt,1,CHEST:5,../../../../Chests/Loot/Common1.nbt,10,CHEST:5,../../../../Chests/Loot/Common2.nbt,10,CHEST:5,../../../../Chests/Loot/Common3.nbt,10,CHEST:5,../../../../Chests/Loot/Common4.nbt,10,CHEST:5,../../../../Chests/Loot/Common5.nbt,10,CHEST:5,../../../../Chests/Loot/Common6.nbt,10,CHEST:5,../../../../Chests/Loot/Common7.nbt,10,CHEST:5,../../../../Chests/Loot/Common8.nbt,10,CHEST:5,../../../../Chests/Loot/Common9.nbt,10,CHEST:5,../../../../Chests/Loot/Common10.nbt,10,CHEST:5,../../../../Chests/Loot/Common10.nbt,11,CHEST:5,../../../../Chests/Loot/Common12.nbt,10,CHEST:5,../../../../Chests/Loot/Common13.nbt,10,CHEST:5,../../../../Chests/Loot/Common14.nbt,10,CHEST:5,../../../../Chests/Loot/Common15.nbt,10,CHEST:5,../../../../Chests/Lore/JungleLore_1.nbt,2,CHEST:5,../../../../Chests/Lore/JungleLore_3.nbt,2,CHEST:5,../../../../Chests/Lore/JungleLore_4.nbt,2,CHEST:5,../../../../Chests/Lore/JungleLore_5.nbt,2,CHEST:5,../../../../Chests/Lore/JungleLore_5.nbt,2,CHEST:5,../../../../Chests/Loot/Rare1.nbt,5,CHEST:5,../../../../Chests/Loot/Rare2.nbt,5,CHEST:5,../../../../Chests/Loot/Rare3.nbt,5,CHEST:5,../../../../Chests/Loot/Rare4.nbt,5,CHEST:5,../../../../Chests/Loot/Rare5.nbt,5,CHEST:5,../../../../Chests/Loot/Rare6.nbt,5,CHEST:5,../../../../Chests/Loot/Rare7.nbt,5,CHEST:5,../../../../Chests/Loot/Rare8.nbt,5,CHEST:5,../../../../Chests/Loot/Rare9.nbt,5,CHEST:5,../../../../Chests/Loot/Rare10.nbt,5,CHEST:5,../../../../Chests/Loot/Rare11.nbt,5,CHEST:5,../../../../Chests/Loot/Rare12.nbt,5,CHEST:5,../../../../Chests/Loot/Rare13.nbt,5,CHEST:5,../../../../Chests/Loot/Rare14.nbt,5,CHEST:5,../../../../Chests/Loot/Rare15.nbt,5,CHEST:5,../../../../Chests/Loot/Epic1.nbt,2,CHEST:5,../../../../Chests/Loot/Epic2.nbt,2,CHEST:5,../../../../Chests/Loot/Epic3.nbt,2,CHEST:5,../../../../Chests/Loot/Epic4.nbt,2,CHEST:5,../../../../Chests/Loot/Epic5.nbt,2,CHEST:5,../../../../Chests/Loot/Epic6.nbt,2,CHEST:5,../../../../Chests/Loot/Epic7.nbt,2,CHEST:5,../../../../Chests/Loot/Epic8.nbt,2,CHEST:5,../../../../Chests/Loot/Epic9.nbt,2,CHEST:5,../../../../Chests/Loot/Epic10.nbt,2,CHEST:5,../../../../Chests/Loot/Epic11.nbt,2,CHEST:5,../../../../Chests/Loot/Epic12.nbt,2,CHEST:5,../../../../Chests/Loot/Epic13.nbt,2,CHEST:5,../../../../Chests/Loot/Epic14.nbt,2,CHEST:5,../../../../Chests/Loot/Epic15.nbt,5,CHEST:5,../../../../Chests/Loot/Rare1.nbt,5,CHEST:5,../../../../Chests/Loot/Rare2.nbt,5,CHEST:5,../../../../Chests/Loot/Rare3.nbt,5,CHEST:5,../../../../Chests/Loot/Rare4.nbt,5,CHEST:5,../../../../Chests/Loot/Rare5.nbt,10,CHEST:5,../../../../Chests/Loot/Rare6.nbt,10,CHEST:5,../../../../Chests/Loot/Rare7.nbt,10,CHEST:5,../../../../Chests/Loot/Rare8.nbt,10,CHEST:5,../../../../Chests/Loot/Rare9.nbt,10,CHEST:5,../../../../Chests/Loot/Rare10.nbt,15,CHEST:5,../../../../Chests/Loot/Rare11.nbt,15,CHEST:5,../../../../Chests/Loot/Rare12.nbt,15,CHEST:5,../../../../Chests/Loot/Rare13.nbt,15,CHEST:5,../../../../Chests/Loot/Rare14.nbt,15,CHEST:5,../../../../Chests/Loot/Rare15.nbt,15,CHEST:5,../../../../Chests/Loot/Epic15.nbt,100)
Block(5,3,-3,LOG:3)
Block(-2,3,-2,WOOD_STEP:11)
Block(-1,3,-2,WOOD:0)
Block(0,3,-2,WOOD:3)
Block(1,3,-2,HAY_BLOCK:0)
Block(2,3,-2,LOG:3)
Block(3,3,-2,WOOD:3)
Block(4,3,-2,LOG:3)
Block(5,3,-2,WOOD:0)
Block(6,3,-2,JUNGLE_WOOD_STAIRS:6)
Block(-2,3,-1,WOOD_STAIRS:3)
Block(-1,3,-1,JUNGLE_WOOD_STAIRS:3)
Block(2,3,-1,WOOD_STAIRS:3)
Block(3,3,-1,WOOD_STEP:3)
Block(4,3,-1,WOOD_STEP:3)
Block(5,3,-1,JUNGLE_WOOD_STAIRS:3)
Block(6,3,-1,WOOD_STEP:0)
Block(-2,4,-6,WOOD_STEP:3)
Block(-1,4,-6,WOOD:3)
Block(0,4,-6,HAY_BLOCK:0)
Block(1,4,-6,WOOD:3)
Block(2,4,-6,HAY_BLOCK:0)
Block(3,4,-6,WOOD_DOUBLE_STEP:3)
Block(4,4,-6,HAY_BLOCK:4)
Block(5,4,-6,WOOD:0)
Block(6,4,-6,JUNGLE_WOOD_STAIRS:2)
Block(-2,4,-5,JUNGLE_WOOD_STAIRS:7)
Block(-1,4,-5,WOOD:0)
Block(5,4,-5,WOOD:0)
Block(6,4,-5,WOOD_DOUBLE_STEP:3)
Block(-2,4,-4,COBBLESTONE_STAIRS:4)
Block(-1,4,-4,LOG:3)
Block(5,4,-4,WOOD:0)
Block(-2,4,-3,WOOD_STEP:11)
Block(-1,4,-3,WOOD:0)
Block(1,4,-3,WOOD_STEP:11)
Block(5,4,-3,LOG:3)
Block(6,4,-3,WOOD_STEP:11)
Block(-2,4,-2,JUNGLE_WOOD_STAIRS:3)
Block(-1,4,-2,HAY_BLOCK:0)
Block(0,4,-2,HAY_BLOCK:8)
Block(1,4,-2,WOOD_STEP:0)
Block(2,4,-2,LOG:3)
Block(3,4,-2,FENCE:0)
Block(4,4,-2,LOG:3)
Block(5,4,-2,WOOD_STAIRS:3)
Block(6,4,-2,WOOD_STEP:3)
Block(3,4,-1,TRAP_DOOR:7)
Block(-2,5,-5,JUNGLE_WOOD_STAIRS:2)
Block(-1,5,-5,HAY_BLOCK:0)
Block(0,5,-5,HAY_BLOCK:0)
Block(1,5,-5,WOOD_STEP:3)
Block(2,5,-5,WOOD_STAIRS:2)
Block(3,5,-5,WOOD:3)
Block(4,5,-5,WOOD:3)
Block(5,5,-5,WOOD_STAIRS:2)
Block(6,5,-5,JUNGLE_WOOD_STAIRS:2)
Block(-2,5,-4,WOOD_DOUBLE_STEP:3)
Block(-1,5,-4,LOG:3)
Block(1,5,-4,WOOD_STEP:11)
Block(2,5,-4,WOOD_STEP:11)
Block(5,5,-4,WOOD_STEP:11)
Block(6,5,-4,JUNGLE_WOOD_STAIRS:1)
Block(-2,5,-3,WOOD_STEP:3)
Block(-1,5,-3,WOOD:3)
Block(0,5,-3,HAY_BLOCK:8)
Block(1,5,-3,WOOD_STAIRS:3)
Block(2,5,-3,WOOD_STAIRS:3)
Block(3,5,-3,WOOD:3)
Block(4,5,-3,WOOD_STAIRS:3)
Block(5,5,-3,HAY_BLOCK:0)
Block(6,5,-3,WOOD_STEP:3)
Block(2,5,-2,WOOD_STAIRS:0)
Block(3,5,-2,LOG:7)
Block(4,5,-2,JUNGLE_WOOD_STAIRS:1)
Block(2,5,-1,JUNGLE_WOOD_STAIRS:3)
Block(3,5,-1,WOOD_STEP:11)
Block(4,5,-1,WOOD_STAIRS:3)
Block(-1,6,-4,COBBLESTONE:0)
Block(0,6,-4,WOOD_STEP:3)
Block(2,6,-4,JUNGLE_WOOD_STAIRS:2)
Block(3,6,-4,WOOD_STEP:0)
Block(4,6,-4,WOOD_STEP:3)
Block(3,6,-3,WOOD_STEP:3)
Block(3,6,-2,WOOD_STEP:3)
Block(-1,7,-4,COBBLE_WALL:0)
Entity(0,0,2,minecraft:villager,1,../../NBT/entities/tribalsmith.txt)
