Author: NLBlackEagle
Description: No description given
SettingsMode: WriteDisable
Frequency: 0
SpawnHeight: highestBlock
UseCenterForHighestBlock: true
MinHeight: 0
MaxHeight: 255
InheritBO3: 
InheritBO3Rotation: NORTH
OverrideChildSettings: true
OverrideParentHeight: false
CanOverride: false
BranchFrequency: 0
BranchFrequencyGroup: 
MustBeBelowOther: false
MustBeInside: 
CannotBeInside: 
ReplacesBO3: 
MustBeInsideWorldBorders: false
CanSpawnOnWater: true
SpawnOnWaterOnly: false
SpawnUnderWater: false
SpawnAtWaterLevel: false
HeightOffset: 0
RemoveAir: true
ReplaceAbove: 
ReplaceBelow: 
ReplaceWithBiomeBlocks: true
ReplaceWithSurfaceBlock: GRASS
ReplaceWithGroundBlock: DIRT
ReplaceWithStoneBlock: STONE
SmoothRadius: 0
SmoothHeightOffset: 0
SmoothStartTop: false
SmoothStartWood: false
SmoothingSurfaceBlock: 
SmoothingGroundBlock: 
BO3Group: 
IsSpawnPoint: false
DoReplaceBlocks: true
E(-7,31,-1,stray,1,../NBT/Mobs/FrozenSailor.txt)
E(-5,35,0,stray,1,../NBT/Mobs/FrozenSailor.txt)
E(-5,35,5,stray,1,../NBT/Mobs/FrozenSailor.txt)
E(-1,36,2,stray,1,../NBT/Mobs/FrozenSailor.txt)
E(0,36,-1,stray,1,../NBT/Mobs/FrozenSailor.txt)
Block(-8,18,-7,PACKED_ICE:0)
Block(-8,18,-6,PACKED_ICE:0)
Block(-8,18,-5,PACKED_ICE:0)
Block(-8,18,-4,PACKED_ICE:0)
Block(-8,18,-3,PACKED_ICE:0)
Block(-8,18,-2,PACKED_ICE:0)
Block(-8,18,-1,PACKED_ICE:0)
Block(-8,18,0,PACKED_ICE:0)
Block(-8,18,1,PACKED_ICE:0)
Block(-8,18,2,PACKED_ICE:0)
Block(-8,18,3,PACKED_ICE:0)
Block(-8,18,4,PACKED_ICE:0)
Block(-8,18,5,PACKED_ICE:0)
Block(-8,18,6,PACKED_ICE:0)
Block(-8,18,7,PACKED_ICE:0)
Block(-8,18,8,PACKED_ICE:0)
Block(-8,19,-7,PACKED_ICE:0)
Block(-8,19,-6,PACKED_ICE:0)
Block(-8,19,-5,PACKED_ICE:0)
Block(-8,19,-4,PACKED_ICE:0)
Block(-8,19,-3,PACKED_ICE:0)
Block(-8,19,-2,PACKED_ICE:0)
Block(-8,19,-1,PACKED_ICE:0)
Block(-8,19,0,PACKED_ICE:0)
Block(-8,19,1,PACKED_ICE:0)
Block(-8,19,2,PACKED_ICE:0)
Block(-8,19,3,PACKED_ICE:0)
Block(-8,19,4,PACKED_ICE:0)
Block(-8,19,5,PACKED_ICE:0)
Block(-8,19,6,PACKED_ICE:0)
Block(-8,19,7,PACKED_ICE:0)
Block(-8,19,8,PACKED_ICE:0)
Block(-8,20,-7,PACKED_ICE:0)
Block(-8,20,-6,PACKED_ICE:0)
Block(-8,20,-5,PACKED_ICE:0)
Block(-8,20,-4,PACKED_ICE:0)
Block(-8,20,-3,PACKED_ICE:0)
Block(-8,20,-2,PACKED_ICE:0)
Block(-8,20,-1,PACKED_ICE:0)
Block(-8,20,0,PACKED_ICE:0)
Block(-8,20,1,PACKED_ICE:0)
Block(-8,20,2,PACKED_ICE:0)
Block(-8,20,3,PACKED_ICE:0)
Block(-8,20,4,PACKED_ICE:0)
Block(-8,20,5,PACKED_ICE:0)
Block(-8,20,6,PACKED_ICE:0)
Block(-8,20,7,PACKED_ICE:0)
Block(-8,20,8,PACKED_ICE:0)
Block(-8,21,-7,PACKED_ICE:0)
Block(-8,21,-6,PACKED_ICE:0)
Block(-8,21,-5,PACKED_ICE:0)
Block(-8,21,-4,PACKED_ICE:0)
Block(-8,21,-3,PACKED_ICE:0)
Block(-8,21,-2,PACKED_ICE:0)
Block(-8,21,-1,PACKED_ICE:0)
Block(-8,21,0,PACKED_ICE:0)
Block(-8,21,1,PACKED_ICE:0)
Block(-8,21,2,PACKED_ICE:0)
Block(-8,21,3,PACKED_ICE:0)
Block(-8,21,4,PACKED_ICE:0)
Block(-8,21,5,PACKED_ICE:0)
Block(-8,21,6,PACKED_ICE:0)
Block(-8,21,7,PACKED_ICE:0)
Block(-8,21,8,PACKED_ICE:0)
Block(-8,22,-6,ICE:0)
Block(-8,22,-5,ICE:0)
Block(-8,22,-4,ICE:0)
Block(-8,22,-3,PACKED_ICE:0)
Block(-8,22,-2,PACKED_ICE:0)
Block(-8,22,-1,ICE:0)
Block(-8,22,0,ICE:0)
Block(-8,22,1,WOOD:5)
Block(-8,22,2,PACKED_ICE:0)
Block(-8,22,3,PACKED_ICE:0)
Block(-8,22,4,PACKED_ICE:0)
Block(-8,22,5,PACKED_ICE:0)
Block(-8,22,6,PACKED_ICE:0)
Block(-8,22,7,PACKED_ICE:0)
Block(-8,22,8,ICE:0)
Block(-8,23,-6,PACKED_ICE:0)
Block(-8,23,-5,ICE:0)
Block(-8,23,-4,ICE:0)
Block(-8,23,-3,ICE:0)
Block(-8,23,-2,ICE:0)
Block(-8,23,-1,ICE:0)
Block(-8,23,0,ICE:0)
Block(-8,23,1,LOG_2:1)
Block(-8,23,2,PACKED_ICE:0)
Block(-8,23,3,PACKED_ICE:0)
Block(-8,23,4,ICE:0)
Block(-8,23,5,ICE:0)
Block(-8,23,6,ICE:0)
Block(-8,23,7,ICE:0)
Block(-8,23,8,ICE:0)
Block(-8,24,-7,ICE:0)
Block(-8,24,-6,ICE:0)
Block(-8,24,-5,ICE:0)
Block(-8,24,-4,ICE:0)
Block(-8,24,-3,ICE:0)
Block(-8,24,-2,ICE:0)
Block(-8,24,-1,ICE:0)
Block(-8,24,0,ICE:0)
Block(-8,24,1,LOG_2:1)
Block(-8,24,2,PACKED_ICE:0)
Block(-8,24,3,ICE:0)
Block(-8,24,4,ICE:0)
Block(-8,24,5,PACKED_ICE:0)
Block(-8,24,6,ICE:0)
Block(-8,24,7,ICE:0)
Block(-8,24,8,ICE:0)
Block(-8,25,-7,PACKED_ICE:0)
Block(-8,25,-6,PACKED_ICE:0)
Block(-8,25,-5,PACKED_ICE:0)
Block(-8,25,-4,PACKED_ICE:0)
Block(-8,25,-3,PACKED_ICE:0)
Block(-8,25,-2,PACKED_ICE:0)
Block(-8,25,-1,PACKED_ICE:0)
Block(-8,25,0,PACKED_ICE:0)
Block(-8,25,1,LOG_2:1)
Block(-8,25,2,PACKED_ICE:0)
Block(-8,25,3,PACKED_ICE:0)
Block(-8,25,4,PACKED_ICE:0)
Block(-8,25,5,ICE:0)
Block(-8,25,6,ICE:0)
Block(-8,25,7,ICE:0)
Block(-8,25,8,ICE:0)
Block(-8,26,-7,PACKED_ICE:0)
Block(-8,26,-6,PACKED_ICE:0)
Block(-8,26,-5,PACKED_ICE:0)
Block(-8,26,-3,PACKED_ICE:0)
Block(-8,26,-2,PACKED_ICE:0)
Block(-8,26,-1,LOG_2:1)
Block(-8,26,0,LOG_2:1)
Block(-8,26,1,LOG:1)
Block(-8,26,2,LOG_2:1)
Block(-8,26,3,LOG_2:1)
Block(-8,26,4,PACKED_ICE:0)
Block(-8,26,5,PACKED_ICE:0)
Block(-8,26,6,PACKED_ICE:0)
Block(-8,26,7,PACKED_ICE:0)
Block(-8,26,8,ICE:0)
Block(-8,27,-7,ICE:0)
Block(-8,27,-6,PACKED_ICE:0)
Block(-8,27,-5,PACKED_ICE:0)
Block(-8,27,-3,LOG_2:1)
Block(-8,27,-2,LOG_2:1)
Block(-8,27,1,LOG:1)
Block(-8,27,4,LOG_2:1)
Block(-8,27,5,LOG_2:1)
Block(-8,27,6,PACKED_ICE:0)
Block(-8,27,7,ICE:0)
Block(-8,27,8,ICE:0)
Block(-8,28,-6,PACKED_ICE:0)
Block(-8,28,-4,LOG_2:1)
Block(-8,28,-2,LOG_2:1)
Block(-8,28,1,LOG:1)
Block(-8,28,4,LOG_2:1)
Block(-8,28,6,LOG_2:1)
Block(-8,28,7,ICE:0)
Block(-8,29,-6,PACKED_ICE:0)
Block(-8,29,-5,ICE:0)
Block(-8,29,-4,WOOD:5)
Block(-8,29,-3,ICE:0)
Block(-8,29,-2,PACKED_ICE:0)
Block(-8,29,-1,PACKED_ICE:0)
Block(-8,29,0,PACKED_ICE:0)
Block(-8,29,1,LOG:1)
Block(-8,29,2,WOOD:5)
Block(-8,29,3,ICE:0)
Block(-8,29,4,WOOD:5)
Block(-8,29,5,WOOD:5)
Block(-8,29,6,WOOD:5)
Block(-8,30,-5,ICE:0)
Block(-8,30,-4,WOOD:5)
Block(-8,30,-3,TRIPWIRE_HOOK:0)
Block(-8,30,1,LOG:1)
Block(-8,30,4,TRIPWIRE:0)
Block(-8,30,5,ICE:0)
Block(-8,30,6,WOOD:5)
Block(-8,31,-5,ICE:0)
Block(-8,31,-4,WOOD:5)
Block(-8,31,-3,WOOD_STEP:5)
Block(-8,31,1,LOG:1)
Block(-8,31,5,ICE:0)
Block(-8,31,6,WOOD:5)
Block(-8,31,7,PACKED_ICE:0)
Block(-8,32,-6,PACKED_ICE:0)
Block(-8,32,-5,ICE:0)
Block(-8,32,-4,STAINED_CLAY:9)
Block(-8,32,-3,WOOD_STEP:13)
Block(-8,32,-2,WOOD_STEP:13)
Block(-8,32,-1,WOOD_STEP:13)
Block(-8,32,0,WOOD_STEP:13)
Block(-8,32,1,LOG:1)
Block(-8,32,2,ICE:0)
Block(-8,32,3,WOOD_STEP:13)
Block(-8,32,4,ICE:0)
Block(-8,32,5,ICE:0)
Block(-8,32,6,STAINED_CLAY:9)
Block(-8,32,7,PACKED_ICE:0)
Block(-8,33,-6,PACKED_ICE:0)
Block(-8,33,-5,PACKED_ICE:0)
Block(-8,33,-4,DISPENSER:2)
Block(-8,33,-3,CONCRETE:15)
Block(-8,33,-2,SPRUCE_WOOD_STAIRS:3)
Block(-8,33,1,LOG:1)
Block(-8,33,4,SPRUCE_WOOD_STAIRS:2)
Block(-8,33,5,CONCRETE:15)
Block(-8,33,6,DISPENSER:3)
Block(-8,33,7,PACKED_ICE:0)
Block(-8,33,8,ICE:0)
Block(-8,34,-7,ICE:0)
Block(-8,34,-6,PACKED_ICE:0)
Block(-8,34,-5,PACKED_ICE:0)
Block(-8,34,-4,STAINED_CLAY:9)
Block(-8,34,1,LOG:1)
Block(-8,34,6,STAINED_CLAY:9)
Block(-8,34,7,PACKED_ICE:0)
Block(-8,34,8,PACKED_ICE:0)
Block(-8,35,-7,PACKED_ICE:0)
Block(-8,35,-6,PACKED_ICE:0)
Block(-8,35,-5,DARK_OAK_STAIRS:6)
Block(-8,35,-4,STAINED_CLAY:9)
Block(-8,35,-3,STAINED_CLAY:9)
Block(-8,35,-2,PACKED_ICE:0)
Block(-8,35,-1,STAINED_CLAY:9)
Block(-8,35,0,STAINED_CLAY:9)
Block(-8,35,1,LOG:1)
Block(-8,35,2,STAINED_CLAY:9)
Block(-8,35,3,STAINED_CLAY:9)
Block(-8,35,4,STAINED_CLAY:9)
Block(-8,35,5,STAINED_CLAY:9)
Block(-8,35,6,STAINED_CLAY:9)
Block(-8,35,7,DARK_OAK_STAIRS:7)
Block(-8,35,8,PACKED_ICE:0)
Block(-8,36,-6,ICE:0)
Block(-8,36,-5,PACKED_ICE:0)
Block(-8,36,-4,STAINED_CLAY:9)
Block(-8,36,-3,PACKED_ICE:0)
Block(-8,36,-2,PACKED_ICE:0)
Block(-8,36,-1,PACKED_ICE:0)
Block(-8,36,0,PACKED_ICE:0)
Block(-8,36,1,LOG_2:1)
Block(-8,36,2,PACKED_ICE:0)
Block(-8,36,3,WOOD_STEP:1)
Block(-8,36,4,WOOD_STEP:1)
Block(-8,36,5,WOOD_STEP:1)
Block(-8,36,6,STAINED_CLAY:9)
Block(-8,36,7,PACKED_ICE:0)
Block(-8,36,8,PACKED_ICE:0)
Block(-8,37,-4,ICE:0)
Block(-8,37,-3,ICE:0)
Block(-8,37,-2,ICE:0)
Block(-8,37,-1,PACKED_ICE:0)
Block(-8,37,0,PACKED_ICE:0)
Block(-8,37,1,LOG:1)
Block(-8,37,6,ICE:0)
Block(-8,37,7,ICE:0)
Block(-8,38,-3,PACKED_ICE:0)
Block(-8,38,-1,ICE:0)
Block(-8,38,0,PACKED_ICE:0)
Block(-8,38,1,LOG:1)
Block(-8,39,0,ICE:0)
Block(-8,39,1,LOG:1)
Block(-8,40,0,ICE:0)
Block(-8,40,1,LOG:1)
Block(-8,41,0,ICE:0)
Block(-8,41,1,LOG:1)
Block(-8,42,0,ICE:0)
Block(-8,42,1,LOG:1)
Block(-8,42,2,ICE:0)
Block(-8,43,0,ICE:0)
Block(-8,43,1,LOG:1)
Block(-8,43,2,ICE:0)
Block(-8,44,1,LOG:1)
Block(-8,44,2,ICE:0)
Block(-8,45,1,LOG:1)
Block(-8,46,0,ICE:0)
Block(-8,46,1,LOG:1)
Block(-8,46,2,ICE:0)
Block(-8,47,0,ICE:0)
Block(-8,47,1,LOG:1)
Block(-8,47,2,ICE:0)
Block(-8,48,1,LOG_2:1)
Block(-8,49,1,SNOW:2)
Block(-7,18,-7,PACKED_ICE:0)
Block(-7,18,-6,PACKED_ICE:0)
Block(-7,18,-5,PACKED_ICE:0)
Block(-7,18,-4,PACKED_ICE:0)
Block(-7,18,-3,PACKED_ICE:0)
Block(-7,18,-2,PACKED_ICE:0)
Block(-7,18,-1,PACKED_ICE:0)
Block(-7,18,0,PACKED_ICE:0)
Block(-7,18,1,PACKED_ICE:0)
Block(-7,18,2,PACKED_ICE:0)
Block(-7,18,3,PACKED_ICE:0)
Block(-7,18,4,PACKED_ICE:0)
Block(-7,18,5,PACKED_ICE:0)
Block(-7,18,6,PACKED_ICE:0)
Block(-7,18,7,PACKED_ICE:0)
Block(-7,18,8,PACKED_ICE:0)
Block(-7,19,-7,PACKED_ICE:0)
Block(-7,19,-6,PACKED_ICE:0)
Block(-7,19,-5,PACKED_ICE:0)
Block(-7,19,-4,PACKED_ICE:0)
Block(-7,19,-3,PACKED_ICE:0)
Block(-7,19,-2,PACKED_ICE:0)
Block(-7,19,-1,PACKED_ICE:0)
Block(-7,19,0,PACKED_ICE:0)
Block(-7,19,1,PACKED_ICE:0)
Block(-7,19,2,PACKED_ICE:0)
Block(-7,19,3,PACKED_ICE:0)
Block(-7,19,4,PACKED_ICE:0)
Block(-7,19,5,PACKED_ICE:0)
Block(-7,19,6,PACKED_ICE:0)
Block(-7,19,7,PACKED_ICE:0)
Block(-7,19,8,PACKED_ICE:0)
Block(-7,20,-7,PACKED_ICE:0)
Block(-7,20,-6,PACKED_ICE:0)
Block(-7,20,-5,PACKED_ICE:0)
Block(-7,20,-4,PACKED_ICE:0)
Block(-7,20,-3,PACKED_ICE:0)
Block(-7,20,-2,PACKED_ICE:0)
Block(-7,20,-1,PACKED_ICE:0)
Block(-7,20,0,PACKED_ICE:0)
Block(-7,20,1,PACKED_ICE:0)
Block(-7,20,2,PACKED_ICE:0)
Block(-7,20,3,PACKED_ICE:0)
Block(-7,20,4,PACKED_ICE:0)
Block(-7,20,5,PACKED_ICE:0)
Block(-7,20,6,PACKED_ICE:0)
Block(-7,20,7,PACKED_ICE:0)
Block(-7,20,8,PACKED_ICE:0)
Block(-7,21,-7,PACKED_ICE:0)
Block(-7,21,-6,PACKED_ICE:0)
Block(-7,21,-5,PACKED_ICE:0)
Block(-7,21,-4,PACKED_ICE:0)
Block(-7,21,-3,PACKED_ICE:0)
Block(-7,21,-2,PACKED_ICE:0)
Block(-7,21,-1,PACKED_ICE:0)
Block(-7,21,0,PACKED_ICE:0)
Block(-7,21,1,PACKED_ICE:0)
Block(-7,21,2,PACKED_ICE:0)
Block(-7,21,3,PACKED_ICE:0)
Block(-7,21,4,PACKED_ICE:0)
Block(-7,21,5,PACKED_ICE:0)
Block(-7,21,6,PACKED_ICE:0)
Block(-7,21,7,PACKED_ICE:0)
Block(-7,21,8,PACKED_ICE:0)
Block(-7,22,-6,PACKED_ICE:0)
Block(-7,22,-5,ICE:0)
Block(-7,22,-4,ICE:0)
Block(-7,22,-3,ICE:0)
Block(-7,22,-2,PACKED_ICE:0)
Block(-7,22,-1,PACKED_ICE:0)
Block(-7,22,0,ICE:0)
Block(-7,22,1,PACKED_ICE:0)
Block(-7,22,2,PACKED_ICE:0)
Block(-7,22,3,PACKED_ICE:0)
Block(-7,22,4,ICE:0)
Block(-7,22,5,ICE:0)
Block(-7,22,6,ICE:0)
Block(-7,22,7,ICE:0)
Block(-7,22,8,PACKED_ICE:0)
Block(-7,23,-6,PACKED_ICE:0)
Block(-7,23,-5,ICE:0)
Block(-7,23,-4,ICE:0)
Block(-7,23,-3,ICE:0)
Block(-7,23,-2,ICE:0)
Block(-7,23,-1,ICE:0)
Block(-7,23,0,ICE:0)
Block(-7,23,1,WOOD:5)
Block(-7,23,2,PACKED_ICE:0)
Block(-7,23,3,PACKED_ICE:0)
Block(-7,23,4,ICE:0)
Block(-7,23,5,ICE:0)
Block(-7,23,6,ICE:0)
Block(-7,23,7,ICE:0)
Block(-7,23,8,PACKED_ICE:0)
Block(-7,24,-6,PACKED_ICE:0)
Block(-7,24,-5,ICE:0)
Block(-7,24,-4,ICE:0)
Block(-7,24,-3,ICE:0)
Block(-7,24,-2,ICE:0)
Block(-7,24,-1,ICE:0)
Block(-7,24,0,ICE:0)
Block(-7,24,1,LOG_2:1)
Block(-7,24,2,PACKED_ICE:0)
Block(-7,24,3,PACKED_ICE:0)
Block(-7,24,4,PACKED_ICE:0)
Block(-7,24,5,PACKED_ICE:0)
Block(-7,24,6,ICE:0)
Block(-7,24,7,ICE:0)
Block(-7,24,8,ICE:0)
Block(-7,25,-7,PACKED_ICE:0)
Block(-7,25,-6,PACKED_ICE:0)
Block(-7,25,-5,PACKED_ICE:0)
Block(-7,25,-4,PACKED_ICE:0)
Block(-7,25,-3,PACKED_ICE:0)
Block(-7,25,-2,PACKED_ICE:0)
Block(-7,25,-1,PACKED_ICE:0)
Block(-7,25,0,PACKED_ICE:0)
Block(-7,25,1,LOG_2:1)
Block(-7,25,2,PACKED_ICE:0)
Block(-7,25,3,PACKED_ICE:0)
Block(-7,25,4,ICE:0)
Block(-7,25,5,PACKED_ICE:0)
Block(-7,25,6,ICE:0)
Block(-7,25,7,ICE:0)
Block(-7,25,8,PACKED_ICE:0)
Block(-7,26,-5,ICE:0)
Block(-7,26,-4,PACKED_ICE:0)
Block(-7,26,-3,PACKED_ICE:0)
Block(-7,26,-2,PACKED_ICE:0)
Block(-7,26,-1,LOG_2:1)
Block(-7,26,0,LOG_2:1)
Block(-7,26,1,WOOD_DOUBLE_STEP:1)
Block(-7,26,2,LOG_2:1)
Block(-7,26,3,LOG_2:1)
Block(-7,26,4,PACKED_ICE:0)
Block(-7,26,5,PACKED_ICE:0)
Block(-7,26,6,PACKED_ICE:0)
Block(-7,26,7,PACKED_ICE:0)
Block(-7,26,8,PACKED_ICE:0)
Block(-7,27,-4,ICE:0)
Block(-7,27,-3,LOG_2:1)
Block(-7,27,-2,LOG_2:1)
Block(-7,27,1,LADDER:5)
Block(-7,27,4,LOG_2:1)
Block(-7,27,5,LOG_2:1)
Block(-7,27,6,PACKED_ICE:0)
Block(-7,27,7,PACKED_ICE:0)
Block(-7,27,8,PACKED_ICE:0)
Block(-7,28,-4,LOG_2:1)
Block(-7,28,-3,WOOD_DOUBLE_STEP:1)
Block(-7,28,1,LADDER:5)
Block(-7,28,5,WOOD_DOUBLE_STEP:1)
Block(-7,28,6,LOG_2:1)
Block(-7,28,7,PACKED_ICE:0)
Block(-7,29,-4,WOOD:5)
Block(-7,29,-3,WOOD:5)
Block(-7,29,-2,WOOD:5)
Block(-7,29,-1,WOOD:5)
Block(-7,29,0,ICE:0)
Block(-7,29,1,LADDER:5)
Block(-7,29,2,ICE:0)
Block(-7,29,3,ICE:0)
Block(-7,29,4,WOOD:5)
Block(-7,29,5,WOOD:5)
Block(-7,29,6,WOOD:5)
Block(-7,29,7,PACKED_ICE:0)
Block(-7,30,-4,DISPENSER:2)
Block(-7,30,-3,CONCRETE:15)
Block(-7,30,-2,DARK_OAK_STAIRS:3)
Block(-7,30,4,DARK_OAK_STAIRS:2)
Block(-7,30,5,CONCRETE:15)
Block(-7,30,6,DISPENSER:3)
Block(-7,31,-5,PACKED_ICE:0)
Block(-7,31,-4,WOOD:5)
Block(-7,31,5,ICE:0)
Block(-7,31,6,WOOD:5)
Block(-7,32,-5,PACKED_ICE:0)
Block(-7,32,-4,WOOD:5)
Block(-7,32,-3,WOOD_STEP:13)
Block(-7,32,-2,WOOD_STEP:13)
Block(-7,32,-1,WOOD_STEP:13)
Block(-7,32,0,WOOD_STEP:13)
Block(-7,32,1,ICE:0)
Block(-7,32,2,ICE:0)
Block(-7,32,3,ICE:0)
Block(-7,32,4,ICE:0)
Block(-7,32,5,WOOD_STEP:13)
Block(-7,32,6,WOOD:5)
Block(-7,32,7,ICE:0)
Block(-7,33,-6,ICE:0)
Block(-7,33,-5,PACKED_ICE:0)
Block(-7,33,-4,STAINED_CLAY:9)
Block(-7,33,-3,STAINED_CLAY:9)
Block(-7,33,-2,STAINED_CLAY:9)
Block(-7,33,-1,STAINED_CLAY:9)
Block(-7,33,1,STAINED_CLAY:9)
Block(-7,33,3,STAINED_CLAY:9)
Block(-7,33,4,STAINED_CLAY:9)
Block(-7,33,5,STAINED_CLAY:9)
Block(-7,33,6,STAINED_CLAY:9)
Block(-7,33,7,ICE:0)
Block(-7,34,-6,ICE:0)
Block(-7,34,-5,PACKED_ICE:0)
Block(-7,34,-4,STAINED_CLAY:9)
Block(-7,34,-3,STAINED_CLAY:9)
Block(-7,34,-2,STAINED_CLAY:9)
Block(-7,34,-1,STAINED_CLAY:9)
Block(-7,34,1,STAINED_CLAY:9)
Block(-7,34,3,STAINED_CLAY:9)
Block(-7,34,4,STAINED_CLAY:9)
Block(-7,34,5,STAINED_CLAY:9)
Block(-7,34,6,STAINED_CLAY:9)
Block(-7,34,7,ICE:0)
Block(-7,34,8,ICE:0)
Block(-7,35,-6,PACKED_ICE:0)
Block(-7,35,-5,WOOD_STEP:13)
Block(-7,35,-4,STAINED_CLAY:9)
Block(-7,35,-3,STAINED_CLAY:9)
Block(-7,35,-2,STAINED_CLAY:9)
Block(-7,35,-1,STAINED_CLAY:9)
Block(-7,35,0,STAINED_CLAY:9)
Block(-7,35,1,STAINED_CLAY:9)
Block(-7,35,2,STAINED_CLAY:9)
Block(-7,35,3,STAINED_CLAY:9)
Block(-7,35,4,STAINED_CLAY:9)
Block(-7,35,5,STAINED_CLAY:9)
Block(-7,35,6,STAINED_CLAY:9)
Block(-7,35,7,WOOD_STEP:13)
Block(-7,35,8,ICE:0)
Block(-7,36,-5,PACKED_ICE:0)
Block(-7,36,-4,STAINED_CLAY:9)
Block(-7,36,-3,STAINED_CLAY:9)
Block(-7,36,-2,PACKED_ICE:0)
Block(-7,36,-1,PACKED_ICE:0)
Block(-7,36,0,STAINED_CLAY:9)
Block(-7,36,1,STAINED_CLAY:9)
Block(-7,36,2,STAINED_CLAY:9)
Block(-7,36,3,STAINED_CLAY:9)
Block(-7,36,4,STAINED_CLAY:9)
Block(-7,36,5,STAINED_CLAY:9)
Block(-7,36,6,STAINED_CLAY:9)
Block(-7,36,7,ICE:0)
Block(-7,36,8,PACKED_ICE:0)
Block(-7,37,-5,ICE:0)
Block(-7,37,-4,PACKED_ICE:0)
Block(-7,37,-3,STAINED_CLAY:9)
Block(-7,37,-2,ICE:0)
Block(-7,37,-1,ICE:0)
Block(-7,37,0,ICE:0)
Block(-7,37,1,PACKED_ICE:0)
Block(-7,37,2,SNOW:1)
Block(-7,37,3,SNOW:2)
Block(-7,37,4,SNOW:1)
Block(-7,37,5,STAINED_CLAY:9)
Block(-7,37,6,PACKED_ICE:0)
Block(-7,38,-3,ICE:0)
Block(-7,38,-2,PACKED_ICE:0)
Block(-7,38,-1,PACKED_ICE:0)
Block(-7,38,0,PACKED_ICE:0)
Block(-7,38,1,ICE:0)
Block(-7,38,5,DARK_OAK_STAIRS:0)
Block(-7,39,-3,ICE:0)
Block(-7,39,-2,PACKED_ICE:0)
Block(-7,39,0,ICE:0)
Block(-7,40,-2,PACKED_ICE:0)
Block(-7,40,1,ICE:0)
Block(-7,41,1,ICE:0)
Block(-7,41,2,ICE:0)
Block(-7,42,0,ICE:0)
Block(-7,42,1,LOG:5)
Block(-7,42,2,ICE:0)
Block(-7,43,0,ICE:0)
Block(-7,43,1,ICE:0)
Block(-7,43,2,ICE:0)
Block(-7,44,1,PACKED_ICE:0)
Block(-7,45,1,WOOL:15)
Block(-7,46,1,WOOL:15)
Block(-7,47,1,WOOL:15)
Block(-7,48,1,SNOW:2)
Block(-6,18,-7,PACKED_ICE:0)
Block(-6,18,-6,PACKED_ICE:0)
Block(-6,18,-5,PACKED_ICE:0)
Block(-6,18,-4,PACKED_ICE:0)
Block(-6,18,-3,PACKED_ICE:0)
Block(-6,18,-2,PACKED_ICE:0)
Block(-6,18,-1,PACKED_ICE:0)
Block(-6,18,0,PACKED_ICE:0)
Block(-6,18,1,PACKED_ICE:0)
Block(-6,18,2,PACKED_ICE:0)
Block(-6,18,3,PACKED_ICE:0)
Block(-6,18,4,PACKED_ICE:0)
Block(-6,18,5,PACKED_ICE:0)
Block(-6,18,6,PACKED_ICE:0)
Block(-6,18,7,PACKED_ICE:0)
Block(-6,18,8,PACKED_ICE:0)
Block(-6,19,-7,PACKED_ICE:0)
Block(-6,19,-6,PACKED_ICE:0)
Block(-6,19,-5,PACKED_ICE:0)
Block(-6,19,-4,PACKED_ICE:0)
Block(-6,19,-3,PACKED_ICE:0)
Block(-6,19,-2,PACKED_ICE:0)
Block(-6,19,-1,PACKED_ICE:0)
Block(-6,19,0,PACKED_ICE:0)
Block(-6,19,1,PACKED_ICE:0)
Block(-6,19,2,PACKED_ICE:0)
Block(-6,19,3,PACKED_ICE:0)
Block(-6,19,4,PACKED_ICE:0)
Block(-6,19,5,PACKED_ICE:0)
Block(-6,19,6,PACKED_ICE:0)
Block(-6,19,7,PACKED_ICE:0)
Block(-6,19,8,PACKED_ICE:0)
Block(-6,20,-7,PACKED_ICE:0)
Block(-6,20,-6,PACKED_ICE:0)
Block(-6,20,-5,PACKED_ICE:0)
Block(-6,20,-4,PACKED_ICE:0)
Block(-6,20,-3,PACKED_ICE:0)
Block(-6,20,-2,PACKED_ICE:0)
Block(-6,20,-1,PACKED_ICE:0)
Block(-6,20,0,PACKED_ICE:0)
Block(-6,20,1,PACKED_ICE:0)
Block(-6,20,2,PACKED_ICE:0)
Block(-6,20,3,PACKED_ICE:0)
Block(-6,20,4,PACKED_ICE:0)
Block(-6,20,5,PACKED_ICE:0)
Block(-6,20,6,PACKED_ICE:0)
Block(-6,20,7,PACKED_ICE:0)
Block(-6,20,8,PACKED_ICE:0)
Block(-6,21,-7,PACKED_ICE:0)
Block(-6,21,-6,PACKED_ICE:0)
Block(-6,21,-5,PACKED_ICE:0)
Block(-6,21,-4,PACKED_ICE:0)
Block(-6,21,-3,PACKED_ICE:0)
Block(-6,21,-2,PACKED_ICE:0)
Block(-6,21,-1,PACKED_ICE:0)
Block(-6,21,0,PACKED_ICE:0)
Block(-6,21,1,PACKED_ICE:0)
Block(-6,21,2,PACKED_ICE:0)
Block(-6,21,3,PACKED_ICE:0)
Block(-6,21,4,PACKED_ICE:0)
Block(-6,21,5,PACKED_ICE:0)
Block(-6,21,6,PACKED_ICE:0)
Block(-6,21,7,PACKED_ICE:0)
Block(-6,21,8,PACKED_ICE:0)
Block(-6,22,-6,PACKED_ICE:0)
Block(-6,22,-5,PACKED_ICE:0)
Block(-6,22,-4,ICE:0)
Block(-6,22,-3,ICE:0)
Block(-6,22,-2,ICE:0)
Block(-6,22,-1,PACKED_ICE:0)
Block(-6,22,0,ICE:0)
Block(-6,22,1,PACKED_ICE:0)
Block(-6,22,2,PACKED_ICE:0)
Block(-6,22,3,PACKED_ICE:0)
Block(-6,22,4,PACKED_ICE:0)
Block(-6,22,5,PACKED_ICE:0)
Block(-6,22,6,PACKED_ICE:0)
Block(-6,22,7,ICE:0)
Block(-6,22,8,ICE:0)
Block(-6,23,-7,PACKED_ICE:0)
Block(-6,23,-6,ICE:0)
Block(-6,23,-5,ICE:0)
Block(-6,23,-4,ICE:0)
Block(-6,23,-3,ICE:0)
Block(-6,23,-2,ICE:0)
Block(-6,23,-1,ICE:0)
Block(-6,23,0,ICE:0)
Block(-6,23,1,WOOD:5)
Block(-6,23,2,PACKED_ICE:0)
Block(-6,23,3,PACKED_ICE:0)
Block(-6,23,4,ICE:0)
Block(-6,23,5,ICE:0)
Block(-6,23,6,ICE:0)
Block(-6,23,7,ICE:0)
Block(-6,23,8,PACKED_ICE:0)
Block(-6,24,-7,ICE:0)
Block(-6,24,-6,ICE:0)
Block(-6,24,-5,ICE:0)
Block(-6,24,-4,ICE:0)
Block(-6,24,-3,ICE:0)
Block(-6,24,-2,ICE:0)
Block(-6,24,-1,ICE:0)
Block(-6,24,0,ICE:0)
Block(-6,24,1,LOG_2:1)
Block(-6,24,2,PACKED_ICE:0)
Block(-6,24,3,PACKED_ICE:0)
Block(-6,24,4,PACKED_ICE:0)
Block(-6,24,5,PACKED_ICE:0)
Block(-6,24,6,ICE:0)
Block(-6,24,7,ICE:0)
Block(-6,24,8,PACKED_ICE:0)
Block(-6,25,-6,PACKED_ICE:0)
Block(-6,25,-5,PACKED_ICE:0)
Block(-6,25,-4,PACKED_ICE:0)
Block(-6,25,-3,PACKED_ICE:0)
Block(-6,25,-2,PACKED_ICE:0)
Block(-6,25,-1,PACKED_ICE:0)
Block(-6,25,0,PACKED_ICE:0)
Block(-6,25,1,LOG_2:1)
Block(-6,25,2,PACKED_ICE:0)
Block(-6,25,3,PACKED_ICE:0)
Block(-6,25,4,ICE:0)
Block(-6,25,5,ICE:0)
Block(-6,25,6,PACKED_ICE:0)
Block(-6,25,7,ICE:0)
Block(-6,25,8,ICE:0)
Block(-6,26,-6,ICE:0)
Block(-6,26,-5,PACKED_ICE:0)
Block(-6,26,-4,PACKED_ICE:0)
Block(-6,26,-3,PACKED_ICE:0)
Block(-6,26,-2,PACKED_ICE:0)
Block(-6,26,-1,LOG_2:1)
Block(-6,26,0,LOG_2:1)
Block(-6,26,1,WOOD_STEP:9)
Block(-6,26,2,LOG_2:1)
Block(-6,26,3,LOG_2:1)
Block(-6,26,4,PACKED_ICE:0)
Block(-6,26,5,PACKED_ICE:0)
Block(-6,26,6,PACKED_ICE:0)
Block(-6,26,7,PACKED_ICE:0)
Block(-6,26,8,ICE:0)
Block(-6,27,-5,PACKED_ICE:0)
Block(-6,27,-4,PACKED_ICE:0)
Block(-6,27,-3,LOG_2:1)
Block(-6,27,-2,LOG_2:1)
RandomBlock(-6,27,-1,AIR:0,20,CHEST:3,../../../../Chests/Loot/ShipJunk_1.nbt,10,CHEST:3,../../../../Chests/Loot/ShipJunk_2.nbt,10,CHEST:3,../../../../Chests/Loot/ShipJunk_3.nbt,10,CHEST:3,../../../../Chests/Loot/ShipJunk_4.nbt,10,CHEST:3,../../../../Chests/Loot/ShipJunk_5.nbt,10,CHEST:3,../../../../Chests/Lore/Frozen_1.nbt,1,CHEST:3,../../../../Chests/Lore/Frozen_2.nbt,1,CHEST:3,../../../../Chests/Lore/Frozen_3.nbt,1,CHEST:3,../../../../Chests/Lore/Frozen_4.nbt,1,CHEST:3,../../../../Chests/Lore/Frozen_5.nbt,1,CHEST:3,../../../../Chests/Loot/Common1.nbt,10,CHEST:3,../../../../Chests/Loot/Common2.nbt,10,CHEST:3,../../../../Chests/Loot/Common3.nbt,10,CHEST:3,../../../../Chests/Loot/Common4.nbt,10,CHEST:3,../../../../Chests/Loot/Common5.nbt,10,CHEST:3,../../../../Chests/Loot/Common6.nbt,10,CHEST:3,../../../../Chests/Loot/Common7.nbt,10,CHEST:3,../../../../Chests/Loot/Common8.nbt,10,CHEST:3,../../../../Chests/Loot/Common9.nbt,10,CHEST:3,../../../../Chests/Loot/Common10.nbt,10,CHEST:3,../../../../Chests/Loot/Common10.nbt,11,CHEST:3,../../../../Chests/Loot/Common12.nbt,10,CHEST:3,../../../../Chests/Loot/Common13.nbt,10,CHEST:3,../../../../Chests/Loot/Common14.nbt,10,CHEST:3,../../../../Chests/Loot/Common15.nbt,10,CHEST:3,../../../../Chests/Lore/Frozen_1.nbt,2,CHEST:3,../../../../Chests/Lore/Frozen_3.nbt,2,CHEST:3,../../../../Chests/Lore/Frozen_4.nbt,2,CHEST:3,../../../../Chests/Lore/Frozen_5.nbt,2,CHEST:3,../../../../Chests/Lore/Frozen_5.nbt,2,CHEST:3,../../../../Chests/Loot/Rare1.nbt,5,CHEST:3,../../../../Chests/Loot/Rare2.nbt,5,CHEST:3,../../../../Chests/Loot/Rare3.nbt,5,CHEST:3,../../../../Chests/Loot/Rare4.nbt,5,CHEST:3,../../../../Chests/Loot/Rare5.nbt,5,CHEST:3,../../../../Chests/Loot/Rare6.nbt,5,CHEST:3,../../../../Chests/Loot/Rare7.nbt,5,CHEST:3,../../../../Chests/Loot/Rare8.nbt,5,CHEST:3,../../../../Chests/Loot/Rare9.nbt,5,CHEST:3,../../../../Chests/Loot/Rare10.nbt,5,CHEST:3,../../../../Chests/Loot/Rare11.nbt,5,CHEST:3,../../../../Chests/Loot/Rare12.nbt,5,CHEST:3,../../../../Chests/Loot/Rare13.nbt,5,CHEST:3,../../../../Chests/Loot/Rare14.nbt,5,CHEST:3,../../../../Chests/Loot/Rare15.nbt,5,CHEST:3,../../../../Chests/Loot/Epic1.nbt,2,CHEST:3,../../../../Chests/Loot/Epic2.nbt,2,CHEST:3,../../../../Chests/Loot/Epic3.nbt,2,CHEST:3,../../../../Chests/Loot/Epic4.nbt,2,CHEST:3,../../../../Chests/Loot/Epic5.nbt,2,CHEST:3,../../../../Chests/Loot/Epic6.nbt,2,CHEST:3,../../../../Chests/Loot/Epic7.nbt,2,CHEST:3,../../../../Chests/Loot/Epic8.nbt,2,CHEST:3,../../../../Chests/Loot/Epic9.nbt,2,CHEST:3,../../../../Chests/Loot/Epic10.nbt,2,CHEST:3,../../../../Chests/Loot/Epic11.nbt,2,CHEST:3,../../../../Chests/Loot/Epic12.nbt,2,CHEST:3,../../../../Chests/Loot/Epic13.nbt,2,CHEST:3,../../../../Chests/Loot/Epic14.nbt,2,CHEST:3,../../../../Chests/Loot/Epic15.nbt,5,CHEST:3,../../../../Chests/Loot/Rare1.nbt,5,CHEST:3,../../../../Chests/Loot/Rare2.nbt,5,CHEST:3,../../../../Chests/Loot/Rare3.nbt,5,CHEST:3,../../../../Chests/Loot/Rare4.nbt,5,CHEST:3,../../../../Chests/Loot/Rare5.nbt,10,CHEST:3,../../../../Chests/Loot/Rare6.nbt,10,CHEST:3,../../../../Chests/Loot/Rare7.nbt,10,CHEST:3,../../../../Chests/Loot/Rare8.nbt,10,CHEST:3,../../../../Chests/Loot/Rare9.nbt,10,CHEST:3,../../../../Chests/Loot/Rare10.nbt,15,CHEST:3,../../../../Chests/Loot/Rare11.nbt,15,CHEST:3,../../../../Chests/Loot/Rare12.nbt,15,CHEST:3,../../../../Chests/Loot/Rare13.nbt,15,CHEST:3,../../../../Chests/Loot/Rare14.nbt,15,CHEST:3,../../../../Chests/Loot/Rare15.nbt,15,CHEST:3,../../../../Chests/Loot/Epic15.nbt,100)
RandomBlock(-6,27,3,AIR:0,20,CHEST:2,../../../../Chests/Loot/ShipJunk_1.nbt,10,CHEST:2,../../../../Chests/Loot/ShipJunk_2.nbt,10,CHEST:2,../../../../Chests/Loot/ShipJunk_3.nbt,10,CHEST:2,../../../../Chests/Loot/ShipJunk_4.nbt,10,CHEST:2,../../../../Chests/Loot/ShipJunk_5.nbt,10,CHEST:2,../../../../Chests/Lore/Frozen_1.nbt,1,CHEST:2,../../../../Chests/Lore/Frozen_2.nbt,1,CHEST:2,../../../../Chests/Lore/Frozen_3.nbt,1,CHEST:2,../../../../Chests/Lore/Frozen_4.nbt,1,CHEST:2,../../../../Chests/Lore/Frozen_5.nbt,1,CHEST:2,../../../../Chests/Loot/Common1.nbt,10,CHEST:2,../../../../Chests/Loot/Common2.nbt,10,CHEST:2,../../../../Chests/Loot/Common3.nbt,10,CHEST:2,../../../../Chests/Loot/Common4.nbt,10,CHEST:2,../../../../Chests/Loot/Common5.nbt,10,CHEST:2,../../../../Chests/Loot/Common6.nbt,10,CHEST:2,../../../../Chests/Loot/Common7.nbt,10,CHEST:2,../../../../Chests/Loot/Common8.nbt,10,CHEST:2,../../../../Chests/Loot/Common9.nbt,10,CHEST:2,../../../../Chests/Loot/Common10.nbt,10,CHEST:2,../../../../Chests/Loot/Common10.nbt,11,CHEST:2,../../../../Chests/Loot/Common12.nbt,10,CHEST:2,../../../../Chests/Loot/Common13.nbt,10,CHEST:2,../../../../Chests/Loot/Common14.nbt,10,CHEST:2,../../../../Chests/Loot/Common15.nbt,10,CHEST:2,../../../../Chests/Lore/Frozen_1.nbt,2,CHEST:2,../../../../Chests/Lore/Frozen_3.nbt,2,CHEST:2,../../../../Chests/Lore/Frozen_4.nbt,2,CHEST:2,../../../../Chests/Lore/Frozen_5.nbt,2,CHEST:2,../../../../Chests/Lore/Frozen_5.nbt,2,CHEST:2,../../../../Chests/Loot/Rare1.nbt,5,CHEST:2,../../../../Chests/Loot/Rare2.nbt,5,CHEST:2,../../../../Chests/Loot/Rare3.nbt,5,CHEST:2,../../../../Chests/Loot/Rare4.nbt,5,CHEST:2,../../../../Chests/Loot/Rare5.nbt,5,CHEST:2,../../../../Chests/Loot/Rare6.nbt,5,CHEST:2,../../../../Chests/Loot/Rare7.nbt,5,CHEST:2,../../../../Chests/Loot/Rare8.nbt,5,CHEST:2,../../../../Chests/Loot/Rare9.nbt,5,CHEST:2,../../../../Chests/Loot/Rare10.nbt,5,CHEST:2,../../../../Chests/Loot/Rare11.nbt,5,CHEST:2,../../../../Chests/Loot/Rare12.nbt,5,CHEST:2,../../../../Chests/Loot/Rare13.nbt,5,CHEST:2,../../../../Chests/Loot/Rare14.nbt,5,CHEST:2,../../../../Chests/Loot/Rare15.nbt,5,CHEST:2,../../../../Chests/Loot/Epic1.nbt,2,CHEST:2,../../../../Chests/Loot/Epic2.nbt,2,CHEST:2,../../../../Chests/Loot/Epic3.nbt,2,CHEST:2,../../../../Chests/Loot/Epic4.nbt,2,CHEST:2,../../../../Chests/Loot/Epic5.nbt,2,CHEST:2,../../../../Chests/Loot/Epic6.nbt,2,CHEST:2,../../../../Chests/Loot/Epic7.nbt,2,CHEST:2,../../../../Chests/Loot/Epic8.nbt,2,CHEST:2,../../../../Chests/Loot/Epic9.nbt,2,CHEST:2,../../../../Chests/Loot/Epic10.nbt,2,CHEST:2,../../../../Chests/Loot/Epic11.nbt,2,CHEST:2,../../../../Chests/Loot/Epic12.nbt,2,CHEST:2,../../../../Chests/Loot/Epic13.nbt,2,CHEST:2,../../../../Chests/Loot/Epic14.nbt,2,CHEST:2,../../../../Chests/Loot/Epic15.nbt,5,CHEST:2,../../../../Chests/Loot/Rare1.nbt,5,CHEST:2,../../../../Chests/Loot/Rare2.nbt,5,CHEST:2,../../../../Chests/Loot/Rare3.nbt,5,CHEST:2,../../../../Chests/Loot/Rare4.nbt,5,CHEST:2,../../../../Chests/Loot/Rare5.nbt,10,CHEST:2,../../../../Chests/Loot/Rare6.nbt,10,CHEST:2,../../../../Chests/Loot/Rare7.nbt,10,CHEST:2,../../../../Chests/Loot/Rare8.nbt,10,CHEST:2,../../../../Chests/Loot/Rare9.nbt,10,CHEST:2,../../../../Chests/Loot/Rare10.nbt,15,CHEST:2,../../../../Chests/Loot/Rare11.nbt,15,CHEST:2,../../../../Chests/Loot/Rare12.nbt,15,CHEST:2,../../../../Chests/Loot/Rare13.nbt,15,CHEST:2,../../../../Chests/Loot/Rare14.nbt,15,CHEST:2,../../../../Chests/Loot/Rare15.nbt,15,CHEST:2,../../../../Chests/Loot/Epic15.nbt,100)
Block(-6,27,4,LOG_2:1)
Block(-6,27,5,LOG_2:1)
Block(-6,27,6,PACKED_ICE:0)
Block(-6,27,7,PACKED_ICE:0)
Block(-6,28,-5,PACKED_ICE:0)
Block(-6,28,-4,LOG_2:1)
Block(-6,28,-3,WOOD_DOUBLE_STEP:1)
Block(-6,28,5,WOOD_DOUBLE_STEP:1)
Block(-6,28,6,LOG_2:1)
Block(-6,28,7,PACKED_ICE:0)
Block(-6,29,-5,ICE:0)
Block(-6,29,-4,WOOD:5)
Block(-6,29,-3,WOOD:5)
Block(-6,29,-2,WOOD:5)
Block(-6,29,-1,WOOD:5)
Block(-6,29,0,ICE:0)
Block(-6,29,1,ICE:0)
Block(-6,29,2,ICE:0)
Block(-6,29,3,WOOD:5)
Block(-6,29,4,WOOD:5)
Block(-6,29,5,WOOD:5)
Block(-6,29,6,WOOD:5)
Block(-6,30,-4,WOOD:5)
Block(-6,30,-3,STAINED_CLAY:9)
Block(-6,30,-2,STAINED_CLAY:9)
Block(-6,30,-1,STAINED_CLAY:9)
Block(-6,30,4,STAINED_CLAY:9)
Block(-6,30,5,STAINED_CLAY:9)
Block(-6,30,6,WOOD:5)
Block(-6,30,7,ICE:0)
Block(-6,31,-4,WOOD:5)
Block(-6,31,-3,STAINED_CLAY:9)
Block(-6,31,-2,STAINED_CLAY:9)
Block(-6,31,4,PACKED_ICE:0)
Block(-6,31,5,STAINED_CLAY:9)
Block(-6,31,6,WOOD:5)
Block(-6,31,7,ICE:0)
Block(-6,32,-4,WOOD:5)
Block(-6,32,-3,WOOD_DOUBLE_STEP:5)
Block(-6,32,-2,WOOD_DOUBLE_STEP:5)
Block(-6,32,-1,WOOD_DOUBLE_STEP:5)
Block(-6,32,0,WOOD_DOUBLE_STEP:5)
Block(-6,32,1,WOOD_DOUBLE_STEP:5)
Block(-6,32,2,WOOD_DOUBLE_STEP:5)
Block(-6,32,3,WOOD_DOUBLE_STEP:5)
Block(-6,32,4,WOOD_DOUBLE_STEP:5)
Block(-6,32,5,WOOD_DOUBLE_STEP:5)
Block(-6,32,6,WOOD:5)
Block(-6,32,7,ICE:0)
Block(-6,32,8,PACKED_ICE:0)
Block(-6,33,-5,ICE:0)
Block(-6,33,-4,WOOD:5)
Block(-6,33,-3,SPRUCE_WOOD_STAIRS:1)
Block(-6,33,-1,SPRUCE_WOOD_STAIRS:1)
Block(-6,33,3,WOOD_STEP:5)
Block(-6,33,6,WOOD:5)
Block(-6,33,7,ICE:0)
Block(-6,33,8,PACKED_ICE:0)
Block(-6,34,-6,PACKED_ICE:0)
Block(-6,34,-5,ICE:0)
Block(-6,34,-4,STAINED_CLAY:9)
Block(-6,34,6,STAINED_CLAY:9)
Block(-6,34,8,PACKED_ICE:0)
Block(-6,35,-5,DARK_OAK_STAIRS:6)
Block(-6,35,-4,STAINED_CLAY:9)
Block(-6,35,-1,DARK_OAK_STAIRS:5)
Block(-6,35,3,DARK_OAK_STAIRS:5)
Block(-6,35,6,STAINED_CLAY:9)
Block(-6,35,7,DARK_OAK_STAIRS:7)
Block(-6,35,8,PACKED_ICE:0)
Block(-6,36,-5,ICE:0)
Block(-6,36,-4,STAINED_CLAY:9)
Block(-6,36,-3,PACKED_ICE:0)
Block(-6,36,-2,PACKED_ICE:0)
Block(-6,36,-1,PACKED_ICE:0)
Block(-6,36,0,STAINED_GLASS:15)
Block(-6,36,1,WOOD_STEP:9)
Block(-6,36,2,ICE:0)
Block(-6,36,3,PACKED_ICE:0)
Block(-6,36,4,ICE:0)
Block(-6,36,5,STAINED_CLAY:9)
Block(-6,36,6,STAINED_CLAY:9)
Block(-6,36,7,ICE:0)
Block(-6,36,8,ICE:0)
Block(-6,37,-4,PACKED_ICE:0)
Block(-6,37,-3,PACKED_ICE:0)
Block(-6,37,-2,ICE:0)
Block(-6,37,-1,ICE:0)
Block(-6,37,0,ICE:0)
Block(-6,37,1,WOOD_STEP:1)
Block(-6,37,4,ICE:0)
Block(-6,37,5,STAINED_CLAY:9)
Block(-6,37,6,PACKED_ICE:0)
Block(-6,37,7,ICE:0)
Block(-6,38,-3,ICE:0)
Block(-6,38,-2,PACKED_ICE:0)
Block(-6,38,-1,ICE:0)
Block(-6,38,2,ICE:0)
Block(-6,38,5,STAINED_CLAY:9)
Block(-6,39,-2,ICE:0)
Block(-6,39,1,PACKED_ICE:0)
Block(-6,39,2,WOOL:15)
Block(-6,39,5,SNOW:3)
Block(-6,40,1,PACKED_ICE:0)
Block(-6,40,2,WOOL:15)
Block(-6,41,0,ICE:0)
Block(-6,41,1,LOG:1)
Block(-6,41,2,WOOL:15)
Block(-6,42,0,ICE:0)
Block(-6,42,1,LOG:5)
Block(-6,42,2,WOOL:15)
Block(-6,43,1,PACKED_ICE:0)
Block(-6,43,2,SNOW:2)
Block(-5,18,-7,PACKED_ICE:0)
Block(-5,18,-6,PACKED_ICE:0)
Block(-5,18,-5,PACKED_ICE:0)
Block(-5,18,-4,PACKED_ICE:0)
Block(-5,18,-3,PACKED_ICE:0)
Block(-5,18,-2,PACKED_ICE:0)
Block(-5,18,-1,PACKED_ICE:0)
Block(-5,18,0,PACKED_ICE:0)
Block(-5,18,1,PACKED_ICE:0)
Block(-5,18,2,PACKED_ICE:0)
Block(-5,18,3,PACKED_ICE:0)
Block(-5,18,4,PACKED_ICE:0)
Block(-5,18,5,PACKED_ICE:0)
Block(-5,18,6,PACKED_ICE:0)
Block(-5,18,7,PACKED_ICE:0)
Block(-5,18,8,PACKED_ICE:0)
Block(-5,19,-7,PACKED_ICE:0)
Block(-5,19,-6,PACKED_ICE:0)
Block(-5,19,-5,PACKED_ICE:0)
Block(-5,19,-4,PACKED_ICE:0)
Block(-5,19,-3,PACKED_ICE:0)
Block(-5,19,-2,PACKED_ICE:0)
Block(-5,19,-1,PACKED_ICE:0)
Block(-5,19,0,PACKED_ICE:0)
Block(-5,19,1,PACKED_ICE:0)
Block(-5,19,2,PACKED_ICE:0)
Block(-5,19,3,PACKED_ICE:0)
Block(-5,19,4,PACKED_ICE:0)
Block(-5,19,5,PACKED_ICE:0)
Block(-5,19,6,PACKED_ICE:0)
Block(-5,19,7,PACKED_ICE:0)
Block(-5,19,8,PACKED_ICE:0)
Block(-5,20,-7,PACKED_ICE:0)
Block(-5,20,-6,PACKED_ICE:0)
Block(-5,20,-5,PACKED_ICE:0)
Block(-5,20,-4,PACKED_ICE:0)
Block(-5,20,-3,PACKED_ICE:0)
Block(-5,20,-2,PACKED_ICE:0)
Block(-5,20,-1,PACKED_ICE:0)
Block(-5,20,0,PACKED_ICE:0)
Block(-5,20,1,PACKED_ICE:0)
Block(-5,20,2,PACKED_ICE:0)
Block(-5,20,3,PACKED_ICE:0)
Block(-5,20,4,PACKED_ICE:0)
Block(-5,20,5,PACKED_ICE:0)
Block(-5,20,6,PACKED_ICE:0)
Block(-5,20,7,PACKED_ICE:0)
Block(-5,20,8,PACKED_ICE:0)
Block(-5,21,-7,PACKED_ICE:0)
Block(-5,21,-6,PACKED_ICE:0)
Block(-5,21,-5,PACKED_ICE:0)
Block(-5,21,-4,PACKED_ICE:0)
Block(-5,21,-3,PACKED_ICE:0)
Block(-5,21,-2,PACKED_ICE:0)
Block(-5,21,-1,PACKED_ICE:0)
Block(-5,21,0,PACKED_ICE:0)
Block(-5,21,1,PACKED_ICE:0)
Block(-5,21,2,PACKED_ICE:0)
Block(-5,21,3,PACKED_ICE:0)
Block(-5,21,4,PACKED_ICE:0)
Block(-5,21,5,PACKED_ICE:0)
Block(-5,21,6,PACKED_ICE:0)
Block(-5,21,7,PACKED_ICE:0)
Block(-5,21,8,PACKED_ICE:0)
Block(-5,22,-6,ICE:0)
Block(-5,22,-5,PACKED_ICE:0)
Block(-5,22,-4,ICE:0)
Block(-5,22,-3,ICE:0)
Block(-5,22,-2,ICE:0)
Block(-5,22,-1,PACKED_ICE:0)
Block(-5,22,0,ICE:0)
Block(-5,22,1,PACKED_ICE:0)
Block(-5,22,2,PACKED_ICE:0)
Block(-5,22,3,PACKED_ICE:0)
Block(-5,22,4,PACKED_ICE:0)
Block(-5,22,5,PACKED_ICE:0)
Block(-5,22,6,PACKED_ICE:0)
Block(-5,22,7,PACKED_ICE:0)
Block(-5,22,8,PACKED_ICE:0)
Block(-5,23,-7,PACKED_ICE:0)
Block(-5,23,-6,ICE:0)
Block(-5,23,-5,ICE:0)
Block(-5,23,-4,ICE:0)
Block(-5,23,-3,ICE:0)
Block(-5,23,-2,ICE:0)
Block(-5,23,-1,ICE:0)
Block(-5,23,0,ICE:0)
Block(-5,23,1,PACKED_ICE:0)
Block(-5,23,2,PACKED_ICE:0)
Block(-5,23,3,ICE:0)
Block(-5,23,4,PACKED_ICE:0)
Block(-5,23,5,PACKED_ICE:0)
Block(-5,23,6,ICE:0)
Block(-5,23,7,ICE:0)
Block(-5,23,8,ICE:0)
Block(-5,24,-6,PACKED_ICE:0)
Block(-5,24,-5,ICE:0)
Block(-5,24,-4,ICE:0)
Block(-5,24,-3,ICE:0)
Block(-5,24,-2,ICE:0)
Block(-5,24,-1,ICE:0)
Block(-5,24,0,ICE:0)
Block(-5,24,1,WOOD:5)
Block(-5,24,2,ICE:0)
Block(-5,24,3,PACKED_ICE:0)
Block(-5,24,4,PACKED_ICE:0)
Block(-5,24,5,PACKED_ICE:0)
Block(-5,24,6,ICE:0)
Block(-5,24,7,ICE:0)
Block(-5,24,8,ICE:0)
Block(-5,25,-7,PACKED_ICE:0)
Block(-5,25,-6,PACKED_ICE:0)
Block(-5,25,-5,PACKED_ICE:0)
Block(-5,25,-4,PACKED_ICE:0)
Block(-5,25,-3,PACKED_ICE:0)
Block(-5,25,-2,PACKED_ICE:0)
Block(-5,25,-1,PACKED_ICE:0)
Block(-5,25,0,PACKED_ICE:0)
Block(-5,25,1,LOG_2:1)
Block(-5,25,2,PACKED_ICE:0)
Block(-5,25,3,ICE:0)
Block(-5,25,4,PACKED_ICE:0)
Block(-5,25,5,ICE:0)
Block(-5,25,6,ICE:0)
Block(-5,25,7,ICE:0)
Block(-5,25,8,ICE:0)
Block(-5,26,-6,PACKED_ICE:0)
Block(-5,26,-5,PACKED_ICE:0)
Block(-5,26,-4,PACKED_ICE:0)
Block(-5,26,-3,ICE:0)
Block(-5,26,-2,PACKED_ICE:0)
Block(-5,26,-1,PACKED_ICE:0)
Block(-5,26,0,LOG_2:1)
Block(-5,26,1,WOOD_STEP:9)
Block(-5,26,2,LOG_2:1)
Block(-5,26,3,PACKED_ICE:0)
Block(-5,26,4,PACKED_ICE:0)
Block(-5,26,5,PACKED_ICE:0)
Block(-5,26,6,ICE:0)
Block(-5,26,7,PACKED_ICE:0)
Block(-5,26,8,PACKED_ICE:0)
Block(-5,27,-5,PACKED_ICE:0)
Block(-5,27,-4,ICE:0)
Block(-5,27,-2,LOG_2:1)
Block(-5,27,-1,LOG_2:1)
Block(-5,27,3,LOG_2:1)
Block(-5,27,4,LOG_2:1)
Block(-5,27,5,PACKED_ICE:0)
Block(-5,27,6,ICE:0)
Block(-5,27,8,PACKED_ICE:0)
Block(-5,28,-4,ICE:0)
Block(-5,28,-3,LOG_2:1)
Block(-5,28,-2,WOOD_DOUBLE_STEP:1)
Block(-5,28,4,WOOD_DOUBLE_STEP:1)
Block(-5,28,5,LOG_2:1)
Block(-5,28,6,ICE:0)
Block(-5,29,-6,PACKED_ICE:0)
Block(-5,29,-4,WOOD:5)
Block(-5,29,-3,WOOD:5)
Block(-5,29,-2,WOOD:5)
Block(-5,29,-1,WOOD:5)
Block(-5,29,0,WOOD:5)
Block(-5,29,1,ICE:0)
Block(-5,29,2,ICE:0)
Block(-5,29,3,WOOD:5)
Block(-5,29,4,WOOD:5)
Block(-5,29,5,WOOD:5)
Block(-5,29,6,WOOD:5)
Block(-5,30,-6,PACKED_ICE:0)
Block(-5,30,-4,WOOD:5)
Block(-5,30,-1,LOG:1)
Block(-5,30,0,PACKED_ICE:0)
Block(-5,30,1,ICE:0)
Block(-5,30,3,LOG:1)
Block(-5,30,4,PACKED_ICE:0)
Block(-5,30,5,PACKED_ICE:0)
Block(-5,30,6,WOOD:5)
Block(-5,31,-6,PACKED_ICE:0)
Block(-5,31,-5,ICE:0)
Block(-5,31,-4,WOOD:5)
Block(-5,31,-1,LOG:1)
Block(-5,31,0,ICE:0)
Block(-5,31,3,LOG:1)
Block(-5,31,4,PACKED_ICE:0)
Block(-5,31,5,PACKED_ICE:0)
Block(-5,31,6,WOOD:5)
Block(-5,32,-6,PACKED_ICE:0)
Block(-5,32,-5,ICE:0)
Block(-5,32,-4,WOOD_DOUBLE_STEP:5)
Block(-5,32,-3,WOOD_STEP:13)
Block(-5,32,-2,WOOD_STEP:13)
Block(-5,32,-1,WOOD_DOUBLE_STEP:5)
Block(-5,32,0,ICE:0)
Block(-5,32,1,WOOD_STEP:13)
Block(-5,32,2,WOOD_STEP:13)
Block(-5,32,3,WOOD_DOUBLE_STEP:5)
Block(-5,32,4,ICE:0)
Block(-5,32,5,WOOD_STEP:13)
Block(-5,32,6,WOOD:5)
Block(-5,33,-6,PACKED_ICE:0)
Block(-5,33,-5,ICE:0)
Block(-5,33,-4,WOOD:5)
Block(-5,33,-3,WOOD_STEP:13)
Block(-5,33,-2,WOOD_STEP:13)
Block(-5,33,-1,DARK_OAK_STAIRS:6)
Block(-5,33,3,WOOD_STEP:5)
Block(-5,33,6,WOOD:5)
Block(-5,33,8,ICE:0)
Block(-5,34,-6,PACKED_ICE:0)
Block(-5,34,-5,PACKED_ICE:0)
Block(-5,34,-4,STAINED_CLAY:9)
Block(-5,34,-3,FLOWER_POT:0)
Block(-5,34,6,STAINED_CLAY:9)
Block(-5,34,7,ICE:0)
Block(-5,34,8,ICE:0)
Block(-5,35,-5,PACKED_ICE:0)
Block(-5,35,-4,STAINED_CLAY:9)
Block(-5,35,-1,WOOD_STEP:13)
Block(-5,35,3,WOOD_STEP:13)
Block(-5,35,6,STAINED_CLAY:9)
Block(-5,35,7,ICE:0)
Block(-5,35,8,PACKED_ICE:0)
Block(-5,36,-5,PACKED_ICE:0)
Block(-5,36,-4,STAINED_CLAY:9)
Block(-5,36,-3,PACKED_ICE:0)
Block(-5,36,-2,PACKED_ICE:0)
Block(-5,36,-1,PACKED_ICE:0)
Block(-5,36,0,ICE:0)
Block(-5,36,1,WOOD_STEP:9)
Block(-5,36,2,ICE:0)
Block(-5,36,3,PACKED_ICE:0)
Block(-5,36,4,STAINED_CLAY:9)
Block(-5,36,5,STAINED_CLAY:9)
Block(-5,36,6,STAINED_CLAY:9)
Block(-5,36,7,PACKED_ICE:0)
Block(-5,36,8,PACKED_ICE:0)
Block(-5,37,-4,ICE:0)
Block(-5,37,-3,PACKED_ICE:0)
Block(-5,37,-2,ICE:0)
Block(-5,37,-1,ICE:0)
Block(-5,37,1,WOOD_STEP:1)
Block(-5,37,3,ICE:0)
Block(-5,37,4,ICE:0)
Block(-5,37,5,STAINED_CLAY:9)
Block(-5,37,6,WOOD_STEP:5)
Block(-5,37,7,PACKED_ICE:0)
Block(-5,38,-4,ICE:0)
Block(-5,38,-3,ICE:0)
Block(-5,38,-2,ICE:0)
Block(-5,38,4,ICE:0)
Block(-5,38,5,STAINED_CLAY:9)
Block(-5,38,6,PACKED_ICE:0)
Block(-5,39,-3,WOOD_STEP:5)
Block(-5,39,5,WOOD_STEP:5)
Block(-5,40,1,ICE:0)
Block(-5,41,1,LOG:5)
Block(-5,42,1,ICE:0)
Block(-4,18,-7,PACKED_ICE:0)
Block(-4,18,-6,PACKED_ICE:0)
Block(-4,18,-5,PACKED_ICE:0)
Block(-4,18,-4,PACKED_ICE:0)
Block(-4,18,-3,PACKED_ICE:0)
Block(-4,18,-2,PACKED_ICE:0)
Block(-4,18,-1,PACKED_ICE:0)
Block(-4,18,0,PACKED_ICE:0)
Block(-4,18,1,PACKED_ICE:0)
Block(-4,18,2,PACKED_ICE:0)
Block(-4,18,3,PACKED_ICE:0)
Block(-4,18,4,PACKED_ICE:0)
Block(-4,18,5,PACKED_ICE:0)
Block(-4,18,6,PACKED_ICE:0)
Block(-4,18,7,PACKED_ICE:0)
Block(-4,18,8,PACKED_ICE:0)
Block(-4,19,-7,PACKED_ICE:0)
Block(-4,19,-6,PACKED_ICE:0)
Block(-4,19,-5,PACKED_ICE:0)
Block(-4,19,-4,PACKED_ICE:0)
Block(-4,19,-3,PACKED_ICE:0)
Block(-4,19,-2,PACKED_ICE:0)
Block(-4,19,-1,PACKED_ICE:0)
Block(-4,19,0,PACKED_ICE:0)
Block(-4,19,1,PACKED_ICE:0)
Block(-4,19,2,PACKED_ICE:0)
Block(-4,19,3,PACKED_ICE:0)
Block(-4,19,4,PACKED_ICE:0)
Block(-4,19,5,PACKED_ICE:0)
Block(-4,19,6,PACKED_ICE:0)
Block(-4,19,7,PACKED_ICE:0)
Block(-4,19,8,PACKED_ICE:0)
Block(-4,20,-7,PACKED_ICE:0)
Block(-4,20,-6,PACKED_ICE:0)
Block(-4,20,-5,PACKED_ICE:0)
Block(-4,20,-4,PACKED_ICE:0)
Block(-4,20,-3,PACKED_ICE:0)
Block(-4,20,-2,PACKED_ICE:0)
Block(-4,20,-1,PACKED_ICE:0)
Block(-4,20,0,PACKED_ICE:0)
Block(-4,20,1,PACKED_ICE:0)
Block(-4,20,2,PACKED_ICE:0)
Block(-4,20,3,PACKED_ICE:0)
Block(-4,20,4,PACKED_ICE:0)
Block(-4,20,5,PACKED_ICE:0)
Block(-4,20,6,PACKED_ICE:0)
Block(-4,20,7,PACKED_ICE:0)
Block(-4,20,8,PACKED_ICE:0)
Block(-4,21,-7,PACKED_ICE:0)
Block(-4,21,-6,PACKED_ICE:0)
Block(-4,21,-5,PACKED_ICE:0)
Block(-4,21,-4,PACKED_ICE:0)
Block(-4,21,-3,PACKED_ICE:0)
Block(-4,21,-2,PACKED_ICE:0)
Block(-4,21,-1,PACKED_ICE:0)
Block(-4,21,0,PACKED_ICE:0)
Block(-4,21,1,PACKED_ICE:0)
Block(-4,21,2,PACKED_ICE:0)
Block(-4,21,3,PACKED_ICE:0)
Block(-4,21,4,PACKED_ICE:0)
Block(-4,21,5,PACKED_ICE:0)
Block(-4,21,6,PACKED_ICE:0)
Block(-4,21,7,PACKED_ICE:0)
Block(-4,21,8,PACKED_ICE:0)
Block(-4,22,-6,ICE:0)
Block(-4,22,-5,PACKED_ICE:0)
Block(-4,22,-4,ICE:0)
Block(-4,22,-3,PACKED_ICE:0)
Block(-4,22,-2,ICE:0)
Block(-4,22,-1,PACKED_ICE:0)
Block(-4,22,0,ICE:0)
Block(-4,22,1,PACKED_ICE:0)
Block(-4,22,2,PACKED_ICE:0)
Block(-4,22,3,PACKED_ICE:0)
Block(-4,22,4,PACKED_ICE:0)
Block(-4,22,5,PACKED_ICE:0)
Block(-4,22,6,ICE:0)
Block(-4,22,7,ICE:0)
Block(-4,22,8,PACKED_ICE:0)
Block(-4,23,-7,ICE:0)
Block(-4,23,-6,ICE:0)
Block(-4,23,-5,ICE:0)
Block(-4,23,-4,ICE:0)
Block(-4,23,-3,ICE:0)
Block(-4,23,-2,ICE:0)
Block(-4,23,-1,ICE:0)
Block(-4,23,0,ICE:0)
Block(-4,23,1,PACKED_ICE:0)
Block(-4,23,2,PACKED_ICE:0)
Block(-4,23,3,PACKED_ICE:0)
Block(-4,23,4,ICE:0)
Block(-4,23,5,ICE:0)
Block(-4,23,6,ICE:0)
Block(-4,23,7,ICE:0)
Block(-4,23,8,ICE:0)
Block(-4,24,-7,PACKED_ICE:0)
Block(-4,24,-6,ICE:0)
Block(-4,24,-5,ICE:0)
Block(-4,24,-4,ICE:0)
Block(-4,24,-3,ICE:0)
Block(-4,24,-2,ICE:0)
Block(-4,24,-1,ICE:0)
Block(-4,24,0,ICE:0)
Block(-4,24,1,WOOD:5)
Block(-4,24,2,ICE:0)
Block(-4,24,3,ICE:0)
Block(-4,24,4,PACKED_ICE:0)
Block(-4,24,5,ICE:0)
Block(-4,24,6,ICE:0)
Block(-4,24,7,PACKED_ICE:0)
Block(-4,24,8,PACKED_ICE:0)
Block(-4,25,-7,PACKED_ICE:0)
Block(-4,25,-6,PACKED_ICE:0)
Block(-4,25,-5,PACKED_ICE:0)
Block(-4,25,-4,PACKED_ICE:0)
Block(-4,25,-3,PACKED_ICE:0)
Block(-4,25,-2,PACKED_ICE:0)
Block(-4,25,-1,PACKED_ICE:0)
Block(-4,25,0,PACKED_ICE:0)
Block(-4,25,1,LOG_2:1)
Block(-4,25,2,PACKED_ICE:0)
Block(-4,25,3,ICE:0)
Block(-4,25,4,ICE:0)
Block(-4,25,5,ICE:0)
Block(-4,25,6,PACKED_ICE:0)
Block(-4,25,7,PACKED_ICE:0)
Block(-4,25,8,PACKED_ICE:0)
Block(-4,26,-7,PACKED_ICE:0)
Block(-4,26,-5,ICE:0)
Block(-4,26,-4,PACKED_ICE:0)
Block(-4,26,-3,PACKED_ICE:0)
Block(-4,26,-2,PACKED_ICE:0)
Block(-4,26,-1,PACKED_ICE:0)
Block(-4,26,0,LOG_2:1)
Block(-4,26,1,WOOD_STEP:9)
Block(-4,26,2,LOG_2:1)
Block(-4,26,3,PACKED_ICE:0)
Block(-4,26,4,PACKED_ICE:0)
Block(-4,26,5,PACKED_ICE:0)
Block(-4,26,6,PACKED_ICE:0)
Block(-4,26,7,ICE:0)
Block(-4,26,8,PACKED_ICE:0)
Block(-4,27,-2,LOG_2:1)
Block(-4,27,-1,LOG_2:1)
Block(-4,27,3,LOG_2:1)
Block(-4,27,4,LOG_2:1)
Block(-4,27,5,PACKED_ICE:0)
Block(-4,27,6,PACKED_ICE:0)
Block(-4,27,7,ICE:0)
Block(-4,27,8,ICE:0)
Block(-4,28,-4,PACKED_ICE:0)
Block(-4,28,-3,LOG_2:1)
Block(-4,28,-2,WOOD_DOUBLE_STEP:1)
Block(-4,28,4,WOOD_DOUBLE_STEP:1)
Block(-4,28,5,LOG_2:1)
Block(-4,28,7,ICE:0)
Block(-4,29,-4,PACKED_ICE:0)
Block(-4,29,-3,WOOD:5)
Block(-4,29,-2,WOOD:5)
Block(-4,29,-1,WOOD:5)
Block(-4,29,0,PACKED_ICE:0)
Block(-4,29,1,PACKED_ICE:0)
Block(-4,29,2,WOOD:5)
Block(-4,29,3,WOOD:5)
Block(-4,29,4,WOOD:5)
Block(-4,29,5,WOOD:5)
Block(-4,30,-5,ICE:0)
Block(-4,30,-4,WOOD:5)
Block(-4,30,-3,PACKED_ICE:0)
Block(-4,30,-2,PACKED_ICE:0)
Block(-4,30,-1,PACKED_ICE:0)
Block(-4,30,0,ICE:0)
Block(-4,30,1,ICE:0)
Block(-4,30,2,ICE:0)
Block(-4,30,3,ICE:0)
Block(-4,30,4,ICE:0)
Block(-4,30,5,ICE:0)
Block(-4,30,6,WOOD:5)
Block(-4,31,-5,ICE:0)
Block(-4,31,-4,WOOD:5)
Block(-4,31,-3,PACKED_ICE:0)
Block(-4,31,-2,PACKED_ICE:0)
Block(-4,31,-1,PACKED_ICE:0)
Block(-4,31,1,ICE:0)
Block(-4,31,2,ICE:0)
Block(-4,31,4,ICE:0)
Block(-4,31,5,PACKED_ICE:0)
Block(-4,31,6,WOOD:5)
Block(-4,31,7,PACKED_ICE:0)
Block(-4,32,-5,ICE:0)
Block(-4,32,-4,WOOD_DOUBLE_STEP:5)
Block(-4,32,-3,WOOD_STEP:13)
Block(-4,32,-2,WOOD_STEP:13)
Block(-4,32,-1,WOOD_DOUBLE_STEP:5)
Block(-4,32,0,WOOD_STEP:13)
Block(-4,32,1,WOOD_STEP:13)
Block(-4,32,2,ICE:0)
Block(-4,32,3,WOOD_STEP:13)
Block(-4,32,4,WOOD_STEP:13)
Block(-4,32,5,WOOD_STEP:13)
Block(-4,32,6,WOOD:5)
Block(-4,32,7,PACKED_ICE:0)
Block(-4,33,-5,ICE:0)
Block(-4,33,-4,WOOD_DOUBLE_STEP:5)
Block(-4,33,-3,SPRUCE_WOOD_STAIRS:0)
Block(-4,33,-1,SPRUCE_WOOD_STAIRS:0)
Block(-4,33,3,WOOD_STEP:5)
Block(-4,33,6,WOOD:5)
Block(-4,33,7,PACKED_ICE:0)
Block(-4,34,-6,ICE:0)
Block(-4,34,-5,ICE:0)
Block(-4,34,-4,STAINED_CLAY:9)
Block(-4,34,6,STAINED_CLAY:9)
Block(-4,34,7,PACKED_ICE:0)
Block(-4,35,-6,PACKED_ICE:0)
Block(-4,35,-5,ICE:0)
Block(-4,35,-4,STAINED_CLAY:9)
Block(-4,35,-1,DARK_OAK_STAIRS:4)
Block(-4,35,3,DARK_OAK_STAIRS:4)
Block(-4,35,6,STAINED_CLAY:9)
Block(-4,35,7,PACKED_ICE:0)
Block(-4,35,8,PACKED_ICE:0)
Block(-4,36,-5,ICE:0)
Block(-4,36,-4,STAINED_CLAY:9)
Block(-4,36,-3,STAINED_CLAY:9)
Block(-4,36,-2,STAINED_CLAY:9)
Block(-4,36,-1,STAINED_CLAY:9)
Block(-4,36,0,STAINED_GLASS:15)
Block(-4,36,1,WOOD_STEP:9)
Block(-4,36,2,STAINED_GLASS:15)
Block(-4,36,3,PACKED_ICE:0)
Block(-4,36,4,STAINED_CLAY:9)
Block(-4,36,5,STAINED_CLAY:9)
Block(-4,36,6,STAINED_CLAY:9)
Block(-4,36,7,PACKED_ICE:0)
Block(-4,36,8,PACKED_ICE:0)
Block(-4,37,-5,PACKED_ICE:0)
Block(-4,37,-4,PACKED_ICE:0)
Block(-4,37,-3,STAINED_CLAY:9)
Block(-4,37,-2,PACKED_ICE:0)
Block(-4,37,-1,SNOW_BLOCK:0)
Block(-4,37,1,WOOD_STEP:1)
Block(-4,37,3,ICE:0)
Block(-4,37,4,PACKED_ICE:0)
Block(-4,37,5,STAINED_CLAY:9)
Block(-4,37,6,WOOD_STEP:5)
Block(-4,37,7,PACKED_ICE:0)
Block(-4,38,-4,PACKED_ICE:0)
Block(-4,38,-3,PACKED_ICE:0)
Block(-4,38,-2,SNOW_BLOCK:0)
Block(-4,38,-1,SNOW:1)
Block(-4,38,1,ICE:0)
Block(-4,38,4,ICE:0)
Block(-4,38,5,STAINED_CLAY:9)
Block(-4,38,6,PACKED_ICE:0)
Block(-4,39,-3,WOOD_STEP:5)
Block(-4,39,-2,SNOW:2)
Block(-4,39,1,ICE:0)
Block(-4,39,5,WOOD_STEP:5)
Block(-4,40,1,ICE:0)
Block(-4,41,1,LOG:5)
Block(-4,42,1,ICE:0)
Block(-3,18,-7,PACKED_ICE:0)
Block(-3,18,-6,PACKED_ICE:0)
Block(-3,18,-5,PACKED_ICE:0)
Block(-3,18,-4,PACKED_ICE:0)
Block(-3,18,-3,PACKED_ICE:0)
Block(-3,18,-2,PACKED_ICE:0)
Block(-3,18,-1,PACKED_ICE:0)
Block(-3,18,0,PACKED_ICE:0)
Block(-3,18,1,PACKED_ICE:0)
Block(-3,18,2,PACKED_ICE:0)
Block(-3,18,3,PACKED_ICE:0)
Block(-3,18,4,PACKED_ICE:0)
Block(-3,18,5,PACKED_ICE:0)
Block(-3,18,6,PACKED_ICE:0)
Block(-3,18,7,PACKED_ICE:0)
Block(-3,18,8,PACKED_ICE:0)
Block(-3,19,-7,PACKED_ICE:0)
Block(-3,19,-6,PACKED_ICE:0)
Block(-3,19,-5,PACKED_ICE:0)
Block(-3,19,-4,PACKED_ICE:0)
Block(-3,19,-3,PACKED_ICE:0)
Block(-3,19,-2,PACKED_ICE:0)
Block(-3,19,-1,PACKED_ICE:0)
Block(-3,19,0,PACKED_ICE:0)
Block(-3,19,1,PACKED_ICE:0)
Block(-3,19,2,PACKED_ICE:0)
Block(-3,19,3,PACKED_ICE:0)
Block(-3,19,4,PACKED_ICE:0)
Block(-3,19,5,PACKED_ICE:0)
Block(-3,19,6,PACKED_ICE:0)
Block(-3,19,7,PACKED_ICE:0)
Block(-3,19,8,PACKED_ICE:0)
Block(-3,20,-7,PACKED_ICE:0)
Block(-3,20,-6,PACKED_ICE:0)
Block(-3,20,-5,PACKED_ICE:0)
Block(-3,20,-4,PACKED_ICE:0)
Block(-3,20,-3,PACKED_ICE:0)
Block(-3,20,-2,PACKED_ICE:0)
Block(-3,20,-1,PACKED_ICE:0)
Block(-3,20,0,PACKED_ICE:0)
Block(-3,20,1,PACKED_ICE:0)
Block(-3,20,2,PACKED_ICE:0)
Block(-3,20,3,PACKED_ICE:0)
Block(-3,20,4,PACKED_ICE:0)
Block(-3,20,5,PACKED_ICE:0)
Block(-3,20,6,PACKED_ICE:0)
Block(-3,20,7,PACKED_ICE:0)
Block(-3,20,8,PACKED_ICE:0)
Block(-3,21,-7,PACKED_ICE:0)
Block(-3,21,-6,PACKED_ICE:0)
Block(-3,21,-5,PACKED_ICE:0)
Block(-3,21,-4,PACKED_ICE:0)
Block(-3,21,-3,PACKED_ICE:0)
Block(-3,21,-2,PACKED_ICE:0)
Block(-3,21,-1,PACKED_ICE:0)
Block(-3,21,0,PACKED_ICE:0)
Block(-3,21,1,PACKED_ICE:0)
Block(-3,21,2,PACKED_ICE:0)
Block(-3,21,3,PACKED_ICE:0)
Block(-3,21,4,PACKED_ICE:0)
Block(-3,21,5,PACKED_ICE:0)
Block(-3,21,6,PACKED_ICE:0)
Block(-3,21,7,PACKED_ICE:0)
Block(-3,21,8,PACKED_ICE:0)
Block(-3,22,-7,ICE:0)
Block(-3,22,-6,PACKED_ICE:0)
Block(-3,22,-5,PACKED_ICE:0)
Block(-3,22,-4,PACKED_ICE:0)
Block(-3,22,-3,ICE:0)
Block(-3,22,-2,ICE:0)
Block(-3,22,-1,ICE:0)
Block(-3,22,0,ICE:0)
Block(-3,22,1,PACKED_ICE:0)
Block(-3,22,2,PACKED_ICE:0)
Block(-3,22,3,PACKED_ICE:0)
Block(-3,22,4,PACKED_ICE:0)
Block(-3,22,5,ICE:0)
Block(-3,22,6,ICE:0)
Block(-3,22,7,ICE:0)
Block(-3,22,8,ICE:0)
Block(-3,23,-7,ICE:0)
Block(-3,23,-6,ICE:0)
Block(-3,23,-5,ICE:0)
Block(-3,23,-4,ICE:0)
Block(-3,23,-3,ICE:0)
Block(-3,23,-2,ICE:0)
Block(-3,23,-1,ICE:0)
Block(-3,23,0,ICE:0)
Block(-3,23,1,PACKED_ICE:0)
Block(-3,23,2,PACKED_ICE:0)
Block(-3,23,3,PACKED_ICE:0)
Block(-3,23,4,ICE:0)
Block(-3,23,5,ICE:0)
Block(-3,23,6,ICE:0)
Block(-3,23,7,ICE:0)
Block(-3,23,8,ICE:0)
Block(-3,24,-7,ICE:0)
Block(-3,24,-6,ICE:0)
Block(-3,24,-5,ICE:0)
Block(-3,24,-4,ICE:0)
Block(-3,24,-3,ICE:0)
Block(-3,24,-2,ICE:0)
Block(-3,24,-1,ICE:0)
Block(-3,24,0,ICE:0)
Block(-3,24,1,PACKED_ICE:0)
Block(-3,24,2,ICE:0)
Block(-3,24,3,ICE:0)
Block(-3,24,4,PACKED_ICE:0)
Block(-3,24,5,ICE:0)
Block(-3,24,6,PACKED_ICE:0)
Block(-3,24,7,PACKED_ICE:0)
Block(-3,24,8,ICE:0)
Block(-3,25,-7,PACKED_ICE:0)
Block(-3,25,-6,PACKED_ICE:0)
Block(-3,25,-5,PACKED_ICE:0)
Block(-3,25,-4,PACKED_ICE:0)
Block(-3,25,-3,PACKED_ICE:0)
Block(-3,25,-2,PACKED_ICE:0)
Block(-3,25,-1,PACKED_ICE:0)
Block(-3,25,0,PACKED_ICE:0)
Block(-3,25,1,WOOD:5)
Block(-3,25,2,PACKED_ICE:0)
Block(-3,25,3,PACKED_ICE:0)
Block(-3,25,4,PACKED_ICE:0)
Block(-3,25,5,ICE:0)
Block(-3,25,6,ICE:0)
Block(-3,25,7,ICE:0)
Block(-3,25,8,PACKED_ICE:0)
Block(-3,26,-7,ICE:0)
Block(-3,26,-6,PACKED_ICE:0)
Block(-3,26,-3,PACKED_ICE:0)
Block(-3,26,-2,PACKED_ICE:0)
Block(-3,26,-1,PACKED_ICE:0)
Block(-3,26,0,LOG_2:1)
Block(-3,26,1,LOG_2:1)
Block(-3,26,2,LOG_2:1)
Block(-3,26,3,PACKED_ICE:0)
Block(-3,26,4,PACKED_ICE:0)
Block(-3,26,5,PACKED_ICE:0)
Block(-3,26,6,PACKED_ICE:0)
Block(-3,26,7,ICE:0)
Block(-3,26,8,PACKED_ICE:0)
Block(-3,27,-6,PACKED_ICE:0)
Block(-3,27,-4,ICE:0)
Block(-3,27,-3,PACKED_ICE:0)
Block(-3,27,-2,LOG_2:1)
Block(-3,27,-1,LOG_2:1)
Block(-3,27,0,LOG_2:1)
Block(-3,27,1,LOG_2:1)
Block(-3,27,2,LOG_2:1)
Block(-3,27,3,LOG_2:1)
Block(-3,27,4,LOG_2:1)
Block(-3,27,5,PACKED_ICE:0)
Block(-3,27,8,PACKED_ICE:0)
Block(-3,28,-4,ICE:0)
Block(-3,28,-3,LOG_2:1)
Block(-3,28,-2,LOG_2:1)
Block(-3,28,-1,LOG_2:1)
Block(-3,28,0,LOG_2:1)
Block(-3,28,1,LOG_2:1)
Block(-3,28,2,LOG_2:1)
Block(-3,28,3,LOG_2:1)
Block(-3,28,4,LOG_2:1)
Block(-3,28,5,LOG_2:1)
Block(-3,29,-4,ICE:0)
Block(-3,29,-3,WOOD:5)
Block(-3,29,-2,WOOD:5)
Block(-3,29,-1,WOOD:5)
Block(-3,29,0,WOOD:5)
Block(-3,29,1,WOOD:5)
Block(-3,29,2,WOOD:5)
Block(-3,29,3,WOOD:5)
Block(-3,29,4,WOOD:5)
Block(-3,29,5,WOOD:5)
Block(-3,29,6,ICE:0)
Block(-3,30,-4,PACKED_ICE:0)
Block(-3,30,-3,WOOD:5)
Block(-3,30,-2,PACKED_ICE:0)
Block(-3,30,-1,PACKED_ICE:0)
Block(-3,30,0,LOG:1)
RandomBlock(-3,30,1,AIR:0,20,CHEST:4,../../../../Chests/Loot/ShipJunk_1.nbt,10,CHEST:4,../../../../Chests/Loot/ShipJunk_2.nbt,10,CHEST:4,../../../../Chests/Loot/ShipJunk_3.nbt,10,CHEST:4,../../../../Chests/Loot/ShipJunk_4.nbt,10,CHEST:4,../../../../Chests/Loot/ShipJunk_5.nbt,10,CHEST:4,../../../../Chests/Lore/Frozen_1.nbt,1,CHEST:4,../../../../Chests/Lore/Frozen_2.nbt,1,CHEST:4,../../../../Chests/Lore/Frozen_3.nbt,1,CHEST:4,../../../../Chests/Lore/Frozen_4.nbt,1,CHEST:4,../../../../Chests/Lore/Frozen_5.nbt,1,CHEST:4,../../../../Chests/Loot/Common1.nbt,10,CHEST:4,../../../../Chests/Loot/Common2.nbt,10,CHEST:4,../../../../Chests/Loot/Common3.nbt,10,CHEST:4,../../../../Chests/Loot/Common4.nbt,10,CHEST:4,../../../../Chests/Loot/Common5.nbt,10,CHEST:4,../../../../Chests/Loot/Common6.nbt,10,CHEST:4,../../../../Chests/Loot/Common7.nbt,10,CHEST:4,../../../../Chests/Loot/Common8.nbt,10,CHEST:4,../../../../Chests/Loot/Common9.nbt,10,CHEST:4,../../../../Chests/Loot/Common10.nbt,10,CHEST:4,../../../../Chests/Loot/Common10.nbt,11,CHEST:4,../../../../Chests/Loot/Common12.nbt,10,CHEST:4,../../../../Chests/Loot/Common13.nbt,10,CHEST:4,../../../../Chests/Loot/Common14.nbt,10,CHEST:4,../../../../Chests/Loot/Common15.nbt,10,CHEST:4,../../../../Chests/Lore/Frozen_1.nbt,2,CHEST:4,../../../../Chests/Lore/Frozen_3.nbt,2,CHEST:4,../../../../Chests/Lore/Frozen_4.nbt,2,CHEST:4,../../../../Chests/Lore/Frozen_5.nbt,2,CHEST:4,../../../../Chests/Lore/Frozen_5.nbt,2,CHEST:4,../../../../Chests/Loot/Rare1.nbt,5,CHEST:4,../../../../Chests/Loot/Rare2.nbt,5,CHEST:4,../../../../Chests/Loot/Rare3.nbt,5,CHEST:4,../../../../Chests/Loot/Rare4.nbt,5,CHEST:4,../../../../Chests/Loot/Rare5.nbt,5,CHEST:4,../../../../Chests/Loot/Rare6.nbt,5,CHEST:4,../../../../Chests/Loot/Rare7.nbt,5,CHEST:4,../../../../Chests/Loot/Rare8.nbt,5,CHEST:4,../../../../Chests/Loot/Rare9.nbt,5,CHEST:4,../../../../Chests/Loot/Rare10.nbt,5,CHEST:4,../../../../Chests/Loot/Rare11.nbt,5,CHEST:4,../../../../Chests/Loot/Rare12.nbt,5,CHEST:4,../../../../Chests/Loot/Rare13.nbt,5,CHEST:4,../../../../Chests/Loot/Rare14.nbt,5,CHEST:4,../../../../Chests/Loot/Rare15.nbt,5,CHEST:4,../../../../Chests/Loot/Epic1.nbt,2,CHEST:4,../../../../Chests/Loot/Epic2.nbt,2,CHEST:4,../../../../Chests/Loot/Epic3.nbt,2,CHEST:4,../../../../Chests/Loot/Epic4.nbt,2,CHEST:4,../../../../Chests/Loot/Epic5.nbt,2,CHEST:4,../../../../Chests/Loot/Epic6.nbt,2,CHEST:4,../../../../Chests/Loot/Epic7.nbt,2,CHEST:4,../../../../Chests/Loot/Epic8.nbt,2,CHEST:4,../../../../Chests/Loot/Epic9.nbt,2,CHEST:4,../../../../Chests/Loot/Epic10.nbt,2,CHEST:4,../../../../Chests/Loot/Epic11.nbt,2,CHEST:4,../../../../Chests/Loot/Epic12.nbt,2,CHEST:4,../../../../Chests/Loot/Epic13.nbt,2,CHEST:4,../../../../Chests/Loot/Epic14.nbt,2,CHEST:4,../../../../Chests/Loot/Epic15.nbt,5,CHEST:4,../../../../Chests/Loot/Rare1.nbt,5,CHEST:4,../../../../Chests/Loot/Rare2.nbt,5,CHEST:4,../../../../Chests/Loot/Rare3.nbt,5,CHEST:4,../../../../Chests/Loot/Rare4.nbt,5,CHEST:4,../../../../Chests/Loot/Rare5.nbt,10,CHEST:4,../../../../Chests/Loot/Rare6.nbt,10,CHEST:4,../../../../Chests/Loot/Rare7.nbt,10,CHEST:4,../../../../Chests/Loot/Rare8.nbt,10,CHEST:4,../../../../Chests/Loot/Rare9.nbt,10,CHEST:4,../../../../Chests/Loot/Rare10.nbt,15,CHEST:4,../../../../Chests/Loot/Rare11.nbt,15,CHEST:4,../../../../Chests/Loot/Rare12.nbt,15,CHEST:4,../../../../Chests/Loot/Rare13.nbt,15,CHEST:4,../../../../Chests/Loot/Rare14.nbt,15,CHEST:4,../../../../Chests/Loot/Rare15.nbt,15,CHEST:4,../../../../Chests/Loot/Epic15.nbt,100)
Block(-3,30,2,LOG:1)
Block(-3,30,3,ICE:0)
Block(-3,30,4,ICE:0)
Block(-3,30,5,WOOD:5)
Block(-3,30,6,ICE:0)
Block(-3,31,-4,WOOD:5)
Block(-3,31,-3,WOOD_DOUBLE_STEP:5)
Block(-3,31,-2,PACKED_ICE:0)
Block(-3,31,0,LOG:1)
Block(-3,31,1,ICE:0)
Block(-3,31,2,LOG:1)
Block(-3,31,3,ICE:0)
Block(-3,31,4,ICE:0)
Block(-3,31,5,WOOD_DOUBLE_STEP:5)
Block(-3,31,6,WOOD:5)
Block(-3,32,-4,WOOD_DOUBLE_STEP:5)
Block(-3,32,-3,WOOD_DOUBLE_STEP:5)
Block(-3,32,-2,WOOD_STEP:13)
Block(-3,32,-1,WOOD_STEP:13)
Block(-3,32,0,WOOD_DOUBLE_STEP:5)
Block(-3,32,1,PACKED_ICE:0)
Block(-3,32,2,WOOD_DOUBLE_STEP:5)
Block(-3,32,3,WOOD_STEP:13)
Block(-3,32,4,WOOD_STEP:13)
Block(-3,32,5,WOOD_DOUBLE_STEP:5)
Block(-3,32,6,WOOD:5)
Block(-3,32,8,ICE:0)
Block(-3,33,-6,ICE:0)
Block(-3,33,-4,WOOD_DOUBLE_STEP:5)
Block(-3,33,-3,STAINED_CLAY:9)
Block(-3,33,-2,STAINED_CLAY:9)
Block(-3,33,-1,WOOD_DOUBLE_STEP:5)
Block(-3,33,3,WOOD:5)
Block(-3,33,4,STAINED_CLAY:9)
Block(-3,33,5,STAINED_CLAY:9)
Block(-3,33,6,WOOD:5)
Block(-3,33,7,ICE:0)
Block(-3,33,8,ICE:0)
Block(-3,34,-6,ICE:0)
Block(-3,34,-5,PACKED_ICE:0)
Block(-3,34,-4,WOOD_DOUBLE_STEP:5)
Block(-3,34,-3,STAINED_CLAY:9)
Block(-3,34,-2,STAINED_CLAY:9)
Block(-3,34,-1,WOOD_DOUBLE_STEP:5)
Block(-3,34,3,WOOD:5)
Block(-3,34,4,STAINED_CLAY:9)
Block(-3,34,5,STAINED_CLAY:9)
Block(-3,34,6,WOOD:5)
Block(-3,34,7,PACKED_ICE:0)
Block(-3,34,8,PACKED_ICE:0)
Block(-3,35,-6,ICE:0)
Block(-3,35,-5,PACKED_ICE:0)
Block(-3,35,-4,STAINED_CLAY:9)
Block(-3,35,-3,STAINED_CLAY:9)
Block(-3,35,-2,STAINED_CLAY:9)
Block(-3,35,-1,WOOD_DOUBLE_STEP:5)
Block(-3,35,0,DARK_OAK_STAIRS:7)
Block(-3,35,1,WOOD_STEP:13)
Block(-3,35,2,DARK_OAK_STAIRS:6)
Block(-3,35,3,WOOD:5)
Block(-3,35,4,STAINED_CLAY:9)
Block(-3,35,5,STAINED_CLAY:9)
Block(-3,35,6,STAINED_CLAY:9)
Block(-3,35,7,PACKED_ICE:0)
Block(-3,35,8,PACKED_ICE:0)
Block(-3,36,-5,PACKED_ICE:0)
Block(-3,36,-4,STAINED_CLAY:9)
Block(-3,36,-3,STAINED_CLAY:9)
Block(-3,36,-2,STAINED_CLAY:9)
Block(-3,36,-1,STAINED_CLAY:9)
Block(-3,36,0,STAINED_CLAY:9)
Block(-3,36,1,STAINED_CLAY:9)
Block(-3,36,2,STAINED_CLAY:9)
Block(-3,36,3,STAINED_CLAY:9)
Block(-3,36,4,STAINED_CLAY:9)
Block(-3,36,5,STAINED_CLAY:9)
Block(-3,36,6,STAINED_CLAY:9)
Block(-3,36,7,PACKED_ICE:0)
Block(-3,37,-5,PACKED_ICE:0)
Block(-3,37,-4,DARK_OAK_STAIRS:0)
Block(-3,37,-3,WOOD:5)
Block(-3,37,-2,ICE:0)
Block(-3,37,-1,ICE:0)
Block(-3,37,0,SNOW_BLOCK:0)
Block(-3,37,1,WOOD_STEP:1)
Block(-3,37,2,ICE:0)
Block(-3,37,3,PACKED_ICE:0)
Block(-3,37,4,PACKED_ICE:0)
Block(-3,37,5,STAINED_CLAY:9)
Block(-3,37,6,DARK_OAK_STAIRS:0)
Block(-3,37,7,ICE:0)
Block(-3,38,-5,PACKED_ICE:0)
Block(-3,38,-4,ICE:0)
Block(-3,38,-3,STAINED_CLAY:9)
Block(-3,38,-2,ICE:0)
Block(-3,38,-1,SNOW_BLOCK:0)
Block(-3,38,0,SNOW:2)
Block(-3,38,3,ICE:0)
Block(-3,38,4,ICE:0)
Block(-3,38,5,STAINED_CLAY:9)
Block(-3,38,6,ICE:0)
Block(-3,39,-4,ICE:0)
Block(-3,39,-3,DARK_OAK_STAIRS:0)
Block(-3,39,-2,SNOW_BLOCK:0)
Block(-3,39,-1,SNOW:1)
Block(-3,39,1,ICE:0)
Block(-3,39,2,WOOL:15)
Block(-3,39,4,ICE:0)
Block(-3,39,5,DARK_OAK_STAIRS:0)
Block(-3,40,-2,SNOW:2)
Block(-3,40,1,LOG:1)
Block(-3,40,2,WOOL:15)
Block(-3,41,1,LOG:5)
Block(-3,41,2,SNOW:2)
Block(-3,42,1,SNOW:0)
Block(-2,18,-7,PACKED_ICE:0)
Block(-2,18,-6,PACKED_ICE:0)
Block(-2,18,-5,PACKED_ICE:0)
Block(-2,18,-4,PACKED_ICE:0)
Block(-2,18,-3,PACKED_ICE:0)
Block(-2,18,-2,PACKED_ICE:0)
Block(-2,18,-1,PACKED_ICE:0)
Block(-2,18,0,PACKED_ICE:0)
Block(-2,18,1,PACKED_ICE:0)
Block(-2,18,2,PACKED_ICE:0)
Block(-2,18,3,PACKED_ICE:0)
Block(-2,18,4,PACKED_ICE:0)
Block(-2,18,5,PACKED_ICE:0)
Block(-2,18,6,PACKED_ICE:0)
Block(-2,18,7,PACKED_ICE:0)
Block(-2,18,8,PACKED_ICE:0)
Block(-2,19,-7,PACKED_ICE:0)
Block(-2,19,-6,PACKED_ICE:0)
Block(-2,19,-5,PACKED_ICE:0)
Block(-2,19,-4,PACKED_ICE:0)
Block(-2,19,-3,PACKED_ICE:0)
Block(-2,19,-2,PACKED_ICE:0)
Block(-2,19,-1,PACKED_ICE:0)
Block(-2,19,0,PACKED_ICE:0)
Block(-2,19,1,PACKED_ICE:0)
Block(-2,19,2,PACKED_ICE:0)
Block(-2,19,3,PACKED_ICE:0)
Block(-2,19,4,PACKED_ICE:0)
Block(-2,19,5,PACKED_ICE:0)
Block(-2,19,6,PACKED_ICE:0)
Block(-2,19,7,PACKED_ICE:0)
Block(-2,19,8,PACKED_ICE:0)
Block(-2,20,-7,PACKED_ICE:0)
Block(-2,20,-6,PACKED_ICE:0)
Block(-2,20,-5,PACKED_ICE:0)
Block(-2,20,-4,PACKED_ICE:0)
Block(-2,20,-3,PACKED_ICE:0)
Block(-2,20,-2,PACKED_ICE:0)
Block(-2,20,-1,PACKED_ICE:0)
Block(-2,20,0,PACKED_ICE:0)
Block(-2,20,1,PACKED_ICE:0)
Block(-2,20,2,PACKED_ICE:0)
Block(-2,20,3,PACKED_ICE:0)
Block(-2,20,4,PACKED_ICE:0)
Block(-2,20,5,PACKED_ICE:0)
Block(-2,20,6,PACKED_ICE:0)
Block(-2,20,7,PACKED_ICE:0)
Block(-2,20,8,PACKED_ICE:0)
Block(-2,21,-7,PACKED_ICE:0)
Block(-2,21,-6,PACKED_ICE:0)
Block(-2,21,-5,PACKED_ICE:0)
Block(-2,21,-4,PACKED_ICE:0)
Block(-2,21,-3,PACKED_ICE:0)
Block(-2,21,-2,PACKED_ICE:0)
Block(-2,21,-1,PACKED_ICE:0)
Block(-2,21,0,PACKED_ICE:0)
Block(-2,21,1,PACKED_ICE:0)
Block(-2,21,2,PACKED_ICE:0)
Block(-2,21,3,PACKED_ICE:0)
Block(-2,21,4,PACKED_ICE:0)
Block(-2,21,5,PACKED_ICE:0)
Block(-2,21,6,PACKED_ICE:0)
Block(-2,21,7,PACKED_ICE:0)
Block(-2,21,8,PACKED_ICE:0)
Block(-2,22,-7,PACKED_ICE:0)
Block(-2,22,-6,PACKED_ICE:0)
Block(-2,22,-5,PACKED_ICE:0)
Block(-2,22,-4,PACKED_ICE:0)
Block(-2,22,-3,PACKED_ICE:0)
Block(-2,22,-2,ICE:0)
Block(-2,22,-1,ICE:0)
Block(-2,22,0,ICE:0)
Block(-2,22,1,PACKED_ICE:0)
Block(-2,22,2,PACKED_ICE:0)
Block(-2,22,3,PACKED_ICE:0)
Block(-2,22,4,ICE:0)
Block(-2,22,5,ICE:0)
Block(-2,22,6,ICE:0)
Block(-2,22,7,ICE:0)
Block(-2,22,8,ICE:0)
Block(-2,23,-7,ICE:0)
Block(-2,23,-6,ICE:0)
Block(-2,23,-5,ICE:0)
Block(-2,23,-4,ICE:0)
Block(-2,23,-3,ICE:0)
Block(-2,23,-2,ICE:0)
Block(-2,23,-1,ICE:0)
Block(-2,23,0,ICE:0)
Block(-2,23,1,PACKED_ICE:0)
Block(-2,23,2,PACKED_ICE:0)
Block(-2,23,3,PACKED_ICE:0)
Block(-2,23,4,ICE:0)
Block(-2,23,5,ICE:0)
Block(-2,23,6,ICE:0)
Block(-2,23,7,ICE:0)
Block(-2,23,8,ICE:0)
Block(-2,24,-7,PACKED_ICE:0)
Block(-2,24,-6,ICE:0)
Block(-2,24,-5,ICE:0)
Block(-2,24,-4,ICE:0)
Block(-2,24,-3,PACKED_ICE:0)
Block(-2,24,-2,ICE:0)
Block(-2,24,-1,ICE:0)
Block(-2,24,0,ICE:0)
Block(-2,24,1,PACKED_ICE:0)
Block(-2,24,2,PACKED_ICE:0)
Block(-2,24,3,ICE:0)
Block(-2,24,4,ICE:0)
Block(-2,24,5,ICE:0)
Block(-2,24,6,PACKED_ICE:0)
Block(-2,24,7,PACKED_ICE:0)
Block(-2,24,8,ICE:0)
Block(-2,25,-7,PACKED_ICE:0)
Block(-2,25,-6,PACKED_ICE:0)
Block(-2,25,-5,PACKED_ICE:0)
Block(-2,25,-4,PACKED_ICE:0)
Block(-2,25,-3,PACKED_ICE:0)
Block(-2,25,-2,PACKED_ICE:0)
Block(-2,25,-1,PACKED_ICE:0)
Block(-2,25,0,PACKED_ICE:0)
Block(-2,25,1,PACKED_ICE:0)
Block(-2,25,2,PACKED_ICE:0)
Block(-2,25,3,PACKED_ICE:0)
Block(-2,25,4,ICE:0)
Block(-2,25,5,ICE:0)
Block(-2,25,6,PACKED_ICE:0)
Block(-2,25,7,ICE:0)
Block(-2,25,8,ICE:0)
Block(-2,26,-7,PACKED_ICE:0)
Block(-2,26,-6,PACKED_ICE:0)
Block(-2,26,-5,PACKED_ICE:0)
Block(-2,26,-4,PACKED_ICE:0)
Block(-2,26,-3,PACKED_ICE:0)
Block(-2,26,-2,PACKED_ICE:0)
Block(-2,26,-1,ICE:0)
Block(-2,26,0,PACKED_ICE:0)
Block(-2,26,1,ICE:0)
Block(-2,26,2,ICE:0)
Block(-2,26,3,PACKED_ICE:0)
Block(-2,26,4,PACKED_ICE:0)
Block(-2,26,5,PACKED_ICE:0)
Block(-2,26,6,ICE:0)
Block(-2,26,7,PACKED_ICE:0)
Block(-2,26,8,PACKED_ICE:0)
Block(-2,27,-7,ICE:0)
Block(-2,27,-6,PACKED_ICE:0)
Block(-2,27,-5,ICE:0)
Block(-2,27,-4,PACKED_ICE:0)
Block(-2,27,-2,PACKED_ICE:0)
Block(-2,27,-1,PACKED_ICE:0)
Block(-2,27,0,PACKED_ICE:0)
Block(-2,27,1,ICE:0)
Block(-2,27,2,ICE:0)
Block(-2,27,3,ICE:0)
Block(-2,27,4,PACKED_ICE:0)
Block(-2,27,5,ICE:0)
Block(-2,27,7,PACKED_ICE:0)
Block(-2,27,8,PACKED_ICE:0)
Block(-2,28,-6,PACKED_ICE:0)
Block(-2,28,-5,ICE:0)
Block(-2,28,-3,ICE:0)
Block(-2,28,-2,PACKED_ICE:0)
Block(-2,28,0,PACKED_ICE:0)
Block(-2,28,1,ICE:0)
Block(-2,28,2,PACKED_ICE:0)
Block(-2,28,5,ICE:0)
Block(-2,28,6,PACKED_ICE:0)
Block(-2,28,7,ICE:0)
Block(-2,28,8,PACKED_ICE:0)
Block(-2,29,-6,PACKED_ICE:0)
Block(-2,29,-4,PACKED_ICE:0)
Block(-2,29,-3,ICE:0)
Block(-2,29,0,ICE:0)
Block(-2,29,1,ICE:0)
Block(-2,29,2,ICE:0)
Block(-2,29,4,ICE:0)
Block(-2,29,6,PACKED_ICE:0)
Block(-2,29,8,PACKED_ICE:0)
Block(-2,30,-5,ICE:0)
Block(-2,30,-4,PACKED_ICE:0)
Block(-2,30,-3,ICE:0)
Block(-2,30,-2,WOOD:5)
Block(-2,30,-1,WOOD:5)
Block(-2,30,0,WOOD:5)
Block(-2,30,1,WOOD:5)
Block(-2,30,2,WOOD:5)
Block(-2,30,3,WOOD:5)
Block(-2,30,4,WOOD:5)
Block(-2,30,5,ICE:0)
Block(-2,30,6,PACKED_ICE:0)
Block(-2,30,8,PACKED_ICE:0)
Block(-2,31,-5,ICE:0)
Block(-2,31,-4,PACKED_ICE:0)
Block(-2,31,-3,WOOD:5)
Block(-2,31,-2,WOOD:5)
Block(-2,31,-1,WOOD:5)
Block(-2,31,0,WOOD:5)
Block(-2,31,1,WOOD:5)
Block(-2,31,2,WOOD:5)
Block(-2,31,3,WOOD:5)
Block(-2,31,4,WOOD:5)
Block(-2,31,5,WOOD:5)
Block(-2,31,6,PACKED_ICE:0)
Block(-2,31,7,ICE:0)
Block(-2,32,-5,ICE:0)
Block(-2,32,-4,PACKED_ICE:0)
Block(-2,32,-3,WOOD:5)
Block(-2,32,-2,WOOD_DOUBLE_STEP:5)
Block(-2,32,-1,WOOD_DOUBLE_STEP:5)
Block(-2,32,0,WOOD_DOUBLE_STEP:5)
Block(-2,32,1,WOOD_DOUBLE_STEP:5)
Block(-2,32,2,WOOD_DOUBLE_STEP:5)
Block(-2,32,3,WOOD_DOUBLE_STEP:5)
Block(-2,32,4,WOOD_DOUBLE_STEP:5)
Block(-2,32,5,WOOD:5)
Block(-2,32,6,PACKED_ICE:0)
Block(-2,32,7,ICE:0)
Block(-2,33,-5,ICE:0)
Block(-2,33,-4,WOOD_DOUBLE_STEP:5)
Block(-2,33,-3,BOOKSHELF:0)
Block(-2,33,-2,BOOKSHELF:0)
Block(-2,33,-1,SPRUCE_WOOD_STAIRS:3)
Block(-2,33,3,SPRUCE_WOOD_STAIRS:2)
Block(-2,33,4,BOOKSHELF:0)
Block(-2,33,5,BOOKSHELF:0)
Block(-2,33,6,WOOD:5)
Block(-2,33,7,ICE:0)
Block(-2,33,8,PACKED_ICE:0)
Block(-2,34,-6,ICE:0)
Block(-2,34,-5,ICE:0)
Block(-2,34,-4,WOOD_DOUBLE_STEP:5)
Block(-2,34,-3,BOOKSHELF:0)
Block(-2,34,5,BOOKSHELF:0)
Block(-2,34,6,WOOD:5)
Block(-2,34,7,ICE:0)
Block(-2,34,8,PACKED_ICE:0)
Block(-2,35,-6,PACKED_ICE:0)
Block(-2,35,-5,ICE:0)
Block(-2,35,-4,STAINED_GLASS:15)
Block(-2,35,-3,SKULL:1)
Block(-2,35,5,SKULL:1)
Block(-2,35,6,STAINED_GLASS:15)
Block(-2,35,7,ICE:0)
Block(-2,36,-6,PACKED_ICE:0)
Block(-2,36,-5,ICE:0)
Block(-2,36,-4,STAINED_GLASS:15)
Block(-2,36,6,STAINED_GLASS:15)
Block(-2,36,7,ICE:0)
Block(-2,36,8,ICE:0)
Block(-2,37,-5,ICE:0)
Block(-2,37,-4,DARK_OAK_STAIRS:2)
Block(-2,37,-3,STAINED_CLAY:9)
Block(-2,37,-2,WOOD_STEP:1)
Block(-2,37,-1,PACKED_ICE:0)
Block(-2,37,0,PACKED_ICE:0)
Block(-2,37,1,PACKED_ICE:0)
Block(-2,37,2,WOOD_STEP:1)
Block(-2,37,3,PACKED_ICE:0)
Block(-2,37,4,PACKED_ICE:0)
Block(-2,37,5,STAINED_CLAY:9)
Block(-2,37,6,DARK_OAK_STAIRS:3)
Block(-2,37,7,PACKED_ICE:0)
Block(-2,38,-4,ICE:0)
Block(-2,38,-3,STAINED_CLAY:9)
Block(-2,38,-2,ICE:0)
Block(-2,38,-1,ICE:0)
Block(-2,38,0,SNOW_BLOCK:0)
Block(-2,38,1,ICE:0)
Block(-2,38,2,PACKED_ICE:0)
Block(-2,38,3,ICE:0)
Block(-2,38,4,PACKED_ICE:0)
Block(-2,38,5,STAINED_CLAY:9)
Block(-2,38,6,PACKED_ICE:0)
Block(-2,39,-4,ICE:0)
Block(-2,39,-3,STAINED_CLAY:9)
Block(-2,39,-2,ICE:0)
Block(-2,39,-1,SNOW_BLOCK:0)
Block(-2,39,0,SNOW:1)
Block(-2,39,1,LOG:1)
Block(-2,39,3,ICE:0)
Block(-2,39,4,ICE:0)
Block(-2,39,5,STAINED_CLAY:9)
Block(-2,39,6,ICE:0)
Block(-2,40,-3,WOOD_STEP:5)
Block(-2,40,-2,SNOW_BLOCK:0)
Block(-2,40,-1,SNOW:3)
Block(-2,40,1,LOG:5)
Block(-2,40,5,WOOD_STEP:5)
Block(-2,41,-2,SNOW:1)
Block(-2,41,1,SNOW:1)
Block(-1,18,-7,PACKED_ICE:0)
Block(-1,18,-6,PACKED_ICE:0)
Block(-1,18,-5,PACKED_ICE:0)
Block(-1,18,-4,PACKED_ICE:0)
Block(-1,18,-3,PACKED_ICE:0)
Block(-1,18,-2,PACKED_ICE:0)
Block(-1,18,-1,PACKED_ICE:0)
Block(-1,18,0,PACKED_ICE:0)
Block(-1,18,1,PACKED_ICE:0)
Block(-1,18,2,PACKED_ICE:0)
Block(-1,18,3,PACKED_ICE:0)
Block(-1,18,4,PACKED_ICE:0)
Block(-1,18,5,PACKED_ICE:0)
Block(-1,18,6,PACKED_ICE:0)
Block(-1,18,7,PACKED_ICE:0)
Block(-1,18,8,PACKED_ICE:0)
Block(-1,19,-7,PACKED_ICE:0)
Block(-1,19,-6,PACKED_ICE:0)
Block(-1,19,-5,PACKED_ICE:0)
Block(-1,19,-4,PACKED_ICE:0)
Block(-1,19,-3,PACKED_ICE:0)
Block(-1,19,-2,PACKED_ICE:0)
Block(-1,19,-1,PACKED_ICE:0)
Block(-1,19,0,PACKED_ICE:0)
Block(-1,19,1,PACKED_ICE:0)
Block(-1,19,2,PACKED_ICE:0)
Block(-1,19,3,PACKED_ICE:0)
Block(-1,19,4,PACKED_ICE:0)
Block(-1,19,5,PACKED_ICE:0)
Block(-1,19,6,PACKED_ICE:0)
Block(-1,19,7,PACKED_ICE:0)
Block(-1,19,8,PACKED_ICE:0)
Block(-1,20,-7,PACKED_ICE:0)
Block(-1,20,-6,PACKED_ICE:0)
Block(-1,20,-5,PACKED_ICE:0)
Block(-1,20,-4,PACKED_ICE:0)
Block(-1,20,-3,PACKED_ICE:0)
Block(-1,20,-2,PACKED_ICE:0)
Block(-1,20,-1,PACKED_ICE:0)
Block(-1,20,0,PACKED_ICE:0)
Block(-1,20,1,PACKED_ICE:0)
Block(-1,20,2,PACKED_ICE:0)
Block(-1,20,3,PACKED_ICE:0)
Block(-1,20,4,PACKED_ICE:0)
Block(-1,20,5,PACKED_ICE:0)
Block(-1,20,6,PACKED_ICE:0)
Block(-1,20,7,PACKED_ICE:0)
Block(-1,20,8,PACKED_ICE:0)
Block(-1,21,-7,PACKED_ICE:0)
Block(-1,21,-6,PACKED_ICE:0)
Block(-1,21,-5,PACKED_ICE:0)
Block(-1,21,-4,PACKED_ICE:0)
Block(-1,21,-3,PACKED_ICE:0)
Block(-1,21,-2,PACKED_ICE:0)
Block(-1,21,-1,PACKED_ICE:0)
Block(-1,21,0,PACKED_ICE:0)
Block(-1,21,1,PACKED_ICE:0)
Block(-1,21,2,PACKED_ICE:0)
Block(-1,21,3,PACKED_ICE:0)
Block(-1,21,4,PACKED_ICE:0)
Block(-1,21,5,PACKED_ICE:0)
Block(-1,21,6,PACKED_ICE:0)
Block(-1,21,7,PACKED_ICE:0)
Block(-1,21,8,PACKED_ICE:0)
Block(-1,22,-7,PACKED_ICE:0)
Block(-1,22,-6,PACKED_ICE:0)
Block(-1,22,-5,PACKED_ICE:0)
Block(-1,22,-4,PACKED_ICE:0)
Block(-1,22,-3,ICE:0)
Block(-1,22,-2,ICE:0)
Block(-1,22,-1,PACKED_ICE:0)
Block(-1,22,0,PACKED_ICE:0)
Block(-1,22,1,WOOD:5)
Block(-1,22,2,PACKED_ICE:0)
Block(-1,22,3,PACKED_ICE:0)
Block(-1,22,4,ICE:0)
Block(-1,22,5,ICE:0)
Block(-1,22,6,ICE:0)
Block(-1,22,7,ICE:0)
Block(-1,22,8,ICE:0)
Block(-1,23,-7,ICE:0)
Block(-1,23,-6,ICE:0)
Block(-1,23,-5,ICE:0)
Block(-1,23,-4,ICE:0)
Block(-1,23,-3,ICE:0)
Block(-1,23,-2,ICE:0)
Block(-1,23,-1,PACKED_ICE:0)
Block(-1,23,0,PACKED_ICE:0)
Block(-1,23,1,LOG_2:1)
Block(-1,23,3,PACKED_ICE:0)
Block(-1,23,4,ICE:0)
Block(-1,23,5,ICE:0)
Block(-1,23,6,ICE:0)
Block(-1,23,7,ICE:0)
Block(-1,23,8,ICE:0)
Block(-1,24,-7,PACKED_ICE:0)
Block(-1,24,-6,PACKED_ICE:0)
Block(-1,24,-5,PACKED_ICE:0)
Block(-1,24,-4,PACKED_ICE:0)
Block(-1,24,-3,PACKED_ICE:0)
Block(-1,24,-2,ICE:0)
Block(-1,24,-1,PACKED_ICE:0)
Block(-1,24,0,ICE:0)
Block(-1,24,1,LOG_2:1)
Block(-1,24,2,PACKED_ICE:0)
Block(-1,24,3,ICE:0)
Block(-1,24,4,ICE:0)
Block(-1,24,5,PACKED_ICE:0)
Block(-1,24,6,PACKED_ICE:0)
Block(-1,24,7,PACKED_ICE:0)
Block(-1,24,8,ICE:0)
Block(-1,25,-7,PACKED_ICE:0)
Block(-1,25,-6,PACKED_ICE:0)
Block(-1,25,-5,PACKED_ICE:0)
Block(-1,25,-4,PACKED_ICE:0)
Block(-1,25,-3,PACKED_ICE:0)
Block(-1,25,-2,PACKED_ICE:0)
Block(-1,25,-1,PACKED_ICE:0)
Block(-1,25,0,PACKED_ICE:0)
Block(-1,25,1,LOG_2:1)
Block(-1,25,2,PACKED_ICE:0)
Block(-1,25,3,PACKED_ICE:0)
Block(-1,25,4,ICE:0)
Block(-1,25,5,PACKED_ICE:0)
Block(-1,25,6,PACKED_ICE:0)
Block(-1,25,7,PACKED_ICE:0)
Block(-1,25,8,ICE:0)
Block(-1,26,-7,ICE:0)
Block(-1,26,-6,PACKED_ICE:0)
Block(-1,26,-4,PACKED_ICE:0)
Block(-1,26,-3,PACKED_ICE:0)
Block(-1,26,-2,PACKED_ICE:0)
Block(-1,26,-1,ICE:0)
Block(-1,26,0,PACKED_ICE:0)
Block(-1,26,1,LOG_2:1)
Block(-1,26,2,PACKED_ICE:0)
Block(-1,26,3,PACKED_ICE:0)
Block(-1,26,5,ICE:0)
Block(-1,26,6,PACKED_ICE:0)
Block(-1,26,7,ICE:0)
Block(-1,26,8,PACKED_ICE:0)
Block(-1,27,-6,PACKED_ICE:0)
Block(-1,27,-3,ICE:0)
Block(-1,27,0,ICE:0)
Block(-1,27,1,LOG_2:1)
Block(-1,27,2,PACKED_ICE:0)
Block(-1,27,3,ICE:0)
Block(-1,27,6,PACKED_ICE:0)
Block(-1,27,7,ICE:0)
Block(-1,27,8,PACKED_ICE:0)
Block(-1,28,-6,ICE:0)
Block(-1,28,-1,ICE:0)
Block(-1,28,0,ICE:0)
Block(-1,28,1,LOG_2:1)
Block(-1,28,2,PACKED_ICE:0)
Block(-1,28,3,ICE:0)
Block(-1,28,6,PACKED_ICE:0)
Block(-1,28,8,PACKED_ICE:0)
Block(-1,29,-1,ICE:0)
Block(-1,29,1,WOOD:5)
Block(-1,29,2,PACKED_ICE:0)
Block(-1,29,3,ICE:0)
Block(-1,29,6,ICE:0)
Block(-1,30,-2,PACKED_ICE:0)
Block(-1,30,-1,ICE:0)
Block(-1,30,3,ICE:0)
Block(-1,31,-4,ICE:0)
Block(-1,31,-2,LOG_2:1)
Block(-1,31,-1,WOOD:5)
Block(-1,31,0,WOOD:5)
Block(-1,31,1,WOOD:5)
Block(-1,31,2,WOOD:5)
Block(-1,31,3,WOOD:5)
Block(-1,31,4,WOOD:5)
Block(-1,31,5,ICE:0)
Block(-1,32,-6,PACKED_ICE:0)
Block(-1,32,-4,ICE:0)
Block(-1,32,-3,WOOD:5)
Block(-1,32,-2,WOOD_DOUBLE_STEP:5)
Block(-1,32,-1,WOOD_DOUBLE_STEP:5)
Block(-1,32,0,WOOD_DOUBLE_STEP:5)
Block(-1,32,1,WOOD_DOUBLE_STEP:5)
Block(-1,32,2,WOOD_DOUBLE_STEP:5)
Block(-1,32,3,WOOD_DOUBLE_STEP:5)
Block(-1,32,4,WOOD_DOUBLE_STEP:5)
Block(-1,32,5,WOOD:5)
Block(-1,33,-6,PACKED_ICE:0)
Block(-1,33,-5,ICE:0)
Block(-1,33,-4,ICE:0)
Block(-1,33,-3,WOOD:5)
Block(-1,33,-2,BOOKSHELF:0)
Block(-1,33,-1,BOOKSHELF:0)
Block(-1,33,0,BOOKSHELF:0)
Block(-1,33,1,BOOKSHELF:0)
Block(-1,33,2,BOOKSHELF:0)
Block(-1,33,3,BOOKSHELF:0)
Block(-1,33,4,BOOKSHELF:0)
Block(-1,33,5,WOOD:5)
Block(-1,33,7,ICE:0)
Block(-1,34,-6,PACKED_ICE:0)
Block(-1,34,-5,ICE:0)
Block(-1,34,-4,DARK_OAK_STAIRS:6)
Block(-1,34,-3,BOOKSHELF:0)
Block(-1,34,5,BOOKSHELF:0)
Block(-1,34,6,DARK_OAK_STAIRS:7)
Block(-1,34,7,PACKED_ICE:0)
Block(-1,35,-6,PACKED_ICE:0)
Block(-1,35,-5,ICE:0)
Block(-1,35,-4,STAINED_GLASS:15)
Block(-1,35,5,FLOWER_POT:0)
Block(-1,35,6,STAINED_GLASS:15)
Block(-1,35,7,PACKED_ICE:0)
Block(-1,35,8,ICE:0)
Block(-1,36,-6,ICE:0)
Block(-1,36,-5,ICE:0)
Block(-1,36,-4,STAINED_GLASS:15)
Block(-1,36,6,STAINED_GLASS:15)
Block(-1,36,7,PACKED_ICE:0)
Block(-1,36,8,PACKED_ICE:0)
Block(-1,37,-4,DARK_OAK_STAIRS:2)
Block(-1,37,-3,WOOD_DOUBLE_STEP:5)
Block(-1,37,-2,STAINED_CLAY:9)
Block(-1,37,-1,STAINED_CLAY:9)
Block(-1,37,0,STAINED_CLAY:9)
Block(-1,37,1,STAINED_CLAY:9)
Block(-1,37,2,STAINED_CLAY:9)
Block(-1,37,3,STAINED_CLAY:9)
Block(-1,37,4,STAINED_CLAY:9)
Block(-1,37,5,WOOD_DOUBLE_STEP:5)
Block(-1,37,6,DARK_OAK_STAIRS:3)
Block(-1,37,7,ICE:0)
Block(-1,37,8,ICE:0)
Block(-1,38,-4,ICE:0)
Block(-1,38,-3,PACKED_ICE:0)
Block(-1,38,-2,STAINED_CLAY:9)
Block(-1,38,-1,ICE:0)
Block(-1,38,0,PACKED_ICE:0)
Block(-1,38,1,LOG:1)
Block(-1,38,2,WOOL:15)
Block(-1,38,3,PACKED_ICE:0)
Block(-1,38,4,STAINED_CLAY:9)
Block(-1,38,5,PACKED_ICE:0)
Block(-1,38,6,PACKED_ICE:0)
Block(-1,38,7,ICE:0)
Block(-1,39,-3,ICE:0)
Block(-1,39,-2,STAINED_CLAY:9)
Block(-1,39,-1,PACKED_ICE:0)
Block(-1,39,0,SNOW_BLOCK:0)
Block(-1,39,1,LOG:5)
Block(-1,39,2,PACKED_ICE:0)
Block(-1,39,3,ICE:0)
Block(-1,39,4,STAINED_CLAY:9)
Block(-1,39,5,ICE:0)
Block(-1,40,-2,WOOD_STEP:5)
Block(-1,40,-1,SNOW_BLOCK:0)
Block(-1,40,0,SNOW:2)
Block(-1,40,1,SNOW_BLOCK:0)
Block(-1,40,3,ICE:0)
Block(-1,40,4,WOOD_STEP:5)
Block(-1,41,-1,SNOW:0)
Block(-1,41,1,SNOW:0)
Block(0,18,-7,PACKED_ICE:0)
Block(0,18,-6,PACKED_ICE:0)
Block(0,18,-5,PACKED_ICE:0)
Block(0,18,-4,PACKED_ICE:0)
Block(0,18,-3,PACKED_ICE:0)
Block(0,18,-2,PACKED_ICE:0)
Block(0,18,-1,PACKED_ICE:0)
Block(0,18,0,PACKED_ICE:0)
Block(0,18,1,PACKED_ICE:0)
Block(0,18,2,PACKED_ICE:0)
Block(0,18,3,PACKED_ICE:0)
Block(0,18,4,PACKED_ICE:0)
Block(0,18,5,PACKED_ICE:0)
Block(0,18,6,PACKED_ICE:0)
Block(0,18,7,PACKED_ICE:0)
Block(0,18,8,PACKED_ICE:0)
Block(0,19,-7,PACKED_ICE:0)
Block(0,19,-6,PACKED_ICE:0)
Block(0,19,-5,PACKED_ICE:0)
Block(0,19,-4,PACKED_ICE:0)
Block(0,19,-3,PACKED_ICE:0)
Block(0,19,-2,PACKED_ICE:0)
Block(0,19,-1,PACKED_ICE:0)
Block(0,19,0,PACKED_ICE:0)
Block(0,19,1,PACKED_ICE:0)
Block(0,19,2,PACKED_ICE:0)
Block(0,19,3,PACKED_ICE:0)
Block(0,19,4,PACKED_ICE:0)
Block(0,19,5,PACKED_ICE:0)
Block(0,19,6,PACKED_ICE:0)
Block(0,19,7,PACKED_ICE:0)
Block(0,19,8,PACKED_ICE:0)
Block(0,20,-7,PACKED_ICE:0)
Block(0,20,-6,PACKED_ICE:0)
Block(0,20,-5,PACKED_ICE:0)
Block(0,20,-4,PACKED_ICE:0)
Block(0,20,-3,PACKED_ICE:0)
Block(0,20,-2,PACKED_ICE:0)
Block(0,20,-1,PACKED_ICE:0)
Block(0,20,0,PACKED_ICE:0)
Block(0,20,1,PACKED_ICE:0)
Block(0,20,2,PACKED_ICE:0)
Block(0,20,3,PACKED_ICE:0)
Block(0,20,4,PACKED_ICE:0)
Block(0,20,5,PACKED_ICE:0)
Block(0,20,6,PACKED_ICE:0)
Block(0,20,7,PACKED_ICE:0)
Block(0,20,8,PACKED_ICE:0)
Block(0,21,-7,PACKED_ICE:0)
Block(0,21,-6,PACKED_ICE:0)
Block(0,21,-5,PACKED_ICE:0)
Block(0,21,-4,PACKED_ICE:0)
Block(0,21,-3,PACKED_ICE:0)
Block(0,21,-2,PACKED_ICE:0)
Block(0,21,-1,PACKED_ICE:0)
Block(0,21,0,PACKED_ICE:0)
Block(0,21,1,PACKED_ICE:0)
Block(0,21,2,PACKED_ICE:0)
Block(0,21,3,PACKED_ICE:0)
Block(0,21,4,PACKED_ICE:0)
Block(0,21,5,PACKED_ICE:0)
Block(0,21,6,PACKED_ICE:0)
Block(0,21,7,PACKED_ICE:0)
Block(0,21,8,PACKED_ICE:0)
Block(0,22,-7,ICE:0)
Block(0,22,-6,ICE:0)
Block(0,22,-5,ICE:0)
Block(0,22,-4,ICE:0)
Block(0,22,-3,ICE:0)
Block(0,22,-2,PACKED_ICE:0)
Block(0,22,-1,PACKED_ICE:0)
Block(0,22,0,PACKED_ICE:0)
Block(0,22,1,WOOD:5)
Block(0,22,2,PACKED_ICE:0)
Block(0,22,3,PACKED_ICE:0)
Block(0,22,4,PACKED_ICE:0)
Block(0,22,5,ICE:0)
Block(0,22,6,ICE:0)
Block(0,22,7,ICE:0)
Block(0,22,8,PACKED_ICE:0)
Block(0,23,-7,ICE:0)
Block(0,23,-6,ICE:0)
Block(0,23,-5,ICE:0)
Block(0,23,-4,ICE:0)
Block(0,23,-3,ICE:0)
Block(0,23,-2,PACKED_ICE:0)
Block(0,23,-1,PACKED_ICE:0)
Block(0,23,0,PACKED_ICE:0)
Block(0,23,1,LOG_2:1)
Block(0,23,2,PACKED_ICE:0)
Block(0,23,3,PACKED_ICE:0)
Block(0,23,4,PACKED_ICE:0)
Block(0,23,5,ICE:0)
Block(0,23,6,ICE:0)
Block(0,23,7,ICE:0)
Block(0,23,8,PACKED_ICE:0)
Block(0,24,-7,ICE:0)
Block(0,24,-6,ICE:0)
Block(0,24,-5,ICE:0)
Block(0,24,-4,PACKED_ICE:0)
Block(0,24,-3,PACKED_ICE:0)
Block(0,24,-2,PACKED_ICE:0)
Block(0,24,0,ICE:0)
Block(0,24,1,LOG_2:1)
Block(0,24,2,PACKED_ICE:0)
Block(0,24,3,PACKED_ICE:0)
Block(0,24,4,ICE:0)
Block(0,24,5,PACKED_ICE:0)
Block(0,24,6,PACKED_ICE:0)
Block(0,24,7,ICE:0)
Block(0,24,8,ICE:0)
Block(0,25,-7,PACKED_ICE:0)
Block(0,25,-6,PACKED_ICE:0)
Block(0,25,-5,PACKED_ICE:0)
Block(0,25,-4,PACKED_ICE:0)
Block(0,25,-3,PACKED_ICE:0)
Block(0,25,-2,PACKED_ICE:0)
Block(0,25,-1,PACKED_ICE:0)
Block(0,25,0,PACKED_ICE:0)
Block(0,25,1,LOG_2:1)
Block(0,25,2,PACKED_ICE:0)
Block(0,25,3,ICE:0)
Block(0,25,4,ICE:0)
Block(0,25,5,ICE:0)
Block(0,25,6,PACKED_ICE:0)
Block(0,25,7,PACKED_ICE:0)
Block(0,25,8,PACKED_ICE:0)
Block(0,26,-7,PACKED_ICE:0)
Block(0,26,-6,ICE:0)
Block(0,26,-5,ICE:0)
Block(0,26,-3,ICE:0)
Block(0,26,-2,PACKED_ICE:0)
Block(0,26,-1,ICE:0)
Block(0,26,0,PACKED_ICE:0)
Block(0,26,1,LOG_2:1)
Block(0,26,2,ICE:0)
Block(0,26,3,PACKED_ICE:0)
Block(0,26,4,PACKED_ICE:0)
Block(0,26,5,PACKED_ICE:0)
Block(0,26,6,ICE:0)
Block(0,26,7,ICE:0)
Block(0,26,8,PACKED_ICE:0)
Block(0,27,-6,ICE:0)
Block(0,27,-2,ICE:0)
Block(0,27,0,PACKED_ICE:0)
Block(0,27,1,LOG_2:1)
Block(0,27,2,PACKED_ICE:0)
Block(0,27,3,PACKED_ICE:0)
Block(0,27,5,ICE:0)
Block(0,27,6,ICE:0)
Block(0,27,8,PACKED_ICE:0)
Block(0,28,-2,ICE:0)
Block(0,28,1,LOG_2:1)
Block(0,28,2,PACKED_ICE:0)
Block(0,28,3,ICE:0)
Block(0,28,4,PACKED_ICE:0)
Block(0,28,5,ICE:0)
Block(0,29,-3,PACKED_ICE:0)
Block(0,29,1,LOG_2:1)
Block(0,29,4,PACKED_ICE:0)
Block(0,29,6,PACKED_ICE:0)
Block(0,30,-3,PACKED_ICE:0)
Block(0,30,-2,ICE:0)
Block(0,30,0,ICE:0)
Block(0,30,1,WOOD:5)
Block(0,30,2,ICE:0)
Block(0,30,4,PACKED_ICE:0)
Block(0,30,6,PACKED_ICE:0)
Block(0,31,-3,PACKED_ICE:0)
Block(0,31,-2,ICE:0)
Block(0,31,-1,PACKED_ICE:0)
Block(0,31,0,ICE:0)
Block(0,31,1,ICE:0)
Block(0,31,2,ICE:0)
Block(0,31,3,ICE:0)
Block(0,31,4,PACKED_ICE:0)
Block(0,31,5,PACKED_ICE:0)
Block(0,31,6,PACKED_ICE:0)
Block(0,31,7,ICE:0)
Block(0,32,-3,PACKED_ICE:0)
Block(0,32,-2,STAINED_CLAY:9)
Block(0,32,-1,STAINED_CLAY:9)
Block(0,32,0,STAINED_CLAY:9)
Block(0,32,1,STAINED_CLAY:9)
Block(0,32,2,STAINED_CLAY:9)
Block(0,32,3,STAINED_CLAY:9)
Block(0,32,4,STAINED_CLAY:9)
Block(0,32,5,PACKED_ICE:0)
Block(0,32,6,PACKED_ICE:0)
Block(0,32,7,ICE:0)
Block(0,33,-3,WOOD:5)
Block(0,33,-2,WOOD:5)
Block(0,33,-1,WOOD_DOUBLE_STEP:5)
Block(0,33,0,WOOD_DOUBLE_STEP:5)
Block(0,33,1,WOOD_DOUBLE_STEP:5)
Block(0,33,2,WOOD_DOUBLE_STEP:5)
Block(0,33,3,WOOD_DOUBLE_STEP:5)
Block(0,33,4,WOOD:5)
Block(0,33,5,WOOD:5)
Block(0,33,6,PACKED_ICE:0)
Block(0,33,7,ICE:0)
Block(0,33,8,ICE:0)
Block(0,34,-5,PACKED_ICE:0)
Block(0,34,-4,WOOD_STEP:13)
Block(0,34,-3,WOOD_DOUBLE_STEP:5)
Block(0,34,5,WOOD_DOUBLE_STEP:5)
Block(0,34,6,WOOD_STEP:13)
Block(0,34,7,ICE:0)
Block(0,34,8,ICE:0)
Block(0,35,-6,PACKED_ICE:0)
Block(0,35,-5,PACKED_ICE:0)
Block(0,35,-4,STAINED_CLAY:9)
Block(0,35,-3,FLOWER_POT:0)
Block(0,35,6,STAINED_CLAY:9)
Block(0,35,7,ICE:0)
Block(0,35,8,ICE:0)
Block(0,36,-6,ICE:0)
Block(0,36,-5,PACKED_ICE:0)
Block(0,36,-4,STAINED_CLAY:9)
Block(0,36,6,STAINED_CLAY:9)
Block(0,36,7,ICE:0)
Block(0,36,8,PACKED_ICE:0)
Block(0,37,-5,ICE:0)
Block(0,37,-4,DARK_OAK_STAIRS:2)
Block(0,37,-3,DARK_OAK_STAIRS:1)
Block(0,37,-2,STAINED_CLAY:9)
Block(0,37,-1,STAINED_CLAY:9)
Block(0,37,0,STAINED_CLAY:9)
Block(0,37,1,STAINED_CLAY:9)
Block(0,37,2,STAINED_CLAY:9)
Block(0,37,3,STAINED_CLAY:9)
Block(0,37,4,STAINED_CLAY:9)
Block(0,37,5,DARK_OAK_STAIRS:3)
Block(0,37,6,DARK_OAK_STAIRS:1)
Block(0,37,7,ICE:0)
Block(0,38,-4,ICE:0)
Block(0,38,-3,ICE:0)
Block(0,38,-2,STAINED_CLAY:9)
Block(0,38,-1,PACKED_ICE:0)
Block(0,38,0,ICE:0)
Block(0,38,1,LOG:5)
Block(0,38,2,PACKED_ICE:0)
Block(0,38,3,PACKED_ICE:0)
Block(0,38,4,STAINED_CLAY:9)
Block(0,38,5,PACKED_ICE:0)
Block(0,38,6,ICE:0)
Block(0,39,-2,STAINED_CLAY:9)
Block(0,39,-1,PACKED_ICE:0)
Block(0,39,0,ICE:0)
Block(0,39,1,PACKED_ICE:0)
Block(0,39,2,ICE:0)
Block(0,39,3,ICE:0)
Block(0,39,4,STAINED_CLAY:9)
Block(0,39,5,PACKED_ICE:0)
Block(0,39,6,ICE:0)
Block(0,40,-2,DARK_OAK_STAIRS:0)
Block(0,40,-1,SNOW_BLOCK:0)
Block(0,40,0,SNOW_BLOCK:0)
Block(0,40,1,SNOW_BLOCK:0)
Block(0,40,2,ICE:0)
Block(0,40,3,ICE:0)
Block(0,40,4,DARK_OAK_STAIRS:0)
Block(0,40,5,ICE:0)
Block(0,41,-1,SNOW:5)
Block(0,41,0,SNOW_BLOCK:0)
Block(0,41,1,SNOW:5)
Block(0,41,2,SNOW_BLOCK:0)
Block(0,41,3,ICE:0)
Block(0,42,0,SNOW:0)
Block(0,42,2,SNOW:0)
Block(0,42,3,ICE:0)
Block(1,18,-7,PACKED_ICE:0)
Block(1,18,-6,PACKED_ICE:0)
Block(1,18,-5,PACKED_ICE:0)
Block(1,18,-4,PACKED_ICE:0)
Block(1,18,-3,PACKED_ICE:0)
Block(1,18,-2,PACKED_ICE:0)
Block(1,18,-1,PACKED_ICE:0)
Block(1,18,0,PACKED_ICE:0)
Block(1,18,1,PACKED_ICE:0)
Block(1,18,2,PACKED_ICE:0)
Block(1,18,3,PACKED_ICE:0)
Block(1,18,4,PACKED_ICE:0)
Block(1,18,5,PACKED_ICE:0)
Block(1,18,6,PACKED_ICE:0)
Block(1,18,7,PACKED_ICE:0)
Block(1,18,8,PACKED_ICE:0)
Block(1,19,-7,PACKED_ICE:0)
Block(1,19,-6,PACKED_ICE:0)
Block(1,19,-5,PACKED_ICE:0)
Block(1,19,-4,PACKED_ICE:0)
Block(1,19,-3,PACKED_ICE:0)
Block(1,19,-2,PACKED_ICE:0)
Block(1,19,-1,PACKED_ICE:0)
Block(1,19,0,PACKED_ICE:0)
Block(1,19,1,PACKED_ICE:0)
Block(1,19,2,PACKED_ICE:0)
Block(1,19,3,PACKED_ICE:0)
Block(1,19,4,PACKED_ICE:0)
Block(1,19,5,PACKED_ICE:0)
Block(1,19,6,PACKED_ICE:0)
Block(1,19,7,PACKED_ICE:0)
Block(1,19,8,PACKED_ICE:0)
Block(1,20,-7,PACKED_ICE:0)
Block(1,20,-6,PACKED_ICE:0)
Block(1,20,-5,PACKED_ICE:0)
Block(1,20,-4,PACKED_ICE:0)
Block(1,20,-3,PACKED_ICE:0)
Block(1,20,-2,PACKED_ICE:0)
Block(1,20,-1,PACKED_ICE:0)
Block(1,20,0,PACKED_ICE:0)
Block(1,20,1,PACKED_ICE:0)
Block(1,20,2,PACKED_ICE:0)
Block(1,20,3,PACKED_ICE:0)
Block(1,20,4,PACKED_ICE:0)
Block(1,20,5,PACKED_ICE:0)
Block(1,20,6,PACKED_ICE:0)
Block(1,20,7,PACKED_ICE:0)
Block(1,20,8,PACKED_ICE:0)
Block(1,21,-7,PACKED_ICE:0)
Block(1,21,-6,PACKED_ICE:0)
Block(1,21,-5,PACKED_ICE:0)
Block(1,21,-4,PACKED_ICE:0)
Block(1,21,-3,PACKED_ICE:0)
Block(1,21,-2,PACKED_ICE:0)
Block(1,21,-1,PACKED_ICE:0)
Block(1,21,0,PACKED_ICE:0)
Block(1,21,1,PACKED_ICE:0)
Block(1,21,2,PACKED_ICE:0)
Block(1,21,3,PACKED_ICE:0)
Block(1,21,4,PACKED_ICE:0)
Block(1,21,5,PACKED_ICE:0)
Block(1,21,6,PACKED_ICE:0)
Block(1,21,7,PACKED_ICE:0)
Block(1,21,8,PACKED_ICE:0)
Block(1,22,-7,PACKED_ICE:0)
Block(1,22,-6,ICE:0)
Block(1,22,-5,ICE:0)
Block(1,22,-4,ICE:0)
Block(1,22,-3,PACKED_ICE:0)
Block(1,22,-2,PACKED_ICE:0)
Block(1,22,-1,PACKED_ICE:0)
Block(1,22,0,PACKED_ICE:0)
Block(1,22,1,WOOD:5)
Block(1,22,2,PACKED_ICE:0)
Block(1,22,3,PACKED_ICE:0)
Block(1,22,4,PACKED_ICE:0)
Block(1,22,5,PACKED_ICE:0)
Block(1,22,6,ICE:0)
Block(1,22,7,ICE:0)
Block(1,22,8,PACKED_ICE:0)
Block(1,23,-7,ICE:0)
Block(1,23,-6,ICE:0)
Block(1,23,-5,ICE:0)
Block(1,23,-4,ICE:0)
Block(1,23,-3,PACKED_ICE:0)
Block(1,23,-2,PACKED_ICE:0)
Block(1,23,-1,PACKED_ICE:0)
Block(1,23,0,PACKED_ICE:0)
Block(1,23,1,LOG_2:1)
Block(1,23,2,PACKED_ICE:0)
Block(1,23,3,PACKED_ICE:0)
Block(1,23,4,PACKED_ICE:0)
Block(1,23,5,PACKED_ICE:0)
Block(1,23,6,PACKED_ICE:0)
Block(1,23,7,ICE:0)
Block(1,23,8,PACKED_ICE:0)
Block(1,24,-7,ICE:0)
Block(1,24,-6,ICE:0)
Block(1,24,-5,ICE:0)
Block(1,24,-4,ICE:0)
Block(1,24,-3,ICE:0)
Block(1,24,-2,ICE:0)
Block(1,24,-1,ICE:0)
Block(1,24,0,ICE:0)
Block(1,24,1,LOG_2:1)
Block(1,24,2,PACKED_ICE:0)
Block(1,24,3,PACKED_ICE:0)
Block(1,24,4,ICE:0)
Block(1,24,5,ICE:0)
Block(1,24,6,ICE:0)
Block(1,24,7,ICE:0)
Block(1,24,8,ICE:0)
Block(1,25,-7,PACKED_ICE:0)
Block(1,25,-6,PACKED_ICE:0)
Block(1,25,-5,PACKED_ICE:0)
Block(1,25,-4,PACKED_ICE:0)
Block(1,25,-3,PACKED_ICE:0)
Block(1,25,-2,PACKED_ICE:0)
Block(1,25,-1,PACKED_ICE:0)
Block(1,25,0,PACKED_ICE:0)
Block(1,25,1,LOG_2:1)
Block(1,25,2,PACKED_ICE:0)
Block(1,25,3,ICE:0)
Block(1,25,4,PACKED_ICE:0)
Block(1,25,5,ICE:0)
Block(1,25,6,ICE:0)
Block(1,25,7,ICE:0)
Block(1,25,8,PACKED_ICE:0)
Block(1,26,-6,PACKED_ICE:0)
Block(1,26,-5,PACKED_ICE:0)
Block(1,26,-4,PACKED_ICE:0)
Block(1,26,-3,PACKED_ICE:0)
Block(1,26,-2,PACKED_ICE:0)
Block(1,26,-1,ICE:0)
Block(1,26,0,PACKED_ICE:0)
Block(1,26,1,LOG_2:1)
Block(1,26,2,PACKED_ICE:0)
Block(1,26,3,PACKED_ICE:0)
Block(1,26,4,ICE:0)
Block(1,26,5,PACKED_ICE:0)
Block(1,26,7,ICE:0)
Block(1,26,8,ICE:0)
Block(1,27,-5,PACKED_ICE:0)
Block(1,27,-4,PACKED_ICE:0)
Block(1,27,-1,ICE:0)
Block(1,27,0,PACKED_ICE:0)
Block(1,27,1,LOG_2:1)
Block(1,27,2,PACKED_ICE:0)
Block(1,27,3,PACKED_ICE:0)
Block(1,27,4,ICE:0)
Block(1,27,7,ICE:0)
Block(1,28,-5,ICE:0)
Block(1,28,-4,ICE:0)
Block(1,28,0,PACKED_ICE:0)
Block(1,28,1,LOG_2:1)
Block(1,28,2,ICE:0)
Block(1,28,4,ICE:0)
Block(1,29,-5,PACKED_ICE:0)
Block(1,29,0,PACKED_ICE:0)
Block(1,29,1,LOG_2:1)
Block(1,30,-6,ICE:0)
Block(1,30,-5,PACKED_ICE:0)
Block(1,30,-1,PACKED_ICE:0)
Block(1,30,0,PACKED_ICE:0)
Block(1,30,1,LOG_2:1)
Block(1,30,3,ICE:0)
Block(1,31,-6,ICE:0)
Block(1,31,-1,PACKED_ICE:0)
Block(1,31,1,WOOD:5)
Block(1,31,3,ICE:0)
Block(1,31,6,ICE:0)
Block(1,32,-6,ICE:0)
Block(1,32,-4,PACKED_ICE:0)
Block(1,32,-2,ICE:0)
Block(1,32,-1,PACKED_ICE:0)
Block(1,32,3,ICE:0)
Block(1,32,4,PACKED_ICE:0)
Block(1,32,6,ICE:0)
Block(1,33,-6,ICE:0)
Block(1,33,-4,PACKED_ICE:0)
Block(1,33,-3,PACKED_ICE:0)
Block(1,33,-2,WOOD_STEP:13)
Block(1,33,-1,STAINED_CLAY:9)
Block(1,33,0,STAINED_CLAY:9)
Block(1,33,1,STAINED_CLAY:9)
Block(1,33,2,STAINED_CLAY:9)
Block(1,33,3,STAINED_CLAY:9)
Block(1,33,4,WOOD_STEP:13)
Block(1,33,5,PACKED_ICE:0)
Block(1,33,6,ICE:0)
Block(1,34,-6,ICE:0)
Block(1,34,-5,ICE:0)
Block(1,34,-4,PACKED_ICE:0)
Block(1,34,-3,DARK_OAK_STAIRS:5)
Block(1,34,0,DARK_OAK_STAIRS:7)
Block(1,34,1,WOOD_STEP:13)
Block(1,34,2,DARK_OAK_STAIRS:6)
Block(1,34,5,DARK_OAK_STAIRS:5)
Block(1,34,6,ICE:0)
Block(1,34,7,PACKED_ICE:0)
Block(1,35,-6,PACKED_ICE:0)
Block(1,35,-5,ICE:0)
Block(1,35,-4,PACKED_ICE:0)
Block(1,35,-3,STAINED_GLASS:15)
Block(1,35,2,FLOWER_POT:0)
Block(1,35,5,STAINED_GLASS:15)
Block(1,35,6,PACKED_ICE:0)
Block(1,35,7,PACKED_ICE:0)
Block(1,36,-5,ICE:0)
Block(1,36,-4,PACKED_ICE:0)
Block(1,36,-3,STAINED_GLASS:15)
Block(1,36,5,STAINED_GLASS:15)
Block(1,36,6,ICE:0)
Block(1,36,7,PACKED_ICE:0)
Block(1,37,-4,PACKED_ICE:0)
Block(1,37,-3,DARK_OAK_STAIRS:2)
Block(1,37,-2,STAINED_CLAY:9)
Block(1,37,-1,STAINED_CLAY:9)
Block(1,37,0,STAINED_CLAY:9)
Block(1,37,1,STAINED_CLAY:9)
Block(1,37,2,STAINED_CLAY:9)
Block(1,37,3,STAINED_CLAY:9)
Block(1,37,4,STAINED_CLAY:9)
Block(1,37,5,DARK_OAK_STAIRS:3)
Block(1,37,6,PACKED_ICE:0)
Block(1,38,-3,ICE:0)
Block(1,38,-2,STAINED_CLAY:9)
Block(1,38,-1,WOOD_STEP:5)
Block(1,38,0,PACKED_ICE:0)
Block(1,38,1,ICE:0)
Block(1,38,2,ICE:0)
Block(1,38,3,WOOD_STEP:5)
Block(1,38,4,STAINED_CLAY:9)
Block(1,38,5,PACKED_ICE:0)
Block(1,38,6,PACKED_ICE:0)
Block(1,39,-3,ICE:0)
Block(1,39,-2,STAINED_CLAY:9)
Block(1,39,-1,PACKED_ICE:0)
Block(1,39,0,PACKED_ICE:0)
Block(1,39,1,ICE:0)
Block(1,39,2,ICE:0)
Block(1,39,3,PACKED_ICE:0)
Block(1,39,4,STAINED_CLAY:9)
Block(1,39,5,ICE:0)
Block(1,40,-2,STAINED_CLAY:9)
Block(1,40,-1,PACKED_ICE:0)
Block(1,40,0,SNOW_BLOCK:0)
Block(1,40,1,ICE:0)
Block(1,40,2,SNOW_BLOCK:0)
Block(1,40,3,SNOW_BLOCK:0)
Block(1,40,4,STAINED_CLAY:9)
Block(1,40,5,ICE:0)
Block(1,41,-2,WOOD_STEP:5)
Block(1,41,-1,SNOW_BLOCK:0)
Block(1,41,0,SNOW_BLOCK:0)
Block(1,41,1,SNOW_BLOCK:0)
Block(1,41,2,SNOW_BLOCK:0)
Block(1,41,3,SNOW_BLOCK:0)
Block(1,41,4,WOOD_STEP:5)
Block(1,42,-1,SNOW:2)
Block(1,42,0,SNOW:5)
Block(1,42,1,SNOW:3)
Block(1,42,2,SNOW:0)
Block(1,42,3,SNOW:0)
Block(2,18,-6,PACKED_ICE:0)
Block(2,18,-5,PACKED_ICE:0)
Block(2,18,-4,PACKED_ICE:0)
Block(2,18,-3,PACKED_ICE:0)
Block(2,18,-2,PACKED_ICE:0)
Block(2,18,0,PACKED_ICE:0)
Block(2,18,1,PACKED_ICE:0)
Block(2,18,2,PACKED_ICE:0)
Block(2,18,3,PACKED_ICE:0)
Block(2,18,4,PACKED_ICE:0)
Block(2,18,5,PACKED_ICE:0)
Block(2,18,6,PACKED_ICE:0)
Block(2,18,7,PACKED_ICE:0)
Block(2,18,8,PACKED_ICE:0)
Block(2,19,-7,PACKED_ICE:0)
Block(2,19,-6,PACKED_ICE:0)
Block(2,19,-5,PACKED_ICE:0)
Block(2,19,-4,PACKED_ICE:0)
Block(2,19,-3,PACKED_ICE:0)
Block(2,19,-2,PACKED_ICE:0)
Block(2,19,-1,PACKED_ICE:0)
Block(2,19,0,PACKED_ICE:0)
Block(2,19,1,PACKED_ICE:0)
Block(2,19,2,PACKED_ICE:0)
Block(2,19,3,PACKED_ICE:0)
Block(2,19,4,PACKED_ICE:0)
Block(2,19,5,PACKED_ICE:0)
Block(2,19,6,PACKED_ICE:0)
Block(2,19,7,PACKED_ICE:0)
Block(2,19,8,PACKED_ICE:0)
Block(2,20,-7,PACKED_ICE:0)
Block(2,20,-6,PACKED_ICE:0)
Block(2,20,-5,PACKED_ICE:0)
Block(2,20,-4,PACKED_ICE:0)
Block(2,20,-3,PACKED_ICE:0)
Block(2,20,-2,PACKED_ICE:0)
Block(2,20,-1,PACKED_ICE:0)
Block(2,20,0,PACKED_ICE:0)
Block(2,20,1,PACKED_ICE:0)
Block(2,20,2,PACKED_ICE:0)
Block(2,20,3,PACKED_ICE:0)
Block(2,20,4,PACKED_ICE:0)
Block(2,20,5,PACKED_ICE:0)
Block(2,20,6,PACKED_ICE:0)
Block(2,20,7,PACKED_ICE:0)
Block(2,20,8,PACKED_ICE:0)
Block(2,21,-7,PACKED_ICE:0)
Block(2,21,-6,PACKED_ICE:0)
Block(2,21,-5,PACKED_ICE:0)
Block(2,21,-4,PACKED_ICE:0)
Block(2,21,-3,PACKED_ICE:0)
Block(2,21,-2,PACKED_ICE:0)
Block(2,21,-1,PACKED_ICE:0)
Block(2,21,0,PACKED_ICE:0)
Block(2,21,1,PACKED_ICE:0)
Block(2,21,2,PACKED_ICE:0)
Block(2,21,3,PACKED_ICE:0)
Block(2,21,4,PACKED_ICE:0)
Block(2,21,5,PACKED_ICE:0)
Block(2,21,6,PACKED_ICE:0)
Block(2,21,7,PACKED_ICE:0)
Block(2,21,8,PACKED_ICE:0)
Block(2,22,-7,PACKED_ICE:0)
Block(2,22,-6,ICE:0)
Block(2,22,-5,ICE:0)
Block(2,22,-4,ICE:0)
Block(2,22,-3,PACKED_ICE:0)
Block(2,22,-2,PACKED_ICE:0)
Block(2,22,-1,PACKED_ICE:0)
Block(2,22,0,PACKED_ICE:0)
Block(2,22,1,WOOD:5)
Block(2,22,2,PACKED_ICE:0)
Block(2,22,3,PACKED_ICE:0)
Block(2,22,4,PACKED_ICE:0)
Block(2,22,5,PACKED_ICE:0)
Block(2,22,6,ICE:0)
Block(2,22,7,PACKED_ICE:0)
Block(2,22,8,PACKED_ICE:0)
Block(2,23,-7,ICE:0)
Block(2,23,-6,ICE:0)
Block(2,23,-5,ICE:0)
Block(2,23,-4,ICE:0)
Block(2,23,-3,PACKED_ICE:0)
Block(2,23,-2,PACKED_ICE:0)
Block(2,23,-1,PACKED_ICE:0)
Block(2,23,0,PACKED_ICE:0)
Block(2,23,1,WOOD:5)
Block(2,23,2,PACKED_ICE:0)
Block(2,23,3,PACKED_ICE:0)
Block(2,23,4,PACKED_ICE:0)
Block(2,23,5,ICE:0)
Block(2,23,6,PACKED_ICE:0)
Block(2,23,7,PACKED_ICE:0)
Block(2,23,8,PACKED_ICE:0)
Block(2,24,-7,ICE:0)
Block(2,24,-6,ICE:0)
Block(2,24,-5,ICE:0)
Block(2,24,-4,ICE:0)
Block(2,24,-3,PACKED_ICE:0)
Block(2,24,-2,PACKED_ICE:0)
Block(2,24,-1,PACKED_ICE:0)
Block(2,24,0,ICE:0)
Block(2,24,1,WOOD:5)
Block(2,24,2,PACKED_ICE:0)
Block(2,24,3,PACKED_ICE:0)
Block(2,24,4,PACKED_ICE:0)
Block(2,24,5,ICE:0)
Block(2,24,6,ICE:0)
Block(2,24,7,ICE:0)
Block(2,24,8,PACKED_ICE:0)
Block(2,25,-7,PACKED_ICE:0)
Block(2,25,-6,PACKED_ICE:0)
Block(2,25,-5,PACKED_ICE:0)
Block(2,25,-4,PACKED_ICE:0)
Block(2,25,-3,PACKED_ICE:0)
Block(2,25,-2,PACKED_ICE:0)
Block(2,25,-1,PACKED_ICE:0)
Block(2,25,0,PACKED_ICE:0)
Block(2,25,1,LOG_2:1)
Block(2,25,2,PACKED_ICE:0)
Block(2,25,3,ICE:0)
Block(2,25,4,ICE:0)
Block(2,25,5,PACKED_ICE:0)
Block(2,25,6,PACKED_ICE:0)
Block(2,25,7,ICE:0)
Block(2,25,8,ICE:0)
Block(2,26,-6,ICE:0)
Block(2,26,-5,PACKED_ICE:0)
Block(2,26,-4,ICE:0)
Block(2,26,-3,ICE:0)
Block(2,26,-2,ICE:0)
Block(2,26,-1,ICE:0)
Block(2,26,0,PACKED_ICE:0)
Block(2,26,1,LOG_2:1)
Block(2,26,2,PACKED_ICE:0)
Block(2,26,3,PACKED_ICE:0)
Block(2,26,4,PACKED_ICE:0)
Block(2,26,5,ICE:0)
Block(2,26,6,ICE:0)
Block(2,26,7,PACKED_ICE:0)
Block(2,26,8,PACKED_ICE:0)
Block(2,27,-5,PACKED_ICE:0)
Block(2,27,0,PACKED_ICE:0)
Block(2,27,1,LOG_2:1)
Block(2,27,2,PACKED_ICE:0)
Block(2,27,3,ICE:0)
Block(2,27,4,PACKED_ICE:0)
Block(2,27,6,ICE:0)
Block(2,27,7,PACKED_ICE:0)
Block(2,27,8,PACKED_ICE:0)
Block(2,28,0,PACKED_ICE:0)
Block(2,28,1,WOOD:5)
Block(2,28,2,PACKED_ICE:0)
Block(2,28,3,ICE:0)
Block(2,28,7,PACKED_ICE:0)
Block(2,29,-3,PACKED_ICE:0)
Block(2,29,-1,ICE:0)
Block(2,29,1,WOOD:5)
Block(2,29,2,PACKED_ICE:0)
Block(2,29,7,ICE:0)
Block(2,30,-3,PACKED_ICE:0)
Block(2,30,-1,ICE:0)
Block(2,30,1,WOOD:5)
Block(2,30,2,PACKED_ICE:0)
Block(2,31,-3,PACKED_ICE:0)
Block(2,31,-2,PACKED_ICE:0)
Block(2,31,-1,ICE:0)
Block(2,31,1,WOOD:5)
Block(2,31,4,ICE:0)
Block(2,32,-3,PACKED_ICE:0)
Block(2,32,-2,ICE:0)
Block(2,32,-1,ICE:0)
Block(2,32,0,PACKED_ICE:0)
Block(2,32,1,ICE:0)
Block(2,32,2,ICE:0)
Block(2,32,4,ICE:0)
Block(2,32,7,ICE:0)
Block(2,33,-5,PACKED_ICE:0)
Block(2,33,-3,PACKED_ICE:0)
Block(2,33,-2,WOOD_STEP:13)
Block(2,33,-1,WOOD_STEP:13)
Block(2,33,0,DARK_OAK_STAIRS:5)
Block(2,33,1,WOOD_STEP:13)
Block(2,33,2,DARK_OAK_STAIRS:5)
Block(2,33,3,WOOD_STEP:13)
Block(2,33,4,WOOD_STEP:13)
Block(2,33,6,ICE:0)
Block(2,33,7,ICE:0)
Block(2,34,-5,PACKED_ICE:0)
Block(2,34,-3,DARK_OAK_STAIRS:6)
Block(2,34,5,DARK_OAK_STAIRS:7)
Block(2,34,6,ICE:0)
Block(2,34,7,PACKED_ICE:0)
Block(2,35,-5,PACKED_ICE:0)
Block(2,35,-4,ICE:0)
Block(2,35,-3,STAINED_GLASS:15)
Block(2,35,5,STAINED_GLASS:15)
Block(2,35,6,PACKED_ICE:0)
Block(2,35,7,ICE:0)
Block(2,36,-4,ICE:0)
Block(2,36,-3,STAINED_GLASS:15)
Block(2,36,5,STAINED_GLASS:15)
Block(2,36,6,ICE:0)
Block(2,37,-4,PACKED_ICE:0)
Block(2,37,-3,DARK_OAK_STAIRS:2)
Block(2,37,-2,STAINED_CLAY:9)
Block(2,37,-1,STAINED_CLAY:9)
Block(2,37,0,STAINED_CLAY:9)
Block(2,37,1,STAINED_CLAY:9)
Block(2,37,2,STAINED_CLAY:9)
Block(2,37,3,STAINED_CLAY:9)
Block(2,37,4,STAINED_CLAY:9)
Block(2,37,5,DARK_OAK_STAIRS:3)
Block(2,37,6,ICE:0)
Block(2,38,-4,ICE:0)
Block(2,38,-3,PACKED_ICE:0)
Block(2,38,-2,STAINED_CLAY:9)
Block(2,38,-1,STAINED_CLAY:9)
Block(2,38,0,WOOD_DOUBLE_STEP:5)
Block(2,38,1,PACKED_ICE:0)
Block(2,38,2,WOOD_DOUBLE_STEP:5)
Block(2,38,3,STAINED_CLAY:9)
Block(2,38,4,STAINED_CLAY:9)
Block(2,38,5,ICE:0)
Block(2,39,-3,ICE:0)
Block(2,39,-2,STAINED_CLAY:9)
Block(2,39,-1,STAINED_CLAY:9)
Block(2,39,0,DARK_OAK_STAIRS:0)
Block(2,39,1,PACKED_ICE:0)
Block(2,39,2,DARK_OAK_STAIRS:0)
Block(2,39,3,STAINED_CLAY:9)
Block(2,39,4,STAINED_CLAY:9)
Block(2,39,5,ICE:0)
Block(2,40,-3,ICE:0)
Block(2,40,-2,STAINED_CLAY:9)
Block(2,40,-1,STAINED_CLAY:9)
Block(2,40,0,SNOW_BLOCK:0)
Block(2,40,1,PACKED_ICE:0)
Block(2,40,2,PACKED_ICE:0)
Block(2,40,3,STAINED_CLAY:9)
Block(2,40,4,STAINED_CLAY:9)
Block(2,41,-2,WOOD_STEP:5)
Block(2,41,-1,WOOD_STEP:5)
Block(2,41,0,SNOW_BLOCK:0)
Block(2,41,1,PACKED_ICE:0)
Block(2,41,2,LEVER:2)
Block(2,41,3,WOOD_STEP:5)
Block(2,41,4,WOOD_STEP:5)
Block(2,42,0,SNOW:2)
Block(3,18,-5,PACKED_ICE:0)
Block(3,18,-4,PACKED_ICE:0)
Block(3,18,1,PACKED_ICE:0)
Block(3,19,-6,PACKED_ICE:0)
Block(3,19,-5,PACKED_ICE:0)
Block(3,19,-4,PACKED_ICE:0)
Block(3,19,-3,PACKED_ICE:0)
Block(3,19,-2,PACKED_ICE:0)
Block(3,19,0,PACKED_ICE:0)
Block(3,19,1,PACKED_ICE:0)
Block(3,19,3,PACKED_ICE:0)
Block(3,19,6,PACKED_ICE:0)
Block(3,19,7,PACKED_ICE:0)
Block(3,19,8,PACKED_ICE:0)
Block(3,20,-7,PACKED_ICE:0)
Block(3,20,-6,PACKED_ICE:0)
Block(3,20,-5,PACKED_ICE:0)
Block(3,20,-4,PACKED_ICE:0)
Block(3,20,-3,PACKED_ICE:0)
Block(3,20,-2,PACKED_ICE:0)
Block(3,20,-1,PACKED_ICE:0)
Block(3,20,0,PACKED_ICE:0)
Block(3,20,1,PACKED_ICE:0)
Block(3,20,2,PACKED_ICE:0)
Block(3,20,3,PACKED_ICE:0)
Block(3,20,4,PACKED_ICE:0)
Block(3,20,5,PACKED_ICE:0)
Block(3,20,6,PACKED_ICE:0)
Block(3,20,7,PACKED_ICE:0)
Block(3,20,8,PACKED_ICE:0)
Block(3,21,-7,PACKED_ICE:0)
Block(3,21,-6,PACKED_ICE:0)
Block(3,21,-5,PACKED_ICE:0)
Block(3,21,-4,PACKED_ICE:0)
Block(3,21,-3,PACKED_ICE:0)
Block(3,21,-2,PACKED_ICE:0)
Block(3,21,-1,ICE:0)
Block(3,21,0,PACKED_ICE:0)
Block(3,21,1,PACKED_ICE:0)
Block(3,21,2,PACKED_ICE:0)
Block(3,21,3,PACKED_ICE:0)
Block(3,21,4,PACKED_ICE:0)
Block(3,21,5,PACKED_ICE:0)
Block(3,21,6,PACKED_ICE:0)
Block(3,21,7,PACKED_ICE:0)
Block(3,21,8,PACKED_ICE:0)
Block(3,22,-7,ICE:0)
Block(3,22,-6,ICE:0)
Block(3,22,-5,ICE:0)
Block(3,22,-4,ICE:0)
Block(3,22,-3,ICE:0)
Block(3,22,-2,ICE:0)
Block(3,22,-1,ICE:0)
Block(3,22,0,ICE:0)
Block(3,22,1,ICE:0)
Block(3,22,2,PACKED_ICE:0)
Block(3,22,3,PACKED_ICE:0)
Block(3,22,4,ICE:0)
Block(3,22,5,PACKED_ICE:0)
Block(3,22,6,ICE:0)
Block(3,22,7,PACKED_ICE:0)
Block(3,22,8,PACKED_ICE:0)
Block(3,23,-7,ICE:0)
Block(3,23,-6,ICE:0)
Block(3,23,-5,ICE:0)
Block(3,23,-4,ICE:0)
Block(3,23,-3,ICE:0)
Block(3,23,-2,ICE:0)
Block(3,23,-1,ICE:0)
Block(3,23,0,ICE:0)
Block(3,23,1,ICE:0)
Block(3,23,2,PACKED_ICE:0)
Block(3,23,3,PACKED_ICE:0)
Block(3,23,4,ICE:0)
Block(3,23,5,PACKED_ICE:0)
Block(3,23,6,PACKED_ICE:0)
Block(3,23,7,ICE:0)
Block(3,23,8,ICE:0)
Block(3,24,-7,PACKED_ICE:0)
Block(3,24,-6,ICE:0)
Block(3,24,-5,ICE:0)
Block(3,24,-4,ICE:0)
Block(3,24,-3,ICE:0)
Block(3,24,-2,ICE:0)
Block(3,24,-1,ICE:0)
Block(3,24,0,ICE:0)
Block(3,24,1,WOOD:5)
Block(3,24,2,PACKED_ICE:0)
Block(3,24,3,PACKED_ICE:0)
Block(3,24,4,PACKED_ICE:0)
Block(3,24,5,ICE:0)
Block(3,24,6,ICE:0)
Block(3,24,7,ICE:0)
Block(3,24,8,PACKED_ICE:0)
Block(3,25,-6,PACKED_ICE:0)
Block(3,25,-5,PACKED_ICE:0)
Block(3,25,-4,PACKED_ICE:0)
Block(3,25,-3,PACKED_ICE:0)
Block(3,25,-2,PACKED_ICE:0)
Block(3,25,-1,PACKED_ICE:0)
Block(3,25,0,PACKED_ICE:0)
Block(3,25,1,WOOD:5)
Block(3,25,2,PACKED_ICE:0)
Block(3,25,3,PACKED_ICE:0)
Block(3,25,4,ICE:0)
Block(3,25,5,ICE:0)
Block(3,25,6,ICE:0)
Block(3,25,7,PACKED_ICE:0)
Block(3,25,8,ICE:0)
Block(3,26,-3,ICE:0)
Block(3,26,-2,ICE:0)
Block(3,26,-1,ICE:0)
Block(3,26,0,PACKED_ICE:0)
Block(3,26,1,WOOD:5)
Block(3,26,2,ICE:0)
Block(3,26,3,ICE:0)
Block(3,26,4,PACKED_ICE:0)
Block(3,26,6,PACKED_ICE:0)
Block(3,26,7,ICE:0)
Block(3,26,8,PACKED_ICE:0)
Block(3,27,0,ICE:0)
Block(3,27,1,WOOD:5)
Block(3,27,2,ICE:0)
Block(3,27,6,PACKED_ICE:0)
Block(3,27,7,ICE:0)
Block(3,27,8,ICE:0)
Block(3,28,1,WOOD:5)
Block(3,28,5,ICE:0)
Block(3,28,7,ICE:0)
Block(3,29,-5,ICE:0)
Block(3,29,1,ICE:0)
Block(3,29,3,ICE:0)
Block(3,29,5,ICE:0)
Block(3,30,-5,ICE:0)
Block(3,30,0,ICE:0)
Block(3,30,1,ICE:0)
Block(3,30,3,ICE:0)
Block(3,30,5,ICE:0)
Block(3,31,-5,ICE:0)
Block(3,31,0,ICE:0)
Block(3,31,1,PACKED_ICE:0)
Block(3,31,2,ICE:0)
Block(3,31,3,ICE:0)
Block(3,31,5,ICE:0)
Block(3,31,6,PACKED_ICE:0)
Block(3,32,-5,ICE:0)
Block(3,32,-4,ICE:0)
Block(3,32,-2,PACKED_ICE:0)
Block(3,32,0,ICE:0)
Block(3,32,1,PACKED_ICE:0)
Block(3,32,2,ICE:0)
Block(3,32,3,ICE:0)
Block(3,32,5,PACKED_ICE:0)
Block(3,32,6,PACKED_ICE:0)
Block(3,33,-5,ICE:0)
Block(3,33,-4,ICE:0)
Block(3,33,-3,PACKED_ICE:0)
Block(3,33,-2,PACKED_ICE:0)
Block(3,33,-1,PACKED_ICE:0)
Block(3,33,0,WOOD_STEP:13)
Block(3,33,1,WOOD_STEP:13)
Block(3,33,2,WOOD_STEP:13)
Block(3,33,3,ICE:0)
Block(3,33,4,PACKED_ICE:0)
Block(3,33,5,PACKED_ICE:0)
Block(3,33,6,PACKED_ICE:0)
Block(3,34,-5,ICE:0)
Block(3,34,-4,ICE:0)
Block(3,34,-3,DARK_OAK_STAIRS:6)
Block(3,34,-2,DARK_OAK_STAIRS:5)
Block(3,34,-1,DARK_OAK_STAIRS:6)
Block(3,34,0,WOOD_DOUBLE_STEP:5)
Block(3,34,1,WOOD_DOUBLE_STEP:5)
Block(3,34,2,WOOD_DOUBLE_STEP:5)
Block(3,34,3,DARK_OAK_STAIRS:7)
Block(3,34,4,DARK_OAK_STAIRS:5)
Block(3,34,5,DARK_OAK_STAIRS:7)
Block(3,34,6,PACKED_ICE:0)
Block(3,35,-4,ICE:0)
Block(3,35,-3,STAINED_CLAY:9)
Block(3,35,-2,STAINED_GLASS:15)
Block(3,35,-1,FLOWER_POT:0)
Block(3,35,0,DARK_OAK_STAIRS:2)
Block(3,35,1,WOOD_DOUBLE_STEP:5)
Block(3,35,2,DARK_OAK_STAIRS:3)
Block(3,35,3,FLOWER_POT:0)
Block(3,35,4,STAINED_GLASS:15)
Block(3,35,5,STAINED_CLAY:9)
Block(3,35,6,PACKED_ICE:0)
Block(3,35,7,ICE:0)
Block(3,36,-4,ICE:0)
Block(3,36,-3,STAINED_CLAY:9)
Block(3,36,-2,STAINED_GLASS:15)
Block(3,36,1,SKULL:1)
Block(3,36,4,STAINED_GLASS:15)
Block(3,36,5,STAINED_CLAY:9)
Block(3,36,6,PACKED_ICE:0)
Block(3,36,7,ICE:0)
Block(3,37,-4,PACKED_ICE:0)
Block(3,37,-3,DARK_OAK_STAIRS:2)
Block(3,37,-2,DARK_OAK_STAIRS:1)
Block(3,37,-1,DARK_OAK_STAIRS:1)
Block(3,37,0,STAINED_CLAY:9)
Block(3,37,1,STAINED_CLAY:9)
Block(3,37,2,STAINED_CLAY:9)
Block(3,37,3,DARK_OAK_STAIRS:3)
Block(3,37,4,DARK_OAK_STAIRS:1)
Block(3,37,5,DARK_OAK_STAIRS:1)
Block(3,37,6,ICE:0)
Block(3,38,-3,ICE:0)
Block(3,38,-2,PACKED_ICE:0)
Block(3,38,-1,ICE:0)
Block(3,38,0,STAINED_CLAY:9)
Block(3,38,1,STAINED_CLAY:9)
Block(3,38,2,STAINED_CLAY:9)
Block(3,38,3,ICE:0)
Block(3,38,4,PACKED_ICE:0)
Block(3,38,5,ICE:0)
Block(3,39,-3,ICE:0)
Block(3,39,-2,PACKED_ICE:0)
Block(3,39,-1,ICE:0)
Block(3,39,0,STAINED_CLAY:9)
Block(3,39,1,STAINED_CLAY:9)
Block(3,39,2,STAINED_CLAY:9)
Block(3,39,3,ICE:0)
Block(3,40,-2,PACKED_ICE:0)
Block(3,40,-1,COBBLE_WALL:0)
Block(3,40,0,STAINED_CLAY:9)
Block(3,40,1,STAINED_CLAY:9)
Block(3,40,2,STAINED_CLAY:9)
Block(3,40,3,COBBLE_WALL:0)
Block(3,41,-1,REDSTONE_LAMP_OFF:0)
Block(3,41,0,WOOD_DOUBLE_STEP:5)
Block(3,41,1,WOOD_DOUBLE_STEP:5)
Block(3,41,2,WOOD_DOUBLE_STEP:5)
Block(3,41,3,REDSTONE_LAMP_OFF:0)
Block(3,42,-1,WOOD_STEP:5)
Block(3,42,0,SNOW:0)
Block(3,42,1,SNOW:4)
Block(3,42,2,SNOW:1)
Block(3,42,3,WOOD_STEP:5)
Block(4,19,-4,PACKED_ICE:0)
Block(4,19,7,PACKED_ICE:0)
Block(4,20,-6,PACKED_ICE:0)
Block(4,20,-5,PACKED_ICE:0)
Block(4,20,-4,PACKED_ICE:0)
Block(4,20,-3,PACKED_ICE:0)
Block(4,20,0,PACKED_ICE:0)
Block(4,20,1,PACKED_ICE:0)
Block(4,20,5,PACKED_ICE:0)
Block(4,20,6,PACKED_ICE:0)
Block(4,20,7,PACKED_ICE:0)
Block(4,20,8,PACKED_ICE:0)
Block(4,21,-7,PACKED_ICE:0)
Block(4,21,-6,PACKED_ICE:0)
Block(4,21,-5,PACKED_ICE:0)
Block(4,21,-4,PACKED_ICE:0)
Block(4,21,-3,ICE:0)
Block(4,21,-2,ICE:0)
Block(4,21,0,PACKED_ICE:0)
Block(4,21,1,ICE:0)
Block(4,21,2,PACKED_ICE:0)
Block(4,21,4,PACKED_ICE:0)
Block(4,21,5,ICE:0)
Block(4,21,6,PACKED_ICE:0)
Block(4,21,7,PACKED_ICE:0)
Block(4,21,8,PACKED_ICE:0)
Block(4,22,-6,PACKED_ICE:0)
Block(4,22,-5,ICE:0)
Block(4,22,-4,ICE:0)
Block(4,22,-3,PACKED_ICE:0)
Block(4,22,-2,PACKED_ICE:0)
Block(4,22,-1,ICE:0)
Block(4,22,0,ICE:0)
Block(4,22,1,PACKED_ICE:0)
Block(4,22,2,PACKED_ICE:0)
Block(4,22,3,ICE:0)
Block(4,22,4,ICE:0)
Block(4,22,5,ICE:0)
Block(4,22,6,ICE:0)
Block(4,22,7,ICE:0)
Block(4,22,8,ICE:0)
Block(4,23,-7,ICE:0)
Block(4,23,-6,PACKED_ICE:0)
Block(4,23,-5,ICE:0)
Block(4,23,-4,ICE:0)
Block(4,23,-3,ICE:0)
Block(4,23,-2,ICE:0)
Block(4,23,-1,ICE:0)
Block(4,23,0,ICE:0)
Block(4,23,1,ICE:0)
Block(4,23,2,PACKED_ICE:0)
Block(4,23,3,ICE:0)
Block(4,23,4,ICE:0)
Block(4,23,5,ICE:0)
Block(4,23,6,PACKED_ICE:0)
Block(4,23,7,PACKED_ICE:0)
Block(4,23,8,PACKED_ICE:0)
Block(4,24,-6,ICE:0)
Block(4,24,-5,ICE:0)
Block(4,24,-4,ICE:0)
Block(4,24,-3,ICE:0)
Block(4,24,-2,ICE:0)
Block(4,24,-1,ICE:0)
Block(4,24,0,ICE:0)
Block(4,24,1,PACKED_ICE:0)
Block(4,24,2,PACKED_ICE:0)
Block(4,24,3,PACKED_ICE:0)
Block(4,24,4,ICE:0)
Block(4,24,5,ICE:0)
Block(4,24,6,PACKED_ICE:0)
Block(4,24,7,ICE:0)
Block(4,24,8,ICE:0)
Block(4,25,-5,PACKED_ICE:0)
Block(4,25,-4,PACKED_ICE:0)
Block(4,25,-3,PACKED_ICE:0)
Block(4,25,-2,PACKED_ICE:0)
Block(4,25,-1,PACKED_ICE:0)
Block(4,25,0,PACKED_ICE:0)
Block(4,25,1,PACKED_ICE:0)
Block(4,25,2,PACKED_ICE:0)
Block(4,25,3,PACKED_ICE:0)
Block(4,25,4,PACKED_ICE:0)
Block(4,25,5,PACKED_ICE:0)
Block(4,25,6,ICE:0)
Block(4,25,7,ICE:0)
Block(4,25,8,ICE:0)
Block(4,26,-5,ICE:0)
Block(4,26,-4,PACKED_ICE:0)
Block(4,26,-3,PACKED_ICE:0)
Block(4,26,-2,ICE:0)
Block(4,26,-1,PACKED_ICE:0)
Block(4,26,0,ICE:0)
Block(4,26,1,PACKED_ICE:0)
Block(4,26,2,ICE:0)
Block(4,26,3,PACKED_ICE:0)
Block(4,26,4,PACKED_ICE:0)
Block(4,26,5,PACKED_ICE:0)
Block(4,26,6,ICE:0)
Block(4,26,7,ICE:0)
Block(4,26,8,ICE:0)
Block(4,27,-4,PACKED_ICE:0)
Block(4,27,-3,PACKED_ICE:0)
Block(4,27,1,PACKED_ICE:0)
Block(4,27,4,PACKED_ICE:0)
Block(4,27,5,PACKED_ICE:0)
Block(4,27,7,ICE:0)
Block(4,28,-4,PACKED_ICE:0)
Block(4,28,-2,ICE:0)
Block(4,28,4,PACKED_ICE:0)
Block(4,29,-2,ICE:0)
Block(4,30,-2,ICE:0)
Block(4,30,2,ICE:0)
Block(4,30,4,PACKED_ICE:0)
Block(4,31,-2,ICE:0)
Block(4,31,2,ICE:0)
Block(4,31,4,PACKED_ICE:0)
Block(4,32,-3,ICE:0)
Block(4,32,-2,ICE:0)
Block(4,32,-1,ICE:0)
Block(4,32,1,ICE:0)
Block(4,32,2,ICE:0)
Block(4,32,4,PACKED_ICE:0)
Block(4,33,-3,ICE:0)
Block(4,33,-2,PACKED_ICE:0)
Block(4,33,-1,ICE:0)
Block(4,33,1,ICE:0)
Block(4,33,2,ICE:0)
Block(4,33,3,PACKED_ICE:0)
Block(4,33,4,PACKED_ICE:0)
Block(4,33,5,ICE:0)
Block(4,34,-4,PACKED_ICE:0)
Block(4,34,-3,ICE:0)
Block(4,34,-2,PACKED_ICE:0)
Block(4,34,-1,WOOD_STEP:13)
Block(4,34,0,DARK_OAK_STAIRS:5)
Block(4,34,1,WOOD_STEP:13)
Block(4,34,2,DARK_OAK_STAIRS:5)
Block(4,34,3,WOOD_STEP:13)
Block(4,34,4,PACKED_ICE:0)
Block(4,34,5,ICE:0)
Block(4,34,6,PACKED_ICE:0)
Block(4,35,-4,PACKED_ICE:0)
Block(4,35,-3,ICE:0)
Block(4,35,-2,PACKED_ICE:0)
Block(4,35,-1,STAINED_GLASS:15)
Block(4,35,0,STAINED_GLASS:15)
Block(4,35,1,STAINED_CLAY:9)
Block(4,35,2,STAINED_GLASS:15)
Block(4,35,3,STAINED_GLASS:15)
Block(4,35,4,PACKED_ICE:0)
Block(4,35,5,ICE:0)
Block(4,35,6,PACKED_ICE:0)
Block(4,36,-3,PACKED_ICE:0)
Block(4,36,-2,PACKED_ICE:0)
Block(4,36,-1,STAINED_GLASS:15)
Block(4,36,0,STAINED_GLASS:15)
Block(4,36,1,STAINED_CLAY:9)
Block(4,36,2,STAINED_GLASS:15)
Block(4,36,3,STAINED_GLASS:15)
Block(4,36,4,PACKED_ICE:0)
Block(4,36,5,ICE:0)
Block(4,36,6,PACKED_ICE:0)
Block(4,37,-3,ICE:0)
Block(4,37,-2,PACKED_ICE:0)
Block(4,37,-1,DARK_OAK_STAIRS:2)
Block(4,37,0,DARK_OAK_STAIRS:1)
Block(4,37,1,DARK_OAK_STAIRS:1)
Block(4,37,2,DARK_OAK_STAIRS:1)
Block(4,37,3,DARK_OAK_STAIRS:1)
Block(4,37,4,PACKED_ICE:0)
Block(4,37,5,ICE:0)
Block(4,38,-1,PACKED_ICE:0)
Block(4,38,0,PACKED_ICE:0)
Block(4,38,1,PACKED_ICE:0)
Block(4,38,2,ICE:0)
Block(4,38,3,PACKED_ICE:0)
Block(4,39,0,ICE:0)
Block(4,39,1,PACKED_ICE:0)
