Author: NLBlackEagle
Description: No description given
SettingsMode: WriteDisable
Frequency: 0
SpawnHeight: highestBlock
UseCenterForHighestBlock: true
MinHeight: 0
MaxHeight: 255
InheritBO3: 
InheritBO3Rotation: NORTH
OverrideChildSettings: true
OverrideParentHeight: false
CanOverride: false
BranchFrequency: 0
BranchFrequencyGroup: 
MustBeBelowOther: false
MustBeInside: 
CannotBeInside: 
ReplacesBO3: 
MustBeInsideWorldBorders: false
CanSpawnOnWater: true
SpawnOnWaterOnly: false
SpawnUnderWater: false
SpawnAtWaterLevel: false
HeightOffset: 0
RemoveAir: false
ReplaceAbove: 
ReplaceBelow: 
ReplaceWithBiomeBlocks: true
ReplaceWithSurfaceBlock: GRASS
ReplaceWithGroundBlock: DIRT
ReplaceWithStoneBlock: STONE
SmoothRadius: 0
SmoothHeightOffset: 0
SmoothStartTop: false
SmoothStartWood: false
SmoothingSurfaceBlock: 
SmoothingGroundBlock: 
BO3Group: 
IsSpawnPoint: false
DoReplaceBlocks: true
Block(-7,750,9,AIR:0)
Block(-3,1,0,DARK_OAK_STAIRS:4)
Block(-3,1,1,DARK_OAK_STAIRS:4)
Block(-3,1,2,DARK_OAK_STAIRS:4)
Block(-3,1,3,DARK_OAK_STAIRS:7)
Block(-3,2,0,SPRUCE_FENCE:0)
RandomBlock(-3,2,1,DARK_OAK_FENCE:0,30,STONE:6,100)
RandomBlock(-3,2,2,DARK_OAK_FENCE:0,30,STONE:6,100)
Block(-3,2,3,SPRUCE_FENCE:0)
Block(-3,3,0,SPRUCE_FENCE:0)
RandomBlock(-3,3,1,DARK_OAK_FENCE:0,30,STONE:6,100)
RandomBlock(-3,3,2,DARK_OAK_FENCE:0,30,STONE:6,100)
Block(-3,3,3,SPRUCE_FENCE:0)
Block(-3,4,0,WOOD:1)
RandomBlock(-3,4,1,DARK_OAK_FENCE:0,30,STONE:6,100)
RandomBlock(-3,4,2,DARK_OAK_FENCE:0,30,STONE:6,100)
Block(-3,4,3,WOOD:1)
Block(-2,1,0,DARK_OAK_STAIRS:6)
Block(-2,1,1,WOOD:5)
Block(-2,1,2,WOOD:5)
Block(-2,1,3,DARK_OAK_STAIRS:7)
RandomBlock(-2,2,0,DARK_OAK_FENCE:0,30,STONE:6,100)
Block(-2,2,1,DARK_OAK_STAIRS:5)
Block(-2,2,2,DARK_OAK_STAIRS:5)
RandomBlock(-2,2,3,DARK_OAK_FENCE:0,30,STONE:6,100)
RandomBlock(-2,3,0,DARK_OAK_FENCE:0,30,STONE:6,100)
RandomBlock(-2,3,1,AIR:0,20,CHEST:5,../../../../Chests/Loot/JunkChest_1.nbt,10,CHEST:5,../../../../Chests/Loot/JunkChest_2.nbt,10,CHEST:5,../../../../Chests/Loot/JunkChest_3.nbt,10,CHEST:5,../../../../Chests/Loot/JunkChest_4.nbt,10,CHEST:5,../../../../Chests/Loot/JunkChest_5.nbt,10,CHEST:5,../../../../Chests/Lore/HiddenMine_1.nbt,1,CHEST:5,../../../../Chests/Lore/HiddenMine_2.nbt,1,CHEST:5,../../../../Chests/Lore/HiddenMine_3.nbt,1,CHEST:5,../../../../Chests/Lore/HiddenMine_4.nbt,1,CHEST:5,../../../../Chests/Lore/HiddenMine_5.nbt,1,CHEST:5,../../../../Chests/Loot/Common1.nbt,10,CHEST:5,../../../../Chests/Loot/Common2.nbt,10,CHEST:5,../../../../Chests/Loot/Common3.nbt,10,CHEST:5,../../../../Chests/Loot/Common4.nbt,10,CHEST:5,../../../../Chests/Loot/Common5.nbt,10,CHEST:5,../../../../Chests/Loot/Common6.nbt,10,CHEST:5,../../../../Chests/Loot/Common7.nbt,10,CHEST:5,../../../../Chests/Loot/Common8.nbt,10,CHEST:5,../../../../Chests/Loot/Common9.nbt,10,CHEST:5,../../../../Chests/Loot/Common10.nbt,10,CHEST:5,../../../../Chests/Loot/Common10.nbt,11,CHEST:5,../../../../Chests/Loot/Common12.nbt,10,CHEST:5,../../../../Chests/Loot/Common13.nbt,10,CHEST:5,../../../../Chests/Loot/Common14.nbt,10,CHEST:5,../../../../Chests/Loot/Common15.nbt,10,CHEST:5,../../../../Chests/Lore/HiddenMine_1.nbt,2,CHEST:5,../../../../Chests/Lore/HiddenMine_3.nbt,2,CHEST:5,../../../../Chests/Lore/HiddenMine_4.nbt,2,CHEST:5,../../../../Chests/Lore/HiddenMine_5.nbt,2,CHEST:5,../../../../Chests/Lore/HiddenMine_5.nbt,2,CHEST:5,../../../../Chests/Loot/Rare1.nbt,5,CHEST:5,../../../../Chests/Loot/Rare2.nbt,5,CHEST:5,../../../../Chests/Loot/Rare3.nbt,5,CHEST:5,../../../../Chests/Loot/Rare4.nbt,5,CHEST:5,../../../../Chests/Loot/Rare5.nbt,5,CHEST:5,../../../../Chests/Loot/Rare6.nbt,5,CHEST:5,../../../../Chests/Loot/Rare7.nbt,5,CHEST:5,../../../../Chests/Loot/Rare8.nbt,5,CHEST:5,../../../../Chests/Loot/Rare9.nbt,5,CHEST:5,../../../../Chests/Loot/Rare10.nbt,5,CHEST:5,../../../../Chests/Loot/Rare11.nbt,5,CHEST:5,../../../../Chests/Loot/Rare12.nbt,5,CHEST:5,../../../../Chests/Loot/Rare13.nbt,5,CHEST:5,../../../../Chests/Loot/Rare14.nbt,5,CHEST:5,../../../../Chests/Loot/Rare15.nbt,5,CHEST:5,../../../../Chests/Loot/Epic1.nbt,2,CHEST:5,../../../../Chests/Loot/Epic2.nbt,2,CHEST:5,../../../../Chests/Loot/Epic3.nbt,2,CHEST:5,../../../../Chests/Loot/Epic4.nbt,2,CHEST:5,../../../../Chests/Loot/Epic5.nbt,2,CHEST:5,../../../../Chests/Loot/Epic6.nbt,2,CHEST:5,../../../../Chests/Loot/Epic7.nbt,2,CHEST:5,../../../../Chests/Loot/Epic8.nbt,2,CHEST:5,../../../../Chests/Loot/Epic9.nbt,2,CHEST:5,../../../../Chests/Loot/Epic10.nbt,2,CHEST:5,../../../../Chests/Loot/Epic11.nbt,2,CHEST:5,../../../../Chests/Loot/Epic12.nbt,2,CHEST:5,../../../../Chests/Loot/Epic13.nbt,2,CHEST:5,../../../../Chests/Loot/Epic14.nbt,2,CHEST:5,../../../../Chests/Loot/Epic15.nbt,5,CHEST:5,../../../../Chests/Loot/Rare1.nbt,5,CHEST:5,../../../../Chests/Loot/Rare2.nbt,5,CHEST:5,../../../../Chests/Loot/Rare3.nbt,5,CHEST:5,../../../../Chests/Loot/Rare4.nbt,5,CHEST:5,../../../../Chests/Loot/Rare5.nbt,10,CHEST:5,../../../../Chests/Loot/Rare6.nbt,10,CHEST:5,../../../../Chests/Loot/Rare7.nbt,10,CHEST:5,../../../../Chests/Loot/Rare8.nbt,10,CHEST:5,../../../../Chests/Loot/Rare9.nbt,10,CHEST:5,../../../../Chests/Loot/Rare10.nbt,15,CHEST:5,../../../../Chests/Loot/Rare11.nbt,15,CHEST:5,../../../../Chests/Loot/Rare12.nbt,15,CHEST:5,../../../../Chests/Loot/Rare13.nbt,15,CHEST:5,../../../../Chests/Loot/Rare14.nbt,15,CHEST:5,../../../../Chests/Loot/Rare15.nbt,15,CHEST:5,../../../../Chests/Loot/Epic15.nbt,100)
RandomBlock(-2,3,2,AIR:0,20,CHEST:5,../../../../Chests/Loot/JunkChest_1.nbt,10,CHEST:5,../../../../Chests/Loot/JunkChest_2.nbt,10,CHEST:5,../../../../Chests/Loot/JunkChest_3.nbt,10,CHEST:5,../../../../Chests/Loot/JunkChest_4.nbt,10,CHEST:5,../../../../Chests/Loot/JunkChest_5.nbt,10,CHEST:5,../../../../Chests/Lore/HiddenMine_1.nbt,1,CHEST:5,../../../../Chests/Lore/HiddenMine_2.nbt,1,CHEST:5,../../../../Chests/Lore/HiddenMine_3.nbt,1,CHEST:5,../../../../Chests/Lore/HiddenMine_4.nbt,1,CHEST:5,../../../../Chests/Lore/HiddenMine_5.nbt,1,CHEST:5,../../../../Chests/Loot/Common1.nbt,10,CHEST:5,../../../../Chests/Loot/Common2.nbt,10,CHEST:5,../../../../Chests/Loot/Common3.nbt,10,CHEST:5,../../../../Chests/Loot/Common4.nbt,10,CHEST:5,../../../../Chests/Loot/Common5.nbt,10,CHEST:5,../../../../Chests/Loot/Common6.nbt,10,CHEST:5,../../../../Chests/Loot/Common7.nbt,10,CHEST:5,../../../../Chests/Loot/Common8.nbt,10,CHEST:5,../../../../Chests/Loot/Common9.nbt,10,CHEST:5,../../../../Chests/Loot/Common10.nbt,10,CHEST:5,../../../../Chests/Loot/Common10.nbt,11,CHEST:5,../../../../Chests/Loot/Common12.nbt,10,CHEST:5,../../../../Chests/Loot/Common13.nbt,10,CHEST:5,../../../../Chests/Loot/Common14.nbt,10,CHEST:5,../../../../Chests/Loot/Common15.nbt,10,CHEST:5,../../../../Chests/Lore/HiddenMine_1.nbt,2,CHEST:5,../../../../Chests/Lore/HiddenMine_3.nbt,2,CHEST:5,../../../../Chests/Lore/HiddenMine_4.nbt,2,CHEST:5,../../../../Chests/Lore/HiddenMine_5.nbt,2,CHEST:5,../../../../Chests/Lore/HiddenMine_5.nbt,2,CHEST:5,../../../../Chests/Loot/Rare1.nbt,5,CHEST:5,../../../../Chests/Loot/Rare2.nbt,5,CHEST:5,../../../../Chests/Loot/Rare3.nbt,5,CHEST:5,../../../../Chests/Loot/Rare4.nbt,5,CHEST:5,../../../../Chests/Loot/Rare5.nbt,5,CHEST:5,../../../../Chests/Loot/Rare6.nbt,5,CHEST:5,../../../../Chests/Loot/Rare7.nbt,5,CHEST:5,../../../../Chests/Loot/Rare8.nbt,5,CHEST:5,../../../../Chests/Loot/Rare9.nbt,5,CHEST:5,../../../../Chests/Loot/Rare10.nbt,5,CHEST:5,../../../../Chests/Loot/Rare11.nbt,5,CHEST:5,../../../../Chests/Loot/Rare12.nbt,5,CHEST:5,../../../../Chests/Loot/Rare13.nbt,5,CHEST:5,../../../../Chests/Loot/Rare14.nbt,5,CHEST:5,../../../../Chests/Loot/Rare15.nbt,5,CHEST:5,../../../../Chests/Loot/Epic1.nbt,2,CHEST:5,../../../../Chests/Loot/Epic2.nbt,2,CHEST:5,../../../../Chests/Loot/Epic3.nbt,2,CHEST:5,../../../../Chests/Loot/Epic4.nbt,2,CHEST:5,../../../../Chests/Loot/Epic5.nbt,2,CHEST:5,../../../../Chests/Loot/Epic6.nbt,2,CHEST:5,../../../../Chests/Loot/Epic7.nbt,2,CHEST:5,../../../../Chests/Loot/Epic8.nbt,2,CHEST:5,../../../../Chests/Loot/Epic9.nbt,2,CHEST:5,../../../../Chests/Loot/Epic10.nbt,2,CHEST:5,../../../../Chests/Loot/Epic11.nbt,2,CHEST:5,../../../../Chests/Loot/Epic12.nbt,2,CHEST:5,../../../../Chests/Loot/Epic13.nbt,2,CHEST:5,../../../../Chests/Loot/Epic14.nbt,2,CHEST:5,../../../../Chests/Loot/Epic15.nbt,5,CHEST:5,../../../../Chests/Loot/Rare1.nbt,5,CHEST:5,../../../../Chests/Loot/Rare2.nbt,5,CHEST:5,../../../../Chests/Loot/Rare3.nbt,5,CHEST:5,../../../../Chests/Loot/Rare4.nbt,5,CHEST:5,../../../../Chests/Loot/Rare5.nbt,10,CHEST:5,../../../../Chests/Loot/Rare6.nbt,10,CHEST:5,../../../../Chests/Loot/Rare7.nbt,10,CHEST:5,../../../../Chests/Loot/Rare8.nbt,10,CHEST:5,../../../../Chests/Loot/Rare9.nbt,10,CHEST:5,../../../../Chests/Loot/Rare10.nbt,15,CHEST:5,../../../../Chests/Loot/Rare11.nbt,15,CHEST:5,../../../../Chests/Loot/Rare12.nbt,15,CHEST:5,../../../../Chests/Loot/Rare13.nbt,15,CHEST:5,../../../../Chests/Loot/Rare14.nbt,15,CHEST:5,../../../../Chests/Loot/Rare15.nbt,15,CHEST:5,../../../../Chests/Loot/Epic15.nbt,100)
RandomBlock(-2,3,3,DARK_OAK_FENCE:0,30,STONE:6,100)
Block(-2,4,0,WOOD:1)
Block(-2,4,1,TRAP_DOOR:9)
Block(-2,4,2,TRAP_DOOR:9)
Block(-2,4,3,WOOD:1)
Block(-1,0,-6,LOG:1)
Block(-1,0,0,LOG:1)
Block(-1,0,3,LOG:1)
Block(-1,0,9,LOG:1)
Block(-1,1,-6,WOOD:5)
Block(-1,1,-5,WOOD:5)
Block(-1,1,-4,WOOD:5)
Block(-1,1,-3,WOOD:5)
Block(-1,1,-2,WOOD:5)
Block(-1,1,-1,WOOD:5)
Block(-1,1,0,WOOD:5)
Block(-1,1,1,WOOD:5)
Block(-1,1,2,WOOD:5)
Block(-1,1,3,WOOD:5)
Block(-1,1,4,WOOD:5)
Block(-1,1,5,WOOD:5)
Block(-1,1,6,WOOD:5)
Block(-1,1,7,WOOD:5)
Block(-1,1,8,WOOD:5)
Block(-1,1,9,WOOD:5)
Block(-1,2,-6,SPRUCE_FENCE:0)
RandomBlock(-1,2,-5,DARK_OAK_FENCE:0,30,STONE:6,100)
RandomBlock(-1,2,-4,DARK_OAK_FENCE:0,30,STONE:6,100)
Block(-1,2,-3,SPRUCE_FENCE:0)
RandomBlock(-1,2,-2,DARK_OAK_FENCE:0,30,STONE:6,100)
RandomBlock(-1,2,-1,DARK_OAK_FENCE:0,30,STONE:6,100)
RandomBlock(-1,2,0,DARK_OAK_FENCE:0,30,STONE:6,100)
Block(-1,2,1,CARPET:13)
Block(-1,2,2,CARPET:13)
RandomBlock(-1,2,3,DARK_OAK_FENCE:0,30,STONE:6,100)
RandomBlock(-1,2,4,DARK_OAK_FENCE:0,30,STONE:6,100)
RandomBlock(-1,2,5,DARK_OAK_FENCE:0,30,STONE:6,100)
Block(-1,2,6,SPRUCE_FENCE:0)
RandomBlock(-1,2,7,DARK_OAK_FENCE:0,30,STONE:6,100)
RandomBlock(-1,2,8,DARK_OAK_FENCE:0,30,STONE:6,100)
Block(-1,2,9,STONE:6)
Block(-1,3,-6,SPRUCE_FENCE:0)
RandomBlock(-1,3,-5,DARK_OAK_FENCE:0,30,STONE:6,100)
RandomBlock(-1,3,-4,DARK_OAK_FENCE:0,30,STONE:6,100)
Block(-1,3,-3,SPRUCE_FENCE:0)
RandomBlock(-1,3,-2,DARK_OAK_FENCE:0,30,STONE:6,100)
RandomBlock(-1,3,-1,DARK_OAK_FENCE:0,30,STONE:6,100)
RandomBlock(-1,3,0,DARK_OAK_FENCE:0,30,STONE:6,100)
Block(-1,3,1,AIR:0)
Block(-1,3,2,AIR:0)
RandomBlock(-1,3,3,DARK_OAK_FENCE:0,30,STONE:6,100)
RandomBlock(-1,3,4,DARK_OAK_FENCE:0,30,STONE:6,100)
RandomBlock(-1,3,5,DARK_OAK_FENCE:0,30,STONE:6,100)
Block(-1,3,6,SPRUCE_FENCE:0)
Block(-1,3,7,TORCH:5)
RandomBlock(-1,3,8,DARK_OAK_FENCE:0,30,STONE:6,100)
Block(-1,3,9,STONE:6)
Block(-1,4,-6,WOOD:1)
RandomBlock(-1,4,-5,DARK_OAK_FENCE:0,30,STONE:6,100)
RandomBlock(-1,4,-4,DARK_OAK_FENCE:0,30,STONE:6,100)
Block(-1,4,-3,WOOD:1)
RandomBlock(-1,4,-2,DARK_OAK_FENCE:0,30,STONE:6,100)
RandomBlock(-1,4,-1,DARK_OAK_FENCE:0,30,STONE:6,100)
Block(-1,4,0,WOOD:1)
Block(-1,4,1,TRAP_DOOR:9)
Block(-1,4,2,TRAP_DOOR:9)
Block(-1,4,3,WOOD:1)
RandomBlock(-1,4,4,DARK_OAK_FENCE:0,30,STONE:6,100)
RandomBlock(-1,4,5,DARK_OAK_FENCE:0,30,STONE:6,100)
Block(-1,4,6,WOOD:1)
RandomBlock(-1,4,7,DARK_OAK_FENCE:0,30,STONE:6,100)
RandomBlock(-1,4,8,DARK_OAK_FENCE:0,30,STONE:6,100)
Block(-1,4,9,WOOD:1)
Block(0,1,-6,WOOD:5)
Block(0,1,-5,WOOD:5)
Block(0,1,-4,WOOD:5)
Block(0,1,-3,WOOD:5)
Block(0,1,-2,WOOD:5)
Block(0,1,-1,WOOD:5)
Block(0,1,0,WOOD:5)
Block(0,1,1,WOOD:5)
Block(0,1,2,WOOD:5)
Block(0,1,3,WOOD:5)
Block(0,1,4,WOOD:5)
Block(0,1,5,WOOD:5)
Block(0,1,6,WOOD:5)
Block(0,1,7,WOOD:5)
Block(0,1,8,WOOD:5)
Block(0,1,9,WOOD:5)
RandomBlock(0,2,-6,DARK_OAK_FENCE:0,30,STONE:6,100)
Block(0,2,-5,DARK_OAK_STAIRS:7)
Block(0,2,-4,AIR:0)
Block(0,2,-3,CARPET:13)
Block(0,2,-2,AIR:0)
Block(0,2,-1,SPRUCE_FENCE:0)
Block(0,2,0,CARPET:13)
Block(0,2,1,AIR:0)
Block(0,2,2,CARPET:13)
Block(0,2,3,AIR:0)
Block(0,2,4,CARPET:13)
Block(0,2,5,CARPET:13)
Block(0,2,6,AIR:0)
Block(0,2,7,AIR:0)
Block(0,2,8,AIR:0)
Block(0,2,9,SPRUCE_DOOR:1)
RandomBlock(0,3,-6,DARK_OAK_FENCE:0,30,STONE:6,100)
RandomBlock(0,3,-5,AIR:0,20,CHEST:3,../../../../Chests/Loot/JunkChest_1.nbt,10,CHEST:3,../../../../Chests/Loot/JunkChest_2.nbt,10,CHEST:3,../../../../Chests/Loot/JunkChest_3.nbt,10,CHEST:3,../../../../Chests/Loot/JunkChest_4.nbt,10,CHEST:3,../../../../Chests/Loot/JunkChest_5.nbt,10,CHEST:3,../../../../Chests/Lore/HiddenMine_1.nbt,1,CHEST:3,../../../../Chests/Lore/HiddenMine_2.nbt,1,CHEST:3,../../../../Chests/Lore/HiddenMine_3.nbt,1,CHEST:3,../../../../Chests/Lore/HiddenMine_4.nbt,1,CHEST:3,../../../../Chests/Lore/HiddenMine_5.nbt,1,CHEST:3,../../../../Chests/Loot/Common1.nbt,10,CHEST:3,../../../../Chests/Loot/Common2.nbt,10,CHEST:3,../../../../Chests/Loot/Common3.nbt,10,CHEST:3,../../../../Chests/Loot/Common4.nbt,10,CHEST:3,../../../../Chests/Loot/Common5.nbt,10,CHEST:3,../../../../Chests/Loot/Common6.nbt,10,CHEST:3,../../../../Chests/Loot/Common7.nbt,10,CHEST:3,../../../../Chests/Loot/Common8.nbt,10,CHEST:3,../../../../Chests/Loot/Common9.nbt,10,CHEST:3,../../../../Chests/Loot/Common10.nbt,10,CHEST:3,../../../../Chests/Loot/Common10.nbt,11,CHEST:3,../../../../Chests/Loot/Common12.nbt,10,CHEST:3,../../../../Chests/Loot/Common13.nbt,10,CHEST:3,../../../../Chests/Loot/Common14.nbt,10,CHEST:3,../../../../Chests/Loot/Common15.nbt,10,CHEST:3,../../../../Chests/Lore/HiddenMine_1.nbt,2,CHEST:3,../../../../Chests/Lore/HiddenMine_3.nbt,2,CHEST:3,../../../../Chests/Lore/HiddenMine_4.nbt,2,CHEST:3,../../../../Chests/Lore/HiddenMine_5.nbt,2,CHEST:3,../../../../Chests/Lore/HiddenMine_5.nbt,2,CHEST:3,../../../../Chests/Loot/Rare1.nbt,5,CHEST:3,../../../../Chests/Loot/Rare2.nbt,5,CHEST:3,../../../../Chests/Loot/Rare3.nbt,5,CHEST:3,../../../../Chests/Loot/Rare4.nbt,5,CHEST:3,../../../../Chests/Loot/Rare5.nbt,5,CHEST:3,../../../../Chests/Loot/Rare6.nbt,5,CHEST:3,../../../../Chests/Loot/Rare7.nbt,5,CHEST:3,../../../../Chests/Loot/Rare8.nbt,5,CHEST:3,../../../../Chests/Loot/Rare9.nbt,5,CHEST:3,../../../../Chests/Loot/Rare10.nbt,5,CHEST:3,../../../../Chests/Loot/Rare11.nbt,5,CHEST:3,../../../../Chests/Loot/Rare12.nbt,5,CHEST:3,../../../../Chests/Loot/Rare13.nbt,5,CHEST:3,../../../../Chests/Loot/Rare14.nbt,5,CHEST:3,../../../../Chests/Loot/Rare15.nbt,5,CHEST:3,../../../../Chests/Loot/Epic1.nbt,2,CHEST:3,../../../../Chests/Loot/Epic2.nbt,2,CHEST:3,../../../../Chests/Loot/Epic3.nbt,2,CHEST:3,../../../../Chests/Loot/Epic4.nbt,2,CHEST:3,../../../../Chests/Loot/Epic5.nbt,2,CHEST:3,../../../../Chests/Loot/Epic6.nbt,2,CHEST:3,../../../../Chests/Loot/Epic7.nbt,2,CHEST:3,../../../../Chests/Loot/Epic8.nbt,2,CHEST:3,../../../../Chests/Loot/Epic9.nbt,2,CHEST:3,../../../../Chests/Loot/Epic10.nbt,2,CHEST:3,../../../../Chests/Loot/Epic11.nbt,2,CHEST:3,../../../../Chests/Loot/Epic12.nbt,2,CHEST:3,../../../../Chests/Loot/Epic13.nbt,2,CHEST:3,../../../../Chests/Loot/Epic14.nbt,2,CHEST:3,../../../../Chests/Loot/Epic15.nbt,5,CHEST:3,../../../../Chests/Loot/Rare1.nbt,5,CHEST:3,../../../../Chests/Loot/Rare2.nbt,5,CHEST:3,../../../../Chests/Loot/Rare3.nbt,5,CHEST:3,../../../../Chests/Loot/Rare4.nbt,5,CHEST:3,../../../../Chests/Loot/Rare5.nbt,10,CHEST:3,../../../../Chests/Loot/Rare6.nbt,10,CHEST:3,../../../../Chests/Loot/Rare7.nbt,10,CHEST:3,../../../../Chests/Loot/Rare8.nbt,10,CHEST:3,../../../../Chests/Loot/Rare9.nbt,10,CHEST:3,../../../../Chests/Loot/Rare10.nbt,15,CHEST:3,../../../../Chests/Loot/Rare11.nbt,15,CHEST:3,../../../../Chests/Loot/Rare12.nbt,15,CHEST:3,../../../../Chests/Loot/Rare13.nbt,15,CHEST:3,../../../../Chests/Loot/Rare14.nbt,15,CHEST:3,../../../../Chests/Loot/Rare15.nbt,15,CHEST:3,../../../../Chests/Loot/Epic15.nbt,100)
Block(0,3,-4,AIR:0)
Block(0,3,-3,AIR:0)
Block(0,3,-2,AIR:0)
Block(0,3,-1,TORCH:5)
Block(0,3,0,AIR:0)
Block(0,3,1,AIR:0)
Block(0,3,2,AIR:0)
Block(0,3,3,AIR:0)
Block(0,3,4,AIR:0)
Block(0,3,5,AIR:0)
Block(0,3,6,AIR:0)
Block(0,3,7,AIR:0)
Block(0,3,8,AIR:0)
Block(0,3,9,SPRUCE_DOOR:9)
Block(0,4,-6,WOOD:1)
Block(0,4,-5,TRAP_DOOR:9)
Block(0,4,-4,TRAP_DOOR:9)
Block(0,4,-3,WOOD:1)
Block(0,4,-2,TRAP_DOOR:9)
Block(0,4,-1,TRAP_DOOR:9)
Block(0,4,0,WOOD:1)
Block(0,4,1,TRAP_DOOR:9)
Block(0,4,2,TRAP_DOOR:9)
Block(0,4,3,WOOD:1)
Block(0,4,4,TRAP_DOOR:9)
Block(0,4,5,TRAP_DOOR:9)
Block(0,4,6,WOOD:1)
Block(0,4,7,TRAP_DOOR:8)
Block(0,4,8,TRAP_DOOR:8)
Block(0,4,9,WOOD:1)
Block(1,1,-6,WOOD:5)
Block(1,1,-5,WOOD:5)
Block(1,1,-4,WOOD:5)
Block(1,1,-3,WOOD:5)
Block(1,1,-2,WOOD:5)
Block(1,1,-1,WOOD:5)
Block(1,1,0,WOOD:5)
Block(1,1,1,WOOD:5)
Block(1,1,2,WOOD:5)
Block(1,1,3,WOOD:5)
Block(1,1,4,WOOD:5)
Block(1,1,5,WOOD:5)
Block(1,1,6,WOOD:5)
Block(1,1,7,WOOD:5)
Block(1,1,8,WOOD:5)
Block(1,1,9,WOOD:5)
RandomBlock(1,2,-6,DARK_OAK_FENCE:0,30,STONE:6,100)
Block(1,2,-5,DARK_OAK_STAIRS:7)
Block(1,2,-4,CARPET:13)
Block(1,2,-3,CARPET:13)
Block(1,2,-2,CARPET:13)
Block(1,2,-1,CARPET:13)
Block(1,2,0,CARPET:13)
Block(1,2,1,AIR:0)
Block(1,2,2,CARPET:13)
Block(1,2,3,CARPET:13)
Block(1,2,4,CARPET:13)
Block(1,2,5,CARPET:13)
Block(1,2,6,CARPET:13)
Block(1,2,7,AIR:0)
Block(1,2,8,AIR:0)
Block(1,2,9,SPRUCE_DOOR:1)
RandomBlock(1,3,-6,DARK_OAK_FENCE:0,30,STONE:6,100)
RandomBlock(1,3,-5,AIR:0,20,CHEST:3,../../../../Chests/Loot/JunkChest_1.nbt,10,CHEST:3,../../../../Chests/Loot/JunkChest_2.nbt,10,CHEST:3,../../../../Chests/Loot/JunkChest_3.nbt,10,CHEST:3,../../../../Chests/Loot/JunkChest_4.nbt,10,CHEST:3,../../../../Chests/Loot/JunkChest_5.nbt,10,CHEST:3,../../../../Chests/Lore/HiddenMine_1.nbt,1,CHEST:3,../../../../Chests/Lore/HiddenMine_2.nbt,1,CHEST:3,../../../../Chests/Lore/HiddenMine_3.nbt,1,CHEST:3,../../../../Chests/Lore/HiddenMine_4.nbt,1,CHEST:3,../../../../Chests/Lore/HiddenMine_5.nbt,1,CHEST:3,../../../../Chests/Loot/Common1.nbt,10,CHEST:3,../../../../Chests/Loot/Common2.nbt,10,CHEST:3,../../../../Chests/Loot/Common3.nbt,10,CHEST:3,../../../../Chests/Loot/Common4.nbt,10,CHEST:3,../../../../Chests/Loot/Common5.nbt,10,CHEST:3,../../../../Chests/Loot/Common6.nbt,10,CHEST:3,../../../../Chests/Loot/Common7.nbt,10,CHEST:3,../../../../Chests/Loot/Common8.nbt,10,CHEST:3,../../../../Chests/Loot/Common9.nbt,10,CHEST:3,../../../../Chests/Loot/Common10.nbt,10,CHEST:3,../../../../Chests/Loot/Common10.nbt,11,CHEST:3,../../../../Chests/Loot/Common12.nbt,10,CHEST:3,../../../../Chests/Loot/Common13.nbt,10,CHEST:3,../../../../Chests/Loot/Common14.nbt,10,CHEST:3,../../../../Chests/Loot/Common15.nbt,10,CHEST:3,../../../../Chests/Lore/HiddenMine_1.nbt,2,CHEST:3,../../../../Chests/Lore/HiddenMine_3.nbt,2,CHEST:3,../../../../Chests/Lore/HiddenMine_4.nbt,2,CHEST:3,../../../../Chests/Lore/HiddenMine_5.nbt,2,CHEST:3,../../../../Chests/Lore/HiddenMine_5.nbt,2,CHEST:3,../../../../Chests/Loot/Rare1.nbt,5,CHEST:3,../../../../Chests/Loot/Rare2.nbt,5,CHEST:3,../../../../Chests/Loot/Rare3.nbt,5,CHEST:3,../../../../Chests/Loot/Rare4.nbt,5,CHEST:3,../../../../Chests/Loot/Rare5.nbt,5,CHEST:3,../../../../Chests/Loot/Rare6.nbt,5,CHEST:3,../../../../Chests/Loot/Rare7.nbt,5,CHEST:3,../../../../Chests/Loot/Rare8.nbt,5,CHEST:3,../../../../Chests/Loot/Rare9.nbt,5,CHEST:3,../../../../Chests/Loot/Rare10.nbt,5,CHEST:3,../../../../Chests/Loot/Rare11.nbt,5,CHEST:3,../../../../Chests/Loot/Rare12.nbt,5,CHEST:3,../../../../Chests/Loot/Rare13.nbt,5,CHEST:3,../../../../Chests/Loot/Rare14.nbt,5,CHEST:3,../../../../Chests/Loot/Rare15.nbt,5,CHEST:3,../../../../Chests/Loot/Epic1.nbt,2,CHEST:3,../../../../Chests/Loot/Epic2.nbt,2,CHEST:3,../../../../Chests/Loot/Epic3.nbt,2,CHEST:3,../../../../Chests/Loot/Epic4.nbt,2,CHEST:3,../../../../Chests/Loot/Epic5.nbt,2,CHEST:3,../../../../Chests/Loot/Epic6.nbt,2,CHEST:3,../../../../Chests/Loot/Epic7.nbt,2,CHEST:3,../../../../Chests/Loot/Epic8.nbt,2,CHEST:3,../../../../Chests/Loot/Epic9.nbt,2,CHEST:3,../../../../Chests/Loot/Epic10.nbt,2,CHEST:3,../../../../Chests/Loot/Epic11.nbt,2,CHEST:3,../../../../Chests/Loot/Epic12.nbt,2,CHEST:3,../../../../Chests/Loot/Epic13.nbt,2,CHEST:3,../../../../Chests/Loot/Epic14.nbt,2,CHEST:3,../../../../Chests/Loot/Epic15.nbt,5,CHEST:3,../../../../Chests/Loot/Rare1.nbt,5,CHEST:3,../../../../Chests/Loot/Rare2.nbt,5,CHEST:3,../../../../Chests/Loot/Rare3.nbt,5,CHEST:3,../../../../Chests/Loot/Rare4.nbt,5,CHEST:3,../../../../Chests/Loot/Rare5.nbt,10,CHEST:3,../../../../Chests/Loot/Rare6.nbt,10,CHEST:3,../../../../Chests/Loot/Rare7.nbt,10,CHEST:3,../../../../Chests/Loot/Rare8.nbt,10,CHEST:3,../../../../Chests/Loot/Rare9.nbt,10,CHEST:3,../../../../Chests/Loot/Rare10.nbt,15,CHEST:3,../../../../Chests/Loot/Rare11.nbt,15,CHEST:3,../../../../Chests/Loot/Rare12.nbt,15,CHEST:3,../../../../Chests/Loot/Rare13.nbt,15,CHEST:3,../../../../Chests/Loot/Rare14.nbt,15,CHEST:3,../../../../Chests/Loot/Rare15.nbt,15,CHEST:3,../../../../Chests/Loot/Epic15.nbt,100)
Block(1,3,-4,AIR:0)
Block(1,3,-3,AIR:0)
Block(1,3,-2,AIR:0)
Block(1,3,-1,AIR:0)
Block(1,3,0,AIR:0)
Block(1,3,1,AIR:0)
Block(1,3,2,AIR:0)
Block(1,3,3,AIR:0)
Block(1,3,4,AIR:0)
Block(1,3,5,AIR:0)
Block(1,3,6,AIR:0)
Block(1,3,7,AIR:0)
Block(1,3,8,AIR:0)
Block(1,3,9,SPRUCE_DOOR:8)
Block(1,4,-6,WOOD:1)
Block(1,4,-5,TRAP_DOOR:9)
Block(1,4,-4,TRAP_DOOR:9)
Block(1,4,-3,WOOD:1)
Block(1,4,-2,TRAP_DOOR:9)
Block(1,4,-1,TRAP_DOOR:9)
Block(1,4,0,WOOD:1)
Block(1,4,1,TRAP_DOOR:9)
Block(1,4,2,TRAP_DOOR:9)
Block(1,4,3,WOOD:1)
Block(1,4,4,TRAP_DOOR:9)
Block(1,4,5,TRAP_DOOR:9)
Block(1,4,6,WOOD:1)
Block(1,4,7,TRAP_DOOR:8)
Block(1,4,8,TRAP_DOOR:8)
Block(1,4,9,WOOD:1)
Block(2,0,-6,LOG:1)
Block(2,0,0,LOG:1)
Block(2,0,9,LOG:1)
Block(2,1,-6,WOOD:5)
Block(2,1,-5,WOOD:5)
Block(2,1,-4,WOOD:5)
Block(2,1,-3,WOOD:5)
Block(2,1,-2,WOOD:5)
Block(2,1,-1,WOOD:5)
Block(2,1,0,WOOD:5)
Block(2,1,1,WOOD:5)
Block(2,1,2,WOOD:5)
Block(2,1,3,WOOD:5)
Block(2,1,4,WOOD:5)
Block(2,1,5,WOOD:5)
Block(2,1,6,WOOD:5)
Block(2,1,7,WOOD:5)
Block(2,1,8,WOOD:5)
Block(2,1,9,WOOD:5)
Block(2,2,-6,SPRUCE_FENCE:0)
Block(2,2,-5,AIR:0)
Block(2,2,-4,CARPET:13)
Block(2,2,-3,AIR:0)
Block(2,2,-2,AIR:0)
Block(2,2,-1,AIR:0)
Block(2,2,0,SPRUCE_FENCE:0)
RandomBlock(2,2,1,DARK_OAK_FENCE:0,30,STONE:6,100)
RandomBlock(2,2,2,DARK_OAK_FENCE:0,30,STONE:6,100)
Block(2,2,3,SPRUCE_FENCE:0)
RandomBlock(2,2,4,DARK_OAK_FENCE:0,30,STONE:6,100)
RandomBlock(2,2,5,DARK_OAK_FENCE:0,30,STONE:6,100)
Block(2,2,6,SPRUCE_FENCE:0)
RandomBlock(2,2,7,DARK_OAK_FENCE:0,30,STONE:6,100)
RandomBlock(2,2,8,DARK_OAK_FENCE:0,30,STONE:6,100)
Block(2,2,9,STONE:6)
Block(2,3,-6,SPRUCE_FENCE:0)
Block(2,3,-5,AIR:0)
Block(2,3,-4,AIR:0)
Block(2,3,-3,AIR:0)
Block(2,3,-2,AIR:0)
Block(2,3,-1,AIR:0)
Block(2,3,0,SPRUCE_FENCE:0)
RandomBlock(2,3,1,DARK_OAK_FENCE:0,30,STONE:6,100)
RandomBlock(2,3,2,DARK_OAK_FENCE:0,30,STONE:6,100)
Block(2,3,3,SPRUCE_FENCE:0)
RandomBlock(2,3,4,DARK_OAK_FENCE:0,30,STONE:6,100)
Block(2,3,5,TORCH:5)
Block(2,3,6,SPRUCE_FENCE:0)
RandomBlock(2,3,7,DARK_OAK_FENCE:0,30,STONE:6,100)
RandomBlock(2,3,8,DARK_OAK_FENCE:0,30,STONE:6,100)
Block(2,3,9,STONE:6)
Block(2,4,-6,WOOD:1)
Block(2,4,-5,TRAP_DOOR:9)
Block(2,4,-4,TRAP_DOOR:9)
Block(2,4,-3,WOOD:1)
Block(2,4,-2,TRAP_DOOR:9)
Block(2,4,-1,TRAP_DOOR:9)
Block(2,4,0,WOOD:1)
RandomBlock(2,4,1,DARK_OAK_FENCE:0,30,STONE:6,100)
RandomBlock(2,4,2,DARK_OAK_FENCE:0,30,STONE:6,100)
Block(2,4,3,WOOD:1)
RandomBlock(2,4,4,DARK_OAK_FENCE:0,30,STONE:6,100)
RandomBlock(2,4,5,DARK_OAK_FENCE:0,30,STONE:6,100)
Block(2,4,6,WOOD:1)
RandomBlock(2,4,7,DARK_OAK_FENCE:0,30,STONE:6,100)
RandomBlock(2,4,8,DARK_OAK_FENCE:0,30,STONE:6,100)
Block(2,4,9,WOOD:1)
Block(3,1,-6,DARK_OAK_STAIRS:6)
Block(3,1,-5,WOOD:5)
Block(3,1,-4,WOOD:5)
Block(3,1,-3,WOOD:5)
Block(3,1,-2,WOOD:5)
Block(3,1,-1,WOOD:5)
Block(3,1,0,DARK_OAK_STAIRS:7)
RandomBlock(3,2,-6,DARK_OAK_FENCE:0,30,STONE:6,100)
Block(3,2,-5,DARK_OAK_STAIRS:7)
Block(3,2,-4,SPRUCE_FENCE:0)
Block(3,2,-3,BOOKSHELF:0)
Block(3,2,-2,BOOKSHELF:0)
Block(3,2,-1,BOOKSHELF:0)
RandomBlock(3,2,0,DARK_OAK_FENCE:0,30,STONE:6,100)
RandomBlock(3,3,-6,DARK_OAK_FENCE:0,30,STONE:6,100)
RandomBlock(3,3,-5,AIR:0,20,CHEST:3,../../../../Chests/Loot/JunkChest_1.nbt,10,CHEST:3,../../../../Chests/Loot/JunkChest_2.nbt,10,CHEST:3,../../../../Chests/Loot/JunkChest_3.nbt,10,CHEST:3,../../../../Chests/Loot/JunkChest_4.nbt,10,CHEST:3,../../../../Chests/Loot/JunkChest_5.nbt,10,CHEST:3,../../../../Chests/Lore/HiddenMine_1.nbt,1,CHEST:3,../../../../Chests/Lore/HiddenMine_2.nbt,1,CHEST:3,../../../../Chests/Lore/HiddenMine_3.nbt,1,CHEST:3,../../../../Chests/Lore/HiddenMine_4.nbt,1,CHEST:3,../../../../Chests/Lore/HiddenMine_5.nbt,1,CHEST:3,../../../../Chests/Loot/Common1.nbt,10,CHEST:3,../../../../Chests/Loot/Common2.nbt,10,CHEST:3,../../../../Chests/Loot/Common3.nbt,10,CHEST:3,../../../../Chests/Loot/Common4.nbt,10,CHEST:3,../../../../Chests/Loot/Common5.nbt,10,CHEST:3,../../../../Chests/Loot/Common6.nbt,10,CHEST:3,../../../../Chests/Loot/Common7.nbt,10,CHEST:3,../../../../Chests/Loot/Common8.nbt,10,CHEST:3,../../../../Chests/Loot/Common9.nbt,10,CHEST:3,../../../../Chests/Loot/Common10.nbt,10,CHEST:3,../../../../Chests/Loot/Common10.nbt,11,CHEST:3,../../../../Chests/Loot/Common12.nbt,10,CHEST:3,../../../../Chests/Loot/Common13.nbt,10,CHEST:3,../../../../Chests/Loot/Common14.nbt,10,CHEST:3,../../../../Chests/Loot/Common15.nbt,10,CHEST:3,../../../../Chests/Lore/HiddenMine_1.nbt,2,CHEST:3,../../../../Chests/Lore/HiddenMine_3.nbt,2,CHEST:3,../../../../Chests/Lore/HiddenMine_4.nbt,2,CHEST:3,../../../../Chests/Lore/HiddenMine_5.nbt,2,CHEST:3,../../../../Chests/Lore/HiddenMine_5.nbt,2,CHEST:3,../../../../Chests/Loot/Rare1.nbt,5,CHEST:3,../../../../Chests/Loot/Rare2.nbt,5,CHEST:3,../../../../Chests/Loot/Rare3.nbt,5,CHEST:3,../../../../Chests/Loot/Rare4.nbt,5,CHEST:3,../../../../Chests/Loot/Rare5.nbt,5,CHEST:3,../../../../Chests/Loot/Rare6.nbt,5,CHEST:3,../../../../Chests/Loot/Rare7.nbt,5,CHEST:3,../../../../Chests/Loot/Rare8.nbt,5,CHEST:3,../../../../Chests/Loot/Rare9.nbt,5,CHEST:3,../../../../Chests/Loot/Rare10.nbt,5,CHEST:3,../../../../Chests/Loot/Rare11.nbt,5,CHEST:3,../../../../Chests/Loot/Rare12.nbt,5,CHEST:3,../../../../Chests/Loot/Rare13.nbt,5,CHEST:3,../../../../Chests/Loot/Rare14.nbt,5,CHEST:3,../../../../Chests/Loot/Rare15.nbt,5,CHEST:3,../../../../Chests/Loot/Epic1.nbt,2,CHEST:3,../../../../Chests/Loot/Epic2.nbt,2,CHEST:3,../../../../Chests/Loot/Epic3.nbt,2,CHEST:3,../../../../Chests/Loot/Epic4.nbt,2,CHEST:3,../../../../Chests/Loot/Epic5.nbt,2,CHEST:3,../../../../Chests/Loot/Epic6.nbt,2,CHEST:3,../../../../Chests/Loot/Epic7.nbt,2,CHEST:3,../../../../Chests/Loot/Epic8.nbt,2,CHEST:3,../../../../Chests/Loot/Epic9.nbt,2,CHEST:3,../../../../Chests/Loot/Epic10.nbt,2,CHEST:3,../../../../Chests/Loot/Epic11.nbt,2,CHEST:3,../../../../Chests/Loot/Epic12.nbt,2,CHEST:3,../../../../Chests/Loot/Epic13.nbt,2,CHEST:3,../../../../Chests/Loot/Epic14.nbt,2,CHEST:3,../../../../Chests/Loot/Epic15.nbt,5,CHEST:3,../../../../Chests/Loot/Rare1.nbt,5,CHEST:3,../../../../Chests/Loot/Rare2.nbt,5,CHEST:3,../../../../Chests/Loot/Rare3.nbt,5,CHEST:3,../../../../Chests/Loot/Rare4.nbt,5,CHEST:3,../../../../Chests/Loot/Rare5.nbt,10,CHEST:3,../../../../Chests/Loot/Rare6.nbt,10,CHEST:3,../../../../Chests/Loot/Rare7.nbt,10,CHEST:3,../../../../Chests/Loot/Rare8.nbt,10,CHEST:3,../../../../Chests/Loot/Rare9.nbt,10,CHEST:3,../../../../Chests/Loot/Rare10.nbt,15,CHEST:3,../../../../Chests/Loot/Rare11.nbt,15,CHEST:3,../../../../Chests/Loot/Rare12.nbt,15,CHEST:3,../../../../Chests/Loot/Rare13.nbt,15,CHEST:3,../../../../Chests/Loot/Rare14.nbt,15,CHEST:3,../../../../Chests/Loot/Rare15.nbt,15,CHEST:3,../../../../Chests/Loot/Epic15.nbt,100)
Block(3,3,-4,TORCH:5)
Block(3,3,-3,BOOKSHELF:0)
Block(3,3,-2,BOOKSHELF:0)
Block(3,3,-1,BOOKSHELF:0)
RandomBlock(3,3,0,DARK_OAK_FENCE:0,30,STONE:6,100)
Block(3,4,-6,WOOD:1)
Block(3,4,-5,TRAP_DOOR:9)
Block(3,4,-4,TRAP_DOOR:9)
Block(3,4,-3,WOOD:1)
Block(3,4,-2,TRAP_DOOR:9)
Block(3,4,-1,TRAP_DOOR:9)
Block(3,4,0,WOOD:1)
Block(4,1,-6,DARK_OAK_STAIRS:6)
Block(4,1,-5,DARK_OAK_STAIRS:5)
Block(4,1,-4,DARK_OAK_STAIRS:5)
Block(4,1,-3,DARK_OAK_STAIRS:5)
Block(4,1,-2,DARK_OAK_STAIRS:5)
Block(4,1,-1,DARK_OAK_STAIRS:5)
Block(4,1,0,DARK_OAK_STAIRS:5)
Block(4,2,-6,SPRUCE_FENCE:0)
RandomBlock(4,2,-5,DARK_OAK_FENCE:0,30,STONE:6,100)
RandomBlock(4,2,-4,DARK_OAK_FENCE:0,30,STONE:6,100)
Block(4,2,-3,SPRUCE_FENCE:0)
RandomBlock(4,2,-2,DARK_OAK_FENCE:0,30,STONE:6,100)
RandomBlock(4,2,-1,DARK_OAK_FENCE:0,30,STONE:6,100)
Block(4,2,0,SPRUCE_FENCE:0)
Block(4,3,-6,SPRUCE_FENCE:0)
RandomBlock(4,3,-5,DARK_OAK_FENCE:0,30,STONE:6,100)
RandomBlock(4,3,-4,DARK_OAK_FENCE:0,30,STONE:6,100)
Block(4,3,-3,SPRUCE_FENCE:0)
RandomBlock(4,3,-2,DARK_OAK_FENCE:0,30,STONE:6,100)
RandomBlock(4,3,-1,DARK_OAK_FENCE:0,30,STONE:6,100)
Block(4,3,0,SPRUCE_FENCE:0)
Block(4,4,-6,WOOD:1)
RandomBlock(4,4,-5,DARK_OAK_FENCE:0,30,STONE:6,100)
RandomBlock(4,4,-4,DARK_OAK_FENCE:0,30,STONE:6,100)
Block(4,4,-3,WOOD:1)
RandomBlock(4,4,-2,DARK_OAK_FENCE:0,30,STONE:6,100)
RandomBlock(4,4,-1,DARK_OAK_FENCE:0,30,STONE:6,100)
Block(4,4,0,WOOD:1)
Block(8,750,-6,AIR:0)
Branch(0,-7,0,true,Mineshaft-N-S-Foundation,NORTH,100.0,0)
Branch(0,-10,0,false,Mineshaft-N-S-Foundation-Ext,NORTH,100.0,0)
Branch(0,-13,0,false,Mineshaft-N-S-Foundation-Ext,NORTH,100.0,0)
Branch(0,-16,0,false,Mineshaft-N-S-Foundation-Ext,NORTH,100.0,0)
Branch(0,-19,0,false,Mineshaft-N-S-Foundation-Ext,NORTH,100.0,0)
Branch(0,-22,0,false,Mineshaft-N-S-Foundation-Ext,NORTH,100.0,0)
Branch(0,-25,0,false,Mineshaft-N-S-Foundation-Ext,NORTH,100.0,0)
Entity(1,2,1,minecraft:villager,1)
