Author: NLBlackEagle
Description: No description given
SettingsMode: WriteDisable
Frequency: 0
SpawnHeight: highestBlock
UseCenterForHighestBlock: true
MinHeight: 0
MaxHeight: 255
InheritBO3: 
InheritBO3Rotation: NORTH
OverrideChildSettings: true
OverrideParentHeight: false
CanOverride: false
BranchFrequency: 0
BranchFrequencyGroup: 
MustBeBelowOther: false
MustBeInside: 
CannotBeInside: 
ReplacesBO3: 
MustBeInsideWorldBorders: false
CanSpawnOnWater: true
SpawnOnWaterOnly: false
SpawnUnderWater: false
SpawnAtWaterLevel: false
HeightOffset: 0
RemoveAir: false
ReplaceAbove: 
ReplaceBelow: 
ReplaceWithBiomeBlocks: true
ReplaceWithSurfaceBlock: GRASS
ReplaceWithGroundBlock: DIRT
ReplaceWithStoneBlock: STONE
SmoothRadius: 0
SmoothHeightOffset: 0
SmoothStartTop: false
SmoothStartWood: false
SmoothingSurfaceBlock: 
SmoothingGroundBlock: 
BO3Group: MineVillageHub:1
IsSpawnPoint: false
DoReplaceBlocks: true
Block(-7,0,-6,LOG:1)
Block(-7,0,0,LOG:1)
Block(-7,0,3,LOG:1)
Block(-7,0,9,LOG:1)
Block(-7,1,-6,WOOD:5)
Block(-7,1,-5,WOOD:5)
Block(-7,1,-4,WOOD:5)
Block(-7,1,-3,WOOD:5)
Block(-7,1,-2,WOOD:5)
Block(-7,1,-1,WOOD:5)
Block(-7,1,0,WOOD:5)
Block(-7,1,1,WOOD:5)
Block(-7,1,2,WOOD:5)
Block(-7,1,3,WOOD:5)
Block(-7,1,4,WOOD:5)
Block(-7,1,5,WOOD:5)
Block(-7,1,6,WOOD:5)
Block(-7,1,7,WOOD:5)
Block(-7,1,8,WOOD:5)
Block(-7,1,9,WOOD:5)
Block(-7,2,-4,SPRUCE_FENCE:0)
Block(-7,2,-3,SMOOTH_BRICK:0)
RandomBlock(-7,2,-2,DARK_OAK_FENCE:0,30,STONE:6,100)
Block(-7,2,-1,SMOOTH_BRICK:0)
Block(-7,2,0,DARK_OAK_STAIRS:2)
Block(-7,2,1,SPRUCE_DOOR:2)
Block(-7,2,2,SPRUCE_DOOR:2)
Block(-7,2,3,DARK_OAK_STAIRS:3)
Block(-7,2,4,SMOOTH_BRICK:0)
RandomBlock(-7,2,5,DARK_OAK_FENCE:0,30,STONE:6,100)
Block(-7,2,6,SMOOTH_BRICK:0)
Block(-7,2,7,SPRUCE_FENCE:0)
Block(-7,3,-4,SPRUCE_FENCE:0)
Block(-7,3,-3,SMOOTH_BRICK:0)
RandomBlock(-7,3,-2,DARK_OAK_FENCE:0,30,STONE:6,100)
Block(-7,3,-1,SMOOTH_BRICK:0)
Block(-7,3,0,DARK_OAK_STAIRS:6)
Block(-7,3,1,SPRUCE_DOOR:9)
Block(-7,3,2,SPRUCE_DOOR:8)
Block(-7,3,3,DARK_OAK_STAIRS:7)
Block(-7,3,4,SMOOTH_BRICK:0)
RandomBlock(-7,3,5,DARK_OAK_FENCE:0,30,STONE:6,100)
Block(-7,3,6,SMOOTH_BRICK:0)
Block(-7,3,7,SPRUCE_FENCE:0)
Block(-7,4,-4,WOOD:1)
Block(-7,4,-3,SMOOTH_BRICK:0)
RandomBlock(-7,4,-2,DARK_OAK_FENCE:0,30,STONE:6,100)
Block(-7,4,-1,SMOOTH_BRICK:0)
Block(-7,4,0,WOOD:1)
Block(-7,4,1,WOOD:1)
Block(-7,4,2,WOOD:1)
Block(-7,4,3,WOOD:1)
Block(-7,4,4,SMOOTH_BRICK:0)
RandomBlock(-7,4,5,DARK_OAK_FENCE:0,30,STONE:6,100)
Block(-7,4,6,SMOOTH_BRICK:0)
Block(-7,4,7,WOOD:1)
Block(-7,5,-4,SPRUCE_FENCE:0)
Block(-7,5,-3,SMOOTH_BRICK:0)
RandomBlock(-7,5,-2,DARK_OAK_FENCE:0,30,STONE:6,100)
Block(-7,5,-1,SMOOTH_BRICK:0)
Block(-7,5,0,SPRUCE_FENCE:0)
RandomBlock(-7,5,1,DARK_OAK_FENCE:0,30,STONE:6,100)
RandomBlock(-7,5,2,DARK_OAK_FENCE:0,30,STONE:6,100)
Block(-7,5,3,SPRUCE_FENCE:0)
Block(-7,5,4,SMOOTH_BRICK:0)
RandomBlock(-7,5,5,DARK_OAK_FENCE:0,30,STONE:6,100)
Block(-7,5,6,SMOOTH_BRICK:0)
Block(-7,5,7,SPRUCE_FENCE:0)
Block(-7,6,-4,WOOD:5)
Block(-7,6,-3,WOOD:5)
Block(-7,6,-2,WOOD:5)
Block(-7,6,-1,WOOD:5)
Block(-7,6,0,WOOD:5)
Block(-7,6,1,WOOD_STEP:13)
Block(-7,6,2,WOOD_STEP:13)
Block(-7,6,3,WOOD:5)
Block(-7,6,4,WOOD:5)
Block(-7,6,5,WOOD:5)
Block(-7,6,6,WOOD:5)
Block(-7,6,7,WOOD:5)
Block(-7,7,-4,SPRUCE_FENCE:0)
Block(-7,7,-3,SMOOTH_BRICK:0)
RandomBlock(-7,7,-2,DARK_OAK_FENCE:0,30,STONE:6,100)
Block(-7,7,-1,SMOOTH_BRICK:0)
Block(-7,7,0,STONE:6)
Block(-7,7,1,SPRUCE_DOOR:0)
Block(-7,7,2,SPRUCE_DOOR:0)
Block(-7,7,3,STONE:6)
Block(-7,7,4,SMOOTH_BRICK:0)
RandomBlock(-7,7,5,DARK_OAK_FENCE:0,30,STONE:6,100)
Block(-7,7,6,SMOOTH_BRICK:0)
Block(-7,7,7,SPRUCE_FENCE:0)
Block(-7,8,-4,SPRUCE_FENCE:0)
Block(-7,8,-3,SMOOTH_BRICK:0)
RandomBlock(-7,8,-2,DARK_OAK_FENCE:0,30,STONE:6,100)
Block(-7,8,-1,SMOOTH_BRICK:0)
Block(-7,8,0,STONE:6)
Block(-7,8,1,SPRUCE_DOOR:8)
Block(-7,8,2,SPRUCE_DOOR:9)
Block(-7,8,3,STONE:6)
Block(-7,8,4,SMOOTH_BRICK:0)
RandomBlock(-7,8,5,DARK_OAK_FENCE:0,30,STONE:6,100)
Block(-7,8,6,SMOOTH_BRICK:0)
Block(-7,8,7,SPRUCE_FENCE:0)
Block(-7,9,-4,WOOD:1)
Block(-7,9,-3,SMOOTH_BRICK:0)
RandomBlock(-7,9,-2,DARK_OAK_FENCE:0,30,STONE:6,100)
Block(-7,9,-1,SMOOTH_BRICK:0)
Block(-7,9,0,WOOD:1)
Block(-7,9,1,WOOD:1)
Block(-7,9,2,WOOD:1)
Block(-7,9,3,WOOD:1)
Block(-7,9,4,SMOOTH_BRICK:0)
RandomBlock(-7,9,5,DARK_OAK_FENCE:0,30,STONE:6,100)
Block(-7,9,6,SMOOTH_BRICK:0)
Block(-7,9,7,WOOD:1)
Block(-7,10,-4,SPRUCE_FENCE:0)
Block(-7,10,-3,SMOOTH_BRICK:0)
RandomBlock(-7,10,-2,DARK_OAK_FENCE:0,30,STONE:6,100)
Block(-7,10,-1,SMOOTH_BRICK:0)
Block(-7,10,0,SPRUCE_FENCE:0)
RandomBlock(-7,10,1,DARK_OAK_FENCE:0,30,STONE:6,100)
RandomBlock(-7,10,2,DARK_OAK_FENCE:0,30,STONE:6,100)
Block(-7,10,3,SPRUCE_FENCE:0)
Block(-7,10,4,SMOOTH_BRICK:0)
RandomBlock(-7,10,5,DARK_OAK_FENCE:0,30,STONE:6,100)
Block(-7,10,6,SMOOTH_BRICK:0)
Block(-7,10,7,SPRUCE_FENCE:0)
Block(-7,11,-4,WOOD:5)
Block(-7,11,-3,WOOD:5)
Block(-7,11,-2,WOOD:5)
Block(-7,11,-1,WOOD:5)
Block(-7,11,0,WOOD:5)
Block(-7,11,1,WOOD_STEP:13)
Block(-7,11,2,WOOD_STEP:13)
Block(-7,11,3,WOOD:5)
Block(-7,11,4,WOOD:5)
Block(-7,11,5,WOOD:5)
Block(-7,11,6,WOOD:5)
Block(-7,11,7,WOOD:5)
Block(-7,12,-4,SPRUCE_FENCE:0)
Block(-7,12,-3,SMOOTH_BRICK:0)
RandomBlock(-7,12,-2,DARK_OAK_FENCE:0,30,STONE:6,100)
Block(-7,12,-1,SMOOTH_BRICK:0)
Block(-7,12,0,SPRUCE_FENCE:0)
Block(-7,12,1,AIR:0)
Block(-7,12,2,AIR:0)
Block(-7,12,3,SPRUCE_FENCE:0)
Block(-7,12,4,SMOOTH_BRICK:0)
RandomBlock(-7,12,5,DARK_OAK_FENCE:0,30,STONE:6,100)
Block(-7,12,6,SMOOTH_BRICK:0)
Block(-7,12,7,SPRUCE_FENCE:0)
Block(-7,13,-4,SPRUCE_FENCE:0)
Block(-7,13,-3,SMOOTH_BRICK:0)
RandomBlock(-7,13,-2,DARK_OAK_FENCE:0,30,STONE:6,100)
Block(-7,13,-1,SMOOTH_BRICK:0)
Block(-7,13,0,SPRUCE_FENCE:0)
Block(-7,13,1,AIR:0)
Block(-7,13,2,AIR:0)
Block(-7,13,3,SPRUCE_FENCE:0)
Block(-7,13,4,SMOOTH_BRICK:0)
RandomBlock(-7,13,5,DARK_OAK_FENCE:0,30,STONE:6,100)
Block(-7,13,6,SMOOTH_BRICK:0)
Block(-7,13,7,SPRUCE_FENCE:0)
Block(-7,14,-4,WOOD:1)
Block(-7,14,-3,SMOOTH_BRICK:0)
RandomBlock(-7,14,-2,DARK_OAK_FENCE:0,30,STONE:6,100)
Block(-7,14,-1,SMOOTH_BRICK:0)
Block(-7,14,0,WOOD:1)
Block(-7,14,1,WOOD:1)
Block(-7,14,2,WOOD:1)
Block(-7,14,3,WOOD:1)
Block(-7,14,4,SMOOTH_BRICK:0)
RandomBlock(-7,14,5,DARK_OAK_FENCE:0,30,STONE:6,100)
Block(-7,14,6,SMOOTH_BRICK:0)
Block(-7,14,7,WOOD:1)
Block(-7,15,-4,WOOD:5)
Block(-7,15,-3,WOOD:5)
Block(-7,15,-2,WOOD:5)
Block(-7,15,-1,WOOD:5)
Block(-7,15,0,WOOD:5)
Block(-7,15,1,WOOD:5)
Block(-7,15,2,WOOD:5)
Block(-7,15,3,WOOD:5)
Block(-7,15,4,WOOD:5)
Block(-7,15,5,WOOD:5)
Block(-7,15,6,WOOD:5)
Block(-7,15,7,WOOD:5)
Block(-6,1,-6,WOOD:5)
Block(-6,1,-5,WOOD:5)
Block(-6,1,-4,WOOD:5)
Block(-6,1,-3,WOOD:5)
Block(-6,1,-2,WOOD:5)
Block(-6,1,-1,WOOD:5)
Block(-6,1,0,WOOD:5)
Block(-6,1,1,WOOD:5)
Block(-6,1,2,WOOD:5)
Block(-6,1,3,WOOD:5)
Block(-6,1,4,WOOD:5)
Block(-6,1,5,WOOD:5)
Block(-6,1,6,WOOD:5)
Block(-6,1,7,WOOD:5)
Block(-6,1,8,WOOD:5)
Block(-6,1,9,WOOD:5)
RandomBlock(-6,2,-5,DARK_OAK_FENCE:0,30,STONE:6,100)
RandomBlock(-6,2,-4,DARK_OAK_FENCE:0,30,STONE:6,100)
Block(-6,2,-3,BOOKSHELF:0)
Block(-6,2,-2,BOOKSHELF:0)
Block(-6,2,-1,SPRUCE_FENCE:0)
Block(-6,2,0,AIR:0)
Block(-6,2,1,AIR:0)
Block(-6,2,2,AIR:0)
Block(-6,2,3,AIR:0)
Block(-6,2,4,SPRUCE_FENCE:0)
Block(-6,2,5,AIR:0)
Block(-6,2,6,AIR:0)
RandomBlock(-6,2,7,DARK_OAK_FENCE:0,30,STONE:6,100)
RandomBlock(-6,2,8,DARK_OAK_FENCE:0,30,STONE:6,100)
RandomBlock(-6,3,-5,DARK_OAK_FENCE:0,30,STONE:6,100)
RandomBlock(-6,3,-4,DARK_OAK_FENCE:0,30,STONE:6,100)
Block(-6,3,-3,BOOKSHELF:0)
Block(-6,3,-2,BOOKSHELF:0)
Block(-6,3,-1,TORCH:5)
Block(-6,3,0,AIR:0)
Block(-6,3,1,AIR:0)
Block(-6,3,2,AIR:0)
Block(-6,3,3,AIR:0)
Block(-6,3,4,TORCH:5)
Block(-6,3,5,AIR:0)
Block(-6,3,6,AIR:0)
RandomBlock(-6,3,7,DARK_OAK_FENCE:0,30,STONE:6,100)
RandomBlock(-6,3,8,DARK_OAK_FENCE:0,30,STONE:6,100)
Block(-6,4,-5,WOOD:1)
RandomBlock(-6,4,-4,DARK_OAK_FENCE:0,30,STONE:6,100)
Block(-6,4,-3,BOOKSHELF:0)
Block(-6,4,-2,AIR:0)
Block(-6,4,-1,AIR:0)
Block(-6,4,0,AIR:0)
Block(-6,4,1,AIR:0)
Block(-6,4,2,AIR:0)
Block(-6,4,3,AIR:0)
Block(-6,4,4,AIR:0)
Block(-6,4,5,AIR:0)
Block(-6,4,6,AIR:0)
RandomBlock(-6,4,7,DARK_OAK_FENCE:0,30,STONE:6,100)
Block(-6,4,8,WOOD:1)
RandomBlock(-6,5,-5,DARK_OAK_FENCE:0,30,STONE:6,100)
RandomBlock(-6,5,-4,DARK_OAK_FENCE:0,30,STONE:6,100)
Block(-6,5,-3,AIR:0)
Block(-6,5,-2,AIR:0)
RandomBlock(-6,5,-1,WALL_BANNER:5,../../NBT/Banners/banner_sun.nbt,50,WALL_BANNER:5,../../NBT/Banners/quarry_banner_0.nbt,10,WALL_BANNER:5,../../NBT/Banners/quarry_banner_1.nbt,10,WALL_BANNER:5,../../NBT/Banners/quarry_banner_2.nbt,10,WALL_BANNER:5,../../NBT/Banners/quarry_banner_3.nbt,10,WALL_BANNER:5,../../NBT/Banners/quarry_banner_4.nbt,100)
Block(-6,5,0,AIR:0)
Block(-6,5,1,AIR:0)
Block(-6,5,2,AIR:0)
Block(-6,5,3,AIR:0)
RandomBlock(-6,5,4,WALL_BANNER:5,../../NBT/Banners/banner_sun.nbt,50,WALL_BANNER:5,../../NBT/Banners/quarry_banner_0.nbt,10,WALL_BANNER:5,../../NBT/Banners/quarry_banner_1.nbt,10,WALL_BANNER:5,../../NBT/Banners/quarry_banner_2.nbt,10,WALL_BANNER:5,../../NBT/Banners/quarry_banner_3.nbt,10,WALL_BANNER:5,../../NBT/Banners/quarry_banner_4.nbt,100)
Block(-6,5,5,AIR:0)
Block(-6,5,6,AIR:0)
RandomBlock(-6,5,7,DARK_OAK_FENCE:0,30,STONE:6,100)
RandomBlock(-6,5,8,DARK_OAK_FENCE:0,30,STONE:6,100)
Block(-6,6,-5,WOOD_DOUBLE_STEP:5)
Block(-6,6,-4,WOOD_DOUBLE_STEP:5)
Block(-6,6,-3,WOOD_STEP:13)
Block(-6,6,-2,WOOD_STEP:13)
Block(-6,6,-1,WOOD_STEP:13)
Block(-6,6,0,WOOD:5)
Block(-6,6,1,WOOD_STEP:13)
Block(-6,6,2,WOOD_STEP:13)
Block(-6,6,3,WOOD:5)
Block(-6,6,4,WOOD_STEP:13)
Block(-6,6,5,WOOD_STEP:13)
Block(-6,6,6,WOOD_STEP:13)
Block(-6,6,7,WOOD_DOUBLE_STEP:5)
Block(-6,6,8,WOOD_DOUBLE_STEP:5)
RandomBlock(-6,7,-5,DARK_OAK_FENCE:0,30,STONE:6,100)
RandomBlock(-6,7,-4,DARK_OAK_FENCE:0,30,STONE:6,100)
Block(-6,7,-3,AIR:0)
Block(-6,7,-2,AIR:0)
Block(-6,7,-1,SPRUCE_FENCE:0)
Block(-6,7,0,AIR:0)
Block(-6,7,1,AIR:0)
Block(-6,7,2,AIR:0)
Block(-6,7,3,AIR:0)
Block(-6,7,4,SPRUCE_FENCE:0)
Block(-6,7,5,AIR:0)
RandomBlock(-6,7,7,DARK_OAK_FENCE:0,30,STONE:6,100)
RandomBlock(-6,7,8,DARK_OAK_FENCE:0,30,STONE:6,100)
RandomBlock(-6,8,-5,DARK_OAK_FENCE:0,30,STONE:6,100)
RandomBlock(-6,8,-4,DARK_OAK_FENCE:0,30,STONE:6,100)
Block(-6,8,-3,AIR:0)
Block(-6,8,-2,AIR:0)
Block(-6,8,-1,TORCH:5)
Block(-6,8,0,AIR:0)
Block(-6,8,1,AIR:0)
Block(-6,8,2,AIR:0)
Block(-6,8,3,AIR:0)
Block(-6,8,4,TORCH:5)
Block(-6,8,5,AIR:0)
Block(-6,8,6,AIR:0)
RandomBlock(-6,8,7,DARK_OAK_FENCE:0,30,STONE:6,100)
RandomBlock(-6,8,8,DARK_OAK_FENCE:0,30,STONE:6,100)
Block(-6,9,-5,WOOD:1)
RandomBlock(-6,9,-4,DARK_OAK_FENCE:0,30,STONE:6,100)
Block(-6,9,-3,AIR:0)
Block(-6,9,-2,AIR:0)
Block(-6,9,-1,AIR:0)
Block(-6,9,0,AIR:0)
Block(-6,9,1,AIR:0)
Block(-6,9,2,AIR:0)
Block(-6,9,3,AIR:0)
Block(-6,9,4,AIR:0)
Block(-6,9,5,AIR:0)
Block(-6,9,6,AIR:0)
RandomBlock(-6,9,7,DARK_OAK_FENCE:0,30,STONE:6,100)
Block(-6,9,8,WOOD:1)
RandomBlock(-6,10,-5,DARK_OAK_FENCE:0,30,STONE:6,100)
RandomBlock(-6,10,-4,DARK_OAK_FENCE:0,30,STONE:6,100)
Block(-6,10,-3,AIR:0)
Block(-6,10,-2,AIR:0)
RandomBlock(-6,10,-1,WALL_BANNER:5,../../NBT/Banners/banner_sun.nbt,50,WALL_BANNER:5,../../NBT/Banners/quarry_banner_0.nbt,10,WALL_BANNER:5,../../NBT/Banners/quarry_banner_1.nbt,10,WALL_BANNER:5,../../NBT/Banners/quarry_banner_2.nbt,10,WALL_BANNER:5,../../NBT/Banners/quarry_banner_3.nbt,10,WALL_BANNER:5,../../NBT/Banners/quarry_banner_4.nbt,100)
Block(-6,10,0,AIR:0)
Block(-6,10,1,AIR:0)
Block(-6,10,2,AIR:0)
Block(-6,10,3,AIR:0)
RandomBlock(-6,10,4,WALL_BANNER:5,../../NBT/Banners/banner_sun.nbt,50,WALL_BANNER:5,../../NBT/Banners/quarry_banner_0.nbt,10,WALL_BANNER:5,../../NBT/Banners/quarry_banner_1.nbt,10,WALL_BANNER:5,../../NBT/Banners/quarry_banner_2.nbt,10,WALL_BANNER:5,../../NBT/Banners/quarry_banner_3.nbt,10,WALL_BANNER:5,../../NBT/Banners/quarry_banner_4.nbt,100)
Block(-6,10,5,AIR:0)
Block(-6,10,6,AIR:0)
RandomBlock(-6,10,7,DARK_OAK_FENCE:0,30,STONE:6,100)
RandomBlock(-6,10,8,DARK_OAK_FENCE:0,30,STONE:6,100)
Block(-6,11,-5,WOOD_DOUBLE_STEP:5)
Block(-6,11,-4,WOOD_DOUBLE_STEP:5)
Block(-6,11,-3,WOOD_STEP:13)
Block(-6,11,-2,WOOD_STEP:13)
Block(-6,11,-1,WOOD_STEP:13)
Block(-6,11,0,WOOD:5)
Block(-6,11,1,WOOD_STEP:13)
Block(-6,11,2,WOOD_STEP:13)
Block(-6,11,3,WOOD:5)
Block(-6,11,4,WOOD_STEP:13)
Block(-6,11,5,WOOD_STEP:13)
Block(-6,11,6,WOOD_STEP:13)
Block(-6,11,7,WOOD_DOUBLE_STEP:5)
Block(-6,11,8,WOOD_DOUBLE_STEP:5)
RandomBlock(-6,12,-5,DARK_OAK_FENCE:0,30,STONE:6,100)
RandomBlock(-6,12,-4,DARK_OAK_FENCE:0,30,STONE:6,100)
Block(-6,12,-3,COAL_ORE:0)
Block(-6,12,-2,COAL_ORE:0)
Block(-6,12,-1,SPRUCE_FENCE:0)
Block(-6,12,0,AIR:0)
Block(-6,12,1,AIR:0)
Block(-6,12,2,AIR:0)
Block(-6,12,3,AIR:0)
Block(-6,12,4,SPRUCE_FENCE:0)
Block(-6,12,5,AIR:0)
Block(-6,12,6,AIR:0)
RandomBlock(-6,12,7,DARK_OAK_FENCE:0,30,STONE:6,100)
RandomBlock(-6,12,8,DARK_OAK_FENCE:0,30,STONE:6,100)
RandomBlock(-6,13,-5,DARK_OAK_FENCE:0,30,STONE:6,100)
RandomBlock(-6,13,-4,DARK_OAK_FENCE:0,30,STONE:6,100)
RandomBlock(-6,13,-3,AIR:0,2,CHEST:5,../../../../Chests/Loot/mine_resources_01.nbt,10,CHEST:5,../../../../Chests/Loot/mine_resources_02.nbt,10,CHEST:5,../../../../Chests/Loot/mine_resources_03.nbt,10,CHEST:5,../../../../Chests/Loot/mine_resources_04.nbt,10,CHEST:5,../../../../Chests/Loot/mine_resources_05.nbt,10,CHEST:5,../../../../Chests/Loot/abandoned_mineshaft.nbt,10,CHEST:5,../../../../Chests/Loot/mine_resources_01.nbt,100)
Block(-6,13,-2,AIR:0)
Block(-6,13,-1,TORCH:5)
Block(-6,13,0,AIR:0)
Block(-6,13,1,AIR:0)
Block(-6,13,2,AIR:0)
Block(-6,13,3,AIR:0)
Block(-6,13,4,TORCH:5)
Block(-6,13,5,AIR:0)
Block(-6,13,6,AIR:0)
RandomBlock(-6,13,7,DARK_OAK_FENCE:0,30,STONE:6,100)
RandomBlock(-6,13,8,DARK_OAK_FENCE:0,30,STONE:6,100)
Block(-6,14,-5,WOOD:1)
RandomBlock(-6,14,-4,DARK_OAK_FENCE:0,30,STONE:6,100)
Block(-6,14,-3,AIR:0)
Block(-6,14,-2,AIR:0)
Block(-6,14,-1,AIR:0)
Block(-6,14,0,AIR:0)
Block(-6,14,1,AIR:0)
Block(-6,14,2,AIR:0)
Block(-6,14,3,AIR:0)
Block(-6,14,4,AIR:0)
Block(-6,14,5,AIR:0)
Block(-6,14,6,AIR:0)
RandomBlock(-6,14,7,DARK_OAK_FENCE:0,30,STONE:6,100)
Block(-6,14,8,WOOD:1)
Block(-6,15,-5,WOOD:5)
RandomBlock(-6,15,-4,DARK_OAK_FENCE:0,30,STONE:6,100)
Block(-6,15,-3,TRAP_DOOR:8)
Block(-6,15,-2,TRAP_DOOR:8)
Block(-6,15,-1,TRAP_DOOR:8)
Block(-6,15,0,WOOD:5)
Block(-6,15,1,TRAP_DOOR:8)
Block(-6,15,2,TRAP_DOOR:8)
Block(-6,15,3,WOOD:5)
Block(-6,15,4,TRAP_DOOR:8)
Block(-6,15,5,TRAP_DOOR:8)
Block(-6,15,6,TRAP_DOOR:8)
RandomBlock(-6,15,7,DARK_OAK_FENCE:0,30,STONE:6,100)
Block(-6,15,8,WOOD:5)
Block(-5,1,-6,WOOD:5)
Block(-5,1,-5,WOOD:5)
Block(-5,1,-4,WOOD:5)
Block(-5,1,-3,WOOD:5)
Block(-5,1,-2,WOOD:5)
Block(-5,1,-1,WOOD:5)
Block(-5,1,0,WOOD:5)
Block(-5,1,1,WOOD:5)
Block(-5,1,2,WOOD:5)
Block(-5,1,3,WOOD:5)
Block(-5,1,4,WOOD:5)
Block(-5,1,5,WOOD:5)
Block(-5,1,6,WOOD:5)
Block(-5,1,7,WOOD:5)
Block(-5,1,8,WOOD:5)
Block(-5,1,9,WOOD:5)
Block(-5,2,-6,SPRUCE_FENCE:0)
RandomBlock(-5,2,-5,DARK_OAK_FENCE:0,30,STONE:6,100)
Block(-5,2,-4,BOOKSHELF:0)
Block(-5,2,-2,AIR:0)
Block(-5,2,-1,AIR:0)
Block(-5,2,0,AIR:0)
Block(-5,2,1,AIR:0)
Block(-5,2,2,AIR:0)
Block(-5,2,3,AIR:0)
Block(-5,2,4,AIR:0)
Block(-5,2,5,AIR:0)
Block(-5,2,6,AIR:0)
Block(-5,2,7,AIR:0)
RandomBlock(-5,2,8,DARK_OAK_FENCE:0,30,STONE:6,100)
Block(-5,2,9,SPRUCE_FENCE:0)
Block(-5,3,-6,SPRUCE_FENCE:0)
RandomBlock(-5,3,-5,DARK_OAK_FENCE:0,30,STONE:6,100)
Block(-5,3,-4,BOOKSHELF:0)
Block(-5,3,-3,AIR:0)
Block(-5,3,-2,AIR:0)
Block(-5,3,-1,AIR:0)
Block(-5,3,0,AIR:0)
Block(-5,3,1,AIR:0)
Block(-5,3,2,AIR:0)
Block(-5,3,3,AIR:0)
Block(-5,3,4,AIR:0)
Block(-5,3,5,AIR:0)
Block(-5,3,6,AIR:0)
Block(-5,3,7,AIR:0)
RandomBlock(-5,3,8,DARK_OAK_FENCE:0,30,STONE:6,100)
Block(-5,3,9,SPRUCE_FENCE:0)
Block(-5,4,-6,WOOD:1)
RandomBlock(-5,4,-5,DARK_OAK_FENCE:0,30,STONE:6,100)
Block(-5,4,-4,AIR:0)
Block(-5,4,-3,AIR:0)
Block(-5,4,-2,AIR:0)
Block(-5,4,-1,AIR:0)
Block(-5,4,0,AIR:0)
Block(-5,4,1,AIR:0)
Block(-5,4,2,AIR:0)
Block(-5,4,3,AIR:0)
Block(-5,4,4,AIR:0)
Block(-5,4,5,AIR:0)
Block(-5,4,6,AIR:0)
Block(-5,4,7,AIR:0)
RandomBlock(-5,4,8,DARK_OAK_FENCE:0,30,STONE:6,100)
Block(-5,4,9,WOOD:1)
Block(-5,5,-6,SPRUCE_FENCE:0)
RandomBlock(-5,5,-5,DARK_OAK_FENCE:0,30,STONE:6,100)
Block(-5,5,-4,AIR:0)
Block(-5,5,-3,AIR:0)
Block(-5,5,-2,AIR:0)
Block(-5,5,-1,AIR:0)
Block(-5,5,0,AIR:0)
Block(-5,5,1,AIR:0)
Block(-5,5,2,AIR:0)
Block(-5,5,3,AIR:0)
Block(-5,5,4,AIR:0)
Block(-5,5,5,AIR:0)
Block(-5,5,6,AIR:0)
Block(-5,5,7,AIR:0)
RandomBlock(-5,5,8,DARK_OAK_FENCE:0,30,STONE:6,100)
Block(-5,5,9,SPRUCE_FENCE:0)
Block(-5,6,-6,WOOD:5)
Block(-5,6,-5,WOOD_DOUBLE_STEP:5)
Block(-5,6,-4,WOOD_STEP:13)
Block(-5,6,-3,WOOD_STEP:13)
Block(-5,6,-2,WOOD_STEP:13)
Block(-5,6,-1,WOOD_STEP:13)
Block(-5,6,0,WOOD:5)
Block(-5,6,1,WOOD_STEP:13)
Block(-5,6,2,WOOD_STEP:13)
Block(-5,6,3,WOOD:5)
Block(-5,6,4,WOOD_STEP:13)
Block(-5,6,5,WOOD_STEP:13)
Block(-5,6,6,WOOD_STEP:13)
Block(-5,6,7,WOOD_STEP:13)
Block(-5,6,8,WOOD_DOUBLE_STEP:5)
Block(-5,6,9,WOOD:5)
Block(-5,7,-6,SPRUCE_FENCE:0)
RandomBlock(-5,7,-5,DARK_OAK_FENCE:0,30,STONE:6,100)
Block(-5,7,-4,AIR:0)
Block(-5,7,-3,CARPET:13)
Block(-5,7,-2,AIR:0)
Block(-5,7,-1,CARPET:13)
Block(-5,7,0,AIR:0)
Block(-5,7,1,AIR:0)
Block(-5,7,2,CARPET:13)
Block(-5,7,3,CARPET:13)
Block(-5,7,4,AIR:0)
Block(-5,7,5,AIR:0)
Block(-5,7,6,AIR:0)
Block(-5,7,7,AIR:0)
RandomBlock(-5,7,8,DARK_OAK_FENCE:0,30,STONE:6,100)
Block(-5,7,9,SPRUCE_FENCE:0)
Block(-5,8,-6,SPRUCE_FENCE:0)
RandomBlock(-5,8,-5,DARK_OAK_FENCE:0,30,STONE:6,100)
Block(-5,8,-4,AIR:0)
Block(-5,8,-3,AIR:0)
Block(-5,8,-2,AIR:0)
Block(-5,8,-1,AIR:0)
Block(-5,8,0,AIR:0)
Block(-5,8,1,AIR:0)
Block(-5,8,2,AIR:0)
Block(-5,8,3,AIR:0)
Block(-5,8,4,AIR:0)
Block(-5,8,5,AIR:0)
Block(-5,8,6,AIR:0)
Block(-5,8,7,AIR:0)
RandomBlock(-5,8,8,DARK_OAK_FENCE:0,30,STONE:6,100)
Block(-5,8,9,SPRUCE_FENCE:0)
Block(-5,9,-6,WOOD:1)
RandomBlock(-5,9,-5,DARK_OAK_FENCE:0,30,STONE:6,100)
Block(-5,9,-4,AIR:0)
Block(-5,9,-3,AIR:0)
Block(-5,9,-2,AIR:0)
Block(-5,9,-1,AIR:0)
Block(-5,9,0,AIR:0)
Block(-5,9,1,AIR:0)
Block(-5,9,2,AIR:0)
Block(-5,9,3,AIR:0)
Block(-5,9,4,AIR:0)
Block(-5,9,5,AIR:0)
Block(-5,9,6,AIR:0)
Block(-5,9,7,AIR:0)
RandomBlock(-5,9,8,DARK_OAK_FENCE:0,30,STONE:6,100)
Block(-5,9,9,WOOD:1)
Block(-5,10,-6,SPRUCE_FENCE:0)
RandomBlock(-5,10,-5,DARK_OAK_FENCE:0,30,STONE:6,100)
Block(-5,10,-4,AIR:0)
Block(-5,10,-3,AIR:0)
Block(-5,10,-2,AIR:0)
Block(-5,10,-1,AIR:0)
Block(-5,10,0,AIR:0)
Block(-5,10,1,AIR:0)
Block(-5,10,2,AIR:0)
Block(-5,10,3,AIR:0)
Block(-5,10,4,AIR:0)
Block(-5,10,5,AIR:0)
Block(-5,10,6,AIR:0)
Block(-5,10,7,AIR:0)
RandomBlock(-5,10,8,DARK_OAK_FENCE:0,30,STONE:6,100)
Block(-5,10,9,SPRUCE_FENCE:0)
Block(-5,11,-6,WOOD:5)
Block(-5,11,-5,WOOD_DOUBLE_STEP:5)
Block(-5,11,-4,WOOD_STEP:13)
Block(-5,11,-3,WOOD_STEP:13)
Block(-5,11,-2,WOOD_STEP:13)
Block(-5,11,-1,WOOD_STEP:13)
Block(-5,11,0,WOOD:5)
Block(-5,11,1,WOOD_STEP:13)
Block(-5,11,2,WOOD_STEP:13)
Block(-5,11,3,WOOD:5)
Block(-5,11,4,WOOD_STEP:13)
Block(-5,11,5,WOOD_STEP:13)
Block(-5,11,6,WOOD_STEP:13)
Block(-5,11,7,WOOD_STEP:13)
Block(-5,11,8,WOOD_DOUBLE_STEP:5)
Block(-5,11,9,WOOD:5)
Block(-5,12,-6,SPRUCE_FENCE:0)
RandomBlock(-5,12,-5,DARK_OAK_FENCE:0,30,STONE:6,100)
Block(-5,12,-4,COAL_ORE:0)
Block(-5,12,-3,COAL_ORE:0)
Block(-5,12,-2,AIR:0)
Block(-5,12,-1,AIR:0)
Block(-5,12,0,AIR:0)
Block(-5,12,1,AIR:0)
Block(-5,12,2,AIR:0)
Block(-5,12,3,AIR:0)
Block(-5,12,4,AIR:0)
Block(-5,12,5,AIR:0)
Block(-5,12,6,AIR:0)
Block(-5,12,7,HAY_BLOCK:0)
RandomBlock(-5,12,8,DARK_OAK_FENCE:0,30,STONE:6,100)
Block(-5,12,9,SPRUCE_FENCE:0)
Block(-5,13,-6,SPRUCE_FENCE:0)
RandomBlock(-5,13,-5,DARK_OAK_FENCE:0,30,STONE:6,100)
Block(-5,13,-4,COAL_ORE:0)
Block(-5,13,-3,AIR:0)
Block(-5,13,-2,AIR:0)
Block(-5,13,-1,AIR:0)
Block(-5,13,0,AIR:0)
Block(-5,13,1,AIR:0)
Block(-5,13,2,AIR:0)
Block(-5,13,3,AIR:0)
Block(-5,13,4,AIR:0)
Block(-5,13,5,AIR:0)
Block(-5,13,6,AIR:0)
Block(-5,13,7,HAY_BLOCK:0)
RandomBlock(-5,13,8,DARK_OAK_FENCE:0,30,STONE:6,100)
Block(-5,13,9,SPRUCE_FENCE:0)
Block(-5,14,-6,WOOD:1)
RandomBlock(-5,14,-5,DARK_OAK_FENCE:0,30,STONE:6,100)
Block(-5,14,-4,AIR:0)
Block(-5,14,-3,AIR:0)
Block(-5,14,-2,AIR:0)
Block(-5,14,-1,AIR:0)
Block(-5,14,0,AIR:0)
Block(-5,14,1,AIR:0)
Block(-5,14,2,AIR:0)
Block(-5,14,3,AIR:0)
Block(-5,14,4,AIR:0)
Block(-5,14,5,AIR:0)
Block(-5,14,6,AIR:0)
Block(-5,14,7,HAY_BLOCK:0)
RandomBlock(-5,14,8,DARK_OAK_FENCE:0,30,STONE:6,100)
Block(-5,14,9,WOOD:1)
Block(-5,15,-6,WOOD:5)
RandomBlock(-5,15,-5,DARK_OAK_FENCE:0,30,STONE:6,100)
Block(-5,15,-4,TRAP_DOOR:8)
Block(-5,15,-3,TRAP_DOOR:8)
Block(-5,15,-2,TRAP_DOOR:8)
Block(-5,15,-1,TRAP_DOOR:8)
Block(-5,15,0,WOOD:5)
Block(-5,15,1,TRAP_DOOR:8)
Block(-5,15,2,TRAP_DOOR:8)
Block(-5,15,3,WOOD:5)
Block(-5,15,4,TRAP_DOOR:8)
Block(-5,15,5,TRAP_DOOR:8)
Block(-5,15,6,TRAP_DOOR:8)
Block(-5,15,7,TRAP_DOOR:8)
RandomBlock(-5,15,8,DARK_OAK_FENCE:0,30,STONE:6,100)
Block(-5,15,9,WOOD:5)
Block(-4,1,-6,WOOD:5)
Block(-4,1,-5,WOOD:5)
Block(-4,1,-4,WOOD:5)
Block(-4,1,-3,WOOD:5)
Block(-4,1,-2,WOOD:5)
Block(-4,1,-1,WOOD:5)
Block(-4,1,0,WOOD:5)
Block(-4,1,1,WOOD:5)
Block(-4,1,2,WOOD:5)
Block(-4,1,3,WOOD:5)
Block(-4,1,4,WOOD:5)
Block(-4,1,5,WOOD:5)
Block(-4,1,6,WOOD:5)
Block(-4,1,7,WOOD:5)
Block(-4,1,8,WOOD:5)
Block(-4,1,9,WOOD:5)
Block(-4,2,-6,SMOOTH_BRICK:0)
Block(-4,2,-5,BOOKSHELF:0)
Block(-4,2,-4,AIR:0)
Block(-4,2,-3,AIR:0)
Block(-4,2,-2,AIR:0)
Block(-4,2,-1,AIR:0)
Block(-4,2,0,AIR:0)
Block(-4,2,1,AIR:0)
Block(-4,2,2,AIR:0)
Block(-4,2,3,AIR:0)
Block(-4,2,4,AIR:0)
Block(-4,2,5,AIR:0)
Block(-4,2,6,AIR:0)
Block(-4,2,7,AIR:0)
Block(-4,2,8,AIR:0)
Block(-4,2,9,SMOOTH_BRICK:0)
Block(-4,3,-6,SMOOTH_BRICK:0)
Block(-4,3,-5,BOOKSHELF:0)
Block(-4,3,-4,AIR:0)
Block(-4,3,-3,AIR:0)
Block(-4,3,-2,AIR:0)
Block(-4,3,-1,AIR:0)
Block(-4,3,0,AIR:0)
Block(-4,3,1,AIR:0)
Block(-4,3,2,AIR:0)
Block(-4,3,3,AIR:0)
Block(-4,3,4,AIR:0)
Block(-4,3,5,AIR:0)
Block(-4,3,6,AIR:0)
Block(-4,3,7,AIR:0)
Block(-4,3,8,AIR:0)
Block(-4,3,9,SMOOTH_BRICK:0)
Block(-4,4,-6,SMOOTH_BRICK:0)
Block(-4,4,-5,AIR:0)
Block(-4,4,-4,AIR:0)
Block(-4,4,-3,AIR:0)
Block(-4,4,-2,AIR:0)
Block(-4,4,-1,AIR:0)
Block(-4,4,0,AIR:0)
Block(-4,4,1,AIR:0)
Block(-4,4,2,AIR:0)
Block(-4,4,3,AIR:0)
Block(-4,4,4,AIR:0)
Block(-4,4,5,AIR:0)
Block(-4,4,6,AIR:0)
Block(-4,4,7,AIR:0)
Block(-4,4,8,AIR:0)
Block(-4,4,9,SMOOTH_BRICK:0)
Block(-4,5,-6,SMOOTH_BRICK:0)
Block(-4,5,-5,AIR:0)
Block(-4,5,-4,AIR:0)
Block(-4,5,-3,AIR:0)
Block(-4,5,-2,AIR:0)
Block(-4,5,-1,AIR:0)
Block(-4,5,0,AIR:0)
Block(-4,5,1,AIR:0)
Block(-4,5,2,AIR:0)
Block(-4,5,3,AIR:0)
Block(-4,5,4,AIR:0)
Block(-4,5,5,AIR:0)
Block(-4,5,6,AIR:0)
Block(-4,5,7,AIR:0)
Block(-4,5,8,AIR:0)
Block(-4,5,9,SMOOTH_BRICK:0)
Block(-4,6,-6,WOOD:5)
Block(-4,6,-5,WOOD_STEP:13)
Block(-4,6,-4,WOOD_STEP:13)
Block(-4,6,-3,WOOD_STEP:13)
Block(-4,6,-2,WOOD_STEP:13)
Block(-4,6,-1,WOOD_STEP:13)
Block(-4,6,0,WOOD:5)
Block(-4,6,1,WOOD_STEP:13)
Block(-4,6,2,WOOD_STEP:13)
Block(-4,6,3,WOOD:5)
Block(-4,6,4,WOOD_STEP:13)
Block(-4,6,5,WOOD_STEP:13)
Block(-4,6,6,WOOD_STEP:13)
Block(-4,6,7,WOOD_STEP:13)
Block(-4,6,8,WOOD_STEP:13)
Block(-4,6,9,WOOD:5)
Block(-4,7,-6,SMOOTH_BRICK:0)
Block(-4,7,-5,AIR:0)
Block(-4,7,-4,CARPET:13)
Block(-4,7,-3,CARPET:13)
Block(-4,7,-2,CARPET:13)
Block(-4,7,-1,CARPET:13)
Block(-4,7,0,CARPET:13)
Block(-4,7,1,CARPET:13)
Block(-4,7,2,CARPET:13)
Block(-4,7,3,CARPET:13)
Block(-4,7,4,CARPET:13)
Block(-4,7,5,CARPET:13)
Block(-4,7,6,CARPET:13)
Block(-4,7,7,AIR:0)
Block(-4,7,8,AIR:0)
Block(-4,7,9,SMOOTH_BRICK:0)
Block(-4,8,-6,SMOOTH_BRICK:0)
Block(-4,8,-5,AIR:0)
Block(-4,8,-4,AIR:0)
Block(-4,8,-3,AIR:0)
Block(-4,8,-2,AIR:0)
Block(-4,8,-1,AIR:0)
Block(-4,8,0,AIR:0)
Block(-4,8,1,AIR:0)
Block(-4,8,2,AIR:0)
Block(-4,8,3,AIR:0)
Block(-4,8,4,AIR:0)
Block(-4,8,5,AIR:0)
Block(-4,8,6,AIR:0)
Block(-4,8,7,AIR:0)
Block(-4,8,8,AIR:0)
Block(-4,8,9,SMOOTH_BRICK:0)
Block(-4,9,-6,SMOOTH_BRICK:0)
Block(-4,9,-5,AIR:0)
Block(-4,9,-4,AIR:0)
Block(-4,9,-3,AIR:0)
Block(-4,9,-2,AIR:0)
Block(-4,9,-1,AIR:0)
Block(-4,9,0,AIR:0)
Block(-4,9,1,AIR:0)
Block(-4,9,2,AIR:0)
Block(-4,9,3,AIR:0)
Block(-4,9,4,AIR:0)
Block(-4,9,5,AIR:0)
Block(-4,9,6,AIR:0)
Block(-4,9,7,AIR:0)
Block(-4,9,8,AIR:0)
Block(-4,9,9,SMOOTH_BRICK:0)
Block(-4,10,-6,SMOOTH_BRICK:0)
Block(-4,10,-5,AIR:0)
Block(-4,10,-4,AIR:0)
Block(-4,10,-3,AIR:0)
Block(-4,10,-2,AIR:0)
Block(-4,10,-1,AIR:0)
Block(-4,10,0,AIR:0)
Block(-4,10,1,AIR:0)
Block(-4,10,2,AIR:0)
Block(-4,10,3,AIR:0)
Block(-4,10,4,AIR:0)
Block(-4,10,5,AIR:0)
Block(-4,10,6,AIR:0)
Block(-4,10,7,AIR:0)
Block(-4,10,8,AIR:0)
Block(-4,10,9,SMOOTH_BRICK:0)
Block(-4,11,-6,WOOD:5)
Block(-4,11,-5,WOOD_STEP:13)
Block(-4,11,-4,WOOD_STEP:13)
Block(-4,11,-3,WOOD_STEP:13)
Block(-4,11,-2,WOOD_STEP:13)
Block(-4,11,-1,WOOD_STEP:13)
Block(-4,11,0,WOOD:5)
Block(-4,11,1,WOOD_STEP:13)
Block(-4,11,2,WOOD_STEP:13)
Block(-4,11,3,WOOD:5)
Block(-4,11,4,WOOD_STEP:13)
Block(-4,11,5,WOOD_STEP:13)
Block(-4,11,6,WOOD_STEP:13)
Block(-4,11,7,WOOD_STEP:13)
Block(-4,11,8,WOOD_STEP:13)
Block(-4,11,9,WOOD:5)
Block(-4,12,-6,SMOOTH_BRICK:0)
Block(-4,12,-5,COAL_ORE:0)
Block(-4,12,-4,COAL_ORE:0)
Block(-4,12,-3,AIR:0)
Block(-4,12,-2,AIR:0)
Block(-4,12,-1,AIR:0)
Block(-4,12,0,AIR:0)
Block(-4,12,1,AIR:0)
Block(-4,12,2,AIR:0)
Block(-4,12,3,COAL_ORE:0)
Block(-4,12,4,COAL_ORE:0)
Block(-4,12,5,AIR:0)
Block(-4,12,6,AIR:0)
Block(-4,12,7,HAY_BLOCK:0)
Block(-4,12,8,HAY_BLOCK:0)
Block(-4,12,9,SMOOTH_BRICK:0)
Block(-4,13,-6,SMOOTH_BRICK:0)
Block(-4,13,-5,COAL_ORE:0)
Block(-4,13,-4,AIR:0)
Block(-4,13,-3,AIR:0)
Block(-4,13,-2,AIR:0)
Block(-4,13,-1,AIR:0)
Block(-4,13,0,AIR:0)
Block(-4,13,1,AIR:0)
Block(-4,13,2,AIR:0)
Block(-4,13,3,AIR:0)
Block(-4,13,4,AIR:0)
Block(-4,13,5,AIR:0)
Block(-4,13,6,AIR:0)
Block(-4,13,7,HAY_BLOCK:0)
Block(-4,13,8,HAY_BLOCK:8)
Block(-4,13,9,SMOOTH_BRICK:0)
Block(-4,14,-6,SMOOTH_BRICK:0)
Block(-4,14,-5,AIR:0)
Block(-4,14,-4,AIR:0)
Block(-4,14,-3,AIR:0)
Block(-4,14,-2,AIR:0)
Block(-4,14,-1,AIR:0)
Block(-4,14,0,AIR:0)
Block(-4,14,1,AIR:0)
Block(-4,14,2,AIR:0)
Block(-4,14,3,AIR:0)
Block(-4,14,4,AIR:0)
Block(-4,14,5,AIR:0)
Block(-4,14,6,AIR:0)
Block(-4,14,7,AIR:0)
Block(-4,14,8,HAY_BLOCK:8)
Block(-4,14,9,SMOOTH_BRICK:0)
Block(-4,15,-6,WOOD:5)
Block(-4,15,-5,TRAP_DOOR:8)
Block(-4,15,-4,TRAP_DOOR:8)
Block(-4,15,-3,TRAP_DOOR:8)
Block(-4,15,-2,TRAP_DOOR:8)
Block(-4,15,-1,TRAP_DOOR:8)
Block(-4,15,0,WOOD:5)
Block(-4,15,1,TRAP_DOOR:8)
Block(-4,15,2,TRAP_DOOR:8)
Block(-4,15,3,WOOD:5)
Block(-4,15,4,TRAP_DOOR:8)
Block(-4,15,5,TRAP_DOOR:8)
Block(-4,15,6,TRAP_DOOR:8)
Block(-4,15,7,TRAP_DOOR:8)
Block(-4,15,8,TRAP_DOOR:8)
Block(-4,15,9,WOOD:5)
Block(-3,1,-6,WOOD:5)
Block(-3,1,-5,WOOD:5)
Block(-3,1,-4,WOOD:5)
Block(-3,1,-3,WOOD:5)
Block(-3,1,-2,WOOD:5)
Block(-3,1,-1,WOOD:5)
Block(-3,1,0,WOOD:5)
Block(-3,1,1,WOOD:5)
Block(-3,1,2,WOOD:5)
Block(-3,1,3,WOOD:5)
Block(-3,1,4,WOOD:5)
Block(-3,1,5,WOOD:5)
Block(-3,1,6,WOOD:5)
Block(-3,1,7,WOOD:5)
Block(-3,1,8,WOOD:5)
Block(-3,1,9,WOOD:5)
RandomBlock(-3,2,-6,DARK_OAK_FENCE:0,30,STONE:6,100)
Block(-3,2,-5,BOOKSHELF:0)
Block(-3,2,-4,AIR:0)
Block(-3,2,-3,AIR:0)
Block(-3,2,-2,AIR:0)
Block(-3,2,-1,AIR:0)
Block(-3,2,0,SPRUCE_FENCE:0)
Block(-3,2,1,SPRUCE_FENCE:0)
Block(-3,2,2,SPRUCE_FENCE:0)
Block(-3,2,3,SPRUCE_FENCE:0)
Block(-3,2,4,SPRUCE_FENCE:0)
Block(-3,2,5,CAULDRON:3)
Block(-3,2,6,SPRUCE_FENCE:0)
Block(-3,2,7,SPRUCE_FENCE:0)
Block(-3,2,8,AIR:0)
RandomBlock(-3,2,9,DARK_OAK_FENCE:0,30,STONE:6,100)
RandomBlock(-3,3,-6,DARK_OAK_FENCE:0,30,STONE:6,100)
RandomBlock(-3,3,-5,AIR:0,20,CHEST:5,../../../../Chests/Loot/JunkChest_1.nbt,10,CHEST:5,../../../../Chests/Loot/JunkChest_2.nbt,10,CHEST:5,../../../../Chests/Loot/JunkChest_3.nbt,10,CHEST:5,../../../../Chests/Loot/JunkChest_4.nbt,10,CHEST:5,../../../../Chests/Loot/JunkChest_5.nbt,10,CHEST:5,../../../../Chests/Lore/HiddenMine_1.nbt,1,CHEST:5,../../../../Chests/Lore/HiddenMine_2.nbt,1,CHEST:5,../../../../Chests/Lore/HiddenMine_3.nbt,1,CHEST:5,../../../../Chests/Lore/HiddenMine_4.nbt,1,CHEST:5,../../../../Chests/Lore/HiddenMine_5.nbt,1,CHEST:5,../../../../Chests/Loot/Common1.nbt,10,CHEST:5,../../../../Chests/Loot/Common2.nbt,10,CHEST:5,../../../../Chests/Loot/Common3.nbt,10,CHEST:5,../../../../Chests/Loot/Common4.nbt,10,CHEST:5,../../../../Chests/Loot/Common5.nbt,10,CHEST:5,../../../../Chests/Loot/Common6.nbt,10,CHEST:5,../../../../Chests/Loot/Common7.nbt,10,CHEST:5,../../../../Chests/Loot/Common8.nbt,10,CHEST:5,../../../../Chests/Loot/Common9.nbt,10,CHEST:5,../../../../Chests/Loot/Common10.nbt,10,CHEST:5,../../../../Chests/Loot/Common10.nbt,11,CHEST:5,../../../../Chests/Loot/Common12.nbt,10,CHEST:5,../../../../Chests/Loot/Common13.nbt,10,CHEST:5,../../../../Chests/Loot/Common14.nbt,10,CHEST:5,../../../../Chests/Loot/Common15.nbt,10,CHEST:5,../../../../Chests/Lore/HiddenMine_1.nbt,2,CHEST:5,../../../../Chests/Lore/HiddenMine_3.nbt,2,CHEST:5,../../../../Chests/Lore/HiddenMine_4.nbt,2,CHEST:5,../../../../Chests/Lore/HiddenMine_5.nbt,2,CHEST:5,../../../../Chests/Lore/HiddenMine_5.nbt,2,CHEST:5,../../../../Chests/Loot/Rare1.nbt,5,CHEST:5,../../../../Chests/Loot/Rare2.nbt,5,CHEST:5,../../../../Chests/Loot/Rare3.nbt,5,CHEST:5,../../../../Chests/Loot/Rare4.nbt,5,CHEST:5,../../../../Chests/Loot/Rare5.nbt,5,CHEST:5,../../../../Chests/Loot/Rare6.nbt,5,CHEST:5,../../../../Chests/Loot/Rare7.nbt,5,CHEST:5,../../../../Chests/Loot/Rare8.nbt,5,CHEST:5,../../../../Chests/Loot/Rare9.nbt,5,CHEST:5,../../../../Chests/Loot/Rare10.nbt,5,CHEST:5,../../../../Chests/Loot/Rare11.nbt,5,CHEST:5,../../../../Chests/Loot/Rare12.nbt,5,CHEST:5,../../../../Chests/Loot/Rare13.nbt,5,CHEST:5,../../../../Chests/Loot/Rare14.nbt,5,CHEST:5,../../../../Chests/Loot/Rare15.nbt,5,CHEST:5,../../../../Chests/Loot/Epic1.nbt,2,CHEST:5,../../../../Chests/Loot/Epic2.nbt,2,CHEST:5,../../../../Chests/Loot/Epic3.nbt,2,CHEST:5,../../../../Chests/Loot/Epic4.nbt,2,CHEST:5,../../../../Chests/Loot/Epic5.nbt,2,CHEST:5,../../../../Chests/Loot/Epic6.nbt,2,CHEST:5,../../../../Chests/Loot/Epic7.nbt,2,CHEST:5,../../../../Chests/Loot/Epic8.nbt,2,CHEST:5,../../../../Chests/Loot/Epic9.nbt,2,CHEST:5,../../../../Chests/Loot/Epic10.nbt,2,CHEST:5,../../../../Chests/Loot/Epic11.nbt,2,CHEST:5,../../../../Chests/Loot/Epic12.nbt,2,CHEST:5,../../../../Chests/Loot/Epic13.nbt,2,CHEST:5,../../../../Chests/Loot/Epic14.nbt,2,CHEST:5,../../../../Chests/Loot/Epic15.nbt,5,CHEST:5,../../../../Chests/Loot/Rare1.nbt,5,CHEST:5,../../../../Chests/Loot/Rare2.nbt,5,CHEST:5,../../../../Chests/Loot/Rare3.nbt,5,CHEST:5,../../../../Chests/Loot/Rare4.nbt,5,CHEST:5,../../../../Chests/Loot/Rare5.nbt,10,CHEST:5,../../../../Chests/Loot/Rare6.nbt,10,CHEST:5,../../../../Chests/Loot/Rare7.nbt,10,CHEST:5,../../../../Chests/Loot/Rare8.nbt,10,CHEST:5,../../../../Chests/Loot/Rare9.nbt,10,CHEST:5,../../../../Chests/Loot/Rare10.nbt,15,CHEST:5,../../../../Chests/Loot/Rare11.nbt,15,CHEST:5,../../../../Chests/Loot/Rare12.nbt,15,CHEST:5,../../../../Chests/Loot/Rare13.nbt,15,CHEST:5,../../../../Chests/Loot/Rare14.nbt,15,CHEST:5,../../../../Chests/Loot/Rare15.nbt,15,CHEST:5,../../../../Chests/Loot/Epic15.nbt,100)
Block(-3,3,-4,AIR:0)
Block(-3,3,-3,AIR:0)
Block(-3,3,-2,AIR:0)
Block(-3,3,-1,AIR:0)
Block(-3,3,0,AIR:0)
Block(-3,3,1,AIR:0)
Block(-3,3,2,AIR:0)
Block(-3,3,3,AIR:0)
Block(-3,3,4,AIR:0)
Block(-3,3,5,AIR:0)
Block(-3,3,6,TORCH:5)
Block(-3,3,7,AIR:0)
Block(-3,3,8,AIR:0)
RandomBlock(-3,3,9,DARK_OAK_FENCE:0,30,STONE:6,100)
RandomBlock(-3,4,-6,DARK_OAK_FENCE:0,30,STONE:6,100)
Block(-3,4,-5,AIR:0)
Block(-3,4,-4,AIR:0)
Block(-3,4,-3,AIR:0)
Block(-3,4,-2,AIR:0)
Block(-3,4,-1,AIR:0)
Block(-3,4,0,WOOD_STEP:13)
Block(-3,4,1,WOOD_STEP:13)
Block(-3,4,2,WOOD_STEP:13)
Block(-3,4,3,WOOD_STEP:13)
Block(-3,4,4,WOOD_STEP:13)
Block(-3,4,5,WOOD_STEP:13)
Block(-3,4,6,WOOD_STEP:13)
Block(-3,4,7,WOOD_STEP:13)
Block(-3,4,8,AIR:0)
RandomBlock(-3,4,9,DARK_OAK_FENCE:0,30,STONE:6,100)
RandomBlock(-3,5,-6,DARK_OAK_FENCE:0,30,STONE:6,100)
Block(-3,5,-5,AIR:0)
Block(-3,5,-4,AIR:0)
Block(-3,5,-3,AIR:0)
Block(-3,5,-2,AIR:0)
Block(-3,5,-1,AIR:0)
Block(-3,5,0,SPRUCE_FENCE:0)
Block(-3,5,1,AIR:0)
Block(-3,5,2,AIR:0)
Block(-3,5,3,SPRUCE_FENCE:0)
Block(-3,5,4,AIR:0)
Block(-3,5,5,AIR:0)
Block(-3,5,6,AIR:0)
Block(-3,5,7,SPRUCE_FENCE:0)
Block(-3,5,8,AIR:0)
RandomBlock(-3,5,9,DARK_OAK_FENCE:0,30,STONE:6,100)
Block(-3,6,-6,WOOD:5)
Block(-3,6,-5,WOOD_STEP:13)
Block(-3,6,-4,WOOD_STEP:13)
Block(-3,6,-3,WOOD_STEP:13)
Block(-3,6,-2,WOOD_STEP:13)
Block(-3,6,-1,WOOD_STEP:13)
Block(-3,6,0,WOOD:5)
Block(-3,6,1,WOOD_STEP:13)
Block(-3,6,2,WOOD_STEP:13)
Block(-3,6,3,WOOD:5)
Block(-3,6,4,WOOD_DOUBLE_STEP:5)
Block(-3,6,5,WOOD_DOUBLE_STEP:5)
Block(-3,6,6,WOOD_STEP:13)
Block(-3,6,7,WOOD_DOUBLE_STEP:5)
Block(-3,6,8,WOOD_STEP:13)
Block(-3,6,9,WOOD:5)
RandomBlock(-3,7,-6,DARK_OAK_FENCE:0,30,STONE:6,100)
Block(-3,7,-5,AIR:0)
Block(-3,7,-4,CARPET:13)
Block(-3,7,-3,CARPET:13)
Block(-3,7,-2,AIR:0)
Block(-3,7,-1,CARPET:13)
Block(-3,7,0,SPRUCE_FENCE:0)
Block(-3,7,1,SPRUCE_FENCE:0)
Block(-3,7,2,SPRUCE_FENCE:0)
Block(-3,7,3,SPRUCE_FENCE:0)
Block(-3,7,4,SPRUCE_FENCE:0)
Block(-3,7,5,SPRUCE_FENCE:0)
Block(-3,7,6,CARPET:13)
Block(-3,7,7,AIR:0)
Block(-3,7,8,AIR:0)
RandomBlock(-3,7,9,DARK_OAK_FENCE:0,30,STONE:6,100)
RandomBlock(-3,8,-6,DARK_OAK_FENCE:0,30,STONE:6,100)
Block(-3,8,-5,AIR:0)
Block(-3,8,-4,AIR:0)
Block(-3,8,-3,AIR:0)
Block(-3,8,-2,AIR:0)
Block(-3,8,-1,AIR:0)
Block(-3,8,0,SPRUCE_FENCE:0)
Block(-3,8,1,AIR:0)
Block(-3,8,2,AIR:0)
Block(-3,8,3,SPRUCE_FENCE:0)
Block(-3,8,4,AIR:0)
Block(-3,8,5,AIR:0)
Block(-3,8,6,AIR:0)
Block(-3,8,7,AIR:0)
Block(-3,8,8,AIR:0)
RandomBlock(-3,8,9,DARK_OAK_FENCE:0,30,STONE:6,100)
RandomBlock(-3,9,-6,DARK_OAK_FENCE:0,30,STONE:6,100)
Block(-3,9,-5,AIR:0)
Block(-3,9,-4,AIR:0)
Block(-3,9,-3,AIR:0)
Block(-3,9,-2,AIR:0)
Block(-3,9,-1,AIR:0)
Block(-3,9,0,SPRUCE_FENCE:0)
Block(-3,9,1,AIR:0)
Block(-3,9,2,AIR:0)
Block(-3,9,3,SPRUCE_FENCE:0)
Block(-3,9,4,AIR:0)
Block(-3,9,5,AIR:0)
Block(-3,9,6,AIR:0)
Block(-3,9,7,AIR:0)
Block(-3,9,8,AIR:0)
RandomBlock(-3,9,9,DARK_OAK_FENCE:0,30,STONE:6,100)
RandomBlock(-3,10,-6,DARK_OAK_FENCE:0,30,STONE:6,100)
Block(-3,10,-5,AIR:0)
Block(-3,10,-4,AIR:0)
Block(-3,10,-3,AIR:0)
Block(-3,10,-2,AIR:0)
Block(-3,10,-1,AIR:0)
Block(-3,10,0,SPRUCE_FENCE:0)
Block(-3,10,1,AIR:0)
Block(-3,10,2,AIR:0)
Block(-3,10,3,SPRUCE_FENCE:0)
Block(-3,10,4,AIR:0)
Block(-3,10,5,AIR:0)
Block(-3,10,6,AIR:0)
Block(-3,10,7,AIR:0)
Block(-3,10,8,AIR:0)
RandomBlock(-3,10,9,DARK_OAK_FENCE:0,30,STONE:6,100)
Block(-3,11,-6,WOOD:5)
Block(-3,11,-5,WOOD_STEP:13)
Block(-3,11,-4,WOOD_STEP:13)
Block(-3,11,-3,WOOD_STEP:13)
Block(-3,11,-2,WOOD_STEP:13)
Block(-3,11,-1,WOOD_STEP:13)
Block(-3,11,0,WOOD:5)
Block(-3,11,1,WOOD_STEP:13)
Block(-3,11,2,WOOD_STEP:13)
Block(-3,11,3,WOOD:5)
Block(-3,11,4,WOOD_DOUBLE_STEP:5)
Block(-3,11,5,WOOD_DOUBLE_STEP:5)
Block(-3,11,6,WOOD_STEP:13)
Block(-3,11,7,WOOD_STEP:13)
Block(-3,11,8,WOOD_STEP:13)
Block(-3,11,9,WOOD:5)
RandomBlock(-3,12,-6,DARK_OAK_FENCE:0,30,STONE:6,100)
Block(-3,12,-5,AIR:0)
Block(-3,12,-4,AIR:0)
Block(-3,12,-3,AIR:0)
Block(-3,12,-2,AIR:0)
Block(-3,12,-1,SMOOTH_BRICK:0)
Block(-3,12,0,SMOOTH_BRICK:0)
Block(-3,12,1,SMOOTH_BRICK:0)
Block(-3,12,2,SMOOTH_BRICK:0)
Block(-3,12,3,SMOOTH_BRICK:0)
Block(-3,12,4,SMOOTH_BRICK:0)
Block(-3,12,5,SMOOTH_BRICK:0)
Block(-3,12,6,AIR:0)
Block(-3,12,7,AIR:0)
Block(-3,12,8,HAY_BLOCK:0)
RandomBlock(-3,12,9,DARK_OAK_FENCE:0,30,STONE:6,100)
RandomBlock(-3,13,-6,DARK_OAK_FENCE:0,30,STONE:6,100)
Block(-3,13,-5,AIR:0)
Block(-3,13,-4,AIR:0)
Block(-3,13,-3,AIR:0)
Block(-3,13,-2,AIR:0)
Block(-3,13,-1,SMOOTH_BRICK:0)
Block(-3,13,0,SPRUCE_FENCE:0)
Block(-3,13,1,SMOOTH_BRICK:0)
Block(-3,13,2,SMOOTH_BRICK:0)
Block(-3,13,3,SPRUCE_FENCE:0)
Block(-3,13,4,SMOOTH_BRICK:0)
Block(-3,13,5,SMOOTH_BRICK:0)
Block(-3,13,6,AIR:0)
Block(-3,13,7,AIR:0)
Block(-3,13,8,HAY_BLOCK:0)
RandomBlock(-3,13,9,DARK_OAK_FENCE:0,30,STONE:6,100)
RandomBlock(-3,14,-6,DARK_OAK_FENCE:0,30,STONE:6,100)
Block(-3,14,-5,AIR:0)
Block(-3,14,-4,AIR:0)
Block(-3,14,-3,AIR:0)
Block(-3,14,-2,AIR:0)
Block(-3,14,-1,WOOD_STEP:5)
Block(-3,14,0,SPRUCE_FENCE:0)
Block(-3,14,1,WOOD_STEP:5)
Block(-3,14,2,WOOD_STEP:5)
Block(-3,14,3,SPRUCE_FENCE:0)
Block(-3,14,4,WOOD_STEP:5)
Block(-3,14,5,WOOD_STEP:5)
Block(-3,14,6,AIR:0)
Block(-3,14,7,AIR:0)
Block(-3,14,8,AIR:0)
RandomBlock(-3,14,9,DARK_OAK_FENCE:0,30,STONE:6,100)
Block(-3,15,-6,WOOD:5)
Block(-3,15,-5,TRAP_DOOR:8)
Block(-3,15,-4,TRAP_DOOR:8)
Block(-3,15,-3,TRAP_DOOR:8)
Block(-3,15,-2,TRAP_DOOR:8)
Block(-3,15,-1,TRAP_DOOR:8)
Block(-3,15,0,WOOD:5)
Block(-3,15,1,TRAP_DOOR:8)
Block(-3,15,2,TRAP_DOOR:8)
Block(-3,15,3,WOOD:5)
Block(-3,15,4,TRAP_DOOR:8)
Block(-3,15,5,TRAP_DOOR:8)
Block(-3,15,6,TRAP_DOOR:8)
Block(-3,15,7,TRAP_DOOR:8)
Block(-3,15,8,TRAP_DOOR:8)
Block(-3,15,9,WOOD:5)
Block(-2,1,-6,WOOD:5)
Block(-2,1,-5,WOOD:5)
Block(-2,1,-4,SMOOTH_BRICK:0)
Block(-2,1,-3,SMOOTH_BRICK:0)
Block(-2,1,-2,WOOD:5)
Block(-2,1,-1,STONE:6)
Block(-2,1,0,STONE:6)
Block(-2,1,1,STONE:6)
Block(-2,1,2,STONE:6)
Block(-2,1,3,STONE:6)
Block(-2,1,4,STONE:6)
Block(-2,1,5,WOOD:5)
Block(-2,1,6,WOOD:5)
Block(-2,1,7,WOOD:5)
Block(-2,1,8,WOOD:5)
Block(-2,1,9,WOOD:5)
Block(-2,2,-6,SMOOTH_BRICK:0)
Block(-2,2,-5,SPRUCE_FENCE:0)
Block(-2,2,-4,AIR:0)
Block(-2,2,-3,AIR:0)
Block(-2,2,-2,AIR:0)
Block(-2,2,-1,AIR:0)
Block(-2,2,0,SPRUCE_WOOD_STAIRS:2)
Block(-2,2,1,SPRUCE_WOOD_STAIRS:7)
Block(-2,2,2,AIR:0)
Block(-2,2,3,AIR:0)
Block(-2,2,4,AIR:0)
Block(-2,2,5,AIR:0)
Block(-2,2,6,AIR:0)
Block(-2,2,7,SPRUCE_FENCE:0)
Block(-2,2,8,AIR:0)
Block(-2,2,9,SMOOTH_BRICK:0)
Block(-2,3,-6,SMOOTH_BRICK:0)
Block(-2,3,-5,AIR:0)
Block(-2,3,-4,AIR:0)
Block(-2,3,-3,AIR:0)
Block(-2,3,-2,AIR:0)
Block(-2,3,-1,AIR:0)
Block(-2,3,0,AIR:0)
Block(-2,3,1,SPRUCE_WOOD_STAIRS:2)
Block(-2,3,2,SPRUCE_WOOD_STAIRS:7)
Block(-2,3,3,AIR:0)
Block(-2,3,4,AIR:0)
Block(-2,3,5,AIR:0)
Block(-2,3,6,AIR:0)
Block(-2,3,7,AIR:0)
Block(-2,3,8,AIR:0)
Block(-2,3,9,SMOOTH_BRICK:0)
Block(-2,4,-6,SMOOTH_BRICK:0)
Block(-2,4,-5,AIR:0)
Block(-2,4,-4,AIR:0)
Block(-2,4,-3,AIR:0)
Block(-2,4,-2,AIR:0)
Block(-2,4,-1,AIR:0)
Block(-2,4,0,AIR:0)
Block(-2,4,1,AIR:0)
Block(-2,4,2,SPRUCE_WOOD_STAIRS:2)
Block(-2,4,3,SPRUCE_WOOD_STAIRS:7)
Block(-2,4,4,AIR:0)
Block(-2,4,5,AIR:0)
Block(-2,4,6,AIR:0)
Block(-2,4,7,WOOD_STEP:13)
Block(-2,4,8,AIR:0)
Block(-2,4,9,SMOOTH_BRICK:0)
Block(-2,5,-6,SMOOTH_BRICK:0)
RandomBlock(-2,5,-5,WALL_BANNER:3,../../NBT/Banners/banner_sun.nbt,50,WALL_BANNER:3,../../NBT/Banners/quarry_banner_0.nbt,10,WALL_BANNER:3,../../NBT/Banners/quarry_banner_1.nbt,10,WALL_BANNER:3,../../NBT/Banners/quarry_banner_2.nbt,10,WALL_BANNER:3,../../NBT/Banners/quarry_banner_3.nbt,10,WALL_BANNER:3,../../NBT/Banners/quarry_banner_4.nbt,100)
Block(-2,5,-4,AIR:0)
Block(-2,5,-3,AIR:0)
Block(-2,5,-2,AIR:0)
Block(-2,5,-1,AIR:0)
RandomBlock(-2,5,0,WALL_BANNER:4,../../NBT/Banners/banner_sun.nbt,50,WALL_BANNER:4,../../NBT/Banners/quarry_banner_0.nbt,10,WALL_BANNER:4,../../NBT/Banners/quarry_banner_1.nbt,10,WALL_BANNER:4,../../NBT/Banners/quarry_banner_2.nbt,10,WALL_BANNER:4,../../NBT/Banners/quarry_banner_3.nbt,10,WALL_BANNER:4,../../NBT/Banners/quarry_banner_4.nbt,100)
Block(-2,5,1,AIR:0)
Block(-2,5,2,AIR:0)
Block(-2,5,3,SPRUCE_WOOD_STAIRS:2)
Block(-2,5,4,SPRUCE_WOOD_STAIRS:7)
Block(-2,5,5,AIR:0)
Block(-2,5,6,AIR:0)
Block(-2,5,7,AIR:0)
RandomBlock(-2,5,8,WALL_BANNER:2,../../NBT/Banners/banner_sun.nbt,50,WALL_BANNER:2,../../NBT/Banners/quarry_banner_0.nbt,10,WALL_BANNER:2,../../NBT/Banners/quarry_banner_1.nbt,10,WALL_BANNER:2,../../NBT/Banners/quarry_banner_2.nbt,10,WALL_BANNER:2,../../NBT/Banners/quarry_banner_3.nbt,10,WALL_BANNER:2,../../NBT/Banners/quarry_banner_4.nbt,100)
Block(-2,5,9,SMOOTH_BRICK:0)
Block(-2,6,-6,WOOD:5)
Block(-2,6,-5,WOOD_STEP:13)
Block(-2,6,-4,WOOD_STEP:13)
Block(-2,6,-3,WOOD_STEP:13)
Block(-2,6,-2,WOOD_STEP:13)
Block(-2,6,-1,WOOD_STEP:13)
Block(-2,6,0,AIR:0)
Block(-2,6,1,AIR:0)
Block(-2,6,2,AIR:0)
Block(-2,6,3,AIR:0)
Block(-2,6,4,AIR:0)
Block(-2,6,5,WOOD_DOUBLE_STEP:5)
Block(-2,6,6,WOOD_STEP:13)
Block(-2,6,7,WOOD_STEP:13)
Block(-2,6,8,WOOD_STEP:13)
Block(-2,6,9,WOOD:5)
Block(-2,7,-6,SMOOTH_BRICK:0)
Block(-2,7,-5,SPRUCE_FENCE:0)
Block(-2,7,-4,AIR:0)
Block(-2,7,-3,CARPET:13)
Block(-2,7,-2,AIR:0)
Block(-2,7,-1,AIR:0)
Block(-2,7,0,SPRUCE_WOOD_STAIRS:2)
Block(-2,7,1,SPRUCE_WOOD_STAIRS:7)
Block(-2,7,2,AIR:0)
Block(-2,7,3,AIR:0)
Block(-2,7,4,AIR:0)
Block(-2,7,5,SPRUCE_FENCE:0)
Block(-2,7,6,CARPET:13)
Block(-2,7,7,AIR:0)
Block(-2,7,8,SPRUCE_FENCE:0)
Block(-2,7,9,SMOOTH_BRICK:0)
Block(-2,8,-6,SMOOTH_BRICK:0)
Block(-2,8,-5,TORCH:5)
Block(-2,8,-4,AIR:0)
Block(-2,8,-3,AIR:0)
Block(-2,8,-2,AIR:0)
Block(-2,8,-1,AIR:0)
Block(-2,8,0,AIR:0)
Block(-2,8,1,SPRUCE_WOOD_STAIRS:2)
Block(-2,8,2,SPRUCE_WOOD_STAIRS:7)
Block(-2,8,3,AIR:0)
Block(-2,8,4,AIR:0)
Block(-2,8,5,AIR:0)
Block(-2,8,6,AIR:0)
Block(-2,8,7,AIR:0)
Block(-2,8,8,TORCH:5)
Block(-2,8,9,SMOOTH_BRICK:0)
Block(-2,9,-6,SMOOTH_BRICK:0)
Block(-2,9,-5,AIR:0)
Block(-2,9,-4,AIR:0)
Block(-2,9,-3,AIR:0)
Block(-2,9,-2,AIR:0)
Block(-2,9,-1,AIR:0)
Block(-2,9,0,AIR:0)
Block(-2,9,1,AIR:0)
Block(-2,9,2,SPRUCE_WOOD_STAIRS:2)
Block(-2,9,3,SPRUCE_WOOD_STAIRS:7)
Block(-2,9,4,AIR:0)
Block(-2,9,5,AIR:0)
Block(-2,9,6,AIR:0)
Block(-2,9,7,AIR:0)
Block(-2,9,8,AIR:0)
Block(-2,9,9,SMOOTH_BRICK:0)
Block(-2,10,-6,SMOOTH_BRICK:0)
RandomBlock(-2,10,-5,WALL_BANNER:3,../../NBT/Banners/banner_sun.nbt,50,WALL_BANNER:3,../../NBT/Banners/quarry_banner_0.nbt,10,WALL_BANNER:3,../../NBT/Banners/quarry_banner_1.nbt,10,WALL_BANNER:3,../../NBT/Banners/quarry_banner_2.nbt,10,WALL_BANNER:3,../../NBT/Banners/quarry_banner_3.nbt,10,WALL_BANNER:3,../../NBT/Banners/quarry_banner_4.nbt,100)
Block(-2,10,-4,AIR:0)
Block(-2,10,-3,AIR:0)
Block(-2,10,-2,AIR:0)
Block(-2,10,-1,AIR:0)
Block(-2,10,0,AIR:0)
Block(-2,10,1,AIR:0)
Block(-2,10,2,AIR:0)
Block(-2,10,3,SPRUCE_WOOD_STAIRS:2)
Block(-2,10,4,SPRUCE_WOOD_STAIRS:7)
Block(-2,10,5,AIR:0)
Block(-2,10,6,AIR:0)
Block(-2,10,7,AIR:0)
RandomBlock(-2,10,8,WALL_BANNER:2,../../NBT/Banners/banner_sun.nbt,50,WALL_BANNER:2,../../NBT/Banners/quarry_banner_0.nbt,10,WALL_BANNER:2,../../NBT/Banners/quarry_banner_1.nbt,10,WALL_BANNER:2,../../NBT/Banners/quarry_banner_2.nbt,10,WALL_BANNER:2,../../NBT/Banners/quarry_banner_3.nbt,10,WALL_BANNER:2,../../NBT/Banners/quarry_banner_4.nbt,100)
Block(-2,10,9,SMOOTH_BRICK:0)
Block(-2,11,-6,WOOD:5)
Block(-2,11,-5,WOOD_STEP:13)
Block(-2,11,-4,WOOD_STEP:13)
Block(-2,11,-3,WOOD_STEP:13)
Block(-2,11,-2,WOOD_STEP:13)
Block(-2,11,-1,WOOD_STEP:13)
Block(-2,11,0,AIR:0)
Block(-2,11,1,AIR:0)
Block(-2,11,2,AIR:0)
Block(-2,11,3,AIR:0)
Block(-2,11,4,AIR:0)
Block(-2,11,5,WOOD_DOUBLE_STEP:5)
Block(-2,11,6,WOOD_STEP:13)
Block(-2,11,7,WOOD_STEP:13)
Block(-2,11,8,WOOD_STEP:13)
Block(-2,11,9,WOOD:5)
Block(-2,12,-6,SMOOTH_BRICK:0)
Block(-2,12,-5,SPRUCE_FENCE:0)
Block(-2,12,-4,AIR:0)
Block(-2,12,-3,AIR:0)
Block(-2,12,-2,COAL_ORE:0)
Block(-2,12,-1,SMOOTH_BRICK:0)
Block(-2,12,0,AIR:0)
Block(-2,12,1,AIR:0)
Block(-2,12,2,AIR:0)
Block(-2,12,3,AIR:0)
Block(-2,12,4,AIR:0)
Block(-2,12,5,SMOOTH_BRICK:0)
Block(-2,12,6,AIR:0)
Block(-2,12,7,AIR:0)
Block(-2,12,8,SPRUCE_FENCE:0)
Block(-2,12,9,SMOOTH_BRICK:0)
Block(-2,13,-6,SMOOTH_BRICK:0)
Block(-2,13,-5,TORCH:5)
Block(-2,13,-4,AIR:0)
Block(-2,13,-3,AIR:0)
Block(-2,13,-2,AIR:0)
Block(-2,13,-1,SMOOTH_BRICK:0)
Block(-2,13,0,AIR:0)
Block(-2,13,1,AIR:0)
Block(-2,13,2,AIR:0)
Block(-2,13,3,AIR:0)
Block(-2,13,4,AIR:0)
Block(-2,13,5,SMOOTH_BRICK:0)
Block(-2,13,6,AIR:0)
Block(-2,13,7,AIR:0)
Block(-2,13,8,TORCH:5)
Block(-2,13,9,SMOOTH_BRICK:0)
Block(-2,14,-6,SMOOTH_BRICK:0)
Block(-2,14,-5,AIR:0)
Block(-2,14,-4,AIR:0)
Block(-2,14,-3,AIR:0)
Block(-2,14,-2,AIR:0)
Block(-2,14,-1,WOOD_STEP:5)
Block(-2,14,0,AIR:0)
Block(-2,14,1,AIR:0)
Block(-2,14,2,AIR:0)
Block(-2,14,3,AIR:0)
Block(-2,14,4,AIR:0)
Block(-2,14,5,WOOD_STEP:5)
Block(-2,14,6,AIR:0)
Block(-2,14,7,AIR:0)
Block(-2,14,8,AIR:0)
Block(-2,14,9,SMOOTH_BRICK:0)
Block(-2,15,-6,WOOD:5)
Block(-2,15,-5,TRAP_DOOR:8)
Block(-2,15,-4,TRAP_DOOR:8)
Block(-2,15,-3,TRAP_DOOR:8)
Block(-2,15,-2,TRAP_DOOR:8)
Block(-2,15,-1,TRAP_DOOR:8)
Block(-2,15,0,WOOD:5)
Block(-2,15,1,TRAP_DOOR:8)
Block(-2,15,2,TRAP_DOOR:8)
Block(-2,15,3,WOOD:5)
Block(-2,15,4,TRAP_DOOR:8)
Block(-2,15,5,TRAP_DOOR:8)
Block(-2,15,6,TRAP_DOOR:8)
Block(-2,15,7,TRAP_DOOR:8)
Block(-2,15,8,TRAP_DOOR:8)
Block(-2,15,9,WOOD:5)
Block(-1,0,-6,LOG:1)
Block(-1,0,9,LOG:1)
Block(-1,1,-6,WOOD:5)
Block(-1,1,-5,WOOD:5)
Block(-1,1,-4,SMOOTH_BRICK:0)
Block(-1,1,-3,SMOOTH_BRICK:0)
Block(-1,1,-2,WOOD:5)
Block(-1,1,-1,STONE:6)
Block(-1,1,0,SMOOTH_BRICK:0)
Block(-1,1,1,SMOOTH_BRICK:0)
Block(-1,1,2,SMOOTH_BRICK:0)
Block(-1,1,3,SMOOTH_BRICK:0)
Block(-1,1,4,STONE:6)
Block(-1,1,5,WOOD:5)
Block(-1,1,6,WOOD:5)
Block(-1,1,7,WOOD:5)
Block(-1,1,8,WOOD:5)
Block(-1,1,9,WOOD:5)
Block(-1,2,-6,DARK_OAK_STAIRS:0)
Block(-1,2,-5,AIR:0)
Block(-1,2,-4,AIR:0)
Block(-1,2,-3,AIR:0)
Block(-1,2,-2,AIR:0)
Block(-1,2,-1,SMOOTH_STAIRS:6)
Block(-1,2,0,SMOOTH_BRICK:0)
Block(-1,2,1,SMOOTH_BRICK:0)
Block(-1,2,2,SMOOTH_BRICK:0)
Block(-1,2,3,SMOOTH_BRICK:0)
Block(-1,2,4,IRON_FENCE:0)
Block(-1,2,5,AIR:0)
Block(-1,2,6,ANVIL:8)
Block(-1,2,7,SPRUCE_FENCE:0)
Block(-1,2,8,AIR:0)
Block(-1,2,9,DARK_OAK_STAIRS:0)
Block(-1,3,-6,DARK_OAK_STAIRS:4)
Block(-1,3,-5,AIR:0)
Block(-1,3,-4,AIR:0)
Block(-1,3,-3,AIR:0)
Block(-1,3,-2,AIR:0)
RandomBlock(-1,3,-1,AIR:0,5,CHEST:2,../../../../Chests/Loot/village_blacksmith.nbt,10,CHEST:2,../../../../Chests/Lore/Generic_5.nbt,1,CHEST:2,../../../../Chests/Lore/Generic_4.nbt,1,CHEST:2,../../../../Chests/Lore/Generic_3.nbt,1,CHEST:2,../../../../Chests/Lore/Generic_2.nbt,1,CHEST:2,../../../../Chests/Lore/Generic_1.nbt,1,CHEST:2,../../../../Chests/Lore/HiddenMine_1.nbt,1,CHEST:2,../../../../Chests/Lore/HiddenMine_2.nbt,1,CHEST:2,../../../../Chests/Lore/HiddenMine_3.nbt,1,CHEST:2,../../../../Chests/Lore/HiddenMine_4.nbt,1,CHEST:2,../../../../Chests/Lore/HiddenMine_5.nbt,1,CHEST:2,../../../../Chests/Loot/village_blacksmith.nbt,100)
Block(-1,3,0,SMOOTH_BRICK:0)
Block(-1,3,1,SMOOTH_BRICK:0)
Block(-1,3,2,SMOOTH_BRICK:0)
Block(-1,3,3,SMOOTH_BRICK:0)
Block(-1,3,4,IRON_FENCE:0)
Block(-1,3,5,AIR:0)
Block(-1,3,6,AIR:0)
Block(-1,3,7,AIR:0)
Block(-1,3,8,AIR:0)
Block(-1,3,9,DARK_OAK_STAIRS:4)
Block(-1,4,-6,WOOD:1)
Block(-1,4,-5,AIR:0)
Block(-1,4,-4,AIR:0)
Block(-1,4,-3,AIR:0)
Block(-1,4,-2,AIR:0)
Block(-1,4,-1,AIR:0)
Block(-1,4,0,SMOOTH_BRICK:0)
Block(-1,4,1,SMOOTH_BRICK:0)
Block(-1,4,2,SMOOTH_BRICK:0)
Block(-1,4,3,SMOOTH_BRICK:0)
Block(-1,4,4,SMOOTH_STAIRS:0)
Block(-1,4,5,AIR:0)
Block(-1,4,6,AIR:0)
Block(-1,4,7,WOOD_STEP:13)
Block(-1,4,8,AIR:0)
Block(-1,4,9,WOOD:1)
Block(-1,5,-6,SPRUCE_FENCE:0)
Block(-1,5,-5,AIR:0)
Block(-1,5,-4,AIR:0)
Block(-1,5,-3,AIR:0)
Block(-1,5,-2,AIR:0)
RandomBlock(-1,5,-1,WALL_BANNER:2,../../NBT/Banners/banner_sun.nbt,50,WALL_BANNER:2,../../NBT/Banners/quarry_banner_0.nbt,10,WALL_BANNER:2,../../NBT/Banners/quarry_banner_1.nbt,10,WALL_BANNER:2,../../NBT/Banners/quarry_banner_2.nbt,10,WALL_BANNER:2,../../NBT/Banners/quarry_banner_3.nbt,10,WALL_BANNER:2,../../NBT/Banners/quarry_banner_4.nbt,100)
Block(-1,5,0,SMOOTH_BRICK:0)
Block(-1,5,1,SMOOTH_BRICK:0)
Block(-1,5,2,SMOOTH_BRICK:0)
Block(-1,5,3,SMOOTH_BRICK:0)
Block(-1,5,4,SPRUCE_WOOD_STAIRS:5)
Block(-1,5,5,AIR:0)
Block(-1,5,6,AIR:0)
Block(-1,5,7,AIR:0)
Block(-1,5,8,AIR:0)
Block(-1,5,9,SPRUCE_FENCE:0)
Block(-1,6,-6,WOOD:5)
Block(-1,6,-5,WOOD:5)
Block(-1,6,-4,WOOD:5)
Block(-1,6,-3,WOOD:5)
Block(-1,6,-2,WOOD:5)
Block(-1,6,-1,WOOD:5)
Block(-1,6,0,SMOOTH_BRICK:0)
Block(-1,6,1,SMOOTH_BRICK:0)
Block(-1,6,2,SMOOTH_BRICK:0)
Block(-1,6,3,SMOOTH_BRICK:0)
Block(-1,6,4,SPRUCE_WOOD_STAIRS:0)
Block(-1,6,5,WOOD:5)
Block(-1,6,6,WOOD:5)
Block(-1,6,7,WOOD:5)
Block(-1,6,8,WOOD:5)
Block(-1,6,9,WOOD:5)
Block(-1,7,-6,STONE:6)
Block(-1,7,-5,AIR:0)
Block(-1,7,-4,CARPET:13)
Block(-1,7,-3,SPRUCE_FENCE:0)
Block(-1,7,-2,DARK_OAK_STAIRS:7)
Block(-1,7,-1,DARK_OAK_STAIRS:6)
Block(-1,7,0,SMOOTH_BRICK:0)
Block(-1,7,1,SMOOTH_BRICK:0)
Block(-1,7,2,SMOOTH_BRICK:0)
Block(-1,7,3,SMOOTH_BRICK:0)
Block(-1,7,4,AIR:0)
Block(-1,7,5,SPRUCE_FENCE:0)
Block(-1,7,6,AIR:0)
Block(-1,7,7,AIR:0)
Block(-1,7,8,AIR:0)
Block(-1,7,9,STONE:6)
Block(-1,8,-6,STONE:6)
Block(-1,8,-5,AIR:0)
Block(-1,8,-4,AIR:0)
Block(-1,8,-3,SPRUCE_FENCE:0)
Block(-1,8,-2,WOOD_PLATE:0)
Block(-1,8,-1,WOOD_PLATE:0)
Block(-1,8,0,SMOOTH_BRICK:0)
Block(-1,8,1,SMOOTH_BRICK:0)
Block(-1,8,2,SMOOTH_BRICK:0)
Block(-1,8,3,SMOOTH_BRICK:0)
Block(-1,8,4,AIR:0)
Block(-1,8,5,AIR:0)
Block(-1,8,6,AIR:0)
Block(-1,8,7,AIR:0)
Block(-1,8,8,AIR:0)
Block(-1,8,9,STONE:6)
Block(-1,9,-6,WOOD:1)
Block(-1,9,-5,AIR:0)
Block(-1,9,-4,AIR:0)
Block(-1,9,-3,WOOD_STEP:5)
Block(-1,9,-2,WOOD_DOUBLE_STEP:5)
Block(-1,9,-1,WOOD_STEP:13)
Block(-1,9,0,SMOOTH_BRICK:0)
Block(-1,9,1,SMOOTH_BRICK:0)
Block(-1,9,2,SMOOTH_BRICK:0)
Block(-1,9,3,SMOOTH_BRICK:0)
Block(-1,9,4,AIR:0)
Block(-1,9,5,AIR:0)
Block(-1,9,6,AIR:0)
Block(-1,9,7,AIR:0)
Block(-1,9,8,AIR:0)
Block(-1,9,9,WOOD:1)
Block(-1,10,-6,SPRUCE_FENCE:0)
Block(-1,10,-5,AIR:0)
Block(-1,10,-4,AIR:0)
Block(-1,10,-3,AIR:0)
Block(-1,10,-2,AIR:0)
Block(-1,10,-1,AIR:0)
Block(-1,10,0,SMOOTH_BRICK:0)
Block(-1,10,1,SMOOTH_BRICK:0)
Block(-1,10,2,SMOOTH_BRICK:0)
Block(-1,10,3,SMOOTH_BRICK:0)
Block(-1,10,4,SPRUCE_WOOD_STAIRS:5)
Block(-1,10,5,AIR:0)
Block(-1,10,6,AIR:0)
Block(-1,10,7,AIR:0)
Block(-1,10,8,AIR:0)
Block(-1,10,9,SPRUCE_FENCE:0)
Block(-1,11,-6,WOOD:5)
Block(-1,11,-5,WOOD:5)
Block(-1,11,-4,WOOD:5)
Block(-1,11,-3,WOOD:5)
Block(-1,11,-2,WOOD:5)
Block(-1,11,-1,WOOD:5)
Block(-1,11,0,SMOOTH_BRICK:0)
Block(-1,11,1,SMOOTH_BRICK:0)
Block(-1,11,2,SMOOTH_BRICK:0)
Block(-1,11,3,SMOOTH_BRICK:0)
Block(-1,11,4,SPRUCE_WOOD_STAIRS:0)
Block(-1,11,5,WOOD:5)
Block(-1,11,6,WOOD:5)
Block(-1,11,7,WOOD:5)
Block(-1,11,8,WOOD:5)
Block(-1,11,9,WOOD:5)
Block(-1,12,-6,SPRUCE_FENCE:0)
Block(-1,12,-5,AIR:0)
Block(-1,12,-4,AIR:0)
Block(-1,12,-3,COAL_ORE:0)
Block(-1,12,-2,COAL_ORE:0)
Block(-1,12,-1,SMOOTH_BRICK:0)
Block(-1,12,0,SMOOTH_BRICK:0)
Block(-1,12,1,SMOOTH_BRICK:0)
Block(-1,12,2,SMOOTH_BRICK:0)
Block(-1,12,3,SMOOTH_BRICK:0)
Block(-1,12,4,AIR:0)
Block(-1,12,5,SMOOTH_BRICK:0)
Block(-1,12,6,HAY_BLOCK:8)
Block(-1,12,7,AIR:0)
Block(-1,12,8,AIR:0)
RandomBlock(-1,12,9,DARK_OAK_FENCE:0,30,STONE:6,100)
Block(-1,13,-6,SPRUCE_FENCE:0)
Block(-1,13,-5,AIR:0)
Block(-1,13,-4,AIR:0)
Block(-1,13,-3,AIR:0)
Block(-1,13,-2,COAL_ORE:0)
Block(-1,13,-1,SMOOTH_BRICK:0)
Block(-1,13,0,SMOOTH_BRICK:0)
Block(-1,13,1,SMOOTH_BRICK:0)
Block(-1,13,2,SMOOTH_BRICK:0)
Block(-1,13,3,SMOOTH_BRICK:0)
Block(-1,13,4,AIR:0)
Block(-1,13,5,SMOOTH_BRICK:0)
Block(-1,13,6,AIR:0)
Block(-1,13,7,AIR:0)
Block(-1,13,8,AIR:0)
RandomBlock(-1,13,9,DARK_OAK_FENCE:0,30,STONE:6,100)
Block(-1,14,-6,WOOD:1)
Block(-1,14,-5,AIR:0)
Block(-1,14,-4,AIR:0)
Block(-1,14,-3,AIR:0)
Block(-1,14,-2,AIR:0)
Block(-1,14,-1,WOOD_STEP:5)
Block(-1,14,0,SMOOTH_BRICK:0)
Block(-1,14,1,SMOOTH_BRICK:0)
Block(-1,14,2,SMOOTH_BRICK:0)
Block(-1,14,3,SMOOTH_BRICK:0)
Block(-1,14,4,AIR:0)
Block(-1,14,5,WOOD_STEP:5)
Block(-1,14,6,AIR:0)
Block(-1,14,7,AIR:0)
Block(-1,14,8,AIR:0)
Block(-1,14,9,WOOD:1)
Block(-1,15,-6,WOOD:5)
Block(-1,15,-5,WOOD:5)
Block(-1,15,-4,WOOD:5)
Block(-1,15,-3,WOOD:5)
Block(-1,15,-2,WOOD:5)
Block(-1,15,-1,WOOD:5)
Block(-1,15,0,SMOOTH_BRICK:0)
Block(-1,15,1,SMOOTH_BRICK:0)
Block(-1,15,2,SMOOTH_BRICK:0)
Block(-1,15,3,SMOOTH_BRICK:0)
Block(-1,15,4,WOOD:5)
Block(-1,15,5,WOOD:5)
Block(-1,15,6,WOOD:5)
Block(-1,15,7,WOOD:5)
Block(-1,15,8,WOOD:5)
Block(-1,15,9,WOOD:5)
Block(0,1,-6,WOOD:5)
Block(0,1,-5,WOOD:5)
Block(0,1,-4,SMOOTH_BRICK:0)
Block(0,1,-3,SMOOTH_BRICK:0)
Block(0,1,-2,WOOD:5)
Block(0,1,-1,STONE:6)
Block(0,1,0,SMOOTH_BRICK:0)
Block(0,1,1,SMOOTH_BRICK:0)
Block(0,1,2,SMOOTH_BRICK:0)
Block(0,1,3,SMOOTH_BRICK:0)
Block(0,1,4,STONE:6)
Block(0,1,5,WOOD:5)
Block(0,1,6,WOOD:5)
Block(0,1,7,WOOD:5)
Block(0,1,8,WOOD:5)
Block(0,1,9,WOOD:5)
Block(0,2,-6,SPRUCE_DOOR:3)
Block(0,2,-5,AIR:0)
Block(0,2,-4,AIR:0)
Block(0,2,-3,AIR:0)
Block(0,2,-2,AIR:0)
Block(0,2,-1,SMOOTH_STAIRS:6)
Block(0,2,0,SMOOTH_BRICK:0)
Block(0,2,1,STATIONARY_LAVA:0)
Block(0,2,2,STATIONARY_LAVA:0)
Block(0,2,3,SMOOTH_STAIRS:7)
Block(0,2,4,AIR:0)
Block(0,2,5,AIR:0)
Block(0,2,6,AIR:0)
Block(0,2,7,SPRUCE_FENCE:0)
Block(0,2,8,AIR:0)
Block(0,2,9,SPRUCE_DOOR:1)
Block(0,3,-6,SPRUCE_DOOR:8)
Block(0,3,-5,AIR:0)
Block(0,3,-4,AIR:0)
Block(0,3,-3,AIR:0)
Block(0,3,-2,AIR:0)
Block(0,3,0,SMOOTH_BRICK:0)
Block(0,3,1,AIR:0)
Block(0,3,2,AIR:0)
Block(0,3,3,AIR:0)
Block(0,3,4,AIR:0)
Block(0,3,5,AIR:0)
Block(0,3,6,AIR:0)
Block(0,3,7,AIR:0)
Block(0,3,8,AIR:0)
Block(0,3,9,SPRUCE_DOOR:9)
Block(0,4,-6,WOOD:1)
Block(0,4,-5,AIR:0)
Block(0,4,-4,AIR:0)
Block(0,4,-3,AIR:0)
Block(0,4,-2,AIR:0)
Block(0,4,-1,AIR:0)
Block(0,4,0,SMOOTH_BRICK:0)
Block(0,4,1,AIR:0)
Block(0,4,2,AIR:0)
Block(0,4,3,SMOOTH_BRICK:0)
Block(0,4,4,SMOOTH_STAIRS:3)
Block(0,4,5,AIR:0)
Block(0,4,6,AIR:0)
Block(0,4,7,WOOD_STEP:13)
Block(0,4,8,AIR:0)
Block(0,4,9,WOOD:1)
RandomBlock(0,5,-6,DARK_OAK_FENCE:0,30,STONE:6,100)
Block(0,5,-5,AIR:0)
Block(0,5,-4,AIR:0)
Block(0,5,-3,AIR:0)
Block(0,5,-2,AIR:0)
Block(0,5,-1,AIR:0)
Block(0,5,0,SMOOTH_BRICK:0)
Block(0,5,1,AIR:0)
Block(0,5,2,AIR:0)
Block(0,5,3,SMOOTH_BRICK:0)
Block(0,5,4,AIR:0)
Block(0,5,5,AIR:0)
Block(0,5,6,AIR:0)
Block(0,5,7,AIR:0)
Block(0,5,8,AIR:0)
RandomBlock(0,5,9,DARK_OAK_FENCE:0,30,STONE:6,100)
Block(0,6,-6,WOOD_STEP:13)
Block(0,6,-5,WOOD_STEP:13)
Block(0,6,-4,WOOD_STEP:13)
Block(0,6,-3,WOOD_STEP:13)
Block(0,6,-2,WOOD_STEP:13)
Block(0,6,-1,WOOD_STEP:13)
Block(0,6,0,SMOOTH_BRICK:0)
Block(0,6,1,AIR:0)
Block(0,6,2,AIR:0)
Block(0,6,3,SMOOTH_BRICK:0)
Block(0,6,4,SPRUCE_WOOD_STAIRS:5)
Block(0,6,5,WOOD_STEP:13)
Block(0,6,6,WOOD_STEP:13)
Block(0,6,7,WOOD_STEP:13)
Block(0,6,8,WOOD_STEP:13)
Block(0,6,9,WOOD_STEP:13)
Block(0,7,-6,SPRUCE_DOOR:1)
Block(0,7,-5,CARPET:13)
Block(0,7,-4,AIR:0)
Block(0,7,-3,DARK_OAK_STAIRS:5)
Block(0,7,-2,AIR:0)
Block(0,7,-1,AIR:0)
Block(0,7,0,SMOOTH_BRICK:0)
Block(0,7,1,AIR:0)
Block(0,7,2,AIR:0)
Block(0,7,3,SMOOTH_BRICK:0)
Block(0,7,4,AIR:0)
Block(0,7,5,AIR:0)
Block(0,7,6,SPRUCE_FENCE:0)
Block(0,7,7,CARPET:13)
Block(0,7,8,AIR:0)
Block(0,7,9,SPRUCE_DOOR:3)
Block(0,8,-6,SPRUCE_DOOR:9)
Block(0,8,-5,AIR:0)
Block(0,8,-4,AIR:0)
Block(0,8,-3,WOOD_PLATE:0)
Block(0,8,-2,AIR:0)
Block(0,8,-1,AIR:0)
Block(0,8,0,SMOOTH_BRICK:0)
Block(0,8,1,AIR:0)
Block(0,8,2,AIR:0)
Block(0,8,3,SMOOTH_BRICK:0)
Block(0,8,4,AIR:0)
Block(0,8,5,AIR:0)
Block(0,8,6,SPRUCE_FENCE:0)
Block(0,8,7,AIR:0)
Block(0,8,8,AIR:0)
Block(0,8,9,SPRUCE_DOOR:8)
Block(0,9,-6,WOOD:1)
Block(0,9,-5,AIR:0)
Block(0,9,-4,AIR:0)
Block(0,9,-3,WOOD_STEP:5)
Block(0,9,-2,WOOD_DOUBLE_STEP:5)
Block(0,9,-1,WOOD_STEP:13)
Block(0,9,0,SMOOTH_BRICK:0)
Block(0,9,1,AIR:0)
Block(0,9,2,AIR:0)
Block(0,9,3,SMOOTH_BRICK:0)
Block(0,9,4,WOOD_STEP:13)
Block(0,9,5,WOOD_DOUBLE_STEP:5)
Block(0,9,6,WOOD_STEP:5)
Block(0,9,7,AIR:0)
Block(0,9,8,AIR:0)
Block(0,9,9,WOOD:1)
RandomBlock(0,10,-6,DARK_OAK_FENCE:0,30,STONE:6,100)
Block(0,10,-5,AIR:0)
Block(0,10,-4,AIR:0)
Block(0,10,-3,AIR:0)
Block(0,10,-2,AIR:0)
Block(0,10,-1,AIR:0)
Block(0,10,0,SMOOTH_BRICK:0)
Block(0,10,1,AIR:0)
Block(0,10,2,AIR:0)
Block(0,10,3,SMOOTH_BRICK:0)
Block(0,10,4,AIR:0)
Block(0,10,5,AIR:0)
Block(0,10,6,AIR:0)
Block(0,10,7,AIR:0)
Block(0,10,8,AIR:0)
RandomBlock(0,10,9,DARK_OAK_FENCE:0,30,STONE:6,100)
Block(0,11,-6,WOOD_STEP:13)
Block(0,11,-5,WOOD_STEP:13)
Block(0,11,-4,WOOD_STEP:13)
Block(0,11,-3,WOOD_STEP:13)
Block(0,11,-2,WOOD_STEP:13)
Block(0,11,-1,WOOD_STEP:13)
Block(0,11,0,SMOOTH_BRICK:0)
Block(0,11,1,IRON_TRAPDOOR:11)
Block(0,11,2,IRON_TRAPDOOR:11)
Block(0,11,3,SMOOTH_BRICK:0)
Block(0,11,4,SPRUCE_WOOD_STAIRS:5)
Block(0,11,5,WOOD_STEP:13)
Block(0,11,6,WOOD_STEP:13)
Block(0,11,7,WOOD_STEP:13)
Block(0,11,8,WOOD_STEP:13)
Block(0,11,9,WOOD_STEP:13)
Block(0,12,-6,AIR:0)
Block(0,12,-5,AIR:0)
Block(0,12,-4,AIR:0)
Block(0,12,-3,AIR:0)
Block(0,12,-2,COAL_ORE:0)
Block(0,12,-1,COAL_ORE:0)
Block(0,12,0,SMOOTH_BRICK:0)
Block(0,12,1,AIR:0)
Block(0,12,2,AIR:0)
Block(0,12,3,SMOOTH_BRICK:0)
Block(0,12,4,SPRUCE_DOOR:0)
Block(0,12,5,SMOOTH_BRICK:0)
Block(0,12,6,AIR:0)
Block(0,12,7,AIR:0)
Block(0,12,8,AIR:0)
Block(0,12,9,AIR:0)
Block(0,13,-6,AIR:0)
Block(0,13,-5,AIR:0)
Block(0,13,-4,AIR:0)
Block(0,13,-3,AIR:0)
Block(0,13,-2,AIR:0)
Block(0,13,-1,COAL_ORE:0)
Block(0,13,0,SMOOTH_BRICK:0)
Block(0,13,1,HUGE_MUSHROOM_1:14)
Block(0,13,2,AIR:0)
Block(0,13,3,SMOOTH_BRICK:0)
Block(0,13,4,SPRUCE_DOOR:9)
Block(0,13,5,SMOOTH_BRICK:0)
Block(0,13,6,AIR:0)
Block(0,13,7,AIR:0)
Block(0,13,8,AIR:0)
Block(0,13,9,AIR:0)
Block(0,14,-6,WOOD:1)
Block(0,14,-5,AIR:0)
Block(0,14,-4,AIR:0)
Block(0,14,-3,AIR:0)
Block(0,14,-2,AIR:0)
Block(0,14,-1,AIR:0)
Block(0,14,0,SMOOTH_BRICK:0)
Block(0,14,1,IRON_FENCE:0)
Block(0,14,2,IRON_FENCE:0)
Block(0,14,3,SMOOTH_BRICK:0)
Block(0,14,4,WOOD_STEP:5)
Block(0,14,5,WOOD_STEP:5)
Block(0,14,6,AIR:0)
Block(0,14,7,AIR:0)
Block(0,14,8,AIR:0)
Block(0,14,9,WOOD:1)
Block(0,15,-6,WOOD:5)
Block(0,15,-5,TRAP_DOOR:8)
Block(0,15,-4,TRAP_DOOR:8)
Block(0,15,-3,TRAP_DOOR:8)
Block(0,15,-2,TRAP_DOOR:8)
Block(0,15,-1,TRAP_DOOR:8)
Block(0,15,0,SMOOTH_BRICK:0)
Block(0,15,1,IRON_TRAPDOOR:9)
Block(0,15,2,IRON_TRAPDOOR:9)
Block(0,15,3,SMOOTH_BRICK:0)
Block(0,15,4,TRAP_DOOR:8)
Block(0,15,5,TRAP_DOOR:8)
Block(0,15,6,TRAP_DOOR:8)
Block(0,15,7,TRAP_DOOR:8)
Block(0,15,8,TRAP_DOOR:8)
Block(0,15,9,WOOD:5)
Block(1,1,-6,WOOD:5)
Block(1,1,-5,WOOD:5)
Block(1,1,-4,SMOOTH_BRICK:0)
Block(1,1,-3,SMOOTH_BRICK:0)
Block(1,1,-2,WOOD:5)
Block(1,1,-1,STONE:6)
Block(1,1,0,SMOOTH_BRICK:0)
Block(1,1,1,SMOOTH_BRICK:0)
Block(1,1,2,SMOOTH_BRICK:0)
Block(1,1,3,SMOOTH_BRICK:0)
Block(1,1,4,STONE:6)
Block(1,1,5,WOOD:5)
Block(1,1,6,WOOD:5)
Block(1,1,7,WOOD:5)
Block(1,1,8,WOOD:5)
Block(1,1,9,WOOD:5)
Block(1,2,-6,SPRUCE_DOOR:3)
Block(1,2,-5,AIR:0)
Block(1,2,-4,AIR:0)
Block(1,2,-3,AIR:0)
Block(1,2,-2,AIR:0)
Block(1,2,-1,SMOOTH_STAIRS:6)
Block(1,2,0,SMOOTH_BRICK:0)
Block(1,2,1,STATIONARY_LAVA:0)
Block(1,2,2,STATIONARY_LAVA:0)
Block(1,2,3,SMOOTH_STAIRS:7)
Block(1,2,4,AIR:0)
Block(1,2,5,AIR:0)
Block(1,2,6,SMOOTH_STAIRS:4)
Block(1,2,7,SPRUCE_FENCE:0)
Block(1,2,8,AIR:0)
Block(1,2,9,SPRUCE_DOOR:1)
Block(1,3,-6,SPRUCE_DOOR:9)
Block(1,3,-5,AIR:0)
Block(1,3,-4,AIR:0)
Block(1,3,-3,AIR:0)
Block(1,3,-2,AIR:0)
Block(1,3,-1,IRON_PLATE:0)
Block(1,3,0,SMOOTH_BRICK:0)
Block(1,3,1,AIR:0)
Block(1,3,2,AIR:0)
Block(1,3,3,AIR:0)
Block(1,3,4,AIR:0)
Block(1,3,5,AIR:0)
Block(1,3,6,IRON_PLATE:0)
Block(1,3,7,AIR:0)
Block(1,3,8,AIR:0)
Block(1,3,9,SPRUCE_DOOR:8)
Block(1,4,-6,WOOD:1)
Block(1,4,-5,AIR:0)
Block(1,4,-4,AIR:0)
Block(1,4,-3,AIR:0)
Block(1,4,-2,AIR:0)
Block(1,4,-1,AIR:0)
Block(1,4,0,SMOOTH_BRICK:0)
Block(1,4,1,AIR:0)
Block(1,4,2,AIR:0)
Block(1,4,3,SMOOTH_BRICK:0)
Block(1,4,4,SMOOTH_STAIRS:3)
Block(1,4,5,AIR:0)
Block(1,4,6,AIR:0)
Block(1,4,7,WOOD_STEP:13)
Block(1,4,8,AIR:0)
Block(1,4,9,WOOD:1)
RandomBlock(1,5,-6,DARK_OAK_FENCE:0,30,STONE:6,100)
Block(1,5,-5,AIR:0)
Block(1,5,-4,AIR:0)
Block(1,5,-3,AIR:0)
Block(1,5,-2,AIR:0)
Block(1,5,-1,AIR:0)
Block(1,5,0,SMOOTH_BRICK:0)
Block(1,5,1,AIR:0)
Block(1,5,2,AIR:0)
Block(1,5,3,SMOOTH_BRICK:0)
Block(1,5,4,AIR:0)
Block(1,5,5,AIR:0)
Block(1,5,6,AIR:0)
Block(1,5,7,AIR:0)
Block(1,5,8,AIR:0)
RandomBlock(1,5,9,DARK_OAK_FENCE:0,30,STONE:6,100)
Block(1,6,-6,WOOD_STEP:13)
Block(1,6,-5,WOOD_STEP:13)
Block(1,6,-4,WOOD_STEP:13)
Block(1,6,-3,WOOD_STEP:13)
Block(1,6,-2,WOOD_STEP:13)
Block(1,6,-1,WOOD_STEP:13)
Block(1,6,0,SMOOTH_BRICK:0)
Block(1,6,1,AIR:0)
Block(1,6,2,AIR:0)
Block(1,6,3,SMOOTH_BRICK:0)
Block(1,6,4,WOOD_STEP:13)
Block(1,6,5,WOOD_STEP:13)
Block(1,6,6,WOOD_STEP:13)
Block(1,6,7,WOOD_STEP:13)
Block(1,6,8,WOOD_STEP:13)
Block(1,6,9,WOOD_STEP:13)
Block(1,7,-6,SPRUCE_DOOR:1)
Block(1,7,-5,AIR:0)
Block(1,7,-4,AIR:0)
Block(1,7,-3,DARK_OAK_STAIRS:4)
Block(1,7,-2,AIR:0)
Block(1,7,-1,BOOKSHELF:0)
Block(1,7,0,SMOOTH_BRICK:0)
Block(1,7,1,AIR:0)
Block(1,7,2,AIR:0)
Block(1,7,3,SMOOTH_BRICK:0)
Block(1,7,5,AIR:0)
Block(1,7,6,AIR:0)
Block(1,7,7,CARPET:13)
Block(1,7,8,CARPET:13)
Block(1,7,9,SPRUCE_DOOR:3)
Block(1,8,-6,SPRUCE_DOOR:8)
Block(1,8,-5,AIR:0)
Block(1,8,-4,AIR:0)
Block(1,8,-3,WOOD_PLATE:0)
Block(1,8,-2,AIR:0)
Block(1,8,0,SMOOTH_BRICK:0)
Block(1,8,1,AIR:0)
Block(1,8,2,AIR:0)
Block(1,8,3,SMOOTH_BRICK:0)
Block(1,8,4,AIR:0)
Block(1,8,5,AIR:0)
Block(1,8,6,AIR:0)
Block(1,8,7,AIR:0)
Block(1,8,8,AIR:0)
Block(1,8,9,SPRUCE_DOOR:9)
Block(1,9,-6,WOOD:1)
Block(1,9,-5,AIR:0)
Block(1,9,-4,AIR:0)
Block(1,9,-3,WOOD_STEP:5)
Block(1,9,-2,WOOD_DOUBLE_STEP:5)
Block(1,9,-1,WOOD_STEP:13)
Block(1,9,0,SMOOTH_BRICK:0)
Block(1,9,1,AIR:0)
Block(1,9,2,AIR:0)
Block(1,9,3,SMOOTH_BRICK:0)
Block(1,9,4,WOOD_STEP:13)
Block(1,9,5,WOOD_DOUBLE_STEP:5)
Block(1,9,6,WOOD_STEP:5)
Block(1,9,7,AIR:0)
Block(1,9,8,AIR:0)
Block(1,9,9,WOOD:1)
RandomBlock(1,10,-6,DARK_OAK_FENCE:0,30,STONE:6,100)
Block(1,10,-5,AIR:0)
Block(1,10,-4,AIR:0)
Block(1,10,-3,AIR:0)
Block(1,10,-2,AIR:0)
Block(1,10,-1,AIR:0)
Block(1,10,0,SMOOTH_BRICK:0)
Block(1,10,1,AIR:0)
Block(1,10,2,AIR:0)
Block(1,10,3,SMOOTH_BRICK:0)
Block(1,10,4,AIR:0)
Block(1,10,5,AIR:0)
Block(1,10,6,AIR:0)
Block(1,10,7,AIR:0)
Block(1,10,8,AIR:0)
RandomBlock(1,10,9,DARK_OAK_FENCE:0,30,STONE:6,100)
Block(1,11,-6,WOOD_STEP:13)
Block(1,11,-5,WOOD_STEP:13)
Block(1,11,-4,WOOD_STEP:13)
Block(1,11,-3,WOOD_STEP:13)
Block(1,11,-2,WOOD_STEP:13)
Block(1,11,-1,WOOD_STEP:13)
Block(1,11,0,SMOOTH_BRICK:0)
Block(1,11,1,IRON_TRAPDOOR:11)
Block(1,11,2,IRON_TRAPDOOR:11)
Block(1,11,3,SMOOTH_BRICK:0)
Block(1,11,4,WOOD_STEP:13)
Block(1,11,5,WOOD_STEP:13)
Block(1,11,6,WOOD_STEP:13)
Block(1,11,7,WOOD_STEP:13)
Block(1,11,8,WOOD_STEP:13)
Block(1,11,9,WOOD_STEP:13)
Block(1,12,-6,AIR:0)
Block(1,12,-5,AIR:0)
Block(1,12,-4,AIR:0)
Block(1,12,-3,AIR:0)
Block(1,12,-2,AIR:0)
Block(1,12,-1,COAL_ORE:0)
Block(1,12,0,SMOOTH_BRICK:0)
Block(1,12,1,AIR:0)
Block(1,12,2,HUGE_MUSHROOM_1:14)
Block(1,12,3,SMOOTH_BRICK:0)
Block(1,12,4,AIR:0)
Block(1,12,5,AIR:0)
Block(1,12,6,AIR:0)
Block(1,12,7,AIR:0)
Block(1,12,8,AIR:0)
Block(1,12,9,AIR:0)
Block(1,13,-6,AIR:0)
Block(1,13,-5,AIR:0)
Block(1,13,-4,AIR:0)
Block(1,13,-3,AIR:0)
Block(1,13,-2,AIR:0)
RandomBlock(1,13,-1,AIR:0,2,CHEST:2,../../../../Chests/Loot/mine_resources_01.nbt,10,CHEST:2,../../../../Chests/Loot/mine_resources_02.nbt,10,CHEST:2,../../../../Chests/Loot/mine_resources_03.nbt,10,CHEST:2,../../../../Chests/Loot/mine_resources_04.nbt,10,CHEST:2,../../../../Chests/Loot/mine_resources_05.nbt,10,CHEST:2,../../../../Chests/Loot/abandoned_mineshaft.nbt,10,CHEST:2,../../../../Chests/Loot/mine_resources_01.nbt,100)
Block(1,13,0,SMOOTH_BRICK:0)
Block(1,13,1,AIR:0)
Block(1,13,2,AIR:0)
Block(1,13,3,SMOOTH_BRICK:0)
Block(1,13,4,AIR:0)
Block(1,13,5,AIR:0)
Block(1,13,6,AIR:0)
Block(1,13,7,AIR:0)
Block(1,13,8,AIR:0)
Block(1,13,9,AIR:0)
Block(1,14,-6,WOOD:1)
Block(1,14,-5,AIR:0)
Block(1,14,-4,AIR:0)
Block(1,14,-3,AIR:0)
Block(1,14,-2,AIR:0)
Block(1,14,-1,AIR:0)
Block(1,14,0,SMOOTH_BRICK:0)
Block(1,14,1,IRON_FENCE:0)
Block(1,14,2,IRON_FENCE:0)
Block(1,14,3,SMOOTH_BRICK:0)
Block(1,14,4,AIR:0)
Block(1,14,5,AIR:0)
Block(1,14,6,AIR:0)
Block(1,14,7,AIR:0)
Block(1,14,8,AIR:0)
Block(1,14,9,WOOD:1)
Block(1,15,-6,WOOD:5)
Block(1,15,-5,TRAP_DOOR:8)
Block(1,15,-4,TRAP_DOOR:8)
Block(1,15,-3,TRAP_DOOR:8)
Block(1,15,-2,TRAP_DOOR:8)
Block(1,15,-1,TRAP_DOOR:8)
Block(1,15,0,SMOOTH_BRICK:0)
Block(1,15,1,IRON_TRAPDOOR:9)
Block(1,15,2,IRON_TRAPDOOR:9)
Block(1,15,3,SMOOTH_BRICK:0)
Block(1,15,4,TRAP_DOOR:8)
Block(1,15,5,TRAP_DOOR:8)
Block(1,15,6,TRAP_DOOR:8)
Block(1,15,7,TRAP_DOOR:8)
Block(1,15,8,TRAP_DOOR:8)
Block(1,15,9,WOOD:5)
Block(2,0,-6,LOG:1)
Block(2,0,9,LOG:1)
Block(2,1,-6,WOOD:5)
Block(2,1,-5,WOOD:5)
Block(2,1,-4,SMOOTH_BRICK:0)
Block(2,1,-3,SMOOTH_BRICK:0)
Block(2,1,-2,WOOD:5)
Block(2,1,-1,STONE:6)
Block(2,1,0,SMOOTH_BRICK:0)
Block(2,1,1,SMOOTH_BRICK:0)
Block(2,1,2,SMOOTH_BRICK:0)
Block(2,1,3,SMOOTH_BRICK:0)
Block(2,1,4,STONE:6)
Block(2,1,5,WOOD:5)
Block(2,1,6,WOOD:5)
Block(2,1,7,WOOD:5)
Block(2,1,8,WOOD:5)
Block(2,1,9,WOOD:5)
Block(2,2,-6,DARK_OAK_STAIRS:1)
Block(2,2,-5,AIR:0)
Block(2,2,-4,AIR:0)
Block(2,2,-3,AIR:0)
Block(2,2,-2,AIR:0)
Block(2,2,-1,SMOOTH_STAIRS:6)
Block(2,2,0,SMOOTH_BRICK:0)
Block(2,2,1,SMOOTH_BRICK:0)
Block(2,2,2,SMOOTH_BRICK:0)
Block(2,2,3,SMOOTH_BRICK:0)
Block(2,2,4,IRON_FENCE:0)
Block(2,2,5,AIR:0)
Block(2,2,6,SMOOTH_BRICK:3)
Block(2,2,7,SPRUCE_FENCE:0)
Block(2,2,8,AIR:0)
Block(2,2,9,DARK_OAK_STAIRS:1)
Block(2,3,-6,DARK_OAK_STAIRS:5)
Block(2,3,-5,AIR:0)
Block(2,3,-4,AIR:0)
Block(2,3,-3,AIR:0)
Block(2,3,-2,AIR:0)
Block(2,3,0,SMOOTH_BRICK:0)
Block(2,3,1,SMOOTH_BRICK:0)
Block(2,3,2,SMOOTH_BRICK:0)
Block(2,3,3,SMOOTH_BRICK:0)
Block(2,3,4,IRON_FENCE:0)
Block(2,3,5,AIR:0)
Block(2,3,6,IRON_PLATE:0)
Block(2,3,7,AIR:0)
Block(2,3,8,AIR:0)
Block(2,3,9,DARK_OAK_STAIRS:5)
Block(2,4,-6,WOOD:1)
Block(2,4,-5,AIR:0)
Block(2,4,-4,AIR:0)
Block(2,4,-3,AIR:0)
Block(2,4,-2,AIR:0)
Block(2,4,-1,AIR:0)
Block(2,4,0,SMOOTH_BRICK:0)
Block(2,4,1,SMOOTH_BRICK:0)
Block(2,4,2,SMOOTH_BRICK:0)
Block(2,4,3,SMOOTH_BRICK:0)
Block(2,4,4,SMOOTH_STAIRS:1)
Block(2,4,5,AIR:0)
Block(2,4,6,AIR:0)
Block(2,4,7,WOOD_STEP:13)
Block(2,4,8,AIR:0)
Block(2,4,9,WOOD:1)
Block(2,5,-6,SPRUCE_FENCE:0)
Block(2,5,-5,AIR:0)
Block(2,5,-4,AIR:0)
Block(2,5,-3,AIR:0)
Block(2,5,-2,AIR:0)
RandomBlock(2,5,-1,WALL_BANNER:2,../../NBT/Banners/banner_sun.nbt,50,WALL_BANNER:2,../../NBT/Banners/quarry_banner_0.nbt,10,WALL_BANNER:2,../../NBT/Banners/quarry_banner_1.nbt,10,WALL_BANNER:2,../../NBT/Banners/quarry_banner_2.nbt,10,WALL_BANNER:2,../../NBT/Banners/quarry_banner_3.nbt,10,WALL_BANNER:2,../../NBT/Banners/quarry_banner_4.nbt,100)
Block(2,5,0,SMOOTH_BRICK:0)
Block(2,5,1,SMOOTH_BRICK:0)
Block(2,5,2,SMOOTH_BRICK:0)
Block(2,5,3,SMOOTH_BRICK:0)
Block(2,5,4,AIR:0)
Block(2,5,5,AIR:0)
Block(2,5,6,AIR:0)
Block(2,5,7,AIR:0)
Block(2,5,8,AIR:0)
Block(2,5,9,SPRUCE_FENCE:0)
Block(2,6,-6,WOOD:5)
Block(2,6,-5,WOOD:5)
Block(2,6,-4,WOOD:5)
Block(2,6,-3,WOOD:5)
Block(2,6,-2,WOOD:5)
Block(2,6,-1,WOOD:5)
Block(2,6,0,SMOOTH_BRICK:0)
Block(2,6,1,SMOOTH_BRICK:0)
Block(2,6,2,SMOOTH_BRICK:0)
Block(2,6,3,SMOOTH_BRICK:0)
Block(2,6,4,WOOD:5)
Block(2,6,5,WOOD:5)
Block(2,6,6,WOOD:5)
Block(2,6,7,WOOD:5)
Block(2,6,8,WOOD:5)
Block(2,6,9,WOOD:5)
Block(2,7,-6,STONE:6)
Block(2,7,-5,CARPET:13)
Block(2,7,-4,CARPET:13)
Block(2,7,-3,SPRUCE_FENCE:0)
Block(2,7,-2,AIR:0)
Block(2,7,-1,BOOKSHELF:0)
Block(2,7,0,SMOOTH_BRICK:0)
Block(2,7,1,SMOOTH_BRICK:0)
Block(2,7,2,SMOOTH_BRICK:0)
Block(2,7,3,SMOOTH_BRICK:0)
Block(2,7,5,AIR:0)
Block(2,7,6,SPRUCE_FENCE:0)
Block(2,7,7,AIR:0)
Block(2,7,8,CARPET:13)
Block(2,7,9,STONE:6)
Block(2,8,-6,STONE:6)
Block(2,8,-5,AIR:0)
Block(2,8,-4,AIR:0)
Block(2,8,-3,SPRUCE_FENCE:0)
Block(2,8,-2,AIR:0)
Block(2,8,-1,BOOKSHELF:0)
Block(2,8,0,SMOOTH_BRICK:0)
Block(2,8,1,SMOOTH_BRICK:0)
Block(2,8,2,SMOOTH_BRICK:0)
Block(2,8,3,SMOOTH_BRICK:0)
Block(2,8,4,AIR:0)
Block(2,8,5,AIR:0)
Block(2,8,6,SPRUCE_FENCE:0)
Block(2,8,7,AIR:0)
Block(2,8,8,AIR:0)
Block(2,8,9,STONE:6)
Block(2,9,-6,WOOD:1)
Block(2,9,-5,AIR:0)
Block(2,9,-4,AIR:0)
Block(2,9,-3,WOOD_STEP:5)
Block(2,9,-2,WOOD_DOUBLE_STEP:5)
Block(2,9,-1,WOOD_STEP:13)
Block(2,9,0,SMOOTH_BRICK:0)
Block(2,9,1,SMOOTH_BRICK:0)
Block(2,9,2,SMOOTH_BRICK:0)
Block(2,9,3,SMOOTH_BRICK:0)
Block(2,9,4,WOOD_STEP:13)
Block(2,9,5,WOOD_DOUBLE_STEP:5)
Block(2,9,6,WOOD_STEP:5)
Block(2,9,7,AIR:0)
Block(2,9,8,AIR:0)
Block(2,9,9,WOOD:1)
Block(2,10,-6,SPRUCE_FENCE:0)
Block(2,10,-5,AIR:0)
Block(2,10,-4,AIR:0)
Block(2,10,-3,AIR:0)
Block(2,10,-2,AIR:0)
Block(2,10,-1,AIR:0)
Block(2,10,0,SMOOTH_BRICK:0)
Block(2,10,1,SMOOTH_BRICK:0)
Block(2,10,2,SMOOTH_BRICK:0)
Block(2,10,3,SMOOTH_BRICK:0)
Block(2,10,4,AIR:0)
Block(2,10,5,AIR:0)
Block(2,10,6,AIR:0)
Block(2,10,7,AIR:0)
Block(2,10,8,AIR:0)
Block(2,10,9,SPRUCE_FENCE:0)
Block(2,11,-6,WOOD:5)
Block(2,11,-5,WOOD:5)
Block(2,11,-4,WOOD:5)
Block(2,11,-3,WOOD:5)
Block(2,11,-2,WOOD:5)
Block(2,11,-1,WOOD:5)
Block(2,11,0,SMOOTH_BRICK:0)
Block(2,11,1,SMOOTH_BRICK:0)
Block(2,11,2,SMOOTH_BRICK:0)
Block(2,11,3,SMOOTH_BRICK:0)
Block(2,11,4,WOOD:5)
Block(2,11,5,WOOD:5)
Block(2,11,6,WOOD:5)
Block(2,11,7,WOOD:5)
Block(2,11,8,WOOD:5)
Block(2,11,9,WOOD:5)
Block(2,12,-6,SPRUCE_FENCE:0)
Block(2,12,-5,AIR:0)
Block(2,12,-4,AIR:0)
Block(2,12,-3,AIR:0)
Block(2,12,-2,AIR:0)
Block(2,12,-1,AIR:0)
Block(2,12,0,SMOOTH_BRICK:0)
Block(2,12,1,SPRUCE_DOOR:2)
Block(2,12,2,SPRUCE_DOOR:2)
Block(2,12,3,SMOOTH_BRICK:0)
Block(2,12,4,AIR:0)
Block(2,12,5,AIR:0)
Block(2,12,6,AIR:0)
Block(2,12,7,AIR:0)
Block(2,12,8,AIR:0)
RandomBlock(2,12,9,DARK_OAK_FENCE:0,30,STONE:6,100)
Block(2,13,-6,SPRUCE_FENCE:0)
Block(2,13,-5,AIR:0)
Block(2,13,-4,AIR:0)
Block(2,13,-3,AIR:0)
Block(2,13,-2,AIR:0)
Block(2,13,-1,AIR:0)
Block(2,13,0,SMOOTH_BRICK:0)
Block(2,13,1,SPRUCE_DOOR:9)
Block(2,13,2,SPRUCE_DOOR:8)
Block(2,13,3,SMOOTH_BRICK:0)
Block(2,13,4,AIR:0)
Block(2,13,5,AIR:0)
Block(2,13,6,AIR:0)
Block(2,13,7,AIR:0)
Block(2,13,8,AIR:0)
RandomBlock(2,13,9,DARK_OAK_FENCE:0,30,STONE:6,100)
Block(2,14,-6,WOOD:1)
Block(2,14,-5,AIR:0)
Block(2,14,-4,AIR:0)
Block(2,14,-3,AIR:0)
Block(2,14,-2,AIR:0)
Block(2,14,-1,AIR:0)
Block(2,14,0,SMOOTH_BRICK:0)
Block(2,14,1,SMOOTH_BRICK:0)
Block(2,14,2,SMOOTH_BRICK:0)
Block(2,14,3,SMOOTH_BRICK:0)
Block(2,14,4,AIR:0)
Block(2,14,5,AIR:0)
Block(2,14,6,AIR:0)
Block(2,14,7,AIR:0)
Block(2,14,8,AIR:0)
Block(2,14,9,WOOD:1)
Block(2,15,-6,WOOD:5)
Block(2,15,-5,WOOD:5)
Block(2,15,-4,WOOD:5)
Block(2,15,-3,WOOD:5)
Block(2,15,-2,WOOD:5)
Block(2,15,-1,WOOD:5)
Block(2,15,0,SMOOTH_BRICK:0)
Block(2,15,1,SMOOTH_BRICK:0)
Block(2,15,2,SMOOTH_BRICK:0)
Block(2,15,3,SMOOTH_BRICK:0)
Block(2,15,4,WOOD:5)
Block(2,15,5,WOOD:5)
Block(2,15,6,WOOD:5)
Block(2,15,7,WOOD:5)
Block(2,15,8,WOOD:5)
Block(2,15,9,WOOD:5)
Block(3,1,-6,WOOD:5)
Block(3,1,-5,WOOD:5)
Block(3,1,-4,SMOOTH_BRICK:0)
Block(3,1,-3,SMOOTH_BRICK:0)
Block(3,1,-2,WOOD:5)
Block(3,1,-1,STONE:6)
Block(3,1,0,STONE:6)
Block(3,1,1,STONE:6)
Block(3,1,2,STONE:6)
Block(3,1,3,STONE:6)
Block(3,1,4,STONE:6)
Block(3,1,5,WOOD:5)
Block(3,1,6,WOOD:5)
Block(3,1,7,WOOD:5)
Block(3,1,8,WOOD:5)
Block(3,1,9,WOOD:5)
Block(3,2,-6,SMOOTH_BRICK:0)
Block(3,2,-5,SPRUCE_FENCE:0)
Block(3,2,-4,AIR:0)
Block(3,2,-3,AIR:0)
Block(3,2,-2,AIR:0)
Block(3,2,-1,SMOOTH_STAIRS:6)
Block(3,2,0,SMOOTH_STAIRS:5)
Block(3,2,1,SMOOTH_STAIRS:5)
Block(3,2,2,SMOOTH_STAIRS:5)
Block(3,2,3,SPRUCE_FENCE:0)
Block(3,2,4,AIR:0)
Block(3,2,5,AIR:0)
Block(3,2,6,SMOOTH_STAIRS:5)
Block(3,2,7,SPRUCE_FENCE:0)
Block(3,2,8,AIR:0)
Block(3,2,9,SMOOTH_BRICK:0)
Block(3,3,-6,SMOOTH_BRICK:0)
Block(3,3,-5,TORCH:5)
Block(3,3,-4,AIR:0)
Block(3,3,-3,AIR:0)
Block(3,3,-2,AIR:0)
Block(3,3,-1,IRON_PLATE:0)
RandomBlock(3,3,0,AIR:0,20,CHEST:5,../../../../Chests/Loot/JunkChest_1.nbt,10,CHEST:5,../../../../Chests/Loot/JunkChest_2.nbt,10,CHEST:5,../../../../Chests/Loot/JunkChest_3.nbt,10,CHEST:5,../../../../Chests/Loot/JunkChest_4.nbt,10,CHEST:5,../../../../Chests/Loot/JunkChest_5.nbt,10,CHEST:5,../../../../Chests/Lore/HiddenMine_1.nbt,1,CHEST:5,../../../../Chests/Lore/HiddenMine_2.nbt,1,CHEST:5,../../../../Chests/Lore/HiddenMine_3.nbt,1,CHEST:5,../../../../Chests/Lore/HiddenMine_4.nbt,1,CHEST:5,../../../../Chests/Lore/HiddenMine_5.nbt,1,CHEST:5,../../../../Chests/Loot/Common1.nbt,10,CHEST:5,../../../../Chests/Loot/Common2.nbt,10,CHEST:5,../../../../Chests/Loot/Common3.nbt,10,CHEST:5,../../../../Chests/Loot/Common4.nbt,10,CHEST:5,../../../../Chests/Loot/Common5.nbt,10,CHEST:5,../../../../Chests/Loot/Common6.nbt,10,CHEST:5,../../../../Chests/Loot/Common7.nbt,10,CHEST:5,../../../../Chests/Loot/Common8.nbt,10,CHEST:5,../../../../Chests/Loot/Common9.nbt,10,CHEST:5,../../../../Chests/Loot/Common10.nbt,10,CHEST:5,../../../../Chests/Loot/Common10.nbt,11,CHEST:5,../../../../Chests/Loot/Common12.nbt,10,CHEST:5,../../../../Chests/Loot/Common13.nbt,10,CHEST:5,../../../../Chests/Loot/Common14.nbt,10,CHEST:5,../../../../Chests/Loot/Common15.nbt,10,CHEST:5,../../../../Chests/Lore/HiddenMine_1.nbt,2,CHEST:5,../../../../Chests/Lore/HiddenMine_3.nbt,2,CHEST:5,../../../../Chests/Lore/HiddenMine_4.nbt,2,CHEST:5,../../../../Chests/Lore/HiddenMine_5.nbt,2,CHEST:5,../../../../Chests/Lore/HiddenMine_5.nbt,2,CHEST:5,../../../../Chests/Loot/Rare1.nbt,5,CHEST:5,../../../../Chests/Loot/Rare2.nbt,5,CHEST:5,../../../../Chests/Loot/Rare3.nbt,5,CHEST:5,../../../../Chests/Loot/Rare4.nbt,5,CHEST:5,../../../../Chests/Loot/Rare5.nbt,5,CHEST:5,../../../../Chests/Loot/Rare6.nbt,5,CHEST:5,../../../../Chests/Loot/Rare7.nbt,5,CHEST:5,../../../../Chests/Loot/Rare8.nbt,5,CHEST:5,../../../../Chests/Loot/Rare9.nbt,5,CHEST:5,../../../../Chests/Loot/Rare10.nbt,5,CHEST:5,../../../../Chests/Loot/Rare11.nbt,5,CHEST:5,../../../../Chests/Loot/Rare12.nbt,5,CHEST:5,../../../../Chests/Loot/Rare13.nbt,5,CHEST:5,../../../../Chests/Loot/Rare14.nbt,5,CHEST:5,../../../../Chests/Loot/Rare15.nbt,5,CHEST:5,../../../../Chests/Loot/Epic1.nbt,2,CHEST:5,../../../../Chests/Loot/Epic2.nbt,2,CHEST:5,../../../../Chests/Loot/Epic3.nbt,2,CHEST:5,../../../../Chests/Loot/Epic4.nbt,2,CHEST:5,../../../../Chests/Loot/Epic5.nbt,2,CHEST:5,../../../../Chests/Loot/Epic6.nbt,2,CHEST:5,../../../../Chests/Loot/Epic7.nbt,2,CHEST:5,../../../../Chests/Loot/Epic8.nbt,2,CHEST:5,../../../../Chests/Loot/Epic9.nbt,2,CHEST:5,../../../../Chests/Loot/Epic10.nbt,2,CHEST:5,../../../../Chests/Loot/Epic11.nbt,2,CHEST:5,../../../../Chests/Loot/Epic12.nbt,2,CHEST:5,../../../../Chests/Loot/Epic13.nbt,2,CHEST:5,../../../../Chests/Loot/Epic14.nbt,2,CHEST:5,../../../../Chests/Loot/Epic15.nbt,5,CHEST:5,../../../../Chests/Loot/Rare1.nbt,5,CHEST:5,../../../../Chests/Loot/Rare2.nbt,5,CHEST:5,../../../../Chests/Loot/Rare3.nbt,5,CHEST:5,../../../../Chests/Loot/Rare4.nbt,5,CHEST:5,../../../../Chests/Loot/Rare5.nbt,10,CHEST:5,../../../../Chests/Loot/Rare6.nbt,10,CHEST:5,../../../../Chests/Loot/Rare7.nbt,10,CHEST:5,../../../../Chests/Loot/Rare8.nbt,10,CHEST:5,../../../../Chests/Loot/Rare9.nbt,10,CHEST:5,../../../../Chests/Loot/Rare10.nbt,15,CHEST:5,../../../../Chests/Loot/Rare11.nbt,15,CHEST:5,../../../../Chests/Loot/Rare12.nbt,15,CHEST:5,../../../../Chests/Loot/Rare13.nbt,15,CHEST:5,../../../../Chests/Loot/Rare14.nbt,15,CHEST:5,../../../../Chests/Loot/Rare15.nbt,15,CHEST:5,../../../../Chests/Loot/Epic15.nbt,100)
RandomBlock(3,3,2,AIR:0,20,CHEST:5,../../../../Chests/Loot/JunkChest_1.nbt,10,CHEST:5,../../../../Chests/Loot/JunkChest_2.nbt,10,CHEST:5,../../../../Chests/Loot/JunkChest_3.nbt,10,CHEST:5,../../../../Chests/Loot/JunkChest_4.nbt,10,CHEST:5,../../../../Chests/Loot/JunkChest_5.nbt,10,CHEST:5,../../../../Chests/Lore/HiddenMine_1.nbt,1,CHEST:5,../../../../Chests/Lore/HiddenMine_2.nbt,1,CHEST:5,../../../../Chests/Lore/HiddenMine_3.nbt,1,CHEST:5,../../../../Chests/Lore/HiddenMine_4.nbt,1,CHEST:5,../../../../Chests/Lore/HiddenMine_5.nbt,1,CHEST:5,../../../../Chests/Loot/Common1.nbt,10,CHEST:5,../../../../Chests/Loot/Common2.nbt,10,CHEST:5,../../../../Chests/Loot/Common3.nbt,10,CHEST:5,../../../../Chests/Loot/Common4.nbt,10,CHEST:5,../../../../Chests/Loot/Common5.nbt,10,CHEST:5,../../../../Chests/Loot/Common6.nbt,10,CHEST:5,../../../../Chests/Loot/Common7.nbt,10,CHEST:5,../../../../Chests/Loot/Common8.nbt,10,CHEST:5,../../../../Chests/Loot/Common9.nbt,10,CHEST:5,../../../../Chests/Loot/Common10.nbt,10,CHEST:5,../../../../Chests/Loot/Common10.nbt,11,CHEST:5,../../../../Chests/Loot/Common12.nbt,10,CHEST:5,../../../../Chests/Loot/Common13.nbt,10,CHEST:5,../../../../Chests/Loot/Common14.nbt,10,CHEST:5,../../../../Chests/Loot/Common15.nbt,10,CHEST:5,../../../../Chests/Lore/HiddenMine_1.nbt,2,CHEST:5,../../../../Chests/Lore/HiddenMine_3.nbt,2,CHEST:5,../../../../Chests/Lore/HiddenMine_4.nbt,2,CHEST:5,../../../../Chests/Lore/HiddenMine_5.nbt,2,CHEST:5,../../../../Chests/Lore/HiddenMine_5.nbt,2,CHEST:5,../../../../Chests/Loot/Rare1.nbt,5,CHEST:5,../../../../Chests/Loot/Rare2.nbt,5,CHEST:5,../../../../Chests/Loot/Rare3.nbt,5,CHEST:5,../../../../Chests/Loot/Rare4.nbt,5,CHEST:5,../../../../Chests/Loot/Rare5.nbt,5,CHEST:5,../../../../Chests/Loot/Rare6.nbt,5,CHEST:5,../../../../Chests/Loot/Rare7.nbt,5,CHEST:5,../../../../Chests/Loot/Rare8.nbt,5,CHEST:5,../../../../Chests/Loot/Rare9.nbt,5,CHEST:5,../../../../Chests/Loot/Rare10.nbt,5,CHEST:5,../../../../Chests/Loot/Rare11.nbt,5,CHEST:5,../../../../Chests/Loot/Rare12.nbt,5,CHEST:5,../../../../Chests/Loot/Rare13.nbt,5,CHEST:5,../../../../Chests/Loot/Rare14.nbt,5,CHEST:5,../../../../Chests/Loot/Rare15.nbt,5,CHEST:5,../../../../Chests/Loot/Epic1.nbt,2,CHEST:5,../../../../Chests/Loot/Epic2.nbt,2,CHEST:5,../../../../Chests/Loot/Epic3.nbt,2,CHEST:5,../../../../Chests/Loot/Epic4.nbt,2,CHEST:5,../../../../Chests/Loot/Epic5.nbt,2,CHEST:5,../../../../Chests/Loot/Epic6.nbt,2,CHEST:5,../../../../Chests/Loot/Epic7.nbt,2,CHEST:5,../../../../Chests/Loot/Epic8.nbt,2,CHEST:5,../../../../Chests/Loot/Epic9.nbt,2,CHEST:5,../../../../Chests/Loot/Epic10.nbt,2,CHEST:5,../../../../Chests/Loot/Epic11.nbt,2,CHEST:5,../../../../Chests/Loot/Epic12.nbt,2,CHEST:5,../../../../Chests/Loot/Epic13.nbt,2,CHEST:5,../../../../Chests/Loot/Epic14.nbt,2,CHEST:5,../../../../Chests/Loot/Epic15.nbt,5,CHEST:5,../../../../Chests/Loot/Rare1.nbt,5,CHEST:5,../../../../Chests/Loot/Rare2.nbt,5,CHEST:5,../../../../Chests/Loot/Rare3.nbt,5,CHEST:5,../../../../Chests/Loot/Rare4.nbt,5,CHEST:5,../../../../Chests/Loot/Rare5.nbt,10,CHEST:5,../../../../Chests/Loot/Rare6.nbt,10,CHEST:5,../../../../Chests/Loot/Rare7.nbt,10,CHEST:5,../../../../Chests/Loot/Rare8.nbt,10,CHEST:5,../../../../Chests/Loot/Rare9.nbt,10,CHEST:5,../../../../Chests/Loot/Rare10.nbt,15,CHEST:5,../../../../Chests/Loot/Rare11.nbt,15,CHEST:5,../../../../Chests/Loot/Rare12.nbt,15,CHEST:5,../../../../Chests/Loot/Rare13.nbt,15,CHEST:5,../../../../Chests/Loot/Rare14.nbt,15,CHEST:5,../../../../Chests/Loot/Rare15.nbt,15,CHEST:5,../../../../Chests/Loot/Epic15.nbt,100)
Block(3,3,3,AIR:0)
Block(3,3,4,AIR:0)
Block(3,3,5,AIR:0)
Block(3,3,6,IRON_PLATE:0)
Block(3,3,7,AIR:0)
Block(3,3,8,AIR:0)
Block(3,3,9,SMOOTH_BRICK:0)
Block(3,4,-6,SMOOTH_BRICK:0)
Block(3,4,-5,AIR:0)
Block(3,4,-4,AIR:0)
Block(3,4,-3,AIR:0)
Block(3,4,-2,AIR:0)
Block(3,4,-1,AIR:0)
Block(3,4,0,AIR:0)
Block(3,4,1,AIR:0)
Block(3,4,2,AIR:0)
Block(3,4,3,WOOD_STEP:13)
Block(3,4,4,AIR:0)
Block(3,4,5,AIR:0)
Block(3,4,6,AIR:0)
Block(3,4,7,WOOD_STEP:13)
Block(3,4,8,AIR:0)
Block(3,4,9,SMOOTH_BRICK:0)
Block(3,5,-6,SMOOTH_BRICK:0)
RandomBlock(3,5,-5,WALL_BANNER:3,../../NBT/Banners/banner_sun.nbt,50,WALL_BANNER:3,../../NBT/Banners/quarry_banner_0.nbt,10,WALL_BANNER:3,../../NBT/Banners/quarry_banner_1.nbt,10,WALL_BANNER:3,../../NBT/Banners/quarry_banner_2.nbt,10,WALL_BANNER:3,../../NBT/Banners/quarry_banner_3.nbt,10,WALL_BANNER:3,../../NBT/Banners/quarry_banner_4.nbt,100)
Block(3,5,-4,AIR:0)
Block(3,5,-3,AIR:0)
Block(3,5,-2,AIR:0)
Block(3,5,-1,AIR:0)
RandomBlock(3,5,0,WALL_BANNER:5,../../NBT/Banners/banner_sun.nbt,50,WALL_BANNER:5,../../NBT/Banners/quarry_banner_0.nbt,10,WALL_BANNER:5,../../NBT/Banners/quarry_banner_1.nbt,10,WALL_BANNER:5,../../NBT/Banners/quarry_banner_2.nbt,10,WALL_BANNER:5,../../NBT/Banners/quarry_banner_3.nbt,10,WALL_BANNER:5,../../NBT/Banners/quarry_banner_4.nbt,100)
Block(3,5,1,AIR:0)
RandomBlock(3,5,2,WALL_BANNER:5,../../NBT/Banners/banner_sun.nbt,50,WALL_BANNER:5,../../NBT/Banners/quarry_banner_0.nbt,10,WALL_BANNER:5,../../NBT/Banners/quarry_banner_1.nbt,10,WALL_BANNER:5,../../NBT/Banners/quarry_banner_2.nbt,10,WALL_BANNER:5,../../NBT/Banners/quarry_banner_3.nbt,10,WALL_BANNER:5,../../NBT/Banners/quarry_banner_4.nbt,100)
Block(3,5,3,AIR:0)
Block(3,5,4,AIR:0)
Block(3,5,5,AIR:0)
Block(3,5,6,AIR:0)
Block(3,5,7,AIR:0)
RandomBlock(3,5,8,WALL_BANNER:2,../../NBT/Banners/banner_sun.nbt,50,WALL_BANNER:2,../../NBT/Banners/quarry_banner_0.nbt,10,WALL_BANNER:2,../../NBT/Banners/quarry_banner_1.nbt,10,WALL_BANNER:2,../../NBT/Banners/quarry_banner_2.nbt,10,WALL_BANNER:2,../../NBT/Banners/quarry_banner_3.nbt,10,WALL_BANNER:2,../../NBT/Banners/quarry_banner_4.nbt,100)
Block(3,5,9,SMOOTH_BRICK:0)
Block(3,6,-6,WOOD:5)
Block(3,6,-5,WOOD_STEP:13)
Block(3,6,-4,WOOD_STEP:13)
Block(3,6,-3,WOOD_STEP:13)
Block(3,6,-2,WOOD_STEP:13)
Block(3,6,-1,WOOD_STEP:13)
Block(3,6,0,WOOD:5)
Block(3,6,1,WOOD_STEP:13)
Block(3,6,2,WOOD_STEP:13)
Block(3,6,3,WOOD:5)
Block(3,6,4,WOOD_STEP:13)
Block(3,6,5,WOOD_STEP:13)
Block(3,6,6,WOOD_STEP:13)
Block(3,6,7,WOOD_STEP:13)
Block(3,6,8,WOOD_STEP:13)
Block(3,6,9,WOOD:5)
Block(3,7,-6,SMOOTH_BRICK:0)
Block(3,7,-5,SPRUCE_FENCE:0)
Block(3,7,-4,CARPET:13)
Block(3,7,-3,DARK_OAK_STAIRS:5)
Block(3,7,-2,AIR:0)
Block(3,7,-1,AIR:0)
Block(3,7,2,BOOKSHELF:0)
Block(3,7,4,AIR:0)
Block(3,7,5,AIR:0)
Block(3,7,6,DARK_OAK_STAIRS:5)
Block(3,7,7,CARPET:13)
Block(3,7,8,SPRUCE_FENCE:0)
Block(3,7,9,SMOOTH_BRICK:0)
Block(3,8,-6,SMOOTH_BRICK:0)
Block(3,8,-5,TORCH:5)
Block(3,8,-4,AIR:0)
Block(3,8,-3,WOOD_PLATE:0)
Block(3,8,-2,AIR:0)
Block(3,8,-1,AIR:0)
Block(3,8,0,AIR:0)
Block(3,8,1,AIR:0)
Block(3,8,2,BOOKSHELF:0)
Block(3,8,3,AIR:0)
Block(3,8,4,AIR:0)
Block(3,8,5,AIR:0)
Block(3,8,6,WOOD_PLATE:0)
Block(3,8,7,AIR:0)
Block(3,8,8,TORCH:5)
Block(3,8,9,SMOOTH_BRICK:0)
Block(3,9,-6,SMOOTH_BRICK:0)
Block(3,9,-5,AIR:0)
Block(3,9,-4,AIR:0)
Block(3,9,-3,AIR:0)
Block(3,9,-2,WOOD_STEP:5)
Block(3,9,-1,WOOD_STEP:13)
Block(3,9,0,WOOD_STEP:13)
Block(3,9,1,WOOD_STEP:13)
Block(3,9,2,WOOD_STEP:13)
Block(3,9,3,WOOD_STEP:13)
Block(3,9,4,WOOD_STEP:13)
Block(3,9,5,WOOD_STEP:5)
Block(3,9,6,AIR:0)
Block(3,9,7,AIR:0)
Block(3,9,8,AIR:0)
Block(3,9,9,SMOOTH_BRICK:0)
Block(3,10,-6,SMOOTH_BRICK:0)
RandomBlock(3,10,-5,WALL_BANNER:3,../../NBT/Banners/banner_sun.nbt,50,WALL_BANNER:3,../../NBT/Banners/quarry_banner_0.nbt,10,WALL_BANNER:3,../../NBT/Banners/quarry_banner_1.nbt,10,WALL_BANNER:3,../../NBT/Banners/quarry_banner_2.nbt,10,WALL_BANNER:3,../../NBT/Banners/quarry_banner_3.nbt,10,WALL_BANNER:3,../../NBT/Banners/quarry_banner_4.nbt,100)
Block(3,10,-4,AIR:0)
Block(3,10,-3,AIR:0)
Block(3,10,-2,AIR:0)
Block(3,10,-1,AIR:0)
Block(3,10,0,AIR:0)
Block(3,10,1,AIR:0)
Block(3,10,2,AIR:0)
Block(3,10,3,AIR:0)
Block(3,10,4,AIR:0)
Block(3,10,5,AIR:0)
Block(3,10,6,AIR:0)
Block(3,10,7,AIR:0)
RandomBlock(3,10,8,WALL_BANNER:2,../../NBT/Banners/banner_sun.nbt,50,WALL_BANNER:2,../../NBT/Banners/quarry_banner_0.nbt,10,WALL_BANNER:2,../../NBT/Banners/quarry_banner_1.nbt,10,WALL_BANNER:2,../../NBT/Banners/quarry_banner_2.nbt,10,WALL_BANNER:2,../../NBT/Banners/quarry_banner_3.nbt,10,WALL_BANNER:2,../../NBT/Banners/quarry_banner_4.nbt,100)
Block(3,10,9,SMOOTH_BRICK:0)
Block(3,11,-6,WOOD:5)
Block(3,11,-5,WOOD_STEP:13)
Block(3,11,-4,WOOD_STEP:13)
Block(3,11,-3,WOOD_STEP:13)
Block(3,11,-2,WOOD_STEP:13)
Block(3,11,-1,WOOD_STEP:13)
Block(3,11,0,WOOD:5)
Block(3,11,1,WOOD_STEP:13)
Block(3,11,2,WOOD_STEP:13)
Block(3,11,3,WOOD:5)
Block(3,11,4,WOOD_STEP:13)
Block(3,11,5,WOOD_STEP:13)
Block(3,11,6,WOOD_STEP:13)
Block(3,11,7,WOOD_STEP:13)
Block(3,11,8,WOOD_STEP:13)
Block(3,11,9,WOOD:5)
Block(3,12,-6,SMOOTH_BRICK:0)
Block(3,12,-5,SPRUCE_FENCE:0)
Block(3,12,-4,AIR:0)
Block(3,12,-3,AIR:0)
Block(3,12,-2,AIR:0)
Block(3,12,-1,AIR:0)
Block(3,12,0,SPRUCE_FENCE:0)
Block(3,12,1,AIR:0)
Block(3,12,2,AIR:0)
Block(3,12,3,SPRUCE_FENCE:0)
Block(3,12,4,AIR:0)
Block(3,12,5,AIR:0)
Block(3,12,6,AIR:0)
Block(3,12,7,AIR:0)
Block(3,12,8,SPRUCE_FENCE:0)
Block(3,12,9,SMOOTH_BRICK:0)
Block(3,13,-6,SMOOTH_BRICK:0)
Block(3,13,-5,TORCH:5)
Block(3,13,-4,AIR:0)
Block(3,13,-3,AIR:0)
Block(3,13,-2,AIR:0)
Block(3,13,-1,AIR:0)
Block(3,13,0,SPRUCE_FENCE:0)
Block(3,13,1,AIR:0)
Block(3,13,2,AIR:0)
Block(3,13,3,SPRUCE_FENCE:0)
Block(3,13,4,AIR:0)
Block(3,13,5,AIR:0)
Block(3,13,6,AIR:0)
Block(3,13,7,AIR:0)
Block(3,13,8,TORCH:5)
Block(3,13,9,SMOOTH_BRICK:0)
Block(3,14,-6,SMOOTH_BRICK:0)
Block(3,14,-5,AIR:0)
Block(3,14,-4,AIR:0)
Block(3,14,-3,AIR:0)
Block(3,14,-2,AIR:0)
Block(3,14,-1,AIR:0)
Block(3,14,0,SPRUCE_FENCE:0)
Block(3,14,1,AIR:0)
Block(3,14,2,AIR:0)
Block(3,14,3,SPRUCE_FENCE:0)
Block(3,14,4,AIR:0)
Block(3,14,5,AIR:0)
Block(3,14,6,AIR:0)
Block(3,14,7,AIR:0)
Block(3,14,8,AIR:0)
Block(3,14,9,SMOOTH_BRICK:0)
Block(3,15,-6,WOOD:5)
Block(3,15,-5,TRAP_DOOR:8)
Block(3,15,-4,TRAP_DOOR:8)
Block(3,15,-3,TRAP_DOOR:8)
Block(3,15,-2,TRAP_DOOR:8)
Block(3,15,-1,TRAP_DOOR:8)
Block(3,15,0,WOOD:5)
Block(3,15,1,TRAP_DOOR:8)
Block(3,15,2,TRAP_DOOR:8)
Block(3,15,3,WOOD:5)
Block(3,15,4,TRAP_DOOR:8)
Block(3,15,5,TRAP_DOOR:8)
Block(3,15,6,TRAP_DOOR:8)
Block(3,15,7,TRAP_DOOR:8)
Block(3,15,8,TRAP_DOOR:8)
Block(3,15,9,WOOD:5)
Block(4,1,-6,WOOD:5)
Block(4,1,-5,WOOD:5)
Block(4,1,-4,SMOOTH_BRICK:0)
Block(4,1,-3,SMOOTH_BRICK:0)
Block(4,1,-2,WOOD:5)
Block(4,1,-1,WOOD:5)
Block(4,1,0,WOOD:5)
Block(4,1,1,WOOD:5)
Block(4,1,2,WOOD:5)
Block(4,1,3,WOOD:5)
Block(4,1,4,WOOD:5)
Block(4,1,5,WOOD:5)
Block(4,1,6,WOOD:5)
Block(4,1,7,WOOD:5)
Block(4,1,8,WOOD:5)
Block(4,1,9,WOOD:5)
RandomBlock(4,2,-6,DARK_OAK_FENCE:0,30,STONE:6,100)
Block(4,2,-5,AIR:0)
Block(4,2,-4,AIR:0)
Block(4,2,-3,AIR:0)
Block(4,2,-2,AIR:0)
Block(4,2,-1,AIR:0)
Block(4,2,0,AIR:0)
Block(4,2,1,AIR:0)
Block(4,2,2,AIR:0)
Block(4,2,3,SPRUCE_FENCE:0)
Block(4,2,4,SPRUCE_FENCE:0)
Block(4,2,5,AIR:0)
Block(4,2,6,SPRUCE_FENCE:0)
Block(4,2,7,SPRUCE_FENCE:0)
Block(4,2,8,AIR:0)
RandomBlock(4,2,9,DARK_OAK_FENCE:0,30,STONE:6,100)
RandomBlock(4,3,-6,DARK_OAK_FENCE:0,30,STONE:6,100)
Block(4,3,-5,AIR:0)
Block(4,3,-4,AIR:0)
Block(4,3,-3,AIR:0)
Block(4,3,-2,AIR:0)
Block(4,3,-1,AIR:0)
Block(4,3,0,AIR:0)
Block(4,3,1,AIR:0)
Block(4,3,2,AIR:0)
Block(4,3,3,AIR:0)
Block(4,3,4,AIR:0)
Block(4,3,5,AIR:0)
Block(4,3,6,TORCH:5)
Block(4,3,7,AIR:0)
Block(4,3,8,AIR:0)
RandomBlock(4,3,9,DARK_OAK_FENCE:0,30,STONE:6,100)
RandomBlock(4,4,-6,DARK_OAK_FENCE:0,30,STONE:6,100)
Block(4,4,-5,AIR:0)
Block(4,4,-4,AIR:0)
Block(4,4,-3,AIR:0)
Block(4,4,-2,AIR:0)
Block(4,4,-1,AIR:0)
Block(4,4,0,AIR:0)
Block(4,4,1,AIR:0)
Block(4,4,2,AIR:0)
Block(4,4,3,WOOD_STEP:13)
Block(4,4,4,WOOD_STEP:13)
Block(4,4,5,WOOD_STEP:13)
Block(4,4,6,WOOD_STEP:13)
Block(4,4,7,WOOD_STEP:13)
Block(4,4,8,AIR:0)
RandomBlock(4,4,9,DARK_OAK_FENCE:0,30,STONE:6,100)
RandomBlock(4,5,-6,DARK_OAK_FENCE:0,30,STONE:6,100)
Block(4,5,-5,AIR:0)
Block(4,5,-4,AIR:0)
Block(4,5,-3,AIR:0)
Block(4,5,-2,AIR:0)
Block(4,5,-1,AIR:0)
Block(4,5,0,AIR:0)
Block(4,5,1,AIR:0)
Block(4,5,2,AIR:0)
Block(4,5,3,SPRUCE_FENCE:0)
Block(4,5,4,AIR:0)
Block(4,5,5,AIR:0)
Block(4,5,6,AIR:0)
Block(4,5,7,SPRUCE_FENCE:0)
Block(4,5,8,AIR:0)
RandomBlock(4,5,9,DARK_OAK_FENCE:0,30,STONE:6,100)
Block(4,6,-6,WOOD:5)
Block(4,6,-5,WOOD_STEP:13)
Block(4,6,-4,WOOD_STEP:13)
Block(4,6,-3,WOOD_STEP:13)
Block(4,6,-2,WOOD_STEP:13)
Block(4,6,-1,WOOD_STEP:13)
Block(4,6,0,WOOD:5)
Block(4,6,1,WOOD_STEP:13)
Block(4,6,2,WOOD_STEP:13)
Block(4,6,3,WOOD:5)
Block(4,6,4,WOOD_STEP:13)
Block(4,6,5,WOOD_STEP:13)
Block(4,6,6,WOOD_STEP:13)
Block(4,6,7,WOOD_DOUBLE_STEP:5)
Block(4,6,8,WOOD_STEP:13)
Block(4,6,9,WOOD:5)
RandomBlock(4,7,-6,DARK_OAK_FENCE:0,30,STONE:6,100)
Block(4,7,-5,AIR:0)
Block(4,7,-4,CARPET:13)
Block(4,7,-3,DARK_OAK_STAIRS:4)
Block(4,7,-2,AIR:0)
Block(4,7,-1,AIR:0)
Block(4,7,0,AIR:0)
Block(4,7,1,AIR:0)
Block(4,7,2,AIR:0)
Block(4,7,3,AIR:0)
Block(4,7,4,AIR:0)
Block(4,7,5,AIR:0)
Block(4,7,6,DARK_OAK_STAIRS:4)
Block(4,7,7,AIR:0)
Block(4,7,8,AIR:0)
RandomBlock(4,7,9,DARK_OAK_FENCE:0,30,STONE:6,100)
RandomBlock(4,8,-6,DARK_OAK_FENCE:0,30,STONE:6,100)
Block(4,8,-5,AIR:0)
Block(4,8,-4,AIR:0)
Block(4,8,-3,WOOD_PLATE:0)
Block(4,8,-2,AIR:0)
Block(4,8,-1,AIR:0)
Block(4,8,0,AIR:0)
Block(4,8,1,AIR:0)
Block(4,8,2,AIR:0)
Block(4,8,3,AIR:0)
Block(4,8,4,AIR:0)
Block(4,8,5,AIR:0)
Block(4,8,6,WOOD_PLATE:0)
Block(4,8,7,AIR:0)
Block(4,8,8,AIR:0)
RandomBlock(4,8,9,DARK_OAK_FENCE:0,30,STONE:6,100)
RandomBlock(4,9,-6,DARK_OAK_FENCE:0,30,STONE:6,100)
Block(4,9,-5,AIR:0)
Block(4,9,-4,AIR:0)
Block(4,9,-3,AIR:0)
Block(4,9,-2,AIR:0)
Block(4,9,-1,WOOD_STEP:5)
Block(4,9,0,WOOD_DOUBLE_STEP:5)
Block(4,9,1,WOOD_DOUBLE_STEP:5)
Block(4,9,2,WOOD_DOUBLE_STEP:5)
Block(4,9,3,WOOD_DOUBLE_STEP:5)
Block(4,9,4,WOOD_STEP:5)
Block(4,9,5,AIR:0)
Block(4,9,6,AIR:0)
Block(4,9,7,AIR:0)
Block(4,9,8,AIR:0)
RandomBlock(4,9,9,DARK_OAK_FENCE:0,30,STONE:6,100)
RandomBlock(4,10,-6,DARK_OAK_FENCE:0,30,STONE:6,100)
Block(4,10,-5,AIR:0)
Block(4,10,-4,AIR:0)
Block(4,10,-3,AIR:0)
Block(4,10,-2,AIR:0)
Block(4,10,-1,AIR:0)
Block(4,10,0,AIR:0)
Block(4,10,1,AIR:0)
Block(4,10,2,AIR:0)
Block(4,10,3,AIR:0)
Block(4,10,4,AIR:0)
Block(4,10,5,AIR:0)
Block(4,10,6,AIR:0)
Block(4,10,7,AIR:0)
Block(4,10,8,AIR:0)
RandomBlock(4,10,9,DARK_OAK_FENCE:0,30,STONE:6,100)
Block(4,11,-6,WOOD:5)
Block(4,11,-5,WOOD_STEP:13)
Block(4,11,-4,WOOD_STEP:13)
Block(4,11,-3,WOOD_STEP:13)
Block(4,11,-2,WOOD_STEP:13)
Block(4,11,-1,WOOD_STEP:13)
Block(4,11,0,WOOD:5)
Block(4,11,1,WOOD_STEP:13)
Block(4,11,2,WOOD_STEP:13)
Block(4,11,3,WOOD:5)
Block(4,11,4,WOOD_STEP:13)
Block(4,11,5,WOOD_STEP:13)
Block(4,11,6,WOOD_STEP:13)
Block(4,11,7,WOOD_STEP:13)
Block(4,11,8,WOOD_STEP:13)
Block(4,11,9,WOOD:5)
RandomBlock(4,12,-6,DARK_OAK_FENCE:0,30,STONE:6,100)
Block(4,12,-5,GOLD_ORE:0)
Block(4,12,-4,COAL_ORE:0)
Block(4,12,-3,AIR:0)
Block(4,12,-2,AIR:0)
Block(4,12,-1,AIR:0)
Block(4,12,0,SPRUCE_FENCE:0)
Block(4,12,1,AIR:0)
Block(4,12,2,AIR:0)
Block(4,12,3,AIR:0)
Block(4,12,4,AIR:0)
Block(4,12,5,AIR:0)
Block(4,12,6,AIR:0)
Block(4,12,7,GOLD_ORE:0)
Block(4,12,8,IRON_ORE:0)
RandomBlock(4,12,9,DARK_OAK_FENCE:0,30,STONE:6,100)
RandomBlock(4,13,-6,DARK_OAK_FENCE:0,30,STONE:6,100)
Block(4,13,-5,AIR:0)
Block(4,13,-4,AIR:0)
Block(4,13,-3,AIR:0)
Block(4,13,-2,AIR:0)
Block(4,13,-1,AIR:0)
Block(4,13,0,TORCH:5)
Block(4,13,1,AIR:0)
Block(4,13,2,AIR:0)
Block(4,13,3,AIR:0)
Block(4,13,4,AIR:0)
Block(4,13,5,AIR:0)
Block(4,13,6,AIR:0)
Block(4,13,7,AIR:0)
RandomBlock(4,13,8,AIR:0,2,CHEST:2,../../../../Chests/Loot/mine_resources_01.nbt,10,CHEST:2,../../../../Chests/Loot/mine_resources_02.nbt,10,CHEST:2,../../../../Chests/Loot/mine_resources_03.nbt,10,CHEST:2,../../../../Chests/Loot/mine_resources_04.nbt,10,CHEST:2,../../../../Chests/Loot/mine_resources_05.nbt,10,CHEST:2,../../../../Chests/Loot/abandoned_mineshaft.nbt,10,CHEST:2,../../../../Chests/Loot/mine_resources_01.nbt,100)
RandomBlock(4,13,9,DARK_OAK_FENCE:0,30,STONE:6,100)
RandomBlock(4,14,-6,DARK_OAK_FENCE:0,30,STONE:6,100)
Block(4,14,-5,AIR:0)
Block(4,14,-4,AIR:0)
Block(4,14,-3,AIR:0)
Block(4,14,-2,AIR:0)
Block(4,14,-1,AIR:0)
Block(4,14,0,AIR:0)
Block(4,14,1,AIR:0)
Block(4,14,2,AIR:0)
Block(4,14,3,AIR:0)
Block(4,14,4,AIR:0)
Block(4,14,5,AIR:0)
Block(4,14,6,AIR:0)
Block(4,14,7,AIR:0)
Block(4,14,8,AIR:0)
RandomBlock(4,14,9,DARK_OAK_FENCE:0,30,STONE:6,100)
Block(4,15,-6,WOOD:5)
Block(4,15,-5,TRAP_DOOR:8)
Block(4,15,-4,TRAP_DOOR:8)
Block(4,15,-3,TRAP_DOOR:8)
Block(4,15,-2,TRAP_DOOR:8)
Block(4,15,-1,TRAP_DOOR:8)
Block(4,15,0,WOOD:5)
Block(4,15,1,TRAP_DOOR:8)
Block(4,15,2,TRAP_DOOR:8)
Block(4,15,3,WOOD:5)
Block(4,15,4,TRAP_DOOR:8)
Block(4,15,5,TRAP_DOOR:8)
Block(4,15,6,TRAP_DOOR:8)
Block(4,15,7,TRAP_DOOR:8)
Block(4,15,8,TRAP_DOOR:8)
Block(4,15,9,WOOD:5)
Block(5,1,-6,WOOD:5)
Block(5,1,-5,WOOD:5)
Block(5,1,-4,SMOOTH_BRICK:0)
Block(5,1,-3,SMOOTH_BRICK:0)
Block(5,1,-2,SMOOTH_BRICK:0)
Block(5,1,-1,SMOOTH_BRICK:0)
Block(5,1,0,SMOOTH_BRICK:0)
Block(5,1,1,SMOOTH_BRICK:0)
Block(5,1,2,SMOOTH_BRICK:0)
Block(5,1,3,SMOOTH_BRICK:0)
Block(5,1,4,SMOOTH_BRICK:0)
Block(5,1,5,SMOOTH_BRICK:0)
Block(5,1,6,SMOOTH_BRICK:0)
Block(5,1,7,WOOD:5)
Block(5,1,8,WOOD:5)
Block(5,1,9,WOOD:5)
Block(5,2,-6,SMOOTH_BRICK:0)
Block(5,2,-5,AIR:0)
Block(5,2,-4,AIR:0)
Block(5,2,-3,AIR:0)
Block(5,2,-2,AIR:0)
Block(5,2,-1,AIR:0)
Block(5,2,0,AIR:0)
Block(5,2,1,AIR:0)
Block(5,2,2,AIR:0)
Block(5,2,3,AIR:0)
Block(5,2,4,AIR:0)
Block(5,2,5,AIR:0)
Block(5,2,6,AIR:0)
Block(5,2,7,AIR:0)
Block(5,2,8,AIR:0)
Block(5,2,9,SMOOTH_BRICK:0)
Block(5,3,-6,SMOOTH_BRICK:0)
Block(5,3,-5,AIR:0)
Block(5,3,-4,AIR:0)
Block(5,3,-3,AIR:0)
Block(5,3,-2,AIR:0)
Block(5,3,-1,AIR:0)
Block(5,3,0,AIR:0)
Block(5,3,1,AIR:0)
Block(5,3,2,AIR:0)
Block(5,3,3,AIR:0)
Block(5,3,4,AIR:0)
Block(5,3,5,AIR:0)
Block(5,3,6,AIR:0)
Block(5,3,7,AIR:0)
Block(5,3,8,AIR:0)
Block(5,3,9,SMOOTH_BRICK:0)
Block(5,4,-6,SMOOTH_BRICK:0)
Block(5,4,-5,AIR:0)
Block(5,4,-4,AIR:0)
Block(5,4,-3,AIR:0)
Block(5,4,-2,AIR:0)
Block(5,4,-1,AIR:0)
Block(5,4,0,AIR:0)
Block(5,4,1,AIR:0)
Block(5,4,2,AIR:0)
Block(5,4,3,AIR:0)
Block(5,4,4,AIR:0)
Block(5,4,5,AIR:0)
Block(5,4,6,AIR:0)
Block(5,4,7,AIR:0)
Block(5,4,8,AIR:0)
Block(5,4,9,SMOOTH_BRICK:0)
Block(5,5,-6,SMOOTH_BRICK:0)
Block(5,5,-5,AIR:0)
Block(5,5,-4,AIR:0)
Block(5,5,-3,AIR:0)
Block(5,5,-2,AIR:0)
Block(5,5,-1,AIR:0)
Block(5,5,0,AIR:0)
Block(5,5,1,AIR:0)
Block(5,5,2,AIR:0)
Block(5,5,3,AIR:0)
Block(5,5,4,AIR:0)
Block(5,5,5,AIR:0)
Block(5,5,6,AIR:0)
Block(5,5,7,AIR:0)
Block(5,5,8,AIR:0)
Block(5,5,9,SMOOTH_BRICK:0)
Block(5,6,-6,WOOD:5)
Block(5,6,-5,WOOD_STEP:13)
Block(5,6,-4,WOOD_STEP:13)
Block(5,6,-3,WOOD_STEP:13)
Block(5,6,-2,WOOD_STEP:13)
Block(5,6,-1,WOOD_STEP:13)
Block(5,6,0,WOOD:5)
Block(5,6,1,WOOD_STEP:13)
Block(5,6,2,WOOD_STEP:13)
Block(5,6,3,WOOD:5)
Block(5,6,4,WOOD_STEP:13)
Block(5,6,5,WOOD_STEP:13)
Block(5,6,6,WOOD_STEP:13)
Block(5,6,7,WOOD_STEP:13)
Block(5,6,8,WOOD_STEP:13)
Block(5,6,9,WOOD:5)
Block(5,7,-6,SMOOTH_BRICK:0)
Block(5,7,-5,AIR:0)
Block(5,7,-4,CARPET:13)
Block(5,7,-3,WORKBENCH:0)
Block(5,7,-2,DARK_OAK_STAIRS:7)
Block(5,7,-1,DARK_OAK_STAIRS:6)
Block(5,7,0,SPRUCE_FENCE:0)
Block(5,7,1,DARK_OAK_STAIRS:7)
Block(5,7,2,DARK_OAK_STAIRS:6)
Block(5,7,3,SPRUCE_FENCE:0)
Block(5,7,4,DARK_OAK_STAIRS:7)
Block(5,7,5,DARK_OAK_STAIRS:6)
Block(5,7,6,CAULDRON:0)
Block(5,7,7,CARPET:13)
Block(5,7,8,AIR:0)
Block(5,7,9,SMOOTH_BRICK:0)
Block(5,8,-6,SMOOTH_BRICK:0)
Block(5,8,-5,AIR:0)
Block(5,8,-4,AIR:0)
Block(5,8,-3,AIR:0)
Block(5,8,-2,WOOD_PLATE:0)
Block(5,8,-1,WOOD_PLATE:0)
Block(5,8,0,SPRUCE_FENCE:0)
Block(5,8,1,WOOD_PLATE:0)
Block(5,8,2,WOOD_PLATE:0)
Block(5,8,3,SPRUCE_FENCE:0)
Block(5,8,4,WOOD_PLATE:0)
Block(5,8,5,WOOD_PLATE:0)
Block(5,8,6,AIR:0)
Block(5,8,7,AIR:0)
Block(5,8,8,AIR:0)
Block(5,8,9,SMOOTH_BRICK:0)
Block(5,9,-6,SMOOTH_BRICK:0)
Block(5,9,-5,AIR:0)
Block(5,9,-4,AIR:0)
Block(5,9,-3,AIR:0)
Block(5,9,-2,AIR:0)
Block(5,9,-1,AIR:0)
Block(5,9,0,WOOD_STEP:5)
Block(5,9,1,WOOD_STEP:5)
Block(5,9,2,WOOD_STEP:5)
Block(5,9,3,WOOD_STEP:5)
Block(5,9,4,AIR:0)
Block(5,9,5,AIR:0)
Block(5,9,6,AIR:0)
Block(5,9,7,AIR:0)
Block(5,9,8,AIR:0)
Block(5,9,9,SMOOTH_BRICK:0)
Block(5,10,-6,SMOOTH_BRICK:0)
Block(5,10,-5,AIR:0)
Block(5,10,-4,AIR:0)
Block(5,10,-3,AIR:0)
Block(5,10,-2,AIR:0)
Block(5,10,-1,AIR:0)
Block(5,10,0,AIR:0)
Block(5,10,1,AIR:0)
Block(5,10,2,AIR:0)
Block(5,10,3,AIR:0)
Block(5,10,4,AIR:0)
Block(5,10,5,AIR:0)
Block(5,10,6,AIR:0)
Block(5,10,7,AIR:0)
Block(5,10,8,AIR:0)
Block(5,10,9,SMOOTH_BRICK:0)
Block(5,11,-6,WOOD:5)
Block(5,11,-5,WOOD_STEP:13)
Block(5,11,-4,WOOD_STEP:13)
Block(5,11,-3,WOOD_STEP:13)
Block(5,11,-2,WOOD_STEP:13)
Block(5,11,-1,WOOD_STEP:13)
Block(5,11,0,WOOD:5)
Block(5,11,1,WOOD_STEP:13)
Block(5,11,2,WOOD_STEP:13)
Block(5,11,3,WOOD:5)
Block(5,11,4,WOOD_STEP:13)
Block(5,11,5,WOOD_STEP:13)
Block(5,11,6,WOOD_STEP:13)
Block(5,11,7,WOOD_STEP:13)
Block(5,11,8,WOOD_STEP:13)
Block(5,11,9,WOOD:5)
Block(5,12,-6,SMOOTH_BRICK:0)
Block(5,12,-5,IRON_ORE:0)
Block(5,12,-4,COAL_ORE:0)
Block(5,12,-3,COAL_ORE:0)
Block(5,12,-2,AIR:0)
Block(5,12,-1,AIR:0)
Block(5,12,0,AIR:0)
Block(5,12,1,AIR:0)
Block(5,12,2,AIR:0)
Block(5,12,3,AIR:0)
Block(5,12,4,AIR:0)
Block(5,12,5,AIR:0)
Block(5,12,6,AIR:0)
Block(5,12,7,COAL_ORE:0)
Block(5,12,8,COAL_ORE:0)
Block(5,12,9,SMOOTH_BRICK:0)
Block(5,13,-6,SMOOTH_BRICK:0)
Block(5,13,-5,GOLD_ORE:0)
Block(5,13,-4,AIR:0)
Block(5,13,-3,AIR:0)
Block(5,13,-2,AIR:0)
Block(5,13,-1,AIR:0)
Block(5,13,0,AIR:0)
Block(5,13,1,AIR:0)
Block(5,13,2,AIR:0)
Block(5,13,3,AIR:0)
Block(5,13,4,AIR:0)
Block(5,13,5,AIR:0)
Block(5,13,6,AIR:0)
Block(5,13,7,IRON_ORE:0)
Block(5,13,8,COAL_ORE:0)
Block(5,13,9,SMOOTH_BRICK:0)
Block(5,14,-6,SMOOTH_BRICK:0)
Block(5,14,-5,AIR:0)
Block(5,14,-4,AIR:0)
Block(5,14,-3,AIR:0)
Block(5,14,-2,AIR:0)
Block(5,14,-1,AIR:0)
Block(5,14,0,AIR:0)
Block(5,14,1,AIR:0)
Block(5,14,2,AIR:0)
Block(5,14,3,AIR:0)
Block(5,14,4,AIR:0)
Block(5,14,5,AIR:0)
Block(5,14,6,AIR:0)
Block(5,14,7,AIR:0)
Block(5,14,8,COAL_ORE:0)
Block(5,14,9,SMOOTH_BRICK:0)
Block(5,15,-6,WOOD:5)
Block(5,15,-5,TRAP_DOOR:8)
Block(5,15,-4,TRAP_DOOR:8)
Block(5,15,-3,TRAP_DOOR:8)
Block(5,15,-2,TRAP_DOOR:8)
Block(5,15,-1,TRAP_DOOR:8)
Block(5,15,0,WOOD:5)
Block(5,15,1,TRAP_DOOR:8)
Block(5,15,2,TRAP_DOOR:8)
Block(5,15,3,WOOD:5)
Block(5,15,4,TRAP_DOOR:8)
Block(5,15,5,TRAP_DOOR:8)
Block(5,15,6,TRAP_DOOR:8)
Block(5,15,7,TRAP_DOOR:8)
Block(5,15,8,TRAP_DOOR:8)
Block(5,15,9,WOOD:5)
Block(6,1,-6,WOOD:5)
Block(6,1,-5,WOOD:5)
Block(6,1,-4,SMOOTH_BRICK:0)
Block(6,1,-3,SMOOTH_BRICK:0)
Block(6,1,-2,SMOOTH_BRICK:0)
Block(6,1,-1,SMOOTH_BRICK:0)
Block(6,1,0,SMOOTH_BRICK:0)
Block(6,1,1,SMOOTH_BRICK:0)
Block(6,1,2,SMOOTH_BRICK:0)
Block(6,1,3,SMOOTH_BRICK:0)
Block(6,1,4,SMOOTH_BRICK:0)
Block(6,1,5,SMOOTH_BRICK:0)
Block(6,1,6,SMOOTH_BRICK:0)
Block(6,1,7,WOOD:5)
Block(6,1,8,WOOD:5)
Block(6,1,9,WOOD:5)
Block(6,2,-6,SPRUCE_FENCE:0)
RandomBlock(6,2,-5,DARK_OAK_FENCE:0,30,STONE:6,100)
Block(6,2,-4,AIR:0)
Block(6,2,-3,AIR:0)
Block(6,2,-2,AIR:0)
Block(6,2,-1,AIR:0)
Block(6,2,0,AIR:0)
Block(6,2,1,AIR:0)
Block(6,2,2,AIR:0)
Block(6,2,3,AIR:0)
Block(6,2,4,AIR:0)
Block(6,2,5,AIR:0)
Block(6,2,6,AIR:0)
Block(6,2,7,AIR:0)
RandomBlock(6,2,8,DARK_OAK_FENCE:0,30,STONE:6,100)
Block(6,2,9,SPRUCE_FENCE:0)
Block(6,3,-6,SPRUCE_FENCE:0)
RandomBlock(6,3,-5,DARK_OAK_FENCE:0,30,STONE:6,100)
Block(6,3,-4,AIR:0)
Block(6,3,-3,AIR:0)
Block(6,3,-2,AIR:0)
Block(6,3,-1,AIR:0)
Block(6,3,0,AIR:0)
Block(6,3,1,AIR:0)
Block(6,3,2,AIR:0)
Block(6,3,3,AIR:0)
Block(6,3,4,AIR:0)
Block(6,3,5,AIR:0)
Block(6,3,6,AIR:0)
Block(6,3,7,AIR:0)
RandomBlock(6,3,8,DARK_OAK_FENCE:0,30,STONE:6,100)
Block(6,3,9,SPRUCE_FENCE:0)
Block(6,4,-6,WOOD:1)
RandomBlock(6,4,-5,DARK_OAK_FENCE:0,30,STONE:6,100)
Block(6,4,-4,AIR:0)
Block(6,4,-3,AIR:0)
Block(6,4,-2,AIR:0)
Block(6,4,-1,AIR:0)
Block(6,4,0,AIR:0)
Block(6,4,1,AIR:0)
Block(6,4,2,AIR:0)
Block(6,4,3,AIR:0)
Block(6,4,4,AIR:0)
Block(6,4,5,AIR:0)
Block(6,4,6,AIR:0)
Block(6,4,7,AIR:0)
RandomBlock(6,4,8,DARK_OAK_FENCE:0,30,STONE:6,100)
Block(6,4,9,WOOD:1)
Block(6,5,-6,SPRUCE_FENCE:0)
RandomBlock(6,5,-5,DARK_OAK_FENCE:0,30,STONE:6,100)
Block(6,5,-4,AIR:0)
Block(6,5,-3,AIR:0)
Block(6,5,-2,AIR:0)
Block(6,5,-1,AIR:0)
Block(6,5,0,AIR:0)
Block(6,5,1,AIR:0)
Block(6,5,2,AIR:0)
Block(6,5,3,AIR:0)
Block(6,5,4,AIR:0)
Block(6,5,5,AIR:0)
Block(6,5,6,AIR:0)
Block(6,5,7,AIR:0)
RandomBlock(6,5,8,DARK_OAK_FENCE:0,30,STONE:6,100)
Block(6,5,9,SPRUCE_FENCE:0)
Block(6,6,-6,WOOD:5)
Block(6,6,-5,WOOD_DOUBLE_STEP:5)
Block(6,6,-4,WOOD_STEP:13)
Block(6,6,-3,WOOD_STEP:13)
Block(6,6,-2,WOOD_STEP:13)
Block(6,6,-1,WOOD_STEP:13)
Block(6,6,0,WOOD:5)
Block(6,6,1,WOOD_STEP:13)
Block(6,6,2,WOOD_STEP:13)
Block(6,6,3,WOOD:5)
Block(6,6,4,WOOD_STEP:13)
Block(6,6,5,WOOD_STEP:13)
Block(6,6,6,WOOD_STEP:13)
Block(6,6,7,WOOD_STEP:13)
Block(6,6,8,WOOD_DOUBLE_STEP:5)
Block(6,6,9,WOOD:5)
Block(6,7,-6,SPRUCE_FENCE:0)
RandomBlock(6,7,-5,DARK_OAK_FENCE:0,30,STONE:6,100)
Block(6,7,-4,AIR:0)
Block(6,7,-3,AIR:0)
Block(6,7,-2,CARPET:13)
Block(6,7,-1,AIR:0)
Block(6,7,0,CARPET:13)
Block(6,7,1,CARPET:13)
Block(6,7,2,CARPET:13)
Block(6,7,3,AIR:0)
Block(6,7,4,CARPET:13)
Block(6,7,5,CARPET:13)
Block(6,7,6,AIR:0)
Block(6,7,7,CARPET:13)
RandomBlock(6,7,8,DARK_OAK_FENCE:0,30,STONE:6,100)
Block(6,7,9,SPRUCE_FENCE:0)
Block(6,8,-6,SPRUCE_FENCE:0)
RandomBlock(6,8,-5,DARK_OAK_FENCE:0,30,STONE:6,100)
Block(6,8,-4,AIR:0)
Block(6,8,-3,AIR:0)
Block(6,8,-2,AIR:0)
Block(6,8,-1,AIR:0)
Block(6,8,0,AIR:0)
Block(6,8,1,AIR:0)
Block(6,8,2,AIR:0)
Block(6,8,3,AIR:0)
Block(6,8,4,AIR:0)
Block(6,8,5,AIR:0)
Block(6,8,6,AIR:0)
Block(6,8,7,AIR:0)
RandomBlock(6,8,8,DARK_OAK_FENCE:0,30,STONE:6,100)
Block(6,8,9,SPRUCE_FENCE:0)
Block(6,9,-6,WOOD:1)
RandomBlock(6,9,-5,DARK_OAK_FENCE:0,30,STONE:6,100)
Block(6,9,-4,AIR:0)
Block(6,9,-3,AIR:0)
Block(6,9,-2,AIR:0)
Block(6,9,-1,AIR:0)
Block(6,9,0,AIR:0)
Block(6,9,1,AIR:0)
Block(6,9,2,AIR:0)
Block(6,9,3,AIR:0)
Block(6,9,4,AIR:0)
Block(6,9,5,AIR:0)
Block(6,9,6,AIR:0)
Block(6,9,7,AIR:0)
RandomBlock(6,9,8,DARK_OAK_FENCE:0,30,STONE:6,100)
Block(6,9,9,WOOD:1)
Block(6,10,-6,SPRUCE_FENCE:0)
RandomBlock(6,10,-5,DARK_OAK_FENCE:0,30,STONE:6,100)
Block(6,10,-4,AIR:0)
Block(6,10,-3,AIR:0)
Block(6,10,-2,AIR:0)
Block(6,10,-1,AIR:0)
Block(6,10,0,AIR:0)
Block(6,10,1,AIR:0)
Block(6,10,2,AIR:0)
Block(6,10,3,AIR:0)
Block(6,10,4,AIR:0)
Block(6,10,5,AIR:0)
Block(6,10,6,AIR:0)
Block(6,10,7,AIR:0)
RandomBlock(6,10,8,DARK_OAK_FENCE:0,30,STONE:6,100)
Block(6,10,9,SPRUCE_FENCE:0)
Block(6,11,-6,WOOD:5)
Block(6,11,-5,WOOD_DOUBLE_STEP:5)
Block(6,11,-4,WOOD_STEP:13)
Block(6,11,-3,WOOD_STEP:13)
Block(6,11,-2,WOOD_STEP:13)
Block(6,11,-1,WOOD_STEP:13)
Block(6,11,0,WOOD:5)
Block(6,11,1,WOOD_STEP:13)
Block(6,11,2,WOOD_STEP:13)
Block(6,11,3,WOOD:5)
Block(6,11,4,WOOD_STEP:13)
Block(6,11,5,WOOD_STEP:13)
Block(6,11,6,WOOD_STEP:13)
Block(6,11,7,WOOD_STEP:13)
Block(6,11,8,WOOD_DOUBLE_STEP:5)
Block(6,11,9,WOOD:5)
Block(6,12,-6,SPRUCE_FENCE:0)
RandomBlock(6,12,-5,DARK_OAK_FENCE:0,30,STONE:6,100)
Block(6,12,-4,IRON_ORE:0)
Block(6,12,-3,COAL_ORE:0)
Block(6,12,-2,AIR:0)
Block(6,12,-1,AIR:0)
Block(6,12,0,AIR:0)
Block(6,12,1,AIR:0)
Block(6,12,2,AIR:0)
Block(6,12,3,AIR:0)
Block(6,12,4,AIR:0)
Block(6,12,5,IRON_ORE:0)
Block(6,12,6,COAL_ORE:0)
Block(6,12,7,COAL_ORE:0)
RandomBlock(6,12,8,DARK_OAK_FENCE:0,30,STONE:6,100)
Block(6,12,9,SPRUCE_FENCE:0)
Block(6,13,-6,SPRUCE_FENCE:0)
RandomBlock(6,13,-5,DARK_OAK_FENCE:0,30,STONE:6,100)
Block(6,13,-4,COAL_ORE:0)
Block(6,13,-3,AIR:0)
Block(6,13,-2,AIR:0)
Block(6,13,-1,AIR:0)
Block(6,13,0,AIR:0)
Block(6,13,1,AIR:0)
Block(6,13,2,AIR:0)
Block(6,13,3,AIR:0)
Block(6,13,4,AIR:0)
Block(6,13,5,AIR:0)
Block(6,13,6,IRON_ORE:0)
