
#######################################################################
# +-----------------------------------------------------------------+ #
# |                            BO4 object                           | #
# +-----------------------------------------------------------------+ #
#######################################################################

Author: NLBlackEagle

Description: No description given

SettingsMode: WriteDisable


#######################################################################
# +-----------------------------------------------------------------+ #
# |                          Main settings                          | #
# +-----------------------------------------------------------------+ #
#######################################################################

Frequency: 0

SpawnHeight: highestBlock

UseCenterForHighestBlock: true

##############################
# Height Limits for the BO4. #
##############################

MinHeight: 0

MaxHeight: 255

InheritBO3: 

InheritBO3Rotation: NORTH

OverrideChildSettings: true

OverrideParentHeight: false

CanOverride: true

BranchFrequency: 0

BranchFrequencyGroup: 

MustBeBelowOther: false

MustBeInside: 

CannotBeInside: 

ReplacesBO3: 

MustBeInsideWorldBorders: false

CanSpawnOnWater: true

SpawnOnWaterOnly: false

SpawnUnderWater: false

SpawnAtWaterLevel: false

HeightOffset: 0

RemoveAir: false

ReplaceAbove: 

ReplaceBelow: 

ReplaceWithBiomeBlocks: true

ReplaceWithSurfaceBlock: GRASS

ReplaceWithGroundBlock: DIRT

ReplaceWithStoneBlock: STONE

SmoothRadius: 0

SmoothHeightOffset: 0

SmoothStartTop: false

SmoothStartWood: false

SmoothingSurfaceBlock: 

SmoothingGroundBlock: 

BO3Group: 

IsSpawnPoint: false

DoReplaceBlocks: true


#######################################################################
# +-----------------------------------------------------------------+ #
# |                              Blocks                             | #
# +-----------------------------------------------------------------+ #
#######################################################################

Block(-7,0,0,WOOD:5)
Block(-7,0,1,WOOD_STEP:13)
Block(-7,0,2,WOOD_STEP:13)
Block(-7,0,3,WOOD:5)
Block(-7,750,9,AIR:0)
RandomBlock(-7,1,0,DARK_OAK_FENCE:0,30,STONE:6,100)
Block(-7,1,1,AIR:0)
Block(-7,1,2,AIR:0)
RandomBlock(-7,1,3,DARK_OAK_FENCE:0,30,STONE:6,100)
RandomBlock(-7,2,0,DARK_OAK_FENCE:0,30,STONE:6,100)
Block(-7,2,1,AIR:0)
Block(-7,2,2,AIR:0)
RandomBlock(-7,2,3,DARK_OAK_FENCE:0,30,STONE:6,100)
RandomBlock(-7,3,0,DARK_OAK_FENCE:0,30,STONE:6,100)
Block(-7,3,1,TRAP_DOOR:11)
Block(-7,3,2,TRAP_DOOR:11)
RandomBlock(-7,3,3,DARK_OAK_FENCE:0,30,STONE:6,100)
Block(-6,0,0,WOOD:5)
Block(-6,0,1,WOOD_STEP:13)
Block(-6,0,2,WOOD_STEP:13)
Block(-6,0,3,WOOD:5)
Block(-6,1,0,STONE:6)
Block(-6,1,1,IRON_DOOR_BLOCK:2)
Block(-6,1,2,IRON_DOOR_BLOCK:2)
Block(-6,1,3,STONE:6)
Block(-6,2,0,STONE:6)
Block(-6,2,1,IRON_DOOR_BLOCK:9)
Block(-6,2,2,IRON_DOOR_BLOCK:8)
Block(-6,2,3,STONE:6)
Block(-6,3,0,WOOD:1)
Block(-6,3,1,WOOD:1)
Block(-6,3,2,WOOD:1)
Block(-6,3,3,WOOD:1)
Block(-5,0,-2,WOOD:5)
Block(-5,0,-1,WOOD:5)
Block(-5,0,0,WOOD:5)
Block(-5,0,1,WOOD_STEP:13)
Block(-5,0,2,WOOD_STEP:13)
Block(-5,0,3,WOOD:5)
Block(-5,0,4,WOOD:5)
Block(-5,0,5,WOOD:5)
Block(-5,1,-2,SPRUCE_FENCE:0)
RandomBlock(-5,1,-1,DARK_OAK_FENCE:0,30,STONE:6,100)
RandomBlock(-5,1,0,DARK_OAK_FENCE:0,30,STONE:6,100)
Block(-5,1,1,AIR:0)
Block(-5,1,2,AIR:0)
RandomBlock(-5,1,3,DARK_OAK_FENCE:0,30,STONE:6,100)
RandomBlock(-5,1,4,DARK_OAK_FENCE:0,30,STONE:6,100)
Block(-5,1,5,SPRUCE_FENCE:0)
Block(-5,2,-2,SPRUCE_FENCE:0)
RandomBlock(-5,2,-1,DARK_OAK_FENCE:0,30,STONE:6,100)
RandomBlock(-5,2,0,DARK_OAK_FENCE:0,30,STONE:6,100)
Block(-5,2,1,AIR:0)
Block(-5,2,2,AIR:0)
RandomBlock(-5,2,3,DARK_OAK_FENCE:0,30,STONE:6,100)
RandomBlock(-5,2,4,DARK_OAK_FENCE:0,30,STONE:6,100)
Block(-5,2,5,SPRUCE_FENCE:0)
Block(-5,3,-2,WOOD:1)
RandomBlock(-5,3,-1,DARK_OAK_FENCE:0,30,STONE:6,100)
RandomBlock(-5,3,0,DARK_OAK_FENCE:0,30,STONE:6,100)
RandomBlock(-5,3,1,DARK_OAK_FENCE:0,30,STONE:6,100)
RandomBlock(-5,3,2,DARK_OAK_FENCE:0,30,STONE:6,100)
RandomBlock(-5,3,3,DARK_OAK_FENCE:0,30,STONE:6,100)
RandomBlock(-5,3,4,DARK_OAK_FENCE:0,30,STONE:6,100)
Block(-5,3,5,WOOD:1)
Block(-4,0,-2,WOOD:5)
Block(-4,0,-1,WOOD_STEP:13)
Block(-4,0,0,WOOD_STEP:13)
Block(-4,0,1,WOOD_STEP:13)
Block(-4,0,2,WOOD_STEP:13)
Block(-4,0,3,WOOD_STEP:13)
Block(-4,0,4,WOOD_STEP:13)
Block(-4,0,5,WOOD:5)
RandomBlock(-4,1,-2,DARK_OAK_FENCE:0,30,STONE:6,100)
Block(-4,1,-1,EMERALD_ORE:0)
Block(-4,1,0,AIR:0)
Block(-4,1,1,AIR:0)
Block(-4,1,2,AIR:0)
Block(-4,1,3,AIR:0)
Block(-4,1,4,EMERALD_ORE:0)
RandomBlock(-4,1,5,DARK_OAK_FENCE:0,30,STONE:6,100)
RandomBlock(-4,2,-2,DARK_OAK_FENCE:0,30,STONE:6,100)
Block(-4,2,-1,EMERALD_ORE:0)
Block(-4,2,0,AIR:0)
Block(-4,2,1,AIR:0)
Block(-4,2,2,AIR:0)
Block(-4,2,3,AIR:0)
Block(-4,2,4,DIAMOND_ORE:0)
RandomBlock(-4,2,5,DARK_OAK_FENCE:0,30,STONE:6,100)
Block(-4,3,-2,WOOD:1)
Block(-4,3,-1,TRAP_DOOR:9)
Block(-4,3,0,TRAP_DOOR:9)
Block(-4,3,1,TRAP_DOOR:9)
Block(-4,3,2,TRAP_DOOR:9)
Block(-4,3,3,TRAP_DOOR:9)
Block(-4,3,4,TRAP_DOOR:9)
Block(-4,3,5,WOOD:1)
Block(-3,0,-2,WOOD:5)
Block(-3,0,-1,WOOD_STEP:13)
Block(-3,0,0,WOOD_STEP:13)
Block(-3,0,1,WOOD_STEP:13)
Block(-3,0,2,WOOD_STEP:13)
Block(-3,0,3,WOOD_STEP:13)
Block(-3,0,4,WOOD_STEP:13)
Block(-3,0,5,WOOD:5)
RandomBlock(-3,1,-2,DARK_OAK_FENCE:0,30,STONE:6,100)
Block(-3,1,-1,EMERALD_ORE:0)
Block(-3,1,0,LAPIS_ORE:0)
Block(-3,1,1,SPRUCE_FENCE:0)
Block(-3,1,2,AIR:0)
Block(-3,1,3,DIAMOND_ORE:0)
Block(-3,1,4,DIAMOND_ORE:0)
RandomBlock(-3,1,5,DARK_OAK_FENCE:0,30,STONE:6,100)
RandomBlock(-3,2,-2,DARK_OAK_FENCE:0,30,STONE:6,100)
Block(-3,2,-1,AIR:0)
Block(-3,2,0,AIR:0)
Block(-3,2,1,TORCH:5)
Block(-3,2,2,AIR:0)
Block(-3,2,3,AIR:0)
Block(-3,2,4,LAPIS_ORE:0)
RandomBlock(-3,2,5,DARK_OAK_FENCE:0,30,STONE:6,100)
Block(-3,3,-2,WOOD:1)
Block(-3,3,-1,TRAP_DOOR:9)
Block(-3,3,0,TRAP_DOOR:9)
Block(-3,3,1,TRAP_DOOR:9)
Block(-3,3,2,TRAP_DOOR:9)
Block(-3,3,3,TRAP_DOOR:9)
Block(-3,3,4,TRAP_DOOR:9)
Block(-3,3,5,WOOD:1)
Block(-2,0,-2,WOOD:5)
Block(-2,0,-1,WOOD:5)
Block(-2,0,0,WOOD:5)
Block(-2,0,1,WOOD:5)
Block(-2,0,2,WOOD:5)
Block(-2,0,3,WOOD:5)
Block(-2,0,4,WOOD:5)
Block(-2,0,5,WOOD:5)
Block(-2,1,-2,SPRUCE_FENCE:0)
RandomBlock(-2,1,-1,DARK_OAK_FENCE:0,30,STONE:6,100)
RandomBlock(-2,1,0,DARK_OAK_FENCE:0,30,STONE:6,100)
RandomBlock(-2,1,1,DARK_OAK_FENCE:0,30,STONE:6,100)
RandomBlock(-2,1,2,DARK_OAK_FENCE:0,30,STONE:6,100)
RandomBlock(-2,1,3,DARK_OAK_FENCE:0,30,STONE:6,100)
RandomBlock(-2,1,4,DARK_OAK_FENCE:0,30,STONE:6,100)
Block(-2,1,5,SPRUCE_FENCE:0)
Block(-2,2,-2,SPRUCE_FENCE:0)
RandomBlock(-2,2,-1,DARK_OAK_FENCE:0,30,STONE:6,100)
RandomBlock(-2,2,0,DARK_OAK_FENCE:0,30,STONE:6,100)
RandomBlock(-2,2,1,DARK_OAK_FENCE:0,30,STONE:6,100)
RandomBlock(-2,2,2,DARK_OAK_FENCE:0,30,STONE:6,100)
RandomBlock(-2,2,3,DARK_OAK_FENCE:0,30,STONE:6,100)
RandomBlock(-2,2,4,DARK_OAK_FENCE:0,30,STONE:6,100)
Block(-2,2,5,SPRUCE_FENCE:0)
Block(-2,3,-2,WOOD:1)
RandomBlock(-2,3,-1,DARK_OAK_FENCE:0,30,STONE:6,100)
RandomBlock(-2,3,0,DARK_OAK_FENCE:0,30,STONE:6,100)
RandomBlock(-2,3,1,DARK_OAK_FENCE:0,30,STONE:6,100)
RandomBlock(-2,3,2,DARK_OAK_FENCE:0,30,STONE:6,100)
RandomBlock(-2,3,3,DARK_OAK_FENCE:0,30,STONE:6,100)
RandomBlock(-2,3,4,DARK_OAK_FENCE:0,30,STONE:6,100)
Block(-2,3,5,WOOD:1)
Block(8,750,-6,AIR:0)

#######################################################################
# +-----------------------------------------------------------------+ #
# |                             Branches                            | #
# +-----------------------------------------------------------------+ #
#######################################################################


#######################################################################
# +-----------------------------------------------------------------+ #
# |                             Entities                            | #
# +-----------------------------------------------------------------+ #
#######################################################################


#######################################################################
# +-----------------------------------------------------------------+ #
# |                            Particles                            | #
# +-----------------------------------------------------------------+ #
#######################################################################


#######################################################################
# +-----------------------------------------------------------------+ #
# |                             Spawners                            | #
# +-----------------------------------------------------------------+ #
#######################################################################


#######################################################################
# +-----------------------------------------------------------------+ #
# |                             ModData                             | #
# +-----------------------------------------------------------------+ #
#######################################################################

