Author: NLBlackEagle
Description: No description given
SettingsMode: WriteDisable
Frequency: 10
SpawnHeight: highestBlock
UseCenterForHighestBlock: true
MinHeight: 63
MaxHeight: 255
InheritBO3: 
InheritBO3Rotation: NORTH
OverrideChildSettings: true
OverrideParentHeight: false
CanOverride: true
BranchFrequency: 5
BranchFrequencyGroup: 
MustBeBelowOther: false
MustBeInside: 
CannotBeInside: 
ReplacesBO3: 
MustBeInsideWorldBorders: false
CanSpawnOnWater: false
SpawnOnWaterOnly: false
SpawnUnderWater: false
SpawnAtWaterLevel: false
HeightOffset: -2
RemoveAir: false
ReplaceAbove: 
ReplaceBelow: cobblestone
ReplaceWithBiomeBlocks: true
ReplaceWithSurfaceBlock: GRASS
ReplaceWithGroundBlock: DIRT
ReplaceWithStoneBlock: STONE
SmoothRadius: 0
SmoothHeightOffset: 0
SmoothStartTop: false
SmoothStartWood: false
SmoothingSurfaceBlock: 
SmoothingGroundBlock: 
BO3Group: Viking_Tower:15
IsSpawnPoint: false
DoReplaceBlocks: true
Block(-3,5,-2,WALL_SIGN:4)
Block(-3,5,-1,WALL_SIGN:4)
Block(-3,5,0,WALL_SIGN:4)
Block(-3,5,1,WALL_SIGN:4)
Block(-3,5,2,WALL_SIGN:4)
Block(-3,5,3,WALL_SIGN:4)
Block(-3,9,-2,WALL_SIGN:4)
Block(-3,9,-1,WALL_SIGN:4)
Block(-3,9,0,WALL_SIGN:4)
Block(-3,9,1,WALL_SIGN:4)
Block(-3,9,2,WALL_SIGN:4)
Block(-3,9,3,WALL_SIGN:4)
Block(-3,13,-2,WALL_SIGN:4)
Block(-3,13,-1,WALL_SIGN:4)
Block(-3,13,0,WALL_SIGN:4)
Block(-3,13,1,WALL_SIGN:4)
Block(-3,13,2,WALL_SIGN:4)
Block(-3,13,3,WALL_SIGN:4)
Block(-3,17,-2,WALL_SIGN:4)
Block(-3,17,-1,WALL_SIGN:4)
Block(-3,17,0,WALL_SIGN:4)
Block(-3,17,1,WALL_SIGN:4)
Block(-3,17,2,WALL_SIGN:4)
Block(-3,17,3,WALL_SIGN:4)
Block(-2,0,-2,LOG:1)
RandomBlock(-2,0,-1,COBBLESTONE:0,60,MOSSY_COBBLESTONE:0,5,SMOOTH_BRICK:0,10,SMOOTH_BRICK:1,10,SMOOTH_BRICK:2,10,COBBLESTONE:0,100)
RandomBlock(-2,0,0,COBBLESTONE:0,60,MOSSY_COBBLESTONE:0,5,SMOOTH_BRICK:0,10,SMOOTH_BRICK:1,10,SMOOTH_BRICK:2,10,COBBLESTONE:0,100)
RandomBlock(-2,0,1,COBBLESTONE:0,60,MOSSY_COBBLESTONE:0,5,SMOOTH_BRICK:0,10,SMOOTH_BRICK:1,10,SMOOTH_BRICK:2,10,COBBLESTONE:0,100)
RandomBlock(-2,0,2,COBBLESTONE:0,60,MOSSY_COBBLESTONE:0,5,SMOOTH_BRICK:0,10,SMOOTH_BRICK:1,10,SMOOTH_BRICK:2,10,COBBLESTONE:0,100)
Block(-2,0,3,LOG:1)
Block(-2,1,-2,LOG:1)
RandomBlock(-2,1,-1,COBBLESTONE:0,60,MOSSY_COBBLESTONE:0,5,SMOOTH_BRICK:0,10,SMOOTH_BRICK:1,10,SMOOTH_BRICK:2,10,COBBLESTONE:0,100)
RandomBlock(-2,1,0,COBBLESTONE:0,60,MOSSY_COBBLESTONE:0,5,SMOOTH_BRICK:0,10,SMOOTH_BRICK:1,10,SMOOTH_BRICK:2,10,COBBLESTONE:0,100)
RandomBlock(-2,1,1,COBBLESTONE:0,60,MOSSY_COBBLESTONE:0,5,SMOOTH_BRICK:0,10,SMOOTH_BRICK:1,10,SMOOTH_BRICK:2,10,COBBLESTONE:0,100)
RandomBlock(-2,1,2,COBBLESTONE:0,60,MOSSY_COBBLESTONE:0,5,SMOOTH_BRICK:0,10,SMOOTH_BRICK:1,10,SMOOTH_BRICK:2,10,COBBLESTONE:0,100)
Block(-2,1,3,LOG:1)
Block(-2,2,-2,LOG:1)
Block(-2,2,-1,SMOOTH_BRICK:0)
RandomBlock(-2,2,0,COBBLESTONE:0,60,MOSSY_COBBLESTONE:0,5,SMOOTH_BRICK:0,10,SMOOTH_BRICK:1,10,SMOOTH_BRICK:2,10,COBBLESTONE:0,100)
Block(-2,2,1,SMOOTH_BRICK:0)
Block(-2,2,2,SMOOTH_BRICK:0)
Block(-2,2,3,LOG:1)
Block(-2,3,-2,LOG:1)
Block(-2,3,-1,SMOOTH_BRICK:0)
RandomBlock(-2,3,0,COBBLESTONE:0,60,MOSSY_COBBLESTONE:0,5,SMOOTH_BRICK:0,10,SMOOTH_BRICK:1,10,SMOOTH_BRICK:2,10,COBBLESTONE:0,100)
Block(-2,3,1,SMOOTH_BRICK:0)
RandomBlock(-2,3,2,COBBLESTONE:0,60,MOSSY_COBBLESTONE:0,5,SMOOTH_BRICK:0,10,SMOOTH_BRICK:1,10,SMOOTH_BRICK:2,10,COBBLESTONE:0,100)
Block(-2,3,3,LOG:1)
Block(-2,4,-2,LOG:1)
RandomBlock(-2,4,-1,COBBLESTONE:0,60,MOSSY_COBBLESTONE:0,5,SMOOTH_BRICK:0,10,SMOOTH_BRICK:1,10,SMOOTH_BRICK:2,10,COBBLESTONE:0,100)
RandomBlock(-2,4,0,COBBLESTONE:0,60,MOSSY_COBBLESTONE:0,5,SMOOTH_BRICK:0,10,SMOOTH_BRICK:1,10,SMOOTH_BRICK:2,10,COBBLESTONE:0,100)
Block(-2,4,1,SMOOTH_BRICK:0)
RandomBlock(-2,4,2,COBBLESTONE:0,60,MOSSY_COBBLESTONE:0,5,SMOOTH_BRICK:0,10,SMOOTH_BRICK:1,10,SMOOTH_BRICK:2,10,COBBLESTONE:0,100)
Block(-2,4,3,LOG:1)
Block(-2,5,-3,WALL_SIGN:2)
Block(-2,5,-2,LOG:1)
Block(-2,5,-1,SMOOTH_BRICK:0)
Block(-2,5,0,SMOOTH_BRICK:0)
Block(-2,5,1,SMOOTH_BRICK:0)
RandomBlock(-2,5,2,COBBLESTONE:0,60,MOSSY_COBBLESTONE:0,5,SMOOTH_BRICK:0,10,SMOOTH_BRICK:1,10,SMOOTH_BRICK:2,10,COBBLESTONE:0,100)
Block(-2,5,3,LOG:1)
Block(-2,5,4,WALL_SIGN:3)
Block(-2,6,-3,WOOD_BUTTON:4)
Block(-2,6,-2,LOG:1)
Block(-2,6,-1,SMOOTH_BRICK:0)
RandomBlock(-2,6,0,COBBLESTONE:0,60,MOSSY_COBBLESTONE:0,5,SMOOTH_BRICK:0,10,SMOOTH_BRICK:1,10,SMOOTH_BRICK:2,10,COBBLESTONE:0,100)
RandomBlock(-2,6,1,SPRUCE_WOOD_STAIRS:2,70,DARK_OAK_STAIRS:2,100)
RandomBlock(-2,6,2,COBBLESTONE:0,60,MOSSY_COBBLESTONE:0,5,SMOOTH_BRICK:0,10,SMOOTH_BRICK:1,10,SMOOTH_BRICK:2,10,COBBLESTONE:0,100)
Block(-2,6,3,LOG:1)
Block(-2,6,4,WOOD_BUTTON:3)
Block(-2,7,-2,LOG:1)
Block(-2,7,-1,SMOOTH_BRICK:0)
RandomBlock(-2,7,0,COBBLESTONE:0,60,MOSSY_COBBLESTONE:0,5,SMOOTH_BRICK:0,10,SMOOTH_BRICK:1,10,SMOOTH_BRICK:2,10,COBBLESTONE:0,100)
Block(-2,7,1,SPRUCE_WOOD_STAIRS:6)
Block(-2,7,2,SMOOTH_BRICK:0)
Block(-2,7,3,LOG:1)
Block(-2,8,-3,WOOD_BUTTON:4)
Block(-2,8,-2,LOG:1)
Block(-2,8,-1,SMOOTH_BRICK:0)
Block(-2,8,0,SMOOTH_BRICK:0)
RandomBlock(-2,8,1,COBBLESTONE:0,60,MOSSY_COBBLESTONE:0,5,SMOOTH_BRICK:0,10,SMOOTH_BRICK:1,10,SMOOTH_BRICK:2,10,COBBLESTONE:0,100)
Block(-2,8,2,SMOOTH_BRICK:0)
Block(-2,8,3,LOG:1)
Block(-2,8,4,WOOD_BUTTON:3)
Block(-2,9,-3,WALL_SIGN:2)
Block(-2,9,-2,LOG:1)
Block(-2,9,-1,SMOOTH_BRICK:0)
Block(-2,9,0,SMOOTH_BRICK:0)
Block(-2,9,1,SMOOTH_BRICK:0)
Block(-2,9,2,WOOD:1)
Block(-2,9,3,LOG:1)
Block(-2,9,4,WALL_SIGN:3)
Block(-2,10,-3,WOOD_BUTTON:4)
Block(-2,10,-2,LOG:1)
Block(-2,10,-1,SMOOTH_BRICK:0)
Block(-2,10,0,WOOD:1)
RandomBlock(-2,10,1,SPRUCE_WOOD_STAIRS:2,70,DARK_OAK_STAIRS:2,100)
Block(-2,10,2,WOOD:1)
Block(-2,10,3,LOG:1)
Block(-2,10,4,WOOD_BUTTON:3)
Block(-2,11,-2,LOG:1)
Block(-2,11,-1,WOOD:5)
Block(-2,11,0,WOOD:1)
Block(-2,11,1,SPRUCE_WOOD_STAIRS:6)
Block(-2,11,2,WOOD:5)
Block(-2,11,3,LOG:1)
Block(-2,12,-3,WOOD_BUTTON:4)
Block(-2,12,-2,LOG:1)
Block(-2,12,-1,WOOD:5)
Block(-2,12,0,WOOD:5)
Block(-2,12,1,WOOD:1)
Block(-2,12,2,WOOD:5)
Block(-2,12,3,LOG:1)
Block(-2,12,4,WOOD_BUTTON:3)
Block(-2,13,-3,WALL_SIGN:2)
Block(-2,13,-2,LOG:1)
Block(-2,13,-1,WOOD:5)
Block(-2,13,0,WOOD:5)
Block(-2,13,1,WOOD:5)
Block(-2,13,2,WOOD:1)
Block(-2,13,3,LOG:1)
Block(-2,13,4,WALL_SIGN:3)
Block(-2,14,-3,WOOD_BUTTON:4)
Block(-2,14,-2,LOG:1)
Block(-2,14,-1,WOOD:5)
RandomBlock(-2,14,0,SPRUCE_WOOD_STAIRS:3,70,DARK_OAK_STAIRS:3,100)
Block(-2,14,1,WOOD:1)
Block(-2,14,2,WOOD:1)
Block(-2,14,3,LOG:1)
Block(-2,14,4,WOOD_BUTTON:3)
Block(-2,15,-2,LOG:1)
Block(-2,15,-1,WOOD:5)
Block(-2,15,0,SPRUCE_WOOD_STAIRS:7)
Block(-2,15,1,WOOD:1)
Block(-2,15,2,WOOD:5)
Block(-2,15,3,LOG:1)
Block(-2,16,-3,WOOD_BUTTON:4)
Block(-2,16,-2,LOG:1)
Block(-2,16,-1,WOOD:5)
Block(-2,16,0,WOOD:5)
Block(-2,16,1,WOOD:1)
Block(-2,16,2,WOOD:5)
Block(-2,16,3,LOG:1)
Block(-2,16,4,WOOD_BUTTON:3)
Block(-2,17,-3,WALL_SIGN:2)
Block(-2,17,-2,LOG:1)
Block(-2,17,-1,WOOD:1)
Block(-2,17,0,WOOD:5)
Block(-2,17,1,WOOD:1)
Block(-2,17,2,WOOD:5)
Block(-2,17,3,LOG:1)
Block(-2,17,4,WALL_SIGN:3)
Block(-2,18,-2,WOOD:1)
Block(-2,18,0,WOOD:1)
Block(-2,18,1,WOOD:1)
Block(-2,18,3,WOOD:1)
RandomBlock(-2,19,-2,SPRUCE_WOOD_STAIRS:3,70,DARK_OAK_STAIRS:3,100)
RandomBlock(-2,19,0,SPRUCE_WOOD_STAIRS:2,70,DARK_OAK_STAIRS:2,100)
RandomBlock(-2,19,1,SPRUCE_WOOD_STAIRS:3,70,DARK_OAK_STAIRS:3,100)
RandomBlock(-2,19,3,SPRUCE_WOOD_STAIRS:2,70,DARK_OAK_STAIRS:2,100)
RandomBlock(-1,0,-2,COBBLESTONE:0,60,MOSSY_COBBLESTONE:0,5,SMOOTH_BRICK:0,10,SMOOTH_BRICK:1,10,SMOOTH_BRICK:2,10,COBBLESTONE:0,100)
RandomBlock(-1,0,-1,COBBLESTONE:0,60,MOSSY_COBBLESTONE:0,5,SMOOTH_BRICK:0,10,SMOOTH_BRICK:1,10,SMOOTH_BRICK:2,10,COBBLESTONE:0,100)
RandomBlock(-1,0,0,COBBLESTONE:0,60,MOSSY_COBBLESTONE:0,5,SMOOTH_BRICK:0,10,SMOOTH_BRICK:1,10,SMOOTH_BRICK:2,10,COBBLESTONE:0,100)
RandomBlock(-1,0,1,COBBLESTONE:0,60,MOSSY_COBBLESTONE:0,5,SMOOTH_BRICK:0,10,SMOOTH_BRICK:1,10,SMOOTH_BRICK:2,10,COBBLESTONE:0,100)
RandomBlock(-1,0,2,COBBLESTONE:0,60,MOSSY_COBBLESTONE:0,5,SMOOTH_BRICK:0,10,SMOOTH_BRICK:1,10,SMOOTH_BRICK:2,10,COBBLESTONE:0,100)
RandomBlock(-1,0,3,COBBLESTONE:0,60,MOSSY_COBBLESTONE:0,5,SMOOTH_BRICK:0,10,SMOOTH_BRICK:1,10,SMOOTH_BRICK:2,10,COBBLESTONE:0,100)
RandomBlock(-1,1,-2,COBBLESTONE:0,60,MOSSY_COBBLESTONE:0,5,SMOOTH_BRICK:0,10,SMOOTH_BRICK:1,10,SMOOTH_BRICK:2,10,COBBLESTONE:0,100)
RandomBlock(-1,1,-1,COBBLESTONE:0,60,MOSSY_COBBLESTONE:0,5,SMOOTH_BRICK:0,10,SMOOTH_BRICK:1,10,SMOOTH_BRICK:2,10,COBBLESTONE:0,100)
RandomBlock(-1,1,0,COBBLESTONE:0,60,MOSSY_COBBLESTONE:0,5,SMOOTH_BRICK:0,10,SMOOTH_BRICK:1,10,SMOOTH_BRICK:2,10,COBBLESTONE:0,100)
RandomBlock(-1,1,1,COBBLESTONE:0,60,MOSSY_COBBLESTONE:0,5,SMOOTH_BRICK:0,10,SMOOTH_BRICK:1,10,SMOOTH_BRICK:2,10,COBBLESTONE:0,100)
RandomBlock(-1,1,2,COBBLESTONE:0,60,MOSSY_COBBLESTONE:0,5,SMOOTH_BRICK:0,10,SMOOTH_BRICK:1,10,SMOOTH_BRICK:2,10,COBBLESTONE:0,100)
RandomBlock(-1,1,3,COBBLESTONE:0,60,MOSSY_COBBLESTONE:0,5,SMOOTH_BRICK:0,10,SMOOTH_BRICK:1,10,SMOOTH_BRICK:2,10,COBBLESTONE:0,100)
RandomBlock(-1,2,-2,COBBLESTONE:0,60,MOSSY_COBBLESTONE:0,5,SMOOTH_BRICK:0,10,SMOOTH_BRICK:1,10,SMOOTH_BRICK:2,10,COBBLESTONE:0,100)
RandomBlock(-1,2,-1,COBBLESTONE:0,60,MOSSY_COBBLESTONE:0,5,SMOOTH_BRICK:0,10,SMOOTH_BRICK:1,10,SMOOTH_BRICK:2,10,COBBLESTONE:0,100)
RandomBlock(-1,2,0,COBBLESTONE:0,60,MOSSY_COBBLESTONE:0,5,SMOOTH_BRICK:0,10,SMOOTH_BRICK:1,10,SMOOTH_BRICK:2,10,COBBLESTONE:0,100)
Block(-1,2,3,SMOOTH_BRICK:0)
RandomBlock(-1,3,-2,COBBLESTONE:0,60,MOSSY_COBBLESTONE:0,5,SMOOTH_BRICK:0,10,SMOOTH_BRICK:1,10,SMOOTH_BRICK:2,10,COBBLESTONE:0,100)
RandomBlock(-1,3,-1,COBBLESTONE:0,60,MOSSY_COBBLESTONE:0,5,SMOOTH_BRICK:0,10,SMOOTH_BRICK:1,10,SMOOTH_BRICK:2,10,COBBLESTONE:0,100)
RandomBlock(-1,3,0,COBBLESTONE:0,60,MOSSY_COBBLESTONE:0,5,SMOOTH_BRICK:0,10,SMOOTH_BRICK:1,10,SMOOTH_BRICK:2,10,COBBLESTONE:0,100)
Block(-1,3,3,SMOOTH_BRICK:0)
Block(-1,4,-2,SMOOTH_BRICK:0)
Block(-1,4,-1,SMOOTH_BRICK:0)
Block(-1,4,0,LOG:5)
Block(-1,4,3,SMOOTH_BRICK:0)
Block(-1,5,-3,WALL_SIGN:2)
Block(-1,5,-2,SMOOTH_BRICK:0)
RandomBlock(-1,5,-1,WOOD_STEP:1,70,WOOD_STEP:5,100)
RandomBlock(-1,5,0,WOOD_STEP:1,70,WOOD_STEP:5,100)
RandomBlock(-1,5,1,WOOD_STEP:1,70,WOOD_STEP:5,100)
RandomBlock(-1,5,2,WOOD_STEP:1,70,WOOD_STEP:5,100)
Block(-1,5,3,SMOOTH_BRICK:0)
Block(-1,5,4,WALL_SIGN:3)
Block(-1,6,-2,SMOOTH_BRICK:0)
Block(-1,6,3,SMOOTH_BRICK:0)
Block(-1,7,-2,SMOOTH_BRICK:0)
RandomBlock(-1,7,3,COBBLESTONE:0,60,MOSSY_COBBLESTONE:0,5,SMOOTH_BRICK:0,10,SMOOTH_BRICK:1,10,SMOOTH_BRICK:2,10,COBBLESTONE:0,100)
Block(-1,8,-2,SMOOTH_BRICK:0)
RandomBlock(-1,8,-1,WOOD_STEP:9,70,WOOD_STEP:13,100)
RandomBlock(-1,8,0,WOOD_STEP:9,70,WOOD_STEP:13,100)
RandomBlock(-1,8,1,WOOD_STEP:9,70,WOOD_STEP:13,100)
RandomBlock(-1,8,2,WOOD_STEP:9,70,WOOD_STEP:13,100)
RandomBlock(-1,8,3,COBBLESTONE:0,60,MOSSY_COBBLESTONE:0,5,SMOOTH_BRICK:0,10,SMOOTH_BRICK:1,10,SMOOTH_BRICK:2,10,COBBLESTONE:0,100)
Block(-1,9,-3,WALL_SIGN:2)
Block(-1,9,-2,SMOOTH_BRICK:0)
Block(-1,9,3,SMOOTH_BRICK:0)
Block(-1,9,4,WALL_SIGN:3)
Block(-1,10,-2,SMOOTH_BRICK:0)
Block(-1,10,3,SMOOTH_BRICK:0)
Block(-1,11,-2,WOOD:5)
Block(-1,11,3,WOOD:1)
Block(-1,12,-2,WOOD:5)
RandomBlock(-1,12,-1,WOOD_STEP:9,70,WOOD_STEP:13,100)
RandomBlock(-1,12,0,WOOD_STEP:9,70,WOOD_STEP:13,100)
RandomBlock(-1,12,1,WOOD_STEP:9,70,WOOD_STEP:13,100)
RandomBlock(-1,12,2,WOOD_STEP:9,70,WOOD_STEP:13,100)
Block(-1,12,3,WOOD:1)
Block(-1,13,-3,WALL_SIGN:2)
Block(-1,13,-2,WOOD:5)
RandomBlock(-1,13,-1,AIR:0,20,CHEST:3,../../../../Chests/Loot/JunkChest_1.nbt,10,CHEST:3,../../../../Chests/Loot/JunkChest_2.nbt,10,CHEST:3,../../../../Chests/Loot/JunkChest_3.nbt,10,CHEST:3,../../../../Chests/Loot/JunkChest_4.nbt,10,CHEST:3,../../../../Chests/Loot/JunkChest_5.nbt,10,CHEST:3,../../../../Chests/Lore/Viking_1.nbt,1,CHEST:3,../../../../Chests/Lore/Viking_2.nbt,1,CHEST:3,../../../../Chests/Lore/Viking_3.nbt,1,CHEST:3,../../../../Chests/Lore/Viking_4.nbt,1,CHEST:3,../../../../Chests/Lore/Viking_5.nbt,1,CHEST:3,../../../../Chests/Loot/Common1.nbt,10,CHEST:3,../../../../Chests/Loot/Common2.nbt,10,CHEST:3,../../../../Chests/Loot/Common3.nbt,10,CHEST:3,../../../../Chests/Loot/Common4.nbt,10,CHEST:3,../../../../Chests/Loot/Common5.nbt,10,CHEST:3,../../../../Chests/Loot/Common6.nbt,10,CHEST:3,../../../../Chests/Loot/Common7.nbt,10,CHEST:3,../../../../Chests/Loot/Common8.nbt,10,CHEST:3,../../../../Chests/Loot/Common9.nbt,10,CHEST:3,../../../../Chests/Loot/Common10.nbt,10,CHEST:3,../../../../Chests/Loot/Common10.nbt,11,CHEST:3,../../../../Chests/Loot/Common12.nbt,10,CHEST:3,../../../../Chests/Loot/Common13.nbt,10,CHEST:3,../../../../Chests/Loot/Common14.nbt,10,CHEST:3,../../../../Chests/Loot/Common15.nbt,10,CHEST:3,../../../../Chests/Lore/Viking_1.nbt,2,CHEST:3,../../../../Chests/Lore/Viking_3.nbt,2,CHEST:3,../../../../Chests/Lore/Viking_4.nbt,2,CHEST:3,../../../../Chests/Lore/Viking_5.nbt,2,CHEST:3,../../../../Chests/Lore/Viking_5.nbt,2,CHEST:3,../../../../Chests/Loot/Rare1.nbt,5,CHEST:3,../../../../Chests/Loot/Rare2.nbt,5,CHEST:3,../../../../Chests/Loot/Rare3.nbt,5,CHEST:3,../../../../Chests/Loot/Rare4.nbt,5,CHEST:3,../../../../Chests/Loot/Rare5.nbt,5,CHEST:3,../../../../Chests/Loot/Rare6.nbt,5,CHEST:3,../../../../Chests/Loot/Rare7.nbt,5,CHEST:3,../../../../Chests/Loot/Rare8.nbt,5,CHEST:3,../../../../Chests/Loot/Rare9.nbt,5,CHEST:3,../../../../Chests/Loot/Rare10.nbt,5,CHEST:3,../../../../Chests/Loot/Rare11.nbt,5,CHEST:3,../../../../Chests/Loot/Rare12.nbt,5,CHEST:3,../../../../Chests/Loot/Rare13.nbt,5,CHEST:3,../../../../Chests/Loot/Rare14.nbt,5,CHEST:3,../../../../Chests/Loot/Rare15.nbt,5,CHEST:3,../../../../Chests/Loot/Epic1.nbt,2,CHEST:3,../../../../Chests/Loot/Epic2.nbt,2,CHEST:3,../../../../Chests/Loot/Epic3.nbt,2,CHEST:3,../../../../Chests/Loot/Epic4.nbt,2,CHEST:3,../../../../Chests/Loot/Epic5.nbt,2,CHEST:3,../../../../Chests/Loot/Epic6.nbt,2,CHEST:3,../../../../Chests/Loot/Epic7.nbt,2,CHEST:3,../../../../Chests/Loot/Epic8.nbt,2,CHEST:3,../../../../Chests/Loot/Epic9.nbt,2,CHEST:3,../../../../Chests/Loot/Epic10.nbt,2,CHEST:3,../../../../Chests/Loot/Epic11.nbt,2,CHEST:3,../../../../Chests/Loot/Epic12.nbt,2,CHEST:3,../../../../Chests/Loot/Epic13.nbt,2,CHEST:3,../../../../Chests/Loot/Epic14.nbt,2,CHEST:3,../../../../Chests/Loot/Epic15.nbt,5,CHEST:3,../../../../Chests/Loot/Rare1.nbt,5,CHEST:3,../../../../Chests/Loot/Rare2.nbt,5,CHEST:3,../../../../Chests/Loot/Rare3.nbt,5,CHEST:3,../../../../Chests/Loot/Rare4.nbt,5,CHEST:3,../../../../Chests/Loot/Rare5.nbt,10,CHEST:3,../../../../Chests/Loot/Rare6.nbt,10,CHEST:3,../../../../Chests/Loot/Rare7.nbt,10,CHEST:3,../../../../Chests/Loot/Rare8.nbt,10,CHEST:3,../../../../Chests/Loot/Rare9.nbt,10,CHEST:3,../../../../Chests/Loot/Rare10.nbt,15,CHEST:3,../../../../Chests/Loot/Rare11.nbt,15,CHEST:3,../../../../Chests/Loot/Rare12.nbt,15,CHEST:3,../../../../Chests/Loot/Rare13.nbt,15,CHEST:3,../../../../Chests/Loot/Rare14.nbt,15,CHEST:3,../../../../Chests/Loot/Rare15.nbt,15,CHEST:3,../../../../Chests/Loot/Epic15.nbt,100)
Block(-1,13,3,WOOD:5)
Block(-1,13,4,WALL_SIGN:3)
Block(-1,14,-2,WOOD:5)
Block(-1,14,3,WOOD:5)
Block(-1,15,-2,WOOD:5)
Block(-1,15,3,WOOD:1)
Block(-1,16,-2,WOOD:5)
RandomBlock(-1,16,-1,WOOD_STEP:9,70,WOOD_STEP:13,100)
RandomBlock(-1,16,0,WOOD_STEP:9,70,WOOD_STEP:13,100)
RandomBlock(-1,16,1,WOOD_STEP:9,70,WOOD_STEP:13,100)
RandomBlock(-1,16,2,WOOD_STEP:9,70,WOOD_STEP:13,100)
Block(-1,16,3,WOOD:1)
Block(-1,17,-3,WALL_SIGN:2)
Block(-1,17,-2,WOOD:1)
RandomBlock(-1,17,-1,WOOD_STEP:1,70,WOOD_STEP:5,100)
RandomBlock(-1,17,0,WOOD_STEP:1,70,WOOD_STEP:5,100)
RandomBlock(-1,17,1,WOOD_STEP:1,70,WOOD_STEP:5,100)
RandomBlock(-1,17,2,WOOD_STEP:1,70,WOOD_STEP:5,100)
Block(-1,17,3,WOOD:1)
Block(-1,17,4,WALL_SIGN:3)
RandomBlock(0,0,-2,COBBLESTONE:0,60,MOSSY_COBBLESTONE:0,5,SMOOTH_BRICK:0,10,SMOOTH_BRICK:1,10,SMOOTH_BRICK:2,10,COBBLESTONE:0,100)
RandomBlock(0,0,-1,COBBLESTONE:0,60,MOSSY_COBBLESTONE:0,5,SMOOTH_BRICK:0,10,SMOOTH_BRICK:1,10,SMOOTH_BRICK:2,10,COBBLESTONE:0,100)
RandomBlock(0,0,0,COBBLESTONE:0,60,MOSSY_COBBLESTONE:0,5,SMOOTH_BRICK:0,10,SMOOTH_BRICK:1,10,SMOOTH_BRICK:2,10,COBBLESTONE:0,100)
RandomBlock(0,0,1,COBBLESTONE:0,60,MOSSY_COBBLESTONE:0,5,SMOOTH_BRICK:0,10,SMOOTH_BRICK:1,10,SMOOTH_BRICK:2,10,COBBLESTONE:0,100)
RandomBlock(0,0,2,COBBLESTONE:0,60,MOSSY_COBBLESTONE:0,5,SMOOTH_BRICK:0,10,SMOOTH_BRICK:1,10,SMOOTH_BRICK:2,10,COBBLESTONE:0,100)
RandomBlock(0,0,3,COBBLESTONE:0,60,MOSSY_COBBLESTONE:0,5,SMOOTH_BRICK:0,10,SMOOTH_BRICK:1,10,SMOOTH_BRICK:2,10,COBBLESTONE:0,100)
RandomBlock(0,1,-2,COBBLESTONE:0,60,MOSSY_COBBLESTONE:0,5,SMOOTH_BRICK:0,10,SMOOTH_BRICK:1,10,SMOOTH_BRICK:2,10,COBBLESTONE:0,100)
RandomBlock(0,1,-1,COBBLESTONE:0,60,MOSSY_COBBLESTONE:0,5,SMOOTH_BRICK:0,10,SMOOTH_BRICK:1,10,SMOOTH_BRICK:2,10,COBBLESTONE:0,100)
RandomBlock(0,1,0,COBBLESTONE:0,60,MOSSY_COBBLESTONE:0,5,SMOOTH_BRICK:0,10,SMOOTH_BRICK:1,10,SMOOTH_BRICK:2,10,COBBLESTONE:0,100)
RandomBlock(0,1,1,COBBLESTONE:0,60,MOSSY_COBBLESTONE:0,5,SMOOTH_BRICK:0,10,SMOOTH_BRICK:1,10,SMOOTH_BRICK:2,10,COBBLESTONE:0,100)
RandomBlock(0,1,2,COBBLESTONE:0,60,MOSSY_COBBLESTONE:0,5,SMOOTH_BRICK:0,10,SMOOTH_BRICK:1,10,SMOOTH_BRICK:2,10,COBBLESTONE:0,100)
RandomBlock(0,1,3,COBBLESTONE:0,60,MOSSY_COBBLESTONE:0,5,SMOOTH_BRICK:0,10,SMOOTH_BRICK:1,10,SMOOTH_BRICK:2,10,COBBLESTONE:0,100)
Block(0,2,-2,SPRUCE_DOOR:1)
Block(0,2,0,SPRUCE_DOOR:1)
RandomBlock(0,2,3,COBBLESTONE:0,60,MOSSY_COBBLESTONE:0,5,SMOOTH_BRICK:0,10,SMOOTH_BRICK:1,10,SMOOTH_BRICK:2,10,COBBLESTONE:0,100)
Block(0,3,-2,SPRUCE_DOOR:9)
Block(0,3,0,SPRUCE_DOOR:8)
RandomBlock(0,3,3,COBBLESTONE:0,60,MOSSY_COBBLESTONE:0,5,SMOOTH_BRICK:0,10,SMOOTH_BRICK:1,10,SMOOTH_BRICK:2,10,COBBLESTONE:0,100)
Block(0,4,-2,SMOOTH_BRICK:0)
Block(0,4,-1,IRON_FENCE:0)
Block(0,4,0,LOG:5)
RandomBlock(0,4,3,COBBLESTONE:0,60,MOSSY_COBBLESTONE:0,5,SMOOTH_BRICK:0,10,SMOOTH_BRICK:1,10,SMOOTH_BRICK:2,10,COBBLESTONE:0,100)
Block(0,5,-3,WALL_SIGN:2)
RandomBlock(0,5,-2,COBBLESTONE:0,60,MOSSY_COBBLESTONE:0,5,SMOOTH_BRICK:0,10,SMOOTH_BRICK:1,10,SMOOTH_BRICK:2,10,COBBLESTONE:0,100)
Block(0,5,-1,TRAP_DOOR:1)
RandomBlock(0,5,0,WOOD_STEP:1,70,WOOD_STEP:5,100)
RandomBlock(0,5,1,WOOD_STEP:1,70,WOOD_STEP:5,100)
RandomBlock(0,5,2,WOOD_STEP:1,70,WOOD_STEP:5,100)
RandomBlock(0,5,3,COBBLESTONE:0,60,MOSSY_COBBLESTONE:0,5,SMOOTH_BRICK:0,10,SMOOTH_BRICK:1,10,SMOOTH_BRICK:2,10,COBBLESTONE:0,100)
Block(0,5,4,WALL_SIGN:3)
RandomBlock(0,6,-2,SPRUCE_WOOD_STAIRS:1,70,DARK_OAK_STAIRS:1,100)
RandomBlock(0,6,3,COBBLESTONE:0,60,MOSSY_COBBLESTONE:0,5,SMOOTH_BRICK:0,10,SMOOTH_BRICK:1,10,SMOOTH_BRICK:2,10,COBBLESTONE:0,100)
Block(0,7,-2,SPRUCE_WOOD_STAIRS:5)
RandomBlock(0,7,3,COBBLESTONE:0,60,MOSSY_COBBLESTONE:0,5,SMOOTH_BRICK:0,10,SMOOTH_BRICK:1,10,SMOOTH_BRICK:2,10,COBBLESTONE:0,100)
RandomBlock(0,8,-2,COBBLESTONE:0,60,MOSSY_COBBLESTONE:0,5,SMOOTH_BRICK:0,10,SMOOTH_BRICK:1,10,SMOOTH_BRICK:2,10,COBBLESTONE:0,100)
RandomBlock(0,8,-1,WOOD_STEP:9,70,WOOD_STEP:13,100)
RandomBlock(0,8,0,WOOD_STEP:9,70,WOOD_STEP:13,100)
RandomBlock(0,8,1,WOOD_STEP:9,70,WOOD_STEP:13,100)
RandomBlock(0,8,2,WOOD_STEP:9,70,WOOD_STEP:13,100)
Block(0,8,3,SMOOTH_BRICK:0)
Block(0,9,-3,WALL_SIGN:2)
Block(0,9,-2,WOOD:1)
Block(0,9,3,WOOD:1)
Block(0,9,4,WALL_SIGN:3)
Block(0,10,-2,WOOD:1)
Block(0,10,3,WOOD:1)
Block(0,11,-2,WOOD:1)
Block(0,11,3,WOOD:1)
Block(0,12,-2,WOOD:1)
RandomBlock(0,12,-1,WOOD_STEP:9,70,WOOD_STEP:13,100)
RandomBlock(0,12,0,WOOD_STEP:9,70,WOOD_STEP:13,100)
RandomBlock(0,12,1,WOOD_STEP:9,70,WOOD_STEP:13,100)
RandomBlock(0,12,2,WOOD_STEP:9,70,WOOD_STEP:13,100)
Block(0,12,3,WOOD:5)
Block(0,13,-3,WALL_SIGN:2)
Block(0,13,-2,WOOD:1)
Block(0,13,3,WOOD:1)
Block(0,13,4,WALL_SIGN:3)
RandomBlock(0,14,-2,SPRUCE_WOOD_STAIRS:1,70,DARK_OAK_STAIRS:1,100)
Block(0,14,3,WOOD:1)
Block(0,15,-2,SPRUCE_WOOD_STAIRS:5)
Block(0,15,3,WOOD:1)
Block(0,16,-2,WOOD:1)
RandomBlock(0,16,-1,WOOD_STEP:9,70,WOOD_STEP:13,100)
RandomBlock(0,16,0,WOOD_STEP:9,70,WOOD_STEP:13,100)
RandomBlock(0,16,1,WOOD_STEP:9,70,WOOD_STEP:13,100)
RandomBlock(0,16,2,WOOD_STEP:9,70,WOOD_STEP:13,100)
Block(0,16,3,WOOD:5)
Block(0,17,-3,WALL_SIGN:2)
Block(0,17,-2,WOOD:1)
Block(0,17,-1,WOOD_DOUBLE_STEP:1)
RandomBlock(0,17,0,WOOD_STEP:1,70,WOOD_STEP:5,100)
RandomBlock(0,17,1,WOOD_STEP:1,70,WOOD_STEP:5,100)
RandomBlock(0,17,2,WOOD_STEP:1,70,WOOD_STEP:5,100)
Block(0,17,3,WOOD:5)
Block(0,17,4,WALL_SIGN:3)
Block(0,18,-2,WOOD:1)
Block(0,18,-1,DARK_OAK_FENCE:0)
Block(0,18,1,AIR:0)
Block(0,18,3,WOOD:5)
RandomBlock(0,19,-2,SPRUCE_WOOD_STAIRS:0,70,DARK_OAK_STAIRS:0,100)
Block(0,19,-1,DARK_OAK_FENCE:0)
RandomBlock(0,19,3,SPRUCE_WOOD_STAIRS:0,70,DARK_OAK_STAIRS:0,100)
Block(0,20,-1,DARK_OAK_FENCE:0)
Block(0,21,-1,DARK_OAK_FENCE:0)
RandomBlock(0,22,-1,STANDING_BANNER:8,../../NBT/Banners/viking_emblem_1.nbt,20,STANDING_BANNER:8,../../NBT/Banners/viking_emblem_2.nbt,20,STANDING_BANNER:8,../../NBT/Banners/viking_emblem_3.nbt,20,STANDING_BANNER:8,../../NBT/Banners/viking_emblem_4.nbt,100)
RandomBlock(1,0,-2,COBBLESTONE:0,60,MOSSY_COBBLESTONE:0,5,SMOOTH_BRICK:0,10,SMOOTH_BRICK:1,10,SMOOTH_BRICK:2,10,COBBLESTONE:0,100)
RandomBlock(1,0,-1,COBBLESTONE:0,60,MOSSY_COBBLESTONE:0,5,SMOOTH_BRICK:0,10,SMOOTH_BRICK:1,10,SMOOTH_BRICK:2,10,COBBLESTONE:0,100)
RandomBlock(1,0,0,COBBLESTONE:0,60,MOSSY_COBBLESTONE:0,5,SMOOTH_BRICK:0,10,SMOOTH_BRICK:1,10,SMOOTH_BRICK:2,10,COBBLESTONE:0,100)
RandomBlock(1,0,1,COBBLESTONE:0,60,MOSSY_COBBLESTONE:0,5,SMOOTH_BRICK:0,10,SMOOTH_BRICK:1,10,SMOOTH_BRICK:2,10,COBBLESTONE:0,100)
RandomBlock(1,0,2,COBBLESTONE:0,60,MOSSY_COBBLESTONE:0,5,SMOOTH_BRICK:0,10,SMOOTH_BRICK:1,10,SMOOTH_BRICK:2,10,COBBLESTONE:0,100)
RandomBlock(1,0,3,COBBLESTONE:0,60,MOSSY_COBBLESTONE:0,5,SMOOTH_BRICK:0,10,SMOOTH_BRICK:1,10,SMOOTH_BRICK:2,10,COBBLESTONE:0,100)
RandomBlock(1,1,-2,COBBLESTONE:0,60,MOSSY_COBBLESTONE:0,5,SMOOTH_BRICK:0,10,SMOOTH_BRICK:1,10,SMOOTH_BRICK:2,10,COBBLESTONE:0,100)
RandomBlock(1,1,-1,COBBLESTONE:0,60,MOSSY_COBBLESTONE:0,5,SMOOTH_BRICK:0,10,SMOOTH_BRICK:1,10,SMOOTH_BRICK:2,10,COBBLESTONE:0,100)
RandomBlock(1,1,0,COBBLESTONE:0,60,MOSSY_COBBLESTONE:0,5,SMOOTH_BRICK:0,10,SMOOTH_BRICK:1,10,SMOOTH_BRICK:2,10,COBBLESTONE:0,100)
RandomBlock(1,1,1,COBBLESTONE:0,60,MOSSY_COBBLESTONE:0,5,SMOOTH_BRICK:0,10,SMOOTH_BRICK:1,10,SMOOTH_BRICK:2,10,COBBLESTONE:0,100)
RandomBlock(1,1,2,COBBLESTONE:0,60,MOSSY_COBBLESTONE:0,5,SMOOTH_BRICK:0,10,SMOOTH_BRICK:1,10,SMOOTH_BRICK:2,10,COBBLESTONE:0,100)
RandomBlock(1,1,3,COBBLESTONE:0,60,MOSSY_COBBLESTONE:0,5,SMOOTH_BRICK:0,10,SMOOTH_BRICK:1,10,SMOOTH_BRICK:2,10,COBBLESTONE:0,100)
RandomBlock(1,2,-2,COBBLESTONE:0,60,MOSSY_COBBLESTONE:0,5,SMOOTH_BRICK:0,10,SMOOTH_BRICK:1,10,SMOOTH_BRICK:2,10,COBBLESTONE:0,100)
RandomBlock(1,2,-1,COBBLESTONE:0,60,MOSSY_COBBLESTONE:0,5,SMOOTH_BRICK:0,10,SMOOTH_BRICK:1,10,SMOOTH_BRICK:2,10,COBBLESTONE:0,100)
Block(1,2,0,LOG:1)
Block(1,2,1,LADDER:3)
Block(1,2,3,SMOOTH_BRICK:0)
RandomBlock(1,3,-2,COBBLESTONE:0,60,MOSSY_COBBLESTONE:0,5,SMOOTH_BRICK:0,10,SMOOTH_BRICK:1,10,SMOOTH_BRICK:2,10,COBBLESTONE:0,100)
Block(1,3,-1,IRON_FENCE:0)
Block(1,3,0,LOG:1)
Block(1,3,1,LADDER:3)
Block(1,3,3,SMOOTH_BRICK:0)
Block(1,4,-2,SMOOTH_BRICK:0)
RandomBlock(1,4,-1,COBBLESTONE:0,60,MOSSY_COBBLESTONE:0,5,SMOOTH_BRICK:0,10,SMOOTH_BRICK:1,10,SMOOTH_BRICK:2,10,COBBLESTONE:0,100)
Block(1,4,0,LOG:1)
Block(1,4,1,LADDER:3)
Block(1,4,3,SMOOTH_BRICK:0)
Block(1,5,-3,WALL_SIGN:2)
RandomBlock(1,5,-2,COBBLESTONE:0,60,MOSSY_COBBLESTONE:0,5,SMOOTH_BRICK:0,10,SMOOTH_BRICK:1,10,SMOOTH_BRICK:2,10,COBBLESTONE:0,100)
RandomBlock(1,5,-1,WOOD_STEP:1,70,WOOD_STEP:5,100)
Block(1,5,0,LOG:1)
Block(1,5,1,LADDER:3)
RandomBlock(1,5,2,WOOD_STEP:1,70,WOOD_STEP:5,100)
Block(1,5,3,SMOOTH_BRICK:0)
Block(1,5,4,WALL_SIGN:3)
RandomBlock(1,6,-2,COBBLESTONE:0,60,MOSSY_COBBLESTONE:0,5,SMOOTH_BRICK:0,10,SMOOTH_BRICK:1,10,SMOOTH_BRICK:2,10,COBBLESTONE:0,100)
Block(1,6,0,LOG:1)
Block(1,6,1,LADDER:3)
RandomBlock(1,6,3,SPRUCE_WOOD_STAIRS:0,70,DARK_OAK_STAIRS:0,100)
RandomBlock(1,7,-2,COBBLESTONE:0,60,MOSSY_COBBLESTONE:0,5,SMOOTH_BRICK:0,10,SMOOTH_BRICK:1,10,SMOOTH_BRICK:2,10,COBBLESTONE:0,100)
Block(1,7,0,LOG:1)
Block(1,7,1,LADDER:3)
Block(1,7,3,SPRUCE_WOOD_STAIRS:4)
Block(1,8,-2,SMOOTH_BRICK:0)
RandomBlock(1,8,-1,WOOD_STEP:9,70,WOOD_STEP:13,100)
Block(1,8,0,LOG:1)
Block(1,8,1,LADDER:3)
RandomBlock(1,8,2,WOOD_STEP:9,70,WOOD_STEP:13,100)
Block(1,8,3,SMOOTH_BRICK:0)
Block(1,9,-3,WALL_SIGN:2)
Block(1,9,-2,WOOD:1)
Block(1,9,0,LOG:1)
Block(1,9,1,LADDER:3)
Block(1,9,3,SMOOTH_BRICK:0)
Block(1,9,4,WALL_SIGN:3)
RandomBlock(1,10,-2,SPRUCE_WOOD_STAIRS:0,70,DARK_OAK_STAIRS:0,100)
Block(1,10,0,LOG:1)
Block(1,10,1,LADDER:3)
RandomBlock(1,10,3,SPRUCE_WOOD_STAIRS:0,70,DARK_OAK_STAIRS:0,100)
Block(1,11,-2,SPRUCE_WOOD_STAIRS:4)
Block(1,11,0,LOG:1)
Block(1,11,1,LADDER:3)
Block(1,11,3,SPRUCE_WOOD_STAIRS:4)
Block(1,12,-2,WOOD:5)
RandomBlock(1,12,-1,WOOD_STEP:9,70,WOOD_STEP:13,100)
Block(1,12,0,LOG:1)
Block(1,12,1,LADDER:3)
RandomBlock(1,12,2,WOOD_STEP:9,70,WOOD_STEP:13,100)
Block(1,12,3,WOOD:5)
Block(1,13,-3,WALL_SIGN:2)
Block(1,13,-2,WOOD:1)
Block(1,13,0,LOG:1)
Block(1,13,1,LADDER:3)
Block(1,13,3,WOOD:5)
Block(1,13,4,WALL_SIGN:3)
Block(1,14,-2,WOOD:1)
Block(1,14,0,LOG:1)
Block(1,14,1,LADDER:3)
RandomBlock(1,14,3,SPRUCE_WOOD_STAIRS:0,70,DARK_OAK_STAIRS:0,100)
Block(1,15,-2,WOOD:1)
Block(1,15,0,LOG:1)
Block(1,15,1,LADDER:3)
Block(1,15,3,SPRUCE_WOOD_STAIRS:4)
Block(1,16,-2,WOOD:5)
RandomBlock(1,16,-1,WOOD_STEP:9,70,WOOD_STEP:13,100)
Block(1,16,0,LOG:1)
Block(1,16,1,LADDER:3)
RandomBlock(1,16,2,WOOD_STEP:9,70,WOOD_STEP:13,100)
Block(1,16,3,WOOD:5)
Block(1,17,-3,WALL_SIGN:2)
Block(1,17,-2,WOOD:5)
RandomBlock(1,17,-1,WOOD_STEP:1,70,WOOD_STEP:5,100)
RandomBlock(1,17,0,WOOD_STEP:1,70,WOOD_STEP:5,100)
Block(1,17,1,TRAP_DOOR:0)
RandomBlock(1,17,2,WOOD_STEP:1,70,WOOD_STEP:5,100)
Block(1,17,3,WOOD:1)
Block(1,17,4,WALL_SIGN:3)
Block(1,18,-2,WOOD:1)
Block(1,18,3,WOOD:1)
RandomBlock(1,19,-2,SPRUCE_WOOD_STAIRS:1,70,DARK_OAK_STAIRS:1,100)
RandomBlock(1,19,3,SPRUCE_WOOD_STAIRS:1,70,DARK_OAK_STAIRS:1,100)
RandomBlock(2,0,-2,COBBLESTONE:0,60,MOSSY_COBBLESTONE:0,5,SMOOTH_BRICK:0,10,SMOOTH_BRICK:1,10,SMOOTH_BRICK:2,10,COBBLESTONE:0,100)
RandomBlock(2,0,-1,COBBLESTONE:0,60,MOSSY_COBBLESTONE:0,5,SMOOTH_BRICK:0,10,SMOOTH_BRICK:1,10,SMOOTH_BRICK:2,10,COBBLESTONE:0,100)
RandomBlock(2,0,0,COBBLESTONE:0,60,MOSSY_COBBLESTONE:0,5,SMOOTH_BRICK:0,10,SMOOTH_BRICK:1,10,SMOOTH_BRICK:2,10,COBBLESTONE:0,100)
RandomBlock(2,0,1,COBBLESTONE:0,60,MOSSY_COBBLESTONE:0,5,SMOOTH_BRICK:0,10,SMOOTH_BRICK:1,10,SMOOTH_BRICK:2,10,COBBLESTONE:0,100)
RandomBlock(2,0,2,COBBLESTONE:0,60,MOSSY_COBBLESTONE:0,5,SMOOTH_BRICK:0,10,SMOOTH_BRICK:1,10,SMOOTH_BRICK:2,10,COBBLESTONE:0,100)
RandomBlock(2,0,3,COBBLESTONE:0,60,MOSSY_COBBLESTONE:0,5,SMOOTH_BRICK:0,10,SMOOTH_BRICK:1,10,SMOOTH_BRICK:2,10,COBBLESTONE:0,100)
RandomBlock(2,1,-2,COBBLESTONE:0,60,MOSSY_COBBLESTONE:0,5,SMOOTH_BRICK:0,10,SMOOTH_BRICK:1,10,SMOOTH_BRICK:2,10,COBBLESTONE:0,100)
RandomBlock(2,1,-1,COBBLESTONE:0,60,MOSSY_COBBLESTONE:0,5,SMOOTH_BRICK:0,10,SMOOTH_BRICK:1,10,SMOOTH_BRICK:2,10,COBBLESTONE:0,100)
RandomBlock(2,1,0,COBBLESTONE:0,60,MOSSY_COBBLESTONE:0,5,SMOOTH_BRICK:0,10,SMOOTH_BRICK:1,10,SMOOTH_BRICK:2,10,COBBLESTONE:0,100)
RandomBlock(2,1,1,COBBLESTONE:0,60,MOSSY_COBBLESTONE:0,5,SMOOTH_BRICK:0,10,SMOOTH_BRICK:1,10,SMOOTH_BRICK:2,10,COBBLESTONE:0,100)
RandomBlock(2,1,2,COBBLESTONE:0,60,MOSSY_COBBLESTONE:0,5,SMOOTH_BRICK:0,10,SMOOTH_BRICK:1,10,SMOOTH_BRICK:2,10,COBBLESTONE:0,100)
RandomBlock(2,1,3,COBBLESTONE:0,60,MOSSY_COBBLESTONE:0,5,SMOOTH_BRICK:0,10,SMOOTH_BRICK:1,10,SMOOTH_BRICK:2,10,COBBLESTONE:0,100)
Block(2,2,-2,SMOOTH_BRICK:0)
RandomBlock(2,2,3,COBBLESTONE:0,60,MOSSY_COBBLESTONE:0,5,SMOOTH_BRICK:0,10,SMOOTH_BRICK:1,10,SMOOTH_BRICK:2,10,COBBLESTONE:0,100)
Block(2,3,-2,SMOOTH_BRICK:0)
RandomBlock(2,3,3,COBBLESTONE:0,60,MOSSY_COBBLESTONE:0,5,SMOOTH_BRICK:0,10,SMOOTH_BRICK:1,10,SMOOTH_BRICK:2,10,COBBLESTONE:0,100)
Block(2,4,-2,SMOOTH_BRICK:0)
Block(2,4,-1,WEB:0)
Block(2,4,0,LOG:5)
RandomBlock(2,4,3,COBBLESTONE:0,60,MOSSY_COBBLESTONE:0,5,SMOOTH_BRICK:0,10,SMOOTH_BRICK:1,10,SMOOTH_BRICK:2,10,COBBLESTONE:0,100)
Block(2,5,-3,WALL_SIGN:2)
RandomBlock(2,5,-2,COBBLESTONE:0,60,MOSSY_COBBLESTONE:0,5,SMOOTH_BRICK:0,10,SMOOTH_BRICK:1,10,SMOOTH_BRICK:2,10,COBBLESTONE:0,100)
RandomBlock(2,5,-1,WOOD_STEP:1,70,WOOD_STEP:5,100)
RandomBlock(2,5,0,WOOD_STEP:1,70,WOOD_STEP:5,100)
RandomBlock(2,5,1,WOOD_STEP:1,70,WOOD_STEP:5,100)
RandomBlock(2,5,2,WOOD_STEP:1,70,WOOD_STEP:5,100)
Block(2,5,3,SMOOTH_BRICK:0)
Block(2,5,4,WALL_SIGN:3)
Block(2,6,-2,SMOOTH_BRICK:0)
Block(2,6,3,SMOOTH_BRICK:0)
Block(2,7,-2,SMOOTH_BRICK:0)
Block(2,7,3,SMOOTH_BRICK:0)
Block(2,8,-2,WOOD:1)
RandomBlock(2,8,-1,WOOD_STEP:9,70,WOOD_STEP:13,100)
RandomBlock(2,8,0,WOOD_STEP:9,70,WOOD_STEP:13,100)
RandomBlock(2,8,1,WOOD_STEP:9,70,WOOD_STEP:13,100)
RandomBlock(2,8,2,WOOD_STEP:9,70,WOOD_STEP:13,100)
Block(2,8,3,SMOOTH_BRICK:0)
Block(2,9,-3,WALL_SIGN:2)
Block(2,9,-2,WOOD:1)
Block(2,9,3,SMOOTH_BRICK:0)
Block(2,9,4,WALL_SIGN:3)
Block(2,10,-2,WOOD:5)
Block(2,10,3,SMOOTH_BRICK:0)
Block(2,11,-2,WOOD:5)
Block(2,11,3,WOOD:5)
Block(2,12,-2,WOOD:5)
RandomBlock(2,12,-1,WOOD_STEP:9,70,WOOD_STEP:13,100)
RandomBlock(2,12,0,WOOD_STEP:9,70,WOOD_STEP:13,100)
RandomBlock(2,12,1,WOOD_STEP:9,70,WOOD_STEP:13,100)
RandomBlock(2,12,2,WOOD_STEP:9,70,WOOD_STEP:13,100)
Block(2,12,3,WOOD:5)
Block(2,13,-3,WALL_SIGN:2)
Block(2,13,-2,WOOD:1)
Block(2,13,3,WOOD:5)
Block(2,13,4,WALL_SIGN:3)
Block(2,14,-2,WOOD:5)
Block(2,14,3,WOOD:5)
Block(2,15,-2,WOOD:5)
Block(2,15,3,WOOD:5)
Block(2,16,-2,WOOD:5)
RandomBlock(2,16,-1,WOOD_STEP:9,70,WOOD_STEP:13,100)
RandomBlock(2,16,0,WOOD_STEP:9,70,WOOD_STEP:13,100)
RandomBlock(2,16,1,WOOD_STEP:9,70,WOOD_STEP:13,100)
RandomBlock(2,16,2,WOOD_STEP:9,70,WOOD_STEP:13,100)
Block(2,16,3,WOOD:5)
Block(2,17,-3,WALL_SIGN:2)
Block(2,17,-2,WOOD:1)
RandomBlock(2,17,-1,WOOD_STEP:1,70,WOOD_STEP:5,100)
RandomBlock(2,17,0,WOOD_STEP:1,70,WOOD_STEP:5,100)
RandomBlock(2,17,1,WOOD_STEP:1,70,WOOD_STEP:5,100)
RandomBlock(2,17,2,WOOD_STEP:1,70,WOOD_STEP:5,100)
Block(2,17,3,WOOD:1)
Block(2,17,4,WALL_SIGN:3)
Block(3,0,-2,LOG:1)
RandomBlock(3,0,-1,COBBLESTONE:0,60,MOSSY_COBBLESTONE:0,5,SMOOTH_BRICK:0,10,SMOOTH_BRICK:1,10,SMOOTH_BRICK:2,10,COBBLESTONE:0,100)
RandomBlock(3,0,0,COBBLESTONE:0,60,MOSSY_COBBLESTONE:0,5,SMOOTH_BRICK:0,10,SMOOTH_BRICK:1,10,SMOOTH_BRICK:2,10,COBBLESTONE:0,100)
RandomBlock(3,0,1,COBBLESTONE:0,60,MOSSY_COBBLESTONE:0,5,SMOOTH_BRICK:0,10,SMOOTH_BRICK:1,10,SMOOTH_BRICK:2,10,COBBLESTONE:0,100)
RandomBlock(3,0,2,COBBLESTONE:0,60,MOSSY_COBBLESTONE:0,5,SMOOTH_BRICK:0,10,SMOOTH_BRICK:1,10,SMOOTH_BRICK:2,10,COBBLESTONE:0,100)
Block(3,0,3,LOG:1)
Block(3,1,-2,LOG:1)
RandomBlock(3,1,-1,COBBLESTONE:0,60,MOSSY_COBBLESTONE:0,5,SMOOTH_BRICK:0,10,SMOOTH_BRICK:1,10,SMOOTH_BRICK:2,10,COBBLESTONE:0,100)
RandomBlock(3,1,0,COBBLESTONE:0,60,MOSSY_COBBLESTONE:0,5,SMOOTH_BRICK:0,10,SMOOTH_BRICK:1,10,SMOOTH_BRICK:2,10,COBBLESTONE:0,100)
RandomBlock(3,1,1,COBBLESTONE:0,60,MOSSY_COBBLESTONE:0,5,SMOOTH_BRICK:0,10,SMOOTH_BRICK:1,10,SMOOTH_BRICK:2,10,COBBLESTONE:0,100)
RandomBlock(3,1,2,COBBLESTONE:0,60,MOSSY_COBBLESTONE:0,5,SMOOTH_BRICK:0,10,SMOOTH_BRICK:1,10,SMOOTH_BRICK:2,10,COBBLESTONE:0,100)
Block(3,1,3,LOG:1)
Block(3,2,-2,LOG:1)
RandomBlock(3,2,-1,COBBLESTONE:0,60,MOSSY_COBBLESTONE:0,5,SMOOTH_BRICK:0,10,SMOOTH_BRICK:1,10,SMOOTH_BRICK:2,10,COBBLESTONE:0,100)
Block(3,2,0,SMOOTH_BRICK:0)
Block(3,2,1,SMOOTH_BRICK:0)
Block(3,2,2,SMOOTH_BRICK:0)
Block(3,2,3,LOG:1)
Block(3,3,-2,LOG:1)
RandomBlock(3,3,-1,COBBLESTONE:0,60,MOSSY_COBBLESTONE:0,5,SMOOTH_BRICK:0,10,SMOOTH_BRICK:1,10,SMOOTH_BRICK:2,10,COBBLESTONE:0,100)
Block(3,3,0,SMOOTH_BRICK:0)
RandomBlock(3,3,1,COBBLESTONE:0,60,MOSSY_COBBLESTONE:0,5,SMOOTH_BRICK:0,10,SMOOTH_BRICK:1,10,SMOOTH_BRICK:2,10,COBBLESTONE:0,100)
RandomBlock(3,3,2,COBBLESTONE:0,60,MOSSY_COBBLESTONE:0,5,SMOOTH_BRICK:0,10,SMOOTH_BRICK:1,10,SMOOTH_BRICK:2,10,COBBLESTONE:0,100)
Block(3,3,3,LOG:1)
Block(3,4,-2,LOG:1)
RandomBlock(3,4,-1,COBBLESTONE:0,60,MOSSY_COBBLESTONE:0,5,SMOOTH_BRICK:0,10,SMOOTH_BRICK:1,10,SMOOTH_BRICK:2,10,COBBLESTONE:0,100)
Block(3,4,0,SMOOTH_BRICK:0)
RandomBlock(3,4,1,COBBLESTONE:0,60,MOSSY_COBBLESTONE:0,5,SMOOTH_BRICK:0,10,SMOOTH_BRICK:1,10,SMOOTH_BRICK:2,10,COBBLESTONE:0,100)
RandomBlock(3,4,2,COBBLESTONE:0,60,MOSSY_COBBLESTONE:0,5,SMOOTH_BRICK:0,10,SMOOTH_BRICK:1,10,SMOOTH_BRICK:2,10,COBBLESTONE:0,100)
Block(3,4,3,LOG:1)
Block(3,5,-3,WALL_SIGN:2)
Block(3,5,-2,LOG:1)
Block(3,5,-1,SMOOTH_BRICK:0)
Block(3,5,0,SMOOTH_BRICK:0)
RandomBlock(3,5,1,COBBLESTONE:0,60,MOSSY_COBBLESTONE:0,5,SMOOTH_BRICK:0,10,SMOOTH_BRICK:1,10,SMOOTH_BRICK:2,10,COBBLESTONE:0,100)
RandomBlock(3,5,2,COBBLESTONE:0,60,MOSSY_COBBLESTONE:0,5,SMOOTH_BRICK:0,10,SMOOTH_BRICK:1,10,SMOOTH_BRICK:2,10,COBBLESTONE:0,100)
Block(3,5,3,LOG:1)
Block(3,5,4,WALL_SIGN:3)
Block(3,6,-3,WOOD_BUTTON:4)
Block(3,6,-2,LOG:1)
Block(3,6,-1,SMOOTH_BRICK:0)
RandomBlock(3,6,0,COBBLESTONE:0,60,MOSSY_COBBLESTONE:0,5,SMOOTH_BRICK:0,10,SMOOTH_BRICK:1,10,SMOOTH_BRICK:2,10,COBBLESTONE:0,100)
RandomBlock(3,6,1,SPRUCE_WOOD_STAIRS:2,70,DARK_OAK_STAIRS:2,100)
Block(3,6,2,SMOOTH_BRICK:0)
Block(3,6,3,LOG:1)
Block(3,6,4,WOOD_BUTTON:3)
Block(3,7,-2,LOG:1)
RandomBlock(3,7,-1,COBBLESTONE:0,60,MOSSY_COBBLESTONE:0,5,SMOOTH_BRICK:0,10,SMOOTH_BRICK:1,10,SMOOTH_BRICK:2,10,COBBLESTONE:0,100)
RandomBlock(3,7,0,COBBLESTONE:0,60,MOSSY_COBBLESTONE:0,5,SMOOTH_BRICK:0,10,SMOOTH_BRICK:1,10,SMOOTH_BRICK:2,10,COBBLESTONE:0,100)
Block(3,7,1,SPRUCE_WOOD_STAIRS:6)
Block(3,7,2,SMOOTH_BRICK:0)
Block(3,7,3,LOG:1)
Block(3,8,-3,WOOD_BUTTON:4)
Block(3,8,-2,LOG:1)
RandomBlock(3,8,-1,COBBLESTONE:0,60,MOSSY_COBBLESTONE:0,5,SMOOTH_BRICK:0,10,SMOOTH_BRICK:1,10,SMOOTH_BRICK:2,10,COBBLESTONE:0,100)
RandomBlock(3,8,0,COBBLESTONE:0,60,MOSSY_COBBLESTONE:0,5,SMOOTH_BRICK:0,10,SMOOTH_BRICK:1,10,SMOOTH_BRICK:2,10,COBBLESTONE:0,100)
Block(3,8,1,SMOOTH_BRICK:0)
Block(3,8,2,SMOOTH_BRICK:0)
Block(3,8,3,LOG:1)
Block(3,8,4,WOOD_BUTTON:3)
Block(3,9,-3,WALL_SIGN:2)
Block(3,9,-2,LOG:1)
Block(3,9,-1,SMOOTH_BRICK:0)
Block(3,9,0,SMOOTH_BRICK:0)
Block(3,9,1,WOOD:1)
Block(3,9,2,WOOD:1)
Block(3,9,3,LOG:1)
Block(3,9,4,WALL_SIGN:3)
Block(3,10,-3,WOOD_BUTTON:4)
Block(3,10,-2,LOG:1)
Block(3,10,-1,SMOOTH_BRICK:0)
RandomBlock(3,10,0,SPRUCE_WOOD_STAIRS:3,70,DARK_OAK_STAIRS:3,100)
Block(3,10,1,WOOD:1)
Block(3,10,2,WOOD:5)
Block(3,10,3,LOG:1)
Block(3,10,4,WOOD_BUTTON:3)
Block(3,11,-2,LOG:1)
Block(3,11,-1,WOOD:1)
Block(3,11,0,SPRUCE_WOOD_STAIRS:7)
Block(3,11,1,WOOD:1)
Block(3,11,2,WOOD:5)
Block(3,11,3,LOG:1)
Block(3,12,-3,WOOD_BUTTON:4)
Block(3,12,-2,LOG:1)
Block(3,12,-1,WOOD:1)
Block(3,12,0,WOOD:1)
Block(3,12,1,WOOD:5)
Block(3,12,2,WOOD:5)
Block(3,12,3,LOG:1)
Block(3,12,4,WOOD_BUTTON:3)
Block(3,13,-3,WALL_SIGN:2)
Block(3,13,-2,LOG:1)
Block(3,13,-1,WOOD:5)
Block(3,13,0,WOOD:5)
Block(3,13,1,WOOD:1)
Block(3,13,2,WOOD:1)
Block(3,13,3,LOG:1)
Block(3,13,4,WALL_SIGN:3)
Block(3,14,-3,WOOD_BUTTON:4)
Block(3,14,-2,LOG:1)
Block(3,14,-1,WOOD:5)
RandomBlock(3,14,0,SPRUCE_WOOD_STAIRS:3,70,DARK_OAK_STAIRS:3,100)
Block(3,14,1,WOOD:1)
Block(3,14,2,WOOD:5)
Block(3,14,3,LOG:1)
Block(3,14,4,WOOD_BUTTON:3)
Block(3,15,-2,LOG:1)
Block(3,15,-1,WOOD:1)
Block(3,15,0,SPRUCE_WOOD_STAIRS:7)
Block(3,15,1,WOOD:1)
Block(3,15,2,WOOD:5)
Block(3,15,3,LOG:1)
Block(3,16,-3,WOOD_BUTTON:4)
Block(3,16,-2,LOG:1)
Block(3,16,-1,WOOD:1)
Block(3,16,0,WOOD:1)
Block(3,16,1,WOOD:5)
Block(3,16,2,WOOD:5)
Block(3,16,3,LOG:1)
Block(3,16,4,WOOD_BUTTON:3)
Block(3,17,-3,WALL_SIGN:2)
Block(3,17,-2,LOG:1)
Block(3,17,-1,WOOD:1)
Block(3,17,0,WOOD:1)
Block(3,17,1,WOOD:5)
Block(3,17,2,WOOD:1)
Block(3,17,3,LOG:1)
Block(3,17,4,WALL_SIGN:3)
Block(3,18,-2,WOOD:1)
Block(3,18,0,WOOD:1)
Block(3,18,1,WOOD:5)
Block(3,18,3,WOOD:1)
RandomBlock(3,19,-2,SPRUCE_WOOD_STAIRS:3,70,DARK_OAK_STAIRS:3,100)
RandomBlock(3,19,0,SPRUCE_WOOD_STAIRS:2,70,DARK_OAK_STAIRS:2,100)
RandomBlock(3,19,1,SPRUCE_WOOD_STAIRS:3,70,DARK_OAK_STAIRS:3,100)
RandomBlock(3,19,3,SPRUCE_WOOD_STAIRS:2,70,DARK_OAK_STAIRS:2,100)
Block(4,5,-2,WALL_SIGN:5)
Block(4,5,-1,WALL_SIGN:5)
Block(4,5,0,WALL_SIGN:5)
Block(4,5,1,WALL_SIGN:5)
Block(4,5,2,WALL_SIGN:5)
Block(4,5,3,WALL_SIGN:5)
Block(4,9,-2,WALL_SIGN:5)
Block(4,9,-1,WALL_SIGN:5)
Block(4,9,0,WALL_SIGN:5)
Block(4,9,1,WALL_SIGN:5)
Block(4,9,2,WALL_SIGN:5)
Block(4,9,3,WALL_SIGN:5)
Block(4,13,-2,WALL_SIGN:5)
Block(4,13,-1,WALL_SIGN:5)
Block(4,13,0,WALL_SIGN:5)
Block(4,13,1,WALL_SIGN:5)
Block(4,13,2,WALL_SIGN:5)
Block(4,13,3,WALL_SIGN:5)
Block(4,17,-2,WALL_SIGN:5)
Block(4,17,-1,WALL_SIGN:5)
Block(4,17,0,WALL_SIGN:5)
Block(4,17,1,WALL_SIGN:5)
Block(4,17,2,WALL_SIGN:5)
Block(4,17,3,WALL_SIGN:5)
Entity(0,18,1,minecraft:stray,1,../../NBT/Entities/VikingVillage/frossen_kriger.txt)
