Author: NLBlackEagle
Description: No description given
SettingsMode: WriteDisable
Frequency: 0
SpawnHeight: highestBlock
UseCenterForHighestBlock: true
MinHeight: 0
MaxHeight: 255
InheritBO3: 
InheritBO3Rotation: NORTH
OverrideChildSettings: true
OverrideParentHeight: false
CanOverride: false
BranchFrequency: 0
BranchFrequencyGroup: 
MustBeBelowOther: false
MustBeInside: 
CannotBeInside: 
ReplacesBO3: 
MustBeInsideWorldBorders: false
CanSpawnOnWater: true
SpawnOnWaterOnly: false
SpawnUnderWater: false
SpawnAtWaterLevel: false
HeightOffset: 0
RemoveAir: false
ReplaceAbove: 
ReplaceBelow: 
ReplaceWithBiomeBlocks: true
ReplaceWithSurfaceBlock: GRASS
ReplaceWithGroundBlock: DIRT
ReplaceWithStoneBlock: STONE
SmoothRadius: 0
SmoothHeightOffset: 0
SmoothStartTop: false
SmoothStartWood: false
SmoothingSurfaceBlock: 
SmoothingGroundBlock: 
BO3Group: 
IsSpawnPoint: false
DoReplaceBlocks: true
Block(-7,0,0,LOG:1)
Block(-7,0,3,LOG:1)
Block(-7,1,0,WOOD:5)
Block(-7,1,1,WOOD:5)
Block(-7,1,2,WOOD:5)
Block(-7,1,3,WOOD:5)
RandomBlock(-7,2,0,DARK_OAK_FENCE:0,30,STONE:6,100)
Block(-7,2,1,AIR:0)
Block(-7,2,2,AIR:0)
RandomBlock(-7,2,3,DARK_OAK_FENCE:0,30,STONE:6,100)
RandomBlock(-7,3,0,DARK_OAK_FENCE:0,30,STONE:6,100)
Block(-7,3,1,AIR:0)
Block(-7,3,2,AIR:0)
RandomBlock(-7,3,3,DARK_OAK_FENCE:0,30,STONE:6,100)
RandomBlock(-7,4,0,DARK_OAK_FENCE:0,30,STONE:6,100)
RandomBlock(-7,4,1,DARK_OAK_FENCE:0,30,STONE:6,100)
RandomBlock(-7,4,2,DARK_OAK_FENCE:0,30,STONE:6,100)
RandomBlock(-7,4,3,DARK_OAK_FENCE:0,30,STONE:6,100)
Block(-6,1,0,WOOD:5)
Block(-6,1,1,WOOD:5)
Block(-6,1,2,WOOD:5)
Block(-6,1,3,WOOD:5)
Block(-6,2,0,STONE:6)
Block(-6,2,1,SPRUCE_DOOR:0)
Block(-6,2,2,SPRUCE_DOOR:0)
Block(-6,2,3,STONE:6)
Block(-6,3,0,STONE:6)
Block(-6,3,1,SPRUCE_DOOR:8)
Block(-6,3,2,SPRUCE_DOOR:9)
Block(-6,3,3,STONE:6)
Block(-6,4,0,WOOD:1)
Block(-6,4,1,WOOD:1)
Block(-6,4,2,WOOD:1)
Block(-6,4,3,WOOD:1)
Block(-5,1,0,WOOD:5)
Block(-5,1,1,WOOD:5)
Block(-5,1,2,WOOD:5)
Block(-5,1,3,WOOD:5)
RandomBlock(-5,2,0,DARK_OAK_FENCE:0,30,STONE:6,100)
Block(-5,2,1,AIR:0)
Block(-5,2,2,AIR:0)
RandomBlock(-5,2,3,DARK_OAK_FENCE:0,30,STONE:6,100)
RandomBlock(-5,3,0,DARK_OAK_FENCE:0,30,STONE:6,100)
Block(-5,3,1,AIR:0)
Block(-5,3,2,AIR:0)
RandomBlock(-5,3,3,DARK_OAK_FENCE:0,30,STONE:6,100)
RandomBlock(-5,4,0,DARK_OAK_FENCE:0,30,STONE:6,100)
Block(-5,4,1,TRAP_DOOR:10)
Block(-5,4,2,TRAP_DOOR:10)
RandomBlock(-5,4,3,DARK_OAK_FENCE:0,30,STONE:6,100)
Block(-4,1,0,WOOD:5)
Block(-4,1,1,WOOD:5)
Block(-4,1,2,WOOD:5)
Block(-4,1,3,WOOD:5)
RandomBlock(-4,2,0,DARK_OAK_FENCE:0,30,STONE:6,100)
Block(-4,2,1,AIR:0)
Block(-4,2,2,AIR:0)
RandomBlock(-4,2,3,DARK_OAK_FENCE:0,30,STONE:6,100)
RandomBlock(-4,3,0,DARK_OAK_FENCE:0,30,STONE:6,100)
Block(-4,3,1,AIR:0)
Block(-4,3,2,AIR:0)
RandomBlock(-4,3,3,DARK_OAK_FENCE:0,30,STONE:6,100)
RandomBlock(-4,4,0,DARK_OAK_FENCE:0,30,STONE:6,100)
Block(-4,4,1,TRAP_DOOR:10)
Block(-4,4,2,TRAP_DOOR:10)
RandomBlock(-4,4,3,DARK_OAK_FENCE:0,30,STONE:6,100)
Block(-3,1,0,WOOD:5)
Block(-3,1,1,WOOD:5)
Block(-3,1,2,WOOD:5)
Block(-3,1,3,WOOD:5)
RandomBlock(-3,2,0,DARK_OAK_FENCE:0,30,STONE:6,100)
Block(-3,2,1,AIR:0)
Block(-3,2,2,AIR:0)
RandomBlock(-3,2,3,DARK_OAK_FENCE:0,30,STONE:6,100)
RandomBlock(-3,3,0,DARK_OAK_FENCE:0,30,STONE:6,100)
Block(-3,3,1,AIR:0)
Block(-3,3,2,AIR:0)
RandomBlock(-3,3,3,DARK_OAK_FENCE:0,30,STONE:6,100)
RandomBlock(-3,4,0,DARK_OAK_FENCE:0,30,STONE:6,100)
Block(-3,4,1,TRAP_DOOR:10)
Block(-3,4,2,TRAP_DOOR:10)
RandomBlock(-3,4,3,DARK_OAK_FENCE:0,30,STONE:6,100)
Block(-2,0,-6,LOG:1)
Block(-2,0,0,LOG:1)
Block(-2,0,3,LOG:1)
Block(-2,0,9,LOG:1)
Block(-2,1,-6,WOOD:5)
Block(-2,1,-5,WOOD:5)
Block(-2,1,-4,WOOD:5)
Block(-2,1,-3,WOOD:5)
Block(-2,1,-2,WOOD:5)
Block(-2,1,-1,WOOD:5)
Block(-2,1,0,WOOD:5)
Block(-2,1,1,WOOD:5)
Block(-2,1,2,WOOD:5)
Block(-2,1,3,WOOD:5)
Block(-2,1,4,WOOD:5)
Block(-2,1,5,WOOD:5)
Block(-2,1,6,WOOD:5)
Block(-2,1,7,WOOD:5)
Block(-2,1,8,WOOD:5)
Block(-2,1,9,WOOD:5)
Block(-2,2,-6,SPRUCE_FENCE:0)
Block(-2,2,-5,SMOOTH_BRICK:0)
RandomBlock(-2,2,-4,DARK_OAK_FENCE:0,30,STONE:6,100)
Block(-2,2,-3,SMOOTH_BRICK:0)
Block(-2,2,-2,SPRUCE_FENCE:0)
Block(-2,2,-1,SMOOTH_BRICK:0)
Block(-2,2,0,SPRUCE_FENCE:0)
Block(-2,2,1,AIR:0)
Block(-2,2,2,AIR:0)
Block(-2,2,3,SPRUCE_FENCE:0)
Block(-2,2,4,SMOOTH_BRICK:0)
Block(-2,2,5,SPRUCE_FENCE:0)
Block(-2,2,6,SMOOTH_BRICK:0)
RandomBlock(-2,2,7,DARK_OAK_FENCE:0,30,STONE:6,100)
Block(-2,2,8,SMOOTH_BRICK:0)
Block(-2,2,9,SPRUCE_FENCE:0)
Block(-2,3,-6,SPRUCE_FENCE:0)
Block(-2,3,-5,SMOOTH_BRICK:0)
RandomBlock(-2,3,-4,DARK_OAK_FENCE:0,30,STONE:6,100)
Block(-2,3,-3,SMOOTH_BRICK:0)
Block(-2,3,-2,SPRUCE_FENCE:0)
Block(-2,3,-1,SMOOTH_BRICK:0)
Block(-2,3,0,SPRUCE_FENCE:0)
Block(-2,3,1,AIR:0)
Block(-2,3,2,AIR:0)
Block(-2,3,3,SPRUCE_FENCE:0)
Block(-2,3,4,SMOOTH_BRICK:0)
Block(-2,3,5,SPRUCE_FENCE:0)
Block(-2,3,6,SMOOTH_BRICK:0)
RandomBlock(-2,3,7,DARK_OAK_FENCE:0,30,STONE:6,100)
Block(-2,3,8,SMOOTH_BRICK:0)
Block(-2,3,9,SPRUCE_FENCE:0)
Block(-2,4,-6,WOOD:1)
Block(-2,4,-5,SMOOTH_BRICK:0)
Block(-2,4,-4,TRAP_DOOR:9)
Block(-2,4,-3,SMOOTH_BRICK:0)
Block(-2,4,-2,WOOD:1)
Block(-2,4,-1,SMOOTH_BRICK:0)
Block(-2,4,0,WOOD:1)
Block(-2,4,1,WOOD:1)
Block(-2,4,2,WOOD:1)
Block(-2,4,3,WOOD:1)
Block(-2,4,4,SMOOTH_BRICK:0)
Block(-2,4,5,WOOD:1)
Block(-2,4,6,SMOOTH_BRICK:0)
RandomBlock(-2,4,7,DARK_OAK_FENCE:0,30,STONE:6,100)
Block(-2,4,8,SMOOTH_BRICK:0)
Block(-2,4,9,WOOD:1)
Block(-2,5,-1,SPRUCE_FENCE:0)
Block(-2,5,0,SPRUCE_FENCE:0)
Block(-2,5,1,SPRUCE_FENCE:0)
Block(-2,5,2,SPRUCE_FENCE:0)
Block(-2,5,3,SPRUCE_FENCE:0)
Block(-2,5,4,SPRUCE_FENCE:0)
Block(-2,6,-1,TRAP_DOOR:0)
Block(-2,6,0,TRAP_DOOR:0)
Block(-2,6,1,SPRUCE_FENCE:0)
Block(-2,6,2,SPRUCE_FENCE:0)
Block(-2,6,3,TRAP_DOOR:1)
Block(-2,6,4,TRAP_DOOR:1)
Block(-1,1,-6,WOOD:5)
Block(-1,1,-5,WOOD:5)
Block(-1,1,-4,WOOD:5)
Block(-1,1,-3,WOOD:5)
Block(-1,1,-2,WOOD:5)
Block(-1,1,-1,WOOD:5)
Block(-1,1,0,WOOD:5)
Block(-1,1,1,WOOD:5)
Block(-1,1,2,WOOD:5)
Block(-1,1,3,WOOD:5)
Block(-1,1,4,WOOD:5)
Block(-1,1,5,WOOD:5)
Block(-1,1,6,WOOD:5)
Block(-1,1,7,WOOD:5)
Block(-1,1,8,WOOD:5)
Block(-1,1,9,WOOD:5)
RandomBlock(-1,2,-6,DARK_OAK_FENCE:0,30,STONE:6,100)
Block(-1,2,-5,DARK_OAK_STAIRS:5)
Block(-1,2,-4,AIR:0)
Block(-1,2,-3,DARK_OAK_STAIRS:5)
Block(-1,2,-2,AIR:0)
Block(-1,2,-1,SPRUCE_FENCE:0)
Block(-1,2,0,AIR:0)
Block(-1,2,1,AIR:0)
Block(-1,2,2,AIR:0)
Block(-1,2,3,AIR:0)
Block(-1,2,4,SPRUCE_FENCE:0)
Block(-1,2,5,SMOOTH_BRICK:0)
Block(-1,2,6,AIR:0)
Block(-1,2,7,AIR:0)
Block(-1,2,8,TRAP_DOOR:8)
RandomBlock(-1,2,9,DARK_OAK_FENCE:0,30,STONE:6,100)
RandomBlock(-1,3,-6,DARK_OAK_FENCE:0,30,STONE:6,100)
RandomBlock(-1,3,-5,AIR:0,20,CHEST:5,../../../../Chests/Loot/JunkChest_1.nbt,10,CHEST:5,../../../../Chests/Loot/JunkChest_2.nbt,10,CHEST:5,../../../../Chests/Loot/JunkChest_3.nbt,10,CHEST:5,../../../../Chests/Loot/JunkChest_4.nbt,10,CHEST:5,../../../../Chests/Loot/JunkChest_5.nbt,10,CHEST:5,../../../../Chests/Lore/HiddenMineWaste_1.nbt,1,CHEST:5,../../../../Chests/Lore/HiddenMineWaste_2.nbt,1,CHEST:5,../../../../Chests/Lore/HiddenMineWaste_3.nbt,1,CHEST:5,../../../../Chests/Lore/HiddenMineWaste_4.nbt,1,CHEST:5,../../../../Chests/Lore/HiddenMineWaste_5.nbt,1,CHEST:5,../../../../Chests/Loot/Common1.nbt,10,CHEST:5,../../../../Chests/Loot/Common2.nbt,10,CHEST:5,../../../../Chests/Loot/Common3.nbt,10,CHEST:5,../../../../Chests/Loot/Common4.nbt,10,CHEST:5,../../../../Chests/Loot/Common5.nbt,10,CHEST:5,../../../../Chests/Loot/Common6.nbt,10,CHEST:5,../../../../Chests/Loot/Common7.nbt,10,CHEST:5,../../../../Chests/Loot/Common8.nbt,10,CHEST:5,../../../../Chests/Loot/Common9.nbt,10,CHEST:5,../../../../Chests/Loot/Common10.nbt,10,CHEST:5,../../../../Chests/Loot/Common10.nbt,11,CHEST:5,../../../../Chests/Loot/Common12.nbt,10,CHEST:5,../../../../Chests/Loot/Common13.nbt,10,CHEST:5,../../../../Chests/Loot/Common14.nbt,10,CHEST:5,../../../../Chests/Loot/Common15.nbt,10,CHEST:5,../../../../Chests/Lore/HiddenMineWaste_1.nbt,2,CHEST:5,../../../../Chests/Lore/HiddenMineWaste_3.nbt,2,CHEST:5,../../../../Chests/Lore/HiddenMineWaste_4.nbt,2,CHEST:5,../../../../Chests/Lore/HiddenMineWaste_5.nbt,2,CHEST:5,../../../../Chests/Lore/HiddenMineWaste_5.nbt,2,CHEST:5,../../../../Chests/Loot/Rare1.nbt,5,CHEST:5,../../../../Chests/Loot/Rare2.nbt,5,CHEST:5,../../../../Chests/Loot/Rare3.nbt,5,CHEST:5,../../../../Chests/Loot/Rare4.nbt,5,CHEST:5,../../../../Chests/Loot/Rare5.nbt,5,CHEST:5,../../../../Chests/Loot/Rare6.nbt,5,CHEST:5,../../../../Chests/Loot/Rare7.nbt,5,CHEST:5,../../../../Chests/Loot/Rare8.nbt,5,CHEST:5,../../../../Chests/Loot/Rare9.nbt,5,CHEST:5,../../../../Chests/Loot/Rare10.nbt,5,CHEST:5,../../../../Chests/Loot/Rare11.nbt,5,CHEST:5,../../../../Chests/Loot/Rare12.nbt,5,CHEST:5,../../../../Chests/Loot/Rare13.nbt,5,CHEST:5,../../../../Chests/Loot/Rare14.nbt,5,CHEST:5,../../../../Chests/Loot/Rare15.nbt,5,CHEST:5,../../../../Chests/Loot/Epic1.nbt,2,CHEST:5,../../../../Chests/Loot/Epic2.nbt,2,CHEST:5,../../../../Chests/Loot/Epic3.nbt,2,CHEST:5,../../../../Chests/Loot/Epic4.nbt,2,CHEST:5,../../../../Chests/Loot/Epic5.nbt,2,CHEST:5,../../../../Chests/Loot/Epic6.nbt,2,CHEST:5,../../../../Chests/Loot/Epic7.nbt,2,CHEST:5,../../../../Chests/Loot/Epic8.nbt,2,CHEST:5,../../../../Chests/Loot/Epic9.nbt,2,CHEST:5,../../../../Chests/Loot/Epic10.nbt,2,CHEST:5,../../../../Chests/Loot/Epic11.nbt,2,CHEST:5,../../../../Chests/Loot/Epic12.nbt,2,CHEST:5,../../../../Chests/Loot/Epic13.nbt,2,CHEST:5,../../../../Chests/Loot/Epic14.nbt,2,CHEST:5,../../../../Chests/Loot/Epic15.nbt,5,CHEST:5,../../../../Chests/Loot/Rare1.nbt,5,CHEST:5,../../../../Chests/Loot/Rare2.nbt,5,CHEST:5,../../../../Chests/Loot/Rare3.nbt,5,CHEST:5,../../../../Chests/Loot/Rare4.nbt,5,CHEST:5,../../../../Chests/Loot/Rare5.nbt,10,CHEST:5,../../../../Chests/Loot/Rare6.nbt,10,CHEST:5,../../../../Chests/Loot/Rare7.nbt,10,CHEST:5,../../../../Chests/Loot/Rare8.nbt,10,CHEST:5,../../../../Chests/Loot/Rare9.nbt,10,CHEST:5,../../../../Chests/Loot/Rare10.nbt,15,CHEST:5,../../../../Chests/Loot/Rare11.nbt,15,CHEST:5,../../../../Chests/Loot/Rare12.nbt,15,CHEST:5,../../../../Chests/Loot/Rare13.nbt,15,CHEST:5,../../../../Chests/Loot/Rare14.nbt,15,CHEST:5,../../../../Chests/Loot/Rare15.nbt,15,CHEST:5,../../../../Chests/Loot/Epic15.nbt,100)
Block(-1,3,-4,AIR:0)
RandomBlock(-1,3,-3,AIR:0,20,CHEST:5,../../../../Chests/Loot/JunkChest_1.nbt,10,CHEST:5,../../../../Chests/Loot/JunkChest_2.nbt,10,CHEST:5,../../../../Chests/Loot/JunkChest_3.nbt,10,CHEST:5,../../../../Chests/Loot/JunkChest_4.nbt,10,CHEST:5,../../../../Chests/Loot/JunkChest_5.nbt,10,CHEST:5,../../../../Chests/Lore/HiddenMineWaste_1.nbt,1,CHEST:5,../../../../Chests/Lore/HiddenMineWaste_2.nbt,1,CHEST:5,../../../../Chests/Lore/HiddenMineWaste_3.nbt,1,CHEST:5,../../../../Chests/Lore/HiddenMineWaste_4.nbt,1,CHEST:5,../../../../Chests/Lore/HiddenMineWaste_5.nbt,1,CHEST:5,../../../../Chests/Loot/Common1.nbt,10,CHEST:5,../../../../Chests/Loot/Common2.nbt,10,CHEST:5,../../../../Chests/Loot/Common3.nbt,10,CHEST:5,../../../../Chests/Loot/Common4.nbt,10,CHEST:5,../../../../Chests/Loot/Common5.nbt,10,CHEST:5,../../../../Chests/Loot/Common6.nbt,10,CHEST:5,../../../../Chests/Loot/Common7.nbt,10,CHEST:5,../../../../Chests/Loot/Common8.nbt,10,CHEST:5,../../../../Chests/Loot/Common9.nbt,10,CHEST:5,../../../../Chests/Loot/Common10.nbt,10,CHEST:5,../../../../Chests/Loot/Common10.nbt,11,CHEST:5,../../../../Chests/Loot/Common12.nbt,10,CHEST:5,../../../../Chests/Loot/Common13.nbt,10,CHEST:5,../../../../Chests/Loot/Common14.nbt,10,CHEST:5,../../../../Chests/Loot/Common15.nbt,10,CHEST:5,../../../../Chests/Lore/HiddenMineWaste_1.nbt,2,CHEST:5,../../../../Chests/Lore/HiddenMineWaste_3.nbt,2,CHEST:5,../../../../Chests/Lore/HiddenMineWaste_4.nbt,2,CHEST:5,../../../../Chests/Lore/HiddenMineWaste_5.nbt,2,CHEST:5,../../../../Chests/Lore/HiddenMineWaste_5.nbt,2,CHEST:5,../../../../Chests/Loot/Rare1.nbt,5,CHEST:5,../../../../Chests/Loot/Rare2.nbt,5,CHEST:5,../../../../Chests/Loot/Rare3.nbt,5,CHEST:5,../../../../Chests/Loot/Rare4.nbt,5,CHEST:5,../../../../Chests/Loot/Rare5.nbt,5,CHEST:5,../../../../Chests/Loot/Rare6.nbt,5,CHEST:5,../../../../Chests/Loot/Rare7.nbt,5,CHEST:5,../../../../Chests/Loot/Rare8.nbt,5,CHEST:5,../../../../Chests/Loot/Rare9.nbt,5,CHEST:5,../../../../Chests/Loot/Rare10.nbt,5,CHEST:5,../../../../Chests/Loot/Rare11.nbt,5,CHEST:5,../../../../Chests/Loot/Rare12.nbt,5,CHEST:5,../../../../Chests/Loot/Rare13.nbt,5,CHEST:5,../../../../Chests/Loot/Rare14.nbt,5,CHEST:5,../../../../Chests/Loot/Rare15.nbt,5,CHEST:5,../../../../Chests/Loot/Epic1.nbt,2,CHEST:5,../../../../Chests/Loot/Epic2.nbt,2,CHEST:5,../../../../Chests/Loot/Epic3.nbt,2,CHEST:5,../../../../Chests/Loot/Epic4.nbt,2,CHEST:5,../../../../Chests/Loot/Epic5.nbt,2,CHEST:5,../../../../Chests/Loot/Epic6.nbt,2,CHEST:5,../../../../Chests/Loot/Epic7.nbt,2,CHEST:5,../../../../Chests/Loot/Epic8.nbt,2,CHEST:5,../../../../Chests/Loot/Epic9.nbt,2,CHEST:5,../../../../Chests/Loot/Epic10.nbt,2,CHEST:5,../../../../Chests/Loot/Epic11.nbt,2,CHEST:5,../../../../Chests/Loot/Epic12.nbt,2,CHEST:5,../../../../Chests/Loot/Epic13.nbt,2,CHEST:5,../../../../Chests/Loot/Epic14.nbt,2,CHEST:5,../../../../Chests/Loot/Epic15.nbt,5,CHEST:5,../../../../Chests/Loot/Rare1.nbt,5,CHEST:5,../../../../Chests/Loot/Rare2.nbt,5,CHEST:5,../../../../Chests/Loot/Rare3.nbt,5,CHEST:5,../../../../Chests/Loot/Rare4.nbt,5,CHEST:5,../../../../Chests/Loot/Rare5.nbt,10,CHEST:5,../../../../Chests/Loot/Rare6.nbt,10,CHEST:5,../../../../Chests/Loot/Rare7.nbt,10,CHEST:5,../../../../Chests/Loot/Rare8.nbt,10,CHEST:5,../../../../Chests/Loot/Rare9.nbt,10,CHEST:5,../../../../Chests/Loot/Rare10.nbt,15,CHEST:5,../../../../Chests/Loot/Rare11.nbt,15,CHEST:5,../../../../Chests/Loot/Rare12.nbt,15,CHEST:5,../../../../Chests/Loot/Rare13.nbt,15,CHEST:5,../../../../Chests/Loot/Rare14.nbt,15,CHEST:5,../../../../Chests/Loot/Rare15.nbt,15,CHEST:5,../../../../Chests/Loot/Epic15.nbt,100)
Block(-1,3,-2,AIR:0)
Block(-1,3,-1,TORCH:5)
Block(-1,3,0,AIR:0)
Block(-1,3,1,AIR:0)
Block(-1,3,2,AIR:0)
Block(-1,3,3,AIR:0)
Block(-1,3,4,TORCH:5)
Block(-1,3,5,SMOOTH_BRICK:0)
Block(-1,3,6,AIR:0)
Block(-1,3,7,AIR:0)
Block(-1,3,8,IRON_FENCE:0)
RandomBlock(-1,3,9,DARK_OAK_FENCE:0,30,STONE:6,100)
Block(-1,4,-6,WOOD:1)
Block(-1,4,-5,SPRUCE_FENCE:0)
Block(-1,4,-4,TRAP_DOOR:9)
Block(-1,4,-3,SPRUCE_FENCE:0)
Block(-1,4,-2,WOOD:1)
Block(-1,4,-1,SMOOTH_BRICK:0)
Block(-1,4,0,AIR:0)
Block(-1,4,1,AIR:0)
Block(-1,4,2,AIR:0)
Block(-1,4,3,AIR:0)
Block(-1,4,4,SMOOTH_BRICK:0)
Block(-1,4,5,WOOD:1)
Block(-1,4,6,TRAP_DOOR:8)
Block(-1,4,7,TRAP_DOOR:8)
Block(-1,4,8,SPRUCE_FENCE:0)
Block(-1,4,9,WOOD:1)
Block(-1,5,-1,SPRUCE_FENCE:0)
RandomBlock(-1,5,0,WALL_BANNER:3,../../NBT/Banners/banner_sun.nbt,50,WALL_BANNER:3,../../NBT/Banners/quarry_banner_0.nbt,10,WALL_BANNER:3,../../NBT/Banners/quarry_banner_1.nbt,10,WALL_BANNER:3,../../NBT/Banners/quarry_banner_2.nbt,10,WALL_BANNER:3,../../NBT/Banners/quarry_banner_3.nbt,10,WALL_BANNER:3,../../NBT/Banners/quarry_banner_4.nbt,100)
Block(-1,5,1,AIR:0)
Block(-1,5,2,AIR:0)
RandomBlock(-1,5,3,WALL_BANNER:2,../../NBT/Banners/banner_sun.nbt,50,WALL_BANNER:2,../../NBT/Banners/quarry_banner_0.nbt,10,WALL_BANNER:2,../../NBT/Banners/quarry_banner_1.nbt,10,WALL_BANNER:2,../../NBT/Banners/quarry_banner_2.nbt,10,WALL_BANNER:2,../../NBT/Banners/quarry_banner_3.nbt,10,WALL_BANNER:2,../../NBT/Banners/quarry_banner_4.nbt,100)
Block(-1,5,4,SPRUCE_FENCE:0)
Block(-1,6,-1,TRAP_DOOR:0)
Block(-1,6,0,TRAP_DOOR:0)
Block(-1,6,1,SPRUCE_FENCE:0)
Block(-1,6,2,SPRUCE_FENCE:0)
Block(-1,6,3,TRAP_DOOR:3)
Block(-1,6,4,TRAP_DOOR:1)
Block(0,1,-6,WOOD:5)
Block(0,1,-5,WOOD:5)
Block(0,1,-4,WOOD:5)
Block(0,1,-3,WOOD:5)
Block(0,1,-2,WOOD:5)
Block(0,1,-1,WOOD:5)
Block(0,1,0,WOOD:5)
Block(0,1,1,WOOD:5)
Block(0,1,2,WOOD:5)
Block(0,1,3,WOOD:5)
Block(0,1,4,WOOD:5)
Block(0,1,5,WOOD:5)
Block(0,1,6,WOOD:5)
Block(0,1,7,WOOD:5)
Block(0,1,8,WOOD:5)
Block(0,1,9,WOOD:5)
RandomBlock(0,2,-6,DARK_OAK_FENCE:0,30,STONE:6,100)
Block(0,2,-5,AIR:0)
Block(0,2,-4,AIR:0)
Block(0,2,-3,AIR:0)
Block(0,2,-2,AIR:0)
Block(0,2,-1,AIR:0)
Block(0,2,0,AIR:0)
Block(0,2,1,AIR:0)
Block(0,2,2,AIR:0)
Block(0,2,3,AIR:0)
Block(0,2,4,AIR:0)
Block(0,2,5,IRON_DOOR_BLOCK:3)
Block(0,2,6,AIR:0)
Block(0,2,7,AIR:0)
Block(0,2,8,TRAP_DOOR:8)
RandomBlock(0,2,9,DARK_OAK_FENCE:0,30,STONE:6,100)
RandomBlock(0,3,-6,DARK_OAK_FENCE:0,30,STONE:6,100)
Block(0,3,-5,AIR:0)
Block(0,3,-4,AIR:0)
Block(0,3,-3,AIR:0)
Block(0,3,-2,AIR:0)
Block(0,3,-1,AIR:0)
Block(0,3,0,AIR:0)
Block(0,3,1,AIR:0)
Block(0,3,2,AIR:0)
Block(0,3,3,AIR:0)
Block(0,3,4,AIR:0)
Block(0,3,5,IRON_DOOR_BLOCK:9)
Block(0,3,6,AIR:0)
Block(0,3,7,AIR:0)
Block(0,3,8,AIR:0)
RandomBlock(0,3,9,DARK_OAK_FENCE:0,30,STONE:6,100)
Block(0,4,-6,WOOD:1)
Block(0,4,-5,SPRUCE_FENCE:0)
Block(0,4,-4,TRAP_DOOR:9)
Block(0,4,-3,TRAP_DOOR:9)
Block(0,4,-2,WOOD:1)
Block(0,4,-1,SMOOTH_BRICK:0)
Block(0,4,0,AIR:0)
Block(0,4,1,AIR:0)
Block(0,4,2,AIR:0)
Block(0,4,3,AIR:0)
Block(0,4,4,SMOOTH_BRICK:0)
Block(0,4,5,WOOD:1)
Block(0,4,6,TRAP_DOOR:8)
Block(0,4,7,TRAP_DOOR:8)
Block(0,4,8,TRAP_DOOR:8)
Block(0,4,9,WOOD:1)
Block(0,5,-1,SPRUCE_FENCE:0)
Block(0,5,0,AIR:0)
Block(0,5,1,AIR:0)
Block(0,5,2,AIR:0)
Block(0,5,3,AIR:0)
Block(0,5,4,SPRUCE_FENCE:0)
Block(0,6,-1,SPRUCE_FENCE:0)
Block(0,6,0,SPRUCE_FENCE:0)
Block(0,6,1,SPRUCE_FENCE:0)
Block(0,6,2,SPRUCE_FENCE:0)
Block(0,6,3,SPRUCE_FENCE:0)
Block(0,6,4,SPRUCE_FENCE:0)
Block(1,1,-6,WOOD:5)
Block(1,1,-5,WOOD:5)
Block(1,1,-4,WOOD:5)
Block(1,1,-3,WOOD:5)
Block(1,1,-2,WOOD:5)
Block(1,1,-1,WOOD:5)
Block(1,1,0,WOOD:5)
Block(1,1,1,WOOD:5)
Block(1,1,2,WOOD:5)
Block(1,1,3,WOOD:5)
Block(1,1,4,WOOD:5)
Block(1,1,5,WOOD:5)
Block(1,1,6,WOOD:5)
Block(1,1,7,WOOD:5)
Block(1,1,8,WOOD:5)
Block(1,1,9,WOOD:5)
RandomBlock(1,2,-6,DARK_OAK_FENCE:0,30,STONE:6,100)
Block(1,2,-5,AIR:0)
Block(1,2,-4,AIR:0)
Block(1,2,-3,AIR:0)
Block(1,2,-2,AIR:0)
Block(1,2,-1,AIR:0)
Block(1,2,0,AIR:0)
Block(1,2,1,AIR:0)
Entity(1,2,2,IRON_GOLEM,1)
Block(1,2,2,AIR:0)
Block(1,2,3,AIR:0)
Block(1,2,4,AIR:0)
Block(1,2,5,SMOOTH_BRICK:0)
Block(1,2,6,AIR:0)
Block(1,2,7,AIR:0)
Block(1,2,8,TRAP_DOOR:8)
RandomBlock(1,2,9,DARK_OAK_FENCE:0,30,STONE:6,100)
RandomBlock(1,3,-6,DARK_OAK_FENCE:0,30,STONE:6,100)
Block(1,3,-5,AIR:0)
Block(1,3,-4,AIR:0)
Block(1,3,-3,AIR:0)
Block(1,3,-2,AIR:0)
Block(1,3,-1,AIR:0)
Block(1,3,0,AIR:0)
Block(1,3,1,AIR:0)
Block(1,3,2,AIR:0)
Block(1,3,3,AIR:0)
Block(1,3,4,LEVER:4)
Block(1,3,5,SMOOTH_BRICK:0)
Block(1,3,6,AIR:0)
Block(1,3,7,AIR:0)
Block(1,3,8,AIR:0)
RandomBlock(1,3,9,DARK_OAK_FENCE:0,30,STONE:6,100)
Block(1,4,-6,WOOD:1)
Block(1,4,-5,TRAP_DOOR:9)
Block(1,4,-4,TRAP_DOOR:9)
Block(1,4,-3,SPRUCE_FENCE:0)
Block(1,4,-2,WOOD:1)
Block(1,4,-1,SMOOTH_BRICK:0)
Block(1,4,0,AIR:0)
Block(1,4,1,AIR:0)
Block(1,4,2,AIR:0)
Block(1,4,3,AIR:0)
Block(1,4,4,SMOOTH_BRICK:0)
Block(1,4,5,WOOD:1)
Block(1,4,6,SPRUCE_FENCE:0)
Block(1,4,7,TRAP_DOOR:8)
Block(1,4,8,SPRUCE_FENCE:0)
Block(1,4,9,WOOD:1)
Block(1,5,-1,SPRUCE_FENCE:0)
Block(1,5,0,AIR:0)
Block(1,5,1,AIR:0)
Block(1,5,2,AIR:0)
Block(1,5,3,AIR:0)
Block(1,5,4,SPRUCE_FENCE:0)
Block(1,6,-1,SPRUCE_FENCE:0)
Block(1,6,0,SPRUCE_FENCE:0)
Block(1,6,1,SPRUCE_FENCE:0)
Block(1,6,2,SPRUCE_FENCE:0)
Block(1,6,3,SPRUCE_FENCE:0)
Block(1,6,4,SPRUCE_FENCE:0)
Block(2,1,-6,WOOD:5)
Block(2,1,-5,WOOD:5)
Block(2,1,-4,WOOD:5)
Block(2,1,-3,WOOD:5)
Block(2,1,-2,WOOD:5)
Block(2,1,-1,WOOD:5)
Block(2,1,0,WOOD:5)
Block(2,1,1,WOOD:5)
Block(2,1,2,WOOD:5)
Block(2,1,3,WOOD:5)
Block(2,1,4,WOOD:5)
Block(2,1,5,WOOD:5)
Block(2,1,6,WOOD:5)
Block(2,1,7,WOOD:5)
Block(2,1,8,WOOD:5)
Block(2,1,9,WOOD:5)
RandomBlock(2,2,-6,DARK_OAK_FENCE:0,30,STONE:6,100)
Block(2,2,-5,DARK_OAK_STAIRS:4)
Block(2,2,-4,AIR:0)
Block(2,2,-3,DARK_OAK_STAIRS:4)
Block(2,2,-2,AIR:0)
Block(2,2,-1,SPRUCE_FENCE:0)
Block(2,2,0,AIR:0)
Block(2,2,1,AIR:0)
Block(2,2,2,AIR:0)
Block(2,2,3,AIR:0)
Block(2,2,4,SPRUCE_FENCE:0)
RandomBlock(2,2,5,DARK_OAK_FENCE:0,30,STONE:6,100)
Block(2,2,6,AIR:0)
Entity(2,2,7,ZOMBIE_VILLAGER,1)
Block(2,2,7,AIR:0)
Block(2,2,8,TRAP_DOOR:10)
RandomBlock(2,2,9,DARK_OAK_FENCE:0,30,STONE:6,100)
RandomBlock(2,3,-6,DARK_OAK_FENCE:0,30,STONE:6,100)
RandomBlock(2,3,-5,AIR:0,20,CHEST:4,../../../../Chests/Loot/JunkChest_1.nbt,10,CHEST:4,../../../../Chests/Loot/JunkChest_2.nbt,10,CHEST:4,../../../../Chests/Loot/JunkChest_3.nbt,10,CHEST:4,../../../../Chests/Loot/JunkChest_4.nbt,10,CHEST:4,../../../../Chests/Loot/JunkChest_5.nbt,10,CHEST:4,../../../../Chests/Lore/HiddenMineWaste_1.nbt,1,CHEST:4,../../../../Chests/Lore/HiddenMineWaste_2.nbt,1,CHEST:4,../../../../Chests/Lore/HiddenMineWaste_3.nbt,1,CHEST:4,../../../../Chests/Lore/HiddenMineWaste_4.nbt,1,CHEST:4,../../../../Chests/Lore/HiddenMineWaste_5.nbt,1,CHEST:4,../../../../Chests/Loot/Common1.nbt,10,CHEST:4,../../../../Chests/Loot/Common2.nbt,10,CHEST:4,../../../../Chests/Loot/Common3.nbt,10,CHEST:4,../../../../Chests/Loot/Common4.nbt,10,CHEST:4,../../../../Chests/Loot/Common5.nbt,10,CHEST:4,../../../../Chests/Loot/Common6.nbt,10,CHEST:4,../../../../Chests/Loot/Common7.nbt,10,CHEST:4,../../../../Chests/Loot/Common8.nbt,10,CHEST:4,../../../../Chests/Loot/Common9.nbt,10,CHEST:4,../../../../Chests/Loot/Common10.nbt,10,CHEST:4,../../../../Chests/Loot/Common10.nbt,11,CHEST:4,../../../../Chests/Loot/Common12.nbt,10,CHEST:4,../../../../Chests/Loot/Common13.nbt,10,CHEST:4,../../../../Chests/Loot/Common14.nbt,10,CHEST:4,../../../../Chests/Loot/Common15.nbt,10,CHEST:4,../../../../Chests/Lore/HiddenMineWaste_1.nbt,2,CHEST:4,../../../../Chests/Lore/HiddenMineWaste_3.nbt,2,CHEST:4,../../../../Chests/Lore/HiddenMineWaste_4.nbt,2,CHEST:4,../../../../Chests/Lore/HiddenMineWaste_5.nbt,2,CHEST:4,../../../../Chests/Lore/HiddenMineWaste_5.nbt,2,CHEST:4,../../../../Chests/Loot/Rare1.nbt,5,CHEST:4,../../../../Chests/Loot/Rare2.nbt,5,CHEST:4,../../../../Chests/Loot/Rare3.nbt,5,CHEST:4,../../../../Chests/Loot/Rare4.nbt,5,CHEST:4,../../../../Chests/Loot/Rare5.nbt,5,CHEST:4,../../../../Chests/Loot/Rare6.nbt,5,CHEST:4,../../../../Chests/Loot/Rare7.nbt,5,CHEST:4,../../../../Chests/Loot/Rare8.nbt,5,CHEST:4,../../../../Chests/Loot/Rare9.nbt,5,CHEST:4,../../../../Chests/Loot/Rare10.nbt,5,CHEST:4,../../../../Chests/Loot/Rare11.nbt,5,CHEST:4,../../../../Chests/Loot/Rare12.nbt,5,CHEST:4,../../../../Chests/Loot/Rare13.nbt,5,CHEST:4,../../../../Chests/Loot/Rare14.nbt,5,CHEST:4,../../../../Chests/Loot/Rare15.nbt,5,CHEST:4,../../../../Chests/Loot/Epic1.nbt,2,CHEST:4,../../../../Chests/Loot/Epic2.nbt,2,CHEST:4,../../../../Chests/Loot/Epic3.nbt,2,CHEST:4,../../../../Chests/Loot/Epic4.nbt,2,CHEST:4,../../../../Chests/Loot/Epic5.nbt,2,CHEST:4,../../../../Chests/Loot/Epic6.nbt,2,CHEST:4,../../../../Chests/Loot/Epic7.nbt,2,CHEST:4,../../../../Chests/Loot/Epic8.nbt,2,CHEST:4,../../../../Chests/Loot/Epic9.nbt,2,CHEST:4,../../../../Chests/Loot/Epic10.nbt,2,CHEST:4,../../../../Chests/Loot/Epic11.nbt,2,CHEST:4,../../../../Chests/Loot/Epic12.nbt,2,CHEST:4,../../../../Chests/Loot/Epic13.nbt,2,CHEST:4,../../../../Chests/Loot/Epic14.nbt,2,CHEST:4,../../../../Chests/Loot/Epic15.nbt,5,CHEST:4,../../../../Chests/Loot/Rare1.nbt,5,CHEST:4,../../../../Chests/Loot/Rare2.nbt,5,CHEST:4,../../../../Chests/Loot/Rare3.nbt,5,CHEST:4,../../../../Chests/Loot/Rare4.nbt,5,CHEST:4,../../../../Chests/Loot/Rare5.nbt,10,CHEST:4,../../../../Chests/Loot/Rare6.nbt,10,CHEST:4,../../../../Chests/Loot/Rare7.nbt,10,CHEST:4,../../../../Chests/Loot/Rare8.nbt,10,CHEST:4,../../../../Chests/Loot/Rare9.nbt,10,CHEST:4,../../../../Chests/Loot/Rare10.nbt,15,CHEST:4,../../../../Chests/Loot/Rare11.nbt,15,CHEST:4,../../../../Chests/Loot/Rare12.nbt,15,CHEST:4,../../../../Chests/Loot/Rare13.nbt,15,CHEST:4,../../../../Chests/Loot/Rare14.nbt,15,CHEST:4,../../../../Chests/Loot/Rare15.nbt,15,CHEST:4,../../../../Chests/Loot/Epic15.nbt,100)
Block(2,3,-4,AIR:0)
RandomBlock(2,3,-3,AIR:0,20,CHEST:4,../../../../Chests/Loot/JunkChest_1.nbt,10,CHEST:4,../../../../Chests/Loot/JunkChest_2.nbt,10,CHEST:4,../../../../Chests/Loot/JunkChest_3.nbt,10,CHEST:4,../../../../Chests/Loot/JunkChest_4.nbt,10,CHEST:4,../../../../Chests/Loot/JunkChest_5.nbt,10,CHEST:4,../../../../Chests/Lore/HiddenMineWaste_1.nbt,1,CHEST:4,../../../../Chests/Lore/HiddenMineWaste_2.nbt,1,CHEST:4,../../../../Chests/Lore/HiddenMineWaste_3.nbt,1,CHEST:4,../../../../Chests/Lore/HiddenMineWaste_4.nbt,1,CHEST:4,../../../../Chests/Lore/HiddenMineWaste_5.nbt,1,CHEST:4,../../../../Chests/Loot/Common1.nbt,10,CHEST:4,../../../../Chests/Loot/Common2.nbt,10,CHEST:4,../../../../Chests/Loot/Common3.nbt,10,CHEST:4,../../../../Chests/Loot/Common4.nbt,10,CHEST:4,../../../../Chests/Loot/Common5.nbt,10,CHEST:4,../../../../Chests/Loot/Common6.nbt,10,CHEST:4,../../../../Chests/Loot/Common7.nbt,10,CHEST:4,../../../../Chests/Loot/Common8.nbt,10,CHEST:4,../../../../Chests/Loot/Common9.nbt,10,CHEST:4,../../../../Chests/Loot/Common10.nbt,10,CHEST:4,../../../../Chests/Loot/Common10.nbt,11,CHEST:4,../../../../Chests/Loot/Common12.nbt,10,CHEST:4,../../../../Chests/Loot/Common13.nbt,10,CHEST:4,../../../../Chests/Loot/Common14.nbt,10,CHEST:4,../../../../Chests/Loot/Common15.nbt,10,CHEST:4,../../../../Chests/Lore/HiddenMineWaste_1.nbt,2,CHEST:4,../../../../Chests/Lore/HiddenMineWaste_3.nbt,2,CHEST:4,../../../../Chests/Lore/HiddenMineWaste_4.nbt,2,CHEST:4,../../../../Chests/Lore/HiddenMineWaste_5.nbt,2,CHEST:4,../../../../Chests/Lore/HiddenMineWaste_5.nbt,2,CHEST:4,../../../../Chests/Loot/Rare1.nbt,5,CHEST:4,../../../../Chests/Loot/Rare2.nbt,5,CHEST:4,../../../../Chests/Loot/Rare3.nbt,5,CHEST:4,../../../../Chests/Loot/Rare4.nbt,5,CHEST:4,../../../../Chests/Loot/Rare5.nbt,5,CHEST:4,../../../../Chests/Loot/Rare6.nbt,5,CHEST:4,../../../../Chests/Loot/Rare7.nbt,5,CHEST:4,../../../../Chests/Loot/Rare8.nbt,5,CHEST:4,../../../../Chests/Loot/Rare9.nbt,5,CHEST:4,../../../../Chests/Loot/Rare10.nbt,5,CHEST:4,../../../../Chests/Loot/Rare11.nbt,5,CHEST:4,../../../../Chests/Loot/Rare12.nbt,5,CHEST:4,../../../../Chests/Loot/Rare13.nbt,5,CHEST:4,../../../../Chests/Loot/Rare14.nbt,5,CHEST:4,../../../../Chests/Loot/Rare15.nbt,5,CHEST:4,../../../../Chests/Loot/Epic1.nbt,2,CHEST:4,../../../../Chests/Loot/Epic2.nbt,2,CHEST:4,../../../../Chests/Loot/Epic3.nbt,2,CHEST:4,../../../../Chests/Loot/Epic4.nbt,2,CHEST:4,../../../../Chests/Loot/Epic5.nbt,2,CHEST:4,../../../../Chests/Loot/Epic6.nbt,2,CHEST:4,../../../../Chests/Loot/Epic7.nbt,2,CHEST:4,../../../../Chests/Loot/Epic8.nbt,2,CHEST:4,../../../../Chests/Loot/Epic9.nbt,2,CHEST:4,../../../../Chests/Loot/Epic10.nbt,2,CHEST:4,../../../../Chests/Loot/Epic11.nbt,2,CHEST:4,../../../../Chests/Loot/Epic12.nbt,2,CHEST:4,../../../../Chests/Loot/Epic13.nbt,2,CHEST:4,../../../../Chests/Loot/Epic14.nbt,2,CHEST:4,../../../../Chests/Loot/Epic15.nbt,5,CHEST:4,../../../../Chests/Loot/Rare1.nbt,5,CHEST:4,../../../../Chests/Loot/Rare2.nbt,5,CHEST:4,../../../../Chests/Loot/Rare3.nbt,5,CHEST:4,../../../../Chests/Loot/Rare4.nbt,5,CHEST:4,../../../../Chests/Loot/Rare5.nbt,10,CHEST:4,../../../../Chests/Loot/Rare6.nbt,10,CHEST:4,../../../../Chests/Loot/Rare7.nbt,10,CHEST:4,../../../../Chests/Loot/Rare8.nbt,10,CHEST:4,../../../../Chests/Loot/Rare9.nbt,10,CHEST:4,../../../../Chests/Loot/Rare10.nbt,15,CHEST:4,../../../../Chests/Loot/Rare11.nbt,15,CHEST:4,../../../../Chests/Loot/Rare12.nbt,15,CHEST:4,../../../../Chests/Loot/Rare13.nbt,15,CHEST:4,../../../../Chests/Loot/Rare14.nbt,15,CHEST:4,../../../../Chests/Loot/Rare15.nbt,15,CHEST:4,../../../../Chests/Loot/Epic15.nbt,100)
Block(2,3,-2,AIR:0)
Block(2,3,-1,TORCH:5)
Block(2,3,0,AIR:0)
Block(2,3,1,AIR:0)
Block(2,3,2,AIR:0)
Block(2,3,3,AIR:0)
Block(2,3,4,TORCH:5)
RandomBlock(2,3,5,DARK_OAK_FENCE:0,30,STONE:6,100)
Block(2,3,6,AIR:0)
Block(2,3,7,AIR:0)
Block(2,3,8,AIR:0)
RandomBlock(2,3,9,DARK_OAK_FENCE:0,30,STONE:6,100)
Block(2,4,-6,WOOD:1)
Block(2,4,-5,TRAP_DOOR:9)
Block(2,4,-4,TRAP_DOOR:9)
Block(2,4,-3,SPRUCE_FENCE:0)
Block(2,4,-2,WOOD:1)
Block(2,4,-1,SMOOTH_BRICK:0)
Block(2,4,0,AIR:0)
Block(2,4,1,AIR:0)
Block(2,4,2,AIR:0)
Block(2,4,3,AIR:0)
Block(2,4,4,SMOOTH_BRICK:0)
Block(2,4,5,WOOD:1)
Block(2,4,6,SPRUCE_FENCE:0)
Block(2,4,7,TRAP_DOOR:8)
Block(2,4,8,SPRUCE_FENCE:0)
Block(2,4,9,WOOD:1)
Block(2,5,-1,SPRUCE_FENCE:0)
RandomBlock(2,5,0,WALL_BANNER:3,../../NBT/Banners/banner_sun.nbt,50,WALL_BANNER:3,../../NBT/Banners/quarry_banner_0.nbt,10,WALL_BANNER:3,../../NBT/Banners/quarry_banner_1.nbt,10,WALL_BANNER:3,../../NBT/Banners/quarry_banner_2.nbt,10,WALL_BANNER:3,../../NBT/Banners/quarry_banner_3.nbt,10,WALL_BANNER:3,../../NBT/Banners/quarry_banner_4.nbt,100)
Block(2,5,1,AIR:0)
Block(2,5,2,AIR:0)
RandomBlock(2,5,3,WALL_BANNER:2,../../NBT/Banners/banner_sun.nbt,50,WALL_BANNER:2,../../NBT/Banners/quarry_banner_0.nbt,10,WALL_BANNER:2,../../NBT/Banners/quarry_banner_1.nbt,10,WALL_BANNER:2,../../NBT/Banners/quarry_banner_2.nbt,10,WALL_BANNER:2,../../NBT/Banners/quarry_banner_3.nbt,10,WALL_BANNER:2,../../NBT/Banners/quarry_banner_4.nbt,100)
Block(2,5,4,SPRUCE_FENCE:0)
Block(2,6,-1,TRAP_DOOR:0)
Block(2,6,0,TRAP_DOOR:0)
Block(2,6,1,SPRUCE_FENCE:0)
Block(2,6,2,SPRUCE_FENCE:0)
Block(2,6,3,TRAP_DOOR:2)
Block(2,6,4,TRAP_DOOR:2)
Block(3,0,-6,LOG:1)
Block(3,0,0,LOG:1)
Block(3,0,3,LOG:1)
Block(3,0,9,LOG:1)
Block(3,1,-6,WOOD:5)
Block(3,1,-5,WOOD:5)
Block(3,1,-4,WOOD:5)
Block(3,1,-3,WOOD:5)
Block(3,1,-2,WOOD:5)
Block(3,1,-1,WOOD:5)
Block(3,1,0,WOOD:5)
Block(3,1,1,WOOD:5)
Block(3,1,2,WOOD:5)
Block(3,1,3,WOOD:5)
Block(3,1,4,WOOD:5)
Block(3,1,5,WOOD:5)
Block(3,1,6,WOOD:5)
Block(3,1,7,WOOD:5)
Block(3,1,8,WOOD:5)
Block(3,1,9,WOOD:5)
Block(3,2,-6,SPRUCE_FENCE:0)
Block(3,2,-5,SMOOTH_BRICK:0)
RandomBlock(3,2,-4,DARK_OAK_FENCE:0,30,STONE:6,100)
Block(3,2,-3,SMOOTH_BRICK:0)
Block(3,2,-2,SPRUCE_FENCE:0)
Block(3,2,-1,SMOOTH_BRICK:0)
Block(3,2,0,SPRUCE_FENCE:0)
Block(3,2,1,AIR:0)
Block(3,2,2,AIR:0)
Block(3,2,3,SPRUCE_FENCE:0)
Block(3,2,4,SMOOTH_BRICK:0)
Block(3,2,5,SPRUCE_FENCE:0)
Block(3,2,6,SMOOTH_BRICK:0)
RandomBlock(3,2,7,DARK_OAK_FENCE:0,30,STONE:6,100)
Block(3,2,8,SMOOTH_BRICK:0)
Block(3,2,9,SPRUCE_FENCE:0)
Block(3,3,-6,SPRUCE_FENCE:0)
Block(3,3,-5,SMOOTH_BRICK:0)
RandomBlock(3,3,-4,DARK_OAK_FENCE:0,30,STONE:6,100)
Block(3,3,-3,SMOOTH_BRICK:0)
Block(3,3,-2,SPRUCE_FENCE:0)
Block(3,3,-1,SMOOTH_BRICK:0)
Block(3,3,0,SPRUCE_FENCE:0)
Block(3,3,1,AIR:0)
Block(3,3,2,AIR:0)
Block(3,3,3,SPRUCE_FENCE:0)
Block(3,3,4,SMOOTH_BRICK:0)
Block(3,3,5,SPRUCE_FENCE:0)
Block(3,3,6,SMOOTH_BRICK:0)
RandomBlock(3,3,7,DARK_OAK_FENCE:0,30,STONE:6,100)
Block(3,3,8,SMOOTH_BRICK:0)
Block(3,3,9,SPRUCE_FENCE:0)
Block(3,4,-6,WOOD:1)
Block(3,4,-5,SMOOTH_BRICK:0)
Block(3,4,-4,TRAP_DOOR:9)
Block(3,4,-3,SMOOTH_BRICK:0)
Block(3,4,-2,WOOD:1)
Block(3,4,-1,SMOOTH_BRICK:0)
Block(3,4,0,WOOD:1)
Block(3,4,1,WOOD:1)
Block(3,4,2,WOOD:1)
Block(3,4,3,WOOD:1)
Block(3,4,4,SMOOTH_BRICK:0)
Block(3,4,5,WOOD:1)
Block(3,4,6,SMOOTH_BRICK:0)
Block(3,4,7,TRAP_DOOR:9)
Block(3,4,8,SMOOTH_BRICK:0)
Block(3,4,9,WOOD:1)
Block(3,5,-1,SPRUCE_FENCE:0)
Block(3,5,0,SPRUCE_FENCE:0)
Block(3,5,1,SPRUCE_FENCE:0)
Block(3,5,2,SPRUCE_FENCE:0)
Block(3,5,3,SPRUCE_FENCE:0)
Block(3,5,4,SPRUCE_FENCE:0)
Block(3,6,-1,TRAP_DOOR:0)
Block(3,6,0,TRAP_DOOR:0)
Block(3,6,1,SPRUCE_FENCE:0)
Block(3,6,2,SPRUCE_FENCE:0)
Block(3,6,3,TRAP_DOOR:1)
Block(3,6,4,TRAP_DOOR:1)
Block(4,1,0,WOOD:5)
Block(4,1,1,WOOD:5)
Block(4,1,2,WOOD:5)
Block(4,1,3,WOOD:5)
RandomBlock(4,2,0,DARK_OAK_FENCE:0,30,STONE:6,100)
Block(4,2,1,AIR:0)
Block(4,2,2,AIR:0)
RandomBlock(4,2,3,DARK_OAK_FENCE:0,30,STONE:6,100)
RandomBlock(4,3,0,DARK_OAK_FENCE:0,30,STONE:6,100)
Block(4,3,1,AIR:0)
Block(4,3,2,AIR:0)
RandomBlock(4,3,3,DARK_OAK_FENCE:0,30,STONE:6,100)
Block(4,4,0,TRAP_DOOR:11)
Block(4,4,1,TRAP_DOOR:11)
Block(4,4,2,TRAP_DOOR:11)
RandomBlock(4,4,3,DARK_OAK_FENCE:0,30,STONE:6,100)
Block(5,1,0,WOOD:5)
Block(5,1,1,WOOD:5)
Block(5,1,2,WOOD:5)
Block(5,1,3,WOOD:5)
RandomBlock(5,2,0,DARK_OAK_FENCE:0,30,STONE:6,100)
Block(5,2,1,AIR:0)
Block(5,2,2,AIR:0)
RandomBlock(5,2,3,DARK_OAK_FENCE:0,30,STONE:6,100)
RandomBlock(5,3,0,DARK_OAK_FENCE:0,30,STONE:6,100)
Block(5,3,1,AIR:0)
Block(5,3,2,AIR:0)
Block(5,3,3,TORCH:5)
Block(5,4,0,TRAP_DOOR:11)
Block(5,4,1,TRAP_DOOR:11)
Block(5,4,2,TRAP_DOOR:11)
RandomBlock(5,4,3,DARK_OAK_FENCE:0,30,STONE:6,100)
Block(6,1,0,WOOD:5)
Block(6,1,1,WOOD:5)
Block(6,1,2,WOOD:5)
Block(6,1,3,WOOD:5)
RandomBlock(6,2,0,DARK_OAK_FENCE:0,30,STONE:6,100)
Block(6,2,1,AIR:0)
Block(6,2,2,AIR:0)
RandomBlock(6,2,3,DARK_OAK_FENCE:0,30,STONE:6,100)
RandomBlock(6,3,0,DARK_OAK_FENCE:0,30,STONE:6,100)
Block(6,3,1,AIR:0)
Block(6,3,2,AIR:0)
RandomBlock(6,3,3,DARK_OAK_FENCE:0,30,STONE:6,100)
RandomBlock(6,4,0,DARK_OAK_FENCE:0,30,STONE:6,100)
Block(6,4,1,TRAP_DOOR:11)
Block(6,4,2,TRAP_DOOR:11)
Block(6,4,3,TRAP_DOOR:11)
Block(7,1,0,WOOD:5)
Block(7,1,1,WOOD:5)
Block(7,1,2,WOOD:5)
Block(7,1,3,WOOD:5)
Block(7,2,0,STONE:6)
Block(7,2,1,SPRUCE_DOOR:0)
Block(7,2,2,SPRUCE_DOOR:0)
Block(7,2,3,STONE:6)
Block(7,3,0,STONE:6)
Block(7,3,1,SPRUCE_DOOR:8)
Block(7,3,2,SPRUCE_DOOR:9)
Block(7,3,3,STONE:6)
Block(7,4,0,WOOD:1)
Block(7,4,1,WOOD:1)
Block(7,4,2,WOOD:1)
Block(7,4,3,WOOD:1)
Block(8,0,0,LOG:1)
Block(8,0,3,LOG:1)
Block(8,1,0,WOOD:5)
Block(8,1,1,WOOD:5)
Block(8,1,2,WOOD:5)
Block(8,1,3,WOOD:5)
RandomBlock(8,2,0,DARK_OAK_FENCE:0,30,STONE:6,100)
Block(8,2,1,AIR:0)
Block(8,2,2,AIR:0)
RandomBlock(8,2,3,DARK_OAK_FENCE:0,30,STONE:6,100)
Block(8,3,0,TORCH:5)
Block(8,3,1,AIR:0)
Block(8,3,2,AIR:0)
RandomBlock(8,3,3,DARK_OAK_FENCE:0,30,STONE:6,100)
RandomBlock(8,4,0,DARK_OAK_FENCE:0,30,STONE:6,100)
Block(8,4,1,TRAP_DOOR:11)
Block(8,4,2,TRAP_DOOR:11)
RandomBlock(8,4,3,DARK_OAK_FENCE:0,30,STONE:6,100)
Branch(-16,0,0,true,W-Mineshaft-Village-Hub01,NORTH,100.0,32)
Branch(0,-7,0,true,W-Mineshaft-Village-Guard-Foundation,NORTH,100.0,0)
Branch(0,-10,0,false,W-Mineshaft-Village-Guard-Foundation-Ext,NORTH,100.0,0)
Branch(0,-13,0,false,W-Mineshaft-Village-Guard-Foundation-Ext,NORTH,100.0,0)
Branch(0,-16,0,false,W-Mineshaft-Village-Guard-Foundation-Ext,NORTH,100.0,0)
Branch(0,-19,0,false,W-Mineshaft-Village-Guard-Foundation-Ext,NORTH,100.0,0)
Branch(0,-22,0,false,W-Mineshaft-Village-Guard-Foundation-Ext,NORTH,100.0,0)
Branch(0,-25,0,false,W-Mineshaft-Village-Guard-Foundation-Ext,NORTH,100.0,0)
