Author: NLBlackEagle
Description: No description given
SettingsMode: WriteDisable
Frequency: 0
SpawnHeight: highestBlock
UseCenterForHighestBlock: true
MinHeight: 0
MaxHeight: 255
InheritBO3: 
InheritBO3Rotation: NORTH
OverrideChildSettings: true
OverrideParentHeight: false
CanOverride: false
BranchFrequency: 0
BranchFrequencyGroup: 
MustBeBelowOther: false
MustBeInside: 
CannotBeInside: 
ReplacesBO3: 
MustBeInsideWorldBorders: false
CanSpawnOnWater: true
SpawnOnWaterOnly: false
SpawnUnderWater: false
SpawnAtWaterLevel: false
HeightOffset: 0
RemoveAir: true
ReplaceAbove: 
ReplaceBelow: 
ReplaceWithBiomeBlocks: true
ReplaceWithSurfaceBlock: GRASS
ReplaceWithGroundBlock: DIRT
ReplaceWithStoneBlock: STONE
SmoothRadius: 0
SmoothHeightOffset: 0
SmoothStartTop: false
SmoothStartWood: false
SmoothingSurfaceBlock: 
SmoothingGroundBlock: 
BO3Group: 
IsSpawnPoint: false
DoReplaceBlocks: true
Block(-7,4,1,SPRUCE_WOOD_STAIRS:0)
Block(-7,4,2,SPRUCE_WOOD_STAIRS:0)
Block(-7,4,3,SPRUCE_WOOD_STAIRS:0)
Block(-7,4,4,SPRUCE_WOOD_STAIRS:0)
Block(-7,4,5,SPRUCE_WOOD_STAIRS:0)
Block(-7,4,6,SPRUCE_WOOD_STAIRS:0)
Block(-7,4,7,SPRUCE_WOOD_STAIRS:0)
Block(-7,4,8,SPRUCE_WOOD_STAIRS:0)
Block(-6,0,2,LOG:1)
Block(-6,0,3,COBBLESTONE:0)
Block(-6,0,4,COBBLESTONE:0)
Block(-6,0,5,COBBLESTONE:0)
Block(-6,0,6,COBBLESTONE:0)
Block(-6,0,7,COBBLESTONE:0)
Block(-6,0,8,COBBLESTONE:0)
Block(-6,1,2,LOG:1)
Block(-6,1,3,COBBLESTONE:0)
Block(-6,1,4,COBBLESTONE:0)
Block(-6,1,5,COBBLESTONE:0)
Block(-6,1,6,COBBLESTONE:0)
Block(-6,1,7,COBBLESTONE:0)
Block(-6,1,8,COBBLESTONE:0)
Block(-6,2,2,LOG:1)
Block(-6,2,3,COBBLESTONE:0)
Block(-6,2,4,COBBLESTONE:0)
Block(-6,2,5,COBBLESTONE:0)
Block(-6,2,6,COBBLESTONE:0)
Block(-6,2,7,COBBLESTONE:0)
Block(-6,2,8,COBBLESTONE:0)
Block(-6,3,2,LOG:1)
Block(-6,3,3,WOOD:1)
Block(-6,3,4,WOOD:1)
Block(-6,3,5,WOOD:1)
Block(-6,3,6,WOOD:1)
Block(-6,3,7,WOOD:1)
Block(-6,3,8,WOOD:1)
Block(-6,4,1,SPRUCE_WOOD_STAIRS:5)
Block(-6,4,2,LOG:1)
Block(-6,4,3,DARK_OAK_FENCE:0)
Block(-6,4,4,DARK_OAK_FENCE:0)
Block(-6,4,5,DARK_OAK_FENCE:0)
Block(-6,4,6,DARK_OAK_FENCE:0)
Block(-6,4,7,DARK_OAK_FENCE:0)
Block(-6,4,8,DARK_OAK_FENCE:0)
Block(-6,5,1,SPRUCE_WOOD_STAIRS:0)
Block(-6,5,2,SPRUCE_WOOD_STAIRS:0)
Block(-6,5,3,SPRUCE_WOOD_STAIRS:0)
Block(-6,5,4,SPRUCE_WOOD_STAIRS:0)
Block(-6,5,5,SPRUCE_WOOD_STAIRS:0)
Block(-6,5,6,SPRUCE_WOOD_STAIRS:0)
Block(-6,5,7,SPRUCE_WOOD_STAIRS:0)
Block(-6,5,8,SPRUCE_WOOD_STAIRS:0)
Block(-5,0,2,COBBLESTONE:0)
Block(-5,0,3,COBBLESTONE:0)
Block(-5,0,4,COBBLESTONE:0)
Block(-5,0,5,COBBLESTONE:0)
Block(-5,0,6,COBBLESTONE:0)
Block(-5,0,7,COBBLESTONE:0)
Block(-5,0,8,COBBLESTONE:0)
Block(-5,1,2,COBBLESTONE:0)
Block(-5,1,3,COBBLESTONE:0)
Block(-5,1,4,COBBLESTONE:0)
Block(-5,1,5,COBBLESTONE:0)
Block(-5,1,6,COBBLESTONE:0)
Block(-5,1,7,COBBLESTONE:0)
Block(-5,1,8,COBBLESTONE:0)
Block(-5,2,2,COBBLESTONE:0)
Block(-5,2,3,COBBLESTONE:0)
Block(-5,2,4,COBBLESTONE:0)
Block(-5,2,5,COBBLESTONE:0)
Block(-5,2,6,COBBLESTONE:0)
Block(-5,2,7,COBBLESTONE:0)
Block(-5,2,8,COBBLESTONE:0)
Block(-5,3,2,WOOD:1)
Block(-5,3,3,DARK_OAK_STAIRS:1)
Block(-5,3,6,COBBLESTONE:0)
Block(-5,4,2,WOOD:1)
RandomBlock(-5,4,3,WALL_BANNER:3,../../NBT/Banners/viking_regular_1.nbt,20,WALL_BANNER:3,../../NBT/Banners/viking_regular_2.nbt,20,WALL_BANNER:3,../../NBT/Banners/viking_regular_3.nbt,20,WALL_BANNER:3,../../NBT/Banners/viking_regular_4.nbt,20,WALL_BANNER:3,../../NBT/Banners/viking_regular_5.nbt,20,WALL_BANNER:3,../../NBT/Banners/viking_regular_6.nbt,20,WALL_BANNER:3,../../NBT/Banners/viking_regular_7.nbt,20,WALL_BANNER:3,../../NBT/Banners/viking_regular_8.nbt,100)
Block(-5,4,6,COBBLESTONE:0)
Block(-5,5,1,SPRUCE_WOOD_STAIRS:5)
Block(-5,5,2,DARK_OAK_FENCE:0)
Block(-5,5,4,SPRUCE_WOOD_STAIRS:5)
Block(-5,5,5,SPRUCE_WOOD_STAIRS:5)
Block(-5,5,6,WOOD:1)
Block(-5,6,1,SPRUCE_WOOD_STAIRS:0)
Block(-5,6,2,SPRUCE_WOOD_STAIRS:0)
Block(-5,6,3,SPRUCE_WOOD_STAIRS:0)
Block(-5,6,4,SPRUCE_WOOD_STAIRS:0)
Block(-5,6,5,SPRUCE_WOOD_STAIRS:0)
Block(-5,6,6,SPRUCE_WOOD_STAIRS:0)
Block(-5,6,7,SPRUCE_WOOD_STAIRS:0)
Block(-5,6,8,SPRUCE_WOOD_STAIRS:0)
Block(-5,7,4,SPRUCE_WOOD_STAIRS:0)
Block(-5,7,5,TRAP_DOOR:14)
Block(-5,7,6,SPRUCE_WOOD_STAIRS:0)
Block(-4,0,2,COBBLESTONE:0)
Block(-4,0,3,COBBLESTONE:0)
Block(-4,0,4,COBBLESTONE:0)
Block(-4,0,5,COBBLESTONE:0)
Block(-4,0,6,COBBLESTONE:0)
Block(-4,0,7,COBBLESTONE:0)
Block(-4,0,8,COBBLESTONE:0)
Block(-4,1,2,COBBLESTONE:0)
Block(-4,1,3,COBBLESTONE:0)
Block(-4,1,4,COBBLESTONE:0)
Block(-4,1,5,COBBLESTONE:0)
Block(-4,1,6,COBBLESTONE:0)
Block(-4,1,7,COBBLESTONE:0)
Block(-4,1,8,COBBLESTONE:0)
Block(-4,2,2,COBBLESTONE:0)
Block(-4,2,3,COBBLESTONE:0)
Block(-4,2,4,COBBLESTONE:0)
Block(-4,2,5,COBBLESTONE:0)
Block(-4,2,6,COBBLESTONE:0)
Block(-4,2,7,COBBLESTONE:0)
Block(-4,2,8,WOOD:5)
Block(-4,3,2,WOOD:1)
Block(-4,3,3,DARK_OAK_STAIRS:3)
Block(-4,3,6,FURNACE:2)
Block(-4,3,8,WOOD:5)
Block(-4,4,2,WOOD:1)
Block(-4,4,6,COBBLESTONE_STAIRS:6)
Block(-4,4,8,WOOD:5)
Block(-4,5,2,WOOD:1)
RandomBlock(-4,5,3,WALL_BANNER:3,../../NBT/Banners/viking_regular_1.nbt,20,WALL_BANNER:3,../../NBT/Banners/viking_regular_2.nbt,20,WALL_BANNER:3,../../NBT/Banners/viking_regular_3.nbt,20,WALL_BANNER:3,../../NBT/Banners/viking_regular_4.nbt,20,WALL_BANNER:3,../../NBT/Banners/viking_regular_5.nbt,20,WALL_BANNER:3,../../NBT/Banners/viking_regular_6.nbt,20,WALL_BANNER:3,../../NBT/Banners/viking_regular_7.nbt,20,WALL_BANNER:3,../../NBT/Banners/viking_regular_8.nbt,100)
Block(-4,5,6,WOOD:1)
Block(-4,5,8,WOOD:5)
Block(-4,6,1,SPRUCE_WOOD_STAIRS:5)
Block(-4,6,2,DARK_OAK_FENCE:0)
Block(-4,6,4,SPRUCE_WOOD_STAIRS:5)
Block(-4,6,6,SPRUCE_WOOD_STAIRS:5)
Block(-4,6,8,WOOD_STEP:1)
Block(-4,7,1,SPRUCE_WOOD_STAIRS:0)
Block(-4,7,2,SPRUCE_WOOD_STAIRS:0)
Block(-4,7,3,SPRUCE_WOOD_STAIRS:0)
Block(-4,7,4,WOOD_DOUBLE_STEP:1)
Block(-4,7,6,WOOD_DOUBLE_STEP:1)
Block(-4,7,7,SPRUCE_WOOD_STAIRS:0)
Block(-4,7,8,SPRUCE_WOOD_STAIRS:0)
Block(-4,8,4,SPRUCE_WOOD_STAIRS:0)
Block(-4,8,5,SPRUCE_WOOD_STAIRS:0)
Block(-4,8,6,SPRUCE_WOOD_STAIRS:0)
Block(-3,0,2,COBBLESTONE:0)
Block(-3,0,3,COBBLESTONE:0)
Block(-3,0,4,COBBLESTONE:0)
Block(-3,0,5,COBBLESTONE:0)
Block(-3,0,6,COBBLESTONE:0)
Block(-3,0,7,COBBLESTONE:0)
Block(-3,0,8,COBBLESTONE:0)
Block(-3,1,2,COBBLESTONE:0)
Block(-3,1,3,COBBLESTONE:0)
Block(-3,1,4,COBBLESTONE:0)
Block(-3,1,5,COBBLESTONE:0)
Block(-3,1,6,COBBLESTONE:0)
Block(-3,1,7,COBBLESTONE:0)
Block(-3,1,8,COBBLESTONE:0)
Block(-3,2,2,COBBLESTONE:0)
Block(-3,2,3,COBBLESTONE:0)
Block(-3,2,4,COBBLESTONE:0)
Block(-3,2,5,COBBLESTONE:0)
Block(-3,2,6,COBBLESTONE:0)
Block(-3,2,7,COBBLESTONE:0)
Block(-3,2,8,WOOD:5)
Block(-3,3,2,SPRUCE_DOOR:3)
Block(-3,3,6,FURNACE:2)
Block(-3,3,7,WOOD:5)
Block(-3,3,8,STATIONARY_WATER:0)
Block(-3,4,2,SPRUCE_DOOR:8)
Block(-3,4,6,COBBLESTONE_STAIRS:6)
Block(-3,4,7,WOOD:5)
Block(-3,4,8,STATIONARY_WATER:0)
Block(-3,5,2,WOOD:1)
RandomBlock(-3,5,3,WALL_BANNER:3,../../NBT/Banners/viking_wealthy_1.nbt,20,WALL_BANNER:3,../../NBT/Banners/viking_wealthy_2.nbt,20,WALL_BANNER:3,../../NBT/Banners/viking_wealthy_3.nbt,20,WALL_BANNER:3,../../NBT/Banners/viking_wealthy_4.nbt,20,WALL_BANNER:3,../../NBT/Banners/viking_wealthy_5.nbt,20,WALL_BANNER:3,../../NBT/Banners/viking_wealthy_6.nbt,20,WALL_BANNER:3,../../NBT/Banners/viking_wealthy_7.nbt,20,WALL_BANNER:3,../../NBT/Banners/viking_wealthy_8.nbt,20,WALL_BANNER:3,../../NBT/Banners/viking_wealthy_9.nbt,100)
Block(-3,5,6,WOOD:1)
Block(-3,5,7,WOOD:5)
Block(-3,6,2,WOOD:1)
Block(-3,6,6,DARK_OAK_FENCE:0)
Block(-3,6,7,WOOD_STEP:1)
Block(-3,6,8,WOOD_STEP:1)
Block(-3,7,1,SPRUCE_WOOD_STAIRS:5)
Block(-3,7,2,DARK_OAK_FENCE:0)
Block(-3,7,4,SPRUCE_WOOD_STAIRS:5)
Block(-3,7,6,SPRUCE_WOOD_STAIRS:5)
Block(-3,8,1,SPRUCE_WOOD_STAIRS:0)
Block(-3,8,2,SPRUCE_WOOD_STAIRS:0)
Block(-3,8,3,SPRUCE_WOOD_STAIRS:0)
Block(-3,8,4,WOOD_DOUBLE_STEP:1)
Block(-3,8,5,WOOD_DOUBLE_STEP:1)
Block(-3,8,6,WOOD_DOUBLE_STEP:1)
Block(-3,8,7,SPRUCE_WOOD_STAIRS:0)
Block(-3,8,8,SPRUCE_WOOD_STAIRS:0)
Block(-3,9,4,WOOD_STEP:1)
Block(-3,9,5,WOOD_STEP:1)
Block(-3,9,6,WOOD_STEP:1)
Block(-2,0,2,COBBLESTONE:0)
Block(-2,0,3,COBBLESTONE:0)
Block(-2,0,4,COBBLESTONE:0)
Block(-2,0,5,COBBLESTONE:0)
Block(-2,0,6,COBBLESTONE:0)
Block(-2,0,7,COBBLESTONE:0)
Block(-2,0,8,COBBLESTONE:0)
Block(-2,1,2,COBBLESTONE:0)
Block(-2,1,3,COBBLESTONE:0)
Block(-2,1,4,COBBLESTONE:0)
Block(-2,1,5,COBBLESTONE:0)
Block(-2,1,6,COBBLESTONE:0)
Block(-2,1,7,COBBLESTONE:0)
Block(-2,1,8,COBBLESTONE:0)
Block(-2,2,2,COBBLESTONE:0)
Block(-2,2,3,COBBLESTONE:0)
Block(-2,2,4,COBBLESTONE:0)
Block(-2,2,5,COBBLESTONE:0)
Block(-2,2,6,COBBLESTONE:0)
Block(-2,2,7,WOOD:5)
Block(-2,2,8,WOOD:5)
Block(-2,3,2,WOOD:1)
Block(-2,3,6,COBBLESTONE:0)
Block(-2,3,7,WOOD:5)
Block(-2,3,8,STATIONARY_WATER:0)
Block(-2,4,2,WOOD:1)
RandomBlock(-2,4,3,WALL_BANNER:3,../../NBT/Banners/viking_wealthy_1.nbt,20,WALL_BANNER:3,../../NBT/Banners/viking_wealthy_2.nbt,20,WALL_BANNER:3,../../NBT/Banners/viking_wealthy_3.nbt,20,WALL_BANNER:3,../../NBT/Banners/viking_wealthy_4.nbt,20,WALL_BANNER:3,../../NBT/Banners/viking_wealthy_5.nbt,20,WALL_BANNER:3,../../NBT/Banners/viking_wealthy_6.nbt,20,WALL_BANNER:3,../../NBT/Banners/viking_wealthy_7.nbt,20,WALL_BANNER:3,../../NBT/Banners/viking_wealthy_8.nbt,20,WALL_BANNER:3,../../NBT/Banners/viking_wealthy_9.nbt,100)
Block(-2,4,6,COBBLESTONE:0)
Block(-2,4,7,WOOD:5)
Block(-2,4,8,STATIONARY_WATER:0)
Block(-2,5,2,WOOD:1)
Block(-2,5,6,WOOD:1)
Block(-2,5,7,WOOD:5)
Block(-2,6,2,WOOD:1)
RandomBlock(-2,6,3,WALL_BANNER:3,../../NBT/Banners/viking_regular_1.nbt,20,WALL_BANNER:3,../../NBT/Banners/viking_regular_2.nbt,20,WALL_BANNER:3,../../NBT/Banners/viking_regular_3.nbt,20,WALL_BANNER:3,../../NBT/Banners/viking_regular_4.nbt,20,WALL_BANNER:3,../../NBT/Banners/viking_regular_5.nbt,20,WALL_BANNER:3,../../NBT/Banners/viking_regular_6.nbt,20,WALL_BANNER:3,../../NBT/Banners/viking_regular_7.nbt,20,WALL_BANNER:3,../../NBT/Banners/viking_regular_8.nbt,100)
Block(-2,6,6,DARK_OAK_FENCE:0)
Block(-2,6,7,WOOD_STEP:1)
Block(-2,6,8,WOOD_STEP:1)
Block(-2,7,2,WOOD:1)
RandomBlock(-2,7,3,WALL_BANNER:3,../../NBT/Banners/viking_wealthy_1.nbt,20,WALL_BANNER:3,../../NBT/Banners/viking_wealthy_2.nbt,20,WALL_BANNER:3,../../NBT/Banners/viking_wealthy_3.nbt,20,WALL_BANNER:3,../../NBT/Banners/viking_wealthy_4.nbt,20,WALL_BANNER:3,../../NBT/Banners/viking_wealthy_5.nbt,20,WALL_BANNER:3,../../NBT/Banners/viking_wealthy_6.nbt,20,WALL_BANNER:3,../../NBT/Banners/viking_wealthy_7.nbt,20,WALL_BANNER:3,../../NBT/Banners/viking_wealthy_8.nbt,20,WALL_BANNER:3,../../NBT/Banners/viking_wealthy_9.nbt,100)
Block(-2,7,6,DARK_OAK_FENCE:0)
Block(-2,8,1,SPRUCE_WOOD_STAIRS:5)
Block(-2,8,2,DARK_OAK_FENCE:0)
Block(-2,8,4,SPRUCE_WOOD_STAIRS:5)
Block(-2,8,5,SPRUCE_WOOD_STAIRS:5)
Block(-2,8,6,SPRUCE_WOOD_STAIRS:5)
Block(-2,9,1,SPRUCE_WOOD_STAIRS:0)
Block(-2,9,2,WOOD_STEP:1)
Block(-2,9,3,WOOD_STEP:1)
Block(-2,9,4,WOOD_STEP:1)
Block(-2,9,5,WOOD_STEP:1)
Block(-2,9,6,WOOD_STEP:1)
Block(-2,9,7,WOOD_STEP:1)
Block(-2,9,8,WOOD_STEP:1)
Block(-2,10,1,WOOD_STEP:1)
Block(-1,0,2,COBBLESTONE:0)
Block(-1,0,3,COBBLESTONE:0)
Block(-1,0,4,COBBLESTONE:0)
Block(-1,0,5,COBBLESTONE:0)
Block(-1,0,6,COBBLESTONE:0)
Block(-1,0,7,COBBLESTONE:0)
Block(-1,0,8,COBBLESTONE:0)
Block(-1,1,2,COBBLESTONE:0)
Block(-1,1,3,COBBLESTONE:0)
Block(-1,1,4,COBBLESTONE:0)
Block(-1,1,5,COBBLESTONE:0)
Block(-1,1,6,COBBLESTONE:0)
Block(-1,1,7,COBBLESTONE:0)
Block(-1,1,8,COBBLESTONE:0)
Block(-1,2,2,LOG:1)
Block(-1,2,3,COBBLESTONE:0)
Block(-1,2,4,COBBLESTONE:0)
Block(-1,2,5,COBBLESTONE:0)
Block(-1,2,6,COBBLESTONE:0)
Block(-1,2,7,COBBLESTONE:0)
Block(-1,2,8,WOOD:5)
Block(-1,3,1,WOOD_BUTTON:4)
Block(-1,3,2,LOG:1)
Block(-1,3,3,FLOWER_POT:0)
Block(-1,3,5,SPRUCE_DOOR:2)
Block(-1,3,6,LOG:1)
Block(-1,3,7,CAULDRON:3)
Block(-1,3,8,WOOD:5)
Block(-1,4,1,WOOD_BUTTON:4)
Block(-1,4,2,LOG:1)
RandomBlock(-1,4,3,WALL_BANNER:3,../../NBT/Banners/viking_wealthy_1.nbt,20,WALL_BANNER:3,../../NBT/Banners/viking_wealthy_2.nbt,20,WALL_BANNER:3,../../NBT/Banners/viking_wealthy_3.nbt,20,WALL_BANNER:3,../../NBT/Banners/viking_wealthy_4.nbt,20,WALL_BANNER:3,../../NBT/Banners/viking_wealthy_5.nbt,20,WALL_BANNER:3,../../NBT/Banners/viking_wealthy_6.nbt,20,WALL_BANNER:3,../../NBT/Banners/viking_wealthy_7.nbt,20,WALL_BANNER:3,../../NBT/Banners/viking_wealthy_8.nbt,20,WALL_BANNER:3,../../NBT/Banners/viking_wealthy_9.nbt,100)
Block(-1,4,5,SPRUCE_DOOR:8)
Block(-1,4,6,LOG:1)
Block(-1,4,7,TRAP_DOOR:3)
Block(-1,4,8,WOOD:5)
Block(-1,5,1,WOOD_BUTTON:4)
Block(-1,5,2,LOG:1)
Block(-1,5,3,WOOD_DOUBLE_STEP:1)
Block(-1,5,4,WOOD_DOUBLE_STEP:1)
Block(-1,5,5,WOOD_DOUBLE_STEP:1)
Block(-1,5,6,LOG:1)
Block(-1,5,8,WOOD:5)
Block(-1,6,1,WOOD_BUTTON:4)
Block(-1,6,2,LOG:1)
Block(-1,6,3,DARK_OAK_FENCE:0)
Block(-1,6,4,DARK_OAK_FENCE:0)
Block(-1,6,5,DARK_OAK_FENCE:0)
Block(-1,6,6,LOG:1)
Block(-1,6,8,WOOD_STEP:1)
Block(-1,7,1,WOOD_BUTTON:4)
Block(-1,7,2,LOG:1)
Block(-1,7,6,LOG:1)
Block(-1,8,1,WOOD_BUTTON:4)
Block(-1,8,2,LOG:1)
RandomBlock(-1,8,5,WALL_BANNER:5,../../NBT/Banners/viking_honor_1.nbt,20,WALL_BANNER:5,../../NBT/Banners/viking_honor_2.nbt,20,WALL_BANNER:5,../../NBT/Banners/viking_honor_3.nbt,20,WALL_BANNER:5,../../NBT/Banners/viking_honor_4.nbt,20,WALL_BANNER:5,../../NBT/Banners/viking_honor_5.nbt,20,WALL_BANNER:5,../../NBT/Banners/viking_honor_6.nbt,100)
Block(-1,8,6,LOG:1)
Block(-1,9,-1,WOOD_BUTTON:4)
Block(-1,9,0,LOG:9)
Block(-1,9,1,LOG:9)
Block(-1,9,2,LOG:9)
Block(-1,9,3,LOG:9)
Block(-1,9,4,LOG:9)
Block(-1,9,5,LOG:9)
Block(-1,9,6,LOG:9)
Block(-1,9,7,LOG:9)
Block(-1,9,8,LOG:9)
Block(0,0,2,COBBLESTONE:0)
Block(0,0,3,COBBLESTONE:0)
Block(0,0,4,COBBLESTONE:0)
Block(0,0,5,COBBLESTONE:0)
Block(0,0,6,COBBLESTONE:0)
Block(0,0,7,COBBLESTONE:0)
Block(0,0,8,COBBLESTONE:0)
Block(0,1,2,COBBLESTONE:0)
Block(0,1,3,COBBLESTONE:0)
Block(0,1,4,COBBLESTONE:0)
Block(0,1,5,COBBLESTONE:0)
Block(0,1,6,COBBLESTONE:0)
Block(0,1,7,COBBLESTONE:0)
Block(0,1,8,COBBLESTONE:0)
Block(0,2,2,COBBLESTONE:0)
Block(0,2,3,COBBLESTONE:0)
Block(0,2,4,COBBLESTONE:0)
Block(0,2,5,COBBLESTONE:0)
Block(0,2,6,COBBLESTONE:0)
Block(0,2,7,COBBLESTONE:0)
Block(0,2,8,COBBLESTONE:0)
Block(0,3,2,WOOD:1)
Block(0,3,3,DARK_OAK_STAIRS:5)
Block(0,3,5,LADDER:2)
Block(0,3,6,WOOD:1)
Block(0,3,7,CAULDRON:3)
Block(0,3,8,CAULDRON:3)
Block(0,4,2,SPRUCE_WOOD_STAIRS:1)
RandomBlock(0,4,3,WALL_BANNER:3,../../NBT/Banners/viking_wealthy_1.nbt,20,WALL_BANNER:3,../../NBT/Banners/viking_wealthy_2.nbt,20,WALL_BANNER:3,../../NBT/Banners/viking_wealthy_3.nbt,20,WALL_BANNER:3,../../NBT/Banners/viking_wealthy_4.nbt,20,WALL_BANNER:3,../../NBT/Banners/viking_wealthy_5.nbt,20,WALL_BANNER:3,../../NBT/Banners/viking_wealthy_6.nbt,20,WALL_BANNER:3,../../NBT/Banners/viking_wealthy_7.nbt,20,WALL_BANNER:3,../../NBT/Banners/viking_wealthy_8.nbt,20,WALL_BANNER:3,../../NBT/Banners/viking_wealthy_9.nbt,100)
Block(0,4,5,LADDER:2)
Block(0,4,6,WOOD:1)
Block(0,4,7,TRAP_DOOR:3)
Block(0,4,8,TRAP_DOOR:3)
Block(0,5,2,WOOD:1)
Block(0,5,3,WOOD_STEP:9)
Block(0,5,4,WOOD_STEP:9)
Block(0,5,5,TRAP_DOOR:12)
Block(0,5,6,WOOD:1)
Block(0,5,8,SPRUCE_WOOD_STAIRS:4)
Block(0,6,2,WOOD:1)
Block(0,6,3,BED_BLOCK:9)
Block(0,6,4,BED_BLOCK:9)
Block(0,6,6,DARK_OAK_FENCE:0)
Block(0,7,2,WOOD:1)
Block(0,7,6,DARK_OAK_FENCE:0)
Block(0,8,1,SPRUCE_WOOD_STAIRS:4)
Block(0,8,2,DARK_OAK_FENCE:0)
Block(0,8,6,SPRUCE_WOOD_STAIRS:4)
Block(0,9,1,SPRUCE_WOOD_STAIRS:1)
Block(0,9,2,WOOD_STEP:1)
Block(0,9,3,WOOD_STEP:1)
Block(0,9,4,WOOD_STEP:1)
Block(0,9,5,WOOD_STEP:1)
Block(0,9,6,WOOD_STEP:1)
Block(0,9,7,WOOD_STEP:1)
Block(0,9,8,WOOD_STEP:1)
Block(0,10,1,WOOD_STEP:1)
Block(1,0,2,COBBLESTONE:0)
Block(1,0,3,COBBLESTONE:0)
Block(1,0,4,COBBLESTONE:0)
Block(1,0,5,COBBLESTONE:0)
Block(1,0,6,COBBLESTONE:0)
Block(1,0,7,COBBLESTONE:0)
Block(1,0,8,COBBLESTONE:0)
Block(1,1,2,COBBLESTONE:0)
Block(1,1,3,COBBLESTONE:0)
Block(1,1,4,COBBLESTONE:0)
Block(1,1,5,COBBLESTONE:0)
Block(1,1,6,COBBLESTONE:0)
Block(1,1,7,COBBLESTONE:0)
Block(1,1,8,COBBLESTONE:0)
Block(1,2,2,COBBLESTONE:0)
Block(1,2,3,COBBLESTONE:0)
Block(1,2,4,COBBLESTONE:0)
Block(1,2,5,COBBLESTONE:0)
Block(1,2,6,COBBLESTONE:0)
Block(1,2,7,COBBLESTONE:0)
Block(1,2,8,COBBLESTONE:0)
Block(1,3,2,WOOD:1)
Block(1,3,3,WOOD_STEP:13)
Block(1,3,5,AIR:0)
Block(1,3,6,WOOD:1)
Block(1,3,7,CAULDRON:3)
Block(1,4,2,SPRUCE_WOOD_STAIRS:0)
Block(1,4,3,FLOWER_POT:0)
Block(1,4,6,WOOD:1)
Block(1,4,7,TRAP_DOOR:3)
Block(1,5,2,WOOD:1)
Block(1,5,3,WOOD_STEP:9)
Block(1,5,4,WOOD_STEP:9)
Block(1,5,5,TRAP_DOOR:8)
Block(1,5,6,WOOD:1)
RandomBlock(1,5,7,WALL_BANNER:3,../../NBT/Banners/viking_wealthy_1.nbt,20,WALL_BANNER:3,../../NBT/Banners/viking_wealthy_2.nbt,20,WALL_BANNER:3,../../NBT/Banners/viking_wealthy_3.nbt,20,WALL_BANNER:3,../../NBT/Banners/viking_wealthy_4.nbt,20,WALL_BANNER:3,../../NBT/Banners/viking_wealthy_5.nbt,20,WALL_BANNER:3,../../NBT/Banners/viking_wealthy_6.nbt,20,WALL_BANNER:3,../../NBT/Banners/viking_wealthy_7.nbt,20,WALL_BANNER:3,../../NBT/Banners/viking_wealthy_8.nbt,20,WALL_BANNER:3,../../NBT/Banners/viking_wealthy_9.nbt,100)
Block(1,5,8,SPRUCE_WOOD_STAIRS:6)
Block(1,6,2,WOOD:1)
Block(1,6,3,BED_BLOCK:1)
Block(1,6,4,BED_BLOCK:1)
Block(1,6,6,DARK_OAK_FENCE:0)
Block(1,7,1,SPRUCE_WOOD_STAIRS:4)
Block(1,7,2,DARK_OAK_FENCE:0)
Block(1,7,6,SPRUCE_WOOD_STAIRS:4)
Block(1,8,1,SPRUCE_WOOD_STAIRS:1)
Block(1,8,2,SPRUCE_WOOD_STAIRS:1)
Block(1,8,3,SPRUCE_WOOD_STAIRS:1)
Block(1,8,4,SPRUCE_WOOD_STAIRS:1)
Block(1,8,5,SPRUCE_WOOD_STAIRS:1)
Block(1,8,6,SPRUCE_WOOD_STAIRS:1)
Block(1,8,7,SPRUCE_WOOD_STAIRS:1)
Block(1,8,8,SPRUCE_WOOD_STAIRS:1)
Block(2,0,2,COBBLESTONE:0)
Block(2,0,3,COBBLESTONE:0)
Block(2,0,4,COBBLESTONE:0)
Block(2,0,5,COBBLESTONE:0)
Block(2,0,6,COBBLESTONE:0)
Block(2,0,7,COBBLESTONE:0)
Block(2,0,8,COBBLESTONE:0)
Block(2,1,2,COBBLESTONE:0)
Block(2,1,3,COBBLESTONE:0)
Block(2,1,4,COBBLESTONE:0)
Block(2,1,5,COBBLESTONE:0)
Block(2,1,6,COBBLESTONE:0)
Block(2,1,7,COBBLESTONE:0)
Block(2,1,8,COBBLESTONE:0)
Block(2,2,2,COBBLESTONE:0)
Block(2,2,3,COBBLESTONE:0)
Block(2,2,4,COBBLESTONE:0)
Block(2,2,5,COBBLESTONE:0)
Block(2,2,6,COBBLESTONE:0)
Block(2,2,7,COBBLESTONE:0)
Block(2,2,8,COBBLESTONE:0)
Block(2,3,2,WOOD:1)
Block(2,3,3,WOOD_STEP:13)
Block(2,3,6,SPRUCE_DOOR:1)
Block(2,4,2,WOOD:1)
RandomBlock(2,4,3,WALL_BANNER:3,../../NBT/Banners/viking_regular_1.nbt,20,WALL_BANNER:3,../../NBT/Banners/viking_regular_2.nbt,20,WALL_BANNER:3,../../NBT/Banners/viking_regular_3.nbt,20,WALL_BANNER:3,../../NBT/Banners/viking_regular_4.nbt,20,WALL_BANNER:3,../../NBT/Banners/viking_regular_5.nbt,20,WALL_BANNER:3,../../NBT/Banners/viking_regular_6.nbt,20,WALL_BANNER:3,../../NBT/Banners/viking_regular_7.nbt,20,WALL_BANNER:3,../../NBT/Banners/viking_regular_8.nbt,100)
Block(2,4,6,SPRUCE_DOOR:8)
Block(2,5,2,WOOD:1)
Block(2,5,3,WOOD_STEP:9)
Block(2,5,4,WOOD_STEP:9)
Block(2,5,5,WOOD_STEP:9)
Block(2,5,6,WOOD:1)
Block(2,6,1,SPRUCE_WOOD_STAIRS:4)
Block(2,6,2,DARK_OAK_FENCE:0)
RandomBlock(2,6,3,AIR:0,20,CHEST:4,../../../../Chests/Loot/JunkChest_1.nbt,10,CHEST:4,../../../../Chests/Loot/JunkChest_2.nbt,10,CHEST:4,../../../../Chests/Loot/JunkChest_3.nbt,10,CHEST:4,../../../../Chests/Loot/JunkChest_4.nbt,10,CHEST:4,../../../../Chests/Loot/JunkChest_5.nbt,10,CHEST:4,../../../../Chests/Lore/Viking_1.nbt,1,CHEST:4,../../../../Chests/Lore/Viking_2.nbt,1,CHEST:4,../../../../Chests/Lore/Viking_3.nbt,1,CHEST:4,../../../../Chests/Lore/Viking_4.nbt,1,CHEST:4,../../../../Chests/Lore/Viking_5.nbt,1,CHEST:4,../../../../Chests/Loot/Common1.nbt,10,CHEST:4,../../../../Chests/Loot/Common2.nbt,10,CHEST:4,../../../../Chests/Loot/Common3.nbt,10,CHEST:4,../../../../Chests/Loot/Common4.nbt,10,CHEST:4,../../../../Chests/Loot/Common5.nbt,10,CHEST:4,../../../../Chests/Loot/Common6.nbt,10,CHEST:4,../../../../Chests/Loot/Common7.nbt,10,CHEST:4,../../../../Chests/Loot/Common8.nbt,10,CHEST:4,../../../../Chests/Loot/Common9.nbt,10,CHEST:4,../../../../Chests/Loot/Common10.nbt,10,CHEST:4,../../../../Chests/Loot/Common10.nbt,11,CHEST:4,../../../../Chests/Loot/Common12.nbt,10,CHEST:4,../../../../Chests/Loot/Common13.nbt,10,CHEST:4,../../../../Chests/Loot/Common14.nbt,10,CHEST:4,../../../../Chests/Loot/Common15.nbt,10,CHEST:4,../../../../Chests/Lore/Viking_1.nbt,2,CHEST:4,../../../../Chests/Lore/Viking_3.nbt,2,CHEST:4,../../../../Chests/Lore/Viking_4.nbt,2,CHEST:4,../../../../Chests/Lore/Viking_5.nbt,2,CHEST:4,../../../../Chests/Lore/Viking_5.nbt,2,CHEST:4,../../../../Chests/Loot/Rare1.nbt,5,CHEST:4,../../../../Chests/Loot/Rare2.nbt,5,CHEST:4,../../../../Chests/Loot/Rare3.nbt,5,CHEST:4,../../../../Chests/Loot/Rare4.nbt,5,CHEST:4,../../../../Chests/Loot/Rare5.nbt,5,CHEST:4,../../../../Chests/Loot/Rare6.nbt,5,CHEST:4,../../../../Chests/Loot/Rare7.nbt,5,CHEST:4,../../../../Chests/Loot/Rare8.nbt,5,CHEST:4,../../../../Chests/Loot/Rare9.nbt,5,CHEST:4,../../../../Chests/Loot/Rare10.nbt,5,CHEST:4,../../../../Chests/Loot/Rare11.nbt,5,CHEST:4,../../../../Chests/Loot/Rare12.nbt,5,CHEST:4,../../../../Chests/Loot/Rare13.nbt,5,CHEST:4,../../../../Chests/Loot/Rare14.nbt,5,CHEST:4,../../../../Chests/Loot/Rare15.nbt,5,CHEST:4,../../../../Chests/Loot/Epic1.nbt,2,CHEST:4,../../../../Chests/Loot/Epic2.nbt,2,CHEST:4,../../../../Chests/Loot/Epic3.nbt,2,CHEST:4,../../../../Chests/Loot/Epic4.nbt,2,CHEST:4,../../../../Chests/Loot/Epic5.nbt,2,CHEST:4,../../../../Chests/Loot/Epic6.nbt,2,CHEST:4,../../../../Chests/Loot/Epic7.nbt,2,CHEST:4,../../../../Chests/Loot/Epic8.nbt,2,CHEST:4,../../../../Chests/Loot/Epic9.nbt,2,CHEST:4,../../../../Chests/Loot/Epic10.nbt,2,CHEST:4,../../../../Chests/Loot/Epic11.nbt,2,CHEST:4,../../../../Chests/Loot/Epic12.nbt,2,CHEST:4,../../../../Chests/Loot/Epic13.nbt,2,CHEST:4,../../../../Chests/Loot/Epic14.nbt,2,CHEST:4,../../../../Chests/Loot/Epic15.nbt,5,CHEST:4,../../../../Chests/Loot/Rare1.nbt,5,CHEST:4,../../../../Chests/Loot/Rare2.nbt,5,CHEST:4,../../../../Chests/Loot/Rare3.nbt,5,CHEST:4,../../../../Chests/Loot/Rare4.nbt,5,CHEST:4,../../../../Chests/Loot/Rare5.nbt,10,CHEST:4,../../../../Chests/Loot/Rare6.nbt,10,CHEST:4,../../../../Chests/Loot/Rare7.nbt,10,CHEST:4,../../../../Chests/Loot/Rare8.nbt,10,CHEST:4,../../../../Chests/Loot/Rare9.nbt,10,CHEST:4,../../../../Chests/Loot/Rare10.nbt,15,CHEST:4,../../../../Chests/Loot/Rare11.nbt,15,CHEST:4,../../../../Chests/Loot/Rare12.nbt,15,CHEST:4,../../../../Chests/Loot/Rare13.nbt,15,CHEST:4,../../../../Chests/Loot/Rare14.nbt,15,CHEST:4,../../../../Chests/Loot/Rare15.nbt,15,CHEST:4,../../../../Chests/Loot/Epic15.nbt,100)
RandomBlock(2,6,4,AIR:0,20,CHEST:4,../../../../Chests/Loot/JunkChest_1.nbt,10,CHEST:4,../../../../Chests/Loot/JunkChest_2.nbt,10,CHEST:4,../../../../Chests/Loot/JunkChest_3.nbt,10,CHEST:4,../../../../Chests/Loot/JunkChest_4.nbt,10,CHEST:4,../../../../Chests/Loot/JunkChest_5.nbt,10,CHEST:4,../../../../Chests/Lore/Viking_1.nbt,1,CHEST:4,../../../../Chests/Lore/Viking_2.nbt,1,CHEST:4,../../../../Chests/Lore/Viking_3.nbt,1,CHEST:4,../../../../Chests/Lore/Viking_4.nbt,1,CHEST:4,../../../../Chests/Lore/Viking_5.nbt,1,CHEST:4,../../../../Chests/Loot/Common1.nbt,10,CHEST:4,../../../../Chests/Loot/Common2.nbt,10,CHEST:4,../../../../Chests/Loot/Common3.nbt,10,CHEST:4,../../../../Chests/Loot/Common4.nbt,10,CHEST:4,../../../../Chests/Loot/Common5.nbt,10,CHEST:4,../../../../Chests/Loot/Common6.nbt,10,CHEST:4,../../../../Chests/Loot/Common7.nbt,10,CHEST:4,../../../../Chests/Loot/Common8.nbt,10,CHEST:4,../../../../Chests/Loot/Common9.nbt,10,CHEST:4,../../../../Chests/Loot/Common10.nbt,10,CHEST:4,../../../../Chests/Loot/Common10.nbt,11,CHEST:4,../../../../Chests/Loot/Common12.nbt,10,CHEST:4,../../../../Chests/Loot/Common13.nbt,10,CHEST:4,../../../../Chests/Loot/Common14.nbt,10,CHEST:4,../../../../Chests/Loot/Common15.nbt,10,CHEST:4,../../../../Chests/Lore/Viking_1.nbt,2,CHEST:4,../../../../Chests/Lore/Viking_3.nbt,2,CHEST:4,../../../../Chests/Lore/Viking_4.nbt,2,CHEST:4,../../../../Chests/Lore/Viking_5.nbt,2,CHEST:4,../../../../Chests/Lore/Viking_5.nbt,2,CHEST:4,../../../../Chests/Loot/Rare1.nbt,5,CHEST:4,../../../../Chests/Loot/Rare2.nbt,5,CHEST:4,../../../../Chests/Loot/Rare3.nbt,5,CHEST:4,../../../../Chests/Loot/Rare4.nbt,5,CHEST:4,../../../../Chests/Loot/Rare5.nbt,5,CHEST:4,../../../../Chests/Loot/Rare6.nbt,5,CHEST:4,../../../../Chests/Loot/Rare7.nbt,5,CHEST:4,../../../../Chests/Loot/Rare8.nbt,5,CHEST:4,../../../../Chests/Loot/Rare9.nbt,5,CHEST:4,../../../../Chests/Loot/Rare10.nbt,5,CHEST:4,../../../../Chests/Loot/Rare11.nbt,5,CHEST:4,../../../../Chests/Loot/Rare12.nbt,5,CHEST:4,../../../../Chests/Loot/Rare13.nbt,5,CHEST:4,../../../../Chests/Loot/Rare14.nbt,5,CHEST:4,../../../../Chests/Loot/Rare15.nbt,5,CHEST:4,../../../../Chests/Loot/Epic1.nbt,2,CHEST:4,../../../../Chests/Loot/Epic2.nbt,2,CHEST:4,../../../../Chests/Loot/Epic3.nbt,2,CHEST:4,../../../../Chests/Loot/Epic4.nbt,2,CHEST:4,../../../../Chests/Loot/Epic5.nbt,2,CHEST:4,../../../../Chests/Loot/Epic6.nbt,2,CHEST:4,../../../../Chests/Loot/Epic7.nbt,2,CHEST:4,../../../../Chests/Loot/Epic8.nbt,2,CHEST:4,../../../../Chests/Loot/Epic9.nbt,2,CHEST:4,../../../../Chests/Loot/Epic10.nbt,2,CHEST:4,../../../../Chests/Loot/Epic11.nbt,2,CHEST:4,../../../../Chests/Loot/Epic12.nbt,2,CHEST:4,../../../../Chests/Loot/Epic13.nbt,2,CHEST:4,../../../../Chests/Loot/Epic14.nbt,2,CHEST:4,../../../../Chests/Loot/Epic15.nbt,5,CHEST:4,../../../../Chests/Loot/Rare1.nbt,5,CHEST:4,../../../../Chests/Loot/Rare2.nbt,5,CHEST:4,../../../../Chests/Loot/Rare3.nbt,5,CHEST:4,../../../../Chests/Loot/Rare4.nbt,5,CHEST:4,../../../../Chests/Loot/Rare5.nbt,10,CHEST:4,../../../../Chests/Loot/Rare6.nbt,10,CHEST:4,../../../../Chests/Loot/Rare7.nbt,10,CHEST:4,../../../../Chests/Loot/Rare8.nbt,10,CHEST:4,../../../../Chests/Loot/Rare9.nbt,10,CHEST:4,../../../../Chests/Loot/Rare10.nbt,15,CHEST:4,../../../../Chests/Loot/Rare11.nbt,15,CHEST:4,../../../../Chests/Loot/Rare12.nbt,15,CHEST:4,../../../../Chests/Loot/Rare13.nbt,15,CHEST:4,../../../../Chests/Loot/Rare14.nbt,15,CHEST:4,../../../../Chests/Loot/Rare15.nbt,15,CHEST:4,../../../../Chests/Loot/Epic15.nbt,100)
Block(2,6,6,SPRUCE_WOOD_STAIRS:4)
RandomBlock(2,6,7,WALL_BANNER:3,../../NBT/Banners/viking_wealthy_1.nbt,20,WALL_BANNER:3,../../NBT/Banners/viking_wealthy_2.nbt,20,WALL_BANNER:3,../../NBT/Banners/viking_wealthy_3.nbt,20,WALL_BANNER:3,../../NBT/Banners/viking_wealthy_4.nbt,20,WALL_BANNER:3,../../NBT/Banners/viking_wealthy_5.nbt,20,WALL_BANNER:3,../../NBT/Banners/viking_wealthy_6.nbt,20,WALL_BANNER:3,../../NBT/Banners/viking_wealthy_7.nbt,20,WALL_BANNER:3,../../NBT/Banners/viking_wealthy_8.nbt,20,WALL_BANNER:3,../../NBT/Banners/viking_wealthy_9.nbt,100)
Block(2,7,1,SPRUCE_WOOD_STAIRS:1)
Block(2,7,2,SPRUCE_WOOD_STAIRS:1)
Block(2,7,3,SPRUCE_WOOD_STAIRS:1)
Block(2,7,4,SPRUCE_WOOD_STAIRS:1)
Block(2,7,5,SPRUCE_WOOD_STAIRS:1)
Block(2,7,6,SPRUCE_WOOD_STAIRS:1)
Block(2,7,7,SPRUCE_WOOD_STAIRS:1)
Block(2,7,8,SPRUCE_WOOD_STAIRS:1)
Block(3,0,2,COBBLESTONE:0)
Block(3,0,3,COBBLESTONE:0)
Block(3,0,4,COBBLESTONE:0)
Block(3,0,5,COBBLESTONE:0)
Block(3,0,6,COBBLESTONE:0)
Block(3,0,7,COBBLESTONE:0)
Block(3,0,8,COBBLESTONE:0)
Block(3,1,2,COBBLESTONE:0)
Block(3,1,3,COBBLESTONE:0)
Block(3,1,4,COBBLESTONE:0)
Block(3,1,5,COBBLESTONE:0)
Block(3,1,6,COBBLESTONE:0)
Block(3,1,7,COBBLESTONE:0)
Block(3,1,8,COBBLESTONE:0)
Block(3,2,2,COBBLESTONE:0)
Block(3,2,3,COBBLESTONE:0)
Block(3,2,4,COBBLESTONE:0)
Block(3,2,5,COBBLESTONE:0)
Block(3,2,6,COBBLESTONE:0)
Block(3,2,7,COBBLESTONE:0)
Block(3,2,8,COBBLESTONE:0)
Block(3,3,2,WOOD:1)
Block(3,3,3,WOOD_STEP:13)
Block(3,3,4,WOOD_STEP:13)
Block(3,3,5,DARK_OAK_STAIRS:6)
Block(3,3,6,WOOD:1)
Block(3,3,7,CAULDRON:0)
Block(3,4,2,WOOD:1)
Block(3,4,3,FLOWER_POT:0)
RandomBlock(3,4,4,WALL_BANNER:4,../../NBT/Banners/viking_regular_1.nbt,20,WALL_BANNER:4,../../NBT/Banners/viking_regular_2.nbt,20,WALL_BANNER:4,../../NBT/Banners/viking_regular_3.nbt,20,WALL_BANNER:4,../../NBT/Banners/viking_regular_4.nbt,20,WALL_BANNER:4,../../NBT/Banners/viking_regular_5.nbt,20,WALL_BANNER:4,../../NBT/Banners/viking_regular_6.nbt,20,WALL_BANNER:4,../../NBT/Banners/viking_regular_7.nbt,20,WALL_BANNER:4,../../NBT/Banners/viking_regular_8.nbt,100)
Block(3,4,5,FLOWER_POT:0)
Block(3,4,6,WOOD:1)
Block(3,4,7,TRAP_DOOR:2)
Block(3,5,1,SPRUCE_WOOD_STAIRS:4)
Block(3,5,2,DARK_OAK_FENCE:0)
Block(3,5,3,WOOD_STEP:9)
Block(3,5,4,WOOD_STEP:9)
Block(3,5,5,WOOD_STEP:9)
Block(3,5,6,WOOD:1)
RandomBlock(3,5,7,WALL_BANNER:3,../../NBT/Banners/viking_wealthy_1.nbt,20,WALL_BANNER:3,../../NBT/Banners/viking_wealthy_2.nbt,20,WALL_BANNER:3,../../NBT/Banners/viking_wealthy_3.nbt,20,WALL_BANNER:3,../../NBT/Banners/viking_wealthy_4.nbt,20,WALL_BANNER:3,../../NBT/Banners/viking_wealthy_5.nbt,20,WALL_BANNER:3,../../NBT/Banners/viking_wealthy_6.nbt,20,WALL_BANNER:3,../../NBT/Banners/viking_wealthy_7.nbt,20,WALL_BANNER:3,../../NBT/Banners/viking_wealthy_8.nbt,20,WALL_BANNER:3,../../NBT/Banners/viking_wealthy_9.nbt,100)
RandomBlock(3,5,8,WALL_BANNER:4,../../NBT/Banners/viking_regular_1.nbt,20,WALL_BANNER:4,../../NBT/Banners/viking_regular_2.nbt,20,WALL_BANNER:4,../../NBT/Banners/viking_regular_3.nbt,20,WALL_BANNER:4,../../NBT/Banners/viking_regular_4.nbt,20,WALL_BANNER:4,../../NBT/Banners/viking_regular_5.nbt,20,WALL_BANNER:4,../../NBT/Banners/viking_regular_6.nbt,20,WALL_BANNER:4,../../NBT/Banners/viking_regular_7.nbt,20,WALL_BANNER:4,../../NBT/Banners/viking_regular_8.nbt,100)
Block(3,6,1,SPRUCE_WOOD_STAIRS:1)
Block(3,6,2,SPRUCE_WOOD_STAIRS:1)
Block(3,6,3,SPRUCE_WOOD_STAIRS:1)
Block(3,6,4,SPRUCE_WOOD_STAIRS:1)
Block(3,6,5,SPRUCE_WOOD_STAIRS:1)
Block(3,6,6,SPRUCE_WOOD_STAIRS:1)
Block(3,6,7,SPRUCE_WOOD_STAIRS:1)
Block(3,6,8,SPRUCE_WOOD_STAIRS:1)
Block(4,0,2,LOG:1)
Block(4,0,3,COBBLESTONE:0)
Block(4,0,4,COBBLESTONE:0)
Block(4,0,5,COBBLESTONE:0)
Block(4,0,6,COBBLESTONE:0)
Block(4,0,7,COBBLESTONE:0)
Block(4,0,8,COBBLESTONE:0)
Block(4,1,2,LOG:1)
Block(4,1,3,COBBLESTONE:0)
Block(4,1,4,COBBLESTONE:0)
Block(4,1,5,COBBLESTONE:0)
Block(4,1,6,COBBLESTONE:0)
Block(4,1,7,COBBLESTONE:0)
Block(4,1,8,COBBLESTONE:0)
Block(4,2,2,LOG:1)
Block(4,2,3,COBBLESTONE:0)
Block(4,2,4,COBBLESTONE:0)
Block(4,2,5,COBBLESTONE:0)
Block(4,2,6,COBBLESTONE:0)
Block(4,2,7,COBBLESTONE:0)
Block(4,2,8,COBBLESTONE:0)
Block(4,3,2,LOG:1)
Block(4,3,3,WOOD:1)
Block(4,3,4,WOOD:1)
Block(4,3,5,WOOD:1)
Block(4,3,6,WOOD:1)
Block(4,3,7,WOOD:1)
Block(4,3,8,WOOD:1)
Block(4,4,1,SPRUCE_WOOD_STAIRS:4)
Block(4,4,2,LOG:1)
Block(4,4,3,DARK_OAK_FENCE:0)
Block(4,4,4,DARK_OAK_FENCE:0)
Block(4,4,5,DARK_OAK_FENCE:0)
Block(4,4,6,DARK_OAK_FENCE:0)
Block(4,4,7,DARK_OAK_FENCE:0)
Block(4,4,8,DARK_OAK_FENCE:0)
Block(4,5,1,SPRUCE_WOOD_STAIRS:1)
Block(4,5,2,SPRUCE_WOOD_STAIRS:1)
Block(4,5,3,SPRUCE_WOOD_STAIRS:1)
Block(4,5,4,SPRUCE_WOOD_STAIRS:1)
Block(4,5,5,SPRUCE_WOOD_STAIRS:1)
Block(4,5,6,SPRUCE_WOOD_STAIRS:1)
Block(4,5,7,SPRUCE_WOOD_STAIRS:1)
Block(4,5,8,SPRUCE_WOOD_STAIRS:1)
Block(5,4,1,SPRUCE_WOOD_STAIRS:1)
Block(5,4,2,SPRUCE_WOOD_STAIRS:1)
Block(5,4,3,SPRUCE_WOOD_STAIRS:1)
Block(5,4,4,SPRUCE_WOOD_STAIRS:1)
Block(5,4,5,SPRUCE_WOOD_STAIRS:1)
Block(5,4,6,SPRUCE_WOOD_STAIRS:1)
Block(5,4,7,SPRUCE_WOOD_STAIRS:1)
Block(5,4,8,SPRUCE_WOOD_STAIRS:1)
Branch(0,0,16,true,viking_brewery_peacefullC0R1,NORTH,100.0,0)
Entity(1,3,5,minecraft:villager,1)
