Author: NLBlackEagle
Description: No description given
SettingsMode: WriteDisable
Frequency: 0
SpawnHeight: highestBlock
UseCenterForHighestBlock: true
MinHeight: 0
MaxHeight: 255
InheritBO3: 
InheritBO3Rotation: NORTH
OverrideChildSettings: true
OverrideParentHeight: false
CanOverride: true
BranchFrequency: 0
BranchFrequencyGroup: 
MustBeBelowOther: false
MustBeInside: 
CannotBeInside: 
ReplacesBO3: 
MustBeInsideWorldBorders: false
CanSpawnOnWater: true
SpawnOnWaterOnly: false
SpawnUnderWater: false
SpawnAtWaterLevel: false
HeightOffset: 0
RemoveAir: false
ReplaceAbove: 
ReplaceBelow: 
ReplaceWithBiomeBlocks: true
ReplaceWithSurfaceBlock: GRASS
ReplaceWithGroundBlock: DIRT
ReplaceWithStoneBlock: STONE
SmoothRadius: 0
SmoothHeightOffset: 0
SmoothStartTop: false
SmoothStartWood: false
SmoothingSurfaceBlock: 
SmoothingGroundBlock: 
BO3Group: 
IsSpawnPoint: false
DoReplaceBlocks: true
Block(-8,1,-5,LOG:1)
Block(-8,1,6,LOG:1)
Block(-8,2,-5,LOG:1)
Block(-8,2,6,LOG:1)
Block(-8,3,-5,LOG:1)
Block(-8,3,6,LOG:1)
Block(-8,4,-7,LOG:5)
Block(-8,4,-6,WOOD_STEP:13)
Block(-8,4,-5,LOG:1)
Block(-8,4,-4,WOOD_STEP:13)
Block(-8,4,-3,WOOD_STEP:13)
Block(-8,4,-2,WOOD_STEP:13)
Block(-8,4,-1,WOOD:1)
Block(-8,4,0,DARK_OAK_STAIRS:0)
Block(-8,4,1,DARK_OAK_STAIRS:0)
Block(-8,4,2,WOOD:1)
Block(-8,4,3,WOOD_STEP:13)
Block(-8,4,4,WOOD_STEP:13)
Block(-8,4,5,WOOD_STEP:13)
Block(-8,4,6,LOG:1)
Block(-8,4,7,WOOD_STEP:13)
Block(-8,4,8,LOG:5)
Block(-8,5,-7,SPRUCE_FENCE:0)
Block(-8,5,-5,LOG:1)
Block(-8,5,-4,SPRUCE_FENCE:0)
Block(-8,5,-2,SPRUCE_FENCE:0)
Block(-8,5,-1,SPRUCE_FENCE:0)
Block(-8,5,2,SPRUCE_FENCE:0)
Block(-8,5,3,SPRUCE_FENCE:0)
Block(-8,5,5,SPRUCE_FENCE:0)
Block(-8,5,6,LOG:1)
Block(-8,5,8,SPRUCE_FENCE:0)
Block(-8,6,-5,LOG:1)
Block(-8,6,-4,SPRUCE_FENCE:0)
Block(-8,6,-2,SPRUCE_FENCE:0)
Block(-8,6,-1,SPRUCE_FENCE:0)
Block(-8,6,2,SPRUCE_FENCE:0)
Block(-8,6,3,SPRUCE_FENCE:0)
Block(-8,6,5,SPRUCE_FENCE:0)
Block(-8,6,6,LOG:1)
Block(-8,7,-5,LOG:1)
Block(-8,7,-4,SPRUCE_FENCE:0)
Block(-8,7,-3,SPRUCE_FENCE:0)
Block(-8,7,-2,SPRUCE_FENCE:0)
Block(-8,7,-1,SPRUCE_FENCE:0)
Block(-8,7,2,SPRUCE_FENCE:0)
Block(-8,7,3,SPRUCE_FENCE:0)
Block(-8,7,4,SPRUCE_FENCE:0)
Block(-8,7,5,SPRUCE_FENCE:0)
Block(-8,7,6,LOG:1)
Block(-8,8,-6,DARK_OAK_STAIRS:2)
Block(-8,8,-5,WOOD:1)
Block(-8,8,-4,WOOD:1)
Block(-8,8,-3,WOOD:1)
Block(-8,8,-2,WOOD:1)
Block(-8,8,-1,WOOD:1)
Block(-8,8,0,WOOD_STEP:13)
Block(-8,8,1,WOOD_STEP:13)
Block(-8,8,2,WOOD:1)
Block(-8,8,3,WOOD:1)
Block(-8,8,4,WOOD:1)
Block(-8,8,5,WOOD:1)
Block(-8,8,6,WOOD:1)
Block(-8,8,7,DARK_OAK_STAIRS:3)
Block(-8,9,-5,DARK_OAK_STAIRS:2)
Block(-8,9,-4,DARK_OAK_STAIRS:0)
Block(-8,9,-3,DARK_OAK_STAIRS:2)
Block(-8,9,-2,WOOD:1)
Block(-8,9,-1,WOOD:1)
Block(-8,9,0,STAINED_GLASS_PANE:15)
Block(-8,9,1,STAINED_GLASS_PANE:15)
Block(-8,9,2,WOOD:1)
Block(-8,9,3,WOOD:1)
Block(-8,9,4,DARK_OAK_STAIRS:0)
Block(-8,9,5,DARK_OAK_STAIRS:0)
Block(-8,9,6,DARK_OAK_STAIRS:3)
Block(-8,10,-2,SPRUCE_WOOD_STAIRS:2)
Block(-8,10,-1,WOOD:1)
Block(-8,10,0,STAINED_GLASS_PANE:15)
Block(-8,10,1,STAINED_GLASS_PANE:15)
Block(-8,10,2,WOOD:1)
Block(-8,10,3,SPRUCE_WOOD_STAIRS:3)
Block(-8,11,-1,SPRUCE_WOOD_STAIRS:2)
Block(-8,11,0,WOOD:1)
Block(-8,11,1,WOOD:1)
Block(-8,11,2,SPRUCE_WOOD_STAIRS:3)
Block(-8,12,0,SPRUCE_WOOD_STAIRS:2)
Block(-8,12,1,SPRUCE_WOOD_STAIRS:3)
Block(-7,4,-7,LOG:5)
Block(-7,4,-6,WOOD_STEP:13)
Block(-7,4,-5,WOOD_STEP:13)
Block(-7,4,-4,WOOD_STEP:13)
Block(-7,4,-3,WOOD_STEP:13)
Block(-7,4,-2,WOOD_STEP:13)
Block(-7,4,-1,WOOD:1)
Block(-7,4,0,WOOD_STEP:13)
Block(-7,4,1,WOOD_STEP:13)
Block(-7,4,2,WOOD:1)
Block(-7,4,3,WOOD_STEP:13)
Block(-7,4,4,WOOD_STEP:13)
Block(-7,4,5,WOOD_STEP:13)
Block(-7,4,6,WOOD_STEP:13)
Block(-7,4,7,WOOD_STEP:13)
Block(-7,4,8,LOG:5)
Block(-7,5,-7,SPRUCE_FENCE:0)
Block(-7,5,-5,SPRUCE_FENCE:0)
Block(-7,5,2,AIR:0)
Block(-7,5,6,SPRUCE_FENCE:0)
Block(-7,5,8,SPRUCE_FENCE:0)
Block(-7,6,-5,SPRUCE_FENCE:0)
Block(-7,6,6,SPRUCE_FENCE:0)
Block(-7,7,-5,SPRUCE_FENCE:0)
Block(-7,7,6,SPRUCE_FENCE:0)
Block(-7,8,-6,DARK_OAK_STAIRS:2)
Block(-7,8,-5,WOOD:1)
Block(-7,8,-4,WOOD_STEP:13)
Block(-7,8,-3,WOOD_STEP:13)
Block(-7,8,-2,WOOD_STEP:13)
Block(-7,8,-1,WOOD:1)
Block(-7,8,0,WOOD_STEP:13)
Block(-7,8,1,WOOD_STEP:13)
Block(-7,8,2,WOOD:1)
Block(-7,8,3,WOOD_STEP:13)
Block(-7,8,4,WOOD_STEP:13)
Block(-7,8,5,WOOD_STEP:13)
Block(-7,8,6,WOOD:1)
Block(-7,8,7,DARK_OAK_STAIRS:3)
Block(-7,9,-5,DARK_OAK_STAIRS:2)
Block(-7,9,-4,WOOD:1)
Block(-7,9,-3,WOOD:1)
Block(-7,9,-2,WOOD:1)
Block(-7,9,-1,WOOD:1)
RandomBlock(-7,9,0,FURNACE:5,../../../../Chests/Loot/furnace_W-Mineshafts_01.nbt,1,FURNACE:5,../../../../Chests/Loot/furnace_W-Mineshafts_02.nbt,1,FURNACE:5,../../../../Chests/Loot/furnace_W-Mineshafts_03.nbt,1,CRAFTING_TABLE:0,1,ANVIL:3,1,ANVIL:7,1,ANVIL:11,1,ANVIL:2,1,ANVIL:6,1,ANVIL:10,1,TNT:0,1,WEB:0,2,AIR:0,30,CHEST:5,../../../../Chests/Loot/abandoned_mineshaft.nbt,10,CHEST:5,../../../../Chests/Lore/Generic_5.nbt,2,CHEST:5,../../../../Chests/Lore/Generic_4.nbt,2,CHEST:5,../../../../Chests/Lore/Generic_3.nbt,2,CHEST:5,../../../../Chests/Lore/Generic_2.nbt,2,CHEST:5,../../../../Chests/Lore/Generic_1.nbt,2,CHEST:5,../../../../Chests/Lore/HiddenMineWaste_1.nbt,1,CHEST:5,../../../../Chests/Lore/HiddenMineWaste_2.nbt,1,CHEST:5,../../../../Chests/Lore/HiddenMineWaste_3.nbt,1,CHEST:5,../../../../Chests/Lore/HiddenMineWaste_4.nbt,1,CHEST:5,../../../../Chests/Lore/HiddenMineWaste_5.nbt,1,CHEST:5,../../../../Chests/Loot/abandoned_mineshaft.nbt,100)
RandomBlock(-7,9,1,FURNACE:5,../../../../Chests/Loot/furnace_W-Mineshafts_01.nbt,1,FURNACE:5,../../../../Chests/Loot/furnace_W-Mineshafts_02.nbt,1,FURNACE:5,../../../../Chests/Loot/furnace_W-Mineshafts_03.nbt,1,CRAFTING_TABLE:0,1,ANVIL:3,1,ANVIL:7,1,ANVIL:11,1,ANVIL:2,1,ANVIL:6,1,ANVIL:10,1,TNT:0,1,WEB:0,2,AIR:0,30,CHEST:5,../../../../Chests/Loot/abandoned_mineshaft.nbt,10,CHEST:5,../../../../Chests/Lore/Generic_5.nbt,2,CHEST:5,../../../../Chests/Lore/Generic_4.nbt,2,CHEST:5,../../../../Chests/Lore/Generic_3.nbt,2,CHEST:5,../../../../Chests/Lore/Generic_2.nbt,2,CHEST:5,../../../../Chests/Lore/Generic_1.nbt,2,CHEST:5,../../../../Chests/Lore/HiddenMineWaste_1.nbt,1,CHEST:5,../../../../Chests/Lore/HiddenMineWaste_2.nbt,1,CHEST:5,../../../../Chests/Lore/HiddenMineWaste_3.nbt,1,CHEST:5,../../../../Chests/Lore/HiddenMineWaste_4.nbt,1,CHEST:5,../../../../Chests/Lore/HiddenMineWaste_5.nbt,1,CHEST:5,../../../../Chests/Loot/abandoned_mineshaft.nbt,100)
Block(-7,9,2,WOOD:1)
Block(-7,9,3,WOOD:1)
Block(-7,9,4,WOOD:1)
Block(-7,9,5,WOOD:1)
Block(-7,9,6,DARK_OAK_STAIRS:3)
Block(-7,10,-4,SPRUCE_WOOD_STAIRS:0)
Block(-7,10,-3,SPRUCE_WOOD_STAIRS:0)
Block(-7,10,-2,SPRUCE_WOOD_STAIRS:2)
Block(-7,10,-1,WOOD:1)
Block(-7,10,2,WOOD:1)
Block(-7,10,3,SPRUCE_WOOD_STAIRS:0)
Block(-7,10,4,SPRUCE_WOOD_STAIRS:0)
Block(-7,10,5,SPRUCE_WOOD_STAIRS:3)
Block(-7,11,-1,SPRUCE_WOOD_STAIRS:2)
Block(-7,11,0,WOOD:1)
Block(-7,11,1,WOOD:1)
Block(-7,11,2,SPRUCE_WOOD_STAIRS:3)
Block(-7,12,0,SPRUCE_WOOD_STAIRS:2)
Block(-7,12,1,SPRUCE_WOOD_STAIRS:3)
Block(-6,0,-1,SPRUCE_FENCE:0)
Block(-6,0,0,SPRUCE_FENCE:0)
Block(-6,0,1,SPRUCE_FENCE:0)
Block(-6,0,2,SPRUCE_FENCE:0)
Block(-6,1,-4,LOG:1)
Block(-6,1,-1,SPRUCE_FENCE:0)
Block(-6,1,0,SPRUCE_FENCE:0)
Block(-6,1,1,SPRUCE_FENCE:0)
Block(-6,1,2,SPRUCE_FENCE:0)
Block(-6,1,5,LOG:1)
Block(-6,2,-4,LOG:1)
Block(-6,2,-1,SPRUCE_FENCE:0)
Block(-6,2,0,SPRUCE_FENCE:0)
Block(-6,2,1,SPRUCE_FENCE:0)
Block(-6,2,2,SPRUCE_FENCE:0)
Block(-6,2,5,LOG:1)
Block(-6,3,-4,LOG:1)
Block(-6,3,-3,SPRUCE_FENCE:0)
Block(-6,3,-2,SPRUCE_FENCE:0)
Block(-6,3,-1,SPRUCE_FENCE:0)
Block(-6,3,0,SPRUCE_FENCE:0)
Block(-6,3,1,SPRUCE_FENCE:0)
Block(-6,3,2,SPRUCE_FENCE:0)
Block(-6,3,3,SPRUCE_FENCE:0)
Block(-6,3,4,SPRUCE_FENCE:0)
Block(-6,3,5,LOG:1)
Block(-6,4,-7,LOG:5)
Block(-6,4,-6,WOOD_STEP:13)
Block(-6,4,-5,WOOD_STEP:13)
Block(-6,4,-4,WOOD:1)
Block(-6,4,-3,WOOD:1)
Block(-6,4,-2,WOOD:1)
Block(-6,4,-1,WOOD:1)
Block(-6,4,0,WOOD:1)
Block(-6,4,1,WOOD:1)
Block(-6,4,2,WOOD:1)
Block(-6,4,3,WOOD:1)
Block(-6,4,4,WOOD:1)
Block(-6,4,5,WOOD:1)
Block(-6,4,6,WOOD_STEP:13)
Block(-6,4,7,WOOD_STEP:13)
Block(-6,4,8,LOG:5)
Block(-6,5,-7,SPRUCE_FENCE:0)
Block(-6,5,-5,SPRUCE_FENCE:0)
Block(-6,5,-4,AIR:0)
Block(-6,5,6,SPRUCE_FENCE:0)
Block(-6,5,8,SPRUCE_FENCE:0)
Block(-6,6,-5,SPRUCE_FENCE:0)
Block(-6,6,6,SPRUCE_FENCE:0)
Block(-6,7,-5,SPRUCE_FENCE:0)
Block(-6,7,6,SPRUCE_FENCE:0)
Block(-6,8,-6,DARK_OAK_STAIRS:2)
Block(-6,8,-5,WOOD:1)
Block(-6,8,-4,WOOD_STEP:13)
Block(-6,8,-3,WOOD_STEP:13)
Block(-6,8,-2,WOOD_STEP:13)
Block(-6,8,-1,WOOD:1)
Block(-6,8,0,WOOD_STEP:13)
Block(-6,8,1,WOOD_STEP:13)
Block(-6,8,2,WOOD:1)
Block(-6,8,3,WOOD_STEP:13)
Block(-6,8,4,WOOD_STEP:13)
Block(-6,8,5,WOOD_STEP:13)
Block(-6,8,6,WOOD:1)
Block(-6,8,7,DARK_OAK_STAIRS:3)
Block(-6,9,-5,DARK_OAK_STAIRS:2)
Block(-6,9,-4,WOOD:1)
Block(-6,9,-3,BOOKSHELF:0)
Block(-6,9,-2,BOOKSHELF:0)
Block(-6,9,-1,BOOKSHELF:0)
Block(-6,9,2,BOOKSHELF:0)
Block(-6,9,3,BOOKSHELF:0)
Block(-6,9,4,BOOKSHELF:0)
Block(-6,9,5,WOOD:1)
Block(-6,9,6,DARK_OAK_STAIRS:3)
Block(-6,10,-4,SPRUCE_WOOD_STAIRS:2)
Block(-6,10,-3,BOOKSHELF:0)
Block(-6,10,-2,BOOKSHELF:0)
Block(-6,10,-1,BOOKSHELF:0)
Block(-6,10,2,BOOKSHELF:0)
Block(-6,10,3,BOOKSHELF:0)
Block(-6,10,4,BOOKSHELF:0)
Block(-6,10,5,SPRUCE_WOOD_STAIRS:3)
Block(-6,11,-3,SPRUCE_WOOD_STAIRS:2)
Block(-6,11,-2,SPRUCE_WOOD_STAIRS:0)
Block(-6,11,-1,SPRUCE_WOOD_STAIRS:2)
Block(-6,11,0,WOOD:1)
Block(-6,11,1,WOOD:1)
Block(-6,11,2,SPRUCE_WOOD_STAIRS:0)
Block(-6,11,3,SPRUCE_WOOD_STAIRS:0)
Block(-6,11,4,SPRUCE_WOOD_STAIRS:3)
Block(-6,12,0,SPRUCE_WOOD_STAIRS:2)
Block(-6,12,1,SPRUCE_WOOD_STAIRS:3)
Block(-5,0,-3,SPRUCE_FENCE:0)
Block(-5,0,-2,SPRUCE_FENCE:0)
Block(-5,0,-1,SPRUCE_FENCE:0)
Block(-5,0,0,LADDER:4)
Block(-5,0,1,LADDER:4)
Block(-5,0,2,SPRUCE_FENCE:0)
Block(-5,0,3,SPRUCE_FENCE:0)
Block(-5,0,4,SPRUCE_FENCE:0)
Block(-5,1,-3,SPRUCE_FENCE:0)
Block(-5,1,-2,SPRUCE_FENCE:0)
Block(-5,1,-1,SPRUCE_FENCE:0)
Block(-5,1,0,LADDER:4)
Block(-5,1,1,LADDER:4)
Block(-5,1,2,SPRUCE_FENCE:0)
Block(-5,1,3,SPRUCE_FENCE:0)
Block(-5,1,4,SPRUCE_FENCE:0)
Block(-5,2,-3,SPRUCE_FENCE:0)
Block(-5,2,-2,SPRUCE_FENCE:0)
Block(-5,2,-1,SPRUCE_FENCE:0)
Block(-5,2,0,LADDER:4)
Block(-5,2,1,LADDER:4)
Block(-5,2,2,SPRUCE_FENCE:0)
Block(-5,2,3,SPRUCE_FENCE:0)
Block(-5,2,4,SPRUCE_FENCE:0)
Block(-5,3,-4,SPRUCE_FENCE:0)
Block(-5,3,-3,SPRUCE_FENCE:0)
Block(-5,3,-2,SPRUCE_FENCE:0)
Block(-5,3,-1,SPRUCE_FENCE:0)
Block(-5,3,0,LADDER:4)
Block(-5,3,1,LADDER:4)
Block(-5,3,2,SPRUCE_FENCE:0)
Block(-5,3,3,SPRUCE_FENCE:0)
Block(-5,3,4,SPRUCE_FENCE:0)
Block(-5,3,5,SPRUCE_FENCE:0)
Block(-5,4,-7,LOG:5)
Block(-5,4,-6,WOOD_STEP:13)
Block(-5,4,-5,WOOD_STEP:13)
Block(-5,4,-4,WOOD:1)
Block(-5,4,-3,DARK_OAK_STAIRS:3)
Block(-5,4,-2,DARK_OAK_STAIRS:1)
Block(-5,4,-1,WOOD:1)
Block(-5,4,0,LADDER:4)
Block(-5,4,1,LADDER:4)
Block(-5,4,2,WOOD:1)
Block(-5,4,3,DARK_OAK_STAIRS:1)
Block(-5,4,4,DARK_OAK_STAIRS:1)
Block(-5,4,5,WOOD:1)
Block(-5,4,6,WOOD_STEP:13)
Block(-5,4,7,WOOD_STEP:13)
Block(-5,4,8,LOG:5)
Block(-5,5,-7,SPRUCE_FENCE:0)
Block(-5,5,-5,SPRUCE_FENCE:0)
Block(-5,5,0,LADDER:4)
Block(-5,5,1,LADDER:4)
Block(-5,5,6,SPRUCE_FENCE:0)
Block(-5,5,8,SPRUCE_FENCE:0)
Block(-5,6,-5,SPRUCE_FENCE:0)
Block(-5,6,6,SPRUCE_FENCE:0)
Block(-5,7,-1,DARK_OAK_STAIRS:4)
Block(-5,7,2,DARK_OAK_STAIRS:4)
Block(-5,7,6,SPRUCE_FENCE:0)
Block(-5,8,-7,DARK_OAK_STAIRS:7)
Block(-5,8,-6,DARK_OAK_STAIRS:2)
Block(-5,8,-5,WOOD:1)
Block(-5,8,-4,WOOD_STEP:13)
Block(-5,8,-3,WOOD_STEP:13)
Block(-5,8,-2,WOOD_STEP:13)
Block(-5,8,-1,WOOD:1)
Block(-5,8,0,WOOD_STEP:13)
Block(-5,8,1,WOOD_STEP:13)
Block(-5,8,2,WOOD:1)
Block(-5,8,3,WOOD_STEP:13)
Block(-5,8,4,WOOD_STEP:13)
Block(-5,8,5,WOOD_STEP:13)
Block(-5,8,6,WOOD:1)
Block(-5,8,7,DARK_OAK_STAIRS:3)
Block(-5,8,8,DARK_OAK_STAIRS:0)
Block(-5,9,-7,DARK_OAK_STAIRS:2)
Block(-5,9,-6,DARK_OAK_STAIRS:7)
Block(-5,9,-5,DARK_OAK_STAIRS:2)
Block(-5,9,-4,WOOD:1)
Block(-5,9,-3,BOOKSHELF:0)
Block(-5,9,-1,TRAP_DOOR:4)
Block(-5,9,0,BIRCH_WOOD_STAIRS:1)
Block(-5,9,1,TRAP_DOOR:5)
Block(-5,9,4,BOOKSHELF:0)
Block(-5,9,5,WOOD:1)
Block(-5,9,6,DARK_OAK_STAIRS:3)
Block(-5,9,7,DARK_OAK_STAIRS:6)
Block(-5,9,8,DARK_OAK_STAIRS:3)
Block(-5,10,-6,DARK_OAK_STAIRS:2)
Block(-5,10,-5,DARK_OAK_STAIRS:7)
Block(-5,10,-4,SPRUCE_WOOD_STAIRS:2)
Block(-5,10,-3,BOOKSHELF:0)
Block(-5,10,4,BOOKSHELF:0)
Block(-5,10,5,SPRUCE_WOOD_STAIRS:3)
Block(-5,10,6,DARK_OAK_STAIRS:6)
Block(-5,10,7,DARK_OAK_STAIRS:3)
Block(-5,11,-5,DARK_OAK_STAIRS:2)
Block(-5,11,-4,DARK_OAK_STAIRS:7)
Block(-5,11,-3,SPRUCE_WOOD_STAIRS:2)
Block(-5,11,-2,WOOD:1)
Block(-5,11,-1,WOOD:1)
Block(-5,11,0,WOOD:1)
Block(-5,11,1,WOOD:1)
Block(-5,11,2,WOOD:1)
Block(-5,11,3,WOOD:1)
Block(-5,11,4,SPRUCE_WOOD_STAIRS:3)
Block(-5,11,5,DARK_OAK_STAIRS:6)
Block(-5,11,6,DARK_OAK_STAIRS:3)
Block(-5,12,-4,DARK_OAK_STAIRS:2)
Block(-5,12,-3,DARK_OAK_STAIRS:7)
Block(-5,12,0,DARK_OAK_STAIRS:6)
Block(-5,12,1,DARK_OAK_STAIRS:7)
Block(-5,12,4,DARK_OAK_STAIRS:6)
Block(-5,12,5,DARK_OAK_STAIRS:3)
Block(-5,13,-3,DARK_OAK_STAIRS:2)
Block(-5,13,-2,DARK_OAK_STAIRS:7)
Block(-5,13,-1,DARK_OAK_STAIRS:6)
Block(-5,13,0,DARK_OAK_STAIRS:3)
Block(-5,13,1,DARK_OAK_STAIRS:2)
Block(-5,13,2,DARK_OAK_STAIRS:7)
Block(-5,13,3,DARK_OAK_STAIRS:6)
Block(-5,13,4,DARK_OAK_STAIRS:3)
Block(-5,14,-2,DARK_OAK_STAIRS:2)
Block(-5,14,-1,DARK_OAK_STAIRS:3)
Block(-5,14,2,DARK_OAK_STAIRS:2)
Block(-5,14,3,DARK_OAK_STAIRS:3)
Block(-4,0,-3,SPRUCE_FENCE:0)
Block(-4,0,-2,AIR:0)
Block(-4,0,-1,WOOD:1)
Block(-4,0,0,AIR:0)
Block(-4,0,1,AIR:0)
Block(-4,0,2,WOOD:1)
Block(-4,0,3,AIR:0)
Block(-4,0,4,SPRUCE_FENCE:0)
Block(-4,1,-7,LOG:1)
Block(-4,1,-3,SPRUCE_FENCE:0)
Block(-4,1,-2,AIR:0)
Block(-4,1,-1,WOOD:1)
Block(-4,1,0,AIR:0)
Block(-4,1,1,AIR:0)
Block(-4,1,2,WOOD:1)
Block(-4,1,3,AIR:0)
Block(-4,1,4,SPRUCE_FENCE:0)
Block(-4,1,8,LOG:1)
Block(-4,2,-7,LOG:1)
Block(-4,2,-3,SPRUCE_FENCE:0)
Block(-4,2,-2,AIR:0)
Block(-4,2,-1,WOOD:1)
Block(-4,2,0,WOOD:1)
Block(-4,2,1,WOOD:1)
Block(-4,2,2,WOOD:1)
Block(-4,2,3,AIR:0)
Block(-4,2,4,SPRUCE_FENCE:0)
Block(-4,2,8,LOG:1)
Block(-4,3,-7,LOG:1)
Block(-4,3,-4,SPRUCE_FENCE:0)
Block(-4,3,-3,SPRUCE_FENCE:0)
Block(-4,3,-2,AIR:0)
Block(-4,3,-1,WOOD:1)
Block(-4,3,0,WOOD:1)
Block(-4,3,1,WOOD:1)
Block(-4,3,2,WOOD:1)
Block(-4,3,3,AIR:0)
Block(-4,3,4,SPRUCE_FENCE:0)
Block(-4,3,5,SPRUCE_FENCE:0)
Block(-4,3,8,LOG:1)
Block(-4,4,-7,LOG:1)
Block(-4,4,-6,WOOD:1)
Block(-4,4,-5,WOOD:1)
Block(-4,4,-4,WOOD:1)
Block(-4,4,-3,DARK_OAK_STAIRS:3)
Block(-4,4,-2,AIR:0)
Block(-4,4,-1,WOOD:1)
Block(-4,4,0,WOOD:1)
Block(-4,4,1,WOOD:1)
Block(-4,4,2,WOOD:1)
Block(-4,4,3,AIR:0)
Block(-4,4,4,DARK_OAK_STAIRS:2)
Block(-4,4,5,WOOD:1)
Block(-4,4,6,WOOD:1)
Block(-4,4,7,WOOD:1)
Block(-4,4,8,LOG:1)
Block(-4,5,-7,LOG:1)
Block(-4,5,-6,SPRUCE_FENCE:0)
Block(-4,5,-5,SPRUCE_FENCE:0)
Block(-4,5,-4,AIR:0)
Block(-4,5,-3,AIR:0)
RandomBlock(-4,5,-2,TORCH:4,25,AIR:0,100)
Block(-4,5,-1,WOOD:1)
Block(-4,5,0,WOOD:1)
Block(-4,5,1,WOOD:1)
Block(-4,5,2,WOOD:1)
RandomBlock(-4,5,3,TORCH:3,25,AIR:0,100)
Block(-4,5,4,AIR:0)
Block(-4,5,5,AIR:0)
Block(-4,5,6,SPRUCE_FENCE:0)
Block(-4,5,7,SPRUCE_FENCE:0)
Block(-4,5,8,LOG:1)
Block(-4,6,-7,LOG:1)
Block(-4,6,-6,SPRUCE_FENCE:0)
Block(-4,6,-5,SPRUCE_FENCE:0)
Block(-4,6,-1,WOOD:1)
Block(-4,6,2,WOOD:1)
Block(-4,6,6,SPRUCE_FENCE:0)
Block(-4,6,7,SPRUCE_FENCE:0)
Block(-4,6,8,LOG:1)
Block(-4,7,-7,LOG:1)
Block(-4,7,-6,SPRUCE_FENCE:0)
Block(-4,7,-5,SPRUCE_FENCE:0)
Block(-4,7,-2,DARK_OAK_STAIRS:6)
Block(-4,7,-1,WOOD:1)
Block(-4,7,2,WOOD:1)
Block(-4,7,3,DARK_OAK_STAIRS:7)
Block(-4,7,6,SPRUCE_FENCE:0)
Block(-4,7,7,SPRUCE_FENCE:0)
Block(-4,7,8,LOG:1)
Block(-4,8,-7,LOG:1)
Block(-4,8,-6,WOOD:1)
Block(-4,8,-5,WOOD:1)
Block(-4,8,-4,WOOD:1)
Block(-4,8,-3,WOOD:1)
Block(-4,8,-2,WOOD:1)
Block(-4,8,-1,WOOD:1)
Block(-4,8,0,WOOD_STEP:13)
Block(-4,8,1,WOOD_STEP:13)
Block(-4,8,2,WOOD:1)
Block(-4,8,3,WOOD:1)
Block(-4,8,4,WOOD:1)
Block(-4,8,5,WOOD:1)
Block(-4,8,6,WOOD:1)
Block(-4,8,7,WOOD:1)
Block(-4,8,8,LOG:1)
Block(-4,9,-7,SPRUCE_WOOD_STAIRS:2)
Block(-4,9,-6,WOOD:1)
Block(-4,9,-5,WOOD:1)
Block(-4,9,-4,WOOD:1)
Block(-4,9,-3,BOOKSHELF:0)
Block(-4,9,-1,DARK_OAK_STAIRS:7)
Block(-4,9,0,WOOD_STEP:13)
Block(-4,9,1,WOOD_STEP:13)
Block(-4,9,2,DARK_OAK_STAIRS:6)
Block(-4,9,4,BOOKSHELF:0)
Block(-4,9,5,WOOD:1)
Block(-4,9,6,WOOD:1)
Block(-4,9,7,WOOD:1)
Block(-4,9,8,SPRUCE_WOOD_STAIRS:0)
Block(-4,10,-6,SPRUCE_WOOD_STAIRS:2)
Block(-4,10,-5,WOOD:1)
Block(-4,10,-4,WOOD:1)
Block(-4,10,-3,BOOKSHELF:0)
Block(-4,10,0,CARPET:0)
Block(-4,10,1,CARPET:0)
Block(-4,10,2,CARPET:0)
Block(-4,10,4,BOOKSHELF:0)
Block(-4,10,5,WOOD:1)
Block(-4,10,6,WOOD:1)
Block(-4,10,7,SPRUCE_WOOD_STAIRS:3)
Block(-4,11,-5,SPRUCE_WOOD_STAIRS:2)
Block(-4,11,-4,WOOD:1)
Block(-4,11,-3,WOOD:1)
Block(-4,11,-2,WOOD:1)
Block(-4,11,-1,WOOD:1)
Block(-4,11,0,WOOD:1)
Block(-4,11,1,WOOD:1)
Block(-4,11,2,WOOD:1)
Block(-4,11,3,WOOD:1)
Block(-4,11,4,WOOD:1)
Block(-4,11,5,WOOD:1)
Block(-4,11,6,SPRUCE_WOOD_STAIRS:3)
Block(-4,12,-4,DARK_OAK_STAIRS:2)
Block(-4,12,-3,SPRUCE_WOOD_STAIRS:7)
Block(-4,12,-2,SPRUCE_FENCE:0)
Block(-4,12,-1,SPRUCE_FENCE:0)
Block(-4,12,0,SPRUCE_FENCE:0)
Block(-4,12,1,SPRUCE_FENCE:0)
Block(-4,12,2,SPRUCE_FENCE:0)
Block(-4,12,3,SPRUCE_FENCE:0)
Block(-4,12,4,SPRUCE_WOOD_STAIRS:6)
Block(-4,12,5,DARK_OAK_STAIRS:3)
Block(-4,13,-3,SPRUCE_WOOD_STAIRS:2)
Block(-4,13,-2,SPRUCE_WOOD_STAIRS:7)
Block(-4,13,3,SPRUCE_WOOD_STAIRS:6)
Block(-4,13,4,SPRUCE_WOOD_STAIRS:3)
Block(-4,14,-2,SPRUCE_WOOD_STAIRS:2)
Block(-4,14,-1,SPRUCE_WOOD_STAIRS:7)
Block(-4,14,2,SPRUCE_WOOD_STAIRS:6)
Block(-4,14,3,SPRUCE_WOOD_STAIRS:3)
Block(-4,15,-1,SPRUCE_WOOD_STAIRS:2)
Block(-4,15,0,SPRUCE_WOOD_STAIRS:7)
Block(-4,15,1,SPRUCE_WOOD_STAIRS:6)
Block(-4,15,2,SPRUCE_WOOD_STAIRS:3)
Block(-4,16,0,SPRUCE_WOOD_STAIRS:2)
Block(-4,16,1,SPRUCE_WOOD_STAIRS:3)
Block(-4,17,0,DARK_OAK_STAIRS:2)
Block(-4,17,1,DARK_OAK_STAIRS:3)
Block(-3,0,-3,SPRUCE_FENCE:0)
Block(-3,0,-2,AIR:0)
Block(-3,0,-1,AIR:0)
Block(-3,0,0,AIR:0)
Block(-3,0,1,AIR:0)
Block(-3,0,2,AIR:0)
Block(-3,0,3,AIR:0)
Block(-3,0,4,SPRUCE_FENCE:0)
Block(-3,1,-3,SPRUCE_FENCE:0)
Block(-3,1,-2,AIR:0)
Block(-3,1,-1,AIR:0)
Block(-3,1,0,AIR:0)
Block(-3,1,1,AIR:0)
Block(-3,1,2,AIR:0)
Block(-3,1,3,AIR:0)
Block(-3,1,4,SPRUCE_FENCE:0)
Block(-3,2,-3,SPRUCE_FENCE:0)
Block(-3,2,-2,AIR:0)
Block(-3,2,-1,AIR:0)
Block(-3,2,0,AIR:0)
Block(-3,2,1,AIR:0)
Block(-3,2,2,AIR:0)
Block(-3,2,3,AIR:0)
Block(-3,2,4,SPRUCE_FENCE:0)
Block(-3,3,-4,SPRUCE_FENCE:0)
Block(-3,3,-3,SPRUCE_FENCE:0)
Block(-3,3,-2,AIR:0)
Block(-3,3,-1,AIR:0)
Block(-3,3,0,AIR:0)
Block(-3,3,1,AIR:0)
Block(-3,3,2,AIR:0)
Block(-3,3,3,AIR:0)
Block(-3,3,4,SPRUCE_FENCE:0)
Block(-3,3,5,SPRUCE_FENCE:0)
Block(-3,4,-7,LOG:5)
Block(-3,4,-6,WOOD_STEP:13)
Block(-3,4,-5,WOOD_STEP:13)
Block(-3,4,-4,WOOD:1)
Block(-3,4,-3,DARK_OAK_STAIRS:3)
Block(-3,4,-2,AIR:0)
Block(-3,4,-1,AIR:0)
Block(-3,4,0,AIR:0)
Block(-3,4,1,AIR:0)
Block(-3,4,2,AIR:0)
Block(-3,4,3,AIR:0)
Block(-3,4,4,DARK_OAK_STAIRS:2)
Block(-3,4,5,WOOD:1)
Block(-3,4,6,WOOD_STEP:13)
Block(-3,4,7,WOOD_STEP:13)
Block(-3,4,8,LOG:5)
Block(-3,5,-6,AIR:0)
Block(-3,5,-5,AIR:0)
Block(-3,5,-4,AIR:0)
Block(-3,5,-3,DARK_OAK_STAIRS:2)
Block(-3,5,-2,DARK_OAK_STAIRS:7)
Block(-3,5,-1,WOOD_STEP:13)
Block(-3,5,0,WOOD_STEP:13)
Block(-3,5,1,WOOD_STEP:13)
Block(-3,5,2,WOOD_STEP:13)
Block(-3,5,3,DARK_OAK_STAIRS:6)
Block(-3,5,4,DARK_OAK_STAIRS:0)
Block(-3,5,5,AIR:0)
Block(-3,5,6,AIR:0)
Block(-3,5,7,AIR:0)
Block(-3,7,-7,SPRUCE_WOOD_STAIRS:0)
Block(-3,7,8,SPRUCE_WOOD_STAIRS:2)
Block(-3,8,-7,SPRUCE_WOOD_STAIRS:7)
Block(-3,8,-6,WOOD_STEP:13)
Block(-3,8,-5,WOOD_STEP:13)
Block(-3,8,-4,WOOD_STEP:13)
Block(-3,8,-3,WOOD_STEP:13)
Block(-3,8,-2,WOOD_STEP:13)
Block(-3,8,-1,DARK_OAK_STAIRS:5)
Block(-3,8,0,WOOD_STEP:13)
Block(-3,8,1,WOOD_STEP:13)
Block(-3,8,2,DARK_OAK_STAIRS:5)
Block(-3,8,3,WOOD_STEP:13)
Block(-3,8,4,WOOD_STEP:13)
Block(-3,8,5,WOOD_STEP:13)
Block(-3,8,6,WOOD_STEP:13)
Block(-3,8,7,WOOD_STEP:13)
Block(-3,8,8,SPRUCE_WOOD_STAIRS:6)
Block(-3,9,-7,WOOD:1)
Block(-3,9,-6,WOOD:1)
Block(-3,9,-5,WOOD_STEP:13)
Block(-3,9,-4,DARK_OAK_STAIRS:6)
Block(-3,9,5,DARK_OAK_STAIRS:7)
Block(-3,9,6,WOOD_STEP:13)
Block(-3,9,7,WOOD:1)
Block(-3,9,8,WOOD:1)
Block(-3,10,-7,SPRUCE_WOOD_STAIRS:0)
Block(-3,10,-6,SPRUCE_WOOD_STAIRS:2)
RandomBlock(-3,10,-4,TORCH:5,25,AIR:0,100)
RandomBlock(-3,10,6,TORCH:5,25,AIR:0,100)
Block(-3,10,7,SPRUCE_WOOD_STAIRS:0)
Block(-3,10,8,SPRUCE_WOOD_STAIRS:0)
Block(-3,11,-5,SPRUCE_WOOD_STAIRS:2)
Block(-3,11,-4,WOOD:1)
Block(-3,11,-3,WOOD:1)
Block(-3,11,-2,WOOD:1)
Block(-3,11,-1,WOOD:1)
Block(-3,11,0,WOOD:1)
Block(-3,11,1,WOOD:1)
Block(-3,11,2,WOOD:1)
Block(-3,11,3,WOOD:1)
Block(-3,11,4,WOOD:1)
Block(-3,11,5,WOOD:1)
Block(-3,11,6,SPRUCE_WOOD_STAIRS:3)
Block(-3,12,-5,DARK_OAK_STAIRS:0)
Block(-3,12,-4,DARK_OAK_STAIRS:2)
Block(-3,12,-3,WOOD:1)
Block(-3,12,-2,WOOD:1)
Block(-3,12,-1,LOG:1)
Block(-3,12,0,STAINED_GLASS_PANE:15)
Block(-3,12,1,STAINED_GLASS_PANE:15)
Block(-3,12,2,LOG:1)
Block(-3,12,3,WOOD:1)
Block(-3,12,4,WOOD:1)
Block(-3,12,5,DARK_OAK_STAIRS:0)
Block(-3,12,6,DARK_OAK_STAIRS:0)
Block(-3,13,-3,SPRUCE_WOOD_STAIRS:2)
Block(-3,13,-2,WOOD:1)
Block(-3,13,-1,LOG:1)
Block(-3,13,0,STAINED_GLASS_PANE:15)
Block(-3,13,1,STAINED_GLASS_PANE:15)
Block(-3,13,2,LOG:1)
Block(-3,13,3,WOOD:1)
Block(-3,13,4,SPRUCE_WOOD_STAIRS:3)
Block(-3,14,-2,SPRUCE_WOOD_STAIRS:2)
Block(-3,14,-1,LOG:1)
Block(-3,14,0,STAINED_GLASS_PANE:15)
Block(-3,14,1,STAINED_GLASS_PANE:15)
Block(-3,14,2,LOG:1)
Block(-3,14,3,SPRUCE_WOOD_STAIRS:3)
Block(-3,15,-1,SPRUCE_WOOD_STAIRS:2)
Block(-3,15,0,WOOD:1)
Block(-3,15,1,WOOD:1)
Block(-3,15,2,SPRUCE_WOOD_STAIRS:3)
Block(-3,16,0,SPRUCE_WOOD_STAIRS:2)
Block(-3,16,1,SPRUCE_WOOD_STAIRS:3)
Block(-3,17,0,WOOD_STEP:5)
Block(-3,17,1,WOOD_STEP:5)
Block(-2,0,-3,WOOD:1)
Block(-2,0,-2,COBBLESTONE_STAIRS:7)
Block(-2,0,-1,AIR:0)
Block(-2,0,0,AIR:0)
Block(-2,0,1,AIR:0)
Block(-2,0,2,AIR:0)
Block(-2,0,3,COBBLESTONE_STAIRS:6)
Block(-2,0,4,WOOD:1)
Block(-2,1,-3,WOOD:1)
Block(-2,1,-2,COBBLESTONE_STAIRS:3)
Block(-2,1,-1,AIR:0)
Block(-2,1,0,AIR:0)
Block(-2,1,1,AIR:0)
Block(-2,1,2,AIR:0)
Block(-2,1,3,COBBLESTONE_STAIRS:2)
Block(-2,1,4,WOOD:1)
Block(-2,2,-3,WOOD:1)
Block(-2,2,-2,COBBLESTONE_STAIRS:7)
Block(-2,2,-1,AIR:0)
Block(-2,2,0,AIR:0)
Block(-2,2,1,AIR:0)
Block(-2,2,2,AIR:0)
Block(-2,2,3,COBBLESTONE_STAIRS:6)
Block(-2,2,4,WOOD:1)
Block(-2,3,-4,SPRUCE_FENCE:0)
Block(-2,3,-3,WOOD:1)
Block(-2,3,-2,COBBLESTONE_STAIRS:7)
Block(-2,3,-1,AIR:0)
Block(-2,3,0,AIR:0)
Block(-2,3,1,AIR:0)
Block(-2,3,2,AIR:0)
Block(-2,3,3,COBBLESTONE_STAIRS:6)
Block(-2,3,4,WOOD:1)
Block(-2,3,5,SPRUCE_FENCE:0)
Block(-2,4,-7,LOG:5)
Block(-2,4,-6,WOOD_STEP:13)
Block(-2,4,-5,WOOD_STEP:13)
Block(-2,4,-4,WOOD:1)
Block(-2,4,-3,WOOD:1)
Block(-2,4,-2,COBBLESTONE_STAIRS:3)
Block(-2,4,-1,AIR:0)
Block(-2,4,0,AIR:0)
Block(-2,4,1,AIR:0)
Block(-2,4,2,AIR:0)
Block(-2,4,3,COBBLESTONE_STAIRS:2)
Block(-2,4,4,WOOD:1)
Block(-2,4,5,WOOD:1)
Block(-2,4,6,WOOD_STEP:13)
Block(-2,4,7,WOOD_STEP:13)
Block(-2,4,8,LOG:5)
Block(-2,5,-7,LOG:1)
Block(-2,5,-6,AIR:0)
Block(-2,5,-5,AIR:0)
Block(-2,5,-4,AIR:0)
Block(-2,5,-3,AIR:0)
Block(-2,5,-2,AIR:0)
Block(-2,5,-1,AIR:0)
Block(-2,5,0,AIR:0)
Block(-2,5,1,AIR:0)
Block(-2,5,2,AIR:0)
Block(-2,5,3,AIR:0)
Block(-2,5,4,AIR:0)
Block(-2,5,5,AIR:0)
Block(-2,5,6,AIR:0)
Block(-2,5,7,AIR:0)
Block(-2,5,8,LOG:1)
Block(-2,6,-7,LOG:1)
Block(-2,6,8,LOG:1)
Block(-2,7,-7,LOG:1)
Block(-2,7,8,LOG:1)
Block(-2,8,-7,SPRUCE_WOOD_STAIRS:2)
Block(-2,8,-6,WOOD_STEP:13)
Block(-2,8,-5,WOOD_STEP:13)
Block(-2,8,-4,WOOD_STEP:13)
Block(-2,8,-3,WOOD_STEP:13)
Block(-2,8,-2,WOOD_STEP:13)
Block(-2,8,-1,WOOD_STEP:13)
Block(-2,8,0,WOOD_STEP:13)
Block(-2,8,1,WOOD_STEP:13)
Block(-2,8,2,WOOD_STEP:13)
Block(-2,8,3,WOOD_STEP:13)
Block(-2,8,4,WOOD_STEP:13)
Block(-2,8,5,WOOD_STEP:13)
Block(-2,8,6,WOOD_STEP:13)
Block(-2,8,7,WOOD_STEP:13)
Block(-2,8,8,SPRUCE_WOOD_STAIRS:3)
Block(-2,9,-1,DARK_OAK_STAIRS:0)
Block(-2,9,2,DARK_OAK_STAIRS:0)
Block(-2,11,-7,SPRUCE_WOOD_STAIRS:0)
Block(-2,11,-6,SPRUCE_WOOD_STAIRS:0)
Block(-2,11,-5,SPRUCE_WOOD_STAIRS:2)
Block(-2,11,-4,DARK_OAK_STAIRS:7)
Block(-2,11,0,WOOD_STEP:13)
Block(-2,11,1,WOOD_STEP:13)
Block(-2,11,5,DARK_OAK_STAIRS:6)
Block(-2,11,6,SPRUCE_WOOD_STAIRS:0)
Block(-2,11,7,SPRUCE_WOOD_STAIRS:0)
Block(-2,11,8,SPRUCE_WOOD_STAIRS:0)
Block(-2,12,-5,DARK_OAK_STAIRS:5)
Block(-2,12,-4,LOG:5)
Block(-2,12,-3,WOOD_STEP:13)
Block(-2,12,-2,WOOD_STEP:13)
Block(-2,12,-1,LOG:5)
Block(-2,12,2,LOG:5)
Block(-2,12,3,WOOD_STEP:13)
Block(-2,12,4,WOOD_STEP:13)
Block(-2,12,5,LOG:5)
Block(-2,12,6,DARK_OAK_STAIRS:5)
Block(-2,13,-5,DARK_OAK_STAIRS:4)
Block(-2,13,-4,SPRUCE_WOOD_STAIRS:0)
Block(-2,13,-3,SPRUCE_WOOD_STAIRS:0)
Block(-2,13,-2,WOOD:1)
Block(-2,13,-1,STAINED_GLASS_PANE:15)
Block(-2,13,2,STAINED_GLASS_PANE:15)
Block(-2,13,3,WOOD:1)
Block(-2,13,4,SPRUCE_WOOD_STAIRS:0)
Block(-2,13,5,SPRUCE_WOOD_STAIRS:0)
Block(-2,13,6,DARK_OAK_STAIRS:4)
Block(-2,14,-5,DARK_OAK_STAIRS:0)
Block(-2,14,-4,SPRUCE_WOOD_STAIRS:0)
Block(-2,14,-3,SPRUCE_WOOD_STAIRS:0)
Block(-2,14,-2,SPRUCE_WOOD_STAIRS:0)
Block(-2,14,-1,STAINED_GLASS_PANE:15)
Block(-2,14,2,STAINED_GLASS_PANE:15)
Block(-2,14,3,SPRUCE_WOOD_STAIRS:3)
Block(-2,14,4,SPRUCE_WOOD_STAIRS:0)
Block(-2,14,5,SPRUCE_WOOD_STAIRS:0)
Block(-2,14,6,DARK_OAK_STAIRS:0)
Block(-2,15,-5,DARK_OAK_STAIRS:0)
Block(-2,15,-4,SPRUCE_WOOD_STAIRS:0)
Block(-2,15,-3,SPRUCE_WOOD_STAIRS:0)
Block(-2,15,-2,SPRUCE_WOOD_STAIRS:0)
Block(-2,15,-1,SPRUCE_WOOD_STAIRS:0)
Block(-2,15,2,SPRUCE_WOOD_STAIRS:0)
Block(-2,15,3,SPRUCE_WOOD_STAIRS:0)
Block(-2,15,4,SPRUCE_WOOD_STAIRS:0)
Block(-2,15,5,DARK_OAK_STAIRS:0)
Block(-2,15,6,DARK_OAK_STAIRS:0)
Block(-2,16,0,SPRUCE_WOOD_STAIRS:2)
Block(-2,16,1,SPRUCE_WOOD_STAIRS:3)
Block(-2,17,0,WOOD_STEP:5)
Block(-2,17,1,WOOD_STEP:5)
Block(-1,0,-3,SPRUCE_FENCE:0)
Block(-1,0,-2,AIR:0)
Block(-1,0,-1,AIR:0)
Block(-1,0,0,AIR:0)
Block(-1,0,1,AIR:0)
Block(-1,0,2,AIR:0)
Block(-1,0,3,AIR:0)
Block(-1,0,4,SPRUCE_FENCE:0)
Block(-1,1,-3,SPRUCE_FENCE:0)
Block(-1,1,-2,AIR:0)
Block(-1,1,-1,AIR:0)
Block(-1,1,0,AIR:0)
Block(-1,1,1,AIR:0)
Block(-1,1,2,AIR:0)
Block(-1,1,3,AIR:0)
Block(-1,1,4,SPRUCE_FENCE:0)
Block(-1,2,-3,SPRUCE_FENCE:0)
Block(-1,2,-2,AIR:0)
Block(-1,2,-1,AIR:0)
Block(-1,2,0,AIR:0)
Block(-1,2,1,AIR:0)
Block(-1,2,2,AIR:0)
Block(-1,2,3,AIR:0)
Block(-1,2,4,SPRUCE_FENCE:0)
Block(-1,3,-4,SPRUCE_FENCE:0)
Block(-1,3,-3,WOOD:1)
Block(-1,3,-2,LADDER:3)
Block(-1,3,-1,AIR:0)
Block(-1,3,0,AIR:0)
Block(-1,3,1,AIR:0)
Block(-1,3,2,AIR:0)
Block(-1,3,3,LADDER:2)
Block(-1,3,4,WOOD:1)
Block(-1,3,5,SPRUCE_FENCE:0)
Block(-1,4,-7,LOG:5)
Block(-1,4,-6,WOOD_STEP:13)
Block(-1,4,-5,WOOD_STEP:13)
Block(-1,4,-4,WOOD:1)
Block(-1,4,-3,DARK_OAK_STAIRS:3)
Block(-1,4,-2,AIR:0)
Block(-1,4,-1,AIR:0)
Block(-1,4,0,AIR:0)
Block(-1,4,1,AIR:0)
Block(-1,4,2,AIR:0)
Block(-1,4,3,AIR:0)
Block(-1,4,4,DARK_OAK_STAIRS:2)
Block(-1,4,5,WOOD:1)
Block(-1,4,6,WOOD_STEP:13)
Block(-1,4,7,WOOD_STEP:13)
Block(-1,4,8,LOG:5)
Block(-1,5,-7,SPRUCE_WOOD_STAIRS:3)
Block(-1,5,-6,AIR:0)
Block(-1,5,-5,AIR:0)
Block(-1,5,-4,AIR:0)
Block(-1,5,-3,AIR:0)
Block(-1,5,-2,AIR:0)
Block(-1,5,-1,AIR:0)
Block(-1,5,0,AIR:0)
Block(-1,5,1,AIR:0)
Block(-1,5,2,AIR:0)
Block(-1,5,3,AIR:0)
Block(-1,5,4,AIR:0)
Block(-1,5,5,AIR:0)
Block(-1,5,6,AIR:0)
Block(-1,5,7,AIR:0)
Block(-1,5,8,SPRUCE_WOOD_STAIRS:2)
Block(-1,8,-6,WOOD_STEP:13)
Block(-1,8,-5,WOOD_STEP:13)
Block(-1,8,-4,WOOD_STEP:13)
Block(-1,8,-3,WOOD_STEP:13)
Block(-1,8,-2,WOOD_STEP:13)
Block(-1,8,0,WOOD_STEP:13)
Block(-1,8,1,WOOD_STEP:13)
Block(-1,8,3,WOOD_STEP:13)
Block(-1,8,4,WOOD_STEP:13)
Block(-1,8,5,WOOD_STEP:13)
Block(-1,8,6,WOOD_STEP:13)
Block(-1,8,7,WOOD_STEP:13)
Block(-1,9,-6,SPRUCE_FENCE:0)
Block(-1,9,-1,DARK_OAK_STAIRS:5)
Block(-1,9,2,DARK_OAK_STAIRS:5)
Block(-1,9,7,SPRUCE_FENCE:0)
Block(-1,10,-2,AIR:0)
Block(-1,10,-1,WOOD:1)
Block(-1,10,0,LADDER:3)
Block(-1,10,1,LADDER:2)
Block(-1,10,2,WOOD:1)
Block(-1,11,-1,WOOD:1)
Block(-1,11,0,LADDER:3)
Block(-1,11,1,LADDER:2)
Block(-1,11,2,WOOD:1)
Block(-1,12,-7,SPRUCE_WOOD_STAIRS:0)
Block(-1,12,-6,SPRUCE_WOOD_STAIRS:0)
Block(-1,12,-5,SPRUCE_WOOD_STAIRS:0)
Block(-1,12,-4,LOG:5)
Block(-1,12,-3,WOOD_STEP:13)
Block(-1,12,-2,WOOD_STEP:13)
Block(-1,12,-1,LOG:5)
Block(-1,12,0,LADDER:3)
Block(-1,12,1,LADDER:2)
Block(-1,12,2,LOG:5)
Block(-1,12,3,WOOD_STEP:13)
Block(-1,12,4,WOOD_STEP:13)
Block(-1,12,5,LOG:5)
Block(-1,12,6,SPRUCE_WOOD_STAIRS:0)
Block(-1,12,7,SPRUCE_WOOD_STAIRS:0)
Block(-1,12,8,SPRUCE_WOOD_STAIRS:0)
Block(-1,13,-1,STAINED_GLASS_PANE:15)
Block(-1,13,2,STAINED_GLASS_PANE:15)
Block(-1,14,-5,DARK_OAK_STAIRS:5)
Block(-1,14,-1,STAINED_GLASS_PANE:15)
Block(-1,14,2,STAINED_GLASS_PANE:15)
Block(-1,14,6,DARK_OAK_STAIRS:5)
Block(-1,15,-5,DARK_OAK_STAIRS:5)
Block(-1,15,-1,LOG:5)
Block(-1,15,2,LOG:5)
Block(-1,15,6,DARK_OAK_STAIRS:5)
Block(-1,16,-5,DARK_OAK_STAIRS:0)
Block(-1,16,-4,SPRUCE_WOOD_STAIRS:0)
Block(-1,16,-3,SPRUCE_WOOD_STAIRS:0)
Block(-1,16,-2,SPRUCE_WOOD_STAIRS:0)
Block(-1,16,-1,SPRUCE_WOOD_STAIRS:0)
Block(-1,16,0,SPRUCE_WOOD_STAIRS:0)
Block(-1,16,1,SPRUCE_WOOD_STAIRS:3)
Block(-1,16,2,SPRUCE_WOOD_STAIRS:0)
Block(-1,16,3,SPRUCE_WOOD_STAIRS:0)
Block(-1,16,4,SPRUCE_WOOD_STAIRS:0)
Block(-1,16,5,SPRUCE_WOOD_STAIRS:0)
Block(-1,16,6,DARK_OAK_STAIRS:0)
Block(-1,17,-5,DARK_OAK_STAIRS:0)
Block(-1,17,-4,WOOD_STEP:5)
Block(-1,17,-3,WOOD_STEP:5)
Block(-1,17,-2,WOOD_STEP:5)
Block(-1,17,-1,WOOD_STEP:5)
Block(-1,17,0,DARK_OAK_STAIRS:0)
Block(-1,17,1,DARK_OAK_STAIRS:0)
Block(-1,17,2,WOOD_STEP:5)
Block(-1,17,3,WOOD_STEP:5)
Block(-1,17,4,WOOD_STEP:5)
Block(-1,17,5,WOOD_STEP:5)
Block(-1,17,6,DARK_OAK_STAIRS:0)
Block(0,0,-3,SPRUCE_FENCE:0)
Block(0,0,-2,AIR:0)
Block(0,0,-1,AIR:0)
Block(0,0,0,AIR:0)
Block(0,0,1,AIR:0)
Block(0,0,2,AIR:0)
Block(0,0,3,AIR:0)
Block(0,0,4,SPRUCE_FENCE:0)
Block(0,1,-3,SPRUCE_FENCE:0)
Block(0,1,-2,AIR:0)
Block(0,1,-1,AIR:0)
Block(0,1,0,AIR:0)
Block(0,1,1,AIR:0)
Block(0,1,2,AIR:0)
Block(0,1,3,AIR:0)
Block(0,1,4,SPRUCE_FENCE:0)
Block(0,2,-3,SPRUCE_FENCE:0)
Block(0,2,-2,AIR:0)
Block(0,2,-1,AIR:0)
Block(0,2,0,AIR:0)
Block(0,2,1,AIR:0)
Block(0,2,2,AIR:0)
Block(0,2,3,AIR:0)
Block(0,2,4,SPRUCE_FENCE:0)
Block(0,3,-4,SPRUCE_FENCE:0)
Block(0,3,-3,WOOD:1)
Block(0,3,-2,LADDER:3)
Block(0,3,-1,AIR:0)
Block(0,3,0,AIR:0)
Block(0,3,1,AIR:0)
Block(0,3,2,AIR:0)
Block(0,3,3,LADDER:2)
Block(0,3,4,WOOD:1)
Block(0,3,5,SPRUCE_FENCE:0)
Block(0,4,-7,LOG:5)
Block(0,4,-6,WOOD_STEP:13)
Block(0,4,-5,WOOD_STEP:13)
Block(0,4,-4,WOOD:1)
Block(0,4,-3,DARK_OAK_STAIRS:3)
Block(0,4,-2,AIR:0)
Block(0,4,-1,AIR:0)
Block(0,4,0,AIR:0)
Block(0,4,1,AIR:0)
Block(0,4,2,AIR:0)
Block(0,4,3,AIR:0)
Block(0,4,4,DARK_OAK_STAIRS:2)
Block(0,4,5,WOOD:1)
Block(0,4,6,WOOD_STEP:13)
Block(0,4,7,WOOD_STEP:13)
Block(0,4,8,LOG:5)
Block(0,5,-7,SPRUCE_WOOD_STAIRS:3)
Block(0,5,-6,AIR:0)
Block(0,5,-5,AIR:0)
Block(0,5,-4,AIR:0)
Block(0,5,-3,AIR:0)
Block(0,5,-2,AIR:0)
Block(0,5,-1,AIR:0)
Block(0,5,0,AIR:0)
Block(0,5,1,AIR:0)
Block(0,5,2,AIR:0)
Block(0,5,3,AIR:0)
Block(0,5,4,AIR:0)
Block(0,5,5,AIR:0)
Block(0,5,6,AIR:0)
Block(0,5,7,AIR:0)
Block(0,5,8,SPRUCE_WOOD_STAIRS:2)
Block(0,8,-6,WOOD_STEP:13)
Block(0,8,-5,WOOD_STEP:13)
Block(0,8,-4,WOOD_STEP:13)
Block(0,8,-3,WOOD_STEP:13)
Block(0,8,-2,WOOD_STEP:13)
Block(0,8,0,WOOD_STEP:13)
Block(0,8,1,WOOD_STEP:13)
Block(0,8,3,WOOD_STEP:13)
Block(0,8,4,WOOD_STEP:13)
Block(0,8,5,WOOD_STEP:13)
Block(0,8,6,WOOD_STEP:13)
Block(0,8,7,WOOD_STEP:13)
Block(0,9,-6,SPRUCE_FENCE:0)
Block(0,9,-1,DARK_OAK_STAIRS:4)
Block(0,9,2,DARK_OAK_STAIRS:4)
Block(0,9,7,SPRUCE_FENCE:0)
Block(0,10,-1,WOOD:1)
Block(0,10,0,LADDER:3)
Block(0,10,1,LADDER:2)
Block(0,10,2,WOOD:1)
Block(0,11,-1,WOOD:1)
Block(0,11,0,LADDER:3)
Block(0,11,1,LADDER:2)
Block(0,11,2,WOOD:1)
Block(0,12,-7,SPRUCE_WOOD_STAIRS:1)
Block(0,12,-6,SPRUCE_WOOD_STAIRS:1)
Block(0,12,-5,SPRUCE_WOOD_STAIRS:1)
Block(0,12,-4,LOG:5)
Block(0,12,-3,WOOD_STEP:13)
Block(0,12,-2,WOOD_STEP:13)
Block(0,12,-1,LOG:5)
Block(0,12,0,LADDER:3)
Block(0,12,1,LADDER:2)
Block(0,12,2,LOG:5)
Block(0,12,3,WOOD_STEP:13)
Block(0,12,4,WOOD_STEP:13)
Block(0,12,5,LOG:5)
Block(0,12,6,SPRUCE_WOOD_STAIRS:1)
Block(0,12,7,SPRUCE_WOOD_STAIRS:1)
Block(0,12,8,SPRUCE_WOOD_STAIRS:1)
Block(0,13,-1,STAINED_GLASS_PANE:15)
Block(0,13,2,STAINED_GLASS_PANE:15)
Block(0,14,-5,DARK_OAK_STAIRS:4)
Block(0,14,-1,STAINED_GLASS_PANE:15)
Block(0,14,2,STAINED_GLASS_PANE:15)
Block(0,14,6,DARK_OAK_STAIRS:4)
Block(0,15,-5,DARK_OAK_STAIRS:4)
Block(0,15,-1,LOG:5)
Block(0,15,2,LOG:5)
Block(0,15,6,DARK_OAK_STAIRS:4)
Block(0,16,-5,DARK_OAK_STAIRS:1)
Block(0,16,-4,SPRUCE_WOOD_STAIRS:1)
Block(0,16,-3,SPRUCE_WOOD_STAIRS:1)
Block(0,16,-2,SPRUCE_WOOD_STAIRS:1)
Block(0,16,-1,SPRUCE_WOOD_STAIRS:1)
Block(0,16,0,SPRUCE_WOOD_STAIRS:2)
Block(0,16,1,SPRUCE_WOOD_STAIRS:1)
Block(0,16,2,SPRUCE_WOOD_STAIRS:1)
Block(0,16,3,SPRUCE_WOOD_STAIRS:1)
Block(0,16,4,SPRUCE_WOOD_STAIRS:1)
Block(0,16,5,SPRUCE_WOOD_STAIRS:1)
Block(0,16,6,DARK_OAK_STAIRS:1)
Block(0,17,-5,DARK_OAK_STAIRS:1)
Block(0,17,-4,WOOD_STEP:5)
Block(0,17,-3,WOOD_STEP:5)
Block(0,17,-2,WOOD_STEP:5)
Block(0,17,-1,WOOD_STEP:5)
Block(0,17,0,DARK_OAK_STAIRS:2)
Block(0,17,1,DARK_OAK_STAIRS:1)
Block(0,17,2,WOOD_STEP:5)
Block(0,17,3,WOOD_STEP:5)
Block(0,17,4,WOOD_STEP:5)
Block(0,17,5,WOOD_STEP:5)
Block(0,17,6,DARK_OAK_STAIRS:1)
Block(1,0,-3,WOOD:1)
Block(1,0,-2,COBBLESTONE_STAIRS:7)
Block(1,0,-1,AIR:0)
Block(1,0,0,AIR:0)
Block(1,0,1,AIR:0)
Block(1,0,2,AIR:0)
Block(1,0,3,COBBLESTONE_STAIRS:6)
Block(1,0,4,WOOD:1)
Block(1,1,-3,WOOD:1)
Block(1,1,-2,COBBLESTONE_STAIRS:3)
Block(1,1,-1,AIR:0)
Block(1,1,0,AIR:0)
Block(1,1,1,AIR:0)
Block(1,1,2,AIR:0)
Block(1,1,3,COBBLESTONE_STAIRS:2)
Block(1,1,4,WOOD:1)
Block(1,2,-3,WOOD:1)
Block(1,2,-2,COBBLESTONE_STAIRS:7)
Block(1,2,-1,AIR:0)
Block(1,2,0,AIR:0)
Block(1,2,1,AIR:0)
Block(1,2,2,AIR:0)
Block(1,2,3,COBBLESTONE_STAIRS:6)
Block(1,2,4,WOOD:1)
Block(1,3,-4,SPRUCE_FENCE:0)
Block(1,3,-3,WOOD:1)
Block(1,3,-2,COBBLESTONE_STAIRS:7)
Block(1,3,-1,AIR:0)
Block(1,3,0,AIR:0)
Block(1,3,1,AIR:0)
Block(1,3,2,AIR:0)
Block(1,3,3,COBBLESTONE_STAIRS:6)
Block(1,3,4,WOOD:1)
Block(1,3,5,SPRUCE_FENCE:0)
Block(1,4,-7,LOG:5)
Block(1,4,-6,WOOD_STEP:13)
Block(1,4,-5,WOOD_STEP:13)
Block(1,4,-4,WOOD:1)
Block(1,4,-3,WOOD:1)
Block(1,4,-2,COBBLESTONE_STAIRS:3)
Block(1,4,-1,AIR:0)
Block(1,4,0,AIR:0)
Block(1,4,1,AIR:0)
Block(1,4,2,AIR:0)
Block(1,4,3,COBBLESTONE_STAIRS:2)
Block(1,4,4,WOOD:1)
Block(1,4,5,WOOD:1)
Block(1,4,6,WOOD_STEP:13)
Block(1,4,7,WOOD_STEP:13)
Block(1,4,8,LOG:5)
Block(1,5,-7,LOG:1)
Block(1,5,-6,AIR:0)
Block(1,5,-5,AIR:0)
Block(1,5,-4,AIR:0)
Block(1,5,-3,AIR:0)
Block(1,5,-2,AIR:0)
Block(1,5,-1,AIR:0)
Block(1,5,0,AIR:0)
Block(1,5,1,AIR:0)
Block(1,5,2,AIR:0)
Block(1,5,3,AIR:0)
Block(1,5,4,AIR:0)
Block(1,5,5,AIR:0)
Block(1,5,6,AIR:0)
Block(1,5,7,AIR:0)
Block(1,5,8,LOG:1)
Block(1,6,-7,LOG:1)
Block(1,6,8,LOG:1)
Block(1,7,-7,LOG:1)
Block(1,7,8,LOG:1)
Block(1,8,-7,SPRUCE_WOOD_STAIRS:2)
Block(1,8,-6,WOOD_STEP:13)
Block(1,8,-5,WOOD_STEP:13)
Block(1,8,-4,WOOD_STEP:13)
Block(1,8,-3,WOOD_STEP:13)
Block(1,8,-2,WOOD_STEP:13)
Block(1,8,-1,WOOD_STEP:13)
Block(1,8,0,WOOD_STEP:13)
Block(1,8,1,WOOD_STEP:13)
Block(1,8,2,WOOD_STEP:13)
Block(1,8,3,WOOD_STEP:13)
Block(1,8,4,WOOD_STEP:13)
Block(1,8,5,WOOD_STEP:13)
Block(1,8,6,WOOD_STEP:13)
Block(1,8,7,WOOD_STEP:13)
Block(1,8,8,SPRUCE_WOOD_STAIRS:3)
Block(1,9,-1,WOOD:1)
Block(1,9,0,WOOD:1)
Block(1,9,1,WOOD:1)
Block(1,9,2,WOOD:1)
Block(1,10,-1,WOOD:1)
Block(1,10,0,WOOD:1)
Block(1,10,1,WOOD:1)
Block(1,10,2,WOOD:1)
Block(1,10,3,WALL_SIGN:3)
Block(1,10,4,AIR:0)
Block(1,11,-7,SPRUCE_WOOD_STAIRS:1)
Block(1,11,-6,SPRUCE_WOOD_STAIRS:1)
Block(1,11,-5,SPRUCE_WOOD_STAIRS:2)
Block(1,11,-4,DARK_OAK_STAIRS:7)
Block(1,11,-1,WOOD:1)
Block(1,11,0,WOOD_DOUBLE_STEP:5)
Block(1,11,1,WOOD_DOUBLE_STEP:5)
Block(1,11,2,WOOD:1)
Block(1,11,5,DARK_OAK_STAIRS:6)
Block(1,11,6,SPRUCE_WOOD_STAIRS:3)
Block(1,11,7,SPRUCE_WOOD_STAIRS:1)
Block(1,11,8,SPRUCE_WOOD_STAIRS:1)
Block(1,12,-5,DARK_OAK_STAIRS:4)
Block(1,12,-4,LOG:5)
Block(1,12,-3,WOOD_STEP:13)
Block(1,12,-2,WOOD_STEP:13)
Block(1,12,-1,LOG:5)
Block(1,12,2,LOG:5)
Block(1,12,3,WOOD_STEP:13)
Block(1,12,4,WOOD_STEP:13)
Block(1,12,5,LOG:5)
Block(1,12,6,DARK_OAK_STAIRS:4)
Block(1,13,-5,DARK_OAK_STAIRS:5)
Block(1,13,-4,SPRUCE_WOOD_STAIRS:1)
Block(1,13,-3,SPRUCE_WOOD_STAIRS:2)
Block(1,13,-2,WOOD:1)
Block(1,13,-1,STAINED_GLASS_PANE:15)
Block(1,13,2,STAINED_GLASS_PANE:15)
Block(1,13,3,WOOD:1)
Block(1,13,4,SPRUCE_WOOD_STAIRS:3)
Block(1,13,5,SPRUCE_WOOD_STAIRS:1)
Block(1,13,6,DARK_OAK_STAIRS:5)
Block(1,14,-5,DARK_OAK_STAIRS:1)
Block(1,14,-4,SPRUCE_WOOD_STAIRS:1)
Block(1,14,-3,SPRUCE_WOOD_STAIRS:1)
Block(1,14,-2,SPRUCE_WOOD_STAIRS:1)
Block(1,14,-1,STAINED_GLASS_PANE:15)
Block(1,14,2,STAINED_GLASS_PANE:15)
Block(1,14,3,SPRUCE_WOOD_STAIRS:1)
Block(1,14,4,SPRUCE_WOOD_STAIRS:1)
Block(1,14,5,SPRUCE_WOOD_STAIRS:1)
Block(1,14,6,DARK_OAK_STAIRS:1)
Block(1,15,-5,DARK_OAK_STAIRS:1)
Block(1,15,-4,SPRUCE_WOOD_STAIRS:1)
Block(1,15,-3,SPRUCE_WOOD_STAIRS:1)
Block(1,15,-2,SPRUCE_WOOD_STAIRS:1)
Block(1,15,-1,SPRUCE_WOOD_STAIRS:2)
Block(1,15,2,SPRUCE_WOOD_STAIRS:1)
Block(1,15,3,SPRUCE_WOOD_STAIRS:1)
Block(1,15,4,SPRUCE_WOOD_STAIRS:1)
Block(1,15,5,SPRUCE_WOOD_STAIRS:1)
Block(1,15,6,DARK_OAK_STAIRS:1)
Block(1,16,0,SPRUCE_WOOD_STAIRS:2)
Block(1,16,1,SPRUCE_WOOD_STAIRS:3)
Block(1,17,0,WOOD_STEP:5)
Block(1,17,1,WOOD_STEP:5)
Block(2,0,-3,SPRUCE_FENCE:0)
Block(2,0,-2,AIR:0)
Block(2,0,-1,AIR:0)
Block(2,0,0,AIR:0)
Block(2,0,1,AIR:0)
Block(2,0,2,AIR:0)
Block(2,0,3,AIR:0)
Block(2,0,4,SPRUCE_FENCE:0)
Block(2,1,-3,SPRUCE_FENCE:0)
Block(2,1,-2,AIR:0)
Block(2,1,-1,AIR:0)
Block(2,1,0,AIR:0)
Block(2,1,1,AIR:0)
Block(2,1,2,AIR:0)
Block(2,1,3,AIR:0)
Block(2,1,4,SPRUCE_FENCE:0)
Block(2,2,-3,SPRUCE_FENCE:0)
Block(2,2,-2,AIR:0)
Block(2,2,-1,AIR:0)
Block(2,2,0,AIR:0)
Block(2,2,1,AIR:0)
Block(2,2,2,AIR:0)
Block(2,2,3,AIR:0)
Block(2,2,4,SPRUCE_FENCE:0)
Block(2,3,-4,SPRUCE_FENCE:0)
Block(2,3,-3,SPRUCE_FENCE:0)
Block(2,3,-2,AIR:0)
Block(2,3,-1,AIR:0)
Block(2,3,0,AIR:0)
Block(2,3,1,AIR:0)
Block(2,3,2,AIR:0)
Block(2,3,3,AIR:0)
Block(2,3,4,SPRUCE_FENCE:0)
Block(2,3,5,SPRUCE_FENCE:0)
Block(2,4,-7,LOG:5)
Block(2,4,-6,WOOD_STEP:13)
Block(2,4,-5,WOOD_STEP:13)
Block(2,4,-4,WOOD:1)
Block(2,4,-3,DARK_OAK_STAIRS:3)
Block(2,4,-2,AIR:0)
Block(2,4,-1,AIR:0)
Block(2,4,0,AIR:0)
Block(2,4,1,AIR:0)
Block(2,4,2,AIR:0)
Block(2,4,3,AIR:0)
Block(2,4,4,DARK_OAK_STAIRS:2)
Block(2,4,5,WOOD:1)
Block(2,4,6,WOOD_STEP:13)
Block(2,4,7,WOOD_STEP:13)
Block(2,4,8,LOG:5)
Block(2,5,-6,AIR:0)
Block(2,5,-5,AIR:0)
Block(2,5,-4,AIR:0)
Block(2,5,-3,DARK_OAK_STAIRS:2)
Block(2,5,-2,DARK_OAK_STAIRS:7)
Block(2,5,-1,WOOD_STEP:13)
Block(2,5,0,WOOD_STEP:13)
Block(2,5,1,WOOD_STEP:13)
Block(2,5,2,WOOD_STEP:13)
Block(2,5,3,DARK_OAK_STAIRS:6)
Block(2,5,4,DARK_OAK_STAIRS:0)
Block(2,5,5,AIR:0)
Block(2,5,6,AIR:0)
Block(2,5,7,AIR:0)
Block(2,7,-7,SPRUCE_WOOD_STAIRS:0)
Block(2,7,8,SPRUCE_WOOD_STAIRS:2)
Block(2,8,-7,SPRUCE_WOOD_STAIRS:7)
Block(2,8,-6,WOOD_STEP:13)
Block(2,8,-5,WOOD_STEP:13)
Block(2,8,-4,WOOD_STEP:13)
Block(2,8,-3,WOOD_STEP:13)
Block(2,8,-2,WOOD_STEP:13)
Block(2,8,-1,DARK_OAK_STAIRS:4)
Block(2,8,0,WOOD_STEP:13)
Block(2,8,1,WOOD_STEP:13)
Block(2,8,2,DARK_OAK_STAIRS:4)
Block(2,8,3,WOOD_STEP:13)
Block(2,8,4,WOOD_STEP:13)
Block(2,8,5,WOOD_STEP:13)
Block(2,8,6,WOOD_STEP:13)
Block(2,8,7,WOOD_STEP:13)
Block(2,8,8,SPRUCE_WOOD_STAIRS:6)
Block(2,9,-7,WOOD:1)
Block(2,9,-6,WOOD:1)
Block(2,9,-5,WOOD:1)
Block(2,9,-4,WOOD:1)
Block(2,9,-3,WOOD:1)
Block(2,9,-2,WOODEN_DOOR:2)
Block(2,9,-1,WOOD:1)
Block(2,9,0,WOOD_STEP:13)
Block(2,9,1,WOOD_STEP:13)
Block(2,9,2,WOOD:1)
Block(2,9,3,WOODEN_DOOR:2)
Block(2,9,4,WOOD:1)
Block(2,9,5,WOOD:1)
Block(2,9,6,WOOD:1)
Block(2,9,7,WOOD:1)
Block(2,9,8,WOOD:1)
Block(2,10,-7,SPRUCE_WOOD_STAIRS:1)
Block(2,10,-6,SPRUCE_WOOD_STAIRS:2)
Block(2,10,-5,WOOD:1)
Block(2,10,-4,WOOD:1)
Block(2,10,-3,WOOD:1)
Block(2,10,-2,WOODEN_DOOR:9)
Block(2,10,-1,WOOD:1)
Block(2,10,0,CARPET:0)
Block(2,10,2,WOOD:1)
Block(2,10,3,WOODEN_DOOR:9)
Block(2,10,4,WOOD:1)
Block(2,10,5,WOOD:1)
Block(2,10,6,WOOD:1)
Block(2,10,7,SPRUCE_WOOD_STAIRS:3)
Block(2,10,8,SPRUCE_WOOD_STAIRS:1)
Block(2,11,-5,SPRUCE_WOOD_STAIRS:2)
Block(2,11,-4,WOOD:1)
Block(2,11,-3,WOOD:1)
Block(2,11,-2,WOOD:1)
Block(2,11,-1,WOOD:1)
Block(2,11,0,WOOD:1)
Block(2,11,1,WOOD:1)
Block(2,11,2,WOOD:1)
Block(2,11,3,WOOD:1)
Block(2,11,4,WOOD:1)
Block(2,11,5,WOOD:1)
Block(2,11,6,SPRUCE_WOOD_STAIRS:3)
Block(2,12,-5,DARK_OAK_STAIRS:1)
Block(2,12,-4,DARK_OAK_STAIRS:2)
Block(2,12,-3,WOOD:1)
Block(2,12,-2,WOOD:1)
Block(2,12,-1,LOG:1)
Block(2,12,0,STAINED_GLASS_PANE:15)
Block(2,12,1,STAINED_GLASS_PANE:15)
Block(2,12,2,LOG:1)
Block(2,12,3,WOOD:1)
Block(2,12,4,WOOD:1)
Block(2,12,5,DARK_OAK_STAIRS:3)
Block(2,12,6,DARK_OAK_STAIRS:1)
Block(2,13,-3,SPRUCE_WOOD_STAIRS:2)
Block(2,13,-2,WOOD:1)
Block(2,13,-1,LOG:1)
Block(2,13,0,STAINED_GLASS_PANE:15)
Block(2,13,1,STAINED_GLASS_PANE:15)
Block(2,13,2,LOG:1)
Block(2,13,3,WOOD:1)
Block(2,13,4,SPRUCE_WOOD_STAIRS:3)
Block(2,14,-2,SPRUCE_WOOD_STAIRS:2)
Block(2,14,-1,LOG:1)
Block(2,14,0,STAINED_GLASS_PANE:15)
Block(2,14,1,STAINED_GLASS_PANE:15)
Block(2,14,2,LOG:1)
Block(2,14,3,SPRUCE_WOOD_STAIRS:3)
Block(2,15,-1,SPRUCE_WOOD_STAIRS:2)
Block(2,15,0,WOOD:1)
Block(2,15,1,WOOD:1)
Block(2,15,2,SPRUCE_WOOD_STAIRS:3)
Block(2,16,0,SPRUCE_WOOD_STAIRS:2)
Block(2,16,1,SPRUCE_WOOD_STAIRS:3)
Block(2,17,0,WOOD_STEP:5)
Block(2,17,1,WOOD_STEP:5)
Block(3,0,-3,SPRUCE_FENCE:0)
Block(3,0,-2,AIR:0)
Block(3,0,-1,WOOD:1)
Block(3,0,0,AIR:0)
Block(3,0,1,AIR:0)
Block(3,0,2,WOOD:1)
Block(3,0,3,AIR:0)
Block(3,0,4,SPRUCE_FENCE:0)
Block(3,1,-7,LOG:1)
Block(3,1,-3,SPRUCE_FENCE:0)
Block(3,1,-2,AIR:0)
Block(3,1,-1,WOOD:1)
Block(3,1,0,AIR:0)
Block(3,1,1,AIR:0)
Block(3,1,2,WOOD:1)
Block(3,1,3,AIR:0)
Block(3,1,4,SPRUCE_FENCE:0)
Block(3,1,8,LOG:1)
Block(3,2,-7,LOG:1)
Block(3,2,-3,SPRUCE_FENCE:0)
Block(3,2,-2,AIR:0)
Block(3,2,-1,WOOD:1)
Block(3,2,0,WOOD:1)
Block(3,2,1,WOOD:1)
Block(3,2,2,WOOD:1)
Block(3,2,3,AIR:0)
Block(3,2,4,SPRUCE_FENCE:0)
Block(3,2,8,LOG:1)
Block(3,3,-7,LOG:1)
Block(3,3,-4,SPRUCE_FENCE:0)
Block(3,3,-3,SPRUCE_FENCE:0)
Block(3,3,-2,AIR:0)
Block(3,3,-1,WOOD:1)
Block(3,3,0,WOOD:1)
Block(3,3,1,WOOD:1)
Block(3,3,2,WOOD:1)
Block(3,3,3,AIR:0)
Block(3,3,4,SPRUCE_FENCE:0)
Block(3,3,5,SPRUCE_FENCE:0)
Block(3,3,8,LOG:1)
Block(3,4,-7,LOG:1)
Block(3,4,-6,WOOD:1)
Block(3,4,-5,WOOD:1)
Block(3,4,-4,WOOD:1)
Block(3,4,-3,DARK_OAK_STAIRS:3)
Block(3,4,-2,AIR:0)
Block(3,4,-1,WOOD:1)
Block(3,4,0,WOOD:1)
Block(3,4,1,WOOD:1)
Block(3,4,2,WOOD:1)
Block(3,4,3,AIR:0)
Block(3,4,4,DARK_OAK_STAIRS:2)
Block(3,4,5,WOOD:1)
Block(3,4,6,WOOD:1)
Block(3,4,7,WOOD:1)
Block(3,4,8,LOG:1)
Block(3,5,-7,LOG:1)
Block(3,5,-6,SPRUCE_FENCE:0)
Block(3,5,-5,SPRUCE_FENCE:0)
RandomBlock(3,5,-2,TORCH:4,25,AIR:0,100)
Block(3,5,-1,WOOD:1)
Block(3,5,0,WOOD:1)
Block(3,5,1,WOOD:1)
Block(3,5,2,WOOD:1)
RandomBlock(3,5,3,TORCH:3,25,AIR:0,100)
Block(3,5,6,SPRUCE_FENCE:0)
Block(3,5,7,SPRUCE_FENCE:0)
Block(3,5,8,LOG:1)
Block(3,6,-7,LOG:1)
Block(3,6,-6,SPRUCE_FENCE:0)
Block(3,6,-5,SPRUCE_FENCE:0)
Block(3,6,-1,WOOD:1)
Block(3,6,2,WOOD:1)
Block(3,6,6,SPRUCE_FENCE:0)
Block(3,6,7,SPRUCE_FENCE:0)
Block(3,6,8,LOG:1)
Block(3,7,-7,LOG:1)
Block(3,7,-6,SPRUCE_FENCE:0)
Block(3,7,-5,SPRUCE_FENCE:0)
Block(3,7,-2,DARK_OAK_STAIRS:6)
Block(3,7,-1,WOOD:1)
Block(3,7,2,WOOD:1)
Block(3,7,3,DARK_OAK_STAIRS:7)
Block(3,7,6,SPRUCE_FENCE:0)
Block(3,7,7,SPRUCE_FENCE:0)
Block(3,7,8,LOG:1)
Block(3,8,-7,LOG:1)
Block(3,8,-6,WOOD:1)
Block(3,8,-5,WOOD:1)
Block(3,8,-4,WOOD:1)
Block(3,8,-3,WOOD:1)
Block(3,8,-2,WOOD:1)
Block(3,8,-1,WOOD:1)
Block(3,8,0,WOOD_STEP:13)
Block(3,8,1,WOOD_STEP:13)
Block(3,8,2,WOOD:1)
Block(3,8,3,WOOD:1)
Block(3,8,4,WOOD:1)
Block(3,8,5,WOOD:1)
Block(3,8,6,WOOD:1)
Block(3,8,7,WOOD:1)
Block(3,8,8,LOG:1)
Block(3,9,-7,SPRUCE_WOOD_STAIRS:2)
Block(3,9,-6,WOOD:1)
Block(3,9,-5,WOOD:1)
Block(3,9,-4,DARK_OAK_STAIRS:7)
Block(3,9,-3,BOOKSHELF:0)
Block(3,9,-1,TRAP_DOOR:4)
Block(3,9,0,BIRCH_WOOD_STAIRS:0)
Block(3,9,1,TRAP_DOOR:5)
Block(3,9,4,WORKBENCH:0)
Block(3,9,5,DARK_OAK_STAIRS:6)
Block(3,9,6,WOOD:1)
Block(3,9,7,WOOD:1)
Block(3,9,8,SPRUCE_WOOD_STAIRS:3)
Block(3,10,-6,SPRUCE_WOOD_STAIRS:2)
Block(3,10,-5,WOOD:1)
Block(3,10,-4,WOOD:1)
Block(3,10,-3,DARK_OAK_STAIRS:7)
Block(3,10,4,DARK_OAK_STAIRS:6)
Block(3,10,5,WOOD:1)
Block(3,10,6,WOOD:1)
Block(3,10,7,SPRUCE_WOOD_STAIRS:3)
Block(3,11,-5,SPRUCE_WOOD_STAIRS:2)
Block(3,11,-4,WOOD:1)
Block(3,11,-3,WOOD:1)
Block(3,11,-2,WOOD:1)
Block(3,11,-1,WOOD:1)
Block(3,11,0,WOOD:1)
Block(3,11,1,WOOD:1)
Block(3,11,2,WOOD:1)
Block(3,11,3,WOOD:1)
Block(3,11,4,WOOD:1)
Block(3,11,5,WOOD:1)
Block(3,11,6,SPRUCE_WOOD_STAIRS:3)
Block(3,12,-4,DARK_OAK_STAIRS:2)
Block(3,12,-3,SPRUCE_WOOD_STAIRS:7)
Block(3,12,-2,SPRUCE_FENCE:0)
Block(3,12,-1,SPRUCE_FENCE:0)
Block(3,12,0,SPRUCE_FENCE:0)
Block(3,12,1,SPRUCE_FENCE:0)
Block(3,12,2,SPRUCE_FENCE:0)
Block(3,12,3,SPRUCE_FENCE:0)
Block(3,12,4,WOOD:1)
Block(3,12,5,SPRUCE_WOOD_STAIRS:3)
Block(3,13,-3,SPRUCE_WOOD_STAIRS:2)
Block(3,13,-2,SPRUCE_WOOD_STAIRS:7)
Block(3,13,3,SPRUCE_WOOD_STAIRS:6)
Block(3,13,4,SPRUCE_WOOD_STAIRS:3)
Block(3,14,-2,SPRUCE_WOOD_STAIRS:2)
Block(3,14,-1,SPRUCE_WOOD_STAIRS:7)
Block(3,14,2,SPRUCE_WOOD_STAIRS:6)
Block(3,14,3,SPRUCE_WOOD_STAIRS:3)
Block(3,15,-1,SPRUCE_WOOD_STAIRS:2)
Block(3,15,0,SPRUCE_WOOD_STAIRS:7)
Block(3,15,1,SPRUCE_WOOD_STAIRS:6)
Block(3,15,2,SPRUCE_WOOD_STAIRS:3)
Block(3,16,0,SPRUCE_WOOD_STAIRS:2)
Block(3,16,1,SPRUCE_WOOD_STAIRS:3)
Block(3,17,0,DARK_OAK_STAIRS:2)
Block(3,17,1,DARK_OAK_STAIRS:3)
Block(4,0,-3,SPRUCE_FENCE:0)
Block(4,0,-2,SPRUCE_FENCE:0)
Block(4,0,-1,SPRUCE_FENCE:0)
Block(4,0,0,LADDER:5)
Block(4,0,1,LADDER:5)
Block(4,0,2,SPRUCE_FENCE:0)
Block(4,0,3,SPRUCE_FENCE:0)
Block(4,0,4,SPRUCE_FENCE:0)
Block(4,1,-3,SPRUCE_FENCE:0)
Block(4,1,-2,SPRUCE_FENCE:0)
Block(4,1,-1,SPRUCE_FENCE:0)
Block(4,1,0,LADDER:5)
Block(4,1,1,LADDER:5)
Block(4,1,2,SPRUCE_FENCE:0)
Block(4,1,3,SPRUCE_FENCE:0)
Block(4,1,4,SPRUCE_FENCE:0)
Block(4,2,-3,SPRUCE_FENCE:0)
Block(4,2,-2,SPRUCE_FENCE:0)
Block(4,2,-1,SPRUCE_FENCE:0)
Block(4,2,0,LADDER:5)
Block(4,2,1,LADDER:5)
Block(4,2,2,SPRUCE_FENCE:0)
Block(4,2,3,SPRUCE_FENCE:0)
Block(4,2,4,SPRUCE_FENCE:0)
Block(4,3,-4,SPRUCE_FENCE:0)
Block(4,3,-3,SPRUCE_FENCE:0)
Block(4,3,-2,SPRUCE_FENCE:0)
Block(4,3,-1,SPRUCE_FENCE:0)
Block(4,3,0,LADDER:5)
Block(4,3,1,LADDER:5)
Block(4,3,2,SPRUCE_FENCE:0)
Block(4,3,3,SPRUCE_FENCE:0)
Block(4,3,4,SPRUCE_FENCE:0)
Block(4,3,5,SPRUCE_FENCE:0)
Block(4,4,-7,LOG:5)
Block(4,4,-6,WOOD_STEP:13)
Block(4,4,-5,WOOD_STEP:13)
Block(4,4,-4,WOOD:1)
Block(4,4,-3,DARK_OAK_STAIRS:0)
Block(4,4,-2,DARK_OAK_STAIRS:0)
Block(4,4,-1,WOOD:1)
Block(4,4,0,LADDER:5)
Block(4,4,1,LADDER:5)
Block(4,4,2,WOOD:1)
Block(4,4,3,DARK_OAK_STAIRS:0)
Block(4,4,4,DARK_OAK_STAIRS:0)
Block(4,4,5,WOOD:1)
Block(4,4,6,WOOD_STEP:13)
Block(4,4,7,WOOD_STEP:13)
Block(4,4,8,LOG:5)
Block(4,5,-7,SPRUCE_FENCE:0)
Block(4,5,-5,SPRUCE_FENCE:0)
Block(4,5,0,LADDER:5)
Block(4,5,1,LADDER:5)
Block(4,5,6,SPRUCE_FENCE:0)
Block(4,5,8,SPRUCE_FENCE:0)
Block(4,6,-5,SPRUCE_FENCE:0)
Block(4,6,6,SPRUCE_FENCE:0)
Block(4,7,-5,SPRUCE_FENCE:0)
Block(4,7,-1,DARK_OAK_STAIRS:5)
Block(4,7,2,DARK_OAK_STAIRS:5)
Block(4,7,6,SPRUCE_FENCE:0)
Block(4,8,-7,DARK_OAK_STAIRS:7)
Block(4,8,-6,DARK_OAK_STAIRS:2)
Block(4,8,-5,WOOD:1)
Block(4,8,-4,WOOD_STEP:13)
Block(4,8,-3,WOOD_STEP:13)
Block(4,8,-2,WOOD_STEP:13)
Block(4,8,-1,WOOD:1)
Block(4,8,0,WOOD_STEP:13)
Block(4,8,1,WOOD_STEP:13)
Block(4,8,2,WOOD:1)
Block(4,8,3,WOOD_STEP:13)
Block(4,8,4,WOOD_STEP:13)
Block(4,8,5,WOOD_STEP:13)
Block(4,8,6,WOOD:1)
Block(4,8,7,DARK_OAK_STAIRS:3)
Block(4,8,8,DARK_OAK_STAIRS:6)
Block(4,9,-7,DARK_OAK_STAIRS:2)
Block(4,9,-6,DARK_OAK_STAIRS:7)
Block(4,9,-5,DARK_OAK_STAIRS:2)
Block(4,9,-4,DARK_OAK_STAIRS:7)
Block(4,9,-3,BOOKSHELF:0)
Block(4,9,-2,CARPET:14)
Block(4,9,-1,CARPET:14)
Block(4,9,0,CARPET:14)
Block(4,9,1,CARPET:14)
Block(4,9,2,CARPET:14)
Block(4,9,3,CARPET:14)
Block(4,9,4,BOOKSHELF:0)
Block(4,9,5,DARK_OAK_STAIRS:6)
Block(4,9,6,DARK_OAK_STAIRS:3)
Block(4,9,7,DARK_OAK_STAIRS:6)
Block(4,9,8,DARK_OAK_STAIRS:3)
Block(4,10,-6,DARK_OAK_STAIRS:2)
Block(4,10,-5,DARK_OAK_STAIRS:7)
Block(4,10,-4,SPRUCE_WOOD_STAIRS:2)
Block(4,10,-3,DARK_OAK_STAIRS:7)
Block(4,10,4,DARK_OAK_STAIRS:6)
Block(4,10,5,SPRUCE_WOOD_STAIRS:3)
Block(4,10,6,DARK_OAK_STAIRS:6)
Block(4,10,7,DARK_OAK_STAIRS:3)
Block(4,11,-5,DARK_OAK_STAIRS:2)
Block(4,11,-4,DARK_OAK_STAIRS:7)
Block(4,11,-3,SPRUCE_WOOD_STAIRS:2)
Block(4,11,-2,WOOD:1)
Block(4,11,-1,WOOD:1)
Block(4,11,0,WOOD:1)
Block(4,11,1,WOOD:1)
Block(4,11,2,WOOD:1)
Block(4,11,3,WOOD:1)
Block(4,11,4,SPRUCE_WOOD_STAIRS:3)
Block(4,11,5,DARK_OAK_STAIRS:6)
Block(4,11,6,DARK_OAK_STAIRS:3)
Block(4,12,-4,DARK_OAK_STAIRS:2)
Block(4,12,-3,DARK_OAK_STAIRS:7)
Block(4,12,0,DARK_OAK_STAIRS:6)
Block(4,12,1,DARK_OAK_STAIRS:7)
Block(4,12,4,DARK_OAK_STAIRS:6)
Block(4,12,5,DARK_OAK_STAIRS:3)
Block(4,13,-3,DARK_OAK_STAIRS:2)
Block(4,13,-2,DARK_OAK_STAIRS:7)
Block(4,13,-1,DARK_OAK_STAIRS:6)
Block(4,13,0,DARK_OAK_STAIRS:3)
Block(4,13,1,DARK_OAK_STAIRS:2)
Block(4,13,2,DARK_OAK_STAIRS:7)
Block(4,13,3,DARK_OAK_STAIRS:6)
Block(4,13,4,DARK_OAK_STAIRS:3)
Block(4,14,-2,DARK_OAK_STAIRS:2)
Block(4,14,-1,DARK_OAK_STAIRS:3)
Block(4,14,2,DARK_OAK_STAIRS:2)
Block(4,14,3,DARK_OAK_STAIRS:3)
Block(5,0,-1,SPRUCE_FENCE:0)
Block(5,0,0,SPRUCE_FENCE:0)
Block(5,0,1,SPRUCE_FENCE:0)
Block(5,0,2,SPRUCE_FENCE:0)
Block(5,1,-1,SPRUCE_FENCE:0)
Block(5,1,0,SPRUCE_FENCE:0)
Block(5,1,1,SPRUCE_FENCE:0)
Block(5,1,2,SPRUCE_FENCE:0)
Block(5,1,5,LOG:1)
Block(5,2,-4,LOG:1)
Block(5,2,-1,SPRUCE_FENCE:0)
Block(5,2,0,SPRUCE_FENCE:0)
Block(5,2,1,SPRUCE_FENCE:0)
Block(5,2,2,SPRUCE_FENCE:0)
Block(5,2,5,LOG:1)
Block(5,3,-4,LOG:1)
Block(5,3,-3,SPRUCE_FENCE:0)
Block(5,3,-2,SPRUCE_FENCE:0)
Block(5,3,-1,SPRUCE_FENCE:0)
Block(5,3,0,SPRUCE_FENCE:0)
Block(5,3,1,SPRUCE_FENCE:0)
Block(5,3,2,SPRUCE_FENCE:0)
Block(5,3,3,SPRUCE_FENCE:0)
Block(5,3,4,SPRUCE_FENCE:0)
Block(5,3,5,LOG:1)
Block(5,4,-7,LOG:5)
Block(5,4,-6,WOOD_STEP:13)
Block(5,4,-5,WOOD_STEP:13)
Block(5,4,-4,WOOD:1)
Block(5,4,-3,WOOD:1)
Block(5,4,-2,WOOD:1)
Block(5,4,-1,WOOD:1)
Block(5,4,0,WOOD:1)
Block(5,4,1,WOOD:1)
Block(5,4,2,WOOD:1)
Block(5,4,3,WOOD:1)
Block(5,4,4,WOOD:1)
Block(5,4,5,WOOD:1)
Block(5,4,6,WOOD_STEP:13)
Block(5,4,7,WOOD_STEP:13)
Block(5,4,8,LOG:5)
Block(5,5,-7,SPRUCE_FENCE:0)
Block(5,5,-5,SPRUCE_FENCE:0)
Block(5,5,6,SPRUCE_FENCE:0)
Block(5,5,8,SPRUCE_FENCE:0)
Block(5,6,-5,SPRUCE_FENCE:0)
Block(5,6,6,SPRUCE_FENCE:0)
Block(5,7,-5,SPRUCE_FENCE:0)
Block(5,7,6,SPRUCE_FENCE:0)
Block(5,8,-6,DARK_OAK_STAIRS:2)
Block(5,8,-5,WOOD:1)
Block(5,8,-4,WOOD_STEP:13)
Block(5,8,-3,WOOD_STEP:13)
Block(5,8,-2,WOOD_STEP:13)
Block(5,8,-1,WOOD:1)
Block(5,8,0,WOOD_STEP:13)
Block(5,8,1,WOOD_STEP:13)
Block(5,8,2,WOOD:1)
Block(5,8,3,WOOD_STEP:13)
Block(5,8,4,WOOD_STEP:13)
Block(5,8,5,WOOD_STEP:13)
Block(5,8,6,WOOD:1)
Block(5,8,7,DARK_OAK_STAIRS:3)
Block(5,9,-5,DARK_OAK_STAIRS:2)
Block(5,9,-4,DARK_OAK_STAIRS:7)
Block(5,9,-3,WORKBENCH:0)
Block(5,9,-2,CARPET:14)
Block(5,9,-1,CARPET:14)
Block(5,9,0,CARPET:14)
Block(5,9,1,CARPET:14)
Block(5,9,2,CARPET:14)
Block(5,9,3,CARPET:14)
Block(5,9,4,WORKBENCH:0)
Block(5,9,5,DARK_OAK_STAIRS:6)
Block(5,9,6,DARK_OAK_STAIRS:3)
Block(5,10,-4,SPRUCE_WOOD_STAIRS:2)
Block(5,10,-3,DARK_OAK_STAIRS:4)
Block(5,10,-2,DARK_OAK_STAIRS:4)
Block(5,10,-1,DARK_OAK_STAIRS:4)
Block(5,10,2,DARK_OAK_STAIRS:4)
Block(5,10,3,DARK_OAK_STAIRS:4)
Block(5,10,4,DARK_OAK_STAIRS:6)
Block(5,10,5,SPRUCE_WOOD_STAIRS:3)
Block(5,11,-3,SPRUCE_WOOD_STAIRS:2)
Block(5,11,-2,SPRUCE_WOOD_STAIRS:1)
Block(5,11,-1,SPRUCE_WOOD_STAIRS:1)
Block(5,11,0,WOOD:1)
Block(5,11,1,WOOD:1)
Block(5,11,2,SPRUCE_WOOD_STAIRS:3)
Block(5,11,3,SPRUCE_WOOD_STAIRS:1)
Block(5,11,4,SPRUCE_WOOD_STAIRS:3)
Block(5,12,0,SPRUCE_WOOD_STAIRS:2)
Block(5,12,1,SPRUCE_WOOD_STAIRS:3)
Block(6,4,-7,LOG:5)
Block(6,4,-6,WOOD_STEP:13)
Block(6,4,-5,WOOD_STEP:13)
Block(6,4,-4,WOOD_STEP:13)
Block(6,4,-3,WOOD_STEP:13)
Block(6,4,-2,WOOD_STEP:13)
Block(6,4,-1,WOOD:1)
Block(6,4,0,WOOD_STEP:13)
Block(6,4,1,WOOD_STEP:13)
Block(6,4,2,WOOD:1)
Block(6,4,3,WOOD_STEP:13)
Block(6,4,4,WOOD_STEP:13)
Block(6,4,5,WOOD_STEP:13)
Block(6,4,6,WOOD_STEP:13)
Block(6,4,7,WOOD_STEP:13)
Block(6,4,8,LOG:5)
Block(6,5,-7,SPRUCE_FENCE:0)
Block(6,5,-5,SPRUCE_FENCE:0)
Block(6,5,-4,AIR:0)
Block(6,5,2,AIR:0)
Block(6,5,6,SPRUCE_FENCE:0)
Block(6,5,8,SPRUCE_FENCE:0)
Block(6,6,-5,SPRUCE_FENCE:0)
Block(6,6,6,SPRUCE_FENCE:0)
Block(6,7,-5,SPRUCE_FENCE:0)
Block(6,7,6,SPRUCE_FENCE:0)
Block(6,8,-6,DARK_OAK_STAIRS:2)
Block(6,8,-5,WOOD:1)
Block(6,8,-4,WOOD_STEP:13)
Block(6,8,-3,WOOD_STEP:13)
Block(6,8,-2,WOOD_STEP:13)
Block(6,8,-1,WOOD:1)
Block(6,8,0,WOOD_STEP:13)
Block(6,8,1,WOOD_STEP:13)
Block(6,8,2,WOOD:1)
Block(6,8,3,WOOD_STEP:13)
Block(6,8,4,WOOD_STEP:13)
Block(6,8,5,WOOD_STEP:13)
Block(6,8,6,WOOD:1)
Block(6,8,7,DARK_OAK_STAIRS:3)
Block(6,9,-5,DARK_OAK_STAIRS:2)
Block(6,9,-4,DARK_OAK_STAIRS:7)
Block(6,9,-3,DARK_OAK_STAIRS:4)
Block(6,9,-2,DARK_OAK_STAIRS:4)
Block(6,9,-1,DARK_OAK_STAIRS:4)
Block(6,9,0,WOOD_STEP:13)
Block(6,9,1,WOOD_STEP:13)
Block(6,9,2,DARK_OAK_STAIRS:4)
Block(6,9,3,DARK_OAK_STAIRS:4)
Block(6,9,4,DARK_OAK_STAIRS:4)
Block(6,9,5,DARK_OAK_STAIRS:6)
Block(6,9,6,DARK_OAK_STAIRS:3)
Block(6,10,-4,SPRUCE_WOOD_STAIRS:1)
Block(6,10,-3,SPRUCE_WOOD_STAIRS:1)
Block(6,10,-2,SPRUCE_WOOD_STAIRS:2)
Block(6,10,-1,WOOD:1)
RandomBlock(6,10,1,TORCH:5,25,AIR:0,100)
Block(6,10,2,WOOD:1)
Block(6,10,3,SPRUCE_WOOD_STAIRS:3)
Block(6,10,4,SPRUCE_WOOD_STAIRS:1)
Block(6,10,5,SPRUCE_WOOD_STAIRS:1)
Block(6,11,-1,SPRUCE_WOOD_STAIRS:2)
Block(6,11,0,WOOD:1)
Block(6,11,1,WOOD:1)
Block(6,11,2,SPRUCE_WOOD_STAIRS:3)
Block(6,12,0,SPRUCE_WOOD_STAIRS:2)
Block(6,12,1,SPRUCE_WOOD_STAIRS:3)
Block(7,1,-5,LOG:1)
Block(7,1,6,LOG:1)
Block(7,2,-5,LOG:1)
Block(7,2,6,LOG:1)
Block(7,3,-5,LOG:1)
Block(7,3,6,LOG:1)
Block(7,4,-7,LOG:5)
Block(7,4,-6,WOOD_STEP:13)
Block(7,4,-5,LOG:1)
Block(7,4,-4,WOOD_STEP:13)
Block(7,4,-3,WOOD_STEP:13)
Block(7,4,-2,WOOD_STEP:13)
Block(7,4,-1,WOOD:1)
Block(7,4,0,DARK_OAK_STAIRS:1)
Block(7,4,1,DARK_OAK_STAIRS:1)
Block(7,4,2,WOOD:1)
Block(7,4,3,WOOD_STEP:13)
Block(7,4,4,WOOD_STEP:13)
Block(7,4,5,WOOD_STEP:13)
Block(7,4,6,LOG:1)
Block(7,4,7,WOOD_STEP:13)
Block(7,4,8,LOG:5)
Block(7,5,-7,SPRUCE_FENCE:0)
Block(7,5,-5,LOG:1)
Block(7,5,-4,SPRUCE_FENCE:0)
Block(7,5,-2,SPRUCE_FENCE:0)
Block(7,5,-1,SPRUCE_FENCE:0)
Block(7,5,2,SPRUCE_FENCE:0)
Block(7,5,3,SPRUCE_FENCE:0)
Block(7,5,5,SPRUCE_FENCE:0)
Block(7,5,6,LOG:1)
Block(7,5,8,SPRUCE_FENCE:0)
Block(7,6,-5,LOG:1)
Block(7,6,-4,SPRUCE_FENCE:0)
Block(7,6,-2,SPRUCE_FENCE:0)
Block(7,6,-1,SPRUCE_FENCE:0)
Block(7,6,2,SPRUCE_FENCE:0)
Block(7,6,3,SPRUCE_FENCE:0)
Block(7,6,5,SPRUCE_FENCE:0)
Block(7,6,6,LOG:1)
Block(7,7,-5,LOG:1)
Block(7,7,-4,SPRUCE_FENCE:0)
Block(7,7,-3,SPRUCE_FENCE:0)
Block(7,7,-2,SPRUCE_FENCE:0)
Block(7,7,-1,SPRUCE_FENCE:0)
Block(7,7,2,SPRUCE_FENCE:0)
Block(7,7,3,SPRUCE_FENCE:0)
Block(7,7,4,SPRUCE_FENCE:0)
Block(7,7,5,SPRUCE_FENCE:0)
Block(7,7,6,LOG:1)
Block(7,8,-6,DARK_OAK_STAIRS:2)
Block(7,8,-5,WOOD:1)
Block(7,8,-4,WOOD:1)
Block(7,8,-3,WOOD:1)
Block(7,8,-2,WOOD:1)
Block(7,8,-1,WOOD:1)
Block(7,8,0,WOOD_STEP:13)
Block(7,8,1,WOOD_STEP:13)
Block(7,8,2,WOOD:1)
Block(7,8,3,WOOD:1)
Block(7,8,4,WOOD:1)
Block(7,8,5,WOOD:1)
Block(7,8,6,WOOD:1)
Block(7,8,7,DARK_OAK_STAIRS:3)
Block(7,9,-5,DARK_OAK_STAIRS:2)
Block(7,9,-4,DARK_OAK_STAIRS:1)
Block(7,9,-3,DARK_OAK_STAIRS:2)
Block(7,9,-2,WOOD:1)
Block(7,9,-1,WOOD:1)
Block(7,9,0,STAINED_GLASS_PANE:15)
Block(7,9,1,STAINED_GLASS_PANE:15)
Block(7,9,2,WOOD:1)
Block(7,9,3,WOOD:1)
Block(7,9,4,DARK_OAK_STAIRS:3)
Block(7,9,5,DARK_OAK_STAIRS:1)
Block(7,9,6,DARK_OAK_STAIRS:3)
Block(7,10,-2,SPRUCE_WOOD_STAIRS:2)
Block(7,10,-1,WOOD:1)
Block(7,10,0,STAINED_GLASS_PANE:15)
Block(7,10,1,STAINED_GLASS_PANE:15)
Block(7,10,2,WOOD:1)
Block(7,10,3,SPRUCE_WOOD_STAIRS:3)
Block(7,11,-1,SPRUCE_WOOD_STAIRS:2)
Block(7,11,0,WOOD:1)
Block(7,11,1,WOOD:1)
Block(7,11,2,SPRUCE_WOOD_STAIRS:3)
Block(7,12,0,SPRUCE_WOOD_STAIRS:2)
Block(7,12,1,SPRUCE_WOOD_STAIRS:3)
Block(5,1,-4,LOG:1)
Block(-8,0,-5,LOG:1)
Block(-8,0,6,LOG:1)
Block(-6,0,-4,LOG:1)
Block(-6,0,5,LOG:1)
Block(-4,0,-7,LOG:1)
Block(-4,0,8,LOG:1)
Block(3,0,-7,LOG:1)
Block(7,0,-5,LOG:1)
Block(7,0,6,LOG:1)
Block(5,0,-4,LOG:1)
Block(5,0,5,LOG:1)
Block(3,0,8,LOG:1)
Block(-8,-1,-5,LOG:1)
Block(-8,-1,6,LOG:1)
Block(-6,-1,-4,LOG:1)
Block(-6,-1,5,LOG:1)
Block(-4,-1,-7,LOG:1)
Block(-4,-1,8,LOG:1)
Block(3,-1,-7,LOG:1)
Block(7,-1,-5,LOG:1)
Block(7,-1,6,LOG:1)
Block(5,-1,-4,LOG:1)
Block(5,-1,5,LOG:1)
Block(3,-1,8,LOG:1)
Block(-8,-2,-5,LOG:1)
Block(-8,-2,6,LOG:1)
Block(-6,-2,-4,LOG:1)
Block(-6,-2,5,LOG:1)
Block(-4,-2,-7,LOG:1)
Block(-4,-2,8,LOG:1)
Block(3,-2,-7,LOG:1)
Block(7,-2,-5,LOG:1)
Block(7,-2,6,LOG:1)
Block(5,-2,-4,LOG:1)
Block(5,-2,5,LOG:1)
Block(3,-2,8,LOG:1)
Block(-8,-3,-5,LOG:1)
Block(-8,-3,6,LOG:1)
Block(-6,-3,-4,LOG:1)
Block(-6,-3,5,LOG:1)
Block(-4,-3,-7,LOG:1)
Block(-4,-3,8,LOG:1)
Block(3,-3,-7,LOG:1)
Block(7,-3,-5,LOG:1)
Block(7,-3,6,LOG:1)
Block(5,-3,-4,LOG:1)
Block(5,-3,5,LOG:1)
Block(3,-3,8,LOG:1)
Block(-8,-4,-5,LOG:1)
Block(-8,-4,6,LOG:1)
Block(-6,-4,-4,LOG:1)
Block(-6,-4,5,LOG:1)
Block(-4,-4,-7,LOG:1)
Block(-4,-4,8,LOG:1)
Block(3,-4,-7,LOG:1)
Block(7,-4,-5,LOG:1)
Block(7,-4,6,LOG:1)
Block(5,-4,-4,LOG:1)
Block(5,-4,5,LOG:1)
Block(3,-4,8,LOG:1)
Block(-8,-5,-5,LOG:1)
Block(-8,-5,6,LOG:1)
Block(-6,-5,-4,LOG:1)
Block(-6,-5,5,LOG:1)
Block(-4,-5,-7,LOG:1)
Block(-4,-5,8,LOG:1)
Block(3,-5,-7,LOG:1)
Block(7,-5,-5,LOG:1)
Block(7,-5,6,LOG:1)
Block(5,-5,-4,LOG:1)
Block(5,-5,5,LOG:1)
Block(3,-5,8,LOG:1)
Block(-8,-6,-5,LOG:1)
Block(-8,-6,6,LOG:1)
Block(-6,-6,-4,LOG:1)
Block(-6,-6,5,LOG:1)
Block(-4,-6,-7,LOG:1)
Block(-4,-6,8,LOG:1)
Block(3,-6,-7,LOG:1)
Block(7,-6,-5,LOG:1)
Block(7,-6,6,LOG:1)
Block(5,-6,-4,LOG:1)
Block(5,-6,5,LOG:1)
Block(3,-6,8,LOG:1)
Block(-8,-7,-5,LOG:1)
Block(-8,-7,6,LOG:1)
Block(-6,-7,-4,LOG:1)
Block(-6,-7,5,LOG:1)
Block(-4,-7,-7,LOG:1)
Block(-4,-7,8,LOG:1)
Block(3,-7,-7,LOG:1)
Block(7,-7,-5,LOG:1)
Block(7,-7,6,LOG:1)
Block(5,-7,-4,LOG:1)
Block(5,-7,5,LOG:1)
Block(3,-7,8,LOG:1)
Block(-8,-8,-5,LOG:1)
Block(-8,-8,6,LOG:1)
Block(-6,-8,-4,LOG:1)
Block(-6,-8,5,LOG:1)
Block(-4,-8,-7,LOG:1)
Block(-4,-8,8,LOG:1)
Block(3,-8,-7,LOG:1)
Block(7,-8,-5,LOG:1)
Block(7,-8,6,LOG:1)
Block(5,-8,-4,LOG:1)
Block(5,-8,5,LOG:1)
Block(3,-8,8,LOG:1)
Block(-8,-9,-5,LOG:1)
Block(-8,-9,6,LOG:1)
Block(-6,-9,-4,LOG:1)
Block(-6,-9,5,LOG:1)
Block(-4,-9,-7,LOG:1)
Block(-4,-9,8,LOG:1)
Block(3,-9,-7,LOG:1)
Block(7,-9,-5,LOG:1)
Block(7,-9,6,LOG:1)
Block(5,-9,-4,LOG:1)
Block(5,-9,5,LOG:1)
Block(3,-9,8,LOG:1)
Block(-8,-10,-5,LOG:1)
Block(-8,-10,6,LOG:1)
Block(-6,-10,-4,LOG:1)
Block(-6,-10,5,LOG:1)
Block(-4,-10,-7,LOG:1)
Block(-4,-10,8,LOG:1)
Block(3,-10,-7,LOG:1)
Block(7,-10,-5,LOG:1)
Block(7,-10,6,LOG:1)
Block(5,-10,-4,LOG:1)
Block(5,-10,5,LOG:1)
Block(3,-10,8,LOG:1)
Block(-8,-11,-5,LOG:1)
Block(-8,-11,6,LOG:1)
Block(-6,-11,-4,LOG:1)
Block(-6,-11,5,LOG:1)
Block(-4,-11,-7,LOG:1)
Block(-4,-11,8,LOG:1)
Block(3,-11,-7,LOG:1)
Block(7,-11,-5,LOG:1)
Block(7,-11,6,LOG:1)
Block(5,-11,-4,LOG:1)
Block(5,-11,5,LOG:1)
Block(3,-11,8,LOG:1)
Block(-8,-12,-5,LOG:1)
Block(-8,-12,6,LOG:1)
Block(-6,-12,-4,LOG:1)
Block(-6,-12,5,LOG:1)
Block(-4,-12,-7,LOG:1)
Block(-4,-12,8,LOG:1)
Block(3,-12,-7,LOG:1)
Block(7,-12,-5,LOG:1)
Block(7,-12,6,LOG:1)
Block(5,-12,-4,LOG:1)
Block(5,-12,5,LOG:1)
Block(3,-12,8,LOG:1)
Block(-8,-13,-5,LOG:1)
Block(-8,-13,6,LOG:1)
Block(-6,-13,-4,LOG:1)
Block(-6,-13,5,LOG:1)
Block(-4,-13,-7,LOG:1)
Block(-4,-13,8,LOG:1)
Block(3,-13,-7,LOG:1)
Block(7,-13,-5,LOG:1)
Block(7,-13,6,LOG:1)
Block(5,-13,-4,LOG:1)
Block(5,-13,5,LOG:1)
Block(3,-13,8,LOG:1)
Block(-8,-14,-5,LOG:1)
Block(-8,-14,6,LOG:1)
Block(-6,-14,-4,LOG:1)
Block(-6,-14,5,LOG:1)
Block(-4,-14,-7,LOG:1)
Block(-4,-14,8,LOG:1)
Block(3,-14,-7,LOG:1)
Block(7,-14,-5,LOG:1)
Block(7,-14,6,LOG:1)
Block(5,-14,-4,LOG:1)
Block(5,-14,5,LOG:1)
Block(3,-14,8,LOG:1)
Block(-8,-15,-5,LOG:1)
Block(-8,-15,6,LOG:1)
Block(-6,-15,-4,LOG:1)
Block(-6,-15,5,LOG:1)
Block(-4,-15,-7,LOG:1)
Block(-4,-15,8,LOG:1)
Block(3,-15,-7,LOG:1)
Block(7,-15,-5,LOG:1)
Block(7,-15,6,LOG:1)
Block(5,-15,-4,LOG:1)
Block(5,-15,5,LOG:1)
Block(3,-15,8,LOG:1)
Branch(16,0,0,true,W-MineshaftMainC2R1,NORTH,100.0,0)
Branch(0,0,16,true,W-MineshaftMainC1R2,NORTH,100.0,0)
Branch(0,0,-16,true,W-MineshaftMainC1R0,NORTH,100.0,0)
Entity(-7,5,2,minecraft:wither_skeleton,1,../../NBT/Mobs/Tunneler.txt)
Entity(-6,5,-4,minecraft:wither_skeleton,1,../../NBT/Mobs/Tunneler.txt)
Entity(-1,10,-2,minecraft:wither_skeleton,1,../../NBT/Mobs/Tunneler.txt)
Entity(1,10,4,minecraft:wither_skeleton,1,../../NBT/Mobs/Tunneler.txt)
Entity(6,5,-4,minecraft:wither_skeleton,1,../../NBT/Mobs/Tunneler.txt)
Entity(6,5,2,minecraft:wither_skeleton,1,../../NBT/Mobs/Tunneler.txt)
