Author: NLBlackEagle
Description: No description given
SettingsMode: WriteDisable
Frequency: 0
SpawnHeight: highestBlock
UseCenterForHighestBlock: true
MinHeight: 0
MaxHeight: 255
InheritBO3: 
InheritBO3Rotation: NORTH
OverrideChildSettings: true
OverrideParentHeight: false
CanOverride: false
BranchFrequency: 0
BranchFrequencyGroup: 
MustBeBelowOther: false
MustBeInside: 
CannotBeInside: 
ReplacesBO3: 
MustBeInsideWorldBorders: false
CanSpawnOnWater: true
SpawnOnWaterOnly: false
SpawnUnderWater: false
SpawnAtWaterLevel: false
HeightOffset: 0
RemoveAir: false
ReplaceAbove: 
ReplaceBelow: 
ReplaceWithBiomeBlocks: true
ReplaceWithSurfaceBlock: GRASS
ReplaceWithGroundBlock: DIRT
ReplaceWithStoneBlock: STONE
SmoothRadius: 0
SmoothHeightOffset: 0
SmoothStartTop: false
SmoothStartWood: false
SmoothingSurfaceBlock: 
SmoothingGroundBlock: 
BO3Group: MineVillageHub:1
IsSpawnPoint: false
DoReplaceBlocks: true
Block(-7,0,-6,LOG:1)
Block(-7,0,0,LOG:1)
Block(-7,0,3,LOG:1)
Block(-7,0,9,LOG:1)
Block(-7,1,-6,WOOD:5)
Block(-7,1,-5,WOOD:5)
Block(-7,1,-4,WOOD:5)
Block(-7,1,-3,WOOD:5)
Block(-7,1,-2,WOOD:5)
Block(-7,1,-1,WOOD:5)
Block(-7,1,0,WOOD:5)
Block(-7,1,1,WOOD:5)
Block(-7,1,2,WOOD:5)
Block(-7,1,3,WOOD:5)
Block(-7,1,4,WOOD:5)
Block(-7,1,5,WOOD:5)
Block(-7,1,6,WOOD:5)
Block(-7,1,7,WOOD:5)
Block(-7,1,8,WOOD:5)
Block(-7,1,9,WOOD:5)
Block(-7,2,-4,SPRUCE_FENCE:0)
Block(-7,2,-3,SMOOTH_BRICK:0)
RandomBlock(-7,2,-2,DARK_OAK_FENCE:0,30,STONE:6,100)
Block(-7,2,-1,SMOOTH_BRICK:0)
Block(-7,2,0,DARK_OAK_STAIRS:2)
Block(-7,2,1,SPRUCE_DOOR:2)
Block(-7,2,2,SPRUCE_DOOR:2)
Block(-7,2,3,DARK_OAK_STAIRS:3)
Block(-7,2,4,SMOOTH_BRICK:0)
RandomBlock(-7,2,5,DARK_OAK_FENCE:0,30,STONE:6,100)
Block(-7,2,6,SMOOTH_BRICK:0)
Block(-7,2,7,SPRUCE_FENCE:0)
Block(-7,3,-4,SPRUCE_FENCE:0)
Block(-7,3,-3,SMOOTH_BRICK:0)
RandomBlock(-7,3,-2,DARK_OAK_FENCE:0,30,STONE:6,100)
Block(-7,3,-1,SMOOTH_BRICK:0)
Block(-7,3,0,DARK_OAK_STAIRS:6)
Block(-7,3,1,SPRUCE_DOOR:9)
Block(-7,3,2,SPRUCE_DOOR:8)
Block(-7,3,3,DARK_OAK_STAIRS:7)
Block(-7,3,4,SMOOTH_BRICK:0)
RandomBlock(-7,3,5,DARK_OAK_FENCE:0,30,STONE:6,100)
Block(-7,3,6,SMOOTH_BRICK:0)
Block(-7,3,7,SPRUCE_FENCE:0)
Block(-7,4,-4,WOOD:1)
Block(-7,4,-3,SMOOTH_BRICK:0)
RandomBlock(-7,4,-2,DARK_OAK_FENCE:0,30,STONE:6,100)
Block(-7,4,-1,SMOOTH_BRICK:0)
Block(-7,4,0,WOOD:1)
Block(-7,4,1,WOOD:1)
Block(-7,4,2,WOOD:1)
Block(-7,4,3,WOOD:1)
Block(-7,4,4,SMOOTH_BRICK:0)
RandomBlock(-7,4,5,DARK_OAK_FENCE:0,30,STONE:6,100)
Block(-7,4,6,SMOOTH_BRICK:0)
Block(-7,4,7,WOOD:1)
Block(-7,5,-4,SPRUCE_FENCE:0)
Block(-7,5,-3,SMOOTH_BRICK:0)
RandomBlock(-7,5,-2,DARK_OAK_FENCE:0,30,STONE:6,100)
Block(-7,5,-1,SMOOTH_BRICK:0)
Block(-7,5,0,SPRUCE_FENCE:0)
RandomBlock(-7,5,1,DARK_OAK_FENCE:0,30,STONE:6,100)
RandomBlock(-7,5,2,DARK_OAK_FENCE:0,30,STONE:6,100)
Block(-7,5,3,SPRUCE_FENCE:0)
Block(-7,5,4,SMOOTH_BRICK:0)
RandomBlock(-7,5,5,DARK_OAK_FENCE:0,30,STONE:6,100)
Block(-7,5,6,SMOOTH_BRICK:0)
Block(-7,5,7,SPRUCE_FENCE:0)
Block(-7,6,-4,WOOD:5)
Block(-7,6,-3,WOOD:5)
Block(-7,6,-2,WOOD:5)
Block(-7,6,-1,WOOD:5)
Block(-7,6,0,WOOD:5)
Block(-7,6,1,WOOD_STEP:13)
Block(-7,6,2,WOOD_STEP:13)
Block(-7,6,3,WOOD:5)
Block(-7,6,4,WOOD:5)
Block(-7,6,5,WOOD:5)
Block(-7,6,6,WOOD:5)
Block(-7,6,7,WOOD:5)
Block(-7,7,-4,SPRUCE_FENCE:0)
Block(-7,7,-3,SMOOTH_BRICK:0)
RandomBlock(-7,7,-2,DARK_OAK_FENCE:0,30,STONE:6,100)
Block(-7,7,-1,SMOOTH_BRICK:0)
Block(-7,7,0,STONE:6)
Block(-7,7,1,SPRUCE_DOOR:0)
Block(-7,7,2,SPRUCE_DOOR:0)
Block(-7,7,3,STONE:6)
Block(-7,7,4,SMOOTH_BRICK:0)
RandomBlock(-7,7,5,DARK_OAK_FENCE:0,30,STONE:6,100)
Block(-7,7,6,SMOOTH_BRICK:0)
Block(-7,7,7,SPRUCE_FENCE:0)
Block(-7,8,-4,SPRUCE_FENCE:0)
Block(-7,8,-3,SMOOTH_BRICK:0)
RandomBlock(-7,8,-2,DARK_OAK_FENCE:0,30,STONE:6,100)
Block(-7,8,-1,SMOOTH_BRICK:0)
Block(-7,8,0,STONE:6)
Block(-7,8,1,SPRUCE_DOOR:8)
Block(-7,8,2,SPRUCE_DOOR:9)
Block(-7,8,3,STONE:6)
Block(-7,8,4,SMOOTH_BRICK:0)
RandomBlock(-7,8,5,DARK_OAK_FENCE:0,30,STONE:6,100)
Block(-7,8,6,SMOOTH_BRICK:0)
Block(-7,8,7,SPRUCE_FENCE:0)
Block(-7,9,-4,WOOD:1)
Block(-7,9,-3,SMOOTH_BRICK:0)
RandomBlock(-7,9,-2,DARK_OAK_FENCE:0,30,STONE:6,100)
Block(-7,9,-1,SMOOTH_BRICK:0)
Block(-7,9,0,WOOD:1)
Block(-7,9,1,WOOD:1)
Block(-7,9,2,WOOD:1)
Block(-7,9,3,WOOD:1)
Block(-7,9,4,SMOOTH_BRICK:0)
RandomBlock(-7,9,5,DARK_OAK_FENCE:0,30,STONE:6,100)
Block(-7,9,6,SMOOTH_BRICK:0)
Block(-7,9,7,WOOD:1)
Block(-7,10,-4,WOOD:5)
Block(-7,10,-3,WOOD:5)
Block(-7,10,-2,WOOD:5)
Block(-7,10,-1,WOOD:5)
Block(-7,10,0,WOOD:5)
Block(-7,10,1,WOOD:5)
Block(-7,10,2,WOOD:5)
Block(-7,10,3,WOOD:5)
Block(-7,10,4,WOOD:5)
Block(-7,10,5,WOOD:5)
Block(-7,10,6,WOOD:5)
Block(-7,10,7,WOOD:5)
Block(-6,1,-6,WOOD:5)
Block(-6,1,-5,WOOD:5)
Block(-6,1,-4,WOOD:5)
Block(-6,1,-3,WOOD:5)
Block(-6,1,-2,WOOD:5)
Block(-6,1,-1,WOOD:5)
Block(-6,1,0,WOOD:5)
Block(-6,1,1,WOOD:5)
Block(-6,1,2,WOOD:5)
Block(-6,1,3,WOOD:5)
Block(-6,1,4,WOOD:5)
Block(-6,1,5,WOOD:5)
Block(-6,1,6,WOOD:5)
Block(-6,1,7,WOOD:5)
Block(-6,1,8,WOOD:5)
Block(-6,1,9,WOOD:5)
RandomBlock(-6,2,-5,DARK_OAK_FENCE:0,30,STONE:6,100)
RandomBlock(-6,2,-4,DARK_OAK_FENCE:0,30,STONE:6,100)
Block(-6,2,-3,AIR:0)
Block(-6,2,-2,AIR:0)
Block(-6,2,-1,SPRUCE_FENCE:0)
Block(-6,2,0,AIR:0)
Block(-6,2,1,CARPET:13)
Block(-6,2,2,CARPET:13)
Block(-6,2,3,AIR:0)
Block(-6,2,4,AIR:0)
Block(-6,2,5,AIR:0)
Block(-6,2,6,ANVIL:10)
RandomBlock(-6,2,7,DARK_OAK_FENCE:0,30,STONE:6,100)
RandomBlock(-6,2,8,DARK_OAK_FENCE:0,30,STONE:6,100)
RandomBlock(-6,3,-5,DARK_OAK_FENCE:0,30,STONE:6,100)
RandomBlock(-6,3,-4,DARK_OAK_FENCE:0,30,STONE:6,100)
Block(-6,3,-3,AIR:0)
Block(-6,3,-2,AIR:0)
Block(-6,3,-1,TORCH:5)
Block(-6,3,0,AIR:0)
Block(-6,3,1,AIR:0)
Block(-6,3,2,AIR:0)
Block(-6,3,3,AIR:0)
Block(-6,3,4,SMOOTH_BRICK:0)
Block(-6,3,5,AIR:0)
Block(-6,3,6,AIR:0)
RandomBlock(-6,3,7,DARK_OAK_FENCE:0,30,STONE:6,100)
RandomBlock(-6,3,8,DARK_OAK_FENCE:0,30,STONE:6,100)
Block(-6,4,-5,WOOD:1)
RandomBlock(-6,4,-4,DARK_OAK_FENCE:0,30,STONE:6,100)
Block(-6,4,-3,AIR:0)
Block(-6,4,-2,AIR:0)
Block(-6,4,-1,AIR:0)
Block(-6,4,0,AIR:0)
Block(-6,4,1,AIR:0)
Block(-6,4,2,AIR:0)
Block(-6,4,3,AIR:0)
Block(-6,4,4,SPRUCE_FENCE:0)
Block(-6,4,5,AIR:0)
Block(-6,4,6,AIR:0)
RandomBlock(-6,4,7,DARK_OAK_FENCE:0,30,STONE:6,100)
Block(-6,4,8,WOOD:1)
RandomBlock(-6,5,-5,DARK_OAK_FENCE:0,30,STONE:6,100)
RandomBlock(-6,5,-4,DARK_OAK_FENCE:0,30,STONE:6,100)
Block(-6,5,-3,AIR:0)
Block(-6,5,-2,AIR:0)
Block(-6,5,-1,AIR:0)
Block(-6,5,0,AIR:0)
Block(-6,5,1,AIR:0)
Block(-6,5,2,AIR:0)
Block(-6,5,3,AIR:0)
Block(-6,5,4,SPRUCE_FENCE:0)
Block(-6,5,5,AIR:0)
RandomBlock(-6,5,6,WALL_BANNER:5,../../NBT/Banners/banner_sun.nbt,50,WALL_BANNER:5,../../NBT/Banners/quarry_banner_0.nbt,10,WALL_BANNER:5,../../NBT/Banners/quarry_banner_1.nbt,10,WALL_BANNER:5,../../NBT/Banners/quarry_banner_2.nbt,10,WALL_BANNER:5,../../NBT/Banners/quarry_banner_3.nbt,10,WALL_BANNER:5,../../NBT/Banners/quarry_banner_4.nbt,100)
RandomBlock(-6,5,7,DARK_OAK_FENCE:0,30,STONE:6,100)
RandomBlock(-6,5,8,DARK_OAK_FENCE:0,30,STONE:6,100)
Block(-6,6,-5,WOOD_DOUBLE_STEP:5)
Block(-6,6,-4,WOOD_DOUBLE_STEP:5)
Block(-6,6,-3,WOOD_STEP:13)
Block(-6,6,-2,WOOD_STEP:13)
Block(-6,6,-1,WOOD_STEP:13)
Block(-6,6,0,WOOD:5)
Block(-6,6,1,WOOD_STEP:13)
Block(-6,6,2,WOOD_STEP:13)
Block(-6,6,3,WOOD:5)
Block(-6,6,4,WOOD_DOUBLE_STEP:5)
Block(-6,6,5,WOOD_STEP:13)
Block(-6,6,6,WOOD_STEP:13)
Block(-6,6,7,WOOD_DOUBLE_STEP:5)
Block(-6,6,8,WOOD_DOUBLE_STEP:5)
RandomBlock(-6,7,-5,DARK_OAK_FENCE:0,30,STONE:6,100)
RandomBlock(-6,7,-4,DARK_OAK_FENCE:0,30,STONE:6,100)
RandomBlock(-6,7,-3,AIR:0,20,CHEST:3,../../../../Chests/Loot/JunkChest_1.nbt,10,CHEST:3,../../../../Chests/Loot/JunkChest_2.nbt,10,CHEST:3,../../../../Chests/Loot/JunkChest_3.nbt,10,CHEST:3,../../../../Chests/Loot/JunkChest_4.nbt,10,CHEST:3,../../../../Chests/Loot/JunkChest_5.nbt,10,CHEST:3,../../../../Chests/Lore/HiddenMineWaste_1.nbt,1,CHEST:3,../../../../Chests/Lore/HiddenMineWaste_2.nbt,1,CHEST:3,../../../../Chests/Lore/HiddenMineWaste_3.nbt,1,CHEST:3,../../../../Chests/Lore/HiddenMineWaste_4.nbt,1,CHEST:3,../../../../Chests/Lore/HiddenMineWaste_5.nbt,1,CHEST:3,../../../../Chests/Loot/Common1.nbt,10,CHEST:3,../../../../Chests/Loot/Common2.nbt,10,CHEST:3,../../../../Chests/Loot/Common3.nbt,10,CHEST:3,../../../../Chests/Loot/Common4.nbt,10,CHEST:3,../../../../Chests/Loot/Common5.nbt,10,CHEST:3,../../../../Chests/Loot/Common6.nbt,10,CHEST:3,../../../../Chests/Loot/Common7.nbt,10,CHEST:3,../../../../Chests/Loot/Common8.nbt,10,CHEST:3,../../../../Chests/Loot/Common9.nbt,10,CHEST:3,../../../../Chests/Loot/Common10.nbt,10,CHEST:3,../../../../Chests/Loot/Common10.nbt,11,CHEST:3,../../../../Chests/Loot/Common12.nbt,10,CHEST:3,../../../../Chests/Loot/Common13.nbt,10,CHEST:3,../../../../Chests/Loot/Common14.nbt,10,CHEST:3,../../../../Chests/Loot/Common15.nbt,10,CHEST:3,../../../../Chests/Lore/HiddenMineWaste_1.nbt,2,CHEST:3,../../../../Chests/Lore/HiddenMineWaste_3.nbt,2,CHEST:3,../../../../Chests/Lore/HiddenMineWaste_4.nbt,2,CHEST:3,../../../../Chests/Lore/HiddenMineWaste_5.nbt,2,CHEST:3,../../../../Chests/Lore/HiddenMineWaste_5.nbt,2,CHEST:3,../../../../Chests/Loot/Rare1.nbt,5,CHEST:3,../../../../Chests/Loot/Rare2.nbt,5,CHEST:3,../../../../Chests/Loot/Rare3.nbt,5,CHEST:3,../../../../Chests/Loot/Rare4.nbt,5,CHEST:3,../../../../Chests/Loot/Rare5.nbt,5,CHEST:3,../../../../Chests/Loot/Rare6.nbt,5,CHEST:3,../../../../Chests/Loot/Rare7.nbt,5,CHEST:3,../../../../Chests/Loot/Rare8.nbt,5,CHEST:3,../../../../Chests/Loot/Rare9.nbt,5,CHEST:3,../../../../Chests/Loot/Rare10.nbt,5,CHEST:3,../../../../Chests/Loot/Rare11.nbt,5,CHEST:3,../../../../Chests/Loot/Rare12.nbt,5,CHEST:3,../../../../Chests/Loot/Rare13.nbt,5,CHEST:3,../../../../Chests/Loot/Rare14.nbt,5,CHEST:3,../../../../Chests/Loot/Rare15.nbt,5,CHEST:3,../../../../Chests/Loot/Epic1.nbt,2,CHEST:3,../../../../Chests/Loot/Epic2.nbt,2,CHEST:3,../../../../Chests/Loot/Epic3.nbt,2,CHEST:3,../../../../Chests/Loot/Epic4.nbt,2,CHEST:3,../../../../Chests/Loot/Epic5.nbt,2,CHEST:3,../../../../Chests/Loot/Epic6.nbt,2,CHEST:3,../../../../Chests/Loot/Epic7.nbt,2,CHEST:3,../../../../Chests/Loot/Epic8.nbt,2,CHEST:3,../../../../Chests/Loot/Epic9.nbt,2,CHEST:3,../../../../Chests/Loot/Epic10.nbt,2,CHEST:3,../../../../Chests/Loot/Epic11.nbt,2,CHEST:3,../../../../Chests/Loot/Epic12.nbt,2,CHEST:3,../../../../Chests/Loot/Epic13.nbt,2,CHEST:3,../../../../Chests/Loot/Epic14.nbt,2,CHEST:3,../../../../Chests/Loot/Epic15.nbt,5,CHEST:3,../../../../Chests/Loot/Rare1.nbt,5,CHEST:3,../../../../Chests/Loot/Rare2.nbt,5,CHEST:3,../../../../Chests/Loot/Rare3.nbt,5,CHEST:3,../../../../Chests/Loot/Rare4.nbt,5,CHEST:3,../../../../Chests/Loot/Rare5.nbt,10,CHEST:3,../../../../Chests/Loot/Rare6.nbt,10,CHEST:3,../../../../Chests/Loot/Rare7.nbt,10,CHEST:3,../../../../Chests/Loot/Rare8.nbt,10,CHEST:3,../../../../Chests/Loot/Rare9.nbt,10,CHEST:3,../../../../Chests/Loot/Rare10.nbt,15,CHEST:3,../../../../Chests/Loot/Rare11.nbt,15,CHEST:3,../../../../Chests/Loot/Rare12.nbt,15,CHEST:3,../../../../Chests/Loot/Rare13.nbt,15,CHEST:3,../../../../Chests/Loot/Rare14.nbt,15,CHEST:3,../../../../Chests/Loot/Rare15.nbt,15,CHEST:3,../../../../Chests/Loot/Epic15.nbt,100)
Block(-6,7,-2,AIR:0)
Block(-6,7,-1,SPRUCE_FENCE:0)
Block(-6,7,0,CARPET:13)
Block(-6,7,1,AIR:0)
Block(-6,7,2,AIR:0)
Block(-6,7,3,BED_BLOCK:0)
Block(-6,7,4,BED_BLOCK:8)
Block(-6,7,5,SMOOTH_BRICK:0)
Block(-6,7,6,SMOOTH_BRICK:0)
RandomBlock(-6,7,7,DARK_OAK_FENCE:0,30,STONE:6,100)
RandomBlock(-6,7,8,DARK_OAK_FENCE:0,30,STONE:6,100)
RandomBlock(-6,8,-5,DARK_OAK_FENCE:0,30,STONE:6,100)
RandomBlock(-6,8,-4,DARK_OAK_FENCE:0,30,STONE:6,100)
Block(-6,8,-3,AIR:0)
Block(-6,8,-2,AIR:0)
Block(-6,8,-1,TORCH:5)
Block(-6,8,0,AIR:0)
Block(-6,8,1,AIR:0)
Block(-6,8,2,AIR:0)
Block(-6,8,3,AIR:0)
Block(-6,8,4,AIR:0)
Block(-6,8,5,SMOOTH_BRICK:0)
Block(-6,8,6,SMOOTH_BRICK:0)
RandomBlock(-6,8,7,DARK_OAK_FENCE:0,30,STONE:6,100)
RandomBlock(-6,8,8,DARK_OAK_FENCE:0,30,STONE:6,100)
Block(-6,9,-5,WOOD:1)
RandomBlock(-6,9,-4,DARK_OAK_FENCE:0,30,STONE:6,100)
Block(-6,9,-3,AIR:0)
Block(-6,9,-2,AIR:0)
Block(-6,9,-1,AIR:0)
Block(-6,9,0,AIR:0)
Block(-6,9,1,AIR:0)
Block(-6,9,2,AIR:0)
Block(-6,9,3,AIR:0)
Block(-6,9,4,AIR:0)
Block(-6,9,5,WOOD_STEP:5)
Block(-6,9,6,WOOD_STEP:5)
RandomBlock(-6,9,7,DARK_OAK_FENCE:0,30,STONE:6,100)
Block(-6,9,8,WOOD:1)
Block(-6,10,-5,WOOD:5)
RandomBlock(-6,10,-4,DARK_OAK_FENCE:0,30,STONE:6,100)
Block(-6,10,-3,TRAP_DOOR:8)
Block(-6,10,-2,TRAP_DOOR:8)
Block(-6,10,-1,TRAP_DOOR:8)
Block(-6,10,0,WOOD:5)
Block(-6,10,1,TRAP_DOOR:8)
Block(-6,10,2,TRAP_DOOR:8)
Block(-6,10,3,WOOD:5)
Block(-6,10,4,TRAP_DOOR:8)
Block(-6,10,5,TRAP_DOOR:8)
Block(-6,10,6,TRAP_DOOR:8)
RandomBlock(-6,10,7,DARK_OAK_FENCE:0,30,STONE:6,100)
Block(-6,10,8,WOOD:5)
Block(-5,1,-6,WOOD:5)
Block(-5,1,-5,WOOD:5)
Block(-5,1,-4,WOOD:5)
Block(-5,1,-3,WOOD:5)
Block(-5,1,-2,WOOD:5)
Block(-5,1,-1,WOOD:5)
Block(-5,1,0,WOOD:5)
Block(-5,1,1,WOOD:5)
Block(-5,1,2,WOOD:5)
Block(-5,1,3,WOOD:5)
Block(-5,1,4,WOOD:5)
Block(-5,1,5,WOOD:5)
Block(-5,1,6,WOOD:5)
Block(-5,1,7,WOOD:5)
Block(-5,1,8,WOOD:5)
Block(-5,1,9,WOOD:5)
Block(-5,2,-6,SPRUCE_FENCE:0)
RandomBlock(-5,2,-5,DARK_OAK_FENCE:0,30,STONE:6,100)
Block(-5,2,-4,AIR:0)
Block(-5,2,-3,CARPET:13)
Block(-5,2,-2,CARPET:13)
Block(-5,2,-1,CARPET:13)
Block(-5,2,0,CARPET:13)
Block(-5,2,1,CARPET:13)
Block(-5,2,2,CARPET:13)
Block(-5,2,3,AIR:0)
Block(-5,2,4,AIR:0)
Block(-5,2,5,AIR:0)
Block(-5,2,6,AIR:0)
Block(-5,2,7,AIR:0)
RandomBlock(-5,2,8,DARK_OAK_FENCE:0,30,STONE:6,100)
Block(-5,2,9,SPRUCE_FENCE:0)
Block(-5,3,-6,SPRUCE_FENCE:0)
RandomBlock(-5,3,-5,DARK_OAK_FENCE:0,30,STONE:6,100)
Block(-5,3,-4,AIR:0)
Block(-5,3,-3,AIR:0)
Block(-5,3,-2,AIR:0)
Block(-5,3,-1,AIR:0)
Block(-5,3,0,AIR:0)
Block(-5,3,1,AIR:0)
Block(-5,3,2,AIR:0)
Block(-5,3,3,AIR:0)
Block(-5,3,4,SMOOTH_BRICK:0)
Block(-5,3,5,AIR:0)
Block(-5,3,6,AIR:0)
Block(-5,3,7,AIR:0)
RandomBlock(-5,3,8,DARK_OAK_FENCE:0,30,STONE:6,100)
Block(-5,3,9,SPRUCE_FENCE:0)
Block(-5,4,-6,WOOD:1)
RandomBlock(-5,4,-5,DARK_OAK_FENCE:0,30,STONE:6,100)
Block(-5,4,-4,AIR:0)
Block(-5,4,-3,AIR:0)
Block(-5,4,-2,AIR:0)
Block(-5,4,-1,AIR:0)
Block(-5,4,0,AIR:0)
Block(-5,4,1,AIR:0)
Block(-5,4,2,AIR:0)
Block(-5,4,3,AIR:0)
Block(-5,4,4,SPRUCE_FENCE:0)
Block(-5,4,5,AIR:0)
Block(-5,4,6,AIR:0)
Block(-5,4,7,AIR:0)
RandomBlock(-5,4,8,DARK_OAK_FENCE:0,30,STONE:6,100)
Block(-5,4,9,WOOD:1)
Block(-5,5,-6,SPRUCE_FENCE:0)
RandomBlock(-5,5,-5,DARK_OAK_FENCE:0,30,STONE:6,100)
Block(-5,5,-4,AIR:0)
Block(-5,5,-3,AIR:0)
Block(-5,5,-2,AIR:0)
Block(-5,5,-1,AIR:0)
Block(-5,5,0,AIR:0)
Block(-5,5,1,AIR:0)
Block(-5,5,2,AIR:0)
Block(-5,5,3,AIR:0)
Block(-5,5,4,SPRUCE_FENCE:0)
Block(-5,5,5,AIR:0)
Block(-5,5,6,AIR:0)
Block(-5,5,7,AIR:0)
RandomBlock(-5,5,8,DARK_OAK_FENCE:0,30,STONE:6,100)
Block(-5,5,9,SPRUCE_FENCE:0)
Block(-5,6,-6,WOOD:5)
Block(-5,6,-5,WOOD_DOUBLE_STEP:5)
Block(-5,6,-4,WOOD_STEP:13)
Block(-5,6,-3,WOOD_STEP:13)
Block(-5,6,-2,WOOD_STEP:13)
Block(-5,6,-1,WOOD_STEP:13)
Block(-5,6,0,WOOD:5)
Block(-5,6,1,WOOD_STEP:13)
Block(-5,6,2,WOOD_STEP:13)
Block(-5,6,3,WOOD:5)
Block(-5,6,4,WOOD_DOUBLE_STEP:5)
Block(-5,6,5,WOOD_STEP:13)
Block(-5,6,6,WOOD_STEP:13)
Block(-5,6,7,WOOD_STEP:13)
Block(-5,6,8,WOOD_DOUBLE_STEP:5)
Block(-5,6,9,WOOD:5)
Block(-5,7,-6,SPRUCE_FENCE:0)
RandomBlock(-5,7,-5,DARK_OAK_FENCE:0,30,STONE:6,100)
Block(-5,7,-4,AIR:0)
RandomBlock(-5,7,-3,AIR:0,20,CHEST:3,../../../../Chests/Loot/JunkChest_1.nbt,10,CHEST:3,../../../../Chests/Loot/JunkChest_2.nbt,10,CHEST:3,../../../../Chests/Loot/JunkChest_3.nbt,10,CHEST:3,../../../../Chests/Loot/JunkChest_4.nbt,10,CHEST:3,../../../../Chests/Loot/JunkChest_5.nbt,10,CHEST:3,../../../../Chests/Lore/HiddenMineWaste_1.nbt,1,CHEST:3,../../../../Chests/Lore/HiddenMineWaste_2.nbt,1,CHEST:3,../../../../Chests/Lore/HiddenMineWaste_3.nbt,1,CHEST:3,../../../../Chests/Lore/HiddenMineWaste_4.nbt,1,CHEST:3,../../../../Chests/Lore/HiddenMineWaste_5.nbt,1,CHEST:3,../../../../Chests/Loot/Common1.nbt,10,CHEST:3,../../../../Chests/Loot/Common2.nbt,10,CHEST:3,../../../../Chests/Loot/Common3.nbt,10,CHEST:3,../../../../Chests/Loot/Common4.nbt,10,CHEST:3,../../../../Chests/Loot/Common5.nbt,10,CHEST:3,../../../../Chests/Loot/Common6.nbt,10,CHEST:3,../../../../Chests/Loot/Common7.nbt,10,CHEST:3,../../../../Chests/Loot/Common8.nbt,10,CHEST:3,../../../../Chests/Loot/Common9.nbt,10,CHEST:3,../../../../Chests/Loot/Common10.nbt,10,CHEST:3,../../../../Chests/Loot/Common10.nbt,11,CHEST:3,../../../../Chests/Loot/Common12.nbt,10,CHEST:3,../../../../Chests/Loot/Common13.nbt,10,CHEST:3,../../../../Chests/Loot/Common14.nbt,10,CHEST:3,../../../../Chests/Loot/Common15.nbt,10,CHEST:3,../../../../Chests/Lore/HiddenMineWaste_1.nbt,2,CHEST:3,../../../../Chests/Lore/HiddenMineWaste_3.nbt,2,CHEST:3,../../../../Chests/Lore/HiddenMineWaste_4.nbt,2,CHEST:3,../../../../Chests/Lore/HiddenMineWaste_5.nbt,2,CHEST:3,../../../../Chests/Lore/HiddenMineWaste_5.nbt,2,CHEST:3,../../../../Chests/Loot/Rare1.nbt,5,CHEST:3,../../../../Chests/Loot/Rare2.nbt,5,CHEST:3,../../../../Chests/Loot/Rare3.nbt,5,CHEST:3,../../../../Chests/Loot/Rare4.nbt,5,CHEST:3,../../../../Chests/Loot/Rare5.nbt,5,CHEST:3,../../../../Chests/Loot/Rare6.nbt,5,CHEST:3,../../../../Chests/Loot/Rare7.nbt,5,CHEST:3,../../../../Chests/Loot/Rare8.nbt,5,CHEST:3,../../../../Chests/Loot/Rare9.nbt,5,CHEST:3,../../../../Chests/Loot/Rare10.nbt,5,CHEST:3,../../../../Chests/Loot/Rare11.nbt,5,CHEST:3,../../../../Chests/Loot/Rare12.nbt,5,CHEST:3,../../../../Chests/Loot/Rare13.nbt,5,CHEST:3,../../../../Chests/Loot/Rare14.nbt,5,CHEST:3,../../../../Chests/Loot/Rare15.nbt,5,CHEST:3,../../../../Chests/Loot/Epic1.nbt,2,CHEST:3,../../../../Chests/Loot/Epic2.nbt,2,CHEST:3,../../../../Chests/Loot/Epic3.nbt,2,CHEST:3,../../../../Chests/Loot/Epic4.nbt,2,CHEST:3,../../../../Chests/Loot/Epic5.nbt,2,CHEST:3,../../../../Chests/Loot/Epic6.nbt,2,CHEST:3,../../../../Chests/Loot/Epic7.nbt,2,CHEST:3,../../../../Chests/Loot/Epic8.nbt,2,CHEST:3,../../../../Chests/Loot/Epic9.nbt,2,CHEST:3,../../../../Chests/Loot/Epic10.nbt,2,CHEST:3,../../../../Chests/Loot/Epic11.nbt,2,CHEST:3,../../../../Chests/Loot/Epic12.nbt,2,CHEST:3,../../../../Chests/Loot/Epic13.nbt,2,CHEST:3,../../../../Chests/Loot/Epic14.nbt,2,CHEST:3,../../../../Chests/Loot/Epic15.nbt,5,CHEST:3,../../../../Chests/Loot/Rare1.nbt,5,CHEST:3,../../../../Chests/Loot/Rare2.nbt,5,CHEST:3,../../../../Chests/Loot/Rare3.nbt,5,CHEST:3,../../../../Chests/Loot/Rare4.nbt,5,CHEST:3,../../../../Chests/Loot/Rare5.nbt,10,CHEST:3,../../../../Chests/Loot/Rare6.nbt,10,CHEST:3,../../../../Chests/Loot/Rare7.nbt,10,CHEST:3,../../../../Chests/Loot/Rare8.nbt,10,CHEST:3,../../../../Chests/Loot/Rare9.nbt,10,CHEST:3,../../../../Chests/Loot/Rare10.nbt,15,CHEST:3,../../../../Chests/Loot/Rare11.nbt,15,CHEST:3,../../../../Chests/Loot/Rare12.nbt,15,CHEST:3,../../../../Chests/Loot/Rare13.nbt,15,CHEST:3,../../../../Chests/Loot/Rare14.nbt,15,CHEST:3,../../../../Chests/Loot/Rare15.nbt,15,CHEST:3,../../../../Chests/Loot/Epic15.nbt,100)
Block(-5,7,-2,AIR:0)
Block(-5,7,-1,AIR:0)
Block(-5,7,0,AIR:0)
Block(-5,7,1,CARPET:13)
Block(-5,7,2,AIR:0)
Block(-5,7,3,BED_BLOCK:0)
Block(-5,7,4,BED_BLOCK:8)
Block(-5,7,5,SMOOTH_BRICK:0)
Block(-5,7,6,BED_BLOCK:9)
Block(-5,7,7,BED_BLOCK:9)
RandomBlock(-5,7,8,DARK_OAK_FENCE:0,30,STONE:6,100)
Block(-5,7,9,SPRUCE_FENCE:0)
Block(-5,8,-6,SPRUCE_FENCE:0)
RandomBlock(-5,8,-5,DARK_OAK_FENCE:0,30,STONE:6,100)
Block(-5,8,-4,AIR:0)
Block(-5,8,-3,AIR:0)
Block(-5,8,-2,AIR:0)
Block(-5,8,-1,AIR:0)
Block(-5,8,0,AIR:0)
Block(-5,8,1,AIR:0)
Block(-5,8,2,AIR:0)
Block(-5,8,3,AIR:0)
Block(-5,8,4,AIR:0)
Block(-5,8,5,SMOOTH_BRICK:0)
Block(-5,8,6,AIR:0)
Block(-5,8,7,AIR:0)
RandomBlock(-5,8,8,DARK_OAK_FENCE:0,30,STONE:6,100)
Block(-5,8,9,SPRUCE_FENCE:0)
Block(-5,9,-6,WOOD:1)
RandomBlock(-5,9,-5,DARK_OAK_FENCE:0,30,STONE:6,100)
Block(-5,9,-4,AIR:0)
Block(-5,9,-3,AIR:0)
Block(-5,9,-2,AIR:0)
Block(-5,9,-1,AIR:0)
Block(-5,9,0,AIR:0)
Block(-5,9,1,AIR:0)
Block(-5,9,2,AIR:0)
Block(-5,9,3,AIR:0)
Block(-5,9,4,AIR:0)
Block(-5,9,5,WOOD_STEP:5)
Block(-5,9,6,AIR:0)
Block(-5,9,7,AIR:0)
RandomBlock(-5,9,8,DARK_OAK_FENCE:0,30,STONE:6,100)
Block(-5,9,9,WOOD:1)
Block(-5,10,-6,WOOD:5)
RandomBlock(-5,10,-5,DARK_OAK_FENCE:0,30,STONE:6,100)
Block(-5,10,-4,TRAP_DOOR:8)
Block(-5,10,-3,TRAP_DOOR:8)
Block(-5,10,-2,TRAP_DOOR:8)
Block(-5,10,-1,TRAP_DOOR:8)
Block(-5,10,0,WOOD:5)
Block(-5,10,1,TRAP_DOOR:8)
Block(-5,10,2,TRAP_DOOR:8)
Block(-5,10,3,WOOD:5)
Block(-5,10,4,TRAP_DOOR:8)
Block(-5,10,5,TRAP_DOOR:8)
Block(-5,10,6,TRAP_DOOR:8)
Block(-5,10,7,TRAP_DOOR:8)
RandomBlock(-5,10,8,DARK_OAK_FENCE:0,30,STONE:6,100)
Block(-5,10,9,WOOD:5)
Block(-4,1,-6,WOOD:5)
Block(-4,1,-5,WOOD:5)
Block(-4,1,-4,WOOD:5)
Block(-4,1,-3,WOOD:5)
Block(-4,1,-2,WOOD:5)
Block(-4,1,-1,WOOD:5)
Block(-4,1,0,WOOD:5)
Block(-4,1,1,WOOD:5)
Block(-4,1,2,WOOD:5)
Block(-4,1,3,WOOD:5)
Block(-4,1,4,WOOD:5)
Block(-4,1,5,WOOD:5)
Block(-4,1,6,WOOD:5)
Block(-4,1,7,WOOD:5)
Block(-4,1,8,WOOD:5)
Block(-4,1,9,WOOD:5)
Block(-4,2,-6,SMOOTH_BRICK:0)
Block(-4,2,-5,AIR:0)
Block(-4,2,-4,AIR:0)
Block(-4,2,-3,AIR:0)
Block(-4,2,-2,CARPET:13)
Block(-4,2,-1,AIR:0)
Block(-4,2,0,CARPET:13)
Block(-4,2,1,CARPET:13)
Block(-4,2,2,AIR:0)
Block(-4,2,3,AIR:0)
Block(-4,2,4,AIR:0)
Block(-4,2,5,AIR:0)
Block(-4,2,6,AIR:0)
Block(-4,2,7,AIR:0)
Block(-4,2,8,AIR:0)
Block(-4,2,9,SMOOTH_BRICK:0)
Block(-4,3,-6,SMOOTH_BRICK:0)
Block(-4,3,-5,AIR:0)
Block(-4,3,-4,AIR:0)
Block(-4,3,-3,AIR:0)
Block(-4,3,-2,AIR:0)
Block(-4,3,-1,AIR:0)
Block(-4,3,0,AIR:0)
Block(-4,3,1,AIR:0)
Block(-4,3,2,AIR:0)
Block(-4,3,3,AIR:0)
Block(-4,3,4,SMOOTH_BRICK:0)
Block(-4,3,5,AIR:0)
Block(-4,3,6,AIR:0)
Block(-4,3,7,AIR:0)
Block(-4,3,8,AIR:0)
Block(-4,3,9,SMOOTH_BRICK:0)
Block(-4,4,-6,SMOOTH_BRICK:0)
Block(-4,4,-5,AIR:0)
Block(-4,4,-4,AIR:0)
Block(-4,4,-3,AIR:0)
Block(-4,4,-2,AIR:0)
Block(-4,4,-1,AIR:0)
Block(-4,4,0,AIR:0)
Block(-4,4,1,AIR:0)
Block(-4,4,2,AIR:0)
Block(-4,4,3,AIR:0)
Block(-4,4,4,SPRUCE_FENCE:0)
Block(-4,4,5,AIR:0)
Block(-4,4,6,AIR:0)
Block(-4,4,7,AIR:0)
Block(-4,4,8,AIR:0)
Block(-4,4,9,SMOOTH_BRICK:0)
Block(-4,5,-6,SMOOTH_BRICK:0)
Block(-4,5,-5,AIR:0)
Block(-4,5,-4,AIR:0)
Block(-4,5,-3,AIR:0)
Block(-4,5,-2,AIR:0)
Block(-4,5,-1,AIR:0)
Block(-4,5,0,AIR:0)
Block(-4,5,1,AIR:0)
Block(-4,5,2,AIR:0)
Block(-4,5,3,AIR:0)
Block(-4,5,4,SPRUCE_FENCE:0)
Block(-4,5,5,AIR:0)
Block(-4,5,6,AIR:0)
Block(-4,5,7,AIR:0)
RandomBlock(-4,5,8,WALL_BANNER:2,../../NBT/Banners/banner_sun.nbt,50,WALL_BANNER:2,../../NBT/Banners/quarry_banner_0.nbt,10,WALL_BANNER:2,../../NBT/Banners/quarry_banner_1.nbt,10,WALL_BANNER:2,../../NBT/Banners/quarry_banner_2.nbt,10,WALL_BANNER:2,../../NBT/Banners/quarry_banner_3.nbt,10,WALL_BANNER:2,../../NBT/Banners/quarry_banner_4.nbt,100)
Block(-4,5,9,SMOOTH_BRICK:0)
Block(-4,6,-6,WOOD:5)
Block(-4,6,-5,WOOD_STEP:13)
Block(-4,6,-4,WOOD_STEP:13)
Block(-4,6,-3,WOOD_STEP:13)
Block(-4,6,-2,WOOD_STEP:13)
Block(-4,6,-1,WOOD_STEP:13)
Block(-4,6,0,WOOD:5)
Block(-4,6,1,WOOD_STEP:13)
Block(-4,6,2,WOOD_STEP:13)
Block(-4,6,3,WOOD:5)
Block(-4,6,4,WOOD_DOUBLE_STEP:5)
Block(-4,6,5,WOOD_STEP:13)
Block(-4,6,6,WOOD_STEP:13)
Block(-4,6,7,WOOD_STEP:13)
Block(-4,6,8,WOOD_STEP:13)
Block(-4,6,9,WOOD:5)
Block(-4,7,-6,SMOOTH_BRICK:0)
Block(-4,7,-5,SMOOTH_BRICK:0)
Block(-4,7,-4,SMOOTH_BRICK:0)
Block(-4,7,-3,SMOOTH_BRICK:0)
Block(-4,7,-2,SMOOTH_BRICK:0)
Block(-4,7,-1,SPRUCE_DOOR:4)
Block(-4,7,0,SMOOTH_BRICK:0)
Block(-4,7,1,SMOOTH_BRICK:0)
Block(-4,7,2,SMOOTH_BRICK:0)
Block(-4,7,3,SMOOTH_BRICK:0)
Block(-4,7,4,SMOOTH_BRICK:0)
Block(-4,7,5,SMOOTH_BRICK:0)
Block(-4,7,6,BED_BLOCK:1)
Block(-4,7,7,BED_BLOCK:1)
Block(-4,7,8,SPRUCE_FENCE:0)
Block(-4,7,9,SMOOTH_BRICK:0)
Block(-4,8,-6,SMOOTH_BRICK:0)
Block(-4,8,-5,SMOOTH_BRICK:0)
Block(-4,8,-4,SMOOTH_BRICK:0)
Block(-4,8,-3,SMOOTH_BRICK:0)
Block(-4,8,-2,SMOOTH_BRICK:0)
Block(-4,8,-1,SPRUCE_DOOR:8)
Block(-4,8,0,SMOOTH_BRICK:0)
Block(-4,8,1,SMOOTH_BRICK:0)
Block(-4,8,2,SMOOTH_BRICK:0)
Block(-4,8,3,SMOOTH_BRICK:0)
Block(-4,8,4,SMOOTH_BRICK:0)
Block(-4,8,5,SMOOTH_BRICK:0)
Block(-4,8,6,AIR:0)
Block(-4,8,7,AIR:0)
Block(-4,8,8,TORCH:5)
Block(-4,8,9,SMOOTH_BRICK:0)
Block(-4,9,-6,SMOOTH_BRICK:0)
Block(-4,9,-5,WOOD_STEP:5)
Block(-4,9,-4,WOOD_STEP:5)
Block(-4,9,-3,WOOD_STEP:5)
Block(-4,9,-2,WOOD_STEP:5)
Block(-4,9,-1,WOOD_STEP:5)
Block(-4,9,0,WOOD_STEP:5)
Block(-4,9,1,WOOD_STEP:5)
Block(-4,9,2,WOOD_STEP:5)
Block(-4,9,3,WOOD_STEP:5)
Block(-4,9,4,WOOD_STEP:5)
Block(-4,9,5,WOOD_STEP:5)
Block(-4,9,6,AIR:0)
Block(-4,9,7,AIR:0)
Block(-4,9,8,AIR:0)
Block(-4,9,9,SMOOTH_BRICK:0)
Block(-4,10,-6,WOOD:5)
Block(-4,10,-5,TRAP_DOOR:8)
Block(-4,10,-4,TRAP_DOOR:8)
Block(-4,10,-3,TRAP_DOOR:8)
Block(-4,10,-2,TRAP_DOOR:8)
Block(-4,10,-1,TRAP_DOOR:8)
Block(-4,10,0,WOOD:5)
Block(-4,10,1,TRAP_DOOR:8)
Block(-4,10,2,TRAP_DOOR:8)
Block(-4,10,3,WOOD:5)
Block(-4,10,4,TRAP_DOOR:8)
Block(-4,10,5,TRAP_DOOR:8)
Block(-4,10,6,TRAP_DOOR:8)
Block(-4,10,7,TRAP_DOOR:8)
Block(-4,10,8,TRAP_DOOR:8)
Block(-4,10,9,WOOD:5)
Block(-3,1,-6,WOOD:5)
Block(-3,1,-5,WOOD:5)
Block(-3,1,-4,WOOD:5)
Block(-3,1,-3,WOOD:5)
Block(-3,1,-2,WOOD:5)
Block(-3,1,-1,WOOD:5)
Block(-3,1,0,WOOD:5)
Block(-3,1,1,WOOD:5)
Block(-3,1,2,WOOD:5)
Block(-3,1,3,WOOD:5)
Block(-3,1,4,WOOD:5)
Block(-3,1,5,WOOD:5)
Block(-3,1,6,WOOD:5)
Block(-3,1,7,WOOD:5)
Block(-3,1,8,WOOD:5)
Block(-3,1,9,WOOD:5)
RandomBlock(-3,2,-6,DARK_OAK_FENCE:0,30,STONE:6,100)
Block(-3,2,-5,AIR:0)
Block(-3,2,-4,AIR:0)
Block(-3,2,-3,AIR:0)
Block(-3,2,-2,CARPET:13)
Block(-3,2,-1,SPRUCE_FENCE:0)
Block(-3,2,0,SMOOTH_BRICK:0)
Block(-3,2,1,AIR:0)
Block(-3,2,2,AIR:0)
Block(-3,2,3,AIR:0)
Block(-3,2,4,SMOOTH_BRICK:0)
Block(-3,2,5,AIR:0)
Block(-3,2,6,DARK_OAK_STAIRS:7)
Block(-3,2,7,WOOD_STEP:13)
Block(-3,2,8,DARK_OAK_STAIRS:6)
RandomBlock(-3,2,9,DARK_OAK_FENCE:0,30,STONE:6,100)
RandomBlock(-3,3,-6,DARK_OAK_FENCE:0,30,STONE:6,100)
Block(-3,3,-5,AIR:0)
Block(-3,3,-4,AIR:0)
Block(-3,3,-3,AIR:0)
Block(-3,3,-2,AIR:0)
Block(-3,3,-1,TORCH:5)
Block(-3,3,0,SMOOTH_BRICK:0)
Block(-3,3,1,SMOOTH_BRICK:0)
Block(-3,3,2,SMOOTH_BRICK:0)
Block(-3,3,3,SMOOTH_BRICK:0)
Block(-3,3,4,SMOOTH_BRICK:0)
Block(-3,3,5,AIR:0)
Block(-3,3,6,AIR:0)
Block(-3,3,7,AIR:0)
Block(-3,3,8,AIR:0)
RandomBlock(-3,3,9,DARK_OAK_FENCE:0,30,STONE:6,100)
RandomBlock(-3,4,-6,DARK_OAK_FENCE:0,30,STONE:6,100)
Block(-3,4,-5,AIR:0)
Block(-3,4,-4,AIR:0)
Block(-3,4,-3,AIR:0)
Block(-3,4,-2,AIR:0)
Block(-3,4,-1,AIR:0)
Block(-3,4,0,SPRUCE_FENCE:0)
Block(-3,4,1,SPRUCE_FENCE:0)
Block(-3,4,2,SPRUCE_FENCE:0)
Block(-3,4,3,SPRUCE_FENCE:0)
Block(-3,4,4,SPRUCE_FENCE:0)
Block(-3,4,5,AIR:0)
Block(-3,4,6,AIR:0)
Block(-3,4,7,AIR:0)
Block(-3,4,8,AIR:0)
RandomBlock(-3,4,9,DARK_OAK_FENCE:0,30,STONE:6,100)
RandomBlock(-3,5,-6,DARK_OAK_FENCE:0,30,STONE:6,100)
Block(-3,5,-5,AIR:0)
Block(-3,5,-4,AIR:0)
Block(-3,5,-3,AIR:0)
Block(-3,5,-2,AIR:0)
Block(-3,5,-1,AIR:0)
Block(-3,5,0,SPRUCE_FENCE:0)
Block(-3,5,1,SPRUCE_FENCE:0)
Block(-3,5,2,SPRUCE_FENCE:0)
Block(-3,5,3,SPRUCE_FENCE:0)
Block(-3,5,4,SPRUCE_FENCE:0)
Block(-3,5,5,AIR:0)
Block(-3,5,6,AIR:0)
Block(-3,5,7,AIR:0)
Block(-3,5,8,AIR:0)
RandomBlock(-3,5,9,DARK_OAK_FENCE:0,30,STONE:6,100)
Block(-3,6,-6,WOOD:5)
Block(-3,6,-5,WOOD_STEP:13)
Block(-3,6,-4,WOOD_STEP:13)
Block(-3,6,-3,WOOD_STEP:13)
Block(-3,6,-2,WOOD_STEP:13)
Block(-3,6,-1,WOOD_STEP:13)
Block(-3,6,0,WOOD:5)
Block(-3,6,1,WOOD_DOUBLE_STEP:5)
Block(-3,6,2,WOOD_DOUBLE_STEP:5)
Block(-3,6,3,WOOD:5)
Block(-3,6,4,WOOD_DOUBLE_STEP:5)
Block(-3,6,5,WOOD_DOUBLE_STEP:5)
Block(-3,6,6,WOOD_STEP:13)
Block(-3,6,7,WOOD_STEP:13)
Block(-3,6,8,WOOD_STEP:13)
Block(-3,6,9,WOOD:5)
RandomBlock(-3,7,-6,DARK_OAK_FENCE:0,30,STONE:6,100)
Block(-3,7,-5,BED_BLOCK:10)
Block(-3,7,-4,BED_BLOCK:2)
Block(-3,7,-3,SPRUCE_FENCE:0)
Block(-3,7,-2,SMOOTH_BRICK:0)
Block(-3,7,-1,AIR:0)
Block(-3,7,0,SPRUCE_FENCE:0)
Block(-3,7,1,SPRUCE_FENCE:0)
Block(-3,7,2,SPRUCE_FENCE:0)
Block(-3,7,3,SPRUCE_FENCE:0)
Block(-3,7,4,SPRUCE_FENCE:0)
Block(-3,7,5,SMOOTH_BRICK:0)
Block(-3,7,6,AIR:0)
Block(-3,7,7,AIR:0)
Block(-3,7,8,AIR:0)
RandomBlock(-3,7,9,DARK_OAK_FENCE:0,30,STONE:6,100)
RandomBlock(-3,8,-6,DARK_OAK_FENCE:0,30,STONE:6,100)
Block(-3,8,-5,AIR:0)
Block(-3,8,-4,AIR:0)
Block(-3,8,-3,TORCH:5)
Block(-3,8,-2,SMOOTH_BRICK:0)
Block(-3,8,-1,AIR:0)
Block(-3,8,0,SPRUCE_FENCE:0)
Block(-3,8,1,AIR:0)
Block(-3,8,2,AIR:0)
Block(-3,8,3,SPRUCE_FENCE:0)
Block(-3,8,4,AIR:0)
Block(-3,8,5,SMOOTH_BRICK:0)
Block(-3,8,6,AIR:0)
Block(-3,8,7,AIR:0)
Block(-3,8,8,AIR:0)
RandomBlock(-3,8,9,DARK_OAK_FENCE:0,30,STONE:6,100)
RandomBlock(-3,9,-6,DARK_OAK_FENCE:0,30,STONE:6,100)
Block(-3,9,-5,AIR:0)
Block(-3,9,-4,AIR:0)
Block(-3,9,-3,AIR:0)
Block(-3,9,-2,WOOD_STEP:5)
Block(-3,9,-1,AIR:0)
Block(-3,9,0,SPRUCE_FENCE:0)
Block(-3,9,1,AIR:0)
Block(-3,9,2,AIR:0)
Block(-3,9,3,SPRUCE_FENCE:0)
Block(-3,9,4,AIR:0)
Block(-3,9,5,WOOD_STEP:5)
Block(-3,9,6,AIR:0)
Block(-3,9,7,AIR:0)
Block(-3,9,8,AIR:0)
RandomBlock(-3,9,9,DARK_OAK_FENCE:0,30,STONE:6,100)
Block(-3,10,-6,WOOD:5)
Block(-3,10,-5,TRAP_DOOR:8)
Block(-3,10,-4,TRAP_DOOR:8)
Block(-3,10,-3,TRAP_DOOR:8)
Block(-3,10,-2,TRAP_DOOR:8)
Block(-3,10,-1,TRAP_DOOR:8)
Block(-3,10,0,WOOD:5)
Block(-3,10,1,TRAP_DOOR:8)
Block(-3,10,2,TRAP_DOOR:8)
Block(-3,10,3,WOOD:5)
Block(-3,10,4,TRAP_DOOR:8)
Block(-3,10,5,TRAP_DOOR:8)
Block(-3,10,6,TRAP_DOOR:8)
Block(-3,10,7,TRAP_DOOR:8)
Block(-3,10,8,TRAP_DOOR:8)
Block(-3,10,9,WOOD:5)
Block(-2,1,-6,WOOD:5)
Block(-2,1,-5,WOOD:5)
Block(-2,1,-4,WOOD:5)
Block(-2,1,-3,WOOD:5)
Block(-2,1,-2,WOOD:5)
Block(-2,1,-1,WOOD:5)
Block(-2,1,0,WOOD:5)
Block(-2,1,1,WOOD:5)
Block(-2,1,2,WOOD:5)
Block(-2,1,3,WOOD:5)
Block(-2,1,4,WOOD:5)
Block(-2,1,5,WOOD:5)
Block(-2,1,6,WOOD:5)
Block(-2,1,7,WOOD:5)
Block(-2,1,8,WOOD:5)
Block(-2,1,9,WOOD:5)
Block(-2,2,-6,SMOOTH_BRICK:0)
Block(-2,2,-5,AIR:0)
Block(-2,2,-4,AIR:0)
Block(-2,2,-3,AIR:0)
Block(-2,2,-2,CARPET:13)
Block(-2,2,-1,CARPET:13)
Block(-2,2,0,SPRUCE_WOOD_STAIRS:2)
Block(-2,2,1,SPRUCE_WOOD_STAIRS:7)
Block(-2,2,2,AIR:0)
Block(-2,2,3,AIR:0)
Block(-2,2,4,AIR:0)
Block(-2,2,5,AIR:0)
Block(-2,2,6,AIR:0)
Block(-2,2,7,AIR:0)
Block(-2,2,8,SPRUCE_FENCE:0)
Block(-2,2,9,SMOOTH_BRICK:0)
Block(-2,3,-6,SMOOTH_BRICK:0)
Block(-2,3,-5,AIR:0)
Block(-2,3,-4,AIR:0)
Block(-2,3,-3,AIR:0)
Block(-2,3,-2,AIR:0)
Block(-2,3,-1,AIR:0)
Block(-2,3,0,AIR:0)
Block(-2,3,1,SPRUCE_WOOD_STAIRS:2)
Block(-2,3,2,SPRUCE_WOOD_STAIRS:7)
Block(-2,3,3,AIR:0)
Block(-2,3,4,AIR:0)
Block(-2,3,5,AIR:0)
Block(-2,3,6,AIR:0)
Block(-2,3,7,AIR:0)
Block(-2,3,8,TORCH:5)
Block(-2,3,9,SMOOTH_BRICK:0)
Block(-2,4,-6,SMOOTH_BRICK:0)
Block(-2,4,-5,AIR:0)
Block(-2,4,-4,AIR:0)
Block(-2,4,-3,AIR:0)
Block(-2,4,-2,AIR:0)
Block(-2,4,-1,AIR:0)
Block(-2,4,0,AIR:0)
Block(-2,4,1,AIR:0)
Block(-2,4,2,SPRUCE_WOOD_STAIRS:2)
Block(-2,4,3,SPRUCE_WOOD_STAIRS:7)
Block(-2,4,4,AIR:0)
Block(-2,4,5,AIR:0)
Block(-2,4,6,AIR:0)
Block(-2,4,7,AIR:0)
Block(-2,4,8,AIR:0)
Block(-2,4,9,SMOOTH_BRICK:0)
Block(-2,5,-6,SMOOTH_BRICK:0)
RandomBlock(-2,5,-5,WALL_BANNER:3,../../NBT/Banners/banner_sun.nbt,50,WALL_BANNER:3,../../NBT/Banners/quarry_banner_0.nbt,10,WALL_BANNER:3,../../NBT/Banners/quarry_banner_1.nbt,10,WALL_BANNER:3,../../NBT/Banners/quarry_banner_2.nbt,10,WALL_BANNER:3,../../NBT/Banners/quarry_banner_3.nbt,10,WALL_BANNER:3,../../NBT/Banners/quarry_banner_4.nbt,100)
Block(-2,5,-4,AIR:0)
Block(-2,5,-3,AIR:0)
Block(-2,5,-2,AIR:0)
Block(-2,5,-1,AIR:0)
Block(-2,5,0,AIR:0)
Block(-2,5,1,AIR:0)
Block(-2,5,2,AIR:0)
Block(-2,5,3,SPRUCE_WOOD_STAIRS:2)
Block(-2,5,4,SPRUCE_WOOD_STAIRS:7)
Block(-2,5,5,AIR:0)
Block(-2,5,6,AIR:0)
Block(-2,5,7,AIR:0)
Block(-2,5,8,AIR:0)
Block(-2,5,9,SMOOTH_BRICK:0)
Block(-2,6,-6,WOOD:5)
Block(-2,6,-5,WOOD_STEP:13)
Block(-2,6,-4,WOOD_STEP:13)
Block(-2,6,-3,WOOD_STEP:13)
Block(-2,6,-2,WOOD_STEP:13)
Block(-2,6,-1,WOOD_STEP:13)
Block(-2,6,0,TRAP_DOOR:11)
Block(-2,6,1,TRAP_DOOR:11)
Block(-2,6,2,AIR:0)
Block(-2,6,3,AIR:0)
Block(-2,6,4,AIR:0)
Block(-2,6,5,WOOD_DOUBLE_STEP:5)
Block(-2,6,6,WOOD_STEP:13)
Block(-2,6,7,WOOD_STEP:13)
Block(-2,6,8,WOOD_STEP:13)
Block(-2,6,9,WOOD:5)
Block(-2,7,-6,SMOOTH_BRICK:0)
Block(-2,7,-5,CARPET:13)
Block(-2,7,-4,CARPET:13)
Block(-2,7,-3,AIR:0)
Block(-2,7,-2,SPRUCE_DOOR:1)
Block(-2,7,-1,AIR:0)
Block(-2,7,0,SPRUCE_FENCE:0)
Block(-2,7,1,AIR:0)
Block(-2,7,2,AIR:0)
Block(-2,7,3,AIR:0)
Block(-2,7,4,AIR:0)
Block(-2,7,5,SMOOTH_BRICK:0)
Block(-2,7,6,AIR:0)
Block(-2,7,7,AIR:0)
RandomBlock(-2,7,8,AIR:0,20,CHEST:4,../../../../Chests/Loot/JunkChest_1.nbt,10,CHEST:4,../../../../Chests/Loot/JunkChest_2.nbt,10,CHEST:4,../../../../Chests/Loot/JunkChest_3.nbt,10,CHEST:4,../../../../Chests/Loot/JunkChest_4.nbt,10,CHEST:4,../../../../Chests/Loot/JunkChest_5.nbt,10,CHEST:4,../../../../Chests/Lore/HiddenMineWaste_1.nbt,1,CHEST:4,../../../../Chests/Lore/HiddenMineWaste_2.nbt,1,CHEST:4,../../../../Chests/Lore/HiddenMineWaste_3.nbt,1,CHEST:4,../../../../Chests/Lore/HiddenMineWaste_4.nbt,1,CHEST:4,../../../../Chests/Lore/HiddenMineWaste_5.nbt,1,CHEST:4,../../../../Chests/Loot/Common1.nbt,10,CHEST:4,../../../../Chests/Loot/Common2.nbt,10,CHEST:4,../../../../Chests/Loot/Common3.nbt,10,CHEST:4,../../../../Chests/Loot/Common4.nbt,10,CHEST:4,../../../../Chests/Loot/Common5.nbt,10,CHEST:4,../../../../Chests/Loot/Common6.nbt,10,CHEST:4,../../../../Chests/Loot/Common7.nbt,10,CHEST:4,../../../../Chests/Loot/Common8.nbt,10,CHEST:4,../../../../Chests/Loot/Common9.nbt,10,CHEST:4,../../../../Chests/Loot/Common10.nbt,10,CHEST:4,../../../../Chests/Loot/Common10.nbt,11,CHEST:4,../../../../Chests/Loot/Common12.nbt,10,CHEST:4,../../../../Chests/Loot/Common13.nbt,10,CHEST:4,../../../../Chests/Loot/Common14.nbt,10,CHEST:4,../../../../Chests/Loot/Common15.nbt,10,CHEST:4,../../../../Chests/Lore/HiddenMineWaste_1.nbt,2,CHEST:4,../../../../Chests/Lore/HiddenMineWaste_3.nbt,2,CHEST:4,../../../../Chests/Lore/HiddenMineWaste_4.nbt,2,CHEST:4,../../../../Chests/Lore/HiddenMineWaste_5.nbt,2,CHEST:4,../../../../Chests/Lore/HiddenMineWaste_5.nbt,2,CHEST:4,../../../../Chests/Loot/Rare1.nbt,5,CHEST:4,../../../../Chests/Loot/Rare2.nbt,5,CHEST:4,../../../../Chests/Loot/Rare3.nbt,5,CHEST:4,../../../../Chests/Loot/Rare4.nbt,5,CHEST:4,../../../../Chests/Loot/Rare5.nbt,5,CHEST:4,../../../../Chests/Loot/Rare6.nbt,5,CHEST:4,../../../../Chests/Loot/Rare7.nbt,5,CHEST:4,../../../../Chests/Loot/Rare8.nbt,5,CHEST:4,../../../../Chests/Loot/Rare9.nbt,5,CHEST:4,../../../../Chests/Loot/Rare10.nbt,5,CHEST:4,../../../../Chests/Loot/Rare11.nbt,5,CHEST:4,../../../../Chests/Loot/Rare12.nbt,5,CHEST:4,../../../../Chests/Loot/Rare13.nbt,5,CHEST:4,../../../../Chests/Loot/Rare14.nbt,5,CHEST:4,../../../../Chests/Loot/Rare15.nbt,5,CHEST:4,../../../../Chests/Loot/Epic1.nbt,2,CHEST:4,../../../../Chests/Loot/Epic2.nbt,2,CHEST:4,../../../../Chests/Loot/Epic3.nbt,2,CHEST:4,../../../../Chests/Loot/Epic4.nbt,2,CHEST:4,../../../../Chests/Loot/Epic5.nbt,2,CHEST:4,../../../../Chests/Loot/Epic6.nbt,2,CHEST:4,../../../../Chests/Loot/Epic7.nbt,2,CHEST:4,../../../../Chests/Loot/Epic8.nbt,2,CHEST:4,../../../../Chests/Loot/Epic9.nbt,2,CHEST:4,../../../../Chests/Loot/Epic10.nbt,2,CHEST:4,../../../../Chests/Loot/Epic11.nbt,2,CHEST:4,../../../../Chests/Loot/Epic12.nbt,2,CHEST:4,../../../../Chests/Loot/Epic13.nbt,2,CHEST:4,../../../../Chests/Loot/Epic14.nbt,2,CHEST:4,../../../../Chests/Loot/Epic15.nbt,5,CHEST:4,../../../../Chests/Loot/Rare1.nbt,5,CHEST:4,../../../../Chests/Loot/Rare2.nbt,5,CHEST:4,../../../../Chests/Loot/Rare3.nbt,5,CHEST:4,../../../../Chests/Loot/Rare4.nbt,5,CHEST:4,../../../../Chests/Loot/Rare5.nbt,10,CHEST:4,../../../../Chests/Loot/Rare6.nbt,10,CHEST:4,../../../../Chests/Loot/Rare7.nbt,10,CHEST:4,../../../../Chests/Loot/Rare8.nbt,10,CHEST:4,../../../../Chests/Loot/Rare9.nbt,10,CHEST:4,../../../../Chests/Loot/Rare10.nbt,15,CHEST:4,../../../../Chests/Loot/Rare11.nbt,15,CHEST:4,../../../../Chests/Loot/Rare12.nbt,15,CHEST:4,../../../../Chests/Loot/Rare13.nbt,15,CHEST:4,../../../../Chests/Loot/Rare14.nbt,15,CHEST:4,../../../../Chests/Loot/Rare15.nbt,15,CHEST:4,../../../../Chests/Loot/Epic15.nbt,100)
Block(-2,7,9,SMOOTH_BRICK:0)
Block(-2,8,-6,SMOOTH_BRICK:0)
Block(-2,8,-5,AIR:0)
Block(-2,8,-4,AIR:0)
Block(-2,8,-3,AIR:0)
Block(-2,8,-2,SPRUCE_DOOR:9)
Block(-2,8,-1,AIR:0)
Block(-2,8,0,AIR:0)
Block(-2,8,1,AIR:0)
Block(-2,8,2,AIR:0)
Block(-2,8,3,AIR:0)
Block(-2,8,4,AIR:0)
Block(-2,8,5,SPRUCE_FENCE:0)
Block(-2,8,6,AIR:0)
Block(-2,8,7,AIR:0)
Block(-2,8,8,AIR:0)
Block(-2,8,9,SMOOTH_BRICK:0)
Block(-2,9,-6,SMOOTH_BRICK:0)
Block(-2,9,-5,AIR:0)
Block(-2,9,-4,AIR:0)
Block(-2,9,-3,AIR:0)
Block(-2,9,-2,WOOD_STEP:5)
Block(-2,9,-1,AIR:0)
Block(-2,9,0,AIR:0)
Block(-2,9,1,AIR:0)
Block(-2,9,2,AIR:0)
Block(-2,9,3,AIR:0)
Block(-2,9,4,AIR:0)
Block(-2,9,5,WOOD_STEP:5)
Block(-2,9,6,AIR:0)
Block(-2,9,7,AIR:0)
Block(-2,9,8,AIR:0)
Block(-2,9,9,SMOOTH_BRICK:0)
Block(-2,10,-6,WOOD:5)
Block(-2,10,-5,TRAP_DOOR:8)
Block(-2,10,-4,TRAP_DOOR:8)
Block(-2,10,-3,TRAP_DOOR:8)
Block(-2,10,-2,TRAP_DOOR:8)
Block(-2,10,-1,TRAP_DOOR:8)
Block(-2,10,0,WOOD:5)
Block(-2,10,1,TRAP_DOOR:8)
Block(-2,10,2,TRAP_DOOR:8)
Block(-2,10,3,WOOD:5)
Block(-2,10,4,TRAP_DOOR:8)
Block(-2,10,5,TRAP_DOOR:8)
Block(-2,10,6,TRAP_DOOR:8)
Block(-2,10,7,TRAP_DOOR:8)
Block(-2,10,8,TRAP_DOOR:8)
Block(-2,10,9,WOOD:5)
Block(-1,0,-6,LOG:1)
Block(-1,0,9,LOG:1)
Block(-1,1,-6,WOOD:5)
Block(-1,1,-5,WOOD:5)
Block(-1,1,-4,WOOD:5)
Block(-1,1,-3,WOOD:5)
Block(-1,1,-2,WOOD:5)
Block(-1,1,-1,WOOD:5)
Block(-1,1,0,WOOD:5)
Block(-1,1,1,WOOD:5)
Block(-1,1,2,WOOD:5)
Block(-1,1,3,WOOD:5)
Block(-1,1,4,WOOD:5)
Block(-1,1,5,WOOD:5)
Block(-1,1,6,WOOD:5)
Block(-1,1,7,WOOD:5)
Block(-1,1,8,WOOD:5)
Block(-1,1,9,WOOD:5)
Block(-1,2,-6,DARK_OAK_STAIRS:0)
Block(-1,2,-5,AIR:0)
Block(-1,2,-4,AIR:0)
Block(-1,2,-3,CARPET:13)
Block(-1,2,-2,CARPET:13)
Block(-1,2,-1,AIR:0)
Block(-1,2,0,SPRUCE_FENCE:0)
Block(-1,2,1,AIR:0)
Block(-1,2,2,AIR:0)
Block(-1,2,3,SPRUCE_FENCE:0)
Block(-1,2,4,AIR:0)
Block(-1,2,5,AIR:0)
Block(-1,2,6,AIR:0)
Block(-1,2,7,AIR:0)
Block(-1,2,8,AIR:0)
Block(-1,2,9,DARK_OAK_STAIRS:0)
Block(-1,3,-6,DARK_OAK_STAIRS:4)
Block(-1,3,-5,AIR:0)
Block(-1,3,-4,AIR:0)
Block(-1,3,-3,AIR:0)
Block(-1,3,-2,AIR:0)
Block(-1,3,-1,AIR:0)
Block(-1,3,0,SPRUCE_FENCE:0)
Block(-1,3,1,AIR:0)
Block(-1,3,2,AIR:0)
Block(-1,3,3,SPRUCE_FENCE:0)
Block(-1,3,4,AIR:0)
Block(-1,3,5,AIR:0)
Block(-1,3,6,AIR:0)
Block(-1,3,7,AIR:0)
Block(-1,3,8,AIR:0)
Block(-1,3,9,DARK_OAK_STAIRS:4)
Block(-1,4,-6,WOOD:1)
Block(-1,4,-5,AIR:0)
Block(-1,4,-4,AIR:0)
Block(-1,4,-3,AIR:0)
Block(-1,4,-2,AIR:0)
Block(-1,4,-1,AIR:0)
Block(-1,4,0,WOOD:1)
Block(-1,4,1,WOOD:1)
Block(-1,4,2,WOOD:1)
Block(-1,4,3,WOOD:1)
Block(-1,4,4,AIR:0)
Block(-1,4,5,AIR:0)
Block(-1,4,6,AIR:0)
Block(-1,4,7,AIR:0)
Block(-1,4,8,AIR:0)
Block(-1,4,9,WOOD:1)
Block(-1,5,-6,SPRUCE_FENCE:0)
Block(-1,5,-5,AIR:0)
Block(-1,5,-4,AIR:0)
Block(-1,5,-3,AIR:0)
Block(-1,5,-2,AIR:0)
Block(-1,5,-1,AIR:0)
Block(-1,5,0,SPRUCE_FENCE:0)
Block(-1,5,1,AIR:0)
Block(-1,5,2,AIR:0)
Block(-1,5,3,SPRUCE_FENCE:0)
Block(-1,5,4,SPRUCE_WOOD_STAIRS:5)
Block(-1,5,5,AIR:0)
Block(-1,5,6,AIR:0)
Block(-1,5,7,AIR:0)
Block(-1,5,8,AIR:0)
Block(-1,5,9,SMOOTH_BRICK:0)
Block(-1,6,-6,WOOD:5)
Block(-1,6,-5,WOOD:5)
Block(-1,6,-4,WOOD:5)
Block(-1,6,-3,WOOD:5)
Block(-1,6,-2,WOOD:5)
Block(-1,6,-1,WOOD:5)
Block(-1,6,0,WOOD:5)
Block(-1,6,1,WOOD:5)
Block(-1,6,2,WOOD:5)
Block(-1,6,3,WOOD:5)
Block(-1,6,4,SPRUCE_WOOD_STAIRS:0)
Block(-1,6,5,WOOD:5)
Block(-1,6,6,WOOD:5)
Block(-1,6,7,WOOD:5)
Block(-1,6,8,WOOD:5)
Block(-1,6,9,WOOD:5)
Block(-1,7,-6,STONE:6)
Block(-1,7,-5,SMOOTH_BRICK:0)
Block(-1,7,-4,SMOOTH_BRICK:0)
Block(-1,7,-3,SMOOTH_BRICK:0)
Block(-1,7,-2,SMOOTH_BRICK:0)
Block(-1,7,-1,CARPET:13)
Block(-1,7,0,SPRUCE_FENCE:0)
Block(-1,7,1,SPRUCE_FENCE:0)
Block(-1,7,2,SPRUCE_FENCE:0)
Block(-1,7,3,SPRUCE_FENCE:0)
Block(-1,7,4,AIR:0)
Block(-1,7,5,SMOOTH_BRICK:0)
Block(-1,7,6,SMOOTH_BRICK:0)
Block(-1,7,7,AIR:0)
Block(-1,7,8,SMOOTH_BRICK:0)
Block(-1,7,9,STONE:6)
Block(-1,8,-6,STONE:6)
Block(-1,8,-5,SPRUCE_FENCE:0)
Block(-1,8,-4,SPRUCE_FENCE:0)
Block(-1,8,-3,SMOOTH_BRICK:0)
Block(-1,8,-2,SMOOTH_BRICK:0)
Block(-1,8,-1,AIR:0)
Block(-1,8,0,SPRUCE_FENCE:0)
Block(-1,8,1,AIR:0)
Block(-1,8,2,AIR:0)
Block(-1,8,3,SPRUCE_FENCE:0)
Block(-1,8,4,AIR:0)
Block(-1,8,5,SMOOTH_BRICK:0)
Block(-1,8,6,SMOOTH_BRICK:0)
Block(-1,8,7,AIR:0)
Block(-1,8,8,SMOOTH_BRICK:0)
Block(-1,8,9,STONE:6)
Block(-1,9,-6,WOOD:1)
Block(-1,9,-5,WOOD_STEP:5)
Block(-1,9,-4,WOOD_STEP:5)
Block(-1,9,-3,WOOD_STEP:5)
Block(-1,9,-2,WOOD_STEP:5)
Block(-1,9,-1,AIR:0)
Block(-1,9,0,WOOD:1)
Block(-1,9,1,WOOD:1)
Block(-1,9,2,WOOD:1)
Block(-1,9,3,WOOD:1)
Block(-1,9,4,AIR:0)
Block(-1,9,5,WOOD_STEP:5)
Block(-1,9,6,WOOD_STEP:5)
Block(-1,9,7,WOOD_STEP:5)
Block(-1,9,8,WOOD_STEP:5)
Block(-1,9,9,WOOD:1)
Block(-1,10,-6,WOOD:5)
Block(-1,10,-5,WOOD:5)
Block(-1,10,-4,WOOD:5)
Block(-1,10,-3,WOOD:5)
Block(-1,10,-2,WOOD:5)
Block(-1,10,-1,WOOD:5)
Block(-1,10,0,WOOD:5)
Block(-1,10,1,TRAP_DOOR:8)
Block(-1,10,2,TRAP_DOOR:8)
Block(-1,10,3,WOOD:5)
Block(-1,10,4,WOOD:5)
Block(-1,10,5,WOOD:5)
Block(-1,10,6,WOOD:5)
Block(-1,10,7,WOOD:5)
Block(-1,10,8,WOOD:5)
Block(-1,10,9,WOOD:5)
Block(0,1,-6,WOOD:5)
Block(0,1,-5,WOOD:5)
Block(0,1,-4,WOOD:5)
Block(0,1,-3,WOOD:5)
Block(0,1,-2,WOOD:5)
Block(0,1,-1,WOOD:5)
Block(0,1,0,WOOD:5)
Block(0,1,1,WOOD:5)
Block(0,1,2,WOOD:5)
Block(0,1,3,WOOD:5)
Block(0,1,4,WOOD:5)
Block(0,1,5,WOOD:5)
Block(0,1,6,WOOD:5)
Block(0,1,7,WOOD:5)
Block(0,1,8,WOOD:5)
Block(0,1,9,WOOD:5)
Block(0,2,-6,SPRUCE_DOOR:3)
Block(0,2,-5,CARPET:13)
Block(0,2,-4,CARPET:13)
Block(0,2,-3,CARPET:13)
Block(0,2,-2,CARPET:13)
Block(0,2,-1,CARPET:13)
Block(0,2,0,CARPET:13)
Block(0,2,1,CARPET:13)
Block(0,2,2,CARPET:13)
Block(0,2,3,AIR:0)
Block(0,2,4,AIR:0)
Block(0,2,5,AIR:0)
Block(0,2,6,AIR:0)
Block(0,2,7,AIR:0)
Block(0,2,8,AIR:0)
Block(0,2,9,SPRUCE_DOOR:1)
Block(0,3,-6,SPRUCE_DOOR:8)
Block(0,3,-5,AIR:0)
Block(0,3,-4,AIR:0)
Block(0,3,-3,AIR:0)
Block(0,3,-2,AIR:0)
Block(0,3,-1,AIR:0)
Block(0,3,0,AIR:0)
Block(0,3,1,AIR:0)
Block(0,3,2,AIR:0)
Block(0,3,3,AIR:0)
Block(0,3,4,AIR:0)
Block(0,3,5,AIR:0)
Block(0,3,6,AIR:0)
Block(0,3,7,AIR:0)
Block(0,3,8,AIR:0)
Block(0,3,9,SPRUCE_DOOR:9)
Block(0,4,-6,WOOD:1)
Block(0,4,-5,AIR:0)
Block(0,4,-4,AIR:0)
Block(0,4,-3,AIR:0)
Block(0,4,-2,AIR:0)
Block(0,4,-1,AIR:0)
Block(0,4,0,WOOD:1)
Block(0,4,1,AIR:0)
Block(0,4,2,AIR:0)
Block(0,4,3,WOOD:1)
Block(0,4,4,AIR:0)
Block(0,4,5,AIR:0)
Block(0,4,6,AIR:0)
Block(0,4,7,AIR:0)
Block(0,4,8,AIR:0)
Block(0,4,9,WOOD:1)
RandomBlock(0,5,-6,DARK_OAK_FENCE:0,30,STONE:6,100)
Block(0,5,-5,AIR:0)
Block(0,5,-4,AIR:0)
Block(0,5,-3,AIR:0)
Block(0,5,-2,AIR:0)
Block(0,5,-1,AIR:0)
Block(0,5,0,AIR:0)
Block(0,5,1,AIR:0)
Block(0,5,2,AIR:0)
Block(0,5,3,AIR:0)
Block(0,5,4,AIR:0)
Block(0,5,5,AIR:0)
Block(0,5,6,AIR:0)
Block(0,5,7,AIR:0)
Block(0,5,8,AIR:0)
Block(0,5,9,SMOOTH_BRICK:0)
Block(0,6,-6,WOOD_STEP:13)
Block(0,6,-5,WOOD_STEP:13)
Block(0,6,-4,WOOD_STEP:13)
Block(0,6,-3,WOOD_STEP:13)
Block(0,6,-2,WOOD_STEP:13)
Block(0,6,-1,WOOD_STEP:13)
Block(0,6,0,WOOD:5)
Block(0,6,1,TRAP_DOOR:9)
Block(0,6,2,TRAP_DOOR:9)
Block(0,6,3,WOOD:5)
Block(0,6,4,SPRUCE_WOOD_STAIRS:5)
Block(0,6,5,WOOD_STEP:13)
Block(0,6,6,WOOD_STEP:13)
Block(0,6,7,WOOD_STEP:13)
Block(0,6,8,WOOD_STEP:13)
Block(0,6,9,WOOD_STEP:13)
Block(0,7,-6,SPRUCE_DOOR:1)
Block(0,7,-5,AIR:0)
RandomBlock(0,7,-4,AIR:0,20,CHEST:5,../../../../Chests/Loot/JunkChest_1.nbt,10,CHEST:5,../../../../Chests/Loot/JunkChest_2.nbt,10,CHEST:5,../../../../Chests/Loot/JunkChest_3.nbt,10,CHEST:5,../../../../Chests/Loot/JunkChest_4.nbt,10,CHEST:5,../../../../Chests/Loot/JunkChest_5.nbt,10,CHEST:5,../../../../Chests/Lore/HiddenMineWaste_1.nbt,1,CHEST:5,../../../../Chests/Lore/HiddenMineWaste_2.nbt,1,CHEST:5,../../../../Chests/Lore/HiddenMineWaste_3.nbt,1,CHEST:5,../../../../Chests/Lore/HiddenMineWaste_4.nbt,1,CHEST:5,../../../../Chests/Lore/HiddenMineWaste_5.nbt,1,CHEST:5,../../../../Chests/Loot/Common1.nbt,10,CHEST:5,../../../../Chests/Loot/Common2.nbt,10,CHEST:5,../../../../Chests/Loot/Common3.nbt,10,CHEST:5,../../../../Chests/Loot/Common4.nbt,10,CHEST:5,../../../../Chests/Loot/Common5.nbt,10,CHEST:5,../../../../Chests/Loot/Common6.nbt,10,CHEST:5,../../../../Chests/Loot/Common7.nbt,10,CHEST:5,../../../../Chests/Loot/Common8.nbt,10,CHEST:5,../../../../Chests/Loot/Common9.nbt,10,CHEST:5,../../../../Chests/Loot/Common10.nbt,10,CHEST:5,../../../../Chests/Loot/Common10.nbt,11,CHEST:5,../../../../Chests/Loot/Common12.nbt,10,CHEST:5,../../../../Chests/Loot/Common13.nbt,10,CHEST:5,../../../../Chests/Loot/Common14.nbt,10,CHEST:5,../../../../Chests/Loot/Common15.nbt,10,CHEST:5,../../../../Chests/Lore/HiddenMineWaste_1.nbt,2,CHEST:5,../../../../Chests/Lore/HiddenMineWaste_3.nbt,2,CHEST:5,../../../../Chests/Lore/HiddenMineWaste_4.nbt,2,CHEST:5,../../../../Chests/Lore/HiddenMineWaste_5.nbt,2,CHEST:5,../../../../Chests/Lore/HiddenMineWaste_5.nbt,2,CHEST:5,../../../../Chests/Loot/Rare1.nbt,5,CHEST:5,../../../../Chests/Loot/Rare2.nbt,5,CHEST:5,../../../../Chests/Loot/Rare3.nbt,5,CHEST:5,../../../../Chests/Loot/Rare4.nbt,5,CHEST:5,../../../../Chests/Loot/Rare5.nbt,5,CHEST:5,../../../../Chests/Loot/Rare6.nbt,5,CHEST:5,../../../../Chests/Loot/Rare7.nbt,5,CHEST:5,../../../../Chests/Loot/Rare8.nbt,5,CHEST:5,../../../../Chests/Loot/Rare9.nbt,5,CHEST:5,../../../../Chests/Loot/Rare10.nbt,5,CHEST:5,../../../../Chests/Loot/Rare11.nbt,5,CHEST:5,../../../../Chests/Loot/Rare12.nbt,5,CHEST:5,../../../../Chests/Loot/Rare13.nbt,5,CHEST:5,../../../../Chests/Loot/Rare14.nbt,5,CHEST:5,../../../../Chests/Loot/Rare15.nbt,5,CHEST:5,../../../../Chests/Loot/Epic1.nbt,2,CHEST:5,../../../../Chests/Loot/Epic2.nbt,2,CHEST:5,../../../../Chests/Loot/Epic3.nbt,2,CHEST:5,../../../../Chests/Loot/Epic4.nbt,2,CHEST:5,../../../../Chests/Loot/Epic5.nbt,2,CHEST:5,../../../../Chests/Loot/Epic6.nbt,2,CHEST:5,../../../../Chests/Loot/Epic7.nbt,2,CHEST:5,../../../../Chests/Loot/Epic8.nbt,2,CHEST:5,../../../../Chests/Loot/Epic9.nbt,2,CHEST:5,../../../../Chests/Loot/Epic10.nbt,2,CHEST:5,../../../../Chests/Loot/Epic11.nbt,2,CHEST:5,../../../../Chests/Loot/Epic12.nbt,2,CHEST:5,../../../../Chests/Loot/Epic13.nbt,2,CHEST:5,../../../../Chests/Loot/Epic14.nbt,2,CHEST:5,../../../../Chests/Loot/Epic15.nbt,5,CHEST:5,../../../../Chests/Loot/Rare1.nbt,5,CHEST:5,../../../../Chests/Loot/Rare2.nbt,5,CHEST:5,../../../../Chests/Loot/Rare3.nbt,5,CHEST:5,../../../../Chests/Loot/Rare4.nbt,5,CHEST:5,../../../../Chests/Loot/Rare5.nbt,10,CHEST:5,../../../../Chests/Loot/Rare6.nbt,10,CHEST:5,../../../../Chests/Loot/Rare7.nbt,10,CHEST:5,../../../../Chests/Loot/Rare8.nbt,10,CHEST:5,../../../../Chests/Loot/Rare9.nbt,10,CHEST:5,../../../../Chests/Loot/Rare10.nbt,15,CHEST:5,../../../../Chests/Loot/Rare11.nbt,15,CHEST:5,../../../../Chests/Loot/Rare12.nbt,15,CHEST:5,../../../../Chests/Loot/Rare13.nbt,15,CHEST:5,../../../../Chests/Loot/Rare14.nbt,15,CHEST:5,../../../../Chests/Loot/Rare15.nbt,15,CHEST:5,../../../../Chests/Loot/Epic15.nbt,100)
Block(0,7,-3,WORKBENCH:0)
Block(0,7,-2,SMOOTH_BRICK:0)
Block(0,7,-1,CARPET:13)
Block(0,7,0,CARPET:13)
Block(0,7,1,CARPET:13)
Block(0,7,2,CARPET:13)
Block(0,7,3,AIR:0)
Block(0,7,4,AIR:0)
Block(0,7,5,SMOOTH_BRICK:0)
Block(0,7,6,CARPET:13)
Block(0,7,7,AIR:0)
Block(0,7,8,AIR:0)
Block(0,7,9,SPRUCE_DOOR:3)
Block(0,8,-6,SPRUCE_DOOR:9)
Block(0,8,-5,AIR:0)
Block(0,8,-4,AIR:0)
Block(0,8,-3,AIR:0)
Block(0,8,-2,SMOOTH_BRICK:0)
RandomBlock(0,8,-1,WALL_BANNER:3,../../NBT/Banners/banner_sun.nbt,50,WALL_BANNER:3,../../NBT/Banners/quarry_banner_0.nbt,10,WALL_BANNER:3,../../NBT/Banners/quarry_banner_1.nbt,10,WALL_BANNER:3,../../NBT/Banners/quarry_banner_2.nbt,10,WALL_BANNER:3,../../NBT/Banners/quarry_banner_3.nbt,10,WALL_BANNER:3,../../NBT/Banners/quarry_banner_4.nbt,100)
Block(0,8,0,AIR:0)
Block(0,8,1,AIR:0)
Block(0,8,2,AIR:0)
Block(0,8,3,AIR:0)
Block(0,8,4,AIR:0)
Block(0,8,5,SMOOTH_BRICK:0)
Block(0,8,6,AIR:0)
Block(0,8,7,AIR:0)
Block(0,8,8,AIR:0)
Block(0,8,9,SPRUCE_DOOR:8)
Block(0,9,-6,WOOD:1)
Block(0,9,-5,AIR:0)
Block(0,9,-4,AIR:0)
Block(0,9,-3,AIR:0)
Block(0,9,-2,WOOD_STEP:5)
Block(0,9,-1,AIR:0)
Block(0,9,0,WOOD:1)
Block(0,9,1,AIR:0)
Block(0,9,2,AIR:0)
Block(0,9,3,WOOD:1)
Block(0,9,4,AIR:0)
Block(0,9,5,WOOD_STEP:5)
Block(0,9,6,AIR:0)
Block(0,9,7,AIR:0)
Block(0,9,8,AIR:0)
Block(0,9,9,WOOD:1)
Block(0,10,-6,WOOD:5)
Block(0,10,-5,TRAP_DOOR:8)
Block(0,10,-4,TRAP_DOOR:8)
Block(0,10,-3,TRAP_DOOR:8)
Block(0,10,-2,TRAP_DOOR:8)
Block(0,10,-1,TRAP_DOOR:8)
Block(0,10,0,TRAP_DOOR:8)
Block(0,10,1,TRAP_DOOR:8)
Block(0,10,2,TRAP_DOOR:8)
Block(0,10,3,TRAP_DOOR:8)
Block(0,10,4,TRAP_DOOR:8)
Block(0,10,5,TRAP_DOOR:8)
Block(0,10,6,TRAP_DOOR:8)
Block(0,10,7,TRAP_DOOR:8)
Block(0,10,8,TRAP_DOOR:8)
Block(0,10,9,WOOD:5)
Block(1,1,-6,WOOD:5)
Block(1,1,-5,WOOD:5)
Block(1,1,-4,WOOD:5)
Block(1,1,-3,WOOD:5)
Block(1,1,-2,WOOD:5)
Block(1,1,-1,WOOD:5)
Block(1,1,0,WOOD:5)
Block(1,1,1,WOOD:5)
Block(1,1,2,WOOD:5)
Block(1,1,3,WOOD:5)
Block(1,1,4,WOOD:5)
Block(1,1,5,WOOD:5)
Block(1,1,6,WOOD:5)
Block(1,1,7,WOOD:5)
Block(1,1,8,WOOD:5)
Block(1,1,9,WOOD:5)
Block(1,2,-6,SPRUCE_DOOR:3)
Block(1,2,-5,CARPET:13)
Block(1,2,-4,CARPET:13)
Block(1,2,-3,AIR:0)
Block(1,2,-2,CARPET:13)
Block(1,2,-1,CARPET:13)
Block(1,2,0,CARPET:13)
Block(1,2,1,CARPET:13)
Block(1,2,2,CARPET:13)
Block(1,2,3,AIR:0)
Block(1,2,4,AIR:0)
Block(1,2,5,AIR:0)
Block(1,2,6,AIR:0)
Block(1,2,7,AIR:0)
Block(1,2,8,AIR:0)
Block(1,2,9,SPRUCE_DOOR:1)
Block(1,3,-6,SPRUCE_DOOR:9)
Block(1,3,-5,AIR:0)
Block(1,3,-4,AIR:0)
Block(1,3,-3,AIR:0)
Block(1,3,-2,AIR:0)
Block(1,3,-1,AIR:0)
Block(1,3,0,AIR:0)
Block(1,3,1,AIR:0)
Block(1,3,2,AIR:0)
Block(1,3,3,AIR:0)
Block(1,3,4,AIR:0)
Block(1,3,5,AIR:0)
Block(1,3,6,AIR:0)
Block(1,3,7,AIR:0)
Block(1,3,8,AIR:0)
Block(1,3,9,SPRUCE_DOOR:8)
Block(1,4,-6,WOOD:1)
Block(1,4,-5,AIR:0)
Block(1,4,-4,AIR:0)
Block(1,4,-3,AIR:0)
Block(1,4,-2,AIR:0)
Block(1,4,-1,AIR:0)
Block(1,4,0,WOOD:1)
Block(1,4,1,AIR:0)
Block(1,4,2,AIR:0)
Block(1,4,3,WOOD:1)
Block(1,4,4,AIR:0)
Block(1,4,5,AIR:0)
Block(1,4,6,AIR:0)
Block(1,4,7,AIR:0)
Block(1,4,8,AIR:0)
Block(1,4,9,WOOD:1)
RandomBlock(1,5,-6,DARK_OAK_FENCE:0,30,STONE:6,100)
Block(1,5,-5,AIR:0)
Block(1,5,-4,AIR:0)
Block(1,5,-3,AIR:0)
Block(1,5,-2,AIR:0)
Block(1,5,-1,AIR:0)
Block(1,5,0,AIR:0)
Block(1,5,1,AIR:0)
Block(1,5,2,AIR:0)
Block(1,5,3,AIR:0)
Block(1,5,4,AIR:0)
Block(1,5,5,AIR:0)
Block(1,5,6,AIR:0)
Block(1,5,7,AIR:0)
Block(1,5,8,AIR:0)
Block(1,5,9,SMOOTH_BRICK:0)
Block(1,6,-6,WOOD_STEP:13)
Block(1,6,-5,WOOD_STEP:13)
Block(1,6,-4,WOOD_STEP:13)
Block(1,6,-3,WOOD_STEP:13)
Block(1,6,-2,WOOD_STEP:13)
Block(1,6,-1,WOOD_STEP:13)
Block(1,6,0,WOOD:5)
Block(1,6,1,TRAP_DOOR:9)
Block(1,6,2,TRAP_DOOR:9)
Block(1,6,3,WOOD:5)
Block(1,6,4,WOOD_STEP:13)
Block(1,6,5,WOOD_STEP:13)
Block(1,6,6,WOOD_STEP:13)
Block(1,6,7,WOOD_STEP:13)
Block(1,6,8,WOOD_STEP:13)
Block(1,6,9,WOOD_STEP:13)
Block(1,7,-6,SPRUCE_DOOR:1)
Block(1,7,-5,AIR:0)
Block(1,7,-4,CARPET:13)
Block(1,7,-3,CARPET:13)
Block(1,7,-2,SMOOTH_BRICK:0)
Block(1,7,-1,AIR:0)
Block(1,7,0,CARPET:13)
Block(1,7,1,CARPET:13)
Block(1,7,2,CARPET:13)
Block(1,7,3,AIR:0)
Block(1,7,4,AIR:0)
Block(1,7,5,SPRUCE_DOOR:7)
Block(1,7,6,AIR:0)
Block(1,7,7,CARPET:13)
Block(1,7,8,AIR:0)
Block(1,7,9,SPRUCE_DOOR:3)
Block(1,8,-6,SPRUCE_DOOR:8)
Block(1,8,-5,AIR:0)
Block(1,8,-4,AIR:0)
Block(1,8,-3,AIR:0)
Block(1,8,-2,SMOOTH_BRICK:0)
Block(1,8,-1,AIR:0)
Block(1,8,0,AIR:0)
Block(1,8,1,AIR:0)
Block(1,8,2,AIR:0)
Block(1,8,3,AIR:0)
Block(1,8,4,AIR:0)
Block(1,8,5,SPRUCE_DOOR:9)
Block(1,8,6,AIR:0)
Block(1,8,7,AIR:0)
Block(1,8,8,AIR:0)
Block(1,8,9,SPRUCE_DOOR:9)
Block(1,9,-6,WOOD:1)
Block(1,9,-5,AIR:0)
Block(1,9,-4,AIR:0)
Block(1,9,-3,AIR:0)
Block(1,9,-2,WOOD_STEP:5)
Block(1,9,-1,AIR:0)
Block(1,9,0,WOOD:1)
Block(1,9,1,AIR:0)
Block(1,9,2,AIR:0)
Block(1,9,3,WOOD:1)
Block(1,9,4,AIR:0)
Block(1,9,5,WOOD_STEP:5)
Block(1,9,6,AIR:0)
Block(1,9,7,AIR:0)
Block(1,9,8,AIR:0)
Block(1,9,9,WOOD:1)
Block(1,10,-6,WOOD:5)
Block(1,10,-5,TRAP_DOOR:8)
Block(1,10,-4,TRAP_DOOR:8)
Block(1,10,-3,TRAP_DOOR:8)
Block(1,10,-2,TRAP_DOOR:8)
Block(1,10,-1,TRAP_DOOR:8)
Block(1,10,0,TRAP_DOOR:8)
Block(1,10,1,TRAP_DOOR:8)
Block(1,10,2,TRAP_DOOR:8)
Block(1,10,3,TRAP_DOOR:8)
Block(1,10,4,TRAP_DOOR:8)
Block(1,10,5,TRAP_DOOR:8)
Block(1,10,6,TRAP_DOOR:8)
Block(1,10,7,TRAP_DOOR:8)
Block(1,10,8,TRAP_DOOR:8)
Block(1,10,9,WOOD:5)
Block(2,0,-6,LOG:1)
Block(2,0,9,LOG:1)
Block(2,1,-6,WOOD:5)
Block(2,1,-5,WOOD:5)
Block(2,1,-4,WOOD:5)
Block(2,1,-3,WOOD:5)
Block(2,1,-2,WOOD:5)
Block(2,1,-1,WOOD:5)
Block(2,1,0,WOOD:5)
Block(2,1,1,WOOD:5)
Block(2,1,2,WOOD:5)
Block(2,1,3,WOOD:5)
Block(2,1,4,WOOD:5)
Block(2,1,5,WOOD:5)
Block(2,1,6,WOOD:5)
Block(2,1,7,WOOD:5)
Block(2,1,8,WOOD:5)
Block(2,1,9,WOOD:5)
Block(2,2,-6,DARK_OAK_STAIRS:1)
Block(2,2,-5,AIR:0)
Block(2,2,-4,AIR:0)
Block(2,2,-3,SPRUCE_FENCE:0)
Block(2,2,-2,AIR:0)
Block(2,2,-1,AIR:0)
Block(2,2,0,SPRUCE_FENCE:0)
Block(2,2,1,CARPET:13)
Block(2,2,2,CARPET:13)
Block(2,2,3,SMOOTH_BRICK:0)
Block(2,2,4,SMOOTH_BRICK:0)
Block(2,2,5,SPRUCE_DOOR:2)
Block(2,2,6,SMOOTH_BRICK:0)
Block(2,2,7,SMOOTH_BRICK:0)
Block(2,2,8,SMOOTH_BRICK:0)
Block(2,2,9,DARK_OAK_STAIRS:1)
Block(2,3,-6,DARK_OAK_STAIRS:5)
Block(2,3,-5,AIR:0)
Block(2,3,-4,AIR:0)
Block(2,3,-3,TORCH:5)
Block(2,3,-2,AIR:0)
Block(2,3,-1,AIR:0)
Block(2,3,0,SPRUCE_FENCE:0)
Block(2,3,1,AIR:0)
Block(2,3,2,AIR:0)
Block(2,3,3,SMOOTH_BRICK:0)
Block(2,3,4,SMOOTH_BRICK:0)
Block(2,3,5,SPRUCE_DOOR:9)
Block(2,3,6,SMOOTH_BRICK:0)
Block(2,3,7,SMOOTH_BRICK:0)
Block(2,3,8,SMOOTH_BRICK:0)
Block(2,3,9,DARK_OAK_STAIRS:5)
Block(2,4,-6,WOOD:1)
Block(2,4,-5,AIR:0)
Block(2,4,-4,AIR:0)
Block(2,4,-3,AIR:0)
Block(2,4,-2,AIR:0)
Block(2,4,-1,AIR:0)
Block(2,4,0,WOOD:1)
Block(2,4,1,WOOD:1)
Block(2,4,2,WOOD:1)
Block(2,4,3,WOOD:1)
Block(2,4,4,SMOOTH_BRICK:0)
Block(2,4,5,SMOOTH_BRICK:0)
Block(2,4,6,SMOOTH_BRICK:0)
Block(2,4,7,SMOOTH_BRICK:0)
Block(2,4,8,SMOOTH_BRICK:0)
Block(2,4,9,WOOD:1)
Block(2,5,-6,SPRUCE_FENCE:0)
Block(2,5,-5,AIR:0)
Block(2,5,-4,AIR:0)
Block(2,5,-3,AIR:0)
Block(2,5,-2,AIR:0)
Block(2,5,-1,AIR:0)
Block(2,5,0,SPRUCE_FENCE:0)
Block(2,5,1,AIR:0)
Block(2,5,2,AIR:0)
Block(2,5,3,SMOOTH_BRICK:0)
Block(2,5,4,SMOOTH_BRICK:0)
Block(2,5,5,SMOOTH_BRICK:0)
Block(2,5,6,SMOOTH_BRICK:0)
Block(2,5,7,SMOOTH_BRICK:0)
Block(2,5,8,SMOOTH_BRICK:0)
Block(2,5,9,SMOOTH_BRICK:0)
Block(2,6,-6,WOOD:5)
Block(2,6,-5,WOOD:5)
Block(2,6,-4,WOOD:5)
Block(2,6,-3,WOOD:5)
Block(2,6,-2,WOOD:5)
Block(2,6,-1,WOOD:5)
Block(2,6,0,WOOD:5)
Block(2,6,1,WOOD:5)
Block(2,6,2,WOOD:5)
Block(2,6,3,WOOD:5)
Block(2,6,4,WOOD:5)
Block(2,6,5,WOOD:5)
Block(2,6,6,WOOD:5)
Block(2,6,7,WOOD:5)
Block(2,6,8,WOOD:5)
Block(2,6,9,WOOD:5)
Block(2,7,-6,STONE:6)
Block(2,7,-5,SPRUCE_FENCE:0)
Block(2,7,-4,AIR:0)
Block(2,7,-3,AIR:0)
Block(2,7,-2,SPRUCE_DOOR:1)
Block(2,7,-1,AIR:0)
Block(2,7,0,SPRUCE_FENCE:0)
Block(2,7,1,AIR:0)
Block(2,7,2,CARPET:13)
Block(2,7,3,SPRUCE_FENCE:0)
Block(2,7,4,AIR:0)
Block(2,7,5,SMOOTH_BRICK:0)
Block(2,7,6,AIR:0)
Block(2,7,7,CARPET:13)
Block(2,7,8,SPRUCE_FENCE:0)
Block(2,7,9,STONE:6)
Block(2,8,-6,STONE:6)
Block(2,8,-5,TORCH:5)
Block(2,8,-4,AIR:0)
Block(2,8,-3,AIR:0)
Block(2,8,-2,SPRUCE_DOOR:9)
Block(2,8,-1,AIR:0)
Block(2,8,0,SPRUCE_FENCE:0)
Block(2,8,1,AIR:0)
Block(2,8,2,AIR:0)
Block(2,8,3,SPRUCE_FENCE:0)
Block(2,8,4,AIR:0)
Block(2,8,5,SMOOTH_BRICK:0)
Block(2,8,6,AIR:0)
Block(2,8,7,AIR:0)
Block(2,8,8,TORCH:5)
Block(2,8,9,STONE:6)
Block(2,9,-6,WOOD:1)
Block(2,9,-5,AIR:0)
Block(2,9,-4,AIR:0)
Block(2,9,-3,AIR:0)
Block(2,9,-2,WOOD_STEP:5)
Block(2,9,-1,AIR:0)
Block(2,9,0,WOOD:1)
Block(2,9,1,WOOD:1)
Block(2,9,2,WOOD:1)
Block(2,9,3,WOOD:1)
Block(2,9,4,AIR:0)
Block(2,9,5,WOOD_STEP:5)
Block(2,9,6,AIR:0)
Block(2,9,7,AIR:0)
Block(2,9,8,AIR:0)
Block(2,9,9,WOOD:1)
Block(2,10,-6,WOOD:5)
Block(2,10,-5,WOOD:5)
Block(2,10,-4,WOOD:5)
Block(2,10,-3,WOOD:5)
Block(2,10,-2,WOOD:5)
Block(2,10,-1,WOOD:5)
Block(2,10,0,WOOD:5)
Block(2,10,1,TRAP_DOOR:8)
Block(2,10,2,TRAP_DOOR:8)
Block(2,10,3,WOOD:5)
Block(2,10,4,WOOD:5)
Block(2,10,5,WOOD:5)
Block(2,10,6,WOOD:5)
Block(2,10,7,WOOD:5)
Block(2,10,8,WOOD:5)
Block(2,10,9,WOOD:5)
Block(3,1,-6,WOOD:5)
Block(3,1,-5,WOOD:5)
Block(3,1,-4,WOOD:5)
Block(3,1,-3,WOOD:5)
Block(3,1,-2,WOOD:5)
Block(3,1,-1,WOOD:5)
Block(3,1,0,WOOD:5)
Block(3,1,1,WOOD:5)
Block(3,1,2,WOOD:5)
Block(3,1,3,WOOD:5)
Block(3,1,4,WOOD:5)
Block(3,1,5,WOOD:5)
Block(3,1,6,WOOD:5)
Block(3,1,7,WOOD:5)
Block(3,1,8,WOOD:5)
Block(3,1,9,WOOD:5)
Block(3,2,-6,SMOOTH_BRICK:0)
Block(3,2,-5,SMOOTH_BRICK:0)
Block(3,2,-4,SMOOTH_BRICK:0)
Block(3,2,-3,SMOOTH_BRICK:0)
Block(3,2,-2,AIR:0)
Block(3,2,-1,AIR:0)
Block(3,2,0,AIR:0)
Block(3,2,1,CARPET:13)
Block(3,2,2,CARPET:13)
Block(3,2,3,SMOOTH_BRICK:0)
Block(3,2,4,SPRUCE_FENCE:0)
Block(3,2,5,AIR:0)
Block(3,2,6,HAY_BLOCK:0)
Block(3,2,7,HAY_BLOCK:4)
Block(3,2,8,HAY_BLOCK:0)
Block(3,2,9,SMOOTH_BRICK:0)
Block(3,3,-6,SMOOTH_BRICK:0)
Block(3,3,-5,SMOOTH_BRICK:0)
Block(3,3,-4,SMOOTH_BRICK:0)
Block(3,3,-3,SMOOTH_BRICK:0)
Block(3,3,-2,AIR:0)
Block(3,3,-1,AIR:0)
Block(3,3,0,AIR:0)
Block(3,3,1,AIR:0)
Block(3,3,2,AIR:0)
Block(3,3,3,SMOOTH_BRICK:0)
Block(3,3,4,TORCH:5)
Block(3,3,5,AIR:0)
Block(3,3,6,AIR:0)
Block(3,3,7,HAY_BLOCK:0)
Block(3,3,8,HAY_BLOCK:0)
Block(3,3,9,SMOOTH_BRICK:0)
Block(3,4,-6,SMOOTH_BRICK:0)
Block(3,4,-5,WOOD_STEP:5)
Block(3,4,-4,WOOD_STEP:5)
Block(3,4,-3,WOOD_STEP:5)
Block(3,4,-2,AIR:0)
Block(3,4,-1,AIR:0)
Block(3,4,0,AIR:0)
Block(3,4,1,AIR:0)
Block(3,4,2,AIR:0)
Block(3,4,3,SMOOTH_BRICK:0)
Block(3,4,4,AIR:0)
Block(3,4,5,AIR:0)
Block(3,4,6,AIR:0)
Block(3,4,7,AIR:0)
Block(3,4,8,HAY_BLOCK:0)
Block(3,4,9,SMOOTH_BRICK:0)
Block(3,5,-6,SMOOTH_BRICK:0)
Block(3,5,-5,AIR:0)
Block(3,5,-4,AIR:0)
Block(3,5,-3,AIR:0)
Block(3,5,-2,AIR:0)
Block(3,5,-1,AIR:0)
Block(3,5,0,AIR:0)
Block(3,5,1,AIR:0)
Block(3,5,2,AIR:0)
Block(3,5,3,SMOOTH_BRICK:0)
Block(3,5,4,AIR:0)
Block(3,5,5,AIR:0)
Block(3,5,6,AIR:0)
Block(3,5,7,AIR:0)
Block(3,5,8,HAY_BLOCK:8)
Block(3,5,9,SMOOTH_BRICK:0)
Block(3,6,-6,WOOD:5)
Block(3,6,-5,WOOD_STEP:13)
Block(3,6,-4,WOOD_STEP:13)
Block(3,6,-3,WOOD_STEP:13)
Block(3,6,-2,WOOD_STEP:13)
Block(3,6,-1,WOOD_STEP:13)
Block(3,6,0,WOOD:5)
Block(3,6,1,WOOD_STEP:13)
Block(3,6,2,WOOD_STEP:13)
Block(3,6,3,WOOD:5)
Block(3,6,4,WOOD_STEP:13)
Block(3,6,5,WOOD_STEP:13)
Block(3,6,6,WOOD_STEP:13)
Block(3,6,7,WOOD_STEP:13)
Block(3,6,8,WOOD_STEP:13)
Block(3,6,9,WOOD:5)
Block(3,7,-6,SMOOTH_BRICK:0)
Block(3,7,-5,SMOOTH_BRICK:0)
Block(3,7,-4,AIR:0)
Block(3,7,-3,SMOOTH_BRICK:0)
Block(3,7,-2,SMOOTH_BRICK:0)
Block(3,7,-1,AIR:0)
Block(3,7,0,CARPET:13)
Block(3,7,1,SPRUCE_FENCE:0)
Block(3,7,2,AIR:0)
Block(3,7,3,AIR:0)
Block(3,7,4,AIR:0)
Block(3,7,5,SMOOTH_BRICK:0)
Block(3,7,6,SMOOTH_BRICK:0)
Block(3,7,7,SMOOTH_BRICK:0)
Block(3,7,8,SMOOTH_BRICK:0)
Block(3,7,9,SMOOTH_BRICK:0)
Block(3,8,-6,SMOOTH_BRICK:0)
Block(3,8,-5,SMOOTH_BRICK:0)
Block(3,8,-4,AIR:0)
Block(3,8,-3,SMOOTH_BRICK:0)
Block(3,8,-2,SMOOTH_BRICK:0)
Block(3,8,-1,AIR:0)
Block(3,8,0,AIR:0)
Block(3,8,1,TORCH:5)
Block(3,8,2,AIR:0)
Block(3,8,3,AIR:0)
Block(3,8,4,AIR:0)
Block(3,8,5,SMOOTH_BRICK:0)
Block(3,8,6,SPRUCE_FENCE:0)
Block(3,8,7,SPRUCE_FENCE:0)
Block(3,8,8,SPRUCE_FENCE:0)
Block(3,8,9,SMOOTH_BRICK:0)
Block(3,9,-6,SMOOTH_BRICK:0)
Block(3,9,-5,WOOD_STEP:5)
Block(3,9,-4,WOOD_STEP:5)
Block(3,9,-3,WOOD_STEP:5)
Block(3,9,-2,WOOD_STEP:5)
Block(3,9,-1,AIR:0)
Block(3,9,0,AIR:0)
Block(3,9,1,AIR:0)
Block(3,9,2,AIR:0)
Block(3,9,3,AIR:0)
Block(3,9,4,AIR:0)
Block(3,9,5,WOOD_STEP:5)
Block(3,9,6,WOOD_STEP:5)
Block(3,9,7,WOOD_STEP:5)
Block(3,9,8,WOOD_STEP:5)
Block(3,9,9,SMOOTH_BRICK:0)
Block(3,10,-6,WOOD:5)
Block(3,10,-5,TRAP_DOOR:8)
Block(3,10,-4,TRAP_DOOR:8)
Block(3,10,-3,TRAP_DOOR:8)
Block(3,10,-2,TRAP_DOOR:8)
Block(3,10,-1,TRAP_DOOR:8)
Block(3,10,0,WOOD:5)
Block(3,10,1,TRAP_DOOR:8)
Block(3,10,2,TRAP_DOOR:8)
Block(3,10,3,WOOD:5)
Block(3,10,4,TRAP_DOOR:8)
Block(3,10,5,TRAP_DOOR:8)
Block(3,10,6,TRAP_DOOR:8)
Block(3,10,7,TRAP_DOOR:8)
Block(3,10,8,TRAP_DOOR:8)
Block(3,10,9,WOOD:5)
Block(4,1,-6,WOOD:5)
Block(4,1,-5,WOOD:5)
Block(4,1,-4,WOOD:5)
Block(4,1,-3,WOOD:5)
Block(4,1,-2,WOOD:5)
Block(4,1,-1,WOOD:5)
Block(4,1,0,WOOD:5)
Block(4,1,1,WOOD:5)
Block(4,1,2,WOOD:5)
Block(4,1,3,WOOD:5)
Block(4,1,4,WOOD:5)
Block(4,1,5,WOOD:5)
Block(4,1,6,WOOD:5)
Block(4,1,7,WOOD:5)
Block(4,1,8,WOOD:5)
Block(4,1,9,WOOD:5)
RandomBlock(4,2,-6,DARK_OAK_FENCE:0,30,STONE:6,100)
Block(4,2,-5,BED_BLOCK:10)
Block(4,2,-4,BED_BLOCK:2)
Block(4,2,-3,SMOOTH_BRICK:0)
Block(4,2,-2,AIR:0)
Block(4,2,-1,AIR:0)
Block(4,2,0,CARPET:13)
Block(4,2,1,CARPET:13)
Block(4,2,2,AIR:0)
Block(4,2,3,SMOOTH_BRICK:0)
Block(4,2,4,AIR:0)
Block(4,2,5,AIR:0)
Block(4,2,6,AIR:0)
Block(4,2,7,HAY_BLOCK:0)
Block(4,2,8,HAY_BLOCK:0)
RandomBlock(4,2,9,DARK_OAK_FENCE:0,30,STONE:6,100)
RandomBlock(4,3,-6,DARK_OAK_FENCE:0,30,STONE:6,100)
Block(4,3,-5,AIR:0)
Block(4,3,-4,AIR:0)
Block(4,3,-3,SMOOTH_BRICK:0)
Block(4,3,-2,AIR:0)
Block(4,3,-1,AIR:0)
Block(4,3,0,AIR:0)
Block(4,3,1,AIR:0)
Block(4,3,2,AIR:0)
Block(4,3,3,SMOOTH_BRICK:0)
Block(4,3,4,AIR:0)
Block(4,3,5,AIR:0)
Block(4,3,6,AIR:0)
Block(4,3,7,AIR:0)
Block(4,3,8,HAY_BLOCK:0)
RandomBlock(4,3,9,DARK_OAK_FENCE:0,30,STONE:6,100)
RandomBlock(4,4,-6,DARK_OAK_FENCE:0,30,STONE:6,100)
Block(4,4,-5,WOOD_STEP:5)
Block(4,4,-4,WOOD_STEP:5)
Block(4,4,-3,WOOD_STEP:5)
Block(4,4,-2,AIR:0)
Block(4,4,-1,AIR:0)
Block(4,4,0,AIR:0)
Block(4,4,1,AIR:0)
Block(4,4,2,AIR:0)
Block(4,4,3,SMOOTH_BRICK:0)
Block(4,4,4,AIR:0)
Block(4,4,5,AIR:0)
Block(4,4,6,AIR:0)
Block(4,4,7,AIR:0)
Block(4,4,8,AIR:0)
RandomBlock(4,4,9,DARK_OAK_FENCE:0,30,STONE:6,100)
RandomBlock(4,5,-6,DARK_OAK_FENCE:0,30,STONE:6,100)
Block(4,5,-5,AIR:0)
Block(4,5,-4,AIR:0)
Block(4,5,-3,AIR:0)
Block(4,5,-2,AIR:0)
Block(4,5,-1,AIR:0)
Block(4,5,0,AIR:0)
Block(4,5,1,AIR:0)
Block(4,5,2,AIR:0)
Block(4,5,3,SMOOTH_BRICK:0)
Block(4,5,4,AIR:0)
Block(4,5,5,AIR:0)
Block(4,5,6,AIR:0)
Block(4,5,7,AIR:0)
Block(4,5,8,AIR:0)
RandomBlock(4,5,9,DARK_OAK_FENCE:0,30,STONE:6,100)
Block(4,6,-6,WOOD:5)
Block(4,6,-5,WOOD_STEP:13)
Block(4,6,-4,WOOD_STEP:13)
Block(4,6,-3,WOOD_STEP:13)
Block(4,6,-2,WOOD_STEP:13)
Block(4,6,-1,WOOD_STEP:13)
Block(4,6,0,WOOD:5)
Block(4,6,1,WOOD_STEP:13)
Block(4,6,2,WOOD_STEP:13)
Block(4,6,3,WOOD:5)
Block(4,6,4,WOOD_STEP:13)
Block(4,6,5,WOOD_STEP:13)
Block(4,6,6,WOOD_STEP:13)
Block(4,6,7,WOOD_STEP:13)
Block(4,6,8,WOOD_STEP:13)
Block(4,6,9,WOOD:5)
RandomBlock(4,7,-6,DARK_OAK_FENCE:0,30,STONE:6,100)
Block(4,7,-5,AIR:0)
Block(4,7,-4,AIR:0)
Block(4,7,-3,SPRUCE_FENCE:0)
Block(4,7,-2,SMOOTH_BRICK:0)
Block(4,7,-1,SMOOTH_BRICK:0)
Block(4,7,0,SMOOTH_BRICK:0)
Block(4,7,1,SMOOTH_BRICK:0)
Block(4,7,2,SMOOTH_BRICK:0)
Block(4,7,3,SPRUCE_DOOR:2)
Block(4,7,4,SMOOTH_BRICK:0)
Block(4,7,5,SMOOTH_BRICK:0)
Block(4,7,6,BED_BLOCK:9)
Block(4,7,7,BED_BLOCK:9)
Block(4,7,8,SPRUCE_FENCE:0)
RandomBlock(4,7,9,DARK_OAK_FENCE:0,30,STONE:6,100)
RandomBlock(4,8,-6,DARK_OAK_FENCE:0,30,STONE:6,100)
Block(4,8,-5,AIR:0)
Block(4,8,-4,AIR:0)
Block(4,8,-3,TORCH:5)
Block(4,8,-2,SMOOTH_BRICK:0)
Block(4,8,-1,SMOOTH_BRICK:0)
Block(4,8,0,SMOOTH_BRICK:0)
Block(4,8,1,SMOOTH_BRICK:0)
Block(4,8,2,SMOOTH_BRICK:0)
Block(4,8,3,SPRUCE_DOOR:9)
Block(4,8,4,SMOOTH_BRICK:0)
Block(4,8,5,SMOOTH_BRICK:0)
Block(4,8,6,AIR:0)
Block(4,8,7,AIR:0)
Block(4,8,8,TORCH:5)
RandomBlock(4,8,9,DARK_OAK_FENCE:0,30,STONE:6,100)
RandomBlock(4,9,-6,DARK_OAK_FENCE:0,30,STONE:6,100)
Block(4,9,-5,AIR:0)
Block(4,9,-4,AIR:0)
Block(4,9,-3,AIR:0)
Block(4,9,-2,WOOD_STEP:5)
Block(4,9,-1,WOOD_STEP:5)
Block(4,9,0,WOOD_STEP:5)
Block(4,9,1,WOOD_STEP:5)
Block(4,9,2,WOOD_STEP:5)
Block(4,9,3,WOOD_STEP:5)
Block(4,9,4,WOOD_STEP:5)
Block(4,9,5,WOOD_STEP:5)
Block(4,9,6,AIR:0)
Block(4,9,7,AIR:0)
Block(4,9,8,AIR:0)
RandomBlock(4,9,9,DARK_OAK_FENCE:0,30,STONE:6,100)
Block(4,10,-6,WOOD:5)
Block(4,10,-5,TRAP_DOOR:8)
Block(4,10,-4,TRAP_DOOR:8)
Block(4,10,-3,TRAP_DOOR:8)
Block(4,10,-2,TRAP_DOOR:8)
Block(4,10,-1,TRAP_DOOR:8)
Block(4,10,0,WOOD:5)
Block(4,10,1,TRAP_DOOR:8)
Block(4,10,2,TRAP_DOOR:8)
Block(4,10,3,WOOD:5)
Block(4,10,4,TRAP_DOOR:8)
Block(4,10,5,TRAP_DOOR:8)
Block(4,10,6,TRAP_DOOR:8)
Block(4,10,7,TRAP_DOOR:8)
Block(4,10,8,TRAP_DOOR:8)
Block(4,10,9,WOOD:5)
Block(5,1,-6,WOOD:5)
Block(5,1,-5,WOOD:5)
Block(5,1,-4,WOOD:5)
Block(5,1,-3,WOOD:5)
Block(5,1,-2,WOOD:5)
Block(5,1,-1,WOOD:5)
Block(5,1,0,WOOD:5)
Block(5,1,1,WOOD:5)
Block(5,1,2,WOOD:5)
Block(5,1,3,WOOD:5)
Block(5,1,4,WOOD:5)
Block(5,1,5,WOOD:5)
Block(5,1,6,WOOD:5)
Block(5,1,7,WOOD:5)
Block(5,1,8,WOOD:5)
Block(5,1,9,WOOD:5)
Block(5,2,-6,SMOOTH_BRICK:0)
Block(5,2,-5,AIR:0)
Block(5,2,-4,AIR:0)
Block(5,2,-3,SPRUCE_DOOR:1)
Block(5,2,-2,AIR:0)
Block(5,2,-1,AIR:0)
Block(5,2,0,CARPET:13)
Block(5,2,1,AIR:0)
Block(5,2,2,SPRUCE_FENCE:0)
Block(5,2,3,SMOOTH_BRICK:0)
Block(5,2,4,HAY_BLOCK:8)
Block(5,2,5,HAY_BLOCK:8)
Block(5,2,6,AIR:0)
Block(5,2,7,AIR:0)
Block(5,2,8,HAY_BLOCK:0)
Block(5,2,9,SMOOTH_BRICK:0)
Block(5,3,-6,SMOOTH_BRICK:0)
Block(5,3,-5,AIR:0)
Block(5,3,-4,AIR:0)
Block(5,3,-3,SPRUCE_DOOR:8)
Block(5,3,-2,AIR:0)
Block(5,3,-1,AIR:0)
Block(5,3,0,AIR:0)
Block(5,3,1,AIR:0)
Block(5,3,2,TORCH:5)
Block(5,3,3,SMOOTH_BRICK:0)
Block(5,3,4,AIR:0)
Block(5,3,5,AIR:0)
Block(5,3,6,AIR:0)
Block(5,3,7,AIR:0)
Block(5,3,8,AIR:0)
Block(5,3,9,SMOOTH_BRICK:0)
Block(5,4,-6,SMOOTH_BRICK:0)
Block(5,4,-5,WOOD_STEP:5)
Block(5,4,-4,WOOD_STEP:5)
Block(5,4,-3,WOOD_STEP:5)
Block(5,4,-2,AIR:0)
Block(5,4,-1,AIR:0)
Block(5,4,0,AIR:0)
Block(5,4,1,AIR:0)
Block(5,4,2,AIR:0)
Block(5,4,3,SMOOTH_BRICK:0)
Block(5,4,4,AIR:0)
Block(5,4,5,AIR:0)
Block(5,4,6,AIR:0)
Block(5,4,7,AIR:0)
Block(5,4,8,AIR:0)
Block(5,4,9,SMOOTH_BRICK:0)
Block(5,5,-6,SMOOTH_BRICK:0)
Block(5,5,-5,AIR:0)
Block(5,5,-4,AIR:0)
Block(5,5,-3,AIR:0)
Block(5,5,-2,AIR:0)
Block(5,5,-1,AIR:0)
Block(5,5,0,AIR:0)
Block(5,5,1,AIR:0)
Block(5,5,2,AIR:0)
Block(5,5,3,SMOOTH_BRICK:0)
Block(5,5,4,AIR:0)
Block(5,5,5,AIR:0)
Block(5,5,6,AIR:0)
Block(5,5,7,AIR:0)
Block(5,5,8,AIR:0)
Block(5,5,9,SMOOTH_BRICK:0)
Block(5,6,-6,WOOD:5)
Block(5,6,-5,WOOD_STEP:13)
Block(5,6,-4,WOOD_STEP:13)
Block(5,6,-3,WOOD_STEP:13)
Block(5,6,-2,WOOD_STEP:13)
Block(5,6,-1,WOOD_STEP:13)
Block(5,6,0,WOOD:5)
Block(5,6,1,WOOD_STEP:13)
Block(5,6,2,WOOD_STEP:13)
Block(5,6,3,WOOD:5)
Block(5,6,4,WOOD_STEP:13)
Block(5,6,5,WOOD_STEP:13)
Block(5,6,6,WOOD_STEP:13)
Block(5,6,7,WOOD_STEP:13)
Block(5,6,8,WOOD_STEP:13)
Block(5,6,9,WOOD:5)
Block(5,7,-6,SMOOTH_BRICK:0)
Block(5,7,-5,CARPET:13)
Block(5,7,-4,CARPET:13)
Block(5,7,-3,BED_BLOCK:0)
Block(5,7,-2,BED_BLOCK:8)
Block(5,7,-1,SMOOTH_BRICK:0)
Block(5,7,0,AIR:0)
Block(5,7,1,CARPET:13)
Block(5,7,2,AIR:0)
Block(5,7,3,AIR:0)
Block(5,7,4,SMOOTH_BRICK:0)
Block(5,7,5,AIR:0)
Block(5,7,6,BED_BLOCK:1)
Block(5,7,7,BED_BLOCK:1)
Block(5,7,8,AIR:0)
Block(5,7,9,SMOOTH_BRICK:0)
Block(5,8,-6,SMOOTH_BRICK:0)
Block(5,8,-5,AIR:0)
Block(5,8,-4,AIR:0)
Block(5,8,-3,AIR:0)
Block(5,8,-2,AIR:0)
Block(5,8,-1,SPRUCE_FENCE:0)
Block(5,8,0,AIR:0)
Block(5,8,1,AIR:0)
Block(5,8,2,AIR:0)
Block(5,8,3,AIR:0)
Block(5,8,4,SMOOTH_BRICK:0)
Block(5,8,5,AIR:0)
Block(5,8,6,AIR:0)
Block(5,8,7,AIR:0)
Block(5,8,8,AIR:0)
Block(5,8,9,SMOOTH_BRICK:0)
Block(5,9,-6,SMOOTH_BRICK:0)
Block(5,9,-5,AIR:0)
Block(5,9,-4,AIR:0)
Block(5,9,-3,AIR:0)
Block(5,9,-2,AIR:0)
Block(5,9,-1,WOOD_STEP:5)
Block(5,9,0,AIR:0)
Block(5,9,1,AIR:0)
Block(5,9,2,AIR:0)
Block(5,9,3,AIR:0)
Block(5,9,4,WOOD_STEP:5)
Block(5,9,5,AIR:0)
Block(5,9,6,AIR:0)
Block(5,9,7,AIR:0)
Block(5,9,8,AIR:0)
Block(5,9,9,SMOOTH_BRICK:0)
Block(5,10,-6,WOOD:5)
Block(5,10,-5,TRAP_DOOR:8)
Block(5,10,-4,TRAP_DOOR:8)
Block(5,10,-3,TRAP_DOOR:8)
Block(5,10,-2,TRAP_DOOR:8)
Block(5,10,-1,TRAP_DOOR:8)
Block(5,10,0,WOOD:5)
Block(5,10,1,TRAP_DOOR:8)
Block(5,10,2,TRAP_DOOR:8)
Block(5,10,3,WOOD:5)
Block(5,10,4,TRAP_DOOR:8)
Block(5,10,5,TRAP_DOOR:8)
Block(5,10,6,TRAP_DOOR:8)
Block(5,10,7,TRAP_DOOR:8)
Block(5,10,8,TRAP_DOOR:8)
Block(5,10,9,WOOD:5)
Block(6,1,-6,WOOD:5)
Block(6,1,-5,WOOD:5)
Block(6,1,-4,WOOD:5)
Block(6,1,-3,WOOD:5)
Block(6,1,-2,WOOD:5)
Block(6,1,-1,WOOD:5)
Block(6,1,0,WOOD:5)
Block(6,1,1,WOOD:5)
Block(6,1,2,WOOD:5)
Block(6,1,3,WOOD:5)
Block(6,1,4,WOOD:5)
Block(6,1,5,WOOD:5)
Block(6,1,6,WOOD:5)
Block(6,1,7,WOOD:5)
Block(6,1,8,WOOD:5)
Block(6,1,9,WOOD:5)
Block(6,2,-6,SPRUCE_FENCE:0)
RandomBlock(6,2,-5,DARK_OAK_FENCE:0,30,STONE:6,100)
Block(6,2,-4,WORKBENCH:0)
Block(6,2,-3,SMOOTH_BRICK:0)
Block(6,2,-2,AIR:0)
Block(6,2,-1,AIR:0)
Block(6,2,0,CARPET:13)
Block(6,2,1,CARPET:13)
Block(6,2,2,CARPET:13)
Block(6,2,3,SMOOTH_BRICK:0)
Block(6,2,4,HAY_BLOCK:0)
Block(6,2,5,HAY_BLOCK:4)
Block(6,2,6,HAY_BLOCK:4)
Block(6,2,7,HAY_BLOCK:0)
RandomBlock(6,2,8,DARK_OAK_FENCE:0,30,STONE:6,100)
Block(6,2,9,SPRUCE_FENCE:0)
Block(6,3,-6,SPRUCE_FENCE:0)
RandomBlock(6,3,-5,DARK_OAK_FENCE:0,30,STONE:6,100)
Block(6,3,-4,AIR:0)
Block(6,3,-3,SMOOTH_BRICK:0)
Block(6,3,-2,AIR:0)
Block(6,3,-1,AIR:0)
Block(6,3,0,AIR:0)
Block(6,3,1,AIR:0)
Block(6,3,2,AIR:0)
Block(6,3,3,SMOOTH_BRICK:0)
Block(6,3,4,HAY_BLOCK:8)
Block(6,3,5,HAY_BLOCK:4)
Block(6,3,6,AIR:0)
Block(6,3,7,AIR:0)
RandomBlock(6,3,8,DARK_OAK_FENCE:0,30,STONE:6,100)
Block(6,3,9,SPRUCE_FENCE:0)
Block(6,4,-6,WOOD:1)
RandomBlock(6,4,-5,DARK_OAK_FENCE:0,30,STONE:6,100)
Block(6,4,-4,WOOD_STEP:5)
Block(6,4,-3,WOOD_STEP:5)
Block(6,4,-2,AIR:0)
Block(6,4,-1,AIR:0)
Block(6,4,0,AIR:0)
Block(6,4,1,AIR:0)
Block(6,4,2,AIR:0)
Block(6,4,3,SMOOTH_BRICK:0)
Block(6,4,4,HAY_BLOCK:4)
Block(6,4,5,AIR:0)
Block(6,4,6,AIR:0)
Block(6,4,7,AIR:0)
RandomBlock(6,4,8,DARK_OAK_FENCE:0,30,STONE:6,100)
Block(6,4,9,WOOD:1)
Block(6,5,-6,SPRUCE_FENCE:0)
RandomBlock(6,5,-5,DARK_OAK_FENCE:0,30,STONE:6,100)
Block(6,5,-4,AIR:0)
Block(6,5,-3,AIR:0)
Block(6,5,-2,AIR:0)
Block(6,5,-1,AIR:0)
Block(6,5,0,AIR:0)
Block(6,5,1,AIR:0)
Block(6,5,2,AIR:0)
Block(6,5,3,SMOOTH_BRICK:0)
Block(6,5,4,AIR:0)
Block(6,5,5,AIR:0)
Block(6,5,6,AIR:0)
Block(6,5,7,AIR:0)
RandomBlock(6,5,8,DARK_OAK_FENCE:0,30,STONE:6,100)
Block(6,5,9,SPRUCE_FENCE:0)
Block(6,6,-6,WOOD:5)
Block(6,6,-5,WOOD_DOUBLE_STEP:5)
Block(6,6,-4,WOOD_STEP:13)
Block(6,6,-3,WOOD_STEP:13)
Block(6,6,-2,WOOD_STEP:13)
Block(6,6,-1,WOOD_STEP:13)
Block(6,6,0,WOOD:5)
Block(6,6,1,WOOD_STEP:13)
Block(6,6,2,WOOD_STEP:13)
Block(6,6,3,WOOD:5)
Block(6,6,4,WOOD_STEP:13)
Block(6,6,5,WOOD_STEP:13)
Block(6,6,6,WOOD_STEP:13)
Block(6,6,7,WOOD_STEP:13)
Block(6,6,8,WOOD_DOUBLE_STEP:5)
Block(6,6,9,WOOD:5)
Block(6,7,-6,SPRUCE_FENCE:0)
RandomBlock(6,7,-5,DARK_OAK_FENCE:0,30,STONE:6,100)
Block(6,7,-4,CARPET:13)
Block(6,7,-3,BED_BLOCK:0)
Block(6,7,-2,BED_BLOCK:8)
Block(6,7,-1,SMOOTH_BRICK:0)
Block(6,7,0,AIR:0)
Block(6,7,1,CARPET:13)
Block(6,7,2,CARPET:13)
Block(6,7,3,AIR:0)
Block(6,7,4,AIR:0)
Block(6,7,5,AIR:0)
Block(6,7,6,AIR:0)
Block(6,7,7,CARPET:13)
RandomBlock(6,7,8,DARK_OAK_FENCE:0,30,STONE:6,100)
Block(6,7,9,SPRUCE_FENCE:0)
Block(6,8,-6,SPRUCE_FENCE:0)
RandomBlock(6,8,-5,DARK_OAK_FENCE:0,30,STONE:6,100)
Block(6,8,-4,AIR:0)
Block(6,8,-3,AIR:0)
Block(6,8,-2,AIR:0)
Block(6,8,-1,SPRUCE_FENCE:0)
Block(6,8,0,AIR:0)
Block(6,8,1,AIR:0)
Block(6,8,2,AIR:0)
Block(6,8,3,AIR:0)
Block(6,8,4,AIR:0)
Block(6,8,5,AIR:0)
Block(6,8,6,AIR:0)
Block(6,8,7,AIR:0)
RandomBlock(6,8,8,DARK_OAK_FENCE:0,30,STONE:6,100)
Block(6,8,9,SPRUCE_FENCE:0)
Block(6,9,-6,WOOD:1)
RandomBlock(6,9,-5,DARK_OAK_FENCE:0,30,STONE:6,100)
Block(6,9,-4,AIR:0)
Block(6,9,-3,AIR:0)
Block(6,9,-2,AIR:0)
Block(6,9,-1,WOOD_STEP:5)
Block(6,9,0,AIR:0)
Block(6,9,1,AIR:0)
Block(6,9,2,AIR:0)
Block(6,9,3,AIR:0)
Block(6,9,4,WOOD_STEP:5)
Block(6,9,5,AIR:0)
Block(6,9,6,AIR:0)
Block(6,9,7,AIR:0)
RandomBlock(6,9,8,DARK_OAK_FENCE:0,30,STONE:6,100)
Block(6,9,9,WOOD:1)
Block(6,10,-6,WOOD:5)
RandomBlock(6,10,-5,DARK_OAK_FENCE:0,30,STONE:6,100)
Block(6,10,-4,TRAP_DOOR:8)
Block(6,10,-3,TRAP_DOOR:8)
Block(6,10,-2,TRAP_DOOR:8)
Block(6,10,-1,TRAP_DOOR:8)
Block(6,10,0,WOOD:5)
Block(6,10,1,TRAP_DOOR:8)
Block(6,10,2,TRAP_DOOR:8)
Block(6,10,3,WOOD:5)
Block(6,10,4,TRAP_DOOR:8)
Block(6,10,5,TRAP_DOOR:8)
Block(6,10,6,TRAP_DOOR:8)
Block(6,10,7,TRAP_DOOR:8)
RandomBlock(6,10,8,DARK_OAK_FENCE:0,30,STONE:6,100)
Block(6,10,9,WOOD:5)
Block(7,1,-6,WOOD:5)
Block(7,1,-5,WOOD:5)
Block(7,1,-4,WOOD:5)
Block(7,1,-3,WOOD:5)
Block(7,1,-2,WOOD:5)
Block(7,1,-1,WOOD:5)
Block(7,1,0,WOOD:5)
Block(7,1,1,WOOD:5)
Block(7,1,2,WOOD:5)
Block(7,1,3,WOOD:5)
Block(7,1,4,WOOD:5)
Block(7,1,5,WOOD:5)
Block(7,1,6,WOOD:5)
Block(7,1,7,WOOD:5)
Block(7,1,8,WOOD:5)
Block(7,1,9,WOOD:5)
RandomBlock(7,2,-5,DARK_OAK_FENCE:0,30,STONE:6,100)
RandomBlock(7,2,-4,DARK_OAK_FENCE:0,30,STONE:6,100)
Block(7,2,-3,SMOOTH_BRICK:0)
Block(7,2,-2,AIR:0)
Block(7,2,-1,AIR:0)
Block(7,2,0,AIR:0)
Block(7,2,1,AIR:0)
Block(7,2,2,AIR:0)
Block(7,2,3,SMOOTH_BRICK:0)
Block(7,2,4,HAY_BLOCK:0)
Block(7,2,5,HAY_BLOCK:0)
Block(7,2,6,HAY_BLOCK:0)
RandomBlock(7,2,7,DARK_OAK_FENCE:0,30,STONE:6,100)
RandomBlock(7,2,8,DARK_OAK_FENCE:0,30,STONE:6,100)
RandomBlock(7,3,-5,DARK_OAK_FENCE:0,30,STONE:6,100)
RandomBlock(7,3,-4,DARK_OAK_FENCE:0,30,STONE:6,100)
Block(7,3,-3,SMOOTH_BRICK:0)
Block(7,3,-2,AIR:0)
Block(7,3,-1,AIR:0)
Block(7,3,0,AIR:0)
Block(7,3,1,AIR:0)
Block(7,3,2,AIR:0)
Block(7,3,3,SMOOTH_BRICK:0)
Block(7,3,4,HAY_BLOCK:8)
Block(7,3,5,HAY_BLOCK:8)
Block(7,3,6,AIR:0)
RandomBlock(7,3,7,DARK_OAK_FENCE:0,30,STONE:6,100)
RandomBlock(7,3,8,DARK_OAK_FENCE:0,30,STONE:6,100)
Block(7,4,-5,WOOD:1)
RandomBlock(7,4,-4,DARK_OAK_FENCE:0,30,STONE:6,100)
Block(7,4,-3,WOOD_STEP:5)
Block(7,4,-2,AIR:0)
Block(7,4,-1,AIR:0)
Block(7,4,0,AIR:0)
Block(7,4,1,AIR:0)
Block(7,4,2,AIR:0)
Block(7,4,3,SMOOTH_BRICK:0)
Block(7,4,4,HAY_BLOCK:8)
Block(7,4,5,HAY_BLOCK:8)
Block(7,4,6,AIR:0)
RandomBlock(7,4,7,DARK_OAK_FENCE:0,30,STONE:6,100)
Block(7,4,8,WOOD:1)
RandomBlock(7,5,-5,DARK_OAK_FENCE:0,30,STONE:6,100)
RandomBlock(7,5,-4,DARK_OAK_FENCE:0,30,STONE:6,100)
Block(7,5,-3,AIR:0)
Block(7,5,-2,AIR:0)
RandomBlock(7,5,-1,WALL_BANNER:4,../../NBT/Banners/banner_sun.nbt,50,WALL_BANNER:4,../../NBT/Banners/quarry_banner_0.nbt,10,WALL_BANNER:4,../../NBT/Banners/quarry_banner_1.nbt,10,WALL_BANNER:4,../../NBT/Banners/quarry_banner_2.nbt,10,WALL_BANNER:4,../../NBT/Banners/quarry_banner_3.nbt,10,WALL_BANNER:4,../../NBT/Banners/quarry_banner_4.nbt,100)
Block(7,5,0,AIR:0)
Block(7,5,1,AIR:0)
Block(7,5,2,AIR:0)
Block(7,5,3,SMOOTH_BRICK:0)
Block(7,5,4,HAY_BLOCK:4)
Block(7,5,5,AIR:0)
Block(7,5,6,AIR:0)
RandomBlock(7,5,7,DARK_OAK_FENCE:0,30,STONE:6,100)
RandomBlock(7,5,8,DARK_OAK_FENCE:0,30,STONE:6,100)
Block(7,6,-5,WOOD_DOUBLE_STEP:5)
Block(7,6,-4,WOOD_DOUBLE_STEP:5)
Block(7,6,-3,WOOD_STEP:13)
Block(7,6,-2,WOOD_STEP:13)
Block(7,6,-1,WOOD_STEP:13)
Block(7,6,0,WOOD:5)
Block(7,6,1,WOOD_STEP:13)
Block(7,6,2,WOOD_STEP:13)
Block(7,6,3,WOOD:5)
Block(7,6,4,WOOD_STEP:13)
Block(7,6,5,WOOD_STEP:13)
Block(7,6,6,WOOD_STEP:13)
Block(7,6,7,WOOD_DOUBLE_STEP:5)
Block(7,6,8,WOOD_DOUBLE_STEP:5)
RandomBlock(7,7,-5,DARK_OAK_FENCE:0,30,STONE:6,100)
RandomBlock(7,7,-4,DARK_OAK_FENCE:0,30,STONE:6,100)
Block(7,7,-3,AIR:0)
RandomBlock(7,7,-2,AIR:0,20,CHEST:2,../../../../Chests/Loot/JunkChest_1.nbt,10,CHEST:2,../../../../Chests/Loot/JunkChest_2.nbt,10,CHEST:2,../../../../Chests/Loot/JunkChest_3.nbt,10,CHEST:2,../../../../Chests/Loot/JunkChest_4.nbt,10,CHEST:2,../../../../Chests/Loot/JunkChest_5.nbt,10,CHEST:2,../../../../Chests/Lore/HiddenMineWaste_1.nbt,1,CHEST:2,../../../../Chests/Lore/HiddenMineWaste_2.nbt,1,CHEST:2,../../../../Chests/Lore/HiddenMineWaste_3.nbt,1,CHEST:2,../../../../Chests/Lore/HiddenMineWaste_4.nbt,1,CHEST:2,../../../../Chests/Lore/HiddenMineWaste_5.nbt,1,CHEST:2,../../../../Chests/Loot/Common1.nbt,10,CHEST:2,../../../../Chests/Loot/Common2.nbt,10,CHEST:2,../../../../Chests/Loot/Common3.nbt,10,CHEST:2,../../../../Chests/Loot/Common4.nbt,10,CHEST:2,../../../../Chests/Loot/Common5.nbt,10,CHEST:2,../../../../Chests/Loot/Common6.nbt,10,CHEST:2,../../../../Chests/Loot/Common7.nbt,10,CHEST:2,../../../../Chests/Loot/Common8.nbt,10,CHEST:2,../../../../Chests/Loot/Common9.nbt,10,CHEST:2,../../../../Chests/Loot/Common10.nbt,10,CHEST:2,../../../../Chests/Loot/Common10.nbt,11,CHEST:2,../../../../Chests/Loot/Common12.nbt,10,CHEST:2,../../../../Chests/Loot/Common13.nbt,10,CHEST:2,../../../../Chests/Loot/Common14.nbt,10,CHEST:2,../../../../Chests/Loot/Common15.nbt,10,CHEST:2,../../../../Chests/Lore/HiddenMineWaste_1.nbt,2,CHEST:2,../../../../Chests/Lore/HiddenMineWaste_3.nbt,2,CHEST:2,../../../../Chests/Lore/HiddenMineWaste_4.nbt,2,CHEST:2,../../../../Chests/Lore/HiddenMineWaste_5.nbt,2,CHEST:2,../../../../Chests/Lore/HiddenMineWaste_5.nbt,2,CHEST:2,../../../../Chests/Loot/Rare1.nbt,5,CHEST:2,../../../../Chests/Loot/Rare2.nbt,5,CHEST:2,../../../../Chests/Loot/Rare3.nbt,5,CHEST:2,../../../../Chests/Loot/Rare4.nbt,5,CHEST:2,../../../../Chests/Loot/Rare5.nbt,5,CHEST:2,../../../../Chests/Loot/Rare6.nbt,5,CHEST:2,../../../../Chests/Loot/Rare7.nbt,5,CHEST:2,../../../../Chests/Loot/Rare8.nbt,5,CHEST:2,../../../../Chests/Loot/Rare9.nbt,5,CHEST:2,../../../../Chests/Loot/Rare10.nbt,5,CHEST:2,../../../../Chests/Loot/Rare11.nbt,5,CHEST:2,../../../../Chests/Loot/Rare12.nbt,5,CHEST:2,../../../../Chests/Loot/Rare13.nbt,5,CHEST:2,../../../../Chests/Loot/Rare14.nbt,5,CHEST:2,../../../../Chests/Loot/Rare15.nbt,5,CHEST:2,../../../../Chests/Loot/Epic1.nbt,2,CHEST:2,../../../../Chests/Loot/Epic2.nbt,2,CHEST:2,../../../../Chests/Loot/Epic3.nbt,2,CHEST:2,../../../../Chests/Loot/Epic4.nbt,2,CHEST:2,../../../../Chests/Loot/Epic5.nbt,2,CHEST:2,../../../../Chests/Loot/Epic6.nbt,2,CHEST:2,../../../../Chests/Loot/Epic7.nbt,2,CHEST:2,../../../../Chests/Loot/Epic8.nbt,2,CHEST:2,../../../../Chests/Loot/Epic9.nbt,2,CHEST:2,../../../../Chests/Loot/Epic10.nbt,2,CHEST:2,../../../../Chests/Loot/Epic11.nbt,2,CHEST:2,../../../../Chests/Loot/Epic12.nbt,2,CHEST:2,../../../../Chests/Loot/Epic13.nbt,2,CHEST:2,../../../../Chests/Loot/Epic14.nbt,2,CHEST:2,../../../../Chests/Loot/Epic15.nbt,5,CHEST:2,../../../../Chests/Loot/Rare1.nbt,5,CHEST:2,../../../../Chests/Loot/Rare2.nbt,5,CHEST:2,../../../../Chests/Loot/Rare3.nbt,5,CHEST:2,../../../../Chests/Loot/Rare4.nbt,5,CHEST:2,../../../../Chests/Loot/Rare5.nbt,10,CHEST:2,../../../../Chests/Loot/Rare6.nbt,10,CHEST:2,../../../../Chests/Loot/Rare7.nbt,10,CHEST:2,../../../../Chests/Loot/Rare8.nbt,10,CHEST:2,../../../../Chests/Loot/Rare9.nbt,10,CHEST:2,../../../../Chests/Loot/Rare10.nbt,15,CHEST:2,../../../../Chests/Loot/Rare11.nbt,15,CHEST:2,../../../../Chests/Loot/Rare12.nbt,15,CHEST:2,../../../../Chests/Loot/Rare13.nbt,15,CHEST:2,../../../../Chests/Loot/Rare14.nbt,15,CHEST:2,../../../../Chests/Loot/Rare15.nbt,15,CHEST:2,../../../../Chests/Loot/Epic15.nbt,100)
Block(7,7,-1,SMOOTH_BRICK:0)
Block(7,7,0,AIR:0)
Block(7,7,1,AIR:0)
Block(7,7,2,AIR:0)
Block(7,7,3,SPRUCE_FENCE:0)
Block(7,7,4,SMOOTH_BRICK:0)
RandomBlock(7,7,5,AIR:0,20,CHEST:4,../../../../Chests/Loot/JunkChest_1.nbt,10,CHEST:4,../../../../Chests/Loot/JunkChest_2.nbt,10,CHEST:4,../../../../Chests/Loot/JunkChest_3.nbt,10,CHEST:4,../../../../Chests/Loot/JunkChest_4.nbt,10,CHEST:4,../../../../Chests/Loot/JunkChest_5.nbt,10,CHEST:4,../../../../Chests/Lore/HiddenMineWaste_1.nbt,1,CHEST:4,../../../../Chests/Lore/HiddenMineWaste_2.nbt,1,CHEST:4,../../../../Chests/Lore/HiddenMineWaste_3.nbt,1,CHEST:4,../../../../Chests/Lore/HiddenMineWaste_4.nbt,1,CHEST:4,../../../../Chests/Lore/HiddenMineWaste_5.nbt,1,CHEST:4,../../../../Chests/Loot/Common1.nbt,10,CHEST:4,../../../../Chests/Loot/Common2.nbt,10,CHEST:4,../../../../Chests/Loot/Common3.nbt,10,CHEST:4,../../../../Chests/Loot/Common4.nbt,10,CHEST:4,../../../../Chests/Loot/Common5.nbt,10,CHEST:4,../../../../Chests/Loot/Common6.nbt,10,CHEST:4,../../../../Chests/Loot/Common7.nbt,10,CHEST:4,../../../../Chests/Loot/Common8.nbt,10,CHEST:4,../../../../Chests/Loot/Common9.nbt,10,CHEST:4,../../../../Chests/Loot/Common10.nbt,10,CHEST:4,../../../../Chests/Loot/Common10.nbt,11,CHEST:4,../../../../Chests/Loot/Common12.nbt,10,CHEST:4,../../../../Chests/Loot/Common13.nbt,10,CHEST:4,../../../../Chests/Loot/Common14.nbt,10,CHEST:4,../../../../Chests/Loot/Common15.nbt,10,CHEST:4,../../../../Chests/Lore/HiddenMineWaste_1.nbt,2,CHEST:4,../../../../Chests/Lore/HiddenMineWaste_3.nbt,2,CHEST:4,../../../../Chests/Lore/HiddenMineWaste_4.nbt,2,CHEST:4,../../../../Chests/Lore/HiddenMineWaste_5.nbt,2,CHEST:4,../../../../Chests/Lore/HiddenMineWaste_5.nbt,2,CHEST:4,../../../../Chests/Loot/Rare1.nbt,5,CHEST:4,../../../../Chests/Loot/Rare2.nbt,5,CHEST:4,../../../../Chests/Loot/Rare3.nbt,5,CHEST:4,../../../../Chests/Loot/Rare4.nbt,5,CHEST:4,../../../../Chests/Loot/Rare5.nbt,5,CHEST:4,../../../../Chests/Loot/Rare6.nbt,5,CHEST:4,../../../../Chests/Loot/Rare7.nbt,5,CHEST:4,../../../../Chests/Loot/Rare8.nbt,5,CHEST:4,../../../../Chests/Loot/Rare9.nbt,5,CHEST:4,../../../../Chests/Loot/Rare10.nbt,5,CHEST:4,../../../../Chests/Loot/Rare11.nbt,5,CHEST:4,../../../../Chests/Loot/Rare12.nbt,5,CHEST:4,../../../../Chests/Loot/Rare13.nbt,5,CHEST:4,../../../../Chests/Loot/Rare14.nbt,5,CHEST:4,../../../../Chests/Loot/Rare15.nbt,5,CHEST:4,../../../../Chests/Loot/Epic1.nbt,2,CHEST:4,../../../../Chests/Loot/Epic2.nbt,2,CHEST:4,../../../../Chests/Loot/Epic3.nbt,2,CHEST:4,../../../../Chests/Loot/Epic4.nbt,2,CHEST:4,../../../../Chests/Loot/Epic5.nbt,2,CHEST:4,../../../../Chests/Loot/Epic6.nbt,2,CHEST:4,../../../../Chests/Loot/Epic7.nbt,2,CHEST:4,../../../../Chests/Loot/Epic8.nbt,2,CHEST:4,../../../../Chests/Loot/Epic9.nbt,2,CHEST:4,../../../../Chests/Loot/Epic10.nbt,2,CHEST:4,../../../../Chests/Loot/Epic11.nbt,2,CHEST:4,../../../../Chests/Loot/Epic12.nbt,2,CHEST:4,../../../../Chests/Loot/Epic13.nbt,2,CHEST:4,../../../../Chests/Loot/Epic14.nbt,2,CHEST:4,../../../../Chests/Loot/Epic15.nbt,5,CHEST:4,../../../../Chests/Loot/Rare1.nbt,5,CHEST:4,../../../../Chests/Loot/Rare2.nbt,5,CHEST:4,../../../../Chests/Loot/Rare3.nbt,5,CHEST:4,../../../../Chests/Loot/Rare4.nbt,5,CHEST:4,../../../../Chests/Loot/Rare5.nbt,10,CHEST:4,../../../../Chests/Loot/Rare6.nbt,10,CHEST:4,../../../../Chests/Loot/Rare7.nbt,10,CHEST:4,../../../../Chests/Loot/Rare8.nbt,10,CHEST:4,../../../../Chests/Loot/Rare9.nbt,10,CHEST:4,../../../../Chests/Loot/Rare10.nbt,15,CHEST:4,../../../../Chests/Loot/Rare11.nbt,15,CHEST:4,../../../../Chests/Loot/Rare12.nbt,15,CHEST:4,../../../../Chests/Loot/Rare13.nbt,15,CHEST:4,../../../../Chests/Loot/Rare14.nbt,15,CHEST:4,../../../../Chests/Loot/Rare15.nbt,15,CHEST:4,../../../../Chests/Loot/Epic15.nbt,100)
RandomBlock(7,7,6,AIR:0,20,CHEST:4,../../../../Chests/Loot/JunkChest_1.nbt,10,CHEST:4,../../../../Chests/Loot/JunkChest_2.nbt,10,CHEST:4,../../../../Chests/Loot/JunkChest_3.nbt,10,CHEST:4,../../../../Chests/Loot/JunkChest_4.nbt,10,CHEST:4,../../../../Chests/Loot/JunkChest_5.nbt,10,CHEST:4,../../../../Chests/Lore/HiddenMineWaste_1.nbt,1,CHEST:4,../../../../Chests/Lore/HiddenMineWaste_2.nbt,1,CHEST:4,../../../../Chests/Lore/HiddenMineWaste_3.nbt,1,CHEST:4,../../../../Chests/Lore/HiddenMineWaste_4.nbt,1,CHEST:4,../../../../Chests/Lore/HiddenMineWaste_5.nbt,1,CHEST:4,../../../../Chests/Loot/Common1.nbt,10,CHEST:4,../../../../Chests/Loot/Common2.nbt,10,CHEST:4,../../../../Chests/Loot/Common3.nbt,10,CHEST:4,../../../../Chests/Loot/Common4.nbt,10,CHEST:4,../../../../Chests/Loot/Common5.nbt,10,CHEST:4,../../../../Chests/Loot/Common6.nbt,10,CHEST:4,../../../../Chests/Loot/Common7.nbt,10,CHEST:4,../../../../Chests/Loot/Common8.nbt,10,CHEST:4,../../../../Chests/Loot/Common9.nbt,10,CHEST:4,../../../../Chests/Loot/Common10.nbt,10,CHEST:4,../../../../Chests/Loot/Common10.nbt,11,CHEST:4,../../../../Chests/Loot/Common12.nbt,10,CHEST:4,../../../../Chests/Loot/Common13.nbt,10,CHEST:4,../../../../Chests/Loot/Common14.nbt,10,CHEST:4,../../../../Chests/Loot/Common15.nbt,10,CHEST:4,../../../../Chests/Lore/HiddenMineWaste_1.nbt,2,CHEST:4,../../../../Chests/Lore/HiddenMineWaste_3.nbt,2,CHEST:4,../../../../Chests/Lore/HiddenMineWaste_4.nbt,2,CHEST:4,../../../../Chests/Lore/HiddenMineWaste_5.nbt,2,CHEST:4,../../../../Chests/Lore/HiddenMineWaste_5.nbt,2,CHEST:4,../../../../Chests/Loot/Rare1.nbt,5,CHEST:4,../../../../Chests/Loot/Rare2.nbt,5,CHEST:4,../../../../Chests/Loot/Rare3.nbt,5,CHEST:4,../../../../Chests/Loot/Rare4.nbt,5,CHEST:4,../../../../Chests/Loot/Rare5.nbt,5,CHEST:4,../../../../Chests/Loot/Rare6.nbt,5,CHEST:4,../../../../Chests/Loot/Rare7.nbt,5,CHEST:4,../../../../Chests/Loot/Rare8.nbt,5,CHEST:4,../../../../Chests/Loot/Rare9.nbt,5,CHEST:4,../../../../Chests/Loot/Rare10.nbt,5,CHEST:4,../../../../Chests/Loot/Rare11.nbt,5,CHEST:4,../../../../Chests/Loot/Rare12.nbt,5,CHEST:4,../../../../Chests/Loot/Rare13.nbt,5,CHEST:4,../../../../Chests/Loot/Rare14.nbt,5,CHEST:4,../../../../Chests/Loot/Rare15.nbt,5,CHEST:4,../../../../Chests/Loot/Epic1.nbt,2,CHEST:4,../../../../Chests/Loot/Epic2.nbt,2,CHEST:4,../../../../Chests/Loot/Epic3.nbt,2,CHEST:4,../../../../Chests/Loot/Epic4.nbt,2,CHEST:4,../../../../Chests/Loot/Epic5.nbt,2,CHEST:4,../../../../Chests/Loot/Epic6.nbt,2,CHEST:4,../../../../Chests/Loot/Epic7.nbt,2,CHEST:4,../../../../Chests/Loot/Epic8.nbt,2,CHEST:4,../../../../Chests/Loot/Epic9.nbt,2,CHEST:4,../../../../Chests/Loot/Epic10.nbt,2,CHEST:4,../../../../Chests/Loot/Epic11.nbt,2,CHEST:4,../../../../Chests/Loot/Epic12.nbt,2,CHEST:4,../../../../Chests/Loot/Epic13.nbt,2,CHEST:4,../../../../Chests/Loot/Epic14.nbt,2,CHEST:4,../../../../Chests/Loot/Epic15.nbt,5,CHEST:4,../../../../Chests/Loot/Rare1.nbt,5,CHEST:4,../../../../Chests/Loot/Rare2.nbt,5,CHEST:4,../../../../Chests/Loot/Rare3.nbt,5,CHEST:4,../../../../Chests/Loot/Rare4.nbt,5,CHEST:4,../../../../Chests/Loot/Rare5.nbt,10,CHEST:4,../../../../Chests/Loot/Rare6.nbt,10,CHEST:4,../../../../Chests/Loot/Rare7.nbt,10,CHEST:4,../../../../Chests/Loot/Rare8.nbt,10,CHEST:4,../../../../Chests/Loot/Rare9.nbt,10,CHEST:4,../../../../Chests/Loot/Rare10.nbt,15,CHEST:4,../../../../Chests/Loot/Rare11.nbt,15,CHEST:4,../../../../Chests/Loot/Rare12.nbt,15,CHEST:4,../../../../Chests/Loot/Rare13.nbt,15,CHEST:4,../../../../Chests/Loot/Rare14.nbt,15,CHEST:4,../../../../Chests/Loot/Rare15.nbt,15,CHEST:4,../../../../Chests/Loot/Epic15.nbt,100)
RandomBlock(7,7,7,DARK_OAK_FENCE:0,30,STONE:6,100)
RandomBlock(7,7,8,DARK_OAK_FENCE:0,30,STONE:6,100)
RandomBlock(7,8,-5,DARK_OAK_FENCE:0,30,STONE:6,100)
RandomBlock(7,8,-4,DARK_OAK_FENCE:0,30,STONE:6,100)
Block(7,8,-3,AIR:0)
Block(7,8,-2,AIR:0)
Block(7,8,-1,SPRUCE_FENCE:0)
Block(7,8,0,AIR:0)
Block(7,8,1,AIR:0)
Block(7,8,2,AIR:0)
Block(7,8,3,TORCH:5)
Block(7,8,4,SMOOTH_BRICK:0)
Block(7,8,5,AIR:0)
Block(7,8,6,AIR:0)
RandomBlock(7,8,7,DARK_OAK_FENCE:0,30,STONE:6,100)
RandomBlock(7,8,8,DARK_OAK_FENCE:0,30,STONE:6,100)
Block(7,9,-5,WOOD:1)
RandomBlock(7,9,-4,DARK_OAK_FENCE:0,30,STONE:6,100)
Block(7,9,-3,AIR:0)
Block(7,9,-2,AIR:0)
Block(7,9,-1,WOOD_STEP:5)
Block(7,9,0,AIR:0)
Block(7,9,1,AIR:0)
Block(7,9,2,AIR:0)
Block(7,9,3,AIR:0)
Block(7,9,4,WOOD_STEP:5)
Block(7,9,5,AIR:0)
Block(7,9,6,AIR:0)
RandomBlock(7,9,7,DARK_OAK_FENCE:0,30,STONE:6,100)
Block(7,9,8,WOOD:1)
Block(7,10,-5,WOOD:5)
RandomBlock(7,10,-4,DARK_OAK_FENCE:0,30,STONE:6,100)
Block(7,10,-3,TRAP_DOOR:8)
Block(7,10,-2,TRAP_DOOR:8)
Block(7,10,-1,TRAP_DOOR:8)
Block(7,10,0,WOOD:5)
Block(7,10,1,TRAP_DOOR:8)
Block(7,10,2,TRAP_DOOR:8)
Block(7,10,3,WOOD:5)
Block(7,10,4,TRAP_DOOR:8)
Block(7,10,5,TRAP_DOOR:8)
Block(7,10,6,TRAP_DOOR:8)
RandomBlock(7,10,7,DARK_OAK_FENCE:0,30,STONE:6,100)
Block(7,10,8,WOOD:5)
Block(8,0,-6,LOG:1)
Block(8,0,0,LOG:1)
Block(8,0,3,LOG:1)
Block(8,0,9,LOG:1)
Block(8,1,-6,WOOD:5)
Block(8,1,-5,WOOD:5)
Block(8,1,-4,WOOD:5)
Block(8,1,-3,WOOD:5)
Block(8,1,-2,WOOD:5)
Block(8,1,-1,WOOD:5)
Block(8,1,0,WOOD:5)
Block(8,1,1,WOOD:5)
Block(8,1,2,WOOD:5)
Block(8,1,3,WOOD:5)
Block(8,1,4,WOOD:5)
Block(8,1,5,WOOD:5)
Block(8,1,6,WOOD:5)
Block(8,1,7,WOOD:5)
Block(8,1,8,WOOD:5)
Block(8,1,9,WOOD:5)
Block(8,2,-4,SPRUCE_FENCE:0)
Block(8,2,-3,SMOOTH_BRICK:0)
RandomBlock(8,2,-2,DARK_OAK_FENCE:0,30,STONE:6,100)
Block(8,2,-1,SMOOTH_BRICK:0)
Block(8,2,0,DARK_OAK_STAIRS:2)
Block(8,2,1,SPRUCE_DOOR:0)
Block(8,2,2,SPRUCE_DOOR:0)
Block(8,2,3,DARK_OAK_STAIRS:3)
Block(8,2,4,SMOOTH_BRICK:0)
RandomBlock(8,2,5,DARK_OAK_FENCE:0,30,STONE:6,100)
Block(8,2,6,SMOOTH_BRICK:0)
Block(8,2,7,SPRUCE_FENCE:0)
Block(8,3,-4,SPRUCE_FENCE:0)
Block(8,3,-3,SMOOTH_BRICK:0)
RandomBlock(8,3,-2,DARK_OAK_FENCE:0,30,STONE:6,100)
Block(8,3,-1,SMOOTH_BRICK:0)
Block(8,3,0,DARK_OAK_STAIRS:6)
Block(8,3,1,SPRUCE_DOOR:8)
Block(8,3,2,SPRUCE_DOOR:9)
Block(8,3,3,DARK_OAK_STAIRS:7)
Block(8,3,4,SMOOTH_BRICK:0)
RandomBlock(8,3,5,DARK_OAK_FENCE:0,30,STONE:6,100)
Block(8,3,6,SMOOTH_BRICK:0)
Block(8,3,7,SPRUCE_FENCE:0)
Block(8,4,-4,WOOD:1)
Block(8,4,-3,SMOOTH_BRICK:0)
RandomBlock(8,4,-2,DARK_OAK_FENCE:0,30,STONE:6,100)
Block(8,4,-1,SMOOTH_BRICK:0)
Block(8,4,0,WOOD:1)
Block(8,4,1,WOOD:1)
Block(8,4,2,WOOD:1)
Block(8,4,3,WOOD:1)
Block(8,4,4,SMOOTH_BRICK:0)
RandomBlock(8,4,5,DARK_OAK_FENCE:0,30,STONE:6,100)
Block(8,4,6,SMOOTH_BRICK:0)
Block(8,4,7,WOOD:1)
Block(8,5,-4,SPRUCE_FENCE:0)
Block(8,5,-3,SMOOTH_BRICK:0)
RandomBlock(8,5,-2,DARK_OAK_FENCE:0,30,STONE:6,100)
Block(8,5,-1,SMOOTH_BRICK:0)
Block(8,5,0,SPRUCE_FENCE:0)
RandomBlock(8,5,1,DARK_OAK_FENCE:0,30,STONE:6,100)
RandomBlock(8,5,2,DARK_OAK_FENCE:0,30,STONE:6,100)
Block(8,5,3,SPRUCE_FENCE:0)
Block(8,5,4,SMOOTH_BRICK:0)
RandomBlock(8,5,5,DARK_OAK_FENCE:0,30,STONE:6,100)
Block(8,5,6,SMOOTH_BRICK:0)
Block(8,5,7,SPRUCE_FENCE:0)
Block(8,6,-4,WOOD:5)
Block(8,6,-3,WOOD:5)
Block(8,6,-2,WOOD:5)
Block(8,6,-1,WOOD:5)
Block(8,6,0,WOOD:5)
Block(8,6,1,WOOD_STEP:13)
Block(8,6,2,WOOD_STEP:13)
Block(8,6,3,WOOD:5)
Block(8,6,4,WOOD:5)
Block(8,6,5,WOOD:5)
Block(8,6,6,WOOD:5)
Block(8,6,7,WOOD:5)
Block(8,7,-4,SPRUCE_FENCE:0)
Block(8,7,-3,SMOOTH_BRICK:0)
RandomBlock(8,7,-2,DARK_OAK_FENCE:0,30,STONE:6,100)
Block(8,7,-1,SMOOTH_BRICK:0)
Block(8,7,0,STONE:6)
Block(8,7,1,SPRUCE_DOOR:2)
Block(8,7,2,SPRUCE_DOOR:2)
Block(8,7,3,STONE:6)
Block(8,7,4,SMOOTH_BRICK:0)
RandomBlock(8,7,5,DARK_OAK_FENCE:0,30,STONE:6,100)
Block(8,7,6,SMOOTH_BRICK:0)
Block(8,7,7,SPRUCE_FENCE:0)
Block(8,8,-4,SPRUCE_FENCE:0)
Block(8,8,-3,SMOOTH_BRICK:0)
RandomBlock(8,8,-2,DARK_OAK_FENCE:0,30,STONE:6,100)
Block(8,8,-1,SMOOTH_BRICK:0)
Block(8,8,0,STONE:6)
Block(8,8,1,SPRUCE_DOOR:9)
Block(8,8,2,SPRUCE_DOOR:8)
Block(8,8,3,STONE:6)
Block(8,8,4,SMOOTH_BRICK:0)
RandomBlock(8,8,5,DARK_OAK_FENCE:0,30,STONE:6,100)
Block(8,8,6,SMOOTH_BRICK:0)
Block(8,8,7,SPRUCE_FENCE:0)
Block(8,9,-4,WOOD:1)
Block(8,9,-3,SMOOTH_BRICK:0)
RandomBlock(8,9,-2,DARK_OAK_FENCE:0,30,STONE:6,100)
Block(8,9,-1,SMOOTH_BRICK:0)
Block(8,9,0,WOOD:1)
Block(8,9,1,WOOD:1)
Block(8,9,2,WOOD:1)
Block(8,9,3,WOOD:1)
Block(8,9,4,SMOOTH_BRICK:0)
RandomBlock(8,9,5,DARK_OAK_FENCE:0,30,STONE:6,100)
Block(8,9,6,SMOOTH_BRICK:0)
Block(8,9,7,WOOD:1)
Block(8,10,-4,WOOD:5)
Block(8,10,-3,WOOD:5)
Block(8,10,-2,WOOD:5)
Block(8,10,-1,WOOD:5)
Block(8,10,0,WOOD:5)
Block(8,10,1,WOOD:5)
Block(8,10,2,WOOD:5)
Block(8,10,3,WOOD:5)
Block(8,10,4,WOOD:5)
Block(8,10,5,WOOD:5)
Block(8,10,6,WOOD:5)
Block(8,10,7,WOOD:5)
WeightedBranch(0,0,-16,false,W-Mineshaft-Village-Connector-01,NORTH,17.0,0,W-Mineshaft-Village-Connector-02,NORTH,17.0,0,W-Mineshaft-Village-Connector-03,NORTH,17.0,0,W-Mineshaft-Village-End-01,NORTH,49.0,0,100.0)
WeightedBranch(0,0,16,false,W-Mineshaft-Village-Connector-01,SOUTH,17.0,0,W-Mineshaft-Village-Connector-02,SOUTH,17.0,0,W-Mineshaft-Village-Connector-03,SOUTH,17.0,0,W-Mineshaft-Village-End-01,SOUTH,49.0,0,100.0)
WeightedBranch(-16,0,0,false,W-Mineshaft-Village-Connector-01,WEST,17.0,0,W-Mineshaft-Village-Connector-02,WEST,17.0,0,W-Mineshaft-Village-Connector-03,WEST,17.0,0,W-Mineshaft-Village-End-01,WEST,49.0,0,100.0)
WeightedBranch(0,6,-16,false,W-Mineshaft-Ext-Beds-01,WEST,10.0,0,W-Mineshaft-Ext-Beds-02,WEST,10.0,0,W-Mineshaft-Ext-Beds-03,WEST,10.0,0,W-Mineshaft-Ext-Beds-04,WEST,10.0,0,W-Mineshaft-Ext-Utility-01,WEST,10.0,0,W-Mineshaft-Ext-Utility-02,WEST,10.0,0,W-Mineshaft-Ext-Utility-03,WEST,10.0,0,W-Mineshaft-Ext-Utility-04,WEST,10.0,0,W-Mineshaft-Ext-Rare-01,WEST,5.0,0,85.0)
WeightedBranch(0,6,16,false,W-Mineshaft-Ext-Beds-01,EAST,10.0,0,W-Mineshaft-Ext-Beds-02,EAST,10.0,0,W-Mineshaft-Ext-Beds-03,EAST,10.0,0,W-Mineshaft-Ext-Beds-04,EAST,10.0,0,W-Mineshaft-Ext-Utility-01,EAST,10.0,0,W-Mineshaft-Ext-Utility-02,EAST,10.0,0,W-Mineshaft-Ext-Utility-03,EAST,10.0,0,W-Mineshaft-Ext-Utility-04,EAST,10.0,0,W-Mineshaft-Ext-Rare-01,EAST,5.0,0,85.0)
WeightedBranch(-16,6,0,false,W-Mineshaft-Ext-Beds-01,SOUTH,10.0,0,W-Mineshaft-Ext-Beds-02,SOUTH,10.0,0,W-Mineshaft-Ext-Beds-03,SOUTH,10.0,0,W-Mineshaft-Ext-Beds-04,SOUTH,10.0,0,W-Mineshaft-Ext-Utility-01,SOUTH,10.0,0,W-Mineshaft-Ext-Utility-02,SOUTH,10.0,0,W-Mineshaft-Ext-Utility-03,SOUTH,10.0,0,W-Mineshaft-Ext-Utility-04,SOUTH,10.0,0,W-Mineshaft-Ext-Rare-01,SOUTH,5.0,0,85.0)
WeightedBranch(16,6,0,false,W-Mineshaft-Ext-Beds-01,NORTH,10.0,0,W-Mineshaft-Ext-Beds-02,NORTH,10.0,0,W-Mineshaft-Ext-Beds-03,NORTH,10.0,0,W-Mineshaft-Ext-Beds-04,NORTH,10.0,0,W-Mineshaft-Ext-Utility-01,NORTH,10.0,0,W-Mineshaft-Ext-Utility-02,NORTH,10.0,0,W-Mineshaft-Ext-Utility-03,NORTH,10.0,0,W-Mineshaft-Ext-Utility-04,NORTH,10.0,0,W-Mineshaft-Ext-Rare-01,NORTH,5.0,0,85.0)
WeightedBranch(0,1,-16,false,W-Mineshaft-Ext-Beds-01,WEST,10.0,0,W-Mineshaft-Ext-Beds-02,WEST,10.0,0,W-Mineshaft-Ext-Beds-03,WEST,10.0,0,W-Mineshaft-Ext-Beds-04,WEST,10.0,0,W-Mineshaft-Ext-Utility-01,WEST,10.0,0,W-Mineshaft-Ext-Utility-02,WEST,10.0,0,W-Mineshaft-Ext-Utility-03,WEST,10.0,0,W-Mineshaft-Ext-Utility-04,WEST,10.0,0,W-Mineshaft-Ext-Rare-01,WEST,5.0,0,85.0)
WeightedBranch(0,1,16,false,W-Mineshaft-Ext-Beds-01,EAST,10.0,0,W-Mineshaft-Ext-Beds-02,EAST,10.0,0,W-Mineshaft-Ext-Beds-03,EAST,10.0,0,W-Mineshaft-Ext-Beds-04,EAST,10.0,0,W-Mineshaft-Ext-Utility-01,EAST,10.0,0,W-Mineshaft-Ext-Utility-02,EAST,10.0,0,W-Mineshaft-Ext-Utility-03,EAST,10.0,0,W-Mineshaft-Ext-Utility-04,EAST,10.0,0,W-Mineshaft-Ext-Rare-01,EAST,5.0,0,85.0)
WeightedBranch(-16,1,0,false,W-Mineshaft-Ext-Beds-01,SOUTH,10.0,0,W-Mineshaft-Ext-Beds-02,SOUTH,10.0,0,W-Mineshaft-Ext-Beds-03,SOUTH,10.0,0,W-Mineshaft-Ext-Beds-04,SOUTH,10.0,0,W-Mineshaft-Ext-Utility-01,SOUTH,10.0,0,W-Mineshaft-Ext-Utility-02,SOUTH,10.0,0,W-Mineshaft-Ext-Utility-03,SOUTH,10.0,0,W-Mineshaft-Ext-Utility-04,SOUTH,10.0,0,W-Mineshaft-Ext-Rare-01,SOUTH,5.0,0,85.0)
WeightedBranch(16,1,0,false,W-Mineshaft-Ext-Beds-01,NORTH,10.0,0,W-Mineshaft-Ext-Beds-02,NORTH,10.0,0,W-Mineshaft-Ext-Beds-03,NORTH,10.0,0,W-Mineshaft-Ext-Beds-04,NORTH,10.0,0,W-Mineshaft-Ext-Utility-01,NORTH,10.0,0,W-Mineshaft-Ext-Utility-02,NORTH,10.0,0,W-Mineshaft-Ext-Utility-03,NORTH,10.0,0,W-Mineshaft-Ext-Utility-04,NORTH,10.0,0,W-Mineshaft-Ext-Rare-01,NORTH,5.0,0,85.0)
Branch(0,-10,0,true,W-Mineshaft-Bottom-Foundation,NORTH,100.0,0)
Branch(0,-13,0,true,W-Mineshaft-Bottom-Foundation-Ext,NORTH,100.0,0)
Branch(0,-16,0,false,W-Mineshaft-Bottom-Foundation-Ext,NORTH,100.0,0)
Branch(0,-19,0,false,W-Mineshaft-Bottom-Foundation-Ext,NORTH,100.0,0)
Branch(0,-22,0,false,W-Mineshaft-Bottom-Foundation-Ext,NORTH,100.0,0)
Branch(0,-25,0,false,W-Mineshaft-Bottom-Foundation-Ext,NORTH,100.0,0)
Entity(-6,7,2,minecraft:villager,1)
Entity(-3,2,-4,minecraft:villager,1)
Entity(-2,2,6,minecraft:villager,1)
Entity(1,7,4,minecraft:ocelot,1,../../NBT/Mobs/VillageCat.txt)
Entity(2,7,1,minecraft:villager,1)
Entity(3,7,-4,minecraft:villager,1)
Entity(5,2,-1,minecraft:villager,1)
Entity(7,7,0,minecraft:villager,1)
