Author: BO3 BulkEdit (by LanToaster)
Description: This Object was Created with BO3_BulkEdit
Version: 3
SettingsMode: WriteDisable
Tree: false
Frequency: 100
Rarity: 100
RotateRandomly: true
SpawnHeight: highestBlock
MinHeight: 0
MaxHeight: 256
MaxBranchDepth: 50
ExcludedBiomes: All
SourceBlocks: AIR
MaxPercentageOutsideSourceBlock: 100
OutsideSourceBlock: placeAnyway
Block(-7,-1,-8,STAINED_HARDENED_CLAY:12)
Block(-6,-1,-8,STAINED_HARDENED_CLAY:12)
Block(-5,-1,-8,STAINED_HARDENED_CLAY:12)
Block(-4,-1,-8,STAINED_HARDENED_CLAY:12)
Block(-3,-1,-8,STAINED_HARDENED_CLAY:12)
Block(-7,-1,-7,STAINED_HARDENED_CLAY:12)
Block(-6,-1,-7,MAGMA:0)
Block(-5,-1,-7,MAGMA:0)
Block(-4,-1,-7,MAGMA:0)
Block(-3,-1,-7,STAINED_HARDENED_CLAY:12)
Block(-7,-1,-6,STAINED_HARDENED_CLAY:12)
Block(-6,-1,-6,MAGMA:0)
Block(-5,-1,-6,MAGMA:0)
Block(-4,-1,-6,MAGMA:0)
Block(-3,-1,-6,STAINED_HARDENED_CLAY:12)
Block(-1,-1,-6,GRASS_PATH:0)
Block(1,-1,-6,LOG_2:0)
Block(5,-1,-6,LOG_2:0)
Block(-7,-1,-5,STAINED_HARDENED_CLAY:12)
Block(-6,-1,-5,STAINED_HARDENED_CLAY:12)
Block(-5,-1,-5,STAINED_HARDENED_CLAY:12)
Block(-4,-1,-5,STAINED_HARDENED_CLAY:12)
Block(-3,-1,-5,STAINED_HARDENED_CLAY:12)
Block(-2,-1,-5,GRASS_PATH:0)
Block(-1,-1,-5,GRASS_PATH:0)
Block(0,-1,-5,GRASS_PATH:0)
Block(-7,-1,-4,GRASS_PATH:0)
Block(-6,-1,-4,GRASS_PATH:0)
Block(-5,-1,-4,GRASS_PATH:0)
Block(-4,-1,-4,GRASS_PATH:0)
Block(-3,-1,-4,GRASS_PATH:0)
Block(-2,-1,-4,DOUBLE_STONE_SLAB:3)
Block(-1,-1,-4,GRASS_PATH:0)
Block(0,-1,-4,DOUBLE_STONE_SLAB:3)
Block(1,-1,-4,GRASS_PATH:0)
Block(-6,-1,-3,GRASS_PATH:0)
Block(-5,-1,-3,GRASS_PATH:0)
Block(-4,-1,-3,GRASS_PATH:0)
Block(-3,-1,-3,GRASS_PATH:0)
Block(-2,-1,-3,GRASS_PATH:0)
Block(-1,-1,-3,GRASS_PATH:0)
Block(0,-1,-3,GRASS_PATH:0)
Block(1,-1,-3,GRASS_PATH:0)
Block(2,-1,-3,GRASS_PATH:0)
Block(-6,-1,-2,GRASS_PATH:0)
Block(-5,-1,-2,GRASS_PATH:0)
Block(-4,-1,-2,DOUBLE_STONE_SLAB:3)
Block(-3,-1,-2,GRASS_PATH:0)
Block(-2,-1,-2,GRASS_PATH:0)
Block(-1,-1,-2,DOUBLE_STONE_SLAB:3)
Block(0,-1,-2,GRASS_PATH:0)
Block(1,-1,-2,GRASS_PATH:0)
Block(-7,-1,-1,GRASS_PATH:0)
Block(-6,-1,-1,GRASS_PATH:0)
Block(-5,-1,-1,GRASS_PATH:0)
Block(-4,-1,-1,GRASS_PATH:0)
Block(-3,-1,-1,GRASS_PATH:0)
Block(-2,-1,-1,GRASS_PATH:0)
Block(-1,-1,-1,DIRT:0)
Block(0,-1,-1,GRASS_PATH:0)
Block(1,-1,-1,GRASS_PATH:0)
Block(-6,-1,0,HAY_BLOCK:4)
Block(-5,-1,0,GRASS_PATH:0)
Block(-4,-1,0,GRASS_PATH:0)
Block(-3,-1,0,DOUBLE_STONE_SLAB:3)
Block(-2,-1,0,GRASS_PATH:0)
Block(0,-1,0,GRASS_PATH:0)
Block(-6,-1,1,HAY_BLOCK:8)
Block(-5,-1,1,HAY_BLOCK:4)
Block(-4,-1,1,GRASS_PATH:0)
Block(-3,-1,1,LOG_2:0)
Block(-2,-1,1,GRASS_PATH:0)
Block(1,-1,1,LOG_2:0)
Block(5,-1,1,LOG_2:0)
Block(-6,-1,2,HAY_BLOCK:4)
Block(-5,-1,2,HAY_BLOCK:8)
Block(-4,-1,2,HAY_BLOCK:0)
Block(-5,-1,3,HAY_BLOCK:0)
Block(-4,-1,3,HAY_BLOCK:0)
Block(-4,-1,4,HAY_BLOCK:0)
Block(-3,-1,5,LOG_2:0)
Block(1,-1,5,LOG_2:0)
Block(5,-1,5,LOG_2:0)
Block(-7,0,-8,STAINED_HARDENED_CLAY:12)
Block(-6,0,-8,STAINED_HARDENED_CLAY:12)
Block(-5,0,-8,STAINED_HARDENED_CLAY:12)
Block(-4,0,-8,STAINED_HARDENED_CLAY:12)
Block(-3,0,-8,STAINED_HARDENED_CLAY:12)
Block(-7,0,-7,STAINED_HARDENED_CLAY:12)
Block(-3,0,-7,STAINED_HARDENED_CLAY:12)
Block(-7,0,-6,STAINED_HARDENED_CLAY:12)
Block(-3,0,-6,STAINED_HARDENED_CLAY:12)
Block(1,0,-6,LOG_2:0)
Block(5,0,-6,LOG_2:0)
Block(-7,0,-5,STAINED_HARDENED_CLAY:12)
Block(-6,0,-5,STAINED_HARDENED_CLAY:12)
Block(-5,0,-5,STONE_SLAB:3)
Block(-4,0,-5,STAINED_HARDENED_CLAY:12)
Block(-3,0,-5,STAINED_HARDENED_CLAY:12)
Block(-2,0,-4,AIR)
Entity(-2,0,-4,VILLAGER,1,../../NBT/entities/tribalbaker.txt)
Block(0,0,-4,HAY_BLOCK:0)
Block(-4,0,-2,AIR)
Block(-1,0,-1,OAK_STAIRS:2)
Block(-3,0,0,AIR)
Block(-1,0,0,OAK_STAIRS:7)
Block(-6,0,1,HAY_BLOCK:0)
Block(-5,0,1,HAY_BLOCK:0)
Block(-3,0,1,LOG_2:0)
Block(1,0,1,LOG_2:0)
Block(5,0,1,LOG_2:0)
Block(-5,0,2,HAY_BLOCK:0)
Block(-4,0,2,HAY_BLOCK:0)
Block(-4,0,3,HAY_BLOCK:0)
Block(-3,0,5,LOG_2:0)
Block(1,0,5,LOG_2:0)
Block(5,0,5,LOG_2:0)
Block(-7,1,-8,STONE_STAIRS:0)
Block(-6,1,-8,STAINED_HARDENED_CLAY:12)
Block(-5,1,-8,STAINED_HARDENED_CLAY:12)
Block(-4,1,-8,STAINED_HARDENED_CLAY:12)
Block(-3,1,-8,STONE_STAIRS:2)
Block(-7,1,-7,STONE_STAIRS:0)
Block(-6,1,-7,STONE_SLAB:11)
Block(-4,1,-7,STONE_SLAB:11)
Block(-3,1,-7,STONE_STAIRS:1)
Block(-7,1,-6,STONE_STAIRS:0)
Block(-6,1,-6,STONE_SLAB:11)
Block(-4,1,-6,STONE_SLAB:11)
Block(-3,1,-6,STONE_STAIRS:1)
Block(1,1,-6,LOG_2:0)
Block(2,1,-6,LOG_2:4)
Block(3,1,-6,LOG_2:4)
Block(4,1,-6,LOG_2:4)
Block(5,1,-6,LOG_2:0)
Block(-7,1,-5,STONE_STAIRS:3)
Block(-6,1,-5,STONE_STAIRS:3)
Block(-4,1,-5,STONE_STAIRS:3)
Block(-3,1,-5,STONE_STAIRS:3)
Block(1,1,-5,LOG_2:8)
Block(2,1,-5,WOODEN_SLAB:10)
Block(3,1,-5,WOODEN_SLAB:10)
Block(4,1,-5,WOODEN_SLAB:10)
Block(5,1,-5,LOG_2:8)
Block(1,1,-4,LOG_2:8)
Block(2,1,-4,WOODEN_SLAB:10)
Block(3,1,-4,WOODEN_SLAB:10)
Block(4,1,-4,WOODEN_SLAB:10)
Block(5,1,-4,LOG_2:8)
Block(1,1,-3,LOG_2:8)
Block(2,1,-3,WOODEN_SLAB:10)
Block(3,1,-3,WOODEN_SLAB:10)
Block(4,1,-3,WOODEN_SLAB:10)
Block(5,1,-3,LOG_2:8)
Block(1,1,-2,LOG_2:8)
Block(2,1,-2,WOODEN_SLAB:10)
Block(3,1,-2,WOODEN_SLAB:10)
Block(4,1,-2,WOODEN_SLAB:10)
Block(5,1,-2,LOG_2:8)
Block(1,1,-1,LOG_2:8)
Block(2,1,-1,WOODEN_SLAB:10)
Block(3,1,-1,WOODEN_SLAB:10)
Block(4,1,-1,WOODEN_SLAB:10)
Block(5,1,-1,LOG_2:8)
Block(-1,1,0,OAK_STAIRS:2)
Block(1,1,0,LOG_2:8)
Block(2,1,0,WOODEN_SLAB:10)
Block(3,1,0,WOODEN_SLAB:10)
Block(4,1,0,WOODEN_SLAB:10)
Block(5,1,0,LOG_2:8)
Block(-3,1,1,LOG_2:0)
Block(-2,1,1,LOG_2:4)
Block(-1,1,1,LOG_2:4)
Block(0,1,1,LOG_2:4)
Block(1,1,1,LOG_2:0)
Block(2,1,1,WOODEN_SLAB:10)
Block(3,1,1,WOODEN_SLAB:10)
Block(4,1,1,WOODEN_SLAB:10)
Block(5,1,1,LOG_2:0)
Block(-4,1,2,HAY_BLOCK:0)
Block(-3,1,2,LOG_2:8)
Block(-2,1,2,WOODEN_SLAB:10)
Block(-1,1,2,WOODEN_SLAB:10)
Block(0,1,2,WOODEN_SLAB:10)
Block(1,1,2,WOODEN_SLAB:10)
Block(2,1,2,WOODEN_SLAB:10)
Block(3,1,2,WOODEN_SLAB:10)
Block(4,1,2,WOODEN_SLAB:10)
Block(5,1,2,LOG_2:8)
Block(-3,1,3,LOG_2:8)
Block(-2,1,3,WOODEN_SLAB:10)
Block(-1,1,3,WOODEN_SLAB:10)
Block(0,1,3,WOODEN_SLAB:10)
Block(1,1,3,WOODEN_SLAB:10)
Block(2,1,3,WOODEN_SLAB:10)
Block(3,1,3,WOODEN_SLAB:10)
Block(4,1,3,WOODEN_SLAB:10)
Block(5,1,3,LOG_2:8)
Block(-3,1,4,LOG_2:8)
Block(-2,1,4,WOODEN_SLAB:10)
Block(-1,1,4,WOODEN_SLAB:10)
Block(0,1,4,WOODEN_SLAB:10)
Block(1,1,4,WOODEN_SLAB:10)
Block(2,1,4,WOODEN_SLAB:10)
Block(3,1,4,WOODEN_SLAB:10)
Block(4,1,4,WOODEN_SLAB:10)
Block(5,1,4,LOG_2:8)
Block(-3,1,5,LOG_2:0)
Block(-2,1,5,LOG_2:4)
Block(-1,1,5,LOG_2:4)
Block(0,1,5,LOG_2:4)
Block(1,1,5,LOG_2:0)
Block(2,1,5,LOG_2:4)
Block(3,1,5,LOG_2:4)
Block(4,1,5,LOG_2:4)
Block(5,1,5,LOG_2:0)
Block(-6,2,-8,STONE_SLAB:3)
Block(-5,2,-8,DOUBLE_STONE_SLAB:3)
Block(-4,2,-8,STONE_SLAB:3)
Block(-6,2,-7,DOUBLE_STONE_SLAB:3)
Block(-4,2,-7,DOUBLE_STONE_SLAB:3)
Block(-6,2,-6,STONE_SLAB:3)
Block(-5,2,-6,DOUBLE_STONE_SLAB:3)
Block(-4,2,-6,STONE_SLAB:3)
Block(1,2,-6,LOG_2:0)
Block(2,2,-6,STAINED_HARDENED_CLAY:15)
Block(3,2,-6,STAINED_HARDENED_CLAY:15)
Block(4,2,-6,STAINED_HARDENED_CLAY:15)
Block(5,2,-6,LOG_2:0)
Block(1,2,-5,STAINED_HARDENED_CLAY:15)
Block(2,2,-5,SPRUCE_STAIRS:7)
Block(4,2,-5,CAULDRON:3)
Block(5,2,-5,STAINED_HARDENED_CLAY:15)
Block(1,2,-4,STAINED_HARDENED_CLAY:15)
Block(2,2,-4,WOODEN_SLAB:9)
Block(4,2,-4,FURNACE:4)
Block(5,2,-4,STAINED_HARDENED_CLAY:15)
Block(1,2,-3,STAINED_HARDENED_CLAY:15)
Block(2,2,-3,WOODEN_SLAB:9)
Block(5,2,-3,STAINED_HARDENED_CLAY:15)
Block(1,2,-2,STAINED_HARDENED_CLAY:15)
Block(2,2,-2,WOODEN_SLAB:9)
Block(4,2,-2,CRAFTING_TABLE:0)
Block(5,2,-2,STAINED_HARDENED_CLAY:15)
Block(1,2,-1,STAINED_HARDENED_CLAY:15)
Block(2,2,-1,WOODEN_SLAB:9)
Block(3,2,-1,AIR)
Block(4,2,-1,CRAFTING_TABLE:0)
Block(5,2,-1,STAINED_HARDENED_CLAY:15)
Block(1,2,0,STAINED_HARDENED_CLAY:15)
Block(2,2,0,SPRUCE_STAIRS:6)
Block(4,2,0,TRAPDOOR:10)
Block(5,2,0,STAINED_HARDENED_CLAY:15)
Block(-3,2,1,LOG_2:0)
Block(-2,2,1,STAINED_HARDENED_CLAY:0)
Block(-1,2,1,BIRCH_DOOR:3)
Block(0,2,1,STAINED_HARDENED_CLAY:0)
Block(1,2,1,LOG_2:0)
Block(4,2,1,TRAPDOOR:10)
Block(5,2,1,LOG_2:0)
Block(-3,2,2,STAINED_HARDENED_CLAY:15)
Block(4,2,2,TRAPDOOR:10)
Block(5,2,2,STAINED_HARDENED_CLAY:15)
Block(-3,2,3,STAINED_HARDENED_CLAY:15)
Block(-2,2,3,ACACIA_FENCE:0)
Block(4,2,3,TRAPDOOR:10)
Block(5,2,3,STAINED_HARDENED_CLAY:15)
Block(-3,2,4,STAINED_HARDENED_CLAY:15)
Block(-2,2,4,ACACIA_FENCE:0)
Block(-1,2,4,ACACIA_FENCE:0)
Block(4,2,4,TRAPDOOR:10)
Block(5,2,4,STAINED_HARDENED_CLAY:15)
Block(-3,2,5,LOG_2:0)
Block(-2,2,5,STAINED_HARDENED_CLAY:15)
Block(-1,2,5,STAINED_HARDENED_CLAY:15)
Block(0,2,5,STAINED_HARDENED_CLAY:15)
Block(1,2,5,LOG_2:0)
Block(2,2,5,STAINED_HARDENED_CLAY:0)
Block(3,2,5,STAINED_HARDENED_CLAY:0)
Block(4,2,5,STAINED_HARDENED_CLAY:0)
Block(5,2,5,LOG_2:0)
Block(-5,3,-8,STONE_STAIRS:2)
Block(-6,3,-7,STONE_STAIRS:0)
Block(-4,3,-7,STONE_STAIRS:1)
Block(-5,3,-6,STONE_STAIRS:3)
Block(1,3,-6,LOG_2:0)
Block(2,3,-6,STAINED_HARDENED_CLAY:15)
Block(3,3,-6,STAINED_HARDENED_CLAY:15)
Block(4,3,-6,STAINED_HARDENED_CLAY:15)
Block(5,3,-6,LOG_2:0)
Block(1,3,-5,STAINED_HARDENED_CLAY:15)
Block(5,3,-5,STAINED_HARDENED_CLAY:15)
Block(1,3,-4,ACACIA_FENCE:0)
Block(4,3,-4,IRON_TRAPDOOR:2)
Block(5,3,-4,STAINED_HARDENED_CLAY:15)
Block(1,3,-3,ACACIA_FENCE:0)
Block(5,3,-3,STAINED_HARDENED_CLAY:15)
Block(1,3,-2,ACACIA_FENCE:0)
RandomBlock(4,3,-2,FLOWER_POT:0,../../NBT/pots/JunglePot01.nbt,10,FLOWER_POT:0,../../NBT/pots/JunglePot02.nbt,10,FLOWER_POT:0,../../NBT/pots/JunglePot03.nbt,10,FLOWER_POT:0,../../NBT/pots/JunglePot04.nbt,10,FLOWER_POT:0,../../NBT/pots/JunglePot05.nbt,10,FLOWER_POT:0,../../NBT/pots/JunglePot06.nbt,10,FLOWER_POT:0,../../NBT/pots/JunglePot07.nbt,10,FLOWER_POT:0,../../NBT/pots/JunglePot08.nbt,100)
Block(5,3,-2,STAINED_HARDENED_CLAY:15)
Block(1,3,-1,ACACIA_FENCE:0)
Block(5,3,-1,ACACIA_FENCE:0)
Block(1,3,0,STAINED_HARDENED_CLAY:15)
Block(5,3,0,STAINED_HARDENED_CLAY:15)
Block(-3,3,1,LOG_2:0)
Block(-2,3,1,STAINED_HARDENED_CLAY:0)
Block(-1,3,1,BIRCH_DOOR:8)
Block(0,3,1,STAINED_HARDENED_CLAY:0)
Block(1,3,1,LOG_2:0)
RandomBlock(4,3,1,AIR:0,20,CHEST:4,../../../../Chests/Loot/JunkChest_1.nbt,10,CHEST:4,../../../../Chests/Loot/JunkChest_2.nbt,10,CHEST:4,../../../../Chests/Loot/JunkChest_3.nbt,10,CHEST:4,../../../../Chests/Loot/JunkChest_4.nbt,10,CHEST:4,../../../../Chests/Loot/JunkChest_5.nbt,10,CHEST:4,../../../../Chests/Lore/JungleLore_1.nbt,1,CHEST:4,../../../../Chests/Lore/JungleLore_2.nbt,1,CHEST:4,../../../../Chests/Lore/JungleLore_3.nbt,1,CHEST:4,../../../../Chests/Lore/JungleLore_4.nbt,1,CHEST:4,../../../../Chests/Lore/JungleLore_5.nbt,1,CHEST:4,../../../../Chests/Loot/Common1.nbt,10,CHEST:4,../../../../Chests/Loot/Common2.nbt,10,CHEST:4,../../../../Chests/Loot/Common3.nbt,10,CHEST:4,../../../../Chests/Loot/Common4.nbt,10,CHEST:4,../../../../Chests/Loot/Common5.nbt,10,CHEST:4,../../../../Chests/Loot/Common6.nbt,10,CHEST:4,../../../../Chests/Loot/Common7.nbt,10,CHEST:4,../../../../Chests/Loot/Common8.nbt,10,CHEST:4,../../../../Chests/Loot/Common9.nbt,10,CHEST:4,../../../../Chests/Loot/Common10.nbt,10,CHEST:4,../../../../Chests/Loot/Common10.nbt,11,CHEST:4,../../../../Chests/Loot/Common12.nbt,10,CHEST:4,../../../../Chests/Loot/Common13.nbt,10,CHEST:4,../../../../Chests/Loot/Common14.nbt,10,CHEST:4,../../../../Chests/Loot/Common15.nbt,10,CHEST:4,../../../../Chests/Lore/JungleLore_1.nbt,2,CHEST:4,../../../../Chests/Lore/JungleLore_3.nbt,2,CHEST:4,../../../../Chests/Lore/JungleLore_4.nbt,2,CHEST:4,../../../../Chests/Lore/JungleLore_5.nbt,2,CHEST:4,../../../../Chests/Lore/JungleLore_5.nbt,2,CHEST:4,../../../../Chests/Loot/Rare1.nbt,5,CHEST:4,../../../../Chests/Loot/Rare2.nbt,5,CHEST:4,../../../../Chests/Loot/Rare3.nbt,5,CHEST:4,../../../../Chests/Loot/Rare4.nbt,5,CHEST:4,../../../../Chests/Loot/Rare5.nbt,5,CHEST:4,../../../../Chests/Loot/Rare6.nbt,5,CHEST:4,../../../../Chests/Loot/Rare7.nbt,5,CHEST:4,../../../../Chests/Loot/Rare8.nbt,5,CHEST:4,../../../../Chests/Loot/Rare9.nbt,5,CHEST:4,../../../../Chests/Loot/Rare10.nbt,5,CHEST:4,../../../../Chests/Loot/Rare11.nbt,5,CHEST:4,../../../../Chests/Loot/Rare12.nbt,5,CHEST:4,../../../../Chests/Loot/Rare13.nbt,5,CHEST:4,../../../../Chests/Loot/Rare14.nbt,5,CHEST:4,../../../../Chests/Loot/Rare15.nbt,5,CHEST:4,../../../../Chests/Loot/Epic1.nbt,2,CHEST:4,../../../../Chests/Loot/Epic2.nbt,2,CHEST:4,../../../../Chests/Loot/Epic3.nbt,2,CHEST:4,../../../../Chests/Loot/Epic4.nbt,2,CHEST:4,../../../../Chests/Loot/Epic5.nbt,2,CHEST:4,../../../../Chests/Loot/Epic6.nbt,2,CHEST:4,../../../../Chests/Loot/Epic7.nbt,2,CHEST:4,../../../../Chests/Loot/Epic8.nbt,2,CHEST:4,../../../../Chests/Loot/Epic9.nbt,2,CHEST:4,../../../../Chests/Loot/Epic10.nbt,2,CHEST:4,../../../../Chests/Loot/Epic11.nbt,2,CHEST:4,../../../../Chests/Loot/Epic12.nbt,2,CHEST:4,../../../../Chests/Loot/Epic13.nbt,2,CHEST:4,../../../../Chests/Loot/Epic14.nbt,2,CHEST:4,../../../../Chests/Loot/Epic15.nbt,5,CHEST:4,../../../../Chests/Loot/Rare1.nbt,5,CHEST:4,../../../../Chests/Loot/Rare2.nbt,5,CHEST:4,../../../../Chests/Loot/Rare3.nbt,5,CHEST:4,../../../../Chests/Loot/Rare4.nbt,5,CHEST:4,../../../../Chests/Loot/Rare5.nbt,10,CHEST:4,../../../../Chests/Loot/Rare6.nbt,10,CHEST:4,../../../../Chests/Loot/Rare7.nbt,10,CHEST:4,../../../../Chests/Loot/Rare8.nbt,10,CHEST:4,../../../../Chests/Loot/Rare9.nbt,10,CHEST:4,../../../../Chests/Loot/Rare10.nbt,15,CHEST:4,../../../../Chests/Loot/Rare11.nbt,15,CHEST:4,../../../../Chests/Loot/Rare12.nbt,15,CHEST:4,../../../../Chests/Loot/Rare13.nbt,15,CHEST:4,../../../../Chests/Loot/Rare14.nbt,15,CHEST:4,../../../../Chests/Loot/Rare15.nbt,15,CHEST:4,../../../../Chests/Loot/Epic15.nbt,100)
Block(5,3,1,LOG_2:0)
Block(-3,3,2,STAINED_HARDENED_CLAY:15)
RandomBlock(4,3,2,AIR:0,20,CHEST:4,../../../../Chests/Loot/JunkChest_1.nbt,10,CHEST:4,../../../../Chests/Loot/JunkChest_2.nbt,10,CHEST:4,../../../../Chests/Loot/JunkChest_3.nbt,10,CHEST:4,../../../../Chests/Loot/JunkChest_4.nbt,10,CHEST:4,../../../../Chests/Loot/JunkChest_5.nbt,10,CHEST:4,../../../../Chests/Lore/JungleLore_1.nbt,1,CHEST:4,../../../../Chests/Lore/JungleLore_2.nbt,1,CHEST:4,../../../../Chests/Lore/JungleLore_3.nbt,1,CHEST:4,../../../../Chests/Lore/JungleLore_4.nbt,1,CHEST:4,../../../../Chests/Lore/JungleLore_5.nbt,1,CHEST:4,../../../../Chests/Loot/Common1.nbt,10,CHEST:4,../../../../Chests/Loot/Common2.nbt,10,CHEST:4,../../../../Chests/Loot/Common3.nbt,10,CHEST:4,../../../../Chests/Loot/Common4.nbt,10,CHEST:4,../../../../Chests/Loot/Common5.nbt,10,CHEST:4,../../../../Chests/Loot/Common6.nbt,10,CHEST:4,../../../../Chests/Loot/Common7.nbt,10,CHEST:4,../../../../Chests/Loot/Common8.nbt,10,CHEST:4,../../../../Chests/Loot/Common9.nbt,10,CHEST:4,../../../../Chests/Loot/Common10.nbt,10,CHEST:4,../../../../Chests/Loot/Common10.nbt,11,CHEST:4,../../../../Chests/Loot/Common12.nbt,10,CHEST:4,../../../../Chests/Loot/Common13.nbt,10,CHEST:4,../../../../Chests/Loot/Common14.nbt,10,CHEST:4,../../../../Chests/Loot/Common15.nbt,10,CHEST:4,../../../../Chests/Lore/JungleLore_1.nbt,2,CHEST:4,../../../../Chests/Lore/JungleLore_3.nbt,2,CHEST:4,../../../../Chests/Lore/JungleLore_4.nbt,2,CHEST:4,../../../../Chests/Lore/JungleLore_5.nbt,2,CHEST:4,../../../../Chests/Lore/JungleLore_5.nbt,2,CHEST:4,../../../../Chests/Loot/Rare1.nbt,5,CHEST:4,../../../../Chests/Loot/Rare2.nbt,5,CHEST:4,../../../../Chests/Loot/Rare3.nbt,5,CHEST:4,../../../../Chests/Loot/Rare4.nbt,5,CHEST:4,../../../../Chests/Loot/Rare5.nbt,5,CHEST:4,../../../../Chests/Loot/Rare6.nbt,5,CHEST:4,../../../../Chests/Loot/Rare7.nbt,5,CHEST:4,../../../../Chests/Loot/Rare8.nbt,5,CHEST:4,../../../../Chests/Loot/Rare9.nbt,5,CHEST:4,../../../../Chests/Loot/Rare10.nbt,5,CHEST:4,../../../../Chests/Loot/Rare11.nbt,5,CHEST:4,../../../../Chests/Loot/Rare12.nbt,5,CHEST:4,../../../../Chests/Loot/Rare13.nbt,5,CHEST:4,../../../../Chests/Loot/Rare14.nbt,5,CHEST:4,../../../../Chests/Loot/Rare15.nbt,5,CHEST:4,../../../../Chests/Loot/Epic1.nbt,2,CHEST:4,../../../../Chests/Loot/Epic2.nbt,2,CHEST:4,../../../../Chests/Loot/Epic3.nbt,2,CHEST:4,../../../../Chests/Loot/Epic4.nbt,2,CHEST:4,../../../../Chests/Loot/Epic5.nbt,2,CHEST:4,../../../../Chests/Loot/Epic6.nbt,2,CHEST:4,../../../../Chests/Loot/Epic7.nbt,2,CHEST:4,../../../../Chests/Loot/Epic8.nbt,2,CHEST:4,../../../../Chests/Loot/Epic9.nbt,2,CHEST:4,../../../../Chests/Loot/Epic10.nbt,2,CHEST:4,../../../../Chests/Loot/Epic11.nbt,2,CHEST:4,../../../../Chests/Loot/Epic12.nbt,2,CHEST:4,../../../../Chests/Loot/Epic13.nbt,2,CHEST:4,../../../../Chests/Loot/Epic14.nbt,2,CHEST:4,../../../../Chests/Loot/Epic15.nbt,5,CHEST:4,../../../../Chests/Loot/Rare1.nbt,5,CHEST:4,../../../../Chests/Loot/Rare2.nbt,5,CHEST:4,../../../../Chests/Loot/Rare3.nbt,5,CHEST:4,../../../../Chests/Loot/Rare4.nbt,5,CHEST:4,../../../../Chests/Loot/Rare5.nbt,10,CHEST:4,../../../../Chests/Loot/Rare6.nbt,10,CHEST:4,../../../../Chests/Loot/Rare7.nbt,10,CHEST:4,../../../../Chests/Loot/Rare8.nbt,10,CHEST:4,../../../../Chests/Loot/Rare9.nbt,10,CHEST:4,../../../../Chests/Loot/Rare10.nbt,15,CHEST:4,../../../../Chests/Loot/Rare11.nbt,15,CHEST:4,../../../../Chests/Loot/Rare12.nbt,15,CHEST:4,../../../../Chests/Loot/Rare13.nbt,15,CHEST:4,../../../../Chests/Loot/Rare14.nbt,15,CHEST:4,../../../../Chests/Loot/Rare15.nbt,15,CHEST:4,../../../../Chests/Loot/Epic15.nbt,100)
Block(5,3,2,STAINED_HARDENED_CLAY:15)
Block(-3,3,3,ACACIA_FENCE:0)
Block(-2,3,3,WOODEN_PRESSURE_PLATE:0)
Block(5,3,3,ACACIA_FENCE:0)
Block(-3,3,4,STAINED_HARDENED_CLAY:15)
Block(-2,3,4,WOODEN_PRESSURE_PLATE:0)
Block(-1,3,4,WOODEN_PRESSURE_PLATE:0)
Block(5,3,4,STAINED_HARDENED_CLAY:15)
Block(-3,3,5,LOG_2:0)
Block(-2,3,5,STAINED_HARDENED_CLAY:15)
Block(-1,3,5,ACACIA_FENCE:0)
Block(0,3,5,STAINED_HARDENED_CLAY:15)
Block(1,3,5,LOG_2:0)
Block(2,3,5,STAINED_HARDENED_CLAY:0)
Block(3,3,5,ACACIA_FENCE:0)
Block(4,3,5,STAINED_HARDENED_CLAY:0)
Block(5,3,5,LOG_2:0)
Block(-5,4,-8,STONE_STAIRS:6)
Block(-6,4,-7,STONE_STAIRS:4)
Block(-4,4,-7,STONE_STAIRS:5)
Block(0,4,-7,OAK_STAIRS:0)
Block(1,4,-7,OAK_STAIRS:5)
Block(5,4,-7,OAK_STAIRS:4)
Block(6,4,-7,DOUBLE_WOODEN_SLAB:1)
Block(-5,4,-6,STONE_STAIRS:7)
Block(0,4,-6,OAK_STAIRS:0)
Block(1,4,-6,LOG_2:0)
Block(2,4,-6,LOG_2:4)
Block(3,4,-6,LOG_2:4)
Block(4,4,-6,LOG_2:4)
Block(5,4,-6,LOG_2:0)
Block(6,4,-6,WOODEN_SLAB:1)
Block(0,4,-5,OAK_STAIRS:0)
Block(1,4,-5,LOG_2:8)
Block(5,4,-5,LOG_2:8)
Block(6,4,-5,DOUBLE_WOODEN_SLAB:1)
Block(0,4,-4,OAK_STAIRS:0)
Block(1,4,-4,LOG_2:8)
Block(5,4,-4,LOG_2:8)
Block(6,4,-4,WOODEN_SLAB:9)
Block(0,4,-3,OAK_STAIRS:0)
Block(1,4,-3,LOG_2:8)
Block(5,4,-3,LOG_2:8)
Block(6,4,-3,WOODEN_SLAB:1)
Block(0,4,-2,OAK_STAIRS:0)
Block(1,4,-2,LOG_2:8)
Block(5,4,-2,LOG_2:8)
Block(6,4,-2,OAK_STAIRS:2)
Block(0,4,-1,OAK_STAIRS:0)
Block(1,4,-1,LOG_2:8)
Block(5,4,-1,LOG_2:8)
Block(6,4,-1,OAK_STAIRS:1)
Block(-4,4,0,OAK_STAIRS:2)
Block(-3,4,0,OAK_STAIRS:2)
Block(-2,4,0,OAK_STAIRS:2)
Block(-1,4,0,OAK_STAIRS:2)
Block(0,4,0,OAK_STAIRS:0)
Block(1,4,0,LOG_2:8)
Block(5,4,0,LOG_2:8)
Block(6,4,0,OAK_STAIRS:3)
Block(-4,4,1,OAK_STAIRS:7)
Block(-3,4,1,LOG_2:0)
Block(-2,4,1,LOG_2:4)
Block(-1,4,1,LOG_2:4)
Block(0,4,1,LOG_2:4)
Block(1,4,1,LOG_2:0)
Block(5,4,1,LOG_2:0)
Block(6,4,1,WOODEN_SLAB:1)
Block(-3,4,2,LOG_2:8)
Block(5,4,2,LOG_2:8)
Block(6,4,2,DOUBLE_WOODEN_SLAB:1)
Block(-3,4,3,LOG_2:8)
Block(5,4,3,LOG_2:8)
Block(6,4,3,WOODEN_SLAB:9)
Block(-3,4,4,LOG_2:8)
Block(-2,4,4,TRAPDOOR:8)
Block(-1,4,4,TRAPDOOR:8)
Block(0,4,4,TRAPDOOR:8)
Block(1,4,4,TRAPDOOR:8)
Block(2,4,4,TRAPDOOR:8)
Block(3,4,4,TRAPDOOR:8)
Block(4,4,4,TRAPDOOR:8)
Block(5,4,4,LOG_2:8)
Block(6,4,4,WOODEN_SLAB:1)
Block(-4,4,5,OAK_STAIRS:6)
Block(-3,4,5,LOG_2:0)
Block(-2,4,5,LOG_2:4)
Block(-1,4,5,LOG_2:4)
Block(0,4,5,LOG_2:4)
Block(1,4,5,LOG_2:0)
Block(2,4,5,LOG_2:4)
Block(3,4,5,LOG_2:4)
Block(4,4,5,LOG_2:4)
Block(5,4,5,LOG_2:0)
Block(6,4,5,OAK_STAIRS:2)
Block(-4,4,6,OAK_STAIRS:3)
Block(-3,4,6,OAK_STAIRS:3)
Block(-2,4,6,OAK_STAIRS:3)
Block(-1,4,6,OAK_STAIRS:3)
Block(0,4,6,OAK_STAIRS:0)
Block(1,4,6,OAK_STAIRS:5)
Block(5,4,6,OAK_STAIRS:4)
Block(6,4,6,OAK_STAIRS:1)
Block(-5,5,-8,COBBLESTONE_WALL:0)
Block(-6,5,-7,COBBLESTONE_WALL:0)
Block(-4,5,-7,COBBLESTONE_WALL:0)
Block(1,5,-7,OAK_STAIRS:0)
Block(2,5,-7,OAK_STAIRS:5)
Block(4,5,-7,OAK_STAIRS:4)
Block(5,5,-7,OAK_STAIRS:1)
Block(-5,5,-6,COBBLESTONE_WALL:0)
Block(1,5,-6,OAK_STAIRS:0)
Block(2,5,-6,STAINED_HARDENED_CLAY:15)
Block(3,5,-6,STAINED_HARDENED_CLAY:15)
Block(4,5,-6,STAINED_HARDENED_CLAY:15)
Block(5,5,-6,OAK_STAIRS:1)
Block(1,5,-5,WOODEN_SLAB:1)
Block(2,5,-5,WOODEN_SLAB:9)
Block(5,5,-5,OAK_STAIRS:1)
Block(1,5,-4,DOUBLE_WOODEN_SLAB:1)
Block(2,5,-4,WOODEN_SLAB:9)
Block(5,5,-4,DOUBLE_WOODEN_SLAB:1)
Block(1,5,-3,OAK_STAIRS:0)
Block(5,5,-3,OAK_STAIRS:1)
Block(1,5,-2,OAK_STAIRS:0)
Block(5,5,-2,OAK_STAIRS:1)
Block(1,5,-1,OAK_STAIRS:0)
Block(5,5,-1,OAK_STAIRS:1)
Block(1,5,0,OAK_STAIRS:0)
Block(5,5,0,OAK_STAIRS:1)
Block(-4,5,1,OAK_STAIRS:2)
Block(-3,5,1,OAK_STAIRS:2)
Block(-2,5,1,OAK_STAIRS:2)
Block(-1,5,1,OAK_STAIRS:2)
Block(0,5,1,OAK_STAIRS:2)
Block(1,5,1,OAK_STAIRS:2)
Block(5,5,1,OAK_STAIRS:1)
Block(-4,5,2,OAK_STAIRS:7)
Block(-3,5,2,STAINED_HARDENED_CLAY:15)
Block(4,5,2,WOODEN_SLAB:9)
Block(5,5,2,DOUBLE_WOODEN_SLAB:1)
Block(-3,5,3,STAINED_HARDENED_CLAY:15)
Block(4,5,3,WOODEN_SLAB:9)
Block(5,5,3,WOODEN_SLAB:1)
Block(-4,5,4,OAK_STAIRS:6)
Block(-3,5,4,STAINED_HARDENED_CLAY:15)
RandomBlock(-1,5,4,AIR:0,20,CHEST:2,../../../../Chests/Loot/JunkChest_1.nbt,10,CHEST:2,../../../../Chests/Loot/JunkChest_2.nbt,10,CHEST:2,../../../../Chests/Loot/JunkChest_3.nbt,10,CHEST:2,../../../../Chests/Loot/JunkChest_4.nbt,10,CHEST:2,../../../../Chests/Loot/JunkChest_5.nbt,10,CHEST:2,../../../../Chests/Lore/JungleLore_1.nbt,1,CHEST:2,../../../../Chests/Lore/JungleLore_2.nbt,1,CHEST:2,../../../../Chests/Lore/JungleLore_3.nbt,1,CHEST:2,../../../../Chests/Lore/JungleLore_4.nbt,1,CHEST:2,../../../../Chests/Lore/JungleLore_5.nbt,1,CHEST:2,../../../../Chests/Loot/Common1.nbt,10,CHEST:2,../../../../Chests/Loot/Common2.nbt,10,CHEST:2,../../../../Chests/Loot/Common3.nbt,10,CHEST:2,../../../../Chests/Loot/Common4.nbt,10,CHEST:2,../../../../Chests/Loot/Common5.nbt,10,CHEST:2,../../../../Chests/Loot/Common6.nbt,10,CHEST:2,../../../../Chests/Loot/Common7.nbt,10,CHEST:2,../../../../Chests/Loot/Common8.nbt,10,CHEST:2,../../../../Chests/Loot/Common9.nbt,10,CHEST:2,../../../../Chests/Loot/Common10.nbt,10,CHEST:2,../../../../Chests/Loot/Common10.nbt,11,CHEST:2,../../../../Chests/Loot/Common12.nbt,10,CHEST:2,../../../../Chests/Loot/Common13.nbt,10,CHEST:2,../../../../Chests/Loot/Common14.nbt,10,CHEST:2,../../../../Chests/Loot/Common15.nbt,10,CHEST:2,../../../../Chests/Lore/JungleLore_1.nbt,2,CHEST:2,../../../../Chests/Lore/JungleLore_3.nbt,2,CHEST:2,../../../../Chests/Lore/JungleLore_4.nbt,2,CHEST:2,../../../../Chests/Lore/JungleLore_5.nbt,2,CHEST:2,../../../../Chests/Lore/JungleLore_5.nbt,2,CHEST:2,../../../../Chests/Loot/Rare1.nbt,5,CHEST:2,../../../../Chests/Loot/Rare2.nbt,5,CHEST:2,../../../../Chests/Loot/Rare3.nbt,5,CHEST:2,../../../../Chests/Loot/Rare4.nbt,5,CHEST:2,../../../../Chests/Loot/Rare5.nbt,5,CHEST:2,../../../../Chests/Loot/Rare6.nbt,5,CHEST:2,../../../../Chests/Loot/Rare7.nbt,5,CHEST:2,../../../../Chests/Loot/Rare8.nbt,5,CHEST:2,../../../../Chests/Loot/Rare9.nbt,5,CHEST:2,../../../../Chests/Loot/Rare10.nbt,5,CHEST:2,../../../../Chests/Loot/Rare11.nbt,5,CHEST:2,../../../../Chests/Loot/Rare12.nbt,5,CHEST:2,../../../../Chests/Loot/Rare13.nbt,5,CHEST:2,../../../../Chests/Loot/Rare14.nbt,5,CHEST:2,../../../../Chests/Loot/Rare15.nbt,5,CHEST:2,../../../../Chests/Loot/Epic1.nbt,2,CHEST:2,../../../../Chests/Loot/Epic2.nbt,2,CHEST:2,../../../../Chests/Loot/Epic3.nbt,2,CHEST:2,../../../../Chests/Loot/Epic4.nbt,2,CHEST:2,../../../../Chests/Loot/Epic5.nbt,2,CHEST:2,../../../../Chests/Loot/Epic6.nbt,2,CHEST:2,../../../../Chests/Loot/Epic7.nbt,2,CHEST:2,../../../../Chests/Loot/Epic8.nbt,2,CHEST:2,../../../../Chests/Loot/Epic9.nbt,2,CHEST:2,../../../../Chests/Loot/Epic10.nbt,2,CHEST:2,../../../../Chests/Loot/Epic11.nbt,2,CHEST:2,../../../../Chests/Loot/Epic12.nbt,2,CHEST:2,../../../../Chests/Loot/Epic13.nbt,2,CHEST:2,../../../../Chests/Loot/Epic14.nbt,2,CHEST:2,../../../../Chests/Loot/Epic15.nbt,5,CHEST:2,../../../../Chests/Loot/Rare1.nbt,5,CHEST:2,../../../../Chests/Loot/Rare2.nbt,5,CHEST:2,../../../../Chests/Loot/Rare3.nbt,5,CHEST:2,../../../../Chests/Loot/Rare4.nbt,5,CHEST:2,../../../../Chests/Loot/Rare5.nbt,10,CHEST:2,../../../../Chests/Loot/Rare6.nbt,10,CHEST:2,../../../../Chests/Loot/Rare7.nbt,10,CHEST:2,../../../../Chests/Loot/Rare8.nbt,10,CHEST:2,../../../../Chests/Loot/Rare9.nbt,10,CHEST:2,../../../../Chests/Loot/Rare10.nbt,15,CHEST:2,../../../../Chests/Loot/Rare11.nbt,15,CHEST:2,../../../../Chests/Loot/Rare12.nbt,15,CHEST:2,../../../../Chests/Loot/Rare13.nbt,15,CHEST:2,../../../../Chests/Loot/Rare14.nbt,15,CHEST:2,../../../../Chests/Loot/Rare15.nbt,15,CHEST:2,../../../../Chests/Loot/Epic15.nbt,100)
RandomBlock(1,5,4,AIR:0,20,CHEST:2,../../../../Chests/Loot/JunkChest_1.nbt,10,CHEST:2,../../../../Chests/Loot/JunkChest_2.nbt,10,CHEST:2,../../../../Chests/Loot/JunkChest_3.nbt,10,CHEST:2,../../../../Chests/Loot/JunkChest_4.nbt,10,CHEST:2,../../../../Chests/Loot/JunkChest_5.nbt,10,CHEST:2,../../../../Chests/Lore/JungleLore_1.nbt,1,CHEST:2,../../../../Chests/Lore/JungleLore_2.nbt,1,CHEST:2,../../../../Chests/Lore/JungleLore_3.nbt,1,CHEST:2,../../../../Chests/Lore/JungleLore_4.nbt,1,CHEST:2,../../../../Chests/Lore/JungleLore_5.nbt,1,CHEST:2,../../../../Chests/Loot/Common1.nbt,10,CHEST:2,../../../../Chests/Loot/Common2.nbt,10,CHEST:2,../../../../Chests/Loot/Common3.nbt,10,CHEST:2,../../../../Chests/Loot/Common4.nbt,10,CHEST:2,../../../../Chests/Loot/Common5.nbt,10,CHEST:2,../../../../Chests/Loot/Common6.nbt,10,CHEST:2,../../../../Chests/Loot/Common7.nbt,10,CHEST:2,../../../../Chests/Loot/Common8.nbt,10,CHEST:2,../../../../Chests/Loot/Common9.nbt,10,CHEST:2,../../../../Chests/Loot/Common10.nbt,10,CHEST:2,../../../../Chests/Loot/Common10.nbt,11,CHEST:2,../../../../Chests/Loot/Common12.nbt,10,CHEST:2,../../../../Chests/Loot/Common13.nbt,10,CHEST:2,../../../../Chests/Loot/Common14.nbt,10,CHEST:2,../../../../Chests/Loot/Common15.nbt,10,CHEST:2,../../../../Chests/Lore/JungleLore_1.nbt,2,CHEST:2,../../../../Chests/Lore/JungleLore_3.nbt,2,CHEST:2,../../../../Chests/Lore/JungleLore_4.nbt,2,CHEST:2,../../../../Chests/Lore/JungleLore_5.nbt,2,CHEST:2,../../../../Chests/Lore/JungleLore_5.nbt,2,CHEST:2,../../../../Chests/Loot/Rare1.nbt,5,CHEST:2,../../../../Chests/Loot/Rare2.nbt,5,CHEST:2,../../../../Chests/Loot/Rare3.nbt,5,CHEST:2,../../../../Chests/Loot/Rare4.nbt,5,CHEST:2,../../../../Chests/Loot/Rare5.nbt,5,CHEST:2,../../../../Chests/Loot/Rare6.nbt,5,CHEST:2,../../../../Chests/Loot/Rare7.nbt,5,CHEST:2,../../../../Chests/Loot/Rare8.nbt,5,CHEST:2,../../../../Chests/Loot/Rare9.nbt,5,CHEST:2,../../../../Chests/Loot/Rare10.nbt,5,CHEST:2,../../../../Chests/Loot/Rare11.nbt,5,CHEST:2,../../../../Chests/Loot/Rare12.nbt,5,CHEST:2,../../../../Chests/Loot/Rare13.nbt,5,CHEST:2,../../../../Chests/Loot/Rare14.nbt,5,CHEST:2,../../../../Chests/Loot/Rare15.nbt,5,CHEST:2,../../../../Chests/Loot/Epic1.nbt,2,CHEST:2,../../../../Chests/Loot/Epic2.nbt,2,CHEST:2,../../../../Chests/Loot/Epic3.nbt,2,CHEST:2,../../../../Chests/Loot/Epic4.nbt,2,CHEST:2,../../../../Chests/Loot/Epic5.nbt,2,CHEST:2,../../../../Chests/Loot/Epic6.nbt,2,CHEST:2,../../../../Chests/Loot/Epic7.nbt,2,CHEST:2,../../../../Chests/Loot/Epic8.nbt,2,CHEST:2,../../../../Chests/Loot/Epic9.nbt,2,CHEST:2,../../../../Chests/Loot/Epic10.nbt,2,CHEST:2,../../../../Chests/Loot/Epic11.nbt,2,CHEST:2,../../../../Chests/Loot/Epic12.nbt,2,CHEST:2,../../../../Chests/Loot/Epic13.nbt,2,CHEST:2,../../../../Chests/Loot/Epic14.nbt,2,CHEST:2,../../../../Chests/Loot/Epic15.nbt,5,CHEST:2,../../../../Chests/Loot/Rare1.nbt,5,CHEST:2,../../../../Chests/Loot/Rare2.nbt,5,CHEST:2,../../../../Chests/Loot/Rare3.nbt,5,CHEST:2,../../../../Chests/Loot/Rare4.nbt,5,CHEST:2,../../../../Chests/Loot/Rare5.nbt,10,CHEST:2,../../../../Chests/Loot/Rare6.nbt,10,CHEST:2,../../../../Chests/Loot/Rare7.nbt,10,CHEST:2,../../../../Chests/Loot/Rare8.nbt,10,CHEST:2,../../../../Chests/Loot/Rare9.nbt,10,CHEST:2,../../../../Chests/Loot/Rare10.nbt,15,CHEST:2,../../../../Chests/Loot/Rare11.nbt,15,CHEST:2,../../../../Chests/Loot/Rare12.nbt,15,CHEST:2,../../../../Chests/Loot/Rare13.nbt,15,CHEST:2,../../../../Chests/Loot/Rare14.nbt,15,CHEST:2,../../../../Chests/Loot/Rare15.nbt,15,CHEST:2,../../../../Chests/Loot/Epic15.nbt,100)
RandomBlock(2,5,4,AIR:0,20,CHEST:2,../../../../Chests/Loot/JunkChest_1.nbt,10,CHEST:2,../../../../Chests/Loot/JunkChest_2.nbt,10,CHEST:2,../../../../Chests/Loot/JunkChest_3.nbt,10,CHEST:2,../../../../Chests/Loot/JunkChest_4.nbt,10,CHEST:2,../../../../Chests/Loot/JunkChest_5.nbt,10,CHEST:2,../../../../Chests/Lore/JungleLore_1.nbt,1,CHEST:2,../../../../Chests/Lore/JungleLore_2.nbt,1,CHEST:2,../../../../Chests/Lore/JungleLore_3.nbt,1,CHEST:2,../../../../Chests/Lore/JungleLore_4.nbt,1,CHEST:2,../../../../Chests/Lore/JungleLore_5.nbt,1,CHEST:2,../../../../Chests/Loot/Common1.nbt,10,CHEST:2,../../../../Chests/Loot/Common2.nbt,10,CHEST:2,../../../../Chests/Loot/Common3.nbt,10,CHEST:2,../../../../Chests/Loot/Common4.nbt,10,CHEST:2,../../../../Chests/Loot/Common5.nbt,10,CHEST:2,../../../../Chests/Loot/Common6.nbt,10,CHEST:2,../../../../Chests/Loot/Common7.nbt,10,CHEST:2,../../../../Chests/Loot/Common8.nbt,10,CHEST:2,../../../../Chests/Loot/Common9.nbt,10,CHEST:2,../../../../Chests/Loot/Common10.nbt,10,CHEST:2,../../../../Chests/Loot/Common10.nbt,11,CHEST:2,../../../../Chests/Loot/Common12.nbt,10,CHEST:2,../../../../Chests/Loot/Common13.nbt,10,CHEST:2,../../../../Chests/Loot/Common14.nbt,10,CHEST:2,../../../../Chests/Loot/Common15.nbt,10,CHEST:2,../../../../Chests/Lore/JungleLore_1.nbt,2,CHEST:2,../../../../Chests/Lore/JungleLore_3.nbt,2,CHEST:2,../../../../Chests/Lore/JungleLore_4.nbt,2,CHEST:2,../../../../Chests/Lore/JungleLore_5.nbt,2,CHEST:2,../../../../Chests/Lore/JungleLore_5.nbt,2,CHEST:2,../../../../Chests/Loot/Rare1.nbt,5,CHEST:2,../../../../Chests/Loot/Rare2.nbt,5,CHEST:2,../../../../Chests/Loot/Rare3.nbt,5,CHEST:2,../../../../Chests/Loot/Rare4.nbt,5,CHEST:2,../../../../Chests/Loot/Rare5.nbt,5,CHEST:2,../../../../Chests/Loot/Rare6.nbt,5,CHEST:2,../../../../Chests/Loot/Rare7.nbt,5,CHEST:2,../../../../Chests/Loot/Rare8.nbt,5,CHEST:2,../../../../Chests/Loot/Rare9.nbt,5,CHEST:2,../../../../Chests/Loot/Rare10.nbt,5,CHEST:2,../../../../Chests/Loot/Rare11.nbt,5,CHEST:2,../../../../Chests/Loot/Rare12.nbt,5,CHEST:2,../../../../Chests/Loot/Rare13.nbt,5,CHEST:2,../../../../Chests/Loot/Rare14.nbt,5,CHEST:2,../../../../Chests/Loot/Rare15.nbt,5,CHEST:2,../../../../Chests/Loot/Epic1.nbt,2,CHEST:2,../../../../Chests/Loot/Epic2.nbt,2,CHEST:2,../../../../Chests/Loot/Epic3.nbt,2,CHEST:2,../../../../Chests/Loot/Epic4.nbt,2,CHEST:2,../../../../Chests/Loot/Epic5.nbt,2,CHEST:2,../../../../Chests/Loot/Epic6.nbt,2,CHEST:2,../../../../Chests/Loot/Epic7.nbt,2,CHEST:2,../../../../Chests/Loot/Epic8.nbt,2,CHEST:2,../../../../Chests/Loot/Epic9.nbt,2,CHEST:2,../../../../Chests/Loot/Epic10.nbt,2,CHEST:2,../../../../Chests/Loot/Epic11.nbt,2,CHEST:2,../../../../Chests/Loot/Epic12.nbt,2,CHEST:2,../../../../Chests/Loot/Epic13.nbt,2,CHEST:2,../../../../Chests/Loot/Epic14.nbt,2,CHEST:2,../../../../Chests/Loot/Epic15.nbt,5,CHEST:2,../../../../Chests/Loot/Rare1.nbt,5,CHEST:2,../../../../Chests/Loot/Rare2.nbt,5,CHEST:2,../../../../Chests/Loot/Rare3.nbt,5,CHEST:2,../../../../Chests/Loot/Rare4.nbt,5,CHEST:2,../../../../Chests/Loot/Rare5.nbt,10,CHEST:2,../../../../Chests/Loot/Rare6.nbt,10,CHEST:2,../../../../Chests/Loot/Rare7.nbt,10,CHEST:2,../../../../Chests/Loot/Rare8.nbt,10,CHEST:2,../../../../Chests/Loot/Rare9.nbt,10,CHEST:2,../../../../Chests/Loot/Rare10.nbt,15,CHEST:2,../../../../Chests/Loot/Rare11.nbt,15,CHEST:2,../../../../Chests/Loot/Rare12.nbt,15,CHEST:2,../../../../Chests/Loot/Rare13.nbt,15,CHEST:2,../../../../Chests/Loot/Rare14.nbt,15,CHEST:2,../../../../Chests/Loot/Rare15.nbt,15,CHEST:2,../../../../Chests/Loot/Epic15.nbt,100)
Block(5,5,4,OAK_STAIRS:1)
Block(-4,5,5,OAK_STAIRS:3)
Block(-3,5,5,OAK_STAIRS:3)
Block(-2,5,5,OAK_STAIRS:3)
Block(-1,5,5,OAK_STAIRS:3)
Block(0,5,5,OAK_STAIRS:3)
Block(1,5,5,OAK_STAIRS:0)
Block(2,5,5,STAINED_HARDENED_CLAY:15)
Block(3,5,5,STAINED_HARDENED_CLAY:15)
Block(4,5,5,STAINED_HARDENED_CLAY:15)
Block(5,5,5,OAK_STAIRS:1)
Block(1,5,6,OAK_STAIRS:0)
Block(2,5,6,OAK_STAIRS:5)
Block(4,5,6,OAK_STAIRS:4)
Block(5,5,6,OAK_STAIRS:1)
Block(-5,6,-8,STONE_SLAB:3)
Block(-6,6,-7,STONE_SLAB:3)
Block(-5,6,-7,STONE_SLAB:3)
Block(-4,6,-7,STONE_SLAB:3)
Block(2,6,-7,OAK_STAIRS:0)
Block(3,6,-7,OAK_STAIRS:6)
Block(4,6,-7,OAK_STAIRS:1)
Block(-5,6,-6,STONE_SLAB:3)
Block(2,6,-6,BIRCH_STAIRS:0)
Block(3,6,-6,WOODEN_SLAB:9)
Block(4,6,-6,BIRCH_STAIRS:1)
Block(3,6,-5,WOODEN_SLAB:1)
Block(4,6,-5,BIRCH_STAIRS:1)
Block(2,6,-4,BIRCH_STAIRS:0)
Block(3,6,-4,WOODEN_SLAB:9)
Block(4,6,-4,BIRCH_STAIRS:1)
Block(2,6,-3,WOODEN_SLAB:1)
Block(3,6,-3,WOODEN_SLAB:9)
Block(4,6,-3,WOODEN_SLAB:1)
Block(2,6,-2,BIRCH_STAIRS:0)
Block(4,6,-2,BIRCH_STAIRS:1)
Block(2,6,-1,BIRCH_STAIRS:0)
Block(4,6,-1,BIRCH_STAIRS:1)
Block(2,6,0,BIRCH_STAIRS:0)
Block(4,6,0,BIRCH_STAIRS:1)
Block(2,6,1,BIRCH_STAIRS:0)
Block(3,6,1,WOODEN_SLAB:9)
Block(4,6,1,BIRCH_STAIRS:1)
Block(-4,6,2,OAK_STAIRS:2)
Block(-3,6,2,BIRCH_STAIRS:2)
Block(-2,6,2,BIRCH_STAIRS:2)
Block(-1,6,2,BIRCH_STAIRS:2)
Block(0,6,2,WOODEN_SLAB:1)
Block(1,6,2,BIRCH_STAIRS:2)
Block(2,6,2,BIRCH_STAIRS:0)
Block(3,6,2,WOODEN_SLAB:1)
Block(-4,6,3,OAK_STAIRS:4)
Block(-3,6,3,STAINED_HARDENED_CLAY:15)
Block(-1,6,3,WOODEN_SLAB:9)
Block(0,6,3,WOODEN_SLAB:9)
Block(1,6,3,WOODEN_SLAB:9)
Block(2,6,3,WOODEN_SLAB:9)
Block(3,6,3,WOODEN_SLAB:1)
Block(-4,6,4,OAK_STAIRS:3)
Block(-3,6,4,BIRCH_STAIRS:3)
Block(-2,6,4,BIRCH_STAIRS:3)
Block(-1,6,4,WOODEN_SLAB:1)
Block(0,6,4,WOODEN_SLAB:1)
Block(1,6,4,WOODEN_SLAB:1)
Block(2,6,4,BIRCH_STAIRS:3)
Block(3,6,4,WOODEN_SLAB:9)
Block(4,6,4,BIRCH_STAIRS:1)
Block(2,6,5,BIRCH_STAIRS:0)
Block(3,6,5,STAINED_HARDENED_CLAY:15)
Block(4,6,5,BIRCH_STAIRS:1)
Block(2,6,6,OAK_STAIRS:0)
Block(3,6,6,OAK_STAIRS:7)
Block(4,6,6,OAK_STAIRS:1)
Block(3,7,-7,WOODEN_SLAB:2)
Block(3,7,-2,WOODEN_SLAB:2)
Block(3,7,-1,WOODEN_SLAB:2)
Block(3,7,0,WOODEN_SLAB:2)
Block(-4,7,3,WOODEN_SLAB:2)
Block(-3,7,3,WOODEN_SLAB:2)
Block(-2,7,3,WOODEN_SLAB:2)
Block(3,7,5,WOODEN_SLAB:2)
Block(3,7,6,WOODEN_SLAB:2)