Author: BO3 BulkEdit (by LanToaster)
Description: This Object was Created with BO3_BulkEdit
SettingsMode: WriteDisable
Frequency: 100
SpawnHeight: highestBlock
UseCenterForHighestBlock: true
MinHeight: 0
MaxHeight: 255
InheritBO3: 
InheritBO3Rotation: NORTH
OverrideChildSettings: true
OverrideParentHeight: true
CanOverride: true
BranchFrequency: 0
BranchFrequencyGroup: 
MustBeBelowOther: false
MustBeInside: 
CannotBeInside: 
ReplacesBO3: 
MustBeInsideWorldBorders: false
CanSpawnOnWater: true
SpawnOnWaterOnly: false
SpawnUnderWater: false
SpawnAtWaterLevel: false
HeightOffset: 1
RemoveAir: true
ReplaceAbove: 
ReplaceBelow: cobblestone
ReplaceWithBiomeBlocks: true
ReplaceWithSurfaceBlock: GRASS
ReplaceWithGroundBlock: DIRT
ReplaceWithStoneBlock: STONE
SmoothRadius: 0
SmoothHeightOffset: 0
SmoothStartTop: false
SmoothStartWood: false
SmoothingSurfaceBlock: 
SmoothingGroundBlock: 
BO3Group: 
IsSpawnPoint: false
DoReplaceBlocks: true
Block(-1,-1,-8,LOG_2:0)
Block(0,-1,-8,HARD_CLAY:0)
Block(1,-1,-8,HARD_CLAY:0)
Block(2,-1,-8,HARD_CLAY:0)
Block(3,-1,-8,HARD_CLAY:0)
Block(4,-1,-8,LOG_2:0)
Block(-5,-1,-7,GRASS_PATH:0)
Block(-3,-1,-7,HAY_BLOCK:0)
Block(-2,-1,-7,HAY_BLOCK:4)
Block(-1,-1,-7,HARD_CLAY:0)
Block(0,-1,-7,STAINED_CLAY:9)
Block(1,-1,-7,STAINED_CLAY:9)
Block(2,-1,-7,STAINED_CLAY:9)
Block(3,-1,-7,STAINED_CLAY:9)
Block(4,-1,-7,HARD_CLAY:0)
Block(-6,-1,-6,GRASS_PATH:0)
Block(-5,-1,-6,GRASS_PATH:0)
Block(-4,-1,-6,GRASS_PATH:0)
Block(-3,-1,-6,HAY_BLOCK:0)
Block(-2,-1,-6,HAY_BLOCK:8)
Block(-1,-1,-6,HARD_CLAY:0)
Block(0,-1,-6,STAINED_CLAY:9)
Block(1,-1,-6,STAINED_CLAY:9)
Block(2,-1,-6,STAINED_CLAY:9)
Block(3,-1,-6,STAINED_CLAY:9)
Block(4,-1,-6,HARD_CLAY:0)
Block(-6,-1,-5,STAINED_CLAY:9)
Block(-5,-1,-5,LOG_2:0)
Block(-4,-1,-5,HARD_CLAY:0)
Block(-3,-1,-5,HARD_CLAY:0)
Block(-2,-1,-5,HARD_CLAY:0)
Block(-1,-1,-5,LOG_2:0)
Block(0,-1,-5,STAINED_CLAY:9)
Block(1,-1,-5,STAINED_CLAY:9)
Block(2,-1,-5,STAINED_CLAY:9)
Block(3,-1,-5,STAINED_CLAY:9)
Block(4,-1,-5,LOG_2:0)
Block(5,-1,-5,GRASS_PATH:0)
Block(-7,-1,-4,GRASS_PATH:0)
Block(-6,-1,-4,GRAVEL:0)
Block(-5,-1,-4,HARD_CLAY:0)
Block(-4,-1,-4,STAINED_CLAY:9)
Block(-3,-1,-4,STAINED_CLAY:9)
Block(-2,-1,-4,STAINED_CLAY:9)
Block(-1,-1,-4,STAINED_CLAY:9)
Block(0,-1,-4,STAINED_CLAY:9)
Block(1,-1,-4,STAINED_CLAY:9)
Block(2,-1,-4,STAINED_CLAY:9)
Block(3,-1,-4,STAINED_CLAY:9)
Block(4,-1,-4,HARD_CLAY:0)
Block(5,-1,-4,GRASS_PATH:0)
Block(-7,-1,-3,GRAVEL:0)
Block(-6,-1,-3,GRAVEL:0)
Block(-5,-1,-3,HARD_CLAY:0)
Block(-4,-1,-3,STAINED_CLAY:9)
Block(-3,-1,-3,STAINED_CLAY:9)
Block(-2,-1,-3,STAINED_CLAY:9)
Block(-1,-1,-3,STAINED_CLAY:9)
Block(0,-1,-3,STAINED_CLAY:9)
Block(1,-1,-3,STAINED_CLAY:9)
Block(2,-1,-3,STAINED_CLAY:9)
Block(3,-1,-3,STAINED_CLAY:9)
Block(4,-1,-3,HARD_CLAY:0)
Block(5,-1,-3,GRASS_PATH:0)
Block(6,-1,-3,GRASS_PATH:0)
Block(-7,-1,-2,STAINED_CLAY:9)
Block(-6,-1,-2,STAINED_CLAY:9)
Block(-5,-1,-2,HARD_CLAY:0)
Block(-4,-1,-2,STAINED_CLAY:9)
Block(-3,-1,-2,STAINED_CLAY:9)
Block(-2,-1,-2,STAINED_CLAY:9)
Block(-1,-1,-2,STAINED_CLAY:9)
Block(0,-1,-2,STAINED_CLAY:9)
Block(1,-1,-2,STAINED_CLAY:9)
Block(2,-1,-2,STAINED_CLAY:9)
Block(3,-1,-2,STAINED_CLAY:9)
Block(4,-1,-2,HARD_CLAY:0)
Block(5,-1,-2,GRASS_PATH:0)
Block(6,-1,-2,GRASS_PATH:0)
Block(-7,-1,-1,GRASS_PATH:0)
Block(-6,-1,-1,GRAVEL:0)
Block(-5,-1,-1,LOG_2:0)
Block(-4,-1,-1,HARD_CLAY:0)
Block(-3,-1,-1,HARD_CLAY:0)
Block(-2,-1,-1,HARD_CLAY:0)
Block(-1,-1,-1,LOG_2:0)
Block(0,-1,-1,STAINED_CLAY:9)
Block(1,-1,-1,STAINED_CLAY:9)
Block(2,-1,-1,STAINED_CLAY:9)
Block(3,-1,-1,STAINED_CLAY:9)
Block(4,-1,-1,LOG_2:0)
Block(5,-1,-1,GRASS_PATH:0)
Block(-7,-1,0,STAINED_CLAY:9)
Block(-6,-1,0,GRAVEL:0)
Block(-5,-1,0,STAINED_CLAY:9)
Block(-4,-1,0,STAINED_CLAY:9)
Block(-3,-1,0,GRAVEL:0)
Block(-2,-1,0,STAINED_CLAY:9)
Block(-1,-1,0,HARD_CLAY:0)
Block(0,-1,0,STAINED_CLAY:9)
Block(1,-1,0,STAINED_CLAY:9)
Block(2,-1,0,STAINED_CLAY:9)
Block(3,-1,0,STAINED_CLAY:9)
Block(4,-1,0,HARD_CLAY:0)
Block(-5,-1,1,STAINED_CLAY:9)
Block(-4,-1,1,GRAVEL:0)
Block(-3,-1,1,GRAVEL:0)
Block(-2,-1,1,STAINED_CLAY:9)
Block(-1,-1,1,HARD_CLAY:0)
Block(0,-1,1,STAINED_CLAY:9)
Block(1,-1,1,STAINED_CLAY:9)
Block(2,-1,1,STAINED_CLAY:9)
Block(3,-1,1,STAINED_CLAY:9)
Block(4,-1,1,HARD_CLAY:0)
Block(5,-1,1,GRASS_PATH:0)
Block(-6,-1,2,STAINED_CLAY:9)
Block(-5,-1,2,STAINED_CLAY:9)
Block(-4,-1,2,GRAVEL:0)
Block(-3,-1,2,STAINED_CLAY:9)
Block(-2,-1,2,STAINED_CLAY:9)
Block(-1,-1,2,HARD_CLAY:0)
Block(0,-1,2,STAINED_CLAY:9)
Block(1,-1,2,STAINED_CLAY:9)
Block(2,-1,2,STAINED_CLAY:9)
Block(3,-1,2,STAINED_CLAY:9)
Block(4,-1,2,HARD_CLAY:0)
Block(5,-1,2,GRASS_PATH:0)
Block(-5,-1,3,STAINED_CLAY:9)
Block(-4,-1,3,STAINED_CLAY:9)
Block(-3,-1,3,STAINED_CLAY:9)
Block(-2,-1,3,STAINED_CLAY:9)
Block(-1,-1,3,HARD_CLAY:0)
Block(0,-1,3,STAINED_CLAY:9)
Block(1,-1,3,STAINED_CLAY:9)
Block(2,-1,3,STAINED_CLAY:9)
Block(3,-1,3,STAINED_CLAY:9)
Block(4,-1,3,HARD_CLAY:0)
Block(5,-1,3,GRASS_PATH:0)
Block(-5,-1,4,STAINED_CLAY:9)
Block(-4,-1,4,GRAVEL:0)
Block(-3,-1,4,GRAVEL:0)
Block(-2,-1,4,GRAVEL:0)
Block(-1,-1,4,LOG_2:0)
Block(0,-1,4,HARD_CLAY:0)
Block(1,-1,4,HARD_CLAY:0)
Block(2,-1,4,HARD_CLAY:0)
Block(3,-1,4,HARD_CLAY:0)
Block(4,-1,4,LOG_2:0)
Block(5,-1,4,GRAVEL:0)
Block(-4,-1,5,STAINED_CLAY:9)
Block(-3,-1,5,STAINED_CLAY:9)
Block(-2,-1,5,GRAVEL:0)
Block(-1,-1,5,STAINED_CLAY:9)
Block(0,-1,5,SOUL_SAND:0)
Block(1,-1,5,STAINED_CLAY:9)
Block(2,-1,5,STAINED_CLAY:9)
Block(3,-1,5,SOUL_SAND:0)
Block(4,-1,5,STAINED_CLAY:9)
Block(5,-1,5,GRASS_PATH:0)
Block(6,-1,5,GRASS_PATH:0)
Block(-2,-1,6,STAINED_CLAY:9)
Block(-1,-1,6,STAINED_CLAY:9)
Block(0,-1,6,STAINED_CLAY:9)
Block(1,-1,6,STAINED_CLAY:9)
Block(2,-1,6,STAINED_CLAY:9)
Block(3,-1,6,STAINED_CLAY:9)
Block(4,-1,6,STAINED_CLAY:9)
Block(5,-1,6,GRASS_PATH:0)
Block(-1,0,-8,LOG_2:0)
Block(0,0,-8,HARD_CLAY:0)
Block(1,0,-8,HARD_CLAY:0)
Block(2,0,-8,HARD_CLAY:0)
Block(3,0,-8,HARD_CLAY:0)
Block(4,0,-8,LOG_2:0)
Block(-2,0,-7,HAY_BLOCK:0)
Block(-1,0,-7,HARD_CLAY:0)
Block(0,0,-7,ACACIA_STAIRS:3)
RandomBlock(1,0,-7,AIR:0,20,CHEST:3,../../../../Chests/Loot/JunkChest_1.nbt,10,CHEST:3,../../../../Chests/Loot/JunkChest_2.nbt,10,CHEST:3,../../../../Chests/Loot/JunkChest_3.nbt,10,CHEST:3,../../../../Chests/Loot/JunkChest_4.nbt,10,CHEST:3,../../../../Chests/Loot/JunkChest_5.nbt,10,CHEST:3,../../../../Chests/Lore/JungleLore_1.nbt,1,CHEST:3,../../../../Chests/Lore/JungleLore_2.nbt,1,CHEST:3,../../../../Chests/Lore/JungleLore_3.nbt,1,CHEST:3,../../../../Chests/Lore/JungleLore_4.nbt,1,CHEST:3,../../../../Chests/Lore/JungleLore_5.nbt,1,CHEST:3,../../../../Chests/Loot/Common1.nbt,10,CHEST:3,../../../../Chests/Loot/Common2.nbt,10,CHEST:3,../../../../Chests/Loot/Common3.nbt,10,CHEST:3,../../../../Chests/Loot/Common4.nbt,10,CHEST:3,../../../../Chests/Loot/Common5.nbt,10,CHEST:3,../../../../Chests/Loot/Common6.nbt,10,CHEST:3,../../../../Chests/Loot/Common7.nbt,10,CHEST:3,../../../../Chests/Loot/Common8.nbt,10,CHEST:3,../../../../Chests/Loot/Common9.nbt,10,CHEST:3,../../../../Chests/Loot/Common10.nbt,10,CHEST:3,../../../../Chests/Loot/Common10.nbt,11,CHEST:3,../../../../Chests/Loot/Common12.nbt,10,CHEST:3,../../../../Chests/Loot/Common13.nbt,10,CHEST:3,../../../../Chests/Loot/Common14.nbt,10,CHEST:3,../../../../Chests/Loot/Common15.nbt,10,CHEST:3,../../../../Chests/Lore/JungleLore_1.nbt,2,CHEST:3,../../../../Chests/Lore/JungleLore_3.nbt,2,CHEST:3,../../../../Chests/Lore/JungleLore_4.nbt,2,CHEST:3,../../../../Chests/Lore/JungleLore_5.nbt,2,CHEST:3,../../../../Chests/Lore/JungleLore_5.nbt,2,CHEST:3,../../../../Chests/Loot/Rare1.nbt,5,CHEST:3,../../../../Chests/Loot/Rare2.nbt,5,CHEST:3,../../../../Chests/Loot/Rare3.nbt,5,CHEST:3,../../../../Chests/Loot/Rare4.nbt,5,CHEST:3,../../../../Chests/Loot/Rare5.nbt,5,CHEST:3,../../../../Chests/Loot/Rare6.nbt,5,CHEST:3,../../../../Chests/Loot/Rare7.nbt,5,CHEST:3,../../../../Chests/Loot/Rare8.nbt,5,CHEST:3,../../../../Chests/Loot/Rare9.nbt,5,CHEST:3,../../../../Chests/Loot/Rare10.nbt,5,CHEST:3,../../../../Chests/Loot/Rare11.nbt,5,CHEST:3,../../../../Chests/Loot/Rare12.nbt,5,CHEST:3,../../../../Chests/Loot/Rare13.nbt,5,CHEST:3,../../../../Chests/Loot/Rare14.nbt,5,CHEST:3,../../../../Chests/Loot/Rare15.nbt,5,CHEST:3,../../../../Chests/Loot/Epic1.nbt,2,CHEST:3,../../../../Chests/Loot/Epic2.nbt,2,CHEST:3,../../../../Chests/Loot/Epic3.nbt,2,CHEST:3,../../../../Chests/Loot/Epic4.nbt,2,CHEST:3,../../../../Chests/Loot/Epic5.nbt,2,CHEST:3,../../../../Chests/Loot/Epic6.nbt,2,CHEST:3,../../../../Chests/Loot/Epic7.nbt,2,CHEST:3,../../../../Chests/Loot/Epic8.nbt,2,CHEST:3,../../../../Chests/Loot/Epic9.nbt,2,CHEST:3,../../../../Chests/Loot/Epic10.nbt,2,CHEST:3,../../../../Chests/Loot/Epic11.nbt,2,CHEST:3,../../../../Chests/Loot/Epic12.nbt,2,CHEST:3,../../../../Chests/Loot/Epic13.nbt,2,CHEST:3,../../../../Chests/Loot/Epic14.nbt,2,CHEST:3,../../../../Chests/Loot/Epic15.nbt,5,CHEST:3,../../../../Chests/Loot/Rare1.nbt,5,CHEST:3,../../../../Chests/Loot/Rare2.nbt,5,CHEST:3,../../../../Chests/Loot/Rare3.nbt,5,CHEST:3,../../../../Chests/Loot/Rare4.nbt,5,CHEST:3,../../../../Chests/Loot/Rare5.nbt,10,CHEST:3,../../../../Chests/Loot/Rare6.nbt,10,CHEST:3,../../../../Chests/Loot/Rare7.nbt,10,CHEST:3,../../../../Chests/Loot/Rare8.nbt,10,CHEST:3,../../../../Chests/Loot/Rare9.nbt,10,CHEST:3,../../../../Chests/Loot/Rare10.nbt,15,CHEST:3,../../../../Chests/Loot/Rare11.nbt,15,CHEST:3,../../../../Chests/Loot/Rare12.nbt,15,CHEST:3,../../../../Chests/Loot/Rare13.nbt,15,CHEST:3,../../../../Chests/Loot/Rare14.nbt,15,CHEST:3,../../../../Chests/Loot/Rare15.nbt,15,CHEST:3,../../../../Chests/Loot/Epic15.nbt,100)
Block(3,0,-7,BED_BLOCK:10)
Block(4,0,-7,HARD_CLAY:0)
Block(-3,0,-6,HAY_BLOCK:4)
Block(-2,0,-6,HAY_BLOCK:0)
Block(-1,0,-6,HARD_CLAY:0)
Block(1,0,-6,AIR)
Block(3,0,-6,BED_BLOCK:2)
Block(4,0,-6,HARD_CLAY:0)
Block(-6,0,-5,ACACIA_FENCE:0)
Block(-5,0,-5,LOG_2:0)
Block(-4,0,-5,HARD_CLAY:0)
Block(-3,0,-5,HARD_CLAY:0)
Block(-2,0,-5,HARD_CLAY:0)
Block(-1,0,-5,LOG_2:0)
Block(0,0,-5,ACACIA_STAIRS:5)
Block(1,0,-5,ACACIA_STAIRS:4)
Block(4,0,-5,LOG_2:0)
Block(-5,0,-4,HARD_CLAY:0)
Block(-4,0,-4,WORKBENCH:0)
Block(-3,0,-4,CAULDRON:3)
RandomBlock(-2,0,-4,AIR:0,20,CHEST:3,../../../../Chests/Loot/JunkChest_1.nbt,10,CHEST:3,../../../../Chests/Loot/JunkChest_2.nbt,10,CHEST:3,../../../../Chests/Loot/JunkChest_3.nbt,10,CHEST:3,../../../../Chests/Loot/JunkChest_4.nbt,10,CHEST:3,../../../../Chests/Loot/JunkChest_5.nbt,10,CHEST:3,../../../../Chests/Lore/JungleLore_1.nbt,1,CHEST:3,../../../../Chests/Lore/JungleLore_2.nbt,1,CHEST:3,../../../../Chests/Lore/JungleLore_3.nbt,1,CHEST:3,../../../../Chests/Lore/JungleLore_4.nbt,1,CHEST:3,../../../../Chests/Lore/JungleLore_5.nbt,1,CHEST:3,../../../../Chests/Loot/Common1.nbt,10,CHEST:3,../../../../Chests/Loot/Common2.nbt,10,CHEST:3,../../../../Chests/Loot/Common3.nbt,10,CHEST:3,../../../../Chests/Loot/Common4.nbt,10,CHEST:3,../../../../Chests/Loot/Common5.nbt,10,CHEST:3,../../../../Chests/Loot/Common6.nbt,10,CHEST:3,../../../../Chests/Loot/Common7.nbt,10,CHEST:3,../../../../Chests/Loot/Common8.nbt,10,CHEST:3,../../../../Chests/Loot/Common9.nbt,10,CHEST:3,../../../../Chests/Loot/Common10.nbt,10,CHEST:3,../../../../Chests/Loot/Common10.nbt,11,CHEST:3,../../../../Chests/Loot/Common12.nbt,10,CHEST:3,../../../../Chests/Loot/Common13.nbt,10,CHEST:3,../../../../Chests/Loot/Common14.nbt,10,CHEST:3,../../../../Chests/Loot/Common15.nbt,10,CHEST:3,../../../../Chests/Lore/JungleLore_1.nbt,2,CHEST:3,../../../../Chests/Lore/JungleLore_3.nbt,2,CHEST:3,../../../../Chests/Lore/JungleLore_4.nbt,2,CHEST:3,../../../../Chests/Lore/JungleLore_5.nbt,2,CHEST:3,../../../../Chests/Lore/JungleLore_5.nbt,2,CHEST:3,../../../../Chests/Loot/Rare1.nbt,5,CHEST:3,../../../../Chests/Loot/Rare2.nbt,5,CHEST:3,../../../../Chests/Loot/Rare3.nbt,5,CHEST:3,../../../../Chests/Loot/Rare4.nbt,5,CHEST:3,../../../../Chests/Loot/Rare5.nbt,5,CHEST:3,../../../../Chests/Loot/Rare6.nbt,5,CHEST:3,../../../../Chests/Loot/Rare7.nbt,5,CHEST:3,../../../../Chests/Loot/Rare8.nbt,5,CHEST:3,../../../../Chests/Loot/Rare9.nbt,5,CHEST:3,../../../../Chests/Loot/Rare10.nbt,5,CHEST:3,../../../../Chests/Loot/Rare11.nbt,5,CHEST:3,../../../../Chests/Loot/Rare12.nbt,5,CHEST:3,../../../../Chests/Loot/Rare13.nbt,5,CHEST:3,../../../../Chests/Loot/Rare14.nbt,5,CHEST:3,../../../../Chests/Loot/Rare15.nbt,5,CHEST:3,../../../../Chests/Loot/Epic1.nbt,2,CHEST:3,../../../../Chests/Loot/Epic2.nbt,2,CHEST:3,../../../../Chests/Loot/Epic3.nbt,2,CHEST:3,../../../../Chests/Loot/Epic4.nbt,2,CHEST:3,../../../../Chests/Loot/Epic5.nbt,2,CHEST:3,../../../../Chests/Loot/Epic6.nbt,2,CHEST:3,../../../../Chests/Loot/Epic7.nbt,2,CHEST:3,../../../../Chests/Loot/Epic8.nbt,2,CHEST:3,../../../../Chests/Loot/Epic9.nbt,2,CHEST:3,../../../../Chests/Loot/Epic10.nbt,2,CHEST:3,../../../../Chests/Loot/Epic11.nbt,2,CHEST:3,../../../../Chests/Loot/Epic12.nbt,2,CHEST:3,../../../../Chests/Loot/Epic13.nbt,2,CHEST:3,../../../../Chests/Loot/Epic14.nbt,2,CHEST:3,../../../../Chests/Loot/Epic15.nbt,5,CHEST:3,../../../../Chests/Loot/Rare1.nbt,5,CHEST:3,../../../../Chests/Loot/Rare2.nbt,5,CHEST:3,../../../../Chests/Loot/Rare3.nbt,5,CHEST:3,../../../../Chests/Loot/Rare4.nbt,5,CHEST:3,../../../../Chests/Loot/Rare5.nbt,10,CHEST:3,../../../../Chests/Loot/Rare6.nbt,10,CHEST:3,../../../../Chests/Loot/Rare7.nbt,10,CHEST:3,../../../../Chests/Loot/Rare8.nbt,10,CHEST:3,../../../../Chests/Loot/Rare9.nbt,10,CHEST:3,../../../../Chests/Loot/Rare10.nbt,15,CHEST:3,../../../../Chests/Loot/Rare11.nbt,15,CHEST:3,../../../../Chests/Loot/Rare12.nbt,15,CHEST:3,../../../../Chests/Loot/Rare13.nbt,15,CHEST:3,../../../../Chests/Loot/Rare14.nbt,15,CHEST:3,../../../../Chests/Loot/Rare15.nbt,15,CHEST:3,../../../../Chests/Loot/Epic15.nbt,100)
RandomBlock(-1,0,-4,AIR:0,20,CHEST:3,../../../../Chests/Loot/JunkChest_1.nbt,10,CHEST:3,../../../../Chests/Loot/JunkChest_2.nbt,10,CHEST:3,../../../../Chests/Loot/JunkChest_3.nbt,10,CHEST:3,../../../../Chests/Loot/JunkChest_4.nbt,10,CHEST:3,../../../../Chests/Loot/JunkChest_5.nbt,10,CHEST:3,../../../../Chests/Lore/JungleLore_1.nbt,1,CHEST:3,../../../../Chests/Lore/JungleLore_2.nbt,1,CHEST:3,../../../../Chests/Lore/JungleLore_3.nbt,1,CHEST:3,../../../../Chests/Lore/JungleLore_4.nbt,1,CHEST:3,../../../../Chests/Lore/JungleLore_5.nbt,1,CHEST:3,../../../../Chests/Loot/Common1.nbt,10,CHEST:3,../../../../Chests/Loot/Common2.nbt,10,CHEST:3,../../../../Chests/Loot/Common3.nbt,10,CHEST:3,../../../../Chests/Loot/Common4.nbt,10,CHEST:3,../../../../Chests/Loot/Common5.nbt,10,CHEST:3,../../../../Chests/Loot/Common6.nbt,10,CHEST:3,../../../../Chests/Loot/Common7.nbt,10,CHEST:3,../../../../Chests/Loot/Common8.nbt,10,CHEST:3,../../../../Chests/Loot/Common9.nbt,10,CHEST:3,../../../../Chests/Loot/Common10.nbt,10,CHEST:3,../../../../Chests/Loot/Common10.nbt,11,CHEST:3,../../../../Chests/Loot/Common12.nbt,10,CHEST:3,../../../../Chests/Loot/Common13.nbt,10,CHEST:3,../../../../Chests/Loot/Common14.nbt,10,CHEST:3,../../../../Chests/Loot/Common15.nbt,10,CHEST:3,../../../../Chests/Lore/JungleLore_1.nbt,2,CHEST:3,../../../../Chests/Lore/JungleLore_3.nbt,2,CHEST:3,../../../../Chests/Lore/JungleLore_4.nbt,2,CHEST:3,../../../../Chests/Lore/JungleLore_5.nbt,2,CHEST:3,../../../../Chests/Lore/JungleLore_5.nbt,2,CHEST:3,../../../../Chests/Loot/Rare1.nbt,5,CHEST:3,../../../../Chests/Loot/Rare2.nbt,5,CHEST:3,../../../../Chests/Loot/Rare3.nbt,5,CHEST:3,../../../../Chests/Loot/Rare4.nbt,5,CHEST:3,../../../../Chests/Loot/Rare5.nbt,5,CHEST:3,../../../../Chests/Loot/Rare6.nbt,5,CHEST:3,../../../../Chests/Loot/Rare7.nbt,5,CHEST:3,../../../../Chests/Loot/Rare8.nbt,5,CHEST:3,../../../../Chests/Loot/Rare9.nbt,5,CHEST:3,../../../../Chests/Loot/Rare10.nbt,5,CHEST:3,../../../../Chests/Loot/Rare11.nbt,5,CHEST:3,../../../../Chests/Loot/Rare12.nbt,5,CHEST:3,../../../../Chests/Loot/Rare13.nbt,5,CHEST:3,../../../../Chests/Loot/Rare14.nbt,5,CHEST:3,../../../../Chests/Loot/Rare15.nbt,5,CHEST:3,../../../../Chests/Loot/Epic1.nbt,2,CHEST:3,../../../../Chests/Loot/Epic2.nbt,2,CHEST:3,../../../../Chests/Loot/Epic3.nbt,2,CHEST:3,../../../../Chests/Loot/Epic4.nbt,2,CHEST:3,../../../../Chests/Loot/Epic5.nbt,2,CHEST:3,../../../../Chests/Loot/Epic6.nbt,2,CHEST:3,../../../../Chests/Loot/Epic7.nbt,2,CHEST:3,../../../../Chests/Loot/Epic8.nbt,2,CHEST:3,../../../../Chests/Loot/Epic9.nbt,2,CHEST:3,../../../../Chests/Loot/Epic10.nbt,2,CHEST:3,../../../../Chests/Loot/Epic11.nbt,2,CHEST:3,../../../../Chests/Loot/Epic12.nbt,2,CHEST:3,../../../../Chests/Loot/Epic13.nbt,2,CHEST:3,../../../../Chests/Loot/Epic14.nbt,2,CHEST:3,../../../../Chests/Loot/Epic15.nbt,5,CHEST:3,../../../../Chests/Loot/Rare1.nbt,5,CHEST:3,../../../../Chests/Loot/Rare2.nbt,5,CHEST:3,../../../../Chests/Loot/Rare3.nbt,5,CHEST:3,../../../../Chests/Loot/Rare4.nbt,5,CHEST:3,../../../../Chests/Loot/Rare5.nbt,10,CHEST:3,../../../../Chests/Loot/Rare6.nbt,10,CHEST:3,../../../../Chests/Loot/Rare7.nbt,10,CHEST:3,../../../../Chests/Loot/Rare8.nbt,10,CHEST:3,../../../../Chests/Loot/Rare9.nbt,10,CHEST:3,../../../../Chests/Loot/Rare10.nbt,15,CHEST:3,../../../../Chests/Loot/Rare11.nbt,15,CHEST:3,../../../../Chests/Loot/Rare12.nbt,15,CHEST:3,../../../../Chests/Loot/Rare13.nbt,15,CHEST:3,../../../../Chests/Loot/Rare14.nbt,15,CHEST:3,../../../../Chests/Loot/Rare15.nbt,15,CHEST:3,../../../../Chests/Loot/Epic15.nbt,100)
Block(4,0,-4,HARD_CLAY:0)
Block(-5,0,-3,BIRCH_DOOR:2)
Block(4,0,-3,HARD_CLAY:0)
Block(-5,0,-2,HARD_CLAY:0)
Block(-4,0,-2,ACACIA_STAIRS:5)
Block(-3,0,-2,WOOD_STEP:12)
Block(-2,0,-2,WOOD_STEP:12)
Block(-1,0,-2,ACACIA_STAIRS:4)
Block(1,0,-2,ACACIA_STAIRS:7)
Block(3,0,-2,ACACIA_STAIRS:7)
Block(4,0,-2,HARD_CLAY:0)
Block(-6,0,-1,ACACIA_FENCE:0)
Block(-5,0,-1,LOG_2:0)
Block(-4,0,-1,HARD_CLAY:0)
Block(-3,0,-1,HARD_CLAY:0)
Block(-2,0,-1,HARD_CLAY:0)
Block(-1,0,-1,LOG_2:0)
Block(0,0,-1,AIR)
Block(1,0,-1,SPRUCE_WOOD_STAIRS:2)
Block(2,0,-1,AIR)
Block(3,0,-1,SPRUCE_WOOD_STAIRS:2)
Block(4,0,-1,LOG_2:0)
Block(-5,0,0,ACACIA_FENCE:0)
Block(-2,0,0,ACACIA_FENCE:0)
Block(-1,0,0,HARD_CLAY:0)
Block(1,0,0,ACACIA_STAIRS:7)
Block(3,0,0,ACACIA_STAIRS:7)
Block(4,0,0,HARD_CLAY:0)
Block(-1,0,1,WOODEN_DOOR:2)
Block(1,0,1,SPRUCE_WOOD_STAIRS:2)
Block(3,0,1,SPRUCE_WOOD_STAIRS:2)
Block(4,0,1,HARD_CLAY:0)
Block(-1,0,2,WOODEN_DOOR:2)
Block(1,0,2,ACACIA_STAIRS:7)
Block(2,0,2,AIR)
Block(3,0,2,ACACIA_STAIRS:7)
Block(4,0,2,HARD_CLAY:0)
Block(-1,0,3,HARD_CLAY:0)
Block(0,0,3,AIR)
Block(1,0,3,SPRUCE_WOOD_STAIRS:2)
Block(3,0,3,SPRUCE_WOOD_STAIRS:2)
Block(4,0,3,HARD_CLAY:0)
Block(-5,0,4,ACACIA_FENCE:0)
Block(-2,0,4,ACACIA_FENCE:0)
Block(-1,0,4,LOG_2:0)
Block(0,0,4,HARD_CLAY:0)
Block(1,0,4,HARD_CLAY:0)
Block(2,0,4,HARD_CLAY:0)
Block(3,0,4,HARD_CLAY:0)
Block(4,0,4,LOG_2:0)
Block(5,0,4,ACACIA_FENCE:0)
Block(-1,0,5,SPRUCE_DOOR:2)
Block(1,0,5,CAULDRON:3)
Block(2,0,5,CAULDRON:3)
Block(4,0,5,SPRUCE_DOOR:0)
Block(0,0,6,SPRUCE_DOOR:1)
Block(3,0,6,SPRUCE_DOOR:1)
Block(-1,1,-8,LOG_2:0)
Block(0,1,-8,STAINED_CLAY:14)
Block(1,1,-8,STAINED_CLAY:14)
Block(2,1,-8,STAINED_CLAY:14)
Block(3,1,-8,STAINED_CLAY:14)
Block(4,1,-8,LOG_2:0)
Block(-1,1,-7,STAINED_CLAY:14)
Block(4,1,-7,STAINED_CLAY:14)
Block(-2,1,-6,HAY_BLOCK:4)
Block(-1,1,-6,STAINED_CLAY:14)
Block(3,1,-6,ACACIA_FENCE:0)
Block(4,1,-6,STAINED_CLAY:14)
Block(-6,1,-5,TORCH:5)
Block(-5,1,-5,LOG_2:0)
Block(-4,1,-5,STAINED_CLAY:14)
Block(-3,1,-5,ACACIA_FENCE:0)
Block(-2,1,-5,STAINED_CLAY:14)
Block(-1,1,-5,LOG_2:0)
RandomBlock(0,1,-5,FLOWER_POT:0,../../NBT/pots/JunglePot01.nbt,10,FLOWER_POT:0,../../NBT/pots/JunglePot02.nbt,10,FLOWER_POT:0,../../NBT/pots/JunglePot03.nbt,10,FLOWER_POT:0,../../NBT/pots/JunglePot04.nbt,10,FLOWER_POT:0,../../NBT/pots/JunglePot05.nbt,10,FLOWER_POT:0,../../NBT/pots/JunglePot06.nbt,10,FLOWER_POT:0,../../NBT/pots/JunglePot07.nbt,10,FLOWER_POT:0,../../NBT/pots/JunglePot08.nbt,100)
Block(4,1,-5,LOG_2:0)
Block(-5,1,-4,STAINED_CLAY:14)
Block(4,1,-4,ACACIA_FENCE:0)
Block(-5,1,-3,BIRCH_DOOR:8)
Block(4,1,-3,ACACIA_FENCE:0)
Block(-5,1,-2,STAINED_CLAY:14)
Block(-2,1,-2,BREWING_STAND:0)
Block(4,1,-2,ACACIA_FENCE:0)
Block(-6,1,-1,TORCH:5)
Block(-5,1,-1,LOG_2:0)
Block(-4,1,-1,STAINED_CLAY:14)
Block(-3,1,-1,ACACIA_FENCE:0)
Block(-2,1,-1,STAINED_CLAY:14)
Block(-1,1,-1,LOG_2:0)
Block(4,1,-1,LOG_2:0)
Block(-5,1,0,TORCH:5)
Block(-2,1,0,TORCH:5)
Block(-1,1,0,STAINED_CLAY:14)
Block(4,1,0,ACACIA_FENCE:0)
Block(-1,1,1,WOODEN_DOOR:9)
Block(4,1,1,ACACIA_FENCE:0)
Block(-1,1,2,WOODEN_DOOR:8)
Block(4,1,2,ACACIA_FENCE:0)
Block(-1,1,3,STAINED_CLAY:14)
Block(4,1,3,ACACIA_FENCE:0)
Block(-5,1,4,TORCH:5)
Block(-2,1,4,TORCH:5)
Block(-1,1,4,LOG_2:0)
Block(0,1,4,STAINED_CLAY:14)
Block(1,1,4,STAINED_CLAY:14)
Block(2,1,4,STAINED_CLAY:14)
Block(3,1,4,STAINED_CLAY:14)
Block(4,1,4,LOG_2:0)
Block(5,1,4,TORCH:5)
Block(-1,1,5,SPRUCE_DOOR:9)
Block(1,1,5,TRAP_DOOR:7)
Block(2,1,5,TRAP_DOOR:6)
Block(4,1,5,SPRUCE_DOOR:8)
Block(0,1,6,SPRUCE_DOOR:9)
Block(3,1,6,SPRUCE_DOOR:8)
Block(-1,2,-8,LOG_2:0)
Block(0,2,-8,STAINED_CLAY:14)
Block(1,2,-8,STAINED_CLAY:14)
Block(2,2,-8,STAINED_CLAY:14)
Block(3,2,-8,STAINED_CLAY:14)
Block(4,2,-8,LOG_2:0)
Block(-1,2,-7,STAINED_CLAY:14)
Block(4,2,-7,STAINED_CLAY:14)
RandomBlock(-3,2,-6,WALL_BANNER:2,../../NBT/banners/JungleBanner01.nbt,8,WALL_BANNER:2,../../NBT/banners/JungleBanner02.nbt,8,WALL_BANNER:2,../../NBT/banners/JungleBanner03.nbt,8,WALL_BANNER:2,../../NBT/banners/JungleBanner04.nbt,8,WALL_BANNER:2,../../NBT/banners/JungleBanner05.nbt,8,WALL_BANNER:2,../../NBT/banners/JungleBanner06.nbt,8,WALL_BANNER:2,../../NBT/banners/JungleBanner07.nbt,8,WALL_BANNER:2,../../NBT/banners/JungleBanner08.nbt,8,WALL_BANNER:2,../../NBT/banners/JungleBanner09.nbt,8,WALL_BANNER:2,../../NBT/banners/JungleBanner10.nbt,8,WALL_BANNER:2,../../NBT/banners/JungleBanner11.nbt,8,WALL_BANNER:2,../../NBT/banners/JungleBanner12.nbt,8,WALL_BANNER:2,../../NBT/banners/JungleBanner13.nbt,8,WALL_BANNER:2,../../NBT/banners/JungleBanner14.nbt,8,WALL_BANNER:2,../../NBT/banners/JungleBanner15.nbt,8,WALL_BANNER:2,../../NBT/banners/JungleBanner16.nbt,8,WALL_BANNER:2,../../NBT/banners/JungleBanner17.nbt,8,WALL_BANNER:2,../../NBT/banners/JungleBanner18.nbt,8,WALL_BANNER:2,../../NBT/banners/JungleBanner19.nbt,8,WALL_BANNER:2,../../NBT/banners/JungleBanner20.nbt,100)
Block(-1,2,-6,STAINED_CLAY:14)
Block(4,2,-6,STAINED_CLAY:14)
Block(-5,2,-5,LOG_2:0)
Block(-4,2,-5,STAINED_CLAY:14)
Block(-3,2,-5,ACACIA_FENCE:0)
Block(-2,2,-5,STAINED_CLAY:14)
Block(-1,2,-5,LOG_2:0)
RandomBlock(0,2,-5,WALL_BANNER:5,../../NBT/banners/JungleBanner01.nbt,8,WALL_BANNER:5,../../NBT/banners/JungleBanner02.nbt,8,WALL_BANNER:5,../../NBT/banners/JungleBanner03.nbt,8,WALL_BANNER:5,../../NBT/banners/JungleBanner04.nbt,8,WALL_BANNER:5,../../NBT/banners/JungleBanner05.nbt,8,WALL_BANNER:5,../../NBT/banners/JungleBanner06.nbt,8,WALL_BANNER:5,../../NBT/banners/JungleBanner07.nbt,8,WALL_BANNER:5,../../NBT/banners/JungleBanner08.nbt,8,WALL_BANNER:5,../../NBT/banners/JungleBanner09.nbt,8,WALL_BANNER:5,../../NBT/banners/JungleBanner10.nbt,8,WALL_BANNER:5,../../NBT/banners/JungleBanner11.nbt,8,WALL_BANNER:5,../../NBT/banners/JungleBanner12.nbt,8,WALL_BANNER:5,../../NBT/banners/JungleBanner13.nbt,8,WALL_BANNER:5,../../NBT/banners/JungleBanner14.nbt,8,WALL_BANNER:5,../../NBT/banners/JungleBanner15.nbt,8,WALL_BANNER:5,../../NBT/banners/JungleBanner16.nbt,8,WALL_BANNER:5,../../NBT/banners/JungleBanner17.nbt,8,WALL_BANNER:5,../../NBT/banners/JungleBanner18.nbt,8,WALL_BANNER:5,../../NBT/banners/JungleBanner19.nbt,8,WALL_BANNER:5,../../NBT/banners/JungleBanner20.nbt,100)
RandomBlock(3,2,-5,WALL_BANNER:4,../../NBT/banners/JungleBanner01.nbt,8,WALL_BANNER:4,../../NBT/banners/JungleBanner02.nbt,8,WALL_BANNER:4,../../NBT/banners/JungleBanner03.nbt,8,WALL_BANNER:4,../../NBT/banners/JungleBanner04.nbt,8,WALL_BANNER:4,../../NBT/banners/JungleBanner05.nbt,8,WALL_BANNER:4,../../NBT/banners/JungleBanner06.nbt,8,WALL_BANNER:4,../../NBT/banners/JungleBanner07.nbt,8,WALL_BANNER:4,../../NBT/banners/JungleBanner08.nbt,8,WALL_BANNER:4,../../NBT/banners/JungleBanner09.nbt,8,WALL_BANNER:4,../../NBT/banners/JungleBanner10.nbt,8,WALL_BANNER:4,../../NBT/banners/JungleBanner11.nbt,8,WALL_BANNER:4,../../NBT/banners/JungleBanner12.nbt,8,WALL_BANNER:4,../../NBT/banners/JungleBanner13.nbt,8,WALL_BANNER:4,../../NBT/banners/JungleBanner14.nbt,8,WALL_BANNER:4,../../NBT/banners/JungleBanner15.nbt,8,WALL_BANNER:4,../../NBT/banners/JungleBanner16.nbt,8,WALL_BANNER:4,../../NBT/banners/JungleBanner17.nbt,8,WALL_BANNER:4,../../NBT/banners/JungleBanner18.nbt,8,WALL_BANNER:4,../../NBT/banners/JungleBanner19.nbt,8,WALL_BANNER:4,../../NBT/banners/JungleBanner20.nbt,100)
Block(4,2,-5,LOG_2:0)
Block(-5,2,-4,STAINED_CLAY:14)
Block(-4,2,-4,ACACIA_FENCE:0)
RandomBlock(-1,2,-4,WALL_BANNER:3,../../NBT/banners/JungleBanner01.nbt,8,WALL_BANNER:3,../../NBT/banners/JungleBanner02.nbt,8,WALL_BANNER:3,../../NBT/banners/JungleBanner03.nbt,8,WALL_BANNER:3,../../NBT/banners/JungleBanner04.nbt,8,WALL_BANNER:3,../../NBT/banners/JungleBanner05.nbt,8,WALL_BANNER:3,../../NBT/banners/JungleBanner06.nbt,8,WALL_BANNER:3,../../NBT/banners/JungleBanner07.nbt,8,WALL_BANNER:3,../../NBT/banners/JungleBanner08.nbt,8,WALL_BANNER:3,../../NBT/banners/JungleBanner09.nbt,8,WALL_BANNER:3,../../NBT/banners/JungleBanner10.nbt,8,WALL_BANNER:3,../../NBT/banners/JungleBanner11.nbt,8,WALL_BANNER:3,../../NBT/banners/JungleBanner12.nbt,8,WALL_BANNER:3,../../NBT/banners/JungleBanner13.nbt,8,WALL_BANNER:3,../../NBT/banners/JungleBanner14.nbt,8,WALL_BANNER:3,../../NBT/banners/JungleBanner15.nbt,8,WALL_BANNER:3,../../NBT/banners/JungleBanner16.nbt,8,WALL_BANNER:3,../../NBT/banners/JungleBanner17.nbt,8,WALL_BANNER:3,../../NBT/banners/JungleBanner18.nbt,8,WALL_BANNER:3,../../NBT/banners/JungleBanner19.nbt,8,WALL_BANNER:3,../../NBT/banners/JungleBanner20.nbt,100)
Block(4,2,-4,ACACIA_FENCE:0)
RandomBlock(5,2,-4,WALL_BANNER:5,../../NBT/banners/JungleBanner01.nbt,8,WALL_BANNER:5,../../NBT/banners/JungleBanner02.nbt,8,WALL_BANNER:5,../../NBT/banners/JungleBanner03.nbt,8,WALL_BANNER:5,../../NBT/banners/JungleBanner04.nbt,8,WALL_BANNER:5,../../NBT/banners/JungleBanner05.nbt,8,WALL_BANNER:5,../../NBT/banners/JungleBanner06.nbt,8,WALL_BANNER:5,../../NBT/banners/JungleBanner07.nbt,8,WALL_BANNER:5,../../NBT/banners/JungleBanner08.nbt,8,WALL_BANNER:5,../../NBT/banners/JungleBanner09.nbt,8,WALL_BANNER:5,../../NBT/banners/JungleBanner10.nbt,8,WALL_BANNER:5,../../NBT/banners/JungleBanner11.nbt,8,WALL_BANNER:5,../../NBT/banners/JungleBanner12.nbt,8,WALL_BANNER:5,../../NBT/banners/JungleBanner13.nbt,8,WALL_BANNER:5,../../NBT/banners/JungleBanner14.nbt,8,WALL_BANNER:5,../../NBT/banners/JungleBanner15.nbt,8,WALL_BANNER:5,../../NBT/banners/JungleBanner16.nbt,8,WALL_BANNER:5,../../NBT/banners/JungleBanner17.nbt,8,WALL_BANNER:5,../../NBT/banners/JungleBanner18.nbt,8,WALL_BANNER:5,../../NBT/banners/JungleBanner19.nbt,8,WALL_BANNER:5,../../NBT/banners/JungleBanner20.nbt,100)
Block(-5,2,-3,STAINED_CLAY:14)
Block(4,2,-3,ACACIA_FENCE:0)
RandomBlock(5,2,-3,WALL_BANNER:5,../../NBT/banners/JungleBanner01.nbt,8,WALL_BANNER:5,../../NBT/banners/JungleBanner02.nbt,8,WALL_BANNER:5,../../NBT/banners/JungleBanner03.nbt,8,WALL_BANNER:5,../../NBT/banners/JungleBanner04.nbt,8,WALL_BANNER:5,../../NBT/banners/JungleBanner05.nbt,8,WALL_BANNER:5,../../NBT/banners/JungleBanner06.nbt,8,WALL_BANNER:5,../../NBT/banners/JungleBanner07.nbt,8,WALL_BANNER:5,../../NBT/banners/JungleBanner08.nbt,8,WALL_BANNER:5,../../NBT/banners/JungleBanner09.nbt,8,WALL_BANNER:5,../../NBT/banners/JungleBanner10.nbt,8,WALL_BANNER:5,../../NBT/banners/JungleBanner11.nbt,8,WALL_BANNER:5,../../NBT/banners/JungleBanner12.nbt,8,WALL_BANNER:5,../../NBT/banners/JungleBanner13.nbt,8,WALL_BANNER:5,../../NBT/banners/JungleBanner14.nbt,8,WALL_BANNER:5,../../NBT/banners/JungleBanner15.nbt,8,WALL_BANNER:5,../../NBT/banners/JungleBanner16.nbt,8,WALL_BANNER:5,../../NBT/banners/JungleBanner17.nbt,8,WALL_BANNER:5,../../NBT/banners/JungleBanner18.nbt,8,WALL_BANNER:5,../../NBT/banners/JungleBanner19.nbt,8,WALL_BANNER:5,../../NBT/banners/JungleBanner20.nbt,100)
Block(-5,2,-2,STAINED_CLAY:14)
Block(-4,2,-2,ACACIA_FENCE:0)
RandomBlock(-1,2,-2,WALL_BANNER:2,../../NBT/banners/JungleBanner01.nbt,8,WALL_BANNER:2,../../NBT/banners/JungleBanner02.nbt,8,WALL_BANNER:2,../../NBT/banners/JungleBanner03.nbt,8,WALL_BANNER:2,../../NBT/banners/JungleBanner04.nbt,8,WALL_BANNER:2,../../NBT/banners/JungleBanner05.nbt,8,WALL_BANNER:2,../../NBT/banners/JungleBanner06.nbt,8,WALL_BANNER:2,../../NBT/banners/JungleBanner07.nbt,8,WALL_BANNER:2,../../NBT/banners/JungleBanner08.nbt,8,WALL_BANNER:2,../../NBT/banners/JungleBanner09.nbt,8,WALL_BANNER:2,../../NBT/banners/JungleBanner10.nbt,8,WALL_BANNER:2,../../NBT/banners/JungleBanner11.nbt,8,WALL_BANNER:2,../../NBT/banners/JungleBanner12.nbt,8,WALL_BANNER:2,../../NBT/banners/JungleBanner13.nbt,8,WALL_BANNER:2,../../NBT/banners/JungleBanner14.nbt,8,WALL_BANNER:2,../../NBT/banners/JungleBanner15.nbt,8,WALL_BANNER:2,../../NBT/banners/JungleBanner16.nbt,8,WALL_BANNER:2,../../NBT/banners/JungleBanner17.nbt,8,WALL_BANNER:2,../../NBT/banners/JungleBanner18.nbt,8,WALL_BANNER:2,../../NBT/banners/JungleBanner19.nbt,8,WALL_BANNER:2,../../NBT/banners/JungleBanner20.nbt,100)
Block(4,2,-2,ACACIA_FENCE:0)
RandomBlock(5,2,-2,WALL_BANNER:5,../../NBT/banners/JungleBanner01.nbt,8,WALL_BANNER:5,../../NBT/banners/JungleBanner02.nbt,8,WALL_BANNER:5,../../NBT/banners/JungleBanner03.nbt,8,WALL_BANNER:5,../../NBT/banners/JungleBanner04.nbt,8,WALL_BANNER:5,../../NBT/banners/JungleBanner05.nbt,8,WALL_BANNER:5,../../NBT/banners/JungleBanner06.nbt,8,WALL_BANNER:5,../../NBT/banners/JungleBanner07.nbt,8,WALL_BANNER:5,../../NBT/banners/JungleBanner08.nbt,8,WALL_BANNER:5,../../NBT/banners/JungleBanner09.nbt,8,WALL_BANNER:5,../../NBT/banners/JungleBanner10.nbt,8,WALL_BANNER:5,../../NBT/banners/JungleBanner11.nbt,8,WALL_BANNER:5,../../NBT/banners/JungleBanner12.nbt,8,WALL_BANNER:5,../../NBT/banners/JungleBanner13.nbt,8,WALL_BANNER:5,../../NBT/banners/JungleBanner14.nbt,8,WALL_BANNER:5,../../NBT/banners/JungleBanner15.nbt,8,WALL_BANNER:5,../../NBT/banners/JungleBanner16.nbt,8,WALL_BANNER:5,../../NBT/banners/JungleBanner17.nbt,8,WALL_BANNER:5,../../NBT/banners/JungleBanner18.nbt,8,WALL_BANNER:5,../../NBT/banners/JungleBanner19.nbt,8,WALL_BANNER:5,../../NBT/banners/JungleBanner20.nbt,100)
Block(-5,2,-1,LOG_2:0)
Block(-4,2,-1,STAINED_CLAY:14)
Block(-3,2,-1,ACACIA_FENCE:0)
Block(-2,2,-1,STAINED_CLAY:14)
Block(-1,2,-1,LOG_2:0)
RandomBlock(0,2,-1,WALL_BANNER:5,../../NBT/banners/JungleBanner01.nbt,8,WALL_BANNER:5,../../NBT/banners/JungleBanner02.nbt,8,WALL_BANNER:5,../../NBT/banners/JungleBanner03.nbt,8,WALL_BANNER:5,../../NBT/banners/JungleBanner04.nbt,8,WALL_BANNER:5,../../NBT/banners/JungleBanner05.nbt,8,WALL_BANNER:5,../../NBT/banners/JungleBanner06.nbt,8,WALL_BANNER:5,../../NBT/banners/JungleBanner07.nbt,8,WALL_BANNER:5,../../NBT/banners/JungleBanner08.nbt,8,WALL_BANNER:5,../../NBT/banners/JungleBanner09.nbt,8,WALL_BANNER:5,../../NBT/banners/JungleBanner10.nbt,8,WALL_BANNER:5,../../NBT/banners/JungleBanner11.nbt,8,WALL_BANNER:5,../../NBT/banners/JungleBanner12.nbt,8,WALL_BANNER:5,../../NBT/banners/JungleBanner13.nbt,8,WALL_BANNER:5,../../NBT/banners/JungleBanner14.nbt,8,WALL_BANNER:5,../../NBT/banners/JungleBanner15.nbt,8,WALL_BANNER:5,../../NBT/banners/JungleBanner16.nbt,8,WALL_BANNER:5,../../NBT/banners/JungleBanner17.nbt,8,WALL_BANNER:5,../../NBT/banners/JungleBanner18.nbt,8,WALL_BANNER:5,../../NBT/banners/JungleBanner19.nbt,8,WALL_BANNER:5,../../NBT/banners/JungleBanner20.nbt,100)
RandomBlock(3,2,-1,WALL_BANNER:4,../../NBT/banners/JungleBanner01.nbt,8,WALL_BANNER:4,../../NBT/banners/JungleBanner02.nbt,8,WALL_BANNER:4,../../NBT/banners/JungleBanner03.nbt,8,WALL_BANNER:4,../../NBT/banners/JungleBanner04.nbt,8,WALL_BANNER:4,../../NBT/banners/JungleBanner05.nbt,8,WALL_BANNER:4,../../NBT/banners/JungleBanner06.nbt,8,WALL_BANNER:4,../../NBT/banners/JungleBanner07.nbt,8,WALL_BANNER:4,../../NBT/banners/JungleBanner08.nbt,8,WALL_BANNER:4,../../NBT/banners/JungleBanner09.nbt,8,WALL_BANNER:4,../../NBT/banners/JungleBanner10.nbt,8,WALL_BANNER:4,../../NBT/banners/JungleBanner11.nbt,8,WALL_BANNER:4,../../NBT/banners/JungleBanner12.nbt,8,WALL_BANNER:4,../../NBT/banners/JungleBanner13.nbt,8,WALL_BANNER:4,../../NBT/banners/JungleBanner14.nbt,8,WALL_BANNER:4,../../NBT/banners/JungleBanner15.nbt,8,WALL_BANNER:4,../../NBT/banners/JungleBanner16.nbt,8,WALL_BANNER:4,../../NBT/banners/JungleBanner17.nbt,8,WALL_BANNER:4,../../NBT/banners/JungleBanner18.nbt,8,WALL_BANNER:4,../../NBT/banners/JungleBanner19.nbt,8,WALL_BANNER:4,../../NBT/banners/JungleBanner20.nbt,100)
Block(4,2,-1,LOG_2:0)
RandomBlock(-3,2,0,WALL_BANNER:3,../../NBT/banners/JungleBanner01.nbt,8,WALL_BANNER:3,../../NBT/banners/JungleBanner02.nbt,8,WALL_BANNER:3,../../NBT/banners/JungleBanner03.nbt,8,WALL_BANNER:3,../../NBT/banners/JungleBanner04.nbt,8,WALL_BANNER:3,../../NBT/banners/JungleBanner05.nbt,8,WALL_BANNER:3,../../NBT/banners/JungleBanner06.nbt,8,WALL_BANNER:3,../../NBT/banners/JungleBanner07.nbt,8,WALL_BANNER:3,../../NBT/banners/JungleBanner08.nbt,8,WALL_BANNER:3,../../NBT/banners/JungleBanner09.nbt,8,WALL_BANNER:3,../../NBT/banners/JungleBanner10.nbt,8,WALL_BANNER:3,../../NBT/banners/JungleBanner11.nbt,8,WALL_BANNER:3,../../NBT/banners/JungleBanner12.nbt,8,WALL_BANNER:3,../../NBT/banners/JungleBanner13.nbt,8,WALL_BANNER:3,../../NBT/banners/JungleBanner14.nbt,8,WALL_BANNER:3,../../NBT/banners/JungleBanner15.nbt,8,WALL_BANNER:3,../../NBT/banners/JungleBanner16.nbt,8,WALL_BANNER:3,../../NBT/banners/JungleBanner17.nbt,8,WALL_BANNER:3,../../NBT/banners/JungleBanner18.nbt,8,WALL_BANNER:3,../../NBT/banners/JungleBanner19.nbt,8,WALL_BANNER:3,../../NBT/banners/JungleBanner20.nbt,100)
Block(-1,2,0,STAINED_CLAY:14)
Block(4,2,0,ACACIA_FENCE:0)
RandomBlock(5,2,0,WALL_BANNER:5,../../NBT/banners/JungleBanner01.nbt,8,WALL_BANNER:5,../../NBT/banners/JungleBanner02.nbt,8,WALL_BANNER:5,../../NBT/banners/JungleBanner03.nbt,8,WALL_BANNER:5,../../NBT/banners/JungleBanner04.nbt,8,WALL_BANNER:5,../../NBT/banners/JungleBanner05.nbt,8,WALL_BANNER:5,../../NBT/banners/JungleBanner06.nbt,8,WALL_BANNER:5,../../NBT/banners/JungleBanner07.nbt,8,WALL_BANNER:5,../../NBT/banners/JungleBanner08.nbt,8,WALL_BANNER:5,../../NBT/banners/JungleBanner09.nbt,8,WALL_BANNER:5,../../NBT/banners/JungleBanner10.nbt,8,WALL_BANNER:5,../../NBT/banners/JungleBanner11.nbt,8,WALL_BANNER:5,../../NBT/banners/JungleBanner12.nbt,8,WALL_BANNER:5,../../NBT/banners/JungleBanner13.nbt,8,WALL_BANNER:5,../../NBT/banners/JungleBanner14.nbt,8,WALL_BANNER:5,../../NBT/banners/JungleBanner15.nbt,8,WALL_BANNER:5,../../NBT/banners/JungleBanner16.nbt,8,WALL_BANNER:5,../../NBT/banners/JungleBanner17.nbt,8,WALL_BANNER:5,../../NBT/banners/JungleBanner18.nbt,8,WALL_BANNER:5,../../NBT/banners/JungleBanner19.nbt,8,WALL_BANNER:5,../../NBT/banners/JungleBanner20.nbt,100)
Block(-1,2,1,STAINED_CLAY:14)
Block(4,2,1,ACACIA_FENCE:0)
RandomBlock(5,2,1,WALL_BANNER:5,../../NBT/banners/JungleBanner01.nbt,8,WALL_BANNER:5,../../NBT/banners/JungleBanner02.nbt,8,WALL_BANNER:5,../../NBT/banners/JungleBanner03.nbt,8,WALL_BANNER:5,../../NBT/banners/JungleBanner04.nbt,8,WALL_BANNER:5,../../NBT/banners/JungleBanner05.nbt,8,WALL_BANNER:5,../../NBT/banners/JungleBanner06.nbt,8,WALL_BANNER:5,../../NBT/banners/JungleBanner07.nbt,8,WALL_BANNER:5,../../NBT/banners/JungleBanner08.nbt,8,WALL_BANNER:5,../../NBT/banners/JungleBanner09.nbt,8,WALL_BANNER:5,../../NBT/banners/JungleBanner10.nbt,8,WALL_BANNER:5,../../NBT/banners/JungleBanner11.nbt,8,WALL_BANNER:5,../../NBT/banners/JungleBanner12.nbt,8,WALL_BANNER:5,../../NBT/banners/JungleBanner13.nbt,8,WALL_BANNER:5,../../NBT/banners/JungleBanner14.nbt,8,WALL_BANNER:5,../../NBT/banners/JungleBanner15.nbt,8,WALL_BANNER:5,../../NBT/banners/JungleBanner16.nbt,8,WALL_BANNER:5,../../NBT/banners/JungleBanner17.nbt,8,WALL_BANNER:5,../../NBT/banners/JungleBanner18.nbt,8,WALL_BANNER:5,../../NBT/banners/JungleBanner19.nbt,8,WALL_BANNER:5,../../NBT/banners/JungleBanner20.nbt,100)
Block(-1,2,2,STAINED_CLAY:14)
Block(4,2,2,ACACIA_FENCE:0)
RandomBlock(5,2,2,WALL_BANNER:5,../../NBT/banners/JungleBanner01.nbt,8,WALL_BANNER:5,../../NBT/banners/JungleBanner02.nbt,8,WALL_BANNER:5,../../NBT/banners/JungleBanner03.nbt,8,WALL_BANNER:5,../../NBT/banners/JungleBanner04.nbt,8,WALL_BANNER:5,../../NBT/banners/JungleBanner05.nbt,8,WALL_BANNER:5,../../NBT/banners/JungleBanner06.nbt,8,WALL_BANNER:5,../../NBT/banners/JungleBanner07.nbt,8,WALL_BANNER:5,../../NBT/banners/JungleBanner08.nbt,8,WALL_BANNER:5,../../NBT/banners/JungleBanner09.nbt,8,WALL_BANNER:5,../../NBT/banners/JungleBanner10.nbt,8,WALL_BANNER:5,../../NBT/banners/JungleBanner11.nbt,8,WALL_BANNER:5,../../NBT/banners/JungleBanner12.nbt,8,WALL_BANNER:5,../../NBT/banners/JungleBanner13.nbt,8,WALL_BANNER:5,../../NBT/banners/JungleBanner14.nbt,8,WALL_BANNER:5,../../NBT/banners/JungleBanner15.nbt,8,WALL_BANNER:5,../../NBT/banners/JungleBanner16.nbt,8,WALL_BANNER:5,../../NBT/banners/JungleBanner17.nbt,8,WALL_BANNER:5,../../NBT/banners/JungleBanner18.nbt,8,WALL_BANNER:5,../../NBT/banners/JungleBanner19.nbt,8,WALL_BANNER:5,../../NBT/banners/JungleBanner20.nbt,100)
Block(-1,2,3,STAINED_CLAY:14)
Block(4,2,3,ACACIA_FENCE:0)
RandomBlock(5,2,3,WALL_BANNER:5,../../NBT/banners/JungleBanner01.nbt,8,WALL_BANNER:5,../../NBT/banners/JungleBanner02.nbt,8,WALL_BANNER:5,../../NBT/banners/JungleBanner03.nbt,8,WALL_BANNER:5,../../NBT/banners/JungleBanner04.nbt,8,WALL_BANNER:5,../../NBT/banners/JungleBanner05.nbt,8,WALL_BANNER:5,../../NBT/banners/JungleBanner06.nbt,8,WALL_BANNER:5,../../NBT/banners/JungleBanner07.nbt,8,WALL_BANNER:5,../../NBT/banners/JungleBanner08.nbt,8,WALL_BANNER:5,../../NBT/banners/JungleBanner09.nbt,8,WALL_BANNER:5,../../NBT/banners/JungleBanner10.nbt,8,WALL_BANNER:5,../../NBT/banners/JungleBanner11.nbt,8,WALL_BANNER:5,../../NBT/banners/JungleBanner12.nbt,8,WALL_BANNER:5,../../NBT/banners/JungleBanner13.nbt,8,WALL_BANNER:5,../../NBT/banners/JungleBanner14.nbt,8,WALL_BANNER:5,../../NBT/banners/JungleBanner15.nbt,8,WALL_BANNER:5,../../NBT/banners/JungleBanner16.nbt,8,WALL_BANNER:5,../../NBT/banners/JungleBanner17.nbt,8,WALL_BANNER:5,../../NBT/banners/JungleBanner18.nbt,8,WALL_BANNER:5,../../NBT/banners/JungleBanner19.nbt,8,WALL_BANNER:5,../../NBT/banners/JungleBanner20.nbt,100)
Block(-1,2,4,LOG_2:0)
Block(0,2,4,STAINED_CLAY:14)
Block(1,2,4,STAINED_CLAY:14)
Block(2,2,4,STAINED_CLAY:14)
Block(3,2,4,STAINED_CLAY:14)
Block(4,2,4,LOG_2:0)
Block(0,2,5,WOOD_STEP:0)
Block(1,2,5,WOOD_STEP:0)
Block(2,2,5,WOOD_STEP:0)
Block(3,2,5,WOOD_STEP:0)
Block(-2,3,-8,WOOD_STAIRS:0)
Block(-1,3,-8,LOG_2:0)
Block(0,3,-8,HARD_CLAY:0)
Block(1,3,-8,HARD_CLAY:0)
Block(2,3,-8,HARD_CLAY:0)
Block(3,3,-8,HARD_CLAY:0)
Block(4,3,-8,LOG_2:0)
Block(5,3,-8,WOOD_STAIRS:1)
Block(-2,3,-7,WOOD_STAIRS:0)
Block(-1,3,-7,HARD_CLAY:0)
Block(0,3,-7,ACACIA_FENCE:0)
Block(1,3,-7,ACACIA_FENCE:0)
Block(2,3,-7,ACACIA_FENCE:0)
Block(3,3,-7,ACACIA_FENCE:0)
Block(4,3,-7,HARD_CLAY:0)
Block(5,3,-7,WOOD_STAIRS:1)
Block(-6,3,-6,WOOD_STAIRS:2)
Block(-5,3,-6,WOOD_STAIRS:2)
Block(-4,3,-6,WOOD_STAIRS:2)
Block(-3,3,-6,WOOD_STAIRS:2)
Block(-2,3,-6,WOOD_STAIRS:2)
Block(-1,3,-6,HARD_CLAY:0)
Block(4,3,-6,HARD_CLAY:0)
Block(5,3,-6,WOOD_STAIRS:1)
Block(-6,3,-5,WOOD_STAIRS:7)
Block(-5,3,-5,LOG_2:0)
Block(-4,3,-5,HARD_CLAY:0)
Block(-3,3,-5,HARD_CLAY:0)
Block(-2,3,-5,HARD_CLAY:0)
Block(-1,3,-5,LOG_2:0)
Block(0,3,-5,ACACIA_FENCE:0)
Block(3,3,-5,ACACIA_FENCE:0)
Block(4,3,-5,LOG_2:0)
Block(5,3,-5,WOOD_STAIRS:1)
Block(-6,3,-4,ACACIA_FENCE:0)
Block(-5,3,-4,HARD_CLAY:0)
Block(-4,3,-4,TORCH:5)
Block(-1,3,-4,ACACIA_FENCE:0)
Block(4,3,-4,HARD_CLAY:0)
Block(5,3,-4,WOOD_STAIRS:1)
Block(-5,3,-3,HARD_CLAY:0)
Block(4,3,-3,HARD_CLAY:0)
Block(5,3,-3,WOOD_STAIRS:1)
Block(-6,3,-2,ACACIA_FENCE:0)
Block(-5,3,-2,HARD_CLAY:0)
Block(-4,3,-2,TORCH:5)
Block(-1,3,-2,ACACIA_FENCE:0)
Block(4,3,-2,HARD_CLAY:0)
Block(5,3,-2,WOOD_STAIRS:1)
Block(-6,3,-1,WOOD_STAIRS:6)
Block(-5,3,-1,LOG_2:0)
Block(-4,3,-1,HARD_CLAY:0)
Block(-3,3,-1,HARD_CLAY:0)
Block(-2,3,-1,HARD_CLAY:0)
Block(-1,3,-1,LOG_2:0)
Block(0,3,-1,ACACIA_FENCE:0)
Block(3,3,-1,ACACIA_FENCE:0)
Block(4,3,-1,LOG_2:0)
Block(5,3,-1,WOOD_STAIRS:1)
Block(-6,3,0,WOOD_STAIRS:3)
Block(-5,3,0,WOOD_STAIRS:3)
Block(-4,3,0,WOOD_STAIRS:3)
Block(-3,3,0,WOOD_STAIRS:3)
Block(-2,3,0,WOOD_STAIRS:3)
Block(-1,3,0,HARD_CLAY:0)
Block(4,3,0,HARD_CLAY:0)
Block(5,3,0,WOOD_STAIRS:1)
Block(-2,3,1,WOOD_STAIRS:0)
Block(-1,3,1,HARD_CLAY:0)
Block(4,3,1,HARD_CLAY:0)
Block(5,3,1,WOOD_STAIRS:1)
Block(-2,3,2,WOOD_STAIRS:0)
Block(-1,3,2,HARD_CLAY:0)
Block(4,3,2,HARD_CLAY:0)
Block(5,3,2,WOOD_STAIRS:1)
Block(-2,3,3,WOOD_STAIRS:0)
Block(-1,3,3,HARD_CLAY:0)
Block(0,3,3,ACACIA_FENCE:0)
Block(1,3,3,ACACIA_FENCE:0)
Block(2,3,3,ACACIA_FENCE:0)
Block(3,3,3,ACACIA_FENCE:0)
Block(4,3,3,HARD_CLAY:0)
Block(5,3,3,WOOD_STAIRS:1)
Block(-2,3,4,WOOD_STAIRS:0)
Block(-1,3,4,LOG_2:0)
Block(0,3,4,HARD_CLAY:0)
Block(1,3,4,HARD_CLAY:0)
Block(2,3,4,HARD_CLAY:0)
Block(3,3,4,HARD_CLAY:0)
Block(4,3,4,LOG_2:0)
Block(5,3,4,WOOD_STAIRS:1)
Block(-2,3,5,WOOD_STAIRS:0)
Block(-1,3,5,WOOD_STAIRS:5)
Block(0,3,5,ACACIA_FENCE:0)
Block(3,3,5,ACACIA_FENCE:0)
Block(4,3,5,WOOD_STAIRS:4)
Block(5,3,5,WOOD_STAIRS:1)
Block(-1,4,-8,LOG_2:0)
Block(0,4,-8,HARD_CLAY:0)
Block(1,4,-8,HARD_CLAY:0)
Block(2,4,-8,HARD_CLAY:0)
Block(3,4,-8,HARD_CLAY:0)
Block(4,4,-8,LOG_2:0)
Block(-1,4,-7,WOOD_STAIRS:0)
Block(0,4,-7,WOOD_STAIRS:5)
Block(1,4,-7,TORCH:5)
Block(2,4,-7,TORCH:5)
Block(3,4,-7,WOOD_STAIRS:4)
Block(4,4,-7,WOOD_STAIRS:1)
Block(-1,4,-6,WOOD_STEP:1)
Block(0,4,-6,WOOD_STAIRS:5)
Block(3,4,-6,WOOD_STAIRS:4)
Block(4,4,-6,WOOD_STEP:2)
Block(-6,4,-5,WOOD_STAIRS:2)
Block(-5,4,-5,LOG_2:0)
Block(-4,4,-5,WOOD_STEP:1)
Block(-3,4,-5,WOOD_STEP:1)
Block(-2,4,-5,WOOD_STAIRS:2)
Block(-1,4,-5,LOG_2:0)
Block(0,4,-5,LOG_2:4)
Block(1,4,-5,LOG_2:4)
Block(2,4,-5,LOG_2:4)
Block(3,4,-5,LOG_2:4)
Block(4,4,-5,LOG_2:0)
Block(-6,4,-4,WOOD_STAIRS:7)
Block(-5,4,-4,HARD_CLAY:0)
Block(-4,4,-4,WOOD_STAIRS:7)
Block(-3,4,-4,WOOD_STAIRS:7)
Block(-2,4,-4,WOOD_STAIRS:7)
Block(-1,4,-4,LOG_2:8)
Block(3,4,-4,WOOD_STAIRS:4)
Block(4,4,-4,WOOD_STAIRS:1)
Block(-5,4,-3,HARD_CLAY:0)
Block(-1,4,-3,LOG_2:8)
Block(3,4,-3,WOOD_STAIRS:4)
Block(4,4,-3,WOOD_STEP:2)
Block(-6,4,-2,WOOD_STAIRS:6)
Block(-5,4,-2,HARD_CLAY:0)
Block(-4,4,-2,WOOD_STAIRS:6)
Block(-3,4,-2,WOOD_STAIRS:6)
Block(-2,4,-2,WOOD_STAIRS:6)
Block(-1,4,-2,LOG_2:8)
Block(3,4,-2,WOOD_STAIRS:4)
Block(4,4,-2,WOOD_STAIRS:1)
Block(-6,4,-1,WOOD_STAIRS:3)
Block(-5,4,-1,LOG_2:0)
Block(-4,4,-1,BIRCH_WOOD_STAIRS:3)
Block(-3,4,-1,BIRCH_WOOD_STAIRS:3)
Block(-2,4,-1,BIRCH_WOOD_STAIRS:3)
Block(-1,4,-1,LOG_2:0)
Block(0,4,-1,LOG_2:4)
Block(1,4,-1,LOG_2:4)
Block(2,4,-1,LOG_2:4)
Block(3,4,-1,LOG_2:4)
Block(4,4,-1,LOG_2:0)
Block(-1,4,0,WOOD_STAIRS:0)
Block(0,4,0,WOOD_STAIRS:5)
Block(3,4,0,WOOD_STAIRS:4)
Block(4,4,0,WOOD_STAIRS:1)
Block(-1,4,1,BIRCH_WOOD_STAIRS:0)
Block(0,4,1,WOOD_STAIRS:5)
Block(3,4,1,WOOD_STAIRS:4)
Block(4,4,1,WOOD_STEP:1)
Block(-1,4,2,BIRCH_WOOD_STAIRS:0)
Block(0,4,2,WOOD_STAIRS:5)
Block(3,4,2,WOOD_STAIRS:4)
Block(4,4,2,WOOD_STEP:1)
Block(-1,4,3,WOOD_STAIRS:0)
Block(0,4,3,WOOD_STAIRS:5)
Block(1,4,3,TORCH:5)
Block(2,4,3,TORCH:5)
Block(3,4,3,WOOD_STAIRS:4)
Block(4,4,3,WOOD_STAIRS:1)
Block(-1,4,4,LOG_2:0)
Block(0,4,4,HARD_CLAY:0)
Block(1,4,4,HARD_CLAY:0)
Block(2,4,4,HARD_CLAY:0)
Block(3,4,4,HARD_CLAY:0)
Block(4,4,4,LOG_2:0)
Block(-1,4,5,WOOD_STAIRS:0)
Block(0,4,5,WOOD_STAIRS:5)
Block(3,4,5,WOOD_STAIRS:4)
Block(4,4,5,WOOD_STAIRS:1)
Block(-1,5,-8,COBBLE_WALL:0)
Block(0,5,-8,WOOD_STAIRS:0)
Block(1,5,-8,HARD_CLAY:0)
Block(2,5,-8,HARD_CLAY:0)
Block(3,5,-8,WOOD_STAIRS:1)
Block(4,5,-8,COBBLE_WALL:0)
Block(0,5,-7,WOOD_STEP:1)
Block(1,5,-7,WOOD_STAIRS:5)
Block(2,5,-7,WOOD_STAIRS:4)
Block(3,5,-7,WOOD_STEP:2)
Block(0,5,-6,WOOD_DOUBLE_STEP:1)
Block(1,5,-6,WOOD_STAIRS:5)
Block(2,5,-6,WOOD_STAIRS:4)
Block(3,5,-6,WOOD_STEP:2)
Block(-5,5,-5,COBBLE_WALL:0)
Block(-1,5,-5,COBBLE_WALL:0)
Block(0,5,-5,WOOD_STAIRS:0)
Block(1,5,-5,WOOD_STAIRS:5)
Block(2,5,-5,WOOD_STAIRS:4)
Block(3,5,-5,WOOD_STAIRS:1)
Block(4,5,-5,COBBLE_WALL:0)
Block(-6,5,-4,WOOD_STAIRS:2)
Block(-5,5,-4,WOOD_STAIRS:2)
Block(-4,5,-4,WOOD_STAIRS:2)
Block(-3,5,-4,WOOD_STEP:1)
Block(-2,5,-4,WOOD_STAIRS:2)
Block(-1,5,-4,WOOD_STAIRS:2)
Block(0,5,-4,WOOD_STAIRS:2)
Block(1,5,-4,WOOD_STAIRS:5)
Block(2,5,-4,WOOD_STAIRS:4)
Block(3,5,-4,WOOD_STEP:2)
Block(-6,5,-3,WOOD_STAIRS:4)
Block(-5,5,-3,HARD_CLAY:0)
Block(-4,5,-3,WOOD_STEP:8)
Block(-3,5,-3,WOOD_STEP:8)
Block(-2,5,-3,WOOD_STEP:8)
Block(-1,5,-3,WOOD_STEP:8)
Block(0,5,-3,WOOD_STEP:8)
Block(1,5,-3,WOOD_STEP:8)
Block(2,5,-3,WOOD_STAIRS:4)
Block(3,5,-3,WOOD_STEP:2)
Block(-6,5,-2,WOOD_STAIRS:3)
Block(-5,5,-2,WOOD_STAIRS:3)
Block(-4,5,-2,WOOD_STEP:1)
Block(-3,5,-2,WOOD_STEP:1)
Block(-2,5,-2,WOOD_STAIRS:3)
Block(-1,5,-2,WOOD_STAIRS:3)
Block(0,5,-2,WOOD_STAIRS:3)
Block(1,5,-2,WOOD_STAIRS:5)
Block(2,5,-2,WOOD_STAIRS:4)
Block(3,5,-2,WOOD_STAIRS:1)
Block(-5,5,-1,COBBLE_WALL:0)
Block(-1,5,-1,COBBLE_WALL:0)
Block(0,5,-1,WOOD_STAIRS:0)
Block(1,5,-1,WOOD_STAIRS:5)
Block(2,5,-1,WOOD_STAIRS:4)
Block(3,5,-1,WOOD_STAIRS:1)
Block(4,5,-1,COBBLE_WALL:0)
Block(0,5,0,BIRCH_WOOD_STAIRS:0)
Block(1,5,0,WOOD_STAIRS:5)
Block(2,5,0,WOOD_STAIRS:4)
Block(3,5,0,WOOD_STAIRS:1)
Block(0,5,1,WOOD_STAIRS:0)
Block(1,5,1,WOOD_STAIRS:5)
Block(2,5,1,WOOD_STAIRS:4)
Block(3,5,1,WOOD_STEP:1)
Block(0,5,2,BIRCH_WOOD_STAIRS:0)
Block(1,5,2,WOOD_STAIRS:5)
Block(2,5,2,WOOD_STAIRS:4)
Block(3,5,2,WOOD_STEP:1)
Block(0,5,3,BIRCH_WOOD_STAIRS:0)
Block(1,5,3,WOOD_STAIRS:5)
Block(2,5,3,WOOD_STAIRS:4)
Block(3,5,3,WOOD_STEP:1)
Block(-1,5,4,COBBLE_WALL:0)
Block(0,5,4,WOOD_STAIRS:0)
Block(1,5,4,HARD_CLAY:0)
Block(2,5,4,HARD_CLAY:0)
Block(3,5,4,WOOD_STAIRS:1)
Block(4,5,4,COBBLE_WALL:0)
Block(0,5,5,WOOD_STAIRS:0)
Block(1,5,5,WOOD_STAIRS:5)
Block(2,5,5,WOOD_STAIRS:4)
Block(3,5,5,WOOD_STAIRS:1)
Block(1,6,-8,WOOD_STAIRS:0)
Block(2,6,-8,WOOD_STAIRS:1)
Block(1,6,-7,WOOD_STEP:0)
Block(2,6,-7,WOOD_STEP:0)
Block(1,6,-6,WOOD_STEP:0)
Block(2,6,-6,WOOD_STEP:0)
Block(-1,6,-5,ACACIA_FENCE:0)
Block(1,6,-5,WOOD_STAIRS:0)
Block(2,6,-5,WOOD_STAIRS:1)
Block(4,6,-5,ACACIA_FENCE:0)
Block(1,6,-4,WOOD_STAIRS:0)
Block(2,6,-4,WOOD_STAIRS:1)
Block(-6,6,-3,WOOD_STEP:0)
Block(-5,6,-3,WOOD_STEP:0)
Block(-2,6,-3,WOOD_STEP:1)
Block(-1,6,-3,WOOD_STEP:1)
Block(0,6,-3,WOOD_STEP:1)
Block(1,6,-3,WOOD_STAIRS:0)
Block(2,6,-3,WOOD_STAIRS:1)
Block(1,6,-2,WOOD_STEP:0)
Block(2,6,-2,WOOD_STAIRS:1)
Block(-1,6,-1,ACACIA_FENCE:0)
Block(1,6,-1,WOOD_STEP:0)
Block(2,6,-1,WOOD_STAIRS:1)
Block(4,6,-1,ACACIA_FENCE:0)
Block(1,6,0,WOOD_STEP:0)
Block(2,6,0,WOOD_STEP:0)
Block(1,6,1,WOOD_STEP:0)
Block(1,6,2,WOOD_STEP:0)
Block(1,6,3,WOOD_STEP:0)
Block(2,6,3,WOOD_STEP:0)
Block(1,6,4,WOOD_STAIRS:0)
Block(2,6,4,WOOD_STAIRS:1)
Block(1,6,5,WOOD_STAIRS:0)
Block(2,6,5,WOOD_STAIRS:1)
Block(-1,7,-5,TORCH:5)
Block(4,7,-5,TORCH:5)
Block(-1,7,-1,TORCH:5)
Block(4,7,-1,TORCH:5)
Entity(1,0,-6,minecraft:villager,1,../../NBT/entities/tribalteacher.txt)
Entity(0,0,-1,minecraft:villager,1,../../NBT/entities/tribalkid.txt)
Entity(2,0,-1,minecraft:villager,1,../../NBT/entities/tribalkid.txt)
Entity(2,0,2,minecraft:villager,1,../../NBT/entities/tribalkid.txt)
Entity(0,0,3,minecraft:villager,1,../../NBT/entities/tribalkid.txt)
