Author: NLBlackEagle
Description: No description given
SettingsMode: WriteDisable
Frequency: 0
SpawnHeight: highestBlock
UseCenterForHighestBlock: true
MinHeight: 0
MaxHeight: 256
InheritBO3: 
InheritBO3Rotation: NORTH
OverrideChildSettings: true
OverrideParentHeight: false
CanOverride: false
BranchFrequency: 0
BranchFrequencyGroup: 
MustBeBelowOther: false
MustBeInside: 
CannotBeInside: 
ReplacesBO3: 
MustBeInsideWorldBorders: false
CanSpawnOnWater: true
SpawnOnWaterOnly: false
SpawnUnderWater: false
SpawnAtWaterLevel: false
HeightOffset: 0
RemoveAir: true
ReplaceAbove: 
ReplaceBelow: 
ReplaceWithBiomeBlocks: true
ReplaceWithSurfaceBlock: GRASS
ReplaceWithGroundBlock: DIRT
ReplaceWithStoneBlock: STONE
SmoothRadius: 0
SmoothHeightOffset: 0
SmoothStartTop: false
SmoothStartWood: false
SmoothingSurfaceBlock: 
SmoothingGroundBlock: 
BO3Group: 
IsSpawnPoint: false
DoReplaceBlocks: true
Block(-8,0,-7,STONE:0)
Block(-8,0,-6,STONE:0)
Block(-8,0,-5,STONE:0)
Block(-8,0,-4,STONE:0)
Block(-8,0,-3,STONE:0)
Block(-8,0,-2,STONE:0)
Block(-8,0,-1,STONE:0)
Block(-8,0,0,STONE:0)
Block(-8,0,1,STONE:0)
Block(-8,0,2,STONE:0)
Block(-8,0,3,STONE:0)
Block(-8,0,4,STONE:0)
Block(-8,0,5,STONE:0)
Block(-8,0,6,STONE:0)
Block(-8,0,7,STONE:0)
Block(-8,0,8,STONE:0)
Block(-8,1,-7,STONE:0)
Block(-8,1,-6,STONE:0)
Block(-8,1,-5,STONE:0)
Block(-8,1,-4,STONE:0)
Block(-8,1,-3,STONE:0)
Block(-8,1,-2,STONE:0)
Block(-8,1,-1,STONE:0)
Block(-8,1,0,STONE:0)
Block(-8,1,1,STONE:0)
Block(-8,1,2,STONE:0)
Block(-8,1,3,STONE:0)
Block(-8,1,4,STONE:0)
Block(-8,1,5,STONE:0)
Block(-8,1,6,STONE:0)
Block(-8,1,7,STONE:0)
Block(-8,1,8,STONE:0)
Block(-8,2,-7,STONE:0)
Block(-8,2,-6,STONE:0)
Block(-8,2,-5,STONE:0)
Block(-8,2,-4,STONE:0)
Block(-8,2,-3,STONE:0)
Block(-8,2,-2,STONE:0)
Block(-8,2,-1,STONE:0)
Block(-8,2,0,STONE:0)
Block(-8,2,1,STONE:0)
Block(-8,2,2,STONE:0)
Block(-8,2,3,STONE:0)
Block(-8,2,4,STONE:0)
Block(-8,2,5,STONE:0)
Block(-8,2,6,STONE:0)
Block(-8,2,7,STONE:0)
Block(-8,2,8,STONE:0)
Block(-8,3,-7,STONE:0)
Block(-8,3,-6,STONE:0)
Block(-8,3,-5,STONE:0)
Block(-8,3,-4,STONE:0)
Block(-8,3,-3,STONE:0)
Block(-8,3,-2,STONE:0)
Block(-8,3,-1,STONE:0)
Block(-8,3,0,STONE:0)
Block(-8,3,1,STONE:0)
Block(-8,3,2,STONE:0)
Block(-8,3,3,STONE:0)
Block(-8,3,4,STONE:0)
Block(-8,3,5,STONE:0)
Block(-8,3,6,STONE:0)
Block(-8,3,7,STONE:0)
Block(-8,3,8,STONE:0)
Block(-8,4,-7,STONE:0)
Block(-8,4,-6,STONE:0)
Block(-8,4,-5,STONE:0)
Block(-8,4,-4,STONE:0)
Block(-8,4,-3,STONE:0)
Block(-8,4,-2,STONE:0)
Block(-8,4,-1,STONE:0)
Block(-8,4,0,STONE:0)
Block(-8,4,1,STONE:0)
Block(-8,4,2,STONE:0)
Block(-8,4,3,STONE:0)
Block(-8,4,4,STONE:0)
Block(-8,4,5,STONE:0)
Block(-8,4,6,STONE:0)
Block(-8,4,7,STONE:0)
Block(-8,4,8,STONE:0)
Block(-8,5,-7,STONE:0)
Block(-8,5,-6,STONE:0)
Block(-8,5,-5,STONE:0)
Block(-8,5,-4,STONE:0)
Block(-8,5,-3,STONE:0)
Block(-8,5,-2,STONE:0)
Block(-8,5,-1,STONE:0)
Block(-8,5,0,STONE:0)
Block(-8,5,1,STONE:0)
Block(-8,5,2,STONE:0)
Block(-8,5,3,STONE:0)
Block(-8,5,4,STONE:0)
Block(-8,5,5,STONE:0)
Block(-8,5,6,STONE:0)
Block(-8,5,7,STONE:0)
Block(-8,5,8,STONE:0)
Block(-8,6,-7,STONE:0)
Block(-8,6,-6,STONE:0)
Block(-8,6,-5,STONE:0)
Block(-8,6,-4,STONE:0)
Block(-8,6,-3,STONE:0)
Block(-8,6,-2,STONE:0)
Block(-8,6,-1,STONE:0)
Block(-8,6,0,STONE:0)
Block(-8,6,1,STONE:0)
Block(-8,6,2,STONE:0)
Block(-8,6,3,STONE:0)
Block(-8,6,4,STONE:0)
Block(-8,6,5,STONE:0)
Block(-8,6,6,STONE:0)
Block(-8,6,7,STONE:0)
Block(-8,6,8,STONE:0)
Block(-8,7,-7,STONE:0)
Block(-8,7,-6,STONE:0)
Block(-8,7,-5,STONE:0)
Block(-8,7,-4,STONE:0)
Block(-8,7,-3,STONE:0)
Block(-8,7,-2,STONE:0)
Block(-8,7,-1,STONE:0)
Block(-8,7,0,STONE:0)
Block(-8,7,1,STONE:0)
Block(-8,7,2,STONE:0)
Block(-8,7,3,STONE:0)
Block(-8,7,4,STONE:0)
Block(-8,7,5,STONE:0)
Block(-8,7,6,STONE:0)
Block(-8,7,7,STONE:0)
Block(-8,7,8,STONE:0)
Block(-8,8,-7,STONE:0)
Block(-8,8,-6,STONE:0)
Block(-8,8,-5,STONE:0)
Block(-8,8,-4,STONE:0)
Block(-8,8,-3,STONE:0)
Block(-8,8,-2,STONE:0)
Block(-8,8,-1,STONE:0)
Block(-8,8,0,STONE:0)
Block(-8,8,1,STONE:0)
Block(-8,8,2,STONE:0)
Block(-8,8,3,STONE:0)
Block(-8,8,4,STONE:0)
Block(-8,8,5,STONE:0)
Block(-8,8,6,STONE:0)
Block(-8,8,7,STONE:0)
Block(-8,8,8,STONE:0)
Block(-8,9,-7,STONE:0)
Block(-8,9,-6,STONE:0)
Block(-8,9,-5,STONE:0)
Block(-8,9,-4,STONE:0)
Block(-8,9,-3,STONE:0)
Block(-8,9,-2,STONE:0)
Block(-8,9,-1,STONE:0)
Block(-8,9,0,STONE:0)
Block(-8,9,1,STONE:0)
Block(-8,9,2,STONE:0)
Block(-8,9,3,STONE:0)
Block(-8,9,4,STONE:0)
Block(-8,9,5,STONE:0)
Block(-8,9,6,STONE:0)
Block(-8,9,7,STONE:0)
Block(-8,9,8,STONE:0)
Block(-8,10,-7,STONE:0)
Block(-8,10,-6,STONE:0)
Block(-8,10,-5,STONE:0)
Block(-8,10,-4,STONE:0)
Block(-8,10,-3,STONE:0)
Block(-8,10,-2,STONE:0)
Block(-8,10,-1,STONE:0)
Block(-8,10,0,STONE:0)
Block(-8,10,1,STONE:0)
Block(-8,10,2,STONE:0)
Block(-8,10,3,STONE:0)
Block(-8,10,4,STONE:0)
Block(-8,10,5,STONE:0)
Block(-8,10,6,STONE:0)
Block(-8,10,7,STONE:0)
Block(-8,10,8,STONE:0)
Block(-8,11,-7,STONE:0)
Block(-8,11,-6,STONE:0)
Block(-8,11,-5,STONE:0)
Block(-8,11,-4,STONE:0)
Block(-8,11,-3,STONE:0)
Block(-8,11,-2,STONE:0)
Block(-8,11,-1,STONE:0)
Block(-8,11,0,STONE:0)
Block(-8,11,1,STONE:0)
Block(-8,11,2,STONE:0)
Block(-8,11,3,STONE:0)
Block(-8,11,4,STONE:0)
Block(-8,11,5,STONE:0)
Block(-8,11,6,STONE:0)
Block(-8,11,7,STONE:0)
Block(-8,11,8,STONE:0)
Block(-8,12,-7,STONE:0)
Block(-8,12,-6,STONE:0)
Block(-8,12,-5,STONE:0)
Block(-8,12,-4,STONE:0)
Block(-8,12,-3,STONE:0)
Block(-8,12,-2,STONE:0)
Block(-8,12,-1,STONE:0)
Block(-8,12,0,STONE:0)
Block(-8,12,1,STONE:0)
Block(-8,12,2,STONE:0)
Block(-8,12,3,STONE:0)
Block(-8,12,4,STONE:0)
Block(-8,12,5,STONE:0)
Block(-8,12,6,STONE:0)
Block(-8,12,7,STONE:0)
Block(-8,12,8,STONE:0)
Block(-8,13,-7,STONE:0)
Block(-8,13,-6,STONE:0)
Block(-8,13,-5,STONE:0)
Block(-8,13,-4,STONE:0)
Block(-8,13,-3,STONE:0)
Block(-8,13,-2,STONE:0)
Block(-8,13,-1,STONE:0)
Block(-8,13,0,STONE:0)
Block(-8,13,1,STONE:0)
Block(-8,13,2,STONE:0)
Block(-8,13,3,STONE:0)
Block(-8,13,4,STONE:0)
Block(-8,13,5,STONE:0)
Block(-8,13,6,STONE:0)
Block(-8,13,7,STONE:0)
Block(-8,13,8,STONE:0)
Block(-8,14,-7,STONE:0)
Block(-8,14,-6,STONE:0)
Block(-8,14,-5,STONE:0)
Block(-8,14,-4,STONE:0)
Block(-8,14,-3,STONE:0)
Block(-8,14,-2,STONE:0)
Block(-8,14,-1,STONE:0)
Block(-8,14,0,STONE:0)
Block(-8,14,1,STONE:0)
Block(-8,14,2,STONE:0)
Block(-8,14,3,STONE:0)
Block(-8,14,4,STONE:0)
Block(-8,14,5,STONE:0)
Block(-8,14,6,STONE:0)
Block(-8,14,7,STONE:0)
Block(-8,14,8,STONE:0)
Block(-8,15,-7,STONE:0)
Block(-8,15,-6,STONE:0)
Block(-8,15,-5,STONE:0)
Block(-8,15,-4,STONE:0)
Block(-8,15,-3,STONE:0)
Block(-8,15,-2,STONE:0)
Block(-8,15,-1,STONE:0)
Block(-8,15,0,STONE:0)
Block(-8,15,1,STONE:0)
Block(-8,15,2,STONE:0)
Block(-8,15,3,STONE:0)
Block(-8,15,4,STONE:0)
Block(-8,15,5,STONE:0)
Block(-8,15,6,SMOOTH_BRICK:0)
Block(-8,15,7,STONE:0)
Block(-8,15,8,STONE:0)
Block(-8,16,-7,STONE:0)
Block(-8,16,-6,STONE:0)
Block(-8,16,-5,STONE:0)
Block(-8,16,-4,STONE:0)
Block(-8,16,-3,STONE:0)
Block(-8,16,-2,STONE:0)
Block(-8,16,-1,STONE:0)
Block(-8,16,0,STONE:0)
Block(-8,16,1,STONE:0)
Block(-8,16,2,STONE:0)
Block(-8,16,3,STONE:0)
Block(-8,16,4,STONE:0)
Block(-8,16,5,STONE:0)
Block(-8,16,6,REDSTONE_WIRE:0)
Block(-8,16,8,STONE:0)
Block(-8,17,-7,STONE:0)
Block(-8,17,-6,STONE:0)
Block(-8,17,-5,STONE:0)
Block(-8,17,-4,STONE:0)
Block(-8,17,-3,STONE:0)
Block(-8,17,-2,STONE:0)
Block(-8,17,-1,STONE:0)
Block(-8,17,0,STONE:0)
Block(-8,17,1,STONE:0)
Block(-8,17,2,STONE:0)
Block(-8,17,3,STONE:0)
Block(-8,17,4,STONE:0)
Block(-8,17,5,STONE:0)
Block(-8,17,8,STONE:0)
Block(-8,18,-7,STONE:0)
Block(-8,18,-6,STONE:0)
Block(-8,18,-5,STONE:0)
Block(-8,18,-4,MAGMA:0)
Block(-8,18,-3,MAGMA:0)
Block(-8,18,-2,STONE:0)
Block(-8,18,-1,STONE:0)
Block(-8,18,0,STONE:0)
Block(-8,18,1,STONE:0)
Block(-8,18,2,STONE:0)
Block(-8,18,3,REDSTONE_WIRE:0)
Block(-8,18,4,REDSTONE_WIRE:0)
Block(-8,18,6,PISTON_STICKY_BASE:9)
Block(-8,18,7,SMOOTH_BRICK:0)
Block(-8,18,8,SMOOTH_BRICK:0)
Block(-8,19,-7,CONCRETE:7)
Block(-8,19,-6,CONCRETE:7)
Block(-8,19,-5,CONCRETE:7)
Block(-8,19,-4,STAINED_GLASS:15)
Block(-8,19,-3,STAINED_GLASS:15)
Block(-8,19,-2,CONCRETE:7)
Block(-8,19,-1,CONCRETE:7)
Block(-8,19,0,CONCRETE:7)
Block(-8,19,1,CONCRETE:7)
Block(-8,19,2,CONCRETE:7)
Block(-8,19,3,CONCRETE:7)
Block(-8,19,4,CONCRETE:7)
Block(-8,19,5,CONCRETE:15)
Block(-8,19,6,PISTON_MOVING_PIECE:9)
Block(-8,19,7,REDSTONE_WIRE:8)
Block(-8,19,8,REDSTONE_WIRE:7)
Block(-8,20,-4,CARPET:14)
Block(-8,20,-3,CARPET:14)
Block(-8,20,0,CONCRETE:15)
Block(-8,20,1,STONE:3)
Block(-8,20,2,CONCRETE:7)
Block(-8,20,6,SMOOTH_STAIRS:2)
Block(-8,20,7,SMOOTH_BRICK:0)
Block(-8,20,8,PISTON_STICKY_BASE:1)
Block(-8,21,0,CONCRETE:15)
Block(-8,21,1,CONCRETE:7)
Block(-8,21,2,CONCRETE:7)
Block(-8,21,7,SMOOTH_BRICK:0)
Block(-8,21,8,SMOOTH_STAIRS:0)
Block(-8,22,0,CONCRETE:15)
Block(-8,22,1,REDSTONE_WIRE:0)
Block(-8,22,2,CONCRETE:7)
RandomBlock(-8,22,7,AIR:0,20,CHEST:4,../../../Chests/Loot/JunkChest_1.nbt,10,CHEST:4,../../../Chests/Loot/JunkChest_2.nbt,10,CHEST:4,../../../Chests/Loot/JunkChest_3.nbt,10,CHEST:4,../../../Chests/Loot/JunkChest_4.nbt,10,CHEST:4,../../../Chests/Loot/JunkChest_5.nbt,10,CHEST:4,../../../Chests/Lore/village_1.nbt,1,CHEST:4,../../../Chests/Lore/village_2.nbt,1,CHEST:4,../../../Chests/Lore/village_3.nbt,1,CHEST:4,../../../Chests/Lore/village_4.nbt,1,CHEST:4,../../../Chests/Lore/village_5.nbt,1,CHEST:4,../../../Chests/Loot/Common1.nbt,10,CHEST:4,../../../Chests/Loot/Common2.nbt,10,CHEST:4,../../../Chests/Loot/Common3.nbt,10,CHEST:4,../../../Chests/Loot/Common4.nbt,10,CHEST:4,../../../Chests/Loot/Common5.nbt,10,CHEST:4,../../../Chests/Loot/Common6.nbt,10,CHEST:4,../../../Chests/Loot/Common7.nbt,10,CHEST:4,../../../Chests/Loot/Common8.nbt,10,CHEST:4,../../../Chests/Loot/Common9.nbt,10,CHEST:4,../../../Chests/Loot/Common10.nbt,10,CHEST:4,../../../Chests/Loot/Common10.nbt,11,CHEST:4,../../../Chests/Loot/Common12.nbt,10,CHEST:4,../../../Chests/Loot/Common13.nbt,10,CHEST:4,../../../Chests/Loot/Common14.nbt,10,CHEST:4,../../../Chests/Loot/Common15.nbt,10,CHEST:4,../../../Chests/Lore/village_1.nbt,2,CHEST:4,../../../Chests/Lore/village_3.nbt,2,CHEST:4,../../../Chests/Lore/village_4.nbt,2,CHEST:4,../../../Chests/Lore/village_5.nbt,2,CHEST:4,../../../Chests/Lore/village_5.nbt,2,CHEST:4,../../../Chests/Loot/Rare1.nbt,5,CHEST:4,../../../Chests/Loot/Rare2.nbt,5,CHEST:4,../../../Chests/Loot/Rare3.nbt,5,CHEST:4,../../../Chests/Loot/Rare4.nbt,5,CHEST:4,../../../Chests/Loot/Rare5.nbt,5,CHEST:4,../../../Chests/Loot/Rare6.nbt,5,CHEST:4,../../../Chests/Loot/Rare7.nbt,5,CHEST:4,../../../Chests/Loot/Rare8.nbt,5,CHEST:4,../../../Chests/Loot/Rare9.nbt,5,CHEST:4,../../../Chests/Loot/Rare10.nbt,5,CHEST:4,../../../Chests/Loot/Rare11.nbt,5,CHEST:4,../../../Chests/Loot/Rare12.nbt,5,CHEST:4,../../../Chests/Loot/Rare13.nbt,5,CHEST:4,../../../Chests/Loot/Rare14.nbt,5,CHEST:4,../../../Chests/Loot/Rare15.nbt,5,CHEST:4,../../../Chests/Loot/Epic1.nbt,2,CHEST:4,../../../Chests/Loot/Epic2.nbt,2,CHEST:4,../../../Chests/Loot/Epic3.nbt,2,CHEST:4,../../../Chests/Loot/Epic4.nbt,2,CHEST:4,../../../Chests/Loot/Epic5.nbt,2,CHEST:4,../../../Chests/Loot/Epic6.nbt,2,CHEST:4,../../../Chests/Loot/Epic7.nbt,2,CHEST:4,../../../Chests/Loot/Epic8.nbt,2,CHEST:4,../../../Chests/Loot/Epic9.nbt,2,CHEST:4,../../../Chests/Loot/Epic10.nbt,2,CHEST:4,../../../Chests/Loot/Epic11.nbt,2,CHEST:4,../../../Chests/Loot/Epic12.nbt,2,CHEST:4,../../../Chests/Loot/Epic13.nbt,2,CHEST:4,../../../Chests/Loot/Epic14.nbt,2,CHEST:4,../../../Chests/Loot/Epic15.nbt,5,CHEST:4,../../../Chests/Loot/Rare1.nbt,5,CHEST:4,../../../Chests/Loot/Rare2.nbt,5,CHEST:4,../../../Chests/Loot/Rare3.nbt,5,CHEST:4,../../../Chests/Loot/Rare4.nbt,5,CHEST:4,../../../Chests/Loot/Rare5.nbt,10,CHEST:4,../../../Chests/Loot/Rare6.nbt,10,CHEST:4,../../../Chests/Loot/Rare7.nbt,10,CHEST:4,../../../Chests/Loot/Rare8.nbt,10,CHEST:4,../../../Chests/Loot/Rare9.nbt,10,CHEST:4,../../../Chests/Loot/Rare10.nbt,15,CHEST:4,../../../Chests/Loot/Rare11.nbt,15,CHEST:4,../../../Chests/Loot/Rare12.nbt,15,CHEST:4,../../../Chests/Loot/Rare13.nbt,15,CHEST:4,../../../Chests/Loot/Rare14.nbt,15,CHEST:4,../../../Chests/Loot/Rare15.nbt,15,CHEST:4,../../../Chests/Loot/Epic15.nbt,100)
Block(-8,23,0,CONCRETE:15)
Block(-8,23,1,STONE:3)
Block(-8,23,2,CONCRETE:7)
Block(-8,24,-7,CONCRETE:15)
Block(-8,24,0,CONCRETE:15)
Block(-8,24,1,STONE:3)
Block(-8,24,2,CONCRETE:7)
Block(-8,25,-7,CONCRETE:15)
Block(-8,25,0,CONCRETE:15)
Block(-8,25,1,STONE:3)
Block(-8,25,2,CONCRETE:7)
Block(-8,26,-7,CONCRETE:15)
Block(-8,26,0,CONCRETE:15)
Block(-8,26,1,STONE:3)
Block(-8,26,2,CONCRETE:7)
Block(-8,27,-7,STONE:0)
Block(-8,27,-6,SMOOTH_STAIRS:7)
Block(-8,27,-1,SMOOTH_STAIRS:6)
Block(-8,27,0,CONCRETE:7)
Block(-8,27,1,STONE:3)
Block(-8,27,2,CONCRETE:7)
Block(-8,28,-7,STONE:0)
Block(-8,28,-6,SMOOTH_BRICK:0)
Block(-8,28,-5,SMOOTH_BRICK:0)
Block(-8,28,-4,STEP:8)
Block(-8,28,-3,STEP:8)
Block(-8,28,-2,SMOOTH_BRICK:0)
Block(-8,28,-1,SMOOTH_BRICK:0)
Block(-8,28,0,SMOOTH_BRICK:0)
Block(-8,28,1,STONE:3)
Block(-8,28,2,CONCRETE:7)
Block(-8,29,-7,STONE:0)
Block(-8,29,-6,SMOOTH_BRICK:0)
Block(-8,29,-5,SMOOTH_BRICK:0)
Block(-8,29,-4,SMOOTH_BRICK:0)
Block(-8,29,-3,SMOOTH_BRICK:0)
Block(-8,29,-2,SMOOTH_BRICK:0)
Block(-8,29,-1,SMOOTH_BRICK:0)
Block(-8,29,0,STONE:3)
Block(-8,29,1,STONE:3)
Block(-8,29,2,SMOOTH_BRICK:0)
Block(-8,30,-7,STONE:0)
Block(-8,30,-6,STONE:0)
Block(-8,30,-5,STONE:0)
Block(-8,30,-4,STONE:0)
Block(-8,30,-3,STONE:0)
Block(-8,30,-2,STONE:0)
Block(-8,30,-1,SMOOTH_BRICK:0)
Block(-8,30,0,STONE:3)
Block(-8,30,1,STONE:3)
Block(-8,30,2,SMOOTH_BRICK:0)
Block(-8,30,5,STEP:8)
Block(-8,31,-7,STONE:0)
Block(-8,31,-6,STONE:0)
Block(-8,31,-5,STONE:0)
Block(-8,31,-4,STONE:0)
Block(-8,31,-3,STONE:0)
Block(-8,31,-2,STONE:0)
Block(-8,31,-1,STONE:0)
Block(-8,31,0,STONE:0)
Block(-8,31,1,STONE:0)
Block(-8,31,2,STONE:0)
Block(-8,31,3,SMOOTH_BRICK:0)
Block(-8,31,4,SMOOTH_BRICK:0)
Block(-8,31,5,SMOOTH_BRICK:0)
Block(-8,31,6,SMOOTH_STAIRS:7)
Block(-8,32,-7,STONE:0)
Block(-8,32,-6,STONE:0)
Block(-8,32,-5,STONE:0)
Block(-8,32,-4,STONE:0)
Block(-8,32,-3,STONE:0)
Block(-8,32,-2,STONE:0)
Block(-8,32,-1,STONE:0)
Block(-8,32,0,STONE:0)
Block(-8,32,1,SMOOTH_BRICK:0)
Block(-8,32,2,SMOOTH_BRICK:0)
Block(-8,32,3,SMOOTH_BRICK:0)
Block(-8,32,4,SMOOTH_BRICK:0)
Block(-8,32,5,STATIONARY_LAVA:0)
Block(-8,32,6,COBBLE_WALL:0)
Block(-8,33,-7,STONE:0)
Block(-8,33,-6,STONE:0)
Block(-8,33,-5,STONE:0)
Block(-8,33,-4,STONE:0)
Block(-8,33,-3,STONE:0)
Block(-8,33,-2,STONE:0)
Block(-8,33,-1,STONE:0)
Block(-8,33,0,STONE:0)
Block(-8,33,1,DIODE_BLOCK_ON:3)
Block(-8,33,2,SMOOTH_BRICK:0)
Block(-8,33,3,SMOOTH_BRICK:0)
Block(-8,33,4,SMOOTH_BRICK:0)
Block(-8,33,5,SMOOTH_BRICK:0)
Block(-8,33,6,CONCRETE:7)
Block(-8,34,-7,STONE:0)
Block(-8,34,-6,STONE:0)
Block(-8,34,-5,STONE:0)
Block(-8,34,-4,STONE:0)
Block(-8,34,-3,STONE:0)
Block(-8,34,-2,STONE:0)
Block(-8,34,-1,STONE:0)
Block(-8,34,0,STONE:0)
Block(-8,34,1,SMOOTH_BRICK:0)
Block(-8,34,2,SMOOTH_BRICK:0)
Block(-8,34,3,SMOOTH_BRICK:0)
Block(-8,34,4,SMOOTH_BRICK:0)
Block(-8,34,5,SMOOTH_BRICK:0)
Block(-8,34,6,CONCRETE:7)
Block(-8,34,7,CONCRETE:7)
Block(-8,34,8,CONCRETE:7)
Block(-8,35,-7,STONE:0)
Block(-8,35,-6,STONE:0)
Block(-8,35,-5,STONE:0)
Block(-8,35,-4,STONE:0)
Block(-8,35,-3,STONE:0)
Block(-8,35,-2,STONE:0)
Block(-8,35,-1,STONE:0)
Block(-8,35,0,STONE:0)
Block(-8,35,1,SMOOTH_BRICK:0)
Block(-8,35,2,SMOOTH_BRICK:0)
Block(-8,35,3,SMOOTH_BRICK:0)
Block(-8,35,4,SMOOTH_BRICK:0)
Block(-8,35,5,SMOOTH_BRICK:0)
Block(-8,35,6,CONCRETE:7)
Block(-8,35,7,CONCRETE:7)
Block(-8,35,8,CONCRETE:7)
Block(-8,36,-7,DIRT:0)
Block(-8,36,-6,DIRT:0)
Block(-8,36,-5,DIRT:0)
Block(-8,36,-4,DIRT:0)
Block(-8,36,-3,DIRT:0)
Block(-8,36,-2,DIRT:0)
Block(-8,36,-1,DIRT:0)
Block(-8,36,0,DIRT:0)
Block(-8,36,1,DIRT:0)
Block(-8,36,2,DIRT:0)
Block(-8,36,3,DIRT:0)
Block(-8,36,4,DIRT:0)
Block(-8,36,5,DIRT:0)
Block(-8,36,6,DIRT:0)
Block(-8,36,7,DIRT:0)
Block(-8,36,8,DIRT:0)
Block(-8,37,-7,DIRT:0)
Block(-8,37,-6,DIRT:0)
Block(-8,37,-5,DIRT:0)
Block(-8,37,-4,DIRT:0)
Block(-8,37,-3,DIRT:0)
Block(-8,37,-2,DIRT:0)
Block(-8,37,-1,DIRT:0)
Block(-8,37,0,DIRT:0)
Block(-8,37,1,DIRT:0)
Block(-8,37,2,DIRT:0)
Block(-8,37,3,DIRT:0)
Block(-8,37,4,DIRT:0)
Block(-8,37,5,DIRT:0)
Block(-8,37,6,DIRT:0)
Block(-8,37,7,DIRT:0)
Block(-8,37,8,DIRT:0)
Block(-8,38,-7,DIRT:0)
Block(-8,38,-6,DIRT:0)
Block(-8,38,-5,DIRT:0)
Block(-8,38,-4,DIRT:0)
Block(-8,38,-3,DIRT:0)
Block(-8,38,-2,DIRT:0)
Block(-8,38,-1,DIRT:0)
Block(-8,38,0,DIRT:0)
Block(-8,38,1,DIRT:0)
Block(-8,38,2,DIRT:0)
Block(-8,38,3,DIRT:0)
Block(-8,38,4,DIRT:0)
Block(-8,38,5,DIRT:0)
Block(-8,38,6,DIRT:0)
Block(-8,38,7,DIRT:0)
Block(-8,38,8,DIRT:0)
Block(-8,39,-7,GRASS:0)
Block(-8,39,-6,GRASS:0)
Block(-8,39,-5,DIRT:0)
Block(-8,39,-4,DIRT:0)
Block(-8,39,-3,SMOOTH_BRICK:0)
Block(-8,39,-2,SMOOTH_BRICK:0)
Block(-8,39,-1,SMOOTH_BRICK:0)
Block(-8,39,0,DOUBLE_STEP:3)
Block(-8,39,1,GRASS:0)
Block(-8,39,2,GRASS:0)
Block(-8,39,3,GRASS:0)
Block(-8,39,4,SMOOTH_BRICK:0)
Block(-8,39,5,GRASS_PATH:0)
Block(-8,39,6,GRASS:0)
Block(-8,39,7,GRAVEL:0)
Block(-8,39,8,GRASS_PATH:0)
Block(-8,40,-7,DARK_OAK_FENCE:0)
Entity(-8,40,-5,CHICKEN,1)
Entity(-8,40,-4,CHICKEN,1)
Block(-8,40,1,LONG_GRASS:1)
Block(-8,40,2,LONG_GRASS:1)
Block(-8,51,-1,LEAVES:0)
Block(-8,52,-2,LEAVES:0)
Block(-8,52,-1,LEAVES:0)
Block(-8,52,0,LEAVES:0)
Block(-8,53,-1,LEAVES:0)
Block(-7,0,-7,STONE:0)
Block(-7,0,-6,STONE:0)
Block(-7,0,-5,STONE:0)
Block(-7,0,-4,STONE:0)
Block(-7,0,-3,STONE:0)
Block(-7,0,-2,STONE:0)
Block(-7,0,-1,STONE:0)
Block(-7,0,0,STONE:0)
Block(-7,0,1,STONE:0)
Block(-7,0,2,STONE:0)
Block(-7,0,3,STONE:0)
Block(-7,0,4,STONE:0)
Block(-7,0,5,STONE:0)
Block(-7,0,6,STONE:0)
Block(-7,0,7,STONE:0)
Block(-7,0,8,STONE:0)
Block(-7,1,-7,STONE:0)
Block(-7,1,-6,STONE:0)
Block(-7,1,-5,STONE:0)
Block(-7,1,-4,STONE:0)
Block(-7,1,-3,STONE:0)
Block(-7,1,-2,STONE:0)
Block(-7,1,-1,STONE:0)
Block(-7,1,0,STONE:0)
Block(-7,1,1,STONE:0)
Block(-7,1,2,STONE:0)
Block(-7,1,3,STONE:0)
Block(-7,1,4,STONE:0)
Block(-7,1,5,STONE:0)
Block(-7,1,6,STONE:0)
Block(-7,1,7,STONE:0)
Block(-7,1,8,STONE:0)
Block(-7,2,-7,STONE:0)
Block(-7,2,-6,STONE:0)
Block(-7,2,-5,STONE:0)
Block(-7,2,-4,STONE:0)
Block(-7,2,-3,STONE:0)
Block(-7,2,-2,STONE:0)
Block(-7,2,-1,STONE:0)
Block(-7,2,0,STONE:0)
Block(-7,2,1,STONE:0)
Block(-7,2,2,STONE:0)
Block(-7,2,3,STONE:0)
Block(-7,2,4,STONE:0)
Block(-7,2,5,STONE:0)
Block(-7,2,6,STONE:0)
Block(-7,2,7,STONE:0)
Block(-7,2,8,STONE:0)
Block(-7,3,-7,STONE:0)
Block(-7,3,-6,STONE:0)
Block(-7,3,-5,STONE:0)
Block(-7,3,-4,STONE:0)
Block(-7,3,-3,STONE:0)
Block(-7,3,-2,STONE:0)
Block(-7,3,-1,STONE:0)
Block(-7,3,0,STONE:0)
Block(-7,3,1,STONE:0)
Block(-7,3,2,STONE:0)
Block(-7,3,3,STONE:0)
Block(-7,3,4,STONE:0)
Block(-7,3,5,STONE:0)
Block(-7,3,6,STONE:0)
Block(-7,3,7,STONE:0)
Block(-7,3,8,STONE:0)
Block(-7,4,-7,STONE:0)
Block(-7,4,-6,STONE:0)
Block(-7,4,-5,STONE:0)
Block(-7,4,-4,STONE:0)
Block(-7,4,-3,STONE:0)
Block(-7,4,-2,STONE:0)
Block(-7,4,-1,STONE:0)
Block(-7,4,0,STONE:0)
Block(-7,4,1,STONE:0)
Block(-7,4,2,STONE:0)
Block(-7,4,3,STONE:0)
Block(-7,4,4,STONE:0)
Block(-7,4,5,STONE:0)
Block(-7,4,6,STONE:0)
Block(-7,4,7,STONE:0)
Block(-7,4,8,STONE:0)
Block(-7,5,-7,STONE:0)
Block(-7,5,-6,STONE:0)
Block(-7,5,-5,STONE:0)
Block(-7,5,-4,STONE:0)
Block(-7,5,-3,STONE:0)
Block(-7,5,-2,STONE:0)
Block(-7,5,-1,STONE:0)
Block(-7,5,0,STONE:0)
Block(-7,5,1,STONE:0)
Block(-7,5,2,STONE:0)
Block(-7,5,3,STONE:0)
Block(-7,5,4,STONE:0)
Block(-7,5,5,STONE:0)
Block(-7,5,6,STONE:0)
Block(-7,5,7,STONE:0)
Block(-7,5,8,STONE:0)
Block(-7,6,-7,STONE:0)
Block(-7,6,-6,STONE:0)
Block(-7,6,-5,STONE:0)
Block(-7,6,-4,STONE:0)
Block(-7,6,-3,STONE:0)
Block(-7,6,-2,STONE:0)
Block(-7,6,-1,STONE:0)
Block(-7,6,0,STONE:0)
Block(-7,6,1,STONE:0)
Block(-7,6,2,STONE:0)
Block(-7,6,3,STONE:0)
Block(-7,6,4,STONE:0)
Block(-7,6,5,STONE:0)
Block(-7,6,6,STONE:0)
Block(-7,6,7,STONE:0)
Block(-7,6,8,STONE:0)
Block(-7,7,-7,STONE:0)
Block(-7,7,-6,STONE:0)
Block(-7,7,-5,STONE:0)
Block(-7,7,-4,STONE:0)
Block(-7,7,-3,STONE:0)
Block(-7,7,-2,STONE:0)
Block(-7,7,-1,STONE:0)
Block(-7,7,0,STONE:0)
Block(-7,7,1,STONE:0)
Block(-7,7,2,STONE:0)
Block(-7,7,3,STONE:0)
Block(-7,7,4,STONE:0)
Block(-7,7,5,STONE:0)
Block(-7,7,6,STONE:0)
Block(-7,7,7,STONE:0)
Block(-7,7,8,STONE:0)
Block(-7,8,-7,STONE:0)
Block(-7,8,-6,STONE:0)
Block(-7,8,-5,STONE:0)
Block(-7,8,-4,STONE:0)
Block(-7,8,-3,STONE:0)
Block(-7,8,-2,STONE:0)
Block(-7,8,-1,STONE:0)
Block(-7,8,0,STONE:0)
Block(-7,8,1,STONE:0)
Block(-7,8,2,STONE:0)
Block(-7,8,3,STONE:0)
Block(-7,8,4,STONE:0)
Block(-7,8,5,STONE:0)
Block(-7,8,6,STONE:0)
Block(-7,8,7,STONE:0)
Block(-7,8,8,STONE:0)
Block(-7,9,-7,STONE:0)
Block(-7,9,-6,STONE:0)
Block(-7,9,-5,STONE:0)
Block(-7,9,-4,STONE:0)
Block(-7,9,-3,STONE:0)
Block(-7,9,-2,STONE:0)
Block(-7,9,-1,STONE:0)
Block(-7,9,0,STONE:0)
Block(-7,9,1,STONE:0)
Block(-7,9,2,STONE:0)
Block(-7,9,3,STONE:0)
Block(-7,9,4,STONE:0)
Block(-7,9,5,STONE:0)
Block(-7,9,6,STONE:0)
Block(-7,9,7,STONE:0)
Block(-7,9,8,STONE:0)
Block(-7,10,-7,STONE:0)
Block(-7,10,-6,STONE:0)
Block(-7,10,-5,STONE:0)
Block(-7,10,-4,STONE:0)
Block(-7,10,-3,STONE:0)
Block(-7,10,-2,STONE:0)
Block(-7,10,-1,STONE:0)
Block(-7,10,0,STONE:0)
Block(-7,10,1,STONE:0)
Block(-7,10,2,STONE:0)
Block(-7,10,3,STONE:0)
Block(-7,10,4,STONE:0)
Block(-7,10,5,STONE:0)
Block(-7,10,6,STONE:0)
Block(-7,10,7,STONE:0)
Block(-7,10,8,STONE:0)
Block(-7,11,-7,STONE:0)
Block(-7,11,-6,STONE:0)
Block(-7,11,-5,STONE:0)
Block(-7,11,-4,STONE:0)
Block(-7,11,-3,STONE:0)
Block(-7,11,-2,STONE:0)
Block(-7,11,-1,STONE:0)
Block(-7,11,0,STONE:0)
Block(-7,11,1,STONE:0)
Block(-7,11,2,STONE:0)
Block(-7,11,3,STONE:0)
Block(-7,11,4,STONE:0)
Block(-7,11,5,STONE:0)
Block(-7,11,6,STONE:0)
Block(-7,11,7,STONE:0)
Block(-7,11,8,STONE:0)
Block(-7,12,-7,STONE:0)
Block(-7,12,-6,STONE:0)
Block(-7,12,-5,STONE:0)
Block(-7,12,-4,STONE:0)
Block(-7,12,-3,STONE:0)
Block(-7,12,-2,STONE:0)
Block(-7,12,-1,STONE:0)
Block(-7,12,0,STONE:0)
Block(-7,12,1,STONE:0)
Block(-7,12,2,STONE:0)
Block(-7,12,3,STONE:0)
Block(-7,12,4,STONE:0)
Block(-7,12,5,STONE:0)
Block(-7,12,6,STONE:0)
Block(-7,12,7,STONE:0)
Block(-7,12,8,STONE:0)
Block(-7,13,-7,STONE:0)
Block(-7,13,-6,STONE:0)
Block(-7,13,-5,STONE:0)
Block(-7,13,-4,STONE:0)
Block(-7,13,-3,STONE:0)
Block(-7,13,-2,STONE:0)
Block(-7,13,-1,STONE:0)
Block(-7,13,0,STONE:0)
Block(-7,13,1,STONE:0)
Block(-7,13,2,STONE:0)
Block(-7,13,3,STONE:0)
Block(-7,13,4,STONE:0)
Block(-7,13,5,STONE:0)
Block(-7,13,6,STONE:0)
Block(-7,13,7,STONE:0)
Block(-7,13,8,STONE:0)
Block(-7,14,-7,STONE:0)
Block(-7,14,-6,STONE:0)
Block(-7,14,-5,STONE:0)
Block(-7,14,-4,STONE:0)
Block(-7,14,-3,STONE:0)
Block(-7,14,-2,STONE:0)
Block(-7,14,-1,STONE:0)
Block(-7,14,0,STONE:0)
Block(-7,14,1,STONE:0)
Block(-7,14,2,STONE:0)
Block(-7,14,3,STONE:0)
Block(-7,14,4,STONE:0)
Block(-7,14,5,STONE:0)
Block(-7,14,6,STONE:0)
Block(-7,14,7,STONE:0)
Block(-7,14,8,STONE:0)
Block(-7,15,-7,STONE:0)
Block(-7,15,-6,STONE:0)
Block(-7,15,-5,STONE:0)
Block(-7,15,-4,STONE:0)
Block(-7,15,-3,STONE:0)
Block(-7,15,-2,STONE:0)
Block(-7,15,-1,STONE:0)
Block(-7,15,0,STONE:0)
Block(-7,15,1,STONE:0)
Block(-7,15,2,STONE:0)
Block(-7,15,3,STONE:0)
Block(-7,15,4,STONE:0)
Block(-7,15,5,STONE:0)
Block(-7,15,6,SMOOTH_BRICK:0)
Block(-7,15,7,STONE:0)
Block(-7,15,8,REDSTONE_WIRE:0)
Block(-7,16,-7,STONE:0)
Block(-7,16,-6,STONE:0)
Block(-7,16,-5,STONE:0)
Block(-7,16,-4,STONE:0)
Block(-7,16,-3,STONE:0)
Block(-7,16,-2,STONE:0)
Block(-7,16,-1,STONE:0)
Block(-7,16,0,STONE:0)
Block(-7,16,1,STONE:0)
Block(-7,16,2,STONE:0)
Block(-7,16,3,STONE:0)
Block(-7,16,4,STONE:0)
Block(-7,16,5,STONE:0)
Block(-7,16,6,REDSTONE_WIRE:0)
Block(-7,16,7,SMOOTH_BRICK:0)
Block(-7,16,8,SMOOTH_BRICK:0)
Block(-7,17,-7,STONE:0)
Block(-7,17,-6,STONE:0)
Block(-7,17,-5,STONE:0)
Block(-7,17,-4,STONE:0)
Block(-7,17,-3,STONE:0)
Block(-7,17,-2,STONE:0)
Block(-7,17,-1,STONE:0)
Block(-7,17,0,STONE:0)
Block(-7,17,1,STONE:0)
Block(-7,17,2,STONE:0)
Block(-7,17,3,STONE:0)
Block(-7,17,4,STONE:0)
Block(-7,17,5,STONE:0)
Block(-7,17,7,SMOOTH_BRICK:0)
Block(-7,18,-7,STONE:0)
Block(-7,18,-6,STONE:0)
Block(-7,18,-5,STONE:0)
Block(-7,18,-4,MAGMA:0)
Block(-7,18,-3,MAGMA:0)
Block(-7,18,-2,STONE:0)
Block(-7,18,-1,STONE:0)
Block(-7,18,0,STONE:0)
Block(-7,18,1,STONE:0)
Block(-7,18,2,STONE:0)
Block(-7,18,3,REDSTONE_WIRE:0)
Block(-7,18,4,REDSTONE_WIRE:0)
Block(-7,18,6,PISTON_STICKY_BASE:9)
Block(-7,18,7,SMOOTH_BRICK:0)
Block(-7,18,8,SMOOTH_BRICK:0)
Block(-7,19,-7,CONCRETE:7)
Block(-7,19,-6,CONCRETE:7)
Block(-7,19,-5,CONCRETE:7)
Block(-7,19,-4,STAINED_GLASS:15)
Block(-7,19,-3,STAINED_GLASS:15)
Block(-7,19,-2,CONCRETE:7)
Block(-7,19,-1,CONCRETE:7)
Block(-7,19,0,CONCRETE:7)
Block(-7,19,1,CONCRETE:7)
Block(-7,19,2,CONCRETE:7)
Block(-7,19,3,CONCRETE:7)
Block(-7,19,4,CONCRETE:7)
Block(-7,19,5,CONCRETE:15)
Block(-7,19,6,PISTON_MOVING_PIECE:9)
Block(-7,19,7,REDSTONE_WIRE:9)
Block(-7,20,-4,CARPET:14)
Block(-7,20,-3,CARPET:14)
Block(-7,20,0,CONCRETE:15)
Block(-7,20,1,STONE:3)
Block(-7,20,2,CONCRETE:7)
Block(-7,20,3,COBBLE_WALL:0)
Block(-7,20,6,SMOOTH_STAIRS:2)
Block(-7,20,7,PISTON_STICKY_BASE:1)
Block(-7,20,8,SMOOTH_BRICK:0)
Block(-7,21,0,CONCRETE:15)
Block(-7,21,1,CONCRETE:7)
Block(-7,21,2,CONCRETE:15)
Block(-7,21,3,TORCH:5)
Block(-7,21,7,SMOOTH_STAIRS:2)
Block(-7,21,8,REDSTONE_WIRE:0)
Block(-7,22,0,CONCRETE:15)
Block(-7,22,1,REDSTONE_WIRE:0)
Block(-7,22,2,SMOOTH_STAIRS:3)
Block(-7,22,8,STEP:0)
Block(-7,23,0,CONCRETE:15)
Block(-7,23,1,STONE:3)
Block(-7,24,-7,CONCRETE:15)
Block(-7,24,0,CONCRETE:15)
Block(-7,24,1,STONE:3)
Block(-7,25,-7,CONCRETE:15)
Block(-7,25,0,CONCRETE:15)
Block(-7,25,1,STONE:3)
Block(-7,26,-7,CONCRETE:15)
Block(-7,26,0,CONCRETE:15)
Block(-7,26,1,STONE:3)
Block(-7,26,2,WALL_BANNER:3,../NBT/DaerocVillage/1120-bannerC208R176.nbt)
Block(-7,27,-7,STONE:0)
Block(-7,27,-6,SMOOTH_STAIRS:7)
Block(-7,27,-1,SMOOTH_STAIRS:6)
Block(-7,27,0,CONCRETE:7)
Block(-7,27,1,STONE:3)
Block(-7,28,-7,STONE:0)
Block(-7,28,-6,SMOOTH_BRICK:0)
Block(-7,28,-5,SMOOTH_BRICK:0)
Block(-7,28,-4,STEP:8)
Block(-7,28,-3,STEP:8)
Block(-7,28,-2,SMOOTH_BRICK:0)
Block(-7,28,-1,SMOOTH_BRICK:0)
Block(-7,28,0,SMOOTH_BRICK:0)
Block(-7,28,1,STONE:3)
Block(-7,28,2,SMOOTH_STAIRS:7)
Block(-7,29,-7,STONE:0)
Block(-7,29,-6,SMOOTH_BRICK:0)
Block(-7,29,-5,SMOOTH_BRICK:0)
Block(-7,29,-4,SMOOTH_BRICK:0)
Block(-7,29,-3,SMOOTH_BRICK:0)
Block(-7,29,-2,SMOOTH_BRICK:0)
Block(-7,29,-1,SMOOTH_BRICK:0)
Block(-7,29,0,STONE:3)
Block(-7,29,1,STONE:3)
Block(-7,29,2,SMOOTH_BRICK:0)
Block(-7,29,3,SMOOTH_STAIRS:7)
Block(-7,30,-7,STONE:0)
Block(-7,30,-6,STONE:0)
Block(-7,30,-5,STONE:0)
Block(-7,30,-4,STONE:0)
Block(-7,30,-3,STONE:0)
Block(-7,30,-2,STONE:0)
Block(-7,30,-1,SMOOTH_BRICK:0)
Block(-7,30,0,STONE:3)
Block(-7,30,1,PISTON_STICKY_BASE:11)
Block(-7,30,2,PISTON_MOVING_PIECE:11)
Block(-7,30,3,CONCRETE:15)
Block(-7,30,5,STEP:8)
Block(-7,31,-7,STONE:0)
Block(-7,31,-6,STONE:0)
Block(-7,31,-5,STONE:0)
Block(-7,31,-4,STONE:0)
Block(-7,31,-3,STONE:0)
Block(-7,31,-2,STONE:0)
Block(-7,31,-1,STONE:0)
Block(-7,31,0,STONE:0)
Block(-7,31,1,PISTON_STICKY_BASE:11)
Block(-7,31,2,PISTON_MOVING_PIECE:11)
Block(-7,31,3,SMOOTH_BRICK:0)
Block(-7,31,4,CONCRETE:7)
Block(-7,31,5,CONCRETE:7)
Block(-7,31,6,SMOOTH_STAIRS:7)
Block(-7,32,-7,STONE:0)
Block(-7,32,-6,STONE:0)
Block(-7,32,-5,STONE:0)
Block(-7,32,-4,STONE:0)
Block(-7,32,-3,STONE:0)
Block(-7,32,-2,STONE:0)
Block(-7,32,-1,STONE:0)
Block(-7,32,0,STONE:0)
Block(-7,32,1,SMOOTH_BRICK:0)
Block(-7,32,2,SMOOTH_BRICK:0)
Block(-7,32,3,STATIONARY_LAVA:8)
Block(-7,32,4,SMOOTH_BRICK:0)
Block(-7,32,5,STATIONARY_LAVA:0)
Block(-7,32,6,CONCRETE:15)
Block(-7,33,-7,STONE:0)
Block(-7,33,-6,STONE:0)
Block(-7,33,-5,STONE:0)
Block(-7,33,-4,STONE:0)
Block(-7,33,-3,STONE:0)
Block(-7,33,-2,STONE:0)
Block(-7,33,-1,STONE:0)
Block(-7,33,0,STONE:0)
Block(-7,33,1,REDSTONE_WIRE:15)
Block(-7,33,2,SMOOTH_BRICK:0)
Block(-7,33,3,STATIONARY_LAVA:0)
Block(-7,33,4,SMOOTH_BRICK:0)
Block(-7,33,5,SMOOTH_BRICK:0)
Block(-7,33,6,CONCRETE:7)
Block(-7,34,-7,STONE:0)
Block(-7,34,-6,STONE:0)
Block(-7,34,-5,STONE:0)
Block(-7,34,-4,STONE:0)
Block(-7,34,-3,STONE:0)
Block(-7,34,-2,STONE:0)
Block(-7,34,-1,STONE:0)
Block(-7,34,0,STONE:0)
Block(-7,34,1,SMOOTH_BRICK:0)
Block(-7,34,2,SMOOTH_BRICK:0)
Block(-7,34,3,SMOOTH_BRICK:0)
Block(-7,34,4,SMOOTH_BRICK:0)
Block(-7,34,5,SMOOTH_BRICK:0)
Block(-7,34,6,CONCRETE:7)
Block(-7,34,7,CONCRETE:7)
Block(-7,34,8,CONCRETE:7)
Block(-7,35,-7,STONE:0)
Block(-7,35,-6,STONE:0)
Block(-7,35,-5,STONE:0)
Block(-7,35,-4,STONE:0)
Block(-7,35,-3,STONE:0)
Block(-7,35,-2,STONE:0)
Block(-7,35,-1,STONE:0)
Block(-7,35,0,STONE:0)
Block(-7,35,1,SMOOTH_BRICK:0)
Block(-7,35,2,SMOOTH_BRICK:0)
Block(-7,35,3,SMOOTH_BRICK:0)
Block(-7,35,4,SMOOTH_BRICK:0)
Block(-7,35,5,SMOOTH_BRICK:0)
Block(-7,35,6,CONCRETE:7)
Block(-7,35,7,CONCRETE:7)
Block(-7,35,8,CONCRETE:7)
Block(-7,36,-7,DIRT:0)
Block(-7,36,-6,DIRT:0)
Block(-7,36,-5,DIRT:0)
Block(-7,36,-4,DIRT:0)
Block(-7,36,-3,DIRT:0)
Block(-7,36,-2,DIRT:0)
Block(-7,36,-1,DIRT:0)
Block(-7,36,0,DIRT:0)
Block(-7,36,1,DIRT:0)
Block(-7,36,2,DIRT:0)
Block(-7,36,3,DIRT:0)
Block(-7,36,4,DIRT:0)
Block(-7,36,5,DIRT:0)
Block(-7,36,6,DIRT:0)
Block(-7,36,7,DIRT:0)
Block(-7,36,8,DIRT:0)
Block(-7,37,-7,DIRT:0)
Block(-7,37,-6,DIRT:0)
Block(-7,37,-5,DIRT:0)
Block(-7,37,-4,DIRT:0)
Block(-7,37,-3,DIRT:0)
Block(-7,37,-2,DIRT:0)
Block(-7,37,-1,DIRT:0)
Block(-7,37,0,DIRT:0)
Block(-7,37,1,DIRT:0)
Block(-7,37,2,DIRT:0)
Block(-7,37,3,DIRT:0)
Block(-7,37,4,DIRT:0)
Block(-7,37,5,DIRT:0)
Block(-7,37,6,DIRT:0)
Block(-7,37,7,DIRT:0)
Block(-7,37,8,DIRT:0)
Block(-7,38,-7,DIRT:0)
Block(-7,38,-6,DIRT:0)
Block(-7,38,-5,DIRT:0)
Block(-7,38,-4,DIRT:0)
Block(-7,38,-3,DIRT:0)
Block(-7,38,-2,DIRT:0)
Block(-7,38,-1,DIRT:0)
Block(-7,38,0,DIRT:0)
Block(-7,38,1,DIRT:0)
Block(-7,38,2,DIRT:0)
Block(-7,38,3,DIRT:0)
Block(-7,38,4,DIRT:0)
Block(-7,38,5,DIRT:0)
Block(-7,38,6,DIRT:0)
Block(-7,38,7,DIRT:0)
Block(-7,38,8,DIRT:0)
Block(-7,39,-7,GRASS:0)
Block(-7,39,-6,GRASS:0)
Block(-7,39,-5,GRASS:0)
Block(-7,39,-4,GRASS:0)
Block(-7,39,-3,COBBLESTONE_STAIRS:3)
Block(-7,39,-2,GRASS:0)
Block(-7,39,-1,STONE:5)
Block(-7,39,0,GRASS:0)
Block(-7,39,1,COBBLESTONE_STAIRS:1)
Block(-7,39,2,DOUBLE_STEP:3)
Block(-7,39,3,STONE:6)
Block(-7,39,4,GRASS:0)
Block(-7,39,5,STONE:6)
Block(-7,39,6,STONE:6)
Block(-7,39,7,GRAVEL:0)
Block(-7,39,8,GRASS:0)
Block(-7,40,-7,DARK_OAK_FENCE:0)
Block(-7,40,-6,DARK_OAK_FENCE:0)
Block(-7,40,-5,DARK_OAK_FENCE:0)
Block(-7,40,-4,DARK_OAK_FENCE:0)
Block(-7,40,-2,LONG_GRASS:1)
Block(-7,40,0,LONG_GRASS:1)
Block(-7,51,-2,LEAVES:0)
Block(-7,51,-1,LOG_2:13)
Block(-7,51,0,LEAVES:0)
Block(-7,52,-2,LEAVES:0)
Block(-7,52,-1,LOG_2:13)
Block(-7,52,0,LEAVES:0)
Block(-7,52,1,LEAVES:0)
Block(-7,53,-3,LEAVES:0)
Block(-7,53,-2,LEAVES:0)
Block(-7,53,-1,LEAVES:0)
Block(-7,53,0,LEAVES:0)
Block(-7,53,1,LEAVES:0)
Block(-7,53,2,LEAVES:0)
Block(-7,54,-2,LEAVES:0)
Block(-7,54,0,LEAVES:0)
Block(-7,54,1,LEAVES:0)
Block(-7,55,0,LEAVES:0)
Block(-7,55,2,LEAVES:0)
Block(-7,56,-1,LEAVES:0)
Block(-6,0,-7,STONE:0)
Block(-6,0,-6,STONE:0)
Block(-6,0,-5,STONE:0)
Block(-6,0,-4,STONE:0)
Block(-6,0,-3,STONE:0)
Block(-6,0,-2,STONE:0)
Block(-6,0,-1,STONE:0)
Block(-6,0,0,STONE:0)
Block(-6,0,1,STONE:0)
Block(-6,0,2,STONE:0)
Block(-6,0,3,STONE:0)
Block(-6,0,4,STONE:0)
Block(-6,0,5,STONE:0)
Block(-6,0,6,STONE:0)
Block(-6,0,7,STONE:0)
Block(-6,0,8,STONE:0)
Block(-6,1,-7,STONE:0)
Block(-6,1,-6,STONE:0)
Block(-6,1,-5,STONE:0)
Block(-6,1,-4,STONE:0)
Block(-6,1,-3,STONE:0)
Block(-6,1,-2,STONE:0)
Block(-6,1,-1,STONE:0)
Block(-6,1,0,STONE:0)
Block(-6,1,1,STONE:0)
Block(-6,1,2,STONE:0)
Block(-6,1,3,STONE:0)
Block(-6,1,4,STONE:0)
Block(-6,1,5,STONE:0)
Block(-6,1,6,STONE:0)
Block(-6,1,7,STONE:0)
Block(-6,1,8,STONE:0)
Block(-6,2,-7,STONE:0)
Block(-6,2,-6,STONE:0)
Block(-6,2,-5,STONE:0)
Block(-6,2,-4,STONE:0)
Block(-6,2,-3,STONE:0)
Block(-6,2,-2,STONE:0)
Block(-6,2,-1,STONE:0)
Block(-6,2,0,STONE:0)
Block(-6,2,1,STONE:0)
Block(-6,2,2,STONE:0)
Block(-6,2,3,STONE:0)
Block(-6,2,4,STONE:0)
Block(-6,2,5,STONE:0)
Block(-6,2,6,STONE:0)
Block(-6,2,7,STONE:0)
Block(-6,2,8,STONE:0)
Block(-6,3,-7,STONE:0)
Block(-6,3,-6,STONE:0)
Block(-6,3,-5,STONE:0)
Block(-6,3,-4,STONE:0)
Block(-6,3,-3,STONE:0)
Block(-6,3,-2,STONE:0)
Block(-6,3,-1,STONE:0)
Block(-6,3,0,STONE:0)
Block(-6,3,1,STONE:0)
Block(-6,3,2,STONE:0)
Block(-6,3,3,STONE:0)
Block(-6,3,4,STONE:0)
Block(-6,3,5,STONE:0)
Block(-6,3,6,STONE:0)
Block(-6,3,7,STONE:0)
Block(-6,3,8,STONE:0)
Block(-6,4,-7,STONE:0)
Block(-6,4,-6,STONE:0)
Block(-6,4,-5,STONE:0)
Block(-6,4,-4,STONE:0)
Block(-6,4,-3,STONE:0)
Block(-6,4,-2,STONE:0)
Block(-6,4,-1,STONE:0)
Block(-6,4,0,STONE:0)
Block(-6,4,1,STONE:0)
Block(-6,4,2,STONE:0)
Block(-6,4,3,STONE:0)
Block(-6,4,4,STONE:0)
Block(-6,4,5,STONE:0)
Block(-6,4,6,STONE:0)
Block(-6,4,7,STONE:0)
Block(-6,4,8,STONE:0)
Block(-6,5,-7,STONE:0)
Block(-6,5,-6,STONE:0)
Block(-6,5,-5,STONE:0)
Block(-6,5,-4,STONE:0)
Block(-6,5,-3,STONE:0)
Block(-6,5,-2,STONE:0)
Block(-6,5,-1,STONE:0)
Block(-6,5,0,STONE:0)
Block(-6,5,1,STONE:0)
Block(-6,5,2,STONE:0)
Block(-6,5,3,STONE:0)
Block(-6,5,4,STONE:0)
Block(-6,5,5,STONE:0)
Block(-6,5,6,STONE:0)
Block(-6,5,7,STONE:0)
Block(-6,5,8,STONE:0)
Block(-6,6,-7,STONE:0)
Block(-6,6,-6,STONE:0)
Block(-6,6,-5,STONE:0)
Block(-6,6,-4,STONE:0)
Block(-6,6,-3,STONE:0)
Block(-6,6,-2,STONE:0)
Block(-6,6,-1,STONE:0)
Block(-6,6,0,STONE:0)
Block(-6,6,1,STONE:0)
Block(-6,6,2,STONE:0)
Block(-6,6,3,STONE:0)
Block(-6,6,4,STONE:0)
Block(-6,6,5,STONE:0)
Block(-6,6,6,STONE:0)
Block(-6,6,7,STONE:0)
Block(-6,6,8,STONE:0)
Block(-6,7,-7,STONE:0)
Block(-6,7,-6,STONE:0)
Block(-6,7,-5,STONE:0)
Block(-6,7,-4,STONE:0)
Block(-6,7,-3,STONE:0)
Block(-6,7,-2,STONE:0)
Block(-6,7,-1,STONE:0)
Block(-6,7,0,STONE:0)
Block(-6,7,1,STONE:0)
Block(-6,7,2,STONE:0)
Block(-6,7,3,STONE:0)
Block(-6,7,4,STONE:0)
Block(-6,7,5,STONE:0)
Block(-6,7,6,STONE:0)
Block(-6,7,7,STONE:0)
Block(-6,7,8,STONE:0)
Block(-6,8,-7,STONE:0)
Block(-6,8,-6,STONE:0)
Block(-6,8,-5,STONE:0)
Block(-6,8,-4,STONE:0)
Block(-6,8,-3,STONE:0)
Block(-6,8,-2,STONE:0)
Block(-6,8,-1,STONE:0)
Block(-6,8,0,STONE:0)
Block(-6,8,1,STONE:0)
Block(-6,8,2,STONE:0)
Block(-6,8,3,STONE:0)
Block(-6,8,4,STONE:0)
Block(-6,8,5,STONE:0)
Block(-6,8,6,STONE:0)
Block(-6,8,7,STONE:0)
Block(-6,8,8,STONE:0)
Block(-6,9,-7,STONE:0)
Block(-6,9,-6,STONE:0)
Block(-6,9,-5,STONE:0)
Block(-6,9,-4,STONE:0)
Block(-6,9,-3,STONE:0)
Block(-6,9,-2,STONE:0)
Block(-6,9,-1,STONE:0)
Block(-6,9,0,STONE:0)
Block(-6,9,1,STONE:0)
Block(-6,9,2,STONE:0)
Block(-6,9,3,STONE:0)
Block(-6,9,4,STONE:0)
Block(-6,9,5,STONE:0)
Block(-6,9,6,STONE:0)
Block(-6,9,7,STONE:0)
Block(-6,9,8,STONE:0)
Block(-6,10,-7,STONE:0)
Block(-6,10,-6,STONE:0)
Block(-6,10,-5,STONE:0)
Block(-6,10,-4,STONE:0)
Block(-6,10,-3,STONE:0)
Block(-6,10,-2,STONE:0)
Block(-6,10,-1,STONE:0)
Block(-6,10,0,STONE:0)
Block(-6,10,1,STONE:0)
Block(-6,10,2,STONE:0)
Block(-6,10,3,STONE:0)
Block(-6,10,4,STONE:0)
Block(-6,10,5,STONE:0)
Block(-6,10,6,STONE:0)
Block(-6,10,7,STONE:0)
Block(-6,10,8,STONE:0)
Block(-6,11,-7,STONE:0)
Block(-6,11,-6,STONE:0)
Block(-6,11,-5,STONE:0)
Block(-6,11,-4,STONE:0)
Block(-6,11,-3,STONE:0)
Block(-6,11,-2,STONE:0)
Block(-6,11,-1,STONE:0)
Block(-6,11,0,STONE:0)
Block(-6,11,1,STONE:0)
Block(-6,11,2,STONE:0)
Block(-6,11,3,STONE:0)
Block(-6,11,4,STONE:0)
Block(-6,11,5,STONE:0)
Block(-6,11,6,STONE:0)
Block(-6,11,7,STONE:0)
Block(-6,11,8,STONE:0)
Block(-6,12,-7,STONE:0)
Block(-6,12,-6,STONE:0)
Block(-6,12,-5,STONE:0)
Block(-6,12,-4,STONE:0)
Block(-6,12,-3,STONE:0)
Block(-6,12,-2,STONE:0)
Block(-6,12,-1,STONE:0)
Block(-6,12,0,STONE:0)
Block(-6,12,1,STONE:0)
Block(-6,12,2,STONE:0)
Block(-6,12,3,STONE:0)
Block(-6,12,4,STONE:0)
Block(-6,12,5,STONE:0)
Block(-6,12,6,STONE:0)
Block(-6,12,7,STONE:0)
Block(-6,12,8,STONE:0)
Block(-6,13,-7,STONE:0)
Block(-6,13,-6,STONE:0)
Block(-6,13,-5,STONE:0)
Block(-6,13,-4,STONE:0)
Block(-6,13,-3,STONE:0)
Block(-6,13,-2,STONE:0)
Block(-6,13,-1,STONE:0)
Block(-6,13,0,STONE:0)
Block(-6,13,1,STONE:0)
Block(-6,13,2,STONE:0)
Block(-6,13,3,STONE:0)
Block(-6,13,4,STONE:0)
Block(-6,13,5,STONE:0)
Block(-6,13,6,STONE:0)
Block(-6,13,7,STONE:0)
Block(-6,13,8,STONE:0)
Block(-6,14,-7,STONE:0)
Block(-6,14,-6,STONE:0)
Block(-6,14,-5,STONE:0)
Block(-6,14,-4,STONE:0)
Block(-6,14,-3,STONE:0)
Block(-6,14,-2,STONE:0)
Block(-6,14,-1,STONE:0)
Block(-6,14,0,STONE:0)
Block(-6,14,1,STONE:0)
Block(-6,14,2,STONE:0)
Block(-6,14,3,STONE:0)
Block(-6,14,4,STONE:0)
Block(-6,14,5,STONE:0)
Block(-6,14,6,STONE:0)
Block(-6,14,7,STONE:0)
Block(-6,14,8,STONE:0)
Block(-6,15,-7,STONE:0)
Block(-6,15,-6,STONE:0)
Block(-6,15,-5,STONE:0)
Block(-6,15,-4,STONE:0)
Block(-6,15,-3,STONE:0)
Block(-6,15,-2,STONE:0)
Block(-6,15,-1,STONE:0)
Block(-6,15,0,STONE:0)
Block(-6,15,1,STONE:0)
Block(-6,15,2,STONE:0)
Block(-6,15,3,STONE:0)
Block(-6,15,4,STONE:0)
Block(-6,15,5,STONE:0)
Block(-6,15,6,SMOOTH_BRICK:0)
Block(-6,15,7,STONE:0)
Block(-6,15,8,REDSTONE_WIRE:0)
Block(-6,16,-7,STONE:0)
Block(-6,16,-6,STONE:0)
Block(-6,16,-5,STONE:0)
Block(-6,16,-4,STONE:0)
Block(-6,16,-3,STONE:0)
Block(-6,16,-2,STONE:0)
Block(-6,16,-1,STONE:0)
Block(-6,16,0,STONE:0)
Block(-6,16,1,STONE:0)
Block(-6,16,2,STONE:0)
Block(-6,16,3,STONE:0)
Block(-6,16,4,STONE:0)
Block(-6,16,5,STONE:0)
Block(-6,16,6,REDSTONE_WIRE:0)
Block(-6,16,7,SMOOTH_BRICK:0)
Block(-6,16,8,SMOOTH_BRICK:0)
Block(-6,17,-7,STONE:0)
Block(-6,17,-6,STONE:0)
Block(-6,17,-5,STONE:0)
Block(-6,17,-4,STONE:0)
Block(-6,17,-3,STONE:0)
Block(-6,17,-2,STONE:0)
Block(-6,17,-1,STONE:0)
Block(-6,17,0,STONE:0)
Block(-6,17,1,STONE:0)
Block(-6,17,2,STONE:0)
Block(-6,17,3,STONE:0)
Block(-6,17,4,STONE:0)
Block(-6,17,5,STONE:0)
Block(-6,17,7,SMOOTH_BRICK:0)
Block(-6,18,-7,STONE:0)
Block(-6,18,-6,STONE:0)
Block(-6,18,-5,STONE:0)
Block(-6,18,-4,MAGMA:0)
Block(-6,18,-3,MAGMA:0)
Block(-6,18,-2,STONE:0)
Block(-6,18,-1,STONE:0)
Block(-6,18,0,STONE:0)
Block(-6,18,1,STONE:0)
Block(-6,18,2,STONE:0)
Block(-6,18,3,REDSTONE_WIRE:0)
Block(-6,18,4,REDSTONE_WIRE:0)
Block(-6,18,6,PISTON_STICKY_BASE:9)
Block(-6,18,7,SMOOTH_BRICK:0)
Block(-6,18,8,SMOOTH_BRICK:0)
Block(-6,19,-7,STONE:0)
Block(-6,19,-6,CONCRETE:7)
Block(-6,19,-5,CONCRETE:7)
Block(-6,19,-4,STAINED_GLASS:15)
Block(-6,19,-3,STAINED_GLASS:15)
Block(-6,19,-2,CONCRETE:7)
Block(-6,19,-1,CONCRETE:7)
Block(-6,19,0,CONCRETE:7)
Block(-6,19,1,CONCRETE:7)
Block(-6,19,2,CONCRETE:7)
Block(-6,19,3,CONCRETE:7)
Block(-6,19,4,CONCRETE:7)
Block(-6,19,5,CONCRETE:15)
Block(-6,19,6,PISTON_MOVING_PIECE:9)
Block(-6,19,7,REDSTONE_WIRE:10)
Block(-6,20,-7,CONCRETE:15)
Block(-6,20,-6,CONCRETE:7)
Block(-6,20,-4,CARPET:14)
Block(-6,20,-3,CARPET:14)
Block(-6,20,-1,CONCRETE:7)
Block(-6,20,0,CONCRETE:15)
Block(-6,20,1,STONE:3)
Block(-6,20,2,CONCRETE:7)
Block(-6,20,6,SMOOTH_STAIRS:2)
Block(-6,20,7,PISTON_STICKY_BASE:1)
Block(-6,20,8,SMOOTH_BRICK:0)
Block(-6,21,-7,CONCRETE:15)
Block(-6,21,-6,CONCRETE:7)
Block(-6,21,-1,CONCRETE:7)
Block(-6,21,0,CONCRETE:15)
Block(-6,21,1,CONCRETE:7)
Block(-6,21,2,CONCRETE:7)
Block(-6,21,7,SMOOTH_STAIRS:2)
Block(-6,21,8,REDSTONE_WIRE:0)
Block(-6,22,-7,CONCRETE:15)
Block(-6,22,-6,CONCRETE:7)
Block(-6,22,-1,CONCRETE:7)
Block(-6,22,0,CONCRETE:15)
Block(-6,22,1,REDSTONE_WIRE:0)
Block(-6,22,2,CONCRETE:7)
Block(-6,22,8,STEP:0)
Block(-6,23,-7,CONCRETE:15)
Block(-6,23,-6,CONCRETE:7)
Block(-6,23,-1,CONCRETE:7)
Block(-6,23,0,CONCRETE:15)
Block(-6,23,1,STONE:3)
Block(-6,23,2,CONCRETE:7)
Block(-6,24,-7,CONCRETE:15)
Block(-6,24,-6,SMOOTH_BRICK:0)
Block(-6,24,-1,CONCRETE:7)
Block(-6,24,0,CONCRETE:15)
Block(-6,24,1,STONE:3)
Block(-6,24,2,CONCRETE:7)
Block(-6,25,-7,CONCRETE:15)
Block(-6,25,-6,SMOOTH_BRICK:0)
Block(-6,25,-1,SMOOTH_BRICK:0)
Block(-6,25,0,CONCRETE:15)
Block(-6,25,1,STONE:3)
Block(-6,25,2,CONCRETE:7)
Block(-6,26,-7,CONCRETE:15)
Block(-6,26,-6,SMOOTH_BRICK:0)
Block(-6,26,-5,SMOOTH_STAIRS:7)
Block(-6,26,-2,SMOOTH_STAIRS:6)
Block(-6,26,-1,SMOOTH_BRICK:0)
Block(-6,26,0,CONCRETE:15)
Block(-6,26,1,STONE:3)
Block(-6,26,2,CONCRETE:7)
Block(-6,27,-7,STONE:0)
Block(-6,27,-6,SMOOTH_BRICK:0)
Block(-6,27,-5,SMOOTH_BRICK:0)
Block(-6,27,-4,SMOOTH_BRICK:0)
Block(-6,27,-3,SMOOTH_BRICK:0)
Block(-6,27,-2,SMOOTH_BRICK:0)
Block(-6,27,-1,SMOOTH_BRICK:0)
Block(-6,27,0,STONE:3)
Block(-6,27,1,STONE:3)
Block(-6,27,2,CONCRETE:7)
Block(-6,28,-7,STONE:0)
Block(-6,28,-6,SMOOTH_BRICK:0)
Block(-6,28,-5,SMOOTH_BRICK:0)
Block(-6,28,-4,SMOOTH_BRICK:0)
Block(-6,28,-3,SMOOTH_BRICK:0)
Block(-6,28,-2,SMOOTH_BRICK:0)
Block(-6,28,-1,SMOOTH_BRICK:0)
Block(-6,28,0,STONE:3)
Block(-6,28,1,STONE:3)
Block(-6,28,2,SMOOTH_BRICK:0)
Block(-6,29,-7,STONE:0)
Block(-6,29,-6,SMOOTH_BRICK:0)
Block(-6,29,-5,SMOOTH_BRICK:0)
Block(-6,29,-4,SMOOTH_BRICK:0)
Block(-6,29,-3,SMOOTH_BRICK:0)
Block(-6,29,-2,SMOOTH_BRICK:0)
Block(-6,29,-1,SMOOTH_BRICK:0)
Block(-6,29,0,STONE:3)
Block(-6,29,1,STONE:3)
Block(-6,29,2,SMOOTH_BRICK:0)
Block(-6,30,-7,STONE:0)
Block(-6,30,-6,STONE:0)
Block(-6,30,-5,STONE:0)
Block(-6,30,-4,STONE:0)
Block(-6,30,-3,STONE:0)
Block(-6,30,-2,STONE:0)
Block(-6,30,-1,SMOOTH_BRICK:0)
Block(-6,30,0,STONE:3)
Block(-6,30,1,STONE:3)
Block(-6,30,2,SMOOTH_BRICK:0)
Block(-6,30,5,STEP:8)
Block(-6,31,-7,STONE:0)
Block(-6,31,-6,STONE:0)
Block(-6,31,-5,STONE:0)
Block(-6,31,-4,STONE:0)
Block(-6,31,-3,STONE:0)
Block(-6,31,-2,STONE:0)
Block(-6,31,-1,STONE:0)
Block(-6,31,0,STONE:0)
Block(-6,31,1,STONE:0)
Block(-6,31,2,STONE:0)
Block(-6,31,3,CONCRETE:7)
Block(-6,31,4,CONCRETE:7)
Block(-6,31,5,CONCRETE:7)
Block(-6,31,6,SMOOTH_STAIRS:7)
Block(-6,32,-7,STONE:0)
Block(-6,32,-6,STONE:0)
Block(-6,32,-5,STONE:0)
Block(-6,32,-4,STONE:0)
Block(-6,32,-3,STONE:0)
Block(-6,32,-2,STONE:0)
Block(-6,32,-1,STONE:0)
Block(-6,32,0,STONE:0)
Block(-6,32,1,SMOOTH_BRICK:0)
Block(-6,32,2,SMOOTH_BRICK:0)
Block(-6,32,3,SMOOTH_BRICK:0)
Block(-6,32,4,CONCRETE:7)
Block(-6,32,5,STATIONARY_LAVA:0)
Block(-6,32,6,COBBLE_WALL:0)
Block(-6,33,-7,STONE:0)
Block(-6,33,-6,STONE:0)
Block(-6,33,-5,STONE:0)
Block(-6,33,-4,STONE:0)
Block(-6,33,-3,STONE:0)
Block(-6,33,-2,STONE:0)
Block(-6,33,-1,STONE:0)
Block(-6,33,0,STONE:0)
Block(-6,33,1,DIODE_BLOCK_ON:3)
Block(-6,33,2,SMOOTH_BRICK:0)
Block(-6,33,3,SMOOTH_BRICK:0)
Block(-6,33,4,SMOOTH_BRICK:0)
Block(-6,33,5,SMOOTH_BRICK:0)
Block(-6,33,6,SMOOTH_BRICK:0)
Block(-6,34,-7,STONE:0)
Block(-6,34,-6,STONE:0)
Block(-6,34,-5,STONE:0)
Block(-6,34,-4,STONE:0)
Block(-6,34,-3,STONE:0)
Block(-6,34,-2,STONE:0)
Block(-6,34,-1,STONE:0)
Block(-6,34,0,STONE:0)
Block(-6,34,1,SMOOTH_BRICK:0)
Block(-6,34,2,SMOOTH_BRICK:0)
Block(-6,34,3,SMOOTH_BRICK:0)
Block(-6,34,4,SMOOTH_BRICK:0)
Block(-6,34,5,SMOOTH_BRICK:0)
Block(-6,34,6,SMOOTH_BRICK:0)
Block(-6,34,7,CONCRETE:7)
Block(-6,34,8,CONCRETE:7)
Block(-6,35,-7,STONE:0)
Block(-6,35,-6,STONE:0)
Block(-6,35,-5,STONE:0)
Block(-6,35,-4,STONE:0)
Block(-6,35,-3,STONE:0)
Block(-6,35,-2,STONE:0)
Block(-6,35,-1,STONE:0)
Block(-6,35,0,STONE:0)
Block(-6,35,1,SMOOTH_BRICK:0)
Block(-6,35,2,SMOOTH_BRICK:0)
Block(-6,35,3,SMOOTH_BRICK:0)
Block(-6,35,4,SMOOTH_BRICK:0)
Block(-6,35,5,SMOOTH_BRICK:0)
Block(-6,35,6,SMOOTH_BRICK:0)
Block(-6,35,7,CONCRETE:7)
Block(-6,35,8,CONCRETE:7)
Block(-6,36,-7,DIRT:0)
Block(-6,36,-6,DIRT:0)
Block(-6,36,-5,DIRT:0)
Block(-6,36,-4,DIRT:0)
Block(-6,36,-3,DIRT:0)
Block(-6,36,-2,DIRT:0)
Block(-6,36,-1,DIRT:0)
Block(-6,36,0,DIRT:0)
Block(-6,36,1,DIRT:0)
Block(-6,36,2,DIRT:0)
Block(-6,36,3,DIRT:0)
Block(-6,36,4,DIRT:0)
Block(-6,36,5,DIRT:0)
Block(-6,36,6,DIRT:0)
Block(-6,36,7,DIRT:0)
Block(-6,36,8,DIRT:0)
Block(-6,37,-7,DIRT:0)
Block(-6,37,-6,DIRT:0)
Block(-6,37,-5,DIRT:0)
Block(-6,37,-4,DIRT:0)
Block(-6,37,-3,DIRT:0)
Block(-6,37,-2,DIRT:0)
Block(-6,37,-1,DIRT:0)
Block(-6,37,0,DIRT:0)
Block(-6,37,1,DIRT:0)
Block(-6,37,2,DIRT:0)
Block(-6,37,3,DIRT:0)
Block(-6,37,4,DIRT:0)
Block(-6,37,5,DIRT:0)
Block(-6,37,6,DIRT:0)
Block(-6,37,7,DIRT:0)
Block(-6,37,8,DIRT:0)
Block(-6,38,-7,GRASS:0)
Block(-6,38,-6,DIRT:0)
Block(-6,38,-5,DIRT:0)
Block(-6,38,-4,DIRT:0)
Block(-6,38,-3,DIRT:0)
Block(-6,38,-2,DIRT:0)
Block(-6,38,-1,DIRT:0)
Block(-6,38,0,DIRT:0)
Block(-6,38,1,DIRT:0)
Block(-6,38,2,DIRT:0)
Block(-6,38,3,DIRT:0)
Block(-6,38,4,DIRT:0)
Block(-6,38,5,DIRT:0)
Block(-6,38,6,DIRT:0)
Block(-6,38,7,DIRT:0)
Block(-6,38,8,DIRT:0)
Block(-6,39,-6,GRASS:0)
Block(-6,39,-5,GRASS:0)
Block(-6,39,-4,GRASS:0)
Block(-6,39,-3,GRASS:0)
Block(-6,39,-2,GRASS:0)
Block(-6,39,-1,GRASS:0)
Block(-6,39,0,GRASS:0)
Block(-6,39,1,GRASS:0)
Block(-6,39,2,GRASS:0)
Block(-6,39,3,GRASS:0)
Block(-6,39,4,DIRT:0)
Block(-6,39,5,GRASS:0)
Block(-6,39,6,COBBLESTONE_STAIRS:2)
Block(-6,39,7,GRASS:0)
Block(-6,39,8,GRASS_PATH:0)
Block(-6,40,-5,LONG_GRASS:1)
Block(-6,40,-4,DARK_OAK_FENCE:0)
Block(-6,40,-3,LONG_GRASS:1)
Block(-6,40,-2,LONG_GRASS:1)
Block(-6,40,-1,YELLOW_FLOWER:0)
Block(-6,40,0,RED_ROSE:8)
Block(-6,40,1,LONG_GRASS:1)
RandomBlock(-6,40,3,AIR:0,20,CHEST:4,../../../Chests/Loot/JunkChest_1.nbt,10,CHEST:4,../../../Chests/Loot/JunkChest_2.nbt,10,CHEST:4,../../../Chests/Loot/JunkChest_3.nbt,10,CHEST:4,../../../Chests/Loot/JunkChest_4.nbt,10,CHEST:4,../../../Chests/Loot/JunkChest_5.nbt,10,CHEST:4,../../../Chests/Lore/village_1.nbt,1,CHEST:4,../../../Chests/Lore/village_2.nbt,1,CHEST:4,../../../Chests/Lore/village_3.nbt,1,CHEST:4,../../../Chests/Lore/village_4.nbt,1,CHEST:4,../../../Chests/Lore/village_5.nbt,1,CHEST:4,../../../Chests/Loot/Common1.nbt,10,CHEST:4,../../../Chests/Loot/Common2.nbt,10,CHEST:4,../../../Chests/Loot/Common3.nbt,10,CHEST:4,../../../Chests/Loot/Common4.nbt,10,CHEST:4,../../../Chests/Loot/Common5.nbt,10,CHEST:4,../../../Chests/Loot/Common6.nbt,10,CHEST:4,../../../Chests/Loot/Common7.nbt,10,CHEST:4,../../../Chests/Loot/Common8.nbt,10,CHEST:4,../../../Chests/Loot/Common9.nbt,10,CHEST:4,../../../Chests/Loot/Common10.nbt,10,CHEST:4,../../../Chests/Loot/Common10.nbt,11,CHEST:4,../../../Chests/Loot/Common12.nbt,10,CHEST:4,../../../Chests/Loot/Common13.nbt,10,CHEST:4,../../../Chests/Loot/Common14.nbt,10,CHEST:4,../../../Chests/Loot/Common15.nbt,10,CHEST:4,../../../Chests/Lore/village_1.nbt,2,CHEST:4,../../../Chests/Lore/village_3.nbt,2,CHEST:4,../../../Chests/Lore/village_4.nbt,2,CHEST:4,../../../Chests/Lore/village_5.nbt,2,CHEST:4,../../../Chests/Lore/village_5.nbt,2,CHEST:4,../../../Chests/Loot/Rare1.nbt,5,CHEST:4,../../../Chests/Loot/Rare2.nbt,5,CHEST:4,../../../Chests/Loot/Rare3.nbt,5,CHEST:4,../../../Chests/Loot/Rare4.nbt,5,CHEST:4,../../../Chests/Loot/Rare5.nbt,5,CHEST:4,../../../Chests/Loot/Rare6.nbt,5,CHEST:4,../../../Chests/Loot/Rare7.nbt,5,CHEST:4,../../../Chests/Loot/Rare8.nbt,5,CHEST:4,../../../Chests/Loot/Rare9.nbt,5,CHEST:4,../../../Chests/Loot/Rare10.nbt,5,CHEST:4,../../../Chests/Loot/Rare11.nbt,5,CHEST:4,../../../Chests/Loot/Rare12.nbt,5,CHEST:4,../../../Chests/Loot/Rare13.nbt,5,CHEST:4,../../../Chests/Loot/Rare14.nbt,5,CHEST:4,../../../Chests/Loot/Rare15.nbt,5,CHEST:4,../../../Chests/Loot/Epic1.nbt,2,CHEST:4,../../../Chests/Loot/Epic2.nbt,2,CHEST:4,../../../Chests/Loot/Epic3.nbt,2,CHEST:4,../../../Chests/Loot/Epic4.nbt,2,CHEST:4,../../../Chests/Loot/Epic5.nbt,2,CHEST:4,../../../Chests/Loot/Epic6.nbt,2,CHEST:4,../../../Chests/Loot/Epic7.nbt,2,CHEST:4,../../../Chests/Loot/Epic8.nbt,2,CHEST:4,../../../Chests/Loot/Epic9.nbt,2,CHEST:4,../../../Chests/Loot/Epic10.nbt,2,CHEST:4,../../../Chests/Loot/Epic11.nbt,2,CHEST:4,../../../Chests/Loot/Epic12.nbt,2,CHEST:4,../../../Chests/Loot/Epic13.nbt,2,CHEST:4,../../../Chests/Loot/Epic14.nbt,2,CHEST:4,../../../Chests/Loot/Epic15.nbt,5,CHEST:4,../../../Chests/Loot/Rare1.nbt,5,CHEST:4,../../../Chests/Loot/Rare2.nbt,5,CHEST:4,../../../Chests/Loot/Rare3.nbt,5,CHEST:4,../../../Chests/Loot/Rare4.nbt,5,CHEST:4,../../../Chests/Loot/Rare5.nbt,10,CHEST:4,../../../Chests/Loot/Rare6.nbt,10,CHEST:4,../../../Chests/Loot/Rare7.nbt,10,CHEST:4,../../../Chests/Loot/Rare8.nbt,10,CHEST:4,../../../Chests/Loot/Rare9.nbt,10,CHEST:4,../../../Chests/Loot/Rare10.nbt,15,CHEST:4,../../../Chests/Loot/Rare11.nbt,15,CHEST:4,../../../Chests/Loot/Rare12.nbt,15,CHEST:4,../../../Chests/Loot/Rare13.nbt,15,CHEST:4,../../../Chests/Loot/Rare14.nbt,15,CHEST:4,../../../Chests/Loot/Rare15.nbt,15,CHEST:4,../../../Chests/Loot/Epic15.nbt,100)
Block(-6,40,4,HAY_BLOCK:0)
Block(-6,40,5,LONG_GRASS:1)
Block(-6,49,-1,LOG_2:13)
Block(-6,50,-1,LOG_2:13)
Block(-6,51,-4,LEAVES:0)
Block(-6,51,-1,LEAVES:0)
Block(-6,51,3,LEAVES:0)
Block(-6,51,4,LEAVES:0)
Block(-6,51,5,LEAVES:0)
Block(-6,52,-5,LEAVES:0)
Block(-6,52,-4,LEAVES:0)
Block(-6,52,-3,LEAVES:0)
Block(-6,52,-2,LEAVES:0)
Block(-6,52,-1,LEAVES:0)
Block(-6,52,0,LEAVES:0)
Block(-6,52,1,LEAVES:0)
Block(-6,52,2,LEAVES:0)
Block(-6,52,4,LEAVES:0)
Block(-6,53,-4,LEAVES:0)
Block(-6,53,-3,LEAVES:0)
Block(-6,53,-2,LEAVES:0)
Block(-6,53,-1,LEAVES:0)
Block(-6,53,0,LEAVES:0)
Block(-6,53,1,LEAVES:0)
Block(-6,53,2,LEAVES:0)
Block(-6,53,3,LEAVES:0)
Block(-6,53,4,LEAVES:0)
Block(-6,54,-3,LEAVES:0)
Block(-6,54,-2,LEAVES:0)
Block(-6,54,-1,LEAVES:0)
Block(-6,54,0,LEAVES:0)
Block(-6,54,1,LEAVES:0)
Block(-6,54,2,LEAVES:0)
Block(-6,54,3,LEAVES:0)
Block(-6,54,4,LEAVES:0)
Block(-6,54,5,LEAVES:0)
Block(-6,55,-1,LEAVES:0)
Block(-6,55,0,LEAVES:0)
Block(-6,55,1,LEAVES:0)
Block(-6,55,2,LEAVES:0)
Block(-6,55,3,LEAVES:0)
Block(-6,55,4,LEAVES:0)
Block(-6,56,-2,LEAVES:0)
Block(-6,56,-1,LEAVES:0)
Block(-6,56,0,LEAVES:0)
Block(-6,56,1,LEAVES:0)
Block(-6,56,2,LEAVES:0)
Block(-6,56,3,LEAVES:0)
Block(-6,57,-1,LEAVES:0)
Block(-6,57,1,LEAVES:0)
Block(-5,0,-7,STONE:0)
Block(-5,0,-6,STONE:0)
Block(-5,0,-5,STONE:0)
Block(-5,0,-4,STONE:0)
Block(-5,0,-3,STONE:0)
Block(-5,0,-2,STONE:0)
Block(-5,0,-1,STONE:0)
Block(-5,0,0,STONE:0)
Block(-5,0,1,STONE:0)
Block(-5,0,2,STONE:0)
Block(-5,0,3,STONE:0)
Block(-5,0,4,STONE:0)
Block(-5,0,5,STONE:0)
Block(-5,0,6,STONE:0)
Block(-5,0,7,STONE:0)
Block(-5,0,8,STONE:0)
Block(-5,1,-7,STONE:0)
Block(-5,1,-6,STONE:0)
Block(-5,1,-5,STONE:0)
Block(-5,1,-4,STONE:0)
Block(-5,1,-3,STONE:0)
Block(-5,1,-2,STONE:0)
Block(-5,1,-1,STONE:0)
Block(-5,1,0,STONE:0)
Block(-5,1,1,STONE:0)
Block(-5,1,2,STONE:0)
Block(-5,1,3,STONE:0)
Block(-5,1,4,STONE:0)
Block(-5,1,5,STONE:0)
Block(-5,1,6,STONE:0)
Block(-5,1,7,STONE:0)
Block(-5,1,8,STONE:0)
Block(-5,2,-7,STONE:0)
Block(-5,2,-6,STONE:0)
Block(-5,2,-5,STONE:0)
Block(-5,2,-4,STONE:0)
Block(-5,2,-3,STONE:0)
Block(-5,2,-2,STONE:0)
Block(-5,2,-1,STONE:0)
Block(-5,2,0,STONE:0)
Block(-5,2,1,STONE:0)
Block(-5,2,2,STONE:0)
Block(-5,2,3,STONE:0)
Block(-5,2,4,STONE:0)
Block(-5,2,5,STONE:0)
Block(-5,2,6,STONE:0)
Block(-5,2,7,STONE:0)
Block(-5,2,8,STONE:0)
Block(-5,3,-7,STONE:0)
Block(-5,3,-6,STONE:0)
Block(-5,3,-5,STONE:0)
Block(-5,3,-4,STONE:0)
Block(-5,3,-3,STONE:0)
Block(-5,3,-2,STONE:0)
Block(-5,3,-1,STONE:0)
Block(-5,3,0,STONE:0)
Block(-5,3,1,STONE:0)
Block(-5,3,2,STONE:0)
Block(-5,3,3,STONE:0)
Block(-5,3,4,STONE:0)
Block(-5,3,5,STONE:0)
Block(-5,3,6,STONE:0)
Block(-5,3,7,STONE:0)
Block(-5,3,8,STONE:0)
Block(-5,4,-7,STONE:0)
Block(-5,4,-6,STONE:0)
Block(-5,4,-5,STONE:0)
Block(-5,4,-4,STONE:0)
Block(-5,4,-3,STONE:0)
Block(-5,4,-2,STONE:0)
Block(-5,4,-1,STONE:0)
Block(-5,4,0,STONE:0)
Block(-5,4,1,STONE:0)
Block(-5,4,2,STONE:0)
Block(-5,4,3,STONE:0)
Block(-5,4,4,STONE:0)
Block(-5,4,5,STONE:0)
Block(-5,4,6,STONE:0)
Block(-5,4,7,STONE:0)
Block(-5,4,8,STONE:0)
Block(-5,5,-7,STONE:0)
Block(-5,5,-6,STONE:0)
Block(-5,5,-5,STONE:0)
Block(-5,5,-4,STONE:0)
Block(-5,5,-3,STONE:0)
Block(-5,5,-2,STONE:0)
Block(-5,5,-1,STONE:0)
Block(-5,5,0,STONE:0)
Block(-5,5,1,STONE:0)
Block(-5,5,2,STONE:0)
Block(-5,5,3,STONE:0)
Block(-5,5,4,STONE:0)
Block(-5,5,5,STONE:0)
Block(-5,5,6,STONE:0)
Block(-5,5,7,STONE:0)
Block(-5,5,8,STONE:0)
Block(-5,6,-7,STONE:0)
Block(-5,6,-6,STONE:0)
Block(-5,6,-5,STONE:0)
Block(-5,6,-4,STONE:0)
Block(-5,6,-3,STONE:0)
Block(-5,6,-2,STONE:0)
Block(-5,6,-1,STONE:0)
Block(-5,6,0,STONE:0)
Block(-5,6,1,STONE:0)
Block(-5,6,2,STONE:0)
Block(-5,6,3,STONE:0)
Block(-5,6,4,STONE:0)
Block(-5,6,5,STONE:0)
Block(-5,6,6,STONE:0)
Block(-5,6,7,STONE:0)
Block(-5,6,8,STONE:0)
Block(-5,7,-7,STONE:0)
Block(-5,7,-6,STONE:0)
Block(-5,7,-5,STONE:0)
Block(-5,7,-4,STONE:0)
Block(-5,7,-3,STONE:0)
Block(-5,7,-2,STONE:0)
Block(-5,7,-1,STONE:0)
Block(-5,7,0,STONE:0)
Block(-5,7,1,STONE:0)
Block(-5,7,2,STONE:0)
Block(-5,7,3,STONE:0)
Block(-5,7,4,STONE:0)
Block(-5,7,5,STONE:0)
Block(-5,7,6,STONE:0)
Block(-5,7,7,STONE:0)
Block(-5,7,8,STONE:0)
Block(-5,8,-7,STONE:0)
Block(-5,8,-6,STONE:0)
Block(-5,8,-5,STONE:0)
Block(-5,8,-4,STONE:0)
Block(-5,8,-3,STONE:0)
Block(-5,8,-2,STONE:0)
Block(-5,8,-1,STONE:0)
Block(-5,8,0,STONE:0)
Block(-5,8,1,STONE:0)
Block(-5,8,2,STONE:0)
Block(-5,8,3,STONE:0)
Block(-5,8,4,STONE:0)
Block(-5,8,5,STONE:0)
Block(-5,8,6,STONE:0)
Block(-5,8,7,STONE:0)
Block(-5,8,8,STONE:0)
Block(-5,9,-7,STONE:0)
Block(-5,9,-6,STONE:0)
Block(-5,9,-5,STONE:0)
Block(-5,9,-4,STONE:0)
Block(-5,9,-3,STONE:0)
Block(-5,9,-2,STONE:0)
Block(-5,9,-1,STONE:0)
Block(-5,9,0,STONE:0)
Block(-5,9,1,STONE:0)
Block(-5,9,2,STONE:0)
Block(-5,9,3,STONE:0)
Block(-5,9,4,STONE:0)
Block(-5,9,5,STONE:0)
Block(-5,9,6,STONE:0)
Block(-5,9,7,STONE:0)
Block(-5,9,8,STONE:0)
Block(-5,10,-7,STONE:0)
Block(-5,10,-6,STONE:0)
Block(-5,10,-5,STONE:0)
Block(-5,10,-4,STONE:0)
Block(-5,10,-3,STONE:0)
Block(-5,10,-2,STONE:0)
Block(-5,10,-1,STONE:0)
Block(-5,10,0,STONE:0)
Block(-5,10,1,STONE:0)
Block(-5,10,2,STONE:0)
Block(-5,10,3,STONE:0)
Block(-5,10,4,STONE:0)
Block(-5,10,5,STONE:0)
Block(-5,10,6,STONE:0)
Block(-5,10,7,STONE:0)
Block(-5,10,8,STONE:0)
Block(-5,11,-7,STONE:0)
Block(-5,11,-6,STONE:0)
Block(-5,11,-5,STONE:0)
Block(-5,11,-4,STONE:0)
Block(-5,11,-3,STONE:0)
Block(-5,11,-2,STONE:0)
Block(-5,11,-1,STONE:0)
Block(-5,11,0,STONE:0)
Block(-5,11,1,STONE:0)
Block(-5,11,2,STONE:0)
Block(-5,11,3,STONE:0)
Block(-5,11,4,STONE:0)
Block(-5,11,5,STONE:0)
Block(-5,11,6,STONE:0)
Block(-5,11,7,STONE:0)
Block(-5,11,8,STONE:0)
Block(-5,12,-7,STONE:0)
Block(-5,12,-6,STONE:0)
Block(-5,12,-5,STONE:0)
Block(-5,12,-4,STONE:0)
Block(-5,12,-3,STONE:0)
Block(-5,12,-2,STONE:0)
Block(-5,12,-1,STONE:0)
Block(-5,12,0,STONE:0)
Block(-5,12,1,STONE:0)
Block(-5,12,2,STONE:0)
Block(-5,12,3,STONE:0)
Block(-5,12,4,STONE:0)
Block(-5,12,5,STONE:0)
Block(-5,12,6,STONE:0)
Block(-5,12,7,STONE:0)
Block(-5,12,8,STONE:0)
Block(-5,13,-7,STONE:0)
Block(-5,13,-6,STONE:0)
Block(-5,13,-5,STONE:0)
Block(-5,13,-4,STONE:0)
Block(-5,13,-3,STONE:0)
Block(-5,13,-2,STONE:0)
Block(-5,13,-1,STONE:0)
Block(-5,13,0,STONE:0)
Block(-5,13,1,STONE:0)
Block(-5,13,2,STONE:0)
Block(-5,13,3,STONE:0)
Block(-5,13,4,STONE:0)
Block(-5,13,5,STONE:0)
Block(-5,13,6,STONE:0)
Block(-5,13,7,STONE:0)
Block(-5,13,8,STONE:0)
Block(-5,14,-7,STONE:0)
Block(-5,14,-6,STONE:0)
Block(-5,14,-5,STONE:0)
Block(-5,14,-4,STONE:0)
Block(-5,14,-3,STONE:0)
Block(-5,14,-2,STONE:0)
Block(-5,14,-1,STONE:0)
Block(-5,14,0,STONE:0)
Block(-5,14,1,STONE:0)
Block(-5,14,2,STONE:0)
Block(-5,14,3,STONE:0)
Block(-5,14,4,STONE:0)
Block(-5,14,5,STONE:0)
Block(-5,14,6,STONE:0)
Block(-5,14,7,STONE:0)
Block(-5,14,8,STONE:0)
Block(-5,15,-7,STONE:0)
Block(-5,15,-6,STONE:0)
Block(-5,15,-5,STONE:0)
Block(-5,15,-4,STONE:0)
Block(-5,15,-3,STONE:0)
Block(-5,15,-2,STONE:0)
Block(-5,15,-1,STONE:0)
Block(-5,15,0,STONE:0)
Block(-5,15,1,STONE:0)
Block(-5,15,2,STONE:0)
Block(-5,15,3,STONE:0)
Block(-5,15,4,STONE:0)
Block(-5,15,5,STONE:0)
Block(-5,15,6,SMOOTH_BRICK:0)
Block(-5,15,7,STONE:0)
Block(-5,15,8,REDSTONE_WIRE:0)
Block(-5,16,-7,STONE:0)
Block(-5,16,-6,STONE:0)
Block(-5,16,-5,STONE:0)
Block(-5,16,-4,STONE:0)
Block(-5,16,-3,STONE:0)
Block(-5,16,-2,STONE:0)
Block(-5,16,-1,STONE:0)
Block(-5,16,0,STONE:0)
Block(-5,16,1,STONE:0)
Block(-5,16,2,STONE:0)
Block(-5,16,3,STONE:0)
Block(-5,16,4,STONE:0)
Block(-5,16,5,STONE:0)
Block(-5,16,6,REDSTONE_WIRE:0)
Block(-5,16,7,STONE:0)
Block(-5,16,8,SMOOTH_BRICK:0)
Block(-5,17,-7,STONE:0)
Block(-5,17,-6,STONE:0)
Block(-5,17,-5,STONE:0)
Block(-5,17,-4,STONE:0)
Block(-5,17,-3,STONE:0)
Block(-5,17,-2,STONE:0)
Block(-5,17,-1,STONE:0)
Block(-5,17,0,STONE:0)
Block(-5,17,1,STONE:0)
Block(-5,17,2,STONE:0)
Block(-5,17,3,STONE:0)
Block(-5,17,4,STONE:0)
Block(-5,17,5,STONE:0)
Block(-5,17,7,STONE:0)
Block(-5,18,-7,STONE:0)
Block(-5,18,-6,STONE:0)
Block(-5,18,-5,STONE:0)
Block(-5,18,-4,MAGMA:0)
Block(-5,18,-3,MAGMA:0)
Block(-5,18,-2,STONE:0)
Block(-5,18,-1,STONE:0)
Block(-5,18,0,STONE:0)
Block(-5,18,1,STONE:0)
Block(-5,18,2,STONE:0)
Block(-5,18,3,REDSTONE_WIRE:0)
Block(-5,18,4,REDSTONE_WIRE:0)
Block(-5,18,6,PISTON_STICKY_BASE:9)
Block(-5,18,7,SMOOTH_BRICK:0)
Block(-5,18,8,SMOOTH_BRICK:0)
Block(-5,19,-7,STONE:0)
Block(-5,19,-6,CONCRETE:7)
Block(-5,19,-5,CONCRETE:7)
Block(-5,19,-4,STAINED_GLASS:15)
Block(-5,19,-3,STAINED_GLASS:15)
Block(-5,19,-2,CONCRETE:7)
Block(-5,19,-1,CONCRETE:7)
Block(-5,19,0,CONCRETE:7)
Block(-5,19,1,CONCRETE:7)
Block(-5,19,2,CONCRETE:7)
Block(-5,19,3,CONCRETE:7)
Block(-5,19,4,CONCRETE:7)
Block(-5,19,5,CONCRETE:15)
Block(-5,19,6,PISTON_MOVING_PIECE:9)
Block(-5,19,7,REDSTONE_WIRE:11)
Block(-5,20,-7,CONCRETE:15)
Block(-5,20,-6,CONCRETE:7)
Block(-5,20,-4,CARPET:14)
Block(-5,20,-3,CARPET:14)
Block(-5,20,-1,CONCRETE:7)
Block(-5,20,0,CONCRETE:15)
Block(-5,20,1,STONE:3)
Block(-5,20,2,CONCRETE:7)
Block(-5,20,6,SMOOTH_STAIRS:2)
Block(-5,20,7,PISTON_STICKY_BASE:1)
Block(-5,20,8,SMOOTH_BRICK:0)
Block(-5,21,-7,CONCRETE:15)
Block(-5,21,-6,CONCRETE:7)
Block(-5,21,-1,CONCRETE:7)
Block(-5,21,0,CONCRETE:15)
Block(-5,21,1,CONCRETE:7)
Block(-5,21,2,CONCRETE:15)
Block(-5,21,7,SMOOTH_STAIRS:2)
Block(-5,21,8,REDSTONE_WIRE:0)
Block(-5,22,-7,CONCRETE:15)
Block(-5,22,-6,CONCRETE:7)
Block(-5,22,-1,CONCRETE:7)
Block(-5,22,0,CONCRETE:15)
Block(-5,22,1,REDSTONE_WIRE:0)
Block(-5,22,2,SMOOTH_STAIRS:3)
Block(-5,22,8,STEP:0)
Block(-5,23,-7,CONCRETE:15)
Block(-5,23,-6,CONCRETE:7)
Block(-5,23,-1,CONCRETE:7)
Block(-5,23,0,CONCRETE:15)
Block(-5,23,1,STONE:3)
Block(-5,24,-7,CONCRETE:15)
Block(-5,24,-6,SMOOTH_BRICK:0)
Block(-5,24,-1,CONCRETE:7)
Block(-5,24,0,CONCRETE:15)
Block(-5,24,1,STONE:3)
Block(-5,25,-7,CONCRETE:15)
Block(-5,25,-6,SMOOTH_BRICK:0)
Block(-5,25,-1,SMOOTH_BRICK:0)
Block(-5,25,0,CONCRETE:15)
Block(-5,25,1,STONE:3)
Block(-5,26,-7,CONCRETE:15)
Block(-5,26,-6,SMOOTH_BRICK:0)
Block(-5,26,-5,SMOOTH_STAIRS:7)
Block(-5,26,-2,SMOOTH_STAIRS:6)
Block(-5,26,-1,SMOOTH_BRICK:0)
Block(-5,26,0,CONCRETE:15)
Block(-5,26,1,STONE:3)
Block(-5,26,2,WALL_BANNER:3,../NBT/DaerocVillage/1154-bannerC208R176.nbt)
Block(-5,27,-7,STONE:0)
Block(-5,27,-6,SMOOTH_BRICK:0)
Block(-5,27,-5,SMOOTH_BRICK:0)
Block(-5,27,-4,SMOOTH_BRICK:0)
Block(-5,27,-3,SMOOTH_BRICK:0)
Block(-5,27,-2,SMOOTH_BRICK:0)
Block(-5,27,-1,SMOOTH_BRICK:0)
Block(-5,27,0,STONE:3)
Block(-5,27,1,STONE:3)
Block(-5,28,-7,STONE:0)
Block(-5,28,-6,SMOOTH_BRICK:0)
Block(-5,28,-5,SMOOTH_BRICK:0)
Block(-5,28,-4,SMOOTH_BRICK:0)
Block(-5,28,-3,SMOOTH_BRICK:0)
Block(-5,28,-2,SMOOTH_BRICK:0)
Block(-5,28,-1,SMOOTH_BRICK:0)
Block(-5,28,0,STONE:3)
Block(-5,28,1,STONE:3)
Block(-5,28,2,SMOOTH_STAIRS:7)
Block(-5,29,-7,STONE:0)
Block(-5,29,-6,SMOOTH_BRICK:0)
Block(-5,29,-5,SMOOTH_BRICK:0)
Block(-5,29,-4,SMOOTH_BRICK:0)
Block(-5,29,-3,SMOOTH_BRICK:0)
Block(-5,29,-2,SMOOTH_BRICK:0)
Block(-5,29,-1,SMOOTH_BRICK:0)
Block(-5,29,0,STONE:3)
Block(-5,29,1,STONE:3)
Block(-5,29,2,SMOOTH_BRICK:0)
Block(-5,29,3,SMOOTH_STAIRS:7)
Block(-5,30,-7,STONE:0)
Block(-5,30,-6,STONE:0)
Block(-5,30,-5,STONE:0)
Block(-5,30,-4,STONE:0)
Block(-5,30,-3,STONE:0)
Block(-5,30,-2,STONE:0)
Block(-5,30,-1,SMOOTH_BRICK:0)
Block(-5,30,0,STONE:3)
Block(-5,30,1,PISTON_STICKY_BASE:11)
Block(-5,30,2,PISTON_MOVING_PIECE:11)
Block(-5,30,3,CONCRETE:15)
Block(-5,30,5,STEP:8)
Block(-5,31,-7,STONE:0)
Block(-5,31,-6,STONE:0)
Block(-5,31,-5,STONE:0)
Block(-5,31,-4,STONE:0)
Block(-5,31,-3,STONE:0)
Block(-5,31,-2,STONE:0)
Block(-5,31,-1,STONE:0)
Block(-5,31,0,STONE:0)
Block(-5,31,1,PISTON_STICKY_BASE:11)
Block(-5,31,2,PISTON_MOVING_PIECE:11)
Block(-5,31,3,CONCRETE:7)
Block(-5,31,4,CONCRETE:7)
Block(-5,31,5,CONCRETE:7)
Block(-5,31,6,SMOOTH_STAIRS:7)
Block(-5,32,-7,STONE:0)
Block(-5,32,-6,STONE:0)
Block(-5,32,-5,STONE:0)
Block(-5,32,-4,STONE:0)
Block(-5,32,-3,STONE:0)
Block(-5,32,-2,STONE:0)
Block(-5,32,-1,STONE:0)
Block(-5,32,0,STONE:0)
Block(-5,32,1,SMOOTH_BRICK:0)
Block(-5,32,2,SMOOTH_BRICK:0)
Block(-5,32,3,STATIONARY_LAVA:8)
Block(-5,32,4,CONCRETE:7)
Block(-5,32,5,STATIONARY_LAVA:0)
Block(-5,32,6,CONCRETE:15)
Block(-5,33,-7,STONE:0)
Block(-5,33,-6,STONE:0)
Block(-5,33,-5,STONE:0)
Block(-5,33,-4,STONE:0)
Block(-5,33,-3,STONE:0)
Block(-5,33,-2,STONE:0)
Block(-5,33,-1,STONE:0)
Block(-5,33,0,STONE:0)
Block(-5,33,1,REDSTONE_WIRE:15)
Block(-5,33,2,SMOOTH_BRICK:0)
Block(-5,33,3,STATIONARY_LAVA:0)
Block(-5,33,4,SMOOTH_BRICK:0)
Block(-5,33,5,CONCRETE:7)
Block(-5,33,6,CONCRETE:7)
Block(-5,34,-7,STONE:0)
Block(-5,34,-6,STONE:0)
Block(-5,34,-5,STONE:0)
Block(-5,34,-4,STONE:0)
Block(-5,34,-3,STONE:0)
Block(-5,34,-2,STONE:0)
Block(-5,34,-1,STONE:0)
Block(-5,34,0,STONE:0)
Block(-5,34,1,SMOOTH_BRICK:0)
Block(-5,34,2,SMOOTH_BRICK:0)
Block(-5,34,3,SMOOTH_BRICK:0)
Block(-5,34,4,SMOOTH_BRICK:0)
Block(-5,34,5,SMOOTH_BRICK:0)
Block(-5,34,6,SMOOTH_BRICK:0)
Block(-5,34,7,SMOOTH_BRICK:0)
Block(-5,34,8,CONCRETE:7)
Block(-5,35,-7,STONE:0)
Block(-5,35,-6,STONE:0)
Block(-5,35,-5,STONE:0)
Block(-5,35,-4,STONE:0)
Block(-5,35,-3,STONE:0)
Block(-5,35,-2,STONE:0)
Block(-5,35,-1,STONE:0)
Block(-5,35,0,STONE:0)
Block(-5,35,1,SMOOTH_BRICK:0)
Block(-5,35,2,SMOOTH_BRICK:0)
Block(-5,35,3,SMOOTH_BRICK:0)
Block(-5,35,4,SMOOTH_BRICK:0)
Block(-5,35,5,SMOOTH_BRICK:0)
Block(-5,35,6,SMOOTH_BRICK:0)
Block(-5,35,7,SMOOTH_BRICK:0)
Block(-5,35,8,CONCRETE:7)
Block(-5,36,-7,DIRT:0)
Block(-5,36,-6,DIRT:0)
Block(-5,36,-5,DIRT:0)
Block(-5,36,-4,DIRT:0)
Block(-5,36,-3,DIRT:0)
Block(-5,36,-2,DIRT:0)
Block(-5,36,-1,DIRT:0)
Block(-5,36,0,DIRT:0)
Block(-5,36,1,DIRT:0)
Block(-5,36,2,DIRT:0)
Block(-5,36,3,DIRT:0)
Block(-5,36,4,DIRT:0)
Block(-5,36,5,DIRT:0)
Block(-5,36,6,DIRT:0)
Block(-5,36,7,DIRT:0)
Block(-5,36,8,DIRT:0)
Block(-5,37,-7,DIRT:0)
Block(-5,37,-6,DIRT:0)
Block(-5,37,-5,DIRT:0)
Block(-5,37,-4,DIRT:0)
Block(-5,37,-3,DIRT:0)
Block(-5,37,-2,DIRT:0)
Block(-5,37,-1,DIRT:0)
Block(-5,37,0,DIRT:0)
Block(-5,37,1,DIRT:0)
Block(-5,37,2,DIRT:0)
Block(-5,37,3,DIRT:0)
Block(-5,37,4,DIRT:0)
Block(-5,37,5,DIRT:0)
Block(-5,37,6,DIRT:0)
Block(-5,37,7,DIRT:0)
Block(-5,37,8,DIRT:0)
Block(-5,38,-7,GRASS:0)
Block(-5,38,-6,DIRT:0)
Block(-5,38,-5,DIRT:0)
Block(-5,38,-4,DIRT:0)
Block(-5,38,-3,DIRT:0)
Block(-5,38,-2,DIRT:0)
Block(-5,38,-1,DIRT:0)
Block(-5,38,0,DIRT:0)
Block(-5,38,1,DIRT:0)
Block(-5,38,2,DIRT:0)
Block(-5,38,3,DIRT:0)
Block(-5,38,4,DIRT:0)
Block(-5,38,5,DIRT:0)
Block(-5,38,6,DIRT:0)
Block(-5,38,7,DIRT:0)
Block(-5,38,8,DIRT:0)
Block(-5,39,-6,GRASS:0)
Block(-5,39,-5,GRASS:0)
Block(-5,39,-4,GRASS:0)
Block(-5,39,-3,GRASS:0)
Block(-5,39,-2,GRASS:0)
Block(-5,39,-1,GRASS:0)
Block(-5,39,0,GRASS:0)
Block(-5,39,1,GRASS:0)
Block(-5,39,2,GRASS:0)
Block(-5,39,3,DIRT:0)
Block(-5,39,4,DIRT:0)
Block(-5,39,5,GRASS:0)
Block(-5,39,6,GRASS:0)
Block(-5,39,7,STONE:6)
Block(-5,39,8,GRASS:0)
Block(-5,40,-4,LONG_GRASS:1)
Block(-5,40,-3,LONG_GRASS:1)
Block(-5,40,-2,LONG_GRASS:1)
Block(-5,40,-1,LONG_GRASS:1)
Block(-5,40,0,LONG_GRASS:1)
Block(-5,40,1,LONG_GRASS:1)
RandomBlock(-5,40,2,AIR:0,20,CHEST:2,../../../Chests/Loot/JunkChest_1.nbt,10,CHEST:2,../../../Chests/Loot/JunkChest_2.nbt,10,CHEST:2,../../../Chests/Loot/JunkChest_3.nbt,10,CHEST:2,../../../Chests/Loot/JunkChest_4.nbt,10,CHEST:2,../../../Chests/Loot/JunkChest_5.nbt,10,CHEST:2,../../../Chests/Lore/village_1.nbt,1,CHEST:2,../../../Chests/Lore/village_2.nbt,1,CHEST:2,../../../Chests/Lore/village_3.nbt,1,CHEST:2,../../../Chests/Lore/village_4.nbt,1,CHEST:2,../../../Chests/Lore/village_5.nbt,1,CHEST:2,../../../Chests/Loot/Common1.nbt,10,CHEST:2,../../../Chests/Loot/Common2.nbt,10,CHEST:2,../../../Chests/Loot/Common3.nbt,10,CHEST:2,../../../Chests/Loot/Common4.nbt,10,CHEST:2,../../../Chests/Loot/Common5.nbt,10,CHEST:2,../../../Chests/Loot/Common6.nbt,10,CHEST:2,../../../Chests/Loot/Common7.nbt,10,CHEST:2,../../../Chests/Loot/Common8.nbt,10,CHEST:2,../../../Chests/Loot/Common9.nbt,10,CHEST:2,../../../Chests/Loot/Common10.nbt,10,CHEST:2,../../../Chests/Loot/Common10.nbt,11,CHEST:2,../../../Chests/Loot/Common12.nbt,10,CHEST:2,../../../Chests/Loot/Common13.nbt,10,CHEST:2,../../../Chests/Loot/Common14.nbt,10,CHEST:2,../../../Chests/Loot/Common15.nbt,10,CHEST:2,../../../Chests/Lore/village_1.nbt,2,CHEST:2,../../../Chests/Lore/village_3.nbt,2,CHEST:2,../../../Chests/Lore/village_4.nbt,2,CHEST:2,../../../Chests/Lore/village_5.nbt,2,CHEST:2,../../../Chests/Lore/village_5.nbt,2,CHEST:2,../../../Chests/Loot/Rare1.nbt,5,CHEST:2,../../../Chests/Loot/Rare2.nbt,5,CHEST:2,../../../Chests/Loot/Rare3.nbt,5,CHEST:2,../../../Chests/Loot/Rare4.nbt,5,CHEST:2,../../../Chests/Loot/Rare5.nbt,5,CHEST:2,../../../Chests/Loot/Rare6.nbt,5,CHEST:2,../../../Chests/Loot/Rare7.nbt,5,CHEST:2,../../../Chests/Loot/Rare8.nbt,5,CHEST:2,../../../Chests/Loot/Rare9.nbt,5,CHEST:2,../../../Chests/Loot/Rare10.nbt,5,CHEST:2,../../../Chests/Loot/Rare11.nbt,5,CHEST:2,../../../Chests/Loot/Rare12.nbt,5,CHEST:2,../../../Chests/Loot/Rare13.nbt,5,CHEST:2,../../../Chests/Loot/Rare14.nbt,5,CHEST:2,../../../Chests/Loot/Rare15.nbt,5,CHEST:2,../../../Chests/Loot/Epic1.nbt,2,CHEST:2,../../../Chests/Loot/Epic2.nbt,2,CHEST:2,../../../Chests/Loot/Epic3.nbt,2,CHEST:2,../../../Chests/Loot/Epic4.nbt,2,CHEST:2,../../../Chests/Loot/Epic5.nbt,2,CHEST:2,../../../Chests/Loot/Epic6.nbt,2,CHEST:2,../../../Chests/Loot/Epic7.nbt,2,CHEST:2,../../../Chests/Loot/Epic8.nbt,2,CHEST:2,../../../Chests/Loot/Epic9.nbt,2,CHEST:2,../../../Chests/Loot/Epic10.nbt,2,CHEST:2,../../../Chests/Loot/Epic11.nbt,2,CHEST:2,../../../Chests/Loot/Epic12.nbt,2,CHEST:2,../../../Chests/Loot/Epic13.nbt,2,CHEST:2,../../../Chests/Loot/Epic14.nbt,2,CHEST:2,../../../Chests/Loot/Epic15.nbt,5,CHEST:2,../../../Chests/Loot/Rare1.nbt,5,CHEST:2,../../../Chests/Loot/Rare2.nbt,5,CHEST:2,../../../Chests/Loot/Rare3.nbt,5,CHEST:2,../../../Chests/Loot/Rare4.nbt,5,CHEST:2,../../../Chests/Loot/Rare5.nbt,10,CHEST:2,../../../Chests/Loot/Rare6.nbt,10,CHEST:2,../../../Chests/Loot/Rare7.nbt,10,CHEST:2,../../../Chests/Loot/Rare8.nbt,10,CHEST:2,../../../Chests/Loot/Rare9.nbt,10,CHEST:2,../../../Chests/Loot/Rare10.nbt,15,CHEST:2,../../../Chests/Loot/Rare11.nbt,15,CHEST:2,../../../Chests/Loot/Rare12.nbt,15,CHEST:2,../../../Chests/Loot/Rare13.nbt,15,CHEST:2,../../../Chests/Loot/Rare14.nbt,15,CHEST:2,../../../Chests/Loot/Rare15.nbt,15,CHEST:2,../../../Chests/Loot/Epic15.nbt,100)
Block(-5,40,3,HAY_BLOCK:0)
Block(-5,40,4,HAY_BLOCK:0)
Block(-5,40,5,LONG_GRASS:1)
Block(-5,40,6,LONG_GRASS:1)
Block(-5,40,8,TRAP_DOOR:4)
Block(-5,41,3,HAY_BLOCK:0)
Block(-5,41,4,HAY_BLOCK:0)
Block(-5,48,-1,LOG_2:13)
Block(-5,49,0,LOG_2:13)
Block(-5,50,1,LOG_2:13)
Block(-5,50,3,LEAVES:0)
Block(-5,50,4,LEAVES:0)
Block(-5,50,5,LEAVES:0)
Block(-5,51,-5,LEAVES:0)
Block(-5,51,-4,LEAVES:0)
Block(-5,51,-3,LEAVES:0)
Block(-5,51,1,LOG_2:13)
Block(-5,51,3,LEAVES:0)
Block(-5,51,4,LEAVES:0)
Block(-5,51,5,LEAVES:0)
Block(-5,52,-6,LEAVES:0)
Block(-5,52,-5,LEAVES:0)
Block(-5,52,-4,LEAVES:0)
Block(-5,52,-3,LEAVES:0)
Block(-5,52,-2,LEAVES:0)
Block(-5,52,-1,LEAVES:0)
Block(-5,52,0,LOG_2:13)
Block(-5,52,1,LEAVES:0)
Block(-5,52,2,LOG_2:13)
Block(-5,52,3,LEAVES:0)
Block(-5,52,4,LEAVES:0)
Block(-5,52,5,LEAVES:0)
Block(-5,53,-5,LEAVES:0)
Block(-5,53,-4,LEAVES:0)
Block(-5,53,-3,LEAVES:0)
Block(-5,53,-2,LEAVES:0)
Block(-5,53,-1,LEAVES:0)
Block(-5,53,0,LOG_2:13)
Block(-5,53,1,LEAVES:0)
Block(-5,53,2,LOG_2:13)
Block(-5,53,3,LEAVES:0)
Block(-5,53,4,LEAVES:0)
Block(-5,53,5,LEAVES:0)
Block(-5,54,-4,LEAVES:0)
Block(-5,54,-3,LEAVES:0)
Block(-5,54,-2,LEAVES:0)
Block(-5,54,-1,LEAVES:0)
Block(-5,54,0,LOG_2:13)
Block(-5,54,1,LEAVES:0)
Block(-5,54,2,LEAVES:0)
Block(-5,54,3,LEAVES:0)
Block(-5,54,4,LEAVES:0)
Block(-5,54,5,LEAVES:0)
Block(-5,55,-4,LEAVES:0)
Block(-5,55,-3,LEAVES:0)
Block(-5,55,-2,LEAVES:0)
Block(-5,55,-1,LEAVES:0)
Block(-5,55,0,LOG:0)
Block(-5,55,1,LEAVES:0)
Block(-5,55,2,LEAVES:0)
Block(-5,55,3,LEAVES:0)
Block(-5,55,4,LEAVES:0)
Block(-5,55,5,LEAVES:0)
Block(-5,56,-3,LEAVES:0)
Block(-5,56,-2,LEAVES:0)
Block(-5,56,-1,LEAVES:0)
Block(-5,56,0,LEAVES:0)
Block(-5,56,1,LEAVES:0)
Block(-5,56,2,LEAVES:0)
Block(-5,56,3,LEAVES:0)
Block(-5,56,4,LEAVES:0)
Block(-5,57,-3,LEAVES:0)
Block(-5,57,-2,LEAVES:0)
Block(-5,57,-1,LEAVES:0)
Block(-5,57,0,LEAVES:0)
Block(-5,57,1,LEAVES:0)
Block(-5,57,2,LEAVES:0)
Block(-5,58,-1,LEAVES:0)
Block(-5,58,1,LEAVES:0)
Block(-4,0,-7,STONE:0)
Block(-4,0,-6,STONE:0)
Block(-4,0,-5,STONE:0)
Block(-4,0,-4,STONE:0)
Block(-4,0,-3,STONE:0)
Block(-4,0,-2,STONE:0)
Block(-4,0,-1,STONE:0)
Block(-4,0,0,STONE:0)
Block(-4,0,1,STONE:0)
Block(-4,0,2,STONE:0)
Block(-4,0,3,STONE:0)
Block(-4,0,4,STONE:0)
Block(-4,0,5,STONE:0)
Block(-4,0,6,STONE:0)
Block(-4,0,7,STONE:0)
Block(-4,0,8,STONE:0)
Block(-4,1,-7,STONE:0)
Block(-4,1,-6,STONE:0)
Block(-4,1,-5,STONE:0)
Block(-4,1,-4,STONE:0)
Block(-4,1,-3,STONE:0)
Block(-4,1,-2,STONE:0)
Block(-4,1,-1,STONE:0)
Block(-4,1,0,STONE:0)
Block(-4,1,1,STONE:0)
Block(-4,1,2,STONE:0)
Block(-4,1,3,STONE:0)
Block(-4,1,4,STONE:0)
Block(-4,1,5,STONE:0)
Block(-4,1,6,STONE:0)
Block(-4,1,7,STONE:0)
Block(-4,1,8,STONE:0)
Block(-4,2,-7,STONE:0)
Block(-4,2,-6,STONE:0)
Block(-4,2,-5,STONE:0)
Block(-4,2,-4,STONE:0)
Block(-4,2,-3,STONE:0)
Block(-4,2,-2,STONE:0)
Block(-4,2,-1,STONE:0)
Block(-4,2,0,STONE:0)
Block(-4,2,1,STONE:0)
Block(-4,2,2,STONE:0)
Block(-4,2,3,STONE:0)
Block(-4,2,4,STONE:0)
Block(-4,2,5,STONE:0)
Block(-4,2,6,STONE:0)
Block(-4,2,7,STONE:0)
Block(-4,2,8,STONE:0)
Block(-4,3,-7,STONE:0)
Block(-4,3,-6,STONE:0)
Block(-4,3,-5,STONE:0)
Block(-4,3,-4,STONE:0)
Block(-4,3,-3,STONE:0)
Block(-4,3,-2,STONE:0)
Block(-4,3,-1,STONE:0)
Block(-4,3,0,STONE:0)
Block(-4,3,1,STONE:0)
Block(-4,3,2,STONE:0)
Block(-4,3,3,STONE:0)
Block(-4,3,4,STONE:0)
Block(-4,3,5,STONE:0)
Block(-4,3,6,STONE:0)
Block(-4,3,7,STONE:0)
Block(-4,3,8,STONE:0)
Block(-4,4,-7,STONE:0)
Block(-4,4,-6,STONE:0)
Block(-4,4,-5,STONE:0)
Block(-4,4,-4,STONE:0)
Block(-4,4,-3,STONE:0)
Block(-4,4,-2,STONE:0)
Block(-4,4,-1,STONE:0)
Block(-4,4,0,STONE:0)
Block(-4,4,1,STONE:0)
Block(-4,4,2,STONE:0)
Block(-4,4,3,STONE:0)
Block(-4,4,4,STONE:0)
Block(-4,4,5,STONE:0)
Block(-4,4,6,STONE:0)
Block(-4,4,7,STONE:0)
Block(-4,4,8,STONE:0)
Block(-4,5,-7,STONE:0)
Block(-4,5,-6,STONE:0)
Block(-4,5,-5,STONE:0)
Block(-4,5,-4,STONE:0)
Block(-4,5,-3,STONE:0)
Block(-4,5,-2,STONE:0)
Block(-4,5,-1,STONE:0)
Block(-4,5,0,STONE:0)
Block(-4,5,1,STONE:0)
Block(-4,5,2,STONE:0)
Block(-4,5,3,STONE:0)
Block(-4,5,4,STONE:0)
Block(-4,5,5,STONE:0)
Block(-4,5,6,STONE:0)
Block(-4,5,7,STONE:0)
Block(-4,5,8,STONE:0)
Block(-4,6,-7,STONE:0)
Block(-4,6,-6,STONE:0)
Block(-4,6,-5,STONE:0)
Block(-4,6,-4,STONE:0)
Block(-4,6,-3,STONE:0)
Block(-4,6,-2,STONE:0)
Block(-4,6,-1,STONE:0)
Block(-4,6,0,STONE:0)
Block(-4,6,1,STONE:0)
Block(-4,6,2,STONE:0)
Block(-4,6,3,STONE:0)
Block(-4,6,4,STONE:0)
Block(-4,6,5,STONE:0)
Block(-4,6,6,STONE:0)
Block(-4,6,7,STONE:0)
Block(-4,6,8,STONE:0)
Block(-4,7,-7,STONE:0)
Block(-4,7,-6,STONE:0)
Block(-4,7,-5,STONE:0)
Block(-4,7,-4,STONE:0)
Block(-4,7,-3,STONE:0)
Block(-4,7,-2,STONE:0)
Block(-4,7,-1,STONE:0)
Block(-4,7,0,STONE:0)
Block(-4,7,1,STONE:0)
Block(-4,7,2,STONE:0)
Block(-4,7,3,STONE:0)
Block(-4,7,4,STONE:0)
Block(-4,7,5,STONE:0)
Block(-4,7,6,STONE:0)
Block(-4,7,7,STONE:0)
Block(-4,7,8,STONE:0)
Block(-4,8,-7,STONE:0)
Block(-4,8,-6,STONE:0)
Block(-4,8,-5,STONE:0)
Block(-4,8,-4,STONE:0)
Block(-4,8,-3,STONE:0)
Block(-4,8,-2,STONE:0)
Block(-4,8,-1,STONE:0)
Block(-4,8,0,STONE:0)
Block(-4,8,1,STONE:0)
Block(-4,8,2,STONE:0)
Block(-4,8,3,STONE:0)
Block(-4,8,4,STONE:0)
Block(-4,8,5,STONE:0)
Block(-4,8,6,STONE:0)
Block(-4,8,7,STONE:0)
Block(-4,8,8,STONE:0)
Block(-4,9,-7,STONE:0)
Block(-4,9,-6,STONE:0)
Block(-4,9,-5,STONE:0)
Block(-4,9,-4,STONE:0)
Block(-4,9,-3,STONE:0)
Block(-4,9,-2,STONE:0)
Block(-4,9,-1,STONE:0)
Block(-4,9,0,STONE:0)
Block(-4,9,1,STONE:0)
Block(-4,9,2,STONE:0)
Block(-4,9,3,STONE:0)
Block(-4,9,4,STONE:0)
Block(-4,9,5,STONE:0)
Block(-4,9,6,STONE:0)
Block(-4,9,7,STONE:0)
Block(-4,9,8,STONE:0)
Block(-4,10,-7,STONE:0)
Block(-4,10,-6,STONE:0)
Block(-4,10,-5,STONE:0)
Block(-4,10,-4,STONE:0)
Block(-4,10,-3,STONE:0)
Block(-4,10,-2,STONE:0)
Block(-4,10,-1,STONE:0)
Block(-4,10,0,STONE:0)
Block(-4,10,1,STONE:0)
Block(-4,10,2,STONE:0)
Block(-4,10,3,STONE:0)
Block(-4,10,4,STONE:0)
Block(-4,10,5,STONE:0)
Block(-4,10,6,STONE:0)
Block(-4,10,7,STONE:0)
Block(-4,10,8,STONE:0)
Block(-4,11,-7,STONE:0)
Block(-4,11,-6,STONE:0)
Block(-4,11,-5,STONE:0)
Block(-4,11,-4,STONE:0)
Block(-4,11,-3,STONE:0)
Block(-4,11,-2,STONE:0)
Block(-4,11,-1,STONE:0)
Block(-4,11,0,STONE:0)
Block(-4,11,1,STONE:0)
Block(-4,11,2,STONE:0)
Block(-4,11,3,STONE:0)
Block(-4,11,4,STONE:0)
Block(-4,11,5,STONE:0)
Block(-4,11,6,STONE:0)
Block(-4,11,7,STONE:0)
Block(-4,11,8,STONE:0)
Block(-4,12,-7,STONE:0)
Block(-4,12,-6,STONE:0)
Block(-4,12,-5,STONE:0)
Block(-4,12,-4,STONE:0)
Block(-4,12,-3,STONE:0)
Block(-4,12,-2,STONE:0)
Block(-4,12,-1,STONE:0)
Block(-4,12,0,STONE:0)
Block(-4,12,1,STONE:0)
Block(-4,12,2,STONE:0)
Block(-4,12,3,STONE:0)
Block(-4,12,4,STONE:0)
Block(-4,12,5,STONE:0)
Block(-4,12,6,STONE:0)
Block(-4,12,7,STONE:0)
Block(-4,12,8,STONE:0)
Block(-4,13,-7,STONE:0)
Block(-4,13,-6,STONE:0)
Block(-4,13,-5,STONE:0)
Block(-4,13,-4,STONE:0)
Block(-4,13,-3,STONE:0)
Block(-4,13,-2,STONE:0)
Block(-4,13,-1,STONE:0)
Block(-4,13,0,STONE:0)
Block(-4,13,1,STONE:0)
Block(-4,13,2,STONE:0)
Block(-4,13,3,STONE:0)
Block(-4,13,4,STONE:0)
Block(-4,13,5,STONE:0)
Block(-4,13,6,STONE:0)
Block(-4,13,7,STONE:0)
Block(-4,13,8,STONE:0)
Block(-4,14,-7,STONE:0)
Block(-4,14,-6,STONE:0)
Block(-4,14,-5,STONE:0)
Block(-4,14,-4,STONE:0)
Block(-4,14,-3,STONE:0)
Block(-4,14,-2,STONE:0)
Block(-4,14,-1,STONE:0)
Block(-4,14,0,STONE:0)
Block(-4,14,1,STONE:0)
Block(-4,14,2,STONE:0)
Block(-4,14,3,STONE:0)
Block(-4,14,4,STONE:0)
Block(-4,14,5,STONE:0)
Block(-4,14,6,STONE:0)
Block(-4,14,7,STONE:0)
Block(-4,14,8,STONE:0)
Block(-4,15,-7,STONE:0)
Block(-4,15,-6,STONE:0)
Block(-4,15,-5,STONE:0)
Block(-4,15,-4,STONE:0)
Block(-4,15,-3,STONE:0)
Block(-4,15,-2,STONE:0)
Block(-4,15,-1,STONE:0)
Block(-4,15,0,STONE:0)
Block(-4,15,1,STONE:0)
Block(-4,15,2,STONE:0)
Block(-4,15,3,STONE:0)
Block(-4,15,4,STONE:0)
Block(-4,15,5,STONE:0)
Block(-4,15,6,SMOOTH_BRICK:0)
Block(-4,15,7,STONE:0)
Block(-4,15,8,DIODE_BLOCK_OFF:1)
Block(-4,16,-7,STONE:0)
Block(-4,16,-6,STONE:0)
Block(-4,16,-5,STONE:0)
Block(-4,16,-4,STONE:0)
Block(-4,16,-3,STONE:0)
Block(-4,16,-2,STONE:0)
Block(-4,16,-1,STONE:0)
Block(-4,16,0,STONE:0)
Block(-4,16,1,STONE:0)
Block(-4,16,2,STONE:0)
Block(-4,16,3,STONE:0)
Block(-4,16,4,STONE:0)
Block(-4,16,5,STONE:0)
Block(-4,16,6,REDSTONE_WIRE:0)
Block(-4,16,7,STONE:0)
Block(-4,16,8,SMOOTH_BRICK:0)
Block(-4,17,-7,STONE:0)
Block(-4,17,-6,STONE:0)
Block(-4,17,-5,STONE:0)
Block(-4,17,-4,STONE:0)
Block(-4,17,-3,STONE:0)
Block(-4,17,-2,STONE:0)
Block(-4,17,-1,STONE:0)
Block(-4,17,0,STONE:0)
Block(-4,17,1,STONE:0)
Block(-4,17,2,STONE:0)
Block(-4,17,3,STONE:0)
Block(-4,17,4,STONE:0)
Block(-4,17,5,STONE:0)
Block(-4,17,7,STONE:0)
Block(-4,18,-7,STONE:0)
Block(-4,18,-6,STONE:0)
Block(-4,18,-5,STONE:0)
Block(-4,18,-4,MAGMA:0)
Block(-4,18,-3,MAGMA:0)
Block(-4,18,-2,STONE:0)
Block(-4,18,-1,STONE:0)
Block(-4,18,0,STONE:0)
Block(-4,18,1,STONE:0)
Block(-4,18,2,STONE:0)
Block(-4,18,3,REDSTONE_WIRE:0)
Block(-4,18,4,REDSTONE_WIRE:0)
Block(-4,18,6,PISTON_STICKY_BASE:9)
Block(-4,18,7,SMOOTH_BRICK:0)
Block(-4,18,8,SMOOTH_BRICK:0)
Block(-4,19,-7,STONE:0)
Block(-4,19,-6,CONCRETE:7)
Block(-4,19,-5,CONCRETE:7)
Block(-4,19,-4,STAINED_GLASS:15)
Block(-4,19,-3,STAINED_GLASS:15)
Block(-4,19,-2,CONCRETE:7)
Block(-4,19,-1,CONCRETE:7)
Block(-4,19,0,CONCRETE:7)
Block(-4,19,1,CONCRETE:7)
Block(-4,19,2,CONCRETE:7)
Block(-4,19,3,CONCRETE:7)
Block(-4,19,4,CONCRETE:7)
Block(-4,19,5,CONCRETE:15)
Block(-4,19,6,PISTON_MOVING_PIECE:9)
Block(-4,19,7,REDSTONE_WIRE:12)
Block(-4,20,-7,CONCRETE:15)
Block(-4,20,-4,CARPET:14)
Block(-4,20,-3,CARPET:14)
Block(-4,20,0,CONCRETE:15)
Block(-4,20,1,STONE:3)
Block(-4,20,2,CONCRETE:7)
Block(-4,20,6,SMOOTH_STAIRS:2)
Block(-4,20,7,PISTON_STICKY_BASE:1)
Block(-4,20,8,SMOOTH_BRICK:0)
Block(-4,21,-7,CONCRETE:15)
Block(-4,21,0,CONCRETE:15)
Block(-4,21,1,CONCRETE:7)
Block(-4,21,2,CONCRETE:7)
Block(-4,21,7,SMOOTH_STAIRS:2)
Block(-4,21,8,REDSTONE_WIRE:0)
Block(-4,22,-7,CONCRETE:15)
Block(-4,22,0,CONCRETE:15)
Block(-4,22,1,REDSTONE_WIRE:0)
Block(-4,22,2,CONCRETE:7)
Block(-4,22,8,SMOOTH_BRICK:0)
Block(-4,23,-7,CONCRETE:15)
Block(-4,23,0,CONCRETE:15)
Block(-4,23,1,STONE:3)
Block(-4,23,2,CONCRETE:7)
Block(-4,23,8,SMOOTH_STAIRS:2)
Block(-4,24,-7,CONCRETE:15)
Block(-4,24,0,CONCRETE:15)
Block(-4,24,1,STONE:3)
Block(-4,24,2,CONCRETE:7)
Block(-4,24,8,SMOOTH_STAIRS:6)
Block(-4,25,-7,CONCRETE:15)
Block(-4,25,0,CONCRETE:15)
Block(-4,25,1,STONE:3)
Block(-4,25,2,CONCRETE:7)
Block(-4,25,8,DOUBLE_STEP:0)
Block(-4,26,-7,CONCRETE:15)
Block(-4,26,-5,WALL_BANNER:5,../NBT/DaerocVillage/1173-bannerC208R176.nbt)
Block(-4,26,-2,WALL_BANNER:5,../NBT/DaerocVillage/1174-bannerC208R176.nbt)
Block(-4,26,0,CONCRETE:15)
Block(-4,26,1,STONE:3)
Block(-4,26,2,CONCRETE:7)
Block(-4,27,-7,STONE:0)
Block(-4,27,-6,SMOOTH_STAIRS:7)
Block(-4,27,-1,SMOOTH_STAIRS:6)
Block(-4,27,0,SMOOTH_BRICK:0)
Block(-4,27,1,STONE:3)
Block(-4,27,2,CONCRETE:7)
Block(-4,28,-7,STONE:0)
Block(-4,28,-6,SMOOTH_BRICK:0)
Block(-4,28,-5,SMOOTH_BRICK:0)
Block(-4,28,-4,STEP:8)
Block(-4,28,-3,STEP:8)
Block(-4,28,-2,SMOOTH_BRICK:0)
Block(-4,28,-1,SMOOTH_BRICK:0)
Block(-4,28,0,SMOOTH_BRICK:0)
Block(-4,28,1,STONE:3)
Block(-4,28,2,CONCRETE:7)
Block(-4,29,-7,STONE:0)
Block(-4,29,-6,SMOOTH_BRICK:0)
Block(-4,29,-5,SMOOTH_BRICK:0)
Block(-4,29,-4,SMOOTH_BRICK:0)
Block(-4,29,-3,SMOOTH_BRICK:0)
Block(-4,29,-2,SMOOTH_BRICK:0)
Block(-4,29,-1,SMOOTH_BRICK:0)
Block(-4,29,0,STONE:3)
Block(-4,29,1,STONE:3)
Block(-4,29,2,SMOOTH_BRICK:0)
Block(-4,30,-7,STONE:0)
Block(-4,30,-6,STONE:0)
Block(-4,30,-5,STONE:0)
Block(-4,30,-4,STONE:0)
Block(-4,30,-3,STONE:0)
Block(-4,30,-2,STONE:0)
Block(-4,30,-1,SMOOTH_BRICK:0)
Block(-4,30,0,STONE:3)
Block(-4,30,1,STONE:3)
Block(-4,30,2,SMOOTH_BRICK:0)
Block(-4,30,5,STEP:8)
Block(-4,31,-7,STONE:0)
Block(-4,31,-6,STONE:0)
Block(-4,31,-5,STONE:0)
Block(-4,31,-4,STONE:0)
Block(-4,31,-3,STONE:0)
Block(-4,31,-2,STONE:0)
Block(-4,31,-1,STONE:0)
Block(-4,31,0,STONE:0)
Block(-4,31,1,STONE:0)
Block(-4,31,2,STONE:0)
Block(-4,31,3,CONCRETE:7)
Block(-4,31,4,CONCRETE:7)
Block(-4,31,5,CONCRETE:7)
Block(-4,31,6,SMOOTH_STAIRS:7)
Block(-4,32,-7,STONE:0)
Block(-4,32,-6,STONE:0)
Block(-4,32,-5,STONE:0)
Block(-4,32,-4,STONE:0)
Block(-4,32,-3,STONE:0)
Block(-4,32,-2,STONE:0)
Block(-4,32,-1,STONE:0)
Block(-4,32,0,STONE:0)
Block(-4,32,1,SMOOTH_BRICK:0)
Block(-4,32,2,SMOOTH_BRICK:0)
Block(-4,32,3,SMOOTH_BRICK:0)
Block(-4,32,4,CONCRETE:7)
Block(-4,32,5,STATIONARY_LAVA:0)
Block(-4,32,6,COBBLE_WALL:0)
Block(-4,33,-7,STONE:0)
Block(-4,33,-6,STONE:0)
Block(-4,33,-5,STONE:0)
Block(-4,33,-4,STONE:0)
Block(-4,33,-3,STONE:0)
Block(-4,33,-2,STONE:0)
Block(-4,33,-1,STONE:0)
Block(-4,33,0,STONE:0)
Block(-4,33,1,DIODE_BLOCK_ON:3)
Block(-4,33,2,SMOOTH_BRICK:0)
Block(-4,33,3,SMOOTH_BRICK:0)
Block(-4,33,4,SMOOTH_BRICK:0)
Block(-4,33,5,CONCRETE:7)
Block(-4,33,6,CONCRETE:7)
Block(-4,34,-7,STONE:0)
Block(-4,34,-6,STONE:0)
Block(-4,34,-5,STONE:0)
Block(-4,34,-4,STONE:0)
Block(-4,34,-3,STONE:0)
Block(-4,34,-2,STONE:0)
Block(-4,34,-1,STONE:0)
Block(-4,34,0,STONE:0)
Block(-4,34,1,SMOOTH_BRICK:0)
Block(-4,34,2,SMOOTH_BRICK:0)
Block(-4,34,3,SMOOTH_BRICK:0)
Block(-4,34,4,SMOOTH_BRICK:0)
Block(-4,34,5,SMOOTH_BRICK:0)
Block(-4,34,6,SMOOTH_BRICK:0)
Block(-4,34,7,CONCRETE:7)
Block(-4,34,8,CONCRETE:7)
Block(-4,35,-7,STONE:0)
Block(-4,35,-6,STONE:0)
Block(-4,35,-5,STONE:0)
Block(-4,35,-4,STONE:0)
Block(-4,35,-3,STONE:0)
Block(-4,35,-2,STONE:0)
Block(-4,35,-1,STONE:0)
Block(-4,35,0,STONE:0)
Block(-4,35,1,SMOOTH_BRICK:0)
Block(-4,35,2,SMOOTH_BRICK:0)
Block(-4,35,3,SMOOTH_BRICK:0)
Block(-4,35,4,SMOOTH_BRICK:0)
Block(-4,35,5,SMOOTH_BRICK:0)
Block(-4,35,6,SMOOTH_BRICK:0)
Block(-4,35,7,CONCRETE:7)
Block(-4,35,8,CONCRETE:7)
Block(-4,36,-7,DIRT:0)
Block(-4,36,-6,DIRT:0)
Block(-4,36,-5,DIRT:0)
Block(-4,36,-4,DIRT:0)
Block(-4,36,-3,DIRT:0)
Block(-4,36,-2,DIRT:0)
Block(-4,36,-1,DIRT:0)
Block(-4,36,0,DIRT:0)
Block(-4,36,1,DIRT:0)
Block(-4,36,2,DIRT:0)
Block(-4,36,3,DIRT:0)
Block(-4,36,4,DIRT:0)
Block(-4,36,5,DIRT:0)
Block(-4,36,6,DIRT:0)
Block(-4,36,7,DIRT:0)
Block(-4,36,8,DIRT:0)
Block(-4,37,-7,DIRT:0)
Block(-4,37,-6,DIRT:0)
Block(-4,37,-5,DIRT:0)
Block(-4,37,-4,DIRT:0)
Block(-4,37,-3,DIRT:0)
Block(-4,37,-2,DIRT:0)
Block(-4,37,-1,DIRT:0)
Block(-4,37,0,DIRT:0)
Block(-4,37,1,DIRT:0)
Block(-4,37,2,DIRT:0)
Block(-4,37,3,DIRT:0)
Block(-4,37,4,DIRT:0)
Block(-4,37,5,DIRT:0)
Block(-4,37,6,DIRT:0)
Block(-4,37,7,DIRT:0)
Block(-4,37,8,DIRT:0)
Block(-4,38,-7,GRASS:0)
Block(-4,38,-6,DIRT:0)
Block(-4,38,-5,DIRT:0)
Block(-4,38,-4,DIRT:0)
Block(-4,38,-3,DIRT:0)
Block(-4,38,-2,DIRT:0)
Block(-4,38,-1,DIRT:0)
Block(-4,38,0,DIRT:0)
Block(-4,38,1,DIRT:0)
Block(-4,38,2,DIRT:0)
Block(-4,38,3,DIRT:0)
Block(-4,38,4,DIRT:0)
Block(-4,38,5,DIRT:0)
Block(-4,38,6,DIRT:0)
Block(-4,38,7,DIRT:0)
Block(-4,38,8,DIRT:0)
Block(-4,39,-6,GRASS:0)
Block(-4,39,-5,GRASS:0)
Block(-4,39,-4,GRASS:0)
Block(-4,39,-3,GRASS:0)
Block(-4,39,-2,GRASS:0)
Block(-4,39,-1,DIRT:0)
Block(-4,39,0,GRASS:0)
Block(-4,39,1,DIRT:0)
Block(-4,39,2,GRASS:0)
Block(-4,39,3,GRASS:0)
Block(-4,39,4,DIRT:0)
Block(-4,39,5,DIRT:0)
Block(-4,39,6,GRASS:0)
Block(-4,39,7,GRASS:0)
Block(-4,39,8,GRASS:0)
Block(-4,40,-4,LONG_GRASS:1)
Block(-4,40,-3,LONG_GRASS:1)
Block(-4,40,-2,LONG_GRASS:1)
Block(-4,40,-1,LOG_2:13)
Block(-4,40,1,LOG_2:13)
Block(-4,40,3,LONG_GRASS:1)
Block(-4,40,4,HAY_BLOCK:0)
Block(-4,40,5,HAY_BLOCK:8)
Block(-4,41,4,HAY_BLOCK:0)
Block(-4,47,-1,LOG_2:13)
Block(-4,49,-6,LEAVES:0)
Block(-4,50,-6,LEAVES:0)
Block(-4,50,4,LEAVES:0)
Block(-4,51,-6,LEAVES:0)
Block(-4,51,-5,LOG_2:13)
Block(-4,51,-4,LEAVES:0)
Block(-4,51,3,LEAVES:0)
Block(-4,51,4,LEAVES:0)
Block(-4,51,5,LEAVES:0)
Block(-4,52,-7,LEAVES:0)
Block(-4,52,-6,LEAVES:0)
Block(-4,52,-5,LOG_2:13)
Block(-4,52,-4,LEAVES:0)
Block(-4,52,-3,LEAVES:0)
Block(-4,52,0,LEAVES:0)
Block(-4,52,2,LEAVES:0)
Block(-4,52,3,LEAVES:0)
Block(-4,52,4,LEAVES:0)
Block(-4,52,5,LEAVES:0)
Block(-4,53,-6,LEAVES:0)
Block(-4,53,-5,LEAVES:0)
Block(-4,53,-4,LEAVES:0)
Block(-4,53,-3,LEAVES:0)
Block(-4,53,-2,LEAVES:0)
Block(-4,53,-1,LEAVES:0)
Block(-4,53,0,LEAVES:0)
Block(-4,53,1,LEAVES:0)
Block(-4,53,2,LEAVES:0)
Block(-4,53,3,LEAVES:0)
Block(-4,53,4,LEAVES:0)
Block(-4,53,5,LEAVES:0)
Block(-4,53,6,LEAVES:0)
Block(-4,54,-5,LEAVES:0)
Block(-4,54,-4,LEAVES:0)
Block(-4,54,-3,LEAVES:0)
Block(-4,54,-2,LEAVES:0)
Block(-4,54,-1,LEAVES:0)
Block(-4,54,0,LEAVES:0)
Block(-4,54,1,LEAVES:0)
Block(-4,54,2,LEAVES:0)
Block(-4,54,3,LEAVES:0)
Block(-4,54,4,LEAVES:0)
Block(-4,54,5,LEAVES:0)
Block(-4,55,-4,LEAVES:0)
Block(-4,55,-3,LEAVES:0)
Block(-4,55,-2,LEAVES:0)
Block(-4,55,-1,LEAVES:0)
Block(-4,55,0,LEAVES:0)
Block(-4,55,1,LEAVES:0)
Block(-4,55,2,LOG:0)
Block(-4,55,3,LEAVES:0)
Block(-4,55,4,LEAVES:0)
Block(-4,55,5,LEAVES:0)
Block(-4,56,-5,LEAVES:0)
Block(-4,56,-4,LEAVES:0)
Block(-4,56,-3,LEAVES:0)
Block(-4,56,-2,LEAVES:0)
Block(-4,56,-1,LEAVES:0)
Block(-4,56,0,LEAVES:0)
Block(-4,56,1,LEAVES:0)
Block(-4,56,2,LEAVES:0)
Block(-4,56,3,LEAVES:0)
Block(-4,56,4,LEAVES:0)
Block(-4,57,-4,LEAVES:0)
Block(-4,57,-3,LEAVES:0)
Block(-4,57,-2,LEAVES:0)
Block(-4,57,-1,LEAVES:0)
Block(-4,57,0,LEAVES:0)
Block(-4,57,1,LEAVES:0)
Block(-4,57,2,LEAVES:0)
Block(-4,58,-3,LEAVES:0)
Block(-4,58,-1,LEAVES:0)
Block(-4,58,0,LEAVES:0)
Block(-4,58,1,LEAVES:0)
Block(-4,58,2,LEAVES:0)
Block(-3,0,-7,STONE:0)
Block(-3,0,-6,STONE:0)
Block(-3,0,-5,STONE:0)
Block(-3,0,-4,STONE:0)
Block(-3,0,-3,STONE:0)
Block(-3,0,-2,STONE:0)
Block(-3,0,-1,STONE:0)
Block(-3,0,0,STONE:0)
Block(-3,0,1,STONE:0)
Block(-3,0,2,STONE:0)
Block(-3,0,3,STONE:0)
Block(-3,0,4,STONE:0)
Block(-3,0,5,STONE:0)
Block(-3,0,6,STONE:0)
Block(-3,0,7,STONE:0)
Block(-3,0,8,STONE:0)
Block(-3,1,-7,STONE:0)
Block(-3,1,-6,STONE:0)
Block(-3,1,-5,STONE:0)
Block(-3,1,-4,STONE:0)
Block(-3,1,-3,STONE:0)
Block(-3,1,-2,STONE:0)
Block(-3,1,-1,STONE:0)
Block(-3,1,0,STONE:0)
Block(-3,1,1,STONE:0)
Block(-3,1,2,STONE:0)
Block(-3,1,3,STONE:0)
Block(-3,1,4,STONE:0)
Block(-3,1,5,STONE:0)
Block(-3,1,6,STONE:0)
Block(-3,1,7,STONE:0)
Block(-3,1,8,STONE:0)
Block(-3,2,-7,STONE:0)
Block(-3,2,-6,STONE:0)
Block(-3,2,-5,STONE:0)
Block(-3,2,-4,STONE:0)
Block(-3,2,-3,STONE:0)
Block(-3,2,-2,STONE:0)
Block(-3,2,-1,STONE:0)
Block(-3,2,0,STONE:0)
Block(-3,2,1,STONE:0)
Block(-3,2,2,STONE:0)
Block(-3,2,3,STONE:0)
Block(-3,2,4,STONE:0)
Block(-3,2,5,STONE:0)
Block(-3,2,6,STONE:0)
Block(-3,2,7,STONE:0)
Block(-3,2,8,STONE:0)
Block(-3,3,-7,STONE:0)
Block(-3,3,-6,STONE:0)
Block(-3,3,-5,STONE:0)
Block(-3,3,-4,STONE:0)
Block(-3,3,-3,STONE:0)
Block(-3,3,-2,STONE:0)
Block(-3,3,-1,STONE:0)
Block(-3,3,0,STONE:0)
Block(-3,3,1,STONE:0)
Block(-3,3,2,STONE:0)
Block(-3,3,3,STONE:0)
Block(-3,3,4,STONE:0)
Block(-3,3,5,STONE:0)
Block(-3,3,6,STONE:0)
Block(-3,3,7,STONE:0)
Block(-3,3,8,STONE:0)
Block(-3,4,-7,STONE:0)
Block(-3,4,-6,STONE:0)
Block(-3,4,-5,STONE:0)
Block(-3,4,-4,STONE:0)
Block(-3,4,-3,STONE:0)
Block(-3,4,-2,STONE:0)
Block(-3,4,-1,STONE:0)
Block(-3,4,0,STONE:0)
Block(-3,4,1,STONE:0)
Block(-3,4,2,STONE:0)
Block(-3,4,3,STONE:0)
Block(-3,4,4,STONE:0)
Block(-3,4,5,STONE:0)
Block(-3,4,6,STONE:0)
Block(-3,4,7,STONE:0)
Block(-3,4,8,STONE:0)
Block(-3,5,-7,STONE:0)
Block(-3,5,-6,STONE:0)
Block(-3,5,-5,STONE:0)
Block(-3,5,-4,STONE:0)
Block(-3,5,-3,STONE:0)
Block(-3,5,-2,STONE:0)
Block(-3,5,-1,STONE:0)
Block(-3,5,0,STONE:0)
Block(-3,5,1,STONE:0)
Block(-3,5,2,STONE:0)
Block(-3,5,3,STONE:0)
Block(-3,5,4,STONE:0)
Block(-3,5,5,STONE:0)
Block(-3,5,6,STONE:0)
Block(-3,5,7,STONE:0)
Block(-3,5,8,STONE:0)
Block(-3,6,-7,STONE:0)
Block(-3,6,-6,STONE:0)
Block(-3,6,-5,STONE:0)
Block(-3,6,-4,STONE:0)
Block(-3,6,-3,STONE:0)
Block(-3,6,-2,STONE:0)
Block(-3,6,-1,STONE:0)
Block(-3,6,0,STONE:0)
Block(-3,6,1,STONE:0)
Block(-3,6,2,STONE:0)
Block(-3,6,3,STONE:0)
Block(-3,6,4,STONE:0)
Block(-3,6,5,STONE:0)
Block(-3,6,6,STONE:0)
Block(-3,6,7,STONE:0)
Block(-3,6,8,STONE:0)
Block(-3,7,-7,STONE:0)
Block(-3,7,-6,STONE:0)
Block(-3,7,-5,STONE:0)
Block(-3,7,-4,STONE:0)
Block(-3,7,-3,STONE:0)
Block(-3,7,-2,STONE:0)
Block(-3,7,-1,STONE:0)
Block(-3,7,0,STONE:0)
Block(-3,7,1,STONE:0)
Block(-3,7,2,STONE:0)
Block(-3,7,3,STONE:0)
Block(-3,7,4,STONE:0)
Block(-3,7,5,STONE:0)
Block(-3,7,6,STONE:0)
Block(-3,7,7,STONE:0)
Block(-3,7,8,STONE:0)
Block(-3,8,-7,STONE:0)
Block(-3,8,-6,STONE:0)
Block(-3,8,-5,STONE:0)
Block(-3,8,-4,STONE:0)
Block(-3,8,-3,STONE:0)
Block(-3,8,-2,STONE:0)
Block(-3,8,-1,STONE:0)
Block(-3,8,0,STONE:0)
Block(-3,8,1,STONE:0)
Block(-3,8,2,STONE:0)
Block(-3,8,3,STONE:0)
Block(-3,8,4,STONE:0)
Block(-3,8,5,STONE:0)
Block(-3,8,6,STONE:0)
Block(-3,8,7,STONE:0)
Block(-3,8,8,STONE:0)
Block(-3,9,-7,STONE:0)
Block(-3,9,-6,STONE:0)
Block(-3,9,-5,STONE:0)
Block(-3,9,-4,STONE:0)
Block(-3,9,-3,STONE:0)
Block(-3,9,-2,STONE:0)
Block(-3,9,-1,STONE:0)
Block(-3,9,0,STONE:0)
Block(-3,9,1,STONE:0)
Block(-3,9,2,STONE:0)
Block(-3,9,3,STONE:0)
Block(-3,9,4,STONE:0)
Block(-3,9,5,STONE:0)
Block(-3,9,6,STONE:0)
Block(-3,9,7,STONE:0)
Block(-3,9,8,STONE:0)
Block(-3,10,-7,STONE:0)
Block(-3,10,-6,STONE:0)
Block(-3,10,-5,STONE:0)
Block(-3,10,-4,STONE:0)
Block(-3,10,-3,STONE:0)
Block(-3,10,-2,STONE:0)
Block(-3,10,-1,STONE:0)
Block(-3,10,0,STONE:0)
Block(-3,10,1,STONE:0)
Block(-3,10,2,STONE:0)
Block(-3,10,3,STONE:0)
Block(-3,10,4,STONE:0)
Block(-3,10,5,STONE:0)
Block(-3,10,6,STONE:0)
Block(-3,10,7,STONE:0)
Block(-3,10,8,STONE:0)
Block(-3,11,-7,STONE:0)
Block(-3,11,-6,STONE:0)
Block(-3,11,-5,STONE:0)
Block(-3,11,-4,STONE:0)
Block(-3,11,-3,STONE:0)
Block(-3,11,-2,STONE:0)
Block(-3,11,-1,STONE:0)
Block(-3,11,0,STONE:0)
Block(-3,11,1,STONE:0)
Block(-3,11,2,STONE:0)
Block(-3,11,3,STONE:0)
Block(-3,11,4,STONE:0)
Block(-3,11,5,STONE:0)
Block(-3,11,6,STONE:0)
Block(-3,11,7,STONE:0)
Block(-3,11,8,STONE:0)
Block(-3,12,-7,STONE:0)
Block(-3,12,-6,STONE:0)
Block(-3,12,-5,STONE:0)
Block(-3,12,-4,STONE:0)
Block(-3,12,-3,STONE:0)
Block(-3,12,-2,STONE:0)
Block(-3,12,-1,STONE:0)
Block(-3,12,0,STONE:0)
Block(-3,12,1,STONE:0)
Block(-3,12,2,STONE:0)
Block(-3,12,3,STONE:0)
Block(-3,12,4,STONE:0)
Block(-3,12,5,STONE:0)
Block(-3,12,6,STONE:0)
Block(-3,12,7,STONE:0)
Block(-3,12,8,STONE:0)
Block(-3,13,-7,STONE:0)
Block(-3,13,-6,STONE:0)
Block(-3,13,-5,STONE:0)
Block(-3,13,-4,STONE:0)
Block(-3,13,-3,STONE:0)
Block(-3,13,-2,STONE:0)
Block(-3,13,-1,STONE:0)
Block(-3,13,0,STONE:0)
Block(-3,13,1,STONE:0)
Block(-3,13,2,STONE:0)
Block(-3,13,3,STONE:0)
Block(-3,13,4,STONE:0)
Block(-3,13,5,STONE:0)
Block(-3,13,6,STONE:0)
Block(-3,13,7,STONE:0)
Block(-3,13,8,STONE:0)
Block(-3,14,-7,STONE:0)
Block(-3,14,-6,STONE:0)
Block(-3,14,-5,STONE:0)
Block(-3,14,-4,STONE:0)
Block(-3,14,-3,STONE:0)
Block(-3,14,-2,STONE:0)
Block(-3,14,-1,STONE:0)
Block(-3,14,0,STONE:0)
Block(-3,14,1,STONE:0)
Block(-3,14,2,STONE:0)
Block(-3,14,3,STONE:0)
Block(-3,14,4,STONE:0)
Block(-3,14,5,STONE:0)
Block(-3,14,6,STONE:0)
Block(-3,14,7,STONE:0)
Block(-3,14,8,STONE:0)
Block(-3,15,-7,STONE:0)
Block(-3,15,-6,STONE:0)
Block(-3,15,-5,STONE:0)
Block(-3,15,-4,STONE:0)
Block(-3,15,-3,STONE:0)
Block(-3,15,-2,STONE:0)
Block(-3,15,-1,STONE:0)
Block(-3,15,0,STONE:0)
Block(-3,15,1,STONE:0)
Block(-3,15,2,STONE:0)
Block(-3,15,3,STONE:0)
Block(-3,15,4,STONE:0)
Block(-3,15,5,STONE:0)
Block(-3,15,8,REDSTONE_WIRE:0)
Block(-3,16,-7,STONE:0)
Block(-3,16,-6,STONE:0)
Block(-3,16,-5,STONE:0)
Block(-3,16,-4,STONE:0)
Block(-3,16,-3,STONE:0)
Block(-3,16,-2,STONE:0)
Block(-3,16,-1,STONE:0)
Block(-3,16,0,STONE:0)
Block(-3,16,1,STONE:0)
Block(-3,16,2,STONE:0)
Block(-3,16,3,STONE:0)
Block(-3,16,4,STONE:0)
Block(-3,16,5,STONE:0)
Block(-3,16,6,SMOOTH_BRICK:0)
Block(-3,16,8,SMOOTH_BRICK:0)
Block(-3,17,-7,STONE:0)
Block(-3,17,-6,STONE:0)
Block(-3,17,-5,STONE:0)
Block(-3,17,-4,STONE:0)
Block(-3,17,-3,STONE:0)
Block(-3,17,-2,STONE:0)
Block(-3,17,-1,STONE:0)
Block(-3,17,0,STONE:0)
Block(-3,17,1,STONE:0)
Block(-3,17,2,STONE:0)
Block(-3,17,3,STONE:0)
Block(-3,17,4,STONE:0)
Block(-3,17,5,STONE:0)
Block(-3,17,6,REDSTONE_WIRE:0)
Block(-3,18,-7,STONE:0)
Block(-3,18,-6,STONE:0)
Block(-3,18,-5,STONE:0)
Block(-3,18,-4,MAGMA:0)
Block(-3,18,-3,MAGMA:0)
Block(-3,18,-2,STONE:0)
Block(-3,18,-1,STONE:0)
Block(-3,18,0,STONE:0)
Block(-3,18,1,STONE:0)
Block(-3,18,2,STONE:0)
Block(-3,18,3,REDSTONE_WIRE:0)
Block(-3,18,4,REDSTONE_WIRE:0)
Block(-3,18,6,PISTON_STICKY_BASE:9)
Block(-3,18,7,SMOOTH_BRICK:0)
Block(-3,18,8,SMOOTH_BRICK:0)
Block(-3,19,-7,STONE:0)
Block(-3,19,-6,CONCRETE:7)
Block(-3,19,-5,CONCRETE:7)
Block(-3,19,-4,STAINED_GLASS:15)
Block(-3,19,-3,STAINED_GLASS:15)
Block(-3,19,-2,CONCRETE:7)
Block(-3,19,-1,CONCRETE:7)
Block(-3,19,0,CONCRETE:7)
Block(-3,19,1,CONCRETE:7)
Block(-3,19,2,CONCRETE:7)
Block(-3,19,3,CONCRETE:7)
Block(-3,19,4,CONCRETE:7)
Block(-3,19,5,CONCRETE:15)
Block(-3,19,6,PISTON_MOVING_PIECE:9)
Block(-3,19,7,REDSTONE_WIRE:13)
Block(-3,20,-7,CONCRETE:15)
Block(-3,20,-4,CARPET:14)
Block(-3,20,-3,CARPET:14)
Block(-3,20,0,CONCRETE:15)
Block(-3,20,1,STONE:3)
Block(-3,20,2,CONCRETE:7)
Block(-3,20,6,SMOOTH_STAIRS:2)
Block(-3,20,7,PISTON_STICKY_BASE:1)
Block(-3,20,8,SMOOTH_BRICK:0)
Block(-3,21,-7,CONCRETE:15)
Block(-3,21,0,CONCRETE:15)
Block(-3,21,1,CONCRETE:7)
Block(-3,21,2,CONCRETE:15)
Block(-3,21,7,SMOOTH_STAIRS:2)
Block(-3,21,8,REDSTONE_WIRE:0)
Block(-3,22,-7,CONCRETE:15)
Block(-3,22,0,CONCRETE:15)
Block(-3,22,1,REDSTONE_WIRE:0)
Block(-3,22,2,SMOOTH_STAIRS:3)
Block(-3,22,8,STEP:0)
Block(-3,23,-7,CONCRETE:15)
Block(-3,23,0,CONCRETE:15)
Block(-3,23,1,STONE:3)
Block(-3,24,-7,CONCRETE:15)
Block(-3,24,0,CONCRETE:15)
Block(-3,24,1,STONE:3)
Block(-3,25,-7,CONCRETE:15)
Block(-3,25,0,CONCRETE:15)
Block(-3,25,1,STONE:3)
Block(-3,25,8,STEP:0)
Block(-3,26,-7,CONCRETE:15)
Block(-3,26,0,CONCRETE:15)
Block(-3,26,1,STONE:3)
Block(-3,26,2,WALL_BANNER:3,../NBT/DaerocVillage/1194-bannerC208R176.nbt)
Block(-3,27,-7,STONE:0)
Block(-3,27,-6,SMOOTH_STAIRS:7)
Block(-3,27,-1,SMOOTH_STAIRS:6)
Block(-3,27,0,CONCRETE:7)
Block(-3,27,1,STONE:3)
Block(-3,28,-7,STONE:0)
Block(-3,28,-6,SMOOTH_BRICK:0)
Block(-3,28,-5,SMOOTH_BRICK:0)
Block(-3,28,-4,STEP:8)
Block(-3,28,-3,STEP:8)
Block(-3,28,-2,SMOOTH_BRICK:0)
Block(-3,28,-1,SMOOTH_BRICK:0)
Block(-3,28,0,CONCRETE:7)
Block(-3,28,1,STONE:3)
Block(-3,28,2,SMOOTH_STAIRS:7)
Block(-3,29,-7,STONE:0)
Block(-3,29,-6,SMOOTH_BRICK:0)
Block(-3,29,-5,SMOOTH_BRICK:0)
Block(-3,29,-4,SMOOTH_BRICK:0)
Block(-3,29,-3,SMOOTH_BRICK:0)
Block(-3,29,-2,SMOOTH_BRICK:0)
Block(-3,29,-1,SMOOTH_BRICK:0)
Block(-3,29,0,STONE:3)
Block(-3,29,1,STONE:3)
Block(-3,29,2,CONCRETE:7)
Block(-3,29,3,SMOOTH_STAIRS:7)
Block(-3,30,-7,STONE:0)
Block(-3,30,-6,STONE:0)
Block(-3,30,-5,STONE:0)
Block(-3,30,-4,STONE:0)
Block(-3,30,-3,STONE:0)
Block(-3,30,-2,STONE:0)
Block(-3,30,-1,SMOOTH_BRICK:0)
Block(-3,30,0,STONE:3)
Block(-3,30,1,PISTON_STICKY_BASE:11)
Block(-3,30,2,PISTON_MOVING_PIECE:11)
Block(-3,30,3,CONCRETE:15)
Block(-3,30,5,STEP:8)
Block(-3,31,-7,STONE:0)
Block(-3,31,-6,STONE:0)
Block(-3,31,-5,STONE:0)
Block(-3,31,-4,STONE:0)
Block(-3,31,-3,STONE:0)
Block(-3,31,-2,STONE:0)
Block(-3,31,-1,STONE:0)
Block(-3,31,0,STONE:0)
Block(-3,31,1,PISTON_STICKY_BASE:11)
Block(-3,31,2,PISTON_MOVING_PIECE:11)
Block(-3,31,3,CONCRETE:7)
Block(-3,31,4,CONCRETE:7)
Block(-3,31,5,CONCRETE:7)
Block(-3,31,6,SMOOTH_STAIRS:7)
Block(-3,32,-7,STONE:0)
Block(-3,32,-6,STONE:0)
Block(-3,32,-5,STONE:0)
Block(-3,32,-4,STONE:0)
Block(-3,32,-3,STONE:0)
Block(-3,32,-2,STONE:0)
Block(-3,32,-1,STONE:0)
Block(-3,32,0,STONE:0)
Block(-3,32,1,SMOOTH_BRICK:0)
Block(-3,32,2,SMOOTH_BRICK:0)
Block(-3,32,3,STATIONARY_LAVA:8)
Block(-3,32,4,CONCRETE:7)
Block(-3,32,5,STATIONARY_LAVA:0)
Block(-3,32,6,CONCRETE:15)
Block(-3,33,-7,STONE:0)
Block(-3,33,-6,STONE:0)
Block(-3,33,-5,STONE:0)
Block(-3,33,-4,STONE:0)
Block(-3,33,-3,STONE:0)
Block(-3,33,-2,STONE:0)
Block(-3,33,-1,STONE:0)
Block(-3,33,0,STONE:0)
Block(-3,33,1,REDSTONE_WIRE:15)
Block(-3,33,2,SMOOTH_BRICK:0)
Block(-3,33,3,STATIONARY_LAVA:0)
Block(-3,33,4,CONCRETE:7)
Block(-3,33,5,CONCRETE:7)
Block(-3,33,6,CONCRETE:7)
Block(-3,34,-7,STONE:0)
Block(-3,34,-6,STONE:0)
Block(-3,34,-5,STONE:0)
Block(-3,34,-4,STONE:0)
Block(-3,34,-3,STONE:0)
Block(-3,34,-2,STONE:0)
Block(-3,34,-1,STONE:0)
Block(-3,34,0,STONE:0)
Block(-3,34,1,SMOOTH_BRICK:0)
Block(-3,34,2,SMOOTH_BRICK:0)
Block(-3,34,3,SMOOTH_BRICK:0)
Block(-3,34,4,SMOOTH_BRICK:0)
Block(-3,34,5,CONCRETE:7)
Block(-3,34,6,CONCRETE:7)
Block(-3,34,7,CONCRETE:7)
Block(-3,34,8,CONCRETE:7)
Block(-3,35,-7,STONE:0)
Block(-3,35,-6,STONE:0)
Block(-3,35,-5,STONE:0)
Block(-3,35,-4,STONE:0)
Block(-3,35,-3,STONE:0)
Block(-3,35,-2,STONE:0)
Block(-3,35,-1,STONE:0)
Block(-3,35,0,STONE:0)
Block(-3,35,1,SMOOTH_BRICK:0)
Block(-3,35,2,SMOOTH_BRICK:0)
Block(-3,35,3,SMOOTH_BRICK:0)
Block(-3,35,4,SMOOTH_BRICK:0)
Block(-3,35,5,SMOOTH_BRICK:0)
Block(-3,35,6,SMOOTH_BRICK:0)
Block(-3,35,7,CONCRETE:7)
Block(-3,35,8,CONCRETE:7)
Block(-3,36,-7,DIRT:0)
Block(-3,36,-6,DIRT:0)
Block(-3,36,-5,DIRT:0)
Block(-3,36,-4,DIRT:0)
Block(-3,36,-3,DIRT:0)
Block(-3,36,-2,DIRT:0)
Block(-3,36,-1,DIRT:0)
Block(-3,36,0,DIRT:0)
Block(-3,36,1,DIRT:0)
Block(-3,36,2,DIRT:0)
Block(-3,36,3,DIRT:0)
Block(-3,36,4,DIRT:0)
Block(-3,36,5,DIRT:0)
Block(-3,36,6,DIRT:0)
Block(-3,36,7,DIRT:0)
Block(-3,36,8,DIRT:0)
Block(-3,37,-7,DIRT:0)
Block(-3,37,-6,DIRT:0)
Block(-3,37,-5,DIRT:0)
Block(-3,37,-4,DIRT:0)
Block(-3,37,-3,DIRT:0)
Block(-3,37,-2,DIRT:0)
Block(-3,37,-1,DIRT:0)
Block(-3,37,0,DIRT:0)
Block(-3,37,1,DIRT:0)
Block(-3,37,2,DIRT:0)
Block(-3,37,3,DIRT:0)
Block(-3,37,4,DIRT:0)
Block(-3,37,5,DIRT:0)
Block(-3,37,6,DIRT:0)
Block(-3,37,7,DIRT:0)
Block(-3,37,8,DIRT:0)
Block(-3,38,-7,GRASS:0)
Block(-3,38,-6,GRASS:0)
Block(-3,38,-5,DIRT:0)
Block(-3,38,-4,DIRT:0)
Block(-3,38,-3,DIRT:0)
Block(-3,38,-2,DIRT:0)
Block(-3,38,-1,DIRT:0)
Block(-3,38,0,DIRT:0)
Block(-3,38,1,DIRT:0)
Block(-3,38,2,DIRT:0)
Block(-3,38,3,DIRT:0)
Block(-3,38,4,DIRT:0)
Block(-3,38,5,DIRT:0)
Block(-3,38,6,DIRT:0)
Block(-3,38,7,DIRT:0)
Block(-3,38,8,DIRT:0)
Block(-3,39,-5,GRASS:0)
Block(-3,39,-4,GRASS:0)
Block(-3,39,-3,DIRT:0)
Block(-3,39,-2,GRASS:0)
Block(-3,39,-1,DIRT:0)
Block(-3,39,0,DIRT:0)
Block(-3,39,1,GRASS:0)
Block(-3,39,2,GRASS:0)
Block(-3,39,3,GRASS:0)
Block(-3,39,4,GRASS:0)
Block(-3,39,5,GRASS:0)
Block(-3,39,6,LOG:0)
Block(-3,39,7,COBBLESTONE:0)
Block(-3,39,8,GRASS:0)
Block(-3,40,-4,LONG_GRASS:1)
Block(-3,40,-3,LOG_2:13)
Block(-3,40,-2,LONG_GRASS:1)
Block(-3,40,-1,LOG_2:13)
Block(-3,40,0,LOG_2:13)
Block(-3,40,3,LONG_GRASS:1)
Block(-3,40,4,LONG_GRASS:1)
Block(-3,40,6,LOG:0)
Block(-3,40,7,COBBLESTONE:0)
Block(-3,40,8,COBBLESTONE_STAIRS:4)
Block(-3,41,-1,LOG_2:13)
Block(-3,41,0,LOG_2:13)
Block(-3,41,6,LOG:0)
Block(-3,41,7,DARK_OAK_FENCE:0)
Block(-3,41,8,SPRUCE_FENCE:0)
Block(-3,42,-1,LOG_2:13)
Block(-3,42,6,WOOD_PLATE:0)
Block(-3,43,-1,LOG_2:13)
Block(-3,45,0,LOG_2:13)
Block(-3,46,-1,LOG_2:13)
Block(-3,46,0,LOG_2:13)
Block(-3,47,-1,LOG_2:13)
Block(-3,50,-7,LEAVES:0)
Block(-3,50,-6,LEAVES:0)
Block(-3,50,-5,LOG_2:13)
Block(-3,51,-7,LEAVES:0)
Block(-3,51,-6,LEAVES:0)
Block(-3,51,-5,LEAVES:0)
Block(-3,51,3,LEAVES:0)
Block(-3,51,4,LEAVES:0)
Block(-3,51,5,LEAVES:0)
Block(-3,52,-7,LEAVES:0)
Block(-3,52,-6,LEAVES:0)
Block(-3,52,-5,LEAVES:0)
Block(-3,52,-4,LEAVES:0)
Block(-3,52,-1,LOG_2:13)
Block(-3,52,3,LEAVES:0)
Block(-3,52,4,LEAVES:0)
Block(-3,52,5,LOG:0)
Block(-3,52,6,LEAVES:0)
Block(-3,53,-7,LEAVES:0)
Block(-3,53,-6,LEAVES:0)
Block(-3,53,-5,LEAVES:0)
Block(-3,53,-4,LEAVES:0)
Block(-3,53,-1,LOG_2:13)
Block(-3,53,1,LEAVES:0)
Block(-3,53,2,LEAVES:0)
Block(-3,53,3,LEAVES:0)
Block(-3,53,4,LEAVES:0)
Block(-3,53,5,LOG:0)
Block(-3,53,6,LEAVES:0)
Block(-3,54,-6,LEAVES:0)
Block(-3,54,-5,LEAVES:0)
Block(-3,54,-4,LEAVES:0)
Block(-3,54,-3,LEAVES:0)
Block(-3,54,-2,LOG_2:13)
Block(-3,54,-1,LOG_2:13)
Block(-3,54,0,LEAVES:0)
Block(-3,54,1,LEAVES:0)
Block(-3,54,2,LOG:0)
Block(-3,54,3,LEAVES:0)
Block(-3,54,4,LEAVES:0)
Block(-3,54,5,LEAVES:0)
Block(-3,54,6,LEAVES:0)
Block(-3,55,-5,LEAVES:0)
Block(-3,55,-4,LEAVES:0)
Block(-3,55,-3,LOG_2:13)
Block(-3,55,-2,LEAVES:0)
Block(-3,55,-1,LOG:0)
Block(-3,55,0,LEAVES:0)
Block(-3,55,1,LEAVES:0)
Block(-3,55,2,LEAVES:0)
Block(-3,55,3,LEAVES:0)
Block(-3,55,4,LEAVES:0)
Block(-3,55,5,LEAVES:0)
Block(-3,56,-6,LEAVES:0)
Block(-3,56,-5,LEAVES:0)
Block(-3,56,-4,LEAVES:0)
Block(-3,56,-3,LEAVES:0)
Block(-3,56,-2,LEAVES:0)
Block(-3,56,-1,LEAVES:0)
Block(-3,56,0,LEAVES:0)
Block(-3,56,1,LEAVES:0)
Block(-3,56,2,LEAVES:0)
Block(-3,56,3,LEAVES:0)
Block(-3,56,4,LEAVES:0)
Block(-3,56,5,LEAVES:0)
Block(-3,57,-5,LEAVES:0)
Block(-3,57,-4,LEAVES:0)
Block(-3,57,-3,LEAVES:0)
Block(-3,57,-2,LEAVES:0)
Block(-3,57,-1,LEAVES:0)
Block(-3,57,0,LEAVES:0)
Block(-3,57,1,LEAVES:0)
Block(-3,57,2,LEAVES:0)
Block(-3,57,3,LEAVES:0)
Block(-3,57,4,LEAVES:0)
Block(-3,57,5,LEAVES:0)
Block(-3,58,-4,LEAVES:0)
Block(-3,58,-3,LEAVES:0)
Block(-3,58,-2,LEAVES:0)
Block(-3,58,-1,LEAVES:0)
Block(-3,58,0,LEAVES:0)
Block(-3,58,1,LEAVES:0)
Block(-3,58,2,LEAVES:0)
Block(-3,58,3,LEAVES:0)
Block(-3,59,-1,LEAVES:0)
Block(-2,0,-7,STONE:0)
Block(-2,0,-6,STONE:0)
Block(-2,0,-5,STONE:0)
Block(-2,0,-4,STONE:0)
Block(-2,0,-3,STONE:0)
Block(-2,0,-2,STONE:0)
Block(-2,0,-1,STONE:0)
Block(-2,0,0,STONE:0)
Block(-2,0,1,STONE:0)
Block(-2,0,2,STONE:0)
Block(-2,0,3,STONE:0)
Block(-2,0,4,STONE:0)
Block(-2,0,5,STONE:0)
Block(-2,0,6,STONE:0)
Block(-2,0,7,STONE:0)
Block(-2,0,8,STONE:0)
Block(-2,1,-7,STONE:0)
Block(-2,1,-6,STONE:0)
Block(-2,1,-5,STONE:0)
Block(-2,1,-4,STONE:0)
Block(-2,1,-3,STONE:0)
Block(-2,1,-2,STONE:0)
Block(-2,1,-1,STONE:0)
Block(-2,1,0,STONE:0)
Block(-2,1,1,STONE:0)
Block(-2,1,2,STONE:0)
Block(-2,1,3,STONE:0)
Block(-2,1,4,STONE:0)
Block(-2,1,5,STONE:0)
Block(-2,1,6,STONE:0)
Block(-2,1,7,STONE:0)
Block(-2,1,8,STONE:0)
Block(-2,2,-7,STONE:0)
Block(-2,2,-6,STONE:0)
Block(-2,2,-5,STONE:0)
Block(-2,2,-4,STONE:0)
Block(-2,2,-3,STONE:0)
Block(-2,2,-2,STONE:0)
Block(-2,2,-1,STONE:0)
Block(-2,2,0,STONE:0)
Block(-2,2,1,STONE:0)
Block(-2,2,2,STONE:0)
Block(-2,2,3,STONE:0)
Block(-2,2,4,STONE:0)
Block(-2,2,5,STONE:0)
Block(-2,2,6,STONE:0)
Block(-2,2,7,STONE:0)
Block(-2,2,8,STONE:0)
Block(-2,3,-7,STONE:0)
Block(-2,3,-6,STONE:0)
Block(-2,3,-5,STONE:0)
Block(-2,3,-4,STONE:0)
Block(-2,3,-3,STONE:0)
Block(-2,3,-2,STONE:0)
Block(-2,3,-1,STONE:0)
Block(-2,3,0,STONE:0)
Block(-2,3,1,STONE:0)
Block(-2,3,2,STONE:0)
Block(-2,3,3,STONE:0)
Block(-2,3,4,STONE:0)
Block(-2,3,5,STONE:0)
Block(-2,3,6,STONE:0)
Block(-2,3,7,STONE:0)
Block(-2,3,8,STONE:0)
Block(-2,4,-7,STONE:0)
Block(-2,4,-6,STONE:0)
Block(-2,4,-5,STONE:0)
Block(-2,4,-4,STONE:0)
Block(-2,4,-3,STONE:0)
Block(-2,4,-2,STONE:0)
Block(-2,4,-1,STONE:0)
Block(-2,4,0,STONE:0)
Block(-2,4,1,STONE:0)
Block(-2,4,2,STONE:0)
Block(-2,4,3,STONE:0)
Block(-2,4,4,STONE:0)
Block(-2,4,5,STONE:0)
Block(-2,4,6,STONE:0)
Block(-2,4,7,STONE:0)
Block(-2,4,8,STONE:0)
Block(-2,5,-7,STONE:0)
Block(-2,5,-6,STONE:0)
Block(-2,5,-5,STONE:0)
Block(-2,5,-4,STONE:0)
Block(-2,5,-3,STONE:0)
Block(-2,5,-2,STONE:0)
Block(-2,5,-1,STONE:0)
Block(-2,5,0,STONE:0)
Block(-2,5,1,STONE:0)
Block(-2,5,2,STONE:0)
Block(-2,5,3,STONE:0)
Block(-2,5,4,STONE:0)
Block(-2,5,5,STONE:0)
Block(-2,5,6,STONE:0)
