Author: NLBlackEagle
Description: No description given
SettingsMode: WriteDisable
Frequency: 0
SpawnHeight: highestBlock
UseCenterForHighestBlock: true
MinHeight: 0
MaxHeight: 256
InheritBO3: 
InheritBO3Rotation: NORTH
OverrideChildSettings: true
OverrideParentHeight: false
CanOverride: false
BranchFrequency: 0
BranchFrequencyGroup: 
MustBeBelowOther: false
MustBeInside: 
CannotBeInside: 
ReplacesBO3: 
MustBeInsideWorldBorders: false
CanSpawnOnWater: true
SpawnOnWaterOnly: false
SpawnUnderWater: false
SpawnAtWaterLevel: false
HeightOffset: 0
RemoveAir: true
ReplaceAbove: 
ReplaceBelow: 
ReplaceWithBiomeBlocks: true
ReplaceWithSurfaceBlock: GRASS
ReplaceWithGroundBlock: DIRT
ReplaceWithStoneBlock: STONE
SmoothRadius: 0
SmoothHeightOffset: 0
SmoothStartTop: false
SmoothStartWood: false
SmoothingSurfaceBlock: 
SmoothingGroundBlock: 
BO3Group: 
IsSpawnPoint: false
DoReplaceBlocks: true
Block(-8,0,-7,STONE:0)
Block(-8,0,-6,STONE:0)
Block(-8,0,-5,STONE:0)
Block(-8,0,-4,STONE:0)
Block(-8,0,-3,STONE:0)
Block(-8,0,-2,STONE:0)
Block(-8,0,-1,STONE:0)
Block(-8,0,0,STONE:0)
Block(-8,0,1,STONE:0)
Block(-8,0,2,STONE:0)
Block(-8,0,3,STONE:0)
Block(-8,0,4,STONE:0)
Block(-8,0,5,STONE:0)
Block(-8,0,6,STONE:0)
Block(-8,0,7,STONE:0)
Block(-8,0,8,STONE:0)
Block(-8,1,-7,STONE:0)
Block(-8,1,-6,STONE:0)
Block(-8,1,-5,STONE:0)
Block(-8,1,-4,STONE:0)
Block(-8,1,-3,STONE:0)
Block(-8,1,-2,STONE:0)
Block(-8,1,-1,STONE:0)
Block(-8,1,0,STONE:0)
Block(-8,1,1,STONE:0)
Block(-8,1,2,STONE:0)
Block(-8,1,3,STONE:0)
Block(-8,1,4,STONE:0)
Block(-8,1,5,STONE:0)
Block(-8,1,6,STONE:0)
Block(-8,1,7,STONE:0)
Block(-8,1,8,STONE:0)
Block(-8,2,-7,STONE:0)
Block(-8,2,-6,STONE:0)
Block(-8,2,-5,STONE:0)
Block(-8,2,-4,STONE:0)
Block(-8,2,-3,STONE:0)
Block(-8,2,-2,STONE:0)
Block(-8,2,-1,STONE:0)
Block(-8,2,0,STONE:0)
Block(-8,2,1,STONE:0)
Block(-8,2,2,STONE:0)
Block(-8,2,3,STONE:0)
Block(-8,2,4,STONE:0)
Block(-8,2,5,STONE:0)
Block(-8,2,6,STONE:0)
Block(-8,2,7,STONE:0)
Block(-8,2,8,STONE:0)
Block(-8,3,-7,STONE:0)
Block(-8,3,-6,STONE:0)
Block(-8,3,-5,STONE:0)
Block(-8,3,-4,STONE:0)
Block(-8,3,-3,STONE:0)
Block(-8,3,-2,STONE:0)
Block(-8,3,-1,STONE:0)
Block(-8,3,0,STONE:0)
Block(-8,3,1,STONE:0)
Block(-8,3,2,STONE:0)
Block(-8,3,3,STONE:0)
Block(-8,3,4,STONE:0)
Block(-8,3,5,STONE:0)
Block(-8,3,6,STONE:0)
Block(-8,3,7,STONE:0)
Block(-8,3,8,STONE:0)
Block(-8,4,-7,STONE:0)
Block(-8,4,-6,STONE:0)
Block(-8,4,-5,STONE:0)
Block(-8,4,-4,STONE:0)
Block(-8,4,-3,STONE:0)
Block(-8,4,-2,STONE:0)
Block(-8,4,-1,STONE:0)
Block(-8,4,0,STONE:0)
Block(-8,4,1,STONE:0)
Block(-8,4,2,STONE:0)
Block(-8,4,3,STONE:0)
Block(-8,4,4,STONE:0)
Block(-8,4,5,STONE:0)
Block(-8,4,6,STONE:0)
Block(-8,4,7,STONE:0)
Block(-8,4,8,STONE:0)
Block(-8,5,-7,STONE:0)
Block(-8,5,-6,STONE:0)
Block(-8,5,-5,STONE:0)
Block(-8,5,-4,STONE:0)
Block(-8,5,-3,STONE:0)
Block(-8,5,-2,STONE:0)
Block(-8,5,-1,STONE:0)
Block(-8,5,0,STONE:0)
Block(-8,5,1,STONE:0)
Block(-8,5,2,STONE:0)
Block(-8,5,3,STONE:0)
Block(-8,5,4,STONE:0)
Block(-8,5,5,STONE:0)
Block(-8,5,6,STONE:0)
Block(-8,5,7,STONE:0)
Block(-8,5,8,STONE:0)
Block(-8,6,-7,STONE:0)
Block(-8,6,-6,STONE:0)
Block(-8,6,-5,STONE:0)
Block(-8,6,-4,STONE:0)
Block(-8,6,-3,STONE:0)
Block(-8,6,-2,STONE:0)
Block(-8,6,-1,STONE:0)
Block(-8,6,0,STONE:0)
Block(-8,6,1,STONE:0)
Block(-8,6,2,STONE:0)
Block(-8,6,3,STONE:0)
Block(-8,6,4,STONE:0)
Block(-8,6,5,STONE:0)
Block(-8,6,6,STONE:0)
Block(-8,6,7,STONE:0)
Block(-8,6,8,STONE:0)
Block(-8,7,-7,STONE:0)
Block(-8,7,-6,STONE:0)
Block(-8,7,-5,STONE:0)
Block(-8,7,-4,STONE:0)
Block(-8,7,-3,STONE:0)
Block(-8,7,-2,STONE:0)
Block(-8,7,-1,STONE:0)
Block(-8,7,0,STONE:0)
Block(-8,7,1,STONE:0)
Block(-8,7,2,STONE:0)
Block(-8,7,3,STONE:0)
Block(-8,7,4,STONE:0)
Block(-8,7,5,STONE:0)
Block(-8,7,6,STONE:0)
Block(-8,7,7,STONE:0)
Block(-8,7,8,STONE:0)
Block(-8,8,-7,STONE:0)
Block(-8,8,-6,STONE:0)
Block(-8,8,-5,STONE:0)
Block(-8,8,-4,STONE:0)
Block(-8,8,-3,STONE:0)
Block(-8,8,-2,STONE:0)
Block(-8,8,-1,STONE:0)
Block(-8,8,0,STONE:0)
Block(-8,8,1,STONE:0)
Block(-8,8,2,STONE:0)
Block(-8,8,3,STONE:0)
Block(-8,8,4,STONE:0)
Block(-8,8,5,STONE:0)
Block(-8,8,6,STONE:0)
Block(-8,8,7,STONE:0)
Block(-8,8,8,STONE:0)
Block(-8,9,-7,STONE:0)
Block(-8,9,-6,STONE:0)
Block(-8,9,-5,STONE:0)
Block(-8,9,-4,STONE:0)
Block(-8,9,-3,STONE:0)
Block(-8,9,-2,STONE:0)
Block(-8,9,-1,STONE:0)
Block(-8,9,0,STONE:0)
Block(-8,9,1,STONE:0)
Block(-8,9,2,STONE:0)
Block(-8,9,3,STONE:0)
Block(-8,9,4,STONE:0)
Block(-8,9,5,STONE:0)
Block(-8,9,6,STONE:0)
Block(-8,9,7,STONE:0)
Block(-8,9,8,STONE:0)
Block(-8,10,-7,STONE:0)
Block(-8,10,-6,STONE:0)
Block(-8,10,-5,STONE:0)
Block(-8,10,-4,STONE:0)
Block(-8,10,-3,STONE:0)
Block(-8,10,-2,STONE:0)
Block(-8,10,-1,STONE:0)
Block(-8,10,0,STONE:0)
Block(-8,10,1,STONE:0)
Block(-8,10,2,STONE:0)
Block(-8,10,3,STONE:0)
Block(-8,10,4,STONE:0)
Block(-8,10,5,STONE:0)
Block(-8,10,6,STONE:0)
Block(-8,10,7,STONE:0)
Block(-8,10,8,STONE:0)
Block(-8,11,-7,STONE:0)
Block(-8,11,-6,STONE:0)
Block(-8,11,-5,STONE:0)
Block(-8,11,-4,STONE:0)
Block(-8,11,-3,STONE:0)
Block(-8,11,-2,STONE:0)
Block(-8,11,-1,STONE:0)
Block(-8,11,0,STONE:0)
Block(-8,11,1,STONE:0)
Block(-8,11,2,STONE:0)
Block(-8,11,3,STONE:0)
Block(-8,11,4,STONE:0)
Block(-8,11,5,STONE:0)
Block(-8,11,6,STONE:0)
Block(-8,11,7,STONE:0)
Block(-8,11,8,STONE:0)
Block(-8,12,-7,STONE:0)
Block(-8,12,-6,STONE:0)
Block(-8,12,-5,STONE:0)
Block(-8,12,-4,STONE:0)
Block(-8,12,-3,STONE:0)
Block(-8,12,-2,STONE:0)
Block(-8,12,-1,STONE:0)
Block(-8,12,0,STONE:0)
Block(-8,12,1,STONE:0)
Block(-8,12,2,STONE:0)
Block(-8,12,3,STONE:0)
Block(-8,12,4,STONE:0)
Block(-8,12,5,STONE:0)
Block(-8,12,6,STONE:0)
Block(-8,12,7,STONE:0)
Block(-8,12,8,STONE:0)
Block(-8,13,-7,STONE:0)
Block(-8,13,-6,STONE:0)
Block(-8,13,-5,STONE:0)
Block(-8,13,-4,STONE:0)
Block(-8,13,-3,STONE:0)
Block(-8,13,-2,STONE:0)
Block(-8,13,-1,STONE:0)
Block(-8,13,0,STONE:0)
Block(-8,13,1,STONE:0)
Block(-8,13,2,STONE:0)
Block(-8,13,3,STONE:0)
Block(-8,13,4,STONE:0)
Block(-8,13,5,STONE:0)
Block(-8,13,6,STONE:0)
Block(-8,13,7,STONE:0)
Block(-8,13,8,STONE:0)
Block(-8,14,-7,STONE:0)
Block(-8,14,-6,STONE:0)
Block(-8,14,-5,STONE:0)
Block(-8,14,-4,STONE:0)
Block(-8,14,-3,STONE:0)
Block(-8,14,-2,STONE:0)
Block(-8,14,-1,STONE:0)
Block(-8,14,0,STONE:0)
Block(-8,14,1,STONE:0)
Block(-8,14,2,STONE:0)
Block(-8,14,3,STONE:0)
Block(-8,14,4,STONE:0)
Block(-8,14,5,STONE:0)
Block(-8,14,6,STONE:0)
Block(-8,14,7,STONE:0)
Block(-8,14,8,STONE:0)
Block(-8,15,-7,STONE:0)
Block(-8,15,-6,STONE:0)
Block(-8,15,-5,STONE:0)
Block(-8,15,-4,STONE:0)
Block(-8,15,-3,STONE:0)
Block(-8,15,-2,STONE:0)
Block(-8,15,-1,STONE:0)
Block(-8,15,0,STONE:0)
Block(-8,15,1,STONE:0)
Block(-8,15,2,STONE:0)
Block(-8,15,3,STONE:0)
Block(-8,15,4,STONE:0)
Block(-8,15,5,STONE:0)
Block(-8,15,6,STONE:0)
Block(-8,15,7,STONE:0)
Block(-8,15,8,STONE:0)
Block(-8,16,-7,STONE:0)
Block(-8,16,-6,STONE:0)
Block(-8,16,-5,STONE:0)
Block(-8,16,-4,STONE:0)
Block(-8,16,-3,STONE:0)
Block(-8,16,-2,STONE:0)
Block(-8,16,-1,STONE:0)
Block(-8,16,0,STONE:0)
Block(-8,16,1,STONE:0)
Block(-8,16,2,STONE:0)
Block(-8,16,3,STONE:0)
Block(-8,16,4,STONE:0)
Block(-8,16,5,STONE:0)
Block(-8,16,6,STONE:0)
Block(-8,16,7,STONE:0)
Block(-8,16,8,STONE:0)
Block(-8,17,-7,STONE:0)
Block(-8,17,-6,STONE:0)
Block(-8,17,-5,STONE:0)
Block(-8,17,-4,STONE:0)
Block(-8,17,-3,STONE:0)
Block(-8,17,-2,STONE:0)
Block(-8,17,-1,STONE:0)
Block(-8,17,0,STONE:0)
Block(-8,17,1,STONE:0)
Block(-8,17,2,STONE:0)
Block(-8,17,3,STONE:0)
Block(-8,17,4,STONE:0)
Block(-8,17,5,STONE:0)
Block(-8,17,6,STONE:0)
Block(-8,17,7,STONE:0)
Block(-8,17,8,STONE:0)
Block(-8,18,-7,STONE:0)
Block(-8,18,-6,STONE:0)
Block(-8,18,-5,STONE:0)
Block(-8,18,-4,STONE:0)
Block(-8,18,-3,STONE:0)
Block(-8,18,-2,STONE:0)
Block(-8,18,-1,STONE:0)
Block(-8,18,0,STONE:0)
Block(-8,18,1,MAGMA:0)
Block(-8,18,2,MAGMA:0)
Block(-8,18,3,STONE:0)
Block(-8,18,4,STONE:0)
Block(-8,18,5,STONE:0)
Block(-8,18,6,CONCRETE:7)
Block(-8,18,7,STONE:0)
Block(-8,18,8,STONE:0)
Block(-8,19,-7,STONE:0)
Block(-8,19,-6,SMOOTH_BRICK:0)
Block(-8,19,-5,SMOOTH_BRICK:0)
Block(-8,19,-4,CONCRETE:7)
Block(-8,19,-3,CONCRETE:7)
Block(-8,19,-2,CONCRETE:7)
Block(-8,19,-1,CONCRETE:7)
Block(-8,19,0,CONCRETE:7)
Block(-8,19,1,STAINED_GLASS:15)
Block(-8,19,2,STAINED_GLASS:15)
Block(-8,19,3,CONCRETE:7)
Block(-8,19,4,CONCRETE:7)
Block(-8,19,5,CONCRETE:7)
Block(-8,19,6,CONCRETE:7)
Block(-8,19,7,CONCRETE:7)
Block(-8,19,8,CONCRETE:7)
Block(-8,20,-7,STONE:0)
Block(-8,20,-6,SMOOTH_BRICK:0)
Block(-8,20,-3,JUNGLE_WOOD_STAIRS:3)
Block(-8,20,-2,DARK_OAK_FENCE:0)
Block(-8,20,-1,JUNGLE_WOOD_STAIRS:2)
Block(-8,20,1,CARPET:14)
Block(-8,20,2,CARPET:14)
Block(-8,20,4,DARK_OAK_FENCE:0)
Block(-8,21,-7,STONE:0)
Block(-8,21,-6,SMOOTH_BRICK:0)
Block(-8,21,-2,CARPET:7)
Block(-8,22,-7,STONE:0)
Block(-8,22,-6,SMOOTH_BRICK:0)
Block(-8,23,-7,STONE:0)
Block(-8,23,-6,SMOOTH_BRICK:0)
Block(-8,24,-7,STONE:0)
Block(-8,24,-6,SMOOTH_BRICK:0)
Block(-8,24,-2,SMOOTH_STAIRS:5)
Block(-8,24,-1,SMOOTH_STAIRS:5)
Block(-8,24,4,SMOOTH_STAIRS:5)
Block(-8,24,5,SMOOTH_STAIRS:5)
Block(-8,25,-7,STONE:0)
Block(-8,25,-6,SMOOTH_BRICK:0)
Block(-8,25,-2,SMOOTH_BRICK:0)
Block(-8,25,-1,SMOOTH_BRICK:0)
Block(-8,25,4,SMOOTH_BRICK:0)
Block(-8,25,5,SMOOTH_BRICK:0)
Block(-8,26,-7,STONE:0)
Block(-8,26,-6,SMOOTH_BRICK:0)
Block(-8,26,-5,SMOOTH_BRICK:0)
Block(-8,26,-4,SMOOTH_BRICK:0)
Block(-8,26,-3,SMOOTH_BRICK:0)
Block(-8,26,-2,SMOOTH_BRICK:0)
Block(-8,26,-1,SMOOTH_BRICK:0)
Block(-8,26,0,SMOOTH_BRICK:0)
Block(-8,26,1,SMOOTH_BRICK:0)
Block(-8,26,2,SMOOTH_BRICK:0)
Block(-8,26,3,SMOOTH_BRICK:0)
Block(-8,26,4,SMOOTH_BRICK:0)
Block(-8,26,5,SMOOTH_BRICK:0)
Block(-8,26,6,SMOOTH_BRICK:0)
Block(-8,26,7,SMOOTH_BRICK:0)
Block(-8,26,8,SMOOTH_BRICK:0)
Block(-8,27,-7,STONE:0)
Block(-8,27,-6,STONE:0)
Block(-8,27,-5,STONE:0)
Block(-8,27,-4,STONE:0)
Block(-8,27,-3,STONE:0)
Block(-8,27,-2,STONE:0)
Block(-8,27,-1,STONE:0)
Block(-8,27,0,STONE:0)
Block(-8,27,1,STONE:0)
Block(-8,27,2,STONE:0)
Block(-8,27,3,STONE:0)
Block(-8,27,4,STONE:0)
Block(-8,27,5,STONE:0)
Block(-8,27,6,STONE:0)
Block(-8,27,7,STONE:0)
Block(-8,27,8,STONE:0)
Block(-8,28,-7,STONE:0)
Block(-8,28,-6,STONE:0)
Block(-8,28,-5,STONE:0)
Block(-8,28,-4,STONE:0)
Block(-8,28,-3,STONE:0)
Block(-8,28,-2,STONE:0)
Block(-8,28,-1,STONE:0)
Block(-8,28,0,STONE:0)
Block(-8,28,1,STONE:0)
Block(-8,28,2,STONE:0)
Block(-8,28,3,STONE:0)
Block(-8,28,4,STONE:0)
Block(-8,28,5,STONE:0)
Block(-8,28,6,STONE:0)
Block(-8,28,7,STONE:0)
Block(-8,28,8,STONE:0)
Block(-8,29,-7,STONE:0)
Block(-8,29,-6,STONE:0)
Block(-8,29,-5,STONE:0)
Block(-8,29,-4,STONE:0)
Block(-8,29,-3,STONE:0)
Block(-8,29,-2,STONE:0)
Block(-8,29,-1,STONE:0)
Block(-8,29,0,STONE:0)
Block(-8,29,1,STONE:0)
Block(-8,29,2,STONE:0)
Block(-8,29,3,STONE:0)
Block(-8,29,4,STONE:0)
Block(-8,29,5,STONE:0)
Block(-8,29,6,STONE:0)
Block(-8,29,7,STONE:0)
Block(-8,29,8,STONE:0)
Block(-8,30,-7,STONE:0)
Block(-8,30,-6,STONE:0)
Block(-8,30,-5,STONE:0)
Block(-8,30,-4,STONE:0)
Block(-8,30,-3,STONE:0)
Block(-8,30,-2,STONE:0)
Block(-8,30,-1,STONE:0)
Block(-8,30,0,STONE:0)
Block(-8,30,1,STONE:0)
Block(-8,30,2,STONE:0)
Block(-8,30,3,STONE:0)
Block(-8,30,4,STONE:0)
Block(-8,30,5,STONE:0)
Block(-8,30,6,STONE:0)
Block(-8,30,7,STONE:0)
Block(-8,30,8,STONE:0)
Block(-8,31,-7,STONE:0)
Block(-8,31,-6,STONE:0)
Block(-8,31,-5,STONE:0)
Block(-8,31,-4,STONE:0)
Block(-8,31,-3,STONE:0)
Block(-8,31,-2,STONE:0)
Block(-8,31,-1,STONE:0)
Block(-8,31,0,STONE:0)
Block(-8,31,1,STONE:0)
Block(-8,31,2,STONE:0)
Block(-8,31,3,STONE:0)
Block(-8,31,4,STONE:0)
Block(-8,31,5,STONE:0)
Block(-8,31,6,STONE:0)
Block(-8,31,7,STONE:0)
Block(-8,31,8,STONE:0)
Block(-8,32,-7,STONE:0)
Block(-8,32,-6,STONE:0)
Block(-8,32,-5,STONE:0)
Block(-8,32,-4,STONE:0)
Block(-8,32,-3,STONE:0)
Block(-8,32,-2,STONE:0)
Block(-8,32,-1,STONE:0)
Block(-8,32,0,STONE:0)
Block(-8,32,1,STONE:0)
Block(-8,32,2,STONE:0)
Block(-8,32,3,STONE:0)
Block(-8,32,4,STONE:0)
Block(-8,32,5,STONE:0)
Block(-8,32,6,STONE:0)
Block(-8,32,7,STONE:0)
Block(-8,32,8,STONE:0)
Block(-8,33,-7,STONE:0)
Block(-8,33,-6,STONE:0)
Block(-8,33,-5,STONE:0)
Block(-8,33,-4,STONE:0)
Block(-8,33,-3,STONE:0)
Block(-8,33,-2,STONE:0)
Block(-8,33,-1,STONE:0)
Block(-8,33,0,STONE:0)
Block(-8,33,1,STONE:0)
Block(-8,33,2,STONE:0)
Block(-8,33,3,STONE:0)
Block(-8,33,4,STONE:0)
Block(-8,33,5,STONE:0)
Block(-8,33,6,STONE:0)
Block(-8,33,7,STONE:0)
Block(-8,33,8,STONE:0)
Block(-8,34,-7,STONE:0)
Block(-8,34,-6,STONE:0)
Block(-8,34,-5,STONE:0)
Block(-8,34,-4,STONE:0)
Block(-8,34,-3,STONE:0)
Block(-8,34,-2,STONE:0)
Block(-8,34,-1,STONE:0)
Block(-8,34,0,STONE:0)
Block(-8,34,1,STONE:0)
Block(-8,34,2,STONE:0)
Block(-8,34,3,STONE:0)
Block(-8,34,4,STONE:0)
Block(-8,34,5,STONE:0)
Block(-8,34,6,STONE:0)
Block(-8,34,7,STONE:0)
Block(-8,34,8,STONE:0)
Block(-8,35,-7,STONE:0)
Block(-8,35,-6,STONE:0)
Block(-8,35,-5,STONE:0)
Block(-8,35,-4,STONE:0)
Block(-8,35,-3,STONE:0)
Block(-8,35,-2,STONE:0)
Block(-8,35,-1,STONE:0)
Block(-8,35,0,STONE:0)
Block(-8,35,1,STONE:0)
Block(-8,35,2,STONE:0)
Block(-8,35,3,STONE:0)
Block(-8,35,4,STONE:0)
Block(-8,35,5,STONE:0)
Block(-8,35,6,STONE:0)
Block(-8,35,7,STONE:0)
Block(-8,35,8,STONE:0)
Block(-8,36,-7,DIRT:0)
Block(-8,36,-6,DIRT:0)
Block(-8,36,-5,DIRT:0)
Block(-8,36,-4,DIRT:0)
Block(-8,36,-3,DIRT:0)
Block(-8,36,-2,DIRT:0)
Block(-8,36,-1,DIRT:0)
Block(-8,36,0,DIRT:0)
Block(-8,36,1,DIRT:0)
Block(-8,36,2,DIRT:0)
Block(-8,36,3,DIRT:0)
Block(-8,36,4,DIRT:0)
Block(-8,36,5,DIRT:1)
Block(-8,36,6,DIRT:1)
Block(-8,36,7,DIRT:1)
Block(-8,36,8,DIRT:1)
Block(-8,37,-7,DIRT:0)
Block(-8,37,-6,DIRT:0)
Block(-8,37,-5,DIRT:0)
Block(-8,37,-4,DIRT:0)
Block(-8,37,-3,DIRT:0)
Block(-8,37,-2,DIRT:0)
Block(-8,37,-1,DIRT:0)
Block(-8,37,0,DIRT:0)
Block(-8,37,1,DIRT:0)
Block(-8,37,2,DIRT:0)
Block(-8,37,3,DIRT:0)
Block(-8,37,4,DIRT:0)
Block(-8,37,5,DIRT:1)
Block(-8,37,6,DIRT:1)
Block(-8,37,7,DIRT:1)
Block(-8,37,8,DIRT:1)
Block(-8,38,-7,GRASS:0)
Block(-8,38,-6,GRASS:0)
Block(-8,38,-5,GRAVEL:0)
Block(-8,38,-4,GRAVEL:0)
Block(-8,38,-3,GRAVEL:0)
Block(-8,38,-2,GRASS:0)
Block(-8,38,-1,GRAVEL:0)
Block(-8,38,0,GRASS:0)
Block(-8,38,1,GRASS:0)
Block(-8,38,2,GRASS:0)
Block(-8,38,3,GRASS:0)
Block(-8,38,4,GRASS:0)
Block(-8,38,5,GRASS:0)
Block(-8,38,6,GRASS:0)
Block(-8,38,7,GRASS:0)
Block(-8,38,8,GRASS:0)
Block(-8,39,-5,WORKBENCH:0)
RandomBlock(-8,39,-4,AIR:0,20,CHEST:4,../../../Chests/Loot/JunkChest_1.nbt,10,CHEST:4,../../../Chests/Loot/JunkChest_2.nbt,10,CHEST:4,../../../Chests/Loot/JunkChest_3.nbt,10,CHEST:4,../../../Chests/Loot/JunkChest_4.nbt,10,CHEST:4,../../../Chests/Loot/JunkChest_5.nbt,10,CHEST:4,../../../Chests/Lore/village_1.nbt,1,CHEST:4,../../../Chests/Lore/village_2.nbt,1,CHEST:4,../../../Chests/Lore/village_3.nbt,1,CHEST:4,../../../Chests/Lore/village_4.nbt,1,CHEST:4,../../../Chests/Lore/village_5.nbt,1,CHEST:4,../../../Chests/Loot/Common1.nbt,10,CHEST:4,../../../Chests/Loot/Common2.nbt,10,CHEST:4,../../../Chests/Loot/Common3.nbt,10,CHEST:4,../../../Chests/Loot/Common4.nbt,10,CHEST:4,../../../Chests/Loot/Common5.nbt,10,CHEST:4,../../../Chests/Loot/Common6.nbt,10,CHEST:4,../../../Chests/Loot/Common7.nbt,10,CHEST:4,../../../Chests/Loot/Common8.nbt,10,CHEST:4,../../../Chests/Loot/Common9.nbt,10,CHEST:4,../../../Chests/Loot/Common10.nbt,10,CHEST:4,../../../Chests/Loot/Common10.nbt,11,CHEST:4,../../../Chests/Loot/Common12.nbt,10,CHEST:4,../../../Chests/Loot/Common13.nbt,10,CHEST:4,../../../Chests/Loot/Common14.nbt,10,CHEST:4,../../../Chests/Loot/Common15.nbt,10,CHEST:4,../../../Chests/Lore/village_1.nbt,2,CHEST:4,../../../Chests/Lore/village_3.nbt,2,CHEST:4,../../../Chests/Lore/village_4.nbt,2,CHEST:4,../../../Chests/Lore/village_5.nbt,2,CHEST:4,../../../Chests/Lore/village_5.nbt,2,CHEST:4,../../../Chests/Loot/Rare1.nbt,5,CHEST:4,../../../Chests/Loot/Rare2.nbt,5,CHEST:4,../../../Chests/Loot/Rare3.nbt,5,CHEST:4,../../../Chests/Loot/Rare4.nbt,5,CHEST:4,../../../Chests/Loot/Rare5.nbt,5,CHEST:4,../../../Chests/Loot/Rare6.nbt,5,CHEST:4,../../../Chests/Loot/Rare7.nbt,5,CHEST:4,../../../Chests/Loot/Rare8.nbt,5,CHEST:4,../../../Chests/Loot/Rare9.nbt,5,CHEST:4,../../../Chests/Loot/Rare10.nbt,5,CHEST:4,../../../Chests/Loot/Rare11.nbt,5,CHEST:4,../../../Chests/Loot/Rare12.nbt,5,CHEST:4,../../../Chests/Loot/Rare13.nbt,5,CHEST:4,../../../Chests/Loot/Rare14.nbt,5,CHEST:4,../../../Chests/Loot/Rare15.nbt,5,CHEST:4,../../../Chests/Loot/Epic1.nbt,2,CHEST:4,../../../Chests/Loot/Epic2.nbt,2,CHEST:4,../../../Chests/Loot/Epic3.nbt,2,CHEST:4,../../../Chests/Loot/Epic4.nbt,2,CHEST:4,../../../Chests/Loot/Epic5.nbt,2,CHEST:4,../../../Chests/Loot/Epic6.nbt,2,CHEST:4,../../../Chests/Loot/Epic7.nbt,2,CHEST:4,../../../Chests/Loot/Epic8.nbt,2,CHEST:4,../../../Chests/Loot/Epic9.nbt,2,CHEST:4,../../../Chests/Loot/Epic10.nbt,2,CHEST:4,../../../Chests/Loot/Epic11.nbt,2,CHEST:4,../../../Chests/Loot/Epic12.nbt,2,CHEST:4,../../../Chests/Loot/Epic13.nbt,2,CHEST:4,../../../Chests/Loot/Epic14.nbt,2,CHEST:4,../../../Chests/Loot/Epic15.nbt,5,CHEST:4,../../../Chests/Loot/Rare1.nbt,5,CHEST:4,../../../Chests/Loot/Rare2.nbt,5,CHEST:4,../../../Chests/Loot/Rare3.nbt,5,CHEST:4,../../../Chests/Loot/Rare4.nbt,5,CHEST:4,../../../Chests/Loot/Rare5.nbt,10,CHEST:4,../../../Chests/Loot/Rare6.nbt,10,CHEST:4,../../../Chests/Loot/Rare7.nbt,10,CHEST:4,../../../Chests/Loot/Rare8.nbt,10,CHEST:4,../../../Chests/Loot/Rare9.nbt,10,CHEST:4,../../../Chests/Loot/Rare10.nbt,15,CHEST:4,../../../Chests/Loot/Rare11.nbt,15,CHEST:4,../../../Chests/Loot/Rare12.nbt,15,CHEST:4,../../../Chests/Loot/Rare13.nbt,15,CHEST:4,../../../Chests/Loot/Rare14.nbt,15,CHEST:4,../../../Chests/Loot/Rare15.nbt,15,CHEST:4,../../../Chests/Loot/Epic15.nbt,100)
RandomBlock(-8,39,-3,AIR:0,20,CHEST:4,../../../Chests/Loot/JunkChest_1.nbt,10,CHEST:4,../../../Chests/Loot/JunkChest_2.nbt,10,CHEST:4,../../../Chests/Loot/JunkChest_3.nbt,10,CHEST:4,../../../Chests/Loot/JunkChest_4.nbt,10,CHEST:4,../../../Chests/Loot/JunkChest_5.nbt,10,CHEST:4,../../../Chests/Lore/village_1.nbt,1,CHEST:4,../../../Chests/Lore/village_2.nbt,1,CHEST:4,../../../Chests/Lore/village_3.nbt,1,CHEST:4,../../../Chests/Lore/village_4.nbt,1,CHEST:4,../../../Chests/Lore/village_5.nbt,1,CHEST:4,../../../Chests/Loot/Common1.nbt,10,CHEST:4,../../../Chests/Loot/Common2.nbt,10,CHEST:4,../../../Chests/Loot/Common3.nbt,10,CHEST:4,../../../Chests/Loot/Common4.nbt,10,CHEST:4,../../../Chests/Loot/Common5.nbt,10,CHEST:4,../../../Chests/Loot/Common6.nbt,10,CHEST:4,../../../Chests/Loot/Common7.nbt,10,CHEST:4,../../../Chests/Loot/Common8.nbt,10,CHEST:4,../../../Chests/Loot/Common9.nbt,10,CHEST:4,../../../Chests/Loot/Common10.nbt,10,CHEST:4,../../../Chests/Loot/Common10.nbt,11,CHEST:4,../../../Chests/Loot/Common12.nbt,10,CHEST:4,../../../Chests/Loot/Common13.nbt,10,CHEST:4,../../../Chests/Loot/Common14.nbt,10,CHEST:4,../../../Chests/Loot/Common15.nbt,10,CHEST:4,../../../Chests/Lore/village_1.nbt,2,CHEST:4,../../../Chests/Lore/village_3.nbt,2,CHEST:4,../../../Chests/Lore/village_4.nbt,2,CHEST:4,../../../Chests/Lore/village_5.nbt,2,CHEST:4,../../../Chests/Lore/village_5.nbt,2,CHEST:4,../../../Chests/Loot/Rare1.nbt,5,CHEST:4,../../../Chests/Loot/Rare2.nbt,5,CHEST:4,../../../Chests/Loot/Rare3.nbt,5,CHEST:4,../../../Chests/Loot/Rare4.nbt,5,CHEST:4,../../../Chests/Loot/Rare5.nbt,5,CHEST:4,../../../Chests/Loot/Rare6.nbt,5,CHEST:4,../../../Chests/Loot/Rare7.nbt,5,CHEST:4,../../../Chests/Loot/Rare8.nbt,5,CHEST:4,../../../Chests/Loot/Rare9.nbt,5,CHEST:4,../../../Chests/Loot/Rare10.nbt,5,CHEST:4,../../../Chests/Loot/Rare11.nbt,5,CHEST:4,../../../Chests/Loot/Rare12.nbt,5,CHEST:4,../../../Chests/Loot/Rare13.nbt,5,CHEST:4,../../../Chests/Loot/Rare14.nbt,5,CHEST:4,../../../Chests/Loot/Rare15.nbt,5,CHEST:4,../../../Chests/Loot/Epic1.nbt,2,CHEST:4,../../../Chests/Loot/Epic2.nbt,2,CHEST:4,../../../Chests/Loot/Epic3.nbt,2,CHEST:4,../../../Chests/Loot/Epic4.nbt,2,CHEST:4,../../../Chests/Loot/Epic5.nbt,2,CHEST:4,../../../Chests/Loot/Epic6.nbt,2,CHEST:4,../../../Chests/Loot/Epic7.nbt,2,CHEST:4,../../../Chests/Loot/Epic8.nbt,2,CHEST:4,../../../Chests/Loot/Epic9.nbt,2,CHEST:4,../../../Chests/Loot/Epic10.nbt,2,CHEST:4,../../../Chests/Loot/Epic11.nbt,2,CHEST:4,../../../Chests/Loot/Epic12.nbt,2,CHEST:4,../../../Chests/Loot/Epic13.nbt,2,CHEST:4,../../../Chests/Loot/Epic14.nbt,2,CHEST:4,../../../Chests/Loot/Epic15.nbt,5,CHEST:4,../../../Chests/Loot/Rare1.nbt,5,CHEST:4,../../../Chests/Loot/Rare2.nbt,5,CHEST:4,../../../Chests/Loot/Rare3.nbt,5,CHEST:4,../../../Chests/Loot/Rare4.nbt,5,CHEST:4,../../../Chests/Loot/Rare5.nbt,10,CHEST:4,../../../Chests/Loot/Rare6.nbt,10,CHEST:4,../../../Chests/Loot/Rare7.nbt,10,CHEST:4,../../../Chests/Loot/Rare8.nbt,10,CHEST:4,../../../Chests/Loot/Rare9.nbt,10,CHEST:4,../../../Chests/Loot/Rare10.nbt,15,CHEST:4,../../../Chests/Loot/Rare11.nbt,15,CHEST:4,../../../Chests/Loot/Rare12.nbt,15,CHEST:4,../../../Chests/Loot/Rare13.nbt,15,CHEST:4,../../../Chests/Loot/Rare14.nbt,15,CHEST:4,../../../Chests/Loot/Rare15.nbt,15,CHEST:4,../../../Chests/Loot/Epic15.nbt,100)
Block(-8,39,0,TRAP_DOOR:10)
Block(-8,39,2,LONG_GRASS:1)
Block(-8,39,3,LONG_GRASS:1)
Block(-8,39,4,LONG_GRASS:1)
Block(-8,39,5,LONG_GRASS:1)
Block(-8,39,6,LONG_GRASS:1)
Block(-8,39,7,LONG_GRASS:1)
Block(-8,39,8,LONG_GRASS:1)
Block(-8,41,5,LEAVES:0)
Block(-8,42,-7,WOOL:12)
Block(-8,42,-6,WOOL:1)
Block(-8,42,-5,WOOL:12)
Block(-8,42,-4,WOOL:1)
Block(-8,42,-3,WOOL:12)
Block(-8,42,-2,WOOL:1)
Block(-8,42,-1,WOOL:12)
Block(-8,42,0,WOOD_STEP:9)
Block(-8,42,4,LEAVES:0)
Block(-8,42,5,LEAVES:0)
Block(-8,43,-7,WOOD_STEP:1)
Block(-8,43,-6,WOOL:1)
Block(-8,43,-5,WOOL:12)
Block(-8,43,-4,WOOL:1)
Block(-8,43,-3,WOOL:12)
Block(-8,43,-2,WOOL:1)
Block(-8,43,-1,WOOD_STEP:1)
Block(-8,43,3,LEAVES:0)
Block(-8,43,4,LOG_2:13)
Block(-8,43,5,LEAVES:0)
Block(-8,43,6,LEAVES:0)
Block(-8,44,-5,WOOD_STEP:1)
Block(-8,44,-4,WOOD_STEP:1)
Block(-8,44,-3,WOOD_STEP:1)
Block(-8,44,1,LEAVES:0)
Block(-8,44,2,LEAVES:0)
Block(-8,44,3,LEAVES:0)
Block(-8,44,4,LEAVES:0)
Block(-8,44,5,LEAVES:0)
Block(-8,44,6,LEAVES:0)
Block(-8,44,7,LEAVES:0)
Block(-8,44,8,LEAVES:0)
Block(-8,45,1,LEAVES:0)
Block(-8,45,2,LEAVES:0)
Block(-8,45,4,LEAVES:0)
Block(-8,45,5,LEAVES:0)
Block(-8,45,6,LEAVES:0)
Block(-8,45,7,LEAVES:0)
Block(-8,45,8,LEAVES:0)
Block(-8,46,0,LEAVES:0)
Block(-8,46,1,LEAVES:0)
Block(-8,46,2,LEAVES:0)
Block(-8,46,3,LEAVES:0)
Block(-8,46,4,LEAVES:0)
Block(-8,46,5,LEAVES:0)
Block(-8,46,6,LEAVES:0)
Block(-8,47,1,LEAVES:0)
Block(-8,47,2,LEAVES:0)
Block(-8,47,3,LEAVES:0)
Block(-8,47,4,LEAVES:0)
Block(-8,47,5,LEAVES:0)
Block(-8,47,6,LEAVES:0)
Block(-8,47,7,LEAVES:0)
Block(-8,47,8,LEAVES:0)
Block(-8,48,1,LEAVES:0)
Block(-8,48,2,LEAVES:0)
Block(-8,48,6,LEAVES:0)
Block(-8,49,3,LEAVES:0)
Block(-8,49,4,LEAVES:0)
Block(-8,49,7,LEAVES:0)
Block(-8,49,8,LEAVES:0)
Block(-8,50,7,LEAVES:0)
Block(-8,50,8,LEAVES:0)
Block(-7,0,-7,STONE:0)
Block(-7,0,-6,STONE:0)
Block(-7,0,-5,STONE:0)
Block(-7,0,-4,STONE:0)
Block(-7,0,-3,STONE:0)
Block(-7,0,-2,STONE:0)
Block(-7,0,-1,STONE:0)
Block(-7,0,0,STONE:0)
Block(-7,0,1,STONE:0)
Block(-7,0,2,STONE:0)
Block(-7,0,3,STONE:0)
Block(-7,0,4,STONE:0)
Block(-7,0,5,STONE:0)
Block(-7,0,6,STONE:0)
Block(-7,0,7,STONE:0)
Block(-7,0,8,STONE:0)
Block(-7,1,-7,STONE:0)
Block(-7,1,-6,STONE:0)
Block(-7,1,-5,STONE:0)
Block(-7,1,-4,STONE:0)
Block(-7,1,-3,STONE:0)
Block(-7,1,-2,STONE:0)
Block(-7,1,-1,STONE:0)
Block(-7,1,0,STONE:0)
Block(-7,1,1,STONE:0)
Block(-7,1,2,STONE:0)
Block(-7,1,3,STONE:0)
Block(-7,1,4,STONE:0)
Block(-7,1,5,STONE:0)
Block(-7,1,6,STONE:0)
Block(-7,1,7,STONE:0)
Block(-7,1,8,STONE:0)
Block(-7,2,-7,STONE:0)
Block(-7,2,-6,STONE:0)
Block(-7,2,-5,STONE:0)
Block(-7,2,-4,STONE:0)
Block(-7,2,-3,STONE:0)
Block(-7,2,-2,STONE:0)
Block(-7,2,-1,STONE:0)
Block(-7,2,0,STONE:0)
Block(-7,2,1,STONE:0)
Block(-7,2,2,STONE:0)
Block(-7,2,3,STONE:0)
Block(-7,2,4,STONE:0)
Block(-7,2,5,STONE:0)
Block(-7,2,6,STONE:0)
Block(-7,2,7,STONE:0)
Block(-7,2,8,STONE:0)
Block(-7,3,-7,STONE:0)
Block(-7,3,-6,STONE:0)
Block(-7,3,-5,STONE:0)
Block(-7,3,-4,STONE:0)
Block(-7,3,-3,STONE:0)
Block(-7,3,-2,STONE:0)
Block(-7,3,-1,STONE:0)
Block(-7,3,0,STONE:0)
Block(-7,3,1,STONE:0)
Block(-7,3,2,STONE:0)
Block(-7,3,3,STONE:0)
Block(-7,3,4,STONE:0)
Block(-7,3,5,STONE:0)
Block(-7,3,6,STONE:0)
Block(-7,3,7,STONE:0)
Block(-7,3,8,STONE:0)
Block(-7,4,-7,STONE:0)
Block(-7,4,-6,STONE:0)
Block(-7,4,-5,STONE:0)
Block(-7,4,-4,STONE:0)
Block(-7,4,-3,STONE:0)
Block(-7,4,-2,STONE:0)
Block(-7,4,-1,STONE:0)
Block(-7,4,0,STONE:0)
Block(-7,4,1,STONE:0)
Block(-7,4,2,STONE:0)
Block(-7,4,3,STONE:0)
Block(-7,4,4,STONE:0)
Block(-7,4,5,STONE:0)
Block(-7,4,6,STONE:0)
Block(-7,4,7,STONE:0)
Block(-7,4,8,STONE:0)
Block(-7,5,-7,STONE:0)
Block(-7,5,-6,STONE:0)
Block(-7,5,-5,STONE:0)
Block(-7,5,-4,STONE:0)
Block(-7,5,-3,STONE:0)
Block(-7,5,-2,STONE:0)
Block(-7,5,-1,STONE:0)
Block(-7,5,0,STONE:0)
Block(-7,5,1,STONE:0)
Block(-7,5,2,STONE:0)
Block(-7,5,3,STONE:0)
Block(-7,5,4,STONE:0)
Block(-7,5,5,STONE:0)
Block(-7,5,6,STONE:0)
Block(-7,5,7,STONE:0)
Block(-7,5,8,STONE:0)
Block(-7,6,-7,STONE:0)
Block(-7,6,-6,STONE:0)
Block(-7,6,-5,STONE:0)
Block(-7,6,-4,STONE:0)
Block(-7,6,-3,STONE:0)
Block(-7,6,-2,STONE:0)
Block(-7,6,-1,STONE:0)
Block(-7,6,0,STONE:0)
Block(-7,6,1,STONE:0)
Block(-7,6,2,STONE:0)
Block(-7,6,3,STONE:0)
Block(-7,6,4,STONE:0)
Block(-7,6,5,STONE:0)
Block(-7,6,6,STONE:0)
Block(-7,6,7,STONE:0)
Block(-7,6,8,STONE:0)
Block(-7,7,-7,STONE:0)
Block(-7,7,-6,STONE:0)
Block(-7,7,-5,STONE:0)
Block(-7,7,-4,STONE:0)
Block(-7,7,-3,STONE:0)
Block(-7,7,-2,STONE:0)
Block(-7,7,-1,STONE:0)
Block(-7,7,0,STONE:0)
Block(-7,7,1,STONE:0)
Block(-7,7,2,STONE:0)
Block(-7,7,3,STONE:0)
Block(-7,7,4,STONE:0)
Block(-7,7,5,STONE:0)
Block(-7,7,6,STONE:0)
Block(-7,7,7,STONE:0)
Block(-7,7,8,STONE:0)
Block(-7,8,-7,STONE:0)
Block(-7,8,-6,STONE:0)
Block(-7,8,-5,STONE:0)
Block(-7,8,-4,STONE:0)
Block(-7,8,-3,STONE:0)
Block(-7,8,-2,STONE:0)
Block(-7,8,-1,STONE:0)
Block(-7,8,0,STONE:0)
Block(-7,8,1,STONE:0)
Block(-7,8,2,STONE:0)
Block(-7,8,3,STONE:0)
Block(-7,8,4,STONE:0)
Block(-7,8,5,STONE:0)
Block(-7,8,6,STONE:0)
Block(-7,8,7,STONE:0)
Block(-7,8,8,STONE:0)
Block(-7,9,-7,STONE:0)
Block(-7,9,-6,STONE:0)
Block(-7,9,-5,STONE:0)
Block(-7,9,-4,STONE:0)
Block(-7,9,-3,STONE:0)
Block(-7,9,-2,STONE:0)
Block(-7,9,-1,STONE:0)
Block(-7,9,0,STONE:0)
Block(-7,9,1,STONE:0)
Block(-7,9,2,STONE:0)
Block(-7,9,3,STONE:0)
Block(-7,9,4,STONE:0)
Block(-7,9,5,STONE:0)
Block(-7,9,6,STONE:0)
Block(-7,9,7,STONE:0)
Block(-7,9,8,STONE:0)
Block(-7,10,-7,STONE:0)
Block(-7,10,-6,STONE:0)
Block(-7,10,-5,STONE:0)
Block(-7,10,-4,STONE:0)
Block(-7,10,-3,STONE:0)
Block(-7,10,-2,STONE:0)
Block(-7,10,-1,STONE:0)
Block(-7,10,0,STONE:0)
Block(-7,10,1,STONE:0)
Block(-7,10,2,STONE:0)
Block(-7,10,3,STONE:0)
Block(-7,10,4,STONE:0)
Block(-7,10,5,STONE:0)
Block(-7,10,6,STONE:0)
Block(-7,10,7,STONE:0)
Block(-7,10,8,STONE:0)
Block(-7,11,-7,STONE:0)
Block(-7,11,-6,STONE:0)
Block(-7,11,-5,STONE:0)
Block(-7,11,-4,STONE:0)
Block(-7,11,-3,STONE:0)
Block(-7,11,-2,STONE:0)
Block(-7,11,-1,STONE:0)
Block(-7,11,0,STONE:0)
Block(-7,11,1,STONE:0)
Block(-7,11,2,STONE:0)
Block(-7,11,3,STONE:0)
Block(-7,11,4,STONE:0)
Block(-7,11,5,STONE:0)
Block(-7,11,6,STONE:0)
Block(-7,11,7,STONE:0)
Block(-7,11,8,STONE:0)
Block(-7,12,-7,STONE:0)
Block(-7,12,-6,STONE:0)
Block(-7,12,-5,STONE:0)
Block(-7,12,-4,STONE:0)
Block(-7,12,-3,STONE:0)
Block(-7,12,-2,STONE:0)
Block(-7,12,-1,STONE:0)
Block(-7,12,0,STONE:0)
Block(-7,12,1,STONE:0)
Block(-7,12,2,STONE:0)
Block(-7,12,3,STONE:0)
Block(-7,12,4,STONE:0)
Block(-7,12,5,STONE:0)
Block(-7,12,6,STONE:0)
Block(-7,12,7,STONE:0)
Block(-7,12,8,STONE:0)
Block(-7,13,-7,STONE:0)
Block(-7,13,-6,STONE:0)
Block(-7,13,-5,STONE:0)
Block(-7,13,-4,STONE:0)
Block(-7,13,-3,STONE:0)
Block(-7,13,-2,STONE:0)
Block(-7,13,-1,STONE:0)
Block(-7,13,0,STONE:0)
Block(-7,13,1,STONE:0)
Block(-7,13,2,STONE:0)
Block(-7,13,3,STONE:0)
Block(-7,13,4,STONE:0)
Block(-7,13,5,STONE:0)
Block(-7,13,6,STONE:0)
Block(-7,13,7,STONE:0)
Block(-7,13,8,STONE:0)
Block(-7,14,-7,STONE:0)
Block(-7,14,-6,STONE:0)
Block(-7,14,-5,STONE:0)
Block(-7,14,-4,STONE:0)
Block(-7,14,-3,STONE:0)
Block(-7,14,-2,STONE:0)
Block(-7,14,-1,STONE:0)
Block(-7,14,0,STONE:0)
Block(-7,14,1,STONE:0)
Block(-7,14,2,STONE:0)
Block(-7,14,3,STONE:0)
Block(-7,14,4,STONE:0)
Block(-7,14,5,STONE:0)
Block(-7,14,6,STONE:0)
Block(-7,14,7,STONE:0)
Block(-7,14,8,STONE:0)
Block(-7,15,-7,STONE:0)
Block(-7,15,-6,STONE:0)
Block(-7,15,-5,STONE:0)
Block(-7,15,-4,STONE:0)
Block(-7,15,-3,STONE:0)
Block(-7,15,-2,STONE:0)
Block(-7,15,-1,STONE:0)
Block(-7,15,0,STONE:0)
Block(-7,15,1,STONE:0)
Block(-7,15,2,STONE:0)
Block(-7,15,3,STONE:0)
Block(-7,15,4,STONE:0)
Block(-7,15,5,STONE:0)
Block(-7,15,6,STONE:0)
Block(-7,15,7,STONE:0)
Block(-7,15,8,STONE:0)
Block(-7,16,-7,STONE:0)
Block(-7,16,-6,STONE:0)
Block(-7,16,-5,STONE:0)
Block(-7,16,-4,STONE:0)
Block(-7,16,-3,STONE:0)
Block(-7,16,-2,STONE:0)
Block(-7,16,-1,STONE:0)
Block(-7,16,0,STONE:0)
Block(-7,16,1,STONE:0)
Block(-7,16,2,STONE:0)
Block(-7,16,3,STONE:0)
Block(-7,16,4,STONE:0)
Block(-7,16,5,STONE:0)
Block(-7,16,6,STONE:0)
Block(-7,16,7,STONE:0)
Block(-7,16,8,STONE:0)
Block(-7,17,-7,STONE:0)
Block(-7,17,-6,STONE:0)
Block(-7,17,-5,STONE:0)
Block(-7,17,-4,STONE:0)
Block(-7,17,-3,STONE:0)
Block(-7,17,-2,STONE:0)
Block(-7,17,-1,STONE:0)
Block(-7,17,0,STONE:0)
Block(-7,17,1,STONE:0)
Block(-7,17,2,STONE:0)
Block(-7,17,3,STONE:0)
Block(-7,17,4,STONE:0)
Block(-7,17,5,STONE:0)
Block(-7,17,6,STONE:0)
Block(-7,17,7,STONE:0)
Block(-7,17,8,STONE:0)
Block(-7,18,-7,STONE:0)
Block(-7,18,-6,STONE:0)
Block(-7,18,-5,STONE:0)
Block(-7,18,-4,STONE:0)
Block(-7,18,-3,STONE:0)
Block(-7,18,-2,STONE:0)
Block(-7,18,-1,STONE:0)
Block(-7,18,0,STONE:0)
Block(-7,18,1,MAGMA:0)
Block(-7,18,2,MAGMA:0)
Block(-7,18,3,STONE:0)
Block(-7,18,4,STONE:0)
Block(-7,18,5,STONE:0)
Block(-7,18,6,STONE:0)
Block(-7,18,7,STONE:0)
Block(-7,18,8,STONE:0)
Block(-7,19,-7,STONE:0)
Block(-7,19,-6,SMOOTH_BRICK:0)
Block(-7,19,-5,CONCRETE:7)
Block(-7,19,-4,CONCRETE:7)
Block(-7,19,-3,CONCRETE:7)
Block(-7,19,-2,CONCRETE:7)
Block(-7,19,-1,CONCRETE:7)
Block(-7,19,0,CONCRETE:7)
Block(-7,19,1,STAINED_GLASS:15)
Block(-7,19,2,STAINED_GLASS:15)
Block(-7,19,3,CONCRETE:7)
Block(-7,19,4,CONCRETE:7)
Block(-7,19,5,CONCRETE:7)
Block(-7,19,6,CONCRETE:7)
Block(-7,19,7,CONCRETE:7)
Block(-7,19,8,CONCRETE:7)
Block(-7,20,-7,STONE:0)
Block(-7,20,-6,SMOOTH_BRICK:0)
Block(-7,20,-2,DARK_OAK_FENCE:0)
Block(-7,20,1,CARPET:14)
Block(-7,20,2,CARPET:14)
Block(-7,20,4,DARK_OAK_FENCE:0)
Block(-7,20,5,CARPET:15)
Block(-7,20,6,CARPET:15)
Block(-7,20,7,CARPET:15)
Block(-7,21,-7,STONE:0)
Block(-7,21,-6,SMOOTH_BRICK:0)
Block(-7,21,-2,CARPET:7)
Block(-7,22,-7,STONE:0)
Block(-7,22,-6,SMOOTH_BRICK:0)
Block(-7,23,-7,STONE:0)
Block(-7,23,-6,SMOOTH_BRICK:0)
Block(-7,24,-7,STONE:0)
Block(-7,24,-6,SMOOTH_BRICK:0)
Block(-7,25,-7,STONE:0)
Block(-7,25,-6,SMOOTH_BRICK:0)
Block(-7,25,-2,SMOOTH_BRICK:0)
Block(-7,25,-1,SMOOTH_BRICK:0)
Block(-7,25,4,SMOOTH_BRICK:0)
Block(-7,25,5,SMOOTH_BRICK:0)
Block(-7,26,-7,STONE:0)
Block(-7,26,-6,SMOOTH_BRICK:0)
Block(-7,26,-5,SMOOTH_BRICK:0)
Block(-7,26,-4,SMOOTH_BRICK:0)
Block(-7,26,-3,SMOOTH_BRICK:0)
Block(-7,26,-2,SMOOTH_BRICK:0)
Block(-7,26,-1,SMOOTH_BRICK:0)
Block(-7,26,0,SMOOTH_BRICK:0)
Block(-7,26,1,SMOOTH_BRICK:0)
Block(-7,26,2,SMOOTH_BRICK:0)
Block(-7,26,3,SMOOTH_BRICK:0)
Block(-7,26,4,SMOOTH_BRICK:0)
Block(-7,26,5,SMOOTH_BRICK:0)
Block(-7,26,6,SMOOTH_BRICK:0)
Block(-7,26,7,SMOOTH_BRICK:0)
Block(-7,26,8,SMOOTH_BRICK:0)
Block(-7,27,-7,STONE:0)
Block(-7,27,-6,STONE:0)
Block(-7,27,-5,STONE:0)
Block(-7,27,-4,STONE:0)
Block(-7,27,-3,STONE:0)
Block(-7,27,-2,STONE:0)
Block(-7,27,-1,STONE:0)
Block(-7,27,0,STONE:0)
Block(-7,27,1,STONE:0)
Block(-7,27,2,STONE:0)
Block(-7,27,3,STONE:0)
Block(-7,27,4,STONE:0)
Block(-7,27,5,STONE:0)
Block(-7,27,6,STONE:0)
Block(-7,27,7,STONE:0)
Block(-7,27,8,STONE:0)
Block(-7,28,-7,STONE:0)
Block(-7,28,-6,STONE:0)
Block(-7,28,-5,STONE:0)
Block(-7,28,-4,STONE:0)
Block(-7,28,-3,STONE:0)
Block(-7,28,-2,STONE:0)
Block(-7,28,-1,STONE:0)
Block(-7,28,0,STONE:0)
Block(-7,28,1,STONE:0)
Block(-7,28,2,STONE:0)
Block(-7,28,3,STONE:0)
Block(-7,28,4,STONE:0)
Block(-7,28,5,STONE:0)
Block(-7,28,6,STONE:0)
Block(-7,28,7,STONE:0)
Block(-7,28,8,STONE:0)
Block(-7,29,-7,STONE:0)
Block(-7,29,-6,STONE:0)
Block(-7,29,-5,STONE:0)
Block(-7,29,-4,STONE:0)
Block(-7,29,-3,STONE:0)
Block(-7,29,-2,STONE:0)
Block(-7,29,-1,STONE:0)
Block(-7,29,0,STONE:0)
Block(-7,29,1,STONE:0)
Block(-7,29,2,STONE:0)
Block(-7,29,3,STONE:0)
Block(-7,29,4,STONE:0)
Block(-7,29,5,STONE:0)
Block(-7,29,6,STONE:0)
Block(-7,29,7,STONE:0)
Block(-7,29,8,STONE:0)
Block(-7,30,-7,STONE:0)
Block(-7,30,-6,STONE:0)
Block(-7,30,-5,STONE:0)
Block(-7,30,-4,STONE:0)
Block(-7,30,-3,STONE:0)
Block(-7,30,-2,STONE:0)
Block(-7,30,-1,STONE:0)
Block(-7,30,0,STONE:0)
Block(-7,30,1,STONE:0)
Block(-7,30,2,STONE:0)
Block(-7,30,3,STONE:0)
Block(-7,30,4,STONE:0)
Block(-7,30,5,STONE:0)
Block(-7,30,6,STONE:0)
Block(-7,30,7,STONE:0)
Block(-7,30,8,STONE:0)
Block(-7,31,-7,STONE:0)
Block(-7,31,-6,STONE:0)
Block(-7,31,-5,STONE:0)
Block(-7,31,-4,STONE:0)
Block(-7,31,-3,STONE:0)
Block(-7,31,-2,STONE:0)
Block(-7,31,-1,STONE:0)
Block(-7,31,0,STONE:0)
Block(-7,31,1,STONE:0)
Block(-7,31,2,STONE:0)
Block(-7,31,3,STONE:0)
Block(-7,31,4,STONE:0)
Block(-7,31,5,STONE:0)
Block(-7,31,6,STONE:0)
Block(-7,31,7,STONE:0)
Block(-7,31,8,STONE:0)
Block(-7,32,-7,STONE:0)
Block(-7,32,-6,STONE:0)
Block(-7,32,-5,STONE:0)
Block(-7,32,-4,STONE:0)
Block(-7,32,-3,STONE:0)
Block(-7,32,-2,STONE:0)
Block(-7,32,-1,STONE:0)
Block(-7,32,0,STONE:0)
Block(-7,32,1,STONE:0)
Block(-7,32,2,STONE:0)
Block(-7,32,3,STONE:0)
Block(-7,32,4,STONE:0)
Block(-7,32,5,STONE:0)
Block(-7,32,6,STONE:0)
Block(-7,32,7,STONE:0)
Block(-7,32,8,STONE:0)
Block(-7,33,-7,STONE:0)
Block(-7,33,-6,STONE:0)
Block(-7,33,-5,STONE:0)
Block(-7,33,-4,STONE:0)
Block(-7,33,-3,STONE:0)
Block(-7,33,-2,STONE:0)
Block(-7,33,-1,STONE:0)
Block(-7,33,0,STONE:0)
Block(-7,33,1,STONE:0)
Block(-7,33,2,STONE:0)
Block(-7,33,3,STONE:0)
Block(-7,33,4,STONE:0)
Block(-7,33,5,STONE:0)
Block(-7,33,6,STONE:0)
Block(-7,33,7,STONE:0)
Block(-7,33,8,STONE:0)
Block(-7,34,-7,STONE:0)
Block(-7,34,-6,STONE:0)
Block(-7,34,-5,STONE:0)
Block(-7,34,-4,STONE:0)
Block(-7,34,-3,STONE:0)
Block(-7,34,-2,STONE:0)
Block(-7,34,-1,STONE:0)
Block(-7,34,0,STONE:0)
Block(-7,34,1,STONE:0)
Block(-7,34,2,STONE:0)
Block(-7,34,3,STONE:0)
Block(-7,34,4,STONE:0)
Block(-7,34,5,STONE:0)
Block(-7,34,6,STONE:0)
Block(-7,34,7,STONE:0)
Block(-7,34,8,STONE:0)
Block(-7,35,-7,STONE:0)
Block(-7,35,-6,STONE:0)
Block(-7,35,-5,STONE:0)
Block(-7,35,-4,STONE:0)
Block(-7,35,-3,STONE:0)
Block(-7,35,-2,STONE:0)
Block(-7,35,-1,STONE:0)
Block(-7,35,0,STONE:0)
Block(-7,35,1,STONE:0)
Block(-7,35,2,STONE:0)
Block(-7,35,3,STONE:0)
Block(-7,35,4,STONE:0)
Block(-7,35,5,STONE:0)
Block(-7,35,6,STONE:0)
Block(-7,35,7,STONE:0)
Block(-7,35,8,STONE:0)
Block(-7,36,-7,DIRT:0)
Block(-7,36,-6,DIRT:0)
Block(-7,36,-5,DIRT:0)
Block(-7,36,-4,DIRT:0)
Block(-7,36,-3,DIRT:0)
Block(-7,36,-2,DIRT:0)
Block(-7,36,-1,DIRT:0)
Block(-7,36,0,DIRT:0)
Block(-7,36,1,DIRT:0)
Block(-7,36,2,DIRT:0)
Block(-7,36,3,DIRT:0)
Block(-7,36,4,DIRT:0)
Block(-7,36,5,DIRT:0)
Block(-7,36,6,DIRT:1)
Block(-7,36,7,DIRT:1)
Block(-7,36,8,DIRT:1)
Block(-7,37,-7,DIRT:0)
Block(-7,37,-6,DIRT:0)
Block(-7,37,-5,DIRT:0)
Block(-7,37,-4,DIRT:0)
Block(-7,37,-3,DIRT:0)
Block(-7,37,-2,DIRT:0)
Block(-7,37,-1,DIRT:0)
Block(-7,37,0,DIRT:0)
Block(-7,37,1,DIRT:0)
Block(-7,37,2,DIRT:0)
Block(-7,37,3,DIRT:0)
Block(-7,37,4,DIRT:0)
Block(-7,37,5,DIRT:0)
Block(-7,37,6,DIRT:1)
Block(-7,37,7,DIRT:1)
Block(-7,37,8,DIRT:1)
Block(-7,38,-7,DIRT:0)
Block(-7,38,-6,GRASS:0)
Block(-7,38,-5,GRAVEL:0)
Block(-7,38,-4,GRAVEL:0)
Block(-7,38,-3,GRASS:0)
Block(-7,38,-2,GRASS:0)
Block(-7,38,-1,DIRT:0)
Block(-7,38,0,GRASS:0)
Block(-7,38,1,GRASS:0)
Block(-7,38,2,GRASS:0)
Block(-7,38,3,GRASS:0)
Block(-7,38,4,GRASS:0)
Block(-7,38,5,DIRT:0)
Block(-7,38,6,GRASS:0)
Block(-7,38,7,GRASS:0)
Block(-7,38,8,GRASS:0)
Block(-7,39,-7,PUMPKIN:0)
Block(-7,39,-5,SPRUCE_WOOD_STAIRS:7)
Block(-7,39,-4,WOOD_STEP:9)
Block(-7,39,-3,SPRUCE_WOOD_STAIRS:6)
Block(-7,39,-1,HAY_BLOCK:0)
Block(-7,39,0,WOOD_STEP:9)
Block(-7,39,2,LONG_GRASS:1)
Block(-7,39,3,LONG_GRASS:1)
Block(-7,39,4,YELLOW_FLOWER:0)
Block(-7,39,5,LOG_2:13)
Block(-7,39,6,LONG_GRASS:1)
Block(-7,39,7,LONG_GRASS:1)
Block(-7,39,8,LONG_GRASS:1)
RandomBlock(-7,40,-7,AIR:0,20,CHEST:3,../../../Chests/Loot/JunkChest_1.nbt,10,CHEST:3,../../../Chests/Loot/JunkChest_2.nbt,10,CHEST:3,../../../Chests/Loot/JunkChest_3.nbt,10,CHEST:3,../../../Chests/Loot/JunkChest_4.nbt,10,CHEST:3,../../../Chests/Loot/JunkChest_5.nbt,10,CHEST:3,../../../Chests/Lore/village_1.nbt,1,CHEST:3,../../../Chests/Lore/village_2.nbt,1,CHEST:3,../../../Chests/Lore/village_3.nbt,1,CHEST:3,../../../Chests/Lore/village_4.nbt,1,CHEST:3,../../../Chests/Lore/village_5.nbt,1,CHEST:3,../../../Chests/Loot/Common1.nbt,10,CHEST:3,../../../Chests/Loot/Common2.nbt,10,CHEST:3,../../../Chests/Loot/Common3.nbt,10,CHEST:3,../../../Chests/Loot/Common4.nbt,10,CHEST:3,../../../Chests/Loot/Common5.nbt,10,CHEST:3,../../../Chests/Loot/Common6.nbt,10,CHEST:3,../../../Chests/Loot/Common7.nbt,10,CHEST:3,../../../Chests/Loot/Common8.nbt,10,CHEST:3,../../../Chests/Loot/Common9.nbt,10,CHEST:3,../../../Chests/Loot/Common10.nbt,10,CHEST:3,../../../Chests/Loot/Common10.nbt,11,CHEST:3,../../../Chests/Loot/Common12.nbt,10,CHEST:3,../../../Chests/Loot/Common13.nbt,10,CHEST:3,../../../Chests/Loot/Common14.nbt,10,CHEST:3,../../../Chests/Loot/Common15.nbt,10,CHEST:3,../../../Chests/Lore/village_1.nbt,2,CHEST:3,../../../Chests/Lore/village_3.nbt,2,CHEST:3,../../../Chests/Lore/village_4.nbt,2,CHEST:3,../../../Chests/Lore/village_5.nbt,2,CHEST:3,../../../Chests/Lore/village_5.nbt,2,CHEST:3,../../../Chests/Loot/Rare1.nbt,5,CHEST:3,../../../Chests/Loot/Rare2.nbt,5,CHEST:3,../../../Chests/Loot/Rare3.nbt,5,CHEST:3,../../../Chests/Loot/Rare4.nbt,5,CHEST:3,../../../Chests/Loot/Rare5.nbt,5,CHEST:3,../../../Chests/Loot/Rare6.nbt,5,CHEST:3,../../../Chests/Loot/Rare7.nbt,5,CHEST:3,../../../Chests/Loot/Rare8.nbt,5,CHEST:3,../../../Chests/Loot/Rare9.nbt,5,CHEST:3,../../../Chests/Loot/Rare10.nbt,5,CHEST:3,../../../Chests/Loot/Rare11.nbt,5,CHEST:3,../../../Chests/Loot/Rare12.nbt,5,CHEST:3,../../../Chests/Loot/Rare13.nbt,5,CHEST:3,../../../Chests/Loot/Rare14.nbt,5,CHEST:3,../../../Chests/Loot/Rare15.nbt,5,CHEST:3,../../../Chests/Loot/Epic1.nbt,2,CHEST:3,../../../Chests/Loot/Epic2.nbt,2,CHEST:3,../../../Chests/Loot/Epic3.nbt,2,CHEST:3,../../../Chests/Loot/Epic4.nbt,2,CHEST:3,../../../Chests/Loot/Epic5.nbt,2,CHEST:3,../../../Chests/Loot/Epic6.nbt,2,CHEST:3,../../../Chests/Loot/Epic7.nbt,2,CHEST:3,../../../Chests/Loot/Epic8.nbt,2,CHEST:3,../../../Chests/Loot/Epic9.nbt,2,CHEST:3,../../../Chests/Loot/Epic10.nbt,2,CHEST:3,../../../Chests/Loot/Epic11.nbt,2,CHEST:3,../../../Chests/Loot/Epic12.nbt,2,CHEST:3,../../../Chests/Loot/Epic13.nbt,2,CHEST:3,../../../Chests/Loot/Epic14.nbt,2,CHEST:3,../../../Chests/Loot/Epic15.nbt,5,CHEST:3,../../../Chests/Loot/Rare1.nbt,5,CHEST:3,../../../Chests/Loot/Rare2.nbt,5,CHEST:3,../../../Chests/Loot/Rare3.nbt,5,CHEST:3,../../../Chests/Loot/Rare4.nbt,5,CHEST:3,../../../Chests/Loot/Rare5.nbt,10,CHEST:3,../../../Chests/Loot/Rare6.nbt,10,CHEST:3,../../../Chests/Loot/Rare7.nbt,10,CHEST:3,../../../Chests/Loot/Rare8.nbt,10,CHEST:3,../../../Chests/Loot/Rare9.nbt,10,CHEST:3,../../../Chests/Loot/Rare10.nbt,15,CHEST:3,../../../Chests/Loot/Rare11.nbt,15,CHEST:3,../../../Chests/Loot/Rare12.nbt,15,CHEST:3,../../../Chests/Loot/Rare13.nbt,15,CHEST:3,../../../Chests/Loot/Rare14.nbt,15,CHEST:3,../../../Chests/Loot/Rare15.nbt,15,CHEST:3,../../../Chests/Loot/Epic15.nbt,100)
Block(-7,40,-5,FLOWER_POT:0,../NBT/DaerocVillage/1526-flower_potC240R176.nbt)
Block(-7,40,-3,CAKE_BLOCK:0)
Block(-7,40,0,CARPET:6)
Block(-7,40,5,LOG_2:13)
Block(-7,41,5,LOG_2:13)
Block(-7,41,6,LEAVES:0)
Block(-7,42,-7,WOOL:12)
Block(-7,42,-6,WOOL:1)
Block(-7,42,-5,WOOL:12)
Block(-7,42,-4,WOOL:1)
Block(-7,42,-3,WOOL:12)
Block(-7,42,-2,WOOL:1)
Block(-7,42,-1,WOOL:12)
Block(-7,42,0,WOOD_STEP:9)
Block(-7,42,3,LEAVES:0)
Block(-7,42,5,LOG_2:13)
Block(-7,42,6,LEAVES:0)
Block(-7,43,-7,WOOD_STEP:1)
Block(-7,43,-6,WOOL:1)
Block(-7,43,-5,WOOL:12)
Block(-7,43,-4,WOOL:1)
Block(-7,43,-3,WOOL:12)
Block(-7,43,-2,WOOL:1)
Block(-7,43,-1,WOOD_STEP:1)
Block(-7,43,3,LEAVES:0)
Block(-7,43,4,LEAVES:0)
Block(-7,43,5,LOG_2:13)
Block(-7,43,6,LEAVES:0)
Block(-7,43,8,LEAVES:0)
Block(-7,44,-5,WOOD_STEP:1)
Block(-7,44,-4,WOOD_STEP:1)
Block(-7,44,-3,WOOD_STEP:1)
Block(-7,44,3,LEAVES:0)
Block(-7,44,4,LEAVES:0)
Block(-7,44,5,LOG_2:13)
Block(-7,44,6,LEAVES:0)
Block(-7,44,8,LEAVES:0)
Block(-7,45,1,LEAVES:0)
Block(-7,45,3,LEAVES:0)
Block(-7,45,4,LEAVES:0)
Block(-7,45,5,LOG_2:13)
Block(-7,45,6,LOG_2:13)
Block(-7,45,7,LEAVES:0)
Block(-7,45,8,LEAVES:0)
Block(-7,46,0,LEAVES:0)
Block(-7,46,1,LEAVES:0)
Block(-7,46,2,LEAVES:0)
Block(-7,46,3,LEAVES:0)
Block(-7,46,4,LEAVES:0)
Block(-7,46,5,LOG_2:13)
Block(-7,46,6,LEAVES:0)
Block(-7,46,7,LOG_2:13)
Block(-7,46,8,LEAVES:0)
Block(-7,47,0,LEAVES:0)
Block(-7,47,1,LEAVES:0)
Block(-7,47,3,LEAVES:0)
Block(-7,47,4,LEAVES:0)
Block(-7,47,5,LOG_2:13)
Block(-7,47,6,LEAVES:0)
Block(-7,47,7,LOG_2:13)
Block(-7,47,8,LEAVES:0)
Block(-7,48,1,LEAVES:0)
Block(-7,48,2,LEAVES:0)
Block(-7,48,3,LEAVES:0)
Block(-7,48,4,LEAVES:0)
Block(-7,48,6,LEAVES:0)
Block(-7,48,7,LEAVES:0)
Block(-7,48,8,LOG_2:13)
Block(-7,49,3,LEAVES:0)
Block(-7,49,4,LEAVES:0)
Block(-7,49,6,LEAVES:0)
Block(-7,49,7,LEAVES:0)
Block(-7,49,8,LEAVES:0)
Block(-7,50,6,LEAVES:0)
Block(-7,50,7,LEAVES:0)
Block(-6,0,-7,STONE:0)
Block(-6,0,-6,STONE:0)
Block(-6,0,-5,STONE:0)
Block(-6,0,-4,STONE:0)
Block(-6,0,-3,STONE:0)
Block(-6,0,-2,STONE:0)
Block(-6,0,-1,STONE:0)
Block(-6,0,0,STONE:0)
Block(-6,0,1,STONE:0)
Block(-6,0,2,STONE:0)
Block(-6,0,3,STONE:0)
Block(-6,0,4,STONE:0)
Block(-6,0,5,STONE:0)
Block(-6,0,6,STONE:0)
Block(-6,0,7,STONE:0)
Block(-6,0,8,STONE:0)
Block(-6,1,-7,STONE:0)
Block(-6,1,-6,STONE:0)
Block(-6,1,-5,STONE:0)
Block(-6,1,-4,STONE:0)
Block(-6,1,-3,STONE:0)
Block(-6,1,-2,STONE:0)
Block(-6,1,-1,STONE:0)
Block(-6,1,0,STONE:0)
Block(-6,1,1,STONE:0)
Block(-6,1,2,STONE:0)
Block(-6,1,3,STONE:0)
Block(-6,1,4,STONE:0)
Block(-6,1,5,STONE:0)
Block(-6,1,6,STONE:0)
Block(-6,1,7,STONE:0)
Block(-6,1,8,STONE:0)
Block(-6,2,-7,STONE:0)
Block(-6,2,-6,STONE:0)
Block(-6,2,-5,STONE:0)
Block(-6,2,-4,STONE:0)
Block(-6,2,-3,STONE:0)
Block(-6,2,-2,STONE:0)
Block(-6,2,-1,STONE:0)
Block(-6,2,0,STONE:0)
Block(-6,2,1,STONE:0)
Block(-6,2,2,STONE:0)
Block(-6,2,3,STONE:0)
Block(-6,2,4,STONE:0)
Block(-6,2,5,STONE:0)
Block(-6,2,6,STONE:0)
Block(-6,2,7,STONE:0)
Block(-6,2,8,STONE:0)
Block(-6,3,-7,STONE:0)
Block(-6,3,-6,STONE:0)
Block(-6,3,-5,STONE:0)
Block(-6,3,-4,STONE:0)
Block(-6,3,-3,STONE:0)
Block(-6,3,-2,STONE:0)
Block(-6,3,-1,STONE:0)
Block(-6,3,0,STONE:0)
Block(-6,3,1,STONE:0)
Block(-6,3,2,STONE:0)
Block(-6,3,3,STONE:0)
Block(-6,3,4,STONE:0)
Block(-6,3,5,STONE:0)
Block(-6,3,6,STONE:0)
Block(-6,3,7,STONE:0)
Block(-6,3,8,STONE:0)
Block(-6,4,-7,STONE:0)
Block(-6,4,-6,STONE:0)
Block(-6,4,-5,STONE:0)
Block(-6,4,-4,STONE:0)
Block(-6,4,-3,STONE:0)
Block(-6,4,-2,STONE:0)
Block(-6,4,-1,STONE:0)
Block(-6,4,0,STONE:0)
Block(-6,4,1,STONE:0)
Block(-6,4,2,STONE:0)
Block(-6,4,3,STONE:0)
Block(-6,4,4,STONE:0)
Block(-6,4,5,STONE:0)
Block(-6,4,6,STONE:0)
Block(-6,4,7,STONE:0)
Block(-6,4,8,STONE:0)
Block(-6,5,-7,STONE:0)
Block(-6,5,-6,STONE:0)
Block(-6,5,-5,STONE:0)
Block(-6,5,-4,STONE:0)
Block(-6,5,-3,STONE:0)
Block(-6,5,-2,STONE:0)
Block(-6,5,-1,STONE:0)
Block(-6,5,0,STONE:0)
Block(-6,5,1,STONE:0)
Block(-6,5,2,STONE:0)
Block(-6,5,3,STONE:0)
Block(-6,5,4,STONE:0)
Block(-6,5,5,STONE:0)
Block(-6,5,6,STONE:0)
Block(-6,5,7,STONE:0)
Block(-6,5,8,STONE:0)
Block(-6,6,-7,STONE:0)
Block(-6,6,-6,STONE:0)
Block(-6,6,-5,STONE:0)
Block(-6,6,-4,STONE:0)
Block(-6,6,-3,STONE:0)
Block(-6,6,-2,STONE:0)
Block(-6,6,-1,STONE:0)
Block(-6,6,0,STONE:0)
Block(-6,6,1,STONE:0)
Block(-6,6,2,STONE:0)
Block(-6,6,3,STONE:0)
Block(-6,6,4,STONE:0)
Block(-6,6,5,STONE:0)
Block(-6,6,6,STONE:0)
Block(-6,6,7,STONE:0)
Block(-6,6,8,STONE:0)
Block(-6,7,-7,STONE:0)
Block(-6,7,-6,STONE:0)
Block(-6,7,-5,STONE:0)
Block(-6,7,-4,STONE:0)
Block(-6,7,-3,STONE:0)
Block(-6,7,-2,STONE:0)
Block(-6,7,-1,STONE:0)
Block(-6,7,0,STONE:0)
Block(-6,7,1,STONE:0)
Block(-6,7,2,STONE:0)
Block(-6,7,3,STONE:0)
Block(-6,7,4,STONE:0)
Block(-6,7,5,STONE:0)
Block(-6,7,6,STONE:0)
Block(-6,7,7,STONE:0)
Block(-6,7,8,STONE:0)
Block(-6,8,-7,STONE:0)
Block(-6,8,-6,STONE:0)
Block(-6,8,-5,STONE:0)
Block(-6,8,-4,STONE:0)
Block(-6,8,-3,STONE:0)
Block(-6,8,-2,STONE:0)
Block(-6,8,-1,STONE:0)
Block(-6,8,0,STONE:0)
Block(-6,8,1,STONE:0)
Block(-6,8,2,STONE:0)
Block(-6,8,3,STONE:0)
Block(-6,8,4,STONE:0)
Block(-6,8,5,STONE:0)
Block(-6,8,6,STONE:0)
Block(-6,8,7,STONE:0)
Block(-6,8,8,STONE:0)
Block(-6,9,-7,STONE:0)
Block(-6,9,-6,STONE:0)
Block(-6,9,-5,STONE:0)
Block(-6,9,-4,STONE:0)
Block(-6,9,-3,STONE:0)
Block(-6,9,-2,STONE:0)
Block(-6,9,-1,STONE:0)
Block(-6,9,0,STONE:0)
Block(-6,9,1,STONE:0)
Block(-6,9,2,STONE:0)
Block(-6,9,3,STONE:0)
Block(-6,9,4,STONE:0)
Block(-6,9,5,STONE:0)
Block(-6,9,6,STONE:0)
Block(-6,9,7,STONE:0)
Block(-6,9,8,STONE:0)
Block(-6,10,-7,STONE:0)
Block(-6,10,-6,STONE:0)
Block(-6,10,-5,STONE:0)
Block(-6,10,-4,STONE:0)
Block(-6,10,-3,STONE:0)
Block(-6,10,-2,STONE:0)
Block(-6,10,-1,STONE:0)
Block(-6,10,0,STONE:0)
Block(-6,10,1,STONE:0)
Block(-6,10,2,STONE:0)
Block(-6,10,3,STONE:0)
Block(-6,10,4,STONE:0)
Block(-6,10,5,STONE:0)
Block(-6,10,6,STONE:0)
Block(-6,10,7,STONE:0)
Block(-6,10,8,STONE:0)
Block(-6,11,-7,STONE:0)
Block(-6,11,-6,STONE:0)
Block(-6,11,-5,STONE:0)
Block(-6,11,-4,STONE:0)
Block(-6,11,-3,STONE:0)
Block(-6,11,-2,STONE:0)
Block(-6,11,-1,STONE:0)
Block(-6,11,0,STONE:0)
Block(-6,11,1,STONE:0)
Block(-6,11,2,STONE:0)
Block(-6,11,3,STONE:0)
Block(-6,11,4,STONE:0)
Block(-6,11,5,STONE:0)
Block(-6,11,6,STONE:0)
Block(-6,11,7,STONE:0)
Block(-6,11,8,STONE:0)
Block(-6,12,-7,STONE:0)
Block(-6,12,-6,STONE:0)
Block(-6,12,-5,STONE:0)
Block(-6,12,-4,STONE:0)
Block(-6,12,-3,STONE:0)
Block(-6,12,-2,STONE:0)
Block(-6,12,-1,STONE:0)
Block(-6,12,0,STONE:0)
Block(-6,12,1,STONE:0)
Block(-6,12,2,STONE:0)
Block(-6,12,3,STONE:0)
Block(-6,12,4,STONE:0)
Block(-6,12,5,STONE:0)
Block(-6,12,6,STONE:0)
Block(-6,12,7,STONE:0)
Block(-6,12,8,STONE:0)
Block(-6,13,-7,STONE:0)
Block(-6,13,-6,STONE:0)
Block(-6,13,-5,STONE:0)
Block(-6,13,-4,STONE:0)
Block(-6,13,-3,STONE:0)
Block(-6,13,-2,STONE:0)
Block(-6,13,-1,STONE:0)
Block(-6,13,0,STONE:0)
Block(-6,13,1,STONE:0)
Block(-6,13,2,STONE:0)
Block(-6,13,3,STONE:0)
Block(-6,13,4,STONE:0)
Block(-6,13,5,STONE:0)
Block(-6,13,6,STONE:0)
Block(-6,13,7,STONE:0)
Block(-6,13,8,STONE:0)
Block(-6,14,-7,STONE:0)
Block(-6,14,-6,STONE:0)
Block(-6,14,-5,STONE:0)
Block(-6,14,-4,STONE:0)
Block(-6,14,-3,STONE:0)
Block(-6,14,-2,STONE:0)
Block(-6,14,-1,STONE:0)
Block(-6,14,0,STONE:0)
Block(-6,14,1,STONE:0)
Block(-6,14,2,STONE:0)
Block(-6,14,3,STONE:0)
Block(-6,14,4,STONE:0)
Block(-6,14,5,STONE:0)
Block(-6,14,6,STONE:0)
Block(-6,14,7,STONE:0)
Block(-6,14,8,STONE:0)
Block(-6,15,-7,STONE:0)
Block(-6,15,-6,STONE:0)
Block(-6,15,-5,STONE:0)
Block(-6,15,-4,STONE:0)
Block(-6,15,-3,STONE:0)
Block(-6,15,-2,STONE:0)
Block(-6,15,-1,STONE:0)
Block(-6,15,0,STONE:0)
Block(-6,15,1,STONE:0)
Block(-6,15,2,STONE:0)
Block(-6,15,3,STONE:0)
Block(-6,15,4,STONE:0)
Block(-6,15,5,STONE:0)
Block(-6,15,6,STONE:0)
Block(-6,15,7,STONE:0)
Block(-6,15,8,STONE:0)
Block(-6,16,-7,STONE:0)
Block(-6,16,-6,STONE:0)
Block(-6,16,-5,STONE:0)
Block(-6,16,-4,STONE:0)
Block(-6,16,-3,STONE:0)
Block(-6,16,-2,STONE:0)
Block(-6,16,-1,STONE:0)
Block(-6,16,0,STONE:0)
Block(-6,16,1,STONE:0)
Block(-6,16,2,STONE:0)
Block(-6,16,3,STONE:0)
Block(-6,16,4,STONE:0)
Block(-6,16,5,STONE:0)
Block(-6,16,6,STONE:0)
Block(-6,16,7,STONE:0)
Block(-6,16,8,STONE:0)
Block(-6,17,-7,STONE:0)
Block(-6,17,-6,STONE:0)
Block(-6,17,-5,STONE:0)
Block(-6,17,-4,STONE:0)
Block(-6,17,-3,STONE:0)
Block(-6,17,-2,STONE:0)
Block(-6,17,-1,STONE:0)
Block(-6,17,0,STONE:0)
Block(-6,17,1,STONE:0)
Block(-6,17,2,STONE:0)
Block(-6,17,3,STONE:0)
Block(-6,17,4,STONE:0)
Block(-6,17,5,STONE:0)
Block(-6,17,6,STONE:0)
Block(-6,17,7,STONE:0)
Block(-6,17,8,STONE:0)
Block(-6,18,-7,STONE:0)
Block(-6,18,-6,REDSTONE_BLOCK:0)
Block(-6,18,-5,STONE:0)
Block(-6,18,-4,STONE:0)
Block(-6,18,-3,STONE:0)
Block(-6,18,-2,STONE:0)
Block(-6,18,-1,STONE:0)
Block(-6,18,0,STONE:0)
Block(-6,18,1,MAGMA:0)
Block(-6,18,2,MAGMA:0)
Block(-6,18,3,STONE:0)
Block(-6,18,4,STONE:0)
Block(-6,18,5,STONE:0)
Block(-6,18,6,STONE:0)
Block(-6,18,7,STONE:0)
Block(-6,18,8,STONE:0)
Block(-6,19,-7,MAGMA:0)
Block(-6,19,-6,PISTON_BASE:9)
Block(-6,19,-5,CONCRETE:7)
Block(-6,19,-4,CONCRETE:7)
Block(-6,19,-3,CONCRETE:7)
Block(-6,19,-2,CONCRETE:7)
Block(-6,19,-1,CONCRETE:7)
Block(-6,19,0,CONCRETE:7)
Block(-6,19,1,STAINED_GLASS:15)
Block(-6,19,2,STAINED_GLASS:15)
Block(-6,19,3,CONCRETE:7)
Block(-6,19,4,CONCRETE:7)
Block(-6,19,5,CONCRETE:7)
Block(-6,19,6,CONCRETE:7)
Block(-6,19,7,CONCRETE:7)
Block(-6,19,8,CONCRETE:7)
Block(-6,20,-7,SMOOTH_BRICK:0)
Block(-6,20,-6,PISTON_MOVING_PIECE:1)
Block(-6,20,-3,JUNGLE_WOOD_STAIRS:3)
Block(-6,20,-2,DARK_OAK_FENCE:0)
Block(-6,20,-1,JUNGLE_WOOD_STAIRS:2)
Block(-6,20,1,CARPET:14)
Block(-6,20,2,CARPET:14)
Block(-6,20,4,DARK_OAK_FENCE:0)
Block(-6,20,5,CARPET:15)
Block(-6,20,6,CARPET:15)
Block(-6,20,7,CARPET:15)
Block(-6,21,-7,SMOOTH_BRICK:0)
Block(-6,21,-2,CARPET:7)
Block(-6,22,-7,SMOOTH_BRICK:0)
Block(-6,23,-7,SMOOTH_BRICK:0)
Block(-6,24,-7,SMOOTH_BRICK:0)
Block(-6,24,-6,SMOOTH_STAIRS:5)
Block(-6,25,-7,SMOOTH_BRICK:0)
Block(-6,25,-6,SMOOTH_BRICK:0)
Block(-6,25,-2,SMOOTH_BRICK:0)
Block(-6,25,-1,SMOOTH_BRICK:0)
Block(-6,25,4,SMOOTH_BRICK:0)
Block(-6,25,5,SMOOTH_BRICK:0)
Block(-6,26,-7,STONE:0)
Block(-6,26,-6,SMOOTH_BRICK:0)
Block(-6,26,-5,SMOOTH_BRICK:0)
Block(-6,26,-4,SMOOTH_BRICK:0)
Block(-6,26,-3,SMOOTH_BRICK:0)
Block(-6,26,-2,SMOOTH_BRICK:0)
Block(-6,26,-1,SMOOTH_BRICK:0)
Block(-6,26,0,SMOOTH_BRICK:0)
Block(-6,26,1,SMOOTH_BRICK:0)
Block(-6,26,2,SMOOTH_BRICK:0)
Block(-6,26,3,SMOOTH_BRICK:0)
Block(-6,26,4,SMOOTH_BRICK:0)
Block(-6,26,5,SMOOTH_BRICK:0)
Block(-6,26,6,SMOOTH_BRICK:0)
Block(-6,26,7,SMOOTH_BRICK:0)
Block(-6,26,8,SMOOTH_BRICK:0)
Block(-6,27,-7,STONE:0)
Block(-6,27,-6,STONE:0)
Block(-6,27,-5,STONE:0)
Block(-6,27,-4,STONE:0)
Block(-6,27,-3,STONE:0)
Block(-6,27,-2,STONE:0)
Block(-6,27,-1,STONE:0)
Block(-6,27,0,STONE:0)
Block(-6,27,1,STONE:0)
Block(-6,27,2,STONE:0)
Block(-6,27,3,STONE:0)
Block(-6,27,4,STONE:0)
Block(-6,27,5,STONE:0)
Block(-6,27,6,STONE:0)
Block(-6,27,7,STONE:0)
Block(-6,27,8,STONE:0)
Block(-6,28,-7,STONE:0)
Block(-6,28,-6,STONE:0)
Block(-6,28,-5,STONE:0)
Block(-6,28,-4,STONE:0)
Block(-6,28,-3,STONE:0)
Block(-6,28,-2,STONE:0)
Block(-6,28,-1,STONE:0)
Block(-6,28,0,STONE:0)
Block(-6,28,1,STONE:0)
Block(-6,28,2,STONE:0)
Block(-6,28,3,STONE:0)
Block(-6,28,4,STONE:0)
Block(-6,28,5,STONE:0)
Block(-6,28,6,STONE:0)
Block(-6,28,7,STONE:0)
Block(-6,28,8,STONE:0)
Block(-6,29,-7,STONE:0)
Block(-6,29,-6,STONE:0)
Block(-6,29,-5,STONE:0)
Block(-6,29,-4,STONE:0)
Block(-6,29,-3,STONE:0)
Block(-6,29,-2,STONE:0)
Block(-6,29,-1,STONE:0)
Block(-6,29,0,STONE:0)
Block(-6,29,1,STONE:0)
Block(-6,29,2,STONE:0)
Block(-6,29,3,STONE:0)
Block(-6,29,4,STONE:0)
Block(-6,29,5,STONE:0)
Block(-6,29,6,STONE:0)
Block(-6,29,7,STONE:0)
Block(-6,29,8,STONE:0)
Block(-6,30,-7,STONE:0)
Block(-6,30,-6,STONE:0)
Block(-6,30,-5,STONE:0)
Block(-6,30,-4,STONE:0)
Block(-6,30,-3,STONE:0)
Block(-6,30,-2,STONE:0)
Block(-6,30,-1,STONE:0)
Block(-6,30,0,STONE:0)
Block(-6,30,1,STONE:0)
Block(-6,30,2,STONE:0)
Block(-6,30,3,STONE:0)
Block(-6,30,4,STONE:0)
Block(-6,30,5,STONE:0)
Block(-6,30,6,STONE:0)
Block(-6,30,7,STONE:0)
Block(-6,30,8,STONE:0)
Block(-6,31,-7,STONE:0)
Block(-6,31,-6,STONE:0)
Block(-6,31,-5,STONE:0)
Block(-6,31,-4,STONE:0)
Block(-6,31,-3,STONE:0)
Block(-6,31,-2,STONE:0)
Block(-6,31,-1,STONE:0)
Block(-6,31,0,STONE:0)
Block(-6,31,1,STONE:0)
Block(-6,31,2,STONE:0)
Block(-6,31,3,STONE:0)
Block(-6,31,4,STONE:0)
Block(-6,31,5,STONE:0)
Block(-6,31,6,STONE:0)
Block(-6,31,7,STONE:0)
Block(-6,31,8,STONE:0)
Block(-6,32,-7,STONE:0)
Block(-6,32,-6,STONE:0)
Block(-6,32,-5,STONE:0)
Block(-6,32,-4,STONE:0)
Block(-6,32,-3,STONE:0)
Block(-6,32,-2,STONE:0)
Block(-6,32,-1,STONE:0)
Block(-6,32,0,STONE:0)
Block(-6,32,1,STONE:0)
Block(-6,32,2,STONE:0)
Block(-6,32,3,STONE:0)
Block(-6,32,4,STONE:0)
Block(-6,32,5,STONE:0)
Block(-6,32,6,STONE:0)
Block(-6,32,7,STONE:0)
Block(-6,32,8,STONE:0)
Block(-6,33,-7,STONE:0)
Block(-6,33,-6,STONE:0)
Block(-6,33,-5,STONE:0)
Block(-6,33,-4,STONE:0)
Block(-6,33,-3,STONE:0)
Block(-6,33,-2,STONE:0)
Block(-6,33,-1,STONE:0)
Block(-6,33,0,STONE:0)
Block(-6,33,1,STONE:0)
Block(-6,33,2,STONE:0)
Block(-6,33,3,STONE:0)
Block(-6,33,4,STONE:0)
Block(-6,33,5,STONE:0)
Block(-6,33,6,STONE:0)
Block(-6,33,7,STONE:0)
Block(-6,33,8,STONE:0)
Block(-6,34,-7,STONE:0)
Block(-6,34,-6,STONE:0)
Block(-6,34,-5,STONE:0)
Block(-6,34,-4,STONE:0)
Block(-6,34,-3,STONE:0)
Block(-6,34,-2,STONE:0)
Block(-6,34,-1,STONE:0)
Block(-6,34,0,STONE:0)
Block(-6,34,1,STONE:0)
Block(-6,34,2,STONE:0)
Block(-6,34,3,STONE:0)
Block(-6,34,4,STONE:0)
Block(-6,34,5,STONE:0)
Block(-6,34,6,STONE:0)
Block(-6,34,7,STONE:0)
Block(-6,34,8,STONE:0)
Block(-6,35,-7,STONE:0)
Block(-6,35,-6,STONE:0)
Block(-6,35,-5,STONE:0)
Block(-6,35,-4,STONE:0)
Block(-6,35,-3,STONE:0)
Block(-6,35,-2,STONE:0)
Block(-6,35,-1,STONE:0)
Block(-6,35,0,STONE:0)
Block(-6,35,1,STONE:0)
Block(-6,35,2,STONE:0)
Block(-6,35,3,STONE:0)
Block(-6,35,4,STONE:0)
Block(-6,35,5,STONE:0)
Block(-6,35,6,STONE:0)
Block(-6,35,7,STONE:0)
Block(-6,35,8,STONE:0)
Block(-6,36,-7,DIRT:0)
Block(-6,36,-6,DIRT:0)
Block(-6,36,-5,DIRT:0)
Block(-6,36,-4,DIRT:0)
Block(-6,36,-3,DIRT:0)
Block(-6,36,-2,DIRT:0)
Block(-6,36,-1,DIRT:0)
Block(-6,36,0,DIRT:0)
Block(-6,36,1,DIRT:0)
Block(-6,36,2,DIRT:0)
Block(-6,36,3,DIRT:0)
Block(-6,36,4,DIRT:0)
Block(-6,36,5,DIRT:0)
Block(-6,36,6,DIRT:0)
Block(-6,36,7,DIRT:1)
Block(-6,36,8,DIRT:1)
Block(-6,37,-7,DIRT:0)
Block(-6,37,-6,DIRT:0)
Block(-6,37,-5,DIRT:0)
Block(-6,37,-4,DIRT:0)
Block(-6,37,-3,DIRT:0)
Block(-6,37,-2,DIRT:0)
Block(-6,37,-1,DIRT:0)
Block(-6,37,0,DIRT:0)
Block(-6,37,1,DIRT:0)
Block(-6,37,2,DIRT:0)
Block(-6,37,3,DIRT:0)
Block(-6,37,4,DIRT:0)
Block(-6,37,5,DIRT:0)
Block(-6,37,6,DIRT:0)
Block(-6,37,7,DIRT:1)
Block(-6,37,8,DIRT:1)
Block(-6,38,-7,DIRT:0)
Block(-6,38,-6,DIRT:0)
Block(-6,38,-5,GRASS:0)
Block(-6,38,-4,DIRT:0)
Block(-6,38,-3,GRAVEL:0)
Block(-6,38,-2,GRASS:0)
Block(-6,38,-1,DIRT:0)
Block(-6,38,0,DIRT:0)
Block(-6,38,1,GRASS:0)
Block(-6,38,2,GRASS:0)
Block(-6,38,3,GRASS:0)
Block(-6,38,4,GRASS:0)
Block(-6,38,5,GRASS:0)
Block(-6,38,6,GRASS:0)
Block(-6,38,7,GRASS:0)
Block(-6,38,8,GRASS:0)
Block(-6,39,-7,MELON_BLOCK:0)
Block(-6,39,-6,HAY_BLOCK:0)
Block(-6,39,-4,CONCRETE_POWDER:1)
Block(-6,39,-1,HAY_BLOCK:0)
Block(-6,39,0,WOOD:1)
Block(-6,39,1,LONG_GRASS:1)
Block(-6,39,2,LONG_GRASS:1)
Block(-6,39,3,LONG_GRASS:1)
Block(-6,39,4,LONG_GRASS:1)
Block(-6,39,5,LONG_GRASS:1)
Block(-6,39,6,LONG_GRASS:1)
Block(-6,39,7,LONG_GRASS:1)
Block(-6,39,8,LONG_GRASS:1)
RandomBlock(-6,40,-7,AIR:0,20,CHEST:3,../../../Chests/Loot/JunkChest_1.nbt,10,CHEST:3,../../../Chests/Loot/JunkChest_2.nbt,10,CHEST:3,../../../Chests/Loot/JunkChest_3.nbt,10,CHEST:3,../../../Chests/Loot/JunkChest_4.nbt,10,CHEST:3,../../../Chests/Loot/JunkChest_5.nbt,10,CHEST:3,../../../Chests/Lore/village_1.nbt,1,CHEST:3,../../../Chests/Lore/village_2.nbt,1,CHEST:3,../../../Chests/Lore/village_3.nbt,1,CHEST:3,../../../Chests/Lore/village_4.nbt,1,CHEST:3,../../../Chests/Lore/village_5.nbt,1,CHEST:3,../../../Chests/Loot/Common1.nbt,10,CHEST:3,../../../Chests/Loot/Common2.nbt,10,CHEST:3,../../../Chests/Loot/Common3.nbt,10,CHEST:3,../../../Chests/Loot/Common4.nbt,10,CHEST:3,../../../Chests/Loot/Common5.nbt,10,CHEST:3,../../../Chests/Loot/Common6.nbt,10,CHEST:3,../../../Chests/Loot/Common7.nbt,10,CHEST:3,../../../Chests/Loot/Common8.nbt,10,CHEST:3,../../../Chests/Loot/Common9.nbt,10,CHEST:3,../../../Chests/Loot/Common10.nbt,10,CHEST:3,../../../Chests/Loot/Common10.nbt,11,CHEST:3,../../../Chests/Loot/Common12.nbt,10,CHEST:3,../../../Chests/Loot/Common13.nbt,10,CHEST:3,../../../Chests/Loot/Common14.nbt,10,CHEST:3,../../../Chests/Loot/Common15.nbt,10,CHEST:3,../../../Chests/Lore/village_1.nbt,2,CHEST:3,../../../Chests/Lore/village_3.nbt,2,CHEST:3,../../../Chests/Lore/village_4.nbt,2,CHEST:3,../../../Chests/Lore/village_5.nbt,2,CHEST:3,../../../Chests/Lore/village_5.nbt,2,CHEST:3,../../../Chests/Loot/Rare1.nbt,5,CHEST:3,../../../Chests/Loot/Rare2.nbt,5,CHEST:3,../../../Chests/Loot/Rare3.nbt,5,CHEST:3,../../../Chests/Loot/Rare4.nbt,5,CHEST:3,../../../Chests/Loot/Rare5.nbt,5,CHEST:3,../../../Chests/Loot/Rare6.nbt,5,CHEST:3,../../../Chests/Loot/Rare7.nbt,5,CHEST:3,../../../Chests/Loot/Rare8.nbt,5,CHEST:3,../../../Chests/Loot/Rare9.nbt,5,CHEST:3,../../../Chests/Loot/Rare10.nbt,5,CHEST:3,../../../Chests/Loot/Rare11.nbt,5,CHEST:3,../../../Chests/Loot/Rare12.nbt,5,CHEST:3,../../../Chests/Loot/Rare13.nbt,5,CHEST:3,../../../Chests/Loot/Rare14.nbt,5,CHEST:3,../../../Chests/Loot/Rare15.nbt,5,CHEST:3,../../../Chests/Loot/Epic1.nbt,2,CHEST:3,../../../Chests/Loot/Epic2.nbt,2,CHEST:3,../../../Chests/Loot/Epic3.nbt,2,CHEST:3,../../../Chests/Loot/Epic4.nbt,2,CHEST:3,../../../Chests/Loot/Epic5.nbt,2,CHEST:3,../../../Chests/Loot/Epic6.nbt,2,CHEST:3,../../../Chests/Loot/Epic7.nbt,2,CHEST:3,../../../Chests/Loot/Epic8.nbt,2,CHEST:3,../../../Chests/Loot/Epic9.nbt,2,CHEST:3,../../../Chests/Loot/Epic10.nbt,2,CHEST:3,../../../Chests/Loot/Epic11.nbt,2,CHEST:3,../../../Chests/Loot/Epic12.nbt,2,CHEST:3,../../../Chests/Loot/Epic13.nbt,2,CHEST:3,../../../Chests/Loot/Epic14.nbt,2,CHEST:3,../../../Chests/Loot/Epic15.nbt,5,CHEST:3,../../../Chests/Loot/Rare1.nbt,5,CHEST:3,../../../Chests/Loot/Rare2.nbt,5,CHEST:3,../../../Chests/Loot/Rare3.nbt,5,CHEST:3,../../../Chests/Loot/Rare4.nbt,5,CHEST:3,../../../Chests/Loot/Rare5.nbt,10,CHEST:3,../../../Chests/Loot/Rare6.nbt,10,CHEST:3,../../../Chests/Loot/Rare7.nbt,10,CHEST:3,../../../Chests/Loot/Rare8.nbt,10,CHEST:3,../../../Chests/Loot/Rare9.nbt,10,CHEST:3,../../../Chests/Loot/Rare10.nbt,15,CHEST:3,../../../Chests/Loot/Rare11.nbt,15,CHEST:3,../../../Chests/Loot/Rare12.nbt,15,CHEST:3,../../../Chests/Loot/Rare13.nbt,15,CHEST:3,../../../Chests/Loot/Rare14.nbt,15,CHEST:3,../../../Chests/Loot/Rare15.nbt,15,CHEST:3,../../../Chests/Loot/Epic15.nbt,100)
Block(-6,40,-1,HAY_BLOCK:0)
Block(-6,40,0,DARK_OAK_FENCE:0)
Block(-6,41,0,DARK_OAK_FENCE:0)
Block(-6,41,5,LEAVES:0)
Block(-6,41,6,LEAVES:0)
Block(-6,42,-7,WOOL:12)
Block(-6,42,-6,WOOL:1)
Block(-6,42,-5,WOOL:12)
Block(-6,42,-4,WOOL:1)
Block(-6,42,-3,WOOL:12)
Block(-6,42,-2,WOOL:1)
Block(-6,42,-1,WOOL:12)
Block(-6,42,0,WOOD:1)
Block(-6,42,6,LEAVES:4)
Block(-6,42,7,LEAVES:0)
Block(-6,42,8,LEAVES:0)
Block(-6,43,-7,WOOD_STEP:1)
Block(-6,43,-6,WOOL:1)
Block(-6,43,-5,WOOL:12)
Block(-6,43,-4,WOOL:1)
Block(-6,43,-3,WOOL:12)
Block(-6,43,-2,WOOL:1)
Block(-6,43,-1,WOOD_STEP:1)
Block(-6,43,2,LEAVES:0)
Block(-6,43,3,LEAVES:0)
Block(-6,43,4,LEAVES:0)
Block(-6,43,5,LEAVES:4)
Block(-6,43,6,LEAVES:4)
Block(-6,43,7,LEAVES:0)
Block(-6,43,8,LEAVES:0)
Block(-6,44,2,LEAVES:0)
Block(-6,44,3,LEAVES:0)
Block(-6,44,4,LEAVES:0)
Block(-6,44,5,LEAVES:0)
Block(-6,44,6,LEAVES:0)
Block(-6,44,7,LEAVES:0)
Block(-6,44,8,LEAVES:0)
Block(-6,45,3,LEAVES:0)
Block(-6,45,5,LEAVES:0)
Block(-6,45,6,LEAVES:0)
Block(-6,45,7,LEAVES:0)
Block(-6,45,8,LEAVES:0)
Block(-6,46,1,LEAVES:0)
Block(-6,46,4,LOG_2:13)
Block(-6,46,5,LEAVES:0)
Block(-6,46,6,LEAVES:0)
Block(-6,46,8,LEAVES:0)
Block(-6,47,1,LEAVES:0)
Block(-6,47,3,LEAVES:0)
Block(-6,47,4,LEAVES:0)
Block(-6,47,5,LEAVES:0)
Block(-6,47,6,LEAVES:0)
Block(-6,47,8,LEAVES:0)
Block(-6,48,1,LEAVES:0)
Block(-6,48,2,LEAVES:0)
Block(-6,48,3,LEAVES:0)
Block(-6,48,6,LEAVES:0)
Block(-6,48,8,LEAVES:0)
Block(-6,49,3,LEAVES:0)
Block(-6,49,4,LEAVES:0)
Block(-6,49,6,LEAVES:0)
Block(-6,49,7,LEAVES:0)
Block(-6,49,8,LEAVES:0)
Block(-6,50,3,LEAVES:0)
Block(-5,0,-7,STONE:0)
Block(-5,0,-6,STONE:0)
Block(-5,0,-5,STONE:0)
Block(-5,0,-4,STONE:0)
Block(-5,0,-3,STONE:0)
Block(-5,0,-2,STONE:0)
Block(-5,0,-1,STONE:0)
Block(-5,0,0,STONE:0)
Block(-5,0,1,STONE:0)
Block(-5,0,2,STONE:0)
Block(-5,0,3,STONE:0)
Block(-5,0,4,STONE:0)
Block(-5,0,5,STONE:0)
Block(-5,0,6,STONE:0)
Block(-5,0,7,STONE:0)
Block(-5,0,8,STONE:0)
Block(-5,1,-7,STONE:0)
Block(-5,1,-6,STONE:0)
Block(-5,1,-5,STONE:0)
Block(-5,1,-4,STONE:0)
Block(-5,1,-3,STONE:0)
Block(-5,1,-2,STONE:0)
Block(-5,1,-1,STONE:0)
Block(-5,1,0,STONE:0)
Block(-5,1,1,STONE:0)
Block(-5,1,2,STONE:0)
Block(-5,1,3,STONE:0)
Block(-5,1,4,STONE:0)
Block(-5,1,5,STONE:0)
Block(-5,1,6,STONE:0)
Block(-5,1,7,STONE:0)
Block(-5,1,8,STONE:0)
Block(-5,2,-7,STONE:0)
Block(-5,2,-6,STONE:0)
Block(-5,2,-5,STONE:0)
Block(-5,2,-4,STONE:0)
Block(-5,2,-3,STONE:0)
Block(-5,2,-2,STONE:0)
Block(-5,2,-1,STONE:0)
Block(-5,2,0,STONE:0)
Block(-5,2,1,STONE:0)
Block(-5,2,2,STONE:0)
Block(-5,2,3,STONE:0)
Block(-5,2,4,STONE:0)
Block(-5,2,5,STONE:0)
Block(-5,2,6,STONE:0)
Block(-5,2,7,STONE:0)
Block(-5,2,8,STONE:0)
Block(-5,3,-7,STONE:0)
Block(-5,3,-6,STONE:0)
Block(-5,3,-5,STONE:0)
Block(-5,3,-4,STONE:0)
Block(-5,3,-3,STONE:0)
Block(-5,3,-2,STONE:0)
Block(-5,3,-1,STONE:0)
Block(-5,3,0,STONE:0)
Block(-5,3,1,STONE:0)
Block(-5,3,2,STONE:0)
Block(-5,3,3,STONE:0)
Block(-5,3,4,STONE:0)
Block(-5,3,5,STONE:0)
Block(-5,3,6,STONE:0)
Block(-5,3,7,STONE:0)
Block(-5,3,8,STONE:0)
Block(-5,4,-7,STONE:0)
Block(-5,4,-6,STONE:0)
Block(-5,4,-5,STONE:0)
Block(-5,4,-4,STONE:0)
Block(-5,4,-3,STONE:0)
Block(-5,4,-2,STONE:0)
Block(-5,4,-1,STONE:0)
Block(-5,4,0,STONE:0)
Block(-5,4,1,STONE:0)
Block(-5,4,2,STONE:0)
Block(-5,4,3,STONE:0)
Block(-5,4,4,STONE:0)
Block(-5,4,5,STONE:0)
Block(-5,4,6,STONE:0)
Block(-5,4,7,STONE:0)
Block(-5,4,8,STONE:0)
Block(-5,5,-7,STONE:0)
Block(-5,5,-6,STONE:0)
Block(-5,5,-5,STONE:0)
Block(-5,5,-4,STONE:0)
Block(-5,5,-3,STONE:0)
Block(-5,5,-2,STONE:0)
Block(-5,5,-1,STONE:0)
Block(-5,5,0,STONE:0)
Block(-5,5,1,STONE:0)
Block(-5,5,2,STONE:0)
Block(-5,5,3,STONE:0)
Block(-5,5,4,STONE:0)
Block(-5,5,5,STONE:0)
Block(-5,5,6,STONE:0)
Block(-5,5,7,STONE:0)
Block(-5,5,8,STONE:0)
Block(-5,6,-7,STONE:0)
Block(-5,6,-6,STONE:0)
Block(-5,6,-5,STONE:0)
Block(-5,6,-4,STONE:0)
Block(-5,6,-3,STONE:0)
Block(-5,6,-2,STONE:0)
Block(-5,6,-1,STONE:0)
Block(-5,6,0,STONE:0)
Block(-5,6,1,STONE:0)
Block(-5,6,2,STONE:0)
Block(-5,6,3,STONE:0)
Block(-5,6,4,STONE:0)
Block(-5,6,5,STONE:0)
Block(-5,6,6,STONE:0)
Block(-5,6,7,STONE:0)
Block(-5,6,8,STONE:0)
Block(-5,7,-7,STONE:0)
Block(-5,7,-6,STONE:0)
Block(-5,7,-5,STONE:0)
Block(-5,7,-4,STONE:0)
Block(-5,7,-3,STONE:0)
Block(-5,7,-2,STONE:0)
Block(-5,7,-1,STONE:0)
Block(-5,7,0,STONE:0)
Block(-5,7,1,STONE:0)
Block(-5,7,2,STONE:0)
Block(-5,7,3,STONE:0)
Block(-5,7,4,STONE:0)
Block(-5,7,5,STONE:0)
Block(-5,7,6,STONE:0)
Block(-5,7,7,STONE:0)
Block(-5,7,8,STONE:0)
Block(-5,8,-7,STONE:0)
Block(-5,8,-6,STONE:0)
Block(-5,8,-5,STONE:0)
Block(-5,8,-4,STONE:0)
Block(-5,8,-3,STONE:0)
Block(-5,8,-2,STONE:0)
Block(-5,8,-1,STONE:0)
Block(-5,8,0,STONE:0)
Block(-5,8,1,STONE:0)
Block(-5,8,2,STONE:0)
Block(-5,8,3,STONE:0)
Block(-5,8,4,STONE:0)
Block(-5,8,5,STONE:0)
Block(-5,8,6,STONE:0)
Block(-5,8,7,STONE:0)
Block(-5,8,8,STONE:0)
Block(-5,9,-7,STONE:0)
Block(-5,9,-6,STONE:0)
Block(-5,9,-5,STONE:0)
Block(-5,9,-4,STONE:0)
Block(-5,9,-3,STONE:0)
Block(-5,9,-2,STONE:0)
Block(-5,9,-1,STONE:0)
Block(-5,9,0,STONE:0)
Block(-5,9,1,STONE:0)
Block(-5,9,2,STONE:0)
Block(-5,9,3,STONE:0)
Block(-5,9,4,STONE:0)
Block(-5,9,5,STONE:0)
Block(-5,9,6,STONE:0)
Block(-5,9,7,STONE:0)
Block(-5,9,8,STONE:0)
Block(-5,10,-7,STONE:0)
Block(-5,10,-6,STONE:0)
Block(-5,10,-5,STONE:0)
Block(-5,10,-4,STONE:0)
Block(-5,10,-3,STONE:0)
Block(-5,10,-2,STONE:0)
Block(-5,10,-1,STONE:0)
Block(-5,10,0,STONE:0)
Block(-5,10,1,STONE:0)
Block(-5,10,2,STONE:0)
Block(-5,10,3,STONE:0)
Block(-5,10,4,STONE:0)
Block(-5,10,5,STONE:0)
Block(-5,10,6,STONE:0)
Block(-5,10,7,STONE:0)
Block(-5,10,8,STONE:0)
Block(-5,11,-7,STONE:0)
Block(-5,11,-6,STONE:0)
Block(-5,11,-5,STONE:0)
Block(-5,11,-4,STONE:0)
Block(-5,11,-3,STONE:0)
Block(-5,11,-2,STONE:0)
Block(-5,11,-1,STONE:0)
Block(-5,11,0,STONE:0)
Block(-5,11,1,STONE:0)
Block(-5,11,2,STONE:0)
Block(-5,11,3,STONE:0)
Block(-5,11,4,STONE:0)
Block(-5,11,5,STONE:0)
Block(-5,11,6,STONE:0)
Block(-5,11,7,STONE:0)
Block(-5,11,8,STONE:0)
Block(-5,12,-7,STONE:0)
Block(-5,12,-6,STONE:0)
Block(-5,12,-5,STONE:0)
Block(-5,12,-4,STONE:0)
Block(-5,12,-3,STONE:0)
Block(-5,12,-2,STONE:0)
Block(-5,12,-1,STONE:0)
Block(-5,12,0,STONE:0)
Block(-5,12,1,STONE:0)
Block(-5,12,2,STONE:0)
Block(-5,12,3,STONE:0)
Block(-5,12,4,STONE:0)
Block(-5,12,5,STONE:0)
Block(-5,12,6,STONE:0)
Block(-5,12,7,STONE:0)
Block(-5,12,8,STONE:0)
Block(-5,13,-7,STONE:0)
Block(-5,13,-6,STONE:0)
Block(-5,13,-5,STONE:0)
Block(-5,13,-4,STONE:0)
Block(-5,13,-3,STONE:0)
Block(-5,13,-2,STONE:0)
Block(-5,13,-1,STONE:0)
Block(-5,13,0,STONE:0)
Block(-5,13,1,STONE:0)
Block(-5,13,2,STONE:0)
Block(-5,13,3,STONE:0)
Block(-5,13,4,STONE:0)
Block(-5,13,5,STONE:0)
Block(-5,13,6,STONE:0)
Block(-5,13,7,STONE:0)
Block(-5,13,8,STONE:0)
Block(-5,14,-7,STONE:0)
Block(-5,14,-6,STONE:0)
Block(-5,14,-5,STONE:0)
Block(-5,14,-4,STONE:0)
Block(-5,14,-3,STONE:0)
Block(-5,14,-2,STONE:0)
Block(-5,14,-1,STONE:0)
Block(-5,14,0,STONE:0)
Block(-5,14,1,STONE:0)
Block(-5,14,2,STONE:0)
Block(-5,14,3,STONE:0)
Block(-5,14,4,STONE:0)
Block(-5,14,5,STONE:0)
Block(-5,14,6,STONE:0)
Block(-5,14,7,STONE:0)
Block(-5,14,8,STONE:0)
Block(-5,15,-7,STONE:0)
Block(-5,15,-6,STONE:0)
Block(-5,15,-5,STONE:0)
Block(-5,15,-4,STONE:0)
Block(-5,15,-3,STONE:0)
Block(-5,15,-2,STONE:0)
Block(-5,15,-1,STONE:0)
Block(-5,15,0,STONE:0)
Block(-5,15,1,STONE:0)
Block(-5,15,2,STONE:0)
Block(-5,15,3,STONE:0)
Block(-5,15,4,STONE:0)
Block(-5,15,5,STONE:0)
Block(-5,15,6,STONE:0)
Block(-5,15,7,STONE:0)
Block(-5,15,8,STONE:0)
Block(-5,16,-7,STONE:0)
Block(-5,16,-6,STONE:0)
Block(-5,16,-5,STONE:0)
Block(-5,16,-4,STONE:0)
Block(-5,16,-3,STONE:0)
Block(-5,16,-2,STONE:0)
Block(-5,16,-1,STONE:0)
Block(-5,16,0,STONE:0)
Block(-5,16,1,STONE:0)
Block(-5,16,2,STONE:0)
Block(-5,16,3,STONE:0)
Block(-5,16,4,STONE:0)
Block(-5,16,5,STONE:0)
Block(-5,16,6,STONE:0)
Block(-5,16,7,STONE:0)
Block(-5,16,8,STONE:0)
Block(-5,17,-7,STONE:0)
Block(-5,17,-6,STONE:0)
Block(-5,17,-5,STONE:0)
Block(-5,17,-4,STONE:0)
Block(-5,17,-3,STONE:0)
Block(-5,17,-2,STONE:0)
Block(-5,17,-1,STONE:0)
Block(-5,17,0,STONE:0)
Block(-5,17,1,STONE:0)
Block(-5,17,2,STONE:0)
Block(-5,17,3,STONE:0)
Block(-5,17,4,STONE:0)
Block(-5,17,5,STONE:0)
Block(-5,17,6,STONE:0)
Block(-5,17,7,STONE:0)
Block(-5,17,8,STONE:0)
Block(-5,18,-7,STONE:0)
Block(-5,18,-6,REDSTONE_BLOCK:0)
Block(-5,18,-5,STONE:0)
Block(-5,18,-4,STONE:0)
Block(-5,18,-3,STONE:0)
Block(-5,18,-2,STONE:0)
Block(-5,18,-1,STONE:0)
Block(-5,18,0,STONE:0)
Block(-5,18,1,MAGMA:0)
Block(-5,18,2,MAGMA:0)
Block(-5,18,3,STONE:0)
Block(-5,18,4,STONE:0)
Block(-5,18,5,STONE:0)
Block(-5,18,6,STONE:0)
Block(-5,18,7,STONE:0)
Block(-5,18,8,STONE:0)
Block(-5,19,-7,MAGMA:0)
Block(-5,19,-6,PISTON_BASE:9)
Block(-5,19,-5,CONCRETE:7)
Block(-5,19,-4,CONCRETE:7)
Block(-5,19,-3,CONCRETE:7)
Block(-5,19,-2,CONCRETE:7)
Block(-5,19,-1,CONCRETE:7)
Block(-5,19,0,CONCRETE:7)
Block(-5,19,1,STAINED_GLASS:15)
Block(-5,19,2,STAINED_GLASS:15)
Block(-5,19,3,CONCRETE:7)
Block(-5,19,4,CONCRETE:7)
Block(-5,19,5,CONCRETE:7)
Block(-5,19,6,CONCRETE:7)
Block(-5,19,7,CONCRETE:7)
Block(-5,19,8,SMOOTH_BRICK:0)
Block(-5,20,-7,SMOOTH_BRICK:0)
Block(-5,20,-6,PISTON_MOVING_PIECE:1)
Block(-5,20,1,CARPET:14)
Block(-5,20,2,CARPET:14)
Entity(-5,20,3,vindication_illager,1)
Block(-5,21,-7,SMOOTH_BRICK:0)
Block(-5,21,-6,FLOWER_POT:0,../NBT/DaerocVillage/1530-flower_potC240R176.nbt)
Block(-5,22,-7,SMOOTH_BRICK:0)
Block(-5,23,-7,SMOOTH_BRICK:0)
Block(-5,24,-7,SMOOTH_BRICK:0)
Block(-5,25,-7,SMOOTH_BRICK:0)
Block(-5,25,-6,SMOOTH_BRICK:0)
Block(-5,25,-2,SMOOTH_BRICK:0)
Block(-5,25,-1,SMOOTH_BRICK:0)
Block(-5,25,4,SMOOTH_BRICK:0)
Block(-5,25,5,SMOOTH_BRICK:0)
Block(-5,26,-7,STONE:0)
Block(-5,26,-6,SMOOTH_BRICK:0)
Block(-5,26,-5,SMOOTH_BRICK:0)
Block(-5,26,-4,SMOOTH_BRICK:0)
Block(-5,26,-3,SMOOTH_BRICK:0)
Block(-5,26,-2,SMOOTH_BRICK:0)
Block(-5,26,-1,SMOOTH_BRICK:0)
Block(-5,26,0,SMOOTH_BRICK:0)
Block(-5,26,1,SMOOTH_BRICK:0)
Block(-5,26,2,SMOOTH_BRICK:0)
Block(-5,26,3,SMOOTH_BRICK:0)
Block(-5,26,4,SMOOTH_BRICK:0)
Block(-5,26,5,SMOOTH_BRICK:0)
Block(-5,26,6,SMOOTH_BRICK:0)
Block(-5,26,7,SMOOTH_BRICK:0)
Block(-5,26,8,SMOOTH_BRICK:0)
Block(-5,27,-7,STONE:0)
Block(-5,27,-6,STONE:0)
Block(-5,27,-5,STONE:0)
Block(-5,27,-4,STONE:0)
Block(-5,27,-3,STONE:0)
Block(-5,27,-2,STONE:0)
Block(-5,27,-1,STONE:0)
Block(-5,27,0,STONE:0)
Block(-5,27,1,STONE:0)
Block(-5,27,2,STONE:0)
Block(-5,27,3,STONE:0)
Block(-5,27,4,STONE:0)
Block(-5,27,5,STONE:0)
Block(-5,27,6,STONE:0)
Block(-5,27,7,STONE:0)
Block(-5,27,8,STONE:0)
Block(-5,28,-7,STONE:0)
Block(-5,28,-6,STONE:0)
Block(-5,28,-5,STONE:0)
Block(-5,28,-4,STONE:0)
Block(-5,28,-3,STONE:0)
Block(-5,28,-2,STONE:0)
Block(-5,28,-1,STONE:0)
Block(-5,28,0,STONE:0)
Block(-5,28,1,STONE:0)
Block(-5,28,2,STONE:0)
Block(-5,28,3,STONE:0)
Block(-5,28,4,STONE:0)
Block(-5,28,5,STONE:0)
Block(-5,28,6,STONE:0)
Block(-5,28,7,STONE:0)
Block(-5,28,8,STONE:0)
Block(-5,29,-7,STONE:0)
Block(-5,29,-6,STONE:0)
Block(-5,29,-5,STONE:0)
Block(-5,29,-4,STONE:0)
Block(-5,29,-3,STONE:0)
Block(-5,29,-2,STONE:0)
Block(-5,29,-1,STONE:0)
Block(-5,29,0,STONE:0)
Block(-5,29,1,STONE:0)
Block(-5,29,2,STONE:0)
Block(-5,29,3,STONE:0)
Block(-5,29,4,STONE:0)
Block(-5,29,5,STONE:0)
Block(-5,29,6,STONE:0)
Block(-5,29,7,STONE:0)
Block(-5,29,8,STONE:0)
Block(-5,30,-7,STONE:0)
Block(-5,30,-6,STONE:0)
Block(-5,30,-5,STONE:0)
Block(-5,30,-4,STONE:0)
Block(-5,30,-3,STONE:0)
Block(-5,30,-2,STONE:0)
Block(-5,30,-1,STONE:0)
Block(-5,30,0,STONE:0)
Block(-5,30,1,STONE:0)
Block(-5,30,2,STONE:0)
Block(-5,30,3,STONE:0)
Block(-5,30,4,STONE:0)
Block(-5,30,5,STONE:0)
Block(-5,30,6,STONE:0)
Block(-5,30,7,STONE:0)
Block(-5,30,8,STONE:0)
Block(-5,31,-7,STONE:0)
Block(-5,31,-6,STONE:0)
Block(-5,31,-5,STONE:0)
Block(-5,31,-4,STONE:0)
Block(-5,31,-3,STONE:0)
Block(-5,31,-2,STONE:0)
Block(-5,31,-1,STONE:0)
Block(-5,31,0,STONE:0)
Block(-5,31,1,STONE:0)
Block(-5,31,2,STONE:0)
Block(-5,31,3,STONE:0)
Block(-5,31,4,STONE:0)
Block(-5,31,5,STONE:0)
Block(-5,31,6,STONE:0)
Block(-5,31,7,STONE:0)
Block(-5,31,8,STONE:0)
Block(-5,32,-7,STONE:0)
Block(-5,32,-6,STONE:0)
Block(-5,32,-5,STONE:0)
Block(-5,32,-4,STONE:0)
Block(-5,32,-3,STONE:0)
Block(-5,32,-2,STONE:0)
Block(-5,32,-1,STONE:0)
Block(-5,32,0,STONE:0)
Block(-5,32,1,STONE:0)
Block(-5,32,2,STONE:0)
Block(-5,32,3,STONE:0)
Block(-5,32,4,STONE:0)
Block(-5,32,5,STONE:0)
Block(-5,32,6,STONE:0)
Block(-5,32,7,STONE:0)
Block(-5,32,8,STONE:0)
Block(-5,33,-7,STONE:0)
Block(-5,33,-6,STONE:0)
Block(-5,33,-5,STONE:0)
Block(-5,33,-4,STONE:0)
Block(-5,33,-3,STONE:0)
Block(-5,33,-2,STONE:0)
Block(-5,33,-1,STONE:0)
Block(-5,33,0,STONE:0)
Block(-5,33,1,STONE:0)
Block(-5,33,2,STONE:0)
Block(-5,33,3,STONE:0)
Block(-5,33,4,STONE:0)
Block(-5,33,5,STONE:0)
Block(-5,33,6,STONE:0)
Block(-5,33,7,STONE:0)
Block(-5,33,8,STONE:0)
Block(-5,34,-7,STONE:0)
Block(-5,34,-6,STONE:0)
Block(-5,34,-5,STONE:0)
Block(-5,34,-4,STONE:0)
Block(-5,34,-3,STONE:0)
Block(-5,34,-2,STONE:0)
Block(-5,34,-1,STONE:0)
Block(-5,34,0,STONE:0)
Block(-5,34,1,STONE:0)
Block(-5,34,2,STONE:0)
Block(-5,34,3,STONE:0)
Block(-5,34,4,STONE:0)
Block(-5,34,5,STONE:0)
Block(-5,34,6,STONE:0)
Block(-5,34,7,STONE:0)
Block(-5,34,8,STONE:0)
Block(-5,35,-7,STONE:0)
Block(-5,35,-6,STONE:0)
Block(-5,35,-5,STONE:0)
Block(-5,35,-4,STONE:0)
Block(-5,35,-3,STONE:0)
Block(-5,35,-2,STONE:0)
Block(-5,35,-1,STONE:0)
Block(-5,35,0,STONE:0)
Block(-5,35,1,STONE:0)
Block(-5,35,2,STONE:0)
Block(-5,35,3,STONE:0)
Block(-5,35,4,STONE:0)
Block(-5,35,5,STONE:0)
Block(-5,35,6,STONE:0)
Block(-5,35,7,STONE:0)
Block(-5,35,8,STONE:0)
Block(-5,36,-7,DIRT:0)
Block(-5,36,-6,DIRT:0)
Block(-5,36,-5,DIRT:0)
Block(-5,36,-4,DIRT:0)
Block(-5,36,-3,DIRT:0)
Block(-5,36,-2,DIRT:0)
Block(-5,36,-1,DIRT:0)
Block(-5,36,0,DIRT:0)
Block(-5,36,1,DIRT:0)
Block(-5,36,2,DIRT:0)
Block(-5,36,3,DIRT:0)
Block(-5,36,4,DIRT:0)
Block(-5,36,5,DIRT:0)
Block(-5,36,6,DIRT:0)
Block(-5,36,7,DIRT:0)
Block(-5,36,8,DIRT:1)
Block(-5,37,-7,DIRT:0)
Block(-5,37,-6,GRAVEL:0)
Block(-5,37,-5,DIRT:0)
Block(-5,37,-4,DIRT:0)
Block(-5,37,-3,DIRT:0)
Block(-5,37,-2,DIRT:0)
Block(-5,37,-1,DIRT:0)
Block(-5,37,0,DIRT:0)
Block(-5,37,1,DIRT:0)
Block(-5,37,2,DIRT:0)
Block(-5,37,3,DIRT:0)
Block(-5,37,4,DIRT:0)
Block(-5,37,5,DIRT:0)
Block(-5,37,6,DIRT:0)
Block(-5,37,7,DIRT:0)
Block(-5,37,8,DIRT:1)
Block(-5,38,-7,DIRT:0)
Block(-5,38,-6,GRASS:0)
Block(-5,38,-5,GRASS:0)
Block(-5,38,-4,GRASS:0)
Block(-5,38,-3,GRASS:0)
Block(-5,38,-2,DIRT:0)
Block(-5,38,-1,DIRT:0)
Block(-5,38,0,GRASS:0)
Block(-5,38,1,GRASS:0)
Block(-5,38,2,DIRT:0)
Block(-5,38,3,GRASS:0)
Block(-5,38,4,GRASS:0)
Block(-5,38,5,GRAVEL:0)
Block(-5,38,6,GRASS:0)
Block(-5,38,7,GRASS:0)
Block(-5,38,8,GRASS:0)
Block(-5,39,-7,WOOD:1)
RandomBlock(-5,39,-6,AIR:0,20,CHEST:4,../../../Chests/Loot/JunkChest_1.nbt,10,CHEST:4,../../../Chests/Loot/JunkChest_2.nbt,10,CHEST:4,../../../Chests/Loot/JunkChest_3.nbt,10,CHEST:4,../../../Chests/Loot/JunkChest_4.nbt,10,CHEST:4,../../../Chests/Loot/JunkChest_5.nbt,10,CHEST:4,../../../Chests/Lore/village_1.nbt,1,CHEST:4,../../../Chests/Lore/village_2.nbt,1,CHEST:4,../../../Chests/Lore/village_3.nbt,1,CHEST:4,../../../Chests/Lore/village_4.nbt,1,CHEST:4,../../../Chests/Lore/village_5.nbt,1,CHEST:4,../../../Chests/Loot/Common1.nbt,10,CHEST:4,../../../Chests/Loot/Common2.nbt,10,CHEST:4,../../../Chests/Loot/Common3.nbt,10,CHEST:4,../../../Chests/Loot/Common4.nbt,10,CHEST:4,../../../Chests/Loot/Common5.nbt,10,CHEST:4,../../../Chests/Loot/Common6.nbt,10,CHEST:4,../../../Chests/Loot/Common7.nbt,10,CHEST:4,../../../Chests/Loot/Common8.nbt,10,CHEST:4,../../../Chests/Loot/Common9.nbt,10,CHEST:4,../../../Chests/Loot/Common10.nbt,10,CHEST:4,../../../Chests/Loot/Common10.nbt,11,CHEST:4,../../../Chests/Loot/Common12.nbt,10,CHEST:4,../../../Chests/Loot/Common13.nbt,10,CHEST:4,../../../Chests/Loot/Common14.nbt,10,CHEST:4,../../../Chests/Loot/Common15.nbt,10,CHEST:4,../../../Chests/Lore/village_1.nbt,2,CHEST:4,../../../Chests/Lore/village_3.nbt,2,CHEST:4,../../../Chests/Lore/village_4.nbt,2,CHEST:4,../../../Chests/Lore/village_5.nbt,2,CHEST:4,../../../Chests/Lore/village_5.nbt,2,CHEST:4,../../../Chests/Loot/Rare1.nbt,5,CHEST:4,../../../Chests/Loot/Rare2.nbt,5,CHEST:4,../../../Chests/Loot/Rare3.nbt,5,CHEST:4,../../../Chests/Loot/Rare4.nbt,5,CHEST:4,../../../Chests/Loot/Rare5.nbt,5,CHEST:4,../../../Chests/Loot/Rare6.nbt,5,CHEST:4,../../../Chests/Loot/Rare7.nbt,5,CHEST:4,../../../Chests/Loot/Rare8.nbt,5,CHEST:4,../../../Chests/Loot/Rare9.nbt,5,CHEST:4,../../../Chests/Loot/Rare10.nbt,5,CHEST:4,../../../Chests/Loot/Rare11.nbt,5,CHEST:4,../../../Chests/Loot/Rare12.nbt,5,CHEST:4,../../../Chests/Loot/Rare13.nbt,5,CHEST:4,../../../Chests/Loot/Rare14.nbt,5,CHEST:4,../../../Chests/Loot/Rare15.nbt,5,CHEST:4,../../../Chests/Loot/Epic1.nbt,2,CHEST:4,../../../Chests/Loot/Epic2.nbt,2,CHEST:4,../../../Chests/Loot/Epic3.nbt,2,CHEST:4,../../../Chests/Loot/Epic4.nbt,2,CHEST:4,../../../Chests/Loot/Epic5.nbt,2,CHEST:4,../../../Chests/Loot/Epic6.nbt,2,CHEST:4,../../../Chests/Loot/Epic7.nbt,2,CHEST:4,../../../Chests/Loot/Epic8.nbt,2,CHEST:4,../../../Chests/Loot/Epic9.nbt,2,CHEST:4,../../../Chests/Loot/Epic10.nbt,2,CHEST:4,../../../Chests/Loot/Epic11.nbt,2,CHEST:4,../../../Chests/Loot/Epic12.nbt,2,CHEST:4,../../../Chests/Loot/Epic13.nbt,2,CHEST:4,../../../Chests/Loot/Epic14.nbt,2,CHEST:4,../../../Chests/Loot/Epic15.nbt,5,CHEST:4,../../../Chests/Loot/Rare1.nbt,5,CHEST:4,../../../Chests/Loot/Rare2.nbt,5,CHEST:4,../../../Chests/Loot/Rare3.nbt,5,CHEST:4,../../../Chests/Loot/Rare4.nbt,5,CHEST:4,../../../Chests/Loot/Rare5.nbt,10,CHEST:4,../../../Chests/Loot/Rare6.nbt,10,CHEST:4,../../../Chests/Loot/Rare7.nbt,10,CHEST:4,../../../Chests/Loot/Rare8.nbt,10,CHEST:4,../../../Chests/Loot/Rare9.nbt,10,CHEST:4,../../../Chests/Loot/Rare10.nbt,15,CHEST:4,../../../Chests/Loot/Rare11.nbt,15,CHEST:4,../../../Chests/Loot/Rare12.nbt,15,CHEST:4,../../../Chests/Loot/Rare13.nbt,15,CHEST:4,../../../Chests/Loot/Rare14.nbt,15,CHEST:4,../../../Chests/Loot/Rare15.nbt,15,CHEST:4,../../../Chests/Loot/Epic15.nbt,100)
RandomBlock(-5,39,-5,AIR:0,20,CHEST:4,../../../Chests/Loot/JunkChest_1.nbt,10,CHEST:4,../../../Chests/Loot/JunkChest_2.nbt,10,CHEST:4,../../../Chests/Loot/JunkChest_3.nbt,10,CHEST:4,../../../Chests/Loot/JunkChest_4.nbt,10,CHEST:4,../../../Chests/Loot/JunkChest_5.nbt,10,CHEST:4,../../../Chests/Lore/village_1.nbt,1,CHEST:4,../../../Chests/Lore/village_2.nbt,1,CHEST:4,../../../Chests/Lore/village_3.nbt,1,CHEST:4,../../../Chests/Lore/village_4.nbt,1,CHEST:4,../../../Chests/Lore/village_5.nbt,1,CHEST:4,../../../Chests/Loot/Common1.nbt,10,CHEST:4,../../../Chests/Loot/Common2.nbt,10,CHEST:4,../../../Chests/Loot/Common3.nbt,10,CHEST:4,../../../Chests/Loot/Common4.nbt,10,CHEST:4,../../../Chests/Loot/Common5.nbt,10,CHEST:4,../../../Chests/Loot/Common6.nbt,10,CHEST:4,../../../Chests/Loot/Common7.nbt,10,CHEST:4,../../../Chests/Loot/Common8.nbt,10,CHEST:4,../../../Chests/Loot/Common9.nbt,10,CHEST:4,../../../Chests/Loot/Common10.nbt,10,CHEST:4,../../../Chests/Loot/Common10.nbt,11,CHEST:4,../../../Chests/Loot/Common12.nbt,10,CHEST:4,../../../Chests/Loot/Common13.nbt,10,CHEST:4,../../../Chests/Loot/Common14.nbt,10,CHEST:4,../../../Chests/Loot/Common15.nbt,10,CHEST:4,../../../Chests/Lore/village_1.nbt,2,CHEST:4,../../../Chests/Lore/village_3.nbt,2,CHEST:4,../../../Chests/Lore/village_4.nbt,2,CHEST:4,../../../Chests/Lore/village_5.nbt,2,CHEST:4,../../../Chests/Lore/village_5.nbt,2,CHEST:4,../../../Chests/Loot/Rare1.nbt,5,CHEST:4,../../../Chests/Loot/Rare2.nbt,5,CHEST:4,../../../Chests/Loot/Rare3.nbt,5,CHEST:4,../../../Chests/Loot/Rare4.nbt,5,CHEST:4,../../../Chests/Loot/Rare5.nbt,5,CHEST:4,../../../Chests/Loot/Rare6.nbt,5,CHEST:4,../../../Chests/Loot/Rare7.nbt,5,CHEST:4,../../../Chests/Loot/Rare8.nbt,5,CHEST:4,../../../Chests/Loot/Rare9.nbt,5,CHEST:4,../../../Chests/Loot/Rare10.nbt,5,CHEST:4,../../../Chests/Loot/Rare11.nbt,5,CHEST:4,../../../Chests/Loot/Rare12.nbt,5,CHEST:4,../../../Chests/Loot/Rare13.nbt,5,CHEST:4,../../../Chests/Loot/Rare14.nbt,5,CHEST:4,../../../Chests/Loot/Rare15.nbt,5,CHEST:4,../../../Chests/Loot/Epic1.nbt,2,CHEST:4,../../../Chests/Loot/Epic2.nbt,2,CHEST:4,../../../Chests/Loot/Epic3.nbt,2,CHEST:4,../../../Chests/Loot/Epic4.nbt,2,CHEST:4,../../../Chests/Loot/Epic5.nbt,2,CHEST:4,../../../Chests/Loot/Epic6.nbt,2,CHEST:4,../../../Chests/Loot/Epic7.nbt,2,CHEST:4,../../../Chests/Loot/Epic8.nbt,2,CHEST:4,../../../Chests/Loot/Epic9.nbt,2,CHEST:4,../../../Chests/Loot/Epic10.nbt,2,CHEST:4,../../../Chests/Loot/Epic11.nbt,2,CHEST:4,../../../Chests/Loot/Epic12.nbt,2,CHEST:4,../../../Chests/Loot/Epic13.nbt,2,CHEST:4,../../../Chests/Loot/Epic14.nbt,2,CHEST:4,../../../Chests/Loot/Epic15.nbt,5,CHEST:4,../../../Chests/Loot/Rare1.nbt,5,CHEST:4,../../../Chests/Loot/Rare2.nbt,5,CHEST:4,../../../Chests/Loot/Rare3.nbt,5,CHEST:4,../../../Chests/Loot/Rare4.nbt,5,CHEST:4,../../../Chests/Loot/Rare5.nbt,10,CHEST:4,../../../Chests/Loot/Rare6.nbt,10,CHEST:4,../../../Chests/Loot/Rare7.nbt,10,CHEST:4,../../../Chests/Loot/Rare8.nbt,10,CHEST:4,../../../Chests/Loot/Rare9.nbt,10,CHEST:4,../../../Chests/Loot/Rare10.nbt,15,CHEST:4,../../../Chests/Loot/Rare11.nbt,15,CHEST:4,../../../Chests/Loot/Rare12.nbt,15,CHEST:4,../../../Chests/Loot/Rare13.nbt,15,CHEST:4,../../../Chests/Loot/Rare14.nbt,15,CHEST:4,../../../Chests/Loot/Rare15.nbt,15,CHEST:4,../../../Chests/Loot/Epic15.nbt,100)
Block(-5,39,-3,LONG_GRASS:1)
Block(-5,39,-2,HAY_BLOCK:0)
Block(-5,39,-1,WOOD:1)
Block(-5,39,1,LONG_GRASS:1)
Block(-5,39,2,MELON_BLOCK:0)
Block(-5,39,3,LONG_GRASS:1)
Block(-5,39,4,LONG_GRASS:1)
Block(-5,39,6,COBBLE_WALL:0)
Block(-5,39,7,LONG_GRASS:1)
Block(-5,39,8,LONG_GRASS:1)
Block(-5,40,-7,FLOWER_POT:0,../NBT/DaerocVillage/1538-flower_potC240R176.nbt)
Block(-5,40,-1,CARPET:6)
Block(-5,40,6,DARK_OAK_FENCE:0)
Block(-5,41,6,DARK_OAK_FENCE:0)
Block(-5,42,-7,WOOD:1)
Block(-5,42,-6,WOOL:1)
Block(-5,42,-5,WOOL:12)
Block(-5,42,-4,WOOL:1)
Block(-5,42,-3,WOOL:12)
Block(-5,42,-2,WOOL:1)
Block(-5,42,-1,WOOD:1)
Block(-5,42,5,LEAVES:4)
Block(-5,42,6,DARK_OAK_FENCE:0)
Block(-5,43,-6,WOOD_STEP:1)
Block(-5,43,-5,WOOD_STEP:1)
Block(-5,43,-4,WOOD_STEP:1)
Block(-5,43,-3,WOOD_STEP:1)
Block(-5,43,-2,WOOD_STEP:1)
Block(-5,43,5,LEAVES:4)
Block(-5,43,6,SPRUCE_WOOD_STAIRS:0)
Block(-5,43,7,LEAVES:0)
Block(-5,44,3,LEAVES:0)
Block(-5,44,5,LEAVES:0)
Block(-5,44,6,LEAVES:0)
Block(-5,44,7,LEAVES:0)
Block(-5,45,2,LEAVES:0)
Block(-5,45,5,LEAVES:0)
Block(-5,45,7,LEAVES:0)
Block(-5,46,2,LEAVES:0)
Block(-5,46,3,LEAVES:0)
Block(-5,46,4,LEAVES:0)
Block(-5,46,5,LEAVES:0)
Block(-5,46,8,LEAVES:0)
Block(-5,47,1,LEAVES:0)
Block(-5,47,2,LEAVES:0)
Block(-5,47,3,LEAVES:0)
Block(-5,47,4,LOG_2:13)
Block(-5,47,6,LEAVES:0)
Block(-5,47,7,LEAVES:0)
Block(-5,47,8,LEAVES:0)
Block(-5,48,1,LEAVES:0)
Block(-5,48,2,LEAVES:0)
Block(-5,48,3,LOG_2:13)
Block(-5,48,4,LEAVES:0)
Block(-5,48,5,LEAVES:0)
Block(-5,48,7,LEAVES:0)
Block(-5,48,8,LEAVES:0)
Block(-5,49,1,LEAVES:0)
Block(-5,49,2,LEAVES:0)
Block(-5,49,4,LEAVES:0)
Block(-5,49,5,LEAVES:0)
Block(-5,50,3,LEAVES:0)
Block(-4,0,-7,STONE:0)
Block(-4,0,-6,STONE:0)
Block(-4,0,-5,STONE:0)
Block(-4,0,-4,STONE:0)
Block(-4,0,-3,STONE:0)
Block(-4,0,-2,STONE:0)
Block(-4,0,-1,STONE:0)
Block(-4,0,0,STONE:0)
Block(-4,0,1,STONE:0)
Block(-4,0,2,STONE:0)
Block(-4,0,3,STONE:0)
Block(-4,0,4,STONE:0)
Block(-4,0,5,STONE:0)
Block(-4,0,6,STONE:0)
Block(-4,0,7,STONE:0)
Block(-4,0,8,STONE:0)
Block(-4,1,-7,STONE:0)
Block(-4,1,-6,STONE:0)
Block(-4,1,-5,STONE:0)
Block(-4,1,-4,STONE:0)
Block(-4,1,-3,STONE:0)
Block(-4,1,-2,STONE:0)
Block(-4,1,-1,STONE:0)
Block(-4,1,0,STONE:0)
Block(-4,1,1,STONE:0)
Block(-4,1,2,STONE:0)
Block(-4,1,3,STONE:0)
Block(-4,1,4,STONE:0)
Block(-4,1,5,STONE:0)
Block(-4,1,6,STONE:0)
Block(-4,1,7,STONE:0)
Block(-4,1,8,STONE:0)
Block(-4,2,-7,STONE:0)
Block(-4,2,-6,STONE:0)
Block(-4,2,-5,STONE:0)
Block(-4,2,-4,STONE:0)
Block(-4,2,-3,STONE:0)
Block(-4,2,-2,STONE:0)
Block(-4,2,-1,STONE:0)
Block(-4,2,0,STONE:0)
Block(-4,2,1,STONE:0)
Block(-4,2,2,STONE:0)
Block(-4,2,3,STONE:0)
Block(-4,2,4,STONE:0)
Block(-4,2,5,STONE:0)
Block(-4,2,6,STONE:0)
Block(-4,2,7,STONE:0)
Block(-4,2,8,STONE:0)
Block(-4,3,-7,STONE:0)
Block(-4,3,-6,STONE:0)
Block(-4,3,-5,STONE:0)
Block(-4,3,-4,STONE:0)
Block(-4,3,-3,STONE:0)
Block(-4,3,-2,STONE:0)
Block(-4,3,-1,STONE:0)
Block(-4,3,0,STONE:0)
Block(-4,3,1,STONE:0)
Block(-4,3,2,STONE:0)
Block(-4,3,3,STONE:0)
Block(-4,3,4,STONE:0)
Block(-4,3,5,STONE:0)
Block(-4,3,6,STONE:0)
Block(-4,3,7,STONE:0)
Block(-4,3,8,STONE:0)
Block(-4,4,-7,STONE:0)
Block(-4,4,-6,STONE:0)
Block(-4,4,-5,STONE:0)
Block(-4,4,-4,STONE:0)
Block(-4,4,-3,STONE:0)
Block(-4,4,-2,STONE:0)
Block(-4,4,-1,STONE:0)
Block(-4,4,0,STONE:0)
Block(-4,4,1,STONE:0)
Block(-4,4,2,STONE:0)
Block(-4,4,3,STONE:0)
Block(-4,4,4,STONE:0)
Block(-4,4,5,STONE:0)
Block(-4,4,6,STONE:0)
Block(-4,4,7,STONE:0)
Block(-4,4,8,STONE:0)
Block(-4,5,-7,STONE:0)
Block(-4,5,-6,STONE:0)
Block(-4,5,-5,STONE:0)
Block(-4,5,-4,STONE:0)
Block(-4,5,-3,STONE:0)
Block(-4,5,-2,STONE:0)
Block(-4,5,-1,STONE:0)
Block(-4,5,0,STONE:0)
Block(-4,5,1,STONE:0)
Block(-4,5,2,STONE:0)
Block(-4,5,3,STONE:0)
Block(-4,5,4,STONE:0)
Block(-4,5,5,STONE:0)
Block(-4,5,6,STONE:0)
Block(-4,5,7,STONE:0)
Block(-4,5,8,STONE:0)
Block(-4,6,-7,STONE:0)
Block(-4,6,-6,STONE:0)
Block(-4,6,-5,STONE:0)
Block(-4,6,-4,STONE:0)
Block(-4,6,-3,STONE:0)
Block(-4,6,-2,STONE:0)
Block(-4,6,-1,STONE:0)
Block(-4,6,0,STONE:0)
Block(-4,6,1,STONE:0)
Block(-4,6,2,STONE:0)
Block(-4,6,3,STONE:0)
Block(-4,6,4,STONE:0)
Block(-4,6,5,STONE:0)
Block(-4,6,6,STONE:0)
Block(-4,6,7,STONE:0)
Block(-4,6,8,STONE:0)
Block(-4,7,-7,STONE:0)
Block(-4,7,-6,STONE:0)
Block(-4,7,-5,STONE:0)
Block(-4,7,-4,STONE:0)
Block(-4,7,-3,STONE:0)
Block(-4,7,-2,STONE:0)
Block(-4,7,-1,STONE:0)
Block(-4,7,0,STONE:0)
Block(-4,7,1,STONE:0)
Block(-4,7,2,STONE:0)
Block(-4,7,3,STONE:0)
Block(-4,7,4,STONE:0)
Block(-4,7,5,STONE:0)
Block(-4,7,6,STONE:0)
Block(-4,7,7,STONE:0)
Block(-4,7,8,STONE:0)
Block(-4,8,-7,STONE:0)
Block(-4,8,-6,STONE:0)
Block(-4,8,-5,STONE:0)
Block(-4,8,-4,STONE:0)
Block(-4,8,-3,STONE:0)
Block(-4,8,-2,STONE:0)
Block(-4,8,-1,STONE:0)
Block(-4,8,0,STONE:0)
Block(-4,8,1,STONE:0)
Block(-4,8,2,STONE:0)
Block(-4,8,3,STONE:0)
Block(-4,8,4,STONE:0)
Block(-4,8,5,STONE:0)
Block(-4,8,6,STONE:0)
Block(-4,8,7,STONE:0)
Block(-4,8,8,STONE:0)
Block(-4,9,-7,STONE:0)
Block(-4,9,-6,STONE:0)
Block(-4,9,-5,STONE:0)
Block(-4,9,-4,STONE:0)
Block(-4,9,-3,STONE:0)
Block(-4,9,-2,STONE:0)
Block(-4,9,-1,STONE:0)
Block(-4,9,0,STONE:0)
Block(-4,9,1,STONE:0)
Block(-4,9,2,STONE:0)
Block(-4,9,3,STONE:0)
Block(-4,9,4,STONE:0)
Block(-4,9,5,STONE:0)
Block(-4,9,6,STONE:0)
Block(-4,9,7,STONE:0)
Block(-4,9,8,STONE:0)
Block(-4,10,-7,STONE:0)
Block(-4,10,-6,STONE:0)
Block(-4,10,-5,STONE:0)
Block(-4,10,-4,STONE:0)
Block(-4,10,-3,STONE:0)
Block(-4,10,-2,STONE:0)
Block(-4,10,-1,STONE:0)
Block(-4,10,0,STONE:0)
Block(-4,10,1,STONE:0)
Block(-4,10,2,STONE:0)
Block(-4,10,3,STONE:0)
Block(-4,10,4,STONE:0)
Block(-4,10,5,STONE:0)
Block(-4,10,6,STONE:0)
Block(-4,10,7,STONE:0)
Block(-4,10,8,STONE:0)
Block(-4,11,-7,STONE:0)
Block(-4,11,-6,STONE:0)
Block(-4,11,-5,STONE:0)
Block(-4,11,-4,STONE:0)
Block(-4,11,-3,STONE:0)
Block(-4,11,-2,STONE:0)
Block(-4,11,-1,STONE:0)
Block(-4,11,0,STONE:0)
Block(-4,11,1,STONE:0)
Block(-4,11,2,STONE:0)
Block(-4,11,3,STONE:0)
Block(-4,11,4,STONE:0)
Block(-4,11,5,STONE:0)
Block(-4,11,6,STONE:0)
Block(-4,11,7,STONE:0)
Block(-4,11,8,STONE:0)
Block(-4,12,-7,STONE:0)
Block(-4,12,-6,STONE:0)
Block(-4,12,-5,STONE:0)
Block(-4,12,-4,STONE:0)
Block(-4,12,-3,STONE:0)
Block(-4,12,-2,STONE:0)
Block(-4,12,-1,STONE:0)
Block(-4,12,0,STONE:0)
Block(-4,12,1,STONE:0)
Block(-4,12,2,STONE:0)
Block(-4,12,3,STONE:0)
Block(-4,12,4,STONE:0)
Block(-4,12,5,STONE:0)
Block(-4,12,6,STONE:0)
Block(-4,12,7,STONE:0)
Block(-4,12,8,STONE:0)
Block(-4,13,-7,STONE:0)
Block(-4,13,-6,STONE:0)
Block(-4,13,-5,STONE:0)
Block(-4,13,-4,STONE:0)
Block(-4,13,-3,STONE:0)
Block(-4,13,-2,STONE:0)
Block(-4,13,-1,STONE:0)
Block(-4,13,0,STONE:0)
Block(-4,13,1,STONE:0)
Block(-4,13,2,STONE:0)
Block(-4,13,3,STONE:0)
Block(-4,13,4,STONE:0)
Block(-4,13,5,STONE:0)
Block(-4,13,6,STONE:0)
Block(-4,13,7,STONE:0)
Block(-4,13,8,STONE:0)
Block(-4,14,-7,STONE:0)
Block(-4,14,-6,STONE:0)
Block(-4,14,-5,STONE:0)
Block(-4,14,-4,STONE:0)
Block(-4,14,-3,STONE:0)
Block(-4,14,-2,STONE:0)
Block(-4,14,-1,STONE:0)
Block(-4,14,0,STONE:0)
Block(-4,14,1,STONE:0)
Block(-4,14,2,STONE:0)
Block(-4,14,3,STONE:0)
Block(-4,14,4,STONE:0)
Block(-4,14,5,STONE:0)
Block(-4,14,6,STONE:0)
Block(-4,14,7,STONE:0)
Block(-4,14,8,STONE:0)
Block(-4,15,-7,STONE:0)
Block(-4,15,-6,STONE:0)
Block(-4,15,-5,STONE:0)
Block(-4,15,-4,STONE:0)
Block(-4,15,-3,STONE:0)
Block(-4,15,-2,STONE:0)
Block(-4,15,-1,STONE:0)
Block(-4,15,0,STONE:0)
Block(-4,15,1,STONE:0)
Block(-4,15,2,STONE:0)
Block(-4,15,3,STONE:0)
Block(-4,15,4,STONE:0)
Block(-4,15,5,STONE:0)
Block(-4,15,6,STONE:0)
Block(-4,15,7,STONE:0)
Block(-4,15,8,STONE:0)
Block(-4,16,-7,STONE:0)
Block(-4,16,-6,STONE:0)
Block(-4,16,-5,STONE:0)
Block(-4,16,-4,STONE:0)
Block(-4,16,-3,STONE:0)
Block(-4,16,-2,STONE:0)
Block(-4,16,-1,STONE:0)
Block(-4,16,0,STONE:0)
Block(-4,16,1,STONE:0)
Block(-4,16,2,STONE:0)
Block(-4,16,3,STONE:0)
Block(-4,16,4,STONE:0)
Block(-4,16,5,STONE:0)
Block(-4,16,6,STONE:0)
Block(-4,16,7,STONE:0)
Block(-4,16,8,STONE:0)
Block(-4,17,-7,STONE:0)
Block(-4,17,-6,STONE:0)
Block(-4,17,-5,STONE:0)
Block(-4,17,-4,STONE:0)
Block(-4,17,-3,STONE:0)
Block(-4,17,-2,STONE:0)
Block(-4,17,-1,STONE:0)
Block(-4,17,0,STONE:0)
Block(-4,17,1,STONE:0)
Block(-4,17,2,STONE:0)
Block(-4,17,3,STONE:0)
Block(-4,17,4,STONE:0)
Block(-4,17,5,STONE:0)
Block(-4,17,6,STONE:0)
Block(-4,17,7,STONE:0)
Block(-4,17,8,STONE:0)
Block(-4,18,-7,STONE:0)
Block(-4,18,-6,REDSTONE_BLOCK:0)
Block(-4,18,-5,STONE:0)
Block(-4,18,-4,STONE:0)
Block(-4,18,-3,MAGMA:0)
Block(-4,18,-2,MAGMA:0)
Block(-4,18,-1,MAGMA:0)
Block(-4,18,0,MAGMA:0)
Block(-4,18,1,MAGMA:0)
Block(-4,18,2,MAGMA:0)
Block(-4,18,3,gray_glazed_terracotta:0)
Block(-4,18,4,gray_glazed_terracotta:0)
Block(-4,18,5,gray_glazed_terracotta:0)
Block(-4,18,6,gray_glazed_terracotta:0)
Block(-4,18,7,STONE:0)
Block(-4,18,8,STONE:0)
Block(-4,19,-7,MAGMA:0)
Block(-4,19,-6,PISTON_BASE:9)
Block(-4,19,-5,CONCRETE:7)
Block(-4,19,-4,CONCRETE:7)
Block(-4,19,-3,gray_glazed_terracotta)
Block(-4,19,-2,gray_glazed_terracotta:1)
Block(-4,19,-1,gray_glazed_terracotta)
Block(-4,19,0,gray_glazed_terracotta)
Block(-4,19,1,STAINED_GLASS:15)
Block(-4,19,2,STAINED_GLASS:15)
Block(-4,19,3,gray_glazed_terracotta:1)
Block(-4,19,4,gray_glazed_terracotta:0)
Block(-4,19,5,gray_glazed_terracotta:0)
Block(-4,19,6,gray_glazed_terracotta:0)
Block(-4,19,7,CONCRETE:7)
Block(-4,19,8,CONCRETE:7)
Block(-4,20,-7,SMOOTH_BRICK:0)
Block(-4,20,-6,PISTON_MOVING_PIECE:1)
Block(-4,20,-3,DARK_OAK_FENCE:0)
Block(-4,20,-2,DARK_OAK_FENCE:0)
Block(-4,20,-1,DARK_OAK_FENCE:0)
Block(-4,20,0,DARK_OAK_FENCE:0)
Block(-4,20,1,CARPET:14)
Block(-4,20,2,CARPET:14)
Block(-4,20,3,DARK_OAK_FENCE:0)
Block(-4,20,4,DARK_OAK_FENCE:0)
Block(-4,20,5,DARK_OAK_FENCE:0)
Block(-4,20,6,DARK_OAK_FENCE:0)
Block(-4,21,-7,SMOOTH_BRICK:0)
Block(-4,22,-7,SMOOTH_BRICK:0)
Block(-4,23,-7,SMOOTH_BRICK:0)
Block(-4,24,-7,SMOOTH_BRICK:0)
Block(-4,24,-6,SMOOTH_STAIRS:4)
Block(-4,24,-2,SMOOTH_STAIRS:4)
Block(-4,24,-1,SMOOTH_STAIRS:4)
Block(-4,24,4,SMOOTH_STAIRS:4)
Block(-4,24,5,SMOOTH_STAIRS:4)
Block(-4,25,-7,SMOOTH_BRICK:0)
Block(-4,25,-6,SMOOTH_BRICK:0)
Block(-4,25,-2,SMOOTH_BRICK:0)
Block(-4,25,-1,SMOOTH_BRICK:0)
Block(-4,25,4,SMOOTH_BRICK:0)
Block(-4,25,5,SMOOTH_BRICK:0)
Block(-4,26,-7,STONE:0)
Block(-4,26,-6,SMOOTH_BRICK:0)
Block(-4,26,-5,SMOOTH_BRICK:0)
Block(-4,26,-4,SMOOTH_BRICK:0)
Block(-4,26,-3,SMOOTH_BRICK:0)
Block(-4,26,-2,SMOOTH_BRICK:0)
Block(-4,26,-1,SMOOTH_BRICK:0)
Block(-4,26,0,SMOOTH_BRICK:0)
Block(-4,26,1,SMOOTH_BRICK:0)
Block(-4,26,2,SMOOTH_BRICK:0)
Block(-4,26,3,SMOOTH_BRICK:0)
Block(-4,26,4,SMOOTH_BRICK:0)
Block(-4,26,5,SMOOTH_BRICK:0)
Block(-4,26,6,SMOOTH_BRICK:0)
Block(-4,26,7,SMOOTH_BRICK:0)
Block(-4,26,8,SMOOTH_BRICK:0)
Block(-4,27,-7,STONE:0)
Block(-4,27,-6,STONE:0)
Block(-4,27,-5,STONE:0)
Block(-4,27,-4,STONE:0)
Block(-4,27,-3,STONE:0)
Block(-4,27,-2,STONE:0)
Block(-4,27,-1,STONE:0)
Block(-4,27,0,STONE:0)
Block(-4,27,1,STONE:0)
Block(-4,27,2,STONE:0)
Block(-4,27,3,STONE:0)
Block(-4,27,4,STONE:0)
Block(-4,27,5,STONE:0)
Block(-4,27,6,STONE:0)
Block(-4,27,7,STONE:0)
Block(-4,27,8,STONE:0)
Block(-4,28,-7,STONE:0)
Block(-4,28,-6,STONE:0)
Block(-4,28,-5,STONE:0)
Block(-4,28,-4,STONE:0)
Block(-4,28,-3,STONE:0)
Block(-4,28,-2,STONE:0)
Block(-4,28,-1,STONE:0)
Block(-4,28,0,STONE:0)
Block(-4,28,1,STONE:0)
Block(-4,28,2,STONE:0)
Block(-4,28,3,STONE:0)
Block(-4,28,4,STONE:0)
Block(-4,28,5,STONE:0)
Block(-4,28,6,STONE:0)
Block(-4,28,7,STONE:0)
Block(-4,28,8,STONE:0)
Block(-4,29,-7,STONE:0)
Block(-4,29,-6,STONE:0)
Block(-4,29,-5,STONE:0)
Block(-4,29,-4,STONE:0)
Block(-4,29,-3,STONE:0)
Block(-4,29,-2,STONE:0)
Block(-4,29,-1,STONE:0)
Block(-4,29,0,STONE:0)
Block(-4,29,1,STONE:0)
Block(-4,29,2,STONE:0)
Block(-4,29,3,STONE:0)
Block(-4,29,4,STONE:0)
Block(-4,29,5,STONE:0)
Block(-4,29,6,STONE:0)
Block(-4,29,7,STONE:0)
Block(-4,29,8,STONE:0)
Block(-4,30,-7,STONE:0)
Block(-4,30,-6,STONE:0)
Block(-4,30,-5,STONE:0)
Block(-4,30,-4,STONE:0)
Block(-4,30,-3,STONE:0)
Block(-4,30,-2,STONE:0)
Block(-4,30,-1,STONE:0)
Block(-4,30,0,STONE:0)
Block(-4,30,1,STONE:0)
Block(-4,30,2,STONE:0)
Block(-4,30,3,STONE:0)
Block(-4,30,4,STONE:0)
Block(-4,30,5,STONE:0)
Block(-4,30,6,STONE:0)
Block(-4,30,7,STONE:0)
Block(-4,30,8,STONE:0)
Block(-4,31,-7,STONE:0)
Block(-4,31,-6,STONE:0)
Block(-4,31,-5,STONE:0)
Block(-4,31,-4,STONE:0)
Block(-4,31,-3,STONE:0)
Block(-4,31,-2,STONE:0)
Block(-4,31,-1,STONE:0)
Block(-4,31,0,STONE:0)
Block(-4,31,1,STONE:0)
Block(-4,31,2,STONE:0)
Block(-4,31,3,STONE:0)
Block(-4,31,4,STONE:0)
Block(-4,31,5,STONE:0)
Block(-4,31,6,STONE:0)
Block(-4,31,7,STONE:0)
Block(-4,31,8,STONE:0)
Block(-4,32,-7,STONE:0)
Block(-4,32,-6,STONE:0)
Block(-4,32,-5,STONE:0)
Block(-4,32,-4,STONE:0)
Block(-4,32,-3,STONE:0)
Block(-4,32,-2,STONE:0)
Block(-4,32,-1,STONE:0)
Block(-4,32,0,STONE:0)
Block(-4,32,1,STONE:0)
Block(-4,32,2,STONE:0)
Block(-4,32,3,STONE:0)
Block(-4,32,4,STONE:0)
Block(-4,32,5,STONE:0)
Block(-4,32,6,STONE:0)
Block(-4,32,7,STONE:0)
Block(-4,32,8,STONE:0)
Block(-4,33,-7,STONE:0)
Block(-4,33,-6,STONE:0)
Block(-4,33,-5,STONE:0)
Block(-4,33,-4,STONE:0)
Block(-4,33,-3,STONE:0)
Block(-4,33,-2,STONE:0)
Block(-4,33,-1,STONE:0)
Block(-4,33,0,STONE:0)
Block(-4,33,1,STONE:0)
Block(-4,33,2,STONE:0)
Block(-4,33,3,STONE:0)
Block(-4,33,4,STONE:0)
Block(-4,33,5,STONE:0)
Block(-4,33,6,STONE:0)
Block(-4,33,7,STONE:0)
Block(-4,33,8,STONE:0)
Block(-4,34,-7,STONE:0)
Block(-4,34,-6,STONE:0)
Block(-4,34,-5,STONE:0)
Block(-4,34,-4,STONE:0)
Block(-4,34,-3,STONE:0)
Block(-4,34,-2,STONE:0)
Block(-4,34,-1,STONE:0)
Block(-4,34,0,STONE:0)
Block(-4,34,1,STONE:0)
Block(-4,34,2,STONE:0)
Block(-4,34,3,STONE:0)
Block(-4,34,4,STONE:0)
Block(-4,34,5,STONE:0)
Block(-4,34,6,STONE:0)
Block(-4,34,7,STONE:0)
Block(-4,34,8,STONE:0)
Block(-4,35,-7,STONE:0)
Block(-4,35,-6,STONE:0)
Block(-4,35,-5,STONE:0)
Block(-4,35,-4,STONE:0)
Block(-4,35,-3,STONE:0)
Block(-4,35,-2,STONE:0)
Block(-4,35,-1,STONE:0)
Block(-4,35,0,STONE:0)
Block(-4,35,1,STONE:0)
Block(-4,35,2,STONE:0)
Block(-4,35,3,STONE:0)
Block(-4,35,4,STONE:0)
Block(-4,35,5,STONE:0)
Block(-4,35,6,STONE:0)
Block(-4,35,7,STONE:0)
Block(-4,35,8,STONE:0)
Block(-4,36,-7,DIRT:0)
Block(-4,36,-6,DIRT:0)
Block(-4,36,-5,DIRT:0)
Block(-4,36,-4,DIRT:0)
Block(-4,36,-3,DIRT:0)
Block(-4,36,-2,DIRT:0)
Block(-4,36,-1,DIRT:0)
Block(-4,36,0,DIRT:0)
Block(-4,36,1,DIRT:0)
Block(-4,36,2,DIRT:0)
Block(-4,36,3,DIRT:0)
Block(-4,36,4,DIRT:0)
Block(-4,36,5,DIRT:0)
Block(-4,36,6,DIRT:0)
Block(-4,36,7,DIRT:0)
Block(-4,36,8,DIRT:0)
Block(-4,37,-7,DIRT:0)
Block(-4,37,-6,DIRT:0)
Block(-4,37,-5,DIRT:0)
Block(-4,37,-4,DIRT:0)
Block(-4,37,-3,DIRT:0)
Block(-4,37,-2,DIRT:0)
Block(-4,37,-1,DIRT:0)
Block(-4,37,0,DIRT:0)
Block(-4,37,1,DIRT:0)
Block(-4,37,2,DIRT:0)
Block(-4,37,3,DIRT:0)
Block(-4,37,4,DIRT:0)
Block(-4,37,5,DIRT:0)
Block(-4,37,6,DIRT:0)
Block(-4,37,7,DIRT:0)
Block(-4,37,8,DIRT:0)
Block(-4,38,-7,GRASS:0)
Block(-4,38,-6,DIRT:0)
Block(-4,38,-5,GRAVEL:0)
Block(-4,38,-4,GRASS:0)
Block(-4,38,-3,GRASS:0)
Block(-4,38,-2,DIRT:0)
Block(-4,38,-1,COBBLESTONE_STAIRS:0)
Block(-4,38,0,GRASS:0)
Block(-4,38,1,SMOOTH_BRICK:0)
Block(-4,38,2,SMOOTH_BRICK:0)
Block(-4,38,3,COBBLESTONE:0)
Block(-4,38,4,GRAVEL:0)
Block(-4,38,5,GRAVEL:0)
Block(-4,38,6,DIRT:0)
Block(-4,38,7,GRASS:0)
Block(-4,38,8,GRASS:0)
Block(-4,39,-6,WOOD:1)
Block(-4,39,-5,WOOD_STEP:9)
Block(-4,39,-4,WOOD_STEP:9)
Block(-4,39,-3,WOOD_STEP:9)
Block(-4,39,-2,WOOD:1)
Block(-4,39,0,LONG_GRASS:1)
Block(-4,39,1,TRAP_DOOR:4)
Block(-4,39,2,DARK_OAK_STAIRS:1)
Block(-4,39,5,COBBLE_WALL:0)
Block(-4,39,6,SMOOTH_BRICK:3)
Block(-4,39,7,COBBLE_WALL:0)
Block(-4,39,8,LONG_GRASS:1)
Block(-4,40,-6,DARK_OAK_FENCE:0)
Block(-4,40,-5,CARPET:11)
Block(-4,40,-4,CARPET:11)
Block(-4,40,-3,CARPET:6)
Block(-4,40,-2,DARK_OAK_FENCE:0)
Block(-4,40,5,DARK_OAK_FENCE:0)
Block(-4,40,6,COBBLE_WALL:0)
Block(-4,40,7,DARK_OAK_FENCE:0)
Block(-4,41,-6,DARK_OAK_FENCE:0)
Block(-4,41,-2,DARK_OAK_FENCE:0)
Block(-4,41,5,DARK_OAK_FENCE:0)
Block(-4,41,6,COBBLE_WALL:0)
Block(-4,41,7,DARK_OAK_FENCE:0)
Block(-4,42,-6,WOOD:1)
Block(-4,42,-5,WOOD_STEP:9)
Block(-4,42,-4,WOOD_STEP:9)
Block(-4,42,-3,WOOD_STEP:9)
Block(-4,42,-2,WOOD:1)
Block(-4,42,5,DARK_OAK_FENCE:0)
Block(-4,42,6,REDSTONE_LAMP_ON:0)
Block(-4,42,7,DARK_OAK_FENCE:0)
Block(-4,43,5,SPRUCE_WOOD_STAIRS:2)
Block(-4,43,6,LEVER:13)
Block(-4,43,7,SPRUCE_WOOD_STAIRS:3)
Block(-4,44,6,WOOD_STEP:1)
Block(-4,45,3,LEAVES:0)
Block(-4,46,3,LEAVES:0)
Block(-4,46,6,LEAVES:0)
Block(-4,47,2,LEAVES:0)
Block(-4,47,4,LEAVES:0)
Block(-4,47,5,LEAVES:0)
Block(-4,47,6,LEAVES:0)
Block(-4,48,1,LEAVES:0)
Block(-4,48,2,LEAVES:0)
Block(-4,48,3,LEAVES:0)
Block(-4,48,4,LEAVES:0)
Block(-4,48,5,LEAVES:0)
Block(-4,48,6,LEAVES:0)
Block(-4,49,3,LEAVES:0)
Block(-3,0,-7,STONE:0)
Block(-3,0,-6,STONE:0)
Block(-3,0,-5,STONE:0)
Block(-3,0,-4,STONE:0)
Block(-3,0,-3,STONE:0)
Block(-3,0,-2,STONE:0)
Block(-3,0,-1,STONE:0)
Block(-3,0,0,STONE:0)
Block(-3,0,1,STONE:0)
Block(-3,0,2,STONE:0)
Block(-3,0,3,STONE:0)
Block(-3,0,4,STONE:0)
Block(-3,0,5,STONE:0)
Block(-3,0,6,STONE:0)
Block(-3,0,7,STONE:0)
Block(-3,0,8,STONE:0)
Block(-3,1,-7,STONE:0)
Block(-3,1,-6,STONE:0)
Block(-3,1,-5,STONE:0)
Block(-3,1,-4,STONE:0)
Block(-3,1,-3,STONE:0)
Block(-3,1,-2,STONE:0)
Block(-3,1,-1,STONE:0)
Block(-3,1,0,STONE:0)
Block(-3,1,1,STONE:0)
Block(-3,1,2,STONE:0)
Block(-3,1,3,STONE:0)
Block(-3,1,4,STONE:0)
Block(-3,1,5,STONE:0)
Block(-3,1,6,STONE:0)
Block(-3,1,7,STONE:0)
Block(-3,1,8,STONE:0)
Block(-3,2,-7,STONE:0)
Block(-3,2,-6,STONE:0)
Block(-3,2,-5,STONE:0)
Block(-3,2,-4,STONE:0)
Block(-3,2,-3,STONE:0)
Block(-3,2,-2,STONE:0)
Block(-3,2,-1,STONE:0)
Block(-3,2,0,STONE:0)
Block(-3,2,1,STONE:0)
Block(-3,2,2,STONE:0)
Block(-3,2,3,STONE:0)
Block(-3,2,4,STONE:0)
Block(-3,2,5,STONE:0)
Block(-3,2,6,STONE:0)
Block(-3,2,7,STONE:0)
Block(-3,2,8,STONE:0)
Block(-3,3,-7,STONE:0)
Block(-3,3,-6,STONE:0)
Block(-3,3,-5,STONE:0)
Block(-3,3,-4,STONE:0)
Block(-3,3,-3,STONE:0)
Block(-3,3,-2,STONE:0)
Block(-3,3,-1,STONE:0)
Block(-3,3,0,STONE:0)
Block(-3,3,1,STONE:0)
Block(-3,3,2,STONE:0)
Block(-3,3,3,STONE:0)
Block(-3,3,4,STONE:0)
Block(-3,3,5,STONE:0)
Block(-3,3,6,STONE:0)
Block(-3,3,7,STONE:0)
Block(-3,3,8,STONE:0)
Block(-3,4,-7,STONE:0)
Block(-3,4,-6,STONE:0)
Block(-3,4,-5,STONE:0)
Block(-3,4,-4,STONE:0)
Block(-3,4,-3,STONE:0)
Block(-3,4,-2,STONE:0)
Block(-3,4,-1,STONE:0)
Block(-3,4,0,STONE:0)
Block(-3,4,1,STONE:0)
Block(-3,4,2,STONE:0)
Block(-3,4,3,STONE:0)
Block(-3,4,4,STONE:0)
Block(-3,4,5,STONE:0)
Block(-3,4,6,STONE:0)
Block(-3,4,7,STONE:0)
Block(-3,4,8,STONE:0)
Block(-3,5,-7,STONE:0)
Block(-3,5,-6,STONE:0)
Block(-3,5,-5,STONE:0)
Block(-3,5,-4,STONE:0)
Block(-3,5,-3,STONE:0)
Block(-3,5,-2,STONE:0)
Block(-3,5,-1,STONE:0)
Block(-3,5,0,STONE:0)
Block(-3,5,1,STONE:0)
Block(-3,5,2,STONE:0)
Block(-3,5,3,STONE:0)
Block(-3,5,4,STONE:0)
Block(-3,5,5,STONE:0)
Block(-3,5,6,STONE:0)
Block(-3,5,7,STONE:0)
Block(-3,5,8,STONE:0)
Block(-3,6,-7,STONE:0)
Block(-3,6,-6,STONE:0)
Block(-3,6,-5,STONE:0)
Block(-3,6,-4,STONE:0)
Block(-3,6,-3,STONE:0)
Block(-3,6,-2,STONE:0)
Block(-3,6,-1,STONE:0)
Block(-3,6,0,STONE:0)
Block(-3,6,1,STONE:0)
Block(-3,6,2,STONE:0)
Block(-3,6,3,STONE:0)
Block(-3,6,4,STONE:0)
Block(-3,6,5,STONE:0)
Block(-3,6,6,STONE:0)
Block(-3,6,7,STONE:0)
Block(-3,6,8,STONE:0)
Block(-3,7,-7,STONE:0)
Block(-3,7,-6,STONE:0)
Block(-3,7,-5,STONE:0)
Block(-3,7,-4,STONE:0)
Block(-3,7,-3,STONE:0)
Block(-3,7,-2,STONE:0)
Block(-3,7,-1,STONE:0)
Block(-3,7,0,STONE:0)
Block(-3,7,1,STONE:0)
Block(-3,7,2,STONE:0)
Block(-3,7,3,STONE:0)
Block(-3,7,4,STONE:0)
Block(-3,7,5,STONE:0)
Block(-3,7,6,STONE:0)
Block(-3,7,7,STONE:0)
Block(-3,7,8,STONE:0)
Block(-3,8,-7,STONE:0)
Block(-3,8,-6,STONE:0)
Block(-3,8,-5,STONE:0)
Block(-3,8,-4,STONE:0)
Block(-3,8,-3,STONE:0)
Block(-3,8,-2,STONE:0)
Block(-3,8,-1,STONE:0)
Block(-3,8,0,STONE:0)
Block(-3,8,1,STONE:0)
Block(-3,8,2,STONE:0)
Block(-3,8,3,STONE:0)
Block(-3,8,4,STONE:0)
Block(-3,8,5,STONE:0)
Block(-3,8,6,STONE:0)
Block(-3,8,7,STONE:0)
Block(-3,8,8,STONE:0)
Block(-3,9,-7,STONE:0)
Block(-3,9,-6,STONE:0)
Block(-3,9,-5,STONE:0)
Block(-3,9,-4,STONE:0)
Block(-3,9,-3,STONE:0)
Block(-3,9,-2,STONE:0)
Block(-3,9,-1,STONE:0)
Block(-3,9,0,STONE:0)
Block(-3,9,1,STONE:0)
Block(-3,9,2,STONE:0)
Block(-3,9,3,STONE:0)
Block(-3,9,4,STONE:0)
Block(-3,9,5,STONE:0)
Block(-3,9,6,STONE:0)
Block(-3,9,7,STONE:0)
Block(-3,9,8,STONE:0)
Block(-3,10,-7,STONE:0)
Block(-3,10,-6,STONE:0)
Block(-3,10,-5,STONE:0)
Block(-3,10,-4,STONE:0)
Block(-3,10,-3,STONE:0)
Block(-3,10,-2,STONE:0)
Block(-3,10,-1,STONE:0)
Block(-3,10,0,STONE:0)
Block(-3,10,1,STONE:0)
Block(-3,10,2,STONE:0)
Block(-3,10,3,STONE:0)
Block(-3,10,4,STONE:0)
Block(-3,10,5,STONE:0)
Block(-3,10,6,STONE:0)
Block(-3,10,7,STONE:0)
Block(-3,10,8,STONE:0)
Block(-3,11,-7,STONE:0)
Block(-3,11,-6,STONE:0)
Block(-3,11,-5,STONE:0)
Block(-3,11,-4,STONE:0)
Block(-3,11,-3,STONE:0)
Block(-3,11,-2,STONE:0)
Block(-3,11,-1,STONE:0)
Block(-3,11,0,STONE:0)
Block(-3,11,1,STONE:0)
Block(-3,11,2,STONE:0)
Block(-3,11,3,STONE:0)
Block(-3,11,4,STONE:0)
Block(-3,11,5,STONE:0)
Block(-3,11,6,STONE:0)
Block(-3,11,7,STONE:0)
Block(-3,11,8,STONE:0)
Block(-3,12,-7,STONE:0)
Block(-3,12,-6,STONE:0)
Block(-3,12,-5,STONE:0)
Block(-3,12,-4,STONE:0)
Block(-3,12,-3,STONE:0)
Block(-3,12,-2,STONE:0)
Block(-3,12,-1,STONE:0)
Block(-3,12,0,STONE:0)
Block(-3,12,1,STONE:0)
Block(-3,12,2,STONE:0)
Block(-3,12,3,STONE:0)
Block(-3,12,4,STONE:0)
Block(-3,12,5,STONE:0)
Block(-3,12,6,STONE:0)
Block(-3,12,7,STONE:0)
