
#######################################################################
# +-----------------------------------------------------------------+ #
# |                            BO4 object                           | #
# +-----------------------------------------------------------------+ #
#######################################################################

Author: NLBlackEagle

Description: No description given

SettingsMode: WriteDisable


#######################################################################
# +-----------------------------------------------------------------+ #
# |                          Main settings                          | #
# +-----------------------------------------------------------------+ #
#######################################################################

Frequency: 0

SpawnHeight: highestBlock

UseCenterForHighestBlock: true

##############################
# Height Limits for the BO4. #
##############################

MinHeight: 0

MaxHeight: 255

InheritBO3: 

InheritBO3Rotation: NORTH

OverrideChildSettings: true

OverrideParentHeight: false

CanOverride: true

BranchFrequency: 0

BranchFrequencyGroup: 

MustBeBelowOther: false

MustBeInside: 

CannotBeInside: 

ReplacesBO3: L4-M-CrossC0R0, L4-M-CrossC0R1, L4-M-CrossC0R2, L4-M-CrossC0R3, L4-M-CrossC1R0, L4-M-CrossC1R1, L4-M-CrossC1R2, L4-M-CrossC1R3, L4-M-CrossC2R0, L4-M-CrossC2R1, L4-M-CrossC2R2, L4-M-CrossC2R3, L4-M-CrossC3R0, L4-M-CrossC3R1, L4-M-CrossC3R2, L4-M-CrossC3R3, L4-M-Straigth-START_01-C0R0, L4-M-Straigth-START_01-C0R1, L4-M-Straigth-START_01-C1R0, L4-M-Straigth-START_01-C1R1, L4-M-Straigth-START_01-C2R0, L4-M-Straigth-START_01-C2R1, L4-M-Straigth-START_01-C3R0, L4-M-Straigth-START_01-C3R1, L4-M-Straigth-3CC0R0, L4-M-Straigth-3CC0R1, L4-M-Straigth-3CC0R2, L4-M-Straigth-3CC1R0, L4-M-Straigth-3CC1R1, L4-M-Straigth-3CC1R2, L4-M-Straigth-3CC2R0, L4-M-Straigth-3CC2R1, L4-M-Straigth-3CC2R2, L4-M-Straigth-3CC3R0, L4-M-Straigth-3CC3R1, L4-M-Straigth-3CC3R2, L4-M-Cross, skyscraper_2x2_01, skyscraper_2x2_02, skyscraper_2x2_03, skyscraper_2x2_04, skyscraper_2x2_05, skyscraper_3x3_01, skyscraper_3x3_02, skyscraper_3x3_03, L3-M-Straigth-2CC0R0, L3-M-Straigth-2CC0R1, L3-M-Straigth-2CC1R0, L3-M-Straigth-2CC1R1, L3-M-Straigth-2CC2R0, L3-M-Straigth-2CC2R1, L3-M-Straigth-2CC3R0, L3-M-Straigth-2CC3R1, L3-M-Straigth-3CC0R0, L3-M-Straigth-3CC0R1, L3-M-Straigth-3CC0R2, L3-M-Straigth-3CC1R0, L3-M-Straigth-3CC1R1, L3-M-Straigth-3CC1R2, L3-M-Straigth-3CC2R0, L3-M-Straigth-3CC2R1, L3-M-Straigth-3CC2R2, L3-M-Straigth-3CC3R0, L3-M-Straigth-3CC3R1, L3-M-Straigth-3CC3R2L4-M-CrossC0R0, L4-M-CrossC0R1, L4-M-CrossC0R2, L4-M-CrossC0R3, L4-M-CrossC1R0, L4-M-CrossC1R1, L4-M-CrossC1R2, L4-M-CrossC1R3, L4-M-CrossC2R0, L4-M-CrossC2R1, L4-M-CrossC2R2, L4-M-CrossC2R3, L4-M-CrossC3R0, L4-M-CrossC3R1, L4-M-CrossC3R2, L4-M-CrossC3R3, L4-M-Straigth-START_01-C0R0, L4-M-Straigth-START_01-C0R1, L4-M-Straigth-START_01-C1R0, L4-M-Straigth-START_01-C1R1, L4-M-Straigth-START_01-C2R0, L4-M-Straigth-START_01-C2R1, L4-M-Straigth-START_01-C3R0, L4-M-Straigth-START_01-C3R1, L4-M-Straigth-3CC0R0, L4-M-Straigth-3CC0R1, L4-M-Straigth-3CC0R2, L4-M-Straigth-3CC1R0, L4-M-Straigth-3CC1R1, L4-M-Straigth-3CC1R2, L4-M-Straigth-3CC2R0, L4-M-Straigth-3CC2R1, L4-M-Straigth-3CC2R2, L4-M-Straigth-3CC3R0, L4-M-Straigth-3CC3R1, L4-M-Straigth-3CC3R2, L4-M-Cross, skyscraper_2x2_01, skyscraper_2x2_02, skyscraper_2x2_03, skyscraper_2x2_04, skyscraper_2x2_05, skyscraper_3x3_01, skyscraper_3x3_02, skyscraper_3x3_03

MustBeInsideWorldBorders: false

CanSpawnOnWater: true

SpawnOnWaterOnly: false

SpawnUnderWater: false

SpawnAtWaterLevel: false

HeightOffset: 0

RemoveAir: false

ReplaceAbove: 

ReplaceBelow: 

ReplaceWithBiomeBlocks: true

ReplaceWithSurfaceBlock: GRASS

ReplaceWithGroundBlock: DIRT

ReplaceWithStoneBlock: STONE

SmoothRadius: 0

SmoothHeightOffset: 0

SmoothStartTop: false

SmoothStartWood: false

SmoothingSurfaceBlock: 

SmoothingGroundBlock: 

BO3Group: 

IsSpawnPoint: false

DoReplaceBlocks: true


#######################################################################
# +-----------------------------------------------------------------+ #
# |                              Blocks                             | #
# +-----------------------------------------------------------------+ #
#######################################################################

Block(-8,0,-7,CONCRETE:7)
Block(-8,0,-6,CONCRETE:7)
Block(-8,0,-5,CONCRETE:7)
Block(-8,0,-4,CONCRETE:7)
Block(-8,0,-3,CONCRETE:7)
Block(-8,0,-2,CONCRETE:7)
Block(-8,0,-1,CONCRETE:7)
Block(-8,0,0,CONCRETE:7)
Block(-8,0,1,CONCRETE:7)
Block(-8,0,2,CONCRETE:7)
Block(-8,0,3,CONCRETE:7)
Block(-8,0,4,CONCRETE:7)
Block(-8,0,5,CONCRETE:7)
Block(-8,0,6,CONCRETE:7)
Block(-8,0,7,CONCRETE:7)
Block(-8,0,8,CONCRETE:7)
Block(-8,1,-7,OBSIDIAN:0)
Block(-8,1,-6,OBSIDIAN:0)
Block(-8,1,-5,OBSIDIAN:0)
Block(-8,1,-4,OBSIDIAN:0)
Block(-8,1,-3,OBSIDIAN:0)
Block(-8,1,-2,OBSIDIAN:0)
Block(-8,1,-1,OBSIDIAN:0)
Block(-8,1,0,OBSIDIAN:0)
Block(-8,1,1,OBSIDIAN:0)
Block(-8,1,2,OBSIDIAN:0)
Block(-8,1,3,OBSIDIAN:0)
Block(-8,1,4,OBSIDIAN:0)
Block(-8,1,5,OBSIDIAN:0)
Block(-8,1,6,OBSIDIAN:0)
Block(-8,1,7,OBSIDIAN:0)
Block(-8,1,8,OBSIDIAN:0)
Block(-8,2,-7,OBSIDIAN:0)
Block(-8,2,-6,OBSIDIAN:0)
Block(-8,2,-5,OBSIDIAN:0)
Block(-8,2,-4,OBSIDIAN:0)
Block(-8,2,-3,OBSIDIAN:0)
Block(-8,2,-2,OBSIDIAN:0)
Block(-8,2,-1,OBSIDIAN:0)
Block(-8,2,0,OBSIDIAN:0)
Block(-8,2,1,OBSIDIAN:0)
Block(-8,2,2,CONCRETE:7)
Block(-8,2,3,CONCRETE:7)
Block(-8,2,4,CONCRETE:7)
Block(-8,2,5,CONCRETE:7)
Block(-8,2,6,CONCRETE:7)
Block(-8,2,7,CONCRETE:7)
Block(-8,2,8,CONCRETE:7)
Block(-8,3,-7,STATIONARY_LAVA:0)
Block(-8,3,-6,STATIONARY_LAVA:0)
Block(-8,3,-5,STATIONARY_LAVA:0)
Block(-8,3,-4,STATIONARY_LAVA:0)
Block(-8,3,-3,STATIONARY_LAVA:0)
Block(-8,3,-2,STATIONARY_LAVA:0)
Block(-8,3,-1,OBSIDIAN:0)
Block(-8,3,0,OBSIDIAN:0)
Block(-8,3,1,OBSIDIAN:0)
Block(-8,3,2,CONCRETE:7)
Block(-8,3,3,CONCRETE:7)
Block(-8,3,4,CONCRETE:7)
Block(-8,3,5,CONCRETE:7)
Block(-8,3,6,CONCRETE:7)
Block(-8,3,7,CONCRETE:7)
Block(-8,3,8,CONCRETE:7)
Block(-8,4,-7,OBSIDIAN:0)
Block(-8,4,-6,OBSIDIAN:0)
Block(-8,4,-5,OBSIDIAN:0)
Block(-8,4,-4,OBSIDIAN:0)
Block(-8,4,-3,OBSIDIAN:0)
Block(-8,4,-2,STATIONARY_LAVA:0)
Block(-8,4,-1,OBSIDIAN:0)
Block(-8,4,0,OBSIDIAN:0)
Block(-8,4,1,OBSIDIAN:0)
Block(-8,4,2,CONCRETE:7)
Block(-8,4,3,CONCRETE:7)
Block(-8,4,4,CONCRETE:7)
Block(-8,4,5,CONCRETE:7)
Block(-8,4,6,CONCRETE:7)
Block(-8,4,7,CONCRETE:7)
Block(-8,4,8,CONCRETE:7)
Block(-8,5,-7,COBBLE_WALL:0)
Block(-8,5,-6,IRON_PLATE:0)
Block(-8,5,-5,OBSIDIAN:0)
Block(-8,5,-4,STATIONARY_LAVA:0)
Block(-8,5,-3,OBSIDIAN:0)
Block(-8,5,-2,STATIONARY_LAVA:0)
Block(-8,5,-1,OBSIDIAN:0)
Block(-8,5,0,OBSIDIAN:0)
Block(-8,5,1,OBSIDIAN:0)
Block(-8,5,2,CONCRETE:7)
Block(-8,5,3,OBSIDIAN:0)
Block(-8,5,4,CONCRETE:1)
Block(-8,5,5,CONCRETE:15)
Block(-8,5,6,CONCRETE:15)
Block(-8,5,7,CONCRETE:15)
Block(-8,5,8,CONCRETE:15)
Block(-8,6,-7,DOUBLE_STEP:0)
Block(-8,6,-6,STONE_BUTTON:3)
Block(-8,6,-5,OBSIDIAN:0)
Block(-8,6,-4,STATIONARY_LAVA:0)
Block(-8,6,-3,OBSIDIAN:0)
Block(-8,6,-2,STATIONARY_LAVA:0)
Block(-8,6,-1,OBSIDIAN:0)
Block(-8,6,0,OBSIDIAN:0)
Block(-8,6,1,OBSIDIAN:0)
Block(-8,6,2,CONCRETE:7)
Block(-8,6,3,OBSIDIAN:0)
Block(-8,6,4,CONCRETE:1)
Block(-8,6,5,CONCRETE_POWDER:15)
Block(-8,6,6,CONCRETE_POWDER:15)
Block(-8,6,7,CONCRETE_POWDER:15)
Block(-8,6,8,CONCRETE_POWDER:15)
Block(-8,7,-7,COBBLE_WALL:0)
Block(-8,7,-6,AIR:0)
Block(-8,7,-5,OBSIDIAN:0)
Block(-8,7,-4,STATIONARY_LAVA:0)
Block(-8,7,-3,OBSIDIAN:0)
Block(-8,7,-2,STATIONARY_LAVA:0)
Block(-8,7,-1,OBSIDIAN:0)
Block(-8,7,0,OBSIDIAN:0)
Block(-8,7,1,OBSIDIAN:0)
Block(-8,7,2,CONCRETE:7)
Block(-8,7,3,OBSIDIAN:0)
Block(-8,7,4,CONCRETE:1)
Block(-8,7,5,CONCRETE_POWDER:15)
Block(-8,7,6,CONCRETE_POWDER:15)
Block(-8,7,7,CONCRETE_POWDER:15)
Block(-8,7,8,CONCRETE_POWDER:15)
Block(-8,8,-7,DOUBLE_STEP:0)
Block(-8,8,-6,STONE_BUTTON:3)
Block(-8,8,-5,OBSIDIAN:0)
Block(-8,8,-4,STATIONARY_LAVA:0)
Block(-8,8,-3,OBSIDIAN:0)
Block(-8,8,-2,STATIONARY_LAVA:0)
Block(-8,8,-1,OBSIDIAN:0)
Block(-8,8,0,OBSIDIAN:0)
Block(-8,8,1,OBSIDIAN:0)
Block(-8,8,2,CONCRETE:7)
Block(-8,8,3,CONCRETE:7)
Block(-8,8,4,CONCRETE:1)
Block(-8,8,5,COAL_BLOCK:0)
Block(-8,8,6,CONCRETE_POWDER:15)
Block(-8,8,7,CONCRETE_POWDER:15)
Block(-8,8,8,CONCRETE_POWDER:15)
Block(-8,9,-7,GOLD_PLATE:0)
Block(-8,9,-6,AIR:0)
Block(-8,9,-5,OBSIDIAN:0)
Block(-8,9,-4,STATIONARY_LAVA:0)
Block(-8,9,-3,OBSIDIAN:0)
Block(-8,9,-2,STATIONARY_LAVA:0)
Block(-8,9,-1,OBSIDIAN:0)
Block(-8,9,0,OBSIDIAN:0)
Block(-8,9,1,OBSIDIAN:0)
Block(-8,9,2,CONCRETE:7)
Block(-8,9,3,OBSIDIAN:0)
Block(-8,9,4,CONCRETE:1)
Block(-8,9,5,CONCRETE_POWDER:15)
Block(-8,9,6,AIR:0)
Block(-8,9,7,AIR:0)
Block(-8,9,8,AIR:0)
Block(-8,10,-7,STEP:8)
Block(-8,10,-6,STEP:8)
Block(-8,10,-5,OBSIDIAN:0)
Block(-8,10,-4,STATIONARY_LAVA:0)
Block(-8,10,-3,OBSIDIAN:0)
Block(-8,10,-2,STATIONARY_LAVA:0)
Block(-8,10,-1,OBSIDIAN:0)
Block(-8,10,0,OBSIDIAN:0)
Block(-8,10,1,OBSIDIAN:0)
Block(-8,10,2,CONCRETE:7)
Block(-8,10,3,OBSIDIAN:0)
Block(-8,10,4,CONCRETE:1)
Block(-8,10,5,AIR:0)
Block(-8,10,6,AIR:0)
Block(-8,10,7,AIR:0)
Block(-8,10,8,AIR:0)
Block(-8,11,-7,OBSIDIAN:0)
Block(-8,11,-6,OBSIDIAN:0)
Block(-8,11,-5,OBSIDIAN:0)
Block(-8,11,-4,OBSIDIAN:0)
Block(-8,11,-3,OBSIDIAN:0)
Block(-8,11,-2,STATIONARY_LAVA:0)
Block(-8,11,-1,OBSIDIAN:0)
Block(-8,11,0,OBSIDIAN:0)
Block(-8,11,1,OBSIDIAN:0)
Block(-8,11,2,CONCRETE:7)
Block(-8,11,3,OBSIDIAN:0)
Block(-8,11,4,CONCRETE:1)
Block(-8,11,5,AIR:0)
Block(-8,11,6,AIR:0)
Block(-8,11,7,AIR:0)
Block(-8,11,8,AIR:0)
Block(-8,12,-7,STATIONARY_LAVA:0)
Block(-8,12,-6,STATIONARY_LAVA:0)
Block(-8,12,-5,STATIONARY_LAVA:0)
Block(-8,12,-4,STATIONARY_LAVA:0)
Block(-8,12,-3,STATIONARY_LAVA:0)
Block(-8,12,-2,STATIONARY_LAVA:0)
Block(-8,12,-1,OBSIDIAN:0)
Block(-8,12,0,OBSIDIAN:0)
Block(-8,12,1,OBSIDIAN:0)
Block(-8,12,2,CONCRETE:7)
Block(-8,12,3,CONCRETE:7)
Block(-8,12,4,CONCRETE:14)
Block(-8,12,5,DROPPER:1,NBT/skyscraper_8x6_01/465-dropperC64R48.nbt)
Block(-8,12,6,DROPPER:1,NBT/skyscraper_8x6_01/466-dropperC64R48.nbt)
Block(-8,12,7,CONCRETE:14)
Block(-8,12,8,DROPPER:1,NBT/skyscraper_8x6_01/467-dropperC64R48.nbt)
Block(-8,13,-7,OBSIDIAN:0)
Block(-8,13,-6,OBSIDIAN:0)
Block(-8,13,-5,OBSIDIAN:0)
Block(-8,13,-4,OBSIDIAN:0)
Block(-8,13,-3,OBSIDIAN:0)
Block(-8,13,-2,OBSIDIAN:0)
Block(-8,13,-1,OBSIDIAN:0)
Block(-8,13,0,OBSIDIAN:0)
Block(-8,13,1,OBSIDIAN:0)
Block(-8,13,2,CONCRETE:7)
Block(-8,13,3,OBSIDIAN:0)
Block(-8,13,4,IRON_FENCE:0)
Block(-8,13,5,COBBLE_WALL:0)
Block(-8,13,6,COBBLE_WALL:0)
Block(-8,13,7,IRON_FENCE:0)
Block(-8,13,8,COBBLE_WALL:0)
Block(-8,14,-7,OBSIDIAN:0)
Block(-8,14,-6,OBSIDIAN:0)
Block(-8,14,-5,OBSIDIAN:0)
Block(-8,14,-4,OBSIDIAN:0)
Block(-8,14,-3,OBSIDIAN:0)
Block(-8,14,-2,OBSIDIAN:0)
Block(-8,14,-1,OBSIDIAN:0)
Block(-8,14,0,OBSIDIAN:0)
Block(-8,14,1,OBSIDIAN:0)
Block(-8,14,2,CONCRETE:7)
Block(-8,14,3,OBSIDIAN:0)
Block(-8,14,4,STEP:8)
Block(-8,14,5,CONCRETE:15)
Block(-8,14,6,CONCRETE:15)
Block(-8,14,7,STEP:8)
Block(-8,14,8,CONCRETE:15)
Block(-8,15,-7,OBSIDIAN:0)
Block(-8,15,-6,OBSIDIAN:0)
Block(-8,15,-5,OBSIDIAN:0)
Block(-8,15,-4,OBSIDIAN:0)
Block(-8,15,-3,OBSIDIAN:0)
Block(-8,15,-2,OBSIDIAN:0)
Block(-8,15,-1,OBSIDIAN:0)
Block(-8,15,0,OBSIDIAN:0)
Block(-8,15,1,OBSIDIAN:0)
Block(-8,15,2,CONCRETE:7)
Block(-8,15,3,CONCRETE:7)
Block(-8,15,4,CONCRETE:12)
Block(-8,15,5,CONCRETE:12)
Block(-8,15,6,CONCRETE:12)
Block(-8,15,7,CONCRETE:12)
Block(-8,15,8,CONCRETE:7)
Block(-8,16,-7,OBSIDIAN:0)
Block(-8,16,-6,OBSIDIAN:0)
Block(-8,16,-5,OBSIDIAN:0)
Block(-8,16,-4,OBSIDIAN:0)
Block(-8,16,-3,OBSIDIAN:0)
Block(-8,16,-2,OBSIDIAN:0)
Block(-8,16,-1,OBSIDIAN:0)
Block(-8,16,0,OBSIDIAN:0)
Block(-8,16,1,OBSIDIAN:0)
Block(-8,16,2,OBSIDIAN:0)
Block(-8,16,3,OBSIDIAN:0)
Block(-8,16,4,OBSIDIAN:0)
Block(-8,16,5,OBSIDIAN:0)
Block(-8,16,6,OBSIDIAN:0)
Block(-8,16,7,OBSIDIAN:0)
Block(-8,16,8,OBSIDIAN:0)
Block(-8,17,-7,CONCRETE:7)
Block(-8,17,-6,CONCRETE:7)
Block(-8,17,-5,CONCRETE:7)
Block(-8,17,-4,CONCRETE:7)
Block(-8,17,-3,CONCRETE:7)
Block(-8,17,-2,CONCRETE:7)
Block(-8,17,-1,CONCRETE:7)
Block(-8,17,0,CONCRETE:7)
Block(-8,17,1,CONCRETE:7)
Block(-8,17,2,CONCRETE:7)
Block(-8,17,3,CONCRETE:7)
Block(-8,17,4,CONCRETE:7)
Block(-8,17,5,CONCRETE:7)
Block(-8,17,6,CONCRETE:7)
Block(-8,17,7,CONCRETE:7)
Block(-8,17,8,CONCRETE:7)
Block(-8,21,-7,STEP:8)
Block(-8,21,-6,STEP:8)
Block(-8,21,-5,STEP:8)
Block(-8,21,-4,STEP:8)
Block(-8,21,-3,STEP:8)
Block(-8,21,-2,STEP:8)
Block(-8,21,-1,STEP:8)
Block(-8,21,0,STEP:8)
Block(-8,21,1,STEP:8)
Block(-8,21,2,STEP:8)
Block(-8,21,3,STEP:8)
Block(-8,21,4,STEP:8)
Block(-8,21,5,STEP:8)
Block(-8,21,6,STEP:8)
Block(-8,21,7,STEP:8)
Block(-8,21,8,STEP:8)
Block(-8,22,-7,CONCRETE:7)
Block(-8,22,-6,CONCRETE:7)
Block(-8,22,-5,CONCRETE:7)
Block(-8,22,-4,CONCRETE:7)
Block(-8,22,-3,CONCRETE:7)
Block(-8,22,-2,CONCRETE:7)
Block(-8,22,-1,CONCRETE:7)
Block(-8,22,0,CONCRETE:12)
Block(-8,22,1,CONCRETE:7)
Block(-8,22,2,CONCRETE:7)
Block(-8,22,3,CONCRETE:7)
Block(-8,22,4,CONCRETE:7)
Block(-8,22,5,CONCRETE:7)
Block(-8,22,6,CONCRETE:7)
Block(-8,22,7,CONCRETE:12)
Block(-8,22,8,CONCRETE:11)
Block(-8,23,-7,OBSIDIAN:0)
Block(-8,23,-6,OBSIDIAN:0)
Block(-8,23,-5,CONCRETE:11)
Block(-8,23,-4,OBSIDIAN:0)
Block(-8,23,-3,OBSIDIAN:0)
Block(-8,23,-2,OBSIDIAN:0)
Block(-8,23,-1,OBSIDIAN:0)
Block(-8,23,0,OBSIDIAN:0)
Block(-8,23,1,OBSIDIAN:0)
Block(-8,23,2,OBSIDIAN:0)
Block(-8,23,3,OBSIDIAN:0)
Block(-8,23,4,OBSIDIAN:0)
Block(-8,23,5,OBSIDIAN:0)
Block(-8,23,6,OBSIDIAN:0)
Block(-8,23,7,OBSIDIAN:0)
Block(-8,23,8,CONCRETE:11)
Block(-8,24,-7,CONCRETE:0)
Block(-8,24,-6,CONCRETE:0)
Block(-8,24,-5,CONCRETE:11)
Block(-8,24,-4,CONCRETE:0)
Block(-8,24,-3,CONCRETE:0)
Block(-8,24,-2,CONCRETE:0)
Block(-8,24,-1,CONCRETE:0)
Block(-8,24,0,CONCRETE:0)
Block(-8,24,1,CONCRETE:0)
Block(-8,24,2,CONCRETE:0)
Block(-8,24,3,CONCRETE:0)
Block(-8,24,4,CONCRETE:0)
Block(-8,24,5,CONCRETE:0)
Block(-8,24,6,CONCRETE:0)
Block(-8,24,7,CONCRETE:0)
Block(-8,24,8,CONCRETE:11)
Block(-8,25,-7,CONCRETE:11)
Block(-8,25,-6,CONCRETE:11)
Block(-8,25,-5,CONCRETE:11)
Block(-8,25,-4,CONCRETE:11)
Block(-8,25,-3,CONCRETE:11)
Block(-8,25,-2,CONCRETE:11)
Block(-8,25,-1,CONCRETE:11)
Block(-8,25,0,CONCRETE:0)
Block(-8,25,1,CONCRETE:0)
Block(-8,25,3,CONCRETE:0)
Block(-8,25,4,CONCRETE:0)
Block(-8,25,5,CONCRETE:0)
Block(-8,25,6,CONCRETE:0)
Block(-8,25,7,CONCRETE:0)
Block(-8,25,8,CONCRETE:0)
Block(-8,26,-7,CONCRETE:0)
Block(-8,26,-6,CONCRETE:0)
Block(-8,26,-5,CONCRETE:0)
Block(-8,26,-4,CONCRETE:0)
Block(-8,26,-3,CONCRETE:0)
Block(-8,26,-2,CONCRETE:0)
Block(-8,26,-1,CONCRETE:0)
Block(-8,26,0,CONCRETE:0)
Block(-8,26,1,CONCRETE:0)
Block(-8,26,3,CONCRETE:0)
Block(-8,26,4,CONCRETE:0)
Block(-8,26,5,CONCRETE:0)
Block(-8,26,6,CONCRETE:0)
Block(-8,26,7,CONCRETE:0)
Block(-8,26,8,CONCRETE:0)
Block(-8,27,-7,DOUBLE_STEP:0)
Block(-8,27,-6,DOUBLE_STEP:0)
Block(-8,27,-5,DOUBLE_STEP:0)
Block(-8,27,-4,DOUBLE_STEP:0)
Block(-8,27,-3,DOUBLE_STEP:0)
Block(-8,27,-2,DOUBLE_STEP:0)
Block(-8,27,-1,CONCRETE:0)
Block(-8,27,0,CONCRETE:0)
Block(-8,27,1,CONCRETE:0)
Block(-8,27,2,CONCRETE:0)
Block(-8,27,3,CONCRETE:15)
Block(-8,27,4,CONCRETE:0)
Block(-8,27,5,STONE:6)
Block(-8,27,6,CONCRETE:0)
Block(-8,27,7,STONE:6)
Block(-8,27,8,CONCRETE:0)
Block(-8,28,-7,TRAP_DOOR:6)
Block(-8,28,-3,TRAP_DOOR:6)
Block(-8,28,-2,TRAP_DOOR:6)
Block(-8,28,-1,TRAP_DOOR:6)
Block(-8,32,1,STAINED_GLASS_PANE:15)
Block(-8,33,1,STAINED_GLASS_PANE:15)
Block(-8,34,1,STAINED_GLASS_PANE:15)
Block(-8,35,1,STAINED_GLASS_PANE:15)
Block(-8,36,1,STAINED_GLASS_PANE:15)
Block(-8,37,1,STAINED_GLASS_PANE:15)
Block(-8,38,1,STAINED_GLASS_PANE:15)
Block(-8,39,1,STAINED_GLASS_PANE:15)
Block(-8,40,1,QUARTZ_STAIRS:6)
Block(-8,41,1,CONCRETE:0)
Block(-8,42,1,CONCRETE:0)
Block(-8,43,1,CONCRETE:0)
Block(-8,44,1,CONCRETE:0)
Block(-8,45,1,QUARTZ_STAIRS:2)
Block(-8,45,2,CONCRETE:0)
Block(-8,46,2,CONCRETE:0)
Block(-8,47,-5,IRON_TRAPDOOR:10)
Block(-8,47,2,QUARTZ_STAIRS:2)
Block(-8,47,3,CONCRETE:0)
Block(-8,48,-5,SEA_LANTERN:0)
Block(-8,48,3,CONCRETE:0)
Block(-8,49,-6,TRAP_DOOR:4)
Block(-8,49,-5,GRASS:0)
Block(-8,49,-4,TRAP_DOOR:5)
Block(-8,49,-2,CONCRETE:7)
Block(-8,49,4,CONCRETE:0)
Block(-8,49,5,CONCRETE:0)
Block(-8,50,-5,LEAVES:12)
Block(-8,50,-2,IRON_FENCE:0)
Block(-8,50,5,CONCRETE:0)
Block(-8,50,6,CONCRETE:0)
Block(-8,51,6,QUARTZ_STAIRS:2)
Block(-8,51,7,CONCRETE:0)
Block(-8,52,7,QUARTZ_STAIRS:2)
Block(-8,52,8,CONCRETE:7)
Block(-8,53,-4,IRON_TRAPDOOR:9)
Block(-8,53,8,CONCRETE:0)
Block(-8,54,-5,TRAP_DOOR:4)
Block(-8,54,-4,SEA_LANTERN:0)
Block(-8,54,-3,TRAP_DOOR:5)
Block(-8,54,7,CONCRETE:7)
Block(-8,55,-4,CONCRETE:7)
Block(-8,55,7,CONCRETE:7)
Block(-8,56,6,CONCRETE:7)
Block(-8,57,6,CONCRETE:7)
Block(-8,58,5,CONCRETE:7)
Block(-8,59,4,CONCRETE:7)
Block(-8,60,2,CONCRETE:7)
Block(-8,60,3,CONCRETE:7)
Block(-8,61,-1,STEP:15)
Block(-8,61,0,CONCRETE:0)
Block(-8,61,1,CONCRETE:0)
Block(-8,62,-2,CONCRETE:7)
Block(-8,62,-1,CONCRETE:7)
Block(-8,63,-7,CONCRETE:7)
Block(-8,63,-6,CONCRETE:7)
Block(-8,63,-5,CONCRETE:7)
Block(-8,63,-4,CONCRETE:7)
Block(-8,63,-3,CONCRETE:7)
Block(-7,0,-7,CONCRETE:7)
Block(-7,0,-6,CONCRETE:7)
Block(-7,0,-5,CONCRETE:7)
Block(-7,0,-4,CONCRETE:7)
Block(-7,0,-3,CONCRETE:7)
Block(-7,0,-2,CONCRETE:7)
Block(-7,0,-1,CONCRETE:7)
Block(-7,0,0,CONCRETE:7)
Block(-7,0,1,CONCRETE:7)
Block(-7,0,2,CONCRETE:7)
Block(-7,0,3,CONCRETE:7)
Block(-7,0,4,CONCRETE:7)
Block(-7,0,5,CONCRETE:7)
Block(-7,0,6,CONCRETE:7)
Block(-7,0,7,CONCRETE:7)
Block(-7,0,8,CONCRETE:7)
Block(-7,1,-7,OBSIDIAN:0)
Block(-7,1,-6,OBSIDIAN:0)
Block(-7,1,-5,OBSIDIAN:0)
Block(-7,1,-4,OBSIDIAN:0)
Block(-7,1,-3,OBSIDIAN:0)
Block(-7,1,-2,OBSIDIAN:0)
Block(-7,1,-1,OBSIDIAN:0)
Block(-7,1,0,OBSIDIAN:0)
Block(-7,1,1,OBSIDIAN:0)
Block(-7,1,2,OBSIDIAN:0)
Block(-7,1,3,OBSIDIAN:0)
Block(-7,1,4,OBSIDIAN:0)
Block(-7,1,5,OBSIDIAN:0)
Block(-7,1,6,OBSIDIAN:0)
Block(-7,1,7,OBSIDIAN:0)
Block(-7,1,8,OBSIDIAN:0)
Block(-7,2,-7,OBSIDIAN:0)
Block(-7,2,-6,OBSIDIAN:0)
Block(-7,2,-5,OBSIDIAN:0)
Block(-7,2,-4,OBSIDIAN:0)
Block(-7,2,-3,OBSIDIAN:0)
Block(-7,2,-2,OBSIDIAN:0)
Block(-7,2,-1,OBSIDIAN:0)
Block(-7,2,0,OBSIDIAN:0)
Block(-7,2,1,OBSIDIAN:0)
Block(-7,2,2,CONCRETE:7)
Block(-7,2,3,CONCRETE:7)
Block(-7,2,4,CONCRETE:7)
Block(-7,2,5,CONCRETE:7)
Block(-7,2,6,CONCRETE:7)
Block(-7,2,7,CONCRETE:7)
Block(-7,2,8,CONCRETE:7)
Block(-7,3,-7,STATIONARY_LAVA:0)
Block(-7,3,-6,STATIONARY_LAVA:0)
Block(-7,3,-5,STATIONARY_LAVA:0)
Block(-7,3,-4,STATIONARY_LAVA:0)
Block(-7,3,-3,STATIONARY_LAVA:0)
Block(-7,3,-2,STATIONARY_LAVA:0)
Block(-7,3,-1,OBSIDIAN:0)
Block(-7,3,0,OBSIDIAN:0)
Block(-7,3,1,OBSIDIAN:0)
Block(-7,3,2,CONCRETE:7)
Block(-7,3,3,CONCRETE:7)
Block(-7,3,4,CONCRETE:7)
Block(-7,3,5,CONCRETE:7)
Block(-7,3,6,CONCRETE:7)
Block(-7,3,7,CONCRETE:7)
Block(-7,3,8,CONCRETE:7)
Block(-7,4,-7,OBSIDIAN:0)
Block(-7,4,-6,OBSIDIAN:0)
Block(-7,4,-5,OBSIDIAN:0)
Block(-7,4,-4,OBSIDIAN:0)
Block(-7,4,-3,OBSIDIAN:0)
Block(-7,4,-2,STATIONARY_LAVA:0)
Block(-7,4,-1,OBSIDIAN:0)
Block(-7,4,0,OBSIDIAN:0)
Block(-7,4,1,OBSIDIAN:0)
Block(-7,4,2,CONCRETE:7)
Block(-7,4,3,CONCRETE:7)
Block(-7,4,4,CONCRETE:7)
Block(-7,4,5,CONCRETE:7)
Block(-7,4,6,CONCRETE:7)
Block(-7,4,7,CONCRETE:7)
Block(-7,4,8,CONCRETE:7)
Block(-7,5,-7,IRON_PLATE:0)
Block(-7,5,-6,IRON_PLATE:0)
Block(-7,5,-5,OBSIDIAN:0)
Block(-7,5,-4,STATIONARY_LAVA:0)
Block(-7,5,-3,OBSIDIAN:0)
Block(-7,5,-2,STATIONARY_LAVA:0)
Block(-7,5,-1,OBSIDIAN:0)
Block(-7,5,0,OBSIDIAN:0)
Block(-7,5,1,OBSIDIAN:0)
Block(-7,5,2,CONCRETE:7)
Block(-7,5,3,OBSIDIAN:0)
Block(-7,5,4,CONCRETE:14)
Block(-7,5,5,CONCRETE:1)
Block(-7,5,6,CONCRETE:1)
Block(-7,5,7,CONCRETE:14)
Block(-7,5,8,CONCRETE:1)
Block(-7,6,-7,STONE_BUTTON:1)
Block(-7,6,-6,AIR:0)
Block(-7,6,-5,OBSIDIAN:0)
Block(-7,6,-4,STATIONARY_LAVA:0)
Block(-7,6,-3,OBSIDIAN:0)
Block(-7,6,-2,STATIONARY_LAVA:0)
Block(-7,6,-1,OBSIDIAN:0)
Block(-7,6,0,OBSIDIAN:0)
Block(-7,6,1,OBSIDIAN:0)
Block(-7,6,2,CONCRETE:7)
Block(-7,6,3,OBSIDIAN:0)
Block(-7,6,4,CONCRETE:14)
Block(-7,6,5,CONCRETE:1)
Block(-7,6,6,CONCRETE:1)
Block(-7,6,7,CONCRETE:14)
Block(-7,6,8,CONCRETE:1)
Block(-7,7,-7,AIR:0)
Block(-7,7,-6,AIR:0)
Block(-7,7,-5,OBSIDIAN:0)
Block(-7,7,-4,STATIONARY_LAVA:0)
Block(-7,7,-3,OBSIDIAN:0)
Block(-7,7,-2,STATIONARY_LAVA:0)
Block(-7,7,-1,OBSIDIAN:0)
Block(-7,7,0,OBSIDIAN:0)
Block(-7,7,1,OBSIDIAN:0)
Block(-7,7,2,CONCRETE:7)
Block(-7,7,3,OBSIDIAN:0)
Block(-7,7,4,CONCRETE:14)
Block(-7,7,5,CONCRETE:1)
Block(-7,7,6,CONCRETE:1)
Block(-7,7,7,CONCRETE:14)
Block(-7,7,8,CONCRETE:1)
Block(-7,8,-7,STONE_BUTTON:1)
Block(-7,8,-6,AIR:0)
Block(-7,8,-5,OBSIDIAN:0)
Block(-7,8,-4,STATIONARY_LAVA:0)
Block(-7,8,-3,OBSIDIAN:0)
Block(-7,8,-2,STATIONARY_LAVA:0)
Block(-7,8,-1,OBSIDIAN:0)
Block(-7,8,0,OBSIDIAN:0)
Block(-7,8,1,OBSIDIAN:0)
Block(-7,8,2,CONCRETE:7)
Block(-7,8,3,CONCRETE:7)
Block(-7,8,4,CONCRETE:14)
Block(-7,8,5,CONCRETE:1)
Block(-7,8,6,CONCRETE:1)
Block(-7,8,7,CONCRETE:14)
Block(-7,8,8,CONCRETE:1)
Block(-7,9,-7,AIR:0)
Block(-7,9,-6,AIR:0)
Block(-7,9,-5,OBSIDIAN:0)
Block(-7,9,-4,STATIONARY_LAVA:0)
Block(-7,9,-3,OBSIDIAN:0)
Block(-7,9,-2,STATIONARY_LAVA:0)
Block(-7,9,-1,OBSIDIAN:0)
Block(-7,9,0,OBSIDIAN:0)
Block(-7,9,1,OBSIDIAN:0)
Block(-7,9,2,CONCRETE:7)
Block(-7,9,3,OBSIDIAN:0)
Block(-7,9,4,CONCRETE:14)
Block(-7,9,5,CONCRETE:1)
Block(-7,9,6,CONCRETE:1)
Block(-7,9,7,CONCRETE:14)
Block(-7,9,8,CONCRETE:1)
Block(-7,10,-7,STEP:8)
Block(-7,10,-6,STEP:8)
Block(-7,10,-5,OBSIDIAN:0)
Block(-7,10,-4,STATIONARY_LAVA:0)
Block(-7,10,-3,OBSIDIAN:0)
Block(-7,10,-2,STATIONARY_LAVA:0)
Block(-7,10,-1,OBSIDIAN:0)
Block(-7,10,0,OBSIDIAN:0)
Block(-7,10,1,OBSIDIAN:0)
Block(-7,10,2,CONCRETE:7)
Block(-7,10,3,OBSIDIAN:0)
Block(-7,10,4,CONCRETE:14)
Block(-7,10,5,CONCRETE:1)
Block(-7,10,6,CONCRETE:1)
Block(-7,10,7,CONCRETE:14)
Block(-7,10,8,CONCRETE:1)
Block(-7,11,-7,OBSIDIAN:0)
Block(-7,11,-6,OBSIDIAN:0)
Block(-7,11,-5,OBSIDIAN:0)
Block(-7,11,-4,OBSIDIAN:0)
Block(-7,11,-3,OBSIDIAN:0)
Block(-7,11,-2,STATIONARY_LAVA:0)
Block(-7,11,-1,OBSIDIAN:0)
Block(-7,11,0,OBSIDIAN:0)
Block(-7,11,1,OBSIDIAN:0)
Block(-7,11,2,CONCRETE:7)
Block(-7,11,3,OBSIDIAN:0)
Block(-7,11,4,CONCRETE:14)
Block(-7,11,5,CONCRETE:1)
Block(-7,11,6,CONCRETE:1)
Block(-7,11,7,CONCRETE:14)
Block(-7,11,8,CONCRETE:1)
Block(-7,12,-7,STATIONARY_LAVA:0)
Block(-7,12,-6,STATIONARY_LAVA:0)
Block(-7,12,-5,STATIONARY_LAVA:0)
Block(-7,12,-4,STATIONARY_LAVA:0)
Block(-7,12,-3,STATIONARY_LAVA:0)
Block(-7,12,-2,STATIONARY_LAVA:0)
Block(-7,12,-1,OBSIDIAN:0)
Block(-7,12,0,OBSIDIAN:0)
Block(-7,12,1,OBSIDIAN:0)
Block(-7,12,2,CONCRETE:7)
Block(-7,12,3,CONCRETE:7)
Block(-7,12,4,CONCRETE:14)
Block(-7,12,5,CONCRETE:1)
Block(-7,12,6,CONCRETE:1)
Block(-7,12,7,CONCRETE:14)
Block(-7,12,8,CONCRETE:1)
Block(-7,13,-7,OBSIDIAN:0)
Block(-7,13,-6,OBSIDIAN:0)
Block(-7,13,-5,OBSIDIAN:0)
Block(-7,13,-4,OBSIDIAN:0)
Block(-7,13,-3,OBSIDIAN:0)
Block(-7,13,-2,OBSIDIAN:0)
Block(-7,13,-1,OBSIDIAN:0)
Block(-7,13,0,OBSIDIAN:0)
Block(-7,13,1,OBSIDIAN:0)
Block(-7,13,2,CONCRETE:7)
Block(-7,13,3,OBSIDIAN:0)
Block(-7,13,4,IRON_FENCE:0)
Block(-7,13,5,AIR:0)
Block(-7,13,6,AIR:0)
Block(-7,13,7,IRON_FENCE:0)
Block(-7,13,8,AIR:0)
Block(-7,14,-7,OBSIDIAN:0)
Block(-7,14,-6,OBSIDIAN:0)
Block(-7,14,-5,OBSIDIAN:0)
Block(-7,14,-4,OBSIDIAN:0)
Block(-7,14,-3,OBSIDIAN:0)
Block(-7,14,-2,OBSIDIAN:0)
Block(-7,14,-1,OBSIDIAN:0)
Block(-7,14,0,OBSIDIAN:0)
Block(-7,14,1,OBSIDIAN:0)
Block(-7,14,2,CONCRETE:7)
Block(-7,14,3,OBSIDIAN:0)
Block(-7,14,4,STEP:8)
Block(-7,14,5,STEP:8)
Block(-7,14,6,STEP:8)
Block(-7,14,7,STEP:8)
Block(-7,14,8,STEP:8)
Block(-7,15,-7,OBSIDIAN:0)
Block(-7,15,-6,OBSIDIAN:0)
Block(-7,15,-5,OBSIDIAN:0)
Block(-7,15,-4,OBSIDIAN:0)
Block(-7,15,-3,OBSIDIAN:0)
Block(-7,15,-2,OBSIDIAN:0)
Block(-7,15,-1,OBSIDIAN:0)
Block(-7,15,0,OBSIDIAN:0)
Block(-7,15,1,OBSIDIAN:0)
Block(-7,15,2,CONCRETE:7)
Block(-7,15,3,CONCRETE:7)
Block(-7,15,4,CONCRETE:12)
Block(-7,15,5,CONCRETE:7)
Block(-7,15,6,CONCRETE:7)
Block(-7,15,7,CONCRETE:7)
Block(-7,15,8,CONCRETE:7)
Block(-7,16,-7,OBSIDIAN:0)
Block(-7,16,-6,OBSIDIAN:0)
Block(-7,16,-5,OBSIDIAN:0)
Block(-7,16,-4,OBSIDIAN:0)
Block(-7,16,-3,OBSIDIAN:0)
Block(-7,16,-2,OBSIDIAN:0)
Block(-7,16,-1,OBSIDIAN:0)
Block(-7,16,0,OBSIDIAN:0)
Block(-7,16,1,OBSIDIAN:0)
Block(-7,16,2,OBSIDIAN:0)
Block(-7,16,3,OBSIDIAN:0)
Block(-7,16,4,OBSIDIAN:0)
Block(-7,16,5,OBSIDIAN:0)
Block(-7,16,6,OBSIDIAN:0)
Block(-7,16,7,OBSIDIAN:0)
Block(-7,16,8,OBSIDIAN:0)
Block(-7,17,-7,CONCRETE:7)
Block(-7,17,-6,CONCRETE:7)
Block(-7,17,-5,CONCRETE:7)
Block(-7,17,-4,CONCRETE:7)
Block(-7,17,-3,CONCRETE:7)
Block(-7,17,-2,CONCRETE:7)
Block(-7,17,-1,CONCRETE:7)
Block(-7,17,0,CONCRETE:7)
Block(-7,17,1,CONCRETE:7)
Block(-7,17,2,CONCRETE:7)
Block(-7,17,3,CONCRETE:7)
Block(-7,17,4,CONCRETE:7)
Block(-7,17,5,CONCRETE:7)
Block(-7,17,6,CONCRETE:7)
Block(-7,17,7,CONCRETE:7)
Block(-7,17,8,CONCRETE:7)
Block(-7,18,-7,CONCRETE:7)
Block(-7,18,-6,CONCRETE:7)
Block(-7,18,-5,CONCRETE:7)
Block(-7,18,-4,CONCRETE:7)
Block(-7,18,-3,CONCRETE:7)
Block(-7,18,-2,CONCRETE:7)
Block(-7,18,-1,CONCRETE:7)
Block(-7,18,0,CONCRETE:7)
Block(-7,18,1,CONCRETE:7)
Block(-7,18,2,CONCRETE:7)
Block(-7,18,3,CONCRETE:7)
Block(-7,18,4,CONCRETE:7)
Block(-7,18,5,CONCRETE:7)
Block(-7,18,6,CONCRETE:7)
Block(-7,18,7,CONCRETE:7)
Block(-7,18,8,CONCRETE:7)
Block(-7,19,-7,CONCRETE:7)
Block(-7,19,-6,CONCRETE:7)
Block(-7,19,-5,CONCRETE:7)
Block(-7,19,-4,CONCRETE:7)
Block(-7,19,-3,CONCRETE:7)
Block(-7,19,-2,CONCRETE:7)
Block(-7,19,-1,CONCRETE:7)
Block(-7,19,0,CONCRETE:7)
Block(-7,19,1,CONCRETE:7)
Block(-7,19,2,CONCRETE:7)
Block(-7,19,3,CONCRETE:7)
Block(-7,19,4,CONCRETE:7)
Block(-7,19,5,CONCRETE:7)
Block(-7,19,6,CONCRETE:7)
Block(-7,19,7,CONCRETE:7)
Block(-7,19,8,CONCRETE:7)
Block(-7,20,-7,CONCRETE:7)
Block(-7,20,-6,CONCRETE:7)
Block(-7,20,-5,CONCRETE:7)
Block(-7,20,-4,CONCRETE:7)
Block(-7,20,-3,CONCRETE:7)
Block(-7,20,-2,CONCRETE:7)
Block(-7,20,-1,CONCRETE:7)
Block(-7,20,0,CONCRETE:7)
Block(-7,20,1,CONCRETE:7)
Block(-7,20,2,CONCRETE:7)
Block(-7,20,3,CONCRETE:7)
Block(-7,20,4,CONCRETE:7)
Block(-7,20,5,CONCRETE:7)
Block(-7,20,6,CONCRETE:7)
Block(-7,20,7,CONCRETE:7)
Block(-7,20,8,CONCRETE:7)
Block(-7,21,-7,CONCRETE:7)
Block(-7,21,-6,CONCRETE:7)
Block(-7,21,-5,CONCRETE:7)
Block(-7,21,-4,CONCRETE:7)
Block(-7,21,-3,CONCRETE:7)
Block(-7,21,-2,CONCRETE:7)
Block(-7,21,-1,CONCRETE:7)
Block(-7,21,0,CONCRETE:7)
Block(-7,21,1,CONCRETE:7)
Block(-7,21,2,CONCRETE:7)
Block(-7,21,3,CONCRETE:7)
Block(-7,21,4,CONCRETE:7)
Block(-7,21,5,CONCRETE:7)
Block(-7,21,6,CONCRETE:7)
Block(-7,21,7,CONCRETE:7)
Block(-7,21,8,CONCRETE:7)
Block(-7,22,-7,CONCRETE:7)
Block(-7,22,-6,CONCRETE:7)
Block(-7,22,-5,CONCRETE:7)
Block(-7,22,-4,CONCRETE:7)
Block(-7,22,-3,CONCRETE:7)
Block(-7,22,-2,CONCRETE:7)
Block(-7,22,-1,CONCRETE:7)
Block(-7,22,0,CONCRETE:12)
Block(-7,22,1,CONCRETE:12)
Block(-7,22,2,CONCRETE:12)
Block(-7,22,3,CONCRETE:12)
Block(-7,22,4,CONCRETE:12)
Block(-7,22,5,CONCRETE:12)
Block(-7,22,6,CONCRETE:12)
Block(-7,22,7,CONCRETE:12)
Block(-7,22,8,CONCRETE:7)
Block(-7,23,-7,OBSIDIAN:0)
Block(-7,23,-6,OBSIDIAN:0)
Block(-7,23,-5,OBSIDIAN:0)
Block(-7,23,-4,OBSIDIAN:0)
Block(-7,23,-3,OBSIDIAN:0)
Block(-7,23,-2,OBSIDIAN:0)
Block(-7,23,-1,OBSIDIAN:0)
Block(-7,23,0,OBSIDIAN:0)
Block(-7,23,1,OBSIDIAN:0)
Block(-7,23,2,OBSIDIAN:0)
Block(-7,23,3,OBSIDIAN:0)
Block(-7,23,4,OBSIDIAN:0)
Block(-7,23,5,OBSIDIAN:0)
Block(-7,23,6,OBSIDIAN:0)
Block(-7,23,7,CONCRETE:12)
Block(-7,23,8,OBSIDIAN:0)
Block(-7,24,-7,CONCRETE:0)
Block(-7,24,-6,CONCRETE:0)
Block(-7,24,-5,CONCRETE:0)
Block(-7,24,-4,CONCRETE:0)
Block(-7,24,-3,CONCRETE:0)
Block(-7,24,-2,CONCRETE:0)
Block(-7,24,-1,CONCRETE:0)
Block(-7,24,0,CONCRETE:0)
Block(-7,24,1,CONCRETE:0)
Block(-7,24,2,CONCRETE:0)
Block(-7,24,3,CONCRETE:0)
Block(-7,24,4,CONCRETE:0)
Block(-7,24,5,CONCRETE:0)
Block(-7,24,6,CONCRETE:0)
Block(-7,24,7,CONCRETE:11)
Block(-7,24,8,CONCRETE:11)
Block(-7,25,-7,CAULDRON:0)
Block(-7,25,-6,CONCRETE:0)
Block(-7,25,-5,CAULDRON:0)
Block(-7,25,-4,CONCRETE:0)
Block(-7,25,-3,CAULDRON:0)
Block(-7,25,-2,CONCRETE:0)
Block(-7,25,-1,CAULDRON:0)
Block(-7,25,0,CONCRETE:0)
Block(-7,25,1,CONCRETE:0)
Block(-7,25,3,CONCRETE:0)
Block(-7,25,6,CONCRETE:0)
Block(-7,25,7,CAULDRON:0)
Block(-7,25,8,CAULDRON:0)
Block(-7,26,-7,TRIPWIRE_HOOK:3)
Block(-7,26,-6,WALL_BANNER:5,NBT/skyscraper_8x6_01/477-bannerC64R48.nbt)
Block(-7,26,-5,TRIPWIRE_HOOK:3)
Block(-7,26,-4,WALL_BANNER:5,NBT/skyscraper_8x6_01/478-bannerC64R48.nbt)
Block(-7,26,-3,TRIPWIRE_HOOK:3)
Block(-7,26,-2,WALL_BANNER:5,NBT/skyscraper_8x6_01/479-bannerC64R48.nbt)
Block(-7,26,-1,TRIPWIRE_HOOK:3)
Block(-7,26,0,CONCRETE:0)
Block(-7,26,1,CONCRETE:0)
Block(-7,26,3,CONCRETE:0)
Block(-7,26,4,WALL_BANNER:3,NBT/skyscraper_8x6_01/480-bannerC64R48.nbt)
Block(-7,26,6,CONCRETE:0)
Block(-7,26,7,TRIPWIRE_HOOK:3)
Block(-7,26,8,TRIPWIRE_HOOK:3)
Block(-7,27,-7,CONCRETE:0)
Block(-7,27,-6,CONCRETE:0)
Block(-7,27,-5,CONCRETE:0)
Block(-7,27,-4,CONCRETE:0)
Block(-7,27,-3,CONCRETE:0)
Block(-7,27,-2,CONCRETE:0)
Block(-7,27,-1,CONCRETE:0)
Block(-7,27,0,CONCRETE:0)
Block(-7,27,1,CONCRETE:0)
Block(-7,27,2,CONCRETE:0)
Block(-7,27,3,CONCRETE:15)
Block(-7,27,4,STONE:4)
Block(-7,27,5,CONCRETE:0)
Block(-7,27,6,STONE:4)
Block(-7,27,7,CONCRETE:0)
Block(-7,27,8,CONCRETE:15)
Block(-7,28,-7,GRASS:0)
Block(-7,28,-6,TRAP_DOOR:5)
Block(-7,28,-4,TRAP_DOOR:4)
Block(-7,28,-3,GRASS:0)
Block(-7,28,-2,GRASS:0)
Block(-7,28,-1,GRASS:0)
Block(-7,28,0,TRAP_DOOR:5)
Block(-7,28,1,CONCRETE:0)
Block(-7,28,2,STAINED_GLASS_PANE:15)
Block(-7,28,3,STAINED_GLASS_PANE:0)
Block(-7,29,-7,DOUBLE_PLANT:1)
Block(-7,29,-3,RED_ROSE:0)
Block(-7,29,-2,FENCE:0)
Block(-7,29,-1,RED_ROSE:0)
Block(-7,29,1,STONE:4)
Block(-7,29,2,STAINED_GLASS_PANE:15)
Block(-7,29,3,STAINED_GLASS_PANE:0)
Block(-7,30,-7,DOUBLE_PLANT:10)
Block(-7,30,-2,LEAVES:12)
Block(-7,30,1,STONE:4)
Block(-7,30,2,STAINED_GLASS_PANE:15)
Block(-7,30,3,STAINED_GLASS_PANE:0)
Block(-7,31,-2,LEAVES:12)
Block(-7,31,1,CONCRETE:0)
Block(-7,31,2,STAINED_GLASS_PANE:15)
Block(-7,31,3,STAINED_GLASS_PANE:0)
Block(-7,32,1,CONCRETE:0)
Block(-7,33,1,CONCRETE:0)
Block(-7,34,1,CONCRETE:0)
Block(-7,35,1,CONCRETE:0)
Block(-7,36,1,CONCRETE:0)
Block(-7,37,1,CONCRETE:0)
Block(-7,38,1,CONCRETE:0)
Block(-7,39,1,CONCRETE:0)
Block(-7,40,1,CONCRETE:0)
Block(-7,41,1,CONCRETE:0)
Block(-7,42,-4,LEAVES:4)
Block(-7,42,1,QUARTZ_STAIRS:2)
Block(-7,42,2,CONCRETE:0)
Block(-7,43,-4,LEAVES:4)
Block(-7,43,2,CONCRETE:0)
Block(-7,44,-4,LEAVES:4)
Block(-7,44,2,CONCRETE:0)
Block(-7,45,-4,LEAVES:4)
Block(-7,45,2,CONCRETE:0)
Block(-7,46,-6,LEAVES:4)
Block(-7,46,-4,LEAVES:12)
Block(-7,46,2,QUARTZ_STAIRS:2)
Block(-7,46,3,CONCRETE:0)
Block(-7,47,-6,LEAVES:4)
Block(-7,47,-5,IRON_TRAPDOOR:10)
Block(-7,47,-4,LEAVES:12)
Block(-7,47,3,CONCRETE:0)
Block(-7,48,-6,LEAVES:4)
Block(-7,48,-5,SEA_LANTERN:0)
Block(-7,48,-4,LEAVES:12)
Block(-7,48,-2,STEP:8)
Block(-7,48,3,QUARTZ_STAIRS:2)
Block(-7,48,4,CONCRETE:0)
Block(-7,49,-7,TRAP_DOOR:6)
Block(-7,49,-6,LEAVES:12)
Block(-7,49,-5,GRASS:0)
Block(-7,49,-4,LEAVES:12)
Block(-7,49,-3,TRAP_DOOR:6)
Block(-7,49,-2,CONCRETE:7)
Block(-7,49,-1,LEVER:3)
Block(-7,49,4,QUARTZ_STAIRS:2)
Block(-7,49,5,CONCRETE:0)
Block(-7,50,-6,LEAVES:12)
Block(-7,50,-5,DOUBLE_PLANT:2)
Block(-7,50,-2,IRON_FENCE:0)
Block(-7,50,-1,IRON_FENCE:0)
Block(-7,50,5,QUARTZ_STAIRS:2)
Block(-7,50,6,CONCRETE:0)
Block(-7,51,-5,DOUBLE_PLANT:10)
Block(-7,51,-1,IRON_FENCE:0)
Block(-7,51,6,STEP:7)
Block(-7,51,7,CONCRETE:0)
Block(-7,51,8,CONCRETE:7)
Block(-7,52,-1,IRON_FENCE:0)
Block(-7,52,8,CONCRETE:7)
Block(-7,53,-1,IRON_FENCE:0)
Block(-7,53,8,CONCRETE:0)
Block(-7,54,-5,TRAP_DOOR:6)
Block(-7,54,-4,STEP:8)
Block(-7,54,-1,IRON_FENCE:0)
Block(-7,54,7,CONCRETE:7)
Block(-7,55,-4,CONCRETE:7)
Block(-7,55,-3,LEVER:3)
Block(-7,55,-1,IRON_FENCE:0)
Block(-7,55,7,CONCRETE:7)
Block(-7,56,-3,IRON_FENCE:0)
Block(-7,56,-1,IRON_FENCE:0)
Block(-7,56,6,CONCRETE:7)
Block(-7,57,-3,IRON_FENCE:0)
Block(-7,57,-1,IRON_FENCE:0)
Block(-7,57,5,QUARTZ_STAIRS:6)
Block(-7,57,6,CONCRETE:7)
Block(-7,58,-3,IRON_FENCE:0)
Block(-7,58,-1,IRON_FENCE:0)
Block(-7,58,5,CONCRETE:7)
Block(-7,59,-3,IRON_FENCE:0)
Block(-7,59,-1,IRON_FENCE:0)
Block(-7,59,3,QUARTZ_STAIRS:6)
Block(-7,59,4,CONCRETE:7)
Block(-7,60,-3,IRON_FENCE:0)
Block(-7,60,-1,IRON_FENCE:0)
Block(-7,60,2,CONCRETE:7)
Block(-7,60,3,CONCRETE:7)
Block(-7,61,-3,IRON_FENCE:0)
Block(-7,61,-1,DOUBLE_STEP:7)
Block(-7,61,0,CONCRETE:0)
Block(-7,61,1,CONCRETE:0)
Block(-7,62,-3,CONCRETE:7)
Block(-7,62,-2,CONCRETE:7)
Block(-7,62,-1,CONCRETE:7)
Block(-7,63,-7,CONCRETE:7)
Block(-7,63,-6,CONCRETE:7)
Block(-7,63,-5,CONCRETE:7)
Block(-7,63,-4,CONCRETE:7)
Block(-6,0,-7,CONCRETE:7)
Block(-6,0,-6,CONCRETE:7)
Block(-6,0,-5,CONCRETE:7)
Block(-6,0,-4,CONCRETE:7)
Block(-6,0,-3,CONCRETE:7)
Block(-6,0,-2,CONCRETE:7)
Block(-6,0,-1,CONCRETE:7)
Block(-6,0,0,CONCRETE:7)
Block(-6,0,1,CONCRETE:7)
Block(-6,0,2,CONCRETE:7)
Block(-6,0,3,CONCRETE:7)
Block(-6,0,4,CONCRETE:7)
Block(-6,0,5,CONCRETE:7)
Block(-6,0,6,CONCRETE:7)
Block(-6,0,7,CONCRETE:7)
Block(-6,0,8,CONCRETE:7)
Block(-6,1,-7,OBSIDIAN:0)
Block(-6,1,-6,OBSIDIAN:0)
Block(-6,1,-5,OBSIDIAN:0)
Block(-6,1,-4,OBSIDIAN:0)
Block(-6,1,-3,OBSIDIAN:0)
Block(-6,1,-2,OBSIDIAN:0)
Block(-6,1,-1,OBSIDIAN:0)
Block(-6,1,0,OBSIDIAN:0)
Block(-6,1,1,OBSIDIAN:0)
Block(-6,1,2,OBSIDIAN:0)
Block(-6,1,3,OBSIDIAN:0)
Block(-6,1,4,OBSIDIAN:0)
Block(-6,1,5,OBSIDIAN:0)
Block(-6,1,6,OBSIDIAN:0)
Block(-6,1,7,OBSIDIAN:0)
Block(-6,1,8,OBSIDIAN:0)
Block(-6,2,-7,OBSIDIAN:0)
Block(-6,2,-6,OBSIDIAN:0)
Block(-6,2,-5,OBSIDIAN:0)
Block(-6,2,-4,OBSIDIAN:0)
Block(-6,2,-3,OBSIDIAN:0)
Block(-6,2,-2,OBSIDIAN:0)
Block(-6,2,-1,OBSIDIAN:0)
Block(-6,2,0,OBSIDIAN:0)
Block(-6,2,1,OBSIDIAN:0)
Block(-6,2,2,CONCRETE:7)
Block(-6,2,3,CONCRETE:7)
Block(-6,2,4,CONCRETE:7)
Block(-6,2,5,CONCRETE:7)
Block(-6,2,6,CONCRETE:7)
Block(-6,2,7,CONCRETE:7)
Block(-6,2,8,CONCRETE:7)
Block(-6,3,-7,STATIONARY_LAVA:0)
Block(-6,3,-6,STATIONARY_LAVA:0)
Block(-6,3,-5,STATIONARY_LAVA:0)
Block(-6,3,-4,STATIONARY_LAVA:0)
Block(-6,3,-3,STATIONARY_LAVA:0)
Block(-6,3,-2,STATIONARY_LAVA:0)
Block(-6,3,-1,OBSIDIAN:0)
Block(-6,3,0,OBSIDIAN:0)
Block(-6,3,1,OBSIDIAN:0)
Block(-6,3,2,CONCRETE:7)
Block(-6,3,3,CONCRETE:7)
Block(-6,3,4,CONCRETE:7)
Block(-6,3,5,CONCRETE:7)
Block(-6,3,6,CONCRETE:7)
Block(-6,3,7,CONCRETE:7)
Block(-6,3,8,CONCRETE:7)
Block(-6,4,-7,OBSIDIAN:0)
Block(-6,4,-6,OBSIDIAN:0)
Block(-6,4,-5,OBSIDIAN:0)
Block(-6,4,-4,OBSIDIAN:0)
Block(-6,4,-3,OBSIDIAN:0)
Block(-6,4,-2,STATIONARY_LAVA:0)
Block(-6,4,-1,OBSIDIAN:0)
Block(-6,4,0,OBSIDIAN:0)
Block(-6,4,1,OBSIDIAN:0)
Block(-6,4,2,CONCRETE:7)
Block(-6,4,3,CONCRETE:7)
Block(-6,4,4,CONCRETE:7)
Block(-6,4,5,CONCRETE:7)
Block(-6,4,6,CONCRETE:7)
Block(-6,4,7,CONCRETE:7)
Block(-6,4,8,CONCRETE:7)
Block(-6,5,-7,IRON_PLATE:0)
Block(-6,5,-6,IRON_PLATE:0)
Block(-6,5,-5,OBSIDIAN:0)
Block(-6,5,-4,STATIONARY_LAVA:0)
Block(-6,5,-3,OBSIDIAN:0)
Block(-6,5,-2,STATIONARY_LAVA:0)
Block(-6,5,-1,OBSIDIAN:0)
Block(-6,5,0,OBSIDIAN:0)
Block(-6,5,1,OBSIDIAN:0)
Block(-6,5,2,CONCRETE:7)
Block(-6,5,3,CONCRETE:7)
Block(-6,5,4,OBSIDIAN:0)
Block(-6,5,5,OBSIDIAN:0)
Block(-6,5,6,OBSIDIAN:0)
Block(-6,5,7,CONCRETE:7)
Block(-6,5,8,OBSIDIAN:0)
Block(-6,6,-7,AIR:0)
Block(-6,6,-6,AIR:0)
Block(-6,6,-5,OBSIDIAN:0)
Block(-6,6,-4,STATIONARY_LAVA:0)
Block(-6,6,-3,OBSIDIAN:0)
Block(-6,6,-2,STATIONARY_LAVA:0)
Block(-6,6,-1,OBSIDIAN:0)
Block(-6,6,0,OBSIDIAN:0)
Block(-6,6,1,OBSIDIAN:0)
Block(-6,6,2,CONCRETE:7)
Block(-6,6,3,CONCRETE:7)
Block(-6,6,4,OBSIDIAN:0)
Block(-6,6,5,OBSIDIAN:0)
Block(-6,6,6,OBSIDIAN:0)
Block(-6,6,7,CONCRETE:7)
Block(-6,6,8,OBSIDIAN:0)
Block(-6,7,-7,AIR:0)
Block(-6,7,-6,AIR:0)
Block(-6,7,-5,OBSIDIAN:0)
Block(-6,7,-4,STATIONARY_LAVA:0)
Block(-6,7,-3,OBSIDIAN:0)
Block(-6,7,-2,STATIONARY_LAVA:0)
Block(-6,7,-1,OBSIDIAN:0)
Block(-6,7,0,OBSIDIAN:0)
Block(-6,7,1,OBSIDIAN:0)
Block(-6,7,2,CONCRETE:7)
Block(-6,7,3,CONCRETE:7)
Block(-6,7,4,OBSIDIAN:0)
Block(-6,7,5,OBSIDIAN:0)
Block(-6,7,6,OBSIDIAN:0)
Block(-6,7,7,CONCRETE:7)
Block(-6,7,8,OBSIDIAN:0)
Block(-6,8,-7,AIR:0)
Block(-6,8,-6,AIR:0)
Block(-6,8,-5,OBSIDIAN:0)
Block(-6,8,-4,STATIONARY_LAVA:0)
Block(-6,8,-3,OBSIDIAN:0)
Block(-6,8,-2,STATIONARY_LAVA:0)
Block(-6,8,-1,OBSIDIAN:0)
Block(-6,8,0,OBSIDIAN:0)
Block(-6,8,1,OBSIDIAN:0)
Block(-6,8,2,CONCRETE:7)
Block(-6,8,3,CONCRETE:7)
Block(-6,8,4,CONCRETE:7)
Block(-6,8,5,CONCRETE:7)
Block(-6,8,6,CONCRETE:7)
Block(-6,8,7,CONCRETE:7)
Block(-6,8,8,CONCRETE:7)
Block(-6,9,-7,AIR:0)
Block(-6,9,-6,AIR:0)
Block(-6,9,-5,OBSIDIAN:0)
Block(-6,9,-4,STATIONARY_LAVA:0)
Block(-6,9,-3,OBSIDIAN:0)
Block(-6,9,-2,STATIONARY_LAVA:0)
Block(-6,9,-1,OBSIDIAN:0)
Block(-6,9,0,OBSIDIAN:0)
Block(-6,9,1,OBSIDIAN:0)
Block(-6,9,2,CONCRETE:7)
Block(-6,9,3,CONCRETE:7)
Block(-6,9,4,OBSIDIAN:0)
Block(-6,9,5,OBSIDIAN:0)
Block(-6,9,6,OBSIDIAN:0)
Block(-6,9,7,CONCRETE:7)
Block(-6,9,8,OBSIDIAN:0)
Block(-6,10,-7,STEP:8)
Block(-6,10,-6,STEP:8)
Block(-6,10,-5,OBSIDIAN:0)
Block(-6,10,-4,STATIONARY_LAVA:0)
Block(-6,10,-3,OBSIDIAN:0)
Block(-6,10,-2,STATIONARY_LAVA:0)
Block(-6,10,-1,OBSIDIAN:0)
Block(-6,10,0,OBSIDIAN:0)
Block(-6,10,1,OBSIDIAN:0)
Block(-6,10,2,CONCRETE:7)
Block(-6,10,3,CONCRETE:7)
Block(-6,10,4,OBSIDIAN:0)
Block(-6,10,5,OBSIDIAN:0)
Block(-6,10,6,OBSIDIAN:0)
Block(-6,10,7,CONCRETE:7)
Block(-6,10,8,OBSIDIAN:0)
Block(-6,11,-7,OBSIDIAN:0)
Block(-6,11,-6,OBSIDIAN:0)
Block(-6,11,-5,OBSIDIAN:0)
Block(-6,11,-4,OBSIDIAN:0)
Block(-6,11,-3,OBSIDIAN:0)
Block(-6,11,-2,STATIONARY_LAVA:0)
Block(-6,11,-1,OBSIDIAN:0)
Block(-6,11,0,OBSIDIAN:0)
Block(-6,11,1,OBSIDIAN:0)
Block(-6,11,2,CONCRETE:7)
Block(-6,11,3,CONCRETE:7)
Block(-6,11,4,OBSIDIAN:0)
Block(-6,11,5,OBSIDIAN:0)
Block(-6,11,6,OBSIDIAN:0)
Block(-6,11,7,CONCRETE:7)
Block(-6,11,8,OBSIDIAN:0)
Block(-6,12,-7,STATIONARY_LAVA:0)
Block(-6,12,-6,STATIONARY_LAVA:0)
Block(-6,12,-5,STATIONARY_LAVA:0)
Block(-6,12,-4,STATIONARY_LAVA:0)
Block(-6,12,-3,STATIONARY_LAVA:0)
Block(-6,12,-2,STATIONARY_LAVA:0)
Block(-6,12,-1,OBSIDIAN:0)
Block(-6,12,0,OBSIDIAN:0)
Block(-6,12,1,OBSIDIAN:0)
Block(-6,12,2,CONCRETE:7)
Block(-6,12,3,CONCRETE:7)
Block(-6,12,4,CONCRETE:7)
Block(-6,12,5,CONCRETE:7)
Block(-6,12,6,CONCRETE:7)
Block(-6,12,7,CONCRETE:7)
Block(-6,12,8,CONCRETE:7)
Block(-6,13,-7,OBSIDIAN:0)
Block(-6,13,-6,OBSIDIAN:0)
Block(-6,13,-5,OBSIDIAN:0)
Block(-6,13,-4,OBSIDIAN:0)
Block(-6,13,-3,OBSIDIAN:0)
Block(-6,13,-2,OBSIDIAN:0)
Block(-6,13,-1,OBSIDIAN:0)
Block(-6,13,0,OBSIDIAN:0)
Block(-6,13,1,OBSIDIAN:0)
Block(-6,13,2,CONCRETE:7)
Block(-6,13,3,CONCRETE:7)
Block(-6,13,4,OBSIDIAN:0)
Block(-6,13,5,OBSIDIAN:0)
Block(-6,13,6,OBSIDIAN:0)
Block(-6,13,7,CONCRETE:7)
Block(-6,13,8,OBSIDIAN:0)
Block(-6,14,-7,OBSIDIAN:0)
Block(-6,14,-6,OBSIDIAN:0)
Block(-6,14,-5,OBSIDIAN:0)
Block(-6,14,-4,OBSIDIAN:0)
Block(-6,14,-3,OBSIDIAN:0)
Block(-6,14,-2,OBSIDIAN:0)
Block(-6,14,-1,OBSIDIAN:0)
Block(-6,14,0,OBSIDIAN:0)
Block(-6,14,1,OBSIDIAN:0)
Block(-6,14,2,CONCRETE:7)
Block(-6,14,3,CONCRETE:7)
Block(-6,14,4,OBSIDIAN:0)
Block(-6,14,5,OBSIDIAN:0)
Block(-6,14,6,OBSIDIAN:0)
Block(-6,14,7,CONCRETE:7)
Block(-6,14,8,OBSIDIAN:0)
Block(-6,15,-7,OBSIDIAN:0)
Block(-6,15,-6,OBSIDIAN:0)
Block(-6,15,-5,OBSIDIAN:0)
Block(-6,15,-4,OBSIDIAN:0)
Block(-6,15,-3,OBSIDIAN:0)
Block(-6,15,-2,OBSIDIAN:0)
Block(-6,15,-1,OBSIDIAN:0)
Block(-6,15,0,OBSIDIAN:0)
Block(-6,15,1,OBSIDIAN:0)
Block(-6,15,2,CONCRETE:7)
Block(-6,15,3,CONCRETE:7)
Block(-6,15,4,CONCRETE:12)
Block(-6,15,5,CONCRETE:7)
Block(-6,15,6,CONCRETE:7)
Block(-6,15,7,CONCRETE:7)
Block(-6,15,8,CONCRETE:7)
Block(-6,16,-7,OBSIDIAN:0)
Block(-6,16,-6,OBSIDIAN:0)
Block(-6,16,-5,OBSIDIAN:0)
Block(-6,16,-4,OBSIDIAN:0)
Block(-6,16,-3,OBSIDIAN:0)
Block(-6,16,-2,OBSIDIAN:0)
Block(-6,16,-1,OBSIDIAN:0)
Block(-6,16,0,OBSIDIAN:0)
Block(-6,16,1,OBSIDIAN:0)
Block(-6,16,2,OBSIDIAN:0)
Block(-6,16,3,OBSIDIAN:0)
Block(-6,16,4,OBSIDIAN:0)
Block(-6,16,5,OBSIDIAN:0)
Block(-6,16,6,OBSIDIAN:0)
Block(-6,16,7,OBSIDIAN:0)
Block(-6,16,8,OBSIDIAN:0)
Block(-6,17,-7,CONCRETE:7)
Block(-6,17,-6,CONCRETE:7)
Block(-6,17,-5,CONCRETE:7)
Block(-6,17,-4,CONCRETE:7)
Block(-6,17,-3,CONCRETE:7)
Block(-6,17,-2,CONCRETE:7)
Block(-6,17,-1,CONCRETE:7)
Block(-6,17,0,CONCRETE:7)
Block(-6,17,1,CONCRETE:7)
Block(-6,17,2,CONCRETE:7)
Block(-6,17,3,CONCRETE:7)
Block(-6,17,4,CONCRETE:7)
Block(-6,17,5,CONCRETE:7)
Block(-6,17,6,CONCRETE:7)
Block(-6,17,7,CONCRETE:7)
Block(-6,17,8,CONCRETE:7)
Block(-6,18,-7,CONCRETE:7)
Block(-6,18,-6,CONCRETE:7)
Block(-6,18,-5,CONCRETE:7)
Block(-6,18,-4,CONCRETE:7)
Block(-6,18,-3,CONCRETE:7)
Block(-6,18,-2,CONCRETE:7)
Block(-6,18,-1,CONCRETE:7)
Block(-6,18,0,CONCRETE:7)
Block(-6,18,1,CONCRETE:7)
Block(-6,18,2,CONCRETE:7)
Block(-6,18,3,CONCRETE:7)
Block(-6,18,4,OBSIDIAN:0)
Block(-6,18,5,OBSIDIAN:0)
Block(-6,18,6,OBSIDIAN:0)
Block(-6,18,7,OBSIDIAN:0)
Block(-6,18,8,OBSIDIAN:0)
Block(-6,19,-7,CONCRETE:7)
Block(-6,19,-6,CONCRETE:7)
Block(-6,19,-5,CONCRETE:7)
Block(-6,19,-4,CONCRETE:7)
Block(-6,19,-3,CONCRETE:7)
Block(-6,19,-2,CONCRETE:7)
Block(-6,19,-1,CONCRETE:7)
Block(-6,19,0,CONCRETE:7)
Block(-6,19,1,CONCRETE:7)
Block(-6,19,2,CONCRETE:7)
Block(-6,19,3,CONCRETE:7)
Block(-6,19,4,OBSIDIAN:0)
Block(-6,19,5,OBSIDIAN:0)
Block(-6,19,6,OBSIDIAN:0)
Block(-6,19,7,OBSIDIAN:0)
Block(-6,19,8,OBSIDIAN:0)
Block(-6,20,-7,CONCRETE:7)
Block(-6,20,-6,CONCRETE:7)
Block(-6,20,-5,CONCRETE:7)
Block(-6,20,-4,CONCRETE:7)
Block(-6,20,-3,CONCRETE:7)
Block(-6,20,-2,CONCRETE:7)
Block(-6,20,-1,CONCRETE:7)
Block(-6,20,0,CONCRETE:7)
Block(-6,20,1,CONCRETE:7)
Block(-6,20,2,CONCRETE:7)
Block(-6,20,3,CONCRETE:7)
Block(-6,20,4,OBSIDIAN:0)
Block(-6,20,5,OBSIDIAN:0)
Block(-6,20,6,OBSIDIAN:0)
Block(-6,20,7,OBSIDIAN:0)
Block(-6,20,8,OBSIDIAN:0)
Block(-6,21,-7,CONCRETE:7)
Block(-6,21,-6,CONCRETE:7)
Block(-6,21,-5,CONCRETE:7)
Block(-6,21,-4,CONCRETE:7)
Block(-6,21,-3,CONCRETE:7)
Block(-6,21,-2,CONCRETE:7)
Block(-6,21,-1,CONCRETE:7)
Block(-6,21,0,CONCRETE:7)
Block(-6,21,1,CONCRETE:7)
Block(-6,21,2,CONCRETE:7)
Block(-6,21,3,CONCRETE:7)
Block(-6,21,4,OBSIDIAN:0)
Block(-6,21,5,OBSIDIAN:0)
Block(-6,21,6,OBSIDIAN:0)
Block(-6,21,7,OBSIDIAN:0)
Block(-6,21,8,OBSIDIAN:0)
Block(-6,22,-7,CONCRETE:7)
Block(-6,22,-6,CONCRETE:7)
Block(-6,22,-5,CONCRETE:7)
Block(-6,22,-4,CONCRETE:7)
Block(-6,22,-3,CONCRETE:7)
Block(-6,22,-2,CONCRETE:7)
Block(-6,22,-1,CONCRETE:7)
Block(-6,22,0,CONCRETE:12)
Block(-6,22,1,CONCRETE:7)
Block(-6,22,2,CONCRETE:7)
Block(-6,22,3,CONCRETE:7)
Block(-6,22,4,OBSIDIAN:0)
Block(-6,22,5,OBSIDIAN:0)
Block(-6,22,6,OBSIDIAN:0)
Block(-6,22,7,OBSIDIAN:0)
Block(-6,22,8,OBSIDIAN:0)
Block(-6,23,-7,OBSIDIAN:0)
Block(-6,23,-6,OBSIDIAN:0)
Block(-6,23,-5,OBSIDIAN:0)
Block(-6,23,-4,OBSIDIAN:0)
Block(-6,23,-3,OBSIDIAN:0)
Block(-6,23,-2,OBSIDIAN:0)
Block(-6,23,-1,OBSIDIAN:0)
Block(-6,23,0,OBSIDIAN:0)
Block(-6,23,1,OBSIDIAN:0)
Block(-6,23,2,OBSIDIAN:0)
Block(-6,23,3,OBSIDIAN:0)
Block(-6,23,4,OBSIDIAN:0)
Block(-6,23,5,OBSIDIAN:0)
Block(-6,23,6,OBSIDIAN:0)
Block(-6,23,7,CONCRETE:12)
Block(-6,23,8,OBSIDIAN:0)
Block(-6,24,-7,CONCRETE:0)
Block(-6,24,-6,CONCRETE:0)
Block(-6,24,-5,CONCRETE:0)
Block(-6,24,-4,CONCRETE:0)
Block(-6,24,-3,CONCRETE:0)
Block(-6,24,-2,CONCRETE:0)
Block(-6,24,-1,CONCRETE:0)
Block(-6,24,0,CONCRETE:0)
Block(-6,24,1,CONCRETE:0)
Block(-6,24,2,CONCRETE:0)
Block(-6,24,3,CONCRETE:0)
Block(-6,24,4,CONCRETE:0)
Block(-6,24,5,CONCRETE:0)
Block(-6,24,6,CONCRETE:0)
Block(-6,24,7,CONCRETE:0)
Block(-6,24,8,CONCRETE:0)
Block(-6,25,1,CONCRETE:0)
Block(-6,25,3,CONCRETE:0)
Block(-6,26,0,WALL_BANNER:2,NBT/skyscraper_8x6_01/487-bannerC64R48.nbt)
Block(-6,26,1,CONCRETE:0)
Block(-6,26,3,CONCRETE:0)
Block(-6,26,4,WALL_BANNER:3,NBT/skyscraper_8x6_01/488-bannerC64R48.nbt)
Block(-6,26,6,WALL_BANNER:5,NBT/skyscraper_8x6_01/489-bannerC64R48.nbt)
Block(-6,27,-7,STEP:8)
Block(-6,27,-6,STEP:8)
Block(-6,27,-5,STEP:8)
Block(-6,27,-4,STEP:8)
Block(-6,27,-3,STEP:8)
Block(-6,27,-2,STEP:8)
Block(-6,27,-1,STEP:8)
Block(-6,27,0,CONCRETE:0)
Block(-6,27,1,CONCRETE:0)
Block(-6,27,2,CONCRETE:0)
Block(-6,27,3,CONCRETE:0)
Block(-6,27,4,CONCRETE:15)
Block(-6,27,5,CONCRETE:0)
Block(-6,27,6,CONCRETE:0)
Block(-6,27,7,CONCRETE:15)
Block(-6,27,8,CONCRETE:0)
Block(-6,28,-7,CONCRETE:7)
Block(-6,28,-3,CONCRETE:7)
Block(-6,28,-2,CONCRETE:7)
Block(-6,28,-1,CONCRETE:7)
Block(-6,28,1,STAINED_GLASS_PANE:15)
Block(-6,29,-7,STAINED_GLASS_PANE:15)
Block(-6,29,-3,STAINED_GLASS_PANE:15)
Block(-6,29,-2,CONCRETE:7)
Block(-6,29,-1,STAINED_GLASS_PANE:15)
Block(-6,29,1,STAINED_GLASS_PANE:15)
Block(-6,30,-2,STEP:0)
Block(-6,30,1,STAINED_GLASS_PANE:15)
Block(-6,31,1,STAINED_GLASS_PANE:15)
Block(-6,32,1,STAINED_GLASS_PANE:15)
Block(-6,33,1,STAINED_GLASS_PANE:15)
Block(-6,34,1,STAINED_GLASS_PANE:15)
Block(-6,35,1,STAINED_GLASS_PANE:15)
Block(-6,36,1,STAINED_GLASS_PANE:15)
Block(-6,36,2,QUARTZ_STAIRS:6)
Block(-6,37,1,STEP:7)
Block(-6,37,2,CONCRETE:0)
Block(-6,38,2,CONCRETE:0)
Block(-6,39,2,CONCRETE:0)
Block(-6,40,2,CONCRETE:0)
Block(-6,41,2,CONCRETE:0)
Block(-6,42,2,CONCRETE:0)
Block(-6,43,2,CONCRETE:0)
Block(-6,44,2,QUARTZ_STAIRS:2)
Block(-6,44,3,CONCRETE:0)
Block(-6,45,3,CONCRETE:0)
Block(-6,46,3,CONCRETE:0)
Block(-6,47,-7,IRON_TRAPDOOR:10)
Block(-6,47,-6,IRON_TRAPDOOR:10)
Block(-6,47,-5,IRON_TRAPDOOR:10)
Block(-6,47,-4,IRON_TRAPDOOR:10)
Block(-6,47,3,STEP:7)
Block(-6,47,4,CONCRETE:0)
Block(-6,48,-7,SEA_LANTERN:0)
Block(-6,48,-6,SEA_LANTERN:0)
Block(-6,48,-5,SEA_LANTERN:0)
Block(-6,48,-4,SEA_LANTERN:0)
Block(-6,48,-3,QUARTZ_STAIRS:7)
Block(-6,48,4,QUARTZ_STAIRS:2)
Block(-6,48,5,CONCRETE:0)
Block(-6,49,-7,GRASS:0)
Block(-6,49,-6,GRASS:0)
Block(-6,49,-5,GRASS:0)
Block(-6,49,-4,GRASS:0)
Block(-6,49,-3,GRASS:0)
Block(-6,49,-2,CONCRETE:7)
Block(-6,49,5,CONCRETE:0)
Block(-6,49,6,CONCRETE:0)
Block(-6,50,-7,LEAVES:12)
Block(-6,50,-6,LEAVES:12)
Block(-6,50,-5,LEAVES:12)
Block(-6,50,-4,LEAVES:12)
Block(-6,50,-3,LEAVES:12)
Block(-6,50,-2,IRON_FENCE:0)
Block(-6,50,6,CONCRETE:0)
Block(-6,50,7,CONCRETE:0)
Block(-6,51,7,CONCRETE:0)
Block(-6,51,8,CONCRETE:7)
Block(-6,52,8,CONCRETE:7)
Block(-6,53,-5,IRON_TRAPDOOR:11)
Block(-6,53,8,CONCRETE:0)
Block(-6,54,-7,TRAP_DOOR:6)
Block(-6,54,-6,TRAP_DOOR:4)
Block(-6,54,-5,SEA_LANTERN:0)
Block(-6,54,-4,TRAP_DOOR:5)
Block(-6,54,7,CONCRETE:7)
Block(-6,55,-5,CONCRETE:7)
Block(-6,55,-4,STEP:8)
Block(-6,55,7,CONCRETE:7)
Block(-6,56,-4,COBBLE_WALL:0)
Block(-6,56,6,CONCRETE:7)
Block(-6,57,-4,IRON_FENCE:0)
Block(-6,57,5,CONCRETE:7)
Block(-6,58,-4,IRON_FENCE:0)
Block(-6,58,4,QUARTZ_STAIRS:6)
Block(-6,58,5,CONCRETE:7)
Block(-6,59,-4,IRON_FENCE:0)
Block(-6,59,3,CONCRETE:7)
Block(-6,59,4,CONCRETE:7)
Block(-6,60,-4,IRON_FENCE:0)
Block(-6,60,0,QUARTZ_STAIRS:4)
Block(-6,60,2,CONCRETE:7)
Block(-6,61,-4,IRON_FENCE:0)
Block(-6,61,-1,STEP:15)
Block(-6,61,0,CONCRETE:0)
Block(-6,61,1,CONCRETE:0)
Block(-6,62,-4,CONCRETE:0)
Block(-6,62,-3,CONCRETE:7)
Block(-6,62,-2,CONCRETE:7)
Block(-6,62,-1,CONCRETE:7)
Block(-6,63,-7,CONCRETE:7)
Block(-6,63,-6,CONCRETE:7)
Block(-6,63,-5,CONCRETE:7)
Block(-6,63,-4,CONCRETE:7)
Block(-5,0,-7,CONCRETE:7)
Block(-5,0,-6,CONCRETE:7)
Block(-5,0,-5,CONCRETE:7)
Block(-5,0,-4,CONCRETE:7)
Block(-5,0,-3,CONCRETE:7)
Block(-5,0,-2,CONCRETE:7)
Block(-5,0,-1,CONCRETE:7)
Block(-5,0,0,CONCRETE:7)
Block(-5,0,1,CONCRETE:7)
Block(-5,0,2,CONCRETE:7)
Block(-5,0,3,CONCRETE:7)
Block(-5,0,4,CONCRETE:7)
Block(-5,0,5,CONCRETE:7)
Block(-5,0,6,CONCRETE:7)
Block(-5,0,7,CONCRETE:7)
Block(-5,0,8,CONCRETE:7)
Block(-5,1,-7,OBSIDIAN:0)
Block(-5,1,-6,OBSIDIAN:0)
Block(-5,1,-5,OBSIDIAN:0)
Block(-5,1,-4,OBSIDIAN:0)
Block(-5,1,-3,OBSIDIAN:0)
Block(-5,1,-2,OBSIDIAN:0)
Block(-5,1,-1,OBSIDIAN:0)
Block(-5,1,0,OBSIDIAN:0)
Block(-5,1,1,OBSIDIAN:0)
Block(-5,1,2,OBSIDIAN:0)
Block(-5,1,3,OBSIDIAN:0)
Block(-5,1,4,OBSIDIAN:0)
Block(-5,1,5,OBSIDIAN:0)
Block(-5,1,6,OBSIDIAN:0)
Block(-5,1,7,OBSIDIAN:0)
Block(-5,1,8,OBSIDIAN:0)
Block(-5,2,-7,OBSIDIAN:0)
Block(-5,2,-6,OBSIDIAN:0)
Block(-5,2,-5,OBSIDIAN:0)
Block(-5,2,-4,OBSIDIAN:0)
Block(-5,2,-3,OBSIDIAN:0)
Block(-5,2,-2,OBSIDIAN:0)
Block(-5,2,-1,OBSIDIAN:0)
Block(-5,2,0,OBSIDIAN:0)
Block(-5,2,1,OBSIDIAN:0)
Block(-5,2,2,CONCRETE:7)
Block(-5,2,3,CONCRETE:7)
Block(-5,2,4,CONCRETE:7)
Block(-5,2,5,CONCRETE:7)
Block(-5,2,6,CONCRETE:7)
Block(-5,2,7,CONCRETE:7)
Block(-5,2,8,CONCRETE:7)
Block(-5,3,-7,STATIONARY_LAVA:0)
Block(-5,3,-6,STATIONARY_LAVA:0)
Block(-5,3,-5,STATIONARY_LAVA:0)
Block(-5,3,-4,STATIONARY_LAVA:0)
Block(-5,3,-3,STATIONARY_LAVA:0)
Block(-5,3,-2,STATIONARY_LAVA:0)
Block(-5,3,-1,OBSIDIAN:0)
Block(-5,3,0,OBSIDIAN:0)
Block(-5,3,1,OBSIDIAN:0)
Block(-5,3,2,CONCRETE:7)
Block(-5,3,3,CONCRETE:7)
Block(-5,3,4,CONCRETE:7)
Block(-5,3,5,CONCRETE:7)
Block(-5,3,6,CONCRETE:7)
Block(-5,3,7,CONCRETE:7)
Block(-5,3,8,CONCRETE:7)
Block(-5,4,-7,OBSIDIAN:0)
Block(-5,4,-6,OBSIDIAN:0)
Block(-5,4,-5,OBSIDIAN:0)
Block(-5,4,-4,OBSIDIAN:0)
Block(-5,4,-3,OBSIDIAN:0)
Block(-5,4,-2,STATIONARY_LAVA:0)
Block(-5,4,-1,OBSIDIAN:0)
Block(-5,4,0,OBSIDIAN:0)
Block(-5,4,1,OBSIDIAN:0)
Block(-5,4,2,CONCRETE:7)
Block(-5,4,3,CONCRETE:7)
Block(-5,4,4,CONCRETE:7)
Block(-5,4,5,CONCRETE:7)
Block(-5,4,6,CONCRETE:7)
Block(-5,4,7,CONCRETE:7)
Block(-5,4,8,CONCRETE:7)
Block(-5,5,-7,IRON_PLATE:0)
Block(-5,5,-6,IRON_PLATE:0)
Block(-5,5,-5,OBSIDIAN:0)
Block(-5,5,-4,STATIONARY_LAVA:0)
Block(-5,5,-3,OBSIDIAN:0)
Block(-5,5,-2,STATIONARY_LAVA:0)
Block(-5,5,-1,OBSIDIAN:0)
Block(-5,5,0,OBSIDIAN:0)
Block(-5,5,1,OBSIDIAN:0)
Block(-5,5,2,CONCRETE:7)
Block(-5,5,3,CONCRETE:7)
Block(-5,5,4,OBSIDIAN:0)
Block(-5,5,5,OBSIDIAN:0)
Block(-5,5,6,OBSIDIAN:0)
Block(-5,5,7,OBSIDIAN:0)
Block(-5,5,8,OBSIDIAN:0)
Block(-5,6,-7,STONE_BUTTON:2)
Block(-5,6,-6,AIR:0)
Block(-5,6,-5,OBSIDIAN:0)
Block(-5,6,-4,STATIONARY_LAVA:0)
Block(-5,6,-3,OBSIDIAN:0)
Block(-5,6,-2,STATIONARY_LAVA:0)
Block(-5,6,-1,OBSIDIAN:0)
Block(-5,6,0,OBSIDIAN:0)
Block(-5,6,1,OBSIDIAN:0)
Block(-5,6,2,CONCRETE:7)
Block(-5,6,3,CONCRETE:7)
Block(-5,6,4,OBSIDIAN:0)
Block(-5,6,5,OBSIDIAN:0)
Block(-5,6,6,OBSIDIAN:0)
Block(-5,6,7,OBSIDIAN:0)
Block(-5,6,8,OBSIDIAN:0)
Block(-5,7,-7,AIR:0)
Block(-5,7,-6,AIR:0)
Block(-5,7,-5,OBSIDIAN:0)
Block(-5,7,-4,STATIONARY_LAVA:0)
Block(-5,7,-3,OBSIDIAN:0)
Block(-5,7,-2,STATIONARY_LAVA:0)
Block(-5,7,-1,OBSIDIAN:0)
Block(-5,7,0,OBSIDIAN:0)
Block(-5,7,1,OBSIDIAN:0)
Block(-5,7,2,CONCRETE:7)
Block(-5,7,3,CONCRETE:7)
Block(-5,7,4,OBSIDIAN:0)
Block(-5,7,5,OBSIDIAN:0)
Block(-5,7,6,OBSIDIAN:0)
Block(-5,7,7,OBSIDIAN:0)
Block(-5,7,8,OBSIDIAN:0)
Block(-5,8,-7,STONE_BUTTON:2)
Block(-5,8,-6,AIR:0)
Block(-5,8,-5,OBSIDIAN:0)
Block(-5,8,-4,STATIONARY_LAVA:0)
Block(-5,8,-3,OBSIDIAN:0)
Block(-5,8,-2,STATIONARY_LAVA:0)
Block(-5,8,-1,OBSIDIAN:0)
Block(-5,8,0,OBSIDIAN:0)
Block(-5,8,1,OBSIDIAN:0)
Block(-5,8,2,CONCRETE:7)
Block(-5,8,3,CONCRETE:7)
Block(-5,8,4,OBSIDIAN:0)
Block(-5,8,5,OBSIDIAN:0)
Block(-5,8,6,OBSIDIAN:0)
Block(-5,8,7,OBSIDIAN:0)
Block(-5,8,8,OBSIDIAN:0)
Block(-5,9,-7,AIR:0)
Block(-5,9,-6,AIR:0)
Block(-5,9,-5,OBSIDIAN:0)
Block(-5,9,-4,STATIONARY_LAVA:0)
Block(-5,9,-3,OBSIDIAN:0)
Block(-5,9,-2,STATIONARY_LAVA:0)
Block(-5,9,-1,OBSIDIAN:0)
Block(-5,9,0,OBSIDIAN:0)
Block(-5,9,1,OBSIDIAN:0)
Block(-5,9,2,CONCRETE:7)
Block(-5,9,3,CONCRETE:7)
Block(-5,9,4,OBSIDIAN:0)
Block(-5,9,5,OBSIDIAN:0)
Block(-5,9,6,OBSIDIAN:0)
Block(-5,9,7,OBSIDIAN:0)
Block(-5,9,8,OBSIDIAN:0)
Block(-5,10,-7,STEP:8)
Block(-5,10,-6,STEP:8)
Block(-5,10,-5,OBSIDIAN:0)
Block(-5,10,-4,STATIONARY_LAVA:0)
Block(-5,10,-3,OBSIDIAN:0)
Block(-5,10,-2,STATIONARY_LAVA:0)
Block(-5,10,-1,OBSIDIAN:0)
Block(-5,10,0,OBSIDIAN:0)
Block(-5,10,1,OBSIDIAN:0)
Block(-5,10,2,CONCRETE:7)
Block(-5,10,3,CONCRETE:7)
Block(-5,10,4,OBSIDIAN:0)
Block(-5,10,5,OBSIDIAN:0)
Block(-5,10,6,OBSIDIAN:0)
Block(-5,10,7,OBSIDIAN:0)
Block(-5,10,8,OBSIDIAN:0)
Block(-5,11,-7,OBSIDIAN:0)
Block(-5,11,-6,OBSIDIAN:0)
Block(-5,11,-5,OBSIDIAN:0)
Block(-5,11,-4,OBSIDIAN:0)
Block(-5,11,-3,OBSIDIAN:0)
Block(-5,11,-2,STATIONARY_LAVA:0)
Block(-5,11,-1,OBSIDIAN:0)
Block(-5,11,0,OBSIDIAN:0)
Block(-5,11,1,OBSIDIAN:0)
Block(-5,11,2,CONCRETE:7)
Block(-5,11,3,CONCRETE:7)
Block(-5,11,4,OBSIDIAN:0)
Block(-5,11,5,OBSIDIAN:0)
Block(-5,11,6,OBSIDIAN:0)
Block(-5,11,7,OBSIDIAN:0)
Block(-5,11,8,OBSIDIAN:0)
Block(-5,12,-7,STATIONARY_LAVA:0)
Block(-5,12,-6,STATIONARY_LAVA:0)
Block(-5,12,-5,STATIONARY_LAVA:0)
Block(-5,12,-4,STATIONARY_LAVA:0)
Block(-5,12,-3,STATIONARY_LAVA:0)
Block(-5,12,-2,STATIONARY_LAVA:0)
Block(-5,12,-1,OBSIDIAN:0)
Block(-5,12,0,OBSIDIAN:0)
Block(-5,12,1,OBSIDIAN:0)
Block(-5,12,2,CONCRETE:7)
Block(-5,12,3,CONCRETE:7)
Block(-5,12,4,OBSIDIAN:0)
Block(-5,12,5,OBSIDIAN:0)
Block(-5,12,6,OBSIDIAN:0)
Block(-5,12,7,OBSIDIAN:0)
Block(-5,12,8,OBSIDIAN:0)
Block(-5,13,-7,OBSIDIAN:0)
Block(-5,13,-6,OBSIDIAN:0)
Block(-5,13,-5,OBSIDIAN:0)
Block(-5,13,-4,OBSIDIAN:0)
Block(-5,13,-3,OBSIDIAN:0)
Block(-5,13,-2,OBSIDIAN:0)
Block(-5,13,-1,OBSIDIAN:0)
Block(-5,13,0,OBSIDIAN:0)
Block(-5,13,1,OBSIDIAN:0)
Block(-5,13,2,CONCRETE:7)
Block(-5,13,3,CONCRETE:7)
Block(-5,13,4,OBSIDIAN:0)
Block(-5,13,5,OBSIDIAN:0)
Block(-5,13,6,OBSIDIAN:0)
Block(-5,13,7,OBSIDIAN:0)
Block(-5,13,8,OBSIDIAN:0)
Block(-5,14,-7,OBSIDIAN:0)
Block(-5,14,-6,OBSIDIAN:0)
Block(-5,14,-5,OBSIDIAN:0)
Block(-5,14,-4,OBSIDIAN:0)
Block(-5,14,-3,OBSIDIAN:0)
Block(-5,14,-2,OBSIDIAN:0)
Block(-5,14,-1,OBSIDIAN:0)
Block(-5,14,0,OBSIDIAN:0)
Block(-5,14,1,OBSIDIAN:0)
Block(-5,14,2,CONCRETE:7)
Block(-5,14,3,CONCRETE:7)
Block(-5,14,4,OBSIDIAN:0)
Block(-5,14,5,OBSIDIAN:0)
Block(-5,14,6,OBSIDIAN:0)
Block(-5,14,7,OBSIDIAN:0)
Block(-5,14,8,OBSIDIAN:0)
Block(-5,15,-7,OBSIDIAN:0)
Block(-5,15,-6,OBSIDIAN:0)
Block(-5,15,-5,OBSIDIAN:0)
Block(-5,15,-4,OBSIDIAN:0)
Block(-5,15,-3,OBSIDIAN:0)
Block(-5,15,-2,OBSIDIAN:0)
Block(-5,15,-1,OBSIDIAN:0)
Block(-5,15,0,OBSIDIAN:0)
Block(-5,15,1,OBSIDIAN:0)
Block(-5,15,2,CONCRETE:7)
Block(-5,15,3,CONCRETE:7)
Block(-5,15,4,CONCRETE:12)
Block(-5,15,5,CONCRETE:7)
Block(-5,15,6,CONCRETE:7)
Block(-5,15,7,CONCRETE:7)
Block(-5,15,8,CONCRETE:7)
Block(-5,16,-7,OBSIDIAN:0)
Block(-5,16,-6,OBSIDIAN:0)
Block(-5,16,-5,OBSIDIAN:0)
Block(-5,16,-4,OBSIDIAN:0)
Block(-5,16,-3,OBSIDIAN:0)
Block(-5,16,-2,OBSIDIAN:0)
Block(-5,16,-1,OBSIDIAN:0)
Block(-5,16,0,OBSIDIAN:0)
Block(-5,16,1,OBSIDIAN:0)
Block(-5,16,2,OBSIDIAN:0)
Block(-5,16,3,OBSIDIAN:0)
Block(-5,16,4,OBSIDIAN:0)
Block(-5,16,5,OBSIDIAN:0)
Block(-5,16,6,OBSIDIAN:0)
Block(-5,16,7,OBSIDIAN:0)
Block(-5,16,8,OBSIDIAN:0)
Block(-5,17,-7,CONCRETE:7)
Block(-5,17,-6,CONCRETE:7)
Block(-5,17,-5,CONCRETE:7)
Block(-5,17,-4,CONCRETE:7)
Block(-5,17,-3,CONCRETE:7)
Block(-5,17,-2,CONCRETE:7)
Block(-5,17,-1,CONCRETE:7)
Block(-5,17,0,CONCRETE:7)
Block(-5,17,1,CONCRETE:7)
Block(-5,17,2,CONCRETE:7)
Block(-5,17,3,CONCRETE:7)
Block(-5,17,4,CONCRETE:7)
Block(-5,17,5,CONCRETE:7)
Block(-5,17,6,CONCRETE:7)
Block(-5,17,7,CONCRETE:7)
Block(-5,17,8,CONCRETE:7)
Block(-5,18,-7,CONCRETE:7)
Block(-5,18,-6,CONCRETE:7)
Block(-5,18,-5,CONCRETE:7)
Block(-5,18,-4,CONCRETE:7)
Block(-5,18,-3,CONCRETE:7)
Block(-5,18,-2,CONCRETE:7)
Block(-5,18,-1,CONCRETE:7)
Block(-5,18,0,CONCRETE:7)
Block(-5,18,1,OBSIDIAN:0)
Block(-5,18,2,OBSIDIAN:0)
Block(-5,18,3,OBSIDIAN:0)
Block(-5,18,4,OBSIDIAN:0)
Block(-5,18,5,CONCRETE:7)
Block(-5,18,6,CONCRETE:7)
Block(-5,18,7,CONCRETE:7)
Block(-5,18,8,CONCRETE:7)
Block(-5,19,-7,CONCRETE:7)
Block(-5,19,-6,CONCRETE:7)
Block(-5,19,-5,CONCRETE:7)
Block(-5,19,-4,CONCRETE:7)
Block(-5,19,-3,CONCRETE:7)
Block(-5,19,-2,CONCRETE:7)
Block(-5,19,-1,CONCRETE:7)
Block(-5,19,0,CONCRETE:7)
Block(-5,19,1,OBSIDIAN:0)
Block(-5,19,2,OBSIDIAN:0)
Block(-5,19,3,OBSIDIAN:0)
Block(-5,19,4,OBSIDIAN:0)
Block(-5,19,5,CONCRETE:7)
Block(-5,19,6,CONCRETE:7)
Block(-5,19,7,CONCRETE:7)
Block(-5,19,8,CONCRETE:7)
Block(-5,20,-7,CONCRETE:7)
Block(-5,20,-6,CONCRETE:7)
Block(-5,20,-5,CONCRETE:7)
Block(-5,20,-4,CONCRETE:7)
Block(-5,20,-3,CONCRETE:7)
Block(-5,20,-2,CONCRETE:7)
Block(-5,20,-1,CONCRETE:7)
Block(-5,20,0,CONCRETE:7)
Block(-5,20,1,OBSIDIAN:0)
Block(-5,20,2,OBSIDIAN:0)
Block(-5,20,3,OBSIDIAN:0)
Block(-5,20,4,OBSIDIAN:0)
Block(-5,20,5,CONCRETE:7)
Block(-5,20,6,CONCRETE:7)
Block(-5,20,7,CONCRETE:7)
Block(-5,20,8,CONCRETE:7)
Block(-5,21,-7,CONCRETE:7)
Block(-5,21,-6,CONCRETE:7)
Block(-5,21,-5,CONCRETE:7)
Block(-5,21,-4,CONCRETE:7)
Block(-5,21,-3,CONCRETE:7)
Block(-5,21,-2,CONCRETE:7)
Block(-5,21,-1,CONCRETE:7)
Block(-5,21,0,CONCRETE:7)
Block(-5,21,1,OBSIDIAN:0)
Block(-5,21,2,OBSIDIAN:0)
Block(-5,21,3,OBSIDIAN:0)
Block(-5,21,4,OBSIDIAN:0)
Block(-5,21,5,CONCRETE:7)
Block(-5,21,6,CONCRETE:7)
Block(-5,21,7,CONCRETE:7)
Block(-5,21,8,CONCRETE:7)
Block(-5,22,-7,CONCRETE:7)
Block(-5,22,-6,CONCRETE:7)
Block(-5,22,-5,CONCRETE:7)
Block(-5,22,-4,CONCRETE:7)
Block(-5,22,-3,CONCRETE:7)
Block(-5,22,-2,CONCRETE:7)
Block(-5,22,-1,CONCRETE:7)
Block(-5,22,0,CONCRETE:12)
Block(-5,22,1,OBSIDIAN:0)
Block(-5,22,2,OBSIDIAN:0)
Block(-5,22,3,OBSIDIAN:0)
Block(-5,22,4,OBSIDIAN:0)
Block(-5,22,5,CONCRETE:7)
Block(-5,22,6,CONCRETE:7)
Block(-5,22,7,CONCRETE:7)
Block(-5,22,8,CONCRETE:7)
Block(-5,23,-7,OBSIDIAN:0)
Block(-5,23,-6,OBSIDIAN:0)
Block(-5,23,-5,OBSIDIAN:0)
Block(-5,23,-4,OBSIDIAN:0)
Block(-5,23,-3,OBSIDIAN:0)
Block(-5,23,-2,OBSIDIAN:0)
Block(-5,23,-1,OBSIDIAN:0)
Block(-5,23,0,OBSIDIAN:0)
Block(-5,23,1,OBSIDIAN:0)
Block(-5,23,2,OBSIDIAN:0)
Block(-5,23,3,OBSIDIAN:0)
Block(-5,23,4,OBSIDIAN:0)
Block(-5,23,5,OBSIDIAN:0)
Block(-5,23,6,OBSIDIAN:0)
Block(-5,23,7,CONCRETE:12)
Block(-5,23,8,OBSIDIAN:0)
Block(-5,24,-7,CONCRETE:0)
Block(-5,24,-6,CONCRETE:0)
Block(-5,24,-5,CONCRETE:0)
Block(-5,24,-4,CONCRETE:0)
Block(-5,24,-3,CONCRETE:0)
Block(-5,24,-2,CONCRETE:0)
Block(-5,24,-1,CONCRETE:0)
Block(-5,24,0,CONCRETE:0)
Block(-5,24,1,CONCRETE:0)
Block(-5,24,2,CONCRETE:0)
Block(-5,24,3,CONCRETE:0)
Block(-5,24,4,CONCRETE:0)
Block(-5,24,5,CONCRETE:0)
Block(-5,24,6,CONCRETE:0)
Block(-5,24,7,CONCRETE:12)
Block(-5,24,8,CONCRETE:0)
Block(-5,25,1,CONCRETE:0)
Block(-5,25,3,CONCRETE:0)
Block(-5,25,6,CONCRETE:0)
Block(-5,25,7,CONCRETE:0)
Block(-5,25,8,CONCRETE:0)
Block(-5,26,0,WALL_BANNER:2,NBT/skyscraper_8x6_01/493-bannerC64R48.nbt)
Block(-5,26,1,CONCRETE:0)
Block(-5,26,3,CONCRETE:0)
Block(-5,26,4,WALL_BANNER:3,NBT/skyscraper_8x6_01/494-bannerC64R48.nbt)
Block(-5,26,6,CONCRETE:0)
Block(-5,26,7,CONCRETE:0)
Block(-5,26,8,CONCRETE:0)
Block(-5,27,-7,STEP:8)
Block(-5,27,-6,STEP:8)
Block(-5,27,-5,STEP:8)
Block(-5,27,-4,STEP:8)
Block(-5,27,-3,STEP:8)
Block(-5,27,-2,STEP:8)
Block(-5,27,-1,STEP:8)
Block(-5,27,0,CONCRETE:0)
Block(-5,27,1,CONCRETE:0)
Block(-5,27,2,CONCRETE:0)
Block(-5,27,3,CONCRETE:0)
Block(-5,27,4,CONCRETE:15)
Block(-5,27,5,STONE:4)
Block(-5,27,6,STONE:6)
Block(-5,27,7,CONCRETE:0)
Block(-5,27,8,STONE:4)
Block(-5,28,-7,SPRUCE_WOOD_STAIRS:3)
Block(-5,28,-3,SPRUCE_WOOD_STAIRS:2)
Block(-5,28,-2,PRISMARINE:0)
Block(-5,28,-1,SPRUCE_WOOD_STAIRS:3)
Block(-5,28,1,STAINED_GLASS_PANE:15)
Block(-5,28,2,CONCRETE:0)
Block(-5,29,-2,STAINED_GLASS_PANE:15)
Block(-5,29,1,STAINED_GLASS_PANE:15)
Block(-5,29,2,STONE:4)
Block(-5,30,1,STAINED_GLASS_PANE:15)
Block(-5,30,2,STONE:4)
Block(-5,31,1,STAINED_GLASS_PANE:15)
Block(-5,31,2,CONCRETE:0)
Block(-5,32,1,STAINED_GLASS_PANE:15)
Block(-5,32,2,CONCRETE:0)
Block(-5,33,1,STAINED_GLASS_PANE:15)
Block(-5,33,2,CONCRETE:0)
Block(-5,34,1,STAINED_GLASS_PANE:15)
Block(-5,34,2,CONCRETE:0)
Block(-5,35,1,STAINED_GLASS_PANE:15)
Block(-5,35,2,CONCRETE:0)
Block(-5,36,1,STAINED_GLASS_PANE:15)
Block(-5,36,2,CONCRETE:0)
Block(-5,37,1,STEP:7)
Block(-5,37,2,CONCRETE:0)
Block(-5,38,2,CONCRETE:0)
Block(-5,39,2,CONCRETE:0)
Block(-5,40,-7,LEAVES:4)
Block(-5,40,2,CONCRETE:0)
Block(-5,41,-7,LEAVES:4)
Block(-5,41,2,CONCRETE:0)
Block(-5,42,-7,LEAVES:4)
Block(-5,42,2,QUARTZ_STAIRS:2)
Block(-5,42,3,CONCRETE:0)
Block(-5,43,-7,LEAVES:4)
Block(-5,43,3,CONCRETE:0)
Block(-5,44,-7,LEAVES:4)
Block(-5,44,3,CONCRETE:0)
Block(-5,45,-7,LEAVES:4)
Block(-5,45,-6,LEAVES:4)
Block(-5,45,3,QUARTZ_STAIRS:2)
Block(-5,45,4,CONCRETE:0)
Block(-5,46,-7,LEAVES:4)
Block(-5,46,-6,LEAVES:4)
Block(-5,46,4,CONCRETE:0)
Block(-5,47,-7,LEAVES:4)
Block(-5,47,-6,LEAVES:4)
Block(-5,47,-5,IRON_TRAPDOOR:10)
Block(-5,47,-4,LEAVES:12)
Block(-5,47,4,QUARTZ_STAIRS:2)
Block(-5,47,5,CONCRETE:0)
Block(-5,48,-7,LEAVES:4)
Block(-5,48,-6,LEAVES:12)
Block(-5,48,-5,SEA_LANTERN:0)
Block(-5,48,-4,LEAVES:4)
Block(-5,48,5,CONCRETE:0)
Block(-5,48,6,CONCRETE:0)
Block(-5,49,-7,LEAVES:12)
Block(-5,49,-6,LEAVES:12)
Block(-5,49,-5,GRASS:0)
Block(-5,49,-4,LEAVES:12)
Block(-5,49,-3,CONCRETE:7)
Block(-5,49,-2,STEP:8)
Block(-5,49,5,QUARTZ_STAIRS:2)
Block(-5,49,6,CONCRETE:0)
Block(-5,49,7,CONCRETE:0)
Block(-5,50,-5,LEAVES:12)
Block(-5,50,-3,IRON_FENCE:0)
Block(-5,50,-2,COBBLE_WALL:0)
Block(-5,50,6,QUARTZ_STAIRS:2)
Block(-5,50,7,CONCRETE:0)
Block(-5,50,8,CONCRETE:0)
Block(-5,51,-2,IRON_FENCE:0)
Block(-5,51,7,STEP:7)
Block(-5,51,8,CONCRETE:7)
Block(-5,52,-2,IRON_FENCE:0)
Block(-5,52,8,CONCRETE:7)
Block(-5,53,-7,IRON_TRAPDOOR:11)
Block(-5,53,-2,IRON_FENCE:0)
Block(-5,53,8,CONCRETE:0)
Block(-5,54,-7,SEA_LANTERN:0)
Block(-5,54,-6,STEP:8)
Block(-5,54,-5,TRAP_DOOR:7)
Block(-5,54,-2,IRON_FENCE:0)
Block(-5,54,7,CONCRETE:7)
Block(-5,55,-7,CONCRETE:7)
Block(-5,55,-6,CONCRETE:7)
Block(-5,55,-5,STEP:8)
Block(-5,55,-2,IRON_FENCE:0)
Block(-5,55,6,QUARTZ_STAIRS:6)
Block(-5,55,7,CONCRETE:7)
Block(-5,56,-5,COBBLE_WALL:0)
Block(-5,56,-2,IRON_FENCE:0)
Block(-5,56,6,CONCRETE:7)
Block(-5,57,-5,IRON_FENCE:0)
Block(-5,57,-2,IRON_FENCE:0)
Block(-5,57,5,CONCRETE:7)
Block(-5,58,-5,IRON_FENCE:0)
Block(-5,58,-2,IRON_FENCE:0)
Block(-5,58,4,CONCRETE:7)
Block(-5,59,-5,IRON_FENCE:0)
Block(-5,59,-2,IRON_FENCE:0)
Block(-5,59,1,QUARTZ_STAIRS:6)
Block(-5,59,2,QUARTZ_STAIRS:4)
Block(-5,59,3,CONCRETE:7)
Block(-5,60,-5,IRON_FENCE:0)
Block(-5,60,-2,IRON_FENCE:0)
Block(-5,60,0,QUARTZ_STAIRS:6)
Block(-5,60,1,CONCRETE:0)
Block(-5,60,2,CONCRETE:7)
Block(-5,61,-5,IRON_FENCE:0)
Block(-5,61,-2,CONCRETE:7)
Block(-5,61,-1,STEP:15)
Block(-5,61,0,CONCRETE:0)
Block(-5,61,1,CONCRETE:0)
Block(-5,62,-5,CONCRETE:0)
Block(-5,62,-4,CONCRETE:7)
Block(-5,62,-3,CONCRETE:7)
Block(-5,62,-2,CONCRETE:7)
Block(-5,62,-1,CONCRETE:7)
Block(-5,63,-7,CONCRETE:7)
Block(-5,63,-6,CONCRETE:7)
Block(-5,63,-5,CONCRETE:7)
Block(-4,0,-7,CONCRETE:7)
Block(-4,0,-6,CONCRETE:7)
Block(-4,0,-5,CONCRETE:7)
Block(-4,0,-4,CONCRETE:7)
Block(-4,0,-3,CONCRETE:7)
Block(-4,0,-2,CONCRETE:7)
Block(-4,0,-1,CONCRETE:7)
Block(-4,0,0,CONCRETE:7)
Block(-4,0,1,CONCRETE:7)
Block(-4,0,2,CONCRETE:7)
Block(-4,0,3,CONCRETE:7)
Block(-4,0,4,CONCRETE:7)
Block(-4,0,5,CONCRETE:7)
Block(-4,0,6,CONCRETE:7)
Block(-4,0,7,CONCRETE:7)
Block(-4,0,8,CONCRETE:7)
Block(-4,1,-7,OBSIDIAN:0)
Block(-4,1,-6,OBSIDIAN:0)
Block(-4,1,-5,OBSIDIAN:0)
Block(-4,1,-4,OBSIDIAN:0)
Block(-4,1,-3,OBSIDIAN:0)
Block(-4,1,-2,OBSIDIAN:0)
Block(-4,1,-1,OBSIDIAN:0)
Block(-4,1,0,OBSIDIAN:0)
Block(-4,1,1,OBSIDIAN:0)
Block(-4,1,2,OBSIDIAN:0)
Block(-4,1,3,OBSIDIAN:0)
Block(-4,1,4,OBSIDIAN:0)
Block(-4,1,5,OBSIDIAN:0)
Block(-4,1,6,OBSIDIAN:0)
Block(-4,1,7,OBSIDIAN:0)
Block(-4,1,8,OBSIDIAN:0)
Block(-4,2,-7,OBSIDIAN:0)
Block(-4,2,-6,OBSIDIAN:0)
Block(-4,2,-5,OBSIDIAN:0)
Block(-4,2,-4,OBSIDIAN:0)
Block(-4,2,-3,OBSIDIAN:0)
Block(-4,2,-2,OBSIDIAN:0)
Block(-4,2,-1,OBSIDIAN:0)
Block(-4,2,0,OBSIDIAN:0)
Block(-4,2,1,OBSIDIAN:0)
Block(-4,2,2,CONCRETE:7)
Block(-4,2,3,CONCRETE:7)
Block(-4,2,4,CONCRETE:7)
Block(-4,2,5,CONCRETE:7)
Block(-4,2,6,CONCRETE:7)
Block(-4,2,7,CONCRETE:7)
Block(-4,2,8,CONCRETE:7)
Block(-4,3,-7,STATIONARY_LAVA:0)
Block(-4,3,-6,STATIONARY_LAVA:0)
Block(-4,3,-5,STATIONARY_LAVA:0)
Block(-4,3,-4,STATIONARY_LAVA:0)
Block(-4,3,-3,STATIONARY_LAVA:0)
Block(-4,3,-2,STATIONARY_LAVA:0)
Block(-4,3,-1,OBSIDIAN:0)
Block(-4,3,0,OBSIDIAN:0)
Block(-4,3,1,OBSIDIAN:0)
Block(-4,3,2,CONCRETE:7)
Block(-4,3,3,CONCRETE:7)
Block(-4,3,4,CONCRETE:7)
Block(-4,3,5,CONCRETE:7)
Block(-4,3,6,CONCRETE:7)
Block(-4,3,7,CONCRETE:7)
Block(-4,3,8,CONCRETE:7)
Block(-4,4,-7,OBSIDIAN:0)
Block(-4,4,-6,OBSIDIAN:0)
Block(-4,4,-5,OBSIDIAN:0)
Block(-4,4,-4,OBSIDIAN:0)
Block(-4,4,-3,OBSIDIAN:0)
Block(-4,4,-2,STATIONARY_LAVA:0)
Block(-4,4,-1,OBSIDIAN:0)
Block(-4,4,0,OBSIDIAN:0)
Block(-4,4,1,OBSIDIAN:0)
Block(-4,4,2,CONCRETE:7)
Block(-4,4,3,CONCRETE:7)
Block(-4,4,4,CONCRETE:7)
Block(-4,4,5,CONCRETE:7)
Block(-4,4,6,CONCRETE:7)
Block(-4,4,7,CONCRETE:7)
Block(-4,4,8,CONCRETE:7)
Block(-4,5,-7,COBBLE_WALL:0)
Block(-4,5,-6,IRON_PLATE:0)
Block(-4,5,-5,OBSIDIAN:0)
Block(-4,5,-4,STATIONARY_LAVA:0)
Block(-4,5,-3,OBSIDIAN:0)
Block(-4,5,-2,STATIONARY_LAVA:0)
Block(-4,5,-1,OBSIDIAN:0)
Block(-4,5,0,OBSIDIAN:0)
Block(-4,5,1,OBSIDIAN:0)
Block(-4,5,2,CONCRETE:7)
Block(-4,5,3,CONCRETE:7)
Block(-4,5,4,OBSIDIAN:0)
Block(-4,5,5,OBSIDIAN:0)
Block(-4,5,6,OBSIDIAN:0)
Block(-4,5,7,OBSIDIAN:0)
Block(-4,5,8,OBSIDIAN:0)
Block(-4,6,-7,DOUBLE_STEP:0)
Block(-4,6,-6,STONE_BUTTON:3)
Block(-4,6,-5,OBSIDIAN:0)
Block(-4,6,-4,STATIONARY_LAVA:0)
Block(-4,6,-3,OBSIDIAN:0)
Block(-4,6,-2,STATIONARY_LAVA:0)
Block(-4,6,-1,OBSIDIAN:0)
Block(-4,6,0,OBSIDIAN:0)
Block(-4,6,1,OBSIDIAN:0)
Block(-4,6,2,CONCRETE:7)
Block(-4,6,3,CONCRETE:7)
Block(-4,6,4,OBSIDIAN:0)
Block(-4,6,5,OBSIDIAN:0)
Block(-4,6,6,OBSIDIAN:0)
Block(-4,6,7,OBSIDIAN:0)
Block(-4,6,8,OBSIDIAN:0)
Block(-4,7,-7,COBBLE_WALL:0)
Block(-4,7,-6,AIR:0)
Block(-4,7,-5,OBSIDIAN:0)
Block(-4,7,-4,STATIONARY_LAVA:0)
Block(-4,7,-3,OBSIDIAN:0)
Block(-4,7,-2,STATIONARY_LAVA:0)
Block(-4,7,-1,OBSIDIAN:0)
Block(-4,7,0,OBSIDIAN:0)
Block(-4,7,1,OBSIDIAN:0)
Block(-4,7,2,CONCRETE:7)
Block(-4,7,3,CONCRETE:7)
Block(-4,7,4,OBSIDIAN:0)
Block(-4,7,5,OBSIDIAN:0)
Block(-4,7,6,OBSIDIAN:0)
Block(-4,7,7,OBSIDIAN:0)
Block(-4,7,8,OBSIDIAN:0)
Block(-4,8,-7,DOUBLE_STEP:0)
Block(-4,8,-6,STONE_BUTTON:3)
Block(-4,8,-5,OBSIDIAN:0)
Block(-4,8,-4,STATIONARY_LAVA:0)
Block(-4,8,-3,OBSIDIAN:0)
Block(-4,8,-2,STATIONARY_LAVA:0)
Block(-4,8,-1,OBSIDIAN:0)
Block(-4,8,0,OBSIDIAN:0)
Block(-4,8,1,OBSIDIAN:0)
Block(-4,8,2,CONCRETE:7)
Block(-4,8,3,CONCRETE:7)
Block(-4,8,4,OBSIDIAN:0)
Block(-4,8,5,OBSIDIAN:0)
Block(-4,8,6,OBSIDIAN:0)
Block(-4,8,7,OBSIDIAN:0)
Block(-4,8,8,OBSIDIAN:0)
Block(-4,9,-7,GOLD_PLATE:0)
Block(-4,9,-6,AIR:0)
Block(-4,9,-5,OBSIDIAN:0)
Block(-4,9,-4,STATIONARY_LAVA:0)
Block(-4,9,-3,OBSIDIAN:0)
Block(-4,9,-2,STATIONARY_LAVA:0)
Block(-4,9,-1,OBSIDIAN:0)
Block(-4,9,0,OBSIDIAN:0)
Block(-4,9,1,OBSIDIAN:0)
Block(-4,9,2,CONCRETE:7)
Block(-4,9,3,CONCRETE:7)
Block(-4,9,4,OBSIDIAN:0)
Block(-4,9,5,OBSIDIAN:0)
Block(-4,9,6,OBSIDIAN:0)
Block(-4,9,7,OBSIDIAN:0)
Block(-4,9,8,OBSIDIAN:0)
Block(-4,10,-7,STEP:8)
Block(-4,10,-6,STEP:8)
Block(-4,10,-5,OBSIDIAN:0)
Block(-4,10,-4,STATIONARY_LAVA:0)
Block(-4,10,-3,OBSIDIAN:0)
Block(-4,10,-2,STATIONARY_LAVA:0)
Block(-4,10,-1,OBSIDIAN:0)
Block(-4,10,0,OBSIDIAN:0)
Block(-4,10,1,OBSIDIAN:0)
Block(-4,10,2,CONCRETE:7)
Block(-4,10,3,CONCRETE:7)
Block(-4,10,4,OBSIDIAN:0)
Block(-4,10,5,OBSIDIAN:0)
Block(-4,10,6,OBSIDIAN:0)
Block(-4,10,7,OBSIDIAN:0)
Block(-4,10,8,OBSIDIAN:0)
Block(-4,11,-7,OBSIDIAN:0)
Block(-4,11,-6,OBSIDIAN:0)
Block(-4,11,-5,OBSIDIAN:0)
Block(-4,11,-4,OBSIDIAN:0)
Block(-4,11,-3,OBSIDIAN:0)
Block(-4,11,-2,STATIONARY_LAVA:0)
Block(-4,11,-1,OBSIDIAN:0)
Block(-4,11,0,OBSIDIAN:0)
Block(-4,11,1,OBSIDIAN:0)
Block(-4,11,2,CONCRETE:7)
Block(-4,11,3,CONCRETE:7)
Block(-4,11,4,OBSIDIAN:0)
Block(-4,11,5,OBSIDIAN:0)
Block(-4,11,6,OBSIDIAN:0)
Block(-4,11,7,OBSIDIAN:0)
Block(-4,11,8,OBSIDIAN:0)
Block(-4,12,-7,STATIONARY_LAVA:0)
Block(-4,12,-6,STATIONARY_LAVA:0)
Block(-4,12,-5,STATIONARY_LAVA:0)
Block(-4,12,-4,STATIONARY_LAVA:0)
Block(-4,12,-3,STATIONARY_LAVA:0)
Block(-4,12,-2,STATIONARY_LAVA:0)
Block(-4,12,-1,OBSIDIAN:0)
Block(-4,12,0,OBSIDIAN:0)
Block(-4,12,1,OBSIDIAN:0)
Block(-4,12,2,CONCRETE:7)
Block(-4,12,3,CONCRETE:7)
Block(-4,12,4,OBSIDIAN:0)
Block(-4,12,5,OBSIDIAN:0)
Block(-4,12,6,OBSIDIAN:0)
Block(-4,12,7,OBSIDIAN:0)
Block(-4,12,8,OBSIDIAN:0)
Block(-4,13,-7,OBSIDIAN:0)
Block(-4,13,-6,OBSIDIAN:0)
Block(-4,13,-5,OBSIDIAN:0)
Block(-4,13,-4,OBSIDIAN:0)
Block(-4,13,-3,OBSIDIAN:0)
Block(-4,13,-2,OBSIDIAN:0)
Block(-4,13,-1,OBSIDIAN:0)
Block(-4,13,0,OBSIDIAN:0)
Block(-4,13,1,OBSIDIAN:0)
Block(-4,13,2,CONCRETE:7)
Block(-4,13,3,CONCRETE:7)
Block(-4,13,4,OBSIDIAN:0)
Block(-4,13,5,OBSIDIAN:0)
Block(-4,13,6,OBSIDIAN:0)
Block(-4,13,7,OBSIDIAN:0)
Block(-4,13,8,OBSIDIAN:0)
Block(-4,14,-7,OBSIDIAN:0)
Block(-4,14,-6,OBSIDIAN:0)
Block(-4,14,-5,OBSIDIAN:0)
Block(-4,14,-4,OBSIDIAN:0)
Block(-4,14,-3,OBSIDIAN:0)
Block(-4,14,-2,OBSIDIAN:0)
Block(-4,14,-1,OBSIDIAN:0)
Block(-4,14,0,OBSIDIAN:0)
Block(-4,14,1,OBSIDIAN:0)
Block(-4,14,2,CONCRETE:7)
Block(-4,14,3,CONCRETE:7)
Block(-4,14,4,OBSIDIAN:0)
Block(-4,14,5,OBSIDIAN:0)
Block(-4,14,6,OBSIDIAN:0)
Block(-4,14,7,OBSIDIAN:0)
Block(-4,14,8,OBSIDIAN:0)
Block(-4,15,-7,OBSIDIAN:0)
Block(-4,15,-6,OBSIDIAN:0)
Block(-4,15,-5,OBSIDIAN:0)
Block(-4,15,-4,OBSIDIAN:0)
Block(-4,15,-3,OBSIDIAN:0)
Block(-4,15,-2,OBSIDIAN:0)
Block(-4,15,-1,OBSIDIAN:0)
Block(-4,15,0,OBSIDIAN:0)
Block(-4,15,1,OBSIDIAN:0)
Block(-4,15,2,CONCRETE:7)
Block(-4,15,3,CONCRETE:7)
Block(-4,15,4,CONCRETE:12)
Block(-4,15,5,CONCRETE:7)
Block(-4,15,6,CONCRETE:7)
Block(-4,15,7,OBSIDIAN:0)
Block(-4,15,8,OBSIDIAN:0)
Block(-4,16,-7,OBSIDIAN:0)
Block(-4,16,-6,OBSIDIAN:0)
Block(-4,16,-5,OBSIDIAN:0)
Block(-4,16,-4,OBSIDIAN:0)
Block(-4,16,-3,OBSIDIAN:0)
Block(-4,16,-2,OBSIDIAN:0)
Block(-4,16,-1,OBSIDIAN:0)
Block(-4,16,0,OBSIDIAN:0)
Block(-4,16,1,OBSIDIAN:0)
Block(-4,16,2,OBSIDIAN:0)
Block(-4,16,3,OBSIDIAN:0)
Block(-4,16,4,OBSIDIAN:0)
Block(-4,16,5,OBSIDIAN:0)
Block(-4,16,6,OBSIDIAN:0)
Block(-4,16,7,OBSIDIAN:0)
Block(-4,16,8,OBSIDIAN:0)
Block(-4,17,-7,CONCRETE:7)
Block(-4,17,-6,CONCRETE:7)
Block(-4,17,-5,CONCRETE:7)
Block(-4,17,-4,CONCRETE:7)
Block(-4,17,-3,CONCRETE:7)
Block(-4,17,-2,CONCRETE:7)
Block(-4,17,-1,CONCRETE:7)
Block(-4,17,0,CONCRETE:7)
Block(-4,17,1,CONCRETE:7)
Block(-4,17,2,CONCRETE:7)
Block(-4,17,3,CONCRETE:7)
Block(-4,17,4,CONCRETE:7)
Block(-4,17,5,CONCRETE:7)
Block(-4,17,6,CONCRETE:7)
Block(-4,17,7,CONCRETE:7)
Block(-4,17,8,CONCRETE:7)
Block(-4,18,-7,CONCRETE:7)
Block(-4,18,-6,CONCRETE:7)
Block(-4,18,-5,CONCRETE:7)
Block(-4,18,-4,CONCRETE:7)
Block(-4,18,-3,CONCRETE:7)
Block(-4,18,-2,CONCRETE:7)
Block(-4,18,-1,OBSIDIAN:0)
Block(-4,18,0,OBSIDIAN:0)
Block(-4,18,1,OBSIDIAN:0)
Block(-4,18,2,CONCRETE:7)
Block(-4,18,3,CONCRETE:7)
Block(-4,18,4,CONCRETE:7)
Block(-4,18,5,CONCRETE:7)
Block(-4,18,6,STEP:0)
Block(-4,18,7,STEP:0)
Block(-4,18,8,STEP:0)
Block(-4,19,-7,CONCRETE:7)
Block(-4,19,-6,CONCRETE:7)
Block(-4,19,-5,CONCRETE:7)
Block(-4,19,-4,CONCRETE:7)
Block(-4,19,-3,CONCRETE:7)
Block(-4,19,-2,CONCRETE:7)
Block(-4,19,-1,OBSIDIAN:0)
Block(-4,19,0,OBSIDIAN:0)
Block(-4,19,1,OBSIDIAN:0)
Block(-4,19,2,CONCRETE:7)
Block(-4,19,3,CONCRETE:7)
Block(-4,19,4,CONCRETE:7)
Block(-4,19,5,CONCRETE:7)
Block(-4,19,6,IRON_FENCE:0)
Block(-4,19,7,IRON_FENCE:0)
Block(-4,19,8,IRON_FENCE:0)
Block(-4,20,-7,CONCRETE:7)
Block(-4,20,-6,CONCRETE:7)
Block(-4,20,-5,CONCRETE:7)
Block(-4,20,-4,CONCRETE:7)
Block(-4,20,-3,CONCRETE:7)
Block(-4,20,-2,CONCRETE:7)
Block(-4,20,-1,OBSIDIAN:0)
Block(-4,20,0,OBSIDIAN:0)
Block(-4,20,1,OBSIDIAN:0)
Block(-4,20,2,CONCRETE:7)
Block(-4,20,3,CONCRETE:7)
Block(-4,20,4,CONCRETE:7)
Block(-4,20,5,CONCRETE:7)
Block(-4,20,6,IRON_FENCE:0)
Block(-4,20,7,IRON_FENCE:0)
Block(-4,20,8,IRON_FENCE:0)
Block(-4,21,-7,CONCRETE:7)
Block(-4,21,-6,CONCRETE:7)
Block(-4,21,-5,CONCRETE:7)
Block(-4,21,-4,CONCRETE:7)
Block(-4,21,-3,CONCRETE:7)
Block(-4,21,-2,CONCRETE:7)
Block(-4,21,-1,OBSIDIAN:0)
Block(-4,21,0,OBSIDIAN:0)
Block(-4,21,1,OBSIDIAN:0)
Block(-4,21,2,CONCRETE:7)
Block(-4,21,3,CONCRETE:7)
Block(-4,21,4,CONCRETE:7)
Block(-4,21,5,CONCRETE:7)
Block(-4,21,6,STEP:8)
Block(-4,21,7,STEP:8)
Block(-4,21,8,STEP:8)
Block(-4,22,-7,CONCRETE:7)
Block(-4,22,-6,CONCRETE:7)
Block(-4,22,-5,CONCRETE:7)
Block(-4,22,-4,CONCRETE:7)
Block(-4,22,-3,CONCRETE:7)
Block(-4,22,-2,CONCRETE:7)
Block(-4,22,-1,OBSIDIAN:0)
Block(-4,22,0,CONCRETE:12)
Block(-4,22,1,OBSIDIAN:0)
Block(-4,22,2,CONCRETE:7)
Block(-4,22,3,CONCRETE:7)
Block(-4,22,4,CONCRETE:7)
Block(-4,22,5,CONCRETE:7)
Block(-4,22,6,OBSIDIAN:0)
Block(-4,22,7,OBSIDIAN:0)
Block(-4,22,8,OBSIDIAN:0)
Block(-4,23,-7,OBSIDIAN:0)
Block(-4,23,-6,OBSIDIAN:0)
Block(-4,23,-5,OBSIDIAN:0)
Block(-4,23,-4,OBSIDIAN:0)
Block(-4,23,-3,OBSIDIAN:0)
Block(-4,23,-2,OBSIDIAN:0)
Block(-4,23,-1,OBSIDIAN:0)
Block(-4,23,0,OBSIDIAN:0)
Block(-4,23,1,OBSIDIAN:0)
Block(-4,23,2,OBSIDIAN:0)
Block(-4,23,3,OBSIDIAN:0)
Block(-4,23,4,OBSIDIAN:0)
Block(-4,23,5,OBSIDIAN:0)
Block(-4,23,6,OBSIDIAN:0)
Block(-4,23,7,OBSIDIAN:0)
Block(-4,23,8,OBSIDIAN:0)
Block(-4,24,-7,CONCRETE:0)
Block(-4,24,-6,CONCRETE:0)
Block(-4,24,-5,CONCRETE:0)
Block(-4,24,-4,CONCRETE:0)
Block(-4,24,-3,CONCRETE:0)
Block(-4,24,-2,CONCRETE:0)
Block(-4,24,-1,CONCRETE:0)
Block(-4,24,0,CONCRETE:0)
Block(-4,24,1,CONCRETE:0)
Block(-4,24,2,CONCRETE:0)
Block(-4,24,3,CONCRETE:0)
Block(-4,24,4,CONCRETE:0)
Block(-4,24,5,CONCRETE:0)
Block(-4,24,6,CONCRETE:0)
Block(-4,24,7,CONCRETE:12)
Block(-4,24,8,CONCRETE:0)
Block(-4,25,-7,SPRUCE_DOOR:2)
Block(-4,25,-6,CONCRETE:0)
Block(-4,25,-5,CONCRETE:0)
Block(-4,25,-4,SPRUCE_DOOR:2)
Block(-4,25,-3,CONCRETE:0)
Block(-4,25,-2,CONCRETE:0)
Block(-4,25,-1,SPRUCE_DOOR:2)
Block(-4,25,0,CONCRETE:0)
Block(-4,25,1,CONCRETE:0)
Block(-4,25,3,CONCRETE:0)
Block(-4,25,6,CONCRETE:0)
Block(-4,25,7,DROPPER:1,NBT/skyscraper_8x6_01/516-dropperC64R48.nbt)
Block(-4,25,8,STEP:0)
Block(-4,26,-7,SPRUCE_DOOR:9)
Block(-4,26,-6,CONCRETE:0)
Block(-4,26,-5,CONCRETE:0)
Block(-4,26,-4,SPRUCE_DOOR:9)
Block(-4,26,-3,CONCRETE:0)
Block(-4,26,-2,CONCRETE:0)
Block(-4,26,-1,SPRUCE_DOOR:9)
Block(-4,26,0,CONCRETE:0)
Block(-4,26,1,CONCRETE:0)
Block(-4,26,2,WALL_BANNER:2,NBT/skyscraper_8x6_01/517-bannerC64R48.nbt)
Block(-4,26,3,CONCRETE:0)
Block(-4,26,4,WALL_BANNER:3,NBT/skyscraper_8x6_01/518-bannerC64R48.nbt)
Block(-4,26,6,CONCRETE:0)
Block(-4,26,7,TRAP_DOOR:5)
Block(-4,27,-7,CONCRETE:0)
Block(-4,27,-6,CONCRETE:0)
Block(-4,27,-5,CONCRETE:0)
Block(-4,27,-4,CONCRETE:0)
Block(-4,27,-3,CONCRETE:0)
Block(-4,27,-2,CONCRETE:0)
Block(-4,27,-1,CONCRETE:0)
Block(-4,27,0,CONCRETE:0)
Block(-4,27,1,CONCRETE:0)
Block(-4,27,2,CONCRETE:0)
Block(-4,27,3,CONCRETE:0)
Block(-4,27,4,CONCRETE:0)
Block(-4,27,5,CONCRETE:15)
Block(-4,27,6,STONE:4)
Block(-4,27,7,CONCRETE:0)
Block(-4,27,8,CONCRETE:0)
Block(-4,28,-7,SPRUCE_WOOD_STAIRS:3)
Block(-4,28,-3,SPRUCE_WOOD_STAIRS:2)
Block(-4,28,-2,PRISMARINE:0)
Block(-4,28,-1,SPRUCE_WOOD_STAIRS:3)
Block(-4,28,2,STAINED_GLASS_PANE:15)
Block(-4,29,-2,STAINED_GLASS_PANE:15)
Block(-4,29,2,STAINED_GLASS_PANE:15)
Block(-4,30,2,STAINED_GLASS_PANE:15)
Block(-4,31,2,STAINED_GLASS_PANE:15)
Block(-4,32,2,STAINED_GLASS_PANE:15)
Block(-4,32,3,QUARTZ_STAIRS:6)
Block(-4,33,2,STEP:7)
Block(-4,33,3,CONCRETE:0)
Block(-4,34,3,CONCRETE:0)
Block(-4,35,3,CONCRETE:0)
Block(-4,36,3,CONCRETE:0)
Block(-4,37,3,CONCRETE:0)
Block(-4,38,3,CONCRETE:0)
Block(-4,39,3,CONCRETE:0)
Block(-4,40,3,CONCRETE:0)
Block(-4,41,3,CONCRETE:0)
Block(-4,42,3,CONCRETE:0)
Block(-4,42,4,CONCRETE:0)
Block(-4,43,3,STEP:7)
Block(-4,43,4,CONCRETE:0)
Block(-4,44,4,CONCRETE:0)
Block(-4,45,4,CONCRETE:0)
Block(-4,46,4,QUARTZ_STAIRS:2)
Block(-4,46,5,CONCRETE:0)
Block(-4,47,5,CONCRETE:0)
Block(-4,47,6,CONCRETE:0)
Block(-4,48,-5,QUARTZ_STAIRS:5)
Block(-4,48,5,STEP:7)
Block(-4,48,6,CONCRETE:0)
Block(-4,48,7,CONCRETE:0)
Block(-4,48,8,CONCRETE:7)
Block(-4,49,-6,TRAP_DOOR:4)
Block(-4,49,-5,GRASS:0)
Block(-4,49,-4,CONCRETE:7)
Block(-4,49,-3,CONCRETE:7)
Block(-4,49,6,STEP:7)
Block(-4,49,7,CONCRETE:0)
Block(-4,49,8,CONCRETE:7)
Block(-4,50,-5,LONG_GRASS:1)
Block(-4,50,-4,IRON_FENCE:0)
Block(-4,50,-3,IRON_FENCE:0)
Block(-4,50,7,QUARTZ_STAIRS:1)
Block(-4,50,8,CONCRETE:0)
Block(-4,51,8,CONCRETE:7)
Block(-4,52,8,CONCRETE:7)
Block(-4,53,7,CONCRETE:0)
Block(-4,54,-7,TRAP_DOOR:7)
Block(-4,54,7,CONCRETE:7)
Block(-4,55,-6,LEVER:1)
Block(-4,55,6,CONCRETE:7)
Block(-4,56,-6,IRON_FENCE:0)
Block(-4,56,6,CONCRETE:7)
Block(-4,57,-6,IRON_FENCE:0)
Block(-4,57,5,CONCRETE:7)
Block(-4,58,-6,IRON_FENCE:0)
Block(-4,58,2,QUARTZ_STAIRS:6)
Block(-4,58,3,QUARTZ_STAIRS:4)
Block(-4,58,4,CONCRETE:7)
Block(-4,59,-6,IRON_FENCE:0)
Block(-4,59,2,CONCRETE:0)
Block(-4,59,3,CONCRETE:7)
Block(-4,60,-6,IRON_FENCE:0)
Block(-4,60,1,CONCRETE:7)
Block(-4,60,2,CONCRETE:7)
Block(-4,61,-6,IRON_FENCE:0)
Block(-4,61,-2,STEP:15)
Block(-4,61,-1,CONCRETE:0)
Block(-4,61,0,CONCRETE:0)
Block(-4,62,-6,CONCRETE:7)
Block(-4,62,-5,CONCRETE:7)
Block(-4,62,-4,CONCRETE:7)
Block(-4,62,-3,CONCRETE:7)
Block(-4,62,-2,CONCRETE:7)
Block(-4,63,-7,CONCRETE:7)
Block(-3,0,-7,CONCRETE:7)
Block(-3,0,-6,CONCRETE:7)
Block(-3,0,-5,CONCRETE:7)
Block(-3,0,-4,CONCRETE:7)
Block(-3,0,-3,CONCRETE:7)
Block(-3,0,-2,CONCRETE:7)
Block(-3,0,-1,CONCRETE:7)
Block(-3,0,0,CONCRETE:7)
Block(-3,0,1,CONCRETE:7)
Block(-3,0,2,CONCRETE:7)
Block(-3,0,3,CONCRETE:7)
Block(-3,0,4,CONCRETE:7)
Block(-3,0,5,CONCRETE:7)
Block(-3,0,6,CONCRETE:7)
Block(-3,0,7,CONCRETE:7)
Block(-3,0,8,CONCRETE:7)
Block(-3,1,-7,OBSIDIAN:0)
Block(-3,1,-6,OBSIDIAN:0)
Block(-3,1,-5,OBSIDIAN:0)
Block(-3,1,-4,OBSIDIAN:0)
Block(-3,1,-3,OBSIDIAN:0)
Block(-3,1,-2,OBSIDIAN:0)
Block(-3,1,-1,OBSIDIAN:0)
Block(-3,1,0,OBSIDIAN:0)
Block(-3,1,1,OBSIDIAN:0)
Block(-3,1,2,OBSIDIAN:0)
Block(-3,1,3,OBSIDIAN:0)
Block(-3,1,4,OBSIDIAN:0)
Block(-3,1,5,OBSIDIAN:0)
Block(-3,1,6,OBSIDIAN:0)
Block(-3,1,7,OBSIDIAN:0)
Block(-3,1,8,OBSIDIAN:0)
Block(-3,2,-7,OBSIDIAN:0)
Block(-3,2,-6,OBSIDIAN:0)
Block(-3,2,-5,OBSIDIAN:0)
Block(-3,2,-4,OBSIDIAN:0)
Block(-3,2,-3,OBSIDIAN:0)
Block(-3,2,-2,OBSIDIAN:0)
Block(-3,2,-1,OBSIDIAN:0)
Block(-3,2,0,OBSIDIAN:0)
Block(-3,2,1,OBSIDIAN:0)
Block(-3,2,2,CONCRETE:7)
Block(-3,2,3,CONCRETE:7)
Block(-3,2,4,CONCRETE:7)
Block(-3,2,5,CONCRETE:7)
Block(-3,2,6,CONCRETE:7)
Block(-3,2,7,CONCRETE:7)
Block(-3,2,8,CONCRETE:7)
Block(-3,3,-7,STATIONARY_LAVA:0)
Block(-3,3,-6,STATIONARY_LAVA:0)
Block(-3,3,-5,STATIONARY_LAVA:0)
Block(-3,3,-4,STATIONARY_LAVA:0)
Block(-3,3,-3,STATIONARY_LAVA:0)
Block(-3,3,-2,STATIONARY_LAVA:0)
Block(-3,3,-1,OBSIDIAN:0)
Block(-3,3,0,OBSIDIAN:0)
Block(-3,3,1,OBSIDIAN:0)
Block(-3,3,2,CONCRETE:7)
Block(-3,3,3,CONCRETE:7)
Block(-3,3,4,CONCRETE:7)
Block(-3,3,5,CONCRETE:7)
Block(-3,3,6,CONCRETE:7)
Block(-3,3,7,CONCRETE:7)
Block(-3,3,8,CONCRETE:7)
Block(-3,4,-7,OBSIDIAN:0)
Block(-3,4,-6,OBSIDIAN:0)
Block(-3,4,-5,OBSIDIAN:0)
Block(-3,4,-4,OBSIDIAN:0)
Block(-3,4,-3,OBSIDIAN:0)
Block(-3,4,-2,STATIONARY_LAVA:0)
Block(-3,4,-1,OBSIDIAN:0)
Block(-3,4,0,OBSIDIAN:0)
Block(-3,4,1,OBSIDIAN:0)
Block(-3,4,2,CONCRETE:7)
Block(-3,4,3,CONCRETE:7)
Block(-3,4,4,CONCRETE:7)
Block(-3,4,5,CONCRETE:7)
Block(-3,4,6,CONCRETE:7)
Block(-3,4,7,CONCRETE:7)
Block(-3,4,8,CONCRETE:7)
Block(-3,5,-7,CONCRETE_POWDER:4)
Block(-3,5,-6,IRON_PLATE:0)
Block(-3,5,-5,OBSIDIAN:0)
Block(-3,5,-4,STATIONARY_LAVA:0)
Block(-3,5,-3,OBSIDIAN:0)
Block(-3,5,-2,STATIONARY_LAVA:0)
Block(-3,5,-1,OBSIDIAN:0)
Block(-3,5,0,OBSIDIAN:0)
Block(-3,5,1,OBSIDIAN:0)
Block(-3,5,2,CONCRETE:7)
Block(-3,5,3,CONCRETE:7)
Block(-3,5,4,OBSIDIAN:0)
Block(-3,5,5,OBSIDIAN:0)
Block(-3,5,6,OBSIDIAN:0)
Block(-3,5,7,CONCRETE:7)
Block(-3,5,8,OBSIDIAN:0)
Block(-3,6,-7,STEP:8)
Block(-3,6,-6,AIR:0)
Block(-3,6,-5,OBSIDIAN:0)
Block(-3,6,-4,STATIONARY_LAVA:0)
Block(-3,6,-3,OBSIDIAN:0)
Block(-3,6,-2,STATIONARY_LAVA:0)
Block(-3,6,-1,OBSIDIAN:0)
Block(-3,6,0,OBSIDIAN:0)
Block(-3,6,1,OBSIDIAN:0)
Block(-3,6,2,CONCRETE:7)
Block(-3,6,3,CONCRETE:7)
Block(-3,6,4,OBSIDIAN:0)
Block(-3,6,5,OBSIDIAN:0)
Block(-3,6,6,OBSIDIAN:0)
Block(-3,6,7,CONCRETE:7)
Block(-3,6,8,OBSIDIAN:0)
Block(-3,7,-7,minecraft:yellow_glazed_terracotta:0)
Block(-3,7,-6,AIR:0)
Block(-3,7,-5,OBSIDIAN:0)
Block(-3,7,-4,STATIONARY_LAVA:0)
Block(-3,7,-3,OBSIDIAN:0)
Block(-3,7,-2,STATIONARY_LAVA:0)
Block(-3,7,-1,OBSIDIAN:0)
Block(-3,7,0,OBSIDIAN:0)
Block(-3,7,1,OBSIDIAN:0)
Block(-3,7,2,CONCRETE:7)
Block(-3,7,3,CONCRETE:7)
Block(-3,7,4,OBSIDIAN:0)
Block(-3,7,5,OBSIDIAN:0)
Block(-3,7,6,OBSIDIAN:0)
Block(-3,7,7,CONCRETE:7)
Block(-3,7,8,OBSIDIAN:0)
Block(-3,8,-7,STEP:8)
Block(-3,8,-6,AIR:0)
Block(-3,8,-5,OBSIDIAN:0)
Block(-3,8,-4,STATIONARY_LAVA:0)
Block(-3,8,-3,OBSIDIAN:0)
Block(-3,8,-2,STATIONARY_LAVA:0)
Block(-3,8,-1,OBSIDIAN:0)
Block(-3,8,0,OBSIDIAN:0)
Block(-3,8,1,OBSIDIAN:0)
Block(-3,8,2,CONCRETE:7)
Block(-3,8,3,CONCRETE:7)
Block(-3,8,4,CONCRETE:7)
Block(-3,8,5,CONCRETE:7)
Block(-3,8,6,CONCRETE:7)
Block(-3,8,7,CONCRETE:7)
Block(-3,8,8,CONCRETE:7)
Block(-3,9,-7,GOLD_PLATE:0)
Block(-3,9,-6,AIR:0)
Block(-3,9,-5,OBSIDIAN:0)
Block(-3,9,-4,STATIONARY_LAVA:0)
Block(-3,9,-3,OBSIDIAN:0)
Block(-3,9,-2,STATIONARY_LAVA:0)
Block(-3,9,-1,OBSIDIAN:0)
Block(-3,9,0,OBSIDIAN:0)
Block(-3,9,1,OBSIDIAN:0)
Block(-3,9,2,CONCRETE:7)
Block(-3,9,3,CONCRETE:7)
Block(-3,9,4,OBSIDIAN:0)
Block(-3,9,5,OBSIDIAN:0)
Block(-3,9,6,OBSIDIAN:0)
Block(-3,9,7,CONCRETE:7)
Block(-3,9,8,OBSIDIAN:0)
Block(-3,10,-7,STEP:8)
Block(-3,10,-6,STEP:8)
Block(-3,10,-5,OBSIDIAN:0)
Block(-3,10,-4,STATIONARY_LAVA:0)
Block(-3,10,-3,OBSIDIAN:0)
Block(-3,10,-2,STATIONARY_LAVA:0)
Block(-3,10,-1,OBSIDIAN:0)
Block(-3,10,0,OBSIDIAN:0)
Block(-3,10,1,OBSIDIAN:0)
Block(-3,10,2,CONCRETE:7)
Block(-3,10,3,CONCRETE:7)
Block(-3,10,4,OBSIDIAN:0)
Block(-3,10,5,OBSIDIAN:0)
Block(-3,10,6,OBSIDIAN:0)
Block(-3,10,7,CONCRETE:7)
Block(-3,10,8,OBSIDIAN:0)
Block(-3,11,-7,OBSIDIAN:0)
Block(-3,11,-6,OBSIDIAN:0)
Block(-3,11,-5,OBSIDIAN:0)
Block(-3,11,-4,OBSIDIAN:0)
Block(-3,11,-3,OBSIDIAN:0)
Block(-3,11,-2,STATIONARY_LAVA:0)
Block(-3,11,-1,OBSIDIAN:0)
Block(-3,11,0,OBSIDIAN:0)
Block(-3,11,1,OBSIDIAN:0)
Block(-3,11,2,CONCRETE:7)
Block(-3,11,3,CONCRETE:7)
Block(-3,11,4,OBSIDIAN:0)
Block(-3,11,5,OBSIDIAN:0)
Block(-3,11,6,OBSIDIAN:0)
Block(-3,11,7,CONCRETE:7)
Block(-3,11,8,OBSIDIAN:0)
Block(-3,12,-7,STATIONARY_LAVA:0)
Block(-3,12,-6,STATIONARY_LAVA:0)
Block(-3,12,-5,STATIONARY_LAVA:0)
Block(-3,12,-4,STATIONARY_LAVA:0)
Block(-3,12,-3,STATIONARY_LAVA:0)
Block(-3,12,-2,STATIONARY_LAVA:0)
Block(-3,12,-1,OBSIDIAN:0)
Block(-3,12,0,OBSIDIAN:0)
Block(-3,12,1,OBSIDIAN:0)
Block(-3,12,2,CONCRETE:7)
Block(-3,12,3,CONCRETE:7)
Block(-3,12,4,CONCRETE:7)
Block(-3,12,5,CONCRETE:7)
Block(-3,12,6,CONCRETE:7)
Block(-3,12,7,OBSIDIAN:0)
Block(-3,12,8,OBSIDIAN:0)
Block(-3,13,-7,OBSIDIAN:0)
Block(-3,13,-6,OBSIDIAN:0)
Block(-3,13,-5,OBSIDIAN:0)
Block(-3,13,-4,OBSIDIAN:0)
Block(-3,13,-3,OBSIDIAN:0)
Block(-3,13,-2,OBSIDIAN:0)
Block(-3,13,-1,OBSIDIAN:0)
Block(-3,13,0,OBSIDIAN:0)
Block(-3,13,1,OBSIDIAN:0)
Block(-3,13,2,CONCRETE:7)
Block(-3,13,3,CONCRETE:7)
Block(-3,13,4,OBSIDIAN:0)
Block(-3,13,5,OBSIDIAN:0)
Block(-3,13,6,OBSIDIAN:0)
Block(-3,13,7,OBSIDIAN:0)
Block(-3,13,8,CONCRETE:7)
Block(-3,14,-7,OBSIDIAN:0)
Block(-3,14,-6,OBSIDIAN:0)
Block(-3,14,-5,OBSIDIAN:0)
Block(-3,14,-4,OBSIDIAN:0)
Block(-3,14,-3,OBSIDIAN:0)
Block(-3,14,-2,OBSIDIAN:0)
Block(-3,14,-1,OBSIDIAN:0)
Block(-3,14,0,OBSIDIAN:0)
Block(-3,14,1,OBSIDIAN:0)
Block(-3,14,2,CONCRETE:7)
Block(-3,14,3,CONCRETE:7)
Block(-3,14,4,OBSIDIAN:0)
Block(-3,14,5,OBSIDIAN:0)
Block(-3,14,6,OBSIDIAN:0)
Block(-3,14,7,OBSIDIAN:0)
Block(-3,14,8,REDSTONE_WIRE:0)
Block(-3,15,-7,OBSIDIAN:0)
Block(-3,15,-6,OBSIDIAN:0)
Block(-3,15,-5,OBSIDIAN:0)
Block(-3,15,-4,OBSIDIAN:0)
Block(-3,15,-3,OBSIDIAN:0)
Block(-3,15,-2,OBSIDIAN:0)
Block(-3,15,-1,OBSIDIAN:0)
Block(-3,15,0,OBSIDIAN:0)
Block(-3,15,1,OBSIDIAN:0)
Block(-3,15,2,CONCRETE:7)
Block(-3,15,3,CONCRETE:7)
Block(-3,15,4,CONCRETE:12)
Block(-3,15,5,CONCRETE:7)
Block(-3,15,6,CONCRETE:7)
Block(-3,15,7,OBSIDIAN:0)
Block(-3,15,8,OBSERVER:0)
Block(-3,16,-7,OBSIDIAN:0)
Block(-3,16,-6,OBSIDIAN:0)
Block(-3,16,-5,OBSIDIAN:0)
Block(-3,16,-4,OBSIDIAN:0)
Block(-3,16,-3,OBSIDIAN:0)
Block(-3,16,-2,OBSIDIAN:0)
Block(-3,16,-1,OBSIDIAN:0)
Block(-3,16,0,OBSIDIAN:0)
Block(-3,16,1,OBSIDIAN:0)
Block(-3,16,2,OBSIDIAN:0)
Block(-3,16,3,OBSIDIAN:0)
Block(-3,16,4,OBSIDIAN:0)
Block(-3,16,5,OBSIDIAN:0)
Block(-3,16,6,OBSIDIAN:0)
Block(-3,16,7,OBSIDIAN:0)
Block(-3,16,8,PISTON_STICKY_BASE:1)
Block(-3,17,-7,CONCRETE:7)
Block(-3,17,-6,CONCRETE:7)
Block(-3,17,-5,CONCRETE:7)
Block(-3,17,-4,CONCRETE:7)
Block(-3,17,-3,CONCRETE:7)
Block(-3,17,-2,CONCRETE:7)
Block(-3,17,-1,CONCRETE:7)
Block(-3,17,0,CONCRETE:7)
Block(-3,17,1,CONCRETE:7)
Block(-3,17,2,CONCRETE:7)
Block(-3,17,3,CONCRETE:7)
Block(-3,17,4,CONCRETE:7)
Block(-3,17,5,CONCRETE:7)
Block(-3,17,6,CONCRETE:7)
Block(-3,17,7,CONCRETE:7)
Block(-3,17,8,STONE:6)
Block(-3,18,-7,CONCRETE:7)
Block(-3,18,-6,CONCRETE:7)
Block(-3,18,-5,CONCRETE:7)
Block(-3,18,-4,CONCRETE:7)
Block(-3,18,-3,CONCRETE:7)
Block(-3,18,-2,OBSIDIAN:0)
Block(-3,18,-1,OBSIDIAN:0)
Block(-3,18,0,CONCRETE:7)
Block(-3,18,1,CONCRETE:7)
Block(-3,18,2,CONCRETE:7)
Block(-3,18,3,STEP:0)
Block(-3,18,4,STEP:0)
Block(-3,18,5,STEP:0)
Block(-3,19,-7,CONCRETE:7)
Block(-3,19,-6,CONCRETE:7)
Block(-3,19,-5,CONCRETE:7)
Block(-3,19,-4,CONCRETE:7)
Block(-3,19,-3,CONCRETE:7)
Block(-3,19,-2,OBSIDIAN:0)
Block(-3,19,-1,OBSIDIAN:0)
Block(-3,19,0,CONCRETE:7)
Block(-3,19,1,CONCRETE:7)
Block(-3,19,2,CONCRETE:7)
Block(-3,19,3,IRON_FENCE:0)
Block(-3,19,4,IRON_FENCE:0)
Block(-3,19,5,IRON_FENCE:0)
Block(-3,20,-7,CONCRETE:7)
Block(-3,20,-6,CONCRETE:7)
Block(-3,20,-5,CONCRETE:7)
Block(-3,20,-4,CONCRETE:7)
Block(-3,20,-3,CONCRETE:7)
Block(-3,20,-2,OBSIDIAN:0)
Block(-3,20,-1,OBSIDIAN:0)
Block(-3,20,0,CONCRETE:7)
Block(-3,20,1,CONCRETE:7)
Block(-3,20,2,CONCRETE:7)
Block(-3,20,3,IRON_FENCE:0)
Block(-3,20,4,IRON_FENCE:0)
Block(-3,20,5,IRON_FENCE:0)
Block(-3,21,-7,CONCRETE:7)
Block(-3,21,-6,CONCRETE:7)
Block(-3,21,-5,CONCRETE:7)
Block(-3,21,-4,CONCRETE:7)
Block(-3,21,-3,CONCRETE:7)
Block(-3,21,-2,OBSIDIAN:0)
Block(-3,21,-1,OBSIDIAN:0)
Block(-3,21,0,CONCRETE:7)
Block(-3,21,1,CONCRETE:7)
Block(-3,21,2,CONCRETE:7)
Block(-3,21,3,STEP:8)
Block(-3,21,4,STEP:8)
Block(-3,21,5,STEP:8)
Block(-3,21,6,STEP:8)
Block(-3,21,7,STEP:8)
Block(-3,21,8,STEP:8)
Block(-3,22,-7,CONCRETE:12)
Block(-3,22,-6,CONCRETE:12)
Block(-3,22,-5,CONCRETE:12)
Block(-3,22,-4,CONCRETE:12)
Block(-3,22,-3,CONCRETE:12)
Block(-3,22,-2,CONCRETE:12)
Block(-3,22,-1,CONCRETE:12)
Block(-3,22,0,CONCRETE:12)
Block(-3,22,1,CONCRETE:7)
Block(-3,22,2,CONCRETE:7)
Block(-3,22,3,OBSIDIAN:0)
Block(-3,22,4,OBSIDIAN:0)
Block(-3,22,5,OBSIDIAN:0)
Block(-3,22,6,OBSIDIAN:0)
Block(-3,22,7,OBSIDIAN:0)
Block(-3,22,8,OBSIDIAN:0)
Block(-3,23,-7,OBSIDIAN:0)
Block(-3,23,-6,CONCRETE:12)
Block(-3,23,-5,OBSIDIAN:0)
Block(-3,23,-4,OBSIDIAN:0)
Block(-3,23,-3,CONCRETE:12)
Block(-3,23,-2,OBSIDIAN:0)
Block(-3,23,-1,OBSIDIAN:0)
Block(-3,23,0,CONCRETE:12)
Block(-3,23,1,OBSIDIAN:0)
Block(-3,23,2,OBSIDIAN:0)
Block(-3,23,3,OBSIDIAN:0)
Block(-3,23,4,OBSIDIAN:0)
Block(-3,23,5,OBSIDIAN:0)
Block(-3,23,6,OBSIDIAN:0)
Block(-3,23,7,OBSIDIAN:0)
Block(-3,23,8,OBSIDIAN:0)
Block(-3,24,-7,CONCRETE:0)
Block(-3,24,-6,CONCRETE:12)
Block(-3,24,-5,CONCRETE:0)
Block(-3,24,-4,CONCRETE:0)
Block(-3,24,-3,CONCRETE:12)
Block(-3,24,-2,CONCRETE:0)
Block(-3,24,-1,CONCRETE:0)
Block(-3,24,0,CONCRETE:12)
Block(-3,24,1,CONCRETE:0)
Block(-3,24,2,CONCRETE:0)
Block(-3,24,3,CONCRETE:0)
Block(-3,24,4,CONCRETE:0)
Block(-3,24,5,CONCRETE:0)
Block(-3,24,6,CONCRETE:0)
Block(-3,24,7,CONCRETE:12)
Block(-3,24,8,CONCRETE:0)
Block(-3,25,-6,DROPPER:1,NBT/skyscraper_8x6_01/523-dropperC64R48.nbt)
Block(-3,25,-5,CONCRETE:0)
Block(-3,25,-3,DROPPER:1,NBT/skyscraper_8x6_01/524-dropperC64R48.nbt)
Block(-3,25,-2,CONCRETE:0)
Block(-3,25,0,DROPPER:1,NBT/skyscraper_8x6_01/525-dropperC64R48.nbt)
Block(-3,25,1,CONCRETE:0)
Block(-3,25,3,SPRUCE_DOOR:1)
Block(-3,25,6,CONCRETE:0)
Block(-3,25,7,CONCRETE:0)
Block(-3,25,8,CONCRETE:0)
Block(-3,26,-6,TRAP_DOOR:7)
Block(-3,26,-5,CONCRETE:0)
Block(-3,26,-3,TRAP_DOOR:7)
Block(-3,26,-2,CONCRETE:0)
Block(-3,26,0,TRAP_DOOR:7)
Block(-3,26,1,CONCRETE:0)
Block(-3,26,3,SPRUCE_DOOR:8)
Block(-3,26,6,CONCRETE:0)
Block(-3,26,7,CONCRETE:0)
Block(-3,26,8,CONCRETE:0)
Block(-3,27,-7,STEP:8)
Block(-3,27,-6,STEP:8)
Block(-3,27,-5,DOUBLE_STEP:0)
Block(-3,27,-4,STEP:8)
Block(-3,27,-3,STEP:8)
Block(-3,27,-2,DOUBLE_STEP:0)
Block(-3,27,-1,STEP:8)
Block(-3,27,0,STEP:8)
Block(-3,27,1,CONCRETE:0)
Block(-3,27,2,CONCRETE:0)
Block(-3,27,3,CONCRETE:0)
Block(-3,27,4,CONCRETE:0)
Block(-3,27,5,CONCRETE:0)
Block(-3,27,6,CONCRETE:15)
Block(-3,27,7,CONCRETE:15)
Block(-3,27,8,STONE:4)
Block(-3,28,-7,CONCRETE:7)
Block(-3,28,-3,CONCRETE:7)
Block(-3,28,-2,CONCRETE:7)
Block(-3,28,-1,CONCRETE:7)
Block(-3,28,2,STAINED_GLASS_PANE:15)
Block(-3,28,3,CONCRETE:0)
Block(-3,28,4,CONCRETE:0)
Block(-3,29,-7,STAINED_GLASS_PANE:15)
Block(-3,29,-3,STAINED_GLASS_PANE:15)
Block(-3,29,-2,CONCRETE:7)
Block(-3,29,-1,STAINED_GLASS_PANE:15)
Block(-3,29,2,STAINED_GLASS_PANE:15)
Block(-3,29,3,STONE:4)
Block(-3,29,4,STONE:4)
Block(-3,30,-2,STEP:0)
Block(-3,30,2,STAINED_GLASS_PANE:15)
Block(-3,30,3,CONCRETE:0)
Block(-3,30,4,CONCRETE:0)
Block(-3,31,2,STAINED_GLASS_PANE:15)
Block(-3,31,3,CONCRETE:0)
Block(-3,31,4,CONCRETE:0)
Block(-3,32,2,STAINED_GLASS_PANE:15)
Block(-3,32,3,CONCRETE:0)
Block(-3,32,4,CONCRETE:0)
Block(-3,33,2,STEP:7)
Block(-3,33,3,CONCRETE:0)
Block(-3,33,4,CONCRETE:0)
Block(-3,34,3,CONCRETE:0)
Block(-3,34,4,CONCRETE:0)
Block(-3,35,3,CONCRETE:0)
Block(-3,35,4,CONCRETE:0)
Block(-3,36,3,CONCRETE:0)
Block(-3,36,4,CONCRETE:0)
Block(-3,37,3,CONCRETE:0)
Block(-3,37,4,CONCRETE:0)
Block(-3,38,3,CONCRETE:0)
Block(-3,38,4,CONCRETE:0)
Block(-3,39,3,CONCRETE:0)
Block(-3,39,4,CONCRETE:0)
Block(-3,40,3,CONCRETE:0)
Block(-3,40,4,CONCRETE:0)
Block(-3,41,3,CONCRETE:0)
Block(-3,41,4,CONCRETE:0)
Block(-3,42,3,COBBLE_WALL:0)
Block(-3,42,4,CONCRETE:0)
Block(-3,43,4,CONCRETE:0)
Block(-3,44,4,QUARTZ_STAIRS:2)
Block(-3,44,5,CONCRETE:0)
Block(-3,44,8,CONCRETE:7)
Block(-3,45,5,CONCRETE:0)
Block(-3,45,8,CONCRETE:7)
Block(-3,46,5,STEP:7)
Block(-3,46,6,CONCRETE:0)
Block(-3,46,8,CONCRETE:0)
Block(-3,47,6,CONCRETE:0)
Block(-3,47,7,CONCRETE:0)
Block(-3,47,8,CONCRETE:7)
Block(-3,48,-6,STEP:8)
Block(-3,48,6,STEP:7)
Block(-3,48,7,CONCRETE:0)
Block(-3,48,8,CONCRETE:7)
Block(-3,49,-7,CONCRETE:7)
Block(-3,49,-6,CONCRETE:7)
Block(-3,49,-5,CONCRETE:7)
Block(-3,49,-4,STEP:8)
Block(-3,49,7,QUARTZ_STAIRS:1)
Block(-3,49,8,CONCRETE:7)
Block(-3,50,-7,IRON_FENCE:0)
Block(-3,50,-6,IRON_FENCE:0)
Block(-3,50,-5,IRON_FENCE:0)
Block(-3,50,-4,COBBLE_WALL:0)
Block(-3,50,8,CONCRETE:0)
Block(-3,51,-4,IRON_FENCE:0)
Block(-3,51,8,CONCRETE:7)
Block(-3,52,-4,IRON_FENCE:0)
Block(-3,52,7,CONCRETE:7)
Block(-3,53,-4,IRON_FENCE:0)
Block(-3,53,7,CONCRETE:0)
Block(-3,54,-4,IRON_FENCE:0)
Block(-3,54,6,QUARTZ_STAIRS:6)
Block(-3,54,7,CONCRETE:7)
Block(-3,55,-4,IRON_FENCE:0)
Block(-3,55,6,CONCRETE:7)
Block(-3,56,-4,IRON_FENCE:0)
Block(-3,56,4,QUARTZ_STAIRS:4)
Block(-3,56,5,CONCRETE:7)
Block(-3,57,-4,IRON_FENCE:0)
Block(-3,57,3,QUARTZ_STAIRS:6)
Block(-3,57,4,CONCRETE:0)
Block(-3,57,5,CONCRETE:7)
Block(-3,58,-4,IRON_FENCE:0)
Block(-3,58,3,CONCRETE:0)
Block(-3,58,4,CONCRETE:7)
Block(-3,59,-4,IRON_FENCE:0)
Block(-3,59,2,CONCRETE:7)
Block(-3,59,3,CONCRETE:7)
Block(-3,60,-4,IRON_FENCE:0)
Block(-3,60,-2,QUARTZ_STAIRS:6)
Block(-3,60,-1,QUARTZ_STAIRS:4)
Block(-3,60,1,CONCRETE:7)
Block(-3,61,-4,CONCRETE:7)
Block(-3,61,-3,STEP:15)
Block(-3,61,-2,CONCRETE:0)
Block(-3,61,-1,CONCRETE:0)
Block(-3,61,0,CONCRETE:0)
Block(-3,62,-7,CONCRETE:7)
Block(-3,62,-6,CONCRETE:7)
Block(-3,62,-5,CONCRETE:7)
Block(-3,62,-4,CONCRETE:7)
Block(-3,62,-3,CONCRETE:7)
Block(-2,0,-7,CONCRETE:7)
Block(-2,0,-6,CONCRETE:7)
Block(-2,0,-5,CONCRETE:7)
Block(-2,0,-4,CONCRETE:7)
Block(-2,0,-3,CONCRETE:7)
Block(-2,0,-2,CONCRETE:7)
Block(-2,0,-1,CONCRETE:7)
Block(-2,0,0,CONCRETE:7)
Block(-2,0,1,CONCRETE:7)
Block(-2,0,2,CONCRETE:7)
Block(-2,0,3,CONCRETE:7)
Block(-2,0,4,CONCRETE:7)
Block(-2,0,5,CONCRETE:7)
Block(-2,0,6,CONCRETE:7)
Block(-2,0,7,CONCRETE:7)
Block(-2,0,8,CONCRETE:7)
Block(-2,1,-7,OBSIDIAN:0)
Block(-2,1,-6,OBSIDIAN:0)
Block(-2,1,-5,OBSIDIAN:0)
Block(-2,1,-4,OBSIDIAN:0)
Block(-2,1,-3,OBSIDIAN:0)
Block(-2,1,-2,OBSIDIAN:0)
Block(-2,1,-1,OBSIDIAN:0)
Block(-2,1,0,OBSIDIAN:0)
Block(-2,1,1,OBSIDIAN:0)
Block(-2,1,2,OBSIDIAN:0)
Block(-2,1,3,OBSIDIAN:0)
Block(-2,1,4,OBSIDIAN:0)
Block(-2,1,5,OBSIDIAN:0)
Block(-2,1,6,OBSIDIAN:0)
Block(-2,1,7,OBSIDIAN:0)
Block(-2,1,8,OBSIDIAN:0)
Block(-2,2,-7,OBSIDIAN:0)
Block(-2,2,-6,OBSIDIAN:0)
Block(-2,2,-5,OBSIDIAN:0)
Block(-2,2,-4,OBSIDIAN:0)
Block(-2,2,-3,OBSIDIAN:0)
Block(-2,2,-2,OBSIDIAN:0)
Block(-2,2,-1,OBSIDIAN:0)
Block(-2,2,0,OBSIDIAN:0)
Block(-2,2,1,OBSIDIAN:0)
Block(-2,2,2,CONCRETE:7)
Block(-2,2,3,CONCRETE:7)
Block(-2,2,4,CONCRETE:7)
Block(-2,2,5,CONCRETE:7)
Block(-2,2,6,CONCRETE:7)
Block(-2,2,7,CONCRETE:7)
Block(-2,2,8,CONCRETE:7)
Block(-2,3,-7,STATIONARY_LAVA:0)
Block(-2,3,-6,STATIONARY_LAVA:0)
Block(-2,3,-5,STATIONARY_LAVA:0)
Block(-2,3,-4,STATIONARY_LAVA:0)
Block(-2,3,-3,STATIONARY_LAVA:0)
Block(-2,3,-2,STATIONARY_LAVA:0)
Block(-2,3,-1,OBSIDIAN:0)
Block(-2,3,0,OBSIDIAN:0)
Block(-2,3,1,OBSIDIAN:0)
Block(-2,3,2,CONCRETE:7)
Block(-2,3,3,CONCRETE:7)
Block(-2,3,4,CONCRETE:7)
Block(-2,3,5,CONCRETE:7)
Block(-2,3,6,CONCRETE:7)
Block(-2,3,7,CONCRETE:7)
Block(-2,3,8,CONCRETE:7)
Block(-2,4,-7,OBSIDIAN:0)
Block(-2,4,-6,OBSIDIAN:0)
Block(-2,4,-5,OBSIDIAN:0)
Block(-2,4,-4,OBSIDIAN:0)
Block(-2,4,-3,OBSIDIAN:0)
Block(-2,4,-2,STATIONARY_LAVA:0)
Block(-2,4,-1,OBSIDIAN:0)
Block(-2,4,0,OBSIDIAN:0)
Block(-2,4,1,OBSIDIAN:0)
Block(-2,4,2,CONCRETE:7)
Block(-2,4,3,CONCRETE:7)
Block(-2,4,4,CONCRETE:7)
Block(-2,4,5,CONCRETE:7)
Block(-2,4,6,CONCRETE:7)
Block(-2,4,7,CONCRETE:7)
Block(-2,4,8,CONCRETE:7)
Block(-2,5,-7,minecraft:yellow_glazed_terracotta:0)
Block(-2,5,-6,IRON_PLATE:0)
Block(-2,5,-5,OBSIDIAN:0)
Block(-2,5,-4,STATIONARY_LAVA:0)
Block(-2,5,-3,OBSIDIAN:0)
Block(-2,5,-2,STATIONARY_LAVA:0)
Block(-2,5,-1,OBSIDIAN:0)
Block(-2,5,0,OBSIDIAN:0)
Block(-2,5,1,OBSIDIAN:0)
Block(-2,5,2,CONCRETE:7)
Block(-2,5,3,CONCRETE:7)
Block(-2,5,4,OBSIDIAN:0)
Block(-2,5,5,OBSIDIAN:0)
Block(-2,5,6,OBSIDIAN:0)
Block(-2,5,7,CONCRETE:7)
Block(-2,5,8,OBSIDIAN:0)
Block(-2,6,-7,STEP:8)
Block(-2,6,-6,AIR:0)
Block(-2,6,-5,OBSIDIAN:0)
Block(-2,6,-4,STATIONARY_LAVA:0)
Block(-2,6,-3,OBSIDIAN:0)
Block(-2,6,-2,STATIONARY_LAVA:0)
Block(-2,6,-1,OBSIDIAN:0)
Block(-2,6,0,OBSIDIAN:0)
Block(-2,6,1,OBSIDIAN:0)
Block(-2,6,2,CONCRETE:7)
Block(-2,6,3,CONCRETE:7)
Block(-2,6,4,OBSIDIAN:0)
Block(-2,6,5,OBSIDIAN:0)
Block(-2,6,6,OBSIDIAN:0)
Block(-2,6,7,CONCRETE:7)
Block(-2,6,8,OBSIDIAN:0)
Block(-2,7,-7,GOLD_PLATE:0)
Block(-2,7,-6,AIR:0)
Block(-2,7,-5,OBSIDIAN:0)
Block(-2,7,-4,STATIONARY_LAVA:0)
Block(-2,7,-3,OBSIDIAN:0)
Block(-2,7,-2,STATIONARY_LAVA:0)
Block(-2,7,-1,OBSIDIAN:0)
Block(-2,7,0,OBSIDIAN:0)
Block(-2,7,1,OBSIDIAN:0)
Block(-2,7,2,CONCRETE:7)
Block(-2,7,3,CONCRETE:7)
Block(-2,7,4,OBSIDIAN:0)
Block(-2,7,5,OBSIDIAN:0)
Block(-2,7,6,OBSIDIAN:0)
Block(-2,7,7,CONCRETE:7)
Block(-2,7,8,OBSIDIAN:0)
Block(-2,8,-7,STEP:8)
Block(-2,8,-6,AIR:0)
Block(-2,8,-5,OBSIDIAN:0)
Block(-2,8,-4,STATIONARY_LAVA:0)
Block(-2,8,-3,OBSIDIAN:0)
Block(-2,8,-2,STATIONARY_LAVA:0)
Block(-2,8,-1,OBSIDIAN:0)
Block(-2,8,0,OBSIDIAN:0)
Block(-2,8,1,OBSIDIAN:0)
Block(-2,8,2,CONCRETE:7)
Block(-2,8,3,CONCRETE:7)
Block(-2,8,4,CONCRETE:7)
Block(-2,8,5,CONCRETE:7)
Block(-2,8,6,CONCRETE:7)
Block(-2,8,7,CONCRETE:7)
Block(-2,8,8,CONCRETE:7)
Block(-2,9,-7,minecraft:yellow_glazed_terracotta:0)
Block(-2,9,-6,AIR:0)
Block(-2,9,-5,OBSIDIAN:0)
Block(-2,9,-4,STATIONARY_LAVA:0)
Block(-2,9,-3,OBSIDIAN:0)
Block(-2,9,-2,STATIONARY_LAVA:0)
Block(-2,9,-1,OBSIDIAN:0)
Block(-2,9,0,OBSIDIAN:0)
Block(-2,9,1,OBSIDIAN:0)
Block(-2,9,2,CONCRETE:7)
Block(-2,9,3,CONCRETE:7)
Block(-2,9,4,OBSIDIAN:0)
Block(-2,9,5,OBSIDIAN:0)
Block(-2,9,6,OBSIDIAN:0)
Block(-2,9,7,CONCRETE:7)
Block(-2,9,8,OBSIDIAN:0)
Block(-2,10,-7,STEP:8)
Block(-2,10,-6,STEP:8)
Block(-2,10,-5,OBSIDIAN:0)
Block(-2,10,-4,STATIONARY_LAVA:0)
Block(-2,10,-3,OBSIDIAN:0)
Block(-2,10,-2,STATIONARY_LAVA:0)
Block(-2,10,-1,OBSIDIAN:0)
Block(-2,10,0,OBSIDIAN:0)
Block(-2,10,1,OBSIDIAN:0)
Block(-2,10,2,CONCRETE:7)
Block(-2,10,3,CONCRETE:7)
Block(-2,10,4,OBSIDIAN:0)
Block(-2,10,5,OBSIDIAN:0)
Block(-2,10,6,OBSIDIAN:0)
Block(-2,10,7,CONCRETE:7)
Block(-2,10,8,OBSIDIAN:0)
Block(-2,11,-7,OBSIDIAN:0)
Block(-2,11,-6,OBSIDIAN:0)
Block(-2,11,-5,OBSIDIAN:0)
Block(-2,11,-4,OBSIDIAN:0)
Block(-2,11,-3,OBSIDIAN:0)
Block(-2,11,-2,STATIONARY_LAVA:0)
Block(-2,11,-1,OBSIDIAN:0)
Block(-2,11,0,OBSIDIAN:0)
Block(-2,11,1,OBSIDIAN:0)
Block(-2,11,2,CONCRETE:7)
Block(-2,11,3,CONCRETE:7)
Block(-2,11,4,OBSIDIAN:0)
Block(-2,11,5,OBSIDIAN:0)
Block(-2,11,6,OBSIDIAN:0)
Block(-2,11,7,CONCRETE:7)
Block(-2,11,8,OBSIDIAN:0)
Block(-2,12,-7,STATIONARY_LAVA:0)
Block(-2,12,-6,STATIONARY_LAVA:0)
Block(-2,12,-5,STATIONARY_LAVA:0)
Block(-2,12,-4,STATIONARY_LAVA:0)
Block(-2,12,-3,STATIONARY_LAVA:0)
Block(-2,12,-2,STATIONARY_LAVA:0)
Block(-2,12,-1,OBSIDIAN:0)
Block(-2,12,0,OBSIDIAN:0)
Block(-2,12,1,OBSIDIAN:0)
Block(-2,12,2,CONCRETE:7)
Block(-2,12,3,CONCRETE:7)
Block(-2,12,4,CONCRETE:7)
Block(-2,12,5,CONCRETE:7)
Block(-2,12,6,CONCRETE:7)
Block(-2,12,7,OBSIDIAN:0)
Block(-2,12,8,OBSIDIAN:0)
Block(-2,13,-7,OBSIDIAN:0)
Block(-2,13,-6,OBSIDIAN:0)
Block(-2,13,-5,OBSIDIAN:0)
Block(-2,13,-4,OBSIDIAN:0)
Block(-2,13,-3,OBSIDIAN:0)
Block(-2,13,-2,OBSIDIAN:0)
Block(-2,13,-1,OBSIDIAN:0)
Block(-2,13,0,OBSIDIAN:0)
Block(-2,13,1,OBSIDIAN:0)
Block(-2,13,2,CONCRETE:7)
Block(-2,13,3,CONCRETE:7)
Block(-2,13,4,OBSIDIAN:0)
Block(-2,13,5,OBSIDIAN:0)
Block(-2,13,6,OBSIDIAN:0)
Block(-2,13,7,OBSIDIAN:0)
Block(-2,13,8,CONCRETE:7)
Block(-2,14,-7,OBSIDIAN:0)
Block(-2,14,-6,OBSIDIAN:0)
Block(-2,14,-5,OBSIDIAN:0)
Block(-2,14,-4,OBSIDIAN:0)
Block(-2,14,-3,OBSIDIAN:0)
Block(-2,14,-2,OBSIDIAN:0)
Block(-2,14,-1,OBSIDIAN:0)
Block(-2,14,0,OBSIDIAN:0)
Block(-2,14,1,OBSIDIAN:0)
Block(-2,14,2,CONCRETE:7)
Block(-2,14,3,CONCRETE:7)
Block(-2,14,4,OBSIDIAN:0)
Block(-2,14,5,OBSIDIAN:0)
Block(-2,14,6,OBSIDIAN:0)
Block(-2,14,7,OBSIDIAN:0)
Block(-2,14,8,REDSTONE_WIRE:0)
Block(-2,15,-7,OBSIDIAN:0)
Block(-2,15,-6,OBSIDIAN:0)
Block(-2,15,-5,OBSIDIAN:0)
Block(-2,15,-4,OBSIDIAN:0)
Block(-2,15,-3,OBSIDIAN:0)
Block(-2,15,-2,OBSIDIAN:0)
Block(-2,15,-1,OBSIDIAN:0)
Block(-2,15,0,OBSIDIAN:0)
Block(-2,15,1,OBSIDIAN:0)
Block(-2,15,2,CONCRETE:7)
Block(-2,15,3,CONCRETE:7)
Block(-2,15,4,CONCRETE:12)
Block(-2,15,5,CONCRETE:7)
Block(-2,15,6,CONCRETE:7)
Block(-2,15,7,OBSIDIAN:0)
Block(-2,15,8,OBSERVER:0)
Block(-2,16,-7,OBSIDIAN:0)
Block(-2,16,-6,OBSIDIAN:0)
Block(-2,16,-5,OBSIDIAN:0)
Block(-2,16,-4,OBSIDIAN:0)
Block(-2,16,-3,OBSIDIAN:0)
Block(-2,16,-2,OBSIDIAN:0)
Block(-2,16,-1,OBSIDIAN:0)
Block(-2,16,0,OBSIDIAN:0)
Block(-2,16,1,OBSIDIAN:0)
Block(-2,16,2,OBSIDIAN:0)
Block(-2,16,3,OBSIDIAN:0)
Block(-2,16,4,OBSIDIAN:0)
Block(-2,16,5,OBSIDIAN:0)
Block(-2,16,6,OBSIDIAN:0)
Block(-2,16,7,OBSIDIAN:0)
Block(-2,16,8,PISTON_STICKY_BASE:1)
Block(-2,17,-7,CONCRETE:7)
Block(-2,17,-6,CONCRETE:7)
Block(-2,17,-5,CONCRETE:7)
Block(-2,17,-4,CONCRETE:7)
Block(-2,17,-3,CONCRETE:7)
Block(-2,17,-2,CONCRETE:7)
Block(-2,17,-1,CONCRETE:7)
Block(-2,17,0,CONCRETE:7)
Block(-2,17,1,CONCRETE:7)
Block(-2,17,2,CONCRETE:7)
Block(-2,17,3,CONCRETE:7)
Block(-2,17,4,CONCRETE:7)
Block(-2,17,5,CONCRETE:7)
Block(-2,17,6,CONCRETE:7)
Block(-2,17,7,CONCRETE:7)
Block(-2,17,8,STONE:6)
Block(-2,18,-7,CONCRETE:7)
Block(-2,18,-6,CONCRETE:7)
Block(-2,18,-5,CONCRETE:7)
Block(-2,18,-4,CONCRETE:7)
Block(-2,18,-3,OBSIDIAN:0)
Block(-2,18,-2,OBSIDIAN:0)
Block(-2,18,-1,CONCRETE:7)
Block(-2,18,0,CONCRETE:7)
Block(-2,18,1,STEP:0)
Block(-2,18,2,STEP:0)
Block(-2,19,-7,CONCRETE:7)
Block(-2,19,-6,CONCRETE:7)
Block(-2,19,-5,CONCRETE:7)
Block(-2,19,-4,CONCRETE:7)
Block(-2,19,-3,OBSIDIAN:0)
Block(-2,19,-2,OBSIDIAN:0)
Block(-2,19,-1,CONCRETE:7)
Block(-2,19,0,CONCRETE:7)
Block(-2,19,1,IRON_FENCE:0)
Block(-2,19,2,IRON_FENCE:0)
Block(-2,20,-7,CONCRETE:7)
Block(-2,20,-6,CONCRETE:7)
Block(-2,20,-5,CONCRETE:7)
Block(-2,20,-4,CONCRETE:7)
Block(-2,20,-3,OBSIDIAN:0)
Block(-2,20,-2,OBSIDIAN:0)
Block(-2,20,-1,CONCRETE:7)
Block(-2,20,0,CONCRETE:7)
Block(-2,20,1,IRON_FENCE:0)
Block(-2,20,2,IRON_FENCE:0)
Block(-2,21,-7,CONCRETE:7)
Block(-2,21,-6,CONCRETE:7)
Block(-2,21,-5,CONCRETE:7)
Block(-2,21,-4,CONCRETE:7)
Block(-2,21,-3,OBSIDIAN:0)
Block(-2,21,-2,OBSIDIAN:0)
Block(-2,21,-1,CONCRETE:7)
Block(-2,21,0,CONCRETE:7)
Block(-2,21,1,STEP:8)
Block(-2,21,2,STEP:8)
Block(-2,21,3,STEP:8)
Block(-2,21,4,STEP:8)
Block(-2,21,5,STEP:8)
Block(-2,21,6,STEP:8)
Block(-2,21,7,STEP:8)
Block(-2,21,8,STEP:8)
Block(-2,22,-7,CONCRETE:7)
Block(-2,22,-6,CONCRETE:7)
Block(-2,22,-5,CONCRETE:7)
Block(-2,22,-4,CONCRETE:7)
Block(-2,22,-3,OBSIDIAN:0)
Block(-2,22,-2,OBSIDIAN:0)
Block(-2,22,-1,CONCRETE:7)
Block(-2,22,0,CONCRETE:7)
Block(-2,22,1,OBSIDIAN:0)
Block(-2,22,2,OBSIDIAN:0)
Block(-2,22,3,OBSIDIAN:0)
Block(-2,22,4,OBSIDIAN:0)
Block(-2,22,5,OBSIDIAN:0)
Block(-2,22,6,OBSIDIAN:0)
Block(-2,22,7,OBSIDIAN:0)
Block(-2,22,8,OBSIDIAN:0)
Block(-2,23,-7,OBSIDIAN:0)
Block(-2,23,-6,OBSIDIAN:0)
Block(-2,23,-5,OBSIDIAN:0)
Block(-2,23,-4,OBSIDIAN:0)
Block(-2,23,-3,OBSIDIAN:0)
Block(-2,23,-2,OBSIDIAN:0)
Block(-2,23,-1,OBSIDIAN:0)
Block(-2,23,0,OBSIDIAN:0)
Block(-2,23,1,OBSIDIAN:0)
Block(-2,23,2,OBSIDIAN:0)
Block(-2,23,3,OBSIDIAN:0)
Block(-2,23,4,OBSIDIAN:0)
Block(-2,23,5,OBSIDIAN:0)
Block(-2,23,6,OBSIDIAN:0)
Block(-2,23,7,OBSIDIAN:0)
Block(-2,23,8,OBSIDIAN:0)
Block(-2,24,-7,CONCRETE:0)
Block(-2,24,-6,CONCRETE:0)
Block(-2,24,-5,CONCRETE:0)
Block(-2,24,-4,CONCRETE:0)
Block(-2,24,-3,CONCRETE:0)
Block(-2,24,-2,CONCRETE:0)
Block(-2,24,-1,CONCRETE:0)
Block(-2,24,0,CONCRETE:0)
Block(-2,24,1,CONCRETE:0)
Block(-2,24,2,CONCRETE:0)
Block(-2,24,3,CONCRETE:0)
Block(-2,24,4,CONCRETE:0)
Block(-2,24,5,CONCRETE:0)
Block(-2,24,6,CONCRETE:0)
Block(-2,24,7,CONCRETE:12)
Block(-2,24,8,CONCRETE:0)
Block(-2,25,-6,STEP:0)
Block(-2,25,-5,CONCRETE:0)
Block(-2,25,-3,STEP:0)
Block(-2,25,-2,CONCRETE:0)
Block(-2,25,0,STEP:0)
Block(-2,25,1,CONCRETE:0)
Block(-2,25,3,CONCRETE:0)
Block(-2,25,6,CONCRETE:0)
Block(-2,25,7,DROPPER:1,NBT/skyscraper_8x6_01/536-dropperC64R48.nbt)
Block(-2,25,8,STEP:0)
