
#######################################################################
# +-----------------------------------------------------------------+ #
# |                            BO4 object                           | #
# +-----------------------------------------------------------------+ #
#######################################################################

Author: NLBlackEagle

Description: No description given

SettingsMode: WriteDisable


#######################################################################
# +-----------------------------------------------------------------+ #
# |                          Main settings                          | #
# +-----------------------------------------------------------------+ #
#######################################################################

Frequency: 0

SpawnHeight: highestBlock

UseCenterForHighestBlock: true

##############################
# Height Limits for the BO4. #
##############################

MinHeight: 0

MaxHeight: 255

InheritBO3: 

InheritBO3Rotation: NORTH

OverrideChildSettings: true

OverrideParentHeight: false

CanOverride: true

BranchFrequency: 0

BranchFrequencyGroup: 

MustBeBelowOther: false

MustBeInside: 

CannotBeInside: 

ReplacesBO3: L4-M-CrossC0R0, L4-M-CrossC0R1, L4-M-CrossC0R2, L4-M-CrossC0R3, L4-M-CrossC1R0, L4-M-CrossC1R1, L4-M-CrossC1R2, L4-M-CrossC1R3, L4-M-CrossC2R0, L4-M-CrossC2R1, L4-M-CrossC2R2, L4-M-CrossC2R3, L4-M-CrossC3R0, L4-M-CrossC3R1, L4-M-CrossC3R2, L4-M-CrossC3R3, L4-M-Straigth-START_01-C0R0, L4-M-Straigth-START_01-C0R1, L4-M-Straigth-START_01-C1R0, L4-M-Straigth-START_01-C1R1, L4-M-Straigth-START_01-C2R0, L4-M-Straigth-START_01-C2R1, L4-M-Straigth-START_01-C3R0, L4-M-Straigth-START_01-C3R1, L4-M-Straigth-3CC0R0, L4-M-Straigth-3CC0R1, L4-M-Straigth-3CC0R2, L4-M-Straigth-3CC1R0, L4-M-Straigth-3CC1R1, L4-M-Straigth-3CC1R2, L4-M-Straigth-3CC2R0, L4-M-Straigth-3CC2R1, L4-M-Straigth-3CC2R2, L4-M-Straigth-3CC3R0, L4-M-Straigth-3CC3R1, L4-M-Straigth-3CC3R2, L4-M-Cross, skyscraper_2x2_01, skyscraper_2x2_02, skyscraper_2x2_03, skyscraper_2x2_04, skyscraper_2x2_05, skyscraper_3x3_01, skyscraper_3x3_02, skyscraper_3x3_03, L3-M-Straigth-2CC0R0, L3-M-Straigth-2CC0R1, L3-M-Straigth-2CC1R0, L3-M-Straigth-2CC1R1, L3-M-Straigth-2CC2R0, L3-M-Straigth-2CC2R1, L3-M-Straigth-2CC3R0, L3-M-Straigth-2CC3R1, L3-M-Straigth-3CC0R0, L3-M-Straigth-3CC0R1, L3-M-Straigth-3CC0R2, L3-M-Straigth-3CC1R0, L3-M-Straigth-3CC1R1, L3-M-Straigth-3CC1R2, L3-M-Straigth-3CC2R0, L3-M-Straigth-3CC2R1, L3-M-Straigth-3CC2R2, L3-M-Straigth-3CC3R0, L3-M-Straigth-3CC3R1, L3-M-Straigth-3CC3R2L4-M-CrossC0R0, L4-M-CrossC0R1, L4-M-CrossC0R2, L4-M-CrossC0R3, L4-M-CrossC1R0, L4-M-CrossC1R1, L4-M-CrossC1R2, L4-M-CrossC1R3, L4-M-CrossC2R0, L4-M-CrossC2R1, L4-M-CrossC2R2, L4-M-CrossC2R3, L4-M-CrossC3R0, L4-M-CrossC3R1, L4-M-CrossC3R2, L4-M-CrossC3R3, L4-M-Straigth-START_01-C0R0, L4-M-Straigth-START_01-C0R1, L4-M-Straigth-START_01-C1R0, L4-M-Straigth-START_01-C1R1, L4-M-Straigth-START_01-C2R0, L4-M-Straigth-START_01-C2R1, L4-M-Straigth-START_01-C3R0, L4-M-Straigth-START_01-C3R1, L4-M-Straigth-3CC0R0, L4-M-Straigth-3CC0R1, L4-M-Straigth-3CC0R2, L4-M-Straigth-3CC1R0, L4-M-Straigth-3CC1R1, L4-M-Straigth-3CC1R2, L4-M-Straigth-3CC2R0, L4-M-Straigth-3CC2R1, L4-M-Straigth-3CC2R2, L4-M-Straigth-3CC3R0, L4-M-Straigth-3CC3R1, L4-M-Straigth-3CC3R2, L4-M-Cross, skyscraper_2x2_01, skyscraper_2x2_02, skyscraper_2x2_03, skyscraper_2x2_04, skyscraper_2x2_05, skyscraper_3x3_01, skyscraper_3x3_02, skyscraper_3x3_03

MustBeInsideWorldBorders: false

CanSpawnOnWater: true

SpawnOnWaterOnly: false

SpawnUnderWater: false

SpawnAtWaterLevel: false

HeightOffset: 0

RemoveAir: false

ReplaceAbove: 

ReplaceBelow: 

ReplaceWithBiomeBlocks: true

ReplaceWithSurfaceBlock: GRASS

ReplaceWithGroundBlock: DIRT

ReplaceWithStoneBlock: STONE

SmoothRadius: 0

SmoothHeightOffset: 0

SmoothStartTop: false

SmoothStartWood: false

SmoothingSurfaceBlock: 

SmoothingGroundBlock: 

BO3Group: 

IsSpawnPoint: false

DoReplaceBlocks: true


#######################################################################
# +-----------------------------------------------------------------+ #
# |                              Blocks                             | #
# +-----------------------------------------------------------------+ #
#######################################################################

Block(-8,0,-7,CONCRETE:7)
Block(-8,0,-6,CONCRETE:7)
Block(-8,0,-5,CONCRETE:7)
Block(-8,0,-4,CONCRETE:7)
Block(-8,0,-3,CONCRETE:7)
Block(-8,0,-2,CONCRETE:7)
Block(-8,0,-1,CONCRETE:7)
Block(-8,0,0,CONCRETE:7)
Block(-8,0,1,CONCRETE:7)
Block(-8,0,2,CONCRETE:7)
Block(-8,0,3,CONCRETE:7)
Block(-8,0,4,CONCRETE:7)
Block(-8,0,5,CONCRETE:7)
Block(-8,0,6,CONCRETE:7)
Block(-8,0,7,CONCRETE:7)
Block(-8,0,8,CONCRETE:7)
Block(-8,1,-7,OBSIDIAN:0)
Block(-8,1,-6,OBSIDIAN:0)
Block(-8,1,-5,OBSIDIAN:0)
Block(-8,1,-4,OBSIDIAN:0)
Block(-8,1,-3,OBSIDIAN:0)
Block(-8,1,-2,OBSIDIAN:0)
Block(-8,1,-1,OBSIDIAN:0)
Block(-8,1,0,OBSIDIAN:0)
Block(-8,1,1,OBSIDIAN:0)
Block(-8,1,2,OBSIDIAN:0)
Block(-8,1,3,OBSIDIAN:0)
Block(-8,1,4,OBSIDIAN:0)
Block(-8,1,5,OBSIDIAN:0)
Block(-8,1,6,OBSIDIAN:0)
Block(-8,1,7,OBSIDIAN:0)
Block(-8,1,8,OBSIDIAN:0)
Block(-8,2,-7,OBSIDIAN:0)
Block(-8,2,-6,OBSIDIAN:0)
Block(-8,2,-5,OBSIDIAN:0)
Block(-8,2,-4,OBSIDIAN:0)
Block(-8,2,-3,OBSIDIAN:0)
Block(-8,2,-2,CONCRETE:7)
Block(-8,2,-1,CONCRETE:7)
Block(-8,2,0,CONCRETE:7)
Block(-8,2,1,CONCRETE:7)
Block(-8,2,2,CONCRETE:7)
Block(-8,2,3,CONCRETE:7)
Block(-8,2,4,CONCRETE:7)
Block(-8,2,5,CONCRETE:7)
Block(-8,2,6,CONCRETE:7)
Block(-8,2,7,CONCRETE:7)
Block(-8,2,8,CONCRETE:7)
Block(-8,3,-7,CONCRETE:7)
Block(-8,3,-6,CONCRETE:7)
Block(-8,3,-5,CONCRETE:7)
Block(-8,3,-4,CONCRETE:7)
Block(-8,3,-3,OBSIDIAN:0)
Block(-8,3,-2,CONCRETE:7)
Block(-8,3,-1,CONCRETE:7)
Block(-8,3,0,CONCRETE:7)
Block(-8,3,1,CONCRETE:7)
Block(-8,3,2,CONCRETE:7)
Block(-8,3,3,CONCRETE:7)
Block(-8,3,4,CONCRETE:7)
Block(-8,3,5,CONCRETE:7)
Block(-8,3,6,CONCRETE:7)
Block(-8,3,7,CONCRETE:7)
Block(-8,3,8,CONCRETE:7)
Block(-8,4,-7,CONCRETE:7)
Block(-8,4,-6,CONCRETE:7)
Block(-8,4,-5,CONCRETE:7)
Block(-8,4,-4,CONCRETE:7)
Block(-8,4,-3,OBSIDIAN:0)
Block(-8,4,-2,CONCRETE:7)
Block(-8,4,-1,CONCRETE:7)
Block(-8,4,0,CONCRETE:7)
Block(-8,4,1,CONCRETE:7)
Block(-8,4,2,CONCRETE:7)
Block(-8,4,3,CONCRETE:7)
Block(-8,4,4,CONCRETE:7)
Block(-8,4,5,CONCRETE:7)
Block(-8,4,6,CONCRETE:7)
Block(-8,4,7,CONCRETE:7)
Block(-8,4,8,CONCRETE:7)
Block(-8,5,-7,AIR:0)
Block(-8,5,-6,AIR:0)
Block(-8,5,-5,AIR:0)
Block(-8,5,-4,CONCRETE:7)
Block(-8,5,-3,OBSIDIAN:0)
Block(-8,5,-2,CONCRETE:7)
Block(-8,5,-1,CONCRETE:7)
Block(-8,5,0,CONCRETE:7)
Block(-8,5,1,AIR:0)
Block(-8,5,2,AIR:0)
Block(-8,5,3,AIR:0)
Block(-8,5,4,AIR:0)
Block(-8,5,5,AIR:0)
Block(-8,5,6,AIR:0)
Block(-8,5,7,AIR:0)
Block(-8,5,8,AIR:0)
Block(-8,6,-7,AIR:0)
Block(-8,6,-6,STONE_BUTTON:2)
Block(-8,6,-5,AIR:0)
Block(-8,6,-4,CONCRETE:7)
Block(-8,6,-3,OBSIDIAN:0)
Block(-8,6,-2,CONCRETE:7)
Block(-8,6,-1,CONCRETE:7)
Block(-8,6,0,CONCRETE:7)
Block(-8,6,1,AIR:0)
Block(-8,6,2,AIR:0)
Block(-8,6,3,AIR:0)
Block(-8,6,4,AIR:0)
Block(-8,6,5,AIR:0)
Block(-8,6,6,AIR:0)
Block(-8,6,7,AIR:0)
Block(-8,6,8,AIR:0)
Block(-8,7,-7,STEP:8)
Block(-8,7,-6,AIR:0)
Block(-8,7,-5,AIR:0)
Block(-8,7,-4,CONCRETE:7)
Block(-8,7,-3,OBSIDIAN:0)
Block(-8,7,-2,CONCRETE:7)
Block(-8,7,-1,CONCRETE:7)
Block(-8,7,0,CONCRETE:7)
Block(-8,7,1,AIR:0)
Block(-8,7,2,AIR:0)
Block(-8,7,3,AIR:0)
Block(-8,7,4,AIR:0)
Block(-8,7,5,AIR:0)
Block(-8,7,6,AIR:0)
Block(-8,7,7,AIR:0)
Block(-8,7,8,AIR:0)
Block(-8,8,-7,CONCRETE:7)
Block(-8,8,-6,STEP:8)
Block(-8,8,-5,STEP:8)
Block(-8,8,-4,CONCRETE:7)
Block(-8,8,-3,OBSIDIAN:0)
Block(-8,8,-2,OBSIDIAN:0)
Block(-8,8,-1,CONCRETE:7)
Block(-8,8,0,CONCRETE:7)
Block(-8,8,1,AIR:0)
Block(-8,8,2,AIR:0)
Block(-8,8,3,AIR:0)
Block(-8,8,4,AIR:0)
Block(-8,8,5,AIR:0)
Block(-8,8,6,AIR:0)
Block(-8,8,7,AIR:0)
Block(-8,8,8,AIR:0)
Block(-8,9,-7,CONCRETE:7)
Block(-8,9,-6,CONCRETE:7)
Block(-8,9,-5,CONCRETE:7)
Block(-8,9,-4,CONCRETE:7)
Block(-8,9,-3,OBSIDIAN:0)
Block(-8,9,-2,CONCRETE:7)
Block(-8,9,-1,CONCRETE:7)
Block(-8,9,0,CONCRETE:7)
Block(-8,9,1,IRON_TRAPDOOR:9)
Block(-8,9,2,AIR:0)
Block(-8,9,3,AIR:0)
Block(-8,9,4,AIR:0)
Block(-8,9,5,AIR:0)
Block(-8,9,6,AIR:0)
Block(-8,9,7,AIR:0)
Block(-8,9,8,AIR:0)
Block(-8,10,-7,AIR:0)
Block(-8,10,-6,AIR:0)
Block(-8,10,-5,AIR:0)
Block(-8,10,-4,CONCRETE:7)
Block(-8,10,-3,OBSIDIAN:0)
Block(-8,10,-2,CONCRETE:7)
Block(-8,10,-1,CONCRETE:7)
Block(-8,10,0,CONCRETE:7)
Block(-8,10,1,CONCRETE:14)
Block(-8,10,2,AIR:0)
Block(-8,10,3,AIR:0)
Block(-8,10,4,IRON_TRAPDOOR:9)
Block(-8,10,5,AIR:0)
Block(-8,10,6,AIR:0)
Block(-8,10,7,AIR:0)
Block(-8,10,8,AIR:0)
Block(-8,11,-7,AIR:0)
Block(-8,11,-6,AIR:0)
Block(-8,11,-5,AIR:0)
Block(-8,11,-4,CONCRETE:7)
Block(-8,11,-3,OBSIDIAN:0)
Block(-8,11,-2,OBSIDIAN:0)
Block(-8,11,-1,CONCRETE:7)
Block(-8,11,0,CONCRETE:7)
Block(-8,11,1,IRON_FENCE:0)
Block(-8,11,2,AIR:0)
Block(-8,11,3,AIR:0)
Block(-8,11,4,CONCRETE:4)
Block(-8,11,5,AIR:0)
Block(-8,11,6,AIR:0)
Block(-8,11,7,AIR:0)
Block(-8,11,8,AIR:0)
Block(-8,12,-7,AIR:0)
Block(-8,12,-6,AIR:0)
Block(-8,12,-5,AIR:0)
Block(-8,12,-4,CONCRETE:7)
Block(-8,12,-3,OBSIDIAN:0)
Block(-8,12,-2,CONCRETE:7)
Block(-8,12,-1,CONCRETE:7)
Block(-8,12,0,CONCRETE:7)
Block(-8,12,1,CONCRETE:7)
Block(-8,12,2,CONCRETE:7)
Block(-8,12,3,CONCRETE:7)
Block(-8,12,4,CONCRETE:7)
Block(-8,12,5,CONCRETE:7)
Block(-8,12,6,CONCRETE:7)
Block(-8,12,7,CONCRETE:7)
Block(-8,12,8,CONCRETE:7)
Block(-8,13,-7,STEP:8)
Block(-8,13,-6,AIR:0)
Block(-8,13,-5,AIR:0)
Block(-8,13,-4,CONCRETE:7)
Block(-8,13,-3,OBSIDIAN:0)
Block(-8,13,-2,CONCRETE:7)
Block(-8,13,-1,CONCRETE:7)
Block(-8,13,0,CONCRETE:7)
Block(-8,13,1,AIR:0)
Block(-8,13,2,AIR:0)
Block(-8,13,3,AIR:0)
Block(-8,13,4,AIR:0)
Block(-8,13,5,AIR:0)
Block(-8,13,6,AIR:0)
Block(-8,13,7,AIR:0)
Block(-8,13,8,AIR:0)
Block(-8,14,-7,CONCRETE:7)
Block(-8,14,-6,AIR:0)
Block(-8,14,-5,AIR:0)
Block(-8,14,-4,CONCRETE:7)
Block(-8,14,-3,OBSIDIAN:0)
Block(-8,14,-2,CONCRETE:7)
Block(-8,14,-1,CONCRETE:7)
Block(-8,14,0,CONCRETE:7)
Block(-8,14,1,CONCRETE:7)
Block(-8,14,2,CONCRETE:7)
Block(-8,14,3,CONCRETE:7)
Block(-8,14,4,CONCRETE:7)
Block(-8,14,5,CONCRETE:7)
Block(-8,14,6,CONCRETE:7)
Block(-8,14,7,CONCRETE:7)
Block(-8,14,8,CONCRETE:7)
Block(-8,15,-7,TRAP_DOOR:15)
Block(-8,15,-6,TRAP_DOOR:7)
Block(-8,15,-5,AIR:0)
Block(-8,15,-4,CONCRETE:7)
Block(-8,15,-3,OBSIDIAN:0)
Block(-8,15,-2,CONCRETE:7)
Block(-8,15,-1,CONCRETE:7)
Block(-8,15,0,CONCRETE:7)
Block(-8,15,1,CONCRETE:7)
Block(-8,15,2,CONCRETE:7)
Block(-8,15,3,CONCRETE:7)
Block(-8,15,4,CONCRETE:7)
Block(-8,15,5,CONCRETE:7)
Block(-8,15,6,CONCRETE:7)
Block(-8,15,7,CONCRETE:7)
Block(-8,15,8,CONCRETE:7)
Block(-8,16,-7,STEP:8)
Block(-8,16,-6,STEP:8)
Block(-8,16,-5,STEP:8)
Block(-8,16,-4,CONCRETE:7)
Block(-8,16,-3,OBSIDIAN:0)
Block(-8,16,-2,OBSIDIAN:0)
Block(-8,16,-1,OBSIDIAN:0)
Block(-8,16,0,OBSIDIAN:0)
Block(-8,16,1,OBSIDIAN:0)
Block(-8,16,2,OBSIDIAN:0)
Block(-8,16,3,OBSIDIAN:0)
Block(-8,16,4,OBSIDIAN:0)
Block(-8,16,5,OBSIDIAN:0)
Block(-8,16,6,OBSIDIAN:0)
Block(-8,16,7,OBSIDIAN:0)
Block(-8,16,8,OBSIDIAN:0)
Block(-8,17,-7,CONCRETE:7)
Block(-8,17,-6,CONCRETE:7)
Block(-8,17,-5,CONCRETE:7)
Block(-8,17,-4,CONCRETE:7)
Block(-8,17,-3,CONCRETE:7)
Block(-8,17,-2,CONCRETE:7)
Block(-8,17,-1,CONCRETE:7)
Block(-8,17,0,CONCRETE:7)
Block(-8,17,1,CONCRETE:7)
Block(-8,17,2,CONCRETE:7)
Block(-8,17,3,CONCRETE:7)
Block(-8,17,4,CONCRETE:7)
Block(-8,17,5,CONCRETE:7)
Block(-8,17,6,CONCRETE:7)
Block(-8,17,7,CONCRETE:7)
Block(-8,17,8,STEP:0)
Block(-8,18,-4,STEP:8)
Block(-8,18,-3,CONCRETE:7)
Block(-8,18,-2,CONCRETE:7)
Block(-8,18,-1,CONCRETE:7)
Block(-8,18,0,CONCRETE:7)
Block(-8,18,1,CONCRETE:7)
Block(-8,18,2,OBSIDIAN:0)
Block(-8,18,3,OBSIDIAN:0)
Block(-8,18,4,QUARTZ_STAIRS:7)
Block(-8,18,5,QUARTZ_STAIRS:4)
Block(-8,18,6,QUARTZ_STAIRS:4)
Block(-8,19,-4,STEP:8)
Block(-8,19,-3,CONCRETE:7)
Block(-8,19,-2,CONCRETE:7)
Block(-8,19,-1,CONCRETE:7)
Block(-8,19,0,CONCRETE:7)
Block(-8,19,1,CONCRETE:7)
Block(-8,19,2,OBSIDIAN:0)
Block(-8,19,3,OBSIDIAN:0)
Block(-8,19,4,QUARTZ_STAIRS:7)
Block(-8,19,5,QUARTZ_STAIRS:4)
Block(-8,19,6,QUARTZ_STAIRS:4)
Block(-8,20,-4,STEP:8)
Block(-8,20,-3,CONCRETE:7)
Block(-8,20,-2,CONCRETE:7)
Block(-8,20,-1,CONCRETE:7)
Block(-8,20,0,CONCRETE:7)
Block(-8,20,1,CONCRETE:7)
Block(-8,20,2,OBSIDIAN:0)
Block(-8,20,3,OBSIDIAN:0)
Block(-8,20,4,QUARTZ_STAIRS:7)
Block(-8,20,5,QUARTZ_STAIRS:4)
Block(-8,20,6,QUARTZ_STAIRS:4)
Block(-8,21,-7,STEP:8)
Block(-8,21,-6,STEP:8)
Block(-8,21,-5,STEP:8)
Block(-8,21,-4,STEP:8)
Block(-8,21,-3,CONCRETE:7)
Block(-8,21,-2,CONCRETE:7)
Block(-8,21,-1,CONCRETE:7)
Block(-8,21,0,CONCRETE:7)
Block(-8,21,1,CONCRETE:7)
Block(-8,21,2,OBSIDIAN:0)
Block(-8,21,3,OBSIDIAN:0)
Block(-8,21,4,QUARTZ_STAIRS:7)
Block(-8,21,5,QUARTZ_STAIRS:4)
Block(-8,21,6,QUARTZ_STAIRS:7)
Block(-8,22,-7,CONCRETE:7)
Block(-8,22,-6,CONCRETE:7)
Block(-8,22,-5,CONCRETE:7)
Block(-8,22,-4,CONCRETE:7)
Block(-8,22,-3,CONCRETE:7)
Block(-8,22,-2,CONCRETE:7)
Block(-8,22,-1,CONCRETE:7)
Block(-8,22,0,CONCRETE:7)
Block(-8,22,1,CONCRETE:7)
Block(-8,22,2,OBSIDIAN:0)
Block(-8,22,3,OBSIDIAN:0)
Block(-8,22,4,QUARTZ_STAIRS:4)
Block(-8,22,5,QUARTZ_STAIRS:4)
Block(-8,22,6,CONCRETE:7)
Block(-8,23,-7,OBSIDIAN:0)
Block(-8,23,-6,OBSIDIAN:0)
Block(-8,23,-5,OBSIDIAN:0)
Block(-8,23,-4,OBSIDIAN:0)
Block(-8,23,-3,OBSIDIAN:0)
Block(-8,23,-2,OBSIDIAN:0)
Block(-8,23,-1,OBSIDIAN:0)
Block(-8,23,0,OBSIDIAN:0)
Block(-8,23,1,OBSIDIAN:0)
Block(-8,23,2,OBSIDIAN:0)
Block(-8,23,3,OBSIDIAN:0)
Block(-8,23,4,OBSIDIAN:0)
Block(-8,23,5,CONCRETE:7)
Block(-8,23,6,CONCRETE:7)
Block(-8,24,-7,CONCRETE:15)
Block(-8,24,-6,CONCRETE:14)
Block(-8,24,-5,CONCRETE:0)
Block(-8,24,-4,STONE:6)
Block(-8,24,-3,CONCRETE:0)
Block(-8,24,-2,CONCRETE:7)
Block(-8,24,-1,CONCRETE:0)
Block(-8,24,0,CONCRETE:0)
Block(-8,24,1,CONCRETE:0)
Block(-8,24,2,CONCRETE:15)
Block(-8,24,3,STONE:6)
Block(-8,24,4,CONCRETE:0)
Block(-8,24,5,QUARTZ_STAIRS:3)
Block(-8,24,6,CONCRETE:7)
Block(-8,25,0,LOG:5)
Block(-8,25,4,CONCRETE:0)
Block(-8,25,6,STEP:7)
Block(-8,26,0,TRAP_DOOR:8)
Block(-8,26,4,CONCRETE:0)
Block(-8,27,-1,TRAP_DOOR:4)
Block(-8,27,0,PRISMARINE:0)
Block(-8,27,1,TRAP_DOOR:5)
Block(-8,27,4,CONCRETE:0)
Block(-8,28,-4,STEP:8)
Block(-8,28,0,TRAP_DOOR:0)
Block(-8,28,3,QUARTZ_STAIRS:6)
Block(-8,28,4,CONCRETE:0)
Block(-8,28,5,QUARTZ_STAIRS:7)
Block(-8,29,-7,CONCRETE:0)
Block(-8,29,-6,CONCRETE:0)
Block(-8,29,-5,CONCRETE:0)
Block(-8,29,-4,CONCRETE:0)
Block(-8,29,-3,CONCRETE:0)
Block(-8,29,-2,CONCRETE:15)
Block(-8,29,-1,CONCRETE:0)
Block(-8,29,0,CONCRETE:0)
Block(-8,29,1,CONCRETE:0)
Block(-8,29,2,CONCRETE:0)
Block(-8,29,3,CONCRETE:0)
Block(-8,29,4,CONCRETE:0)
Block(-8,29,5,CONCRETE:0)
Block(-8,29,6,QUARTZ_STAIRS:7)
Block(-8,30,-1,TRAP_DOOR:4)
Block(-8,30,0,GRASS:0)
Block(-8,30,1,CONCRETE:0)
Block(-8,30,3,CONCRETE:0)
Block(-8,30,4,CONCRETE:0)
Block(-8,30,5,CONCRETE:0)
Block(-8,30,6,COBBLE_WALL:0)
Block(-8,31,0,DOUBLE_PLANT:1)
Block(-8,31,1,CONCRETE:0)
Block(-8,31,3,CONCRETE:0)
Block(-8,31,4,CONCRETE:0)
Block(-8,31,5,CONCRETE:0)
Block(-8,32,0,DOUBLE_PLANT:10)
Block(-8,32,1,CONCRETE:0)
Block(-8,32,2,QUARTZ_STAIRS:5)
Block(-8,32,3,CONCRETE:0)
Block(-8,32,4,CONCRETE:0)
Block(-8,32,5,CONCRETE:0)
Block(-8,33,1,CONCRETE:0)
Block(-8,33,2,QUARTZ_STAIRS:0)
Block(-8,33,3,CONCRETE:0)
Block(-8,33,4,CONCRETE:0)
Block(-8,33,5,CONCRETE:0)
Block(-8,33,6,QUARTZ_STAIRS:7)
Block(-8,34,1,STAINED_GLASS_PANE:15)
Block(-8,34,3,CONCRETE:0)
Block(-8,34,4,CONCRETE:0)
Block(-8,34,5,CONCRETE:0)
Block(-8,34,6,COBBLE_WALL:0)
Block(-8,35,3,CONCRETE:0)
Block(-8,35,4,CONCRETE:0)
Block(-8,35,5,CONCRETE:0)
Block(-8,36,3,CONCRETE:0)
Block(-8,36,4,CONCRETE:0)
Block(-8,36,5,CONCRETE:0)
Block(-8,36,6,QUARTZ_STAIRS:7)
Block(-8,37,3,CONCRETE:0)
Block(-8,37,4,CONCRETE:0)
Block(-8,37,5,CONCRETE:0)
Block(-8,37,6,QUARTZ_STAIRS:7)
Block(-8,38,-4,IRON_TRAPDOOR:11)
Block(-8,38,2,QUARTZ_STAIRS:6)
Block(-8,38,3,CONCRETE:0)
Block(-8,38,4,CONCRETE:0)
Block(-8,38,5,CONCRETE:0)
Block(-8,38,6,IRON_FENCE:0)
Block(-8,39,-5,TRAP_DOOR:4)
Block(-8,39,-4,PRISMARINE:0)
Block(-8,39,-3,TRAP_DOOR:5)
Block(-8,39,2,CONCRETE:0)
Block(-8,39,3,CONCRETE:0)
Block(-8,39,4,CONCRETE:7)
Block(-8,39,5,COBBLE_WALL:0)
Block(-8,40,-4,IRON_FENCE:0)
Block(-8,40,2,QUARTZ_STAIRS:0)
Block(-8,40,3,CONCRETE:7)
Block(-8,41,-4,IRON_FENCE:0)
Block(-8,41,1,QUARTZ_STAIRS:6)
Block(-8,41,2,QUARTZ_STAIRS:4)
Block(-8,41,3,CONCRETE:7)
Block(-8,42,-4,IRON_FENCE:0)
Block(-8,42,1,CONCRETE:0)
Block(-8,42,2,CONCRETE:7)
Block(-8,43,-4,COBBLE_WALL:0)
Block(-8,43,-1,STEP:15)
Block(-8,43,1,CONCRETE:7)
Block(-8,44,-4,CONCRETE:7)
Block(-8,44,-3,QUARTZ_STAIRS:6)
Block(-8,44,-2,CONCRETE:0)
Block(-8,44,-1,CONCRETE:7)
Block(-8,44,0,CONCRETE:7)
Block(-8,45,-4,CONCRETE:7)
Block(-8,45,-3,CONCRETE:0)
Block(-8,45,-2,CONCRETE:0)
Block(-8,46,-7,CONCRETE:7)
Block(-8,46,-6,CONCRETE:7)
Block(-8,46,-5,CONCRETE:7)
Block(-8,46,-4,CONCRETE:7)
Block(-7,0,-7,CONCRETE:7)
Block(-7,0,-6,CONCRETE:7)
Block(-7,0,-5,CONCRETE:7)
Block(-7,0,-4,CONCRETE:7)
Block(-7,0,-3,CONCRETE:7)
Block(-7,0,-2,CONCRETE:7)
Block(-7,0,-1,CONCRETE:7)
Block(-7,0,0,CONCRETE:7)
Block(-7,0,1,CONCRETE:7)
Block(-7,0,2,CONCRETE:7)
Block(-7,0,3,CONCRETE:7)
Block(-7,0,4,CONCRETE:7)
Block(-7,0,5,CONCRETE:7)
Block(-7,0,6,CONCRETE:7)
Block(-7,0,7,CONCRETE:7)
Block(-7,0,8,CONCRETE:7)
Block(-7,1,-7,OBSIDIAN:0)
Block(-7,1,-6,OBSIDIAN:0)
Block(-7,1,-5,OBSIDIAN:0)
Block(-7,1,-4,OBSIDIAN:0)
Block(-7,1,-3,OBSIDIAN:0)
Block(-7,1,-2,OBSIDIAN:0)
Block(-7,1,-1,OBSIDIAN:0)
Block(-7,1,0,OBSIDIAN:0)
Block(-7,1,1,OBSIDIAN:0)
Block(-7,1,2,OBSIDIAN:0)
Block(-7,1,3,OBSIDIAN:0)
Block(-7,1,4,OBSIDIAN:0)
Block(-7,1,5,OBSIDIAN:0)
Block(-7,1,6,OBSIDIAN:0)
Block(-7,1,7,OBSIDIAN:0)
Block(-7,1,8,OBSIDIAN:0)
Block(-7,2,-7,OBSIDIAN:0)
Block(-7,2,-6,OBSIDIAN:0)
Block(-7,2,-5,OBSIDIAN:0)
Block(-7,2,-4,OBSIDIAN:0)
Block(-7,2,-3,OBSIDIAN:0)
Block(-7,2,-2,CONCRETE:7)
Block(-7,2,-1,CONCRETE:7)
Block(-7,2,0,CONCRETE:7)
Block(-7,2,1,CONCRETE:7)
Block(-7,2,2,CONCRETE:7)
Block(-7,2,3,CONCRETE:7)
Block(-7,2,4,CONCRETE:7)
Block(-7,2,5,CONCRETE:7)
Block(-7,2,6,CONCRETE:7)
Block(-7,2,7,CONCRETE:7)
Block(-7,2,8,CONCRETE:7)
Block(-7,3,-7,CONCRETE:7)
Block(-7,3,-6,CONCRETE:7)
Block(-7,3,-5,CONCRETE:7)
Block(-7,3,-4,CONCRETE:7)
Block(-7,3,-3,OBSIDIAN:0)
Block(-7,3,-2,CONCRETE:7)
Block(-7,3,-1,CONCRETE:7)
Block(-7,3,0,CONCRETE:7)
Block(-7,3,1,CONCRETE:7)
Block(-7,3,2,CONCRETE:7)
Block(-7,3,3,CONCRETE:7)
Block(-7,3,4,CONCRETE:7)
Block(-7,3,5,CONCRETE:7)
Block(-7,3,6,CONCRETE:7)
Block(-7,3,7,CONCRETE:7)
Block(-7,3,8,CONCRETE:7)
Block(-7,4,-7,CONCRETE:7)
Block(-7,4,-6,CONCRETE:7)
Block(-7,4,-5,CONCRETE:7)
Block(-7,4,-4,CONCRETE:7)
Block(-7,4,-3,OBSIDIAN:0)
Block(-7,4,-2,CONCRETE:7)
Block(-7,4,-1,CONCRETE:7)
Block(-7,4,0,CONCRETE:7)
Block(-7,4,1,CONCRETE:7)
Block(-7,4,2,CONCRETE:7)
Block(-7,4,3,CONCRETE:7)
Block(-7,4,4,CONCRETE:7)
Block(-7,4,5,CONCRETE:7)
Block(-7,4,6,CONCRETE:7)
Block(-7,4,7,CONCRETE:7)
Block(-7,4,8,CONCRETE:7)
Block(-7,5,-7,IRON_DOOR_BLOCK:0)
Block(-7,5,-6,CONCRETE:7)
Block(-7,5,-5,CONCRETE:7)
Block(-7,5,-4,CONCRETE:7)
Block(-7,5,-3,OBSIDIAN:0)
Block(-7,5,-2,CONCRETE:7)
Block(-7,5,-1,OBSIDIAN:0)
Block(-7,5,0,OBSIDIAN:0)
Block(-7,5,1,AIR:0)
Block(-7,5,2,STONE_BUTTON:2)
Block(-7,5,3,AIR:0)
Block(-7,5,4,AIR:0)
Block(-7,5,5,AIR:0)
Block(-7,5,6,AIR:0)
Block(-7,5,7,AIR:0)
Block(-7,5,8,IRON_DOOR_BLOCK:2)
Block(-7,6,-7,IRON_DOOR_BLOCK:9)
Block(-7,6,-6,CONCRETE:7)
Block(-7,6,-5,CONCRETE:7)
Block(-7,6,-4,CONCRETE:7)
Block(-7,6,-3,OBSIDIAN:0)
Block(-7,6,-2,CONCRETE:7)
Block(-7,6,-1,OBSIDIAN:0)
Block(-7,6,0,OBSIDIAN:0)
Block(-7,6,1,AIR:0)
Block(-7,6,2,TRIPWIRE_HOOK:1)
Block(-7,6,3,AIR:0)
Block(-7,6,4,AIR:0)
Block(-7,6,5,AIR:0)
Block(-7,6,6,AIR:0)
Block(-7,6,7,AIR:0)
Block(-7,6,8,IRON_DOOR_BLOCK:8)
Block(-7,7,-7,CONCRETE:7)
Block(-7,7,-6,CONCRETE:7)
Block(-7,7,-5,CONCRETE:7)
Block(-7,7,-4,CONCRETE:7)
Block(-7,7,-3,OBSIDIAN:0)
Block(-7,7,-2,CONCRETE:7)
Block(-7,7,-1,OBSIDIAN:0)
Block(-7,7,0,OBSIDIAN:0)
Block(-7,7,1,AIR:0)
Block(-7,7,2,LEVER:2)
Block(-7,7,3,AIR:0)
Block(-7,7,4,AIR:0)
Block(-7,7,5,AIR:0)
Block(-7,7,6,AIR:0)
Block(-7,7,7,AIR:0)
Block(-7,7,8,AIR:0)
Block(-7,8,-7,CONCRETE:7)
Block(-7,8,-6,CONCRETE:7)
Block(-7,8,-5,CONCRETE:7)
Block(-7,8,-4,CONCRETE:7)
Block(-7,8,-3,OBSIDIAN:0)
Block(-7,8,-2,OBSIDIAN:0)
Block(-7,8,-1,CONCRETE:7)
Block(-7,8,0,CONCRETE:7)
Block(-7,8,1,AIR:0)
Block(-7,8,2,AIR:0)
Block(-7,8,3,AIR:0)
Block(-7,8,4,AIR:0)
Block(-7,8,5,AIR:0)
Block(-7,8,6,AIR:0)
Block(-7,8,7,AIR:0)
Block(-7,8,8,AIR:0)
Block(-7,9,-7,CONCRETE:7)
Block(-7,9,-6,CONCRETE:7)
Block(-7,9,-5,CONCRETE:7)
Block(-7,9,-4,CONCRETE:7)
Block(-7,9,-3,OBSIDIAN:0)
Block(-7,9,-2,CONCRETE:7)
Block(-7,9,-1,OBSIDIAN:0)
Block(-7,9,0,OBSIDIAN:0)
Block(-7,9,1,IRON_TRAPDOOR:10)
Block(-7,9,2,AIR:0)
Block(-7,9,3,AIR:0)
Block(-7,9,4,AIR:0)
Block(-7,9,5,AIR:0)
Block(-7,9,6,AIR:0)
Block(-7,9,7,AIR:0)
Block(-7,9,8,AIR:0)
Block(-7,10,-7,CONCRETE:7)
Block(-7,10,-6,CONCRETE:7)
Block(-7,10,-5,CONCRETE:7)
Block(-7,10,-4,CONCRETE:7)
Block(-7,10,-3,OBSIDIAN:0)
Block(-7,10,-2,CONCRETE:7)
Block(-7,10,-1,OBSIDIAN:0)
Block(-7,10,0,OBSIDIAN:0)
Block(-7,10,1,CONCRETE:14)
Block(-7,10,2,AIR:0)
Block(-7,10,3,AIR:0)
Block(-7,10,4,IRON_TRAPDOOR:9)
Block(-7,10,5,AIR:0)
Block(-7,10,6,AIR:0)
Block(-7,10,7,AIR:0)
Block(-7,10,8,AIR:0)
Block(-7,11,-7,CONCRETE:7)
Block(-7,11,-6,CONCRETE:7)
Block(-7,11,-5,CONCRETE:7)
Block(-7,11,-4,CONCRETE:7)
Block(-7,11,-3,OBSIDIAN:0)
Block(-7,11,-2,OBSIDIAN:0)
Block(-7,11,-1,OBSIDIAN:0)
Block(-7,11,0,OBSIDIAN:0)
Block(-7,11,1,AIR:0)
Block(-7,11,2,AIR:0)
Block(-7,11,3,AIR:0)
Block(-7,11,4,CONCRETE:4)
Block(-7,11,5,AIR:0)
Block(-7,11,6,AIR:0)
Block(-7,11,7,AIR:0)
Block(-7,11,8,AIR:0)
Block(-7,12,-7,CONCRETE:7)
Block(-7,12,-6,CONCRETE:7)
Block(-7,12,-5,CONCRETE:7)
Block(-7,12,-4,CONCRETE:7)
Block(-7,12,-3,OBSIDIAN:0)
Block(-7,12,-2,CONCRETE:7)
Block(-7,12,-1,CONCRETE:7)
Block(-7,12,0,CONCRETE:7)
Block(-7,12,1,IRON_TRAPDOOR:10)
Block(-7,12,2,IRON_TRAPDOOR:10)
Block(-7,12,3,CONCRETE:7)
Block(-7,12,4,IRON_TRAPDOOR:9)
Block(-7,12,5,IRON_TRAPDOOR:9)
Block(-7,12,6,IRON_TRAPDOOR:9)
Block(-7,12,7,CONCRETE:7)
Block(-7,12,8,IRON_TRAPDOOR:9)
Block(-7,13,-7,CONCRETE:7)
Block(-7,13,-6,CONCRETE:7)
Block(-7,13,-5,CONCRETE:7)
Block(-7,13,-4,CONCRETE:7)
Block(-7,13,-3,OBSIDIAN:0)
Block(-7,13,-2,CONCRETE:7)
Block(-7,13,-1,OBSIDIAN:0)
Block(-7,13,0,OBSIDIAN:0)
Block(-7,13,1,AIR:0)
Block(-7,13,2,AIR:0)
Block(-7,13,3,AIR:0)
Block(-7,13,4,AIR:0)
Block(-7,13,5,AIR:0)
Block(-7,13,6,AIR:0)
Block(-7,13,7,AIR:0)
Block(-7,13,8,AIR:0)
Block(-7,14,-7,CONCRETE:7)
Block(-7,14,-6,CONCRETE:7)
Block(-7,14,-5,CONCRETE:7)
Block(-7,14,-4,CONCRETE:7)
Block(-7,14,-3,OBSIDIAN:0)
Block(-7,14,-2,CONCRETE:7)
Block(-7,14,-1,OBSIDIAN:0)
Block(-7,14,0,OBSIDIAN:0)
Block(-7,14,1,STEP:8)
Block(-7,14,2,STEP:8)
Block(-7,14,3,CONCRETE:7)
Block(-7,14,4,STEP:8)
Block(-7,14,5,STEP:8)
Block(-7,14,6,STEP:8)
Block(-7,14,7,CONCRETE:7)
Block(-7,14,8,STEP:8)
Block(-7,15,-7,CONCRETE:7)
Block(-7,15,-6,CONCRETE:7)
Block(-7,15,-5,CONCRETE:7)
Block(-7,15,-4,CONCRETE:7)
Block(-7,15,-3,OBSIDIAN:0)
Block(-7,15,-2,CONCRETE:7)
Block(-7,15,-1,CONCRETE:7)
Block(-7,15,0,CONCRETE:7)
Block(-7,15,1,CONCRETE:7)
Block(-7,15,2,CONCRETE:7)
Block(-7,15,3,CONCRETE:7)
Block(-7,15,4,CONCRETE:7)
Block(-7,15,5,CONCRETE:7)
Block(-7,15,6,CONCRETE:7)
Block(-7,15,7,CONCRETE:7)
Block(-7,15,8,CONCRETE:7)
Block(-7,16,-7,CONCRETE:7)
Block(-7,16,-6,CONCRETE:7)
Block(-7,16,-5,CONCRETE:7)
Block(-7,16,-4,CONCRETE:7)
Block(-7,16,-3,OBSIDIAN:0)
Block(-7,16,-2,OBSIDIAN:0)
Block(-7,16,-1,OBSIDIAN:0)
Block(-7,16,0,OBSIDIAN:0)
Block(-7,16,1,OBSIDIAN:0)
Block(-7,16,2,OBSIDIAN:0)
Block(-7,16,3,OBSIDIAN:0)
Block(-7,16,4,OBSIDIAN:0)
Block(-7,16,5,OBSIDIAN:0)
Block(-7,16,6,OBSIDIAN:0)
Block(-7,16,7,OBSIDIAN:0)
Block(-7,16,8,OBSIDIAN:0)
Block(-7,17,-7,CONCRETE:7)
Block(-7,17,-6,CONCRETE:7)
Block(-7,17,-5,CONCRETE:7)
Block(-7,17,-4,CONCRETE:7)
Block(-7,17,-3,CONCRETE:7)
Block(-7,17,-2,CONCRETE:7)
Block(-7,17,-1,CONCRETE:7)
Block(-7,17,0,CONCRETE:7)
Block(-7,17,1,CONCRETE:7)
Block(-7,17,2,CONCRETE:7)
Block(-7,17,3,CONCRETE:7)
Block(-7,17,4,CONCRETE:7)
Block(-7,17,5,CONCRETE:7)
Block(-7,17,6,CONCRETE:7)
Block(-7,17,7,CONCRETE:7)
Block(-7,17,8,CONCRETE:7)
Block(-7,18,-4,STEP:8)
Block(-7,18,-3,CONCRETE:7)
Block(-7,18,-2,CONCRETE:7)
Block(-7,18,-1,CONCRETE:7)
Block(-7,18,0,CONCRETE:7)
Block(-7,18,1,CONCRETE:7)
Block(-7,18,2,OBSIDIAN:0)
Block(-7,18,3,OBSIDIAN:0)
Block(-7,18,4,OBSIDIAN:0)
Block(-7,18,5,CONCRETE:0)
Block(-7,18,6,QUARTZ_STAIRS:7)
Block(-7,18,8,COBBLE_WALL:0)
Block(-7,19,-4,STEP:8)
Block(-7,19,-3,CONCRETE:7)
Block(-7,19,-2,CONCRETE:7)
Block(-7,19,-1,CONCRETE:7)
Block(-7,19,0,CONCRETE:7)
Block(-7,19,1,CONCRETE:7)
Block(-7,19,2,OBSIDIAN:0)
Block(-7,19,3,OBSIDIAN:0)
Block(-7,19,4,OBSIDIAN:0)
Block(-7,19,5,CONCRETE:0)
Block(-7,19,6,QUARTZ_STAIRS:7)
Block(-7,20,-4,STEP:8)
Block(-7,20,-3,CONCRETE:7)
Block(-7,20,-2,CONCRETE:7)
Block(-7,20,-1,CONCRETE:7)
Block(-7,20,0,CONCRETE:7)
Block(-7,20,1,CONCRETE:7)
Block(-7,20,2,OBSIDIAN:0)
Block(-7,20,3,OBSIDIAN:0)
Block(-7,20,4,OBSIDIAN:0)
Block(-7,20,5,CONCRETE:0)
Block(-7,20,6,QUARTZ_STAIRS:7)
Block(-7,21,-7,STEP:8)
Block(-7,21,-6,STEP:8)
Block(-7,21,-5,STEP:8)
Block(-7,21,-4,STEP:8)
Block(-7,21,-3,CONCRETE:7)
Block(-7,21,-2,CONCRETE:7)
Block(-7,21,-1,CONCRETE:7)
Block(-7,21,0,CONCRETE:7)
Block(-7,21,1,CONCRETE:7)
Block(-7,21,2,OBSIDIAN:0)
Block(-7,21,3,OBSIDIAN:0)
Block(-7,21,4,OBSIDIAN:0)
Block(-7,21,5,CONCRETE:0)
Block(-7,21,6,QUARTZ_STAIRS:7)
Block(-7,22,-7,CONCRETE:7)
Block(-7,22,-6,CONCRETE:7)
Block(-7,22,-5,CONCRETE:7)
Block(-7,22,-4,CONCRETE:7)
Block(-7,22,-3,CONCRETE:7)
Block(-7,22,-2,CONCRETE:7)
Block(-7,22,-1,CONCRETE:7)
Block(-7,22,0,CONCRETE:7)
Block(-7,22,1,CONCRETE:7)
Block(-7,22,2,OBSIDIAN:0)
Block(-7,22,3,OBSIDIAN:0)
Block(-7,22,4,OBSIDIAN:0)
Block(-7,22,5,CONCRETE:0)
Block(-7,22,6,QUARTZ_STAIRS:7)
Block(-7,23,-7,OBSIDIAN:0)
Block(-7,23,-6,OBSIDIAN:0)
Block(-7,23,-5,OBSIDIAN:0)
Block(-7,23,-4,OBSIDIAN:0)
Block(-7,23,-3,OBSIDIAN:0)
Block(-7,23,-2,OBSIDIAN:0)
Block(-7,23,-1,OBSIDIAN:0)
Block(-7,23,0,OBSIDIAN:0)
Block(-7,23,1,OBSIDIAN:0)
Block(-7,23,2,OBSIDIAN:0)
Block(-7,23,3,OBSIDIAN:0)
Block(-7,23,4,OBSIDIAN:0)
Block(-7,23,5,OBSIDIAN:0)
Block(-7,23,6,CONCRETE:7)
Block(-7,24,-7,CONCRETE:0)
Block(-7,24,-6,CONCRETE:0)
Block(-7,24,-5,STONE:6)
Block(-7,24,-4,CONCRETE:0)
Block(-7,24,-3,CONCRETE:7)
Block(-7,24,-2,CONCRETE:15)
Block(-7,24,-1,CONCRETE:0)
Block(-7,24,0,CONCRETE:0)
Block(-7,24,1,CONCRETE:15)
Block(-7,24,2,CONCRETE:15)
Block(-7,24,3,STONE:6)
Block(-7,24,4,CONCRETE:7)
Block(-7,24,5,STEP:0)
Block(-7,24,6,STEP:8)
Block(-7,25,-4,CONCRETE:0)
Block(-7,25,-2,DARK_OAK_STAIRS:3)
Block(-7,25,0,LOG:5)
Block(-7,25,1,DARK_OAK_STAIRS:2)
Block(-7,25,4,STAINED_GLASS_PANE:15)
Block(-7,26,-4,CONCRETE:0)
Block(-7,26,0,TRAP_DOOR:8)
Block(-7,26,4,STAINED_GLASS_PANE:15)
Block(-7,27,-4,CONCRETE:0)
Block(-7,27,-1,TRAP_DOOR:4)
Block(-7,27,0,SEA_LANTERN:0)
Block(-7,27,1,TRAP_DOOR:5)
Block(-7,27,4,STAINED_GLASS_PANE:15)
Block(-7,28,-4,CONCRETE:0)
Block(-7,28,0,IRON_FENCE:0)
Block(-7,28,4,STEP:8)
Block(-7,29,-7,STEP:8)
Block(-7,29,-6,QUARTZ_STAIRS:5)
Block(-7,29,-5,CONCRETE:0)
Block(-7,29,-4,CONCRETE:0)
Block(-7,29,-3,CONCRETE:0)
Block(-7,29,-2,CONCRETE:0)
Block(-7,29,-1,CONCRETE:15)
Block(-7,29,0,CONCRETE:15)
Block(-7,29,1,CONCRETE:0)
Block(-7,29,2,CONCRETE:0)
Block(-7,29,3,CONCRETE:0)
Block(-7,29,4,CONCRETE:0)
Block(-7,29,5,CONCRETE:0)
Block(-7,29,6,STEP:8)
Block(-7,30,-7,STAINED_GLASS_PANE:15)
Block(-7,30,-6,CONCRETE:0)
Block(-7,30,0,TRAP_DOOR:7)
Block(-7,30,4,CONCRETE:7)
Block(-7,30,5,STEP:7)
Block(-7,30,6,IRON_FENCE:0)
Block(-7,31,-6,STEP:0)
Block(-7,31,4,STAINED_GLASS_PANE:15)
Block(-7,32,1,QUARTZ_STAIRS:5)
Block(-7,32,4,STAINED_GLASS_PANE:15)
Block(-7,32,5,STEP:8)
Block(-7,33,1,CONCRETE:0)
Block(-7,33,2,CONCRETE:0)
Block(-7,33,3,CONCRETE:0)
Block(-7,33,4,CONCRETE:0)
Block(-7,33,5,CONCRETE:0)
Block(-7,33,6,STEP:8)
Block(-7,34,1,CONCRETE:0)
Block(-7,34,4,CONCRETE:7)
Block(-7,34,5,STEP:7)
Block(-7,34,6,IRON_FENCE:0)
Block(-7,35,1,STEP:0)
Block(-7,35,4,STAINED_GLASS_PANE:15)
Block(-7,36,4,STAINED_GLASS_PANE:15)
Block(-7,36,5,QUARTZ_STAIRS:5)
Block(-7,37,4,QUARTZ_STAIRS:6)
Block(-7,37,5,CONCRETE:0)
Block(-7,37,6,STEP:8)
Block(-7,38,3,CONCRETE:0)
Block(-7,38,4,CONCRETE:7)
Block(-7,38,5,STEP:0)
Block(-7,39,-6,TRAP_DOOR:6)
Block(-7,39,-4,TRAP_DOOR:7)
Block(-7,39,2,QUARTZ_STAIRS:5)
Block(-7,39,3,CONCRETE:0)
Block(-7,39,4,CONCRETE:7)
Block(-7,40,2,CONCRETE:0)
Block(-7,40,3,CONCRETE:7)
Block(-7,41,2,CONCRETE:0)
Block(-7,41,3,CONCRETE:7)
Block(-7,42,2,CONCRETE:7)
Block(-7,43,1,CONCRETE:7)
Block(-7,44,-3,QUARTZ_STAIRS:4)
Block(-7,44,-1,CONCRETE:7)
Block(-7,44,0,CONCRETE:7)
Block(-7,45,-4,CONCRETE:0)
Block(-7,45,-3,CONCRETE:0)
Block(-7,45,-2,CONCRETE:0)
Block(-7,46,-7,CONCRETE:7)
Block(-7,46,-6,CONCRETE:7)
Block(-7,46,-5,CONCRETE:7)
Block(-6,0,-7,CONCRETE:7)
Block(-6,0,-6,CONCRETE:7)
Block(-6,0,-5,CONCRETE:7)
Block(-6,0,-4,CONCRETE:7)
Block(-6,0,-3,CONCRETE:7)
Block(-6,0,-2,CONCRETE:7)
Block(-6,0,-1,CONCRETE:7)
Block(-6,0,0,CONCRETE:7)
Block(-6,0,1,CONCRETE:7)
Block(-6,0,2,CONCRETE:7)
Block(-6,0,3,CONCRETE:7)
Block(-6,0,4,CONCRETE:7)
Block(-6,0,5,CONCRETE:7)
Block(-6,0,6,CONCRETE:7)
Block(-6,0,7,CONCRETE:7)
Block(-6,0,8,CONCRETE:7)
Block(-6,1,-7,OBSIDIAN:0)
Block(-6,1,-6,OBSIDIAN:0)
Block(-6,1,-5,OBSIDIAN:0)
Block(-6,1,-4,OBSIDIAN:0)
Block(-6,1,-3,OBSIDIAN:0)
Block(-6,1,-2,OBSIDIAN:0)
Block(-6,1,-1,OBSIDIAN:0)
Block(-6,1,0,OBSIDIAN:0)
Block(-6,1,1,OBSIDIAN:0)
Block(-6,1,2,OBSIDIAN:0)
Block(-6,1,3,OBSIDIAN:0)
Block(-6,1,4,OBSIDIAN:0)
Block(-6,1,5,OBSIDIAN:0)
Block(-6,1,6,OBSIDIAN:0)
Block(-6,1,7,OBSIDIAN:0)
Block(-6,1,8,OBSIDIAN:0)
Block(-6,2,-7,OBSIDIAN:0)
Block(-6,2,-6,OBSIDIAN:0)
Block(-6,2,-5,OBSIDIAN:0)
Block(-6,2,-4,OBSIDIAN:0)
Block(-6,2,-3,OBSIDIAN:0)
Block(-6,2,-2,CONCRETE:7)
Block(-6,2,-1,CONCRETE:7)
Block(-6,2,0,CONCRETE:7)
Block(-6,2,1,CONCRETE:7)
Block(-6,2,2,CONCRETE:7)
Block(-6,2,3,CONCRETE:7)
Block(-6,2,4,CONCRETE:7)
Block(-6,2,5,CONCRETE:7)
Block(-6,2,6,CONCRETE:7)
Block(-6,2,7,CONCRETE:7)
Block(-6,2,8,CONCRETE:7)
Block(-6,3,-7,OBSIDIAN:0)
Block(-6,3,-6,OBSIDIAN:0)
Block(-6,3,-5,OBSIDIAN:0)
Block(-6,3,-4,OBSIDIAN:0)
Block(-6,3,-3,OBSIDIAN:0)
Block(-6,3,-2,CONCRETE:7)
Block(-6,3,-1,CONCRETE:7)
Block(-6,3,0,CONCRETE:7)
Block(-6,3,1,CONCRETE:7)
Block(-6,3,2,CONCRETE:7)
Block(-6,3,3,CONCRETE:7)
Block(-6,3,4,CONCRETE:7)
Block(-6,3,5,CONCRETE:7)
Block(-6,3,6,CONCRETE:7)
Block(-6,3,7,CONCRETE:7)
Block(-6,3,8,CONCRETE:7)
Block(-6,4,-7,OBSIDIAN:0)
Block(-6,4,-6,OBSIDIAN:0)
Block(-6,4,-5,OBSIDIAN:0)
Block(-6,4,-4,OBSIDIAN:0)
Block(-6,4,-3,OBSIDIAN:0)
Block(-6,4,-2,CONCRETE:7)
Block(-6,4,-1,CONCRETE:7)
Block(-6,4,0,CONCRETE:7)
Block(-6,4,1,CONCRETE:7)
Block(-6,4,2,CONCRETE:7)
Block(-6,4,3,CONCRETE:7)
Block(-6,4,4,CONCRETE:7)
Block(-6,4,5,CONCRETE:7)
Block(-6,4,6,CONCRETE:7)
Block(-6,4,7,CONCRETE:7)
Block(-6,4,8,CONCRETE:7)
Block(-6,5,-7,AIR:0)
Block(-6,5,-6,OBSIDIAN:0)
Block(-6,5,-5,OBSIDIAN:0)
Block(-6,5,-4,OBSIDIAN:0)
Block(-6,5,-3,OBSIDIAN:0)
Block(-6,5,-2,CONCRETE:7)
Block(-6,5,-1,OBSIDIAN:0)
Block(-6,5,0,OBSIDIAN:0)
Block(-6,5,1,WORKBENCH:0)
Block(-6,5,2,FURNACE:4,NBT/skyscraper_8x6_01/76-furnaceC16R48.nbt)
Block(-6,5,3,CONCRETE:7)
Block(-6,5,4,STEP:8)
Block(-6,5,5,STEP:8)
Block(-6,5,6,STEP:8)
Block(-6,5,7,CONCRETE:7)
Block(-6,5,8,IRON_TRAPDOOR:10)
Block(-6,6,-7,AIR:0)
Block(-6,6,-6,OBSIDIAN:0)
Block(-6,6,-5,OBSIDIAN:0)
Block(-6,6,-4,OBSIDIAN:0)
Block(-6,6,-3,OBSIDIAN:0)
Block(-6,6,-2,CONCRETE:7)
Block(-6,6,-1,OBSIDIAN:0)
Block(-6,6,0,OBSIDIAN:0)
Block(-6,6,1,WORKBENCH:0)
Block(-6,6,2,DROPPER:4,NBT/skyscraper_8x6_01/80-dropperC16R48.nbt)
Block(-6,6,3,CONCRETE:7)
#RandomBlock(-6,6,4,TRAPPED_CHEST:5,../../../../../Chests/Loot/ModernCityJunk_1.nbt,65,CHEST:4,../../../../../Chests/Loot/ModernCityJunk_1.nbt,20,CHEST:4,../../../../../Chests/Loot/ModernCityJunk_2.nbt,15,CHEST:4,../../../../../Chests/Loot/ModernCityJunk_3.nbt,15,CHEST:4,../../../../../Chests/Loot/ModernCityJunk_4.nbt,15,CHEST:4,../../../../../Chests/Loot/ModernCityJunk_5.nbt,15,CHEST:4,../../../../../Chests/Loot/ModernCityCommon_1.nbt,5,CHEST:4,../../../../../Chests/Loot/ModernCityCommon_2.nbt,5,CHEST:4,../../../../../Chests/Loot/ModernCityCommon_3.nbt,5,CHEST:4,../../../../../Chests/Loot/ModernCityCommon_4.nbt,5,CHEST:4,../../../../../Chests/Loot/ModernCityCommon_5.nbt,5,CHEST:4,../../../../../Chests/Loot/ModernCityGood_1.nbt,3,CHEST:4,../../../../../Chests/Loot/ModernCityGood_2.nbt,3,CHEST:4,../../../../../Chests/Loot/ModernCityGood_3.nbt,3,CHEST:4,../../../../../Chests/Loot/ModernCityGood_4.nbt,3,CHEST:4,../../../../../Chests/Loot/ModernCityGood_5.nbt,3,CHEST:4,../../../../../Chests/Loot/ModernCityEpic_1.nbt,1,CHEST:4,../../../../../Chests/Loot/ModernCityEpic_2.nbt,1,CHEST:4,../../../../../Chests/Loot/ModernCityEpic_3.nbt,1,CHEST:4,../../../../../Chests/Loot/ModernCityEpic_4.nbt,1,CHEST:4,../../../../../Chests/Loot/ModernCityEpic_5.nbt,1,CHEST:4,../../../../../Chests/Loot/Common1.nbt,25,CHEST:4,../../../../../Chests/Loot/Common2.nbt,25,CHEST:4,../../../../../Chests/Loot/Common3.nbt,25,CHEST:4,../../../../../Chests/Loot/Common4.nbt,25,CHEST:4,../../../../../Chests/Loot/Common5.nbt,25,CHEST:4,../../../../../Chests/Loot/Common6.nbt,25,CHEST:4,../../../../../Chests/Loot/Common7.nbt,25,CHEST:4,../../../../../Chests/Loot/Common8.nbt,25,CHEST:4,../../../../../Chests/Loot/Common9.nbt,25,CHEST:4,../../../../../Chests/Loot/Common10.nbt,25,CHEST:4,../../../../../Chests/Loot/Common11.nbt,25,CHEST:4,../../../../../Chests/Loot/Common12.nbt,25,CHEST:4,../../../../../Chests/Loot/Common13.nbt,25,CHEST:4,../../../../../Chests/Loot/Common14.nbt,25,CHEST:4,../../../../../Chests/Loot/Common15.nbt,25,CHEST:4,../../../../../Chests/Loot/Rare1.nbt,10,CHEST:4,../../../../../Chests/Loot/Rare2.nbt,10,CHEST:5,../../../../../Chests/Loot/Rare3.nbt,10,CHEST:4,../../../../../Chests/Loot/Rare4.nbt,10,CHEST:4,../../../../../Chests/Loot/Rare5.nbt,10,CHEST:4,../../../../../Chests/Loot/Rare6.nbt,10,CHEST:4,../../../../../Chests/Loot/Rare7.nbt,10,CHEST:4,../../../../../Chests/Loot/Rare8.nbt,10,CHEST:4,../../../../../Chests/Loot/Rare9.nbt,10,CHEST:4,../../../../../Chests/Loot/Rare10.nbt,10,CHEST:4,../../../../../Chests/Loot/Rare11.nbt,10,CHEST:4,../../../../../Chests/Loot/Rare12.nbt,10,CHEST:4,../../../../../Chests/Loot/Rare13.nbt,10,CHEST:4,../../../../../Chests/Loot/Rare14.nbt,10,CHEST:4,../../../../../Chests/Loot/Rare15.nbt,10,CHEST:4,../../../../../Chests/Loot/Epic1.nbt,1,CHEST:4,../../../../../Chests/Loot/Epic2.nbt,1,CHEST:4,../../../../../Chests/Loot/Epic3.nbt,1,CHEST:4,../../../../../Chests/Loot/Epic4.nbt,1,CHEST:4,../../../../../Chests/Loot/Epic5.nbt,1,CHEST:4,../../../../../Chests/Loot/Epic6.nbt,1,CHEST:4,../../../../../Chests/Loot/Epic7.nbt,1,CHEST:4,../../../../../Chests/Loot/Epic8.nbt,1,CHEST:4,../../../../../Chests/Loot/Epic9.nbt,1,CHEST:4,../../../../../Chests/Loot/Epic10.nbt,1,CHEST:4,../../../../../Chests/Loot/Epic11.nbt,1,CHEST:4,../../../../../Chests/Loot/Epic12.nbt,1,CHEST:4,../../../../../Chests/Loot/Epic13.nbt,1,CHEST:4,../../../../../Chests/Loot/Epic14.nbt,1,CHEST:4,../../../../../Chests/Loot/Epic15.nbt,1,CHEST:4,../../../../../Chests/Loot/ModernCityJunk_1.nbt,100)
Block(-6,6,5,AIR:0)
Block(-6,6,6,AIR:0)
Block(-6,6,7,CONCRETE:7)
#RandomBlock(-6,6,8,TRAPPED_CHEST:5,../../../../../Chests/Loot/ModernCityJunk_1.nbt,65,CHEST:4,../../../../../Chests/Loot/ModernCityJunk_1.nbt,20,CHEST:4,../../../../../Chests/Loot/ModernCityJunk_2.nbt,15,CHEST:4,../../../../../Chests/Loot/ModernCityJunk_3.nbt,15,CHEST:4,../../../../../Chests/Loot/ModernCityJunk_4.nbt,15,CHEST:4,../../../../../Chests/Loot/ModernCityJunk_5.nbt,15,CHEST:4,../../../../../Chests/Loot/ModernCityCommon_1.nbt,5,CHEST:4,../../../../../Chests/Loot/ModernCityCommon_2.nbt,5,CHEST:4,../../../../../Chests/Loot/ModernCityCommon_3.nbt,5,CHEST:4,../../../../../Chests/Loot/ModernCityCommon_4.nbt,5,CHEST:4,../../../../../Chests/Loot/ModernCityCommon_5.nbt,5,CHEST:4,../../../../../Chests/Loot/ModernCityGood_1.nbt,3,CHEST:4,../../../../../Chests/Loot/ModernCityGood_2.nbt,3,CHEST:4,../../../../../Chests/Loot/ModernCityGood_3.nbt,3,CHEST:4,../../../../../Chests/Loot/ModernCityGood_4.nbt,3,CHEST:4,../../../../../Chests/Loot/ModernCityGood_5.nbt,3,CHEST:4,../../../../../Chests/Loot/ModernCityEpic_1.nbt,1,CHEST:4,../../../../../Chests/Loot/ModernCityEpic_2.nbt,1,CHEST:4,../../../../../Chests/Loot/ModernCityEpic_3.nbt,1,CHEST:4,../../../../../Chests/Loot/ModernCityEpic_4.nbt,1,CHEST:4,../../../../../Chests/Loot/ModernCityEpic_5.nbt,1,CHEST:4,../../../../../Chests/Loot/Common1.nbt,25,CHEST:4,../../../../../Chests/Loot/Common2.nbt,25,CHEST:4,../../../../../Chests/Loot/Common3.nbt,25,CHEST:4,../../../../../Chests/Loot/Common4.nbt,25,CHEST:4,../../../../../Chests/Loot/Common5.nbt,25,CHEST:4,../../../../../Chests/Loot/Common6.nbt,25,CHEST:4,../../../../../Chests/Loot/Common7.nbt,25,CHEST:4,../../../../../Chests/Loot/Common8.nbt,25,CHEST:4,../../../../../Chests/Loot/Common9.nbt,25,CHEST:4,../../../../../Chests/Loot/Common10.nbt,25,CHEST:4,../../../../../Chests/Loot/Common11.nbt,25,CHEST:4,../../../../../Chests/Loot/Common12.nbt,25,CHEST:4,../../../../../Chests/Loot/Common13.nbt,25,CHEST:4,../../../../../Chests/Loot/Common14.nbt,25,CHEST:4,../../../../../Chests/Loot/Common15.nbt,25,CHEST:4,../../../../../Chests/Loot/Rare1.nbt,10,CHEST:4,../../../../../Chests/Loot/Rare2.nbt,10,CHEST:5,../../../../../Chests/Loot/Rare3.nbt,10,CHEST:4,../../../../../Chests/Loot/Rare4.nbt,10,CHEST:4,../../../../../Chests/Loot/Rare5.nbt,10,CHEST:4,../../../../../Chests/Loot/Rare6.nbt,10,CHEST:4,../../../../../Chests/Loot/Rare7.nbt,10,CHEST:4,../../../../../Chests/Loot/Rare8.nbt,10,CHEST:4,../../../../../Chests/Loot/Rare9.nbt,10,CHEST:4,../../../../../Chests/Loot/Rare10.nbt,10,CHEST:4,../../../../../Chests/Loot/Rare11.nbt,10,CHEST:4,../../../../../Chests/Loot/Rare12.nbt,10,CHEST:4,../../../../../Chests/Loot/Rare13.nbt,10,CHEST:4,../../../../../Chests/Loot/Rare14.nbt,10,CHEST:4,../../../../../Chests/Loot/Rare15.nbt,10,CHEST:4,../../../../../Chests/Loot/Epic1.nbt,1,CHEST:4,../../../../../Chests/Loot/Epic2.nbt,1,CHEST:4,../../../../../Chests/Loot/Epic3.nbt,1,CHEST:4,../../../../../Chests/Loot/Epic4.nbt,1,CHEST:4,../../../../../Chests/Loot/Epic5.nbt,1,CHEST:4,../../../../../Chests/Loot/Epic6.nbt,1,CHEST:4,../../../../../Chests/Loot/Epic7.nbt,1,CHEST:4,../../../../../Chests/Loot/Epic8.nbt,1,CHEST:4,../../../../../Chests/Loot/Epic9.nbt,1,CHEST:4,../../../../../Chests/Loot/Epic10.nbt,1,CHEST:4,../../../../../Chests/Loot/Epic11.nbt,1,CHEST:4,../../../../../Chests/Loot/Epic12.nbt,1,CHEST:4,../../../../../Chests/Loot/Epic13.nbt,1,CHEST:4,../../../../../Chests/Loot/Epic14.nbt,1,CHEST:4,../../../../../Chests/Loot/Epic15.nbt,1,CHEST:4,../../../../../Chests/Loot/ModernCityJunk_1.nbt,100)
Block(-6,7,-7,OBSIDIAN:0)
Block(-6,7,-6,OBSIDIAN:0)
Block(-6,7,-5,OBSIDIAN:0)
Block(-6,7,-4,OBSIDIAN:0)
Block(-6,7,-3,OBSIDIAN:0)
Block(-6,7,-2,CONCRETE:7)
Block(-6,7,-1,OBSIDIAN:0)
Block(-6,7,0,OBSIDIAN:0)
Block(-6,7,1,DROPPER:0,NBT/skyscraper_8x6_01/86-dropperC16R48.nbt)
Block(-6,7,2,REDSTONE_LAMP_OFF:0)
Block(-6,7,3,CONCRETE:7)
Block(-6,7,4,AIR:0)
Block(-6,7,5,AIR:0)
Block(-6,7,6,AIR:0)
Block(-6,7,7,CONCRETE:7)
Block(-6,7,8,IRON_TRAPDOOR:2)
Block(-6,8,-7,OBSIDIAN:0)
Block(-6,8,-6,OBSIDIAN:0)
Block(-6,8,-5,OBSIDIAN:0)
Block(-6,8,-4,OBSIDIAN:0)
Block(-6,8,-3,OBSIDIAN:0)
Block(-6,8,-2,OBSIDIAN:0)
Block(-6,8,-1,CONCRETE:7)
Block(-6,8,0,CONCRETE:7)
Block(-6,8,1,AIR:0)
Block(-6,8,2,AIR:0)
Block(-6,8,3,CONCRETE:7)
Block(-6,8,4,IRON_TRAPDOOR:10)
Block(-6,8,5,IRON_TRAPDOOR:10)
Block(-6,8,6,IRON_TRAPDOOR:10)
Block(-6,8,7,CONCRETE:7)
Block(-6,8,8,AIR:0)
Block(-6,9,-7,OBSIDIAN:0)
Block(-6,9,-6,OBSIDIAN:0)
Block(-6,9,-5,OBSIDIAN:0)
Block(-6,9,-4,OBSIDIAN:0)
Block(-6,9,-3,OBSIDIAN:0)
Block(-6,9,-2,CONCRETE:7)
Block(-6,9,-1,OBSIDIAN:0)
Block(-6,9,0,OBSIDIAN:0)
Block(-6,9,1,IRON_TRAPDOOR:10)
Block(-6,9,2,IRON_TRAPDOOR:10)
Block(-6,9,3,IRON_TRAPDOOR:10)
Block(-6,9,4,CONCRETE:14)
Block(-6,9,5,AIR:0)
Block(-6,9,6,AIR:0)
Block(-6,9,7,AIR:0)
Block(-6,9,8,AIR:0)
Block(-6,10,-7,OBSIDIAN:0)
Block(-6,10,-6,OBSIDIAN:0)
Block(-6,10,-5,OBSIDIAN:0)
Block(-6,10,-4,OBSIDIAN:0)
Block(-6,10,-3,OBSIDIAN:0)
Block(-6,10,-2,CONCRETE:7)
Block(-6,10,-1,OBSIDIAN:0)
Block(-6,10,0,OBSIDIAN:0)
Block(-6,10,1,CONCRETE:14)
Block(-6,10,2,CONCRETE:14)
Block(-6,10,3,CONCRETE:14)
Block(-6,10,4,CONCRETE:14)
Block(-6,10,5,AIR:0)
Block(-6,10,6,AIR:0)
Block(-6,10,7,AIR:0)
Block(-6,10,8,AIR:0)
Block(-6,11,-7,OBSIDIAN:0)
Block(-6,11,-6,OBSIDIAN:0)
Block(-6,11,-5,OBSIDIAN:0)
Block(-6,11,-4,OBSIDIAN:0)
Block(-6,11,-3,OBSIDIAN:0)
Block(-6,11,-2,OBSIDIAN:0)
Block(-6,11,-1,OBSIDIAN:0)
Block(-6,11,0,OBSIDIAN:0)
Block(-6,11,1,AIR:0)
Block(-6,11,2,AIR:0)
Block(-6,11,3,IRON_FENCE:0)
Block(-6,11,4,CONCRETE:4)
Block(-6,11,5,AIR:0)
Block(-6,11,6,AIR:0)
Block(-6,11,7,AIR:0)
Block(-6,11,8,AIR:0)
Block(-6,12,-7,OBSIDIAN:0)
Block(-6,12,-6,OBSIDIAN:0)
Block(-6,12,-5,OBSIDIAN:0)
Block(-6,12,-4,OBSIDIAN:0)
Block(-6,12,-3,OBSIDIAN:0)
Block(-6,12,-2,CONCRETE:7)
Block(-6,12,-1,CONCRETE:7)
Block(-6,12,0,CONCRETE:7)
Block(-6,12,1,IRON_TRAPDOOR:10)
Block(-6,12,2,IRON_TRAPDOOR:10)
Block(-6,12,3,CONCRETE:7)
Block(-6,12,4,IRON_TRAPDOOR:10)
Block(-6,12,5,IRON_TRAPDOOR:9)
Block(-6,12,6,IRON_TRAPDOOR:9)
Block(-6,12,7,CONCRETE:7)
Block(-6,12,8,IRON_TRAPDOOR:9)
Block(-6,13,-7,OBSIDIAN:0)
Block(-6,13,-6,OBSIDIAN:0)
Block(-6,13,-5,OBSIDIAN:0)
Block(-6,13,-4,OBSIDIAN:0)
Block(-6,13,-3,OBSIDIAN:0)
Block(-6,13,-2,CONCRETE:7)
Block(-6,13,-1,OBSIDIAN:0)
Block(-6,13,0,OBSIDIAN:0)
Block(-6,13,1,AIR:0)
Block(-6,13,2,AIR:0)
Block(-6,13,3,AIR:0)
Block(-6,13,4,AIR:0)
Block(-6,13,5,AIR:0)
Block(-6,13,6,AIR:0)
Block(-6,13,7,AIR:0)
Block(-6,13,8,AIR:0)
Block(-6,14,-7,OBSIDIAN:0)
Block(-6,14,-6,OBSIDIAN:0)
Block(-6,14,-5,OBSIDIAN:0)
Block(-6,14,-4,OBSIDIAN:0)
Block(-6,14,-3,OBSIDIAN:0)
Block(-6,14,-2,CONCRETE:7)
Block(-6,14,-1,OBSIDIAN:0)
Block(-6,14,0,OBSIDIAN:0)
Block(-6,14,1,STEP:8)
Block(-6,14,2,STEP:8)
Block(-6,14,3,CONCRETE:7)
Block(-6,14,4,STEP:8)
Block(-6,14,5,STEP:8)
Block(-6,14,6,STEP:8)
Block(-6,14,7,CONCRETE:7)
Block(-6,14,8,STEP:8)
Block(-6,15,-7,OBSIDIAN:0)
Block(-6,15,-6,OBSIDIAN:0)
Block(-6,15,-5,OBSIDIAN:0)
Block(-6,15,-4,OBSIDIAN:0)
Block(-6,15,-3,OBSIDIAN:0)
Block(-6,15,-2,CONCRETE:7)
Block(-6,15,-1,CONCRETE:7)
Block(-6,15,0,CONCRETE:7)
Block(-6,15,1,CONCRETE:7)
Block(-6,15,2,CONCRETE:7)
Block(-6,15,3,CONCRETE:7)
Block(-6,15,4,CONCRETE:7)
Block(-6,15,5,CONCRETE:7)
Block(-6,15,6,CONCRETE:7)
Block(-6,15,7,CONCRETE:7)
Block(-6,15,8,CONCRETE:7)
Block(-6,16,-7,OBSIDIAN:0)
Block(-6,16,-6,OBSIDIAN:0)
Block(-6,16,-5,OBSIDIAN:0)
Block(-6,16,-4,OBSIDIAN:0)
Block(-6,16,-3,OBSIDIAN:0)
Block(-6,16,-2,OBSIDIAN:0)
Block(-6,16,-1,OBSIDIAN:0)
Block(-6,16,0,OBSIDIAN:0)
Block(-6,16,1,OBSIDIAN:0)
Block(-6,16,2,OBSIDIAN:0)
Block(-6,16,3,OBSIDIAN:0)
Block(-6,16,4,OBSIDIAN:0)
Block(-6,16,5,OBSIDIAN:0)
Block(-6,16,6,OBSIDIAN:0)
Block(-6,16,7,OBSIDIAN:0)
Block(-6,16,8,OBSIDIAN:0)
Block(-6,17,-7,CONCRETE:7)
Block(-6,17,-6,CONCRETE:7)
Block(-6,17,-5,CONCRETE:7)
Block(-6,17,-4,CONCRETE:7)
Block(-6,17,-3,CONCRETE:7)
Block(-6,17,-2,CONCRETE:7)
Block(-6,17,-1,CONCRETE:7)
Block(-6,17,0,CONCRETE:7)
Block(-6,17,1,CONCRETE:7)
Block(-6,17,2,CONCRETE:7)
Block(-6,17,3,CONCRETE:7)
Block(-6,17,4,CONCRETE:7)
Block(-6,17,5,CONCRETE:7)
Block(-6,17,6,CONCRETE:7)
Block(-6,17,7,CONCRETE:7)
Block(-6,17,8,CONCRETE:7)
Block(-6,18,-5,QUARTZ_STAIRS:2)
Block(-6,18,-4,CONCRETE:7)
Block(-6,18,-3,CONCRETE:7)
Block(-6,18,-2,CONCRETE:7)
Block(-6,18,-1,CONCRETE:7)
Block(-6,18,0,CONCRETE:7)
Block(-6,18,1,CONCRETE:7)
Block(-6,18,2,OBSIDIAN:0)
Block(-6,18,3,OBSIDIAN:0)
Block(-6,18,4,OBSIDIAN:0)
Block(-6,18,5,CONCRETE:0)
Block(-6,18,6,QUARTZ_STAIRS:7)
Block(-6,18,7,QUARTZ_STAIRS:4)
Block(-6,19,-6,TRIPWIRE_HOOK:2)
Block(-6,19,-5,CONCRETE:14)
Block(-6,19,-4,CONCRETE:7)
Block(-6,19,-3,CONCRETE:7)
Block(-6,19,-2,CONCRETE:7)
Block(-6,19,-1,CONCRETE:7)
Block(-6,19,0,CONCRETE:7)
Block(-6,19,1,CONCRETE:7)
Block(-6,19,2,OBSIDIAN:0)
Block(-6,19,3,OBSIDIAN:0)
Block(-6,19,4,OBSIDIAN:0)
Block(-6,19,5,CONCRETE:0)
Block(-6,19,6,QUARTZ_STAIRS:7)
Block(-6,19,7,QUARTZ_STAIRS:4)
Block(-6,20,-5,IRON_TRAPDOOR:0)
Block(-6,20,-4,CONCRETE:7)
Block(-6,20,-3,CONCRETE:7)
Block(-6,20,-2,CONCRETE:7)
Block(-6,20,-1,CONCRETE:7)
Block(-6,20,0,CONCRETE:7)
Block(-6,20,1,CONCRETE:7)
Block(-6,20,2,OBSIDIAN:0)
Block(-6,20,3,OBSIDIAN:0)
Block(-6,20,4,OBSIDIAN:0)
Block(-6,20,5,CONCRETE:0)
Block(-6,20,6,QUARTZ_STAIRS:7)
Block(-6,20,7,QUARTZ_STAIRS:4)
Block(-6,21,-7,STEP:8)
Block(-6,21,-6,STEP:8)
Block(-6,21,-5,STEP:8)
Block(-6,21,-4,CONCRETE:7)
Block(-6,21,-3,CONCRETE:7)
Block(-6,21,-2,CONCRETE:7)
Block(-6,21,-1,CONCRETE:7)
Block(-6,21,0,CONCRETE:7)
Block(-6,21,1,CONCRETE:7)
Block(-6,21,2,OBSIDIAN:0)
Block(-6,21,3,OBSIDIAN:0)
Block(-6,21,4,OBSIDIAN:0)
Block(-6,21,5,CONCRETE:0)
Block(-6,21,6,QUARTZ_STAIRS:4)
Block(-6,21,7,CONCRETE:7)
Block(-6,22,-7,CONCRETE:7)
Block(-6,22,-6,CONCRETE:7)
Block(-6,22,-5,CONCRETE:7)
Block(-6,22,-4,CONCRETE:7)
Block(-6,22,-3,CONCRETE:7)
Block(-6,22,-2,CONCRETE:7)
Block(-6,22,-1,CONCRETE:7)
Block(-6,22,0,CONCRETE:7)
Block(-6,22,1,CONCRETE:7)
Block(-6,22,2,OBSIDIAN:0)
Block(-6,22,3,OBSIDIAN:0)
Block(-6,22,4,OBSIDIAN:0)
Block(-6,22,5,CONCRETE:0)
Block(-6,22,6,QUARTZ_STAIRS:4)
Block(-6,22,7,CONCRETE:7)
Block(-6,23,-7,OBSIDIAN:0)
Block(-6,23,-6,OBSIDIAN:0)
Block(-6,23,-5,OBSIDIAN:0)
Block(-6,23,-4,OBSIDIAN:0)
Block(-6,23,-3,OBSIDIAN:0)
Block(-6,23,-2,OBSIDIAN:0)
Block(-6,23,-1,OBSIDIAN:0)
Block(-6,23,0,OBSIDIAN:0)
Block(-6,23,1,OBSIDIAN:0)
Block(-6,23,2,OBSIDIAN:0)
Block(-6,23,3,OBSIDIAN:0)
Block(-6,23,4,OBSIDIAN:0)
Block(-6,23,5,OBSIDIAN:0)
Block(-6,23,6,CONCRETE:7)
Block(-6,23,7,CONCRETE:7)
Block(-6,24,-7,STONE:4)
Block(-6,24,-6,STONE:4)
Block(-6,24,-5,STONE:6)
Block(-6,24,-4,CONCRETE:0)
Block(-6,24,-3,CONCRETE:7)
Block(-6,24,-2,CONCRETE:0)
Block(-6,24,-1,CONCRETE:15)
Block(-6,24,0,CONCRETE:0)
Block(-6,24,1,CONCRETE:15)
Block(-6,24,2,STONE:6)
Block(-6,24,3,CONCRETE:0)
Block(-6,24,4,CONCRETE:0)
Block(-6,24,5,QUARTZ_STAIRS:3)
Block(-6,24,6,CONCRETE:7)
Block(-6,24,7,CONCRETE:7)
Block(-6,25,0,LOG:5)
Block(-6,25,1,STANDING_BANNER:2,NBT/skyscraper_8x6_01/88-bannerC16R48.nbt)
Block(-6,25,2,TRAP_DOOR:5)
Block(-6,25,4,CONCRETE:0)
Block(-6,25,7,STEP:7)
Block(-6,26,1,IRON_TRAPDOOR:1)
Block(-6,26,4,CONCRETE:0)
Block(-6,27,0,TRAP_DOOR:7)
Block(-6,27,4,CONCRETE:0)
Block(-6,28,4,CONCRETE:0)
Block(-6,28,5,QUARTZ_STAIRS:7)
Block(-6,29,-5,QUARTZ_STAIRS:5)
Block(-6,29,-4,STEP:8)
Block(-6,29,-3,CONCRETE:0)
Block(-6,29,-2,CONCRETE:0)
Block(-6,29,-1,CONCRETE:0)
Block(-6,29,0,CONCRETE:0)
Block(-6,29,1,CONCRETE:15)
Block(-6,29,2,CONCRETE:0)
Block(-6,29,3,CONCRETE:0)
Block(-6,29,4,CONCRETE:0)
Block(-6,29,5,CONCRETE:0)
Block(-6,29,6,QUARTZ_STAIRS:7)
Block(-6,30,-5,CONCRETE:0)
Block(-6,30,-4,STAINED_GLASS_PANE:15)
Block(-6,30,-3,STAINED_GLASS_PANE:15)
Block(-6,30,4,CONCRETE:0)
Block(-6,30,5,CONCRETE:0)
Block(-6,30,6,COBBLE_WALL:0)
Block(-6,31,-5,STEP:0)
Block(-6,31,4,CONCRETE:0)
Block(-6,31,5,CONCRETE:0)
Block(-6,32,4,CONCRETE:0)
Block(-6,32,5,CONCRETE:0)
Block(-6,33,1,CONCRETE:0)
Block(-6,33,2,STEP:8)
Block(-6,33,3,STEP:8)
Block(-6,33,4,CONCRETE:0)
Block(-6,33,5,CONCRETE:0)
Block(-6,33,6,QUARTZ_STAIRS:7)
Block(-6,34,1,STAINED_GLASS_PANE:15)
Block(-6,34,4,CONCRETE:7)
Block(-6,34,5,STEP:7)
Block(-6,34,6,COBBLE_WALL:0)
Block(-6,35,4,STAINED_GLASS_PANE:15)
Block(-6,36,4,STAINED_GLASS_PANE:15)
Block(-6,36,5,COBBLE_WALL:0)
Block(-6,37,4,CONCRETE:0)
Block(-6,37,5,CONCRETE:0)
Block(-6,37,6,STEP:8)
Block(-6,38,-6,IRON_TRAPDOOR:11)
Block(-6,38,3,CONCRETE:0)
Block(-6,38,4,CONCRETE:7)
Block(-6,38,5,CONCRETE:0)
Block(-6,39,-7,TRAP_DOOR:4)
Block(-6,39,-6,SEA_LANTERN:0)
Block(-6,39,-5,TRAP_DOOR:5)
Block(-6,39,3,CONCRETE:0)
Block(-6,39,4,CONCRETE:7)
Block(-6,39,5,COBBLE_WALL:0)
Block(-6,40,-6,IRON_FENCE:0)
Block(-6,40,2,QUARTZ_STAIRS:5)
Block(-6,40,3,CONCRETE:7)
Block(-6,41,-6,IRON_FENCE:0)
Block(-6,41,1,QUARTZ_STAIRS:6)
Block(-6,41,2,CONCRETE:7)
Block(-6,42,-6,IRON_FENCE:0)
Block(-6,42,1,CONCRETE:0)
Block(-6,42,2,CONCRETE:7)
Block(-6,43,-6,COBBLE_WALL:0)
Block(-6,43,-2,QUARTZ_STAIRS:6)
Block(-6,43,-1,QUARTZ_STAIRS:4)
Block(-6,43,0,CONCRETE:7)
Block(-6,43,1,CONCRETE:7)
Block(-6,44,-6,CONCRETE:7)
Block(-6,44,-3,QUARTZ_STAIRS:6)
Block(-6,44,-2,CONCRETE:0)
Block(-6,44,-1,CONCRETE:7)
Block(-6,45,-6,CONCRETE:7)
Block(-6,45,-5,CONCRETE:0)
Block(-6,45,-4,CONCRETE:0)
Block(-6,45,-3,CONCRETE:0)
Block(-6,45,-2,CONCRETE:0)
Block(-6,46,-7,CONCRETE:7)
Block(-6,46,-6,CONCRETE:7)
Block(-5,0,-7,CONCRETE:7)
Block(-5,0,-6,CONCRETE:7)
Block(-5,0,-5,CONCRETE:7)
Block(-5,0,-4,CONCRETE:7)
Block(-5,0,-3,CONCRETE:7)
Block(-5,0,-2,CONCRETE:7)
Block(-5,0,-1,CONCRETE:7)
Block(-5,0,0,CONCRETE:7)
Block(-5,0,1,CONCRETE:7)
Block(-5,0,2,CONCRETE:7)
Block(-5,0,3,CONCRETE:7)
Block(-5,0,4,CONCRETE:7)
Block(-5,0,5,CONCRETE:7)
Block(-5,0,6,CONCRETE:7)
Block(-5,0,7,CONCRETE:7)
Block(-5,0,8,CONCRETE:7)
Block(-5,1,-7,OBSIDIAN:0)
Block(-5,1,-6,OBSIDIAN:0)
Block(-5,1,-5,OBSIDIAN:0)
Block(-5,1,-4,OBSIDIAN:0)
Block(-5,1,-3,OBSIDIAN:0)
Block(-5,1,-2,OBSIDIAN:0)
Block(-5,1,-1,OBSIDIAN:0)
Block(-5,1,0,OBSIDIAN:0)
Block(-5,1,1,OBSIDIAN:0)
Block(-5,1,2,OBSIDIAN:0)
Block(-5,1,3,OBSIDIAN:0)
Block(-5,1,4,OBSIDIAN:0)
Block(-5,1,5,OBSIDIAN:0)
Block(-5,1,6,OBSIDIAN:0)
Block(-5,1,7,OBSIDIAN:0)
Block(-5,1,8,OBSIDIAN:0)
Block(-5,2,-7,CONCRETE:7)
Block(-5,2,-6,CONCRETE:7)
Block(-5,2,-5,CONCRETE:7)
Block(-5,2,-4,CONCRETE:7)
Block(-5,2,-3,CONCRETE:7)
Block(-5,2,-2,CONCRETE:7)
Block(-5,2,-1,CONCRETE:7)
Block(-5,2,0,CONCRETE:7)
Block(-5,2,1,CONCRETE:7)
Block(-5,2,2,CONCRETE:7)
Block(-5,2,3,CONCRETE:7)
Block(-5,2,4,CONCRETE:7)
Block(-5,2,5,CONCRETE:7)
Block(-5,2,6,CONCRETE:7)
Block(-5,2,7,CONCRETE:7)
Block(-5,2,8,CONCRETE:7)
Block(-5,3,-7,CONCRETE:7)
Block(-5,3,-6,CONCRETE:7)
Block(-5,3,-5,CONCRETE:7)
Block(-5,3,-4,CONCRETE:7)
Block(-5,3,-3,CONCRETE:7)
Block(-5,3,-2,CONCRETE:7)
Block(-5,3,-1,CONCRETE:7)
Block(-5,3,0,CONCRETE:7)
Block(-5,3,1,CONCRETE:7)
Block(-5,3,2,CONCRETE:7)
Block(-5,3,3,CONCRETE:7)
Block(-5,3,4,CONCRETE:7)
Block(-5,3,5,CONCRETE:7)
Block(-5,3,6,CONCRETE:7)
Block(-5,3,7,CONCRETE:7)
Block(-5,3,8,CONCRETE:7)
Block(-5,4,-7,CONCRETE:7)
Block(-5,4,-6,OBSIDIAN:0)
Block(-5,4,-5,CONCRETE:7)
Block(-5,4,-4,CONCRETE:7)
Block(-5,4,-3,CONCRETE:7)
Block(-5,4,-2,OBSIDIAN:0)
Block(-5,4,-1,CONCRETE:7)
Block(-5,4,0,CONCRETE:7)
Block(-5,4,1,CONCRETE:7)
Block(-5,4,2,CONCRETE:7)
Block(-5,4,3,CONCRETE:7)
Block(-5,4,4,CONCRETE:7)
Block(-5,4,5,CONCRETE:7)
Block(-5,4,6,CONCRETE:7)
Block(-5,4,7,CONCRETE:7)
Block(-5,4,8,CONCRETE:7)
Block(-5,5,-7,IRON_DOOR_BLOCK:2)
Block(-5,5,-6,OBSIDIAN:0)
Block(-5,5,-5,CONCRETE:7)
Block(-5,5,-4,CONCRETE:7)
Block(-5,5,-3,CONCRETE:7)
Block(-5,5,-2,OBSIDIAN:0)
Block(-5,5,-1,OBSIDIAN:0)
Block(-5,5,0,OBSIDIAN:0)
Block(-5,5,1,OBSIDIAN:0)
Block(-5,5,2,OBSIDIAN:0)
Block(-5,5,3,CONCRETE:7)
Block(-5,5,4,OBSIDIAN:0)
Block(-5,5,5,OBSIDIAN:0)
Block(-5,5,6,OBSIDIAN:0)
Block(-5,5,7,CONCRETE:7)
Block(-5,5,8,OBSIDIAN:0)
Block(-5,6,-7,IRON_DOOR_BLOCK:8)
Block(-5,6,-6,OBSIDIAN:0)
Block(-5,6,-5,CONCRETE:7)
Block(-5,6,-4,CONCRETE:7)
Block(-5,6,-3,CONCRETE:7)
Block(-5,6,-2,OBSIDIAN:0)
Block(-5,6,-1,OBSIDIAN:0)
Block(-5,6,0,OBSIDIAN:0)
Block(-5,6,1,OBSIDIAN:0)
Block(-5,6,2,OBSIDIAN:0)
Block(-5,6,3,CONCRETE:7)
Block(-5,6,4,OBSIDIAN:0)
Block(-5,6,5,OBSIDIAN:0)
Block(-5,6,6,OBSIDIAN:0)
Block(-5,6,7,CONCRETE:7)
Block(-5,6,8,OBSIDIAN:0)
Block(-5,7,-7,CONCRETE:7)
Block(-5,7,-6,OBSIDIAN:0)
Block(-5,7,-5,CONCRETE:7)
Block(-5,7,-4,CONCRETE:7)
Block(-5,7,-3,CONCRETE:7)
Block(-5,7,-2,OBSIDIAN:0)
Block(-5,7,-1,OBSIDIAN:0)
Block(-5,7,0,OBSIDIAN:0)
Block(-5,7,1,OBSIDIAN:0)
Block(-5,7,2,OBSIDIAN:0)
Block(-5,7,3,CONCRETE:7)
Block(-5,7,4,OBSIDIAN:0)
Block(-5,7,5,OBSIDIAN:0)
Block(-5,7,6,OBSIDIAN:0)
Block(-5,7,7,CONCRETE:7)
Block(-5,7,8,OBSIDIAN:0)
Block(-5,8,-7,OBSIDIAN:0)
Block(-5,8,-6,OBSIDIAN:0)
Block(-5,8,-5,OBSIDIAN:0)
Block(-5,8,-4,OBSIDIAN:0)
Block(-5,8,-3,OBSIDIAN:0)
Block(-5,8,-2,OBSIDIAN:0)
Block(-5,8,-1,CONCRETE:7)
Block(-5,8,0,CONCRETE:7)
Block(-5,8,1,CONCRETE:7)
Block(-5,8,2,CONCRETE:7)
Block(-5,8,3,CONCRETE:7)
Block(-5,8,4,CONCRETE:7)
Block(-5,8,5,CONCRETE:7)
Block(-5,8,6,CONCRETE:7)
Block(-5,8,7,CONCRETE:7)
Block(-5,8,8,CONCRETE:7)
Block(-5,9,-7,CONCRETE:7)
Block(-5,9,-6,OBSIDIAN:0)
Block(-5,9,-5,CONCRETE:7)
Block(-5,9,-4,CONCRETE:7)
Block(-5,9,-3,CONCRETE:7)
Block(-5,9,-2,OBSIDIAN:0)
Block(-5,9,-1,OBSIDIAN:0)
Block(-5,9,0,OBSIDIAN:0)
Block(-5,9,1,OBSIDIAN:0)
Block(-5,9,2,OBSIDIAN:0)
Block(-5,9,3,CONCRETE:7)
Block(-5,9,4,CONCRETE:14)
Block(-5,9,5,OBSIDIAN:0)
Block(-5,9,6,OBSIDIAN:0)
Block(-5,9,7,CONCRETE:7)
Block(-5,9,8,OBSIDIAN:0)
Block(-5,10,-7,CONCRETE:7)
Block(-5,10,-6,OBSIDIAN:0)
Block(-5,10,-5,CONCRETE:7)
Block(-5,10,-4,CONCRETE:7)
Block(-5,10,-3,CONCRETE:7)
Block(-5,10,-2,OBSIDIAN:0)
Block(-5,10,-1,OBSIDIAN:0)
Block(-5,10,0,OBSIDIAN:0)
Block(-5,10,1,OBSIDIAN:0)
Block(-5,10,2,OBSIDIAN:0)
Block(-5,10,3,CONCRETE:7)
Block(-5,10,4,OBSIDIAN:0)
Block(-5,10,5,OBSIDIAN:0)
Block(-5,10,6,OBSIDIAN:0)
Block(-5,10,7,CONCRETE:7)
Block(-5,10,8,OBSIDIAN:0)
Block(-5,11,-7,OBSIDIAN:0)
Block(-5,11,-6,OBSIDIAN:0)
Block(-5,11,-5,OBSIDIAN:0)
Block(-5,11,-4,OBSIDIAN:0)
Block(-5,11,-3,OBSIDIAN:0)
Block(-5,11,-2,OBSIDIAN:0)
Block(-5,11,-1,OBSIDIAN:0)
Block(-5,11,0,OBSIDIAN:0)
Block(-5,11,1,OBSIDIAN:0)
Block(-5,11,2,OBSIDIAN:0)
Block(-5,11,3,CONCRETE:7)
Block(-5,11,4,CONCRETE:4)
Block(-5,11,5,OBSIDIAN:0)
Block(-5,11,6,OBSIDIAN:0)
Block(-5,11,7,CONCRETE:7)
Block(-5,11,8,OBSIDIAN:0)
Block(-5,12,-7,CONCRETE:7)
Block(-5,12,-6,OBSIDIAN:0)
Block(-5,12,-5,CONCRETE:7)
Block(-5,12,-4,CONCRETE:7)
Block(-5,12,-3,CONCRETE:7)
Block(-5,12,-2,OBSIDIAN:0)
Block(-5,12,-1,CONCRETE:7)
Block(-5,12,0,CONCRETE:7)
Block(-5,12,1,CONCRETE:7)
Block(-5,12,2,CONCRETE:7)
Block(-5,12,3,CONCRETE:7)
Block(-5,12,4,CONCRETE:7)
Block(-5,12,5,CONCRETE:7)
Block(-5,12,6,CONCRETE:7)
Block(-5,12,7,CONCRETE:7)
Block(-5,12,8,CONCRETE:7)
Block(-5,13,-7,CONCRETE:7)
Block(-5,13,-6,OBSIDIAN:0)
Block(-5,13,-5,CONCRETE:7)
Block(-5,13,-4,CONCRETE:7)
Block(-5,13,-3,CONCRETE:7)
Block(-5,13,-2,OBSIDIAN:0)
Block(-5,13,-1,OBSIDIAN:0)
Block(-5,13,0,OBSIDIAN:0)
Block(-5,13,1,OBSIDIAN:0)
Block(-5,13,2,OBSIDIAN:0)
Block(-5,13,3,CONCRETE:7)
Block(-5,13,4,OBSIDIAN:0)
Block(-5,13,5,OBSIDIAN:0)
Block(-5,13,6,OBSIDIAN:0)
Block(-5,13,7,CONCRETE:7)
Block(-5,13,8,OBSIDIAN:0)
Block(-5,14,-7,CONCRETE:7)
Block(-5,14,-6,OBSIDIAN:0)
Block(-5,14,-5,CONCRETE:7)
Block(-5,14,-4,CONCRETE:7)
Block(-5,14,-3,CONCRETE:7)
Block(-5,14,-2,OBSIDIAN:0)
Block(-5,14,-1,OBSIDIAN:0)
Block(-5,14,0,OBSIDIAN:0)
Block(-5,14,1,OBSIDIAN:0)
Block(-5,14,2,OBSIDIAN:0)
Block(-5,14,3,CONCRETE:7)
Block(-5,14,4,OBSIDIAN:0)
Block(-5,14,5,OBSIDIAN:0)
Block(-5,14,6,OBSIDIAN:0)
Block(-5,14,7,CONCRETE:7)
Block(-5,14,8,OBSIDIAN:0)
Block(-5,15,-7,CONCRETE:7)
Block(-5,15,-6,CONCRETE:7)
Block(-5,15,-5,CONCRETE:7)
Block(-5,15,-4,CONCRETE:7)
Block(-5,15,-3,CONCRETE:7)
Block(-5,15,-2,CONCRETE:7)
Block(-5,15,-1,CONCRETE:7)
Block(-5,15,0,CONCRETE:7)
Block(-5,15,1,CONCRETE:7)
Block(-5,15,2,CONCRETE:7)
Block(-5,15,3,CONCRETE:7)
Block(-5,15,4,CONCRETE:7)
Block(-5,15,5,CONCRETE:7)
Block(-5,15,6,CONCRETE:7)
Block(-5,15,7,CONCRETE:7)
Block(-5,15,8,CONCRETE:7)
Block(-5,16,-7,OBSIDIAN:0)
Block(-5,16,-6,OBSIDIAN:0)
Block(-5,16,-5,OBSIDIAN:0)
Block(-5,16,-4,OBSIDIAN:0)
Block(-5,16,-3,OBSIDIAN:0)
Block(-5,16,-2,OBSIDIAN:0)
Block(-5,16,-1,OBSIDIAN:0)
Block(-5,16,0,OBSIDIAN:0)
Block(-5,16,1,OBSIDIAN:0)
Block(-5,16,2,OBSIDIAN:0)
Block(-5,16,3,OBSIDIAN:0)
Block(-5,16,4,OBSIDIAN:0)
Block(-5,16,5,OBSIDIAN:0)
Block(-5,16,6,OBSIDIAN:0)
Block(-5,16,7,OBSIDIAN:0)
Block(-5,16,8,OBSIDIAN:0)
Block(-5,17,-7,CONCRETE:7)
Block(-5,17,-6,CONCRETE:7)
Block(-5,17,-5,CONCRETE:7)
Block(-5,17,-4,CONCRETE:7)
Block(-5,17,-3,CONCRETE:7)
Block(-5,17,-2,CONCRETE:7)
Block(-5,17,-1,CONCRETE:7)
Block(-5,17,0,CONCRETE:7)
Block(-5,17,1,CONCRETE:7)
Block(-5,17,2,CONCRETE:7)
Block(-5,17,3,CONCRETE:7)
Block(-5,17,4,CONCRETE:7)
Block(-5,17,5,CONCRETE:7)
Block(-5,17,6,CONCRETE:7)
Block(-5,17,7,CONCRETE:7)
Block(-5,17,8,CONCRETE:7)
Block(-5,18,-4,STEP:8)
Block(-5,18,-3,CONCRETE:7)
Block(-5,18,-2,CONCRETE:7)
Block(-5,18,-1,CONCRETE:7)
Block(-5,18,0,CONCRETE:7)
Block(-5,18,1,CONCRETE:7)
Block(-5,18,2,CONCRETE:7)
Block(-5,18,3,CONCRETE:7)
Block(-5,18,4,OBSIDIAN:0)
Block(-5,18,5,CONCRETE:0)
Block(-5,18,6,CONCRETE:0)
Block(-5,18,7,QUARTZ_STAIRS:7)
Block(-5,19,-4,STEP:8)
Block(-5,19,-3,CONCRETE:7)
Block(-5,19,-2,CONCRETE:7)
Block(-5,19,-1,CONCRETE:7)
Block(-5,19,0,CONCRETE:7)
Block(-5,19,1,CONCRETE:7)
Block(-5,19,2,CONCRETE:7)
Block(-5,19,3,CONCRETE:7)
Block(-5,19,4,OBSIDIAN:0)
Block(-5,19,5,CONCRETE:0)
Block(-5,19,6,CONCRETE:0)
Block(-5,19,7,QUARTZ_STAIRS:7)
Block(-5,20,-4,STEP:8)
Block(-5,20,-3,CONCRETE:7)
Block(-5,20,-2,CONCRETE:7)
Block(-5,20,-1,CONCRETE:7)
Block(-5,20,0,CONCRETE:7)
Block(-5,20,1,CONCRETE:7)
Block(-5,20,2,CONCRETE:7)
Block(-5,20,3,CONCRETE:7)
Block(-5,20,4,OBSIDIAN:0)
Block(-5,20,5,CONCRETE:0)
Block(-5,20,6,CONCRETE:0)
Block(-5,20,7,QUARTZ_STAIRS:7)
Block(-5,21,-7,STEP:8)
Block(-5,21,-6,STEP:8)
Block(-5,21,-5,STEP:8)
Block(-5,21,-4,STEP:8)
Block(-5,21,-3,CONCRETE:7)
Block(-5,21,-2,CONCRETE:7)
Block(-5,21,-1,CONCRETE:7)
Block(-5,21,0,CONCRETE:7)
Block(-5,21,1,CONCRETE:7)
Block(-5,21,2,CONCRETE:7)
Block(-5,21,3,CONCRETE:7)
Block(-5,21,4,OBSIDIAN:0)
Block(-5,21,5,CONCRETE:0)
Block(-5,21,6,CONCRETE:0)
Block(-5,21,7,QUARTZ_STAIRS:7)
Block(-5,22,-7,CONCRETE:7)
Block(-5,22,-6,CONCRETE:7)
Block(-5,22,-5,CONCRETE:7)
Block(-5,22,-4,CONCRETE:7)
Block(-5,22,-3,CONCRETE:7)
Block(-5,22,-2,CONCRETE:7)
Block(-5,22,-1,CONCRETE:7)
Block(-5,22,0,CONCRETE:7)
Block(-5,22,1,CONCRETE:7)
Block(-5,22,2,CONCRETE:7)
Block(-5,22,3,CONCRETE:7)
Block(-5,22,4,OBSIDIAN:0)
Block(-5,22,5,CONCRETE:0)
Block(-5,22,6,CONCRETE:0)
Block(-5,22,7,QUARTZ_STAIRS:7)
Block(-5,23,-7,OBSIDIAN:0)
Block(-5,23,-6,OBSIDIAN:0)
Block(-5,23,-5,OBSIDIAN:0)
Block(-5,23,-4,OBSIDIAN:0)
Block(-5,23,-3,OBSIDIAN:0)
Block(-5,23,-2,OBSIDIAN:0)
Block(-5,23,-1,OBSIDIAN:0)
Block(-5,23,0,OBSIDIAN:0)
Block(-5,23,1,OBSIDIAN:0)
Block(-5,23,2,OBSIDIAN:0)
Block(-5,23,3,OBSIDIAN:0)
Block(-5,23,4,OBSIDIAN:0)
Block(-5,23,5,OBSIDIAN:0)
Block(-5,23,6,CONCRETE:0)
Block(-5,23,7,CONCRETE:7)
Block(-5,24,-7,STONE:6)
Block(-5,24,-6,CONCRETE:0)
Block(-5,24,-5,STONE:4)
Block(-5,24,-4,STONE:4)
Block(-5,24,-3,CONCRETE:0)
Block(-5,24,-2,CONCRETE:0)
Block(-5,24,-1,CONCRETE:0)
Block(-5,24,0,CONCRETE:15)
Block(-5,24,1,CONCRETE:15)
Block(-5,24,2,STONE:6)
Block(-5,24,3,CONCRETE:0)
Block(-5,24,4,CONCRETE:7)
Block(-5,24,5,STEP:0)
Block(-5,24,7,STEP:8)
Block(-5,25,0,TRAP_DOOR:7)
Block(-5,25,1,TRAP_DOOR:7)
Block(-5,25,4,STAINED_GLASS_PANE:15)
Block(-5,26,4,STAINED_GLASS_PANE:15)
Block(-5,27,4,STAINED_GLASS_PANE:15)
Block(-5,28,4,STEP:8)
Block(-5,29,-3,QUARTZ_STAIRS:6)
Block(-5,29,-2,CONCRETE:0)
Block(-5,29,-1,CONCRETE:0)
Block(-5,29,0,CONCRETE:0)
Block(-5,29,1,CONCRETE:0)
Block(-5,29,2,CONCRETE:15)
Block(-5,29,3,CONCRETE:0)
Block(-5,29,4,CONCRETE:0)
Block(-5,29,5,CONCRETE:0)
Block(-5,29,6,STEP:8)
Block(-5,30,-3,CONCRETE:0)
Block(-5,30,-2,STAINED_GLASS_PANE:15)
Block(-5,30,4,CONCRETE:7)
Block(-5,30,5,STEP:7)
Block(-5,30,6,IRON_FENCE:0)
Block(-5,31,-3,STEP:0)
Block(-5,31,4,STAINED_GLASS_PANE:15)
Block(-5,32,4,STAINED_GLASS_PANE:15)
Block(-5,32,5,STEP:8)
Block(-5,33,1,CONCRETE:0)
Block(-5,33,2,STEP:8)
Block(-5,33,3,STEP:8)
Block(-5,33,4,CONCRETE:0)
Block(-5,33,5,CONCRETE:0)
Block(-5,33,6,STEP:8)
Block(-5,34,1,STAINED_GLASS_PANE:15)
Block(-5,34,4,CONCRETE:7)
Block(-5,34,5,STEP:7)
Block(-5,34,6,IRON_FENCE:0)
Block(-5,35,4,STAINED_GLASS_PANE:15)
Block(-5,36,4,STAINED_GLASS_PANE:15)
Block(-5,36,5,QUARTZ_STAIRS:4)
Block(-5,37,4,QUARTZ_STAIRS:6)
Block(-5,37,5,CONCRETE:0)
Block(-5,37,6,STEP:8)
Block(-5,38,3,QUARTZ_STAIRS:5)
Block(-5,38,4,CONCRETE:7)
Block(-5,38,5,STEP:0)
Block(-5,39,-6,TRAP_DOOR:7)
Block(-5,39,3,CONCRETE:0)
Block(-5,39,4,CONCRETE:7)
Block(-5,40,3,CONCRETE:7)
Block(-5,41,2,CONCRETE:7)
Block(-5,42,-1,STEP:15)
Block(-5,42,0,STEP:15)
Block(-5,42,1,CONCRETE:7)
Block(-5,43,-1,CONCRETE:0)
Block(-5,43,0,CONCRETE:7)
Block(-5,44,-5,QUARTZ_STAIRS:6)
Block(-5,44,-4,QUARTZ_STAIRS:4)
Block(-5,44,-2,CONCRETE:7)
Block(-5,44,-1,CONCRETE:7)
Block(-5,45,-7,CONCRETE:0)
Block(-5,45,-6,CONCRETE:0)
Block(-5,45,-5,CONCRETE:0)
Block(-5,45,-4,CONCRETE:0)
Block(-5,45,-3,CONCRETE:0)
Block(-4,0,-7,CONCRETE:7)
Block(-4,0,-6,CONCRETE:7)
Block(-4,0,-5,CONCRETE:7)
Block(-4,0,-4,CONCRETE:7)
Block(-4,0,-3,CONCRETE:7)
Block(-4,0,-2,CONCRETE:7)
Block(-4,0,-1,CONCRETE:7)
Block(-4,0,0,CONCRETE:7)
Block(-4,0,1,CONCRETE:7)
Block(-4,0,2,CONCRETE:7)
Block(-4,0,3,CONCRETE:7)
Block(-4,0,4,CONCRETE:7)
Block(-4,0,5,CONCRETE:7)
Block(-4,0,6,CONCRETE:7)
Block(-4,0,7,CONCRETE:7)
Block(-4,0,8,CONCRETE:7)
Block(-4,1,-7,OBSIDIAN:0)
Block(-4,1,-6,OBSIDIAN:0)
Block(-4,1,-5,OBSIDIAN:0)
Block(-4,1,-4,OBSIDIAN:0)
Block(-4,1,-3,OBSIDIAN:0)
Block(-4,1,-2,OBSIDIAN:0)
Block(-4,1,-1,OBSIDIAN:0)
Block(-4,1,0,OBSIDIAN:0)
Block(-4,1,1,OBSIDIAN:0)
Block(-4,1,2,OBSIDIAN:0)
Block(-4,1,3,OBSIDIAN:0)
Block(-4,1,4,OBSIDIAN:0)
Block(-4,1,5,OBSIDIAN:0)
Block(-4,1,6,OBSIDIAN:0)
Block(-4,1,7,OBSIDIAN:0)
Block(-4,1,8,OBSIDIAN:0)
Block(-4,2,-7,CONCRETE:7)
Block(-4,2,-6,CONCRETE:7)
Block(-4,2,-5,CONCRETE:7)
Block(-4,2,-4,CONCRETE:7)
Block(-4,2,-3,CONCRETE:7)
Block(-4,2,-2,CONCRETE:7)
Block(-4,2,-1,CONCRETE:7)
Block(-4,2,0,CONCRETE:7)
Block(-4,2,1,CONCRETE:7)
Block(-4,2,2,CONCRETE:7)
Block(-4,2,3,CONCRETE:7)
Block(-4,2,4,CONCRETE:7)
Block(-4,2,5,CONCRETE:7)
Block(-4,2,6,CONCRETE:7)
Block(-4,2,7,CONCRETE:7)
Block(-4,2,8,CONCRETE:7)
Block(-4,3,-7,CONCRETE:7)
Block(-4,3,-6,CONCRETE:7)
Block(-4,3,-5,CONCRETE:7)
Block(-4,3,-4,CONCRETE:7)
Block(-4,3,-3,CONCRETE:7)
Block(-4,3,-2,CONCRETE:7)
Block(-4,3,-1,CONCRETE:7)
Block(-4,3,0,CONCRETE:7)
Block(-4,3,1,CONCRETE:7)
Block(-4,3,2,CONCRETE:7)
Block(-4,3,3,CONCRETE:7)
Block(-4,3,4,CONCRETE:7)
Block(-4,3,5,CONCRETE:7)
Block(-4,3,6,CONCRETE:7)
Block(-4,3,7,CONCRETE:7)
Block(-4,3,8,CONCRETE:7)
Block(-4,4,-7,CONCRETE:7)
Block(-4,4,-6,CONCRETE:7)
Block(-4,4,-5,CONCRETE:7)
Block(-4,4,-4,CONCRETE:7)
Block(-4,4,-3,CONCRETE:7)
Block(-4,4,-2,CONCRETE:7)
Block(-4,4,-1,CONCRETE:7)
Block(-4,4,0,CONCRETE:7)
Block(-4,4,1,CONCRETE:7)
Block(-4,4,2,CONCRETE:7)
Block(-4,4,3,CONCRETE:7)
Block(-4,4,4,CONCRETE:7)
Block(-4,4,5,CONCRETE:7)
Block(-4,4,6,CONCRETE:7)
Block(-4,4,7,CONCRETE:7)
Block(-4,4,8,CONCRETE:7)
Block(-4,5,-7,AIR:0)
Block(-4,5,-6,IRON_FENCE:0)
Block(-4,5,-5,CONCRETE:7)
Block(-4,5,-4,IRON_FENCE:0)
Block(-4,5,-3,IRON_FENCE:0)
Block(-4,5,-2,IRON_FENCE:0)
Block(-4,5,-1,CONCRETE:7)
Block(-4,5,0,IRON_FENCE:0)
Block(-4,5,1,IRON_FENCE:0)
Block(-4,5,2,IRON_FENCE:0)
Block(-4,5,3,CONCRETE:7)
Block(-4,5,4,IRON_FENCE:0)
Block(-4,5,5,IRON_FENCE:0)
Block(-4,5,6,IRON_FENCE:0)
Block(-4,5,7,CONCRETE:7)
Block(-4,5,8,IRON_FENCE:0)
Block(-4,6,-7,AIR:0)
Block(-4,6,-6,STONE_BUTTON:1)
Block(-4,6,-5,CONCRETE:7)
Block(-4,6,-4,IRON_FENCE:0)
Block(-4,6,-3,IRON_FENCE:0)
Block(-4,6,-2,IRON_FENCE:0)
Block(-4,6,-1,CONCRETE:7)
Block(-4,6,0,IRON_FENCE:0)
Block(-4,6,1,IRON_FENCE:0)
Block(-4,6,2,IRON_FENCE:0)
Block(-4,6,3,CONCRETE:7)
Block(-4,6,4,IRON_FENCE:0)
Block(-4,6,5,IRON_FENCE:0)
Block(-4,6,6,IRON_FENCE:0)
Block(-4,6,7,CONCRETE:7)
Block(-4,6,8,IRON_FENCE:0)
Block(-4,7,-7,IRON_FENCE:0)
Block(-4,7,-6,IRON_FENCE:0)
Block(-4,7,-5,CONCRETE:7)
Block(-4,7,-4,IRON_FENCE:0)
Block(-4,7,-3,IRON_FENCE:0)
Block(-4,7,-2,IRON_FENCE:0)
Block(-4,7,-1,CONCRETE:7)
Block(-4,7,0,IRON_FENCE:0)
Block(-4,7,1,IRON_FENCE:0)
Block(-4,7,2,IRON_FENCE:0)
Block(-4,7,3,CONCRETE:7)
Block(-4,7,4,IRON_FENCE:0)
Block(-4,7,5,IRON_FENCE:0)
Block(-4,7,6,IRON_FENCE:0)
Block(-4,7,7,CONCRETE:7)
Block(-4,7,8,IRON_FENCE:0)
Block(-4,8,-7,CONCRETE:7)
Block(-4,8,-6,CONCRETE:7)
Block(-4,8,-5,CONCRETE:7)
Block(-4,8,-4,CONCRETE:7)
Block(-4,8,-3,CONCRETE:7)
Block(-4,8,-2,CONCRETE:7)
Block(-4,8,-1,CONCRETE:7)
Block(-4,8,0,CONCRETE:7)
Block(-4,8,1,CONCRETE:7)
Block(-4,8,2,CONCRETE:7)
Block(-4,8,3,CONCRETE:7)
Block(-4,8,4,CONCRETE:7)
Block(-4,8,5,CONCRETE:7)
Block(-4,8,6,CONCRETE:7)
Block(-4,8,7,CONCRETE:7)
Block(-4,8,8,CONCRETE:7)
Block(-4,9,-7,IRON_FENCE:0)
Block(-4,9,-6,IRON_FENCE:0)
Block(-4,9,-5,CONCRETE:7)
Block(-4,9,-4,IRON_FENCE:0)
Block(-4,9,-3,IRON_FENCE:0)
Block(-4,9,-2,IRON_FENCE:0)
Block(-4,9,-1,CONCRETE:7)
Block(-4,9,0,IRON_FENCE:0)
Block(-4,9,1,IRON_FENCE:0)
Block(-4,9,2,IRON_FENCE:0)
Block(-4,9,3,CONCRETE:7)
Block(-4,9,4,CONCRETE:14)
Block(-4,9,5,IRON_FENCE:0)
Block(-4,9,6,IRON_FENCE:0)
Block(-4,9,7,CONCRETE:7)
Block(-4,9,8,IRON_FENCE:0)
Block(-4,10,-7,IRON_FENCE:0)
Block(-4,10,-6,IRON_FENCE:0)
Block(-4,10,-5,CONCRETE:7)
Block(-4,10,-4,IRON_FENCE:0)
Block(-4,10,-3,IRON_FENCE:0)
Block(-4,10,-2,IRON_FENCE:0)
Block(-4,10,-1,CONCRETE:7)
Block(-4,10,0,IRON_FENCE:0)
Block(-4,10,1,IRON_FENCE:0)
Block(-4,10,2,IRON_FENCE:0)
Block(-4,10,3,CONCRETE:7)
Block(-4,10,4,IRON_FENCE:0)
Block(-4,10,5,IRON_FENCE:0)
Block(-4,10,6,IRON_FENCE:0)
Block(-4,10,7,CONCRETE:7)
Block(-4,10,8,IRON_FENCE:0)
Block(-4,11,-7,IRON_FENCE:0)
Block(-4,11,-6,IRON_FENCE:0)
Block(-4,11,-5,CONCRETE:7)
Block(-4,11,-4,IRON_FENCE:0)
Block(-4,11,-3,IRON_FENCE:0)
Block(-4,11,-2,IRON_FENCE:0)
Block(-4,11,-1,CONCRETE:7)
Block(-4,11,0,IRON_FENCE:0)
Block(-4,11,1,IRON_FENCE:0)
Block(-4,11,2,IRON_FENCE:0)
Block(-4,11,3,CONCRETE:7)
Block(-4,11,4,CONCRETE:4)
Block(-4,11,5,IRON_FENCE:0)
Block(-4,11,6,IRON_FENCE:0)
Block(-4,11,7,CONCRETE:7)
Block(-4,11,8,IRON_FENCE:0)
Block(-4,12,-7,CONCRETE:7)
Block(-4,12,-6,CONCRETE:7)
Block(-4,12,-5,CONCRETE:7)
Block(-4,12,-4,CONCRETE:7)
Block(-4,12,-3,CONCRETE:7)
Block(-4,12,-2,CONCRETE:7)
Block(-4,12,-1,CONCRETE:7)
Block(-4,12,0,CONCRETE:7)
Block(-4,12,1,CONCRETE:7)
Block(-4,12,2,CONCRETE:7)
Block(-4,12,3,CONCRETE:7)
Block(-4,12,4,CONCRETE:7)
Block(-4,12,5,CONCRETE:7)
Block(-4,12,6,CONCRETE:7)
Block(-4,12,7,CONCRETE:7)
Block(-4,12,8,CONCRETE:7)
Block(-4,13,-7,OBSIDIAN:0)
Block(-4,13,-6,OBSIDIAN:0)
Block(-4,13,-5,CONCRETE:7)
Block(-4,13,-4,OBSIDIAN:0)
Block(-4,13,-3,OBSIDIAN:0)
Block(-4,13,-2,OBSIDIAN:0)
Block(-4,13,-1,CONCRETE:7)
Block(-4,13,0,IRON_FENCE:0)
Block(-4,13,1,IRON_FENCE:0)
Block(-4,13,2,IRON_FENCE:0)
Block(-4,13,3,CONCRETE:7)
Block(-4,13,4,IRON_FENCE:0)
Block(-4,13,5,IRON_FENCE:0)
Block(-4,13,6,IRON_FENCE:0)
Block(-4,13,7,CONCRETE:7)
Block(-4,13,8,IRON_FENCE:0)
Block(-4,14,-7,OBSIDIAN:0)
Block(-4,14,-6,OBSIDIAN:0)
Block(-4,14,-5,CONCRETE:7)
Block(-4,14,-4,OBSIDIAN:0)
Block(-4,14,-3,OBSIDIAN:0)
Block(-4,14,-2,OBSIDIAN:0)
Block(-4,14,-1,CONCRETE:7)
Block(-4,14,0,IRON_FENCE:0)
Block(-4,14,1,IRON_FENCE:0)
Block(-4,14,2,IRON_FENCE:0)
Block(-4,14,3,CONCRETE:7)
Block(-4,14,4,IRON_FENCE:0)
Block(-4,14,5,IRON_FENCE:0)
Block(-4,14,6,IRON_FENCE:0)
Block(-4,14,7,CONCRETE:7)
Block(-4,14,8,IRON_FENCE:0)
Block(-4,15,-7,CONCRETE:7)
Block(-4,15,-6,CONCRETE:7)
Block(-4,15,-5,CONCRETE:7)
Block(-4,15,-4,CONCRETE:7)
Block(-4,15,-3,CONCRETE:7)
Block(-4,15,-2,CONCRETE:7)
Block(-4,15,-1,CONCRETE:7)
Block(-4,15,0,CONCRETE:7)
Block(-4,15,1,CONCRETE:7)
Block(-4,15,2,CONCRETE:7)
Block(-4,15,3,CONCRETE:7)
Block(-4,15,4,CONCRETE:7)
Block(-4,15,5,CONCRETE:7)
Block(-4,15,6,CONCRETE:7)
Block(-4,15,7,CONCRETE:7)
Block(-4,15,8,CONCRETE:7)
Block(-4,16,-7,OBSIDIAN:0)
Block(-4,16,-6,OBSIDIAN:0)
Block(-4,16,-5,OBSIDIAN:0)
Block(-4,16,-4,OBSIDIAN:0)
Block(-4,16,-3,OBSIDIAN:0)
Block(-4,16,-2,OBSIDIAN:0)
Block(-4,16,-1,OBSIDIAN:0)
Block(-4,16,0,OBSIDIAN:0)
Block(-4,16,1,OBSIDIAN:0)
Block(-4,16,2,OBSIDIAN:0)
Block(-4,16,3,OBSIDIAN:0)
Block(-4,16,4,OBSIDIAN:0)
Block(-4,16,5,OBSIDIAN:0)
Block(-4,16,6,OBSIDIAN:0)
Block(-4,16,7,OBSIDIAN:0)
Block(-4,16,8,OBSIDIAN:0)
Block(-4,17,-7,CONCRETE:7)
Block(-4,17,-6,CONCRETE:7)
Block(-4,17,-5,CONCRETE:7)
Block(-4,17,-4,CONCRETE:7)
Block(-4,17,-3,CONCRETE:7)
Block(-4,17,-2,CONCRETE:7)
Block(-4,17,-1,CONCRETE:7)
Block(-4,17,0,CONCRETE:7)
Block(-4,17,1,CONCRETE:7)
Block(-4,17,2,CONCRETE:7)
Block(-4,17,3,CONCRETE:7)
Block(-4,17,4,CONCRETE:7)
Block(-4,17,5,CONCRETE:7)
Block(-4,17,6,CONCRETE:7)
Block(-4,17,7,CONCRETE:7)
Block(-4,17,8,CONCRETE:7)
Block(-4,18,-6,STEP:0)
Block(-4,18,-5,QUARTZ_STAIRS:0)
Block(-4,18,-4,CONCRETE:7)
Block(-4,18,-3,CONCRETE:7)
Block(-4,18,-2,CONCRETE:7)
Block(-4,18,-1,CONCRETE:7)
Block(-4,18,0,CONCRETE:7)
Block(-4,18,1,CONCRETE:7)
Block(-4,18,2,CONCRETE:7)
Block(-4,18,3,CONCRETE:7)
Block(-4,18,4,OBSIDIAN:0)
Block(-4,18,5,OBSIDIAN:0)
Block(-4,18,6,CONCRETE:0)
Block(-4,18,7,QUARTZ_STAIRS:7)
Block(-4,18,8,QUARTZ_STAIRS:4)
Block(-4,19,-6,STONE_BUTTON:2)
Block(-4,19,-5,DOUBLE_STEP:0)
Block(-4,19,-4,CONCRETE:7)
Block(-4,19,-3,CONCRETE:7)
Block(-4,19,-2,CONCRETE:7)
Block(-4,19,-1,CONCRETE:7)
Block(-4,19,0,CONCRETE:7)
Block(-4,19,1,CONCRETE:7)
Block(-4,19,2,CONCRETE:7)
Block(-4,19,3,CONCRETE:7)
Block(-4,19,4,OBSIDIAN:0)
Block(-4,19,5,OBSIDIAN:0)
Block(-4,19,6,CONCRETE:0)
Block(-4,19,7,QUARTZ_STAIRS:7)
Block(-4,19,8,QUARTZ_STAIRS:4)
Block(-4,20,-7,STEP:8)
Block(-4,20,-6,STEP:8)
Block(-4,20,-5,QUARTZ_STAIRS:4)
Block(-4,20,-4,CONCRETE:7)
Block(-4,20,-3,CONCRETE:7)
Block(-4,20,-2,CONCRETE:7)
Block(-4,20,-1,CONCRETE:7)
Block(-4,20,0,CONCRETE:7)
Block(-4,20,1,CONCRETE:7)
Block(-4,20,2,CONCRETE:7)
Block(-4,20,3,CONCRETE:7)
Block(-4,20,4,OBSIDIAN:0)
Block(-4,20,5,OBSIDIAN:0)
Block(-4,20,6,CONCRETE:0)
Block(-4,20,7,QUARTZ_STAIRS:4)
Block(-4,20,8,CONCRETE:7)
Block(-4,21,-7,CONCRETE:7)
Block(-4,21,-6,CONCRETE:7)
Block(-4,21,-5,CONCRETE:7)
Block(-4,21,-4,CONCRETE:7)
Block(-4,21,-3,CONCRETE:7)
Block(-4,21,-2,CONCRETE:7)
Block(-4,21,-1,CONCRETE:7)
Block(-4,21,0,CONCRETE:7)
Block(-4,21,1,CONCRETE:7)
Block(-4,21,2,CONCRETE:7)
Block(-4,21,3,CONCRETE:7)
Block(-4,21,4,OBSIDIAN:0)
Block(-4,21,5,OBSIDIAN:0)
Block(-4,21,6,CONCRETE:0)
Block(-4,21,7,QUARTZ_STAIRS:4)
Block(-4,21,8,CONCRETE:7)
Block(-4,22,-7,CONCRETE:7)
Block(-4,22,-6,CONCRETE:7)
Block(-4,22,-5,CONCRETE:7)
Block(-4,22,-4,CONCRETE:7)
Block(-4,22,-3,CONCRETE:7)
Block(-4,22,-2,CONCRETE:7)
Block(-4,22,-1,CONCRETE:7)
Block(-4,22,0,CONCRETE:7)
Block(-4,22,1,CONCRETE:7)
Block(-4,22,2,CONCRETE:7)
Block(-4,22,3,CONCRETE:7)
Block(-4,22,4,OBSIDIAN:0)
Block(-4,22,5,OBSIDIAN:0)
Block(-4,22,6,CONCRETE:0)
Block(-4,22,7,QUARTZ_STAIRS:4)
Block(-4,22,8,CONCRETE:7)
Block(-4,23,-7,OBSIDIAN:0)
Block(-4,23,-6,OBSIDIAN:0)
Block(-4,23,-5,OBSIDIAN:0)
Block(-4,23,-4,OBSIDIAN:0)
Block(-4,23,-3,OBSIDIAN:0)
Block(-4,23,-2,OBSIDIAN:0)
Block(-4,23,-1,OBSIDIAN:0)
Block(-4,23,0,OBSIDIAN:0)
Block(-4,23,1,OBSIDIAN:0)
Block(-4,23,2,OBSIDIAN:0)
Block(-4,23,3,OBSIDIAN:0)
Block(-4,23,4,OBSIDIAN:0)
Block(-4,23,5,OBSIDIAN:0)
Block(-4,23,6,CONCRETE:0)
Block(-4,23,7,CONCRETE:7)
Block(-4,23,8,CONCRETE:7)
Block(-4,24,-7,CONCRETE:0)
Block(-4,24,-6,CONCRETE:7)
Block(-4,24,-5,CONCRETE:7)
Block(-4,24,-4,CONCRETE:0)
Block(-4,24,-3,STONE:4)
Block(-4,24,-2,CONCRETE:0)
Block(-4,24,-1,CONCRETE:0)
Block(-4,24,0,CONCRETE:15)
Block(-4,24,1,STONE:6)
Block(-4,24,2,CONCRETE:0)
Block(-4,24,3,CONCRETE:0)
Block(-4,24,4,CONCRETE:0)
Block(-4,24,5,QUARTZ_STAIRS:3)
Block(-4,24,7,CONCRETE:7)
Block(-4,24,8,CONCRETE:7)
Block(-4,25,0,LOG_2:0)
Block(-4,25,4,CONCRETE:0)
Block(-4,25,8,STEP:7)
Block(-4,26,0,TRAP_DOOR:0)
Block(-4,26,4,CONCRETE:0)
Block(-4,27,4,CONCRETE:0)
Block(-4,28,4,CONCRETE:0)
Block(-4,28,5,QUARTZ_STAIRS:7)
Block(-4,29,-2,STEP:8)
Block(-4,29,-1,CONCRETE:0)
Block(-4,29,0,CONCRETE:0)
Block(-4,29,1,CONCRETE:0)
Block(-4,29,2,CONCRETE:15)
Block(-4,29,3,CONCRETE:0)
Block(-4,29,4,CONCRETE:0)
Block(-4,29,5,CONCRETE:0)
Block(-4,29,6,QUARTZ_STAIRS:7)
Block(-4,30,-2,STAINED_GLASS_PANE:15)
Block(-4,30,4,CONCRETE:0)
Block(-4,30,5,CONCRETE:0)
Block(-4,30,6,COBBLE_WALL:0)
Block(-4,31,4,CONCRETE:0)
Block(-4,31,5,CONCRETE:0)
Block(-4,32,1,QUARTZ_STAIRS:4)
Block(-4,32,4,CONCRETE:0)
Block(-4,32,5,CONCRETE:0)
Block(-4,33,1,CONCRETE:0)
Block(-4,33,2,STEP:8)
Block(-4,33,3,STEP:8)
Block(-4,33,4,CONCRETE:0)
Block(-4,33,5,CONCRETE:0)
Block(-4,33,6,QUARTZ_STAIRS:7)
Block(-4,34,1,STAINED_GLASS_PANE:15)
Block(-4,34,4,CONCRETE:0)
Block(-4,34,5,CONCRETE:0)
Block(-4,34,6,COBBLE_WALL:0)
Block(-4,35,4,CONCRETE:0)
Block(-4,35,5,CONCRETE:0)
Block(-4,36,4,CONCRETE:0)
Block(-4,36,5,CONCRETE:0)
Block(-4,37,4,CONCRETE:0)
Block(-4,37,5,CONCRETE:0)
Block(-4,37,6,QUARTZ_STAIRS:7)
Block(-4,38,4,CONCRETE:0)
Block(-4,38,5,CONCRETE:0)
Block(-4,38,6,QUARTZ_STAIRS:7)
Block(-4,39,4,CONCRETE:0)
Block(-4,39,5,CONCRETE:0)
Block(-4,39,6,IRON_FENCE:0)
Block(-4,40,3,STEP:15)
Block(-4,40,4,STEP:7)
Block(-4,40,5,COBBLE_WALL:0)
Block(-4,41,2,CONCRETE:7)
Block(-4,42,1,CONCRETE:7)
Block(-4,43,-3,STEP:15)
Block(-4,43,-2,CONCRETE:0)
Block(-4,43,-1,CONCRETE:7)
Block(-4,43,0,CONCRETE:7)
Block(-4,44,-4,CONCRETE:0)
Block(-4,44,-3,CONCRETE:7)
Block(-4,44,-2,CONCRETE:7)
Block(-4,45,-7,CONCRETE:0)
Block(-4,45,-6,CONCRETE:0)
Block(-4,45,-5,CONCRETE:0)
Block(-4,45,-4,CONCRETE:0)
Block(-3,0,-7,CONCRETE:7)
Block(-3,0,-6,CONCRETE:7)
Block(-3,0,-5,CONCRETE:7)
Block(-3,0,-4,CONCRETE:7)
Block(-3,0,-3,CONCRETE:7)
Block(-3,0,-2,CONCRETE:7)
Block(-3,0,-1,CONCRETE:7)
Block(-3,0,0,CONCRETE:7)
Block(-3,0,1,CONCRETE:7)
Block(-3,0,2,CONCRETE:7)
Block(-3,0,3,CONCRETE:7)
Block(-3,0,4,CONCRETE:7)
Block(-3,0,5,CONCRETE:7)
Block(-3,0,6,CONCRETE:7)
Block(-3,0,7,CONCRETE:7)
Block(-3,0,8,CONCRETE:7)
Block(-3,1,-7,OBSIDIAN:0)
Block(-3,1,-6,OBSIDIAN:0)
Block(-3,1,-5,OBSIDIAN:0)
Block(-3,1,-4,OBSIDIAN:0)
Block(-3,1,-3,OBSIDIAN:0)
Block(-3,1,-2,OBSIDIAN:0)
Block(-3,1,-1,OBSIDIAN:0)
Block(-3,1,0,OBSIDIAN:0)
Block(-3,1,1,OBSIDIAN:0)
Block(-3,1,2,OBSIDIAN:0)
Block(-3,1,3,OBSIDIAN:0)
Block(-3,1,4,OBSIDIAN:0)
Block(-3,1,5,OBSIDIAN:0)
Block(-3,1,6,OBSIDIAN:0)
Block(-3,1,7,OBSIDIAN:0)
Block(-3,1,8,OBSIDIAN:0)
Block(-3,2,-7,CONCRETE:11)
Block(-3,2,-6,CONCRETE:11)
Block(-3,2,-5,CONCRETE:11)
Block(-3,2,-4,CONCRETE:11)
Block(-3,2,-3,CONCRETE:11)
Block(-3,2,-2,CONCRETE:11)
Block(-3,2,-1,CONCRETE:11)
Block(-3,2,0,CONCRETE:11)
Block(-3,2,1,CONCRETE:11)
Block(-3,2,2,CONCRETE:11)
Block(-3,2,3,CONCRETE:11)
Block(-3,2,4,CONCRETE:11)
Block(-3,2,5,CONCRETE:11)
Block(-3,2,6,CONCRETE:11)
Block(-3,2,7,CONCRETE:11)
Block(-3,2,8,CONCRETE:11)
Block(-3,3,-7,CONCRETE:7)
Block(-3,3,-6,CONCRETE:7)
Block(-3,3,-5,CONCRETE:7)
Block(-3,3,-4,CONCRETE:7)
Block(-3,3,-3,CONCRETE:7)
Block(-3,3,-2,CONCRETE:7)
Block(-3,3,-1,PRISMARINE:0)
Block(-3,3,0,CONCRETE:7)
Block(-3,3,1,CONCRETE:7)
Block(-3,3,2,CONCRETE:7)
Block(-3,3,3,PRISMARINE:0)
Block(-3,3,4,CONCRETE:7)
Block(-3,3,5,CONCRETE:7)
Block(-3,3,6,CONCRETE:7)
Block(-3,3,7,SEA_LANTERN:0)
Block(-3,3,8,CONCRETE:7)
Block(-3,4,-7,CONCRETE:7)
Block(-3,4,-6,CONCRETE:7)
Block(-3,4,-5,CONCRETE:4)
Block(-3,4,-4,CONCRETE:7)
Block(-3,4,-3,CONCRETE:7)
Block(-3,4,-2,CONCRETE:7)
Block(-3,4,-1,IRON_TRAPDOOR:11)
Block(-3,4,0,CONCRETE:7)
Block(-3,4,1,CONCRETE:7)
Block(-3,4,2,CONCRETE:7)
Block(-3,4,3,IRON_TRAPDOOR:11)
Block(-3,4,4,CONCRETE:7)
Block(-3,4,5,CONCRETE:7)
Block(-3,4,6,CONCRETE:7)
Block(-3,4,7,IRON_TRAPDOOR:11)
Block(-3,4,8,CONCRETE:7)
Block(-3,5,-7,AIR:0)
Block(-3,5,-6,AIR:0)
Block(-3,5,-5,IRON_FENCE:0)
Block(-3,5,-4,AIR:0)
Block(-3,5,-3,AIR:0)
Block(-3,5,-2,AIR:0)
Block(-3,5,-1,AIR:0)
Block(-3,5,0,AIR:0)
Block(-3,5,1,AIR:0)
Block(-3,5,2,AIR:0)
Block(-3,5,3,AIR:0)
Block(-3,5,4,AIR:0)
Block(-3,5,5,AIR:0)
Block(-3,5,6,AIR:0)
Block(-3,5,7,AIR:0)
Block(-3,5,8,AIR:0)
Block(-3,6,-7,AIR:0)
Block(-3,6,-6,AIR:0)
Block(-3,6,-5,IRON_FENCE:0)
Block(-3,6,-4,AIR:0)
Block(-3,6,-3,AIR:0)
Block(-3,6,-2,AIR:0)
Block(-3,6,-1,AIR:0)
Block(-3,6,0,AIR:0)
Block(-3,6,1,AIR:0)
Block(-3,6,2,AIR:0)
Block(-3,6,3,AIR:0)
Block(-3,6,4,AIR:0)
Block(-3,6,5,AIR:0)
Block(-3,6,6,AIR:0)
Block(-3,6,7,AIR:0)
Block(-3,6,8,AIR:0)
Block(-3,7,-7,AIR:0)
Block(-3,7,-6,AIR:0)
Block(-3,7,-5,IRON_FENCE:0)
Block(-3,7,-4,AIR:0)
Block(-3,7,-3,AIR:0)
Block(-3,7,-2,AIR:0)
Block(-3,7,-1,AIR:0)
Block(-3,7,0,AIR:0)
Block(-3,7,1,AIR:0)
Block(-3,7,2,AIR:0)
Block(-3,7,3,AIR:0)
Block(-3,7,4,AIR:0)
Block(-3,7,5,AIR:0)
Block(-3,7,6,AIR:0)
Block(-3,7,7,AIR:0)
Block(-3,7,8,AIR:0)
Block(-3,8,-7,AIR:0)
Block(-3,8,-6,AIR:0)
Block(-3,8,-5,CONCRETE:7)
Block(-3,8,-4,AIR:0)
Block(-3,8,-3,AIR:0)
Block(-3,8,-2,AIR:0)
Block(-3,8,-1,CONCRETE:7)
Block(-3,8,0,AIR:0)
Block(-3,8,1,AIR:0)
Block(-3,8,2,AIR:0)
Block(-3,8,3,CONCRETE:7)
Block(-3,8,4,IRON_TRAPDOOR:9)
Block(-3,8,5,AIR:0)
Block(-3,8,6,AIR:0)
Block(-3,8,7,CONCRETE:7)
Block(-3,8,8,AIR:0)
Block(-3,9,-7,AIR:0)
Block(-3,9,-6,AIR:0)
Block(-3,9,-5,IRON_FENCE:0)
Block(-3,9,-4,AIR:0)
Block(-3,9,-3,AIR:0)
Block(-3,9,-2,AIR:0)
Block(-3,9,-1,AIR:0)
Block(-3,9,0,AIR:0)
Block(-3,9,1,AIR:0)
Block(-3,9,2,AIR:0)
Block(-3,9,3,AIR:0)
Block(-3,9,4,CONCRETE:14)
Block(-3,9,5,AIR:0)
Block(-3,9,6,AIR:0)
Block(-3,9,7,AIR:0)
Block(-3,9,8,AIR:0)
Block(-3,10,-7,AIR:0)
Block(-3,10,-6,AIR:0)
Block(-3,10,-5,IRON_FENCE:0)
Block(-3,10,-4,AIR:0)
Block(-3,10,-3,AIR:0)
Block(-3,10,-2,AIR:0)
Block(-3,10,-1,AIR:0)
Block(-3,10,0,AIR:0)
Block(-3,10,1,AIR:0)
Block(-3,10,2,AIR:0)
Block(-3,10,3,AIR:0)
Block(-3,10,4,IRON_TRAPDOOR:8)
Block(-3,10,5,AIR:0)
Block(-3,10,6,AIR:0)
Block(-3,10,7,AIR:0)
Block(-3,10,8,AIR:0)
Block(-3,11,-7,AIR:0)
Block(-3,11,-6,AIR:0)
Block(-3,11,-5,IRON_FENCE:0)
Block(-3,11,-4,AIR:0)
Block(-3,11,-3,AIR:0)
Block(-3,11,-2,AIR:0)
Block(-3,11,-1,AIR:0)
Block(-3,11,0,LEVER:2)
Block(-3,11,1,AIR:0)
Block(-3,11,2,AIR:0)
Block(-3,11,3,AIR:0)
Block(-3,11,4,CONCRETE:4)
Block(-3,11,5,AIR:0)
Block(-3,11,6,AIR:0)
Block(-3,11,7,AIR:0)
Block(-3,11,8,LEVER:2)
Block(-3,12,-7,STEP:8)
Block(-3,12,-6,STEP:8)
Block(-3,12,-5,CONCRETE:7)
Block(-3,12,-4,STEP:8)
Block(-3,12,-3,STEP:8)
Block(-3,12,-2,STEP:8)
Block(-3,12,-1,CONCRETE:7)
Block(-3,12,0,DOUBLE_STEP:0)
Block(-3,12,1,STEP:8)
Block(-3,12,2,STEP:8)
Block(-3,12,3,CONCRETE:7)
Block(-3,12,4,STEP:8)
Block(-3,12,5,STEP:8)
Block(-3,12,6,STEP:8)
Block(-3,12,7,CONCRETE:7)
Block(-3,12,8,DOUBLE_STEP:0)
Block(-3,13,-7,OBSIDIAN:0)
Block(-3,13,-6,OBSIDIAN:0)
Block(-3,13,-5,OBSIDIAN:0)
Block(-3,13,-4,OBSIDIAN:0)
Block(-3,13,-3,OBSIDIAN:0)
Block(-3,13,-2,OBSIDIAN:0)
Block(-3,13,-1,OBSIDIAN:0)
Block(-3,13,0,AIR:0)
Block(-3,13,1,AIR:0)
Block(-3,13,2,AIR:0)
Block(-3,13,3,AIR:0)
Block(-3,13,4,AIR:0)
Block(-3,13,5,AIR:0)
Block(-3,13,6,AIR:0)
Block(-3,13,7,AIR:0)
Block(-3,13,8,AIR:0)
Block(-3,14,-7,OBSIDIAN:0)
Block(-3,14,-6,OBSIDIAN:0)
Block(-3,14,-5,OBSIDIAN:0)
Block(-3,14,-4,OBSIDIAN:0)
Block(-3,14,-3,OBSIDIAN:0)
Block(-3,14,-2,OBSIDIAN:0)
Block(-3,14,-1,OBSIDIAN:0)
Block(-3,14,0,AIR:0)
Block(-3,14,1,AIR:0)
Block(-3,14,2,AIR:0)
Block(-3,14,3,AIR:0)
Block(-3,14,4,AIR:0)
Block(-3,14,5,AIR:0)
Block(-3,14,6,AIR:0)
Block(-3,14,7,AIR:0)
Block(-3,14,8,AIR:0)
Block(-3,15,-7,CONCRETE:7)
Block(-3,15,-6,CONCRETE:7)
Block(-3,15,-5,CONCRETE:7)
Block(-3,15,-4,CONCRETE:7)
Block(-3,15,-3,CONCRETE:7)
Block(-3,15,-2,CONCRETE:7)
Block(-3,15,-1,CONCRETE:7)
Block(-3,15,0,CONCRETE:7)
Block(-3,15,1,CONCRETE:7)
Block(-3,15,2,CONCRETE:7)
Block(-3,15,3,CONCRETE:7)
Block(-3,15,4,CONCRETE:7)
Block(-3,15,5,CONCRETE:7)
Block(-3,15,6,CONCRETE:7)
Block(-3,15,7,CONCRETE:7)
Block(-3,15,8,CONCRETE:7)
Block(-3,16,-7,OBSIDIAN:0)
Block(-3,16,-6,OBSIDIAN:0)
Block(-3,16,-5,OBSIDIAN:0)
Block(-3,16,-4,OBSIDIAN:0)
Block(-3,16,-3,OBSIDIAN:0)
Block(-3,16,-2,OBSIDIAN:0)
Block(-3,16,-1,OBSIDIAN:0)
Block(-3,16,0,OBSIDIAN:0)
Block(-3,16,1,OBSIDIAN:0)
Block(-3,16,2,OBSIDIAN:0)
Block(-3,16,3,OBSIDIAN:0)
Block(-3,16,4,OBSIDIAN:0)
Block(-3,16,5,OBSIDIAN:0)
Block(-3,16,6,OBSIDIAN:0)
Block(-3,16,7,OBSIDIAN:0)
Block(-3,16,8,OBSIDIAN:0)
Block(-3,17,-7,CONCRETE:7)
Block(-3,17,-6,CONCRETE:7)
Block(-3,17,-5,CONCRETE:7)
Block(-3,17,-4,CONCRETE:7)
Block(-3,17,-3,CONCRETE:7)
Block(-3,17,-2,CONCRETE:7)
Block(-3,17,-1,CONCRETE:7)
Block(-3,17,0,CONCRETE:7)
Block(-3,17,1,CONCRETE:7)
Block(-3,17,2,CONCRETE:7)
Block(-3,17,3,CONCRETE:7)
Block(-3,17,4,CONCRETE:7)
Block(-3,17,5,CONCRETE:7)
Block(-3,17,6,CONCRETE:7)
Block(-3,17,7,CONCRETE:7)
Block(-3,17,8,CONCRETE:7)
Block(-3,18,-7,IRON_DOOR_BLOCK:0)
Block(-3,18,-6,OBSIDIAN:0)
Block(-3,18,-5,OBSIDIAN:0)
Block(-3,18,-4,OBSIDIAN:0)
Block(-3,18,-3,OBSIDIAN:0)
Block(-3,18,-2,OBSIDIAN:0)
Block(-3,18,-1,OBSIDIAN:0)
Block(-3,18,0,OBSIDIAN:0)
Block(-3,18,1,OBSIDIAN:0)
Block(-3,18,2,OBSIDIAN:0)
Block(-3,18,3,CONCRETE:7)
Block(-3,18,4,CONCRETE:7)
Block(-3,18,5,OBSIDIAN:0)
Block(-3,18,6,CONCRETE:0)
Block(-3,18,7,CONCRETE:0)
Block(-3,18,8,QUARTZ_STAIRS:7)
Block(-3,19,-7,IRON_DOOR_BLOCK:9)
Block(-3,19,-6,OBSIDIAN:0)
Block(-3,19,-5,OBSIDIAN:0)
Block(-3,19,-4,OBSIDIAN:0)
Block(-3,19,-3,OBSIDIAN:0)
Block(-3,19,-2,OBSIDIAN:0)
Block(-3,19,-1,OBSIDIAN:0)
Block(-3,19,0,OBSIDIAN:0)
Block(-3,19,1,OBSIDIAN:0)
Block(-3,19,2,OBSIDIAN:0)
Block(-3,19,3,CONCRETE:7)
Block(-3,19,4,CONCRETE:7)
Block(-3,19,5,OBSIDIAN:0)
Block(-3,19,6,CONCRETE:0)
Block(-3,19,7,CONCRETE:0)
Block(-3,19,8,QUARTZ_STAIRS:7)
Block(-3,20,-7,OBSIDIAN:0)
Block(-3,20,-6,OBSIDIAN:0)
Block(-3,20,-5,OBSIDIAN:0)
Block(-3,20,-4,OBSIDIAN:0)
Block(-3,20,-3,OBSIDIAN:0)
Block(-3,20,-2,OBSIDIAN:0)
Block(-3,20,-1,OBSIDIAN:0)
Block(-3,20,0,OBSIDIAN:0)
Block(-3,20,1,OBSIDIAN:0)
Block(-3,20,2,OBSIDIAN:0)
Block(-3,20,3,CONCRETE:7)
Block(-3,20,4,CONCRETE:7)
Block(-3,20,5,OBSIDIAN:0)
Block(-3,20,6,CONCRETE:0)
Block(-3,20,7,CONCRETE:0)
Block(-3,20,8,QUARTZ_STAIRS:7)
Block(-3,21,-7,OBSIDIAN:0)
Block(-3,21,-6,OBSIDIAN:0)
Block(-3,21,-5,OBSIDIAN:0)
Block(-3,21,-4,OBSIDIAN:0)
Block(-3,21,-3,OBSIDIAN:0)
Block(-3,21,-2,OBSIDIAN:0)
Block(-3,21,-1,OBSIDIAN:0)
Block(-3,21,0,OBSIDIAN:0)
Block(-3,21,1,OBSIDIAN:0)
Block(-3,21,2,OBSIDIAN:0)
Block(-3,21,3,CONCRETE:7)
Block(-3,21,4,CONCRETE:7)
Block(-3,21,5,OBSIDIAN:0)
Block(-3,21,6,CONCRETE:0)
Block(-3,21,7,CONCRETE:0)
Block(-3,21,8,QUARTZ_STAIRS:7)
Block(-3,22,-7,CONCRETE:7)
Block(-3,22,-6,CONCRETE:7)
Block(-3,22,-5,CONCRETE:7)
Block(-3,22,-4,CONCRETE:7)
Block(-3,22,-3,CONCRETE:7)
Block(-3,22,-2,CONCRETE:7)
Block(-3,22,-1,CONCRETE:7)
Block(-3,22,0,CONCRETE:7)
Block(-3,22,1,CONCRETE:7)
Block(-3,22,2,CONCRETE:7)
Block(-3,22,3,CONCRETE:7)
Block(-3,22,4,CONCRETE:7)
Block(-3,22,5,OBSIDIAN:0)
Block(-3,22,6,CONCRETE:0)
Block(-3,22,7,CONCRETE:0)
Block(-3,22,8,QUARTZ_STAIRS:7)
Block(-3,23,-7,OBSIDIAN:0)
Block(-3,23,-6,OBSIDIAN:0)
Block(-3,23,-5,OBSIDIAN:0)
Block(-3,23,-4,OBSIDIAN:0)
Block(-3,23,-3,OBSIDIAN:0)
Block(-3,23,-2,OBSIDIAN:0)
Block(-3,23,-1,OBSIDIAN:0)
Block(-3,23,0,OBSIDIAN:0)
Block(-3,23,1,OBSIDIAN:0)
Block(-3,23,2,OBSIDIAN:0)
Block(-3,23,3,OBSIDIAN:0)
Block(-3,23,4,OBSIDIAN:0)
Block(-3,23,5,OBSIDIAN:0)
Block(-3,23,6,CONCRETE:0)
Block(-3,23,7,CONCRETE:0)
Block(-3,23,8,CONCRETE:7)
Block(-3,24,-7,CONCRETE:7)
Block(-3,24,-6,CONCRETE:15)
Block(-3,24,-5,CONCRETE:0)
Block(-3,24,-4,CONCRETE:0)
Block(-3,24,-3,CONCRETE:0)
Block(-3,24,-2,STONE:4)
Block(-3,24,-1,CONCRETE:15)
Block(-3,24,0,CONCRETE:15)
Block(-3,24,1,STONE:6)
Block(-3,24,2,CONCRETE:0)
Block(-3,24,3,CONCRETE:0)
Block(-3,24,4,CONCRETE:7)
Block(-3,24,5,STEP:0)
Block(-3,24,8,STEP:8)
Block(-3,25,-1,STAINED_GLASS_PANE:0)
Block(-3,25,0,STAINED_GLASS_PANE:0)
Block(-3,25,1,STAINED_GLASS_PANE:0)
Block(-3,25,4,STAINED_GLASS_PANE:15)
Block(-3,26,4,STAINED_GLASS_PANE:15)
Block(-3,27,4,STAINED_GLASS_PANE:15)
Block(-3,28,4,STEP:8)
Block(-3,29,-2,QUARTZ_STAIRS:6)
Block(-3,29,-1,CONCRETE:0)
Block(-3,29,0,CONCRETE:0)
Block(-3,29,1,CONCRETE:0)
Block(-3,29,2,CONCRETE:0)
Block(-3,29,3,CONCRETE:15)
Block(-3,29,4,CONCRETE:0)
Block(-3,29,5,CONCRETE:0)
Block(-3,29,6,STEP:8)
Block(-3,30,-2,CONCRETE:0)
Block(-3,30,-1,STAINED_GLASS_PANE:15)
Block(-3,30,1,CONCRETE:0)
Block(-3,30,4,CONCRETE:7)
Block(-3,30,5,STEP:7)
Block(-3,30,6,IRON_FENCE:0)
Block(-3,31,-2,STEP:0)
Block(-3,31,1,CONCRETE:0)
Block(-3,31,4,STAINED_GLASS_PANE:15)
Block(-3,32,1,CONCRETE:0)
Block(-3,32,4,STAINED_GLASS_PANE:15)
Block(-3,32,5,STEP:8)
Block(-3,33,1,CONCRETE:0)
Block(-3,33,2,CONCRETE:0)
Block(-3,33,3,CONCRETE:0)
Block(-3,33,4,CONCRETE:0)
Block(-3,33,5,CONCRETE:0)
Block(-3,33,6,STEP:8)
Block(-3,34,1,CONCRETE:0)
Block(-3,34,4,CONCRETE:7)
Block(-3,34,5,STEP:7)
Block(-3,34,6,IRON_FENCE:0)
Block(-3,35,1,STEP:0)
Block(-3,35,4,STAINED_GLASS_PANE:15)
Block(-3,36,4,STAINED_GLASS_PANE:15)
Block(-3,37,4,STAINED_GLASS_PANE:15)
Block(-3,37,5,QUARTZ_STAIRS:5)
Block(-3,38,4,QUARTZ_STAIRS:6)
Block(-3,38,5,CONCRETE:0)
Block(-3,38,6,STEP:8)
Block(-3,39,4,DOUBLE_STEP:7)
Block(-3,39,5,STEP:0)
Block(-3,40,3,STEP:15)
Block(-3,40,4,STEP:7)
Block(-3,41,1,CONCRETE:7)
Block(-3,41,2,STEP:7)
Block(-3,42,0,CONCRETE:7)
Block(-3,43,-2,CONCRETE:7)
Block(-3,43,-1,CONCRETE:7)
Block(-3,44,-7,CONCRETE:7)
Block(-3,44,-6,CONCRETE:7)
Block(-3,44,-5,CONCRETE:7)
Block(-3,44,-4,CONCRETE:7)
Block(-3,44,-3,CONCRETE:7)
Block(-2,0,-7,CONCRETE:7)
Block(-2,0,-6,CONCRETE:7)
Block(-2,0,-5,CONCRETE:7)
Block(-2,0,-4,CONCRETE:7)
Block(-2,0,-3,CONCRETE:7)
Block(-2,0,-2,CONCRETE:7)
Block(-2,0,-1,CONCRETE:7)
Block(-2,0,0,CONCRETE:7)
Block(-2,0,1,CONCRETE:7)
Block(-2,0,2,CONCRETE:7)
Block(-2,0,3,CONCRETE:7)
Block(-2,0,4,CONCRETE:7)
Block(-2,0,5,CONCRETE:7)
Block(-2,0,6,CONCRETE:7)
Block(-2,0,7,CONCRETE:7)
Block(-2,0,8,CONCRETE:7)
Block(-2,1,-7,OBSIDIAN:0)
Block(-2,1,-6,OBSIDIAN:0)
Block(-2,1,-5,OBSIDIAN:0)
Block(-2,1,-4,OBSIDIAN:0)
Block(-2,1,-3,OBSIDIAN:0)
Block(-2,1,-2,OBSIDIAN:0)
Block(-2,1,-1,OBSIDIAN:0)
Block(-2,1,0,OBSIDIAN:0)
Block(-2,1,1,OBSIDIAN:0)
Block(-2,1,2,OBSIDIAN:0)
Block(-2,1,3,OBSIDIAN:0)
Block(-2,1,4,OBSIDIAN:0)
Block(-2,1,5,OBSIDIAN:0)
Block(-2,1,6,OBSIDIAN:0)
Block(-2,1,7,OBSIDIAN:0)
Block(-2,1,8,OBSIDIAN:0)
Block(-2,2,-7,CONCRETE:7)
Block(-2,2,-6,CONCRETE:7)
Block(-2,2,-5,CONCRETE:7)
Block(-2,2,-4,CONCRETE:7)
Block(-2,2,-3,CONCRETE:7)
Block(-2,2,-2,CONCRETE:7)
Block(-2,2,-1,CONCRETE:7)
Block(-2,2,0,CONCRETE:7)
Block(-2,2,1,CONCRETE:7)
Block(-2,2,2,CONCRETE:7)
Block(-2,2,3,CONCRETE:7)
Block(-2,2,4,CONCRETE:7)
Block(-2,2,5,CONCRETE:7)
Block(-2,2,6,CONCRETE:7)
Block(-2,2,7,CONCRETE:7)
Block(-2,2,8,CONCRETE:7)
Block(-2,3,-7,CONCRETE:7)
Block(-2,3,-6,CONCRETE:7)
Block(-2,3,-5,CONCRETE:7)
Block(-2,3,-4,CONCRETE:7)
Block(-2,3,-3,CONCRETE:7)
Block(-2,3,-2,CONCRETE:7)
Block(-2,3,-1,CONCRETE:7)
Block(-2,3,0,CONCRETE:7)
Block(-2,3,1,CONCRETE:7)
Block(-2,3,2,CONCRETE:7)
Block(-2,3,3,CONCRETE:7)
Block(-2,3,4,CONCRETE:7)
Block(-2,3,5,CONCRETE:7)
Block(-2,3,6,CONCRETE:7)
Block(-2,3,7,CONCRETE:7)
Block(-2,3,8,CONCRETE:7)
Block(-2,4,-7,CONCRETE:7)
Block(-2,4,-6,CONCRETE:7)
Block(-2,4,-5,CONCRETE:15)
Block(-2,4,-4,CONCRETE:7)
Block(-2,4,-3,CONCRETE:7)
Block(-2,4,-2,CONCRETE:7)
Block(-2,4,-1,CONCRETE:7)
Block(-2,4,0,CONCRETE:7)
Block(-2,4,1,CONCRETE:7)
Block(-2,4,2,CONCRETE:7)
Block(-2,4,3,CONCRETE:7)
Block(-2,4,4,CONCRETE:7)
Block(-2,4,5,CONCRETE:7)
Block(-2,4,6,CONCRETE:7)
Block(-2,4,7,CONCRETE:7)
Block(-2,4,8,CONCRETE:7)
Block(-2,5,-7,AIR:0)
Block(-2,5,-6,AIR:0)
Block(-2,5,-5,AIR:0)
Block(-2,5,-4,AIR:0)
Block(-2,5,-3,AIR:0)
Block(-2,5,-2,AIR:0)
Block(-2,5,-1,AIR:0)
Block(-2,5,0,AIR:0)
Block(-2,5,1,AIR:0)
Block(-2,5,2,AIR:0)
Block(-2,5,3,AIR:0)
Block(-2,5,4,AIR:0)
Block(-2,5,5,AIR:0)
Block(-2,5,6,AIR:0)
Block(-2,5,7,AIR:0)
Block(-2,5,8,AIR:0)
Block(-2,6,-7,AIR:0)
Block(-2,6,-6,AIR:0)
Block(-2,6,-5,AIR:0)
Block(-2,6,-4,AIR:0)
Block(-2,6,-3,AIR:0)
Block(-2,6,-2,AIR:0)
Block(-2,6,-1,AIR:0)
Block(-2,6,0,AIR:0)
Block(-2,6,1,AIR:0)
Block(-2,6,2,AIR:0)
Block(-2,6,3,AIR:0)
Block(-2,6,4,AIR:0)
Block(-2,6,5,AIR:0)
Block(-2,6,6,AIR:0)
Block(-2,6,7,AIR:0)
Block(-2,6,8,AIR:0)
Block(-2,7,-7,AIR:0)
Block(-2,7,-6,AIR:0)
Block(-2,7,-5,IRON_FENCE:0)
Block(-2,7,-4,AIR:0)
Block(-2,7,-3,AIR:0)
Block(-2,7,-2,AIR:0)
Block(-2,7,-1,AIR:0)
Block(-2,7,0,AIR:0)
Block(-2,7,1,AIR:0)
Block(-2,7,2,AIR:0)
Block(-2,7,3,AIR:0)
Block(-2,7,4,AIR:0)
Block(-2,7,5,AIR:0)
Block(-2,7,6,AIR:0)
Block(-2,7,7,AIR:0)
Block(-2,7,8,AIR:0)
Block(-2,8,-7,AIR:0)
Block(-2,8,-6,AIR:0)
Block(-2,8,-5,CONCRETE:7)
Block(-2,8,-4,AIR:0)
Block(-2,8,-3,AIR:0)
Block(-2,8,-2,AIR:0)
Block(-2,8,-1,CONCRETE:7)
Block(-2,8,0,AIR:0)
Block(-2,8,1,AIR:0)
Block(-2,8,2,AIR:0)
Block(-2,8,3,CONCRETE:7)
Block(-2,8,4,IRON_TRAPDOOR:9)
Block(-2,8,5,AIR:0)
Block(-2,8,6,AIR:0)
Block(-2,8,7,CONCRETE:7)
Block(-2,8,8,AIR:0)
Block(-2,9,-7,AIR:0)
Block(-2,9,-6,AIR:0)
Block(-2,9,-5,IRON_FENCE:0)
Block(-2,9,-4,AIR:0)
Block(-2,9,-3,AIR:0)
Block(-2,9,-2,AIR:0)
Block(-2,9,-1,AIR:0)
Block(-2,9,0,AIR:0)
Block(-2,9,1,AIR:0)
Block(-2,9,2,AIR:0)
Block(-2,9,3,AIR:0)
Block(-2,9,4,CONCRETE:14)
Block(-2,9,5,AIR:0)
Block(-2,9,6,AIR:0)
Block(-2,9,7,AIR:0)
Block(-2,9,8,AIR:0)
Block(-2,10,-7,AIR:0)
Block(-2,10,-6,AIR:0)
Block(-2,10,-5,IRON_FENCE:0)
Block(-2,10,-4,AIR:0)
Block(-2,10,-3,AIR:0)
Block(-2,10,-2,AIR:0)
Block(-2,10,-1,AIR:0)
Block(-2,10,0,AIR:0)
Block(-2,10,1,AIR:0)
Block(-2,10,2,AIR:0)
Block(-2,10,3,AIR:0)
Block(-2,10,4,IRON_TRAPDOOR:8)
Block(-2,10,5,AIR:0)
Block(-2,10,6,AIR:0)
Block(-2,10,7,AIR:0)
Block(-2,10,8,AIR:0)
Block(-2,11,-7,STEP:13)
Block(-2,11,-6,STEP:13)
Block(-2,11,-5,STEP:13)
Block(-2,11,-4,STEP:13)
Block(-2,11,-3,STEP:13)
Block(-2,11,-2,STEP:13)
Block(-2,11,-1,STEP:13)
Block(-2,11,0,DROPPER:0,NBT/skyscraper_8x6_01/95-dropperC16R48.nbt)
Block(-2,11,1,STEP:13)
Block(-2,11,2,STEP:13)
Block(-2,11,3,STEP:13)
Block(-2,11,4,CONCRETE:4)
Block(-2,11,5,STEP:13)
Block(-2,11,6,STEP:13)
Block(-2,11,7,STEP:13)
Block(-2,11,8,DROPPER:0,NBT/skyscraper_8x6_01/96-dropperC16R48.nbt)
Block(-2,12,-7,STEP:8)
Block(-2,12,-6,STEP:8)
Block(-2,12,-5,CONCRETE:7)
Block(-2,12,-4,STEP:8)
Block(-2,12,-3,STEP:8)
Block(-2,12,-2,STEP:8)
Block(-2,12,-1,CONCRETE:7)
Block(-2,12,0,STEP:8)
Block(-2,12,1,STEP:8)
Block(-2,12,2,STEP:8)
Block(-2,12,3,CONCRETE:7)
Block(-2,12,4,STEP:8)
Block(-2,12,5,STEP:8)
Block(-2,12,6,STEP:8)
Block(-2,12,7,CONCRETE:7)
Block(-2,12,8,STEP:8)
Block(-2,13,-7,OBSIDIAN:0)
Block(-2,13,-6,OBSIDIAN:0)
Block(-2,13,-5,OBSIDIAN:0)
Block(-2,13,-4,OBSIDIAN:0)
Block(-2,13,-3,OBSIDIAN:0)
Block(-2,13,-2,OBSIDIAN:0)
Block(-2,13,-1,OBSIDIAN:0)
Block(-2,13,0,AIR:0)
Block(-2,13,1,AIR:0)
Block(-2,13,2,AIR:0)
Block(-2,13,3,AIR:0)
Block(-2,13,4,AIR:0)
Block(-2,13,5,AIR:0)
Block(-2,13,6,AIR:0)
Block(-2,13,7,AIR:0)
Block(-2,13,8,AIR:0)
Block(-2,14,-7,OBSIDIAN:0)
Block(-2,14,-6,OBSIDIAN:0)
Block(-2,14,-5,OBSIDIAN:0)
Block(-2,14,-4,OBSIDIAN:0)
Block(-2,14,-3,OBSIDIAN:0)
Block(-2,14,-2,OBSIDIAN:0)
Block(-2,14,-1,OBSIDIAN:0)
Block(-2,14,0,AIR:0)
Block(-2,14,1,AIR:0)
Block(-2,14,2,AIR:0)
Block(-2,14,3,AIR:0)
Block(-2,14,4,AIR:0)
Block(-2,14,5,AIR:0)
Block(-2,14,6,AIR:0)
Block(-2,14,7,AIR:0)
Block(-2,14,8,AIR:0)
Block(-2,15,-7,CONCRETE:7)
Block(-2,15,-6,CONCRETE:7)
Block(-2,15,-5,CONCRETE:7)
Block(-2,15,-4,CONCRETE:7)
Block(-2,15,-3,CONCRETE:7)
Block(-2,15,-2,CONCRETE:7)
Block(-2,15,-1,CONCRETE:7)
Block(-2,15,0,CONCRETE:7)
Block(-2,15,1,CONCRETE:7)
Block(-2,15,2,CONCRETE:7)
Block(-2,15,3,CONCRETE:7)
Block(-2,15,4,CONCRETE:7)
Block(-2,15,5,CONCRETE:7)
Block(-2,15,6,CONCRETE:7)
Block(-2,15,7,CONCRETE:7)
Block(-2,15,8,CONCRETE:7)
Block(-2,16,-7,OBSIDIAN:0)
Block(-2,16,-6,OBSIDIAN:0)
Block(-2,16,-5,OBSIDIAN:0)
Block(-2,16,-4,OBSIDIAN:0)
Block(-2,16,-3,OBSIDIAN:0)
Block(-2,16,-2,OBSIDIAN:0)
Block(-2,16,-1,OBSIDIAN:0)
Block(-2,16,0,OBSIDIAN:0)
Block(-2,16,1,OBSIDIAN:0)
Block(-2,16,2,OBSIDIAN:0)
Block(-2,16,3,OBSIDIAN:0)
Block(-2,16,4,OBSIDIAN:0)
Block(-2,16,5,OBSIDIAN:0)
Block(-2,16,6,OBSIDIAN:0)
Block(-2,16,7,OBSIDIAN:0)
Block(-2,16,8,OBSIDIAN:0)
Block(-2,17,-7,CONCRETE:7)
Block(-2,17,-6,CONCRETE:7)
Block(-2,17,-5,CONCRETE:7)
Block(-2,17,-4,CONCRETE:7)
Block(-2,17,-3,CONCRETE:7)
Block(-2,17,-2,CONCRETE:7)
Block(-2,17,-1,CONCRETE:7)
Block(-2,17,0,CONCRETE:7)
Block(-2,17,1,CONCRETE:7)
Block(-2,17,2,CONCRETE:7)
Block(-2,17,3,CONCRETE:7)
Block(-2,17,4,CONCRETE:7)
Block(-2,17,5,CONCRETE:7)
Block(-2,17,6,CONCRETE:7)
Block(-2,17,7,CONCRETE:7)
Block(-2,17,8,CONCRETE:7)
Block(-2,18,-6,CONCRETE:7)
Block(-2,18,-5,IRON_FENCE:0)
Block(-2,18,-4,CONCRETE:7)
Block(-2,18,-3,IRON_FENCE:0)
Block(-2,18,-2,CONCRETE:7)
Block(-2,18,-1,IRON_FENCE:0)
Block(-2,18,0,CONCRETE:7)
Block(-2,18,1,IRON_FENCE:0)
Block(-2,18,2,CONCRETE:7)
Block(-2,18,3,CONCRETE:7)
Block(-2,18,4,CONCRETE:7)
Block(-2,18,5,OBSIDIAN:0)
Block(-2,18,6,OBSIDIAN:0)
Block(-2,18,7,CONCRETE:0)
Block(-2,18,8,QUARTZ_STAIRS:7)
Block(-2,19,-7,STONE_BUTTON:4)
Block(-2,19,-6,CONCRETE:7)
Block(-2,19,-5,IRON_FENCE:0)
Block(-2,19,-4,CONCRETE:7)
Block(-2,19,-3,IRON_FENCE:0)
Block(-2,19,-2,CONCRETE:7)
Block(-2,19,-1,IRON_FENCE:0)
Block(-2,19,0,CONCRETE:7)
Block(-2,19,1,IRON_FENCE:0)
Block(-2,19,2,CONCRETE:7)
Block(-2,19,3,CONCRETE:7)
Block(-2,19,4,CONCRETE:7)
Block(-2,19,5,OBSIDIAN:0)
Block(-2,19,6,OBSIDIAN:0)
Block(-2,19,7,CONCRETE:0)
Block(-2,19,8,QUARTZ_STAIRS:4)
Block(-2,20,-7,IRON_FENCE:0)
Block(-2,20,-6,CONCRETE:7)
Block(-2,20,-5,IRON_FENCE:0)
Block(-2,20,-4,CONCRETE:7)
Block(-2,20,-3,IRON_FENCE:0)
Block(-2,20,-2,CONCRETE:7)
Block(-2,20,-1,IRON_FENCE:0)
Block(-2,20,0,CONCRETE:7)
Block(-2,20,1,IRON_FENCE:0)
Block(-2,20,2,CONCRETE:7)
Block(-2,20,3,CONCRETE:7)
Block(-2,20,4,CONCRETE:7)
Block(-2,20,5,OBSIDIAN:0)
Block(-2,20,6,OBSIDIAN:0)
Block(-2,20,7,CONCRETE:0)
Block(-2,20,8,QUARTZ_STAIRS:4)
Block(-2,21,-7,CONCRETE:7)
Block(-2,21,-6,CONCRETE:7)
Block(-2,21,-5,CONCRETE:7)
Block(-2,21,-4,CONCRETE:7)
Block(-2,21,-3,CONCRETE:7)
Block(-2,21,-2,CONCRETE:7)
Block(-2,21,-1,CONCRETE:7)
Block(-2,21,0,CONCRETE:7)
Block(-2,21,1,CONCRETE:7)
Block(-2,21,2,CONCRETE:7)
Block(-2,21,3,CONCRETE:7)
Block(-2,21,4,CONCRETE:7)
Block(-2,21,5,OBSIDIAN:0)
Block(-2,21,6,OBSIDIAN:0)
Block(-2,21,7,CONCRETE:0)
Block(-2,21,8,QUARTZ_STAIRS:4)
Block(-2,22,-7,CONCRETE:7)
Block(-2,22,-6,CONCRETE:7)
Block(-2,22,-5,CONCRETE:7)
Block(-2,22,-4,CONCRETE:7)
Block(-2,22,-3,CONCRETE:7)
Block(-2,22,-2,CONCRETE:7)
Block(-2,22,-1,CONCRETE:7)
Block(-2,22,0,CONCRETE:7)
Block(-2,22,1,CONCRETE:7)
Block(-2,22,2,CONCRETE:7)
Block(-2,22,3,CONCRETE:7)
Block(-2,22,4,CONCRETE:7)
Block(-2,22,5,OBSIDIAN:0)
Block(-2,22,6,OBSIDIAN:0)
Block(-2,22,7,CONCRETE:0)
Block(-2,22,8,QUARTZ_STAIRS:4)
Block(-2,23,-7,OBSIDIAN:0)
Block(-2,23,-6,OBSIDIAN:0)
Block(-2,23,-5,OBSIDIAN:0)
Block(-2,23,-4,OBSIDIAN:0)
Block(-2,23,-3,OBSIDIAN:0)
Block(-2,23,-2,OBSIDIAN:0)
Block(-2,23,-1,OBSIDIAN:0)
Block(-2,23,0,OBSIDIAN:0)
Block(-2,23,1,OBSIDIAN:0)
Block(-2,23,2,OBSIDIAN:0)
Block(-2,23,3,OBSIDIAN:0)
Block(-2,23,4,OBSIDIAN:0)
Block(-2,23,5,OBSIDIAN:0)
Block(-2,23,6,CONCRETE:0)
Block(-2,23,7,CONCRETE:0)
Block(-2,23,8,CONCRETE:7)
Block(-2,24,-7,CONCRETE:0)
Block(-2,24,-6,CONCRETE:0)
Block(-2,24,-5,CONCRETE:15)
Block(-2,24,-4,CONCRETE:0)
Block(-2,24,-3,CONCRETE:0)
Block(-2,24,-2,CONCRETE:15)
Block(-2,24,-1,CONCRETE:15)
Block(-2,24,0,STONE:6)
Block(-2,24,1,CONCRETE:0)
Block(-2,24,2,CONCRETE:0)
Block(-2,24,3,CONCRETE:0)
Block(-2,24,4,CONCRETE:0)
Block(-2,24,5,QUARTZ_STAIRS:3)
Block(-2,24,8,CONCRETE:7)
Block(-2,25,-2,STAINED_GLASS_PANE:0)
Block(-2,25,-1,STAINED_GLASS_PANE:0)
Block(-2,25,1,STAINED_GLASS_PANE:0)
Block(-2,25,4,CONCRETE:0)
Block(-2,26,4,CONCRETE:0)
Block(-2,27,4,CONCRETE:0)
Block(-2,28,4,CONCRETE:0)
Block(-2,28,5,QUARTZ_STAIRS:7)
Block(-2,29,-1,STEP:8)
Block(-2,29,0,CONCRETE:0)
Block(-2,29,1,CONCRETE:0)
Block(-2,29,2,CONCRETE:0)
Block(-2,29,3,CONCRETE:0)
Block(-2,29,4,CONCRETE:0)
Block(-2,29,5,CONCRETE:0)
Block(-2,29,6,QUARTZ_STAIRS:7)
Block(-2,30,-1,STAINED_GLASS_PANE:15)
Block(-2,30,4,CONCRETE:0)
Block(-2,30,5,CONCRETE:0)
Block(-2,30,6,COBBLE_WALL:0)
Block(-2,31,4,CONCRETE:0)
Block(-2,31,5,CONCRETE:0)
Block(-2,32,1,QUARTZ_STAIRS:5)
Block(-2,32,4,CONCRETE:0)
Block(-2,32,5,CONCRETE:0)
Block(-2,33,1,CONCRETE:0)
Block(-2,33,2,STEP:8)
Block(-2,33,3,STEP:8)
Block(-2,33,4,CONCRETE:0)
Block(-2,33,5,CONCRETE:0)
Block(-2,33,6,QUARTZ_STAIRS:7)
Block(-2,34,1,STAINED_GLASS_PANE:15)
Block(-2,34,4,CONCRETE:7)
Block(-2,34,5,STEP:7)
Block(-2,34,6,COBBLE_WALL:0)
Block(-2,35,4,STAINED_GLASS_PANE:15)
Block(-2,36,4,STAINED_GLASS_PANE:15)
Block(-2,37,4,STAINED_GLASS_PANE:15)
Block(-2,37,5,COBBLE_WALL:0)
Block(-2,38,4,CONCRETE:0)
Block(-2,38,5,CONCRETE:0)
Block(-2,38,6,STEP:8)
Block(-2,39,4,CONCRETE:0)
Block(-2,39,5,CONCRETE:0)
Block(-2,40,2,STEP:15)
Block(-2,40,3,STEP:15)
Block(-2,40,4,STEP:7)
Block(-2,40,5,COBBLE_WALL:0)
Block(-2,41,0,CONCRETE:7)
Block(-2,41,1,STEP:7)
Block(-2,41,2,STEP:7)
Block(-2,42,-1,CONCRETE:7)
Block(-2,43,-4,CONCRETE:7)
Block(-2,43,-3,CONCRETE:7)
Block(-2,43,-2,CONCRETE:7)
Block(-2,44,-7,CONCRETE:7)
Block(-2,44,-6,CONCRETE:7)
Block(-2,44,-5,CONCRETE:7)
Block(-1,0,-7,CONCRETE:7)
Block(-1,0,-6,CONCRETE:7)
Block(-1,0,-5,CONCRETE:7)
Block(-1,0,-4,CONCRETE:7)
Block(-1,0,-3,CONCRETE:7)
Block(-1,0,-2,CONCRETE:7)
Block(-1,0,-1,CONCRETE:7)
Block(-1,0,0,CONCRETE:7)
Block(-1,0,1,CONCRETE:7)
Block(-1,0,2,CONCRETE:7)
Block(-1,0,3,CONCRETE:7)
Block(-1,0,4,CONCRETE:7)
Block(-1,0,5,CONCRETE:7)
Block(-1,0,6,CONCRETE:7)
Block(-1,0,7,CONCRETE:7)
Block(-1,0,8,CONCRETE:7)
Block(-1,1,-7,OBSIDIAN:0)
Block(-1,1,-6,OBSIDIAN:0)
Block(-1,1,-5,OBSIDIAN:0)
Block(-1,1,-4,OBSIDIAN:0)
Block(-1,1,-3,OBSIDIAN:0)
Block(-1,1,-2,OBSIDIAN:0)
Block(-1,1,-1,OBSIDIAN:0)
Block(-1,1,0,OBSIDIAN:0)
Block(-1,1,1,OBSIDIAN:0)
Block(-1,1,2,OBSIDIAN:0)
Block(-1,1,3,OBSIDIAN:0)
Block(-1,1,4,OBSIDIAN:0)
Block(-1,1,5,OBSIDIAN:0)
Block(-1,1,6,OBSIDIAN:0)
Block(-1,1,7,OBSIDIAN:0)
Block(-1,1,8,OBSIDIAN:0)
Block(-1,2,-7,CONCRETE:12)
Block(-1,2,-6,CONCRETE:12)
Block(-1,2,-5,CONCRETE:12)
Block(-1,2,-4,CONCRETE:12)
Block(-1,2,-3,CONCRETE:12)
Block(-1,2,-2,CONCRETE:12)
Block(-1,2,-1,CONCRETE:12)
Block(-1,2,0,CONCRETE:12)
Block(-1,2,1,CONCRETE:12)
Block(-1,2,2,CONCRETE:12)
Block(-1,2,3,CONCRETE:12)
Block(-1,2,4,CONCRETE:12)
Block(-1,2,5,CONCRETE:12)
Block(-1,2,6,CONCRETE:12)
Block(-1,2,7,CONCRETE:12)
Block(-1,2,8,CONCRETE:12)
Block(-1,3,-7,CONCRETE:7)
Block(-1,3,-6,CONCRETE:7)
Block(-1,3,-5,CONCRETE:7)
Block(-1,3,-4,CONCRETE:7)
Block(-1,3,-3,CONCRETE:7)
Block(-1,3,-2,CONCRETE:7)
Block(-1,3,-1,CONCRETE:7)
Block(-1,3,0,CONCRETE:7)
Block(-1,3,1,CONCRETE:7)
Block(-1,3,2,CONCRETE:7)
Block(-1,3,3,CONCRETE:7)
Block(-1,3,4,CONCRETE:7)
Block(-1,3,5,CONCRETE:7)
Block(-1,3,6,CONCRETE:7)
Block(-1,3,7,CONCRETE:7)
Block(-1,3,8,CONCRETE:7)
Block(-1,4,-7,CONCRETE:7)
Block(-1,4,-6,CONCRETE:7)
Block(-1,4,-5,CONCRETE:4)
Block(-1,4,-4,CONCRETE:7)
Block(-1,4,-3,CONCRETE:7)
Block(-1,4,-2,CONCRETE:7)
Block(-1,4,-1,CONCRETE:7)
Block(-1,4,0,CONCRETE:7)
Block(-1,4,1,CONCRETE:7)
Block(-1,4,2,CONCRETE:7)
Block(-1,4,3,CONCRETE:7)
Block(-1,4,4,CONCRETE:7)
Block(-1,4,5,CONCRETE:7)
Block(-1,4,6,CONCRETE:7)
Block(-1,4,7,CONCRETE:7)
Block(-1,4,8,CONCRETE:7)
Block(-1,5,-7,AIR:0)
Block(-1,5,-6,AIR:0)
Block(-1,5,-5,AIR:0)
Block(-1,5,-4,AIR:0)
Block(-1,5,-3,AIR:0)
Block(-1,5,-2,AIR:0)
Block(-1,5,-1,AIR:0)
Block(-1,5,0,AIR:0)
Block(-1,5,1,AIR:0)
Block(-1,5,2,AIR:0)
Block(-1,5,3,AIR:0)
Block(-1,5,4,AIR:0)
Block(-1,5,5,AIR:0)
Block(-1,5,6,AIR:0)
Block(-1,5,7,AIR:0)
Block(-1,5,8,AIR:0)
Block(-1,6,-7,AIR:0)
Block(-1,6,-6,AIR:0)
Block(-1,6,-5,IRON_FENCE:0)
Block(-1,6,-4,AIR:0)
Block(-1,6,-3,AIR:0)
Block(-1,6,-2,AIR:0)
Block(-1,6,-1,AIR:0)
Block(-1,6,0,AIR:0)
Block(-1,6,1,AIR:0)
Block(-1,6,2,AIR:0)
Block(-1,6,3,AIR:0)
Block(-1,6,4,AIR:0)
Block(-1,6,5,AIR:0)
Block(-1,6,6,AIR:0)
Block(-1,6,7,AIR:0)
Block(-1,6,8,AIR:0)
Block(-1,7,-7,AIR:0)
Block(-1,7,-6,AIR:0)
Block(-1,7,-5,IRON_FENCE:0)
Block(-1,7,-4,AIR:0)
Block(-1,7,-3,AIR:0)
Block(-1,7,-2,AIR:0)
Block(-1,7,-1,AIR:0)
Block(-1,7,0,AIR:0)
Block(-1,7,1,AIR:0)
Block(-1,7,2,AIR:0)
Block(-1,7,3,AIR:0)
Block(-1,7,4,AIR:0)
Block(-1,7,5,AIR:0)
Block(-1,7,6,AIR:0)
Block(-1,7,7,AIR:0)
Block(-1,7,8,AIR:0)
Block(-1,8,-7,AIR:0)
Block(-1,8,-6,AIR:0)
Block(-1,8,-5,CONCRETE:7)
Block(-1,8,-4,AIR:0)
Block(-1,8,-3,AIR:0)
Block(-1,8,-2,AIR:0)
Block(-1,8,-1,CONCRETE:7)
Block(-1,8,0,AIR:0)
Block(-1,8,1,AIR:0)
Block(-1,8,2,AIR:0)
Block(-1,8,3,CONCRETE:7)
Block(-1,8,4,IRON_TRAPDOOR:9)
Block(-1,8,5,AIR:0)
Block(-1,8,6,AIR:0)
Block(-1,8,7,CONCRETE:7)
Block(-1,8,8,AIR:0)
Block(-1,9,-7,AIR:0)
Block(-1,9,-6,AIR:0)
Block(-1,9,-5,IRON_FENCE:0)
Block(-1,9,-4,AIR:0)
Block(-1,9,-3,AIR:0)
Block(-1,9,-2,AIR:0)
Block(-1,9,-1,AIR:0)
Block(-1,9,0,AIR:0)
Block(-1,9,1,AIR:0)
Block(-1,9,2,AIR:0)
Block(-1,9,3,AIR:0)
Block(-1,9,4,CONCRETE:14)
Block(-1,9,5,AIR:0)
Block(-1,9,6,AIR:0)
Block(-1,9,7,AIR:0)
Block(-1,9,8,AIR:0)
Block(-1,10,-7,AIR:0)
Block(-1,10,-6,AIR:0)
Block(-1,10,-5,IRON_FENCE:0)
Block(-1,10,-4,AIR:0)
Block(-1,10,-3,AIR:0)
Block(-1,10,-2,AIR:0)
Block(-1,10,-1,AIR:0)
Block(-1,10,0,AIR:0)
Block(-1,10,1,AIR:0)
Block(-1,10,2,AIR:0)
Block(-1,10,3,AIR:0)
Block(-1,10,4,IRON_TRAPDOOR:8)
Block(-1,10,5,AIR:0)
Block(-1,10,6,AIR:0)
Block(-1,10,7,AIR:0)
Block(-1,10,8,AIR:0)
Block(-1,11,-7,AIR:0)
Block(-1,11,-6,AIR:0)
Block(-1,11,-5,IRON_FENCE:0)
Block(-1,11,-4,AIR:0)
Block(-1,11,-3,AIR:0)
Block(-1,11,-2,AIR:0)
Block(-1,11,-1,AIR:0)
Block(-1,11,0,LEVER:1)
Block(-1,11,1,AIR:0)
Block(-1,11,2,AIR:0)
Block(-1,11,3,AIR:0)
Block(-1,11,4,CONCRETE:4)
Block(-1,11,5,AIR:0)
Block(-1,11,6,AIR:0)
Block(-1,11,7,AIR:0)
Block(-1,11,8,LEVER:1)
Block(-1,12,-7,STEP:8)
Block(-1,12,-6,STEP:8)
Block(-1,12,-5,CONCRETE:7)
Block(-1,12,-4,STEP:8)
Block(-1,12,-3,STEP:8)
Block(-1,12,-2,STEP:8)
Block(-1,12,-1,CONCRETE:7)
Block(-1,12,0,DOUBLE_STEP:0)
Block(-1,12,1,STEP:8)
Block(-1,12,2,STEP:8)
Block(-1,12,3,CONCRETE:7)
Block(-1,12,4,STEP:8)
Block(-1,12,5,STEP:8)
Block(-1,12,6,STEP:8)
Block(-1,12,7,CONCRETE:7)
Block(-1,12,8,DOUBLE_STEP:0)
Block(-1,13,-7,OBSIDIAN:0)
Block(-1,13,-6,OBSIDIAN:0)
