
#######################################################################
# +-----------------------------------------------------------------+ #
# |                            BO4 object                           | #
# +-----------------------------------------------------------------+ #
#######################################################################

Author: NLBlackEagle

Description: No description given

SettingsMode: WriteDisable


#######################################################################
# +-----------------------------------------------------------------+ #
# |                          Main settings                          | #
# +-----------------------------------------------------------------+ #
#######################################################################

Frequency: 0

SpawnHeight: highestBlock

UseCenterForHighestBlock: true

##############################
# Height Limits for the BO4. #
##############################

MinHeight: 0

MaxHeight: 255

InheritBO3: 

InheritBO3Rotation: NORTH

OverrideChildSettings: true

OverrideParentHeight: false

CanOverride: true

BranchFrequency: 0

BranchFrequencyGroup: 

MustBeBelowOther: false

MustBeInside: 

CannotBeInside: 

ReplacesBO3: L4-M-CrossC0R0, L4-M-CrossC0R1, L4-M-CrossC0R2, L4-M-CrossC0R3, L4-M-CrossC1R0, L4-M-CrossC1R1, L4-M-CrossC1R2, L4-M-CrossC1R3, L4-M-CrossC2R0, L4-M-CrossC2R1, L4-M-CrossC2R2, L4-M-CrossC2R3, L4-M-CrossC3R0, L4-M-CrossC3R1, L4-M-CrossC3R2, L4-M-CrossC3R3, L4-M-Straigth-START_01-C0R0, L4-M-Straigth-START_01-C0R1, L4-M-Straigth-START_01-C1R0, L4-M-Straigth-START_01-C1R1, L4-M-Straigth-START_01-C2R0, L4-M-Straigth-START_01-C2R1, L4-M-Straigth-START_01-C3R0, L4-M-Straigth-START_01-C3R1, L4-M-Straigth-3CC0R0, L4-M-Straigth-3CC0R1, L4-M-Straigth-3CC0R2, L4-M-Straigth-3CC1R0, L4-M-Straigth-3CC1R1, L4-M-Straigth-3CC1R2, L4-M-Straigth-3CC2R0, L4-M-Straigth-3CC2R1, L4-M-Straigth-3CC2R2, L4-M-Straigth-3CC3R0, L4-M-Straigth-3CC3R1, L4-M-Straigth-3CC3R2, L4-M-Cross, skyscraper_2x2_01, skyscraper_2x2_02, skyscraper_2x2_03, skyscraper_2x2_04, skyscraper_2x2_05, skyscraper_3x3_01, skyscraper_3x3_02, skyscraper_3x3_03, L3-M-Straigth-2CC0R0, L3-M-Straigth-2CC0R1, L3-M-Straigth-2CC1R0, L3-M-Straigth-2CC1R1, L3-M-Straigth-2CC2R0, L3-M-Straigth-2CC2R1, L3-M-Straigth-2CC3R0, L3-M-Straigth-2CC3R1, L3-M-Straigth-3CC0R0, L3-M-Straigth-3CC0R1, L3-M-Straigth-3CC0R2, L3-M-Straigth-3CC1R0, L3-M-Straigth-3CC1R1, L3-M-Straigth-3CC1R2, L3-M-Straigth-3CC2R0, L3-M-Straigth-3CC2R1, L3-M-Straigth-3CC2R2, L3-M-Straigth-3CC3R0, L3-M-Straigth-3CC3R1, L3-M-Straigth-3CC3R2L4-M-CrossC0R0, L4-M-CrossC0R1, L4-M-CrossC0R2, L4-M-CrossC0R3, L4-M-CrossC1R0, L4-M-CrossC1R1, L4-M-CrossC1R2, L4-M-CrossC1R3, L4-M-CrossC2R0, L4-M-CrossC2R1, L4-M-CrossC2R2, L4-M-CrossC2R3, L4-M-CrossC3R0, L4-M-CrossC3R1, L4-M-CrossC3R2, L4-M-CrossC3R3, L4-M-Straigth-START_01-C0R0, L4-M-Straigth-START_01-C0R1, L4-M-Straigth-START_01-C1R0, L4-M-Straigth-START_01-C1R1, L4-M-Straigth-START_01-C2R0, L4-M-Straigth-START_01-C2R1, L4-M-Straigth-START_01-C3R0, L4-M-Straigth-START_01-C3R1, L4-M-Straigth-3CC0R0, L4-M-Straigth-3CC0R1, L4-M-Straigth-3CC0R2, L4-M-Straigth-3CC1R0, L4-M-Straigth-3CC1R1, L4-M-Straigth-3CC1R2, L4-M-Straigth-3CC2R0, L4-M-Straigth-3CC2R1, L4-M-Straigth-3

MustBeInsideWorldBorders: false

CanSpawnOnWater: true

SpawnOnWaterOnly: false

SpawnUnderWater: false

SpawnAtWaterLevel: false

HeightOffset: 0

RemoveAir: false

ReplaceAbove: 

ReplaceBelow: 

ReplaceWithBiomeBlocks: true

ReplaceWithSurfaceBlock: GRASS

ReplaceWithGroundBlock: DIRT

ReplaceWithStoneBlock: STONE

SmoothRadius: 0

SmoothHeightOffset: 0

SmoothStartTop: false

SmoothStartWood: false

SmoothingSurfaceBlock: 

SmoothingGroundBlock: 

BO3Group: 

IsSpawnPoint: false

DoReplaceBlocks: true


#######################################################################
# +-----------------------------------------------------------------+ #
# |                              Blocks                             | #
# +-----------------------------------------------------------------+ #
#######################################################################

Block(-8,0,-7,CONCRETE:7)
Block(-8,0,-6,CONCRETE:7)
Block(-8,0,-5,CONCRETE:7)
Block(-8,0,-4,CONCRETE:7)
Block(-8,0,-3,CONCRETE:7)
Block(-8,0,-2,CONCRETE:7)
Block(-8,0,-1,CONCRETE:7)
Block(-8,0,0,CONCRETE:7)
Block(-8,0,1,CONCRETE:7)
Block(-8,0,2,CONCRETE:7)
Block(-8,0,3,CONCRETE:7)
Block(-8,0,4,CONCRETE:7)
Block(-8,0,5,CONCRETE:7)
Block(-8,0,6,CONCRETE:7)
Block(-8,0,7,CONCRETE:7)
Block(-8,0,8,CONCRETE:7)
Block(-8,1,-7,AIR:0)
Block(-8,1,-6,AIR:0)
Block(-8,1,-5,AIR:0)
Block(-8,1,-4,SMOOTH_STAIRS:2)
Block(-8,1,-3,CONCRETE:7)
Block(-8,1,-2,CONCRETE:7)
Block(-8,1,-1,CONCRETE:7)
Block(-8,1,0,CONCRETE:7)
Block(-8,1,1,CONCRETE:7)
Block(-8,1,2,CONCRETE:7)
Block(-8,1,3,STATIONARY_WATER:0)
Block(-8,1,4,STATIONARY_WATER:0)
Block(-8,1,5,CONCRETE:7)
Block(-8,1,6,CONCRETE:7)
Block(-8,1,7,CONCRETE:7)
Block(-8,1,8,CONCRETE:7)
Block(-8,2,-7,IRON_TRAPDOOR:9)
Block(-8,2,-6,IRON_TRAPDOOR:11)
Block(-8,2,-5,AIR:0)
Block(-8,2,-4,AIR:0)
Block(-8,2,-3,SMOOTH_STAIRS:2)
Block(-8,2,-2,CONCRETE:7)
Block(-8,2,-1,CONCRETE:7)
Block(-8,2,0,CONCRETE:7)
Block(-8,2,1,CONCRETE:7)
Block(-8,2,2,SMOOTH_STAIRS:3)
Block(-8,2,3,AIR:0)
Block(-8,2,4,AIR:0)
Block(-8,2,5,SMOOTH_STAIRS:2)
Block(-8,2,6,CONCRETE:7)
Block(-8,2,7,CONCRETE:7)
Block(-8,2,8,CONCRETE:7)
Block(-8,3,-7,AIR:0)
Block(-8,3,-6,AIR:0)
Block(-8,3,-5,AIR:0)
Block(-8,3,-4,AIR:0)
Block(-8,3,-3,AIR:0)
Block(-8,3,-2,AIR:0)
Block(-8,3,-1,AIR:0)
Block(-8,3,0,AIR:0)
Block(-8,3,1,AIR:0)
Block(-8,3,2,AIR:0)
Block(-8,3,3,AIR:0)
Block(-8,3,4,AIR:0)
Block(-8,3,5,AIR:0)
Block(-8,3,6,AIR:0)
Block(-8,3,7,AIR:0)
Block(-8,3,8,CONCRETE:7)
Block(-8,4,-7,AIR:0)
Block(-8,4,-6,AIR:0)
Block(-8,4,-5,AIR:0)
Block(-8,4,-4,AIR:0)
Block(-8,4,-3,AIR:0)
Block(-8,4,-2,AIR:0)
Block(-8,4,-1,AIR:0)
Block(-8,4,0,AIR:0)
Block(-8,4,1,AIR:0)
Block(-8,4,2,AIR:0)
Block(-8,4,3,AIR:0)
Block(-8,4,4,AIR:0)
Block(-8,4,5,AIR:0)
Block(-8,4,6,AIR:0)
Block(-8,4,7,AIR:0)
Block(-8,4,8,CONCRETE:7)
Block(-8,5,-7,AIR:0)
Block(-8,5,-6,AIR:0)
Block(-8,5,-5,AIR:0)
Block(-8,5,-4,AIR:0)
Block(-8,5,-3,AIR:0)
Block(-8,5,-2,AIR:0)
Block(-8,5,-1,AIR:0)
Block(-8,5,0,AIR:0)
Block(-8,5,1,AIR:0)
Block(-8,5,2,AIR:0)
Block(-8,5,3,AIR:0)
Block(-8,5,4,AIR:0)
Block(-8,5,5,AIR:0)
Block(-8,5,6,CONCRETE:12)
Block(-8,5,7,CONCRETE:4)
Block(-8,5,8,CONCRETE:7)
Block(-8,6,-7,CONCRETE:7)
Block(-8,6,-6,AIR:0)
Block(-8,6,-5,AIR:0)
Block(-8,6,-4,AIR:0)
Block(-8,6,-3,AIR:0)
Block(-8,6,-2,AIR:0)
Block(-8,6,-1,AIR:0)
Block(-8,6,0,AIR:0)
Block(-8,6,1,AIR:0)
Block(-8,6,2,AIR:0)
Block(-8,6,3,AIR:0)
Block(-8,6,4,AIR:0)
Block(-8,6,5,AIR:0)
Block(-8,6,6,AIR:0)
Block(-8,6,7,AIR:0)
Block(-8,6,8,CONCRETE:7)
Block(-8,7,-7,CONCRETE:7)
Block(-8,7,-6,CONCRETE:7)
Block(-8,7,-5,CONCRETE:7)
Block(-8,7,-4,CONCRETE:7)
Block(-8,7,-3,CONCRETE:7)
Block(-8,7,-2,CONCRETE:7)
Block(-8,7,-1,CONCRETE:7)
Block(-8,7,0,CONCRETE:7)
Block(-8,7,1,CONCRETE:7)
Block(-8,7,2,CONCRETE:7)
Block(-8,7,3,CONCRETE:7)
Block(-8,7,4,CONCRETE:7)
Block(-8,7,5,CONCRETE:7)
Block(-8,7,6,CONCRETE:7)
Block(-8,7,7,CONCRETE:7)
Block(-8,7,8,CONCRETE:7)
Block(-8,8,-7,CONCRETE:7)
Block(-8,8,-6,CONCRETE:7)
Block(-8,8,-5,CONCRETE:7)
Block(-8,8,-4,CONCRETE:7)
Block(-8,8,-3,CONCRETE:7)
Block(-8,8,-2,CONCRETE:7)
Block(-8,8,-1,CONCRETE:7)
Block(-8,8,0,CONCRETE:7)
Block(-8,8,1,CONCRETE:7)
Block(-8,8,2,CONCRETE:7)
Block(-8,8,3,CONCRETE:7)
Block(-8,8,4,CONCRETE:7)
Block(-8,8,5,STEP:0)
Block(-8,8,6,STEP:0)
Block(-8,8,7,STEP:0)
Block(-8,8,8,STEP:0)
Block(-8,9,-7,CONCRETE:7)
Block(-8,9,-6,CONCRETE:7)
Block(-8,9,-5,CONCRETE:7)
Block(-8,9,-4,CONCRETE:7)
Block(-8,9,-3,CONCRETE:7)
Block(-8,9,-2,CONCRETE:7)
Block(-8,9,-1,CONCRETE:7)
Block(-8,9,0,CONCRETE:7)
Block(-8,9,1,CONCRETE:7)
Block(-8,9,2,CONCRETE:7)
Block(-8,9,3,CONCRETE:7)
Block(-8,9,4,CONCRETE:7)
Block(-8,9,5,AIR:0)
Block(-8,9,6,AIR:0)
Block(-8,9,7,IRON_TRAPDOOR:8)
Block(-8,9,8,IRON_TRAPDOOR:10)
Block(-8,10,-7,CONCRETE:7)
Block(-8,10,-6,CONCRETE:7)
Block(-8,10,-5,CONCRETE:7)
Block(-8,10,-4,CONCRETE:7)
Block(-8,10,-3,CONCRETE:7)
Block(-8,10,-2,CONCRETE:7)
Block(-8,10,-1,CONCRETE:7)
Block(-8,10,0,CONCRETE:7)
Block(-8,10,1,DISPENSER:5,NBT/skyscraper_2x2_04/303-dispenserC16R0.nbt)
Block(-8,10,2,DISPENSER:5,NBT/skyscraper_2x2_04/304-dispenserC16R0.nbt)
Block(-8,10,3,DISPENSER:5,NBT/skyscraper_2x2_04/305-dispenserC16R0.nbt)
Block(-8,10,4,CONCRETE:7)
Block(-8,10,5,AIR:0)
Block(-8,10,6,AIR:0)
Block(-8,10,7,IRON_FENCE:0)
Block(-8,10,8,AIR:0)
Block(-8,11,-7,CONCRETE:7)
Block(-8,11,-6,CONCRETE:7)
Block(-8,11,-5,CONCRETE:7)
Block(-8,11,-4,CONCRETE:7)
Block(-8,11,-3,SMOOTH_STAIRS:1)
Block(-8,11,-2,SMOOTH_STAIRS:1)
Block(-8,11,-1,CONCRETE:7)
Block(-8,11,0,CONCRETE:7)
Block(-8,11,1,DISPENSER:5,NBT/skyscraper_2x2_04/306-dispenserC16R0.nbt)
Block(-8,11,2,DISPENSER:5,NBT/skyscraper_2x2_04/307-dispenserC16R0.nbt)
Block(-8,11,3,DISPENSER:5,NBT/skyscraper_2x2_04/308-dispenserC16R0.nbt)
Block(-8,11,4,CONCRETE:7)
Block(-8,11,5,AIR:0)
Block(-8,11,6,AIR:0)
Block(-8,11,7,AIR:0)
Block(-8,11,8,AIR:0)
Block(-8,12,-7,CONCRETE:7)
Block(-8,12,-6,CONCRETE:7)
Block(-8,12,-5,CONCRETE:7)
Block(-8,12,-4,CONCRETE:7)
Block(-8,12,-3,AIR:0)
Block(-8,12,-2,AIR:0)
Block(-8,12,-1,CONCRETE:7)
Block(-8,12,0,CONCRETE:7)
Block(-8,12,1,DISPENSER:5,NBT/skyscraper_2x2_04/309-dispenserC16R0.nbt)
Block(-8,12,2,DISPENSER:13,NBT/skyscraper_2x2_04/310-dispenserC16R0.nbt)
Block(-8,12,3,DISPENSER:5,NBT/skyscraper_2x2_04/311-dispenserC16R0.nbt)
Block(-8,12,4,CONCRETE:7)
Block(-8,12,5,AIR:0)
Block(-8,12,6,AIR:0)
Block(-8,12,7,AIR:0)
Block(-8,12,8,AIR:0)
Block(-8,13,-7,CONCRETE:7)
Block(-8,13,-6,CONCRETE:7)
Block(-8,13,-5,CONCRETE:7)
Block(-8,13,-4,CONCRETE:7)
Block(-8,13,-3,AIR:0)
Block(-8,13,-2,AIR:0)
Block(-8,13,-1,CONCRETE:7)
Block(-8,13,0,CONCRETE:7)
Block(-8,13,1,CONCRETE:7)
Block(-8,13,2,CONCRETE:7)
Block(-8,13,3,CONCRETE:7)
Block(-8,13,4,CONCRETE:7)
Block(-8,13,5,AIR:0)
Block(-8,13,6,AIR:0)
Block(-8,13,7,AIR:0)
Block(-8,13,8,AIR:0)
Block(-8,14,-7,CONCRETE:7)
Block(-8,14,-6,CONCRETE:7)
Block(-8,14,-5,CONCRETE:7)
Block(-8,14,-4,CONCRETE:7)
Block(-8,14,-3,AIR:0)
Block(-8,14,-2,AIR:0)
Block(-8,14,-1,CONCRETE:7)
Block(-8,14,0,CONCRETE:7)
Block(-8,14,1,DISPENSER:5,NBT/skyscraper_2x2_04/312-dispenserC16R0.nbt)
Block(-8,14,2,DISPENSER:5,NBT/skyscraper_2x2_04/313-dispenserC16R0.nbt)
Block(-8,14,3,DISPENSER:5,NBT/skyscraper_2x2_04/314-dispenserC16R0.nbt)
Block(-8,14,4,CONCRETE:7)
Block(-8,14,5,AIR:0)
Block(-8,14,6,STEP:8)
Block(-8,14,7,AIR:0)
Block(-8,14,8,STEP:8)
Block(-8,15,-7,CONCRETE:7)
Block(-8,15,-6,CONCRETE:7)
Block(-8,15,-5,CONCRETE:7)
Block(-8,15,-4,CONCRETE:7)
Block(-8,15,-3,SMOOTH_STAIRS:4)
Block(-8,15,-2,SMOOTH_STAIRS:4)
Block(-8,15,-1,CONCRETE:7)
Block(-8,15,0,CONCRETE:7)
Block(-8,15,1,DISPENSER:5,NBT/skyscraper_2x2_04/315-dispenserC16R0.nbt)
Block(-8,15,2,DISPENSER:5,NBT/skyscraper_2x2_04/316-dispenserC16R0.nbt)
Block(-8,15,3,DISPENSER:5,NBT/skyscraper_2x2_04/317-dispenserC16R0.nbt)
Block(-8,15,4,CONCRETE:7)
Block(-8,15,5,AIR:0)
Block(-8,15,6,CONCRETE:7)
Block(-8,15,7,AIR:0)
Block(-8,15,8,CONCRETE:7)
Block(-8,16,-7,CONCRETE:7)
Block(-8,16,-6,CONCRETE:7)
Block(-8,16,-5,CONCRETE:7)
Block(-8,16,-4,CONCRETE:7)
Block(-8,16,-3,CONCRETE:7)
Block(-8,16,-2,CONCRETE:7)
Block(-8,16,-1,CONCRETE:7)
Block(-8,16,0,CONCRETE:7)
Block(-8,16,1,DISPENSER:5,NBT/skyscraper_2x2_04/318-dispenserC16R0.nbt)
Block(-8,16,2,DISPENSER:5,NBT/skyscraper_2x2_04/319-dispenserC16R0.nbt)
Block(-8,16,3,DISPENSER:5,NBT/skyscraper_2x2_04/320-dispenserC16R0.nbt)
Block(-8,16,4,CONCRETE:7)
Block(-8,16,5,AIR:0)
Block(-8,16,6,AIR:0)
Block(-8,16,7,AIR:0)
Block(-8,16,8,AIR:0)
Block(-8,17,-7,CONCRETE:7)
Block(-8,17,-6,CONCRETE:7)
Block(-8,17,-5,CONCRETE:7)
Block(-8,17,-4,CONCRETE:7)
Block(-8,17,-3,CONCRETE:7)
Block(-8,17,-2,CONCRETE:7)
Block(-8,17,-1,CONCRETE:7)
Block(-8,17,0,CONCRETE:7)
Block(-8,17,1,CONCRETE:7)
Block(-8,17,2,CONCRETE:7)
Block(-8,17,3,CONCRETE:7)
Block(-8,17,4,CONCRETE:7)
Block(-8,17,5,CONCRETE:7)
Block(-8,17,6,CONCRETE:7)
Block(-8,17,7,CONCRETE:7)
Block(-8,17,8,CONCRETE:7)
Block(-8,18,-5,CONCRETE:8)
Block(-8,18,-4,CONCRETE:8)
Block(-8,18,-3,CONCRETE:8)
Block(-8,18,-2,CONCRETE:8)
Block(-8,18,-1,CONCRETE:8)
Block(-8,18,0,CONCRETE:15)
Block(-8,18,1,CONCRETE:15)
Block(-8,18,2,CONCRETE:15)
Block(-8,18,3,CONCRETE:15)
Block(-8,18,4,CONCRETE:15)
Block(-8,18,5,CONCRETE:15)
Block(-8,18,6,CONCRETE:15)
Block(-8,18,7,CONCRETE:8)
Block(-8,18,8,CONCRETE:8)
Block(-8,19,-5,STAINED_GLASS:15)
Block(-8,19,0,FENCE:0)
Block(-8,19,1,WOOD_STAIRS:2)
Block(-8,19,2,WOOD_STAIRS:3)
Block(-8,19,3,FENCE:0)
Block(-8,19,4,WOOD_STAIRS:2)
Block(-8,19,5,WOOD_STAIRS:3)
Block(-8,19,6,FENCE:0)
Block(-8,20,-5,STAINED_GLASS:15)
Block(-8,20,0,WOOD_PLATE:0)
Block(-8,20,3,WOOD_PLATE:0)
Block(-8,20,6,WOOD_PLATE:0)
Block(-8,21,-5,STAINED_GLASS:15)
Block(-8,22,-5,STAINED_GLASS:15)
Block(-8,22,-2,LEAVES:4)
Block(-8,23,-5,STAINED_GLASS:15)
Block(-8,24,-5,STAINED_GLASS:15)
Block(-8,25,-5,STAINED_GLASS:15)
Block(-8,26,-5,STAINED_GLASS:15)
Block(-8,27,-5,STAINED_GLASS:15)
Block(-8,28,-5,STAINED_GLASS:15)
Block(-8,29,-5,STAINED_GLASS:15)
Block(-8,30,-5,STAINED_GLASS:15)
Block(-8,31,-5,STAINED_GLASS:15)
Block(-8,32,-5,STAINED_GLASS:15)
Block(-8,32,4,TRAP_DOOR:7)
Block(-8,33,-5,STAINED_GLASS:15)
Block(-8,34,-5,STAINED_GLASS:15)
Block(-8,35,-5,STAINED_GLASS:15)
Block(-8,36,-5,STAINED_GLASS:15)
Block(-8,37,-5,STAINED_GLASS:15)
Block(-8,38,-5,STAINED_GLASS:15)
Block(-8,39,-5,STAINED_GLASS:15)
Block(-8,40,-5,STAINED_GLASS:15)
Block(-8,41,-5,STAINED_GLASS:15)
Block(-8,42,-5,STAINED_GLASS:15)
Block(-8,43,-5,STAINED_GLASS:15)
Block(-8,44,-5,STAINED_GLASS:15)
Block(-8,45,-5,STAINED_GLASS:15)
Block(-8,46,-5,STAINED_GLASS:15)
Block(-8,47,-5,STAINED_GLASS:15)
Block(-8,48,-5,STAINED_GLASS:15)
Block(-8,49,-5,STAINED_GLASS:15)
Block(-8,50,-5,STAINED_GLASS:15)
Block(-8,50,4,TRAP_DOOR:15)
Block(-8,51,-5,STAINED_GLASS:15)
Block(-8,52,-5,STAINED_GLASS:15)
Block(-8,53,-5,STAINED_GLASS:15)
Block(-8,54,-5,STAINED_GLASS:15)
Block(-8,55,-5,STAINED_GLASS:15)
Block(-8,56,-5,STAINED_GLASS:15)
Block(-8,57,-5,STAINED_GLASS:15)
Block(-8,58,-5,STAINED_GLASS:15)
Block(-8,59,-5,STAINED_GLASS:15)
Block(-8,60,-5,STAINED_GLASS:15)
Block(-8,61,-5,STAINED_GLASS:15)
Block(-8,62,-5,STAINED_GLASS:15)
Block(-8,63,-5,STAINED_GLASS:15)
Block(-8,64,-5,STAINED_GLASS:15)
Block(-8,65,-5,STAINED_GLASS:15)
Block(-8,66,-5,STAINED_GLASS:15)
Block(-8,67,-5,STAINED_GLASS:15)
Block(-8,68,-5,STAINED_GLASS:15)
Block(-8,69,-5,STAINED_GLASS:15)
Block(-8,70,-5,STAINED_GLASS:15)
Block(-8,71,-5,STAINED_GLASS:15)
Block(-8,72,-5,STAINED_GLASS:15)
Block(-8,73,-5,STAINED_GLASS:15)
Block(-8,74,-5,STAINED_GLASS:15)
Block(-8,75,-5,STAINED_GLASS:15)
Block(-8,76,-5,STAINED_GLASS:15)
Block(-8,77,-5,STAINED_GLASS:15)
Block(-8,78,-5,STAINED_GLASS:15)
Block(-8,79,-5,STAINED_GLASS:15)
Block(-8,80,-5,STAINED_GLASS:15)
Block(-8,81,-5,STAINED_GLASS:15)
Block(-8,81,4,TRAP_DOOR:15)
Block(-8,82,-5,CONCRETE:8)
Block(-8,82,0,CONCRETE:8)
Block(-8,83,-5,CONCRETE:8)
Block(-8,83,-4,CONCRETE:8)
Block(-8,83,-3,CONCRETE:8)
Block(-8,83,-2,CONCRETE:8)
Block(-8,83,-1,CONCRETE:8)
Block(-8,83,0,CONCRETE:8)
Block(-8,84,-5,CONCRETE:8)
Block(-8,84,-4,CONCRETE:8)
Block(-8,84,-3,CONCRETE:8)
Block(-8,84,-2,CONCRETE:8)
Block(-8,84,-1,CONCRETE:8)
Block(-8,84,0,CONCRETE:8)
Block(-8,85,0,STAINED_GLASS:15)
Block(-8,86,0,STAINED_GLASS:15)
Block(-8,87,0,STAINED_GLASS:15)
Block(-8,88,0,STAINED_GLASS:15)
Block(-8,89,0,STAINED_GLASS:15)
Block(-8,90,0,STAINED_GLASS:15)
Block(-8,91,0,STAINED_GLASS:15)
Block(-8,92,0,STAINED_GLASS:15)
Block(-8,93,0,STAINED_GLASS:15)
Block(-8,94,0,STAINED_GLASS:15)
Block(-8,94,4,TRAP_DOOR:15)
Block(-8,95,0,STAINED_GLASS:15)
Block(-8,96,0,STAINED_GLASS:15)
Block(-8,97,0,STAINED_GLASS:15)
Block(-8,98,0,STAINED_GLASS:15)
Block(-8,99,0,STAINED_GLASS:15)
Block(-8,100,0,STAINED_GLASS:15)
Block(-8,101,0,STAINED_GLASS:15)
Block(-8,102,0,STAINED_GLASS:15)
Block(-8,103,0,STAINED_GLASS:15)
Block(-8,104,0,STAINED_GLASS:15)
Block(-8,105,0,STAINED_GLASS:15)
Block(-8,106,0,STAINED_GLASS:15)
Block(-8,107,0,STAINED_GLASS:15)
Block(-8,108,0,CONCRETE:15)
Block(-8,108,6,CONCRETE:15)
Block(-8,109,0,CONCRETE:15)
Block(-8,109,1,CONCRETE:15)
Block(-8,109,2,CONCRETE:15)
Block(-8,109,3,CONCRETE:15)
Block(-8,109,4,CONCRETE:15)
Block(-8,109,5,CONCRETE:15)
Block(-8,109,6,CONCRETE:15)
Block(-8,110,0,CONCRETE:15)
Block(-8,110,1,CONCRETE:15)
Block(-8,110,2,CONCRETE:15)
Block(-8,110,3,CONCRETE:15)
Block(-8,110,4,CONCRETE:15)
Block(-8,110,5,CONCRETE:15)
Block(-8,110,6,CONCRETE:15)
Block(-8,111,6,STAINED_GLASS:15)
Block(-8,112,6,STAINED_GLASS:15)
Block(-8,113,6,STAINED_GLASS:15)
Block(-8,114,6,STAINED_GLASS:15)
Block(-8,115,6,STAINED_GLASS:15)
Block(-8,116,6,STAINED_GLASS:15)
Block(-8,117,6,STAINED_GLASS:15)
Block(-8,118,6,STAINED_GLASS:15)
Block(-8,119,6,STAINED_GLASS:15)
Block(-8,120,6,STAINED_GLASS:15)
Block(-8,121,6,STAINED_GLASS:15)
Block(-8,122,6,STAINED_GLASS:15)
Block(-8,123,6,STAINED_GLASS:15)
Block(-8,123,7,CONCRETE:8)
Block(-8,123,8,CONCRETE:8)
Block(-8,124,6,STAINED_GLASS:15)
Block(-8,124,7,STAINED_GLASS_PANE:15)
Block(-8,124,8,STAINED_GLASS_PANE:15)
Block(-8,125,6,STAINED_GLASS:15)
Block(-8,126,6,STAINED_GLASS:15)
Block(-8,127,6,STAINED_GLASS:15)
Block(-8,128,6,STAINED_GLASS:15)
Block(-8,129,6,STAINED_GLASS:15)
Block(-8,130,6,STAINED_GLASS:15)
Block(-8,131,6,STAINED_GLASS:15)
Block(-8,132,6,CONCRETE:8)
Block(-8,133,6,CONCRETE:8)
Block(-8,133,7,CONCRETE:8)
Block(-8,133,8,CONCRETE:8)
Block(-8,134,6,CONCRETE:8)
Block(-8,134,7,CONCRETE:8)
Block(-8,134,8,CONCRETE:8)
Block(-7,0,-7,CONCRETE:7)
Block(-7,0,-6,CONCRETE:7)
Block(-7,0,-5,CONCRETE:7)
Block(-7,0,-4,CONCRETE:7)
Block(-7,0,-3,CONCRETE:7)
Block(-7,0,-2,CONCRETE:7)
Block(-7,0,-1,CONCRETE:7)
Block(-7,0,0,CONCRETE:7)
Block(-7,0,1,CONCRETE:7)
Block(-7,0,2,CONCRETE:7)
Block(-7,0,3,CONCRETE:7)
Block(-7,0,4,CONCRETE:7)
Block(-7,0,5,CONCRETE:7)
Block(-7,0,6,CONCRETE:7)
Block(-7,0,7,CONCRETE:7)
Block(-7,0,8,CONCRETE:7)
Block(-7,1,-7,CONCRETE:7)
Block(-7,1,-6,CONCRETE:7)
Block(-7,1,-5,CONCRETE:7)
Block(-7,1,-4,CONCRETE:7)
Block(-7,1,-3,CONCRETE:7)
Block(-7,1,-2,CONCRETE:7)
Block(-7,1,-1,CONCRETE:7)
Block(-7,1,0,CONCRETE:7)
Block(-7,1,1,CONCRETE:7)
Block(-7,1,2,CONCRETE:7)
Block(-7,1,3,STATIONARY_WATER:0)
Block(-7,1,4,STATIONARY_WATER:0)
Block(-7,1,5,CONCRETE:7)
Block(-7,1,6,CONCRETE:7)
Block(-7,1,7,CONCRETE:7)
Block(-7,1,8,CONCRETE:7)
Block(-7,2,-7,CONCRETE:7)
Block(-7,2,-6,CONCRETE:7)
Block(-7,2,-5,CONCRETE:7)
Block(-7,2,-4,CONCRETE:7)
Block(-7,2,-3,CONCRETE:7)
Block(-7,2,-2,CONCRETE:7)
Block(-7,2,-1,CONCRETE:7)
Block(-7,2,0,CONCRETE:7)
Block(-7,2,1,CONCRETE:7)
Block(-7,2,2,SMOOTH_STAIRS:3)
Block(-7,2,3,AIR:0)
Block(-7,2,4,AIR:0)
Block(-7,2,5,SMOOTH_STAIRS:2)
Block(-7,2,6,CONCRETE:7)
Block(-7,2,7,CONCRETE:7)
Block(-7,2,8,CONCRETE:7)
Block(-7,3,-7,AIR:0)
Block(-7,3,-6,AIR:0)
Block(-7,3,-5,AIR:0)
Block(-7,3,-4,AIR:0)
Block(-7,3,-3,AIR:0)
Block(-7,3,-2,AIR:0)
Block(-7,3,-1,AIR:0)
Block(-7,3,0,AIR:0)
Block(-7,3,1,AIR:0)
Block(-7,3,2,AIR:0)
Block(-7,3,3,AIR:0)
Block(-7,3,4,AIR:0)
Block(-7,3,5,AIR:0)
Block(-7,3,6,AIR:0)
Block(-7,3,7,AIR:0)
Block(-7,3,8,CONCRETE:7)
Block(-7,4,-7,AIR:0)
Block(-7,4,-6,AIR:0)
Block(-7,4,-5,AIR:0)
Block(-7,4,-4,AIR:0)
Block(-7,4,-3,AIR:0)
Block(-7,4,-2,AIR:0)
Block(-7,4,-1,AIR:0)
Block(-7,4,0,AIR:0)
Block(-7,4,1,AIR:0)
Block(-7,4,2,AIR:0)
Block(-7,4,3,AIR:0)
Block(-7,4,4,AIR:0)
Block(-7,4,5,AIR:0)
Block(-7,4,6,AIR:0)
Block(-7,4,7,AIR:0)
Block(-7,4,8,CONCRETE:7)
Block(-7,5,-7,AIR:0)
Block(-7,5,-6,AIR:0)
Block(-7,5,-5,AIR:0)
Block(-7,5,-4,AIR:0)
Block(-7,5,-3,AIR:0)
Block(-7,5,-2,AIR:0)
Block(-7,5,-1,AIR:0)
Block(-7,5,0,AIR:0)
Block(-7,5,1,AIR:0)
Block(-7,5,2,AIR:0)
Block(-7,5,3,AIR:0)
Block(-7,5,4,AIR:0)
Block(-7,5,5,AIR:0)
Block(-7,5,6,CONCRETE:12)
Block(-7,5,7,CONCRETE:4)
Block(-7,5,8,CONCRETE:7)
Block(-7,6,-7,CONCRETE:7)
Block(-7,6,-6,AIR:0)
Block(-7,6,-5,AIR:0)
Block(-7,6,-4,AIR:0)
Block(-7,6,-3,AIR:0)
Block(-7,6,-2,AIR:0)
Block(-7,6,-1,AIR:0)
Block(-7,6,0,AIR:0)
Block(-7,6,1,AIR:0)
Block(-7,6,2,AIR:0)
Block(-7,6,3,AIR:0)
Block(-7,6,4,AIR:0)
Block(-7,6,5,AIR:0)
Block(-7,6,6,IRON_FENCE:0)
Block(-7,6,7,AIR:0)
Block(-7,6,8,CONCRETE:7)
Block(-7,7,-7,CONCRETE:7)
Block(-7,7,-6,CONCRETE:7)
Block(-7,7,-5,CONCRETE:7)
Block(-7,7,-4,CONCRETE:7)
Block(-7,7,-3,CONCRETE:7)
Block(-7,7,-2,CONCRETE:7)
Block(-7,7,-1,CONCRETE:7)
Block(-7,7,0,CONCRETE:7)
Block(-7,7,1,CONCRETE:7)
Block(-7,7,2,CONCRETE:7)
Block(-7,7,3,CONCRETE:7)
Block(-7,7,4,CONCRETE:7)
Block(-7,7,5,CONCRETE:7)
Block(-7,7,6,CONCRETE:7)
Block(-7,7,7,CONCRETE:7)
Block(-7,7,8,CONCRETE:7)
Block(-7,8,-7,CONCRETE:7)
Block(-7,8,-6,CONCRETE:7)
Block(-7,8,-5,CONCRETE:7)
Block(-7,8,-4,CONCRETE:7)
Block(-7,8,-3,CONCRETE:7)
Block(-7,8,-2,CONCRETE:7)
Block(-7,8,-1,CONCRETE:7)
Block(-7,8,0,CONCRETE:7)
Block(-7,8,1,CONCRETE:7)
Block(-7,8,2,CONCRETE:7)
Block(-7,8,3,CONCRETE:7)
Block(-7,8,4,CONCRETE:7)
Block(-7,8,5,STEP:0)
Block(-7,8,6,STEP:0)
Block(-7,8,7,STEP:0)
Block(-7,8,8,STEP:0)
Block(-7,9,-7,CONCRETE:7)
Block(-7,9,-6,CONCRETE:7)
Block(-7,9,-5,CONCRETE:7)
Block(-7,9,-4,CONCRETE:7)
Block(-7,9,-3,CONCRETE:7)
Block(-7,9,-2,CONCRETE:7)
Block(-7,9,-1,CONCRETE:7)
Block(-7,9,0,CONCRETE:7)
Block(-7,9,1,CONCRETE:7)
Block(-7,9,2,LEVER:10)
Block(-7,9,3,CONCRETE:7)
Block(-7,9,4,CONCRETE:7)
Block(-7,9,5,AIR:0)
Block(-7,9,6,AIR:0)
Block(-7,9,7,IRON_TRAPDOOR:10)
Block(-7,9,8,IRON_TRAPDOOR:10)
Block(-7,10,-7,CONCRETE:7)
Block(-7,10,-6,CONCRETE:7)
Block(-7,10,-5,CONCRETE:7)
Block(-7,10,-4,CONCRETE:7)
Block(-7,10,-3,SMOOTH_STAIRS:1)
Block(-7,10,-2,SMOOTH_STAIRS:1)
Block(-7,10,-1,CONCRETE:7)
Block(-7,10,0,CONCRETE:7)
Block(-7,10,1,IRON_FENCE:0)
Block(-7,10,2,IRON_FENCE:0)
Block(-7,10,3,IRON_FENCE:0)
Block(-7,10,4,CONCRETE:7)
Block(-7,10,5,AIR:0)
Block(-7,10,6,AIR:0)
Block(-7,10,7,IRON_FENCE:0)
Block(-7,10,8,AIR:0)
Block(-7,11,-7,CONCRETE:7)
Block(-7,11,-6,CONCRETE:7)
Block(-7,11,-5,CONCRETE:7)
Block(-7,11,-4,CONCRETE:7)
Block(-7,11,-3,AIR:0)
Block(-7,11,-2,AIR:0)
Block(-7,11,-1,CONCRETE:7)
Block(-7,11,0,CONCRETE:7)
Block(-7,11,1,IRON_FENCE:0)
Block(-7,11,2,IRON_FENCE:0)
Block(-7,11,3,IRON_FENCE:0)
Block(-7,11,4,CONCRETE:7)
Block(-7,11,5,AIR:0)
Block(-7,11,6,AIR:0)
Block(-7,11,7,AIR:0)
Block(-7,11,8,AIR:0)
Block(-7,12,-7,CONCRETE:7)
Block(-7,12,-6,CONCRETE:7)
Block(-7,12,-5,CONCRETE:7)
Block(-7,12,-4,CONCRETE:7)
Block(-7,12,-3,AIR:0)
Block(-7,12,-2,AIR:0)
Block(-7,12,-1,CONCRETE:7)
Block(-7,12,0,CONCRETE:7)
Block(-7,12,1,IRON_FENCE:0)
Block(-7,12,2,IRON_FENCE:0)
Block(-7,12,3,IRON_FENCE:0)
Block(-7,12,4,CONCRETE:7)
Block(-7,12,5,AIR:0)
Block(-7,12,6,AIR:0)
Block(-7,12,7,AIR:0)
Block(-7,12,8,AIR:0)
Block(-7,13,-7,CONCRETE:7)
Block(-7,13,-6,CONCRETE:7)
Block(-7,13,-5,CONCRETE:7)
Block(-7,13,-4,CONCRETE:7)
Block(-7,13,-3,AIR:0)
Block(-7,13,-2,AIR:0)
Block(-7,13,-1,CONCRETE:7)
Block(-7,13,0,CONCRETE:7)
Block(-7,13,1,CONCRETE:7)
Block(-7,13,2,LEVER:10)
Block(-7,13,3,CONCRETE:7)
Block(-7,13,4,CONCRETE:7)
Block(-7,13,5,AIR:0)
Block(-7,13,6,AIR:0)
Block(-7,13,7,AIR:0)
Block(-7,13,8,AIR:0)
Block(-7,14,-7,CONCRETE:7)
Block(-7,14,-6,CONCRETE:7)
Block(-7,14,-5,CONCRETE:7)
Block(-7,14,-4,CONCRETE:7)
Block(-7,14,-3,SMOOTH_STAIRS:4)
Block(-7,14,-2,SMOOTH_STAIRS:4)
Block(-7,14,-1,CONCRETE:7)
Block(-7,14,0,CONCRETE:7)
Block(-7,14,1,IRON_FENCE:0)
Block(-7,14,2,IRON_FENCE:0)
Block(-7,14,3,IRON_FENCE:0)
Block(-7,14,4,CONCRETE:7)
Block(-7,14,5,AIR:0)
Block(-7,14,6,STEP:8)
Block(-7,14,7,AIR:0)
Block(-7,14,8,STEP:8)
Block(-7,15,-7,CONCRETE:7)
Block(-7,15,-6,CONCRETE:7)
Block(-7,15,-5,CONCRETE:7)
Block(-7,15,-4,CONCRETE:7)
Block(-7,15,-3,CONCRETE:7)
Block(-7,15,-2,CONCRETE:7)
Block(-7,15,-1,CONCRETE:7)
Block(-7,15,0,CONCRETE:7)
Block(-7,15,1,IRON_FENCE:0)
Block(-7,15,2,IRON_FENCE:0)
Block(-7,15,3,IRON_FENCE:0)
Block(-7,15,4,CONCRETE:7)
Block(-7,15,5,AIR:0)
Block(-7,15,6,CONCRETE:7)
Block(-7,15,7,AIR:0)
Block(-7,15,8,CONCRETE:7)
Block(-7,16,-7,CONCRETE:7)
Block(-7,16,-6,CONCRETE:7)
Block(-7,16,-5,CONCRETE:7)
Block(-7,16,-4,CONCRETE:7)
Block(-7,16,-3,CONCRETE:7)
Block(-7,16,-2,CONCRETE:7)
Block(-7,16,-1,CONCRETE:7)
Block(-7,16,0,CONCRETE:7)
Block(-7,16,1,IRON_FENCE:0)
Block(-7,16,2,IRON_FENCE:0)
Block(-7,16,3,IRON_FENCE:0)
Block(-7,16,4,CONCRETE:7)
Block(-7,16,5,AIR:0)
Block(-7,16,6,AIR:0)
Block(-7,16,7,AIR:0)
Block(-7,16,8,AIR:0)
Block(-7,17,-7,CONCRETE:7)
Block(-7,17,-6,CONCRETE:7)
Block(-7,17,-5,CONCRETE:7)
Block(-7,17,-4,CONCRETE:7)
Block(-7,17,-3,CONCRETE:7)
Block(-7,17,-2,CONCRETE:7)
Block(-7,17,-1,CONCRETE:7)
Block(-7,17,0,CONCRETE:7)
Block(-7,17,1,CONCRETE:7)
Block(-7,17,2,CONCRETE:7)
Block(-7,17,3,CONCRETE:7)
Block(-7,17,4,CONCRETE:7)
Block(-7,17,5,CONCRETE:7)
Block(-7,17,6,CONCRETE:7)
Block(-7,17,7,CONCRETE:7)
Block(-7,17,8,CONCRETE:7)
Block(-7,18,-5,CONCRETE:8)
Block(-7,18,-4,CONCRETE:8)
Block(-7,18,-3,CONCRETE:8)
Block(-7,18,-2,CONCRETE:8)
Block(-7,18,-1,CONCRETE:8)
Block(-7,18,0,CONCRETE:15)
Block(-7,18,1,CONCRETE:15)
Block(-7,18,2,CONCRETE:15)
Block(-7,18,3,CONCRETE:15)
Block(-7,18,4,CONCRETE:15)
Block(-7,18,5,CONCRETE:15)
Block(-7,18,6,CONCRETE:15)
Block(-7,18,7,CONCRETE:8)
Block(-7,18,8,CONCRETE:8)
Block(-7,19,-5,STAINED_GLASS:15)
Block(-7,19,-4,CONCRETE:8)
Block(-7,19,-3,STAINED_GLASS_PANE:15)
Block(-7,19,-2,STAINED_GLASS_PANE:15)
Block(-7,19,-1,STAINED_GLASS_PANE:15)
Block(-7,19,0,CONCRETE:8)
Block(-7,19,1,CONCRETE:15)
Block(-7,19,2,CONCRETE:15)
#RandomBlock(-7,19,3,TRAPPED_CHEST:5,../../../../../Chests/Loot/ModernCityJunk_1.nbt,65,CHEST:4,../../../../../Chests/Loot/ModernCityJunk_1.nbt,20,CHEST:4,../../../../../Chests/Loot/ModernCityJunk_2.nbt,15,CHEST:4,../../../../../Chests/Loot/ModernCityJunk_3.nbt,15,CHEST:4,../../../../../Chests/Loot/ModernCityJunk_4.nbt,15,CHEST:4,../../../../../Chests/Loot/ModernCityJunk_5.nbt,15,CHEST:4,../../../../../Chests/Loot/ModernCityCommon_1.nbt,5,CHEST:4,../../../../../Chests/Loot/ModernCityCommon_2.nbt,5,CHEST:4,../../../../../Chests/Loot/ModernCityCommon_3.nbt,5,CHEST:4,../../../../../Chests/Loot/ModernCityCommon_4.nbt,5,CHEST:4,../../../../../Chests/Loot/ModernCityCommon_5.nbt,5,CHEST:4,../../../../../Chests/Loot/ModernCityGood_1.nbt,3,CHEST:4,../../../../../Chests/Loot/ModernCityGood_2.nbt,3,CHEST:4,../../../../../Chests/Loot/ModernCityGood_3.nbt,3,CHEST:4,../../../../../Chests/Loot/ModernCityGood_4.nbt,3,CHEST:4,../../../../../Chests/Loot/ModernCityGood_5.nbt,3,CHEST:4,../../../../../Chests/Loot/ModernCityEpic_1.nbt,1,CHEST:4,../../../../../Chests/Loot/ModernCityEpic_2.nbt,1,CHEST:4,../../../../../Chests/Loot/ModernCityEpic_3.nbt,1,CHEST:4,../../../../../Chests/Loot/ModernCityEpic_4.nbt,1,CHEST:4,../../../../../Chests/Loot/ModernCityEpic_5.nbt,1,CHEST:4,../../../../../Chests/Loot/Common1.nbt,25,CHEST:4,../../../../../Chests/Loot/Common2.nbt,25,CHEST:4,../../../../../Chests/Loot/Common3.nbt,25,CHEST:4,../../../../../Chests/Loot/Common4.nbt,25,CHEST:4,../../../../../Chests/Loot/Common5.nbt,25,CHEST:4,../../../../../Chests/Loot/Common6.nbt,25,CHEST:4,../../../../../Chests/Loot/Common7.nbt,25,CHEST:4,../../../../../Chests/Loot/Common8.nbt,25,CHEST:4,../../../../../Chests/Loot/Common9.nbt,25,CHEST:4,../../../../../Chests/Loot/Common10.nbt,25,CHEST:4,../../../../../Chests/Loot/Common11.nbt,25,CHEST:4,../../../../../Chests/Loot/Common12.nbt,25,CHEST:4,../../../../../Chests/Loot/Common13.nbt,25,CHEST:4,../../../../../Chests/Loot/Common14.nbt,25,CHEST:4,../../../../../Chests/Loot/Common15.nbt,25,CHEST:4,../../../../../Chests/Loot/Rare1.nbt,10,CHEST:4,../../../../../Chests/Loot/Rare2.nbt,10,CHEST:5,../../../../../Chests/Loot/Rare3.nbt,10,CHEST:4,../../../../../Chests/Loot/Rare4.nbt,10,CHEST:4,../../../../../Chests/Loot/Rare5.nbt,10,CHEST:4,../../../../../Chests/Loot/Rare6.nbt,10,CHEST:4,../../../../../Chests/Loot/Rare7.nbt,10,CHEST:4,../../../../../Chests/Loot/Rare8.nbt,10,CHEST:4,../../../../../Chests/Loot/Rare9.nbt,10,CHEST:4,../../../../../Chests/Loot/Rare10.nbt,10,CHEST:4,../../../../../Chests/Loot/Rare11.nbt,10,CHEST:4,../../../../../Chests/Loot/Rare12.nbt,10,CHEST:4,../../../../../Chests/Loot/Rare13.nbt,10,CHEST:4,../../../../../Chests/Loot/Rare14.nbt,10,CHEST:4,../../../../../Chests/Loot/Rare15.nbt,10,CHEST:4,../../../../../Chests/Loot/Epic1.nbt,1,CHEST:4,../../../../../Chests/Loot/Epic2.nbt,1,CHEST:4,../../../../../Chests/Loot/Epic3.nbt,1,CHEST:4,../../../../../Chests/Loot/Epic4.nbt,1,CHEST:4,../../../../../Chests/Loot/Epic5.nbt,1,CHEST:4,../../../../../Chests/Loot/Epic6.nbt,1,CHEST:4,../../../../../Chests/Loot/Epic7.nbt,1,CHEST:4,../../../../../Chests/Loot/Epic8.nbt,1,CHEST:4,../../../../../Chests/Loot/Epic9.nbt,1,CHEST:4,../../../../../Chests/Loot/Epic10.nbt,1,CHEST:4,../../../../../Chests/Loot/Epic11.nbt,1,CHEST:4,../../../../../Chests/Loot/Epic12.nbt,1,CHEST:4,../../../../../Chests/Loot/Epic13.nbt,1,CHEST:4,../../../../../Chests/Loot/Epic14.nbt,1,CHEST:4,../../../../../Chests/Loot/Epic15.nbt,1,CHEST:4,../../../../../Chests/Loot/ModernCityJunk_1.nbt,100)
Block(-7,19,4,CONCRETE:15)
Block(-7,19,5,CONCRETE:15)
Block(-7,19,7,CONCRETE:15)
Block(-7,20,-5,STAINED_GLASS:15)
Block(-7,20,-4,CONCRETE:8)
Block(-7,20,0,CONCRETE:8)
Block(-7,20,1,FLOWER_POT:0,NBT/skyscraper_2x2_04/329-flower_potC16R0.nbt)
Block(-7,20,2,CONCRETE:15)
Block(-7,20,4,CONCRETE:15)
Block(-7,20,5,FLOWER_POT:0,NBT/skyscraper_2x2_04/330-flower_potC16R0.nbt)
Block(-7,20,7,CONCRETE:15)
Block(-7,21,-5,STAINED_GLASS:15)
Block(-7,21,-4,CONCRETE:8)
Block(-7,21,-2,LEAVES:12)
Block(-7,21,0,CONCRETE:8)
Block(-7,21,2,CONCRETE:15)
Block(-7,21,5,CONCRETE:15)
Block(-7,21,8,CONCRETE:15)
Block(-7,22,-5,STAINED_GLASS:15)
Block(-7,22,-4,CONCRETE:8)
Block(-7,22,-3,LEAVES:12)
Block(-7,22,-2,SPRUCE_FENCE:0)
Block(-7,22,-1,LEAVES:4)
Block(-7,22,0,CONCRETE:8)
Block(-7,22,3,CONCRETE:15)
Block(-7,22,5,CONCRETE:15)
Block(-7,22,8,CONCRETE:15)
Block(-7,23,-5,STAINED_GLASS:15)
Block(-7,23,-4,CONCRETE:8)
Block(-7,23,-2,LEAVES:12)
Block(-7,23,0,CONCRETE:8)
Block(-7,23,2,CONCRETE:15)
Block(-7,23,5,CONCRETE:15)
Block(-7,23,8,CONCRETE:15)
Block(-7,24,-5,STAINED_GLASS:15)
Block(-7,24,-4,CONCRETE:8)
Block(-7,24,-1,LEAVES:12)
Block(-7,24,0,CONCRETE:8)
Block(-7,24,1,CONCRETE:15)
Block(-7,24,4,CONCRETE:15)
Block(-7,24,7,CONCRETE:15)
Block(-7,25,-5,STAINED_GLASS:15)
Block(-7,25,-4,CONCRETE:8)
Block(-7,25,0,CONCRETE:8)
Block(-7,25,4,CONCRETE:15)
Block(-7,25,7,CONCRETE:15)
Block(-7,26,-5,STAINED_GLASS:15)
Block(-7,26,-4,CONCRETE:8)
Block(-7,26,0,CONCRETE:8)
Block(-7,26,3,CONCRETE:15)
Block(-7,26,6,CONCRETE:15)
Block(-7,27,-5,STAINED_GLASS:15)
Block(-7,27,-4,CONCRETE:8)
Block(-7,27,-3,CONCRETE:8)
Block(-7,27,-2,CONCRETE:8)
Block(-7,27,-1,CONCRETE:8)
Block(-7,27,0,CONCRETE:8)
Block(-7,27,1,CONCRETE:8)
Block(-7,27,2,CONCRETE:8)
Block(-7,27,3,CONCRETE:8)
Block(-7,27,4,CONCRETE:8)
Block(-7,27,5,CONCRETE:8)
Block(-7,27,6,CONCRETE:8)
Block(-7,27,7,CONCRETE:8)
Block(-7,27,8,CONCRETE:8)
Block(-7,28,-5,STAINED_GLASS:15)
Block(-7,28,-4,CONCRETE:8)
Block(-7,28,-3,STAINED_GLASS_PANE:15)
Block(-7,28,-2,STAINED_GLASS_PANE:15)
Block(-7,28,-1,STAINED_GLASS_PANE:15)
Block(-7,28,0,CONCRETE:8)
Block(-7,28,1,STAINED_GLASS_PANE:15)
Block(-7,28,2,STAINED_GLASS_PANE:15)
Block(-7,28,3,STAINED_GLASS_PANE:15)
Block(-7,28,4,STAINED_GLASS_PANE:15)
Block(-7,28,5,STAINED_GLASS_PANE:15)
Block(-7,28,6,STAINED_GLASS_PANE:15)
Block(-7,28,7,STAINED_GLASS_PANE:15)
Block(-7,28,8,STAINED_GLASS_PANE:15)
Block(-7,29,-5,STAINED_GLASS:15)
Block(-7,29,-4,CONCRETE:8)
Block(-7,29,0,CONCRETE:8)
Block(-7,30,-5,STAINED_GLASS:15)
Block(-7,30,-4,CONCRETE:8)
Block(-7,30,0,CONCRETE:8)
Block(-7,31,-5,STAINED_GLASS:15)
Block(-7,31,-4,CONCRETE:8)
Block(-7,31,0,CONCRETE:8)
Block(-7,32,-5,STAINED_GLASS:15)
Block(-7,32,-4,CONCRETE:8)
Block(-7,32,0,CONCRETE:8)
Block(-7,33,-5,STAINED_GLASS:15)
Block(-7,33,-4,CONCRETE:8)
Block(-7,33,0,CONCRETE:8)
Block(-7,34,-5,STAINED_GLASS:15)
Block(-7,34,-4,CONCRETE:8)
Block(-7,34,0,CONCRETE:8)
Block(-7,35,-5,STAINED_GLASS:15)
Block(-7,35,-4,CONCRETE:8)
Block(-7,35,-3,CONCRETE:8)
Block(-7,35,-2,CONCRETE:8)
Block(-7,35,-1,CONCRETE:8)
Block(-7,35,0,CONCRETE:8)
Block(-7,35,1,CONCRETE:8)
Block(-7,35,2,CONCRETE:8)
Block(-7,35,3,CONCRETE:8)
Block(-7,35,4,CONCRETE:8)
Block(-7,35,5,CONCRETE:8)
Block(-7,35,6,CONCRETE:8)
Block(-7,35,7,CONCRETE:8)
Block(-7,35,8,CONCRETE:8)
Block(-7,36,-5,STAINED_GLASS:15)
Block(-7,36,-4,CONCRETE:8)
Block(-7,36,-3,STAINED_GLASS_PANE:15)
Block(-7,36,-2,STAINED_GLASS_PANE:15)
Block(-7,36,-1,STAINED_GLASS_PANE:15)
Block(-7,36,0,CONCRETE:8)
Block(-7,36,1,STAINED_GLASS_PANE:15)
Block(-7,36,2,STAINED_GLASS_PANE:15)
Block(-7,36,3,STAINED_GLASS_PANE:15)
Block(-7,36,4,STAINED_GLASS_PANE:15)
Block(-7,36,5,STAINED_GLASS_PANE:15)
Block(-7,36,6,STAINED_GLASS_PANE:15)
Block(-7,36,7,STAINED_GLASS_PANE:15)
Block(-7,36,8,STAINED_GLASS_PANE:15)
Block(-7,37,-5,STAINED_GLASS:15)
Block(-7,37,-4,CONCRETE:8)
Block(-7,37,0,CONCRETE:8)
Block(-7,38,-5,STAINED_GLASS:15)
Block(-7,38,-4,CONCRETE:8)
Block(-7,38,0,CONCRETE:8)
Block(-7,39,-5,STAINED_GLASS:15)
Block(-7,39,-4,CONCRETE:8)
Block(-7,39,0,CONCRETE:8)
Block(-7,40,-5,STAINED_GLASS:15)
Block(-7,40,-4,CONCRETE:8)
Block(-7,40,0,CONCRETE:8)
Block(-7,41,-5,STAINED_GLASS:15)
Block(-7,41,-4,CONCRETE:8)
Block(-7,41,0,CONCRETE:8)
Block(-7,42,-5,STAINED_GLASS:15)
Block(-7,42,-4,CONCRETE:8)
Block(-7,42,0,CONCRETE:8)
Block(-7,43,-5,STAINED_GLASS:15)
Block(-7,43,-4,CONCRETE:8)
Block(-7,43,-3,CONCRETE:8)
Block(-7,43,-2,CONCRETE:8)
Block(-7,43,-1,CONCRETE:8)
Block(-7,43,0,CONCRETE:8)
Block(-7,43,1,CONCRETE:8)
Block(-7,43,2,CONCRETE:8)
Block(-7,43,3,CONCRETE:8)
Block(-7,43,4,CONCRETE:8)
Block(-7,43,5,CONCRETE:8)
Block(-7,43,6,CONCRETE:8)
Block(-7,43,7,CONCRETE:8)
Block(-7,43,8,CONCRETE:8)
Block(-7,44,-5,STAINED_GLASS:15)
Block(-7,44,-4,CONCRETE:8)
Block(-7,44,-3,STAINED_GLASS_PANE:15)
Block(-7,44,-2,STAINED_GLASS_PANE:15)
Block(-7,44,-1,STAINED_GLASS_PANE:15)
Block(-7,44,0,CONCRETE:8)
Block(-7,44,1,STAINED_GLASS_PANE:15)
Block(-7,44,2,STAINED_GLASS_PANE:15)
Block(-7,44,3,STAINED_GLASS_PANE:15)
Block(-7,44,4,STAINED_GLASS_PANE:15)
Block(-7,44,5,STAINED_GLASS_PANE:15)
Block(-7,44,6,STAINED_GLASS_PANE:15)
Block(-7,44,7,STAINED_GLASS_PANE:15)
Block(-7,44,8,STAINED_GLASS_PANE:15)
Block(-7,45,-5,STAINED_GLASS:15)
Block(-7,45,-4,CONCRETE:8)
Block(-7,45,0,CONCRETE:8)
Block(-7,46,-5,STAINED_GLASS:15)
Block(-7,46,-4,CONCRETE:8)
Block(-7,46,0,CONCRETE:8)
Block(-7,47,-5,STAINED_GLASS:15)
Block(-7,47,-4,CONCRETE:8)
Block(-7,47,0,CONCRETE:8)
Block(-7,48,-5,STAINED_GLASS:15)
Block(-7,48,-4,CONCRETE:8)
Block(-7,48,0,CONCRETE:8)
Block(-7,49,-5,STAINED_GLASS:15)
Block(-7,49,-4,CONCRETE:8)
Block(-7,49,0,CONCRETE:8)
Block(-7,50,-5,STAINED_GLASS:15)
Block(-7,50,-4,CONCRETE:8)
Block(-7,50,0,CONCRETE:8)
Block(-7,51,-5,STAINED_GLASS:15)
Block(-7,51,-4,CONCRETE:8)
Block(-7,51,-3,CONCRETE:8)
Block(-7,51,-2,CONCRETE:8)
Block(-7,51,-1,CONCRETE:8)
Block(-7,51,0,CONCRETE:8)
Block(-7,51,1,CONCRETE:8)
Block(-7,51,2,CONCRETE:8)
Block(-7,51,3,CONCRETE:8)
Block(-7,51,4,CONCRETE:8)
Block(-7,51,5,CONCRETE:8)
Block(-7,51,6,CONCRETE:8)
Block(-7,51,7,CONCRETE:8)
Block(-7,51,8,CONCRETE:8)
Block(-7,52,-5,STAINED_GLASS:15)
Block(-7,52,-4,CONCRETE:8)
Block(-7,52,-3,STAINED_GLASS_PANE:15)
Block(-7,52,-2,STAINED_GLASS_PANE:15)
Block(-7,52,-1,STAINED_GLASS_PANE:15)
Block(-7,52,0,CONCRETE:8)
Block(-7,52,1,STAINED_GLASS_PANE:15)
Block(-7,52,2,STAINED_GLASS_PANE:15)
Block(-7,52,3,STAINED_GLASS_PANE:15)
Block(-7,52,4,STAINED_GLASS_PANE:15)
Block(-7,52,5,STAINED_GLASS_PANE:15)
Block(-7,52,6,STAINED_GLASS_PANE:15)
Block(-7,52,7,STAINED_GLASS_PANE:15)
Block(-7,52,8,STAINED_GLASS_PANE:15)
Block(-7,53,-5,STAINED_GLASS:15)
Block(-7,53,-4,CONCRETE:8)
Block(-7,53,0,CONCRETE:8)
Block(-7,54,-5,STAINED_GLASS:15)
Block(-7,54,-4,CONCRETE:8)
Block(-7,54,0,CONCRETE:8)
Block(-7,55,-5,STAINED_GLASS:15)
Block(-7,55,-4,CONCRETE:8)
Block(-7,55,0,CONCRETE:8)
Block(-7,56,-5,STAINED_GLASS:15)
Block(-7,56,-4,CONCRETE:8)
Block(-7,56,0,CONCRETE:8)
Block(-7,57,-5,STAINED_GLASS:15)
Block(-7,57,-4,CONCRETE:8)
Block(-7,57,0,CONCRETE:8)
Block(-7,58,-5,STAINED_GLASS:15)
Block(-7,58,-4,CONCRETE:8)
Block(-7,58,0,CONCRETE:8)
Block(-7,59,-5,STAINED_GLASS:15)
Block(-7,59,-4,CONCRETE:8)
Block(-7,59,-3,CONCRETE:8)
Block(-7,59,-2,CONCRETE:8)
Block(-7,59,-1,CONCRETE:8)
Block(-7,59,0,CONCRETE:8)
Block(-7,59,1,CONCRETE:8)
Block(-7,59,2,CONCRETE:8)
Block(-7,59,3,CONCRETE:8)
Block(-7,59,4,CONCRETE:8)
Block(-7,59,5,CONCRETE:8)
Block(-7,59,6,CONCRETE:8)
Block(-7,59,7,CONCRETE:8)
Block(-7,59,8,CONCRETE:8)
Block(-7,60,-5,STAINED_GLASS:15)
Block(-7,60,-4,CONCRETE:8)
Block(-7,60,-3,STAINED_GLASS_PANE:15)
Block(-7,60,-2,STAINED_GLASS_PANE:15)
Block(-7,60,-1,STAINED_GLASS_PANE:15)
Block(-7,60,0,CONCRETE:8)
Block(-7,60,1,STAINED_GLASS_PANE:15)
Block(-7,60,2,STAINED_GLASS_PANE:15)
Block(-7,60,3,STAINED_GLASS_PANE:15)
Block(-7,60,4,STAINED_GLASS_PANE:15)
Block(-7,60,5,STAINED_GLASS_PANE:15)
Block(-7,60,6,STAINED_GLASS_PANE:15)
Block(-7,60,7,STAINED_GLASS_PANE:15)
Block(-7,60,8,STAINED_GLASS_PANE:15)
Block(-7,61,-5,STAINED_GLASS:15)
Block(-7,61,-4,CONCRETE:8)
Block(-7,61,0,CONCRETE:8)
Block(-7,62,-5,STAINED_GLASS:15)
Block(-7,62,-4,CONCRETE:8)
Block(-7,62,0,CONCRETE:8)
Block(-7,63,-5,STAINED_GLASS:15)
Block(-7,63,-4,CONCRETE:8)
Block(-7,63,0,CONCRETE:8)
Block(-7,64,-5,STAINED_GLASS:15)
Block(-7,64,-4,CONCRETE:8)
Block(-7,64,0,CONCRETE:8)
Block(-7,65,-5,STAINED_GLASS:15)
Block(-7,65,-4,CONCRETE:8)
Block(-7,65,0,CONCRETE:8)
Block(-7,66,-5,STAINED_GLASS:15)
Block(-7,66,-4,CONCRETE:8)
Block(-7,66,0,CONCRETE:8)
Block(-7,67,-5,STAINED_GLASS:15)
Block(-7,67,-4,CONCRETE:8)
Block(-7,67,-3,CONCRETE:8)
Block(-7,67,-2,CONCRETE:8)
Block(-7,67,-1,CONCRETE:8)
Block(-7,67,0,CONCRETE:8)
Block(-7,67,1,CONCRETE:8)
Block(-7,67,2,CONCRETE:8)
Block(-7,67,3,CONCRETE:8)
Block(-7,67,4,CONCRETE:8)
Block(-7,67,5,CONCRETE:8)
Block(-7,67,6,CONCRETE:8)
Block(-7,67,7,CONCRETE:8)
Block(-7,67,8,CONCRETE:8)
Block(-7,68,-5,STAINED_GLASS:15)
Block(-7,68,-4,CONCRETE:8)
Block(-7,68,-3,STAINED_GLASS_PANE:15)
Block(-7,68,-2,STAINED_GLASS_PANE:15)
Block(-7,68,-1,STAINED_GLASS_PANE:15)
Block(-7,68,0,CONCRETE:8)
Block(-7,68,1,STAINED_GLASS_PANE:15)
Block(-7,68,2,STAINED_GLASS_PANE:15)
Block(-7,68,3,STAINED_GLASS_PANE:15)
Block(-7,68,4,STAINED_GLASS_PANE:15)
Block(-7,68,5,STAINED_GLASS_PANE:15)
Block(-7,68,6,STAINED_GLASS_PANE:15)
Block(-7,68,7,STAINED_GLASS_PANE:15)
Block(-7,68,8,STAINED_GLASS_PANE:15)
Block(-7,69,-5,STAINED_GLASS:15)
Block(-7,69,-4,CONCRETE:8)
Block(-7,69,0,CONCRETE:8)
Block(-7,70,-5,STAINED_GLASS:15)
Block(-7,70,-4,CONCRETE:8)
Block(-7,70,0,CONCRETE:8)
Block(-7,71,-5,STAINED_GLASS:15)
Block(-7,71,-4,CONCRETE:8)
Block(-7,71,0,CONCRETE:8)
Block(-7,72,-5,STAINED_GLASS:15)
Block(-7,72,-4,CONCRETE:8)
Block(-7,72,0,CONCRETE:8)
Block(-7,73,-5,STAINED_GLASS:15)
Block(-7,73,-4,CONCRETE:8)
Block(-7,73,0,CONCRETE:8)
Block(-7,74,-5,STAINED_GLASS:15)
Block(-7,74,-4,CONCRETE:8)
Block(-7,74,0,CONCRETE:8)
Block(-7,75,-5,STAINED_GLASS:15)
Block(-7,75,-4,CONCRETE:8)
Block(-7,75,-3,CONCRETE:8)
Block(-7,75,-2,CONCRETE:8)
Block(-7,75,-1,CONCRETE:8)
Block(-7,75,0,CONCRETE:8)
Block(-7,75,1,CONCRETE:8)
Block(-7,75,2,CONCRETE:8)
Block(-7,75,3,CONCRETE:8)
Block(-7,75,4,CONCRETE:8)
Block(-7,75,5,CONCRETE:8)
Block(-7,75,6,CONCRETE:8)
Block(-7,75,7,CONCRETE:8)
Block(-7,75,8,CONCRETE:8)
Block(-7,76,-5,STAINED_GLASS:15)
Block(-7,76,-4,CONCRETE:8)
Block(-7,76,-3,STAINED_GLASS_PANE:15)
Block(-7,76,-2,STAINED_GLASS_PANE:15)
Block(-7,76,-1,STAINED_GLASS_PANE:15)
Block(-7,76,0,CONCRETE:8)
Block(-7,76,1,STAINED_GLASS_PANE:15)
Block(-7,76,2,STAINED_GLASS_PANE:15)
Block(-7,76,3,STAINED_GLASS_PANE:15)
Block(-7,76,4,STAINED_GLASS_PANE:15)
Block(-7,76,5,STAINED_GLASS_PANE:15)
Block(-7,76,6,STAINED_GLASS_PANE:15)
Block(-7,76,7,STAINED_GLASS_PANE:15)
Block(-7,76,8,STAINED_GLASS_PANE:15)
Block(-7,77,-5,STAINED_GLASS:15)
Block(-7,77,-4,CONCRETE:8)
Block(-7,77,0,CONCRETE:8)
Block(-7,78,-5,STAINED_GLASS:15)
Block(-7,78,-4,CONCRETE:8)
Block(-7,78,0,CONCRETE:8)
Block(-7,79,-5,STAINED_GLASS:15)
Block(-7,79,-4,CONCRETE:8)
Block(-7,79,0,CONCRETE:8)
Block(-7,80,-5,STAINED_GLASS:15)
Block(-7,80,-4,CONCRETE:8)
Block(-7,80,0,CONCRETE:8)
Block(-7,81,-5,CONCRETE:8)
Block(-7,81,-4,CONCRETE:8)
Block(-7,81,0,CONCRETE:8)
Block(-7,82,-5,CONCRETE:8)
Block(-7,82,-4,CONCRETE:8)
Block(-7,82,-3,CONCRETE:8)
Block(-7,82,-2,CONCRETE:8)
Block(-7,82,-1,CONCRETE:8)
Block(-7,82,0,CONCRETE:8)
Block(-7,83,-5,CONCRETE:8)
Block(-7,83,-4,CONCRETE:8)
Block(-7,83,-3,CONCRETE:8)
Block(-7,83,-2,CONCRETE:8)
Block(-7,83,-1,CONCRETE:8)
Block(-7,83,0,CONCRETE:8)
Block(-7,83,1,CONCRETE:8)
Block(-7,83,2,CONCRETE:8)
Block(-7,83,3,CONCRETE:8)
Block(-7,83,4,CONCRETE:8)
Block(-7,83,5,CONCRETE:8)
Block(-7,83,6,CONCRETE:8)
Block(-7,83,7,CONCRETE:8)
Block(-7,83,8,CONCRETE:8)
Block(-7,84,0,STAINED_GLASS:15)
Block(-7,84,1,STAINED_GLASS_PANE:15)
Block(-7,84,2,STAINED_GLASS_PANE:15)
Block(-7,84,3,STAINED_GLASS_PANE:15)
Block(-7,84,4,STAINED_GLASS_PANE:15)
Block(-7,84,5,STAINED_GLASS_PANE:15)
Block(-7,84,6,STAINED_GLASS_PANE:15)
Block(-7,84,7,STAINED_GLASS_PANE:15)
Block(-7,84,8,STAINED_GLASS_PANE:15)
Block(-7,85,0,STAINED_GLASS:15)
Block(-7,86,0,STAINED_GLASS:15)
Block(-7,87,0,STAINED_GLASS:15)
Block(-7,88,0,STAINED_GLASS:15)
Block(-7,89,0,STAINED_GLASS:15)
Block(-7,90,0,STAINED_GLASS:15)
Block(-7,91,0,STAINED_GLASS:15)
Block(-7,91,1,CONCRETE:8)
Block(-7,91,2,CONCRETE:8)
Block(-7,91,3,CONCRETE:8)
Block(-7,91,4,CONCRETE:8)
Block(-7,91,5,CONCRETE:8)
Block(-7,91,6,CONCRETE:8)
Block(-7,91,7,CONCRETE:8)
Block(-7,91,8,CONCRETE:8)
Block(-7,92,0,STAINED_GLASS:15)
Block(-7,92,1,STAINED_GLASS_PANE:15)
Block(-7,92,2,STAINED_GLASS_PANE:15)
Block(-7,92,3,STAINED_GLASS_PANE:15)
Block(-7,92,4,STAINED_GLASS_PANE:15)
Block(-7,92,5,STAINED_GLASS_PANE:15)
Block(-7,92,6,STAINED_GLASS_PANE:15)
Block(-7,92,7,STAINED_GLASS_PANE:15)
Block(-7,92,8,STAINED_GLASS_PANE:15)
Block(-7,93,0,STAINED_GLASS:15)
Block(-7,94,0,STAINED_GLASS:15)
Block(-7,95,0,STAINED_GLASS:15)
Block(-7,96,0,STAINED_GLASS:15)
Block(-7,97,0,STAINED_GLASS:15)
Block(-7,98,0,STAINED_GLASS:15)
Block(-7,99,0,STAINED_GLASS:15)
Block(-7,99,1,CONCRETE:8)
Block(-7,99,2,CONCRETE:8)
Block(-7,99,3,CONCRETE:8)
Block(-7,99,4,CONCRETE:8)
Block(-7,99,5,CONCRETE:8)
Block(-7,99,6,CONCRETE:8)
Block(-7,99,7,CONCRETE:8)
Block(-7,99,8,CONCRETE:8)
Block(-7,100,0,STAINED_GLASS:15)
Block(-7,100,1,STAINED_GLASS_PANE:15)
Block(-7,100,2,STAINED_GLASS_PANE:15)
Block(-7,100,3,STAINED_GLASS_PANE:15)
Block(-7,100,4,STAINED_GLASS_PANE:15)
Block(-7,100,5,STAINED_GLASS_PANE:15)
Block(-7,100,6,STAINED_GLASS_PANE:15)
Block(-7,100,7,STAINED_GLASS_PANE:15)
Block(-7,100,8,STAINED_GLASS_PANE:15)
Block(-7,101,0,STAINED_GLASS:15)
Block(-7,102,0,STAINED_GLASS:15)
Block(-7,103,0,STAINED_GLASS:15)
Block(-7,104,0,STAINED_GLASS:15)
Block(-7,105,0,STAINED_GLASS:15)
Block(-7,106,0,STAINED_GLASS:15)
Block(-7,107,0,CONCRETE:15)
Block(-7,107,6,CONCRETE:15)
Block(-7,107,7,CONCRETE:8)
Block(-7,107,8,CONCRETE:8)
Block(-7,108,0,CONCRETE:15)
Block(-7,108,1,CONCRETE:15)
Block(-7,108,2,CONCRETE:15)
Block(-7,108,3,CONCRETE:15)
Block(-7,108,4,CONCRETE:15)
Block(-7,108,5,CONCRETE:15)
Block(-7,108,6,CONCRETE:15)
Block(-7,108,7,STAINED_GLASS_PANE:15)
Block(-7,108,8,STAINED_GLASS_PANE:15)
Block(-7,109,0,CONCRETE:15)
Block(-7,109,1,CONCRETE:15)
Block(-7,109,2,CONCRETE:15)
Block(-7,109,3,CONCRETE:15)
Block(-7,109,4,CONCRETE:15)
Block(-7,109,5,CONCRETE:15)
Block(-7,109,6,CONCRETE:15)
Block(-7,110,6,STAINED_GLASS:15)
Block(-7,111,6,STAINED_GLASS:15)
Block(-7,112,6,STAINED_GLASS:15)
Block(-7,113,6,STAINED_GLASS:15)
Block(-7,114,6,STAINED_GLASS:15)
Block(-7,115,6,STAINED_GLASS:15)
Block(-7,115,7,CONCRETE:8)
Block(-7,115,8,CONCRETE:8)
Block(-7,116,6,STAINED_GLASS:15)
Block(-7,116,7,STAINED_GLASS_PANE:15)
Block(-7,116,8,STAINED_GLASS_PANE:15)
Block(-7,117,6,STAINED_GLASS:15)
Block(-7,118,6,STAINED_GLASS:15)
Block(-7,119,6,STAINED_GLASS:15)
Block(-7,120,6,STAINED_GLASS:15)
Block(-7,121,6,STAINED_GLASS:15)
Block(-7,122,6,STAINED_GLASS:15)
Block(-7,123,6,STAINED_GLASS:15)
Block(-7,123,7,CONCRETE:8)
Block(-7,123,8,CONCRETE:8)
Block(-7,124,6,STAINED_GLASS:15)
Block(-7,125,6,STAINED_GLASS:15)
Block(-7,126,6,STAINED_GLASS:15)
Block(-7,127,6,STAINED_GLASS:15)
Block(-7,128,6,STAINED_GLASS:15)
Block(-7,129,6,STAINED_GLASS:15)
Block(-7,130,6,STAINED_GLASS:15)
Block(-7,131,6,STAINED_GLASS:15)
Block(-7,132,6,STAINED_GLASS:15)
Block(-7,133,6,CONCRETE:8)
Block(-7,134,6,CONCRETE:8)
Block(-7,134,7,CONCRETE:8)
Block(-7,134,8,CONCRETE:8)
Block(-7,135,6,CONCRETE:8)
Block(-7,135,7,CONCRETE:8)
Block(-7,135,8,CONCRETE:8)
Block(-6,0,-7,CONCRETE:7)
Block(-6,0,-6,CONCRETE:7)
Block(-6,0,-5,CONCRETE:7)
Block(-6,0,-4,CONCRETE:7)
Block(-6,0,-3,CONCRETE:7)
Block(-6,0,-2,CONCRETE:7)
Block(-6,0,-1,CONCRETE:7)
Block(-6,0,0,CONCRETE:7)
Block(-6,0,1,CONCRETE:7)
Block(-6,0,2,CONCRETE:7)
Block(-6,0,3,CONCRETE:7)
Block(-6,0,4,CONCRETE:7)
Block(-6,0,5,CONCRETE:7)
Block(-6,0,6,CONCRETE:7)
Block(-6,0,7,CONCRETE:7)
Block(-6,0,8,CONCRETE:7)
Block(-6,1,-7,CONCRETE:7)
Block(-6,1,-6,CONCRETE:7)
Block(-6,1,-5,CONCRETE:7)
Block(-6,1,-4,CONCRETE:7)
Block(-6,1,-3,CONCRETE:7)
Block(-6,1,-2,CONCRETE:7)
Block(-6,1,-1,CONCRETE:7)
Block(-6,1,0,CONCRETE:7)
Block(-6,1,1,CONCRETE:7)
Block(-6,1,2,CONCRETE:7)
Block(-6,1,3,STATIONARY_WATER:0)
Block(-6,1,4,STATIONARY_WATER:0)
Block(-6,1,5,CONCRETE:7)
Block(-6,1,6,CONCRETE:7)
Block(-6,1,7,CONCRETE:7)
Block(-6,1,8,CONCRETE:7)
Block(-6,2,-7,SMOOTH_STAIRS:1)
Block(-6,2,-6,SMOOTH_STAIRS:1)
Block(-6,2,-5,SMOOTH_STAIRS:1)
Block(-6,2,-4,SMOOTH_STAIRS:1)
Block(-6,2,-3,SMOOTH_STAIRS:1)
Block(-6,2,-2,SMOOTH_STAIRS:1)
Block(-6,2,-1,SMOOTH_STAIRS:1)
Block(-6,2,0,SMOOTH_STAIRS:1)
Block(-6,2,1,SMOOTH_STAIRS:1)
Block(-6,2,2,SMOOTH_STAIRS:1)
Block(-6,2,3,AIR:0)
Block(-6,2,4,AIR:0)
Block(-6,2,5,SMOOTH_STAIRS:1)
Block(-6,2,6,SMOOTH_STAIRS:1)
Block(-6,2,7,SMOOTH_STAIRS:1)
Block(-6,2,8,SMOOTH_STAIRS:1)
Block(-6,3,-7,AIR:0)
Block(-6,3,-6,AIR:0)
Block(-6,3,-5,AIR:0)
Block(-6,3,-4,AIR:0)
Block(-6,3,-3,AIR:0)
Block(-6,3,-2,AIR:0)
Block(-6,3,-1,AIR:0)
Block(-6,3,0,AIR:0)
Block(-6,3,1,AIR:0)
Block(-6,3,2,AIR:0)
Block(-6,3,3,AIR:0)
Block(-6,3,4,AIR:0)
Block(-6,3,5,AIR:0)
Block(-6,3,6,AIR:0)
Block(-6,3,7,AIR:0)
Block(-6,3,8,AIR:0)
Block(-6,4,-7,AIR:0)
Block(-6,4,-6,AIR:0)
Block(-6,4,-5,AIR:0)
Block(-6,4,-4,AIR:0)
Block(-6,4,-3,AIR:0)
Block(-6,4,-2,AIR:0)
Block(-6,4,-1,AIR:0)
Block(-6,4,0,AIR:0)
Block(-6,4,1,AIR:0)
Block(-6,4,2,AIR:0)
Block(-6,4,3,AIR:0)
Block(-6,4,4,AIR:0)
Block(-6,4,5,AIR:0)
Block(-6,4,6,AIR:0)
Block(-6,4,7,AIR:0)
Block(-6,4,8,AIR:0)
Block(-6,5,-7,AIR:0)
Block(-6,5,-6,AIR:0)
Block(-6,5,-5,AIR:0)
Block(-6,5,-4,AIR:0)
Block(-6,5,-3,AIR:0)
Block(-6,5,-2,AIR:0)
Block(-6,5,-1,AIR:0)
Block(-6,5,0,AIR:0)
Block(-6,5,1,AIR:0)
Block(-6,5,2,AIR:0)
Block(-6,5,3,AIR:0)
Block(-6,5,4,AIR:0)
Block(-6,5,5,AIR:0)
Block(-6,5,6,CONCRETE:12)
Block(-6,5,7,CONCRETE:4)
Block(-6,5,8,AIR:0)
Block(-6,6,-7,CONCRETE:7)
Block(-6,6,-6,AIR:0)
Block(-6,6,-5,AIR:0)
Block(-6,6,-4,AIR:0)
Block(-6,6,-3,AIR:0)
Block(-6,6,-2,AIR:0)
Block(-6,6,-1,AIR:0)
Block(-6,6,0,AIR:0)
Block(-6,6,1,AIR:0)
Block(-6,6,2,AIR:0)
Block(-6,6,3,AIR:0)
Block(-6,6,4,AIR:0)
Block(-6,6,5,AIR:0)
Block(-6,6,6,AIR:0)
Block(-6,6,7,AIR:0)
Block(-6,6,8,AIR:0)
Block(-6,7,-7,CONCRETE:7)
Block(-6,7,-6,CONCRETE:7)
Block(-6,7,-5,CONCRETE:7)
Block(-6,7,-4,CONCRETE:7)
Block(-6,7,-3,CONCRETE:7)
Block(-6,7,-2,CONCRETE:7)
Block(-6,7,-1,CONCRETE:7)
Block(-6,7,0,CONCRETE:7)
Block(-6,7,1,CONCRETE:7)
Block(-6,7,2,CONCRETE:7)
Block(-6,7,3,CONCRETE:7)
Block(-6,7,4,CONCRETE:7)
Block(-6,7,5,CONCRETE:7)
Block(-6,7,6,CONCRETE:7)
Block(-6,7,7,CONCRETE:7)
Block(-6,7,8,CONCRETE:7)
Block(-6,8,-7,CONCRETE:7)
Block(-6,8,-6,CONCRETE:7)
Block(-6,8,-5,CONCRETE:7)
Block(-6,8,-4,CONCRETE:7)
Block(-6,8,-3,CONCRETE:7)
Block(-6,8,-2,CONCRETE:7)
Block(-6,8,-1,CONCRETE:7)
Block(-6,8,0,CONCRETE:7)
Block(-6,8,1,CONCRETE:7)
Block(-6,8,2,CONCRETE:7)
Block(-6,8,3,CONCRETE:7)
Block(-6,8,4,CONCRETE:7)
Block(-6,8,5,CONCRETE:7)
Block(-6,8,6,CONCRETE:7)
Block(-6,8,7,CONCRETE:7)
Block(-6,8,8,CONCRETE:7)
Block(-6,9,-7,CONCRETE:7)
Block(-6,9,-6,CONCRETE:7)
Block(-6,9,-5,CONCRETE:7)
Block(-6,9,-4,CONCRETE:7)
Block(-6,9,-3,CONCRETE:7)
Block(-6,9,-2,CONCRETE:7)
Block(-6,9,-1,CONCRETE:7)
Block(-6,9,0,CONCRETE:7)
Block(-6,9,1,CONCRETE:7)
Block(-6,9,2,CONCRETE:7)
Block(-6,9,3,CONCRETE:7)
Block(-6,9,4,CONCRETE:7)
Block(-6,9,5,CONCRETE:7)
Block(-6,9,6,CONCRETE:7)
Block(-6,9,7,CONCRETE:7)
Block(-6,9,8,CONCRETE:7)
Block(-6,10,-7,CONCRETE:7)
Block(-6,10,-6,CONCRETE:7)
Block(-6,10,-5,CONCRETE:7)
Block(-6,10,-4,CONCRETE:7)
Block(-6,10,-3,AIR:0)
Block(-6,10,-2,AIR:0)
Block(-6,10,-1,CONCRETE:7)
Block(-6,10,0,CONCRETE:7)
Block(-6,10,1,QUARTZ_STAIRS:3)
Block(-6,10,2,IRON_TRAPDOOR:5)
Block(-6,10,3,QUARTZ_STAIRS:2)
Block(-6,10,4,CONCRETE:7)
Block(-6,10,5,CONCRETE:7)
Block(-6,10,6,CONCRETE:7)
Block(-6,10,7,CONCRETE:7)
Block(-6,10,8,AIR:0)
Block(-6,11,-7,CONCRETE:7)
Block(-6,11,-6,CONCRETE:7)
Block(-6,11,-5,CONCRETE:7)
Block(-6,11,-4,CONCRETE:7)
Block(-6,11,-3,AIR:0)
Block(-6,11,-2,AIR:0)
Block(-6,11,-1,CONCRETE:7)
Block(-6,11,0,CONCRETE:7)
Block(-6,11,1,IRON_TRAPDOOR:8)
Block(-6,11,2,CONCRETE:14)
Block(-6,11,3,IRON_TRAPDOOR:1)
Block(-6,11,4,CONCRETE:7)
Block(-6,11,5,CONCRETE:7)
Block(-6,11,6,CONCRETE:7)
Block(-6,11,7,CONCRETE:7)
Block(-6,11,8,AIR:0)
Block(-6,12,-7,CONCRETE:7)
Block(-6,12,-6,CONCRETE:7)
Block(-6,12,-5,CONCRETE:7)
Block(-6,12,-4,CONCRETE:7)
Block(-6,12,-3,AIR:0)
Block(-6,12,-2,AIR:0)
Block(-6,12,-1,CONCRETE:7)
Block(-6,12,0,CONCRETE:7)
Block(-6,12,1,QUARTZ_STAIRS:7)
Block(-6,12,2,IRON_TRAPDOOR:4)
Block(-6,12,3,QUARTZ_STAIRS:6)
Block(-6,12,4,CONCRETE:7)
Block(-6,12,5,CONCRETE:7)
Block(-6,12,6,CONCRETE:7)
Block(-6,12,7,CONCRETE:7)
Block(-6,12,8,AIR:0)
Block(-6,13,-7,CONCRETE:7)
Block(-6,13,-6,CONCRETE:7)
Block(-6,13,-5,CONCRETE:7)
Block(-6,13,-4,CONCRETE:7)
Block(-6,13,-3,SMOOTH_STAIRS:4)
Block(-6,13,-2,SMOOTH_STAIRS:4)
Block(-6,13,-1,CONCRETE:7)
Block(-6,13,0,CONCRETE:7)
Block(-6,13,1,CONCRETE:7)
Block(-6,13,2,CONCRETE:7)
Block(-6,13,3,CONCRETE:7)
Block(-6,13,4,CONCRETE:7)
Block(-6,13,5,CONCRETE:7)
Block(-6,13,6,CONCRETE:7)
Block(-6,13,7,CONCRETE:7)
Block(-6,13,8,AIR:0)
Block(-6,14,-7,CONCRETE:7)
Block(-6,14,-6,CONCRETE:7)
Block(-6,14,-5,CONCRETE:7)
Block(-6,14,-4,CONCRETE:7)
Block(-6,14,-3,CONCRETE:7)
Block(-6,14,-2,CONCRETE:7)
Block(-6,14,-1,CONCRETE:7)
Block(-6,14,0,CONCRETE:7)
Block(-6,14,1,QUARTZ_STAIRS:3)
Block(-6,14,2,IRON_TRAPDOOR:5)
Block(-6,14,3,QUARTZ_STAIRS:2)
Block(-6,14,4,CONCRETE:7)
Block(-6,14,5,CONCRETE:7)
Block(-6,14,6,CONCRETE:7)
Block(-6,14,7,CONCRETE:7)
Block(-6,14,8,CONCRETE:7)
Block(-6,15,-7,CONCRETE:7)
Block(-6,15,-6,CONCRETE:7)
Block(-6,15,-5,CONCRETE:7)
Block(-6,15,-4,CONCRETE:7)
Block(-6,15,-3,CONCRETE:7)
Block(-6,15,-2,CONCRETE:7)
Block(-6,15,-1,CONCRETE:7)
Block(-6,15,0,CONCRETE:7)
Block(-6,15,1,IRON_TRAPDOOR:8)
Block(-6,15,2,CONCRETE:14)
Block(-6,15,3,IRON_TRAPDOOR:1)
Block(-6,15,4,CONCRETE:7)
Block(-6,15,5,CONCRETE:7)
Block(-6,15,6,CONCRETE:7)
Block(-6,15,7,CONCRETE:7)
Block(-6,15,8,CONCRETE:7)
Block(-6,16,-7,CONCRETE:7)
Block(-6,16,-6,CONCRETE:7)
Block(-6,16,-5,CONCRETE:7)
Block(-6,16,-4,CONCRETE:7)
Block(-6,16,-3,CONCRETE:7)
Block(-6,16,-2,CONCRETE:7)
Block(-6,16,-1,CONCRETE:7)
Block(-6,16,0,CONCRETE:7)
Block(-6,16,1,QUARTZ_STAIRS:7)
Block(-6,16,2,IRON_TRAPDOOR:4)
Block(-6,16,3,QUARTZ_STAIRS:6)
Block(-6,16,4,CONCRETE:7)
Block(-6,16,5,CONCRETE:7)
Block(-6,16,6,CONCRETE:7)
Block(-6,16,7,CONCRETE:7)
Block(-6,16,8,CONCRETE:7)
Block(-6,17,-7,CONCRETE:7)
Block(-6,17,-6,CONCRETE:7)
Block(-6,17,-5,CONCRETE:7)
Block(-6,17,-4,CONCRETE:7)
Block(-6,17,-3,CONCRETE:7)
Block(-6,17,-2,CONCRETE:7)
Block(-6,17,-1,CONCRETE:7)
Block(-6,17,0,CONCRETE:7)
Block(-6,17,1,CONCRETE:7)
Block(-6,17,2,CONCRETE:7)
Block(-6,17,3,CONCRETE:7)
Block(-6,17,4,CONCRETE:7)
Block(-6,17,5,CONCRETE:7)
Block(-6,17,6,CONCRETE:7)
Block(-6,17,7,CONCRETE:7)
Block(-6,17,8,CONCRETE:7)
Block(-6,18,-5,CONCRETE:8)
Block(-6,18,-4,DIRT:2)
Block(-6,18,-3,DIRT:2)
Block(-6,18,-2,DIRT:2)
Block(-6,18,-1,DIRT:2)
Block(-6,18,0,CONCRETE:15)
Block(-6,18,1,CONCRETE:15)
Block(-6,18,2,CONCRETE:15)
Block(-6,18,3,CONCRETE:15)
Block(-6,18,4,CONCRETE:15)
Block(-6,18,5,CONCRETE:15)
Block(-6,18,6,CONCRETE:15)
Block(-6,18,7,CONCRETE:8)
Block(-6,18,8,CONCRETE:8)
Block(-6,19,-5,STAINED_GLASS:15)
Block(-6,19,-4,LONG_GRASS:1)
Block(-6,19,-3,RED_MUSHROOM:0)
Block(-6,19,-2,LONG_GRASS:1)
Block(-6,19,-1,DOUBLE_PLANT:5)
Block(-6,19,0,CONCRETE:8)
Block(-6,19,1,CONCRETE:8)
Block(-6,19,2,CONCRETE:8)
Block(-6,19,3,CONCRETE:8)
Block(-6,19,4,CONCRETE:8)
Block(-6,19,5,CONCRETE:8)
Block(-6,19,6,CONCRETE:8)
Block(-6,19,7,CONCRETE:8)
Block(-6,19,8,CONCRETE:8)
Block(-6,20,-5,STAINED_GLASS:15)
Block(-6,20,-1,DOUBLE_PLANT:10)
Block(-6,20,0,CONCRETE:8)
Block(-6,20,1,CONCRETE:8)
Block(-6,20,2,CONCRETE:8)
Block(-6,20,3,CONCRETE:8)
Block(-6,20,4,CONCRETE:8)
Block(-6,20,5,CONCRETE:8)
Block(-6,20,6,CONCRETE:8)
Block(-6,20,7,CONCRETE:8)
Block(-6,20,8,CONCRETE:8)
Block(-6,21,-5,STAINED_GLASS:15)
Block(-6,21,0,CONCRETE:8)
Block(-6,21,1,CONCRETE:8)
Block(-6,21,2,CONCRETE:8)
Block(-6,21,3,CONCRETE:8)
Block(-6,21,4,CONCRETE:8)
Block(-6,21,5,CONCRETE:8)
Block(-6,21,6,CONCRETE:8)
Block(-6,21,7,CONCRETE:8)
Block(-6,21,8,CONCRETE:8)
Block(-6,22,-5,STAINED_GLASS:15)
Block(-6,22,-2,LOG:5)
Block(-6,22,-1,LEAVES:4)
Block(-6,22,0,CONCRETE:8)
Block(-6,22,1,CONCRETE:8)
Block(-6,22,2,CONCRETE:8)
Block(-6,22,3,CONCRETE:8)
Block(-6,22,4,CONCRETE:8)
Block(-6,22,5,CONCRETE:8)
Block(-6,22,6,CONCRETE:8)
Block(-6,22,7,CONCRETE:8)
Block(-6,22,8,CONCRETE:8)
Block(-6,23,-5,STAINED_GLASS:15)
Block(-6,23,-4,LEAVES:12)
Block(-6,23,-3,LEAVES:12)
Block(-6,23,-2,LEAVES:12)
Block(-6,23,0,CONCRETE:8)
Block(-6,23,1,CONCRETE:8)
Block(-6,23,2,CONCRETE:8)
Block(-6,23,3,CONCRETE:8)
Block(-6,23,4,CONCRETE:8)
Block(-6,23,5,CONCRETE:8)
Block(-6,23,6,CONCRETE:8)
Block(-6,23,7,CONCRETE:8)
Block(-6,23,8,CONCRETE:8)
Block(-6,24,-5,STAINED_GLASS:15)
Block(-6,24,-3,LEAVES:4)
Block(-6,24,-2,LEAVES:12)
Block(-6,24,-1,LEAVES:4)
Block(-6,24,0,CONCRETE:8)
Block(-6,24,1,CONCRETE:8)
Block(-6,24,2,CONCRETE:8)
Block(-6,24,3,CONCRETE:8)
Block(-6,24,4,CONCRETE:8)
Block(-6,24,5,CONCRETE:8)
Block(-6,24,6,CONCRETE:8)
Block(-6,24,7,CONCRETE:8)
Block(-6,24,8,CONCRETE:8)
Block(-6,25,-5,STAINED_GLASS:15)
Block(-6,25,-2,LEAVES:12)
Block(-6,25,0,CONCRETE:8)
Block(-6,25,1,CONCRETE:8)
Block(-6,25,2,CONCRETE:8)
Block(-6,25,3,CONCRETE:8)
Block(-6,25,4,CONCRETE:8)
Block(-6,25,5,CONCRETE:8)
Block(-6,25,6,CONCRETE:8)
Block(-6,25,7,CONCRETE:8)
Block(-6,25,8,CONCRETE:8)
Block(-6,26,-5,STAINED_GLASS:15)
Block(-6,26,0,CONCRETE:8)
Block(-6,26,1,CONCRETE:8)
Block(-6,26,2,CONCRETE:8)
Block(-6,26,3,CONCRETE:8)
Block(-6,26,4,CONCRETE:8)
Block(-6,26,5,CONCRETE:8)
Block(-6,26,6,CONCRETE:8)
Block(-6,26,7,CONCRETE:8)
Block(-6,26,8,CONCRETE:8)
Block(-6,27,-5,STAINED_GLASS:15)
Block(-6,27,-4,CONCRETE:8)
Block(-6,27,-3,CONCRETE:8)
Block(-6,27,-2,CONCRETE:8)
Block(-6,27,-1,CONCRETE:8)
Block(-6,27,0,CONCRETE:8)
Block(-6,27,1,CONCRETE:8)
Block(-6,27,2,CONCRETE:8)
Block(-6,27,3,CONCRETE:8)
Block(-6,27,4,CONCRETE:8)
Block(-6,27,5,CONCRETE:8)
Block(-6,27,6,CONCRETE:8)
Block(-6,27,7,CONCRETE:8)
Block(-6,27,8,CONCRETE:8)
Block(-6,28,-5,STAINED_GLASS:15)
Block(-6,28,-4,DISPENSER:3,NBT/skyscraper_2x2_04/331-dispenserC16R0.nbt)
Block(-6,28,-3,TRIPWIRE_HOOK:0)
Block(-6,29,-5,STAINED_GLASS:15)
Block(-6,29,-4,DISPENSER:3,NBT/skyscraper_2x2_04/332-dispenserC16R0.nbt)
Block(-6,29,-3,WALL_BANNER:3,NBT/skyscraper_2x2_04/333-bannerC16R0.nbt)
Block(-6,30,-5,STAINED_GLASS:15)
Block(-6,30,-4,IRON_TRAPDOOR:1)
Block(-6,31,-5,STAINED_GLASS:15)
Block(-6,32,-5,STAINED_GLASS:15)
Block(-6,33,-5,STAINED_GLASS:15)
Block(-6,34,-5,STAINED_GLASS:15)
Block(-6,35,-5,STAINED_GLASS:15)
Block(-6,35,-4,CONCRETE:8)
Block(-6,35,-3,CONCRETE:8)
Block(-6,35,-2,CONCRETE:8)
Block(-6,35,-1,CONCRETE:8)
Block(-6,35,0,CONCRETE:8)
Block(-6,35,1,CONCRETE:8)
Block(-6,35,2,CONCRETE:8)
Block(-6,35,3,CONCRETE:8)
Block(-6,35,4,CONCRETE:8)
Block(-6,35,5,CONCRETE:8)
Block(-6,35,6,CONCRETE:8)
Block(-6,35,7,CONCRETE:8)
Block(-6,35,8,CONCRETE:8)
Block(-6,36,-5,STAINED_GLASS:15)
Block(-6,36,-4,DISPENSER:3,NBT/skyscraper_2x2_04/334-dispenserC16R0.nbt)
Block(-6,36,-3,TRIPWIRE_HOOK:0)
Block(-6,37,-5,STAINED_GLASS:15)
Block(-6,37,-4,DISPENSER:3,NBT/skyscraper_2x2_04/335-dispenserC16R0.nbt)
Block(-6,37,-3,WALL_BANNER:3,NBT/skyscraper_2x2_04/336-bannerC16R0.nbt)
Block(-6,38,-5,STAINED_GLASS:15)
Block(-6,38,-4,IRON_TRAPDOOR:1)
Block(-6,39,-5,STAINED_GLASS:15)
Block(-6,40,-5,STAINED_GLASS:15)
Block(-6,41,-5,STAINED_GLASS:15)
Block(-6,42,-5,STAINED_GLASS:15)
Block(-6,43,-5,STAINED_GLASS:15)
Block(-6,43,-4,CONCRETE:8)
Block(-6,43,-3,CONCRETE:8)
Block(-6,43,-2,CONCRETE:8)
Block(-6,43,-1,CONCRETE:8)
Block(-6,43,0,CONCRETE:8)
Block(-6,43,1,CONCRETE:8)
Block(-6,43,2,CONCRETE:8)
Block(-6,43,3,CONCRETE:8)
Block(-6,43,4,CONCRETE:8)
Block(-6,43,5,CONCRETE:8)
Block(-6,43,6,CONCRETE:8)
Block(-6,43,7,CONCRETE:8)
Block(-6,43,8,CONCRETE:8)
Block(-6,44,-5,STAINED_GLASS:15)
Block(-6,44,-4,DISPENSER:3,NBT/skyscraper_2x2_04/337-dispenserC16R0.nbt)
Block(-6,44,-3,TRIPWIRE_HOOK:0)
Block(-6,45,-5,STAINED_GLASS:15)
Block(-6,45,-4,DISPENSER:3,NBT/skyscraper_2x2_04/338-dispenserC16R0.nbt)
Block(-6,45,-3,WALL_BANNER:3,NBT/skyscraper_2x2_04/339-bannerC16R0.nbt)
Block(-6,46,-5,STAINED_GLASS:15)
Block(-6,46,-4,IRON_TRAPDOOR:1)
Block(-6,47,-5,STAINED_GLASS:15)
Block(-6,48,-5,STAINED_GLASS:15)
Block(-6,49,-5,STAINED_GLASS:15)
Block(-6,50,-5,STAINED_GLASS:15)
Block(-6,51,-5,STAINED_GLASS:15)
Block(-6,51,-4,CONCRETE:8)
Block(-6,51,-3,CONCRETE:8)
Block(-6,51,-2,CONCRETE:8)
Block(-6,51,-1,CONCRETE:8)
Block(-6,51,0,CONCRETE:8)
Block(-6,51,1,CONCRETE:8)
Block(-6,51,2,CONCRETE:8)
Block(-6,51,3,CONCRETE:8)
Block(-6,51,4,CONCRETE:8)
Block(-6,51,5,CONCRETE:8)
Block(-6,51,6,CONCRETE:8)
Block(-6,51,7,CONCRETE:8)
Block(-6,51,8,CONCRETE:8)
Block(-6,52,-5,STAINED_GLASS:15)
Block(-6,52,-4,DISPENSER:3,NBT/skyscraper_2x2_04/340-dispenserC16R0.nbt)
Block(-6,52,-3,TRIPWIRE_HOOK:0)
Block(-6,53,-5,STAINED_GLASS:15)
Block(-6,53,-4,DISPENSER:3,NBT/skyscraper_2x2_04/341-dispenserC16R0.nbt)
Block(-6,53,-3,WALL_BANNER:3,NBT/skyscraper_2x2_04/342-bannerC16R0.nbt)
Block(-6,54,-5,STAINED_GLASS:15)
Block(-6,54,-4,IRON_TRAPDOOR:1)
Block(-6,55,-5,STAINED_GLASS:15)
Block(-6,56,-5,STAINED_GLASS:15)
Block(-6,57,-5,STAINED_GLASS:15)
Block(-6,58,-5,STAINED_GLASS:15)
Block(-6,59,-5,STAINED_GLASS:15)
Block(-6,59,-4,CONCRETE:8)
Block(-6,59,-3,CONCRETE:8)
Block(-6,59,-2,CONCRETE:8)
Block(-6,59,-1,CONCRETE:8)
Block(-6,59,0,CONCRETE:8)
Block(-6,59,1,CONCRETE:8)
Block(-6,59,2,CONCRETE:8)
Block(-6,59,3,CONCRETE:8)
Block(-6,59,4,CONCRETE:8)
Block(-6,59,5,CONCRETE:8)
Block(-6,59,6,CONCRETE:8)
Block(-6,59,7,CONCRETE:8)
Block(-6,59,8,CONCRETE:8)
Block(-6,60,-5,STAINED_GLASS:15)
Block(-6,60,-4,DISPENSER:3,NBT/skyscraper_2x2_04/343-dispenserC16R0.nbt)
Block(-6,60,-3,TRIPWIRE_HOOK:0)
Block(-6,61,-5,STAINED_GLASS:15)
Block(-6,61,-4,DISPENSER:3,NBT/skyscraper_2x2_04/344-dispenserC16R0.nbt)
Block(-6,61,-3,WALL_BANNER:3,NBT/skyscraper_2x2_04/345-bannerC16R0.nbt)
Block(-6,62,-5,STAINED_GLASS:15)
Block(-6,62,-4,IRON_TRAPDOOR:1)
Block(-6,63,-5,STAINED_GLASS:15)
Block(-6,64,-5,STAINED_GLASS:15)
Block(-6,65,-5,STAINED_GLASS:15)
Block(-6,66,-5,STAINED_GLASS:15)
Block(-6,67,-5,STAINED_GLASS:15)
Block(-6,67,-4,CONCRETE:8)
Block(-6,67,-3,CONCRETE:8)
Block(-6,67,-2,CONCRETE:8)
Block(-6,67,-1,CONCRETE:8)
Block(-6,67,0,CONCRETE:8)
Block(-6,67,1,CONCRETE:8)
Block(-6,67,2,CONCRETE:8)
Block(-6,67,3,CONCRETE:8)
Block(-6,67,4,CONCRETE:8)
Block(-6,67,5,CONCRETE:8)
Block(-6,67,6,CONCRETE:8)
Block(-6,67,7,CONCRETE:8)
Block(-6,67,8,CONCRETE:8)
Block(-6,68,-5,STAINED_GLASS:15)
Block(-6,68,-4,DISPENSER:3,NBT/skyscraper_2x2_04/346-dispenserC16R0.nbt)
Block(-6,68,-3,TRIPWIRE_HOOK:0)
Block(-6,69,-5,STAINED_GLASS:15)
Block(-6,69,-4,DISPENSER:3,NBT/skyscraper_2x2_04/347-dispenserC16R0.nbt)
Block(-6,69,-3,WALL_BANNER:3,NBT/skyscraper_2x2_04/348-bannerC16R0.nbt)
Block(-6,70,-5,STAINED_GLASS:15)
Block(-6,70,-4,IRON_TRAPDOOR:1)
Block(-6,71,-5,STAINED_GLASS:15)
Block(-6,72,-5,STAINED_GLASS:15)
Block(-6,73,-5,STAINED_GLASS:15)
Block(-6,74,-5,STAINED_GLASS:15)
Block(-6,75,-5,STAINED_GLASS:15)
Block(-6,75,-4,CONCRETE:8)
Block(-6,75,-3,CONCRETE:8)
Block(-6,75,-2,CONCRETE:8)
Block(-6,75,-1,CONCRETE:8)
Block(-6,75,0,CONCRETE:8)
Block(-6,75,1,CONCRETE:8)
Block(-6,75,2,CONCRETE:8)
Block(-6,75,3,CONCRETE:8)
Block(-6,75,4,CONCRETE:8)
Block(-6,75,5,CONCRETE:8)
Block(-6,75,6,CONCRETE:8)
Block(-6,75,7,CONCRETE:8)
Block(-6,75,8,CONCRETE:8)
Block(-6,76,-5,STAINED_GLASS:15)
Block(-6,76,-4,DISPENSER:3,NBT/skyscraper_2x2_04/349-dispenserC16R0.nbt)
Block(-6,76,-3,TRIPWIRE_HOOK:0)
Block(-6,77,-5,STAINED_GLASS:15)
Block(-6,77,-4,DISPENSER:3,NBT/skyscraper_2x2_04/350-dispenserC16R0.nbt)
Block(-6,77,-3,WALL_BANNER:3,NBT/skyscraper_2x2_04/351-bannerC16R0.nbt)
Block(-6,78,-5,STAINED_GLASS:15)
Block(-6,78,-4,IRON_TRAPDOOR:1)
Block(-6,79,-5,STAINED_GLASS:15)
Block(-6,80,-5,CONCRETE:8)
Block(-6,80,0,CONCRETE:8)
Block(-6,81,-5,CONCRETE:8)
Block(-6,81,-4,CONCRETE:8)
Block(-6,81,-3,CONCRETE:8)
Block(-6,81,-2,CONCRETE:8)
Block(-6,81,-1,CONCRETE:8)
Block(-6,81,0,CONCRETE:8)
Block(-6,82,-5,CONCRETE:8)
Block(-6,82,-4,CONCRETE:8)
Block(-6,82,-3,CONCRETE:8)
Block(-6,82,-2,CONCRETE:8)
Block(-6,82,-1,CONCRETE:8)
Block(-6,82,0,CONCRETE:8)
Block(-6,83,0,STAINED_GLASS:15)
Block(-6,83,1,CONCRETE:8)
Block(-6,83,2,CONCRETE:8)
Block(-6,83,3,CONCRETE:8)
Block(-6,83,4,CONCRETE:8)
Block(-6,83,5,CONCRETE:8)
Block(-6,83,6,CONCRETE:8)
Block(-6,83,7,CONCRETE:8)
Block(-6,83,8,CONCRETE:8)
Block(-6,84,0,STAINED_GLASS:15)
Block(-6,85,0,STAINED_GLASS:15)
Block(-6,86,0,STAINED_GLASS:15)
Block(-6,87,0,STAINED_GLASS:15)
Block(-6,88,0,STAINED_GLASS:15)
Block(-6,89,0,STAINED_GLASS:15)
Block(-6,90,0,STAINED_GLASS:15)
Block(-6,91,0,STAINED_GLASS:15)
Block(-6,91,1,CONCRETE:8)
Block(-6,91,2,CONCRETE:8)
Block(-6,91,3,CONCRETE:8)
Block(-6,91,4,CONCRETE:8)
Block(-6,91,5,CONCRETE:8)
Block(-6,91,6,CONCRETE:8)
Block(-6,91,7,CONCRETE:8)
Block(-6,91,8,CONCRETE:8)
Block(-6,92,0,STAINED_GLASS:15)
Block(-6,93,0,STAINED_GLASS:15)
Block(-6,94,0,STAINED_GLASS:15)
Block(-6,95,0,STAINED_GLASS:15)
Block(-6,96,0,STAINED_GLASS:15)
Block(-6,97,0,STAINED_GLASS:15)
Block(-6,98,0,STAINED_GLASS:15)
Block(-6,99,0,STAINED_GLASS:15)
Block(-6,99,1,CONCRETE:8)
Block(-6,99,2,CONCRETE:8)
Block(-6,99,3,CONCRETE:8)
Block(-6,99,4,CONCRETE:8)
Block(-6,99,5,CONCRETE:8)
Block(-6,99,6,CONCRETE:8)
Block(-6,99,7,CONCRETE:8)
Block(-6,99,8,CONCRETE:8)
Block(-6,100,0,STAINED_GLASS:15)
Block(-6,101,0,STAINED_GLASS:15)
Block(-6,102,0,STAINED_GLASS:15)
Block(-6,103,0,STAINED_GLASS:15)
Block(-6,104,0,STAINED_GLASS:15)
Block(-6,105,0,STAINED_GLASS:15)
Block(-6,106,0,CONCRETE:15)
Block(-6,106,6,CONCRETE:15)
Block(-6,107,0,CONCRETE:15)
Block(-6,107,1,CONCRETE:15)
Block(-6,107,2,CONCRETE:15)
Block(-6,107,3,CONCRETE:15)
Block(-6,107,4,CONCRETE:15)
Block(-6,107,5,CONCRETE:15)
Block(-6,107,6,CONCRETE:15)
Block(-6,107,7,CONCRETE:8)
Block(-6,107,8,CONCRETE:8)
Block(-6,108,0,CONCRETE:15)
Block(-6,108,1,CONCRETE:15)
Block(-6,108,2,CONCRETE:15)
Block(-6,108,3,CONCRETE:15)
Block(-6,108,4,CONCRETE:15)
Block(-6,108,5,CONCRETE:15)
Block(-6,108,6,CONCRETE:15)
Block(-6,109,6,STAINED_GLASS:15)
Block(-6,110,6,STAINED_GLASS:15)
Block(-6,111,6,STAINED_GLASS:15)
Block(-6,112,6,STAINED_GLASS:15)
Block(-6,113,6,STAINED_GLASS:15)
Block(-6,114,6,STAINED_GLASS:15)
Block(-6,115,6,STAINED_GLASS:15)
Block(-6,115,7,CONCRETE:8)
Block(-6,115,8,CONCRETE:8)
Block(-6,116,6,STAINED_GLASS:15)
Block(-6,117,6,STAINED_GLASS:15)
Block(-6,118,6,STAINED_GLASS:15)
Block(-6,119,6,STAINED_GLASS:15)
Block(-6,120,6,STAINED_GLASS:15)
Block(-6,121,6,STAINED_GLASS:15)
Block(-6,122,6,STAINED_GLASS:15)
Block(-6,122,7,QUARTZ_STAIRS:4)
Block(-6,123,6,STAINED_GLASS:15)
Block(-6,123,7,QUARTZ_STAIRS:1)
Block(-6,123,8,CONCRETE:8)
Block(-6,124,6,STAINED_GLASS:15)
Block(-6,125,6,STAINED_GLASS:15)
Block(-6,126,6,STAINED_GLASS:15)
Block(-6,127,6,STAINED_GLASS:15)
Block(-6,128,6,STAINED_GLASS:15)
Block(-6,129,6,STAINED_GLASS:15)
Block(-6,130,6,STAINED_GLASS:15)
Block(-6,131,6,STAINED_GLASS:15)
Block(-6,132,6,STAINED_GLASS:15)
Block(-6,133,6,STAINED_GLASS:15)
Block(-6,134,6,CONCRETE:8)
Block(-6,135,6,CONCRETE:8)
Block(-6,135,7,CONCRETE:8)
Block(-6,135,8,CONCRETE:8)
Block(-6,136,6,CONCRETE:8)
Block(-6,136,7,CONCRETE:8)
Block(-6,136,8,CONCRETE:8)
Block(-5,0,-7,CONCRETE:7)
Block(-5,0,-6,CONCRETE:7)
Block(-5,0,-5,CONCRETE:7)
Block(-5,0,-4,CONCRETE:7)
Block(-5,0,-3,CONCRETE:7)
Block(-5,0,-2,CONCRETE:7)
Block(-5,0,-1,CONCRETE:7)
Block(-5,0,0,CONCRETE:7)
Block(-5,0,1,CONCRETE:7)
Block(-5,0,2,CONCRETE:7)
Block(-5,0,3,CONCRETE:7)
Block(-5,0,4,CONCRETE:7)
Block(-5,0,5,CONCRETE:7)
Block(-5,0,6,CONCRETE:7)
Block(-5,0,7,CONCRETE:7)
Block(-5,0,8,CONCRETE:7)
Block(-5,1,-7,STATIONARY_WATER:0)
Block(-5,1,-6,STATIONARY_WATER:0)
Block(-5,1,-5,STATIONARY_WATER:0)
Block(-5,1,-4,STATIONARY_WATER:0)
Block(-5,1,-3,STATIONARY_WATER:0)
Block(-5,1,-2,STATIONARY_WATER:0)
Block(-5,1,-1,STATIONARY_WATER:0)
Block(-5,1,0,STATIONARY_WATER:0)
Block(-5,1,1,STATIONARY_WATER:0)
Block(-5,1,2,STATIONARY_WATER:0)
Block(-5,1,3,STATIONARY_WATER:0)
Block(-5,1,4,STATIONARY_WATER:0)
Block(-5,1,5,STATIONARY_WATER:0)
Block(-5,1,6,STATIONARY_WATER:0)
Block(-5,1,7,STATIONARY_WATER:0)
Block(-5,1,8,STATIONARY_WATER:0)
Block(-5,2,-7,AIR:0)
Block(-5,2,-6,AIR:0)
Block(-5,2,-5,AIR:0)
Block(-5,2,-4,AIR:0)
Block(-5,2,-3,AIR:0)
Block(-5,2,-2,AIR:0)
Block(-5,2,-1,AIR:0)
Block(-5,2,0,AIR:0)
Block(-5,2,1,AIR:0)
Block(-5,2,2,AIR:0)
Block(-5,2,3,AIR:0)
Block(-5,2,4,AIR:0)
Block(-5,2,5,AIR:0)
Block(-5,2,6,AIR:0)
Block(-5,2,7,AIR:0)
Block(-5,2,8,AIR:0)
Block(-5,3,-7,AIR:0)
Block(-5,3,-6,AIR:0)
Block(-5,3,-5,AIR:0)
Block(-5,3,-4,AIR:0)
Block(-5,3,-3,AIR:0)
Block(-5,3,-2,AIR:0)
Block(-5,3,-1,AIR:0)
Block(-5,3,0,AIR:0)
Block(-5,3,1,AIR:0)
Block(-5,3,2,AIR:0)
Block(-5,3,3,AIR:0)
Block(-5,3,4,AIR:0)
Block(-5,3,5,AIR:0)
Block(-5,3,6,AIR:0)
Block(-5,3,7,AIR:0)
Block(-5,3,8,AIR:0)
Block(-5,4,-7,AIR:0)
Block(-5,4,-6,AIR:0)
Block(-5,4,-5,AIR:0)
Block(-5,4,-4,AIR:0)
Block(-5,4,-3,AIR:0)
Block(-5,4,-2,AIR:0)
Block(-5,4,-1,AIR:0)
Block(-5,4,0,AIR:0)
Block(-5,4,1,AIR:0)
Block(-5,4,2,AIR:0)
Block(-5,4,3,AIR:0)
Block(-5,4,4,AIR:0)
Block(-5,4,5,AIR:0)
Block(-5,4,6,AIR:0)
Block(-5,4,7,AIR:0)
Block(-5,4,8,AIR:0)
Block(-5,5,-7,AIR:0)
Block(-5,5,-6,AIR:0)
Block(-5,5,-5,AIR:0)
Block(-5,5,-4,AIR:0)
Block(-5,5,-3,AIR:0)
Block(-5,5,-2,AIR:0)
Block(-5,5,-1,AIR:0)
Block(-5,5,0,AIR:0)
Block(-5,5,1,AIR:0)
Block(-5,5,2,AIR:0)
Block(-5,5,3,AIR:0)
Block(-5,5,4,AIR:0)
Block(-5,5,5,AIR:0)
Block(-5,5,6,CONCRETE:12)
Block(-5,5,7,CONCRETE:4)
Block(-5,5,8,AIR:0)
Block(-5,6,-7,CONCRETE:7)
Block(-5,6,-6,AIR:0)
Block(-5,6,-5,AIR:0)
Block(-5,6,-4,AIR:0)
Block(-5,6,-3,AIR:0)
Block(-5,6,-2,AIR:0)
Block(-5,6,-1,AIR:0)
Block(-5,6,0,AIR:0)
Block(-5,6,1,AIR:0)
Block(-5,6,2,AIR:0)
Block(-5,6,3,AIR:0)
Block(-5,6,4,AIR:0)
Block(-5,6,5,AIR:0)
Block(-5,6,6,AIR:0)
Block(-5,6,7,IRON_FENCE:0)
Block(-5,6,8,AIR:0)
Block(-5,7,-7,CONCRETE:7)
Block(-5,7,-6,CONCRETE:7)
Block(-5,7,-5,CONCRETE:7)
Block(-5,7,-4,CONCRETE:7)
Block(-5,7,-3,CONCRETE:7)
Block(-5,7,-2,CONCRETE:7)
Block(-5,7,-1,CONCRETE:7)
Block(-5,7,0,CONCRETE:7)
Block(-5,7,1,CONCRETE:7)
Block(-5,7,2,CONCRETE:7)
Block(-5,7,3,CONCRETE:7)
Block(-5,7,4,CONCRETE:7)
Block(-5,7,5,CONCRETE:7)
Block(-5,7,6,CONCRETE:7)
Block(-5,7,7,CONCRETE:7)
Block(-5,7,8,CONCRETE:7)
Block(-5,8,-7,CONCRETE:7)
Block(-5,8,-6,CONCRETE:7)
Block(-5,8,-5,CONCRETE:7)
Block(-5,8,-4,CONCRETE:7)
Block(-5,8,-3,CONCRETE:7)
Block(-5,8,-2,CONCRETE:7)
Block(-5,8,-1,CONCRETE:7)
Block(-5,8,0,CONCRETE:7)
Block(-5,8,1,CONCRETE:7)
Block(-5,8,2,CONCRETE:7)
Block(-5,8,3,CONCRETE:7)
Block(-5,8,4,CONCRETE:7)
Block(-5,8,5,CONCRETE:7)
Block(-5,8,6,CONCRETE:7)
Block(-5,8,7,CONCRETE:7)
Block(-5,8,8,CONCRETE:7)
Block(-5,9,-7,CONCRETE:7)
Block(-5,9,-6,CONCRETE:7)
Block(-5,9,-5,CONCRETE:7)
Block(-5,9,-4,CONCRETE:7)
Block(-5,9,-3,CONCRETE:7)
Block(-5,9,-2,CONCRETE:7)
Block(-5,9,-1,CONCRETE:7)
Block(-5,9,0,AIR:0)
Block(-5,9,1,AIR:0)
Block(-5,9,2,AIR:0)
Block(-5,9,3,AIR:0)
Block(-5,9,4,AIR:0)
Block(-5,9,5,CONCRETE:14)
Block(-5,9,6,CONCRETE:7)
Block(-5,9,7,CONCRETE:7)
Block(-5,9,8,CONCRETE:7)
Block(-5,10,-7,CONCRETE:7)
Block(-5,10,-6,CONCRETE:7)
Block(-5,10,-5,CONCRETE:7)
Block(-5,10,-4,CONCRETE:7)
Block(-5,10,-3,AIR:0)
Block(-5,10,-2,AIR:0)
Block(-5,10,-1,CONCRETE:7)
Block(-5,10,0,AIR:0)
Block(-5,10,1,AIR:0)
Block(-5,10,2,AIR:0)
Block(-5,10,3,AIR:0)
Block(-5,10,4,AIR:0)
Block(-5,10,5,CONCRETE:15)
Block(-5,10,6,OBSIDIAN:0)
Block(-5,10,7,CONCRETE:7)
Block(-5,10,8,AIR:0)
Block(-5,11,-7,CONCRETE:7)
Block(-5,11,-6,CONCRETE:7)
Block(-5,11,-5,CONCRETE:7)
Block(-5,11,-4,CONCRETE:7)
Block(-5,11,-3,AIR:0)
Block(-5,11,-2,AIR:0)
Block(-5,11,-1,CONCRETE:7)
Block(-5,11,0,AIR:0)
Block(-5,11,1,AIR:0)
Block(-5,11,2,STONE_BUTTON:1)
Block(-5,11,3,AIR:0)
Block(-5,11,4,AIR:0)
Block(-5,11,5,CONCRETE:14)
Block(-5,11,6,OBSIDIAN:0)
Block(-5,11,7,CONCRETE:7)
Block(-5,11,8,AIR:0)
Block(-5,12,-7,CONCRETE:7)
Block(-5,12,-6,CONCRETE:7)
Block(-5,12,-5,CONCRETE:7)
Block(-5,12,-4,CONCRETE:7)
Block(-5,12,-3,AIR:0)
Block(-5,12,-2,AIR:0)
Block(-5,12,-1,CONCRETE:7)
Block(-5,12,0,AIR:0)
Block(-5,12,1,AIR:0)
Block(-5,12,2,AIR:0)
Block(-5,12,3,AIR:0)
Block(-5,12,4,AIR:0)
Block(-5,12,5,CONCRETE:15)
Block(-5,12,6,OBSIDIAN:0)
Block(-5,12,7,CONCRETE:7)
Block(-5,12,8,AIR:0)
Block(-5,13,-7,CONCRETE:7)
Block(-5,13,-6,CONCRETE:7)
Block(-5,13,-5,CONCRETE:7)
Block(-5,13,-4,CONCRETE:7)
Block(-5,13,-3,CONCRETE:7)
Block(-5,13,-2,CONCRETE:7)
Block(-5,13,-1,CONCRETE:7)
Block(-5,13,0,AIR:0)
Block(-5,13,1,AIR:0)
Block(-5,13,2,AIR:0)
Block(-5,13,3,AIR:0)
Block(-5,13,4,AIR:0)
Block(-5,13,5,CONCRETE:7)
Block(-5,13,6,OBSIDIAN:0)
Block(-5,13,7,CONCRETE:7)
Block(-5,13,8,AIR:0)
Block(-5,14,-7,CONCRETE:7)
Block(-5,14,-6,CONCRETE:7)
Block(-5,14,-5,CONCRETE:7)
Block(-5,14,-4,CONCRETE:7)
Block(-5,14,-3,DROPPER:3,NBT/skyscraper_2x2_04/354-dropperC16R0.nbt)
Block(-5,14,-2,AIR:0)
Block(-5,14,-1,SMOOTH_STAIRS:3)
Block(-5,14,0,AIR:0)
Block(-5,14,1,AIR:0)
Block(-5,14,2,AIR:0)
Block(-5,14,3,AIR:0)
Block(-5,14,4,AIR:0)
Block(-5,14,5,CONCRETE:7)
Block(-5,14,6,OBSIDIAN:0)
Block(-5,14,7,CONCRETE:7)
Block(-5,14,8,AIR:0)
Block(-5,15,-7,CONCRETE:7)
Block(-5,15,-6,CONCRETE:7)
Block(-5,15,-5,CONCRETE:7)
Block(-5,15,-4,CONCRETE:7)
Block(-5,15,-3,DROPPER:3,NBT/skyscraper_2x2_04/355-dropperC16R0.nbt)
Block(-5,15,-2,AIR:0)
Block(-5,15,-1,STEP:8)
Block(-5,15,0,AIR:0)
Block(-5,15,1,AIR:0)
Block(-5,15,2,STONE_BUTTON:1)
Block(-5,15,3,AIR:0)
Block(-5,15,4,AIR:0)
Block(-5,15,5,CONCRETE:7)
Block(-5,15,6,REDSTONE_WIRE:10)
Block(-5,15,7,CONCRETE:7)
Block(-5,15,8,AIR:0)
Block(-5,16,-7,CONCRETE:7)
Block(-5,16,-6,CONCRETE:7)
Block(-5,16,-5,CONCRETE:7)
Block(-5,16,-4,CONCRETE:7)
Block(-5,16,-3,CONCRETE:7)
Block(-5,16,-2,CONCRETE:7)
Block(-5,16,-1,CONCRETE:7)
Block(-5,16,0,AIR:0)
Block(-5,16,1,AIR:0)
Block(-5,16,2,AIR:0)
Block(-5,16,3,AIR:0)
Block(-5,16,4,AIR:0)
Block(-5,16,5,CONCRETE:7)
Block(-5,16,6,AIR:0)
Block(-5,16,7,CONCRETE:7)
Block(-5,16,8,CONCRETE:7)
Block(-5,17,-7,CONCRETE:7)
Block(-5,17,-6,CONCRETE:7)
Block(-5,17,-5,CONCRETE:7)
Block(-5,17,-4,CONCRETE:7)
Block(-5,17,-3,CONCRETE:7)
Block(-5,17,-2,CONCRETE:7)
Block(-5,17,-1,CONCRETE:7)
Block(-5,17,0,AIR:0)
Block(-5,17,1,AIR:0)
Block(-5,17,2,AIR:0)
Block(-5,17,3,AIR:0)
Block(-5,17,4,AIR:0)
Block(-5,17,5,CONCRETE:7)
Block(-5,17,6,CONCRETE:7)
Block(-5,17,7,CONCRETE:7)
Block(-5,17,8,CONCRETE:7)
Block(-5,18,-5,CONCRETE:8)
Block(-5,18,-4,DIRT:2)
Block(-5,18,-3,DIRT:2)
Block(-5,18,-2,DIRT:2)
Block(-5,18,-1,DIRT:2)
Block(-5,18,0,CONCRETE:15)
Block(-5,18,1,CONCRETE:15)
Block(-5,18,2,CONCRETE:15)
Block(-5,18,3,CONCRETE:15)
Block(-5,18,4,CONCRETE:15)
Block(-5,18,5,CONCRETE:15)
Block(-5,18,6,CONCRETE:15)
Block(-5,18,7,CONCRETE:8)
Block(-5,18,8,CONCRETE:8)
Block(-5,19,-5,STAINED_GLASS:15)
Block(-5,19,-4,DOUBLE_PLANT:3)
Block(-5,19,-3,LONG_GRASS:1)
Block(-5,19,-2,LOG:1)
Block(-5,19,-1,DOUBLE_PLANT:1)
Block(-5,19,0,CONCRETE:8)
Block(-5,19,1,DROPPER:1,NBT/skyscraper_2x2_04/356-dropperC16R0.nbt)
Block(-5,19,2,CONCRETE:15)
Block(-5,19,3,DROPPER:1,NBT/skyscraper_2x2_04/357-dropperC16R0.nbt)
Block(-5,19,4,CONCRETE:15)
Block(-5,19,5,DROPPER:1,NBT/skyscraper_2x2_04/358-dropperC16R0.nbt)
Block(-5,19,6,CONCRETE:15)
Block(-5,19,7,DROPPER:1,NBT/skyscraper_2x2_04/359-dropperC16R0.nbt)
Block(-5,19,8,CONCRETE:8)
Block(-5,20,-5,STAINED_GLASS:15)
Block(-5,20,-4,DOUBLE_PLANT:10)
Block(-5,20,-2,LOG:1)
Block(-5,20,-1,DOUBLE_PLANT:10)
Block(-5,20,0,CONCRETE:8)
Block(-5,20,1,TRAP_DOOR:7)
Block(-5,20,2,CONCRETE:15)
Block(-5,20,3,TRAP_DOOR:7)
Block(-5,20,4,CONCRETE:15)
Block(-5,20,5,TRAP_DOOR:7)
Block(-5,20,6,CONCRETE:15)
Block(-5,20,7,TRAP_DOOR:7)
Block(-5,20,8,CONCRETE:8)
Block(-5,21,-5,STAINED_GLASS:15)
Block(-5,21,-2,LOG:1)
Block(-5,21,-1,SPRUCE_FENCE:0)
Block(-5,21,0,CONCRETE:8)
Block(-5,21,2,CONCRETE:15)
Block(-5,21,4,CONCRETE:15)
Block(-5,21,6,CONCRETE:15)
Block(-5,21,8,CONCRETE:8)
Block(-5,22,-5,STAINED_GLASS:15)
Block(-5,22,-4,LEAVES:12)
Block(-5,22,-3,SPRUCE_FENCE:0)
Block(-5,22,-2,LOG:1)
Block(-5,22,-1,LEAVES:4)
Block(-5,22,0,CONCRETE:8)
Block(-5,22,1,CONCRETE:15)
Block(-5,22,2,CONCRETE:15)
Block(-5,22,3,CONCRETE:15)
Block(-5,22,4,CONCRETE:15)
Block(-5,22,5,CONCRETE:15)
Block(-5,22,6,CONCRETE:15)
Block(-5,22,7,CONCRETE:8)
Block(-5,22,8,CONCRETE:8)
Block(-5,23,-5,STAINED_GLASS:15)
Block(-5,23,-4,LEAVES:12)
Block(-5,23,-3,LOG:9)
Block(-5,23,-2,LOG:1)
Block(-5,23,-1,LEAVES:4)
Block(-5,23,0,CONCRETE:8)
#RandomBlock(-5,23,1,TRAPPED_CHEST:5,../../../../../Chests/Loot/ModernCityJunk_1.nbt,65,CHEST:5,../../../../../Chests/Loot/ModernCityJunk_1.nbt,20,CHEST:5,../../../../../Chests/Loot/ModernCityJunk_2.nbt,15,CHEST:5,../../../../../Chests/Loot/ModernCityJunk_3.nbt,15,CHEST:5,../../../../../Chests/Loot/ModernCityJunk_4.nbt,15,CHEST:5,../../../../../Chests/Loot/ModernCityJunk_5.nbt,15,CHEST:5,../../../../../Chests/Loot/ModernCityCommon_1.nbt,5,CHEST:5,../../../../../Chests/Loot/ModernCityCommon_2.nbt,5,CHEST:5,../../../../../Chests/Loot/ModernCityCommon_3.nbt,5,CHEST:5,../../../../../Chests/Loot/ModernCityCommon_4.nbt,5,CHEST:5,../../../../../Chests/Loot/ModernCityCommon_5.nbt,5,CHEST:5,../../../../../Chests/Loot/ModernCityGood_1.nbt,3,CHEST:5,../../../../../Chests/Loot/ModernCityGood_2.nbt,3,CHEST:5,../../../../../Chests/Loot/ModernCityGood_3.nbt,3,CHEST:5,../../../../../Chests/Loot/ModernCityGood_4.nbt,3,CHEST:5,../../../../../Chests/Loot/ModernCityGood_5.nbt,3,CHEST:5,../../../../../Chests/Loot/ModernCityEpic_1.nbt,1,CHEST:5,../../../../../Chests/Loot/ModernCityEpic_2.nbt,1,CHEST:5,../../../../../Chests/Loot/ModernCityEpic_3.nbt,1,CHEST:5,../../../../../Chests/Loot/ModernCityEpic_4.nbt,1,CHEST:5,../../../../../Chests/Loot/ModernCityEpic_5.nbt,1,CHEST:5,../../../../../Chests/Loot/Common1.nbt,25,CHEST:5,../../../../../Chests/Loot/Common2.nbt,25,CHEST:5,../../../../../Chests/Loot/Common3.nbt,25,CHEST:5,../../../../../Chests/Loot/Common4.nbt,25,CHEST:5,../../../../../Chests/Loot/Common5.nbt,25,CHEST:5,../../../../../Chests/Loot/Common6.nbt,25,CHEST:5,../../../../../Chests/Loot/Common7.nbt,25,CHEST:5,../../../../../Chests/Loot/Common8.nbt,25,CHEST:5,../../../../../Chests/Loot/Common9.nbt,25,CHEST:5,../../../../../Chests/Loot/Common10.nbt,25,CHEST:5,../../../../../Chests/Loot/Common11.nbt,25,CHEST:5,../../../../../Chests/Loot/Common12.nbt,25,CHEST:5,../../../../../Chests/Loot/Common13.nbt,25,CHEST:5,../../../../../Chests/Loot/Common14.nbt,25,CHEST:5,../../../../../Chests/Loot/Common15.nbt,25,CHEST:5,../../../../../Chests/Loot/Rare1.nbt,10,CHEST:5,../../../../../Chests/Loot/Rare2.nbt,10,CHEST:5,../../../../../Chests/Loot/Rare3.nbt,10,CHEST:5,../../../../../Chests/Loot/Rare4.nbt,10,CHEST:5,../../../../../Chests/Loot/Rare5.nbt,10,CHEST:5,../../../../../Chests/Loot/Rare6.nbt,10,CHEST:5,../../../../../Chests/Loot/Rare7.nbt,10,CHEST:5,../../../../../Chests/Loot/Rare8.nbt,10,CHEST:5,../../../../../Chests/Loot/Rare9.nbt,10,CHEST:5,../../../../../Chests/Loot/Rare10.nbt,10,CHEST:5,../../../../../Chests/Loot/Rare11.nbt,10,CHEST:5,../../../../../Chests/Loot/Rare12.nbt,10,CHEST:5,../../../../../Chests/Loot/Rare13.nbt,10,CHEST:5,../../../../../Chests/Loot/Rare14.nbt,10,CHEST:5,../../../../../Chests/Loot/Rare15.nbt,10,CHEST:5,../../../../../Chests/Loot/Epic1.nbt,1,CHEST:5,../../../../../Chests/Loot/Epic2.nbt,1,CHEST:5,../../../../../Chests/Loot/Epic3.nbt,1,CHEST:5,../../../../../Chests/Loot/Epic4.nbt,1,CHEST:5,../../../../../Chests/Loot/Epic5.nbt,1,CHEST:5,../../../../../Chests/Loot/Epic6.nbt,1,CHEST:5,../../../../../Chests/Loot/Epic7.nbt,1,CHEST:5,../../../../../Chests/Loot/Epic8.nbt,1,CHEST:5,../../../../../Chests/Loot/Epic9.nbt,1,CHEST:5,../../../../../Chests/Loot/Epic10.nbt,1,CHEST:5,../../../../../Chests/Loot/Epic11.nbt,1,CHEST:5,../../../../../Chests/Loot/Epic12.nbt,1,CHEST:5,../../../../../Chests/Loot/Epic13.nbt,1,CHEST:5,../../../../../Chests/Loot/Epic14.nbt,1,CHEST:5,../../../../../Chests/Loot/Epic15.nbt,1,CHEST:5,../../../../../Chests/Loot/ModernCityJunk_1.nbt,100)
Block(-5,23,2,IRON_TRAPDOOR:11)
Block(-5,23,3,DROPPER:5,NBT/skyscraper_2x2_04/361-dropperC16R0.nbt)
Block(-5,23,4,FURNACE:5,NBT/skyscraper_2x2_04/362-furnaceC16R0.nbt)
Block(-5,23,5,OBSERVER:4)
Block(-5,23,6,WORKBENCH:0)
Block(-5,23,7,FURNACE:5,NBT/skyscraper_2x2_04/363-furnaceC16R0.nbt)
Block(-5,23,8,DROPPER:5,NBT/skyscraper_2x2_04/364-dropperC16R0.nbt)
Block(-5,24,-5,STAINED_GLASS:15)
Block(-5,24,-4,LEAVES:12)
Block(-5,24,-3,SPRUCE_FENCE:0)
Block(-5,24,-2,LOG:1)
Block(-5,24,-1,LEAVES:4)
Block(-5,24,0,CONCRETE:8)
Block(-5,24,1,IRON_TRAPDOOR:11)
Block(-5,24,2,IRON_TRAPDOOR:11)
Block(-5,24,3,REDSTONE_LAMP_OFF:0)
Block(-5,24,4,REDSTONE_LAMP_OFF:0)
Block(-5,24,5,OBSERVER:4)
Block(-5,24,6,WORKBENCH:0)
Block(-5,24,7,DROPPER:5,NBT/skyscraper_2x2_04/365-dropperC16R0.nbt)
Block(-5,24,8,REDSTONE_LAMP_OFF:0)
Block(-5,25,-5,STAINED_GLASS:15)
Block(-5,25,-3,LEAVES:12)
Block(-5,25,-2,SPRUCE_FENCE:0)
Block(-5,25,-1,LEAVES:12)
Block(-5,25,0,CONCRETE:8)
Block(-5,25,1,IRON_TRAPDOOR:11)
#RandomBlock(-5,25,2,TRAPPED_CHEST:5,../../../../../Chests/Loot/ModernCityJunk_1.nbt,65,CHEST:5,../../../../../Chests/Loot/ModernCityJunk_1.nbt,20,CHEST:5,../../../../../Chests/Loot/ModernCityJunk_2.nbt,15,CHEST:5,../../../../../Chests/Loot/ModernCityJunk_3.nbt,15,CHEST:5,../../../../../Chests/Loot/ModernCityJunk_4.nbt,15,CHEST:5,../../../../../Chests/Loot/ModernCityJunk_5.nbt,15,CHEST:5,../../../../../Chests/Loot/ModernCityCommon_1.nbt,5,CHEST:5,../../../../../Chests/Loot/ModernCityCommon_2.nbt,5,CHEST:5,../../../../../Chests/Loot/ModernCityCommon_3.nbt,5,CHEST:5,../../../../../Chests/Loot/ModernCityCommon_4.nbt,5,CHEST:5,../../../../../Chests/Loot/ModernCityCommon_5.nbt,5,CHEST:5,../../../../../Chests/Loot/ModernCityGood_1.nbt,3,CHEST:5,../../../../../Chests/Loot/ModernCityGood_2.nbt,3,CHEST:5,../../../../../Chests/Loot/ModernCityGood_3.nbt,3,CHEST:5,../../../../../Chests/Loot/ModernCityGood_4.nbt,3,CHEST:5,../../../../../Chests/Loot/ModernCityGood_5.nbt,3,CHEST:5,../../../../../Chests/Loot/ModernCityEpic_1.nbt,1,CHEST:5,../../../../../Chests/Loot/ModernCityEpic_2.nbt,1,CHEST:5,../../../../../Chests/Loot/ModernCityEpic_3.nbt,1,CHEST:5,../../../../../Chests/Loot/ModernCityEpic_4.nbt,1,CHEST:5,../../../../../Chests/Loot/ModernCityEpic_5.nbt,1,CHEST:5,../../../../../Chests/Loot/Common1.nbt,25,CHEST:5,../../../../../Chests/Loot/Common2.nbt,25,CHEST:5,../../../../../Chests/Loot/Common3.nbt,25,CHEST:5,../../../../../Chests/Loot/Common4.nbt,25,CHEST:5,../../../../../Chests/Loot/Common5.nbt,25,CHEST:5,../../../../../Chests/Loot/Common6.nbt,25,CHEST:5,../../../../../Chests/Loot/Common7.nbt,25,CHEST:5,../../../../../Chests/Loot/Common8.nbt,25,CHEST:5,../../../../../Chests/Loot/Common9.nbt,25,CHEST:5,../../../../../Chests/Loot/Common10.nbt,25,CHEST:5,../../../../../Chests/Loot/Common11.nbt,25,CHEST:5,../../../../../Chests/Loot/Common12.nbt,25,CHEST:5,../../../../../Chests/Loot/Common13.nbt,25,CHEST:5,../../../../../Chests/Loot/Common14.nbt,25,CHEST:5,../../../../../Chests/Loot/Common15.nbt,25,CHEST:5,../../../../../Chests/Loot/Rare1.nbt,10,CHEST:5,../../../../../Chests/Loot/Rare2.nbt,10,CHEST:5,../../../../../Chests/Loot/Rare3.nbt,10,CHEST:5,../../../../../Chests/Loot/Rare4.nbt,10,CHEST:5,../../../../../Chests/Loot/Rare5.nbt,10,CHEST:5,../../../../../Chests/Loot/Rare6.nbt,10,CHEST:5,../../../../../Chests/Loot/Rare7.nbt,10,CHEST:5,../../../../../Chests/Loot/Rare8.nbt,10,CHEST:5,../../../../../Chests/Loot/Rare9.nbt,10,CHEST:5,../../../../../Chests/Loot/Rare10.nbt,10,CHEST:5,../../../../../Chests/Loot/Rare11.nbt,10,CHEST:5,../../../../../Chests/Loot/Rare12.nbt,10,CHEST:5,../../../../../Chests/Loot/Rare13.nbt,10,CHEST:5,../../../../../Chests/Loot/Rare14.nbt,10,CHEST:5,../../../../../Chests/Loot/Rare15.nbt,10,CHEST:5,../../../../../Chests/Loot/Epic1.nbt,1,CHEST:5,../../../../../Chests/Loot/Epic2.nbt,1,CHEST:5,../../../../../Chests/Loot/Epic3.nbt,1,CHEST:5,../../../../../Chests/Loot/Epic4.nbt,1,CHEST:5,../../../../../Chests/Loot/Epic5.nbt,1,CHEST:5,../../../../../Chests/Loot/Epic6.nbt,1,CHEST:5,../../../../../Chests/Loot/Epic7.nbt,1,CHEST:5,../../../../../Chests/Loot/Epic8.nbt,1,CHEST:5,../../../../../Chests/Loot/Epic9.nbt,1,CHEST:5,../../../../../Chests/Loot/Epic10.nbt,1,CHEST:5,../../../../../Chests/Loot/Epic11.nbt,1,CHEST:5,../../../../../Chests/Loot/Epic12.nbt,1,CHEST:5,../../../../../Chests/Loot/Epic13.nbt,1,CHEST:5,../../../../../Chests/Loot/Epic14.nbt,1,CHEST:5,../../../../../Chests/Loot/Epic15.nbt,1,CHEST:5,../../../../../Chests/Loot/ModernCityJunk_1.nbt,100)
Block(-5,25,3,CONCRETE:8)
Block(-5,25,4,CONCRETE:8)
Block(-5,25,5,CONCRETE:8)
Block(-5,25,6,WORKBENCH:0)
Block(-5,25,7,OBSERVER:4)
Block(-5,25,8,OBSERVER:4)
Block(-5,26,-5,STAINED_GLASS:15)
Block(-5,26,-2,LEAVES:12)
Block(-5,26,-1,LEAVES:12)
Block(-5,26,0,CONCRETE:8)
#RandomBlock(-5,26,1,TRAPPED_CHEST:5,../../../../../Chests/Loot/ModernCityJunk_1.nbt,65,CHEST:5,../../../../../Chests/Loot/ModernCityJunk_1.nbt,20,CHEST:5,../../../../../Chests/Loot/ModernCityJunk_2.nbt,15,CHEST:5,../../../../../Chests/Loot/ModernCityJunk_3.nbt,15,CHEST:5,../../../../../Chests/Loot/ModernCityJunk_4.nbt,15,CHEST:5,../../../../../Chests/Loot/ModernCityJunk_5.nbt,15,CHEST:5,../../../../../Chests/Loot/ModernCityCommon_1.nbt,5,CHEST:5,../../../../../Chests/Loot/ModernCityCommon_2.nbt,5,CHEST:5,../../../../../Chests/Loot/ModernCityCommon_3.nbt,5,CHEST:5,../../../../../Chests/Loot/ModernCityCommon_4.nbt,5,CHEST:5,../../../../../Chests/Loot/ModernCityCommon_5.nbt,5,CHEST:5,../../../../../Chests/Loot/ModernCityGood_1.nbt,3,CHEST:5,../../../../../Chests/Loot/ModernCityGood_2.nbt,3,CHEST:5,../../../../../Chests/Loot/ModernCityGood_3.nbt,3,CHEST:5,../../../../../Chests/Loot/ModernCityGood_4.nbt,3,CHEST:5,../../../../../Chests/Loot/ModernCityGood_5.nbt,3,CHEST:5,../../../../../Chests/Loot/ModernCityEpic_1.nbt,1,CHEST:5,../../../../../Chests/Loot/ModernCityEpic_2.nbt,1,CHEST:5,../../../../../Chests/Loot/ModernCityEpic_3.nbt,1,CHEST:5,../../../../../Chests/Loot/ModernCityEpic_4.nbt,1,CHEST:5,../../../../../Chests/Loot/ModernCityEpic_5.nbt,1,CHEST:5,../../../../../Chests/Loot/Common1.nbt,25,CHEST:5,../../../../../Chests/Loot/Common2.nbt,25,CHEST:5,../../../../../Chests/Loot/Common3.nbt,25,CHEST:5,../../../../../Chests/Loot/Common4.nbt,25,CHEST:5,../../../../../Chests/Loot/Common5.nbt,25,CHEST:5,../../../../../Chests/Loot/Common6.nbt,25,CHEST:5,../../../../../Chests/Loot/Common7.nbt,25,CHEST:5,../../../../../Chests/Loot/Common8.nbt,25,CHEST:5,../../../../../Chests/Loot/Common9.nbt,25,CHEST:5,../../../../../Chests/Loot/Common10.nbt,25,CHEST:5,../../../../../Chests/Loot/Common11.nbt,25,CHEST:5,../../../../../Chests/Loot/Common12.nbt,25,CHEST:5,../../../../../Chests/Loot/Common13.nbt,25,CHEST:5,../../../../../Chests/Loot/Common14.nbt,25,CHEST:5,../../../../../Chests/Loot/Common15.nbt,25,CHEST:5,../../../../../Chests/Loot/Rare1.nbt,10,CHEST:5,../../../../../Chests/Loot/Rare2.nbt,10,CHEST:5,../../../../../Chests/Loot/Rare3.nbt,10,CHEST:5,../../../../../Chests/Loot/Rare4.nbt,10,CHEST:5,../../../../../Chests/Loot/Rare5.nbt,10,CHEST:5,../../../../../Chests/Loot/Rare6.nbt,10,CHEST:5,../../../../../Chests/Loot/Rare7.nbt,10,CHEST:5,../../../../../Chests/Loot/Rare8.nbt,10,CHEST:5,../../../../../Chests/Loot/Rare9.nbt,10,CHEST:5,../../../../../Chests/Loot/Rare10.nbt,10,CHEST:5,../../../../../Chests/Loot/Rare11.nbt,10,CHEST:5,../../../../../Chests/Loot/Rare12.nbt,10,CHEST:5,../../../../../Chests/Loot/Rare13.nbt,10,CHEST:5,../../../../../Chests/Loot/Rare14.nbt,10,CHEST:5,../../../../../Chests/Loot/Rare15.nbt,10,CHEST:5,../../../../../Chests/Loot/Epic1.nbt,1,CHEST:5,../../../../../Chests/Loot/Epic2.nbt,1,CHEST:5,../../../../../Chests/Loot/Epic3.nbt,1,CHEST:5,../../../../../Chests/Loot/Epic4.nbt,1,CHEST:5,../../../../../Chests/Loot/Epic5.nbt,1,CHEST:5,../../../../../Chests/Loot/Epic6.nbt,1,CHEST:5,../../../../../Chests/Loot/Epic7.nbt,1,CHEST:5,../../../../../Chests/Loot/Epic8.nbt,1,CHEST:5,../../../../../Chests/Loot/Epic9.nbt,1,CHEST:5,../../../../../Chests/Loot/Epic10.nbt,1,CHEST:5,../../../../../Chests/Loot/Epic11.nbt,1,CHEST:5,../../../../../Chests/Loot/Epic12.nbt,1,CHEST:5,../../../../../Chests/Loot/Epic13.nbt,1,CHEST:5,../../../../../Chests/Loot/Epic14.nbt,1,CHEST:5,../../../../../Chests/Loot/Epic15.nbt,1,CHEST:5,../../../../../Chests/Loot/ModernCityJunk_1.nbt,100)
Block(-5,26,3,CONCRETE:8)
Block(-5,26,4,CONCRETE:8)
Block(-5,26,5,CONCRETE:8)
Block(-5,26,6,CONCRETE:8)
Block(-5,26,7,CONCRETE:8)
Block(-5,26,8,CONCRETE:8)
Block(-5,27,-5,STAINED_GLASS:15)
Block(-5,27,-4,CONCRETE:8)
Block(-5,27,-3,CONCRETE:8)
Block(-5,27,-2,CONCRETE:8)
Block(-5,27,-1,CONCRETE:8)
Block(-5,27,0,CONCRETE:8)
Block(-5,27,1,CONCRETE:8)
Block(-5,27,2,CONCRETE:8)
Block(-5,27,3,CONCRETE:8)
Block(-5,27,4,CONCRETE:8)
Block(-5,27,5,CONCRETE:8)
Block(-5,27,6,CONCRETE:8)
Block(-5,27,7,CONCRETE:8)
Block(-5,27,8,CONCRETE:8)
Block(-5,28,-5,STAINED_GLASS:15)
Block(-5,28,-4,CONCRETE:14)
Block(-5,28,-3,STONE_BUTTON:3)
Block(-5,29,-5,STAINED_GLASS:15)
Block(-5,29,-4,CONCRETE:14)
Block(-5,29,-3,STONE_BUTTON:3)
Block(-5,30,-5,STAINED_GLASS:15)
Block(-5,30,-4,IRON_TRAPDOOR:1)
Block(-5,31,-5,STAINED_GLASS:15)
Block(-5,32,-5,STAINED_GLASS:15)
Block(-5,33,-5,STAINED_GLASS:15)
Block(-5,34,-5,STAINED_GLASS:15)
Block(-5,35,-5,STAINED_GLASS:15)
Block(-5,35,-4,CONCRETE:8)
Block(-5,35,-3,CONCRETE:8)
Block(-5,35,-2,CONCRETE:8)
Block(-5,35,-1,CONCRETE:8)
Block(-5,35,0,CONCRETE:8)
Block(-5,35,1,CONCRETE:8)
Block(-5,35,2,CONCRETE:8)
Block(-5,35,3,CONCRETE:8)
Block(-5,35,4,CONCRETE:8)
Block(-5,35,5,CONCRETE:8)
Block(-5,35,6,CONCRETE:8)
Block(-5,35,7,CONCRETE:8)
Block(-5,35,8,CONCRETE:8)
Block(-5,36,-5,STAINED_GLASS:15)
Block(-5,36,-4,CONCRETE:14)
Block(-5,36,-3,STONE_BUTTON:3)
Block(-5,37,-5,STAINED_GLASS:15)
Block(-5,37,-4,CONCRETE:14)
Block(-5,37,-3,STONE_BUTTON:3)
Block(-5,38,-5,STAINED_GLASS:15)
Block(-5,38,-4,IRON_TRAPDOOR:1)
Block(-5,39,-5,STAINED_GLASS:15)
Block(-5,40,-5,STAINED_GLASS:15)
Block(-5,41,-5,STAINED_GLASS:15)
Block(-5,42,-5,STAINED_GLASS:15)
Block(-5,43,-5,STAINED_GLASS:15)
Block(-5,43,-4,CONCRETE:8)
Block(-5,43,-3,CONCRETE:8)
Block(-5,43,-2,CONCRETE:8)
Block(-5,43,-1,CONCRETE:8)
Block(-5,43,0,CONCRETE:8)
Block(-5,43,1,CONCRETE:8)
Block(-5,43,2,CONCRETE:8)
Block(-5,43,3,CONCRETE:8)
Block(-5,43,4,CONCRETE:8)
Block(-5,43,5,CONCRETE:8)
Block(-5,43,6,CONCRETE:8)
Block(-5,43,7,CONCRETE:8)
Block(-5,43,8,CONCRETE:8)
Block(-5,44,-5,STAINED_GLASS:15)
Block(-5,44,-4,CONCRETE:14)
Block(-5,44,-3,STONE_BUTTON:3)
Block(-5,45,-5,STAINED_GLASS:15)
Block(-5,45,-4,CONCRETE:14)
Block(-5,45,-3,STONE_BUTTON:3)
Block(-5,46,-5,STAINED_GLASS:15)
Block(-5,46,-4,IRON_TRAPDOOR:1)
Block(-5,47,-5,STAINED_GLASS:15)
Block(-5,48,-5,STAINED_GLASS:15)
Block(-5,49,-5,STAINED_GLASS:15)
Block(-5,50,-5,STAINED_GLASS:15)
Block(-5,51,-5,STAINED_GLASS:15)
Block(-5,51,-4,CONCRETE:8)
Block(-5,51,-3,CONCRETE:8)
Block(-5,51,-2,CONCRETE:8)
Block(-5,51,-1,CONCRETE:8)
Block(-5,51,0,CONCRETE:8)
Block(-5,51,1,CONCRETE:8)
Block(-5,51,2,CONCRETE:8)
Block(-5,51,3,CONCRETE:8)
Block(-5,51,4,CONCRETE:8)
Block(-5,51,5,CONCRETE:8)
Block(-5,51,6,CONCRETE:8)
Block(-5,51,7,CONCRETE:8)
Block(-5,51,8,CONCRETE:8)
Block(-5,52,-5,STAINED_GLASS:15)
Block(-5,52,-4,CONCRETE:14)
Block(-5,52,-3,STONE_BUTTON:3)
Block(-5,53,-5,STAINED_GLASS:15)
Block(-5,53,-4,CONCRETE:14)
Block(-5,53,-3,STONE_BUTTON:3)
Block(-5,54,-5,STAINED_GLASS:15)
Block(-5,54,-4,IRON_TRAPDOOR:1)
Block(-5,55,-5,STAINED_GLASS:15)
Block(-5,56,-5,STAINED_GLASS:15)
Block(-5,57,-5,STAINED_GLASS:15)
Block(-5,58,-5,STAINED_GLASS:15)
Block(-5,59,-5,STAINED_GLASS:15)
Block(-5,59,-4,CONCRETE:8)
Block(-5,59,-3,CONCRETE:8)
Block(-5,59,-2,CONCRETE:8)
Block(-5,59,-1,CONCRETE:8)
Block(-5,59,0,CONCRETE:8)
Block(-5,59,1,CONCRETE:8)
Block(-5,59,2,CONCRETE:8)
Block(-5,59,3,CONCRETE:8)
Block(-5,59,4,CONCRETE:8)
Block(-5,59,5,CONCRETE:8)
Block(-5,59,6,CONCRETE:8)
Block(-5,59,7,CONCRETE:8)
Block(-5,59,8,CONCRETE:8)
Block(-5,60,-5,STAINED_GLASS:15)
Block(-5,60,-4,CONCRETE:14)
Block(-5,60,-3,STONE_BUTTON:3)
Block(-5,61,-5,STAINED_GLASS:15)
Block(-5,61,-4,CONCRETE:14)
Block(-5,61,-3,STONE_BUTTON:3)
Block(-5,62,-5,STAINED_GLASS:15)
Block(-5,62,-4,IRON_TRAPDOOR:1)
Block(-5,63,-5,STAINED_GLASS:15)
Block(-5,64,-5,STAINED_GLASS:15)
Block(-5,65,-5,STAINED_GLASS:15)
Block(-5,66,-5,STAINED_GLASS:15)
Block(-5,67,-5,STAINED_GLASS:15)
Block(-5,67,-4,CONCRETE:8)
Block(-5,67,-3,CONCRETE:8)
Block(-5,67,-2,CONCRETE:8)
Block(-5,67,-1,CONCRETE:8)
Block(-5,67,0,CONCRETE:8)
Block(-5,67,1,CONCRETE:8)
Block(-5,67,2,CONCRETE:8)
Block(-5,67,3,CONCRETE:8)
Block(-5,67,4,CONCRETE:8)
Block(-5,67,5,CONCRETE:8)
Block(-5,67,6,CONCRETE:8)
Block(-5,67,7,CONCRETE:8)
Block(-5,67,8,CONCRETE:8)
Block(-5,68,-5,STAINED_GLASS:15)
Block(-5,68,-4,CONCRETE:14)
Block(-5,68,-3,STONE_BUTTON:3)
Block(-5,69,-5,STAINED_GLASS:15)
Block(-5,69,-4,CONCRETE:14)
Block(-5,69,-3,STONE_BUTTON:3)
Block(-5,70,-5,STAINED_GLASS:15)
Block(-5,70,-4,IRON_TRAPDOOR:1)
Block(-5,71,-5,STAINED_GLASS:15)
Block(-5,72,-5,STAINED_GLASS:15)
Block(-5,73,-5,STAINED_GLASS:15)
Block(-5,74,-5,STAINED_GLASS:15)
Block(-5,75,-5,STAINED_GLASS:15)
Block(-5,75,-4,CONCRETE:8)
Block(-5,75,-3,CONCRETE:8)
Block(-5,75,-2,CONCRETE:8)
Block(-5,75,-1,CONCRETE:8)
Block(-5,75,0,CONCRETE:8)
Block(-5,75,1,CONCRETE:8)
Block(-5,75,2,CONCRETE:8)
Block(-5,75,3,CONCRETE:8)
Block(-5,75,4,CONCRETE:8)
Block(-5,75,5,CONCRETE:8)
Block(-5,75,6,CONCRETE:8)
Block(-5,75,7,CONCRETE:8)
Block(-5,75,8,CONCRETE:8)
Block(-5,76,-5,STAINED_GLASS:15)
Block(-5,76,-4,CONCRETE:14)
Block(-5,76,-3,STONE_BUTTON:3)
Block(-5,77,-5,STAINED_GLASS:15)
Block(-5,77,-4,CONCRETE:14)
Block(-5,77,-3,STONE_BUTTON:3)
Block(-5,78,-5,STAINED_GLASS:15)
Block(-5,78,-4,IRON_TRAPDOOR:1)
Block(-5,79,-5,CONCRETE:8)
Block(-5,79,0,CONCRETE:8)
Block(-5,80,-5,CONCRETE:8)
Block(-5,80,-4,CONCRETE:8)
Block(-5,80,-3,CONCRETE:8)
Block(-5,80,-2,CONCRETE:8)
Block(-5,80,-1,CONCRETE:8)
Block(-5,80,0,CONCRETE:8)
Block(-5,81,-5,CONCRETE:8)
Block(-5,81,-4,CONCRETE:8)
Block(-5,81,-3,CONCRETE:8)
Block(-5,81,-2,CONCRETE:8)
Block(-5,81,-1,CONCRETE:8)
Block(-5,81,0,CONCRETE:8)
Block(-5,82,0,STAINED_GLASS:15)
Block(-5,83,0,STAINED_GLASS:15)
Block(-5,83,1,CONCRETE:8)
Block(-5,83,2,CONCRETE:8)
Block(-5,83,3,CONCRETE:8)
Block(-5,83,4,CONCRETE:8)
Block(-5,83,5,CONCRETE:8)
Block(-5,83,6,CONCRETE:8)
Block(-5,83,7,CONCRETE:8)
Block(-5,83,8,CONCRETE:8)
Block(-5,84,0,STAINED_GLASS:15)
Block(-5,85,0,STAINED_GLASS:15)
Block(-5,86,0,STAINED_GLASS:15)
Block(-5,87,0,STAINED_GLASS:15)
Block(-5,88,0,STAINED_GLASS:15)
Block(-5,89,0,STAINED_GLASS:15)
Block(-5,90,0,STAINED_GLASS:15)
Block(-5,91,0,STAINED_GLASS:15)
Block(-5,91,1,CONCRETE:8)
Block(-5,91,2,CONCRETE:8)
Block(-5,91,3,CONCRETE:8)
Block(-5,91,4,CONCRETE:8)
Block(-5,91,5,CONCRETE:8)
Block(-5,91,6,CONCRETE:8)
Block(-5,91,7,CONCRETE:8)
Block(-5,91,8,CONCRETE:8)
Block(-5,92,0,STAINED_GLASS:15)
Block(-5,93,0,STAINED_GLASS:15)
Block(-5,94,0,STAINED_GLASS:15)
Block(-5,95,0,STAINED_GLASS:15)
Block(-5,96,0,STAINED_GLASS:15)
Block(-5,97,0,STAINED_GLASS:15)
Block(-5,98,0,STAINED_GLASS:15)
Block(-5,99,0,STAINED_GLASS:15)
Block(-5,99,1,CONCRETE:8)
Block(-5,99,2,CONCRETE:8)
Block(-5,99,3,CONCRETE:8)
Block(-5,99,4,CONCRETE:8)
Block(-5,99,5,CONCRETE:8)
Block(-5,99,6,CONCRETE:8)
Block(-5,99,7,CONCRETE:8)
Block(-5,99,8,CONCRETE:8)
Block(-5,100,0,STAINED_GLASS:15)
Block(-5,101,0,STAINED_GLASS:15)
Block(-5,102,0,STAINED_GLASS:15)
Block(-5,103,0,STAINED_GLASS:15)
Block(-5,104,0,STAINED_GLASS:15)
Block(-5,105,0,CONCRETE:15)
Block(-5,105,6,CONCRETE:15)
Block(-5,106,0,CONCRETE:15)
Block(-5,106,1,CONCRETE:15)
Block(-5,106,2,CONCRETE:15)
Block(-5,106,3,CONCRETE:15)
Block(-5,106,4,CONCRETE:15)
Block(-5,106,5,CONCRETE:15)
Block(-5,106,6,CONCRETE:15)
Block(-5,107,0,CONCRETE:15)
Block(-5,107,1,CONCRETE:15)
Block(-5,107,2,CONCRETE:15)
Block(-5,107,3,CONCRETE:15)
Block(-5,107,4,CONCRETE:15)
Block(-5,107,5,CONCRETE:15)
Block(-5,107,6,CONCRETE:15)
Block(-5,107,7,CONCRETE:8)
Block(-5,107,8,CONCRETE:8)
Block(-5,108,6,STAINED_GLASS:15)
Block(-5,108,7,CONCRETE:15)
Block(-5,109,6,STAINED_GLASS:15)
Block(-5,109,7,CONCRETE:14)
Block(-5,110,6,STAINED_GLASS:15)
Block(-5,110,7,DISPENSER:1,NBT/skyscraper_2x2_04/374-dispenserC16R0.nbt)
Block(-5,111,6,STAINED_GLASS:15)
Block(-5,111,7,IRON_FENCE:0)
Block(-5,112,6,STAINED_GLASS:15)
Block(-5,112,7,IRON_FENCE:0)
Block(-5,112,8,IRON_FENCE:0)
Block(-5,113,6,STAINED_GLASS:15)
Block(-5,114,6,STAINED_GLASS:15)
Block(-5,115,6,STAINED_GLASS:15)
Block(-5,115,7,CONCRETE:8)
Block(-5,115,8,CONCRETE:8)
Block(-5,116,6,STAINED_GLASS:15)
Block(-5,116,8,CONCRETE:8)
Block(-5,117,6,STAINED_GLASS:15)
Block(-5,117,8,CONCRETE:8)
Block(-5,118,6,STAINED_GLASS:15)
Block(-5,118,8,CONCRETE:8)
Block(-5,119,6,STAINED_GLASS:15)
Block(-5,119,8,CONCRETE:8)
Block(-5,120,6,STAINED_GLASS:15)
Block(-5,120,8,CONCRETE:8)
Block(-5,121,6,STAINED_GLASS:15)
Block(-5,121,7,QUARTZ_STAIRS:4)
Block(-5,121,8,CONCRETE:8)
Block(-5,122,6,STAINED_GLASS:15)
Block(-5,122,7,QUARTZ_STAIRS:1)
Block(-5,122,8,CONCRETE:8)
Block(-5,123,6,STAINED_GLASS:15)
Block(-5,123,8,CONCRETE:8)
Block(-5,124,6,STAINED_GLASS:15)
Block(-5,124,8,STAINED_GLASS_PANE:15)
Block(-5,125,6,STAINED_GLASS:15)
Block(-5,126,6,STAINED_GLASS:15)
Block(-5,127,6,STAINED_GLASS:15)
Block(-5,128,6,STAINED_GLASS:15)
Block(-5,129,6,STAINED_GLASS:15)
Block(-5,130,6,STAINED_GLASS:15)
Block(-5,131,6,STAINED_GLASS:15)
Block(-5,132,6,STAINED_GLASS:15)
Block(-5,133,6,STAINED_GLASS:15)
Block(-5,134,6,STAINED_GLASS:15)
Block(-5,135,6,CONCRETE:8)
Block(-5,136,6,CONCRETE:8)
Block(-5,136,7,CONCRETE:8)
Block(-5,136,8,CONCRETE:8)
Block(-5,137,6,CONCRETE:8)
Block(-5,137,7,CONCRETE:8)
Block(-5,137,8,CONCRETE:8)
Block(-4,0,-7,CONCRETE:7)
Block(-4,0,-6,CONCRETE:7)
Block(-4,0,-5,CONCRETE:7)
Block(-4,0,-4,CONCRETE:7)
Block(-4,0,-3,CONCRETE:7)
Block(-4,0,-2,CONCRETE:7)
Block(-4,0,-1,CONCRETE:7)
Block(-4,0,0,CONCRETE:7)
Block(-4,0,1,CONCRETE:7)
Block(-4,0,2,CONCRETE:7)
Block(-4,0,3,CONCRETE:7)
Block(-4,0,4,CONCRETE:7)
Block(-4,0,5,CONCRETE:7)
Block(-4,0,6,CONCRETE:7)
Block(-4,0,7,CONCRETE:7)
Block(-4,0,8,CONCRETE:7)
Block(-4,1,-7,STATIONARY_WATER:0)
Block(-4,1,-6,STATIONARY_WATER:0)
Block(-4,1,-5,STATIONARY_WATER:0)
Block(-4,1,-4,STATIONARY_WATER:0)
Block(-4,1,-3,STATIONARY_WATER:0)
Block(-4,1,-2,STATIONARY_WATER:0)
Block(-4,1,-1,STATIONARY_WATER:0)
Block(-4,1,0,STATIONARY_WATER:0)
Block(-4,1,1,STATIONARY_WATER:0)
Block(-4,1,2,STATIONARY_WATER:0)
Block(-4,1,3,STATIONARY_WATER:0)
Block(-4,1,4,STATIONARY_WATER:0)
Block(-4,1,5,STATIONARY_WATER:0)
Block(-4,1,6,STATIONARY_WATER:0)
Block(-4,1,7,STATIONARY_WATER:0)
Block(-4,1,8,STATIONARY_WATER:0)
Block(-4,2,-7,AIR:0)
Block(-4,2,-6,AIR:0)
Block(-4,2,-5,AIR:0)
Block(-4,2,-4,AIR:0)
Block(-4,2,-3,AIR:0)
Block(-4,2,-2,AIR:0)
Block(-4,2,-1,AIR:0)
Block(-4,2,0,AIR:0)
Block(-4,2,1,AIR:0)
Block(-4,2,2,AIR:0)
Block(-4,2,3,AIR:0)
Block(-4,2,4,AIR:0)
Block(-4,2,5,AIR:0)
Block(-4,2,6,AIR:0)
Block(-4,2,7,AIR:0)
Block(-4,2,8,AIR:0)
Block(-4,3,-7,AIR:0)
Block(-4,3,-6,AIR:0)
Block(-4,3,-5,AIR:0)
Block(-4,3,-4,AIR:0)
Block(-4,3,-3,AIR:0)
Block(-4,3,-2,AIR:0)
Block(-4,3,-1,AIR:0)
Block(-4,3,0,AIR:0)
Block(-4,3,1,AIR:0)
Block(-4,3,2,AIR:0)
Block(-4,3,3,AIR:0)
Block(-4,3,4,AIR:0)
Block(-4,3,5,AIR:0)
Block(-4,3,6,AIR:0)
Block(-4,3,7,AIR:0)
Block(-4,3,8,AIR:0)
Block(-4,4,-7,AIR:0)
Block(-4,4,-6,AIR:0)
Block(-4,4,-5,AIR:0)
Block(-4,4,-4,AIR:0)
Block(-4,4,-3,AIR:0)
Block(-4,4,-2,AIR:0)
Block(-4,4,-1,AIR:0)
Block(-4,4,0,AIR:0)
Block(-4,4,1,AIR:0)
Block(-4,4,2,AIR:0)
Block(-4,4,3,AIR:0)
Block(-4,4,4,AIR:0)
Block(-4,4,5,AIR:0)
Block(-4,4,6,AIR:0)
Block(-4,4,7,AIR:0)
Block(-4,4,8,AIR:0)
Block(-4,5,-7,AIR:0)
Block(-4,5,-6,AIR:0)
Block(-4,5,-5,AIR:0)
Block(-4,5,-4,AIR:0)
Block(-4,5,-3,AIR:0)
Block(-4,5,-2,AIR:0)
Block(-4,5,-1,AIR:0)
Block(-4,5,0,AIR:0)
Block(-4,5,1,AIR:0)
Block(-4,5,2,AIR:0)
Block(-4,5,3,AIR:0)
Block(-4,5,4,AIR:0)
Block(-4,5,5,AIR:0)
Block(-4,5,6,CONCRETE:12)
Block(-4,5,7,CONCRETE:4)
Block(-4,5,8,AIR:0)
Block(-4,6,-7,CONCRETE:7)
Block(-4,6,-6,AIR:0)
Block(-4,6,-5,AIR:0)
Block(-4,6,-4,AIR:0)
Block(-4,6,-3,AIR:0)
Block(-4,6,-2,AIR:0)
Block(-4,6,-1,AIR:0)
Block(-4,6,0,AIR:0)
Block(-4,6,1,AIR:0)
Block(-4,6,2,AIR:0)
Block(-4,6,3,AIR:0)
Block(-4,6,4,AIR:0)
Block(-4,6,5,AIR:0)
Block(-4,6,6,AIR:0)
Block(-4,6,7,AIR:0)
Block(-4,6,8,AIR:0)
Block(-4,7,-7,CONCRETE:7)
Block(-4,7,-6,CONCRETE:7)
Block(-4,7,-5,CONCRETE:7)
Block(-4,7,-4,CONCRETE:7)
Block(-4,7,-3,CONCRETE:7)
Block(-4,7,-2,CONCRETE:7)
Block(-4,7,-1,CONCRETE:7)
Block(-4,7,0,CONCRETE:7)
Block(-4,7,1,CONCRETE:7)
Block(-4,7,2,CONCRETE:7)
Block(-4,7,3,CONCRETE:7)
Block(-4,7,4,CONCRETE:7)
Block(-4,7,5,CONCRETE:7)
Block(-4,7,6,CONCRETE:7)
Block(-4,7,7,CONCRETE:7)
Block(-4,7,8,CONCRETE:7)
Block(-4,8,-7,CONCRETE:7)
Block(-4,8,-6,CONCRETE:7)
Block(-4,8,-5,CONCRETE:7)
Block(-4,8,-4,CONCRETE:7)
Block(-4,8,-3,CONCRETE:7)
Block(-4,8,-2,CONCRETE:7)
Block(-4,8,-1,CONCRETE:7)
Block(-4,8,0,CONCRETE:7)
Block(-4,8,1,CONCRETE:7)
Block(-4,8,2,CONCRETE:7)
Block(-4,8,3,CONCRETE:7)
Block(-4,8,4,CONCRETE:7)
Block(-4,8,5,CONCRETE:7)
Block(-4,8,6,PISTON_STICKY_BASE:9)
Block(-4,8,7,REDSTONE_WIRE:8)
Block(-4,8,8,REDSTONE_WIRE:9)
Block(-4,9,-7,CONCRETE:7)
Block(-4,9,-6,CONCRETE:7)
Block(-4,9,-5,CONCRETE:7)
Block(-4,9,-4,CONCRETE:7)
Block(-4,9,-3,CONCRETE:7)
Block(-4,9,-2,CONCRETE:7)
Block(-4,9,-1,CONCRETE:7)
Block(-4,9,0,AIR:0)
Block(-4,9,1,AIR:0)
Block(-4,9,2,AIR:0)
Block(-4,9,3,AIR:0)
Block(-4,9,4,AIR:0)
Block(-4,9,5,CONCRETE:15)
Block(-4,9,6,PISTON_MOVING_PIECE:9)
Block(-4,9,7,CONCRETE:7)
Block(-4,9,8,CONCRETE:7)
Block(-4,10,-7,CONCRETE:7)
Block(-4,10,-6,CONCRETE:7)
Block(-4,10,-5,CONCRETE:7)
Block(-4,10,-4,CONCRETE:7)
Block(-4,10,-3,AIR:0)
Block(-4,10,-2,AIR:0)
Block(-4,10,-1,CONCRETE:7)
Block(-4,10,0,AIR:0)
Block(-4,10,1,AIR:0)
Block(-4,10,2,AIR:0)
Block(-4,10,3,AIR:0)
Block(-4,10,4,AIR:0)
Block(-4,10,5,AIR:0)
Block(-4,10,6,CONCRETE:4)
Block(-4,10,7,AIR:0)
Block(-4,10,8,AIR:0)
Block(-4,11,-7,CONCRETE:7)
Block(-4,11,-6,CONCRETE:7)
Block(-4,11,-5,CONCRETE:7)
Block(-4,11,-4,CONCRETE:7)
Block(-4,11,-3,AIR:0)
Block(-4,11,-2,AIR:0)
Block(-4,11,-1,CONCRETE:7)
Block(-4,11,0,AIR:0)
Block(-4,11,1,AIR:0)
Block(-4,11,2,AIR:0)
Block(-4,11,3,AIR:0)
Block(-4,11,4,AIR:0)
Block(-4,11,5,AIR:0)
Block(-4,11,6,CONCRETE:4)
Block(-4,11,7,AIR:0)
Block(-4,11,8,AIR:0)
Block(-4,12,-7,CONCRETE:7)
Block(-4,12,-6,CONCRETE:7)
Block(-4,12,-5,CONCRETE:7)
Block(-4,12,-4,CONCRETE:7)
Block(-4,12,-3,AIR:0)
Block(-4,12,-2,AIR:0)
Block(-4,12,-1,CONCRETE:7)
Block(-4,12,0,AIR:0)
Block(-4,12,1,AIR:0)
Block(-4,12,2,AIR:0)
Block(-4,12,3,AIR:0)
Block(-4,12,4,AIR:0)
Block(-4,12,5,CONCRETE:14)
Block(-4,12,6,PISTON_MOVING_PIECE:8)
Block(-4,12,7,CONCRETE:7)
Block(-4,12,8,AIR:0)
Block(-4,13,-7,CONCRETE:7)
Block(-4,13,-6,CONCRETE:7)
Block(-4,13,-5,CONCRETE:7)
Block(-4,13,-4,CONCRETE:7)
Block(-4,13,-3,STEP:8)
Block(-4,13,-2,STEP:8)
Block(-4,13,-1,CONCRETE:7)
Block(-4,13,0,AIR:0)
Block(-4,13,1,AIR:0)
Block(-4,13,2,AIR:0)
Block(-4,13,3,AIR:0)
Block(-4,13,4,AIR:0)
Block(-4,13,5,CONCRETE:7)
Block(-4,13,6,PISTON_STICKY_BASE:8)
Block(-4,13,7,CONCRETE:7)
Block(-4,13,8,AIR:0)
Block(-4,14,-7,CONCRETE:7)
Block(-4,14,-6,CONCRETE:7)
Block(-4,14,-5,CONCRETE:7)
Block(-4,14,-4,CONCRETE:7)
Block(-4,14,-3,DROPPER:3,NBT/skyscraper_2x2_04/388-dropperC16R0.nbt)
Block(-4,14,-2,AIR:0)
Block(-4,14,-1,SMOOTH_STAIRS:3)
Block(-4,14,0,AIR:0)
Block(-4,14,1,AIR:0)
Block(-4,14,2,AIR:0)
Block(-4,14,3,AIR:0)
Block(-4,14,4,AIR:0)
Block(-4,14,5,CONCRETE:7)
Block(-4,14,6,OBSIDIAN:0)
Block(-4,14,7,CONCRETE:7)
Block(-4,14,8,AIR:0)
Block(-4,15,-7,CONCRETE:7)
Block(-4,15,-6,CONCRETE:7)
Block(-4,15,-5,CONCRETE:7)
Block(-4,15,-4,CONCRETE:7)
Block(-4,15,-3,DROPPER:3,NBT/skyscraper_2x2_04/389-dropperC16R0.nbt)
Block(-4,15,-2,AIR:0)
Block(-4,15,-1,STEP:8)
Block(-4,15,0,AIR:0)
Block(-4,15,1,AIR:0)
Block(-4,15,2,AIR:0)
Block(-4,15,3,AIR:0)
Block(-4,15,4,AIR:0)
Block(-4,15,5,CONCRETE:7)
