
#######################################################################
# +-----------------------------------------------------------------+ #
# |                            BO4 object                           | #
# +-----------------------------------------------------------------+ #
#######################################################################

Author: NLBlackEagle

Description: No description given

SettingsMode: WriteDisable


#######################################################################
# +-----------------------------------------------------------------+ #
# |                          Main settings                          | #
# +-----------------------------------------------------------------+ #
#######################################################################

Frequency: 0

SpawnHeight: highestBlock

UseCenterForHighestBlock: true

##############################
# Height Limits for the BO4. #
##############################

MinHeight: 0

MaxHeight: 255

InheritBO3: 

InheritBO3Rotation: NORTH

OverrideChildSettings: true

OverrideParentHeight: false

CanOverride: true

BranchFrequency: 0

BranchFrequencyGroup: 

MustBeBelowOther: false

MustBeInside: 

CannotBeInside: 

ReplacesBO3: L4-M-CrossC0R0, L4-M-CrossC0R1, L4-M-CrossC0R2, L4-M-CrossC0R3, L4-M-CrossC1R0, L4-M-CrossC1R1, L4-M-CrossC1R2, L4-M-CrossC1R3, L4-M-CrossC2R0, L4-M-CrossC2R1, L4-M-CrossC2R2, L4-M-CrossC2R3, L4-M-CrossC3R0, L4-M-CrossC3R1, L4-M-CrossC3R2, L4-M-CrossC3R3, L4-M-Straigth-START_01-C0R0, L4-M-Straigth-START_01-C0R1, L4-M-Straigth-START_01-C1R0, L4-M-Straigth-START_01-C1R1, L4-M-Straigth-START_01-C2R0, L4-M-Straigth-START_01-C2R1, L4-M-Straigth-START_01-C3R0, L4-M-Straigth-START_01-C3R1, L4-M-Straigth-3CC0R0, L4-M-Straigth-3CC0R1, L4-M-Straigth-3CC0R2, L4-M-Straigth-3CC1R0, L4-M-Straigth-3CC1R1, L4-M-Straigth-3CC1R2, L4-M-Straigth-3CC2R0, L4-M-Straigth-3CC2R1, L4-M-Straigth-3CC2R2, L4-M-Straigth-3CC3R0, L4-M-Straigth-3CC3R1, L4-M-Straigth-3CC3R2, L4-M-Cross, skyscraper_2x2_01, skyscraper_2x2_02, skyscraper_2x2_03, skyscraper_2x2_04, skyscraper_2x2_05, skyscraper_3x3_01, skyscraper_3x3_02, skyscraper_3x3_03, L3-M-Straigth-2CC0R0, L3-M-Straigth-2CC0R1, L3-M-Straigth-2CC1R0, L3-M-Straigth-2CC1R1, L3-M-Straigth-2CC2R0, L3-M-Straigth-2CC2R1, L3-M-Straigth-2CC3R0, L3-M-Straigth-2CC3R1, L3-M-Straigth-3CC0R0, L3-M-Straigth-3CC0R1, L3-M-Straigth-3CC0R2, L3-M-Straigth-3CC1R0, L3-M-Straigth-3CC1R1, L3-M-Straigth-3CC1R2, L3-M-Straigth-3CC2R0, L3-M-Straigth-3CC2R1, L3-M-Straigth-3CC2R2, L3-M-Straigth-3CC3R0, L3-M-Straigth-3CC3R1, L3-M-Straigth-3CC3R2L4-M-CrossC0R0, L4-M-CrossC0R1, L4-M-CrossC0R2, L4-M-CrossC0R3, L4-M-CrossC1R0, L4-M-CrossC1R1, L4-M-CrossC1R2, L4-M-CrossC1R3, L4-M-CrossC2R0, L4-M-CrossC2R1, L4-M-CrossC2R2, L4-M-CrossC2R3, L4-M-CrossC3R0, L4-M-CrossC3R1, L4-M-CrossC3R2, L4-M-CrossC3R3, L4-M-Straigth-START_01-C0R0, L4-M-Straigth-START_01-C0R1, L4-M-Straigth-START_01-C1R0, L4-M-Straigth-START_01-C1R1, L4-M-Straigth-START_01-C2R0, L4-M-Straigth-START_01-C2R1, L4-M-Straigth-START_01-C3R0, L4-M-Straigth-START_01-C3R1, L4-M-Straigth-3CC0R0, L4-M-Straigth-3CC0R1, L4-M-Straigth-3CC0R2, L4-M-Straigth-3CC1R0, L4-M-Straigth-3CC1R1, L4-M-Straigth-3CC1R2, L4-M-Straigth-3CC2R0, L4-M-Straigth-3CC2R1, L4-M-Straigth-3CC2R2, L4-M-Straigth-3CC3R0, L4-M-Straigth-3CC3R1, L4-M-Straigth-3CC3R2, L4-M-Cross, skyscraper_2x2_01, skyscraper_2x2_02, skyscraper_2x2_03, skyscraper_2x2_04, skyscraper_2x2_05, skyscraper_3x3_01, skyscraper_3x3_02, skyscraper_3x3_03

MustBeInsideWorldBorders: false

CanSpawnOnWater: true

SpawnOnWaterOnly: false

SpawnUnderWater: false

SpawnAtWaterLevel: false

HeightOffset: 0

RemoveAir: false

ReplaceAbove: 

ReplaceBelow: 

ReplaceWithBiomeBlocks: true

ReplaceWithSurfaceBlock: GRASS

ReplaceWithGroundBlock: DIRT

ReplaceWithStoneBlock: STONE

SmoothRadius: 0

SmoothHeightOffset: 0

SmoothStartTop: false

SmoothStartWood: false

SmoothingSurfaceBlock: 

SmoothingGroundBlock: 

BO3Group: 

IsSpawnPoint: false

DoReplaceBlocks: true


#######################################################################
# +-----------------------------------------------------------------+ #
# |                              Blocks                             | #
# +-----------------------------------------------------------------+ #
#######################################################################

Block(-8,0,-7,CONCRETE:7)
Block(-8,0,-6,CONCRETE:7)
Block(-8,0,-5,CONCRETE:7)
Block(-8,0,-4,CONCRETE:7)
Block(-8,0,-3,CONCRETE:7)
Block(-8,0,-2,CONCRETE:7)
Block(-8,0,-1,CONCRETE:7)
Block(-8,0,0,CONCRETE:7)
Block(-8,0,1,CONCRETE:7)
Block(-8,0,2,CONCRETE:7)
Block(-8,0,3,CONCRETE:7)
Block(-8,0,4,CONCRETE:7)
Block(-8,0,5,CONCRETE:7)
Block(-8,0,6,CONCRETE:7)
Block(-8,0,7,CONCRETE:7)
Block(-8,0,8,CONCRETE:7)
Block(-8,1,-7,CONCRETE:7)
Block(-8,1,-6,CONCRETE:7)
Block(-8,1,-5,CONCRETE:7)
Block(-8,1,-4,CONCRETE:7)
Block(-8,1,-3,CONCRETE:7)
Block(-8,1,-2,CONCRETE:7)
Block(-8,1,-1,CONCRETE:7)
Block(-8,1,0,CONCRETE:7)
Block(-8,1,1,CONCRETE:7)
Block(-8,1,2,CONCRETE:7)
Block(-8,1,3,CONCRETE:7)
Block(-8,1,4,CONCRETE:7)
Block(-8,1,5,CONCRETE:7)
Block(-8,1,6,CONCRETE:7)
Block(-8,1,7,CONCRETE:7)
Block(-8,1,8,CONCRETE:7)
Block(-8,2,-7,CONCRETE:7)
Block(-8,2,-6,CONCRETE:7)
Block(-8,2,-5,CONCRETE:7)
Block(-8,2,-4,CONCRETE:7)
Block(-8,2,-3,CONCRETE:7)
Block(-8,2,-2,CONCRETE:7)
Block(-8,2,-1,CONCRETE:7)
Block(-8,2,0,CONCRETE:7)
Block(-8,2,1,CONCRETE:7)
Block(-8,2,2,CONCRETE:7)
Block(-8,2,3,CONCRETE:7)
Block(-8,2,4,CONCRETE:7)
Block(-8,2,5,CONCRETE:7)
Block(-8,2,6,CONCRETE:7)
Block(-8,2,7,CONCRETE:7)
Block(-8,2,8,CONCRETE:7)
Block(-8,3,-7,CONCRETE:7)
Block(-8,3,-6,CONCRETE:7)
Block(-8,3,-5,CONCRETE:7)
Block(-8,3,-4,CONCRETE:7)
Block(-8,3,-3,CONCRETE:7)
Block(-8,3,-2,CONCRETE:7)
Block(-8,3,-1,CONCRETE:7)
Block(-8,3,0,CONCRETE:7)
Block(-8,3,1,CONCRETE:7)
Block(-8,3,2,CONCRETE:7)
Block(-8,3,3,CONCRETE:7)
Block(-8,3,4,CONCRETE:7)
Block(-8,3,5,CONCRETE:7)
Block(-8,3,6,CONCRETE:7)
Block(-8,3,7,CONCRETE:7)
Block(-8,3,8,CONCRETE:7)
Block(-8,4,-7,CONCRETE:7)
Block(-8,4,-6,CONCRETE:7)
Block(-8,4,-5,CONCRETE:7)
Block(-8,4,-4,CONCRETE:7)
Block(-8,4,-3,CONCRETE:7)
Block(-8,4,-2,CONCRETE:7)
Block(-8,4,-1,CONCRETE:7)
Block(-8,4,0,CONCRETE:7)
Block(-8,4,1,CONCRETE:7)
Block(-8,4,2,CONCRETE:7)
Block(-8,4,3,CONCRETE:7)
Block(-8,4,4,CONCRETE:7)
Block(-8,4,5,CONCRETE:7)
Block(-8,4,6,CONCRETE:7)
Block(-8,4,7,CONCRETE:7)
Block(-8,4,8,CONCRETE:7)
Block(-8,5,-7,CONCRETE:7)
Block(-8,5,-6,CONCRETE:7)
Block(-8,5,-5,CONCRETE:7)
Block(-8,5,-4,CONCRETE:7)
Block(-8,5,-3,CONCRETE:7)
Block(-8,5,-2,CONCRETE:7)
Block(-8,5,-1,CONCRETE:7)
Block(-8,5,0,CONCRETE:7)
Block(-8,5,1,CONCRETE:7)
Block(-8,5,2,CONCRETE:7)
Block(-8,5,3,CONCRETE:7)
Block(-8,5,4,CONCRETE:7)
Block(-8,5,5,CONCRETE:7)
Block(-8,5,6,CONCRETE:7)
Block(-8,5,7,CONCRETE:7)
Block(-8,5,8,CONCRETE:7)
Block(-8,6,-7,CONCRETE:7)
Block(-8,6,-6,CONCRETE:7)
Block(-8,6,-5,CONCRETE:7)
Block(-8,6,-4,CONCRETE:7)
Block(-8,6,-3,CONCRETE:7)
Block(-8,6,-2,CONCRETE:7)
Block(-8,6,-1,CONCRETE:7)
Block(-8,6,0,CONCRETE:7)
Block(-8,6,1,CONCRETE:7)
Block(-8,6,2,CONCRETE:7)
Block(-8,6,3,CONCRETE:7)
Block(-8,6,4,CONCRETE:7)
Block(-8,6,5,CONCRETE:7)
Block(-8,6,6,CONCRETE:7)
Block(-8,6,7,CONCRETE:7)
Block(-8,6,8,CONCRETE:7)
Block(-8,7,-7,CONCRETE:7)
Block(-8,7,-6,CONCRETE:7)
Block(-8,7,-5,CONCRETE:7)
Block(-8,7,-4,CONCRETE:7)
Block(-8,7,-3,CONCRETE:7)
Block(-8,7,-2,CONCRETE:7)
Block(-8,7,-1,CONCRETE:7)
Block(-8,7,0,CONCRETE:7)
Block(-8,7,1,CONCRETE:7)
Block(-8,7,2,CONCRETE:7)
Block(-8,7,3,CONCRETE:7)
Block(-8,7,4,CONCRETE:7)
Block(-8,7,5,CONCRETE:7)
Block(-8,7,6,CONCRETE:7)
Block(-8,7,7,CONCRETE:7)
Block(-8,7,8,CONCRETE:7)
Block(-8,8,-7,CONCRETE:7)
Block(-8,8,-6,CONCRETE:7)
Block(-8,8,-5,CONCRETE:7)
Block(-8,8,-4,CONCRETE:7)
Block(-8,8,-3,CONCRETE:7)
Block(-8,8,-2,CONCRETE:7)
Block(-8,8,-1,CONCRETE:7)
Block(-8,8,0,CONCRETE:7)
Block(-8,8,1,CONCRETE:7)
Block(-8,8,2,CONCRETE:7)
Block(-8,8,3,CONCRETE:7)
Block(-8,8,4,CONCRETE:7)
Block(-8,8,5,CONCRETE:7)
Block(-8,8,6,CONCRETE:7)
Block(-8,8,7,CONCRETE:7)
Block(-8,8,8,CONCRETE:7)
Block(-8,9,-7,CONCRETE:7)
Block(-8,9,-6,CONCRETE:7)
Block(-8,9,-5,CONCRETE:7)
Block(-8,9,-4,CONCRETE:7)
Block(-8,9,-3,CONCRETE:7)
Block(-8,9,-2,CONCRETE:7)
Block(-8,9,-1,CONCRETE:7)
Block(-8,9,0,CONCRETE:7)
Block(-8,9,1,CONCRETE:7)
Block(-8,9,2,CONCRETE:7)
Block(-8,9,3,CONCRETE:7)
Block(-8,9,4,CONCRETE:7)
Block(-8,9,5,CONCRETE:7)
Block(-8,9,6,CONCRETE:7)
Block(-8,9,7,CONCRETE:7)
Block(-8,9,8,CONCRETE:7)
Block(-8,10,-7,CONCRETE:7)
Block(-8,10,-6,CONCRETE:7)
Block(-8,10,-5,CONCRETE:7)
Block(-8,10,-4,CONCRETE:7)
Block(-8,10,-3,CONCRETE:7)
Block(-8,10,-2,CONCRETE:7)
Block(-8,10,-1,CONCRETE:7)
Block(-8,10,0,CONCRETE:7)
Block(-8,10,1,CONCRETE:7)
Block(-8,10,2,CONCRETE:7)
Block(-8,10,3,CONCRETE:7)
Block(-8,10,4,CONCRETE:7)
Block(-8,10,5,CONCRETE:7)
Block(-8,10,6,CONCRETE:7)
Block(-8,10,7,CONCRETE:7)
Block(-8,10,8,CONCRETE:7)
Block(-8,11,-7,CONCRETE:7)
Block(-8,11,-6,CONCRETE:7)
Block(-8,11,-5,CONCRETE:7)
Block(-8,11,-4,CONCRETE:7)
Block(-8,11,-3,CONCRETE:7)
Block(-8,11,-2,CONCRETE:7)
Block(-8,11,-1,CONCRETE:7)
Block(-8,11,0,CONCRETE:7)
Block(-8,11,1,CONCRETE:7)
Block(-8,11,2,CONCRETE:7)
Block(-8,11,3,CONCRETE:7)
Block(-8,11,4,CONCRETE:7)
Block(-8,11,5,CONCRETE:7)
Block(-8,11,6,CONCRETE:7)
Block(-8,11,7,CONCRETE:7)
Block(-8,11,8,CONCRETE:7)
Block(-8,12,-7,CONCRETE:7)
Block(-8,12,-6,CONCRETE:7)
Block(-8,12,-5,CONCRETE:7)
Block(-8,12,-4,CONCRETE:7)
Block(-8,12,-3,CONCRETE:7)
Block(-8,12,-2,CONCRETE:7)
Block(-8,12,-1,CONCRETE:7)
Block(-8,12,0,CONCRETE:7)
Block(-8,12,1,CONCRETE:7)
Block(-8,12,2,CONCRETE:7)
Block(-8,12,3,CONCRETE:7)
Block(-8,12,4,CONCRETE:7)
Block(-8,12,5,CONCRETE:7)
Block(-8,12,6,CONCRETE:7)
Block(-8,12,7,CONCRETE:7)
Block(-8,12,8,CONCRETE:7)
Block(-8,13,-7,CONCRETE:7)
Block(-8,13,-6,CONCRETE:7)
Block(-8,13,-5,CONCRETE:7)
Block(-8,13,-4,CONCRETE:7)
Block(-8,13,-3,CONCRETE:7)
Block(-8,13,-2,CONCRETE:7)
Block(-8,13,-1,CONCRETE:7)
Block(-8,13,0,CONCRETE:7)
Block(-8,13,1,CONCRETE:7)
Block(-8,13,2,CONCRETE:7)
Block(-8,13,3,CONCRETE:7)
Block(-8,13,4,CONCRETE:7)
Block(-8,13,5,CONCRETE:7)
Block(-8,13,6,CONCRETE:7)
Block(-8,13,7,CONCRETE:7)
Block(-8,13,8,CONCRETE:7)
Block(-8,14,-7,CONCRETE:7)
Block(-8,14,-6,CONCRETE:7)
Block(-8,14,-5,CONCRETE:7)
Block(-8,14,-4,CONCRETE:7)
Block(-8,14,-3,CONCRETE:7)
Block(-8,14,-2,CONCRETE:7)
Block(-8,14,-1,CONCRETE:7)
Block(-8,14,0,CONCRETE:7)
Block(-8,14,1,CONCRETE:7)
Block(-8,14,2,CONCRETE:7)
Block(-8,14,3,CONCRETE:7)
Block(-8,14,4,CONCRETE:7)
Block(-8,14,5,CONCRETE:7)
Block(-8,14,6,CONCRETE:7)
Block(-8,14,7,CONCRETE:7)
Block(-8,14,8,CONCRETE:7)
Block(-8,15,-7,CONCRETE:7)
Block(-8,15,-6,CONCRETE:7)
Block(-8,15,-5,CONCRETE:7)
Block(-8,15,-4,CONCRETE:7)
Block(-8,15,-3,CONCRETE:7)
Block(-8,15,-2,CONCRETE:7)
Block(-8,15,-1,CONCRETE:7)
Block(-8,15,0,CONCRETE:7)
Block(-8,15,1,CONCRETE:7)
Block(-8,15,2,CONCRETE:7)
Block(-8,15,3,CONCRETE:7)
Block(-8,15,4,CONCRETE:7)
Block(-8,15,5,CONCRETE:7)
Block(-8,15,6,CONCRETE:7)
Block(-8,15,7,CONCRETE:7)
Block(-8,15,8,CONCRETE:7)
Block(-8,16,-7,CONCRETE:7)
Block(-8,16,-6,CONCRETE:7)
Block(-8,16,-5,CONCRETE:7)
Block(-8,16,-4,CONCRETE:7)
Block(-8,16,-3,CONCRETE:7)
Block(-8,16,-2,CONCRETE:7)
Block(-8,16,-1,CONCRETE:7)
Block(-8,16,0,CONCRETE:7)
Block(-8,16,1,CONCRETE:7)
Block(-8,16,2,CONCRETE:7)
Block(-8,16,3,CONCRETE:7)
Block(-8,16,4,CONCRETE:7)
Block(-8,16,5,CONCRETE:7)
Block(-8,16,6,CONCRETE:7)
Block(-8,16,7,CONCRETE:7)
Block(-8,16,8,CONCRETE:7)
Block(-8,17,-7,CONCRETE:7)
Block(-8,17,-6,CONCRETE:7)
Block(-8,17,-5,CONCRETE:7)
Block(-8,17,-4,CONCRETE:7)
Block(-8,17,-3,CONCRETE:7)
Block(-8,17,-2,CONCRETE:7)
Block(-8,17,-1,CONCRETE:7)
Block(-8,17,0,CONCRETE:7)
Block(-8,17,1,CONCRETE:7)
Block(-8,17,2,CONCRETE:7)
Block(-8,17,3,CONCRETE:7)
Block(-8,17,4,CONCRETE:7)
Block(-8,17,5,CONCRETE:7)
Block(-8,17,6,CONCRETE:7)
Block(-8,17,7,CONCRETE:7)
Block(-8,17,8,CONCRETE:7)
Block(-8,25,-7,CONCRETE:8)
Block(-8,25,-6,CONCRETE:8)
Block(-8,25,-5,CONCRETE:8)
Block(-8,25,-4,CONCRETE:8)
Block(-8,25,-3,CONCRETE:8)
Block(-8,25,-2,CONCRETE:8)
Block(-8,25,-1,CONCRETE:8)
Block(-8,25,0,CONCRETE:8)
Block(-8,25,1,CONCRETE:8)
Block(-8,25,2,CONCRETE:8)
Block(-8,25,3,CONCRETE:8)
Block(-8,25,4,CONCRETE:8)
Block(-8,25,5,CONCRETE:8)
Block(-8,25,6,CONCRETE:8)
Block(-8,25,7,CONCRETE:8)
Block(-8,25,8,CONCRETE:8)
Block(-8,26,-7,STAINED_GLASS_PANE:15)
Block(-8,26,-6,STAINED_GLASS_PANE:15)
Block(-8,26,-5,STAINED_GLASS_PANE:15)
Block(-8,26,-4,STAINED_GLASS_PANE:15)
Block(-8,26,-3,STAINED_GLASS_PANE:15)
Block(-8,26,-2,STAINED_GLASS_PANE:15)
Block(-8,26,-1,STAINED_GLASS_PANE:15)
Block(-8,26,0,STAINED_GLASS_PANE:15)
Block(-8,26,1,STAINED_GLASS_PANE:15)
Block(-8,26,2,STAINED_GLASS_PANE:15)
Block(-8,26,3,STAINED_GLASS_PANE:15)
Block(-8,26,4,STAINED_GLASS_PANE:15)
Block(-8,26,5,STAINED_GLASS_PANE:15)
Block(-8,26,6,STAINED_GLASS_PANE:15)
Block(-8,26,7,STAINED_GLASS_PANE:15)
Block(-8,26,8,STAINED_GLASS_PANE:15)
Block(-8,29,-7,CONCRETE:8)
Block(-8,29,-6,CONCRETE:8)
Block(-8,29,-5,CONCRETE:8)
Block(-8,29,-4,CONCRETE:8)
Block(-8,29,-3,CONCRETE:8)
Block(-8,29,-2,CONCRETE:8)
Block(-8,29,-1,CONCRETE:8)
Block(-8,29,0,CONCRETE:8)
Block(-8,29,1,CONCRETE:8)
Block(-8,29,2,CONCRETE:8)
Block(-8,29,3,CONCRETE:8)
Block(-8,29,4,CONCRETE:8)
Block(-8,29,5,CONCRETE:8)
Block(-8,29,6,CONCRETE:8)
Block(-8,29,7,CONCRETE:8)
Block(-8,29,8,CONCRETE:8)
Block(-8,30,-7,STAINED_GLASS_PANE:15)
Block(-8,30,-6,STAINED_GLASS_PANE:15)
Block(-8,30,-5,STAINED_GLASS_PANE:15)
Block(-8,30,-4,STAINED_GLASS_PANE:15)
Block(-8,30,-3,STAINED_GLASS_PANE:15)
Block(-8,30,-2,STAINED_GLASS_PANE:15)
Block(-8,30,-1,STAINED_GLASS_PANE:15)
Block(-8,30,0,STAINED_GLASS_PANE:15)
Block(-8,30,1,STAINED_GLASS_PANE:15)
Block(-8,30,2,STAINED_GLASS_PANE:15)
Block(-8,30,3,STAINED_GLASS_PANE:15)
Block(-8,30,4,STAINED_GLASS_PANE:15)
Block(-8,30,5,STAINED_GLASS_PANE:15)
Block(-8,30,6,STAINED_GLASS_PANE:15)
Block(-8,30,7,STAINED_GLASS_PANE:15)
Block(-8,30,8,STAINED_GLASS_PANE:15)
Block(-8,33,-7,CONCRETE:8)
Block(-8,33,-6,CONCRETE:8)
Block(-8,33,-5,CONCRETE:8)
Block(-8,33,-4,CONCRETE:8)
Block(-8,33,-3,CONCRETE:8)
Block(-8,33,-2,CONCRETE:8)
Block(-8,33,-1,CONCRETE:8)
Block(-8,33,0,CONCRETE:8)
Block(-8,33,1,CONCRETE:8)
Block(-8,33,2,CONCRETE:8)
Block(-8,33,3,CONCRETE:8)
Block(-8,33,4,CONCRETE:8)
Block(-8,33,5,CONCRETE:8)
Block(-8,33,6,CONCRETE:8)
Block(-8,33,7,CONCRETE:8)
Block(-8,33,8,CONCRETE:8)
Block(-8,34,-7,STAINED_GLASS_PANE:15)
Block(-8,34,-6,STAINED_GLASS_PANE:15)
Block(-8,34,-5,STAINED_GLASS_PANE:15)
Block(-8,34,-4,STAINED_GLASS_PANE:15)
Block(-8,34,-3,STAINED_GLASS_PANE:15)
Block(-8,34,-2,STAINED_GLASS_PANE:15)
Block(-8,34,-1,STAINED_GLASS_PANE:15)
Block(-8,34,0,STAINED_GLASS_PANE:15)
Block(-8,34,1,STAINED_GLASS_PANE:15)
Block(-8,34,2,STAINED_GLASS_PANE:15)
Block(-8,34,3,STAINED_GLASS_PANE:15)
Block(-8,34,4,STAINED_GLASS_PANE:15)
Block(-8,34,5,STAINED_GLASS_PANE:15)
Block(-8,34,6,STAINED_GLASS_PANE:15)
Block(-8,34,7,STAINED_GLASS_PANE:15)
Block(-8,34,8,STAINED_GLASS_PANE:15)
Block(-8,37,-7,CONCRETE:8)
Block(-8,37,-6,CONCRETE:8)
Block(-8,37,-5,CONCRETE:8)
Block(-8,37,-4,CONCRETE:8)
Block(-8,37,-3,CONCRETE:8)
Block(-8,37,-2,CONCRETE:8)
Block(-8,37,-1,CONCRETE:8)
Block(-8,37,0,CONCRETE:8)
Block(-8,37,1,CONCRETE:8)
Block(-8,37,2,CONCRETE:8)
Block(-8,37,3,CONCRETE:8)
Block(-8,37,4,CONCRETE:8)
Block(-8,37,5,CONCRETE:8)
Block(-8,37,6,CONCRETE:8)
Block(-8,37,7,CONCRETE:8)
Block(-8,37,8,CONCRETE:8)
Block(-8,38,-7,STAINED_GLASS_PANE:15)
Block(-8,38,-6,STAINED_GLASS_PANE:15)
Block(-8,38,-5,STAINED_GLASS_PANE:15)
Block(-8,38,-4,STAINED_GLASS_PANE:15)
Block(-8,38,-3,STAINED_GLASS_PANE:15)
Block(-8,38,-2,STAINED_GLASS_PANE:15)
Block(-8,38,-1,STAINED_GLASS_PANE:15)
Block(-8,38,0,STAINED_GLASS_PANE:15)
Block(-8,38,1,STAINED_GLASS_PANE:15)
Block(-8,38,2,STAINED_GLASS_PANE:15)
Block(-8,38,3,STAINED_GLASS_PANE:15)
Block(-8,38,4,STAINED_GLASS_PANE:15)
Block(-8,38,5,STAINED_GLASS_PANE:15)
Block(-8,38,6,STAINED_GLASS_PANE:15)
Block(-8,38,7,STAINED_GLASS_PANE:15)
Block(-8,38,8,STAINED_GLASS_PANE:15)
Block(-8,41,-7,CONCRETE:8)
Block(-8,41,-6,CONCRETE:8)
Block(-8,41,-5,CONCRETE:8)
Block(-8,41,-4,CONCRETE:8)
Block(-8,41,-3,CONCRETE:8)
Block(-8,41,-2,CONCRETE:8)
Block(-8,41,-1,CONCRETE:8)
Block(-8,41,0,CONCRETE:8)
Block(-8,41,1,CONCRETE:8)
Block(-8,41,2,CONCRETE:8)
Block(-8,41,3,CONCRETE:8)
Block(-8,41,4,CONCRETE:8)
Block(-8,41,5,CONCRETE:8)
Block(-8,41,6,CONCRETE:8)
Block(-8,41,7,CONCRETE:8)
Block(-8,41,8,CONCRETE:8)
Block(-8,42,-7,STAINED_GLASS_PANE:15)
Block(-8,42,-6,STAINED_GLASS_PANE:15)
Block(-8,42,-5,STAINED_GLASS_PANE:15)
Block(-8,42,-4,STAINED_GLASS_PANE:15)
Block(-8,42,-3,STAINED_GLASS_PANE:15)
Block(-8,42,-2,STAINED_GLASS_PANE:15)
Block(-8,42,-1,STAINED_GLASS_PANE:15)
Block(-8,42,0,STAINED_GLASS_PANE:15)
Block(-8,42,1,STAINED_GLASS_PANE:15)
Block(-8,42,2,STAINED_GLASS_PANE:15)
Block(-8,42,3,STAINED_GLASS_PANE:15)
Block(-8,42,4,STAINED_GLASS_PANE:15)
Block(-8,42,5,STAINED_GLASS_PANE:15)
Block(-8,42,6,STAINED_GLASS_PANE:15)
Block(-8,42,7,STAINED_GLASS_PANE:15)
Block(-8,42,8,STAINED_GLASS_PANE:15)
Block(-8,45,-7,CONCRETE:8)
Block(-8,45,-6,CONCRETE:8)
Block(-8,45,-5,CONCRETE:8)
Block(-8,45,-4,CONCRETE:8)
Block(-8,45,-3,CONCRETE:8)
Block(-8,45,-2,CONCRETE:8)
Block(-8,45,-1,CONCRETE:8)
Block(-8,45,0,CONCRETE:8)
Block(-8,45,1,CONCRETE:8)
Block(-8,45,2,CONCRETE:8)
Block(-8,45,3,CONCRETE:8)
Block(-8,45,4,CONCRETE:8)
Block(-8,45,5,CONCRETE:8)
Block(-8,45,6,CONCRETE:8)
Block(-8,45,7,CONCRETE:8)
Block(-8,45,8,CONCRETE:8)
Block(-8,46,-7,STAINED_GLASS_PANE:15)
Block(-8,46,-6,STAINED_GLASS_PANE:15)
Block(-8,46,-5,STAINED_GLASS_PANE:15)
Block(-8,46,-4,STAINED_GLASS_PANE:15)
Block(-8,46,-3,STAINED_GLASS_PANE:15)
Block(-8,46,-2,STAINED_GLASS_PANE:15)
Block(-8,46,-1,STAINED_GLASS_PANE:15)
Block(-8,46,0,STAINED_GLASS_PANE:15)
Block(-8,46,1,STAINED_GLASS_PANE:15)
Block(-8,46,2,STAINED_GLASS_PANE:15)
Block(-8,46,3,STAINED_GLASS_PANE:15)
Block(-8,46,4,STAINED_GLASS_PANE:15)
Block(-8,46,5,STAINED_GLASS_PANE:15)
Block(-8,46,6,STAINED_GLASS_PANE:15)
Block(-8,46,7,STAINED_GLASS_PANE:15)
Block(-8,46,8,STAINED_GLASS_PANE:15)
Block(-8,49,-7,CONCRETE:8)
Block(-8,49,-6,CONCRETE:8)
Block(-8,49,-5,CONCRETE:8)
Block(-8,49,-4,CONCRETE:8)
Block(-8,49,-3,CONCRETE:8)
Block(-8,49,-2,CONCRETE:8)
Block(-8,49,-1,CONCRETE:8)
Block(-8,49,0,CONCRETE:8)
Block(-8,49,1,CONCRETE:8)
Block(-8,49,2,CONCRETE:8)
Block(-8,49,3,CONCRETE:8)
Block(-8,49,4,CONCRETE:8)
Block(-8,49,5,CONCRETE:8)
Block(-8,49,6,CONCRETE:8)
Block(-8,49,7,CONCRETE:8)
Block(-8,49,8,CONCRETE:8)
Block(-8,50,-7,STAINED_GLASS_PANE:15)
Block(-8,50,-6,STAINED_GLASS_PANE:15)
Block(-8,50,-5,STAINED_GLASS_PANE:15)
Block(-8,50,-4,STAINED_GLASS_PANE:15)
Block(-8,50,-3,STAINED_GLASS_PANE:15)
Block(-8,50,-2,STAINED_GLASS_PANE:15)
Block(-8,50,-1,STAINED_GLASS_PANE:15)
Block(-8,50,0,STAINED_GLASS_PANE:15)
Block(-8,50,1,STAINED_GLASS_PANE:15)
Block(-8,50,2,STAINED_GLASS_PANE:15)
Block(-8,50,3,STAINED_GLASS_PANE:15)
Block(-8,50,4,STAINED_GLASS_PANE:15)
Block(-8,50,5,STAINED_GLASS_PANE:15)
Block(-8,50,6,STAINED_GLASS_PANE:15)
Block(-8,50,7,STAINED_GLASS_PANE:15)
Block(-8,50,8,STAINED_GLASS_PANE:15)
Block(-8,53,-7,CONCRETE:8)
Block(-8,53,-6,CONCRETE:8)
Block(-8,53,-5,CONCRETE:8)
Block(-8,53,-4,CONCRETE:8)
Block(-8,53,-3,CONCRETE:8)
Block(-8,53,-2,CONCRETE:8)
Block(-8,53,-1,CONCRETE:8)
Block(-8,53,0,CONCRETE:8)
Block(-8,53,1,CONCRETE:8)
Block(-8,53,2,CONCRETE:8)
Block(-8,53,3,CONCRETE:8)
Block(-8,53,4,CONCRETE:8)
Block(-8,53,5,CONCRETE:8)
Block(-8,53,6,CONCRETE:8)
Block(-8,53,7,CONCRETE:8)
Block(-8,53,8,CONCRETE:8)
Block(-8,54,-7,STAINED_GLASS_PANE:15)
Block(-8,54,-6,STAINED_GLASS_PANE:15)
Block(-8,54,-5,STAINED_GLASS_PANE:15)
Block(-8,54,-4,STAINED_GLASS_PANE:15)
Block(-8,54,-3,STAINED_GLASS_PANE:15)
Block(-8,54,-2,STAINED_GLASS_PANE:15)
Block(-8,54,-1,STAINED_GLASS_PANE:15)
Block(-8,54,0,STAINED_GLASS_PANE:15)
Block(-8,54,1,STAINED_GLASS_PANE:15)
Block(-8,54,2,STAINED_GLASS_PANE:15)
Block(-8,54,3,STAINED_GLASS_PANE:15)
Block(-8,54,4,STAINED_GLASS_PANE:15)
Block(-8,54,5,STAINED_GLASS_PANE:15)
Block(-8,54,6,STAINED_GLASS_PANE:15)
Block(-8,54,7,STAINED_GLASS_PANE:15)
Block(-8,54,8,STAINED_GLASS_PANE:15)
Block(-8,57,-7,CONCRETE:8)
Block(-8,57,-6,CONCRETE:8)
Block(-8,57,-5,CONCRETE:8)
Block(-8,57,-4,CONCRETE:8)
Block(-8,57,-3,CONCRETE:8)
Block(-8,57,-2,CONCRETE:8)
Block(-8,57,-1,CONCRETE:8)
Block(-8,57,0,CONCRETE:8)
Block(-8,57,1,CONCRETE:8)
Block(-8,57,2,CONCRETE:8)
Block(-8,57,3,CONCRETE:8)
Block(-8,57,4,CONCRETE:8)
Block(-8,57,5,CONCRETE:8)
Block(-8,57,6,CONCRETE:8)
Block(-8,57,7,CONCRETE:8)
Block(-8,57,8,CONCRETE:8)
Block(-8,58,-7,STAINED_GLASS_PANE:15)
Block(-8,58,-6,STAINED_GLASS_PANE:15)
Block(-8,58,-5,STAINED_GLASS_PANE:15)
Block(-8,58,-4,STAINED_GLASS_PANE:15)
Block(-8,58,-3,STAINED_GLASS_PANE:15)
Block(-8,58,-2,STAINED_GLASS_PANE:15)
Block(-8,58,-1,STAINED_GLASS_PANE:15)
Block(-8,58,0,STAINED_GLASS_PANE:15)
Block(-8,58,1,STAINED_GLASS_PANE:15)
Block(-8,58,2,STAINED_GLASS_PANE:15)
Block(-8,58,3,STAINED_GLASS_PANE:15)
Block(-8,58,4,STAINED_GLASS_PANE:15)
Block(-8,58,5,STAINED_GLASS_PANE:15)
Block(-8,58,6,STAINED_GLASS_PANE:15)
Block(-8,58,7,STAINED_GLASS_PANE:15)
Block(-8,58,8,STAINED_GLASS_PANE:15)
Block(-8,61,-7,CONCRETE:8)
Block(-8,61,-6,CONCRETE:8)
Block(-8,61,-5,CONCRETE:8)
Block(-8,61,-4,CONCRETE:8)
Block(-8,61,-3,CONCRETE:8)
Block(-8,61,-2,CONCRETE:8)
Block(-8,61,-1,CONCRETE:8)
Block(-8,61,0,CONCRETE:8)
Block(-8,61,1,CONCRETE:8)
Block(-8,61,2,CONCRETE:8)
Block(-8,61,3,CONCRETE:8)
Block(-8,61,4,CONCRETE:8)
Block(-8,61,5,CONCRETE:8)
Block(-8,61,6,CONCRETE:8)
Block(-8,61,7,CONCRETE:8)
Block(-8,61,8,CONCRETE:8)
Block(-8,62,-7,STAINED_GLASS_PANE:15)
Block(-8,62,-6,STAINED_GLASS_PANE:15)
Block(-8,62,-5,STAINED_GLASS_PANE:15)
Block(-8,62,-4,STAINED_GLASS_PANE:15)
Block(-8,62,-3,STAINED_GLASS_PANE:15)
Block(-8,62,-2,STAINED_GLASS_PANE:15)
Block(-8,62,-1,STAINED_GLASS_PANE:15)
Block(-8,62,0,STAINED_GLASS_PANE:15)
Block(-8,62,1,STAINED_GLASS_PANE:15)
Block(-8,62,2,STAINED_GLASS_PANE:15)
Block(-8,62,3,STAINED_GLASS_PANE:15)
Block(-8,62,4,STAINED_GLASS_PANE:15)
Block(-8,62,5,STAINED_GLASS_PANE:15)
Block(-8,62,6,STAINED_GLASS_PANE:15)
Block(-8,62,7,STAINED_GLASS_PANE:15)
Block(-8,62,8,STAINED_GLASS_PANE:15)
Block(-8,65,-7,CONCRETE:8)
Block(-8,65,-6,CONCRETE:8)
Block(-8,65,-5,CONCRETE:8)
Block(-8,65,-4,CONCRETE:8)
Block(-8,65,-3,CONCRETE:8)
Block(-8,65,-2,CONCRETE:8)
Block(-8,65,-1,CONCRETE:8)
Block(-8,65,0,CONCRETE:8)
Block(-8,65,1,CONCRETE:8)
Block(-8,65,2,CONCRETE:8)
Block(-8,65,3,CONCRETE:8)
Block(-8,65,4,CONCRETE:8)
Block(-8,65,5,CONCRETE:8)
Block(-8,65,6,CONCRETE:8)
Block(-8,65,7,CONCRETE:8)
Block(-8,65,8,CONCRETE:8)
Block(-8,66,-7,STAINED_GLASS_PANE:15)
Block(-8,66,-6,STAINED_GLASS_PANE:15)
Block(-8,66,-5,STAINED_GLASS_PANE:15)
Block(-8,66,-4,STAINED_GLASS_PANE:15)
Block(-8,66,-3,STAINED_GLASS_PANE:15)
Block(-8,66,-2,STAINED_GLASS_PANE:15)
Block(-8,66,-1,STAINED_GLASS_PANE:15)
Block(-8,66,0,STAINED_GLASS_PANE:15)
Block(-8,66,1,STAINED_GLASS_PANE:15)
Block(-8,66,2,STAINED_GLASS_PANE:15)
Block(-8,66,3,STAINED_GLASS_PANE:15)
Block(-8,66,4,STAINED_GLASS_PANE:15)
Block(-8,66,5,STAINED_GLASS_PANE:15)
Block(-8,66,6,STAINED_GLASS_PANE:15)
Block(-8,66,7,STAINED_GLASS_PANE:15)
Block(-8,66,8,STAINED_GLASS_PANE:15)
Block(-8,69,-7,CONCRETE:8)
Block(-8,69,-6,CONCRETE:8)
Block(-8,69,-5,CONCRETE:8)
Block(-8,69,-4,CONCRETE:8)
Block(-8,69,-3,CONCRETE:8)
Block(-8,69,-2,CONCRETE:8)
Block(-8,69,-1,CONCRETE:8)
Block(-8,69,0,CONCRETE:8)
Block(-8,69,1,CONCRETE:8)
Block(-8,69,2,CONCRETE:8)
Block(-8,69,3,CONCRETE:8)
Block(-8,69,4,CONCRETE:8)
Block(-8,69,5,CONCRETE:8)
Block(-8,69,6,CONCRETE:8)
Block(-8,69,7,CONCRETE:8)
Block(-8,69,8,CONCRETE:8)
Block(-8,70,-7,STAINED_GLASS_PANE:15)
Block(-8,70,-6,STAINED_GLASS_PANE:15)
Block(-8,70,-5,STAINED_GLASS_PANE:15)
Block(-8,70,-4,STAINED_GLASS_PANE:15)
Block(-8,70,-3,STAINED_GLASS_PANE:15)
Block(-8,70,-2,STAINED_GLASS_PANE:15)
Block(-8,70,-1,STAINED_GLASS_PANE:15)
Block(-8,70,0,STAINED_GLASS_PANE:15)
Block(-8,70,1,STAINED_GLASS_PANE:15)
Block(-8,70,2,STAINED_GLASS_PANE:15)
Block(-8,70,3,STAINED_GLASS_PANE:15)
Block(-8,70,4,STAINED_GLASS_PANE:15)
Block(-8,70,5,STAINED_GLASS_PANE:15)
Block(-8,70,6,STAINED_GLASS_PANE:15)
Block(-8,70,7,STAINED_GLASS_PANE:15)
Block(-8,70,8,STAINED_GLASS_PANE:15)
Block(-8,73,-7,CONCRETE:8)
Block(-8,73,-6,CONCRETE:8)
Block(-8,73,-5,CONCRETE:8)
Block(-8,73,-4,CONCRETE:8)
Block(-8,73,-3,CONCRETE:8)
Block(-8,73,-2,CONCRETE:8)
Block(-8,73,-1,CONCRETE:8)
Block(-8,73,0,CONCRETE:8)
Block(-8,73,1,CONCRETE:8)
Block(-8,73,2,CONCRETE:8)
Block(-8,73,3,CONCRETE:8)
Block(-8,73,4,CONCRETE:8)
Block(-8,73,5,CONCRETE:8)
Block(-8,73,6,CONCRETE:8)
Block(-8,73,7,CONCRETE:8)
Block(-8,73,8,CONCRETE:8)
Block(-8,74,-7,STAINED_GLASS_PANE:15)
Block(-8,74,-6,STAINED_GLASS_PANE:15)
Block(-8,74,-5,STAINED_GLASS_PANE:15)
Block(-8,74,-4,STAINED_GLASS_PANE:15)
Block(-8,74,-3,STAINED_GLASS_PANE:15)
Block(-8,74,-2,STAINED_GLASS_PANE:15)
Block(-8,74,-1,STAINED_GLASS_PANE:15)
Block(-8,74,0,STAINED_GLASS_PANE:15)
Block(-8,74,1,STAINED_GLASS_PANE:15)
Block(-8,74,2,STAINED_GLASS_PANE:15)
Block(-8,74,3,STAINED_GLASS_PANE:15)
Block(-8,74,4,STAINED_GLASS_PANE:15)
Block(-8,74,5,STAINED_GLASS_PANE:15)
Block(-8,74,6,STAINED_GLASS_PANE:15)
Block(-8,74,7,STAINED_GLASS_PANE:15)
Block(-8,74,8,STAINED_GLASS_PANE:15)
Block(-8,77,-7,CONCRETE:8)
Block(-8,77,-6,CONCRETE:8)
Block(-8,77,-5,CONCRETE:8)
Block(-8,77,-4,CONCRETE:8)
Block(-8,77,-3,CONCRETE:8)
Block(-8,77,-2,CONCRETE:8)
Block(-8,77,-1,CONCRETE:8)
Block(-8,77,0,CONCRETE:8)
Block(-8,77,1,CONCRETE:8)
Block(-8,77,2,CONCRETE:8)
Block(-8,77,3,CONCRETE:8)
Block(-8,77,4,CONCRETE:8)
Block(-8,77,5,CONCRETE:8)
Block(-8,77,6,CONCRETE:8)
Block(-8,77,7,CONCRETE:8)
Block(-8,77,8,CONCRETE:8)
Block(-8,78,-7,STAINED_GLASS_PANE:15)
Block(-8,78,-6,STAINED_GLASS_PANE:15)
Block(-8,78,-5,STAINED_GLASS_PANE:15)
Block(-8,78,-4,STAINED_GLASS_PANE:15)
Block(-8,78,-3,STAINED_GLASS_PANE:15)
Block(-8,78,-2,STAINED_GLASS_PANE:15)
Block(-8,78,-1,STAINED_GLASS_PANE:15)
Block(-8,78,0,STAINED_GLASS_PANE:15)
Block(-8,78,1,STAINED_GLASS_PANE:15)
Block(-8,78,2,STAINED_GLASS_PANE:15)
Block(-8,78,3,STAINED_GLASS_PANE:15)
Block(-8,78,4,STAINED_GLASS_PANE:15)
Block(-8,78,5,STAINED_GLASS_PANE:15)
Block(-8,78,6,STAINED_GLASS_PANE:15)
Block(-8,78,7,STAINED_GLASS_PANE:15)
Block(-8,78,8,STAINED_GLASS_PANE:15)
Block(-8,81,-7,CONCRETE:8)
Block(-8,81,-6,CONCRETE:8)
Block(-8,81,-5,CONCRETE:8)
Block(-8,81,-4,CONCRETE:8)
Block(-8,81,-3,CONCRETE:8)
Block(-8,81,-2,CONCRETE:8)
Block(-8,81,-1,CONCRETE:8)
Block(-8,81,0,CONCRETE:8)
Block(-8,81,1,CONCRETE:8)
Block(-8,81,2,CONCRETE:8)
Block(-8,81,3,CONCRETE:8)
Block(-8,81,4,CONCRETE:8)
Block(-8,81,5,CONCRETE:8)
Block(-8,81,6,CONCRETE:8)
Block(-8,81,7,CONCRETE:8)
Block(-8,81,8,CONCRETE:8)
Block(-8,82,-7,STAINED_GLASS_PANE:15)
Block(-8,82,-6,STAINED_GLASS_PANE:15)
Block(-8,82,-5,STAINED_GLASS_PANE:15)
Block(-8,82,-4,STAINED_GLASS_PANE:15)
Block(-8,82,-3,STAINED_GLASS_PANE:15)
Block(-8,82,-2,STAINED_GLASS_PANE:15)
Block(-8,82,-1,STAINED_GLASS_PANE:15)
Block(-8,82,0,STAINED_GLASS_PANE:15)
Block(-8,82,1,STAINED_GLASS_PANE:15)
Block(-8,82,2,STAINED_GLASS_PANE:15)
Block(-8,82,3,STAINED_GLASS_PANE:15)
Block(-8,82,4,STAINED_GLASS_PANE:15)
Block(-8,82,5,STAINED_GLASS_PANE:15)
Block(-8,82,6,STAINED_GLASS_PANE:15)
Block(-8,82,7,STAINED_GLASS_PANE:15)
Block(-8,82,8,STAINED_GLASS_PANE:15)
Block(-8,85,-7,CONCRETE:8)
Block(-8,85,-6,CONCRETE:8)
Block(-8,85,-5,CONCRETE:8)
Block(-8,85,-4,CONCRETE:8)
Block(-8,85,-3,CONCRETE:8)
Block(-8,85,-2,CONCRETE:8)
Block(-8,85,-1,CONCRETE:8)
Block(-8,85,0,CONCRETE:8)
Block(-8,85,1,CONCRETE:8)
Block(-8,85,2,CONCRETE:8)
Block(-8,85,3,CONCRETE:8)
Block(-8,85,4,CONCRETE:8)
Block(-8,85,5,CONCRETE:8)
Block(-8,85,6,CONCRETE:8)
Block(-8,85,7,CONCRETE:8)
Block(-8,85,8,CONCRETE:8)
Block(-8,86,-7,STAINED_GLASS_PANE:15)
Block(-8,86,-6,STAINED_GLASS_PANE:15)
Block(-8,86,-5,STAINED_GLASS_PANE:15)
Block(-8,86,-4,STAINED_GLASS_PANE:15)
Block(-8,86,-3,STAINED_GLASS_PANE:15)
Block(-8,86,-2,STAINED_GLASS_PANE:15)
Block(-8,86,-1,STAINED_GLASS_PANE:15)
Block(-8,86,0,STAINED_GLASS_PANE:15)
Block(-8,86,1,STAINED_GLASS_PANE:15)
Block(-8,86,2,STAINED_GLASS_PANE:15)
Block(-8,86,3,STAINED_GLASS_PANE:15)
Block(-8,86,4,STAINED_GLASS_PANE:15)
Block(-8,86,5,STAINED_GLASS_PANE:15)
Block(-8,86,6,STAINED_GLASS_PANE:15)
Block(-8,86,7,STAINED_GLASS_PANE:15)
Block(-8,86,8,STAINED_GLASS_PANE:15)
Block(-8,89,-7,CONCRETE:8)
Block(-8,89,-6,CONCRETE:8)
Block(-8,89,-5,CONCRETE:8)
Block(-8,89,-4,CONCRETE:8)
Block(-8,89,-3,CONCRETE:8)
Block(-8,89,-2,CONCRETE:8)
Block(-8,89,-1,CONCRETE:8)
Block(-8,89,0,CONCRETE:8)
Block(-8,89,1,CONCRETE:8)
Block(-8,89,2,CONCRETE:8)
Block(-8,89,3,CONCRETE:8)
Block(-8,89,4,CONCRETE:8)
Block(-8,89,5,CONCRETE:8)
Block(-8,89,6,CONCRETE:8)
Block(-8,89,7,CONCRETE:8)
Block(-8,89,8,CONCRETE:8)
Block(-8,90,-7,STAINED_GLASS_PANE:15)
Block(-8,90,-6,STAINED_GLASS_PANE:15)
Block(-8,90,-5,STAINED_GLASS_PANE:15)
Block(-8,90,-4,STAINED_GLASS_PANE:15)
Block(-8,90,-3,STAINED_GLASS_PANE:15)
Block(-8,90,-2,STAINED_GLASS_PANE:15)
Block(-8,90,-1,STAINED_GLASS_PANE:15)
Block(-8,90,0,STAINED_GLASS_PANE:15)
Block(-8,90,1,STAINED_GLASS_PANE:15)
Block(-8,90,2,STAINED_GLASS_PANE:15)
Block(-8,90,3,STAINED_GLASS_PANE:15)
Block(-8,90,4,STAINED_GLASS_PANE:15)
Block(-8,90,5,STAINED_GLASS_PANE:15)
Block(-8,90,6,STAINED_GLASS_PANE:15)
Block(-8,90,7,STAINED_GLASS_PANE:15)
Block(-8,90,8,STAINED_GLASS_PANE:15)
Block(-8,93,-7,CONCRETE:8)
Block(-8,93,-6,CONCRETE:8)
Block(-8,93,-5,CONCRETE:8)
Block(-8,93,-4,CONCRETE:8)
Block(-8,93,-3,CONCRETE:8)
Block(-8,93,-2,CONCRETE:8)
Block(-8,93,-1,CONCRETE:8)
Block(-8,93,0,CONCRETE:8)
Block(-8,93,1,CONCRETE:8)
Block(-8,93,2,CONCRETE:8)
Block(-8,93,3,CONCRETE:8)
Block(-8,93,4,CONCRETE:8)
Block(-8,93,5,CONCRETE:8)
Block(-8,93,6,CONCRETE:8)
Block(-8,93,7,CONCRETE:8)
Block(-8,93,8,CONCRETE:8)
Block(-8,94,-7,STAINED_GLASS_PANE:15)
Block(-8,94,-6,STAINED_GLASS_PANE:15)
Block(-8,94,-5,STAINED_GLASS_PANE:15)
Block(-8,94,-4,STAINED_GLASS_PANE:15)
Block(-8,94,-3,STAINED_GLASS_PANE:15)
Block(-8,94,-2,STAINED_GLASS_PANE:15)
Block(-8,94,-1,STAINED_GLASS_PANE:15)
Block(-8,94,0,STAINED_GLASS_PANE:15)
Block(-8,94,1,STAINED_GLASS_PANE:15)
Block(-8,94,2,STAINED_GLASS_PANE:15)
Block(-8,94,3,STAINED_GLASS_PANE:15)
Block(-8,94,4,STAINED_GLASS_PANE:15)
Block(-8,94,5,STAINED_GLASS_PANE:15)
Block(-8,94,6,STAINED_GLASS_PANE:15)
Block(-8,94,7,STAINED_GLASS_PANE:15)
Block(-8,94,8,STAINED_GLASS_PANE:15)
Block(-8,97,-7,CONCRETE:8)
Block(-8,97,-6,CONCRETE:8)
Block(-8,97,-5,CONCRETE:8)
Block(-8,97,-4,CONCRETE:8)
Block(-8,97,-3,CONCRETE:8)
Block(-8,97,-2,CONCRETE:8)
Block(-8,97,-1,CONCRETE:8)
Block(-8,97,0,CONCRETE:8)
Block(-8,97,1,CONCRETE:8)
Block(-8,97,2,CONCRETE:8)
Block(-8,97,3,CONCRETE:8)
Block(-8,97,4,CONCRETE:8)
Block(-8,97,5,CONCRETE:8)
Block(-8,97,6,CONCRETE:8)
Block(-8,97,7,CONCRETE:8)
Block(-8,97,8,CONCRETE:8)
Block(-8,98,-7,STAINED_GLASS_PANE:15)
Block(-8,98,-6,STAINED_GLASS_PANE:15)
Block(-8,98,-5,STAINED_GLASS_PANE:15)
Block(-8,98,-4,STAINED_GLASS_PANE:15)
Block(-8,98,-3,STAINED_GLASS_PANE:15)
Block(-8,98,-2,STAINED_GLASS_PANE:15)
Block(-8,98,-1,STAINED_GLASS_PANE:15)
Block(-8,98,0,STAINED_GLASS_PANE:15)
Block(-8,98,1,STAINED_GLASS_PANE:15)
Block(-8,98,2,STAINED_GLASS_PANE:15)
Block(-8,98,3,STAINED_GLASS_PANE:15)
Block(-8,98,4,STAINED_GLASS_PANE:15)
Block(-8,98,5,STAINED_GLASS_PANE:15)
Block(-8,98,6,STAINED_GLASS_PANE:15)
Block(-8,98,7,STAINED_GLASS_PANE:15)
Block(-8,98,8,STAINED_GLASS_PANE:15)
Block(-8,101,-7,CONCRETE:8)
Block(-8,101,-6,CONCRETE:8)
Block(-8,101,-5,CONCRETE:8)
Block(-8,101,-4,CONCRETE:8)
Block(-8,101,-3,CONCRETE:8)
Block(-8,101,-2,CONCRETE:8)
Block(-8,101,-1,CONCRETE:8)
Block(-8,101,0,CONCRETE:8)
Block(-8,101,1,CONCRETE:8)
Block(-8,101,2,CONCRETE:8)
Block(-8,101,3,CONCRETE:8)
Block(-8,101,4,CONCRETE:8)
Block(-8,101,5,CONCRETE:8)
Block(-8,101,6,CONCRETE:8)
Block(-8,101,7,CONCRETE:8)
Block(-8,101,8,CONCRETE:8)
Block(-8,102,-7,STAINED_GLASS_PANE:15)
Block(-8,102,-6,STAINED_GLASS_PANE:15)
Block(-8,102,-5,STAINED_GLASS_PANE:15)
Block(-8,102,-4,STAINED_GLASS_PANE:15)
Block(-8,102,-3,STAINED_GLASS_PANE:15)
Block(-8,102,-2,STAINED_GLASS_PANE:15)
Block(-8,102,-1,STAINED_GLASS_PANE:15)
Block(-8,102,0,STAINED_GLASS_PANE:15)
Block(-8,102,1,STAINED_GLASS_PANE:15)
Block(-8,102,2,STAINED_GLASS_PANE:15)
Block(-8,102,3,STAINED_GLASS_PANE:15)
Block(-8,102,4,STAINED_GLASS_PANE:15)
Block(-8,102,5,STAINED_GLASS_PANE:15)
Block(-8,102,6,STAINED_GLASS_PANE:15)
Block(-8,102,7,STAINED_GLASS_PANE:15)
Block(-8,102,8,STAINED_GLASS_PANE:15)
Block(-8,105,-7,CONCRETE:8)
Block(-8,105,-6,CONCRETE:8)
Block(-8,105,-5,CONCRETE:8)
Block(-8,105,-4,CONCRETE:8)
Block(-8,105,-3,CONCRETE:8)
Block(-8,105,-2,CONCRETE:8)
Block(-8,105,-1,CONCRETE:8)
Block(-8,105,0,CONCRETE:8)
Block(-8,105,1,CONCRETE:8)
Block(-8,105,2,CONCRETE:8)
Block(-8,105,3,CONCRETE:8)
Block(-8,105,4,CONCRETE:8)
Block(-8,105,5,CONCRETE:8)
Block(-8,105,6,CONCRETE:8)
Block(-8,105,7,CONCRETE:8)
Block(-8,105,8,CONCRETE:8)
Block(-8,106,-7,STAINED_GLASS_PANE:15)
Block(-8,106,-6,STAINED_GLASS_PANE:15)
Block(-8,106,-5,STAINED_GLASS_PANE:15)
Block(-8,106,-4,STAINED_GLASS_PANE:15)
Block(-8,106,-3,STAINED_GLASS_PANE:15)
Block(-8,106,-2,STAINED_GLASS_PANE:15)
Block(-8,106,-1,STAINED_GLASS_PANE:15)
Block(-8,106,0,STAINED_GLASS_PANE:15)
Block(-8,106,1,STAINED_GLASS_PANE:15)
Block(-8,106,2,STAINED_GLASS_PANE:15)
Block(-8,106,3,STAINED_GLASS_PANE:15)
Block(-8,106,4,STAINED_GLASS_PANE:15)
Block(-8,106,5,STAINED_GLASS_PANE:15)
Block(-8,106,6,STAINED_GLASS_PANE:15)
Block(-8,106,7,STAINED_GLASS_PANE:15)
Block(-8,106,8,STAINED_GLASS_PANE:15)
Block(-8,109,-7,CONCRETE:8)
Block(-8,109,-6,CONCRETE:8)
Block(-8,109,-5,CONCRETE:8)
Block(-8,109,-4,CONCRETE:8)
Block(-8,109,-3,CONCRETE:8)
Block(-8,109,-2,CONCRETE:8)
Block(-8,109,-1,CONCRETE:8)
Block(-8,109,0,CONCRETE:8)
Block(-8,109,1,CONCRETE:8)
Block(-8,109,2,CONCRETE:8)
Block(-8,109,3,CONCRETE:8)
Block(-8,109,4,CONCRETE:8)
Block(-8,109,5,CONCRETE:8)
Block(-8,109,6,CONCRETE:8)
Block(-8,109,7,CONCRETE:8)
Block(-8,109,8,CONCRETE:8)
Block(-8,110,-7,STAINED_GLASS_PANE:15)
Block(-8,110,-6,STAINED_GLASS_PANE:15)
Block(-8,110,-5,STAINED_GLASS_PANE:15)
Block(-8,110,-4,STAINED_GLASS_PANE:15)
Block(-8,110,-3,STAINED_GLASS_PANE:15)
Block(-8,110,-2,STAINED_GLASS_PANE:15)
Block(-8,110,-1,STAINED_GLASS_PANE:15)
Block(-8,110,0,STAINED_GLASS_PANE:15)
Block(-8,110,1,STAINED_GLASS_PANE:15)
Block(-8,110,2,STAINED_GLASS_PANE:15)
Block(-8,110,3,STAINED_GLASS_PANE:15)
Block(-8,110,4,STAINED_GLASS_PANE:15)
Block(-8,110,5,STAINED_GLASS_PANE:15)
Block(-8,110,6,STAINED_GLASS_PANE:15)
Block(-8,110,7,STAINED_GLASS_PANE:15)
Block(-8,110,8,STAINED_GLASS_PANE:15)
Block(-8,117,-7,CONCRETE:15)
Block(-8,117,-6,CONCRETE:15)
Block(-8,117,-5,CONCRETE:15)
Block(-8,117,-4,CONCRETE:15)
Block(-8,117,-3,CONCRETE:15)
Block(-8,117,-2,CONCRETE:15)
Block(-8,117,-1,CONCRETE:15)
Block(-8,117,0,CONCRETE:15)
Block(-8,117,1,CONCRETE:15)
Block(-8,117,2,CONCRETE:15)
Block(-8,117,3,CONCRETE:15)
Block(-8,117,4,CONCRETE:15)
Block(-8,117,5,CONCRETE:15)
Block(-8,117,6,CONCRETE:15)
Block(-8,117,7,CONCRETE:15)
Block(-8,117,8,CONCRETE:15)
Block(-8,118,-7,CONCRETE:15)
Block(-8,118,-6,CONCRETE:15)
Block(-8,118,-5,CONCRETE:15)
Block(-8,118,-4,CONCRETE:15)
Block(-8,118,-3,CONCRETE:15)
Block(-8,118,-2,CONCRETE:15)
Block(-8,118,-1,CONCRETE:15)
Block(-8,118,0,CONCRETE:15)
Block(-8,118,1,CONCRETE:15)
Block(-8,118,2,CONCRETE:15)
Block(-8,118,3,CONCRETE:15)
Block(-8,118,4,CONCRETE:15)
Block(-8,118,5,CONCRETE:15)
Block(-8,118,6,CONCRETE:15)
Block(-8,118,7,CONCRETE:15)
Block(-8,118,8,CONCRETE:15)
Block(-8,119,-7,CONCRETE:15)
Block(-8,119,-6,CONCRETE:15)
Block(-8,119,-5,CONCRETE:15)
Block(-8,119,-4,CONCRETE:15)
Block(-8,119,-3,CONCRETE:15)
Block(-8,119,-2,CONCRETE:15)
Block(-8,119,-1,CONCRETE:15)
Block(-8,119,0,CONCRETE:15)
Block(-8,119,1,CONCRETE:15)
Block(-8,119,2,CONCRETE:15)
Block(-8,119,3,CONCRETE:15)
Block(-8,119,4,CONCRETE:15)
Block(-8,119,5,CONCRETE:15)
Block(-8,119,6,CONCRETE:15)
Block(-8,119,7,CONCRETE:15)
Block(-8,119,8,CONCRETE:15)
Block(-7,0,-7,CONCRETE:7)
Block(-7,0,-6,CONCRETE:7)
Block(-7,0,-5,CONCRETE:7)
Block(-7,0,-4,CONCRETE:7)
Block(-7,0,-3,CONCRETE:7)
Block(-7,0,-2,CONCRETE:7)
Block(-7,0,-1,CONCRETE:7)
Block(-7,0,0,CONCRETE:7)
Block(-7,0,1,CONCRETE:7)
Block(-7,0,2,CONCRETE:7)
Block(-7,0,3,CONCRETE:7)
Block(-7,0,4,CONCRETE:7)
Block(-7,0,5,CONCRETE:7)
Block(-7,0,6,CONCRETE:7)
Block(-7,0,7,CONCRETE:7)
Block(-7,0,8,CONCRETE:7)
Block(-7,1,-7,CONCRETE:7)
Block(-7,1,-6,CONCRETE:7)
Block(-7,1,-5,CONCRETE:7)
Block(-7,1,-4,CONCRETE:7)
Block(-7,1,-3,CONCRETE:7)
Block(-7,1,-2,CONCRETE:7)
Block(-7,1,-1,CONCRETE:7)
Block(-7,1,0,CONCRETE:7)
Block(-7,1,1,CONCRETE:7)
Block(-7,1,2,CONCRETE:7)
Block(-7,1,3,CONCRETE:7)
Block(-7,1,4,CONCRETE:7)
Block(-7,1,5,CONCRETE:7)
Block(-7,1,6,CONCRETE:7)
Block(-7,1,7,CONCRETE:7)
Block(-7,1,8,CONCRETE:7)
Block(-7,2,-7,CONCRETE:7)
Block(-7,2,-6,CONCRETE:7)
Block(-7,2,-5,CONCRETE:7)
Block(-7,2,-4,CONCRETE:7)
Block(-7,2,-3,CONCRETE:7)
Block(-7,2,-2,CONCRETE:7)
Block(-7,2,-1,CONCRETE:7)
Block(-7,2,0,CONCRETE:7)
Block(-7,2,1,CONCRETE:7)
Block(-7,2,2,CONCRETE:7)
Block(-7,2,3,CONCRETE:7)
Block(-7,2,4,CONCRETE:7)
Block(-7,2,5,CONCRETE:7)
Block(-7,2,6,CONCRETE:7)
Block(-7,2,7,CONCRETE:7)
Block(-7,2,8,CONCRETE:7)
Block(-7,3,-7,CONCRETE:7)
Block(-7,3,-6,CONCRETE:7)
Block(-7,3,-5,CONCRETE:7)
Block(-7,3,-4,CONCRETE:7)
Block(-7,3,-3,CONCRETE:7)
Block(-7,3,-2,CONCRETE:7)
Block(-7,3,-1,CONCRETE:7)
Block(-7,3,0,CONCRETE:7)
Block(-7,3,1,CONCRETE:7)
Block(-7,3,2,CONCRETE:7)
Block(-7,3,3,CONCRETE:7)
Block(-7,3,4,CONCRETE:7)
Block(-7,3,5,CONCRETE:7)
Block(-7,3,6,CONCRETE:7)
Block(-7,3,7,CONCRETE:7)
Block(-7,3,8,CONCRETE:7)
Block(-7,4,-7,CONCRETE:7)
Block(-7,4,-6,CONCRETE:7)
Block(-7,4,-5,CONCRETE:7)
Block(-7,4,-4,CONCRETE:7)
Block(-7,4,-3,CONCRETE:7)
Block(-7,4,-2,CONCRETE:7)
Block(-7,4,-1,CONCRETE:7)
Block(-7,4,0,CONCRETE:7)
Block(-7,4,1,CONCRETE:7)
Block(-7,4,2,CONCRETE:7)
Block(-7,4,3,CONCRETE:7)
Block(-7,4,4,CONCRETE:7)
Block(-7,4,5,CONCRETE:7)
Block(-7,4,6,CONCRETE:7)
Block(-7,4,7,CONCRETE:7)
Block(-7,4,8,CONCRETE:7)
Block(-7,5,-7,CONCRETE:7)
Block(-7,5,-6,CONCRETE:7)
Block(-7,5,-5,CONCRETE:7)
Block(-7,5,-4,CONCRETE:7)
Block(-7,5,-3,CONCRETE:7)
Block(-7,5,-2,CONCRETE:7)
Block(-7,5,-1,CONCRETE:7)
Block(-7,5,0,CONCRETE:7)
Block(-7,5,1,CONCRETE:7)
Block(-7,5,2,CONCRETE:7)
Block(-7,5,3,CONCRETE:7)
Block(-7,5,4,CONCRETE:7)
Block(-7,5,5,CONCRETE:7)
Block(-7,5,6,CONCRETE:7)
Block(-7,5,7,CONCRETE:7)
Block(-7,5,8,CONCRETE:7)
Block(-7,6,-7,CONCRETE:7)
Block(-7,6,-6,CONCRETE:7)
Block(-7,6,-5,CONCRETE:7)
Block(-7,6,-4,CONCRETE:7)
Block(-7,6,-3,CONCRETE:7)
Block(-7,6,-2,CONCRETE:7)
Block(-7,6,-1,CONCRETE:7)
Block(-7,6,0,CONCRETE:7)
Block(-7,6,1,CONCRETE:7)
Block(-7,6,2,CONCRETE:7)
Block(-7,6,3,CONCRETE:7)
Block(-7,6,4,CONCRETE:7)
Block(-7,6,5,CONCRETE:7)
Block(-7,6,6,CONCRETE:7)
Block(-7,6,7,CONCRETE:7)
Block(-7,6,8,CONCRETE:7)
Block(-7,7,-7,CONCRETE:7)
Block(-7,7,-6,CONCRETE:7)
Block(-7,7,-5,CONCRETE:7)
Block(-7,7,-4,CONCRETE:7)
Block(-7,7,-3,CONCRETE:7)
Block(-7,7,-2,CONCRETE:7)
Block(-7,7,-1,CONCRETE:7)
Block(-7,7,0,CONCRETE:7)
Block(-7,7,1,CONCRETE:7)
Block(-7,7,2,CONCRETE:7)
Block(-7,7,3,CONCRETE:7)
Block(-7,7,4,CONCRETE:7)
Block(-7,7,5,CONCRETE:7)
Block(-7,7,6,CONCRETE:7)
Block(-7,7,7,CONCRETE:7)
Block(-7,7,8,CONCRETE:7)
Block(-7,8,-7,CONCRETE:7)
Block(-7,8,-6,CONCRETE:7)
Block(-7,8,-5,CONCRETE:7)
Block(-7,8,-4,CONCRETE:7)
Block(-7,8,-3,CONCRETE:7)
Block(-7,8,-2,CONCRETE:7)
Block(-7,8,-1,CONCRETE:7)
Block(-7,8,0,CONCRETE:7)
Block(-7,8,1,CONCRETE:7)
Block(-7,8,2,CONCRETE:7)
Block(-7,8,3,CONCRETE:7)
Block(-7,8,4,CONCRETE:7)
Block(-7,8,5,CONCRETE:7)
Block(-7,8,6,CONCRETE:7)
Block(-7,8,7,CONCRETE:7)
Block(-7,8,8,CONCRETE:7)
Block(-7,9,-7,CONCRETE:7)
Block(-7,9,-6,CONCRETE:7)
Block(-7,9,-5,CONCRETE:7)
Block(-7,9,-4,CONCRETE:7)
Block(-7,9,-3,CONCRETE:7)
Block(-7,9,-2,CONCRETE:7)
Block(-7,9,-1,CONCRETE:7)
Block(-7,9,0,CONCRETE:7)
Block(-7,9,1,CONCRETE:7)
Block(-7,9,2,CONCRETE:7)
Block(-7,9,3,CONCRETE:7)
Block(-7,9,4,CONCRETE:7)
Block(-7,9,5,CONCRETE:7)
Block(-7,9,6,CONCRETE:7)
Block(-7,9,7,CONCRETE:7)
Block(-7,9,8,CONCRETE:7)
Block(-7,10,-7,CONCRETE:8)
Block(-7,10,-6,CONCRETE:8)
Block(-7,10,-5,CONCRETE:8)
Block(-7,10,-4,CONCRETE:8)
Block(-7,10,-3,CONCRETE:8)
Block(-7,10,-2,CONCRETE:8)
Block(-7,10,-1,CONCRETE:8)
Block(-7,10,0,CONCRETE:8)
Block(-7,10,1,CONCRETE:8)
Block(-7,10,2,CONCRETE:8)
Block(-7,10,3,CONCRETE:8)
Block(-7,10,4,CONCRETE:8)
Block(-7,10,5,CONCRETE:8)
Block(-7,10,6,CONCRETE:8)
Block(-7,10,7,CONCRETE:8)
Block(-7,10,8,CONCRETE:8)
Block(-7,11,-7,CONCRETE:8)
Block(-7,11,-6,CONCRETE:8)
Block(-7,11,-5,CONCRETE:8)
Block(-7,11,-4,CONCRETE:8)
Block(-7,11,-3,CONCRETE:8)
Block(-7,11,-2,CONCRETE:8)
Block(-7,11,-1,CONCRETE:8)
Block(-7,11,0,CONCRETE:8)
Block(-7,11,1,CONCRETE:8)
Block(-7,11,2,CONCRETE:8)
Block(-7,11,3,CONCRETE:8)
Block(-7,11,4,CONCRETE:8)
Block(-7,11,5,CONCRETE:8)
Block(-7,11,6,CONCRETE:8)
Block(-7,11,7,CONCRETE:8)
Block(-7,11,8,CONCRETE:8)
Block(-7,12,-7,CONCRETE:8)
Block(-7,12,-6,CONCRETE:8)
Block(-7,12,-5,CONCRETE:8)
Block(-7,12,-4,CONCRETE:8)
Block(-7,12,-3,CONCRETE:8)
Block(-7,12,-2,CONCRETE:8)
Block(-7,12,-1,CONCRETE:8)
Block(-7,12,0,CONCRETE:8)
Block(-7,12,1,CONCRETE:8)
Block(-7,12,2,CONCRETE:8)
Block(-7,12,3,CONCRETE:8)
Block(-7,12,4,CONCRETE:8)
Block(-7,12,5,CONCRETE:8)
Block(-7,12,6,CONCRETE:8)
Block(-7,12,7,CONCRETE:8)
Block(-7,12,8,CONCRETE:8)
Block(-7,13,-7,CONCRETE:8)
Block(-7,13,-6,CONCRETE:8)
Block(-7,13,-5,CONCRETE:8)
Block(-7,13,-4,CONCRETE:8)
Block(-7,13,-3,CONCRETE:8)
Block(-7,13,-2,CONCRETE:8)
Block(-7,13,-1,CONCRETE:8)
Block(-7,13,0,CONCRETE:8)
Block(-7,13,1,CONCRETE:8)
Block(-7,13,2,CONCRETE:8)
Block(-7,13,3,CONCRETE:8)
Block(-7,13,4,CONCRETE:8)
Block(-7,13,5,CONCRETE:8)
Block(-7,13,6,CONCRETE:8)
Block(-7,13,7,CONCRETE:8)
Block(-7,13,8,CONCRETE:8)
Block(-7,14,-7,CONCRETE:8)
Block(-7,14,-6,CONCRETE:8)
Block(-7,14,-5,CONCRETE:8)
Block(-7,14,-4,CONCRETE:8)
Block(-7,14,-3,CONCRETE:8)
Block(-7,14,-2,CONCRETE:8)
Block(-7,14,-1,CONCRETE:8)
Block(-7,14,0,CONCRETE:8)
Block(-7,14,1,CONCRETE:8)
Block(-7,14,2,CONCRETE:8)
Block(-7,14,3,CONCRETE:8)
Block(-7,14,4,CONCRETE:8)
Block(-7,14,5,CONCRETE:8)
Block(-7,14,6,CONCRETE:8)
Block(-7,14,7,CONCRETE:8)
Block(-7,14,8,CONCRETE:8)
Block(-7,15,-7,CONCRETE:7)
Block(-7,15,-6,CONCRETE:7)
Block(-7,15,-5,CONCRETE:7)
Block(-7,15,-4,CONCRETE:7)
Block(-7,15,-3,CONCRETE:7)
Block(-7,15,-2,CONCRETE:7)
Block(-7,15,-1,CONCRETE:7)
Block(-7,15,0,CONCRETE:7)
Block(-7,15,1,CONCRETE:7)
Block(-7,15,2,CONCRETE:7)
Block(-7,15,3,CONCRETE:7)
Block(-7,15,4,CONCRETE:7)
Block(-7,15,5,CONCRETE:7)
Block(-7,15,6,CONCRETE:7)
Block(-7,15,7,CONCRETE:7)
Block(-7,15,8,CONCRETE:7)
Block(-7,16,-7,CONCRETE:15)
Block(-7,16,-6,CONCRETE:15)
Block(-7,16,-5,CONCRETE:15)
Block(-7,16,-4,CONCRETE:15)
Block(-7,16,-3,CONCRETE:15)
Block(-7,16,-2,CONCRETE:15)
Block(-7,16,-1,CONCRETE:15)
Block(-7,16,0,CONCRETE:15)
Block(-7,16,1,CONCRETE:15)
Block(-7,16,2,CONCRETE:15)
Block(-7,16,3,CONCRETE:15)
Block(-7,16,4,CONCRETE:15)
Block(-7,16,5,CONCRETE:15)
Block(-7,16,6,CONCRETE:15)
Block(-7,16,7,CONCRETE:15)
Block(-7,16,8,CONCRETE:15)
Block(-7,17,-7,CONCRETE:8)
Block(-7,17,-6,CONCRETE:8)
Block(-7,17,-5,CONCRETE:8)
Block(-7,17,-4,CONCRETE:8)
Block(-7,17,-3,GRASS:0)
Block(-7,17,-2,DIRT:1)
Block(-7,17,-1,GRASS:0)
Block(-7,17,0,DIRT:1)
Block(-7,17,1,GRASS:0)
Block(-7,17,2,GRASS:0)
Block(-7,17,3,DIRT:1)
Block(-7,17,4,DIRT:1)
Block(-7,17,5,GRASS:0)
Block(-7,17,6,GRASS:0)
Block(-7,17,7,DIRT:1)
Block(-7,17,8,GRASS:0)
Block(-7,25,-7,CONCRETE:8)
Block(-7,25,-6,CONCRETE:8)
Block(-7,25,-5,CONCRETE:8)
Block(-7,25,-4,CONCRETE:8)
Block(-7,25,-3,CONCRETE:8)
Block(-7,25,-2,CONCRETE:8)
Block(-7,25,-1,CONCRETE:8)
Block(-7,25,0,CONCRETE:8)
Block(-7,25,1,CONCRETE:8)
Block(-7,25,2,CONCRETE:8)
Block(-7,25,3,CONCRETE:8)
Block(-7,25,4,CONCRETE:8)
Block(-7,25,5,CONCRETE:8)
Block(-7,25,6,CONCRETE:8)
Block(-7,25,7,CONCRETE:8)
Block(-7,25,8,CONCRETE:8)
Block(-7,26,-7,WOOD_STEP:5)
Block(-7,26,-5,WOOD_STEP:5)
Block(-7,26,-3,WOOD_STEP:5)
Block(-7,29,-7,CONCRETE:8)
Block(-7,29,-6,CONCRETE:8)
Block(-7,29,-5,CONCRETE:8)
Block(-7,29,-4,CONCRETE:8)
Block(-7,29,-3,CONCRETE:8)
Block(-7,29,-2,CONCRETE:8)
Block(-7,29,-1,CONCRETE:8)
Block(-7,29,0,CONCRETE:8)
Block(-7,29,1,CONCRETE:8)
Block(-7,29,2,CONCRETE:8)
Block(-7,29,3,CONCRETE:8)
Block(-7,29,4,CONCRETE:8)
Block(-7,29,5,CONCRETE:8)
Block(-7,29,6,CONCRETE:8)
Block(-7,29,7,CONCRETE:8)
Block(-7,29,8,CONCRETE:8)
Block(-7,30,-7,WOOD_STEP:5)
Block(-7,30,-5,WOOD_STEP:5)
Block(-7,30,-3,WOOD_STEP:5)
Block(-7,33,-7,CONCRETE:8)
Block(-7,33,-6,CONCRETE:8)
Block(-7,33,-5,CONCRETE:8)
Block(-7,33,-4,CONCRETE:8)
Block(-7,33,-3,CONCRETE:8)
Block(-7,33,-2,CONCRETE:8)
Block(-7,33,-1,CONCRETE:8)
Block(-7,33,0,CONCRETE:8)
Block(-7,33,1,CONCRETE:8)
Block(-7,33,2,CONCRETE:8)
Block(-7,33,3,CONCRETE:8)
Block(-7,33,4,CONCRETE:8)
Block(-7,33,5,CONCRETE:8)
Block(-7,33,6,CONCRETE:8)
Block(-7,33,7,CONCRETE:8)
Block(-7,33,8,CONCRETE:8)
Block(-7,34,-7,WOOD_STEP:5)
Block(-7,34,-5,WOOD_STEP:5)
Block(-7,34,-3,WOOD_STEP:5)
Block(-7,37,-7,CONCRETE:8)
Block(-7,37,-6,CONCRETE:8)
Block(-7,37,-5,CONCRETE:8)
Block(-7,37,-4,CONCRETE:8)
Block(-7,37,-3,CONCRETE:8)
Block(-7,37,-2,CONCRETE:8)
Block(-7,37,-1,CONCRETE:8)
Block(-7,37,0,CONCRETE:8)
Block(-7,37,1,CONCRETE:8)
Block(-7,37,2,CONCRETE:8)
Block(-7,37,3,CONCRETE:8)
Block(-7,37,4,CONCRETE:8)
Block(-7,37,5,CONCRETE:8)
Block(-7,37,6,CONCRETE:8)
Block(-7,37,7,CONCRETE:8)
Block(-7,37,8,CONCRETE:8)
Block(-7,38,-7,WOOD_STEP:5)
Block(-7,38,-5,WOOD_STEP:5)
Block(-7,38,-3,WOOD_STEP:5)
Block(-7,41,-7,CONCRETE:8)
Block(-7,41,-6,CONCRETE:8)
Block(-7,41,-5,CONCRETE:8)
Block(-7,41,-4,CONCRETE:8)
Block(-7,41,-3,CONCRETE:8)
Block(-7,41,-2,CONCRETE:8)
Block(-7,41,-1,CONCRETE:8)
Block(-7,41,0,CONCRETE:8)
Block(-7,41,1,CONCRETE:8)
Block(-7,41,2,CONCRETE:8)
Block(-7,41,3,CONCRETE:8)
Block(-7,41,4,CONCRETE:8)
Block(-7,41,5,CONCRETE:8)
Block(-7,41,6,CONCRETE:8)
Block(-7,41,7,CONCRETE:8)
Block(-7,41,8,CONCRETE:8)
Block(-7,42,-7,WOOD_STEP:5)
Block(-7,42,-5,WOOD_STEP:5)
Block(-7,42,-3,WOOD_STEP:5)
Block(-7,45,-7,CONCRETE:8)
Block(-7,45,-6,CONCRETE:8)
Block(-7,45,-5,CONCRETE:8)
Block(-7,45,-4,CONCRETE:8)
Block(-7,45,-3,CONCRETE:8)
Block(-7,45,-2,CONCRETE:8)
Block(-7,45,-1,CONCRETE:8)
Block(-7,45,0,CONCRETE:8)
Block(-7,45,1,CONCRETE:8)
Block(-7,45,2,CONCRETE:8)
Block(-7,45,3,CONCRETE:8)
Block(-7,45,4,CONCRETE:8)
Block(-7,45,5,CONCRETE:8)
Block(-7,45,6,CONCRETE:8)
Block(-7,45,7,CONCRETE:8)
Block(-7,45,8,CONCRETE:8)
Block(-7,46,-7,WOOD_STEP:5)
Block(-7,46,-5,WOOD_STEP:5)
Block(-7,46,-3,WOOD_STEP:5)
Block(-7,49,-7,CONCRETE:8)
Block(-7,49,-6,CONCRETE:8)
Block(-7,49,-5,CONCRETE:8)
Block(-7,49,-4,CONCRETE:8)
Block(-7,49,-3,CONCRETE:8)
Block(-7,49,-2,CONCRETE:8)
Block(-7,49,-1,CONCRETE:8)
Block(-7,49,0,CONCRETE:8)
Block(-7,49,1,CONCRETE:8)
Block(-7,49,2,CONCRETE:8)
Block(-7,49,3,CONCRETE:8)
Block(-7,49,4,CONCRETE:8)
Block(-7,49,5,CONCRETE:8)
Block(-7,49,6,CONCRETE:8)
Block(-7,49,7,CONCRETE:8)
Block(-7,49,8,CONCRETE:8)
Block(-7,50,-7,WOOD_STEP:5)
Block(-7,50,-5,WOOD_STEP:5)
Block(-7,50,-3,WOOD_STEP:5)
Block(-7,53,-7,CONCRETE:8)
Block(-7,53,-6,CONCRETE:8)
Block(-7,53,-5,CONCRETE:8)
Block(-7,53,-4,CONCRETE:8)
Block(-7,53,-3,CONCRETE:8)
Block(-7,53,-2,CONCRETE:8)
Block(-7,53,-1,CONCRETE:8)
Block(-7,53,0,CONCRETE:8)
Block(-7,53,1,CONCRETE:8)
Block(-7,53,2,CONCRETE:8)
Block(-7,53,3,CONCRETE:8)
Block(-7,53,4,CONCRETE:8)
Block(-7,53,5,CONCRETE:8)
Block(-7,53,6,CONCRETE:8)
Block(-7,53,7,CONCRETE:8)
Block(-7,53,8,CONCRETE:8)
Block(-7,54,-7,WOOD_STEP:5)
Block(-7,54,-5,WOOD_STEP:5)
Block(-7,54,-3,WOOD_STEP:5)
Block(-7,57,-7,CONCRETE:8)
Block(-7,57,-6,CONCRETE:8)
Block(-7,57,-5,CONCRETE:8)
Block(-7,57,-4,CONCRETE:8)
Block(-7,57,-3,CONCRETE:8)
Block(-7,57,-2,CONCRETE:8)
Block(-7,57,-1,CONCRETE:8)
Block(-7,57,0,CONCRETE:8)
Block(-7,57,1,CONCRETE:8)
Block(-7,57,2,CONCRETE:8)
Block(-7,57,3,CONCRETE:8)
Block(-7,57,4,CONCRETE:8)
Block(-7,57,5,CONCRETE:8)
Block(-7,57,6,CONCRETE:8)
Block(-7,57,7,CONCRETE:8)
Block(-7,57,8,CONCRETE:8)
Block(-7,58,-7,WOOD_STEP:5)
Block(-7,58,-5,WOOD_STEP:5)
Block(-7,58,-3,WOOD_STEP:5)
Block(-7,61,-7,CONCRETE:8)
Block(-7,61,-6,CONCRETE:8)
Block(-7,61,-5,CONCRETE:8)
Block(-7,61,-4,CONCRETE:8)
Block(-7,61,-3,CONCRETE:8)
Block(-7,61,-2,CONCRETE:8)
Block(-7,61,-1,CONCRETE:8)
Block(-7,61,0,CONCRETE:8)
Block(-7,61,1,CONCRETE:8)
Block(-7,61,2,CONCRETE:8)
Block(-7,61,3,CONCRETE:8)
Block(-7,61,4,CONCRETE:8)
Block(-7,61,5,CONCRETE:8)
Block(-7,61,6,CONCRETE:8)
Block(-7,61,7,CONCRETE:8)
Block(-7,61,8,CONCRETE:8)
Block(-7,62,-7,WOOD_STEP:5)
Block(-7,62,-5,WOOD_STEP:5)
Block(-7,62,-3,WOOD_STEP:5)
Block(-7,65,-7,CONCRETE:8)
Block(-7,65,-6,CONCRETE:8)
Block(-7,65,-5,CONCRETE:8)
Block(-7,65,-4,CONCRETE:8)
Block(-7,65,-3,CONCRETE:8)
Block(-7,65,-2,CONCRETE:8)
Block(-7,65,-1,CONCRETE:8)
Block(-7,65,0,CONCRETE:8)
Block(-7,65,1,CONCRETE:8)
Block(-7,65,2,CONCRETE:8)
Block(-7,65,3,CONCRETE:8)
Block(-7,65,4,CONCRETE:8)
Block(-7,65,5,CONCRETE:8)
Block(-7,65,6,CONCRETE:8)
Block(-7,65,7,CONCRETE:8)
Block(-7,65,8,CONCRETE:8)
Block(-7,66,-7,WOOD_STEP:5)
Block(-7,66,-5,WOOD_STEP:5)
Block(-7,66,-3,WOOD_STEP:5)
Block(-7,69,-7,CONCRETE:8)
Block(-7,69,-6,CONCRETE:8)
Block(-7,69,-5,CONCRETE:8)
Block(-7,69,-4,CONCRETE:8)
Block(-7,69,-3,CONCRETE:8)
Block(-7,69,-2,CONCRETE:8)
Block(-7,69,-1,CONCRETE:8)
Block(-7,69,0,CONCRETE:8)
Block(-7,69,1,CONCRETE:8)
Block(-7,69,2,CONCRETE:8)
Block(-7,69,3,CONCRETE:8)
Block(-7,69,4,CONCRETE:8)
Block(-7,69,5,CONCRETE:8)
Block(-7,69,6,CONCRETE:8)
Block(-7,69,7,CONCRETE:8)
Block(-7,69,8,CONCRETE:8)
Block(-7,70,-7,WOOD_STEP:5)
Block(-7,70,-5,WOOD_STEP:5)
Block(-7,70,-3,WOOD_STEP:5)
Block(-7,73,-7,CONCRETE:8)
Block(-7,73,-6,CONCRETE:8)
Block(-7,73,-5,CONCRETE:8)
Block(-7,73,-4,CONCRETE:8)
Block(-7,73,-3,CONCRETE:8)
Block(-7,73,-2,CONCRETE:8)
Block(-7,73,-1,CONCRETE:8)
Block(-7,73,0,CONCRETE:8)
Block(-7,73,1,CONCRETE:8)
Block(-7,73,2,CONCRETE:8)
Block(-7,73,3,CONCRETE:8)
Block(-7,73,4,CONCRETE:8)
Block(-7,73,5,CONCRETE:8)
Block(-7,73,6,CONCRETE:8)
Block(-7,73,7,CONCRETE:8)
Block(-7,73,8,CONCRETE:8)
Block(-7,74,-7,WOOD_STEP:5)
Block(-7,74,-5,WOOD_STEP:5)
Block(-7,74,-3,WOOD_STEP:5)
Block(-7,77,-7,CONCRETE:8)
Block(-7,77,-6,CONCRETE:8)
Block(-7,77,-5,CONCRETE:8)
Block(-7,77,-4,CONCRETE:8)
Block(-7,77,-3,CONCRETE:8)
Block(-7,77,-2,CONCRETE:8)
Block(-7,77,-1,CONCRETE:8)
Block(-7,77,0,CONCRETE:8)
Block(-7,77,1,CONCRETE:8)
Block(-7,77,2,CONCRETE:8)
Block(-7,77,3,CONCRETE:8)
Block(-7,77,4,CONCRETE:8)
Block(-7,77,5,CONCRETE:8)
Block(-7,77,6,CONCRETE:8)
Block(-7,77,7,CONCRETE:8)
Block(-7,77,8,CONCRETE:8)
Block(-7,78,-7,WOOD_STEP:5)
Block(-7,78,-5,WOOD_STEP:5)
Block(-7,78,-3,WOOD_STEP:5)
Block(-7,81,-7,CONCRETE:8)
Block(-7,81,-6,CONCRETE:8)
Block(-7,81,-5,CONCRETE:8)
Block(-7,81,-4,CONCRETE:8)
Block(-7,81,-3,CONCRETE:8)
Block(-7,81,-2,CONCRETE:8)
Block(-7,81,-1,CONCRETE:8)
Block(-7,81,0,CONCRETE:8)
Block(-7,81,1,CONCRETE:8)
Block(-7,81,2,CONCRETE:8)
Block(-7,81,3,CONCRETE:8)
Block(-7,81,4,CONCRETE:8)
Block(-7,81,5,CONCRETE:8)
Block(-7,81,6,CONCRETE:8)
Block(-7,81,7,CONCRETE:8)
Block(-7,81,8,CONCRETE:8)
Block(-7,82,-7,WOOD_STEP:5)
Block(-7,82,-5,WOOD_STEP:5)
Block(-7,82,-3,WOOD_STEP:5)
Block(-7,85,-7,CONCRETE:8)
Block(-7,85,-6,CONCRETE:8)
Block(-7,85,-5,CONCRETE:8)
Block(-7,85,-4,CONCRETE:8)
Block(-7,85,-3,CONCRETE:8)
Block(-7,85,-2,CONCRETE:8)
Block(-7,85,-1,CONCRETE:8)
Block(-7,85,0,CONCRETE:8)
Block(-7,85,1,CONCRETE:8)
Block(-7,85,2,CONCRETE:8)
Block(-7,85,3,CONCRETE:8)
Block(-7,85,4,CONCRETE:8)
Block(-7,85,5,CONCRETE:8)
Block(-7,85,6,CONCRETE:8)
Block(-7,85,7,CONCRETE:8)
Block(-7,85,8,CONCRETE:8)
Block(-7,86,-7,WOOD_STEP:5)
Block(-7,86,-5,WOOD_STEP:5)
Block(-7,86,-3,WOOD_STEP:5)
Block(-7,89,-7,CONCRETE:8)
Block(-7,89,-6,CONCRETE:8)
Block(-7,89,-5,CONCRETE:8)
Block(-7,89,-4,CONCRETE:8)
Block(-7,89,-3,CONCRETE:8)
Block(-7,89,-2,CONCRETE:8)
Block(-7,89,-1,CONCRETE:8)
Block(-7,89,0,CONCRETE:8)
Block(-7,89,1,CONCRETE:8)
Block(-7,89,2,CONCRETE:8)
Block(-7,89,3,CONCRETE:8)
Block(-7,89,4,CONCRETE:8)
Block(-7,89,5,CONCRETE:8)
Block(-7,89,6,CONCRETE:8)
Block(-7,89,7,CONCRETE:8)
Block(-7,89,8,CONCRETE:8)
Block(-7,90,-7,WOOD_STEP:5)
Block(-7,90,-5,WOOD_STEP:5)
Block(-7,90,-3,WOOD_STEP:5)
Block(-7,93,-7,CONCRETE:8)
Block(-7,93,-6,CONCRETE:8)
Block(-7,93,-5,CONCRETE:8)
Block(-7,93,-4,CONCRETE:8)
Block(-7,93,-3,CONCRETE:8)
Block(-7,93,-2,CONCRETE:8)
Block(-7,93,-1,CONCRETE:8)
Block(-7,93,0,CONCRETE:8)
Block(-7,93,1,CONCRETE:8)
Block(-7,93,2,CONCRETE:8)
Block(-7,93,3,CONCRETE:8)
Block(-7,93,4,CONCRETE:8)
Block(-7,93,5,CONCRETE:8)
Block(-7,93,6,CONCRETE:8)
Block(-7,93,7,CONCRETE:8)
Block(-7,93,8,CONCRETE:8)
Block(-7,94,-7,WOOD_STEP:5)
Block(-7,94,-5,WOOD_STEP:5)
Block(-7,94,-3,WOOD_STEP:5)
Block(-7,97,-7,CONCRETE:8)
Block(-7,97,-6,CONCRETE:8)
Block(-7,97,-5,CONCRETE:8)
Block(-7,97,-4,CONCRETE:8)
Block(-7,97,-3,CONCRETE:8)
Block(-7,97,-2,CONCRETE:8)
Block(-7,97,-1,CONCRETE:8)
Block(-7,97,0,CONCRETE:8)
Block(-7,97,1,CONCRETE:8)
Block(-7,97,2,CONCRETE:8)
Block(-7,97,3,CONCRETE:8)
Block(-7,97,4,CONCRETE:8)
Block(-7,97,5,CONCRETE:8)
Block(-7,97,6,CONCRETE:8)
Block(-7,97,7,CONCRETE:8)
Block(-7,97,8,CONCRETE:8)
Block(-7,98,-7,WOOD_STEP:5)
Block(-7,98,-5,WOOD_STEP:5)
Block(-7,98,-3,WOOD_STEP:5)
Block(-7,101,-7,CONCRETE:8)
Block(-7,101,-6,CONCRETE:8)
Block(-7,101,-5,CONCRETE:8)
Block(-7,101,-4,CONCRETE:8)
Block(-7,101,-3,CONCRETE:8)
Block(-7,101,-2,CONCRETE:8)
Block(-7,101,-1,CONCRETE:8)
Block(-7,101,0,CONCRETE:8)
Block(-7,101,1,CONCRETE:8)
Block(-7,101,2,CONCRETE:8)
Block(-7,101,3,CONCRETE:8)
Block(-7,101,4,CONCRETE:8)
Block(-7,101,5,CONCRETE:8)
Block(-7,101,6,CONCRETE:8)
Block(-7,101,7,CONCRETE:8)
Block(-7,101,8,CONCRETE:8)
Block(-7,102,-7,WOOD_STEP:5)
Block(-7,102,-5,WOOD_STEP:5)
Block(-7,102,-3,WOOD_STEP:5)
Block(-7,105,-7,CONCRETE:8)
Block(-7,105,-6,CONCRETE:8)
Block(-7,105,-5,CONCRETE:8)
Block(-7,105,-4,CONCRETE:8)
Block(-7,105,-3,CONCRETE:8)
Block(-7,105,-2,CONCRETE:8)
Block(-7,105,-1,CONCRETE:8)
Block(-7,105,0,CONCRETE:8)
Block(-7,105,1,CONCRETE:8)
Block(-7,105,2,CONCRETE:8)
Block(-7,105,3,CONCRETE:8)
Block(-7,105,4,CONCRETE:8)
Block(-7,105,5,CONCRETE:8)
Block(-7,105,6,CONCRETE:8)
Block(-7,105,7,CONCRETE:8)
Block(-7,105,8,CONCRETE:8)
Block(-7,106,-7,WOOD_STEP:5)
Block(-7,106,-5,WOOD_STEP:5)
Block(-7,106,-3,WOOD_STEP:5)
Block(-7,109,-7,CONCRETE:8)
Block(-7,109,-6,CONCRETE:8)
Block(-7,109,-5,CONCRETE:8)
Block(-7,109,-4,CONCRETE:8)
Block(-7,109,-3,CONCRETE:8)
Block(-7,109,-2,CONCRETE:8)
Block(-7,109,-1,CONCRETE:8)
Block(-7,109,0,CONCRETE:8)
Block(-7,109,1,CONCRETE:8)
Block(-7,109,2,CONCRETE:8)
Block(-7,109,3,CONCRETE:8)
Block(-7,109,4,CONCRETE:8)
Block(-7,109,5,CONCRETE:8)
Block(-7,109,6,CONCRETE:8)
Block(-7,109,7,CONCRETE:8)
Block(-7,109,8,CONCRETE:8)
Block(-7,110,6,STONE_PLATE:0)
Block(-7,110,7,STONE_PLATE:0)
Block(-7,117,-7,CONCRETE:8)
Block(-7,117,-6,CONCRETE:8)
Block(-7,117,-5,CONCRETE:8)
Block(-7,117,-4,CONCRETE:8)
Block(-7,117,-3,CONCRETE:8)
Block(-7,117,-2,CONCRETE:8)
Block(-7,117,-1,CONCRETE:8)
Block(-7,117,0,CONCRETE:8)
Block(-7,117,1,CONCRETE:8)
Block(-7,117,2,CONCRETE:8)
Block(-7,117,3,CONCRETE:8)
Block(-7,117,4,CONCRETE:8)
Block(-7,117,5,CONCRETE:8)
Block(-7,117,6,CONCRETE:8)
Block(-7,117,7,CONCRETE:8)
Block(-7,117,8,CONCRETE:8)
Block(-6,0,-7,CONCRETE:7)
Block(-6,0,-6,CONCRETE:7)
Block(-6,0,-5,CONCRETE:7)
Block(-6,0,-4,CONCRETE:7)
Block(-6,0,-3,CONCRETE:7)
Block(-6,0,-2,CONCRETE:7)
Block(-6,0,-1,CONCRETE:7)
Block(-6,0,0,CONCRETE:7)
Block(-6,0,1,CONCRETE:7)
Block(-6,0,2,CONCRETE:7)
Block(-6,0,3,CONCRETE:7)
Block(-6,0,4,CONCRETE:7)
Block(-6,0,5,CONCRETE:7)
Block(-6,0,6,CONCRETE:7)
Block(-6,0,7,CONCRETE:7)
Block(-6,0,8,CONCRETE:7)
Block(-6,1,-7,CONCRETE:7)
Block(-6,1,-6,CONCRETE:7)
Block(-6,1,-5,CONCRETE:7)
Block(-6,1,-4,CONCRETE:7)
Block(-6,1,-3,CONCRETE:7)
Block(-6,1,-2,CONCRETE:7)
Block(-6,1,-1,CONCRETE:7)
Block(-6,1,0,CONCRETE:7)
Block(-6,1,1,CONCRETE:7)
Block(-6,1,2,CONCRETE:7)
Block(-6,1,3,CONCRETE:7)
Block(-6,1,4,CONCRETE:7)
Block(-6,1,5,CONCRETE:7)
Block(-6,1,6,CONCRETE:7)
Block(-6,1,7,CONCRETE:7)
Block(-6,1,8,CONCRETE:7)
Block(-6,2,-7,CONCRETE:7)
Block(-6,2,-6,CONCRETE:7)
Block(-6,2,-5,CONCRETE:7)
Block(-6,2,-4,CONCRETE:7)
Block(-6,2,-3,CONCRETE:7)
Block(-6,2,-2,CONCRETE:7)
Block(-6,2,-1,CONCRETE:7)
Block(-6,2,0,CONCRETE:7)
Block(-6,2,1,CONCRETE:7)
Block(-6,2,2,CONCRETE:7)
Block(-6,2,3,CONCRETE:7)
Block(-6,2,4,CONCRETE:7)
Block(-6,2,5,CONCRETE:7)
Block(-6,2,6,CONCRETE:7)
Block(-6,2,7,CONCRETE:7)
Block(-6,2,8,CONCRETE:7)
Block(-6,3,-7,CONCRETE:7)
Block(-6,3,-6,CONCRETE:7)
Block(-6,3,-5,CONCRETE:7)
Block(-6,3,-4,CONCRETE:7)
Block(-6,3,-3,CONCRETE:7)
Block(-6,3,-2,CONCRETE:7)
Block(-6,3,-1,CONCRETE:7)
Block(-6,3,0,CONCRETE:7)
Block(-6,3,1,CONCRETE:7)
Block(-6,3,2,CONCRETE:7)
Block(-6,3,3,CONCRETE:7)
Block(-6,3,4,CONCRETE:7)
Block(-6,3,5,CONCRETE:7)
Block(-6,3,6,CONCRETE:7)
Block(-6,3,7,CONCRETE:7)
Block(-6,3,8,CONCRETE:7)
Block(-6,4,-7,CONCRETE:7)
Block(-6,4,-6,CONCRETE:7)
Block(-6,4,-5,CONCRETE:7)
Block(-6,4,-4,CONCRETE:7)
Block(-6,4,-3,CONCRETE:7)
Block(-6,4,-2,CONCRETE:7)
Block(-6,4,-1,CONCRETE:7)
Block(-6,4,0,CONCRETE:7)
Block(-6,4,1,CONCRETE:7)
Block(-6,4,2,CONCRETE:7)
Block(-6,4,3,CONCRETE:7)
Block(-6,4,4,CONCRETE:7)
Block(-6,4,5,CONCRETE:7)
Block(-6,4,6,CONCRETE:7)
Block(-6,4,7,CONCRETE:7)
Block(-6,4,8,CONCRETE:7)
Block(-6,5,-7,CONCRETE:7)
Block(-6,5,-6,CONCRETE:7)
Block(-6,5,-5,CONCRETE:7)
Block(-6,5,-4,CONCRETE:7)
Block(-6,5,-3,CONCRETE:7)
Block(-6,5,-2,CONCRETE:7)
Block(-6,5,-1,CONCRETE:7)
Block(-6,5,0,CONCRETE:7)
Block(-6,5,1,CONCRETE:7)
Block(-6,5,2,CONCRETE:7)
Block(-6,5,3,CONCRETE:7)
Block(-6,5,4,CONCRETE:7)
Block(-6,5,5,CONCRETE:7)
Block(-6,5,6,CONCRETE:7)
Block(-6,5,7,CONCRETE:7)
Block(-6,5,8,CONCRETE:7)
Block(-6,6,-7,CONCRETE:7)
Block(-6,6,-6,CONCRETE:7)
Block(-6,6,-5,CONCRETE:7)
Block(-6,6,-4,CONCRETE:7)
Block(-6,6,-3,CONCRETE:7)
Block(-6,6,-2,CONCRETE:7)
Block(-6,6,-1,CONCRETE:7)
Block(-6,6,0,CONCRETE:7)
Block(-6,6,1,CONCRETE:7)
Block(-6,6,2,CONCRETE:7)
Block(-6,6,3,CONCRETE:7)
Block(-6,6,4,CONCRETE:7)
Block(-6,6,5,CONCRETE:7)
Block(-6,6,6,CONCRETE:7)
Block(-6,6,7,CONCRETE:7)
Block(-6,6,8,CONCRETE:7)
Block(-6,7,-7,CONCRETE:7)
Block(-6,7,-6,CONCRETE:7)
Block(-6,7,-5,CONCRETE:7)
Block(-6,7,-4,CONCRETE:7)
Block(-6,7,-3,CONCRETE:7)
Block(-6,7,-2,CONCRETE:7)
Block(-6,7,-1,CONCRETE:7)
Block(-6,7,0,CONCRETE:7)
Block(-6,7,1,CONCRETE:7)
Block(-6,7,2,CONCRETE:7)
Block(-6,7,3,CONCRETE:7)
Block(-6,7,4,CONCRETE:7)
Block(-6,7,5,CONCRETE:7)
Block(-6,7,6,CONCRETE:7)
Block(-6,7,7,CONCRETE:7)
Block(-6,7,8,CONCRETE:7)
Block(-6,8,-7,CONCRETE:7)
Block(-6,8,-6,CONCRETE:7)
Block(-6,8,-5,CONCRETE:7)
Block(-6,8,-4,CONCRETE:7)
Block(-6,8,-3,CONCRETE:7)
Block(-6,8,-2,CONCRETE:7)
Block(-6,8,-1,CONCRETE:7)
Block(-6,8,0,CONCRETE:7)
Block(-6,8,1,CONCRETE:7)
Block(-6,8,2,CONCRETE:7)
Block(-6,8,3,CONCRETE:7)
Block(-6,8,4,CONCRETE:7)
Block(-6,8,5,CONCRETE:7)
Block(-6,8,6,CONCRETE:7)
Block(-6,8,7,CONCRETE:7)
Block(-6,8,8,CONCRETE:7)
Block(-6,9,-7,CONCRETE:7)
Block(-6,9,-6,CONCRETE:7)
Block(-6,9,-5,CONCRETE:7)
Block(-6,9,-4,CONCRETE:7)
Block(-6,9,-3,CONCRETE:7)
Block(-6,9,-2,CONCRETE:7)
Block(-6,9,-1,CONCRETE:7)
Block(-6,9,0,CONCRETE:7)
Block(-6,9,1,CONCRETE:7)
Block(-6,9,2,CONCRETE:7)
Block(-6,9,3,CONCRETE:7)
Block(-6,9,4,CONCRETE:7)
Block(-6,9,5,CONCRETE:7)
Block(-6,9,6,CONCRETE:7)
Block(-6,9,7,CONCRETE:7)
Block(-6,9,8,CONCRETE:7)
Block(-6,10,-7,CONCRETE:8)
Block(-6,10,-6,CONCRETE:8)
Block(-6,10,-5,CONCRETE:8)
Block(-6,10,-4,CONCRETE:8)
Block(-6,10,-3,CONCRETE:8)
Block(-6,10,-2,CONCRETE:8)
Block(-6,10,-1,CONCRETE:8)
Block(-6,10,0,CONCRETE:8)
Block(-6,10,1,CONCRETE:8)
Block(-6,10,2,CONCRETE:8)
Block(-6,10,3,CONCRETE:8)
Block(-6,10,4,CONCRETE:8)
Block(-6,10,5,CONCRETE:8)
Block(-6,10,6,CONCRETE:8)
Block(-6,10,7,CONCRETE:8)
Block(-6,10,8,CONCRETE:8)
Block(-6,11,-7,CONCRETE:8)
Block(-6,11,-6,CONCRETE:8)
Block(-6,11,-5,CONCRETE:8)
Block(-6,11,-4,CONCRETE:8)
Block(-6,11,-3,CONCRETE:8)
Block(-6,11,-2,CONCRETE:8)
Block(-6,11,-1,CONCRETE:8)
Block(-6,11,0,CONCRETE:8)
Block(-6,11,1,CONCRETE:8)
Block(-6,11,2,CONCRETE:8)
Block(-6,11,3,CONCRETE:8)
Block(-6,11,4,CONCRETE:8)
Block(-6,11,5,CONCRETE:8)
Block(-6,11,6,CONCRETE:8)
Block(-6,11,7,CONCRETE:8)
Block(-6,11,8,CONCRETE:8)
Block(-6,12,-7,CONCRETE:8)
Block(-6,12,-6,CONCRETE:8)
Block(-6,12,-5,CONCRETE:8)
Block(-6,12,-4,CONCRETE:8)
Block(-6,12,-3,CONCRETE:8)
Block(-6,12,-2,CONCRETE:8)
Block(-6,12,-1,CONCRETE:8)
Block(-6,12,0,CONCRETE:8)
Block(-6,12,1,CONCRETE:8)
Block(-6,12,2,CONCRETE:8)
Block(-6,12,3,CONCRETE:8)
Block(-6,12,4,CONCRETE:8)
Block(-6,12,5,CONCRETE:8)
Block(-6,12,6,CONCRETE:8)
Block(-6,12,7,CONCRETE:8)
Block(-6,12,8,CONCRETE:8)
Block(-6,13,-7,CONCRETE:8)
Block(-6,13,-6,CONCRETE:8)
Block(-6,13,-5,CONCRETE:8)
Block(-6,13,-4,CONCRETE:8)
Block(-6,13,-3,CONCRETE:8)
Block(-6,13,-2,CONCRETE:8)
Block(-6,13,-1,CONCRETE:8)
Block(-6,13,0,CONCRETE:8)
Block(-6,13,1,CONCRETE:8)
Block(-6,13,2,CONCRETE:8)
Block(-6,13,3,CONCRETE:8)
Block(-6,13,4,CONCRETE:8)
Block(-6,13,5,CONCRETE:8)
Block(-6,13,6,CONCRETE:8)
Block(-6,13,7,CONCRETE:8)
Block(-6,13,8,CONCRETE:8)
Block(-6,14,-7,CONCRETE:8)
Block(-6,14,-6,CONCRETE:8)
Block(-6,14,-5,CONCRETE:8)
Block(-6,14,-4,CONCRETE:8)
Block(-6,14,-3,CONCRETE:8)
Block(-6,14,-2,CONCRETE:8)
Block(-6,14,-1,CONCRETE:8)
Block(-6,14,0,CONCRETE:8)
Block(-6,14,1,CONCRETE:8)
Block(-6,14,2,CONCRETE:8)
Block(-6,14,3,CONCRETE:8)
Block(-6,14,4,CONCRETE:8)
Block(-6,14,5,CONCRETE:8)
Block(-6,14,6,CONCRETE:8)
Block(-6,14,7,CONCRETE:8)
Block(-6,14,8,CONCRETE:8)
Block(-6,15,-7,CONCRETE:7)
Block(-6,15,-6,CONCRETE:7)
Block(-6,15,-5,CONCRETE:7)
Block(-6,15,-4,CONCRETE:7)
Block(-6,15,-3,CONCRETE:7)
Block(-6,15,-2,CONCRETE:7)
Block(-6,15,-1,CONCRETE:7)
Block(-6,15,0,CONCRETE:7)
Block(-6,15,1,CONCRETE:7)
Block(-6,15,2,CONCRETE:7)
Block(-6,15,3,CONCRETE:7)
Block(-6,15,4,CONCRETE:7)
Block(-6,15,5,CONCRETE:7)
Block(-6,15,6,CONCRETE:7)
Block(-6,15,7,CONCRETE:7)
Block(-6,15,8,CONCRETE:7)
Block(-6,16,-7,CONCRETE:15)
Block(-6,16,-6,CONCRETE:15)
Block(-6,16,-5,CONCRETE:15)
Block(-6,16,-4,CONCRETE:15)
Block(-6,16,-3,CONCRETE:15)
Block(-6,16,-2,CONCRETE:15)
Block(-6,16,-1,CONCRETE:15)
Block(-6,16,0,CONCRETE:15)
Block(-6,16,1,CONCRETE:15)
Block(-6,16,2,CONCRETE:15)
Block(-6,16,3,CONCRETE:15)
Block(-6,16,4,CONCRETE:15)
Block(-6,16,5,CONCRETE:15)
Block(-6,16,6,CONCRETE:15)
Block(-6,16,7,CONCRETE:15)
Block(-6,16,8,CONCRETE:15)
Block(-6,17,-7,CONCRETE:8)
Block(-6,17,-6,CONCRETE:8)
Block(-6,17,-5,CONCRETE:8)
Block(-6,17,-4,CONCRETE:8)
Block(-6,17,-3,DIRT:1)
Block(-6,17,-2,DIRT:1)
Block(-6,17,-1,GRASS:0)
Block(-6,17,0,GRASS:0)
Block(-6,17,1,GRASS:0)
Block(-6,17,2,DIRT:1)
Block(-6,17,3,DIRT:1)
Block(-6,17,4,GRASS:0)
Block(-6,17,5,GRASS:0)
Block(-6,17,6,DIRT:1)
Block(-6,17,7,GRASS:0)
Block(-6,17,8,GRASS:0)
Block(-6,25,-7,CONCRETE:8)
Block(-6,25,-6,CONCRETE:8)
Block(-6,25,-5,CONCRETE:8)
Block(-6,25,-4,CONCRETE:8)
Block(-6,25,-3,CONCRETE:8)
Block(-6,25,-2,CONCRETE:8)
Block(-6,25,-1,CONCRETE:8)
Block(-6,25,0,CONCRETE:8)
Block(-6,25,1,CONCRETE:8)
Block(-6,25,2,CONCRETE:8)
Block(-6,25,3,CONCRETE:8)
Block(-6,25,4,CONCRETE:8)
Block(-6,25,5,CONCRETE:8)
Block(-6,25,6,CONCRETE:8)
Block(-6,25,7,CONCRETE:8)
Block(-6,25,8,CONCRETE:8)
Block(-6,26,-7,DARK_OAK_STAIRS:0)
Block(-6,26,-5,DARK_OAK_STAIRS:0)
Block(-6,26,-3,DARK_OAK_STAIRS:0)
Block(-6,26,1,SMOOTH_STAIRS:6)
Block(-6,26,2,FURNACE:4,NBT/skyscraper_3x3_02/1-furnaceC0R16.nbt)
Block(-6,26,3,SMOOTH_STAIRS:7)
Block(-6,27,1,IRON_PLATE:0)
Block(-6,27,2,IRON_TRAPDOOR:2)
Block(-6,27,3,IRON_PLATE:0)
Block(-6,29,-7,CONCRETE:8)
Block(-6,29,-6,CONCRETE:8)
Block(-6,29,-5,CONCRETE:8)
Block(-6,29,-4,CONCRETE:8)
Block(-6,29,-3,CONCRETE:8)
Block(-6,29,-2,CONCRETE:8)
Block(-6,29,-1,CONCRETE:8)
Block(-6,29,0,CONCRETE:8)
Block(-6,29,1,CONCRETE:8)
Block(-6,29,2,CONCRETE:8)
Block(-6,29,3,CONCRETE:8)
Block(-6,29,4,CONCRETE:8)
Block(-6,29,5,CONCRETE:8)
Block(-6,29,6,CONCRETE:8)
Block(-6,29,7,CONCRETE:8)
Block(-6,29,8,CONCRETE:8)
Block(-6,30,-7,DARK_OAK_STAIRS:0)
Block(-6,30,-5,DARK_OAK_STAIRS:0)
Block(-6,30,-3,DARK_OAK_STAIRS:0)
Block(-6,30,1,SMOOTH_STAIRS:6)
Block(-6,30,2,FURNACE:4,NBT/skyscraper_3x3_02/2-furnaceC0R16.nbt)
Block(-6,30,3,SMOOTH_STAIRS:7)
Block(-6,31,1,IRON_PLATE:0)
Block(-6,31,2,IRON_TRAPDOOR:2)
Block(-6,31,3,IRON_PLATE:0)
Block(-6,33,-7,CONCRETE:8)
Block(-6,33,-6,CONCRETE:8)
Block(-6,33,-5,CONCRETE:8)
Block(-6,33,-4,CONCRETE:8)
Block(-6,33,-3,CONCRETE:8)
Block(-6,33,-2,CONCRETE:8)
Block(-6,33,-1,CONCRETE:8)
Block(-6,33,0,CONCRETE:8)
Block(-6,33,1,CONCRETE:8)
Block(-6,33,2,CONCRETE:8)
Block(-6,33,3,CONCRETE:8)
Block(-6,33,4,CONCRETE:8)
Block(-6,33,5,CONCRETE:8)
Block(-6,33,6,CONCRETE:8)
Block(-6,33,7,CONCRETE:8)
Block(-6,33,8,CONCRETE:8)
Block(-6,34,-7,DARK_OAK_STAIRS:0)
Block(-6,34,-5,DARK_OAK_STAIRS:0)
Block(-6,34,-3,DARK_OAK_STAIRS:0)
Block(-6,34,1,SMOOTH_STAIRS:6)
Block(-6,34,2,FURNACE:4,NBT/skyscraper_3x3_02/3-furnaceC0R16.nbt)
Block(-6,34,3,SMOOTH_STAIRS:7)
Block(-6,35,1,IRON_PLATE:0)
Block(-6,35,2,IRON_TRAPDOOR:2)
Block(-6,35,3,IRON_PLATE:0)
Block(-6,37,-7,CONCRETE:8)
Block(-6,37,-6,CONCRETE:8)
Block(-6,37,-5,CONCRETE:8)
Block(-6,37,-4,CONCRETE:8)
Block(-6,37,-3,CONCRETE:8)
Block(-6,37,-2,CONCRETE:8)
Block(-6,37,-1,CONCRETE:8)
Block(-6,37,0,CONCRETE:8)
Block(-6,37,1,CONCRETE:8)
Block(-6,37,2,CONCRETE:8)
Block(-6,37,3,CONCRETE:8)
Block(-6,37,4,CONCRETE:8)
Block(-6,37,5,CONCRETE:8)
Block(-6,37,6,CONCRETE:8)
Block(-6,37,7,CONCRETE:8)
Block(-6,37,8,CONCRETE:8)
Block(-6,38,-7,DARK_OAK_STAIRS:0)
Block(-6,38,-5,DARK_OAK_STAIRS:0)
Block(-6,38,-3,DARK_OAK_STAIRS:0)
Block(-6,38,1,SMOOTH_STAIRS:6)
Block(-6,38,2,FURNACE:4,NBT/skyscraper_3x3_02/4-furnaceC0R16.nbt)
Block(-6,38,3,SMOOTH_STAIRS:7)
Block(-6,39,1,IRON_PLATE:0)
Block(-6,39,2,IRON_TRAPDOOR:2)
Block(-6,39,3,IRON_PLATE:0)
Block(-6,41,-7,CONCRETE:8)
Block(-6,41,-6,CONCRETE:8)
Block(-6,41,-5,CONCRETE:8)
Block(-6,41,-4,CONCRETE:8)
Block(-6,41,-3,CONCRETE:8)
Block(-6,41,-2,CONCRETE:8)
Block(-6,41,-1,CONCRETE:8)
Block(-6,41,0,CONCRETE:8)
Block(-6,41,1,CONCRETE:8)
Block(-6,41,2,CONCRETE:8)
Block(-6,41,3,CONCRETE:8)
Block(-6,41,4,CONCRETE:8)
Block(-6,41,5,CONCRETE:8)
Block(-6,41,6,CONCRETE:8)
Block(-6,41,7,CONCRETE:8)
Block(-6,41,8,CONCRETE:8)
Block(-6,42,-7,DARK_OAK_STAIRS:0)
Block(-6,42,-5,DARK_OAK_STAIRS:0)
Block(-6,42,-3,DARK_OAK_STAIRS:0)
Block(-6,42,1,SMOOTH_STAIRS:6)
Block(-6,42,2,FURNACE:4,NBT/skyscraper_3x3_02/5-furnaceC0R16.nbt)
Block(-6,42,3,SMOOTH_STAIRS:7)
Block(-6,43,1,IRON_PLATE:0)
Block(-6,43,2,IRON_TRAPDOOR:2)
Block(-6,43,3,IRON_PLATE:0)
Block(-6,45,-7,CONCRETE:8)
Block(-6,45,-6,CONCRETE:8)
Block(-6,45,-5,CONCRETE:8)
Block(-6,45,-4,CONCRETE:8)
Block(-6,45,-3,CONCRETE:8)
Block(-6,45,-2,CONCRETE:8)
Block(-6,45,-1,CONCRETE:8)
Block(-6,45,0,CONCRETE:8)
Block(-6,45,1,CONCRETE:8)
Block(-6,45,2,CONCRETE:8)
Block(-6,45,3,CONCRETE:8)
Block(-6,45,4,CONCRETE:8)
Block(-6,45,5,CONCRETE:8)
Block(-6,45,6,CONCRETE:8)
Block(-6,45,7,CONCRETE:8)
Block(-6,45,8,CONCRETE:8)
Block(-6,46,-7,DARK_OAK_STAIRS:0)
Block(-6,46,-5,DARK_OAK_STAIRS:0)
Block(-6,46,-3,DARK_OAK_STAIRS:0)
Block(-6,46,1,SMOOTH_STAIRS:6)
Block(-6,46,2,FURNACE:4,NBT/skyscraper_3x3_02/6-furnaceC0R16.nbt)
Block(-6,46,3,SMOOTH_STAIRS:7)
Block(-6,47,1,IRON_PLATE:0)
Block(-6,47,2,IRON_TRAPDOOR:2)
Block(-6,47,3,IRON_PLATE:0)
Block(-6,49,-7,CONCRETE:8)
Block(-6,49,-6,CONCRETE:8)
Block(-6,49,-5,CONCRETE:8)
Block(-6,49,-4,CONCRETE:8)
Block(-6,49,-3,CONCRETE:8)
Block(-6,49,-2,CONCRETE:8)
Block(-6,49,-1,CONCRETE:8)
Block(-6,49,0,CONCRETE:8)
Block(-6,49,1,CONCRETE:8)
Block(-6,49,2,CONCRETE:8)
Block(-6,49,3,CONCRETE:8)
Block(-6,49,4,CONCRETE:8)
Block(-6,49,5,CONCRETE:8)
Block(-6,49,6,CONCRETE:8)
Block(-6,49,7,CONCRETE:8)
Block(-6,49,8,CONCRETE:8)
Block(-6,50,-7,DARK_OAK_STAIRS:0)
Block(-6,50,-5,DARK_OAK_STAIRS:0)
Block(-6,50,-3,DARK_OAK_STAIRS:0)
Block(-6,50,1,SMOOTH_STAIRS:6)
Block(-6,50,2,FURNACE:4,NBT/skyscraper_3x3_02/7-furnaceC0R16.nbt)
Block(-6,50,3,SMOOTH_STAIRS:7)
Block(-6,51,1,IRON_PLATE:0)
Block(-6,51,2,IRON_TRAPDOOR:2)
Block(-6,51,3,IRON_PLATE:0)
Block(-6,53,-7,CONCRETE:8)
Block(-6,53,-6,CONCRETE:8)
Block(-6,53,-5,CONCRETE:8)
Block(-6,53,-4,CONCRETE:8)
Block(-6,53,-3,CONCRETE:8)
Block(-6,53,-2,CONCRETE:8)
Block(-6,53,-1,CONCRETE:8)
Block(-6,53,0,CONCRETE:8)
Block(-6,53,1,CONCRETE:8)
Block(-6,53,2,CONCRETE:8)
Block(-6,53,3,CONCRETE:8)
Block(-6,53,4,CONCRETE:8)
Block(-6,53,5,CONCRETE:8)
Block(-6,53,6,CONCRETE:8)
Block(-6,53,7,CONCRETE:8)
Block(-6,53,8,CONCRETE:8)
Block(-6,54,-7,DARK_OAK_STAIRS:0)
Block(-6,54,-5,DARK_OAK_STAIRS:0)
Block(-6,54,-3,DARK_OAK_STAIRS:0)
Block(-6,54,1,SMOOTH_STAIRS:6)
Block(-6,54,2,FURNACE:4,NBT/skyscraper_3x3_02/8-furnaceC0R16.nbt)
Block(-6,54,3,SMOOTH_STAIRS:7)
Block(-6,55,1,IRON_PLATE:0)
Block(-6,55,2,IRON_TRAPDOOR:2)
Block(-6,55,3,IRON_PLATE:0)
Block(-6,57,-7,CONCRETE:8)
Block(-6,57,-6,CONCRETE:8)
Block(-6,57,-5,CONCRETE:8)
Block(-6,57,-4,CONCRETE:8)
Block(-6,57,-3,CONCRETE:8)
Block(-6,57,-2,CONCRETE:8)
Block(-6,57,-1,CONCRETE:8)
Block(-6,57,0,CONCRETE:8)
Block(-6,57,1,CONCRETE:8)
Block(-6,57,2,CONCRETE:8)
Block(-6,57,3,CONCRETE:8)
Block(-6,57,4,CONCRETE:8)
Block(-6,57,5,CONCRETE:8)
Block(-6,57,6,CONCRETE:8)
Block(-6,57,7,CONCRETE:8)
Block(-6,57,8,CONCRETE:8)
Block(-6,58,-7,DARK_OAK_STAIRS:0)
Block(-6,58,-5,DARK_OAK_STAIRS:0)
Block(-6,58,-3,DARK_OAK_STAIRS:0)
Block(-6,58,1,SMOOTH_STAIRS:6)
Block(-6,58,2,FURNACE:4,NBT/skyscraper_3x3_02/9-furnaceC0R16.nbt)
Block(-6,58,3,SMOOTH_STAIRS:7)
Block(-6,59,1,IRON_PLATE:0)
Block(-6,59,2,IRON_TRAPDOOR:2)
Block(-6,59,3,IRON_PLATE:0)
Block(-6,61,-7,CONCRETE:8)
Block(-6,61,-6,CONCRETE:8)
Block(-6,61,-5,CONCRETE:8)
Block(-6,61,-4,CONCRETE:8)
Block(-6,61,-3,CONCRETE:8)
Block(-6,61,-2,CONCRETE:8)
Block(-6,61,-1,CONCRETE:8)
Block(-6,61,0,CONCRETE:8)
Block(-6,61,1,CONCRETE:8)
Block(-6,61,2,CONCRETE:8)
Block(-6,61,3,CONCRETE:8)
Block(-6,61,4,CONCRETE:8)
Block(-6,61,5,CONCRETE:8)
Block(-6,61,6,CONCRETE:8)
Block(-6,61,7,CONCRETE:8)
Block(-6,61,8,CONCRETE:8)
Block(-6,62,-7,DARK_OAK_STAIRS:0)
Block(-6,62,-5,DARK_OAK_STAIRS:0)
Block(-6,62,-3,DARK_OAK_STAIRS:0)
Block(-6,62,1,SMOOTH_STAIRS:6)
Block(-6,62,2,FURNACE:4,NBT/skyscraper_3x3_02/10-furnaceC0R16.nbt)
Block(-6,62,3,SMOOTH_STAIRS:7)
Block(-6,63,1,IRON_PLATE:0)
Block(-6,63,2,IRON_TRAPDOOR:2)
Block(-6,63,3,IRON_PLATE:0)
Block(-6,65,-7,CONCRETE:8)
Block(-6,65,-6,CONCRETE:8)
Block(-6,65,-5,CONCRETE:8)
Block(-6,65,-4,CONCRETE:8)
Block(-6,65,-3,CONCRETE:8)
Block(-6,65,-2,CONCRETE:8)
Block(-6,65,-1,CONCRETE:8)
Block(-6,65,0,CONCRETE:8)
Block(-6,65,1,CONCRETE:8)
Block(-6,65,2,CONCRETE:8)
Block(-6,65,3,CONCRETE:8)
Block(-6,65,4,CONCRETE:8)
Block(-6,65,5,CONCRETE:8)
Block(-6,65,6,CONCRETE:8)
Block(-6,65,7,CONCRETE:8)
Block(-6,65,8,CONCRETE:8)
Block(-6,66,-7,DARK_OAK_STAIRS:0)
Block(-6,66,-5,DARK_OAK_STAIRS:0)
Block(-6,66,-3,DARK_OAK_STAIRS:0)
Block(-6,66,1,SMOOTH_STAIRS:6)
Block(-6,66,2,FURNACE:4,NBT/skyscraper_3x3_02/11-furnaceC0R16.nbt)
Block(-6,66,3,SMOOTH_STAIRS:7)
Block(-6,67,1,IRON_PLATE:0)
Block(-6,67,2,IRON_TRAPDOOR:2)
Block(-6,67,3,IRON_PLATE:0)
Block(-6,69,-7,CONCRETE:8)
Block(-6,69,-6,CONCRETE:8)
Block(-6,69,-5,CONCRETE:8)
Block(-6,69,-4,CONCRETE:8)
Block(-6,69,-3,CONCRETE:8)
Block(-6,69,-2,CONCRETE:8)
Block(-6,69,-1,CONCRETE:8)
Block(-6,69,0,CONCRETE:8)
Block(-6,69,1,CONCRETE:8)
Block(-6,69,2,CONCRETE:8)
Block(-6,69,3,CONCRETE:8)
Block(-6,69,4,CONCRETE:8)
Block(-6,69,5,CONCRETE:8)
Block(-6,69,6,CONCRETE:8)
Block(-6,69,7,CONCRETE:8)
Block(-6,69,8,CONCRETE:8)
Block(-6,70,-7,DARK_OAK_STAIRS:0)
Block(-6,70,-5,DARK_OAK_STAIRS:0)
Block(-6,70,-3,DARK_OAK_STAIRS:0)
Block(-6,70,1,SMOOTH_STAIRS:6)
Block(-6,70,2,FURNACE:4,NBT/skyscraper_3x3_02/12-furnaceC0R16.nbt)
Block(-6,70,3,SMOOTH_STAIRS:7)
Block(-6,71,1,IRON_PLATE:0)
Block(-6,71,2,IRON_TRAPDOOR:2)
Block(-6,71,3,IRON_PLATE:0)
Block(-6,73,-7,CONCRETE:8)
Block(-6,73,-6,CONCRETE:8)
Block(-6,73,-5,CONCRETE:8)
Block(-6,73,-4,CONCRETE:8)
Block(-6,73,-3,CONCRETE:8)
Block(-6,73,-2,CONCRETE:8)
Block(-6,73,-1,CONCRETE:8)
Block(-6,73,0,CONCRETE:8)
Block(-6,73,1,CONCRETE:8)
Block(-6,73,2,CONCRETE:8)
Block(-6,73,3,CONCRETE:8)
Block(-6,73,4,CONCRETE:8)
Block(-6,73,5,CONCRETE:8)
Block(-6,73,6,CONCRETE:8)
Block(-6,73,7,CONCRETE:8)
Block(-6,73,8,CONCRETE:8)
Block(-6,74,-7,DARK_OAK_STAIRS:0)
Block(-6,74,-5,DARK_OAK_STAIRS:0)
Block(-6,74,-3,DARK_OAK_STAIRS:0)
Block(-6,74,1,SMOOTH_STAIRS:6)
Block(-6,74,2,FURNACE:4,NBT/skyscraper_3x3_02/13-furnaceC0R16.nbt)
Block(-6,74,3,SMOOTH_STAIRS:7)
Block(-6,75,1,IRON_PLATE:0)
Block(-6,75,2,IRON_TRAPDOOR:2)
Block(-6,75,3,IRON_PLATE:0)
Block(-6,77,-7,CONCRETE:8)
Block(-6,77,-6,CONCRETE:8)
Block(-6,77,-5,CONCRETE:8)
Block(-6,77,-4,CONCRETE:8)
Block(-6,77,-3,CONCRETE:8)
Block(-6,77,-2,CONCRETE:8)
Block(-6,77,-1,CONCRETE:8)
Block(-6,77,0,CONCRETE:8)
Block(-6,77,1,CONCRETE:8)
Block(-6,77,2,CONCRETE:8)
Block(-6,77,3,CONCRETE:8)
Block(-6,77,4,CONCRETE:8)
Block(-6,77,5,CONCRETE:8)
Block(-6,77,6,CONCRETE:8)
Block(-6,77,7,CONCRETE:8)
Block(-6,77,8,CONCRETE:8)
Block(-6,78,-7,DARK_OAK_STAIRS:0)
Block(-6,78,-5,DARK_OAK_STAIRS:0)
Block(-6,78,-3,DARK_OAK_STAIRS:0)
Block(-6,78,1,SMOOTH_STAIRS:6)
Block(-6,78,2,FURNACE:4,NBT/skyscraper_3x3_02/14-furnaceC0R16.nbt)
Block(-6,78,3,SMOOTH_STAIRS:7)
Block(-6,79,1,IRON_PLATE:0)
Block(-6,79,2,IRON_TRAPDOOR:2)
Block(-6,79,3,IRON_PLATE:0)
Block(-6,81,-7,CONCRETE:8)
Block(-6,81,-6,CONCRETE:8)
Block(-6,81,-5,CONCRETE:8)
Block(-6,81,-4,CONCRETE:8)
Block(-6,81,-3,CONCRETE:8)
Block(-6,81,-2,CONCRETE:8)
Block(-6,81,-1,CONCRETE:8)
Block(-6,81,0,CONCRETE:8)
Block(-6,81,1,CONCRETE:8)
Block(-6,81,2,CONCRETE:8)
Block(-6,81,3,CONCRETE:8)
Block(-6,81,4,CONCRETE:8)
Block(-6,81,5,CONCRETE:8)
Block(-6,81,6,CONCRETE:8)
Block(-6,81,7,CONCRETE:8)
Block(-6,81,8,CONCRETE:8)
Block(-6,82,-7,DARK_OAK_STAIRS:0)
Block(-6,82,-5,DARK_OAK_STAIRS:0)
Block(-6,82,-3,DARK_OAK_STAIRS:0)
Block(-6,82,1,SMOOTH_STAIRS:6)
Block(-6,82,2,FURNACE:4,NBT/skyscraper_3x3_02/15-furnaceC0R16.nbt)
Block(-6,82,3,SMOOTH_STAIRS:7)
Block(-6,83,1,IRON_PLATE:0)
Block(-6,83,2,IRON_TRAPDOOR:2)
Block(-6,83,3,IRON_PLATE:0)
Block(-6,85,-7,CONCRETE:8)
Block(-6,85,-6,CONCRETE:8)
Block(-6,85,-5,CONCRETE:8)
Block(-6,85,-4,CONCRETE:8)
Block(-6,85,-3,CONCRETE:8)
Block(-6,85,-2,CONCRETE:8)
Block(-6,85,-1,CONCRETE:8)
Block(-6,85,0,CONCRETE:8)
Block(-6,85,1,CONCRETE:8)
Block(-6,85,2,CONCRETE:8)
Block(-6,85,3,CONCRETE:8)
Block(-6,85,4,CONCRETE:8)
Block(-6,85,5,CONCRETE:8)
Block(-6,85,6,CONCRETE:8)
Block(-6,85,7,CONCRETE:8)
Block(-6,85,8,CONCRETE:8)
Block(-6,86,-7,DARK_OAK_STAIRS:0)
Block(-6,86,-5,DARK_OAK_STAIRS:0)
Block(-6,86,-3,DARK_OAK_STAIRS:0)
Block(-6,86,1,SMOOTH_STAIRS:6)
Block(-6,86,2,FURNACE:4,NBT/skyscraper_3x3_02/16-furnaceC0R16.nbt)
Block(-6,86,3,SMOOTH_STAIRS:7)
Block(-6,87,1,IRON_PLATE:0)
Block(-6,87,2,IRON_TRAPDOOR:2)
Block(-6,87,3,IRON_PLATE:0)
Block(-6,89,-7,CONCRETE:8)
Block(-6,89,-6,CONCRETE:8)
Block(-6,89,-5,CONCRETE:8)
Block(-6,89,-4,CONCRETE:8)
Block(-6,89,-3,CONCRETE:8)
Block(-6,89,-2,CONCRETE:8)
Block(-6,89,-1,CONCRETE:8)
Block(-6,89,0,CONCRETE:8)
Block(-6,89,1,CONCRETE:8)
Block(-6,89,2,CONCRETE:8)
Block(-6,89,3,CONCRETE:8)
Block(-6,89,4,CONCRETE:8)
Block(-6,89,5,CONCRETE:8)
Block(-6,89,6,CONCRETE:8)
Block(-6,89,7,CONCRETE:8)
Block(-6,89,8,CONCRETE:8)
Block(-6,90,-7,DARK_OAK_STAIRS:0)
Block(-6,90,-5,DARK_OAK_STAIRS:0)
Block(-6,90,-3,DARK_OAK_STAIRS:0)
Block(-6,90,1,SMOOTH_STAIRS:6)
Block(-6,90,2,FURNACE:4,NBT/skyscraper_3x3_02/17-furnaceC0R16.nbt)
Block(-6,90,3,SMOOTH_STAIRS:7)
Block(-6,91,1,IRON_PLATE:0)
Block(-6,91,2,IRON_TRAPDOOR:2)
Block(-6,91,3,IRON_PLATE:0)
Block(-6,93,-7,CONCRETE:8)
Block(-6,93,-6,CONCRETE:8)
Block(-6,93,-5,CONCRETE:8)
Block(-6,93,-4,CONCRETE:8)
Block(-6,93,-3,CONCRETE:8)
Block(-6,93,-2,CONCRETE:8)
Block(-6,93,-1,CONCRETE:8)
Block(-6,93,0,CONCRETE:8)
Block(-6,93,1,CONCRETE:8)
Block(-6,93,2,CONCRETE:8)
Block(-6,93,3,CONCRETE:8)
Block(-6,93,4,CONCRETE:8)
Block(-6,93,5,CONCRETE:8)
Block(-6,93,6,CONCRETE:8)
Block(-6,93,7,CONCRETE:8)
Block(-6,93,8,CONCRETE:8)
Block(-6,94,-7,DARK_OAK_STAIRS:0)
Block(-6,94,-5,DARK_OAK_STAIRS:0)
Block(-6,94,-3,DARK_OAK_STAIRS:0)
Block(-6,94,1,SMOOTH_STAIRS:6)
Block(-6,94,2,FURNACE:4,NBT/skyscraper_3x3_02/18-furnaceC0R16.nbt)
Block(-6,94,3,SMOOTH_STAIRS:7)
Block(-6,95,1,IRON_PLATE:0)
Block(-6,95,2,IRON_TRAPDOOR:2)
Block(-6,95,3,IRON_PLATE:0)
Block(-6,97,-7,CONCRETE:8)
Block(-6,97,-6,CONCRETE:8)
Block(-6,97,-5,CONCRETE:8)
Block(-6,97,-4,CONCRETE:8)
Block(-6,97,-3,CONCRETE:8)
Block(-6,97,-2,CONCRETE:8)
Block(-6,97,-1,CONCRETE:8)
Block(-6,97,0,CONCRETE:8)
Block(-6,97,1,CONCRETE:8)
Block(-6,97,2,CONCRETE:8)
Block(-6,97,3,CONCRETE:8)
Block(-6,97,4,CONCRETE:8)
Block(-6,97,5,CONCRETE:8)
Block(-6,97,6,CONCRETE:8)
Block(-6,97,7,CONCRETE:8)
Block(-6,97,8,CONCRETE:8)
Block(-6,98,-7,DARK_OAK_STAIRS:0)
Block(-6,98,-5,DARK_OAK_STAIRS:0)
Block(-6,98,-3,DARK_OAK_STAIRS:0)
Block(-6,98,1,SMOOTH_STAIRS:6)
Block(-6,98,2,FURNACE:4,NBT/skyscraper_3x3_02/19-furnaceC0R16.nbt)
Block(-6,98,3,SMOOTH_STAIRS:7)
Block(-6,99,1,IRON_PLATE:0)
Block(-6,99,2,IRON_TRAPDOOR:2)
Block(-6,99,3,IRON_PLATE:0)
Block(-6,101,-7,CONCRETE:8)
Block(-6,101,-6,CONCRETE:8)
Block(-6,101,-5,CONCRETE:8)
Block(-6,101,-4,CONCRETE:8)
Block(-6,101,-3,CONCRETE:8)
Block(-6,101,-2,CONCRETE:8)
Block(-6,101,-1,CONCRETE:8)
Block(-6,101,0,CONCRETE:8)
Block(-6,101,1,CONCRETE:8)
Block(-6,101,2,CONCRETE:8)
Block(-6,101,3,CONCRETE:8)
Block(-6,101,4,CONCRETE:8)
Block(-6,101,5,CONCRETE:8)
Block(-6,101,6,CONCRETE:8)
Block(-6,101,7,CONCRETE:8)
Block(-6,101,8,CONCRETE:8)
Block(-6,102,-7,DARK_OAK_STAIRS:0)
Block(-6,102,-5,DARK_OAK_STAIRS:0)
Block(-6,102,-3,DARK_OAK_STAIRS:0)
Block(-6,102,1,SMOOTH_STAIRS:6)
Block(-6,102,2,FURNACE:4,NBT/skyscraper_3x3_02/20-furnaceC0R16.nbt)
Block(-6,102,3,SMOOTH_STAIRS:7)
Block(-6,103,1,IRON_PLATE:0)
Block(-6,103,2,IRON_TRAPDOOR:2)
Block(-6,103,3,IRON_PLATE:0)
Block(-6,105,-7,CONCRETE:8)
Block(-6,105,-6,CONCRETE:8)
Block(-6,105,-5,CONCRETE:8)
Block(-6,105,-4,CONCRETE:8)
Block(-6,105,-3,CONCRETE:8)
Block(-6,105,-2,CONCRETE:8)
Block(-6,105,-1,CONCRETE:8)
Block(-6,105,0,CONCRETE:8)
Block(-6,105,1,CONCRETE:8)
Block(-6,105,2,CONCRETE:8)
Block(-6,105,3,CONCRETE:8)
Block(-6,105,4,CONCRETE:8)
Block(-6,105,5,CONCRETE:8)
Block(-6,105,6,CONCRETE:8)
Block(-6,105,7,CONCRETE:8)
Block(-6,105,8,CONCRETE:8)
Block(-6,106,-7,DARK_OAK_STAIRS:0)
Block(-6,106,-5,DARK_OAK_STAIRS:0)
Block(-6,106,-3,DARK_OAK_STAIRS:0)
Block(-6,106,1,SMOOTH_STAIRS:6)
Block(-6,106,2,FURNACE:4,NBT/skyscraper_3x3_02/21-furnaceC0R16.nbt)
Block(-6,106,3,SMOOTH_STAIRS:7)
Block(-6,107,1,IRON_PLATE:0)
Block(-6,107,2,IRON_TRAPDOOR:2)
Block(-6,107,3,IRON_PLATE:0)
Block(-6,109,-7,CONCRETE:8)
Block(-6,109,-6,CONCRETE:8)
Block(-6,109,-5,CONCRETE:8)
Block(-6,109,-4,CONCRETE:8)
Block(-6,109,-3,CONCRETE:8)
Block(-6,109,-2,CONCRETE:8)
Block(-6,109,-1,CONCRETE:8)
Block(-6,109,0,CONCRETE:8)
Block(-6,109,1,CONCRETE:8)
Block(-6,109,2,CONCRETE:8)
Block(-6,109,3,CONCRETE:8)
Block(-6,109,4,CONCRETE:8)
Block(-6,109,5,CONCRETE:8)
Block(-6,109,6,CONCRETE:8)
Block(-6,109,7,CONCRETE:8)
Block(-6,109,8,CONCRETE:8)
Block(-6,110,4,WOOD_STEP:5)
Block(-6,110,6,STONE_PLATE:0)
Block(-6,110,7,STONE_PLATE:0)
Block(-6,117,-7,CONCRETE:8)
Block(-6,117,-6,CONCRETE:8)
Block(-6,117,-5,CONCRETE:8)
Block(-6,117,-4,CONCRETE:8)
Block(-6,117,-3,CONCRETE:8)
Block(-6,117,-2,CONCRETE:8)
Block(-6,117,-1,CONCRETE:8)
Block(-6,117,0,CONCRETE:8)
Block(-6,117,1,CONCRETE:8)
Block(-6,117,2,CONCRETE:8)
Block(-6,117,3,CONCRETE:8)
Block(-6,117,4,CONCRETE:8)
Block(-6,117,5,CONCRETE:8)
Block(-6,117,6,CONCRETE:8)
Block(-6,117,7,CONCRETE:8)
Block(-6,117,8,CONCRETE:8)
Block(-5,0,-7,CONCRETE:7)
Block(-5,0,-6,CONCRETE:7)
Block(-5,0,-5,CONCRETE:7)
Block(-5,0,-4,CONCRETE:7)
Block(-5,0,-3,CONCRETE:7)
Block(-5,0,-2,CONCRETE:7)
Block(-5,0,-1,CONCRETE:7)
Block(-5,0,0,CONCRETE:7)
Block(-5,0,1,CONCRETE:7)
Block(-5,0,2,CONCRETE:7)
Block(-5,0,3,CONCRETE:7)
Block(-5,0,4,CONCRETE:7)
Block(-5,0,5,CONCRETE:7)
Block(-5,0,6,CONCRETE:7)
Block(-5,0,7,CONCRETE:7)
Block(-5,0,8,CONCRETE:7)
Block(-5,1,-7,CONCRETE:7)
Block(-5,1,-6,CONCRETE:7)
Block(-5,1,-5,CONCRETE:7)
Block(-5,1,-4,CONCRETE:7)
Block(-5,1,-3,CONCRETE:7)
Block(-5,1,-2,CONCRETE:7)
Block(-5,1,-1,CONCRETE:7)
Block(-5,1,0,CONCRETE:7)
Block(-5,1,1,CONCRETE:7)
Block(-5,1,2,CONCRETE:7)
Block(-5,1,3,CONCRETE:7)
Block(-5,1,4,CONCRETE:7)
Block(-5,1,5,CONCRETE:7)
Block(-5,1,6,CONCRETE:7)
Block(-5,1,7,CONCRETE:7)
Block(-5,1,8,CONCRETE:7)
Block(-5,2,-7,CONCRETE:7)
Block(-5,2,-6,CONCRETE:7)
Block(-5,2,-5,CONCRETE:7)
Block(-5,2,-4,CONCRETE:7)
Block(-5,2,-3,CONCRETE:7)
Block(-5,2,-2,CONCRETE:7)
Block(-5,2,-1,CONCRETE:7)
Block(-5,2,0,CONCRETE:7)
Block(-5,2,1,CONCRETE:7)
Block(-5,2,2,CONCRETE:7)
Block(-5,2,3,CONCRETE:7)
Block(-5,2,4,CONCRETE:7)
Block(-5,2,5,CONCRETE:7)
Block(-5,2,6,CONCRETE:7)
Block(-5,2,7,CONCRETE:7)
Block(-5,2,8,CONCRETE:7)
Block(-5,3,-7,CONCRETE:7)
Block(-5,3,-6,SMOOTH_STAIRS:1)
Block(-5,3,-5,SMOOTH_STAIRS:1)
Block(-5,3,-4,CONCRETE:7)
Block(-5,3,-3,SMOOTH_STAIRS:1)
Block(-5,3,-2,SMOOTH_STAIRS:1)
Block(-5,3,-1,CONCRETE:7)
Block(-5,3,0,SMOOTH_STAIRS:1)
Block(-5,3,1,SMOOTH_STAIRS:1)
Block(-5,3,2,CONCRETE:7)
Block(-5,3,3,SMOOTH_STAIRS:1)
Block(-5,3,4,SMOOTH_STAIRS:1)
Block(-5,3,5,CONCRETE:7)
Block(-5,3,6,SMOOTH_STAIRS:1)
Block(-5,3,7,SMOOTH_STAIRS:1)
Block(-5,3,8,CONCRETE:7)
Block(-5,4,-7,CONCRETE:7)
Block(-5,4,-6,COBBLE_WALL:0)
Block(-5,4,-5,COBBLE_WALL:0)
Block(-5,4,-4,CONCRETE:7)
Block(-5,4,-3,COBBLE_WALL:0)
Block(-5,4,-2,COBBLE_WALL:0)
Block(-5,4,-1,CONCRETE:7)
Block(-5,4,0,COBBLE_WALL:0)
Block(-5,4,1,COBBLE_WALL:0)
Block(-5,4,2,CONCRETE:7)
Block(-5,4,3,COBBLE_WALL:0)
Block(-5,4,4,COBBLE_WALL:0)
Block(-5,4,5,CONCRETE:7)
Block(-5,4,6,COBBLE_WALL:0)
Block(-5,4,7,COBBLE_WALL:0)
Block(-5,4,8,CONCRETE:7)
Block(-5,5,-7,CONCRETE:7)
Block(-5,5,-6,SMOOTH_STAIRS:5)
Block(-5,5,-5,SMOOTH_STAIRS:5)
Block(-5,5,-4,CONCRETE:7)
Block(-5,5,-3,SMOOTH_STAIRS:5)
Block(-5,5,-2,SMOOTH_STAIRS:5)
Block(-5,5,-1,CONCRETE:7)
Block(-5,5,0,SMOOTH_STAIRS:5)
Block(-5,5,1,SMOOTH_STAIRS:5)
Block(-5,5,2,CONCRETE:7)
Block(-5,5,3,SMOOTH_STAIRS:5)
Block(-5,5,4,SMOOTH_STAIRS:5)
Block(-5,5,5,CONCRETE:7)
Block(-5,5,6,SMOOTH_STAIRS:5)
Block(-5,5,7,SMOOTH_STAIRS:5)
Block(-5,5,8,CONCRETE:7)
Block(-5,6,-7,CONCRETE:7)
Block(-5,6,-6,CONCRETE:7)
Block(-5,6,-5,CONCRETE:7)
Block(-5,6,-4,CONCRETE:7)
Block(-5,6,-3,CONCRETE:7)
Block(-5,6,-2,CONCRETE:7)
Block(-5,6,-1,CONCRETE:7)
Block(-5,6,0,CONCRETE:7)
Block(-5,6,1,CONCRETE:7)
Block(-5,6,2,CONCRETE:7)
Block(-5,6,3,CONCRETE:7)
Block(-5,6,4,CONCRETE:7)
Block(-5,6,5,CONCRETE:7)
Block(-5,6,6,CONCRETE:7)
Block(-5,6,7,CONCRETE:7)
Block(-5,6,8,CONCRETE:7)
Block(-5,7,-7,CONCRETE:7)
Block(-5,7,-6,CONCRETE:7)
Block(-5,7,-5,CONCRETE:7)
Block(-5,7,-4,CONCRETE:7)
Block(-5,7,-3,CONCRETE:7)
Block(-5,7,-2,CONCRETE:7)
Block(-5,7,-1,CONCRETE:7)
Block(-5,7,0,CONCRETE:7)
Block(-5,7,1,CONCRETE:7)
Block(-5,7,2,CONCRETE:7)
Block(-5,7,3,CONCRETE:7)
Block(-5,7,4,CONCRETE:7)
Block(-5,7,5,CONCRETE:7)
Block(-5,7,6,CONCRETE:7)
Block(-5,7,7,CONCRETE:7)
Block(-5,7,8,CONCRETE:7)
Block(-5,8,-7,CONCRETE:7)
Block(-5,8,-6,CONCRETE:7)
Block(-5,8,-5,CONCRETE:7)
Block(-5,8,-4,CONCRETE:7)
Block(-5,8,-3,CONCRETE:7)
Block(-5,8,-2,CONCRETE:7)
Block(-5,8,-1,CONCRETE:7)
Block(-5,8,0,CONCRETE:7)
Block(-5,8,1,CONCRETE:7)
Block(-5,8,2,CONCRETE:7)
Block(-5,8,3,CONCRETE:7)
Block(-5,8,4,CONCRETE:7)
Block(-5,8,5,CONCRETE:7)
Block(-5,8,6,CONCRETE:7)
Block(-5,8,7,CONCRETE:7)
Block(-5,8,8,CONCRETE:7)
Block(-5,9,-7,CONCRETE:7)
Block(-5,9,-6,CONCRETE:7)
Block(-5,9,-5,CONCRETE:7)
Block(-5,9,-4,CONCRETE:7)
Block(-5,9,-3,CONCRETE:7)
Block(-5,9,-2,CONCRETE:7)
Block(-5,9,-1,CONCRETE:7)
Block(-5,9,0,CONCRETE:7)
Block(-5,9,1,CONCRETE:7)
Block(-5,9,2,CONCRETE:7)
Block(-5,9,3,CONCRETE:7)
Block(-5,9,4,CONCRETE:7)
Block(-5,9,5,CONCRETE:7)
Block(-5,9,6,CONCRETE:7)
Block(-5,9,7,CONCRETE:7)
Block(-5,9,8,CONCRETE:7)
Block(-5,10,-7,CONCRETE:8)
Block(-5,10,-6,CONCRETE:8)
Block(-5,10,-5,CONCRETE:8)
Block(-5,10,-4,CONCRETE:8)
Block(-5,10,-3,CONCRETE:8)
Block(-5,10,-2,CONCRETE:8)
Block(-5,10,-1,CONCRETE:8)
Block(-5,10,0,CONCRETE:8)
Block(-5,10,1,CONCRETE:8)
Block(-5,10,2,CONCRETE:8)
Block(-5,10,3,CONCRETE:8)
Block(-5,10,4,CONCRETE:8)
Block(-5,10,5,CONCRETE:8)
Block(-5,10,6,CONCRETE:8)
Block(-5,10,7,CONCRETE:8)
Block(-5,10,8,CONCRETE:8)
Block(-5,11,-7,CONCRETE:8)
Block(-5,11,-6,CONCRETE:8)
Block(-5,11,-5,CONCRETE:8)
Block(-5,11,-4,CONCRETE:8)
Block(-5,11,-3,CONCRETE:8)
Block(-5,11,-2,CONCRETE:8)
Block(-5,11,-1,CONCRETE:8)
Block(-5,11,0,CONCRETE:8)
Block(-5,11,1,CONCRETE:8)
Block(-5,11,2,CONCRETE:8)
Block(-5,11,3,CONCRETE:8)
Block(-5,11,4,CONCRETE:8)
Block(-5,11,5,CONCRETE:8)
Block(-5,11,6,CONCRETE:8)
Block(-5,11,7,CONCRETE:8)
Block(-5,11,8,CONCRETE:8)
Block(-5,12,-7,CONCRETE:8)
Block(-5,12,-6,CONCRETE:8)
Block(-5,12,-5,CONCRETE:8)
Block(-5,12,-4,CONCRETE:8)
Block(-5,12,-3,CONCRETE:8)
Block(-5,12,-2,CONCRETE:8)
Block(-5,12,-1,CONCRETE:8)
Block(-5,12,0,CONCRETE:8)
Block(-5,12,1,CONCRETE:8)
Block(-5,12,2,CONCRETE:8)
Block(-5,12,3,CONCRETE:8)
Block(-5,12,4,CONCRETE:8)
Block(-5,12,5,CONCRETE:8)
Block(-5,12,6,CONCRETE:8)
Block(-5,12,7,CONCRETE:8)
Block(-5,12,8,CONCRETE:8)
Block(-5,13,-7,CONCRETE:8)
Block(-5,13,-6,CONCRETE:8)
Block(-5,13,-5,CONCRETE:8)
Block(-5,13,-4,CONCRETE:8)
Block(-5,13,-3,CONCRETE:8)
Block(-5,13,-2,CONCRETE:8)
Block(-5,13,-1,CONCRETE:8)
Block(-5,13,0,CONCRETE:8)
Block(-5,13,1,CONCRETE:8)
Block(-5,13,2,CONCRETE:8)
Block(-5,13,3,CONCRETE:8)
Block(-5,13,4,CONCRETE:8)
Block(-5,13,5,CONCRETE:8)
Block(-5,13,6,CONCRETE:8)
Block(-5,13,7,CONCRETE:8)
Block(-5,13,8,CONCRETE:8)
Block(-5,14,-7,CONCRETE:8)
Block(-5,14,-6,CONCRETE:8)
Block(-5,14,-5,CONCRETE:8)
Block(-5,14,-4,CONCRETE:8)
Block(-5,14,-3,CONCRETE:8)
Block(-5,14,-2,CONCRETE:8)
Block(-5,14,-1,CONCRETE:8)
Block(-5,14,0,CONCRETE:8)
Block(-5,14,1,CONCRETE:8)
Block(-5,14,2,CONCRETE:8)
Block(-5,14,3,CONCRETE:8)
Block(-5,14,4,CONCRETE:8)
Block(-5,14,5,CONCRETE:8)
Block(-5,14,6,CONCRETE:8)
Block(-5,14,7,CONCRETE:8)
Block(-5,14,8,CONCRETE:8)
Block(-5,15,-7,CONCRETE:7)
Block(-5,15,-6,CONCRETE:7)
Block(-5,15,-5,CONCRETE:7)
Block(-5,15,-4,CONCRETE:7)
Block(-5,15,-3,CONCRETE:7)
Block(-5,15,-2,CONCRETE:7)
Block(-5,15,-1,CONCRETE:7)
Block(-5,15,0,CONCRETE:7)
Block(-5,15,1,CONCRETE:7)
Block(-5,15,2,CONCRETE:7)
Block(-5,15,3,CONCRETE:7)
Block(-5,15,4,CONCRETE:7)
Block(-5,15,5,CONCRETE:7)
Block(-5,15,6,CONCRETE:7)
Block(-5,15,7,CONCRETE:7)
Block(-5,15,8,CONCRETE:7)
Block(-5,16,-7,CONCRETE:15)
Block(-5,16,-6,CONCRETE:15)
Block(-5,16,-5,CONCRETE:15)
Block(-5,16,-4,CONCRETE:15)
Block(-5,16,-3,CONCRETE:15)
Block(-5,16,-2,CONCRETE:15)
Block(-5,16,-1,CONCRETE:15)
Block(-5,16,0,CONCRETE:15)
Block(-5,16,1,CONCRETE:15)
Block(-5,16,2,CONCRETE:15)
Block(-5,16,3,CONCRETE:15)
Block(-5,16,4,CONCRETE:15)
Block(-5,16,5,CONCRETE:15)
Block(-5,16,6,CONCRETE:15)
Block(-5,16,7,CONCRETE:15)
Block(-5,16,8,CONCRETE:15)
Block(-5,17,-7,CONCRETE:8)
Block(-5,17,-6,CONCRETE:8)
Block(-5,17,-5,CONCRETE:8)
Block(-5,17,-4,CONCRETE:8)
Block(-5,17,-3,CONCRETE:8)
Block(-5,17,-2,CONCRETE:8)
Block(-5,17,-1,CONCRETE:8)
Block(-5,17,0,CONCRETE:8)
Block(-5,17,1,CONCRETE:8)
Block(-5,17,2,CONCRETE:8)
Block(-5,17,3,CONCRETE:8)
Block(-5,17,4,CONCRETE:8)
Block(-5,17,5,CONCRETE:8)
Block(-5,17,6,SEA_LANTERN:0)
Block(-5,17,7,GRASS:0)
Block(-5,17,8,DIRT:1)
Block(-5,18,-7,STAINED_GLASS_PANE:15)
Block(-5,18,-4,STAINED_GLASS_PANE:15)
Block(-5,18,-3,STAINED_GLASS:15)
Block(-5,18,-2,STAINED_GLASS:15)
Block(-5,18,-1,STAINED_GLASS:15)
Block(-5,18,0,STAINED_GLASS:15)
Block(-5,18,1,STAINED_GLASS:15)
Block(-5,18,2,STAINED_GLASS:15)
Block(-5,18,3,STAINED_GLASS:15)
Block(-5,18,4,STAINED_GLASS:15)
Block(-5,18,5,STAINED_GLASS:15)
Block(-5,18,6,STAINED_GLASS:15)
Block(-5,19,-7,STAINED_GLASS_PANE:15)
Block(-5,19,-4,STAINED_GLASS_PANE:15)
Block(-5,19,-3,STAINED_GLASS:15)
Block(-5,19,-2,STAINED_GLASS:15)
Block(-5,19,-1,STAINED_GLASS:15)
Block(-5,19,0,STAINED_GLASS:15)
Block(-5,19,1,STAINED_GLASS:15)
Block(-5,19,2,STAINED_GLASS:15)
Block(-5,19,3,STAINED_GLASS:15)
Block(-5,19,4,STAINED_GLASS:15)
Block(-5,19,5,STAINED_GLASS:15)
Block(-5,19,6,STAINED_GLASS:15)
Block(-5,20,-7,STAINED_GLASS_PANE:15)
Block(-5,20,-6,STAINED_GLASS_PANE:15)
Block(-5,20,-5,STAINED_GLASS_PANE:15)
Block(-5,20,-4,STAINED_GLASS_PANE:15)
Block(-5,20,-3,STAINED_GLASS:15)
Block(-5,20,-2,STAINED_GLASS:15)
Block(-5,20,-1,STAINED_GLASS:15)
Block(-5,20,0,STAINED_GLASS:15)
Block(-5,20,1,STAINED_GLASS:15)
Block(-5,20,2,STAINED_GLASS:15)
Block(-5,20,3,STAINED_GLASS:15)
Block(-5,20,4,STAINED_GLASS:15)
Block(-5,20,5,STAINED_GLASS:15)
Block(-5,20,6,STAINED_GLASS:15)
Block(-5,21,-7,STAINED_GLASS:15)
Block(-5,21,-6,STAINED_GLASS:15)
Block(-5,21,-5,STAINED_GLASS:15)
Block(-5,21,-4,STAINED_GLASS:15)
Block(-5,21,-3,STAINED_GLASS:15)
Block(-5,21,-2,STAINED_GLASS:15)
Block(-5,21,-1,STAINED_GLASS:15)
Block(-5,21,0,STAINED_GLASS:15)
Block(-5,21,1,STAINED_GLASS:15)
Block(-5,21,2,STAINED_GLASS:15)
Block(-5,21,3,STAINED_GLASS:15)
Block(-5,21,4,STAINED_GLASS:15)
Block(-5,21,5,STAINED_GLASS:15)
Block(-5,21,6,STAINED_GLASS:15)
Block(-5,22,-7,CONCRETE:7)
Block(-5,22,-6,CONCRETE:7)
Block(-5,22,-5,CONCRETE:7)
Block(-5,22,-4,CONCRETE:7)
Block(-5,22,-3,STAINED_GLASS:15)
Block(-5,22,-2,STAINED_GLASS:15)
Block(-5,22,-1,STAINED_GLASS:15)
Block(-5,22,0,STAINED_GLASS:15)
Block(-5,22,1,STAINED_GLASS:15)
Block(-5,22,2,STAINED_GLASS:15)
Block(-5,22,3,STAINED_GLASS:15)
Block(-5,22,4,STAINED_GLASS:15)
Block(-5,22,5,STAINED_GLASS:15)
Block(-5,22,6,STAINED_GLASS:15)
Block(-5,23,-7,CONCRETE:7)
Block(-5,23,-6,CONCRETE:7)
Block(-5,23,-5,CONCRETE:7)
Block(-5,23,-4,CONCRETE:7)
Block(-5,23,-3,STAINED_GLASS:15)
Block(-5,23,-2,STAINED_GLASS:15)
Block(-5,23,-1,STAINED_GLASS:15)
Block(-5,23,0,STAINED_GLASS:15)
Block(-5,23,1,STAINED_GLASS:15)
Block(-5,23,2,STAINED_GLASS:15)
Block(-5,23,3,STAINED_GLASS:15)
Block(-5,23,4,STAINED_GLASS:15)
Block(-5,23,5,STAINED_GLASS:15)
Block(-5,23,6,STAINED_GLASS:15)
Block(-5,24,-7,CONCRETE:7)
Block(-5,24,-6,CONCRETE:7)
Block(-5,24,-5,CONCRETE:7)
Block(-5,24,-4,CONCRETE:7)
Block(-5,24,-3,STAINED_GLASS:15)
Block(-5,24,-2,STAINED_GLASS:15)
Block(-5,24,-1,STAINED_GLASS:15)
Block(-5,24,0,STAINED_GLASS:15)
Block(-5,24,1,STAINED_GLASS:15)
Block(-5,24,2,STAINED_GLASS:15)
Block(-5,24,3,STAINED_GLASS:15)
Block(-5,24,4,STAINED_GLASS:15)
Block(-5,24,5,STAINED_GLASS:15)
Block(-5,24,6,STAINED_GLASS:15)
Block(-5,25,-7,CONCRETE:8)
Block(-5,25,-6,CONCRETE:8)
Block(-5,25,-5,CONCRETE:8)
Block(-5,25,-4,CONCRETE:8)
Block(-5,25,-3,CONCRETE:8)
Block(-5,25,-2,CONCRETE:8)
Block(-5,25,-1,CONCRETE:8)
Block(-5,25,0,CONCRETE:8)
Block(-5,25,1,CONCRETE:8)
Block(-5,25,2,CONCRETE:8)
Block(-5,25,3,CONCRETE:8)
Block(-5,25,4,CONCRETE:8)
Block(-5,25,5,CONCRETE:8)
Block(-5,25,6,CONCRETE:8)
Block(-5,25,7,CONCRETE:8)
Block(-5,25,8,CONCRETE:8)
Block(-5,26,-7,CONCRETE:7)
Block(-5,26,-6,CONCRETE:7)
Block(-5,26,-5,CONCRETE:7)
Block(-5,26,-4,CONCRETE:7)
Block(-5,26,-3,STAINED_GLASS:15)
Block(-5,26,-2,STAINED_GLASS:15)
Block(-5,26,-1,STAINED_GLASS:15)
Block(-5,26,0,STAINED_GLASS:15)
Block(-5,26,1,STAINED_GLASS:15)
Block(-5,26,2,STAINED_GLASS:15)
Block(-5,26,3,STAINED_GLASS:15)
Block(-5,26,4,STAINED_GLASS:15)
Block(-5,26,5,STAINED_GLASS:15)
Block(-5,26,6,STAINED_GLASS:15)
Block(-5,27,-7,CONCRETE:7)
Block(-5,27,-6,CONCRETE:7)
Block(-5,27,-5,CONCRETE:7)
Block(-5,27,-4,CONCRETE:7)
Block(-5,27,-3,STAINED_GLASS:15)
Block(-5,27,-2,STAINED_GLASS:15)
Block(-5,27,-1,STAINED_GLASS:15)
Block(-5,27,0,STAINED_GLASS:15)
Block(-5,27,1,STAINED_GLASS:15)
Block(-5,27,2,STAINED_GLASS:15)
Block(-5,27,3,STAINED_GLASS:15)
Block(-5,27,4,STAINED_GLASS:15)
Block(-5,27,5,STAINED_GLASS:15)
Block(-5,27,6,STAINED_GLASS:15)
Block(-5,28,-7,CONCRETE:7)
Block(-5,28,-6,CONCRETE:7)
Block(-5,28,-5,CONCRETE:7)
Block(-5,28,-4,CONCRETE:7)
Block(-5,28,-3,STAINED_GLASS:15)
Block(-5,28,-2,STAINED_GLASS:15)
Block(-5,28,-1,STAINED_GLASS:15)
Block(-5,28,0,STAINED_GLASS:15)
Block(-5,28,1,STAINED_GLASS:15)
Block(-5,28,2,STAINED_GLASS:15)
Block(-5,28,3,STAINED_GLASS:15)
Block(-5,28,4,STAINED_GLASS:15)
Block(-5,28,5,STAINED_GLASS:15)
Block(-5,28,6,STAINED_GLASS:15)
Block(-5,29,-7,CONCRETE:8)
Block(-5,29,-6,CONCRETE:8)
Block(-5,29,-5,CONCRETE:8)
Block(-5,29,-4,CONCRETE:8)
Block(-5,29,-3,CONCRETE:8)
Block(-5,29,-2,CONCRETE:8)
Block(-5,29,-1,CONCRETE:8)
Block(-5,29,0,CONCRETE:8)
Block(-5,29,1,CONCRETE:8)
Block(-5,29,2,CONCRETE:8)
Block(-5,29,3,CONCRETE:8)
Block(-5,29,4,CONCRETE:8)
Block(-5,29,5,CONCRETE:8)
Block(-5,29,6,CONCRETE:8)
Block(-5,29,7,CONCRETE:8)
Block(-5,29,8,CONCRETE:8)
Block(-5,30,-7,CONCRETE:7)
Block(-5,30,-6,CONCRETE:7)
Block(-5,30,-5,CONCRETE:7)
Block(-5,30,-4,CONCRETE:7)
Block(-5,30,-3,STAINED_GLASS:15)
Block(-5,30,-2,STAINED_GLASS:15)
Block(-5,30,-1,STAINED_GLASS:15)
Block(-5,30,0,STAINED_GLASS:15)
Block(-5,30,1,STAINED_GLASS:15)
Block(-5,30,2,STAINED_GLASS:15)
Block(-5,30,3,STAINED_GLASS:15)
Block(-5,30,4,STAINED_GLASS:15)
Block(-5,30,5,STAINED_GLASS:15)
Block(-5,30,6,STAINED_GLASS:15)
Block(-5,31,-7,CONCRETE:7)
Block(-5,31,-6,CONCRETE:7)
Block(-5,31,-5,CONCRETE:7)
Block(-5,31,-4,CONCRETE:7)
Block(-5,31,-3,STAINED_GLASS:15)
Block(-5,31,-2,STAINED_GLASS:15)
Block(-5,31,-1,STAINED_GLASS:15)
Block(-5,31,0,STAINED_GLASS:15)
Block(-5,31,1,STAINED_GLASS:15)
Block(-5,31,2,STAINED_GLASS:15)
Block(-5,31,3,STAINED_GLASS:15)
Block(-5,31,4,STAINED_GLASS:15)
Block(-5,31,5,STAINED_GLASS:15)
Block(-5,31,6,STAINED_GLASS:15)
Block(-5,32,-7,CONCRETE:7)
Block(-5,32,-6,CONCRETE:7)
Block(-5,32,-5,CONCRETE:7)
Block(-5,32,-4,CONCRETE:7)
Block(-5,32,-3,STAINED_GLASS:15)
Block(-5,32,-2,STAINED_GLASS:15)
Block(-5,32,-1,STAINED_GLASS:15)
Block(-5,32,0,STAINED_GLASS:15)
Block(-5,32,1,STAINED_GLASS:15)
Block(-5,32,2,STAINED_GLASS:15)
Block(-5,32,3,STAINED_GLASS:15)
Block(-5,32,4,STAINED_GLASS:15)
Block(-5,32,5,STAINED_GLASS:15)
Block(-5,32,6,STAINED_GLASS:15)
Block(-5,33,-7,CONCRETE:8)
Block(-5,33,-6,CONCRETE:8)
Block(-5,33,-5,CONCRETE:8)
Block(-5,33,-4,CONCRETE:8)
Block(-5,33,-3,CONCRETE:8)
Block(-5,33,-2,CONCRETE:8)
Block(-5,33,-1,CONCRETE:8)
Block(-5,33,0,CONCRETE:8)
Block(-5,33,1,CONCRETE:8)
Block(-5,33,2,CONCRETE:8)
Block(-5,33,3,CONCRETE:8)
Block(-5,33,4,CONCRETE:8)
Block(-5,33,5,CONCRETE:8)
Block(-5,33,6,CONCRETE:8)
Block(-5,33,7,CONCRETE:8)
Block(-5,33,8,CONCRETE:8)
Block(-5,34,-7,CONCRETE:7)
Block(-5,34,-6,CONCRETE:7)
Block(-5,34,-5,CONCRETE:7)
Block(-5,34,-4,CONCRETE:7)
Block(-5,34,-3,STAINED_GLASS:15)
Block(-5,34,-2,STAINED_GLASS:15)
Block(-5,34,-1,STAINED_GLASS:15)
Block(-5,34,0,STAINED_GLASS:15)
Block(-5,34,1,STAINED_GLASS:15)
Block(-5,34,2,STAINED_GLASS:15)
Block(-5,34,3,STAINED_GLASS:15)
Block(-5,34,4,STAINED_GLASS:15)
Block(-5,34,5,STAINED_GLASS:15)
Block(-5,34,6,STAINED_GLASS:15)
Block(-5,35,-7,CONCRETE:7)
Block(-5,35,-6,CONCRETE:7)
Block(-5,35,-5,CONCRETE:7)
Block(-5,35,-4,CONCRETE:7)
Block(-5,35,-3,STAINED_GLASS:15)
Block(-5,35,-2,STAINED_GLASS:15)
Block(-5,35,-1,STAINED_GLASS:15)
Block(-5,35,0,STAINED_GLASS:15)
Block(-5,35,1,STAINED_GLASS:15)
Block(-5,35,2,STAINED_GLASS:15)
Block(-5,35,3,STAINED_GLASS:15)
Block(-5,35,4,STAINED_GLASS:15)
Block(-5,35,5,STAINED_GLASS:15)
Block(-5,35,6,STAINED_GLASS:15)
Block(-5,36,-7,CONCRETE:7)
Block(-5,36,-6,CONCRETE:7)
Block(-5,36,-5,CONCRETE:7)
Block(-5,36,-4,CONCRETE:7)
Block(-5,36,-3,STAINED_GLASS:15)
Block(-5,36,-2,STAINED_GLASS:15)
Block(-5,36,-1,STAINED_GLASS:15)
Block(-5,36,0,STAINED_GLASS:15)
Block(-5,36,1,STAINED_GLASS:15)
Block(-5,36,2,STAINED_GLASS:15)
Block(-5,36,3,STAINED_GLASS:15)
Block(-5,36,4,STAINED_GLASS:15)
Block(-5,36,5,STAINED_GLASS:15)
Block(-5,36,6,STAINED_GLASS:15)
Block(-5,37,-7,CONCRETE:8)
Block(-5,37,-6,CONCRETE:8)
Block(-5,37,-5,CONCRETE:8)
Block(-5,37,-4,CONCRETE:8)
Block(-5,37,-3,CONCRETE:8)
Block(-5,37,-2,CONCRETE:8)
Block(-5,37,-1,CONCRETE:8)
Block(-5,37,0,CONCRETE:8)
Block(-5,37,1,CONCRETE:8)
Block(-5,37,2,CONCRETE:8)
Block(-5,37,3,CONCRETE:8)
Block(-5,37,4,CONCRETE:8)
Block(-5,37,5,CONCRETE:8)
Block(-5,37,6,CONCRETE:8)
Block(-5,37,7,CONCRETE:8)
Block(-5,37,8,CONCRETE:8)
Block(-5,38,-7,CONCRETE:7)
Block(-5,38,-6,CONCRETE:7)
Block(-5,38,-5,CONCRETE:7)
Block(-5,38,-4,CONCRETE:7)
Block(-5,38,-3,STAINED_GLASS:15)
Block(-5,38,-2,STAINED_GLASS:15)
Block(-5,38,-1,STAINED_GLASS:15)
Block(-5,38,0,STAINED_GLASS:15)
Block(-5,38,1,STAINED_GLASS:15)
Block(-5,38,2,STAINED_GLASS:15)
Block(-5,38,3,STAINED_GLASS:15)
Block(-5,38,4,STAINED_GLASS:15)
Block(-5,38,5,STAINED_GLASS:15)
Block(-5,38,6,STAINED_GLASS:15)
Block(-5,39,-7,CONCRETE:7)
Block(-5,39,-6,CONCRETE:7)
Block(-5,39,-5,CONCRETE:7)
Block(-5,39,-4,CONCRETE:7)
Block(-5,39,-3,STAINED_GLASS:15)
Block(-5,39,-2,STAINED_GLASS:15)
Block(-5,39,-1,STAINED_GLASS:15)
Block(-5,39,0,STAINED_GLASS:15)
Block(-5,39,1,STAINED_GLASS:15)
Block(-5,39,2,STAINED_GLASS:15)
Block(-5,39,3,STAINED_GLASS:15)
Block(-5,39,4,STAINED_GLASS:15)
Block(-5,39,5,STAINED_GLASS:15)
Block(-5,39,6,STAINED_GLASS:15)
Block(-5,40,-7,CONCRETE:7)
Block(-5,40,-6,CONCRETE:7)
Block(-5,40,-5,CONCRETE:7)
Block(-5,40,-4,CONCRETE:7)
Block(-5,40,-3,STAINED_GLASS:15)
Block(-5,40,-2,STAINED_GLASS:15)
Block(-5,40,-1,STAINED_GLASS:15)
Block(-5,40,0,STAINED_GLASS:15)
Block(-5,40,1,STAINED_GLASS:15)
Block(-5,40,2,STAINED_GLASS:15)
Block(-5,40,3,STAINED_GLASS:15)
Block(-5,40,4,STAINED_GLASS:15)
Block(-5,40,5,STAINED_GLASS:15)
Block(-5,40,6,STAINED_GLASS:15)
Block(-5,41,-7,CONCRETE:8)
Block(-5,41,-6,CONCRETE:8)
Block(-5,41,-5,CONCRETE:8)
Block(-5,41,-4,CONCRETE:8)
Block(-5,41,-3,CONCRETE:8)
Block(-5,41,-2,CONCRETE:8)
Block(-5,41,-1,CONCRETE:8)
Block(-5,41,0,CONCRETE:8)
Block(-5,41,1,CONCRETE:8)
Block(-5,41,2,CONCRETE:8)
Block(-5,41,3,CONCRETE:8)
Block(-5,41,4,CONCRETE:8)
Block(-5,41,5,CONCRETE:8)
Block(-5,41,6,CONCRETE:8)
Block(-5,41,7,CONCRETE:8)
Block(-5,41,8,CONCRETE:8)
Block(-5,42,-7,CONCRETE:7)
Block(-5,42,-6,CONCRETE:7)
Block(-5,42,-5,CONCRETE:7)
Block(-5,42,-4,CONCRETE:7)
Block(-5,42,-3,STAINED_GLASS:15)
Block(-5,42,-2,STAINED_GLASS:15)
Block(-5,42,-1,STAINED_GLASS:15)
Block(-5,42,0,STAINED_GLASS:15)
Block(-5,42,1,STAINED_GLASS:15)
Block(-5,42,2,STAINED_GLASS:15)
Block(-5,42,3,STAINED_GLASS:15)
Block(-5,42,4,STAINED_GLASS:15)
Block(-5,42,5,STAINED_GLASS:15)
Block(-5,42,6,STAINED_GLASS:15)
Block(-5,43,-7,CONCRETE:7)
Block(-5,43,-6,CONCRETE:7)
Block(-5,43,-5,CONCRETE:7)
Block(-5,43,-4,CONCRETE:7)
Block(-5,43,-3,STAINED_GLASS:15)
Block(-5,43,-2,STAINED_GLASS:15)
Block(-5,43,-1,STAINED_GLASS:15)
Block(-5,43,0,STAINED_GLASS:15)
Block(-5,43,1,STAINED_GLASS:15)
Block(-5,43,2,STAINED_GLASS:15)
Block(-5,43,3,STAINED_GLASS:15)
Block(-5,43,4,STAINED_GLASS:15)
Block(-5,43,5,STAINED_GLASS:15)
Block(-5,43,6,STAINED_GLASS:15)
Block(-5,44,-7,CONCRETE:7)
Block(-5,44,-6,CONCRETE:7)
Block(-5,44,-5,CONCRETE:7)
Block(-5,44,-4,CONCRETE:7)
Block(-5,44,-3,STAINED_GLASS:15)
Block(-5,44,-2,STAINED_GLASS:15)
Block(-5,44,-1,STAINED_GLASS:15)
Block(-5,44,0,STAINED_GLASS:15)
Block(-5,44,1,STAINED_GLASS:15)
Block(-5,44,2,STAINED_GLASS:15)
Block(-5,44,3,STAINED_GLASS:15)
Block(-5,44,4,STAINED_GLASS:15)
Block(-5,44,5,STAINED_GLASS:15)
Block(-5,44,6,STAINED_GLASS:15)
Block(-5,45,-7,CONCRETE:8)
Block(-5,45,-6,CONCRETE:8)
Block(-5,45,-5,CONCRETE:8)
Block(-5,45,-4,CONCRETE:8)
Block(-5,45,-3,CONCRETE:8)
Block(-5,45,-2,CONCRETE:8)
Block(-5,45,-1,CONCRETE:8)
Block(-5,45,0,CONCRETE:8)
Block(-5,45,1,CONCRETE:8)
Block(-5,45,2,CONCRETE:8)
Block(-5,45,3,CONCRETE:8)
Block(-5,45,4,CONCRETE:8)
Block(-5,45,5,CONCRETE:8)
Block(-5,45,6,CONCRETE:8)
Block(-5,45,7,CONCRETE:8)
Block(-5,45,8,CONCRETE:8)
Block(-5,46,-7,CONCRETE:7)
Block(-5,46,-6,CONCRETE:7)
Block(-5,46,-5,CONCRETE:7)
Block(-5,46,-4,CONCRETE:7)
Block(-5,46,-3,STAINED_GLASS:15)
Block(-5,46,-2,STAINED_GLASS:15)
Block(-5,46,-1,STAINED_GLASS:15)
Block(-5,46,0,STAINED_GLASS:15)
Block(-5,46,1,STAINED_GLASS:15)
Block(-5,46,2,STAINED_GLASS:15)
Block(-5,46,3,STAINED_GLASS:15)
Block(-5,46,4,STAINED_GLASS:15)
Block(-5,46,5,STAINED_GLASS:15)
Block(-5,46,6,STAINED_GLASS:15)
Block(-5,47,-7,CONCRETE:7)
Block(-5,47,-6,CONCRETE:7)
Block(-5,47,-5,CONCRETE:7)
Block(-5,47,-4,CONCRETE:7)
Block(-5,47,-3,STAINED_GLASS:15)
Block(-5,47,-2,STAINED_GLASS:15)
Block(-5,47,-1,STAINED_GLASS:15)
Block(-5,47,0,STAINED_GLASS:15)
Block(-5,47,1,STAINED_GLASS:15)
Block(-5,47,2,STAINED_GLASS:15)
Block(-5,47,3,STAINED_GLASS:15)
Block(-5,47,4,STAINED_GLASS:15)
Block(-5,47,5,STAINED_GLASS:15)
Block(-5,47,6,STAINED_GLASS:15)
Block(-5,48,-7,CONCRETE:7)
Block(-5,48,-6,CONCRETE:7)
Block(-5,48,-5,CONCRETE:7)
Block(-5,48,-4,CONCRETE:7)
Block(-5,48,-3,STAINED_GLASS:15)
Block(-5,48,-2,STAINED_GLASS:15)
Block(-5,48,-1,STAINED_GLASS:15)
Block(-5,48,0,STAINED_GLASS:15)
Block(-5,48,1,STAINED_GLASS:15)
Block(-5,48,2,STAINED_GLASS:15)
Block(-5,48,3,STAINED_GLASS:15)
Block(-5,48,4,STAINED_GLASS:15)
Block(-5,48,5,STAINED_GLASS:15)
Block(-5,48,6,STAINED_GLASS:15)
Block(-5,49,-7,CONCRETE:8)
Block(-5,49,-6,CONCRETE:8)
Block(-5,49,-5,CONCRETE:8)
Block(-5,49,-4,CONCRETE:8)
Block(-5,49,-3,CONCRETE:8)
Block(-5,49,-2,CONCRETE:8)
Block(-5,49,-1,CONCRETE:8)
Block(-5,49,0,CONCRETE:8)
Block(-5,49,1,CONCRETE:8)
