
#######################################################################
# +-----------------------------------------------------------------+ #
# |                            BO4 object                           | #
# +-----------------------------------------------------------------+ #
#######################################################################

Author: NLBlackEagle

Description: No description given

SettingsMode: WriteDisable


#######################################################################
# +-----------------------------------------------------------------+ #
# |                          Main settings                          | #
# +-----------------------------------------------------------------+ #
#######################################################################

Frequency: 0

SpawnHeight: highestBlock

UseCenterForHighestBlock: true

##############################
# Height Limits for the BO4. #
##############################

MinHeight: 0

MaxHeight: 255

InheritBO3: 

InheritBO3Rotation: NORTH

OverrideChildSettings: true

OverrideParentHeight: false

CanOverride: true

BranchFrequency: 0

BranchFrequencyGroup: 

MustBeBelowOther: false

MustBeInside: 

CannotBeInside: 

ReplacesBO3: L4-M-CrossC0R0, L4-M-CrossC0R1, L4-M-CrossC0R2, L4-M-CrossC0R3, L4-M-CrossC1R0, L4-M-CrossC1R1, L4-M-CrossC1R2, L4-M-CrossC1R3, L4-M-CrossC2R0, L4-M-CrossC2R1, L4-M-CrossC2R2, L4-M-CrossC2R3, L4-M-CrossC3R0, L4-M-CrossC3R1, L4-M-CrossC3R2, L4-M-CrossC3R3, L4-M-Straigth-START_01-C0R0, L4-M-Straigth-START_01-C0R1, L4-M-Straigth-START_01-C1R0, L4-M-Straigth-START_01-C1R1, L4-M-Straigth-START_01-C2R0, L4-M-Straigth-START_01-C2R1, L4-M-Straigth-START_01-C3R0, L4-M-Straigth-START_01-C3R1, L4-M-Straigth-3CC0R0, L4-M-Straigth-3CC0R1, L4-M-Straigth-3CC0R2, L4-M-Straigth-3CC1R0, L4-M-Straigth-3CC1R1, L4-M-Straigth-3CC1R2, L4-M-Straigth-3CC2R0, L4-M-Straigth-3CC2R1, L4-M-Straigth-3CC2R2, L4-M-Straigth-3CC3R0, L4-M-Straigth-3CC3R1, L4-M-Straigth-3CC3R2, L4-M-Cross, skyscraper_2x2_01, skyscraper_2x2_02, skyscraper_2x2_03, skyscraper_2x2_04, skyscraper_2x2_05, skyscraper_3x3_01, skyscraper_3x3_02, skyscraper_3x3_03, L3-M-Straigth-2CC0R0, L3-M-Straigth-2CC0R1, L3-M-Straigth-2CC1R0, L3-M-Straigth-2CC1R1, L3-M-Straigth-2CC2R0, L3-M-Straigth-2CC2R1, L3-M-Straigth-2CC3R0, L3-M-Straigth-2CC3R1, L3-M-Straigth-3CC0R0, L3-M-Straigth-3CC0R1, L3-M-Straigth-3CC0R2, L3-M-Straigth-3CC1R0, L3-M-Straigth-3CC1R1, L3-M-Straigth-3CC1R2, L3-M-Straigth-3CC2R0, L3-M-Straigth-3CC2R1, L3-M-Straigth-3CC2R2, L3-M-Straigth-3CC3R0, L3-M-Straigth-3CC3R1, L3-M-Straigth-3CC3R2L4-M-CrossC0R0, L4-M-CrossC0R1, L4-M-CrossC0R2, L4-M-CrossC0R3, L4-M-CrossC1R0, L4-M-CrossC1R1, L4-M-CrossC1R2, L4-M-CrossC1R3, L4-M-CrossC2R0, L4-M-CrossC2R1, L4-M-CrossC2R2, L4-M-CrossC2R3, L4-M-CrossC3R0, L4-M-CrossC3R1, L4-M-CrossC3R2, L4-M-CrossC3R3, L4-M-Straigth-START_01-C0R0, L4-M-Straigth-START_01-C0R1, L4-M-Straigth-START_01-C1R0, L4-M-Straigth-START_01-C1R1, L4-M-Straigth-START_01-C2R0, L4-M-Straigth-START_01-C2R1, L4-M-Straigth-START_01-C3R0, L4-M-Straigth-START_01-C3R1, L4-M-Straigth-3CC0R0, L4-M-Straigth-3CC0R1, L4-M-Straigth-3CC0R2, L4-M-Straigth-3CC1R0, L4-M-Straigth-3CC1R1, L4-M-Straigth-3CC1R2, L4-M-Straigth-3CC2R0, L4-M-Straigth-3CC2R1, L4-M-Straigth-3

MustBeInsideWorldBorders: false

CanSpawnOnWater: true

SpawnOnWaterOnly: false

SpawnUnderWater: false

SpawnAtWaterLevel: false

HeightOffset: 0

RemoveAir: false

ReplaceAbove: 

ReplaceBelow: 

ReplaceWithBiomeBlocks: true

ReplaceWithSurfaceBlock: GRASS

ReplaceWithGroundBlock: DIRT

ReplaceWithStoneBlock: STONE

SmoothRadius: 0

SmoothHeightOffset: 0

SmoothStartTop: false

SmoothStartWood: false

SmoothingSurfaceBlock: 

SmoothingGroundBlock: 

BO3Group: 

IsSpawnPoint: false

DoReplaceBlocks: true


#######################################################################
# +-----------------------------------------------------------------+ #
# |                              Blocks                             | #
# +-----------------------------------------------------------------+ #
#######################################################################

Block(-8,0,-7,CONCRETE:7)
Block(-8,0,-6,CONCRETE:7)
Block(-8,0,-5,CONCRETE:7)
Block(-8,0,-4,CONCRETE:7)
Block(-8,0,-3,CONCRETE:7)
Block(-8,0,-2,CONCRETE:7)
Block(-8,0,-1,CONCRETE:7)
Block(-8,0,0,CONCRETE:7)
Block(-8,0,1,CONCRETE:7)
Block(-8,0,2,CONCRETE:7)
Block(-8,0,3,CONCRETE:7)
Block(-8,0,4,CONCRETE:7)
Block(-8,0,5,CONCRETE:7)
Block(-8,0,6,CONCRETE:7)
Block(-8,0,7,CONCRETE:7)
Block(-8,0,8,CONCRETE:7)
Block(-8,1,-7,CONCRETE:7)
Block(-8,1,-6,CONCRETE:7)
Block(-8,1,-5,CONCRETE:7)
Block(-8,1,-4,CONCRETE:7)
Block(-8,1,-3,CONCRETE:7)
Block(-8,1,-2,STATIONARY_WATER:0)
Block(-8,1,-1,STATIONARY_WATER:0)
Block(-8,1,0,STATIONARY_WATER:0)
Block(-8,1,1,STATIONARY_WATER:0)
Block(-8,1,2,CONCRETE:7)
Block(-8,1,3,CONCRETE:7)
Block(-8,1,4,CONCRETE:7)
Block(-8,1,5,CONCRETE:7)
Block(-8,1,6,CONCRETE:7)
Block(-8,1,7,AIR:0)
Block(-8,1,8,CONCRETE:7)
Block(-8,2,-7,CONCRETE:7)
Block(-8,2,-6,CONCRETE:7)
Block(-8,2,-5,CONCRETE:7)
Block(-8,2,-4,CONCRETE:7)
Block(-8,2,-3,SMOOTH_STAIRS:3)
Block(-8,2,-2,AIR:0)
Block(-8,2,-1,AIR:0)
Block(-8,2,0,AIR:0)
Block(-8,2,1,AIR:0)
Block(-8,2,2,SMOOTH_STAIRS:2)
Block(-8,2,3,CONCRETE:7)
Block(-8,2,4,CONCRETE:7)
Block(-8,2,5,CONCRETE:7)
Block(-8,2,6,CONCRETE:7)
Block(-8,2,7,IRON_TRAPDOOR:8)
Block(-8,2,8,CONCRETE:7)
Block(-8,3,-7,AIR:0)
Block(-8,3,-6,AIR:0)
Block(-8,3,-5,CONCRETE:7)
Block(-8,3,-4,CONCRETE:7)
Block(-8,3,-3,AIR:0)
Block(-8,3,-2,AIR:0)
Block(-8,3,-1,AIR:0)
Block(-8,3,0,AIR:0)
Block(-8,3,1,AIR:0)
Block(-8,3,2,AIR:0)
Block(-8,3,3,AIR:0)
Block(-8,3,4,CONCRETE:7)
Block(-8,3,5,CONCRETE:7)
Block(-8,3,6,AIR:0)
Block(-8,3,7,AIR:0)
Block(-8,3,8,CONCRETE:7)
Block(-8,4,-7,AIR:0)
Block(-8,4,-6,AIR:0)
Block(-8,4,-5,CONCRETE:7)
Block(-8,4,-4,CONCRETE:7)
Block(-8,4,-3,AIR:0)
Block(-8,4,-2,AIR:0)
Block(-8,4,-1,AIR:0)
Block(-8,4,0,AIR:0)
Block(-8,4,1,AIR:0)
Block(-8,4,2,AIR:0)
Block(-8,4,3,AIR:0)
Block(-8,4,4,CONCRETE:7)
Block(-8,4,5,CONCRETE:7)
Block(-8,4,6,AIR:0)
Block(-8,4,7,AIR:0)
Block(-8,4,8,CONCRETE:7)
Block(-8,5,-7,CONCRETE:14)
Block(-8,5,-6,CONCRETE:11)
Block(-8,5,-5,CONCRETE:7)
Block(-8,5,-4,CONCRETE:7)
Block(-8,5,-3,AIR:0)
Block(-8,5,-2,AIR:0)
Block(-8,5,-1,AIR:0)
Block(-8,5,0,AIR:0)
Block(-8,5,1,AIR:0)
Block(-8,5,2,AIR:0)
Block(-8,5,3,AIR:0)
Block(-8,5,4,CONCRETE:7)
Block(-8,5,5,CONCRETE:7)
Block(-8,5,6,AIR:0)
Block(-8,5,7,AIR:0)
Block(-8,5,8,CONCRETE:7)
Block(-8,6,-7,IRON_FENCE:0)
Block(-8,6,-6,AIR:0)
Block(-8,6,-5,CONCRETE:7)
Block(-8,6,-4,CONCRETE:7)
Block(-8,6,-3,AIR:0)
Block(-8,6,-2,AIR:0)
Block(-8,6,-1,AIR:0)
Block(-8,6,0,AIR:0)
Block(-8,6,1,AIR:0)
Block(-8,6,2,AIR:0)
Block(-8,6,3,AIR:0)
Block(-8,6,4,CONCRETE:7)
Block(-8,6,5,CONCRETE:7)
Block(-8,6,6,AIR:0)
Block(-8,6,7,AIR:0)
Block(-8,6,8,CONCRETE:7)
Block(-8,7,-7,CONCRETE:7)
Block(-8,7,-6,CONCRETE:7)
Block(-8,7,-5,CONCRETE:7)
Block(-8,7,-4,CONCRETE:7)
Block(-8,7,-3,CONCRETE:7)
Block(-8,7,-2,CONCRETE:7)
Block(-8,7,-1,CONCRETE:7)
Block(-8,7,0,CONCRETE:7)
Block(-8,7,1,CONCRETE:7)
Block(-8,7,2,DROPPER:1,NBT/skyscraper_2x2_04/302-dropperC16R16.nbt)
Block(-8,7,3,CONCRETE:7)
Block(-8,7,4,CONCRETE:7)
Block(-8,7,5,CONCRETE:7)
Block(-8,7,6,CONCRETE:7)
Block(-8,7,7,CONCRETE:7)
Block(-8,7,8,CONCRETE:7)
Block(-8,8,-7,STEP:0)
Block(-8,8,-6,STEP:0)
Block(-8,8,-5,STEP:0)
Block(-8,8,-4,STEP:0)
Block(-8,8,-3,STEP:0)
Block(-8,8,-2,STEP:0)
Block(-8,8,-1,STEP:0)
Block(-8,8,0,STEP:0)
Block(-8,8,1,STEP:0)
Block(-8,8,2,IRON_TRAPDOOR:0)
Block(-8,8,3,CONCRETE:7)
Block(-8,8,4,CONCRETE:7)
Block(-8,8,5,CONCRETE:7)
Block(-8,8,6,CONCRETE:7)
Block(-8,8,7,CONCRETE:7)
Block(-8,8,8,CONCRETE:7)
Block(-8,9,-7,IRON_TRAPDOOR:10)
Block(-8,9,-6,IRON_TRAPDOOR:10)
Block(-8,9,-5,IRON_TRAPDOOR:10)
Block(-8,9,-4,AIR:0)
Block(-8,9,-3,AIR:0)
Block(-8,9,-2,AIR:0)
Block(-8,9,-1,AIR:0)
Block(-8,9,0,IRON_FENCE:0)
Block(-8,9,1,AIR:0)
Block(-8,9,2,AIR:0)
Block(-8,9,3,CONCRETE:7)
Block(-8,9,4,CONCRETE:7)
Block(-8,9,5,CONCRETE:7)
Block(-8,9,6,CONCRETE:7)
Block(-8,9,7,CONCRETE:7)
Block(-8,9,8,CONCRETE:7)
Block(-8,10,-7,AIR:0)
Block(-8,10,-6,AIR:0)
Block(-8,10,-5,IRON_FENCE:0)
Block(-8,10,-4,AIR:0)
Block(-8,10,-3,AIR:0)
Block(-8,10,-2,AIR:0)
Block(-8,10,-1,AIR:0)
Block(-8,10,0,IRON_FENCE:0)
Block(-8,10,1,AIR:0)
Block(-8,10,2,AIR:0)
Block(-8,10,3,CONCRETE:7)
Block(-8,10,4,CONCRETE:7)
Block(-8,10,5,CONCRETE:7)
Block(-8,10,6,CONCRETE:7)
Block(-8,10,7,CONCRETE:7)
Block(-8,10,8,CONCRETE:7)
Block(-8,11,-7,AIR:0)
Block(-8,11,-6,AIR:0)
Block(-8,11,-5,AIR:0)
Block(-8,11,-4,AIR:0)
Block(-8,11,-3,AIR:0)
Block(-8,11,-2,AIR:0)
Block(-8,11,-1,AIR:0)
Block(-8,11,0,CONCRETE:7)
Block(-8,11,1,CONCRETE:7)
Block(-8,11,2,CONCRETE:7)
Block(-8,11,3,CONCRETE:7)
Block(-8,11,4,CONCRETE:7)
Block(-8,11,5,CONCRETE:7)
Block(-8,11,6,CONCRETE:7)
Block(-8,11,7,CONCRETE:7)
Block(-8,11,8,CONCRETE:7)
Block(-8,12,-7,AIR:0)
Block(-8,12,-6,AIR:0)
Block(-8,12,-5,AIR:0)
Block(-8,12,-4,AIR:0)
Block(-8,12,-3,CONCRETE:4)
Block(-8,12,-2,AIR:0)
Block(-8,12,-1,AIR:0)
Block(-8,12,0,CONCRETE:7)
Block(-8,12,1,CONCRETE:7)
Block(-8,12,2,CONCRETE:7)
Block(-8,12,3,CONCRETE:7)
Block(-8,12,4,CONCRETE:7)
Block(-8,12,5,CONCRETE:7)
Block(-8,12,6,CONCRETE:7)
Block(-8,12,7,CONCRETE:7)
Block(-8,12,8,CONCRETE:7)
Block(-8,13,-7,AIR:0)
Block(-8,13,-6,AIR:0)
Block(-8,13,-5,AIR:0)
Block(-8,13,-4,AIR:0)
Block(-8,13,-3,AIR:0)
Block(-8,13,-2,AIR:0)
Block(-8,13,-1,AIR:0)
Block(-8,13,0,CONCRETE:7)
Block(-8,13,1,CONCRETE:7)
Block(-8,13,2,CONCRETE:7)
Block(-8,13,3,CONCRETE:7)
Block(-8,13,4,CONCRETE:7)
Block(-8,13,5,CONCRETE:7)
Block(-8,13,6,CONCRETE:7)
Block(-8,13,7,CONCRETE:7)
Block(-8,13,8,CONCRETE:7)
Block(-8,14,-7,AIR:0)
Block(-8,14,-6,STEP:8)
Block(-8,14,-5,AIR:0)
Block(-8,14,-4,STEP:8)
Block(-8,14,-3,AIR:0)
Block(-8,14,-2,STEP:8)
Block(-8,14,-1,AIR:0)
Block(-8,14,0,CONCRETE:7)
Block(-8,14,1,CONCRETE:7)
Block(-8,14,2,CONCRETE:7)
Block(-8,14,3,CONCRETE:7)
Block(-8,14,4,CONCRETE:7)
Block(-8,14,5,CONCRETE:7)
Block(-8,14,6,CONCRETE:7)
Block(-8,14,7,CONCRETE:7)
Block(-8,14,8,CONCRETE:7)
Block(-8,15,-7,AIR:0)
Block(-8,15,-6,CONCRETE:7)
Block(-8,15,-5,AIR:0)
Block(-8,15,-4,CONCRETE:7)
Block(-8,15,-3,AIR:0)
Block(-8,15,-2,CONCRETE:7)
Block(-8,15,-1,AIR:0)
Block(-8,15,0,CONCRETE:7)
Block(-8,15,1,CONCRETE:7)
Block(-8,15,2,CONCRETE:7)
Block(-8,15,3,CONCRETE:7)
Block(-8,15,4,CONCRETE:7)
Block(-8,15,5,CONCRETE:7)
Block(-8,15,6,CONCRETE:7)
Block(-8,15,7,CONCRETE:7)
Block(-8,15,8,CONCRETE:7)
Block(-8,16,-7,AIR:0)
Block(-8,16,-6,AIR:0)
Block(-8,16,-5,AIR:0)
Block(-8,16,-4,AIR:0)
Block(-8,16,-3,AIR:0)
Block(-8,16,-2,AIR:0)
Block(-8,16,-1,AIR:0)
Block(-8,16,0,CONCRETE:7)
Block(-8,16,1,CONCRETE:7)
Block(-8,16,2,CONCRETE:7)
Block(-8,16,3,CONCRETE:7)
Block(-8,16,4,CONCRETE:7)
Block(-8,16,5,CONCRETE:7)
Block(-8,16,6,CONCRETE:7)
Block(-8,16,7,CONCRETE:7)
Block(-8,16,8,CONCRETE:7)
Block(-8,17,-7,CONCRETE:7)
Block(-8,17,-6,CONCRETE:7)
Block(-8,17,-5,CONCRETE:7)
Block(-8,17,-4,CONCRETE:7)
Block(-8,17,-3,CONCRETE:7)
Block(-8,17,-2,CONCRETE:7)
Block(-8,17,-1,CONCRETE:7)
Block(-8,17,0,CONCRETE:7)
Block(-8,17,1,CONCRETE:7)
Block(-8,17,2,CONCRETE:7)
Block(-8,17,3,CONCRETE:7)
Block(-8,17,4,CONCRETE:7)
Block(-8,17,5,CONCRETE:7)
Block(-8,17,6,CONCRETE:7)
Block(-8,17,7,CONCRETE:7)
Block(-8,17,8,CONCRETE:7)
Block(-8,18,-7,CONCRETE:8)
Block(-8,18,-6,CONCRETE:8)
Block(-8,18,-5,CONCRETE:8)
Block(-8,18,-4,CONCRETE:8)
Block(-8,18,-3,CONCRETE:8)
Block(-8,18,-2,CONCRETE:15)
Block(-8,18,-1,CONCRETE:15)
Block(-8,18,0,CONCRETE:15)
Block(-8,18,1,CONCRETE:15)
Block(-8,18,2,CONCRETE:15)
Block(-8,18,3,CONCRETE:8)
Block(-8,18,4,CONCRETE:8)
Block(-8,18,5,CONCRETE:8)
Block(-8,18,6,CONCRETE:8)
Block(-8,18,7,CONCRETE:8)
Block(-8,18,8,CONCRETE:8)
Block(-8,19,1,QUARTZ_STAIRS:2)
Block(-8,19,2,OBSERVER:5)
Block(-8,19,3,QUARTZ_STAIRS:7)
Block(-8,19,6,IRON_TRAPDOOR:4)
Block(-8,19,7,CONCRETE:8)
Block(-8,20,2,IRON_TRAPDOOR:3)
Block(-8,20,3,STONE_BUTTON:5)
Block(-8,20,6,IRON_TRAPDOOR:12)
Block(-8,20,7,CONCRETE:8)
Block(-8,21,2,IRON_TRAPDOOR:9)
Block(-8,21,6,IRON_TRAPDOOR:12)
Block(-8,21,7,CONCRETE:8)
Block(-8,22,6,IRON_TRAPDOOR:4)
Block(-8,22,7,CONCRETE:8)
Block(-8,23,6,LEVER:12)
Block(-8,23,7,CONCRETE:8)
Block(-8,23,8,IRON_TRAPDOOR:5)
Block(-8,24,4,STEP:8)
Block(-8,24,6,STEP:8)
Block(-8,24,8,STAINED_GLASS:15)
Block(-8,25,8,STAINED_GLASS:15)
Block(-8,26,8,STAINED_GLASS:15)
Block(-8,27,2,CONCRETE:8)
Block(-8,27,3,CONCRETE:8)
Block(-8,27,4,CONCRETE:8)
Block(-8,27,5,CONCRETE:8)
Block(-8,27,6,CONCRETE:8)
Block(-8,27,7,CONCRETE:8)
Block(-8,27,8,STAINED_GLASS:15)
Block(-8,28,2,STAINED_GLASS_PANE:15)
Block(-8,28,4,STAINED_GLASS:15)
Block(-8,28,5,IRON_TRAPDOOR:9)
Block(-8,28,6,CONCRETE:0)
Block(-8,28,7,IRON_TRAPDOOR:10)
Block(-8,28,8,STAINED_GLASS:15)
Block(-8,29,4,STAINED_GLASS:15)
Block(-8,29,5,CONCRETE:15)
Block(-8,29,6,CONCRETE:15)
Block(-8,29,8,STAINED_GLASS:15)
Block(-8,30,4,STAINED_GLASS:15)
Block(-8,30,5,CONCRETE:15)
Block(-8,30,6,CONCRETE:15)
Block(-8,30,7,WALL_BANNER:3,NBT/skyscraper_2x2_04/321-bannerC16R16.nbt)
Block(-8,30,8,STAINED_GLASS:15)
Block(-8,31,4,STAINED_GLASS:15)
Block(-8,31,5,CONCRETE:15)
Block(-8,31,6,REDSTONE_LAMP_OFF:0)
Block(-8,31,8,STAINED_GLASS:15)
Block(-8,32,4,STAINED_GLASS:15)
Block(-8,32,5,IRON_TRAPDOOR:1)
Block(-8,32,6,IRON_TRAPDOOR:1)
Block(-8,32,8,STAINED_GLASS:15)
Block(-8,33,4,STAINED_GLASS:15)
Block(-8,33,8,STAINED_GLASS:15)
Block(-8,34,4,STAINED_GLASS:15)
Block(-8,34,6,CONCRETE:0)
Block(-8,34,8,STAINED_GLASS:15)
Block(-8,35,2,CONCRETE:8)
Block(-8,35,3,CONCRETE:8)
Block(-8,35,4,CONCRETE:8)
Block(-8,35,5,CONCRETE:8)
Block(-8,35,6,CONCRETE:8)
Block(-8,35,7,CONCRETE:8)
Block(-8,35,8,STAINED_GLASS:15)
Block(-8,36,2,STAINED_GLASS_PANE:15)
Block(-8,36,4,STAINED_GLASS:15)
Block(-8,36,5,IRON_TRAPDOOR:9)
Block(-8,36,6,CONCRETE:0)
Block(-8,36,7,IRON_TRAPDOOR:10)
Block(-8,36,8,STAINED_GLASS:15)
Block(-8,37,4,STAINED_GLASS:15)
Block(-8,37,5,CONCRETE:15)
Block(-8,37,6,CONCRETE:15)
Block(-8,37,8,STAINED_GLASS:15)
Block(-8,38,4,STAINED_GLASS:15)
Block(-8,38,5,CONCRETE:15)
Block(-8,38,6,CONCRETE:15)
Block(-8,38,7,WALL_BANNER:3,NBT/skyscraper_2x2_04/322-bannerC16R16.nbt)
Block(-8,38,8,STAINED_GLASS:15)
Block(-8,39,4,STAINED_GLASS:15)
Block(-8,39,5,CONCRETE:15)
Block(-8,39,6,REDSTONE_LAMP_OFF:0)
Block(-8,39,8,STAINED_GLASS:15)
Block(-8,40,4,STAINED_GLASS:15)
Block(-8,40,5,IRON_TRAPDOOR:1)
Block(-8,40,6,IRON_TRAPDOOR:1)
Block(-8,40,8,STAINED_GLASS:15)
Block(-8,41,4,STAINED_GLASS:15)
Block(-8,41,8,STAINED_GLASS:15)
Block(-8,42,4,STAINED_GLASS:15)
Block(-8,42,6,CONCRETE:0)
Block(-8,42,8,STAINED_GLASS:15)
Block(-8,43,2,CONCRETE:8)
Block(-8,43,3,CONCRETE:8)
Block(-8,43,4,CONCRETE:8)
Block(-8,43,5,CONCRETE:8)
Block(-8,43,6,CONCRETE:8)
Block(-8,43,7,CONCRETE:8)
Block(-8,43,8,STAINED_GLASS:15)
Block(-8,44,2,STAINED_GLASS_PANE:15)
Block(-8,44,4,STAINED_GLASS:15)
Block(-8,44,5,IRON_TRAPDOOR:9)
Block(-8,44,6,CONCRETE:0)
Block(-8,44,7,IRON_TRAPDOOR:10)
Block(-8,44,8,STAINED_GLASS:15)
Block(-8,45,4,STAINED_GLASS:15)
Block(-8,45,5,CONCRETE:15)
Block(-8,45,6,CONCRETE:15)
Block(-8,45,8,STAINED_GLASS:15)
Block(-8,46,4,STAINED_GLASS:15)
Block(-8,46,5,CONCRETE:15)
Block(-8,46,6,CONCRETE:15)
Block(-8,46,7,WALL_BANNER:3,NBT/skyscraper_2x2_04/323-bannerC16R16.nbt)
Block(-8,46,8,STAINED_GLASS:15)
Block(-8,47,4,STAINED_GLASS:15)
Block(-8,47,5,CONCRETE:15)
Block(-8,47,6,REDSTONE_LAMP_OFF:0)
Block(-8,47,8,STAINED_GLASS:15)
Block(-8,48,4,STAINED_GLASS:15)
Block(-8,48,5,IRON_TRAPDOOR:1)
Block(-8,48,6,IRON_TRAPDOOR:1)
Block(-8,48,8,STAINED_GLASS:15)
Block(-8,49,4,STAINED_GLASS:15)
Block(-8,49,8,STAINED_GLASS:15)
Block(-8,50,4,STAINED_GLASS:15)
Block(-8,50,6,CONCRETE:0)
Block(-8,50,8,STAINED_GLASS:15)
Block(-8,51,2,CONCRETE:8)
Block(-8,51,3,CONCRETE:8)
Block(-8,51,4,CONCRETE:8)
Block(-8,51,5,CONCRETE:8)
Block(-8,51,6,CONCRETE:8)
Block(-8,51,7,CONCRETE:8)
Block(-8,51,8,STAINED_GLASS:15)
Block(-8,52,2,STAINED_GLASS_PANE:15)
Block(-8,52,4,STAINED_GLASS:15)
Block(-8,52,5,IRON_TRAPDOOR:9)
Block(-8,52,6,CONCRETE:0)
Block(-8,52,7,IRON_TRAPDOOR:10)
Block(-8,52,8,STAINED_GLASS:15)
Block(-8,53,4,STAINED_GLASS:15)
Block(-8,53,5,CONCRETE:15)
Block(-8,53,6,CONCRETE:15)
Block(-8,53,8,STAINED_GLASS:15)
Block(-8,54,4,STAINED_GLASS:15)
Block(-8,54,5,CONCRETE:15)
Block(-8,54,6,CONCRETE:15)
Block(-8,54,7,WALL_BANNER:3,NBT/skyscraper_2x2_04/324-bannerC16R16.nbt)
Block(-8,54,8,STAINED_GLASS:15)
Block(-8,55,4,STAINED_GLASS:15)
Block(-8,55,5,CONCRETE:15)
Block(-8,55,6,REDSTONE_LAMP_OFF:0)
Block(-8,55,8,STAINED_GLASS:15)
Block(-8,56,4,STAINED_GLASS:15)
Block(-8,56,5,IRON_TRAPDOOR:1)
Block(-8,56,6,IRON_TRAPDOOR:1)
Block(-8,56,8,STAINED_GLASS:15)
Block(-8,57,4,STAINED_GLASS:15)
Block(-8,57,8,STAINED_GLASS:15)
Block(-8,58,4,STAINED_GLASS:15)
Block(-8,58,6,CONCRETE:0)
Block(-8,58,8,STAINED_GLASS:15)
Block(-8,59,2,CONCRETE:8)
Block(-8,59,3,CONCRETE:8)
Block(-8,59,4,CONCRETE:8)
Block(-8,59,5,CONCRETE:8)
Block(-8,59,6,CONCRETE:8)
Block(-8,59,7,CONCRETE:8)
Block(-8,59,8,STAINED_GLASS:15)
Block(-8,60,2,STAINED_GLASS_PANE:15)
Block(-8,60,4,STAINED_GLASS:15)
Block(-8,60,5,IRON_TRAPDOOR:9)
Block(-8,60,6,CONCRETE:0)
Block(-8,60,7,IRON_TRAPDOOR:10)
Block(-8,60,8,STAINED_GLASS:15)
Block(-8,61,4,STAINED_GLASS:15)
Block(-8,61,5,CONCRETE:15)
Block(-8,61,6,CONCRETE:15)
Block(-8,61,8,STAINED_GLASS:15)
Block(-8,62,4,STAINED_GLASS:15)
Block(-8,62,5,CONCRETE:15)
Block(-8,62,6,CONCRETE:15)
Block(-8,62,7,WALL_BANNER:3,NBT/skyscraper_2x2_04/325-bannerC16R16.nbt)
Block(-8,62,8,STAINED_GLASS:15)
Block(-8,63,4,STAINED_GLASS:15)
Block(-8,63,5,CONCRETE:15)
Block(-8,63,6,REDSTONE_LAMP_OFF:0)
Block(-8,63,8,STAINED_GLASS:15)
Block(-8,64,4,STAINED_GLASS:15)
Block(-8,64,5,IRON_TRAPDOOR:1)
Block(-8,64,6,IRON_TRAPDOOR:1)
Block(-8,64,8,STAINED_GLASS:15)
Block(-8,65,4,STAINED_GLASS:15)
Block(-8,65,8,STAINED_GLASS:15)
Block(-8,66,4,STAINED_GLASS:15)
Block(-8,66,6,CONCRETE:0)
Block(-8,66,8,STAINED_GLASS:15)
Block(-8,67,2,CONCRETE:8)
Block(-8,67,3,CONCRETE:8)
Block(-8,67,4,CONCRETE:8)
Block(-8,67,5,CONCRETE:8)
Block(-8,67,6,CONCRETE:8)
Block(-8,67,7,CONCRETE:8)
Block(-8,67,8,STAINED_GLASS:15)
Block(-8,68,2,STAINED_GLASS_PANE:15)
Block(-8,68,4,STAINED_GLASS:15)
Block(-8,68,5,IRON_TRAPDOOR:9)
Block(-8,68,6,CONCRETE:0)
Block(-8,68,7,IRON_TRAPDOOR:10)
Block(-8,68,8,STAINED_GLASS:15)
Block(-8,69,4,STAINED_GLASS:15)
Block(-8,69,5,CONCRETE:15)
Block(-8,69,6,CONCRETE:15)
Block(-8,69,8,STAINED_GLASS:15)
Block(-8,70,4,STAINED_GLASS:15)
Block(-8,70,5,CONCRETE:15)
Block(-8,70,6,CONCRETE:15)
Block(-8,70,7,WALL_BANNER:3,NBT/skyscraper_2x2_04/326-bannerC16R16.nbt)
Block(-8,70,8,STAINED_GLASS:15)
Block(-8,71,4,STAINED_GLASS:15)
Block(-8,71,5,CONCRETE:15)
Block(-8,71,6,REDSTONE_LAMP_OFF:0)
Block(-8,71,8,STAINED_GLASS:15)
Block(-8,72,4,STAINED_GLASS:15)
Block(-8,72,5,IRON_TRAPDOOR:1)
Block(-8,72,6,IRON_TRAPDOOR:1)
Block(-8,72,8,STAINED_GLASS:15)
Block(-8,73,4,STAINED_GLASS:15)
Block(-8,73,8,STAINED_GLASS:15)
Block(-8,74,4,STAINED_GLASS:15)
Block(-8,74,6,CONCRETE:0)
Block(-8,74,8,STAINED_GLASS:15)
Block(-8,75,0,CONCRETE:8)
Block(-8,75,1,CONCRETE:8)
Block(-8,75,2,CONCRETE:8)
Block(-8,75,3,CONCRETE:8)
Block(-8,75,4,CONCRETE:8)
Block(-8,75,5,CONCRETE:8)
Block(-8,75,6,CONCRETE:8)
Block(-8,75,7,CONCRETE:8)
Block(-8,75,8,STAINED_GLASS:15)
Block(-8,76,0,STAINED_GLASS_PANE:15)
Block(-8,76,2,CONCRETE:8)
Block(-8,76,8,CONCRETE:8)
Block(-8,77,2,CONCRETE:8)
Block(-8,77,3,CONCRETE:8)
Block(-8,77,4,CONCRETE:8)
Block(-8,77,5,CONCRETE:8)
Block(-8,77,6,CONCRETE:8)
Block(-8,77,7,CONCRETE:8)
Block(-8,77,8,CONCRETE:8)
Block(-8,78,2,CONCRETE:8)
Block(-8,78,3,CONCRETE:8)
Block(-8,78,4,CONCRETE:8)
Block(-8,78,5,CONCRETE:8)
Block(-8,78,6,CONCRETE:8)
Block(-8,78,7,CONCRETE:8)
Block(-8,78,8,CONCRETE:8)
Block(-8,79,2,STAINED_GLASS:15)
Block(-8,80,2,STAINED_GLASS:15)
Block(-8,81,2,STAINED_GLASS:15)
Block(-8,82,2,STAINED_GLASS:15)
Block(-8,83,0,CONCRETE:8)
Block(-8,83,1,CONCRETE:8)
Block(-8,83,2,STAINED_GLASS:15)
Block(-8,84,0,STAINED_GLASS_PANE:15)
Block(-8,84,2,STAINED_GLASS:15)
Block(-8,85,2,STAINED_GLASS:15)
Block(-8,86,2,STAINED_GLASS:15)
Block(-8,87,2,STAINED_GLASS:15)
Block(-8,88,2,STAINED_GLASS:15)
Block(-8,89,2,STAINED_GLASS:15)
Block(-8,90,2,STAINED_GLASS:15)
Block(-8,91,0,CONCRETE:8)
Block(-8,91,1,CONCRETE:8)
Block(-8,91,2,STAINED_GLASS:15)
Block(-8,92,0,STAINED_GLASS_PANE:15)
Block(-8,92,2,STAINED_GLASS:15)
Block(-8,93,2,STAINED_GLASS:15)
Block(-8,94,2,STAINED_GLASS:15)
Block(-8,95,2,STAINED_GLASS:15)
Block(-8,96,2,STAINED_GLASS:15)
Block(-8,97,-2,CONCRETE:15)
Block(-8,97,2,CONCRETE:15)
Block(-8,98,-2,CONCRETE:15)
Block(-8,98,-1,CONCRETE:15)
Block(-8,98,0,CONCRETE:15)
Block(-8,98,1,CONCRETE:15)
Block(-8,98,2,CONCRETE:15)
Block(-8,99,-4,CONCRETE:8)
Block(-8,99,-3,CONCRETE:8)
Block(-8,99,-2,CONCRETE:15)
Block(-8,99,-1,CONCRETE:15)
Block(-8,99,0,CONCRETE:15)
Block(-8,99,1,CONCRETE:15)
Block(-8,99,2,CONCRETE:15)
Block(-8,100,-4,STAINED_GLASS_PANE:15)
Block(-8,100,-2,STAINED_GLASS:15)
Block(-8,101,-2,STAINED_GLASS:15)
Block(-8,102,-2,STAINED_GLASS:15)
Block(-8,103,-2,STAINED_GLASS:15)
Block(-8,104,-2,STAINED_GLASS:15)
Block(-8,105,-2,STAINED_GLASS:15)
Block(-8,106,-2,STAINED_GLASS:15)
Block(-8,107,-4,CONCRETE:8)
Block(-8,107,-3,CONCRETE:8)
Block(-8,107,-2,STAINED_GLASS:15)
Block(-8,108,-4,STAINED_GLASS_PANE:15)
Block(-8,108,-2,STAINED_GLASS:15)
Block(-8,109,-2,STAINED_GLASS:15)
Block(-8,110,-2,STAINED_GLASS:15)
Block(-8,111,-2,STAINED_GLASS:15)
Block(-8,112,-2,STAINED_GLASS:15)
Block(-8,113,-2,STAINED_GLASS:15)
Block(-8,114,-2,STAINED_GLASS:15)
Block(-8,115,-4,CONCRETE:8)
Block(-8,115,-3,CONCRETE:8)
Block(-8,115,-2,STAINED_GLASS:15)
Block(-8,116,-4,STAINED_GLASS_PANE:15)
Block(-8,116,-2,STAINED_GLASS:15)
Block(-8,117,-2,STAINED_GLASS:15)
Block(-8,118,-2,STAINED_GLASS:15)
Block(-8,119,-2,STAINED_GLASS:15)
Block(-8,120,-3,TRIPWIRE:4)
Block(-8,120,-2,STAINED_GLASS:15)
Block(-8,121,-2,STAINED_GLASS:15)
Block(-8,122,-2,STAINED_GLASS:15)
Block(-8,123,-7,CONCRETE:8)
Block(-8,123,-6,CONCRETE:8)
Block(-8,123,-5,CONCRETE:8)
Block(-8,123,-4,CONCRETE:8)
Block(-8,123,-3,CONCRETE:8)
Block(-8,123,-2,STAINED_GLASS:15)
Block(-8,124,-7,STAINED_GLASS_PANE:15)
Block(-8,124,-6,STAINED_GLASS_PANE:15)
Block(-8,124,-5,STAINED_GLASS_PANE:15)
Block(-8,124,-4,IRON_TRAPDOOR:10)
Block(-8,124,-2,STAINED_GLASS:15)
Block(-8,125,-4,CONCRETE:14)
Block(-8,125,-2,STAINED_GLASS:15)
Block(-8,126,-2,STAINED_GLASS:15)
Block(-8,127,-2,STAINED_GLASS:15)
Block(-8,128,-2,STAINED_GLASS:15)
Block(-8,129,-2,STAINED_GLASS:15)
Block(-8,130,-2,STAINED_GLASS:15)
Block(-8,131,-2,STAINED_GLASS:15)
Block(-8,132,-2,CONCRETE:8)
Block(-8,133,-7,CONCRETE:8)
Block(-8,133,-6,CONCRETE:8)
Block(-8,133,-5,CONCRETE:8)
Block(-8,133,-4,CONCRETE:8)
Block(-8,133,-3,CONCRETE:8)
Block(-8,133,-2,CONCRETE:8)
Block(-8,134,-7,CONCRETE:8)
Block(-8,134,-6,CONCRETE:8)
Block(-8,134,-5,CONCRETE:8)
Block(-8,134,-4,CONCRETE:8)
Block(-8,134,-3,CONCRETE:8)
Block(-8,134,-2,CONCRETE:8)
Block(-7,0,-7,CONCRETE:7)
Block(-7,0,-6,CONCRETE:7)
Block(-7,0,-5,CONCRETE:7)
Block(-7,0,-4,CONCRETE:7)
Block(-7,0,-3,CONCRETE:7)
Block(-7,0,-2,CONCRETE:7)
Block(-7,0,-1,CONCRETE:7)
Block(-7,0,0,CONCRETE:7)
Block(-7,0,1,CONCRETE:7)
Block(-7,0,2,CONCRETE:7)
Block(-7,0,3,CONCRETE:7)
Block(-7,0,4,CONCRETE:7)
Block(-7,0,5,CONCRETE:7)
Block(-7,0,6,CONCRETE:7)
Block(-7,0,7,CONCRETE:7)
Block(-7,0,8,CONCRETE:7)
Block(-7,1,-7,CONCRETE:7)
Block(-7,1,-6,CONCRETE:7)
Block(-7,1,-5,CONCRETE:7)
Block(-7,1,-4,CONCRETE:7)
Block(-7,1,-3,CONCRETE:7)
Block(-7,1,-2,STATIONARY_WATER:0)
Block(-7,1,-1,STATIONARY_WATER:0)
Block(-7,1,0,STATIONARY_WATER:0)
Block(-7,1,1,STATIONARY_WATER:0)
Block(-7,1,2,CONCRETE:7)
Block(-7,1,3,CONCRETE:7)
Block(-7,1,4,CONCRETE:7)
Block(-7,1,5,SMOOTH_STAIRS:3)
Block(-7,1,6,AIR:0)
Block(-7,1,7,AIR:0)
Block(-7,1,8,CONCRETE:7)
Block(-7,2,-7,CONCRETE:7)
Block(-7,2,-6,CONCRETE:7)
Block(-7,2,-5,CONCRETE:7)
Block(-7,2,-4,CONCRETE:7)
Block(-7,2,-3,SMOOTH_STAIRS:3)
Block(-7,2,-2,AIR:0)
Block(-7,2,-1,AIR:0)
Block(-7,2,0,AIR:0)
Block(-7,2,1,AIR:0)
Block(-7,2,2,SMOOTH_STAIRS:2)
Block(-7,2,3,CONCRETE:7)
Block(-7,2,4,SMOOTH_STAIRS:3)
Block(-7,2,5,AIR:0)
Block(-7,2,6,AIR:0)
Block(-7,2,7,IRON_TRAPDOOR:8)
Block(-7,2,8,CONCRETE:7)
Block(-7,3,-7,AIR:0)
Block(-7,3,-6,AIR:0)
Block(-7,3,-5,CONCRETE:7)
Block(-7,3,-4,CONCRETE:7)
Block(-7,3,-3,AIR:0)
Block(-7,3,-2,AIR:0)
Block(-7,3,-1,AIR:0)
Block(-7,3,0,AIR:0)
Block(-7,3,1,AIR:0)
Block(-7,3,2,AIR:0)
Block(-7,3,3,AIR:0)
Block(-7,3,4,AIR:0)
Block(-7,3,5,AIR:0)
Block(-7,3,6,AIR:0)
Block(-7,3,7,AIR:0)
Block(-7,3,8,CONCRETE:7)
Block(-7,4,-7,AIR:0)
Block(-7,4,-6,AIR:0)
Block(-7,4,-5,CONCRETE:7)
Block(-7,4,-4,CONCRETE:7)
Block(-7,4,-3,AIR:0)
Block(-7,4,-2,AIR:0)
Block(-7,4,-1,AIR:0)
Block(-7,4,0,AIR:0)
Block(-7,4,1,AIR:0)
Block(-7,4,2,AIR:0)
Block(-7,4,3,AIR:0)
Block(-7,4,4,AIR:0)
Block(-7,4,5,AIR:0)
Block(-7,4,6,AIR:0)
Block(-7,4,7,AIR:0)
Block(-7,4,8,CONCRETE:7)
Block(-7,5,-7,CONCRETE:14)
Block(-7,5,-6,CONCRETE:11)
Block(-7,5,-5,CONCRETE:7)
Block(-7,5,-4,CONCRETE:7)
Block(-7,5,-3,AIR:0)
Block(-7,5,-2,AIR:0)
Block(-7,5,-1,AIR:0)
Block(-7,5,0,AIR:0)
Block(-7,5,1,AIR:0)
Block(-7,5,2,AIR:0)
Block(-7,5,3,AIR:0)
Block(-7,5,4,AIR:0)
Block(-7,5,5,AIR:0)
Block(-7,5,6,AIR:0)
Block(-7,5,7,AIR:0)
Block(-7,5,8,CONCRETE:7)
Block(-7,6,-7,AIR:0)
Block(-7,6,-6,AIR:0)
Block(-7,6,-5,CONCRETE:7)
Block(-7,6,-4,CONCRETE:7)
Block(-7,6,-3,AIR:0)
Block(-7,6,-2,AIR:0)
Block(-7,6,-1,AIR:0)
Block(-7,6,0,AIR:0)
Block(-7,6,1,AIR:0)
Block(-7,6,2,AIR:0)
Block(-7,6,3,AIR:0)
Block(-7,6,4,AIR:0)
Block(-7,6,5,AIR:0)
Block(-7,6,6,AIR:0)
Block(-7,6,7,AIR:0)
Block(-7,6,8,CONCRETE:7)
Block(-7,7,-7,CONCRETE:7)
Block(-7,7,-6,CONCRETE:7)
Block(-7,7,-5,CONCRETE:7)
Block(-7,7,-4,CONCRETE:7)
Block(-7,7,-3,CONCRETE:7)
Block(-7,7,-2,CONCRETE:7)
Block(-7,7,-1,CONCRETE:7)
Block(-7,7,0,CONCRETE:7)
Block(-7,7,1,CONCRETE:7)
Block(-7,7,2,DROPPER:1,NBT/skyscraper_2x2_04/327-dropperC16R16.nbt)
Block(-7,7,3,CONCRETE:7)
Block(-7,7,4,CONCRETE:7)
Block(-7,7,5,CONCRETE:7)
Block(-7,7,6,CONCRETE:7)
Block(-7,7,7,CONCRETE:7)
Block(-7,7,8,CONCRETE:7)
Block(-7,8,-7,STEP:0)
Block(-7,8,-6,STEP:0)
Block(-7,8,-5,STEP:0)
Block(-7,8,-4,STEP:0)
Block(-7,8,-3,STEP:0)
Block(-7,8,-2,STEP:0)
Block(-7,8,-1,STEP:0)
Block(-7,8,0,STEP:0)
Block(-7,8,1,STEP:0)
Block(-7,8,2,IRON_TRAPDOOR:0)
Block(-7,8,3,CONCRETE:7)
Block(-7,8,4,CONCRETE:7)
Block(-7,8,5,CONCRETE:7)
Block(-7,8,6,CONCRETE:7)
Block(-7,8,7,CONCRETE:7)
Block(-7,8,8,CONCRETE:7)
Block(-7,9,-7,IRON_TRAPDOOR:10)
Block(-7,9,-6,IRON_TRAPDOOR:10)
Block(-7,9,-5,IRON_TRAPDOOR:10)
Block(-7,9,-4,AIR:0)
Block(-7,9,-3,AIR:0)
Block(-7,9,-2,AIR:0)
Block(-7,9,-1,AIR:0)
Block(-7,9,0,IRON_FENCE:0)
Block(-7,9,1,AIR:0)
Block(-7,9,2,AIR:0)
Block(-7,9,3,CONCRETE:7)
Block(-7,9,4,CONCRETE:7)
Block(-7,9,5,CONCRETE:7)
Block(-7,9,6,CONCRETE:7)
Block(-7,9,7,CONCRETE:7)
Block(-7,9,8,CONCRETE:7)
Block(-7,10,-7,AIR:0)
Block(-7,10,-6,AIR:0)
Block(-7,10,-5,IRON_FENCE:0)
Block(-7,10,-4,AIR:0)
Block(-7,10,-3,AIR:0)
Block(-7,10,-2,AIR:0)
Block(-7,10,-1,AIR:0)
Block(-7,10,0,IRON_FENCE:0)
Block(-7,10,1,AIR:0)
Block(-7,10,2,AIR:0)
Block(-7,10,3,CONCRETE:7)
Block(-7,10,4,CONCRETE:7)
Block(-7,10,5,CONCRETE:7)
Block(-7,10,6,CONCRETE:7)
Block(-7,10,7,CONCRETE:7)
Block(-7,10,8,CONCRETE:7)
Block(-7,11,-7,AIR:0)
Block(-7,11,-6,AIR:0)
Block(-7,11,-5,AIR:0)
Block(-7,11,-4,AIR:0)
Block(-7,11,-3,AIR:0)
Block(-7,11,-2,AIR:0)
Block(-7,11,-1,AIR:0)
Block(-7,11,0,CONCRETE:7)
Block(-7,11,1,CONCRETE:7)
Block(-7,11,2,CONCRETE:7)
Block(-7,11,3,CONCRETE:7)
Block(-7,11,4,CONCRETE:7)
Block(-7,11,5,CONCRETE:7)
Block(-7,11,6,CONCRETE:7)
Block(-7,11,7,CONCRETE:7)
Block(-7,11,8,CONCRETE:7)
Block(-7,12,-7,AIR:0)
Block(-7,12,-6,AIR:0)
Block(-7,12,-5,AIR:0)
Block(-7,12,-4,AIR:0)
Block(-7,12,-3,CONCRETE:4)
Block(-7,12,-2,AIR:0)
Block(-7,12,-1,AIR:0)
Block(-7,12,0,CONCRETE:7)
Block(-7,12,1,CONCRETE:7)
Block(-7,12,2,CONCRETE:7)
Block(-7,12,3,CONCRETE:7)
Block(-7,12,4,CONCRETE:7)
Block(-7,12,5,CONCRETE:7)
Block(-7,12,6,CONCRETE:7)
Block(-7,12,7,CONCRETE:7)
Block(-7,12,8,CONCRETE:7)
Block(-7,13,-7,AIR:0)
Block(-7,13,-6,AIR:0)
Block(-7,13,-5,AIR:0)
Block(-7,13,-4,AIR:0)
Block(-7,13,-3,AIR:0)
Block(-7,13,-2,AIR:0)
Block(-7,13,-1,AIR:0)
Block(-7,13,0,CONCRETE:7)
Block(-7,13,1,CONCRETE:7)
Block(-7,13,2,CONCRETE:7)
Block(-7,13,3,CONCRETE:7)
Block(-7,13,4,CONCRETE:7)
Block(-7,13,5,CONCRETE:7)
Block(-7,13,6,CONCRETE:7)
Block(-7,13,7,CONCRETE:7)
Block(-7,13,8,CONCRETE:7)
Block(-7,14,-7,AIR:0)
Block(-7,14,-6,STEP:8)
Block(-7,14,-5,AIR:0)
Block(-7,14,-4,STEP:8)
Block(-7,14,-3,AIR:0)
Block(-7,14,-2,STEP:8)
Block(-7,14,-1,AIR:0)
Block(-7,14,0,CONCRETE:7)
Block(-7,14,1,CONCRETE:7)
Block(-7,14,2,CONCRETE:7)
Block(-7,14,3,CONCRETE:7)
Block(-7,14,4,CONCRETE:7)
Block(-7,14,5,CONCRETE:7)
Block(-7,14,6,CONCRETE:7)
Block(-7,14,7,CONCRETE:7)
Block(-7,14,8,CONCRETE:7)
Block(-7,15,-7,AIR:0)
Block(-7,15,-6,CONCRETE:7)
Block(-7,15,-5,AIR:0)
Block(-7,15,-4,CONCRETE:7)
Block(-7,15,-3,AIR:0)
Block(-7,15,-2,CONCRETE:7)
Block(-7,15,-1,AIR:0)
Block(-7,15,0,CONCRETE:7)
Block(-7,15,1,CONCRETE:7)
Block(-7,15,2,CONCRETE:7)
Block(-7,15,3,CONCRETE:7)
Block(-7,15,4,CONCRETE:7)
Block(-7,15,5,CONCRETE:7)
Block(-7,15,6,CONCRETE:7)
Block(-7,15,7,CONCRETE:7)
Block(-7,15,8,CONCRETE:7)
Block(-7,16,-7,AIR:0)
Block(-7,16,-6,AIR:0)
Block(-7,16,-5,AIR:0)
Block(-7,16,-4,AIR:0)
Block(-7,16,-3,AIR:0)
Block(-7,16,-2,AIR:0)
Block(-7,16,-1,AIR:0)
Block(-7,16,0,CONCRETE:7)
Block(-7,16,1,CONCRETE:7)
Block(-7,16,2,CONCRETE:7)
Block(-7,16,3,CONCRETE:7)
Block(-7,16,4,CONCRETE:7)
Block(-7,16,5,CONCRETE:7)
Block(-7,16,6,CONCRETE:7)
Block(-7,16,7,CONCRETE:7)
Block(-7,16,8,CONCRETE:7)
Block(-7,17,-7,CONCRETE:7)
Block(-7,17,-6,CONCRETE:7)
Block(-7,17,-5,CONCRETE:7)
Block(-7,17,-4,CONCRETE:7)
Block(-7,17,-3,CONCRETE:7)
Block(-7,17,-2,CONCRETE:7)
Block(-7,17,-1,CONCRETE:7)
Block(-7,17,0,CONCRETE:7)
Block(-7,17,1,CONCRETE:7)
Block(-7,17,2,CONCRETE:7)
Block(-7,17,3,CONCRETE:7)
Block(-7,17,4,CONCRETE:7)
Block(-7,17,5,CONCRETE:7)
Block(-7,17,6,CONCRETE:7)
Block(-7,17,7,CONCRETE:7)
Block(-7,17,8,CONCRETE:7)
Block(-7,18,-7,CONCRETE:8)
Block(-7,18,-6,CONCRETE:8)
Block(-7,18,-5,CONCRETE:8)
Block(-7,18,-4,CONCRETE:8)
Block(-7,18,-3,CONCRETE:8)
Block(-7,18,-2,CONCRETE:15)
Block(-7,18,-1,CONCRETE:15)
Block(-7,18,0,CONCRETE:15)
Block(-7,18,1,CONCRETE:15)
Block(-7,18,2,CONCRETE:15)
Block(-7,18,3,STONE:4)
Block(-7,18,4,CONCRETE:8)
Block(-7,18,5,CONCRETE:8)
Block(-7,18,6,CONCRETE:8)
Block(-7,18,7,CONCRETE:8)
Block(-7,18,8,CONCRETE:8)
Block(-7,19,-7,CONCRETE:8)
Block(-7,19,-2,CARPET:14)
Block(-7,19,-1,CARPET:14)
Block(-7,19,0,CARPET:14)
Block(-7,19,2,SPRUCE_FENCE_GATE:0)
Block(-7,19,6,LEVER:12)
Block(-7,19,7,CONCRETE:8)
Block(-7,19,8,IRON_TRAPDOOR:5)
Block(-7,20,-7,CONCRETE:8)
Block(-7,20,6,LEVER:12)
Block(-7,20,7,CONCRETE:8)
Block(-7,20,8,IRON_TRAPDOOR:5)
Block(-7,21,-7,CONCRETE:8)
Block(-7,21,2,IRON_TRAPDOOR:9)
Block(-7,21,6,LEVER:12)
Block(-7,21,7,CONCRETE:8)
Block(-7,21,8,IRON_TRAPDOOR:5)
Block(-7,22,-7,CONCRETE:8)
Block(-7,22,6,LEVER:12)
Block(-7,22,7,CONCRETE:8)
Block(-7,22,8,IRON_TRAPDOOR:5)
Block(-7,23,-7,CONCRETE:8)
Block(-7,23,6,LEVER:12)
Block(-7,23,7,CONCRETE:8)
Block(-7,23,8,IRON_TRAPDOOR:5)
Block(-7,24,-7,CONCRETE:8)
Block(-7,24,4,STEP:8)
Block(-7,24,5,PRISMARINE:0)
Block(-7,24,6,STEP:8)
Block(-7,24,8,STAINED_GLASS:15)
Block(-7,25,-7,CONCRETE:8)
Block(-7,25,4,IRON_FENCE:0)
Block(-7,25,6,IRON_FENCE:0)
Block(-7,25,8,STAINED_GLASS:15)
Block(-7,26,-7,CONCRETE:8)
Block(-7,26,2,SMOOTH_STAIRS:4)
Block(-7,26,4,IRON_FENCE:0)
Block(-7,26,6,IRON_FENCE:0)
Block(-7,26,8,STAINED_GLASS:15)
Block(-7,27,-7,CONCRETE:8)
Block(-7,27,2,CONCRETE:8)
Block(-7,27,3,CONCRETE:8)
Block(-7,27,4,CONCRETE:8)
Block(-7,27,5,CONCRETE:8)
Block(-7,27,6,CONCRETE:8)
Block(-7,27,7,CONCRETE:8)
Block(-7,27,8,STAINED_GLASS:15)
Block(-7,28,-7,CONCRETE:8)
Block(-7,28,2,STAINED_GLASS_PANE:15)
Block(-7,28,4,STAINED_GLASS:15)
Block(-7,28,5,IRON_TRAPDOOR:9)
Block(-7,28,6,CONCRETE:0)
Block(-7,28,7,IRON_TRAPDOOR:10)
Block(-7,28,8,STAINED_GLASS:15)
Block(-7,29,-7,CONCRETE:8)
Block(-7,29,4,STAINED_GLASS:15)
Block(-7,29,6,IRON_DOOR_BLOCK:2)
Block(-7,29,8,STAINED_GLASS:15)
Block(-7,30,-7,CONCRETE:8)
Block(-7,30,4,STAINED_GLASS:15)
Block(-7,30,6,IRON_DOOR_BLOCK:10)
Block(-7,30,8,STAINED_GLASS:15)
Block(-7,31,-7,CONCRETE:8)
Block(-7,31,4,STAINED_GLASS:15)
Block(-7,31,6,IRON_TRAPDOOR:2)
Block(-7,31,8,STAINED_GLASS:15)
Block(-7,32,-7,CONCRETE:8)
Block(-7,32,4,STAINED_GLASS:15)
Block(-7,32,8,STAINED_GLASS:15)
Block(-7,33,-7,CONCRETE:8)
Block(-7,33,4,STAINED_GLASS:15)
Block(-7,33,8,STAINED_GLASS:15)
Block(-7,34,-7,CONCRETE:8)
Block(-7,34,4,STAINED_GLASS:15)
Block(-7,34,6,CONCRETE:0)
Block(-7,34,8,STAINED_GLASS:15)
Block(-7,35,-7,CONCRETE:8)
Block(-7,35,2,CONCRETE:8)
Block(-7,35,3,CONCRETE:8)
Block(-7,35,4,CONCRETE:8)
Block(-7,35,5,CONCRETE:8)
Block(-7,35,6,CONCRETE:8)
Block(-7,35,7,CONCRETE:8)
Block(-7,35,8,STAINED_GLASS:15)
Block(-7,36,-7,CONCRETE:8)
Block(-7,36,2,STAINED_GLASS_PANE:15)
Block(-7,36,4,STAINED_GLASS:15)
Block(-7,36,5,IRON_TRAPDOOR:9)
Block(-7,36,6,CONCRETE:0)
Block(-7,36,7,IRON_TRAPDOOR:10)
Block(-7,36,8,STAINED_GLASS:15)
Block(-7,37,-7,CONCRETE:8)
Block(-7,37,4,STAINED_GLASS:15)
Block(-7,37,6,IRON_DOOR_BLOCK:2)
Block(-7,37,8,STAINED_GLASS:15)
Block(-7,38,-7,CONCRETE:8)
Block(-7,38,4,STAINED_GLASS:15)
Block(-7,38,6,IRON_DOOR_BLOCK:10)
Block(-7,38,8,STAINED_GLASS:15)
Block(-7,39,-7,CONCRETE:8)
Block(-7,39,4,STAINED_GLASS:15)
Block(-7,39,6,IRON_TRAPDOOR:2)
Block(-7,39,8,STAINED_GLASS:15)
Block(-7,40,-7,CONCRETE:8)
Block(-7,40,4,STAINED_GLASS:15)
Block(-7,40,8,STAINED_GLASS:15)
Block(-7,41,-7,CONCRETE:8)
Block(-7,41,4,STAINED_GLASS:15)
Block(-7,41,8,STAINED_GLASS:15)
Block(-7,42,-7,CONCRETE:8)
Block(-7,42,4,STAINED_GLASS:15)
Block(-7,42,6,CONCRETE:0)
Block(-7,42,8,STAINED_GLASS:15)
Block(-7,43,-7,CONCRETE:8)
Block(-7,43,2,CONCRETE:8)
Block(-7,43,3,CONCRETE:8)
Block(-7,43,4,CONCRETE:8)
Block(-7,43,5,CONCRETE:8)
Block(-7,43,6,CONCRETE:8)
Block(-7,43,7,CONCRETE:8)
Block(-7,43,8,STAINED_GLASS:15)
Block(-7,44,-7,CONCRETE:8)
Block(-7,44,2,STAINED_GLASS_PANE:15)
Block(-7,44,4,STAINED_GLASS:15)
Block(-7,44,5,IRON_TRAPDOOR:9)
Block(-7,44,6,CONCRETE:0)
Block(-7,44,7,IRON_TRAPDOOR:10)
Block(-7,44,8,STAINED_GLASS:15)
Block(-7,45,-7,CONCRETE:8)
Block(-7,45,4,STAINED_GLASS:15)
Block(-7,45,6,IRON_DOOR_BLOCK:2)
Block(-7,45,8,STAINED_GLASS:15)
Block(-7,46,-7,CONCRETE:8)
Block(-7,46,4,STAINED_GLASS:15)
Block(-7,46,6,IRON_DOOR_BLOCK:10)
Block(-7,46,8,STAINED_GLASS:15)
Block(-7,47,-7,CONCRETE:8)
Block(-7,47,4,STAINED_GLASS:15)
Block(-7,47,6,IRON_TRAPDOOR:2)
Block(-7,47,8,STAINED_GLASS:15)
Block(-7,48,-7,CONCRETE:8)
Block(-7,48,4,STAINED_GLASS:15)
Block(-7,48,8,STAINED_GLASS:15)
Block(-7,49,-7,CONCRETE:8)
Block(-7,49,4,STAINED_GLASS:15)
Block(-7,49,8,STAINED_GLASS:15)
Block(-7,50,-7,CONCRETE:8)
Block(-7,50,4,STAINED_GLASS:15)
Block(-7,50,6,CONCRETE:0)
Block(-7,50,8,STAINED_GLASS:15)
Block(-7,51,-7,CONCRETE:8)
Block(-7,51,2,CONCRETE:8)
Block(-7,51,3,CONCRETE:8)
Block(-7,51,4,CONCRETE:8)
Block(-7,51,5,CONCRETE:8)
Block(-7,51,6,CONCRETE:8)
Block(-7,51,7,CONCRETE:8)
Block(-7,51,8,STAINED_GLASS:15)
Block(-7,52,-7,CONCRETE:8)
Block(-7,52,2,STAINED_GLASS_PANE:15)
Block(-7,52,4,STAINED_GLASS:15)
Block(-7,52,5,IRON_TRAPDOOR:9)
Block(-7,52,6,CONCRETE:0)
Block(-7,52,7,IRON_TRAPDOOR:10)
Block(-7,52,8,STAINED_GLASS:15)
Block(-7,53,-7,CONCRETE:8)
Block(-7,53,4,STAINED_GLASS:15)
Block(-7,53,6,IRON_DOOR_BLOCK:2)
Block(-7,53,8,STAINED_GLASS:15)
Block(-7,54,-7,CONCRETE:8)
Block(-7,54,4,STAINED_GLASS:15)
Block(-7,54,6,IRON_DOOR_BLOCK:10)
Block(-7,54,8,STAINED_GLASS:15)
Block(-7,55,-7,CONCRETE:8)
Block(-7,55,4,STAINED_GLASS:15)
Block(-7,55,6,IRON_TRAPDOOR:2)
Block(-7,55,8,STAINED_GLASS:15)
Block(-7,56,-7,CONCRETE:8)
Block(-7,56,4,STAINED_GLASS:15)
Block(-7,56,8,STAINED_GLASS:15)
Block(-7,57,-7,CONCRETE:8)
Block(-7,57,4,STAINED_GLASS:15)
Block(-7,57,8,STAINED_GLASS:15)
Block(-7,58,-7,CONCRETE:8)
Block(-7,58,4,STAINED_GLASS:15)
Block(-7,58,6,CONCRETE:0)
Block(-7,58,8,STAINED_GLASS:15)
Block(-7,59,-7,CONCRETE:8)
Block(-7,59,2,CONCRETE:8)
Block(-7,59,3,CONCRETE:8)
Block(-7,59,4,CONCRETE:8)
Block(-7,59,5,CONCRETE:8)
Block(-7,59,6,CONCRETE:8)
Block(-7,59,7,CONCRETE:8)
Block(-7,59,8,STAINED_GLASS:15)
Block(-7,60,-7,CONCRETE:8)
Block(-7,60,2,STAINED_GLASS_PANE:15)
Block(-7,60,4,STAINED_GLASS:15)
Block(-7,60,5,IRON_TRAPDOOR:9)
Block(-7,60,6,CONCRETE:0)
Block(-7,60,7,IRON_TRAPDOOR:10)
Block(-7,60,8,STAINED_GLASS:15)
Block(-7,61,-7,CONCRETE:8)
Block(-7,61,4,STAINED_GLASS:15)
Block(-7,61,6,IRON_DOOR_BLOCK:2)
Block(-7,61,8,STAINED_GLASS:15)
Block(-7,62,-7,CONCRETE:8)
Block(-7,62,4,STAINED_GLASS:15)
Block(-7,62,6,IRON_DOOR_BLOCK:10)
Block(-7,62,8,STAINED_GLASS:15)
Block(-7,63,-7,CONCRETE:8)
Block(-7,63,4,STAINED_GLASS:15)
Block(-7,63,6,IRON_TRAPDOOR:2)
Block(-7,63,8,STAINED_GLASS:15)
Block(-7,64,-7,CONCRETE:8)
Block(-7,64,4,STAINED_GLASS:15)
Block(-7,64,8,STAINED_GLASS:15)
Block(-7,65,-7,CONCRETE:8)
Block(-7,65,4,STAINED_GLASS:15)
Block(-7,65,8,STAINED_GLASS:15)
Block(-7,66,-7,CONCRETE:8)
Block(-7,66,4,STAINED_GLASS:15)
Block(-7,66,6,CONCRETE:0)
Block(-7,66,8,STAINED_GLASS:15)
Block(-7,67,-7,CONCRETE:8)
Block(-7,67,2,CONCRETE:8)
Block(-7,67,3,CONCRETE:8)
Block(-7,67,4,CONCRETE:8)
Block(-7,67,5,CONCRETE:8)
Block(-7,67,6,CONCRETE:8)
Block(-7,67,7,CONCRETE:8)
Block(-7,67,8,STAINED_GLASS:15)
Block(-7,68,-7,CONCRETE:8)
Block(-7,68,2,STAINED_GLASS_PANE:15)
Block(-7,68,4,STAINED_GLASS:15)
Block(-7,68,5,IRON_TRAPDOOR:9)
Block(-7,68,6,CONCRETE:0)
Block(-7,68,7,IRON_TRAPDOOR:10)
Block(-7,68,8,STAINED_GLASS:15)
Block(-7,69,-7,CONCRETE:8)
Block(-7,69,4,STAINED_GLASS:15)
Block(-7,69,6,IRON_DOOR_BLOCK:2)
Block(-7,69,8,STAINED_GLASS:15)
Block(-7,70,-7,CONCRETE:8)
Block(-7,70,4,STAINED_GLASS:15)
Block(-7,70,6,IRON_DOOR_BLOCK:10)
Block(-7,70,8,STAINED_GLASS:15)
Block(-7,71,-7,CONCRETE:8)
Block(-7,71,4,STAINED_GLASS:15)
Block(-7,71,6,IRON_TRAPDOOR:2)
Block(-7,71,8,STAINED_GLASS:15)
Block(-7,72,-7,CONCRETE:8)
Block(-7,72,4,STAINED_GLASS:15)
Block(-7,72,8,STAINED_GLASS:15)
Block(-7,73,-7,CONCRETE:8)
Block(-7,73,4,STAINED_GLASS:15)
Block(-7,73,8,STAINED_GLASS:15)
Block(-7,74,-7,CONCRETE:8)
Block(-7,74,4,STAINED_GLASS:15)
Block(-7,74,6,CONCRETE:0)
Block(-7,74,8,STAINED_GLASS:15)
Block(-7,75,-7,CONCRETE:8)
Block(-7,75,0,CONCRETE:8)
Block(-7,75,1,CONCRETE:8)
Block(-7,75,2,CONCRETE:8)
Block(-7,75,3,CONCRETE:8)
Block(-7,75,4,CONCRETE:8)
Block(-7,75,5,CONCRETE:8)
Block(-7,75,6,CONCRETE:8)
Block(-7,75,7,CONCRETE:8)
Block(-7,75,8,STAINED_GLASS:15)
Block(-7,76,-7,CONCRETE:8)
Block(-7,76,0,STAINED_GLASS_PANE:15)
Block(-7,76,8,STAINED_GLASS:15)
Block(-7,77,-7,CONCRETE:8)
Block(-7,77,2,CONCRETE:8)
Block(-7,77,8,CONCRETE:8)
Block(-7,78,-7,CONCRETE:8)
Block(-7,78,2,CONCRETE:8)
Block(-7,78,3,CONCRETE:8)
Block(-7,78,4,CONCRETE:8)
Block(-7,78,5,CONCRETE:8)
Block(-7,78,6,CONCRETE:8)
Block(-7,78,7,CONCRETE:8)
Block(-7,78,8,CONCRETE:8)
Block(-7,79,-7,CONCRETE:8)
Block(-7,79,2,CONCRETE:8)
Block(-7,79,3,CONCRETE:8)
Block(-7,79,4,CONCRETE:8)
Block(-7,79,5,CONCRETE:8)
Block(-7,79,6,CONCRETE:8)
Block(-7,79,7,CONCRETE:8)
Block(-7,79,8,CONCRETE:8)
Block(-7,80,-7,CONCRETE:8)
Block(-7,80,2,STAINED_GLASS:15)
Block(-7,81,-7,CONCRETE:8)
Block(-7,81,2,STAINED_GLASS:15)
Block(-7,82,-7,CONCRETE:8)
Block(-7,82,2,STAINED_GLASS:15)
Block(-7,83,-7,CONCRETE:8)
Block(-7,83,0,CONCRETE:8)
Block(-7,83,1,CONCRETE:8)
Block(-7,83,2,STAINED_GLASS:15)
Block(-7,84,-7,CONCRETE:8)
Block(-7,84,0,STAINED_GLASS_PANE:15)
Block(-7,84,2,STAINED_GLASS:15)
Block(-7,85,-7,CONCRETE:8)
Block(-7,85,2,STAINED_GLASS:15)
Block(-7,86,-7,CONCRETE:8)
Block(-7,86,2,STAINED_GLASS:15)
Block(-7,87,-7,CONCRETE:8)
Block(-7,87,2,STAINED_GLASS:15)
Block(-7,88,-7,CONCRETE:8)
Block(-7,88,2,STAINED_GLASS:15)
Block(-7,89,-7,CONCRETE:8)
Block(-7,89,2,STAINED_GLASS:15)
Block(-7,90,-7,CONCRETE:8)
Block(-7,90,2,STAINED_GLASS:15)
Block(-7,91,-7,CONCRETE:8)
Block(-7,91,0,CONCRETE:8)
Block(-7,91,1,CONCRETE:8)
Block(-7,91,2,STAINED_GLASS:15)
Block(-7,92,-7,CONCRETE:8)
Block(-7,92,0,STAINED_GLASS_PANE:15)
Block(-7,92,2,STAINED_GLASS:15)
Block(-7,93,-7,CONCRETE:8)
Block(-7,93,2,STAINED_GLASS:15)
Block(-7,94,-7,CONCRETE:8)
Block(-7,94,2,STAINED_GLASS:15)
Block(-7,95,-7,CONCRETE:8)
Block(-7,95,2,STAINED_GLASS:15)
Block(-7,96,-7,CONCRETE:8)
Block(-7,96,-2,CONCRETE:15)
Block(-7,96,2,CONCRETE:15)
Block(-7,97,-7,CONCRETE:8)
Block(-7,97,-2,CONCRETE:15)
Block(-7,97,-1,CONCRETE:15)
Block(-7,97,0,CONCRETE:15)
Block(-7,97,1,CONCRETE:15)
Block(-7,97,2,CONCRETE:15)
Block(-7,98,-7,CONCRETE:8)
Block(-7,98,-2,CONCRETE:15)
Block(-7,98,-1,CONCRETE:15)
Block(-7,98,0,CONCRETE:15)
Block(-7,98,1,CONCRETE:15)
Block(-7,98,2,CONCRETE:15)
Block(-7,99,-7,CONCRETE:8)
Block(-7,99,-6,CONCRETE:8)
Block(-7,99,-5,CONCRETE:8)
Block(-7,99,-4,CONCRETE:8)
Block(-7,99,-3,CONCRETE:8)
Block(-7,99,-2,STAINED_GLASS:15)
Block(-7,100,-7,CONCRETE:8)
Block(-7,100,-6,STAINED_GLASS_PANE:15)
Block(-7,100,-5,STAINED_GLASS_PANE:15)
Block(-7,100,-4,STAINED_GLASS_PANE:15)
Block(-7,100,-2,STAINED_GLASS:15)
Block(-7,101,-7,CONCRETE:8)
Block(-7,101,-2,STAINED_GLASS:15)
Block(-7,102,-7,CONCRETE:8)
Block(-7,102,-2,STAINED_GLASS:15)
Block(-7,103,-7,CONCRETE:8)
Block(-7,103,-2,STAINED_GLASS:15)
Block(-7,104,-7,CONCRETE:8)
Block(-7,104,-2,STAINED_GLASS:15)
Block(-7,105,-7,CONCRETE:8)
Block(-7,105,-2,STAINED_GLASS:15)
Block(-7,106,-7,CONCRETE:8)
Block(-7,106,-2,STAINED_GLASS:15)
Block(-7,107,-7,CONCRETE:8)
Block(-7,107,-6,CONCRETE:8)
Block(-7,107,-5,CONCRETE:8)
Block(-7,107,-4,CONCRETE:8)
Block(-7,107,-3,CONCRETE:8)
Block(-7,107,-2,STAINED_GLASS:15)
Block(-7,108,-7,CONCRETE:8)
Block(-7,108,-6,STAINED_GLASS_PANE:15)
Block(-7,108,-5,STAINED_GLASS_PANE:15)
Block(-7,108,-4,STAINED_GLASS_PANE:15)
Block(-7,108,-2,STAINED_GLASS:15)
Block(-7,109,-7,CONCRETE:8)
Block(-7,109,-2,STAINED_GLASS:15)
Block(-7,110,-7,CONCRETE:8)
Block(-7,110,-2,STAINED_GLASS:15)
Block(-7,111,-7,CONCRETE:8)
Block(-7,111,-2,STAINED_GLASS:15)
Block(-7,112,-7,CONCRETE:8)
Block(-7,112,-2,STAINED_GLASS:15)
Block(-7,113,-7,CONCRETE:8)
Block(-7,113,-2,STAINED_GLASS:15)
Block(-7,114,-7,CONCRETE:8)
Block(-7,114,-2,STAINED_GLASS:15)
Block(-7,115,-7,CONCRETE:8)
Block(-7,115,-6,CONCRETE:8)
Block(-7,115,-5,CONCRETE:8)
Block(-7,115,-4,CONCRETE:8)
Block(-7,115,-3,CONCRETE:8)
Block(-7,115,-2,STAINED_GLASS:15)
Block(-7,116,-7,CONCRETE:8)
Block(-7,116,-6,STAINED_GLASS_PANE:15)
Block(-7,116,-5,STAINED_GLASS_PANE:15)
Block(-7,116,-4,STAINED_GLASS_PANE:15)
Block(-7,116,-2,STAINED_GLASS:15)
Block(-7,117,-7,CONCRETE:8)
Block(-7,117,-2,STAINED_GLASS:15)
Block(-7,118,-7,CONCRETE:8)
Block(-7,118,-2,STAINED_GLASS:15)
Block(-7,119,-7,CONCRETE:8)
Block(-7,119,-2,STAINED_GLASS:15)
Block(-7,120,-7,CONCRETE:8)
Block(-7,120,-3,TRIPWIRE:4)
Block(-7,120,-2,STAINED_GLASS:15)
Block(-7,121,-7,CONCRETE:8)
Block(-7,121,-2,STAINED_GLASS:15)
Block(-7,122,-7,CONCRETE:8)
Block(-7,122,-2,STAINED_GLASS:15)
Block(-7,123,-7,CONCRETE:8)
Block(-7,123,-6,CONCRETE:8)
Block(-7,123,-5,CONCRETE:8)
Block(-7,123,-4,CONCRETE:8)
Block(-7,123,-3,CONCRETE:8)
Block(-7,123,-2,STAINED_GLASS:15)
Block(-7,124,-7,CONCRETE:8)
Block(-7,124,-5,STAINED_GLASS_PANE:15)
Block(-7,124,-4,QUARTZ_STAIRS:0)
Block(-7,124,-2,STAINED_GLASS:15)
Block(-7,125,-7,CONCRETE:8)
Block(-7,125,-4,CONCRETE:14)
Block(-7,125,-2,STAINED_GLASS:15)
Block(-7,126,-7,CONCRETE:8)
Block(-7,126,-4,QUARTZ_STAIRS:4)
Block(-7,126,-2,STAINED_GLASS:15)
Block(-7,127,-7,CONCRETE:8)
Block(-7,127,-6,IRON_TRAPDOOR:9)
Block(-7,127,-5,IRON_TRAPDOOR:10)
Block(-7,127,-4,IRON_TRAPDOOR:10)
Block(-7,127,-3,IRON_TRAPDOOR:9)
Block(-7,127,-2,STAINED_GLASS:15)
Block(-7,128,-7,CONCRETE:8)
Block(-7,128,-6,STAINED_GLASS_PANE:15)
Block(-7,128,-5,STAINED_GLASS_PANE:15)
Block(-7,128,-4,STAINED_GLASS_PANE:15)
Block(-7,128,-3,STAINED_GLASS_PANE:15)
Block(-7,128,-2,STAINED_GLASS:15)
Block(-7,129,-7,CONCRETE:8)
Block(-7,129,-2,STAINED_GLASS:15)
Block(-7,130,-7,CONCRETE:8)
Block(-7,130,-2,STAINED_GLASS:15)
Block(-7,131,-7,CONCRETE:8)
Block(-7,131,-2,STAINED_GLASS:15)
Block(-7,132,-7,CONCRETE:8)
Block(-7,132,-2,STAINED_GLASS:15)
Block(-7,133,-7,CONCRETE:8)
Block(-7,133,-2,CONCRETE:8)
Block(-7,134,-7,CONCRETE:8)
Block(-7,134,-6,CONCRETE:8)
Block(-7,134,-5,CONCRETE:8)
Block(-7,134,-4,CONCRETE:8)
Block(-7,134,-3,CONCRETE:8)
Block(-7,134,-2,CONCRETE:8)
Block(-7,135,-7,CONCRETE:8)
Block(-7,135,-6,CONCRETE:8)
Block(-7,135,-5,CONCRETE:8)
Block(-7,135,-4,CONCRETE:8)
Block(-7,135,-3,CONCRETE:8)
Block(-7,135,-2,CONCRETE:8)
Block(-6,0,-7,CONCRETE:7)
Block(-6,0,-6,CONCRETE:7)
Block(-6,0,-5,CONCRETE:7)
Block(-6,0,-4,CONCRETE:7)
Block(-6,0,-3,CONCRETE:7)
Block(-6,0,-2,CONCRETE:7)
Block(-6,0,-1,CONCRETE:7)
Block(-6,0,0,CONCRETE:7)
Block(-6,0,1,CONCRETE:7)
Block(-6,0,2,CONCRETE:7)
Block(-6,0,3,CONCRETE:7)
Block(-6,0,4,CONCRETE:7)
Block(-6,0,5,CONCRETE:7)
Block(-6,0,6,CONCRETE:7)
Block(-6,0,7,CONCRETE:7)
Block(-6,0,8,CONCRETE:7)
Block(-6,1,-7,CONCRETE:7)
Block(-6,1,-6,CONCRETE:7)
Block(-6,1,-5,CONCRETE:7)
Block(-6,1,-4,CONCRETE:7)
Block(-6,1,-3,CONCRETE:7)
Block(-6,1,-2,STATIONARY_WATER:0)
Block(-6,1,-1,STATIONARY_WATER:0)
Block(-6,1,0,STATIONARY_WATER:0)
Block(-6,1,1,STATIONARY_WATER:0)
Block(-6,1,2,CONCRETE:7)
Block(-6,1,3,CONCRETE:7)
Block(-6,1,4,CONCRETE:7)
Block(-6,1,5,CONCRETE:7)
Block(-6,1,6,CONCRETE:7)
Block(-6,1,7,CONCRETE:7)
Block(-6,1,8,CONCRETE:7)
Block(-6,2,-7,SMOOTH_STAIRS:1)
Block(-6,2,-6,SMOOTH_STAIRS:1)
Block(-6,2,-5,SMOOTH_STAIRS:1)
Block(-6,2,-4,SMOOTH_STAIRS:1)
Block(-6,2,-3,SMOOTH_STAIRS:1)
Block(-6,2,-2,AIR:0)
Block(-6,2,-1,AIR:0)
Block(-6,2,0,AIR:0)
Block(-6,2,1,AIR:0)
Block(-6,2,2,CONCRETE:7)
Block(-6,2,3,CONCRETE:7)
Block(-6,2,4,CONCRETE:7)
Block(-6,2,5,CONCRETE:7)
Block(-6,2,6,CONCRETE:7)
Block(-6,2,7,CONCRETE:7)
Block(-6,2,8,CONCRETE:7)
Block(-6,3,-7,AIR:0)
Block(-6,3,-6,AIR:0)
Block(-6,3,-5,AIR:0)
Block(-6,3,-4,AIR:0)
Block(-6,3,-3,AIR:0)
Block(-6,3,-2,AIR:0)
Block(-6,3,-1,AIR:0)
Block(-6,3,0,AIR:0)
Block(-6,3,1,AIR:0)
Block(-6,3,2,CONCRETE:7)
Block(-6,3,3,CONCRETE:7)
Block(-6,3,4,CONCRETE:7)
Block(-6,3,5,CONCRETE:7)
Block(-6,3,6,CONCRETE:7)
Block(-6,3,7,CONCRETE:7)
Block(-6,3,8,CONCRETE:7)
Block(-6,4,-7,AIR:0)
Block(-6,4,-6,AIR:0)
Block(-6,4,-5,AIR:0)
Block(-6,4,-4,AIR:0)
Block(-6,4,-3,AIR:0)
Block(-6,4,-2,AIR:0)
Block(-6,4,-1,AIR:0)
Block(-6,4,0,AIR:0)
Block(-6,4,1,AIR:0)
Block(-6,4,2,CONCRETE:7)
Block(-6,4,3,CONCRETE:7)
Block(-6,4,4,CONCRETE:7)
Block(-6,4,5,CONCRETE:7)
Block(-6,4,6,CONCRETE:7)
Block(-6,4,7,CONCRETE:7)
Block(-6,4,8,CONCRETE:7)
Block(-6,5,-7,CONCRETE:14)
Block(-6,5,-6,CONCRETE:11)
Block(-6,5,-5,AIR:0)
Block(-6,5,-4,AIR:0)
Block(-6,5,-3,AIR:0)
Block(-6,5,-2,AIR:0)
Block(-6,5,-1,AIR:0)
Block(-6,5,0,AIR:0)
Block(-6,5,1,AIR:0)
Block(-6,5,2,CONCRETE:7)
Block(-6,5,3,CONCRETE:7)
Block(-6,5,4,CONCRETE:7)
Block(-6,5,5,CONCRETE:7)
Block(-6,5,6,CONCRETE:7)
Block(-6,5,7,CONCRETE:7)
Block(-6,5,8,CONCRETE:7)
Block(-6,6,-7,AIR:0)
Block(-6,6,-6,AIR:0)
Block(-6,6,-5,AIR:0)
Block(-6,6,-4,AIR:0)
Block(-6,6,-3,AIR:0)
Block(-6,6,-2,AIR:0)
Block(-6,6,-1,AIR:0)
Block(-6,6,0,AIR:0)
Block(-6,6,1,AIR:0)
Block(-6,6,2,CONCRETE:7)
Block(-6,6,3,CONCRETE:7)
Block(-6,6,4,CONCRETE:7)
Block(-6,6,5,CONCRETE:7)
Block(-6,6,6,CONCRETE:7)
Block(-6,6,7,CONCRETE:7)
Block(-6,6,8,CONCRETE:7)
Block(-6,7,-7,CONCRETE:7)
Block(-6,7,-6,CONCRETE:7)
Block(-6,7,-5,CONCRETE:7)
Block(-6,7,-4,CONCRETE:7)
Block(-6,7,-3,CONCRETE:7)
Block(-6,7,-2,CONCRETE:7)
Block(-6,7,-1,CONCRETE:7)
Block(-6,7,0,CONCRETE:7)
Block(-6,7,1,CONCRETE:7)
Block(-6,7,2,CONCRETE:12)
Block(-6,7,3,CONCRETE:7)
Block(-6,7,4,CONCRETE:7)
Block(-6,7,5,CONCRETE:7)
Block(-6,7,6,CONCRETE:7)
Block(-6,7,7,CONCRETE:7)
Block(-6,7,8,CONCRETE:7)
Block(-6,8,-7,CONCRETE:7)
Block(-6,8,-6,CONCRETE:7)
Block(-6,8,-5,CONCRETE:7)
Block(-6,8,-4,CONCRETE:7)
Block(-6,8,-3,CONCRETE:7)
Block(-6,8,-2,SMOOTH_STAIRS:3)
Block(-6,8,-1,STEP:0)
Block(-6,8,0,CONCRETE:7)
Block(-6,8,1,CONCRETE:7)
Block(-6,8,2,CONCRETE:7)
Block(-6,8,3,CONCRETE:7)
Block(-6,8,4,CONCRETE:7)
Block(-6,8,5,CONCRETE:7)
Block(-6,8,6,CONCRETE:7)
Block(-6,8,7,CONCRETE:7)
Block(-6,8,8,CONCRETE:7)
Block(-6,9,-7,CONCRETE:7)
Block(-6,9,-6,CONCRETE:7)
Block(-6,9,-5,CONCRETE:7)
Block(-6,9,-4,CONCRETE:7)
Block(-6,9,-3,SMOOTH_STAIRS:3)
Block(-6,9,-2,AIR:0)
Block(-6,9,-1,AIR:0)
Block(-6,9,0,CONCRETE:7)
Block(-6,9,1,CONCRETE:7)
Block(-6,9,2,CONCRETE:7)
Block(-6,9,3,CONCRETE:7)
Block(-6,9,4,CONCRETE:7)
Block(-6,9,5,CONCRETE:7)
Block(-6,9,6,CONCRETE:7)
Block(-6,9,7,CONCRETE:7)
Block(-6,9,8,CONCRETE:7)
Block(-6,10,-7,AIR:0)
Block(-6,10,-6,AIR:0)
Block(-6,10,-5,CONCRETE:7)
Block(-6,10,-4,AIR:0)
Block(-6,10,-3,AIR:0)
Block(-6,10,-2,AIR:0)
Block(-6,10,-1,AIR:0)
Block(-6,10,0,CONCRETE:7)
Block(-6,10,1,CONCRETE:7)
Block(-6,10,2,CONCRETE:7)
Block(-6,10,3,CONCRETE:7)
Block(-6,10,4,CONCRETE:7)
Block(-6,10,5,CONCRETE:7)
Block(-6,10,6,CONCRETE:7)
Block(-6,10,7,CONCRETE:7)
Block(-6,10,8,CONCRETE:7)
Block(-6,11,-7,AIR:0)
Block(-6,11,-6,AIR:0)
Block(-6,11,-5,CONCRETE:7)
Block(-6,11,-4,AIR:0)
Block(-6,11,-3,AIR:0)
Block(-6,11,-2,AIR:0)
Block(-6,11,-1,AIR:0)
Block(-6,11,0,CONCRETE:7)
Block(-6,11,1,CONCRETE:7)
Block(-6,11,2,CONCRETE:7)
Block(-6,11,3,CONCRETE:7)
Block(-6,11,4,CONCRETE:7)
Block(-6,11,5,CONCRETE:7)
Block(-6,11,6,CONCRETE:7)
Block(-6,11,7,CONCRETE:7)
Block(-6,11,8,CONCRETE:7)
Block(-6,12,-7,AIR:0)
Block(-6,12,-6,AIR:0)
Block(-6,12,-5,CONCRETE:7)
Block(-6,12,-4,AIR:0)
Block(-6,12,-3,CONCRETE:4)
Block(-6,12,-2,AIR:0)
Block(-6,12,-1,AIR:0)
Block(-6,12,0,CONCRETE:7)
Block(-6,12,1,CONCRETE:7)
Block(-6,12,2,CONCRETE:7)
Block(-6,12,3,CONCRETE:7)
Block(-6,12,4,CONCRETE:7)
Block(-6,12,5,CONCRETE:7)
Block(-6,12,6,CONCRETE:7)
Block(-6,12,7,CONCRETE:7)
Block(-6,12,8,CONCRETE:7)
Block(-6,13,-7,AIR:0)
Block(-6,13,-6,AIR:0)
Block(-6,13,-5,CONCRETE:7)
Block(-6,13,-4,AIR:0)
Block(-6,13,-3,IRON_FENCE:0)
Block(-6,13,-2,AIR:0)
Block(-6,13,-1,AIR:0)
Block(-6,13,0,CONCRETE:7)
Block(-6,13,1,CONCRETE:7)
Block(-6,13,2,CONCRETE:7)
Block(-6,13,3,CONCRETE:7)
Block(-6,13,4,CONCRETE:7)
Block(-6,13,5,CONCRETE:7)
Block(-6,13,6,CONCRETE:7)
Block(-6,13,7,CONCRETE:7)
Block(-6,13,8,CONCRETE:7)
Block(-6,14,-7,CONCRETE:7)
Block(-6,14,-6,CONCRETE:7)
Block(-6,14,-5,CONCRETE:7)
Block(-6,14,-4,CONCRETE:7)
Block(-6,14,-3,CONCRETE:7)
Block(-6,14,-2,CONCRETE:7)
Block(-6,14,-1,CONCRETE:7)
Block(-6,14,0,CONCRETE:7)
Block(-6,14,1,CONCRETE:7)
Block(-6,14,2,CONCRETE:7)
Block(-6,14,3,CONCRETE:7)
Block(-6,14,4,CONCRETE:7)
Block(-6,14,5,CONCRETE:7)
Block(-6,14,6,CONCRETE:7)
Block(-6,14,7,CONCRETE:7)
Block(-6,14,8,CONCRETE:7)
Block(-6,15,-7,CONCRETE:7)
Block(-6,15,-6,CONCRETE:7)
Block(-6,15,-5,CONCRETE:7)
Block(-6,15,-4,CONCRETE:7)
Block(-6,15,-3,CONCRETE:7)
Block(-6,15,-2,CONCRETE:7)
Block(-6,15,-1,CONCRETE:7)
Block(-6,15,0,CONCRETE:7)
Block(-6,15,1,CONCRETE:7)
Block(-6,15,2,CONCRETE:7)
Block(-6,15,3,CONCRETE:7)
Block(-6,15,4,CONCRETE:7)
Block(-6,15,5,CONCRETE:7)
Block(-6,15,6,CONCRETE:7)
Block(-6,15,7,CONCRETE:7)
Block(-6,15,8,CONCRETE:7)
Block(-6,16,-7,CONCRETE:7)
Block(-6,16,-6,CONCRETE:7)
Block(-6,16,-5,CONCRETE:7)
Block(-6,16,-4,CONCRETE:7)
Block(-6,16,-3,CONCRETE:7)
Block(-6,16,-2,CONCRETE:7)
Block(-6,16,-1,CONCRETE:7)
Block(-6,16,0,CONCRETE:7)
Block(-6,16,1,CONCRETE:7)
Block(-6,16,2,CONCRETE:7)
Block(-6,16,3,CONCRETE:7)
Block(-6,16,4,CONCRETE:7)
Block(-6,16,5,CONCRETE:7)
Block(-6,16,6,CONCRETE:7)
Block(-6,16,7,CONCRETE:7)
Block(-6,16,8,CONCRETE:7)
Block(-6,17,-7,CONCRETE:7)
Block(-6,17,-6,CONCRETE:7)
Block(-6,17,-5,CONCRETE:7)
Block(-6,17,-4,CONCRETE:7)
Block(-6,17,-3,CONCRETE:7)
Block(-6,17,-2,CONCRETE:7)
Block(-6,17,-1,CONCRETE:7)
Block(-6,17,0,CONCRETE:7)
Block(-6,17,1,CONCRETE:7)
Block(-6,17,2,CONCRETE:7)
Block(-6,17,3,CONCRETE:7)
Block(-6,17,4,CONCRETE:7)
Block(-6,17,5,CONCRETE:7)
Block(-6,17,6,CONCRETE:7)
Block(-6,17,7,CONCRETE:7)
Block(-6,17,8,CONCRETE:7)
Block(-6,18,-7,CONCRETE:8)
Block(-6,18,-6,CONCRETE:8)
Block(-6,18,-5,CONCRETE:8)
Block(-6,18,-4,CONCRETE:8)
Block(-6,18,-3,CONCRETE:8)
Block(-6,18,-2,CONCRETE:15)
Block(-6,18,-1,CONCRETE:15)
Block(-6,18,0,CONCRETE:15)
Block(-6,18,1,CONCRETE:15)
Block(-6,18,2,CONCRETE:15)
Block(-6,18,3,CONCRETE:8)
Block(-6,18,4,CONCRETE:8)
Block(-6,18,5,CONCRETE:8)
Block(-6,18,6,CONCRETE:8)
Block(-6,18,7,CONCRETE:8)
Block(-6,18,8,CONCRETE:8)
Block(-6,19,-7,CONCRETE:8)
Block(-6,19,-4,CONCRETE:8)
Block(-6,19,-3,CONCRETE:8)
Block(-6,19,-2,CONCRETE:8)
Block(-6,19,-1,CONCRETE:8)
Block(-6,19,0,CONCRETE:8)
Block(-6,19,1,CONCRETE:8)
Block(-6,19,2,CONCRETE:8)
Block(-6,19,3,CONCRETE:8)
Block(-6,19,8,STAINED_GLASS:15)
Block(-6,20,-7,CONCRETE:8)
Block(-6,20,-4,CONCRETE:8)
Block(-6,20,-3,CONCRETE:8)
Block(-6,20,-2,CONCRETE:8)
Block(-6,20,-1,CONCRETE:8)
Block(-6,20,0,CONCRETE:8)
Block(-6,20,1,CONCRETE:8)
Block(-6,20,2,CONCRETE:8)
Block(-6,20,3,CONCRETE:8)
Block(-6,20,8,STAINED_GLASS:15)
Block(-6,21,-7,CONCRETE:8)
Block(-6,21,-6,IRON_TRAPDOOR:2)
Block(-6,21,-5,IRON_TRAPDOOR:2)
Block(-6,21,-4,CONCRETE:8)
Block(-6,21,-3,CONCRETE:8)
Block(-6,21,-2,CONCRETE:8)
Block(-6,21,-1,CONCRETE:8)
Block(-6,21,0,CONCRETE:8)
Block(-6,21,1,CONCRETE:8)
Block(-6,21,2,CONCRETE:8)
Block(-6,21,3,CONCRETE:8)
Block(-6,21,8,STAINED_GLASS:15)
Block(-6,22,-7,CONCRETE:8)
Block(-6,22,-4,CONCRETE:8)
Block(-6,22,-3,CONCRETE:8)
Block(-6,22,-2,CONCRETE:8)
Block(-6,22,-1,CONCRETE:8)
Block(-6,22,0,CONCRETE:8)
Block(-6,22,1,CONCRETE:8)
Block(-6,22,2,CONCRETE:8)
Block(-6,22,3,CONCRETE:8)
Block(-6,22,8,STAINED_GLASS:15)
Block(-6,23,-7,CONCRETE:8)
Block(-6,23,-4,CONCRETE:8)
Block(-6,23,-3,CONCRETE:8)
Block(-6,23,-2,CONCRETE:8)
Block(-6,23,-1,CONCRETE:8)
Block(-6,23,0,CONCRETE:8)
Block(-6,23,1,CONCRETE:8)
Block(-6,23,2,CONCRETE:8)
Block(-6,23,3,CONCRETE:8)
Block(-6,23,8,STAINED_GLASS:15)
Block(-6,24,-7,CONCRETE:8)
Block(-6,24,-4,CONCRETE:8)
Block(-6,24,-3,CONCRETE:8)
Block(-6,24,-2,CONCRETE:8)
Block(-6,24,-1,CONCRETE:8)
Block(-6,24,0,CONCRETE:8)
Block(-6,24,1,CONCRETE:8)
Block(-6,24,2,CONCRETE:8)
Block(-6,24,3,CONCRETE:8)
Block(-6,24,8,STAINED_GLASS:15)
Block(-6,25,-7,CONCRETE:8)
Block(-6,25,-4,CONCRETE:8)
Block(-6,25,-3,CONCRETE:8)
Block(-6,25,-2,CONCRETE:8)
Block(-6,25,-1,CONCRETE:8)
Block(-6,25,0,CONCRETE:8)
Block(-6,25,1,CONCRETE:8)
Block(-6,25,2,CONCRETE:8)
Block(-6,25,3,CONCRETE:8)
Block(-6,25,8,STAINED_GLASS:15)
Block(-6,26,-7,CONCRETE:8)
Block(-6,26,-4,CONCRETE:8)
Block(-6,26,-3,CONCRETE:8)
Block(-6,26,-2,CONCRETE:8)
Block(-6,26,-1,CONCRETE:8)
Block(-6,26,0,CONCRETE:8)
Block(-6,26,1,CONCRETE:8)
Block(-6,26,2,CONCRETE:8)
Block(-6,26,3,CONCRETE:8)
Block(-6,26,8,STAINED_GLASS:15)
Block(-6,27,-7,CONCRETE:8)
Block(-6,27,-6,CONCRETE:8)
Block(-6,27,-5,CONCRETE:8)
Block(-6,27,-4,CONCRETE:8)
Block(-6,27,-3,CONCRETE:8)
Block(-6,27,-2,CONCRETE:8)
Block(-6,27,-1,CONCRETE:8)
Block(-6,27,0,CONCRETE:8)
Block(-6,27,1,CONCRETE:8)
Block(-6,27,2,CONCRETE:8)
Block(-6,27,3,CONCRETE:8)
Block(-6,27,4,CONCRETE:8)
Block(-6,27,5,CONCRETE:8)
Block(-6,27,6,CONCRETE:8)
Block(-6,27,7,CONCRETE:8)
Block(-6,27,8,STAINED_GLASS:15)
Block(-6,28,-7,STAINED_GLASS_PANE:15)
Block(-6,28,-6,STAINED_GLASS_PANE:15)
Block(-6,28,-5,STAINED_GLASS_PANE:15)
Block(-6,28,-4,STAINED_GLASS_PANE:15)
Block(-6,28,-3,STAINED_GLASS_PANE:15)
Block(-6,28,-2,STAINED_GLASS_PANE:15)
Block(-6,28,-1,STAINED_GLASS_PANE:15)
Block(-6,28,0,STAINED_GLASS_PANE:15)
Block(-6,28,1,STAINED_GLASS_PANE:15)
Block(-6,28,2,CONCRETE:8)
Block(-6,28,4,STAINED_GLASS:15)
Block(-6,28,5,IRON_TRAPDOOR:9)
Block(-6,28,6,CONCRETE:0)
Block(-6,28,7,IRON_TRAPDOOR:10)
Block(-6,28,8,STAINED_GLASS:15)
Block(-6,29,2,CONCRETE:8)
Block(-6,29,4,STAINED_GLASS:15)
Block(-6,29,5,CONCRETE:15)
Block(-6,29,6,CONCRETE:14)
Block(-6,29,7,STONE_BUTTON:3)
Block(-6,29,8,STAINED_GLASS:15)
Block(-6,30,2,CONCRETE:8)
Block(-6,30,4,STAINED_GLASS:15)
Block(-6,30,5,CONCRETE:15)
Block(-6,30,6,CONCRETE:14)
Block(-6,30,7,STONE_BUTTON:3)
Block(-6,30,8,STAINED_GLASS:15)
Block(-6,31,2,CONCRETE:8)
Block(-6,31,4,STAINED_GLASS:15)
Block(-6,31,5,CONCRETE:15)
Block(-6,31,6,CONCRETE:14)
Block(-6,31,7,STONE_BUTTON:3)
Block(-6,31,8,STAINED_GLASS:15)
Block(-6,32,2,CONCRETE:8)
Block(-6,32,4,STAINED_GLASS:15)
Block(-6,32,5,IRON_TRAPDOOR:2)
Block(-6,32,6,IRON_FENCE:0)
Block(-6,32,8,STAINED_GLASS:15)
Block(-6,33,2,CONCRETE:8)
Block(-6,33,4,STAINED_GLASS:15)
Block(-6,33,6,IRON_FENCE:0)
Block(-6,33,8,STAINED_GLASS:15)
Block(-6,34,2,CONCRETE:8)
Block(-6,34,4,STAINED_GLASS:15)
Block(-6,34,6,CONCRETE:0)
Block(-6,34,8,STAINED_GLASS:15)
Block(-6,35,-7,CONCRETE:8)
Block(-6,35,-6,CONCRETE:8)
Block(-6,35,-5,CONCRETE:8)
Block(-6,35,-4,CONCRETE:8)
Block(-6,35,-3,CONCRETE:8)
Block(-6,35,-2,CONCRETE:8)
Block(-6,35,-1,CONCRETE:8)
Block(-6,35,0,CONCRETE:8)
Block(-6,35,1,CONCRETE:8)
Block(-6,35,2,CONCRETE:8)
Block(-6,35,3,CONCRETE:8)
Block(-6,35,4,CONCRETE:8)
Block(-6,35,5,CONCRETE:8)
Block(-6,35,6,CONCRETE:8)
Block(-6,35,7,CONCRETE:8)
Block(-6,35,8,STAINED_GLASS:15)
Block(-6,36,-7,STAINED_GLASS_PANE:15)
Block(-6,36,-6,STAINED_GLASS_PANE:15)
Block(-6,36,-5,STAINED_GLASS_PANE:15)
Block(-6,36,-4,STAINED_GLASS_PANE:15)
Block(-6,36,-3,STAINED_GLASS_PANE:15)
Block(-6,36,-2,STAINED_GLASS_PANE:15)
Block(-6,36,-1,STAINED_GLASS_PANE:15)
Block(-6,36,0,STAINED_GLASS_PANE:15)
Block(-6,36,1,STAINED_GLASS_PANE:15)
Block(-6,36,2,CONCRETE:8)
Block(-6,36,4,STAINED_GLASS:15)
Block(-6,36,5,IRON_TRAPDOOR:9)
Block(-6,36,6,CONCRETE:0)
Block(-6,36,7,IRON_TRAPDOOR:10)
Block(-6,36,8,STAINED_GLASS:15)
Block(-6,37,2,CONCRETE:8)
Block(-6,37,4,STAINED_GLASS:15)
Block(-6,37,5,CONCRETE:15)
Block(-6,37,6,CONCRETE:14)
Block(-6,37,7,STONE_BUTTON:3)
Block(-6,37,8,STAINED_GLASS:15)
Block(-6,38,2,CONCRETE:8)
Block(-6,38,4,STAINED_GLASS:15)
Block(-6,38,5,CONCRETE:15)
Block(-6,38,6,CONCRETE:14)
Block(-6,38,7,STONE_BUTTON:3)
Block(-6,38,8,STAINED_GLASS:15)
Block(-6,39,2,CONCRETE:8)
Block(-6,39,4,STAINED_GLASS:15)
Block(-6,39,5,CONCRETE:15)
Block(-6,39,6,CONCRETE:14)
Block(-6,39,7,STONE_BUTTON:3)
Block(-6,39,8,STAINED_GLASS:15)
Block(-6,40,2,CONCRETE:8)
Block(-6,40,4,STAINED_GLASS:15)
Block(-6,40,5,IRON_TRAPDOOR:2)
Block(-6,40,6,IRON_FENCE:0)
Block(-6,40,8,STAINED_GLASS:15)
Block(-6,41,2,CONCRETE:8)
Block(-6,41,4,STAINED_GLASS:15)
Block(-6,41,6,IRON_FENCE:0)
Block(-6,41,8,STAINED_GLASS:15)
Block(-6,42,2,CONCRETE:8)
Block(-6,42,4,STAINED_GLASS:15)
Block(-6,42,6,CONCRETE:0)
Block(-6,42,8,STAINED_GLASS:15)
Block(-6,43,-7,CONCRETE:8)
Block(-6,43,-6,CONCRETE:8)
Block(-6,43,-5,CONCRETE:8)
Block(-6,43,-4,CONCRETE:8)
Block(-6,43,-3,CONCRETE:8)
Block(-6,43,-2,CONCRETE:8)
Block(-6,43,-1,CONCRETE:8)
Block(-6,43,0,CONCRETE:8)
Block(-6,43,1,CONCRETE:8)
Block(-6,43,2,CONCRETE:8)
Block(-6,43,3,CONCRETE:8)
Block(-6,43,4,CONCRETE:8)
Block(-6,43,5,CONCRETE:8)
Block(-6,43,6,CONCRETE:8)
Block(-6,43,7,CONCRETE:8)
Block(-6,43,8,STAINED_GLASS:15)
Block(-6,44,-7,STAINED_GLASS_PANE:15)
Block(-6,44,-6,STAINED_GLASS_PANE:15)
Block(-6,44,-5,STAINED_GLASS_PANE:15)
Block(-6,44,-4,STAINED_GLASS_PANE:15)
Block(-6,44,-3,STAINED_GLASS_PANE:15)
Block(-6,44,-2,STAINED_GLASS_PANE:15)
Block(-6,44,-1,STAINED_GLASS_PANE:15)
Block(-6,44,0,STAINED_GLASS_PANE:15)
Block(-6,44,1,STAINED_GLASS_PANE:15)
Block(-6,44,2,CONCRETE:8)
Block(-6,44,4,STAINED_GLASS:15)
Block(-6,44,5,IRON_TRAPDOOR:9)
Block(-6,44,6,CONCRETE:0)
Block(-6,44,7,IRON_TRAPDOOR:10)
Block(-6,44,8,STAINED_GLASS:15)
Block(-6,45,2,CONCRETE:8)
Block(-6,45,4,STAINED_GLASS:15)
Block(-6,45,5,CONCRETE:15)
Block(-6,45,6,CONCRETE:14)
Block(-6,45,7,STONE_BUTTON:3)
Block(-6,45,8,STAINED_GLASS:15)
Block(-6,46,2,CONCRETE:8)
Block(-6,46,4,STAINED_GLASS:15)
Block(-6,46,5,CONCRETE:15)
Block(-6,46,6,CONCRETE:14)
Block(-6,46,7,STONE_BUTTON:3)
Block(-6,46,8,STAINED_GLASS:15)
Block(-6,47,2,CONCRETE:8)
Block(-6,47,4,STAINED_GLASS:15)
Block(-6,47,5,CONCRETE:15)
Block(-6,47,6,CONCRETE:14)
Block(-6,47,7,STONE_BUTTON:3)
Block(-6,47,8,STAINED_GLASS:15)
Block(-6,48,2,CONCRETE:8)
Block(-6,48,4,STAINED_GLASS:15)
Block(-6,48,5,IRON_TRAPDOOR:2)
Block(-6,48,6,IRON_FENCE:0)
Block(-6,48,8,STAINED_GLASS:15)
Block(-6,49,2,CONCRETE:8)
Block(-6,49,4,STAINED_GLASS:15)
Block(-6,49,6,IRON_FENCE:0)
Block(-6,49,8,STAINED_GLASS:15)
Block(-6,50,2,CONCRETE:8)
Block(-6,50,4,STAINED_GLASS:15)
Block(-6,50,6,CONCRETE:0)
Block(-6,50,8,STAINED_GLASS:15)
Block(-6,51,-7,CONCRETE:8)
Block(-6,51,-6,CONCRETE:8)
Block(-6,51,-5,CONCRETE:8)
Block(-6,51,-4,CONCRETE:8)
Block(-6,51,-3,CONCRETE:8)
Block(-6,51,-2,CONCRETE:8)
Block(-6,51,-1,CONCRETE:8)
Block(-6,51,0,CONCRETE:8)
Block(-6,51,1,CONCRETE:8)
Block(-6,51,2,CONCRETE:8)
Block(-6,51,3,CONCRETE:8)
Block(-6,51,4,CONCRETE:8)
Block(-6,51,5,CONCRETE:8)
Block(-6,51,6,CONCRETE:8)
Block(-6,51,7,CONCRETE:8)
Block(-6,51,8,STAINED_GLASS:15)
Block(-6,52,-7,STAINED_GLASS_PANE:15)
Block(-6,52,-6,STAINED_GLASS_PANE:15)
Block(-6,52,-5,STAINED_GLASS_PANE:15)
Block(-6,52,-4,STAINED_GLASS_PANE:15)
Block(-6,52,-3,STAINED_GLASS_PANE:15)
Block(-6,52,-2,STAINED_GLASS_PANE:15)
Block(-6,52,-1,STAINED_GLASS_PANE:15)
Block(-6,52,0,STAINED_GLASS_PANE:15)
Block(-6,52,1,STAINED_GLASS_PANE:15)
Block(-6,52,2,CONCRETE:8)
Block(-6,52,4,STAINED_GLASS:15)
Block(-6,52,5,IRON_TRAPDOOR:9)
Block(-6,52,6,CONCRETE:0)
Block(-6,52,7,IRON_TRAPDOOR:10)
Block(-6,52,8,STAINED_GLASS:15)
Block(-6,53,2,CONCRETE:8)
Block(-6,53,4,STAINED_GLASS:15)
Block(-6,53,5,CONCRETE:15)
Block(-6,53,6,CONCRETE:14)
Block(-6,53,7,STONE_BUTTON:3)
Block(-6,53,8,STAINED_GLASS:15)
Block(-6,54,2,CONCRETE:8)
Block(-6,54,4,STAINED_GLASS:15)
Block(-6,54,5,CONCRETE:15)
Block(-6,54,6,CONCRETE:14)
Block(-6,54,7,STONE_BUTTON:3)
Block(-6,54,8,STAINED_GLASS:15)
Block(-6,55,2,CONCRETE:8)
Block(-6,55,4,STAINED_GLASS:15)
Block(-6,55,5,CONCRETE:15)
Block(-6,55,6,CONCRETE:14)
Block(-6,55,7,STONE_BUTTON:3)
Block(-6,55,8,STAINED_GLASS:15)
Block(-6,56,2,CONCRETE:8)
Block(-6,56,4,STAINED_GLASS:15)
Block(-6,56,5,IRON_TRAPDOOR:2)
Block(-6,56,6,IRON_FENCE:0)
Block(-6,56,8,STAINED_GLASS:15)
Block(-6,57,2,CONCRETE:8)
Block(-6,57,4,STAINED_GLASS:15)
Block(-6,57,6,IRON_FENCE:0)
Block(-6,57,8,STAINED_GLASS:15)
Block(-6,58,2,CONCRETE:8)
Block(-6,58,4,STAINED_GLASS:15)
Block(-6,58,6,CONCRETE:0)
Block(-6,58,8,STAINED_GLASS:15)
Block(-6,59,-7,CONCRETE:8)
Block(-6,59,-6,CONCRETE:8)
Block(-6,59,-5,CONCRETE:8)
Block(-6,59,-4,CONCRETE:8)
Block(-6,59,-3,CONCRETE:8)
Block(-6,59,-2,CONCRETE:8)
Block(-6,59,-1,CONCRETE:8)
Block(-6,59,0,CONCRETE:8)
Block(-6,59,1,CONCRETE:8)
Block(-6,59,2,CONCRETE:8)
Block(-6,59,3,CONCRETE:8)
Block(-6,59,4,CONCRETE:8)
Block(-6,59,5,CONCRETE:8)
Block(-6,59,6,CONCRETE:8)
Block(-6,59,7,CONCRETE:8)
Block(-6,59,8,STAINED_GLASS:15)
Block(-6,60,-7,STAINED_GLASS_PANE:15)
Block(-6,60,-6,STAINED_GLASS_PANE:15)
Block(-6,60,-5,STAINED_GLASS_PANE:15)
Block(-6,60,-4,STAINED_GLASS_PANE:15)
Block(-6,60,-3,STAINED_GLASS_PANE:15)
Block(-6,60,-2,STAINED_GLASS_PANE:15)
Block(-6,60,-1,STAINED_GLASS_PANE:15)
Block(-6,60,0,STAINED_GLASS_PANE:15)
Block(-6,60,1,STAINED_GLASS_PANE:15)
Block(-6,60,2,CONCRETE:8)
Block(-6,60,4,STAINED_GLASS:15)
Block(-6,60,5,IRON_TRAPDOOR:9)
Block(-6,60,6,CONCRETE:0)
Block(-6,60,7,IRON_TRAPDOOR:10)
Block(-6,60,8,STAINED_GLASS:15)
Block(-6,61,2,CONCRETE:8)
Block(-6,61,4,STAINED_GLASS:15)
Block(-6,61,5,CONCRETE:15)
Block(-6,61,6,CONCRETE:14)
Block(-6,61,7,STONE_BUTTON:3)
Block(-6,61,8,STAINED_GLASS:15)
Block(-6,62,2,CONCRETE:8)
Block(-6,62,4,STAINED_GLASS:15)
Block(-6,62,5,CONCRETE:15)
Block(-6,62,6,CONCRETE:14)
Block(-6,62,7,STONE_BUTTON:3)
Block(-6,62,8,STAINED_GLASS:15)
Block(-6,63,2,CONCRETE:8)
Block(-6,63,4,STAINED_GLASS:15)
Block(-6,63,5,CONCRETE:15)
Block(-6,63,6,CONCRETE:14)
Block(-6,63,7,STONE_BUTTON:3)
Block(-6,63,8,STAINED_GLASS:15)
Block(-6,64,2,CONCRETE:8)
Block(-6,64,4,STAINED_GLASS:15)
Block(-6,64,5,IRON_TRAPDOOR:2)
Block(-6,64,6,IRON_FENCE:0)
Block(-6,64,8,STAINED_GLASS:15)
Block(-6,65,2,CONCRETE:8)
Block(-6,65,4,STAINED_GLASS:15)
Block(-6,65,6,IRON_FENCE:0)
Block(-6,65,8,STAINED_GLASS:15)
Block(-6,66,2,CONCRETE:8)
Block(-6,66,4,STAINED_GLASS:15)
Block(-6,66,6,CONCRETE:0)
Block(-6,66,8,STAINED_GLASS:15)
Block(-6,67,-7,CONCRETE:8)
Block(-6,67,-6,CONCRETE:8)
Block(-6,67,-5,CONCRETE:8)
Block(-6,67,-4,CONCRETE:8)
Block(-6,67,-3,CONCRETE:8)
Block(-6,67,-2,CONCRETE:8)
Block(-6,67,-1,CONCRETE:8)
Block(-6,67,0,CONCRETE:8)
Block(-6,67,1,CONCRETE:8)
Block(-6,67,2,CONCRETE:8)
Block(-6,67,3,CONCRETE:8)
Block(-6,67,4,CONCRETE:8)
Block(-6,67,5,CONCRETE:8)
Block(-6,67,6,CONCRETE:8)
Block(-6,67,7,CONCRETE:8)
Block(-6,67,8,STAINED_GLASS:15)
Block(-6,68,-7,STAINED_GLASS_PANE:15)
Block(-6,68,-6,STAINED_GLASS_PANE:15)
Block(-6,68,-5,STAINED_GLASS_PANE:15)
Block(-6,68,-4,STAINED_GLASS_PANE:15)
Block(-6,68,-3,STAINED_GLASS_PANE:15)
Block(-6,68,-2,STAINED_GLASS_PANE:15)
Block(-6,68,-1,STAINED_GLASS_PANE:15)
Block(-6,68,0,STAINED_GLASS_PANE:15)
Block(-6,68,1,STAINED_GLASS_PANE:15)
Block(-6,68,2,CONCRETE:8)
Block(-6,68,4,STAINED_GLASS:15)
Block(-6,68,5,IRON_TRAPDOOR:9)
Block(-6,68,6,CONCRETE:0)
Block(-6,68,7,IRON_TRAPDOOR:10)
Block(-6,68,8,STAINED_GLASS:15)
Block(-6,69,2,CONCRETE:8)
Block(-6,69,4,STAINED_GLASS:15)
Block(-6,69,5,CONCRETE:15)
Block(-6,69,6,CONCRETE:14)
Block(-6,69,7,STONE_BUTTON:3)
Block(-6,69,8,STAINED_GLASS:15)
Block(-6,70,2,CONCRETE:8)
Block(-6,70,4,STAINED_GLASS:15)
Block(-6,70,5,CONCRETE:15)
Block(-6,70,6,CONCRETE:14)
Block(-6,70,7,STONE_BUTTON:3)
Block(-6,70,8,STAINED_GLASS:15)
Block(-6,71,2,CONCRETE:8)
Block(-6,71,4,STAINED_GLASS:15)
Block(-6,71,5,CONCRETE:15)
Block(-6,71,6,CONCRETE:14)
Block(-6,71,7,STONE_BUTTON:3)
Block(-6,71,8,STAINED_GLASS:15)
Block(-6,72,2,CONCRETE:8)
Block(-6,72,4,STAINED_GLASS:15)
Block(-6,72,5,IRON_TRAPDOOR:2)
Block(-6,72,6,IRON_FENCE:0)
Block(-6,72,8,STAINED_GLASS:15)
Block(-6,73,2,CONCRETE:8)
Block(-6,73,4,STAINED_GLASS:15)
Block(-6,73,6,IRON_FENCE:0)
Block(-6,73,8,STAINED_GLASS:15)
Block(-6,74,2,CONCRETE:8)
Block(-6,74,4,STAINED_GLASS:15)
Block(-6,74,6,CONCRETE:0)
Block(-6,74,8,STAINED_GLASS:15)
Block(-6,75,-7,CONCRETE:8)
Block(-6,75,-6,CONCRETE:8)
Block(-6,75,-5,CONCRETE:8)
Block(-6,75,-4,CONCRETE:8)
Block(-6,75,-3,CONCRETE:8)
Block(-6,75,-2,CONCRETE:8)
Block(-6,75,-1,CONCRETE:8)
Block(-6,75,0,CONCRETE:8)
Block(-6,75,1,CONCRETE:8)
Block(-6,75,2,CONCRETE:8)
Block(-6,75,3,CONCRETE:8)
Block(-6,75,4,CONCRETE:8)
Block(-6,75,5,CONCRETE:8)
Block(-6,75,6,CONCRETE:8)
Block(-6,75,7,CONCRETE:8)
Block(-6,75,8,STAINED_GLASS:15)
Block(-6,76,-7,STAINED_GLASS_PANE:15)
Block(-6,76,-6,STAINED_GLASS_PANE:15)
Block(-6,76,-5,STAINED_GLASS_PANE:15)
Block(-6,76,-4,STAINED_GLASS_PANE:15)
Block(-6,76,-3,STAINED_GLASS_PANE:15)
Block(-6,76,-2,STAINED_GLASS_PANE:15)
Block(-6,76,-1,STAINED_GLASS_PANE:15)
Block(-6,76,0,STAINED_GLASS_PANE:15)
Block(-6,76,8,STAINED_GLASS:15)
Block(-6,77,8,STAINED_GLASS:15)
Block(-6,78,2,CONCRETE:8)
Block(-6,78,8,CONCRETE:8)
Block(-6,79,2,CONCRETE:8)
Block(-6,79,3,CONCRETE:8)
Block(-6,79,4,CONCRETE:8)
Block(-6,79,5,CONCRETE:8)
Block(-6,79,6,CONCRETE:8)
Block(-6,79,7,CONCRETE:8)
Block(-6,79,8,CONCRETE:8)
Block(-6,80,2,CONCRETE:8)
Block(-6,80,3,CONCRETE:8)
Block(-6,80,4,CONCRETE:8)
Block(-6,80,5,CONCRETE:8)
Block(-6,80,6,CONCRETE:8)
Block(-6,80,7,CONCRETE:8)
Block(-6,80,8,CONCRETE:8)
Block(-6,81,2,STAINED_GLASS:15)
Block(-6,82,2,STAINED_GLASS:15)
Block(-6,83,-7,CONCRETE:8)
Block(-6,83,-6,CONCRETE:8)
Block(-6,83,-5,CONCRETE:8)
Block(-6,83,-4,CONCRETE:8)
Block(-6,83,-3,CONCRETE:8)
Block(-6,83,-2,CONCRETE:8)
Block(-6,83,-1,CONCRETE:8)
Block(-6,83,0,CONCRETE:8)
Block(-6,83,1,CONCRETE:8)
Block(-6,83,2,STAINED_GLASS:15)
Block(-6,84,-7,STAINED_GLASS_PANE:15)
Block(-6,84,-6,STAINED_GLASS_PANE:15)
Block(-6,84,-5,STAINED_GLASS_PANE:15)
Block(-6,84,-4,STAINED_GLASS_PANE:15)
Block(-6,84,-3,STAINED_GLASS_PANE:15)
Block(-6,84,-2,STAINED_GLASS_PANE:15)
Block(-6,84,-1,STAINED_GLASS_PANE:15)
Block(-6,84,0,STAINED_GLASS_PANE:15)
Block(-6,84,2,STAINED_GLASS:15)
Block(-6,85,2,STAINED_GLASS:15)
Block(-6,86,2,STAINED_GLASS:15)
Block(-6,87,2,STAINED_GLASS:15)
Block(-6,88,2,STAINED_GLASS:15)
Block(-6,89,2,STAINED_GLASS:15)
Block(-6,90,2,STAINED_GLASS:15)
Block(-6,91,-7,CONCRETE:8)
Block(-6,91,-6,CONCRETE:8)
Block(-6,91,-5,CONCRETE:8)
Block(-6,91,-4,CONCRETE:8)
Block(-6,91,-3,CONCRETE:8)
Block(-6,91,-2,CONCRETE:8)
Block(-6,91,-1,CONCRETE:8)
Block(-6,91,0,CONCRETE:8)
Block(-6,91,1,CONCRETE:8)
Block(-6,91,2,STAINED_GLASS:15)
Block(-6,92,-7,STAINED_GLASS_PANE:15)
Block(-6,92,-6,STAINED_GLASS_PANE:15)
Block(-6,92,-5,STAINED_GLASS_PANE:15)
Block(-6,92,-4,STAINED_GLASS_PANE:15)
Block(-6,92,-3,STAINED_GLASS_PANE:15)
Block(-6,92,-2,STAINED_GLASS_PANE:15)
Block(-6,92,-1,STAINED_GLASS_PANE:15)
Block(-6,92,0,STAINED_GLASS_PANE:15)
Block(-6,92,2,STAINED_GLASS:15)
Block(-6,93,2,STAINED_GLASS:15)
Block(-6,94,2,STAINED_GLASS:15)
Block(-6,95,-2,CONCRETE:15)
Block(-6,95,2,CONCRETE:15)
Block(-6,96,-2,CONCRETE:15)
Block(-6,96,-1,CONCRETE:15)
Block(-6,96,0,CONCRETE:15)
Block(-6,96,1,CONCRETE:15)
Block(-6,96,2,CONCRETE:15)
Block(-6,97,-2,CONCRETE:15)
Block(-6,97,-1,CONCRETE:15)
Block(-6,97,0,CONCRETE:15)
Block(-6,97,1,CONCRETE:15)
Block(-6,97,2,CONCRETE:15)
Block(-6,98,-2,STAINED_GLASS:15)
Block(-6,99,-7,CONCRETE:8)
Block(-6,99,-6,CONCRETE:8)
Block(-6,99,-5,CONCRETE:8)
Block(-6,99,-4,CONCRETE:8)
Block(-6,99,-3,CONCRETE:8)
Block(-6,99,-2,STAINED_GLASS:15)
Block(-6,100,-2,STAINED_GLASS:15)
Block(-6,101,-2,STAINED_GLASS:15)
Block(-6,102,-2,STAINED_GLASS:15)
Block(-6,103,-2,STAINED_GLASS:15)
Block(-6,104,-2,STAINED_GLASS:15)
Block(-6,105,-2,STAINED_GLASS:15)
Block(-6,106,-2,STAINED_GLASS:15)
Block(-6,107,-7,CONCRETE:8)
Block(-6,107,-6,CONCRETE:8)
Block(-6,107,-5,CONCRETE:8)
Block(-6,107,-4,CONCRETE:8)
Block(-6,107,-3,CONCRETE:8)
Block(-6,107,-2,STAINED_GLASS:15)
Block(-6,108,-2,STAINED_GLASS:15)
Block(-6,109,-2,STAINED_GLASS:15)
Block(-6,110,-2,STAINED_GLASS:15)
Block(-6,111,-2,STAINED_GLASS:15)
Block(-6,112,-2,STAINED_GLASS:15)
Block(-6,113,-2,STAINED_GLASS:15)
Block(-6,114,-2,STAINED_GLASS:15)
Block(-6,115,-7,CONCRETE:8)
Block(-6,115,-6,CONCRETE:8)
Block(-6,115,-5,CONCRETE:8)
Block(-6,115,-4,CONCRETE:8)
Block(-6,115,-3,CONCRETE:8)
Block(-6,115,-2,STAINED_GLASS:15)
Block(-6,116,-2,STAINED_GLASS:15)
Block(-6,117,-2,STAINED_GLASS:15)
Block(-6,118,-2,STAINED_GLASS:15)
Block(-6,119,-2,STAINED_GLASS:15)
Block(-6,120,-3,TRIPWIRE_HOOK:5)
Block(-6,120,-2,STAINED_GLASS:15)
Block(-6,121,-2,STAINED_GLASS:15)
Block(-6,122,-7,IRON_TRAPDOOR:10)
Block(-6,122,-6,IRON_TRAPDOOR:10)
Block(-6,122,-5,IRON_TRAPDOOR:10)
Block(-6,122,-4,IRON_TRAPDOOR:10)
Block(-6,122,-3,IRON_TRAPDOOR:10)
Block(-6,122,-2,STAINED_GLASS:15)
Block(-6,123,-7,CONCRETE:8)
Block(-6,123,-6,CONCRETE:8)
Block(-6,123,-5,CONCRETE:8)
Block(-6,123,-4,CONCRETE:8)
Block(-6,123,-3,CONCRETE:14)
Block(-6,123,-2,STAINED_GLASS:15)
Block(-6,124,-5,STAINED_GLASS_PANE:15)
Block(-6,124,-4,CONCRETE:15)
Block(-6,124,-3,CONCRETE:14)
Block(-6,124,-2,STAINED_GLASS:15)
Block(-6,125,-4,CONCRETE:15)
Block(-6,125,-3,IRON_FENCE:0)
Block(-6,125,-2,STAINED_GLASS:15)
Block(-6,126,-4,CONCRETE:15)
Block(-6,126,-3,IRON_FENCE:0)
Block(-6,126,-2,STAINED_GLASS:15)
Block(-6,127,-7,IRON_TRAPDOOR:10)
Block(-6,127,-6,IRON_TRAPDOOR:10)
Block(-6,127,-5,IRON_TRAPDOOR:10)
Block(-6,127,-4,CONCRETE:15)
Block(-6,127,-3,IRON_FENCE:0)
Block(-6,127,-2,STAINED_GLASS:15)
Block(-6,128,-7,STAINED_GLASS_PANE:15)
Block(-6,128,-4,CONCRETE:15)
Block(-6,128,-3,IRON_FENCE:0)
Block(-6,128,-2,STAINED_GLASS:15)
Block(-6,129,-4,CONCRETE:15)
Block(-6,129,-3,CONCRETE:14)
Block(-6,129,-2,STAINED_GLASS:15)
Block(-6,130,-5,IRON_TRAPDOOR:8)
Block(-6,130,-4,CONCRETE:15)
Block(-6,130,-3,STEP:0)
Block(-6,130,-2,STAINED_GLASS:15)
Block(-6,131,-5,CONCRETE:8)
Block(-6,131,-4,CONCRETE:15)
Block(-6,131,-3,IRON_TRAPDOOR:9)
Block(-6,131,-2,STAINED_GLASS:15)
Block(-6,132,-5,STAINED_GLASS_PANE:15)
Block(-6,132,-4,CONCRETE:15)
Block(-6,132,-2,STAINED_GLASS:15)
Block(-6,133,-2,STAINED_GLASS:15)
Block(-6,134,-2,CONCRETE:8)
Block(-6,135,-7,CONCRETE:8)
Block(-6,135,-6,CONCRETE:8)
Block(-6,135,-5,CONCRETE:8)
Block(-6,135,-4,CONCRETE:8)
Block(-6,135,-3,CONCRETE:8)
Block(-6,135,-2,CONCRETE:8)
Block(-6,136,-7,CONCRETE:8)
Block(-6,136,-6,CONCRETE:8)
Block(-6,136,-5,CONCRETE:8)
Block(-6,136,-4,CONCRETE:8)
Block(-6,136,-3,CONCRETE:8)
Block(-6,136,-2,CONCRETE:8)
Block(-5,0,-7,CONCRETE:7)
Block(-5,0,-6,CONCRETE:7)
Block(-5,0,-5,CONCRETE:7)
Block(-5,0,-4,CONCRETE:7)
Block(-5,0,-3,CONCRETE:7)
Block(-5,0,-2,CONCRETE:7)
Block(-5,0,-1,CONCRETE:7)
Block(-5,0,0,CONCRETE:7)
Block(-5,0,1,CONCRETE:7)
Block(-5,0,2,CONCRETE:7)
Block(-5,0,3,CONCRETE:7)
Block(-5,0,4,CONCRETE:7)
Block(-5,0,5,CONCRETE:7)
Block(-5,0,6,CONCRETE:7)
Block(-5,0,7,CONCRETE:7)
Block(-5,0,8,CONCRETE:7)
Block(-5,1,-7,STATIONARY_WATER:0)
Block(-5,1,-6,STATIONARY_WATER:0)
Block(-5,1,-5,STATIONARY_WATER:0)
Block(-5,1,-4,STATIONARY_WATER:0)
Block(-5,1,-3,STATIONARY_WATER:0)
Block(-5,1,-2,STATIONARY_WATER:0)
Block(-5,1,-1,STATIONARY_WATER:0)
Block(-5,1,0,STATIONARY_WATER:0)
Block(-5,1,1,STATIONARY_WATER:0)
Block(-5,1,2,CONCRETE:7)
Block(-5,1,3,CONCRETE:7)
Block(-5,1,4,CONCRETE:7)
Block(-5,1,5,CONCRETE:7)
Block(-5,1,6,CONCRETE:7)
Block(-5,1,7,CONCRETE:7)
Block(-5,1,8,CONCRETE:7)
Block(-5,2,-7,AIR:0)
Block(-5,2,-6,AIR:0)
Block(-5,2,-5,AIR:0)
Block(-5,2,-4,AIR:0)
Block(-5,2,-3,AIR:0)
Block(-5,2,-2,AIR:0)
Block(-5,2,-1,AIR:0)
Block(-5,2,0,AIR:0)
Block(-5,2,1,AIR:0)
Block(-5,2,2,CONCRETE:7)
Block(-5,2,3,SMOOTH_STAIRS:1)
Block(-5,2,4,SMOOTH_STAIRS:1)
Block(-5,2,5,SMOOTH_STAIRS:1)
Block(-5,2,6,SMOOTH_STAIRS:1)
Block(-5,2,7,SMOOTH_STAIRS:1)
Block(-5,2,8,SMOOTH_STAIRS:1)
Block(-5,3,-7,AIR:0)
Block(-5,3,-6,AIR:0)
Block(-5,3,-5,AIR:0)
Block(-5,3,-4,AIR:0)
Block(-5,3,-3,AIR:0)
Block(-5,3,-2,AIR:0)
Block(-5,3,-1,AIR:0)
Block(-5,3,0,AIR:0)
Block(-5,3,1,AIR:0)
Block(-5,3,2,CONCRETE:7)
Block(-5,3,3,AIR:0)
Block(-5,3,4,AIR:0)
Block(-5,3,5,AIR:0)
Block(-5,3,6,AIR:0)
Block(-5,3,7,AIR:0)
Block(-5,3,8,AIR:0)
Block(-5,4,-7,AIR:0)
Block(-5,4,-6,AIR:0)
Block(-5,4,-5,AIR:0)
Block(-5,4,-4,AIR:0)
Block(-5,4,-3,AIR:0)
Block(-5,4,-2,AIR:0)
Block(-5,4,-1,AIR:0)
Block(-5,4,0,AIR:0)
Block(-5,4,1,AIR:0)
Block(-5,4,2,CONCRETE:7)
Block(-5,4,3,STEP:8)
Block(-5,4,4,CONCRETE:7)
Block(-5,4,5,STEP:8)
Block(-5,4,6,STEP:8)
Block(-5,4,7,CONCRETE:7)
Block(-5,4,8,STEP:8)
Block(-5,5,-7,CONCRETE:14)
Block(-5,5,-6,CONCRETE:11)
Block(-5,5,-5,AIR:0)
Block(-5,5,-4,AIR:0)
Block(-5,5,-3,AIR:0)
Block(-5,5,-2,AIR:0)
Block(-5,5,-1,AIR:0)
Block(-5,5,0,AIR:0)
Block(-5,5,1,AIR:0)
Block(-5,5,2,CONCRETE:7)
Block(-5,5,3,CONCRETE:7)
Block(-5,5,4,CONCRETE:7)
Block(-5,5,5,CONCRETE:7)
Block(-5,5,6,CONCRETE:7)
Block(-5,5,7,CONCRETE:7)
Block(-5,5,8,CONCRETE:7)
Block(-5,6,-7,IRON_FENCE:0)
Block(-5,6,-6,AIR:0)
Block(-5,6,-5,AIR:0)
Block(-5,6,-4,AIR:0)
Block(-5,6,-3,AIR:0)
Block(-5,6,-2,AIR:0)
Block(-5,6,-1,AIR:0)
Block(-5,6,0,AIR:0)
Block(-5,6,1,AIR:0)
Block(-5,6,2,CONCRETE:7)
Block(-5,6,3,CONCRETE:7)
Block(-5,6,4,CONCRETE:7)
Block(-5,6,5,CONCRETE:7)
Block(-5,6,6,CONCRETE:7)
Block(-5,6,7,CONCRETE:7)
Block(-5,6,8,CONCRETE:7)
Block(-5,7,-7,CONCRETE:7)
Block(-5,7,-6,CONCRETE:7)
Block(-5,7,-5,CONCRETE:7)
Block(-5,7,-4,CONCRETE:7)
Block(-5,7,-3,CONCRETE:7)
Block(-5,7,-2,CONCRETE:7)
Block(-5,7,-1,CONCRETE:7)
Block(-5,7,0,CONCRETE:7)
Block(-5,7,1,CONCRETE:7)
Block(-5,7,2,CONCRETE:7)
Block(-5,7,3,CONCRETE:7)
Block(-5,7,4,CONCRETE:7)
Block(-5,7,5,CONCRETE:7)
Block(-5,7,6,CONCRETE:7)
Block(-5,7,7,CONCRETE:7)
Block(-5,7,8,CONCRETE:7)
Block(-5,8,-7,CONCRETE:7)
Block(-5,8,-6,CONCRETE:7)
Block(-5,8,-5,CONCRETE:7)
Block(-5,8,-4,CONCRETE:7)
Block(-5,8,-3,CONCRETE:7)
Block(-5,8,-2,CONCRETE:7)
Block(-5,8,-1,CONCRETE:7)
Block(-5,8,0,CONCRETE:7)
Block(-5,8,1,AIR:0)
Block(-5,8,2,AIR:0)
Block(-5,8,3,QUARTZ_STAIRS:2)
Block(-5,8,4,CONCRETE:15)
Block(-5,8,5,CONCRETE:15)
Block(-5,8,6,CONCRETE:15)
Block(-5,8,7,CONCRETE:15)
Block(-5,8,8,CONCRETE:7)
Block(-5,9,-7,CONCRETE:7)
Block(-5,9,-6,CONCRETE:7)
Block(-5,9,-5,CONCRETE:7)
Block(-5,9,-4,CONCRETE:7)
Block(-5,9,-3,CONCRETE:7)
Block(-5,9,-2,CONCRETE:7)
Block(-5,9,-1,CONCRETE:7)
Block(-5,9,0,CONCRETE:7)
Block(-5,9,1,AIR:0)
Block(-5,9,2,AIR:0)
Block(-5,9,3,DROPPER:2,NBT/skyscraper_2x2_04/352-dropperC16R16.nbt)
Block(-5,9,4,CONCRETE:4)
Block(-5,9,5,CONCRETE:4)
Block(-5,9,6,CONCRETE:4)
Block(-5,9,7,CONCRETE:4)
Block(-5,9,8,CONCRETE:7)
Block(-5,10,-7,AIR:0)
Block(-5,10,-6,AIR:0)
Block(-5,10,-5,AIR:0)
Block(-5,10,-4,AIR:0)
Block(-5,10,-3,AIR:0)
Block(-5,10,-2,AIR:0)
Block(-5,10,-1,CONCRETE:7)
Block(-5,10,0,CONCRETE:7)
Block(-5,10,1,AIR:0)
Block(-5,10,2,AIR:0)
Block(-5,10,3,REDSTONE_LAMP_OFF:0)
Block(-5,10,4,CONCRETE:15)
Block(-5,10,5,QUARTZ_STAIRS:0)
Block(-5,10,6,DROPPER:5,NBT/skyscraper_2x2_04/353-dropperC16R16.nbt)
Block(-5,10,7,QUARTZ_STAIRS:0)
Block(-5,10,8,CONCRETE:7)
Block(-5,11,-7,AIR:0)
Block(-5,11,-6,AIR:0)
Block(-5,11,-5,AIR:0)
Block(-5,11,-4,AIR:0)
Block(-5,11,-3,AIR:0)
Block(-5,11,-2,AIR:0)
Block(-5,11,-1,CONCRETE:7)
Block(-5,11,0,CONCRETE:7)
Block(-5,11,1,AIR:0)
Block(-5,11,2,AIR:0)
Block(-5,11,3,IRON_TRAPDOOR:0)
Block(-5,11,4,IRON_TRAPDOOR:1)
Block(-5,11,5,IRON_TRAPDOOR:2)
Block(-5,11,6,IRON_TRAPDOOR:2)
Block(-5,11,7,IRON_TRAPDOOR:2)
Block(-5,11,8,CONCRETE:7)
Block(-5,12,-7,AIR:0)
Block(-5,12,-6,AIR:0)
Block(-5,12,-5,AIR:0)
Block(-5,12,-4,AIR:0)
Block(-5,12,-3,CONCRETE:4)
Block(-5,12,-2,AIR:0)
Block(-5,12,-1,CONCRETE:7)
Block(-5,12,0,CONCRETE:7)
Block(-5,12,1,AIR:0)
Block(-5,12,2,AIR:0)
Block(-5,12,3,AIR:0)
Block(-5,12,4,AIR:0)
Block(-5,12,5,AIR:0)
Block(-5,12,6,AIR:0)
Block(-5,12,7,AIR:0)
Block(-5,12,8,CONCRETE:7)
Block(-5,13,-7,AIR:0)
Block(-5,13,-6,AIR:0)
Block(-5,13,-5,AIR:0)
Block(-5,13,-4,AIR:0)
Block(-5,13,-3,AIR:0)
Block(-5,13,-2,AIR:0)
Block(-5,13,-1,CONCRETE:7)
Block(-5,13,0,CONCRETE:7)
Block(-5,13,1,AIR:0)
Block(-5,13,2,AIR:0)
Block(-5,13,3,AIR:0)
Block(-5,13,4,AIR:0)
Block(-5,13,5,AIR:0)
Block(-5,13,6,AIR:0)
Block(-5,13,7,AIR:0)
Block(-5,13,8,CONCRETE:7)
Block(-5,14,-7,CONCRETE:7)
Block(-5,14,-6,AIR:0)
Block(-5,14,-5,CONCRETE:7)
Block(-5,14,-4,AIR:0)
Block(-5,14,-3,CONCRETE:7)
Block(-5,14,-2,AIR:0)
Block(-5,14,-1,CONCRETE:7)
Block(-5,14,0,CONCRETE:7)
Block(-5,14,1,CONCRETE:7)
Block(-5,14,2,CONCRETE:7)
Block(-5,14,3,CONCRETE:7)
Block(-5,14,4,CONCRETE:7)
Block(-5,14,5,CONCRETE:7)
Block(-5,14,6,CONCRETE:7)
Block(-5,14,7,CONCRETE:7)
Block(-5,14,8,CONCRETE:7)
Block(-5,15,-7,AIR:0)
Block(-5,15,-6,AIR:0)
Block(-5,15,-5,AIR:0)
Block(-5,15,-4,AIR:0)
Block(-5,15,-3,AIR:0)
Block(-5,15,-2,AIR:0)
Block(-5,15,-1,CONCRETE:7)
Block(-5,15,0,CONCRETE:7)
Block(-5,15,1,CONCRETE:7)
Block(-5,15,2,CONCRETE:7)
Block(-5,15,3,CONCRETE:7)
Block(-5,15,4,CONCRETE:7)
Block(-5,15,5,CONCRETE:7)
Block(-5,15,6,CONCRETE:7)
Block(-5,15,7,CONCRETE:7)
Block(-5,15,8,CONCRETE:7)
Block(-5,16,-7,CONCRETE:7)
Block(-5,16,-6,CONCRETE:7)
Block(-5,16,-5,CONCRETE:7)
Block(-5,16,-4,CONCRETE:7)
Block(-5,16,-3,CONCRETE:7)
Block(-5,16,-2,CONCRETE:7)
Block(-5,16,-1,CONCRETE:7)
Block(-5,16,0,CONCRETE:7)
Block(-5,16,1,CONCRETE:7)
Block(-5,16,2,CONCRETE:7)
Block(-5,16,3,CONCRETE:7)
Block(-5,16,4,CONCRETE:7)
Block(-5,16,5,CONCRETE:7)
Block(-5,16,6,CONCRETE:7)
Block(-5,16,7,CONCRETE:7)
Block(-5,16,8,CONCRETE:7)
Block(-5,17,-7,CONCRETE:7)
Block(-5,17,-6,CONCRETE:7)
Block(-5,17,-5,CONCRETE:7)
Block(-5,17,-4,CONCRETE:7)
Block(-5,17,-3,CONCRETE:7)
Block(-5,17,-2,CONCRETE:7)
Block(-5,17,-1,CONCRETE:7)
Block(-5,17,0,CONCRETE:7)
Block(-5,17,1,CONCRETE:7)
Block(-5,17,2,CONCRETE:7)
Block(-5,17,3,CONCRETE:7)
Block(-5,17,4,CONCRETE:7)
Block(-5,17,5,CONCRETE:7)
Block(-5,17,6,CONCRETE:7)
Block(-5,17,7,CONCRETE:7)
Block(-5,17,8,CONCRETE:7)
Block(-5,18,-7,CONCRETE:8)
Block(-5,18,-6,CONCRETE:8)
Block(-5,18,-5,CONCRETE:8)
Block(-5,18,-4,CONCRETE:8)
Block(-5,18,-3,CONCRETE:8)
Block(-5,18,-2,CONCRETE:15)
Block(-5,18,-1,CONCRETE:15)
Block(-5,18,0,CONCRETE:15)
Block(-5,18,1,CONCRETE:15)
Block(-5,18,2,CONCRETE:15)
Block(-5,18,3,CONCRETE:8)
Block(-5,18,4,CONCRETE:8)
Block(-5,18,5,CONCRETE:8)
Block(-5,18,6,CONCRETE:8)
Block(-5,18,7,CONCRETE:8)
Block(-5,18,8,CONCRETE:8)
Block(-5,19,-7,CONCRETE:8)
Block(-5,19,-4,CONCRETE:8)
Block(-5,19,-2,SMOOTH_STAIRS:2)
Block(-5,19,-1,SMOOTH_STAIRS:7)
Block(-5,19,2,CONCRETE:8)
Block(-5,19,3,CONCRETE:8)
Block(-5,19,4,CONCRETE:8)
Block(-5,19,5,CONCRETE:8)
Block(-5,19,6,CONCRETE:8)
Block(-5,19,8,STAINED_GLASS:15)
Block(-5,20,-7,CONCRETE:8)
Block(-5,20,-6,STONE_BUTTON:3)
Block(-5,20,-5,STONE_BUTTON:4)
Block(-5,20,-4,CONCRETE:8)
Block(-5,20,-1,SMOOTH_STAIRS:2)
Block(-5,20,0,SMOOTH_STAIRS:7)
Block(-5,20,1,STONE_BUTTON:4)
Block(-5,20,2,CONCRETE:8)
Block(-5,20,3,CONCRETE:8)
Block(-5,20,4,IRON_TRAPDOOR:3)
Block(-5,20,5,IRON_TRAPDOOR:3)
Block(-5,20,6,CONCRETE:8)
Block(-5,20,8,STAINED_GLASS:15)
Block(-5,21,-7,CONCRETE:8)
Block(-5,21,-6,STAINED_GLASS:15)
Block(-5,21,-5,STAINED_GLASS:15)
Block(-5,21,-4,CONCRETE:8)
Block(-5,21,0,SMOOTH_STAIRS:2)
Block(-5,21,1,SMOOTH_STAIRS:7)
Block(-5,21,2,CONCRETE:8)
Block(-5,21,3,CONCRETE:8)
Block(-5,21,4,STAINED_GLASS_PANE:15)
Block(-5,21,5,STAINED_GLASS_PANE:15)
Block(-5,21,6,CONCRETE:8)
Block(-5,21,8,STAINED_GLASS:15)
Block(-5,22,-7,CONCRETE:8)
Block(-5,22,-6,STAINED_GLASS:15)
Block(-5,22,-5,STAINED_GLASS:15)
Block(-5,22,-4,CONCRETE:8)
Block(-5,22,2,CONCRETE:8)
Block(-5,22,3,CONCRETE:8)
Block(-5,22,4,CONCRETE:8)
Block(-5,22,5,CONCRETE:8)
Block(-5,22,6,CONCRETE:8)
Block(-5,22,8,STAINED_GLASS:15)
Block(-5,23,-7,CONCRETE:8)
Block(-5,23,-6,STAINED_GLASS:15)
Block(-5,23,-5,STAINED_GLASS:15)
Block(-5,23,-4,CONCRETE:8)
Block(-5,23,2,CONCRETE:8)
Block(-5,23,3,CONCRETE:8)
Block(-5,23,4,STAINED_GLASS_PANE:15)
Block(-5,23,5,STAINED_GLASS_PANE:15)
Block(-5,23,6,CONCRETE:8)
Block(-5,23,8,STAINED_GLASS:15)
Block(-5,24,-7,CONCRETE:8)
Block(-5,24,-6,STAINED_GLASS:15)
Block(-5,24,-5,STAINED_GLASS:15)
Block(-5,24,-4,CONCRETE:8)
Block(-5,24,2,CONCRETE:8)
Block(-5,24,3,CONCRETE:8)
Block(-5,24,4,STAINED_GLASS_PANE:15)
Block(-5,24,5,STAINED_GLASS_PANE:15)
Block(-5,24,6,CONCRETE:8)
Block(-5,24,8,STAINED_GLASS:15)
Block(-5,25,-7,CONCRETE:8)
Block(-5,25,-6,STAINED_GLASS:15)
Block(-5,25,-5,STAINED_GLASS:15)
Block(-5,25,-4,CONCRETE:8)
Block(-5,25,2,CONCRETE:8)
Block(-5,25,3,CONCRETE:8)
Block(-5,25,4,CONCRETE:8)
Block(-5,25,5,CONCRETE:8)
Block(-5,25,6,CONCRETE:8)
Block(-5,25,8,STAINED_GLASS:15)
Block(-5,26,-7,CONCRETE:8)
Block(-5,26,-6,STAINED_GLASS:15)
Block(-5,26,-5,STAINED_GLASS:15)
Block(-5,26,-4,CONCRETE:8)
Block(-5,26,2,CONCRETE:8)
Block(-5,26,3,CONCRETE:8)
Block(-5,26,4,CONCRETE:8)
Block(-5,26,5,CONCRETE:8)
Block(-5,26,6,CONCRETE:8)
Block(-5,26,8,STAINED_GLASS:15)
Block(-5,27,-7,CONCRETE:8)
Block(-5,27,-6,CONCRETE:8)
Block(-5,27,-5,CONCRETE:8)
Block(-5,27,-4,CONCRETE:8)
Block(-5,27,-3,CONCRETE:8)
Block(-5,27,-2,CONCRETE:8)
Block(-5,27,-1,CONCRETE:8)
Block(-5,27,0,CONCRETE:8)
Block(-5,27,1,CONCRETE:8)
Block(-5,27,2,CONCRETE:8)
Block(-5,27,3,CONCRETE:8)
Block(-5,27,4,CONCRETE:8)
Block(-5,27,5,CONCRETE:8)
Block(-5,27,6,CONCRETE:8)
Block(-5,27,7,CONCRETE:8)
Block(-5,27,8,STAINED_GLASS:15)
Block(-5,28,4,STAINED_GLASS:15)
Block(-5,28,5,IRON_TRAPDOOR:9)
Block(-5,28,6,CONCRETE:0)
Block(-5,28,7,IRON_TRAPDOOR:10)
Block(-5,28,8,STAINED_GLASS:15)
Block(-5,29,4,STAINED_GLASS:15)
Block(-5,29,5,CONCRETE:15)
Block(-5,29,6,CONCRETE:15)
Block(-5,29,8,STAINED_GLASS:15)
Block(-5,30,4,STAINED_GLASS:15)
Block(-5,30,5,CONCRETE:15)
Block(-5,30,6,CONCRETE:15)
Block(-5,30,7,WALL_BANNER:3,NBT/skyscraper_2x2_04/368-bannerC16R16.nbt)
Block(-5,30,8,STAINED_GLASS:15)
Block(-5,31,4,STAINED_GLASS:15)
Block(-5,31,5,CONCRETE:15)
Block(-5,31,6,REDSTONE_LAMP_OFF:0)
Block(-5,31,8,STAINED_GLASS:15)
Block(-5,32,4,STAINED_GLASS:15)
Block(-5,32,5,IRON_TRAPDOOR:1)
Block(-5,32,6,IRON_TRAPDOOR:1)
Block(-5,32,8,STAINED_GLASS:15)
Block(-5,33,4,STAINED_GLASS:15)
Block(-5,33,8,STAINED_GLASS:15)
Block(-5,34,4,STAINED_GLASS:15)
Block(-5,34,6,CONCRETE:0)
Block(-5,34,8,STAINED_GLASS:15)
Block(-5,35,-7,CONCRETE:8)
Block(-5,35,-6,CONCRETE:8)
Block(-5,35,-5,CONCRETE:8)
Block(-5,35,-4,CONCRETE:8)
Block(-5,35,-3,CONCRETE:8)
Block(-5,35,-2,CONCRETE:8)
Block(-5,35,-1,CONCRETE:8)
Block(-5,35,0,CONCRETE:8)
Block(-5,35,1,CONCRETE:8)
Block(-5,35,2,CONCRETE:8)
Block(-5,35,3,CONCRETE:8)
Block(-5,35,4,CONCRETE:8)
Block(-5,35,5,CONCRETE:8)
Block(-5,35,6,CONCRETE:8)
Block(-5,35,7,CONCRETE:8)
Block(-5,35,8,STAINED_GLASS:15)
Block(-5,36,4,STAINED_GLASS:15)
Block(-5,36,5,IRON_TRAPDOOR:9)
Block(-5,36,6,CONCRETE:0)
Block(-5,36,7,IRON_TRAPDOOR:10)
Block(-5,36,8,STAINED_GLASS:15)
Block(-5,37,4,STAINED_GLASS:15)
Block(-5,37,5,CONCRETE:15)
Block(-5,37,6,CONCRETE:15)
Block(-5,37,8,STAINED_GLASS:15)
Block(-5,38,4,STAINED_GLASS:15)
Block(-5,38,5,CONCRETE:15)
Block(-5,38,6,CONCRETE:15)
Block(-5,38,7,WALL_BANNER:3,NBT/skyscraper_2x2_04/369-bannerC16R16.nbt)
Block(-5,38,8,STAINED_GLASS:15)
Block(-5,39,4,STAINED_GLASS:15)
Block(-5,39,5,CONCRETE:15)
Block(-5,39,6,REDSTONE_LAMP_OFF:0)
Block(-5,39,8,STAINED_GLASS:15)
Block(-5,40,4,STAINED_GLASS:15)
Block(-5,40,5,IRON_TRAPDOOR:1)
Block(-5,40,6,IRON_TRAPDOOR:1)
Block(-5,40,8,STAINED_GLASS:15)
Block(-5,41,4,STAINED_GLASS:15)
Block(-5,41,8,STAINED_GLASS:15)
Block(-5,42,4,STAINED_GLASS:15)
Block(-5,42,6,CONCRETE:0)
Block(-5,42,8,STAINED_GLASS:15)
Block(-5,43,-7,CONCRETE:8)
Block(-5,43,-6,CONCRETE:8)
Block(-5,43,-5,CONCRETE:8)
Block(-5,43,-4,CONCRETE:8)
Block(-5,43,-3,CONCRETE:8)
Block(-5,43,-2,CONCRETE:8)
Block(-5,43,-1,CONCRETE:8)
Block(-5,43,0,CONCRETE:8)
Block(-5,43,1,CONCRETE:8)
Block(-5,43,2,CONCRETE:8)
Block(-5,43,3,CONCRETE:8)
Block(-5,43,4,CONCRETE:8)
Block(-5,43,5,CONCRETE:8)
Block(-5,43,6,CONCRETE:8)
Block(-5,43,7,CONCRETE:8)
Block(-5,43,8,STAINED_GLASS:15)
Block(-5,44,4,STAINED_GLASS:15)
Block(-5,44,5,IRON_TRAPDOOR:9)
Block(-5,44,6,CONCRETE:0)
Block(-5,44,7,IRON_TRAPDOOR:10)
Block(-5,44,8,STAINED_GLASS:15)
Block(-5,45,4,STAINED_GLASS:15)
Block(-5,45,5,CONCRETE:15)
Block(-5,45,6,CONCRETE:15)
Block(-5,45,8,STAINED_GLASS:15)
Block(-5,46,4,STAINED_GLASS:15)
Block(-5,46,5,CONCRETE:15)
Block(-5,46,6,CONCRETE:15)
Block(-5,46,7,WALL_BANNER:3,NBT/skyscraper_2x2_04/370-bannerC16R16.nbt)
Block(-5,46,8,STAINED_GLASS:15)
Block(-5,47,4,STAINED_GLASS:15)
Block(-5,47,5,CONCRETE:15)
Block(-5,47,6,REDSTONE_LAMP_OFF:0)
Block(-5,47,8,STAINED_GLASS:15)
Block(-5,48,4,STAINED_GLASS:15)
Block(-5,48,5,IRON_TRAPDOOR:1)
Block(-5,48,6,IRON_TRAPDOOR:1)
Block(-5,48,8,STAINED_GLASS:15)
Block(-5,49,4,STAINED_GLASS:15)
Block(-5,49,8,STAINED_GLASS:15)
Block(-5,50,4,STAINED_GLASS:15)
Block(-5,50,6,CONCRETE:0)
Block(-5,50,8,STAINED_GLASS:15)
Block(-5,51,-7,CONCRETE:8)
Block(-5,51,-6,CONCRETE:8)
Block(-5,51,-5,CONCRETE:8)
Block(-5,51,-4,CONCRETE:8)
Block(-5,51,-3,CONCRETE:8)
Block(-5,51,-2,CONCRETE:8)
Block(-5,51,-1,CONCRETE:8)
Block(-5,51,0,CONCRETE:8)
Block(-5,51,1,CONCRETE:8)
Block(-5,51,2,CONCRETE:8)
Block(-5,51,3,CONCRETE:8)
Block(-5,51,4,CONCRETE:8)
Block(-5,51,5,CONCRETE:8)
Block(-5,51,6,CONCRETE:8)
Block(-5,51,7,CONCRETE:8)
Block(-5,51,8,STAINED_GLASS:15)
Block(-5,52,4,STAINED_GLASS:15)
Block(-5,52,5,IRON_TRAPDOOR:9)
Block(-5,52,6,CONCRETE:0)
Block(-5,52,7,IRON_TRAPDOOR:10)
Block(-5,52,8,STAINED_GLASS:15)
Block(-5,53,4,STAINED_GLASS:15)
Block(-5,53,5,CONCRETE:15)
Block(-5,53,6,CONCRETE:15)
Block(-5,53,8,STAINED_GLASS:15)
Block(-5,54,4,STAINED_GLASS:15)
Block(-5,54,5,CONCRETE:15)
Block(-5,54,6,CONCRETE:15)
Block(-5,54,7,WALL_BANNER:3,NBT/skyscraper_2x2_04/371-bannerC16R16.nbt)
Block(-5,54,8,STAINED_GLASS:15)
Block(-5,55,4,STAINED_GLASS:15)
Block(-5,55,5,CONCRETE:15)
Block(-5,55,6,REDSTONE_LAMP_OFF:0)
Block(-5,55,8,STAINED_GLASS:15)
Block(-5,56,4,STAINED_GLASS:15)
Block(-5,56,5,IRON_TRAPDOOR:1)
Block(-5,56,6,IRON_TRAPDOOR:1)
Block(-5,56,8,STAINED_GLASS:15)
Block(-5,57,4,STAINED_GLASS:15)
Block(-5,57,8,STAINED_GLASS:15)
Block(-5,58,4,STAINED_GLASS:15)
Block(-5,58,6,CONCRETE:0)
Block(-5,58,8,STAINED_GLASS:15)
Block(-5,59,-7,CONCRETE:8)
Block(-5,59,-6,CONCRETE:8)
Block(-5,59,-5,CONCRETE:8)
Block(-5,59,-4,CONCRETE:8)
Block(-5,59,-3,CONCRETE:8)
Block(-5,59,-2,CONCRETE:8)
Block(-5,59,-1,CONCRETE:8)
Block(-5,59,0,CONCRETE:8)
Block(-5,59,1,CONCRETE:8)
Block(-5,59,2,CONCRETE:8)
Block(-5,59,3,CONCRETE:8)
Block(-5,59,4,CONCRETE:8)
Block(-5,59,5,CONCRETE:8)
Block(-5,59,6,CONCRETE:8)
Block(-5,59,7,CONCRETE:8)
Block(-5,59,8,STAINED_GLASS:15)
Block(-5,60,4,STAINED_GLASS:15)
Block(-5,60,5,IRON_TRAPDOOR:9)
Block(-5,60,6,CONCRETE:0)
Block(-5,60,7,IRON_TRAPDOOR:10)
Block(-5,60,8,STAINED_GLASS:15)
Block(-5,61,4,STAINED_GLASS:15)
Block(-5,61,5,CONCRETE:15)
Block(-5,61,6,CONCRETE:15)
Block(-5,61,8,STAINED_GLASS:15)
Block(-5,62,4,STAINED_GLASS:15)
Block(-5,62,5,CONCRETE:15)
Block(-5,62,6,CONCRETE:15)
Block(-5,62,7,WALL_BANNER:3,NBT/skyscraper_2x2_04/372-bannerC16R16.nbt)
Block(-5,62,8,STAINED_GLASS:15)
Block(-5,63,4,STAINED_GLASS:15)
Block(-5,63,5,CONCRETE:15)
Block(-5,63,6,REDSTONE_LAMP_OFF:0)
Block(-5,63,8,STAINED_GLASS:15)
Block(-5,64,4,STAINED_GLASS:15)
Block(-5,64,5,IRON_TRAPDOOR:1)
Block(-5,64,6,IRON_TRAPDOOR:1)
Block(-5,64,8,STAINED_GLASS:15)
Block(-5,65,4,STAINED_GLASS:15)
Block(-5,65,8,STAINED_GLASS:15)
Block(-5,66,4,STAINED_GLASS:15)
Block(-5,66,6,CONCRETE:0)
Block(-5,66,8,STAINED_GLASS:15)
Block(-5,67,-7,CONCRETE:8)
Block(-5,67,-6,CONCRETE:8)
Block(-5,67,-5,CONCRETE:8)
Block(-5,67,-4,CONCRETE:8)
Block(-5,67,-3,CONCRETE:8)
Block(-5,67,-2,CONCRETE:8)
Block(-5,67,-1,CONCRETE:8)
Block(-5,67,0,CONCRETE:8)
Block(-5,67,1,CONCRETE:8)
Block(-5,67,2,CONCRETE:8)
Block(-5,67,3,CONCRETE:8)
Block(-5,67,4,CONCRETE:8)
Block(-5,67,5,CONCRETE:8)
Block(-5,67,6,CONCRETE:8)
Block(-5,67,7,CONCRETE:8)
Block(-5,67,8,STAINED_GLASS:15)
Block(-5,68,4,STAINED_GLASS:15)
Block(-5,68,5,IRON_TRAPDOOR:9)
Block(-5,68,6,CONCRETE:0)
Block(-5,68,7,IRON_TRAPDOOR:10)
Block(-5,68,8,STAINED_GLASS:15)
Block(-5,69,4,STAINED_GLASS:15)
Block(-5,69,5,CONCRETE:15)
Block(-5,69,6,CONCRETE:15)
Block(-5,69,8,STAINED_GLASS:15)
Block(-5,70,4,STAINED_GLASS:15)
Block(-5,70,5,CONCRETE:15)
Block(-5,70,6,CONCRETE:15)
Block(-5,70,7,WALL_BANNER:3,NBT/skyscraper_2x2_04/373-bannerC16R16.nbt)
Block(-5,70,8,STAINED_GLASS:15)
Block(-5,71,4,STAINED_GLASS:15)
Block(-5,71,5,CONCRETE:15)
Block(-5,71,6,REDSTONE_LAMP_OFF:0)
Block(-5,71,8,STAINED_GLASS:15)
Block(-5,72,4,STAINED_GLASS:15)
Block(-5,72,5,IRON_TRAPDOOR:1)
Block(-5,72,6,IRON_TRAPDOOR:1)
Block(-5,72,8,STAINED_GLASS:15)
Block(-5,73,4,STAINED_GLASS:15)
Block(-5,73,8,STAINED_GLASS:15)
Block(-5,74,4,STAINED_GLASS:15)
Block(-5,74,6,CONCRETE:0)
Block(-5,74,8,STAINED_GLASS:15)
Block(-5,75,-7,CONCRETE:8)
Block(-5,75,-6,CONCRETE:8)
Block(-5,75,-5,CONCRETE:8)
Block(-5,75,-4,CONCRETE:8)
Block(-5,75,-3,CONCRETE:8)
Block(-5,75,-2,CONCRETE:8)
Block(-5,75,-1,CONCRETE:8)
Block(-5,75,0,CONCRETE:8)
Block(-5,75,1,CONCRETE:8)
Block(-5,75,2,CONCRETE:8)
Block(-5,75,3,CONCRETE:8)
Block(-5,75,4,CONCRETE:8)
Block(-5,75,5,CONCRETE:8)
Block(-5,75,6,CONCRETE:8)
Block(-5,75,7,CONCRETE:8)
Block(-5,75,8,STAINED_GLASS:15)
Block(-5,76,8,STAINED_GLASS:15)
Block(-5,77,8,STAINED_GLASS:15)
Block(-5,78,8,STAINED_GLASS:15)
Block(-5,79,2,CONCRETE:8)
Block(-5,79,8,CONCRETE:8)
Block(-5,80,2,CONCRETE:8)
Block(-5,80,3,CONCRETE:8)
Block(-5,80,4,CONCRETE:8)
Block(-5,80,5,CONCRETE:8)
Block(-5,80,6,CONCRETE:8)
Block(-5,80,7,CONCRETE:8)
Block(-5,80,8,CONCRETE:8)
Block(-5,81,2,CONCRETE:8)
Block(-5,81,3,CONCRETE:8)
Block(-5,81,4,CONCRETE:8)
Block(-5,81,5,CONCRETE:8)
Block(-5,81,6,CONCRETE:8)
Block(-5,81,7,CONCRETE:8)
Block(-5,81,8,CONCRETE:8)
Block(-5,82,2,STAINED_GLASS:15)
Block(-5,83,-7,CONCRETE:8)
Block(-5,83,-6,CONCRETE:8)
Block(-5,83,-5,CONCRETE:8)
Block(-5,83,-4,CONCRETE:8)
Block(-5,83,-3,CONCRETE:8)
Block(-5,83,-2,CONCRETE:8)
Block(-5,83,-1,CONCRETE:8)
Block(-5,83,0,CONCRETE:8)
Block(-5,83,1,CONCRETE:8)
Block(-5,83,2,STAINED_GLASS:15)
Block(-5,84,2,STAINED_GLASS:15)
Block(-5,85,2,STAINED_GLASS:15)
Block(-5,86,2,STAINED_GLASS:15)
Block(-5,87,2,STAINED_GLASS:15)
Block(-5,88,2,STAINED_GLASS:15)
Block(-5,89,2,STAINED_GLASS:15)
Block(-5,90,2,STAINED_GLASS:15)
Block(-5,91,-7,CONCRETE:8)
Block(-5,91,-6,CONCRETE:8)
Block(-5,91,-5,CONCRETE:8)
Block(-5,91,-4,CONCRETE:8)
Block(-5,91,-3,CONCRETE:8)
Block(-5,91,-2,CONCRETE:8)
Block(-5,91,-1,CONCRETE:8)
Block(-5,91,0,CONCRETE:8)
Block(-5,91,1,CONCRETE:8)
Block(-5,91,2,STAINED_GLASS:15)
Block(-5,92,2,STAINED_GLASS:15)
Block(-5,93,2,STAINED_GLASS:15)
Block(-5,94,-2,CONCRETE:15)
Block(-5,94,2,CONCRETE:15)
Block(-5,95,-2,CONCRETE:15)
Block(-5,95,-1,CONCRETE:15)
Block(-5,95,0,CONCRETE:15)
Block(-5,95,1,CONCRETE:15)
Block(-5,95,2,CONCRETE:15)
Block(-5,96,-2,CONCRETE:15)
Block(-5,96,-1,CONCRETE:15)
Block(-5,96,0,CONCRETE:15)
Block(-5,96,1,CONCRETE:15)
Block(-5,96,2,CONCRETE:15)
Block(-5,97,-2,STAINED_GLASS:15)
Block(-5,98,-2,STAINED_GLASS:15)
Block(-5,99,-7,CONCRETE:8)
Block(-5,99,-6,CONCRETE:8)
Block(-5,99,-5,CONCRETE:8)
Block(-5,99,-4,CONCRETE:8)
Block(-5,99,-3,CONCRETE:8)
Block(-5,99,-2,STAINED_GLASS:15)
Block(-5,100,-2,STAINED_GLASS:15)
Block(-5,101,-2,STAINED_GLASS:15)
Block(-5,102,-2,STAINED_GLASS:15)
Block(-5,103,-2,STAINED_GLASS:15)
Block(-5,104,-2,STAINED_GLASS:15)
Block(-5,105,-2,STAINED_GLASS:15)
Block(-5,106,-2,STAINED_GLASS:15)
Block(-5,107,-7,CONCRETE:8)
Block(-5,107,-6,CONCRETE:8)
Block(-5,107,-5,CONCRETE:8)
Block(-5,107,-4,CONCRETE:8)
Block(-5,107,-3,CONCRETE:8)
Block(-5,107,-2,STAINED_GLASS:15)
Block(-5,108,-7,CONCRETE:15)
Block(-5,108,-5,CONCRETE:15)
Block(-5,108,-3,CONCRETE:15)
Block(-5,108,-2,STAINED_GLASS:15)
Block(-5,109,-7,CONCRETE:14)
Block(-5,109,-5,CONCRETE:14)
Block(-5,109,-3,CONCRETE:14)
Block(-5,109,-2,STAINED_GLASS:15)
Block(-5,110,-7,DISPENSER:1,NBT/skyscraper_2x2_04/375-dispenserC16R16.nbt)
Block(-5,110,-5,DISPENSER:1,NBT/skyscraper_2x2_04/376-dispenserC16R16.nbt)
Block(-5,110,-3,DISPENSER:1,NBT/skyscraper_2x2_04/377-dispenserC16R16.nbt)
Block(-5,110,-2,STAINED_GLASS:15)
Block(-5,111,-7,IRON_FENCE:0)
Block(-5,111,-5,IRON_FENCE:0)
Block(-5,111,-3,IRON_FENCE:0)
Block(-5,111,-2,STAINED_GLASS:15)
Block(-5,112,-7,IRON_FENCE:0)
Block(-5,112,-6,IRON_FENCE:0)
Block(-5,112,-5,IRON_FENCE:0)
Block(-5,112,-4,IRON_FENCE:0)
Block(-5,112,-3,IRON_FENCE:0)
Block(-5,112,-2,STAINED_GLASS:15)
Block(-5,113,-7,IRON_TRAPDOOR:11)
Block(-5,113,-5,IRON_TRAPDOOR:10)
Block(-5,113,-3,IRON_TRAPDOOR:10)
Block(-5,113,-2,STAINED_GLASS:15)
Block(-5,114,-7,CONCRETE:15)
Block(-5,114,-5,CONCRETE:15)
Block(-5,114,-3,CONCRETE:15)
Block(-5,114,-2,STAINED_GLASS:15)
Block(-5,115,-7,CONCRETE:15)
Block(-5,115,-6,CONCRETE:8)
Block(-5,115,-5,CONCRETE:15)
Block(-5,115,-4,CONCRETE:8)
Block(-5,115,-3,CONCRETE:15)
Block(-5,115,-2,STAINED_GLASS:15)
Block(-5,116,-7,CONCRETE:15)
Block(-5,116,-5,CONCRETE:15)
Block(-5,116,-3,CONCRETE:15)
Block(-5,116,-2,STAINED_GLASS:15)
Block(-5,117,-7,CONCRETE:15)
Block(-5,117,-5,CONCRETE:15)
Block(-5,117,-4,IRON_TRAPDOOR:8)
Block(-5,117,-3,CONCRETE:15)
Block(-5,117,-2,STAINED_GLASS:15)
Block(-5,118,-7,DISPENSER:1,NBT/skyscraper_2x2_04/378-dispenserC16R16.nbt)
Block(-5,118,-6,IRON_FENCE:0)
Block(-5,118,-5,DISPENSER:1,NBT/skyscraper_2x2_04/379-dispenserC16R16.nbt)
Block(-5,118,-4,IRON_FENCE:0)
Block(-5,118,-3,DISPENSER:1,NBT/skyscraper_2x2_04/380-dispenserC16R16.nbt)
Block(-5,118,-2,STAINED_GLASS:15)
Block(-5,119,-7,COBBLE_WALL:0)
Block(-5,119,-6,IRON_FENCE:0)
Block(-5,119,-5,COBBLE_WALL:0)
Block(-5,119,-4,IRON_FENCE:0)
Block(-5,119,-3,COBBLE_WALL:0)
Block(-5,119,-2,STAINED_GLASS:15)
Block(-5,120,-7,CONCRETE:14)
Block(-5,120,-6,IRON_FENCE:0)
Block(-5,120,-5,CONCRETE:14)
Block(-5,120,-4,IRON_FENCE:0)
Block(-5,120,-3,CONCRETE:14)
Block(-5,120,-2,STAINED_GLASS:15)
Block(-5,121,-7,DAYLIGHT_DETECTOR_INVERTED:6,NBT/skyscraper_2x2_04/381-daylight_detectorC16R16.nbt)
Block(-5,121,-6,IRON_FENCE:0)
Block(-5,121,-5,DAYLIGHT_DETECTOR_INVERTED:5,NBT/skyscraper_2x2_04/382-daylight_detectorC16R16.nbt)
Block(-5,121,-4,IRON_FENCE:0)
Block(-5,121,-3,DAYLIGHT_DETECTOR_INVERTED:3,NBT/skyscraper_2x2_04/383-daylight_detectorC16R16.nbt)
Block(-5,121,-2,STAINED_GLASS:15)
Block(-5,122,-6,DISPENSER:0,NBT/skyscraper_2x2_04/384-dispenserC16R16.nbt)
Block(-5,122,-4,DISPENSER:0,NBT/skyscraper_2x2_04/385-dispenserC16R16.nbt)
Block(-5,122,-2,STAINED_GLASS:15)
Block(-5,123,-7,CONCRETE:8)
Block(-5,123,-6,CONCRETE:8)
Block(-5,123,-5,CONCRETE:8)
Block(-5,123,-4,CONCRETE:8)
Block(-5,123,-3,CONCRETE:8)
Block(-5,123,-2,STAINED_GLASS:15)
Block(-5,124,-6,QUARTZ_STAIRS:0)
Block(-5,124,-4,STAINED_GLASS_PANE:14)
Block(-5,124,-3,COBBLE_WALL:0)
Block(-5,124,-2,STAINED_GLASS:15)
Block(-5,125,-4,STAINED_GLASS_PANE:14)
Block(-5,125,-3,COBBLE_WALL:0)
Block(-5,125,-2,STAINED_GLASS:15)
Block(-5,126,-4,STAINED_GLASS_PANE:14)
Block(-5,126,-3,COBBLE_WALL:0)
Block(-5,126,-2,STAINED_GLASS:15)
Block(-5,127,-7,IRON_TRAPDOOR:10)
Block(-5,127,-6,IRON_TRAPDOOR:10)
Block(-5,127,-5,IRON_TRAPDOOR:10)
Block(-5,127,-4,STAINED_GLASS_PANE:14)
Block(-5,127,-3,COBBLE_WALL:0)
Block(-5,127,-2,STAINED_GLASS:15)
Block(-5,128,-7,STAINED_GLASS_PANE:15)
Block(-5,128,-4,STAINED_GLASS_PANE:14)
Block(-5,128,-3,COBBLE_WALL:0)
Block(-5,128,-2,STAINED_GLASS:15)
Block(-5,129,-4,STAINED_GLASS_PANE:14)
Block(-5,129,-3,COBBLE_WALL:0)
Block(-5,129,-2,STAINED_GLASS:15)
Block(-5,130,-5,IRON_TRAPDOOR:11)
Block(-5,130,-4,STAINED_GLASS_PANE:14)
Block(-5,130,-3,DROPPER:0,NBT/skyscraper_2x2_04/386-dropperC16R16.nbt)
Block(-5,130,-2,STAINED_GLASS:15)
Block(-5,131,-5,CONCRETE:8)
Block(-5,131,-4,CONCRETE:8)
Block(-5,131,-3,CONCRETE:8)
Block(-5,131,-2,STAINED_GLASS:15)
Block(-5,132,-5,STAINED_GLASS_PANE:15)
Block(-5,132,-4,IRON_FENCE:0)
Block(-5,132,-2,STAINED_GLASS:15)
Block(-5,133,-2,STAINED_GLASS:15)
Block(-5,134,-2,STAINED_GLASS:15)
Block(-5,135,-2,CONCRETE:8)
Block(-5,136,-7,CONCRETE:8)
Block(-5,136,-6,CONCRETE:8)
Block(-5,136,-5,CONCRETE:8)
Block(-5,136,-4,CONCRETE:8)
Block(-5,136,-3,CONCRETE:8)
Block(-5,136,-2,CONCRETE:8)
Block(-5,137,-7,CONCRETE:8)
Block(-5,137,-6,CONCRETE:8)
Block(-5,137,-5,CONCRETE:8)
Block(-5,137,-4,CONCRETE:8)
Block(-5,137,-3,CONCRETE:8)
Block(-5,137,-2,CONCRETE:8)
Block(-4,0,-7,CONCRETE:7)
Block(-4,0,-6,CONCRETE:7)
Block(-4,0,-5,CONCRETE:7)
Block(-4,0,-4,CONCRETE:7)
Block(-4,0,-3,CONCRETE:7)
Block(-4,0,-2,CONCRETE:7)
Block(-4,0,-1,CONCRETE:7)
Block(-4,0,0,CONCRETE:7)
Block(-4,0,1,CONCRETE:7)
Block(-4,0,2,CONCRETE:7)
Block(-4,0,3,CONCRETE:7)
Block(-4,0,4,CONCRETE:7)
Block(-4,0,5,CONCRETE:7)
Block(-4,0,6,CONCRETE:7)
Block(-4,0,7,CONCRETE:7)
Block(-4,0,8,CONCRETE:7)
Block(-4,1,-7,STATIONARY_WATER:0)
Block(-4,1,-6,STATIONARY_WATER:0)
Block(-4,1,-5,STATIONARY_WATER:0)
Block(-4,1,-4,STATIONARY_WATER:0)
Block(-4,1,-3,STATIONARY_WATER:0)
Block(-4,1,-2,STATIONARY_WATER:0)
Block(-4,1,-1,STATIONARY_WATER:0)
Block(-4,1,0,STATIONARY_WATER:0)
Block(-4,1,1,STATIONARY_WATER:0)
Block(-4,1,2,STATIONARY_WATER:0)
Block(-4,1,3,STATIONARY_WATER:0)
Block(-4,1,4,STATIONARY_WATER:0)
Block(-4,1,5,STATIONARY_WATER:0)
Block(-4,1,6,STATIONARY_WATER:0)
Block(-4,1,7,STATIONARY_WATER:0)
Block(-4,1,8,STATIONARY_WATER:0)
Block(-4,2,-7,AIR:0)
Block(-4,2,-6,AIR:0)
Block(-4,2,-5,AIR:0)
Block(-4,2,-4,AIR:0)
Block(-4,2,-3,AIR:0)
Block(-4,2,-2,AIR:0)
Block(-4,2,-1,AIR:0)
Block(-4,2,0,AIR:0)
Block(-4,2,1,AIR:0)
Block(-4,2,2,AIR:0)
Block(-4,2,3,AIR:0)
Block(-4,2,4,AIR:0)
Block(-4,2,5,AIR:0)
Block(-4,2,6,AIR:0)
Block(-4,2,7,AIR:0)
Block(-4,2,8,AIR:0)
Block(-4,3,-7,AIR:0)
Block(-4,3,-6,AIR:0)
Block(-4,3,-5,AIR:0)
Block(-4,3,-4,AIR:0)
Block(-4,3,-3,AIR:0)
Block(-4,3,-2,AIR:0)
Block(-4,3,-1,AIR:0)
Block(-4,3,0,AIR:0)
Block(-4,3,1,AIR:0)
Block(-4,3,2,AIR:0)
Block(-4,3,3,AIR:0)
Block(-4,3,4,AIR:0)
Block(-4,3,5,AIR:0)
Block(-4,3,6,AIR:0)
Block(-4,3,7,AIR:0)
Block(-4,3,8,AIR:0)
Block(-4,4,-7,AIR:0)
Block(-4,4,-6,AIR:0)
Block(-4,4,-5,AIR:0)
Block(-4,4,-4,AIR:0)
Block(-4,4,-3,AIR:0)
Block(-4,4,-2,AIR:0)
Block(-4,4,-1,AIR:0)
Block(-4,4,0,AIR:0)
Block(-4,4,1,AIR:0)
Block(-4,4,2,CONCRETE:7)
Block(-4,4,3,STEP:8)
Block(-4,4,4,CONCRETE:7)
Block(-4,4,5,STEP:8)
Block(-4,4,6,STEP:8)
Block(-4,4,7,CONCRETE:7)
Block(-4,4,8,STEP:8)
Block(-4,5,-7,CONCRETE:14)
Block(-4,5,-6,CONCRETE:11)
Block(-4,5,-5,AIR:0)
Block(-4,5,-4,AIR:0)
Block(-4,5,-3,AIR:0)
Block(-4,5,-2,AIR:0)
Block(-4,5,-1,AIR:0)
Block(-4,5,0,AIR:0)
Block(-4,5,1,AIR:0)
Block(-4,5,2,CONCRETE:7)
Block(-4,5,3,CONCRETE:7)
Block(-4,5,4,CONCRETE:7)
Block(-4,5,5,CONCRETE:7)
Block(-4,5,6,CONCRETE:7)
Block(-4,5,7,CONCRETE:7)
Block(-4,5,8,CONCRETE:7)
Block(-4,6,-7,AIR:0)
Block(-4,6,-6,IRON_FENCE:0)
Block(-4,6,-5,AIR:0)
Block(-4,6,-4,AIR:0)
Block(-4,6,-3,AIR:0)
Block(-4,6,-2,AIR:0)
Block(-4,6,-1,AIR:0)
Block(-4,6,0,AIR:0)
Block(-4,6,1,AIR:0)
Block(-4,6,2,CONCRETE:7)
Block(-4,6,3,CONCRETE:7)
Block(-4,6,4,CONCRETE:7)
Block(-4,6,5,CONCRETE:7)
Block(-4,6,6,CONCRETE:7)
Block(-4,6,7,CONCRETE:7)
Block(-4,6,8,CONCRETE:7)
Block(-4,7,-7,CONCRETE:7)
Block(-4,7,-6,CONCRETE:7)
Block(-4,7,-5,CONCRETE:7)
Block(-4,7,-4,CONCRETE:7)
Block(-4,7,-3,CONCRETE:7)
Block(-4,7,-2,CONCRETE:7)
Block(-4,7,-1,CONCRETE:7)
Block(-4,7,0,CONCRETE:7)
Block(-4,7,1,CONCRETE:7)
Block(-4,7,2,CONCRETE:7)
Block(-4,7,3,CONCRETE:7)
Block(-4,7,4,CONCRETE:7)
Block(-4,7,5,CONCRETE:7)
Block(-4,7,6,CONCRETE:7)
Block(-4,7,7,CONCRETE:7)
Block(-4,7,8,CONCRETE:7)
Block(-4,8,-7,CONCRETE:7)
Block(-4,8,-6,CONCRETE:7)
Block(-4,8,-5,CONCRETE:7)
Block(-4,8,-4,CONCRETE:7)
Block(-4,8,-3,CONCRETE:7)
Block(-4,8,-2,CONCRETE:7)
Block(-4,8,-1,CONCRETE:7)
Block(-4,8,0,CONCRETE:7)
Block(-4,8,1,AIR:0)
Block(-4,8,2,STONE_BUTTON:4)
Block(-4,8,3,CONCRETE:15)
Block(-4,8,4,CONCRETE:15)
Block(-4,8,5,CONCRETE:15)
Block(-4,8,6,CONCRETE:15)
Block(-4,8,7,CONCRETE:15)
Block(-4,8,8,CONCRETE:7)
Block(-4,9,-7,CONCRETE:7)
Block(-4,9,-6,CONCRETE:7)
Block(-4,9,-5,CONCRETE:7)
Block(-4,9,-4,CONCRETE:7)
Block(-4,9,-3,CONCRETE:7)
Block(-4,9,-2,CONCRETE:7)
