
#######################################################################
# +-----------------------------------------------------------------+ #
# |                            BO4 object                           | #
# +-----------------------------------------------------------------+ #
#######################################################################

Author: NLBlackEagle

Description: No description given

SettingsMode: WriteDisable


#######################################################################
# +-----------------------------------------------------------------+ #
# |                          Main settings                          | #
# +-----------------------------------------------------------------+ #
#######################################################################

Frequency: 0

SpawnHeight: highestBlock

UseCenterForHighestBlock: true

##############################
# Height Limits for the BO4. #
##############################

MinHeight: 0

MaxHeight: 255

InheritBO3: 

InheritBO3Rotation: NORTH

OverrideChildSettings: true

OverrideParentHeight: false

CanOverride: true

BranchFrequency: 0

BranchFrequencyGroup: 

MustBeBelowOther: false

MustBeInside: 

CannotBeInside: 

ReplacesBO3: L4-M-CrossC0R0, L4-M-CrossC0R1, L4-M-CrossC0R2, L4-M-CrossC0R3, L4-M-CrossC1R0, L4-M-CrossC1R1, L4-M-CrossC1R2, L4-M-CrossC1R3, L4-M-CrossC2R0, L4-M-CrossC2R1, L4-M-CrossC2R2, L4-M-CrossC2R3, L4-M-CrossC3R0, L4-M-CrossC3R1, L4-M-CrossC3R2, L4-M-CrossC3R3, L4-M-Straigth-START_01-C0R0, L4-M-Straigth-START_01-C0R1, L4-M-Straigth-START_01-C1R0, L4-M-Straigth-START_01-C1R1, L4-M-Straigth-START_01-C2R0, L4-M-Straigth-START_01-C2R1, L4-M-Straigth-START_01-C3R0, L4-M-Straigth-START_01-C3R1, L4-M-Straigth-3CC0R0, L4-M-Straigth-3CC0R1, L4-M-Straigth-3CC0R2, L4-M-Straigth-3CC1R0, L4-M-Straigth-3CC1R1, L4-M-Straigth-3CC1R2, L4-M-Straigth-3CC2R0, L4-M-Straigth-3CC2R1, L4-M-Straigth-3CC2R2, L4-M-Straigth-3CC3R0, L4-M-Straigth-3CC3R1, L4-M-Straigth-3CC3R2, L4-M-Cross, skyscraper_2x2_01, skyscraper_2x2_02, skyscraper_2x2_03, skyscraper_2x2_04, skyscraper_2x2_05, skyscraper_3x3_01, skyscraper_3x3_02, skyscraper_3x3_03, L3-M-Straigth-2CC0R0, L3-M-Straigth-2CC0R1, L3-M-Straigth-2CC1R0, L3-M-Straigth-2CC1R1, L3-M-Straigth-2CC2R0, L3-M-Straigth-2CC2R1, L3-M-Straigth-2CC3R0, L3-M-Straigth-2CC3R1, L3-M-Straigth-3CC0R0, L3-M-Straigth-3CC0R1, L3-M-Straigth-3CC0R2, L3-M-Straigth-3CC1R0, L3-M-Straigth-3CC1R1, L3-M-Straigth-3CC1R2, L3-M-Straigth-3CC2R0, L3-M-Straigth-3CC2R1, L3-M-Straigth-3CC2R2, L3-M-Straigth-3CC3R0, L3-M-Straigth-3CC3R1, L3-M-Straigth-3CC3R2L4-M-CrossC0R0, L4-M-CrossC0R1, L4-M-CrossC0R2, L4-M-CrossC0R3, L4-M-CrossC1R0, L4-M-CrossC1R1, L4-M-CrossC1R2, L4-M-CrossC1R3, L4-M-CrossC2R0, L4-M-CrossC2R1, L4-M-CrossC2R2, L4-M-CrossC2R3, L4-M-CrossC3R0, L4-M-CrossC3R1, L4-M-CrossC3R2, L4-M-CrossC3R3, L4-M-Straigth-START_01-C0R0, L4-M-Straigth-START_01-C0R1, L4-M-Straigth-START_01-C1R0, L4-M-Straigth-START_01-C1R1, L4-M-Straigth-START_01-C2R0, L4-M-Straigth-START_01-C2R1, L4-M-Straigth-START_01-C3R0, L4-M-Straigth-START_01-C3R1, L4-M-Straigth-3CC0R0, L4-M-Straigth-3CC0R1, L4-M-Straigth-3CC0R2, L4-M-Straigth-3CC1R0, L4-M-Straigth-3CC1R1, L4-M-Straigth-3CC1R2, L4-M-Straigth-3CC2R0, L4-M-Straigth-3CC2R1, L4-M-Straigth-3CC2R2, L4-M-Straigth-3CC3R0, L4-M-Straigth-3CC3R1, L4-M-Straigth-3CC3R2, L4-M-Cross, skyscraper_2x2_01, skyscraper_2x2_02, skyscraper_2x2_03, skyscraper_2x2_04, skyscraper_2x2_05, skyscraper_3x3_01, skyscraper_3x3_02, skyscraper_3x3_03

MustBeInsideWorldBorders: false

CanSpawnOnWater: true

SpawnOnWaterOnly: false

SpawnUnderWater: false

SpawnAtWaterLevel: false

HeightOffset: 0

RemoveAir: false

ReplaceAbove: 

ReplaceBelow: 

ReplaceWithBiomeBlocks: true

ReplaceWithSurfaceBlock: GRASS

ReplaceWithGroundBlock: DIRT

ReplaceWithStoneBlock: STONE

SmoothRadius: 0

SmoothHeightOffset: 0

SmoothStartTop: false

SmoothStartWood: false

SmoothingSurfaceBlock: 

SmoothingGroundBlock: 

BO3Group: 

IsSpawnPoint: false

DoReplaceBlocks: true


#######################################################################
# +-----------------------------------------------------------------+ #
# |                              Blocks                             | #
# +-----------------------------------------------------------------+ #
#######################################################################

Block(-8,0,-7,CONCRETE:7)
Block(-8,0,-6,CONCRETE:7)
Block(-8,0,-5,CONCRETE:7)
Block(-8,0,-4,CONCRETE:7)
Block(-8,0,-3,CONCRETE:7)
Block(-8,0,-2,CONCRETE:7)
Block(-8,0,-1,CONCRETE:7)
Block(-8,0,0,CONCRETE:7)
Block(-8,0,1,CONCRETE:7)
Block(-8,0,2,CONCRETE:7)
Block(-8,0,3,CONCRETE:7)
Block(-8,0,4,CONCRETE:7)
Block(-8,0,5,CONCRETE:7)
Block(-8,0,6,CONCRETE:7)
Block(-8,0,7,CONCRETE:7)
Block(-8,0,8,CONCRETE:7)
Block(-8,1,-7,CONCRETE:7)
Block(-8,1,-6,CONCRETE:7)
Block(-8,1,-5,CONCRETE:7)
Block(-8,1,-4,CONCRETE:7)
Block(-8,1,-3,CONCRETE:7)
Block(-8,1,-2,CONCRETE:7)
Block(-8,1,-1,CONCRETE:7)
Block(-8,1,0,CONCRETE:7)
Block(-8,1,1,CONCRETE:7)
Block(-8,1,2,CONCRETE:7)
Block(-8,1,3,CONCRETE:7)
Block(-8,1,4,CONCRETE:7)
Block(-8,1,5,CONCRETE:7)
Block(-8,1,6,CONCRETE:7)
Block(-8,1,7,CONCRETE:7)
Block(-8,1,8,CONCRETE:7)
Block(-8,2,-7,CONCRETE:7)
Block(-8,2,-6,CONCRETE:7)
Block(-8,2,-5,CONCRETE:7)
Block(-8,2,-4,CONCRETE:7)
Block(-8,2,-3,CONCRETE:7)
Block(-8,2,-2,CONCRETE:7)
Block(-8,2,-1,CONCRETE:7)
Block(-8,2,0,CONCRETE:7)
Block(-8,2,1,CONCRETE:7)
Block(-8,2,2,CONCRETE:7)
Block(-8,2,3,CONCRETE:7)
Block(-8,2,4,CONCRETE:7)
Block(-8,2,5,CONCRETE:7)
Block(-8,2,6,CONCRETE:7)
Block(-8,2,7,CONCRETE:7)
Block(-8,2,8,CONCRETE:7)
Block(-8,3,-7,CONCRETE:7)
Block(-8,3,-6,CONCRETE:7)
Block(-8,3,-5,CONCRETE:7)
Block(-8,3,-4,CONCRETE:7)
Block(-8,3,-3,CONCRETE:7)
Block(-8,3,-2,CONCRETE:7)
Block(-8,3,-1,CONCRETE:7)
Block(-8,3,0,CONCRETE:7)
Block(-8,3,1,CONCRETE:7)
Block(-8,3,2,CONCRETE:7)
Block(-8,3,3,CONCRETE:7)
Block(-8,3,4,CONCRETE:7)
Block(-8,3,5,CONCRETE:7)
Block(-8,3,6,CONCRETE:7)
Block(-8,3,7,CONCRETE:7)
Block(-8,3,8,CONCRETE:7)
Block(-8,4,-7,CONCRETE:7)
Block(-8,4,-6,CONCRETE:7)
Block(-8,4,-5,CONCRETE:7)
Block(-8,4,-4,CONCRETE:7)
Block(-8,4,-3,CONCRETE:7)
Block(-8,4,-2,CONCRETE:7)
Block(-8,4,-1,CONCRETE:7)
Block(-8,4,0,CONCRETE:7)
Block(-8,4,1,CONCRETE:7)
Block(-8,4,2,CONCRETE:7)
Block(-8,4,3,CONCRETE:7)
Block(-8,4,4,CONCRETE:7)
Block(-8,4,5,CONCRETE:7)
Block(-8,4,6,CONCRETE:7)
Block(-8,4,7,CONCRETE:7)
Block(-8,4,8,CONCRETE:7)
Block(-8,5,-7,CONCRETE:7)
Block(-8,5,-6,CONCRETE:7)
Block(-8,5,-5,CONCRETE:7)
Block(-8,5,-4,CONCRETE:7)
Block(-8,5,-3,CONCRETE:7)
Block(-8,5,-2,CONCRETE:7)
Block(-8,5,-1,CONCRETE:7)
Block(-8,5,0,CONCRETE:7)
Block(-8,5,1,CONCRETE:7)
Block(-8,5,2,CONCRETE:7)
Block(-8,5,3,CONCRETE:7)
Block(-8,5,4,CONCRETE:7)
Block(-8,5,5,CONCRETE:7)
Block(-8,5,6,CONCRETE:7)
Block(-8,5,7,CONCRETE:7)
Block(-8,5,8,CONCRETE:7)
Block(-8,6,-7,CONCRETE:7)
Block(-8,6,-6,CONCRETE:7)
Block(-8,6,-5,CONCRETE:7)
Block(-8,6,-4,CONCRETE:7)
Block(-8,6,-3,CONCRETE:7)
Block(-8,6,-2,CONCRETE:7)
Block(-8,6,-1,CONCRETE:7)
Block(-8,6,0,CONCRETE:7)
Block(-8,6,1,CONCRETE:7)
Block(-8,6,2,CONCRETE:7)
Block(-8,6,3,CONCRETE:7)
Block(-8,6,4,CONCRETE:7)
Block(-8,6,5,CONCRETE:7)
Block(-8,6,6,CONCRETE:7)
Block(-8,6,7,CONCRETE:7)
Block(-8,6,8,CONCRETE:7)
Block(-8,7,-7,CONCRETE:7)
Block(-8,7,-6,CONCRETE:7)
Block(-8,7,-5,CONCRETE:7)
Block(-8,7,-4,CONCRETE:7)
Block(-8,7,-3,CONCRETE:7)
Block(-8,7,-2,CONCRETE:7)
Block(-8,7,-1,CONCRETE:7)
Block(-8,7,0,CONCRETE:7)
Block(-8,7,1,CONCRETE:7)
Block(-8,7,2,CONCRETE:7)
Block(-8,7,3,CONCRETE:7)
Block(-8,7,4,CONCRETE:7)
Block(-8,7,5,CONCRETE:7)
Block(-8,7,6,CONCRETE:7)
Block(-8,7,7,CONCRETE:7)
Block(-8,7,8,CONCRETE:7)
Block(-8,8,-7,CONCRETE:7)
Block(-8,8,-6,CONCRETE:7)
Block(-8,8,-5,CONCRETE:7)
Block(-8,8,-4,CONCRETE:7)
Block(-8,8,-3,CONCRETE:7)
Block(-8,8,-2,CONCRETE:7)
Block(-8,8,-1,CONCRETE:7)
Block(-8,8,0,CONCRETE:7)
Block(-8,8,1,CONCRETE:7)
Block(-8,8,2,CONCRETE:7)
Block(-8,8,3,CONCRETE:7)
Block(-8,8,4,CONCRETE:7)
Block(-8,8,5,CONCRETE:7)
Block(-8,8,6,CONCRETE:7)
Block(-8,8,7,CONCRETE:7)
Block(-8,8,8,CONCRETE:7)
Block(-8,9,-7,BRICK:0)
Block(-8,9,-6,CONCRETE:7)
Block(-8,9,-5,CONCRETE:7)
Block(-8,9,-4,CONCRETE:7)
Block(-8,9,-3,CONCRETE:7)
Block(-8,9,-2,CONCRETE:7)
Block(-8,9,-1,CONCRETE:7)
Block(-8,9,0,CONCRETE:7)
Block(-8,9,1,CONCRETE:7)
Block(-8,9,2,CONCRETE:7)
Block(-8,9,3,CONCRETE:7)
Block(-8,9,4,CONCRETE:7)
Block(-8,9,5,CONCRETE:7)
Block(-8,9,6,CONCRETE:7)
Block(-8,9,7,BRICK:0)
Block(-8,9,8,CONCRETE:7)
Block(-8,10,-7,BRICK:0)
Block(-8,10,-6,CONCRETE:7)
Block(-8,10,-5,BRICK:0)
Block(-8,10,-4,CONCRETE:7)
Block(-8,10,-3,CONCRETE:7)
Block(-8,10,-2,BRICK:0)
Block(-8,10,-1,CONCRETE:7)
Block(-8,10,0,CONCRETE:7)
Block(-8,10,1,BRICK:0)
Block(-8,10,2,CONCRETE:7)
Block(-8,10,3,CONCRETE:7)
Block(-8,10,4,CONCRETE:7)
Block(-8,10,5,CONCRETE:7)
Block(-8,10,6,CONCRETE:7)
Block(-8,10,7,CONCRETE:7)
Block(-8,10,8,BRICK:0)
Block(-8,11,-7,BRICK:0)
Block(-8,11,-6,BRICK:0)
Block(-8,11,-5,BRICK:0)
Block(-8,11,-4,BRICK_STAIRS:1)
Block(-8,11,-3,BRICK_STAIRS:2)
Block(-8,11,-2,BRICK:0)
Block(-8,11,-1,BRICK_STAIRS:3)
Block(-8,11,0,BRICK_STAIRS:1)
Block(-8,11,1,BRICK_STAIRS:5)
Block(-8,11,2,BRICK:0)
Block(-8,11,3,CONCRETE:7)
Block(-8,11,4,CONCRETE:7)
Block(-8,11,5,CONCRETE:7)
Block(-8,11,6,BRICK:0)
Block(-8,11,7,BRICK_STAIRS:1)
Block(-8,11,8,BRICK:0)
Block(-8,12,-7,BRICK:0)
Block(-8,12,-6,CONCRETE:7)
Block(-8,12,-5,BRICK_STAIRS:5)
Block(-8,12,-4,BRICK:0)
Block(-8,12,-3,BRICK_STAIRS:5)
Block(-8,12,-2,BRICK:0)
Block(-8,12,-1,CONCRETE:7)
Block(-8,12,0,CONCRETE:7)
Block(-8,12,1,BRICK:0)
Block(-8,12,2,CONCRETE:7)
Block(-8,12,3,CONCRETE:7)
Block(-8,12,4,CONCRETE:7)
Block(-8,12,5,BRICK:0)
Block(-8,12,6,BRICK_STAIRS:5)
Block(-8,12,7,BRICK:0)
Block(-8,12,8,BRICK:0)
Block(-8,13,-7,CONCRETE:7)
Block(-8,13,-6,CONCRETE:7)
Block(-8,13,-5,CONCRETE:7)
Block(-8,13,-4,CONCRETE:7)
Block(-8,13,-3,BRICK:0)
Block(-8,13,-2,CONCRETE:7)
Block(-8,13,-1,CONCRETE:7)
Block(-8,13,0,CONCRETE:7)
Block(-8,13,1,CONCRETE:7)
Block(-8,13,2,CONCRETE:7)
Block(-8,13,3,CONCRETE:7)
Block(-8,13,4,CONCRETE:7)
Block(-8,13,5,CONCRETE:7)
Block(-8,13,6,BRICK:0)
Block(-8,13,7,CONCRETE:7)
Block(-8,13,8,CONCRETE:7)
Block(-8,14,-7,CONCRETE:7)
Block(-8,14,-6,CONCRETE:7)
Block(-8,14,-5,CONCRETE:7)
Block(-8,14,-4,CONCRETE:7)
Block(-8,14,-3,CONCRETE:7)
Block(-8,14,-2,CONCRETE:7)
Block(-8,14,-1,CONCRETE:7)
Block(-8,14,0,CONCRETE:7)
Block(-8,14,1,CONCRETE:7)
Block(-8,14,2,CONCRETE:7)
Block(-8,14,3,CONCRETE:7)
Block(-8,14,4,CONCRETE:7)
Block(-8,14,5,CONCRETE:7)
Block(-8,14,6,CONCRETE:7)
Block(-8,14,7,CONCRETE:7)
Block(-8,14,8,CONCRETE:7)
Block(-8,15,-7,CONCRETE:7)
Block(-8,15,-6,CONCRETE:7)
Block(-8,15,-5,CONCRETE:7)
Block(-8,15,-4,CONCRETE:7)
Block(-8,15,-3,CONCRETE:7)
Block(-8,15,-2,CONCRETE:7)
Block(-8,15,-1,CONCRETE:7)
Block(-8,15,0,CONCRETE:7)
Block(-8,15,1,CONCRETE:7)
Block(-8,15,2,CONCRETE:7)
Block(-8,15,3,CONCRETE:7)
Block(-8,15,4,CONCRETE:7)
Block(-8,15,5,CONCRETE:7)
Block(-8,15,6,CONCRETE:7)
Block(-8,15,7,CONCRETE:7)
Block(-8,15,8,CONCRETE:7)
Block(-8,16,-7,CONCRETE:7)
Block(-8,16,-6,CONCRETE:7)
Block(-8,16,-5,CONCRETE:7)
Block(-8,16,-4,CONCRETE:7)
Block(-8,16,-3,CONCRETE:7)
Block(-8,16,-2,CONCRETE:7)
Block(-8,16,-1,CONCRETE:7)
Block(-8,16,0,CONCRETE:7)
Block(-8,16,1,CONCRETE:7)
Block(-8,16,2,CONCRETE:7)
Block(-8,16,3,CONCRETE:7)
Block(-8,16,4,CONCRETE:7)
Block(-8,16,5,CONCRETE:7)
Block(-8,16,6,CONCRETE:7)
Block(-8,16,7,CONCRETE:7)
Block(-8,16,8,CONCRETE:7)
Block(-8,17,-7,CONCRETE:15)
Block(-8,17,-6,CONCRETE:15)
Block(-8,17,-5,CONCRETE:15)
Block(-8,17,-4,SMOOTH_STAIRS:0)
Block(-8,17,-3,SMOOTH_STAIRS:0)
Block(-8,17,-2,SMOOTH_STAIRS:0)
Block(-8,17,-1,SMOOTH_STAIRS:0)
Block(-8,17,0,CONCRETE:15)
Block(-8,17,1,CONCRETE:15)
Block(-8,17,2,CONCRETE:15)
Block(-8,17,3,CONCRETE:15)
Block(-8,17,4,CONCRETE:15)
Block(-8,17,5,CONCRETE:15)
Block(-8,17,6,SMOOTH_STAIRS:0)
Block(-8,17,7,SMOOTH_STAIRS:0)
Block(-8,17,8,SMOOTH_STAIRS:0)
Block(-8,28,6,SMOOTH_STAIRS:4)
Block(-8,28,7,SMOOTH_STAIRS:4)
Block(-8,28,8,SMOOTH_STAIRS:4)
Block(-8,29,-6,STEP:8)
Block(-8,29,-5,STEP:8)
Block(-8,29,-4,SMOOTH_STAIRS:4)
Block(-8,29,-3,SMOOTH_STAIRS:4)
Block(-8,29,-2,SMOOTH_STAIRS:4)
Block(-8,29,-1,STEP:8)
Block(-8,29,0,SMOOTH_STAIRS:4)
Block(-8,29,1,STEP:8)
Block(-8,29,2,SMOOTH_STAIRS:4)
Block(-8,29,3,STEP:8)
Block(-8,29,4,SMOOTH_STAIRS:4)
Block(-8,29,5,SMOOTH_STAIRS:4)
Block(-8,29,6,CONCRETE:7)
Block(-8,29,7,CONCRETE:7)
Block(-8,29,8,CONCRETE:15)
Block(-8,30,-4,COBBLE_WALL:0)
Block(-8,30,-2,IRON_FENCE:0)
Block(-8,30,0,IRON_FENCE:0)
Block(-8,30,2,IRON_FENCE:0)
Block(-8,30,3,SMOOTH_STAIRS:6)
Block(-8,30,4,CONCRETE:7)
Block(-8,30,5,CONCRETE:7)
Block(-8,30,6,CONCRETE:15)
Block(-8,30,7,STAINED_GLASS_PANE:7)
Block(-8,30,8,STAINED_GLASS_PANE:7)
Block(-8,31,3,CONCRETE:7)
Block(-8,31,4,CONCRETE:15)
Block(-8,31,5,STAINED_GLASS_PANE:7)
Block(-8,31,6,STAINED_GLASS_PANE:7)
Block(-8,31,7,STAINED_GLASS_PANE:7)
Block(-8,31,8,STAINED_GLASS_PANE:7)
Block(-8,32,2,SMOOTH_STAIRS:6)
Block(-8,32,3,CONCRETE:7)
Block(-8,32,4,STAINED_GLASS_PANE:7)
Block(-8,32,5,STAINED_GLASS_PANE:7)
Block(-8,32,6,STAINED_GLASS_PANE:7)
Block(-8,32,7,STAINED_GLASS_PANE:7)
Block(-8,32,8,STAINED_GLASS_PANE:7)
Block(-8,33,2,CONCRETE:7)
Block(-8,33,3,CONCRETE:15)
Block(-8,33,4,STAINED_GLASS_PANE:7)
Block(-8,33,5,STAINED_GLASS_PANE:7)
Block(-8,33,6,STAINED_GLASS_PANE:7)
Block(-8,33,7,STAINED_GLASS_PANE:7)
Block(-8,33,8,STAINED_GLASS_PANE:7)
Block(-8,34,1,SMOOTH_STAIRS:6)
Block(-8,34,2,CONCRETE:7)
Block(-8,34,3,STAINED_GLASS_PANE:7)
Block(-8,34,4,STAINED_GLASS_PANE:7)
Block(-8,34,5,STAINED_GLASS_PANE:7)
Block(-8,34,6,STAINED_GLASS_PANE:7)
Block(-8,34,7,STAINED_GLASS_PANE:7)
Block(-8,34,8,STAINED_GLASS_PANE:7)
Block(-8,35,1,COBBLE_WALL:0)
Block(-8,35,2,CONCRETE:15)
Block(-8,35,3,STAINED_GLASS_PANE:7)
Block(-8,35,4,STAINED_GLASS_PANE:7)
Block(-8,35,5,STAINED_GLASS_PANE:7)
Block(-8,35,6,STAINED_GLASS_PANE:7)
Block(-8,35,7,STAINED_GLASS_PANE:7)
Block(-8,35,8,STAINED_GLASS_PANE:7)
Block(-8,36,1,COBBLE_WALL:0)
Block(-8,36,2,CONCRETE:15)
Block(-8,36,3,STAINED_GLASS_PANE:7)
Block(-8,36,4,STAINED_GLASS_PANE:7)
Block(-8,36,5,STAINED_GLASS_PANE:7)
Block(-8,36,6,STAINED_GLASS_PANE:7)
Block(-8,36,7,STAINED_GLASS_PANE:7)
Block(-8,36,8,STAINED_GLASS_PANE:7)
Block(-8,37,1,SMOOTH_STAIRS:2)
Block(-8,37,2,CONCRETE:7)
Block(-8,37,3,STAINED_GLASS_PANE:7)
Block(-8,37,4,STAINED_GLASS_PANE:7)
Block(-8,37,5,STAINED_GLASS_PANE:7)
Block(-8,37,6,STAINED_GLASS_PANE:7)
Block(-8,37,7,STAINED_GLASS_PANE:7)
Block(-8,37,8,STAINED_GLASS_PANE:7)
Block(-8,38,2,CONCRETE:7)
Block(-8,38,3,CONCRETE:15)
Block(-8,38,4,STAINED_GLASS_PANE:7)
Block(-8,38,5,STAINED_GLASS_PANE:7)
Block(-8,38,6,STAINED_GLASS_PANE:7)
Block(-8,38,7,STAINED_GLASS_PANE:7)
Block(-8,38,8,STAINED_GLASS_PANE:7)
Block(-8,39,2,SMOOTH_STAIRS:2)
Block(-8,39,3,CONCRETE:7)
Block(-8,39,4,STAINED_GLASS_PANE:7)
Block(-8,39,5,STAINED_GLASS_PANE:7)
Block(-8,39,6,STAINED_GLASS_PANE:7)
Block(-8,39,7,STAINED_GLASS_PANE:7)
Block(-8,39,8,STAINED_GLASS_PANE:7)
Block(-8,40,3,CONCRETE:7)
Block(-8,40,4,CONCRETE:15)
Block(-8,40,5,STAINED_GLASS_PANE:7)
Block(-8,40,6,STAINED_GLASS_PANE:7)
Block(-8,40,7,STAINED_GLASS_PANE:7)
Block(-8,40,8,STAINED_GLASS_PANE:7)
Block(-8,41,3,SMOOTH_STAIRS:2)
Block(-8,41,4,CONCRETE:7)
Block(-8,41,5,CONCRETE:7)
Block(-8,41,6,CONCRETE:15)
Block(-8,41,7,STAINED_GLASS_PANE:7)
Block(-8,41,8,STAINED_GLASS_PANE:7)
Block(-8,42,5,SMOOTH_STAIRS:2)
Block(-8,42,6,CONCRETE:7)
Block(-8,42,7,CONCRETE:7)
Block(-8,42,8,CONCRETE:15)
Block(-8,43,7,SMOOTH_STAIRS:2)
Block(-8,43,8,SMOOTH_STAIRS:0)
Block(-8,60,3,IRON_TRAPDOOR:14)
Block(-8,60,4,IRON_TRAPDOOR:14)
Block(-8,129,7,IRON_FENCE:0)
Block(-8,130,7,IRON_FENCE:0)
Block(-8,131,7,IRON_FENCE:0)
Block(-8,132,7,IRON_FENCE:0)
Block(-8,133,7,COBBLE_WALL:0)
Block(-8,134,7,CONCRETE:8)
Block(-8,139,5,SMOOTH_STAIRS:4)
Block(-8,140,4,STEP:0)
Block(-8,140,5,SMOOTH_STAIRS:1)
Block(-8,140,6,STEP:0)
Block(-8,141,5,SKULL:1,NBT/skyscraper_2x2_02/1-skullC0R0.nbt)
Block(-7,0,-7,CONCRETE:7)
Block(-7,0,-6,CONCRETE:7)
Block(-7,0,-5,CONCRETE:7)
Block(-7,0,-4,CONCRETE:7)
Block(-7,0,-3,CONCRETE:7)
Block(-7,0,-2,CONCRETE:7)
Block(-7,0,-1,CONCRETE:7)
Block(-7,0,0,CONCRETE:7)
Block(-7,0,1,CONCRETE:7)
Block(-7,0,2,CONCRETE:7)
Block(-7,0,3,CONCRETE:7)
Block(-7,0,4,CONCRETE:7)
Block(-7,0,5,CONCRETE:7)
Block(-7,0,6,CONCRETE:7)
Block(-7,0,7,CONCRETE:7)
Block(-7,0,8,CONCRETE:7)
Block(-7,1,-7,CONCRETE:7)
Block(-7,1,-6,CONCRETE:7)
Block(-7,1,-5,CONCRETE:7)
Block(-7,1,-4,CONCRETE:7)
Block(-7,1,-3,CONCRETE:7)
Block(-7,1,-2,CONCRETE:7)
Block(-7,1,-1,CONCRETE:7)
Block(-7,1,0,CONCRETE:7)
Block(-7,1,1,CONCRETE:7)
Block(-7,1,2,CONCRETE:7)
Block(-7,1,3,CONCRETE:7)
Block(-7,1,4,CONCRETE:7)
Block(-7,1,5,CONCRETE:7)
Block(-7,1,6,CONCRETE:7)
Block(-7,1,7,CONCRETE:7)
Block(-7,1,8,CONCRETE:7)
Block(-7,2,-7,CONCRETE:7)
Block(-7,2,-6,CONCRETE:7)
Block(-7,2,-5,CONCRETE:7)
Block(-7,2,-4,CONCRETE:7)
Block(-7,2,-3,CONCRETE:7)
Block(-7,2,-2,CONCRETE:7)
Block(-7,2,-1,CONCRETE:7)
Block(-7,2,0,CONCRETE:7)
Block(-7,2,1,CONCRETE:7)
Block(-7,2,2,CONCRETE:7)
Block(-7,2,3,CONCRETE:7)
Block(-7,2,4,CONCRETE:7)
Block(-7,2,5,CONCRETE:7)
Block(-7,2,6,CONCRETE:7)
Block(-7,2,7,CONCRETE:7)
Block(-7,2,8,CONCRETE:7)
Block(-7,3,-7,CONCRETE:7)
Block(-7,3,-6,CONCRETE:7)
Block(-7,3,-5,CONCRETE:7)
Block(-7,3,-4,CONCRETE:7)
Block(-7,3,-3,CONCRETE:7)
Block(-7,3,-2,CONCRETE:7)
Block(-7,3,-1,CONCRETE:7)
Block(-7,3,0,CONCRETE:7)
Block(-7,3,1,CONCRETE:7)
Block(-7,3,2,CONCRETE:7)
Block(-7,3,3,CONCRETE:7)
Block(-7,3,4,CONCRETE:7)
Block(-7,3,5,CONCRETE:7)
Block(-7,3,6,CONCRETE:7)
Block(-7,3,7,CONCRETE:7)
Block(-7,3,8,CONCRETE:7)
Block(-7,4,-7,CONCRETE:7)
Block(-7,4,-6,CONCRETE:7)
Block(-7,4,-5,CONCRETE:7)
Block(-7,4,-4,CONCRETE:7)
Block(-7,4,-3,CONCRETE:7)
Block(-7,4,-2,CONCRETE:7)
Block(-7,4,-1,CONCRETE:7)
Block(-7,4,0,CONCRETE:7)
Block(-7,4,1,CONCRETE:7)
Block(-7,4,2,CONCRETE:7)
Block(-7,4,3,CONCRETE:7)
Block(-7,4,4,CONCRETE:7)
Block(-7,4,5,CONCRETE:7)
Block(-7,4,6,CONCRETE:7)
Block(-7,4,7,CONCRETE:7)
Block(-7,4,8,CONCRETE:7)
Block(-7,5,-7,CONCRETE:7)
Block(-7,5,-6,CONCRETE:7)
Block(-7,5,-5,CONCRETE:7)
Block(-7,5,-4,CONCRETE:7)
Block(-7,5,-3,CONCRETE:7)
Block(-7,5,-2,CONCRETE:7)
Block(-7,5,-1,CONCRETE:7)
Block(-7,5,0,CONCRETE:7)
Block(-7,5,1,CONCRETE:7)
Block(-7,5,2,CONCRETE:7)
Block(-7,5,3,CONCRETE:7)
Block(-7,5,4,CONCRETE:7)
Block(-7,5,5,CONCRETE:7)
Block(-7,5,6,CONCRETE:7)
Block(-7,5,7,CONCRETE:7)
Block(-7,5,8,CONCRETE:7)
Block(-7,6,-7,CONCRETE:7)
Block(-7,6,-6,CONCRETE:7)
Block(-7,6,-5,CONCRETE:7)
Block(-7,6,-4,CONCRETE:7)
Block(-7,6,-3,CONCRETE:7)
Block(-7,6,-2,CONCRETE:7)
Block(-7,6,-1,CONCRETE:7)
Block(-7,6,0,CONCRETE:7)
Block(-7,6,1,CONCRETE:7)
Block(-7,6,2,CONCRETE:7)
Block(-7,6,3,CONCRETE:7)
Block(-7,6,4,CONCRETE:7)
Block(-7,6,5,CONCRETE:7)
Block(-7,6,6,CONCRETE:7)
Block(-7,6,7,CONCRETE:7)
Block(-7,6,8,CONCRETE:7)
Block(-7,7,-7,CONCRETE:7)
Block(-7,7,-6,CONCRETE:15)
Block(-7,7,-5,CONCRETE:7)
Block(-7,7,-4,CONCRETE:15)
Block(-7,7,-3,CONCRETE:15)
Block(-7,7,-2,CONCRETE:15)
Block(-7,7,-1,CONCRETE:15)
Block(-7,7,0,CONCRETE:15)
Block(-7,7,1,CONCRETE:15)
Block(-7,7,2,CONCRETE:15)
Block(-7,7,3,CONCRETE:15)
Block(-7,7,4,CONCRETE:15)
Block(-7,7,5,CONCRETE:15)
Block(-7,7,6,CONCRETE:15)
Block(-7,7,7,CONCRETE:15)
Block(-7,7,8,CONCRETE:15)
Block(-7,8,-7,BRICK:0)
Block(-7,8,-5,CONCRETE:11)
Block(-7,8,-4,CONCRETE:11)
Block(-7,8,-3,CONCRETE:11)
Block(-7,8,-2,CONCRETE:11)
Block(-7,8,0,CONCRETE:4)
Block(-7,8,1,CONCRETE:7)
Block(-7,8,2,CONCRETE:7)
Block(-7,8,3,CONCRETE:7)
Block(-7,8,4,CONCRETE:7)
Block(-7,8,5,CONCRETE:7)
Block(-7,8,6,CONCRETE:7)
Block(-7,8,7,BRICK_STAIRS:3)
Block(-7,9,-7,BRICK_STAIRS:3)
Block(-7,9,-5,SMOOTH_STAIRS:2)
Block(-7,9,-4,CONCRETE:11)
Block(-7,9,-3,CONCRETE:11)
Block(-7,9,-2,SMOOTH_STAIRS:3)
Block(-7,9,0,CONCRETE:4)
Block(-7,9,1,IRON_FENCE:0)
Block(-7,9,2,SMOOTH_STAIRS:2)
Block(-7,9,3,DROPPER:5,NBT/skyscraper_2x2_02/3-dropperC0R0.nbt)
#RandomBlock(-7,9,4,TRAPPED_CHEST:5,../../../../../Chests/Loot/ModernCityJunk_1.nbt,65,CHEST:5,../../../../../Chests/Loot/ModernCityJunk_1.nbt,20,CHEST:5,../../../../../Chests/Loot/ModernCityJunk_2.nbt,15,CHEST:5,../../../../../Chests/Loot/ModernCityJunk_3.nbt,15,CHEST:5,../../../../../Chests/Loot/ModernCityJunk_4.nbt,15,CHEST:5,../../../../../Chests/Loot/ModernCityJunk_5.nbt,15,CHEST:5,../../../../../Chests/Loot/ModernCityCommon_1.nbt,5,CHEST:5,../../../../../Chests/Loot/ModernCityCommon_2.nbt,5,CHEST:5,../../../../../Chests/Loot/ModernCityCommon_3.nbt,5,CHEST:5,../../../../../Chests/Loot/ModernCityCommon_4.nbt,5,CHEST:5,../../../../../Chests/Loot/ModernCityCommon_5.nbt,5,CHEST:5,../../../../../Chests/Loot/ModernCityGood_1.nbt,3,CHEST:5,../../../../../Chests/Loot/ModernCityGood_2.nbt,3,CHEST:5,../../../../../Chests/Loot/ModernCityGood_3.nbt,3,CHEST:5,../../../../../Chests/Loot/ModernCityGood_4.nbt,3,CHEST:5,../../../../../Chests/Loot/ModernCityGood_5.nbt,3,CHEST:5,../../../../../Chests/Loot/ModernCityEpic_1.nbt,1,CHEST:5,../../../../../Chests/Loot/ModernCityEpic_2.nbt,1,CHEST:5,../../../../../Chests/Loot/ModernCityEpic_3.nbt,1,CHEST:5,../../../../../Chests/Loot/ModernCityEpic_4.nbt,1,CHEST:5,../../../../../Chests/Loot/ModernCityEpic_5.nbt,1,CHEST:5,../../../../../Chests/Loot/Common1.nbt,25,CHEST:5,../../../../../Chests/Loot/Common2.nbt,25,CHEST:5,../../../../../Chests/Loot/Common3.nbt,25,CHEST:5,../../../../../Chests/Loot/Common4.nbt,25,CHEST:5,../../../../../Chests/Loot/Common5.nbt,25,CHEST:5,../../../../../Chests/Loot/Common6.nbt,25,CHEST:5,../../../../../Chests/Loot/Common7.nbt,25,CHEST:5,../../../../../Chests/Loot/Common8.nbt,25,CHEST:5,../../../../../Chests/Loot/Common9.nbt,25,CHEST:5,../../../../../Chests/Loot/Common10.nbt,25,CHEST:5,../../../../../Chests/Loot/Common11.nbt,25,CHEST:5,../../../../../Chests/Loot/Common12.nbt,25,CHEST:5,../../../../../Chests/Loot/Common13.nbt,25,CHEST:5,../../../../../Chests/Loot/Common14.nbt,25,CHEST:5,../../../../../Chests/Loot/Common15.nbt,25,CHEST:5,../../../../../Chests/Loot/Rare1.nbt,10,CHEST:5,../../../../../Chests/Loot/Rare2.nbt,10,CHEST:5,../../../../../Chests/Loot/Rare3.nbt,10,CHEST:5,../../../../../Chests/Loot/Rare4.nbt,10,CHEST:5,../../../../../Chests/Loot/Rare5.nbt,10,CHEST:5,../../../../../Chests/Loot/Rare6.nbt,10,CHEST:5,../../../../../Chests/Loot/Rare7.nbt,10,CHEST:5,../../../../../Chests/Loot/Rare8.nbt,10,CHEST:5,../../../../../Chests/Loot/Rare9.nbt,10,CHEST:5,../../../../../Chests/Loot/Rare10.nbt,10,CHEST:5,../../../../../Chests/Loot/Rare11.nbt,10,CHEST:5,../../../../../Chests/Loot/Rare12.nbt,10,CHEST:5,../../../../../Chests/Loot/Rare13.nbt,10,CHEST:5,../../../../../Chests/Loot/Rare14.nbt,10,CHEST:5,../../../../../Chests/Loot/Rare15.nbt,10,CHEST:5,../../../../../Chests/Loot/Epic1.nbt,1,CHEST:5,../../../../../Chests/Loot/Epic2.nbt,1,CHEST:5,../../../../../Chests/Loot/Epic3.nbt,1,CHEST:5,../../../../../Chests/Loot/Epic4.nbt,1,CHEST:5,../../../../../Chests/Loot/Epic5.nbt,1,CHEST:5,../../../../../Chests/Loot/Epic6.nbt,1,CHEST:5,../../../../../Chests/Loot/Epic7.nbt,1,CHEST:5,../../../../../Chests/Loot/Epic8.nbt,1,CHEST:5,../../../../../Chests/Loot/Epic9.nbt,1,CHEST:5,../../../../../Chests/Loot/Epic10.nbt,1,CHEST:5,../../../../../Chests/Loot/Epic11.nbt,1,CHEST:5,../../../../../Chests/Loot/Epic12.nbt,1,CHEST:5,../../../../../Chests/Loot/Epic13.nbt,1,CHEST:5,../../../../../Chests/Loot/Epic14.nbt,1,CHEST:5,../../../../../Chests/Loot/Epic15.nbt,1,CHEST:5,../../../../../Chests/Loot/ModernCityJunk_1.nbt,100)
Block(-7,9,5,WORKBENCH:0)
Block(-7,9,6,SMOOTH_STAIRS:3)
Block(-7,9,7,IRON_FENCE:0)
Block(-7,10,-7,BRICK:0)
Block(-7,10,-4,SMOOTH_STAIRS:2)
Block(-7,10,-3,SMOOTH_STAIRS:3)
Block(-7,10,0,CONCRETE:4)
Block(-7,10,2,SMOOTH_STAIRS:6)
Block(-7,10,3,REDSTONE_LAMP_OFF:0)
#RandomBlock(-7,10,4,TRAPPED_CHEST:5,../../../../../Chests/Loot/ModernCityJunk_1.nbt,65,CHEST:5,../../../../../Chests/Loot/ModernCityJunk_1.nbt,20,CHEST:5,../../../../../Chests/Loot/ModernCityJunk_2.nbt,15,CHEST:5,../../../../../Chests/Loot/ModernCityJunk_3.nbt,15,CHEST:5,../../../../../Chests/Loot/ModernCityJunk_4.nbt,15,CHEST:5,../../../../../Chests/Loot/ModernCityJunk_5.nbt,15,CHEST:5,../../../../../Chests/Loot/ModernCityCommon_1.nbt,5,CHEST:5,../../../../../Chests/Loot/ModernCityCommon_2.nbt,5,CHEST:5,../../../../../Chests/Loot/ModernCityCommon_3.nbt,5,CHEST:5,../../../../../Chests/Loot/ModernCityCommon_4.nbt,5,CHEST:5,../../../../../Chests/Loot/ModernCityCommon_5.nbt,5,CHEST:5,../../../../../Chests/Loot/ModernCityGood_1.nbt,3,CHEST:5,../../../../../Chests/Loot/ModernCityGood_2.nbt,3,CHEST:5,../../../../../Chests/Loot/ModernCityGood_3.nbt,3,CHEST:5,../../../../../Chests/Loot/ModernCityGood_4.nbt,3,CHEST:5,../../../../../Chests/Loot/ModernCityGood_5.nbt,3,CHEST:5,../../../../../Chests/Loot/ModernCityEpic_1.nbt,1,CHEST:5,../../../../../Chests/Loot/ModernCityEpic_2.nbt,1,CHEST:5,../../../../../Chests/Loot/ModernCityEpic_3.nbt,1,CHEST:5,../../../../../Chests/Loot/ModernCityEpic_4.nbt,1,CHEST:5,../../../../../Chests/Loot/ModernCityEpic_5.nbt,1,CHEST:5,../../../../../Chests/Loot/Common1.nbt,25,CHEST:5,../../../../../Chests/Loot/Common2.nbt,25,CHEST:5,../../../../../Chests/Loot/Common3.nbt,25,CHEST:5,../../../../../Chests/Loot/Common4.nbt,25,CHEST:5,../../../../../Chests/Loot/Common5.nbt,25,CHEST:5,../../../../../Chests/Loot/Common6.nbt,25,CHEST:5,../../../../../Chests/Loot/Common7.nbt,25,CHEST:5,../../../../../Chests/Loot/Common8.nbt,25,CHEST:5,../../../../../Chests/Loot/Common9.nbt,25,CHEST:5,../../../../../Chests/Loot/Common10.nbt,25,CHEST:5,../../../../../Chests/Loot/Common11.nbt,25,CHEST:5,../../../../../Chests/Loot/Common12.nbt,25,CHEST:5,../../../../../Chests/Loot/Common13.nbt,25,CHEST:5,../../../../../Chests/Loot/Common14.nbt,25,CHEST:5,../../../../../Chests/Loot/Common15.nbt,25,CHEST:5,../../../../../Chests/Loot/Rare1.nbt,10,CHEST:5,../../../../../Chests/Loot/Rare2.nbt,10,CHEST:5,../../../../../Chests/Loot/Rare3.nbt,10,CHEST:5,../../../../../Chests/Loot/Rare4.nbt,10,CHEST:5,../../../../../Chests/Loot/Rare5.nbt,10,CHEST:5,../../../../../Chests/Loot/Rare6.nbt,10,CHEST:5,../../../../../Chests/Loot/Rare7.nbt,10,CHEST:5,../../../../../Chests/Loot/Rare8.nbt,10,CHEST:5,../../../../../Chests/Loot/Rare9.nbt,10,CHEST:5,../../../../../Chests/Loot/Rare10.nbt,10,CHEST:5,../../../../../Chests/Loot/Rare11.nbt,10,CHEST:5,../../../../../Chests/Loot/Rare12.nbt,10,CHEST:5,../../../../../Chests/Loot/Rare13.nbt,10,CHEST:5,../../../../../Chests/Loot/Rare14.nbt,10,CHEST:5,../../../../../Chests/Loot/Rare15.nbt,10,CHEST:5,../../../../../Chests/Loot/Epic1.nbt,1,CHEST:5,../../../../../Chests/Loot/Epic2.nbt,1,CHEST:5,../../../../../Chests/Loot/Epic3.nbt,1,CHEST:5,../../../../../Chests/Loot/Epic4.nbt,1,CHEST:5,../../../../../Chests/Loot/Epic5.nbt,1,CHEST:5,../../../../../Chests/Loot/Epic6.nbt,1,CHEST:5,../../../../../Chests/Loot/Epic7.nbt,1,CHEST:5,../../../../../Chests/Loot/Epic8.nbt,1,CHEST:5,../../../../../Chests/Loot/Epic9.nbt,1,CHEST:5,../../../../../Chests/Loot/Epic10.nbt,1,CHEST:5,../../../../../Chests/Loot/Epic11.nbt,1,CHEST:5,../../../../../Chests/Loot/Epic12.nbt,1,CHEST:5,../../../../../Chests/Loot/Epic13.nbt,1,CHEST:5,../../../../../Chests/Loot/Epic14.nbt,1,CHEST:5,../../../../../Chests/Loot/Epic15.nbt,1,CHEST:5,../../../../../Chests/Loot/ModernCityJunk_1.nbt,100)
Block(-7,10,5,FURNACE:5,NBT/skyscraper_2x2_02/6-furnaceC0R0.nbt)
Block(-7,10,6,SMOOTH_STAIRS:7)
Block(-7,11,-7,BRICK_STAIRS:7)
Block(-7,11,0,CONCRETE:4)
Block(-7,11,2,STEP:0)
Block(-7,11,3,STEP:0)
Block(-7,11,4,STEP:0)
Block(-7,11,5,STEP:0)
Block(-7,11,6,STEP:0)
Block(-7,12,-7,BRICK_STAIRS:5)
Block(-7,12,0,CONCRETE:4)
Block(-7,13,-7,BRICK_STAIRS:7)
Block(-7,13,-5,SMOOTH_STAIRS:5)
Block(-7,13,0,GOLD_PLATE:0)
Block(-7,13,1,SMOOTH_STAIRS:5)
Block(-7,13,3,CONCRETE:1)
Block(-7,13,7,SMOOTH_STAIRS:5)
Block(-7,14,-7,CONCRETE:7)
Block(-7,14,-6,SMOOTH_STAIRS:5)
Block(-7,14,-5,CONCRETE:7)
Block(-7,14,-4,SMOOTH_STAIRS:5)
Block(-7,14,-3,SMOOTH_STAIRS:5)
Block(-7,14,-2,CONCRETE:14)
Block(-7,14,-1,SMOOTH_STAIRS:5)
Block(-7,14,0,SMOOTH_STAIRS:5)
Block(-7,14,1,CONCRETE:7)
Block(-7,14,2,SMOOTH_STAIRS:5)
Block(-7,14,3,SMOOTH_STAIRS:5)
Block(-7,14,4,CONCRETE:7)
Block(-7,14,5,SMOOTH_STAIRS:5)
Block(-7,14,6,SMOOTH_STAIRS:5)
Block(-7,14,7,CONCRETE:7)
Block(-7,14,8,SMOOTH_STAIRS:5)
Block(-7,15,-7,CONCRETE:7)
Block(-7,15,-6,CONCRETE:7)
Block(-7,15,-5,CONCRETE:7)
Block(-7,15,-4,CONCRETE:7)
Block(-7,15,-3,CONCRETE:7)
Block(-7,15,-2,CONCRETE:7)
Block(-7,15,-1,CONCRETE:7)
Block(-7,15,0,CONCRETE:7)
Block(-7,15,1,CONCRETE:7)
Block(-7,15,2,CONCRETE:7)
Block(-7,15,3,CONCRETE:7)
Block(-7,15,4,CONCRETE:7)
Block(-7,15,5,CONCRETE:7)
Block(-7,15,6,CONCRETE:7)
Block(-7,15,7,CONCRETE:7)
Block(-7,15,8,CONCRETE:7)
Block(-7,16,-7,CONCRETE:7)
Block(-7,16,-6,CONCRETE:7)
Block(-7,16,-5,CONCRETE:7)
Block(-7,16,-4,CONCRETE:7)
Block(-7,16,-3,CONCRETE:7)
Block(-7,16,-2,CONCRETE:7)
Block(-7,16,-1,CONCRETE:7)
Block(-7,16,0,CONCRETE:7)
Block(-7,16,1,CONCRETE:7)
Block(-7,16,2,CONCRETE:7)
Block(-7,16,3,CONCRETE:7)
Block(-7,16,4,CONCRETE:7)
Block(-7,16,5,CONCRETE:7)
Block(-7,16,6,CONCRETE:7)
Block(-7,16,7,CONCRETE:7)
Block(-7,16,8,CONCRETE:7)
Block(-7,17,-7,CONCRETE:15)
Block(-7,17,-6,CONCRETE:7)
Block(-7,17,-5,CONCRETE:7)
Block(-7,17,-4,CONCRETE:7)
Block(-7,17,-3,CONCRETE:7)
Block(-7,17,-2,CONCRETE:7)
Block(-7,17,-1,CONCRETE:7)
Block(-7,17,0,CONCRETE:7)
Block(-7,17,1,CONCRETE:7)
Block(-7,17,2,CONCRETE:7)
Block(-7,17,3,CONCRETE:7)
Block(-7,17,4,CONCRETE:7)
Block(-7,17,5,CONCRETE:7)
Block(-7,17,6,CONCRETE:7)
Block(-7,17,7,CONCRETE:7)
Block(-7,17,8,CONCRETE:7)
Block(-7,18,-4,SMOOTH_STAIRS:0)
Block(-7,18,-3,CONCRETE:0)
Block(-7,18,-2,SMOOTH_STAIRS:0)
Block(-7,18,4,SMOOTH_STAIRS:2)
Block(-7,18,5,SMOOTH_STAIRS:0)
Block(-7,18,6,CONCRETE:7)
Block(-7,18,7,CONCRETE:8)
Block(-7,18,8,CONCRETE:7)
Block(-7,19,-3,SMOOTH_STAIRS:0)
Block(-7,19,6,CONCRETE:7)
Block(-7,19,7,STAINED_GLASS_PANE:7)
Block(-7,19,8,STAINED_GLASS_PANE:7)
Block(-7,20,6,STEP:0)
Block(-7,20,7,STAINED_GLASS_PANE:7)
Block(-7,20,8,STAINED_GLASS_PANE:7)
Block(-7,21,7,STAINED_GLASS_PANE:7)
Block(-7,21,8,STAINED_GLASS_PANE:7)
Block(-7,22,7,STAINED_GLASS_PANE:7)
Block(-7,22,8,STAINED_GLASS_PANE:7)
Block(-7,23,7,STAINED_GLASS_PANE:7)
Block(-7,23,8,STAINED_GLASS_PANE:7)
Block(-7,24,7,STAINED_GLASS_PANE:7)
Block(-7,24,8,STAINED_GLASS_PANE:7)
Block(-7,25,6,STEP:8)
Block(-7,25,7,STAINED_GLASS_PANE:7)
Block(-7,25,8,STAINED_GLASS_PANE:7)
Block(-7,26,-3,SMOOTH_STAIRS:4)
Block(-7,26,6,CONCRETE:7)
Block(-7,26,7,STAINED_GLASS_PANE:7)
Block(-7,26,8,STAINED_GLASS_PANE:7)
Block(-7,27,-4,SMOOTH_STAIRS:4)
Block(-7,27,-3,CONCRETE:0)
Block(-7,27,-2,SMOOTH_STAIRS:4)
Block(-7,27,4,SMOOTH_STAIRS:6)
Block(-7,27,5,SMOOTH_STAIRS:4)
Block(-7,27,6,CONCRETE:7)
Block(-7,27,7,CONCRETE:8)
Block(-7,27,8,CONCRETE:7)
Block(-7,28,-6,CONCRETE:15)
Block(-7,28,-5,SMOOTH_STAIRS:4)
Block(-7,28,-4,CONCRETE:15)
Block(-7,28,-3,CONCRETE:7)
Block(-7,28,-2,CONCRETE:7)
Block(-7,28,-1,SMOOTH_STAIRS:4)
Block(-7,28,0,CONCRETE:15)
Block(-7,28,1,SMOOTH_STAIRS:4)
Block(-7,28,2,CONCRETE:15)
Block(-7,28,3,SMOOTH_STAIRS:4)
Block(-7,28,4,CONCRETE:15)
Block(-7,28,5,CONCRETE:15)
Block(-7,28,6,CONCRETE:7)
Block(-7,28,7,CONCRETE:7)
Block(-7,28,8,CONCRETE:7)
Block(-7,29,-7,STEP:8)
Block(-7,29,-6,CONCRETE:8)
Block(-7,29,-5,CONCRETE:7)
Block(-7,29,-4,CONCRETE:7)
Block(-7,29,-3,CONCRETE:7)
Block(-7,29,-2,CONCRETE:7)
Block(-7,29,-1,CONCRETE:7)
Block(-7,29,0,CONCRETE:7)
Block(-7,29,1,CONCRETE:7)
Block(-7,29,2,CONCRETE:7)
Block(-7,29,3,CONCRETE:7)
Block(-7,29,4,CONCRETE:7)
Block(-7,29,5,CONCRETE:7)
Block(-7,29,6,CONCRETE:7)
Block(-7,29,7,CONCRETE:7)
Block(-7,29,8,CONCRETE:7)
Block(-7,30,-6,STEP:0)
Block(-7,30,-5,CONCRETE:8)
Block(-7,30,-4,CONCRETE:15)
Block(-7,30,-3,CONCRETE:15)
Block(-7,30,-2,CONCRETE:7)
Block(-7,30,-1,SMOOTH_STAIRS:4)
Block(-7,30,0,CONCRETE:7)
Block(-7,30,1,STEP:0)
Block(-7,30,2,CONCRETE:7)
Block(-7,30,3,CONCRETE:7)
Block(-7,30,4,CONCRETE:7)
Block(-7,30,5,CONCRETE:15)
Block(-7,30,6,CONCRETE:15)
Block(-7,30,7,CONCRETE:15)
Block(-7,31,-4,CONCRETE:8)
Block(-7,31,-3,CONCRETE:8)
Block(-7,31,-2,CONCRETE:15)
Block(-7,31,-1,CONCRETE:7)
Block(-7,31,0,CONCRETE:7)
Block(-7,31,1,SMOOTH_STAIRS:4)
Block(-7,31,2,CONCRETE:7)
Block(-7,31,3,CONCRETE:7)
Block(-7,31,4,CONCRETE:15)
Block(-7,31,7,CONCRETE:15)
Block(-7,32,-3,SMOOTH_STAIRS:2)
Block(-7,32,-2,CONCRETE:8)
Block(-7,32,-1,CONCRETE:15)
Block(-7,32,0,CONCRETE:7)
Block(-7,32,1,CONCRETE:7)
Block(-7,32,2,CONCRETE:7)
Block(-7,32,3,CONCRETE:15)
Block(-7,32,7,CONCRETE:15)
Block(-7,33,-2,SMOOTH_STAIRS:0)
Block(-7,33,-1,CONCRETE:8)
Block(-7,33,0,CONCRETE:15)
Block(-7,33,1,CONCRETE:7)
Block(-7,33,2,CONCRETE:7)
Block(-7,33,3,CONCRETE:15)
Block(-7,33,8,CONCRETE:15)
Block(-7,34,-1,CONCRETE:8)
Block(-7,34,0,CONCRETE:15)
Block(-7,34,1,CONCRETE:15)
Block(-7,34,2,CONCRETE:15)
Block(-7,34,8,CONCRETE:15)
Block(-7,35,-1,SMOOTH_STAIRS:2)
Block(-7,35,0,CONCRETE:8)
Block(-7,35,1,CONCRETE:15)
Block(-7,35,2,CONCRETE:15)
Block(-7,36,-6,SEA_LANTERN:0)
Block(-7,36,0,CONCRETE:8)
Block(-7,36,1,CONCRETE:15)
Block(-7,36,2,CONCRETE:15)
Block(-7,36,8,CONCRETE:14)
Block(-7,37,-6,IRON_FENCE:0)
Block(-7,37,0,CONCRETE:8)
Block(-7,37,1,CONCRETE:15)
Block(-7,37,2,CONCRETE:15)
Block(-7,37,6,CONCRETE:14)
Block(-7,37,7,CONCRETE:14)
Block(-7,38,-6,IRON_FENCE:0)
Block(-7,38,-1,SMOOTH_STAIRS:6)
Block(-7,38,0,CONCRETE:8)
Block(-7,38,1,STEP:0)
Block(-7,38,2,CONCRETE:7)
Block(-7,38,3,CONCRETE:15)
Block(-7,38,5,CONCRETE:14)
Block(-7,39,-6,IRON_FENCE:0)
Block(-7,39,-1,CONCRETE:8)
Block(-7,39,0,STEP:0)
Block(-7,39,2,CONCRETE:7)
Block(-7,39,3,CONCRETE:15)
Block(-7,40,-6,IRON_FENCE:0)
Block(-7,40,-2,SMOOTH_STAIRS:4)
Block(-7,40,-1,CONCRETE:8)
Block(-7,40,3,CONCRETE:7)
Block(-7,40,4,CONCRETE:15)
Block(-7,41,-6,IRON_FENCE:0)
Block(-7,41,-3,SMOOTH_STAIRS:6)
Block(-7,41,-2,CONCRETE:8)
Block(-7,41,-1,STEP:0)
Block(-7,41,3,CONCRETE:7)
Block(-7,41,4,CONCRETE:7)
Block(-7,41,5,CONCRETE:15)
Block(-7,41,6,CONCRETE:15)
Block(-7,42,-6,IRON_FENCE:0)
Block(-7,42,-4,CONCRETE:8)
Block(-7,42,-3,CONCRETE:8)
Block(-7,42,-2,STEP:0)
Block(-7,42,4,STEP:0)
Block(-7,42,5,CONCRETE:7)
Block(-7,42,6,CONCRETE:7)
Block(-7,42,7,CONCRETE:15)
Block(-7,42,8,CONCRETE:15)
Block(-7,43,-6,IRON_FENCE:0)
Block(-7,43,-5,CONCRETE:8)
Block(-7,43,-4,STEP:0)
Block(-7,43,-3,STEP:0)
Block(-7,43,6,STEP:0)
Block(-7,43,7,CONCRETE:7)
Block(-7,43,8,CONCRETE:7)
Block(-7,44,-6,CONCRETE:8)
Block(-7,44,-5,STEP:0)
Block(-7,44,7,CONCRETE:7)
Block(-7,44,8,IRON_FENCE:0)
Block(-7,45,-6,CONCRETE:8)
Block(-7,45,7,CONCRETE:7)
Block(-7,46,-6,STEP:0)
Block(-7,46,7,COBBLE_WALL:0)
Block(-7,59,2,STEP:8)
Block(-7,59,3,STEP:8)
Block(-7,59,4,STEP:8)
Block(-7,59,5,STEP:8)
Block(-7,60,2,SMOOTH_STAIRS:6)
Block(-7,60,3,LEVER:11)
Block(-7,60,4,LEVER:12)
Block(-7,60,5,SMOOTH_STAIRS:7)
Block(-7,61,2,IRON_FENCE:0)
Block(-7,61,5,IRON_FENCE:0)
Block(-7,62,2,IRON_FENCE:0)
Block(-7,62,5,IRON_FENCE:0)
Block(-7,63,2,IRON_FENCE:0)
Block(-7,63,5,IRON_FENCE:0)
Block(-7,64,2,IRON_FENCE:0)
Block(-7,64,5,IRON_FENCE:0)
Block(-7,65,2,IRON_FENCE:0)
Block(-7,65,5,IRON_FENCE:0)
Block(-7,66,2,IRON_FENCE:0)
Block(-7,66,5,IRON_FENCE:0)
Block(-7,67,2,IRON_FENCE:0)
Block(-7,67,5,IRON_FENCE:0)
Block(-7,68,2,IRON_FENCE:0)
Block(-7,68,5,IRON_FENCE:0)
Block(-7,68,7,IRON_FENCE:0)
Block(-7,69,2,IRON_FENCE:0)
Block(-7,69,5,IRON_FENCE:0)
Block(-7,69,7,IRON_FENCE:0)
Block(-7,70,2,IRON_FENCE:0)
Block(-7,70,5,IRON_FENCE:0)
Block(-7,70,7,IRON_FENCE:0)
Block(-7,71,2,IRON_FENCE:0)
Block(-7,71,5,IRON_FENCE:0)
Block(-7,71,7,IRON_FENCE:0)
Block(-7,72,2,IRON_FENCE:0)
Block(-7,72,5,IRON_FENCE:0)
Block(-7,72,7,IRON_FENCE:0)
Block(-7,73,2,IRON_FENCE:0)
Block(-7,73,5,IRON_FENCE:0)
Block(-7,73,7,IRON_FENCE:0)
Block(-7,74,2,IRON_FENCE:0)
Block(-7,74,5,IRON_FENCE:0)
Block(-7,74,7,IRON_FENCE:0)
Block(-7,75,2,IRON_FENCE:0)
Block(-7,75,5,IRON_FENCE:0)
Block(-7,75,7,IRON_FENCE:0)
Block(-7,76,2,IRON_FENCE:0)
Block(-7,76,5,IRON_FENCE:0)
Block(-7,76,7,IRON_FENCE:0)
Block(-7,77,2,IRON_FENCE:0)
Block(-7,77,5,IRON_FENCE:0)
Block(-7,77,7,IRON_FENCE:0)
Block(-7,78,2,IRON_FENCE:0)
Block(-7,78,5,IRON_FENCE:0)
Block(-7,78,7,IRON_FENCE:0)
Block(-7,79,2,IRON_FENCE:0)
Block(-7,79,5,IRON_FENCE:0)
Block(-7,79,7,IRON_FENCE:0)
Block(-7,80,2,IRON_FENCE:0)
Block(-7,80,5,IRON_FENCE:0)
Block(-7,80,7,IRON_FENCE:0)
Block(-7,81,2,IRON_FENCE:0)
Block(-7,81,5,IRON_FENCE:0)
Block(-7,81,7,COBBLE_WALL:0)
Block(-7,82,2,IRON_FENCE:0)
Block(-7,82,5,IRON_FENCE:0)
Block(-7,82,7,CONCRETE:8)
Block(-7,83,2,IRON_FENCE:0)
Block(-7,83,5,IRON_FENCE:0)
Block(-7,83,7,SMOOTH_STAIRS:0)
Block(-7,84,2,COBBLE_WALL:0)
Block(-7,84,5,COBBLE_WALL:0)
Block(-7,84,6,SMOOTH_STAIRS:4)
Block(-7,85,2,CONCRETE:8)
Block(-7,85,5,CONCRETE:8)
Block(-7,85,6,CONCRETE:7)
Block(-7,85,8,SMOOTH_STAIRS:4)
Block(-7,86,2,SMOOTH_STAIRS:0)
Block(-7,86,5,SMOOTH_STAIRS:4)
Block(-7,86,6,CONCRETE:7)
Block(-7,86,8,CONCRETE:7)
Block(-7,87,2,SMOOTH_STAIRS:4)
Block(-7,87,3,STEP:8)
Block(-7,87,4,SMOOTH_STAIRS:6)
Block(-7,87,5,CONCRETE:7)
Block(-7,87,6,LAPIS_BLOCK:0)
Block(-7,87,8,SMOOTH_STAIRS:0)
Block(-7,88,1,SMOOTH_STAIRS:6)
Block(-7,88,2,CONCRETE:7)
Block(-7,88,3,CONCRETE:7)
Block(-7,88,4,CONCRETE:7)
Block(-7,88,5,SMOOTH_STAIRS:0)
Block(-7,88,6,SMOOTH_STAIRS:0)
Block(-7,89,-1,SMOOTH_STAIRS:4)
Block(-7,89,0,CONCRETE:7)
Block(-7,89,1,CONCRETE:7)
Block(-7,89,2,SMOOTH_STAIRS:0)
Block(-7,89,3,STEP:0)
Block(-7,90,-1,CONCRETE:7)
Block(-7,90,0,SMOOTH_STAIRS:3)
Block(-7,90,1,PRISMARINE:0)
Block(-7,90,3,PRISMARINE:0)
Block(-7,90,5,PRISMARINE:0)
Block(-7,90,6,SEA_LANTERN:0)
Block(-7,90,7,PRISMARINE:0)
Block(-7,91,-1,CONCRETE:7)
Block(-7,91,1,PRISMARINE:0)
Block(-7,91,2,PRISMARINE:0)
Block(-7,91,3,PRISMARINE:0)
Block(-7,91,5,PRISMARINE:0)
Block(-7,91,7,PRISMARINE:0)
Block(-7,92,-1,CONCRETE:7)
Block(-7,92,0,SMOOTH_STAIRS:7)
Block(-7,92,1,SEA_LANTERN:0)
Block(-7,92,3,PRISMARINE:0)
Block(-7,92,5,PRISMARINE:0)
Block(-7,92,6,PRISMARINE:0)
Block(-7,92,7,PRISMARINE:0)
Block(-7,93,-1,SMOOTH_STAIRS:0)
Block(-7,93,0,CONCRETE:7)
Block(-7,93,1,CONCRETE:7)
Block(-7,93,2,SMOOTH_STAIRS:4)
Block(-7,93,3,STEP:8)
Block(-7,94,1,SMOOTH_STAIRS:2)
Block(-7,94,2,CONCRETE:7)
Block(-7,94,3,CONCRETE:7)
Block(-7,94,4,CONCRETE:7)
Block(-7,94,5,SMOOTH_STAIRS:4)
Block(-7,94,6,SMOOTH_STAIRS:4)
Block(-7,95,2,SMOOTH_STAIRS:0)
Block(-7,95,3,STEP:0)
Block(-7,95,4,SMOOTH_STAIRS:2)
Block(-7,95,5,CONCRETE:7)
Block(-7,95,6,LAPIS_BLOCK:0)
Block(-7,95,8,SMOOTH_STAIRS:4)
Block(-7,96,5,SMOOTH_STAIRS:0)
Block(-7,96,6,CONCRETE:7)
Block(-7,96,8,CONCRETE:7)
Block(-7,97,6,CONCRETE:7)
Block(-7,97,8,SMOOTH_STAIRS:0)
Block(-7,98,6,SMOOTH_STAIRS:0)
Block(-7,106,2,IRON_FENCE:0)
Block(-7,107,2,IRON_FENCE:0)
Block(-7,108,2,IRON_FENCE:0)
Block(-7,108,5,IRON_FENCE:0)
Block(-7,109,2,IRON_FENCE:0)
Block(-7,109,5,IRON_FENCE:0)
Block(-7,110,2,IRON_FENCE:0)
Block(-7,110,5,IRON_FENCE:0)
Block(-7,111,2,IRON_FENCE:0)
Block(-7,111,5,IRON_FENCE:0)
Block(-7,112,2,IRON_FENCE:0)
Block(-7,112,5,IRON_FENCE:0)
Block(-7,113,2,IRON_FENCE:0)
Block(-7,113,5,IRON_FENCE:0)
Block(-7,114,2,IRON_FENCE:0)
Block(-7,114,5,IRON_FENCE:0)
Block(-7,115,2,IRON_FENCE:0)
Block(-7,115,5,IRON_FENCE:0)
Block(-7,116,2,IRON_FENCE:0)
Block(-7,116,5,IRON_FENCE:0)
Block(-7,117,2,IRON_FENCE:0)
Block(-7,117,5,IRON_FENCE:0)
Block(-7,118,2,IRON_FENCE:0)
Block(-7,118,5,IRON_FENCE:0)
Block(-7,119,2,IRON_FENCE:0)
Block(-7,119,5,IRON_FENCE:0)
Block(-7,120,2,IRON_FENCE:0)
Block(-7,120,5,IRON_FENCE:0)
Block(-7,121,2,IRON_FENCE:0)
Block(-7,121,5,IRON_FENCE:0)
Block(-7,122,2,IRON_FENCE:0)
Block(-7,122,5,IRON_FENCE:0)
Block(-7,123,2,IRON_FENCE:0)
Block(-7,123,5,IRON_FENCE:0)
Block(-7,124,2,IRON_FENCE:0)
Block(-7,124,5,IRON_FENCE:0)
Block(-7,125,2,IRON_FENCE:0)
Block(-7,125,5,IRON_FENCE:0)
Block(-7,126,2,IRON_FENCE:0)
Block(-7,126,5,IRON_FENCE:0)
Block(-7,127,2,IRON_FENCE:0)
Block(-7,127,5,IRON_FENCE:0)
Block(-7,128,2,IRON_FENCE:0)
Block(-7,128,5,IRON_FENCE:0)
Block(-7,129,2,IRON_FENCE:0)
Block(-7,129,5,IRON_FENCE:0)
Block(-7,130,2,COBBLE_WALL:0)
Block(-7,130,5,COBBLE_WALL:0)
Block(-7,131,2,CONCRETE:8)
Block(-7,131,5,CONCRETE:8)
Block(-7,132,5,SMOOTH_STAIRS:0)
Block(-7,133,7,SMOOTH_STAIRS:4)
Block(-7,134,-1,SMOOTH_STAIRS:4)
Block(-7,134,7,CONCRETE:8)
Block(-7,135,-1,CONCRETE:7)
Block(-7,135,0,SMOOTH_STAIRS:4)
Block(-7,135,1,SMOOTH_STAIRS:4)
Block(-7,136,-1,CONCRETE:7)
Block(-7,136,0,CONCRETE:7)
Block(-7,136,1,CONCRETE:7)
Block(-7,136,2,SMOOTH_STAIRS:4)
Block(-7,136,3,SMOOTH_STAIRS:4)
Block(-7,137,-3,SMOOTH_STAIRS:4)
Block(-7,137,-1,CONCRETE:15)
Block(-7,137,0,CONCRETE:15)
Block(-7,137,1,CONCRETE:7)
Block(-7,137,2,CONCRETE:7)
Block(-7,137,3,CONCRETE:7)
Block(-7,137,4,SMOOTH_STAIRS:4)
Block(-7,138,-5,STEP:8)
Block(-7,138,-4,SMOOTH_STAIRS:4)
Block(-7,138,-3,CONCRETE:7)
Block(-7,138,-2,SMOOTH_STAIRS:4)
Block(-7,138,-1,CONCRETE:15)
Block(-7,138,0,CONCRETE:15)
Block(-7,138,1,CONCRETE:15)
Block(-7,138,2,CONCRETE:15)
Block(-7,138,3,CONCRETE:7)
Block(-7,138,4,CONCRETE:7)
Block(-7,138,5,SMOOTH_STAIRS:4)
Block(-7,139,-5,SMOOTH_STAIRS:2)
Block(-7,139,-4,CONCRETE:8)
Block(-7,139,-3,CONCRETE:7)
Block(-7,139,-2,CONCRETE:7)
Block(-7,139,-1,CONCRETE:7)
Block(-7,139,0,CONCRETE:7)
Block(-7,139,1,CONCRETE:7)
Block(-7,139,2,CONCRETE:15)
Block(-7,139,3,CONCRETE:15)
Block(-7,139,4,CONCRETE:7)
Block(-7,139,5,CONCRETE:7)
Block(-7,139,6,SMOOTH_STAIRS:4)
Block(-7,139,7,SMOOTH_STAIRS:4)
Block(-7,139,8,SMOOTH_STAIRS:4)
Block(-7,140,-4,SMOOTH_STAIRS:2)
Block(-7,140,-3,CONCRETE:7)
Block(-7,140,-2,CONCRETE:7)
Block(-7,140,-1,SMOOTH_STAIRS:3)
Block(-7,140,0,STEP:0)
Block(-7,140,1,CONCRETE:7)
Block(-7,140,2,STEP:0)
Block(-7,140,3,SMOOTH_STAIRS:2)
Block(-7,140,4,CONCRETE:7)
Block(-7,140,5,CONCRETE:7)
Block(-7,140,6,SMOOTH_STAIRS:3)
Block(-7,140,7,STEP:0)
Block(-7,140,8,STEP:0)
Block(-7,141,-3,CONCRETE:7)
Block(-7,141,-2,STEP:0)
Block(-7,141,1,COBBLE_WALL:0)
Block(-7,141,4,STEP:0)
Block(-7,141,5,CONCRETE:7)
Block(-7,142,-5,SMOOTH_STAIRS:4)
Block(-7,142,-3,STEP:0)
Block(-7,142,5,STEP:0)
Block(-7,143,-5,CONCRETE:7)
Block(-7,143,-4,SMOOTH_STAIRS:7)
Block(-7,143,-3,STEP:8)
Block(-7,143,-2,STEP:8)
Block(-7,143,-1,STEP:8)
Block(-7,143,0,STEP:8)
Block(-7,143,1,STEP:8)
Block(-7,143,2,STEP:8)
Block(-7,143,3,STEP:8)
Block(-7,143,4,STEP:8)
Block(-7,143,5,SMOOTH_STAIRS:4)
Block(-7,143,6,STEP:8)
Block(-7,143,7,STEP:8)
Block(-7,143,8,STEP:8)
Block(-7,144,-5,STEP:0)
Block(-7,144,-4,SMOOTH_STAIRS:0)
Block(-7,144,-3,SMOOTH_STAIRS:3)
Block(-7,144,1,COBBLE_WALL:0)
Block(-7,144,5,COBBLE_WALL:0)
Block(-6,0,-7,CONCRETE:7)
Block(-6,0,-6,CONCRETE:7)
Block(-6,0,-5,CONCRETE:7)
Block(-6,0,-4,CONCRETE:7)
Block(-6,0,-3,CONCRETE:7)
Block(-6,0,-2,CONCRETE:7)
Block(-6,0,-1,CONCRETE:7)
Block(-6,0,0,CONCRETE:7)
Block(-6,0,1,CONCRETE:7)
Block(-6,0,2,CONCRETE:7)
Block(-6,0,3,CONCRETE:7)
Block(-6,0,4,CONCRETE:7)
Block(-6,0,5,CONCRETE:7)
Block(-6,0,6,CONCRETE:7)
Block(-6,0,7,CONCRETE:7)
Block(-6,0,8,CONCRETE:7)
Block(-6,1,-7,CONCRETE:7)
Block(-6,1,-6,CONCRETE:7)
Block(-6,1,-5,CONCRETE:7)
Block(-6,1,-4,CONCRETE:7)
Block(-6,1,-3,CONCRETE:7)
Block(-6,1,-2,CONCRETE:7)
Block(-6,1,-1,CONCRETE:7)
Block(-6,1,0,CONCRETE:7)
Block(-6,1,1,CONCRETE:7)
Block(-6,1,2,CONCRETE:7)
Block(-6,1,3,CONCRETE:7)
Block(-6,1,4,CONCRETE:7)
Block(-6,1,5,CONCRETE:7)
Block(-6,1,6,CONCRETE:7)
Block(-6,1,7,CONCRETE:7)
Block(-6,1,8,CONCRETE:7)
Block(-6,2,-7,CONCRETE:7)
Block(-6,2,-6,CONCRETE:7)
Block(-6,2,-5,CONCRETE:7)
Block(-6,2,-4,CONCRETE:7)
Block(-6,2,-3,CONCRETE:7)
Block(-6,2,-2,CONCRETE:7)
Block(-6,2,-1,CONCRETE:7)
Block(-6,2,0,CONCRETE:7)
Block(-6,2,1,CONCRETE:7)
Block(-6,2,2,CONCRETE:7)
Block(-6,2,3,CONCRETE:7)
Block(-6,2,4,CONCRETE:7)
Block(-6,2,5,CONCRETE:7)
Block(-6,2,6,CONCRETE:7)
Block(-6,2,7,CONCRETE:7)
Block(-6,2,8,CONCRETE:7)
Block(-6,3,-7,CONCRETE:7)
Block(-6,3,-6,CONCRETE:7)
Block(-6,3,-5,CONCRETE:7)
Block(-6,3,-4,CONCRETE:7)
Block(-6,3,-3,CONCRETE:7)
Block(-6,3,-2,CONCRETE:7)
Block(-6,3,-1,CONCRETE:7)
Block(-6,3,0,CONCRETE:7)
Block(-6,3,1,CONCRETE:7)
Block(-6,3,2,CONCRETE:7)
Block(-6,3,3,CONCRETE:7)
Block(-6,3,4,CONCRETE:7)
Block(-6,3,5,CONCRETE:7)
Block(-6,3,6,CONCRETE:7)
Block(-6,3,7,CONCRETE:7)
Block(-6,3,8,CONCRETE:7)
Block(-6,4,-7,CONCRETE:7)
Block(-6,4,-6,CONCRETE:7)
Block(-6,4,-5,CONCRETE:7)
Block(-6,4,-4,CONCRETE:7)
Block(-6,4,-3,CONCRETE:7)
Block(-6,4,-2,CONCRETE:7)
Block(-6,4,-1,CONCRETE:7)
Block(-6,4,0,CONCRETE:7)
Block(-6,4,1,CONCRETE:7)
Block(-6,4,2,CONCRETE:7)
Block(-6,4,3,CONCRETE:7)
Block(-6,4,4,CONCRETE:7)
Block(-6,4,5,CONCRETE:7)
Block(-6,4,6,CONCRETE:7)
Block(-6,4,7,CONCRETE:7)
Block(-6,4,8,CONCRETE:7)
Block(-6,5,-7,CONCRETE:7)
Block(-6,5,-6,CONCRETE:7)
Block(-6,5,-5,CONCRETE:7)
Block(-6,5,-4,CONCRETE:7)
Block(-6,5,-3,CONCRETE:7)
Block(-6,5,-2,CONCRETE:7)
Block(-6,5,-1,CONCRETE:7)
Block(-6,5,0,CONCRETE:7)
Block(-6,5,1,CONCRETE:7)
Block(-6,5,2,CONCRETE:7)
Block(-6,5,3,CONCRETE:7)
Block(-6,5,4,CONCRETE:7)
Block(-6,5,5,CONCRETE:7)
Block(-6,5,6,CONCRETE:7)
Block(-6,5,7,CONCRETE:7)
Block(-6,5,8,CONCRETE:7)
Block(-6,6,-7,CONCRETE:7)
Block(-6,6,-6,CONCRETE:7)
Block(-6,6,-5,CONCRETE:7)
Block(-6,6,-4,CONCRETE:7)
Block(-6,6,-3,CONCRETE:7)
Block(-6,6,-2,CONCRETE:7)
Block(-6,6,-1,CONCRETE:7)
Block(-6,6,0,CONCRETE:7)
Block(-6,6,1,CONCRETE:7)
Block(-6,6,2,CONCRETE:7)
Block(-6,6,3,CONCRETE:7)
Block(-6,6,4,CONCRETE:7)
Block(-6,6,5,CONCRETE:7)
Block(-6,6,6,CONCRETE:7)
Block(-6,6,7,CONCRETE:7)
Block(-6,6,8,CONCRETE:7)
Block(-6,7,-7,CONCRETE:7)
Block(-6,7,-6,CONCRETE:7)
Block(-6,7,-5,CONCRETE:15)
Block(-6,7,-4,CONCRETE:15)
Block(-6,7,-3,CONCRETE:15)
Block(-6,7,-2,CONCRETE:15)
Block(-6,7,-1,CONCRETE:15)
Block(-6,7,0,CONCRETE:15)
Block(-6,7,1,CONCRETE:15)
Block(-6,7,2,CONCRETE:15)
Block(-6,7,3,CONCRETE:15)
Block(-6,7,4,CONCRETE:15)
Block(-6,7,5,CONCRETE:15)
Block(-6,7,6,CONCRETE:15)
Block(-6,7,7,CONCRETE:15)
Block(-6,7,8,CONCRETE:15)
Block(-6,8,-7,BRICK:0)
Block(-6,8,-6,CONCRETE:11)
Block(-6,8,-5,CONCRETE:11)
Block(-6,8,-4,CONCRETE:11)
Block(-6,8,-3,CONCRETE:11)
Block(-6,8,-2,CONCRETE:11)
Block(-6,8,-1,CONCRETE:11)
Block(-6,8,1,CONCRETE:7)
Block(-6,8,2,STEP:8)
Block(-6,8,3,STEP:8)
Block(-6,8,4,CONCRETE:7)
Block(-6,8,5,STEP:8)
Block(-6,8,6,STEP:8)
Block(-6,8,7,BRICK:0)
Block(-6,9,-7,BRICK:0)
Block(-6,9,-6,SMOOTH_STAIRS:0)
Block(-6,9,-5,CONCRETE:11)
Block(-6,9,-4,CONCRETE:11)
Block(-6,9,-3,CONCRETE:11)
Block(-6,9,-2,CONCRETE:11)
Block(-6,9,-1,SMOOTH_STAIRS:0)
Block(-6,9,1,IRON_FENCE:0)
Block(-6,9,3,IRON_DOOR_BLOCK:0)
Block(-6,9,4,IRON_DOOR_BLOCK:0)
Block(-6,9,5,IRON_DOOR_BLOCK:0)
Block(-6,9,7,IRON_FENCE:0)
Block(-6,10,-7,BRICK_STAIRS:7)
Block(-6,10,-5,CONCRETE:11)
Block(-6,10,-4,CONCRETE:11)
Block(-6,10,-3,CONCRETE:11)
Block(-6,10,-2,CONCRETE:11)
Block(-6,10,3,IRON_DOOR_BLOCK:8)
Block(-6,10,4,IRON_DOOR_BLOCK:8)
Block(-6,10,5,IRON_DOOR_BLOCK:8)
Block(-6,11,-7,BRICK_STAIRS:3)
Block(-6,11,-5,STEP:0)
Block(-6,11,-4,CONCRETE:11)
Block(-6,11,-3,CONCRETE:11)
Block(-6,11,-2,STEP:0)
Block(-6,12,-7,BRICK_STAIRS:7)
Block(-6,12,-4,SMOOTH_STAIRS:0)
Block(-6,12,-3,SMOOTH_STAIRS:0)
Block(-6,12,0,CONCRETE:4)
Block(-6,13,-7,BRICK:0)
Block(-6,13,0,COBBLE_WALL:0)
Block(-6,13,3,CONCRETE:1)
Block(-6,14,-7,CONCRETE:7)
Block(-6,14,-5,SMOOTH_STAIRS:5)
Block(-6,14,-2,CONCRETE:14)
Block(-6,14,0,COBBLE_WALL:0)
Block(-6,14,1,CONCRETE:7)
Block(-6,14,3,IRON_FENCE:0)
Block(-6,14,4,BRICK_STAIRS:7)
Block(-6,14,7,CONCRETE:7)
Block(-6,14,8,STEP:12)
Block(-6,15,-7,CONCRETE:7)
Block(-6,15,-6,CONCRETE:7)
Block(-6,15,-5,CONCRETE:7)
Block(-6,15,-4,CONCRETE:7)
Block(-6,15,-3,CONCRETE:7)
Block(-6,15,-2,CONCRETE:7)
Block(-6,15,-1,CONCRETE:7)
Block(-6,15,0,CONCRETE:7)
Block(-6,15,1,CONCRETE:7)
Block(-6,15,2,CONCRETE:7)
Block(-6,15,3,CONCRETE:7)
Block(-6,15,4,CONCRETE:7)
Block(-6,15,5,CONCRETE:7)
Block(-6,15,6,STEP:12)
Block(-6,15,7,CONCRETE:7)
Block(-6,15,8,CONCRETE:7)
Block(-6,16,-7,CONCRETE:7)
Block(-6,16,-6,CONCRETE:7)
Block(-6,16,-5,CONCRETE:7)
Block(-6,16,-4,CONCRETE:7)
Block(-6,16,-3,CONCRETE:7)
Block(-6,16,-2,CONCRETE:7)
Block(-6,16,-1,CONCRETE:7)
Block(-6,16,0,CONCRETE:7)
Block(-6,16,1,CONCRETE:7)
Block(-6,16,2,CONCRETE:7)
Block(-6,16,3,CONCRETE:7)
Block(-6,16,4,CONCRETE:7)
Block(-6,16,5,CONCRETE:7)
Block(-6,16,6,CONCRETE:7)
Block(-6,16,7,CONCRETE:7)
Block(-6,16,8,CONCRETE:7)
Block(-6,17,-7,CONCRETE:15)
Block(-6,17,-6,CONCRETE:7)
Block(-6,17,-5,CONCRETE:7)
Block(-6,17,-4,CONCRETE:7)
Block(-6,17,-3,CONCRETE:7)
Block(-6,17,-2,CONCRETE:7)
Block(-6,17,-1,CONCRETE:7)
Block(-6,17,0,CONCRETE:7)
Block(-6,17,1,CONCRETE:7)
Block(-6,17,2,CONCRETE:7)
Block(-6,17,3,CONCRETE:7)
Block(-6,17,4,CONCRETE:7)
Block(-6,17,5,CONCRETE:7)
Block(-6,17,6,CONCRETE:7)
Block(-6,17,7,CONCRETE:7)
Block(-6,17,8,CONCRETE:7)
Block(-6,18,-5,CONCRETE:7)
Block(-6,18,-4,CONCRETE:8)
Block(-6,18,-3,CONCRETE:0)
Block(-6,18,-2,CONCRETE:8)
Block(-6,18,-1,CONCRETE:8)
Block(-6,18,2,SMOOTH_STAIRS:0)
Block(-6,18,3,CONCRETE:7)
Block(-6,18,4,CONCRETE:8)
Block(-6,18,5,CONCRETE:8)
Block(-6,18,6,CONCRETE:8)
Block(-6,18,7,CONCRETE:8)
Block(-6,18,8,SMOOTH_STAIRS:1)
Block(-6,19,-5,CONCRETE:7)
Block(-6,19,-4,CONCRETE:8)
Block(-6,19,-3,CONCRETE:0)
Block(-6,19,-2,CONCRETE:8)
Block(-6,19,-1,SMOOTH_STAIRS:3)
Block(-6,19,3,CONCRETE:7)
Block(-6,19,4,STAINED_GLASS_PANE:7)
Block(-6,19,5,STAINED_GLASS_PANE:7)
Block(-6,19,6,STAINED_GLASS_PANE:7)
Block(-6,19,7,CONCRETE:8)
Block(-6,20,-5,STEP:0)
Block(-6,20,-4,CONCRETE:8)
Block(-6,20,-3,CONCRETE:0)
Block(-6,20,-2,SMOOTH_STAIRS:0)
Block(-6,20,3,CONCRETE:7)
Block(-6,20,4,STAINED_GLASS_PANE:7)
Block(-6,20,5,STAINED_GLASS_PANE:7)
Block(-6,20,6,STAINED_GLASS_PANE:7)
Block(-6,20,7,CONCRETE:8)
Block(-6,21,-4,CONCRETE:8)
Block(-6,21,-3,CONCRETE:0)
Block(-6,21,3,STEP:0)
Block(-6,21,4,STAINED_GLASS_PANE:7)
Block(-6,21,5,STAINED_GLASS_PANE:7)
Block(-6,21,6,STAINED_GLASS_PANE:7)
Block(-6,21,7,CONCRETE:8)
Block(-6,22,-4,SMOOTH_STAIRS:0)
Block(-6,22,-3,CONCRETE:0)
Block(-6,22,4,STAINED_GLASS_PANE:7)
Block(-6,22,5,STAINED_GLASS_PANE:7)
Block(-6,22,6,STAINED_GLASS_PANE:7)
Block(-6,22,7,CONCRETE:8)
Block(-6,23,-4,SMOOTH_STAIRS:4)
Block(-6,23,-3,CONCRETE:0)
Block(-6,23,4,STAINED_GLASS_PANE:7)
Block(-6,23,5,STAINED_GLASS_PANE:7)
Block(-6,23,6,STAINED_GLASS_PANE:7)
Block(-6,23,7,CONCRETE:8)
Block(-6,24,-4,CONCRETE:8)
Block(-6,24,-3,CONCRETE:0)
Block(-6,24,3,STEP:8)
Block(-6,24,4,STAINED_GLASS_PANE:7)
Block(-6,24,5,STAINED_GLASS_PANE:7)
Block(-6,24,6,STAINED_GLASS_PANE:7)
Block(-6,24,7,CONCRETE:8)
Block(-6,25,-5,STEP:8)
Block(-6,25,-4,CONCRETE:8)
Block(-6,25,-3,CONCRETE:0)
Block(-6,25,-2,SMOOTH_STAIRS:4)
Block(-6,25,3,CONCRETE:7)
Block(-6,25,4,STAINED_GLASS_PANE:7)
Block(-6,25,5,STAINED_GLASS_PANE:7)
Block(-6,25,6,STAINED_GLASS_PANE:7)
Block(-6,25,7,CONCRETE:8)
Block(-6,26,-5,CONCRETE:7)
Block(-6,26,-4,CONCRETE:8)
Block(-6,26,-3,CONCRETE:0)
Block(-6,26,-2,CONCRETE:8)
Block(-6,26,-1,SMOOTH_STAIRS:7)
Block(-6,26,3,CONCRETE:7)
Block(-6,26,4,STAINED_GLASS_PANE:7)
Block(-6,26,5,STAINED_GLASS_PANE:7)
Block(-6,26,6,STAINED_GLASS_PANE:7)
Block(-6,26,7,CONCRETE:8)
Block(-6,27,-5,CONCRETE:7)
Block(-6,27,-4,CONCRETE:8)
Block(-6,27,-3,CONCRETE:0)
Block(-6,27,-2,CONCRETE:8)
Block(-6,27,-1,CONCRETE:8)
Block(-6,27,2,SMOOTH_STAIRS:4)
Block(-6,27,3,CONCRETE:7)
Block(-6,27,4,CONCRETE:8)
Block(-6,27,5,CONCRETE:8)
Block(-6,27,6,CONCRETE:8)
Block(-6,27,7,CONCRETE:8)
Block(-6,27,8,SMOOTH_STAIRS:5)
Block(-6,28,-6,SMOOTH_STAIRS:6)
Block(-6,28,-5,CONCRETE:7)
Block(-6,28,-4,CONCRETE:7)
Block(-6,28,-3,CONCRETE:7)
Block(-6,28,-2,CONCRETE:7)
Block(-6,28,-1,CONCRETE:7)
Block(-6,28,0,CONCRETE:7)
Block(-6,28,1,CONCRETE:7)
Block(-6,28,2,CONCRETE:7)
Block(-6,28,3,CONCRETE:7)
Block(-6,28,4,CONCRETE:7)
Block(-6,28,5,CONCRETE:7)
Block(-6,28,6,CONCRETE:7)
Block(-6,28,7,CONCRETE:7)
Block(-6,28,8,CONCRETE:7)
Block(-6,29,-7,STEP:8)
Block(-6,29,-6,CONCRETE:7)
Block(-6,29,-5,CONCRETE:7)
Block(-6,29,-4,CONCRETE:7)
Block(-6,29,-3,CONCRETE:7)
Block(-6,29,-2,CONCRETE:7)
Block(-6,29,-1,CONCRETE:7)
Block(-6,29,0,CONCRETE:7)
Block(-6,29,1,CONCRETE:7)
Block(-6,29,2,CONCRETE:7)
Block(-6,29,3,CONCRETE:7)
Block(-6,29,4,CONCRETE:7)
Block(-6,29,5,CONCRETE:7)
Block(-6,29,6,CONCRETE:7)
Block(-6,29,7,CONCRETE:7)
Block(-6,29,8,CONCRETE:7)
Block(-6,30,-6,CONCRETE:8)
Block(-6,30,-5,CONCRETE:7)
Block(-6,30,-4,CONCRETE:7)
Block(-6,30,-3,CONCRETE:7)
Block(-6,30,-2,CONCRETE:0)
Block(-6,30,-1,CONCRETE:7)
Block(-6,30,0,CONCRETE:7)
Block(-6,30,1,CONCRETE:7)
Block(-6,30,2,CONCRETE:7)
Block(-6,30,3,CONCRETE:7)
Block(-6,30,4,CONCRETE:7)
Block(-6,30,5,CONCRETE:15)
Block(-6,30,6,CONCRETE:15)
Block(-6,30,7,PRISMARINE:0)
Block(-6,30,8,PRISMARINE:0)
Block(-6,31,-5,CONCRETE:7)
Block(-6,31,-4,CONCRETE:7)
Block(-6,31,-3,CONCRETE:7)
Block(-6,31,-2,CONCRETE:7)
Block(-6,31,-1,CONCRETE:7)
Block(-6,31,0,CONCRETE:7)
Block(-6,31,1,CONCRETE:7)
Block(-6,31,2,CONCRETE:7)
Block(-6,31,3,CONCRETE:7)
Block(-6,31,4,CONCRETE:15)
Block(-6,31,5,PRISMARINE:0)
Block(-6,31,6,PRISMARINE:0)
Block(-6,31,7,PRISMARINE:0)
Block(-6,31,8,PRISMARINE:0)
Block(-6,32,-5,STEP:0)
Block(-6,32,-4,CONCRETE:7)
Block(-6,32,-3,CONCRETE:7)
Block(-6,32,-2,CONCRETE:7)
Block(-6,32,-1,CONCRETE:7)
Block(-6,32,0,CONCRETE:7)
Block(-6,32,1,CONCRETE:7)
Block(-6,32,2,CONCRETE:7)
Block(-6,32,3,CONCRETE:15)
Block(-6,32,4,PRISMARINE:0)
Block(-6,32,5,PRISMARINE:0)
Block(-6,32,6,PRISMARINE:0)
Block(-6,32,7,PRISMARINE:0)
Block(-6,32,8,PRISMARINE:0)
Block(-6,33,-4,SMOOTH_STAIRS:2)
Block(-6,33,-3,CONCRETE:7)
Block(-6,33,-2,CONCRETE:7)
Block(-6,33,-1,CONCRETE:7)
Block(-6,33,0,CONCRETE:7)
Block(-6,33,1,CONCRETE:7)
Block(-6,33,2,CONCRETE:7)
Block(-6,33,3,CONCRETE:15)
Block(-6,33,4,PRISMARINE:0)
Block(-6,33,5,PRISMARINE:0)
Block(-6,33,6,PRISMARINE:0)
Block(-6,33,7,PRISMARINE:0)
Block(-6,33,8,PRISMARINE:0)
Block(-6,34,-2,CONCRETE:7)
Block(-6,34,-1,CONCRETE:7)
Block(-6,34,0,CONCRETE:7)
Block(-6,34,1,CONCRETE:7)
Block(-6,34,2,CONCRETE:15)
Block(-6,34,3,PRISMARINE:0)
Block(-6,34,4,PRISMARINE:0)
Block(-6,34,5,PRISMARINE:0)
Block(-6,34,6,PRISMARINE:0)
Block(-6,34,7,PRISMARINE:0)
Block(-6,34,8,PRISMARINE:0)
Block(-6,35,-2,CONCRETE:7)
Block(-6,35,-1,CONCRETE:7)
Block(-6,35,0,CONCRETE:7)
Block(-6,35,1,CONCRETE:7)
Block(-6,35,2,CONCRETE:15)
Block(-6,35,3,PRISMARINE:0)
Block(-6,35,4,PRISMARINE:0)
Block(-6,35,5,PRISMARINE:0)
Block(-6,35,6,PRISMARINE:0)
Block(-6,35,7,PRISMARINE:0)
Block(-6,35,8,PRISMARINE:0)
Block(-6,36,-2,SMOOTH_STAIRS:2)
Block(-6,36,-1,CONCRETE:7)
Block(-6,36,0,CONCRETE:7)
Block(-6,36,1,CONCRETE:7)
Block(-6,36,2,CONCRETE:15)
Block(-6,36,3,PRISMARINE:0)
Block(-6,36,4,PRISMARINE:0)
Block(-6,36,5,PRISMARINE:0)
Block(-6,36,6,PRISMARINE:0)
Block(-6,36,7,PRISMARINE:0)
Block(-6,36,8,PRISMARINE:0)
Block(-6,37,-2,SMOOTH_STAIRS:6)
Block(-6,37,-1,CONCRETE:7)
Block(-6,37,0,CONCRETE:7)
Block(-6,37,1,CONCRETE:7)
Block(-6,37,2,CONCRETE:15)
Block(-6,37,3,PRISMARINE:0)
Block(-6,37,4,PRISMARINE:0)
Block(-6,37,5,PRISMARINE:0)
Block(-6,37,6,PRISMARINE:0)
Block(-6,37,7,PRISMARINE:0)
Block(-6,37,8,PRISMARINE:0)
Block(-6,38,-5,SEA_LANTERN:0)
Block(-6,38,-2,CONCRETE:7)
Block(-6,38,-1,CONCRETE:7)
Block(-6,38,0,CONCRETE:7)
Block(-6,38,1,CONCRETE:0)
Block(-6,38,2,CONCRETE:7)
Block(-6,38,3,CONCRETE:15)
Block(-6,38,4,PRISMARINE:0)
Block(-6,38,5,PRISMARINE:0)
Block(-6,38,6,PRISMARINE:0)
Block(-6,38,7,PRISMARINE:0)
Block(-6,38,8,PRISMARINE:0)
Block(-6,39,-5,IRON_FENCE:0)
Block(-6,39,-3,SMOOTH_STAIRS:6)
Block(-6,39,-2,CONCRETE:7)
Block(-6,39,-1,CONCRETE:7)
Block(-6,39,0,CONCRETE:0)
Block(-6,39,1,STEP:0)
Block(-6,39,2,CONCRETE:7)
Block(-6,39,3,CONCRETE:15)
Block(-6,39,4,PRISMARINE:0)
Block(-6,39,5,PRISMARINE:0)
Block(-6,39,6,PRISMARINE:0)
Block(-6,39,7,PRISMARINE:0)
Block(-6,39,8,PRISMARINE:0)
Block(-6,40,-5,IRON_FENCE:0)
Block(-6,40,-4,STEP:8)
Block(-6,40,-3,CONCRETE:7)
Block(-6,40,-2,CONCRETE:7)
Block(-6,40,-1,CONCRETE:7)
Block(-6,40,0,CONCRETE:0)
Block(-6,40,2,STEP:0)
Block(-6,40,3,CONCRETE:7)
Block(-6,40,4,CONCRETE:15)
Block(-6,40,5,PRISMARINE:0)
Block(-6,40,6,PRISMARINE:0)
Block(-6,40,7,PRISMARINE:0)
Block(-6,40,8,PRISMARINE:0)
Block(-6,41,-5,IRON_FENCE:0)
Block(-6,41,-4,CONCRETE:7)
Block(-6,41,-3,CONCRETE:7)
Block(-6,41,-2,CONCRETE:7)
Block(-6,41,-1,CONCRETE:0)
Block(-6,41,0,STEP:0)
Block(-6,41,3,CONCRETE:7)
Block(-6,41,4,CONCRETE:7)
Block(-6,41,5,CONCRETE:15)
Block(-6,41,6,CONCRETE:15)
Block(-6,41,7,PRISMARINE:0)
Block(-6,41,8,PRISMARINE:0)
Block(-6,42,-5,CONCRETE:7)
Block(-6,42,-4,CONCRETE:7)
Block(-6,42,-3,CONCRETE:7)
Block(-6,42,-2,CONCRETE:0)
Block(-6,42,-1,STEP:0)
Block(-6,42,3,COBBLE_WALL:0)
Block(-6,42,4,STEP:0)
Block(-6,42,5,CONCRETE:7)
Block(-6,42,6,CONCRETE:7)
Block(-6,42,7,CONCRETE:15)
Block(-6,42,8,CONCRETE:15)
Block(-6,43,-6,CONCRETE:8)
Block(-6,43,-5,CONCRETE:8)
Block(-6,43,-4,CONCRETE:0)
Block(-6,43,-3,CONCRETE:0)
Block(-6,43,-2,STEP:0)
Block(-6,43,5,COBBLE_WALL:0)
Block(-6,43,6,STEP:0)
Block(-6,43,7,CONCRETE:7)
Block(-6,43,8,CONCRETE:7)
Block(-6,44,-6,STEP:0)
Block(-6,44,-5,CONCRETE:8)
Block(-6,44,-4,CONCRETE:8)
Block(-6,44,-3,STEP:0)
Block(-6,45,-5,STEP:0)
Block(-6,45,7,SMOOTH_STAIRS:5)
Block(-6,46,6,STEP:8)
Block(-6,46,7,SMOOTH_STAIRS:0)
Block(-6,47,5,STEP:8)
Block(-6,47,6,CONCRETE:8)
Block(-6,47,8,STEP:8)
Block(-6,48,3,COBBLE_WALL:0)
Block(-6,48,4,SMOOTH_STAIRS:4)
Block(-6,48,5,CONCRETE:8)
Block(-6,48,6,CONCRETE:8)
Block(-6,48,7,SMOOTH_STAIRS:4)
Block(-6,48,8,CONCRETE:8)
Block(-6,49,2,SMOOTH_STAIRS:4)
Block(-6,49,3,CONCRETE:8)
Block(-6,49,4,CONCRETE:8)
Block(-6,49,5,CONCRETE:8)
Block(-6,49,6,CONCRETE:8)
Block(-6,49,7,CONCRETE:8)
Block(-6,49,8,CONCRETE:8)
Block(-6,50,0,SMOOTH_STAIRS:4)
Block(-6,50,1,SMOOTH_STAIRS:4)
Block(-6,50,2,CONCRETE:8)
Block(-6,50,3,SMOOTH_STAIRS:0)
Block(-6,50,4,SMOOTH_STAIRS:0)
Block(-6,50,5,CONCRETE:8)
Block(-6,50,6,CONCRETE:8)
Block(-6,50,7,SMOOTH_STAIRS:0)
Block(-6,50,8,CONCRETE:8)
Block(-6,51,-1,SMOOTH_STAIRS:4)
Block(-6,51,0,CONCRETE:8)
Block(-6,51,1,CONCRETE:8)
Block(-6,51,2,CONCRETE:8)
Block(-6,51,3,STAINED_GLASS_PANE:7)
Block(-6,51,4,STAINED_GLASS_PANE:7)
Block(-6,51,5,CONCRETE:8)
Block(-6,51,6,CONCRETE:8)
Block(-6,51,7,STAINED_GLASS_PANE:7)
Block(-6,51,8,CONCRETE:8)
Block(-6,52,-1,CONCRETE:8)
Block(-6,52,0,STAINED_GLASS_PANE:7)
Block(-6,52,1,STAINED_GLASS_PANE:7)
Block(-6,52,2,CONCRETE:8)
Block(-6,52,3,STAINED_GLASS_PANE:7)
Block(-6,52,4,STAINED_GLASS_PANE:7)
Block(-6,52,5,CONCRETE:8)
Block(-6,52,6,CONCRETE:8)
Block(-6,52,7,STAINED_GLASS_PANE:7)
Block(-6,52,8,CONCRETE:8)
Block(-6,53,-1,CONCRETE:8)
Block(-6,53,0,STAINED_GLASS_PANE:7)
Block(-6,53,1,STAINED_GLASS_PANE:7)
Block(-6,53,2,CONCRETE:8)
Block(-6,53,3,STAINED_GLASS_PANE:7)
Block(-6,53,4,STAINED_GLASS_PANE:7)
Block(-6,53,5,CONCRETE:8)
Block(-6,53,6,CONCRETE:8)
Block(-6,53,7,STAINED_GLASS_PANE:7)
Block(-6,53,8,CONCRETE:8)
Block(-6,54,-1,CONCRETE:8)
Block(-6,54,0,STAINED_GLASS_PANE:7)
Block(-6,54,1,STAINED_GLASS_PANE:7)
Block(-6,54,2,CONCRETE:8)
Block(-6,54,3,STAINED_GLASS_PANE:7)
Block(-6,54,4,STAINED_GLASS_PANE:7)
Block(-6,54,5,CONCRETE:8)
Block(-6,54,6,CONCRETE:8)
Block(-6,54,7,STAINED_GLASS_PANE:7)
Block(-6,54,8,CONCRETE:8)
Block(-6,55,-1,CONCRETE:8)
Block(-6,55,0,STAINED_GLASS_PANE:7)
Block(-6,55,1,STAINED_GLASS_PANE:7)
Block(-6,55,2,CONCRETE:8)
Block(-6,55,3,STAINED_GLASS_PANE:7)
Block(-6,55,4,STAINED_GLASS_PANE:7)
Block(-6,55,5,CONCRETE:8)
Block(-6,55,6,CONCRETE:8)
Block(-6,55,7,STAINED_GLASS_PANE:7)
Block(-6,55,8,CONCRETE:8)
Block(-6,56,-1,CONCRETE:8)
Block(-6,56,0,STAINED_GLASS_PANE:7)
Block(-6,56,1,STAINED_GLASS_PANE:7)
Block(-6,56,2,CONCRETE:8)
Block(-6,56,3,STAINED_GLASS_PANE:7)
Block(-6,56,4,STAINED_GLASS_PANE:7)
Block(-6,56,5,CONCRETE:8)
Block(-6,56,6,CONCRETE:8)
Block(-6,56,7,STAINED_GLASS_PANE:7)
Block(-6,56,8,CONCRETE:8)
Block(-6,57,-1,CONCRETE:8)
Block(-6,57,0,STAINED_GLASS_PANE:7)
Block(-6,57,1,STAINED_GLASS_PANE:7)
Block(-6,57,2,CONCRETE:8)
Block(-6,57,3,STAINED_GLASS_PANE:7)
Block(-6,57,4,STAINED_GLASS_PANE:7)
Block(-6,57,5,CONCRETE:8)
Block(-6,57,6,CONCRETE:8)
Block(-6,57,7,STAINED_GLASS_PANE:7)
Block(-6,57,8,CONCRETE:8)
Block(-6,58,-1,CONCRETE:8)
Block(-6,58,0,STAINED_GLASS_PANE:7)
Block(-6,58,1,STAINED_GLASS_PANE:7)
Block(-6,58,2,CONCRETE:8)
Block(-6,58,3,STAINED_GLASS_PANE:7)
Block(-6,58,4,STAINED_GLASS_PANE:7)
Block(-6,58,5,CONCRETE:8)
Block(-6,58,6,CONCRETE:8)
Block(-6,58,7,STAINED_GLASS_PANE:7)
Block(-6,58,8,CONCRETE:8)
Block(-6,59,-1,CONCRETE:8)
Block(-6,59,0,STAINED_GLASS_PANE:7)
Block(-6,59,1,STAINED_GLASS_PANE:7)
Block(-6,59,2,CONCRETE:8)
Block(-6,59,3,STAINED_GLASS_PANE:7)
Block(-6,59,4,STAINED_GLASS_PANE:7)
Block(-6,59,5,CONCRETE:8)
Block(-6,59,6,CONCRETE:8)
Block(-6,59,7,STAINED_GLASS_PANE:7)
Block(-6,59,8,CONCRETE:8)
Block(-6,60,-1,CONCRETE:8)
Block(-6,60,0,STAINED_GLASS_PANE:7)
Block(-6,60,1,STAINED_GLASS_PANE:7)
Block(-6,60,2,CONCRETE:8)
Block(-6,60,3,STAINED_GLASS_PANE:7)
Block(-6,60,4,STAINED_GLASS_PANE:7)
Block(-6,60,5,CONCRETE:8)
Block(-6,60,6,CONCRETE:8)
Block(-6,60,7,STAINED_GLASS_PANE:7)
Block(-6,60,8,CONCRETE:8)
Block(-6,61,-1,CONCRETE:8)
Block(-6,61,0,STAINED_GLASS_PANE:7)
Block(-6,61,1,STAINED_GLASS_PANE:7)
Block(-6,61,2,CONCRETE:8)
Block(-6,61,3,STAINED_GLASS_PANE:7)
Block(-6,61,4,STAINED_GLASS_PANE:7)
Block(-6,61,5,CONCRETE:8)
Block(-6,61,6,CONCRETE:8)
Block(-6,61,7,STAINED_GLASS_PANE:7)
Block(-6,61,8,CONCRETE:8)
Block(-6,62,-1,CONCRETE:8)
Block(-6,62,0,STAINED_GLASS_PANE:7)
Block(-6,62,1,STAINED_GLASS_PANE:7)
Block(-6,62,2,CONCRETE:8)
Block(-6,62,3,STAINED_GLASS_PANE:7)
Block(-6,62,4,STAINED_GLASS_PANE:7)
Block(-6,62,5,CONCRETE:8)
Block(-6,62,6,CONCRETE:8)
Block(-6,62,7,STAINED_GLASS_PANE:7)
Block(-6,62,8,CONCRETE:8)
Block(-6,63,-1,CONCRETE:8)
Block(-6,63,0,STAINED_GLASS_PANE:7)
Block(-6,63,1,STAINED_GLASS_PANE:7)
Block(-6,63,2,CONCRETE:8)
Block(-6,63,3,STAINED_GLASS_PANE:7)
Block(-6,63,4,STAINED_GLASS_PANE:7)
Block(-6,63,5,CONCRETE:8)
Block(-6,63,6,CONCRETE:8)
Block(-6,63,7,STAINED_GLASS_PANE:7)
Block(-6,63,8,CONCRETE:8)
Block(-6,64,-1,CONCRETE:8)
Block(-6,64,0,STAINED_GLASS_PANE:7)
Block(-6,64,1,STAINED_GLASS_PANE:7)
Block(-6,64,2,CONCRETE:8)
Block(-6,64,3,STAINED_GLASS_PANE:7)
Block(-6,64,4,STAINED_GLASS_PANE:7)
Block(-6,64,5,CONCRETE:8)
Block(-6,64,6,CONCRETE:8)
Block(-6,64,7,STAINED_GLASS_PANE:7)
Block(-6,64,8,CONCRETE:8)
Block(-6,65,-1,CONCRETE:8)
Block(-6,65,0,STAINED_GLASS_PANE:7)
Block(-6,65,1,STAINED_GLASS_PANE:7)
Block(-6,65,2,CONCRETE:8)
Block(-6,65,3,STAINED_GLASS_PANE:7)
Block(-6,65,4,STAINED_GLASS_PANE:7)
Block(-6,65,5,CONCRETE:8)
Block(-6,65,6,CONCRETE:8)
Block(-6,65,7,STAINED_GLASS_PANE:7)
Block(-6,65,8,CONCRETE:8)
Block(-6,66,-1,CONCRETE:8)
Block(-6,66,0,STAINED_GLASS_PANE:7)
Block(-6,66,1,STAINED_GLASS_PANE:7)
Block(-6,66,2,CONCRETE:8)
Block(-6,66,3,STAINED_GLASS_PANE:7)
Block(-6,66,4,STAINED_GLASS_PANE:7)
Block(-6,66,5,CONCRETE:8)
Block(-6,66,6,CONCRETE:8)
Block(-6,66,7,STAINED_GLASS_PANE:7)
Block(-6,66,8,CONCRETE:8)
Block(-6,67,-1,CONCRETE:8)
Block(-6,67,0,STAINED_GLASS_PANE:7)
Block(-6,67,1,STAINED_GLASS_PANE:7)
Block(-6,67,2,CONCRETE:8)
Block(-6,67,3,STAINED_GLASS_PANE:7)
Block(-6,67,4,STAINED_GLASS_PANE:7)
Block(-6,67,5,CONCRETE:8)
Block(-6,67,6,CONCRETE:8)
Block(-6,67,7,STAINED_GLASS_PANE:7)
Block(-6,67,8,CONCRETE:8)
Block(-6,68,-1,CONCRETE:8)
Block(-6,68,0,STAINED_GLASS_PANE:7)
Block(-6,68,1,STAINED_GLASS_PANE:7)
Block(-6,68,2,CONCRETE:8)
Block(-6,68,3,STAINED_GLASS_PANE:7)
Block(-6,68,4,STAINED_GLASS_PANE:7)
Block(-6,68,5,CONCRETE:8)
Block(-6,68,6,CONCRETE:8)
Block(-6,68,7,STAINED_GLASS_PANE:7)
Block(-6,68,8,CONCRETE:8)
Block(-6,69,-1,CONCRETE:8)
Block(-6,69,0,STAINED_GLASS_PANE:7)
Block(-6,69,1,STAINED_GLASS_PANE:7)
Block(-6,69,2,CONCRETE:8)
Block(-6,69,3,STAINED_GLASS_PANE:7)
Block(-6,69,4,STAINED_GLASS_PANE:7)
Block(-6,69,5,CONCRETE:8)
Block(-6,69,6,CONCRETE:8)
Block(-6,69,7,STAINED_GLASS_PANE:7)
Block(-6,69,8,CONCRETE:8)
Block(-6,70,-1,CONCRETE:8)
Block(-6,70,0,STAINED_GLASS_PANE:7)
Block(-6,70,1,STAINED_GLASS_PANE:7)
Block(-6,70,2,CONCRETE:8)
Block(-6,70,3,STAINED_GLASS_PANE:7)
Block(-6,70,4,STAINED_GLASS_PANE:7)
Block(-6,70,5,CONCRETE:8)
Block(-6,70,6,CONCRETE:8)
Block(-6,70,7,STAINED_GLASS_PANE:7)
Block(-6,70,8,CONCRETE:8)
Block(-6,71,-1,CONCRETE:8)
Block(-6,71,0,STAINED_GLASS_PANE:7)
Block(-6,71,1,STAINED_GLASS_PANE:7)
Block(-6,71,2,CONCRETE:8)
Block(-6,71,3,STAINED_GLASS_PANE:7)
Block(-6,71,4,STAINED_GLASS_PANE:7)
Block(-6,71,5,CONCRETE:8)
Block(-6,71,6,CONCRETE:8)
Block(-6,71,7,STAINED_GLASS_PANE:7)
Block(-6,71,8,CONCRETE:8)
Block(-6,72,-1,CONCRETE:8)
Block(-6,72,0,STAINED_GLASS_PANE:7)
Block(-6,72,1,STAINED_GLASS_PANE:7)
Block(-6,72,2,CONCRETE:8)
Block(-6,72,3,STAINED_GLASS_PANE:7)
Block(-6,72,4,STAINED_GLASS_PANE:7)
Block(-6,72,5,CONCRETE:8)
Block(-6,72,6,CONCRETE:8)
Block(-6,72,7,STAINED_GLASS_PANE:7)
Block(-6,72,8,CONCRETE:8)
Block(-6,73,-1,CONCRETE:8)
Block(-6,73,0,STAINED_GLASS_PANE:7)
Block(-6,73,1,STAINED_GLASS_PANE:7)
Block(-6,73,2,CONCRETE:8)
Block(-6,73,3,STAINED_GLASS_PANE:7)
Block(-6,73,4,STAINED_GLASS_PANE:7)
Block(-6,73,5,CONCRETE:8)
Block(-6,73,6,CONCRETE:8)
Block(-6,73,7,STAINED_GLASS_PANE:7)
Block(-6,73,8,CONCRETE:8)
Block(-6,74,-1,CONCRETE:8)
Block(-6,74,0,STAINED_GLASS_PANE:7)
Block(-6,74,1,STAINED_GLASS_PANE:7)
Block(-6,74,2,CONCRETE:8)
Block(-6,74,3,STAINED_GLASS_PANE:7)
Block(-6,74,4,STAINED_GLASS_PANE:7)
Block(-6,74,5,CONCRETE:8)
Block(-6,74,6,CONCRETE:8)
Block(-6,74,7,STAINED_GLASS_PANE:7)
Block(-6,74,8,CONCRETE:8)
Block(-6,75,-1,CONCRETE:8)
Block(-6,75,0,STAINED_GLASS_PANE:7)
Block(-6,75,1,STAINED_GLASS_PANE:7)
Block(-6,75,2,CONCRETE:8)
Block(-6,75,3,STAINED_GLASS_PANE:7)
Block(-6,75,4,STAINED_GLASS_PANE:7)
Block(-6,75,5,CONCRETE:8)
Block(-6,75,6,CONCRETE:8)
Block(-6,75,7,STAINED_GLASS_PANE:7)
Block(-6,75,8,CONCRETE:8)
Block(-6,76,-1,CONCRETE:8)
Block(-6,76,0,STAINED_GLASS_PANE:7)
Block(-6,76,1,STAINED_GLASS_PANE:7)
Block(-6,76,2,CONCRETE:8)
Block(-6,76,3,STAINED_GLASS_PANE:7)
Block(-6,76,4,STAINED_GLASS_PANE:7)
Block(-6,76,5,CONCRETE:8)
Block(-6,76,6,CONCRETE:8)
Block(-6,76,7,STAINED_GLASS_PANE:7)
Block(-6,76,8,CONCRETE:8)
Block(-6,77,-1,CONCRETE:8)
Block(-6,77,0,STAINED_GLASS_PANE:7)
Block(-6,77,1,STAINED_GLASS_PANE:7)
Block(-6,77,2,CONCRETE:8)
Block(-6,77,3,STAINED_GLASS_PANE:7)
Block(-6,77,4,STAINED_GLASS_PANE:7)
Block(-6,77,5,CONCRETE:8)
Block(-6,77,6,CONCRETE:8)
Block(-6,77,7,STAINED_GLASS_PANE:7)
Block(-6,77,8,CONCRETE:8)
Block(-6,78,-1,CONCRETE:8)
Block(-6,78,0,STAINED_GLASS_PANE:7)
Block(-6,78,1,STAINED_GLASS_PANE:7)
Block(-6,78,2,CONCRETE:8)
Block(-6,78,3,STAINED_GLASS_PANE:7)
Block(-6,78,4,STAINED_GLASS_PANE:7)
Block(-6,78,5,CONCRETE:8)
Block(-6,78,6,CONCRETE:8)
Block(-6,78,7,STAINED_GLASS_PANE:7)
Block(-6,78,8,CONCRETE:8)
Block(-6,79,-1,CONCRETE:8)
Block(-6,79,0,STAINED_GLASS_PANE:7)
Block(-6,79,1,STAINED_GLASS_PANE:7)
Block(-6,79,2,CONCRETE:8)
Block(-6,79,3,STAINED_GLASS_PANE:7)
Block(-6,79,4,STAINED_GLASS_PANE:7)
Block(-6,79,5,CONCRETE:8)
Block(-6,79,6,CONCRETE:8)
Block(-6,79,7,STAINED_GLASS_PANE:7)
Block(-6,79,8,CONCRETE:8)
Block(-6,80,-1,CONCRETE:8)
Block(-6,80,0,STAINED_GLASS_PANE:7)
Block(-6,80,1,STAINED_GLASS_PANE:7)
Block(-6,80,2,CONCRETE:8)
Block(-6,80,3,STAINED_GLASS_PANE:7)
Block(-6,80,4,STAINED_GLASS_PANE:7)
Block(-6,80,5,CONCRETE:8)
Block(-6,80,6,CONCRETE:8)
Block(-6,80,7,STAINED_GLASS_PANE:7)
Block(-6,80,8,CONCRETE:8)
Block(-6,81,-1,CONCRETE:8)
Block(-6,81,0,STAINED_GLASS_PANE:7)
Block(-6,81,1,STAINED_GLASS_PANE:7)
Block(-6,81,2,CONCRETE:8)
Block(-6,81,3,STAINED_GLASS_PANE:7)
Block(-6,81,4,STAINED_GLASS_PANE:7)
Block(-6,81,5,CONCRETE:8)
Block(-6,81,6,CONCRETE:8)
Block(-6,81,7,STAINED_GLASS_PANE:7)
Block(-6,81,8,CONCRETE:8)
Block(-6,82,-1,CONCRETE:8)
Block(-6,82,0,STAINED_GLASS_PANE:7)
Block(-6,82,1,STAINED_GLASS_PANE:7)
Block(-6,82,2,CONCRETE:8)
Block(-6,82,3,STAINED_GLASS_PANE:7)
Block(-6,82,4,STAINED_GLASS_PANE:7)
Block(-6,82,5,CONCRETE:8)
Block(-6,82,6,CONCRETE:8)
Block(-6,82,7,CONCRETE:8)
Block(-6,82,8,CONCRETE:8)
Block(-6,83,-1,CONCRETE:8)
Block(-6,83,0,STAINED_GLASS_PANE:7)
Block(-6,83,1,STAINED_GLASS_PANE:7)
Block(-6,83,2,CONCRETE:8)
Block(-6,83,3,STAINED_GLASS_PANE:7)
Block(-6,83,4,STAINED_GLASS_PANE:7)
Block(-6,83,5,CONCRETE:8)
Block(-6,83,6,CONCRETE:8)
Block(-6,83,7,CONCRETE:8)
Block(-6,83,8,CONCRETE:8)
Block(-6,84,-1,CONCRETE:8)
Block(-6,84,0,STAINED_GLASS_PANE:7)
Block(-6,84,1,STAINED_GLASS_PANE:7)
Block(-6,84,2,CONCRETE:8)
Block(-6,84,3,STAINED_GLASS_PANE:7)
Block(-6,84,4,STAINED_GLASS_PANE:7)
Block(-6,84,5,CONCRETE:8)
Block(-6,84,6,CONCRETE:8)
Block(-6,84,7,STEP:0)
Block(-6,84,8,CONCRETE:8)
Block(-6,85,-1,CONCRETE:8)
Block(-6,85,0,STAINED_GLASS_PANE:7)
Block(-6,85,1,STAINED_GLASS_PANE:7)
Block(-6,85,2,CONCRETE:8)
Block(-6,85,3,STAINED_GLASS_PANE:7)
Block(-6,85,4,STAINED_GLASS_PANE:7)
Block(-6,85,5,CONCRETE:8)
Block(-6,85,6,CONCRETE:7)
Block(-6,85,7,STEP:0)
Block(-6,85,8,CONCRETE:8)
Block(-6,86,-1,CONCRETE:8)
Block(-6,86,0,STAINED_GLASS_PANE:7)
Block(-6,86,1,STAINED_GLASS_PANE:7)
Block(-6,86,2,CONCRETE:8)
Block(-6,86,3,STAINED_GLASS_PANE:7)
Block(-6,86,4,STAINED_GLASS_PANE:7)
Block(-6,86,5,CONCRETE:8)
Block(-6,86,6,CONCRETE:7)
Block(-6,86,7,STEP:0)
Block(-6,86,8,CONCRETE:7)
Block(-6,87,-1,CONCRETE:8)
Block(-6,87,0,STAINED_GLASS_PANE:7)
Block(-6,87,1,STAINED_GLASS_PANE:7)
Block(-6,87,2,CONCRETE:8)
Block(-6,87,3,STAINED_GLASS_PANE:7)
Block(-6,87,4,STAINED_GLASS_PANE:7)
Block(-6,87,5,CONCRETE:7)
Block(-6,87,6,CONCRETE:7)
Block(-6,87,7,STEP:0)
Block(-6,87,8,CONCRETE:8)
Block(-6,88,-1,CONCRETE:8)
Block(-6,88,0,STAINED_GLASS_PANE:7)
Block(-6,88,1,STAINED_GLASS_PANE:7)
Block(-6,88,2,CONCRETE:7)
Block(-6,88,3,CONCRETE:7)
Block(-6,88,4,CONCRETE:7)
Block(-6,88,5,CONCRETE:8)
Block(-6,88,6,CONCRETE:8)
Block(-6,88,7,STEP:0)
Block(-6,88,8,CONCRETE:8)
Block(-6,89,-3,SMOOTH_STAIRS:4)
Block(-6,89,-1,CONCRETE:8)
Block(-6,89,0,CONCRETE:7)
Block(-6,89,1,CONCRETE:7)
Block(-6,89,2,CONCRETE:8)
Block(-6,89,3,STEP:0)
Block(-6,89,4,STEP:0)
Block(-6,89,5,CONCRETE:8)
Block(-6,89,6,CONCRETE:8)
Block(-6,89,7,STEP:0)
Block(-6,89,8,SMOOTH_STAIRS:0)
Block(-6,90,-3,CONCRETE:7)
Block(-6,90,-2,SMOOTH_STAIRS:6)
Block(-6,90,-1,CONCRETE:7)
Block(-6,90,0,STEP:0)
Block(-6,90,1,STEP:0)
Block(-6,90,2,STEP:0)
Block(-6,90,3,STEP:0)
Block(-6,90,4,STEP:0)
Block(-6,90,5,SMOOTH_STAIRS:0)
Block(-6,90,6,SMOOTH_STAIRS:0)
Block(-6,90,7,STEP:0)
Block(-6,90,8,STEP:0)
Block(-6,91,-3,IRON_FENCE:0)
Block(-6,91,-2,CONCRETE:7)
Block(-6,91,-1,CONCRETE:8)
Block(-6,91,0,STEP:0)
Block(-6,91,1,STEP:0)
Block(-6,91,2,STEP:0)
Block(-6,91,3,STEP:0)
Block(-6,91,4,STEP:0)
Block(-6,91,5,STEP:0)
Block(-6,91,6,STEP:0)
Block(-6,91,7,STEP:0)
Block(-6,91,8,STEP:0)
Block(-6,92,-3,CONCRETE:7)
Block(-6,92,-2,SMOOTH_STAIRS:2)
Block(-6,92,-1,CONCRETE:7)
Block(-6,92,0,STEP:8)
Block(-6,92,1,STEP:8)
Block(-6,92,2,STEP:8)
Block(-6,92,3,STEP:8)
Block(-6,92,4,STEP:8)
Block(-6,92,5,SMOOTH_STAIRS:4)
Block(-6,92,6,SMOOTH_STAIRS:4)
Block(-6,92,7,STEP:8)
Block(-6,92,8,STEP:8)
Block(-6,93,-3,SMOOTH_STAIRS:0)
Block(-6,93,-1,CONCRETE:8)
Block(-6,93,0,CONCRETE:7)
Block(-6,93,1,CONCRETE:7)
Block(-6,93,2,CONCRETE:8)
Block(-6,93,3,STEP:8)
Block(-6,93,4,STEP:8)
Block(-6,93,5,CONCRETE:8)
Block(-6,93,6,CONCRETE:8)
Block(-6,93,7,STEP:8)
Block(-6,93,8,SMOOTH_STAIRS:4)
Block(-6,94,-1,CONCRETE:8)
Block(-6,94,0,STAINED_GLASS_PANE:7)
Block(-6,94,1,STAINED_GLASS_PANE:7)
Block(-6,94,2,CONCRETE:7)
Block(-6,94,3,CONCRETE:7)
Block(-6,94,4,CONCRETE:7)
Block(-6,94,5,CONCRETE:8)
Block(-6,94,6,CONCRETE:8)
Block(-6,94,7,STEP:8)
Block(-6,94,8,CONCRETE:8)
Block(-6,95,-1,CONCRETE:8)
Block(-6,95,0,STAINED_GLASS_PANE:7)
Block(-6,95,1,STAINED_GLASS_PANE:7)
Block(-6,95,2,CONCRETE:8)
Block(-6,95,3,STAINED_GLASS_PANE:7)
Block(-6,95,4,STAINED_GLASS_PANE:7)
Block(-6,95,5,CONCRETE:7)
Block(-6,95,6,CONCRETE:7)
Block(-6,95,7,STEP:8)
Block(-6,95,8,CONCRETE:8)
Block(-6,96,-1,CONCRETE:8)
Block(-6,96,0,STAINED_GLASS_PANE:7)
Block(-6,96,1,STAINED_GLASS_PANE:7)
Block(-6,96,2,CONCRETE:8)
Block(-6,96,3,STAINED_GLASS_PANE:7)
Block(-6,96,4,STAINED_GLASS_PANE:7)
Block(-6,96,5,CONCRETE:8)
Block(-6,96,6,CONCRETE:7)
Block(-6,96,7,STEP:8)
Block(-6,96,8,CONCRETE:7)
Block(-6,97,-1,CONCRETE:8)
Block(-6,97,0,STAINED_GLASS_PANE:7)
Block(-6,97,1,STAINED_GLASS_PANE:7)
Block(-6,97,2,CONCRETE:8)
Block(-6,97,3,STAINED_GLASS_PANE:7)
Block(-6,97,4,STAINED_GLASS_PANE:7)
Block(-6,97,5,CONCRETE:8)
Block(-6,97,6,CONCRETE:7)
Block(-6,97,7,STEP:8)
Block(-6,97,8,CONCRETE:8)
Block(-6,98,-1,CONCRETE:8)
Block(-6,98,0,STAINED_GLASS_PANE:7)
Block(-6,98,1,STAINED_GLASS_PANE:7)
Block(-6,98,2,CONCRETE:8)
Block(-6,98,3,STAINED_GLASS_PANE:7)
Block(-6,98,4,STAINED_GLASS_PANE:7)
Block(-6,98,5,CONCRETE:8)
Block(-6,98,6,CONCRETE:8)
Block(-6,98,7,STAINED_GLASS_PANE:7)
Block(-6,98,8,CONCRETE:8)
Block(-6,99,-1,CONCRETE:8)
Block(-6,99,0,STAINED_GLASS_PANE:7)
Block(-6,99,1,STAINED_GLASS_PANE:7)
Block(-6,99,2,CONCRETE:8)
Block(-6,99,3,STAINED_GLASS_PANE:7)
Block(-6,99,4,STAINED_GLASS_PANE:7)
Block(-6,99,5,CONCRETE:8)
Block(-6,99,6,CONCRETE:8)
Block(-6,99,7,STAINED_GLASS_PANE:7)
Block(-6,99,8,CONCRETE:8)
Block(-6,100,-1,CONCRETE:8)
Block(-6,100,0,STAINED_GLASS_PANE:7)
Block(-6,100,1,STAINED_GLASS_PANE:7)
Block(-6,100,2,CONCRETE:8)
Block(-6,100,3,STAINED_GLASS_PANE:7)
Block(-6,100,4,STAINED_GLASS_PANE:7)
Block(-6,100,5,CONCRETE:8)
Block(-6,100,6,CONCRETE:8)
Block(-6,100,7,STAINED_GLASS_PANE:7)
Block(-6,100,8,CONCRETE:8)
Block(-6,101,-1,CONCRETE:8)
Block(-6,101,0,STAINED_GLASS_PANE:7)
Block(-6,101,1,STAINED_GLASS_PANE:7)
Block(-6,101,2,CONCRETE:8)
Block(-6,101,3,STAINED_GLASS_PANE:7)
Block(-6,101,4,STAINED_GLASS_PANE:7)
Block(-6,101,5,CONCRETE:8)
Block(-6,101,6,CONCRETE:8)
Block(-6,101,7,STAINED_GLASS_PANE:7)
Block(-6,101,8,CONCRETE:8)
Block(-6,102,-1,CONCRETE:8)
Block(-6,102,0,STAINED_GLASS_PANE:7)
Block(-6,102,1,STAINED_GLASS_PANE:7)
Block(-6,102,2,CONCRETE:8)
Block(-6,102,3,STAINED_GLASS_PANE:7)
Block(-6,102,4,STAINED_GLASS_PANE:7)
Block(-6,102,5,CONCRETE:8)
Block(-6,102,6,CONCRETE:8)
Block(-6,102,7,STAINED_GLASS_PANE:7)
Block(-6,102,8,CONCRETE:8)
Block(-6,103,-1,CONCRETE:8)
Block(-6,103,0,STAINED_GLASS_PANE:7)
Block(-6,103,1,STAINED_GLASS_PANE:7)
Block(-6,103,2,CONCRETE:8)
Block(-6,103,3,STAINED_GLASS_PANE:7)
Block(-6,103,4,STAINED_GLASS_PANE:7)
Block(-6,103,5,CONCRETE:8)
Block(-6,103,6,CONCRETE:8)
Block(-6,103,7,STAINED_GLASS_PANE:7)
Block(-6,103,8,CONCRETE:8)
Block(-6,104,-1,CONCRETE:8)
Block(-6,104,0,STAINED_GLASS_PANE:7)
Block(-6,104,1,STAINED_GLASS_PANE:7)
Block(-6,104,2,CONCRETE:8)
Block(-6,104,3,STAINED_GLASS_PANE:7)
Block(-6,104,4,STAINED_GLASS_PANE:7)
Block(-6,104,5,CONCRETE:8)
Block(-6,104,6,CONCRETE:8)
Block(-6,104,7,STAINED_GLASS_PANE:7)
Block(-6,104,8,CONCRETE:8)
Block(-6,105,-1,CONCRETE:8)
Block(-6,105,0,STAINED_GLASS_PANE:7)
Block(-6,105,1,STAINED_GLASS_PANE:7)
Block(-6,105,2,CONCRETE:8)
Block(-6,105,3,STAINED_GLASS_PANE:7)
Block(-6,105,4,STAINED_GLASS_PANE:7)
Block(-6,105,5,CONCRETE:8)
Block(-6,105,6,CONCRETE:8)
Block(-6,105,7,STAINED_GLASS_PANE:7)
Block(-6,105,8,CONCRETE:8)
Block(-6,106,-1,CONCRETE:8)
Block(-6,106,0,STAINED_GLASS_PANE:7)
Block(-6,106,1,STAINED_GLASS_PANE:7)
Block(-6,106,2,CONCRETE:8)
Block(-6,106,3,STAINED_GLASS_PANE:7)
Block(-6,106,4,STAINED_GLASS_PANE:7)
Block(-6,106,5,CONCRETE:8)
Block(-6,106,6,CONCRETE:8)
Block(-6,106,7,STAINED_GLASS_PANE:7)
Block(-6,106,8,CONCRETE:8)
Block(-6,107,-1,CONCRETE:8)
Block(-6,107,0,STAINED_GLASS_PANE:7)
Block(-6,107,1,STAINED_GLASS_PANE:7)
Block(-6,107,2,CONCRETE:8)
Block(-6,107,3,STAINED_GLASS_PANE:7)
Block(-6,107,4,STAINED_GLASS_PANE:7)
Block(-6,107,5,CONCRETE:8)
Block(-6,107,6,CONCRETE:8)
Block(-6,107,7,STAINED_GLASS_PANE:7)
Block(-6,107,8,CONCRETE:8)
Block(-6,108,-1,CONCRETE:8)
Block(-6,108,0,STAINED_GLASS_PANE:7)
Block(-6,108,1,STAINED_GLASS_PANE:7)
Block(-6,108,2,CONCRETE:8)
Block(-6,108,3,STAINED_GLASS_PANE:7)
Block(-6,108,4,STAINED_GLASS_PANE:7)
Block(-6,108,5,CONCRETE:8)
Block(-6,108,6,CONCRETE:8)
Block(-6,108,7,STAINED_GLASS_PANE:7)
Block(-6,108,8,CONCRETE:8)
Block(-6,109,-1,CONCRETE:8)
Block(-6,109,0,STAINED_GLASS_PANE:7)
Block(-6,109,1,STAINED_GLASS_PANE:7)
Block(-6,109,2,CONCRETE:8)
Block(-6,109,3,STAINED_GLASS_PANE:7)
Block(-6,109,4,STAINED_GLASS_PANE:7)
Block(-6,109,5,CONCRETE:8)
Block(-6,109,6,CONCRETE:8)
Block(-6,109,7,STAINED_GLASS_PANE:7)
Block(-6,109,8,CONCRETE:8)
Block(-6,110,-1,CONCRETE:8)
Block(-6,110,0,STAINED_GLASS_PANE:7)
Block(-6,110,1,STAINED_GLASS_PANE:7)
Block(-6,110,2,CONCRETE:8)
Block(-6,110,3,STAINED_GLASS_PANE:7)
Block(-6,110,4,STAINED_GLASS_PANE:7)
Block(-6,110,5,CONCRETE:8)
Block(-6,110,6,CONCRETE:8)
Block(-6,110,7,STAINED_GLASS_PANE:7)
Block(-6,110,8,CONCRETE:8)
Block(-6,111,-1,CONCRETE:8)
Block(-6,111,0,STAINED_GLASS_PANE:7)
Block(-6,111,1,STAINED_GLASS_PANE:7)
Block(-6,111,2,CONCRETE:8)
Block(-6,111,3,STAINED_GLASS_PANE:7)
Block(-6,111,4,STAINED_GLASS_PANE:7)
Block(-6,111,5,CONCRETE:8)
Block(-6,111,6,CONCRETE:8)
Block(-6,111,7,STAINED_GLASS_PANE:7)
Block(-6,111,8,CONCRETE:8)
Block(-6,112,-1,CONCRETE:8)
Block(-6,112,0,STAINED_GLASS_PANE:7)
Block(-6,112,1,STAINED_GLASS_PANE:7)
Block(-6,112,2,CONCRETE:8)
Block(-6,112,3,STAINED_GLASS_PANE:7)
Block(-6,112,4,STAINED_GLASS_PANE:7)
Block(-6,112,5,CONCRETE:8)
Block(-6,112,6,CONCRETE:8)
Block(-6,112,7,STAINED_GLASS_PANE:7)
Block(-6,112,8,CONCRETE:8)
Block(-6,113,-1,CONCRETE:8)
Block(-6,113,0,STAINED_GLASS_PANE:7)
Block(-6,113,1,STAINED_GLASS_PANE:7)
Block(-6,113,2,CONCRETE:8)
Block(-6,113,3,STAINED_GLASS_PANE:7)
Block(-6,113,4,STAINED_GLASS_PANE:7)
Block(-6,113,5,CONCRETE:8)
Block(-6,113,6,CONCRETE:8)
Block(-6,113,7,STAINED_GLASS_PANE:7)
Block(-6,113,8,CONCRETE:8)
Block(-6,114,-1,CONCRETE:8)
Block(-6,114,0,STAINED_GLASS_PANE:7)
Block(-6,114,1,STAINED_GLASS_PANE:7)
Block(-6,114,2,CONCRETE:8)
Block(-6,114,3,STAINED_GLASS_PANE:7)
Block(-6,114,4,STAINED_GLASS_PANE:7)
Block(-6,114,5,CONCRETE:8)
Block(-6,114,6,CONCRETE:8)
Block(-6,114,7,STAINED_GLASS_PANE:7)
Block(-6,114,8,CONCRETE:8)
Block(-6,115,-1,CONCRETE:8)
Block(-6,115,0,STAINED_GLASS_PANE:7)
Block(-6,115,1,STAINED_GLASS_PANE:7)
Block(-6,115,2,CONCRETE:8)
Block(-6,115,3,STAINED_GLASS_PANE:7)
Block(-6,115,4,STAINED_GLASS_PANE:7)
Block(-6,115,5,CONCRETE:8)
Block(-6,115,6,CONCRETE:8)
Block(-6,115,7,STAINED_GLASS_PANE:7)
Block(-6,115,8,CONCRETE:8)
Block(-6,116,-1,CONCRETE:8)
Block(-6,116,0,STAINED_GLASS_PANE:7)
Block(-6,116,1,STAINED_GLASS_PANE:7)
Block(-6,116,2,CONCRETE:8)
Block(-6,116,3,STAINED_GLASS_PANE:7)
Block(-6,116,4,STAINED_GLASS_PANE:7)
Block(-6,116,5,CONCRETE:8)
Block(-6,116,6,CONCRETE:8)
Block(-6,116,7,STAINED_GLASS_PANE:7)
Block(-6,116,8,CONCRETE:8)
Block(-6,117,-1,CONCRETE:8)
Block(-6,117,0,STAINED_GLASS_PANE:7)
Block(-6,117,1,STAINED_GLASS_PANE:7)
Block(-6,117,2,CONCRETE:8)
Block(-6,117,3,STAINED_GLASS_PANE:7)
Block(-6,117,4,STAINED_GLASS_PANE:7)
Block(-6,117,5,CONCRETE:8)
Block(-6,117,6,CONCRETE:8)
Block(-6,117,7,STAINED_GLASS_PANE:7)
Block(-6,117,8,CONCRETE:8)
Block(-6,118,-1,CONCRETE:8)
Block(-6,118,0,STAINED_GLASS_PANE:7)
Block(-6,118,1,STAINED_GLASS_PANE:7)
Block(-6,118,2,CONCRETE:8)
Block(-6,118,3,STAINED_GLASS_PANE:7)
Block(-6,118,4,STAINED_GLASS_PANE:7)
Block(-6,118,5,CONCRETE:8)
Block(-6,118,6,CONCRETE:8)
Block(-6,118,7,STAINED_GLASS_PANE:7)
Block(-6,118,8,CONCRETE:8)
Block(-6,119,-1,CONCRETE:8)
Block(-6,119,0,STAINED_GLASS_PANE:7)
Block(-6,119,1,STAINED_GLASS_PANE:7)
Block(-6,119,2,CONCRETE:8)
Block(-6,119,3,STAINED_GLASS_PANE:7)
Block(-6,119,4,STAINED_GLASS_PANE:7)
Block(-6,119,5,CONCRETE:8)
Block(-6,119,6,CONCRETE:8)
Block(-6,119,7,STAINED_GLASS_PANE:7)
Block(-6,119,8,CONCRETE:8)
Block(-6,120,-1,CONCRETE:8)
Block(-6,120,0,STAINED_GLASS_PANE:7)
Block(-6,120,1,STAINED_GLASS_PANE:7)
Block(-6,120,2,CONCRETE:8)
Block(-6,120,3,STAINED_GLASS_PANE:7)
Block(-6,120,4,STAINED_GLASS_PANE:7)
Block(-6,120,5,CONCRETE:8)
Block(-6,120,6,CONCRETE:8)
Block(-6,120,7,STAINED_GLASS_PANE:7)
Block(-6,120,8,CONCRETE:8)
Block(-6,121,-1,CONCRETE:8)
Block(-6,121,0,STAINED_GLASS_PANE:7)
Block(-6,121,1,STAINED_GLASS_PANE:7)
Block(-6,121,2,CONCRETE:8)
Block(-6,121,3,STAINED_GLASS_PANE:7)
Block(-6,121,4,STAINED_GLASS_PANE:7)
Block(-6,121,5,CONCRETE:8)
Block(-6,121,6,CONCRETE:8)
Block(-6,121,7,STAINED_GLASS_PANE:7)
Block(-6,121,8,CONCRETE:8)
Block(-6,122,-1,CONCRETE:8)
Block(-6,122,0,STAINED_GLASS_PANE:7)
Block(-6,122,1,STAINED_GLASS_PANE:7)
Block(-6,122,2,CONCRETE:8)
Block(-6,122,3,STAINED_GLASS_PANE:7)
Block(-6,122,4,STAINED_GLASS_PANE:7)
Block(-6,122,5,CONCRETE:8)
Block(-6,122,6,CONCRETE:8)
Block(-6,122,7,STAINED_GLASS_PANE:7)
Block(-6,122,8,CONCRETE:8)
Block(-6,123,-1,CONCRETE:8)
Block(-6,123,0,STAINED_GLASS_PANE:7)
Block(-6,123,1,STAINED_GLASS_PANE:7)
Block(-6,123,2,CONCRETE:8)
Block(-6,123,3,STAINED_GLASS_PANE:7)
Block(-6,123,4,STAINED_GLASS_PANE:7)
Block(-6,123,5,CONCRETE:8)
Block(-6,123,6,CONCRETE:8)
Block(-6,123,7,STAINED_GLASS_PANE:7)
Block(-6,123,8,CONCRETE:8)
Block(-6,124,-1,CONCRETE:8)
Block(-6,124,0,STAINED_GLASS_PANE:7)
Block(-6,124,1,STAINED_GLASS_PANE:7)
Block(-6,124,2,CONCRETE:8)
Block(-6,124,3,STAINED_GLASS_PANE:7)
Block(-6,124,4,STAINED_GLASS_PANE:7)
Block(-6,124,5,CONCRETE:8)
Block(-6,124,6,CONCRETE:8)
Block(-6,124,7,STAINED_GLASS_PANE:7)
Block(-6,124,8,CONCRETE:8)
Block(-6,125,-1,CONCRETE:8)
Block(-6,125,0,STAINED_GLASS_PANE:7)
Block(-6,125,1,STAINED_GLASS_PANE:7)
Block(-6,125,2,CONCRETE:8)
Block(-6,125,3,STAINED_GLASS_PANE:7)
Block(-6,125,4,STAINED_GLASS_PANE:7)
Block(-6,125,5,CONCRETE:8)
Block(-6,125,6,CONCRETE:8)
Block(-6,125,7,STAINED_GLASS_PANE:7)
Block(-6,125,8,CONCRETE:8)
Block(-6,126,-1,CONCRETE:8)
Block(-6,126,0,STAINED_GLASS_PANE:7)
Block(-6,126,1,STAINED_GLASS_PANE:7)
Block(-6,126,2,CONCRETE:8)
Block(-6,126,3,STAINED_GLASS_PANE:7)
Block(-6,126,4,STAINED_GLASS_PANE:7)
Block(-6,126,5,CONCRETE:8)
Block(-6,126,6,CONCRETE:8)
Block(-6,126,7,STAINED_GLASS_PANE:7)
Block(-6,126,8,CONCRETE:8)
Block(-6,127,-1,CONCRETE:8)
Block(-6,127,0,STAINED_GLASS_PANE:7)
Block(-6,127,1,STAINED_GLASS_PANE:7)
Block(-6,127,2,CONCRETE:8)
Block(-6,127,3,STAINED_GLASS_PANE:7)
Block(-6,127,4,STAINED_GLASS_PANE:7)
Block(-6,127,5,CONCRETE:8)
Block(-6,127,6,CONCRETE:8)
Block(-6,127,7,STAINED_GLASS_PANE:7)
Block(-6,127,8,CONCRETE:8)
Block(-6,128,-1,CONCRETE:8)
Block(-6,128,0,STAINED_GLASS_PANE:7)
Block(-6,128,1,STAINED_GLASS_PANE:7)
Block(-6,128,2,CONCRETE:8)
Block(-6,128,3,STAINED_GLASS_PANE:7)
Block(-6,128,4,STAINED_GLASS_PANE:7)
Block(-6,128,5,CONCRETE:8)
Block(-6,128,6,CONCRETE:8)
Block(-6,128,7,STAINED_GLASS_PANE:7)
Block(-6,128,8,CONCRETE:8)
Block(-6,129,-1,CONCRETE:8)
Block(-6,129,0,STAINED_GLASS_PANE:7)
Block(-6,129,1,STAINED_GLASS_PANE:7)
Block(-6,129,2,CONCRETE:8)
Block(-6,129,3,STAINED_GLASS_PANE:7)
Block(-6,129,4,STAINED_GLASS_PANE:7)
Block(-6,129,5,CONCRETE:8)
Block(-6,129,6,CONCRETE:8)
Block(-6,129,7,STAINED_GLASS_PANE:7)
Block(-6,129,8,CONCRETE:8)
Block(-6,130,-1,CONCRETE:8)
Block(-6,130,0,SMOOTH_STAIRS:4)
Block(-6,130,1,SMOOTH_STAIRS:4)
Block(-6,130,2,CONCRETE:8)
Block(-6,130,3,STAINED_GLASS_PANE:7)
Block(-6,130,4,STAINED_GLASS_PANE:7)
Block(-6,130,5,CONCRETE:8)
Block(-6,130,6,CONCRETE:8)
Block(-6,130,7,STAINED_GLASS_PANE:7)
Block(-6,130,8,CONCRETE:8)
Block(-6,131,-1,SMOOTH_STAIRS:0)
Block(-6,131,0,CONCRETE:8)
Block(-6,131,1,CONCRETE:8)
Block(-6,131,2,CONCRETE:8)
Block(-6,131,3,STAINED_GLASS_PANE:7)
Block(-6,131,4,STAINED_GLASS_PANE:7)
Block(-6,131,5,CONCRETE:8)
Block(-6,131,6,CONCRETE:8)
Block(-6,131,7,STAINED_GLASS_PANE:7)
Block(-6,131,8,CONCRETE:8)
Block(-6,132,-1,SMOOTH_STAIRS:4)
Block(-6,132,0,SMOOTH_STAIRS:0)
Block(-6,132,1,SMOOTH_STAIRS:0)
Block(-6,132,2,CONCRETE:8)
Block(-6,132,3,SMOOTH_STAIRS:4)
Block(-6,132,4,SMOOTH_STAIRS:4)
Block(-6,132,5,CONCRETE:8)
Block(-6,132,6,CONCRETE:8)
Block(-6,132,7,SMOOTH_STAIRS:4)
Block(-6,132,8,CONCRETE:8)
Block(-6,133,-3,SMOOTH_STAIRS:4)
Block(-6,133,-2,STEP:8)
Block(-6,133,-1,CONCRETE:8)
Block(-6,133,0,SMOOTH_STAIRS:4)
Block(-6,133,1,SMOOTH_STAIRS:4)
Block(-6,133,2,SMOOTH_STAIRS:0)
Block(-6,133,3,CONCRETE:8)
Block(-6,133,4,CONCRETE:8)
Block(-6,133,5,CONCRETE:8)
Block(-6,133,6,CONCRETE:8)
Block(-6,133,7,CONCRETE:8)
Block(-6,133,8,CONCRETE:8)
Block(-6,134,-3,CONCRETE:7)
Block(-6,134,-2,CONCRETE:7)
Block(-6,134,-1,CONCRETE:7)
Block(-6,134,0,CONCRETE:8)
Block(-6,134,1,CONCRETE:8)
Block(-6,134,2,SMOOTH_STAIRS:4)
Block(-6,134,3,COBBLE_WALL:0)
Block(-6,134,4,SMOOTH_STAIRS:0)
Block(-6,134,5,CONCRETE:8)
Block(-6,134,6,CONCRETE:8)
Block(-6,134,7,CONCRETE:8)
Block(-6,134,8,CONCRETE:8)
Block(-6,135,-3,CONCRETE:15)
Block(-6,135,-2,CONCRETE:7)
Block(-6,135,-1,CONCRETE:7)
Block(-6,135,0,CONCRETE:7)
Block(-6,135,1,CONCRETE:7)
Block(-6,135,2,CONCRETE:8)
Block(-6,135,3,CONCRETE:8)
Block(-6,135,4,SMOOTH_STAIRS:4)
Block(-6,135,5,STEP:0)
Block(-6,135,6,CONCRETE:8)
Block(-6,135,8,STEP:0)
Block(-6,136,-4,SMOOTH_STAIRS:4)
Block(-6,136,-3,CONCRETE:15)
Block(-6,136,-2,CONCRETE:15)
Block(-6,136,-1,CONCRETE:7)
Block(-6,136,0,CONCRETE:7)
Block(-6,136,1,CONCRETE:7)
Block(-6,136,2,CONCRETE:7)
Block(-6,136,3,CONCRETE:7)
Block(-6,136,4,CONCRETE:8)
Block(-6,136,5,SMOOTH_STAIRS:4)
Block(-6,136,6,STEP:0)
Block(-6,136,8,SMOOTH_STAIRS:4)
Block(-6,137,-5,STEP:8)
Block(-6,137,-4,CONCRETE:7)
Block(-6,137,-3,CONCRETE:15)
Block(-6,137,-2,CONCRETE:15)
Block(-6,137,-1,CONCRETE:7)
Block(-6,137,0,CONCRETE:7)
Block(-6,137,1,CONCRETE:7)
Block(-6,137,2,CONCRETE:7)
Block(-6,137,3,CONCRETE:7)
Block(-6,137,4,CONCRETE:7)
Block(-6,137,5,CONCRETE:8)
Block(-6,137,6,SMOOTH_STAIRS:4)
Block(-6,137,7,STONE_BUTTON:2)
Block(-6,137,8,CONCRETE:8)
Block(-6,138,-6,STEP:8)
Block(-6,138,-5,CONCRETE:8)
Block(-6,138,-4,CONCRETE:7)
Block(-6,138,-3,CONCRETE:15)
Block(-6,138,-2,CONCRETE:15)
Block(-6,138,-1,CONCRETE:7)
Block(-6,138,0,CONCRETE:7)
Block(-6,138,1,CONCRETE:7)
Block(-6,138,2,CONCRETE:7)
Block(-6,138,3,CONCRETE:7)
Block(-6,138,4,CONCRETE:7)
Block(-6,138,5,CONCRETE:7)
Block(-6,138,6,CONCRETE:8)
Block(-6,138,7,CONCRETE:8)
Block(-6,138,8,CONCRETE:8)
Block(-6,139,-6,SMOOTH_STAIRS:0)
Block(-6,139,-5,CONCRETE:7)
Block(-6,139,-4,CONCRETE:7)
Block(-6,139,-3,CONCRETE:15)
Block(-6,139,-2,CONCRETE:15)
Block(-6,139,-1,CONCRETE:7)
Block(-6,139,0,CONCRETE:7)
Block(-6,139,1,CONCRETE:7)
Block(-6,139,2,CONCRETE:7)
Block(-6,139,3,CONCRETE:7)
Block(-6,139,4,CONCRETE:7)
Block(-6,139,5,CONCRETE:7)
Block(-6,139,6,CONCRETE:7)
Block(-6,139,7,CONCRETE:7)
Block(-6,139,8,CONCRETE:7)
Block(-6,140,-5,CONCRETE:7)
Block(-6,140,-4,CONCRETE:7)
Block(-6,140,-3,CONCRETE:7)
Block(-6,140,-2,CONCRETE:7)
Block(-6,140,-1,STAINED_GLASS:15)
Block(-6,140,0,STAINED_GLASS:15)
Block(-6,140,1,STAINED_GLASS:15)
Block(-6,140,2,STAINED_GLASS:15)
Block(-6,140,3,STAINED_GLASS:15)
Block(-6,140,4,CONCRETE:7)
Block(-6,140,5,CONCRETE:7)
Block(-6,140,6,STAINED_GLASS:15)
Block(-6,140,7,STAINED_GLASS:15)
Block(-6,140,8,STAINED_GLASS:15)
Block(-6,141,-5,CONCRETE:7)
Block(-6,141,-4,STAINED_GLASS:15)
Block(-6,141,-3,CONCRETE:7)
Block(-6,141,-2,STAINED_GLASS:15)
Block(-6,141,-1,STAINED_GLASS:15)
Block(-6,141,0,STAINED_GLASS:15)
Block(-6,141,1,STAINED_GLASS:15)
Block(-6,141,2,STAINED_GLASS:15)
Block(-6,141,3,STAINED_GLASS:15)
Block(-6,141,4,STAINED_GLASS:15)
Block(-6,141,5,CONCRETE:7)
Block(-6,141,6,STAINED_GLASS:15)
Block(-6,141,7,STAINED_GLASS:15)
Block(-6,141,8,STAINED_GLASS:15)
Block(-6,142,-6,SMOOTH_STAIRS:6)
Block(-6,142,-5,CONCRETE:7)
Block(-6,142,-4,STAINED_GLASS:15)
Block(-6,142,-3,CONCRETE:7)
Block(-6,142,-2,STAINED_GLASS:15)
Block(-6,142,-1,STAINED_GLASS:15)
Block(-6,142,0,STAINED_GLASS:15)
Block(-6,142,1,STAINED_GLASS:15)
Block(-6,142,2,STAINED_GLASS:15)
Block(-6,142,3,STAINED_GLASS:15)
Block(-6,142,4,STAINED_GLASS:15)
Block(-6,142,5,CONCRETE:7)
Block(-6,142,6,STAINED_GLASS:15)
Block(-6,142,7,STAINED_GLASS:15)
Block(-6,142,8,STAINED_GLASS:15)
Block(-6,143,-6,CONCRETE:7)
Block(-6,143,-5,CONCRETE:7)
Block(-6,143,-4,CONCRETE:7)
Block(-6,143,-3,CONCRETE:7)
Block(-6,143,-2,CONCRETE:7)
Block(-6,143,-1,CONCRETE:7)
Block(-6,143,0,CONCRETE:7)
Block(-6,143,1,CONCRETE:7)
Block(-6,143,2,CONCRETE:7)
Block(-6,143,3,CONCRETE:7)
Block(-6,143,4,CONCRETE:7)
Block(-6,143,5,CONCRETE:7)
Block(-6,143,6,CONCRETE:7)
Block(-6,143,7,CONCRETE:7)
Block(-6,143,8,CONCRETE:7)
Block(-6,144,-6,STEP:0)
Block(-6,144,-5,CONCRETE:7)
Block(-6,144,-4,CONCRETE:7)
Block(-6,144,-3,CONCRETE:7)
Block(-6,144,-2,STAINED_GLASS:15)
Block(-6,144,-1,CONCRETE:7)
Block(-6,144,0,STAINED_GLASS:15)
Block(-6,144,1,CONCRETE:7)
Block(-6,144,2,STAINED_GLASS:15)
Block(-6,144,3,CONCRETE:7)
Block(-6,144,4,CONCRETE:7)
Block(-6,144,5,CONCRETE:7)
Block(-6,144,6,CONCRETE:7)
Block(-6,144,7,CONCRETE:7)
Block(-6,144,8,CONCRETE:7)
Block(-6,145,-5,STEP:0)
Block(-6,145,-4,CONCRETE:7)
Block(-6,145,-3,CONCRETE:7)
Block(-6,145,-2,STAINED_GLASS:15)
Block(-6,145,-1,STAINED_GLASS_PANE:15)
Block(-6,145,0,STAINED_GLASS:15)
Block(-6,145,1,STAINED_GLASS_PANE:15)
Block(-6,145,2,STAINED_GLASS:15)
Block(-6,145,3,CONCRETE:7)
Block(-6,145,4,IRON_FENCE:0)
Block(-6,145,5,CONCRETE:7)
Block(-6,145,6,IRON_FENCE:0)
Block(-6,145,7,IRON_FENCE:0)
Block(-6,145,8,IRON_FENCE:0)
Block(-6,146,-4,SMOOTH_STAIRS:0)
Block(-6,146,-3,CONCRETE:7)
Block(-6,146,-2,STAINED_GLASS:15)
Block(-6,146,-1,STAINED_GLASS_PANE:15)
Block(-6,146,0,STAINED_GLASS:15)
Block(-6,146,1,STAINED_GLASS_PANE:15)
Block(-6,146,2,STAINED_GLASS:15)
Block(-6,146,3,CONCRETE:7)
Block(-6,146,5,STEP:0)
Block(-6,147,-3,CONCRETE:7)
Block(-6,147,-2,STAINED_GLASS:15)
Block(-6,147,-1,STAINED_GLASS_PANE:15)
Block(-6,147,0,STAINED_GLASS:15)
Block(-6,147,1,STAINED_GLASS_PANE:15)
Block(-6,147,2,STAINED_GLASS:15)
Block(-6,147,3,CONCRETE:7)
Block(-6,148,-3,CONCRETE:7)
Block(-6,148,-2,STAINED_GLASS:15)
Block(-6,148,-1,STAINED_GLASS_PANE:15)
Block(-6,148,0,STAINED_GLASS:15)
Block(-6,148,1,STAINED_GLASS_PANE:15)
Block(-6,148,2,STAINED_GLASS:15)
Block(-6,148,3,CONCRETE:7)
Block(-6,149,-3,CONCRETE:7)
Block(-6,149,-2,STAINED_GLASS:15)
Block(-6,149,-1,CONCRETE:7)
Block(-6,149,0,STAINED_GLASS:15)
Block(-6,149,1,CONCRETE:7)
Block(-6,149,2,STAINED_GLASS:15)
Block(-6,149,3,CONCRETE:7)
Block(-6,149,4,SMOOTH_STAIRS:4)
Block(-6,149,5,SMOOTH_STAIRS:4)
Block(-6,150,-3,CONCRETE:7)
Block(-6,150,-2,IRON_FENCE:0)
Block(-6,150,-1,CONCRETE:7)
Block(-6,150,0,IRON_FENCE:0)
Block(-6,150,1,CONCRETE:7)
Block(-6,150,2,IRON_FENCE:0)
Block(-6,150,3,CONCRETE:7)
Block(-6,150,4,IRON_FENCE:0)
Block(-6,150,5,IRON_FENCE:0)
Block(-6,151,-3,STEP:0)
Block(-6,151,-1,STEP:0)
Block(-6,151,1,STEP:0)
Block(-6,151,3,STEP:0)
Block(-5,0,-7,CONCRETE:7)
Block(-5,0,-6,CONCRETE:7)
Block(-5,0,-5,CONCRETE:7)
Block(-5,0,-4,CONCRETE:7)
Block(-5,0,-3,CONCRETE:7)
Block(-5,0,-2,CONCRETE:7)
Block(-5,0,-1,CONCRETE:7)
Block(-5,0,0,CONCRETE:7)
Block(-5,0,1,CONCRETE:7)
Block(-5,0,2,CONCRETE:7)
Block(-5,0,3,CONCRETE:7)
Block(-5,0,4,CONCRETE:7)
Block(-5,0,5,CONCRETE:7)
Block(-5,0,6,CONCRETE:7)
Block(-5,0,7,CONCRETE:7)
Block(-5,0,8,CONCRETE:7)
Block(-5,1,-7,CONCRETE:7)
Block(-5,1,-6,CONCRETE:7)
Block(-5,1,-5,CONCRETE:7)
Block(-5,1,-4,CONCRETE:7)
Block(-5,1,-3,CONCRETE:7)
Block(-5,1,-2,CONCRETE:7)
Block(-5,1,-1,CONCRETE:7)
Block(-5,1,0,CONCRETE:7)
Block(-5,1,1,CONCRETE:7)
Block(-5,1,2,CONCRETE:7)
Block(-5,1,3,CONCRETE:7)
Block(-5,1,4,CONCRETE:7)
Block(-5,1,5,CONCRETE:7)
Block(-5,1,6,CONCRETE:7)
Block(-5,1,7,CONCRETE:7)
Block(-5,1,8,CONCRETE:7)
Block(-5,2,-7,CONCRETE:7)
Block(-5,2,-6,CONCRETE:7)
Block(-5,2,-5,CONCRETE:7)
Block(-5,2,-4,CONCRETE:7)
Block(-5,2,-3,CONCRETE:7)
Block(-5,2,-2,CONCRETE:7)
Block(-5,2,-1,CONCRETE:7)
Block(-5,2,0,CONCRETE:7)
Block(-5,2,1,CONCRETE:7)
Block(-5,2,2,CONCRETE:7)
Block(-5,2,3,CONCRETE:7)
Block(-5,2,4,CONCRETE:7)
Block(-5,2,5,CONCRETE:7)
Block(-5,2,6,CONCRETE:7)
Block(-5,2,7,CONCRETE:7)
Block(-5,2,8,CONCRETE:7)
Block(-5,3,-7,CONCRETE:7)
Block(-5,3,-6,CONCRETE:7)
Block(-5,3,-5,CONCRETE:7)
Block(-5,3,-4,CONCRETE:7)
Block(-5,3,-3,CONCRETE:7)
Block(-5,3,-2,CONCRETE:7)
Block(-5,3,-1,CONCRETE:7)
Block(-5,3,0,CONCRETE:7)
Block(-5,3,1,CONCRETE:7)
Block(-5,3,2,CONCRETE:7)
Block(-5,3,3,CONCRETE:7)
Block(-5,3,4,CONCRETE:7)
Block(-5,3,5,CONCRETE:7)
Block(-5,3,6,CONCRETE:7)
Block(-5,3,7,SMOOTH_STAIRS:1)
Block(-5,3,8,SMOOTH_STAIRS:1)
Block(-5,4,-7,CONCRETE:7)
Block(-5,4,-6,CONCRETE:7)
Block(-5,4,-5,CONCRETE:7)
Block(-5,4,-4,CONCRETE:7)
Block(-5,4,-3,CONCRETE:7)
Block(-5,4,-2,CONCRETE:7)
Block(-5,4,-1,CONCRETE:7)
Block(-5,4,0,CONCRETE:7)
Block(-5,4,1,CONCRETE:7)
Block(-5,4,2,CONCRETE:7)
Block(-5,4,3,CONCRETE:7)
Block(-5,4,4,CONCRETE:7)
Block(-5,4,5,CONCRETE:7)
Block(-5,4,6,CONCRETE:7)
Block(-5,4,7,COBBLE_WALL:0)
Block(-5,4,8,COBBLE_WALL:0)
Block(-5,5,-7,CONCRETE:7)
Block(-5,5,-6,CONCRETE:7)
Block(-5,5,-5,CONCRETE:7)
Block(-5,5,-4,CONCRETE:7)
Block(-5,5,-3,CONCRETE:7)
Block(-5,5,-2,CONCRETE:7)
Block(-5,5,-1,CONCRETE:7)
Block(-5,5,0,CONCRETE:7)
Block(-5,5,1,CONCRETE:7)
Block(-5,5,2,CONCRETE:7)
Block(-5,5,3,CONCRETE:7)
Block(-5,5,4,CONCRETE:7)
Block(-5,5,5,CONCRETE:7)
Block(-5,5,6,CONCRETE:7)
Block(-5,5,7,SMOOTH_STAIRS:5)
Block(-5,5,8,SMOOTH_STAIRS:5)
Block(-5,6,-7,CONCRETE:7)
Block(-5,6,-6,CONCRETE:7)
Block(-5,6,-5,CONCRETE:7)
Block(-5,6,-4,CONCRETE:7)
Block(-5,6,-3,CONCRETE:7)
Block(-5,6,-2,CONCRETE:7)
Block(-5,6,-1,CONCRETE:7)
Block(-5,6,0,CONCRETE:7)
Block(-5,6,1,CONCRETE:7)
Block(-5,6,2,CONCRETE:7)
Block(-5,6,3,CONCRETE:7)
Block(-5,6,4,CONCRETE:7)
Block(-5,6,5,CONCRETE:7)
Block(-5,6,6,CONCRETE:7)
Block(-5,6,7,CONCRETE:7)
Block(-5,6,8,CONCRETE:7)
Block(-5,7,-7,CONCRETE:7)
Block(-5,7,-6,CONCRETE:15)
Block(-5,7,-5,CONCRETE:15)
Block(-5,7,-4,CONCRETE:15)
Block(-5,7,-3,CONCRETE:15)
Block(-5,7,-2,CONCRETE:15)
Block(-5,7,-1,CONCRETE:15)
Block(-5,7,0,CONCRETE:15)
Block(-5,7,1,CONCRETE:15)
Block(-5,7,2,CONCRETE:15)
Block(-5,7,3,CONCRETE:15)
Block(-5,7,4,CONCRETE:15)
Block(-5,7,5,CONCRETE:15)
Block(-5,7,6,CONCRETE:15)
Block(-5,7,7,CONCRETE:15)
Block(-5,7,8,CONCRETE:15)
Block(-5,8,-7,BRICK:0)
Block(-5,8,-6,CONCRETE:11)
Block(-5,8,-5,CONCRETE:11)
Block(-5,8,-4,STATIONARY_WATER:0)
Block(-5,8,-3,STATIONARY_WATER:0)
Block(-5,8,-2,CONCRETE:11)
Block(-5,8,-1,CONCRETE:11)
Block(-5,8,1,CONCRETE:7)
Block(-5,8,2,STEP:8)
Block(-5,8,3,STEP:8)
Block(-5,8,4,CONCRETE:7)
Block(-5,8,5,STEP:8)
Block(-5,8,6,STEP:8)
Block(-5,8,7,BRICK_STAIRS:7)
Block(-5,9,-7,BRICK:0)
Block(-5,9,-6,CONCRETE:11)
Block(-5,9,-5,CONCRETE:11)
Block(-5,9,-4,STATIONARY_WATER:0)
Block(-5,9,-3,STATIONARY_WATER:0)
Block(-5,9,-2,CONCRETE:11)
Block(-5,9,-1,CONCRETE:11)
Block(-5,9,1,IRON_FENCE:0)
Block(-5,9,7,IRON_FENCE:0)
Block(-5,10,-7,BRICK:0)
Block(-5,10,-6,SMOOTH_STAIRS:0)
Block(-5,10,-5,CONCRETE:11)
Block(-5,10,-4,STATIONARY_WATER:0)
Block(-5,10,-3,STATIONARY_WATER:0)
Block(-5,10,-2,CONCRETE:11)
Block(-5,10,-1,SMOOTH_STAIRS:0)
Block(-5,11,-7,BRICK_STAIRS:0)
Block(-5,11,-5,CONCRETE:11)
Block(-5,11,-4,STATIONARY_WATER:0)
Block(-5,11,-3,STATIONARY_WATER:0)
Block(-5,11,-2,CONCRETE:11)
Block(-5,12,-7,BRICK:0)
Block(-5,12,-5,SMOOTH_STAIRS:2)
Block(-5,12,-4,CONCRETE:11)
Block(-5,12,-3,CONCRETE:11)
Block(-5,12,-2,SMOOTH_STAIRS:3)
Block(-5,12,0,CONCRETE:4)
Block(-5,13,-7,BRICK:0)
Block(-5,13,-4,STEP:0)
Block(-5,13,-3,STEP:0)
Block(-5,13,0,GOLD_PLATE:0)
Block(-5,13,3,CONCRETE:1)
Block(-5,14,-7,BRICK:0)
Block(-5,14,-2,CONCRETE:14)
Block(-5,14,1,BRICK:0)
Block(-5,14,3,STONE_PLATE:0)
Block(-5,14,4,BRICK_STAIRS:4)
Block(-5,14,7,BRICK_STAIRS:7)
Block(-5,15,-7,CONCRETE:7)
Block(-5,15,-6,CONCRETE:7)
Block(-5,15,-5,CONCRETE:7)
Block(-5,15,-4,CONCRETE:7)
Block(-5,15,-3,CONCRETE:7)
Block(-5,15,-2,CONCRETE:7)
Block(-5,15,-1,CONCRETE:7)
Block(-5,15,0,CONCRETE:7)
Block(-5,15,1,CONCRETE:7)
Block(-5,15,2,BRICK:0)
Block(-5,15,3,CONCRETE:7)
Block(-5,15,4,CONCRETE:7)
Block(-5,15,5,BRICK_STAIRS:5)
Block(-5,15,6,BRICK_STAIRS:6)
Block(-5,15,7,CONCRETE:7)
Block(-5,15,8,BRICK_STAIRS:7)
Block(-5,16,-7,CONCRETE:7)
Block(-5,16,-6,CONCRETE:7)
Block(-5,16,-5,CONCRETE:7)
Block(-5,16,-4,CONCRETE:7)
Block(-5,16,-3,CONCRETE:7)
Block(-5,16,-2,CONCRETE:7)
Block(-5,16,-1,CONCRETE:7)
Block(-5,16,0,CONCRETE:7)
Block(-5,16,1,CONCRETE:7)
Block(-5,16,2,CONCRETE:7)
Block(-5,16,3,CONCRETE:7)
Block(-5,16,4,CONCRETE:7)
Block(-5,16,5,CONCRETE:7)
Block(-5,16,6,CONCRETE:7)
Block(-5,16,7,CONCRETE:7)
Block(-5,16,8,CONCRETE:7)
Block(-5,17,-7,SMOOTH_STAIRS:2)
Block(-5,17,-6,CONCRETE:7)
Block(-5,17,-5,CONCRETE:7)
Block(-5,17,-4,CONCRETE:7)
Block(-5,17,-3,CONCRETE:7)
Block(-5,17,-2,CONCRETE:7)
Block(-5,17,-1,CONCRETE:7)
Block(-5,17,0,CONCRETE:7)
Block(-5,17,1,CONCRETE:7)
Block(-5,17,2,CONCRETE:7)
Block(-5,17,3,CONCRETE:7)
Block(-5,17,4,CONCRETE:7)
Block(-5,17,5,CONCRETE:15)
Block(-5,17,6,CONCRETE:15)
Block(-5,17,7,CONCRETE:15)
Block(-5,17,8,CONCRETE:15)
Block(-5,18,-6,SMOOTH_STAIRS:2)
Block(-5,18,-5,CONCRETE:8)
Block(-5,18,-4,CONCRETE:7)
Block(-5,18,-3,CONCRETE:7)
Block(-5,18,-2,CONCRETE:7)
Block(-5,18,-1,CONCRETE:7)
Block(-5,18,0,SMOOTH_STAIRS:0)
Block(-5,18,1,CONCRETE:7)
Block(-5,18,2,CONCRETE:8)
Block(-5,18,3,CONCRETE:8)
Block(-5,18,4,CONCRETE:8)
Block(-5,18,5,QUARTZ_STAIRS:3)
Block(-5,18,6,DARK_OAK_FENCE:0)
Block(-5,18,7,QUARTZ_STAIRS:2)
Block(-5,19,-5,CONCRETE:8)
Block(-5,19,-4,CONCRETE:7)
Block(-5,19,-3,CONCRETE:7)
Block(-5,19,-2,CONCRETE:7)
Block(-5,19,-1,CONCRETE:7)
Block(-5,19,1,CONCRETE:7)
Block(-5,19,2,STAINED_GLASS_PANE:7)
Block(-5,19,3,STAINED_GLASS_PANE:7)
Block(-5,19,4,CONCRETE:8)
Block(-5,19,6,CARPET:15)
Block(-5,20,-5,CONCRETE:8)
Block(-5,20,-4,CONCRETE:7)
Block(-5,20,-3,CONCRETE:7)
Block(-5,20,-2,CONCRETE:7)
Block(-5,20,-1,CONCRETE:7)
Block(-5,20,1,CONCRETE:7)
Block(-5,20,2,STAINED_GLASS_PANE:7)
Block(-5,20,3,STAINED_GLASS_PANE:7)
Block(-5,20,4,CONCRETE:8)
Block(-5,21,-5,CONCRETE:8)
Block(-5,21,-4,CONCRETE:7)
Block(-5,21,-3,CONCRETE:7)
Block(-5,21,-2,CONCRETE:7)
Block(-5,21,-1,SMOOTH_STAIRS:0)
Block(-5,21,1,CONCRETE:7)
Block(-5,21,2,STAINED_GLASS_PANE:7)
Block(-5,21,3,STAINED_GLASS_PANE:7)
Block(-5,21,4,CONCRETE:8)
Block(-5,22,-5,SMOOTH_STAIRS:2)
Block(-5,22,-4,CONCRETE:7)
Block(-5,22,-3,CONCRETE:7)
Block(-5,22,-2,CONCRETE:7)
Block(-5,22,1,STEP:0)
Block(-5,22,2,STAINED_GLASS_PANE:7)
Block(-5,22,3,STAINED_GLASS_PANE:7)
Block(-5,22,4,CONCRETE:8)
Block(-5,22,7,SMOOTH_STAIRS:5)
Block(-5,23,-5,SMOOTH_STAIRS:6)
Block(-5,23,-4,CONCRETE:7)
Block(-5,23,-3,CONCRETE:7)
Block(-5,23,-2,CONCRETE:7)
Block(-5,23,1,STEP:8)
Block(-5,23,2,STAINED_GLASS_PANE:7)
Block(-5,23,3,STAINED_GLASS_PANE:7)
Block(-5,23,4,CONCRETE:8)
Block(-5,23,6,TRAP_DOOR:4)
Block(-5,23,7,DIRT:2)
Block(-5,23,8,TRAP_DOOR:5)
Block(-5,24,-5,CONCRETE:8)
Block(-5,24,-4,CONCRETE:7)
Block(-5,24,-3,CONCRETE:7)
Block(-5,24,-2,CONCRETE:7)
Block(-5,24,-1,SMOOTH_STAIRS:4)
Block(-5,24,1,CONCRETE:7)
Block(-5,24,2,STAINED_GLASS_PANE:7)
Block(-5,24,3,STAINED_GLASS_PANE:7)
Block(-5,24,4,CONCRETE:8)
Block(-5,24,7,DEAD_BUSH:0)
Block(-5,25,-5,CONCRETE:8)
Block(-5,25,-4,CONCRETE:7)
Block(-5,25,-3,CONCRETE:7)
Block(-5,25,-2,CONCRETE:7)
Block(-5,25,-1,CONCRETE:7)
Block(-5,25,1,CONCRETE:7)
Block(-5,25,2,STAINED_GLASS_PANE:7)
Block(-5,25,3,STAINED_GLASS_PANE:7)
Block(-5,25,4,CONCRETE:8)
Block(-5,26,-5,CONCRETE:8)
Block(-5,26,-4,CONCRETE:7)
Block(-5,26,-3,CONCRETE:7)
Block(-5,26,-2,CONCRETE:7)
Block(-5,26,-1,CONCRETE:7)
Block(-5,26,1,CONCRETE:7)
Block(-5,26,2,STAINED_GLASS_PANE:7)
Block(-5,26,3,STAINED_GLASS_PANE:7)
Block(-5,26,4,CONCRETE:8)
Block(-5,27,-6,SMOOTH_STAIRS:6)
Block(-5,27,-5,CONCRETE:8)
Block(-5,27,-4,CONCRETE:7)
Block(-5,27,-3,CONCRETE:7)
Block(-5,27,-2,CONCRETE:7)
Block(-5,27,-1,CONCRETE:7)
Block(-5,27,0,SMOOTH_STAIRS:4)
Block(-5,27,1,CONCRETE:7)
Block(-5,27,2,CONCRETE:8)
Block(-5,27,3,CONCRETE:8)
Block(-5,27,4,CONCRETE:8)
Block(-5,28,-6,CONCRETE:15)
Block(-5,28,-5,CONCRETE:7)
Block(-5,28,-4,CONCRETE:7)
Block(-5,28,-3,CONCRETE:7)
Block(-5,28,-2,CONCRETE:7)
Block(-5,28,-1,CONCRETE:7)
Block(-5,28,0,CONCRETE:7)
Block(-5,28,1,CONCRETE:7)
Block(-5,28,2,CONCRETE:7)
Block(-5,28,3,CONCRETE:7)
Block(-5,28,4,CONCRETE:7)
Block(-5,28,5,CONCRETE:7)
Block(-5,28,6,CONCRETE:7)
Block(-5,28,7,CONCRETE:7)
Block(-5,28,8,CONCRETE:7)
Block(-5,29,-7,SMOOTH_STAIRS:6)
Block(-5,29,-6,CONCRETE:7)
Block(-5,29,-5,CONCRETE:7)
Block(-5,29,-4,CONCRETE:7)
Block(-5,29,-3,CONCRETE:7)
Block(-5,29,-2,CONCRETE:7)
Block(-5,29,-1,CONCRETE:7)
Block(-5,29,0,CONCRETE:7)
Block(-5,29,1,CONCRETE:7)
Block(-5,29,2,CONCRETE:7)
Block(-5,29,3,CONCRETE:7)
Block(-5,29,4,CONCRETE:7)
Block(-5,29,5,CONCRETE:7)
Block(-5,29,6,CONCRETE:7)
Block(-5,29,7,CONCRETE:7)
Block(-5,29,8,CONCRETE:7)
Block(-5,30,-7,COBBLE_WALL:0)
Block(-5,30,-6,CONCRETE:15)
Block(-5,30,-5,CONCRETE:7)
Block(-5,30,-4,CONCRETE:7)
Block(-5,30,-3,CONCRETE:7)
Block(-5,30,-2,CONCRETE:7)
Block(-5,30,-1,CONCRETE:7)
Block(-5,30,0,CONCRETE:7)
Block(-5,30,1,CONCRETE:7)
Block(-5,30,2,CONCRETE:7)
Block(-5,30,3,CONCRETE:7)
Block(-5,30,4,CONCRETE:7)
Block(-5,30,5,CONCRETE:7)
Block(-5,30,6,CONCRETE:7)
Block(-5,30,7,CONCRETE:7)
Block(-5,30,8,CONCRETE:7)
Block(-5,31,-6,CONCRETE:8)
Block(-5,31,-5,CONCRETE:7)
Block(-5,31,-4,CONCRETE:7)
Block(-5,31,-3,CONCRETE:7)
Block(-5,31,-2,CONCRETE:7)
Block(-5,31,-1,PRISMARINE:0)
Block(-5,31,0,CONCRETE:7)
Block(-5,31,1,CONCRETE:7)
Block(-5,31,2,PRISMARINE:0)
Block(-5,31,3,CONCRETE:7)
Block(-5,31,4,CONCRETE:7)
Block(-5,31,5,PRISMARINE:0)
Block(-5,31,6,CONCRETE:7)
Block(-5,31,7,CONCRETE:7)
Block(-5,31,8,PRISMARINE:0)
Block(-5,32,-5,CONCRETE:7)
Block(-5,32,-4,CONCRETE:7)
Block(-5,32,-3,CONCRETE:15)
Block(-5,32,-2,CONCRETE:7)
Block(-5,32,-1,CONCRETE:7)
Block(-5,32,0,CONCRETE:7)
Block(-5,32,1,CONCRETE:7)
Block(-5,32,2,CONCRETE:7)
Block(-5,32,3,CONCRETE:7)
Block(-5,32,4,CONCRETE:7)
Block(-5,32,5,CONCRETE:7)
Block(-5,32,6,CONCRETE:7)
Block(-5,32,7,CONCRETE:7)
Block(-5,32,8,CONCRETE:7)
Block(-5,33,-5,SMOOTH_STAIRS:0)
Block(-5,33,-4,CONCRETE:7)
Block(-5,33,-3,SMOOTH_STAIRS:5)
