
#######################################################################
# +-----------------------------------------------------------------+ #
# |                            BO4 object                           | #
# +-----------------------------------------------------------------+ #
#######################################################################

Author: NLBlackEagle

Description: No description given

SettingsMode: WriteDisable


#######################################################################
# +-----------------------------------------------------------------+ #
# |                          Main settings                          | #
# +-----------------------------------------------------------------+ #
#######################################################################

Frequency: 0

SpawnHeight: highestBlock

UseCenterForHighestBlock: true

##############################
# Height Limits for the BO4. #
##############################

MinHeight: 0

MaxHeight: 255

InheritBO3: 

InheritBO3Rotation: NORTH

OverrideChildSettings: true

OverrideParentHeight: false

CanOverride: true

BranchFrequency: 0

BranchFrequencyGroup: 

MustBeBelowOther: false

MustBeInside: 

CannotBeInside: 

ReplacesBO3: L4-M-CrossC0R0, L4-M-CrossC0R1, L4-M-CrossC0R2, L4-M-CrossC0R3, L4-M-CrossC1R0, L4-M-CrossC1R1, L4-M-CrossC1R2, L4-M-CrossC1R3, L4-M-CrossC2R0, L4-M-CrossC2R1, L4-M-CrossC2R2, L4-M-CrossC2R3, L4-M-CrossC3R0, L4-M-CrossC3R1, L4-M-CrossC3R2, L4-M-CrossC3R3, L4-M-Straigth-START_01-C0R0, L4-M-Straigth-START_01-C0R1, L4-M-Straigth-START_01-C1R0, L4-M-Straigth-START_01-C1R1, L4-M-Straigth-START_01-C2R0, L4-M-Straigth-START_01-C2R1, L4-M-Straigth-START_01-C3R0, L4-M-Straigth-START_01-C3R1, L4-M-Straigth-3CC0R0, L4-M-Straigth-3CC0R1, L4-M-Straigth-3CC0R2, L4-M-Straigth-3CC1R0, L4-M-Straigth-3CC1R1, L4-M-Straigth-3CC1R2, L4-M-Straigth-3CC2R0, L4-M-Straigth-3CC2R1, L4-M-Straigth-3CC2R2, L4-M-Straigth-3CC3R0, L4-M-Straigth-3CC3R1, L4-M-Straigth-3CC3R2, L4-M-Cross, skyscraper_2x2_01, skyscraper_2x2_02, skyscraper_2x2_03, skyscraper_2x2_04, skyscraper_2x2_05, skyscraper_3x3_01, skyscraper_3x3_02, skyscraper_3x3_03, L3-M-Straigth-2CC0R0, L3-M-Straigth-2CC0R1, L3-M-Straigth-2CC1R0, L3-M-Straigth-2CC1R1, L3-M-Straigth-2CC2R0, L3-M-Straigth-2CC2R1, L3-M-Straigth-2CC3R0, L3-M-Straigth-2CC3R1, L3-M-Straigth-3CC0R0, L3-M-Straigth-3CC0R1, L3-M-Straigth-3CC0R2, L3-M-Straigth-3CC1R0, L3-M-Straigth-3CC1R1, L3-M-Straigth-3CC1R2, L3-M-Straigth-3CC2R0, L3-M-Straigth-3CC2R1, L3-M-Straigth-3CC2R2, L3-M-Straigth-3CC3R0, L3-M-Straigth-3CC3R1, L3-M-Straigth-3CC3R2L4-M-CrossC0R0, L4-M-CrossC0R1, L4-M-CrossC0R2, L4-M-CrossC0R3, L4-M-CrossC1R0, L4-M-CrossC1R1, L4-M-CrossC1R2, L4-M-CrossC1R3, L4-M-CrossC2R0, L4-M-CrossC2R1, L4-M-CrossC2R2, L4-M-CrossC2R3, L4-M-CrossC3R0, L4-M-CrossC3R1, L4-M-CrossC3R2, L4-M-CrossC3R3, L4-M-Straigth-START_01-C0R0, L4-M-Straigth-START_01-C0R1, L4-M-Straigth-START_01-C1R0, L4-M-Straigth-START_01-C1R1, L4-M-Straigth-START_01-C2R0, L4-M-Straigth-START_01-C2R1, L4-M-Straigth-START_01-C3R0, L4-M-Straigth-START_01-C3R1, L4-M-Straigth-3CC0R0, L4-M-Straigth-3CC0R1, L4-M-Straigth-3CC0R2, L4-M-Straigth-3CC1R0, L4-M-Straigth-3CC1R1, L4-M-Straigth-3CC1R2, L4-M-Straigth-3CC2R0, L4-M-Straigth-3CC2R1, L4-M-Straigth-3CC2R2, L4-M-Straigth-3CC3R0, L4-M-Straigth-3CC3R1, L4-M-Straigth-3CC3R2, L4-M-Cross, skyscraper_2x2_01, skyscraper_2x2_02, skyscraper_2x2_03, skyscraper_2x2_04, skyscraper_2x2_05, skyscraper_3x3_01, skyscraper_3x3_02, skyscraper_3x3_03

MustBeInsideWorldBorders: false

CanSpawnOnWater: true

SpawnOnWaterOnly: false

SpawnUnderWater: false

SpawnAtWaterLevel: false

HeightOffset: 0

RemoveAir: false

ReplaceAbove: 

ReplaceBelow: 

ReplaceWithBiomeBlocks: true

ReplaceWithSurfaceBlock: GRASS

ReplaceWithGroundBlock: DIRT

ReplaceWithStoneBlock: STONE

SmoothRadius: 0

SmoothHeightOffset: 0

SmoothStartTop: false

SmoothStartWood: false

SmoothingSurfaceBlock: 

SmoothingGroundBlock: 

BO3Group: 

IsSpawnPoint: false

DoReplaceBlocks: true


#######################################################################
# +-----------------------------------------------------------------+ #
# |                              Blocks                             | #
# +-----------------------------------------------------------------+ #
#######################################################################

Block(-8,0,-7,CONCRETE:7)
Block(-8,0,-6,CONCRETE:7)
Block(-8,0,-5,CONCRETE:7)
Block(-8,0,-4,CONCRETE:7)
Block(-8,0,-3,CONCRETE:7)
Block(-8,0,-2,CONCRETE:7)
Block(-8,0,-1,CONCRETE:7)
Block(-8,0,0,CONCRETE:7)
Block(-8,0,1,CONCRETE:7)
Block(-8,0,2,CONCRETE:7)
Block(-8,0,3,CONCRETE:7)
Block(-8,0,4,CONCRETE:7)
Block(-8,0,5,CONCRETE:7)
Block(-8,0,6,CONCRETE:7)
Block(-8,0,7,CONCRETE:7)
Block(-8,0,8,CONCRETE:7)
Block(-8,1,-7,CONCRETE:7)
Block(-8,1,-6,CONCRETE:7)
Block(-8,1,-5,CONCRETE:7)
Block(-8,1,-4,CONCRETE:7)
Block(-8,1,-3,CONCRETE:7)
Block(-8,1,-2,STATIONARY_WATER:0)
Block(-8,1,-1,STATIONARY_WATER:0)
Block(-8,1,0,STATIONARY_WATER:0)
Block(-8,1,1,STATIONARY_WATER:0)
Block(-8,1,2,CONCRETE:7)
Block(-8,1,3,CONCRETE:7)
Block(-8,1,4,CONCRETE:7)
Block(-8,1,5,CONCRETE:7)
Block(-8,1,6,CONCRETE:7)
Block(-8,1,7,AIR:0)
Block(-8,1,8,CONCRETE:7)
Block(-8,2,-7,CONCRETE:7)
Block(-8,2,-6,CONCRETE:7)
Block(-8,2,-5,CONCRETE:7)
Block(-8,2,-4,CONCRETE:7)
Block(-8,2,-3,SMOOTH_STAIRS:3)
Block(-8,2,-2,AIR:0)
Block(-8,2,-1,AIR:0)
Block(-8,2,0,AIR:0)
Block(-8,2,1,AIR:0)
Block(-8,2,2,SMOOTH_STAIRS:2)
Block(-8,2,3,CONCRETE:7)
Block(-8,2,4,CONCRETE:7)
Block(-8,2,5,CONCRETE:7)
Block(-8,2,6,CONCRETE:7)
Block(-8,2,7,IRON_TRAPDOOR:8)
Block(-8,2,8,CONCRETE:7)
Block(-8,3,-7,AIR:0)
Block(-8,3,-6,AIR:0)
Block(-8,3,-5,CONCRETE:7)
Block(-8,3,-4,CONCRETE:7)
Block(-8,3,-3,AIR:0)
Block(-8,3,-2,AIR:0)
Block(-8,3,-1,AIR:0)
Block(-8,3,0,AIR:0)
Block(-8,3,1,AIR:0)
Block(-8,3,2,AIR:0)
Block(-8,3,3,AIR:0)
Block(-8,3,4,CONCRETE:7)
Block(-8,3,5,CONCRETE:7)
Block(-8,3,6,AIR:0)
Block(-8,3,7,AIR:0)
Block(-8,3,8,CONCRETE:7)
Block(-8,4,-7,AIR:0)
Block(-8,4,-6,AIR:0)
Block(-8,4,-5,CONCRETE:7)
Block(-8,4,-4,CONCRETE:7)
Block(-8,4,-3,AIR:0)
Block(-8,4,-2,AIR:0)
Block(-8,4,-1,AIR:0)
Block(-8,4,0,AIR:0)
Block(-8,4,1,AIR:0)
Block(-8,4,2,AIR:0)
Block(-8,4,3,AIR:0)
Block(-8,4,4,CONCRETE:7)
Block(-8,4,5,CONCRETE:7)
Block(-8,4,6,AIR:0)
Block(-8,4,7,AIR:0)
Block(-8,4,8,CONCRETE:7)
Block(-8,5,-7,CONCRETE:14)
Block(-8,5,-6,CONCRETE:11)
Block(-8,5,-5,CONCRETE:7)
Block(-8,5,-4,CONCRETE:7)
Block(-8,5,-3,AIR:0)
Block(-8,5,-2,AIR:0)
Block(-8,5,-1,AIR:0)
Block(-8,5,0,AIR:0)
Block(-8,5,1,AIR:0)
Block(-8,5,2,AIR:0)
Block(-8,5,3,AIR:0)
Block(-8,5,4,CONCRETE:7)
Block(-8,5,5,CONCRETE:7)
Block(-8,5,6,AIR:0)
Block(-8,5,7,AIR:0)
Block(-8,5,8,CONCRETE:7)
Block(-8,6,-7,IRON_FENCE:0)
Block(-8,6,-6,AIR:0)
Block(-8,6,-5,CONCRETE:7)
Block(-8,6,-4,CONCRETE:7)
Block(-8,6,-3,AIR:0)
Block(-8,6,-2,AIR:0)
Block(-8,6,-1,AIR:0)
Block(-8,6,0,AIR:0)
Block(-8,6,1,AIR:0)
Block(-8,6,2,AIR:0)
Block(-8,6,3,AIR:0)
Block(-8,6,4,CONCRETE:7)
Block(-8,6,5,CONCRETE:7)
Block(-8,6,6,AIR:0)
Block(-8,6,7,AIR:0)
Block(-8,6,8,CONCRETE:7)
Block(-8,7,-7,CONCRETE:7)
Block(-8,7,-6,CONCRETE:7)
Block(-8,7,-5,CONCRETE:7)
Block(-8,7,-4,CONCRETE:7)
Block(-8,7,-3,CONCRETE:7)
Block(-8,7,-2,CONCRETE:7)
Block(-8,7,-1,CONCRETE:7)
Block(-8,7,0,CONCRETE:7)
Block(-8,7,1,CONCRETE:7)
Block(-8,7,2,CONCRETE:7)
Block(-8,7,3,CONCRETE:7)
Block(-8,7,4,CONCRETE:7)
Block(-8,7,5,CONCRETE:7)
Block(-8,7,6,CONCRETE:7)
Block(-8,7,7,CONCRETE:7)
Block(-8,7,8,CONCRETE:7)
Block(-8,8,-7,CONCRETE:7)
Block(-8,8,-6,CONCRETE:7)
Block(-8,8,-5,CONCRETE:7)
Block(-8,8,-4,CONCRETE:7)
Block(-8,8,-3,CONCRETE:7)
Block(-8,8,-2,CONCRETE:7)
Block(-8,8,-1,CONCRETE:7)
Block(-8,8,0,CONCRETE:7)
Block(-8,8,1,CONCRETE:7)
Block(-8,8,2,CONCRETE:7)
Block(-8,8,3,CONCRETE:7)
Block(-8,8,4,CONCRETE:7)
Block(-8,8,5,CONCRETE:7)
Block(-8,8,6,CONCRETE:7)
Block(-8,8,7,CONCRETE:7)
Block(-8,8,8,CONCRETE:7)
Block(-8,9,-7,CONCRETE:7)
Block(-8,9,-6,CONCRETE:7)
Block(-8,9,-5,CONCRETE:7)
Block(-8,9,-4,CONCRETE:7)
Block(-8,9,-3,CONCRETE:7)
Block(-8,9,-2,CONCRETE:7)
Block(-8,9,-1,CONCRETE:7)
Block(-8,9,0,CONCRETE:7)
Block(-8,9,1,CONCRETE:7)
Block(-8,9,2,CONCRETE:7)
Block(-8,9,3,CONCRETE:7)
Block(-8,9,4,CONCRETE:7)
Block(-8,9,5,CONCRETE:7)
Block(-8,9,6,CONCRETE:7)
Block(-8,9,7,CONCRETE:7)
Block(-8,9,8,CONCRETE:7)
Block(-8,10,-7,CONCRETE:7)
Block(-8,10,-6,CONCRETE:7)
Block(-8,10,-5,CONCRETE:7)
Block(-8,10,-4,CONCRETE:7)
Block(-8,10,-3,CONCRETE:7)
Block(-8,10,-2,CONCRETE:7)
Block(-8,10,-1,CONCRETE:7)
Block(-8,10,0,CONCRETE:7)
Block(-8,10,1,CONCRETE:7)
Block(-8,10,2,CONCRETE:7)
Block(-8,10,3,CONCRETE:7)
Block(-8,10,4,CONCRETE:7)
Block(-8,10,5,CONCRETE:7)
Block(-8,10,6,CONCRETE:7)
Block(-8,10,7,CONCRETE:7)
Block(-8,10,8,CONCRETE:7)
Block(-8,11,-7,CONCRETE:7)
Block(-8,11,-6,CONCRETE:7)
Block(-8,11,-5,CONCRETE:7)
Block(-8,11,-4,CONCRETE:7)
Block(-8,11,-3,CONCRETE:7)
Block(-8,11,-2,CONCRETE:7)
Block(-8,11,-1,CONCRETE:7)
Block(-8,11,0,CONCRETE:7)
Block(-8,11,1,CONCRETE:7)
Block(-8,11,2,CONCRETE:7)
Block(-8,11,3,CONCRETE:7)
Block(-8,11,4,CONCRETE:7)
Block(-8,11,5,CONCRETE:7)
Block(-8,11,6,CONCRETE:7)
Block(-8,11,7,CONCRETE:7)
Block(-8,11,8,CONCRETE:7)
Block(-8,12,-7,CONCRETE:7)
Block(-8,12,-6,CONCRETE:7)
Block(-8,12,-5,CONCRETE:7)
Block(-8,12,-4,CONCRETE:7)
Block(-8,12,-3,CONCRETE:7)
Block(-8,12,-2,CONCRETE:7)
Block(-8,12,-1,CONCRETE:7)
Block(-8,12,0,CONCRETE:7)
Block(-8,12,1,CONCRETE:7)
Block(-8,12,2,CONCRETE:7)
Block(-8,12,3,CONCRETE:7)
Block(-8,12,4,CONCRETE:7)
Block(-8,12,5,CONCRETE:7)
Block(-8,12,6,CONCRETE:7)
Block(-8,12,7,CONCRETE:7)
Block(-8,12,8,CONCRETE:7)
Block(-8,13,-7,CONCRETE:7)
Block(-8,13,-6,CONCRETE:7)
Block(-8,13,-5,CONCRETE:7)
Block(-8,13,-4,CONCRETE:7)
Block(-8,13,-3,CONCRETE:7)
Block(-8,13,-2,CONCRETE:7)
Block(-8,13,-1,CONCRETE:7)
Block(-8,13,0,CONCRETE:7)
Block(-8,13,1,CONCRETE:7)
Block(-8,13,2,CONCRETE:7)
Block(-8,13,3,CONCRETE:7)
Block(-8,13,4,CONCRETE:7)
Block(-8,13,5,CONCRETE:7)
Block(-8,13,6,CONCRETE:7)
Block(-8,13,7,CONCRETE:7)
Block(-8,13,8,CONCRETE:7)
Block(-8,14,-7,CONCRETE:7)
Block(-8,14,-6,CONCRETE:7)
Block(-8,14,-5,CONCRETE:7)
Block(-8,14,-4,CONCRETE:7)
Block(-8,14,-3,CONCRETE:7)
Block(-8,14,-2,IRON_DOOR_BLOCK:0)
Block(-8,14,-1,IRON_DOOR_BLOCK:0)
Block(-8,14,0,CONCRETE:7)
Block(-8,14,1,CONCRETE:7)
Block(-8,14,2,CONCRETE:7)
Block(-8,14,3,CONCRETE:7)
Block(-8,14,4,CONCRETE:7)
Block(-8,14,5,CONCRETE:7)
Block(-8,14,6,CONCRETE:7)
Block(-8,14,7,CONCRETE:7)
Block(-8,14,8,CONCRETE:7)
Block(-8,15,-7,CONCRETE:7)
Block(-8,15,-6,CONCRETE:7)
Block(-8,15,-5,CONCRETE:7)
Block(-8,15,-4,CONCRETE:7)
Block(-8,15,-3,CONCRETE:7)
Block(-8,15,-2,IRON_DOOR_BLOCK:8)
Block(-8,15,-1,IRON_DOOR_BLOCK:9)
Block(-8,15,0,CONCRETE:7)
Block(-8,15,1,CONCRETE:7)
Block(-8,15,2,CONCRETE:7)
Block(-8,15,3,CONCRETE:7)
Block(-8,15,4,CONCRETE:7)
Block(-8,15,5,CONCRETE:7)
Block(-8,15,6,CONCRETE:7)
Block(-8,15,7,CONCRETE:7)
Block(-8,15,8,CONCRETE:7)
Block(-8,16,-7,CONCRETE:7)
Block(-8,16,-6,CONCRETE:7)
Block(-8,16,-5,CONCRETE:7)
Block(-8,16,-4,CONCRETE:7)
Block(-8,16,-3,CONCRETE:7)
Block(-8,16,-2,CONCRETE:7)
Block(-8,16,-1,CONCRETE:7)
Block(-8,16,0,CONCRETE:7)
Block(-8,16,1,CONCRETE:7)
Block(-8,16,2,CONCRETE:7)
Block(-8,16,3,CONCRETE:7)
Block(-8,16,4,CONCRETE:7)
Block(-8,16,5,CONCRETE:7)
Block(-8,16,6,CONCRETE:7)
Block(-8,16,7,CONCRETE:7)
Block(-8,16,8,CONCRETE:7)
Block(-8,17,-7,CONCRETE:7)
Block(-8,17,-6,CONCRETE:7)
Block(-8,17,-5,CONCRETE:7)
Block(-8,17,-4,CONCRETE:7)
Block(-8,17,-3,CONCRETE:7)
Block(-8,17,-2,CONCRETE:7)
Block(-8,17,-1,CONCRETE:7)
Block(-8,17,0,CONCRETE:7)
Block(-8,17,1,CONCRETE:7)
Block(-8,17,2,CONCRETE:7)
Block(-8,17,3,CONCRETE:7)
Block(-8,17,4,CONCRETE:7)
Block(-8,17,5,CONCRETE:7)
Block(-8,17,6,CONCRETE:7)
Block(-8,17,7,CONCRETE:7)
Block(-8,17,8,DOUBLE_STEP:0)
Block(-8,18,-7,STAINED_GLASS_PANE:15)
Block(-8,18,-6,CONCRETE:7)
Block(-8,18,-3,DARK_OAK_DOOR:1)
Block(-8,18,5,DARK_OAK_STAIRS:2)
Block(-8,18,6,GRASS:0)
Block(-8,18,7,CONCRETE:7)
Block(-8,19,-7,STAINED_GLASS_PANE:15)
Block(-8,19,-6,CONCRETE:7)
Block(-8,19,-3,DARK_OAK_DOOR:8)
Block(-8,19,6,LONG_GRASS:1)
Block(-8,19,7,STAINED_GLASS_PANE:15)
Block(-8,20,-7,STAINED_GLASS_PANE:15)
Block(-8,20,-6,CONCRETE:7)
Block(-8,20,-3,STAINED_GLASS:15)
Block(-8,20,7,STAINED_GLASS_PANE:15)
Block(-8,21,-7,CONCRETE:7)
Block(-8,21,-6,CONCRETE:7)
Block(-8,21,-5,STEP:8)
Block(-8,21,-4,STEP:8)
Block(-8,21,-3,CONCRETE:7)
Block(-8,21,-2,CONCRETE:8)
Block(-8,21,-1,CONCRETE:8)
Block(-8,21,0,CONCRETE:8)
Block(-8,21,1,CONCRETE:8)
Block(-8,21,2,CONCRETE:8)
Block(-8,21,3,CONCRETE:8)
Block(-8,21,4,CONCRETE:8)
Block(-8,21,5,CONCRETE:8)
Block(-8,21,6,CONCRETE:8)
Block(-8,21,7,CONCRETE:7)
Block(-8,22,-7,STAINED_GLASS_PANE:15)
Block(-8,22,-6,CONCRETE:7)
Block(-8,22,-3,DARK_OAK_DOOR:3)
Block(-8,22,2,TRAP_DOOR:4)
Block(-8,22,3,DARK_OAK_STAIRS:3)
Block(-8,22,4,CARPET:14)
Block(-8,22,5,CARPET:14)
Block(-8,22,6,IRON_TRAPDOOR:8)
Block(-8,22,7,CONCRETE:7)
Block(-8,23,-7,STAINED_GLASS_PANE:15)
Block(-8,23,-6,CONCRETE:7)
Block(-8,23,-3,DARK_OAK_DOOR:9)
Block(-8,23,2,TRAP_DOOR:4)
Block(-8,23,3,WALL_BANNER:3,NBT/skyscraper_2x2_05/1252-bannerC16R16.nbt)
Block(-8,23,6,WALL_BANNER:2,NBT/skyscraper_2x2_05/1253-bannerC16R16.nbt)
Block(-8,23,7,STAINED_GLASS_PANE:15)
Block(-8,24,-7,STAINED_GLASS_PANE:15)
Block(-8,24,-6,CONCRETE:7)
Block(-8,24,-3,CONCRETE:7)
Block(-8,24,6,WALL_BANNER:2,NBT/skyscraper_2x2_05/1255-bannerC16R16.nbt)
Block(-8,24,7,STAINED_GLASS_PANE:15)
Block(-8,25,-7,CONCRETE:7)
Block(-8,25,-6,CONCRETE:7)
Block(-8,25,-5,STEP:8)
Block(-8,25,-4,STEP:8)
Block(-8,25,-3,CONCRETE:7)
Block(-8,25,-2,CONCRETE:8)
Block(-8,25,-1,CONCRETE:8)
Block(-8,25,0,CONCRETE:8)
Block(-8,25,1,CONCRETE:8)
Block(-8,25,2,CONCRETE:8)
Block(-8,25,3,CONCRETE:8)
Block(-8,25,4,CONCRETE:8)
Block(-8,25,5,CONCRETE:8)
Block(-8,25,6,CONCRETE:8)
Block(-8,25,7,CONCRETE:7)
Block(-8,26,-7,STAINED_GLASS_PANE:15)
Block(-8,26,-6,CONCRETE:7)
Block(-8,26,-3,DARK_OAK_DOOR:3)
Block(-8,26,2,TRAP_DOOR:4)
Block(-8,26,3,DARK_OAK_STAIRS:3)
Block(-8,26,4,CARPET:14)
Block(-8,26,5,CARPET:14)
Block(-8,26,6,IRON_TRAPDOOR:8)
Block(-8,26,7,CONCRETE:7)
Block(-8,27,-7,STAINED_GLASS_PANE:15)
Block(-8,27,-6,CONCRETE:7)
Block(-8,27,-3,DARK_OAK_DOOR:9)
Block(-8,27,2,TRAP_DOOR:4)
Block(-8,27,3,WALL_BANNER:3,NBT/skyscraper_2x2_05/1256-bannerC16R16.nbt)
Block(-8,27,6,WALL_BANNER:2,NBT/skyscraper_2x2_05/1257-bannerC16R16.nbt)
Block(-8,27,7,STAINED_GLASS_PANE:15)
Block(-8,28,-7,STAINED_GLASS_PANE:15)
Block(-8,28,-6,CONCRETE:7)
Block(-8,28,-3,CONCRETE:7)
Block(-8,28,6,WALL_BANNER:2,NBT/skyscraper_2x2_05/1259-bannerC16R16.nbt)
Block(-8,28,7,STAINED_GLASS_PANE:15)
Block(-8,29,-7,CONCRETE:7)
Block(-8,29,-6,CONCRETE:7)
Block(-8,29,-5,STEP:8)
Block(-8,29,-4,STEP:8)
Block(-8,29,-3,CONCRETE:7)
Block(-8,29,-2,CONCRETE:8)
Block(-8,29,-1,CONCRETE:8)
Block(-8,29,0,CONCRETE:8)
Block(-8,29,1,CONCRETE:8)
Block(-8,29,2,CONCRETE:8)
Block(-8,29,3,CONCRETE:8)
Block(-8,29,4,CONCRETE:8)
Block(-8,29,5,CONCRETE:8)
Block(-8,29,6,CONCRETE:8)
Block(-8,29,7,CONCRETE:7)
Block(-8,30,-7,STAINED_GLASS_PANE:15)
Block(-8,30,-6,CONCRETE:7)
Block(-8,30,-3,DARK_OAK_DOOR:3)
Block(-8,30,2,TRAP_DOOR:4)
Block(-8,30,3,DARK_OAK_STAIRS:3)
Block(-8,30,4,CARPET:14)
Block(-8,30,5,CARPET:14)
Block(-8,30,6,IRON_TRAPDOOR:8)
Block(-8,30,7,CONCRETE:7)
Block(-8,31,-7,STAINED_GLASS_PANE:15)
Block(-8,31,-6,CONCRETE:7)
Block(-8,31,-3,DARK_OAK_DOOR:9)
Block(-8,31,2,TRAP_DOOR:4)
Block(-8,31,3,WALL_BANNER:3,NBT/skyscraper_2x2_05/1260-bannerC16R16.nbt)
Block(-8,31,6,WALL_BANNER:2,NBT/skyscraper_2x2_05/1261-bannerC16R16.nbt)
Block(-8,31,7,STAINED_GLASS_PANE:15)
Block(-8,32,-7,STAINED_GLASS_PANE:15)
Block(-8,32,-6,CONCRETE:7)
Block(-8,32,-3,CONCRETE:7)
Block(-8,32,6,WALL_BANNER:2,NBT/skyscraper_2x2_05/1263-bannerC16R16.nbt)
Block(-8,32,7,STAINED_GLASS_PANE:15)
Block(-8,33,-7,CONCRETE:7)
Block(-8,33,-6,CONCRETE:7)
Block(-8,33,-5,STEP:8)
Block(-8,33,-4,STEP:8)
Block(-8,33,-3,CONCRETE:7)
Block(-8,33,-2,CONCRETE:8)
Block(-8,33,-1,CONCRETE:8)
Block(-8,33,0,CONCRETE:8)
Block(-8,33,1,CONCRETE:8)
Block(-8,33,2,CONCRETE:8)
Block(-8,33,3,CONCRETE:8)
Block(-8,33,4,CONCRETE:8)
Block(-8,33,5,CONCRETE:8)
Block(-8,33,6,CONCRETE:8)
Block(-8,33,7,CONCRETE:7)
Block(-8,34,-7,STAINED_GLASS_PANE:15)
Block(-8,34,-6,CONCRETE:7)
Block(-8,34,-3,DARK_OAK_DOOR:3)
Block(-8,34,2,TRAP_DOOR:4)
Block(-8,34,3,DARK_OAK_STAIRS:3)
Block(-8,34,4,CARPET:14)
Block(-8,34,5,CARPET:14)
Block(-8,34,6,IRON_TRAPDOOR:8)
Block(-8,34,7,CONCRETE:7)
Block(-8,35,-7,STAINED_GLASS_PANE:15)
Block(-8,35,-6,CONCRETE:7)
Block(-8,35,-3,DARK_OAK_DOOR:9)
Block(-8,35,2,TRAP_DOOR:4)
Block(-8,35,3,WALL_BANNER:3,NBT/skyscraper_2x2_05/1264-bannerC16R16.nbt)
Block(-8,35,6,WALL_BANNER:2,NBT/skyscraper_2x2_05/1265-bannerC16R16.nbt)
Block(-8,35,7,STAINED_GLASS_PANE:15)
Block(-8,36,-7,STAINED_GLASS_PANE:15)
Block(-8,36,-6,CONCRETE:7)
Block(-8,36,-3,CONCRETE:7)
Block(-8,36,6,WALL_BANNER:2,NBT/skyscraper_2x2_05/1267-bannerC16R16.nbt)
Block(-8,36,7,STAINED_GLASS_PANE:15)
Block(-8,37,-7,CONCRETE:7)
Block(-8,37,-6,CONCRETE:7)
Block(-8,37,-5,STEP:8)
Block(-8,37,-4,STEP:8)
Block(-8,37,-3,CONCRETE:7)
Block(-8,37,-2,CONCRETE:8)
Block(-8,37,-1,CONCRETE:8)
Block(-8,37,0,CONCRETE:8)
Block(-8,37,1,CONCRETE:8)
Block(-8,37,2,CONCRETE:8)
Block(-8,37,3,CONCRETE:8)
Block(-8,37,4,CONCRETE:8)
Block(-8,37,5,CONCRETE:8)
Block(-8,37,6,CONCRETE:8)
Block(-8,37,7,CONCRETE:7)
Block(-8,38,-7,STAINED_GLASS_PANE:15)
Block(-8,38,-6,CONCRETE:7)
Block(-8,38,-3,DARK_OAK_DOOR:3)
Block(-8,38,2,TRAP_DOOR:4)
Block(-8,38,3,DARK_OAK_STAIRS:3)
Block(-8,38,4,CARPET:14)
Block(-8,38,5,CARPET:14)
Block(-8,38,6,IRON_TRAPDOOR:8)
Block(-8,38,7,CONCRETE:8)
Block(-8,39,-7,STAINED_GLASS_PANE:15)
Block(-8,39,-6,CONCRETE:7)
Block(-8,39,-3,DARK_OAK_DOOR:9)
Block(-8,39,2,TRAP_DOOR:4)
Block(-8,39,3,WALL_BANNER:3,NBT/skyscraper_2x2_05/1268-bannerC16R16.nbt)
Block(-8,39,6,WALL_BANNER:2,NBT/skyscraper_2x2_05/1269-bannerC16R16.nbt)
Block(-8,39,7,STAINED_GLASS_PANE:15)
Block(-8,40,-7,STAINED_GLASS_PANE:15)
Block(-8,40,-6,CONCRETE:7)
Block(-8,40,-3,CONCRETE:7)
Block(-8,40,6,WALL_BANNER:2,NBT/skyscraper_2x2_05/1271-bannerC16R16.nbt)
Block(-8,40,7,STAINED_GLASS_PANE:15)
Block(-8,41,-7,CONCRETE:7)
Block(-8,41,-6,CONCRETE:7)
Block(-8,41,-5,STEP:8)
Block(-8,41,-4,STEP:8)
Block(-8,41,-3,CONCRETE:7)
Block(-8,41,-2,CONCRETE:8)
Block(-8,41,-1,CONCRETE:8)
Block(-8,41,0,CONCRETE:8)
Block(-8,41,1,CONCRETE:8)
Block(-8,41,2,CONCRETE:8)
Block(-8,41,3,CONCRETE:8)
Block(-8,41,4,CONCRETE:8)
Block(-8,41,5,CONCRETE:8)
Block(-8,41,6,CONCRETE:8)
Block(-8,41,7,CONCRETE:8)
Block(-8,42,-7,STAINED_GLASS_PANE:15)
Block(-8,42,-6,CONCRETE:7)
Block(-8,42,-3,DARK_OAK_DOOR:3)
Block(-8,42,2,TRAP_DOOR:4)
Block(-8,42,3,DARK_OAK_STAIRS:3)
Block(-8,42,4,CARPET:14)
Block(-8,42,5,CARPET:14)
Block(-8,42,6,IRON_TRAPDOOR:8)
Block(-8,42,7,CONCRETE:8)
Block(-8,43,-7,STAINED_GLASS_PANE:15)
Block(-8,43,-6,CONCRETE:7)
Block(-8,43,-3,DARK_OAK_DOOR:9)
Block(-8,43,2,TRAP_DOOR:4)
Block(-8,43,3,WALL_BANNER:3,NBT/skyscraper_2x2_05/1272-bannerC16R16.nbt)
Block(-8,43,6,WALL_BANNER:2,NBT/skyscraper_2x2_05/1273-bannerC16R16.nbt)
Block(-8,43,7,STAINED_GLASS_PANE:15)
Block(-8,44,-7,STAINED_GLASS_PANE:15)
Block(-8,44,-6,CONCRETE:7)
Block(-8,44,-3,CONCRETE:7)
Block(-8,44,6,WALL_BANNER:2,NBT/skyscraper_2x2_05/1275-bannerC16R16.nbt)
Block(-8,44,7,STAINED_GLASS_PANE:15)
Block(-8,45,-7,CONCRETE:7)
Block(-8,45,-6,CONCRETE:7)
Block(-8,45,-5,STEP:8)
Block(-8,45,-4,STEP:8)
Block(-8,45,-3,CONCRETE:7)
Block(-8,45,-2,CONCRETE:8)
Block(-8,45,-1,CONCRETE:8)
Block(-8,45,0,CONCRETE:8)
Block(-8,45,1,CONCRETE:8)
Block(-8,45,2,CONCRETE:8)
Block(-8,45,3,CONCRETE:8)
Block(-8,45,4,CONCRETE:8)
Block(-8,45,5,CONCRETE:8)
Block(-8,45,6,CONCRETE:8)
Block(-8,45,7,CONCRETE:8)
Block(-8,46,-7,STAINED_GLASS_PANE:15)
Block(-8,46,-6,CONCRETE:7)
Block(-8,46,-3,DARK_OAK_DOOR:3)
Block(-8,46,2,TRAP_DOOR:4)
Block(-8,46,3,DARK_OAK_STAIRS:3)
Block(-8,46,4,CARPET:14)
Block(-8,46,5,CARPET:14)
Block(-8,46,6,IRON_TRAPDOOR:8)
Block(-8,46,7,CONCRETE:8)
Block(-8,47,-7,STAINED_GLASS_PANE:15)
Block(-8,47,-6,CONCRETE:7)
Block(-8,47,-3,DARK_OAK_DOOR:9)
Block(-8,47,2,TRAP_DOOR:4)
Block(-8,47,3,WALL_BANNER:3,NBT/skyscraper_2x2_05/1276-bannerC16R16.nbt)
Block(-8,47,6,WALL_BANNER:2,NBT/skyscraper_2x2_05/1277-bannerC16R16.nbt)
Block(-8,47,7,STAINED_GLASS_PANE:15)
Block(-8,48,-7,STAINED_GLASS_PANE:15)
Block(-8,48,-6,CONCRETE:7)
Block(-8,48,-3,CONCRETE:7)
Block(-8,48,6,WALL_BANNER:2,NBT/skyscraper_2x2_05/1279-bannerC16R16.nbt)
Block(-8,48,7,STAINED_GLASS_PANE:15)
Block(-8,49,-7,CONCRETE:7)
Block(-8,49,-6,CONCRETE:7)
Block(-8,49,-5,STEP:8)
Block(-8,49,-4,STEP:8)
Block(-8,49,-3,CONCRETE:7)
Block(-8,49,-2,CONCRETE:7)
Block(-8,49,-1,CONCRETE:7)
Block(-8,49,0,CONCRETE:7)
Block(-8,49,1,CONCRETE:7)
Block(-8,49,2,CONCRETE:7)
Block(-8,49,3,CONCRETE:7)
Block(-8,49,4,CONCRETE:7)
Block(-8,49,5,CONCRETE:7)
Block(-8,49,6,CONCRETE:7)
Block(-8,49,7,CONCRETE:7)
Block(-8,50,-7,STAINED_GLASS_PANE:15)
Block(-8,50,-6,CONCRETE:7)
Block(-8,50,-3,CONCRETE:7)
Block(-8,50,1,IRON_TRAPDOOR:8)
Block(-8,50,2,CONCRETE:7)
Block(-8,50,3,IRON_TRAPDOOR:9)
Block(-8,50,6,IRON_FENCE:0)
Block(-8,50,7,SMOOTH_STAIRS:7)
Block(-8,51,-7,STAINED_GLASS_PANE:15)
Block(-8,51,-6,CONCRETE:7)
Block(-8,51,-3,CONCRETE:7)
#RandomBlock(-8,51,1,TRAPPED_CHEST:5,../../../../../Chests/Loot/ModernCityJunk_1.nbt,65,CHEST:2,../../../../../Chests/Loot/ModernCityJunk_1.nbt,20,CHEST:2,../../../../../Chests/Loot/ModernCityJunk_2.nbt,15,CHEST:2,../../../../../Chests/Loot/ModernCityJunk_3.nbt,15,CHEST:2,../../../../../Chests/Loot/ModernCityJunk_4.nbt,15,CHEST:2,../../../../../Chests/Loot/ModernCityJunk_5.nbt,15,CHEST:2,../../../../../Chests/Loot/ModernCityCommon_1.nbt,5,CHEST:2,../../../../../Chests/Loot/ModernCityCommon_2.nbt,5,CHEST:2,../../../../../Chests/Loot/ModernCityCommon_3.nbt,5,CHEST:2,../../../../../Chests/Loot/ModernCityCommon_4.nbt,5,CHEST:2,../../../../../Chests/Loot/ModernCityCommon_5.nbt,5,CHEST:2,../../../../../Chests/Loot/ModernCityGood_1.nbt,3,CHEST:2,../../../../../Chests/Loot/ModernCityGood_2.nbt,3,CHEST:2,../../../../../Chests/Loot/ModernCityGood_3.nbt,3,CHEST:2,../../../../../Chests/Loot/ModernCityGood_4.nbt,3,CHEST:2,../../../../../Chests/Loot/ModernCityGood_5.nbt,3,CHEST:2,../../../../../Chests/Loot/ModernCityEpic_1.nbt,1,CHEST:2,../../../../../Chests/Loot/ModernCityEpic_2.nbt,1,CHEST:2,../../../../../Chests/Loot/ModernCityEpic_3.nbt,1,CHEST:2,../../../../../Chests/Loot/ModernCityEpic_4.nbt,1,CHEST:2,../../../../../Chests/Loot/ModernCityEpic_5.nbt,1,CHEST:2,../../../../../Chests/Loot/Common1.nbt,25,CHEST:2,../../../../../Chests/Loot/Common2.nbt,25,CHEST:2,../../../../../Chests/Loot/Common3.nbt,25,CHEST:2,../../../../../Chests/Loot/Common4.nbt,25,CHEST:2,../../../../../Chests/Loot/Common5.nbt,25,CHEST:2,../../../../../Chests/Loot/Common6.nbt,25,CHEST:2,../../../../../Chests/Loot/Common7.nbt,25,CHEST:2,../../../../../Chests/Loot/Common8.nbt,25,CHEST:2,../../../../../Chests/Loot/Common9.nbt,25,CHEST:2,../../../../../Chests/Loot/Common10.nbt,25,CHEST:2,../../../../../Chests/Loot/Common11.nbt,25,CHEST:2,../../../../../Chests/Loot/Common12.nbt,25,CHEST:2,../../../../../Chests/Loot/Common13.nbt,25,CHEST:2,../../../../../Chests/Loot/Common14.nbt,25,CHEST:2,../../../../../Chests/Loot/Common15.nbt,25,CHEST:2,../../../../../Chests/Loot/Rare1.nbt,10,CHEST:2,../../../../../Chests/Loot/Rare2.nbt,10,CHEST:5,../../../../../Chests/Loot/Rare3.nbt,10,CHEST:2,../../../../../Chests/Loot/Rare4.nbt,10,CHEST:2,../../../../../Chests/Loot/Rare5.nbt,10,CHEST:2,../../../../../Chests/Loot/Rare6.nbt,10,CHEST:2,../../../../../Chests/Loot/Rare7.nbt,10,CHEST:2,../../../../../Chests/Loot/Rare8.nbt,10,CHEST:2,../../../../../Chests/Loot/Rare9.nbt,10,CHEST:2,../../../../../Chests/Loot/Rare10.nbt,10,CHEST:2,../../../../../Chests/Loot/Rare11.nbt,10,CHEST:2,../../../../../Chests/Loot/Rare12.nbt,10,CHEST:2,../../../../../Chests/Loot/Rare13.nbt,10,CHEST:2,../../../../../Chests/Loot/Rare14.nbt,10,CHEST:2,../../../../../Chests/Loot/Rare15.nbt,10,CHEST:2,../../../../../Chests/Loot/Epic1.nbt,1,CHEST:2,../../../../../Chests/Loot/Epic2.nbt,1,CHEST:2,../../../../../Chests/Loot/Epic3.nbt,1,CHEST:2,../../../../../Chests/Loot/Epic4.nbt,1,CHEST:2,../../../../../Chests/Loot/Epic5.nbt,1,CHEST:2,../../../../../Chests/Loot/Epic6.nbt,1,CHEST:2,../../../../../Chests/Loot/Epic7.nbt,1,CHEST:2,../../../../../Chests/Loot/Epic8.nbt,1,CHEST:2,../../../../../Chests/Loot/Epic9.nbt,1,CHEST:2,../../../../../Chests/Loot/Epic10.nbt,1,CHEST:2,../../../../../Chests/Loot/Epic11.nbt,1,CHEST:2,../../../../../Chests/Loot/Epic12.nbt,1,CHEST:2,../../../../../Chests/Loot/Epic13.nbt,1,CHEST:2,../../../../../Chests/Loot/Epic14.nbt,1,CHEST:2,../../../../../Chests/Loot/Epic15.nbt,1,CHEST:2,../../../../../Chests/Loot/ModernCityJunk_1.nbt,100)
Block(-8,51,2,CONCRETE:7)
Block(-8,51,6,IRON_FENCE:0)
Block(-8,51,7,SMOOTH_STAIRS:7)
Block(-8,52,-7,STAINED_GLASS_PANE:15)
Block(-8,52,-6,CONCRETE:7)
Block(-8,52,-3,CONCRETE:7)
Block(-8,52,-2,STEP:8)
Block(-8,52,-1,STEP:8)
Block(-8,52,0,STEP:8)
Block(-8,52,1,STEP:8)
Block(-8,52,2,CONCRETE:7)
Block(-8,52,3,STEP:8)
Block(-8,52,4,STEP:8)
Block(-8,52,5,CONCRETE:12)
Block(-8,52,6,IRON_FENCE:0)
Block(-8,52,7,SMOOTH_STAIRS:7)
Block(-8,53,-7,CONCRETE:7)
Block(-8,53,-6,CONCRETE:7)
Block(-8,53,-5,STEP:8)
Block(-8,53,-4,STEP:8)
Block(-8,53,-3,CONCRETE:7)
Block(-8,53,-2,CONCRETE:7)
Block(-8,53,-1,CONCRETE:7)
Block(-8,53,0,CONCRETE:7)
Block(-8,53,1,CONCRETE:7)
Block(-8,53,2,DOUBLE_STEP:0)
Block(-8,53,3,GRASS:0)
Block(-8,53,4,GRASS:0)
Block(-8,53,5,DOUBLE_STEP:0)
Block(-8,53,6,CONCRETE:7)
Block(-8,53,7,CONCRETE:7)
Block(-8,54,-7,STAINED_GLASS_PANE:15)
Block(-8,54,-6,CONCRETE:7)
Block(-8,54,-3,DARK_OAK_DOOR:3)
Block(-8,54,7,IRON_FENCE:0)
Block(-8,55,-7,STAINED_GLASS_PANE:15)
Block(-8,55,-6,CONCRETE:7)
Block(-8,55,-3,DARK_OAK_DOOR:9)
Block(-8,56,-7,STAINED_GLASS_PANE:15)
Block(-8,56,-6,CONCRETE:7)
Block(-8,56,-3,CONCRETE:8)
Block(-8,57,-7,CONCRETE:7)
Block(-8,57,-6,CONCRETE:7)
Block(-8,57,-5,STEP:8)
Block(-8,57,-4,STEP:8)
Block(-8,57,-3,CONCRETE:8)
Block(-8,57,-2,SMOOTH_STAIRS:7)
Block(-8,58,-7,STAINED_GLASS_PANE:15)
Block(-8,58,-6,CONCRETE:7)
Block(-8,58,-3,CONCRETE:8)
Block(-8,58,-2,IRON_FENCE:0)
Block(-8,59,-7,STAINED_GLASS_PANE:15)
Block(-8,59,-6,CONCRETE:7)
Block(-8,59,-3,STAINED_GLASS_PANE:15)
Block(-8,60,-7,STAINED_GLASS_PANE:15)
Block(-8,60,-6,CONCRETE:7)
Block(-8,60,-3,STAINED_GLASS_PANE:15)
Block(-8,61,-7,CONCRETE:7)
Block(-8,61,-6,CONCRETE:7)
Block(-8,61,-5,STEP:8)
Block(-8,61,-4,STEP:8)
Block(-8,61,-3,CONCRETE:8)
Block(-8,61,-2,SMOOTH_STAIRS:7)
Block(-8,62,-7,STAINED_GLASS_PANE:15)
Block(-8,62,-6,CONCRETE:7)
Block(-8,62,-3,CONCRETE:8)
Block(-8,62,-2,IRON_FENCE:0)
Block(-8,63,-7,STAINED_GLASS_PANE:15)
Block(-8,63,-6,CONCRETE:7)
Block(-8,63,-3,STAINED_GLASS_PANE:15)
Block(-8,64,-7,STAINED_GLASS_PANE:15)
Block(-8,64,-6,CONCRETE:7)
Block(-8,64,-3,STAINED_GLASS_PANE:15)
Block(-8,65,-7,CONCRETE:7)
Block(-8,65,-6,CONCRETE:7)
Block(-8,65,-5,STEP:8)
Block(-8,65,-4,STEP:8)
Block(-8,65,-3,CONCRETE:8)
Block(-8,65,-2,SMOOTH_STAIRS:7)
Block(-8,66,-7,STAINED_GLASS_PANE:15)
Block(-8,66,-6,CONCRETE:7)
Block(-8,66,-3,CONCRETE:8)
Block(-8,66,-2,IRON_FENCE:0)
Block(-8,67,-7,STAINED_GLASS_PANE:15)
Block(-8,67,-6,CONCRETE:7)
Block(-8,67,-3,STAINED_GLASS_PANE:15)
Block(-8,68,-7,STAINED_GLASS_PANE:15)
Block(-8,68,-6,CONCRETE:7)
Block(-8,68,-3,STAINED_GLASS_PANE:15)
Block(-8,69,-7,CONCRETE:7)
Block(-8,69,-6,CONCRETE:7)
Block(-8,69,-5,STEP:8)
Block(-8,69,-4,STEP:8)
Block(-8,69,-3,CONCRETE:8)
Block(-8,69,-2,SMOOTH_STAIRS:7)
Block(-8,70,-7,STAINED_GLASS_PANE:15)
Block(-8,70,-6,CONCRETE:7)
Block(-8,70,-3,CONCRETE:8)
Block(-8,70,-2,IRON_FENCE:0)
Block(-8,71,-7,STAINED_GLASS_PANE:15)
Block(-8,71,-6,CONCRETE:7)
Block(-8,71,-3,STAINED_GLASS_PANE:15)
Block(-8,72,-7,STAINED_GLASS_PANE:15)
Block(-8,72,-6,CONCRETE:7)
Block(-8,72,-3,STAINED_GLASS_PANE:15)
Block(-8,73,-7,CONCRETE:7)
Block(-8,73,-6,CONCRETE:7)
Block(-8,73,-5,STEP:8)
Block(-8,73,-4,STEP:8)
Block(-8,73,-3,CONCRETE:8)
Block(-8,73,-2,SMOOTH_STAIRS:7)
Block(-8,74,-7,STAINED_GLASS_PANE:15)
Block(-8,74,-6,CONCRETE:7)
Block(-8,74,-3,CONCRETE:8)
Block(-8,74,-2,IRON_FENCE:0)
Block(-8,75,-7,STAINED_GLASS_PANE:15)
Block(-8,75,-6,CONCRETE:7)
Block(-8,75,-3,STAINED_GLASS_PANE:15)
Block(-8,76,-7,STAINED_GLASS_PANE:15)
Block(-8,76,-6,CONCRETE:7)
Block(-8,76,-3,STAINED_GLASS_PANE:15)
Block(-8,77,-7,CONCRETE:7)
Block(-8,77,-6,CONCRETE:7)
Block(-8,77,-5,STEP:8)
Block(-8,77,-4,STEP:8)
Block(-8,77,-3,CONCRETE:8)
Block(-8,77,-2,SMOOTH_STAIRS:7)
Block(-8,78,-7,STAINED_GLASS_PANE:15)
Block(-8,78,-6,CONCRETE:7)
Block(-8,78,-3,CONCRETE:8)
Block(-8,78,-2,IRON_FENCE:0)
Block(-8,79,-7,STAINED_GLASS_PANE:15)
Block(-8,79,-6,CONCRETE:7)
Block(-8,79,-3,STAINED_GLASS_PANE:15)
Block(-8,80,-7,STAINED_GLASS_PANE:15)
Block(-8,80,-6,CONCRETE:7)
Block(-8,80,-3,STAINED_GLASS_PANE:15)
Block(-8,81,-7,CONCRETE:7)
Block(-8,81,-6,CONCRETE:7)
Block(-8,81,-5,CONCRETE:7)
Block(-8,81,-4,STEP:8)
Block(-8,81,-3,CONCRETE:7)
Block(-8,81,-2,SMOOTH_STAIRS:7)
Block(-8,82,-7,STAINED_GLASS_PANE:15)
Block(-8,82,-6,STAINED_GLASS_PANE:15)
Block(-8,82,-5,CONCRETE:8)
Block(-8,82,-2,IRON_FENCE:0)
Block(-8,83,-7,SMOOTH_STAIRS:4)
Block(-8,83,-6,SMOOTH_STAIRS:4)
Block(-8,83,-5,CONCRETE:8)
Block(-8,84,-7,SMOOTH_STAIRS:1)
Block(-8,84,-6,SMOOTH_STAIRS:1)
Block(-8,84,-5,CONCRETE:8)
Block(-8,85,-5,CONCRETE:8)
Block(-8,86,-5,CONCRETE:8)
Block(-8,87,-5,STAINED_GLASS_PANE:15)
Block(-8,88,-5,STAINED_GLASS_PANE:15)
Block(-8,89,-7,CONCRETE:7)
Block(-8,89,-6,CONCRETE:7)
Block(-8,89,-5,CONCRETE:8)
Block(-8,90,-5,STAINED_GLASS_PANE:15)
Block(-8,91,-5,STAINED_GLASS_PANE:15)
Block(-8,92,-5,STAINED_GLASS_PANE:15)
Block(-8,93,-7,STAINED_GLASS:15)
Block(-8,93,-6,STAINED_GLASS:15)
Block(-8,93,-5,STAINED_GLASS:15)
Block(-8,94,-5,IRON_TRAPDOOR:3)
Block(-7,0,-7,CONCRETE:7)
Block(-7,0,-6,CONCRETE:7)
Block(-7,0,-5,CONCRETE:7)
Block(-7,0,-4,CONCRETE:7)
Block(-7,0,-3,CONCRETE:7)
Block(-7,0,-2,CONCRETE:7)
Block(-7,0,-1,CONCRETE:7)
Block(-7,0,0,CONCRETE:7)
Block(-7,0,1,CONCRETE:7)
Block(-7,0,2,CONCRETE:7)
Block(-7,0,3,CONCRETE:7)
Block(-7,0,4,CONCRETE:7)
Block(-7,0,5,CONCRETE:7)
Block(-7,0,6,CONCRETE:7)
Block(-7,0,7,CONCRETE:7)
Block(-7,0,8,CONCRETE:7)
Block(-7,1,-7,CONCRETE:7)
Block(-7,1,-6,CONCRETE:7)
Block(-7,1,-5,CONCRETE:7)
Block(-7,1,-4,CONCRETE:7)
Block(-7,1,-3,CONCRETE:7)
Block(-7,1,-2,STATIONARY_WATER:0)
Block(-7,1,-1,STATIONARY_WATER:0)
Block(-7,1,0,STATIONARY_WATER:0)
Block(-7,1,1,STATIONARY_WATER:0)
Block(-7,1,2,CONCRETE:7)
Block(-7,1,3,CONCRETE:7)
Block(-7,1,4,CONCRETE:7)
Block(-7,1,5,SMOOTH_STAIRS:3)
Block(-7,1,6,AIR:0)
Block(-7,1,7,AIR:0)
Block(-7,1,8,CONCRETE:7)
Block(-7,2,-7,CONCRETE:7)
Block(-7,2,-6,CONCRETE:7)
Block(-7,2,-5,CONCRETE:7)
Block(-7,2,-4,CONCRETE:7)
Block(-7,2,-3,SMOOTH_STAIRS:3)
Block(-7,2,-2,AIR:0)
Block(-7,2,-1,AIR:0)
Block(-7,2,0,AIR:0)
Block(-7,2,1,AIR:0)
Block(-7,2,2,SMOOTH_STAIRS:2)
Block(-7,2,3,CONCRETE:7)
Block(-7,2,4,SMOOTH_STAIRS:3)
Block(-7,2,5,AIR:0)
Block(-7,2,6,AIR:0)
Block(-7,2,7,IRON_TRAPDOOR:8)
Block(-7,2,8,CONCRETE:7)
Block(-7,3,-7,AIR:0)
Block(-7,3,-6,AIR:0)
Block(-7,3,-5,CONCRETE:7)
Block(-7,3,-4,CONCRETE:7)
Block(-7,3,-3,AIR:0)
Block(-7,3,-2,AIR:0)
Block(-7,3,-1,AIR:0)
Block(-7,3,0,AIR:0)
Block(-7,3,1,AIR:0)
Block(-7,3,2,AIR:0)
Block(-7,3,3,AIR:0)
Block(-7,3,4,AIR:0)
Block(-7,3,5,AIR:0)
Block(-7,3,6,AIR:0)
Block(-7,3,7,AIR:0)
Block(-7,3,8,CONCRETE:7)
Block(-7,4,-7,AIR:0)
Block(-7,4,-6,AIR:0)
Block(-7,4,-5,CONCRETE:7)
Block(-7,4,-4,CONCRETE:7)
Block(-7,4,-3,AIR:0)
Block(-7,4,-2,AIR:0)
Block(-7,4,-1,AIR:0)
Block(-7,4,0,AIR:0)
Block(-7,4,1,AIR:0)
Block(-7,4,2,AIR:0)
Block(-7,4,3,AIR:0)
Block(-7,4,4,AIR:0)
Block(-7,4,5,AIR:0)
Block(-7,4,6,AIR:0)
Block(-7,4,7,AIR:0)
Block(-7,4,8,CONCRETE:7)
Block(-7,5,-7,CONCRETE:14)
Block(-7,5,-6,CONCRETE:11)
Block(-7,5,-5,CONCRETE:7)
Block(-7,5,-4,CONCRETE:7)
Block(-7,5,-3,AIR:0)
Block(-7,5,-2,AIR:0)
Block(-7,5,-1,AIR:0)
Block(-7,5,0,AIR:0)
Block(-7,5,1,AIR:0)
Block(-7,5,2,AIR:0)
Block(-7,5,3,AIR:0)
Block(-7,5,4,AIR:0)
Block(-7,5,5,AIR:0)
Block(-7,5,6,AIR:0)
Block(-7,5,7,AIR:0)
Block(-7,5,8,CONCRETE:7)
Block(-7,6,-7,AIR:0)
Block(-7,6,-6,AIR:0)
Block(-7,6,-5,CONCRETE:7)
Block(-7,6,-4,CONCRETE:7)
Block(-7,6,-3,AIR:0)
Block(-7,6,-2,AIR:0)
Block(-7,6,-1,AIR:0)
Block(-7,6,0,AIR:0)
Block(-7,6,1,AIR:0)
Block(-7,6,2,AIR:0)
Block(-7,6,3,AIR:0)
Block(-7,6,4,AIR:0)
Block(-7,6,5,AIR:0)
Block(-7,6,6,AIR:0)
Block(-7,6,7,AIR:0)
Block(-7,6,8,CONCRETE:7)
Block(-7,7,-7,CONCRETE:7)
Block(-7,7,-6,CONCRETE:7)
Block(-7,7,-5,CONCRETE:7)
Block(-7,7,-4,CONCRETE:7)
Block(-7,7,-3,CONCRETE:7)
Block(-7,7,-2,CONCRETE:7)
Block(-7,7,-1,CONCRETE:7)
Block(-7,7,0,CONCRETE:7)
Block(-7,7,1,CONCRETE:7)
Block(-7,7,2,CONCRETE:7)
Block(-7,7,3,CONCRETE:7)
Block(-7,7,4,CONCRETE:7)
Block(-7,7,5,CONCRETE:7)
Block(-7,7,6,CONCRETE:7)
Block(-7,7,7,CONCRETE:7)
Block(-7,7,8,CONCRETE:7)
Block(-7,8,-7,CONCRETE:7)
Block(-7,8,-6,CONCRETE:7)
Block(-7,8,-5,CONCRETE:7)
Block(-7,8,-4,CONCRETE:7)
Block(-7,8,-3,CONCRETE:7)
Block(-7,8,-2,CONCRETE:7)
Block(-7,8,-1,CONCRETE:7)
Block(-7,8,0,CONCRETE:7)
Block(-7,8,1,CONCRETE:7)
Block(-7,8,2,CONCRETE:7)
Block(-7,8,3,CONCRETE:7)
Block(-7,8,4,CONCRETE:7)
Block(-7,8,5,CONCRETE:7)
Block(-7,8,6,CONCRETE:7)
Block(-7,8,7,CONCRETE:7)
Block(-7,8,8,CONCRETE:7)
Block(-7,9,-7,CONCRETE:7)
Block(-7,9,-6,CONCRETE:7)
Block(-7,9,-5,CONCRETE:7)
Block(-7,9,-4,CONCRETE:7)
Block(-7,9,-3,CONCRETE:7)
Block(-7,9,-2,CONCRETE:7)
Block(-7,9,-1,CONCRETE:7)
Block(-7,9,0,CONCRETE:7)
Block(-7,9,1,CONCRETE:7)
Block(-7,9,2,CONCRETE:7)
Block(-7,9,3,CONCRETE:7)
Block(-7,9,4,CONCRETE:7)
Block(-7,9,5,CONCRETE:7)
Block(-7,9,6,CONCRETE:7)
Block(-7,9,7,CONCRETE:7)
Block(-7,9,8,CONCRETE:7)
Block(-7,10,-7,CONCRETE:7)
Block(-7,10,-6,CONCRETE:7)
Block(-7,10,-5,CONCRETE:7)
Block(-7,10,-4,CONCRETE:7)
Block(-7,10,-3,CONCRETE:7)
Block(-7,10,-2,CONCRETE:7)
Block(-7,10,-1,CONCRETE:7)
Block(-7,10,0,CONCRETE:7)
Block(-7,10,1,CONCRETE:7)
Block(-7,10,2,CONCRETE:7)
Block(-7,10,3,CONCRETE:7)
Block(-7,10,4,CONCRETE:7)
Block(-7,10,5,CONCRETE:7)
Block(-7,10,6,CONCRETE:7)
Block(-7,10,7,CONCRETE:7)
Block(-7,10,8,CONCRETE:7)
Block(-7,11,-7,CONCRETE:7)
Block(-7,11,-6,CONCRETE:7)
Block(-7,11,-5,CONCRETE:7)
Block(-7,11,-4,CONCRETE:7)
Block(-7,11,-3,CONCRETE:7)
Block(-7,11,-2,CONCRETE:7)
Block(-7,11,-1,CONCRETE:7)
Block(-7,11,0,CONCRETE:7)
Block(-7,11,1,CONCRETE:7)
Block(-7,11,2,CONCRETE:7)
Block(-7,11,3,CONCRETE:7)
Block(-7,11,4,CONCRETE:7)
Block(-7,11,5,CONCRETE:7)
Block(-7,11,6,CONCRETE:7)
Block(-7,11,7,CONCRETE:7)
Block(-7,11,8,CONCRETE:7)
Block(-7,12,-7,CONCRETE:7)
Block(-7,12,-6,CONCRETE:7)
Block(-7,12,-5,CONCRETE:7)
Block(-7,12,-4,CONCRETE:7)
Block(-7,12,-3,CONCRETE:7)
Block(-7,12,-2,CONCRETE:7)
Block(-7,12,-1,CONCRETE:7)
Block(-7,12,0,CONCRETE:7)
Block(-7,12,1,CONCRETE:7)
Block(-7,12,2,CONCRETE:7)
Block(-7,12,3,CONCRETE:7)
Block(-7,12,4,CONCRETE:7)
Block(-7,12,5,CONCRETE:7)
Block(-7,12,6,CONCRETE:7)
Block(-7,12,7,CONCRETE:7)
Block(-7,12,8,CONCRETE:7)
Block(-7,13,-7,CONCRETE:7)
Block(-7,13,-6,CONCRETE:7)
Block(-7,13,-5,CONCRETE:7)
Block(-7,13,-4,CONCRETE:7)
Block(-7,13,-3,CONCRETE:7)
Block(-7,13,-2,CONCRETE:7)
Block(-7,13,-1,CONCRETE:7)
Block(-7,13,0,CONCRETE:7)
Block(-7,13,1,CONCRETE:7)
Block(-7,13,2,CONCRETE:7)
Block(-7,13,3,CONCRETE:7)
Block(-7,13,4,CONCRETE:7)
Block(-7,13,5,CONCRETE:7)
Block(-7,13,6,CONCRETE:7)
Block(-7,13,7,CONCRETE:7)
Block(-7,13,8,CONCRETE:7)
Block(-7,14,-7,AIR:0)
Block(-7,14,-6,AIR:0)
Block(-7,14,-5,AIR:0)
Block(-7,14,-4,AIR:0)
Block(-7,14,-3,AIR:0)
Block(-7,14,-2,AIR:0)
Block(-7,14,-1,AIR:0)
Block(-7,14,0,AIR:0)
Block(-7,14,1,AIR:0)
Block(-7,14,2,AIR:0)
Block(-7,14,3,AIR:0)
Block(-7,14,4,AIR:0)
Block(-7,14,5,AIR:0)
Block(-7,14,6,AIR:0)
Block(-7,14,7,AIR:0)
Block(-7,14,8,CONCRETE:7)
Block(-7,15,-7,AIR:0)
Block(-7,15,-6,AIR:0)
Block(-7,15,-5,AIR:0)
Block(-7,15,-4,AIR:0)
Block(-7,15,-3,STONE_BUTTON:1)
Block(-7,15,-2,AIR:0)
Block(-7,15,-1,AIR:0)
Block(-7,15,0,STONE_BUTTON:1)
Block(-7,15,1,AIR:0)
Block(-7,15,2,AIR:0)
Block(-7,15,3,AIR:0)
Block(-7,15,4,AIR:0)
Block(-7,15,5,AIR:0)
Block(-7,15,6,AIR:0)
Block(-7,15,7,AIR:0)
Block(-7,15,8,CONCRETE:7)
Block(-7,16,-7,AIR:0)
Block(-7,16,-6,AIR:0)
Block(-7,16,-5,AIR:0)
Block(-7,16,-4,AIR:0)
Block(-7,16,-3,AIR:0)
Block(-7,16,-2,AIR:0)
Block(-7,16,-1,AIR:0)
Block(-7,16,0,AIR:0)
Block(-7,16,1,AIR:0)
Block(-7,16,2,AIR:0)
Block(-7,16,3,AIR:0)
Block(-7,16,4,AIR:0)
Block(-7,16,5,AIR:0)
Block(-7,16,6,AIR:0)
Block(-7,16,7,AIR:0)
Block(-7,16,8,CONCRETE:7)
Block(-7,17,-7,CONCRETE:7)
Block(-7,17,-6,CONCRETE:7)
Block(-7,17,-5,CONCRETE:7)
Block(-7,17,-4,CONCRETE:7)
Block(-7,17,-3,CONCRETE:7)
Block(-7,17,-2,CONCRETE:7)
Block(-7,17,-1,CONCRETE:7)
Block(-7,17,0,CONCRETE:7)
Block(-7,17,1,CONCRETE:7)
Block(-7,17,2,CONCRETE:7)
Block(-7,17,3,CONCRETE:7)
Block(-7,17,4,CONCRETE:7)
Block(-7,17,5,CONCRETE:7)
Block(-7,17,6,CONCRETE:7)
Block(-7,17,7,CONCRETE:7)
Block(-7,17,8,DOUBLE_STEP:0)
Block(-7,18,-3,CONCRETE:7)
Block(-7,18,0,DARK_OAK_STAIRS:4)
Block(-7,18,1,DARK_OAK_STAIRS:4)
Block(-7,18,5,DARK_OAK_STAIRS:2)
Block(-7,18,6,GRASS:0)
Block(-7,18,7,CONCRETE:7)
Block(-7,19,-3,CONCRETE:7)
Block(-7,19,0,CARPET:0)
Block(-7,19,1,CARPET:0)
Block(-7,19,6,LEAVES:12)
Block(-7,19,7,CONCRETE:7)
Block(-7,20,-3,CONCRETE:7)
Block(-7,20,6,LEAVES:4)
Block(-7,20,7,CONCRETE:7)
Block(-7,21,-7,STEP:8)
Block(-7,21,-6,STEP:8)
Block(-7,21,-5,STEP:8)
Block(-7,21,-4,STEP:8)
Block(-7,21,-3,CONCRETE:7)
Block(-7,21,-2,CONCRETE:8)
Block(-7,21,-1,CONCRETE:8)
Block(-7,21,0,CONCRETE:8)
Block(-7,21,1,CONCRETE:8)
Block(-7,21,2,CONCRETE:8)
Block(-7,21,3,CONCRETE:8)
Block(-7,21,4,CONCRETE:8)
Block(-7,21,5,CONCRETE:8)
Block(-7,21,6,CONCRETE:8)
Block(-7,21,7,CONCRETE:7)
Block(-7,22,-3,CONCRETE:7)
Block(-7,22,0,WORKBENCH:0)
Block(-7,22,1,WOOD:5)
Block(-7,22,3,WALL_SIGN:5,NBT/skyscraper_2x2_05/1293-signC16R16.nbt)
Block(-7,22,4,CARPET:14)
Block(-7,22,5,CARPET:14)
Block(-7,22,6,CONCRETE:15)
Block(-7,22,7,CONCRETE:7)
Block(-7,23,-3,CONCRETE:7)
Block(-7,23,0,IRON_PLATE:0)
Block(-7,23,1,IRON_PLATE:0)
Block(-7,23,5,WALL_BANNER:2,NBT/skyscraper_2x2_05/1294-bannerC16R16.nbt)
Block(-7,23,6,CONCRETE:15)
Block(-7,23,7,CONCRETE:7)
Block(-7,24,-3,CONCRETE:7)
Block(-7,24,6,IRON_TRAPDOOR:2)
Block(-7,24,7,CONCRETE:7)
Block(-7,25,-7,STEP:8)
Block(-7,25,-6,STEP:8)
Block(-7,25,-5,STEP:8)
Block(-7,25,-4,STEP:8)
Block(-7,25,-3,CONCRETE:7)
Block(-7,25,-2,CONCRETE:8)
Block(-7,25,-1,CONCRETE:8)
Block(-7,25,0,CONCRETE:8)
Block(-7,25,1,CONCRETE:8)
Block(-7,25,2,CONCRETE:8)
Block(-7,25,3,CONCRETE:8)
Block(-7,25,4,CONCRETE:8)
Block(-7,25,5,CONCRETE:8)
Block(-7,25,6,CONCRETE:8)
Block(-7,25,7,CONCRETE:7)
Block(-7,26,-3,CONCRETE:7)
Block(-7,26,0,WORKBENCH:0)
Block(-7,26,1,WOOD:5)
Block(-7,26,3,WALL_SIGN:5,NBT/skyscraper_2x2_05/1296-signC16R16.nbt)
Block(-7,26,4,CARPET:14)
Block(-7,26,5,CARPET:14)
Block(-7,26,6,CONCRETE:15)
Block(-7,26,7,CONCRETE:7)
Block(-7,27,-3,CONCRETE:7)
Block(-7,27,0,IRON_PLATE:0)
Block(-7,27,1,IRON_PLATE:0)
Block(-7,27,5,WALL_BANNER:2,NBT/skyscraper_2x2_05/1297-bannerC16R16.nbt)
Block(-7,27,6,CONCRETE:15)
Block(-7,27,7,CONCRETE:7)
Block(-7,28,-3,CONCRETE:7)
Block(-7,28,6,IRON_TRAPDOOR:2)
Block(-7,28,7,CONCRETE:7)
Block(-7,29,-7,STEP:8)
Block(-7,29,-6,STEP:8)
Block(-7,29,-5,STEP:8)
Block(-7,29,-4,STEP:8)
Block(-7,29,-3,CONCRETE:7)
Block(-7,29,-2,CONCRETE:8)
Block(-7,29,-1,CONCRETE:8)
Block(-7,29,0,CONCRETE:8)
Block(-7,29,1,CONCRETE:8)
Block(-7,29,2,CONCRETE:8)
Block(-7,29,3,CONCRETE:8)
Block(-7,29,4,CONCRETE:8)
Block(-7,29,5,CONCRETE:8)
Block(-7,29,6,CONCRETE:8)
Block(-7,29,7,CONCRETE:7)
Block(-7,30,-3,CONCRETE:7)
Block(-7,30,0,WORKBENCH:0)
Block(-7,30,1,WOOD:5)
Block(-7,30,3,WALL_SIGN:5,NBT/skyscraper_2x2_05/1299-signC16R16.nbt)
Block(-7,30,4,CARPET:14)
Block(-7,30,5,CARPET:14)
Block(-7,30,6,CONCRETE:15)
Block(-7,30,7,CONCRETE:7)
Block(-7,31,-3,CONCRETE:7)
Block(-7,31,0,IRON_PLATE:0)
Block(-7,31,1,IRON_PLATE:0)
Block(-7,31,5,WALL_BANNER:2,NBT/skyscraper_2x2_05/1300-bannerC16R16.nbt)
Block(-7,31,6,CONCRETE:15)
Block(-7,31,7,CONCRETE:7)
Block(-7,32,-3,CONCRETE:7)
Block(-7,32,6,IRON_TRAPDOOR:2)
Block(-7,32,7,CONCRETE:7)
Block(-7,33,-7,STEP:8)
Block(-7,33,-6,STEP:8)
Block(-7,33,-5,STEP:8)
Block(-7,33,-4,STEP:8)
Block(-7,33,-3,CONCRETE:7)
Block(-7,33,-2,CONCRETE:8)
Block(-7,33,-1,CONCRETE:8)
Block(-7,33,0,CONCRETE:8)
Block(-7,33,1,CONCRETE:8)
Block(-7,33,2,CONCRETE:8)
Block(-7,33,3,CONCRETE:8)
Block(-7,33,4,CONCRETE:8)
Block(-7,33,5,CONCRETE:8)
Block(-7,33,6,CONCRETE:8)
Block(-7,33,7,CONCRETE:7)
Block(-7,34,-3,CONCRETE:7)
Block(-7,34,0,WORKBENCH:0)
Block(-7,34,1,WOOD:5)
Block(-7,34,3,WALL_SIGN:5,NBT/skyscraper_2x2_05/1302-signC16R16.nbt)
Block(-7,34,4,CARPET:14)
Block(-7,34,5,CARPET:14)
Block(-7,34,6,CONCRETE:15)
Block(-7,34,7,CONCRETE:7)
Block(-7,35,-3,CONCRETE:7)
Block(-7,35,0,IRON_PLATE:0)
Block(-7,35,1,IRON_PLATE:0)
Block(-7,35,5,WALL_BANNER:2,NBT/skyscraper_2x2_05/1303-bannerC16R16.nbt)
Block(-7,35,6,CONCRETE:15)
Block(-7,35,7,CONCRETE:7)
Block(-7,36,-3,CONCRETE:7)
Block(-7,36,6,IRON_TRAPDOOR:2)
Block(-7,36,7,CONCRETE:7)
Block(-7,37,-7,STEP:8)
Block(-7,37,-6,STEP:8)
Block(-7,37,-5,STEP:8)
Block(-7,37,-4,STEP:8)
Block(-7,37,-3,CONCRETE:7)
Block(-7,37,-2,CONCRETE:8)
Block(-7,37,-1,CONCRETE:8)
Block(-7,37,0,CONCRETE:8)
Block(-7,37,1,CONCRETE:8)
Block(-7,37,2,CONCRETE:8)
Block(-7,37,3,CONCRETE:8)
Block(-7,37,4,CONCRETE:8)
Block(-7,37,5,CONCRETE:8)
Block(-7,37,6,CONCRETE:8)
Block(-7,37,7,CONCRETE:7)
Block(-7,38,-3,CONCRETE:7)
Block(-7,38,0,WORKBENCH:0)
Block(-7,38,1,WOOD:5)
Block(-7,38,3,WALL_SIGN:5,NBT/skyscraper_2x2_05/1305-signC16R16.nbt)
Block(-7,38,4,CARPET:14)
Block(-7,38,5,CARPET:14)
Block(-7,38,6,CONCRETE:15)
Block(-7,38,7,CONCRETE:8)
Block(-7,39,-3,CONCRETE:7)
Block(-7,39,0,IRON_PLATE:0)
Block(-7,39,1,IRON_PLATE:0)
Block(-7,39,5,WALL_BANNER:2,NBT/skyscraper_2x2_05/1306-bannerC16R16.nbt)
Block(-7,39,6,CONCRETE:15)
Block(-7,39,7,CONCRETE:8)
Block(-7,40,-3,CONCRETE:7)
Block(-7,40,6,IRON_TRAPDOOR:2)
Block(-7,40,7,CONCRETE:8)
Block(-7,41,-7,STEP:8)
Block(-7,41,-6,STEP:8)
Block(-7,41,-5,STEP:8)
Block(-7,41,-4,STEP:8)
Block(-7,41,-3,CONCRETE:7)
Block(-7,41,-2,CONCRETE:8)
Block(-7,41,-1,CONCRETE:8)
Block(-7,41,0,CONCRETE:8)
Block(-7,41,1,CONCRETE:8)
Block(-7,41,2,CONCRETE:8)
Block(-7,41,3,CONCRETE:8)
Block(-7,41,4,CONCRETE:8)
Block(-7,41,5,CONCRETE:8)
Block(-7,41,6,CONCRETE:8)
Block(-7,41,7,CONCRETE:8)
Block(-7,42,-3,CONCRETE:7)
Block(-7,42,0,WORKBENCH:0)
Block(-7,42,1,WOOD:5)
Block(-7,42,3,WALL_SIGN:5,NBT/skyscraper_2x2_05/1308-signC16R16.nbt)
Block(-7,42,4,CARPET:14)
Block(-7,42,5,CARPET:14)
Block(-7,42,6,CONCRETE:15)
Block(-7,42,7,CONCRETE:8)
Block(-7,43,-3,CONCRETE:7)
Block(-7,43,0,IRON_PLATE:0)
Block(-7,43,1,IRON_PLATE:0)
Block(-7,43,5,WALL_BANNER:2,NBT/skyscraper_2x2_05/1309-bannerC16R16.nbt)
Block(-7,43,6,CONCRETE:15)
Block(-7,43,7,CONCRETE:8)
Block(-7,44,-3,CONCRETE:7)
Block(-7,44,6,IRON_TRAPDOOR:2)
Block(-7,44,7,CONCRETE:8)
Block(-7,45,-7,STEP:8)
Block(-7,45,-6,STEP:8)
Block(-7,45,-5,STEP:8)
Block(-7,45,-4,STEP:8)
Block(-7,45,-3,CONCRETE:7)
Block(-7,45,-2,CONCRETE:8)
Block(-7,45,-1,CONCRETE:8)
Block(-7,45,0,CONCRETE:8)
Block(-7,45,1,CONCRETE:8)
Block(-7,45,2,CONCRETE:8)
Block(-7,45,3,CONCRETE:8)
Block(-7,45,4,CONCRETE:8)
Block(-7,45,5,CONCRETE:8)
Block(-7,45,6,CONCRETE:8)
Block(-7,45,7,CONCRETE:8)
Block(-7,46,-3,CONCRETE:7)
Block(-7,46,0,WORKBENCH:0)
Block(-7,46,1,WOOD:5)
Block(-7,46,3,WALL_SIGN:5,NBT/skyscraper_2x2_05/1311-signC16R16.nbt)
Block(-7,46,4,CARPET:14)
Block(-7,46,5,CARPET:14)
Block(-7,46,6,CONCRETE:15)
Block(-7,46,7,CONCRETE:8)
Block(-7,47,-3,CONCRETE:7)
Block(-7,47,0,IRON_PLATE:0)
Block(-7,47,1,IRON_PLATE:0)
Block(-7,47,5,WALL_BANNER:2,NBT/skyscraper_2x2_05/1312-bannerC16R16.nbt)
Block(-7,47,6,CONCRETE:15)
Block(-7,47,7,CONCRETE:8)
Block(-7,48,-3,CONCRETE:7)
Block(-7,48,6,IRON_TRAPDOOR:2)
Block(-7,48,7,CONCRETE:8)
Block(-7,49,-7,STEP:8)
Block(-7,49,-6,STEP:8)
Block(-7,49,-5,STEP:8)
Block(-7,49,-4,STEP:8)
Block(-7,49,-3,CONCRETE:7)
Block(-7,49,-2,CONCRETE:7)
Block(-7,49,-1,CONCRETE:7)
Block(-7,49,0,CONCRETE:7)
Block(-7,49,1,CONCRETE:7)
Block(-7,49,2,CONCRETE:7)
Block(-7,49,3,CONCRETE:7)
Block(-7,49,4,CONCRETE:7)
Block(-7,49,5,CONCRETE:7)
Block(-7,49,6,CONCRETE:7)
Block(-7,49,7,CONCRETE:7)
Block(-7,50,-3,DARK_OAK_DOOR:3)
Block(-7,50,1,IRON_TRAPDOOR:8)
Block(-7,50,2,CONCRETE:7)
Block(-7,50,3,IRON_TRAPDOOR:9)
Block(-7,50,6,CONCRETE:8)
Block(-7,50,7,CONCRETE:8)
Block(-7,51,-3,DARK_OAK_DOOR:9)
#RandomBlock(-7,51,1,TRAPPED_CHEST:5,../../../../../Chests/Loot/ModernCityJunk_1.nbt,65,CHEST:2,../../../../../Chests/Loot/ModernCityJunk_1.nbt,20,CHEST:2,../../../../../Chests/Loot/ModernCityJunk_2.nbt,15,CHEST:2,../../../../../Chests/Loot/ModernCityJunk_3.nbt,15,CHEST:2,../../../../../Chests/Loot/ModernCityJunk_4.nbt,15,CHEST:2,../../../../../Chests/Loot/ModernCityJunk_5.nbt,15,CHEST:2,../../../../../Chests/Loot/ModernCityCommon_1.nbt,5,CHEST:2,../../../../../Chests/Loot/ModernCityCommon_2.nbt,5,CHEST:2,../../../../../Chests/Loot/ModernCityCommon_3.nbt,5,CHEST:2,../../../../../Chests/Loot/ModernCityCommon_4.nbt,5,CHEST:2,../../../../../Chests/Loot/ModernCityCommon_5.nbt,5,CHEST:2,../../../../../Chests/Loot/ModernCityGood_1.nbt,3,CHEST:2,../../../../../Chests/Loot/ModernCityGood_2.nbt,3,CHEST:2,../../../../../Chests/Loot/ModernCityGood_3.nbt,3,CHEST:2,../../../../../Chests/Loot/ModernCityGood_4.nbt,3,CHEST:2,../../../../../Chests/Loot/ModernCityGood_5.nbt,3,CHEST:2,../../../../../Chests/Loot/ModernCityEpic_1.nbt,1,CHEST:2,../../../../../Chests/Loot/ModernCityEpic_2.nbt,1,CHEST:2,../../../../../Chests/Loot/ModernCityEpic_3.nbt,1,CHEST:2,../../../../../Chests/Loot/ModernCityEpic_4.nbt,1,CHEST:2,../../../../../Chests/Loot/ModernCityEpic_5.nbt,1,CHEST:2,../../../../../Chests/Loot/Common1.nbt,25,CHEST:2,../../../../../Chests/Loot/Common2.nbt,25,CHEST:2,../../../../../Chests/Loot/Common3.nbt,25,CHEST:2,../../../../../Chests/Loot/Common4.nbt,25,CHEST:2,../../../../../Chests/Loot/Common5.nbt,25,CHEST:2,../../../../../Chests/Loot/Common6.nbt,25,CHEST:2,../../../../../Chests/Loot/Common7.nbt,25,CHEST:2,../../../../../Chests/Loot/Common8.nbt,25,CHEST:2,../../../../../Chests/Loot/Common9.nbt,25,CHEST:2,../../../../../Chests/Loot/Common10.nbt,25,CHEST:2,../../../../../Chests/Loot/Common11.nbt,25,CHEST:2,../../../../../Chests/Loot/Common12.nbt,25,CHEST:2,../../../../../Chests/Loot/Common13.nbt,25,CHEST:2,../../../../../Chests/Loot/Common14.nbt,25,CHEST:2,../../../../../Chests/Loot/Common15.nbt,25,CHEST:2,../../../../../Chests/Loot/Rare1.nbt,10,CHEST:2,../../../../../Chests/Loot/Rare2.nbt,10,CHEST:5,../../../../../Chests/Loot/Rare3.nbt,10,CHEST:2,../../../../../Chests/Loot/Rare4.nbt,10,CHEST:2,../../../../../Chests/Loot/Rare5.nbt,10,CHEST:2,../../../../../Chests/Loot/Rare6.nbt,10,CHEST:2,../../../../../Chests/Loot/Rare7.nbt,10,CHEST:2,../../../../../Chests/Loot/Rare8.nbt,10,CHEST:2,../../../../../Chests/Loot/Rare9.nbt,10,CHEST:2,../../../../../Chests/Loot/Rare10.nbt,10,CHEST:2,../../../../../Chests/Loot/Rare11.nbt,10,CHEST:2,../../../../../Chests/Loot/Rare12.nbt,10,CHEST:2,../../../../../Chests/Loot/Rare13.nbt,10,CHEST:2,../../../../../Chests/Loot/Rare14.nbt,10,CHEST:2,../../../../../Chests/Loot/Rare15.nbt,10,CHEST:2,../../../../../Chests/Loot/Epic1.nbt,1,CHEST:2,../../../../../Chests/Loot/Epic2.nbt,1,CHEST:2,../../../../../Chests/Loot/Epic3.nbt,1,CHEST:2,../../../../../Chests/Loot/Epic4.nbt,1,CHEST:2,../../../../../Chests/Loot/Epic5.nbt,1,CHEST:2,../../../../../Chests/Loot/Epic6.nbt,1,CHEST:2,../../../../../Chests/Loot/Epic7.nbt,1,CHEST:2,../../../../../Chests/Loot/Epic8.nbt,1,CHEST:2,../../../../../Chests/Loot/Epic9.nbt,1,CHEST:2,../../../../../Chests/Loot/Epic10.nbt,1,CHEST:2,../../../../../Chests/Loot/Epic11.nbt,1,CHEST:2,../../../../../Chests/Loot/Epic12.nbt,1,CHEST:2,../../../../../Chests/Loot/Epic13.nbt,1,CHEST:2,../../../../../Chests/Loot/Epic14.nbt,1,CHEST:2,../../../../../Chests/Loot/Epic15.nbt,1,CHEST:2,../../../../../Chests/Loot/ModernCityJunk_1.nbt,100)
Block(-7,51,2,CONCRETE:7)
#RandomBlock(-7,51,3,TRAPPED_CHEST:5,../../../../../Chests/Loot/ModernCityJunk_1.nbt,65,CHEST:3,../../../../../Chests/Loot/ModernCityJunk_1.nbt,20,CHEST:3,../../../../../Chests/Loot/ModernCityJunk_2.nbt,15,CHEST:3,../../../../../Chests/Loot/ModernCityJunk_3.nbt,15,CHEST:3,../../../../../Chests/Loot/ModernCityJunk_4.nbt,15,CHEST:3,../../../../../Chests/Loot/ModernCityJunk_5.nbt,15,CHEST:3,../../../../../Chests/Loot/ModernCityCommon_1.nbt,5,CHEST:3,../../../../../Chests/Loot/ModernCityCommon_2.nbt,5,CHEST:3,../../../../../Chests/Loot/ModernCityCommon_3.nbt,5,CHEST:3,../../../../../Chests/Loot/ModernCityCommon_4.nbt,5,CHEST:3,../../../../../Chests/Loot/ModernCityCommon_5.nbt,5,CHEST:3,../../../../../Chests/Loot/ModernCityGood_1.nbt,3,CHEST:3,../../../../../Chests/Loot/ModernCityGood_2.nbt,3,CHEST:3,../../../../../Chests/Loot/ModernCityGood_3.nbt,3,CHEST:3,../../../../../Chests/Loot/ModernCityGood_4.nbt,3,CHEST:3,../../../../../Chests/Loot/ModernCityGood_5.nbt,3,CHEST:3,../../../../../Chests/Loot/ModernCityEpic_1.nbt,1,CHEST:3,../../../../../Chests/Loot/ModernCityEpic_2.nbt,1,CHEST:3,../../../../../Chests/Loot/ModernCityEpic_3.nbt,1,CHEST:3,../../../../../Chests/Loot/ModernCityEpic_4.nbt,1,CHEST:3,../../../../../Chests/Loot/ModernCityEpic_5.nbt,1,CHEST:3,../../../../../Chests/Loot/Common1.nbt,25,CHEST:3,../../../../../Chests/Loot/Common2.nbt,25,CHEST:3,../../../../../Chests/Loot/Common3.nbt,25,CHEST:3,../../../../../Chests/Loot/Common4.nbt,25,CHEST:3,../../../../../Chests/Loot/Common5.nbt,25,CHEST:3,../../../../../Chests/Loot/Common6.nbt,25,CHEST:3,../../../../../Chests/Loot/Common7.nbt,25,CHEST:3,../../../../../Chests/Loot/Common8.nbt,25,CHEST:3,../../../../../Chests/Loot/Common9.nbt,25,CHEST:3,../../../../../Chests/Loot/Common10.nbt,25,CHEST:3,../../../../../Chests/Loot/Common11.nbt,25,CHEST:3,../../../../../Chests/Loot/Common12.nbt,25,CHEST:3,../../../../../Chests/Loot/Common13.nbt,25,CHEST:3,../../../../../Chests/Loot/Common14.nbt,25,CHEST:3,../../../../../Chests/Loot/Common15.nbt,25,CHEST:3,../../../../../Chests/Loot/Rare1.nbt,10,CHEST:3,../../../../../Chests/Loot/Rare2.nbt,10,CHEST:5,../../../../../Chests/Loot/Rare3.nbt,10,CHEST:3,../../../../../Chests/Loot/Rare4.nbt,10,CHEST:3,../../../../../Chests/Loot/Rare5.nbt,10,CHEST:3,../../../../../Chests/Loot/Rare6.nbt,10,CHEST:3,../../../../../Chests/Loot/Rare7.nbt,10,CHEST:3,../../../../../Chests/Loot/Rare8.nbt,10,CHEST:3,../../../../../Chests/Loot/Rare9.nbt,10,CHEST:3,../../../../../Chests/Loot/Rare10.nbt,10,CHEST:3,../../../../../Chests/Loot/Rare11.nbt,10,CHEST:3,../../../../../Chests/Loot/Rare12.nbt,10,CHEST:3,../../../../../Chests/Loot/Rare13.nbt,10,CHEST:3,../../../../../Chests/Loot/Rare14.nbt,10,CHEST:3,../../../../../Chests/Loot/Rare15.nbt,10,CHEST:3,../../../../../Chests/Loot/Epic1.nbt,1,CHEST:3,../../../../../Chests/Loot/Epic2.nbt,1,CHEST:3,../../../../../Chests/Loot/Epic3.nbt,1,CHEST:3,../../../../../Chests/Loot/Epic4.nbt,1,CHEST:3,../../../../../Chests/Loot/Epic5.nbt,1,CHEST:3,../../../../../Chests/Loot/Epic6.nbt,1,CHEST:3,../../../../../Chests/Loot/Epic7.nbt,1,CHEST:3,../../../../../Chests/Loot/Epic8.nbt,1,CHEST:3,../../../../../Chests/Loot/Epic9.nbt,1,CHEST:3,../../../../../Chests/Loot/Epic10.nbt,1,CHEST:3,../../../../../Chests/Loot/Epic11.nbt,1,CHEST:3,../../../../../Chests/Loot/Epic12.nbt,1,CHEST:3,../../../../../Chests/Loot/Epic13.nbt,1,CHEST:3,../../../../../Chests/Loot/Epic14.nbt,1,CHEST:3,../../../../../Chests/Loot/Epic15.nbt,1,CHEST:3,../../../../../Chests/Loot/ModernCityJunk_1.nbt,100)
Block(-7,51,6,CONCRETE:8)
Block(-7,51,7,CONCRETE:8)
Block(-7,52,-3,CONCRETE:7)
Block(-7,52,-2,STEP:8)
Block(-7,52,-1,STEP:8)
Block(-7,52,0,STEP:8)
Block(-7,52,1,STEP:8)
Block(-7,52,2,CONCRETE:7)
Block(-7,52,3,STEP:8)
Block(-7,52,4,STEP:8)
Block(-7,52,5,CONCRETE:12)
Block(-7,52,6,CONCRETE:8)
Block(-7,52,7,CONCRETE:8)
Block(-7,53,-7,STEP:8)
Block(-7,53,-6,STEP:8)
Block(-7,53,-5,STEP:8)
Block(-7,53,-4,STEP:8)
Block(-7,53,-3,CONCRETE:7)
Block(-7,53,-2,CONCRETE:7)
Block(-7,53,-1,CONCRETE:7)
Block(-7,53,0,CONCRETE:7)
Block(-7,53,1,CONCRETE:7)
Block(-7,53,2,DOUBLE_STEP:0)
Block(-7,53,3,GRASS:0)
Block(-7,53,4,GRASS:0)
Block(-7,53,5,DOUBLE_STEP:0)
Block(-7,53,6,CONCRETE:7)
Block(-7,53,7,CONCRETE:7)
Block(-7,54,-3,CONCRETE:8)
Block(-7,54,-2,IRON_DOOR_BLOCK:2)
Block(-7,54,-1,IRON_DOOR_BLOCK:2)
Block(-7,54,0,IRON_DOOR_BLOCK:2)
Block(-7,54,7,IRON_FENCE:0)
Block(-7,55,-3,CONCRETE:8)
Block(-7,55,-2,IRON_DOOR_BLOCK:9)
Block(-7,55,-1,IRON_DOOR_BLOCK:8)
Block(-7,55,0,IRON_DOOR_BLOCK:8)
Block(-7,56,-3,CONCRETE:8)
Block(-7,57,-7,STEP:8)
Block(-7,57,-6,STEP:8)
Block(-7,57,-5,STEP:8)
Block(-7,57,-4,STEP:8)
Block(-7,57,-3,CONCRETE:8)
Block(-7,57,-2,SMOOTH_STAIRS:7)
Block(-7,58,-3,CONCRETE:8)
Block(-7,58,-2,IRON_FENCE:0)
Block(-7,59,-3,CONCRETE:8)
Block(-7,60,-3,CONCRETE:8)
Block(-7,61,-7,STEP:8)
Block(-7,61,-6,STEP:8)
Block(-7,61,-5,STEP:8)
Block(-7,61,-4,STEP:8)
Block(-7,61,-3,CONCRETE:8)
Block(-7,61,-2,SMOOTH_STAIRS:7)
Block(-7,62,-3,CONCRETE:8)
Block(-7,62,-2,IRON_FENCE:0)
Block(-7,63,-3,CONCRETE:8)
Block(-7,64,-3,CONCRETE:8)
Block(-7,65,-7,STEP:8)
Block(-7,65,-6,STEP:8)
Block(-7,65,-5,STEP:8)
Block(-7,65,-4,STEP:8)
Block(-7,65,-3,CONCRETE:8)
Block(-7,65,-2,SMOOTH_STAIRS:7)
Block(-7,66,-3,CONCRETE:8)
Block(-7,66,-2,IRON_FENCE:0)
Block(-7,67,-3,CONCRETE:8)
Block(-7,68,-3,CONCRETE:8)
Block(-7,69,-7,STEP:8)
Block(-7,69,-6,STEP:8)
Block(-7,69,-5,STEP:8)
Block(-7,69,-4,STEP:8)
Block(-7,69,-3,CONCRETE:8)
Block(-7,69,-2,SMOOTH_STAIRS:7)
Block(-7,70,-3,CONCRETE:8)
Block(-7,70,-2,IRON_FENCE:0)
Block(-7,71,-3,CONCRETE:8)
Block(-7,72,-3,CONCRETE:8)
Block(-7,73,-7,STEP:8)
Block(-7,73,-6,STEP:8)
Block(-7,73,-5,STEP:8)
Block(-7,73,-4,STEP:8)
Block(-7,73,-3,CONCRETE:8)
Block(-7,73,-2,SMOOTH_STAIRS:7)
Block(-7,74,-3,CONCRETE:8)
Block(-7,74,-2,IRON_FENCE:0)
Block(-7,75,-3,CONCRETE:8)
Block(-7,76,-3,CONCRETE:8)
Block(-7,77,-7,STEP:8)
Block(-7,77,-6,STEP:8)
Block(-7,77,-5,STEP:8)
Block(-7,77,-4,STEP:8)
Block(-7,77,-3,CONCRETE:8)
Block(-7,77,-2,SMOOTH_STAIRS:7)
Block(-7,78,-3,CONCRETE:8)
Block(-7,78,-2,IRON_FENCE:0)
Block(-7,79,-3,CONCRETE:8)
Block(-7,80,-3,CONCRETE:8)
Block(-7,81,-7,STEP:8)
Block(-7,81,-6,STEP:8)
Block(-7,81,-5,CONCRETE:7)
Block(-7,81,-4,STEP:8)
Block(-7,81,-3,CONCRETE:7)
Block(-7,81,-2,SMOOTH_STAIRS:7)
Block(-7,82,-7,CONCRETE:8)
Block(-7,82,-6,CONCRETE:8)
Block(-7,82,-5,CONCRETE:8)
Block(-7,82,-2,IRON_FENCE:0)
Block(-7,83,-7,SMOOTH_STAIRS:1)
Block(-7,83,-6,SMOOTH_STAIRS:1)
Block(-7,83,-5,CONCRETE:8)
Block(-7,84,-5,CONCRETE:8)
Block(-7,85,-5,CONCRETE:8)
Block(-7,86,-5,CONCRETE:8)
Block(-7,87,-5,CONCRETE:8)
Block(-7,88,-5,CONCRETE:8)
Block(-7,89,-7,CONCRETE:7)
Block(-7,89,-6,CONCRETE:7)
Block(-7,89,-5,CONCRETE:8)
Block(-7,90,-7,STAINED_GLASS_PANE:15)
Block(-7,90,-5,STAINED_GLASS_PANE:15)
Block(-7,91,-5,STAINED_GLASS_PANE:15)
Block(-7,92,-5,STAINED_GLASS_PANE:15)
Block(-7,93,-7,STAINED_GLASS:15)
Block(-7,93,-6,STAINED_GLASS:15)
Block(-7,93,-5,STAINED_GLASS:15)
Block(-7,94,-5,IRON_TRAPDOOR:3)
Block(-6,0,-7,CONCRETE:7)
Block(-6,0,-6,CONCRETE:7)
Block(-6,0,-5,CONCRETE:7)
Block(-6,0,-4,CONCRETE:7)
Block(-6,0,-3,CONCRETE:7)
Block(-6,0,-2,CONCRETE:7)
Block(-6,0,-1,CONCRETE:7)
Block(-6,0,0,CONCRETE:7)
Block(-6,0,1,CONCRETE:7)
Block(-6,0,2,CONCRETE:7)
Block(-6,0,3,CONCRETE:7)
Block(-6,0,4,CONCRETE:7)
Block(-6,0,5,CONCRETE:7)
Block(-6,0,6,CONCRETE:7)
Block(-6,0,7,CONCRETE:7)
Block(-6,0,8,CONCRETE:7)
Block(-6,1,-7,CONCRETE:7)
Block(-6,1,-6,CONCRETE:7)
Block(-6,1,-5,CONCRETE:7)
Block(-6,1,-4,CONCRETE:7)
Block(-6,1,-3,CONCRETE:7)
Block(-6,1,-2,STATIONARY_WATER:0)
Block(-6,1,-1,STATIONARY_WATER:0)
Block(-6,1,0,STATIONARY_WATER:0)
Block(-6,1,1,STATIONARY_WATER:0)
Block(-6,1,2,CONCRETE:7)
Block(-6,1,3,CONCRETE:7)
Block(-6,1,4,CONCRETE:7)
Block(-6,1,5,CONCRETE:7)
Block(-6,1,6,CONCRETE:7)
Block(-6,1,7,CONCRETE:7)
Block(-6,1,8,CONCRETE:7)
Block(-6,2,-7,SMOOTH_STAIRS:1)
Block(-6,2,-6,SMOOTH_STAIRS:1)
Block(-6,2,-5,SMOOTH_STAIRS:1)
Block(-6,2,-4,SMOOTH_STAIRS:1)
Block(-6,2,-3,SMOOTH_STAIRS:1)
Block(-6,2,-2,AIR:0)
Block(-6,2,-1,AIR:0)
Block(-6,2,0,AIR:0)
Block(-6,2,1,AIR:0)
Block(-6,2,2,CONCRETE:7)
Block(-6,2,3,CONCRETE:7)
Block(-6,2,4,CONCRETE:7)
Block(-6,2,5,CONCRETE:7)
Block(-6,2,6,CONCRETE:7)
Block(-6,2,7,CONCRETE:7)
Block(-6,2,8,CONCRETE:7)
Block(-6,3,-7,AIR:0)
Block(-6,3,-6,AIR:0)
Block(-6,3,-5,AIR:0)
Block(-6,3,-4,AIR:0)
Block(-6,3,-3,AIR:0)
Block(-6,3,-2,AIR:0)
Block(-6,3,-1,AIR:0)
Block(-6,3,0,AIR:0)
Block(-6,3,1,AIR:0)
Block(-6,3,2,CONCRETE:7)
Block(-6,3,3,CONCRETE:7)
Block(-6,3,4,CONCRETE:7)
Block(-6,3,5,CONCRETE:7)
Block(-6,3,6,CONCRETE:7)
Block(-6,3,7,CONCRETE:7)
Block(-6,3,8,CONCRETE:7)
Block(-6,4,-7,AIR:0)
Block(-6,4,-6,AIR:0)
Block(-6,4,-5,AIR:0)
Block(-6,4,-4,AIR:0)
Block(-6,4,-3,AIR:0)
Block(-6,4,-2,AIR:0)
Block(-6,4,-1,AIR:0)
Block(-6,4,0,AIR:0)
Block(-6,4,1,AIR:0)
Block(-6,4,2,CONCRETE:7)
Block(-6,4,3,CONCRETE:7)
Block(-6,4,4,CONCRETE:7)
Block(-6,4,5,CONCRETE:7)
Block(-6,4,6,CONCRETE:7)
Block(-6,4,7,CONCRETE:7)
Block(-6,4,8,CONCRETE:7)
Block(-6,5,-7,CONCRETE:14)
Block(-6,5,-6,CONCRETE:11)
Block(-6,5,-5,AIR:0)
Block(-6,5,-4,AIR:0)
Block(-6,5,-3,AIR:0)
Block(-6,5,-2,AIR:0)
Block(-6,5,-1,AIR:0)
Block(-6,5,0,AIR:0)
Block(-6,5,1,AIR:0)
Block(-6,5,2,CONCRETE:7)
Block(-6,5,3,CONCRETE:7)
Block(-6,5,4,CONCRETE:7)
Block(-6,5,5,CONCRETE:7)
Block(-6,5,6,CONCRETE:7)
Block(-6,5,7,CONCRETE:7)
Block(-6,5,8,CONCRETE:7)
Block(-6,6,-7,AIR:0)
Block(-6,6,-6,AIR:0)
Block(-6,6,-5,AIR:0)
Block(-6,6,-4,AIR:0)
Block(-6,6,-3,AIR:0)
Block(-6,6,-2,AIR:0)
Block(-6,6,-1,AIR:0)
Block(-6,6,0,AIR:0)
Block(-6,6,1,AIR:0)
Block(-6,6,2,CONCRETE:7)
Block(-6,6,3,CONCRETE:7)
Block(-6,6,4,CONCRETE:7)
Block(-6,6,5,CONCRETE:7)
Block(-6,6,6,CONCRETE:7)
Block(-6,6,7,CONCRETE:7)
Block(-6,6,8,CONCRETE:7)
Block(-6,7,-7,CONCRETE:7)
Block(-6,7,-6,CONCRETE:7)
Block(-6,7,-5,CONCRETE:7)
Block(-6,7,-4,CONCRETE:7)
Block(-6,7,-3,CONCRETE:7)
Block(-6,7,-2,CONCRETE:7)
Block(-6,7,-1,CONCRETE:7)
Block(-6,7,0,CONCRETE:7)
Block(-6,7,1,CONCRETE:7)
Block(-6,7,2,CONCRETE:7)
Block(-6,7,3,CONCRETE:7)
Block(-6,7,4,CONCRETE:7)
Block(-6,7,5,CONCRETE:7)
Block(-6,7,6,CONCRETE:7)
Block(-6,7,7,CONCRETE:7)
Block(-6,7,8,CONCRETE:7)
Block(-6,8,-7,CONCRETE:7)
Block(-6,8,-6,CONCRETE:7)
Block(-6,8,-5,CONCRETE:7)
Block(-6,8,-4,CONCRETE:7)
Block(-6,8,-3,CONCRETE:7)
Block(-6,8,-2,CONCRETE:7)
Block(-6,8,-1,CONCRETE:7)
Block(-6,8,0,CONCRETE:7)
Block(-6,8,1,CONCRETE:7)
Block(-6,8,2,CONCRETE:7)
Block(-6,8,3,CONCRETE:7)
Block(-6,8,4,CONCRETE:7)
Block(-6,8,5,CONCRETE:7)
Block(-6,8,6,CONCRETE:7)
Block(-6,8,7,CONCRETE:7)
Block(-6,8,8,CONCRETE:7)
Block(-6,9,-7,CONCRETE:7)
Block(-6,9,-6,CONCRETE:7)
Block(-6,9,-5,CONCRETE:7)
Block(-6,9,-4,CONCRETE:7)
Block(-6,9,-3,CONCRETE:7)
Block(-6,9,-2,CONCRETE:7)
Block(-6,9,-1,CONCRETE:7)
Block(-6,9,0,CONCRETE:7)
Block(-6,9,1,CONCRETE:7)
Block(-6,9,2,CONCRETE:7)
Block(-6,9,3,CONCRETE:7)
Block(-6,9,4,CONCRETE:7)
Block(-6,9,5,CONCRETE:7)
Block(-6,9,6,CONCRETE:7)
Block(-6,9,7,CONCRETE:7)
Block(-6,9,8,CONCRETE:7)
Block(-6,10,-7,CONCRETE:7)
Block(-6,10,-6,CONCRETE:7)
Block(-6,10,-5,CONCRETE:7)
Block(-6,10,-4,CONCRETE:7)
Block(-6,10,-3,CONCRETE:7)
Block(-6,10,-2,CONCRETE:7)
Block(-6,10,-1,CONCRETE:7)
Block(-6,10,0,CONCRETE:7)
Block(-6,10,1,CONCRETE:7)
Block(-6,10,2,CONCRETE:7)
Block(-6,10,3,CONCRETE:7)
Block(-6,10,4,CONCRETE:7)
Block(-6,10,5,CONCRETE:7)
Block(-6,10,6,CONCRETE:7)
Block(-6,10,7,CONCRETE:7)
Block(-6,10,8,CONCRETE:7)
Block(-6,11,-7,CONCRETE:7)
Block(-6,11,-6,CONCRETE:7)
Block(-6,11,-5,CONCRETE:7)
Block(-6,11,-4,CONCRETE:7)
Block(-6,11,-3,CONCRETE:7)
Block(-6,11,-2,CONCRETE:7)
Block(-6,11,-1,CONCRETE:7)
Block(-6,11,0,CONCRETE:7)
Block(-6,11,1,CONCRETE:7)
Block(-6,11,2,CONCRETE:7)
Block(-6,11,3,CONCRETE:7)
Block(-6,11,4,CONCRETE:7)
Block(-6,11,5,CONCRETE:7)
Block(-6,11,6,CONCRETE:7)
Block(-6,11,7,CONCRETE:7)
Block(-6,11,8,CONCRETE:7)
Block(-6,12,-7,CONCRETE:7)
Block(-6,12,-6,CONCRETE:7)
Block(-6,12,-5,CONCRETE:7)
Block(-6,12,-4,CONCRETE:7)
Block(-6,12,-3,CONCRETE:7)
Block(-6,12,-2,CONCRETE:7)
Block(-6,12,-1,CONCRETE:7)
Block(-6,12,0,CONCRETE:7)
Block(-6,12,1,CONCRETE:7)
Block(-6,12,2,CONCRETE:7)
Block(-6,12,3,CONCRETE:7)
Block(-6,12,4,CONCRETE:7)
Block(-6,12,5,CONCRETE:7)
Block(-6,12,6,CONCRETE:7)
Block(-6,12,7,CONCRETE:7)
Block(-6,12,8,CONCRETE:7)
Block(-6,13,-7,CONCRETE:7)
Block(-6,13,-6,CONCRETE:7)
Block(-6,13,-5,CONCRETE:7)
Block(-6,13,-4,CONCRETE:7)
Block(-6,13,-3,CONCRETE:7)
Block(-6,13,-2,CONCRETE:7)
Block(-6,13,-1,CONCRETE:7)
Block(-6,13,0,CONCRETE:7)
Block(-6,13,1,CONCRETE:7)
Block(-6,13,2,CONCRETE:7)
Block(-6,13,3,CONCRETE:7)
Block(-6,13,4,CONCRETE:7)
Block(-6,13,5,CONCRETE:7)
Block(-6,13,6,CONCRETE:7)
Block(-6,13,7,CONCRETE:7)
Block(-6,13,8,CONCRETE:7)
Block(-6,14,-7,STAINED_GLASS_PANE:15)
Block(-6,14,-6,STAINED_GLASS_PANE:15)
Block(-6,14,-5,STAINED_GLASS_PANE:15)
Block(-6,14,-4,STAINED_GLASS_PANE:15)
Block(-6,14,-3,STAINED_GLASS_PANE:15)
Block(-6,14,-2,STAINED_GLASS_PANE:15)
Block(-6,14,-1,STAINED_GLASS_PANE:15)
Block(-6,14,0,STAINED_GLASS_PANE:15)
Block(-6,14,1,STAINED_GLASS_PANE:15)
Block(-6,14,2,STAINED_GLASS_PANE:15)
Block(-6,14,3,STAINED_GLASS_PANE:15)
Block(-6,14,4,STAINED_GLASS_PANE:15)
Block(-6,14,5,CONCRETE:7)
Block(-6,14,6,AIR:0)
Block(-6,14,7,AIR:0)
Block(-6,14,8,CONCRETE:7)
Block(-6,15,-7,STAINED_GLASS_PANE:15)
Block(-6,15,-6,STAINED_GLASS_PANE:15)
Block(-6,15,-5,STAINED_GLASS_PANE:15)
Block(-6,15,-4,STAINED_GLASS_PANE:15)
Block(-6,15,-3,STAINED_GLASS_PANE:15)
Block(-6,15,-2,STAINED_GLASS_PANE:15)
Block(-6,15,-1,STAINED_GLASS_PANE:15)
Block(-6,15,0,STAINED_GLASS_PANE:15)
Block(-6,15,1,STAINED_GLASS_PANE:15)
Block(-6,15,2,STAINED_GLASS_PANE:15)
Block(-6,15,3,STAINED_GLASS_PANE:15)
Block(-6,15,4,STAINED_GLASS_PANE:15)
Block(-6,15,5,CONCRETE:7)
Block(-6,15,6,AIR:0)
Block(-6,15,7,AIR:0)
Block(-6,15,8,CONCRETE:7)
Block(-6,16,-7,STAINED_GLASS_PANE:15)
Block(-6,16,-6,STAINED_GLASS_PANE:15)
Block(-6,16,-5,STAINED_GLASS_PANE:15)
Block(-6,16,-4,STAINED_GLASS_PANE:15)
Block(-6,16,-3,STAINED_GLASS_PANE:15)
Block(-6,16,-2,STAINED_GLASS_PANE:15)
Block(-6,16,-1,STAINED_GLASS_PANE:15)
Block(-6,16,0,STAINED_GLASS_PANE:15)
Block(-6,16,1,STAINED_GLASS_PANE:15)
Block(-6,16,2,STAINED_GLASS_PANE:15)
Block(-6,16,3,STAINED_GLASS_PANE:15)
Block(-6,16,4,STAINED_GLASS_PANE:15)
Block(-6,16,5,CONCRETE:7)
Block(-6,16,6,AIR:0)
Block(-6,16,7,AIR:0)
Block(-6,16,8,CONCRETE:7)
Block(-6,17,-7,CONCRETE:7)
Block(-6,17,-6,CONCRETE:7)
Block(-6,17,-5,CONCRETE:7)
Block(-6,17,-4,CONCRETE:7)
Block(-6,17,-3,CONCRETE:7)
Block(-6,17,-2,CONCRETE:7)
Block(-6,17,-1,CONCRETE:7)
Block(-6,17,0,CONCRETE:7)
Block(-6,17,1,CONCRETE:7)
Block(-6,17,2,CONCRETE:7)
Block(-6,17,3,CONCRETE:7)
Block(-6,17,4,CONCRETE:7)
Block(-6,17,5,CONCRETE:7)
Block(-6,17,6,CONCRETE:7)
Block(-6,17,7,CONCRETE:7)
Block(-6,17,8,DOUBLE_STEP:0)
Block(-6,18,-3,CONCRETE:7)
Block(-6,18,0,WOOD:5)
Block(-6,18,1,WOOD:5)
Block(-6,18,5,TRAP_DOOR:7)
Block(-6,18,6,TRAP_DOOR:7)
Block(-6,18,7,CONCRETE:7)
Block(-6,19,-3,STAINED_GLASS_PANE:15)
Block(-6,19,0,CARPET:0)
Block(-6,19,1,CARPET:0)
Block(-6,19,7,STAINED_GLASS_PANE:15)
Block(-6,20,-3,STAINED_GLASS_PANE:15)
Block(-6,20,7,STAINED_GLASS_PANE:15)
Block(-6,21,-7,STEP:8)
Block(-6,21,-6,STEP:8)
Block(-6,21,-5,STEP:8)
Block(-6,21,-4,STEP:8)
Block(-6,21,-3,CONCRETE:7)
Block(-6,21,-2,CONCRETE:8)
Block(-6,21,-1,CONCRETE:8)
Block(-6,21,0,CONCRETE:8)
Block(-6,21,1,CONCRETE:8)
Block(-6,21,2,CONCRETE:8)
Block(-6,21,3,CONCRETE:8)
Block(-6,21,4,CONCRETE:8)
Block(-6,21,5,CONCRETE:8)
Block(-6,21,6,CONCRETE:8)
Block(-6,21,7,CONCRETE:7)
Block(-6,22,-3,CONCRETE:7)
Block(-6,22,-2,IRON_DOOR_BLOCK:2)
Block(-6,22,-1,IRON_DOOR_BLOCK:2)
Block(-6,22,7,CONCRETE:7)
Block(-6,23,-3,STAINED_GLASS_PANE:15)
Block(-6,23,-2,IRON_DOOR_BLOCK:9)
Block(-6,23,-1,IRON_DOOR_BLOCK:8)
Block(-6,23,7,STAINED_GLASS_PANE:15)
Block(-6,24,-6,WALL_BANNER:4,NBT/skyscraper_2x2_05/1332-bannerC16R16.nbt)
Block(-6,24,-3,STAINED_GLASS_PANE:15)
Block(-6,24,-2,WALL_BANNER:3,NBT/skyscraper_2x2_05/1333-bannerC16R16.nbt)
Block(-6,24,6,WALL_BANNER:2,NBT/skyscraper_2x2_05/1334-bannerC16R16.nbt)
Block(-6,24,7,STAINED_GLASS_PANE:15)
Block(-6,25,-7,STEP:8)
Block(-6,25,-6,STEP:8)
Block(-6,25,-5,STEP:8)
Block(-6,25,-4,STEP:8)
Block(-6,25,-3,CONCRETE:7)
Block(-6,25,-2,CONCRETE:8)
Block(-6,25,-1,CONCRETE:8)
Block(-6,25,0,CONCRETE:8)
Block(-6,25,1,CONCRETE:8)
Block(-6,25,2,CONCRETE:8)
Block(-6,25,3,CONCRETE:8)
Block(-6,25,4,CONCRETE:8)
Block(-6,25,5,CONCRETE:8)
Block(-6,25,6,CONCRETE:8)
Block(-6,25,7,CONCRETE:7)
Block(-6,26,-3,CONCRETE:7)
Block(-6,26,-2,IRON_DOOR_BLOCK:2)
Block(-6,26,-1,IRON_DOOR_BLOCK:2)
Block(-6,26,7,CONCRETE:7)
Block(-6,27,-3,STAINED_GLASS_PANE:15)
Block(-6,27,-2,IRON_DOOR_BLOCK:9)
Block(-6,27,-1,IRON_DOOR_BLOCK:8)
Block(-6,27,7,STAINED_GLASS_PANE:15)
Block(-6,28,-6,WALL_BANNER:4,NBT/skyscraper_2x2_05/1339-bannerC16R16.nbt)
Block(-6,28,-3,STAINED_GLASS_PANE:15)
Block(-6,28,-2,WALL_BANNER:3,NBT/skyscraper_2x2_05/1340-bannerC16R16.nbt)
Block(-6,28,6,WALL_BANNER:2,NBT/skyscraper_2x2_05/1341-bannerC16R16.nbt)
Block(-6,28,7,STAINED_GLASS_PANE:15)
Block(-6,29,-7,STEP:8)
Block(-6,29,-6,STEP:8)
Block(-6,29,-5,STEP:8)
Block(-6,29,-4,STEP:8)
Block(-6,29,-3,CONCRETE:7)
Block(-6,29,-2,CONCRETE:8)
Block(-6,29,-1,CONCRETE:8)
Block(-6,29,0,CONCRETE:8)
Block(-6,29,1,CONCRETE:8)
Block(-6,29,2,CONCRETE:8)
Block(-6,29,3,CONCRETE:8)
Block(-6,29,4,CONCRETE:8)
Block(-6,29,5,CONCRETE:8)
Block(-6,29,6,CONCRETE:8)
Block(-6,29,7,CONCRETE:7)
Block(-6,30,-3,CONCRETE:7)
Block(-6,30,-2,IRON_DOOR_BLOCK:2)
Block(-6,30,-1,IRON_DOOR_BLOCK:2)
Block(-6,30,7,CONCRETE:7)
Block(-6,31,-3,STAINED_GLASS_PANE:15)
Block(-6,31,-2,IRON_DOOR_BLOCK:9)
Block(-6,31,-1,IRON_DOOR_BLOCK:8)
Block(-6,31,7,STAINED_GLASS_PANE:15)
Block(-6,32,-6,WALL_BANNER:4,NBT/skyscraper_2x2_05/1346-bannerC16R16.nbt)
Block(-6,32,-3,STAINED_GLASS_PANE:15)
Block(-6,32,-2,WALL_BANNER:3,NBT/skyscraper_2x2_05/1347-bannerC16R16.nbt)
Block(-6,32,6,WALL_BANNER:2,NBT/skyscraper_2x2_05/1348-bannerC16R16.nbt)
Block(-6,32,7,STAINED_GLASS_PANE:15)
Block(-6,33,-7,STEP:8)
Block(-6,33,-6,STEP:8)
Block(-6,33,-5,STEP:8)
Block(-6,33,-4,STEP:8)
Block(-6,33,-3,CONCRETE:7)
Block(-6,33,-2,CONCRETE:8)
Block(-6,33,-1,CONCRETE:8)
Block(-6,33,0,CONCRETE:8)
Block(-6,33,1,CONCRETE:8)
Block(-6,33,2,CONCRETE:8)
Block(-6,33,3,CONCRETE:8)
Block(-6,33,4,CONCRETE:8)
Block(-6,33,5,CONCRETE:8)
Block(-6,33,6,CONCRETE:8)
Block(-6,33,7,CONCRETE:7)
Block(-6,34,-3,CONCRETE:7)
Block(-6,34,-2,IRON_DOOR_BLOCK:2)
Block(-6,34,-1,IRON_DOOR_BLOCK:2)
Block(-6,34,7,CONCRETE:7)
Block(-6,35,-3,STAINED_GLASS_PANE:15)
Block(-6,35,-2,IRON_DOOR_BLOCK:9)
Block(-6,35,-1,IRON_DOOR_BLOCK:8)
Block(-6,35,7,STAINED_GLASS_PANE:15)
Block(-6,36,-6,WALL_BANNER:4,NBT/skyscraper_2x2_05/1353-bannerC16R16.nbt)
Block(-6,36,-3,STAINED_GLASS_PANE:15)
Block(-6,36,-2,WALL_BANNER:3,NBT/skyscraper_2x2_05/1354-bannerC16R16.nbt)
Block(-6,36,6,WALL_BANNER:2,NBT/skyscraper_2x2_05/1355-bannerC16R16.nbt)
Block(-6,36,7,STAINED_GLASS_PANE:15)
Block(-6,37,-7,STEP:8)
Block(-6,37,-6,STEP:8)
Block(-6,37,-5,STEP:8)
Block(-6,37,-4,STEP:8)
Block(-6,37,-3,CONCRETE:7)
Block(-6,37,-2,CONCRETE:8)
Block(-6,37,-1,CONCRETE:8)
Block(-6,37,0,CONCRETE:8)
Block(-6,37,1,CONCRETE:8)
Block(-6,37,2,CONCRETE:8)
Block(-6,37,3,CONCRETE:8)
Block(-6,37,4,CONCRETE:8)
Block(-6,37,5,CONCRETE:8)
Block(-6,37,6,CONCRETE:8)
Block(-6,37,7,CONCRETE:7)
Block(-6,38,-3,CONCRETE:7)
Block(-6,38,-2,IRON_DOOR_BLOCK:2)
Block(-6,38,-1,IRON_DOOR_BLOCK:2)
Block(-6,38,7,CONCRETE:8)
Block(-6,39,-3,STAINED_GLASS_PANE:15)
Block(-6,39,-2,IRON_DOOR_BLOCK:9)
Block(-6,39,-1,IRON_DOOR_BLOCK:8)
Block(-6,39,7,STAINED_GLASS_PANE:15)
Block(-6,40,-7,WALL_BANNER:4,NBT/skyscraper_2x2_05/1359-bannerC16R16.nbt)
Block(-6,40,-3,STAINED_GLASS_PANE:15)
Block(-6,40,-2,WALL_BANNER:3,NBT/skyscraper_2x2_05/1360-bannerC16R16.nbt)
Block(-6,40,6,WALL_BANNER:2,NBT/skyscraper_2x2_05/1361-bannerC16R16.nbt)
Block(-6,40,7,STAINED_GLASS_PANE:15)
Block(-6,41,-7,STEP:8)
Block(-6,41,-6,STEP:8)
Block(-6,41,-5,STEP:8)
Block(-6,41,-4,STEP:8)
Block(-6,41,-3,CONCRETE:7)
Block(-6,41,-2,CONCRETE:8)
Block(-6,41,-1,CONCRETE:8)
Block(-6,41,0,CONCRETE:8)
Block(-6,41,1,CONCRETE:8)
Block(-6,41,2,CONCRETE:8)
Block(-6,41,3,CONCRETE:8)
Block(-6,41,4,CONCRETE:8)
Block(-6,41,5,CONCRETE:8)
Block(-6,41,6,CONCRETE:8)
Block(-6,41,7,CONCRETE:8)
Block(-6,42,-3,CONCRETE:7)
Block(-6,42,-2,IRON_DOOR_BLOCK:2)
Block(-6,42,-1,IRON_DOOR_BLOCK:2)
Block(-6,42,7,CONCRETE:8)
Block(-6,43,-3,STAINED_GLASS_PANE:15)
Block(-6,43,-2,IRON_DOOR_BLOCK:9)
Block(-6,43,-1,IRON_DOOR_BLOCK:8)
Block(-6,43,7,STAINED_GLASS_PANE:15)
Block(-6,44,-6,WALL_BANNER:4,NBT/skyscraper_2x2_05/1366-bannerC16R16.nbt)
Block(-6,44,-3,STAINED_GLASS_PANE:15)
Block(-6,44,-2,WALL_BANNER:3,NBT/skyscraper_2x2_05/1367-bannerC16R16.nbt)
Block(-6,44,6,WALL_BANNER:2,NBT/skyscraper_2x2_05/1368-bannerC16R16.nbt)
Block(-6,44,7,STAINED_GLASS_PANE:15)
Block(-6,45,-7,STEP:8)
Block(-6,45,-6,STEP:8)
Block(-6,45,-5,STEP:8)
Block(-6,45,-4,STEP:8)
Block(-6,45,-3,CONCRETE:7)
Block(-6,45,-2,CONCRETE:8)
Block(-6,45,-1,CONCRETE:8)
Block(-6,45,0,CONCRETE:8)
Block(-6,45,1,CONCRETE:8)
Block(-6,45,2,CONCRETE:8)
Block(-6,45,3,CONCRETE:8)
Block(-6,45,4,CONCRETE:8)
Block(-6,45,5,CONCRETE:8)
Block(-6,45,6,CONCRETE:8)
Block(-6,45,7,CONCRETE:8)
Block(-6,46,-3,CONCRETE:7)
Block(-6,46,-2,IRON_DOOR_BLOCK:2)
Block(-6,46,-1,IRON_DOOR_BLOCK:2)
Block(-6,46,7,CONCRETE:8)
Block(-6,47,-3,STAINED_GLASS_PANE:15)
Block(-6,47,-2,IRON_DOOR_BLOCK:9)
Block(-6,47,-1,IRON_DOOR_BLOCK:8)
Block(-6,47,7,STAINED_GLASS_PANE:15)
Block(-6,48,-7,WALL_BANNER:4,NBT/skyscraper_2x2_05/1373-bannerC16R16.nbt)
Block(-6,48,-3,STAINED_GLASS_PANE:15)
Block(-6,48,-2,WALL_BANNER:3,NBT/skyscraper_2x2_05/1374-bannerC16R16.nbt)
Block(-6,48,6,WALL_BANNER:2,NBT/skyscraper_2x2_05/1375-bannerC16R16.nbt)
Block(-6,48,7,STAINED_GLASS_PANE:15)
Block(-6,49,-7,STEP:8)
Block(-6,49,-6,STEP:8)
Block(-6,49,-5,STEP:8)
Block(-6,49,-4,STEP:8)
Block(-6,49,-3,CONCRETE:7)
Block(-6,49,-2,CONCRETE:7)
Block(-6,49,-1,CONCRETE:7)
Block(-6,49,0,CONCRETE:7)
Block(-6,49,1,CONCRETE:7)
Block(-6,49,2,CONCRETE:7)
Block(-6,49,3,CONCRETE:7)
Block(-6,49,4,CONCRETE:7)
Block(-6,49,5,CONCRETE:7)
Block(-6,49,6,CONCRETE:7)
Block(-6,49,7,CONCRETE:7)
Block(-6,50,-3,CONCRETE:7)
Block(-6,50,1,IRON_TRAPDOOR:8)
Block(-6,50,2,CONCRETE:7)
Block(-6,50,3,IRON_TRAPDOOR:9)
Block(-6,50,6,IRON_FENCE:0)
Block(-6,50,7,SMOOTH_STAIRS:7)
Block(-6,51,-3,CONCRETE:7)
Block(-6,51,1,STONE_BUTTON:2)
Block(-6,51,2,CONCRETE:7)
#RandomBlock(-6,51,3,TRAPPED_CHEST:5,../../../../../Chests/Loot/ModernCityJunk_1.nbt,65,CHEST:3,../../../../../Chests/Loot/ModernCityJunk_1.nbt,20,CHEST:3,../../../../../Chests/Loot/ModernCityJunk_2.nbt,15,CHEST:3,../../../../../Chests/Loot/ModernCityJunk_3.nbt,15,CHEST:3,../../../../../Chests/Loot/ModernCityJunk_4.nbt,15,CHEST:3,../../../../../Chests/Loot/ModernCityJunk_5.nbt,15,CHEST:3,../../../../../Chests/Loot/ModernCityCommon_1.nbt,5,CHEST:3,../../../../../Chests/Loot/ModernCityCommon_2.nbt,5,CHEST:3,../../../../../Chests/Loot/ModernCityCommon_3.nbt,5,CHEST:3,../../../../../Chests/Loot/ModernCityCommon_4.nbt,5,CHEST:3,../../../../../Chests/Loot/ModernCityCommon_5.nbt,5,CHEST:3,../../../../../Chests/Loot/ModernCityGood_1.nbt,3,CHEST:3,../../../../../Chests/Loot/ModernCityGood_2.nbt,3,CHEST:3,../../../../../Chests/Loot/ModernCityGood_3.nbt,3,CHEST:3,../../../../../Chests/Loot/ModernCityGood_4.nbt,3,CHEST:3,../../../../../Chests/Loot/ModernCityGood_5.nbt,3,CHEST:3,../../../../../Chests/Loot/ModernCityEpic_1.nbt,1,CHEST:3,../../../../../Chests/Loot/ModernCityEpic_2.nbt,1,CHEST:3,../../../../../Chests/Loot/ModernCityEpic_3.nbt,1,CHEST:3,../../../../../Chests/Loot/ModernCityEpic_4.nbt,1,CHEST:3,../../../../../Chests/Loot/ModernCityEpic_5.nbt,1,CHEST:3,../../../../../Chests/Loot/Common1.nbt,25,CHEST:3,../../../../../Chests/Loot/Common2.nbt,25,CHEST:3,../../../../../Chests/Loot/Common3.nbt,25,CHEST:3,../../../../../Chests/Loot/Common4.nbt,25,CHEST:3,../../../../../Chests/Loot/Common5.nbt,25,CHEST:3,../../../../../Chests/Loot/Common6.nbt,25,CHEST:3,../../../../../Chests/Loot/Common7.nbt,25,CHEST:3,../../../../../Chests/Loot/Common8.nbt,25,CHEST:3,../../../../../Chests/Loot/Common9.nbt,25,CHEST:3,../../../../../Chests/Loot/Common10.nbt,25,CHEST:3,../../../../../Chests/Loot/Common11.nbt,25,CHEST:3,../../../../../Chests/Loot/Common12.nbt,25,CHEST:3,../../../../../Chests/Loot/Common13.nbt,25,CHEST:3,../../../../../Chests/Loot/Common14.nbt,25,CHEST:3,../../../../../Chests/Loot/Common15.nbt,25,CHEST:3,../../../../../Chests/Loot/Rare1.nbt,10,CHEST:3,../../../../../Chests/Loot/Rare2.nbt,10,CHEST:5,../../../../../Chests/Loot/Rare3.nbt,10,CHEST:3,../../../../../Chests/Loot/Rare4.nbt,10,CHEST:3,../../../../../Chests/Loot/Rare5.nbt,10,CHEST:3,../../../../../Chests/Loot/Rare6.nbt,10,CHEST:3,../../../../../Chests/Loot/Rare7.nbt,10,CHEST:3,../../../../../Chests/Loot/Rare8.nbt,10,CHEST:3,../../../../../Chests/Loot/Rare9.nbt,10,CHEST:3,../../../../../Chests/Loot/Rare10.nbt,10,CHEST:3,../../../../../Chests/Loot/Rare11.nbt,10,CHEST:3,../../../../../Chests/Loot/Rare12.nbt,10,CHEST:3,../../../../../Chests/Loot/Rare13.nbt,10,CHEST:3,../../../../../Chests/Loot/Rare14.nbt,10,CHEST:3,../../../../../Chests/Loot/Rare15.nbt,10,CHEST:3,../../../../../Chests/Loot/Epic1.nbt,1,CHEST:3,../../../../../Chests/Loot/Epic2.nbt,1,CHEST:3,../../../../../Chests/Loot/Epic3.nbt,1,CHEST:3,../../../../../Chests/Loot/Epic4.nbt,1,CHEST:3,../../../../../Chests/Loot/Epic5.nbt,1,CHEST:3,../../../../../Chests/Loot/Epic6.nbt,1,CHEST:3,../../../../../Chests/Loot/Epic7.nbt,1,CHEST:3,../../../../../Chests/Loot/Epic8.nbt,1,CHEST:3,../../../../../Chests/Loot/Epic9.nbt,1,CHEST:3,../../../../../Chests/Loot/Epic10.nbt,1,CHEST:3,../../../../../Chests/Loot/Epic11.nbt,1,CHEST:3,../../../../../Chests/Loot/Epic12.nbt,1,CHEST:3,../../../../../Chests/Loot/Epic13.nbt,1,CHEST:3,../../../../../Chests/Loot/Epic14.nbt,1,CHEST:3,../../../../../Chests/Loot/Epic15.nbt,1,CHEST:3,../../../../../Chests/Loot/ModernCityJunk_1.nbt,100)
Block(-6,51,6,IRON_FENCE:0)
Block(-6,51,7,SMOOTH_STAIRS:7)
Block(-6,52,-7,WALL_BANNER:4,NBT/skyscraper_2x2_05/1381-bannerC16R16.nbt)
Block(-6,52,-3,CONCRETE:7)
Block(-6,52,-2,STEP:8)
Block(-6,52,-1,STEP:8)
Block(-6,52,0,STEP:8)
Block(-6,52,1,STEP:8)
Block(-6,52,2,CONCRETE:7)
Block(-6,52,3,STEP:8)
Block(-6,52,4,STEP:8)
Block(-6,52,5,CONCRETE:12)
Block(-6,52,6,IRON_FENCE:0)
Block(-6,52,7,SMOOTH_STAIRS:7)
Block(-6,53,-7,STEP:8)
Block(-6,53,-6,STEP:8)
Block(-6,53,-5,STEP:8)
Block(-6,53,-4,STEP:8)
Block(-6,53,-3,CONCRETE:7)
Block(-6,53,-2,CONCRETE:7)
Block(-6,53,-1,CONCRETE:7)
Block(-6,53,0,CONCRETE:7)
Block(-6,53,1,CONCRETE:7)
Block(-6,53,2,DOUBLE_STEP:0)
Block(-6,53,3,GRASS:0)
Block(-6,53,4,GRASS:0)
Block(-6,53,5,DOUBLE_STEP:0)
Block(-6,53,6,CONCRETE:7)
Block(-6,53,7,CONCRETE:7)
Block(-6,54,-3,CONCRETE:8)
Block(-6,54,-2,QUARTZ_STAIRS:1)
Block(-6,54,-1,QUARTZ_STAIRS:1)
Block(-6,54,7,IRON_FENCE:0)
Block(-6,55,-3,STAINED_GLASS_PANE:15)
Block(-6,56,-7,WALL_BANNER:4,NBT/skyscraper_2x2_05/1386-bannerC16R16.nbt)
Block(-6,56,-3,STAINED_GLASS_PANE:15)
Block(-6,57,-7,STEP:8)
Block(-6,57,-6,STEP:8)
Block(-6,57,-5,STEP:8)
Block(-6,57,-4,STEP:8)
Block(-6,57,-3,CONCRETE:8)
Block(-6,57,-2,SMOOTH_STAIRS:5)
Block(-6,58,-3,CONCRETE:8)
Block(-6,58,-2,IRON_FENCE:0)
Block(-6,59,-3,STAINED_GLASS_PANE:15)
Block(-6,60,-7,WALL_BANNER:4,NBT/skyscraper_2x2_05/1391-bannerC16R16.nbt)
Block(-6,60,-3,STAINED_GLASS_PANE:15)
Block(-6,61,-7,STEP:8)
Block(-6,61,-6,STEP:8)
Block(-6,61,-5,STEP:8)
Block(-6,61,-4,STEP:8)
Block(-6,61,-3,CONCRETE:8)
Block(-6,61,-2,SMOOTH_STAIRS:5)
Block(-6,62,-3,CONCRETE:8)
Block(-6,62,-2,IRON_FENCE:0)
Block(-6,63,-3,STAINED_GLASS_PANE:15)
Block(-6,64,-6,WALL_BANNER:4,NBT/skyscraper_2x2_05/1395-bannerC16R16.nbt)
Block(-6,64,-3,STAINED_GLASS_PANE:15)
Block(-6,65,-7,STEP:8)
Block(-6,65,-6,STEP:8)
Block(-6,65,-5,STEP:8)
Block(-6,65,-4,STEP:8)
Block(-6,65,-3,CONCRETE:8)
Block(-6,65,-2,SMOOTH_STAIRS:5)
Block(-6,66,-3,CONCRETE:8)
Block(-6,66,-2,IRON_FENCE:0)
Block(-6,67,-3,STAINED_GLASS_PANE:15)
Block(-6,68,-6,WALL_BANNER:4,NBT/skyscraper_2x2_05/1399-bannerC16R16.nbt)
Block(-6,68,-3,STAINED_GLASS_PANE:15)
Block(-6,69,-7,STEP:8)
Block(-6,69,-6,STEP:8)
Block(-6,69,-5,STEP:8)
Block(-6,69,-4,STEP:8)
Block(-6,69,-3,CONCRETE:8)
Block(-6,69,-2,SMOOTH_STAIRS:5)
Block(-6,70,-3,CONCRETE:8)
Block(-6,70,-2,IRON_FENCE:0)
Block(-6,71,-3,STAINED_GLASS_PANE:15)
Block(-6,72,-7,WALL_BANNER:4,NBT/skyscraper_2x2_05/1404-bannerC16R16.nbt)
Block(-6,72,-3,STAINED_GLASS_PANE:15)
Block(-6,73,-7,STEP:8)
Block(-6,73,-6,STEP:8)
Block(-6,73,-5,STEP:8)
Block(-6,73,-4,STEP:8)
Block(-6,73,-3,CONCRETE:8)
Block(-6,73,-2,SMOOTH_STAIRS:5)
Block(-6,74,-3,CONCRETE:8)
Block(-6,74,-2,IRON_FENCE:0)
Block(-6,75,-3,STAINED_GLASS_PANE:15)
Block(-6,76,-7,WALL_BANNER:4,NBT/skyscraper_2x2_05/1409-bannerC16R16.nbt)
Block(-6,76,-3,STAINED_GLASS_PANE:15)
Block(-6,77,-7,STEP:8)
Block(-6,77,-6,STEP:8)
Block(-6,77,-5,STEP:8)
Block(-6,77,-4,STEP:8)
Block(-6,77,-3,CONCRETE:8)
Block(-6,77,-2,SMOOTH_STAIRS:5)
Block(-6,78,-3,CONCRETE:8)
Block(-6,78,-2,IRON_FENCE:0)
Block(-6,79,-3,STAINED_GLASS_PANE:15)
Block(-6,80,-7,WALL_BANNER:4,NBT/skyscraper_2x2_05/1414-bannerC16R16.nbt)
Block(-6,80,-3,STAINED_GLASS_PANE:15)
Block(-6,81,-7,STEP:8)
Block(-6,81,-6,STEP:8)
Block(-6,81,-5,CONCRETE:7)
Block(-6,81,-4,STEP:8)
Block(-6,81,-3,CONCRETE:7)
Block(-6,81,-2,SMOOTH_STAIRS:5)
Block(-6,82,-7,CONCRETE:8)
Block(-6,82,-6,CONCRETE:8)
Block(-6,82,-5,CONCRETE:8)
Block(-6,82,-3,IRON_FENCE:0)
Block(-6,82,-2,IRON_FENCE:0)
Block(-6,83,-5,CONCRETE:8)
Block(-6,84,-5,CONCRETE:8)
Block(-6,85,-5,CONCRETE:8)
Block(-6,86,-5,CONCRETE:8)
Block(-6,87,-5,STAINED_GLASS_PANE:15)
Block(-6,88,-5,STAINED_GLASS_PANE:15)
Block(-6,89,-7,CONCRETE:7)
Block(-6,89,-6,CONCRETE:7)
Block(-6,89,-5,CONCRETE:8)
Block(-6,90,-5,STAINED_GLASS_PANE:15)
Block(-6,91,-5,STAINED_GLASS_PANE:15)
Block(-6,92,-5,STAINED_GLASS_PANE:15)
Block(-6,93,-7,STAINED_GLASS:15)
Block(-6,93,-6,STAINED_GLASS:15)
Block(-6,93,-5,STAINED_GLASS:15)
Block(-6,94,-5,IRON_TRAPDOOR:3)
Block(-5,0,-7,CONCRETE:7)
Block(-5,0,-6,CONCRETE:7)
Block(-5,0,-5,CONCRETE:7)
Block(-5,0,-4,CONCRETE:7)
Block(-5,0,-3,CONCRETE:7)
Block(-5,0,-2,CONCRETE:7)
Block(-5,0,-1,CONCRETE:7)
Block(-5,0,0,CONCRETE:7)
Block(-5,0,1,CONCRETE:7)
Block(-5,0,2,CONCRETE:7)
Block(-5,0,3,CONCRETE:7)
Block(-5,0,4,CONCRETE:7)
Block(-5,0,5,CONCRETE:7)
Block(-5,0,6,CONCRETE:7)
Block(-5,0,7,CONCRETE:7)
Block(-5,0,8,CONCRETE:7)
Block(-5,1,-7,STATIONARY_WATER:0)
Block(-5,1,-6,STATIONARY_WATER:0)
Block(-5,1,-5,STATIONARY_WATER:0)
Block(-5,1,-4,STATIONARY_WATER:0)
Block(-5,1,-3,STATIONARY_WATER:0)
Block(-5,1,-2,STATIONARY_WATER:0)
Block(-5,1,-1,STATIONARY_WATER:0)
Block(-5,1,0,STATIONARY_WATER:0)
Block(-5,1,1,STATIONARY_WATER:0)
Block(-5,1,2,CONCRETE:7)
Block(-5,1,3,CONCRETE:7)
Block(-5,1,4,CONCRETE:7)
Block(-5,1,5,CONCRETE:7)
Block(-5,1,6,CONCRETE:7)
Block(-5,1,7,CONCRETE:7)
Block(-5,1,8,CONCRETE:7)
Block(-5,2,-7,AIR:0)
Block(-5,2,-6,AIR:0)
Block(-5,2,-5,AIR:0)
Block(-5,2,-4,AIR:0)
Block(-5,2,-3,AIR:0)
Block(-5,2,-2,AIR:0)
Block(-5,2,-1,AIR:0)
Block(-5,2,0,AIR:0)
Block(-5,2,1,AIR:0)
Block(-5,2,2,CONCRETE:7)
Block(-5,2,3,SMOOTH_STAIRS:1)
Block(-5,2,4,SMOOTH_STAIRS:1)
Block(-5,2,5,SMOOTH_STAIRS:1)
Block(-5,2,6,SMOOTH_STAIRS:1)
Block(-5,2,7,SMOOTH_STAIRS:1)
Block(-5,2,8,SMOOTH_STAIRS:1)
Block(-5,3,-7,AIR:0)
Block(-5,3,-6,AIR:0)
Block(-5,3,-5,AIR:0)
Block(-5,3,-4,AIR:0)
Block(-5,3,-3,AIR:0)
Block(-5,3,-2,AIR:0)
Block(-5,3,-1,AIR:0)
Block(-5,3,0,AIR:0)
Block(-5,3,1,AIR:0)
Block(-5,3,2,CONCRETE:7)
Block(-5,3,3,AIR:0)
Block(-5,3,4,AIR:0)
Block(-5,3,5,AIR:0)
Block(-5,3,6,AIR:0)
Block(-5,3,7,AIR:0)
Block(-5,3,8,AIR:0)
Block(-5,4,-7,AIR:0)
Block(-5,4,-6,AIR:0)
Block(-5,4,-5,AIR:0)
Block(-5,4,-4,AIR:0)
Block(-5,4,-3,AIR:0)
Block(-5,4,-2,AIR:0)
Block(-5,4,-1,AIR:0)
Block(-5,4,0,AIR:0)
Block(-5,4,1,AIR:0)
Block(-5,4,2,CONCRETE:7)
Block(-5,4,3,STEP:8)
Block(-5,4,4,CONCRETE:7)
Block(-5,4,5,STEP:8)
Block(-5,4,6,STEP:8)
Block(-5,4,7,CONCRETE:7)
Block(-5,4,8,STEP:8)
Block(-5,5,-7,CONCRETE:14)
Block(-5,5,-6,CONCRETE:11)
Block(-5,5,-5,AIR:0)
Block(-5,5,-4,AIR:0)
Block(-5,5,-3,AIR:0)
Block(-5,5,-2,AIR:0)
Block(-5,5,-1,AIR:0)
Block(-5,5,0,AIR:0)
Block(-5,5,1,AIR:0)
Block(-5,5,2,CONCRETE:7)
Block(-5,5,3,CONCRETE:7)
Block(-5,5,4,CONCRETE:7)
Block(-5,5,5,CONCRETE:7)
Block(-5,5,6,CONCRETE:7)
Block(-5,5,7,CONCRETE:7)
Block(-5,5,8,CONCRETE:7)
Block(-5,6,-7,IRON_FENCE:0)
Block(-5,6,-6,AIR:0)
Block(-5,6,-5,AIR:0)
Block(-5,6,-4,AIR:0)
Block(-5,6,-3,AIR:0)
Block(-5,6,-2,AIR:0)
Block(-5,6,-1,AIR:0)
Block(-5,6,0,AIR:0)
Block(-5,6,1,AIR:0)
Block(-5,6,2,CONCRETE:7)
Block(-5,6,3,CONCRETE:7)
Block(-5,6,4,CONCRETE:7)
Block(-5,6,5,CONCRETE:7)
Block(-5,6,6,CONCRETE:7)
Block(-5,6,7,CONCRETE:7)
Block(-5,6,8,CONCRETE:7)
Block(-5,7,-7,CONCRETE:7)
Block(-5,7,-6,CONCRETE:7)
Block(-5,7,-5,CONCRETE:7)
Block(-5,7,-4,CONCRETE:7)
Block(-5,7,-3,CONCRETE:7)
Block(-5,7,-2,CONCRETE:7)
Block(-5,7,-1,CONCRETE:7)
Block(-5,7,0,CONCRETE:7)
Block(-5,7,1,CONCRETE:7)
Block(-5,7,2,CONCRETE:7)
Block(-5,7,3,CONCRETE:7)
Block(-5,7,4,CONCRETE:7)
Block(-5,7,5,CONCRETE:7)
Block(-5,7,6,CONCRETE:7)
Block(-5,7,7,CONCRETE:7)
Block(-5,7,8,CONCRETE:7)
Block(-5,8,-7,CONCRETE:7)
Block(-5,8,-6,CONCRETE:7)
Block(-5,8,-5,CONCRETE:7)
Block(-5,8,-4,CONCRETE:7)
Block(-5,8,-3,CONCRETE:7)
Block(-5,8,-2,CONCRETE:7)
Block(-5,8,-1,CONCRETE:7)
Block(-5,8,0,CONCRETE:7)
Block(-5,8,1,CONCRETE:7)
Block(-5,8,2,CONCRETE:7)
Block(-5,8,3,CONCRETE:7)
Block(-5,8,4,CONCRETE:7)
Block(-5,8,5,CONCRETE:7)
Block(-5,8,6,CONCRETE:7)
Block(-5,8,7,CONCRETE:7)
Block(-5,8,8,CONCRETE:7)
Block(-5,9,-7,CONCRETE:7)
Block(-5,9,-6,CONCRETE:7)
Block(-5,9,-5,CONCRETE:7)
Block(-5,9,-4,CONCRETE:7)
Block(-5,9,-3,CONCRETE:7)
Block(-5,9,-2,CONCRETE:7)
Block(-5,9,-1,CONCRETE:7)
Block(-5,9,0,CONCRETE:7)
Block(-5,9,1,CONCRETE:7)
Block(-5,9,2,CONCRETE:7)
Block(-5,9,3,CONCRETE:7)
Block(-5,9,4,CONCRETE:7)
Block(-5,9,5,CONCRETE:7)
Block(-5,9,6,CONCRETE:7)
Block(-5,9,7,CONCRETE:7)
Block(-5,9,8,CONCRETE:7)
Block(-5,10,-7,CONCRETE:7)
Block(-5,10,-6,CONCRETE:7)
Block(-5,10,-5,CONCRETE:7)
Block(-5,10,-4,CONCRETE:7)
Block(-5,10,-3,CONCRETE:7)
Block(-5,10,-2,CONCRETE:7)
Block(-5,10,-1,CONCRETE:7)
Block(-5,10,0,CONCRETE:7)
Block(-5,10,1,CONCRETE:7)
Block(-5,10,2,CONCRETE:7)
Block(-5,10,3,CONCRETE:7)
Block(-5,10,4,CONCRETE:7)
Block(-5,10,5,CONCRETE:7)
Block(-5,10,6,CONCRETE:7)
Block(-5,10,7,CONCRETE:7)
Block(-5,10,8,CONCRETE:7)
Block(-5,11,-7,CONCRETE:7)
Block(-5,11,-6,CONCRETE:7)
Block(-5,11,-5,CONCRETE:7)
Block(-5,11,-4,CONCRETE:7)
Block(-5,11,-3,CONCRETE:7)
Block(-5,11,-2,CONCRETE:7)
Block(-5,11,-1,CONCRETE:7)
Block(-5,11,0,CONCRETE:7)
Block(-5,11,1,CONCRETE:7)
Block(-5,11,2,CONCRETE:7)
Block(-5,11,3,CONCRETE:7)
Block(-5,11,4,CONCRETE:7)
Block(-5,11,5,CONCRETE:7)
Block(-5,11,6,CONCRETE:7)
Block(-5,11,7,CONCRETE:7)
Block(-5,11,8,CONCRETE:7)
Block(-5,12,-7,CONCRETE:7)
Block(-5,12,-6,CONCRETE:7)
Block(-5,12,-5,CONCRETE:7)
Block(-5,12,-4,CONCRETE:7)
Block(-5,12,-3,CONCRETE:7)
Block(-5,12,-2,CONCRETE:7)
Block(-5,12,-1,CONCRETE:7)
Block(-5,12,0,CONCRETE:7)
Block(-5,12,1,CONCRETE:7)
Block(-5,12,2,CONCRETE:7)
Block(-5,12,3,CONCRETE:7)
Block(-5,12,4,CONCRETE:7)
Block(-5,12,5,CONCRETE:7)
Block(-5,12,6,CONCRETE:7)
Block(-5,12,7,CONCRETE:7)
Block(-5,12,8,CONCRETE:7)
Block(-5,13,-7,AIR:0)
Block(-5,13,-6,AIR:0)
Block(-5,13,-5,STONE_BUTTON:2)
Block(-5,13,-4,STONE_BUTTON:2)
Block(-5,13,-3,AIR:0)
Block(-5,13,-2,AIR:0)
Block(-5,13,-1,AIR:0)
Block(-5,13,0,AIR:0)
Block(-5,13,1,STONE_BUTTON:2)
Block(-5,13,2,STONE_BUTTON:2)
Block(-5,13,3,AIR:0)
Block(-5,13,4,AIR:0)
Block(-5,13,5,AIR:0)
Block(-5,13,6,QUARTZ_STAIRS:1)
Block(-5,13,7,QUARTZ_STAIRS:1)
Block(-5,13,8,CONCRETE:7)
Block(-5,14,-7,AIR:0)
Block(-5,14,-6,AIR:0)
Block(-5,14,-5,STONE_BUTTON:2)
Block(-5,14,-4,AIR:0)
Block(-5,14,-3,AIR:0)
Block(-5,14,-2,AIR:0)
Block(-5,14,-1,AIR:0)
Block(-5,14,0,AIR:0)
Block(-5,14,1,STONE_BUTTON:2)
Block(-5,14,2,AIR:0)
Block(-5,14,3,AIR:0)
Block(-5,14,4,AIR:0)
Block(-5,14,5,AIR:0)
Block(-5,14,6,AIR:0)
Block(-5,14,7,AIR:0)
Block(-5,14,8,CONCRETE:7)
Block(-5,15,-7,AIR:0)
Block(-5,15,-6,AIR:0)
Block(-5,15,-5,STONE_BUTTON:2)
Block(-5,15,-4,LEVER:2)
Block(-5,15,-3,AIR:0)
Block(-5,15,-2,AIR:0)
Block(-5,15,-1,AIR:0)
Block(-5,15,0,AIR:0)
Block(-5,15,1,STONE_BUTTON:2)
Block(-5,15,2,LEVER:2)
Block(-5,15,3,AIR:0)
Block(-5,15,4,AIR:0)
Block(-5,15,5,AIR:0)
Block(-5,15,6,AIR:0)
Block(-5,15,7,AIR:0)
Block(-5,15,8,CONCRETE:7)
Block(-5,16,-7,AIR:0)
Block(-5,16,-6,AIR:0)
Block(-5,16,-5,AIR:0)
Block(-5,16,-4,AIR:0)
Block(-5,16,-3,AIR:0)
Block(-5,16,-2,AIR:0)
Block(-5,16,-1,AIR:0)
Block(-5,16,0,AIR:0)
Block(-5,16,1,AIR:0)
Block(-5,16,2,AIR:0)
Block(-5,16,3,AIR:0)
Block(-5,16,4,AIR:0)
Block(-5,16,5,AIR:0)
Block(-5,16,6,AIR:0)
Block(-5,16,7,AIR:0)
Block(-5,16,8,CONCRETE:7)
Block(-5,17,-7,CONCRETE:7)
Block(-5,17,-6,CONCRETE:7)
Block(-5,17,-5,CONCRETE:7)
Block(-5,17,-4,CONCRETE:7)
Block(-5,17,-3,CONCRETE:7)
Block(-5,17,-2,CONCRETE:7)
Block(-5,17,-1,CONCRETE:7)
Block(-5,17,0,CONCRETE:7)
Block(-5,17,1,CONCRETE:7)
Block(-5,17,2,CONCRETE:7)
Block(-5,17,3,CONCRETE:7)
Block(-5,17,4,CONCRETE:7)
Block(-5,17,5,CONCRETE:7)
Block(-5,17,6,CONCRETE:7)
Block(-5,17,7,CONCRETE:7)
Block(-5,17,8,DOUBLE_STEP:0)
Block(-5,18,-5,CONCRETE:7)
Block(-5,18,-4,CONCRETE:7)
Block(-5,18,-3,CONCRETE:7)
Block(-5,18,0,CONCRETE:7)
Block(-5,18,1,CONCRETE:7)
Block(-5,18,4,CONCRETE:7)
Block(-5,18,5,CONCRETE:7)
Block(-5,18,7,CONCRETE:7)
Block(-5,19,-5,CONCRETE:7)
Block(-5,19,-4,CONCRETE:7)
Block(-5,19,-3,CONCRETE:7)
Block(-5,19,0,CONCRETE:7)
Block(-5,19,1,CONCRETE:7)
Block(-5,19,4,CONCRETE:7)
Block(-5,19,5,CONCRETE:7)
Block(-5,19,7,CONCRETE:7)
Block(-5,20,-5,CONCRETE:7)
Block(-5,20,-4,CONCRETE:7)
Block(-5,20,-3,CONCRETE:7)
Block(-5,20,0,CONCRETE:7)
Block(-5,20,1,CONCRETE:7)
Block(-5,20,4,CONCRETE:7)
Block(-5,20,5,CONCRETE:7)
Block(-5,20,7,CONCRETE:7)
Block(-5,21,-7,CONCRETE:7)
Block(-5,21,-6,CONCRETE:7)
Block(-5,21,-5,CONCRETE:7)
Block(-5,21,-4,CONCRETE:7)
Block(-5,21,-3,CONCRETE:7)
Block(-5,21,-2,CONCRETE:8)
Block(-5,21,-1,CONCRETE:8)
Block(-5,21,0,CONCRETE:8)
Block(-5,21,1,CONCRETE:8)
Block(-5,21,2,CONCRETE:8)
Block(-5,21,3,CONCRETE:8)
Block(-5,21,4,CONCRETE:8)
Block(-5,21,5,CONCRETE:8)
Block(-5,21,6,CONCRETE:8)
Block(-5,21,7,CONCRETE:7)
Block(-5,22,-7,CONCRETE:7)
Block(-5,22,-6,CONCRETE:7)
Block(-5,22,-5,DARK_OAK_DOOR:2)
Block(-5,22,-4,CONCRETE:7)
Block(-5,22,-3,CONCRETE:7)
Block(-5,22,-2,DROPPER:4,NBT/skyscraper_2x2_05/1415-dropperC16R16.nbt)
Block(-5,22,-1,DROPPER:4,NBT/skyscraper_2x2_05/1416-dropperC16R16.nbt)
Block(-5,22,0,FURNACE:4,NBT/skyscraper_2x2_05/1417-furnaceC16R16.nbt)
Block(-5,22,1,FURNACE:4,NBT/skyscraper_2x2_05/1418-furnaceC16R16.nbt)
Block(-5,22,2,CAULDRON:3)
Block(-5,22,3,IRON_DOOR_BLOCK:3)
Block(-5,22,7,CONCRETE:7)
Block(-5,23,-7,CONCRETE:7)
Block(-5,23,-6,CONCRETE:7)
Block(-5,23,-5,DARK_OAK_DOOR:9)
Block(-5,23,-4,CONCRETE:7)
Block(-5,23,-3,CONCRETE:7)
Block(-5,23,-2,DROPPER:4,NBT/skyscraper_2x2_05/1419-dropperC16R16.nbt)
Block(-5,23,-1,DROPPER:4,NBT/skyscraper_2x2_05/1420-dropperC16R16.nbt)
Block(-5,23,0,IRON_TRAPDOOR:2)
Block(-5,23,1,IRON_TRAPDOOR:2)
Block(-5,23,2,TRIPWIRE_HOOK:1)
Block(-5,23,3,IRON_DOOR_BLOCK:9)
Block(-5,23,7,CONCRETE:7)
Block(-5,24,-7,CONCRETE:7)
Block(-5,24,-6,CONCRETE:7)
Block(-5,24,-5,CONCRETE:7)
Block(-5,24,-4,CONCRETE:7)
Block(-5,24,-3,CONCRETE:7)
Block(-5,24,-2,IRON_TRAPDOOR:1)
Block(-5,24,-1,IRON_TRAPDOOR:1)
Block(-5,24,0,IRON_TRAPDOOR:2)
Block(-5,24,1,IRON_TRAPDOOR:2)
Block(-5,24,2,IRON_TRAPDOOR:2)
Block(-5,24,3,IRON_TRAPDOOR:2)
Block(-5,24,7,CONCRETE:7)
Block(-5,25,-7,CONCRETE:7)
Block(-5,25,-6,CONCRETE:7)
Block(-5,25,-5,CONCRETE:7)
Block(-5,25,-4,CONCRETE:7)
Block(-5,25,-3,CONCRETE:7)
Block(-5,25,-2,CONCRETE:8)
Block(-5,25,-1,CONCRETE:8)
Block(-5,25,0,CONCRETE:8)
Block(-5,25,1,CONCRETE:8)
Block(-5,25,2,CONCRETE:8)
Block(-5,25,3,CONCRETE:8)
Block(-5,25,4,CONCRETE:8)
Block(-5,25,5,CONCRETE:8)
Block(-5,25,6,CONCRETE:8)
Block(-5,25,7,CONCRETE:7)
Block(-5,26,-7,CONCRETE:7)
Block(-5,26,-6,CONCRETE:7)
Block(-5,26,-5,DARK_OAK_DOOR:2)
Block(-5,26,-4,CONCRETE:7)
Block(-5,26,-3,CONCRETE:7)
Block(-5,26,-2,DROPPER:4,NBT/skyscraper_2x2_05/1421-dropperC16R16.nbt)
Block(-5,26,-1,DROPPER:4,NBT/skyscraper_2x2_05/1422-dropperC16R16.nbt)
Block(-5,26,0,FURNACE:4,NBT/skyscraper_2x2_05/1423-furnaceC16R16.nbt)
Block(-5,26,1,FURNACE:4,NBT/skyscraper_2x2_05/1424-furnaceC16R16.nbt)
Block(-5,26,2,CAULDRON:3)
Block(-5,26,3,IRON_DOOR_BLOCK:3)
Block(-5,26,7,CONCRETE:7)
Block(-5,27,-7,CONCRETE:7)
Block(-5,27,-6,CONCRETE:7)
Block(-5,27,-5,DARK_OAK_DOOR:9)
Block(-5,27,-4,CONCRETE:7)
Block(-5,27,-3,CONCRETE:7)
Block(-5,27,-2,DROPPER:4,NBT/skyscraper_2x2_05/1425-dropperC16R16.nbt)
Block(-5,27,-1,DROPPER:4,NBT/skyscraper_2x2_05/1426-dropperC16R16.nbt)
Block(-5,27,0,IRON_TRAPDOOR:2)
Block(-5,27,1,IRON_TRAPDOOR:2)
Block(-5,27,2,TRIPWIRE_HOOK:1)
Block(-5,27,3,IRON_DOOR_BLOCK:9)
Block(-5,27,7,CONCRETE:7)
Block(-5,28,-7,CONCRETE:7)
Block(-5,28,-6,CONCRETE:7)
Block(-5,28,-5,CONCRETE:7)
Block(-5,28,-4,CONCRETE:7)
Block(-5,28,-3,CONCRETE:7)
Block(-5,28,-2,IRON_TRAPDOOR:1)
Block(-5,28,-1,IRON_TRAPDOOR:1)
Block(-5,28,0,IRON_TRAPDOOR:2)
Block(-5,28,1,IRON_TRAPDOOR:2)
Block(-5,28,2,IRON_TRAPDOOR:2)
Block(-5,28,3,IRON_TRAPDOOR:2)
Block(-5,28,7,CONCRETE:7)
Block(-5,29,-7,CONCRETE:7)
Block(-5,29,-6,CONCRETE:7)
Block(-5,29,-5,CONCRETE:7)
Block(-5,29,-4,CONCRETE:7)
Block(-5,29,-3,CONCRETE:7)
Block(-5,29,-2,CONCRETE:8)
Block(-5,29,-1,CONCRETE:8)
Block(-5,29,0,CONCRETE:8)
Block(-5,29,1,CONCRETE:8)
Block(-5,29,2,CONCRETE:8)
Block(-5,29,3,CONCRETE:8)
Block(-5,29,4,CONCRETE:8)
Block(-5,29,5,CONCRETE:8)
Block(-5,29,6,CONCRETE:8)
Block(-5,29,7,CONCRETE:7)
Block(-5,30,-7,CONCRETE:7)
Block(-5,30,-6,CONCRETE:7)
Block(-5,30,-5,DARK_OAK_DOOR:2)
Block(-5,30,-4,CONCRETE:7)
Block(-5,30,-3,CONCRETE:7)
Block(-5,30,-2,DROPPER:4,NBT/skyscraper_2x2_05/1427-dropperC16R16.nbt)
Block(-5,30,-1,DROPPER:4,NBT/skyscraper_2x2_05/1428-dropperC16R16.nbt)
Block(-5,30,0,FURNACE:4,NBT/skyscraper_2x2_05/1429-furnaceC16R16.nbt)
Block(-5,30,1,FURNACE:4,NBT/skyscraper_2x2_05/1430-furnaceC16R16.nbt)
Block(-5,30,2,CAULDRON:3)
Block(-5,30,3,IRON_DOOR_BLOCK:3)
Block(-5,30,7,CONCRETE:7)
Block(-5,31,-7,CONCRETE:7)
Block(-5,31,-6,CONCRETE:7)
Block(-5,31,-5,DARK_OAK_DOOR:9)
Block(-5,31,-4,CONCRETE:7)
Block(-5,31,-3,CONCRETE:7)
Block(-5,31,-2,DROPPER:4,NBT/skyscraper_2x2_05/1431-dropperC16R16.nbt)
Block(-5,31,-1,DROPPER:4,NBT/skyscraper_2x2_05/1432-dropperC16R16.nbt)
Block(-5,31,0,IRON_TRAPDOOR:2)
Block(-5,31,1,IRON_TRAPDOOR:2)
Block(-5,31,2,TRIPWIRE_HOOK:1)
Block(-5,31,3,IRON_DOOR_BLOCK:9)
Block(-5,31,7,CONCRETE:7)
Block(-5,32,-7,CONCRETE:7)
Block(-5,32,-6,CONCRETE:7)
Block(-5,32,-5,CONCRETE:7)
Block(-5,32,-4,CONCRETE:7)
Block(-5,32,-3,CONCRETE:7)
Block(-5,32,-2,IRON_TRAPDOOR:1)
Block(-5,32,-1,IRON_TRAPDOOR:1)
Block(-5,32,0,IRON_TRAPDOOR:2)
Block(-5,32,1,IRON_TRAPDOOR:2)
Block(-5,32,2,IRON_TRAPDOOR:2)
Block(-5,32,3,IRON_TRAPDOOR:2)
Block(-5,32,7,CONCRETE:7)
Block(-5,33,-7,CONCRETE:7)
Block(-5,33,-6,CONCRETE:7)
Block(-5,33,-5,CONCRETE:7)
Block(-5,33,-4,CONCRETE:7)
Block(-5,33,-3,CONCRETE:7)
Block(-5,33,-2,CONCRETE:8)
Block(-5,33,-1,CONCRETE:8)
Block(-5,33,0,CONCRETE:8)
Block(-5,33,1,CONCRETE:8)
Block(-5,33,2,CONCRETE:8)
Block(-5,33,3,CONCRETE:8)
Block(-5,33,4,CONCRETE:8)
Block(-5,33,5,CONCRETE:8)
Block(-5,33,6,CONCRETE:8)
Block(-5,33,7,CONCRETE:7)
Block(-5,34,-7,CONCRETE:7)
Block(-5,34,-6,CONCRETE:7)
Block(-5,34,-5,DARK_OAK_DOOR:2)
Block(-5,34,-4,CONCRETE:7)
Block(-5,34,-3,CONCRETE:7)
Block(-5,34,-2,DROPPER:4,NBT/skyscraper_2x2_05/1433-dropperC16R16.nbt)
Block(-5,34,-1,DROPPER:4,NBT/skyscraper_2x2_05/1434-dropperC16R16.nbt)
Block(-5,34,0,FURNACE:4,NBT/skyscraper_2x2_05/1435-furnaceC16R16.nbt)
Block(-5,34,1,FURNACE:4,NBT/skyscraper_2x2_05/1436-furnaceC16R16.nbt)
Block(-5,34,2,CAULDRON:3)
Block(-5,34,3,IRON_DOOR_BLOCK:3)
Block(-5,34,7,CONCRETE:7)
Block(-5,35,-7,CONCRETE:7)
Block(-5,35,-6,CONCRETE:7)
Block(-5,35,-5,DARK_OAK_DOOR:9)
Block(-5,35,-4,CONCRETE:7)
Block(-5,35,-3,CONCRETE:7)
Block(-5,35,-2,DROPPER:4,NBT/skyscraper_2x2_05/1437-dropperC16R16.nbt)
Block(-5,35,-1,DROPPER:4,NBT/skyscraper_2x2_05/1438-dropperC16R16.nbt)
Block(-5,35,0,IRON_TRAPDOOR:2)
Block(-5,35,1,IRON_TRAPDOOR:2)
Block(-5,35,2,TRIPWIRE_HOOK:1)
Block(-5,35,3,IRON_DOOR_BLOCK:9)
Block(-5,35,7,CONCRETE:7)
Block(-5,36,-7,CONCRETE:7)
Block(-5,36,-6,CONCRETE:7)
Block(-5,36,-5,CONCRETE:7)
Block(-5,36,-4,CONCRETE:7)
Block(-5,36,-3,CONCRETE:7)
Block(-5,36,-2,IRON_TRAPDOOR:1)
Block(-5,36,-1,IRON_TRAPDOOR:1)
Block(-5,36,0,IRON_TRAPDOOR:2)
Block(-5,36,1,IRON_TRAPDOOR:2)
Block(-5,36,2,IRON_TRAPDOOR:2)
Block(-5,36,3,IRON_TRAPDOOR:2)
Block(-5,36,7,CONCRETE:7)
Block(-5,37,-7,CONCRETE:7)
Block(-5,37,-6,CONCRETE:7)
Block(-5,37,-5,CONCRETE:7)
Block(-5,37,-4,CONCRETE:7)
Block(-5,37,-3,CONCRETE:7)
Block(-5,37,-2,CONCRETE:8)
Block(-5,37,-1,CONCRETE:8)
Block(-5,37,0,CONCRETE:8)
Block(-5,37,1,CONCRETE:8)
Block(-5,37,2,CONCRETE:8)
Block(-5,37,3,CONCRETE:8)
Block(-5,37,4,CONCRETE:8)
Block(-5,37,5,CONCRETE:8)
Block(-5,37,6,CONCRETE:8)
Block(-5,37,7,CONCRETE:7)
Block(-5,38,-7,CONCRETE:8)
Block(-5,38,-6,CONCRETE:8)
Block(-5,38,-5,DARK_OAK_DOOR:2)
Block(-5,38,-4,CONCRETE:8)
Block(-5,38,-3,CONCRETE:7)
Block(-5,38,-2,DROPPER:4,NBT/skyscraper_2x2_05/1439-dropperC16R16.nbt)
Block(-5,38,-1,DROPPER:4,NBT/skyscraper_2x2_05/1440-dropperC16R16.nbt)
Block(-5,38,0,FURNACE:4,NBT/skyscraper_2x2_05/1441-furnaceC16R16.nbt)
Block(-5,38,1,FURNACE:4,NBT/skyscraper_2x2_05/1442-furnaceC16R16.nbt)
Block(-5,38,2,CAULDRON:3)
Block(-5,38,3,IRON_DOOR_BLOCK:3)
Block(-5,38,7,CONCRETE:8)
Block(-5,39,-7,CONCRETE:8)
Block(-5,39,-6,CONCRETE:8)
Block(-5,39,-5,DARK_OAK_DOOR:9)
Block(-5,39,-4,CONCRETE:8)
Block(-5,39,-3,CONCRETE:7)
Block(-5,39,-2,DROPPER:4,NBT/skyscraper_2x2_05/1443-dropperC16R16.nbt)
Block(-5,39,-1,DROPPER:4,NBT/skyscraper_2x2_05/1444-dropperC16R16.nbt)
Block(-5,39,0,IRON_TRAPDOOR:2)
Block(-5,39,1,IRON_TRAPDOOR:2)
Block(-5,39,2,TRIPWIRE_HOOK:1)
Block(-5,39,3,IRON_DOOR_BLOCK:9)
Block(-5,39,7,CONCRETE:8)
Block(-5,40,-7,CONCRETE:8)
Block(-5,40,-6,CONCRETE:8)
Block(-5,40,-5,CONCRETE:8)
Block(-5,40,-4,CONCRETE:8)
Block(-5,40,-3,CONCRETE:7)
Block(-5,40,-2,IRON_TRAPDOOR:1)
Block(-5,40,-1,IRON_TRAPDOOR:1)
Block(-5,40,0,IRON_TRAPDOOR:2)
Block(-5,40,1,IRON_TRAPDOOR:2)
Block(-5,40,2,IRON_TRAPDOOR:2)
Block(-5,40,3,IRON_TRAPDOOR:2)
Block(-5,40,7,CONCRETE:8)
Block(-5,41,-7,CONCRETE:8)
Block(-5,41,-6,CONCRETE:8)
Block(-5,41,-5,CONCRETE:8)
Block(-5,41,-4,CONCRETE:8)
Block(-5,41,-3,CONCRETE:7)
Block(-5,41,-2,CONCRETE:8)
Block(-5,41,-1,CONCRETE:8)
Block(-5,41,0,CONCRETE:8)
Block(-5,41,1,CONCRETE:8)
Block(-5,41,2,CONCRETE:8)
Block(-5,41,3,CONCRETE:8)
Block(-5,41,4,CONCRETE:8)
Block(-5,41,5,CONCRETE:8)
Block(-5,41,6,CONCRETE:8)
Block(-5,41,7,CONCRETE:8)
Block(-5,42,-7,CONCRETE:8)
Block(-5,42,-6,CONCRETE:8)
Block(-5,42,-5,DARK_OAK_DOOR:2)
Block(-5,42,-4,CONCRETE:8)
Block(-5,42,-3,CONCRETE:7)
Block(-5,42,-2,DROPPER:4,NBT/skyscraper_2x2_05/1445-dropperC16R16.nbt)
Block(-5,42,-1,DROPPER:4,NBT/skyscraper_2x2_05/1446-dropperC16R16.nbt)
Block(-5,42,0,FURNACE:4,NBT/skyscraper_2x2_05/1447-furnaceC16R16.nbt)
Block(-5,42,1,FURNACE:4,NBT/skyscraper_2x2_05/1448-furnaceC16R16.nbt)
Block(-5,42,2,CAULDRON:3)
Block(-5,42,3,IRON_DOOR_BLOCK:3)
Block(-5,42,7,CONCRETE:8)
Block(-5,43,-7,CONCRETE:8)
Block(-5,43,-6,CONCRETE:8)
Block(-5,43,-5,DARK_OAK_DOOR:9)
Block(-5,43,-4,CONCRETE:8)
Block(-5,43,-3,CONCRETE:7)
Block(-5,43,-2,DROPPER:4,NBT/skyscraper_2x2_05/1449-dropperC16R16.nbt)
Block(-5,43,-1,DROPPER:4,NBT/skyscraper_2x2_05/1450-dropperC16R16.nbt)
Block(-5,43,0,IRON_TRAPDOOR:2)
Block(-5,43,1,IRON_TRAPDOOR:2)
Block(-5,43,2,TRIPWIRE_HOOK:1)
Block(-5,43,3,IRON_DOOR_BLOCK:9)
Block(-5,43,7,CONCRETE:8)
Block(-5,44,-7,CONCRETE:8)
Block(-5,44,-6,CONCRETE:8)
Block(-5,44,-5,CONCRETE:8)
Block(-5,44,-4,CONCRETE:8)
Block(-5,44,-3,CONCRETE:7)
Block(-5,44,-2,IRON_TRAPDOOR:1)
Block(-5,44,-1,IRON_TRAPDOOR:1)
Block(-5,44,0,IRON_TRAPDOOR:2)
Block(-5,44,1,IRON_TRAPDOOR:2)
Block(-5,44,2,IRON_TRAPDOOR:2)
Block(-5,44,3,IRON_TRAPDOOR:2)
Block(-5,44,7,CONCRETE:8)
Block(-5,45,-7,CONCRETE:8)
Block(-5,45,-6,CONCRETE:8)
Block(-5,45,-5,CONCRETE:8)
Block(-5,45,-4,CONCRETE:8)
Block(-5,45,-3,CONCRETE:7)
Block(-5,45,-2,CONCRETE:8)
Block(-5,45,-1,CONCRETE:8)
Block(-5,45,0,CONCRETE:8)
Block(-5,45,1,CONCRETE:8)
Block(-5,45,2,CONCRETE:8)
Block(-5,45,3,CONCRETE:8)
Block(-5,45,4,CONCRETE:8)
Block(-5,45,5,CONCRETE:8)
Block(-5,45,6,CONCRETE:8)
Block(-5,45,7,CONCRETE:8)
Block(-5,46,-7,CONCRETE:8)
Block(-5,46,-6,CONCRETE:8)
Block(-5,46,-5,DARK_OAK_DOOR:2)
Block(-5,46,-4,CONCRETE:8)
Block(-5,46,-3,CONCRETE:7)
Block(-5,46,-2,DROPPER:4,NBT/skyscraper_2x2_05/1451-dropperC16R16.nbt)
Block(-5,46,-1,DROPPER:4,NBT/skyscraper_2x2_05/1452-dropperC16R16.nbt)
Block(-5,46,0,FURNACE:4,NBT/skyscraper_2x2_05/1453-furnaceC16R16.nbt)
Block(-5,46,1,FURNACE:4,NBT/skyscraper_2x2_05/1454-furnaceC16R16.nbt)
Block(-5,46,2,CAULDRON:3)
Block(-5,46,3,IRON_DOOR_BLOCK:3)
Block(-5,46,7,CONCRETE:8)
Block(-5,47,-7,CONCRETE:8)
Block(-5,47,-6,CONCRETE:8)
Block(-5,47,-5,DARK_OAK_DOOR:9)
Block(-5,47,-4,CONCRETE:8)
Block(-5,47,-3,CONCRETE:7)
Block(-5,47,-2,DROPPER:4,NBT/skyscraper_2x2_05/1455-dropperC16R16.nbt)
Block(-5,47,-1,DROPPER:4,NBT/skyscraper_2x2_05/1456-dropperC16R16.nbt)
Block(-5,47,0,IRON_TRAPDOOR:2)
Block(-5,47,1,IRON_TRAPDOOR:2)
Block(-5,47,2,TRIPWIRE_HOOK:1)
Block(-5,47,3,IRON_DOOR_BLOCK:9)
Block(-5,47,7,CONCRETE:8)
Block(-5,48,-7,CONCRETE:8)
Block(-5,48,-6,CONCRETE:8)
Block(-5,48,-5,CONCRETE:8)
Block(-5,48,-4,CONCRETE:8)
Block(-5,48,-3,CONCRETE:7)
Block(-5,48,-2,IRON_TRAPDOOR:1)
Block(-5,48,-1,IRON_TRAPDOOR:1)
Block(-5,48,0,IRON_TRAPDOOR:2)
Block(-5,48,1,IRON_TRAPDOOR:2)
Block(-5,48,2,IRON_TRAPDOOR:2)
Block(-5,48,3,IRON_TRAPDOOR:2)
Block(-5,48,7,CONCRETE:8)
Block(-5,49,-7,CONCRETE:7)
Block(-5,49,-6,CONCRETE:7)
Block(-5,49,-5,CONCRETE:7)
Block(-5,49,-4,CONCRETE:7)
Block(-5,49,-3,CONCRETE:7)
Block(-5,49,-2,CONCRETE:7)
Block(-5,49,-1,CONCRETE:7)
Block(-5,49,0,CONCRETE:7)
Block(-5,49,1,CONCRETE:7)
Block(-5,49,2,CONCRETE:7)
Block(-5,49,3,CONCRETE:7)
Block(-5,49,4,CONCRETE:7)
Block(-5,49,5,CONCRETE:7)
Block(-5,49,6,CONCRETE:7)
Block(-5,49,7,CONCRETE:7)
Block(-5,50,-7,CONCRETE:8)
Block(-5,50,-6,CONCRETE:8)
Block(-5,50,-5,DARK_OAK_DOOR:2)
Block(-5,50,-4,CONCRETE:8)
Block(-5,50,-3,CONCRETE:7)
Block(-5,50,-2,CONCRETE:7)
Block(-5,50,-1,CONCRETE:7)
Block(-5,50,0,IRON_DOOR_BLOCK:2)
Block(-5,50,1,CONCRETE:7)
Block(-5,50,2,CONCRETE:7)
Block(-5,50,3,IRON_DOOR_BLOCK:0)
Block(-5,50,6,IRON_FENCE:0)
Block(-5,50,7,SMOOTH_STAIRS:7)
Block(-5,51,-7,CONCRETE:8)
Block(-5,51,-6,CONCRETE:8)
Block(-5,51,-5,DARK_OAK_DOOR:9)
Block(-5,51,-4,CONCRETE:8)
Block(-5,51,-3,CONCRETE:7)
Block(-5,51,-2,CONCRETE:7)
Block(-5,51,-1,CONCRETE:7)
Block(-5,51,0,IRON_DOOR_BLOCK:9)
Block(-5,51,1,CONCRETE:7)
Block(-5,51,2,CONCRETE:7)
Block(-5,51,3,IRON_DOOR_BLOCK:8)
Block(-5,51,6,IRON_FENCE:0)
Block(-5,51,7,SMOOTH_STAIRS:7)
Block(-5,52,-7,CONCRETE:8)
Block(-5,52,-6,CONCRETE:8)
Block(-5,52,-5,CONCRETE:8)
Block(-5,52,-4,CONCRETE:8)
Block(-5,52,-3,CONCRETE:7)
Block(-5,52,-2,CONCRETE:7)
Block(-5,52,-1,CONCRETE:7)
Block(-5,52,0,CONCRETE:7)
Block(-5,52,1,CONCRETE:7)
Block(-5,52,2,CONCRETE:7)
Block(-5,52,3,STEP:8)
Block(-5,52,4,STEP:8)
Block(-5,52,5,CONCRETE:12)
Block(-5,52,6,IRON_FENCE:0)
Block(-5,52,7,SMOOTH_STAIRS:7)
Block(-5,53,-7,CONCRETE:7)
Block(-5,53,-6,CONCRETE:7)
Block(-5,53,-5,CONCRETE:7)
Block(-5,53,-4,CONCRETE:7)
Block(-5,53,-3,CONCRETE:7)
Block(-5,53,-2,CONCRETE:7)
Block(-5,53,-1,CONCRETE:7)
Block(-5,53,0,CONCRETE:7)
Block(-5,53,1,CONCRETE:7)
Block(-5,53,2,DOUBLE_STEP:0)
Block(-5,53,3,DOUBLE_STEP:0)
Block(-5,53,4,DOUBLE_STEP:0)
Block(-5,53,5,DOUBLE_STEP:0)
Block(-5,53,6,CONCRETE:7)
Block(-5,53,7,CONCRETE:7)
Block(-5,54,-7,CONCRETE:8)
Block(-5,54,-6,CONCRETE:8)
Block(-5,54,-5,DARK_OAK_DOOR:2)
Block(-5,54,-4,CONCRETE:8)
Block(-5,54,-3,CONCRETE:8)
Block(-5,54,0,IRON_FENCE:0)
Block(-5,54,7,IRON_FENCE:0)
Block(-5,55,-7,CONCRETE:8)
Block(-5,55,-6,CONCRETE:8)
Block(-5,55,-5,DARK_OAK_DOOR:9)
Block(-5,55,-4,CONCRETE:8)
Block(-5,55,-3,CONCRETE:8)
Block(-5,55,-2,IRON_TRAPDOOR:1)
Block(-5,55,-1,IRON_TRAPDOOR:1)
Block(-5,55,0,IRON_TRAPDOOR:1)
Block(-5,56,-7,CONCRETE:8)
Block(-5,56,-6,CONCRETE:8)
Block(-5,56,-5,CONCRETE:8)
Block(-5,56,-4,CONCRETE:8)
Block(-5,56,-3,CONCRETE:8)
Block(-5,57,-7,CONCRETE:8)
Block(-5,57,-6,CONCRETE:8)
Block(-5,57,-5,CONCRETE:8)
Block(-5,57,-4,CONCRETE:8)
Block(-5,57,-3,CONCRETE:8)
Block(-5,58,-7,CONCRETE:8)
Block(-5,58,-6,CONCRETE:8)
Block(-5,58,-5,DARK_OAK_DOOR:2)
Block(-5,58,-4,CONCRETE:8)
Block(-5,58,-3,CONCRETE:8)
Block(-5,59,-7,CONCRETE:8)
Block(-5,59,-6,CONCRETE:8)
Block(-5,59,-5,DARK_OAK_DOOR:9)
Block(-5,59,-4,CONCRETE:8)
Block(-5,59,-3,CONCRETE:8)
Block(-5,60,-7,CONCRETE:8)
Block(-5,60,-6,CONCRETE:8)
Block(-5,60,-5,CONCRETE:8)
Block(-5,60,-4,CONCRETE:8)
Block(-5,60,-3,CONCRETE:8)
Block(-5,61,-7,CONCRETE:8)
Block(-5,61,-6,CONCRETE:8)
Block(-5,61,-5,CONCRETE:8)
Block(-5,61,-4,CONCRETE:8)
Block(-5,61,-3,CONCRETE:8)
Block(-5,62,-7,CONCRETE:8)
