
#######################################################################
# +-----------------------------------------------------------------+ #
# |                            BO4 object                           | #
# +-----------------------------------------------------------------+ #
#######################################################################

Author: NLBlackEagle

Description: No description given

SettingsMode: WriteDisable


#######################################################################
# +-----------------------------------------------------------------+ #
# |                          Main settings                          | #
# +-----------------------------------------------------------------+ #
#######################################################################

Frequency: 0

SpawnHeight: highestBlock

UseCenterForHighestBlock: true

##############################
# Height Limits for the BO4. #
##############################

MinHeight: 0

MaxHeight: 255

InheritBO3: 

InheritBO3Rotation: NORTH

OverrideChildSettings: true

OverrideParentHeight: false

CanOverride: true

BranchFrequency: 0

BranchFrequencyGroup: 

MustBeBelowOther: false

MustBeInside: 

CannotBeInside: 

ReplacesBO3: L4-M-CrossC0R0, L4-M-CrossC0R1, L4-M-CrossC0R2, L4-M-CrossC0R3, L4-M-CrossC1R0, L4-M-CrossC1R1, L4-M-CrossC1R2, L4-M-CrossC1R3, L4-M-CrossC2R0, L4-M-CrossC2R1, L4-M-CrossC2R2, L4-M-CrossC2R3, L4-M-CrossC3R0, L4-M-CrossC3R1, L4-M-CrossC3R2, L4-M-CrossC3R3, L4-M-Straigth-START_01-C0R0, L4-M-Straigth-START_01-C0R1, L4-M-Straigth-START_01-C1R0, L4-M-Straigth-START_01-C1R1, L4-M-Straigth-START_01-C2R0, L4-M-Straigth-START_01-C2R1, L4-M-Straigth-START_01-C3R0, L4-M-Straigth-START_01-C3R1, L4-M-Straigth-3CC0R0, L4-M-Straigth-3CC0R1, L4-M-Straigth-3CC0R2, L4-M-Straigth-3CC1R0, L4-M-Straigth-3CC1R1, L4-M-Straigth-3CC1R2, L4-M-Straigth-3CC2R0, L4-M-Straigth-3CC2R1, L4-M-Straigth-3CC2R2, L4-M-Straigth-3CC3R0, L4-M-Straigth-3CC3R1, L4-M-Straigth-3CC3R2, L4-M-Cross, skyscraper_2x2_01, skyscraper_2x2_02, skyscraper_2x2_03, skyscraper_2x2_04, skyscraper_2x2_05, skyscraper_3x3_01, skyscraper_3x3_02, skyscraper_3x3_03, L3-M-Straigth-2CC0R0, L3-M-Straigth-2CC0R1, L3-M-Straigth-2CC1R0, L3-M-Straigth-2CC1R1, L3-M-Straigth-2CC2R0, L3-M-Straigth-2CC2R1, L3-M-Straigth-2CC3R0, L3-M-Straigth-2CC3R1, L3-M-Straigth-3CC0R0, L3-M-Straigth-3CC0R1, L3-M-Straigth-3CC0R2, L3-M-Straigth-3CC1R0, L3-M-Straigth-3CC1R1, L3-M-Straigth-3CC1R2, L3-M-Straigth-3CC2R0, L3-M-Straigth-3CC2R1, L3-M-Straigth-3CC2R2, L3-M-Straigth-3CC3R0, L3-M-Straigth-3CC3R1, L3-M-Straigth-3CC3R2L4-M-CrossC0R0, L4-M-CrossC0R1, L4-M-CrossC0R2, L4-M-CrossC0R3, L4-M-CrossC1R0, L4-M-CrossC1R1, L4-M-CrossC1R2, L4-M-CrossC1R3, L4-M-CrossC2R0, L4-M-CrossC2R1, L4-M-CrossC2R2, L4-M-CrossC2R3, L4-M-CrossC3R0, L4-M-CrossC3R1, L4-M-CrossC3R2, L4-M-CrossC3R3, L4-M-Straigth-START_01-C0R0, L4-M-Straigth-START_01-C0R1, L4-M-Straigth-START_01-C1R0, L4-M-Straigth-START_01-C1R1, L4-M-Straigth-START_01-C2R0, L4-M-Straigth-START_01-C2R1, L4-M-Straigth-START_01-C3R0, L4-M-Straigth-START_01-C3R1, L4-M-Straigth-3CC0R0, L4-M-Straigth-3CC0R1, L4-M-Straigth-3CC0R2, L4-M-Straigth-3CC1R0, L4-M-Straigth-3CC1R1, L4-M-Straigth-3CC1R2, L4-M-Straigth-3CC2R0, L4-M-Straigth-3CC2R1, L4-M-Straigth-3CC2R2, L4-M-Straigth-3CC3R0, L4-M-Straigth-3CC3R1, L4-M-Straigth-3CC3R2, L4-M-Cross, skyscraper_2x2_01, skyscraper_2x2_02, skyscraper_2x2_03, skyscraper_2x2_04, skyscraper_2x2_05, skyscraper_3x3_01, skyscraper_3x3_02, skyscraper_3x3_03

MustBeInsideWorldBorders: false

CanSpawnOnWater: true

SpawnOnWaterOnly: false

SpawnUnderWater: false

SpawnAtWaterLevel: false

HeightOffset: 0

RemoveAir: false

ReplaceAbove: 

ReplaceBelow: 

ReplaceWithBiomeBlocks: true

ReplaceWithSurfaceBlock: GRASS

ReplaceWithGroundBlock: DIRT

ReplaceWithStoneBlock: STONE

SmoothRadius: 0

SmoothHeightOffset: 0

SmoothStartTop: false

SmoothStartWood: false

SmoothingSurfaceBlock: 

SmoothingGroundBlock: 

BO3Group: 

IsSpawnPoint: false

DoReplaceBlocks: true


#######################################################################
# +-----------------------------------------------------------------+ #
# |                              Blocks                             | #
# +-----------------------------------------------------------------+ #
#######################################################################

Block(-8,0,-7,CONCRETE:7)
Block(-8,0,-6,CONCRETE:7)
Block(-8,0,-5,CONCRETE:7)
Block(-8,0,-4,CONCRETE:7)
Block(-8,0,-3,CONCRETE:7)
Block(-8,0,-2,CONCRETE:7)
Block(-8,0,-1,CONCRETE:7)
Block(-8,0,0,CONCRETE:7)
Block(-8,0,1,CONCRETE:7)
Block(-8,0,2,CONCRETE:7)
Block(-8,0,3,CONCRETE:7)
Block(-8,0,4,CONCRETE:7)
Block(-8,0,5,CONCRETE:7)
Block(-8,0,6,CONCRETE:7)
Block(-8,0,7,CONCRETE:7)
Block(-8,0,8,CONCRETE:7)
Block(-8,1,-7,CONCRETE:7)
Block(-8,1,-6,CONCRETE:7)
Block(-8,1,-5,CONCRETE:7)
Block(-8,1,-4,CONCRETE:7)
Block(-8,1,-3,CONCRETE:7)
Block(-8,1,-2,CONCRETE:7)
Block(-8,1,-1,CONCRETE:7)
Block(-8,1,0,CONCRETE:7)
Block(-8,1,1,CONCRETE:7)
Block(-8,1,2,CONCRETE:7)
Block(-8,1,3,CONCRETE:7)
Block(-8,1,4,CONCRETE:7)
Block(-8,1,5,CONCRETE:7)
Block(-8,1,6,CONCRETE:7)
Block(-8,1,7,CONCRETE:7)
Block(-8,1,8,CONCRETE:7)
Block(-8,2,-7,CONCRETE:7)
Block(-8,2,-6,CONCRETE:7)
Block(-8,2,-5,CONCRETE:7)
Block(-8,2,-4,CONCRETE:7)
Block(-8,2,-3,CONCRETE:7)
Block(-8,2,-2,CONCRETE:7)
Block(-8,2,-1,CONCRETE:7)
Block(-8,2,0,CONCRETE:7)
Block(-8,2,1,CONCRETE:7)
Block(-8,2,2,CONCRETE:7)
Block(-8,2,3,CONCRETE:7)
Block(-8,2,4,CONCRETE:7)
Block(-8,2,5,CONCRETE:7)
Block(-8,2,6,CONCRETE:7)
Block(-8,2,7,CONCRETE:7)
Block(-8,2,8,CONCRETE:7)
Block(-8,3,-7,CONCRETE:7)
Block(-8,3,-6,CONCRETE:7)
Block(-8,3,-5,CONCRETE:7)
Block(-8,3,-4,CONCRETE:7)
Block(-8,3,-3,CONCRETE:7)
Block(-8,3,-2,CONCRETE:7)
Block(-8,3,-1,CONCRETE:7)
Block(-8,3,0,CONCRETE:7)
Block(-8,3,1,CONCRETE:7)
Block(-8,3,2,CONCRETE:7)
Block(-8,3,3,CONCRETE:7)
Block(-8,3,4,CONCRETE:7)
Block(-8,3,5,CONCRETE:7)
Block(-8,3,6,CONCRETE:7)
Block(-8,3,7,CONCRETE:7)
Block(-8,3,8,CONCRETE:7)
Block(-8,4,-7,CONCRETE:7)
Block(-8,4,-6,CONCRETE:7)
Block(-8,4,-5,CONCRETE:7)
Block(-8,4,-4,CONCRETE:7)
Block(-8,4,-3,CONCRETE:7)
Block(-8,4,-2,CONCRETE:7)
Block(-8,4,-1,CONCRETE:7)
Block(-8,4,0,CONCRETE:7)
Block(-8,4,1,CONCRETE:7)
Block(-8,4,2,CONCRETE:7)
Block(-8,4,3,CONCRETE:7)
Block(-8,4,4,CONCRETE:7)
Block(-8,4,5,CONCRETE:7)
Block(-8,4,6,CONCRETE:7)
Block(-8,4,7,CONCRETE:7)
Block(-8,4,8,CONCRETE:7)
Block(-8,5,-7,CONCRETE:7)
Block(-8,5,-6,CONCRETE:7)
Block(-8,5,-5,CONCRETE:7)
Block(-8,5,-4,CONCRETE:7)
Block(-8,5,-3,CONCRETE:7)
Block(-8,5,-2,CONCRETE:7)
Block(-8,5,-1,CONCRETE:7)
Block(-8,5,0,CONCRETE:7)
Block(-8,5,1,CONCRETE:7)
Block(-8,5,2,CONCRETE:7)
Block(-8,5,3,CONCRETE:7)
Block(-8,5,4,CONCRETE:7)
Block(-8,5,5,CONCRETE:7)
Block(-8,5,6,CONCRETE:7)
Block(-8,5,7,CONCRETE:7)
Block(-8,5,8,CONCRETE:7)
Block(-8,6,-7,CONCRETE:7)
Block(-8,6,-6,CONCRETE:7)
Block(-8,6,-5,CONCRETE:7)
Block(-8,6,-4,CONCRETE:7)
Block(-8,6,-3,CONCRETE:7)
Block(-8,6,-2,CONCRETE:7)
Block(-8,6,-1,CONCRETE:7)
Block(-8,6,0,CONCRETE:7)
Block(-8,6,1,CONCRETE:7)
Block(-8,6,2,CONCRETE:7)
Block(-8,6,3,CONCRETE:7)
Block(-8,6,4,CONCRETE:7)
Block(-8,6,5,CONCRETE:7)
Block(-8,6,6,CONCRETE:7)
Block(-8,6,7,CONCRETE:7)
Block(-8,6,8,CONCRETE:7)
Block(-8,7,-7,CONCRETE:7)
Block(-8,7,-6,CONCRETE:7)
Block(-8,7,-5,CONCRETE:7)
Block(-8,7,-4,CONCRETE:7)
Block(-8,7,-3,CONCRETE:7)
Block(-8,7,-2,CONCRETE:7)
Block(-8,7,-1,CONCRETE:7)
Block(-8,7,0,CONCRETE:7)
Block(-8,7,1,CONCRETE:7)
Block(-8,7,2,CONCRETE:7)
Block(-8,7,3,CONCRETE:7)
Block(-8,7,4,CONCRETE:7)
Block(-8,7,5,CONCRETE:7)
Block(-8,7,6,CONCRETE:7)
Block(-8,7,7,CONCRETE:7)
Block(-8,7,8,CONCRETE:7)
Block(-8,8,-7,CONCRETE:7)
Block(-8,8,-6,CONCRETE:7)
Block(-8,8,-5,CONCRETE:7)
Block(-8,8,-4,CONCRETE:7)
Block(-8,8,-3,CONCRETE:7)
Block(-8,8,-2,CONCRETE:7)
Block(-8,8,-1,CONCRETE:7)
Block(-8,8,0,CONCRETE:7)
Block(-8,8,1,CONCRETE:7)
Block(-8,8,2,CONCRETE:7)
Block(-8,8,3,CONCRETE:7)
Block(-8,8,4,CONCRETE:7)
Block(-8,8,5,CONCRETE:7)
Block(-8,8,6,CONCRETE:7)
Block(-8,8,7,CONCRETE:7)
Block(-8,8,8,CONCRETE:7)
Block(-8,9,-7,CONCRETE:7)
Block(-8,9,-6,CONCRETE:7)
Block(-8,9,-5,CONCRETE:7)
Block(-8,9,-4,CONCRETE:7)
Block(-8,9,-3,CONCRETE:7)
Block(-8,9,-2,CONCRETE:7)
Block(-8,9,-1,CONCRETE:7)
Block(-8,9,0,CONCRETE:7)
Block(-8,9,1,CONCRETE:7)
Block(-8,9,2,CONCRETE:7)
Block(-8,9,3,CONCRETE:7)
Block(-8,9,4,CONCRETE:7)
Block(-8,9,5,CONCRETE:7)
Block(-8,9,6,CONCRETE:7)
Block(-8,9,7,CONCRETE:7)
Block(-8,9,8,CONCRETE:7)
Block(-8,10,-7,CONCRETE:7)
Block(-8,10,-6,CONCRETE:7)
Block(-8,10,-5,CONCRETE:7)
Block(-8,10,-4,CONCRETE:7)
Block(-8,10,-3,CONCRETE:7)
Block(-8,10,-2,CONCRETE:7)
Block(-8,10,-1,CONCRETE:7)
Block(-8,10,0,CONCRETE:7)
Block(-8,10,1,CONCRETE:7)
Block(-8,10,2,CONCRETE:7)
Block(-8,10,3,CONCRETE:7)
Block(-8,10,4,CONCRETE:7)
Block(-8,10,5,CONCRETE:7)
Block(-8,10,6,CONCRETE:7)
Block(-8,10,7,CONCRETE:7)
Block(-8,10,8,CONCRETE:7)
Block(-8,11,-7,CONCRETE:7)
Block(-8,11,-6,CONCRETE:7)
Block(-8,11,-5,CONCRETE:7)
Block(-8,11,-4,CONCRETE:7)
Block(-8,11,-3,CONCRETE:7)
Block(-8,11,-2,CONCRETE:7)
Block(-8,11,-1,CONCRETE:7)
Block(-8,11,0,CONCRETE:7)
Block(-8,11,1,CONCRETE:7)
Block(-8,11,2,CONCRETE:7)
Block(-8,11,3,CONCRETE:7)
Block(-8,11,4,CONCRETE:7)
Block(-8,11,5,CONCRETE:7)
Block(-8,11,6,CONCRETE:7)
Block(-8,11,7,CONCRETE:7)
Block(-8,11,8,CONCRETE:7)
Block(-8,12,-7,CONCRETE:7)
Block(-8,12,-6,CONCRETE:7)
Block(-8,12,-5,CONCRETE:7)
Block(-8,12,-4,CONCRETE:7)
Block(-8,12,-3,CONCRETE:7)
Block(-8,12,-2,CONCRETE:7)
Block(-8,12,-1,CONCRETE:7)
Block(-8,12,0,CONCRETE:7)
Block(-8,12,1,CONCRETE:7)
Block(-8,12,2,CONCRETE:7)
Block(-8,12,3,CONCRETE:7)
Block(-8,12,4,CONCRETE:7)
Block(-8,12,5,CONCRETE:7)
Block(-8,12,6,CONCRETE:7)
Block(-8,12,7,CONCRETE:7)
Block(-8,12,8,CONCRETE:7)
Block(-8,13,-7,CONCRETE:7)
Block(-8,13,-6,CONCRETE:7)
Block(-8,13,-5,CONCRETE:7)
Block(-8,13,-4,CONCRETE:7)
Block(-8,13,-3,CONCRETE:7)
Block(-8,13,-2,CONCRETE:7)
Block(-8,13,-1,CONCRETE:7)
Block(-8,13,0,CONCRETE:7)
Block(-8,13,1,CONCRETE:7)
Block(-8,13,2,CONCRETE:7)
Block(-8,13,3,CONCRETE:7)
Block(-8,13,4,CONCRETE:7)
Block(-8,13,5,CONCRETE:7)
Block(-8,13,6,CONCRETE:7)
Block(-8,13,7,CONCRETE:7)
Block(-8,13,8,CONCRETE:7)
Block(-8,14,-7,CONCRETE:7)
Block(-8,14,-6,CONCRETE:7)
Block(-8,14,-5,CONCRETE:7)
Block(-8,14,-4,CONCRETE:7)
Block(-8,14,-3,CONCRETE:7)
Block(-8,14,-2,CONCRETE:7)
Block(-8,14,-1,CONCRETE:7)
Block(-8,14,0,CONCRETE:7)
Block(-8,14,1,CONCRETE:7)
Block(-8,14,2,CONCRETE:7)
Block(-8,14,3,CONCRETE:7)
Block(-8,14,4,CONCRETE:7)
Block(-8,14,5,CONCRETE:7)
Block(-8,14,6,CONCRETE:7)
Block(-8,14,7,CONCRETE:7)
Block(-8,14,8,CONCRETE:7)
Block(-8,15,-7,CONCRETE:7)
Block(-8,15,-6,CONCRETE:7)
Block(-8,15,-5,CONCRETE:7)
Block(-8,15,-4,CONCRETE:7)
Block(-8,15,-3,CONCRETE:7)
Block(-8,15,-2,CONCRETE:7)
Block(-8,15,-1,CONCRETE:7)
Block(-8,15,0,CONCRETE:7)
Block(-8,15,1,CONCRETE:7)
Block(-8,15,2,CONCRETE:7)
Block(-8,15,3,CONCRETE:7)
Block(-8,15,4,CONCRETE:7)
Block(-8,15,5,CONCRETE:7)
Block(-8,15,6,CONCRETE:7)
Block(-8,15,7,CONCRETE:7)
Block(-8,15,8,CONCRETE:7)
Block(-8,16,-7,CONCRETE:7)
Block(-8,16,-6,CONCRETE:7)
Block(-8,16,-5,CONCRETE:7)
Block(-8,16,-4,CONCRETE:7)
Block(-8,16,-3,CONCRETE:7)
Block(-8,16,-2,CONCRETE:7)
Block(-8,16,-1,CONCRETE:7)
Block(-8,16,0,CONCRETE:7)
Block(-8,16,1,CONCRETE:7)
Block(-8,16,2,CONCRETE:7)
Block(-8,16,3,CONCRETE:7)
Block(-8,16,4,CONCRETE:7)
Block(-8,16,5,CONCRETE:7)
Block(-8,16,6,CONCRETE:7)
Block(-8,16,7,CONCRETE:7)
Block(-8,16,8,CONCRETE:7)
Block(-8,17,-7,CONCRETE:7)
Block(-8,17,-6,CONCRETE:7)
Block(-8,17,-5,CONCRETE:7)
Block(-8,17,-4,CONCRETE:7)
Block(-8,17,-3,CONCRETE:7)
Block(-8,17,-2,CONCRETE:7)
Block(-8,17,-1,CONCRETE:7)
Block(-8,17,0,CONCRETE:7)
Block(-8,17,1,CONCRETE:7)
Block(-8,17,2,CONCRETE:7)
Block(-8,17,3,CONCRETE:7)
Block(-8,17,4,CONCRETE:7)
Block(-8,17,5,CONCRETE:7)
Block(-8,17,6,CONCRETE:7)
Block(-8,17,7,CONCRETE:7)
Block(-8,17,8,CONCRETE:7)
Block(-8,18,-3,CONCRETE:7)
Block(-8,18,-2,STAINED_GLASS:15)
Block(-8,18,-1,CONCRETE:7)
Block(-8,18,0,STAINED_GLASS:15)
Block(-8,18,1,CONCRETE:7)
Block(-8,18,4,CONCRETE:7)
Block(-8,18,5,STAINED_GLASS:15)
Block(-8,18,6,CONCRETE:7)
Block(-8,18,7,STAINED_GLASS:15)
Block(-8,18,8,CONCRETE:7)
Block(-8,19,-3,CONCRETE:7)
Block(-8,19,-2,STAINED_GLASS:15)
Block(-8,19,-1,CONCRETE:7)
Block(-8,19,0,STAINED_GLASS:15)
Block(-8,19,1,CONCRETE:7)
Block(-8,19,4,CONCRETE:7)
Block(-8,19,5,STAINED_GLASS:15)
Block(-8,19,6,CONCRETE:7)
Block(-8,19,7,STAINED_GLASS:15)
Block(-8,19,8,CONCRETE:7)
Block(-8,20,-3,CONCRETE:7)
Block(-8,20,-2,STAINED_GLASS:15)
Block(-8,20,-1,CONCRETE:7)
Block(-8,20,0,STAINED_GLASS:15)
Block(-8,20,1,CONCRETE:7)
Block(-8,20,4,CONCRETE:7)
Block(-8,20,5,STAINED_GLASS:15)
Block(-8,20,6,CONCRETE:7)
Block(-8,20,7,STAINED_GLASS:15)
Block(-8,20,8,CONCRETE:7)
Block(-8,21,-3,CONCRETE:7)
Block(-8,21,-2,STAINED_GLASS:15)
Block(-8,21,-1,CONCRETE:7)
Block(-8,21,0,STAINED_GLASS:15)
Block(-8,21,1,CONCRETE:7)
Block(-8,21,4,CONCRETE:7)
Block(-8,21,5,STAINED_GLASS:15)
Block(-8,21,6,CONCRETE:7)
Block(-8,21,7,STAINED_GLASS:15)
Block(-8,21,8,CONCRETE:7)
Block(-8,22,-3,CONCRETE:7)
Block(-8,22,-2,STAINED_GLASS:15)
Block(-8,22,-1,CONCRETE:7)
Block(-8,22,0,STAINED_GLASS:15)
Block(-8,22,1,CONCRETE:7)
Block(-8,22,4,CONCRETE:7)
Block(-8,22,5,STAINED_GLASS:15)
Block(-8,22,6,CONCRETE:7)
Block(-8,22,7,STAINED_GLASS:15)
Block(-8,22,8,CONCRETE:7)
Block(-8,23,-3,CONCRETE:7)
Block(-8,23,-2,STAINED_GLASS:15)
Block(-8,23,-1,CONCRETE:7)
Block(-8,23,0,STAINED_GLASS:15)
Block(-8,23,1,CONCRETE:7)
Block(-8,23,4,CONCRETE:7)
Block(-8,23,5,STAINED_GLASS:15)
Block(-8,23,6,CONCRETE:7)
Block(-8,23,7,STAINED_GLASS:15)
Block(-8,23,8,CONCRETE:7)
Block(-8,24,-3,CONCRETE:7)
Block(-8,24,-2,STAINED_GLASS:15)
Block(-8,24,-1,CONCRETE:7)
Block(-8,24,0,STAINED_GLASS:15)
Block(-8,24,1,CONCRETE:7)
Block(-8,24,4,CONCRETE:7)
Block(-8,24,5,STAINED_GLASS:15)
Block(-8,24,6,CONCRETE:7)
Block(-8,24,7,STAINED_GLASS:15)
Block(-8,24,8,CONCRETE:7)
Block(-8,25,-3,CONCRETE:7)
Block(-8,25,-2,STAINED_GLASS:15)
Block(-8,25,-1,CONCRETE:7)
Block(-8,25,0,STAINED_GLASS:15)
Block(-8,25,1,CONCRETE:7)
Block(-8,25,4,CONCRETE:7)
Block(-8,25,5,STAINED_GLASS:15)
Block(-8,25,6,CONCRETE:7)
Block(-8,25,7,STAINED_GLASS:15)
Block(-8,25,8,CONCRETE:7)
Block(-8,26,-3,CONCRETE:7)
Block(-8,26,-2,STAINED_GLASS:15)
Block(-8,26,-1,CONCRETE:7)
Block(-8,26,0,STAINED_GLASS:15)
Block(-8,26,1,CONCRETE:7)
Block(-8,26,4,CONCRETE:7)
Block(-8,26,5,STAINED_GLASS:15)
Block(-8,26,6,CONCRETE:7)
Block(-8,26,7,STAINED_GLASS:15)
Block(-8,26,8,CONCRETE:7)
Block(-8,27,-3,CONCRETE:7)
Block(-8,27,-2,STAINED_GLASS:15)
Block(-8,27,-1,CONCRETE:7)
Block(-8,27,0,STAINED_GLASS:15)
Block(-8,27,1,CONCRETE:7)
Block(-8,27,4,CONCRETE:7)
Block(-8,27,5,STAINED_GLASS:15)
Block(-8,27,6,CONCRETE:7)
Block(-8,27,7,STAINED_GLASS:15)
Block(-8,27,8,CONCRETE:7)
Block(-8,28,-3,CONCRETE:7)
Block(-8,28,-2,STAINED_GLASS:15)
Block(-8,28,-1,CONCRETE:7)
Block(-8,28,0,STAINED_GLASS:15)
Block(-8,28,1,CONCRETE:7)
Block(-8,28,4,CONCRETE:7)
Block(-8,28,5,STAINED_GLASS:15)
Block(-8,28,6,CONCRETE:7)
Block(-8,28,7,STAINED_GLASS:15)
Block(-8,28,8,CONCRETE:7)
Block(-8,29,-3,CONCRETE:7)
Block(-8,29,-2,STAINED_GLASS:15)
Block(-8,29,-1,CONCRETE:7)
Block(-8,29,0,STAINED_GLASS:15)
Block(-8,29,1,CONCRETE:7)
Block(-8,29,4,CONCRETE:7)
Block(-8,29,5,STAINED_GLASS:15)
Block(-8,29,6,CONCRETE:7)
Block(-8,29,7,STAINED_GLASS:15)
Block(-8,29,8,CONCRETE:7)
Block(-8,30,-3,CONCRETE:7)
Block(-8,30,-2,STAINED_GLASS:15)
Block(-8,30,-1,CONCRETE:7)
Block(-8,30,0,STAINED_GLASS:15)
Block(-8,30,1,CONCRETE:7)
Block(-8,30,4,CONCRETE:7)
Block(-8,30,5,STAINED_GLASS:15)
Block(-8,30,6,CONCRETE:7)
Block(-8,30,7,STAINED_GLASS:15)
Block(-8,30,8,CONCRETE:7)
Block(-8,31,-3,CONCRETE:7)
Block(-8,31,-2,STAINED_GLASS:15)
Block(-8,31,-1,CONCRETE:7)
Block(-8,31,0,STAINED_GLASS:15)
Block(-8,31,1,CONCRETE:7)
Block(-8,31,4,CONCRETE:7)
Block(-8,31,5,STAINED_GLASS:15)
Block(-8,31,6,CONCRETE:7)
Block(-8,31,7,STAINED_GLASS:15)
Block(-8,31,8,CONCRETE:7)
Block(-8,32,-3,CONCRETE:7)
Block(-8,32,-2,STAINED_GLASS:15)
Block(-8,32,-1,CONCRETE:7)
Block(-8,32,0,STAINED_GLASS:15)
Block(-8,32,1,CONCRETE:7)
Block(-8,32,4,CONCRETE:7)
Block(-8,32,5,STAINED_GLASS:15)
Block(-8,32,6,CONCRETE:7)
Block(-8,32,7,STAINED_GLASS:15)
Block(-8,32,8,CONCRETE:7)
Block(-8,33,-3,CONCRETE:7)
Block(-8,33,-2,STAINED_GLASS:15)
Block(-8,33,-1,CONCRETE:7)
Block(-8,33,0,STAINED_GLASS:15)
Block(-8,33,1,CONCRETE:7)
Block(-8,33,4,CONCRETE:7)
Block(-8,33,5,STAINED_GLASS:15)
Block(-8,33,6,CONCRETE:7)
Block(-8,33,7,STAINED_GLASS:15)
Block(-8,33,8,CONCRETE:7)
Block(-8,34,-3,CONCRETE:7)
Block(-8,34,-2,STAINED_GLASS:15)
Block(-8,34,-1,CONCRETE:7)
Block(-8,34,0,STAINED_GLASS:15)
Block(-8,34,1,CONCRETE:7)
Block(-8,34,4,CONCRETE:7)
Block(-8,34,5,STAINED_GLASS:15)
Block(-8,34,6,CONCRETE:7)
Block(-8,34,7,STAINED_GLASS:15)
Block(-8,34,8,CONCRETE:7)
Block(-8,35,-3,CONCRETE:7)
Block(-8,35,-2,STAINED_GLASS:15)
Block(-8,35,-1,CONCRETE:7)
Block(-8,35,0,STAINED_GLASS:15)
Block(-8,35,1,CONCRETE:7)
Block(-8,35,4,CONCRETE:7)
Block(-8,35,5,STAINED_GLASS:15)
Block(-8,35,6,CONCRETE:7)
Block(-8,35,7,STAINED_GLASS:15)
Block(-8,35,8,CONCRETE:7)
Block(-8,36,-3,CONCRETE:7)
Block(-8,36,-2,STAINED_GLASS:15)
Block(-8,36,-1,CONCRETE:7)
Block(-8,36,0,STAINED_GLASS:15)
Block(-8,36,1,CONCRETE:7)
Block(-8,36,4,CONCRETE:7)
Block(-8,36,5,STAINED_GLASS:15)
Block(-8,36,6,CONCRETE:7)
Block(-8,36,7,STAINED_GLASS:15)
Block(-8,36,8,CONCRETE:7)
Block(-8,37,-3,CONCRETE:7)
Block(-8,37,-2,STAINED_GLASS:15)
Block(-8,37,-1,CONCRETE:7)
Block(-8,37,0,STAINED_GLASS:15)
Block(-8,37,1,CONCRETE:7)
Block(-8,37,4,CONCRETE:7)
Block(-8,37,5,STAINED_GLASS:15)
Block(-8,37,6,CONCRETE:7)
Block(-8,37,7,STAINED_GLASS:15)
Block(-8,37,8,CONCRETE:7)
Block(-8,38,-3,CONCRETE:7)
Block(-8,38,-2,STAINED_GLASS:15)
Block(-8,38,-1,CONCRETE:7)
Block(-8,38,0,STAINED_GLASS:15)
Block(-8,38,1,CONCRETE:7)
Block(-8,38,4,CONCRETE:7)
Block(-8,38,5,STAINED_GLASS:15)
Block(-8,38,6,CONCRETE:7)
Block(-8,38,7,STAINED_GLASS:15)
Block(-8,38,8,CONCRETE:7)
Block(-8,39,-3,CONCRETE:7)
Block(-8,39,-2,STAINED_GLASS:15)
Block(-8,39,-1,CONCRETE:7)
Block(-8,39,0,STAINED_GLASS:15)
Block(-8,39,1,CONCRETE:7)
Block(-8,39,4,CONCRETE:7)
Block(-8,39,5,STAINED_GLASS:15)
Block(-8,39,6,CONCRETE:7)
Block(-8,39,7,STAINED_GLASS:15)
Block(-8,39,8,CONCRETE:7)
Block(-8,40,-3,CONCRETE:7)
Block(-8,40,-2,STAINED_GLASS:15)
Block(-8,40,-1,CONCRETE:7)
Block(-8,40,0,STAINED_GLASS:15)
Block(-8,40,1,CONCRETE:7)
Block(-8,40,4,CONCRETE:7)
Block(-8,40,5,STAINED_GLASS:15)
Block(-8,40,6,CONCRETE:7)
Block(-8,40,7,STAINED_GLASS:15)
Block(-8,40,8,CONCRETE:7)
Block(-8,41,-3,CONCRETE:7)
Block(-8,41,-2,STAINED_GLASS:15)
Block(-8,41,-1,CONCRETE:7)
Block(-8,41,0,STAINED_GLASS:15)
Block(-8,41,1,CONCRETE:7)
Block(-8,41,4,CONCRETE:7)
Block(-8,41,5,STAINED_GLASS:15)
Block(-8,41,6,CONCRETE:7)
Block(-8,41,7,STAINED_GLASS:15)
Block(-8,41,8,CONCRETE:7)
Block(-8,42,-3,CONCRETE:7)
Block(-8,42,-2,STAINED_GLASS:15)
Block(-8,42,-1,CONCRETE:7)
Block(-8,42,0,STAINED_GLASS:15)
Block(-8,42,1,CONCRETE:7)
Block(-8,42,4,CONCRETE:7)
Block(-8,42,5,STAINED_GLASS:15)
Block(-8,42,6,CONCRETE:7)
Block(-8,42,7,STAINED_GLASS:15)
Block(-8,42,8,CONCRETE:7)
Block(-8,43,-3,CONCRETE:7)
Block(-8,43,-2,STAINED_GLASS:15)
Block(-8,43,-1,CONCRETE:7)
Block(-8,43,0,STAINED_GLASS:15)
Block(-8,43,1,CONCRETE:7)
Block(-8,43,4,CONCRETE:7)
Block(-8,43,5,STAINED_GLASS:15)
Block(-8,43,6,CONCRETE:7)
Block(-8,43,7,STAINED_GLASS:15)
Block(-8,43,8,CONCRETE:7)
Block(-8,44,-3,CONCRETE:7)
Block(-8,44,-2,STAINED_GLASS:15)
Block(-8,44,-1,CONCRETE:7)
Block(-8,44,0,STAINED_GLASS:15)
Block(-8,44,1,CONCRETE:7)
Block(-8,44,4,CONCRETE:7)
Block(-8,44,5,STAINED_GLASS:15)
Block(-8,44,6,CONCRETE:7)
Block(-8,44,7,STAINED_GLASS:15)
Block(-8,44,8,CONCRETE:7)
Block(-8,45,-3,CONCRETE:7)
Block(-8,45,-2,STAINED_GLASS:15)
Block(-8,45,-1,CONCRETE:7)
Block(-8,45,0,STAINED_GLASS:15)
Block(-8,45,1,CONCRETE:7)
Block(-8,45,4,CONCRETE:7)
Block(-8,45,5,STAINED_GLASS:15)
Block(-8,45,6,CONCRETE:7)
Block(-8,45,7,STAINED_GLASS:15)
Block(-8,45,8,CONCRETE:7)
Block(-8,46,-3,CONCRETE:7)
Block(-8,46,-2,STAINED_GLASS:15)
Block(-8,46,-1,CONCRETE:7)
Block(-8,46,0,STAINED_GLASS:15)
Block(-8,46,1,CONCRETE:7)
Block(-8,46,4,CONCRETE:7)
Block(-8,46,5,STAINED_GLASS:15)
Block(-8,46,6,CONCRETE:7)
Block(-8,46,7,STAINED_GLASS:15)
Block(-8,46,8,CONCRETE:7)
Block(-8,47,-3,CONCRETE:7)
Block(-8,47,-2,STAINED_GLASS:15)
Block(-8,47,-1,CONCRETE:7)
Block(-8,47,0,STAINED_GLASS:15)
Block(-8,47,1,CONCRETE:7)
Block(-8,47,4,CONCRETE:7)
Block(-8,47,5,STAINED_GLASS:15)
Block(-8,47,6,CONCRETE:7)
Block(-8,47,7,STAINED_GLASS:15)
Block(-8,47,8,CONCRETE:7)
Block(-8,48,-3,CONCRETE:7)
Block(-8,48,-2,STAINED_GLASS:15)
Block(-8,48,-1,CONCRETE:7)
Block(-8,48,0,STAINED_GLASS:15)
Block(-8,48,1,CONCRETE:7)
Block(-8,48,4,CONCRETE:7)
Block(-8,48,5,STAINED_GLASS:15)
Block(-8,48,6,CONCRETE:7)
Block(-8,48,7,STAINED_GLASS:15)
Block(-8,48,8,CONCRETE:7)
Block(-8,49,-3,CONCRETE:7)
Block(-8,49,-2,STAINED_GLASS:15)
Block(-8,49,-1,CONCRETE:7)
Block(-8,49,0,STAINED_GLASS:15)
Block(-8,49,1,CONCRETE:7)
Block(-8,50,-3,CONCRETE:7)
Block(-8,50,-2,STAINED_GLASS:15)
Block(-8,50,-1,CONCRETE:7)
Block(-8,50,0,STAINED_GLASS:15)
Block(-8,50,1,CONCRETE:7)
Block(-8,51,-3,CONCRETE:7)
Block(-8,51,-2,STAINED_GLASS:15)
Block(-8,51,-1,CONCRETE:7)
Block(-8,51,0,STAINED_GLASS:15)
Block(-8,51,1,CONCRETE:7)
Block(-8,52,-3,CONCRETE:7)
Block(-8,52,-2,STAINED_GLASS:15)
Block(-8,52,-1,CONCRETE:7)
Block(-8,52,0,STAINED_GLASS:15)
Block(-8,52,1,CONCRETE:7)
Block(-8,53,-3,CONCRETE:7)
Block(-8,53,-2,STAINED_GLASS:15)
Block(-8,53,-1,CONCRETE:7)
Block(-8,53,0,STAINED_GLASS:15)
Block(-8,53,1,CONCRETE:7)
Block(-8,54,-3,CONCRETE:7)
Block(-8,54,-2,STAINED_GLASS:15)
Block(-8,54,-1,CONCRETE:7)
Block(-8,54,0,STAINED_GLASS:15)
Block(-8,54,1,CONCRETE:7)
Block(-8,55,-3,CONCRETE:7)
Block(-8,55,-2,STAINED_GLASS:15)
Block(-8,55,-1,CONCRETE:7)
Block(-8,55,0,STAINED_GLASS:15)
Block(-8,55,1,CONCRETE:7)
Block(-8,56,-3,CONCRETE:7)
Block(-8,56,-2,CONCRETE:7)
Block(-8,56,-1,CONCRETE:7)
Block(-8,56,0,CONCRETE:7)
Block(-8,56,1,CONCRETE:7)
Block(-8,57,-3,CONCRETE:7)
Block(-8,57,-2,CONCRETE:7)
Block(-8,57,-1,CONCRETE:7)
Block(-8,57,0,CONCRETE:7)
Block(-8,57,1,CONCRETE:7)
Block(-8,58,-3,CONCRETE:7)
Block(-8,58,-2,STAINED_GLASS:15)
Block(-8,58,-1,CONCRETE:7)
Block(-8,58,0,STAINED_GLASS:15)
Block(-8,58,1,CONCRETE:7)
Block(-8,59,-3,CONCRETE:7)
Block(-8,59,-2,STAINED_GLASS:15)
Block(-8,59,-1,CONCRETE:7)
Block(-8,59,0,STAINED_GLASS:15)
Block(-8,59,1,CONCRETE:7)
Block(-8,60,-3,CONCRETE:7)
Block(-8,60,-2,STAINED_GLASS:15)
Block(-8,60,-1,CONCRETE:7)
Block(-8,60,0,STAINED_GLASS:15)
Block(-8,60,1,CONCRETE:7)
Block(-8,61,-3,CONCRETE:7)
Block(-8,61,-2,STAINED_GLASS:15)
Block(-8,61,-1,CONCRETE:7)
Block(-8,61,0,STAINED_GLASS:15)
Block(-8,61,1,CONCRETE:7)
Block(-8,62,-3,CONCRETE:7)
Block(-8,62,-2,STAINED_GLASS:15)
Block(-8,62,-1,CONCRETE:7)
Block(-8,62,0,STAINED_GLASS:15)
Block(-8,62,1,CONCRETE:7)
Block(-8,63,-3,CONCRETE:7)
Block(-8,63,-2,STAINED_GLASS:15)
Block(-8,63,-1,CONCRETE:7)
Block(-8,63,0,STAINED_GLASS:15)
Block(-8,63,1,CONCRETE:7)
Block(-8,64,-3,CONCRETE:7)
Block(-8,64,-2,STAINED_GLASS:15)
Block(-8,64,-1,CONCRETE:7)
Block(-8,64,0,STAINED_GLASS:15)
Block(-8,64,1,CONCRETE:7)
Block(-8,65,-3,CONCRETE:7)
Block(-8,65,-2,STAINED_GLASS:15)
Block(-8,65,-1,CONCRETE:7)
Block(-8,65,0,STAINED_GLASS:15)
Block(-8,65,1,CONCRETE:7)
Block(-8,66,-3,CONCRETE:7)
Block(-8,66,-2,STAINED_GLASS:15)
Block(-8,66,-1,CONCRETE:7)
Block(-8,66,0,STAINED_GLASS:15)
Block(-8,66,1,CONCRETE:7)
Block(-8,67,-3,CONCRETE:7)
Block(-8,67,-2,STAINED_GLASS:15)
Block(-8,67,-1,CONCRETE:7)
Block(-8,67,0,STAINED_GLASS:15)
Block(-8,67,1,CONCRETE:7)
Block(-8,68,-3,CONCRETE:7)
Block(-8,68,-2,STAINED_GLASS:15)
Block(-8,68,-1,CONCRETE:7)
Block(-8,68,0,STAINED_GLASS:15)
Block(-8,68,1,CONCRETE:7)
Block(-8,69,-3,CONCRETE:7)
Block(-8,69,-2,STAINED_GLASS:15)
Block(-8,69,-1,CONCRETE:7)
Block(-8,69,0,STAINED_GLASS:15)
Block(-8,69,1,CONCRETE:7)
Block(-8,77,3,CONCRETE:7)
Block(-8,77,4,STAINED_GLASS:15)
Block(-8,77,5,CONCRETE:7)
Block(-8,77,6,STAINED_GLASS:15)
Block(-8,77,7,CONCRETE:7)
Block(-8,77,8,STAINED_GLASS:15)
Block(-8,78,3,CONCRETE:7)
Block(-8,78,4,STAINED_GLASS:15)
Block(-8,78,5,CONCRETE:7)
Block(-8,78,6,STAINED_GLASS:15)
Block(-8,78,7,CONCRETE:7)
Block(-8,78,8,STAINED_GLASS:15)
Block(-8,79,3,CONCRETE:7)
Block(-8,79,4,STAINED_GLASS:15)
Block(-8,79,5,CONCRETE:7)
Block(-8,79,6,STAINED_GLASS:15)
Block(-8,79,7,CONCRETE:7)
Block(-8,79,8,STAINED_GLASS:15)
Block(-8,80,3,CONCRETE:7)
Block(-8,80,4,STAINED_GLASS:15)
Block(-8,80,5,CONCRETE:7)
Block(-8,80,6,STAINED_GLASS:15)
Block(-8,80,7,CONCRETE:7)
Block(-8,80,8,STAINED_GLASS:15)
Block(-8,81,3,CONCRETE:7)
Block(-8,81,4,STAINED_GLASS:15)
Block(-8,81,5,CONCRETE:7)
Block(-8,81,6,STAINED_GLASS:15)
Block(-8,81,7,CONCRETE:7)
Block(-8,81,8,STAINED_GLASS:15)
Block(-7,0,-7,CONCRETE:7)
Block(-7,0,-6,CONCRETE:7)
Block(-7,0,-5,CONCRETE:7)
Block(-7,0,-4,CONCRETE:7)
Block(-7,0,-3,CONCRETE:7)
Block(-7,0,-2,CONCRETE:7)
Block(-7,0,-1,CONCRETE:7)
Block(-7,0,0,CONCRETE:7)
Block(-7,0,1,CONCRETE:7)
Block(-7,0,2,CONCRETE:7)
Block(-7,0,3,CONCRETE:7)
Block(-7,0,4,CONCRETE:7)
Block(-7,0,5,CONCRETE:7)
Block(-7,0,6,CONCRETE:7)
Block(-7,0,7,CONCRETE:7)
Block(-7,0,8,CONCRETE:7)
Block(-7,1,-7,CONCRETE:7)
Block(-7,1,-6,CONCRETE:7)
Block(-7,1,-5,CONCRETE:7)
Block(-7,1,-4,CONCRETE:7)
Block(-7,1,-3,CONCRETE:7)
Block(-7,1,-2,CONCRETE:7)
Block(-7,1,-1,CONCRETE:7)
Block(-7,1,0,CONCRETE:7)
Block(-7,1,1,CONCRETE:7)
Block(-7,1,2,CONCRETE:7)
Block(-7,1,3,CONCRETE:7)
Block(-7,1,4,CONCRETE:7)
Block(-7,1,5,CONCRETE:7)
Block(-7,1,6,CONCRETE:7)
Block(-7,1,7,CONCRETE:7)
Block(-7,1,8,CONCRETE:7)
Block(-7,2,-7,CONCRETE:7)
Block(-7,2,-6,CONCRETE:7)
Block(-7,2,-5,CONCRETE:7)
Block(-7,2,-4,CONCRETE:7)
Block(-7,2,-3,CONCRETE:7)
Block(-7,2,-2,CONCRETE:7)
Block(-7,2,-1,CONCRETE:7)
Block(-7,2,0,CONCRETE:7)
Block(-7,2,1,CONCRETE:7)
Block(-7,2,2,CONCRETE:7)
Block(-7,2,3,CONCRETE:7)
Block(-7,2,4,CONCRETE:7)
Block(-7,2,5,CONCRETE:7)
Block(-7,2,6,CONCRETE:7)
Block(-7,2,7,CONCRETE:7)
Block(-7,2,8,CONCRETE:7)
Block(-7,3,-7,CONCRETE:7)
Block(-7,3,-6,CONCRETE:7)
Block(-7,3,-5,CONCRETE:7)
Block(-7,3,-4,CONCRETE:7)
Block(-7,3,-3,CONCRETE:7)
Block(-7,3,-2,CONCRETE:7)
Block(-7,3,-1,CONCRETE:7)
Block(-7,3,0,CONCRETE:7)
Block(-7,3,1,CONCRETE:7)
Block(-7,3,2,CONCRETE:7)
Block(-7,3,3,CONCRETE:7)
Block(-7,3,4,CONCRETE:7)
Block(-7,3,5,CONCRETE:7)
Block(-7,3,6,CONCRETE:7)
Block(-7,3,7,CONCRETE:7)
Block(-7,3,8,CONCRETE:7)
Block(-7,4,-7,CONCRETE:7)
Block(-7,4,-6,CONCRETE:7)
Block(-7,4,-5,CONCRETE:7)
Block(-7,4,-4,CONCRETE:7)
Block(-7,4,-3,CONCRETE:7)
Block(-7,4,-2,CONCRETE:7)
Block(-7,4,-1,CONCRETE:7)
Block(-7,4,0,CONCRETE:7)
Block(-7,4,1,CONCRETE:7)
Block(-7,4,2,CONCRETE:7)
Block(-7,4,3,CONCRETE:7)
Block(-7,4,4,CONCRETE:7)
Block(-7,4,5,CONCRETE:7)
Block(-7,4,6,CONCRETE:7)
Block(-7,4,7,CONCRETE:7)
Block(-7,4,8,CONCRETE:7)
Block(-7,5,-7,CONCRETE:7)
Block(-7,5,-6,CONCRETE:7)
Block(-7,5,-5,CONCRETE:7)
Block(-7,5,-4,CONCRETE:7)
Block(-7,5,-3,CONCRETE:7)
Block(-7,5,-2,CONCRETE:7)
Block(-7,5,-1,CONCRETE:7)
Block(-7,5,0,CONCRETE:7)
Block(-7,5,1,CONCRETE:7)
Block(-7,5,2,CONCRETE:7)
Block(-7,5,3,CONCRETE:7)
Block(-7,5,4,CONCRETE:7)
Block(-7,5,5,CONCRETE:7)
Block(-7,5,6,CONCRETE:7)
Block(-7,5,7,CONCRETE:7)
Block(-7,5,8,CONCRETE:7)
Block(-7,6,-7,CONCRETE:7)
Block(-7,6,-6,CONCRETE:7)
Block(-7,6,-5,CONCRETE:7)
Block(-7,6,-4,CONCRETE:7)
Block(-7,6,-3,CONCRETE:7)
Block(-7,6,-2,CONCRETE:7)
Block(-7,6,-1,CONCRETE:7)
Block(-7,6,0,CONCRETE:7)
Block(-7,6,1,CONCRETE:7)
Block(-7,6,2,CONCRETE:7)
Block(-7,6,3,CONCRETE:7)
Block(-7,6,4,CONCRETE:7)
Block(-7,6,5,CONCRETE:7)
Block(-7,6,6,CONCRETE:7)
Block(-7,6,7,CONCRETE:7)
Block(-7,6,8,CONCRETE:7)
Block(-7,7,-7,CONCRETE:7)
Block(-7,7,-6,CONCRETE:7)
Block(-7,7,-5,CONCRETE:7)
Block(-7,7,-4,CONCRETE:7)
Block(-7,7,-3,CONCRETE:7)
Block(-7,7,-2,CONCRETE:7)
Block(-7,7,-1,CONCRETE:7)
Block(-7,7,0,CONCRETE:7)
Block(-7,7,1,CONCRETE:7)
Block(-7,7,2,CONCRETE:7)
Block(-7,7,3,CONCRETE:7)
Block(-7,7,4,CONCRETE:7)
Block(-7,7,5,CONCRETE:7)
Block(-7,7,6,CONCRETE:7)
Block(-7,7,7,CONCRETE:7)
Block(-7,7,8,CONCRETE:7)
Block(-7,8,-7,CONCRETE:7)
Block(-7,8,-5,CONCRETE:15)
Block(-7,8,-4,CONCRETE:15)
Block(-7,8,-3,CONCRETE:15)
Block(-7,8,0,CONCRETE:15)
Block(-7,8,1,CONCRETE:15)
Block(-7,8,2,CONCRETE:15)
Block(-7,8,4,CONCRETE:7)
Block(-7,8,5,CONCRETE:7)
Block(-7,8,6,CONCRETE:7)
Block(-7,8,7,CONCRETE:7)
Block(-7,8,8,CONCRETE:7)
Block(-7,9,-7,CONCRETE:7)
Block(-7,9,-5,CONCRETE:15)
Block(-7,9,-4,CONCRETE:15)
Block(-7,9,-3,CONCRETE:15)
Block(-7,9,0,CONCRETE:15)
Block(-7,9,1,CONCRETE:15)
Block(-7,9,2,CONCRETE:15)
Block(-7,9,4,CONCRETE:7)
Block(-7,9,5,CONCRETE:7)
Block(-7,9,6,CONCRETE:7)
Block(-7,9,7,CONCRETE:7)
Block(-7,9,8,CONCRETE:7)
Block(-7,10,-7,CONCRETE:7)
Block(-7,10,-5,CONCRETE:15)
Block(-7,10,-4,CONCRETE:15)
Block(-7,10,-3,CONCRETE:15)
Block(-7,10,0,CONCRETE:15)
Block(-7,10,1,CONCRETE:15)
Block(-7,10,2,CONCRETE:15)
Block(-7,10,4,CONCRETE:7)
Block(-7,10,5,CONCRETE:7)
Block(-7,10,6,CONCRETE:7)
Block(-7,10,7,CONCRETE:7)
Block(-7,10,8,CONCRETE:7)
Block(-7,11,-7,CONCRETE:7)
Block(-7,11,-6,CONCRETE:7)
Block(-7,11,-5,CONCRETE:7)
Block(-7,11,-4,CONCRETE:7)
Block(-7,11,-3,CONCRETE:7)
Block(-7,11,-2,CONCRETE:7)
Block(-7,11,-1,CONCRETE:7)
Block(-7,11,0,CONCRETE:7)
Block(-7,11,1,CONCRETE:7)
Block(-7,11,2,CONCRETE:7)
Block(-7,11,3,CONCRETE:7)
Block(-7,11,4,CONCRETE:7)
Block(-7,11,5,CONCRETE:7)
Block(-7,11,6,CONCRETE:7)
Block(-7,11,7,CONCRETE:7)
Block(-7,11,8,CONCRETE:7)
Block(-7,12,-7,CONCRETE:7)
Block(-7,12,-6,CONCRETE:7)
Block(-7,12,-5,CONCRETE:7)
Block(-7,12,-4,CONCRETE:7)
Block(-7,12,-3,CONCRETE:7)
Block(-7,12,-2,CONCRETE:7)
Block(-7,12,-1,CONCRETE:7)
Block(-7,12,0,CONCRETE:7)
Block(-7,12,1,CONCRETE:7)
Block(-7,12,2,CONCRETE:7)
Block(-7,12,3,CONCRETE:7)
Block(-7,12,4,CONCRETE:7)
Block(-7,12,5,CONCRETE:7)
Block(-7,12,6,CONCRETE:7)
Block(-7,12,7,CONCRETE:7)
Block(-7,12,8,CONCRETE:7)
Block(-7,13,-7,CONCRETE:7)
Block(-7,13,-6,CONCRETE:7)
Block(-7,13,-5,CONCRETE:7)
Block(-7,13,-4,CONCRETE:7)
Block(-7,13,-3,CONCRETE:7)
Block(-7,13,-2,CONCRETE:7)
Block(-7,13,-1,CONCRETE:7)
Block(-7,13,0,CONCRETE:7)
Block(-7,13,1,CONCRETE:7)
Block(-7,13,2,CONCRETE:7)
Block(-7,13,3,CONCRETE:7)
Block(-7,13,4,CONCRETE:7)
Block(-7,13,5,CONCRETE:7)
Block(-7,13,6,CONCRETE:7)
Block(-7,13,7,CONCRETE:7)
Block(-7,13,8,CONCRETE:7)
Block(-7,14,-7,CONCRETE:7)
Block(-7,14,-6,CONCRETE:7)
Block(-7,14,-5,CONCRETE:7)
Block(-7,14,-4,CONCRETE:7)
Block(-7,14,-3,CONCRETE:7)
Block(-7,14,-2,CONCRETE:7)
Block(-7,14,-1,CONCRETE:7)
Block(-7,14,0,CONCRETE:7)
Block(-7,14,1,CONCRETE:7)
Block(-7,14,2,CONCRETE:7)
Block(-7,14,3,CONCRETE:7)
Block(-7,14,4,CONCRETE:7)
Block(-7,14,5,CONCRETE:7)
Block(-7,14,6,CONCRETE:7)
Block(-7,14,7,CONCRETE:7)
Block(-7,14,8,CONCRETE:7)
Block(-7,15,-7,CONCRETE:7)
Block(-7,15,-6,CONCRETE:7)
Block(-7,15,-5,CONCRETE:7)
Block(-7,15,-4,CONCRETE:7)
Block(-7,15,-3,CONCRETE:7)
Block(-7,15,-2,CONCRETE:7)
Block(-7,15,-1,CONCRETE:7)
Block(-7,15,0,CONCRETE:7)
Block(-7,15,1,CONCRETE:7)
Block(-7,15,2,CONCRETE:7)
Block(-7,15,3,CONCRETE:7)
Block(-7,15,4,CONCRETE:7)
Block(-7,15,5,CONCRETE:7)
Block(-7,15,6,CONCRETE:7)
Block(-7,15,7,CONCRETE:7)
Block(-7,15,8,CONCRETE:7)
Block(-7,16,-7,CONCRETE:7)
Block(-7,16,-6,CONCRETE:7)
Block(-7,16,-5,CONCRETE:7)
Block(-7,16,-4,CONCRETE:7)
Block(-7,16,-3,CONCRETE:7)
Block(-7,16,-2,CONCRETE:7)
Block(-7,16,-1,CONCRETE:7)
Block(-7,16,0,CONCRETE:7)
Block(-7,16,1,CONCRETE:7)
Block(-7,16,2,CONCRETE:7)
Block(-7,16,3,CONCRETE:7)
Block(-7,16,4,CONCRETE:7)
Block(-7,16,5,CONCRETE:7)
Block(-7,16,6,CONCRETE:7)
Block(-7,16,7,CONCRETE:7)
Block(-7,16,8,CONCRETE:7)
Block(-7,17,-7,CONCRETE:7)
Block(-7,17,-6,CONCRETE:7)
Block(-7,17,-5,CONCRETE:7)
Block(-7,17,-4,CONCRETE:7)
Block(-7,17,-3,CONCRETE:7)
Block(-7,17,-2,CONCRETE:7)
Block(-7,17,-1,CONCRETE:7)
Block(-7,17,0,CONCRETE:7)
Block(-7,17,1,CONCRETE:7)
Block(-7,17,2,CONCRETE:7)
Block(-7,17,3,CONCRETE:7)
Block(-7,17,4,CONCRETE:7)
Block(-7,17,5,CONCRETE:8)
Block(-7,17,6,DIRT:2)
Block(-7,17,7,DIRT:2)
Block(-7,17,8,DIRT:2)
Block(-7,18,-3,CONCRETE:7)
Block(-7,18,1,CONCRETE:7)
Block(-7,18,4,CONCRETE:7)
Block(-7,18,6,DOUBLE_PLANT:4)
Block(-7,18,7,DOUBLE_PLANT:4)
Block(-7,18,8,DEAD_BUSH:0)
Block(-7,19,-3,CONCRETE:7)
Block(-7,19,1,CONCRETE:7)
Block(-7,19,4,CONCRETE:7)
Block(-7,19,6,DOUBLE_PLANT:10)
Block(-7,19,7,DOUBLE_PLANT:10)
Block(-7,20,-3,CONCRETE:7)
Block(-7,20,1,CONCRETE:7)
Block(-7,20,4,CONCRETE:7)
Block(-7,21,-3,CONCRETE:7)
Block(-7,21,1,CONCRETE:7)
Block(-7,21,4,CONCRETE:7)
Block(-7,22,-3,CONCRETE:7)
Block(-7,22,-2,STAINED_GLASS:15)
Block(-7,22,-1,CONCRETE:7)
Block(-7,22,0,STAINED_GLASS:15)
Block(-7,22,1,CONCRETE:7)
Block(-7,22,4,CONCRETE:7)
Block(-7,23,-3,CONCRETE:7)
Block(-7,23,-2,DARK_OAK_STAIRS:3)
Block(-7,23,-1,DARK_OAK_FENCE:0)
Block(-7,23,0,DARK_OAK_STAIRS:2)
Block(-7,23,1,CONCRETE:7)
Block(-7,23,4,CONCRETE:7)
Block(-7,24,-3,CONCRETE:7)
Block(-7,24,-2,TRAP_DOOR:13)
Block(-7,24,-1,CARPET:8)
Block(-7,24,0,TRAP_DOOR:12)
Block(-7,24,1,CONCRETE:7)
Block(-7,24,4,CONCRETE:7)
Block(-7,25,-3,CONCRETE:7)
Block(-7,25,1,CONCRETE:7)
Block(-7,25,4,CONCRETE:7)
Block(-7,26,-3,CONCRETE:7)
Block(-7,26,1,CONCRETE:7)
Block(-7,26,4,CONCRETE:7)
Block(-7,26,5,STAINED_GLASS_PANE:15)
Block(-7,26,6,CONCRETE:7)
Block(-7,26,7,STAINED_GLASS:15)
Block(-7,26,8,CONCRETE:7)
Block(-7,27,-3,CONCRETE:7)
Block(-7,27,1,CONCRETE:7)
Block(-7,27,4,CONCRETE:7)
Block(-7,27,5,STAINED_GLASS_PANE:15)
Block(-7,28,-3,CONCRETE:7)
Block(-7,28,1,CONCRETE:7)
Block(-7,28,4,CONCRETE:7)
Block(-7,29,-3,CONCRETE:7)
Block(-7,29,1,CONCRETE:7)
Block(-7,29,4,CONCRETE:7)
Block(-7,30,-3,CONCRETE:7)
Block(-7,30,1,CONCRETE:7)
Block(-7,30,4,CONCRETE:7)
Block(-7,31,-3,CONCRETE:7)
Block(-7,31,-2,STAINED_GLASS:15)
Block(-7,31,-1,CONCRETE:7)
Block(-7,31,0,STAINED_GLASS:15)
Block(-7,31,1,CONCRETE:7)
Block(-7,31,4,CONCRETE:7)
Block(-7,32,-3,CONCRETE:7)
Block(-7,32,-2,QUARTZ_STAIRS:7)
Block(-7,32,-1,STANDING_BANNER:11,NBT/skyscraper_2x2_03/1-bannerC0R0.nbt)
Block(-7,32,0,QUARTZ_STAIRS:6)
Block(-7,32,1,CONCRETE:7)
Block(-7,32,4,CONCRETE:7)
Block(-7,33,-3,CONCRETE:7)
Block(-7,33,-2,CARPET:8)
Block(-7,33,-1,CARPET:8)
Block(-7,33,0,CARPET:8)
Block(-7,33,1,CONCRETE:7)
Block(-7,33,4,CONCRETE:7)
Block(-7,34,-3,CONCRETE:7)
Block(-7,34,1,CONCRETE:7)
Block(-7,34,4,CONCRETE:7)
Block(-7,35,-3,CONCRETE:7)
Block(-7,35,1,CONCRETE:7)
Block(-7,35,4,CONCRETE:7)
Block(-7,36,-3,CONCRETE:7)
Block(-7,36,1,CONCRETE:7)
Block(-7,36,4,CONCRETE:7)
Block(-7,37,-3,CONCRETE:7)
Block(-7,37,1,CONCRETE:7)
Block(-7,37,4,CONCRETE:7)
Block(-7,37,5,STAINED_GLASS:15)
Block(-7,37,6,CONCRETE:7)
Block(-7,37,7,STAINED_GLASS:15)
Block(-7,37,8,STAINED_GLASS:15)
Block(-7,38,-3,CONCRETE:7)
Block(-7,38,1,CONCRETE:7)
Block(-7,38,4,CONCRETE:7)
Block(-7,39,-3,CONCRETE:7)
Block(-7,39,1,CONCRETE:7)
Block(-7,39,4,CONCRETE:7)
Block(-7,39,8,WALL_BANNER:4,NBT/skyscraper_2x2_03/2-bannerC0R0.nbt)
Block(-7,40,-3,CONCRETE:7)
Block(-7,40,1,CONCRETE:7)
Block(-7,40,4,CONCRETE:7)
Block(-7,41,-3,CONCRETE:7)
Block(-7,41,1,CONCRETE:7)
Block(-7,41,4,CONCRETE:7)
Block(-7,42,4,CONCRETE:7)
Block(-7,42,5,STAINED_GLASS:15)
Block(-7,42,6,CONCRETE:7)
Block(-7,42,7,STAINED_GLASS:15)
Block(-7,42,8,CONCRETE:7)
Block(-7,43,4,CONCRETE:7)
Block(-7,43,6,STANDING_BANNER:0,NBT/skyscraper_2x2_03/3-bannerC0R0.nbt)
Block(-7,43,7,DARK_OAK_STAIRS:2)
Block(-7,44,4,CONCRETE:7)
Block(-7,44,5,WALL_BANNER:2,NBT/skyscraper_2x2_03/6-bannerC0R0.nbt)
Block(-7,44,6,IRON_TRAPDOOR:3)
Block(-7,44,7,TRAP_DOOR:4)
Block(-7,44,8,WALL_BANNER:2,NBT/skyscraper_2x2_03/7-bannerC0R0.nbt)
Block(-7,45,4,CONCRETE:7)
Block(-7,46,4,CONCRETE:7)
Block(-7,47,4,CONCRETE:7)
Block(-7,48,4,CONCRETE:7)
Block(-7,48,5,STAINED_GLASS:15)
Block(-7,48,6,CONCRETE:7)
Block(-7,48,7,STAINED_GLASS:15)
Block(-7,48,8,CONCRETE:7)
Block(-7,50,-3,CONCRETE:7)
Block(-7,50,-2,CONCRETE:7)
Block(-7,50,-1,CONCRETE:7)
Block(-7,50,0,CONCRETE:7)
Block(-7,50,1,CONCRETE:7)
Block(-7,51,-3,STAINED_GLASS:15)
Block(-7,51,-2,WORKBENCH:0)
Block(-7,51,0,QUARTZ_STAIRS:6)
Block(-7,51,1,CONCRETE:7)
Block(-7,52,-3,STAINED_GLASS:15)
#RandomBlock(-7,52,-2,TRAPPED_CHEST:5,../../../../../Chests/Loot/ModernCityJunk_1.nbt,65,CHEST:5,../../../../../Chests/Loot/ModernCityJunk_1.nbt,20,CHEST:5,../../../../../Chests/Loot/ModernCityJunk_2.nbt,15,CHEST:5,../../../../../Chests/Loot/ModernCityJunk_3.nbt,15,CHEST:5,../../../../../Chests/Loot/ModernCityJunk_4.nbt,15,CHEST:5,../../../../../Chests/Loot/ModernCityJunk_5.nbt,15,CHEST:5,../../../../../Chests/Loot/ModernCityCommon_1.nbt,5,CHEST:5,../../../../../Chests/Loot/ModernCityCommon_2.nbt,5,CHEST:5,../../../../../Chests/Loot/ModernCityCommon_3.nbt,5,CHEST:5,../../../../../Chests/Loot/ModernCityCommon_4.nbt,5,CHEST:5,../../../../../Chests/Loot/ModernCityCommon_5.nbt,5,CHEST:5,../../../../../Chests/Loot/ModernCityGood_1.nbt,3,CHEST:5,../../../../../Chests/Loot/ModernCityGood_2.nbt,3,CHEST:5,../../../../../Chests/Loot/ModernCityGood_3.nbt,3,CHEST:5,../../../../../Chests/Loot/ModernCityGood_4.nbt,3,CHEST:5,../../../../../Chests/Loot/ModernCityGood_5.nbt,3,CHEST:5,../../../../../Chests/Loot/ModernCityEpic_1.nbt,1,CHEST:5,../../../../../Chests/Loot/ModernCityEpic_2.nbt,1,CHEST:5,../../../../../Chests/Loot/ModernCityEpic_3.nbt,1,CHEST:5,../../../../../Chests/Loot/ModernCityEpic_4.nbt,1,CHEST:5,../../../../../Chests/Loot/ModernCityEpic_5.nbt,1,CHEST:5,../../../../../Chests/Loot/Common1.nbt,25,CHEST:5,../../../../../Chests/Loot/Common2.nbt,25,CHEST:5,../../../../../Chests/Loot/Common3.nbt,25,CHEST:5,../../../../../Chests/Loot/Common4.nbt,25,CHEST:5,../../../../../Chests/Loot/Common5.nbt,25,CHEST:5,../../../../../Chests/Loot/Common6.nbt,25,CHEST:5,../../../../../Chests/Loot/Common7.nbt,25,CHEST:5,../../../../../Chests/Loot/Common8.nbt,25,CHEST:5,../../../../../Chests/Loot/Common9.nbt,25,CHEST:5,../../../../../Chests/Loot/Common10.nbt,25,CHEST:5,../../../../../Chests/Loot/Common11.nbt,25,CHEST:5,../../../../../Chests/Loot/Common12.nbt,25,CHEST:5,../../../../../Chests/Loot/Common13.nbt,25,CHEST:5,../../../../../Chests/Loot/Common14.nbt,25,CHEST:5,../../../../../Chests/Loot/Common15.nbt,25,CHEST:5,../../../../../Chests/Loot/Rare1.nbt,10,CHEST:5,../../../../../Chests/Loot/Rare2.nbt,10,CHEST:5,../../../../../Chests/Loot/Rare3.nbt,10,CHEST:5,../../../../../Chests/Loot/Rare4.nbt,10,CHEST:5,../../../../../Chests/Loot/Rare5.nbt,10,CHEST:5,../../../../../Chests/Loot/Rare6.nbt,10,CHEST:5,../../../../../Chests/Loot/Rare7.nbt,10,CHEST:5,../../../../../Chests/Loot/Rare8.nbt,10,CHEST:5,../../../../../Chests/Loot/Rare9.nbt,10,CHEST:5,../../../../../Chests/Loot/Rare10.nbt,10,CHEST:5,../../../../../Chests/Loot/Rare11.nbt,10,CHEST:5,../../../../../Chests/Loot/Rare12.nbt,10,CHEST:5,../../../../../Chests/Loot/Rare13.nbt,10,CHEST:5,../../../../../Chests/Loot/Rare14.nbt,10,CHEST:5,../../../../../Chests/Loot/Rare15.nbt,10,CHEST:5,../../../../../Chests/Loot/Epic1.nbt,1,CHEST:5,../../../../../Chests/Loot/Epic2.nbt,1,CHEST:5,../../../../../Chests/Loot/Epic3.nbt,1,CHEST:5,../../../../../Chests/Loot/Epic4.nbt,1,CHEST:5,../../../../../Chests/Loot/Epic5.nbt,1,CHEST:5,../../../../../Chests/Loot/Epic6.nbt,1,CHEST:5,../../../../../Chests/Loot/Epic7.nbt,1,CHEST:5,../../../../../Chests/Loot/Epic8.nbt,1,CHEST:5,../../../../../Chests/Loot/Epic9.nbt,1,CHEST:5,../../../../../Chests/Loot/Epic10.nbt,1,CHEST:5,../../../../../Chests/Loot/Epic11.nbt,1,CHEST:5,../../../../../Chests/Loot/Epic12.nbt,1,CHEST:5,../../../../../Chests/Loot/Epic13.nbt,1,CHEST:5,../../../../../Chests/Loot/Epic14.nbt,1,CHEST:5,../../../../../Chests/Loot/Epic15.nbt,1,CHEST:5,../../../../../Chests/Loot/ModernCityJunk_1.nbt,100)
Block(-7,52,0,QUARTZ_STAIRS:6)
Block(-7,52,1,CONCRETE:7)
Block(-7,53,-3,STAINED_GLASS:15)
Block(-7,53,0,QUARTZ_STAIRS:6)
Block(-7,53,1,CONCRETE:7)
Block(-7,54,-3,STAINED_GLASS:15)
Block(-7,54,1,CONCRETE:7)
Block(-7,55,-3,STAINED_GLASS:15)
Block(-7,55,-2,CONCRETE:7)
Block(-7,55,-1,CONCRETE:7)
Block(-7,55,0,STAINED_GLASS:15)
Block(-7,55,1,CONCRETE:7)
Block(-7,56,-3,CONCRETE:7)
Block(-7,56,-1,IRON_PLATE:0)
Block(-7,56,0,QUARTZ_STAIRS:3)
Block(-7,56,1,CONCRETE:7)
Block(-7,57,-3,CONCRETE:7)
Block(-7,57,0,TRIPWIRE_HOOK:2)
Block(-7,57,1,CONCRETE:7)
Block(-7,58,-3,STAINED_GLASS:15)
Block(-7,58,1,CONCRETE:7)
Block(-7,59,-3,STAINED_GLASS:15)
Block(-7,59,-2,CONCRETE:7)
Block(-7,59,-1,CONCRETE:7)
Block(-7,59,0,CONCRETE:7)
Block(-7,59,1,CONCRETE:7)
Block(-7,60,-3,STAINED_GLASS:15)
Block(-7,60,-1,BIRCH_DOOR:1)
Block(-7,60,0,DROPPER:1,NBT/skyscraper_2x2_03/10-dropperC0R0.nbt)
Block(-7,60,1,CONCRETE:7)
Block(-7,61,-3,STAINED_GLASS:15)
Block(-7,61,-1,BIRCH_DOOR:9)
Block(-7,61,0,TRAP_DOOR:4)
Block(-7,61,1,CONCRETE:7)
Block(-7,62,-3,STAINED_GLASS:15)
Block(-7,62,1,CONCRETE:7)
Block(-7,63,-3,STAINED_GLASS:15)
Block(-7,63,1,CONCRETE:7)
Block(-7,64,-3,STAINED_GLASS:15)
Block(-7,64,1,CONCRETE:7)
Block(-7,65,-3,STAINED_GLASS:15)
Block(-7,65,1,CONCRETE:7)
Block(-7,66,-3,STAINED_GLASS:15)
Block(-7,66,-2,CONCRETE:7)
Block(-7,66,-1,CONCRETE:7)
Block(-7,66,0,CONCRETE:7)
Block(-7,66,1,CONCRETE:7)
Block(-7,67,-3,STAINED_GLASS:15)
Block(-7,67,-1,WALL_SIGN:2,NBT/skyscraper_2x2_03/11-signC0R0.nbt)
Block(-7,67,0,DARK_OAK_STAIRS:1)
Block(-7,67,1,STAINED_GLASS:15)
Block(-7,68,-3,STAINED_GLASS:15)
Block(-7,68,0,TRAP_DOOR:7)
Block(-7,68,1,STAINED_GLASS:15)
Block(-7,69,-3,STAINED_GLASS:15)
Block(-7,69,-2,STAINED_GLASS:15)
Block(-7,69,-1,CONCRETE:7)
Block(-7,69,0,STAINED_GLASS:15)
Block(-7,69,1,CONCRETE:7)
Block(-7,73,5,CONCRETE:7)
Block(-7,73,6,STAINED_GLASS:15)
Block(-7,73,7,CONCRETE:7)
Block(-7,73,8,STAINED_GLASS:15)
Block(-7,74,5,CONCRETE:7)
Block(-7,74,6,STAINED_GLASS:15)
Block(-7,74,7,CONCRETE:7)
Block(-7,74,8,STAINED_GLASS:15)
Block(-7,75,5,CONCRETE:7)
Block(-7,75,6,STAINED_GLASS:15)
Block(-7,75,7,CONCRETE:7)
Block(-7,75,8,STAINED_GLASS:15)
Block(-7,76,5,CONCRETE:7)
Block(-7,76,6,STAINED_GLASS:15)
Block(-7,76,7,CONCRETE:7)
Block(-7,76,8,STAINED_GLASS:15)
Block(-7,77,3,CONCRETE:7)
Block(-7,77,4,STAINED_GLASS:15)
Block(-7,77,5,CONCRETE:7)
Block(-7,77,6,CONCRETE:7)
Block(-7,77,7,CONCRETE:7)
Block(-7,77,8,CONCRETE:7)
Block(-7,78,3,CONCRETE:7)
Block(-7,78,4,DIRT:2)
Block(-7,78,5,TRAP_DOOR:13)
Block(-7,78,6,TRAP_DOOR:12)
Block(-7,78,7,DIRT:2)
Block(-7,78,8,DARK_OAK_STAIRS:3)
Block(-7,79,3,CONCRETE:7)
Block(-7,79,4,FLOWER_POT:0,NBT/skyscraper_2x2_03/13-flower_potC0R0.nbt)
Block(-7,79,7,FLOWER_POT:0,NBT/skyscraper_2x2_03/14-flower_potC0R0.nbt)
Block(-7,80,3,CONCRETE:7)
Block(-7,80,4,LEAVES:4)
Block(-7,80,7,LEAVES:4)
Block(-7,81,3,CONCRETE:7)
Block(-7,81,4,STAINED_GLASS:15)
Block(-7,81,5,CONCRETE:7)
Block(-7,81,6,STAINED_GLASS:15)
Block(-7,81,7,CONCRETE:7)
Block(-7,81,8,STAINED_GLASS:15)
Block(-6,0,-7,CONCRETE:7)
Block(-6,0,-6,CONCRETE:7)
Block(-6,0,-5,CONCRETE:7)
Block(-6,0,-4,CONCRETE:7)
Block(-6,0,-3,CONCRETE:7)
Block(-6,0,-2,CONCRETE:7)
Block(-6,0,-1,CONCRETE:7)
Block(-6,0,0,CONCRETE:7)
Block(-6,0,1,CONCRETE:7)
Block(-6,0,2,CONCRETE:7)
Block(-6,0,3,CONCRETE:7)
Block(-6,0,4,CONCRETE:7)
Block(-6,0,5,CONCRETE:7)
Block(-6,0,6,CONCRETE:7)
Block(-6,0,7,CONCRETE:7)
Block(-6,0,8,CONCRETE:7)
Block(-6,1,-7,CONCRETE:7)
Block(-6,1,-6,CONCRETE:7)
Block(-6,1,-5,CONCRETE:7)
Block(-6,1,-4,CONCRETE:7)
Block(-6,1,-3,CONCRETE:7)
Block(-6,1,-2,CONCRETE:7)
Block(-6,1,-1,CONCRETE:7)
Block(-6,1,0,CONCRETE:7)
Block(-6,1,1,CONCRETE:7)
Block(-6,1,2,CONCRETE:7)
Block(-6,1,3,CONCRETE:7)
Block(-6,1,4,CONCRETE:7)
Block(-6,1,5,CONCRETE:7)
Block(-6,1,6,CONCRETE:7)
Block(-6,1,7,CONCRETE:7)
Block(-6,1,8,CONCRETE:7)
Block(-6,2,-7,CONCRETE:7)
Block(-6,2,-6,CONCRETE:7)
Block(-6,2,-5,CONCRETE:7)
Block(-6,2,-4,CONCRETE:7)
Block(-6,2,-3,CONCRETE:7)
Block(-6,2,-2,CONCRETE:7)
Block(-6,2,-1,CONCRETE:7)
Block(-6,2,0,CONCRETE:7)
Block(-6,2,1,CONCRETE:7)
Block(-6,2,2,CONCRETE:7)
Block(-6,2,3,CONCRETE:7)
Block(-6,2,4,CONCRETE:7)
Block(-6,2,5,CONCRETE:7)
Block(-6,2,6,CONCRETE:7)
Block(-6,2,7,CONCRETE:7)
Block(-6,2,8,CONCRETE:7)
Block(-6,3,-7,CONCRETE:7)
Block(-6,3,-6,CONCRETE:7)
Block(-6,3,-5,CONCRETE:7)
Block(-6,3,-4,CONCRETE:7)
Block(-6,3,-3,CONCRETE:7)
Block(-6,3,-2,CONCRETE:7)
Block(-6,3,-1,CONCRETE:7)
Block(-6,3,0,CONCRETE:7)
Block(-6,3,1,CONCRETE:7)
Block(-6,3,2,CONCRETE:7)
Block(-6,3,3,CONCRETE:7)
Block(-6,3,4,CONCRETE:7)
Block(-6,3,5,CONCRETE:7)
Block(-6,3,6,CONCRETE:7)
Block(-6,3,7,CONCRETE:7)
Block(-6,3,8,CONCRETE:7)
Block(-6,4,-7,CONCRETE:7)
Block(-6,4,-6,CONCRETE:7)
Block(-6,4,-5,CONCRETE:7)
Block(-6,4,-4,CONCRETE:7)
Block(-6,4,-3,CONCRETE:7)
Block(-6,4,-2,CONCRETE:7)
Block(-6,4,-1,CONCRETE:7)
Block(-6,4,0,CONCRETE:7)
Block(-6,4,1,CONCRETE:7)
Block(-6,4,2,CONCRETE:7)
Block(-6,4,3,CONCRETE:7)
Block(-6,4,4,CONCRETE:7)
Block(-6,4,5,CONCRETE:7)
Block(-6,4,6,CONCRETE:7)
Block(-6,4,7,CONCRETE:7)
Block(-6,4,8,CONCRETE:7)
Block(-6,5,-7,CONCRETE:7)
Block(-6,5,-6,CONCRETE:7)
Block(-6,5,-5,CONCRETE:7)
Block(-6,5,-4,CONCRETE:7)
Block(-6,5,-3,CONCRETE:7)
Block(-6,5,-2,CONCRETE:7)
Block(-6,5,-1,CONCRETE:7)
Block(-6,5,0,CONCRETE:7)
Block(-6,5,1,CONCRETE:7)
Block(-6,5,2,CONCRETE:7)
Block(-6,5,3,CONCRETE:7)
Block(-6,5,4,CONCRETE:7)
Block(-6,5,5,CONCRETE:7)
Block(-6,5,6,CONCRETE:7)
Block(-6,5,7,CONCRETE:7)
Block(-6,5,8,CONCRETE:7)
Block(-6,6,-7,CONCRETE:7)
Block(-6,6,-6,CONCRETE:7)
Block(-6,6,-5,CONCRETE:7)
Block(-6,6,-4,CONCRETE:7)
Block(-6,6,-3,CONCRETE:7)
Block(-6,6,-2,CONCRETE:7)
Block(-6,6,-1,CONCRETE:7)
Block(-6,6,0,CONCRETE:7)
Block(-6,6,1,CONCRETE:7)
Block(-6,6,2,CONCRETE:7)
Block(-6,6,3,CONCRETE:7)
Block(-6,6,4,CONCRETE:7)
Block(-6,6,5,CONCRETE:7)
Block(-6,6,6,CONCRETE:7)
Block(-6,6,7,CONCRETE:7)
Block(-6,6,8,CONCRETE:7)
Block(-6,7,-7,CONCRETE:7)
Block(-6,7,-6,CONCRETE:7)
Block(-6,7,-5,CONCRETE:7)
Block(-6,7,-4,CONCRETE:7)
Block(-6,7,-3,CONCRETE:7)
Block(-6,7,-2,CONCRETE:7)
Block(-6,7,-1,CONCRETE:7)
Block(-6,7,0,CONCRETE:7)
Block(-6,7,1,CONCRETE:7)
Block(-6,7,2,CONCRETE:7)
Block(-6,7,3,CONCRETE:7)
Block(-6,7,4,CONCRETE:7)
Block(-6,7,5,CONCRETE:7)
Block(-6,7,6,CONCRETE:7)
Block(-6,7,7,CONCRETE:7)
Block(-6,7,8,CONCRETE:7)
Block(-6,8,-7,CONCRETE:7)
Block(-6,8,-5,CONCRETE:15)
Block(-6,8,-4,TNT:0)
Block(-6,8,-3,CONCRETE:15)
Block(-6,8,0,CONCRETE:15)
Block(-6,8,1,TNT:0)
Block(-6,8,2,CONCRETE:15)
Block(-6,8,4,CONCRETE:7)
Block(-6,8,5,CONCRETE:7)
Block(-6,8,6,CONCRETE:7)
Block(-6,8,7,CONCRETE:7)
Block(-6,8,8,CONCRETE:7)
Block(-6,9,-7,CONCRETE:7)
Block(-6,9,-5,CONCRETE:15)
Block(-6,9,-4,TNT:0)
Block(-6,9,-3,CONCRETE:15)
Block(-6,9,0,CONCRETE:15)
Block(-6,9,1,TNT:0)
Block(-6,9,2,CONCRETE:15)
Block(-6,9,4,CONCRETE:7)
Block(-6,9,5,CONCRETE:7)
Block(-6,9,6,CONCRETE:7)
Block(-6,9,7,CONCRETE:7)
Block(-6,9,8,CONCRETE:7)
Block(-6,10,-7,CONCRETE:7)
Block(-6,10,-5,CONCRETE:15)
Block(-6,10,-4,CONCRETE:15)
Block(-6,10,-3,CONCRETE:15)
Block(-6,10,0,CONCRETE:15)
Block(-6,10,1,CONCRETE:15)
Block(-6,10,2,CONCRETE:15)
Block(-6,10,4,CONCRETE:7)
Block(-6,10,5,CONCRETE:7)
Block(-6,10,6,CONCRETE:7)
Block(-6,10,7,CONCRETE:7)
Block(-6,10,8,CONCRETE:7)
Block(-6,11,-7,CONCRETE:7)
Block(-6,11,-6,CONCRETE:7)
Block(-6,11,-5,CONCRETE:7)
Block(-6,11,-4,CONCRETE:7)
Block(-6,11,-3,CONCRETE:7)
Block(-6,11,-2,CONCRETE:7)
Block(-6,11,-1,CONCRETE:7)
Block(-6,11,0,CONCRETE:7)
Block(-6,11,1,CONCRETE:7)
Block(-6,11,2,CONCRETE:7)
Block(-6,11,3,CONCRETE:7)
Block(-6,11,4,CONCRETE:7)
Block(-6,11,5,CONCRETE:7)
Block(-6,11,6,CONCRETE:7)
Block(-6,11,7,CONCRETE:7)
Block(-6,11,8,CONCRETE:7)
Block(-6,12,-7,CONCRETE:7)
Block(-6,12,-6,CONCRETE:7)
Block(-6,12,-5,CONCRETE:7)
Block(-6,12,-4,CONCRETE:7)
Block(-6,12,-3,CONCRETE:7)
Block(-6,12,-2,CONCRETE:7)
Block(-6,12,-1,CONCRETE:7)
Block(-6,12,0,CONCRETE:7)
Block(-6,12,1,CONCRETE:7)
Block(-6,12,2,CONCRETE:7)
Block(-6,12,3,CONCRETE:7)
Block(-6,12,4,CONCRETE:7)
Block(-6,12,5,CONCRETE:7)
Block(-6,12,6,CONCRETE:7)
Block(-6,12,7,CONCRETE:7)
Block(-6,12,8,CONCRETE:7)
Block(-6,13,-7,CONCRETE:7)
Block(-6,13,-6,CONCRETE:7)
Block(-6,13,-5,CONCRETE:7)
Block(-6,13,-4,CONCRETE:7)
Block(-6,13,-3,CONCRETE:7)
Block(-6,13,-2,CONCRETE:7)
Block(-6,13,-1,CONCRETE:7)
Block(-6,13,0,CONCRETE:7)
Block(-6,13,1,CONCRETE:7)
Block(-6,13,2,CONCRETE:7)
Block(-6,13,3,CONCRETE:7)
Block(-6,13,4,CONCRETE:7)
Block(-6,13,5,CONCRETE:7)
Block(-6,13,6,CONCRETE:7)
Block(-6,13,7,CONCRETE:7)
Block(-6,13,8,CONCRETE:7)
Block(-6,14,-7,CONCRETE:7)
Block(-6,14,-6,CONCRETE:7)
Block(-6,14,-5,CONCRETE:7)
Block(-6,14,-4,CONCRETE:7)
Block(-6,14,-3,CONCRETE:7)
Block(-6,14,-2,CONCRETE:7)
Block(-6,14,-1,CONCRETE:7)
Block(-6,14,0,CONCRETE:7)
Block(-6,14,1,CONCRETE:7)
Block(-6,14,2,CONCRETE:7)
Block(-6,14,3,CONCRETE:7)
Block(-6,14,4,CONCRETE:7)
Block(-6,14,5,CONCRETE:7)
Block(-6,14,6,CONCRETE:7)
Block(-6,14,7,CONCRETE:7)
Block(-6,14,8,CONCRETE:7)
Block(-6,15,-7,CONCRETE:7)
Block(-6,15,-6,CONCRETE:7)
Block(-6,15,-5,CONCRETE:7)
Block(-6,15,-4,CONCRETE:7)
Block(-6,15,-3,CONCRETE:7)
Block(-6,15,-2,CONCRETE:7)
Block(-6,15,-1,CONCRETE:7)
Block(-6,15,0,CONCRETE:7)
Block(-6,15,1,CONCRETE:7)
Block(-6,15,2,CONCRETE:7)
Block(-6,15,3,CONCRETE:7)
Block(-6,15,4,CONCRETE:7)
Block(-6,15,5,CONCRETE:7)
Block(-6,15,6,CONCRETE:7)
Block(-6,15,7,CONCRETE:7)
Block(-6,15,8,CONCRETE:7)
Block(-6,16,-7,CONCRETE:7)
Block(-6,16,-6,CONCRETE:7)
Block(-6,16,-5,CONCRETE:7)
Block(-6,16,-4,CONCRETE:7)
Block(-6,16,-3,CONCRETE:7)
Block(-6,16,-2,CONCRETE:7)
Block(-6,16,-1,CONCRETE:7)
Block(-6,16,0,CONCRETE:7)
Block(-6,16,1,CONCRETE:7)
Block(-6,16,2,CONCRETE:7)
Block(-6,16,3,CONCRETE:7)
Block(-6,16,4,CONCRETE:7)
Block(-6,16,5,CONCRETE:7)
Block(-6,16,6,CONCRETE:7)
Block(-6,16,7,CONCRETE:7)
Block(-6,16,8,CONCRETE:7)
Block(-6,17,-7,CONCRETE:7)
Block(-6,17,-6,CONCRETE:7)
Block(-6,17,-5,CONCRETE:7)
Block(-6,17,-4,CONCRETE:7)
Block(-6,17,-3,CONCRETE:7)
Block(-6,17,-2,CONCRETE:7)
Block(-6,17,-1,CONCRETE:7)
Block(-6,17,0,CONCRETE:7)
Block(-6,17,1,CONCRETE:7)
Block(-6,17,2,CONCRETE:7)
Block(-6,17,3,CONCRETE:7)
Block(-6,17,4,CONCRETE:7)
Block(-6,17,5,CONCRETE:8)
Block(-6,17,6,DIRT:2)
Block(-6,17,7,DIRT:2)
Block(-6,17,8,DIRT:2)
Block(-6,18,-3,CONCRETE:7)
Block(-6,18,1,CONCRETE:7)
Block(-6,18,2,CONCRETE:8)
Block(-6,18,3,CONCRETE:8)
Block(-6,18,4,CONCRETE:8)
Block(-6,18,5,STAINED_GLASS_PANE:15)
Block(-6,18,6,LONG_GRASS:1)
Block(-6,18,7,DEAD_BUSH:0)
Block(-6,18,8,DOUBLE_PLANT:4)
Block(-6,19,-3,CONCRETE:7)
Block(-6,19,1,CONCRETE:7)
Block(-6,19,2,CONCRETE:8)
Block(-6,19,3,CONCRETE:8)
Block(-6,19,4,CONCRETE:8)
Block(-6,19,5,STAINED_GLASS_PANE:15)
Block(-6,19,8,DOUBLE_PLANT:10)
Block(-6,20,-3,CONCRETE:7)
Block(-6,20,1,CONCRETE:7)
Block(-6,20,2,CONCRETE:8)
Block(-6,20,3,CONCRETE:8)
Block(-6,20,4,CONCRETE:8)
Block(-6,21,-3,CONCRETE:7)
Block(-6,21,1,CONCRETE:7)
Block(-6,21,2,CONCRETE:8)
Block(-6,21,3,CONCRETE:8)
Block(-6,21,4,CONCRETE:8)
Block(-6,22,-3,CONCRETE:7)
Block(-6,22,-2,STAINED_GLASS:15)
Block(-6,22,-1,CONCRETE:7)
Block(-6,22,0,STAINED_GLASS:15)
Block(-6,22,1,CONCRETE:7)
Block(-6,22,2,CONCRETE:8)
Block(-6,22,3,CONCRETE:8)
Block(-6,22,4,CONCRETE:8)
Block(-6,22,5,STAINED_GLASS_PANE:15)
Block(-6,22,7,IRON_TRAPDOOR:9)
Block(-6,23,-3,CONCRETE:7)
Block(-6,23,-2,WALL_SIGN:5,NBT/skyscraper_2x2_03/19-signC0R0.nbt)
Block(-6,23,0,WALL_SIGN:5,NBT/skyscraper_2x2_03/20-signC0R0.nbt)
Block(-6,23,1,CONCRETE:7)
Block(-6,23,2,CONCRETE:8)
Block(-6,23,3,CONCRETE:8)
Block(-6,23,4,CONCRETE:8)
Block(-6,23,5,STAINED_GLASS_PANE:15)
Block(-6,23,6,STEP:8)
Block(-6,23,7,PRISMARINE:0)
Block(-6,23,8,STEP:8)
Block(-6,24,-3,CONCRETE:7)
Block(-6,24,1,CONCRETE:7)
Block(-6,24,2,CONCRETE:8)
Block(-6,24,3,CONCRETE:8)
Block(-6,24,4,CONCRETE:8)
Block(-6,24,6,IRON_FENCE:0)
Block(-6,24,7,IRON_TRAPDOOR:3)
Block(-6,25,-3,CONCRETE:7)
Block(-6,25,1,CONCRETE:7)
Block(-6,25,2,CONCRETE:8)
Block(-6,25,3,CONCRETE:8)
Block(-6,25,4,CONCRETE:8)
Block(-6,25,6,IRON_FENCE:0)
Block(-6,26,-3,CONCRETE:7)
Block(-6,26,1,CONCRETE:7)
Block(-6,26,2,CONCRETE:8)
Block(-6,26,3,CONCRETE:8)
Block(-6,26,4,CONCRETE:8)
Block(-6,26,5,STAINED_GLASS_PANE:15)
Block(-6,26,6,CONCRETE:7)
Block(-6,26,7,STAINED_GLASS:15)
Block(-6,26,8,CONCRETE:7)
Block(-6,27,-3,CONCRETE:7)
Block(-6,27,1,CONCRETE:7)
Block(-6,27,2,CONCRETE:8)
Block(-6,27,3,CONCRETE:8)
Block(-6,27,4,CONCRETE:8)
Block(-6,27,5,STAINED_GLASS_PANE:15)
Block(-6,27,7,WALL_SIGN:2,NBT/skyscraper_2x2_03/21-signC0R0.nbt)
Block(-6,27,8,DARK_OAK_STAIRS:1)
Block(-6,28,-3,CONCRETE:7)
Block(-6,28,1,CONCRETE:7)
Block(-6,28,2,CONCRETE:8)
Block(-6,28,3,CONCRETE:8)
Block(-6,28,4,CONCRETE:8)
Block(-6,28,8,TRAP_DOOR:7)
Block(-6,29,-3,CONCRETE:7)
Block(-6,29,1,CONCRETE:7)
Block(-6,29,2,CONCRETE:8)
Block(-6,29,3,CONCRETE:8)
Block(-6,29,4,CONCRETE:8)
Block(-6,30,-3,CONCRETE:7)
Block(-6,30,1,CONCRETE:7)
Block(-6,30,2,CONCRETE:8)
Block(-6,30,3,CONCRETE:8)
Block(-6,30,4,CONCRETE:8)
Block(-6,31,-3,CONCRETE:7)
Block(-6,31,-2,STAINED_GLASS:15)
Block(-6,31,-1,CONCRETE:7)
Block(-6,31,0,STAINED_GLASS:15)
Block(-6,31,1,CONCRETE:7)
Block(-6,31,2,CONCRETE:8)
Block(-6,31,3,CONCRETE:8)
Block(-6,31,4,CONCRETE:8)
Block(-6,32,-3,CONCRETE:7)
Block(-6,32,-2,WALL_SIGN:2,NBT/skyscraper_2x2_03/25-signC0R0.nbt)
Block(-6,32,-1,DARK_OAK_STAIRS:0)
Block(-6,32,0,WALL_SIGN:3,NBT/skyscraper_2x2_03/26-signC0R0.nbt)
Block(-6,32,1,CONCRETE:7)
Block(-6,32,2,CONCRETE:8)
Block(-6,32,3,CONCRETE:8)
Block(-6,32,4,CONCRETE:8)
Block(-6,33,-3,CONCRETE:7)
Block(-6,33,-1,TRAP_DOOR:6)
Block(-6,33,0,TRAP_DOOR:6)
Block(-6,33,1,CONCRETE:7)
Block(-6,33,2,CONCRETE:8)
Block(-6,33,3,CONCRETE:8)
Block(-6,33,4,CONCRETE:8)
Block(-6,34,-3,CONCRETE:7)
Block(-6,34,1,CONCRETE:7)
Block(-6,34,2,CONCRETE:8)
Block(-6,34,3,CONCRETE:8)
Block(-6,34,4,CONCRETE:8)
Block(-6,35,-3,CONCRETE:7)
Block(-6,35,1,CONCRETE:7)
Block(-6,35,2,CONCRETE:8)
Block(-6,35,3,CONCRETE:8)
Block(-6,35,4,CONCRETE:8)
Block(-6,36,-3,CONCRETE:7)
Block(-6,36,1,CONCRETE:7)
Block(-6,36,2,CONCRETE:8)
Block(-6,36,3,CONCRETE:8)
Block(-6,36,4,CONCRETE:8)
Block(-6,37,-3,CONCRETE:7)
Block(-6,37,1,CONCRETE:7)
Block(-6,37,2,CONCRETE:8)
Block(-6,37,3,CONCRETE:8)
Block(-6,37,4,CONCRETE:8)
Block(-6,37,5,STAINED_GLASS:15)
Block(-6,37,6,CONCRETE:7)
Block(-6,37,7,STAINED_GLASS:15)
Block(-6,37,8,STAINED_GLASS:15)
Block(-6,38,-3,CONCRETE:7)
Block(-6,38,1,CONCRETE:7)
Block(-6,38,2,CONCRETE:8)
Block(-6,38,3,CONCRETE:8)
Block(-6,38,4,CONCRETE:8)
Block(-6,38,7,WALL_SIGN:2,NBT/skyscraper_2x2_03/27-signC0R0.nbt)
Block(-6,38,8,DARK_OAK_STAIRS:1)
Block(-6,39,-3,CONCRETE:7)
Block(-6,39,1,CONCRETE:7)
Block(-6,39,2,CONCRETE:8)
Block(-6,39,3,CONCRETE:8)
Block(-6,39,4,CONCRETE:8)
Block(-6,39,8,TRAP_DOOR:7)
Block(-6,40,-3,CONCRETE:7)
Block(-6,40,1,CONCRETE:7)
Block(-6,40,2,CONCRETE:8)
Block(-6,40,3,CONCRETE:8)
Block(-6,40,4,CONCRETE:8)
Block(-6,41,-3,CONCRETE:7)
Block(-6,41,1,CONCRETE:7)
Block(-6,41,2,CONCRETE:8)
Block(-6,41,3,CONCRETE:8)
Block(-6,41,4,CONCRETE:8)
Block(-6,42,-5,CONCRETE:7)
Block(-6,42,-4,CONCRETE:7)
Block(-6,42,-3,CONCRETE:7)
Block(-6,42,-2,CONCRETE:7)
Block(-6,42,-1,CONCRETE:7)
Block(-6,42,0,CONCRETE:7)
Block(-6,42,1,CONCRETE:8)
Block(-6,42,2,CONCRETE:8)
Block(-6,42,3,CONCRETE:8)
Block(-6,42,4,CONCRETE:7)
Block(-6,42,5,STAINED_GLASS:15)
Block(-6,42,6,CONCRETE:7)
Block(-6,42,7,STAINED_GLASS:15)
Block(-6,42,8,CONCRETE:7)
Block(-6,43,-5,CONCRETE:7)
Block(-6,43,-4,STAINED_GLASS:15)
Block(-6,43,-3,STAINED_GLASS:15)
Block(-6,43,-2,STAINED_GLASS:15)
Block(-6,43,-1,STAINED_GLASS:15)
Block(-6,43,0,CONCRETE:7)
Block(-6,43,1,STAINED_GLASS_PANE:15)
Block(-6,43,2,STAINED_GLASS_PANE:15)
Block(-6,43,3,STAINED_GLASS_PANE:15)
Block(-6,43,4,CONCRETE:7)
Block(-6,43,6,QUARTZ_STAIRS:4)
Block(-6,43,7,WALL_SIGN:5,NBT/skyscraper_2x2_03/29-signC0R0.nbt)
Block(-6,44,-5,CONCRETE:7)
Block(-6,44,-4,STAINED_GLASS:15)
Block(-6,44,-3,STAINED_GLASS:15)
Block(-6,44,-2,STAINED_GLASS:15)
Block(-6,44,-1,STAINED_GLASS:15)
Block(-6,44,0,CONCRETE:7)
Block(-6,44,4,CONCRETE:7)
Block(-6,44,5,WALL_BANNER:2,NBT/skyscraper_2x2_03/34-bannerC0R0.nbt)
Block(-6,44,6,IRON_TRAPDOOR:3)
Block(-6,44,7,IRON_TRAPDOOR:1)
Block(-6,44,8,WALL_BANNER:2,NBT/skyscraper_2x2_03/35-bannerC0R0.nbt)
Block(-6,45,-5,CONCRETE:7)
Block(-6,45,-4,STAINED_GLASS:15)
Block(-6,45,-3,STAINED_GLASS:15)
Block(-6,45,-2,STAINED_GLASS:15)
Block(-6,45,-1,STAINED_GLASS:15)
Block(-6,45,0,CONCRETE:7)
Block(-6,45,4,CONCRETE:7)
Block(-6,46,-5,CONCRETE:7)
Block(-6,46,-4,STAINED_GLASS:15)
Block(-6,46,-3,STAINED_GLASS:15)
Block(-6,46,-2,STAINED_GLASS:15)
Block(-6,46,-1,STAINED_GLASS:15)
Block(-6,46,0,CONCRETE:7)
Block(-6,46,4,CONCRETE:7)
Block(-6,47,-5,CONCRETE:7)
Block(-6,47,-4,STAINED_GLASS:15)
Block(-6,47,-3,STAINED_GLASS:15)
Block(-6,47,-2,STAINED_GLASS:15)
Block(-6,47,-1,STAINED_GLASS:15)
Block(-6,47,0,CONCRETE:7)
Block(-6,47,4,CONCRETE:7)
Block(-6,48,-5,CONCRETE:7)
Block(-6,48,-4,STAINED_GLASS:15)
Block(-6,48,-3,STAINED_GLASS:15)
Block(-6,48,-2,STAINED_GLASS:15)
Block(-6,48,-1,STAINED_GLASS:15)
Block(-6,48,0,CONCRETE:7)
Block(-6,48,4,CONCRETE:7)
Block(-6,48,5,STAINED_GLASS:15)
Block(-6,48,6,CONCRETE:7)
Block(-6,48,7,STAINED_GLASS:15)
Block(-6,48,8,CONCRETE:7)
Block(-6,49,-5,CONCRETE:7)
Block(-6,49,-4,STAINED_GLASS:15)
Block(-6,49,-3,STAINED_GLASS:15)
Block(-6,49,-2,STAINED_GLASS:15)
Block(-6,49,-1,STAINED_GLASS:15)
Block(-6,49,0,CONCRETE:7)
Block(-6,50,-5,CONCRETE:7)
Block(-6,50,-4,CONCRETE:7)
Block(-6,50,-3,CONCRETE:7)
Block(-6,50,-2,CONCRETE:7)
Block(-6,50,-1,CONCRETE:7)
Block(-6,50,0,CONCRETE:7)
Block(-6,50,1,CONCRETE:7)
Block(-6,51,-3,CONCRETE:7)
Block(-6,51,0,QUARTZ_STAIRS:6)
Block(-6,51,1,CONCRETE:7)
Block(-6,52,-3,CONCRETE:7)
Block(-6,52,0,QUARTZ_STAIRS:6)
Block(-6,52,1,CONCRETE:7)
Block(-6,53,-3,CONCRETE:7)
Block(-6,53,0,QUARTZ_STAIRS:6)
Block(-6,53,1,CONCRETE:7)
Block(-6,54,-3,CONCRETE:7)
Block(-6,54,0,FURNACE:2,NBT/skyscraper_2x2_03/39-furnaceC0R0.nbt)
Block(-6,54,1,CONCRETE:7)
Block(-6,55,-3,CONCRETE:7)
Block(-6,55,-2,CONCRETE:7)
Block(-6,55,-1,CONCRETE:7)
Block(-6,55,0,STAINED_GLASS:15)
Block(-6,55,1,CONCRETE:7)
Block(-6,56,-3,CONCRETE:7)
Block(-6,56,-1,IRON_PLATE:0)
Block(-6,56,0,QUARTZ_STAIRS:3)
Block(-6,56,1,CONCRETE:7)
Block(-6,57,-3,CONCRETE:7)
Block(-6,57,0,TRIPWIRE_HOOK:2)
Block(-6,57,1,CONCRETE:7)
Block(-6,58,-3,CONCRETE:7)
Block(-6,58,1,CONCRETE:7)
Block(-6,59,-3,CONCRETE:7)
Block(-6,59,-2,CONCRETE:7)
Block(-6,59,-1,CONCRETE:7)
Block(-6,59,0,CONCRETE:7)
Block(-6,59,1,CONCRETE:7)
Block(-6,60,-3,CONCRETE:7)
Block(-6,60,-1,CONCRETE:7)
Block(-6,60,0,CONCRETE:7)
Block(-6,60,1,CONCRETE:7)
Block(-6,61,-3,CONCRETE:7)
Block(-6,61,-1,CONCRETE:7)
Block(-6,61,0,CONCRETE:7)
Block(-6,61,1,CONCRETE:7)
Block(-6,62,-3,CONCRETE:7)
Block(-6,62,-1,CONCRETE:7)
Block(-6,62,0,CONCRETE:7)
Block(-6,62,1,CONCRETE:7)
Block(-6,63,-3,CONCRETE:7)
Block(-6,63,-1,CONCRETE:7)
Block(-6,63,0,CONCRETE:7)
Block(-6,63,1,CONCRETE:7)
Block(-6,64,-3,CONCRETE:7)
Block(-6,64,-1,CONCRETE:7)
Block(-6,64,0,CONCRETE:7)
Block(-6,64,1,CONCRETE:7)
Block(-6,65,-3,CONCRETE:7)
Block(-6,65,-1,CONCRETE:7)
Block(-6,65,0,CONCRETE:7)
Block(-6,65,1,CONCRETE:7)
Block(-6,66,-3,CONCRETE:7)
Block(-6,66,-2,CONCRETE:7)
Block(-6,66,-1,CONCRETE:7)
Block(-6,66,0,CONCRETE:7)
Block(-6,66,1,CONCRETE:7)
Block(-6,67,-3,CONCRETE:7)
Block(-6,67,-1,QUARTZ_STAIRS:7)
Block(-6,67,0,STANDING_BANNER:5,NBT/skyscraper_2x2_03/40-bannerC0R0.nbt)
Block(-6,67,1,STAINED_GLASS:15)
Block(-6,68,-3,CONCRETE:7)
Block(-6,68,-2,WALL_BANNER:2,NBT/skyscraper_2x2_03/41-bannerC0R0.nbt)
Block(-6,68,-1,IRON_TRAPDOOR:0)
Block(-6,68,0,IRON_TRAPDOOR:0)
Block(-6,68,1,STAINED_GLASS:15)
Block(-6,69,-3,CONCRETE:7)
Block(-6,69,-2,STAINED_GLASS:15)
Block(-6,69,-1,CONCRETE:7)
Block(-6,69,0,STAINED_GLASS:15)
Block(-6,69,1,CONCRETE:7)
Block(-6,73,5,CONCRETE:7)
Block(-6,73,6,STAINED_GLASS:15)
Block(-6,73,7,CONCRETE:7)
Block(-6,73,8,STAINED_GLASS:15)
Block(-6,74,5,CONCRETE:7)
Block(-6,74,6,STAINED_GLASS:15)
Block(-6,74,7,DARK_OAK_STAIRS:1)
Block(-6,74,8,DARK_OAK_STAIRS:1)
Block(-6,75,5,CONCRETE:7)
Block(-6,75,6,STAINED_GLASS:15)
Block(-6,76,5,CONCRETE:7)
Block(-6,76,6,STAINED_GLASS:15)
Block(-6,77,3,CONCRETE:7)
Block(-6,77,4,STAINED_GLASS:15)
Block(-6,77,5,CONCRETE:7)
Block(-6,77,6,CONCRETE:7)
Block(-6,77,7,CONCRETE:7)
Block(-6,77,8,CONCRETE:7)
Block(-6,78,3,CONCRETE:7)
Block(-6,78,4,DARK_OAK_STAIRS:1)
Block(-6,78,7,DARK_OAK_STAIRS:1)
Block(-6,78,8,DARK_OAK_STAIRS:3)
Block(-6,79,3,CONCRETE:7)
Block(-6,80,3,CONCRETE:7)
Block(-6,81,3,CONCRETE:7)
Block(-6,81,4,STAINED_GLASS:15)
Block(-6,81,5,CONCRETE:7)
Block(-6,81,6,STAINED_GLASS:15)
Block(-6,81,7,CONCRETE:7)
Block(-6,81,8,STAINED_GLASS:15)
Block(-5,0,-7,CONCRETE:7)
Block(-5,0,-6,CONCRETE:7)
Block(-5,0,-5,CONCRETE:7)
Block(-5,0,-4,CONCRETE:7)
Block(-5,0,-3,CONCRETE:7)
Block(-5,0,-2,CONCRETE:7)
Block(-5,0,-1,CONCRETE:7)
Block(-5,0,0,CONCRETE:7)
Block(-5,0,1,CONCRETE:7)
Block(-5,0,2,CONCRETE:7)
Block(-5,0,3,CONCRETE:7)
Block(-5,0,4,CONCRETE:7)
Block(-5,0,5,CONCRETE:7)
Block(-5,0,6,CONCRETE:7)
Block(-5,0,7,CONCRETE:7)
Block(-5,0,8,CONCRETE:7)
Block(-5,1,-7,CONCRETE:7)
Block(-5,1,-6,CONCRETE:7)
Block(-5,1,-5,CONCRETE:7)
Block(-5,1,-4,CONCRETE:7)
Block(-5,1,-3,CONCRETE:7)
Block(-5,1,-2,CONCRETE:7)
Block(-5,1,-1,CONCRETE:7)
Block(-5,1,0,CONCRETE:7)
Block(-5,1,1,CONCRETE:7)
Block(-5,1,2,CONCRETE:7)
Block(-5,1,3,CONCRETE:7)
Block(-5,1,4,CONCRETE:7)
Block(-5,1,5,CONCRETE:7)
Block(-5,1,6,CONCRETE:7)
Block(-5,1,7,CONCRETE:7)
Block(-5,1,8,CONCRETE:7)
Block(-5,2,-7,CONCRETE:7)
Block(-5,2,-6,CONCRETE:7)
Block(-5,2,-5,CONCRETE:7)
Block(-5,2,-4,CONCRETE:7)
Block(-5,2,-3,CONCRETE:7)
Block(-5,2,-2,CONCRETE:7)
Block(-5,2,-1,CONCRETE:7)
Block(-5,2,0,CONCRETE:7)
Block(-5,2,1,CONCRETE:7)
Block(-5,2,2,CONCRETE:7)
Block(-5,2,3,CONCRETE:7)
Block(-5,2,4,CONCRETE:7)
Block(-5,2,5,CONCRETE:7)
Block(-5,2,6,CONCRETE:7)
Block(-5,2,7,CONCRETE:7)
Block(-5,2,8,CONCRETE:7)
Block(-5,3,-7,CONCRETE:7)
Block(-5,3,-6,CONCRETE:7)
Block(-5,3,-5,CONCRETE:7)
Block(-5,3,-4,CONCRETE:7)
Block(-5,3,-3,CONCRETE:7)
Block(-5,3,-2,CONCRETE:7)
Block(-5,3,-1,CONCRETE:7)
Block(-5,3,0,CONCRETE:7)
Block(-5,3,1,CONCRETE:7)
Block(-5,3,2,CONCRETE:7)
Block(-5,3,3,CONCRETE:7)
Block(-5,3,4,CONCRETE:7)
Block(-5,3,5,CONCRETE:7)
Block(-5,3,6,CONCRETE:7)
Block(-5,3,7,SMOOTH_STAIRS:1)
Block(-5,3,8,SMOOTH_STAIRS:1)
Block(-5,4,-7,CONCRETE:7)
Block(-5,4,-6,CONCRETE:7)
Block(-5,4,-5,CONCRETE:7)
Block(-5,4,-4,CONCRETE:7)
Block(-5,4,-3,CONCRETE:7)
Block(-5,4,-2,CONCRETE:7)
Block(-5,4,-1,CONCRETE:7)
Block(-5,4,0,CONCRETE:7)
Block(-5,4,1,CONCRETE:7)
Block(-5,4,2,CONCRETE:7)
Block(-5,4,3,CONCRETE:7)
Block(-5,4,4,CONCRETE:7)
Block(-5,4,5,CONCRETE:7)
Block(-5,4,6,CONCRETE:7)
Block(-5,4,7,COBBLE_WALL:0)
Block(-5,4,8,COBBLE_WALL:0)
Block(-5,5,-7,CONCRETE:7)
Block(-5,5,-6,CONCRETE:7)
Block(-5,5,-5,CONCRETE:7)
Block(-5,5,-4,CONCRETE:7)
Block(-5,5,-3,CONCRETE:7)
Block(-5,5,-2,CONCRETE:7)
Block(-5,5,-1,CONCRETE:7)
Block(-5,5,0,CONCRETE:7)
Block(-5,5,1,CONCRETE:7)
Block(-5,5,2,CONCRETE:7)
Block(-5,5,3,CONCRETE:7)
Block(-5,5,4,CONCRETE:7)
Block(-5,5,5,CONCRETE:7)
Block(-5,5,6,CONCRETE:7)
Block(-5,5,7,SMOOTH_STAIRS:5)
Block(-5,5,8,SMOOTH_STAIRS:5)
Block(-5,6,-7,CONCRETE:7)
Block(-5,6,-6,CONCRETE:7)
Block(-5,6,-5,CONCRETE:7)
Block(-5,6,-4,CONCRETE:7)
Block(-5,6,-3,CONCRETE:7)
Block(-5,6,-2,CONCRETE:7)
Block(-5,6,-1,CONCRETE:7)
Block(-5,6,0,CONCRETE:7)
Block(-5,6,1,CONCRETE:7)
Block(-5,6,2,CONCRETE:7)
Block(-5,6,3,CONCRETE:7)
Block(-5,6,4,CONCRETE:7)
Block(-5,6,5,CONCRETE:7)
Block(-5,6,6,CONCRETE:7)
Block(-5,6,7,CONCRETE:7)
Block(-5,6,8,CONCRETE:7)
Block(-5,7,-7,CONCRETE:7)
Block(-5,7,-6,CONCRETE:7)
Block(-5,7,-5,CONCRETE:7)
Block(-5,7,-4,CONCRETE:7)
Block(-5,7,-3,CONCRETE:7)
Block(-5,7,-2,CONCRETE:7)
Block(-5,7,-1,CONCRETE:7)
Block(-5,7,0,CONCRETE:7)
Block(-5,7,1,CONCRETE:7)
Block(-5,7,2,CONCRETE:7)
Block(-5,7,3,CONCRETE:7)
Block(-5,7,4,CONCRETE:7)
Block(-5,7,5,CONCRETE:7)
Block(-5,7,6,CONCRETE:7)
Block(-5,7,7,CONCRETE:7)
Block(-5,7,8,CONCRETE:7)
Block(-5,8,-7,CONCRETE:7)
Block(-5,8,-5,CONCRETE:15)
Block(-5,8,-4,DIODE_BLOCK_OFF:15)
Block(-5,8,-3,CONCRETE:15)
Block(-5,8,0,CONCRETE:15)
Block(-5,8,1,DIODE_BLOCK_OFF:15)
Block(-5,8,2,CONCRETE:15)
Block(-5,8,4,CONCRETE:7)
Block(-5,8,5,CONCRETE:7)
Block(-5,8,6,CONCRETE:7)
Block(-5,8,7,CONCRETE:7)
Block(-5,8,8,CONCRETE:7)
Block(-5,9,-7,CONCRETE:7)
Block(-5,9,-5,CONCRETE:15)
Block(-5,9,-4,CONCRETE:15)
Block(-5,9,-3,CONCRETE:15)
Block(-5,9,0,CONCRETE:15)
Block(-5,9,1,CONCRETE:15)
Block(-5,9,2,CONCRETE:15)
Block(-5,9,4,CONCRETE:7)
Block(-5,9,5,CONCRETE:7)
Block(-5,9,6,CONCRETE:7)
Block(-5,9,7,CONCRETE:7)
Block(-5,9,8,CONCRETE:7)
Block(-5,10,-7,CONCRETE:7)
Block(-5,10,-5,CONCRETE:15)
Block(-5,10,-4,CONCRETE:15)
Block(-5,10,-3,CONCRETE:15)
Block(-5,10,0,CONCRETE:15)
Block(-5,10,1,CONCRETE:15)
Block(-5,10,2,CONCRETE:15)
Block(-5,10,4,CONCRETE:7)
Block(-5,10,5,CONCRETE:7)
Block(-5,10,6,CONCRETE:7)
Block(-5,10,7,CONCRETE:7)
Block(-5,10,8,CONCRETE:7)
Block(-5,11,-7,CONCRETE:7)
Block(-5,11,-6,CONCRETE:7)
Block(-5,11,-5,CONCRETE:7)
Block(-5,11,-4,CONCRETE:7)
Block(-5,11,-3,CONCRETE:7)
Block(-5,11,-2,CONCRETE:7)
Block(-5,11,-1,CONCRETE:7)
Block(-5,11,0,CONCRETE:7)
Block(-5,11,1,CONCRETE:7)
Block(-5,11,2,CONCRETE:7)
Block(-5,11,3,CONCRETE:7)
Block(-5,11,4,CONCRETE:7)
Block(-5,11,5,CONCRETE:7)
Block(-5,11,6,CONCRETE:7)
Block(-5,11,7,CONCRETE:7)
Block(-5,11,8,CONCRETE:7)
Block(-5,12,-7,CONCRETE:7)
Block(-5,12,-6,CONCRETE:7)
Block(-5,12,-5,CONCRETE:7)
Block(-5,12,-4,CONCRETE:7)
Block(-5,12,-3,CONCRETE:7)
Block(-5,12,-2,CONCRETE:7)
Block(-5,12,-1,QUARTZ_STAIRS:7)
Block(-5,12,0,STEP:15)
Block(-5,12,1,STEP:15)
Block(-5,12,2,QUARTZ_STAIRS:6)
Block(-5,12,3,CONCRETE:7)
Block(-5,12,4,CONCRETE:7)
Block(-5,12,5,CONCRETE:7)
Block(-5,12,6,CONCRETE:7)
Block(-5,12,7,CONCRETE:7)
Block(-5,12,8,CONCRETE:7)
Block(-5,13,-7,CONCRETE:7)
Block(-5,13,-6,CONCRETE:7)
Block(-5,13,-5,CONCRETE:7)
Block(-5,13,-4,CONCRETE:7)
Block(-5,13,-3,CONCRETE:7)
Block(-5,13,-2,CONCRETE:7)
Block(-5,13,3,CONCRETE:7)
Block(-5,13,4,CONCRETE:7)
Block(-5,13,5,CONCRETE:7)
Block(-5,13,6,CONCRETE:7)
Block(-5,13,7,CONCRETE:7)
Block(-5,13,8,CONCRETE:7)
Block(-5,14,-7,CONCRETE:7)
Block(-5,14,-6,CONCRETE:7)
Block(-5,14,-5,CONCRETE:7)
Block(-5,14,-4,CONCRETE:7)
Block(-5,14,-3,CONCRETE:7)
Block(-5,14,-2,CONCRETE:7)
Block(-5,14,-1,CONCRETE:7)
Block(-5,14,0,CONCRETE:7)
Block(-5,14,1,CONCRETE:7)
Block(-5,14,2,CONCRETE:7)
Block(-5,14,3,CONCRETE:7)
Block(-5,14,4,CONCRETE:7)
Block(-5,14,5,CONCRETE:7)
Block(-5,14,6,CONCRETE:7)
Block(-5,14,7,CONCRETE:7)
Block(-5,14,8,CONCRETE:7)
Block(-5,15,-7,CONCRETE:7)
Block(-5,15,-6,CONCRETE:7)
Block(-5,15,-5,CONCRETE:7)
Block(-5,15,-4,CONCRETE:7)
Block(-5,15,-3,CONCRETE:7)
Block(-5,15,-2,CONCRETE:7)
Block(-5,15,-1,CONCRETE:7)
Block(-5,15,0,CONCRETE:7)
Block(-5,15,1,CONCRETE:7)
Block(-5,15,2,CONCRETE:7)
Block(-5,15,3,CONCRETE:7)
Block(-5,15,4,CONCRETE:7)
Block(-5,15,5,CONCRETE:7)
Block(-5,15,6,CONCRETE:7)
Block(-5,15,7,CONCRETE:7)
Block(-5,15,8,CONCRETE:7)
Block(-5,16,-7,CONCRETE:7)
Block(-5,16,-6,CONCRETE:7)
Block(-5,16,-5,CONCRETE:7)
Block(-5,16,-4,CONCRETE:7)
Block(-5,16,-3,CONCRETE:7)
Block(-5,16,-2,CONCRETE:7)
Block(-5,16,-1,CONCRETE:7)
Block(-5,16,0,CONCRETE:7)
Block(-5,16,1,CONCRETE:7)
Block(-5,16,2,CONCRETE:7)
Block(-5,16,3,CONCRETE:7)
Block(-5,16,4,CONCRETE:7)
Block(-5,16,5,CONCRETE:7)
Block(-5,16,6,CONCRETE:7)
Block(-5,16,7,CONCRETE:7)
Block(-5,16,8,CONCRETE:7)
Block(-5,17,-7,CONCRETE:7)
Block(-5,17,-6,CONCRETE:7)
Block(-5,17,-5,CONCRETE:7)
Block(-5,17,-4,CONCRETE:7)
Block(-5,17,-3,CONCRETE:7)
Block(-5,17,-2,CONCRETE:7)
Block(-5,17,-1,CONCRETE:7)
Block(-5,17,0,CONCRETE:7)
Block(-5,17,1,CONCRETE:7)
Block(-5,17,2,CONCRETE:7)
Block(-5,17,3,CONCRETE:7)
Block(-5,17,4,CONCRETE:7)
Block(-5,17,5,CONCRETE:8)
Block(-5,17,6,CONCRETE:8)
Block(-5,17,7,CONCRETE:8)
Block(-5,17,8,CONCRETE:8)
Block(-5,18,-3,CONCRETE:7)
Block(-5,18,5,STAINED_GLASS_PANE:15)
Block(-5,18,6,STAINED_GLASS_PANE:15)
Block(-5,18,7,STAINED_GLASS_PANE:15)
Block(-5,18,8,STAINED_GLASS_PANE:15)
Block(-5,19,-3,CONCRETE:7)
Block(-5,19,5,STAINED_GLASS_PANE:15)
Block(-5,19,6,STAINED_GLASS_PANE:15)
Block(-5,19,7,STAINED_GLASS_PANE:15)
Block(-5,19,8,STAINED_GLASS_PANE:15)
Block(-5,20,-3,CONCRETE:7)
Block(-5,21,-3,CONCRETE:7)
Block(-5,22,-3,CONCRETE:7)
Block(-5,22,-2,STAINED_GLASS:15)
Block(-5,22,-1,CONCRETE:7)
Block(-5,22,0,STAINED_GLASS:15)
Block(-5,22,1,CONCRETE:7)
Block(-5,22,2,STAINED_GLASS:15)
Block(-5,22,3,STAINED_GLASS:15)
Block(-5,22,4,CONCRETE:7)
Block(-5,22,5,STAINED_GLASS_PANE:15)
Block(-5,23,-3,CONCRETE:7)
Block(-5,23,-2,TRAP_DOOR:14)
Block(-5,23,1,WALL_SIGN:2,NBT/skyscraper_2x2_03/43-signC0R0.nbt)
Block(-5,23,2,DARK_OAK_STAIRS:1)
Block(-5,23,3,DARK_OAK_STAIRS:1)
Block(-5,23,4,WALL_SIGN:3,NBT/skyscraper_2x2_03/44-signC0R0.nbt)
Block(-5,23,5,STAINED_GLASS_PANE:15)
Block(-5,24,-3,CONCRETE:7)
Block(-5,25,-3,CONCRETE:7)
Block(-5,26,-3,CONCRETE:7)
Block(-5,26,5,STAINED_GLASS_PANE:15)
Block(-5,26,6,CONCRETE:7)
Block(-5,26,7,STAINED_GLASS:15)
Block(-5,26,8,CONCRETE:7)
Block(-5,27,-3,CONCRETE:7)
Block(-5,27,5,STAINED_GLASS_PANE:15)
Block(-5,27,7,QUARTZ_STAIRS:7)
Block(-5,27,8,STANDING_BANNER:3,NBT/skyscraper_2x2_03/45-bannerC0R0.nbt)
Block(-5,28,-3,CONCRETE:7)
Block(-5,28,-1,STEP:8)
Block(-5,28,7,IRON_TRAPDOOR:1)
Block(-5,28,8,IRON_TRAPDOOR:1)
Block(-5,29,-3,CONCRETE:7)
Block(-5,29,-1,IRON_FENCE:0)
Block(-5,30,-3,CONCRETE:7)
Block(-5,30,-1,IRON_FENCE:0)
Block(-5,31,-3,CONCRETE:7)
Block(-5,31,-2,STAINED_GLASS:15)
Block(-5,31,-1,CONCRETE:7)
Block(-5,31,0,STAINED_GLASS:15)
Block(-5,31,1,CONCRETE:7)
Block(-5,31,2,STAINED_GLASS_PANE:15)
Block(-5,32,-3,CONCRETE:7)
Block(-5,32,2,STAINED_GLASS_PANE:15)
Block(-5,33,-3,CONCRETE:7)
Block(-5,33,-1,WALL_BANNER:5,NBT/skyscraper_2x2_03/49-bannerC0R0.nbt)
Block(-5,33,0,WALL_BANNER:5,NBT/skyscraper_2x2_03/50-bannerC0R0.nbt)
Block(-5,34,-3,CONCRETE:7)
Block(-5,35,-3,CONCRETE:7)
Block(-5,36,-3,CONCRETE:7)
Block(-5,37,-3,CONCRETE:7)
Block(-5,37,4,STAINED_GLASS_PANE:15)
Block(-5,37,5,STAINED_GLASS:15)
Block(-5,37,6,CONCRETE:7)
Block(-5,37,7,CONCRETE:7)
Block(-5,37,8,CONCRETE:7)
Block(-5,38,-3,CONCRETE:7)
Block(-5,38,4,STAINED_GLASS_PANE:15)
Block(-5,38,6,QUARTZ_STAIRS:7)
Block(-5,38,7,STANDING_BANNER:3,NBT/skyscraper_2x2_03/51-bannerC0R0.nbt)
Block(-5,38,8,STANDING_BANNER:4,NBT/skyscraper_2x2_03/52-bannerC0R0.nbt)
Block(-5,39,-3,CONCRETE:7)
Block(-5,39,6,IRON_TRAPDOOR:1)
Block(-5,39,7,IRON_TRAPDOOR:1)
Block(-5,39,8,IRON_TRAPDOOR:1)
Block(-5,40,-3,CONCRETE:7)
Block(-5,41,-3,CONCRETE:7)
Block(-5,42,-5,CONCRETE:7)
Block(-5,42,-4,CONCRETE:7)
Block(-5,42,-3,CONCRETE:7)
Block(-5,42,-2,CONCRETE:7)
Block(-5,42,-1,CONCRETE:7)
Block(-5,42,0,CONCRETE:7)
Block(-5,42,1,CONCRETE:8)
Block(-5,42,2,CONCRETE:8)
Block(-5,42,3,CONCRETE:8)
Block(-5,42,4,CONCRETE:7)
Block(-5,42,5,STAINED_GLASS:15)
Block(-5,42,6,CONCRETE:7)
Block(-5,42,7,STAINED_GLASS:15)
Block(-5,42,8,CONCRETE:7)
Block(-5,43,-5,STAINED_GLASS:15)
Block(-5,43,-4,IRON_TRAPDOOR:11)
Block(-5,43,-3,IRON_TRAPDOOR:11)
Block(-5,43,-2,IRON_TRAPDOOR:11)
Block(-5,43,-1,IRON_TRAPDOOR:11)
Block(-5,43,0,CONCRETE:7)
Block(-5,43,4,CONCRETE:7)
Block(-5,44,-5,STAINED_GLASS:15)
Block(-5,44,-4,WORKBENCH:0)
#RandomBlock(-5,44,-2,TRAPPED_CHEST:5,../../../../../Chests/Loot/ModernCityJunk_1.nbt,65,CHEST:5,../../../../../Chests/Loot/ModernCityJunk_1.nbt,20,CHEST:5,../../../../../Chests/Loot/ModernCityJunk_2.nbt,15,CHEST:5,../../../../../Chests/Loot/ModernCityJunk_3.nbt,15,CHEST:5,../../../../../Chests/Loot/ModernCityJunk_4.nbt,15,CHEST:5,../../../../../Chests/Loot/ModernCityJunk_5.nbt,15,CHEST:5,../../../../../Chests/Loot/ModernCityCommon_1.nbt,5,CHEST:5,../../../../../Chests/Loot/ModernCityCommon_2.nbt,5,CHEST:5,../../../../../Chests/Loot/ModernCityCommon_3.nbt,5,CHEST:5,../../../../../Chests/Loot/ModernCityCommon_4.nbt,5,CHEST:5,../../../../../Chests/Loot/ModernCityCommon_5.nbt,5,CHEST:5,../../../../../Chests/Loot/ModernCityGood_1.nbt,3,CHEST:5,../../../../../Chests/Loot/ModernCityGood_2.nbt,3,CHEST:5,../../../../../Chests/Loot/ModernCityGood_3.nbt,3,CHEST:5,../../../../../Chests/Loot/ModernCityGood_4.nbt,3,CHEST:5,../../../../../Chests/Loot/ModernCityGood_5.nbt,3,CHEST:5,../../../../../Chests/Loot/ModernCityEpic_1.nbt,1,CHEST:5,../../../../../Chests/Loot/ModernCityEpic_2.nbt,1,CHEST:5,../../../../../Chests/Loot/ModernCityEpic_3.nbt,1,CHEST:5,../../../../../Chests/Loot/ModernCityEpic_4.nbt,1,CHEST:5,../../../../../Chests/Loot/ModernCityEpic_5.nbt,1,CHEST:5,../../../../../Chests/Loot/Common1.nbt,25,CHEST:5,../../../../../Chests/Loot/Common2.nbt,25,CHEST:5,../../../../../Chests/Loot/Common3.nbt,25,CHEST:5,../../../../../Chests/Loot/Common4.nbt,25,CHEST:5,../../../../../Chests/Loot/Common5.nbt,25,CHEST:5,../../../../../Chests/Loot/Common6.nbt,25,CHEST:5,../../../../../Chests/Loot/Common7.nbt,25,CHEST:5,../../../../../Chests/Loot/Common8.nbt,25,CHEST:5,../../../../../Chests/Loot/Common9.nbt,25,CHEST:5,../../../../../Chests/Loot/Common10.nbt,25,CHEST:5,../../../../../Chests/Loot/Common11.nbt,25,CHEST:5,../../../../../Chests/Loot/Common12.nbt,25,CHEST:5,../../../../../Chests/Loot/Common13.nbt,25,CHEST:5,../../../../../Chests/Loot/Common14.nbt,25,CHEST:5,../../../../../Chests/Loot/Common15.nbt,25,CHEST:5,../../../../../Chests/Loot/Rare1.nbt,10,CHEST:5,../../../../../Chests/Loot/Rare2.nbt,10,CHEST:5,../../../../../Chests/Loot/Rare3.nbt,10,CHEST:5,../../../../../Chests/Loot/Rare4.nbt,10,CHEST:5,../../../../../Chests/Loot/Rare5.nbt,10,CHEST:5,../../../../../Chests/Loot/Rare6.nbt,10,CHEST:5,../../../../../Chests/Loot/Rare7.nbt,10,CHEST:5,../../../../../Chests/Loot/Rare8.nbt,10,CHEST:5,../../../../../Chests/Loot/Rare9.nbt,10,CHEST:5,../../../../../Chests/Loot/Rare10.nbt,10,CHEST:5,../../../../../Chests/Loot/Rare11.nbt,10,CHEST:5,../../../../../Chests/Loot/Rare12.nbt,10,CHEST:5,../../../../../Chests/Loot/Rare13.nbt,10,CHEST:5,../../../../../Chests/Loot/Rare14.nbt,10,CHEST:5,../../../../../Chests/Loot/Rare15.nbt,10,CHEST:5,../../../../../Chests/Loot/Epic1.nbt,1,CHEST:5,../../../../../Chests/Loot/Epic2.nbt,1,CHEST:5,../../../../../Chests/Loot/Epic3.nbt,1,CHEST:5,../../../../../Chests/Loot/Epic4.nbt,1,CHEST:5,../../../../../Chests/Loot/Epic5.nbt,1,CHEST:5,../../../../../Chests/Loot/Epic6.nbt,1,CHEST:5,../../../../../Chests/Loot/Epic7.nbt,1,CHEST:5,../../../../../Chests/Loot/Epic8.nbt,1,CHEST:5,../../../../../Chests/Loot/Epic9.nbt,1,CHEST:5,../../../../../Chests/Loot/Epic10.nbt,1,CHEST:5,../../../../../Chests/Loot/Epic11.nbt,1,CHEST:5,../../../../../Chests/Loot/Epic12.nbt,1,CHEST:5,../../../../../Chests/Loot/Epic13.nbt,1,CHEST:5,../../../../../Chests/Loot/Epic14.nbt,1,CHEST:5,../../../../../Chests/Loot/Epic15.nbt,1,CHEST:5,../../../../../Chests/Loot/ModernCityJunk_1.nbt,100)
#RandomBlock(-5,44,-1,TRAPPED_CHEST:5,../../../../../Chests/Loot/ModernCityJunk_1.nbt,65,CHEST:5,../../../../../Chests/Loot/ModernCityJunk_1.nbt,20,CHEST:5,../../../../../Chests/Loot/ModernCityJunk_2.nbt,15,CHEST:5,../../../../../Chests/Loot/ModernCityJunk_3.nbt,15,CHEST:5,../../../../../Chests/Loot/ModernCityJunk_4.nbt,15,CHEST:5,../../../../../Chests/Loot/ModernCityJunk_5.nbt,15,CHEST:5,../../../../../Chests/Loot/ModernCityCommon_1.nbt,5,CHEST:5,../../../../../Chests/Loot/ModernCityCommon_2.nbt,5,CHEST:5,../../../../../Chests/Loot/ModernCityCommon_3.nbt,5,CHEST:5,../../../../../Chests/Loot/ModernCityCommon_4.nbt,5,CHEST:5,../../../../../Chests/Loot/ModernCityCommon_5.nbt,5,CHEST:5,../../../../../Chests/Loot/ModernCityGood_1.nbt,3,CHEST:5,../../../../../Chests/Loot/ModernCityGood_2.nbt,3,CHEST:5,../../../../../Chests/Loot/ModernCityGood_3.nbt,3,CHEST:5,../../../../../Chests/Loot/ModernCityGood_4.nbt,3,CHEST:5,../../../../../Chests/Loot/ModernCityGood_5.nbt,3,CHEST:5,../../../../../Chests/Loot/ModernCityEpic_1.nbt,1,CHEST:5,../../../../../Chests/Loot/ModernCityEpic_2.nbt,1,CHEST:5,../../../../../Chests/Loot/ModernCityEpic_3.nbt,1,CHEST:5,../../../../../Chests/Loot/ModernCityEpic_4.nbt,1,CHEST:5,../../../../../Chests/Loot/ModernCityEpic_5.nbt,1,CHEST:5,../../../../../Chests/Loot/Common1.nbt,25,CHEST:5,../../../../../Chests/Loot/Common2.nbt,25,CHEST:5,../../../../../Chests/Loot/Common3.nbt,25,CHEST:5,../../../../../Chests/Loot/Common4.nbt,25,CHEST:5,../../../../../Chests/Loot/Common5.nbt,25,CHEST:5,../../../../../Chests/Loot/Common6.nbt,25,CHEST:5,../../../../../Chests/Loot/Common7.nbt,25,CHEST:5,../../../../../Chests/Loot/Common8.nbt,25,CHEST:5,../../../../../Chests/Loot/Common9.nbt,25,CHEST:5,../../../../../Chests/Loot/Common10.nbt,25,CHEST:5,../../../../../Chests/Loot/Common11.nbt,25,CHEST:5,../../../../../Chests/Loot/Common12.nbt,25,CHEST:5,../../../../../Chests/Loot/Common13.nbt,25,CHEST:5,../../../../../Chests/Loot/Common14.nbt,25,CHEST:5,../../../../../Chests/Loot/Common15.nbt,25,CHEST:5,../../../../../Chests/Loot/Rare1.nbt,10,CHEST:5,../../../../../Chests/Loot/Rare2.nbt,10,CHEST:5,../../../../../Chests/Loot/Rare3.nbt,10,CHEST:5,../../../../../Chests/Loot/Rare4.nbt,10,CHEST:5,../../../../../Chests/Loot/Rare5.nbt,10,CHEST:5,../../../../../Chests/Loot/Rare6.nbt,10,CHEST:5,../../../../../Chests/Loot/Rare7.nbt,10,CHEST:5,../../../../../Chests/Loot/Rare8.nbt,10,CHEST:5,../../../../../Chests/Loot/Rare9.nbt,10,CHEST:5,../../../../../Chests/Loot/Rare10.nbt,10,CHEST:5,../../../../../Chests/Loot/Rare11.nbt,10,CHEST:5,../../../../../Chests/Loot/Rare12.nbt,10,CHEST:5,../../../../../Chests/Loot/Rare13.nbt,10,CHEST:5,../../../../../Chests/Loot/Rare14.nbt,10,CHEST:5,../../../../../Chests/Loot/Rare15.nbt,10,CHEST:5,../../../../../Chests/Loot/Epic1.nbt,1,CHEST:5,../../../../../Chests/Loot/Epic2.nbt,1,CHEST:5,../../../../../Chests/Loot/Epic3.nbt,1,CHEST:5,../../../../../Chests/Loot/Epic4.nbt,1,CHEST:5,../../../../../Chests/Loot/Epic5.nbt,1,CHEST:5,../../../../../Chests/Loot/Epic6.nbt,1,CHEST:5,../../../../../Chests/Loot/Epic7.nbt,1,CHEST:5,../../../../../Chests/Loot/Epic8.nbt,1,CHEST:5,../../../../../Chests/Loot/Epic9.nbt,1,CHEST:5,../../../../../Chests/Loot/Epic10.nbt,1,CHEST:5,../../../../../Chests/Loot/Epic11.nbt,1,CHEST:5,../../../../../Chests/Loot/Epic12.nbt,1,CHEST:5,../../../../../Chests/Loot/Epic13.nbt,1,CHEST:5,../../../../../Chests/Loot/Epic14.nbt,1,CHEST:5,../../../../../Chests/Loot/Epic15.nbt,1,CHEST:5,../../../../../Chests/Loot/ModernCityJunk_1.nbt,100)
Block(-5,44,0,CONCRETE:7)
Block(-5,44,4,CONCRETE:7)
Block(-5,44,6,WALL_BANNER:5,NBT/skyscraper_2x2_03/57-bannerC0R0.nbt)
Block(-5,44,7,WALL_BANNER:5,NBT/skyscraper_2x2_03/58-bannerC0R0.nbt)
Block(-5,45,-5,STAINED_GLASS:15)
Block(-5,45,-4,IRON_TRAPDOOR:11)
Block(-5,45,-3,IRON_TRAPDOOR:11)
Block(-5,45,-2,IRON_TRAPDOOR:11)
Block(-5,45,-1,IRON_TRAPDOOR:8)
Block(-5,45,0,CONCRETE:7)
Block(-5,45,4,CONCRETE:7)
Block(-5,46,-5,STAINED_GLASS:15)
#RandomBlock(-5,46,-4,TRAPPED_CHEST:5,../../../../../Chests/Loot/ModernCityJunk_1.nbt,65,CHEST:5,../../../../../Chests/Loot/ModernCityJunk_1.nbt,20,CHEST:5,../../../../../Chests/Loot/ModernCityJunk_2.nbt,15,CHEST:5,../../../../../Chests/Loot/ModernCityJunk_3.nbt,15,CHEST:5,../../../../../Chests/Loot/ModernCityJunk_4.nbt,15,CHEST:5,../../../../../Chests/Loot/ModernCityJunk_5.nbt,15,CHEST:5,../../../../../Chests/Loot/ModernCityCommon_1.nbt,5,CHEST:5,../../../../../Chests/Loot/ModernCityCommon_2.nbt,5,CHEST:5,../../../../../Chests/Loot/ModernCityCommon_3.nbt,5,CHEST:5,../../../../../Chests/Loot/ModernCityCommon_4.nbt,5,CHEST:5,../../../../../Chests/Loot/ModernCityCommon_5.nbt,5,CHEST:5,../../../../../Chests/Loot/ModernCityGood_1.nbt,3,CHEST:5,../../../../../Chests/Loot/ModernCityGood_2.nbt,3,CHEST:5,../../../../../Chests/Loot/ModernCityGood_3.nbt,3,CHEST:5,../../../../../Chests/Loot/ModernCityGood_4.nbt,3,CHEST:5,../../../../../Chests/Loot/ModernCityGood_5.nbt,3,CHEST:5,../../../../../Chests/Loot/ModernCityEpic_1.nbt,1,CHEST:5,../../../../../Chests/Loot/ModernCityEpic_2.nbt,1,CHEST:5,../../../../../Chests/Loot/ModernCityEpic_3.nbt,1,CHEST:5,../../../../../Chests/Loot/ModernCityEpic_4.nbt,1,CHEST:5,../../../../../Chests/Loot/ModernCityEpic_5.nbt,1,CHEST:5,../../../../../Chests/Loot/Common1.nbt,25,CHEST:5,../../../../../Chests/Loot/Common2.nbt,25,CHEST:5,../../../../../Chests/Loot/Common3.nbt,25,CHEST:5,../../../../../Chests/Loot/Common4.nbt,25,CHEST:5,../../../../../Chests/Loot/Common5.nbt,25,CHEST:5,../../../../../Chests/Loot/Common6.nbt,25,CHEST:5,../../../../../Chests/Loot/Common7.nbt,25,CHEST:5,../../../../../Chests/Loot/Common8.nbt,25,CHEST:5,../../../../../Chests/Loot/Common9.nbt,25,CHEST:5,../../../../../Chests/Loot/Common10.nbt,25,CHEST:5,../../../../../Chests/Loot/Common11.nbt,25,CHEST:5,../../../../../Chests/Loot/Common12.nbt,25,CHEST:5,../../../../../Chests/Loot/Common13.nbt,25,CHEST:5,../../../../../Chests/Loot/Common14.nbt,25,CHEST:5,../../../../../Chests/Loot/Common15.nbt,25,CHEST:5,../../../../../Chests/Loot/Rare1.nbt,10,CHEST:5,../../../../../Chests/Loot/Rare2.nbt,10,CHEST:5,../../../../../Chests/Loot/Rare3.nbt,10,CHEST:5,../../../../../Chests/Loot/Rare4.nbt,10,CHEST:5,../../../../../Chests/Loot/Rare5.nbt,10,CHEST:5,../../../../../Chests/Loot/Rare6.nbt,10,CHEST:5,../../../../../Chests/Loot/Rare7.nbt,10,CHEST:5,../../../../../Chests/Loot/Rare8.nbt,10,CHEST:5,../../../../../Chests/Loot/Rare9.nbt,10,CHEST:5,../../../../../Chests/Loot/Rare10.nbt,10,CHEST:5,../../../../../Chests/Loot/Rare11.nbt,10,CHEST:5,../../../../../Chests/Loot/Rare12.nbt,10,CHEST:5,../../../../../Chests/Loot/Rare13.nbt,10,CHEST:5,../../../../../Chests/Loot/Rare14.nbt,10,CHEST:5,../../../../../Chests/Loot/Rare15.nbt,10,CHEST:5,../../../../../Chests/Loot/Epic1.nbt,1,CHEST:5,../../../../../Chests/Loot/Epic2.nbt,1,CHEST:5,../../../../../Chests/Loot/Epic3.nbt,1,CHEST:5,../../../../../Chests/Loot/Epic4.nbt,1,CHEST:5,../../../../../Chests/Loot/Epic5.nbt,1,CHEST:5,../../../../../Chests/Loot/Epic6.nbt,1,CHEST:5,../../../../../Chests/Loot/Epic7.nbt,1,CHEST:5,../../../../../Chests/Loot/Epic8.nbt,1,CHEST:5,../../../../../Chests/Loot/Epic9.nbt,1,CHEST:5,../../../../../Chests/Loot/Epic10.nbt,1,CHEST:5,../../../../../Chests/Loot/Epic11.nbt,1,CHEST:5,../../../../../Chests/Loot/Epic12.nbt,1,CHEST:5,../../../../../Chests/Loot/Epic13.nbt,1,CHEST:5,../../../../../Chests/Loot/Epic14.nbt,1,CHEST:5,../../../../../Chests/Loot/Epic15.nbt,1,CHEST:5,../../../../../Chests/Loot/ModernCityJunk_1.nbt,100)
#RandomBlock(-5,46,-3,TRAPPED_CHEST:5,../../../../../Chests/Loot/ModernCityJunk_1.nbt,65,CHEST:5,../../../../../Chests/Loot/ModernCityJunk_1.nbt,20,CHEST:5,../../../../../Chests/Loot/ModernCityJunk_2.nbt,15,CHEST:5,../../../../../Chests/Loot/ModernCityJunk_3.nbt,15,CHEST:5,../../../../../Chests/Loot/ModernCityJunk_4.nbt,15,CHEST:5,../../../../../Chests/Loot/ModernCityJunk_5.nbt,15,CHEST:5,../../../../../Chests/Loot/ModernCityCommon_1.nbt,5,CHEST:5,../../../../../Chests/Loot/ModernCityCommon_2.nbt,5,CHEST:5,../../../../../Chests/Loot/ModernCityCommon_3.nbt,5,CHEST:5,../../../../../Chests/Loot/ModernCityCommon_4.nbt,5,CHEST:5,../../../../../Chests/Loot/ModernCityCommon_5.nbt,5,CHEST:5,../../../../../Chests/Loot/ModernCityGood_1.nbt,3,CHEST:5,../../../../../Chests/Loot/ModernCityGood_2.nbt,3,CHEST:5,../../../../../Chests/Loot/ModernCityGood_3.nbt,3,CHEST:5,../../../../../Chests/Loot/ModernCityGood_4.nbt,3,CHEST:5,../../../../../Chests/Loot/ModernCityGood_5.nbt,3,CHEST:5,../../../../../Chests/Loot/ModernCityEpic_1.nbt,1,CHEST:5,../../../../../Chests/Loot/ModernCityEpic_2.nbt,1,CHEST:5,../../../../../Chests/Loot/ModernCityEpic_3.nbt,1,CHEST:5,../../../../../Chests/Loot/ModernCityEpic_4.nbt,1,CHEST:5,../../../../../Chests/Loot/ModernCityEpic_5.nbt,1,CHEST:5,../../../../../Chests/Loot/Common1.nbt,25,CHEST:5,../../../../../Chests/Loot/Common2.nbt,25,CHEST:5,../../../../../Chests/Loot/Common3.nbt,25,CHEST:5,../../../../../Chests/Loot/Common4.nbt,25,CHEST:5,../../../../../Chests/Loot/Common5.nbt,25,CHEST:5,../../../../../Chests/Loot/Common6.nbt,25,CHEST:5,../../../../../Chests/Loot/Common7.nbt,25,CHEST:5,../../../../../Chests/Loot/Common8.nbt,25,CHEST:5,../../../../../Chests/Loot/Common9.nbt,25,CHEST:5,../../../../../Chests/Loot/Common10.nbt,25,CHEST:5,../../../../../Chests/Loot/Common11.nbt,25,CHEST:5,../../../../../Chests/Loot/Common12.nbt,25,CHEST:5,../../../../../Chests/Loot/Common13.nbt,25,CHEST:5,../../../../../Chests/Loot/Common14.nbt,25,CHEST:5,../../../../../Chests/Loot/Common15.nbt,25,CHEST:5,../../../../../Chests/Loot/Rare1.nbt,10,CHEST:5,../../../../../Chests/Loot/Rare2.nbt,10,CHEST:5,../../../../../Chests/Loot/Rare3.nbt,10,CHEST:5,../../../../../Chests/Loot/Rare4.nbt,10,CHEST:5,../../../../../Chests/Loot/Rare5.nbt,10,CHEST:5,../../../../../Chests/Loot/Rare6.nbt,10,CHEST:5,../../../../../Chests/Loot/Rare7.nbt,10,CHEST:5,../../../../../Chests/Loot/Rare8.nbt,10,CHEST:5,../../../../../Chests/Loot/Rare9.nbt,10,CHEST:5,../../../../../Chests/Loot/Rare10.nbt,10,CHEST:5,../../../../../Chests/Loot/Rare11.nbt,10,CHEST:5,../../../../../Chests/Loot/Rare12.nbt,10,CHEST:5,../../../../../Chests/Loot/Rare13.nbt,10,CHEST:5,../../../../../Chests/Loot/Rare14.nbt,10,CHEST:5,../../../../../Chests/Loot/Rare15.nbt,10,CHEST:5,../../../../../Chests/Loot/Epic1.nbt,1,CHEST:5,../../../../../Chests/Loot/Epic2.nbt,1,CHEST:5,../../../../../Chests/Loot/Epic3.nbt,1,CHEST:5,../../../../../Chests/Loot/Epic4.nbt,1,CHEST:5,../../../../../Chests/Loot/Epic5.nbt,1,CHEST:5,../../../../../Chests/Loot/Epic6.nbt,1,CHEST:5,../../../../../Chests/Loot/Epic7.nbt,1,CHEST:5,../../../../../Chests/Loot/Epic8.nbt,1,CHEST:5,../../../../../Chests/Loot/Epic9.nbt,1,CHEST:5,../../../../../Chests/Loot/Epic10.nbt,1,CHEST:5,../../../../../Chests/Loot/Epic11.nbt,1,CHEST:5,../../../../../Chests/Loot/Epic12.nbt,1,CHEST:5,../../../../../Chests/Loot/Epic13.nbt,1,CHEST:5,../../../../../Chests/Loot/Epic14.nbt,1,CHEST:5,../../../../../Chests/Loot/Epic15.nbt,1,CHEST:5,../../../../../Chests/Loot/ModernCityJunk_1.nbt,100)
Block(-5,46,-1,WORKBENCH:0)
Block(-5,46,0,CONCRETE:7)
Block(-5,46,4,CONCRETE:7)
Block(-5,47,-5,STAINED_GLASS:15)
Block(-5,47,-4,IRON_TRAPDOOR:11)
Block(-5,47,-3,IRON_TRAPDOOR:11)
Block(-5,47,-2,IRON_TRAPDOOR:11)
Block(-5,47,-1,IRON_TRAPDOOR:8)
Block(-5,47,0,CONCRETE:7)
Block(-5,47,4,CONCRETE:7)
Block(-5,48,-5,STAINED_GLASS:15)
Block(-5,48,-4,DROPPER:5,NBT/skyscraper_2x2_03/66-dropperC0R0.nbt)
#RandomBlock(-5,48,-2,TRAPPED_CHEST:5,../../../../../Chests/Loot/ModernCityJunk_1.nbt,65,CHEST:5,../../../../../Chests/Loot/ModernCityJunk_1.nbt,20,CHEST:5,../../../../../Chests/Loot/ModernCityJunk_2.nbt,15,CHEST:5,../../../../../Chests/Loot/ModernCityJunk_3.nbt,15,CHEST:5,../../../../../Chests/Loot/ModernCityJunk_4.nbt,15,CHEST:5,../../../../../Chests/Loot/ModernCityJunk_5.nbt,15,CHEST:5,../../../../../Chests/Loot/ModernCityCommon_1.nbt,5,CHEST:5,../../../../../Chests/Loot/ModernCityCommon_2.nbt,5,CHEST:5,../../../../../Chests/Loot/ModernCityCommon_3.nbt,5,CHEST:5,../../../../../Chests/Loot/ModernCityCommon_4.nbt,5,CHEST:5,../../../../../Chests/Loot/ModernCityCommon_5.nbt,5,CHEST:5,../../../../../Chests/Loot/ModernCityGood_1.nbt,3,CHEST:5,../../../../../Chests/Loot/ModernCityGood_2.nbt,3,CHEST:5,../../../../../Chests/Loot/ModernCityGood_3.nbt,3,CHEST:5,../../../../../Chests/Loot/ModernCityGood_4.nbt,3,CHEST:5,../../../../../Chests/Loot/ModernCityGood_5.nbt,3,CHEST:5,../../../../../Chests/Loot/ModernCityEpic_1.nbt,1,CHEST:5,../../../../../Chests/Loot/ModernCityEpic_2.nbt,1,CHEST:5,../../../../../Chests/Loot/ModernCityEpic_3.nbt,1,CHEST:5,../../../../../Chests/Loot/ModernCityEpic_4.nbt,1,CHEST:5,../../../../../Chests/Loot/ModernCityEpic_5.nbt,1,CHEST:5,../../../../../Chests/Loot/Common1.nbt,25,CHEST:5,../../../../../Chests/Loot/Common2.nbt,25,CHEST:5,../../../../../Chests/Loot/Common3.nbt,25,CHEST:5,../../../../../Chests/Loot/Common4.nbt,25,CHEST:5,../../../../../Chests/Loot/Common5.nbt,25,CHEST:5,../../../../../Chests/Loot/Common6.nbt,25,CHEST:5,../../../../../Chests/Loot/Common7.nbt,25,CHEST:5,../../../../../Chests/Loot/Common8.nbt,25,CHEST:5,../../../../../Chests/Loot/Common9.nbt,25,CHEST:5,../../../../../Chests/Loot/Common10.nbt,25,CHEST:5,../../../../../Chests/Loot/Common11.nbt,25,CHEST:5,../../../../../Chests/Loot/Common12.nbt,25,CHEST:5,../../../../../Chests/Loot/Common13.nbt,25,CHEST:5,../../../../../Chests/Loot/Common14.nbt,25,CHEST:5,../../../../../Chests/Loot/Common15.nbt,25,CHEST:5,../../../../../Chests/Loot/Rare1.nbt,10,CHEST:5,../../../../../Chests/Loot/Rare2.nbt,10,CHEST:5,../../../../../Chests/Loot/Rare3.nbt,10,CHEST:5,../../../../../Chests/Loot/Rare4.nbt,10,CHEST:5,../../../../../Chests/Loot/Rare5.nbt,10,CHEST:5,../../../../../Chests/Loot/Rare6.nbt,10,CHEST:5,../../../../../Chests/Loot/Rare7.nbt,10,CHEST:5,../../../../../Chests/Loot/Rare8.nbt,10,CHEST:5,../../../../../Chests/Loot/Rare9.nbt,10,CHEST:5,../../../../../Chests/Loot/Rare10.nbt,10,CHEST:5,../../../../../Chests/Loot/Rare11.nbt,10,CHEST:5,../../../../../Chests/Loot/Rare12.nbt,10,CHEST:5,../../../../../Chests/Loot/Rare13.nbt,10,CHEST:5,../../../../../Chests/Loot/Rare14.nbt,10,CHEST:5,../../../../../Chests/Loot/Rare15.nbt,10,CHEST:5,../../../../../Chests/Loot/Epic1.nbt,1,CHEST:5,../../../../../Chests/Loot/Epic2.nbt,1,CHEST:5,../../../../../Chests/Loot/Epic3.nbt,1,CHEST:5,../../../../../Chests/Loot/Epic4.nbt,1,CHEST:5,../../../../../Chests/Loot/Epic5.nbt,1,CHEST:5,../../../../../Chests/Loot/Epic6.nbt,1,CHEST:5,../../../../../Chests/Loot/Epic7.nbt,1,CHEST:5,../../../../../Chests/Loot/Epic8.nbt,1,CHEST:5,../../../../../Chests/Loot/Epic9.nbt,1,CHEST:5,../../../../../Chests/Loot/Epic10.nbt,1,CHEST:5,../../../../../Chests/Loot/Epic11.nbt,1,CHEST:5,../../../../../Chests/Loot/Epic12.nbt,1,CHEST:5,../../../../../Chests/Loot/Epic13.nbt,1,CHEST:5,../../../../../Chests/Loot/Epic14.nbt,1,CHEST:5,../../../../../Chests/Loot/Epic15.nbt,1,CHEST:5,../../../../../Chests/Loot/ModernCityJunk_1.nbt,100)
#RandomBlock(-5,48,-1,TRAPPED_CHEST:5,../../../../../Chests/Loot/ModernCityJunk_1.nbt,65,CHEST:5,../../../../../Chests/Loot/ModernCityJunk_1.nbt,20,CHEST:5,../../../../../Chests/Loot/ModernCityJunk_2.nbt,15,CHEST:5,../../../../../Chests/Loot/ModernCityJunk_3.nbt,15,CHEST:5,../../../../../Chests/Loot/ModernCityJunk_4.nbt,15,CHEST:5,../../../../../Chests/Loot/ModernCityJunk_5.nbt,15,CHEST:5,../../../../../Chests/Loot/ModernCityCommon_1.nbt,5,CHEST:5,../../../../../Chests/Loot/ModernCityCommon_2.nbt,5,CHEST:5,../../../../../Chests/Loot/ModernCityCommon_3.nbt,5,CHEST:5,../../../../../Chests/Loot/ModernCityCommon_4.nbt,5,CHEST:5,../../../../../Chests/Loot/ModernCityCommon_5.nbt,5,CHEST:5,../../../../../Chests/Loot/ModernCityGood_1.nbt,3,CHEST:5,../../../../../Chests/Loot/ModernCityGood_2.nbt,3,CHEST:5,../../../../../Chests/Loot/ModernCityGood_3.nbt,3,CHEST:5,../../../../../Chests/Loot/ModernCityGood_4.nbt,3,CHEST:5,../../../../../Chests/Loot/ModernCityGood_5.nbt,3,CHEST:5,../../../../../Chests/Loot/ModernCityEpic_1.nbt,1,CHEST:5,../../../../../Chests/Loot/ModernCityEpic_2.nbt,1,CHEST:5,../../../../../Chests/Loot/ModernCityEpic_3.nbt,1,CHEST:5,../../../../../Chests/Loot/ModernCityEpic_4.nbt,1,CHEST:5,../../../../../Chests/Loot/ModernCityEpic_5.nbt,1,CHEST:5,../../../../../Chests/Loot/Common1.nbt,25,CHEST:5,../../../../../Chests/Loot/Common2.nbt,25,CHEST:5,../../../../../Chests/Loot/Common3.nbt,25,CHEST:5,../../../../../Chests/Loot/Common4.nbt,25,CHEST:5,../../../../../Chests/Loot/Common5.nbt,25,CHEST:5,../../../../../Chests/Loot/Common6.nbt,25,CHEST:5,../../../../../Chests/Loot/Common7.nbt,25,CHEST:5,../../../../../Chests/Loot/Common8.nbt,25,CHEST:5,../../../../../Chests/Loot/Common9.nbt,25,CHEST:5,../../../../../Chests/Loot/Common10.nbt,25,CHEST:5,../../../../../Chests/Loot/Common11.nbt,25,CHEST:5,../../../../../Chests/Loot/Common12.nbt,25,CHEST:5,../../../../../Chests/Loot/Common13.nbt,25,CHEST:5,../../../../../Chests/Loot/Common14.nbt,25,CHEST:5,../../../../../Chests/Loot/Common15.nbt,25,CHEST:5,../../../../../Chests/Loot/Rare1.nbt,10,CHEST:5,../../../../../Chests/Loot/Rare2.nbt,10,CHEST:5,../../../../../Chests/Loot/Rare3.nbt,10,CHEST:5,../../../../../Chests/Loot/Rare4.nbt,10,CHEST:5,../../../../../Chests/Loot/Rare5.nbt,10,CHEST:5,../../../../../Chests/Loot/Rare6.nbt,10,CHEST:5,../../../../../Chests/Loot/Rare7.nbt,10,CHEST:5,../../../../../Chests/Loot/Rare8.nbt,10,CHEST:5,../../../../../Chests/Loot/Rare9.nbt,10,CHEST:5,../../../../../Chests/Loot/Rare10.nbt,10,CHEST:5,../../../../../Chests/Loot/Rare11.nbt,10,CHEST:5,../../../../../Chests/Loot/Rare12.nbt,10,CHEST:5,../../../../../Chests/Loot/Rare13.nbt,10,CHEST:5,../../../../../Chests/Loot/Rare14.nbt,10,CHEST:5,../../../../../Chests/Loot/Rare15.nbt,10,CHEST:5,../../../../../Chests/Loot/Epic1.nbt,1,CHEST:5,../../../../../Chests/Loot/Epic2.nbt,1,CHEST:5,../../../../../Chests/Loot/Epic3.nbt,1,CHEST:5,../../../../../Chests/Loot/Epic4.nbt,1,CHEST:5,../../../../../Chests/Loot/Epic5.nbt,1,CHEST:5,../../../../../Chests/Loot/Epic6.nbt,1,CHEST:5,../../../../../Chests/Loot/Epic7.nbt,1,CHEST:5,../../../../../Chests/Loot/Epic8.nbt,1,CHEST:5,../../../../../Chests/Loot/Epic9.nbt,1,CHEST:5,../../../../../Chests/Loot/Epic10.nbt,1,CHEST:5,../../../../../Chests/Loot/Epic11.nbt,1,CHEST:5,../../../../../Chests/Loot/Epic12.nbt,1,CHEST:5,../../../../../Chests/Loot/Epic13.nbt,1,CHEST:5,../../../../../Chests/Loot/Epic14.nbt,1,CHEST:5,../../../../../Chests/Loot/Epic15.nbt,1,CHEST:5,../../../../../Chests/Loot/ModernCityJunk_1.nbt,100)
Block(-5,48,0,CONCRETE:7)
Block(-5,48,4,CONCRETE:7)
Block(-5,48,5,STAINED_GLASS:15)
Block(-5,48,6,CONCRETE:7)
Block(-5,48,7,STAINED_GLASS:15)
Block(-5,48,8,CONCRETE:7)
Block(-5,49,-5,STAINED_GLASS:15)
Block(-5,49,0,CONCRETE:7)
Block(-5,50,-5,STAINED_GLASS:15)
Block(-5,50,-4,STAINED_GLASS:15)
Block(-5,50,-3,STAINED_GLASS:15)
Block(-5,50,-2,CONCRETE:7)
Block(-5,50,-1,CONCRETE:7)
Block(-5,50,0,CONCRETE:7)
Block(-5,50,1,CONCRETE:7)
Block(-5,51,-3,STAINED_GLASS:15)
Block(-5,51,0,QUARTZ_STAIRS:6)
Block(-5,51,1,CONCRETE:7)
Block(-5,52,-3,STAINED_GLASS:15)
Block(-5,52,0,QUARTZ_STAIRS:6)
Block(-5,52,1,CONCRETE:7)
Block(-5,53,-3,STAINED_GLASS:15)
Block(-5,53,0,QUARTZ_STAIRS:6)
Block(-5,53,1,CONCRETE:7)
Block(-5,54,-3,STAINED_GLASS:15)
Block(-5,54,1,CONCRETE:7)
Block(-5,55,-3,STAINED_GLASS:15)
Block(-5,55,-2,CONCRETE:7)
Block(-5,55,-1,CONCRETE:7)
Block(-5,55,0,STAINED_GLASS:15)
Block(-5,55,1,CONCRETE:7)
Block(-5,56,-3,CONCRETE:7)
Block(-5,56,-1,IRON_PLATE:0)
Block(-5,56,0,QUARTZ_STAIRS:3)
Block(-5,56,1,CONCRETE:7)
Block(-5,57,-3,CONCRETE:7)
Block(-5,57,0,TRIPWIRE_HOOK:2)
Block(-5,57,1,CONCRETE:7)
Block(-5,58,-3,STAINED_GLASS:15)
Block(-5,58,1,CONCRETE:7)
Block(-5,59,-3,STAINED_GLASS:15)
Block(-5,59,-2,CONCRETE:7)
Block(-5,59,-1,CONCRETE:7)
Block(-5,59,0,CONCRETE:7)
Block(-5,59,1,CONCRETE:7)
Block(-5,60,-3,STAINED_GLASS:15)
Block(-5,60,-1,BIRCH_DOOR:1)
Block(-5,60,0,DROPPER:1,NBT/skyscraper_2x2_03/70-dropperC0R0.nbt)
Block(-5,60,1,CONCRETE:7)
Block(-5,61,-3,STAINED_GLASS:15)
Block(-5,61,-1,BIRCH_DOOR:9)
Block(-5,61,0,TRAP_DOOR:4)
Block(-5,61,1,CONCRETE:7)
Block(-5,62,-3,STAINED_GLASS:15)
Block(-5,62,1,CONCRETE:7)
Block(-5,63,-3,STAINED_GLASS:15)
Block(-5,63,1,CONCRETE:7)
Block(-5,64,-3,STAINED_GLASS:15)
Block(-5,64,1,CONCRETE:7)
Block(-5,65,-3,STAINED_GLASS:15)
Block(-5,65,1,CONCRETE:7)
Block(-5,66,-3,STAINED_GLASS:15)
Block(-5,66,-2,CONCRETE:7)
Block(-5,66,-1,CONCRETE:7)
Block(-5,66,0,CONCRETE:7)
Block(-5,66,1,CONCRETE:7)
Block(-5,67,-3,STAINED_GLASS:15)
Block(-5,67,1,STAINED_GLASS:15)
Block(-5,68,-3,STAINED_GLASS:15)
Block(-5,68,-1,WALL_BANNER:5,NBT/skyscraper_2x2_03/71-bannerC0R0.nbt)
Block(-5,68,0,WALL_BANNER:5,NBT/skyscraper_2x2_03/72-bannerC0R0.nbt)
Block(-5,68,1,STAINED_GLASS:15)
Block(-5,69,-3,STAINED_GLASS:15)
Block(-5,69,-2,STAINED_GLASS:15)
Block(-5,69,-1,CONCRETE:7)
Block(-5,69,0,STAINED_GLASS:15)
Block(-5,69,1,CONCRETE:7)
Block(-5,73,5,CONCRETE:7)
Block(-5,73,6,STAINED_GLASS:15)
Block(-5,73,7,CONCRETE:7)
Block(-5,73,8,STAINED_GLASS:15)
Block(-5,74,5,CONCRETE:7)
Block(-5,74,6,STAINED_GLASS:15)
Block(-5,74,7,DARK_OAK_STAIRS:3)
Block(-5,75,5,CONCRETE:7)
Block(-5,75,6,STAINED_GLASS:15)
Block(-5,76,5,CONCRETE:7)
Block(-5,76,6,STAINED_GLASS:15)
Block(-5,77,3,CONCRETE:7)
Block(-5,77,4,STAINED_GLASS:15)
Block(-5,77,5,CONCRETE:7)
Block(-5,77,6,CONCRETE:7)
Block(-5,77,7,CONCRETE:7)
Block(-5,77,8,CONCRETE:7)
Block(-5,78,3,CONCRETE:7)
Block(-5,78,4,DARK_OAK_STAIRS:3)
Block(-5,78,7,DARK_OAK_STAIRS:2)
Block(-5,78,8,DARK_OAK_STAIRS:3)
Block(-5,79,3,CONCRETE:7)
Block(-5,80,3,CONCRETE:7)
Block(-5,80,7,IRON_TRAPDOOR:11)
Block(-5,81,3,CONCRETE:7)
Block(-5,81,4,STAINED_GLASS:15)
Block(-5,81,5,CONCRETE:7)
Block(-5,81,6,STAINED_GLASS:15)
Block(-5,81,7,CONCRETE:7)
Block(-5,81,8,STAINED_GLASS:15)
Block(-4,0,-7,CONCRETE:7)
Block(-4,0,-6,CONCRETE:7)
Block(-4,0,-5,CONCRETE:7)
Block(-4,0,-4,CONCRETE:7)
Block(-4,0,-3,CONCRETE:7)
Block(-4,0,-2,CONCRETE:7)
Block(-4,0,-1,CONCRETE:7)
Block(-4,0,0,CONCRETE:7)
Block(-4,0,1,CONCRETE:7)
Block(-4,0,2,CONCRETE:7)
Block(-4,0,3,CONCRETE:7)
Block(-4,0,4,CONCRETE:7)
Block(-4,0,5,CONCRETE:7)
Block(-4,0,6,CONCRETE:7)
Block(-4,0,7,CONCRETE:7)
Block(-4,0,8,CONCRETE:7)
Block(-4,1,-7,CONCRETE:7)
Block(-4,1,-6,CONCRETE:7)
Block(-4,1,-5,CONCRETE:7)
Block(-4,1,-4,CONCRETE:7)
Block(-4,1,-3,CONCRETE:7)
Block(-4,1,-2,CONCRETE:7)
Block(-4,1,-1,CONCRETE:7)
Block(-4,1,0,CONCRETE:7)
Block(-4,1,1,CONCRETE:7)
Block(-4,1,2,CONCRETE:7)
Block(-4,1,3,CONCRETE:7)
Block(-4,1,4,CONCRETE:7)
Block(-4,2,-7,CONCRETE:7)
Block(-4,2,-6,CONCRETE:7)
Block(-4,2,-5,CONCRETE:7)
Block(-4,2,-4,CONCRETE:7)
Block(-4,2,-3,CONCRETE:7)
Block(-4,2,-2,CONCRETE:7)
Block(-4,2,-1,CONCRETE:7)
Block(-4,2,0,CONCRETE:7)
Block(-4,2,1,CONCRETE:7)
Block(-4,2,2,CONCRETE:7)
Block(-4,2,3,CONCRETE:7)
Block(-4,2,4,CONCRETE:7)
Block(-4,2,5,IRON_TRAPDOOR:8)
Block(-4,2,6,IRON_TRAPDOOR:8)
Block(-4,2,7,IRON_TRAPDOOR:8)
Block(-4,2,8,IRON_TRAPDOOR:8)
Block(-4,3,-7,CONCRETE:7)
Block(-4,3,-6,CONCRETE:7)
Block(-4,3,-5,CONCRETE:7)
Block(-4,3,-4,CONCRETE:7)
Block(-4,3,-3,CONCRETE:7)
Block(-4,3,-2,CONCRETE:7)
Block(-4,3,-1,CONCRETE:7)
Block(-4,3,0,CONCRETE:7)
Block(-4,3,1,CONCRETE:7)
Block(-4,3,2,CONCRETE:7)
Block(-4,3,3,CONCRETE:7)
Block(-4,3,4,CONCRETE:7)
Block(-4,3,7,CONCRETE:4)
Block(-4,3,8,CONCRETE:4)
Block(-4,4,-7,CONCRETE:7)
Block(-4,4,-6,CONCRETE:7)
Block(-4,4,-5,CONCRETE:7)
Block(-4,4,-4,CONCRETE:7)
Block(-4,4,-3,CONCRETE:7)
Block(-4,4,-2,CONCRETE:7)
Block(-4,4,-1,CONCRETE:7)
Block(-4,4,0,CONCRETE:7)
Block(-4,4,1,CONCRETE:7)
Block(-4,4,2,CONCRETE:7)
Block(-4,4,3,CONCRETE:7)
Block(-4,4,4,CONCRETE:7)
Block(-4,4,7,CONCRETE:4)
Block(-4,5,-7,CONCRETE:7)
Block(-4,5,-6,CONCRETE:7)
Block(-4,5,-5,CONCRETE:7)
Block(-4,5,-4,CONCRETE:7)
Block(-4,5,-3,CONCRETE:7)
Block(-4,5,-2,CONCRETE:7)
Block(-4,5,-1,CONCRETE:7)
Block(-4,5,0,CONCRETE:7)
Block(-4,5,1,CONCRETE:7)
Block(-4,5,2,CONCRETE:7)
Block(-4,5,3,CONCRETE:7)
Block(-4,5,4,CONCRETE:7)
Block(-4,5,6,SMOOTH_STAIRS:5)
Block(-4,5,7,CONCRETE:4)
Block(-4,6,-7,CONCRETE:7)
Block(-4,6,-6,CONCRETE:7)
Block(-4,6,-5,CONCRETE:7)
Block(-4,6,-4,CONCRETE:7)
Block(-4,6,-3,CONCRETE:7)
Block(-4,6,-2,CONCRETE:7)
Block(-4,6,-1,CONCRETE:7)
Block(-4,6,0,CONCRETE:7)
Block(-4,6,1,CONCRETE:7)
Block(-4,6,2,CONCRETE:7)
Block(-4,6,3,CONCRETE:7)
Block(-4,6,4,CONCRETE:7)
Block(-4,6,5,CONCRETE:7)
Block(-4,6,6,CONCRETE:7)
Block(-4,6,7,CONCRETE:7)
Block(-4,6,8,CONCRETE:7)
Block(-4,7,-7,CONCRETE:7)
Block(-4,7,-6,CONCRETE:7)
Block(-4,7,-5,CONCRETE:7)
Block(-4,7,-4,CONCRETE:7)
Block(-4,7,-3,CONCRETE:7)
Block(-4,7,-2,CONCRETE:7)
Block(-4,7,-1,CONCRETE:7)
Block(-4,7,0,CONCRETE:7)
Block(-4,7,1,CONCRETE:7)
Block(-4,7,2,CONCRETE:7)
Block(-4,7,3,CONCRETE:7)
Block(-4,7,4,CONCRETE:7)
Block(-4,7,5,CONCRETE:7)
Block(-4,7,6,CONCRETE:7)
Block(-4,7,7,CONCRETE:7)
Block(-4,7,8,CONCRETE:7)
Block(-4,8,-7,CONCRETE:7)
Block(-4,8,-5,CONCRETE:15)
Block(-4,8,-4,DIODE_BLOCK_OFF:15)
Block(-4,8,-3,CONCRETE:15)
Block(-4,8,0,CONCRETE:15)
Block(-4,8,1,DIODE_BLOCK_OFF:15)
Block(-4,8,2,CONCRETE:15)
Block(-4,8,4,CONCRETE:7)
Block(-4,8,5,CONCRETE:7)
Block(-4,8,7,SMOOTH_STAIRS:3)
Block(-4,9,-7,CONCRETE:7)
Block(-4,9,-5,CONCRETE:15)
Block(-4,9,-4,PISTON_BASE:1)
Block(-4,9,-3,CONCRETE:15)
Block(-4,9,0,CONCRETE:15)
Block(-4,9,1,PISTON_BASE:1)
Block(-4,9,2,CONCRETE:15)
Block(-4,9,4,CONCRETE:7)
Block(-4,9,5,CONCRETE:7)
Block(-4,9,6,SMOOTH_STAIRS:3)
Block(-4,10,-7,CONCRETE:7)
Block(-4,10,-5,CONCRETE:15)
Block(-4,10,-3,CONCRETE:15)
Block(-4,10,0,CONCRETE:15)
Block(-4,10,2,CONCRETE:15)
Block(-4,10,4,CONCRETE:7)
Block(-4,10,5,SMOOTH_STAIRS:3)
Block(-4,11,-7,CONCRETE:7)
Block(-4,11,-6,CONCRETE:7)
Block(-4,11,-5,CONCRETE:7)
Block(-4,11,-4,CONCRETE:7)
Block(-4,11,-3,CONCRETE:7)
Block(-4,11,-2,CONCRETE:7)
Block(-4,11,-1,CONCRETE:7)
Block(-4,11,0,CONCRETE:7)
Block(-4,11,1,CONCRETE:7)
Block(-4,11,2,CONCRETE:7)
Block(-4,11,3,CONCRETE:7)
Block(-4,11,4,SMOOTH_STAIRS:3)
Block(-4,11,8,SMOOTH_STAIRS:6)
Block(-4,12,-7,CONCRETE:7)
Block(-4,12,-6,CONCRETE:7)
Block(-4,12,-5,CONCRETE:7)
Block(-4,12,-4,CONCRETE:7)
Block(-4,12,-3,CONCRETE:7)
Block(-4,12,-2,CONCRETE:7)
Block(-4,12,7,SMOOTH_STAIRS:6)
Block(-4,12,8,CONCRETE:7)
Block(-4,13,-7,CONCRETE:7)
Block(-4,13,-6,CONCRETE:7)
Block(-4,13,-5,CONCRETE:7)
Block(-4,13,-4,CONCRETE:7)
Block(-4,13,-3,CONCRETE:7)
Block(-4,13,-2,CONCRETE:7)
Block(-4,13,6,SMOOTH_STAIRS:6)
Block(-4,13,7,CONCRETE:7)
Block(-4,13,8,CONCRETE:7)
Block(-4,14,-7,CONCRETE:7)
Block(-4,14,-6,CONCRETE:7)
Block(-4,14,-5,CONCRETE:7)
Block(-4,14,-4,CONCRETE:7)
Block(-4,14,-3,CONCRETE:7)
Block(-4,14,-2,CONCRETE:7)
Block(-4,14,-1,CONCRETE:7)
Block(-4,14,0,CONCRETE:7)
Block(-4,14,1,CONCRETE:7)
