
#######################################################################
# +-----------------------------------------------------------------+ #
# |                            BO4 object                           | #
# +-----------------------------------------------------------------+ #
#######################################################################

Author: NLBlackEagle

Description: No description given

SettingsMode: WriteDisable


#######################################################################
# +-----------------------------------------------------------------+ #
# |                          Main settings                          | #
# +-----------------------------------------------------------------+ #
#######################################################################

Frequency: 0

SpawnHeight: highestBlock

UseCenterForHighestBlock: true

##############################
# Height Limits for the BO4. #
##############################

MinHeight: 0

MaxHeight: 255

InheritBO3: 

InheritBO3Rotation: NORTH

OverrideChildSettings: true

OverrideParentHeight: false

CanOverride: false

BranchFrequency: 0

BranchFrequencyGroup: 

MustBeBelowOther: false

MustBeInside: 

CannotBeInside: 

ReplacesBO3: 

MustBeInsideWorldBorders: false

CanSpawnOnWater: true

SpawnOnWaterOnly: false

SpawnUnderWater: false

SpawnAtWaterLevel: false

HeightOffset: 0

RemoveAir: true

ReplaceAbove: 

ReplaceBelow: 

ReplaceWithBiomeBlocks: true

ReplaceWithSurfaceBlock: GRASS

ReplaceWithGroundBlock: DIRT

ReplaceWithStoneBlock: STONE

SmoothRadius: 0

SmoothHeightOffset: 0

SmoothStartTop: false

SmoothStartWood: false

SmoothingSurfaceBlock: 

SmoothingGroundBlock: 

BO3Group: 

IsSpawnPoint: false

DoReplaceBlocks: true


#######################################################################
# +-----------------------------------------------------------------+ #
# |                              Blocks                             | #
# +-----------------------------------------------------------------+ #
#######################################################################

E(-2,38,-1,stray,1,../NBT/Mobs/FrozenSailor.txt)

Block(-8,9,0,PACKED_ICE:0)
Block(-8,10,0,PACKED_ICE:0)
Block(-8,10,1,ICE:0)
Block(-8,11,-1,PACKED_ICE:0)
Block(-8,11,0,PACKED_ICE:0)
Block(-8,11,1,PACKED_ICE:0)
Block(-8,11,2,ICE:0)
Block(-8,12,-2,ICE:0)
Block(-8,12,-1,ICE:0)
Block(-8,12,0,PACKED_ICE:0)
Block(-8,12,1,PACKED_ICE:0)
Block(-8,12,2,ICE:0)
Block(-8,12,3,ICE:0)
Block(-8,13,-2,ICE:0)
Block(-8,13,-1,PACKED_ICE:0)
Block(-8,13,0,PACKED_ICE:0)
Block(-8,13,1,PACKED_ICE:0)
Block(-8,13,2,ICE:0)
Block(-8,13,3,ICE:0)
Block(-8,13,4,ICE:0)
Block(-8,14,-5,ICE:0)
Block(-8,14,-3,ICE:0)
Block(-8,14,-2,ICE:0)
Block(-8,14,-1,ICE:0)
Block(-8,14,0,PACKED_ICE:0)
Block(-8,14,1,PACKED_ICE:0)
Block(-8,14,2,PACKED_ICE:0)
Block(-8,14,3,ICE:0)
Block(-8,14,4,ICE:0)
Block(-8,14,5,ICE:0)
Block(-8,15,-5,ICE:0)
Block(-8,15,-4,ICE:0)
Block(-8,15,-3,ICE:0)
Block(-8,15,-2,ICE:0)
Block(-8,15,-1,PACKED_ICE:0)
Block(-8,15,0,PACKED_ICE:0)
Block(-8,15,1,PACKED_ICE:0)
Block(-8,15,2,PACKED_ICE:0)
Block(-8,15,3,PACKED_ICE:0)
Block(-8,15,4,ICE:0)
Block(-8,15,5,ICE:0)
Block(-8,15,6,ICE:0)
Block(-8,16,-6,ICE:0)
Block(-8,16,-5,ICE:0)
Block(-8,16,-4,ICE:0)
Block(-8,16,-3,PACKED_ICE:0)
Block(-8,16,-2,PACKED_ICE:0)
Block(-8,16,-1,PACKED_ICE:0)
Block(-8,16,0,PACKED_ICE:0)
Block(-8,16,1,PACKED_ICE:0)
Block(-8,16,2,PACKED_ICE:0)
Block(-8,16,3,PACKED_ICE:0)
Block(-8,16,4,PACKED_ICE:0)
Block(-8,16,5,PACKED_ICE:0)
Block(-8,16,6,ICE:0)
Block(-8,16,7,PACKED_ICE:0)
Block(-8,17,-6,ICE:0)
Block(-8,17,-5,PACKED_ICE:0)
Block(-8,17,-4,PACKED_ICE:0)
Block(-8,17,-3,PACKED_ICE:0)
Block(-8,17,-2,PACKED_ICE:0)
Block(-8,17,-1,PACKED_ICE:0)
Block(-8,17,0,PACKED_ICE:0)
Block(-8,17,1,PACKED_ICE:0)
Block(-8,17,2,PACKED_ICE:0)
Block(-8,17,3,PACKED_ICE:0)
Block(-8,17,4,PACKED_ICE:0)
Block(-8,17,5,ICE:0)
Block(-8,18,-7,PACKED_ICE:0)
Block(-8,18,-6,SNOW_BLOCK:0)
Block(-8,18,-5,SNOW_BLOCK:0)
Block(-8,18,-4,PACKED_ICE:0)
Block(-8,18,-3,PACKED_ICE:0)
Block(-8,18,-2,PACKED_ICE:0)
Block(-8,18,-1,PACKED_ICE:0)
Block(-8,18,0,PACKED_ICE:0)
Block(-8,18,1,PACKED_ICE:0)
Block(-8,18,2,PACKED_ICE:0)
Block(-8,18,3,PACKED_ICE:0)
Block(-8,18,4,PACKED_ICE:0)
Block(-8,18,5,PACKED_ICE:0)
Block(-8,19,-6,SNOW:3)
Block(-8,19,-5,SNOW:5)
Block(-8,19,-4,SNOW_BLOCK:0)
Block(-8,19,-3,SNOW_BLOCK:0)
Block(-8,19,-2,PACKED_ICE:0)
Block(-8,19,-1,PACKED_ICE:0)
Block(-8,19,0,PACKED_ICE:0)
Block(-8,19,1,PACKED_ICE:0)
Block(-8,19,2,PACKED_ICE:0)
Block(-8,19,3,PACKED_ICE:0)
Block(-8,19,4,PACKED_ICE:0)
Block(-8,19,5,PACKED_ICE:0)
Block(-8,20,-3,SNOW:2)
Block(-8,20,-2,PACKED_ICE:0)
Block(-8,20,-1,PACKED_ICE:0)
Block(-8,20,0,PACKED_ICE:0)
Block(-8,20,1,PACKED_ICE:0)
Block(-8,20,2,ICE:0)
Block(-8,20,3,ICE:0)
Block(-8,20,4,ICE:0)
Block(-8,21,-2,PACKED_ICE:0)
Block(-8,21,-1,PACKED_ICE:0)
Block(-8,21,0,PACKED_ICE:0)
Block(-8,21,1,PACKED_ICE:0)
Block(-8,21,2,ICE:0)
Block(-8,21,3,ICE:0)
Block(-8,22,-4,PACKED_ICE:0)
Block(-8,22,-3,PACKED_ICE:0)
Block(-8,22,0,PACKED_ICE:0)
Block(-8,22,1,PACKED_ICE:0)
Block(-8,22,2,ICE:0)
Block(-8,22,3,ICE:0)
Block(-8,23,-4,ICE:0)
Block(-8,23,0,PACKED_ICE:0)
Block(-8,23,1,PACKED_ICE:0)
Block(-8,23,2,PACKED_ICE:0)
Block(-8,23,3,PACKED_ICE:0)
Block(-8,24,-5,ICE:0)
Block(-8,24,-4,PACKED_ICE:0)
Block(-8,24,0,PACKED_ICE:0)
Block(-8,24,1,PACKED_ICE:0)
Block(-8,24,2,PACKED_ICE:0)
Block(-8,24,3,PACKED_ICE:0)
Block(-8,25,-5,ICE:0)
Block(-8,25,-4,ICE:0)
Block(-8,25,-3,PACKED_ICE:0)
Block(-8,25,0,ICE:0)
Block(-8,25,1,PACKED_ICE:0)
Block(-8,25,2,PACKED_ICE:0)
Block(-8,26,-5,ICE:0)
Block(-8,26,-4,ICE:0)
Block(-8,26,-3,PACKED_ICE:0)
Block(-8,26,0,ICE:0)
Block(-8,26,1,ICE:0)
Block(-8,27,-5,ICE:0)
Block(-8,27,-4,ICE:0)
Block(-8,27,-3,PACKED_ICE:0)
Block(-8,27,0,ICE:0)
Block(-8,27,1,PACKED_ICE:0)
Block(-8,27,3,ICE:0)
Block(-8,28,-4,ICE:0)
Block(-8,28,-3,PACKED_ICE:0)
Block(-8,28,-2,PACKED_ICE:0)
Block(-8,28,-1,PACKED_ICE:0)
Block(-8,28,0,PACKED_ICE:0)
Block(-8,28,1,PACKED_ICE:0)
Block(-8,28,3,ICE:0)
Block(-8,29,-4,PACKED_ICE:0)
Block(-8,29,-3,PACKED_ICE:0)
Block(-8,29,-2,PACKED_ICE:0)
Block(-8,29,-1,PACKED_ICE:0)
Block(-8,29,0,PACKED_ICE:0)
Block(-8,29,1,PACKED_ICE:0)
Block(-8,29,3,ICE:0)
Block(-8,30,-4,SNOW:0)
Block(-8,30,-3,PACKED_ICE:0)
Block(-8,30,-2,PACKED_ICE:0)
Block(-8,30,-1,PACKED_ICE:0)
Block(-8,30,0,PACKED_ICE:0)
Block(-8,30,1,PACKED_ICE:0)
Block(-8,30,3,ICE:0)
Block(-8,31,-1,PACKED_ICE:0)
Block(-8,31,0,SNOW_BLOCK:0)
Block(-8,31,1,SNOW_BLOCK:0)
Block(-8,31,3,PACKED_ICE:0)
Block(-8,32,-1,PACKED_ICE:0)
Block(-8,32,0,WOOD:5)
Block(-8,32,1,SNOW:3)
Block(-8,32,3,PACKED_ICE:0)
Block(-8,33,0,LOG_2:1)
Block(-8,33,3,PACKED_ICE:0)
Block(-8,33,4,ICE:0)
Block(-8,34,-1,PACKED_ICE:0)
Block(-8,34,0,LOG_2:1)
Block(-8,34,3,PACKED_ICE:0)
Block(-8,34,4,ICE:0)
Block(-8,34,6,ICE:0)
Block(-8,35,-5,ICE:0)
Block(-8,35,-2,PACKED_ICE:0)
Block(-8,35,-1,PACKED_ICE:0)
Block(-8,35,0,LOG_2:1)
Block(-8,35,1,PACKED_ICE:0)
Block(-8,35,3,PACKED_ICE:0)
Block(-8,35,4,ICE:0)
Block(-8,35,6,ICE:0)
Block(-8,36,-5,ICE:0)
Block(-8,36,-4,ICE:0)
Block(-8,36,-3,PACKED_ICE:0)
Block(-8,36,-2,PACKED_ICE:0)
Block(-8,36,-1,LOG_2:1)
Block(-8,36,0,ICE:0)
Block(-8,36,1,LOG_2:1)
Block(-8,36,2,LOG_2:1)
Block(-8,36,3,LOG_2:1)
Block(-8,36,4,ICE:0)
Block(-8,36,6,ICE:0)
Block(-8,37,-5,ICE:0)
Block(-8,37,-4,LOG_2:1)
Block(-8,37,-3,ICE:0)
Block(-8,37,-2,PACKED_ICE:0)
Block(-8,37,-1,PACKED_ICE:0)
Block(-8,37,0,LOG:5)
Block(-8,37,1,ICE:0)
Block(-8,37,2,ICE:0)
Block(-8,37,3,ICE:0)
Block(-8,37,4,PACKED_ICE:0)
Block(-8,37,6,ICE:0)
Block(-8,38,-6,ICE:0)
Block(-8,38,-5,LOG_2:1)
Block(-8,38,-3,ICE:0)
Block(-8,38,-2,PACKED_ICE:0)
Block(-8,38,-1,PACKED_ICE:0)
Block(-8,38,0,ICE:0)
Block(-8,38,1,ICE:0)
Block(-8,38,2,ICE:0)
Block(-8,38,3,ICE:0)
Block(-8,38,4,ICE:0)
Block(-8,38,5,LOG_2:1)
Block(-8,38,6,ICE:0)
Block(-8,39,-7,PACKED_ICE:0)
Block(-8,39,-6,WOOD:5)
Block(-8,39,-5,WOOD:5)
Block(-8,39,-4,WOOD:5)
Block(-8,39,-3,WOOD:5)
Block(-8,39,-2,WOOD:5)
Block(-8,39,-1,ICE:0)
Block(-8,39,0,WOOD:5)
Block(-8,39,1,ICE:0)
Block(-8,39,2,WOOD:5)
Block(-8,39,3,WOOD:5)
Block(-8,39,4,WOOD:5)
Block(-8,39,5,WOOD:5)
Block(-8,39,6,PACKED_ICE:0)
Block(-8,40,-7,PACKED_ICE:0)
Block(-8,40,-6,DISPENSER:3)
Block(-8,40,-5,COAL_BLOCK:0)
Block(-8,40,-4,DARK_OAK_STAIRS:3)
Block(-8,40,-3,SNOW_BLOCK:0)
Block(-8,40,-2,ICE:0)
Block(-8,40,-1,ICE:0)
Block(-8,40,0,ICE:0)
Block(-8,40,1,ICE:0)
Block(-8,40,2,ICE:0)
Block(-8,40,3,ICE:0)
Block(-8,40,4,DARK_OAK_STAIRS:2)
Block(-8,40,5,COAL_BLOCK:0)
Block(-8,40,6,DISPENSER:3)
Block(-8,40,7,ICE:0)
Block(-8,41,-7,PACKED_ICE:0)
Block(-8,41,-6,PACKED_ICE:0)
Block(-8,41,-5,PACKED_ICE:0)
Block(-8,41,-4,SNOW_BLOCK:0)
Block(-8,41,-3,SNOW_BLOCK:0)
Block(-8,41,-2,SNOW_BLOCK:0)
Block(-8,41,-1,PACKED_ICE:0)
Block(-8,41,0,PACKED_ICE:0)
Block(-8,41,1,PACKED_ICE:0)
Block(-8,41,2,PACKED_ICE:0)
Block(-8,41,3,SNOW_BLOCK:0)
Block(-8,41,4,SNOW_BLOCK:0)
Block(-8,41,5,SNOW_BLOCK:0)
Block(-8,41,6,PACKED_ICE:0)
Block(-8,41,7,ICE:0)
Block(-8,42,-6,STAINED_CLAY:9)
Block(-8,42,-5,WOOD_DOUBLE_STEP:5)
Block(-8,42,-4,WOOD_STEP:13)
Block(-8,42,-3,SNOW_BLOCK:0)
Block(-8,42,-2,SNOW_BLOCK:0)
Block(-8,42,-1,SNOW_BLOCK:0)
Block(-8,42,0,ICE:0)
Block(-8,42,1,ICE:0)
Block(-8,42,3,SNOW:0)
Block(-8,42,4,SNOW:0)
Block(-8,43,-6,SNOW:0)
Block(-8,43,-5,SNOW:1)
Block(-8,43,-3,SNOW:2)
Block(-8,43,-2,SNOW:0)
Block(-8,43,-1,SNOW_BLOCK:0)
Block(-8,44,-1,SNOW:1)
Block(-7,8,0,ICE:0)
Block(-7,9,0,PACKED_ICE:0)
Block(-7,9,1,ICE:0)
Block(-7,10,-1,PACKED_ICE:0)
Block(-7,10,0,PACKED_ICE:0)
Block(-7,10,1,ICE:0)
Block(-7,10,2,ICE:0)
Block(-7,11,-1,ICE:0)
Block(-7,11,0,PACKED_ICE:0)
Block(-7,11,1,ICE:0)
Block(-7,11,2,ICE:0)
Block(-7,11,3,ICE:0)
Block(-7,12,-2,ICE:0)
Block(-7,12,-1,ICE:0)
Block(-7,12,0,PACKED_ICE:0)
Block(-7,12,1,PACKED_ICE:0)
Block(-7,12,2,ICE:0)
Block(-7,12,3,ICE:0)
Block(-7,13,-2,ICE:0)
Block(-7,13,-1,ICE:0)
Block(-7,13,0,PACKED_ICE:0)
Block(-7,13,1,PACKED_ICE:0)
Block(-7,13,2,ICE:0)
Block(-7,13,3,ICE:0)
Block(-7,13,4,ICE:0)
Block(-7,14,-3,ICE:0)
Block(-7,14,-2,ICE:0)
Block(-7,14,-1,ICE:0)
Block(-7,14,0,PACKED_ICE:0)
Block(-7,14,1,PACKED_ICE:0)
Block(-7,14,2,PACKED_ICE:0)
Block(-7,14,3,PACKED_ICE:0)
Block(-7,14,4,ICE:0)
Block(-7,14,5,ICE:0)
Block(-7,15,-5,ICE:0)
Block(-7,15,-4,ICE:0)
Block(-7,15,-3,ICE:0)
Block(-7,15,-2,ICE:0)
Block(-7,15,-1,ICE:0)
Block(-7,15,0,PACKED_ICE:0)
Block(-7,15,1,PACKED_ICE:0)
Block(-7,15,2,PACKED_ICE:0)
Block(-7,15,3,PACKED_ICE:0)
Block(-7,15,4,PACKED_ICE:0)
Block(-7,15,5,ICE:0)
Block(-7,15,6,PACKED_ICE:0)
Block(-7,15,7,PACKED_ICE:0)
Block(-7,16,-6,ICE:0)
Block(-7,16,-5,ICE:0)
Block(-7,16,-4,ICE:0)
Block(-7,16,-3,PACKED_ICE:0)
Block(-7,16,-2,PACKED_ICE:0)
Block(-7,16,-1,PACKED_ICE:0)
Block(-7,16,0,PACKED_ICE:0)
Block(-7,16,1,PACKED_ICE:0)
Block(-7,16,2,PACKED_ICE:0)
Block(-7,16,3,PACKED_ICE:0)
Block(-7,16,4,PACKED_ICE:0)
Block(-7,16,5,ICE:0)
Block(-7,16,6,ICE:0)
Block(-7,16,7,ICE:0)
Block(-7,17,-6,SNOW_BLOCK:0)
Block(-7,17,-5,ICE:0)
Block(-7,17,-4,PACKED_ICE:0)
Block(-7,17,-3,PACKED_ICE:0)
Block(-7,17,-2,PACKED_ICE:0)
Block(-7,17,-1,PACKED_ICE:0)
Block(-7,17,0,PACKED_ICE:0)
Block(-7,17,1,PACKED_ICE:0)
Block(-7,17,2,PACKED_ICE:0)
Block(-7,17,3,PACKED_ICE:0)
Block(-7,17,4,PACKED_ICE:0)
Block(-7,17,5,ICE:0)
Block(-7,17,6,ICE:0)
Block(-7,18,-6,SNOW:4)
Block(-7,18,-5,SNOW_BLOCK:0)
Block(-7,18,-4,PACKED_ICE:0)
Block(-7,18,-3,PACKED_ICE:0)
Block(-7,18,-2,PACKED_ICE:0)
Block(-7,18,-1,PACKED_ICE:0)
Block(-7,18,0,PACKED_ICE:0)
Block(-7,18,1,PACKED_ICE:0)
Block(-7,18,2,PACKED_ICE:0)
Block(-7,18,3,PACKED_ICE:0)
Block(-7,18,4,ICE:0)
Block(-7,18,5,ICE:0)
Block(-7,19,-5,SNOW:1)
Block(-7,19,-4,SNOW_BLOCK:0)
Block(-7,19,-3,PACKED_ICE:0)
Block(-7,19,-2,PACKED_ICE:0)
Block(-7,19,-1,PACKED_ICE:0)
Block(-7,19,0,PACKED_ICE:0)
Block(-7,19,1,PACKED_ICE:0)
Block(-7,19,2,PACKED_ICE:0)
Block(-7,19,3,ICE:0)
Block(-7,19,4,ICE:0)
Block(-7,20,-4,SNOW:2)
Block(-7,20,-3,SNOW_BLOCK:0)
Block(-7,20,-2,PACKED_ICE:0)
Block(-7,20,-1,PACKED_ICE:0)
Block(-7,20,0,PACKED_ICE:0)
Block(-7,20,1,PACKED_ICE:0)
Block(-7,20,2,PACKED_ICE:0)
Block(-7,20,3,ICE:0)
Block(-7,21,-3,PACKED_ICE:0)
Block(-7,21,-2,PACKED_ICE:0)
Block(-7,21,-1,PACKED_ICE:0)
Block(-7,21,0,PACKED_ICE:0)
Block(-7,21,1,PACKED_ICE:0)
Block(-7,21,2,ICE:0)
Block(-7,21,3,ICE:0)
Block(-7,22,-5,ICE:0)
Block(-7,22,-4,ICE:0)
Block(-7,22,-3,PACKED_ICE:0)
Block(-7,22,-2,PACKED_ICE:0)
Block(-7,22,-1,PACKED_ICE:0)
Block(-7,22,0,PACKED_ICE:0)
Block(-7,22,1,PACKED_ICE:0)
Block(-7,22,2,PACKED_ICE:0)
Block(-7,22,3,ICE:0)
Block(-7,23,-5,ICE:0)
Block(-7,23,-4,ICE:0)
Block(-7,23,0,PACKED_ICE:0)
Block(-7,23,1,PACKED_ICE:0)
Block(-7,23,2,PACKED_ICE:0)
Block(-7,23,3,PACKED_ICE:0)
Block(-7,24,-5,ICE:0)
Block(-7,24,-4,ICE:0)
Block(-7,24,0,PACKED_ICE:0)
Block(-7,24,1,PACKED_ICE:0)
Block(-7,24,2,PACKED_ICE:0)
Block(-7,24,3,PACKED_ICE:0)
Block(-7,25,-5,ICE:0)
Block(-7,25,-4,PACKED_ICE:0)
Block(-7,25,0,PACKED_ICE:0)
Block(-7,25,1,PACKED_ICE:0)
Block(-7,25,2,PACKED_ICE:0)
Block(-7,26,-4,ICE:0)
Block(-7,26,0,PACKED_ICE:0)
Block(-7,26,1,PACKED_ICE:0)
Block(-7,26,2,PACKED_ICE:0)
Block(-7,27,-4,ICE:0)
Block(-7,27,-3,PACKED_ICE:0)
Block(-7,27,-1,PACKED_ICE:0)
Block(-7,27,0,PACKED_ICE:0)
Block(-7,27,1,PACKED_ICE:0)
Block(-7,27,2,PACKED_ICE:0)
Block(-7,28,-3,PACKED_ICE:0)
Block(-7,28,-2,PACKED_ICE:0)
Block(-7,28,-1,PACKED_ICE:0)
Block(-7,28,0,PACKED_ICE:0)
Block(-7,28,1,PACKED_ICE:0)
Block(-7,28,2,PACKED_ICE:0)
Block(-7,29,-3,PACKED_ICE:0)
Block(-7,29,-2,PACKED_ICE:0)
Block(-7,29,-1,PACKED_ICE:0)
Block(-7,29,0,PACKED_ICE:0)
Block(-7,29,1,PACKED_ICE:0)
Block(-7,29,2,PACKED_ICE:0)
Block(-7,30,-3,PACKED_ICE:0)
Block(-7,30,-2,PACKED_ICE:0)
Block(-7,30,-1,PACKED_ICE:0)
Block(-7,30,0,PACKED_ICE:0)
Block(-7,30,1,PACKED_ICE:0)
Block(-7,30,2,PACKED_ICE:0)
Block(-7,31,-2,PACKED_ICE:0)
Block(-7,31,-1,PACKED_ICE:0)
Block(-7,31,0,SNOW_BLOCK:0)
Block(-7,31,1,SNOW_BLOCK:0)
Block(-7,32,-1,ICE:0)
Block(-7,32,0,WOOD:5)
Block(-7,32,1,SNOW:5)
Block(-7,33,-6,ICE:0)
Block(-7,33,0,LOG_2:1)
Block(-7,34,-6,ICE:0)
Block(-7,34,-4,PACKED_ICE:0)
Block(-7,34,0,LOG_2:1)
Block(-7,35,-6,ICE:0)
Block(-7,35,-4,PACKED_ICE:0)
Block(-7,35,-2,PACKED_ICE:0)
Block(-7,35,-1,PACKED_ICE:0)
Block(-7,35,0,LOG_2:1)
Block(-7,35,1,PACKED_ICE:0)
Block(-7,36,-6,ICE:0)
Block(-7,36,-4,PACKED_ICE:0)
Block(-7,36,-3,PACKED_ICE:0)
Block(-7,36,-1,PACKED_ICE:0)
Block(-7,36,0,PACKED_ICE:0)
Block(-7,36,1,LOG_2:1)
Block(-7,36,2,LOG_2:1)
Block(-7,36,3,LOG_2:1)
Block(-7,37,-7,ICE:0)
Block(-7,37,-6,ICE:0)
Block(-7,37,-4,PACKED_ICE:0)
Block(-7,37,-3,PACKED_ICE:0)
Block(-7,37,-1,WOOD_DOUBLE_STEP:1)
Block(-7,37,0,LOG:5)
Block(-7,37,1,WOOD_DOUBLE_STEP:1)
Block(-7,37,2,WOOD_DOUBLE_STEP:1)
Block(-7,37,3,WOOD_DOUBLE_STEP:1)
Block(-7,37,4,PACKED_ICE:0)
Block(-7,38,-7,ICE:0)
Block(-7,38,-6,ICE:0)
Block(-7,38,-5,LOG_2:1)
Block(-7,38,-4,WOOD_DOUBLE_STEP:1)
Block(-7,38,-3,PACKED_ICE:0)
Block(-7,38,-2,WOOD_DOUBLE_STEP:1)
Block(-7,38,-1,WOOD_DOUBLE_STEP:1)
Block(-7,38,0,WOOD:5)
Block(-7,38,1,WOOD_DOUBLE_STEP:1)
Block(-7,38,2,WOOD_DOUBLE_STEP:1)
Block(-7,38,3,WOOD_DOUBLE_STEP:1)
Block(-7,38,4,WOOD_DOUBLE_STEP:1)
Block(-7,38,5,LOG_2:1)
Block(-7,39,-7,ICE:0)
Block(-7,39,-6,ICE:0)
Block(-7,39,-5,PACKED_ICE:0)
Block(-7,39,-4,PACKED_ICE:0)
Block(-7,39,-3,PACKED_ICE:0)
Block(-7,39,-2,PACKED_ICE:0)
Block(-7,39,-1,PACKED_ICE:0)
Block(-7,39,0,PACKED_ICE:0)
Block(-7,39,1,WOOD:5)
Block(-7,39,2,WOOD:5)
Block(-7,39,3,WOOD:5)
Block(-7,39,4,WOOD:5)
Block(-7,39,5,PACKED_ICE:0)
Block(-7,39,6,ICE:0)
Block(-7,40,-7,ICE:0)
Block(-7,40,-6,WOOD:5)
Block(-7,40,-5,PACKED_ICE:0)
Block(-7,40,-4,PACKED_ICE:0)
Block(-7,40,-3,SNOW_BLOCK:0)
Block(-7,40,-2,ICE:0)
Block(-7,40,-1,ICE:0)
Block(-7,40,0,PACKED_ICE:0)
Block(-7,40,1,ICE:0)
Block(-7,40,2,ICE:0)
Block(-7,40,3,SNOW_BLOCK:0)
Block(-7,40,4,FLOWER_POT:0)
Block(-7,40,5,SKULL:1)
Block(-7,40,6,PACKED_ICE:0)
Block(-7,40,7,ICE:0)
Block(-7,41,-7,PACKED_ICE:0)
Block(-7,41,-6,PACKED_ICE:0)
Block(-7,41,-5,WOOD_STEP:5)
Block(-7,41,-4,PACKED_ICE:0)
Block(-7,41,-3,SNOW_BLOCK:0)
Block(-7,41,-2,SNOW_BLOCK:0)
Block(-7,41,-1,SNOW_BLOCK:0)
Block(-7,41,0,PACKED_ICE:0)
Block(-7,41,1,PACKED_ICE:0)
Block(-7,41,2,SNOW:0)
Block(-7,41,5,WOOD_STEP:5)
Block(-7,41,6,WOOD:5)
Block(-7,41,7,ICE:0)
Block(-7,42,-6,PACKED_ICE:0)
Block(-7,42,-5,STAINED_CLAY:9)
Block(-7,42,-4,WOOD_STEP:13)
Block(-7,42,-3,SNOW_BLOCK:0)
Block(-7,42,-2,SNOW_BLOCK:0)
Block(-7,42,-1,SNOW_BLOCK:0)
Block(-7,42,6,SNOW:1)
Block(-7,43,-5,SNOW_BLOCK:0)
Block(-7,43,-4,SNOW_BLOCK:0)
Block(-7,43,-3,SNOW:1)
Block(-7,43,-2,SNOW:2)
Block(-7,43,-1,SNOW:2)
Block(-7,44,-5,SNOW:2)
Block(-7,44,-4,SNOW:0)
Block(-6,4,0,ICE:0)
Block(-6,5,0,ICE:0)
Block(-6,6,0,ICE:0)
Block(-6,7,0,ICE:0)
Block(-6,7,1,ICE:0)
Block(-6,8,-1,PACKED_ICE:0)
Block(-6,8,0,ICE:0)
Block(-6,8,1,ICE:0)
Block(-6,9,-1,ICE:0)
Block(-6,9,0,ICE:0)
Block(-6,9,1,ICE:0)
Block(-6,10,-1,ICE:0)
Block(-6,10,0,ICE:0)
Block(-6,10,1,ICE:0)
Block(-6,10,2,ICE:0)
Block(-6,11,-2,ICE:0)
Block(-6,11,-1,ICE:0)
Block(-6,11,0,PACKED_ICE:0)
Block(-6,11,1,ICE:0)
Block(-6,11,2,ICE:0)
Block(-6,12,-2,ICE:0)
Block(-6,12,-1,ICE:0)
Block(-6,12,0,PACKED_ICE:0)
Block(-6,12,1,PACKED_ICE:0)
Block(-6,12,2,ICE:0)
Block(-6,12,3,ICE:0)
Block(-6,13,-3,ICE:0)
Block(-6,13,-2,ICE:0)
Block(-6,13,-1,PACKED_ICE:0)
Block(-6,13,0,PACKED_ICE:0)
Block(-6,13,1,PACKED_ICE:0)
Block(-6,13,2,PACKED_ICE:0)
Block(-6,13,3,ICE:0)
Block(-6,13,4,PACKED_ICE:0)
Block(-6,14,-4,ICE:0)
Block(-6,14,-3,ICE:0)
Block(-6,14,-2,ICE:0)
Block(-6,14,-1,ICE:0)
Block(-6,14,0,PACKED_ICE:0)
Block(-6,14,1,PACKED_ICE:0)
Block(-6,14,2,PACKED_ICE:0)
Block(-6,14,3,PACKED_ICE:0)
Block(-6,14,4,PACKED_ICE:0)
Block(-6,14,5,PACKED_ICE:0)
Block(-6,14,6,PACKED_ICE:0)
Block(-6,15,-5,ICE:0)
Block(-6,15,-4,ICE:0)
Block(-6,15,-3,ICE:0)
Block(-6,15,-2,ICE:0)
Block(-6,15,-1,PACKED_ICE:0)
Block(-6,15,0,PACKED_ICE:0)
Block(-6,15,1,PACKED_ICE:0)
Block(-6,15,2,PACKED_ICE:0)
Block(-6,15,3,PACKED_ICE:0)
Block(-6,15,4,PACKED_ICE:0)
Block(-6,15,5,PACKED_ICE:0)
Block(-6,15,6,PACKED_ICE:0)
Block(-6,15,7,PACKED_ICE:0)
Block(-6,16,-5,ICE:0)
Block(-6,16,-4,PACKED_ICE:0)
Block(-6,16,-3,PACKED_ICE:0)
Block(-6,16,-2,PACKED_ICE:0)
Block(-6,16,-1,PACKED_ICE:0)
Block(-6,16,0,PACKED_ICE:0)
Block(-6,16,1,PACKED_ICE:0)
Block(-6,16,2,PACKED_ICE:0)
Block(-6,16,3,PACKED_ICE:0)
Block(-6,16,4,PACKED_ICE:0)
Block(-6,16,5,PACKED_ICE:0)
Block(-6,16,6,ICE:0)
Block(-6,17,-6,ICE:0)
Block(-6,17,-5,PACKED_ICE:0)
Block(-6,17,-4,PACKED_ICE:0)
Block(-6,17,-3,PACKED_ICE:0)
Block(-6,17,-2,PACKED_ICE:0)
Block(-6,17,-1,PACKED_ICE:0)
Block(-6,17,0,PACKED_ICE:0)
Block(-6,17,1,PACKED_ICE:0)
Block(-6,17,2,PACKED_ICE:0)
Block(-6,17,3,PACKED_ICE:0)
Block(-6,17,4,PACKED_ICE:0)
Block(-6,17,5,ICE:0)
Block(-6,18,-5,PACKED_ICE:0)
Block(-6,18,-4,PACKED_ICE:0)
Block(-6,18,-3,PACKED_ICE:0)
Block(-6,18,-2,PACKED_ICE:0)
Block(-6,18,-1,PACKED_ICE:0)
Block(-6,18,0,PACKED_ICE:0)
Block(-6,18,1,PACKED_ICE:0)
Block(-6,18,2,PACKED_ICE:0)
Block(-6,18,3,ICE:0)
Block(-6,18,4,ICE:0)
Block(-6,18,5,ICE:0)
Block(-6,19,-4,PACKED_ICE:0)
Block(-6,19,-3,PACKED_ICE:0)
Block(-6,19,-2,PACKED_ICE:0)
Block(-6,19,-1,PACKED_ICE:0)
Block(-6,19,0,PACKED_ICE:0)
Block(-6,19,1,PACKED_ICE:0)
Block(-6,19,2,PACKED_ICE:0)
Block(-6,19,3,ICE:0)
Block(-6,19,4,ICE:0)
Block(-6,20,-5,ICE:0)
Block(-6,20,-4,ICE:0)
Block(-6,20,-3,PACKED_ICE:0)
Block(-6,20,-2,PACKED_ICE:0)
Block(-6,20,-1,PACKED_ICE:0)
Block(-6,20,0,PACKED_ICE:0)
Block(-6,20,1,PACKED_ICE:0)
Block(-6,20,2,PACKED_ICE:0)
Block(-6,20,3,ICE:0)
Block(-6,20,4,ICE:0)
Block(-6,21,-5,ICE:0)
Block(-6,21,-4,ICE:0)
Block(-6,21,-3,PACKED_ICE:0)
Block(-6,21,-2,PACKED_ICE:0)
Block(-6,21,-1,PACKED_ICE:0)
Block(-6,21,0,PACKED_ICE:0)
Block(-6,21,1,PACKED_ICE:0)
Block(-6,21,2,PACKED_ICE:0)
Block(-6,21,3,ICE:0)
Block(-6,21,4,ICE:0)
Block(-6,22,-5,ICE:0)
Block(-6,22,-4,ICE:0)
Block(-6,22,-3,PACKED_ICE:0)
Block(-6,22,-2,PACKED_ICE:0)
Block(-6,22,-1,PACKED_ICE:0)
Block(-6,22,0,PACKED_ICE:0)
Block(-6,22,1,PACKED_ICE:0)
Block(-6,22,2,PACKED_ICE:0)
Block(-6,22,3,ICE:0)
Block(-6,22,4,ICE:0)
Block(-6,23,-5,ICE:0)
Block(-6,23,-4,ICE:0)
Block(-6,23,-3,PACKED_ICE:0)
Block(-6,23,0,PACKED_ICE:0)
Block(-6,23,1,PACKED_ICE:0)
Block(-6,23,2,PACKED_ICE:0)
Block(-6,23,3,PACKED_ICE:0)
Block(-6,24,-5,ICE:0)
Block(-6,24,-4,PACKED_ICE:0)
Block(-6,24,0,PACKED_ICE:0)
Block(-6,24,1,PACKED_ICE:0)
Block(-6,24,2,PACKED_ICE:0)
Block(-6,24,3,PACKED_ICE:0)
Block(-6,25,-5,PACKED_ICE:0)
Block(-6,25,-4,PACKED_ICE:0)
Block(-6,25,0,PACKED_ICE:0)
Block(-6,25,1,PACKED_ICE:0)
Block(-6,25,2,PACKED_ICE:0)
Block(-6,25,3,PACKED_ICE:0)
Block(-6,26,-5,PACKED_ICE:0)
Block(-6,26,-4,PACKED_ICE:0)
Block(-6,26,0,PACKED_ICE:0)
Block(-6,26,1,PACKED_ICE:0)
Block(-6,26,2,PACKED_ICE:0)
Block(-6,26,3,PACKED_ICE:0)
Block(-6,27,-5,PACKED_ICE:0)
Block(-6,27,-4,ICE:0)
Block(-6,27,-3,PACKED_ICE:0)
Block(-6,27,-2,PACKED_ICE:0)
Block(-6,27,-1,PACKED_ICE:0)
Block(-6,27,0,PACKED_ICE:0)
Block(-6,27,1,PACKED_ICE:0)
Block(-6,27,2,PACKED_ICE:0)
Block(-6,27,3,PACKED_ICE:0)
Block(-6,28,-5,ICE:0)
Block(-6,28,-4,ICE:0)
Block(-6,28,-3,ICE:0)
Block(-6,28,-2,PACKED_ICE:0)
Block(-6,28,-1,PACKED_ICE:0)
Block(-6,28,0,PACKED_ICE:0)
Block(-6,28,1,PACKED_ICE:0)
Block(-6,28,2,PACKED_ICE:0)
Block(-6,29,-4,ICE:0)
Block(-6,29,-3,PACKED_ICE:0)
Block(-6,29,-2,PACKED_ICE:0)
Block(-6,29,-1,PACKED_ICE:0)
Block(-6,29,0,PACKED_ICE:0)
Block(-6,29,1,PACKED_ICE:0)
Block(-6,29,2,PACKED_ICE:0)
Block(-6,30,-4,PACKED_ICE:0)
Block(-6,30,-3,PACKED_ICE:0)
Block(-6,30,-2,PACKED_ICE:0)
Block(-6,30,-1,PACKED_ICE:0)
Block(-6,30,0,PACKED_ICE:0)
Block(-6,30,1,PACKED_ICE:0)
Block(-6,30,2,PACKED_ICE:0)
Block(-6,31,-4,PACKED_ICE:0)
Block(-6,31,-2,PACKED_ICE:0)
Block(-6,31,0,PACKED_ICE:0)
Block(-6,31,1,SNOW_BLOCK:0)
Block(-6,31,2,SNOW_BLOCK:0)
Block(-6,32,0,WOOD:5)
Block(-6,32,1,SNOW:7)
Block(-6,32,2,SNOW:5)
Block(-6,33,0,LOG_2:1)
Block(-6,34,-1,ICE:0)
Block(-6,34,0,LOG_2:1)
Block(-6,35,-5,PACKED_ICE:0)
Block(-6,35,-2,PACKED_ICE:0)
Block(-6,35,-1,ICE:0)
Block(-6,35,0,LOG:1)
Block(-6,35,1,PACKED_ICE:0)
Block(-6,35,2,PACKED_ICE:0)
Block(-6,36,-6,PACKED_ICE:0)
Block(-6,36,-5,PACKED_ICE:0)
Block(-6,36,-2,PACKED_ICE:0)
Block(-6,36,-1,LOG_2:1)
Block(-6,36,0,LOG:1)
Block(-6,36,1,LOG_2:1)
Block(-6,36,2,LOG_2:1)
Block(-6,36,3,PACKED_ICE:0)
Block(-6,36,6,ICE:0)
Block(-6,37,-6,PACKED_ICE:0)
Block(-6,37,-5,PACKED_ICE:0)
Block(-6,37,-4,LOG_2:1)
Block(-6,37,-2,PACKED_ICE:0)
Block(-6,37,-1,PACKED_ICE:0)
Block(-6,37,0,LOG:1)
Block(-6,37,1,PACKED_ICE:0)
Block(-6,37,2,PACKED_ICE:0)
Block(-6,37,3,LOG_2:1)
Block(-6,37,4,LOG_2:1)
Block(-6,37,6,ICE:0)
Block(-6,38,-7,ICE:0)
Block(-6,38,-6,PACKED_ICE:0)
Block(-6,38,-5,LOG_2:1)
Block(-6,38,-3,PACKED_ICE:0)
Block(-6,38,-2,PACKED_ICE:0)
Block(-6,38,-1,PACKED_ICE:0)
Block(-6,38,0,LOG:1)
Block(-6,38,1,PACKED_ICE:0)
Block(-6,38,3,LOG_2:1)
Block(-6,38,5,PACKED_ICE:0)
Block(-6,38,6,ICE:0)
Block(-6,39,-7,ICE:0)
Block(-6,39,-6,PACKED_ICE:0)
Block(-6,39,-5,WOOD:5)
Block(-6,39,-4,PACKED_ICE:0)
Block(-6,39,-3,PACKED_ICE:0)
Block(-6,39,-2,PACKED_ICE:0)
Block(-6,39,-1,WOOD:5)
Block(-6,39,0,LOG:1)
Block(-6,39,1,WOOD:5)
Block(-6,39,2,WOOD:5)
Block(-6,39,3,WOOD:5)
Block(-6,39,4,WOOD:5)
Block(-6,39,5,PACKED_ICE:0)
Block(-6,39,6,ICE:0)
Block(-6,40,-7,ICE:0)
Block(-6,40,-6,ICE:0)
Block(-6,40,-5,WOOD:5)
Block(-6,40,-4,PACKED_ICE:0)
Block(-6,40,-3,ICE:0)
Block(-6,40,-2,PACKED_ICE:0)
Block(-6,40,-1,PACKED_ICE:0)
Block(-6,40,0,LOG:1)
Block(-6,40,1,ICE:0)
Block(-6,40,2,SNOW:5)
Block(-6,40,3,SNOW_BLOCK:0)
Block(-6,40,4,TRIPWIRE_HOOK:2)
Block(-6,40,5,WOOD:5)
Block(-6,40,6,ICE:0)
Block(-6,41,-7,ICE:0)
Block(-6,41,-6,ICE:0)
Block(-6,41,-5,WOOD:5)
Block(-6,41,-4,PACKED_ICE:0)
Block(-6,41,-3,ICE:0)
Block(-6,41,-2,PACKED_ICE:0)
Block(-6,41,-1,PACKED_ICE:0)
Block(-6,41,0,LOG:1)
Block(-6,41,1,SNOW:0)
Block(-6,41,4,WOOD_STEP:5)
Block(-6,41,5,WOOD:5)
Block(-6,41,6,ICE:0)
Block(-6,41,7,ICE:0)
Block(-6,42,-6,PACKED_ICE:0)
Block(-6,42,-5,STAINED_CLAY:9)
Block(-6,42,-4,WOOD_STEP:13)
Block(-6,42,-3,SNOW_BLOCK:0)
Block(-6,42,-2,SNOW_BLOCK:0)
Block(-6,42,-1,PACKED_ICE:0)
Block(-6,42,0,SNOW:3)
Block(-6,42,5,SNOW:1)
Block(-6,43,-5,SNOW:3)
Block(-6,43,-4,SNOW_BLOCK:0)
Block(-6,43,-3,SNOW:0)
Block(-6,43,-2,SNOW_BLOCK:0)
Block(-6,44,-4,SNOW:0)
Block(-6,44,-2,SNOW:1)
Block(-5,6,0,ICE:0)
Block(-5,7,0,ICE:0)
Block(-5,8,0,ICE:0)
Block(-5,9,0,ICE:0)
Block(-5,10,-1,ICE:0)
Block(-5,10,0,ICE:0)
Block(-5,10,1,ICE:0)
Block(-5,10,5,PACKED_ICE:0)
Block(-5,11,-2,ICE:0)
Block(-5,11,-1,ICE:0)
Block(-5,11,0,ICE:0)
Block(-5,11,1,PACKED_ICE:0)
Block(-5,11,2,ICE:0)
Block(-5,11,5,PACKED_ICE:0)
Block(-5,12,-3,ICE:0)
Block(-5,12,-2,ICE:0)
Block(-5,12,-1,ICE:0)
Block(-5,12,0,PACKED_ICE:0)
Block(-5,12,1,PACKED_ICE:0)
Block(-5,12,2,PACKED_ICE:0)
Block(-5,12,3,ICE:0)
Block(-5,12,5,PACKED_ICE:0)
Block(-5,13,-3,ICE:0)
Block(-5,13,-2,ICE:0)
Block(-5,13,-1,PACKED_ICE:0)
Block(-5,13,0,PACKED_ICE:0)
Block(-5,13,1,PACKED_ICE:0)
Block(-5,13,2,PACKED_ICE:0)
Block(-5,13,3,PACKED_ICE:0)
Block(-5,13,4,PACKED_ICE:0)
Block(-5,13,5,PACKED_ICE:0)
Block(-5,13,6,PACKED_ICE:0)
Block(-5,14,-4,PACKED_ICE:0)
Block(-5,14,-3,ICE:0)
Block(-5,14,-2,PACKED_ICE:0)
Block(-5,14,-1,PACKED_ICE:0)
Block(-5,14,0,PACKED_ICE:0)
Block(-5,14,1,PACKED_ICE:0)
Block(-5,14,2,PACKED_ICE:0)
Block(-5,14,3,PACKED_ICE:0)
Block(-5,14,4,PACKED_ICE:0)
Block(-5,14,5,PACKED_ICE:0)
Block(-5,14,6,PACKED_ICE:0)
Block(-5,15,-5,PACKED_ICE:0)
Block(-5,15,-4,PACKED_ICE:0)
Block(-5,15,-3,PACKED_ICE:0)
Block(-5,15,-2,PACKED_ICE:0)
Block(-5,15,-1,PACKED_ICE:0)
Block(-5,15,0,PACKED_ICE:0)
Block(-5,15,1,PACKED_ICE:0)
Block(-5,15,2,PACKED_ICE:0)
Block(-5,15,3,PACKED_ICE:0)
Block(-5,15,4,PACKED_ICE:0)
Block(-5,15,5,PACKED_ICE:0)
Block(-5,15,6,PACKED_ICE:0)
Block(-5,15,7,PACKED_ICE:0)
Block(-5,16,-5,PACKED_ICE:0)
Block(-5,16,-4,PACKED_ICE:0)
Block(-5,16,-3,PACKED_ICE:0)
Block(-5,16,-2,PACKED_ICE:0)
Block(-5,16,-1,PACKED_ICE:0)
Block(-5,16,0,PACKED_ICE:0)
Block(-5,16,1,PACKED_ICE:0)
Block(-5,16,2,PACKED_ICE:0)
Block(-5,16,3,PACKED_ICE:0)
Block(-5,16,4,PACKED_ICE:0)
Block(-5,16,5,PACKED_ICE:0)
Block(-5,16,6,PACKED_ICE:0)
Block(-5,16,7,PACKED_ICE:0)
Block(-5,17,-7,ICE:0)
Block(-5,17,-6,PACKED_ICE:0)
Block(-5,17,-5,PACKED_ICE:0)
Block(-5,17,-4,PACKED_ICE:0)
Block(-5,17,-3,PACKED_ICE:0)
Block(-5,17,-2,PACKED_ICE:0)
Block(-5,17,-1,PACKED_ICE:0)
Block(-5,17,0,PACKED_ICE:0)
Block(-5,17,1,PACKED_ICE:0)
Block(-5,17,2,PACKED_ICE:0)
Block(-5,17,3,PACKED_ICE:0)
Block(-5,17,4,PACKED_ICE:0)
Block(-5,17,5,PACKED_ICE:0)
Block(-5,17,6,PACKED_ICE:0)
Block(-5,18,-7,ICE:0)
Block(-5,18,-6,ICE:0)
Block(-5,18,-5,ICE:0)
Block(-5,18,-4,PACKED_ICE:0)
Block(-5,18,-3,PACKED_ICE:0)
Block(-5,18,-2,PACKED_ICE:0)
Block(-5,18,-1,PACKED_ICE:0)
Block(-5,18,0,PACKED_ICE:0)
Block(-5,18,1,PACKED_ICE:0)
Block(-5,18,2,PACKED_ICE:0)
Block(-5,18,3,PACKED_ICE:0)
Block(-5,18,4,ICE:0)
Block(-5,18,5,PACKED_ICE:0)
Block(-5,19,-7,ICE:0)
Block(-5,19,-6,ICE:0)
Block(-5,19,-5,ICE:0)
Block(-5,19,-4,ICE:0)
Block(-5,19,-3,PACKED_ICE:0)
Block(-5,19,-2,PACKED_ICE:0)
Block(-5,19,-1,PACKED_ICE:0)
Block(-5,19,0,PACKED_ICE:0)
Block(-5,19,1,PACKED_ICE:0)
Block(-5,19,2,PACKED_ICE:0)
Block(-5,19,3,ICE:0)
Block(-5,19,4,ICE:0)
Block(-5,19,5,ICE:0)
Block(-5,20,-6,ICE:0)
Block(-5,20,-5,ICE:0)
Block(-5,20,-4,ICE:0)
Block(-5,20,-3,PACKED_ICE:0)
Block(-5,20,-2,PACKED_ICE:0)
Block(-5,20,-1,PACKED_ICE:0)
Block(-5,20,0,PACKED_ICE:0)
Block(-5,20,1,PACKED_ICE:0)
Block(-5,20,2,PACKED_ICE:0)
Block(-5,20,3,PACKED_ICE:0)
Block(-5,20,4,ICE:0)
Block(-5,20,5,ICE:0)
Block(-5,21,-6,ICE:0)
Block(-5,21,-5,ICE:0)
Block(-5,21,-4,ICE:0)
Block(-5,21,-3,PACKED_ICE:0)
Block(-5,21,-2,PACKED_ICE:0)
Block(-5,21,-1,PACKED_ICE:0)
Block(-5,21,0,PACKED_ICE:0)
Block(-5,21,1,PACKED_ICE:0)
Block(-5,21,2,PACKED_ICE:0)
Block(-5,21,3,ICE:0)
Block(-5,21,4,ICE:0)
Block(-5,22,-6,ICE:0)
Block(-5,22,-5,ICE:0)
Block(-5,22,-4,ICE:0)
Block(-5,22,-3,PACKED_ICE:0)
Block(-5,22,-1,PACKED_ICE:0)
Block(-5,22,0,PACKED_ICE:0)
Block(-5,22,1,PACKED_ICE:0)
Block(-5,22,2,PACKED_ICE:0)
Block(-5,22,3,PACKED_ICE:0)
Block(-5,22,4,ICE:0)
Block(-5,23,-6,PACKED_ICE:0)
Block(-5,23,-5,ICE:0)
Block(-5,23,-4,PACKED_ICE:0)
Block(-5,23,0,PACKED_ICE:0)
Block(-5,23,1,PACKED_ICE:0)
Block(-5,23,2,PACKED_ICE:0)
Block(-5,23,3,PACKED_ICE:0)
Block(-5,23,4,PACKED_ICE:0)
Block(-5,24,-6,PACKED_ICE:0)
Block(-5,24,-5,PACKED_ICE:0)
Block(-5,24,-4,PACKED_ICE:0)
Block(-5,24,0,PACKED_ICE:0)
Block(-5,24,1,PACKED_ICE:0)
Block(-5,24,2,PACKED_ICE:0)
Block(-5,24,3,PACKED_ICE:0)
Block(-5,24,4,PACKED_ICE:0)
Block(-5,25,-6,SNOW:0)
Block(-5,25,-5,PACKED_ICE:0)
Block(-5,25,-4,PACKED_ICE:0)
Block(-5,25,0,PACKED_ICE:0)
Block(-5,25,1,PACKED_ICE:0)
Block(-5,25,2,PACKED_ICE:0)
Block(-5,25,3,PACKED_ICE:0)
Block(-5,25,4,PACKED_ICE:0)
Block(-5,26,-5,PACKED_ICE:0)
Block(-5,26,-4,PACKED_ICE:0)
Block(-5,26,-3,PACKED_ICE:0)
Block(-5,26,-1,PACKED_ICE:0)
Block(-5,26,0,PACKED_ICE:0)
Block(-5,26,1,PACKED_ICE:0)
Block(-5,26,2,PACKED_ICE:0)
Block(-5,26,3,PACKED_ICE:0)
Block(-5,26,4,PACKED_ICE:0)
Block(-5,27,-4,ICE:0)
Block(-5,27,-3,ICE:0)
Block(-5,27,-2,PACKED_ICE:0)
Block(-5,27,-1,PACKED_ICE:0)
Block(-5,27,0,PACKED_ICE:0)
Block(-5,27,1,PACKED_ICE:0)
Block(-5,27,2,PACKED_ICE:0)
Block(-5,27,3,PACKED_ICE:0)
Block(-5,28,-4,ICE:0)
Block(-5,28,-3,ICE:0)
Block(-5,28,-2,PACKED_ICE:0)
Block(-5,28,-1,PACKED_ICE:0)
Block(-5,28,0,PACKED_ICE:0)
Block(-5,28,1,PACKED_ICE:0)
Block(-5,28,2,PACKED_ICE:0)
Block(-5,28,3,PACKED_ICE:0)
Block(-5,29,-3,ICE:0)
Block(-5,29,-2,PACKED_ICE:0)
Block(-5,29,-1,PACKED_ICE:0)
Block(-5,29,0,PACKED_ICE:0)
Block(-5,29,1,PACKED_ICE:0)
Block(-5,29,2,PACKED_ICE:0)
Block(-5,29,3,PACKED_ICE:0)
Block(-5,30,-3,ICE:0)
Block(-5,30,-2,ICE:0)
Block(-5,30,-1,PACKED_ICE:0)
Block(-5,30,0,PACKED_ICE:0)
Block(-5,30,1,PACKED_ICE:0)
Block(-5,30,2,PACKED_ICE:0)
Block(-5,31,-2,PACKED_ICE:0)
Block(-5,31,-1,PACKED_ICE:0)
Block(-5,31,0,PACKED_ICE:0)
Block(-5,31,1,SNOW_BLOCK:0)
Block(-5,31,2,SNOW_BLOCK:0)
Block(-5,32,-7,PACKED_ICE:0)
Block(-5,32,-1,ICE:0)
Block(-5,32,0,PACKED_ICE:0)
Block(-5,32,1,SNOW:3)
Block(-5,32,2,SNOW:2)
Block(-5,33,-7,PACKED_ICE:0)
Block(-5,33,-1,PACKED_ICE:0)
Block(-5,33,0,WOOD:5)
Block(-5,34,-7,PACKED_ICE:0)
Block(-5,34,-1,PACKED_ICE:0)
Block(-5,34,0,LOG_2:1)
Block(-5,35,-7,PACKED_ICE:0)
Block(-5,35,-2,ICE:0)
Block(-5,35,-1,PACKED_ICE:0)
Block(-5,35,0,LOG_2:1)
Block(-5,35,1,PACKED_ICE:0)
Block(-5,35,2,PACKED_ICE:0)
Block(-5,35,3,PACKED_ICE:0)
Block(-5,36,-7,PACKED_ICE:0)
Block(-5,36,-3,PACKED_ICE:0)
Block(-5,36,-2,LOG_2:1)
Block(-5,36,-1,LOG_2:1)
Block(-5,36,0,PACKED_ICE:0)
Block(-5,36,1,LOG_2:1)
Block(-5,36,2,LOG_2:1)
Block(-5,36,3,PACKED_ICE:0)
Block(-5,37,-7,PACKED_ICE:0)
Block(-5,37,-6,ICE:0)
Block(-5,37,-5,ICE:0)
Block(-5,37,-3,LOG_2:1)
Block(-5,37,-2,SNOW:7)
Block(-5,37,-1,SNOW:4)
Block(-5,37,0,PACKED_ICE:0)
Block(-5,37,1,SNOW:0)
Block(-5,37,2,SNOW:5)
Block(-5,37,3,LOG_2:1)
Block(-5,37,4,PACKED_ICE:0)
Block(-5,38,-7,PACKED_ICE:0)
Block(-5,38,-6,ICE:0)
Block(-5,38,-5,LOG_2:1)
Block(-5,38,-4,WOOD_DOUBLE_STEP:1)
Block(-5,38,-3,BED_BLOCK:9)
Block(-5,38,-1,PACKED_ICE:0)
Block(-5,38,0,PACKED_ICE:0)
Block(-5,38,3,BED_BLOCK:9)
Block(-5,38,5,PACKED_ICE:0)
Block(-5,39,-7,PACKED_ICE:0)
Block(-5,39,-6,ICE:0)
Block(-5,39,-5,WOOD:5)
Block(-5,39,-4,WOOD:5)
Block(-5,39,-3,WOOD:5)
Block(-5,39,-2,WOOD:5)
Block(-5,39,-1,WOOD:5)
Block(-5,39,0,PACKED_ICE:0)
Block(-5,39,2,WOOD:5)
Block(-5,39,3,WOOD:5)
Block(-5,39,4,WOOD:5)
Block(-5,39,5,WOOD:5)
Block(-5,40,-7,PACKED_ICE:0)
Block(-5,40,-6,ICE:0)
Block(-5,40,-5,DISPENSER:2)
Block(-5,40,-4,COAL_BLOCK:0)
Block(-5,40,-3,DARK_OAK_STAIRS:3)
Block(-5,40,-2,ICE:0)
Block(-5,40,-1,ICE:0)
Block(-5,40,0,ICE:0)
Block(-5,40,2,SNOW:4)
Block(-5,40,3,DARK_OAK_STAIRS:2)
Block(-5,40,4,COAL_BLOCK:0)
Block(-5,40,5,DISPENSER:3)
Block(-5,40,6,PACKED_ICE:0)
Block(-5,41,-7,PACKED_ICE:0)
Block(-5,41,-6,ICE:0)
Block(-5,41,-5,WOOD:5)
Block(-5,41,-4,PACKED_ICE:0)
Block(-5,41,-3,ICE:0)
Block(-5,41,-2,ICE:0)
Block(-5,41,-1,PACKED_ICE:0)
Block(-5,41,0,SNOW:0)
Block(-5,41,4,SNOW:2)
Block(-5,41,5,WOOD:5)
Block(-5,41,6,ICE:0)
Block(-5,42,-7,SNOW:0)
Block(-5,42,-6,PACKED_ICE:0)
Block(-5,42,-5,PACKED_ICE:0)
Block(-5,42,-4,PACKED_ICE:0)
Block(-5,42,-3,ICE:0)
Block(-5,42,-2,ICE:0)
Block(-5,42,-1,PACKED_ICE:0)
Block(-5,42,4,WOOD_STEP:13)
Block(-5,42,5,WOOD:5)
Block(-5,43,-6,SNOW:0)
Block(-5,43,-5,SNOW_BLOCK:0)
Block(-5,43,-4,ICE:0)
Block(-5,43,-3,ICE:0)
Block(-5,43,-2,SNOW:0)
Block(-5,43,-1,PACKED_ICE:0)
Block(-5,43,5,SNOW:2)
Block(-5,44,-5,SNOW:0)
Block(-5,44,-3,SNOW:0)
Block(-5,44,-1,PACKED_ICE:0)
Block(-5,45,-1,PACKED_ICE:0)
Block(-5,46,-1,ICE:0)
Block(-5,47,-1,SNOW:0)
Block(-4,10,0,ICE:0)
Block(-4,11,-1,ICE:0)
Block(-4,11,0,ICE:0)
Block(-4,11,1,ICE:0)
Block(-4,11,2,ICE:0)
Block(-4,11,3,ICE:0)
Block(-4,12,-3,PACKED_ICE:0)
Block(-4,12,-2,ICE:0)
Block(-4,12,-1,PACKED_ICE:0)
Block(-4,12,0,PACKED_ICE:0)
Block(-4,12,1,ICE:0)
Block(-4,12,2,ICE:0)
Block(-4,12,3,ICE:0)
Block(-4,12,4,ICE:0)
Block(-4,13,-3,PACKED_ICE:0)
Block(-4,13,-2,PACKED_ICE:0)
Block(-4,13,-1,PACKED_ICE:0)
Block(-4,13,0,PACKED_ICE:0)
Block(-4,13,1,PACKED_ICE:0)
Block(-4,13,2,PACKED_ICE:0)
Block(-4,13,3,PACKED_ICE:0)
Block(-4,13,4,PACKED_ICE:0)
Block(-4,13,5,PACKED_ICE:0)
Block(-4,14,-5,PACKED_ICE:0)
Block(-4,14,-4,PACKED_ICE:0)
Block(-4,14,-3,PACKED_ICE:0)
Block(-4,14,-2,PACKED_ICE:0)
Block(-4,14,-1,PACKED_ICE:0)
Block(-4,14,0,PACKED_ICE:0)
Block(-4,14,1,PACKED_ICE:0)
Block(-4,14,2,PACKED_ICE:0)
Block(-4,14,3,PACKED_ICE:0)
Block(-4,14,4,PACKED_ICE:0)
Block(-4,14,5,PACKED_ICE:0)
Block(-4,14,6,PACKED_ICE:0)
Block(-4,15,-5,PACKED_ICE:0)
Block(-4,15,-4,PACKED_ICE:0)
Block(-4,15,-3,PACKED_ICE:0)
Block(-4,15,-2,PACKED_ICE:0)
Block(-4,15,-1,PACKED_ICE:0)
Block(-4,15,0,PACKED_ICE:0)
Block(-4,15,1,PACKED_ICE:0)
Block(-4,15,2,PACKED_ICE:0)
Block(-4,15,3,PACKED_ICE:0)
Block(-4,15,4,PACKED_ICE:0)
Block(-4,15,5,ICE:0)
Block(-4,15,6,PACKED_ICE:0)
Block(-4,15,7,PACKED_ICE:0)
Block(-4,16,-6,ICE:0)
Block(-4,16,-5,PACKED_ICE:0)
Block(-4,16,-4,PACKED_ICE:0)
Block(-4,16,-3,PACKED_ICE:0)
Block(-4,16,-2,PACKED_ICE:0)
Block(-4,16,-1,PACKED_ICE:0)
Block(-4,16,0,PACKED_ICE:0)
Block(-4,16,1,PACKED_ICE:0)
Block(-4,16,2,PACKED_ICE:0)
Block(-4,16,3,PACKED_ICE:0)
Block(-4,16,4,PACKED_ICE:0)
Block(-4,16,5,PACKED_ICE:0)
Block(-4,16,6,PACKED_ICE:0)
Block(-4,17,-7,ICE:0)
Block(-4,17,-6,ICE:0)
Block(-4,17,-5,PACKED_ICE:0)
Block(-4,17,-4,PACKED_ICE:0)
Block(-4,17,-3,PACKED_ICE:0)
Block(-4,17,-2,PACKED_ICE:0)
Block(-4,17,-1,PACKED_ICE:0)
Block(-4,17,0,PACKED_ICE:0)
Block(-4,17,1,PACKED_ICE:0)
Block(-4,17,2,PACKED_ICE:0)
Block(-4,17,3,PACKED_ICE:0)
Block(-4,17,4,PACKED_ICE:0)
Block(-4,17,5,PACKED_ICE:0)
Block(-4,17,6,PACKED_ICE:0)
Block(-4,18,-7,ICE:0)
Block(-4,18,-6,ICE:0)
Block(-4,18,-5,PACKED_ICE:0)
Block(-4,18,-4,PACKED_ICE:0)
Block(-4,18,-3,PACKED_ICE:0)
Block(-4,18,-2,PACKED_ICE:0)
Block(-4,18,-1,PACKED_ICE:0)
Block(-4,18,0,PACKED_ICE:0)
Block(-4,18,1,PACKED_ICE:0)
Block(-4,18,2,PACKED_ICE:0)
Block(-4,18,3,PACKED_ICE:0)
Block(-4,18,4,PACKED_ICE:0)
Block(-4,18,5,PACKED_ICE:0)
Block(-4,18,6,PACKED_ICE:0)
Block(-4,19,-6,ICE:0)
Block(-4,19,-5,ICE:0)
Block(-4,19,-4,PACKED_ICE:0)
Block(-4,19,-3,PACKED_ICE:0)
Block(-4,19,-2,PACKED_ICE:0)
Block(-4,19,-1,PACKED_ICE:0)
Block(-4,19,0,PACKED_ICE:0)
Block(-4,19,1,PACKED_ICE:0)
Block(-4,19,2,PACKED_ICE:0)
Block(-4,19,3,PACKED_ICE:0)
Block(-4,19,4,PACKED_ICE:0)
Block(-4,19,5,ICE:0)
Block(-4,19,6,PACKED_ICE:0)
Block(-4,20,-6,ICE:0)
Block(-4,20,-5,ICE:0)
Block(-4,20,-4,ICE:0)
Block(-4,20,-3,PACKED_ICE:0)
Block(-4,20,-2,PACKED_ICE:0)
Block(-4,20,-1,PACKED_ICE:0)
Block(-4,20,0,PACKED_ICE:0)
Block(-4,20,1,PACKED_ICE:0)
Block(-4,20,2,PACKED_ICE:0)
Block(-4,20,3,PACKED_ICE:0)
Block(-4,20,4,ICE:0)
Block(-4,20,5,ICE:0)
Block(-4,21,-6,PACKED_ICE:0)
Block(-4,21,-5,ICE:0)
Block(-4,21,-4,PACKED_ICE:0)
Block(-4,21,-3,PACKED_ICE:0)
Block(-4,21,-2,PACKED_ICE:0)
Block(-4,21,-1,PACKED_ICE:0)
Block(-4,21,0,PACKED_ICE:0)
Block(-4,21,1,PACKED_ICE:0)
Block(-4,21,2,PACKED_ICE:0)
Block(-4,21,3,PACKED_ICE:0)
Block(-4,21,4,ICE:0)
Block(-4,21,5,ICE:0)
Block(-4,22,-6,PACKED_ICE:0)
Block(-4,22,-5,PACKED_ICE:0)
Block(-4,22,-4,PACKED_ICE:0)
Block(-4,22,0,PACKED_ICE:0)
Block(-4,22,1,PACKED_ICE:0)
Block(-4,22,2,PACKED_ICE:0)
Block(-4,22,3,ICE:0)
Block(-4,22,4,ICE:0)
Block(-4,22,5,ICE:0)
Block(-4,23,-5,PACKED_ICE:0)
Block(-4,23,-4,PACKED_ICE:0)
Block(-4,23,0,PACKED_ICE:0)
Block(-4,23,1,PACKED_ICE:0)
Block(-4,23,2,PACKED_ICE:0)
Block(-4,23,3,PACKED_ICE:0)
Block(-4,23,4,ICE:0)
Block(-4,23,5,PACKED_ICE:0)
Block(-4,24,-5,PACKED_ICE:0)
Block(-4,24,-4,PACKED_ICE:0)
Block(-4,24,0,PACKED_ICE:0)
Block(-4,24,1,PACKED_ICE:0)
Block(-4,24,2,PACKED_ICE:0)
Block(-4,24,3,PACKED_ICE:0)
Block(-4,24,4,PACKED_ICE:0)
Block(-4,24,5,PACKED_ICE:0)
Block(-4,25,-5,PACKED_ICE:0)
Block(-4,25,-4,PACKED_ICE:0)
Block(-4,25,0,PACKED_ICE:0)
Block(-4,25,1,PACKED_ICE:0)
Block(-4,25,2,PACKED_ICE:0)
Block(-4,25,3,PACKED_ICE:0)
Block(-4,25,4,PACKED_ICE:0)
Block(-4,26,-5,SNOW:0)
Block(-4,26,-4,PACKED_ICE:0)
Block(-4,26,0,PACKED_ICE:0)
Block(-4,26,1,PACKED_ICE:0)
Block(-4,26,2,PACKED_ICE:0)
Block(-4,26,3,PACKED_ICE:0)
Block(-4,26,4,PACKED_ICE:0)
Block(-4,27,-4,ICE:0)
Block(-4,27,-3,PACKED_ICE:0)
Block(-4,27,-2,PACKED_ICE:0)
Block(-4,27,-1,PACKED_ICE:0)
Block(-4,27,0,PACKED_ICE:0)
Block(-4,27,1,PACKED_ICE:0)
Block(-4,27,2,PACKED_ICE:0)
Block(-4,27,3,PACKED_ICE:0)
Block(-4,27,4,PACKED_ICE:0)
Block(-4,28,-3,ICE:0)
Block(-4,28,-2,PACKED_ICE:0)
Block(-4,28,-1,PACKED_ICE:0)
Block(-4,28,0,PACKED_ICE:0)
Block(-4,28,1,PACKED_ICE:0)
Block(-4,28,2,PACKED_ICE:0)
Block(-4,28,3,PACKED_ICE:0)
Block(-4,28,4,PACKED_ICE:0)
Block(-4,29,-3,ICE:0)
Block(-4,29,-2,ICE:0)
Block(-4,29,-1,PACKED_ICE:0)
Block(-4,29,0,PACKED_ICE:0)
Block(-4,29,1,PACKED_ICE:0)
Block(-4,29,2,PACKED_ICE:0)
Block(-4,29,3,PACKED_ICE:0)
Block(-4,30,-3,ICE:0)
Block(-4,30,-2,ICE:0)
Block(-4,30,-1,PACKED_ICE:0)
Block(-4,30,0,PACKED_ICE:0)
Block(-4,30,1,PACKED_ICE:0)
Block(-4,30,2,PACKED_ICE:0)
Block(-4,30,3,PACKED_ICE:0)
Block(-4,31,-3,ICE:0)
Block(-4,31,-2,SNOW_BLOCK:0)
Block(-4,31,-1,SNOW_BLOCK:0)
Block(-4,31,0,SNOW_BLOCK:0)
Block(-4,31,1,SNOW_BLOCK:0)
Block(-4,31,3,PACKED_ICE:0)
Block(-4,32,-2,SNOW:1)
Block(-4,32,-1,SNOW:6)
Block(-4,32,0,SNOW:3)
Block(-4,32,1,SNOW:2)
Block(-4,32,3,ICE:0)
Block(-4,33,0,WOOD:5)
Block(-4,33,3,PACKED_ICE:0)
Block(-4,34,0,LOG_2:1)
Block(-4,34,3,PACKED_ICE:0)
Block(-4,35,-6,ICE:0)
Block(-4,35,-2,PACKED_ICE:0)
Block(-4,35,0,LOG_2:1)
Block(-4,35,1,PACKED_ICE:0)
Block(-4,35,2,PACKED_ICE:0)
Block(-4,35,3,PACKED_ICE:0)
Block(-4,36,-6,ICE:0)
Block(-4,36,-4,ICE:0)
Block(-4,36,-3,ICE:0)
Block(-4,36,-2,LOG_2:1)
Block(-4,36,-1,LOG_2:1)
Block(-4,36,0,WOOD_STEP:9)
Block(-4,36,1,LOG_2:1)
Block(-4,36,2,LOG_2:1)
Block(-4,36,3,PACKED_ICE:0)
Block(-4,36,4,PACKED_ICE:0)
Block(-4,37,-6,ICE:0)
Block(-4,37,-5,ICE:0)
Block(-4,37,-4,LOG_2:1)
Block(-4,37,-3,LOG_2:1)
RandomBlock(-4,37,-2,AIR:0,20,CHEST:3,../../../../Chests/Loot/ShipJunk_1.nbt,10,CHEST:3,../../../../Chests/Loot/ShipJunk_2.nbt,10,CHEST:3,../../../../Chests/Loot/ShipJunk_3.nbt,10,CHEST:3,../../../../Chests/Loot/ShipJunk_4.nbt,10,CHEST:3,../../../../Chests/Loot/ShipJunk_5.nbt,10,CHEST:3,../../../../Chests/Lore/Frozen_1.nbt,1,CHEST:3,../../../../Chests/Lore/Frozen_2.nbt,1,CHEST:3,../../../../Chests/Lore/Frozen_3.nbt,1,CHEST:3,../../../../Chests/Lore/Frozen_4.nbt,1,CHEST:3,../../../../Chests/Lore/Frozen_5.nbt,1,CHEST:3,../../../../Chests/Loot/Common1.nbt,10,CHEST:3,../../../../Chests/Loot/Common2.nbt,10,CHEST:3,../../../../Chests/Loot/Common3.nbt,10,CHEST:3,../../../../Chests/Loot/Common4.nbt,10,CHEST:3,../../../../Chests/Loot/Common5.nbt,10,CHEST:3,../../../../Chests/Loot/Common6.nbt,10,CHEST:3,../../../../Chests/Loot/Common7.nbt,10,CHEST:3,../../../../Chests/Loot/Common8.nbt,10,CHEST:3,../../../../Chests/Loot/Common9.nbt,10,CHEST:3,../../../../Chests/Loot/Common10.nbt,10,CHEST:3,../../../../Chests/Loot/Common10.nbt,11,CHEST:3,../../../../Chests/Loot/Common12.nbt,10,CHEST:3,../../../../Chests/Loot/Common13.nbt,10,CHEST:3,../../../../Chests/Loot/Common14.nbt,10,CHEST:3,../../../../Chests/Loot/Common15.nbt,10,CHEST:3,../../../../Chests/Lore/Frozen_1.nbt,2,CHEST:3,../../../../Chests/Lore/Frozen_3.nbt,2,CHEST:3,../../../../Chests/Lore/Frozen_4.nbt,2,CHEST:3,../../../../Chests/Lore/Frozen_5.nbt,2,CHEST:3,../../../../Chests/Lore/Frozen_5.nbt,2,CHEST:3,../../../../Chests/Loot/Rare1.nbt,5,CHEST:3,../../../../Chests/Loot/Rare2.nbt,5,CHEST:3,../../../../Chests/Loot/Rare3.nbt,5,CHEST:3,../../../../Chests/Loot/Rare4.nbt,5,CHEST:3,../../../../Chests/Loot/Rare5.nbt,5,CHEST:3,../../../../Chests/Loot/Rare6.nbt,5,CHEST:3,../../../../Chests/Loot/Rare7.nbt,5,CHEST:3,../../../../Chests/Loot/Rare8.nbt,5,CHEST:3,../../../../Chests/Loot/Rare9.nbt,5,CHEST:3,../../../../Chests/Loot/Rare10.nbt,5,CHEST:3,../../../../Chests/Loot/Rare11.nbt,5,CHEST:3,../../../../Chests/Loot/Rare12.nbt,5,CHEST:3,../../../../Chests/Loot/Rare13.nbt,5,CHEST:3,../../../../Chests/Loot/Rare14.nbt,5,CHEST:3,../../../../Chests/Loot/Rare15.nbt,5,CHEST:3,../../../../Chests/Loot/Epic1.nbt,2,CHEST:3,../../../../Chests/Loot/Epic2.nbt,2,CHEST:3,../../../../Chests/Loot/Epic3.nbt,2,CHEST:3,../../../../Chests/Loot/Epic4.nbt,2,CHEST:3,../../../../Chests/Loot/Epic5.nbt,2,CHEST:3,../../../../Chests/Loot/Epic6.nbt,2,CHEST:3,../../../../Chests/Loot/Epic7.nbt,2,CHEST:3,../../../../Chests/Loot/Epic8.nbt,2,CHEST:3,../../../../Chests/Loot/Epic9.nbt,2,CHEST:3,../../../../Chests/Loot/Epic10.nbt,2,CHEST:3,../../../../Chests/Loot/Epic11.nbt,2,CHEST:3,../../../../Chests/Loot/Epic12.nbt,2,CHEST:3,../../../../Chests/Loot/Epic13.nbt,2,CHEST:3,../../../../Chests/Loot/Epic14.nbt,2,CHEST:3,../../../../Chests/Loot/Epic15.nbt,5,CHEST:3,../../../../Chests/Loot/Rare1.nbt,5,CHEST:3,../../../../Chests/Loot/Rare2.nbt,5,CHEST:3,../../../../Chests/Loot/Rare3.nbt,5,CHEST:3,../../../../Chests/Loot/Rare4.nbt,5,CHEST:3,../../../../Chests/Loot/Rare5.nbt,10,CHEST:3,../../../../Chests/Loot/Rare6.nbt,10,CHEST:3,../../../../Chests/Loot/Rare7.nbt,10,CHEST:3,../../../../Chests/Loot/Rare8.nbt,10,CHEST:3,../../../../Chests/Loot/Rare9.nbt,10,CHEST:3,../../../../Chests/Loot/Rare10.nbt,15,CHEST:3,../../../../Chests/Loot/Rare11.nbt,15,CHEST:3,../../../../Chests/Loot/Rare12.nbt,15,CHEST:3,../../../../Chests/Loot/Rare13.nbt,15,CHEST:3,../../../../Chests/Loot/Rare14.nbt,15,CHEST:3,../../../../Chests/Loot/Rare15.nbt,15,CHEST:3,../../../../Chests/Loot/Epic15.nbt,100)
Block(-4,37,-1,SNOW:6)
Block(-4,37,1,SNOW:0)
RandomBlock(-4,37,2,AIR:0,20,CHEST:2,../../../../Chests/Loot/ShipJunk_1.nbt,10,CHEST:2,../../../../Chests/Loot/ShipJunk_2.nbt,10,CHEST:2,../../../../Chests/Loot/ShipJunk_3.nbt,10,CHEST:2,../../../../Chests/Loot/ShipJunk_4.nbt,10,CHEST:2,../../../../Chests/Loot/ShipJunk_5.nbt,10,CHEST:2,../../../../Chests/Lore/Frozen_1.nbt,1,CHEST:2,../../../../Chests/Lore/Frozen_2.nbt,1,CHEST:2,../../../../Chests/Lore/Frozen_3.nbt,1,CHEST:2,../../../../Chests/Lore/Frozen_4.nbt,1,CHEST:2,../../../../Chests/Lore/Frozen_5.nbt,1,CHEST:2,../../../../Chests/Loot/Common1.nbt,10,CHEST:2,../../../../Chests/Loot/Common2.nbt,10,CHEST:2,../../../../Chests/Loot/Common3.nbt,10,CHEST:2,../../../../Chests/Loot/Common4.nbt,10,CHEST:2,../../../../Chests/Loot/Common5.nbt,10,CHEST:2,../../../../Chests/Loot/Common6.nbt,10,CHEST:2,../../../../Chests/Loot/Common7.nbt,10,CHEST:2,../../../../Chests/Loot/Common8.nbt,10,CHEST:2,../../../../Chests/Loot/Common9.nbt,10,CHEST:2,../../../../Chests/Loot/Common10.nbt,10,CHEST:2,../../../../Chests/Loot/Common10.nbt,11,CHEST:2,../../../../Chests/Loot/Common12.nbt,10,CHEST:2,../../../../Chests/Loot/Common13.nbt,10,CHEST:2,../../../../Chests/Loot/Common14.nbt,10,CHEST:2,../../../../Chests/Loot/Common15.nbt,10,CHEST:2,../../../../Chests/Lore/Frozen_1.nbt,2,CHEST:2,../../../../Chests/Lore/Frozen_3.nbt,2,CHEST:2,../../../../Chests/Lore/Frozen_4.nbt,2,CHEST:2,../../../../Chests/Lore/Frozen_5.nbt,2,CHEST:2,../../../../Chests/Lore/Frozen_5.nbt,2,CHEST:2,../../../../Chests/Loot/Rare1.nbt,5,CHEST:2,../../../../Chests/Loot/Rare2.nbt,5,CHEST:2,../../../../Chests/Loot/Rare3.nbt,5,CHEST:2,../../../../Chests/Loot/Rare4.nbt,5,CHEST:2,../../../../Chests/Loot/Rare5.nbt,5,CHEST:2,../../../../Chests/Loot/Rare6.nbt,5,CHEST:2,../../../../Chests/Loot/Rare7.nbt,5,CHEST:2,../../../../Chests/Loot/Rare8.nbt,5,CHEST:2,../../../../Chests/Loot/Rare9.nbt,5,CHEST:2,../../../../Chests/Loot/Rare10.nbt,5,CHEST:2,../../../../Chests/Loot/Rare11.nbt,5,CHEST:2,../../../../Chests/Loot/Rare12.nbt,5,CHEST:2,../../../../Chests/Loot/Rare13.nbt,5,CHEST:2,../../../../Chests/Loot/Rare14.nbt,5,CHEST:2,../../../../Chests/Loot/Rare15.nbt,5,CHEST:2,../../../../Chests/Loot/Epic1.nbt,2,CHEST:2,../../../../Chests/Loot/Epic2.nbt,2,CHEST:2,../../../../Chests/Loot/Epic3.nbt,2,CHEST:2,../../../../Chests/Loot/Epic4.nbt,2,CHEST:2,../../../../Chests/Loot/Epic5.nbt,2,CHEST:2,../../../../Chests/Loot/Epic6.nbt,2,CHEST:2,../../../../Chests/Loot/Epic7.nbt,2,CHEST:2,../../../../Chests/Loot/Epic8.nbt,2,CHEST:2,../../../../Chests/Loot/Epic9.nbt,2,CHEST:2,../../../../Chests/Loot/Epic10.nbt,2,CHEST:2,../../../../Chests/Loot/Epic11.nbt,2,CHEST:2,../../../../Chests/Loot/Epic12.nbt,2,CHEST:2,../../../../Chests/Loot/Epic13.nbt,2,CHEST:2,../../../../Chests/Loot/Epic14.nbt,2,CHEST:2,../../../../Chests/Loot/Epic15.nbt,5,CHEST:2,../../../../Chests/Loot/Rare1.nbt,5,CHEST:2,../../../../Chests/Loot/Rare2.nbt,5,CHEST:2,../../../../Chests/Loot/Rare3.nbt,5,CHEST:2,../../../../Chests/Loot/Rare4.nbt,5,CHEST:2,../../../../Chests/Loot/Rare5.nbt,10,CHEST:2,../../../../Chests/Loot/Rare6.nbt,10,CHEST:2,../../../../Chests/Loot/Rare7.nbt,10,CHEST:2,../../../../Chests/Loot/Rare8.nbt,10,CHEST:2,../../../../Chests/Loot/Rare9.nbt,10,CHEST:2,../../../../Chests/Loot/Rare10.nbt,15,CHEST:2,../../../../Chests/Loot/Rare11.nbt,15,CHEST:2,../../../../Chests/Loot/Rare12.nbt,15,CHEST:2,../../../../Chests/Loot/Rare13.nbt,15,CHEST:2,../../../../Chests/Loot/Rare14.nbt,15,CHEST:2,../../../../Chests/Loot/Rare15.nbt,15,CHEST:2,../../../../Chests/Loot/Epic15.nbt,100)
Block(-4,37,3,LOG_2:1)
Block(-4,37,4,PACKED_ICE:0)
Block(-4,38,-7,ICE:0)
Block(-4,38,-6,ICE:0)
Block(-4,38,-5,LOG_2:1)
Block(-4,38,-4,WOOD_DOUBLE_STEP:1)
Block(-4,38,-3,BED_BLOCK:1)
Block(-4,38,4,WOOD_DOUBLE_STEP:1)
Block(-4,38,5,PACKED_ICE:0)
Block(-4,39,-7,ICE:0)
Block(-4,39,-6,ICE:0)
Block(-4,39,-5,WOOD:5)
Block(-4,39,-4,WOOD:5)
Block(-4,39,-3,WOOD:5)
Block(-4,39,-2,WOOD:5)
Block(-4,39,-1,WOOD:5)
Block(-4,39,0,WOOD:5)
Block(-4,39,1,WOOD:5)
Block(-4,39,2,WOOD:5)
Block(-4,39,3,WOOD:5)
Block(-4,39,4,WOOD:5)
Block(-4,39,5,PACKED_ICE:0)
Block(-4,39,6,ICE:0)
Block(-4,40,-7,ICE:0)
Block(-4,40,-6,PACKED_ICE:0)
Block(-4,40,-5,WOOD:5)
Block(-4,40,-4,STAINED_CLAY:9)
Block(-4,40,-3,STAINED_CLAY:9)
Block(-4,40,-2,STAINED_CLAY:9)
Block(-4,40,-1,ICE:0)
Block(-4,40,0,STAINED_CLAY:9)
Block(-4,40,1,ICE:0)
Block(-4,40,2,STAINED_CLAY:9)
Block(-4,40,3,STAINED_CLAY:9)
Block(-4,40,4,STAINED_CLAY:9)
Block(-4,40,5,ICE:0)
Block(-4,40,6,ICE:0)
Block(-4,41,-6,PACKED_ICE:0)
Block(-4,41,-5,WOOD:5)
Block(-4,41,-4,STAINED_CLAY:9)
Block(-4,41,-3,ICE:0)
Block(-4,41,-2,STAINED_CLAY:9)
Block(-4,41,-1,ICE:0)
Block(-4,41,0,ICE:0)
Block(-4,41,1,ICE:0)
Block(-4,41,2,STAINED_CLAY:9)
Block(-4,41,3,STAINED_CLAY:9)
Block(-4,41,4,STAINED_CLAY:9)
Block(-4,41,5,PACKED_ICE:0)
Block(-4,41,6,SNOW:0)
Block(-4,42,-6,SNOW:0)
Block(-4,42,-5,PACKED_ICE:0)
Block(-4,42,-4,PACKED_ICE:0)
Block(-4,42,-3,PACKED_ICE:0)
Block(-4,42,-2,ICE:0)
Block(-4,42,-1,ICE:0)
Block(-4,42,0,ICE:0)
Block(-4,42,1,ICE:0)
Block(-4,42,2,SNOW_BLOCK:0)
Block(-4,42,3,WOOD_DOUBLE_STEP:5)
Block(-4,42,4,WOOD_DOUBLE_STEP:5)
Block(-4,42,5,WOOD:5)
Block(-4,43,-5,SNOW_BLOCK:0)
Block(-4,43,-4,PACKED_ICE:0)
Block(-4,43,-3,PACKED_ICE:0)
Block(-4,43,-2,PACKED_ICE:0)
Block(-4,43,-1,ICE:0)
Block(-4,43,0,SNOW_BLOCK:0)
Block(-4,43,1,SNOW_BLOCK:0)
Block(-4,43,2,SNOW:7)
Block(-4,43,3,SNOW:7)
Block(-4,43,4,SNOW:5)
Block(-4,43,5,SNOW:3)
Block(-4,44,-5,SNOW:1)
Block(-4,44,-3,PACKED_ICE:0)
Block(-4,44,0,SNOW:2)
Block(-4,44,1,SNOW:1)
Block(-4,45,-3,ICE:0)
Block(-4,46,-3,SNOW:0)
Block(-3,11,-5,PACKED_ICE:0)
Block(-3,11,0,ICE:0)
Block(-3,11,1,ICE:0)
Block(-3,11,2,ICE:0)
Block(-3,12,-5,PACKED_ICE:0)
Block(-3,12,-1,ICE:0)
Block(-3,12,0,ICE:0)
Block(-3,12,1,ICE:0)
Block(-3,12,2,ICE:0)
Block(-3,12,3,ICE:0)
Block(-3,13,-6,PACKED_ICE:0)
Block(-3,13,-5,PACKED_ICE:0)
Block(-3,13,-3,ICE:0)
Block(-3,13,-2,ICE:0)
Block(-3,13,-1,ICE:0)
Block(-3,13,0,PACKED_ICE:0)
Block(-3,13,1,ICE:0)
Block(-3,13,2,PACKED_ICE:0)
Block(-3,13,3,PACKED_ICE:0)
Block(-3,13,4,PACKED_ICE:0)
Block(-3,14,-6,PACKED_ICE:0)
Block(-3,14,-5,PACKED_ICE:0)
Block(-3,14,-4,PACKED_ICE:0)
Block(-3,14,-3,PACKED_ICE:0)
Block(-3,14,-2,ICE:0)
Block(-3,14,-1,PACKED_ICE:0)
Block(-3,14,0,PACKED_ICE:0)
Block(-3,14,1,PACKED_ICE:0)
Block(-3,14,2,PACKED_ICE:0)
Block(-3,14,3,PACKED_ICE:0)
Block(-3,14,4,PACKED_ICE:0)
Block(-3,14,5,PACKED_ICE:0)
Block(-3,15,-6,PACKED_ICE:0)
Block(-3,15,-5,PACKED_ICE:0)
Block(-3,15,-4,PACKED_ICE:0)
Block(-3,15,-3,PACKED_ICE:0)
Block(-3,15,-2,PACKED_ICE:0)
Block(-3,15,-1,PACKED_ICE:0)
Block(-3,15,0,PACKED_ICE:0)
Block(-3,15,1,PACKED_ICE:0)
Block(-3,15,2,PACKED_ICE:0)
Block(-3,15,3,PACKED_ICE:0)
Block(-3,15,4,ICE:0)
Block(-3,15,5,PACKED_ICE:0)
Block(-3,15,6,PACKED_ICE:0)
Block(-3,16,-6,ICE:0)
Block(-3,16,-5,PACKED_ICE:0)
Block(-3,16,-4,PACKED_ICE:0)
Block(-3,16,-3,PACKED_ICE:0)
Block(-3,16,-2,PACKED_ICE:0)
Block(-3,16,-1,PACKED_ICE:0)
Block(-3,16,0,PACKED_ICE:0)
Block(-3,16,1,PACKED_ICE:0)
Block(-3,16,2,PACKED_ICE:0)
Block(-3,16,3,PACKED_ICE:0)
Block(-3,16,4,PACKED_ICE:0)
Block(-3,16,5,PACKED_ICE:0)
Block(-3,16,6,PACKED_ICE:0)
Block(-3,17,-6,ICE:0)
Block(-3,17,-5,ICE:0)
Block(-3,17,-4,PACKED_ICE:0)
Block(-3,17,-3,PACKED_ICE:0)
Block(-3,17,-2,PACKED_ICE:0)
Block(-3,17,-1,PACKED_ICE:0)
Block(-3,17,0,PACKED_ICE:0)
Block(-3,17,1,PACKED_ICE:0)
Block(-3,17,2,PACKED_ICE:0)
Block(-3,17,3,PACKED_ICE:0)
Block(-3,17,4,PACKED_ICE:0)
Block(-3,17,5,PACKED_ICE:0)
Block(-3,17,6,PACKED_ICE:0)
Block(-3,18,-6,ICE:0)
Block(-3,18,-5,PACKED_ICE:0)
Block(-3,18,-4,PACKED_ICE:0)
Block(-3,18,-3,PACKED_ICE:0)
Block(-3,18,-2,PACKED_ICE:0)
Block(-3,18,-1,PACKED_ICE:0)
Block(-3,18,0,PACKED_ICE:0)
Block(-3,18,1,PACKED_ICE:0)
Block(-3,18,2,PACKED_ICE:0)
Block(-3,18,3,PACKED_ICE:0)
Block(-3,18,4,PACKED_ICE:0)
Block(-3,18,5,PACKED_ICE:0)
Block(-3,19,-6,PACKED_ICE:0)
Block(-3,19,-5,PACKED_ICE:0)
Block(-3,19,-4,PACKED_ICE:0)
Block(-3,19,-3,PACKED_ICE:0)
Block(-3,19,-2,PACKED_ICE:0)
Block(-3,19,-1,PACKED_ICE:0)
Block(-3,19,0,PACKED_ICE:0)
Block(-3,19,1,PACKED_ICE:0)
Block(-3,19,2,PACKED_ICE:0)
Block(-3,19,3,PACKED_ICE:0)
Block(-3,19,4,PACKED_ICE:0)
Block(-3,20,-5,PACKED_ICE:0)
Block(-3,20,-4,PACKED_ICE:0)
Block(-3,20,-3,PACKED_ICE:0)
Block(-3,20,-2,PACKED_ICE:0)
Block(-3,20,-1,PACKED_ICE:0)
Block(-3,20,0,PACKED_ICE:0)
Block(-3,20,1,PACKED_ICE:0)
Block(-3,20,2,PACKED_ICE:0)
Block(-3,20,3,PACKED_ICE:0)
Block(-3,20,4,PACKED_ICE:0)
Block(-3,21,-5,PACKED_ICE:0)
Block(-3,21,-4,PACKED_ICE:0)
Block(-3,21,-3,PACKED_ICE:0)
Block(-3,21,-2,PACKED_ICE:0)
Block(-3,21,-1,PACKED_ICE:0)
Block(-3,21,0,PACKED_ICE:0)
Block(-3,21,1,PACKED_ICE:0)
Block(-3,21,2,PACKED_ICE:0)
Block(-3,21,3,ICE:0)
Block(-3,21,4,ICE:0)
Block(-3,22,-5,PACKED_ICE:0)
Block(-3,22,-4,PACKED_ICE:0)
Block(-3,22,-3,PACKED_ICE:0)
Block(-3,22,0,PACKED_ICE:0)
Block(-3,22,1,PACKED_ICE:0)
Block(-3,22,2,ICE:0)
Block(-3,22,3,ICE:0)
Block(-3,22,4,ICE:0)
Block(-3,23,-5,PACKED_ICE:0)
Block(-3,23,-4,PACKED_ICE:0)
Block(-3,23,1,PACKED_ICE:0)
Block(-3,23,2,PACKED_ICE:0)
Block(-3,23,3,ICE:0)
Block(-3,23,4,ICE:0)
Block(-3,24,-5,PACKED_ICE:0)
Block(-3,24,-4,PACKED_ICE:0)
Block(-3,24,-3,PACKED_ICE:0)
Block(-3,24,0,PACKED_ICE:0)
Block(-3,24,1,PACKED_ICE:0)
Block(-3,24,2,PACKED_ICE:0)
Block(-3,24,3,PACKED_ICE:0)
Block(-3,25,-4,PACKED_ICE:0)
Block(-3,25,0,PACKED_ICE:0)
Block(-3,25,1,PACKED_ICE:0)
Block(-3,25,2,PACKED_ICE:0)
Block(-3,26,-4,PACKED_ICE:0)
Block(-3,26,-3,PACKED_ICE:0)
Block(-3,26,-1,PACKED_ICE:0)
Block(-3,26,0,PACKED_ICE:0)
Block(-3,26,1,PACKED_ICE:0)
Block(-3,26,2,PACKED_ICE:0)
Block(-3,27,-3,PACKED_ICE:0)
Block(-3,27,-2,PACKED_ICE:0)
Block(-3,27,-1,PACKED_ICE:0)
Block(-3,27,0,PACKED_ICE:0)
Block(-3,27,1,PACKED_ICE:0)
Block(-3,27,2,PACKED_ICE:0)
Block(-3,28,-3,PACKED_ICE:0)
Block(-3,28,-2,PACKED_ICE:0)
Block(-3,28,-1,PACKED_ICE:0)
Block(-3,28,0,PACKED_ICE:0)
Block(-3,28,1,PACKED_ICE:0)
Block(-3,29,-3,ICE:0)
Block(-3,29,-2,ICE:0)
Block(-3,29,-1,PACKED_ICE:0)
Block(-3,29,0,PACKED_ICE:0)
Block(-3,29,1,PACKED_ICE:0)
Block(-3,30,-2,ICE:0)
Block(-3,30,-1,PACKED_ICE:0)
Block(-3,30,0,PACKED_ICE:0)
Block(-3,30,1,PACKED_ICE:0)
Block(-3,31,-1,SNOW_BLOCK:0)
Block(-3,31,0,SNOW_BLOCK:0)
Block(-3,32,-2,ICE:0)
Block(-3,32,-1,SNOW:3)
Block(-3,32,0,SNOW:0)
Block(-3,33,-2,ICE:0)
Block(-3,34,-2,ICE:0)
Block(-3,34,0,WOOD:5)
Block(-3,34,5,PACKED_ICE:0)
Block(-3,35,-2,ICE:0)
Block(-3,35,0,LOG_2:1)
Block(-3,35,1,PACKED_ICE:0)
Block(-3,35,5,PACKED_ICE:0)
Block(-3,36,-3,PACKED_ICE:0)
Block(-3,36,-2,ICE:0)
Block(-3,36,-1,LOG_2:1)
Block(-3,36,0,WOOD_STEP:9)
Block(-3,36,1,LOG_2:1)
Block(-3,36,2,PACKED_ICE:0)
Block(-3,36,3,PACKED_ICE:0)
Block(-3,36,5,PACKED_ICE:0)
Block(-3,37,-4,ICE:0)
Block(-3,37,-3,LOG_2:1)
Block(-3,37,-2,LOG_2:1)
Block(-3,37,2,LOG_2:1)
Block(-3,37,3,LOG_2:1)
Block(-3,37,5,PACKED_ICE:0)
Block(-3,38,-5,ICE:0)
Block(-3,38,-4,LOG_2:1)
Block(-3,38,-3,WOOD_DOUBLE_STEP:1)
Block(-3,38,-2,BED_BLOCK:3)
Block(-3,38,3,WOOD_DOUBLE_STEP:1)
Block(-3,38,4,LOG_2:1)
Block(-3,38,5,PACKED_ICE:0)
Block(-3,38,6,ICE:0)
Block(-3,39,-7,ICE:0)
Block(-3,39,-6,PACKED_ICE:0)
Block(-3,39,-5,WOOD:5)
Block(-3,39,-4,WOOD:5)
Block(-3,39,-3,WOOD:5)
Block(-3,39,-2,WOOD:5)
Block(-3,39,-1,WOOD:5)
Block(-3,39,0,WOOD:5)
Block(-3,39,1,WOOD:5)
Block(-3,39,2,WOOD:5)
Block(-3,39,3,WOOD:5)
Block(-3,39,4,WOOD:5)
Block(-3,39,5,PACKED_ICE:0)
Block(-3,39,6,ICE:0)
Block(-3,40,-7,PACKED_ICE:0)
Block(-3,40,-6,ICE:0)
Block(-3,40,-5,WOOD:5)
Block(-3,40,-4,ICE:0)
Block(-3,40,-3,ICE:0)
Block(-3,40,-2,LOG:1)
Block(-3,40,-1,PACKED_ICE:0)
Block(-3,40,0,PACKED_ICE:0)
Block(-3,40,1,PACKED_ICE:0)
Block(-3,40,2,LOG:1)
Block(-3,40,4,ICE:0)
Block(-3,40,5,ICE:0)
Block(-3,40,6,SNOW:0)
Block(-3,41,-6,PACKED_ICE:0)
Block(-3,41,-5,ICE:0)
Block(-3,41,-4,ICE:0)
Block(-3,41,-3,ICE:0)
Block(-3,41,-2,ICE:0)
Block(-3,41,-1,ICE:0)
Block(-3,41,0,PACKED_ICE:0)
Block(-3,41,1,PACKED_ICE:0)
Block(-3,41,2,LOG:1)
Block(-3,41,5,ICE:0)
Block(-3,42,-6,PACKED_ICE:0)
Block(-3,42,-5,PACKED_ICE:0)
Block(-3,42,-4,PACKED_ICE:0)
Block(-3,42,-3,ICE:0)
Block(-3,42,-2,ICE:0)
Block(-3,42,-1,PACKED_ICE:0)
Block(-3,42,0,PACKED_ICE:0)
Block(-3,42,1,SNOW_BLOCK:0)
Block(-3,42,2,SNOW_BLOCK:0)
Block(-3,42,3,WOOD_STEP:13)
Block(-3,42,4,SNOW_BLOCK:0)
Block(-3,42,5,PACKED_ICE:0)
Block(-3,43,-5,SNOW_BLOCK:0)
Block(-3,43,-4,SNOW_BLOCK:0)
Block(-3,43,-3,PACKED_ICE:0)
Block(-3,43,-2,ICE:0)
Block(-3,43,-1,PACKED_ICE:0)
Block(-3,43,0,ICE:0)
Block(-3,43,1,SNOW_BLOCK:0)
Block(-3,43,2,SNOW_BLOCK:0)
Block(-3,43,3,SNOW_BLOCK:0)
Block(-3,43,4,SNOW:4)
Block(-3,44,-5,SNOW:0)
Block(-3,44,-4,SNOW:3)
Block(-3,44,-1,PACKED_ICE:0)
Block(-3,44,0,SNOW_BLOCK:0)
Block(-3,44,1,SNOW:6)
Block(-3,44,2,SNOW:3)
Block(-3,44,3,SNOW:1)
Block(-3,45,-1,ICE:0)
Block(-3,45,0,SNOW:1)
Block(-3,46,-1,SNOW:0)
Block(-2,11,0,ICE:0)
Block(-2,12,-1,ICE:0)
Block(-2,12,0,ICE:0)
Block(-2,12,1,ICE:0)
Block(-2,13,-2,ICE:0)
Block(-2,13,-1,ICE:0)
Block(-2,13,0,ICE:0)
Block(-2,13,1,ICE:0)
Block(-2,13,2,ICE:0)
Block(-2,13,3,ICE:0)
Block(-2,14,-4,PACKED_ICE:0)
Block(-2,14,-3,ICE:0)
Block(-2,14,-2,ICE:0)
Block(-2,14,-1,ICE:0)
Block(-2,14,0,PACKED_ICE:0)
Block(-2,14,1,ICE:0)
Block(-2,14,2,ICE:0)
Block(-2,14,3,ICE:0)
Block(-2,14,4,ICE:0)
Block(-2,14,5,PACKED_ICE:0)
Block(-2,15,-5,PACKED_ICE:0)
Block(-2,15,-4,PACKED_ICE:0)
Block(-2,15,-3,PACKED_ICE:0)
Block(-2,15,-2,PACKED_ICE:0)
Block(-2,15,-1,PACKED_ICE:0)
Block(-2,15,0,PACKED_ICE:0)
Block(-2,15,1,PACKED_ICE:0)
Block(-2,15,2,ICE:0)
Block(-2,15,3,ICE:0)
Block(-2,15,4,ICE:0)
Block(-2,15,5,ICE:0)
Block(-2,16,-5,ICE:0)
Block(-2,16,-4,PACKED_ICE:0)
Block(-2,16,-3,PACKED_ICE:0)
Block(-2,16,-2,PACKED_ICE:0)
Block(-2,16,-1,PACKED_ICE:0)
Block(-2,16,0,PACKED_ICE:0)
Block(-2,16,1,PACKED_ICE:0)
Block(-2,16,2,ICE:0)
Block(-2,16,3,ICE:0)
Block(-2,16,4,ICE:0)
Block(-2,16,5,ICE:0)
Block(-2,16,6,ICE:0)
Block(-2,17,-7,ICE:0)
Block(-2,17,-6,ICE:0)
Block(-2,17,-5,ICE:0)
Block(-2,17,-4,PACKED_ICE:0)
Block(-2,17,-3,PACKED_ICE:0)
Block(-2,17,-2,PACKED_ICE:0)
Block(-2,17,-1,PACKED_ICE:0)
Block(-2,17,0,PACKED_ICE:0)
Block(-2,17,1,PACKED_ICE:0)
Block(-2,17,2,ICE:0)
Block(-2,17,3,ICE:0)
Block(-2,17,4,ICE:0)
Block(-2,17,5,ICE:0)
Block(-2,18,-6,ICE:0)
Block(-2,18,-5,ICE:0)
Block(-2,18,-4,PACKED_ICE:0)
Block(-2,18,-3,PACKED_ICE:0)
Block(-2,18,-2,PACKED_ICE:0)
Block(-2,18,-1,PACKED_ICE:0)
Block(-2,18,0,PACKED_ICE:0)
Block(-2,18,1,PACKED_ICE:0)
Block(-2,18,2,ICE:0)
Block(-2,18,3,ICE:0)
Block(-2,18,4,ICE:0)
Block(-2,19,-6,PACKED_ICE:0)
Block(-2,19,-5,PACKED_ICE:0)
Block(-2,19,-4,PACKED_ICE:0)
Block(-2,19,-3,PACKED_ICE:0)
Block(-2,19,-2,PACKED_ICE:0)
Block(-2,19,-1,PACKED_ICE:0)
Block(-2,19,0,PACKED_ICE:0)
Block(-2,19,1,PACKED_ICE:0)
Block(-2,19,2,ICE:0)
Block(-2,19,3,ICE:0)
Block(-2,19,4,ICE:0)
Block(-2,20,-6,PACKED_ICE:0)
Block(-2,20,-5,PACKED_ICE:0)
Block(-2,20,-4,PACKED_ICE:0)
Block(-2,20,-3,PACKED_ICE:0)
Block(-2,20,-2,PACKED_ICE:0)
Block(-2,20,-1,PACKED_ICE:0)
Block(-2,20,0,PACKED_ICE:0)
Block(-2,20,1,PACKED_ICE:0)
Block(-2,20,2,ICE:0)
Block(-2,20,3,ICE:0)
Block(-2,20,4,ICE:0)
Block(-2,21,-6,PACKED_ICE:0)
Block(-2,21,-5,PACKED_ICE:0)
Block(-2,21,-4,PACKED_ICE:0)
Block(-2,21,-3,PACKED_ICE:0)
Block(-2,21,-2,PACKED_ICE:0)
Block(-2,21,-1,PACKED_ICE:0)
Block(-2,21,0,PACKED_ICE:0)
Block(-2,21,1,PACKED_ICE:0)
Block(-2,21,2,ICE:0)
Block(-2,21,3,ICE:0)
Block(-2,22,-5,PACKED_ICE:0)
Block(-2,22,-4,PACKED_ICE:0)
Block(-2,22,-3,PACKED_ICE:0)
Block(-2,22,1,PACKED_ICE:0)
Block(-2,22,2,ICE:0)
Block(-2,22,3,ICE:0)
Block(-2,23,-5,PACKED_ICE:0)
Block(-2,23,-4,PACKED_ICE:0)
Block(-2,23,-3,PACKED_ICE:0)
Block(-2,23,1,PACKED_ICE:0)
Block(-2,23,2,ICE:0)
Block(-2,23,3,ICE:0)
Block(-2,24,-5,PACKED_ICE:0)
Block(-2,24,-4,PACKED_ICE:0)
Block(-2,24,-3,PACKED_ICE:0)
Block(-2,24,1,PACKED_ICE:0)
Block(-2,24,2,ICE:0)
Block(-2,25,-5,PACKED_ICE:0)
Block(-2,25,-4,PACKED_ICE:0)
Block(-2,25,-3,PACKED_ICE:0)
Block(-2,25,-2,PACKED_ICE:0)
Block(-2,25,-1,PACKED_ICE:0)
Block(-2,25,0,PACKED_ICE:0)
Block(-2,25,1,PACKED_ICE:0)
Block(-2,25,2,ICE:0)
Block(-2,26,-5,PACKED_ICE:0)
Block(-2,26,-4,PACKED_ICE:0)
Block(-2,26,-3,PACKED_ICE:0)
Block(-2,26,-2,PACKED_ICE:0)
Block(-2,26,-1,PACKED_ICE:0)
Block(-2,26,0,PACKED_ICE:0)
Block(-2,26,2,ICE:0)
Block(-2,27,-5,SNOW:0)
Block(-2,27,-4,PACKED_ICE:0)
Block(-2,27,-3,PACKED_ICE:0)
Block(-2,27,-2,PACKED_ICE:0)
Block(-2,27,-1,PACKED_ICE:0)
Block(-2,27,0,PACKED_ICE:0)
Block(-2,28,-4,PACKED_ICE:0)
Block(-2,28,-3,PACKED_ICE:0)
Block(-2,28,-2,PACKED_ICE:0)
Block(-2,28,-1,PACKED_ICE:0)
Block(-2,29,-4,PACKED_ICE:0)
Block(-2,29,-3,ICE:0)
Block(-2,29,-2,PACKED_ICE:0)
Block(-2,29,-1,PACKED_ICE:0)
Block(-2,30,-3,ICE:0)
Block(-2,30,-2,ICE:0)
Block(-2,31,-3,ICE:0)
Block(-2,34,0,WOOD:5)
Block(-2,34,1,PACKED_ICE:0)
Block(-2,35,-4,ICE:0)
Block(-2,35,-2,PACKED_ICE:0)
Block(-2,35,0,LOG_2:1)
Block(-2,35,1,PACKED_ICE:0)
Block(-2,35,2,PACKED_ICE:0)
Block(-2,36,-7,ICE:0)
Block(-2,36,-4,ICE:0)
Block(-2,36,-3,PACKED_ICE:0)
Block(-2,36,-2,PACKED_ICE:0)
Block(-2,36,-1,LOG_2:1)
Block(-2,36,0,WOOD_STEP:9)
Block(-2,36,1,LOG_2:1)
Block(-2,36,2,PACKED_ICE:0)
Block(-2,37,-7,ICE:0)
Block(-2,37,-5,ICE:0)
Block(-2,37,-4,ICE:0)
Block(-2,37,-3,LOG_2:1)
Block(-2,37,-2,LOG_2:1)
Block(-2,37,0,SKULL:1)
Block(-2,37,2,LOG_2:1)
Block(-2,37,3,LOG_2:1)
Block(-2,38,-7,ICE:0)
Block(-2,38,-5,ICE:0)
Block(-2,38,-4,LOG_2:1)
Block(-2,38,-3,WOOD_DOUBLE_STEP:1)
Block(-2,38,-2,BED_BLOCK:11)
Block(-2,38,2,SKULL:1)
Block(-2,38,3,WOOD_DOUBLE_STEP:1)
Block(-2,38,4,LOG_2:1)
Block(-2,39,-7,ICE:0)
Block(-2,39,-6,ICE:0)
Block(-2,39,-5,ICE:0)
Block(-2,39,-4,WOOD:5)
Block(-2,39,-3,WOOD:5)
Block(-2,39,-2,PACKED_ICE:0)
Block(-2,39,-1,WOOD:5)
Block(-2,39,0,WOOD:5)
Block(-2,39,1,WOOD:5)
Block(-2,39,2,WOOD:5)
Block(-2,39,3,WOOD:5)
Block(-2,39,4,WOOD:5)
Block(-2,39,5,ICE:0)
Block(-2,40,-7,ICE:0)
Block(-2,40,-6,ICE:0)
Block(-2,40,-5,PACKED_ICE:0)
Block(-2,40,-4,ICE:0)
Block(-2,40,-3,PACKED_ICE:0)
Block(-2,40,-2,ICE:0)
Block(-2,40,-1,PACKED_ICE:0)
Block(-2,40,0,PACKED_ICE:0)
Block(-2,40,1,PACKED_ICE:0)
Block(-2,40,5,WOOD:5)
Block(-2,41,-7,PACKED_ICE:0)
Block(-2,41,-6,ICE:0)
Block(-2,41,-5,PACKED_ICE:0)
Block(-2,41,-4,PACKED_ICE:0)
Block(-2,41,-3,ICE:0)
Block(-2,41,-2,ICE:0)
Block(-2,41,-1,PACKED_ICE:0)
Block(-2,41,0,PACKED_ICE:0)
Block(-2,41,1,PACKED_ICE:0)
Block(-2,41,5,ICE:0)
Block(-2,42,-5,SNOW_BLOCK:0)
Block(-2,42,-4,PACKED_ICE:0)
Block(-2,42,-3,ICE:0)
Block(-2,42,-2,PACKED_ICE:0)
Block(-2,42,-1,PACKED_ICE:0)
Block(-2,42,0,PACKED_ICE:0)
Block(-2,42,1,PACKED_ICE:0)
Block(-2,42,2,WOOD_STEP:13)
Block(-2,42,3,SNOW_BLOCK:0)
Block(-2,42,4,SNOW_BLOCK:0)
Block(-2,42,5,PACKED_ICE:0)
Block(-2,43,-5,SNOW:4)
Block(-2,43,-4,SNOW_BLOCK:0)
Block(-2,43,-3,SNOW_BLOCK:0)
Block(-2,43,-2,PACKED_ICE:0)
Block(-2,43,-1,PACKED_ICE:0)
Block(-2,43,0,PACKED_ICE:0)
Block(-2,43,1,ICE:0)
Block(-2,43,2,SNOW_BLOCK:0)
Block(-2,43,3,SNOW_BLOCK:0)
Block(-2,43,4,SNOW:6)
Block(-2,44,-4,SNOW:1)
Block(-2,44,-3,SNOW:6)
Block(-2,44,-2,PACKED_ICE:0)
Block(-2,44,-1,ICE:0)
Block(-2,44,0,ICE:0)
Block(-2,44,1,SNOW_BLOCK:0)
Block(-2,44,2,SNOW:2)
Block(-2,44,3,SNOW:0)
Block(-2,45,-2,PACKED_ICE:0)
Block(-2,45,-1,PACKED_ICE:0)
Block(-2,45,0,SNOW_BLOCK:0)
Block(-2,45,1,SNOW:1)
Block(-2,46,-2,SNOW:0)
Block(-2,46,-1,PACKED_ICE:0)
Block(-2,46,0,SNOW:3)
Block(-2,47,-1,PACKED_ICE:0)
Block(-2,48,-1,ICE:0)
Block(-2,49,-1,SNOW:0)
Block(-1,11,-1,ICE:0)
Block(-1,12,-2,ICE:0)
Block(-1,12,-1,ICE:0)
Block(-1,12,0,ICE:0)
Block(-1,13,-2,ICE:0)
Block(-1,13,-1,ICE:0)
Block(-1,13,0,ICE:0)
Block(-1,13,1,ICE:0)
Block(-1,14,-3,ICE:0)
Block(-1,14,-2,ICE:0)
Block(-1,14,-1,ICE:0)
Block(-1,14,0,ICE:0)
Block(-1,14,1,ICE:0)
Block(-1,14,2,ICE:0)
Block(-1,14,3,ICE:0)
Block(-1,15,-4,PACKED_ICE:0)
Block(-1,15,-3,PACKED_ICE:0)
Block(-1,15,-2,PACKED_ICE:0)
Block(-1,15,-1,PACKED_ICE:0)
Block(-1,15,0,ICE:0)
Block(-1,15,1,ICE:0)
Block(-1,15,2,ICE:0)
Block(-1,15,3,ICE:0)
Block(-1,15,4,ICE:0)
Block(-1,15,5,ICE:0)
Block(-1,16,-5,PACKED_ICE:0)
Block(-1,16,-4,PACKED_ICE:0)
Block(-1,16,-3,PACKED_ICE:0)
Block(-1,16,-2,PACKED_ICE:0)
Block(-1,16,-1,PACKED_ICE:0)
Block(-1,16,0,ICE:0)
Block(-1,16,1,ICE:0)
Block(-1,16,2,ICE:0)
Block(-1,16,3,ICE:0)
Block(-1,16,4,ICE:0)
Block(-1,16,5,ICE:0)
Block(-1,17,-6,ICE:0)
Block(-1,17,-5,ICE:0)
Block(-1,17,-4,PACKED_ICE:0)
Block(-1,17,-3,PACKED_ICE:0)
Block(-1,17,-2,PACKED_ICE:0)
Block(-1,17,-1,PACKED_ICE:0)
Block(-1,17,0,ICE:0)
Block(-1,17,1,ICE:0)
Block(-1,17,2,ICE:0)
Block(-1,17,3,ICE:0)
Block(-1,17,4,ICE:0)
Block(-1,17,5,ICE:0)
Block(-1,18,-7,PACKED_ICE:0)
Block(-1,18,-6,ICE:0)
Block(-1,18,-5,PACKED_ICE:0)
Block(-1,18,-4,PACKED_ICE:0)
Block(-1,18,-3,PACKED_ICE:0)
Block(-1,18,-2,PACKED_ICE:0)
Block(-1,18,-1,PACKED_ICE:0)
Block(-1,18,0,ICE:0)
Block(-1,18,1,ICE:0)
Block(-1,18,2,ICE:0)
Block(-1,18,3,ICE:0)
Block(-1,18,4,ICE:0)
Block(-1,19,-7,PACKED_ICE:0)
Block(-1,19,-6,PACKED_ICE:0)
Block(-1,19,-5,PACKED_ICE:0)
Block(-1,19,-4,PACKED_ICE:0)
Block(-1,19,-3,PACKED_ICE:0)
Block(-1,19,-2,PACKED_ICE:0)
Block(-1,19,-1,PACKED_ICE:0)
Block(-1,19,0,ICE:0)
Block(-1,19,1,ICE:0)
Block(-1,19,2,ICE:0)
Block(-1,19,3,ICE:0)
Block(-1,20,-6,PACKED_ICE:0)
Block(-1,20,-5,PACKED_ICE:0)
Block(-1,20,-4,PACKED_ICE:0)
Block(-1,20,-3,PACKED_ICE:0)
Block(-1,20,-2,PACKED_ICE:0)
Block(-1,20,-1,PACKED_ICE:0)
Block(-1,20,0,ICE:0)
Block(-1,20,1,ICE:0)
Block(-1,20,2,ICE:0)
Block(-1,21,-6,PACKED_ICE:0)
Block(-1,21,-5,PACKED_ICE:0)
Block(-1,21,-4,PACKED_ICE:0)
Block(-1,21,-3,PACKED_ICE:0)
Block(-1,21,-2,PACKED_ICE:0)
Block(-1,21,0,ICE:0)
Block(-1,21,1,ICE:0)
Block(-1,21,2,ICE:0)
Block(-1,22,-6,PACKED_ICE:0)
Block(-1,22,-5,PACKED_ICE:0)
Block(-1,22,-4,PACKED_ICE:0)
Block(-1,22,-3,PACKED_ICE:0)
Block(-1,22,1,ICE:0)
Block(-1,22,2,ICE:0)
Block(-1,23,-6,PACKED_ICE:0)
Block(-1,23,-5,PACKED_ICE:0)
Block(-1,23,-4,PACKED_ICE:0)
Block(-1,23,-3,PACKED_ICE:0)
Block(-1,23,1,ICE:0)
Block(-1,24,-6,PACKED_ICE:0)
Block(-1,24,-5,PACKED_ICE:0)
Block(-1,24,-4,PACKED_ICE:0)
Block(-1,24,-3,PACKED_ICE:0)
Block(-1,24,-2,PACKED_ICE:0)
Block(-1,24,0,ICE:0)
Block(-1,24,1,ICE:0)
Block(-1,25,-6,PACKED_ICE:0)
Block(-1,25,-5,PACKED_ICE:0)
Block(-1,25,-4,PACKED_ICE:0)
Block(-1,25,-3,PACKED_ICE:0)
Block(-1,25,-2,PACKED_ICE:0)
Block(-1,25,-1,PACKED_ICE:0)
Block(-1,25,0,ICE:0)
Block(-1,26,-6,SNOW:0)
Block(-1,26,-5,PACKED_ICE:0)
Block(-1,26,-4,PACKED_ICE:0)
Block(-1,26,-3,PACKED_ICE:0)
Block(-1,26,-2,PACKED_ICE:0)
Block(-1,26,-1,PACKED_ICE:0)
Block(-1,26,0,ICE:0)
Block(-1,27,-5,PACKED_ICE:0)
Block(-1,27,-4,PACKED_ICE:0)
Block(-1,27,-3,PACKED_ICE:0)
Block(-1,27,-2,PACKED_ICE:0)
Block(-1,27,-1,PACKED_ICE:0)
Block(-1,28,-5,PACKED_ICE:0)
Block(-1,28,-4,PACKED_ICE:0)
Block(-1,28,-3,PACKED_ICE:0)
Block(-1,28,-2,PACKED_ICE:0)
Block(-1,28,-1,PACKED_ICE:0)
Block(-1,29,-5,SNOW:0)
Block(-1,29,-4,PACKED_ICE:0)
Block(-1,29,-3,PACKED_ICE:0)
Block(-1,29,-2,PACKED_ICE:0)
Block(-1,30,-4,ICE:0)
Block(-1,30,-3,ICE:0)
Block(-1,30,-2,PACKED_ICE:0)
Block(-1,31,2,ICE:0)
Block(-1,32,-5,ICE:0)
Block(-1,32,2,ICE:0)
Block(-1,33,-5,ICE:0)
Block(-1,33,2,ICE:0)
Block(-1,33,4,PACKED_ICE:0)
Block(-1,34,-5,ICE:0)
Block(-1,34,0,DARK_OAK_FENCE:0)
Block(-1,34,1,PACKED_ICE:0)
Block(-1,34,2,PACKED_ICE:0)
Block(-1,34,4,PACKED_ICE:0)
Block(-1,35,-5,PACKED_ICE:0)
Block(-1,35,0,WOOD:5)
Block(-1,35,1,PACKED_ICE:0)
Block(-1,35,2,PACKED_ICE:0)
Block(-1,35,4,PACKED_ICE:0)
Block(-1,36,-5,ICE:0)
Block(-1,36,-2,PACKED_ICE:0)
Block(-1,36,-1,LOG_2:1)
Block(-1,36,0,LOG_2:1)
Block(-1,36,1,LOG_2:1)
Block(-1,36,2,ICE:0)
Block(-1,36,3,ICE:0)
Block(-1,36,4,PACKED_ICE:0)
Block(-1,37,-5,ICE:0)
Block(-1,37,-3,LOG_2:1)
Block(-1,37,-2,LOG_2:1)
Block(-1,37,-1,LOG_2:1)
Block(-1,37,0,LOG_2:1)
Block(-1,37,1,LOG_2:1)
Block(-1,37,2,LOG_2:1)
Block(-1,37,3,LOG_2:1)
Block(-1,37,4,PACKED_ICE:0)
Block(-1,38,-6,ICE:0)
Block(-1,38,-5,PACKED_ICE:0)
Block(-1,38,-4,LOG_2:1)
Block(-1,38,-3,LOG_2:1)
Block(-1,38,-2,LOG_2:1)
Block(-1,38,-1,LOG_2:1)
Block(-1,38,0,LOG_2:1)
Block(-1,38,1,LOG_2:1)
Block(-1,38,2,LOG_2:1)
Block(-1,38,3,LOG_2:1)
Block(-1,38,4,PACKED_ICE:0)
Block(-1,38,5,ICE:0)
Block(-1,39,-7,ICE:0)
Block(-1,39,-6,ICE:0)
Block(-1,39,-5,PACKED_ICE:0)
Block(-1,39,-4,WOOD:5)
Block(-1,39,-2,PACKED_ICE:0)
Block(-1,39,-1,WOOD:5)
Block(-1,39,0,WOOD:5)
Block(-1,39,1,PACKED_ICE:0)
Block(-1,39,2,WOOD:5)
Block(-1,39,3,WOOD:5)
Block(-1,39,4,PACKED_ICE:0)
Block(-1,39,5,ICE:0)
Block(-1,40,-7,ICE:0)
Block(-1,40,-6,ICE:0)
Block(-1,40,-5,PACKED_ICE:0)
Block(-1,40,-4,WOOD:5)
Block(-1,40,-3,PACKED_ICE:0)
Block(-1,40,-2,PACKED_ICE:0)
Block(-1,40,-1,PACKED_ICE:0)
Block(-1,40,0,PACKED_ICE:0)
Block(-1,40,1,LOG:1)
Block(-1,40,2,PACKED_ICE:0)
Block(-1,40,4,PACKED_ICE:0)
Block(-1,40,5,ICE:0)
Block(-1,41,-7,SNOW:0)
Block(-1,41,-6,ICE:0)
Block(-1,41,-5,PACKED_ICE:0)
Block(-1,41,-4,WOOD_DOUBLE_STEP:5)
Block(-1,41,-3,ICE:0)
Block(-1,41,-2,ICE:0)
Block(-1,41,-1,LOG:1)
Block(-1,41,0,PACKED_ICE:0)
Block(-1,41,1,LOG:1)
Block(-1,41,4,WOOD_DOUBLE_STEP:5)
Block(-1,41,5,WOOD:5)
Block(-1,42,-6,SNOW:0)
Block(-1,42,-5,PACKED_ICE:0)
Block(-1,42,-4,WOOD_DOUBLE_STEP:5)
Block(-1,42,-3,WOOD_DOUBLE_STEP:1)
Block(-1,42,-2,ICE:0)
Block(-1,42,-1,ICE:0)
Block(-1,42,0,PACKED_ICE:0)
Block(-1,42,1,PACKED_ICE:0)
Block(-1,42,2,WOOD_STEP:13)
Block(-1,42,3,SNOW_BLOCK:0)
Block(-1,42,4,WOOD_DOUBLE_STEP:5)
Block(-1,42,5,WOOD:5)
Block(-1,43,-4,SNOW:3)
Block(-1,43,-3,SNOW:7)
Block(-1,43,-2,PACKED_ICE:0)
Block(-1,43,-1,PACKED_ICE:0)
Block(-1,43,0,ICE:0)
Block(-1,43,1,SNOW_BLOCK:0)
Block(-1,43,2,SNOW_BLOCK:0)
Block(-1,43,3,SNOW:7)
Block(-1,43,4,SNOW:5)
Block(-1,43,5,SNOW:2)
Block(-1,44,-2,PACKED_ICE:0)
Block(-1,44,-1,ICE:0)
Block(-1,44,0,SNOW_BLOCK:0)
Block(-1,44,1,SNOW:5)
Block(-1,44,2,SNOW:1)
Block(-1,45,0,SNOW:2)
Block(0,9,-1,PACKED_ICE:0)
Block(0,10,-1,PACKED_ICE:0)
Block(0,11,-2,PACKED_ICE:0)
Block(0,11,-1,PACKED_ICE:0)
Block(0,11,0,PACKED_ICE:0)
Block(0,12,-2,ICE:0)
Block(0,12,-1,PACKED_ICE:0)
Block(0,12,0,PACKED_ICE:0)
Block(0,12,1,ICE:0)
Block(0,13,-3,ICE:0)
Block(0,13,-2,ICE:0)
Block(0,13,-1,ICE:0)
Block(0,13,0,ICE:0)
Block(0,13,1,ICE:0)
Block(0,14,-3,ICE:0)
Block(0,14,-2,ICE:0)
Block(0,14,-1,PACKED_ICE:0)
Block(0,14,0,PACKED_ICE:0)
Block(0,14,1,ICE:0)
Block(0,14,2,ICE:0)
Block(0,15,-4,PACKED_ICE:0)
Block(0,15,-3,ICE:0)
Block(0,15,-2,ICE:0)
Block(0,15,-1,ICE:0)
Block(0,15,0,ICE:0)
Block(0,15,1,ICE:0)
Block(0,15,2,ICE:0)
Block(0,15,3,ICE:0)
Block(0,15,4,ICE:0)
Block(0,16,-4,ICE:0)
Block(0,16,-3,ICE:0)
Block(0,16,-2,ICE:0)
Block(0,16,-1,ICE:0)
Block(0,16,0,ICE:0)
Block(0,16,1,ICE:0)
Block(0,16,2,ICE:0)
Block(0,16,3,ICE:0)
Block(0,16,4,ICE:0)
Block(0,16,5,ICE:0)
Block(0,17,-5,ICE:0)
Block(0,17,-4,ICE:0)
Block(0,17,-3,ICE:0)
Block(0,17,-2,ICE:0)
Block(0,17,-1,ICE:0)
Block(0,17,0,ICE:0)
Block(0,17,1,ICE:0)
Block(0,17,2,PACKED_ICE:0)
Block(0,17,3,ICE:0)
Block(0,17,4,ICE:0)
Block(0,18,-6,ICE:0)
Block(0,18,-5,ICE:0)
Block(0,18,-4,ICE:0)
Block(0,18,-3,ICE:0)
Block(0,18,-2,ICE:0)
Block(0,18,-1,ICE:0)
Block(0,18,0,ICE:0)
Block(0,18,1,ICE:0)
Block(0,18,2,PACKED_ICE:0)
Block(0,18,3,ICE:0)
Block(0,19,-7,PACKED_ICE:0)
Block(0,19,-6,ICE:0)
Block(0,19,-5,ICE:0)
Block(0,19,-4,ICE:0)
Block(0,19,-3,ICE:0)
Block(0,19,-2,ICE:0)
Block(0,19,-1,ICE:0)
Block(0,19,0,ICE:0)
Block(0,19,1,ICE:0)
Block(0,19,2,PACKED_ICE:0)
Block(0,20,-7,PACKED_ICE:0)
Block(0,20,-6,ICE:0)
Block(0,20,-5,ICE:0)
Block(0,20,-4,ICE:0)
Block(0,20,-3,ICE:0)
Block(0,20,-2,SNOW_BLOCK:0)
Block(0,20,-1,SNOW_BLOCK:0)
Block(0,20,0,SNOW_BLOCK:0)
Block(0,20,1,SNOW_BLOCK:0)
Block(0,21,-7,PACKED_ICE:0)
Block(0,21,-6,ICE:0)
Block(0,21,-5,ICE:0)
Block(0,21,-4,ICE:0)
Block(0,21,-3,ICE:0)
Block(0,21,-2,SNOW:6)
Block(0,21,-1,SNOW:4)
Block(0,21,0,SNOW:3)
Block(0,21,1,SNOW:2)
Block(0,22,-7,SNOW:0)
Block(0,22,-6,ICE:0)
Block(0,22,-5,ICE:0)
Block(0,22,-4,ICE:0)
Block(0,22,-3,ICE:0)
Block(0,23,-6,SNOW:0)
Block(0,23,-5,ICE:0)
Block(0,23,-4,ICE:0)
Block(0,23,-3,ICE:0)
Block(0,24,-5,ICE:0)
Block(0,24,-4,ICE:0)
Block(0,24,-3,ICE:0)
Block(0,24,-2,ICE:0)
Block(0,24,-1,ICE:0)
Block(0,24,0,ICE:0)
Block(0,25,-5,ICE:0)
Block(0,25,-4,ICE:0)
Block(0,25,-3,ICE:0)
Block(0,25,-2,ICE:0)
Block(0,25,-1,ICE:0)
Block(0,25,0,ICE:0)
Block(0,26,-5,SNOW:0)
Block(0,26,-4,ICE:0)
Block(0,26,-3,ICE:0)
Block(0,26,-2,ICE:0)
Block(0,26,-1,ICE:0)
Block(0,27,-4,ICE:0)
Block(0,27,-3,ICE:0)
Block(0,27,-2,ICE:0)
Block(0,27,-1,ICE:0)
Block(0,28,-4,ICE:0)
Block(0,28,-3,ICE:0)
Block(0,28,-2,ICE:0)
Block(0,29,-4,ICE:0)
Block(0,29,-3,ICE:0)
Block(0,30,-4,ICE:0)
Block(0,30,-3,ICE:0)
Block(0,33,0,DARK_OAK_FENCE:0)
Block(0,34,0,PACKED_ICE:0)
Block(0,35,-1,PACKED_ICE:0)
Block(0,35,0,PACKED_ICE:0)
Block(0,35,1,ICE:0)
Block(0,36,-2,ICE:0)
Block(0,36,-1,DARK_OAK_FENCE:0)
Block(0,36,0,PACKED_ICE:0)
Block(0,36,1,PACKED_ICE:0)
Block(0,36,2,ICE:0)
Block(0,36,4,ICE:0)
Block(0,37,-5,PACKED_ICE:0)
Block(0,37,-2,ICE:0)
Block(0,37,-1,DARK_OAK_FENCE:0)
Block(0,37,0,DARK_OAK_FENCE:0)
Block(0,37,1,DARK_OAK_FENCE:0)
Block(0,37,2,ICE:0)
Block(0,37,4,ICE:0)
Block(0,38,-5,PACKED_ICE:0)
Block(0,38,-2,ICE:0)
Block(0,38,-1,ICE:0)
Block(0,38,0,DARK_OAK_FENCE:0)
Block(0,38,1,PACKED_ICE:0)
Block(0,38,4,ICE:0)
Block(0,39,-6,ICE:0)
Block(0,39,-5,PACKED_ICE:0)
Block(0,39,-3,ICE:0)
Block(0,39,-2,PACKED_ICE:0)
Block(0,39,-1,PACKED_ICE:0)
Block(0,39,0,DARK_OAK_FENCE:0)
Block(0,39,1,PACKED_ICE:0)
Block(0,39,2,PACKED_ICE:0)
Block(0,39,3,ICE:0)
Block(0,39,4,ICE:0)
Block(0,40,-6,ICE:0)
Block(0,40,-5,PACKED_ICE:0)
Block(0,40,-4,PACKED_ICE:0)
Block(0,40,-3,ICE:0)
Block(0,40,-2,ICE:0)
Block(0,40,-1,PACKED_ICE:0)
Block(0,40,1,PACKED_ICE:0)
Block(0,40,2,PACKED_ICE:0)
Block(0,40,3,WOOD:5)
Block(0,40,4,ICE:0)
Block(0,40,5,ICE:0)
Block(0,41,-6,SNOW:0)
Block(0,41,-5,PACKED_ICE:0)
Block(0,41,-4,PACKED_ICE:0)
Block(0,41,-3,ICE:0)
Block(0,41,-1,WOOD:5)
Block(0,41,0,REDSTONE_LAMP_OFF:0)
Block(0,41,1,PACKED_ICE:0)
Block(0,41,2,ICE:0)
Block(0,41,3,WOOD:5)
Block(0,41,4,WOOD:5)
Block(0,41,5,ICE:0)
Block(0,42,-5,SNOW:0)
Block(0,42,-4,ICE:0)
Block(0,42,-3,ICE:0)
Block(0,42,-2,WOOD_DOUBLE_STEP:5)
Block(0,42,-1,WOOD_DOUBLE_STEP:5)
Block(0,42,0,WOOD_DOUBLE_STEP:5)
Block(0,42,1,WOOD_DOUBLE_STEP:5)
Block(0,42,2,SNOW_BLOCK:0)
Block(0,42,3,SNOW_BLOCK:0)
Block(0,42,4,WOOD:5)
Block(0,42,5,SNOW:0)
Block(0,43,-3,SNOW_BLOCK:0)
Block(0,43,-2,ICE:0)
Block(0,43,-1,PACKED_ICE:0)
Block(0,43,0,SNOW_BLOCK:0)
Block(0,43,1,SNOW_BLOCK:0)
Block(0,43,2,SNOW_BLOCK:0)
Block(0,43,3,SNOW:6)
Block(0,43,4,SNOW:3)
Block(0,44,-3,SNOW:0)
Block(0,44,0,SNOW:3)
Block(0,44,1,SNOW:1)
Block(1,7,-1,PACKED_ICE:0)
Block(1,8,-1,PACKED_ICE:0)
Block(1,9,-2,PACKED_ICE:0)
Block(1,9,-1,PACKED_ICE:0)
Block(1,9,0,PACKED_ICE:0)
Block(1,10,-2,PACKED_ICE:0)
Block(1,10,-1,PACKED_ICE:0)
Block(1,10,0,PACKED_ICE:0)
Block(1,11,-2,PACKED_ICE:0)
Block(1,11,-1,PACKED_ICE:0)
Block(1,11,0,PACKED_ICE:0)
Block(1,12,-2,ICE:0)
Block(1,12,-1,PACKED_ICE:0)
Block(1,12,0,PACKED_ICE:0)
Block(1,13,-2,ICE:0)
Block(1,13,-1,ICE:0)
Block(1,13,0,PACKED_ICE:0)
Block(1,13,1,PACKED_ICE:0)
Block(1,14,-3,ICE:0)
Block(1,14,-2,ICE:0)
Block(1,14,-1,PACKED_ICE:0)
Block(1,14,0,PACKED_ICE:0)
Block(1,14,1,ICE:0)
Block(1,15,-4,ICE:0)
Block(1,15,-3,ICE:0)
Block(1,15,-2,ICE:0)
Block(1,15,-1,ICE:0)
Block(1,15,0,ICE:0)
Block(1,15,1,ICE:0)
Block(1,15,2,ICE:0)
Block(1,15,3,ICE:0)
Block(1,16,-4,ICE:0)
Block(1,16,-3,ICE:0)
Block(1,16,-2,ICE:0)
Block(1,16,-1,ICE:0)
Block(1,16,0,ICE:0)
Block(1,16,1,ICE:0)
Block(1,16,2,ICE:0)
Block(1,16,3,PACKED_ICE:0)
Block(1,17,-5,ICE:0)
Block(1,17,-4,ICE:0)
Block(1,17,-3,ICE:0)
Block(1,17,-2,ICE:0)
Block(1,17,-1,ICE:0)
Block(1,17,0,ICE:0)
Block(1,17,1,ICE:0)
Block(1,17,2,PACKED_ICE:0)
Block(1,17,3,PACKED_ICE:0)
Block(1,18,-6,ICE:0)
Block(1,18,-5,ICE:0)
Block(1,18,-4,ICE:0)
Block(1,18,-3,ICE:0)
Block(1,18,-2,ICE:0)
Block(1,18,-1,ICE:0)
Block(1,18,0,ICE:0)
Block(1,18,1,ICE:0)
Block(1,19,-7,PACKED_ICE:0)
Block(1,19,-6,ICE:0)
Block(1,19,-5,ICE:0)
Block(1,19,-4,ICE:0)
Block(1,19,-3,ICE:0)
Block(1,19,-2,ICE:0)
Block(1,19,-1,ICE:0)
Block(1,19,0,ICE:0)
Block(1,19,1,ICE:0)
Block(1,20,-7,ICE:0)
Block(1,20,-6,ICE:0)
Block(1,20,-5,ICE:0)
Block(1,20,-4,ICE:0)
Block(1,20,-3,ICE:0)
Block(1,20,-2,ICE:0)
Block(1,20,-1,SNOW_BLOCK:0)
Block(1,20,0,SNOW_BLOCK:0)
Block(1,20,1,SNOW_BLOCK:0)
Block(1,21,-7,ICE:0)
Block(1,21,-6,ICE:0)
Block(1,21,-5,ICE:0)
Block(1,21,-4,ICE:0)
Block(1,21,-3,ICE:0)
Block(1,21,-2,ICE:0)
Block(1,21,-1,SNOW:6)
Block(1,21,0,SNOW:4)
Block(1,21,1,SNOW:1)
Block(1,22,-7,ICE:0)
Block(1,22,-6,ICE:0)
Block(1,22,-5,ICE:0)
Block(1,22,-4,ICE:0)
Block(1,22,-3,ICE:0)
Block(1,23,-7,ICE:0)
Block(1,23,-6,ICE:0)
Block(1,23,-5,ICE:0)
Block(1,23,-4,ICE:0)
Block(1,23,-3,ICE:0)
Block(1,23,-2,ICE:0)
Block(1,24,-7,ICE:0)
Block(1,24,-6,ICE:0)
Block(1,24,-5,ICE:0)
Block(1,24,-4,ICE:0)
Block(1,24,-3,ICE:0)
Block(1,24,-2,ICE:0)
Block(1,24,-1,ICE:0)
Block(1,25,-7,SNOW:0)
Block(1,25,-6,ICE:0)
Block(1,25,-5,ICE:0)
Block(1,25,-4,ICE:0)
Block(1,25,-3,ICE:0)
Block(1,25,-2,ICE:0)
Block(1,25,-1,ICE:0)
Block(1,26,-6,ICE:0)
Block(1,26,-5,ICE:0)
Block(1,26,-4,ICE:0)
Block(1,26,-3,ICE:0)
Block(1,26,-2,ICE:0)
Block(1,26,-1,ICE:0)
Block(1,27,-6,ICE:0)
Block(1,27,-5,ICE:0)
Block(1,27,-4,ICE:0)
Block(1,27,-3,ICE:0)
Block(1,27,-2,ICE:0)
Block(1,27,-1,ICE:0)
Block(1,28,-6,ICE:0)
Block(1,28,-5,ICE:0)
Block(1,28,-4,ICE:0)
Block(1,28,-3,ICE:0)
Block(1,28,-2,ICE:0)
Block(1,28,-1,ICE:0)
Block(1,29,-6,SNOW:0)
Block(1,29,-5,ICE:0)
Block(1,29,-4,ICE:0)
Block(1,29,-3,ICE:0)
Block(1,29,-2,ICE:0)
Block(1,29,-1,ICE:0)
Block(1,30,-5,ICE:0)
Block(1,30,-4,ICE:0)
Block(1,30,-3,ICE:0)
Block(1,30,-2,ICE:0)
Block(1,30,-1,ICE:0)
Block(1,31,-5,ICE:0)
Block(1,31,-4,ICE:0)
Block(1,31,-3,ICE:0)
Block(1,31,-2,ICE:0)
Block(1,32,-5,SNOW:0)
Block(1,32,-4,ICE:0)
Block(1,32,-2,ICE:0)
Block(1,32,0,WOOD:5)
Block(1,33,-4,ICE:0)
Block(1,33,-2,ICE:0)
Block(1,33,0,LOG_2:1)
Block(1,34,-4,SNOW:0)
Block(1,34,-2,ICE:0)
Block(1,34,0,PACKED_ICE:0)
Block(1,34,1,PACKED_ICE:0)
Block(1,35,-2,ICE:0)
Block(1,35,-1,PACKED_ICE:0)
Block(1,35,0,LOG_2:1)
Block(1,35,1,ICE:0)
Block(1,36,-4,ICE:0)
Block(1,36,-2,ICE:0)
Block(1,36,-1,PACKED_ICE:0)
Block(1,36,0,LOG_2:1)
Block(1,36,1,ICE:0)
Block(1,37,-4,ICE:0)
Block(1,37,-2,ICE:0)
Block(1,37,-1,ICE:0)
Block(1,37,0,LOG_2:1)
Block(1,37,1,PACKED_ICE:0)
Block(1,38,-4,ICE:0)
Block(1,38,-1,PACKED_ICE:0)
Block(1,38,0,PACKED_ICE:0)
Block(1,38,1,PACKED_ICE:0)
Block(1,39,-5,ICE:0)
Block(1,39,-4,ICE:0)
Block(1,39,-1,PACKED_ICE:0)
Block(1,39,0,PACKED_ICE:0)
Block(1,39,1,PACKED_ICE:0)
Block(1,40,-5,SNOW:0)
Block(1,40,-4,ICE:0)
Block(1,40,0,PACKED_ICE:0)
Block(1,40,1,ICE:0)
Block(1,40,3,ICE:0)
Block(1,41,-4,ICE:0)
Block(1,41,-3,ICE:0)
Block(1,41,-2,WOOD:5)
Block(1,41,-1,WOOD:5)
Block(1,41,0,WOOD:5)
Block(1,41,1,ICE:0)
Block(1,41,2,ICE:0)
Block(1,41,3,WOOD:5)
Block(1,41,4,ICE:0)
Block(1,42,-3,SNOW_BLOCK:0)
Block(1,42,-2,WOOD_DOUBLE_STEP:5)
Block(1,42,-1,WOOD_DOUBLE_STEP:5)
Block(1,42,0,WOOD_DOUBLE_STEP:5)
Block(1,42,1,WOOD_DOUBLE_STEP:5)
Block(1,42,2,SNOW_BLOCK:0)
Block(1,42,3,WOOD_DOUBLE_STEP:5)
Block(1,42,4,WOOD:5)
Block(1,43,-3,SNOW:0)
Block(1,43,-2,SNOW:3)
Block(1,43,-1,SNOW:6)
Block(1,43,0,SNOW_BLOCK:0)
Block(1,43,1,SNOW_BLOCK:0)
Block(1,43,2,SNOW:6)
Block(1,43,3,SNOW:4)
Block(1,43,4,SNOW:2)
Block(1,44,0,SNOW:0)
Block(2,9,-1,PACKED_ICE:0)
Block(2,10,-1,PACKED_ICE:0)
Block(2,11,-1,PACKED_ICE:0)
Block(2,12,-1,ICE:0)
Block(2,12,0,PACKED_ICE:0)
Block(2,13,-2,ICE:0)
Block(2,13,-1,ICE:0)
Block(2,13,0,PACKED_ICE:0)
Block(2,14,-2,ICE:0)
Block(2,14,-1,ICE:0)
Block(2,14,0,PACKED_ICE:0)
Block(2,15,-3,ICE:0)
Block(2,15,-2,ICE:0)
Block(2,15,-1,ICE:0)
Block(2,15,0,ICE:0)
Block(2,15,1,ICE:0)
Block(2,15,2,ICE:0)
Block(2,16,-5,ICE:0)
Block(2,16,-4,ICE:0)
Block(2,16,-3,ICE:0)
Block(2,16,-2,ICE:0)
Block(2,16,-1,ICE:0)
Block(2,16,0,ICE:0)
Block(2,16,1,ICE:0)
Block(2,16,2,ICE:0)
Block(2,17,-6,ICE:0)
Block(2,17,-5,ICE:0)
Block(2,17,-4,ICE:0)
Block(2,17,-3,ICE:0)
Block(2,17,-2,ICE:0)
Block(2,17,-1,ICE:0)
Block(2,17,0,ICE:0)
Block(2,17,1,ICE:0)
Block(2,17,2,ICE:0)
Block(2,18,-7,PACKED_ICE:0)
Block(2,18,-6,ICE:0)
Block(2,18,-5,ICE:0)
Block(2,18,-4,ICE:0)
Block(2,18,-3,ICE:0)
Block(2,18,-2,ICE:0)
Block(2,18,-1,ICE:0)
Block(2,18,0,ICE:0)
Block(2,18,1,ICE:0)
Block(2,18,2,ICE:0)
Block(2,19,-7,ICE:0)
Block(2,19,-6,ICE:0)
Block(2,19,-5,ICE:0)
Block(2,19,-4,ICE:0)
Block(2,19,-3,ICE:0)
Block(2,19,-2,ICE:0)
Block(2,19,-1,ICE:0)
Block(2,19,0,ICE:0)
Block(2,19,1,ICE:0)
Block(2,20,-7,ICE:0)
Block(2,20,-6,ICE:0)
Block(2,20,-5,ICE:0)
Block(2,20,-4,ICE:0)
Block(2,20,-3,ICE:0)
Block(2,20,-2,ICE:0)
Block(2,20,-1,SNOW_BLOCK:0)
Block(2,20,0,SNOW_BLOCK:0)
Block(2,20,1,ICE:0)
Block(2,21,-7,ICE:0)
Block(2,21,-6,ICE:0)
Block(2,21,-5,ICE:0)
Block(2,21,-4,ICE:0)
Block(2,21,-3,ICE:0)
Block(2,21,-2,ICE:0)
Block(2,21,-1,SNOW:7)
Block(2,21,0,SNOW:7)
Block(2,22,-7,SNOW:0)
Block(2,22,-6,ICE:0)
Block(2,22,-5,ICE:0)
Block(2,22,-4,ICE:0)
Block(2,22,-3,ICE:0)
Block(2,22,-2,ICE:0)
Block(2,23,-6,ICE:0)
Block(2,23,-5,ICE:0)
Block(2,23,-4,ICE:0)
Block(2,23,-3,ICE:0)
Block(2,23,-2,ICE:0)
Block(2,24,-6,ICE:0)
Block(2,24,-5,ICE:0)
Block(2,24,-4,ICE:0)
Block(2,24,-3,ICE:0)
Block(2,24,-2,ICE:0)
Block(2,24,-1,ICE:0)
Block(2,24,0,ICE:0)
Block(2,25,-6,ICE:0)
Block(2,25,-5,ICE:0)
Block(2,25,-4,ICE:0)
Block(2,25,-3,ICE:0)
Block(2,25,-2,ICE:0)
Block(2,25,-1,ICE:0)
Block(2,26,-6,ICE:0)
Block(2,26,-5,ICE:0)
Block(2,26,-4,ICE:0)
Block(2,26,-3,ICE:0)
Block(2,26,-2,ICE:0)
Block(2,26,-1,ICE:0)
Block(2,27,-6,ICE:0)
Block(2,27,-5,ICE:0)
Block(2,27,-4,ICE:0)
Block(2,27,-3,ICE:0)
Block(2,27,-2,ICE:0)
Block(2,28,-6,SNOW:0)
Block(2,28,-5,ICE:0)
Block(2,28,-4,ICE:0)
Block(2,28,-3,ICE:0)
Block(2,28,-2,ICE:0)
Block(2,29,-5,ICE:0)
Block(2,29,-4,ICE:0)
Block(2,29,-3,ICE:0)
Block(2,29,-2,ICE:0)
Block(2,30,-5,ICE:0)
Block(2,30,-4,ICE:0)
Block(2,30,-3,ICE:0)
Block(2,30,-2,ICE:0)
Block(2,31,-5,SNOW:0)
Block(2,31,-4,ICE:0)
Block(2,31,-3,ICE:0)
Block(2,31,-2,ICE:0)
Block(2,32,-2,SNOW:0)
Block(2,32,0,WOOD:5)
Block(2,33,0,LOG_2:1)
Block(2,34,0,PACKED_ICE:0)
Block(2,35,-1,PACKED_ICE:0)
Block(2,35,0,PACKED_ICE:0)
Block(2,35,1,ICE:0)
Block(2,36,-2,PACKED_ICE:0)
Block(2,36,-1,PACKED_ICE:0)
Block(2,36,0,PACKED_ICE:0)
Block(2,36,1,ICE:0)
Block(2,37,-2,PACKED_ICE:0)
Block(2,37,-1,PACKED_ICE:0)
Block(2,37,0,LOG_2:1)
Block(2,37,1,PACKED_ICE:0)
Block(2,38,-2,ICE:0)
Block(2,38,-1,PACKED_ICE:0)
Block(2,38,0,LOG_2:1)
Block(2,38,1,ICE:0)
Block(2,39,-2,ICE:0)
Block(2,39,0,ICE:0)
Block(2,39,1,ICE:0)
Block(2,40,-4,ICE:0)
Block(2,40,-3,PACKED_ICE:0)
Block(2,40,-2,ICE:0)
Block(2,40,0,ICE:0)
Block(2,40,1,SNOW:0)
Block(2,41,-4,ICE:0)
Block(2,41,-3,ICE:0)
Block(2,41,-2,PACKED_ICE:0)
Block(2,41,-1,ICE:0)
Block(2,41,0,ICE:0)
Block(2,41,1,ICE:0)
Block(2,42,-2,PACKED_ICE:0)
Block(2,42,-1,PACKED_ICE:0)
Block(2,42,0,ICE:0)
Block(2,42,1,STAINED_CLAY:9)
Block(2,42,2,STAINED_CLAY:9)
Block(2,42,3,STAINED_CLAY:9)
Block(2,43,1,SNOW:6)
Block(2,43,2,SNOW:4)
Block(2,43,3,SNOW:1)
Block(3,11,-1,PACKED_ICE:0)
Block(3,12,-1,PACKED_ICE:0)
Block(3,13,-1,ICE:0)
Block(3,14,-3,PACKED_ICE:0)
Block(3,14,-2,ICE:0)
Block(3,14,-1,PACKED_ICE:0)
Block(3,14,0,PACKED_ICE:0)
Block(3,15,-5,ICE:0)
Block(3,15,-4,ICE:0)
Block(3,15,-3,ICE:0)
Block(3,15,-2,ICE:0)
Block(3,15,-1,ICE:0)
Block(3,15,0,ICE:0)
Block(3,15,1,ICE:0)
Block(3,16,-6,ICE:0)
Block(3,16,-5,ICE:0)
Block(3,16,-4,ICE:0)
Block(3,16,-3,ICE:0)
Block(3,16,-2,ICE:0)
Block(3,16,-1,ICE:0)
Block(3,16,0,ICE:0)
Block(3,16,1,ICE:0)
Block(3,16,2,ICE:0)
Block(3,17,-7,PACKED_ICE:0)
Block(3,17,-6,ICE:0)
Block(3,17,-5,ICE:0)
Block(3,17,-4,ICE:0)
Block(3,17,-3,ICE:0)
Block(3,17,-2,ICE:0)
Block(3,17,-1,ICE:0)
Block(3,17,0,ICE:0)
Block(3,17,1,ICE:0)
Block(3,17,2,ICE:0)
Block(3,18,-7,ICE:0)
Block(3,18,-6,ICE:0)
Block(3,18,-5,ICE:0)
Block(3,18,-4,ICE:0)
Block(3,18,-3,ICE:0)
Block(3,18,-2,ICE:0)
Block(3,18,-1,ICE:0)
Block(3,18,0,ICE:0)
Block(3,18,1,ICE:0)
Block(3,19,-7,ICE:0)
Block(3,19,-6,ICE:0)
Block(3,19,-5,ICE:0)
Block(3,19,-4,ICE:0)
Block(3,19,-3,ICE:0)
Block(3,19,-2,ICE:0)
Block(3,19,-1,ICE:0)
Block(3,19,0,ICE:0)
Block(3,19,1,ICE:0)
Block(3,20,-6,ICE:0)
Block(3,20,-5,ICE:0)
Block(3,20,-4,ICE:0)
Block(3,20,-3,ICE:0)
Block(3,20,-2,ICE:0)
Block(3,20,-1,ICE:0)
Block(3,20,0,ICE:0)
Block(3,20,1,ICE:0)
Block(3,21,-6,ICE:0)
Block(3,21,-5,ICE:0)
Block(3,21,-4,ICE:0)
Block(3,21,-3,ICE:0)
Block(3,21,-2,ICE:0)
Block(3,21,-1,ICE:0)
Block(3,22,-6,ICE:0)
Block(3,22,-5,ICE:0)
Block(3,22,-4,ICE:0)
Block(3,22,-3,ICE:0)
Block(3,22,-2,ICE:0)
Block(3,23,-6,ICE:0)
Block(3,23,-5,ICE:0)
Block(3,23,-4,ICE:0)
Block(3,23,-3,ICE:0)
Block(3,23,-2,ICE:0)
Block(3,23,-1,ICE:0)
Block(3,24,-6,ICE:0)
Block(3,24,-5,ICE:0)
Block(3,24,-4,ICE:0)
Block(3,24,-3,ICE:0)
Block(3,24,-2,ICE:0)
Block(3,24,-1,ICE:0)
Block(3,24,0,ICE:0)
Block(3,25,-6,ICE:0)
Block(3,25,-5,ICE:0)
Block(3,25,-4,ICE:0)
Block(3,25,-3,ICE:0)
Block(3,25,-2,ICE:0)
Block(3,25,-1,ICE:0)
Block(3,25,0,ICE:0)
Block(3,26,-6,SNOW:0)
Block(3,26,-5,ICE:0)
Block(3,26,-4,ICE:0)
Block(3,26,-3,ICE:0)
Block(3,26,-2,ICE:0)
Block(3,26,-1,ICE:0)
Block(3,27,-5,ICE:0)
Block(3,27,-4,ICE:0)
Block(3,27,-3,ICE:0)
Block(3,27,-2,ICE:0)
Block(3,27,-1,ICE:0)
Block(3,28,-5,ICE:0)
Block(3,28,-4,ICE:0)
Block(3,28,-3,ICE:0)
Block(3,28,-2,ICE:0)
Block(3,28,-1,ICE:0)
Block(3,29,-5,SNOW:0)
Block(3,29,-4,ICE:0)
Block(3,29,-3,SNOW:0)
Block(3,29,-2,ICE:0)
Block(3,29,-1,SNOW:0)
Block(3,30,-4,ICE:0)
Block(3,30,-2,ICE:0)
Block(3,30,0,PACKED_ICE:0)
Block(3,31,-4,ICE:0)
Block(3,31,-2,SNOW:0)
Block(3,31,0,PACKED_ICE:0)
Block(3,32,-4,ICE:0)
Block(3,32,0,PACKED_ICE:0)
Block(3,33,0,PACKED_ICE:0)
Block(3,34,0,PACKED_ICE:0)
Block(3,35,0,PACKED_ICE:0)
Block(3,36,-1,ICE:0)
Block(3,36,0,PACKED_ICE:0)
Block(3,36,1,PACKED_ICE:0)
Block(3,37,-1,ICE:0)
Block(3,37,0,PACKED_ICE:0)
Block(3,37,1,PACKED_ICE:0)
Block(3,38,-1,ICE:0)
Block(3,38,0,LOG_2:1)
Block(3,38,1,PACKED_ICE:0)
Block(3,39,-1,PACKED_ICE:0)
Block(3,39,0,LOG_2:1)
Block(3,40,-1,SNOW:0)
Block(3,40,0,ICE:0)
Block(3,41,0,SNOW:0)
Block(4,14,-2,PACKED_ICE:0)
Block(4,15,-4,ICE:0)
Block(4,15,-3,ICE:0)
Block(4,15,-2,ICE:0)
Block(4,15,-1,ICE:0)
Block(4,15,0,ICE:0)
Block(4,16,-6,PACKED_ICE:0)
Block(4,16,-5,ICE:0)
Block(4,16,-4,ICE:0)
Block(4,16,-3,ICE:0)
Block(4,16,-2,ICE:0)
Block(4,16,-1,ICE:0)
Block(4,16,0,ICE:0)
Block(4,16,1,PACKED_ICE:0)
Block(4,17,-6,PACKED_ICE:0)
Block(4,17,-5,ICE:0)
Block(4,17,-4,ICE:0)
Block(4,17,-3,ICE:0)
Block(4,17,-2,ICE:0)
Block(4,17,-1,ICE:0)
Block(4,17,0,ICE:0)
Block(4,17,1,ICE:0)
Block(4,17,2,ICE:0)
Block(4,18,-6,PACKED_ICE:0)
Block(4,18,-5,ICE:0)
Block(4,18,-4,ICE:0)
Block(4,18,-3,ICE:0)
Block(4,18,-2,ICE:0)
Block(4,18,-1,ICE:0)
Block(4,18,0,ICE:0)
Block(4,18,1,ICE:0)
Block(4,18,2,ICE:0)
Block(4,19,-6,PACKED_ICE:0)
Block(4,19,-5,ICE:0)
Block(4,19,-4,ICE:0)
Block(4,19,-3,ICE:0)
Block(4,19,-2,ICE:0)
Block(4,19,-1,ICE:0)
Block(4,19,0,ICE:0)
Block(4,19,1,ICE:0)
Block(4,20,-6,PACKED_ICE:0)
Block(4,20,-5,ICE:0)
Block(4,20,-4,ICE:0)
Block(4,20,-3,ICE:0)
Block(4,20,-2,ICE:0)
Block(4,20,-1,ICE:0)
Block(4,20,0,ICE:0)
Block(4,21,-5,ICE:0)
Block(4,21,-4,ICE:0)
Block(4,21,-3,ICE:0)
Block(4,21,-2,ICE:0)
Block(4,21,-1,ICE:0)
Block(4,22,-5,ICE:0)
Block(4,22,-4,ICE:0)
Block(4,22,-3,ICE:0)
Block(4,22,-2,ICE:0)
Block(4,22,-1,ICE:0)
Block(4,23,-5,SNOW:0)
Block(4,23,-4,ICE:0)
Block(4,23,-3,ICE:0)
Block(4,23,-2,ICE:0)
Block(4,23,-1,ICE:0)
Block(4,24,-4,ICE:0)
Block(4,24,-3,SNOW:0)
Block(4,24,-2,ICE:0)
Block(4,24,-1,ICE:0)
Block(4,25,-4,ICE:0)
Block(4,25,-2,ICE:0)
Block(4,26,-4,ICE:0)
Block(4,26,-2,ICE:0)
Block(4,27,-4,SNOW:0)
Block(4,27,-2,ICE:0)
Block(4,28,-2,SNOW:0)
Block(4,36,0,PACKED_ICE:0)
Block(4,37,0,PACKED_ICE:0)
Block(4,38,0,PACKED_ICE:0)
Block(4,38,1,PACKED_ICE:0)
Block(4,39,0,WOOD:5)
Block(4,40,0,SNOW:2)
Block(5,15,-3,ICE:0)
Block(5,16,-5,PACKED_ICE:0)
Block(5,16,-4,ICE:0)
Block(5,16,-3,ICE:0)
Block(5,16,-2,ICE:0)
Block(5,16,-1,ICE:0)
Block(5,16,0,PACKED_ICE:0)
Block(5,17,-6,PACKED_ICE:0)
Block(5,17,-5,PACKED_ICE:0)
Block(5,17,-4,ICE:0)
Block(5,17,-3,ICE:0)
Block(5,17,-2,ICE:0)
Block(5,17,-1,PACKED_ICE:0)
Block(5,17,0,PACKED_ICE:0)
Block(5,18,-6,PACKED_ICE:0)
Block(5,18,-5,PACKED_ICE:0)
Block(5,18,-4,ICE:0)
Block(5,18,-3,ICE:0)
Block(5,18,-2,ICE:0)
Block(5,18,-1,PACKED_ICE:0)
Block(5,19,-5,PACKED_ICE:0)
Block(5,19,-3,ICE:0)
Block(5,19,-2,ICE:0)
Block(5,19,-1,PACKED_ICE:0)
Block(5,20,-5,PACKED_ICE:0)
Block(5,20,-3,ICE:0)
Block(5,20,-2,ICE:0)
Block(5,21,-5,PACKED_ICE:0)
Block(5,21,-2,ICE:0)
Block(6,16,-3,ICE:0)
Block(6,16,-2,ICE:0)
Block(6,16,-1,ICE:0)
Block(6,17,-3,ICE:0)
Block(6,17,-2,ICE:0)
Block(6,17,-1,ICE:0)
Block(6,18,-2,ICE:0)

#######################################################################
# +-----------------------------------------------------------------+ #
# |                             Branches                            | #
# +-----------------------------------------------------------------+ #
#######################################################################


#######################################################################
# +-----------------------------------------------------------------+ #
# |                             Entities                            | #
# +-----------------------------------------------------------------+ #
#######################################################################


#######################################################################
# +-----------------------------------------------------------------+ #
# |                            Particles                            | #
# +-----------------------------------------------------------------+ #
#######################################################################


#######################################################################
# +-----------------------------------------------------------------+ #
# |                             Spawners                            | #
# +-----------------------------------------------------------------+ #
#######################################################################


#######################################################################
# +-----------------------------------------------------------------+ #
# |                             ModData                             | #
# +-----------------------------------------------------------------+ #
#######################################################################

