Author: NLBlackEagle
Description: No description given
SettingsMode: WriteDisable
Frequency: 10
SpawnHeight: highestBlock
UseCenterForHighestBlock: true
MinHeight: 63
MaxHeight: 255
InheritBO3: 
InheritBO3Rotation: NORTH
OverrideChildSettings: true
OverrideParentHeight: false
CanOverride: true
BranchFrequency: 5
BranchFrequencyGroup: 
MustBeBelowOther: false
MustBeInside: 
CannotBeInside: 
ReplacesBO3: 
MustBeInsideWorldBorders: false
CanSpawnOnWater: false
SpawnOnWaterOnly: false
SpawnUnderWater: false
SpawnAtWaterLevel: false
HeightOffset: 0
RemoveAir: false
ReplaceAbove: 
ReplaceBelow: cobblestone
ReplaceWithBiomeBlocks: true
ReplaceWithSurfaceBlock: GRASS
ReplaceWithGroundBlock: DIRT
ReplaceWithStoneBlock: STONE
SmoothRadius: 0
SmoothHeightOffset: 0
SmoothStartTop: false
SmoothStartWood: false
SmoothingSurfaceBlock: 
SmoothingGroundBlock: 
BO3Group: 
IsSpawnPoint: false
DoReplaceBlocks: true
Block(-4,0,-3,LOG:1)
Block(-4,0,2,LOG:1)
Block(-4,1,-3,LOG:1)
Block(-4,1,-2,WOOD:1)
Block(-4,1,-1,WOOD:1)
Block(-4,1,0,WOOD:1)
Block(-4,1,1,WOOD:1)
Block(-4,1,2,LOG:1)
Block(-4,2,-3,LOG:1)
Block(-4,2,2,LOG:1)
Block(-4,3,-3,WOOD_DOUBLE_STEP:1)
Block(-4,3,-2,WOOD_DOUBLE_STEP:1)
Block(-4,3,-1,WOOD_DOUBLE_STEP:1)
Block(-4,3,0,WOOD_DOUBLE_STEP:1)
Block(-4,3,1,WOOD_DOUBLE_STEP:1)
Block(-4,3,2,WOOD_DOUBLE_STEP:1)
Block(-3,1,-3,WOOD:1)
Block(-3,1,-1,WALL_SIGN:4)
Block(-3,1,1,WORKBENCH:0)
Block(-3,1,2,WOOD:1)
Block(-2,1,-3,WOOD:1)
Block(-2,1,-1,DARK_OAK_STAIRS:2)
Block(-2,1,0,TRAP_DOOR:5)
Block(-2,1,1,SPRUCE_DOOR:3)
Block(-2,2,-2,IRON_PLATE:0)
RandomBlock(-2,2,-1,WALL_BANNER:5,../../NBT/Banners/viking_wealthy_1.nbt,20,WALL_BANNER:5,../../NBT/Banners/viking_wealthy_2.nbt,20,WALL_BANNER:5,../../NBT/Banners/viking_wealthy_3.nbt,20,WALL_BANNER:5,../../NBT/Banners/viking_wealthy_4.nbt,20,WALL_BANNER:5,../../NBT/Banners/viking_wealthy_5.nbt,20,WALL_BANNER:5,../../NBT/Banners/viking_wealthy_6.nbt,20,WALL_BANNER:5,../../NBT/Banners/viking_wealthy_7.nbt,20,WALL_BANNER:5,../../NBT/Banners/viking_wealthy_8.nbt,20,WALL_BANNER:5,../../NBT/Banners/viking_wealthy_9.nbt,100)
Block(-2,2,0,TRAP_DOOR:5)
Block(-2,2,1,SPRUCE_DOOR:8)
Block(-2,2,2,TRAP_DOOR:9)
Block(-2,3,-3,DARK_OAK_FENCE:0)
Block(-2,3,2,DARK_OAK_FENCE:0)
Block(-2,4,-5,WOOD_BUTTON:4)
Block(-2,4,-4,LOG:9)
Block(-2,4,-3,LOG:9)
Block(-2,4,-2,LOG:9)
Block(-2,4,-1,LOG:9)
Block(-2,4,0,LOG:9)
Block(-2,4,1,LOG:9)
Block(-2,4,2,LOG:9)
Block(-2,4,3,LOG:9)
Block(-2,4,4,WOOD_BUTTON:3)
Block(-1,1,-3,WOOD:1)
Block(-1,1,-1,WALL_SIGN:5)
Block(-1,1,2,WOOD:1)
RandomBlock(-1,2,1,AIR:0,20,CHEST:2,../../../../Chests/Loot/JunkChest_1.nbt,10,CHEST:2,../../../../Chests/Loot/JunkChest_2.nbt,10,CHEST:2,../../../../Chests/Loot/JunkChest_3.nbt,10,CHEST:2,../../../../Chests/Loot/JunkChest_4.nbt,10,CHEST:2,../../../../Chests/Loot/JunkChest_5.nbt,10,CHEST:2,../../../../Chests/Lore/Viking_1.nbt,1,CHEST:2,../../../../Chests/Lore/Viking_2.nbt,1,CHEST:2,../../../../Chests/Lore/Viking_3.nbt,1,CHEST:2,../../../../Chests/Lore/Viking_4.nbt,1,CHEST:2,../../../../Chests/Lore/Viking_5.nbt,1,CHEST:2,../../../../Chests/Loot/Common1.nbt,10,CHEST:2,../../../../Chests/Loot/Common2.nbt,10,CHEST:2,../../../../Chests/Loot/Common3.nbt,10,CHEST:2,../../../../Chests/Loot/Common4.nbt,10,CHEST:2,../../../../Chests/Loot/Common5.nbt,10,CHEST:2,../../../../Chests/Loot/Common6.nbt,10,CHEST:2,../../../../Chests/Loot/Common7.nbt,10,CHEST:2,../../../../Chests/Loot/Common8.nbt,10,CHEST:2,../../../../Chests/Loot/Common9.nbt,10,CHEST:2,../../../../Chests/Loot/Common10.nbt,10,CHEST:2,../../../../Chests/Loot/Common10.nbt,11,CHEST:2,../../../../Chests/Loot/Common12.nbt,10,CHEST:2,../../../../Chests/Loot/Common13.nbt,10,CHEST:2,../../../../Chests/Loot/Common14.nbt,10,CHEST:2,../../../../Chests/Loot/Common15.nbt,10,CHEST:2,../../../../Chests/Lore/Viking_1.nbt,2,CHEST:2,../../../../Chests/Lore/Viking_3.nbt,2,CHEST:2,../../../../Chests/Lore/Viking_4.nbt,2,CHEST:2,../../../../Chests/Lore/Viking_5.nbt,2,CHEST:2,../../../../Chests/Lore/Viking_5.nbt,2,CHEST:2,../../../../Chests/Loot/Rare1.nbt,5,CHEST:2,../../../../Chests/Loot/Rare2.nbt,5,CHEST:2,../../../../Chests/Loot/Rare3.nbt,5,CHEST:2,../../../../Chests/Loot/Rare4.nbt,5,CHEST:2,../../../../Chests/Loot/Rare5.nbt,5,CHEST:2,../../../../Chests/Loot/Rare6.nbt,5,CHEST:2,../../../../Chests/Loot/Rare7.nbt,5,CHEST:2,../../../../Chests/Loot/Rare8.nbt,5,CHEST:2,../../../../Chests/Loot/Rare9.nbt,5,CHEST:2,../../../../Chests/Loot/Rare10.nbt,5,CHEST:2,../../../../Chests/Loot/Rare11.nbt,5,CHEST:2,../../../../Chests/Loot/Rare12.nbt,5,CHEST:2,../../../../Chests/Loot/Rare13.nbt,5,CHEST:2,../../../../Chests/Loot/Rare14.nbt,5,CHEST:2,../../../../Chests/Loot/Rare15.nbt,5,CHEST:2,../../../../Chests/Loot/Epic1.nbt,2,CHEST:2,../../../../Chests/Loot/Epic2.nbt,2,CHEST:2,../../../../Chests/Loot/Epic3.nbt,2,CHEST:2,../../../../Chests/Loot/Epic4.nbt,2,CHEST:2,../../../../Chests/Loot/Epic5.nbt,2,CHEST:2,../../../../Chests/Loot/Epic6.nbt,2,CHEST:2,../../../../Chests/Loot/Epic7.nbt,2,CHEST:2,../../../../Chests/Loot/Epic8.nbt,2,CHEST:2,../../../../Chests/Loot/Epic9.nbt,2,CHEST:2,../../../../Chests/Loot/Epic10.nbt,2,CHEST:2,../../../../Chests/Loot/Epic11.nbt,2,CHEST:2,../../../../Chests/Loot/Epic12.nbt,2,CHEST:2,../../../../Chests/Loot/Epic13.nbt,2,CHEST:2,../../../../Chests/Loot/Epic14.nbt,2,CHEST:2,../../../../Chests/Loot/Epic15.nbt,5,CHEST:2,../../../../Chests/Loot/Rare1.nbt,5,CHEST:2,../../../../Chests/Loot/Rare2.nbt,5,CHEST:2,../../../../Chests/Loot/Rare3.nbt,5,CHEST:2,../../../../Chests/Loot/Rare4.nbt,5,CHEST:2,../../../../Chests/Loot/Rare5.nbt,10,CHEST:2,../../../../Chests/Loot/Rare6.nbt,10,CHEST:2,../../../../Chests/Loot/Rare7.nbt,10,CHEST:2,../../../../Chests/Loot/Rare8.nbt,10,CHEST:2,../../../../Chests/Loot/Rare9.nbt,10,CHEST:2,../../../../Chests/Loot/Rare10.nbt,15,CHEST:2,../../../../Chests/Loot/Rare11.nbt,15,CHEST:2,../../../../Chests/Loot/Rare12.nbt,15,CHEST:2,../../../../Chests/Loot/Rare13.nbt,15,CHEST:2,../../../../Chests/Loot/Rare14.nbt,15,CHEST:2,../../../../Chests/Loot/Rare15.nbt,15,CHEST:2,../../../../Chests/Loot/Epic15.nbt,100)
Block(0,1,-3,WOOD:1)
Block(0,1,-2,STONE:6)
Block(0,1,-1,AIR:0)
Block(0,1,2,WOOD:1)
Block(0,2,-2,TRIPWIRE_HOOK:0)
RandomBlock(0,2,1,AIR:0,20,CHEST:2,../../../../Chests/Loot/JunkChest_1.nbt,10,CHEST:2,../../../../Chests/Loot/JunkChest_2.nbt,10,CHEST:2,../../../../Chests/Loot/JunkChest_3.nbt,10,CHEST:2,../../../../Chests/Loot/JunkChest_4.nbt,10,CHEST:2,../../../../Chests/Loot/JunkChest_5.nbt,10,CHEST:2,../../../../Chests/Lore/Viking_1.nbt,1,CHEST:2,../../../../Chests/Lore/Viking_2.nbt,1,CHEST:2,../../../../Chests/Lore/Viking_3.nbt,1,CHEST:2,../../../../Chests/Lore/Viking_4.nbt,1,CHEST:2,../../../../Chests/Lore/Viking_5.nbt,1,CHEST:2,../../../../Chests/Loot/Common1.nbt,10,CHEST:2,../../../../Chests/Loot/Common2.nbt,10,CHEST:2,../../../../Chests/Loot/Common3.nbt,10,CHEST:2,../../../../Chests/Loot/Common4.nbt,10,CHEST:2,../../../../Chests/Loot/Common5.nbt,10,CHEST:2,../../../../Chests/Loot/Common6.nbt,10,CHEST:2,../../../../Chests/Loot/Common7.nbt,10,CHEST:2,../../../../Chests/Loot/Common8.nbt,10,CHEST:2,../../../../Chests/Loot/Common9.nbt,10,CHEST:2,../../../../Chests/Loot/Common10.nbt,10,CHEST:2,../../../../Chests/Loot/Common10.nbt,11,CHEST:2,../../../../Chests/Loot/Common12.nbt,10,CHEST:2,../../../../Chests/Loot/Common13.nbt,10,CHEST:2,../../../../Chests/Loot/Common14.nbt,10,CHEST:2,../../../../Chests/Loot/Common15.nbt,10,CHEST:2,../../../../Chests/Lore/Viking_1.nbt,2,CHEST:2,../../../../Chests/Lore/Viking_3.nbt,2,CHEST:2,../../../../Chests/Lore/Viking_4.nbt,2,CHEST:2,../../../../Chests/Lore/Viking_5.nbt,2,CHEST:2,../../../../Chests/Lore/Viking_5.nbt,2,CHEST:2,../../../../Chests/Loot/Rare1.nbt,5,CHEST:2,../../../../Chests/Loot/Rare2.nbt,5,CHEST:2,../../../../Chests/Loot/Rare3.nbt,5,CHEST:2,../../../../Chests/Loot/Rare4.nbt,5,CHEST:2,../../../../Chests/Loot/Rare5.nbt,5,CHEST:2,../../../../Chests/Loot/Rare6.nbt,5,CHEST:2,../../../../Chests/Loot/Rare7.nbt,5,CHEST:2,../../../../Chests/Loot/Rare8.nbt,5,CHEST:2,../../../../Chests/Loot/Rare9.nbt,5,CHEST:2,../../../../Chests/Loot/Rare10.nbt,5,CHEST:2,../../../../Chests/Loot/Rare11.nbt,5,CHEST:2,../../../../Chests/Loot/Rare12.nbt,5,CHEST:2,../../../../Chests/Loot/Rare13.nbt,5,CHEST:2,../../../../Chests/Loot/Rare14.nbt,5,CHEST:2,../../../../Chests/Loot/Rare15.nbt,5,CHEST:2,../../../../Chests/Loot/Epic1.nbt,2,CHEST:2,../../../../Chests/Loot/Epic2.nbt,2,CHEST:2,../../../../Chests/Loot/Epic3.nbt,2,CHEST:2,../../../../Chests/Loot/Epic4.nbt,2,CHEST:2,../../../../Chests/Loot/Epic5.nbt,2,CHEST:2,../../../../Chests/Loot/Epic6.nbt,2,CHEST:2,../../../../Chests/Loot/Epic7.nbt,2,CHEST:2,../../../../Chests/Loot/Epic8.nbt,2,CHEST:2,../../../../Chests/Loot/Epic9.nbt,2,CHEST:2,../../../../Chests/Loot/Epic10.nbt,2,CHEST:2,../../../../Chests/Loot/Epic11.nbt,2,CHEST:2,../../../../Chests/Loot/Epic12.nbt,2,CHEST:2,../../../../Chests/Loot/Epic13.nbt,2,CHEST:2,../../../../Chests/Loot/Epic14.nbt,2,CHEST:2,../../../../Chests/Loot/Epic15.nbt,5,CHEST:2,../../../../Chests/Loot/Rare1.nbt,5,CHEST:2,../../../../Chests/Loot/Rare2.nbt,5,CHEST:2,../../../../Chests/Loot/Rare3.nbt,5,CHEST:2,../../../../Chests/Loot/Rare4.nbt,5,CHEST:2,../../../../Chests/Loot/Rare5.nbt,10,CHEST:2,../../../../Chests/Loot/Rare6.nbt,10,CHEST:2,../../../../Chests/Loot/Rare7.nbt,10,CHEST:2,../../../../Chests/Loot/Rare8.nbt,10,CHEST:2,../../../../Chests/Loot/Rare9.nbt,10,CHEST:2,../../../../Chests/Loot/Rare10.nbt,15,CHEST:2,../../../../Chests/Loot/Rare11.nbt,15,CHEST:2,../../../../Chests/Loot/Rare12.nbt,15,CHEST:2,../../../../Chests/Loot/Rare13.nbt,15,CHEST:2,../../../../Chests/Loot/Rare14.nbt,15,CHEST:2,../../../../Chests/Loot/Rare15.nbt,15,CHEST:2,../../../../Chests/Loot/Epic15.nbt,100)
Block(0,3,-3,WOOD_DOUBLE_STEP:1)
Block(0,3,2,WOOD_DOUBLE_STEP:1)
Block(1,0,-3,LOG:1)
Block(1,0,2,LOG:1)
Block(1,1,-3,LOG:1)
Block(1,1,-2,WOOD:1)
Block(1,1,-1,WOOD:1)
Block(1,1,0,WOOD:1)
Block(1,1,1,WOOD:1)
Block(1,1,2,LOG:1)
Block(1,2,-3,LOG:1)
Block(1,2,2,LOG:1)



Block(-4,0,-2,COBBLESTONE:0)
Block(-4,0,-1,COBBLESTONE:0)
Block(-4,0,0,COBBLESTONE:0)
Block(-4,0,1,COBBLESTONE:0)
Block(-4,2,-2,SPRUCE_WOOD_STAIRS:4)
Block(-4,2,-1,SPRUCE_WOOD_STAIRS:7)
Block(-4,2,0,SPRUCE_WOOD_STAIRS:6)
Block(-4,2,1,SPRUCE_WOOD_STAIRS:4)
Block(-3,0,-3,COBBLESTONE:0)
Block(-3,0,-2,COBBLESTONE:0)
Block(-3,0,-1,COBBLESTONE:0)
Block(-3,0,0,COBBLESTONE:0)
Block(-3,0,1,COBBLESTONE:0)
Block(-3,0,2,COBBLESTONE:0)
Block(-3,2,-3,SPRUCE_WOOD_STAIRS:6)
Block(-3,2,2,SPRUCE_WOOD_STAIRS:7)
Block(-2,0,-3,COBBLESTONE:0)
Block(-2,0,-2,COBBLESTONE:0)
Block(-2,0,-1,COBBLESTONE:0)
Block(-2,0,0,COBBLESTONE:0)
Block(-2,0,1,COBBLESTONE:0)
Block(-2,0,2,COBBLESTONE:0)
Block(-2,2,-3,SPRUCE_WOOD_STAIRS:6)
Block(-1,0,-3,COBBLESTONE:0)
Block(-1,0,-2,COBBLESTONE:0)
Block(-1,0,-1,COBBLESTONE:0)
Block(-1,0,0,COBBLESTONE:0)
Block(-1,0,1,COBBLESTONE:0)
Block(-1,0,2,COBBLESTONE:0)
Block(-1,1,-2,SPRUCE_WOOD_STAIRS:4)
Block(-1,1,1,SPRUCE_WOOD_STAIRS:5)
Block(-1,2,-3,SPRUCE_WOOD_STAIRS:6)
Block(-1,2,2,SPRUCE_WOOD_STAIRS:7)
Block(0,0,-3,COBBLESTONE:0)
Block(0,0,-2,COBBLESTONE:0)
Block(0,0,-1,COBBLESTONE:0)
Block(0,0,0,COBBLESTONE:0)
Block(0,0,1,COBBLESTONE:0)
Block(0,0,2,COBBLESTONE:0)
Block(0,2,-3,SPRUCE_WOOD_STAIRS:6)
Block(0,2,2,SPRUCE_WOOD_STAIRS:7)
Block(1,0,-2,COBBLESTONE:0)
Block(1,0,-1,COBBLESTONE:0)
Block(1,0,0,COBBLESTONE:0)
Block(1,0,1,COBBLESTONE:0)
Block(1,2,-2,SPRUCE_WOOD_STAIRS:7)
Block(1,2,-1,SPRUCE_WOOD_STAIRS:6)
Block(1,2,0,SPRUCE_WOOD_STAIRS:5)
Block(1,2,1,SPRUCE_WOOD_STAIRS:5)

Block(-5,3,-3,WOOD_STEP:1)
Block(-5,3,-2,WOOD_STEP:1)
Block(-5,3,-1,WOOD_STEP:1)
Block(-5,3,0,WOOD_STEP:1)
Block(-5,3,1,WOOD_STEP:1)
Block(-5,3,2,WOOD_STEP:1)
Block(-3,1,-2,WOOD_STEP:9)
Block(-3,3,-3,WOOD_STEP:9)
Block(-3,3,2,WOOD_STEP:9)
Block(-3,4,-3,WOOD_STEP:1)
Block(-3,4,-2,WOOD_STEP:1)
Block(-3,4,-1,WOOD_STEP:1)
Block(-3,4,0,WOOD_STEP:1)
Block(-3,4,1,WOOD_STEP:1)
Block(-3,4,2,WOOD_STEP:1)
Block(-2,1,-2,WOOD_STEP:9)
Block(-1,3,-3,WOOD_STEP:9)
Block(-1,3,2,WOOD_STEP:9)
Block(-1,4,-3,WOOD_STEP:1)
Block(-1,4,-2,WOOD_STEP:1)
Block(-1,4,-1,WOOD_STEP:1)
Block(-1,4,0,WOOD_STEP:1)
Block(-1,4,1,WOOD_STEP:1)
Block(-1,4,2,WOOD_STEP:1)
Block(0,1,1,WOOD_STEP:9)
Block(0,3,-2,WOOD_STEP:9)
Block(0,3,-1,WOOD_STEP:9)
Block(0,3,0,WOOD_STEP:9)
Block(0,3,1,WOOD_STEP:9)
Block(1,3,-3,WOOD_STEP:1)
Block(1,3,-2,WOOD_STEP:1)
Block(1,3,-1,WOOD_STEP:1)
Block(1,3,0,WOOD_STEP:1)
Block(1,3,1,WOOD_STEP:1)
Block(1,3,2,WOOD_STEP:1)
Block(2,2,-3,WOOD_STEP:9)
Block(2,2,-2,WOOD_STEP:9)
Block(2,2,-1,WOOD_STEP:9)
Block(2,2,0,WOOD_STEP:9)
Block(2,2,1,WOOD_STEP:9)
Block(2,2,2,WOOD_STEP:9)

Entity(0,1,-1,minecraft:villager,1,../../NBT/Entities/VikingVillage/villager_librarian.txt)