Author: NLBlackEagle
Description: No description given
SettingsMode: WriteDisable
Frequency: 10
SpawnHeight: highestBlock
UseCenterForHighestBlock: true
MinHeight: 63
MaxHeight: 255
InheritBO3: 
InheritBO3Rotation: NORTH
OverrideChildSettings: true
OverrideParentHeight: false
CanOverride: true
BranchFrequency: 5
BranchFrequencyGroup: 
MustBeBelowOther: false
MustBeInside: 
CannotBeInside: 
ReplacesBO3: 
MustBeInsideWorldBorders: false
CanSpawnOnWater: false
SpawnOnWaterOnly: false
SpawnUnderWater: false
SpawnAtWaterLevel: false
HeightOffset: -2
RemoveAir: false
ReplaceAbove: 
ReplaceBelow: cobblestone
ReplaceWithBiomeBlocks: true
ReplaceWithSurfaceBlock: GRASS
ReplaceWithGroundBlock: DIRT
ReplaceWithStoneBlock: STONE
SmoothRadius: 0
SmoothHeightOffset: 0
SmoothStartTop: false
SmoothStartWood: false
SmoothingSurfaceBlock: 
SmoothingGroundBlock: 
BO3Group: Viking_Tower:15
IsSpawnPoint: false
DoReplaceBlocks: true
Block(-3,5,-2,WALL_SIGN:4)
Block(-3,5,-1,WALL_SIGN:4)
Block(-3,5,0,WALL_SIGN:4)
Block(-3,5,1,WALL_SIGN:4)
Block(-3,5,2,WALL_SIGN:4)
Block(-3,5,3,WALL_SIGN:4)
Block(-3,9,-2,WALL_SIGN:4)
Block(-3,9,-1,WALL_SIGN:4)
Block(-3,9,0,WALL_SIGN:4)
Block(-3,9,1,WALL_SIGN:4)
Block(-3,9,2,WALL_SIGN:4)
Block(-3,9,3,WALL_SIGN:4)
Block(-2,0,-2,LOG:1)
Block(-2,0,3,LOG:1)
Block(-2,1,-2,LOG:1)
Block(-2,1,3,LOG:1)
Block(-2,2,-2,LOG:1)
Block(-2,2,-1,SMOOTH_BRICK:0)
Block(-2,2,1,SMOOTH_BRICK:0)
Block(-2,2,2,SMOOTH_BRICK:0)
Block(-2,2,3,LOG:1)
Block(-2,3,-2,LOG:1)
Block(-2,3,-1,SMOOTH_BRICK:0)
Block(-2,3,1,SMOOTH_BRICK:0)
Block(-2,3,3,LOG:1)
Block(-2,4,-2,LOG:1)
Block(-2,4,1,SMOOTH_BRICK:0)
Block(-2,4,3,LOG:1)
Block(-2,5,-3,WALL_SIGN:2)
Block(-2,5,-2,LOG:1)
Block(-2,5,-1,WOOD:5)
Block(-2,5,0,WOOD:5)
Block(-2,5,1,WOOD:5)
Block(-2,5,2,WOOD:1)
Block(-2,5,3,LOG:1)
Block(-2,5,4,WALL_SIGN:3)
Block(-2,6,-3,WOOD_BUTTON:4)
Block(-2,6,-2,LOG:1)
Block(-2,6,-1,WOOD:5)
Block(-2,6,0,WOOD:1)
Block(-2,6,2,WOOD:1)
Block(-2,6,3,LOG:1)
Block(-2,6,4,WOOD_BUTTON:3)
Block(-2,7,-2,LOG:1)
Block(-2,7,-1,WOOD:5)
Block(-2,7,0,WOOD:1)
Block(-2,7,2,WOOD:5)
Block(-2,7,3,LOG:1)
Block(-2,8,-3,WOOD_BUTTON:4)
Block(-2,8,-2,LOG:1)
Block(-2,8,-1,WOOD:5)
Block(-2,8,0,WOOD:5)
Block(-2,8,1,WOOD:1)
Block(-2,8,2,WOOD:5)
Block(-2,8,3,LOG:1)
Block(-2,8,4,WOOD_BUTTON:3)
Block(-2,9,-3,WALL_SIGN:2)
Block(-2,9,-2,LOG:1)
Block(-2,9,-1,WOOD:1)
Block(-2,9,0,WOOD:5)
Block(-2,9,1,WOOD:1)
Block(-2,9,2,WOOD:5)
Block(-2,9,3,LOG:1)
Block(-2,9,4,WALL_SIGN:3)
Block(-2,10,-2,WOOD:1)
Block(-2,10,0,WOOD:1)
Block(-2,10,1,WOOD:1)
Block(-2,10,3,WOOD:1)
Block(-1,2,1,TRAP_DOOR:11)
Block(-1,2,2,TRAP_DOOR:11)
Block(-1,2,3,SMOOTH_BRICK:0)
RandomBlock(-1,3,1,AIR:0,20,CHEST:5,../../../../Chests/Loot/JunkChest_1.nbt,10,CHEST:5,../../../../Chests/Loot/JunkChest_2.nbt,10,CHEST:5,../../../../Chests/Loot/JunkChest_3.nbt,10,CHEST:5,../../../../Chests/Loot/JunkChest_4.nbt,10,CHEST:5,../../../../Chests/Loot/JunkChest_5.nbt,10,CHEST:5,../../../../Chests/Lore/Viking_1.nbt,1,CHEST:5,../../../../Chests/Lore/Viking_2.nbt,1,CHEST:5,../../../../Chests/Lore/Viking_3.nbt,1,CHEST:5,../../../../Chests/Lore/Viking_4.nbt,1,CHEST:5,../../../../Chests/Lore/Viking_5.nbt,1,CHEST:5,../../../../Chests/Loot/Common1.nbt,10,CHEST:5,../../../../Chests/Loot/Common2.nbt,10,CHEST:5,../../../../Chests/Loot/Common3.nbt,10,CHEST:5,../../../../Chests/Loot/Common4.nbt,10,CHEST:5,../../../../Chests/Loot/Common5.nbt,10,CHEST:5,../../../../Chests/Loot/Common6.nbt,10,CHEST:5,../../../../Chests/Loot/Common7.nbt,10,CHEST:5,../../../../Chests/Loot/Common8.nbt,10,CHEST:5,../../../../Chests/Loot/Common9.nbt,10,CHEST:5,../../../../Chests/Loot/Common10.nbt,10,CHEST:5,../../../../Chests/Loot/Common10.nbt,11,CHEST:5,../../../../Chests/Loot/Common12.nbt,10,CHEST:5,../../../../Chests/Loot/Common13.nbt,10,CHEST:5,../../../../Chests/Loot/Common14.nbt,10,CHEST:5,../../../../Chests/Loot/Common15.nbt,10,CHEST:5,../../../../Chests/Lore/Viking_1.nbt,2,CHEST:5,../../../../Chests/Lore/Viking_3.nbt,2,CHEST:5,../../../../Chests/Lore/Viking_4.nbt,2,CHEST:5,../../../../Chests/Lore/Viking_5.nbt,2,CHEST:5,../../../../Chests/Lore/Viking_5.nbt,2,CHEST:5,../../../../Chests/Loot/Rare1.nbt,5,CHEST:5,../../../../Chests/Loot/Rare2.nbt,5,CHEST:5,../../../../Chests/Loot/Rare3.nbt,5,CHEST:5,../../../../Chests/Loot/Rare4.nbt,5,CHEST:5,../../../../Chests/Loot/Rare5.nbt,5,CHEST:5,../../../../Chests/Loot/Rare6.nbt,5,CHEST:5,../../../../Chests/Loot/Rare7.nbt,5,CHEST:5,../../../../Chests/Loot/Rare8.nbt,5,CHEST:5,../../../../Chests/Loot/Rare9.nbt,5,CHEST:5,../../../../Chests/Loot/Rare10.nbt,5,CHEST:5,../../../../Chests/Loot/Rare11.nbt,5,CHEST:5,../../../../Chests/Loot/Rare12.nbt,5,CHEST:5,../../../../Chests/Loot/Rare13.nbt,5,CHEST:5,../../../../Chests/Loot/Rare14.nbt,5,CHEST:5,../../../../Chests/Loot/Rare15.nbt,5,CHEST:5,../../../../Chests/Loot/Epic1.nbt,2,CHEST:5,../../../../Chests/Loot/Epic2.nbt,2,CHEST:5,../../../../Chests/Loot/Epic3.nbt,2,CHEST:5,../../../../Chests/Loot/Epic4.nbt,2,CHEST:5,../../../../Chests/Loot/Epic5.nbt,2,CHEST:5,../../../../Chests/Loot/Epic6.nbt,2,CHEST:5,../../../../Chests/Loot/Epic7.nbt,2,CHEST:5,../../../../Chests/Loot/Epic8.nbt,2,CHEST:5,../../../../Chests/Loot/Epic9.nbt,2,CHEST:5,../../../../Chests/Loot/Epic10.nbt,2,CHEST:5,../../../../Chests/Loot/Epic11.nbt,2,CHEST:5,../../../../Chests/Loot/Epic12.nbt,2,CHEST:5,../../../../Chests/Loot/Epic13.nbt,2,CHEST:5,../../../../Chests/Loot/Epic14.nbt,2,CHEST:5,../../../../Chests/Loot/Epic15.nbt,5,CHEST:5,../../../../Chests/Loot/Rare1.nbt,5,CHEST:5,../../../../Chests/Loot/Rare2.nbt,5,CHEST:5,../../../../Chests/Loot/Rare3.nbt,5,CHEST:5,../../../../Chests/Loot/Rare4.nbt,5,CHEST:5,../../../../Chests/Loot/Rare5.nbt,10,CHEST:5,../../../../Chests/Loot/Rare6.nbt,10,CHEST:5,../../../../Chests/Loot/Rare7.nbt,10,CHEST:5,../../../../Chests/Loot/Rare8.nbt,10,CHEST:5,../../../../Chests/Loot/Rare9.nbt,10,CHEST:5,../../../../Chests/Loot/Rare10.nbt,15,CHEST:5,../../../../Chests/Loot/Rare11.nbt,15,CHEST:5,../../../../Chests/Loot/Rare12.nbt,15,CHEST:5,../../../../Chests/Loot/Rare13.nbt,15,CHEST:5,../../../../Chests/Loot/Rare14.nbt,15,CHEST:5,../../../../Chests/Loot/Rare15.nbt,15,CHEST:5,../../../../Chests/Loot/Epic15.nbt,100)
RandomBlock(-1,3,2,AIR:0,20,CHEST:5,../../../../Chests/Loot/JunkChest_1.nbt,10,CHEST:5,../../../../Chests/Loot/JunkChest_2.nbt,10,CHEST:5,../../../../Chests/Loot/JunkChest_3.nbt,10,CHEST:5,../../../../Chests/Loot/JunkChest_4.nbt,10,CHEST:5,../../../../Chests/Loot/JunkChest_5.nbt,10,CHEST:5,../../../../Chests/Lore/Viking_1.nbt,1,CHEST:5,../../../../Chests/Lore/Viking_2.nbt,1,CHEST:5,../../../../Chests/Lore/Viking_3.nbt,1,CHEST:5,../../../../Chests/Lore/Viking_4.nbt,1,CHEST:5,../../../../Chests/Lore/Viking_5.nbt,1,CHEST:5,../../../../Chests/Loot/Common1.nbt,10,CHEST:5,../../../../Chests/Loot/Common2.nbt,10,CHEST:5,../../../../Chests/Loot/Common3.nbt,10,CHEST:5,../../../../Chests/Loot/Common4.nbt,10,CHEST:5,../../../../Chests/Loot/Common5.nbt,10,CHEST:5,../../../../Chests/Loot/Common6.nbt,10,CHEST:5,../../../../Chests/Loot/Common7.nbt,10,CHEST:5,../../../../Chests/Loot/Common8.nbt,10,CHEST:5,../../../../Chests/Loot/Common9.nbt,10,CHEST:5,../../../../Chests/Loot/Common10.nbt,10,CHEST:5,../../../../Chests/Loot/Common10.nbt,11,CHEST:5,../../../../Chests/Loot/Common12.nbt,10,CHEST:5,../../../../Chests/Loot/Common13.nbt,10,CHEST:5,../../../../Chests/Loot/Common14.nbt,10,CHEST:5,../../../../Chests/Loot/Common15.nbt,10,CHEST:5,../../../../Chests/Lore/Viking_1.nbt,2,CHEST:5,../../../../Chests/Lore/Viking_3.nbt,2,CHEST:5,../../../../Chests/Lore/Viking_4.nbt,2,CHEST:5,../../../../Chests/Lore/Viking_5.nbt,2,CHEST:5,../../../../Chests/Lore/Viking_5.nbt,2,CHEST:5,../../../../Chests/Loot/Rare1.nbt,5,CHEST:5,../../../../Chests/Loot/Rare2.nbt,5,CHEST:5,../../../../Chests/Loot/Rare3.nbt,5,CHEST:5,../../../../Chests/Loot/Rare4.nbt,5,CHEST:5,../../../../Chests/Loot/Rare5.nbt,5,CHEST:5,../../../../Chests/Loot/Rare6.nbt,5,CHEST:5,../../../../Chests/Loot/Rare7.nbt,5,CHEST:5,../../../../Chests/Loot/Rare8.nbt,5,CHEST:5,../../../../Chests/Loot/Rare9.nbt,5,CHEST:5,../../../../Chests/Loot/Rare10.nbt,5,CHEST:5,../../../../Chests/Loot/Rare11.nbt,5,CHEST:5,../../../../Chests/Loot/Rare12.nbt,5,CHEST:5,../../../../Chests/Loot/Rare13.nbt,5,CHEST:5,../../../../Chests/Loot/Rare14.nbt,5,CHEST:5,../../../../Chests/Loot/Rare15.nbt,5,CHEST:5,../../../../Chests/Loot/Epic1.nbt,2,CHEST:5,../../../../Chests/Loot/Epic2.nbt,2,CHEST:5,../../../../Chests/Loot/Epic3.nbt,2,CHEST:5,../../../../Chests/Loot/Epic4.nbt,2,CHEST:5,../../../../Chests/Loot/Epic5.nbt,2,CHEST:5,../../../../Chests/Loot/Epic6.nbt,2,CHEST:5,../../../../Chests/Loot/Epic7.nbt,2,CHEST:5,../../../../Chests/Loot/Epic8.nbt,2,CHEST:5,../../../../Chests/Loot/Epic9.nbt,2,CHEST:5,../../../../Chests/Loot/Epic10.nbt,2,CHEST:5,../../../../Chests/Loot/Epic11.nbt,2,CHEST:5,../../../../Chests/Loot/Epic12.nbt,2,CHEST:5,../../../../Chests/Loot/Epic13.nbt,2,CHEST:5,../../../../Chests/Loot/Epic14.nbt,2,CHEST:5,../../../../Chests/Loot/Epic15.nbt,5,CHEST:5,../../../../Chests/Loot/Rare1.nbt,5,CHEST:5,../../../../Chests/Loot/Rare2.nbt,5,CHEST:5,../../../../Chests/Loot/Rare3.nbt,5,CHEST:5,../../../../Chests/Loot/Rare4.nbt,5,CHEST:5,../../../../Chests/Loot/Rare5.nbt,10,CHEST:5,../../../../Chests/Loot/Rare6.nbt,10,CHEST:5,../../../../Chests/Loot/Rare7.nbt,10,CHEST:5,../../../../Chests/Loot/Rare8.nbt,10,CHEST:5,../../../../Chests/Loot/Rare9.nbt,10,CHEST:5,../../../../Chests/Loot/Rare10.nbt,15,CHEST:5,../../../../Chests/Loot/Rare11.nbt,15,CHEST:5,../../../../Chests/Loot/Rare12.nbt,15,CHEST:5,../../../../Chests/Loot/Rare13.nbt,15,CHEST:5,../../../../Chests/Loot/Rare14.nbt,15,CHEST:5,../../../../Chests/Loot/Rare15.nbt,15,CHEST:5,../../../../Chests/Loot/Epic15.nbt,100)
Block(-1,3,3,SMOOTH_BRICK:0)
Block(-1,4,-2,SMOOTH_BRICK:0)
Block(-1,4,-1,SMOOTH_BRICK:0)
Block(-1,4,0,LOG:5)
Block(-1,4,3,SMOOTH_BRICK:0)
Block(-1,5,-3,WALL_SIGN:2)
Block(-1,5,-2,WOOD:5)
Block(-1,5,3,WOOD:5)
Block(-1,5,4,WALL_SIGN:3)
Block(-1,6,-2,WOOD:5)
Block(-1,6,3,WOOD:5)
Block(-1,7,-2,WOOD:5)
Block(-1,7,3,WOOD:1)
Block(-1,8,-2,WOOD:5)
Block(-1,8,3,WOOD:1)
Block(-1,9,-3,WALL_SIGN:2)
Block(-1,9,-2,WOOD:1)
Block(-1,9,1,WOOD_DOUBLE_STEP:1)
Block(-1,9,3,WOOD:1)
Block(-1,9,4,WALL_SIGN:3)
Block(-1,10,1,DARK_OAK_FENCE:0)
Block(-1,11,1,DARK_OAK_FENCE:0)
Block(-1,12,1,DARK_OAK_FENCE:0)
RandomBlock(-1,13,1,STANDING_BANNER:6,../../NBT/Banners/viking_emblem_1.nbt,20,STANDING_BANNER:6,../../NBT/Banners/viking_emblem_2.nbt,20,STANDING_BANNER:6,../../NBT/Banners/viking_emblem_3.nbt,20,STANDING_BANNER:6,../../NBT/Banners/viking_emblem_4.nbt,100)
Block(0,2,-2,SPRUCE_DOOR:1)
Block(0,2,0,SPRUCE_DOOR:1)
Block(0,3,-2,SPRUCE_DOOR:9)
Block(0,3,0,SPRUCE_DOOR:8)
Block(0,4,-2,SMOOTH_BRICK:0)
Block(0,4,-1,IRON_FENCE:0)
Block(0,4,0,LOG:5)
Block(0,5,-3,WALL_SIGN:2)
Block(0,5,-2,WOOD:1)
Block(0,5,-1,TRAP_DOOR:1)
Block(0,5,3,WOOD:1)
Block(0,5,4,WALL_SIGN:3)
Block(0,6,3,WOOD:1)
Block(0,7,3,WOOD:1)
Block(0,8,-2,WOOD:1)
Block(0,8,3,WOOD:5)
Block(0,9,-3,WALL_SIGN:2)
Block(0,9,-2,WOOD:1)
Block(0,9,3,WOOD:5)
Block(0,9,4,WALL_SIGN:3)
Block(0,10,-2,WOOD:1)
Block(0,10,3,WOOD:5)
Block(1,2,0,LOG:1)
Block(1,2,1,LADDER:3)
Block(1,2,3,SMOOTH_BRICK:0)
Block(1,3,-1,IRON_FENCE:0)
Block(1,3,0,LOG:1)
Block(1,3,1,LADDER:3)
Block(1,3,3,SMOOTH_BRICK:0)
Block(1,4,-2,SMOOTH_BRICK:0)
Block(1,4,0,LOG:1)
Block(1,4,1,LADDER:3)
Block(1,4,3,SMOOTH_BRICK:0)
Block(1,5,-3,WALL_SIGN:2)
Block(1,5,-2,WOOD:1)
Block(1,5,0,LOG:1)
Block(1,5,1,LADDER:3)
Block(1,5,3,WOOD:5)
Block(1,5,4,WALL_SIGN:3)
Block(1,6,-2,WOOD:1)
Block(1,6,0,LOG:1)
Block(1,6,1,LADDER:3)
Block(1,7,-2,WOOD:1)
Block(1,7,0,LOG:1)
Block(1,7,1,LADDER:3)
Block(1,8,-2,WOOD:5)
Block(1,8,0,LOG:1)
Block(1,8,1,LADDER:3)
Block(1,8,3,WOOD:5)
Block(1,9,-3,WALL_SIGN:2)
Block(1,9,-2,WOOD:5)
Block(1,9,1,TRAP_DOOR:0)
Block(1,9,3,WOOD:1)
Block(1,9,4,WALL_SIGN:3)
Block(1,10,-2,WOOD:1)
Block(1,10,0,AIR:0)
Block(1,10,3,WOOD:1)
Block(2,2,-2,SMOOTH_BRICK:0)
Block(2,3,-2,SMOOTH_BRICK:0)
Block(2,4,-2,SMOOTH_BRICK:0)
Block(2,4,0,LOG:5)
Block(2,5,-3,WALL_SIGN:2)
Block(2,5,-2,WOOD:1)
Block(2,5,3,WOOD:5)
Block(2,5,4,WALL_SIGN:3)
Block(2,6,-2,WOOD:5)
Block(2,6,3,WOOD:5)
Block(2,7,-2,WOOD:5)
Block(2,7,3,WOOD:5)
Block(2,8,-2,WOOD:5)
Block(2,8,3,WOOD:5)
Block(2,9,-3,WALL_SIGN:2)
Block(2,9,-2,WOOD:1)
Block(2,9,3,WOOD:1)
Block(2,9,4,WALL_SIGN:3)
Block(3,0,-2,LOG:1)
Block(3,0,3,LOG:1)
Block(3,1,-2,LOG:1)
Block(3,1,3,LOG:1)
Block(3,2,-2,LOG:1)
Block(3,2,0,SMOOTH_BRICK:0)
Block(3,2,1,SMOOTH_BRICK:0)
Block(3,2,2,SMOOTH_BRICK:0)
Block(3,2,3,LOG:1)
Block(3,3,-2,LOG:1)
Block(3,3,0,SMOOTH_BRICK:0)
Block(3,3,3,LOG:1)
Block(3,4,-2,LOG:1)
Block(3,4,0,SMOOTH_BRICK:0)
Block(3,4,3,LOG:1)
Block(3,5,-3,WALL_SIGN:2)
Block(3,5,-2,LOG:1)
Block(3,5,-1,WOOD:5)
Block(3,5,0,WOOD:5)
Block(3,5,1,WOOD:1)
Block(3,5,2,WOOD:1)
Block(3,5,3,LOG:1)
Block(3,5,4,WALL_SIGN:3)
Block(3,6,-3,WOOD_BUTTON:4)
Block(3,6,-2,LOG:1)
Block(3,6,-1,WOOD:5)
Block(3,6,1,WOOD:1)
Block(3,6,2,WOOD:5)
Block(3,6,3,LOG:1)
Block(3,6,4,WOOD_BUTTON:3)
Block(3,7,-2,LOG:1)
Block(3,7,-1,WOOD:1)
Block(3,7,1,WOOD:1)
Block(3,7,2,WOOD:5)
Block(3,7,3,LOG:1)
Block(3,8,-3,WOOD_BUTTON:4)
Block(3,8,-2,LOG:1)
Block(3,8,-1,WOOD:1)
Block(3,8,0,WOOD:1)
Block(3,8,1,WOOD:5)
Block(3,8,2,WOOD:5)
Block(3,8,3,LOG:1)
Block(3,8,4,WOOD_BUTTON:3)
Block(3,9,-3,WALL_SIGN:2)
Block(3,9,-2,LOG:1)
Block(3,9,-1,WOOD:1)
Block(3,9,0,WOOD:1)
Block(3,9,1,WOOD:5)
Block(3,9,2,WOOD:1)
Block(3,9,3,LOG:1)
Block(3,9,4,WALL_SIGN:3)
Block(3,10,-2,WOOD:1)
Block(3,10,0,WOOD:1)
Block(3,10,1,WOOD:5)
Block(3,10,3,WOOD:1)
Block(4,5,-2,WALL_SIGN:5)
Block(4,5,-1,WALL_SIGN:5)
Block(4,5,0,WALL_SIGN:5)
Block(4,5,1,WALL_SIGN:5)
Block(4,5,2,WALL_SIGN:5)
Block(4,5,3,WALL_SIGN:5)
Block(4,9,-2,WALL_SIGN:5)
Block(4,9,-1,WALL_SIGN:5)
Block(4,9,0,WALL_SIGN:5)
Block(4,9,1,WALL_SIGN:5)
Block(4,9,2,WALL_SIGN:5)
Block(4,9,3,WALL_SIGN:5)



Block(-2,0,-1,COBBLESTONE:0)
Block(-2,0,0,COBBLESTONE:0)
Block(-2,0,1,COBBLESTONE:0)
Block(-2,0,2,COBBLESTONE:0)
Block(-2,1,-1,COBBLESTONE:0)
Block(-2,1,0,COBBLESTONE:0)
Block(-2,1,1,COBBLESTONE:0)
Block(-2,1,2,COBBLESTONE:0)
Block(-2,2,0,COBBLESTONE:0)
Block(-2,3,0,COBBLESTONE:0)
Block(-2,3,2,COBBLESTONE:0)
Block(-2,4,-1,COBBLESTONE:0)
Block(-2,4,0,COBBLESTONE:0)
Block(-2,4,2,COBBLESTONE:0)
Block(-2,6,1,SPRUCE_WOOD_STAIRS:2)
Block(-2,7,1,SPRUCE_WOOD_STAIRS:6)
Block(-2,11,-2,SPRUCE_WOOD_STAIRS:3)
Block(-2,11,0,SPRUCE_WOOD_STAIRS:2)
Block(-2,11,1,SPRUCE_WOOD_STAIRS:3)
Block(-2,11,3,SPRUCE_WOOD_STAIRS:2)
Block(-1,0,-2,COBBLESTONE:0)
Block(-1,0,-1,COBBLESTONE:0)
Block(-1,0,0,COBBLESTONE:0)
Block(-1,0,1,COBBLESTONE:0)
Block(-1,0,2,COBBLESTONE:0)
Block(-1,0,3,COBBLESTONE:0)
Block(-1,1,-2,COBBLESTONE:0)
Block(-1,1,-1,COBBLESTONE:0)
Block(-1,1,0,COBBLESTONE:0)
Block(-1,1,1,COBBLESTONE:0)
Block(-1,1,2,COBBLESTONE:0)
Block(-1,1,3,COBBLESTONE:0)
Block(-1,2,-2,COBBLESTONE:0)
Block(-1,2,-1,COBBLESTONE:0)
Block(-1,2,0,COBBLESTONE:0)
Block(-1,3,-2,COBBLESTONE:0)
Block(-1,3,-1,COBBLESTONE:0)
Block(-1,3,0,COBBLESTONE:0)
Block(0,0,-2,COBBLESTONE:0)
Block(0,0,-1,COBBLESTONE:0)
Block(0,0,0,COBBLESTONE:0)
Block(0,0,1,COBBLESTONE:0)
Block(0,0,2,COBBLESTONE:0)
Block(0,0,3,COBBLESTONE:0)
Block(0,1,-2,COBBLESTONE:0)
Block(0,1,-1,COBBLESTONE:0)
Block(0,1,0,COBBLESTONE:0)
Block(0,1,1,COBBLESTONE:0)
Block(0,1,2,COBBLESTONE:0)
Block(0,1,3,COBBLESTONE:0)
Block(0,2,3,COBBLESTONE:0)
Block(0,3,3,COBBLESTONE:0)
Block(0,4,3,COBBLESTONE:0)
Block(0,6,-2,SPRUCE_WOOD_STAIRS:1)
Block(0,7,-2,SPRUCE_WOOD_STAIRS:5)
Block(0,11,-2,SPRUCE_WOOD_STAIRS:0)
Block(0,11,3,SPRUCE_WOOD_STAIRS:0)
Block(1,0,-2,COBBLESTONE:0)
Block(1,0,-1,COBBLESTONE:0)
Block(1,0,0,COBBLESTONE:0)
Block(1,0,1,COBBLESTONE:0)
Block(1,0,2,COBBLESTONE:0)
Block(1,0,3,COBBLESTONE:0)
Block(1,1,-2,COBBLESTONE:0)
Block(1,1,-1,COBBLESTONE:0)
Block(1,1,0,COBBLESTONE:0)
Block(1,1,1,COBBLESTONE:0)
Block(1,1,2,COBBLESTONE:0)
Block(1,1,3,COBBLESTONE:0)
Block(1,2,-2,COBBLESTONE:0)
Block(1,2,-1,COBBLESTONE:0)
Block(1,3,-2,COBBLESTONE:0)
Block(1,4,-1,COBBLESTONE:0)
Block(1,6,3,SPRUCE_WOOD_STAIRS:0)
Block(1,7,3,SPRUCE_WOOD_STAIRS:4)
Block(1,11,-2,SPRUCE_WOOD_STAIRS:1)
Block(1,11,3,SPRUCE_WOOD_STAIRS:1)
Block(2,0,-2,COBBLESTONE:0)
Block(2,0,-1,COBBLESTONE:0)
Block(2,0,0,COBBLESTONE:0)
Block(2,0,1,COBBLESTONE:0)
Block(2,0,2,COBBLESTONE:0)
Block(2,0,3,COBBLESTONE:0)
Block(2,1,-2,COBBLESTONE:0)
Block(2,1,-1,COBBLESTONE:0)
Block(2,1,0,COBBLESTONE:0)
Block(2,1,1,COBBLESTONE:0)
Block(2,1,2,COBBLESTONE:0)
Block(2,1,3,COBBLESTONE:0)
Block(2,2,3,COBBLESTONE:0)
Block(2,3,3,COBBLESTONE:0)
Block(2,4,3,COBBLESTONE:0)
Block(3,0,-1,COBBLESTONE:0)
Block(3,0,0,COBBLESTONE:0)
Block(3,0,1,COBBLESTONE:0)
Block(3,0,2,COBBLESTONE:0)
Block(3,1,-1,COBBLESTONE:0)
Block(3,1,0,COBBLESTONE:0)
Block(3,1,1,COBBLESTONE:0)
Block(3,1,2,COBBLESTONE:0)
Block(3,2,-1,COBBLESTONE:0)
Block(3,3,-1,COBBLESTONE:0)
Block(3,3,1,COBBLESTONE:0)
Block(3,3,2,COBBLESTONE:0)
Block(3,4,-1,COBBLESTONE:0)
Block(3,4,1,COBBLESTONE:0)
Block(3,4,2,COBBLESTONE:0)
Block(3,6,0,SPRUCE_WOOD_STAIRS:3)
Block(3,7,0,SPRUCE_WOOD_STAIRS:7)
Block(3,11,-2,SPRUCE_WOOD_STAIRS:3)
Block(3,11,0,SPRUCE_WOOD_STAIRS:2)
Block(3,11,1,SPRUCE_WOOD_STAIRS:3)
Block(3,11,3,SPRUCE_WOOD_STAIRS:2)

Block(-1,5,-1,WOOD_STEP:1)
Block(-1,5,0,WOOD_STEP:1)
Block(-1,5,1,WOOD_STEP:1)
Block(-1,5,2,WOOD_STEP:1)
Block(-1,8,-1,WOOD_STEP:9)
Block(-1,8,0,WOOD_STEP:9)
Block(-1,8,1,WOOD_STEP:9)
Block(-1,8,2,WOOD_STEP:9)
Block(-1,9,-1,WOOD_STEP:1)
Block(-1,9,0,WOOD_STEP:1)
Block(-1,9,2,WOOD_STEP:1)
Block(0,5,0,WOOD_STEP:1)
Block(0,5,1,WOOD_STEP:1)
Block(0,5,2,WOOD_STEP:1)
Block(0,8,-1,WOOD_STEP:9)
Block(0,8,0,WOOD_STEP:9)
Block(0,8,1,WOOD_STEP:9)
Block(0,8,2,WOOD_STEP:9)
Block(0,9,-1,WOOD_STEP:1)
Block(0,9,0,WOOD_STEP:1)
Block(0,9,1,WOOD_STEP:1)
Block(0,9,2,WOOD_STEP:1)
Block(1,5,-1,WOOD_STEP:1)
Block(1,5,2,WOOD_STEP:1)
Block(1,8,-1,WOOD_STEP:9)
Block(1,8,2,WOOD_STEP:9)
Block(1,9,-1,WOOD_STEP:1)
Block(1,9,0,WOOD_STEP:1)
Block(1,9,2,WOOD_STEP:1)
Block(2,5,-1,WOOD_STEP:1)
Block(2,5,0,WOOD_STEP:1)
Block(2,5,1,WOOD_STEP:1)
Block(2,5,2,WOOD_STEP:1)
Block(2,8,-1,WOOD_STEP:9)
Block(2,8,0,WOOD_STEP:9)
Block(2,8,1,WOOD_STEP:9)
Block(2,8,2,WOOD_STEP:9)
Block(2,9,-1,WOOD_STEP:1)
Block(2,9,0,WOOD_STEP:1)
Block(2,9,1,WOOD_STEP:1)
Block(2,9,2,WOOD_STEP:1)
