#######################################################################
# +-----------------------------------------------------------------+ #
# |                            BO3 object                           | #
# +-----------------------------------------------------------------+ #
#######################################################################

Author: Bo3 BulkEdit

Description: Converted Schematic - Modified by Bo3BulkEdit

Version: 3

SettingsMode: WriteDisable

#######################################################################
# +-----------------------------------------------------------------+ #
# |                          Main settings                          | #
# +-----------------------------------------------------------------+ #
#######################################################################

IsOTGPlus: true
Tree: false
Frequency: 1
Rarity: 100
RotateRandomly: false
SpawnHeight: randomY
SpawnHeightOffset: 0
SpawnHeightVariance: 0
MaxBranchDepth: 10
ExcludedBiomes: All

##############################
# Height Limits for the BO3. #
##############################

MinHeight: 0
MaxHeight: 256

#######################################################################
# +-----------------------------------------------------------------+ #
# |                      Source block settings                      | #
# +-----------------------------------------------------------------+ #
#######################################################################

SourceBlocks: AIR
MaxPercentageOutsideSourceBlock: 100
OutsideSourceBlock: placeAnyway

#######################################################################
# +-----------------------------------------------------------------+ #
# |                               OTG+                              | #
# +-----------------------------------------------------------------+ #
#######################################################################

BranchFrequency: 2
ReplaceWithBiomeBlocks: true
ReplaceWithGroundBlock: DIRT
ReplaceWithSurfaceBlock: GRASS
ReplaceWithStoneBlock: STONE
SmoothRadius: 0
SmoothHeightOffset: 0
IsSpawnPoint: true

#######################################################################
# +-----------------------------------------------------------------+ #
# |                              Blocks                             | #
# +-----------------------------------------------------------------+ #
#######################################################################

Block(0,750,0,AIR)
Block(15,750,15,AIR)
RandomBlock(14,15,13,WALL_BANNER:3,../NBT/Banners/Banner1.nbt,25,WALL_BANNER:3,../NBT/Banners/Banner2.nbt,25,WALL_BANNER:3,../NBT/Banners/Banner3.nbt,100)
RandomBlock(12,15,15,WALL_BANNER:5,../NBT/Banners/Banner1.nbt,25,WALL_BANNER:5,../NBT/Banners/Banner2.nbt,25,WALL_BANNER:5,../NBT/Banners/Banner3.nbt,100)
RandomBlock(12,20,15,CHEST:5,../../../Chests/Loot/BoneChest_1.nbt,10,CHEST:5,../../../Chests/Loot/BoneChest_2.nbt,10,CHEST:5,../../../Chests/Loot/BoneChest_3.nbt,10,CHEST:5,../../../Chests/Loot/BoneChest_4.nbt,10,CHEST:5,../../../Chests/Loot/BoneChest_5.nbt,10,CHEST:5,../../../Chests/Lore/Witch_1.nbt,1,CHEST:5,../../../Chests/Lore/Witch_2.nbt,1,CHEST:5,../../../Chests/Lore/Witch_3.nbt,1,CHEST:5,../../../Chests/Lore/Witch_4.nbt,1,CHEST:5,../../../Chests/Lore/Witch_5.nbt,1,CHEST:5,../../../Chests/Loot/Common1.nbt,5,CHEST:5,../../../Chests/Loot/Common2.nbt,5,CHEST:5,../../../Chests/Loot/Common3.nbt,5,CHEST:5,../../../Chests/Loot/Common4.nbt,5,CHEST:5,../../../Chests/Loot/Common5.nbt,5,CHEST:5,../../../Chests/Loot/Common6.nbt,5,CHEST:5,../../../Chests/Loot/Common7.nbt,5,CHEST:5,../../../Chests/Loot/Common8.nbt,5,CHEST:5,../../../Chests/Loot/Common9.nbt,5,CHEST:5,../../../Chests/Loot/Common10.nbt,5,CHEST:5,../../../Chests/Loot/Common11.nbt,5,CHEST:5,../../../Chests/Loot/Common12.nbt,5,CHEST:5,../../../Chests/Loot/Common13.nbt,5,CHEST:5,../../../Chests/Loot/Common14.nbt,5,CHEST:5,../../../Chests/Loot/Common15.nbt,5,CHEST:5,../../../Chests/Lore/Witch_1.nbt,2,CHEST:5,../../../Chests/Lore/Witch_2.nbt,2,CHEST:5,../../../Chests/Lore/Witch_3.nbt,2,CHEST:5,../../../Chests/Lore/Witch_4.nbt,2,CHEST:5,../../../Chests/Lore/Witch_5.nbt,2,CHEST:5,../../../Chests/Loot/Rare1.nbt,5,CHEST:5,../../../Chests/Loot/Rare2.nbt,5,CHEST:5,../../../Chests/Loot/Rare3.nbt,5,CHEST:5,../../../Chests/Loot/Rare4.nbt,5,CHEST:5,../../../Chests/Loot/Rare5.nbt,5,CHEST:5,../../../Chests/Loot/Rare6.nbt,5,CHEST:5,../../../Chests/Loot/Rare7.nbt,5,CHEST:5,../../../Chests/Loot/Rare8.nbt,5,CHEST:5,../../../Chests/Loot/Rare9.nbt,5,CHEST:5,../../../Chests/Loot/Rare10.nbt,5,CHEST:5,../../../Chests/Loot/Rare11.nbt,5,CHEST:5,../../../Chests/Loot/Rare12.nbt,5,CHEST:5,../../../Chests/Loot/Rare13.nbt,5,CHEST:5,../../../Chests/Loot/Rare14.nbt,5,CHEST:5,../../../Chests/Loot/Rare15.nbt,5,CHEST:5,../../../Chests/Loot/Epic1.nbt,2,CHEST:5,../../../Chests/Loot/Epic2.nbt,2,CHEST:5,../../../Chests/Loot/Epic3.nbt,2,CHEST:5,../../../Chests/Loot/Epic4.nbt,2,CHEST:5,../../../Chests/Loot/Epic5.nbt,2,CHEST:5,../../../Chests/Loot/Epic6.nbt,2,CHEST:5,../../../Chests/Loot/Epic7.nbt,2,CHEST:5,../../../Chests/Loot/Epic8.nbt,2,CHEST:5,../../../Chests/Loot/Epic9.nbt,2,CHEST:5,../../../Chests/Loot/Epic10.nbt,2,CHEST:5,../../../Chests/Loot/Epic11.nbt,2,CHEST:5,../../../Chests/Loot/Epic12.nbt,2,CHEST:5,../../../Chests/Loot/Epic13.nbt,2,CHEST:5,../../../Chests/Loot/Epic14.nbt,2,CHEST:5,../../../Chests/Loot/Epic15.nbt,5,CHEST:5,../../../Chests/Loot/Rare1.nbt,5,CHEST:5,../../../Chests/Loot/Rare2.nbt,5,CHEST:5,../../../Chests/Loot/Rare3.nbt,5,CHEST:5,../../../Chests/Loot/Rare4.nbt,5,CHEST:5,../../../Chests/Loot/Rare5.nbt,10,CHEST:5,../../../Chests/Loot/Rare6.nbt,10,CHEST:5,../../../Chests/Loot/Rare7.nbt,10,CHEST:5,../../../Chests/Loot/Rare8.nbt,10,CHEST:5,../../../Chests/Loot/Rare9.nbt,10,CHEST:5,../../../Chests/Loot/Rare10.nbt,15,CHEST:5,../../../Chests/Loot/Rare11.nbt,15,CHEST:5,../../../Chests/Loot/Rare12.nbt,15,CHEST:5,../../../Chests/Loot/Rare13.nbt,15,CHEST:5,../../../Chests/Loot/Rare14.nbt,15,CHEST:5,../../../Chests/Loot/Rare15.nbt,15,CHEST:5,../../../Chests/Loot/Epic15.nbt,100)
Block(6,7,11,LOG:1)
Block(6,0,11,LOG:1)
Block(11,0,11,LOG:1)
Block(15,0,11,LOG:1)
Block(6,1,11,LOG:1)
Block(11,1,11,LOG:1)
Block(15,1,11,LOG:1)
Block(6,2,11,LOG:1)
Block(11,2,11,LOG:1)
Block(15,2,11,LOG:1)
Block(6,3,11,LOG:1)
Block(11,3,11,LOG:1)
Block(15,3,11,LOG:1)
Block(6,4,11,LOG:1)
Block(11,4,11,LOG:1)
Block(15,4,11,LOG:1)
Block(6,5,11,LOG:1)
Block(11,5,11,LOG:1)
Block(15,5,11,LOG:1)
Block(6,6,11,LOG:1)
Block(11,6,11,LOG:1)
Block(15,6,11,LOG:1)
Block(11,7,11,LOG:1)
Block(15,7,11,LOG:1)
Block(6,8,11,LOG:1)
Block(11,8,11,LOG:1)
Block(15,8,11,LOG:1)
Block(6,9,11,LOG:1)
Block(7,9,11,FENCE:0)
Block(8,9,11,FENCE:0)
Block(9,9,11,FENCE:0)
Block(10,9,11,FENCE:0)
Block(11,9,11,LOG:1)
Block(12,9,11,FENCE:0)
Block(13,9,11,FENCE:0)
Block(14,9,11,FENCE:0)
Block(15,9,11,LOG:1)
Block(6,9,12,FENCE:0)
Block(11,9,12,FENCE:0)
Block(15,9,12,FENCE:0)
Block(6,9,13,FENCE:0)
Block(11,9,13,FENCE:0)
Block(15,9,13,FENCE:0)
Block(6,9,14,FENCE:0)
Block(11,9,14,FENCE:0)
Block(15,9,14,FENCE:0)
Block(6,9,15,FENCE:0)
Block(11,9,15,FENCE:0)
Block(15,9,15,FENCE:0)
Block(6,10,11,LOG:1)
Block(7,10,11,LOG:5)
Block(8,10,11,LOG:5)
Block(9,10,11,LOG:5)
Block(10,10,11,LOG:5)
Block(11,10,11,LOG:1)
Block(12,10,11,LOG:5)
Block(13,10,11,LOG:5)
Block(14,10,11,LOG:5)
Block(15,10,11,LOG:1)
Block(6,10,12,LOG:9)
Block(7,10,12,WOODEN_SLAB:9)
Block(8,10,12,WOODEN_SLAB:9)
Block(9,10,12,WOODEN_SLAB:9)
Block(10,10,12,WOODEN_SLAB:9)
Block(11,10,12,LOG:9)
Block(12,10,12,WOODEN_SLAB:9)
Block(13,10,12,WOODEN_SLAB:9)
Block(14,10,12,WOODEN_SLAB:9)
Block(15,10,12,LOG:9)
Block(6,10,13,LOG:9)
Block(7,10,13,WOODEN_SLAB:9)
Block(8,10,13,WOODEN_SLAB:9)
Block(9,10,13,WOODEN_SLAB:9)
Block(10,10,13,WOODEN_SLAB:9)
Block(11,10,13,LOG:9)
Block(12,10,13,WOODEN_SLAB:9)
Block(13,10,13,WOODEN_SLAB:9)
Block(14,10,13,WOODEN_SLAB:9)
Block(15,10,13,LOG:9)
Block(6,10,14,LOG:9)
Block(7,10,14,WOODEN_SLAB:9)
Block(8,10,14,WOODEN_SLAB:9)
Block(9,10,14,WOODEN_SLAB:9)
Block(10,10,14,WOODEN_SLAB:9)
Block(11,10,14,LOG:9)
Block(12,10,14,WOODEN_SLAB:9)
Block(13,10,14,WOODEN_SLAB:9)
Block(14,10,14,WOODEN_SLAB:9)
Block(15,10,14,LOG:9)
Block(6,10,15,LOG:9)
Block(7,10,15,WOODEN_SLAB:9)
Block(8,10,15,WOODEN_SLAB:9)
Block(9,10,15,WOODEN_SLAB:9)
Block(10,10,15,WOODEN_SLAB:9)
Block(11,10,15,LOG:9)
Block(12,10,15,WOODEN_SLAB:9)
Block(13,10,15,WOODEN_SLAB:9)
Block(14,10,15,WOODEN_SLAB:9)
Block(15,10,15,LOG:9)
Block(6,11,11,LOG:1)
Block(7,11,11,TRAPDOOR:4)
Block(11,11,11,STONE_BRICK_STAIRS:2)
Block(12,11,11,FENCE:0)
Block(13,11,11,FENCE:0)
Block(14,11,11,FENCE:0)
Block(15,11,11,STONE_BRICK_STAIRS:2)
Block(6,11,12,TRAPDOOR:14)
Block(7,11,12,LOG:1)
Block(8,11,12,OAK_STAIRS:2)
Block(9,11,12,OAK_STAIRS:2)
Block(10,11,12,OAK_STAIRS:2)
Block(11,11,12,LOG:1)
Block(12,11,12,STONE_BRICK_STAIRS:2)
Block(13,11,12,STONE_BRICK_STAIRS:2)
Block(14,11,12,STONE_BRICK_STAIRS:2)
Block(15,11,12,LOG:1)
Block(7,11,13,OAK_STAIRS:0)
Block(8,11,13,LOG:1)
Block(9,11,13,STONEBRICK:0)
Block(10,11,13,STONEBRICK:0)
Block(11,11,13,FENCE:0)
Block(12,11,13,STONEBRICK:0)
Block(13,11,13,STONEBRICK:0)
Block(14,11,13,STONEBRICK:0)
Block(15,11,13,FENCE:0)
Block(7,11,14,OAK_STAIRS:0)
Block(8,11,14,STONEBRICK:0)
Block(9,11,14,LOG:1)
Block(10,11,14,STONEBRICK:0)
Block(11,11,14,FENCE:0)
Block(12,11,14,STONEBRICK:0)
Block(13,11,14,STONEBRICK:0)
Block(14,11,14,STONEBRICK:0)
Block(15,11,14,FENCE:0)
Block(7,11,15,OAK_STAIRS:0)
Block(8,11,15,STONEBRICK:0)
Block(9,11,15,STONEBRICK:0)
Block(10,11,15,STONEBRICK:0)
Block(11,11,15,FENCE:0)
Block(12,11,15,STONEBRICK:0)
Block(13,11,15,STONEBRICK:0)
Block(14,11,15,STONEBRICK:0)
Block(15,11,15,FENCE:0)
Block(6,12,11,FENCE:0)
Block(7,12,11,STONE_BUTTON:4)
Block(11,12,11,STONE_BRICK_STAIRS:6)
Block(12,12,11,STONE_SLAB:13)
Block(13,12,11,STONE_SLAB:13)
Block(14,12,11,STONE_SLAB:13)
Block(15,12,11,STONE_BRICK_STAIRS:6)
Block(6,12,12,STONE_BUTTON:2)
Block(7,12,12,LOG_2:1)
Block(8,12,12,TRAPDOOR:12)
Block(11,12,12,LOG:1)
Block(12,12,12,LOG_2:5)
Block(13,12,12,LOG_2:5)
Block(14,12,12,LOG_2:5)
Block(15,12,12,LOG:1)
Block(7,12,13,TRAPDOOR:14)
Block(8,12,13,LOG:1)
Block(9,12,13,OAK_STAIRS:2)
Block(10,12,13,OAK_STAIRS:2)
Block(11,12,13,LOG_2:9)
Block(12,12,13,WOODEN_SLAB:10)
Block(13,12,13,WOODEN_SLAB:10)
Block(14,12,13,WOODEN_SLAB:10)
Block(15,12,13,LOG_2:9)
Block(8,12,14,OAK_STAIRS:0)
Block(9,12,14,LOG:1)
Block(10,12,14,OAK_STAIRS:7)
Block(11,12,14,LOG_2:9)
Block(12,12,14,WOODEN_SLAB:10)
Block(13,12,14,WOODEN_SLAB:10)
Block(14,12,14,WOODEN_SLAB:10)
Block(15,12,14,LOG_2:9)
Block(8,12,15,OAK_STAIRS:0)
Block(9,12,15,OAK_STAIRS:5)
Block(10,12,15,STONE_SLAB:8)
Block(11,12,15,LOG_2:9)
Block(12,12,15,STONE_SLAB:8)
Block(13,12,15,WOODEN_SLAB:10)
Block(14,12,15,STONE_SLAB:8)
Block(15,12,15,LOG_2:9)
Block(11,13,11,STONE_BRICK_STAIRS:6)
Block(12,13,11,COBBLESTONE_WALL:0)
Block(13,13,11,STONE_BUTTON:4)
Block(14,13,11,COBBLESTONE_WALL:0)
Block(15,13,11,STONE_BRICK_STAIRS:6)
Block(7,13,12,FENCE:0)
Block(8,13,12,STONE_BUTTON:4)
Block(11,13,12,LOG:1)
Block(12,13,12,MONSTER_EGG:2)
Block(13,13,12,STONEBRICK:3)
Block(14,13,12,MONSTER_EGG:2)
Block(15,13,12,LOG:1)
Block(7,13,13,STONE_BUTTON:2)
Block(8,13,13,LOG_2:1)
Block(9,13,13,TRAPDOOR:0)
Block(11,13,13,SPRUCE_DOOR:2)
Block(13,13,13,DARK_OAK_FENCE:0)
Block(14,13,13,WALL_SIGN:4)
Block(15,13,13,OAK_STAIRS:3)
Block(8,13,14,TRAPDOOR:6)
Block(9,13,14,LOG_2:1)
Block(10,13,14,TRAPDOOR:7)
Block(11,13,14,LOG:1)
Block(15,13,14,FENCE:0)
Block(9,13,15,TRAPDOOR:5)
Block(11,13,15,BIRCH_STAIRS:0)
Block(12,13,15,CRAFTING_TABLE:0)
Block(14,13,15,WALL_SIGN:4)
Block(15,13,15,OAK_STAIRS:2)
Block(11,14,11,STONE_SLAB:5)
Block(12,14,11,STONE_SLAB:13)
Block(14,14,11,STONE_SLAB:13)
Block(15,14,11,STONE_SLAB:5)
Block(7,14,12,WOODEN_SLAB:1)
Block(8,14,12,WOODEN_SLAB:9)
Block(10,14,12,WOODEN_SLAB:9)
Block(11,14,12,LOG:1)
Block(12,14,12,MONSTER_EGG:1)
Block(13,14,12,STAINED_GLASS_PANE:0)
Block(14,14,12,MONSTER_EGG:1)
Block(15,14,12,LOG:1)
Block(7,14,13,WOODEN_SLAB:9)
Block(8,14,13,FENCE:0)
Block(9,14,13,STONE_BUTTON:4)
Block(11,14,13,SPRUCE_DOOR:8)
Block(13,14,13,TORCH:5)
Block(8,14,14,STONE_BUTTON:2)
Block(9,14,14,LOG_2:1)
Block(11,14,14,LOG:1)
Block(15,14,14,CARPET:15)
Block(11,14,15,STAINED_GLASS_PANE:10)
Block(12,14,15,FLOWER_POT:0)
Block(11,15,11,TRAPDOOR:4)
Block(13,15,11,STONE_SLAB:5)
Block(15,15,11,TRAPDOOR:4)
Block(9,15,12,WOODEN_SLAB:1)
Block(10,15,12,TRAPDOOR:6)
Block(11,15,12,LOG:1)
Block(12,15,12,STONE_STAIRS:2)
Block(13,15,12,STONE_STAIRS:2)
Block(14,15,12,STONE_STAIRS:2)
Block(15,15,12,LOG:1)
Block(8,15,13,WOODEN_SLAB:1)
Block(9,15,13,WOODEN_SLAB:9)
Block(10,15,13,WOODEN_SLAB:1)
Block(11,15,13,BIRCH_STAIRS:4)
Block(7,15,14,WOODEN_SLAB:1)
Block(8,15,14,WOODEN_SLAB:9)
Block(9,15,14,FENCE:0)
Block(10,15,14,WOODEN_SLAB:9)
Block(11,15,14,LOG:1)
Block(7,15,15,DOUBLE_WOODEN_SLAB:1)
Block(8,15,15,WOODEN_SLAB:9)
Block(9,15,15,WOODEN_SLAB:9)
Block(10,15,15,WOODEN_SLAB:9)
Block(11,15,15,BIRCH_STAIRS:4)
Block(11,16,10,SPRUCE_STAIRS:2)
Block(12,16,10,SPRUCE_STAIRS:0)
Block(13,16,10,SPRUCE_STAIRS:5)
Block(10,16,11,SPRUCE_STAIRS:4)
Block(11,16,11,LOG_2:9)
Block(12,16,11,STONE_BUTTON:4)
Block(13,16,11,STONE_BUTTON:4)
Block(14,16,11,STONE_BUTTON:4)
Block(15,16,11,STONE_BRICK_STAIRS:6)
Block(10,16,12,LOG_2:5)
Block(11,16,12,LOG:1)
Block(12,16,12,LOG_2:5)
Block(13,16,12,LOG_2:5)
Block(14,16,12,LOG_2:5)
Block(15,16,12,LOG:1)
Block(10,16,13,STONE_BUTTON:2)
Block(11,16,13,LOG_2:9)
Block(12,16,13,WOODEN_SLAB:10)
Block(13,16,13,WOODEN_SLAB:10)
Block(14,16,13,WOODEN_SLAB:10)
Block(15,16,13,LOG_2:9)
Block(9,16,14,WOODEN_SLAB:1)
Block(10,16,14,STONE_BUTTON:2)
Block(11,16,14,LOG_2:9)
Block(12,16,14,WOODEN_SLAB:10)
Block(13,16,14,WOODEN_SLAB:10)
Block(14,16,14,WOODEN_SLAB:10)
Block(15,16,14,LOG_2:9)
Block(7,16,15,LOG_2:9)
Block(8,16,15,STONE_SLAB:13)
Block(9,16,15,STONE_SLAB:5)
Block(10,16,15,STONE_SLAB:13)
Block(11,16,15,LOG_2:9)
Block(12,16,15,WOODEN_SLAB:10)
Block(13,16,15,WOODEN_SLAB:10)
Block(14,16,15,WOODEN_SLAB:10)
Block(15,16,15,LOG_2:9)
Block(13,17,10,SPRUCE_STAIRS:0)
Block(14,17,10,SPRUCE_STAIRS:2)
Block(15,17,10,SPRUCE_STAIRS:2)
Block(10,17,11,SPRUCE_STAIRS:2)
Block(11,17,11,OAK_STAIRS:2)
Block(12,17,11,OAK_STAIRS:0)
Block(13,17,11,PLANKS:0)
Block(14,17,11,PLANKS:0)
Block(15,17,11,PLANKS:0)
Block(10,17,12,SPRUCE_STAIRS:7)
Block(11,17,12,LOG:1)
Block(12,17,12,HAY_BLOCK:4)
Block(13,17,12,HAY_BLOCK:0)
Block(14,17,12,HAY_BLOCK:8)
Block(15,17,12,LOG:1)
Block(11,17,13,SPRUCE_STAIRS:0)
Block(12,17,13,HAY_BLOCK:4)
Block(13,17,13,HAY_BLOCK:8)
Block(14,17,13,HAY_BLOCK:0)
Block(15,17,13,DARK_OAK_FENCE:0)
Block(11,17,14,SPRUCE_STAIRS:0)
Block(12,17,14,WEB:0)
Block(7,17,15,STONE_BUTTON:4)
Block(11,17,15,SPRUCE_STAIRS:0)
Block(12,17,15,DARK_OAK_FENCE:0)
Block(13,18,11,OAK_STAIRS:0)
Block(14,18,11,OAK_STAIRS:2)
Block(15,18,11,OAK_STAIRS:2)
Block(10,18,12,SPRUCE_STAIRS:2)
Block(11,18,12,OAK_STAIRS:2)
Block(12,18,12,OAK_STAIRS:0)
Block(13,18,12,OAK_STAIRS:5)
Block(14,18,12,HAY_BLOCK:8)
Block(15,18,12,LOG:1)
Block(9,18,13,SPRUCE_STAIRS:4)
Block(10,18,13,SPRUCE_STAIRS:7)
Block(11,18,13,LOG:1)
Block(12,18,13,WEB:0)
Block(13,18,13,HAY_BLOCK:4)
Block(14,18,13,HAY_BLOCK:0)
Block(15,18,13,TORCH:5)
Block(11,18,14,SPRUCE_STAIRS:4)
Block(11,18,15,PLANKS:1)
Block(12,18,15,TORCH:5)
Block(13,19,12,OAK_STAIRS:0)
Block(14,19,12,OAK_STAIRS:2)
Block(15,19,12,OAK_STAIRS:2)
Block(9,19,13,PLANKS:1)
Block(10,19,13,PLANKS:0)
Block(11,19,13,PLANKS:0)
Block(12,19,13,PLANKS:0)
Block(13,19,13,OAK_STAIRS:5)
Block(14,19,13,WOODEN_SLAB:9)
Block(15,19,13,LOG:1)
Block(10,19,14,STONE_BUTTON:2)
Block(11,19,14,LOG:1)
Block(12,19,14,WOODEN_SLAB:10)
Block(13,19,14,WOODEN_SLAB:10)
Block(14,19,14,WOODEN_SLAB:10)
Block(15,19,14,LOG_2:9)
Block(8,19,15,TRAPDOOR:4)
Block(11,19,15,PLANKS:1)
Block(12,19,15,WOODEN_SLAB:10)
Block(13,19,15,WOODEN_SLAB:10)
Block(14,19,15,WOODEN_SLAB:10)
Block(15,19,15,LOG_2:9)
Block(9,20,13,SPRUCE_STAIRS:2)
Block(10,20,13,OAK_STAIRS:2)
Block(11,20,13,OAK_STAIRS:2)
Block(12,20,13,OAK_STAIRS:0)
Block(13,20,13,PLANKS:1)
Block(14,20,13,SPRUCE_STAIRS:1)
Block(15,20,13,WOODEN_SLAB:1)
Block(8,20,14,SPRUCE_STAIRS:4)
Block(9,20,14,SPRUCE_STAIRS:7)
Block(10,20,14,STONE_BUTTON:2)
Block(11,20,14,LOG:1)
Block(12,20,14,PLANKS:0)
Block(13,20,14,PLANKS:0)
Block(14,20,14,PLANKS:5)
Block(15,20,14,PLANKS:5)
Block(11,20,15,SPRUCE_STAIRS:4)
Block(13,21,13,WOODEN_SLAB:1)
Block(14,21,13,WOODEN_SLAB:9)
Block(8,21,14,SPRUCE_STAIRS:2)
Block(9,21,14,OAK_STAIRS:2)
Block(10,21,14,OAK_STAIRS:2)
Block(11,21,14,OAK_STAIRS:2)
Block(12,21,14,OAK_STAIRS:0)
Block(13,21,14,OAK_STAIRS:5)
Block(14,21,14,PLANKS:5)
Block(15,21,14,STAINED_GLASS_PANE:0)
Block(7,21,15,SPRUCE_STAIRS:4)
Block(8,21,15,SPRUCE_STAIRS:7)
Block(10,21,15,STONE_BUTTON:2)
Block(11,21,15,LOG:1)
Block(15,22,13,WOODEN_SLAB:1)
Block(13,22,14,OAK_STAIRS:0)
Block(14,22,14,OAK_STAIRS:2)
Block(15,22,14,OAK_STAIRS:2)
Block(7,22,15,SPRUCE_STAIRS:2)
Block(8,22,15,OAK_STAIRS:2)
Block(9,22,15,OAK_STAIRS:2)
Block(10,22,15,OAK_STAIRS:2)
Block(11,22,15,OAK_STAIRS:2)
Block(12,22,15,OAK_STAIRS:0)
Block(13,22,15,OAK_STAIRS:5)
Block(15,22,15,LOG:1)
Block(13,23,15,OAK_STAIRS:0)
Block(14,23,15,OAK_STAIRS:2)
Block(15,23,15,OAK_STAIRS:2)

