Author: NLBlackEagle
Description: No description given
SettingsMode: WriteDisable
Frequency: 0
SpawnHeight: highestBlock
UseCenterForHighestBlock: true
MinHeight: 0
MaxHeight: 255
InheritBO3: 
InheritBO3Rotation: NORTH
OverrideChildSettings: true
OverrideParentHeight: false
CanOverride: true
BranchFrequency: 0
BranchFrequencyGroup: 
MustBeBelowOther: false
MustBeInside: 
CannotBeInside: 
ReplacesBO3: 
MustBeInsideWorldBorders: false
CanSpawnOnWater: true
SpawnOnWaterOnly: false
SpawnUnderWater: false
SpawnAtWaterLevel: false
HeightOffset: 0
RemoveAir: false
ReplaceAbove: 
ReplaceBelow: 
ReplaceWithBiomeBlocks: false
ReplaceWithSurfaceBlock: GRASS
ReplaceWithGroundBlock: DIRT
ReplaceWithStoneBlock: STONE
SmoothRadius: 0
SmoothHeightOffset: 0
SmoothStartTop: false
SmoothStartWood: false
SmoothingSurfaceBlock: 
SmoothingGroundBlock: 
BO3Group: 
IsSpawnPoint: false
DoReplaceBlocks: false
Block(-7,0,-6,CONCRETE:15)
Block(-7,0,-4,CONCRETE:15)
RandomBlock(-7,0,-2,CONCRETE:7,70,STAINED_CLAY:12,15,STAINED_CLAY:15,5,CONCRETE:7,100)
RandomBlock(-7,0,-1,CONCRETE:7,70,STAINED_CLAY:12,15,STAINED_CLAY:15,5,CONCRETE:7,100)
RandomBlock(-7,0,0,CONCRETE:7,70,STAINED_CLAY:12,15,STAINED_CLAY:15,5,CONCRETE:7,100)
RandomBlock(-7,0,1,CONCRETE:7,70,STAINED_CLAY:12,15,STAINED_CLAY:15,5,CONCRETE:7,100)
RandomBlock(-7,0,2,CONCRETE:7,70,STAINED_CLAY:12,15,STAINED_CLAY:15,5,CONCRETE:7,100)
RandomBlock(-7,0,3,CONCRETE:7,70,STAINED_CLAY:12,15,STAINED_CLAY:15,5,CONCRETE:7,100)
Block(-7,0,5,CONCRETE:15)
Block(-7,0,7,CONCRETE:15)
Block(-7,11,-6,CONCRETE:15)
Block(-7,11,-4,CONCRETE:15)
RandomBlock(-7,11,-2,CONCRETE:7,70,STAINED_CLAY:12,15,STAINED_CLAY:15,5,CONCRETE:7,100)
RandomBlock(-7,11,-1,CONCRETE:7,70,STAINED_CLAY:12,15,STAINED_CLAY:15,5,CONCRETE:7,100)
RandomBlock(-7,11,0,CONCRETE:7,70,STAINED_CLAY:12,15,STAINED_CLAY:15,5,CONCRETE:7,100)
RandomBlock(-7,11,1,CONCRETE:7,70,STAINED_CLAY:12,15,STAINED_CLAY:15,5,CONCRETE:7,100)
RandomBlock(-7,11,2,CONCRETE:7,70,STAINED_CLAY:12,15,STAINED_CLAY:15,5,CONCRETE:7,100)
RandomBlock(-7,11,3,CONCRETE:7,70,STAINED_CLAY:12,15,STAINED_CLAY:15,5,CONCRETE:7,100)
Block(-7,11,5,CONCRETE:15)
Block(-7,11,7,CONCRETE:15)
Block(-7,12,-6,CONCRETE:15)
Block(-7,12,-4,CONCRETE:15)
RandomBlock(-7,12,-2,CONCRETE:7,70,STAINED_CLAY:12,15,STAINED_CLAY:15,5,CONCRETE:7,100)
RandomBlock(-7,12,-1,CONCRETE:7,70,STAINED_CLAY:12,15,STAINED_CLAY:15,5,CONCRETE:7,100)
RandomBlock(-7,12,0,CONCRETE:7,70,STAINED_CLAY:12,15,STAINED_CLAY:15,5,CONCRETE:7,100)
RandomBlock(-7,12,1,CONCRETE:7,70,STAINED_CLAY:12,15,STAINED_CLAY:15,5,CONCRETE:7,100)
RandomBlock(-7,12,2,CONCRETE:7,70,STAINED_CLAY:12,15,STAINED_CLAY:15,5,CONCRETE:7,100)
RandomBlock(-7,12,3,CONCRETE:7,70,STAINED_CLAY:12,15,STAINED_CLAY:15,5,CONCRETE:7,100)
Block(-7,12,5,CONCRETE:15)
Block(-7,12,7,CONCRETE:15)
Block(-7,13,-6,CONCRETE:15)
Block(-7,13,-4,CONCRETE:15)
RandomBlock(-7,13,-2,CONCRETE:7,70,STAINED_CLAY:12,15,STAINED_CLAY:15,5,CONCRETE:7,100)
RandomBlock(-7,13,-1,CONCRETE:7,70,STAINED_CLAY:12,15,STAINED_CLAY:15,5,CONCRETE:7,100)
RandomBlock(-7,13,0,CONCRETE:7,70,STAINED_CLAY:12,15,STAINED_CLAY:15,5,CONCRETE:7,100)
RandomBlock(-7,13,1,CONCRETE:7,70,STAINED_CLAY:12,15,STAINED_CLAY:15,5,CONCRETE:7,100)
RandomBlock(-7,13,2,CONCRETE:7,70,STAINED_CLAY:12,15,STAINED_CLAY:15,5,CONCRETE:7,100)
RandomBlock(-7,13,3,CONCRETE:7,70,STAINED_CLAY:12,15,STAINED_CLAY:15,5,CONCRETE:7,100)
Block(-7,13,5,CONCRETE:15)
Block(-7,13,7,CONCRETE:15)
Block(-7,14,-6,CONCRETE:15)
Block(-7,14,-4,CONCRETE:15)
RandomBlock(-7,14,-2,CONCRETE:7,70,STAINED_CLAY:12,15,STAINED_CLAY:15,5,CONCRETE:7,100)
RandomBlock(-7,14,-1,CONCRETE:7,70,STAINED_CLAY:12,15,STAINED_CLAY:15,5,CONCRETE:7,100)
RandomBlock(-7,14,0,CONCRETE:7,70,STAINED_CLAY:12,15,STAINED_CLAY:15,5,CONCRETE:7,100)
RandomBlock(-7,14,1,CONCRETE:7,70,STAINED_CLAY:12,15,STAINED_CLAY:15,5,CONCRETE:7,100)
RandomBlock(-7,14,2,CONCRETE:7,70,STAINED_CLAY:12,15,STAINED_CLAY:15,5,CONCRETE:7,100)
RandomBlock(-7,14,3,CONCRETE:7,70,STAINED_CLAY:12,15,STAINED_CLAY:15,5,CONCRETE:7,100)
Block(-7,14,5,CONCRETE:15)
Block(-7,14,7,CONCRETE:15)
RandomBlock(-7,15,-7,CONCRETE:7,70,STAINED_CLAY:12,15,STAINED_CLAY:15,5,CONCRETE:7,100)
RandomBlock(-7,15,-6,CONCRETE:7,70,STAINED_CLAY:12,15,STAINED_CLAY:15,5,CONCRETE:7,100)
RandomBlock(-7,15,-5,CONCRETE:7,70,STAINED_CLAY:12,15,STAINED_CLAY:15,5,CONCRETE:7,100)
RandomBlock(-7,15,-4,CONCRETE:7,70,STAINED_CLAY:12,15,STAINED_CLAY:15,5,CONCRETE:7,100)
RandomBlock(-7,15,-3,CONCRETE:7,70,STAINED_CLAY:12,15,STAINED_CLAY:15,5,CONCRETE:7,100)
RandomBlock(-7,15,-2,CONCRETE:7,70,STAINED_CLAY:12,15,STAINED_CLAY:15,5,CONCRETE:7,100)
RandomBlock(-7,15,-1,CONCRETE:7,70,STAINED_CLAY:12,15,STAINED_CLAY:15,5,CONCRETE:7,100)
RandomBlock(-7,15,0,CONCRETE:7,70,STAINED_CLAY:12,15,STAINED_CLAY:15,5,CONCRETE:7,100)
RandomBlock(-7,15,1,CONCRETE:7,70,STAINED_CLAY:12,15,STAINED_CLAY:15,5,CONCRETE:7,100)
RandomBlock(-7,15,2,CONCRETE:7,70,STAINED_CLAY:12,15,STAINED_CLAY:15,5,CONCRETE:7,100)
RandomBlock(-7,15,3,CONCRETE:7,70,STAINED_CLAY:12,15,STAINED_CLAY:15,5,CONCRETE:7,100)
RandomBlock(-7,15,4,CONCRETE:7,70,STAINED_CLAY:12,15,STAINED_CLAY:15,5,CONCRETE:7,100)
RandomBlock(-7,15,5,CONCRETE:7,70,STAINED_CLAY:12,15,STAINED_CLAY:15,5,CONCRETE:7,100)
RandomBlock(-7,15,6,CONCRETE:7,70,STAINED_CLAY:12,15,STAINED_CLAY:15,5,CONCRETE:7,100)
RandomBlock(-7,15,7,CONCRETE:7,70,STAINED_CLAY:12,15,STAINED_CLAY:15,5,CONCRETE:7,100)
RandomBlock(-7,15,8,CONCRETE:7,70,STAINED_CLAY:12,15,STAINED_CLAY:15,5,CONCRETE:7,100)
RandomBlock(-7,16,-6,CONCRETE:7,70,STAINED_CLAY:12,15,STAINED_CLAY:15,5,CONCRETE:7,100)
RandomBlock(-7,16,-4,CONCRETE:7,70,STAINED_CLAY:12,15,STAINED_CLAY:15,5,CONCRETE:7,100)
RandomBlock(-7,16,-2,CONCRETE:7,70,STAINED_CLAY:12,15,STAINED_CLAY:15,5,CONCRETE:7,100)
RandomBlock(-7,16,0,CONCRETE:7,70,STAINED_CLAY:12,15,STAINED_CLAY:15,5,CONCRETE:7,100)
RandomBlock(-7,16,1,CONCRETE:7,70,STAINED_CLAY:12,15,STAINED_CLAY:15,5,CONCRETE:7,100)
RandomBlock(-7,16,3,CONCRETE:7,70,STAINED_CLAY:12,15,STAINED_CLAY:15,5,CONCRETE:7,100)
RandomBlock(-7,16,5,CONCRETE:7,70,STAINED_CLAY:12,15,STAINED_CLAY:15,5,CONCRETE:7,100)
RandomBlock(-7,16,7,CONCRETE:7,70,STAINED_CLAY:12,15,STAINED_CLAY:15,5,CONCRETE:7,100)
RandomBlock(-7,17,-6,CONCRETE:7,70,STAINED_CLAY:12,15,STAINED_CLAY:15,5,CONCRETE:7,100)
RandomBlock(-7,17,-4,CONCRETE:7,70,STAINED_CLAY:12,15,STAINED_CLAY:15,5,CONCRETE:7,100)
RandomBlock(-7,17,-2,CONCRETE:7,70,STAINED_CLAY:12,15,STAINED_CLAY:15,5,CONCRETE:7,100)
RandomBlock(-7,17,0,CONCRETE:7,70,STAINED_CLAY:12,15,STAINED_CLAY:15,5,CONCRETE:7,100)
RandomBlock(-7,17,1,CONCRETE:7,70,STAINED_CLAY:12,15,STAINED_CLAY:15,5,CONCRETE:7,100)
RandomBlock(-7,17,3,CONCRETE:7,70,STAINED_CLAY:12,15,STAINED_CLAY:15,5,CONCRETE:7,100)
RandomBlock(-7,17,5,CONCRETE:7,70,STAINED_CLAY:12,15,STAINED_CLAY:15,5,CONCRETE:7,100)
RandomBlock(-7,17,7,CONCRETE:7,70,STAINED_CLAY:12,15,STAINED_CLAY:15,5,CONCRETE:7,100)
Block(-7,18,-7,STONE_BUTTON:2)
RandomBlock(-7,18,-6,CONCRETE:7,70,STAINED_CLAY:12,15,STAINED_CLAY:15,5,CONCRETE:7,100)
Block(-7,18,-5,STONE_BUTTON:2)
RandomBlock(-7,18,-4,CONCRETE:7,70,STAINED_CLAY:12,15,STAINED_CLAY:15,5,CONCRETE:7,100)
Block(-7,18,-3,STONE_BUTTON:2)
RandomBlock(-7,18,-2,CONCRETE:7,70,STAINED_CLAY:12,15,STAINED_CLAY:15,5,CONCRETE:7,100)
Block(-7,18,-1,STONE_BUTTON:2)
RandomBlock(-7,18,0,CONCRETE:7,70,STAINED_CLAY:12,15,STAINED_CLAY:15,5,CONCRETE:7,100)
RandomBlock(-7,18,1,CONCRETE:7,70,STAINED_CLAY:12,15,STAINED_CLAY:15,5,CONCRETE:7,100)
Block(-7,18,2,STONE_BUTTON:2)
RandomBlock(-7,18,3,CONCRETE:7,70,STAINED_CLAY:12,15,STAINED_CLAY:15,5,CONCRETE:7,100)
Block(-7,18,4,STONE_BUTTON:2)
RandomBlock(-7,18,5,CONCRETE:7,70,STAINED_CLAY:12,15,STAINED_CLAY:15,5,CONCRETE:7,100)
Block(-7,18,6,STONE_BUTTON:2)
RandomBlock(-7,18,7,CONCRETE:7,70,STAINED_CLAY:12,15,STAINED_CLAY:15,5,CONCRETE:7,100)
Block(-7,18,8,STONE_BUTTON:2)
RandomBlock(-7,19,-6,CONCRETE:7,70,STAINED_CLAY:12,15,STAINED_CLAY:15,5,CONCRETE:7,100)
RandomBlock(-7,19,-4,CONCRETE:7,70,STAINED_CLAY:12,15,STAINED_CLAY:15,5,CONCRETE:7,100)
RandomBlock(-7,19,-2,CONCRETE:7,70,STAINED_CLAY:12,15,STAINED_CLAY:15,5,CONCRETE:7,100)
RandomBlock(-7,19,0,CONCRETE:7,70,STAINED_CLAY:12,15,STAINED_CLAY:15,5,CONCRETE:7,100)
RandomBlock(-7,19,1,CONCRETE:7,70,STAINED_CLAY:12,15,STAINED_CLAY:15,5,CONCRETE:7,100)
RandomBlock(-7,19,3,CONCRETE:7,70,STAINED_CLAY:12,15,STAINED_CLAY:15,5,CONCRETE:7,100)
RandomBlock(-7,19,5,CONCRETE:7,70,STAINED_CLAY:12,15,STAINED_CLAY:15,5,CONCRETE:7,100)
RandomBlock(-7,19,7,CONCRETE:7,70,STAINED_CLAY:12,15,STAINED_CLAY:15,5,CONCRETE:7,100)
RandomBlock(-7,20,-6,CONCRETE:7,70,STAINED_CLAY:12,15,STAINED_CLAY:15,5,CONCRETE:7,100)
RandomBlock(-7,20,-4,CONCRETE:7,70,STAINED_CLAY:12,15,STAINED_CLAY:15,5,CONCRETE:7,100)
RandomBlock(-7,20,-2,CONCRETE:7,70,STAINED_CLAY:12,15,STAINED_CLAY:15,5,CONCRETE:7,100)
RandomBlock(-7,20,0,CONCRETE:7,70,STAINED_CLAY:12,15,STAINED_CLAY:15,5,CONCRETE:7,100)
RandomBlock(-7,20,1,CONCRETE:7,70,STAINED_CLAY:12,15,STAINED_CLAY:15,5,CONCRETE:7,100)
RandomBlock(-7,20,3,CONCRETE:7,70,STAINED_CLAY:12,15,STAINED_CLAY:15,5,CONCRETE:7,100)
RandomBlock(-7,20,5,CONCRETE:7,70,STAINED_CLAY:12,15,STAINED_CLAY:15,5,CONCRETE:7,100)
RandomBlock(-7,20,7,CONCRETE:7,70,STAINED_CLAY:12,15,STAINED_CLAY:15,5,CONCRETE:7,100)
RandomBlock(-7,21,-6,CONCRETE:7,70,STAINED_CLAY:12,15,STAINED_CLAY:15,5,CONCRETE:7,100)
RandomBlock(-7,21,-4,CONCRETE:7,70,STAINED_CLAY:12,15,STAINED_CLAY:15,5,CONCRETE:7,100)
RandomBlock(-7,21,-2,CONCRETE:7,70,STAINED_CLAY:12,15,STAINED_CLAY:15,5,CONCRETE:7,100)
RandomBlock(-7,21,0,CONCRETE:7,70,STAINED_CLAY:12,15,STAINED_CLAY:15,5,CONCRETE:7,100)
RandomBlock(-7,21,1,CONCRETE:7,70,STAINED_CLAY:12,15,STAINED_CLAY:15,5,CONCRETE:7,100)
RandomBlock(-7,21,3,CONCRETE:7,70,STAINED_CLAY:12,15,STAINED_CLAY:15,5,CONCRETE:7,100)
RandomBlock(-7,21,5,CONCRETE:7,70,STAINED_CLAY:12,15,STAINED_CLAY:15,5,CONCRETE:7,100)
RandomBlock(-7,21,7,CONCRETE:7,70,STAINED_CLAY:12,15,STAINED_CLAY:15,5,CONCRETE:7,100)
RandomBlock(-7,22,-7,CONCRETE:7,70,STAINED_CLAY:12,15,STAINED_CLAY:15,5,CONCRETE:7,100)
RandomBlock(-7,22,-6,CONCRETE:7,70,STAINED_CLAY:12,15,STAINED_CLAY:15,5,CONCRETE:7,100)
RandomBlock(-7,22,-5,CONCRETE:7,70,STAINED_CLAY:12,15,STAINED_CLAY:15,5,CONCRETE:7,100)
RandomBlock(-7,22,-4,CONCRETE:7,70,STAINED_CLAY:12,15,STAINED_CLAY:15,5,CONCRETE:7,100)
RandomBlock(-7,22,-3,CONCRETE:7,70,STAINED_CLAY:12,15,STAINED_CLAY:15,5,CONCRETE:7,100)
RandomBlock(-7,22,-2,CONCRETE:7,70,STAINED_CLAY:12,15,STAINED_CLAY:15,5,CONCRETE:7,100)
RandomBlock(-7,22,-1,CONCRETE:7,70,STAINED_CLAY:12,15,STAINED_CLAY:15,5,CONCRETE:7,100)
RandomBlock(-7,22,0,CONCRETE:7,70,STAINED_CLAY:12,15,STAINED_CLAY:15,5,CONCRETE:7,100)
RandomBlock(-7,22,1,CONCRETE:7,70,STAINED_CLAY:12,15,STAINED_CLAY:15,5,CONCRETE:7,100)
RandomBlock(-7,22,2,CONCRETE:7,70,STAINED_CLAY:12,15,STAINED_CLAY:15,5,CONCRETE:7,100)
RandomBlock(-7,22,3,CONCRETE:7,70,STAINED_CLAY:12,15,STAINED_CLAY:15,5,CONCRETE:7,100)
RandomBlock(-7,22,4,CONCRETE:7,70,STAINED_CLAY:12,15,STAINED_CLAY:15,5,CONCRETE:7,100)
RandomBlock(-7,22,5,CONCRETE:7,70,STAINED_CLAY:12,15,STAINED_CLAY:15,5,CONCRETE:7,100)
RandomBlock(-7,22,6,CONCRETE:7,70,STAINED_CLAY:12,15,STAINED_CLAY:15,5,CONCRETE:7,100)
RandomBlock(-7,22,7,CONCRETE:7,70,STAINED_CLAY:12,15,STAINED_CLAY:15,5,CONCRETE:7,100)
RandomBlock(-7,22,8,CONCRETE:7,70,STAINED_CLAY:12,15,STAINED_CLAY:15,5,CONCRETE:7,100)
RandomBlock(-7,23,-2,CONCRETE:7,70,STAINED_CLAY:12,15,STAINED_CLAY:15,5,CONCRETE:7,100)
Block(-7,23,-1,SMOOTH_STAIRS:0)
Block(-7,23,0,SMOOTH_STAIRS:0)
Block(-7,23,1,SMOOTH_STAIRS:0)
Block(-7,23,2,SMOOTH_STAIRS:0)
RandomBlock(-7,23,3,CONCRETE:7,70,STAINED_CLAY:12,15,STAINED_CLAY:15,5,CONCRETE:7,100)
RandomBlock(-7,24,-2,CONCRETE:7,70,STAINED_CLAY:12,15,STAINED_CLAY:15,5,CONCRETE:7,100)
Block(-7,24,-1,SMOOTH_STAIRS:0)
Block(-7,24,0,SMOOTH_STAIRS:0)
Block(-7,24,1,SMOOTH_STAIRS:0)
Block(-7,24,2,SMOOTH_STAIRS:0)
RandomBlock(-7,24,3,CONCRETE:7,70,STAINED_CLAY:12,15,STAINED_CLAY:15,5,CONCRETE:7,100)
RandomBlock(-7,25,-2,CONCRETE:7,70,STAINED_CLAY:12,15,STAINED_CLAY:15,5,CONCRETE:7,100)
Block(-7,25,-1,SMOOTH_STAIRS:0)
Block(-7,25,0,SMOOTH_STAIRS:0)
Block(-7,25,1,SMOOTH_STAIRS:0)
Block(-7,25,2,SMOOTH_STAIRS:0)
RandomBlock(-7,25,3,CONCRETE:7,70,STAINED_CLAY:12,15,STAINED_CLAY:15,5,CONCRETE:7,100)
RandomBlock(-7,26,-2,CONCRETE:7,70,STAINED_CLAY:12,15,STAINED_CLAY:15,5,CONCRETE:7,100)
RandomBlock(-7,26,-1,CONCRETE:7,70,STAINED_CLAY:12,15,STAINED_CLAY:15,5,CONCRETE:7,100)
RandomBlock(-7,26,0,CONCRETE:7,70,STAINED_CLAY:12,15,STAINED_CLAY:15,5,CONCRETE:7,100)
RandomBlock(-7,26,1,CONCRETE:7,70,STAINED_CLAY:12,15,STAINED_CLAY:15,5,CONCRETE:7,100)
RandomBlock(-7,26,2,CONCRETE:7,70,STAINED_CLAY:12,15,STAINED_CLAY:15,5,CONCRETE:7,100)
RandomBlock(-7,26,3,CONCRETE:7,70,STAINED_CLAY:12,15,STAINED_CLAY:15,5,CONCRETE:7,100)
RandomBlock(-6,0,-2,CONCRETE:7,70,STAINED_CLAY:12,15,STAINED_CLAY:15,5,CONCRETE:7,100)
RandomBlock(-6,0,-1,CONCRETE:7,70,STAINED_CLAY:12,15,STAINED_CLAY:15,5,CONCRETE:7,100)
RandomBlock(-6,0,0,CONCRETE:7,70,STAINED_CLAY:12,15,STAINED_CLAY:15,5,CONCRETE:7,100)
RandomBlock(-6,0,1,CONCRETE:7,70,STAINED_CLAY:12,15,STAINED_CLAY:15,5,CONCRETE:7,100)
RandomBlock(-6,0,2,CONCRETE:7,70,STAINED_CLAY:12,15,STAINED_CLAY:15,5,CONCRETE:7,100)
RandomBlock(-6,0,3,CONCRETE:7,70,STAINED_CLAY:12,15,STAINED_CLAY:15,5,CONCRETE:7,100)
RandomBlock(-6,11,-2,CONCRETE:7,70,STAINED_CLAY:12,15,STAINED_CLAY:15,5,CONCRETE:7,100)
RandomBlock(-6,11,-1,CONCRETE:7,70,STAINED_CLAY:12,15,STAINED_CLAY:15,5,CONCRETE:7,100)
RandomBlock(-6,11,0,CONCRETE:7,70,STAINED_CLAY:12,15,STAINED_CLAY:15,5,CONCRETE:7,100)
RandomBlock(-6,11,1,CONCRETE:7,70,STAINED_CLAY:12,15,STAINED_CLAY:15,5,CONCRETE:7,100)
RandomBlock(-6,11,2,CONCRETE:7,70,STAINED_CLAY:12,15,STAINED_CLAY:15,5,CONCRETE:7,100)
RandomBlock(-6,11,3,CONCRETE:7,70,STAINED_CLAY:12,15,STAINED_CLAY:15,5,CONCRETE:7,100)
RandomBlock(-6,12,-2,CONCRETE:7,70,STAINED_CLAY:12,15,STAINED_CLAY:15,5,CONCRETE:7,100)
RandomBlock(-6,12,-1,CONCRETE:7,70,STAINED_CLAY:12,15,STAINED_CLAY:15,5,CONCRETE:7,100)
RandomBlock(-6,12,0,CONCRETE:7,70,STAINED_CLAY:12,15,STAINED_CLAY:15,5,CONCRETE:7,100)
RandomBlock(-6,12,1,CONCRETE:7,70,STAINED_CLAY:12,15,STAINED_CLAY:15,5,CONCRETE:7,100)
RandomBlock(-6,12,2,CONCRETE:7,70,STAINED_CLAY:12,15,STAINED_CLAY:15,5,CONCRETE:7,100)
RandomBlock(-6,12,3,CONCRETE:7,70,STAINED_CLAY:12,15,STAINED_CLAY:15,5,CONCRETE:7,100)
RandomBlock(-6,13,-2,CONCRETE:7,70,STAINED_CLAY:12,15,STAINED_CLAY:15,5,CONCRETE:7,100)
RandomBlock(-6,13,-1,CONCRETE:7,70,STAINED_CLAY:12,15,STAINED_CLAY:15,5,CONCRETE:7,100)
RandomBlock(-6,13,0,CONCRETE:7,70,STAINED_CLAY:12,15,STAINED_CLAY:15,5,CONCRETE:7,100)
RandomBlock(-6,13,1,CONCRETE:7,70,STAINED_CLAY:12,15,STAINED_CLAY:15,5,CONCRETE:7,100)
RandomBlock(-6,13,2,CONCRETE:7,70,STAINED_CLAY:12,15,STAINED_CLAY:15,5,CONCRETE:7,100)
RandomBlock(-6,13,3,CONCRETE:7,70,STAINED_CLAY:12,15,STAINED_CLAY:15,5,CONCRETE:7,100)
Block(-6,14,-6,CONCRETE:15)
Block(-6,14,-4,CONCRETE:15)
RandomBlock(-6,14,-2,CONCRETE:7,70,STAINED_CLAY:12,15,STAINED_CLAY:15,5,CONCRETE:7,100)
RandomBlock(-6,14,-1,CONCRETE:7,70,STAINED_CLAY:12,15,STAINED_CLAY:15,5,CONCRETE:7,100)
RandomBlock(-6,14,0,CONCRETE:7,70,STAINED_CLAY:12,15,STAINED_CLAY:15,5,CONCRETE:7,100)
RandomBlock(-6,14,1,CONCRETE:7,70,STAINED_CLAY:12,15,STAINED_CLAY:15,5,CONCRETE:7,100)
RandomBlock(-6,14,2,CONCRETE:7,70,STAINED_CLAY:12,15,STAINED_CLAY:15,5,CONCRETE:7,100)
RandomBlock(-6,14,3,CONCRETE:7,70,STAINED_CLAY:12,15,STAINED_CLAY:15,5,CONCRETE:7,100)
Block(-6,14,5,CONCRETE:15)
Block(-6,14,7,CONCRETE:15)
RandomBlock(-6,15,-7,CONCRETE:7,70,STAINED_CLAY:12,15,STAINED_CLAY:15,5,CONCRETE:7,100)
RandomBlock(-6,15,-6,CONCRETE:7,70,STAINED_CLAY:12,15,STAINED_CLAY:15,5,CONCRETE:7,100)
RandomBlock(-6,15,-5,CONCRETE:7,70,STAINED_CLAY:12,15,STAINED_CLAY:15,5,CONCRETE:7,100)
RandomBlock(-6,15,-4,CONCRETE:7,70,STAINED_CLAY:12,15,STAINED_CLAY:15,5,CONCRETE:7,100)
RandomBlock(-6,15,-3,CONCRETE:7,70,STAINED_CLAY:12,15,STAINED_CLAY:15,5,CONCRETE:7,100)
RandomBlock(-6,15,-2,CONCRETE:7,70,STAINED_CLAY:12,15,STAINED_CLAY:15,5,CONCRETE:7,100)
RandomBlock(-6,15,-1,CONCRETE:7,70,STAINED_CLAY:12,15,STAINED_CLAY:15,5,CONCRETE:7,100)
RandomBlock(-6,15,0,CONCRETE:7,70,STAINED_CLAY:12,15,STAINED_CLAY:15,5,CONCRETE:7,100)
RandomBlock(-6,15,1,CONCRETE:7,70,STAINED_CLAY:12,15,STAINED_CLAY:15,5,CONCRETE:7,100)
RandomBlock(-6,15,2,CONCRETE:7,70,STAINED_CLAY:12,15,STAINED_CLAY:15,5,CONCRETE:7,100)
RandomBlock(-6,15,3,CONCRETE:7,70,STAINED_CLAY:12,15,STAINED_CLAY:15,5,CONCRETE:7,100)
RandomBlock(-6,15,4,CONCRETE:7,70,STAINED_CLAY:12,15,STAINED_CLAY:15,5,CONCRETE:7,100)
RandomBlock(-6,15,5,CONCRETE:7,70,STAINED_CLAY:12,15,STAINED_CLAY:15,5,CONCRETE:7,100)
RandomBlock(-6,15,6,CONCRETE:7,70,STAINED_CLAY:12,15,STAINED_CLAY:15,5,CONCRETE:7,100)
RandomBlock(-6,15,7,CONCRETE:7,70,STAINED_CLAY:12,15,STAINED_CLAY:15,5,CONCRETE:7,100)
RandomBlock(-6,15,8,CONCRETE:7,70,STAINED_CLAY:12,15,STAINED_CLAY:15,5,CONCRETE:7,100)
RandomBlock(-6,16,-7,CONCRETE:7,70,STAINED_CLAY:12,15,STAINED_CLAY:15,5,CONCRETE:7,100)
RandomBlock(-6,16,-6,CONCRETE:7,70,STAINED_CLAY:12,15,STAINED_CLAY:15,5,CONCRETE:7,100)
RandomBlock(-6,16,-5,CONCRETE:7,70,STAINED_CLAY:12,15,STAINED_CLAY:15,5,CONCRETE:7,100)
RandomBlock(-6,16,-4,CONCRETE:7,70,STAINED_CLAY:12,15,STAINED_CLAY:15,5,CONCRETE:7,100)
RandomBlock(-6,16,-3,CONCRETE:7,70,STAINED_CLAY:12,15,STAINED_CLAY:15,5,CONCRETE:7,100)
RandomBlock(-6,16,-2,CONCRETE:7,70,STAINED_CLAY:12,15,STAINED_CLAY:15,5,CONCRETE:7,100)
RandomBlock(-6,16,-1,CONCRETE:7,70,STAINED_CLAY:12,15,STAINED_CLAY:15,5,CONCRETE:7,100)
RandomBlock(-6,16,0,CONCRETE:7,70,STAINED_CLAY:12,15,STAINED_CLAY:15,5,CONCRETE:7,100)
RandomBlock(-6,16,1,CONCRETE:7,70,STAINED_CLAY:12,15,STAINED_CLAY:15,5,CONCRETE:7,100)
RandomBlock(-6,16,2,CONCRETE:7,70,STAINED_CLAY:12,15,STAINED_CLAY:15,5,CONCRETE:7,100)
RandomBlock(-6,16,3,CONCRETE:7,70,STAINED_CLAY:12,15,STAINED_CLAY:15,5,CONCRETE:7,100)
RandomBlock(-6,16,4,CONCRETE:7,70,STAINED_CLAY:12,15,STAINED_CLAY:15,5,CONCRETE:7,100)
RandomBlock(-6,16,5,CONCRETE:7,70,STAINED_CLAY:12,15,STAINED_CLAY:15,5,CONCRETE:7,100)
RandomBlock(-6,16,6,CONCRETE:7,70,STAINED_CLAY:12,15,STAINED_CLAY:15,5,CONCRETE:7,100)
RandomBlock(-6,16,7,CONCRETE:7,70,STAINED_CLAY:12,15,STAINED_CLAY:15,5,CONCRETE:7,100)
RandomBlock(-6,16,8,CONCRETE:7,70,STAINED_CLAY:12,15,STAINED_CLAY:15,5,CONCRETE:7,100)
RandomBlock(-6,17,-7,CONCRETE:7,70,STAINED_CLAY:12,15,STAINED_CLAY:15,5,CONCRETE:7,100)
RandomBlock(-6,17,-6,CONCRETE:7,70,STAINED_CLAY:12,15,STAINED_CLAY:15,5,CONCRETE:7,100)
RandomBlock(-6,17,-5,CONCRETE:7,70,STAINED_CLAY:12,15,STAINED_CLAY:15,5,CONCRETE:7,100)
RandomBlock(-6,17,-4,CONCRETE:7,70,STAINED_CLAY:12,15,STAINED_CLAY:15,5,CONCRETE:7,100)
RandomBlock(-6,17,-3,CONCRETE:7,70,STAINED_CLAY:12,15,STAINED_CLAY:15,5,CONCRETE:7,100)
RandomBlock(-6,17,-2,CONCRETE:7,70,STAINED_CLAY:12,15,STAINED_CLAY:15,5,CONCRETE:7,100)
RandomBlock(-6,17,-1,CONCRETE:7,70,STAINED_CLAY:12,15,STAINED_CLAY:15,5,CONCRETE:7,100)
RandomBlock(-6,17,0,CONCRETE:7,70,STAINED_CLAY:12,15,STAINED_CLAY:15,5,CONCRETE:7,100)
RandomBlock(-6,17,1,CONCRETE:7,70,STAINED_CLAY:12,15,STAINED_CLAY:15,5,CONCRETE:7,100)
RandomBlock(-6,17,2,CONCRETE:7,70,STAINED_CLAY:12,15,STAINED_CLAY:15,5,CONCRETE:7,100)
RandomBlock(-6,17,3,CONCRETE:7,70,STAINED_CLAY:12,15,STAINED_CLAY:15,5,CONCRETE:7,100)
RandomBlock(-6,17,4,CONCRETE:7,70,STAINED_CLAY:12,15,STAINED_CLAY:15,5,CONCRETE:7,100)
RandomBlock(-6,17,5,CONCRETE:7,70,STAINED_CLAY:12,15,STAINED_CLAY:15,5,CONCRETE:7,100)
RandomBlock(-6,17,6,CONCRETE:7,70,STAINED_CLAY:12,15,STAINED_CLAY:15,5,CONCRETE:7,100)
RandomBlock(-6,17,7,CONCRETE:7,70,STAINED_CLAY:12,15,STAINED_CLAY:15,5,CONCRETE:7,100)
RandomBlock(-6,17,8,CONCRETE:7,70,STAINED_CLAY:12,15,STAINED_CLAY:15,5,CONCRETE:7,100)
RandomBlock(-6,18,-7,CONCRETE:7,70,STAINED_CLAY:12,15,STAINED_CLAY:15,5,CONCRETE:7,100)
RandomBlock(-6,18,-6,CONCRETE:7,70,STAINED_CLAY:12,15,STAINED_CLAY:15,5,CONCRETE:7,100)
RandomBlock(-6,18,-5,CONCRETE:7,70,STAINED_CLAY:12,15,STAINED_CLAY:15,5,CONCRETE:7,100)
RandomBlock(-6,18,-4,CONCRETE:7,70,STAINED_CLAY:12,15,STAINED_CLAY:15,5,CONCRETE:7,100)
RandomBlock(-6,18,-3,CONCRETE:7,70,STAINED_CLAY:12,15,STAINED_CLAY:15,5,CONCRETE:7,100)
RandomBlock(-6,18,-2,CONCRETE:7,70,STAINED_CLAY:12,15,STAINED_CLAY:15,5,CONCRETE:7,100)
RandomBlock(-6,18,-1,CONCRETE:7,70,STAINED_CLAY:12,15,STAINED_CLAY:15,5,CONCRETE:7,100)
RandomBlock(-6,18,0,CONCRETE:7,70,STAINED_CLAY:12,15,STAINED_CLAY:15,5,CONCRETE:7,100)
RandomBlock(-6,18,1,CONCRETE:7,70,STAINED_CLAY:12,15,STAINED_CLAY:15,5,CONCRETE:7,100)
RandomBlock(-6,18,2,CONCRETE:7,70,STAINED_CLAY:12,15,STAINED_CLAY:15,5,CONCRETE:7,100)
RandomBlock(-6,18,3,CONCRETE:7,70,STAINED_CLAY:12,15,STAINED_CLAY:15,5,CONCRETE:7,100)
RandomBlock(-6,18,4,CONCRETE:7,70,STAINED_CLAY:12,15,STAINED_CLAY:15,5,CONCRETE:7,100)
RandomBlock(-6,18,5,CONCRETE:7,70,STAINED_CLAY:12,15,STAINED_CLAY:15,5,CONCRETE:7,100)
RandomBlock(-6,18,6,CONCRETE:7,70,STAINED_CLAY:12,15,STAINED_CLAY:15,5,CONCRETE:7,100)
RandomBlock(-6,18,7,CONCRETE:7,70,STAINED_CLAY:12,15,STAINED_CLAY:15,5,CONCRETE:7,100)
RandomBlock(-6,18,8,CONCRETE:7,70,STAINED_CLAY:12,15,STAINED_CLAY:15,5,CONCRETE:7,100)
RandomBlock(-6,19,-7,CONCRETE:7,70,STAINED_CLAY:12,15,STAINED_CLAY:15,5,CONCRETE:7,100)
RandomBlock(-6,19,-6,CONCRETE:7,70,STAINED_CLAY:12,15,STAINED_CLAY:15,5,CONCRETE:7,100)
RandomBlock(-6,19,-5,CONCRETE:7,70,STAINED_CLAY:12,15,STAINED_CLAY:15,5,CONCRETE:7,100)
RandomBlock(-6,19,-4,CONCRETE:7,70,STAINED_CLAY:12,15,STAINED_CLAY:15,5,CONCRETE:7,100)
RandomBlock(-6,19,-3,CONCRETE:7,70,STAINED_CLAY:12,15,STAINED_CLAY:15,5,CONCRETE:7,100)
RandomBlock(-6,19,-2,CONCRETE:7,70,STAINED_CLAY:12,15,STAINED_CLAY:15,5,CONCRETE:7,100)
RandomBlock(-6,19,-1,CONCRETE:7,70,STAINED_CLAY:12,15,STAINED_CLAY:15,5,CONCRETE:7,100)
RandomBlock(-6,19,0,CONCRETE:7,70,STAINED_CLAY:12,15,STAINED_CLAY:15,5,CONCRETE:7,100)
RandomBlock(-6,19,1,CONCRETE:7,70,STAINED_CLAY:12,15,STAINED_CLAY:15,5,CONCRETE:7,100)
RandomBlock(-6,19,2,CONCRETE:7,70,STAINED_CLAY:12,15,STAINED_CLAY:15,5,CONCRETE:7,100)
RandomBlock(-6,19,3,CONCRETE:7,70,STAINED_CLAY:12,15,STAINED_CLAY:15,5,CONCRETE:7,100)
RandomBlock(-6,19,4,CONCRETE:7,70,STAINED_CLAY:12,15,STAINED_CLAY:15,5,CONCRETE:7,100)
RandomBlock(-6,19,5,CONCRETE:7,70,STAINED_CLAY:12,15,STAINED_CLAY:15,5,CONCRETE:7,100)
RandomBlock(-6,19,6,CONCRETE:7,70,STAINED_CLAY:12,15,STAINED_CLAY:15,5,CONCRETE:7,100)
RandomBlock(-6,19,7,CONCRETE:7,70,STAINED_CLAY:12,15,STAINED_CLAY:15,5,CONCRETE:7,100)
RandomBlock(-6,19,8,CONCRETE:7,70,STAINED_CLAY:12,15,STAINED_CLAY:15,5,CONCRETE:7,100)
RandomBlock(-6,20,-7,CONCRETE:7,70,STAINED_CLAY:12,15,STAINED_CLAY:15,5,CONCRETE:7,100)
RandomBlock(-6,20,-6,CONCRETE:7,70,STAINED_CLAY:12,15,STAINED_CLAY:15,5,CONCRETE:7,100)
RandomBlock(-6,20,-5,CONCRETE:7,70,STAINED_CLAY:12,15,STAINED_CLAY:15,5,CONCRETE:7,100)
RandomBlock(-6,20,-4,CONCRETE:7,70,STAINED_CLAY:12,15,STAINED_CLAY:15,5,CONCRETE:7,100)
RandomBlock(-6,20,-3,CONCRETE:7,70,STAINED_CLAY:12,15,STAINED_CLAY:15,5,CONCRETE:7,100)
RandomBlock(-6,20,-2,CONCRETE:7,70,STAINED_CLAY:12,15,STAINED_CLAY:15,5,CONCRETE:7,100)
RandomBlock(-6,20,-1,CONCRETE:7,70,STAINED_CLAY:12,15,STAINED_CLAY:15,5,CONCRETE:7,100)
RandomBlock(-6,20,0,CONCRETE:7,70,STAINED_CLAY:12,15,STAINED_CLAY:15,5,CONCRETE:7,100)
RandomBlock(-6,20,1,CONCRETE:7,70,STAINED_CLAY:12,15,STAINED_CLAY:15,5,CONCRETE:7,100)
RandomBlock(-6,20,2,CONCRETE:7,70,STAINED_CLAY:12,15,STAINED_CLAY:15,5,CONCRETE:7,100)
RandomBlock(-6,20,3,CONCRETE:7,70,STAINED_CLAY:12,15,STAINED_CLAY:15,5,CONCRETE:7,100)
RandomBlock(-6,20,4,CONCRETE:7,70,STAINED_CLAY:12,15,STAINED_CLAY:15,5,CONCRETE:7,100)
RandomBlock(-6,20,5,CONCRETE:7,70,STAINED_CLAY:12,15,STAINED_CLAY:15,5,CONCRETE:7,100)
RandomBlock(-6,20,6,CONCRETE:7,70,STAINED_CLAY:12,15,STAINED_CLAY:15,5,CONCRETE:7,100)
RandomBlock(-6,20,7,CONCRETE:7,70,STAINED_CLAY:12,15,STAINED_CLAY:15,5,CONCRETE:7,100)
RandomBlock(-6,20,8,CONCRETE:7,70,STAINED_CLAY:12,15,STAINED_CLAY:15,5,CONCRETE:7,100)
RandomBlock(-6,21,-7,CONCRETE:7,70,STAINED_CLAY:12,15,STAINED_CLAY:15,5,CONCRETE:7,100)
RandomBlock(-6,21,-6,CONCRETE:7,70,STAINED_CLAY:12,15,STAINED_CLAY:15,5,CONCRETE:7,100)
RandomBlock(-6,21,-5,CONCRETE:7,70,STAINED_CLAY:12,15,STAINED_CLAY:15,5,CONCRETE:7,100)
RandomBlock(-6,21,-4,CONCRETE:7,70,STAINED_CLAY:12,15,STAINED_CLAY:15,5,CONCRETE:7,100)
RandomBlock(-6,21,-3,CONCRETE:7,70,STAINED_CLAY:12,15,STAINED_CLAY:15,5,CONCRETE:7,100)
RandomBlock(-6,21,-2,CONCRETE:7,70,STAINED_CLAY:12,15,STAINED_CLAY:15,5,CONCRETE:7,100)
RandomBlock(-6,21,-1,CONCRETE:7,70,STAINED_CLAY:12,15,STAINED_CLAY:15,5,CONCRETE:7,100)
RandomBlock(-6,21,0,CONCRETE:7,70,STAINED_CLAY:12,15,STAINED_CLAY:15,5,CONCRETE:7,100)
RandomBlock(-6,21,1,CONCRETE:7,70,STAINED_CLAY:12,15,STAINED_CLAY:15,5,CONCRETE:7,100)
RandomBlock(-6,21,2,CONCRETE:7,70,STAINED_CLAY:12,15,STAINED_CLAY:15,5,CONCRETE:7,100)
RandomBlock(-6,21,3,CONCRETE:7,70,STAINED_CLAY:12,15,STAINED_CLAY:15,5,CONCRETE:7,100)
RandomBlock(-6,21,4,CONCRETE:7,70,STAINED_CLAY:12,15,STAINED_CLAY:15,5,CONCRETE:7,100)
RandomBlock(-6,21,5,CONCRETE:7,70,STAINED_CLAY:12,15,STAINED_CLAY:15,5,CONCRETE:7,100)
RandomBlock(-6,21,6,CONCRETE:7,70,STAINED_CLAY:12,15,STAINED_CLAY:15,5,CONCRETE:7,100)
RandomBlock(-6,21,7,CONCRETE:7,70,STAINED_CLAY:12,15,STAINED_CLAY:15,5,CONCRETE:7,100)
RandomBlock(-6,21,8,CONCRETE:7,70,STAINED_CLAY:12,15,STAINED_CLAY:15,5,CONCRETE:7,100)
Block(-6,22,-7,STEP:8)
Block(-6,22,-6,STEP:8)
Block(-6,22,-5,STEP:8)
Block(-6,22,-4,STEP:8)
RandomBlock(-6,22,-3,CONCRETE:7,70,STAINED_CLAY:12,15,STAINED_CLAY:15,5,CONCRETE:7,100)
RandomBlock(-6,22,-2,CONCRETE:7,70,STAINED_CLAY:12,15,STAINED_CLAY:15,5,CONCRETE:7,100)
RandomBlock(-6,22,-1,CONCRETE:7,70,STAINED_CLAY:12,15,STAINED_CLAY:15,5,CONCRETE:7,100)
RandomBlock(-6,22,0,CONCRETE:7,70,STAINED_CLAY:12,15,STAINED_CLAY:15,5,CONCRETE:7,100)
RandomBlock(-6,22,1,CONCRETE:7,70,STAINED_CLAY:12,15,STAINED_CLAY:15,5,CONCRETE:7,100)
RandomBlock(-6,22,2,CONCRETE:7,70,STAINED_CLAY:12,15,STAINED_CLAY:15,5,CONCRETE:7,100)
RandomBlock(-6,22,3,CONCRETE:7,70,STAINED_CLAY:12,15,STAINED_CLAY:15,5,CONCRETE:7,100)
RandomBlock(-6,22,4,CONCRETE:7,70,STAINED_CLAY:12,15,STAINED_CLAY:15,5,CONCRETE:7,100)
Block(-6,22,5,STEP:8)
Block(-6,22,6,STEP:8)
Block(-6,22,7,STEP:8)
Block(-6,22,8,STEP:8)
Block(-6,23,-2,SMOOTH_STAIRS:2)
Block(-6,23,-1,AIR:0)
Block(-6,23,0,AIR:0)
Block(-6,23,1,AIR:0)
Block(-6,23,2,AIR:0)
Block(-6,23,3,SMOOTH_STAIRS:3)
Block(-6,24,-2,SMOOTH_STAIRS:2)
Block(-6,24,-1,AIR:0)
Block(-6,24,0,AIR:0)
Block(-6,24,1,AIR:0)
Block(-6,24,2,AIR:0)
Block(-6,24,3,SMOOTH_STAIRS:3)
Block(-6,25,-2,SMOOTH_STAIRS:2)
Block(-6,25,-1,AIR:0)
Block(-6,25,0,AIR:0)
Block(-6,25,1,AIR:0)
Block(-6,25,2,AIR:0)
Block(-6,25,3,SMOOTH_STAIRS:3)
RandomBlock(-6,26,-2,CONCRETE:7,70,STAINED_CLAY:12,15,STAINED_CLAY:15,5,CONCRETE:7,100)
Block(-6,26,-1,STEP:8)
Block(-6,26,0,STEP:8)
Block(-6,26,1,STEP:8)
Block(-6,26,2,STEP:8)
RandomBlock(-6,26,3,CONCRETE:7,70,STAINED_CLAY:12,15,STAINED_CLAY:15,5,CONCRETE:7,100)
RandomBlock(-5,0,-2,CONCRETE:7,70,STAINED_CLAY:12,15,STAINED_CLAY:15,5,CONCRETE:7,100)
Block(-5,0,-1,AIR:0)
Block(-5,0,0,AIR:0)
Block(-5,0,1,AIR:0)
Block(-5,0,2,AIR:0)
RandomBlock(-5,0,3,CONCRETE:7,70,STAINED_CLAY:12,15,STAINED_CLAY:15,5,CONCRETE:7,100)
RandomBlock(-5,11,-2,CONCRETE:7,70,STAINED_CLAY:12,15,STAINED_CLAY:15,5,CONCRETE:7,100)
Block(-5,11,-1,AIR:0)
Block(-5,11,0,AIR:0)
Block(-5,11,1,AIR:0)
Block(-5,11,2,AIR:0)
RandomBlock(-5,11,3,CONCRETE:7,70,STAINED_CLAY:12,15,STAINED_CLAY:15,5,CONCRETE:7,100)
RandomBlock(-5,12,-2,CONCRETE:7,70,STAINED_CLAY:12,15,STAINED_CLAY:15,5,CONCRETE:7,100)
Block(-5,12,-1,AIR:0)
Block(-5,12,0,AIR:0)
Block(-5,12,1,AIR:0)
Block(-5,12,2,AIR:0)
RandomBlock(-5,12,3,CONCRETE:7,70,STAINED_CLAY:12,15,STAINED_CLAY:15,5,CONCRETE:7,100)
RandomBlock(-5,13,-2,CONCRETE:7,70,STAINED_CLAY:12,15,STAINED_CLAY:15,5,CONCRETE:7,100)
Block(-5,13,-1,AIR:0)
Block(-5,13,0,AIR:0)
Block(-5,13,1,AIR:0)
Block(-5,13,2,AIR:0)
RandomBlock(-5,13,3,CONCRETE:7,70,STAINED_CLAY:12,15,STAINED_CLAY:15,5,CONCRETE:7,100)
Block(-5,14,-6,CONCRETE:15)
Block(-5,14,-4,CONCRETE:15)
RandomBlock(-5,14,-2,CONCRETE:7,70,STAINED_CLAY:12,15,STAINED_CLAY:15,5,CONCRETE:7,100)
Block(-5,14,-1,AIR:0)
Block(-5,14,0,AIR:0)
Block(-5,14,1,AIR:0)
Block(-5,14,2,AIR:0)
RandomBlock(-5,14,3,CONCRETE:7,70,STAINED_CLAY:12,15,STAINED_CLAY:15,5,CONCRETE:7,100)
Block(-5,14,5,CONCRETE:15)
Block(-5,14,7,CONCRETE:15)
RandomBlock(-5,15,-7,CONCRETE:7,70,STAINED_CLAY:12,15,STAINED_CLAY:15,5,CONCRETE:7,100)
RandomBlock(-5,15,-6,CONCRETE:7,70,STAINED_CLAY:12,15,STAINED_CLAY:15,5,CONCRETE:7,100)
Block(-5,15,-5,STAINED_CLAY:9)
Block(-5,15,-4,STAINED_CLAY:9)
Block(-5,15,-3,STAINED_CLAY:9)
RandomBlock(-5,15,-2,CONCRETE:7,70,STAINED_CLAY:12,15,STAINED_CLAY:15,5,CONCRETE:7,100)
Block(-5,15,-1,AIR:0)
Block(-5,15,0,AIR:0)
Block(-5,15,1,AIR:0)
Block(-5,15,2,AIR:0)
RandomBlock(-5,15,3,CONCRETE:7,70,STAINED_CLAY:12,15,STAINED_CLAY:15,5,CONCRETE:7,100)
Block(-5,15,4,STAINED_CLAY:9)
Block(-5,15,5,STAINED_CLAY:9)
Block(-5,15,6,STAINED_CLAY:9)
RandomBlock(-5,15,7,CONCRETE:7,70,STAINED_CLAY:12,15,STAINED_CLAY:15,5,CONCRETE:7,100)
RandomBlock(-5,15,8,CONCRETE:7,70,STAINED_CLAY:12,15,STAINED_CLAY:15,5,CONCRETE:7,100)
RandomBlock(-5,16,-7,CONCRETE:7,70,STAINED_CLAY:12,15,STAINED_CLAY:15,5,CONCRETE:7,100)
RandomBlock(-5,16,-6,CONCRETE:7,70,STAINED_CLAY:12,15,STAINED_CLAY:15,5,CONCRETE:7,100)
Block(-5,16,-5,AIR:0)
Block(-5,16,-4,AIR:0)
Block(-5,16,-3,AIR:0)
RandomBlock(-5,16,-2,CONCRETE:7,70,STAINED_CLAY:12,15,STAINED_CLAY:15,5,CONCRETE:7,100)
Block(-5,16,-1,AIR:0)
Block(-5,16,0,AIR:0)
Block(-5,16,1,AIR:0)
Block(-5,16,2,AIR:0)
RandomBlock(-5,16,3,CONCRETE:7,70,STAINED_CLAY:12,15,STAINED_CLAY:15,5,CONCRETE:7,100)
Block(-5,16,4,STEP:8)
Block(-5,16,5,STEP:8)
Block(-5,16,6,STEP:8)
RandomBlock(-5,16,7,CONCRETE:7,70,STAINED_CLAY:12,15,STAINED_CLAY:15,5,CONCRETE:7,100)
RandomBlock(-5,16,8,CONCRETE:7,70,STAINED_CLAY:12,15,STAINED_CLAY:15,5,CONCRETE:7,100)
RandomBlock(-5,17,-7,CONCRETE:7,70,STAINED_CLAY:12,15,STAINED_CLAY:15,5,CONCRETE:7,100)
RandomBlock(-5,17,-6,CONCRETE:7,70,STAINED_CLAY:12,15,STAINED_CLAY:15,5,CONCRETE:7,100)
Block(-5,17,-5,AIR:0)
Block(-5,17,-4,AIR:0)
Block(-5,17,-3,AIR:0)
RandomBlock(-5,17,-2,CONCRETE:7,70,STAINED_CLAY:12,15,STAINED_CLAY:15,5,CONCRETE:7,100)
Block(-5,17,-1,AIR:0)
Block(-5,17,0,AIR:0)
Block(-5,17,1,AIR:0)
Block(-5,17,2,AIR:0)
RandomBlock(-5,17,3,CONCRETE:7,70,STAINED_CLAY:12,15,STAINED_CLAY:15,5,CONCRETE:7,100)
Block(-5,17,4,AIR:0)
RandomBlock(-5,17,5,CHEST:5,../../../Chests/Lore/ModernCity_1.nbt,1,CHEST:5,../../../Chests/Lore/ModernCity_2.nbt,1,CHEST:5,../../../Chests/Lore/ModernCity_3.nbt,1,CHEST:5,../../../Chests/Lore/ModernCity_4.nbt,1,CHEST:5,../../../Chests/Lore/ModernCity_5.nbt,1,CHEST:5,../../../Chests/Loot/ModernCityCommon1.nbt,5,CHEST:5,../../../Chests/Loot/ModernCityCommon2.nbt,5,CHEST:5,../../../Chests/Loot/ModernCityCommon3.nbt,5,CHEST:5,../../../Chests/Loot/ModernCityCommon4.nbt,5,CHEST:5,../../../Chests/Loot/ModernCityCommon5.nbt,5,CHEST:5,../../../Chests/Loot/Common6.nbt,5,CHEST:5,../../../Chests/Loot/Common7.nbt,5,CHEST:5,../../../Chests/Loot/Common8.nbt,5,CHEST:5,../../../Chests/Loot/Common9.nbt,5,CHEST:5,../../../Chests/Loot/ModernCityCommon10.nbt,5,CHEST:5,../../../Chests/Loot/ModernCityCommon11.nbt,5,CHEST:5,../../../Chests/Loot/ModernCityCommon12.nbt,5,CHEST:5,../../../Chests/Loot/ModernCityCommon13.nbt,5,CHEST:5,../../../Chests/Loot/ModernCityCommon14.nbt,5,CHEST:5,../../../Chests/Loot/ModernCityCommon15.nbt,5,CHEST:5,../../../Chests/Lore/ModernCity_1.nbt,2,CHEST:5,../../../Chests/Lore/ModernCity_2.nbt,2,CHEST:5,../../../Chests/Lore/ModernCity_3.nbt,2,CHEST:5,../../../Chests/Lore/ModernCity_4.nbt,2,CHEST:5,../../../Chests/Lore/ModernCity_5.nbt,2,CHEST:5,../../../Chests/Loot/ModernCityRare_1.nbt,5,CHEST:5,../../../Chests/Loot/ModernCityRare_2.nbt,5,CHEST:5,../../../Chests/Loot/ModernCityRare_3.nbt,5,CHEST:5,../../../Chests/Loot/ModernCityRare_4.nbt,5,CHEST:5,../../../Chests/Loot/ModernCityRare_5.nbt,5,CHEST:5,../../../Chests/Loot/Rare6.nbt,5,CHEST:5,../../../Chests/Loot/Rare7.nbt,5,CHEST:5,../../../Chests/Loot/Rare8.nbt,5,CHEST:5,../../../Chests/Loot/Rare9.nbt,5,CHEST:5,../../../Chests/Loot/Rare10.nbt,5,CHEST:5,../../../Chests/Loot/Rare11.nbt,5,CHEST:5,../../../Chests/Loot/Rare12.nbt,5,CHEST:5,../../../Chests/Loot/Rare13.nbt,5,CHEST:5,../../../Chests/Loot/Rare14.nbt,5,CHEST:5,../../../Chests/Loot/Rare15.nbt,5,CHEST:5,../../../Chests/Loot/ModernCityEpic_1.nbt,2,CHEST:5,../../../Chests/Loot/ModernCityEpic_2.nbt,2,CHEST:5,../../../Chests/Loot/ModernCityEpic_3.nbt,2,CHEST:5,../../../Chests/Loot/ModernCityEpic_4.nbt,2,CHEST:5,../../../Chests/Loot/ModernCityEpic_5.nbt,2,CHEST:5,../../../Chests/Loot/Epic6.nbt,2,CHEST:5,../../../Chests/Loot/Epic7.nbt,2,CHEST:5,../../../Chests/Loot/Epic8.nbt,2,CHEST:5,../../../Chests/Loot/Epic9.nbt,2,CHEST:5,../../../Chests/Loot/Epic10.nbt,2,CHEST:5,../../../Chests/Loot/Epic11.nbt,2,CHEST:5,../../../Chests/Loot/Epic12.nbt,2,CHEST:5,../../../Chests/Loot/Epic13.nbt,2,CHEST:5,../../../Chests/Loot/Epic14.nbt,2,CHEST:5,../../../Chests/Loot/Epic15.nbt,5,CHEST:5,../../../Chests/Loot/ModernCityRare_1.nbt,5,CHEST:5,../../../Chests/Loot/ModernCityRare_2.nbt,5,CHEST:5,../../../Chests/Loot/ModernCityRare_3.nbt,5,CHEST:5,../../../Chests/Loot/ModernCityRare_4.nbt,5,CHEST:5,../../../Chests/Loot/ModernCityRare_5.nbt,10,CHEST:5,../../../Chests/Loot/Rare6.nbt,10,CHEST:5,../../../Chests/Loot/Rare7.nbt,10,CHEST:5,../../../Chests/Loot/Rare8.nbt,10,CHEST:5,../../../Chests/Loot/Rare9.nbt,10,CHEST:5,../../../Chests/Loot/Rare10.nbt,15,CHEST:5,../../../Chests/Loot/Rare11.nbt,15,CHEST:5,../../../Chests/Loot/Rare12.nbt,15,CHEST:5,../../../Chests/Loot/Rare13.nbt,15,CHEST:5,../../../Chests/Loot/Rare14.nbt,15,CHEST:5,../../../Chests/Loot/Rare15.nbt,15,CHEST:5,../../../Chests/Loot/Epic15.nbt,100)
RandomBlock(-5,17,6,CHEST:5,../../../Chests/Lore/ModernCity_1.nbt,1,CHEST:5,../../../Chests/Lore/ModernCity_2.nbt,1,CHEST:5,../../../Chests/Lore/ModernCity_3.nbt,1,CHEST:5,../../../Chests/Lore/ModernCity_4.nbt,1,CHEST:5,../../../Chests/Lore/ModernCity_5.nbt,1,CHEST:5,../../../Chests/Loot/ModernCityCommon1.nbt,5,CHEST:5,../../../Chests/Loot/ModernCityCommon2.nbt,5,CHEST:5,../../../Chests/Loot/ModernCityCommon3.nbt,5,CHEST:5,../../../Chests/Loot/ModernCityCommon4.nbt,5,CHEST:5,../../../Chests/Loot/ModernCityCommon5.nbt,5,CHEST:5,../../../Chests/Loot/Common6.nbt,5,CHEST:5,../../../Chests/Loot/Common7.nbt,5,CHEST:5,../../../Chests/Loot/Common8.nbt,5,CHEST:5,../../../Chests/Loot/Common9.nbt,5,CHEST:5,../../../Chests/Loot/ModernCityCommon10.nbt,5,CHEST:5,../../../Chests/Loot/ModernCityCommon11.nbt,5,CHEST:5,../../../Chests/Loot/ModernCityCommon12.nbt,5,CHEST:5,../../../Chests/Loot/ModernCityCommon13.nbt,5,CHEST:5,../../../Chests/Loot/ModernCityCommon14.nbt,5,CHEST:5,../../../Chests/Loot/ModernCityCommon15.nbt,5,CHEST:5,../../../Chests/Lore/ModernCity_1.nbt,2,CHEST:5,../../../Chests/Lore/ModernCity_2.nbt,2,CHEST:5,../../../Chests/Lore/ModernCity_3.nbt,2,CHEST:5,../../../Chests/Lore/ModernCity_4.nbt,2,CHEST:5,../../../Chests/Lore/ModernCity_5.nbt,2,CHEST:5,../../../Chests/Loot/ModernCityRare_1.nbt,5,CHEST:5,../../../Chests/Loot/ModernCityRare_2.nbt,5,CHEST:5,../../../Chests/Loot/ModernCityRare_3.nbt,5,CHEST:5,../../../Chests/Loot/ModernCityRare_4.nbt,5,CHEST:5,../../../Chests/Loot/ModernCityRare_5.nbt,5,CHEST:5,../../../Chests/Loot/Rare6.nbt,5,CHEST:5,../../../Chests/Loot/Rare7.nbt,5,CHEST:5,../../../Chests/Loot/Rare8.nbt,5,CHEST:5,../../../Chests/Loot/Rare9.nbt,5,CHEST:5,../../../Chests/Loot/Rare10.nbt,5,CHEST:5,../../../Chests/Loot/Rare11.nbt,5,CHEST:5,../../../Chests/Loot/Rare12.nbt,5,CHEST:5,../../../Chests/Loot/Rare13.nbt,5,CHEST:5,../../../Chests/Loot/Rare14.nbt,5,CHEST:5,../../../Chests/Loot/Rare15.nbt,5,CHEST:5,../../../Chests/Loot/ModernCityEpic_1.nbt,2,CHEST:5,../../../Chests/Loot/ModernCityEpic_2.nbt,2,CHEST:5,../../../Chests/Loot/ModernCityEpic_3.nbt,2,CHEST:5,../../../Chests/Loot/ModernCityEpic_4.nbt,2,CHEST:5,../../../Chests/Loot/ModernCityEpic_5.nbt,2,CHEST:5,../../../Chests/Loot/Epic6.nbt,2,CHEST:5,../../../Chests/Loot/Epic7.nbt,2,CHEST:5,../../../Chests/Loot/Epic8.nbt,2,CHEST:5,../../../Chests/Loot/Epic9.nbt,2,CHEST:5,../../../Chests/Loot/Epic10.nbt,2,CHEST:5,../../../Chests/Loot/Epic11.nbt,2,CHEST:5,../../../Chests/Loot/Epic12.nbt,2,CHEST:5,../../../Chests/Loot/Epic13.nbt,2,CHEST:5,../../../Chests/Loot/Epic14.nbt,2,CHEST:5,../../../Chests/Loot/Epic15.nbt,5,CHEST:5,../../../Chests/Loot/ModernCityRare_1.nbt,5,CHEST:5,../../../Chests/Loot/ModernCityRare_2.nbt,5,CHEST:5,../../../Chests/Loot/ModernCityRare_3.nbt,5,CHEST:5,../../../Chests/Loot/ModernCityRare_4.nbt,5,CHEST:5,../../../Chests/Loot/ModernCityRare_5.nbt,10,CHEST:5,../../../Chests/Loot/Rare6.nbt,10,CHEST:5,../../../Chests/Loot/Rare7.nbt,10,CHEST:5,../../../Chests/Loot/Rare8.nbt,10,CHEST:5,../../../Chests/Loot/Rare9.nbt,10,CHEST:5,../../../Chests/Loot/Rare10.nbt,15,CHEST:5,../../../Chests/Loot/Rare11.nbt,15,CHEST:5,../../../Chests/Loot/Rare12.nbt,15,CHEST:5,../../../Chests/Loot/Rare13.nbt,15,CHEST:5,../../../Chests/Loot/Rare14.nbt,15,CHEST:5,../../../Chests/Loot/Rare15.nbt,15,CHEST:5,../../../Chests/Loot/Epic15.nbt,100)
RandomBlock(-5,17,7,CONCRETE:7,70,STAINED_CLAY:12,15,STAINED_CLAY:15,5,CONCRETE:7,100)
RandomBlock(-5,17,8,CONCRETE:7,70,STAINED_CLAY:12,15,STAINED_CLAY:15,5,CONCRETE:7,100)
RandomBlock(-5,18,-7,CONCRETE:7,70,STAINED_CLAY:12,15,STAINED_CLAY:15,5,CONCRETE:7,100)
RandomBlock(-5,18,-6,CONCRETE:7,70,STAINED_CLAY:12,15,STAINED_CLAY:15,5,CONCRETE:7,100)
Block(-5,18,-5,AIR:0)
Block(-5,18,-4,AIR:0)
Block(-5,18,-3,AIR:0)
RandomBlock(-5,18,-2,CONCRETE:7,70,STAINED_CLAY:12,15,STAINED_CLAY:15,5,CONCRETE:7,100)
Block(-5,18,-1,AIR:0)
Block(-5,18,0,AIR:0)
Block(-5,18,1,AIR:0)
Block(-5,18,2,AIR:0)
RandomBlock(-5,18,3,CONCRETE:7,70,STAINED_CLAY:12,15,STAINED_CLAY:15,5,CONCRETE:7,100)
Block(-5,18,4,AIR:0)
Block(-5,18,5,AIR:0)
Block(-5,18,6,AIR:0)
RandomBlock(-5,18,7,CONCRETE:7,70,STAINED_CLAY:12,15,STAINED_CLAY:15,5,CONCRETE:7,100)
RandomBlock(-5,18,8,CONCRETE:7,70,STAINED_CLAY:12,15,STAINED_CLAY:15,5,CONCRETE:7,100)
RandomBlock(-5,19,-7,CONCRETE:7,70,STAINED_CLAY:12,15,STAINED_CLAY:15,5,CONCRETE:7,100)
RandomBlock(-5,19,-6,CONCRETE:7,70,STAINED_CLAY:12,15,STAINED_CLAY:15,5,CONCRETE:7,100)
Block(-5,19,-5,AIR:0)
Block(-5,19,-4,AIR:0)
Block(-5,19,-3,AIR:0)
RandomBlock(-5,19,-2,CONCRETE:7,70,STAINED_CLAY:12,15,STAINED_CLAY:15,5,CONCRETE:7,100)
Block(-5,19,-1,AIR:0)
Block(-5,19,0,AIR:0)
Block(-5,19,1,AIR:0)
Block(-5,19,2,AIR:0)
RandomBlock(-5,19,3,CONCRETE:7,70,STAINED_CLAY:12,15,STAINED_CLAY:15,5,CONCRETE:7,100)
Block(-5,19,4,AIR:0)
Block(-5,19,5,AIR:0)
Block(-5,19,6,AIR:0)
RandomBlock(-5,19,7,CONCRETE:7,70,STAINED_CLAY:12,15,STAINED_CLAY:15,5,CONCRETE:7,100)
RandomBlock(-5,19,8,CONCRETE:7,70,STAINED_CLAY:12,15,STAINED_CLAY:15,5,CONCRETE:7,100)
RandomBlock(-5,20,-7,CONCRETE:7,70,STAINED_CLAY:12,15,STAINED_CLAY:15,5,CONCRETE:7,100)
RandomBlock(-5,20,-6,CONCRETE:7,70,STAINED_CLAY:12,15,STAINED_CLAY:15,5,CONCRETE:7,100)
Block(-5,20,-5,AIR:0)
Block(-5,20,-4,AIR:0)
Block(-5,20,-3,AIR:0)
RandomBlock(-5,20,-2,CONCRETE:7,70,STAINED_CLAY:12,15,STAINED_CLAY:15,5,CONCRETE:7,100)
Block(-5,20,-1,AIR:0)
Block(-5,20,0,AIR:0)
Block(-5,20,1,AIR:0)
Block(-5,20,2,AIR:0)
RandomBlock(-5,20,3,CONCRETE:7,70,STAINED_CLAY:12,15,STAINED_CLAY:15,5,CONCRETE:7,100)
Block(-5,20,4,AIR:0)
Block(-5,20,5,AIR:0)
Block(-5,20,6,AIR:0)
RandomBlock(-5,20,7,CONCRETE:7,70,STAINED_CLAY:12,15,STAINED_CLAY:15,5,CONCRETE:7,100)
RandomBlock(-5,20,8,CONCRETE:7,70,STAINED_CLAY:12,15,STAINED_CLAY:15,5,CONCRETE:7,100)
RandomBlock(-5,21,-7,CONCRETE:7,70,STAINED_CLAY:12,15,STAINED_CLAY:15,5,CONCRETE:7,100)
RandomBlock(-5,21,-6,CONCRETE:7,70,STAINED_CLAY:12,15,STAINED_CLAY:15,5,CONCRETE:7,100)
RandomBlock(-5,21,-5,CONCRETE:7,70,STAINED_CLAY:12,15,STAINED_CLAY:15,5,CONCRETE:7,100)
RandomBlock(-5,21,-4,CONCRETE:7,70,STAINED_CLAY:12,15,STAINED_CLAY:15,5,CONCRETE:7,100)
RandomBlock(-5,21,-3,CONCRETE:7,70,STAINED_CLAY:12,15,STAINED_CLAY:15,5,CONCRETE:7,100)
RandomBlock(-5,21,-2,CONCRETE:7,70,STAINED_CLAY:12,15,STAINED_CLAY:15,5,CONCRETE:7,100)
Block(-5,21,-1,AIR:0)
Block(-5,21,0,AIR:0)
Block(-5,21,1,AIR:0)
Block(-5,21,2,AIR:0)
RandomBlock(-5,21,3,CONCRETE:7,70,STAINED_CLAY:12,15,STAINED_CLAY:15,5,CONCRETE:7,100)
RandomBlock(-5,21,4,CONCRETE:7,70,STAINED_CLAY:12,15,STAINED_CLAY:15,5,CONCRETE:7,100)
RandomBlock(-5,21,5,CONCRETE:7,70,STAINED_CLAY:12,15,STAINED_CLAY:15,5,CONCRETE:7,100)
RandomBlock(-5,21,6,CONCRETE:7,70,STAINED_CLAY:12,15,STAINED_CLAY:15,5,CONCRETE:7,100)
RandomBlock(-5,21,7,CONCRETE:7,70,STAINED_CLAY:12,15,STAINED_CLAY:15,5,CONCRETE:7,100)
RandomBlock(-5,21,8,CONCRETE:7,70,STAINED_CLAY:12,15,STAINED_CLAY:15,5,CONCRETE:7,100)
Block(-5,22,-7,DOUBLE_STEP:0)
Block(-5,22,-6,DOUBLE_STEP:0)
Block(-5,22,-5,DOUBLE_STEP:0)
Block(-5,22,-4,DOUBLE_STEP:0)
RandomBlock(-5,22,-3,CONCRETE:7,70,STAINED_CLAY:12,15,STAINED_CLAY:15,5,CONCRETE:7,100)
RandomBlock(-5,22,-2,CONCRETE:7,70,STAINED_CLAY:12,15,STAINED_CLAY:15,5,CONCRETE:7,100)
Block(-5,22,-1,AIR:0)
RandomBlock(-5,22,0,CONCRETE:7,70,STAINED_CLAY:12,15,STAINED_CLAY:15,5,CONCRETE:7,100)
RandomBlock(-5,22,1,CONCRETE:7,70,STAINED_CLAY:12,15,STAINED_CLAY:15,5,CONCRETE:7,100)
Block(-5,22,2,AIR:0)
RandomBlock(-5,22,3,CONCRETE:7,70,STAINED_CLAY:12,15,STAINED_CLAY:15,5,CONCRETE:7,100)
RandomBlock(-5,22,4,CONCRETE:7,70,STAINED_CLAY:12,15,STAINED_CLAY:15,5,CONCRETE:7,100)
Block(-5,22,5,DOUBLE_STEP:0)
Block(-5,22,6,DOUBLE_STEP:0)
Block(-5,22,7,DOUBLE_STEP:0)
Block(-5,22,8,DOUBLE_STEP:0)
Block(-5,23,-2,SMOOTH_STAIRS:2)
Block(-5,23,-1,AIR:0)
Block(-5,23,0,AIR:0)
Block(-5,23,1,AIR:0)
Block(-5,23,2,AIR:0)
Block(-5,23,3,SMOOTH_STAIRS:3)
Block(-5,24,-2,SMOOTH_STAIRS:2)
Block(-5,24,-1,AIR:0)
Block(-5,24,0,AIR:0)
Block(-5,24,1,AIR:0)
Block(-5,24,2,AIR:0)
Block(-5,24,3,SMOOTH_STAIRS:3)
Block(-5,25,-2,SMOOTH_STAIRS:2)
Block(-5,25,-1,AIR:0)
Block(-5,25,0,AIR:0)
Block(-5,25,1,AIR:0)
Block(-5,25,2,AIR:0)
Block(-5,25,3,SMOOTH_STAIRS:3)
RandomBlock(-5,26,-2,CONCRETE:7,70,STAINED_CLAY:12,15,STAINED_CLAY:15,5,CONCRETE:7,100)
Block(-5,26,-1,STEP:8)
Block(-5,26,0,STEP:8)
Block(-5,26,1,STEP:8)
Block(-5,26,2,STEP:8)
RandomBlock(-5,26,3,CONCRETE:7,70,STAINED_CLAY:12,15,STAINED_CLAY:15,5,CONCRETE:7,100)
RandomBlock(-4,0,-2,CONCRETE:7,70,STAINED_CLAY:12,15,STAINED_CLAY:15,5,CONCRETE:7,100)
Block(-4,0,-1,AIR:0)
Block(-4,0,0,AIR:0)
Block(-4,0,1,AIR:0)
Block(-4,0,2,AIR:0)
RandomBlock(-4,0,3,CONCRETE:7,70,STAINED_CLAY:12,15,STAINED_CLAY:15,5,CONCRETE:7,100)
RandomBlock(-4,11,-2,CONCRETE:7,70,STAINED_CLAY:12,15,STAINED_CLAY:15,5,CONCRETE:7,100)
Block(-4,11,-1,AIR:0)
Block(-4,11,0,AIR:0)
Block(-4,11,1,AIR:0)
Block(-4,11,2,AIR:0)
Block(-4,11,3,CONCRETE:0)
RandomBlock(-4,12,-2,CONCRETE:7,70,STAINED_CLAY:12,15,STAINED_CLAY:15,5,CONCRETE:7,100)
Block(-4,12,-1,AIR:0)
Block(-4,12,0,AIR:0)
Block(-4,12,1,AIR:0)
Block(-4,12,2,AIR:0)
Block(-4,12,3,CONCRETE:0)
RandomBlock(-4,13,-2,CONCRETE:7,70,STAINED_CLAY:12,15,STAINED_CLAY:15,5,CONCRETE:7,100)
Block(-4,13,-1,AIR:0)
Block(-4,13,0,AIR:0)
Block(-4,13,1,AIR:0)
Block(-4,13,2,AIR:0)
Block(-4,13,3,CONCRETE:0)
Block(-4,14,-6,CONCRETE:15)
Block(-4,14,-4,CONCRETE:15)
Block(-4,14,-2,CONCRETE:0)
Block(-4,14,-1,AIR:0)
Block(-4,14,0,AIR:0)
Block(-4,14,1,AIR:0)
Block(-4,14,2,AIR:0)
Block(-4,14,3,CONCRETE:0)
Block(-4,14,5,CONCRETE:15)
Block(-4,14,7,CONCRETE:15)
RandomBlock(-4,15,-7,CONCRETE:7,70,STAINED_CLAY:12,15,STAINED_CLAY:15,5,CONCRETE:7,100)
RandomBlock(-4,15,-6,CONCRETE:7,70,STAINED_CLAY:12,15,STAINED_CLAY:15,5,CONCRETE:7,100)
Block(-4,15,-5,STAINED_CLAY:9)
Block(-4,15,-4,STAINED_CLAY:9)
Block(-4,15,-3,STAINED_CLAY:9)
RandomBlock(-4,15,-2,CONCRETE:7,70,STAINED_CLAY:12,15,STAINED_CLAY:15,5,CONCRETE:7,100)
Block(-4,15,-1,AIR:0)
Block(-4,15,0,AIR:0)
Block(-4,15,1,AIR:0)
Block(-4,15,2,AIR:0)
RandomBlock(-4,15,3,CONCRETE:7,70,STAINED_CLAY:12,15,STAINED_CLAY:15,5,CONCRETE:7,100)
Block(-4,15,4,STAINED_CLAY:9)
Block(-4,15,5,STAINED_CLAY:9)
Block(-4,15,6,STAINED_CLAY:9)
RandomBlock(-4,15,7,CONCRETE:7,70,STAINED_CLAY:12,15,STAINED_CLAY:15,5,CONCRETE:7,100)
RandomBlock(-4,15,8,CONCRETE:7,70,STAINED_CLAY:12,15,STAINED_CLAY:15,5,CONCRETE:7,100)
RandomBlock(-4,16,-7,CONCRETE:7,70,STAINED_CLAY:12,15,STAINED_CLAY:15,5,CONCRETE:7,100)
Block(-4,16,-6,STEP:8)
Block(-4,16,-5,AIR:0)
Block(-4,16,-4,AIR:0)
Block(-4,16,-3,AIR:0)
Block(-4,16,-2,IRON_FENCE:0)
Block(-4,16,-1,AIR:0)
Block(-4,16,0,AIR:0)
Block(-4,16,1,AIR:0)
Block(-4,16,2,AIR:0)
Block(-4,16,3,IRON_FENCE:0)
Block(-4,16,4,AIR:0)
Block(-4,16,5,AIR:0)
Block(-4,16,6,AIR:0)
Block(-4,16,7,STEP:8)
RandomBlock(-4,16,8,CONCRETE:7,70,STAINED_CLAY:12,15,STAINED_CLAY:15,5,CONCRETE:7,100)
RandomBlock(-4,17,-7,CONCRETE:7,70,STAINED_CLAY:12,15,STAINED_CLAY:15,5,CONCRETE:7,100)
RandomBlock(-4,17,-6,CHEST:3,../../../Chests/Lore/ModernCity_1.nbt,1,CHEST:3,../../../Chests/Lore/ModernCity_2.nbt,1,CHEST:3,../../../Chests/Lore/ModernCity_3.nbt,1,CHEST:3,../../../Chests/Lore/ModernCity_4.nbt,1,CHEST:3,../../../Chests/Lore/ModernCity_5.nbt,1,CHEST:3,../../../Chests/Loot/ModernCityCommon1.nbt,5,CHEST:3,../../../Chests/Loot/ModernCityCommon2.nbt,5,CHEST:3,../../../Chests/Loot/ModernCityCommon3.nbt,5,CHEST:3,../../../Chests/Loot/ModernCityCommon4.nbt,5,CHEST:3,../../../Chests/Loot/ModernCityCommon5.nbt,5,CHEST:3,../../../Chests/Loot/Common6.nbt,5,CHEST:3,../../../Chests/Loot/Common7.nbt,5,CHEST:3,../../../Chests/Loot/Common8.nbt,5,CHEST:3,../../../Chests/Loot/Common9.nbt,5,CHEST:3,../../../Chests/Loot/ModernCityCommon10.nbt,5,CHEST:3,../../../Chests/Loot/ModernCityCommon11.nbt,5,CHEST:3,../../../Chests/Loot/ModernCityCommon12.nbt,5,CHEST:3,../../../Chests/Loot/ModernCityCommon13.nbt,5,CHEST:3,../../../Chests/Loot/ModernCityCommon14.nbt,5,CHEST:3,../../../Chests/Loot/ModernCityCommon15.nbt,5,CHEST:3,../../../Chests/Lore/ModernCity_1.nbt,2,CHEST:3,../../../Chests/Lore/ModernCity_2.nbt,2,CHEST:3,../../../Chests/Lore/ModernCity_3.nbt,2,CHEST:3,../../../Chests/Lore/ModernCity_4.nbt,2,CHEST:3,../../../Chests/Lore/ModernCity_5.nbt,2,CHEST:3,../../../Chests/Loot/ModernCityRare_1.nbt,5,CHEST:3,../../../Chests/Loot/ModernCityRare_2.nbt,5,CHEST:3,../../../Chests/Loot/ModernCityRare_3.nbt,5,CHEST:3,../../../Chests/Loot/ModernCityRare_4.nbt,5,CHEST:3,../../../Chests/Loot/ModernCityRare_5.nbt,5,CHEST:3,../../../Chests/Loot/Rare6.nbt,5,CHEST:3,../../../Chests/Loot/Rare7.nbt,5,CHEST:3,../../../Chests/Loot/Rare8.nbt,5,CHEST:3,../../../Chests/Loot/Rare9.nbt,5,CHEST:3,../../../Chests/Loot/Rare10.nbt,5,CHEST:3,../../../Chests/Loot/Rare11.nbt,5,CHEST:3,../../../Chests/Loot/Rare12.nbt,5,CHEST:3,../../../Chests/Loot/Rare13.nbt,5,CHEST:3,../../../Chests/Loot/Rare14.nbt,5,CHEST:3,../../../Chests/Loot/Rare15.nbt,5,CHEST:3,../../../Chests/Loot/ModernCityEpic_1.nbt,2,CHEST:3,../../../Chests/Loot/ModernCityEpic_2.nbt,2,CHEST:3,../../../Chests/Loot/ModernCityEpic_3.nbt,2,CHEST:3,../../../Chests/Loot/ModernCityEpic_4.nbt,2,CHEST:3,../../../Chests/Loot/ModernCityEpic_5.nbt,2,CHEST:3,../../../Chests/Loot/Epic6.nbt,2,CHEST:3,../../../Chests/Loot/Epic7.nbt,2,CHEST:3,../../../Chests/Loot/Epic8.nbt,2,CHEST:3,../../../Chests/Loot/Epic9.nbt,2,CHEST:3,../../../Chests/Loot/Epic10.nbt,2,CHEST:3,../../../Chests/Loot/Epic11.nbt,2,CHEST:3,../../../Chests/Loot/Epic12.nbt,2,CHEST:3,../../../Chests/Loot/Epic13.nbt,2,CHEST:3,../../../Chests/Loot/Epic14.nbt,2,CHEST:3,../../../Chests/Loot/Epic15.nbt,5,CHEST:3,../../../Chests/Loot/ModernCityRare_1.nbt,5,CHEST:3,../../../Chests/Loot/ModernCityRare_2.nbt,5,CHEST:3,../../../Chests/Loot/ModernCityRare_3.nbt,5,CHEST:3,../../../Chests/Loot/ModernCityRare_4.nbt,5,CHEST:3,../../../Chests/Loot/ModernCityRare_5.nbt,10,CHEST:3,../../../Chests/Loot/Rare6.nbt,10,CHEST:3,../../../Chests/Loot/Rare7.nbt,10,CHEST:3,../../../Chests/Loot/Rare8.nbt,10,CHEST:3,../../../Chests/Loot/Rare9.nbt,10,CHEST:3,../../../Chests/Loot/Rare10.nbt,15,CHEST:3,../../../Chests/Loot/Rare11.nbt,15,CHEST:3,../../../Chests/Loot/Rare12.nbt,15,CHEST:3,../../../Chests/Loot/Rare13.nbt,15,CHEST:3,../../../Chests/Loot/Rare14.nbt,15,CHEST:3,../../../Chests/Loot/Rare15.nbt,15,CHEST:3,../../../Chests/Loot/Epic15.nbt,100)
Block(-4,17,-5,AIR:0)
Block(-4,17,-4,AIR:0)
Block(-4,17,-3,AIR:0)
Block(-4,17,-2,AIR:0)
Block(-4,17,-1,AIR:0)
Block(-4,17,0,AIR:0)
Block(-4,17,1,AIR:0)
Block(-4,17,2,AIR:0)
Block(-4,17,3,AIR:0)
Block(-4,17,4,AIR:0)
Block(-4,17,5,AIR:0)
Block(-4,17,6,AIR:0)
Block(-4,17,7,AIR:0)
RandomBlock(-4,17,8,CONCRETE:7,70,STAINED_CLAY:12,15,STAINED_CLAY:15,5,CONCRETE:7,100)
RandomBlock(-4,18,-7,CONCRETE:7,70,STAINED_CLAY:12,15,STAINED_CLAY:15,5,CONCRETE:7,100)
Block(-4,18,-6,AIR:0)
Block(-4,18,-5,AIR:0)
Block(-4,18,-4,AIR:0)
Block(-4,18,-3,AIR:0)
Block(-4,18,-2,AIR:0)
Block(-4,18,-1,AIR:0)
Block(-4,18,0,AIR:0)
Block(-4,18,1,AIR:0)
Block(-4,18,2,AIR:0)
Block(-4,18,3,AIR:0)
Block(-4,18,4,AIR:0)
Block(-4,18,5,AIR:0)
Block(-4,18,6,AIR:0)
Block(-4,18,7,AIR:0)
RandomBlock(-4,18,8,CONCRETE:7,70,STAINED_CLAY:12,15,STAINED_CLAY:15,5,CONCRETE:7,100)
RandomBlock(-4,19,-7,CONCRETE:7,70,STAINED_CLAY:12,15,STAINED_CLAY:15,5,CONCRETE:7,100)
Block(-4,19,-6,AIR:0)
Block(-4,19,-5,AIR:0)
Block(-4,19,-4,AIR:0)
Block(-4,19,-3,AIR:0)
Block(-4,19,-2,AIR:0)
Block(-4,19,-1,AIR:0)
Block(-4,19,0,AIR:0)
Block(-4,19,1,AIR:0)
Block(-4,19,2,AIR:0)
Block(-4,19,3,AIR:0)
Block(-4,19,4,AIR:0)
Block(-4,19,5,AIR:0)
Block(-4,19,6,AIR:0)
Block(-4,19,7,AIR:0)
RandomBlock(-4,19,8,CONCRETE:7,70,STAINED_CLAY:12,15,STAINED_CLAY:15,5,CONCRETE:7,100)
RandomBlock(-4,20,-7,CONCRETE:7,70,STAINED_CLAY:12,15,STAINED_CLAY:15,5,CONCRETE:7,100)
Block(-4,20,-6,AIR:0)
Block(-4,20,-5,AIR:0)
Block(-4,20,-4,AIR:0)
Block(-4,20,-3,AIR:0)
Block(-4,20,-2,AIR:0)
Block(-4,20,-1,AIR:0)
Block(-4,20,0,AIR:0)
Block(-4,20,1,AIR:0)
Block(-4,20,2,AIR:0)
Block(-4,20,3,AIR:0)
Block(-4,20,4,AIR:0)
Block(-4,20,5,AIR:0)
Block(-4,20,6,AIR:0)
Block(-4,20,7,AIR:0)
RandomBlock(-4,20,8,CONCRETE:7,70,STAINED_CLAY:12,15,STAINED_CLAY:15,5,CONCRETE:7,100)
RandomBlock(-4,21,-7,CONCRETE:7,70,STAINED_CLAY:12,15,STAINED_CLAY:15,5,CONCRETE:7,100)
Block(-4,21,-6,AIR:0)
Block(-4,21,-5,AIR:0)
Block(-4,21,-4,AIR:0)
Block(-4,21,-3,AIR:0)
Block(-4,21,-2,AIR:0)
Block(-4,21,-1,AIR:0)
Block(-4,21,0,AIR:0)
Block(-4,21,1,AIR:0)
Block(-4,21,2,AIR:0)
Block(-4,21,3,AIR:0)
Block(-4,21,4,AIR:0)
Block(-4,21,5,AIR:0)
Block(-4,21,6,AIR:0)
Block(-4,21,7,AIR:0)
RandomBlock(-4,21,8,CONCRETE:7,70,STAINED_CLAY:12,15,STAINED_CLAY:15,5,CONCRETE:7,100)
Block(-4,22,-7,DOUBLE_STEP:0)
Block(-4,22,-6,STEP:8)
Block(-4,22,-5,STEP:8)
Block(-4,22,-4,STEP:8)
RandomBlock(-4,22,-3,CONCRETE:7,70,STAINED_CLAY:12,15,STAINED_CLAY:15,5,CONCRETE:7,100)
RandomBlock(-4,22,-2,CONCRETE:7,70,STAINED_CLAY:12,15,STAINED_CLAY:15,5,CONCRETE:7,100)
Block(-4,22,-1,AIR:0)
Block(-4,22,0,QUARTZ_STAIRS:5)
Block(-4,22,1,QUARTZ_STAIRS:5)
Block(-4,22,2,AIR:0)
RandomBlock(-4,22,3,CONCRETE:7,70,STAINED_CLAY:12,15,STAINED_CLAY:15,5,CONCRETE:7,100)
RandomBlock(-4,22,4,CONCRETE:7,70,STAINED_CLAY:12,15,STAINED_CLAY:15,5,CONCRETE:7,100)
Block(-4,22,5,STEP:8)
Block(-4,22,6,STEP:8)
Block(-4,22,7,STEP:8)
Block(-4,22,8,DOUBLE_STEP:0)
Block(-4,23,-2,SMOOTH_STAIRS:2)
Block(-4,23,-1,AIR:0)
Block(-4,23,0,AIR:0)
Block(-4,23,1,AIR:0)
Block(-4,23,2,AIR:0)
Block(-4,23,3,SMOOTH_STAIRS:3)
Block(-4,24,-2,SMOOTH_STAIRS:2)
Block(-4,24,-1,AIR:0)
Block(-4,24,0,AIR:0)
Block(-4,24,1,AIR:0)
Block(-4,24,2,AIR:0)
Block(-4,24,3,SMOOTH_STAIRS:3)
Block(-4,25,-2,SMOOTH_STAIRS:2)
Block(-4,25,-1,AIR:0)
Block(-4,25,0,AIR:0)
Block(-4,25,1,AIR:0)
Block(-4,25,2,AIR:0)
Block(-4,25,3,SMOOTH_STAIRS:3)
RandomBlock(-4,26,-2,CONCRETE:7,70,STAINED_CLAY:12,15,STAINED_CLAY:15,5,CONCRETE:7,100)
Block(-4,26,-1,STEP:8)
Block(-4,26,0,STEP:8)
Block(-4,26,1,STEP:8)
Block(-4,26,2,STEP:8)
RandomBlock(-4,26,3,CONCRETE:7,70,STAINED_CLAY:12,15,STAINED_CLAY:15,5,CONCRETE:7,100)
RandomBlock(-3,0,-2,CONCRETE:7,70,STAINED_CLAY:12,15,STAINED_CLAY:15,5,CONCRETE:7,100)
Block(-3,0,-1,AIR:0)
Block(-3,0,0,COBBLE_WALL:0)
Block(-3,0,1,COBBLE_WALL:0)
Block(-3,0,2,AIR:0)
RandomBlock(-3,0,3,CONCRETE:7,70,STAINED_CLAY:12,15,STAINED_CLAY:15,5,CONCRETE:7,100)
Block(-3,11,-2,CONCRETE:0)
Block(-3,11,-1,AIR:0)
Block(-3,11,0,COBBLE_WALL:0)
Block(-3,11,1,COBBLE_WALL:0)
Block(-3,11,2,AIR:0)
Block(-3,11,3,CONCRETE:0)
Block(-3,12,-2,CONCRETE:0)
Block(-3,12,-1,AIR:0)
Block(-3,12,0,COBBLE_WALL:0)
Block(-3,12,1,COBBLE_WALL:0)
Block(-3,12,2,AIR:0)
RandomBlock(-3,12,3,CONCRETE:7,70,STAINED_CLAY:12,15,STAINED_CLAY:15,5,CONCRETE:7,100)
Block(-3,13,-2,CONCRETE:0)
Block(-3,13,-1,AIR:0)
Block(-3,13,0,COBBLE_WALL:0)
Block(-3,13,1,COBBLE_WALL:0)
Block(-3,13,2,AIR:0)
RandomBlock(-3,13,3,CONCRETE:7,70,STAINED_CLAY:12,15,STAINED_CLAY:15,5,CONCRETE:7,100)
Block(-3,14,-6,CONCRETE:15)
Block(-3,14,-4,CONCRETE:15)
Block(-3,14,-2,CONCRETE:0)
Block(-3,14,-1,AIR:0)
Block(-3,14,0,COBBLE_WALL:0)
Block(-3,14,1,COBBLE_WALL:0)
Block(-3,14,2,AIR:0)
RandomBlock(-3,14,3,CONCRETE:7,70,STAINED_CLAY:12,15,STAINED_CLAY:15,5,CONCRETE:7,100)
Block(-3,14,5,CONCRETE:15)
Block(-3,14,7,CONCRETE:15)
RandomBlock(-3,15,-7,CONCRETE:7,70,STAINED_CLAY:12,15,STAINED_CLAY:15,5,CONCRETE:7,100)
RandomBlock(-3,15,-6,CONCRETE:7,70,STAINED_CLAY:12,15,STAINED_CLAY:15,5,CONCRETE:7,100)
Block(-3,15,-5,STAINED_CLAY:9)
Block(-3,15,-4,STAINED_CLAY:9)
Block(-3,15,-3,STAINED_CLAY:9)
RandomBlock(-3,15,-2,CONCRETE:7,70,STAINED_CLAY:12,15,STAINED_CLAY:15,5,CONCRETE:7,100)
Block(-3,15,-1,AIR:0)
Block(-3,15,0,COBBLE_WALL:0)
Block(-3,15,1,COBBLE_WALL:0)
Block(-3,15,2,AIR:0)
RandomBlock(-3,15,3,CONCRETE:7,70,STAINED_CLAY:12,15,STAINED_CLAY:15,5,CONCRETE:7,100)
Block(-3,15,4,STAINED_CLAY:9)
Block(-3,15,5,STAINED_CLAY:9)
Block(-3,15,6,STAINED_CLAY:9)
RandomBlock(-3,15,7,CONCRETE:7,70,STAINED_CLAY:12,15,STAINED_CLAY:15,5,CONCRETE:7,100)
RandomBlock(-3,15,8,CONCRETE:7,70,STAINED_CLAY:12,15,STAINED_CLAY:15,5,CONCRETE:7,100)
RandomBlock(-3,16,-7,CONCRETE:7,70,STAINED_CLAY:12,15,STAINED_CLAY:15,5,CONCRETE:7,100)
Block(-3,16,-6,STEP:8)
Block(-3,16,-5,AIR:0)
Block(-3,16,-4,AIR:0)
Block(-3,16,-3,AIR:0)
Block(-3,16,-2,IRON_FENCE:0)
Block(-3,16,-1,AIR:0)
Block(-3,16,0,COBBLE_WALL:0)
Block(-3,16,1,COBBLE_WALL:0)
Block(-3,16,2,AIR:0)
Block(-3,16,3,IRON_FENCE:0)
Block(-3,16,4,AIR:0)
Block(-3,16,5,AIR:0)
Block(-3,16,6,AIR:0)
Block(-3,16,7,STEP:8)
RandomBlock(-3,16,8,CONCRETE:7,70,STAINED_CLAY:12,15,STAINED_CLAY:15,5,CONCRETE:7,100)
RandomBlock(-3,17,-7,CONCRETE:7,70,STAINED_CLAY:12,15,STAINED_CLAY:15,5,CONCRETE:7,100)
RandomBlock(-3,17,-6,CHEST:3,../../../Chests/Lore/ModernCity_1.nbt,1,CHEST:3,../../../Chests/Lore/ModernCity_2.nbt,1,CHEST:3,../../../Chests/Lore/ModernCity_3.nbt,1,CHEST:3,../../../Chests/Lore/ModernCity_4.nbt,1,CHEST:3,../../../Chests/Lore/ModernCity_5.nbt,1,CHEST:3,../../../Chests/Loot/ModernCityCommon1.nbt,5,CHEST:3,../../../Chests/Loot/ModernCityCommon2.nbt,5,CHEST:3,../../../Chests/Loot/ModernCityCommon3.nbt,5,CHEST:3,../../../Chests/Loot/ModernCityCommon4.nbt,5,CHEST:3,../../../Chests/Loot/ModernCityCommon5.nbt,5,CHEST:3,../../../Chests/Loot/Common6.nbt,5,CHEST:3,../../../Chests/Loot/Common7.nbt,5,CHEST:3,../../../Chests/Loot/Common8.nbt,5,CHEST:3,../../../Chests/Loot/Common9.nbt,5,CHEST:3,../../../Chests/Loot/ModernCityCommon10.nbt,5,CHEST:3,../../../Chests/Loot/ModernCityCommon11.nbt,5,CHEST:3,../../../Chests/Loot/ModernCityCommon12.nbt,5,CHEST:3,../../../Chests/Loot/ModernCityCommon13.nbt,5,CHEST:3,../../../Chests/Loot/ModernCityCommon14.nbt,5,CHEST:3,../../../Chests/Loot/ModernCityCommon15.nbt,5,CHEST:3,../../../Chests/Lore/ModernCity_1.nbt,2,CHEST:3,../../../Chests/Lore/ModernCity_2.nbt,2,CHEST:3,../../../Chests/Lore/ModernCity_3.nbt,2,CHEST:3,../../../Chests/Lore/ModernCity_4.nbt,2,CHEST:3,../../../Chests/Lore/ModernCity_5.nbt,2,CHEST:3,../../../Chests/Loot/ModernCityRare_1.nbt,5,CHEST:3,../../../Chests/Loot/ModernCityRare_2.nbt,5,CHEST:3,../../../Chests/Loot/ModernCityRare_3.nbt,5,CHEST:3,../../../Chests/Loot/ModernCityRare_4.nbt,5,CHEST:3,../../../Chests/Loot/ModernCityRare_5.nbt,5,CHEST:3,../../../Chests/Loot/Rare6.nbt,5,CHEST:3,../../../Chests/Loot/Rare7.nbt,5,CHEST:3,../../../Chests/Loot/Rare8.nbt,5,CHEST:3,../../../Chests/Loot/Rare9.nbt,5,CHEST:3,../../../Chests/Loot/Rare10.nbt,5,CHEST:3,../../../Chests/Loot/Rare11.nbt,5,CHEST:3,../../../Chests/Loot/Rare12.nbt,5,CHEST:3,../../../Chests/Loot/Rare13.nbt,5,CHEST:3,../../../Chests/Loot/Rare14.nbt,5,CHEST:3,../../../Chests/Loot/Rare15.nbt,5,CHEST:3,../../../Chests/Loot/ModernCityEpic_1.nbt,2,CHEST:3,../../../Chests/Loot/ModernCityEpic_2.nbt,2,CHEST:3,../../../Chests/Loot/ModernCityEpic_3.nbt,2,CHEST:3,../../../Chests/Loot/ModernCityEpic_4.nbt,2,CHEST:3,../../../Chests/Loot/ModernCityEpic_5.nbt,2,CHEST:3,../../../Chests/Loot/Epic6.nbt,2,CHEST:3,../../../Chests/Loot/Epic7.nbt,2,CHEST:3,../../../Chests/Loot/Epic8.nbt,2,CHEST:3,../../../Chests/Loot/Epic9.nbt,2,CHEST:3,../../../Chests/Loot/Epic10.nbt,2,CHEST:3,../../../Chests/Loot/Epic11.nbt,2,CHEST:3,../../../Chests/Loot/Epic12.nbt,2,CHEST:3,../../../Chests/Loot/Epic13.nbt,2,CHEST:3,../../../Chests/Loot/Epic14.nbt,2,CHEST:3,../../../Chests/Loot/Epic15.nbt,5,CHEST:3,../../../Chests/Loot/ModernCityRare_1.nbt,5,CHEST:3,../../../Chests/Loot/ModernCityRare_2.nbt,5,CHEST:3,../../../Chests/Loot/ModernCityRare_3.nbt,5,CHEST:3,../../../Chests/Loot/ModernCityRare_4.nbt,5,CHEST:3,../../../Chests/Loot/ModernCityRare_5.nbt,10,CHEST:3,../../../Chests/Loot/Rare6.nbt,10,CHEST:3,../../../Chests/Loot/Rare7.nbt,10,CHEST:3,../../../Chests/Loot/Rare8.nbt,10,CHEST:3,../../../Chests/Loot/Rare9.nbt,10,CHEST:3,../../../Chests/Loot/Rare10.nbt,15,CHEST:3,../../../Chests/Loot/Rare11.nbt,15,CHEST:3,../../../Chests/Loot/Rare12.nbt,15,CHEST:3,../../../Chests/Loot/Rare13.nbt,15,CHEST:3,../../../Chests/Loot/Rare14.nbt,15,CHEST:3,../../../Chests/Loot/Rare15.nbt,15,CHEST:3,../../../Chests/Loot/Epic15.nbt,100)
Block(-3,17,-5,AIR:0)
Block(-3,17,-4,AIR:0)
Block(-3,17,-3,AIR:0)
Block(-3,17,-2,AIR:0)
Block(-3,17,-1,AIR:0)
Block(-3,17,0,COBBLE_WALL:0)
Block(-3,17,1,COBBLE_WALL:0)
Block(-3,17,2,AIR:0)
Block(-3,17,3,AIR:0)
Block(-3,17,4,AIR:0)
Block(-3,17,5,AIR:0)
Block(-3,17,6,AIR:0)
Block(-3,17,7,AIR:0)
RandomBlock(-3,17,8,CONCRETE:7,70,STAINED_CLAY:12,15,STAINED_CLAY:15,5,CONCRETE:7,100)
RandomBlock(-3,18,-7,CONCRETE:7,70,STAINED_CLAY:12,15,STAINED_CLAY:15,5,CONCRETE:7,100)
Block(-3,18,-6,AIR:0)
Block(-3,18,-5,AIR:0)
Block(-3,18,-4,AIR:0)
Block(-3,18,-3,AIR:0)
Block(-3,18,-2,AIR:0)
Block(-3,18,-1,AIR:0)
Block(-3,18,0,COBBLE_WALL:0)
Block(-3,18,1,COBBLE_WALL:0)
Block(-3,18,2,AIR:0)
Block(-3,18,3,AIR:0)
Block(-3,18,4,AIR:0)
Block(-3,18,5,AIR:0)
Block(-3,18,6,AIR:0)
Block(-3,18,7,AIR:0)
RandomBlock(-3,18,8,CONCRETE:7,70,STAINED_CLAY:12,15,STAINED_CLAY:15,5,CONCRETE:7,100)
RandomBlock(-3,19,-7,CONCRETE:7,70,STAINED_CLAY:12,15,STAINED_CLAY:15,5,CONCRETE:7,100)
Block(-3,19,-6,AIR:0)
Block(-3,19,-5,AIR:0)
Block(-3,19,-4,AIR:0)
Block(-3,19,-3,AIR:0)
Block(-3,19,-2,AIR:0)
Block(-3,19,-1,AIR:0)
Block(-3,19,0,COBBLE_WALL:0)
Block(-3,19,1,COBBLE_WALL:0)
Block(-3,19,2,AIR:0)
Block(-3,19,3,AIR:0)
Block(-3,19,4,AIR:0)
Block(-3,19,5,AIR:0)
Block(-3,19,6,AIR:0)
Block(-3,19,7,AIR:0)
RandomBlock(-3,19,8,CONCRETE:7,70,STAINED_CLAY:12,15,STAINED_CLAY:15,5,CONCRETE:7,100)
RandomBlock(-3,20,-7,CONCRETE:7,70,STAINED_CLAY:12,15,STAINED_CLAY:15,5,CONCRETE:7,100)
Block(-3,20,-6,AIR:0)
Block(-3,20,-5,AIR:0)
Block(-3,20,-4,AIR:0)
Block(-3,20,-3,AIR:0)
Block(-3,20,-2,AIR:0)
Block(-3,20,-1,AIR:0)
Block(-3,20,0,COBBLE_WALL:0)
Block(-3,20,1,COBBLE_WALL:0)
Block(-3,20,2,AIR:0)
Block(-3,20,3,AIR:0)
Block(-3,20,4,AIR:0)
Block(-3,20,5,AIR:0)
Block(-3,20,6,AIR:0)
Block(-3,20,7,AIR:0)
RandomBlock(-3,20,8,CONCRETE:7,70,STAINED_CLAY:12,15,STAINED_CLAY:15,5,CONCRETE:7,100)
RandomBlock(-3,21,-7,CONCRETE:7,70,STAINED_CLAY:12,15,STAINED_CLAY:15,5,CONCRETE:7,100)
Block(-3,21,-6,AIR:0)
Block(-3,21,-5,AIR:0)
Block(-3,21,-4,AIR:0)
Block(-3,21,-3,AIR:0)
Block(-3,21,-2,AIR:0)
Block(-3,21,-1,AIR:0)
Block(-3,21,0,COBBLE_WALL:0)
Block(-3,21,1,COBBLE_WALL:0)
Block(-3,21,2,AIR:0)
Block(-3,21,3,AIR:0)
Block(-3,21,4,AIR:0)
Block(-3,21,5,AIR:0)
Block(-3,21,6,AIR:0)
Block(-3,21,7,AIR:0)
RandomBlock(-3,21,8,CONCRETE:7,70,STAINED_CLAY:12,15,STAINED_CLAY:15,5,CONCRETE:7,100)
Block(-3,22,-7,DOUBLE_STEP:0)
Block(-3,22,-6,STEP:8)
Block(-3,22,-5,STEP:8)
Block(-3,22,-4,STEP:8)
RandomBlock(-3,22,-3,CONCRETE:7,70,STAINED_CLAY:12,15,STAINED_CLAY:15,5,CONCRETE:7,100)
RandomBlock(-3,22,-2,CONCRETE:7,70,STAINED_CLAY:12,15,STAINED_CLAY:15,5,CONCRETE:7,100)
Block(-3,22,-1,AIR:0)
Block(-3,22,0,COBBLE_WALL:0)
Block(-3,22,1,COBBLE_WALL:0)
Block(-3,22,2,AIR:0)
RandomBlock(-3,22,3,CONCRETE:7,70,STAINED_CLAY:12,15,STAINED_CLAY:15,5,CONCRETE:7,100)
RandomBlock(-3,22,4,CONCRETE:7,70,STAINED_CLAY:12,15,STAINED_CLAY:15,5,CONCRETE:7,100)
Block(-3,22,5,STEP:8)
Block(-3,22,6,STEP:8)
Block(-3,22,7,STEP:8)
Block(-3,22,8,DOUBLE_STEP:0)
Block(-3,23,-2,SMOOTH_STAIRS:2)
Block(-3,23,-1,AIR:0)
Block(-3,23,0,COBBLE_WALL:0)
Block(-3,23,1,COBBLE_WALL:0)
Block(-3,23,2,AIR:0)
Block(-3,23,3,SMOOTH_STAIRS:3)
Block(-3,24,-2,SMOOTH_STAIRS:2)
Block(-3,24,-1,AIR:0)
Block(-3,24,0,COBBLE_WALL:0)
Block(-3,24,1,COBBLE_WALL:0)
Block(-3,24,2,AIR:0)
Block(-3,24,3,SMOOTH_STAIRS:3)
Block(-3,25,-2,SMOOTH_STAIRS:2)
Block(-3,25,-1,AIR:0)
Block(-3,25,0,AIR:0)
Block(-3,25,1,AIR:0)
Block(-3,25,2,AIR:0)
Block(-3,25,3,SMOOTH_STAIRS:3)
RandomBlock(-3,26,-2,CONCRETE:7,70,STAINED_CLAY:12,15,STAINED_CLAY:15,5,CONCRETE:7,100)
Block(-3,26,-1,STEP:8)
Block(-3,26,0,STEP:8)
Block(-3,26,1,STEP:8)
Block(-3,26,2,STEP:8)
RandomBlock(-3,26,3,CONCRETE:7,70,STAINED_CLAY:12,15,STAINED_CLAY:15,5,CONCRETE:7,100)
RandomBlock(-2,0,-2,CONCRETE:7,70,STAINED_CLAY:12,15,STAINED_CLAY:15,5,CONCRETE:7,100)
Block(-2,0,-1,AIR:0)
Block(-2,0,0,AIR:0)
Block(-2,0,1,AIR:0)
Block(-2,0,2,AIR:0)
RandomBlock(-2,0,3,CONCRETE:7,70,STAINED_CLAY:12,15,STAINED_CLAY:15,5,CONCRETE:7,100)
RandomBlock(-2,11,-2,CONCRETE:7,70,STAINED_CLAY:12,15,STAINED_CLAY:15,5,CONCRETE:7,100)
Block(-2,11,-1,AIR:0)
Block(-2,11,0,AIR:0)
Block(-2,11,1,AIR:0)
Block(-2,11,2,AIR:0)
Block(-2,11,3,CONCRETE:0)
RandomBlock(-2,12,-2,CONCRETE:7,70,STAINED_CLAY:12,15,STAINED_CLAY:15,5,CONCRETE:7,100)
Block(-2,12,-1,AIR:0)
Block(-2,12,0,AIR:0)
Block(-2,12,1,AIR:0)
Block(-2,12,2,AIR:0)
Block(-2,12,3,CONCRETE:0)
RandomBlock(-2,13,-2,CONCRETE:7,70,STAINED_CLAY:12,15,STAINED_CLAY:15,5,CONCRETE:7,100)
Block(-2,13,-1,AIR:0)
Block(-2,13,0,AIR:0)
Block(-2,13,1,AIR:0)
Block(-2,13,2,AIR:0)
Block(-2,13,3,CONCRETE:0)
Block(-2,14,-6,CONCRETE:15)
Block(-2,14,-4,CONCRETE:15)
Block(-2,14,-2,CONCRETE:0)
Block(-2,14,-1,AIR:0)
Block(-2,14,0,AIR:0)
Block(-2,14,1,AIR:0)
Block(-2,14,2,AIR:0)
Block(-2,14,3,CONCRETE:0)
Block(-2,14,5,CONCRETE:15)
Block(-2,14,7,CONCRETE:15)
RandomBlock(-2,15,-7,CONCRETE:7,70,STAINED_CLAY:12,15,STAINED_CLAY:15,5,CONCRETE:7,100)
RandomBlock(-2,15,-6,CONCRETE:7,70,STAINED_CLAY:12,15,STAINED_CLAY:15,5,CONCRETE:7,100)
Block(-2,15,-5,STAINED_CLAY:9)
Block(-2,15,-4,STAINED_CLAY:9)
Block(-2,15,-3,STAINED_CLAY:9)
RandomBlock(-2,15,-2,CONCRETE:7,70,STAINED_CLAY:12,15,STAINED_CLAY:15,5,CONCRETE:7,100)
Block(-2,15,-1,AIR:0)
Block(-2,15,0,AIR:0)
Block(-2,15,1,AIR:0)
Block(-2,15,2,AIR:0)
RandomBlock(-2,15,3,CONCRETE:7,70,STAINED_CLAY:12,15,STAINED_CLAY:15,5,CONCRETE:7,100)
Block(-2,15,4,STAINED_CLAY:9)
Block(-2,15,5,STAINED_CLAY:9)
Block(-2,15,6,STAINED_CLAY:9)
RandomBlock(-2,15,7,CONCRETE:7,70,STAINED_CLAY:12,15,STAINED_CLAY:15,5,CONCRETE:7,100)
RandomBlock(-2,15,8,CONCRETE:7,70,STAINED_CLAY:12,15,STAINED_CLAY:15,5,CONCRETE:7,100)
RandomBlock(-2,16,-7,CONCRETE:7,70,STAINED_CLAY:12,15,STAINED_CLAY:15,5,CONCRETE:7,100)
Block(-2,16,-6,STEP:8)
Block(-2,16,-5,AIR:0)
Block(-2,16,-4,AIR:0)
Block(-2,16,-3,AIR:0)
Block(-2,16,-2,IRON_FENCE:0)
Block(-2,16,-1,AIR:0)
Block(-2,16,0,AIR:0)
Block(-2,16,1,AIR:0)
Block(-2,16,2,AIR:0)
Block(-2,16,3,IRON_FENCE:0)
Block(-2,16,4,AIR:0)
Block(-2,16,5,AIR:0)
Block(-2,16,6,AIR:0)
Block(-2,16,7,STEP:8)
RandomBlock(-2,16,8,CONCRETE:7,70,STAINED_CLAY:12,15,STAINED_CLAY:15,5,CONCRETE:7,100)
RandomBlock(-2,17,-7,CONCRETE:7,70,STAINED_CLAY:12,15,STAINED_CLAY:15,5,CONCRETE:7,100)
Block(-2,17,-6,AIR:0)
Block(-2,17,-5,AIR:0)
Block(-2,17,-4,AIR:0)
Block(-2,17,-3,AIR:0)
Block(-2,17,-2,AIR:0)
Block(-2,17,-1,AIR:0)
Block(-2,17,0,AIR:0)
Block(-2,17,1,AIR:0)
Block(-2,17,2,AIR:0)
Block(-2,17,3,AIR:0)
Block(-2,17,4,AIR:0)
Block(-2,17,5,AIR:0)
Block(-2,17,6,AIR:0)
Block(-2,17,7,AIR:0)
RandomBlock(-2,17,8,CONCRETE:7,70,STAINED_CLAY:12,15,STAINED_CLAY:15,5,CONCRETE:7,100)
RandomBlock(-2,18,-7,CONCRETE:7,70,STAINED_CLAY:12,15,STAINED_CLAY:15,5,CONCRETE:7,100)
Block(-2,18,-6,AIR:0)
Block(-2,18,-5,AIR:0)
Block(-2,18,-4,AIR:0)
Block(-2,18,-3,AIR:0)
Block(-2,18,-2,AIR:0)
Block(-2,18,-1,AIR:0)
Block(-2,18,0,AIR:0)
Block(-2,18,1,AIR:0)
Block(-2,18,2,AIR:0)
Block(-2,18,3,AIR:0)
Block(-2,18,4,AIR:0)
Block(-2,18,5,AIR:0)
Block(-2,18,6,AIR:0)
Block(-2,18,7,AIR:0)
RandomBlock(-2,18,8,CONCRETE:7,70,STAINED_CLAY:12,15,STAINED_CLAY:15,5,CONCRETE:7,100)
RandomBlock(-2,19,-7,CONCRETE:7,70,STAINED_CLAY:12,15,STAINED_CLAY:15,5,CONCRETE:7,100)
Block(-2,19,-6,AIR:0)
Block(-2,19,-5,AIR:0)
Block(-2,19,-4,AIR:0)
Block(-2,19,-3,AIR:0)
Block(-2,19,-2,AIR:0)
Block(-2,19,-1,AIR:0)
Block(-2,19,0,AIR:0)
Block(-2,19,1,AIR:0)
Block(-2,19,2,AIR:0)
Block(-2,19,3,AIR:0)
Block(-2,19,4,AIR:0)
Block(-2,19,5,AIR:0)
Block(-2,19,6,AIR:0)
Block(-2,19,7,AIR:0)
RandomBlock(-2,19,8,CONCRETE:7,70,STAINED_CLAY:12,15,STAINED_CLAY:15,5,CONCRETE:7,100)
RandomBlock(-2,20,-7,CONCRETE:7,70,STAINED_CLAY:12,15,STAINED_CLAY:15,5,CONCRETE:7,100)
Block(-2,20,-6,AIR:0)
Block(-2,20,-5,AIR:0)
Block(-2,20,-4,AIR:0)
Block(-2,20,-3,AIR:0)
Block(-2,20,-2,AIR:0)
Block(-2,20,-1,AIR:0)
Block(-2,20,0,AIR:0)
Block(-2,20,1,AIR:0)
Block(-2,20,2,AIR:0)
Block(-2,20,3,AIR:0)
Block(-2,20,4,AIR:0)
Block(-2,20,5,AIR:0)
Block(-2,20,6,AIR:0)
Block(-2,20,7,AIR:0)
RandomBlock(-2,20,8,CONCRETE:7,70,STAINED_CLAY:12,15,STAINED_CLAY:15,5,CONCRETE:7,100)
RandomBlock(-2,21,-7,CONCRETE:7,70,STAINED_CLAY:12,15,STAINED_CLAY:15,5,CONCRETE:7,100)
Block(-2,21,-6,AIR:0)
Block(-2,21,-5,AIR:0)
Block(-2,21,-4,AIR:0)
Block(-2,21,-3,AIR:0)
Block(-2,21,-2,AIR:0)
Block(-2,21,-1,AIR:0)
Block(-2,21,0,AIR:0)
Block(-2,21,1,AIR:0)
Block(-2,21,2,AIR:0)
Block(-2,21,3,AIR:0)
Block(-2,21,4,AIR:0)
Block(-2,21,5,AIR:0)
Block(-2,21,6,AIR:0)
Block(-2,21,7,AIR:0)
RandomBlock(-2,21,8,CONCRETE:7,70,STAINED_CLAY:12,15,STAINED_CLAY:15,5,CONCRETE:7,100)
Block(-2,22,-7,DOUBLE_STEP:0)
Block(-2,22,-6,STEP:8)
Block(-2,22,-5,STEP:8)
Block(-2,22,-4,STEP:8)
RandomBlock(-2,22,-3,CONCRETE:7,70,STAINED_CLAY:12,15,STAINED_CLAY:15,5,CONCRETE:7,100)
RandomBlock(-2,22,-2,CONCRETE:7,70,STAINED_CLAY:12,15,STAINED_CLAY:15,5,CONCRETE:7,100)
Block(-2,22,-1,AIR:0)
Block(-2,22,0,QUARTZ_STAIRS:4)
Block(-2,22,1,QUARTZ_STAIRS:4)
Block(-2,22,2,AIR:0)
RandomBlock(-2,22,3,CONCRETE:7,70,STAINED_CLAY:12,15,STAINED_CLAY:15,5,CONCRETE:7,100)
RandomBlock(-2,22,4,CONCRETE:7,70,STAINED_CLAY:12,15,STAINED_CLAY:15,5,CONCRETE:7,100)
Block(-2,22,5,STEP:8)
Block(-2,22,6,STEP:8)
Block(-2,22,7,STEP:8)
Block(-2,22,8,DOUBLE_STEP:0)
Block(-2,23,-2,SMOOTH_STAIRS:2)
Block(-2,23,-1,AIR:0)
Block(-2,23,0,ANVIL:10)
Block(-2,23,1,ANVIL:10)
Block(-2,23,2,AIR:0)
Block(-2,23,3,SMOOTH_STAIRS:3)
Block(-2,24,-2,SMOOTH_STAIRS:2)
Block(-2,24,-1,AIR:0)
Block(-2,24,0,COBBLE_WALL:0)
Block(-2,24,1,COBBLE_WALL:0)
Block(-2,24,2,AIR:0)
Block(-2,24,3,SMOOTH_STAIRS:3)
Block(-2,25,-2,SMOOTH_STAIRS:2)
Block(-2,25,-1,AIR:0)
Block(-2,25,0,AIR:0)
Block(-2,25,1,AIR:0)
Block(-2,25,2,AIR:0)
Block(-2,25,3,SMOOTH_STAIRS:3)
RandomBlock(-2,26,-2,CONCRETE:7,70,STAINED_CLAY:12,15,STAINED_CLAY:15,5,CONCRETE:7,100)
Block(-2,26,-1,STEP:8)
Block(-2,26,0,STEP:8)
Block(-2,26,1,STEP:8)
Block(-2,26,2,STEP:8)
RandomBlock(-2,26,3,CONCRETE:7,70,STAINED_CLAY:12,15,STAINED_CLAY:15,5,CONCRETE:7,100)
Block(-1,0,-6,CONCRETE:15)
Block(-1,0,-4,CONCRETE:15)
RandomBlock(-1,0,-2,CONCRETE:7,70,STAINED_CLAY:12,15,STAINED_CLAY:15,5,CONCRETE:7,100)
Block(-1,0,-1,AIR:0)
Block(-1,0,0,AIR:0)
Block(-1,0,1,AIR:0)
Block(-1,0,2,AIR:0)
RandomBlock(-1,0,3,CONCRETE:7,70,STAINED_CLAY:12,15,STAINED_CLAY:15,5,CONCRETE:7,100)
Block(-1,0,5,CONCRETE:15)
Block(-1,0,7,CONCRETE:15)
Block(-1,11,-6,CONCRETE:15)
Block(-1,11,-4,CONCRETE:15)
RandomBlock(-1,11,-2,CONCRETE:7,70,STAINED_CLAY:12,15,STAINED_CLAY:15,5,CONCRETE:7,100)
Block(-1,11,-1,AIR:0)
Block(-1,11,0,AIR:0)
Block(-1,11,1,AIR:0)
Block(-1,11,2,AIR:0)
RandomBlock(-1,11,3,CONCRETE:7,70,STAINED_CLAY:12,15,STAINED_CLAY:15,5,CONCRETE:7,100)
Block(-1,11,5,CONCRETE:15)
Block(-1,11,7,CONCRETE:15)
Block(-1,12,-6,CONCRETE:15)
Block(-1,12,-4,CONCRETE:15)
RandomBlock(-1,12,-2,CONCRETE:7,70,STAINED_CLAY:12,15,STAINED_CLAY:15,5,CONCRETE:7,100)
Block(-1,12,-1,AIR:0)
Block(-1,12,0,AIR:0)
Block(-1,12,1,AIR:0)
Block(-1,12,2,AIR:0)
RandomBlock(-1,12,3,CONCRETE:7,70,STAINED_CLAY:12,15,STAINED_CLAY:15,5,CONCRETE:7,100)
Block(-1,12,5,CONCRETE:15)
Block(-1,12,7,CONCRETE:15)
Block(-1,13,-6,CONCRETE:15)
Block(-1,13,-4,CONCRETE:15)
RandomBlock(-1,13,-2,CONCRETE:7,70,STAINED_CLAY:12,15,STAINED_CLAY:15,5,CONCRETE:7,100)
Block(-1,13,-1,AIR:0)
Block(-1,13,0,AIR:0)
Block(-1,13,1,AIR:0)
Block(-1,13,2,AIR:0)
RandomBlock(-1,13,3,CONCRETE:7,70,STAINED_CLAY:12,15,STAINED_CLAY:15,5,CONCRETE:7,100)
Block(-1,13,5,CONCRETE:15)
Block(-1,13,7,CONCRETE:15)
Block(-1,14,-6,CONCRETE:15)
Block(-1,14,-4,CONCRETE:15)
RandomBlock(-1,14,-2,CONCRETE:7,70,STAINED_CLAY:12,15,STAINED_CLAY:15,5,CONCRETE:7,100)
Block(-1,14,-1,AIR:0)
Block(-1,14,0,AIR:0)
Block(-1,14,1,AIR:0)
Block(-1,14,2,AIR:0)
RandomBlock(-1,14,3,CONCRETE:7,70,STAINED_CLAY:12,15,STAINED_CLAY:15,5,CONCRETE:7,100)
Block(-1,14,5,CONCRETE:15)
Block(-1,14,7,CONCRETE:15)
RandomBlock(-1,15,-7,CONCRETE:7,70,STAINED_CLAY:12,15,STAINED_CLAY:15,5,CONCRETE:7,100)
RandomBlock(-1,15,-6,CONCRETE:7,70,STAINED_CLAY:12,15,STAINED_CLAY:15,5,CONCRETE:7,100)
Block(-1,15,-5,STAINED_CLAY:9)
Block(-1,15,-4,STAINED_CLAY:9)
Block(-1,15,-3,STAINED_CLAY:9)
RandomBlock(-1,15,-2,CONCRETE:7,70,STAINED_CLAY:12,15,STAINED_CLAY:15,5,CONCRETE:7,100)
Block(-1,15,-1,AIR:0)
Block(-1,15,0,AIR:0)
Block(-1,15,1,AIR:0)
Block(-1,15,2,AIR:0)
RandomBlock(-1,15,3,CONCRETE:7,70,STAINED_CLAY:12,15,STAINED_CLAY:15,5,CONCRETE:7,100)
Block(-1,15,4,STAINED_CLAY:9)
Block(-1,15,5,STAINED_CLAY:9)
Block(-1,15,6,STAINED_CLAY:9)
RandomBlock(-1,15,7,CONCRETE:7,70,STAINED_CLAY:12,15,STAINED_CLAY:15,5,CONCRETE:7,100)
RandomBlock(-1,15,8,CONCRETE:7,70,STAINED_CLAY:12,15,STAINED_CLAY:15,5,CONCRETE:7,100)
RandomBlock(-1,16,-7,CONCRETE:7,70,STAINED_CLAY:12,15,STAINED_CLAY:15,5,CONCRETE:7,100)
Block(-1,16,-6,STEP:8)
Block(-1,16,-5,AIR:0)
Block(-1,16,-4,AIR:0)
Block(-1,16,-3,AIR:0)
Block(-1,16,-2,IRON_FENCE:0)
Block(-1,16,-1,AIR:0)
Block(-1,16,0,AIR:0)
Block(-1,16,1,AIR:0)
Block(-1,16,2,AIR:0)
Block(-1,16,3,IRON_FENCE:0)
Block(-1,16,4,AIR:0)
Block(-1,16,5,AIR:0)
Block(-1,16,6,AIR:0)
Block(-1,16,7,STEP:8)
RandomBlock(-1,16,8,CONCRETE:7,70,STAINED_CLAY:12,15,STAINED_CLAY:15,5,CONCRETE:7,100)
RandomBlock(-1,17,-7,CONCRETE:7,70,STAINED_CLAY:12,15,STAINED_CLAY:15,5,CONCRETE:7,100)
Block(-1,17,-6,AIR:0)
Block(-1,17,-5,AIR:0)
Block(-1,17,-4,AIR:0)
Block(-1,17,-3,AIR:0)
Block(-1,17,-2,AIR:0)
Block(-1,17,-1,AIR:0)
Block(-1,17,0,AIR:0)
Block(-1,17,1,AIR:0)
Block(-1,17,2,AIR:0)
Block(-1,17,3,AIR:0)
Block(-1,17,4,AIR:0)
Block(-1,17,5,AIR:0)
Block(-1,17,6,AIR:0)
RandomBlock(-1,17,7,CHEST:2,../../../Chests/Lore/ModernCity_1.nbt,1,CHEST:2,../../../Chests/Lore/ModernCity_2.nbt,1,CHEST:2,../../../Chests/Lore/ModernCity_3.nbt,1,CHEST:2,../../../Chests/Lore/ModernCity_4.nbt,1,CHEST:2,../../../Chests/Lore/ModernCity_5.nbt,1,CHEST:2,../../../Chests/Loot/ModernCityCommon1.nbt,5,CHEST:2,../../../Chests/Loot/ModernCityCommon2.nbt,5,CHEST:2,../../../Chests/Loot/ModernCityCommon3.nbt,5,CHEST:2,../../../Chests/Loot/ModernCityCommon4.nbt,5,CHEST:2,../../../Chests/Loot/ModernCityCommon5.nbt,5,CHEST:2,../../../Chests/Loot/Common6.nbt,5,CHEST:2,../../../Chests/Loot/Common7.nbt,5,CHEST:2,../../../Chests/Loot/Common8.nbt,5,CHEST:2,../../../Chests/Loot/Common9.nbt,5,CHEST:2,../../../Chests/Loot/ModernCityCommon10.nbt,5,CHEST:2,../../../Chests/Loot/ModernCityCommon11.nbt,5,CHEST:2,../../../Chests/Loot/ModernCityCommon12.nbt,5,CHEST:2,../../../Chests/Loot/ModernCityCommon13.nbt,5,CHEST:2,../../../Chests/Loot/ModernCityCommon14.nbt,5,CHEST:2,../../../Chests/Loot/ModernCityCommon15.nbt,5,CHEST:2,../../../Chests/Lore/ModernCity_1.nbt,2,CHEST:2,../../../Chests/Lore/ModernCity_2.nbt,2,CHEST:2,../../../Chests/Lore/ModernCity_3.nbt,2,CHEST:2,../../../Chests/Lore/ModernCity_4.nbt,2,CHEST:2,../../../Chests/Lore/ModernCity_5.nbt,2,CHEST:2,../../../Chests/Loot/ModernCityRare_1.nbt,5,CHEST:2,../../../Chests/Loot/ModernCityRare_2.nbt,5,CHEST:2,../../../Chests/Loot/ModernCityRare_3.nbt,5,CHEST:2,../../../Chests/Loot/ModernCityRare_4.nbt,5,CHEST:2,../../../Chests/Loot/ModernCityRare_5.nbt,5,CHEST:2,../../../Chests/Loot/Rare6.nbt,5,CHEST:2,../../../Chests/Loot/Rare7.nbt,5,CHEST:2,../../../Chests/Loot/Rare8.nbt,5,CHEST:2,../../../Chests/Loot/Rare9.nbt,5,CHEST:2,../../../Chests/Loot/Rare10.nbt,5,CHEST:2,../../../Chests/Loot/Rare11.nbt,5,CHEST:2,../../../Chests/Loot/Rare12.nbt,5,CHEST:2,../../../Chests/Loot/Rare13.nbt,5,CHEST:2,../../../Chests/Loot/Rare14.nbt,5,CHEST:2,../../../Chests/Loot/Rare15.nbt,5,CHEST:2,../../../Chests/Loot/ModernCityEpic_1.nbt,2,CHEST:2,../../../Chests/Loot/ModernCityEpic_2.nbt,2,CHEST:2,../../../Chests/Loot/ModernCityEpic_3.nbt,2,CHEST:2,../../../Chests/Loot/ModernCityEpic_4.nbt,2,CHEST:2,../../../Chests/Loot/ModernCityEpic_5.nbt,2,CHEST:2,../../../Chests/Loot/Epic6.nbt,2,CHEST:2,../../../Chests/Loot/Epic7.nbt,2,CHEST:2,../../../Chests/Loot/Epic8.nbt,2,CHEST:2,../../../Chests/Loot/Epic9.nbt,2,CHEST:2,../../../Chests/Loot/Epic10.nbt,2,CHEST:2,../../../Chests/Loot/Epic11.nbt,2,CHEST:2,../../../Chests/Loot/Epic12.nbt,2,CHEST:2,../../../Chests/Loot/Epic13.nbt,2,CHEST:2,../../../Chests/Loot/Epic14.nbt,2,CHEST:2,../../../Chests/Loot/Epic15.nbt,5,CHEST:2,../../../Chests/Loot/ModernCityRare_1.nbt,5,CHEST:2,../../../Chests/Loot/ModernCityRare_2.nbt,5,CHEST:2,../../../Chests/Loot/ModernCityRare_3.nbt,5,CHEST:2,../../../Chests/Loot/ModernCityRare_4.nbt,5,CHEST:2,../../../Chests/Loot/ModernCityRare_5.nbt,10,CHEST:2,../../../Chests/Loot/Rare6.nbt,10,CHEST:2,../../../Chests/Loot/Rare7.nbt,10,CHEST:2,../../../Chests/Loot/Rare8.nbt,10,CHEST:2,../../../Chests/Loot/Rare9.nbt,10,CHEST:2,../../../Chests/Loot/Rare10.nbt,15,CHEST:2,../../../Chests/Loot/Rare11.nbt,15,CHEST:2,../../../Chests/Loot/Rare12.nbt,15,CHEST:2,../../../Chests/Loot/Rare13.nbt,15,CHEST:2,../../../Chests/Loot/Rare14.nbt,15,CHEST:2,../../../Chests/Loot/Rare15.nbt,15,CHEST:2,../../../Chests/Loot/Epic15.nbt,100)
RandomBlock(-1,17,8,CONCRETE:7,70,STAINED_CLAY:12,15,STAINED_CLAY:15,5,CONCRETE:7,100)
RandomBlock(-1,18,-7,CONCRETE:7,70,STAINED_CLAY:12,15,STAINED_CLAY:15,5,CONCRETE:7,100)
Block(-1,18,-6,AIR:0)
Block(-1,18,-5,AIR:0)
Block(-1,18,-4,AIR:0)
Block(-1,18,-3,AIR:0)
Block(-1,18,-2,AIR:0)
Block(-1,18,-1,AIR:0)
Block(-1,18,0,AIR:0)
Block(-1,18,1,AIR:0)
Block(-1,18,2,AIR:0)
Block(-1,18,3,AIR:0)
Block(-1,18,4,AIR:0)
Block(-1,18,5,AIR:0)
Block(-1,18,6,AIR:0)
Block(-1,18,7,AIR:0)
RandomBlock(-1,18,8,CONCRETE:7,70,STAINED_CLAY:12,15,STAINED_CLAY:15,5,CONCRETE:7,100)
RandomBlock(-1,19,-7,CONCRETE:7,70,STAINED_CLAY:12,15,STAINED_CLAY:15,5,CONCRETE:7,100)
Block(-1,19,-6,AIR:0)
Block(-1,19,-5,AIR:0)
Block(-1,19,-4,AIR:0)
Block(-1,19,-3,AIR:0)
Block(-1,19,-2,AIR:0)
Block(-1,19,-1,AIR:0)
Block(-1,19,0,AIR:0)
Block(-1,19,1,AIR:0)
Block(-1,19,2,AIR:0)
Block(-1,19,3,AIR:0)
Block(-1,19,4,AIR:0)
Block(-1,19,5,AIR:0)
Block(-1,19,6,AIR:0)
Block(-1,19,7,AIR:0)
RandomBlock(-1,19,8,CONCRETE:7,70,STAINED_CLAY:12,15,STAINED_CLAY:15,5,CONCRETE:7,100)
RandomBlock(-1,20,-7,CONCRETE:7,70,STAINED_CLAY:12,15,STAINED_CLAY:15,5,CONCRETE:7,100)
Block(-1,20,-6,AIR:0)
Block(-1,20,-5,AIR:0)
Block(-1,20,-4,AIR:0)
Block(-1,20,-3,AIR:0)
Block(-1,20,-2,AIR:0)
Block(-1,20,-1,AIR:0)
Block(-1,20,0,AIR:0)
Block(-1,20,1,AIR:0)
Block(-1,20,2,AIR:0)
Block(-1,20,3,AIR:0)
Block(-1,20,4,AIR:0)
Block(-1,20,5,AIR:0)
Block(-1,20,6,AIR:0)
Block(-1,20,7,AIR:0)
RandomBlock(-1,20,8,CONCRETE:7,70,STAINED_CLAY:12,15,STAINED_CLAY:15,5,CONCRETE:7,100)
RandomBlock(-1,21,-7,CONCRETE:7,70,STAINED_CLAY:12,15,STAINED_CLAY:15,5,CONCRETE:7,100)
Block(-1,21,-6,AIR:0)
Block(-1,21,-5,AIR:0)
Block(-1,21,-4,AIR:0)
Block(-1,21,-3,AIR:0)
Block(-1,21,-2,AIR:0)
Block(-1,21,-1,AIR:0)
Block(-1,21,0,AIR:0)
Block(-1,21,1,AIR:0)
Block(-1,21,2,AIR:0)
Block(-1,21,3,AIR:0)
Block(-1,21,4,AIR:0)
Block(-1,21,5,AIR:0)
Block(-1,21,6,AIR:0)
Block(-1,21,7,AIR:0)
RandomBlock(-1,21,8,CONCRETE:7,70,STAINED_CLAY:12,15,STAINED_CLAY:15,5,CONCRETE:7,100)
Block(-1,22,-7,DOUBLE_STEP:0)
Block(-1,22,-6,STEP:8)
Block(-1,22,-5,STEP:8)
Block(-1,22,-4,STEP:8)
RandomBlock(-1,22,-3,CONCRETE:7,70,STAINED_CLAY:12,15,STAINED_CLAY:15,5,CONCRETE:7,100)
RandomBlock(-1,22,-2,CONCRETE:7,70,STAINED_CLAY:12,15,STAINED_CLAY:15,5,CONCRETE:7,100)
Block(-1,22,-1,AIR:0)
RandomBlock(-1,22,0,CONCRETE:7,70,STAINED_CLAY:12,15,STAINED_CLAY:15,5,CONCRETE:7,100)
RandomBlock(-1,22,1,CONCRETE:7,70,STAINED_CLAY:12,15,STAINED_CLAY:15,5,CONCRETE:7,100)
Block(-1,22,2,AIR:0)
RandomBlock(-1,22,3,CONCRETE:7,70,STAINED_CLAY:12,15,STAINED_CLAY:15,5,CONCRETE:7,100)
RandomBlock(-1,22,4,CONCRETE:7,70,STAINED_CLAY:12,15,STAINED_CLAY:15,5,CONCRETE:7,100)
Block(-1,22,5,STEP:8)
Block(-1,22,6,STEP:8)
Block(-1,22,7,STEP:8)
Block(-1,22,8,DOUBLE_STEP:0)
Block(-1,23,-2,SMOOTH_STAIRS:2)
Block(-1,23,-1,AIR:0)
Block(-1,23,0,AIR:0)
Block(-1,23,1,AIR:0)
Block(-1,23,2,AIR:0)
Block(-1,23,3,SMOOTH_STAIRS:3)
Block(-1,24,-2,SMOOTH_STAIRS:2)
Block(-1,24,-1,AIR:0)
Block(-1,24,0,COBBLE_WALL:0)
Block(-1,24,1,COBBLE_WALL:0)
Block(-1,24,2,AIR:0)
Block(-1,24,3,SMOOTH_STAIRS:3)
Block(-1,25,-2,SMOOTH_STAIRS:2)
Block(-1,25,-1,AIR:0)
Block(-1,25,0,AIR:0)
Block(-1,25,1,AIR:0)
Block(-1,25,2,AIR:0)
Block(-1,25,3,SMOOTH_STAIRS:3)
RandomBlock(-1,26,-2,CONCRETE:7,70,STAINED_CLAY:12,15,STAINED_CLAY:15,5,CONCRETE:7,100)
Block(-1,26,-1,STEP:8)
Block(-1,26,0,STEP:8)
Block(-1,26,1,STEP:8)
Block(-1,26,2,STEP:8)
RandomBlock(-1,26,3,CONCRETE:7,70,STAINED_CLAY:12,15,STAINED_CLAY:15,5,CONCRETE:7,100)
RandomBlock(0,0,-2,CONCRETE:7,70,STAINED_CLAY:12,15,STAINED_CLAY:15,5,CONCRETE:7,100)
RandomBlock(0,0,-1,CONCRETE:7,70,STAINED_CLAY:12,15,STAINED_CLAY:15,5,CONCRETE:7,100)
RandomBlock(0,0,0,CONCRETE:7,70,STAINED_CLAY:12,15,STAINED_CLAY:15,5,CONCRETE:7,100)
RandomBlock(0,0,1,CONCRETE:7,70,STAINED_CLAY:12,15,STAINED_CLAY:15,5,CONCRETE:7,100)
RandomBlock(0,0,2,CONCRETE:7,70,STAINED_CLAY:12,15,STAINED_CLAY:15,5,CONCRETE:7,100)
RandomBlock(0,0,3,CONCRETE:7,70,STAINED_CLAY:12,15,STAINED_CLAY:15,5,CONCRETE:7,100)
RandomBlock(0,11,-2,CONCRETE:7,70,STAINED_CLAY:12,15,STAINED_CLAY:15,5,CONCRETE:7,100)
RandomBlock(0,11,-1,CONCRETE:7,70,STAINED_CLAY:12,15,STAINED_CLAY:15,5,CONCRETE:7,100)
RandomBlock(0,11,0,CONCRETE:7,70,STAINED_CLAY:12,15,STAINED_CLAY:15,5,CONCRETE:7,100)
RandomBlock(0,11,1,CONCRETE:7,70,STAINED_CLAY:12,15,STAINED_CLAY:15,5,CONCRETE:7,100)
RandomBlock(0,11,2,CONCRETE:7,70,STAINED_CLAY:12,15,STAINED_CLAY:15,5,CONCRETE:7,100)
RandomBlock(0,11,3,CONCRETE:7,70,STAINED_CLAY:12,15,STAINED_CLAY:15,5,CONCRETE:7,100)
RandomBlock(0,12,-2,CONCRETE:7,70,STAINED_CLAY:12,15,STAINED_CLAY:15,5,CONCRETE:7,100)
Block(0,12,-1,IRON_FENCE:0)
Block(0,12,0,IRON_FENCE:0)
Block(0,12,1,IRON_FENCE:0)
Block(0,12,2,IRON_FENCE:0)
RandomBlock(0,12,3,CONCRETE:7,70,STAINED_CLAY:12,15,STAINED_CLAY:15,5,CONCRETE:7,100)
RandomBlock(0,13,-2,CONCRETE:7,70,STAINED_CLAY:12,15,STAINED_CLAY:15,5,CONCRETE:7,100)
Block(0,13,-1,IRON_FENCE:0)
Block(0,13,0,IRON_FENCE:0)
Block(0,13,1,IRON_FENCE:0)
Block(0,13,2,IRON_FENCE:0)
RandomBlock(0,13,3,CONCRETE:7,70,STAINED_CLAY:12,15,STAINED_CLAY:15,5,CONCRETE:7,100)
Block(0,14,-6,CONCRETE:15)
Block(0,14,-4,CONCRETE:15)
RandomBlock(0,14,-2,CONCRETE:7,70,STAINED_CLAY:12,15,STAINED_CLAY:15,5,CONCRETE:7,100)
Block(0,14,-1,STEP:0)
Block(0,14,0,STEP:0)
Block(0,14,1,STEP:0)
Block(0,14,2,STEP:0)
RandomBlock(0,14,3,CONCRETE:7,70,STAINED_CLAY:12,15,STAINED_CLAY:15,5,CONCRETE:7,100)
Block(0,14,5,CONCRETE:15)
Block(0,14,7,CONCRETE:15)
RandomBlock(0,15,-7,CONCRETE:7,70,STAINED_CLAY:12,15,STAINED_CLAY:15,5,CONCRETE:7,100)
RandomBlock(0,15,-6,CONCRETE:7,70,STAINED_CLAY:12,15,STAINED_CLAY:15,5,CONCRETE:7,100)
Block(0,15,-5,STAINED_CLAY:9)
Block(0,15,-4,STAINED_CLAY:9)
Block(0,15,-3,STAINED_CLAY:9)
RandomBlock(0,15,-2,CONCRETE:7,70,STAINED_CLAY:12,15,STAINED_CLAY:15,5,CONCRETE:7,100)
Block(0,15,-1,AIR:0)
Block(0,15,0,AIR:0)
Block(0,15,1,AIR:0)
Block(0,15,2,AIR:0)
RandomBlock(0,15,3,CONCRETE:7,70,STAINED_CLAY:12,15,STAINED_CLAY:15,5,CONCRETE:7,100)
Block(0,15,4,STAINED_CLAY:9)
Block(0,15,5,STAINED_CLAY:9)
Block(0,15,6,STAINED_CLAY:9)
RandomBlock(0,15,7,CONCRETE:7,70,STAINED_CLAY:12,15,STAINED_CLAY:15,5,CONCRETE:7,100)
RandomBlock(0,15,8,CONCRETE:7,70,STAINED_CLAY:12,15,STAINED_CLAY:15,5,CONCRETE:7,100)
RandomBlock(0,16,-7,CONCRETE:7,70,STAINED_CLAY:12,15,STAINED_CLAY:15,5,CONCRETE:7,100)
RandomBlock(0,16,-6,CONCRETE:7,70,STAINED_CLAY:12,15,STAINED_CLAY:15,5,CONCRETE:7,100)
Block(0,16,-5,AIR:0)
Block(0,16,-4,AIR:0)
Block(0,16,-3,AIR:0)
RandomBlock(0,16,-2,CONCRETE:7,70,STAINED_CLAY:12,15,STAINED_CLAY:15,5,CONCRETE:7,100)
Block(0,16,-1,AIR:0)
Block(0,16,0,AIR:0)
Block(0,16,1,AIR:0)
Block(0,16,2,AIR:0)
RandomBlock(0,16,3,CONCRETE:7,70,STAINED_CLAY:12,15,STAINED_CLAY:15,5,CONCRETE:7,100)
Block(0,16,4,AIR:0)
Block(0,16,5,AIR:0)
Block(0,16,6,AIR:0)
RandomBlock(0,16,7,CONCRETE:7,70,STAINED_CLAY:12,15,STAINED_CLAY:15,5,CONCRETE:7,100)
RandomBlock(0,16,8,CONCRETE:7,70,STAINED_CLAY:12,15,STAINED_CLAY:15,5,CONCRETE:7,100)
RandomBlock(0,17,-7,CONCRETE:7,70,STAINED_CLAY:12,15,STAINED_CLAY:15,5,CONCRETE:7,100)
RandomBlock(0,17,-6,CONCRETE:7,70,STAINED_CLAY:12,15,STAINED_CLAY:15,5,CONCRETE:7,100)
Block(0,17,-5,AIR:0)
Block(0,17,-4,AIR:0)
Block(0,17,-3,AIR:0)
RandomBlock(0,17,-2,CONCRETE:7,70,STAINED_CLAY:12,15,STAINED_CLAY:15,5,CONCRETE:7,100)
Block(0,17,-1,AIR:0)
Block(0,17,0,AIR:0)
Block(0,17,1,AIR:0)
Block(0,17,2,AIR:0)
RandomBlock(0,17,3,CONCRETE:7,70,STAINED_CLAY:12,15,STAINED_CLAY:15,5,CONCRETE:7,100)
Block(0,17,4,AIR:0)
Block(0,17,5,AIR:0)
Block(0,17,6,AIR:0)
RandomBlock(0,17,7,CONCRETE:7,70,STAINED_CLAY:12,15,STAINED_CLAY:15,5,CONCRETE:7,100)
RandomBlock(0,17,8,CONCRETE:7,70,STAINED_CLAY:12,15,STAINED_CLAY:15,5,CONCRETE:7,100)
RandomBlock(0,18,-7,CONCRETE:7,70,STAINED_CLAY:12,15,STAINED_CLAY:15,5,CONCRETE:7,100)
RandomBlock(0,18,-6,CONCRETE:7,70,STAINED_CLAY:12,15,STAINED_CLAY:15,5,CONCRETE:7,100)
Block(0,18,-5,AIR:0)
Block(0,18,-4,AIR:0)
Block(0,18,-3,AIR:0)
RandomBlock(0,18,-2,CONCRETE:7,70,STAINED_CLAY:12,15,STAINED_CLAY:15,5,CONCRETE:7,100)
Block(0,18,-1,AIR:0)
Block(0,18,0,AIR:0)
Block(0,18,1,AIR:0)
Block(0,18,2,AIR:0)
RandomBlock(0,18,3,CONCRETE:7,70,STAINED_CLAY:12,15,STAINED_CLAY:15,5,CONCRETE:7,100)
Block(0,18,4,AIR:0)
Block(0,18,5,AIR:0)
Block(0,18,6,AIR:0)
RandomBlock(0,18,7,CONCRETE:7,70,STAINED_CLAY:12,15,STAINED_CLAY:15,5,CONCRETE:7,100)
RandomBlock(0,18,8,CONCRETE:7,70,STAINED_CLAY:12,15,STAINED_CLAY:15,5,CONCRETE:7,100)
RandomBlock(0,19,-7,CONCRETE:7,70,STAINED_CLAY:12,15,STAINED_CLAY:15,5,CONCRETE:7,100)
RandomBlock(0,19,-6,CONCRETE:7,70,STAINED_CLAY:12,15,STAINED_CLAY:15,5,CONCRETE:7,100)
Block(0,19,-5,AIR:0)
Block(0,19,-4,AIR:0)
Block(0,19,-3,AIR:0)
RandomBlock(0,19,-2,CONCRETE:7,70,STAINED_CLAY:12,15,STAINED_CLAY:15,5,CONCRETE:7,100)
Block(0,19,-1,AIR:0)
Block(0,19,0,AIR:0)
Block(0,19,1,AIR:0)
Block(0,19,2,AIR:0)
RandomBlock(0,19,3,CONCRETE:7,70,STAINED_CLAY:12,15,STAINED_CLAY:15,5,CONCRETE:7,100)
Block(0,19,4,AIR:0)
Block(0,19,5,AIR:0)
Block(0,19,6,AIR:0)
RandomBlock(0,19,7,CONCRETE:7,70,STAINED_CLAY:12,15,STAINED_CLAY:15,5,CONCRETE:7,100)
RandomBlock(0,19,8,CONCRETE:7,70,STAINED_CLAY:12,15,STAINED_CLAY:15,5,CONCRETE:7,100)
RandomBlock(0,20,-7,CONCRETE:7,70,STAINED_CLAY:12,15,STAINED_CLAY:15,5,CONCRETE:7,100)
RandomBlock(0,20,-6,CONCRETE:7,70,STAINED_CLAY:12,15,STAINED_CLAY:15,5,CONCRETE:7,100)
Block(0,20,-5,AIR:0)
Block(0,20,-4,AIR:0)
Block(0,20,-3,AIR:0)
RandomBlock(0,20,-2,CONCRETE:7,70,STAINED_CLAY:12,15,STAINED_CLAY:15,5,CONCRETE:7,100)
Block(0,20,-1,SMOOTH_STAIRS:0)
Block(0,20,0,CONCRETE:15)
Block(0,20,1,CONCRETE:15)
Block(0,20,2,SMOOTH_STAIRS:0)
RandomBlock(0,20,3,CONCRETE:7,70,STAINED_CLAY:12,15,STAINED_CLAY:15,5,CONCRETE:7,100)
Block(0,20,4,AIR:0)
Block(0,20,5,AIR:0)
Block(0,20,6,AIR:0)
RandomBlock(0,20,7,CONCRETE:7,70,STAINED_CLAY:12,15,STAINED_CLAY:15,5,CONCRETE:7,100)
RandomBlock(0,20,8,CONCRETE:7,70,STAINED_CLAY:12,15,STAINED_CLAY:15,5,CONCRETE:7,100)
RandomBlock(0,21,-7,CONCRETE:7,70,STAINED_CLAY:12,15,STAINED_CLAY:15,5,CONCRETE:7,100)
RandomBlock(0,21,-6,CONCRETE:7,70,STAINED_CLAY:12,15,STAINED_CLAY:15,5,CONCRETE:7,100)
RandomBlock(0,21,-5,CONCRETE:7,70,STAINED_CLAY:12,15,STAINED_CLAY:15,5,CONCRETE:7,100)
RandomBlock(0,21,-4,CONCRETE:7,70,STAINED_CLAY:12,15,STAINED_CLAY:15,5,CONCRETE:7,100)
RandomBlock(0,21,-3,CONCRETE:7,70,STAINED_CLAY:12,15,STAINED_CLAY:15,5,CONCRETE:7,100)
RandomBlock(0,21,-2,CONCRETE:7,70,STAINED_CLAY:12,15,STAINED_CLAY:15,5,CONCRETE:7,100)
Block(0,21,-1,SMOOTH_STAIRS:4)
RandomBlock(0,21,0,CONCRETE:7,70,STAINED_CLAY:12,15,STAINED_CLAY:15,5,CONCRETE:7,100)
RandomBlock(0,21,1,CONCRETE:7,70,STAINED_CLAY:12,15,STAINED_CLAY:15,5,CONCRETE:7,100)
Block(0,21,2,SMOOTH_STAIRS:4)
RandomBlock(0,21,3,CONCRETE:7,70,STAINED_CLAY:12,15,STAINED_CLAY:15,5,CONCRETE:7,100)
RandomBlock(0,21,4,CONCRETE:7,70,STAINED_CLAY:12,15,STAINED_CLAY:15,5,CONCRETE:7,100)
RandomBlock(0,21,5,CONCRETE:7,70,STAINED_CLAY:12,15,STAINED_CLAY:15,5,CONCRETE:7,100)
RandomBlock(0,21,6,CONCRETE:7,70,STAINED_CLAY:12,15,STAINED_CLAY:15,5,CONCRETE:7,100)
RandomBlock(0,21,7,CONCRETE:7,70,STAINED_CLAY:12,15,STAINED_CLAY:15,5,CONCRETE:7,100)
RandomBlock(0,21,8,CONCRETE:7,70,STAINED_CLAY:12,15,STAINED_CLAY:15,5,CONCRETE:7,100)
Block(0,22,-7,DOUBLE_STEP:0)
Block(0,22,-6,DOUBLE_STEP:0)
Block(0,22,-5,DOUBLE_STEP:0)
Block(0,22,-4,DOUBLE_STEP:0)
RandomBlock(0,22,-3,CONCRETE:7,70,STAINED_CLAY:12,15,STAINED_CLAY:15,5,CONCRETE:7,100)
RandomBlock(0,22,-2,CONCRETE:7,70,STAINED_CLAY:12,15,STAINED_CLAY:15,5,CONCRETE:7,100)
RandomBlock(0,22,-1,CONCRETE:7,70,STAINED_CLAY:12,15,STAINED_CLAY:15,5,CONCRETE:7,100)
RandomBlock(0,22,0,CONCRETE:7,70,STAINED_CLAY:12,15,STAINED_CLAY:15,5,CONCRETE:7,100)
RandomBlock(0,22,1,CONCRETE:7,70,STAINED_CLAY:12,15,STAINED_CLAY:15,5,CONCRETE:7,100)
RandomBlock(0,22,2,CONCRETE:7,70,STAINED_CLAY:12,15,STAINED_CLAY:15,5,CONCRETE:7,100)
RandomBlock(0,22,3,CONCRETE:7,70,STAINED_CLAY:12,15,STAINED_CLAY:15,5,CONCRETE:7,100)
RandomBlock(0,22,4,CONCRETE:7,70,STAINED_CLAY:12,15,STAINED_CLAY:15,5,CONCRETE:7,100)
Block(0,22,5,DOUBLE_STEP:0)
Block(0,22,6,DOUBLE_STEP:0)
Block(0,22,7,DOUBLE_STEP:0)
Block(0,22,8,DOUBLE_STEP:0)
RandomBlock(0,23,-2,CONCRETE:7,70,STAINED_CLAY:12,15,STAINED_CLAY:15,5,CONCRETE:7,100)
Block(0,23,-1,AIR:0)
Block(0,23,0,COBBLE_WALL:0)
Block(0,23,1,COBBLE_WALL:0)
Block(0,23,2,AIR:0)
RandomBlock(0,23,3,CONCRETE:7,70,STAINED_CLAY:12,15,STAINED_CLAY:15,5,CONCRETE:7,100)
RandomBlock(0,24,-2,CONCRETE:7,70,STAINED_CLAY:12,15,STAINED_CLAY:15,5,CONCRETE:7,100)
Block(0,24,-1,AIR:0)
Block(0,24,0,COBBLE_WALL:0)
Block(0,24,1,COBBLE_WALL:0)
Block(0,24,2,AIR:0)
RandomBlock(0,24,3,CONCRETE:7,70,STAINED_CLAY:12,15,STAINED_CLAY:15,5,CONCRETE:7,100)
RandomBlock(0,25,-2,CONCRETE:7,70,STAINED_CLAY:12,15,STAINED_CLAY:15,5,CONCRETE:7,100)
Block(0,25,-1,AIR:0)
Block(0,25,0,COBBLE_WALL:0)
Block(0,25,1,COBBLE_WALL:0)
Block(0,25,2,AIR:0)
RandomBlock(0,25,3,CONCRETE:7,70,STAINED_CLAY:12,15,STAINED_CLAY:15,5,CONCRETE:7,100)
RandomBlock(0,26,-2,CONCRETE:7,70,STAINED_CLAY:12,15,STAINED_CLAY:15,5,CONCRETE:7,100)
Block(0,26,-1,STEP:8)
Block(0,26,0,STEP:8)
Block(0,26,1,STEP:8)
Block(0,26,2,STEP:8)
RandomBlock(0,26,3,CONCRETE:7,70,STAINED_CLAY:12,15,STAINED_CLAY:15,5,CONCRETE:7,100)
Block(1,0,-2,CONCRETE:15)
Block(1,0,3,CONCRETE:15)
Block(1,11,-3,STAINED_CLAY:9)
RandomBlock(1,11,-2,CONCRETE:7,70,STAINED_CLAY:12,15,STAINED_CLAY:15,5,CONCRETE:7,100)
Block(1,11,-1,STAINED_CLAY:9)
Block(1,11,0,STAINED_CLAY:9)
Block(1,11,1,STAINED_CLAY:9)
Block(1,11,2,STAINED_CLAY:9)
RandomBlock(1,11,3,CONCRETE:7,70,STAINED_CLAY:12,15,STAINED_CLAY:15,5,CONCRETE:7,100)
Block(1,11,4,STAINED_CLAY:9)
RandomBlock(1,12,-3,CONCRETE:7,70,STAINED_CLAY:12,15,STAINED_CLAY:15,5,CONCRETE:7,100)
RandomBlock(1,12,-2,CONCRETE:7,70,STAINED_CLAY:12,15,STAINED_CLAY:15,5,CONCRETE:7,100)
Block(1,12,-1,AIR:0)
Block(1,12,0,AIR:0)
Block(1,12,1,AIR:0)
Block(1,12,2,AIR:0)
RandomBlock(1,12,3,CONCRETE:7,70,STAINED_CLAY:12,15,STAINED_CLAY:15,5,CONCRETE:7,100)
RandomBlock(1,12,4,CONCRETE:7,70,STAINED_CLAY:12,15,STAINED_CLAY:15,5,CONCRETE:7,100)
RandomBlock(1,13,-3,CONCRETE:7,70,STAINED_CLAY:12,15,STAINED_CLAY:15,5,CONCRETE:7,100)
RandomBlock(1,13,-2,CONCRETE:7,70,STAINED_CLAY:12,15,STAINED_CLAY:15,5,CONCRETE:7,100)
Block(1,13,-1,AIR:0)
Block(1,13,0,AIR:0)
Block(1,13,1,AIR:0)
Block(1,13,2,AIR:0)
RandomBlock(1,13,3,CONCRETE:7,70,STAINED_CLAY:12,15,STAINED_CLAY:15,5,CONCRETE:7,100)
RandomBlock(1,13,4,CONCRETE:7,70,STAINED_CLAY:12,15,STAINED_CLAY:15,5,CONCRETE:7,100)
Block(1,14,-6,CONCRETE:15)
Block(1,14,-4,CONCRETE:15)
RandomBlock(1,14,-3,CONCRETE:7,70,STAINED_CLAY:12,15,STAINED_CLAY:15,5,CONCRETE:7,100)
RandomBlock(1,14,-2,CONCRETE:7,70,STAINED_CLAY:12,15,STAINED_CLAY:15,5,CONCRETE:7,100)
Block(1,14,-1,AIR:0)
Block(1,14,0,AIR:0)
Block(1,14,1,AIR:0)
Block(1,14,2,AIR:0)
RandomBlock(1,14,3,CONCRETE:7,70,STAINED_CLAY:12,15,STAINED_CLAY:15,5,CONCRETE:7,100)
RandomBlock(1,14,4,CONCRETE:7,70,STAINED_CLAY:12,15,STAINED_CLAY:15,5,CONCRETE:7,100)
Block(1,14,5,CONCRETE:15)
Block(1,14,7,CONCRETE:15)
RandomBlock(1,15,-7,CONCRETE:7,70,STAINED_CLAY:12,15,STAINED_CLAY:15,5,CONCRETE:7,100)
RandomBlock(1,15,-6,CONCRETE:7,70,STAINED_CLAY:12,15,STAINED_CLAY:15,5,CONCRETE:7,100)
Block(1,15,-5,STAINED_CLAY:9)
Block(1,15,-4,STAINED_CLAY:9)
Block(1,15,-3,STAINED_CLAY:9)
RandomBlock(1,15,-2,CONCRETE:7,70,STAINED_CLAY:12,15,STAINED_CLAY:15,5,CONCRETE:7,100)
Block(1,15,-1,AIR:0)
Block(1,15,0,AIR:0)
Block(1,15,1,AIR:0)
Block(1,15,2,AIR:0)
RandomBlock(1,15,3,CONCRETE:7,70,STAINED_CLAY:12,15,STAINED_CLAY:15,5,CONCRETE:7,100)
Block(1,15,4,STAINED_CLAY:9)
Block(1,15,5,STAINED_CLAY:9)
Block(1,15,6,STAINED_CLAY:9)
RandomBlock(1,15,7,CONCRETE:7,70,STAINED_CLAY:12,15,STAINED_CLAY:15,5,CONCRETE:7,100)
RandomBlock(1,15,8,CONCRETE:7,70,STAINED_CLAY:12,15,STAINED_CLAY:15,5,CONCRETE:7,100)
RandomBlock(1,16,-7,CONCRETE:7,70,STAINED_CLAY:12,15,STAINED_CLAY:15,5,CONCRETE:7,100)
Block(1,16,-6,AIR:0)
Block(1,16,-5,AIR:0)
Block(1,16,-4,AIR:0)
Block(1,16,-3,IRON_FENCE:0)
Block(1,16,-2,IRON_FENCE:0)
Block(1,16,-1,AIR:0)
Block(1,16,0,AIR:0)
Block(1,16,1,AIR:0)
Block(1,16,2,AIR:0)
Block(1,16,3,IRON_FENCE:0)
Block(1,16,4,IRON_FENCE:0)
Block(1,16,5,AIR:0)
Block(1,16,6,AIR:0)
Block(1,16,7,AIR:0)
RandomBlock(1,16,8,CONCRETE:7,70,STAINED_CLAY:12,15,STAINED_CLAY:15,5,CONCRETE:7,100)
RandomBlock(1,17,-7,CONCRETE:7,70,STAINED_CLAY:12,15,STAINED_CLAY:15,5,CONCRETE:7,100)
Block(1,17,-6,AIR:0)
Block(1,17,-5,AIR:0)
Block(1,17,-4,AIR:0)
Block(1,17,-3,AIR:0)
Block(1,17,-2,AIR:0)
Block(1,17,-1,AIR:0)
Block(1,17,0,AIR:0)
Block(1,17,1,AIR:0)
Block(1,17,2,AIR:0)
Block(1,17,3,AIR:0)
Block(1,17,4,AIR:0)
Block(1,17,5,AIR:0)
Block(1,17,6,AIR:0)
Block(1,17,7,STONE_BUTTON:4)
RandomBlock(1,17,8,CONCRETE:7,70,STAINED_CLAY:12,15,STAINED_CLAY:15,5,CONCRETE:7,100)
RandomBlock(1,18,-7,CONCRETE:7,70,STAINED_CLAY:12,15,STAINED_CLAY:15,5,CONCRETE:7,100)
Block(1,18,-6,AIR:0)
Block(1,18,-5,AIR:0)
Block(1,18,-4,AIR:0)
Block(1,18,-3,AIR:0)
Block(1,18,-2,AIR:0)
Block(1,18,-1,AIR:0)
Block(1,18,0,AIR:0)
Block(1,18,1,AIR:0)
Block(1,18,2,AIR:0)
Block(1,18,3,AIR:0)
Block(1,18,4,AIR:0)
Block(1,18,5,AIR:0)
Block(1,18,6,AIR:0)
Block(1,18,7,AIR:0)
RandomBlock(1,18,8,CONCRETE:7,70,STAINED_CLAY:12,15,STAINED_CLAY:15,5,CONCRETE:7,100)
RandomBlock(1,19,-7,CONCRETE:7,70,STAINED_CLAY:12,15,STAINED_CLAY:15,5,CONCRETE:7,100)
Block(1,19,-6,AIR:0)
Block(1,19,-5,AIR:0)
Block(1,19,-4,AIR:0)
Block(1,19,-3,AIR:0)
Block(1,19,-2,AIR:0)
Block(1,19,-1,AIR:0)
Block(1,19,0,AIR:0)
Block(1,19,1,AIR:0)
Block(1,19,2,AIR:0)
Block(1,19,3,AIR:0)
Block(1,19,4,AIR:0)
Block(1,19,5,AIR:0)
Block(1,19,6,AIR:0)
Block(1,19,7,AIR:0)
RandomBlock(1,19,8,CONCRETE:7,70,STAINED_CLAY:12,15,STAINED_CLAY:15,5,CONCRETE:7,100)
RandomBlock(1,20,-7,CONCRETE:7,70,STAINED_CLAY:12,15,STAINED_CLAY:15,5,CONCRETE:7,100)
Block(1,20,-6,AIR:0)
Block(1,20,-5,AIR:0)
Block(1,20,-4,AIR:0)
Block(1,20,-3,AIR:0)
Block(1,20,-2,AIR:0)
Block(1,20,-1,SMOOTH_STAIRS:2)
Block(1,20,0,CONCRETE:15)
Block(1,20,1,CONCRETE:15)
Block(1,20,2,SMOOTH_STAIRS:3)
Block(1,20,3,AIR:0)
Block(1,20,4,AIR:0)
Block(1,20,5,AIR:0)
Block(1,20,6,AIR:0)
Block(1,20,7,AIR:0)
RandomBlock(1,20,8,CONCRETE:7,70,STAINED_CLAY:12,15,STAINED_CLAY:15,5,CONCRETE:7,100)
RandomBlock(1,21,-7,CONCRETE:7,70,STAINED_CLAY:12,15,STAINED_CLAY:15,5,CONCRETE:7,100)
Block(1,21,-6,AIR:0)
Block(1,21,-5,AIR:0)
Block(1,21,-4,AIR:0)
Block(1,21,-3,AIR:0)
Block(1,21,-2,AIR:0)
Block(1,21,-1,SMOOTH_STAIRS:6)
RandomBlock(1,21,0,CONCRETE:7,70,STAINED_CLAY:12,15,STAINED_CLAY:15,5,CONCRETE:7,100)
RandomBlock(1,21,1,CONCRETE:7,70,STAINED_CLAY:12,15,STAINED_CLAY:15,5,CONCRETE:7,100)
Block(1,21,2,SMOOTH_STAIRS:7)
Block(1,21,3,AIR:0)
Block(1,21,4,AIR:0)
Block(1,21,5,AIR:0)
Block(1,21,6,AIR:0)
Block(1,21,7,AIR:0)
RandomBlock(1,21,8,CONCRETE:7,70,STAINED_CLAY:12,15,STAINED_CLAY:15,5,CONCRETE:7,100)
Block(1,22,-7,DOUBLE_STEP:0)
Block(1,22,-6,STEP:8)
Block(1,22,-5,STEP:8)
Block(1,22,-4,STEP:8)
RandomBlock(1,22,-3,CONCRETE:7,70,STAINED_CLAY:12,15,STAINED_CLAY:15,5,CONCRETE:7,100)
RandomBlock(1,22,-2,CONCRETE:7,70,STAINED_CLAY:12,15,STAINED_CLAY:15,5,CONCRETE:7,100)
RandomBlock(1,22,-1,CONCRETE:7,70,STAINED_CLAY:12,15,STAINED_CLAY:15,5,CONCRETE:7,100)
RandomBlock(1,22,0,CONCRETE:7,70,STAINED_CLAY:12,15,STAINED_CLAY:15,5,CONCRETE:7,100)
RandomBlock(1,22,1,CONCRETE:7,70,STAINED_CLAY:12,15,STAINED_CLAY:15,5,CONCRETE:7,100)
RandomBlock(1,22,2,CONCRETE:7,70,STAINED_CLAY:12,15,STAINED_CLAY:15,5,CONCRETE:7,100)
RandomBlock(1,22,3,CONCRETE:7,70,STAINED_CLAY:12,15,STAINED_CLAY:15,5,CONCRETE:7,100)
RandomBlock(1,22,4,CONCRETE:7,70,STAINED_CLAY:12,15,STAINED_CLAY:15,5,CONCRETE:7,100)
Block(1,22,5,STEP:8)
Block(1,22,6,STEP:8)
Block(1,22,7,STEP:8)
Block(1,22,8,DOUBLE_STEP:0)
Block(1,23,-2,SMOOTH_STAIRS:2)
Block(1,23,-1,CONCRETE:15)
Block(1,23,0,COBBLE_WALL:0)
Block(1,23,1,COBBLE_WALL:0)
Block(1,23,2,CONCRETE:15)
Block(1,23,3,SMOOTH_STAIRS:3)
Block(1,24,-2,SMOOTH_STAIRS:2)
Block(1,24,-1,QUARTZ_STAIRS:2)
Block(1,24,0,CONCRETE:15)
Block(1,24,1,CONCRETE:15)
Block(1,24,2,QUARTZ_STAIRS:3)
Block(1,24,3,SMOOTH_STAIRS:3)
Block(1,25,-2,SMOOTH_STAIRS:2)
Block(1,25,-1,AIR:0)
Block(1,25,0,COBBLE_WALL:0)
Block(1,25,1,COBBLE_WALL:0)
Block(1,25,2,AIR:0)
Block(1,25,3,SMOOTH_STAIRS:3)
RandomBlock(1,26,-2,CONCRETE:7,70,STAINED_CLAY:12,15,STAINED_CLAY:15,5,CONCRETE:7,100)
Block(1,26,-1,STEP:8)
Block(1,26,0,STEP:8)
Block(1,26,1,STEP:8)
Block(1,26,2,STEP:8)
RandomBlock(1,26,3,CONCRETE:7,70,STAINED_CLAY:12,15,STAINED_CLAY:15,5,CONCRETE:7,100)
Block(2,11,-3,STAINED_CLAY:9)
RandomBlock(2,11,-2,CONCRETE:7,70,STAINED_CLAY:12,15,STAINED_CLAY:15,5,CONCRETE:7,100)
Block(2,11,-1,STAINED_CLAY:9)
Block(2,11,0,STAINED_CLAY:9)
Block(2,11,1,STAINED_CLAY:9)
Block(2,11,2,STAINED_CLAY:9)
RandomBlock(2,11,3,CONCRETE:7,70,STAINED_CLAY:12,15,STAINED_CLAY:15,5,CONCRETE:7,100)
Block(2,11,4,STAINED_CLAY:9)
Block(2,12,-3,STAINED_CLAY:9)
Block(2,12,-2,LADDER:3)
Block(2,12,-1,AIR:0)
Block(2,12,0,AIR:0)
Block(2,12,1,AIR:0)
Block(2,12,2,AIR:0)
Block(2,12,3,LADDER:2)
Block(2,12,4,STAINED_CLAY:9)
Block(2,13,-3,STAINED_CLAY:9)
Block(2,13,-2,LADDER:3)
Block(2,13,-1,AIR:0)
Block(2,13,0,AIR:0)
Block(2,13,1,AIR:0)
Block(2,13,2,AIR:0)
Block(2,13,3,LADDER:2)
Block(2,13,4,STAINED_CLAY:9)
Block(2,14,-6,CONCRETE:15)
Block(2,14,-4,CONCRETE:15)
Block(2,14,-3,STAINED_CLAY:9)
Block(2,14,-2,LADDER:3)
Block(2,14,-1,AIR:0)
Block(2,14,0,AIR:0)
Block(2,14,1,AIR:0)
Block(2,14,2,AIR:0)
Block(2,14,3,LADDER:2)
Block(2,14,4,STAINED_CLAY:9)
Block(2,14,5,CONCRETE:15)
Block(2,14,7,CONCRETE:15)
RandomBlock(2,15,-7,CONCRETE:7,70,STAINED_CLAY:12,15,STAINED_CLAY:15,5,CONCRETE:7,100)
RandomBlock(2,15,-6,CONCRETE:7,70,STAINED_CLAY:12,15,STAINED_CLAY:15,5,CONCRETE:7,100)
Block(2,15,-5,STAINED_CLAY:9)
Block(2,15,-4,STAINED_CLAY:9)
Block(2,15,-3,STAINED_CLAY:9)
Block(2,15,-2,LADDER:3)
Block(2,15,-1,AIR:0)
Block(2,15,0,AIR:0)
Block(2,15,1,AIR:0)
Block(2,15,2,AIR:0)
Block(2,15,3,LADDER:2)
Block(2,15,4,STAINED_CLAY:9)
Block(2,15,5,STAINED_CLAY:9)
Block(2,15,6,STAINED_CLAY:9)
RandomBlock(2,15,7,CONCRETE:7,70,STAINED_CLAY:12,15,STAINED_CLAY:15,5,CONCRETE:7,100)
RandomBlock(2,15,8,CONCRETE:7,70,STAINED_CLAY:12,15,STAINED_CLAY:15,5,CONCRETE:7,100)
Block(2,16,-7,IRON_DOOR_BLOCK:1)
Block(2,16,-6,AIR:0)
Block(2,16,-5,AIR:0)
Block(2,16,-4,AIR:0)
Block(2,16,-3,AIR:0)
Block(2,16,-2,AIR:0)
Block(2,16,-1,AIR:0)
Block(2,16,0,AIR:0)
Block(2,16,1,AIR:0)
Block(2,16,2,AIR:0)
Block(2,16,3,AIR:0)
Block(2,16,4,AIR:0)
Block(2,16,5,AIR:0)
Block(2,16,6,AIR:0)
Block(2,16,7,AIR:0)
Block(2,16,8,IRON_DOOR_BLOCK:3)
Block(2,17,-7,IRON_DOOR_BLOCK:8)
Block(2,17,-6,AIR:0)
Block(2,17,-5,AIR:0)
Block(2,17,-4,AIR:0)
Block(2,17,-3,AIR:0)
Block(2,17,-2,AIR:0)
Block(2,17,-1,AIR:0)
Block(2,17,0,AIR:0)
Block(2,17,1,AIR:0)
Block(2,17,2,AIR:0)
Block(2,17,3,AIR:0)
Block(2,17,4,AIR:0)
Block(2,17,5,AIR:0)
Block(2,17,6,AIR:0)
Block(2,17,7,AIR:0)
Block(2,17,8,IRON_DOOR_BLOCK:9)
RandomBlock(2,18,-7,CONCRETE:7,70,STAINED_CLAY:12,15,STAINED_CLAY:15,5,CONCRETE:7,100)
Block(2,18,-6,AIR:0)
Block(2,18,-5,AIR:0)
Block(2,18,-4,AIR:0)
Block(2,18,-3,AIR:0)
Block(2,18,-2,AIR:0)
Block(2,18,-1,AIR:0)
Block(2,18,0,AIR:0)
Block(2,18,1,AIR:0)
Block(2,18,2,AIR:0)
Block(2,18,3,AIR:0)
Block(2,18,4,AIR:0)
Block(2,18,5,AIR:0)
Block(2,18,6,AIR:0)
Block(2,18,7,AIR:0)
RandomBlock(2,18,8,CONCRETE:7,70,STAINED_CLAY:12,15,STAINED_CLAY:15,5,CONCRETE:7,100)
RandomBlock(2,19,-7,CONCRETE:7,70,STAINED_CLAY:12,15,STAINED_CLAY:15,5,CONCRETE:7,100)
Block(2,19,-6,AIR:0)
Block(2,19,-5,AIR:0)
Block(2,19,-4,AIR:0)
Block(2,19,-3,AIR:0)
Block(2,19,-2,AIR:0)
Block(2,19,-1,AIR:0)
Block(2,19,0,AIR:0)
Block(2,19,1,AIR:0)
Block(2,19,2,AIR:0)
Block(2,19,3,AIR:0)
Block(2,19,4,AIR:0)
Block(2,19,5,AIR:0)
Block(2,19,6,AIR:0)
Block(2,19,7,AIR:0)
RandomBlock(2,19,8,CONCRETE:7,70,STAINED_CLAY:12,15,STAINED_CLAY:15,5,CONCRETE:7,100)
RandomBlock(2,20,-7,CONCRETE:7,70,STAINED_CLAY:12,15,STAINED_CLAY:15,5,CONCRETE:7,100)
Block(2,20,-6,AIR:0)
Block(2,20,-5,AIR:0)
Block(2,20,-4,AIR:0)
Block(2,20,-3,AIR:0)
Block(2,20,-2,AIR:0)
Block(2,20,-1,SMOOTH_STAIRS:2)
Block(2,20,0,CONCRETE:15)
Block(2,20,1,CONCRETE:15)
Block(2,20,2,SMOOTH_STAIRS:3)
Block(2,20,3,AIR:0)
Block(2,20,4,AIR:0)
Block(2,20,5,AIR:0)
Block(2,20,6,AIR:0)
Block(2,20,7,AIR:0)
RandomBlock(2,20,8,CONCRETE:7,70,STAINED_CLAY:12,15,STAINED_CLAY:15,5,CONCRETE:7,100)
RandomBlock(2,21,-7,CONCRETE:7,70,STAINED_CLAY:12,15,STAINED_CLAY:15,5,CONCRETE:7,100)
Block(2,21,-6,AIR:0)
Block(2,21,-5,AIR:0)
Block(2,21,-4,AIR:0)
Block(2,21,-3,AIR:0)
Block(2,21,-2,AIR:0)
Block(2,21,-1,SMOOTH_STAIRS:6)
RandomBlock(2,21,0,CONCRETE:7,70,STAINED_CLAY:12,15,STAINED_CLAY:15,5,CONCRETE:7,100)
RandomBlock(2,21,1,CONCRETE:7,70,STAINED_CLAY:12,15,STAINED_CLAY:15,5,CONCRETE:7,100)
Block(2,21,2,SMOOTH_STAIRS:7)
Block(2,21,3,AIR:0)
Block(2,21,4,AIR:0)
Block(2,21,5,AIR:0)
Block(2,21,6,AIR:0)
Block(2,21,7,AIR:0)
RandomBlock(2,21,8,CONCRETE:7,70,STAINED_CLAY:12,15,STAINED_CLAY:15,5,CONCRETE:7,100)
Block(2,22,-7,DOUBLE_STEP:0)
Block(2,22,-6,STEP:8)
Block(2,22,-5,STEP:8)
Block(2,22,-4,STEP:8)
RandomBlock(2,22,-3,CONCRETE:7,70,STAINED_CLAY:12,15,STAINED_CLAY:15,5,CONCRETE:7,100)
RandomBlock(2,22,-2,CONCRETE:7,70,STAINED_CLAY:12,15,STAINED_CLAY:15,5,CONCRETE:7,100)
RandomBlock(2,22,-1,CONCRETE:7,70,STAINED_CLAY:12,15,STAINED_CLAY:15,5,CONCRETE:7,100)
RandomBlock(2,22,0,CONCRETE:7,70,STAINED_CLAY:12,15,STAINED_CLAY:15,5,CONCRETE:7,100)
RandomBlock(2,22,1,CONCRETE:7,70,STAINED_CLAY:12,15,STAINED_CLAY:15,5,CONCRETE:7,100)
RandomBlock(2,22,2,CONCRETE:7,70,STAINED_CLAY:12,15,STAINED_CLAY:15,5,CONCRETE:7,100)
RandomBlock(2,22,3,CONCRETE:7,70,STAINED_CLAY:12,15,STAINED_CLAY:15,5,CONCRETE:7,100)
RandomBlock(2,22,4,CONCRETE:7,70,STAINED_CLAY:12,15,STAINED_CLAY:15,5,CONCRETE:7,100)
Block(2,22,5,STEP:8)
Block(2,22,6,STEP:8)
Block(2,22,7,STEP:8)
Block(2,22,8,DOUBLE_STEP:0)
Block(2,23,-2,SMOOTH_STAIRS:2)
Block(2,23,-1,AIR:0)
Block(2,23,0,COBBLE_WALL:0)
Block(2,23,1,COBBLE_WALL:0)
Block(2,23,2,AIR:0)
Block(2,23,3,SMOOTH_STAIRS:3)
Block(2,24,-2,SMOOTH_STAIRS:2)
Block(2,24,-1,AIR:0)
Block(2,24,0,COBBLE_WALL:0)
Block(2,24,1,COBBLE_WALL:0)
Block(2,24,2,AIR:0)
Block(2,24,3,SMOOTH_STAIRS:3)
Block(2,25,-2,SMOOTH_STAIRS:2)
