
#######################################################################
# +-----------------------------------------------------------------+ #
# |                            BO4 object                           | #
# +-----------------------------------------------------------------+ #
#######################################################################

Author: NLBlackEagle

Description: No description given

SettingsMode: WriteDisable


#######################################################################
# +-----------------------------------------------------------------+ #
# |                          Main settings                          | #
# +-----------------------------------------------------------------+ #
#######################################################################

Frequency: 0

SpawnHeight: highestBlock

UseCenterForHighestBlock: true

##############################
# Height Limits for the BO4. #
##############################

MinHeight: 0

MaxHeight: 255

InheritBO3: 

InheritBO3Rotation: NORTH

OverrideChildSettings: true

OverrideParentHeight: false

CanOverride: true

BranchFrequency: 0

BranchFrequencyGroup: 

MustBeBelowOther: false

MustBeInside: 

CannotBeInside: 

ReplacesBO3: 

MustBeInsideWorldBorders: false

CanSpawnOnWater: true

SpawnOnWaterOnly: false

SpawnUnderWater: false

SpawnAtWaterLevel: false

HeightOffset: 0

RemoveAir: false

ReplaceAbove: 

ReplaceBelow: 

ReplaceWithBiomeBlocks: false

ReplaceWithSurfaceBlock: GRASS

ReplaceWithGroundBlock: DIRT

ReplaceWithStoneBlock: STONE

SmoothRadius: 0

SmoothHeightOffset: 0

SmoothStartTop: false

SmoothStartWood: false

SmoothingSurfaceBlock: 

SmoothingGroundBlock: 

BO3Group: 

IsSpawnPoint: false

DoReplaceBlocks: false


#######################################################################
# +-----------------------------------------------------------------+ #
# |                              Blocks                             | #
# +-----------------------------------------------------------------+ #
#######################################################################

RandomBlock(-8,11,-2,CONCRETE:7,70,STAINED_CLAY:12,15,STAINED_CLAY:15,5,CONCRETE:7,100)
RandomBlock(-8,11,-1,CONCRETE:7,70,STAINED_CLAY:12,15,STAINED_CLAY:15,5,CONCRETE:7,100)
RandomBlock(-8,11,0,CONCRETE:7,70,STAINED_CLAY:12,15,STAINED_CLAY:15,5,CONCRETE:7,100)
RandomBlock(-8,11,1,CONCRETE:7,70,STAINED_CLAY:12,15,STAINED_CLAY:15,5,CONCRETE:7,100)
RandomBlock(-8,11,2,CONCRETE:7,70,STAINED_CLAY:12,15,STAINED_CLAY:15,5,CONCRETE:7,100)
RandomBlock(-8,11,3,CONCRETE:7,70,STAINED_CLAY:12,15,STAINED_CLAY:15,5,CONCRETE:7,100)
RandomBlock(-8,12,-2,CONCRETE:7,70,STAINED_CLAY:12,15,STAINED_CLAY:15,5,CONCRETE:7,100)
RandomBlock(-8,12,-1,CONCRETE:7,70,STAINED_CLAY:12,15,STAINED_CLAY:15,5,CONCRETE:7,100)
RandomBlock(-8,12,0,CONCRETE:7,70,STAINED_CLAY:12,15,STAINED_CLAY:15,5,CONCRETE:7,100)
RandomBlock(-8,12,1,CONCRETE:7,70,STAINED_CLAY:12,15,STAINED_CLAY:15,5,CONCRETE:7,100)
RandomBlock(-8,12,2,CONCRETE:7,70,STAINED_CLAY:12,15,STAINED_CLAY:15,5,CONCRETE:7,100)
RandomBlock(-8,12,3,CONCRETE:7,70,STAINED_CLAY:12,15,STAINED_CLAY:15,5,CONCRETE:7,100)
RandomBlock(-8,13,-2,CONCRETE:7,70,STAINED_CLAY:12,15,STAINED_CLAY:15,5,CONCRETE:7,100)
RandomBlock(-8,13,-1,CONCRETE:7,70,STAINED_CLAY:12,15,STAINED_CLAY:15,5,CONCRETE:7,100)
RandomBlock(-8,13,0,CONCRETE:7,70,STAINED_CLAY:12,15,STAINED_CLAY:15,5,CONCRETE:7,100)
RandomBlock(-8,13,1,CONCRETE:7,70,STAINED_CLAY:12,15,STAINED_CLAY:15,5,CONCRETE:7,100)
RandomBlock(-8,13,2,CONCRETE:7,70,STAINED_CLAY:12,15,STAINED_CLAY:15,5,CONCRETE:7,100)
RandomBlock(-8,13,3,CONCRETE:7,70,STAINED_CLAY:12,15,STAINED_CLAY:15,5,CONCRETE:7,100)
RandomBlock(-8,14,-2,CONCRETE:7,70,STAINED_CLAY:12,15,STAINED_CLAY:15,5,CONCRETE:7,100)
RandomBlock(-8,14,-1,CONCRETE:7,70,STAINED_CLAY:12,15,STAINED_CLAY:15,5,CONCRETE:7,100)
RandomBlock(-8,14,0,CONCRETE:7,70,STAINED_CLAY:12,15,STAINED_CLAY:15,5,CONCRETE:7,100)
RandomBlock(-8,14,1,CONCRETE:7,70,STAINED_CLAY:12,15,STAINED_CLAY:15,5,CONCRETE:7,100)
RandomBlock(-8,14,2,CONCRETE:7,70,STAINED_CLAY:12,15,STAINED_CLAY:15,5,CONCRETE:7,100)
RandomBlock(-8,14,3,CONCRETE:7,70,STAINED_CLAY:12,15,STAINED_CLAY:15,5,CONCRETE:7,100)
RandomBlock(-8,15,-2,CONCRETE:7,70,STAINED_CLAY:12,15,STAINED_CLAY:15,5,CONCRETE:7,100)
RandomBlock(-8,15,3,CONCRETE:7,70,STAINED_CLAY:12,15,STAINED_CLAY:15,5,CONCRETE:7,100)
RandomBlock(-8,16,-2,CONCRETE:7,70,STAINED_CLAY:12,15,STAINED_CLAY:15,5,CONCRETE:7,100)
RandomBlock(-8,16,3,CONCRETE:7,70,STAINED_CLAY:12,15,STAINED_CLAY:15,5,CONCRETE:7,100)
Block(-8,20,0,AIR:0)
Block(-8,20,1,AIR:0)
Block(-8,20,2,AIR:0)
Block(-8,21,-2,AIR:0)
Block(-8,21,-1,AIR:0)
Block(-8,21,0,AIR:0)
Block(-8,21,1,AIR:0)
Block(-8,21,2,AIR:0)
Block(-8,21,3,AIR:0)
Block(-8,21,4,AIR:0)
Block(-8,22,-3,AIR:0)
Block(-8,22,-2,AIR:0)
Block(-8,22,-1,AIR:0)
Block(-8,22,0,AIR:0)
Block(-8,22,1,AIR:0)
Block(-8,22,2,AIR:0)
Block(-8,22,3,AIR:0)
Block(-8,22,4,AIR:0)
Block(-8,22,5,AIR:0)
RandomBlock(-7,11,-2,CONCRETE:7,70,STAINED_CLAY:12,15,STAINED_CLAY:15,5,CONCRETE:7,100)
RandomBlock(-7,11,-1,CONCRETE:7,70,STAINED_CLAY:12,15,STAINED_CLAY:15,5,CONCRETE:7,100)
RandomBlock(-7,11,0,CONCRETE:7,70,STAINED_CLAY:12,15,STAINED_CLAY:15,5,CONCRETE:7,100)
RandomBlock(-7,11,1,CONCRETE:7,70,STAINED_CLAY:12,15,STAINED_CLAY:15,5,CONCRETE:7,100)
RandomBlock(-7,11,2,CONCRETE:7,70,STAINED_CLAY:12,15,STAINED_CLAY:15,5,CONCRETE:7,100)
RandomBlock(-7,11,3,CONCRETE:7,70,STAINED_CLAY:12,15,STAINED_CLAY:15,5,CONCRETE:7,100)
RandomBlock(-7,12,-2,CONCRETE:7,70,STAINED_CLAY:12,15,STAINED_CLAY:15,5,CONCRETE:7,100)
RandomBlock(-7,12,-1,CONCRETE:7,70,STAINED_CLAY:12,15,STAINED_CLAY:15,5,CONCRETE:7,100)
RandomBlock(-7,12,0,CONCRETE:7,70,STAINED_CLAY:12,15,STAINED_CLAY:15,5,CONCRETE:7,100)
RandomBlock(-7,12,1,CONCRETE:7,70,STAINED_CLAY:12,15,STAINED_CLAY:15,5,CONCRETE:7,100)
RandomBlock(-7,12,2,CONCRETE:7,70,STAINED_CLAY:12,15,STAINED_CLAY:15,5,CONCRETE:7,100)
RandomBlock(-7,12,3,CONCRETE:7,70,STAINED_CLAY:12,15,STAINED_CLAY:15,5,CONCRETE:7,100)
RandomBlock(-7,13,-2,CONCRETE:7,70,STAINED_CLAY:12,15,STAINED_CLAY:15,5,CONCRETE:7,100)
RandomBlock(-7,13,-1,CONCRETE:7,70,STAINED_CLAY:12,15,STAINED_CLAY:15,5,CONCRETE:7,100)
RandomBlock(-7,13,0,CONCRETE:7,70,STAINED_CLAY:12,15,STAINED_CLAY:15,5,CONCRETE:7,100)
RandomBlock(-7,13,1,CONCRETE:7,70,STAINED_CLAY:12,15,STAINED_CLAY:15,5,CONCRETE:7,100)
RandomBlock(-7,13,2,CONCRETE:7,70,STAINED_CLAY:12,15,STAINED_CLAY:15,5,CONCRETE:7,100)
RandomBlock(-7,13,3,CONCRETE:7,70,STAINED_CLAY:12,15,STAINED_CLAY:15,5,CONCRETE:7,100)
RandomBlock(-7,14,-2,CONCRETE:7,70,STAINED_CLAY:12,15,STAINED_CLAY:15,5,CONCRETE:7,100)
RandomBlock(-7,14,-1,CONCRETE:7,70,STAINED_CLAY:12,15,STAINED_CLAY:15,5,CONCRETE:7,100)
RandomBlock(-7,14,0,CONCRETE:7,70,STAINED_CLAY:12,15,STAINED_CLAY:15,5,CONCRETE:7,100)
RandomBlock(-7,14,1,CONCRETE:7,70,STAINED_CLAY:12,15,STAINED_CLAY:15,5,CONCRETE:7,100)
RandomBlock(-7,14,2,CONCRETE:7,70,STAINED_CLAY:12,15,STAINED_CLAY:15,5,CONCRETE:7,100)
RandomBlock(-7,14,3,CONCRETE:7,70,STAINED_CLAY:12,15,STAINED_CLAY:15,5,CONCRETE:7,100)
RandomBlock(-7,15,-2,CONCRETE:7,70,STAINED_CLAY:12,15,STAINED_CLAY:15,5,CONCRETE:7,100)
RandomBlock(-7,15,3,CONCRETE:7,70,STAINED_CLAY:12,15,STAINED_CLAY:15,5,CONCRETE:7,100)
RandomBlock(-7,16,-2,CONCRETE:7,70,STAINED_CLAY:12,15,STAINED_CLAY:15,5,CONCRETE:7,100)
RandomBlock(-7,16,3,CONCRETE:7,70,STAINED_CLAY:12,15,STAINED_CLAY:15,5,CONCRETE:7,100)
Block(-7,20,1,AIR:0)
Block(-7,21,-1,AIR:0)
Block(-7,21,0,AIR:0)
Block(-7,21,1,AIR:0)
Block(-7,21,2,AIR:0)
Block(-7,21,3,AIR:0)
Block(-7,22,-2,AIR:0)
Block(-7,22,-1,AIR:0)
Block(-7,22,0,AIR:0)
Block(-7,22,1,AIR:0)
Block(-7,22,2,AIR:0)
Block(-7,22,3,AIR:0)
Block(-7,22,4,AIR:0)
RandomBlock(-6,11,-2,CONCRETE:7,70,STAINED_CLAY:12,15,STAINED_CLAY:15,5,CONCRETE:7,100)
RandomBlock(-6,11,-1,CONCRETE:7,70,STAINED_CLAY:12,15,STAINED_CLAY:15,5,CONCRETE:7,100)
RandomBlock(-6,11,0,CONCRETE:7,70,STAINED_CLAY:12,15,STAINED_CLAY:15,5,CONCRETE:7,100)
RandomBlock(-6,11,1,CONCRETE:7,70,STAINED_CLAY:12,15,STAINED_CLAY:15,5,CONCRETE:7,100)
RandomBlock(-6,11,2,CONCRETE:7,70,STAINED_CLAY:12,15,STAINED_CLAY:15,5,CONCRETE:7,100)
RandomBlock(-6,11,3,CONCRETE:7,70,STAINED_CLAY:12,15,STAINED_CLAY:15,5,CONCRETE:7,100)
RandomBlock(-6,12,-2,CONCRETE:7,70,STAINED_CLAY:12,15,STAINED_CLAY:15,5,CONCRETE:7,100)
RandomBlock(-6,12,-1,CONCRETE:7,70,STAINED_CLAY:12,15,STAINED_CLAY:15,5,CONCRETE:7,100)
RandomBlock(-6,12,0,CONCRETE:7,70,STAINED_CLAY:12,15,STAINED_CLAY:15,5,CONCRETE:7,100)
RandomBlock(-6,12,1,CONCRETE:7,70,STAINED_CLAY:12,15,STAINED_CLAY:15,5,CONCRETE:7,100)
RandomBlock(-6,12,2,CONCRETE:7,70,STAINED_CLAY:12,15,STAINED_CLAY:15,5,CONCRETE:7,100)
RandomBlock(-6,12,3,CONCRETE:7,70,STAINED_CLAY:12,15,STAINED_CLAY:15,5,CONCRETE:7,100)
RandomBlock(-6,13,-2,CONCRETE:7,70,STAINED_CLAY:12,15,STAINED_CLAY:15,5,CONCRETE:7,100)
RandomBlock(-6,13,-1,CONCRETE:7,70,STAINED_CLAY:12,15,STAINED_CLAY:15,5,CONCRETE:7,100)
RandomBlock(-6,13,0,CONCRETE:7,70,STAINED_CLAY:12,15,STAINED_CLAY:15,5,CONCRETE:7,100)
RandomBlock(-6,13,1,CONCRETE:7,70,STAINED_CLAY:12,15,STAINED_CLAY:15,5,CONCRETE:7,100)
RandomBlock(-6,13,2,CONCRETE:7,70,STAINED_CLAY:12,15,STAINED_CLAY:15,5,CONCRETE:7,100)
RandomBlock(-6,13,3,CONCRETE:7,70,STAINED_CLAY:12,15,STAINED_CLAY:15,5,CONCRETE:7,100)
RandomBlock(-6,14,-2,CONCRETE:7,70,STAINED_CLAY:12,15,STAINED_CLAY:15,5,CONCRETE:7,100)
RandomBlock(-6,14,-1,CONCRETE:7,70,STAINED_CLAY:12,15,STAINED_CLAY:15,5,CONCRETE:7,100)
RandomBlock(-6,14,0,CONCRETE:7,70,STAINED_CLAY:12,15,STAINED_CLAY:15,5,CONCRETE:7,100)
RandomBlock(-6,14,1,CONCRETE:7,70,STAINED_CLAY:12,15,STAINED_CLAY:15,5,CONCRETE:7,100)
RandomBlock(-6,14,2,CONCRETE:7,70,STAINED_CLAY:12,15,STAINED_CLAY:15,5,CONCRETE:7,100)
RandomBlock(-6,14,3,CONCRETE:7,70,STAINED_CLAY:12,15,STAINED_CLAY:15,5,CONCRETE:7,100)
RandomBlock(-6,15,-2,CONCRETE:7,70,STAINED_CLAY:12,15,STAINED_CLAY:15,5,CONCRETE:7,100)
Block(-6,15,-1,STEP:0)
Block(-6,15,0,STEP:0)
Block(-6,15,1,STEP:0)
Block(-6,15,2,STEP:0)
RandomBlock(-6,15,3,CONCRETE:7,70,STAINED_CLAY:12,15,STAINED_CLAY:15,5,CONCRETE:7,100)
RandomBlock(-6,16,-2,CONCRETE:7,70,STAINED_CLAY:12,15,STAINED_CLAY:15,5,CONCRETE:7,100)
RandomBlock(-6,16,3,CONCRETE:7,70,STAINED_CLAY:12,15,STAINED_CLAY:15,5,CONCRETE:7,100)
Block(-6,21,0,AIR:0)
Block(-6,21,1,AIR:0)
Block(-6,21,2,AIR:0)
Block(-6,21,3,AIR:0)
Block(-6,22,-1,AIR:0)
Block(-6,22,0,AIR:0)
Block(-6,22,1,AIR:0)
Block(-6,22,2,AIR:0)
Block(-6,22,3,AIR:0)
Block(-6,22,4,AIR:0)
RandomBlock(-5,11,-2,CONCRETE:7,70,STAINED_CLAY:12,15,STAINED_CLAY:15,5,CONCRETE:7,100)
RandomBlock(-5,11,-1,CONCRETE:7,70,STAINED_CLAY:12,15,STAINED_CLAY:15,5,CONCRETE:7,100)
RandomBlock(-5,11,0,CONCRETE:7,70,STAINED_CLAY:12,15,STAINED_CLAY:15,5,CONCRETE:7,100)
RandomBlock(-5,11,1,CONCRETE:7,70,STAINED_CLAY:12,15,STAINED_CLAY:15,5,CONCRETE:7,100)
RandomBlock(-5,11,2,CONCRETE:7,70,STAINED_CLAY:12,15,STAINED_CLAY:15,5,CONCRETE:7,100)
RandomBlock(-5,11,3,CONCRETE:7,70,STAINED_CLAY:12,15,STAINED_CLAY:15,5,CONCRETE:7,100)
RandomBlock(-5,12,-2,CONCRETE:7,70,STAINED_CLAY:12,15,STAINED_CLAY:15,5,CONCRETE:7,100)
RandomBlock(-5,12,-1,CONCRETE:7,70,STAINED_CLAY:12,15,STAINED_CLAY:15,5,CONCRETE:7,100)
RandomBlock(-5,12,0,CONCRETE:7,70,STAINED_CLAY:12,15,STAINED_CLAY:15,5,CONCRETE:7,100)
RandomBlock(-5,12,1,CONCRETE:7,70,STAINED_CLAY:12,15,STAINED_CLAY:15,5,CONCRETE:7,100)
RandomBlock(-5,12,2,CONCRETE:7,70,STAINED_CLAY:12,15,STAINED_CLAY:15,5,CONCRETE:7,100)
RandomBlock(-5,12,3,CONCRETE:7,70,STAINED_CLAY:12,15,STAINED_CLAY:15,5,CONCRETE:7,100)
RandomBlock(-5,13,-2,CONCRETE:7,70,STAINED_CLAY:12,15,STAINED_CLAY:15,5,CONCRETE:7,100)
RandomBlock(-5,13,-1,CONCRETE:7,70,STAINED_CLAY:12,15,STAINED_CLAY:15,5,CONCRETE:7,100)
RandomBlock(-5,13,0,CONCRETE:7,70,STAINED_CLAY:12,15,STAINED_CLAY:15,5,CONCRETE:7,100)
RandomBlock(-5,13,1,CONCRETE:7,70,STAINED_CLAY:12,15,STAINED_CLAY:15,5,CONCRETE:7,100)
RandomBlock(-5,13,2,CONCRETE:7,70,STAINED_CLAY:12,15,STAINED_CLAY:15,5,CONCRETE:7,100)
RandomBlock(-5,13,3,CONCRETE:7,70,STAINED_CLAY:12,15,STAINED_CLAY:15,5,CONCRETE:7,100)
RandomBlock(-5,14,-2,CONCRETE:7,70,STAINED_CLAY:12,15,STAINED_CLAY:15,5,CONCRETE:7,100)
RandomBlock(-5,14,-1,CONCRETE:7,70,STAINED_CLAY:12,15,STAINED_CLAY:15,5,CONCRETE:7,100)
RandomBlock(-5,14,0,CONCRETE:7,70,STAINED_CLAY:12,15,STAINED_CLAY:15,5,CONCRETE:7,100)
RandomBlock(-5,14,1,CONCRETE:7,70,STAINED_CLAY:12,15,STAINED_CLAY:15,5,CONCRETE:7,100)
RandomBlock(-5,14,2,CONCRETE:7,70,STAINED_CLAY:12,15,STAINED_CLAY:15,5,CONCRETE:7,100)
RandomBlock(-5,14,3,CONCRETE:7,70,STAINED_CLAY:12,15,STAINED_CLAY:15,5,CONCRETE:7,100)
RandomBlock(-5,15,-2,CONCRETE:7,70,STAINED_CLAY:12,15,STAINED_CLAY:15,5,CONCRETE:7,100)
Block(-5,15,-1,STEP:0)
Block(-5,15,0,STEP:0)
Block(-5,15,1,STEP:0)
Block(-5,15,2,STEP:0)
RandomBlock(-5,15,3,CONCRETE:7,70,STAINED_CLAY:12,15,STAINED_CLAY:15,5,CONCRETE:7,100)
RandomBlock(-5,16,-2,CONCRETE:7,70,STAINED_CLAY:12,15,STAINED_CLAY:15,5,CONCRETE:7,100)
RandomBlock(-5,16,3,CONCRETE:7,70,STAINED_CLAY:12,15,STAINED_CLAY:15,5,CONCRETE:7,100)
Block(-5,21,1,AIR:0)
Block(-5,21,2,AIR:0)
Block(-5,22,0,AIR:0)
Block(-5,22,1,AIR:0)
Block(-5,22,2,AIR:0)
Block(-5,22,3,AIR:0)
RandomBlock(-4,11,-2,CONCRETE:7,70,STAINED_CLAY:12,15,STAINED_CLAY:15,5,CONCRETE:7,100)
RandomBlock(-4,11,-1,CONCRETE:7,70,STAINED_CLAY:12,15,STAINED_CLAY:15,5,CONCRETE:7,100)
RandomBlock(-4,11,0,CONCRETE:7,70,STAINED_CLAY:12,15,STAINED_CLAY:15,5,CONCRETE:7,100)
RandomBlock(-4,11,1,CONCRETE:7,70,STAINED_CLAY:12,15,STAINED_CLAY:15,5,CONCRETE:7,100)
RandomBlock(-4,11,2,CONCRETE:7,70,STAINED_CLAY:12,15,STAINED_CLAY:15,5,CONCRETE:7,100)
RandomBlock(-4,11,3,CONCRETE:7,70,STAINED_CLAY:12,15,STAINED_CLAY:15,5,CONCRETE:7,100)
RandomBlock(-4,12,-2,CONCRETE:7,70,STAINED_CLAY:12,15,STAINED_CLAY:15,5,CONCRETE:7,100)
RandomBlock(-4,12,-1,CONCRETE:7,70,STAINED_CLAY:12,15,STAINED_CLAY:15,5,CONCRETE:7,100)
RandomBlock(-4,12,0,CONCRETE:7,70,STAINED_CLAY:12,15,STAINED_CLAY:15,5,CONCRETE:7,100)
RandomBlock(-4,12,1,CONCRETE:7,70,STAINED_CLAY:12,15,STAINED_CLAY:15,5,CONCRETE:7,100)
RandomBlock(-4,12,2,CONCRETE:7,70,STAINED_CLAY:12,15,STAINED_CLAY:15,5,CONCRETE:7,100)
RandomBlock(-4,12,3,CONCRETE:7,70,STAINED_CLAY:12,15,STAINED_CLAY:15,5,CONCRETE:7,100)
RandomBlock(-4,13,-2,CONCRETE:7,70,STAINED_CLAY:12,15,STAINED_CLAY:15,5,CONCRETE:7,100)
RandomBlock(-4,13,-1,CONCRETE:7,70,STAINED_CLAY:12,15,STAINED_CLAY:15,5,CONCRETE:7,100)
RandomBlock(-4,13,0,CONCRETE:7,70,STAINED_CLAY:12,15,STAINED_CLAY:15,5,CONCRETE:7,100)
RandomBlock(-4,13,1,CONCRETE:7,70,STAINED_CLAY:12,15,STAINED_CLAY:15,5,CONCRETE:7,100)
RandomBlock(-4,13,2,CONCRETE:7,70,STAINED_CLAY:12,15,STAINED_CLAY:15,5,CONCRETE:7,100)
RandomBlock(-4,13,3,CONCRETE:7,70,STAINED_CLAY:12,15,STAINED_CLAY:15,5,CONCRETE:7,100)
RandomBlock(-4,14,-2,CONCRETE:7,70,STAINED_CLAY:12,15,STAINED_CLAY:15,5,CONCRETE:7,100)
RandomBlock(-4,14,-1,CONCRETE:7,70,STAINED_CLAY:12,15,STAINED_CLAY:15,5,CONCRETE:7,100)
RandomBlock(-4,14,0,CONCRETE:7,70,STAINED_CLAY:12,15,STAINED_CLAY:15,5,CONCRETE:7,100)
RandomBlock(-4,14,1,CONCRETE:7,70,STAINED_CLAY:12,15,STAINED_CLAY:15,5,CONCRETE:7,100)
RandomBlock(-4,14,2,CONCRETE:7,70,STAINED_CLAY:12,15,STAINED_CLAY:15,5,CONCRETE:7,100)
RandomBlock(-4,14,3,CONCRETE:7,70,STAINED_CLAY:12,15,STAINED_CLAY:15,5,CONCRETE:7,100)
RandomBlock(-4,15,-2,CONCRETE:7,70,STAINED_CLAY:12,15,STAINED_CLAY:15,5,CONCRETE:7,100)
RandomBlock(-4,15,-1,CONCRETE:7,70,STAINED_CLAY:12,15,STAINED_CLAY:15,5,CONCRETE:7,100)
RandomBlock(-4,15,0,CONCRETE:7,70,STAINED_CLAY:12,15,STAINED_CLAY:15,5,CONCRETE:7,100)
RandomBlock(-4,15,1,CONCRETE:7,70,STAINED_CLAY:12,15,STAINED_CLAY:15,5,CONCRETE:7,100)
RandomBlock(-4,15,2,CONCRETE:7,70,STAINED_CLAY:12,15,STAINED_CLAY:15,5,CONCRETE:7,100)
RandomBlock(-4,15,3,CONCRETE:7,70,STAINED_CLAY:12,15,STAINED_CLAY:15,5,CONCRETE:7,100)
RandomBlock(-4,16,-2,CONCRETE:7,70,STAINED_CLAY:12,15,STAINED_CLAY:15,5,CONCRETE:7,100)
RandomBlock(-4,16,3,CONCRETE:7,70,STAINED_CLAY:12,15,STAINED_CLAY:15,5,CONCRETE:7,100)
Block(-4,22,1,AIR:0)
Block(-4,22,2,AIR:0)
Block(-4,22,3,AIR:0)
Block(-3,22,1,AIR:0)
Block(-3,22,2,AIR:0)
Block(-2,22,2,AIR:0)
Block(-1,22,2,AIR:0)

#Block(-4,0,-2,CONCRETE:15)
#Block(-4,0,3,CONCRETE:15)
#Block(-4,1,-2,CONCRETE:15)
#Block(-4,1,3,CONCRETE:15)
#Block(-4,2,-2,CONCRETE:15)
#Block(-4,2,3,CONCRETE:15)
#Block(-8,10,-2,CONCRETE:15)
#Block(-8,10,3,CONCRETE:15)
#Block(-7,10,-2,CONCRETE:15)
#Block(-7,10,3,CONCRETE:15)
#Block(-6,10,-2,CONCRETE:15)
#Block(-6,10,3,CONCRETE:15)
#Block(-5,10,-2,CONCRETE:15)
#Block(-5,10,3,CONCRETE:15)
#Block(-4,3,-2,CONCRETE:15)
#Block(-4,3,3,CONCRETE:15)
#Block(-4,4,-2,CONCRETE:15)
#Block(-4,4,3,CONCRETE:15)
#Block(-4,5,-2,CONCRETE:15)
#Block(-4,5,3,CONCRETE:15)
#Block(-4,6,-2,CONCRETE:15)
#Block(-4,6,3,CONCRETE:15)
#Block(-4,7,-2,CONCRETE:15)
#Block(-4,7,3,CONCRETE:15)
#Block(-4,8,-2,CONCRETE:15)
#Block(-4,8,3,CONCRETE:15)
#Block(-4,9,-2,CONCRETE:15)
#Block(-4,9,3,CONCRETE:15)
#Block(-4,10,-2,CONCRETE:15)
#Block(-4,10,3,CONCRETE:15)








#######################################################################
# +-----------------------------------------------------------------+ #
# |                             Branches                            | #
# +-----------------------------------------------------------------+ #
#######################################################################

Branch(0,0,16,true,DeepTunnel_EntranceHighC2R2,NORTH,100.0,0)


#######################################################################
# +-----------------------------------------------------------------+ #
# |                             Entities                            | #
# +-----------------------------------------------------------------+ #
#######################################################################


#######################################################################
# +-----------------------------------------------------------------+ #
# |                            Particles                            | #
# +-----------------------------------------------------------------+ #
#######################################################################


#######################################################################
# +-----------------------------------------------------------------+ #
# |                             Spawners                            | #
# +-----------------------------------------------------------------+ #
#######################################################################


#######################################################################
# +-----------------------------------------------------------------+ #
# |                             ModData                             | #
# +-----------------------------------------------------------------+ #
#######################################################################

