
#######################################################################
# +-----------------------------------------------------------------+ #
# |                            BO4 object                           | #
# +-----------------------------------------------------------------+ #
#######################################################################

Author: NLBlackEagle

Description: No description given

SettingsMode: WriteDisable


#######################################################################
# +-----------------------------------------------------------------+ #
# |                          Main settings                          | #
# +-----------------------------------------------------------------+ #
#######################################################################

Frequency: 0

SpawnHeight: highestBlock

UseCenterForHighestBlock: true

##############################
# Height Limits for the BO4. #
##############################

MinHeight: 0

MaxHeight: 255

InheritBO3: 

InheritBO3Rotation: NORTH

OverrideChildSettings: true

OverrideParentHeight: false

CanOverride: true

BranchFrequency: 0

BranchFrequencyGroup: 

MustBeBelowOther: false

MustBeInside: 

CannotBeInside: 

ReplacesBO3: 

MustBeInsideWorldBorders: false

CanSpawnOnWater: true

SpawnOnWaterOnly: false

SpawnUnderWater: false

SpawnAtWaterLevel: false

HeightOffset: 0

RemoveAir: false

ReplaceAbove: 

ReplaceBelow: 

ReplaceWithBiomeBlocks: false

ReplaceWithSurfaceBlock: GRASS

ReplaceWithGroundBlock: DIRT

ReplaceWithStoneBlock: STONE

SmoothRadius: 0

SmoothHeightOffset: 0

SmoothStartTop: false

SmoothStartWood: false

SmoothingSurfaceBlock: 

SmoothingGroundBlock: 

BO3Group: 

IsSpawnPoint: false

DoReplaceBlocks: false


#######################################################################
# +-----------------------------------------------------------------+ #
# |                              Blocks                             | #
# +-----------------------------------------------------------------+ #
#######################################################################

RandomBlock(-8,11,-6,CONCRETE:7,70,STAINED_CLAY:12,15,STAINED_CLAY:15,5,CONCRETE:7,100)
Block(-8,11,-5,IRON_FENCE:0)
Block(-8,11,-4,LADDER:4)
Block(-8,11,-3,IRON_FENCE:0)
RandomBlock(-8,11,-2,CONCRETE:7,70,STAINED_CLAY:12,15,STAINED_CLAY:15,5,CONCRETE:7,100)
Block(-8,11,-1,STAINED_CLAY:9)
Block(-8,11,0,STAINED_CLAY:9)
Block(-8,11,1,STAINED_CLAY:9)
Block(-8,11,2,STAINED_CLAY:9)
RandomBlock(-8,11,3,CONCRETE:7,70,STAINED_CLAY:12,15,STAINED_CLAY:15,5,CONCRETE:7,100)
Block(-8,11,4,IRON_FENCE:0)
Block(-8,11,5,LADDER:4)
Block(-8,11,6,IRON_FENCE:0)
RandomBlock(-8,11,7,CONCRETE:7,70,STAINED_CLAY:12,15,STAINED_CLAY:15,5,CONCRETE:7,100)
RandomBlock(-8,12,-6,CONCRETE:7,70,STAINED_CLAY:12,15,STAINED_CLAY:15,5,CONCRETE:7,100)
Block(-8,12,-5,IRON_FENCE:0)
Block(-8,12,-4,LADDER:4)
Block(-8,12,-3,IRON_FENCE:0)
RandomBlock(-8,12,-2,CONCRETE:7,70,STAINED_CLAY:12,15,STAINED_CLAY:15,5,CONCRETE:7,100)
Block(-8,12,-1,AIR:0)
Block(-8,12,0,AIR:0)
Block(-8,12,1,AIR:0)
Block(-8,12,2,AIR:0)
RandomBlock(-8,12,3,CONCRETE:7,70,STAINED_CLAY:12,15,STAINED_CLAY:15,5,CONCRETE:7,100)
Block(-8,12,4,IRON_FENCE:0)
Block(-8,12,5,LADDER:4)
Block(-8,12,6,IRON_FENCE:0)
RandomBlock(-8,12,7,CONCRETE:7,70,STAINED_CLAY:12,15,STAINED_CLAY:15,5,CONCRETE:7,100)
RandomBlock(-8,13,-6,CONCRETE:7,70,STAINED_CLAY:12,15,STAINED_CLAY:15,5,CONCRETE:7,100)
Block(-8,13,-5,IRON_FENCE:0)
Block(-8,13,-4,LADDER:4)
Block(-8,13,-3,IRON_FENCE:0)
RandomBlock(-8,13,-2,CONCRETE:7,70,STAINED_CLAY:12,15,STAINED_CLAY:15,5,CONCRETE:7,100)
Block(-8,13,-1,AIR:0)
Block(-8,13,0,AIR:0)
Block(-8,13,1,AIR:0)
Block(-8,13,2,AIR:0)
RandomBlock(-8,13,3,CONCRETE:7,70,STAINED_CLAY:12,15,STAINED_CLAY:15,5,CONCRETE:7,100)
Block(-8,13,4,IRON_FENCE:0)
Block(-8,13,5,LADDER:4)
Block(-8,13,6,IRON_FENCE:0)
RandomBlock(-8,13,7,CONCRETE:7,70,STAINED_CLAY:12,15,STAINED_CLAY:15,5,CONCRETE:7,100)
RandomBlock(-8,14,-6,CONCRETE:7,70,STAINED_CLAY:12,15,STAINED_CLAY:15,5,CONCRETE:7,100)
Block(-8,14,-5,IRON_FENCE:0)
Block(-8,14,-4,LADDER:4)
Block(-8,14,-3,IRON_FENCE:0)
RandomBlock(-8,14,-2,CONCRETE:7,70,STAINED_CLAY:12,15,STAINED_CLAY:15,5,CONCRETE:7,100)
Block(-8,14,-1,AIR:0)
Block(-8,14,0,AIR:0)
Block(-8,14,1,AIR:0)
Block(-8,14,2,AIR:0)
RandomBlock(-8,14,3,CONCRETE:7,70,STAINED_CLAY:12,15,STAINED_CLAY:15,5,CONCRETE:7,100)
Block(-8,14,4,IRON_FENCE:0)
Block(-8,14,5,LADDER:4)
Block(-8,14,6,IRON_FENCE:0)
RandomBlock(-8,14,7,CONCRETE:7,70,STAINED_CLAY:12,15,STAINED_CLAY:15,5,CONCRETE:7,100)
RandomBlock(-8,15,-7,CONCRETE:7,70,STAINED_CLAY:12,15,STAINED_CLAY:15,5,CONCRETE:7,100)
RandomBlock(-8,15,-6,CONCRETE:7,70,STAINED_CLAY:12,15,STAINED_CLAY:15,5,CONCRETE:7,100)
Block(-8,15,-5,IRON_TRAPDOOR:0)
Block(-8,15,-4,LADDER:4)
Block(-8,15,-3,IRON_TRAPDOOR:0)
RandomBlock(-8,15,-2,CONCRETE:7,70,STAINED_CLAY:12,15,STAINED_CLAY:15,5,CONCRETE:7,100)
Block(-8,15,-1,AIR:0)
Block(-8,15,0,AIR:0)
Block(-8,15,1,AIR:0)
Block(-8,15,2,AIR:0)
RandomBlock(-8,15,3,CONCRETE:7,70,STAINED_CLAY:12,15,STAINED_CLAY:15,5,CONCRETE:7,100)
Block(-8,15,4,IRON_TRAPDOOR:1)
Block(-8,15,5,LADDER:4)
Block(-8,15,6,IRON_TRAPDOOR:1)
RandomBlock(-8,15,7,CONCRETE:7,70,STAINED_CLAY:12,15,STAINED_CLAY:15,5,CONCRETE:7,100)
RandomBlock(-8,15,8,CONCRETE:7,70,STAINED_CLAY:12,15,STAINED_CLAY:15,5,CONCRETE:7,100)
RandomBlock(-8,16,-7,CONCRETE:7,70,STAINED_CLAY:12,15,STAINED_CLAY:15,5,CONCRETE:7,100)
RandomBlock(-8,16,-6,CONCRETE:7,70,STAINED_CLAY:12,15,STAINED_CLAY:15,5,CONCRETE:7,100)
Block(-8,16,-5,AIR:0)
Block(-8,16,-4,LADDER:4)
Block(-8,16,-3,AIR:0)
RandomBlock(-8,16,-2,CONCRETE:7,70,STAINED_CLAY:12,15,STAINED_CLAY:15,5,CONCRETE:7,100)
Block(-8,16,-1,IRON_TRAPDOOR:10)
Block(-8,16,0,IRON_TRAPDOOR:10)
Block(-8,16,1,IRON_TRAPDOOR:10)
Block(-8,16,2,IRON_TRAPDOOR:10)
RandomBlock(-8,16,3,CONCRETE:7,70,STAINED_CLAY:12,15,STAINED_CLAY:15,5,CONCRETE:7,100)
Block(-8,16,4,AIR:0)
Block(-8,16,5,LADDER:4)
Block(-8,16,6,AIR:0)
RandomBlock(-8,16,7,CONCRETE:7,70,STAINED_CLAY:12,15,STAINED_CLAY:15,5,CONCRETE:7,100)
RandomBlock(-8,16,8,CONCRETE:7,70,STAINED_CLAY:12,15,STAINED_CLAY:15,5,CONCRETE:7,100)
RandomBlock(-8,17,-7,CONCRETE:7,70,STAINED_CLAY:12,15,STAINED_CLAY:15,5,CONCRETE:7,100)
RandomBlock(-8,17,-6,CONCRETE:7,70,STAINED_CLAY:12,15,STAINED_CLAY:15,5,CONCRETE:7,100)
Block(-8,17,-5,AIR:0)
Block(-8,17,-4,AIR:0)
Block(-8,17,-3,AIR:0)
RandomBlock(-8,17,-2,CONCRETE:7,70,STAINED_CLAY:12,15,STAINED_CLAY:15,5,CONCRETE:7,100)
Block(-8,17,-1,STEP:0)
Block(-8,17,0,AIR:0)
Block(-8,17,1,AIR:0)
Block(-8,17,2,STEP:0)
RandomBlock(-8,17,3,CONCRETE:7,70,STAINED_CLAY:12,15,STAINED_CLAY:15,5,CONCRETE:7,100)
Block(-8,17,4,AIR:0)
Block(-8,17,5,AIR:0)
Block(-8,17,6,AIR:0)
RandomBlock(-8,17,7,CONCRETE:7,70,STAINED_CLAY:12,15,STAINED_CLAY:15,5,CONCRETE:7,100)
RandomBlock(-8,17,8,CONCRETE:7,70,STAINED_CLAY:12,15,STAINED_CLAY:15,5,CONCRETE:7,100)
RandomBlock(-8,18,-7,CONCRETE:7,70,STAINED_CLAY:12,15,STAINED_CLAY:15,5,CONCRETE:7,100)
RandomBlock(-8,18,-6,CONCRETE:7,70,STAINED_CLAY:12,15,STAINED_CLAY:15,5,CONCRETE:7,100)
Block(-8,18,-5,STEP:8)
Block(-8,18,-4,STEP:8)
Block(-8,18,-3,STEP:8)
RandomBlock(-8,18,-2,CONCRETE:7,70,STAINED_CLAY:12,15,STAINED_CLAY:15,5,CONCRETE:7,100)
Block(-8,18,-1,AIR:0)
Block(-8,18,0,AIR:0)
Block(-8,18,1,AIR:0)
Block(-8,18,2,AIR:0)
RandomBlock(-8,18,3,CONCRETE:7,70,STAINED_CLAY:12,15,STAINED_CLAY:15,5,CONCRETE:7,100)
Block(-8,18,4,STEP:8)
Block(-8,18,5,STEP:8)
Block(-8,18,6,STEP:8)
RandomBlock(-8,18,7,CONCRETE:7,70,STAINED_CLAY:12,15,STAINED_CLAY:15,5,CONCRETE:7,100)
RandomBlock(-8,18,8,CONCRETE:7,70,STAINED_CLAY:12,15,STAINED_CLAY:15,5,CONCRETE:7,100)
RandomBlock(-8,19,-7,CONCRETE:7,70,STAINED_CLAY:12,15,STAINED_CLAY:15,5,CONCRETE:7,100)
RandomBlock(-8,19,-6,CONCRETE:7,70,STAINED_CLAY:12,15,STAINED_CLAY:15,5,CONCRETE:7,100)
RandomBlock(-8,19,-5,CONCRETE:7,70,STAINED_CLAY:12,15,STAINED_CLAY:15,5,CONCRETE:7,100)
RandomBlock(-8,19,-4,CONCRETE:7,70,STAINED_CLAY:12,15,STAINED_CLAY:15,5,CONCRETE:7,100)
RandomBlock(-8,19,-3,CONCRETE:7,70,STAINED_CLAY:12,15,STAINED_CLAY:15,5,CONCRETE:7,100)
RandomBlock(-8,19,-2,CONCRETE:7,70,STAINED_CLAY:12,15,STAINED_CLAY:15,5,CONCRETE:7,100)
Block(-8,19,-1,AIR:0)
Block(-8,19,0,AIR:0)
Block(-8,19,1,AIR:0)
Block(-8,19,2,AIR:0)
RandomBlock(-8,19,3,CONCRETE:7,70,STAINED_CLAY:12,15,STAINED_CLAY:15,5,CONCRETE:7,100)
RandomBlock(-8,19,4,CONCRETE:7,70,STAINED_CLAY:12,15,STAINED_CLAY:15,5,CONCRETE:7,100)
RandomBlock(-8,19,5,CONCRETE:7,70,STAINED_CLAY:12,15,STAINED_CLAY:15,5,CONCRETE:7,100)
RandomBlock(-8,19,6,CONCRETE:7,70,STAINED_CLAY:12,15,STAINED_CLAY:15,5,CONCRETE:7,100)
RandomBlock(-8,19,7,CONCRETE:7,70,STAINED_CLAY:12,15,STAINED_CLAY:15,5,CONCRETE:7,100)
RandomBlock(-8,19,8,CONCRETE:7,70,STAINED_CLAY:12,15,STAINED_CLAY:15,5,CONCRETE:7,100)
RandomBlock(-8,20,-7,CONCRETE:7,70,STAINED_CLAY:12,15,STAINED_CLAY:15,5,CONCRETE:7,100)
RandomBlock(-8,20,-6,CONCRETE:7,70,STAINED_CLAY:12,15,STAINED_CLAY:15,5,CONCRETE:7,100)
RandomBlock(-8,20,-5,CONCRETE:7,70,STAINED_CLAY:12,15,STAINED_CLAY:15,5,CONCRETE:7,100)
RandomBlock(-8,20,-4,CONCRETE:7,70,STAINED_CLAY:12,15,STAINED_CLAY:15,5,CONCRETE:7,100)
RandomBlock(-8,20,-3,CONCRETE:7,70,STAINED_CLAY:12,15,STAINED_CLAY:15,5,CONCRETE:7,100)
RandomBlock(-8,20,-2,CONCRETE:7,70,STAINED_CLAY:12,15,STAINED_CLAY:15,5,CONCRETE:7,100)
RandomBlock(-8,20,-1,CONCRETE:7,70,STAINED_CLAY:12,15,STAINED_CLAY:15,5,CONCRETE:7,100)
RandomBlock(-8,20,0,CONCRETE:7,70,STAINED_CLAY:12,15,STAINED_CLAY:15,5,CONCRETE:7,100)
RandomBlock(-8,20,1,CONCRETE:7,70,STAINED_CLAY:12,15,STAINED_CLAY:15,5,CONCRETE:7,100)
RandomBlock(-8,20,2,CONCRETE:7,70,STAINED_CLAY:12,15,STAINED_CLAY:15,5,CONCRETE:7,100)
RandomBlock(-8,20,3,CONCRETE:7,70,STAINED_CLAY:12,15,STAINED_CLAY:15,5,CONCRETE:7,100)
RandomBlock(-8,20,4,CONCRETE:7,70,STAINED_CLAY:12,15,STAINED_CLAY:15,5,CONCRETE:7,100)
RandomBlock(-8,20,5,CONCRETE:7,70,STAINED_CLAY:12,15,STAINED_CLAY:15,5,CONCRETE:7,100)
RandomBlock(-8,20,6,CONCRETE:7,70,STAINED_CLAY:12,15,STAINED_CLAY:15,5,CONCRETE:7,100)
RandomBlock(-8,20,7,CONCRETE:7,70,STAINED_CLAY:12,15,STAINED_CLAY:15,5,CONCRETE:7,100)
RandomBlock(-8,20,8,CONCRETE:7,70,STAINED_CLAY:12,15,STAINED_CLAY:15,5,CONCRETE:7,100)
RandomBlock(-8,21,-7,CONCRETE:7,70,STAINED_CLAY:12,15,STAINED_CLAY:15,5,CONCRETE:7,100)
RandomBlock(-8,21,-6,CONCRETE:7,70,STAINED_CLAY:12,15,STAINED_CLAY:15,5,CONCRETE:7,100)
RandomBlock(-8,21,-5,CONCRETE:7,70,STAINED_CLAY:12,15,STAINED_CLAY:15,5,CONCRETE:7,100)
RandomBlock(-8,21,-4,CONCRETE:7,70,STAINED_CLAY:12,15,STAINED_CLAY:15,5,CONCRETE:7,100)
RandomBlock(-8,21,-3,CONCRETE:7,70,STAINED_CLAY:12,15,STAINED_CLAY:15,5,CONCRETE:7,100)
RandomBlock(-8,21,-2,CONCRETE:7,70,STAINED_CLAY:12,15,STAINED_CLAY:15,5,CONCRETE:7,100)
RandomBlock(-8,21,-1,CONCRETE:7,70,STAINED_CLAY:12,15,STAINED_CLAY:15,5,CONCRETE:7,100)
RandomBlock(-8,21,0,CONCRETE:7,70,STAINED_CLAY:12,15,STAINED_CLAY:15,5,CONCRETE:7,100)
RandomBlock(-8,21,1,CONCRETE:7,70,STAINED_CLAY:12,15,STAINED_CLAY:15,5,CONCRETE:7,100)
RandomBlock(-8,21,2,CONCRETE:7,70,STAINED_CLAY:12,15,STAINED_CLAY:15,5,CONCRETE:7,100)
RandomBlock(-8,21,3,CONCRETE:7,70,STAINED_CLAY:12,15,STAINED_CLAY:15,5,CONCRETE:7,100)
RandomBlock(-8,21,4,CONCRETE:7,70,STAINED_CLAY:12,15,STAINED_CLAY:15,5,CONCRETE:7,100)
RandomBlock(-8,21,5,CONCRETE:7,70,STAINED_CLAY:12,15,STAINED_CLAY:15,5,CONCRETE:7,100)
RandomBlock(-8,21,6,CONCRETE:7,70,STAINED_CLAY:12,15,STAINED_CLAY:15,5,CONCRETE:7,100)
RandomBlock(-8,21,7,CONCRETE:7,70,STAINED_CLAY:12,15,STAINED_CLAY:15,5,CONCRETE:7,100)
RandomBlock(-8,21,8,CONCRETE:7,70,STAINED_CLAY:12,15,STAINED_CLAY:15,5,CONCRETE:7,100)
Block(-8,22,-7,STEP:8)
Block(-8,22,-6,STEP:8)
Block(-8,22,-5,STEP:8)
Block(-8,22,-4,STEP:8)
RandomBlock(-8,22,-3,CONCRETE:7,70,STAINED_CLAY:12,15,STAINED_CLAY:15,5,CONCRETE:7,100)
Block(-8,22,-2,STEP:8)
Block(-8,22,-1,STEP:8)
Block(-8,22,0,STEP:8)
Block(-8,22,1,STEP:8)
Block(-8,22,2,STEP:8)
Block(-8,22,3,STEP:8)
RandomBlock(-8,22,4,CONCRETE:7,70,STAINED_CLAY:12,15,STAINED_CLAY:15,5,CONCRETE:7,100)
Block(-8,22,5,STEP:8)
Block(-8,22,6,STEP:8)
Block(-8,22,7,STEP:8)
Block(-8,22,8,STEP:8)
RandomBlock(-7,11,-6,CONCRETE:7,70,STAINED_CLAY:12,15,STAINED_CLAY:15,5,CONCRETE:7,100)
RandomBlock(-7,11,-5,CONCRETE:7,70,STAINED_CLAY:12,15,STAINED_CLAY:15,5,CONCRETE:7,100)
RandomBlock(-7,11,-4,CONCRETE:7,70,STAINED_CLAY:12,15,STAINED_CLAY:15,5,CONCRETE:7,100)
RandomBlock(-7,11,-3,CONCRETE:7,70,STAINED_CLAY:12,15,STAINED_CLAY:15,5,CONCRETE:7,100)
RandomBlock(-7,11,-2,CONCRETE:7,70,STAINED_CLAY:12,15,STAINED_CLAY:15,5,CONCRETE:7,100)
Block(-7,11,-1,STAINED_CLAY:9)
Block(-7,11,0,STAINED_CLAY:9)
Block(-7,11,1,STAINED_CLAY:9)
Block(-7,11,2,STAINED_CLAY:9)
RandomBlock(-7,11,3,CONCRETE:7,70,STAINED_CLAY:12,15,STAINED_CLAY:15,5,CONCRETE:7,100)
RandomBlock(-7,11,4,CONCRETE:7,70,STAINED_CLAY:12,15,STAINED_CLAY:15,5,CONCRETE:7,100)
RandomBlock(-7,11,5,CONCRETE:7,70,STAINED_CLAY:12,15,STAINED_CLAY:15,5,CONCRETE:7,100)
RandomBlock(-7,11,6,CONCRETE:7,70,STAINED_CLAY:12,15,STAINED_CLAY:15,5,CONCRETE:7,100)
RandomBlock(-7,11,7,CONCRETE:7,70,STAINED_CLAY:12,15,STAINED_CLAY:15,5,CONCRETE:7,100)
RandomBlock(-7,12,-6,CONCRETE:7,70,STAINED_CLAY:12,15,STAINED_CLAY:15,5,CONCRETE:7,100)
RandomBlock(-7,12,-5,CONCRETE:7,70,STAINED_CLAY:12,15,STAINED_CLAY:15,5,CONCRETE:7,100)
RandomBlock(-7,12,-4,CONCRETE:7,70,STAINED_CLAY:12,15,STAINED_CLAY:15,5,CONCRETE:7,100)
RandomBlock(-7,12,-3,CONCRETE:7,70,STAINED_CLAY:12,15,STAINED_CLAY:15,5,CONCRETE:7,100)
RandomBlock(-7,12,-2,CONCRETE:7,70,STAINED_CLAY:12,15,STAINED_CLAY:15,5,CONCRETE:7,100)
Block(-7,12,-1,DARK_OAK_DOOR:2)
Block(-7,12,0,AIR:0)
Block(-7,12,1,DARK_OAK_DOOR:2)
Block(-7,12,2,DARK_OAK_DOOR:2)
RandomBlock(-7,12,3,CONCRETE:7,70,STAINED_CLAY:12,15,STAINED_CLAY:15,5,CONCRETE:7,100)
RandomBlock(-7,12,4,CONCRETE:7,70,STAINED_CLAY:12,15,STAINED_CLAY:15,5,CONCRETE:7,100)
RandomBlock(-7,12,5,CONCRETE:7,70,STAINED_CLAY:12,15,STAINED_CLAY:15,5,CONCRETE:7,100)
RandomBlock(-7,12,6,CONCRETE:7,70,STAINED_CLAY:12,15,STAINED_CLAY:15,5,CONCRETE:7,100)
RandomBlock(-7,12,7,CONCRETE:7,70,STAINED_CLAY:12,15,STAINED_CLAY:15,5,CONCRETE:7,100)
RandomBlock(-7,13,-6,CONCRETE:7,70,STAINED_CLAY:12,15,STAINED_CLAY:15,5,CONCRETE:7,100)
RandomBlock(-7,13,-5,CONCRETE:7,70,STAINED_CLAY:12,15,STAINED_CLAY:15,5,CONCRETE:7,100)
RandomBlock(-7,13,-4,CONCRETE:7,70,STAINED_CLAY:12,15,STAINED_CLAY:15,5,CONCRETE:7,100)
RandomBlock(-7,13,-3,CONCRETE:7,70,STAINED_CLAY:12,15,STAINED_CLAY:15,5,CONCRETE:7,100)
RandomBlock(-7,13,-2,CONCRETE:7,70,STAINED_CLAY:12,15,STAINED_CLAY:15,5,CONCRETE:7,100)
Block(-7,13,-1,DARK_OAK_DOOR:9)
Block(-7,13,0,AIR:0)
Block(-7,13,1,DARK_OAK_DOOR:9)
Block(-7,13,2,DARK_OAK_DOOR:9)
RandomBlock(-7,13,3,CONCRETE:7,70,STAINED_CLAY:12,15,STAINED_CLAY:15,5,CONCRETE:7,100)
RandomBlock(-7,13,4,CONCRETE:7,70,STAINED_CLAY:12,15,STAINED_CLAY:15,5,CONCRETE:7,100)
RandomBlock(-7,13,5,CONCRETE:7,70,STAINED_CLAY:12,15,STAINED_CLAY:15,5,CONCRETE:7,100)
RandomBlock(-7,13,6,CONCRETE:7,70,STAINED_CLAY:12,15,STAINED_CLAY:15,5,CONCRETE:7,100)
RandomBlock(-7,13,7,CONCRETE:7,70,STAINED_CLAY:12,15,STAINED_CLAY:15,5,CONCRETE:7,100)
RandomBlock(-7,14,-6,CONCRETE:7,70,STAINED_CLAY:12,15,STAINED_CLAY:15,5,CONCRETE:7,100)
RandomBlock(-7,14,-5,CONCRETE:7,70,STAINED_CLAY:12,15,STAINED_CLAY:15,5,CONCRETE:7,100)
RandomBlock(-7,14,-4,CONCRETE:7,70,STAINED_CLAY:12,15,STAINED_CLAY:15,5,CONCRETE:7,100)
RandomBlock(-7,14,-3,CONCRETE:7,70,STAINED_CLAY:12,15,STAINED_CLAY:15,5,CONCRETE:7,100)
RandomBlock(-7,14,-2,CONCRETE:7,70,STAINED_CLAY:12,15,STAINED_CLAY:15,5,CONCRETE:7,100)
Block(-7,14,-1,DARK_OAK_DOOR:2)
Block(-7,14,0,DARK_OAK_DOOR:2)
Block(-7,14,1,DARK_OAK_DOOR:2)
Block(-7,14,2,DARK_OAK_DOOR:2)
RandomBlock(-7,14,3,CONCRETE:7,70,STAINED_CLAY:12,15,STAINED_CLAY:15,5,CONCRETE:7,100)
RandomBlock(-7,14,4,CONCRETE:7,70,STAINED_CLAY:12,15,STAINED_CLAY:15,5,CONCRETE:7,100)
RandomBlock(-7,14,5,CONCRETE:7,70,STAINED_CLAY:12,15,STAINED_CLAY:15,5,CONCRETE:7,100)
RandomBlock(-7,14,6,CONCRETE:7,70,STAINED_CLAY:12,15,STAINED_CLAY:15,5,CONCRETE:7,100)
RandomBlock(-7,14,7,CONCRETE:7,70,STAINED_CLAY:12,15,STAINED_CLAY:15,5,CONCRETE:7,100)
RandomBlock(-7,15,-7,CONCRETE:7,70,STAINED_CLAY:12,15,STAINED_CLAY:15,5,CONCRETE:7,100)
RandomBlock(-7,15,-6,CONCRETE:7,70,STAINED_CLAY:12,15,STAINED_CLAY:15,5,CONCRETE:7,100)
RandomBlock(-7,15,-5,CONCRETE:7,70,STAINED_CLAY:12,15,STAINED_CLAY:15,5,CONCRETE:7,100)
RandomBlock(-7,15,-4,CONCRETE:7,70,STAINED_CLAY:12,15,STAINED_CLAY:15,5,CONCRETE:7,100)
RandomBlock(-7,15,-3,CONCRETE:7,70,STAINED_CLAY:12,15,STAINED_CLAY:15,5,CONCRETE:7,100)
RandomBlock(-7,15,-2,CONCRETE:7,70,STAINED_CLAY:12,15,STAINED_CLAY:15,5,CONCRETE:7,100)
Block(-7,15,-1,DARK_OAK_DOOR:9)
Block(-7,15,0,DARK_OAK_DOOR:9)
Block(-7,15,1,DARK_OAK_DOOR:9)
Block(-7,15,2,DARK_OAK_DOOR:9)
RandomBlock(-7,15,3,CONCRETE:7,70,STAINED_CLAY:12,15,STAINED_CLAY:15,5,CONCRETE:7,100)
RandomBlock(-7,15,4,CONCRETE:7,70,STAINED_CLAY:12,15,STAINED_CLAY:15,5,CONCRETE:7,100)
RandomBlock(-7,15,5,CONCRETE:7,70,STAINED_CLAY:12,15,STAINED_CLAY:15,5,CONCRETE:7,100)
RandomBlock(-7,15,6,CONCRETE:7,70,STAINED_CLAY:12,15,STAINED_CLAY:15,5,CONCRETE:7,100)
RandomBlock(-7,15,7,CONCRETE:7,70,STAINED_CLAY:12,15,STAINED_CLAY:15,5,CONCRETE:7,100)
RandomBlock(-7,15,8,CONCRETE:7,70,STAINED_CLAY:12,15,STAINED_CLAY:15,5,CONCRETE:7,100)
RandomBlock(-7,16,-7,CONCRETE:7,70,STAINED_CLAY:12,15,STAINED_CLAY:15,5,CONCRETE:7,100)
RandomBlock(-7,16,-6,CONCRETE:7,70,STAINED_CLAY:12,15,STAINED_CLAY:15,5,CONCRETE:7,100)
RandomBlock(-7,16,-5,CONCRETE:7,70,STAINED_CLAY:12,15,STAINED_CLAY:15,5,CONCRETE:7,100)
RandomBlock(-7,16,-4,CONCRETE:7,70,STAINED_CLAY:12,15,STAINED_CLAY:15,5,CONCRETE:7,100)
RandomBlock(-7,16,-3,CONCRETE:7,70,STAINED_CLAY:12,15,STAINED_CLAY:15,5,CONCRETE:7,100)
RandomBlock(-7,16,-2,CONCRETE:7,70,STAINED_CLAY:12,15,STAINED_CLAY:15,5,CONCRETE:7,100)
Block(-7,16,-1,IRON_TRAPDOOR:10)
Block(-7,16,0,IRON_TRAPDOOR:9)
Block(-7,16,1,IRON_TRAPDOOR:9)
Block(-7,16,2,IRON_TRAPDOOR:9)
RandomBlock(-7,16,3,CONCRETE:7,70,STAINED_CLAY:12,15,STAINED_CLAY:15,5,CONCRETE:7,100)
RandomBlock(-7,16,4,CONCRETE:7,70,STAINED_CLAY:12,15,STAINED_CLAY:15,5,CONCRETE:7,100)
RandomBlock(-7,16,5,CONCRETE:7,70,STAINED_CLAY:12,15,STAINED_CLAY:15,5,CONCRETE:7,100)
RandomBlock(-7,16,6,CONCRETE:7,70,STAINED_CLAY:12,15,STAINED_CLAY:15,5,CONCRETE:7,100)
RandomBlock(-7,16,7,CONCRETE:7,70,STAINED_CLAY:12,15,STAINED_CLAY:15,5,CONCRETE:7,100)
RandomBlock(-7,16,8,CONCRETE:7,70,STAINED_CLAY:12,15,STAINED_CLAY:15,5,CONCRETE:7,100)
RandomBlock(-7,17,-7,CONCRETE:7,70,STAINED_CLAY:12,15,STAINED_CLAY:15,5,CONCRETE:7,100)
RandomBlock(-7,17,-6,CONCRETE:7,70,STAINED_CLAY:12,15,STAINED_CLAY:15,5,CONCRETE:7,100)
RandomBlock(-7,17,-5,CONCRETE:7,70,STAINED_CLAY:12,15,STAINED_CLAY:15,5,CONCRETE:7,100)
RandomBlock(-7,17,-4,CONCRETE:7,70,STAINED_CLAY:12,15,STAINED_CLAY:15,5,CONCRETE:7,100)
RandomBlock(-7,17,-3,CONCRETE:7,70,STAINED_CLAY:12,15,STAINED_CLAY:15,5,CONCRETE:7,100)
RandomBlock(-7,17,-2,CONCRETE:7,70,STAINED_CLAY:12,15,STAINED_CLAY:15,5,CONCRETE:7,100)
Block(-7,17,-1,STEP:0)
Block(-7,17,0,AIR:0)
Block(-7,17,1,AIR:0)
Block(-7,17,2,STEP:0)
RandomBlock(-7,17,3,CONCRETE:7,70,STAINED_CLAY:12,15,STAINED_CLAY:15,5,CONCRETE:7,100)
RandomBlock(-7,17,4,CONCRETE:7,70,STAINED_CLAY:12,15,STAINED_CLAY:15,5,CONCRETE:7,100)
RandomBlock(-7,17,5,CONCRETE:7,70,STAINED_CLAY:12,15,STAINED_CLAY:15,5,CONCRETE:7,100)
RandomBlock(-7,17,6,CONCRETE:7,70,STAINED_CLAY:12,15,STAINED_CLAY:15,5,CONCRETE:7,100)
RandomBlock(-7,17,7,CONCRETE:7,70,STAINED_CLAY:12,15,STAINED_CLAY:15,5,CONCRETE:7,100)
RandomBlock(-7,17,8,CONCRETE:7,70,STAINED_CLAY:12,15,STAINED_CLAY:15,5,CONCRETE:7,100)
RandomBlock(-7,18,-7,CONCRETE:7,70,STAINED_CLAY:12,15,STAINED_CLAY:15,5,CONCRETE:7,100)
RandomBlock(-7,18,-6,CONCRETE:7,70,STAINED_CLAY:12,15,STAINED_CLAY:15,5,CONCRETE:7,100)
RandomBlock(-7,18,-5,CONCRETE:7,70,STAINED_CLAY:12,15,STAINED_CLAY:15,5,CONCRETE:7,100)
RandomBlock(-7,18,-4,CONCRETE:7,70,STAINED_CLAY:12,15,STAINED_CLAY:15,5,CONCRETE:7,100)
RandomBlock(-7,18,-3,CONCRETE:7,70,STAINED_CLAY:12,15,STAINED_CLAY:15,5,CONCRETE:7,100)
RandomBlock(-7,18,-2,CONCRETE:7,70,STAINED_CLAY:12,15,STAINED_CLAY:15,5,CONCRETE:7,100)
RandomBlock(-7,18,-1,CONCRETE:7,70,STAINED_CLAY:12,15,STAINED_CLAY:15,5,CONCRETE:7,100)
RandomBlock(-7,18,0,CONCRETE:7,70,STAINED_CLAY:12,15,STAINED_CLAY:15,5,CONCRETE:7,100)
RandomBlock(-7,18,1,CONCRETE:7,70,STAINED_CLAY:12,15,STAINED_CLAY:15,5,CONCRETE:7,100)
RandomBlock(-7,18,2,CONCRETE:7,70,STAINED_CLAY:12,15,STAINED_CLAY:15,5,CONCRETE:7,100)
RandomBlock(-7,18,3,CONCRETE:7,70,STAINED_CLAY:12,15,STAINED_CLAY:15,5,CONCRETE:7,100)
RandomBlock(-7,18,4,CONCRETE:7,70,STAINED_CLAY:12,15,STAINED_CLAY:15,5,CONCRETE:7,100)
RandomBlock(-7,18,5,CONCRETE:7,70,STAINED_CLAY:12,15,STAINED_CLAY:15,5,CONCRETE:7,100)
RandomBlock(-7,18,6,CONCRETE:7,70,STAINED_CLAY:12,15,STAINED_CLAY:15,5,CONCRETE:7,100)
RandomBlock(-7,18,7,CONCRETE:7,70,STAINED_CLAY:12,15,STAINED_CLAY:15,5,CONCRETE:7,100)
RandomBlock(-7,18,8,CONCRETE:7,70,STAINED_CLAY:12,15,STAINED_CLAY:15,5,CONCRETE:7,100)
RandomBlock(-7,19,-7,CONCRETE:7,70,STAINED_CLAY:12,15,STAINED_CLAY:15,5,CONCRETE:7,100)
RandomBlock(-7,19,-6,CONCRETE:7,70,STAINED_CLAY:12,15,STAINED_CLAY:15,5,CONCRETE:7,100)
RandomBlock(-7,19,-5,CONCRETE:7,70,STAINED_CLAY:12,15,STAINED_CLAY:15,5,CONCRETE:7,100)
RandomBlock(-7,19,-4,CONCRETE:7,70,STAINED_CLAY:12,15,STAINED_CLAY:15,5,CONCRETE:7,100)
RandomBlock(-7,19,-3,CONCRETE:7,70,STAINED_CLAY:12,15,STAINED_CLAY:15,5,CONCRETE:7,100)
RandomBlock(-7,19,-2,CONCRETE:7,70,STAINED_CLAY:12,15,STAINED_CLAY:15,5,CONCRETE:7,100)
RandomBlock(-7,19,-1,CONCRETE:7,70,STAINED_CLAY:12,15,STAINED_CLAY:15,5,CONCRETE:7,100)
RandomBlock(-7,19,0,CONCRETE:7,70,STAINED_CLAY:12,15,STAINED_CLAY:15,5,CONCRETE:7,100)
RandomBlock(-7,19,1,CONCRETE:7,70,STAINED_CLAY:12,15,STAINED_CLAY:15,5,CONCRETE:7,100)
RandomBlock(-7,19,2,CONCRETE:7,70,STAINED_CLAY:12,15,STAINED_CLAY:15,5,CONCRETE:7,100)
RandomBlock(-7,19,3,CONCRETE:7,70,STAINED_CLAY:12,15,STAINED_CLAY:15,5,CONCRETE:7,100)
RandomBlock(-7,19,4,CONCRETE:7,70,STAINED_CLAY:12,15,STAINED_CLAY:15,5,CONCRETE:7,100)
RandomBlock(-7,19,5,CONCRETE:7,70,STAINED_CLAY:12,15,STAINED_CLAY:15,5,CONCRETE:7,100)
RandomBlock(-7,19,6,CONCRETE:7,70,STAINED_CLAY:12,15,STAINED_CLAY:15,5,CONCRETE:7,100)
RandomBlock(-7,19,7,CONCRETE:7,70,STAINED_CLAY:12,15,STAINED_CLAY:15,5,CONCRETE:7,100)
RandomBlock(-7,19,8,CONCRETE:7,70,STAINED_CLAY:12,15,STAINED_CLAY:15,5,CONCRETE:7,100)
RandomBlock(-7,20,-7,CONCRETE:7,70,STAINED_CLAY:12,15,STAINED_CLAY:15,5,CONCRETE:7,100)
RandomBlock(-7,20,-6,CONCRETE:7,70,STAINED_CLAY:12,15,STAINED_CLAY:15,5,CONCRETE:7,100)
RandomBlock(-7,20,-5,CONCRETE:7,70,STAINED_CLAY:12,15,STAINED_CLAY:15,5,CONCRETE:7,100)
RandomBlock(-7,20,-4,CONCRETE:7,70,STAINED_CLAY:12,15,STAINED_CLAY:15,5,CONCRETE:7,100)
RandomBlock(-7,20,-3,CONCRETE:7,70,STAINED_CLAY:12,15,STAINED_CLAY:15,5,CONCRETE:7,100)
RandomBlock(-7,20,-2,CONCRETE:7,70,STAINED_CLAY:12,15,STAINED_CLAY:15,5,CONCRETE:7,100)
RandomBlock(-7,20,-1,CONCRETE:7,70,STAINED_CLAY:12,15,STAINED_CLAY:15,5,CONCRETE:7,100)
RandomBlock(-7,20,0,CONCRETE:7,70,STAINED_CLAY:12,15,STAINED_CLAY:15,5,CONCRETE:7,100)
RandomBlock(-7,20,1,CONCRETE:7,70,STAINED_CLAY:12,15,STAINED_CLAY:15,5,CONCRETE:7,100)
RandomBlock(-7,20,2,CONCRETE:7,70,STAINED_CLAY:12,15,STAINED_CLAY:15,5,CONCRETE:7,100)
RandomBlock(-7,20,3,CONCRETE:7,70,STAINED_CLAY:12,15,STAINED_CLAY:15,5,CONCRETE:7,100)
RandomBlock(-7,20,4,CONCRETE:7,70,STAINED_CLAY:12,15,STAINED_CLAY:15,5,CONCRETE:7,100)
RandomBlock(-7,20,5,CONCRETE:7,70,STAINED_CLAY:12,15,STAINED_CLAY:15,5,CONCRETE:7,100)
RandomBlock(-7,20,6,CONCRETE:7,70,STAINED_CLAY:12,15,STAINED_CLAY:15,5,CONCRETE:7,100)
RandomBlock(-7,20,7,CONCRETE:7,70,STAINED_CLAY:12,15,STAINED_CLAY:15,5,CONCRETE:7,100)
RandomBlock(-7,20,8,CONCRETE:7,70,STAINED_CLAY:12,15,STAINED_CLAY:15,5,CONCRETE:7,100)
RandomBlock(-7,21,-7,CONCRETE:7,70,STAINED_CLAY:12,15,STAINED_CLAY:15,5,CONCRETE:7,100)
RandomBlock(-7,21,-6,CONCRETE:7,70,STAINED_CLAY:12,15,STAINED_CLAY:15,5,CONCRETE:7,100)
RandomBlock(-7,21,-5,CONCRETE:7,70,STAINED_CLAY:12,15,STAINED_CLAY:15,5,CONCRETE:7,100)
RandomBlock(-7,21,-4,CONCRETE:7,70,STAINED_CLAY:12,15,STAINED_CLAY:15,5,CONCRETE:7,100)
RandomBlock(-7,21,-3,CONCRETE:7,70,STAINED_CLAY:12,15,STAINED_CLAY:15,5,CONCRETE:7,100)
RandomBlock(-7,21,-2,CONCRETE:7,70,STAINED_CLAY:12,15,STAINED_CLAY:15,5,CONCRETE:7,100)
RandomBlock(-7,21,-1,CONCRETE:7,70,STAINED_CLAY:12,15,STAINED_CLAY:15,5,CONCRETE:7,100)
RandomBlock(-7,21,0,CONCRETE:7,70,STAINED_CLAY:12,15,STAINED_CLAY:15,5,CONCRETE:7,100)
RandomBlock(-7,21,1,CONCRETE:7,70,STAINED_CLAY:12,15,STAINED_CLAY:15,5,CONCRETE:7,100)
RandomBlock(-7,21,2,CONCRETE:7,70,STAINED_CLAY:12,15,STAINED_CLAY:15,5,CONCRETE:7,100)
RandomBlock(-7,21,3,CONCRETE:7,70,STAINED_CLAY:12,15,STAINED_CLAY:15,5,CONCRETE:7,100)
RandomBlock(-7,21,4,CONCRETE:7,70,STAINED_CLAY:12,15,STAINED_CLAY:15,5,CONCRETE:7,100)
RandomBlock(-7,21,5,CONCRETE:7,70,STAINED_CLAY:12,15,STAINED_CLAY:15,5,CONCRETE:7,100)
RandomBlock(-7,21,6,CONCRETE:7,70,STAINED_CLAY:12,15,STAINED_CLAY:15,5,CONCRETE:7,100)
RandomBlock(-7,21,7,CONCRETE:7,70,STAINED_CLAY:12,15,STAINED_CLAY:15,5,CONCRETE:7,100)
RandomBlock(-7,21,8,CONCRETE:7,70,STAINED_CLAY:12,15,STAINED_CLAY:15,5,CONCRETE:7,100)
Block(-7,22,-7,STEP:8)
Block(-7,22,-6,STEP:8)
Block(-7,22,-5,STEP:8)
Block(-7,22,-4,STEP:8)
RandomBlock(-7,22,-3,CONCRETE:7,70,STAINED_CLAY:12,15,STAINED_CLAY:15,5,CONCRETE:7,100)
Block(-7,22,-2,STEP:8)
Block(-7,22,-1,STEP:8)
Block(-7,22,0,STEP:8)
Block(-7,22,1,STEP:8)
Block(-7,22,2,STEP:8)
Block(-7,22,3,STEP:8)
RandomBlock(-7,22,4,CONCRETE:7,70,STAINED_CLAY:12,15,STAINED_CLAY:15,5,CONCRETE:7,100)
Block(-7,22,5,STEP:8)
Block(-7,22,6,STEP:8)
Block(-7,22,7,STEP:8)
Block(-7,22,8,STEP:8)
RandomBlock(-6,11,-2,CONCRETE:7,70,STAINED_CLAY:12,15,STAINED_CLAY:15,5,CONCRETE:7,100)
RandomBlock(-6,11,-1,CONCRETE:7,70,STAINED_CLAY:12,15,STAINED_CLAY:15,5,CONCRETE:7,100)
RandomBlock(-6,11,0,CONCRETE:7,70,STAINED_CLAY:12,15,STAINED_CLAY:15,5,CONCRETE:7,100)
RandomBlock(-6,11,1,CONCRETE:7,70,STAINED_CLAY:12,15,STAINED_CLAY:15,5,CONCRETE:7,100)
RandomBlock(-6,11,2,CONCRETE:7,70,STAINED_CLAY:12,15,STAINED_CLAY:15,5,CONCRETE:7,100)
RandomBlock(-6,11,3,CONCRETE:7,70,STAINED_CLAY:12,15,STAINED_CLAY:15,5,CONCRETE:7,100)
RandomBlock(-6,12,-2,CONCRETE:7,70,STAINED_CLAY:12,15,STAINED_CLAY:15,5,CONCRETE:7,100)
Block(-6,12,-1,IRON_TRAPDOOR:7)
Block(-6,12,0,IRON_DOOR_BLOCK:0)
Block(-6,12,1,IRON_TRAPDOOR:7)
Block(-6,12,2,IRON_TRAPDOOR:7)
RandomBlock(-6,12,3,CONCRETE:7,70,STAINED_CLAY:12,15,STAINED_CLAY:15,5,CONCRETE:7,100)
RandomBlock(-6,13,-2,CONCRETE:7,70,STAINED_CLAY:12,15,STAINED_CLAY:15,5,CONCRETE:7,100)
Block(-6,13,-1,IRON_TRAPDOOR:7)
Block(-6,13,0,IRON_DOOR_BLOCK:9)
Block(-6,13,1,IRON_TRAPDOOR:7)
Block(-6,13,2,IRON_TRAPDOOR:7)
RandomBlock(-6,13,3,CONCRETE:7,70,STAINED_CLAY:12,15,STAINED_CLAY:15,5,CONCRETE:7,100)
Block(-6,14,-6,CONCRETE:15)
Block(-6,14,-4,CONCRETE:15)
RandomBlock(-6,14,-2,CONCRETE:7,70,STAINED_CLAY:12,15,STAINED_CLAY:15,5,CONCRETE:7,100)
Block(-6,14,-1,IRON_TRAPDOOR:7)
Block(-6,14,0,IRON_TRAPDOOR:7)
Block(-6,14,1,IRON_TRAPDOOR:7)
Block(-6,14,2,IRON_TRAPDOOR:7)
RandomBlock(-6,14,3,CONCRETE:7,70,STAINED_CLAY:12,15,STAINED_CLAY:15,5,CONCRETE:7,100)
Block(-6,14,5,CONCRETE:15)
Block(-6,14,7,CONCRETE:15)
RandomBlock(-6,15,-7,CONCRETE:7,70,STAINED_CLAY:12,15,STAINED_CLAY:15,5,CONCRETE:7,100)
RandomBlock(-6,15,-6,CONCRETE:7,70,STAINED_CLAY:12,15,STAINED_CLAY:15,5,CONCRETE:7,100)
RandomBlock(-6,15,-5,CONCRETE:7,70,STAINED_CLAY:12,15,STAINED_CLAY:15,5,CONCRETE:7,100)
RandomBlock(-6,15,-4,CONCRETE:7,70,STAINED_CLAY:12,15,STAINED_CLAY:15,5,CONCRETE:7,100)
RandomBlock(-6,15,-3,CONCRETE:7,70,STAINED_CLAY:12,15,STAINED_CLAY:15,5,CONCRETE:7,100)
RandomBlock(-6,15,-2,CONCRETE:7,70,STAINED_CLAY:12,15,STAINED_CLAY:15,5,CONCRETE:7,100)
Block(-6,15,-1,IRON_TRAPDOOR:7)
Block(-6,15,0,IRON_TRAPDOOR:7)
Block(-6,15,1,IRON_TRAPDOOR:7)
Block(-6,15,2,IRON_TRAPDOOR:7)
RandomBlock(-6,15,3,CONCRETE:7,70,STAINED_CLAY:12,15,STAINED_CLAY:15,5,CONCRETE:7,100)
RandomBlock(-6,15,4,CONCRETE:7,70,STAINED_CLAY:12,15,STAINED_CLAY:15,5,CONCRETE:7,100)
RandomBlock(-6,15,5,CONCRETE:7,70,STAINED_CLAY:12,15,STAINED_CLAY:15,5,CONCRETE:7,100)
RandomBlock(-6,15,6,CONCRETE:7,70,STAINED_CLAY:12,15,STAINED_CLAY:15,5,CONCRETE:7,100)
RandomBlock(-6,15,7,CONCRETE:7,70,STAINED_CLAY:12,15,STAINED_CLAY:15,5,CONCRETE:7,100)
RandomBlock(-6,15,8,CONCRETE:7,70,STAINED_CLAY:12,15,STAINED_CLAY:15,5,CONCRETE:7,100)
RandomBlock(-6,16,-7,CONCRETE:7,70,STAINED_CLAY:12,15,STAINED_CLAY:15,5,CONCRETE:7,100)
RandomBlock(-6,16,-6,CONCRETE:7,70,STAINED_CLAY:12,15,STAINED_CLAY:15,5,CONCRETE:7,100)
RandomBlock(-6,16,-5,CONCRETE:7,70,STAINED_CLAY:12,15,STAINED_CLAY:15,5,CONCRETE:7,100)
RandomBlock(-6,16,-4,CONCRETE:7,70,STAINED_CLAY:12,15,STAINED_CLAY:15,5,CONCRETE:7,100)
RandomBlock(-6,16,-3,CONCRETE:7,70,STAINED_CLAY:12,15,STAINED_CLAY:15,5,CONCRETE:7,100)
RandomBlock(-6,16,-2,CONCRETE:7,70,STAINED_CLAY:12,15,STAINED_CLAY:15,5,CONCRETE:7,100)
Block(-6,16,-1,IRON_TRAPDOOR:7)
Block(-6,16,0,IRON_TRAPDOOR:7)
Block(-6,16,1,IRON_TRAPDOOR:7)
Block(-6,16,2,IRON_TRAPDOOR:7)
RandomBlock(-6,16,3,CONCRETE:7,70,STAINED_CLAY:12,15,STAINED_CLAY:15,5,CONCRETE:7,100)
RandomBlock(-6,16,4,CONCRETE:7,70,STAINED_CLAY:12,15,STAINED_CLAY:15,5,CONCRETE:7,100)
RandomBlock(-6,16,5,CONCRETE:7,70,STAINED_CLAY:12,15,STAINED_CLAY:15,5,CONCRETE:7,100)
RandomBlock(-6,16,6,CONCRETE:7,70,STAINED_CLAY:12,15,STAINED_CLAY:15,5,CONCRETE:7,100)
RandomBlock(-6,16,7,CONCRETE:7,70,STAINED_CLAY:12,15,STAINED_CLAY:15,5,CONCRETE:7,100)
RandomBlock(-6,16,8,CONCRETE:7,70,STAINED_CLAY:12,15,STAINED_CLAY:15,5,CONCRETE:7,100)
RandomBlock(-6,17,-7,CONCRETE:7,70,STAINED_CLAY:12,15,STAINED_CLAY:15,5,CONCRETE:7,100)
RandomBlock(-6,17,-6,CONCRETE:7,70,STAINED_CLAY:12,15,STAINED_CLAY:15,5,CONCRETE:7,100)
RandomBlock(-6,17,-5,CONCRETE:7,70,STAINED_CLAY:12,15,STAINED_CLAY:15,5,CONCRETE:7,100)
RandomBlock(-6,17,-4,CONCRETE:7,70,STAINED_CLAY:12,15,STAINED_CLAY:15,5,CONCRETE:7,100)
RandomBlock(-6,17,-3,CONCRETE:7,70,STAINED_CLAY:12,15,STAINED_CLAY:15,5,CONCRETE:7,100)
RandomBlock(-6,17,-2,CONCRETE:7,70,STAINED_CLAY:12,15,STAINED_CLAY:15,5,CONCRETE:7,100)
RandomBlock(-6,17,-1,CONCRETE:7,70,STAINED_CLAY:12,15,STAINED_CLAY:15,5,CONCRETE:7,100)
RandomBlock(-6,17,0,CONCRETE:7,70,STAINED_CLAY:12,15,STAINED_CLAY:15,5,CONCRETE:7,100)
RandomBlock(-6,17,1,CONCRETE:7,70,STAINED_CLAY:12,15,STAINED_CLAY:15,5,CONCRETE:7,100)
RandomBlock(-6,17,2,CONCRETE:7,70,STAINED_CLAY:12,15,STAINED_CLAY:15,5,CONCRETE:7,100)
RandomBlock(-6,17,3,CONCRETE:7,70,STAINED_CLAY:12,15,STAINED_CLAY:15,5,CONCRETE:7,100)
RandomBlock(-6,17,4,CONCRETE:7,70,STAINED_CLAY:12,15,STAINED_CLAY:15,5,CONCRETE:7,100)
RandomBlock(-6,17,5,CONCRETE:7,70,STAINED_CLAY:12,15,STAINED_CLAY:15,5,CONCRETE:7,100)
RandomBlock(-6,17,6,CONCRETE:7,70,STAINED_CLAY:12,15,STAINED_CLAY:15,5,CONCRETE:7,100)
RandomBlock(-6,17,7,CONCRETE:7,70,STAINED_CLAY:12,15,STAINED_CLAY:15,5,CONCRETE:7,100)
RandomBlock(-6,17,8,CONCRETE:7,70,STAINED_CLAY:12,15,STAINED_CLAY:15,5,CONCRETE:7,100)
RandomBlock(-6,18,-7,CONCRETE:7,70,STAINED_CLAY:12,15,STAINED_CLAY:15,5,CONCRETE:7,100)
RandomBlock(-6,18,-6,CONCRETE:7,70,STAINED_CLAY:12,15,STAINED_CLAY:15,5,CONCRETE:7,100)
RandomBlock(-6,18,-5,CONCRETE:7,70,STAINED_CLAY:12,15,STAINED_CLAY:15,5,CONCRETE:7,100)
RandomBlock(-6,18,-4,CONCRETE:7,70,STAINED_CLAY:12,15,STAINED_CLAY:15,5,CONCRETE:7,100)
RandomBlock(-6,18,-3,CONCRETE:7,70,STAINED_CLAY:12,15,STAINED_CLAY:15,5,CONCRETE:7,100)
RandomBlock(-6,18,-2,CONCRETE:7,70,STAINED_CLAY:12,15,STAINED_CLAY:15,5,CONCRETE:7,100)
RandomBlock(-6,18,-1,CONCRETE:7,70,STAINED_CLAY:12,15,STAINED_CLAY:15,5,CONCRETE:7,100)
RandomBlock(-6,18,0,CONCRETE:7,70,STAINED_CLAY:12,15,STAINED_CLAY:15,5,CONCRETE:7,100)
RandomBlock(-6,18,1,CONCRETE:7,70,STAINED_CLAY:12,15,STAINED_CLAY:15,5,CONCRETE:7,100)
RandomBlock(-6,18,2,CONCRETE:7,70,STAINED_CLAY:12,15,STAINED_CLAY:15,5,CONCRETE:7,100)
RandomBlock(-6,18,3,CONCRETE:7,70,STAINED_CLAY:12,15,STAINED_CLAY:15,5,CONCRETE:7,100)
RandomBlock(-6,18,4,CONCRETE:7,70,STAINED_CLAY:12,15,STAINED_CLAY:15,5,CONCRETE:7,100)
RandomBlock(-6,18,5,CONCRETE:7,70,STAINED_CLAY:12,15,STAINED_CLAY:15,5,CONCRETE:7,100)
RandomBlock(-6,18,6,CONCRETE:7,70,STAINED_CLAY:12,15,STAINED_CLAY:15,5,CONCRETE:7,100)
RandomBlock(-6,18,7,CONCRETE:7,70,STAINED_CLAY:12,15,STAINED_CLAY:15,5,CONCRETE:7,100)
RandomBlock(-6,18,8,CONCRETE:7,70,STAINED_CLAY:12,15,STAINED_CLAY:15,5,CONCRETE:7,100)
RandomBlock(-6,19,-7,CONCRETE:7,70,STAINED_CLAY:12,15,STAINED_CLAY:15,5,CONCRETE:7,100)
RandomBlock(-6,19,-6,CONCRETE:7,70,STAINED_CLAY:12,15,STAINED_CLAY:15,5,CONCRETE:7,100)
RandomBlock(-6,19,-5,CONCRETE:7,70,STAINED_CLAY:12,15,STAINED_CLAY:15,5,CONCRETE:7,100)
RandomBlock(-6,19,-4,CONCRETE:7,70,STAINED_CLAY:12,15,STAINED_CLAY:15,5,CONCRETE:7,100)
RandomBlock(-6,19,-3,CONCRETE:7,70,STAINED_CLAY:12,15,STAINED_CLAY:15,5,CONCRETE:7,100)
RandomBlock(-6,19,-2,CONCRETE:7,70,STAINED_CLAY:12,15,STAINED_CLAY:15,5,CONCRETE:7,100)
RandomBlock(-6,19,-1,CONCRETE:7,70,STAINED_CLAY:12,15,STAINED_CLAY:15,5,CONCRETE:7,100)
RandomBlock(-6,19,0,CONCRETE:7,70,STAINED_CLAY:12,15,STAINED_CLAY:15,5,CONCRETE:7,100)
RandomBlock(-6,19,1,CONCRETE:7,70,STAINED_CLAY:12,15,STAINED_CLAY:15,5,CONCRETE:7,100)
RandomBlock(-6,19,2,CONCRETE:7,70,STAINED_CLAY:12,15,STAINED_CLAY:15,5,CONCRETE:7,100)
RandomBlock(-6,19,3,CONCRETE:7,70,STAINED_CLAY:12,15,STAINED_CLAY:15,5,CONCRETE:7,100)
RandomBlock(-6,19,4,CONCRETE:7,70,STAINED_CLAY:12,15,STAINED_CLAY:15,5,CONCRETE:7,100)
RandomBlock(-6,19,5,CONCRETE:7,70,STAINED_CLAY:12,15,STAINED_CLAY:15,5,CONCRETE:7,100)
RandomBlock(-6,19,6,CONCRETE:7,70,STAINED_CLAY:12,15,STAINED_CLAY:15,5,CONCRETE:7,100)
RandomBlock(-6,19,7,CONCRETE:7,70,STAINED_CLAY:12,15,STAINED_CLAY:15,5,CONCRETE:7,100)
RandomBlock(-6,19,8,CONCRETE:7,70,STAINED_CLAY:12,15,STAINED_CLAY:15,5,CONCRETE:7,100)
RandomBlock(-6,20,-7,CONCRETE:7,70,STAINED_CLAY:12,15,STAINED_CLAY:15,5,CONCRETE:7,100)
RandomBlock(-6,20,-6,CONCRETE:7,70,STAINED_CLAY:12,15,STAINED_CLAY:15,5,CONCRETE:7,100)
RandomBlock(-6,20,-5,CONCRETE:7,70,STAINED_CLAY:12,15,STAINED_CLAY:15,5,CONCRETE:7,100)
RandomBlock(-6,20,-4,CONCRETE:7,70,STAINED_CLAY:12,15,STAINED_CLAY:15,5,CONCRETE:7,100)
RandomBlock(-6,20,-3,CONCRETE:7,70,STAINED_CLAY:12,15,STAINED_CLAY:15,5,CONCRETE:7,100)
RandomBlock(-6,20,-2,CONCRETE:7,70,STAINED_CLAY:12,15,STAINED_CLAY:15,5,CONCRETE:7,100)
RandomBlock(-6,20,-1,CONCRETE:7,70,STAINED_CLAY:12,15,STAINED_CLAY:15,5,CONCRETE:7,100)
RandomBlock(-6,20,0,CONCRETE:7,70,STAINED_CLAY:12,15,STAINED_CLAY:15,5,CONCRETE:7,100)
RandomBlock(-6,20,1,CONCRETE:7,70,STAINED_CLAY:12,15,STAINED_CLAY:15,5,CONCRETE:7,100)
RandomBlock(-6,20,2,CONCRETE:7,70,STAINED_CLAY:12,15,STAINED_CLAY:15,5,CONCRETE:7,100)
RandomBlock(-6,20,3,CONCRETE:7,70,STAINED_CLAY:12,15,STAINED_CLAY:15,5,CONCRETE:7,100)
RandomBlock(-6,20,4,CONCRETE:7,70,STAINED_CLAY:12,15,STAINED_CLAY:15,5,CONCRETE:7,100)
RandomBlock(-6,20,5,CONCRETE:7,70,STAINED_CLAY:12,15,STAINED_CLAY:15,5,CONCRETE:7,100)
RandomBlock(-6,20,6,CONCRETE:7,70,STAINED_CLAY:12,15,STAINED_CLAY:15,5,CONCRETE:7,100)
RandomBlock(-6,20,7,CONCRETE:7,70,STAINED_CLAY:12,15,STAINED_CLAY:15,5,CONCRETE:7,100)
RandomBlock(-6,20,8,CONCRETE:7,70,STAINED_CLAY:12,15,STAINED_CLAY:15,5,CONCRETE:7,100)
RandomBlock(-6,21,-7,CONCRETE:7,70,STAINED_CLAY:12,15,STAINED_CLAY:15,5,CONCRETE:7,100)
RandomBlock(-6,21,-6,CONCRETE:7,70,STAINED_CLAY:12,15,STAINED_CLAY:15,5,CONCRETE:7,100)
RandomBlock(-6,21,-5,CONCRETE:7,70,STAINED_CLAY:12,15,STAINED_CLAY:15,5,CONCRETE:7,100)
RandomBlock(-6,21,-4,CONCRETE:7,70,STAINED_CLAY:12,15,STAINED_CLAY:15,5,CONCRETE:7,100)
RandomBlock(-6,21,-3,CONCRETE:7,70,STAINED_CLAY:12,15,STAINED_CLAY:15,5,CONCRETE:7,100)
RandomBlock(-6,21,-2,CONCRETE:7,70,STAINED_CLAY:12,15,STAINED_CLAY:15,5,CONCRETE:7,100)
RandomBlock(-6,21,-1,CONCRETE:7,70,STAINED_CLAY:12,15,STAINED_CLAY:15,5,CONCRETE:7,100)
RandomBlock(-6,21,0,CONCRETE:7,70,STAINED_CLAY:12,15,STAINED_CLAY:15,5,CONCRETE:7,100)
RandomBlock(-6,21,1,CONCRETE:7,70,STAINED_CLAY:12,15,STAINED_CLAY:15,5,CONCRETE:7,100)
RandomBlock(-6,21,2,CONCRETE:7,70,STAINED_CLAY:12,15,STAINED_CLAY:15,5,CONCRETE:7,100)
RandomBlock(-6,21,3,CONCRETE:7,70,STAINED_CLAY:12,15,STAINED_CLAY:15,5,CONCRETE:7,100)
RandomBlock(-6,21,4,CONCRETE:7,70,STAINED_CLAY:12,15,STAINED_CLAY:15,5,CONCRETE:7,100)
RandomBlock(-6,21,5,CONCRETE:7,70,STAINED_CLAY:12,15,STAINED_CLAY:15,5,CONCRETE:7,100)
RandomBlock(-6,21,6,CONCRETE:7,70,STAINED_CLAY:12,15,STAINED_CLAY:15,5,CONCRETE:7,100)
RandomBlock(-6,21,7,CONCRETE:7,70,STAINED_CLAY:12,15,STAINED_CLAY:15,5,CONCRETE:7,100)
RandomBlock(-6,21,8,CONCRETE:7,70,STAINED_CLAY:12,15,STAINED_CLAY:15,5,CONCRETE:7,100)
Block(-6,22,-7,STEP:8)
Block(-6,22,-6,STEP:8)
Block(-6,22,-5,STEP:8)
Block(-6,22,-4,STEP:8)
RandomBlock(-6,22,-3,CONCRETE:7,70,STAINED_CLAY:12,15,STAINED_CLAY:15,5,CONCRETE:7,100)
Block(-6,22,-2,STEP:8)
Block(-6,22,-1,STEP:8)
Block(-6,22,0,STEP:8)
Block(-6,22,1,STEP:8)
Block(-6,22,2,STEP:8)
Block(-6,22,3,STEP:8)
RandomBlock(-6,22,4,CONCRETE:7,70,STAINED_CLAY:12,15,STAINED_CLAY:15,5,CONCRETE:7,100)
Block(-6,22,5,STEP:8)
Block(-6,22,6,STEP:8)
Block(-6,22,7,STEP:8)
Block(-6,22,8,STEP:8)
Block(-5,11,-6,CONCRETE:15)
Block(-5,11,-4,CONCRETE:15)
RandomBlock(-5,11,-2,CONCRETE:7,70,STAINED_CLAY:12,15,STAINED_CLAY:15,5,CONCRETE:7,100)
RandomBlock(-5,11,-1,CONCRETE:7,70,STAINED_CLAY:12,15,STAINED_CLAY:15,5,CONCRETE:7,100)
RandomBlock(-5,11,0,CONCRETE:7,70,STAINED_CLAY:12,15,STAINED_CLAY:15,5,CONCRETE:7,100)
RandomBlock(-5,11,1,CONCRETE:7,70,STAINED_CLAY:12,15,STAINED_CLAY:15,5,CONCRETE:7,100)
RandomBlock(-5,11,2,CONCRETE:7,70,STAINED_CLAY:12,15,STAINED_CLAY:15,5,CONCRETE:7,100)
RandomBlock(-5,11,3,CONCRETE:7,70,STAINED_CLAY:12,15,STAINED_CLAY:15,5,CONCRETE:7,100)
Block(-5,11,5,CONCRETE:15)
Block(-5,11,7,CONCRETE:15)
Block(-5,12,-6,CONCRETE:15)
Block(-5,12,-4,CONCRETE:15)
RandomBlock(-5,12,-2,CONCRETE:7,70,STAINED_CLAY:12,15,STAINED_CLAY:15,5,CONCRETE:7,100)
Block(-5,12,1,AIR:0)
Block(-5,12,2,AIR:0)
RandomBlock(-5,12,3,CONCRETE:7,70,STAINED_CLAY:12,15,STAINED_CLAY:15,5,CONCRETE:7,100)
Block(-5,12,5,CONCRETE:15)
Block(-5,12,7,CONCRETE:15)
Block(-5,13,-6,CONCRETE:15)
Block(-5,13,-4,CONCRETE:15)
RandomBlock(-5,13,-2,CONCRETE:7,70,STAINED_CLAY:12,15,STAINED_CLAY:15,5,CONCRETE:7,100)
Block(-5,13,-1,AIR:0)
Block(-5,13,0,AIR:0)
Block(-5,13,1,AIR:0)
Block(-5,13,2,AIR:0)
RandomBlock(-5,13,3,CONCRETE:7,70,STAINED_CLAY:12,15,STAINED_CLAY:15,5,CONCRETE:7,100)
Block(-5,13,5,CONCRETE:15)
Block(-5,13,7,CONCRETE:15)
Block(-5,14,-6,CONCRETE:15)
Block(-5,14,-4,CONCRETE:15)
RandomBlock(-5,14,-2,CONCRETE:7,70,STAINED_CLAY:12,15,STAINED_CLAY:15,5,CONCRETE:7,100)
Block(-5,14,-1,AIR:0)
Block(-5,14,0,AIR:0)
Block(-5,14,1,AIR:0)
Block(-5,14,2,AIR:0)
RandomBlock(-5,14,3,CONCRETE:7,70,STAINED_CLAY:12,15,STAINED_CLAY:15,5,CONCRETE:7,100)
Block(-5,14,5,CONCRETE:15)
Block(-5,14,7,CONCRETE:15)
RandomBlock(-5,15,-7,CONCRETE:7,70,STAINED_CLAY:12,15,STAINED_CLAY:15,5,CONCRETE:7,100)
RandomBlock(-5,15,-6,CONCRETE:7,70,STAINED_CLAY:12,15,STAINED_CLAY:15,5,CONCRETE:7,100)
RandomBlock(-5,15,-5,CONCRETE:7,70,STAINED_CLAY:12,15,STAINED_CLAY:15,5,CONCRETE:7,100)
RandomBlock(-5,15,-4,CONCRETE:7,70,STAINED_CLAY:12,15,STAINED_CLAY:15,5,CONCRETE:7,100)
RandomBlock(-5,15,-3,CONCRETE:7,70,STAINED_CLAY:12,15,STAINED_CLAY:15,5,CONCRETE:7,100)
RandomBlock(-5,15,-2,CONCRETE:7,70,STAINED_CLAY:12,15,STAINED_CLAY:15,5,CONCRETE:7,100)
Block(-5,15,-1,AIR:0)
Block(-5,15,0,AIR:0)
Block(-5,15,1,AIR:0)
Block(-5,15,2,AIR:0)
RandomBlock(-5,15,3,CONCRETE:7,70,STAINED_CLAY:12,15,STAINED_CLAY:15,5,CONCRETE:7,100)
RandomBlock(-5,15,4,CONCRETE:7,70,STAINED_CLAY:12,15,STAINED_CLAY:15,5,CONCRETE:7,100)
RandomBlock(-5,15,5,CONCRETE:7,70,STAINED_CLAY:12,15,STAINED_CLAY:15,5,CONCRETE:7,100)
RandomBlock(-5,15,6,CONCRETE:7,70,STAINED_CLAY:12,15,STAINED_CLAY:15,5,CONCRETE:7,100)
RandomBlock(-5,15,7,CONCRETE:7,70,STAINED_CLAY:12,15,STAINED_CLAY:15,5,CONCRETE:7,100)
RandomBlock(-5,15,8,CONCRETE:7,70,STAINED_CLAY:12,15,STAINED_CLAY:15,5,CONCRETE:7,100)
RandomBlock(-5,16,-6,CONCRETE:7,70,STAINED_CLAY:12,15,STAINED_CLAY:15,5,CONCRETE:7,100)
RandomBlock(-5,16,-4,CONCRETE:7,70,STAINED_CLAY:12,15,STAINED_CLAY:15,5,CONCRETE:7,100)
RandomBlock(-5,16,-2,CONCRETE:7,70,STAINED_CLAY:12,15,STAINED_CLAY:15,5,CONCRETE:7,100)
Block(-5,16,-1,AIR:0)
Block(-5,16,0,AIR:0)
Block(-5,16,1,AIR:0)
Block(-5,16,2,AIR:0)
RandomBlock(-5,16,3,CONCRETE:7,70,STAINED_CLAY:12,15,STAINED_CLAY:15,5,CONCRETE:7,100)
RandomBlock(-5,16,5,CONCRETE:7,70,STAINED_CLAY:12,15,STAINED_CLAY:15,5,CONCRETE:7,100)
RandomBlock(-5,16,7,CONCRETE:7,70,STAINED_CLAY:12,15,STAINED_CLAY:15,5,CONCRETE:7,100)
RandomBlock(-5,17,-6,CONCRETE:7,70,STAINED_CLAY:12,15,STAINED_CLAY:15,5,CONCRETE:7,100)
RandomBlock(-5,17,-4,CONCRETE:7,70,STAINED_CLAY:12,15,STAINED_CLAY:15,5,CONCRETE:7,100)
RandomBlock(-5,17,-2,CONCRETE:7,70,STAINED_CLAY:12,15,STAINED_CLAY:15,5,CONCRETE:7,100)
Block(-5,17,-1,AIR:0)
Block(-5,17,0,AIR:0)
Block(-5,17,1,AIR:0)
Block(-5,17,2,AIR:0)
RandomBlock(-5,17,3,CONCRETE:7,70,STAINED_CLAY:12,15,STAINED_CLAY:15,5,CONCRETE:7,100)
RandomBlock(-5,17,5,CONCRETE:7,70,STAINED_CLAY:12,15,STAINED_CLAY:15,5,CONCRETE:7,100)
RandomBlock(-5,17,7,CONCRETE:7,70,STAINED_CLAY:12,15,STAINED_CLAY:15,5,CONCRETE:7,100)
Block(-5,18,-7,STONE_BUTTON:1)
RandomBlock(-5,18,-6,CONCRETE:7,70,STAINED_CLAY:12,15,STAINED_CLAY:15,5,CONCRETE:7,100)
Block(-5,18,-5,STONE_BUTTON:1)
RandomBlock(-5,18,-4,CONCRETE:7,70,STAINED_CLAY:12,15,STAINED_CLAY:15,5,CONCRETE:7,100)
Block(-5,18,-3,STONE_BUTTON:1)
RandomBlock(-5,18,-2,CONCRETE:7,70,STAINED_CLAY:12,15,STAINED_CLAY:15,5,CONCRETE:7,100)
Block(-5,18,-1,AIR:0)
Block(-5,18,0,AIR:0)
Block(-5,18,1,AIR:0)
Block(-5,18,2,AIR:0)
RandomBlock(-5,18,3,CONCRETE:7,70,STAINED_CLAY:12,15,STAINED_CLAY:15,5,CONCRETE:7,100)
Block(-5,18,4,STONE_BUTTON:1)
RandomBlock(-5,18,5,CONCRETE:7,70,STAINED_CLAY:12,15,STAINED_CLAY:15,5,CONCRETE:7,100)
Block(-5,18,6,STONE_BUTTON:1)
RandomBlock(-5,18,7,CONCRETE:7,70,STAINED_CLAY:12,15,STAINED_CLAY:15,5,CONCRETE:7,100)
Block(-5,18,8,STONE_BUTTON:1)
RandomBlock(-5,19,-6,CONCRETE:7,70,STAINED_CLAY:12,15,STAINED_CLAY:15,5,CONCRETE:7,100)
Block(-5,19,-5,AIR:0)
RandomBlock(-5,19,-4,CONCRETE:7,70,STAINED_CLAY:12,15,STAINED_CLAY:15,5,CONCRETE:7,100)
Block(-5,19,-3,AIR:0)
RandomBlock(-5,19,-2,CONCRETE:7,70,STAINED_CLAY:12,15,STAINED_CLAY:15,5,CONCRETE:7,100)
Block(-5,19,-1,AIR:0)
Block(-5,19,0,AIR:0)
Block(-5,19,1,AIR:0)
Block(-5,19,2,AIR:0)
RandomBlock(-5,19,3,CONCRETE:7,70,STAINED_CLAY:12,15,STAINED_CLAY:15,5,CONCRETE:7,100)
Block(-5,19,4,AIR:0)
RandomBlock(-5,19,5,CONCRETE:7,70,STAINED_CLAY:12,15,STAINED_CLAY:15,5,CONCRETE:7,100)
Block(-5,19,6,AIR:0)
RandomBlock(-5,19,7,CONCRETE:7,70,STAINED_CLAY:12,15,STAINED_CLAY:15,5,CONCRETE:7,100)
Block(-5,20,-7,AIR:0)
RandomBlock(-5,20,-6,CONCRETE:7,70,STAINED_CLAY:12,15,STAINED_CLAY:15,5,CONCRETE:7,100)
Block(-5,20,-5,AIR:0)
RandomBlock(-5,20,-4,CONCRETE:7,70,STAINED_CLAY:12,15,STAINED_CLAY:15,5,CONCRETE:7,100)
Block(-5,20,-3,AIR:0)
RandomBlock(-5,20,-2,CONCRETE:7,70,STAINED_CLAY:12,15,STAINED_CLAY:15,5,CONCRETE:7,100)
Block(-5,20,-1,AIR:0)
Block(-5,20,0,AIR:0)
Block(-5,20,1,AIR:0)
Block(-5,20,2,AIR:0)
RandomBlock(-5,20,3,CONCRETE:7,70,STAINED_CLAY:12,15,STAINED_CLAY:15,5,CONCRETE:7,100)
Block(-5,20,4,AIR:0)
RandomBlock(-5,20,5,CONCRETE:7,70,STAINED_CLAY:12,15,STAINED_CLAY:15,5,CONCRETE:7,100)
Block(-5,20,6,AIR:0)
RandomBlock(-5,20,7,CONCRETE:7,70,STAINED_CLAY:12,15,STAINED_CLAY:15,5,CONCRETE:7,100)
Block(-5,21,-7,AIR:0)
RandomBlock(-5,21,-6,CONCRETE:7,70,STAINED_CLAY:12,15,STAINED_CLAY:15,5,CONCRETE:7,100)
Block(-5,21,-5,AIR:0)
RandomBlock(-5,21,-4,CONCRETE:7,70,STAINED_CLAY:12,15,STAINED_CLAY:15,5,CONCRETE:7,100)
Block(-5,21,-3,AIR:0)
RandomBlock(-5,21,-2,CONCRETE:7,70,STAINED_CLAY:12,15,STAINED_CLAY:15,5,CONCRETE:7,100)
Block(-5,21,-1,AIR:0)
Block(-5,21,0,AIR:0)
Block(-5,21,1,AIR:0)
Block(-5,21,2,AIR:0)
RandomBlock(-5,21,3,CONCRETE:7,70,STAINED_CLAY:12,15,STAINED_CLAY:15,5,CONCRETE:7,100)
Block(-5,21,4,AIR:0)
RandomBlock(-5,21,5,CONCRETE:7,70,STAINED_CLAY:12,15,STAINED_CLAY:15,5,CONCRETE:7,100)
Block(-5,21,6,AIR:0)
RandomBlock(-5,21,7,CONCRETE:7,70,STAINED_CLAY:12,15,STAINED_CLAY:15,5,CONCRETE:7,100)
Block(-5,21,8,AIR:0)
RandomBlock(-5,22,-7,CONCRETE:7,70,STAINED_CLAY:12,15,STAINED_CLAY:15,5,CONCRETE:7,100)
RandomBlock(-5,22,-6,CONCRETE:7,70,STAINED_CLAY:12,15,STAINED_CLAY:15,5,CONCRETE:7,100)
RandomBlock(-5,22,-5,CONCRETE:7,70,STAINED_CLAY:12,15,STAINED_CLAY:15,5,CONCRETE:7,100)
RandomBlock(-5,22,-4,CONCRETE:7,70,STAINED_CLAY:12,15,STAINED_CLAY:15,5,CONCRETE:7,100)
RandomBlock(-5,22,-3,CONCRETE:7,70,STAINED_CLAY:12,15,STAINED_CLAY:15,5,CONCRETE:7,100)
RandomBlock(-5,22,-2,CONCRETE:7,70,STAINED_CLAY:12,15,STAINED_CLAY:15,5,CONCRETE:7,100)
RandomBlock(-5,22,-1,CONCRETE:7,70,STAINED_CLAY:12,15,STAINED_CLAY:15,5,CONCRETE:7,100)
RandomBlock(-5,22,0,CONCRETE:7,70,STAINED_CLAY:12,15,STAINED_CLAY:15,5,CONCRETE:7,100)
RandomBlock(-5,22,1,CONCRETE:7,70,STAINED_CLAY:12,15,STAINED_CLAY:15,5,CONCRETE:7,100)
RandomBlock(-5,22,2,CONCRETE:7,70,STAINED_CLAY:12,15,STAINED_CLAY:15,5,CONCRETE:7,100)
RandomBlock(-5,22,3,CONCRETE:7,70,STAINED_CLAY:12,15,STAINED_CLAY:15,5,CONCRETE:7,100)
RandomBlock(-5,22,4,CONCRETE:7,70,STAINED_CLAY:12,15,STAINED_CLAY:15,5,CONCRETE:7,100)
RandomBlock(-5,22,5,CONCRETE:7,70,STAINED_CLAY:12,15,STAINED_CLAY:15,5,CONCRETE:7,100)
RandomBlock(-5,22,6,CONCRETE:7,70,STAINED_CLAY:12,15,STAINED_CLAY:15,5,CONCRETE:7,100)
RandomBlock(-5,22,7,CONCRETE:7,70,STAINED_CLAY:12,15,STAINED_CLAY:15,5,CONCRETE:7,100)
RandomBlock(-5,22,8,CONCRETE:7,70,STAINED_CLAY:12,15,STAINED_CLAY:15,5,CONCRETE:7,100)
RandomBlock(-4,11,-2,CONCRETE:7,70,STAINED_CLAY:12,15,STAINED_CLAY:15,5,CONCRETE:7,100)
RandomBlock(-4,11,-1,CONCRETE:7,70,STAINED_CLAY:12,15,STAINED_CLAY:15,5,CONCRETE:7,100)
RandomBlock(-4,11,0,CONCRETE:7,70,STAINED_CLAY:12,15,STAINED_CLAY:15,5,CONCRETE:7,100)
RandomBlock(-4,11,1,CONCRETE:7,70,STAINED_CLAY:12,15,STAINED_CLAY:15,5,CONCRETE:7,100)
RandomBlock(-4,11,2,CONCRETE:7,70,STAINED_CLAY:12,15,STAINED_CLAY:15,5,CONCRETE:7,100)
RandomBlock(-4,11,3,CONCRETE:7,70,STAINED_CLAY:12,15,STAINED_CLAY:15,5,CONCRETE:7,100)
RandomBlock(-4,12,-2,CONCRETE:7,70,STAINED_CLAY:12,15,STAINED_CLAY:15,5,CONCRETE:7,100)
Block(-4,12,1,AIR:0)
RandomBlock(-4,12,3,CONCRETE:7,70,STAINED_CLAY:12,15,STAINED_CLAY:15,5,CONCRETE:7,100)
RandomBlock(-4,13,-2,CONCRETE:7,70,STAINED_CLAY:12,15,STAINED_CLAY:15,5,CONCRETE:7,100)
Block(-4,13,0,AIR:0)
Block(-4,13,1,AIR:0)
Block(-4,13,2,AIR:0)
RandomBlock(-4,13,3,CONCRETE:7,70,STAINED_CLAY:12,15,STAINED_CLAY:15,5,CONCRETE:7,100)
RandomBlock(-4,14,-2,CONCRETE:7,70,STAINED_CLAY:12,15,STAINED_CLAY:15,5,CONCRETE:7,100)
Block(-4,14,-1,AIR:0)
Block(-4,14,0,AIR:0)
Block(-4,14,1,AIR:0)
Block(-4,14,2,AIR:0)
RandomBlock(-4,14,3,CONCRETE:7,70,STAINED_CLAY:12,15,STAINED_CLAY:15,5,CONCRETE:7,100)
RandomBlock(-4,15,-2,CONCRETE:7,70,STAINED_CLAY:12,15,STAINED_CLAY:15,5,CONCRETE:7,100)
Block(-4,15,-1,AIR:0)
Block(-4,15,0,AIR:0)
Block(-4,15,1,AIR:0)
Block(-4,15,2,AIR:0)
RandomBlock(-4,15,3,CONCRETE:7,70,STAINED_CLAY:12,15,STAINED_CLAY:15,5,CONCRETE:7,100)
RandomBlock(-4,16,-2,CONCRETE:7,70,STAINED_CLAY:12,15,STAINED_CLAY:15,5,CONCRETE:7,100)
Block(-4,16,-1,AIR:0)
Block(-4,16,0,AIR:0)
Block(-4,16,1,AIR:0)
Block(-4,16,2,AIR:0)
RandomBlock(-4,16,3,CONCRETE:7,70,STAINED_CLAY:12,15,STAINED_CLAY:15,5,CONCRETE:7,100)
Block(-4,17,-4,AIR:0)
Block(-4,17,-3,AIR:0)
Block(-4,17,-2,AIR:0)
Block(-4,17,-1,AIR:0)
Block(-4,17,0,AIR:0)
Block(-4,17,1,AIR:0)
Block(-4,17,2,AIR:0)
Block(-4,17,3,AIR:0)
Block(-4,18,-5,AIR:0)
Block(-4,18,-4,AIR:0)
Block(-4,18,-3,AIR:0)
Block(-4,18,-2,AIR:0)
Block(-4,18,-1,AIR:0)
Block(-4,18,0,AIR:0)
Block(-4,18,1,AIR:0)
Block(-4,18,2,AIR:0)
Block(-4,18,3,AIR:0)
Block(-4,18,4,AIR:0)
Block(-4,18,5,AIR:0)
Block(-4,18,6,AIR:0)
Block(-4,19,-6,AIR:0)
Block(-4,19,-5,AIR:0)
Block(-4,19,-4,AIR:0)
Block(-4,19,-3,AIR:0)
Block(-4,19,-2,AIR:0)
Block(-4,19,-1,AIR:0)
Block(-4,19,0,AIR:0)
Block(-4,19,1,AIR:0)
Block(-4,19,2,AIR:0)
Block(-4,19,3,AIR:0)
Block(-4,19,4,AIR:0)
Block(-4,19,5,AIR:0)
Block(-4,19,6,AIR:0)
Block(-4,20,-7,AIR:0)
Block(-4,20,-6,AIR:0)
Block(-4,20,-5,AIR:0)
Block(-4,20,-4,AIR:0)
Block(-4,20,-3,AIR:0)
Block(-4,20,-2,AIR:0)
Block(-4,20,-1,AIR:0)
Block(-4,20,0,AIR:0)
Block(-4,20,1,AIR:0)
Block(-4,20,2,AIR:0)
Block(-4,20,3,AIR:0)
Block(-4,20,4,AIR:0)
Block(-4,20,5,AIR:0)
Block(-4,20,6,AIR:0)
Block(-4,20,7,AIR:0)
Block(-4,21,-7,AIR:0)
Block(-4,21,-6,AIR:0)
Block(-4,21,-5,AIR:0)
Block(-4,21,-4,AIR:0)
Block(-4,21,-3,AIR:0)
Block(-4,21,-2,AIR:0)
Block(-4,21,-1,AIR:0)
Block(-4,21,0,AIR:0)
Block(-4,21,1,AIR:0)
Block(-4,21,2,AIR:0)
Block(-4,21,3,AIR:0)
Block(-4,21,4,AIR:0)
Block(-4,21,5,AIR:0)
Block(-4,21,6,AIR:0)
Block(-4,21,7,AIR:0)
Block(-4,21,8,AIR:0)
Block(-4,22,-7,AIR:0)
Block(-4,22,-6,AIR:0)
Block(-4,22,-5,AIR:0)
Block(-4,22,-4,AIR:0)
Block(-4,22,-3,AIR:0)
Block(-4,22,-2,AIR:0)
Block(-4,22,-1,AIR:0)
Block(-4,22,0,AIR:0)
Block(-4,22,1,AIR:0)
Block(-4,22,2,AIR:0)
Block(-4,22,3,AIR:0)
Block(-4,22,4,AIR:0)
Block(-4,22,5,AIR:0)
Block(-4,22,6,AIR:0)
Block(-4,22,7,AIR:0)
Block(-4,22,8,AIR:0)
RandomBlock(-3,11,-2,CONCRETE:7,70,STAINED_CLAY:12,15,STAINED_CLAY:15,5,CONCRETE:7,100)
RandomBlock(-3,11,-1,CONCRETE:7,70,STAINED_CLAY:12,15,STAINED_CLAY:15,5,CONCRETE:7,100)
RandomBlock(-3,11,0,CONCRETE:7,70,STAINED_CLAY:12,15,STAINED_CLAY:15,5,CONCRETE:7,100)
RandomBlock(-3,11,1,CONCRETE:7,70,STAINED_CLAY:12,15,STAINED_CLAY:15,5,CONCRETE:7,100)
RandomBlock(-3,11,2,CONCRETE:7,70,STAINED_CLAY:12,15,STAINED_CLAY:15,5,CONCRETE:7,100)
RandomBlock(-3,11,3,CONCRETE:7,70,STAINED_CLAY:12,15,STAINED_CLAY:15,5,CONCRETE:7,100)
RandomBlock(-3,12,-2,CONCRETE:7,70,STAINED_CLAY:12,15,STAINED_CLAY:15,5,CONCRETE:7,100)
RandomBlock(-3,12,3,CONCRETE:7,70,STAINED_CLAY:12,15,STAINED_CLAY:15,5,CONCRETE:7,100)
RandomBlock(-3,13,-2,CONCRETE:7,70,STAINED_CLAY:12,15,STAINED_CLAY:15,5,CONCRETE:7,100)
Block(-3,13,1,AIR:0)
RandomBlock(-3,13,3,CONCRETE:7,70,STAINED_CLAY:12,15,STAINED_CLAY:15,5,CONCRETE:7,100)
RandomBlock(-3,14,-2,CONCRETE:7,70,STAINED_CLAY:12,15,STAINED_CLAY:15,5,CONCRETE:7,100)
Block(-3,14,-1,AIR:0)
Block(-3,14,0,AIR:0)
Block(-3,14,1,AIR:0)
Block(-3,14,2,AIR:0)
RandomBlock(-3,14,3,CONCRETE:7,70,STAINED_CLAY:12,15,STAINED_CLAY:15,5,CONCRETE:7,100)
RandomBlock(-3,15,-2,CONCRETE:7,70,STAINED_CLAY:12,15,STAINED_CLAY:15,5,CONCRETE:7,100)
Block(-3,15,-1,AIR:0)
Block(-3,15,0,AIR:0)
Block(-3,15,1,AIR:0)
Block(-3,15,2,AIR:0)
RandomBlock(-3,15,3,CONCRETE:7,70,STAINED_CLAY:12,15,STAINED_CLAY:15,5,CONCRETE:7,100)
RandomBlock(-3,16,-2,CONCRETE:7,70,STAINED_CLAY:12,15,STAINED_CLAY:15,5,CONCRETE:7,100)
Block(-3,16,-1,AIR:0)
Block(-3,16,0,AIR:0)
Block(-3,16,1,AIR:0)
Block(-3,16,2,AIR:0)
RandomBlock(-3,16,3,CONCRETE:7,70,STAINED_CLAY:12,15,STAINED_CLAY:15,5,CONCRETE:7,100)
Block(-3,17,-3,AIR:0)
Block(-3,17,-2,AIR:0)
Block(-3,17,-1,AIR:0)
Block(-3,17,0,AIR:0)
Block(-3,17,1,AIR:0)
Block(-3,17,2,AIR:0)
Block(-3,17,3,AIR:0)
Block(-3,17,4,AIR:0)
Block(-3,18,-5,AIR:0)
Block(-3,18,-4,AIR:0)
Block(-3,18,-3,AIR:0)
Block(-3,18,-2,AIR:0)
Block(-3,18,-1,AIR:0)
Block(-3,18,0,AIR:0)
Block(-3,18,1,AIR:0)
Block(-3,18,2,AIR:0)
Block(-3,18,3,AIR:0)
Block(-3,18,4,AIR:0)
Block(-3,18,5,AIR:0)
Block(-3,19,-6,AIR:0)
Block(-3,19,-5,AIR:0)
Block(-3,19,-4,AIR:0)
Block(-3,19,-3,AIR:0)
Block(-3,19,-2,AIR:0)
Block(-3,19,-1,AIR:0)
Block(-3,19,0,AIR:0)
Block(-3,19,1,AIR:0)
Block(-3,19,2,AIR:0)
Block(-3,19,3,AIR:0)
Block(-3,19,4,AIR:0)
Block(-3,19,5,AIR:0)
Block(-3,19,6,AIR:0)
Block(-3,20,-7,AIR:0)
Block(-3,20,-6,AIR:0)
Block(-3,20,-5,AIR:0)
Block(-3,20,-4,AIR:0)
Block(-3,20,-3,AIR:0)
Block(-3,20,-2,AIR:0)
Block(-3,20,-1,AIR:0)
Block(-3,20,0,AIR:0)
Block(-3,20,1,AIR:0)
Block(-3,20,2,AIR:0)
Block(-3,20,3,AIR:0)
Block(-3,20,4,AIR:0)
Block(-3,20,5,AIR:0)
Block(-3,20,6,AIR:0)
Block(-3,20,7,AIR:0)
Block(-3,21,-7,AIR:0)
Block(-3,21,-6,AIR:0)
Block(-3,21,-5,AIR:0)
Block(-3,21,-4,AIR:0)
Block(-3,21,-3,AIR:0)
Block(-3,21,-2,AIR:0)
Block(-3,21,-1,AIR:0)
Block(-3,21,0,AIR:0)
Block(-3,21,1,AIR:0)
Block(-3,21,2,AIR:0)
Block(-3,21,3,AIR:0)
Block(-3,21,4,AIR:0)
Block(-3,21,5,AIR:0)
Block(-3,21,6,AIR:0)
Block(-3,21,7,AIR:0)
Block(-3,21,8,AIR:0)
Block(-3,22,-7,AIR:0)
Block(-3,22,-6,AIR:0)
Block(-3,22,-5,AIR:0)
Block(-3,22,-4,AIR:0)
Block(-3,22,-3,AIR:0)
Block(-3,22,-2,AIR:0)
Block(-3,22,-1,AIR:0)
Block(-3,22,0,AIR:0)
Block(-3,22,1,AIR:0)
Block(-3,22,2,AIR:0)
Block(-3,22,3,AIR:0)
Block(-3,22,4,AIR:0)
Block(-3,22,5,AIR:0)
Block(-3,22,6,AIR:0)
Block(-3,22,7,AIR:0)
Block(-3,22,8,AIR:0)
RandomBlock(-2,11,-2,CONCRETE:7,70,STAINED_CLAY:12,15,STAINED_CLAY:15,5,CONCRETE:7,100)
RandomBlock(-2,11,-1,CONCRETE:7,70,STAINED_CLAY:12,15,STAINED_CLAY:15,5,CONCRETE:7,100)
RandomBlock(-2,11,0,CONCRETE:7,70,STAINED_CLAY:12,15,STAINED_CLAY:15,5,CONCRETE:7,100)
RandomBlock(-2,11,1,CONCRETE:7,70,STAINED_CLAY:12,15,STAINED_CLAY:15,5,CONCRETE:7,100)
RandomBlock(-2,11,2,CONCRETE:7,70,STAINED_CLAY:12,15,STAINED_CLAY:15,5,CONCRETE:7,100)
RandomBlock(-2,11,3,CONCRETE:7,70,STAINED_CLAY:12,15,STAINED_CLAY:15,5,CONCRETE:7,100)
RandomBlock(-2,12,-2,CONCRETE:7,70,STAINED_CLAY:12,15,STAINED_CLAY:15,5,CONCRETE:7,100)
Block(-2,12,-1,STEP:0)
Block(-2,12,0,STEP:0)
Block(-2,12,1,STEP:0)
Block(-2,12,2,STEP:0)
RandomBlock(-2,12,3,CONCRETE:7,70,STAINED_CLAY:12,15,STAINED_CLAY:15,5,CONCRETE:7,100)
RandomBlock(-2,13,-2,CONCRETE:7,70,STAINED_CLAY:12,15,STAINED_CLAY:15,5,CONCRETE:7,100)
RandomBlock(-2,13,3,CONCRETE:7,70,STAINED_CLAY:12,15,STAINED_CLAY:15,5,CONCRETE:7,100)
RandomBlock(-2,14,-2,CONCRETE:7,70,STAINED_CLAY:12,15,STAINED_CLAY:15,5,CONCRETE:7,100)
Block(-2,14,0,AIR:0)
Block(-2,14,1,AIR:0)
Block(-2,14,2,AIR:0)
RandomBlock(-2,14,3,CONCRETE:7,70,STAINED_CLAY:12,15,STAINED_CLAY:15,5,CONCRETE:7,100)
RandomBlock(-2,15,-2,CONCRETE:7,70,STAINED_CLAY:12,15,STAINED_CLAY:15,5,CONCRETE:7,100)
Block(-2,15,-1,AIR:0)
Block(-2,15,0,AIR:0)
Block(-2,15,1,AIR:0)
Block(-2,15,2,AIR:0)
RandomBlock(-2,15,3,CONCRETE:7,70,STAINED_CLAY:12,15,STAINED_CLAY:15,5,CONCRETE:7,100)
RandomBlock(-2,16,-2,CONCRETE:7,70,STAINED_CLAY:12,15,STAINED_CLAY:15,5,CONCRETE:7,100)
Block(-2,16,-1,AIR:0)
Block(-2,16,0,AIR:0)
Block(-2,16,1,AIR:0)
Block(-2,16,2,AIR:0)
RandomBlock(-2,16,3,CONCRETE:7,70,STAINED_CLAY:12,15,STAINED_CLAY:15,5,CONCRETE:7,100)
Block(-2,17,-3,AIR:0)
Block(-2,17,-2,AIR:0)
Block(-2,17,-1,AIR:0)
Block(-2,17,0,AIR:0)
Block(-2,17,1,AIR:0)
Block(-2,17,2,AIR:0)
Block(-2,17,3,AIR:0)
Block(-2,17,4,AIR:0)
Block(-2,18,-4,AIR:0)
Block(-2,18,-3,AIR:0)
Block(-2,18,-2,AIR:0)
Block(-2,18,-1,AIR:0)
Block(-2,18,0,AIR:0)
Block(-2,18,1,AIR:0)
Block(-2,18,2,AIR:0)
Block(-2,18,3,AIR:0)
Block(-2,18,4,AIR:0)
Block(-2,18,5,AIR:0)
Block(-2,19,-6,AIR:0)
Block(-2,19,-5,AIR:0)
Block(-2,19,-4,AIR:0)
Block(-2,19,-3,AIR:0)
Block(-2,19,-2,AIR:0)
Block(-2,19,-1,AIR:0)
Block(-2,19,0,AIR:0)
Block(-2,19,1,AIR:0)
Block(-2,19,2,AIR:0)
Block(-2,19,3,AIR:0)
Block(-2,19,4,AIR:0)
Block(-2,19,5,AIR:0)
Block(-2,19,6,AIR:0)
Block(-2,20,-7,AIR:0)
Block(-2,20,-6,AIR:0)
Block(-2,20,-5,AIR:0)
Block(-2,20,-4,AIR:0)
Block(-2,20,-3,AIR:0)
Block(-2,20,-2,AIR:0)
Block(-2,20,-1,AIR:0)
Block(-2,20,0,AIR:0)
Block(-2,20,1,AIR:0)
Block(-2,20,2,AIR:0)
Block(-2,20,3,AIR:0)
Block(-2,20,4,AIR:0)
Block(-2,20,5,AIR:0)
Block(-2,20,6,AIR:0)
Block(-2,20,7,AIR:0)
Block(-2,21,-7,AIR:0)
Block(-2,21,-6,AIR:0)
Block(-2,21,-5,AIR:0)
Block(-2,21,-4,AIR:0)
Block(-2,21,-3,AIR:0)
Block(-2,21,-2,AIR:0)
Block(-2,21,-1,AIR:0)
Block(-2,21,0,AIR:0)
Block(-2,21,1,AIR:0)
Block(-2,21,2,AIR:0)
Block(-2,21,3,AIR:0)
Block(-2,21,4,AIR:0)
Block(-2,21,5,AIR:0)
Block(-2,21,6,AIR:0)
Block(-2,21,7,AIR:0)
Block(-2,22,-7,AIR:0)
Block(-2,22,-6,AIR:0)
Block(-2,22,-5,AIR:0)
Block(-2,22,-4,AIR:0)
Block(-2,22,-3,AIR:0)
Block(-2,22,-2,AIR:0)
Block(-2,22,-1,AIR:0)
Block(-2,22,0,AIR:0)
Block(-2,22,1,AIR:0)
Block(-2,22,2,AIR:0)
Block(-2,22,3,AIR:0)
Block(-2,22,4,AIR:0)
Block(-2,22,5,AIR:0)
Block(-2,22,6,AIR:0)
Block(-2,22,7,AIR:0)
Block(-2,22,8,AIR:0)
RandomBlock(-1,11,-2,CONCRETE:7,70,STAINED_CLAY:12,15,STAINED_CLAY:15,5,CONCRETE:7,100)
RandomBlock(-1,11,-1,CONCRETE:7,70,STAINED_CLAY:12,15,STAINED_CLAY:15,5,CONCRETE:7,100)
RandomBlock(-1,11,0,CONCRETE:7,70,STAINED_CLAY:12,15,STAINED_CLAY:15,5,CONCRETE:7,100)
RandomBlock(-1,11,1,CONCRETE:7,70,STAINED_CLAY:12,15,STAINED_CLAY:15,5,CONCRETE:7,100)
RandomBlock(-1,11,2,CONCRETE:7,70,STAINED_CLAY:12,15,STAINED_CLAY:15,5,CONCRETE:7,100)
RandomBlock(-1,11,3,CONCRETE:7,70,STAINED_CLAY:12,15,STAINED_CLAY:15,5,CONCRETE:7,100)
RandomBlock(-1,12,-2,CONCRETE:7,70,STAINED_CLAY:12,15,STAINED_CLAY:15,5,CONCRETE:7,100)
Block(-1,12,-1,STEP:0)
Block(-1,12,0,STEP:0)
Block(-1,12,1,STEP:0)
Block(-1,12,2,STEP:0)
RandomBlock(-1,12,3,CONCRETE:7,70,STAINED_CLAY:12,15,STAINED_CLAY:15,5,CONCRETE:7,100)
RandomBlock(-1,13,-2,CONCRETE:7,70,STAINED_CLAY:12,15,STAINED_CLAY:15,5,CONCRETE:7,100)
RandomBlock(-1,13,3,CONCRETE:7,70,STAINED_CLAY:12,15,STAINED_CLAY:15,5,CONCRETE:7,100)
RandomBlock(-1,14,-2,CONCRETE:7,70,STAINED_CLAY:12,15,STAINED_CLAY:15,5,CONCRETE:7,100)
Block(-1,14,1,AIR:0)
RandomBlock(-1,14,3,CONCRETE:7,70,STAINED_CLAY:12,15,STAINED_CLAY:15,5,CONCRETE:7,100)
RandomBlock(-1,15,-2,CONCRETE:7,70,STAINED_CLAY:12,15,STAINED_CLAY:15,5,CONCRETE:7,100)
Block(-1,15,-1,AIR:0)
Block(-1,15,0,AIR:0)
Block(-1,15,1,AIR:0)
Block(-1,15,2,AIR:0)
RandomBlock(-1,15,3,CONCRETE:7,70,STAINED_CLAY:12,15,STAINED_CLAY:15,5,CONCRETE:7,100)
RandomBlock(-1,16,-2,CONCRETE:7,70,STAINED_CLAY:12,15,STAINED_CLAY:15,5,CONCRETE:7,100)
Block(-1,16,-1,AIR:0)
Block(-1,16,0,AIR:0)
Block(-1,16,1,AIR:0)
Block(-1,16,2,AIR:0)
RandomBlock(-1,16,3,CONCRETE:7,70,STAINED_CLAY:12,15,STAINED_CLAY:15,5,CONCRETE:7,100)
Block(-1,17,-2,AIR:0)
Block(-1,17,-1,AIR:0)
Block(-1,17,0,AIR:0)
Block(-1,17,1,AIR:0)
Block(-1,17,2,AIR:0)
Block(-1,17,3,AIR:0)
Block(-1,17,4,AIR:0)
Block(-1,17,5,AIR:0)
Block(-1,18,-3,AIR:0)
Block(-1,18,-2,AIR:0)
Block(-1,18,-1,AIR:0)
Block(-1,18,0,AIR:0)
Block(-1,18,1,AIR:0)
Block(-1,18,2,AIR:0)
Block(-1,18,3,AIR:0)
Block(-1,18,4,AIR:0)
Block(-1,18,5,AIR:0)
Block(-1,19,-5,AIR:0)
Block(-1,19,-4,AIR:0)
Block(-1,19,-3,AIR:0)
Block(-1,19,-2,AIR:0)
Block(-1,19,-1,AIR:0)
Block(-1,19,0,AIR:0)
Block(-1,19,1,AIR:0)
Block(-1,19,2,AIR:0)
Block(-1,19,3,AIR:0)
Block(-1,19,4,AIR:0)
Block(-1,19,5,AIR:0)
Block(-1,20,-6,AIR:0)
Block(-1,20,-5,AIR:0)
Block(-1,20,-4,AIR:0)
Block(-1,20,-3,AIR:0)
Block(-1,20,-2,AIR:0)
Block(-1,20,-1,AIR:0)
Block(-1,20,0,AIR:0)
Block(-1,20,1,AIR:0)
Block(-1,20,2,AIR:0)
Block(-1,20,3,AIR:0)
Block(-1,20,4,AIR:0)
Block(-1,20,5,AIR:0)
Block(-1,20,6,AIR:0)
Block(-1,21,-7,AIR:0)
Block(-1,21,-6,AIR:0)
Block(-1,21,-5,AIR:0)
Block(-1,21,-4,AIR:0)
Block(-1,21,-3,AIR:0)
Block(-1,21,-2,AIR:0)
Block(-1,21,-1,AIR:0)
Block(-1,21,0,AIR:0)
Block(-1,21,1,AIR:0)
Block(-1,21,2,AIR:0)
Block(-1,21,3,AIR:0)
Block(-1,21,4,AIR:0)
Block(-1,21,5,AIR:0)
Block(-1,21,6,AIR:0)
Block(-1,21,7,AIR:0)
Block(-1,22,-7,AIR:0)
Block(-1,22,-6,AIR:0)
Block(-1,22,-5,AIR:0)
Block(-1,22,-4,AIR:0)
Block(-1,22,-3,AIR:0)
Block(-1,22,-2,AIR:0)
Block(-1,22,-1,AIR:0)
Block(-1,22,0,AIR:0)
Block(-1,22,1,AIR:0)
Block(-1,22,2,AIR:0)
Block(-1,22,3,AIR:0)
Block(-1,22,4,AIR:0)
Block(-1,22,5,AIR:0)
Block(-1,22,6,AIR:0)
Block(-1,22,7,AIR:0)
Block(-1,22,8,AIR:0)
RandomBlock(0,11,-2,CONCRETE:7,70,STAINED_CLAY:12,15,STAINED_CLAY:15,5,CONCRETE:7,100)
RandomBlock(0,11,-1,CONCRETE:7,70,STAINED_CLAY:12,15,STAINED_CLAY:15,5,CONCRETE:7,100)
RandomBlock(0,11,0,CONCRETE:7,70,STAINED_CLAY:12,15,STAINED_CLAY:15,5,CONCRETE:7,100)
RandomBlock(0,11,1,CONCRETE:7,70,STAINED_CLAY:12,15,STAINED_CLAY:15,5,CONCRETE:7,100)
RandomBlock(0,11,2,CONCRETE:7,70,STAINED_CLAY:12,15,STAINED_CLAY:15,5,CONCRETE:7,100)
RandomBlock(0,11,3,CONCRETE:7,70,STAINED_CLAY:12,15,STAINED_CLAY:15,5,CONCRETE:7,100)
RandomBlock(0,12,-2,CONCRETE:7,70,STAINED_CLAY:12,15,STAINED_CLAY:15,5,CONCRETE:7,100)
RandomBlock(0,12,-1,CONCRETE:7,70,STAINED_CLAY:12,15,STAINED_CLAY:15,5,CONCRETE:7,100)
RandomBlock(0,12,0,CONCRETE:7,70,STAINED_CLAY:12,15,STAINED_CLAY:15,5,CONCRETE:7,100)
RandomBlock(0,12,1,CONCRETE:7,70,STAINED_CLAY:12,15,STAINED_CLAY:15,5,CONCRETE:7,100)
RandomBlock(0,12,2,CONCRETE:7,70,STAINED_CLAY:12,15,STAINED_CLAY:15,5,CONCRETE:7,100)
RandomBlock(0,12,3,CONCRETE:7,70,STAINED_CLAY:12,15,STAINED_CLAY:15,5,CONCRETE:7,100)
RandomBlock(0,13,-2,CONCRETE:7,70,STAINED_CLAY:12,15,STAINED_CLAY:15,5,CONCRETE:7,100)
RandomBlock(0,13,3,CONCRETE:7,70,STAINED_CLAY:12,15,STAINED_CLAY:15,5,CONCRETE:7,100)
RandomBlock(0,14,-2,CONCRETE:7,70,STAINED_CLAY:12,15,STAINED_CLAY:15,5,CONCRETE:7,100)
RandomBlock(0,14,3,CONCRETE:7,70,STAINED_CLAY:12,15,STAINED_CLAY:15,5,CONCRETE:7,100)
RandomBlock(0,15,-2,CONCRETE:7,70,STAINED_CLAY:12,15,STAINED_CLAY:15,5,CONCRETE:7,100)
Block(0,15,0,AIR:0)
Block(0,15,1,AIR:0)
Block(0,15,2,AIR:0)
RandomBlock(0,15,3,CONCRETE:7,70,STAINED_CLAY:12,15,STAINED_CLAY:15,5,CONCRETE:7,100)
RandomBlock(0,16,-2,CONCRETE:7,70,STAINED_CLAY:12,15,STAINED_CLAY:15,5,CONCRETE:7,100)
Block(0,16,-1,AIR:0)
Block(0,16,0,AIR:0)
Block(0,16,1,AIR:0)
Block(0,16,2,AIR:0)
RandomBlock(0,16,3,CONCRETE:7,70,STAINED_CLAY:12,15,STAINED_CLAY:15,5,CONCRETE:7,100)
Block(0,17,-1,AIR:0)
Block(0,17,0,AIR:0)
Block(0,17,1,AIR:0)
Block(0,17,2,AIR:0)
Block(0,17,3,AIR:0)
Block(0,17,4,AIR:0)
Block(0,18,-2,AIR:0)
Block(0,18,-1,AIR:0)
Block(0,18,0,AIR:0)
Block(0,18,1,AIR:0)
Block(0,18,2,AIR:0)
Block(0,18,3,AIR:0)
Block(0,18,4,AIR:0)
Block(0,18,5,AIR:0)
Block(0,19,-4,AIR:0)
Block(0,19,-3,AIR:0)
Block(0,19,-2,AIR:0)
Block(0,19,-1,AIR:0)
Block(0,19,0,AIR:0)
Block(0,19,1,AIR:0)
Block(0,19,2,AIR:0)
Block(0,19,3,AIR:0)
Block(0,19,4,AIR:0)
Block(0,19,5,AIR:0)
Block(0,20,-6,AIR:0)
Block(0,20,-5,AIR:0)
Block(0,20,-4,AIR:0)
Block(0,20,-3,AIR:0)
Block(0,20,-2,AIR:0)
Block(0,20,-1,AIR:0)
Block(0,20,0,AIR:0)
Block(0,20,1,AIR:0)
Block(0,20,2,AIR:0)
Block(0,20,3,AIR:0)
Block(0,20,4,AIR:0)
Block(0,20,5,AIR:0)
Block(0,20,6,AIR:0)
Block(0,21,-7,AIR:0)
Block(0,21,-6,AIR:0)
Block(0,21,-5,AIR:0)
Block(0,21,-4,AIR:0)
Block(0,21,-3,AIR:0)
Block(0,21,-2,AIR:0)
Block(0,21,-1,AIR:0)
Block(0,21,0,AIR:0)
Block(0,21,1,AIR:0)
Block(0,21,2,AIR:0)
Block(0,21,3,AIR:0)
Block(0,21,4,AIR:0)
Block(0,21,5,AIR:0)
Block(0,21,6,AIR:0)
Block(0,21,7,AIR:0)
Block(0,22,-7,AIR:0)
Block(0,22,-6,AIR:0)
Block(0,22,-5,AIR:0)
Block(0,22,-4,AIR:0)
Block(0,22,-3,AIR:0)
Block(0,22,-2,AIR:0)
Block(0,22,-1,AIR:0)
Block(0,22,0,AIR:0)
Block(0,22,1,AIR:0)
Block(0,22,2,AIR:0)
Block(0,22,3,AIR:0)
Block(0,22,4,AIR:0)
Block(0,22,5,AIR:0)
Block(0,22,6,AIR:0)
Block(0,22,7,AIR:0)
Block(0,22,8,AIR:0)
RandomBlock(1,11,-2,CONCRETE:7,70,STAINED_CLAY:12,15,STAINED_CLAY:15,5,CONCRETE:7,100)
RandomBlock(1,11,-1,CONCRETE:7,70,STAINED_CLAY:12,15,STAINED_CLAY:15,5,CONCRETE:7,100)
RandomBlock(1,11,0,CONCRETE:7,70,STAINED_CLAY:12,15,STAINED_CLAY:15,5,CONCRETE:7,100)
RandomBlock(1,11,1,CONCRETE:7,70,STAINED_CLAY:12,15,STAINED_CLAY:15,5,CONCRETE:7,100)
RandomBlock(1,11,2,CONCRETE:7,70,STAINED_CLAY:12,15,STAINED_CLAY:15,5,CONCRETE:7,100)
RandomBlock(1,11,3,CONCRETE:7,70,STAINED_CLAY:12,15,STAINED_CLAY:15,5,CONCRETE:7,100)
RandomBlock(1,12,-2,CONCRETE:7,70,STAINED_CLAY:12,15,STAINED_CLAY:15,5,CONCRETE:7,100)
RandomBlock(1,12,-1,CONCRETE:7,70,STAINED_CLAY:12,15,STAINED_CLAY:15,5,CONCRETE:7,100)
RandomBlock(1,12,0,CONCRETE:7,70,STAINED_CLAY:12,15,STAINED_CLAY:15,5,CONCRETE:7,100)
RandomBlock(1,12,1,CONCRETE:7,70,STAINED_CLAY:12,15,STAINED_CLAY:15,5,CONCRETE:7,100)
RandomBlock(1,12,2,CONCRETE:7,70,STAINED_CLAY:12,15,STAINED_CLAY:15,5,CONCRETE:7,100)
RandomBlock(1,12,3,CONCRETE:7,70,STAINED_CLAY:12,15,STAINED_CLAY:15,5,CONCRETE:7,100)
RandomBlock(1,13,-2,CONCRETE:7,70,STAINED_CLAY:12,15,STAINED_CLAY:15,5,CONCRETE:7,100)
RandomBlock(1,13,3,CONCRETE:7,70,STAINED_CLAY:12,15,STAINED_CLAY:15,5,CONCRETE:7,100)
RandomBlock(1,14,-2,CONCRETE:7,70,STAINED_CLAY:12,15,STAINED_CLAY:15,5,CONCRETE:7,100)
RandomBlock(1,14,3,CONCRETE:7,70,STAINED_CLAY:12,15,STAINED_CLAY:15,5,CONCRETE:7,100)
RandomBlock(1,15,-2,CONCRETE:7,70,STAINED_CLAY:12,15,STAINED_CLAY:15,5,CONCRETE:7,100)
RandomBlock(1,15,3,CONCRETE:7,70,STAINED_CLAY:12,15,STAINED_CLAY:15,5,CONCRETE:7,100)
RandomBlock(1,16,-2,CONCRETE:7,70,STAINED_CLAY:12,15,STAINED_CLAY:15,5,CONCRETE:7,100)
Block(1,16,0,AIR:0)
Block(1,16,1,AIR:0)
Block(1,16,2,AIR:0)
RandomBlock(1,16,3,CONCRETE:7,70,STAINED_CLAY:12,15,STAINED_CLAY:15,5,CONCRETE:7,100)
Block(1,17,-1,AIR:0)
Block(1,17,0,AIR:0)
Block(1,17,1,AIR:0)
Block(1,17,2,AIR:0)
Block(1,17,3,AIR:0)
Block(1,18,-2,AIR:0)
Block(1,18,-1,AIR:0)
Block(1,18,0,AIR:0)
Block(1,18,1,AIR:0)
Block(1,18,2,AIR:0)
Block(1,18,3,AIR:0)
Block(1,18,4,AIR:0)
Block(1,19,-3,AIR:0)
Block(1,19,-2,AIR:0)
Block(1,19,-1,AIR:0)
Block(1,19,0,AIR:0)
Block(1,19,1,AIR:0)
Block(1,19,2,AIR:0)
Block(1,19,3,AIR:0)
Block(1,19,4,AIR:0)
Block(1,19,5,AIR:0)
Block(1,20,-5,AIR:0)
Block(1,20,-4,AIR:0)
Block(1,20,-3,AIR:0)
Block(1,20,-2,AIR:0)
Block(1,20,-1,AIR:0)
Block(1,20,0,AIR:0)
Block(1,20,1,AIR:0)
Block(1,20,2,AIR:0)
Block(1,20,3,AIR:0)
Block(1,20,4,AIR:0)
Block(1,20,5,AIR:0)
Block(1,20,6,AIR:0)
Block(1,21,-7,AIR:0)
Block(1,21,-6,AIR:0)
Block(1,21,-5,AIR:0)
Block(1,21,-4,AIR:0)
Block(1,21,-3,AIR:0)
Block(1,21,-2,AIR:0)
Block(1,21,-1,AIR:0)
Block(1,21,0,AIR:0)
Block(1,21,1,AIR:0)
Block(1,21,2,AIR:0)
Block(1,21,3,AIR:0)
Block(1,21,4,AIR:0)
Block(1,21,5,AIR:0)
Block(1,21,6,AIR:0)
Block(1,21,7,AIR:0)
Block(1,22,-7,AIR:0)
Block(1,22,-6,AIR:0)
Block(1,22,-5,AIR:0)
Block(1,22,-4,AIR:0)
Block(1,22,-3,AIR:0)
Block(1,22,-2,AIR:0)
Block(1,22,-1,AIR:0)
Block(1,22,0,AIR:0)
Block(1,22,1,AIR:0)
Block(1,22,2,AIR:0)
Block(1,22,3,AIR:0)
Block(1,22,4,AIR:0)
Block(1,22,5,AIR:0)
Block(1,22,6,AIR:0)
Block(1,22,7,AIR:0)
Block(1,22,8,AIR:0)
RandomBlock(2,11,-2,CONCRETE:7,70,STAINED_CLAY:12,15,STAINED_CLAY:15,5,CONCRETE:7,100)
RandomBlock(2,11,-1,CONCRETE:7,70,STAINED_CLAY:12,15,STAINED_CLAY:15,5,CONCRETE:7,100)
RandomBlock(2,11,0,CONCRETE:7,70,STAINED_CLAY:12,15,STAINED_CLAY:15,5,CONCRETE:7,100)
RandomBlock(2,11,1,CONCRETE:7,70,STAINED_CLAY:12,15,STAINED_CLAY:15,5,CONCRETE:7,100)
RandomBlock(2,11,2,CONCRETE:7,70,STAINED_CLAY:12,15,STAINED_CLAY:15,5,CONCRETE:7,100)
RandomBlock(2,11,3,CONCRETE:7,70,STAINED_CLAY:12,15,STAINED_CLAY:15,5,CONCRETE:7,100)
RandomBlock(2,12,-2,CONCRETE:7,70,STAINED_CLAY:12,15,STAINED_CLAY:15,5,CONCRETE:7,100)
RandomBlock(2,12,-1,CONCRETE:7,70,STAINED_CLAY:12,15,STAINED_CLAY:15,5,CONCRETE:7,100)
RandomBlock(2,12,0,CONCRETE:7,70,STAINED_CLAY:12,15,STAINED_CLAY:15,5,CONCRETE:7,100)
RandomBlock(2,12,1,CONCRETE:7,70,STAINED_CLAY:12,15,STAINED_CLAY:15,5,CONCRETE:7,100)
RandomBlock(2,12,2,CONCRETE:7,70,STAINED_CLAY:12,15,STAINED_CLAY:15,5,CONCRETE:7,100)
RandomBlock(2,12,3,CONCRETE:7,70,STAINED_CLAY:12,15,STAINED_CLAY:15,5,CONCRETE:7,100)
RandomBlock(2,13,-2,CONCRETE:7,70,STAINED_CLAY:12,15,STAINED_CLAY:15,5,CONCRETE:7,100)
Block(2,13,-1,STEP:0)
Block(2,13,0,STEP:0)
Block(2,13,1,STEP:0)
Block(2,13,2,STEP:0)
RandomBlock(2,13,3,CONCRETE:7,70,STAINED_CLAY:12,15,STAINED_CLAY:15,5,CONCRETE:7,100)
RandomBlock(2,14,-2,CONCRETE:7,70,STAINED_CLAY:12,15,STAINED_CLAY:15,5,CONCRETE:7,100)
RandomBlock(2,14,3,CONCRETE:7,70,STAINED_CLAY:12,15,STAINED_CLAY:15,5,CONCRETE:7,100)
RandomBlock(2,15,-2,CONCRETE:7,70,STAINED_CLAY:12,15,STAINED_CLAY:15,5,CONCRETE:7,100)
RandomBlock(2,15,3,CONCRETE:7,70,STAINED_CLAY:12,15,STAINED_CLAY:15,5,CONCRETE:7,100)
RandomBlock(2,16,-2,CONCRETE:7,70,STAINED_CLAY:12,15,STAINED_CLAY:15,5,CONCRETE:7,100)
Block(2,16,1,AIR:0)
Block(2,16,2,AIR:0)
RandomBlock(2,16,3,CONCRETE:7,70,STAINED_CLAY:12,15,STAINED_CLAY:15,5,CONCRETE:7,100)
Block(2,17,-1,AIR:0)
Block(2,17,0,AIR:0)
Block(2,17,1,AIR:0)
Block(2,17,2,AIR:0)
Block(2,17,3,AIR:0)
Block(2,18,-2,AIR:0)
Block(2,18,-1,AIR:0)
Block(2,18,0,AIR:0)
Block(2,18,1,AIR:0)
Block(2,18,2,AIR:0)
Block(2,18,3,AIR:0)
Block(2,19,-3,AIR:0)
Block(2,19,-2,AIR:0)
Block(2,19,-1,AIR:0)
Block(2,19,0,AIR:0)
Block(2,19,1,AIR:0)
Block(2,19,2,AIR:0)
Block(2,19,3,AIR:0)
Block(2,19,4,AIR:0)
Block(2,20,-4,AIR:0)
Block(2,20,-3,AIR:0)
Block(2,20,-2,AIR:0)
Block(2,20,-1,AIR:0)
Block(2,20,0,AIR:0)
Block(2,20,1,AIR:0)
Block(2,20,2,AIR:0)
Block(2,20,3,AIR:0)
Block(2,20,4,AIR:0)
Block(2,20,5,AIR:0)
Block(2,21,-6,AIR:0)
Block(2,21,-5,AIR:0)
Block(2,21,-4,AIR:0)
Block(2,21,-3,AIR:0)
Block(2,21,-2,AIR:0)
Block(2,21,-1,AIR:0)
Block(2,21,0,AIR:0)
Block(2,21,1,AIR:0)
Block(2,21,2,AIR:0)
Block(2,21,3,AIR:0)
Block(2,21,4,AIR:0)
Block(2,21,5,AIR:0)
Block(2,21,6,AIR:0)
Block(2,21,7,AIR:0)
Block(2,22,-7,AIR:0)
Block(2,22,-6,AIR:0)
Block(2,22,-5,AIR:0)
Block(2,22,-4,AIR:0)
Block(2,22,-3,AIR:0)
Block(2,22,-2,AIR:0)
Block(2,22,-1,AIR:0)
Block(2,22,0,AIR:0)
Block(2,22,1,AIR:0)
Block(2,22,2,AIR:0)
Block(2,22,3,AIR:0)
Block(2,22,4,AIR:0)
Block(2,22,5,AIR:0)
Block(2,22,6,AIR:0)
Block(2,22,7,AIR:0)
Block(2,22,8,AIR:0)
RandomBlock(3,11,-2,CONCRETE:7,70,STAINED_CLAY:12,15,STAINED_CLAY:15,5,CONCRETE:7,100)
RandomBlock(3,11,-1,CONCRETE:7,70,STAINED_CLAY:12,15,STAINED_CLAY:15,5,CONCRETE:7,100)
RandomBlock(3,11,0,CONCRETE:7,70,STAINED_CLAY:12,15,STAINED_CLAY:15,5,CONCRETE:7,100)
RandomBlock(3,11,1,CONCRETE:7,70,STAINED_CLAY:12,15,STAINED_CLAY:15,5,CONCRETE:7,100)
RandomBlock(3,11,2,CONCRETE:7,70,STAINED_CLAY:12,15,STAINED_CLAY:15,5,CONCRETE:7,100)
RandomBlock(3,11,3,CONCRETE:7,70,STAINED_CLAY:12,15,STAINED_CLAY:15,5,CONCRETE:7,100)
RandomBlock(3,12,-2,CONCRETE:7,70,STAINED_CLAY:12,15,STAINED_CLAY:15,5,CONCRETE:7,100)
RandomBlock(3,12,-1,CONCRETE:7,70,STAINED_CLAY:12,15,STAINED_CLAY:15,5,CONCRETE:7,100)
RandomBlock(3,12,0,CONCRETE:7,70,STAINED_CLAY:12,15,STAINED_CLAY:15,5,CONCRETE:7,100)
RandomBlock(3,12,1,CONCRETE:7,70,STAINED_CLAY:12,15,STAINED_CLAY:15,5,CONCRETE:7,100)
RandomBlock(3,12,2,CONCRETE:7,70,STAINED_CLAY:12,15,STAINED_CLAY:15,5,CONCRETE:7,100)
RandomBlock(3,12,3,CONCRETE:7,70,STAINED_CLAY:12,15,STAINED_CLAY:15,5,CONCRETE:7,100)
RandomBlock(3,13,-2,CONCRETE:7,70,STAINED_CLAY:12,15,STAINED_CLAY:15,5,CONCRETE:7,100)
Block(3,13,-1,STEP:0)
Block(3,13,0,STEP:0)
Block(3,13,1,STEP:0)
Block(3,13,2,STEP:0)
RandomBlock(3,13,3,CONCRETE:7,70,STAINED_CLAY:12,15,STAINED_CLAY:15,5,CONCRETE:7,100)
RandomBlock(3,14,-2,CONCRETE:7,70,STAINED_CLAY:12,15,STAINED_CLAY:15,5,CONCRETE:7,100)
RandomBlock(3,14,3,CONCRETE:7,70,STAINED_CLAY:12,15,STAINED_CLAY:15,5,CONCRETE:7,100)
RandomBlock(3,15,-2,CONCRETE:7,70,STAINED_CLAY:12,15,STAINED_CLAY:15,5,CONCRETE:7,100)
RandomBlock(3,15,3,CONCRETE:7,70,STAINED_CLAY:12,15,STAINED_CLAY:15,5,CONCRETE:7,100)
RandomBlock(3,16,-2,CONCRETE:7,70,STAINED_CLAY:12,15,STAINED_CLAY:15,5,CONCRETE:7,100)
RandomBlock(3,16,3,CONCRETE:7,70,STAINED_CLAY:12,15,STAINED_CLAY:15,5,CONCRETE:7,100)
Block(3,17,0,AIR:0)
Block(3,17,1,AIR:0)
Block(3,17,2,AIR:0)
Block(3,18,-1,AIR:0)
Block(3,18,0,AIR:0)
Block(3,18,1,AIR:0)
Block(3,18,2,AIR:0)
Block(3,18,3,AIR:0)
Block(3,19,-3,AIR:0)
Block(3,19,-2,AIR:0)
Block(3,19,-1,AIR:0)
Block(3,19,0,AIR:0)
Block(3,19,1,AIR:0)
Block(3,19,2,AIR:0)
Block(3,19,3,AIR:0)
Block(3,19,4,AIR:0)
Block(3,20,-3,AIR:0)
Block(3,20,-2,AIR:0)
Block(3,20,-1,AIR:0)
Block(3,20,0,AIR:0)
Block(3,20,1,AIR:0)
Block(3,20,2,AIR:0)
Block(3,20,3,AIR:0)
Block(3,20,4,AIR:0)
Block(3,21,-6,AIR:0)
Block(3,21,-5,AIR:0)
Block(3,21,-4,AIR:0)
Block(3,21,-3,AIR:0)
Block(3,21,-2,AIR:0)
Block(3,21,-1,AIR:0)
Block(3,21,0,AIR:0)
Block(3,21,1,AIR:0)
Block(3,21,2,AIR:0)
Block(3,21,3,AIR:0)
Block(3,21,4,AIR:0)
Block(3,21,5,AIR:0)
Block(3,21,6,AIR:0)
Block(3,21,7,AIR:0)
Block(3,22,-7,AIR:0)
Block(3,22,-6,AIR:0)
Block(3,22,-5,AIR:0)
Block(3,22,-4,AIR:0)
Block(3,22,-3,AIR:0)
Block(3,22,-2,AIR:0)
Block(3,22,-1,AIR:0)
Block(3,22,0,AIR:0)
Block(3,22,1,AIR:0)
Block(3,22,2,AIR:0)
Block(3,22,3,AIR:0)
Block(3,22,4,AIR:0)
Block(3,22,5,AIR:0)
Block(3,22,6,AIR:0)
Block(3,22,7,AIR:0)
Block(3,22,8,AIR:0)
RandomBlock(4,11,-2,CONCRETE:7,70,STAINED_CLAY:12,15,STAINED_CLAY:15,5,CONCRETE:7,100)
RandomBlock(4,11,-1,CONCRETE:7,70,STAINED_CLAY:12,15,STAINED_CLAY:15,5,CONCRETE:7,100)
RandomBlock(4,11,0,CONCRETE:7,70,STAINED_CLAY:12,15,STAINED_CLAY:15,5,CONCRETE:7,100)
RandomBlock(4,11,1,CONCRETE:7,70,STAINED_CLAY:12,15,STAINED_CLAY:15,5,CONCRETE:7,100)
RandomBlock(4,11,2,CONCRETE:7,70,STAINED_CLAY:12,15,STAINED_CLAY:15,5,CONCRETE:7,100)
RandomBlock(4,11,3,CONCRETE:7,70,STAINED_CLAY:12,15,STAINED_CLAY:15,5,CONCRETE:7,100)
RandomBlock(4,12,-2,CONCRETE:7,70,STAINED_CLAY:12,15,STAINED_CLAY:15,5,CONCRETE:7,100)
RandomBlock(4,12,-1,CONCRETE:7,70,STAINED_CLAY:12,15,STAINED_CLAY:15,5,CONCRETE:7,100)
RandomBlock(4,12,0,CONCRETE:7,70,STAINED_CLAY:12,15,STAINED_CLAY:15,5,CONCRETE:7,100)
RandomBlock(4,12,1,CONCRETE:7,70,STAINED_CLAY:12,15,STAINED_CLAY:15,5,CONCRETE:7,100)
RandomBlock(4,12,2,CONCRETE:7,70,STAINED_CLAY:12,15,STAINED_CLAY:15,5,CONCRETE:7,100)
RandomBlock(4,12,3,CONCRETE:7,70,STAINED_CLAY:12,15,STAINED_CLAY:15,5,CONCRETE:7,100)
RandomBlock(4,13,-2,CONCRETE:7,70,STAINED_CLAY:12,15,STAINED_CLAY:15,5,CONCRETE:7,100)
RandomBlock(4,13,-1,CONCRETE:7,70,STAINED_CLAY:12,15,STAINED_CLAY:15,5,CONCRETE:7,100)
RandomBlock(4,13,0,CONCRETE:7,70,STAINED_CLAY:12,15,STAINED_CLAY:15,5,CONCRETE:7,100)
RandomBlock(4,13,1,CONCRETE:7,70,STAINED_CLAY:12,15,STAINED_CLAY:15,5,CONCRETE:7,100)
RandomBlock(4,13,2,CONCRETE:7,70,STAINED_CLAY:12,15,STAINED_CLAY:15,5,CONCRETE:7,100)
RandomBlock(4,13,3,CONCRETE:7,70,STAINED_CLAY:12,15,STAINED_CLAY:15,5,CONCRETE:7,100)
RandomBlock(4,14,-2,CONCRETE:7,70,STAINED_CLAY:12,15,STAINED_CLAY:15,5,CONCRETE:7,100)
RandomBlock(4,14,3,CONCRETE:7,70,STAINED_CLAY:12,15,STAINED_CLAY:15,5,CONCRETE:7,100)
RandomBlock(4,15,-2,CONCRETE:7,70,STAINED_CLAY:12,15,STAINED_CLAY:15,5,CONCRETE:7,100)
RandomBlock(4,15,3,CONCRETE:7,70,STAINED_CLAY:12,15,STAINED_CLAY:15,5,CONCRETE:7,100)
RandomBlock(4,16,-2,CONCRETE:7,70,STAINED_CLAY:12,15,STAINED_CLAY:15,5,CONCRETE:7,100)
RandomBlock(4,16,3,CONCRETE:7,70,STAINED_CLAY:12,15,STAINED_CLAY:15,5,CONCRETE:7,100)
Block(4,18,0,AIR:0)
Block(4,18,1,AIR:0)
Block(4,18,2,AIR:0)
Block(4,19,-2,AIR:0)
Block(4,19,-1,AIR:0)
Block(4,19,0,AIR:0)
Block(4,19,1,AIR:0)
Block(4,19,2,AIR:0)
Block(4,19,3,AIR:0)
Block(4,19,4,AIR:0)
Block(4,20,-3,AIR:0)
Block(4,20,-2,AIR:0)
Block(4,20,-1,AIR:0)
Block(4,20,0,AIR:0)
Block(4,20,1,AIR:0)
Block(4,20,2,AIR:0)
Block(4,20,3,AIR:0)
Block(4,20,4,AIR:0)
Block(4,21,-5,AIR:0)
Block(4,21,-4,AIR:0)
Block(4,21,-3,AIR:0)
Block(4,21,-2,AIR:0)
Block(4,21,-1,AIR:0)
Block(4,21,0,AIR:0)
Block(4,21,1,AIR:0)
Block(4,21,2,AIR:0)
Block(4,21,3,AIR:0)
Block(4,21,4,AIR:0)
Block(4,21,5,AIR:0)
Block(4,21,6,AIR:0)
Block(4,22,-7,AIR:0)
Block(4,22,-6,AIR:0)
Block(4,22,-5,AIR:0)
Block(4,22,-4,AIR:0)
Block(4,22,-3,AIR:0)
Block(4,22,-2,AIR:0)
Block(4,22,-1,AIR:0)
Block(4,22,0,AIR:0)
Block(4,22,1,AIR:0)
Block(4,22,2,AIR:0)
Block(4,22,3,AIR:0)
Block(4,22,4,AIR:0)
Block(4,22,5,AIR:0)
Block(4,22,6,AIR:0)
Block(4,22,7,AIR:0)
RandomBlock(5,11,-2,CONCRETE:7,70,STAINED_CLAY:12,15,STAINED_CLAY:15,5,CONCRETE:7,100)
RandomBlock(5,11,-1,CONCRETE:7,70,STAINED_CLAY:12,15,STAINED_CLAY:15,5,CONCRETE:7,100)
RandomBlock(5,11,0,CONCRETE:7,70,STAINED_CLAY:12,15,STAINED_CLAY:15,5,CONCRETE:7,100)
RandomBlock(5,11,1,CONCRETE:7,70,STAINED_CLAY:12,15,STAINED_CLAY:15,5,CONCRETE:7,100)
RandomBlock(5,11,2,CONCRETE:7,70,STAINED_CLAY:12,15,STAINED_CLAY:15,5,CONCRETE:7,100)
RandomBlock(5,11,3,CONCRETE:7,70,STAINED_CLAY:12,15,STAINED_CLAY:15,5,CONCRETE:7,100)
RandomBlock(5,12,-2,CONCRETE:7,70,STAINED_CLAY:12,15,STAINED_CLAY:15,5,CONCRETE:7,100)
RandomBlock(5,12,-1,CONCRETE:7,70,STAINED_CLAY:12,15,STAINED_CLAY:15,5,CONCRETE:7,100)
RandomBlock(5,12,0,CONCRETE:7,70,STAINED_CLAY:12,15,STAINED_CLAY:15,5,CONCRETE:7,100)
RandomBlock(5,12,1,CONCRETE:7,70,STAINED_CLAY:12,15,STAINED_CLAY:15,5,CONCRETE:7,100)
RandomBlock(5,12,2,CONCRETE:7,70,STAINED_CLAY:12,15,STAINED_CLAY:15,5,CONCRETE:7,100)
RandomBlock(5,12,3,CONCRETE:7,70,STAINED_CLAY:12,15,STAINED_CLAY:15,5,CONCRETE:7,100)
RandomBlock(5,13,-2,CONCRETE:7,70,STAINED_CLAY:12,15,STAINED_CLAY:15,5,CONCRETE:7,100)
RandomBlock(5,13,-1,CONCRETE:7,70,STAINED_CLAY:12,15,STAINED_CLAY:15,5,CONCRETE:7,100)
RandomBlock(5,13,0,CONCRETE:7,70,STAINED_CLAY:12,15,STAINED_CLAY:15,5,CONCRETE:7,100)
RandomBlock(5,13,1,CONCRETE:7,70,STAINED_CLAY:12,15,STAINED_CLAY:15,5,CONCRETE:7,100)
RandomBlock(5,13,2,CONCRETE:7,70,STAINED_CLAY:12,15,STAINED_CLAY:15,5,CONCRETE:7,100)
RandomBlock(5,13,3,CONCRETE:7,70,STAINED_CLAY:12,15,STAINED_CLAY:15,5,CONCRETE:7,100)
RandomBlock(5,14,-2,CONCRETE:7,70,STAINED_CLAY:12,15,STAINED_CLAY:15,5,CONCRETE:7,100)
RandomBlock(5,14,3,CONCRETE:7,70,STAINED_CLAY:12,15,STAINED_CLAY:15,5,CONCRETE:7,100)
RandomBlock(5,15,-2,CONCRETE:7,70,STAINED_CLAY:12,15,STAINED_CLAY:15,5,CONCRETE:7,100)
RandomBlock(5,15,3,CONCRETE:7,70,STAINED_CLAY:12,15,STAINED_CLAY:15,5,CONCRETE:7,100)
RandomBlock(5,16,-2,CONCRETE:7,70,STAINED_CLAY:12,15,STAINED_CLAY:15,5,CONCRETE:7,100)
RandomBlock(5,16,3,CONCRETE:7,70,STAINED_CLAY:12,15,STAINED_CLAY:15,5,CONCRETE:7,100)
Block(5,18,0,AIR:0)
Block(5,18,1,AIR:0)
Block(5,19,-1,AIR:0)
Block(5,19,0,AIR:0)
Block(5,19,1,AIR:0)
Block(5,19,2,AIR:0)
Block(5,19,3,AIR:0)
Block(5,20,-2,AIR:0)
Block(5,20,-1,AIR:0)
Block(5,20,0,AIR:0)
Block(5,20,1,AIR:0)
Block(5,20,2,AIR:0)
Block(5,20,3,AIR:0)
Block(5,20,4,AIR:0)
Block(5,21,-5,AIR:0)
Block(5,21,-4,AIR:0)
Block(5,21,-3,AIR:0)
Block(5,21,-2,AIR:0)
Block(5,21,-1,AIR:0)
Block(5,21,0,AIR:0)
Block(5,21,1,AIR:0)
Block(5,21,2,AIR:0)
Block(5,21,3,AIR:0)
Block(5,21,4,AIR:0)
Block(5,21,5,AIR:0)
Block(5,22,-6,AIR:0)
Block(5,22,-5,AIR:0)
Block(5,22,-4,AIR:0)
Block(5,22,-3,AIR:0)
Block(5,22,-2,AIR:0)
Block(5,22,-1,AIR:0)
Block(5,22,0,AIR:0)
Block(5,22,1,AIR:0)
Block(5,22,2,AIR:0)
Block(5,22,3,AIR:0)
Block(5,22,4,AIR:0)
Block(5,22,5,AIR:0)
Block(5,22,6,AIR:0)
RandomBlock(6,11,-2,CONCRETE:7,70,STAINED_CLAY:12,15,STAINED_CLAY:15,5,CONCRETE:7,100)
RandomBlock(6,11,-1,CONCRETE:7,70,STAINED_CLAY:12,15,STAINED_CLAY:15,5,CONCRETE:7,100)
RandomBlock(6,11,0,CONCRETE:7,70,STAINED_CLAY:12,15,STAINED_CLAY:15,5,CONCRETE:7,100)
RandomBlock(6,11,1,CONCRETE:7,70,STAINED_CLAY:12,15,STAINED_CLAY:15,5,CONCRETE:7,100)
RandomBlock(6,11,2,CONCRETE:7,70,STAINED_CLAY:12,15,STAINED_CLAY:15,5,CONCRETE:7,100)
RandomBlock(6,11,3,CONCRETE:7,70,STAINED_CLAY:12,15,STAINED_CLAY:15,5,CONCRETE:7,100)
RandomBlock(6,12,-2,CONCRETE:7,70,STAINED_CLAY:12,15,STAINED_CLAY:15,5,CONCRETE:7,100)
RandomBlock(6,12,-1,CONCRETE:7,70,STAINED_CLAY:12,15,STAINED_CLAY:15,5,CONCRETE:7,100)
RandomBlock(6,12,0,CONCRETE:7,70,STAINED_CLAY:12,15,STAINED_CLAY:15,5,CONCRETE:7,100)
RandomBlock(6,12,1,CONCRETE:7,70,STAINED_CLAY:12,15,STAINED_CLAY:15,5,CONCRETE:7,100)
RandomBlock(6,12,2,CONCRETE:7,70,STAINED_CLAY:12,15,STAINED_CLAY:15,5,CONCRETE:7,100)
RandomBlock(6,12,3,CONCRETE:7,70,STAINED_CLAY:12,15,STAINED_CLAY:15,5,CONCRETE:7,100)
RandomBlock(6,13,-2,CONCRETE:7,70,STAINED_CLAY:12,15,STAINED_CLAY:15,5,CONCRETE:7,100)
RandomBlock(6,13,-1,CONCRETE:7,70,STAINED_CLAY:12,15,STAINED_CLAY:15,5,CONCRETE:7,100)
RandomBlock(6,13,0,CONCRETE:7,70,STAINED_CLAY:12,15,STAINED_CLAY:15,5,CONCRETE:7,100)
RandomBlock(6,13,1,CONCRETE:7,70,STAINED_CLAY:12,15,STAINED_CLAY:15,5,CONCRETE:7,100)
RandomBlock(6,13,2,CONCRETE:7,70,STAINED_CLAY:12,15,STAINED_CLAY:15,5,CONCRETE:7,100)
RandomBlock(6,13,3,CONCRETE:7,70,STAINED_CLAY:12,15,STAINED_CLAY:15,5,CONCRETE:7,100)
RandomBlock(6,14,-2,CONCRETE:7,70,STAINED_CLAY:12,15,STAINED_CLAY:15,5,CONCRETE:7,100)
Block(6,14,-1,STEP:0)
Block(6,14,0,STEP:0)
Block(6,14,1,STEP:0)
Block(6,14,2,STEP:0)
RandomBlock(6,14,3,CONCRETE:7,70,STAINED_CLAY:12,15,STAINED_CLAY:15,5,CONCRETE:7,100)
RandomBlock(6,15,-2,CONCRETE:7,70,STAINED_CLAY:12,15,STAINED_CLAY:15,5,CONCRETE:7,100)
RandomBlock(6,15,3,CONCRETE:7,70,STAINED_CLAY:12,15,STAINED_CLAY:15,5,CONCRETE:7,100)
RandomBlock(6,16,-2,CONCRETE:7,70,STAINED_CLAY:12,15,STAINED_CLAY:15,5,CONCRETE:7,100)
RandomBlock(6,16,3,CONCRETE:7,70,STAINED_CLAY:12,15,STAINED_CLAY:15,5,CONCRETE:7,100)
Block(6,18,1,AIR:0)
Block(6,19,0,AIR:0)
Block(6,19,1,AIR:0)
Block(6,19,2,AIR:0)
Block(6,20,-1,AIR:0)
Block(6,20,0,AIR:0)
Block(6,20,1,AIR:0)
Block(6,20,2,AIR:0)
Block(6,20,3,AIR:0)
Block(6,21,-4,AIR:0)
Block(6,21,-3,AIR:0)
Block(6,21,-2,AIR:0)
Block(6,21,-1,AIR:0)
Block(6,21,0,AIR:0)
Block(6,21,1,AIR:0)
Block(6,21,2,AIR:0)
Block(6,21,3,AIR:0)
Block(6,21,4,AIR:0)
Block(6,21,5,AIR:0)
Block(6,22,-5,AIR:0)
Block(6,22,-4,AIR:0)
Block(6,22,-3,AIR:0)
Block(6,22,-2,AIR:0)
Block(6,22,-1,AIR:0)
Block(6,22,0,AIR:0)
Block(6,22,1,AIR:0)
Block(6,22,2,AIR:0)
Block(6,22,3,AIR:0)
Block(6,22,4,AIR:0)
Block(6,22,5,AIR:0)
Block(6,22,6,AIR:0)
RandomBlock(7,11,-2,CONCRETE:7,70,STAINED_CLAY:12,15,STAINED_CLAY:15,5,CONCRETE:7,100)
RandomBlock(7,11,-1,CONCRETE:7,70,STAINED_CLAY:12,15,STAINED_CLAY:15,5,CONCRETE:7,100)
RandomBlock(7,11,0,CONCRETE:7,70,STAINED_CLAY:12,15,STAINED_CLAY:15,5,CONCRETE:7,100)
RandomBlock(7,11,1,CONCRETE:7,70,STAINED_CLAY:12,15,STAINED_CLAY:15,5,CONCRETE:7,100)
RandomBlock(7,11,2,CONCRETE:7,70,STAINED_CLAY:12,15,STAINED_CLAY:15,5,CONCRETE:7,100)
RandomBlock(7,11,3,CONCRETE:7,70,STAINED_CLAY:12,15,STAINED_CLAY:15,5,CONCRETE:7,100)
RandomBlock(7,12,-2,CONCRETE:7,70,STAINED_CLAY:12,15,STAINED_CLAY:15,5,CONCRETE:7,100)
RandomBlock(7,12,-1,CONCRETE:7,70,STAINED_CLAY:12,15,STAINED_CLAY:15,5,CONCRETE:7,100)
RandomBlock(7,12,0,CONCRETE:7,70,STAINED_CLAY:12,15,STAINED_CLAY:15,5,CONCRETE:7,100)
RandomBlock(7,12,1,CONCRETE:7,70,STAINED_CLAY:12,15,STAINED_CLAY:15,5,CONCRETE:7,100)
RandomBlock(7,12,2,CONCRETE:7,70,STAINED_CLAY:12,15,STAINED_CLAY:15,5,CONCRETE:7,100)
RandomBlock(7,12,3,CONCRETE:7,70,STAINED_CLAY:12,15,STAINED_CLAY:15,5,CONCRETE:7,100)
RandomBlock(7,13,-2,CONCRETE:7,70,STAINED_CLAY:12,15,STAINED_CLAY:15,5,CONCRETE:7,100)
RandomBlock(7,13,-1,CONCRETE:7,70,STAINED_CLAY:12,15,STAINED_CLAY:15,5,CONCRETE:7,100)
RandomBlock(7,13,0,CONCRETE:7,70,STAINED_CLAY:12,15,STAINED_CLAY:15,5,CONCRETE:7,100)
RandomBlock(7,13,1,CONCRETE:7,70,STAINED_CLAY:12,15,STAINED_CLAY:15,5,CONCRETE:7,100)
RandomBlock(7,13,2,CONCRETE:7,70,STAINED_CLAY:12,15,STAINED_CLAY:15,5,CONCRETE:7,100)
RandomBlock(7,13,3,CONCRETE:7,70,STAINED_CLAY:12,15,STAINED_CLAY:15,5,CONCRETE:7,100)
RandomBlock(7,14,-2,CONCRETE:7,70,STAINED_CLAY:12,15,STAINED_CLAY:15,5,CONCRETE:7,100)
Block(7,14,-1,STEP:0)
Block(7,14,0,STEP:0)
Block(7,14,1,STEP:0)
Block(7,14,2,STEP:0)
RandomBlock(7,14,3,CONCRETE:7,70,STAINED_CLAY:12,15,STAINED_CLAY:15,5,CONCRETE:7,100)
RandomBlock(7,15,-2,CONCRETE:7,70,STAINED_CLAY:12,15,STAINED_CLAY:15,5,CONCRETE:7,100)
RandomBlock(7,15,3,CONCRETE:7,70,STAINED_CLAY:12,15,STAINED_CLAY:15,5,CONCRETE:7,100)
RandomBlock(7,16,-2,CONCRETE:7,70,STAINED_CLAY:12,15,STAINED_CLAY:15,5,CONCRETE:7,100)
RandomBlock(7,16,3,CONCRETE:7,70,STAINED_CLAY:12,15,STAINED_CLAY:15,5,CONCRETE:7,100)
Block(7,19,0,AIR:0)
Block(7,19,1,AIR:0)
Block(7,19,2,AIR:0)
Block(7,20,-1,AIR:0)
Block(7,20,0,AIR:0)
Block(7,20,1,AIR:0)
Block(7,20,2,AIR:0)
Block(7,21,-3,AIR:0)
Block(7,21,-2,AIR:0)
Block(7,21,-1,AIR:0)
Block(7,21,0,AIR:0)
Block(7,21,1,AIR:0)
Block(7,21,2,AIR:0)
Block(7,21,3,AIR:0)
Block(7,21,4,AIR:0)
Block(7,22,-4,AIR:0)
Block(7,22,-3,AIR:0)
Block(7,22,-2,AIR:0)
Block(7,22,-1,AIR:0)
Block(7,22,0,AIR:0)
Block(7,22,1,AIR:0)
Block(7,22,2,AIR:0)
Block(7,22,3,AIR:0)
Block(7,22,4,AIR:0)
Block(7,22,5,AIR:0)

#RandomBlock(-8,0,-6,CONCRETE:7,70,STAINED_CLAY:12,15,STAINED_CLAY:15,5,CONCRETE:7,100)
#Block(-8,0,-5,IRON_FENCE:0)
#Block(-8,0,-4,LADDER:4)
#Block(-8,0,-3,IRON_FENCE:0)
#RandomBlock(-8,0,-2,CONCRETE:7,70,STAINED_CLAY:12,15,STAINED_CLAY:15,5,CONCRETE:7,100)
#RandomBlock(-8,0,3,CONCRETE:7,70,STAINED_CLAY:12,15,STAINED_CLAY:15,5,CONCRETE:7,100)
#Block(-8,0,4,IRON_FENCE:0)
#Block(-8,0,5,LADDER:4)
#Block(-8,0,6,IRON_FENCE:0)
#RandomBlock(-8,0,7,CONCRETE:7,70,STAINED_CLAY:12,15,STAINED_CLAY:15,5,CONCRETE:7,100)
#RandomBlock(-7,0,-6,CONCRETE:7,70,STAINED_CLAY:12,15,STAINED_CLAY:15,5,CONCRETE:7,100)
#RandomBlock(-7,0,-5,CONCRETE:7,70,STAINED_CLAY:12,15,STAINED_CLAY:15,5,CONCRETE:7,100)
#RandomBlock(-7,0,-4,CONCRETE:7,70,STAINED_CLAY:12,15,STAINED_CLAY:15,5,CONCRETE:7,100)
#RandomBlock(-7,0,-3,CONCRETE:7,70,STAINED_CLAY:12,15,STAINED_CLAY:15,5,CONCRETE:7,100)
#RandomBlock(-7,0,-2,CONCRETE:7,70,STAINED_CLAY:12,15,STAINED_CLAY:15,5,CONCRETE:7,100)
#RandomBlock(-7,0,3,CONCRETE:7,70,STAINED_CLAY:12,15,STAINED_CLAY:15,5,CONCRETE:7,100)
#RandomBlock(-7,0,4,CONCRETE:7,70,STAINED_CLAY:12,15,STAINED_CLAY:15,5,CONCRETE:7,100)
#RandomBlock(-7,0,5,CONCRETE:7,70,STAINED_CLAY:12,15,STAINED_CLAY:15,5,CONCRETE:7,100)
#RandomBlock(-7,0,6,CONCRETE:7,70,STAINED_CLAY:12,15,STAINED_CLAY:15,5,CONCRETE:7,100)
#RandomBlock(-7,0,7,CONCRETE:7,70,STAINED_CLAY:12,15,STAINED_CLAY:15,5,CONCRETE:7,100)
#Block(-6,0,-2,CONCRETE:15)
#Block(-6,0,3,CONCRETE:15)
#Block(-5,0,-6,CONCRETE:15)
#Block(-5,0,-4,CONCRETE:15)
#Block(-5,0,5,CONCRETE:15)
#Block(-5,0,7,CONCRETE:15)
#Block(-3,0,-2,CONCRETE:15)
#Block(-3,0,3,CONCRETE:15)
#Block(2,0,-2,CONCRETE:15)
#Block(2,0,3,CONCRETE:15)
#Block(7,0,-2,CONCRETE:15)
#Block(7,0,3,CONCRETE:15)
#RandomBlock(-8,1,-6,CONCRETE:7,70,STAINED_CLAY:12,15,STAINED_CLAY:15,5,CONCRETE:7,100)
#Block(-8,1,-5,IRON_FENCE:0)
#Block(-8,1,-4,LADDER:4)
#Block(-8,1,-3,IRON_FENCE:0)
#RandomBlock(-8,1,-2,CONCRETE:7,70,STAINED_CLAY:12,15,STAINED_CLAY:15,5,CONCRETE:7,100)
#RandomBlock(-8,1,3,CONCRETE:7,70,STAINED_CLAY:12,15,STAINED_CLAY:15,5,CONCRETE:7,100)
#Block(-8,1,4,IRON_FENCE:0)
#Block(-8,1,5,LADDER:4)
#Block(-8,1,6,IRON_FENCE:0)
#RandomBlock(-8,1,7,CONCRETE:7,70,STAINED_CLAY:12,15,STAINED_CLAY:15,5,CONCRETE:7,100)
#RandomBlock(-7,1,-6,CONCRETE:7,70,STAINED_CLAY:12,15,STAINED_CLAY:15,5,CONCRETE:7,100)
#RandomBlock(-7,1,-5,CONCRETE:7,70,STAINED_CLAY:12,15,STAINED_CLAY:15,5,CONCRETE:7,100)
#RandomBlock(-7,1,-4,CONCRETE:7,70,STAINED_CLAY:12,15,STAINED_CLAY:15,5,CONCRETE:7,100)
#RandomBlock(-7,1,-3,CONCRETE:7,70,STAINED_CLAY:12,15,STAINED_CLAY:15,5,CONCRETE:7,100)
#RandomBlock(-7,1,-2,CONCRETE:7,70,STAINED_CLAY:12,15,STAINED_CLAY:15,5,CONCRETE:7,100)
#RandomBlock(-7,1,3,CONCRETE:7,70,STAINED_CLAY:12,15,STAINED_CLAY:15,5,CONCRETE:7,100)
#RandomBlock(-7,1,4,CONCRETE:7,70,STAINED_CLAY:12,15,STAINED_CLAY:15,5,CONCRETE:7,100)
#RandomBlock(-7,1,5,CONCRETE:7,70,STAINED_CLAY:12,15,STAINED_CLAY:15,5,CONCRETE:7,100)
#RandomBlock(-7,1,6,CONCRETE:7,70,STAINED_CLAY:12,15,STAINED_CLAY:15,5,CONCRETE:7,100)
#RandomBlock(-7,1,7,CONCRETE:7,70,STAINED_CLAY:12,15,STAINED_CLAY:15,5,CONCRETE:7,100)
#Block(-6,1,-2,CONCRETE:15)
#Block(-6,1,3,CONCRETE:15)
#Block(-5,1,-6,CONCRETE:15)
#Block(-5,1,-4,CONCRETE:15)
#Block(-5,1,5,CONCRETE:15)
#Block(-5,1,7,CONCRETE:15)
#Block(-3,1,-2,CONCRETE:15)
#Block(-3,1,3,CONCRETE:15)
#Block(2,1,-2,CONCRETE:15)
#Block(2,1,3,CONCRETE:15)
#Block(7,1,-2,CONCRETE:15)
#Block(7,1,3,CONCRETE:15)
#RandomBlock(-8,2,-6,CONCRETE:7,70,STAINED_CLAY:12,15,STAINED_CLAY:15,5,CONCRETE:7,100)
#Block(-8,2,-5,IRON_FENCE:0)
#Block(-8,2,-4,LADDER:4)
#Block(-8,2,-3,IRON_FENCE:0)
#RandomBlock(-8,2,-2,CONCRETE:7,70,STAINED_CLAY:12,15,STAINED_CLAY:15,5,CONCRETE:7,100)
#RandomBlock(-8,2,3,CONCRETE:7,70,STAINED_CLAY:12,15,STAINED_CLAY:15,5,CONCRETE:7,100)
#Block(-8,2,4,IRON_FENCE:0)
#Block(-8,2,5,LADDER:4)
#Block(-8,2,6,IRON_FENCE:0)
#RandomBlock(-8,2,7,CONCRETE:7,70,STAINED_CLAY:12,15,STAINED_CLAY:15,5,CONCRETE:7,100)
#RandomBlock(-7,2,-6,CONCRETE:7,70,STAINED_CLAY:12,15,STAINED_CLAY:15,5,CONCRETE:7,100)
#RandomBlock(-7,2,-5,CONCRETE:7,70,STAINED_CLAY:12,15,STAINED_CLAY:15,5,CONCRETE:7,100)
#RandomBlock(-7,2,-4,CONCRETE:7,70,STAINED_CLAY:12,15,STAINED_CLAY:15,5,CONCRETE:7,100)
#RandomBlock(-7,2,-3,CONCRETE:7,70,STAINED_CLAY:12,15,STAINED_CLAY:15,5,CONCRETE:7,100)
#RandomBlock(-7,2,-2,CONCRETE:7,70,STAINED_CLAY:12,15,STAINED_CLAY:15,5,CONCRETE:7,100)
#RandomBlock(-7,2,3,CONCRETE:7,70,STAINED_CLAY:12,15,STAINED_CLAY:15,5,CONCRETE:7,100)
#RandomBlock(-7,2,4,CONCRETE:7,70,STAINED_CLAY:12,15,STAINED_CLAY:15,5,CONCRETE:7,100)
#RandomBlock(-7,2,5,CONCRETE:7,70,STAINED_CLAY:12,15,STAINED_CLAY:15,5,CONCRETE:7,100)
#RandomBlock(-7,2,6,CONCRETE:7,70,STAINED_CLAY:12,15,STAINED_CLAY:15,5,CONCRETE:7,100)
#RandomBlock(-7,2,7,CONCRETE:7,70,STAINED_CLAY:12,15,STAINED_CLAY:15,5,CONCRETE:7,100)
#Block(-6,2,-2,CONCRETE:15)
#Block(-6,2,3,CONCRETE:15)
#Block(-5,2,-6,CONCRETE:15)
#Block(-5,2,-4,CONCRETE:15)
#Block(-5,2,5,CONCRETE:15)
#Block(-5,2,7,CONCRETE:15)
#Block(-3,2,-2,CONCRETE:15)
#Block(-3,2,3,CONCRETE:15)
#Block(2,2,-2,CONCRETE:15)
#Block(2,2,3,CONCRETE:15)
#Block(7,2,-2,CONCRETE:15)
#Block(7,2,3,CONCRETE:15)
#RandomBlock(-8,3,-6,CONCRETE:7,70,STAINED_CLAY:12,15,STAINED_CLAY:15,5,CONCRETE:7,100)
#Block(-8,3,-5,IRON_FENCE:0)
#Block(-8,3,-4,LADDER:4)
#Block(-8,3,-3,IRON_FENCE:0)
#RandomBlock(-8,3,-2,CONCRETE:7,70,STAINED_CLAY:12,15,STAINED_CLAY:15,5,CONCRETE:7,100)
#RandomBlock(-8,3,3,CONCRETE:7,70,STAINED_CLAY:12,15,STAINED_CLAY:15,5,CONCRETE:7,100)
#Block(-8,3,4,IRON_FENCE:0)
#Block(-8,3,5,LADDER:4)
#Block(-8,3,6,IRON_FENCE:0)
#RandomBlock(-8,3,7,CONCRETE:7,70,STAINED_CLAY:12,15,STAINED_CLAY:15,5,CONCRETE:7,100)
#RandomBlock(-8,4,-6,CONCRETE:7,70,STAINED_CLAY:12,15,STAINED_CLAY:15,5,CONCRETE:7,100)
#Block(-8,4,-5,IRON_FENCE:0)
#Block(-8,4,-4,LADDER:4)
#Block(-8,4,-3,IRON_FENCE:0)
#RandomBlock(-8,4,-2,CONCRETE:7,70,STAINED_CLAY:12,15,STAINED_CLAY:15,5,CONCRETE:7,100)
#RandomBlock(-8,4,3,CONCRETE:7,70,STAINED_CLAY:12,15,STAINED_CLAY:15,5,CONCRETE:7,100)
#Block(-8,4,4,IRON_FENCE:0)
#Block(-8,4,5,LADDER:4)
#Block(-8,4,6,IRON_FENCE:0)
#RandomBlock(-8,4,7,CONCRETE:7,70,STAINED_CLAY:12,15,STAINED_CLAY:15,5,CONCRETE:7,100)
#RandomBlock(-8,5,-6,CONCRETE:7,70,STAINED_CLAY:12,15,STAINED_CLAY:15,5,CONCRETE:7,100)
#Block(-8,5,-5,IRON_FENCE:0)
#Block(-8,5,-4,LADDER:4)
#Block(-8,5,-3,IRON_FENCE:0)
#RandomBlock(-8,5,-2,CONCRETE:7,70,STAINED_CLAY:12,15,STAINED_CLAY:15,5,CONCRETE:7,100)
#RandomBlock(-8,5,3,CONCRETE:7,70,STAINED_CLAY:12,15,STAINED_CLAY:15,5,CONCRETE:7,100)
#Block(-8,5,4,IRON_FENCE:0)
#Block(-8,5,5,LADDER:4)
#Block(-8,5,6,IRON_FENCE:0)
#RandomBlock(-8,5,7,CONCRETE:7,70,STAINED_CLAY:12,15,STAINED_CLAY:15,5,CONCRETE:7,100)
#RandomBlock(-8,6,-6,CONCRETE:7,70,STAINED_CLAY:12,15,STAINED_CLAY:15,5,CONCRETE:7,100)
#Block(-8,6,-5,IRON_FENCE:0)
#Block(-8,6,-4,LADDER:4)
#Block(-8,6,-3,IRON_FENCE:0)
#RandomBlock(-8,6,-2,CONCRETE:7,70,STAINED_CLAY:12,15,STAINED_CLAY:15,5,CONCRETE:7,100)
#RandomBlock(-8,6,3,CONCRETE:7,70,STAINED_CLAY:12,15,STAINED_CLAY:15,5,CONCRETE:7,100)
#Block(-8,6,4,IRON_FENCE:0)
#Block(-8,6,5,LADDER:4)
#Block(-8,6,6,IRON_FENCE:0)
#RandomBlock(-8,6,7,CONCRETE:7,70,STAINED_CLAY:12,15,STAINED_CLAY:15,5,CONCRETE:7,100)
#RandomBlock(-8,7,-6,CONCRETE:7,70,STAINED_CLAY:12,15,STAINED_CLAY:15,5,CONCRETE:7,100)
#Block(-8,7,-5,IRON_FENCE:0)
#Block(-8,7,-4,LADDER:4)
#Block(-8,7,-3,IRON_FENCE:0)
#RandomBlock(-8,7,-2,CONCRETE:7,70,STAINED_CLAY:12,15,STAINED_CLAY:15,5,CONCRETE:7,100)
#RandomBlock(-8,7,3,CONCRETE:7,70,STAINED_CLAY:12,15,STAINED_CLAY:15,5,CONCRETE:7,100)
#Block(-8,7,4,IRON_FENCE:0)
#Block(-8,7,5,LADDER:4)
#Block(-8,7,6,IRON_FENCE:0)
#RandomBlock(-8,7,7,CONCRETE:7,70,STAINED_CLAY:12,15,STAINED_CLAY:15,5,CONCRETE:7,100)
#RandomBlock(-8,8,-6,CONCRETE:7,70,STAINED_CLAY:12,15,STAINED_CLAY:15,5,CONCRETE:7,100)
#Block(-8,8,-5,IRON_FENCE:0)
#Block(-8,8,-4,LADDER:4)
#Block(-8,8,-3,IRON_FENCE:0)
#RandomBlock(-8,8,-2,CONCRETE:7,70,STAINED_CLAY:12,15,STAINED_CLAY:15,5,CONCRETE:7,100)
#RandomBlock(-8,8,3,CONCRETE:7,70,STAINED_CLAY:12,15,STAINED_CLAY:15,5,CONCRETE:7,100)
#Block(-8,8,4,IRON_FENCE:0)
#Block(-8,8,5,LADDER:4)
#Block(-8,8,6,IRON_FENCE:0)
#RandomBlock(-8,8,7,CONCRETE:7,70,STAINED_CLAY:12,15,STAINED_CLAY:15,5,CONCRETE:7,100)
#RandomBlock(-8,9,-6,CONCRETE:7,70,STAINED_CLAY:12,15,STAINED_CLAY:15,5,CONCRETE:7,100)
#Block(-8,9,-5,IRON_FENCE:0)
#Block(-8,9,-4,LADDER:4)
#Block(-8,9,-3,IRON_FENCE:0)
#RandomBlock(-8,9,-2,CONCRETE:7,70,STAINED_CLAY:12,15,STAINED_CLAY:15,5,CONCRETE:7,100)
#RandomBlock(-8,9,3,CONCRETE:7,70,STAINED_CLAY:12,15,STAINED_CLAY:15,5,CONCRETE:7,100)
#Block(-8,9,4,IRON_FENCE:0)
#Block(-8,9,5,LADDER:4)
#Block(-8,9,6,IRON_FENCE:0)
#RandomBlock(-8,9,7,CONCRETE:7,70,STAINED_CLAY:12,15,STAINED_CLAY:15,5,CONCRETE:7,100)
#RandomBlock(-8,10,-6,CONCRETE:7,70,STAINED_CLAY:12,15,STAINED_CLAY:15,5,CONCRETE:7,100)
#Block(-8,10,-5,IRON_FENCE:0)
#Block(-8,10,-4,LADDER:4)
#Block(-8,10,-3,IRON_FENCE:0)
#RandomBlock(-8,10,-2,CONCRETE:7,70,STAINED_CLAY:12,15,STAINED_CLAY:15,5,CONCRETE:7,100)
#RandomBlock(-8,10,3,CONCRETE:7,70,STAINED_CLAY:12,15,STAINED_CLAY:15,5,CONCRETE:7,100)
#Block(-8,10,4,IRON_FENCE:0)
#Block(-8,10,5,LADDER:4)
#Block(-8,10,6,IRON_FENCE:0)
#RandomBlock(-8,10,7,CONCRETE:7,70,STAINED_CLAY:12,15,STAINED_CLAY:15,5,CONCRETE:7,100)
#RandomBlock(-7,3,-6,CONCRETE:7,70,STAINED_CLAY:12,15,STAINED_CLAY:15,5,CONCRETE:7,100)
#RandomBlock(-7,3,-5,CONCRETE:7,70,STAINED_CLAY:12,15,STAINED_CLAY:15,5,CONCRETE:7,100)
#RandomBlock(-7,3,-4,CONCRETE:7,70,STAINED_CLAY:12,15,STAINED_CLAY:15,5,CONCRETE:7,100)
#RandomBlock(-7,3,-3,CONCRETE:7,70,STAINED_CLAY:12,15,STAINED_CLAY:15,5,CONCRETE:7,100)
#RandomBlock(-7,3,-2,CONCRETE:7,70,STAINED_CLAY:12,15,STAINED_CLAY:15,5,CONCRETE:7,100)
#RandomBlock(-7,3,3,CONCRETE:7,70,STAINED_CLAY:12,15,STAINED_CLAY:15,5,CONCRETE:7,100)
#RandomBlock(-7,3,4,CONCRETE:7,70,STAINED_CLAY:12,15,STAINED_CLAY:15,5,CONCRETE:7,100)
#RandomBlock(-7,3,5,CONCRETE:7,70,STAINED_CLAY:12,15,STAINED_CLAY:15,5,CONCRETE:7,100)
#RandomBlock(-7,3,6,CONCRETE:7,70,STAINED_CLAY:12,15,STAINED_CLAY:15,5,CONCRETE:7,100)
#RandomBlock(-7,3,7,CONCRETE:7,70,STAINED_CLAY:12,15,STAINED_CLAY:15,5,CONCRETE:7,100)
#RandomBlock(-7,4,-6,CONCRETE:7,70,STAINED_CLAY:12,15,STAINED_CLAY:15,5,CONCRETE:7,100)
#RandomBlock(-7,4,-5,CONCRETE:7,70,STAINED_CLAY:12,15,STAINED_CLAY:15,5,CONCRETE:7,100)
#RandomBlock(-7,4,-4,CONCRETE:7,70,STAINED_CLAY:12,15,STAINED_CLAY:15,5,CONCRETE:7,100)
#RandomBlock(-7,4,-3,CONCRETE:7,70,STAINED_CLAY:12,15,STAINED_CLAY:15,5,CONCRETE:7,100)
#RandomBlock(-7,4,-2,CONCRETE:7,70,STAINED_CLAY:12,15,STAINED_CLAY:15,5,CONCRETE:7,100)
#RandomBlock(-7,4,3,CONCRETE:7,70,STAINED_CLAY:12,15,STAINED_CLAY:15,5,CONCRETE:7,100)
#RandomBlock(-7,4,4,CONCRETE:7,70,STAINED_CLAY:12,15,STAINED_CLAY:15,5,CONCRETE:7,100)
#RandomBlock(-7,4,5,CONCRETE:7,70,STAINED_CLAY:12,15,STAINED_CLAY:15,5,CONCRETE:7,100)
#RandomBlock(-7,4,6,CONCRETE:7,70,STAINED_CLAY:12,15,STAINED_CLAY:15,5,CONCRETE:7,100)
#RandomBlock(-7,4,7,CONCRETE:7,70,STAINED_CLAY:12,15,STAINED_CLAY:15,5,CONCRETE:7,100)
#RandomBlock(-7,5,-6,CONCRETE:7,70,STAINED_CLAY:12,15,STAINED_CLAY:15,5,CONCRETE:7,100)
#RandomBlock(-7,5,-5,CONCRETE:7,70,STAINED_CLAY:12,15,STAINED_CLAY:15,5,CONCRETE:7,100)
#RandomBlock(-7,5,-4,CONCRETE:7,70,STAINED_CLAY:12,15,STAINED_CLAY:15,5,CONCRETE:7,100)
#RandomBlock(-7,5,-3,CONCRETE:7,70,STAINED_CLAY:12,15,STAINED_CLAY:15,5,CONCRETE:7,100)
#RandomBlock(-7,5,-2,CONCRETE:7,70,STAINED_CLAY:12,15,STAINED_CLAY:15,5,CONCRETE:7,100)
#RandomBlock(-7,5,3,CONCRETE:7,70,STAINED_CLAY:12,15,STAINED_CLAY:15,5,CONCRETE:7,100)
#RandomBlock(-7,5,4,CONCRETE:7,70,STAINED_CLAY:12,15,STAINED_CLAY:15,5,CONCRETE:7,100)
#RandomBlock(-7,5,5,CONCRETE:7,70,STAINED_CLAY:12,15,STAINED_CLAY:15,5,CONCRETE:7,100)
#RandomBlock(-7,5,6,CONCRETE:7,70,STAINED_CLAY:12,15,STAINED_CLAY:15,5,CONCRETE:7,100)
#RandomBlock(-7,5,7,CONCRETE:7,70,STAINED_CLAY:12,15,STAINED_CLAY:15,5,CONCRETE:7,100)
#RandomBlock(-7,6,-6,CONCRETE:7,70,STAINED_CLAY:12,15,STAINED_CLAY:15,5,CONCRETE:7,100)
#RandomBlock(-7,6,-5,CONCRETE:7,70,STAINED_CLAY:12,15,STAINED_CLAY:15,5,CONCRETE:7,100)
#RandomBlock(-7,6,-4,CONCRETE:7,70,STAINED_CLAY:12,15,STAINED_CLAY:15,5,CONCRETE:7,100)
#RandomBlock(-7,6,-3,CONCRETE:7,70,STAINED_CLAY:12,15,STAINED_CLAY:15,5,CONCRETE:7,100)
#RandomBlock(-7,6,-2,CONCRETE:7,70,STAINED_CLAY:12,15,STAINED_CLAY:15,5,CONCRETE:7,100)
#RandomBlock(-7,6,3,CONCRETE:7,70,STAINED_CLAY:12,15,STAINED_CLAY:15,5,CONCRETE:7,100)
#RandomBlock(-7,6,4,CONCRETE:7,70,STAINED_CLAY:12,15,STAINED_CLAY:15,5,CONCRETE:7,100)
#RandomBlock(-7,6,5,CONCRETE:7,70,STAINED_CLAY:12,15,STAINED_CLAY:15,5,CONCRETE:7,100)
#RandomBlock(-7,6,6,CONCRETE:7,70,STAINED_CLAY:12,15,STAINED_CLAY:15,5,CONCRETE:7,100)
#RandomBlock(-7,6,7,CONCRETE:7,70,STAINED_CLAY:12,15,STAINED_CLAY:15,5,CONCRETE:7,100)
#RandomBlock(-7,7,-6,CONCRETE:7,70,STAINED_CLAY:12,15,STAINED_CLAY:15,5,CONCRETE:7,100)
#RandomBlock(-7,7,-5,CONCRETE:7,70,STAINED_CLAY:12,15,STAINED_CLAY:15,5,CONCRETE:7,100)
#RandomBlock(-7,7,-4,CONCRETE:7,70,STAINED_CLAY:12,15,STAINED_CLAY:15,5,CONCRETE:7,100)
#RandomBlock(-7,7,-3,CONCRETE:7,70,STAINED_CLAY:12,15,STAINED_CLAY:15,5,CONCRETE:7,100)
#RandomBlock(-7,7,-2,CONCRETE:7,70,STAINED_CLAY:12,15,STAINED_CLAY:15,5,CONCRETE:7,100)
#RandomBlock(-7,7,3,CONCRETE:7,70,STAINED_CLAY:12,15,STAINED_CLAY:15,5,CONCRETE:7,100)
#RandomBlock(-7,7,4,CONCRETE:7,70,STAINED_CLAY:12,15,STAINED_CLAY:15,5,CONCRETE:7,100)
#RandomBlock(-7,7,5,CONCRETE:7,70,STAINED_CLAY:12,15,STAINED_CLAY:15,5,CONCRETE:7,100)
#RandomBlock(-7,7,6,CONCRETE:7,70,STAINED_CLAY:12,15,STAINED_CLAY:15,5,CONCRETE:7,100)
#RandomBlock(-7,7,7,CONCRETE:7,70,STAINED_CLAY:12,15,STAINED_CLAY:15,5,CONCRETE:7,100)
#RandomBlock(-7,8,-6,CONCRETE:7,70,STAINED_CLAY:12,15,STAINED_CLAY:15,5,CONCRETE:7,100)
#RandomBlock(-7,8,-5,CONCRETE:7,70,STAINED_CLAY:12,15,STAINED_CLAY:15,5,CONCRETE:7,100)
#RandomBlock(-7,8,-4,CONCRETE:7,70,STAINED_CLAY:12,15,STAINED_CLAY:15,5,CONCRETE:7,100)
#RandomBlock(-7,8,-3,CONCRETE:7,70,STAINED_CLAY:12,15,STAINED_CLAY:15,5,CONCRETE:7,100)
#RandomBlock(-7,8,-2,CONCRETE:7,70,STAINED_CLAY:12,15,STAINED_CLAY:15,5,CONCRETE:7,100)
#RandomBlock(-7,8,3,CONCRETE:7,70,STAINED_CLAY:12,15,STAINED_CLAY:15,5,CONCRETE:7,100)
#RandomBlock(-7,8,4,CONCRETE:7,70,STAINED_CLAY:12,15,STAINED_CLAY:15,5,CONCRETE:7,100)
#RandomBlock(-7,8,5,CONCRETE:7,70,STAINED_CLAY:12,15,STAINED_CLAY:15,5,CONCRETE:7,100)
#RandomBlock(-7,8,6,CONCRETE:7,70,STAINED_CLAY:12,15,STAINED_CLAY:15,5,CONCRETE:7,100)
#RandomBlock(-7,8,7,CONCRETE:7,70,STAINED_CLAY:12,15,STAINED_CLAY:15,5,CONCRETE:7,100)
#RandomBlock(-7,9,-6,CONCRETE:7,70,STAINED_CLAY:12,15,STAINED_CLAY:15,5,CONCRETE:7,100)
#RandomBlock(-7,9,-5,CONCRETE:7,70,STAINED_CLAY:12,15,STAINED_CLAY:15,5,CONCRETE:7,100)
#RandomBlock(-7,9,-4,CONCRETE:7,70,STAINED_CLAY:12,15,STAINED_CLAY:15,5,CONCRETE:7,100)
#RandomBlock(-7,9,-3,CONCRETE:7,70,STAINED_CLAY:12,15,STAINED_CLAY:15,5,CONCRETE:7,100)
#RandomBlock(-7,9,-2,CONCRETE:7,70,STAINED_CLAY:12,15,STAINED_CLAY:15,5,CONCRETE:7,100)
#RandomBlock(-7,9,3,CONCRETE:7,70,STAINED_CLAY:12,15,STAINED_CLAY:15,5,CONCRETE:7,100)
#RandomBlock(-7,9,4,CONCRETE:7,70,STAINED_CLAY:12,15,STAINED_CLAY:15,5,CONCRETE:7,100)
#RandomBlock(-7,9,5,CONCRETE:7,70,STAINED_CLAY:12,15,STAINED_CLAY:15,5,CONCRETE:7,100)
#RandomBlock(-7,9,6,CONCRETE:7,70,STAINED_CLAY:12,15,STAINED_CLAY:15,5,CONCRETE:7,100)
#RandomBlock(-7,9,7,CONCRETE:7,70,STAINED_CLAY:12,15,STAINED_CLAY:15,5,CONCRETE:7,100)
#RandomBlock(-7,10,-6,CONCRETE:7,70,STAINED_CLAY:12,15,STAINED_CLAY:15,5,CONCRETE:7,100)
#RandomBlock(-7,10,-5,CONCRETE:7,70,STAINED_CLAY:12,15,STAINED_CLAY:15,5,CONCRETE:7,100)
#RandomBlock(-7,10,-4,CONCRETE:7,70,STAINED_CLAY:12,15,STAINED_CLAY:15,5,CONCRETE:7,100)
#RandomBlock(-7,10,-3,CONCRETE:7,70,STAINED_CLAY:12,15,STAINED_CLAY:15,5,CONCRETE:7,100)
#RandomBlock(-7,10,-2,CONCRETE:7,70,STAINED_CLAY:12,15,STAINED_CLAY:15,5,CONCRETE:7,100)
#RandomBlock(-7,10,3,CONCRETE:7,70,STAINED_CLAY:12,15,STAINED_CLAY:15,5,CONCRETE:7,100)
#RandomBlock(-7,10,4,CONCRETE:7,70,STAINED_CLAY:12,15,STAINED_CLAY:15,5,CONCRETE:7,100)
#RandomBlock(-7,10,5,CONCRETE:7,70,STAINED_CLAY:12,15,STAINED_CLAY:15,5,CONCRETE:7,100)
#RandomBlock(-7,10,6,CONCRETE:7,70,STAINED_CLAY:12,15,STAINED_CLAY:15,5,CONCRETE:7,100)
#RandomBlock(-7,10,7,CONCRETE:7,70,STAINED_CLAY:12,15,STAINED_CLAY:15,5,CONCRETE:7,100)
#Block(-6,3,-2,CONCRETE:15)
#Block(-6,3,3,CONCRETE:15)
#Block(-6,4,-2,CONCRETE:15)
#Block(-6,4,3,CONCRETE:15)
#Block(-6,5,-2,CONCRETE:15)
#Block(-6,5,3,CONCRETE:15)
#Block(-6,6,-2,CONCRETE:15)
#Block(-6,6,3,CONCRETE:15)
#Block(-6,7,-2,CONCRETE:15)
#Block(-6,7,3,CONCRETE:15)
#Block(-6,8,-2,CONCRETE:15)
#Block(-6,8,3,CONCRETE:15)
#Block(-6,9,-2,CONCRETE:15)
#Block(-6,9,3,CONCRETE:15)
#Block(-6,10,-2,CONCRETE:15)
#Block(-6,10,3,CONCRETE:15)
#Block(-5,3,-6,CONCRETE:15)
#Block(-5,3,-4,CONCRETE:15)
#Block(-5,3,5,CONCRETE:15)
#Block(-5,3,7,CONCRETE:15)
#Block(-5,4,-6,CONCRETE:15)
#Block(-5,4,-4,CONCRETE:15)
#Block(-5,4,5,CONCRETE:15)
#Block(-5,4,7,CONCRETE:15)
#Block(-5,5,-6,CONCRETE:15)
#Block(-5,5,-4,CONCRETE:15)
#Block(-5,5,5,CONCRETE:15)
#Block(-5,5,7,CONCRETE:15)
#Block(-5,6,-6,CONCRETE:15)
#Block(-5,6,-4,CONCRETE:15)
#Block(-5,6,5,CONCRETE:15)
#Block(-5,6,7,CONCRETE:15)
#Block(-5,7,-6,CONCRETE:15)
#Block(-5,7,-4,CONCRETE:15)
#Block(-5,7,5,CONCRETE:15)
#Block(-5,7,7,CONCRETE:15)
#Block(-5,8,-6,CONCRETE:15)
#Block(-5,8,-4,CONCRETE:15)
#Block(-5,8,5,CONCRETE:15)
#Block(-5,8,7,CONCRETE:15)
#Block(-5,9,-6,CONCRETE:15)
#Block(-5,9,-4,CONCRETE:15)
#Block(-5,9,5,CONCRETE:15)
#Block(-5,9,7,CONCRETE:15)
#Block(-5,10,-6,CONCRETE:15)
#Block(-5,10,-4,CONCRETE:15)
#Block(-5,10,-2,CONCRETE:15)
#Block(-5,10,3,CONCRETE:15)
#Block(-5,10,5,CONCRETE:15)
