Author: NLBlackEagle
Description: No description given
SettingsMode: WriteDisable
Frequency: 0
SpawnHeight: highestBlock
UseCenterForHighestBlock: true
MinHeight: 0
MaxHeight: 255
InheritBO3: 
InheritBO3Rotation: NORTH
OverrideChildSettings: true
OverrideParentHeight: false
CanOverride: false
BranchFrequency: 0
BranchFrequencyGroup: 
MustBeBelowOther: false
MustBeInside: 
CannotBeInside: 
ReplacesBO3: 
MustBeInsideWorldBorders: false
CanSpawnOnWater: true
SpawnOnWaterOnly: false
SpawnUnderWater: false
SpawnAtWaterLevel: false
HeightOffset: 0
RemoveAir: false
ReplaceAbove: 
ReplaceBelow: 
ReplaceWithBiomeBlocks: false
ReplaceWithSurfaceBlock: GRASS
ReplaceWithGroundBlock: DIRT
ReplaceWithStoneBlock: STONE
SmoothRadius: 0
SmoothHeightOffset: 0
SmoothStartTop: false
SmoothStartWood: false
SmoothingSurfaceBlock: 
SmoothingGroundBlock: 
BO3Group: 
IsSpawnPoint: false
DoReplaceBlocks: false
Block(-8,3,2,LOG_2:13)
Block(-8,3,3,LOG_2:13)
Block(-8,3,4,LOG_2:13)
Block(-8,3,5,LOG_2:13)
Block(-8,3,6,LOG_2:13)
Block(-8,3,7,LOG_2:13)
Block(-8,3,8,LOG_2:13)
Block(-8,4,-2,LOG_2:13)
Block(-8,4,-1,LOG_2:13)
Block(-8,4,0,LOG_2:13)
Block(-8,4,1,LOG_2:13)
Block(-8,4,2,HAY_BLOCK:8)
Block(-8,4,3,HAY_BLOCK:8)
Block(-8,4,4,AIR:0)
Block(-8,4,5,HAY_BLOCK:4)
Block(-8,4,6,WOOD:5)
Block(-8,4,7,AIR:0)
Block(-8,4,8,AIR:0)
Block(-8,5,-3,LOG_2:13)
Block(-8,5,-2,BRICK:0)
Block(-8,5,-1,BRICK:0)
Block(-8,5,0,WOOD:5)
Block(-8,5,1,HAY_BLOCK:8)
Block(-8,5,2,AIR:0)
Block(-8,5,3,AIR:0)
Block(-8,5,4,AIR:0)
Block(-8,5,5,HAY_BLOCK:0)
Block(-8,5,6,WOOD:5)
Block(-8,5,7,AIR:0)
Block(-8,5,8,AIR:0)
Block(-8,6,-5,LOG_2:13)
Block(-8,6,-4,LOG_2:13)
Block(-8,6,-3,BRICK:0)
Block(-8,6,-2,BRICK:0)
Block(-8,6,-1,BRICK:0)
Block(-8,6,0,WOOD:5)
Block(-8,6,1,HAY_BLOCK:4)
Block(-8,6,2,AIR:0)
Block(-8,6,3,AIR:0)
Block(-8,6,4,AIR:0)
Block(-8,6,5,AIR:0)
Block(-8,6,6,WOOD:5)
Block(-8,6,7,AIR:0)
Block(-8,6,8,AIR:0)
Block(-8,7,-5,WOOD:5)
Block(-8,7,-4,WOOD:5)
Block(-8,7,-3,BRICK:0)
Block(-8,7,-2,MAGMA:0)
Block(-8,7,-1,BRICK:0)
Block(-8,7,0,WOOD:5)
Block(-8,7,1,WOOD:5)
Block(-8,7,2,WOOD:5)
Block(-8,7,3,WOOD:5)
Block(-8,7,4,WOOD:5)
Block(-8,7,5,WOOD:5)
Block(-8,7,6,WOOD:5)
Block(-8,7,7,WOOD:5)
Block(-8,7,8,WOOD:5)
Block(-8,8,-6,WOOD:5)
Block(-8,8,-5,FURNACE:3)
Block(-8,8,-4,CARPET:12)
Block(-8,8,-3,STEP:4)
Block(-8,8,-1,BRICK:0)
Block(-8,8,0,STAINED_CLAY:9)
Block(-8,8,2,CARPET:12)
Block(-8,8,3,BED_BLOCK:10)
Block(-8,8,4,BED_BLOCK:2)
Block(-8,8,5,STONE_BUTTON:4)
Block(-8,8,6,WOOD:2)
Block(-8,8,7,WOOD:2)
Block(-8,8,8,WOOD:2)
Block(-8,9,-7,WOOD:5)
Block(-8,9,-6,WOOD:5)
Block(-8,9,-5,STONE_PLATE:0)
Block(-8,9,-3,STEP:12)
Block(-8,9,-2,IRON_TRAPDOOR:1)
Block(-8,9,-1,BRICK:0)
Block(-8,9,0,STAINED_CLAY:9)
Block(-8,9,6,STONE_BUTTON:5)
Block(-8,9,7,STONE_BUTTON:5)
Block(-8,9,8,STONE_BUTTON:5)
Block(-8,10,-7,STAINED_CLAY:9)
Block(-8,10,-6,STAINED_CLAY:9)
Block(-8,10,-5,STAINED_CLAY:9)
Block(-8,10,-4,STAINED_CLAY:9)
Block(-8,10,-3,BRICK:0)
Block(-8,10,-2,BRICK:0)
Block(-8,10,-1,BRICK:0)
Block(-8,10,0,WOOD_DOUBLE_STEP:5)
Block(-8,10,1,WOOD_STEP:13)
Block(-8,10,2,WOOD_STEP:13)
Block(-8,10,3,WOOD_STEP:13)
Block(-8,10,4,WOOD_STEP:13)
Block(-8,10,5,WOOD_STEP:13)
Block(-8,10,6,WOOD_STEP:13)
Block(-8,10,7,WOOD_STEP:13)
Block(-8,10,8,WOOD_STEP:13)
Block(-8,11,-4,STAINED_CLAY:9)
Block(-8,11,-3,STAINED_CLAY:9)
Block(-8,11,-2,STAINED_CLAY:9)
Block(-8,11,-1,WOOD_STEP:1)
Block(-8,11,0,STONE_BUTTON:2)
Block(-8,11,1,STONE_BUTTON:2)
Block(-8,12,-4,STAINED_CLAY:9)
Block(-8,12,-3,SPRUCE_WOOD_STAIRS:3)
Block(-8,12,0,STONE_BUTTON:2)
Block(-8,15,-3,WOOL:15)
Block(-8,16,-4,WOOL:15)
Block(-8,17,-4,WOOL:15)
Block(-8,18,-4,WOOL:15)
Block(-8,18,-3,WOOL:15)
Block(-8,19,-3,WOOL:15)
Block(-8,19,-1,SPRUCE_FENCE:0)
Block(-8,19,0,SPRUCE_FENCE:0)
Block(-8,20,-3,WOOL:15)
Block(-8,20,-1,SPRUCE_FENCE:0)
Block(-8,20,0,SPRUCE_FENCE:0)
Block(-8,21,-3,WOOL:15)
Block(-8,21,-2,SPRUCE_FENCE:0)
Block(-8,22,-2,LOG:5)
Block(-8,23,-1,WOOD_STEP:13)
Block(-8,23,0,WOOD_STEP:13)
Block(-8,23,1,WOOD_STEP:13)
Block(-8,24,-1,SPRUCE_FENCE:0)
Block(-8,24,0,SPRUCE_FENCE:0)
Block(-8,24,1,SPRUCE_FENCE:0)
Block(-8,25,-2,WOOL:15)
Block(-8,25,-1,SPRUCE_FENCE:0)
Block(-8,25,0,SPRUCE_FENCE:0)
Block(-8,25,1,SPRUCE_FENCE:0)
Block(-8,26,-3,WOOL:15)
Block(-8,26,-1,SPRUCE_FENCE:0)
Block(-8,26,0,SPRUCE_FENCE:0)
Block(-8,26,1,SPRUCE_FENCE:0)
Block(-8,27,-3,WOOL:15)
Block(-8,27,-1,SPRUCE_FENCE:0)
Block(-8,27,0,SPRUCE_FENCE:0)
Block(-8,27,1,SPRUCE_FENCE:0)
Block(-8,28,-3,WOOL:15)
Block(-8,28,-1,SPRUCE_FENCE:0)
Block(-8,28,0,SPRUCE_FENCE:0)
Block(-8,28,1,SPRUCE_FENCE:0)
Block(-8,29,-4,WOOL:15)
Block(-8,29,-1,SPRUCE_FENCE:0)
Block(-8,29,0,SPRUCE_FENCE:0)
Block(-8,30,-3,WOOL:15)
Block(-8,30,-1,SPRUCE_FENCE:0)
Block(-8,30,0,SPRUCE_FENCE:0)
Block(-8,31,-3,WOOL:15)
Block(-8,31,-1,SPRUCE_FENCE:0)
Block(-8,31,0,SPRUCE_FENCE:0)
Block(-8,32,-3,WOOL:15)
Block(-8,33,-1,SPRUCE_FENCE:0)
Block(-8,34,-1,LOG:5)
Block(-8,36,-3,WOOL:15)
Block(-8,37,-4,WOOL:15)
Block(-8,38,-3,WOOL:15)
Block(-8,39,-3,WOOL:15)
Block(-8,40,-2,SPRUCE_FENCE:0)
Block(-8,41,-2,LOG:5)
Block(-7,2,3,LOG_2:13)
Block(-7,2,4,LOG_2:13)
Block(-7,2,5,LOG_2:13)
Block(-7,2,6,LOG_2:13)
Block(-7,2,7,LOG_2:13)
Block(-7,2,8,LOG_2:13)
Block(-7,3,-1,LOG_2:13)
Block(-7,3,0,LOG_2:13)
Block(-7,3,1,LOG_2:13)
Block(-7,3,2,LOG_2:13)
Block(-7,3,3,LOG_2:13)
Block(-7,3,4,LOG_2:13)
Block(-7,3,5,LOG_2:13)
Block(-7,3,6,LOG_2:13)
Block(-7,3,7,LOG_2:13)
Block(-7,3,8,STONE:1)
Block(-7,4,-3,LOG_2:13)
Block(-7,4,-2,LOG_2:13)
Block(-7,4,-1,WOOD:5)
Block(-7,4,0,WOOD:5)
Block(-7,4,1,HAY_BLOCK:8)
Block(-7,4,2,AIR:0)
Block(-7,4,3,AIR:0)
Block(-7,4,4,AIR:0)
Block(-7,4,5,LADDER:2)
Block(-7,4,6,WOOD:5)
Block(-7,4,7,LADDER:3)
Block(-7,4,8,AIR:0)
Block(-7,5,-4,LOG_2:13)
Block(-7,5,-3,BRICK:0)
Block(-7,5,-2,BRICK:0)
Block(-7,5,-1,BRICK:0)
Block(-7,5,0,WOOD:5)
Block(-7,5,1,HAY_BLOCK:4)
Block(-7,5,2,AIR:0)
Block(-7,5,3,AIR:0)
Block(-7,5,4,AIR:0)
Block(-7,5,5,LADDER:2)
Block(-7,5,6,WOOD:5)
Block(-7,5,7,LADDER:3)
Block(-7,5,8,AIR:0)
Block(-7,6,-5,LOG_2:13)
Block(-7,6,-4,BRICK:0)
Block(-7,6,-3,BRICK:0)
Block(-7,6,-2,BRICK:0)
Block(-7,6,-1,BRICK:0)
Block(-7,6,0,WOOD:5)
Block(-7,6,1,AIR:0)
Block(-7,6,2,AIR:0)
Block(-7,6,3,AIR:0)
Block(-7,6,4,AIR:0)
Block(-7,6,5,LADDER:2)
Block(-7,6,6,WOOD:5)
Block(-7,6,7,LADDER:3)
Block(-7,6,8,AIR:0)
Block(-7,7,-5,WOOD:5)
Block(-7,7,-4,WOOD:5)
Block(-7,7,-3,BRICK:0)
Block(-7,7,-2,BRICK:0)
Block(-7,7,-1,BRICK:0)
Block(-7,7,0,WOOD:5)
Block(-7,7,1,WOOD:5)
Block(-7,7,2,TRAP_DOOR:10)
Block(-7,7,3,TRAP_DOOR:10)
Block(-7,7,4,TRAP_DOOR:10)
Block(-7,7,5,TRAP_DOOR:10)
Block(-7,7,6,WOOD_DOUBLE_STEP:1)
Block(-7,7,7,TRAP_DOOR:10)
Block(-7,7,8,TRAP_DOOR:10)
Block(-7,8,-7,WOOD:5)
Block(-7,8,-6,WOOD:5)
Block(-7,8,-5,WORKBENCH:0)
Block(-7,8,-3,BRICK:0)
Block(-7,8,-2,BRICK:0)
Block(-7,8,-1,BRICK:0)
Block(-7,8,0,STAINED_CLAY:9)
RandomBlock(-7,8,1,AIR:0,20,CHEST:3,../../../../Chests/Loot/PirateJunk_1.nbt,10,CHEST:3,../../../../Chests/Loot/PirateJunk_2.nbt,10,CHEST:3,../../../../Chests/Loot/PirateJunk_3.nbt,10,CHEST:3,../../../../Chests/Loot/PirateJunk_4.nbt,10,CHEST:3,../../../../Chests/Loot/PirateJunk_5.nbt,10,CHEST:3,../../../../Chests/Traveler/Travelers_Castle.nbt,1,CHEST:3,../../../../Chests/Traveler/Travelers_Church.nbt,1,CHEST:3,../../../../Chests/Traveler/Travelers_Daeroc.nbt,1,CHEST:3,../../../../Chests/Traveler/Travelers_Farmsteads.nbt,1,CHEST:3,../../../../Chests/Traveler/Travelers_GreenDungeon.nbt,1,CHEST:3,../../../../Chests/Traveler/Travelers_IceShips.nbt,1,CHEST:3,../../../../Chests/Traveler/Travelers_IceTemple.nbt,1,CHEST:3,../../../../Chests/Traveler/Travelers_LegacySpawn.nbt,1,CHEST:3,../../../../Chests/Traveler/Travelers_Mineshafts.nbt,1,CHEST:3,../../../../Chests/Traveler/Travelers_Mountains.nbt,1,CHEST:3,../../../../Chests/Traveler/Travelers_Origin.nbt,1,CHEST:3,../../../../Chests/Traveler/Travelers_Pirate.nbt,1,CHEST:3,../../../../Chests/Traveler/Travelers_Quarry.nbt,1,CHEST:3,../../../../Chests/Traveler/Travelers_Spook.nbt,1,CHEST:3,../../../../Chests/Traveler/Travelers_Tribal.nbt,1,CHEST:3,../../../../Chests/Lore/Pirate_1.nbt,1,CHEST:3,../../../../Chests/Lore/Pirate_2.nbt,1,CHEST:3,../../../../Chests/Lore/Pirate_3.nbt,1,CHEST:3,../../../../Chests/Lore/Pirate_4.nbt,1,CHEST:3,../../../../Chests/Lore/Pirate_5.nbt,1,CHEST:3,../../../../Chests/Loot/Common1.nbt,10,CHEST:3,../../../../Chests/Loot/Common2.nbt,10,CHEST:3,../../../../Chests/Loot/Common3.nbt,10,CHEST:3,../../../../Chests/Loot/Common4.nbt,10,CHEST:3,../../../../Chests/Loot/Common5.nbt,10,CHEST:3,../../../../Chests/Loot/Common6.nbt,10,CHEST:3,../../../../Chests/Loot/Common7.nbt,10,CHEST:3,../../../../Chests/Loot/Common8.nbt,10,CHEST:3,../../../../Chests/Loot/Common9.nbt,10,CHEST:3,../../../../Chests/Loot/Common10.nbt,10,CHEST:3,../../../../Chests/Loot/Common10.nbt,11,CHEST:3,../../../../Chests/Loot/Common12.nbt,10,CHEST:3,../../../../Chests/Loot/Common13.nbt,10,CHEST:3,../../../../Chests/Loot/Common14.nbt,10,CHEST:3,../../../../Chests/Loot/Common15.nbt,10,CHEST:3,../../../../Chests/Lore/Pirate_1.nbt,2,CHEST:3,../../../../Chests/Lore/Pirate_3.nbt,2,CHEST:3,../../../../Chests/Lore/Pirate_4.nbt,2,CHEST:3,../../../../Chests/Lore/Pirate_5.nbt,2,CHEST:3,../../../../Chests/Lore/Pirate_5.nbt,2,CHEST:3,../../../../Chests/Loot/Rare1.nbt,5,CHEST:3,../../../../Chests/Loot/Rare2.nbt,5,CHEST:3,../../../../Chests/Loot/Rare3.nbt,5,CHEST:3,../../../../Chests/Loot/Rare4.nbt,5,CHEST:3,../../../../Chests/Loot/Rare5.nbt,5,CHEST:3,../../../../Chests/Loot/Rare6.nbt,5,CHEST:3,../../../../Chests/Loot/Rare7.nbt,5,CHEST:3,../../../../Chests/Loot/Rare8.nbt,5,CHEST:3,../../../../Chests/Loot/Rare9.nbt,5,CHEST:3,../../../../Chests/Loot/Rare10.nbt,5,CHEST:3,../../../../Chests/Loot/Rare11.nbt,5,CHEST:3,../../../../Chests/Loot/Rare12.nbt,5,CHEST:3,../../../../Chests/Loot/Rare13.nbt,5,CHEST:3,../../../../Chests/Loot/Rare14.nbt,5,CHEST:3,../../../../Chests/Loot/Rare15.nbt,5,CHEST:3,../../../../Chests/Loot/Epic1.nbt,2,CHEST:3,../../../../Chests/Loot/Epic2.nbt,2,CHEST:3,../../../../Chests/Loot/Epic3.nbt,2,CHEST:3,../../../../Chests/Loot/Epic4.nbt,2,CHEST:3,../../../../Chests/Loot/Epic5.nbt,2,CHEST:3,../../../../Chests/Loot/Epic6.nbt,2,CHEST:3,../../../../Chests/Loot/Epic7.nbt,2,CHEST:3,../../../../Chests/Loot/Epic8.nbt,2,CHEST:3,../../../../Chests/Loot/Epic9.nbt,2,CHEST:3,../../../../Chests/Loot/Epic10.nbt,2,CHEST:3,../../../../Chests/Loot/Epic11.nbt,2,CHEST:3,../../../../Chests/Loot/Epic12.nbt,2,CHEST:3,../../../../Chests/Loot/Epic13.nbt,2,CHEST:3,../../../../Chests/Loot/Epic14.nbt,2,CHEST:3,../../../../Chests/Loot/Epic15.nbt,5,CHEST:3,../../../../Chests/Loot/Rare1.nbt,5,CHEST:3,../../../../Chests/Loot/Rare2.nbt,5,CHEST:3,../../../../Chests/Loot/Rare3.nbt,5,CHEST:3,../../../../Chests/Loot/Rare4.nbt,5,CHEST:3,../../../../Chests/Loot/Rare5.nbt,10,CHEST:3,../../../../Chests/Loot/Rare6.nbt,10,CHEST:3,../../../../Chests/Loot/Rare7.nbt,10,CHEST:3,../../../../Chests/Loot/Rare8.nbt,10,CHEST:3,../../../../Chests/Loot/Rare9.nbt,10,CHEST:3,../../../../Chests/Loot/Rare10.nbt,15,CHEST:3,../../../../Chests/Loot/Rare11.nbt,15,CHEST:3,../../../../Chests/Loot/Rare12.nbt,15,CHEST:3,../../../../Chests/Loot/Rare13.nbt,15,CHEST:3,../../../../Chests/Loot/Rare14.nbt,15,CHEST:3,../../../../Chests/Loot/Rare15.nbt,15,CHEST:3,../../../../Chests/Loot/Epic15.nbt,100)
Block(-7,8,6,STONE_BUTTON:1)
Block(-7,8,7,STONE_BUTTON:1)
Block(-7,8,8,STONE_BUTTON:1)
Block(-7,9,-7,WOOD:5)
Block(-7,9,-6,WOOD:5)
Block(-7,9,-5,WOOD_PLATE:0)
Block(-7,9,-3,BRICK:0)
Block(-7,9,-2,DOUBLE_STEP:4)
Block(-7,9,-1,BRICK:0)
Block(-7,9,0,STAINED_CLAY:9)
Block(-7,10,-7,STAINED_CLAY:9)
Block(-7,10,-6,STAINED_CLAY:9)
Block(-7,10,-5,STAINED_CLAY:9)
Block(-7,10,-4,STAINED_CLAY:9)
Block(-7,10,-3,BRICK:0)
Block(-7,10,-2,BRICK:0)
Block(-7,10,-1,BRICK:0)
Block(-7,10,0,WOOD_DOUBLE_STEP:5)
Block(-7,10,1,WOOD_STEP:13)
Block(-7,10,2,WOOD_STEP:13)
Block(-7,11,-4,STAINED_CLAY:9)
Block(-7,11,-3,STAINED_CLAY:9)
Block(-7,11,-2,STAINED_CLAY:9)
Block(-7,11,-1,WOOD_STEP:1)
Block(-7,11,0,WOOD:2)
Block(-7,11,1,WOOD:2)
Block(-7,11,2,STONE_BUTTON:3)
Block(-7,11,3,TRAP_DOOR:2)
Block(-7,11,4,TRAP_DOOR:2)
Block(-7,11,5,TRAP_DOOR:2)
Block(-7,11,6,TRAP_DOOR:2)
Block(-7,11,7,TRAP_DOOR:2)
Block(-7,11,8,TRAP_DOOR:2)
Block(-7,12,-4,STAINED_CLAY:9)
Block(-7,12,-1,STONE_BUTTON:4)
Block(-7,12,0,WOOD:2)
Block(-7,12,1,STONE_BUTTON:3)
Block(-7,13,-4,WOOD_STEP:5)
Block(-7,13,0,STONE_BUTTON:2)
Block(-7,15,-2,WOOL:15)
Block(-7,16,-3,WOOL:15)
Block(-7,17,-4,WOOL:15)
Block(-7,18,-3,WOOL:15)
Block(-7,19,-3,WOOL:15)
Block(-7,20,-3,WOOL:15)
Block(-7,20,-1,SPRUCE_FENCE:0)
Block(-7,20,0,SPRUCE_FENCE:0)
Block(-7,21,-2,WOOL:15)
Block(-7,21,-1,SPRUCE_FENCE:0)
Block(-7,22,-1,LOG:5)
Block(-7,23,-1,WOOD_STEP:13)
Block(-7,23,0,WOOD_STEP:13)
Block(-7,23,1,WOOD_STEP:13)
Block(-7,24,-1,SPRUCE_FENCE:0)
Block(-7,24,1,SPRUCE_FENCE:0)
Block(-7,25,-2,WOOL:15)
Block(-7,26,-3,WOOL:15)
Block(-7,27,-3,WOOL:15)
Block(-7,28,-3,WOOL:15)
Block(-7,29,-3,WOOL:15)
Block(-7,30,-3,WOOL:15)
Block(-7,31,-3,WOOL:15)
Block(-7,31,-1,SPRUCE_FENCE:0)
Block(-7,31,0,SPRUCE_FENCE:0)
Block(-7,32,-3,WOOL:15)
Block(-7,32,-1,SPRUCE_FENCE:0)
Block(-7,33,-1,SPRUCE_FENCE:0)
Block(-7,34,-1,LOG:5)
Block(-7,36,-3,WOOL:15)
Block(-7,37,-3,WOOL:15)
Block(-7,38,-3,WOOL:15)
Block(-7,39,-3,WOOL:15)
Block(-7,40,-1,SPRUCE_FENCE:0)
Block(-7,41,-1,LOG:5)
Block(-6,0,3,WOOD:5)
Block(-6,0,4,WOOD:5)
Block(-6,0,5,WOOD:5)
Block(-6,0,6,WOOD:5)
Block(-6,0,7,WOOD:5)
Block(-6,0,8,WOOD:5)
Block(-6,1,-1,WOOD:5)
Block(-6,1,0,WOOD:5)
Block(-6,1,1,WOOD:5)
Block(-6,1,2,WOOD:5)
Block(-6,1,3,LOG_2:13)
Block(-6,1,4,LOG_2:13)
Block(-6,1,5,LOG_2:13)
Block(-6,1,6,LOG_2:13)
Block(-6,1,7,LOG_2:13)
Block(-6,1,8,LOG_2:13)
Block(-6,2,-3,WOOD:5)
Block(-6,2,-2,WOOD:5)
Block(-6,2,-1,LOG_2:13)
Block(-6,2,0,LOG_2:13)
Block(-6,2,1,LOG_2:13)
Block(-6,2,2,LOG_2:13)
Block(-6,2,3,LOG_2:13)
Block(-6,2,4,LOG_2:13)
Block(-6,2,5,LOG_2:13)
Block(-6,2,6,LOG_2:13)
Block(-6,2,7,LOG_2:13)
Block(-6,2,8,LOG_2:13)
Block(-6,3,-4,WOOD:5)
Block(-6,3,-3,LOG_2:13)
Block(-6,3,-2,LOG_2:13)
Block(-6,3,-1,LOG_2:13)
Block(-6,3,0,LOG_2:13)
Block(-6,3,1,LOG_2:13)
Block(-6,3,2,LOG_2:13)
Block(-6,3,3,LOG_2:13)
Block(-6,3,4,LOG_2:13)
Block(-6,3,5,LOG_2:13)
Block(-6,3,6,LOG_2:13)
Block(-6,3,7,LOG_2:13)
Block(-6,3,8,STONE:1)
Block(-6,4,-5,WOOD:5)
Block(-6,4,-4,LOG_2:13)
Block(-6,4,-3,WOOD:5)
Block(-6,4,-2,WOOD:5)
Block(-6,4,-1,LOG:1)
Block(-6,4,0,WOOD:5)
Block(-6,4,1,HAY_BLOCK:8)
Block(-6,4,2,AIR:0)
Block(-6,4,3,AIR:0)
Block(-6,4,4,AIR:0)
Block(-6,4,5,AIR:0)
Block(-6,4,6,WOOD:5)
Block(-6,4,7,AIR:0)
Block(-6,4,8,AIR:0)
Block(-6,5,-6,WOOD:5)
Block(-6,5,-5,LOG_2:13)
Block(-6,5,-4,WOOD:5)
Block(-6,5,-3,BED_BLOCK:10)
Block(-6,5,-2,BED_BLOCK:2)
Block(-6,5,-1,LOG:1)
Block(-6,5,0,WOOD:5)
Block(-6,5,1,HAY_BLOCK:0)
Block(-6,5,2,AIR:0)
Block(-6,5,3,AIR:0)
Block(-6,5,4,AIR:0)
Block(-6,5,5,AIR:0)
Block(-6,5,6,WOOD:5)
Block(-6,5,7,AIR:0)
Block(-6,5,8,AIR:0)
Block(-6,6,-7,WOOD:5)
Block(-6,6,-6,LOG_2:13)
Block(-6,6,-5,WOOD:5)
Block(-6,6,-4,WOOD:5)
Block(-6,6,-3,BED_BLOCK:10)
Block(-6,6,-2,BED_BLOCK:2)
Block(-6,6,-1,LOG:1)
Block(-6,6,0,WOOD:5)
Block(-6,6,1,AIR:0)
Block(-6,6,2,AIR:0)
Block(-6,6,3,AIR:0)
Block(-6,6,4,AIR:0)
Block(-6,6,5,AIR:0)
Block(-6,6,6,WOOD:5)
Block(-6,6,7,AIR:0)
Block(-6,6,8,AIR:0)
Block(-6,7,-7,WOOD:5)
Block(-6,7,-6,WOOD:5)
Block(-6,7,-5,WOOD:5)
Block(-6,7,-4,WOOD:5)
Block(-6,7,-3,WOOD:5)
Block(-6,7,-2,WOOD:5)
Block(-6,7,-1,LOG:1)
Block(-6,7,0,WOOD:5)
Block(-6,7,1,WOOD:5)
Block(-6,7,2,WOOD_STEP:9)
Block(-6,7,3,WOOD_STEP:9)
Block(-6,7,4,WOOD_STEP:9)
Block(-6,7,5,WOOD_STEP:9)
Block(-6,7,6,WOOD_DOUBLE_STEP:1)
Block(-6,7,7,WOOD_STEP:9)
Block(-6,7,8,WOOD_STEP:9)
Block(-6,8,-7,WOOD:5)
Block(-6,8,-6,WOOD:5)
Block(-6,8,-5,WOOD:5)
Block(-6,8,-4,CARPET:12)
Block(-6,8,-3,WOOD:5)
Block(-6,8,-2,WOOD:5)
Block(-6,8,-1,LOG:1)
Block(-6,8,0,STAINED_CLAY:9)
Block(-6,8,1,WOOD:5)
Block(-6,8,3,SPRUCE_FENCE:0)
Block(-6,8,4,BED_BLOCK:10)
Block(-6,8,5,BED_BLOCK:2)
Block(-6,8,6,SPRUCE_FENCE:0)
Block(-6,8,7,BED_BLOCK:10)
Block(-6,8,8,BED_BLOCK:2)
Block(-6,9,-7,WOOD:5)
Block(-6,9,-6,WOOD:5)
Block(-6,9,-5,WOOD:5)
Block(-6,9,-3,WOOD:5)
Block(-6,9,-2,WOOD:5)
Block(-6,9,-1,LOG:1)
Block(-6,9,0,STAINED_CLAY:9)
Block(-6,9,1,TORCH:5)
Block(-6,9,3,SPRUCE_FENCE:0)
Block(-6,9,4,BED_BLOCK:0)
Block(-6,9,5,BED_BLOCK:8)
Block(-6,9,6,SPRUCE_FENCE:0)
Block(-6,9,7,BED_BLOCK:0)
Block(-6,9,8,BED_BLOCK:8)
Block(-6,10,-7,STAINED_CLAY:9)
Block(-6,10,-6,STAINED_CLAY:9)
Block(-6,10,-5,WOOD_DOUBLE_STEP:1)
Block(-6,10,-4,WOOD_DOUBLE_STEP:1)
Block(-6,10,-3,WOOD_DOUBLE_STEP:1)
Block(-6,10,-2,WOOD_DOUBLE_STEP:1)
Block(-6,10,-1,LOG:1)
Block(-6,10,0,WOOD_DOUBLE_STEP:5)
Block(-6,10,1,WOOD_STEP:13)
Block(-6,10,2,WOOD_STEP:13)
Block(-6,10,3,SPRUCE_FENCE:0)
Block(-6,10,6,SPRUCE_FENCE:0)
Block(-6,11,-7,WOOD_STEP:9)
Block(-6,11,-6,WOOD_DOUBLE_STEP:1)
Block(-6,11,-5,WOOD_DOUBLE_STEP:1)
Block(-6,11,-4,STAINED_CLAY:9)
Block(-6,11,-3,STAINED_CLAY:9)
Block(-6,11,-2,STAINED_CLAY:9)
Block(-6,11,-1,LOG:1)
Block(-6,11,0,WOOD:2)
Block(-6,11,1,WOOD:2)
Block(-6,11,2,STONE_BUTTON:3)
Block(-6,11,3,WOOD_STEP:1)
Block(-6,11,4,WOOD_STEP:1)
Block(-6,11,5,WOOD_STEP:1)
Block(-6,11,6,WOOD_STEP:1)
Block(-6,11,7,WOOD_STEP:1)
Block(-6,11,8,WOOD_STEP:1)
Block(-6,12,-7,WOOD_DOUBLE_STEP:1)
Block(-6,12,-6,WOOD_STEP:1)
Block(-6,12,-4,STAINED_CLAY:9)
Block(-6,12,-1,LOG:1)
Block(-6,12,0,WOOD:2)
Block(-6,13,-4,WOOD_STEP:5)
Block(-6,13,-3,AIR:0)
Block(-6,13,-1,LOG:1)
Block(-6,13,0,WOOD:2)
Block(-6,13,1,STONE_BUTTON:3)
Block(-6,14,-1,LOG:1)
Block(-6,15,-2,WOOL:15)
Block(-6,15,-1,LOG:1)
Block(-6,15,4,WOOL:15)
Block(-6,15,5,WOOL:15)
Block(-6,16,-3,WOOL:15)
Block(-6,16,-1,LOG:1)
Block(-6,16,0,WOOL:15)
Block(-6,16,1,WOOL:15)
Block(-6,16,2,WOOL:15)
Block(-6,16,3,WOOL:15)
Block(-6,17,-3,WOOL:15)
Block(-6,17,-1,LOG:1)
Block(-6,17,0,SPRUCE_FENCE:0)
Block(-6,17,1,SPRUCE_FENCE:0)
Block(-6,17,2,SPRUCE_FENCE:0)
Block(-6,17,3,WOOL:15)
Block(-6,17,4,WOOL:15)
Block(-6,17,5,WOOL:15)
Block(-6,18,-7,SPRUCE_FENCE:0)
Block(-6,18,-3,WOOL:15)
Block(-6,18,-1,LOG:1)
Block(-6,18,2,SPRUCE_FENCE:0)
Block(-6,18,3,SPRUCE_FENCE:0)
Block(-6,18,4,SPRUCE_FENCE:0)
Block(-6,18,5,WOOL:15)
Block(-6,18,6,WOOL:15)
Block(-6,18,7,WOOL:15)
Block(-6,19,-7,SPRUCE_FENCE:0)
Block(-6,19,-6,SPRUCE_FENCE:0)
Block(-6,19,-3,WOOL:15)
Block(-6,19,-1,LOG:1)
Block(-6,19,4,SPRUCE_FENCE:0)
Block(-6,19,5,SPRUCE_FENCE:0)
Block(-6,19,6,SPRUCE_FENCE:0)
Block(-6,19,7,WOOL:15)
Block(-6,19,8,WOOL:15)
Block(-6,20,-7,WOOL:15)
Block(-6,20,-6,SPRUCE_FENCE:0)
Block(-6,20,-5,SPRUCE_FENCE:0)
Block(-6,20,-2,WOOL:15)
Block(-6,20,-1,LOG:1)
Block(-6,20,6,SPRUCE_FENCE:0)
Block(-6,20,7,SPRUCE_FENCE:0)
Block(-6,20,8,SPRUCE_FENCE:0)
Block(-6,21,-7,WOOL:15)
Block(-6,21,-5,SPRUCE_FENCE:0)
Block(-6,21,-4,SPRUCE_FENCE:0)
Block(-6,21,-2,WOOL:15)
Block(-6,21,-1,LOG:1)
Block(-6,21,8,SPRUCE_FENCE:0)
Block(-6,22,-4,SPRUCE_FENCE:0)
Block(-6,22,-3,SPRUCE_FENCE:0)
Block(-6,22,-1,LOG:1)
Block(-6,23,-3,SPRUCE_FENCE:0)
Block(-6,23,-2,SPRUCE_FENCE:0)
Block(-6,23,-1,LOG:1)
Block(-6,23,0,WOOD_STEP:13)
Block(-6,23,1,WOOD_STEP:13)
Block(-6,23,3,WOOL:15)
Block(-6,23,4,WOOL:15)
Block(-6,24,-1,LOG:1)
Block(-6,24,1,SPRUCE_FENCE:0)
Block(-6,24,5,WOOL:15)
Block(-6,24,8,WOOL:15)
Block(-6,25,-2,WOOL:15)
Block(-6,25,-1,LOG:1)
Block(-6,25,6,WOOL:15)
Block(-6,25,7,WOOL:15)
Block(-6,25,8,WOOL:15)
Block(-6,26,-3,WOOL:15)
Block(-6,26,-1,LOG:1)
Block(-6,27,-3,WOOL:15)
Block(-6,27,-1,LOG:1)
Block(-6,28,-7,WOOL:15)
Block(-6,28,-3,WOOL:15)
Block(-6,28,-1,LOG:1)
Block(-6,29,-7,WOOL:15)
Block(-6,29,-6,WOOL:15)
Block(-6,29,-3,WOOL:15)
Block(-6,29,-1,LOG:1)
Block(-6,29,2,WOOL:15)
Block(-6,30,-7,SPRUCE_FENCE:0)
Block(-6,30,-6,WOOL:15)
Block(-6,30,-3,WOOL:15)
Block(-6,30,-1,LOG:1)
Block(-6,30,1,WOOL:15)
Block(-6,30,2,WOOL:15)
Block(-6,30,3,WOOL:15)
Block(-6,31,-7,SPRUCE_FENCE:0)
Block(-6,31,-6,SPRUCE_FENCE:0)
Block(-6,31,-5,WOOL:15)
Block(-6,31,-3,WOOL:15)
Block(-6,31,-1,LOG:1)
Block(-6,31,0,SPRUCE_FENCE:0)
Block(-6,31,1,SPRUCE_FENCE:0)
Block(-6,31,2,SPRUCE_FENCE:0)
Block(-6,31,3,WOOL:15)
Block(-6,31,4,WOOL:15)
Block(-6,31,5,WOOL:15)
Block(-6,32,-6,SPRUCE_FENCE:0)
Block(-6,32,-5,SPRUCE_FENCE:0)
Block(-6,32,-3,WOOL:15)
Block(-6,32,-1,LOG:1)
Block(-6,32,2,SPRUCE_FENCE:0)
Block(-6,32,3,SPRUCE_FENCE:0)
Block(-6,32,4,SPRUCE_FENCE:0)
Block(-6,32,5,WOOL:15)
Block(-6,32,6,WOOL:15)
Block(-6,32,7,WOOL:15)
Block(-6,33,-5,SPRUCE_FENCE:0)
Block(-6,33,-4,SPRUCE_FENCE:0)
Block(-6,33,-1,LOG:1)
Block(-6,33,4,SPRUCE_FENCE:0)
Block(-6,33,5,SPRUCE_FENCE:0)
Block(-6,33,6,SPRUCE_FENCE:0)
Block(-6,33,7,WOOL:15)
Block(-6,33,8,WOOL:15)
Block(-6,34,-4,SPRUCE_FENCE:0)
Block(-6,34,-3,SPRUCE_FENCE:0)
Block(-6,34,-1,LOG:1)
Block(-6,34,6,SPRUCE_FENCE:0)
Block(-6,34,7,SPRUCE_FENCE:0)
Block(-6,34,8,SPRUCE_FENCE:0)
Block(-6,35,-3,SPRUCE_FENCE:0)
Block(-6,35,-2,SPRUCE_FENCE:0)
Block(-6,35,-1,LOG:1)
Block(-6,35,8,SPRUCE_FENCE:0)
Block(-6,36,-3,WOOL:15)
Block(-6,36,-1,LOG:1)
Block(-6,37,-3,WOOL:15)
Block(-6,37,-1,LOG:1)
Block(-6,38,-3,WOOL:15)
Block(-6,38,-1,LOG:1)
Block(-6,38,0,SPRUCE_FENCE:0)
Block(-6,38,1,SPRUCE_FENCE:0)
Block(-6,38,2,SPRUCE_FENCE:0)
Block(-6,39,-2,WOOL:15)
Block(-6,39,-1,LOG:1)
Block(-6,39,2,SPRUCE_FENCE:0)
Block(-6,39,3,SPRUCE_FENCE:0)
Block(-6,39,4,SPRUCE_FENCE:0)
Block(-6,40,-1,LOG:1)
Block(-6,40,4,SPRUCE_FENCE:0)
Block(-6,40,5,SPRUCE_FENCE:0)
Block(-6,40,6,SPRUCE_FENCE:0)
Block(-6,41,-1,LOG:1)
Block(-6,41,6,SPRUCE_FENCE:0)
Block(-6,41,7,SPRUCE_FENCE:0)
Block(-6,41,8,SPRUCE_FENCE:0)
Block(-6,42,-1,LOG:1)
Block(-6,42,8,SPRUCE_FENCE:0)
Block(-6,43,-1,LOG:1)
Block(-6,44,-1,COBBLE_WALL:0)
Block(-6,45,-1,COBBLE_WALL:0)
Block(-6,46,-1,DARK_OAK_FENCE:0)
Block(-6,46,4,WOOL:15)
Block(-6,46,5,WOOL:15)
Block(-6,47,-1,DARK_OAK_FENCE:0)
Block(-6,47,0,WOOL:15)
Block(-6,48,-1,DARK_OAK_FENCE:0)
RandomBlock(-6,49,-1,STANDING_BANNER:7,../../Banners/skullpillager_01.nbt,20,STANDING_BANNER:7,../../Banners/skullpillager_02.nbt,20,STANDING_BANNER:7,../../Banners/skullpillager_03.nbt,20,STANDING_BANNER:7,../../Banners/skullpillager_04.nbt,20,STANDING_BANNER:7,../../Banners/skullpillager_05.nbt,100)
Block(-5,2,3,LOG_2:13)
Block(-5,2,4,LOG_2:13)
Block(-5,2,5,LOG_2:13)
Block(-5,2,6,LOG_2:13)
Block(-5,2,7,LOG_2:13)
Block(-5,2,8,LOG_2:13)
Block(-5,3,-1,LOG_2:13)
Block(-5,3,0,LOG_2:13)
Block(-5,3,1,LOG_2:13)
Block(-5,3,2,LOG_2:13)
Block(-5,3,3,LOG_2:13)
Block(-5,3,4,LOG_2:13)
Block(-5,3,5,LOG_2:13)
Block(-5,3,6,LOG_2:13)
Block(-5,3,7,LOG_2:13)
Block(-5,3,8,AIR:0)
Block(-5,4,-3,LOG_2:13)
Block(-5,4,-2,LOG_2:13)
Block(-5,4,-1,WOOD:5)
Block(-5,4,0,WOOD:5)
Block(-5,4,1,HAY_BLOCK:0)
Block(-5,4,2,HAY_BLOCK:8)
Block(-5,4,3,AIR:0)
Block(-5,4,4,AIR:0)
Block(-5,4,5,AIR:0)
Block(-5,4,6,WOOD:5)
Block(-5,4,7,AIR:0)
Block(-5,4,8,AIR:0)
Block(-5,5,-4,LOG_2:13)
Block(-5,5,-3,AIR:0)
Block(-5,5,-2,AIR:0)
Block(-5,5,-1,LADDER:5)
Block(-5,5,0,WOOD:5)
Block(-5,5,1,AIR:0)
Block(-5,5,2,AIR:0)
Block(-5,5,3,AIR:0)
Block(-5,5,4,AIR:0)
Block(-5,5,5,AIR:0)
Block(-5,5,6,WOOD:5)
Block(-5,5,7,AIR:0)
Block(-5,5,8,AIR:0)
Block(-5,6,-5,LOG_2:13)
Block(-5,6,-4,WOOD:5)
Block(-5,6,-3,AIR:0)
Block(-5,6,-2,AIR:0)
Block(-5,6,-1,LADDER:5)
Block(-5,6,0,WOOD:5)
Block(-5,6,1,AIR:0)
Block(-5,6,2,AIR:0)
Block(-5,6,3,AIR:0)
Block(-5,6,4,AIR:0)
Block(-5,6,5,AIR:0)
Block(-5,6,6,WOOD:5)
Block(-5,6,7,AIR:0)
Block(-5,6,8,AIR:0)
Block(-5,7,-6,WOOD:5)
Block(-5,7,-5,WOOD:5)
Block(-5,7,-4,WOOD:5)
Block(-5,7,-3,WOOD:5)
Block(-5,7,-2,WOOD:5)
Block(-5,7,-1,LADDER:5)
Block(-5,7,0,WOOD:5)
Block(-5,7,1,WOOD:5)
Block(-5,7,2,TRAP_DOOR:11)
Block(-5,7,3,TRAP_DOOR:11)
Block(-5,7,4,TRAP_DOOR:11)
Block(-5,7,5,TRAP_DOOR:11)
Block(-5,7,6,WOOD_DOUBLE_STEP:1)
Block(-5,7,7,TRAP_DOOR:11)
Block(-5,7,8,TRAP_DOOR:11)
Block(-5,8,-7,WOOD:5)
Block(-5,8,-6,WOOD:5)
Block(-5,8,-5,LADDER:3)
Block(-5,8,-4,CARPET:12)
Block(-5,8,-3,CARPET:12)
Block(-5,8,-1,TRAP_DOOR:3)
Block(-5,8,0,STAINED_CLAY:9)
Block(-5,8,5,STONE_BUTTON:2)
Block(-5,8,6,STONE_BUTTON:2)
Block(-5,8,7,STONE_BUTTON:2)
Block(-5,9,-7,WOOD:5)
Block(-5,9,-6,WOOD:5)
Block(-5,9,-5,LADDER:3)
Block(-5,9,0,STAINED_CLAY:9)
Block(-5,10,-7,STAINED_CLAY:9)
Block(-5,10,-6,STAINED_CLAY:9)
Block(-5,10,-5,LADDER:3)
Block(-5,10,-4,WOOD_STEP:13)
Block(-5,10,-3,WOOD_STEP:13)
Block(-5,10,-2,WOOD_STEP:13)
Block(-5,10,-1,WOOD_STEP:13)
Block(-5,10,0,WOOD_DOUBLE_STEP:5)
Block(-5,10,1,WOOD_STEP:13)
Block(-5,10,2,WOOD_STEP:13)
Block(-5,11,-5,TRAP_DOOR:0)
Block(-5,11,-4,STAINED_CLAY:9)
Block(-5,11,-3,STAINED_CLAY:9)
Block(-5,11,-2,STAINED_CLAY:9)
Block(-5,11,-1,WOOD_STEP:1)
Block(-5,11,0,WOOD:2)
Block(-5,11,1,WOOD:2)
Block(-5,11,2,STONE_BUTTON:3)
Block(-5,11,3,TRAP_DOOR:3)
Block(-5,11,4,TRAP_DOOR:3)
Block(-5,11,5,TRAP_DOOR:3)
Block(-5,11,6,TRAP_DOOR:3)
Block(-5,11,7,TRAP_DOOR:3)
Block(-5,11,8,TRAP_DOOR:3)
Block(-5,12,-4,STAINED_CLAY:9)
Block(-5,12,0,STONE_BUTTON:1)
Block(-5,12,1,STONE_BUTTON:5)
Block(-5,13,-4,WOOD_STEP:5)
Block(-5,13,0,STONE_BUTTON:1)
Block(-5,15,-2,WOOL:15)
Block(-5,15,6,WOOL:15)
Block(-5,15,7,WOOL:15)
Block(-5,15,8,WOOL:15)
Block(-5,16,-2,WOOL:15)
Block(-5,16,4,WOOL:15)
Block(-5,16,5,WOOL:15)
Block(-5,16,6,WOOL:15)
Block(-5,17,-3,WOOL:15)
Block(-5,17,6,WOOL:15)
Block(-5,17,7,WOOL:15)
Block(-5,17,8,WOOL:15)
Block(-5,18,-3,WOOL:15)
Block(-5,18,8,WOOL:15)
Block(-5,19,-2,WOOL:15)
Block(-5,20,-2,WOOL:15)
Block(-5,20,-1,SPRUCE_FENCE:0)
Block(-5,20,0,SPRUCE_FENCE:0)
Block(-5,21,-2,WOOL:15)
Block(-5,21,-1,SPRUCE_FENCE:0)
Block(-5,22,-1,LOG:5)
Block(-5,23,-1,WOOD_STEP:13)
Block(-5,23,0,WOOD_STEP:13)
Block(-5,23,1,WOOD_STEP:13)
Block(-5,23,2,WOOL:15)
Block(-5,24,-1,SPRUCE_FENCE:0)
Block(-5,24,1,SPRUCE_FENCE:0)
Block(-5,24,3,WOOL:15)
Block(-5,24,4,WOOL:15)
Block(-5,25,-2,WOOL:15)
Block(-5,25,4,WOOL:15)
Block(-5,25,5,WOOL:15)
Block(-5,26,-7,WOOL:15)
Block(-5,26,-2,WOOL:15)
Block(-5,26,5,WOOL:15)
Block(-5,26,6,WOOL:15)
Block(-5,26,7,WOOL:15)
Block(-5,26,8,WOOL:15)
Block(-5,27,-7,WOOL:15)
Block(-5,27,-3,WOOL:15)
Block(-5,27,3,WOOL:15)
Block(-5,27,7,WOOL:15)
Block(-5,27,8,WOOL:15)
Block(-5,28,-3,WOOL:15)
Block(-5,28,3,WOOL:15)
Block(-5,29,-3,WOOL:15)
Block(-5,29,3,WOOL:15)
Block(-5,29,4,WOOL:15)
Block(-5,30,-3,WOOL:15)
Block(-5,30,4,WOOL:15)
Block(-5,30,5,WOOL:15)
Block(-5,30,6,WOOL:15)
Block(-5,31,-3,WOOL:15)
Block(-5,31,-1,SPRUCE_FENCE:0)
Block(-5,31,0,SPRUCE_FENCE:0)
Block(-5,31,6,WOOL:15)
Block(-5,31,7,WOOL:15)
Block(-5,31,8,WOOL:15)
Block(-5,32,-2,WOOL:15)
Block(-5,32,-1,SPRUCE_FENCE:0)
Block(-5,32,8,WOOL:15)
Block(-5,33,-1,SPRUCE_FENCE:0)
Block(-5,34,-1,LOG:5)
Block(-5,36,-2,WOOL:15)
Block(-5,37,-3,WOOL:15)
Block(-5,38,-2,WOOL:15)
Block(-5,39,-2,WOOL:15)
Block(-5,40,-1,SPRUCE_FENCE:0)
Block(-5,41,-1,LOG:5)
Block(-5,47,1,WOOL:15)
Block(-5,47,2,WOOL:15)
Block(-5,47,3,WOOL:15)
Block(-4,3,2,LOG_2:13)
Block(-4,3,3,LOG_2:13)
Block(-4,3,4,LOG_2:13)
Block(-4,3,5,LOG_2:13)
Block(-4,3,6,LOG_2:13)
Block(-4,3,7,LOG_2:13)
Block(-4,3,8,LOG_2:13)
Block(-4,4,-2,LOG_2:13)
Block(-4,4,-1,LOG_2:13)
Block(-4,4,0,LOG_2:13)
Block(-4,4,1,LOG_2:13)
Block(-4,4,2,HAY_BLOCK:8)
Block(-4,4,3,AIR:0)
Block(-4,4,4,AIR:0)
Block(-4,4,5,HAY_BLOCK:4)
Block(-4,4,6,WOOD:5)
Block(-4,4,7,COAL_ORE:0)
Block(-4,4,8,AIR:0)
Block(-4,5,-3,LOG_2:13)
Block(-4,5,-2,AIR:0)
Block(-4,5,-1,AIR:0)
Block(-4,5,0,WOOD:5)
Block(-4,5,1,HAY_BLOCK:0)
Block(-4,5,2,AIR:0)
Block(-4,5,3,AIR:0)
Block(-4,5,4,AIR:0)
Block(-4,5,5,AIR:0)
Block(-4,5,6,WOOD:5)
Block(-4,5,7,AIR:0)
Block(-4,5,8,AIR:0)
Block(-4,6,-5,LOG_2:13)
Block(-4,6,-4,LOG_2:13)
Block(-4,6,-3,WOOD:5)
Block(-4,6,-2,AIR:0)
Block(-4,6,-1,AIR:0)
Block(-4,6,0,WOOD:5)
Block(-4,6,1,AIR:0)
Block(-4,6,2,AIR:0)
Block(-4,6,3,AIR:0)
Block(-4,6,4,AIR:0)
Block(-4,6,5,AIR:0)
Block(-4,6,6,WOOD:5)
Block(-4,6,7,AIR:0)
Block(-4,6,8,AIR:0)
Block(-4,7,-5,WOOD:5)
Block(-4,7,-4,WOOD:5)
Block(-4,7,-3,WOOD:5)
Block(-4,7,-2,WOOD:5)
Block(-4,7,-1,WOOD:5)
Block(-4,7,0,WOOD:5)
Block(-4,7,1,WOOD:5)
Block(-4,7,2,WOOD:5)
Block(-4,7,3,WOOD:5)
Block(-4,7,4,WOOD:5)
Block(-4,7,5,WOOD:5)
Block(-4,7,6,WOOD:5)
Block(-4,7,7,WOOD:5)
Block(-4,7,8,WOOD:5)
Block(-4,8,-6,WOOD:5)
Block(-4,8,-5,WOOD:5)
Block(-4,8,-4,CARPET:13)
Block(-4,8,-2,CARPET:12)
Block(-4,8,-1,CARPET:13)
Block(-4,8,0,DARK_OAK_DOOR:4)
Block(-4,8,2,BED_BLOCK:9)
Block(-4,8,3,CARPET:12)
Block(-4,8,4,STONE_BUTTON:4)
Block(-4,8,5,WOOD:2)
Block(-4,8,6,WOOD:2)
Block(-4,8,7,WOOD:2)
Block(-4,8,8,STONE_BUTTON:3)
Block(-4,9,-7,WOOD:5)
Block(-4,9,-6,WOOD:5)
Block(-4,9,-5,WOOD:5)
Block(-4,9,0,DARK_OAK_DOOR:8)
Block(-4,9,5,STONE_BUTTON:5)
Block(-4,9,6,STONE_BUTTON:5)
Block(-4,9,7,STONE_BUTTON:5)
Block(-4,10,-7,STAINED_CLAY:9)
Block(-4,10,-6,STAINED_CLAY:9)
Block(-4,10,-5,STAINED_CLAY:9)
Block(-4,10,-4,WOOD_STEP:13)
Block(-4,10,-3,WOOD_STEP:13)
Block(-4,10,-2,WOOD_STEP:13)
Block(-4,10,-1,WOOD_STEP:13)
Block(-4,10,0,WOOD_DOUBLE_STEP:5)
Block(-4,10,1,WOOD_STEP:13)
Block(-4,10,2,WOOD_STEP:13)
Block(-4,10,3,WOOD_STEP:13)
Block(-4,10,4,WOOD_STEP:13)
Block(-4,10,5,WOOD_STEP:13)
Block(-4,10,6,WOOD_STEP:13)
Block(-4,10,7,WOOD_STEP:13)
Block(-4,10,8,WOOD_STEP:13)
Block(-4,11,-5,LADDER:2)
Block(-4,11,-4,STAINED_CLAY:9)
Block(-4,11,-3,STAINED_CLAY:9)
Block(-4,11,-2,STAINED_CLAY:9)
Block(-4,11,-1,WOOD_STEP:1)
Block(-4,11,0,STONE_BUTTON:1)
Block(-4,11,1,WOOD:2)
Block(-4,11,2,STONE_BUTTON:3)
Block(-4,11,6,STONE_BUTTON:2)
Block(-4,11,7,STONE_BUTTON:2)
Block(-4,11,8,STONE_BUTTON:2)
Block(-4,12,-5,LADDER:2)
Block(-4,12,-4,STAINED_CLAY:9)
Block(-4,12,-3,SPRUCE_WOOD_STAIRS:3)
Block(-4,12,1,STONE_BUTTON:5)
Block(-4,15,-1,WOOL:15)
Block(-4,16,-2,WOOL:15)
Block(-4,16,7,WOOL:15)
Block(-4,16,8,WOOL:15)
Block(-4,17,-2,WOOL:15)
Block(-4,18,-2,WOOL:15)
Block(-4,19,-2,WOOL:15)
Block(-4,19,-1,SPRUCE_FENCE:0)
Block(-4,19,0,SPRUCE_FENCE:0)
Block(-4,20,-2,WOOL:15)
Block(-4,20,-1,SPRUCE_FENCE:0)
Block(-4,20,0,SPRUCE_FENCE:0)
Block(-4,21,-1,WOOL:15)
Block(-4,21,0,SPRUCE_FENCE:0)
Block(-4,22,0,LOG:5)
Block(-4,23,-1,WOOD_STEP:13)
Block(-4,23,0,WOOD_STEP:13)
Block(-4,23,1,WOOD_STEP:13)
Block(-4,24,-1,SPRUCE_FENCE:0)
Block(-4,24,0,SPRUCE_FENCE:0)
Block(-4,24,1,SPRUCE_FENCE:0)
Block(-4,24,2,WOOL:15)
Block(-4,25,-2,WOOL:15)
Block(-4,25,-1,SPRUCE_FENCE:0)
Block(-4,25,0,SPRUCE_FENCE:0)
Block(-4,25,1,SPRUCE_FENCE:0)
Block(-4,25,2,WOOL:15)
Block(-4,25,3,WOOL:15)
Block(-4,26,-2,WOOL:15)
Block(-4,26,-1,SPRUCE_FENCE:0)
Block(-4,26,0,SPRUCE_FENCE:0)
Block(-4,26,1,SPRUCE_FENCE:0)
Block(-4,26,3,WOOL:15)
Block(-4,26,4,WOOL:15)
Block(-4,27,-2,WOOL:15)
Block(-4,27,-1,SPRUCE_FENCE:0)
Block(-4,27,0,SPRUCE_FENCE:0)
Block(-4,27,1,SPRUCE_FENCE:0)
Block(-4,27,4,WOOL:15)
Block(-4,27,5,WOOL:15)
Block(-4,27,6,WOOL:15)
Block(-4,28,-3,WOOL:15)
Block(-4,28,-1,SPRUCE_FENCE:0)
Block(-4,28,0,SPRUCE_FENCE:0)
Block(-4,28,1,SPRUCE_FENCE:0)
Block(-4,28,4,WOOL:15)
Block(-4,28,5,WOOL:15)
Block(-4,28,6,WOOL:15)
Block(-4,28,7,WOOL:15)
Block(-4,28,8,WOOL:15)
Block(-4,29,-3,WOOL:15)
Block(-4,29,-1,SPRUCE_FENCE:0)
Block(-4,29,0,SPRUCE_FENCE:0)
Block(-4,29,5,WOOL:15)
Block(-4,29,6,WOOL:15)
Block(-4,29,7,WOOL:15)
Block(-4,29,8,WOOL:15)
Block(-4,30,-3,WOOL:15)
Block(-4,30,-1,SPRUCE_FENCE:0)
Block(-4,30,0,SPRUCE_FENCE:0)
Block(-4,30,7,WOOL:15)
Block(-4,30,8,WOOL:15)
Block(-4,31,-2,WOOL:15)
Block(-4,31,-1,SPRUCE_FENCE:0)
Block(-4,31,0,SPRUCE_FENCE:0)
Block(-4,32,-2,WOOL:15)
Block(-4,33,-1,SPRUCE_FENCE:0)
Block(-4,34,-1,LOG:5)
Block(-4,36,-2,WOOL:15)
Block(-4,37,-2,WOOL:15)
Block(-4,38,-2,WOOL:15)
Block(-4,39,-2,WOOL:15)
Block(-4,40,0,SPRUCE_FENCE:0)
Block(-4,41,0,LOG:5)
Block(-3,3,6,LOG_2:13)
Block(-3,3,7,LOG_2:13)
Block(-3,3,8,LOG_2:13)
Block(-3,4,0,LOG_2:13)
Block(-3,4,1,LOG_2:13)
Block(-3,4,2,LOG_2:13)
Block(-3,4,3,LOG_2:13)
Block(-3,4,4,LOG_2:13)
Block(-3,4,5,LOG_2:13)
Block(-3,4,6,WOOD:5)
Block(-3,4,7,COAL_ORE:0)
Block(-3,4,8,IRON_ORE:0)
Block(-3,5,-2,LOG_2:13)
Block(-3,5,-1,LOG_2:13)
Block(-3,5,0,WOOD:5)
Block(-3,5,1,HAY_BLOCK:4)
Block(-3,5,2,AIR:0)
Block(-3,5,3,AIR:0)
Block(-3,5,4,AIR:0)
Block(-3,5,5,AIR:0)
Block(-3,5,6,WOOD:5)
Block(-3,5,7,COAL_ORE:0)
Block(-3,5,8,AIR:0)
Block(-3,6,-4,LOG_2:13)
Block(-3,6,-3,LOG_2:13)
Block(-3,6,-2,WOOD:5)
Block(-3,6,-1,WOOD:5)
Block(-3,6,0,WOOD:5)
Block(-3,6,1,HAY_BLOCK:8)
Block(-3,6,2,AIR:0)
Block(-3,6,3,AIR:0)
Block(-3,6,4,AIR:0)
Block(-3,6,5,AIR:0)
Block(-3,6,6,WOOD:5)
Block(-3,6,7,AIR:0)
Block(-3,6,8,AIR:0)
Block(-3,7,-5,WOOD:5)
Block(-3,7,-4,WOOD:5)
Block(-3,7,-3,WOOD:5)
Block(-3,7,-2,WOOD:5)
Block(-3,7,-1,WOOD:5)
Block(-3,7,0,WOOD:5)
Block(-3,7,1,WOOD:5)
Block(-3,7,2,WOOD:5)
Block(-3,7,3,WOOD:5)
Block(-3,7,4,WOOD:5)
Block(-3,7,5,WOOD:5)
Block(-3,7,6,WOOD:5)
Block(-3,7,7,WOOD:5)
Block(-3,7,8,WOOD:5)
Block(-3,8,-5,WOOD:5)
Block(-3,8,-4,WOOD:5)
Block(-3,8,-1,CARPET:12)
Block(-3,8,0,STAINED_CLAY:9)
Block(-3,8,1,CARPET:13)
Block(-3,8,2,BED_BLOCK:1)
Block(-3,8,3,CARPET:12)
Block(-3,8,4,CARPET:12)
Block(-3,8,5,STONE_BUTTON:1)
Block(-3,8,6,STONE_BUTTON:1)
Block(-3,8,7,STONE_BUTTON:1)
Block(-3,8,8,CARPET:12)
Block(-3,9,-7,WOOD_BUTTON:1)
Block(-3,9,-6,WOOD_BUTTON:1)
Block(-3,9,-5,WOOD:5)
Block(-3,9,-4,WOOD:5)
Block(-3,9,0,STAINED_CLAY:9)
Block(-3,10,-6,STAINED_CLAY:9)
Block(-3,10,-5,STAINED_CLAY:9)
Block(-3,10,-4,STAINED_CLAY:9)
Block(-3,10,-3,WOOD_STEP:13)
Block(-3,10,-2,WOOD_STEP:13)
Block(-3,10,-1,WOOD_STEP:13)
Block(-3,10,0,WOOD_DOUBLE_STEP:5)
Block(-3,10,1,WOOD_STEP:13)
Block(-3,10,2,WOOD_STEP:13)
Block(-3,10,3,WOOD_STEP:13)
Block(-3,10,4,WOOD_STEP:13)
Block(-3,10,5,WOOD_STEP:13)
Block(-3,10,6,WOOD_STEP:13)
Block(-3,10,7,WOOD_STEP:13)
Block(-3,10,8,WOOD_STEP:13)
Block(-3,11,-7,WOOD_STEP:5)
Block(-3,11,-6,WOOD_STEP:5)
Block(-3,11,-5,WOOD_STEP:13)
Block(-3,11,-4,STAINED_CLAY:9)
Block(-3,11,-3,STAINED_CLAY:9)
Block(-3,11,-2,STAINED_CLAY:9)
Block(-3,11,-1,WOOD_STEP:1)
Block(-3,11,1,STONE_BUTTON:1)
Block(-3,11,5,STONE_BUTTON:4)
Block(-3,11,6,WOOD:2)
Block(-3,11,7,WOOD:2)
Block(-3,11,8,WOOD:2)
Block(-3,12,-7,WOOD_STEP:5)
Block(-3,12,-6,WOOD_STEP:13)
Block(-3,12,-5,DARK_OAK_STAIRS:6)
Block(-3,12,-4,STAINED_CLAY:9)
Block(-3,12,4,AIR:0)
Block(-3,12,6,STONE_BUTTON:5)
Block(-3,12,7,STONE_BUTTON:5)
Block(-3,12,8,STONE_BUTTON:5)
Block(-3,13,-4,WOOD_STEP:5)
Block(-3,14,-1,WOOL:15)
Block(-3,15,-1,WOOL:15)
Block(-3,16,-2,WOOL:15)
Block(-3,17,-2,WOOL:15)
Block(-3,17,-1,SPRUCE_FENCE:0)
Block(-3,17,0,SPRUCE_FENCE:0)
Block(-3,18,-2,WOOL:15)
Block(-3,18,-1,SPRUCE_FENCE:0)
Block(-3,18,0,SPRUCE_FENCE:0)
Block(-3,19,-2,WOOL:15)
Block(-3,19,-1,SPRUCE_FENCE:0)
Block(-3,19,0,SPRUCE_FENCE:0)
Block(-3,20,-1,WOOL:15)
Block(-3,21,-1,WOOL:15)
Block(-3,21,0,SPRUCE_FENCE:0)
Block(-3,22,0,LOG:5)
Block(-3,25,-1,WOOL:15)
Block(-3,26,-2,WOOL:15)
Block(-3,27,-2,WOOL:15)
Block(-3,28,-2,WOOL:15)
Block(-3,29,-3,WOOL:15)
Block(-3,30,-2,WOOL:15)
Block(-3,31,-2,WOOL:15)
Block(-3,32,-2,WOOL:15)
Block(-3,33,-1,WOOL:15)
Block(-3,33,0,SPRUCE_FENCE:0)
Block(-3,34,0,LOG:5)
Block(-3,35,-1,WOOL:15)
Block(-3,36,-2,WOOL:15)
Block(-3,37,-2,WOOL:15)
Block(-3,38,-2,WOOL:15)
Block(-3,39,-1,WOOL:15)
Block(-3,40,-1,WOOL:15)
Block(-3,40,0,SPRUCE_FENCE:0)
Block(-3,41,0,LOG:5)
Block(-2,4,2,LOG_2:13)
Block(-2,4,3,LOG_2:13)
Block(-2,4,4,LOG_2:13)
Block(-2,4,5,LOG_2:13)
Block(-2,4,6,LOG_2:13)
Block(-2,4,7,LOG_2:13)
Block(-2,4,8,LOG_2:13)
Block(-2,5,-1,LOG_2:13)
Block(-2,5,0,LOG_2:13)
Block(-2,5,1,LOG_2:13)
Block(-2,5,2,HAY_BLOCK:8)
Block(-2,5,3,HAY_BLOCK:0)
Block(-2,5,4,HAY_BLOCK:4)
Block(-2,5,5,HAY_BLOCK:0)
Block(-2,5,6,WOOD:5)
Block(-2,5,7,STONE:3)
Block(-2,5,8,COAL_ORE:0)
Block(-2,6,-3,LOG_2:13)
Block(-2,6,-2,LOG_2:13)
Block(-2,6,-1,WOOD:5)
Block(-2,6,0,WOOD:5)
Block(-2,6,1,HAY_BLOCK:8)
Block(-2,6,2,AIR:0)
Block(-2,6,3,AIR:0)
Block(-2,6,4,AIR:0)
Block(-2,6,5,AIR:0)
Block(-2,6,6,WOOD:5)
Block(-2,6,7,AIR:0)
Block(-2,6,8,AIR:0)
Block(-2,7,-3,WOOD:5)
Block(-2,7,-2,WOOD:5)
Block(-2,7,-1,WOOD:5)
Block(-2,7,0,WOOD:5)
Block(-2,7,1,WOOD:5)
Block(-2,7,2,WOOD:5)
Block(-2,7,3,WOOD:5)
Block(-2,7,4,WOOD:5)
Block(-2,7,5,WOOD:5)
Block(-2,7,6,WOOD:5)
Block(-2,7,7,WOOD:5)
Block(-2,7,8,WOOD:5)
Block(-2,8,-4,WOOD:5)
Block(-2,8,-3,WOOD:5)
Block(-2,8,-2,BED_BLOCK:10)
Block(-2,8,-1,BED_BLOCK:2)
Block(-2,8,0,STAINED_CLAY:9)
Block(-2,8,1,TRIPWIRE:0)
Block(-2,8,2,DARK_OAK_STAIRS:0)
Block(-2,8,4,CARPET:13)
Block(-2,8,6,BED_BLOCK:0)
Block(-2,8,7,BED_BLOCK:8)
Block(-2,8,8,CARPET:12)
Block(-2,9,-5,WOOD_BUTTON:1)
Block(-2,9,-4,WOOD:5)
Block(-2,9,-3,WOOD:5)
Block(-2,9,-2,BED_BLOCK:0)
Block(-2,9,-1,BED_BLOCK:8)
Block(-2,9,0,STAINED_CLAY:9)
Block(-2,9,5,AIR:0)
Block(-2,10,-3,STAINED_CLAY:9)
Block(-2,10,-2,WOOD_STEP:13)
Block(-2,10,-1,WOOD_STEP:13)
Block(-2,10,0,WOOD_DOUBLE_STEP:5)
Block(-2,10,1,WOOD_STEP:13)
Block(-2,10,2,WOOD_STEP:13)
Block(-2,10,3,WOOD_STEP:13)
Block(-2,10,4,WOOD_STEP:13)
Block(-2,10,5,WOOD_STEP:13)
Block(-2,10,6,WOOD_STEP:13)
Block(-2,10,7,WOOD_STEP:13)
Block(-2,10,8,WOOD_STEP:13)
Block(-2,11,-3,STAINED_CLAY:9)
Block(-2,11,-2,STAINED_CLAY:9)
Block(-2,11,-1,WOOD_STEP:1)
Block(-2,11,3,SPRUCE_WOOD_STAIRS:0)
Block(-2,11,6,STONE_BUTTON:1)
Block(-2,11,7,STONE_BUTTON:1)
Block(-2,11,8,STONE_BUTTON:1)
Block(-2,12,-3,STAINED_CLAY:9)
Block(-2,12,-2,STAINED_CLAY:9)
Block(-2,13,-3,WOOD_STEP:5)
Block(-2,13,-2,WOOD_STEP:5)
Block(-2,14,-1,WOOL:15)
Block(-2,15,-1,WOOL:15)
Block(-2,15,0,SPRUCE_FENCE:0)
Block(-2,15,1,SPRUCE_FENCE:0)
Block(-2,16,-1,WOOL:15)
Block(-2,16,0,SPRUCE_FENCE:0)
Block(-2,16,1,SPRUCE_FENCE:0)
Block(-2,17,-2,WOOL:15)
Block(-2,17,-1,SPRUCE_FENCE:0)
Block(-2,17,0,SPRUCE_FENCE:0)
Block(-2,17,1,SPRUCE_FENCE:0)
Block(-2,18,-2,WOOL:15)
Block(-2,19,-1,WOOL:15)
Block(-2,20,-1,WOOL:15)
Block(-2,21,-1,WOOL:15)
Block(-2,21,0,SPRUCE_FENCE:0)
Block(-2,22,0,LOG:5)
Block(-2,24,-1,WOOL:15)
Block(-2,25,-1,WOOL:15)
Block(-2,26,-1,WOOL:15)
Block(-2,27,-2,WOOL:15)
Block(-2,28,-2,WOOL:15)
Block(-2,29,-2,WOOL:15)
Block(-2,30,-2,WOOL:15)
Block(-2,31,-2,WOOL:15)
Block(-2,32,-1,WOOL:15)
Block(-2,33,-1,WOOL:15)
Block(-2,33,0,SPRUCE_FENCE:0)
Block(-2,34,0,LOG:5)
Block(-2,35,-1,WOOL:15)
Block(-2,36,-1,WOOL:15)
Block(-2,37,-2,WOOL:15)
Block(-2,38,-1,WOOL:15)
Block(-2,39,-1,WOOL:15)
Block(-2,40,-1,WOOL:15)
Block(-2,40,0,SPRUCE_FENCE:0)
Block(-2,41,0,LOG:5)
Block(-1,4,5,LOG_2:13)
Block(-1,4,6,LOG_2:13)
Block(-1,4,7,LOG_2:13)
Block(-1,4,8,LOG_2:13)
Block(-1,5,1,LOG_2:13)
Block(-1,5,2,LOG_2:13)
Block(-1,5,3,LOG_2:13)
Block(-1,5,4,LOG_2:13)
Block(-1,5,5,HAY_BLOCK:4)
Block(-1,5,6,WOOD:5)
Block(-1,5,7,STONE:3)
Block(-1,5,8,STONE:3)
Block(-1,6,-1,LOG_2:13)
Block(-1,6,0,LOG_2:13)
Block(-1,6,1,LOG_2:13)
Block(-1,6,2,AIR:0)
Block(-1,6,3,AIR:0)
Block(-1,6,4,AIR:0)
Block(-1,6,5,AIR:0)
Block(-1,6,6,WOOD:5)
Block(-1,6,7,STONE:3)
Block(-1,6,8,AIR:0)
Block(-1,7,-2,WOOD:5)
Block(-1,7,-1,WOOD:5)
Block(-1,7,0,WOOD:5)
Block(-1,7,1,WOOD:5)
Block(-1,7,2,WOOD:5)
Block(-1,7,3,WOOD:5)
Block(-1,7,4,WOOD:5)
Block(-1,7,5,WOOD:5)
Block(-1,7,6,WOOD:5)
Block(-1,7,7,WOOD:5)
Block(-1,7,8,WOOD:5)
Block(-1,8,-2,WOOD:5)
Block(-1,8,-1,WOOD:5)
Block(-1,8,0,STAINED_CLAY:9)
Block(-1,8,1,TRIPWIRE_HOOK:1)
Block(-1,8,2,CONCRETE:15)
Block(-1,8,3,STONE_BUTTON:3)
Block(-1,8,4,TRIPWIRE:0)
Block(-1,8,5,DARK_OAK_STAIRS:0)
Block(-1,8,7,TRIPWIRE:0)
Block(-1,8,8,DARK_OAK_STAIRS:0)
Block(-1,9,-4,WOOD_BUTTON:1)
Block(-1,9,-3,WOOD_BUTTON:1)
Block(-1,9,-2,WOOD:5)
Block(-1,9,-1,WOOD:5)
Block(-1,9,0,STAINED_CLAY:9)
Block(-1,9,1,WOOD_STEP:5)
Block(-1,9,2,WOOD_BUTTON:5)
Block(-1,9,3,WOOD_STEP:5)
Block(-1,10,-2,STAINED_CLAY:9)
Block(-1,10,-1,STAINED_CLAY:9)
Block(-1,10,0,STAINED_CLAY:9)
Block(-1,10,1,WOOD_STEP:13)
Block(-1,10,2,WOOD_STEP:13)
Block(-1,10,3,WOOD_STEP:13)
Block(-1,10,4,WOOD_STEP:13)
Block(-1,10,5,WOOD_STEP:13)
Block(-1,10,6,WOOD_STEP:13)
Block(-1,10,7,WOOD_STEP:13)
Block(-1,10,8,WOOD_STEP:13)
Block(-1,11,-1,STAINED_CLAY:9)
Block(-1,11,0,STAINED_CLAY:9)
Block(-1,11,2,WOOD_BUTTON:4)
Block(-1,11,3,DISPENSER:9)
Block(-1,11,4,WOOD_BUTTON:3)
Block(-1,11,7,SPRUCE_WOOD_STAIRS:0)
Block(-1,12,-1,WOOD_STEP:5)
Block(-1,12,0,WOOD_STEP:5)
Block(-1,12,3,LEVER:14)
Block(-1,13,-1,SPRUCE_FENCE:0)
Block(-1,13,0,SPRUCE_FENCE:0)
Block(-1,13,1,SPRUCE_FENCE:0)
Block(-1,13,2,SPRUCE_FENCE:0)
Block(-1,14,0,WOOL:15)
Block(-1,14,1,SPRUCE_FENCE:0)
Block(-1,15,-1,WOOL:15)
Block(-1,15,0,SPRUCE_FENCE:0)
Block(-1,15,1,SPRUCE_FENCE:0)
Block(-1,16,-1,WOOL:15)
Block(-1,17,-1,WOOL:15)
Block(-1,18,-1,WOOL:15)
Block(-1,19,-1,WOOL:15)
Block(-1,20,-1,WOOL:15)
Block(-1,21,0,WOOL:15)
Block(-1,21,1,SPRUCE_FENCE:0)
Block(-1,22,1,LOG:5)
Block(-1,24,-1,WOOL:15)
Block(-1,25,-1,WOOL:15)
Block(-1,26,-1,WOOL:15)
Block(-1,27,-1,WOOL:15)
Block(-1,28,-2,WOOL:15)
Block(-1,29,-2,WOOL:15)
Block(-1,30,-2,WOOL:15)
Block(-1,31,-1,WOOL:15)
Block(-1,32,-1,WOOL:15)
Block(-1,33,0,WOOL:15)
Block(-1,34,0,LOG:5)
Block(-1,35,-1,WOOL:15)
Block(-1,36,-1,WOOL:15)
Block(-1,37,-1,WOOL:15)
Block(-1,38,-1,WOOL:15)
Block(-1,41,0,WOOL:15)
Block(-1,41,1,WOOL:15)
Block(0,5,5,LOG_2:13)
Block(0,5,6,LOG_2:13)
Block(0,5,7,LOG_2:13)
Block(0,5,8,LOG_2:13)
Block(0,6,2,LOG_2:13)
Block(0,6,3,LOG_2:13)
Block(0,6,4,LOG_2:13)
Block(0,6,5,LOG_2:13)
Block(0,6,6,LOG_2:13)
Block(0,6,7,LOG_2:13)
Block(0,6,8,LOG_2:13)
Block(0,7,1,WOOD:5)
Block(0,7,2,WOOD:5)
Block(0,7,3,WOOD:5)
Block(0,7,4,WOOD:5)
Block(0,7,5,WOOD:5)
Block(0,7,6,WOOD:5)
Block(0,7,7,WOOD:5)
Block(0,7,8,WOOD:5)
Block(0,8,0,WOOD:5)
Block(0,8,1,WOOD:5)
Block(0,8,2,DISPENSER:5)
Block(0,8,3,WOOD:5)
Block(0,8,4,TRIPWIRE_HOOK:1)
Block(0,8,5,CONCRETE:15)
Block(0,8,6,STONE_BUTTON:3)
Block(0,8,7,TRIPWIRE_HOOK:1)
Block(0,8,8,CONCRETE:15)
Block(0,9,-2,WOOD_BUTTON:1)
Block(0,9,-1,WOOD_BUTTON:1)
Block(0,9,0,WOOD:5)
Block(0,9,1,WOOD:5)
Block(0,9,2,WOOD:5)
Block(0,9,3,WOOD:5)
Block(0,9,4,WOOD_STEP:5)
Block(0,9,5,WOOD_BUTTON:5)
Block(0,9,6,WOOD_STEP:5)
Block(0,9,7,WOOD_STEP:5)
Block(0,9,8,WOOD_BUTTON:5)
Block(0,10,-1,DARK_OAK_STAIRS:5)
Block(0,10,0,WOOD_STEP:13)
Block(0,10,1,STAINED_CLAY:9)
Block(0,10,2,STAINED_CLAY:9)
Block(0,10,3,STAINED_CLAY:9)
Block(0,10,4,STAINED_CLAY:9)
Block(0,10,5,WOOD_STEP:13)
Block(0,10,6,WOOD_STEP:13)
Block(0,10,7,WOOD_STEP:13)
Block(0,10,8,WOOD_STEP:13)
Block(0,11,-1,SPRUCE_FENCE:0)
Block(0,11,0,SPRUCE_FENCE:0)
Block(0,11,1,STAINED_CLAY:9)
Block(0,11,2,STAINED_CLAY:9)
Block(0,11,3,CONCRETE:15)
Block(0,11,4,STAINED_CLAY:9)
Block(0,11,5,STAINED_CLAY:9)
Block(0,11,6,WOOD_BUTTON:4)
Block(0,11,7,DISPENSER:9)
Block(0,11,8,WOOD_BUTTON:3)
Block(0,12,-1,SPRUCE_FENCE:0)
Block(0,12,0,SPRUCE_FENCE:0)
Block(0,12,1,SPRUCE_FENCE:0)
Block(0,12,2,SPRUCE_FENCE:0)
Block(0,12,4,WOOD_STEP:5)
Block(0,12,5,WOOD_STEP:5)
Block(0,12,7,LEVER:14)
Block(0,13,-1,SPRUCE_FENCE:0)
Block(0,13,0,SPRUCE_FENCE:0)
Block(0,13,1,SPRUCE_FENCE:0)
Block(0,13,2,SPRUCE_FENCE:0)
Block(0,14,0,WOOL:15)
Block(0,15,0,WOOL:15)
Block(0,16,-1,WOOL:15)
Block(0,17,-1,WOOL:15)
Block(0,18,-1,WOOL:15)
Block(0,19,-1,WOOL:15)
Block(0,20,0,WOOL:15)
Block(0,21,0,WOOL:15)
Block(0,21,1,SPRUCE_FENCE:0)
Block(0,22,1,LOG:5)
Block(0,24,0,WOOL:15)
Block(0,25,0,WOOL:15)
Block(0,26,-1,WOOL:15)
Block(0,27,-1,WOOL:15)
Block(0,28,-1,WOOL:15)
Block(0,29,-2,WOOL:15)
Block(0,30,-1,WOOL:15)
Block(0,31,-1,WOOL:15)
Block(0,32,0,WOOL:15)
Block(0,33,0,WOOL:15)
Block(0,33,1,SPRUCE_FENCE:0)
Block(0,34,1,LOG:5)
Block(0,35,0,WOOL:15)
Block(0,36,-1,WOOL:15)
Block(0,37,-1,WOOL:15)
Block(0,42,1,WOOL:15)
Block(0,42,2,WOOL:15)
Block(1,7,5,WOOD:5)
Block(1,7,6,WOOD:5)
Block(1,7,7,WOOD:5)
Block(1,7,8,WOOD:5)
Block(1,8,2,TRAP_DOOR:11)
Block(1,8,4,WOOD:5)
Block(1,8,5,DISPENSER:5)
Block(1,8,6,WOOD:5)
Block(1,8,7,WOOD:5)
Block(1,8,8,DISPENSER:5)
Block(1,9,0,WOOD_BUTTON:1)
Block(1,9,1,WOOD_BUTTON:1)
Block(1,9,2,WOOD_BUTTON:1)
Block(1,9,3,WOOD_BUTTON:1)
Block(1,9,4,WOOD:5)
Block(1,9,5,WOOD:5)
Block(1,9,6,WOOD:5)
Block(1,9,7,WOOD:5)
Block(1,9,8,WOOD:5)
Block(1,10,1,WOOD_STEP:13)
Block(1,10,2,DARK_OAK_STAIRS:5)
Block(1,10,5,STAINED_CLAY:9)
Block(1,10,6,STAINED_CLAY:9)
Block(1,10,7,STAINED_CLAY:9)
Block(1,10,8,STAINED_CLAY:9)
Block(1,11,1,SPRUCE_FENCE:0)
Block(1,11,2,SPRUCE_FENCE:0)
Block(1,11,3,DISPENSER:5)
Block(1,11,6,STAINED_CLAY:9)
Block(1,11,7,CONCRETE:15)
Block(1,11,8,STAINED_CLAY:9)
Block(1,12,1,SPRUCE_FENCE:0)
Block(1,12,2,SPRUCE_FENCE:0)
Block(1,12,6,WOOD_STEP:5)
Block(1,12,8,WOOD_STEP:5)
Block(1,13,0,WOOL:15)
Block(1,14,0,WOOL:15)
Block(1,15,0,WOOL:15)
Block(1,16,0,WOOL:15)
Block(1,17,-1,WOOL:15)
Block(1,18,-1,WOOL:15)
Block(1,19,0,WOOL:15)
Block(1,20,0,WOOL:15)
Block(1,21,0,WOOL:15)
Block(1,21,1,SPRUCE_FENCE:0)
Block(1,22,1,LOG:5)
Block(1,24,0,WOOL:15)
Block(1,25,0,WOOL:15)
Block(1,26,0,WOOL:15)
Block(1,27,-1,WOOL:15)
Block(1,28,-1,WOOL:15)
Block(1,29,-1,WOOL:15)
Block(1,30,-1,WOOL:15)
Block(1,31,0,WOOL:15)
Block(1,32,0,WOOL:15)
Block(1,33,0,WOOL:15)
Block(1,33,1,SPRUCE_FENCE:0)
Block(1,34,1,LOG:5)
Block(1,35,0,WOOL:15)
Block(1,36,0,WOOL:15)
Block(2,8,5,TRAP_DOOR:11)
Block(2,8,8,TRAP_DOOR:11)
Block(2,9,4,WOOD_BUTTON:1)
Block(2,9,5,WOOD_BUTTON:1)
Block(2,9,6,WOOD_BUTTON:1)
Block(2,9,7,WOOD_BUTTON:1)
Block(2,9,8,WOOD_BUTTON:1)
Block(2,11,7,DISPENSER:5)
Block(2,13,1,WOOL:15)
Block(2,14,1,WOOL:15)
Block(2,15,0,WOOL:15)
Block(2,16,0,WOOL:15)
Block(2,17,0,WOOL:15)
Block(2,18,0,WOOL:15)
Block(2,19,0,WOOL:15)
Block(2,20,0,WOOL:15)
Block(2,21,1,WOOL:15)
Block(2,21,2,SPRUCE_FENCE:0)
Block(2,22,2,LOG:5)
Block(2,23,1,WOOL:15)
Block(2,24,1,WOOL:15)
Block(2,25,0,WOOL:15)
Block(2,26,0,WOOL:15)
Block(2,27,0,WOOL:15)
Block(2,28,-1,WOOL:15)
Block(2,29,-1,WOOL:15)
Block(2,30,0,WOOL:15)
Block(2,31,0,WOOL:15)
Block(2,32,0,WOOL:15)
Block(2,33,1,WOOL:15)
Block(2,34,1,LOG:5)
Block(2,35,1,WOOL:15)
Block(3,13,2,WOOL:15)
Block(3,14,1,WOOL:15)
Block(3,15,1,WOOL:15)
Block(3,16,0,WOOL:15)
Block(3,17,0,WOOL:15)
Block(3,18,0,WOOL:15)
Block(3,19,0,WOOL:15)
Block(3,20,1,WOOL:15)
Block(3,21,2,WOOL:15)
Block(3,22,2,LOG:5)
Block(3,23,2,WOOL:15)
Block(3,24,1,WOOL:15)
Block(3,25,1,WOOL:15)
Block(3,26,0,WOOL:15)
Block(3,31,0,WOOL:15)
Block(3,32,1,WOOL:15)
Block(3,33,2,WOOL:15)
Block(3,33,3,WOOL:15)
Block(4,14,2,WOOL:15)
Block(4,14,3,WOOL:15)
Block(4,15,1,WOOL:15)
Block(4,15,4,WOOL:15)
Block(4,19,1,WOOL:15)
Block(4,20,2,WOOL:15)
Block(4,21,3,WOOL:15)
Block(4,22,2,LOG:5)
Block(4,23,2,WOOL:15)
Block(4,24,2,WOOL:15)
Block(4,33,3,WOOL:15)
Block(4,34,4,WOOL:15)
Block(5,21,4,WOOL:15)
Block(6,22,5,WOOL:15)
Branch(0,0,16,true,Pillager_FloatC1R2,NORTH,100.0,0)
Entity(-6,13,-3,minecraft:stray,1,../../NPCs/Pirate04.txt)
Entity(-3,12,4,minecraft:wither_skeleton,1,../../NPCs/Pirate02.txt)
Entity(-2,9,5,minecraft:stray,1,../../NPCs/Pirate04.txt)
