Author: NLBlackEagle
Description: No description given
SettingsMode: WriteDisable
Frequency: 0
SpawnHeight: highestBlock
UseCenterForHighestBlock: true
MinHeight: 0
MaxHeight: 255
InheritBO3: 
InheritBO3Rotation: NORTH
OverrideChildSettings: true
OverrideParentHeight: false
CanOverride: false
BranchFrequency: 0
BranchFrequencyGroup: 
MustBeBelowOther: false
MustBeInside: 
CannotBeInside: 
ReplacesBO3: 
MustBeInsideWorldBorders: false
CanSpawnOnWater: true
SpawnOnWaterOnly: false
SpawnUnderWater: false
SpawnAtWaterLevel: false
HeightOffset: 0
RemoveAir: false
ReplaceAbove: 
ReplaceBelow: 
ReplaceWithBiomeBlocks: false
ReplaceWithSurfaceBlock: GRASS
ReplaceWithGroundBlock: DIRT
ReplaceWithStoneBlock: STONE
SmoothRadius: 0
SmoothHeightOffset: 0
SmoothStartTop: false
SmoothStartWood: false
SmoothingSurfaceBlock: 
SmoothingGroundBlock: 
BO3Group: 
IsSpawnPoint: false
DoReplaceBlocks: false
Block(-3,24,-2,WOOL:15)
Block(-3,24,-1,WOOL:15)
Block(-3,36,-2,WOOL:15)
Block(-3,36,-1,WOOL:15)
Block(-2,10,-2,WOOL:15)
Block(-2,11,-2,WOOL:15)
Block(-2,23,-2,WOOL:15)
Block(-2,24,-2,WOOL:15)
Block(-2,34,-3,WOOL:15)
Block(-2,35,-2,WOOL:15)
Block(-2,36,-2,WOOL:15)
Block(-1,11,-3,WOOL:15)
Block(-1,11,-2,WOOL:15)
Block(-1,21,-4,WOOL:15)
Block(-1,22,-3,WOOL:15)
Block(-1,23,-3,WOOL:15)
Block(-1,33,-4,WOOL:15)
Block(-1,34,-4,WOOL:15)
Block(-1,35,-3,WOOL:15)
Block(0,12,-4,WOOL:15)
Block(0,12,-3,WOOL:15)
Block(0,13,-4,WOOL:15)
Block(0,14,-5,WOOL:15)
Block(0,15,-5,WOOL:15)
Block(0,20,-4,WOOL:15)
Block(0,21,-4,WOOL:15)
Block(0,22,-4,WOOL:15)
Block(0,31,-6,WOOL:15)
Block(0,32,-5,WOOL:15)
Block(0,33,-5,WOOL:15)
Block(0,34,-5,WOOL:15)
Block(0,35,-4,WOOL:15)
Block(1,12,-4,WOOL:15)
Block(1,13,-4,WOOL:15)
Block(1,14,-4,WOOL:15)
Block(1,15,-5,WOOL:15)
Block(1,16,-5,WOOL:15)
Block(1,19,-5,WOOL:15)
Block(1,20,-5,WOOL:15)
Block(1,21,-4,WOOL:15)
Block(1,21,-3,SPRUCE_FENCE:0)
Block(1,22,-3,LOG:5)
Block(1,23,-4,WOOL:15)
Block(1,24,-5,WOOL:15)
Block(1,25,-6,WOOL:15)
Block(1,26,-6,WOOL:15)
Block(1,30,-6,WOOL:15)
Block(1,31,-6,WOOL:15)
Block(1,32,-6,WOOL:15)
Block(1,33,-5,WOOL:15)
Block(1,34,-5,WOOL:15)
Block(1,35,-4,WOOL:15)
Block(2,8,-5,TRAP_DOOR:10)
Block(2,8,-2,TRAP_DOOR:10)
Block(2,9,-7,WOOD_BUTTON:2)
Block(2,9,-6,WOOD_BUTTON:2)
Block(2,9,-5,WOOD_BUTTON:2)
Block(2,9,-4,WOOD_BUTTON:2)
Block(2,9,-3,WOOD_BUTTON:2)
Block(2,9,-2,WOOD_BUTTON:2)
Block(2,9,-1,WOOD_BUTTON:2)
Block(2,9,0,WOOD_BUTTON:2)
Block(2,11,-6,DISPENSER:4)
Block(2,11,-3,DISPENSER:4)
Block(2,13,-4,WOOL:15)
Block(2,14,-4,WOOL:15)
Block(2,15,-4,WOOL:15)
Block(2,16,-5,WOOL:15)
Block(2,18,-5,WOOL:15)
Block(2,19,-5,WOOL:15)
Block(2,20,-4,WOOL:15)
Block(2,21,-4,WOOL:15)
Block(2,21,-3,SPRUCE_FENCE:0)
Block(2,22,-3,LOG:5)
Block(2,23,-4,WOOL:15)
Block(2,24,-5,WOOL:15)
Block(2,24,-4,WOOL:15)
Block(2,25,-6,WOOL:15)
Block(2,26,-6,WOOL:15)
Block(2,27,-7,WOOL:15)
Block(2,28,-7,WOOL:15)
Block(2,29,-7,WOOL:15)
Block(2,30,-6,WOOL:15)
Block(2,31,-6,WOOL:15)
Block(2,32,-5,WOOL:15)
Block(2,33,-5,WOOL:15)
Block(2,34,-4,WOOL:15)
Block(2,35,-4,WOOL:15)
Block(2,35,-3,SPRUCE_FENCE:0)
Block(2,36,-3,LOG:5)
Block(2,37,-3,WOOL:15)
Block(2,46,0,WOOL:15)
Block(2,46,1,WOOL:15)
Block(3,7,-7,WOOD:5)
Block(3,7,-6,WOOD:5)
Block(3,7,-5,WOOD:5)
Block(3,7,-4,WOOD:5)
Block(3,7,-3,WOOD:5)
Block(3,7,-2,WOOD:5)
Block(3,7,-1,WOOD:5)
Block(3,7,1,LADDER:4)
Block(3,8,-7,WOOD:5)
Block(3,8,-6,WOOD:5)
Block(3,8,-5,DISPENSER:4)
Block(3,8,-4,WOOD:5)
Block(3,8,-3,WOOD:5)
Block(3,8,-2,DISPENSER:4)
Block(3,8,-1,WOOD:5)
Block(3,8,0,WOOD:5)
Block(3,8,1,LADDER:4)
Block(3,8,2,TRAP_DOOR:10)
Block(3,8,5,TRAP_DOOR:10)
Block(3,8,8,TRAP_DOOR:10)
Block(3,9,-7,WOOD:5)
Block(3,9,-6,WOOD:5)
Block(3,9,-5,WOOD:5)
Block(3,9,-4,WOOD:5)
Block(3,9,-3,WOOD:5)
Block(3,9,-2,WOOD:5)
Block(3,9,-1,WOOD:5)
Block(3,9,0,WOOD:5)
Block(3,9,1,LADDER:4)
Block(3,9,2,WOOD_BUTTON:2)
Block(3,9,3,WOOD_BUTTON:2)
Block(3,9,4,WOOD_BUTTON:2)
Block(3,9,5,WOOD_BUTTON:2)
Block(3,9,6,WOOD_BUTTON:2)
Block(3,9,7,WOOD_BUTTON:2)
Block(3,9,8,WOOD_BUTTON:2)
Block(3,10,-7,STAINED_CLAY:9)
Block(3,10,-6,STAINED_CLAY:9)
Block(3,10,-5,STAINED_CLAY:9)
Block(3,10,-4,STAINED_CLAY:9)
Block(3,10,-3,STAINED_CLAY:9)
Block(3,10,-2,STAINED_CLAY:9)
Block(3,10,-1,STAINED_CLAY:9)
Block(3,10,1,LADDER:4)
Block(3,11,-7,STAINED_CLAY:9)
Block(3,11,-6,CONCRETE:15)
Block(3,11,-5,STAINED_CLAY:9)
Block(3,11,-4,STAINED_CLAY:9)
Block(3,11,-3,CONCRETE:15)
Block(3,11,-2,STAINED_CLAY:9)
Block(3,11,0,DISPENSER:4)
Block(3,11,1,LADDER:4)
Block(3,11,2,DARK_OAK_STAIRS:4)
Block(3,11,3,WOOD_STEP:13)
Block(3,11,4,WOOD_STEP:13)
Block(3,11,5,DARK_OAK_STAIRS:4)
Block(3,12,-7,WOOD_STEP:5)
Block(3,12,-5,WOOD_STEP:5)
Block(3,12,-4,WOOD_STEP:5)
Block(3,12,-2,WOOD_STEP:5)
Block(3,12,2,SPRUCE_FENCE:0)
Block(3,12,3,SPRUCE_FENCE:0)
Block(3,12,4,SPRUCE_FENCE:0)
Block(3,12,5,SPRUCE_FENCE:0)
Block(3,13,-3,WOOL:15)
Block(3,13,2,SPRUCE_FENCE:0)
Block(3,13,3,SPRUCE_FENCE:0)
Block(3,13,4,SPRUCE_FENCE:0)
Block(3,13,5,SPRUCE_FENCE:0)
Block(3,14,-4,WOOL:15)
Block(3,14,2,SPRUCE_FENCE:0)
Block(3,14,3,SPRUCE_FENCE:0)
Block(3,14,4,SPRUCE_FENCE:0)
Block(3,15,-4,WOOL:15)
Block(3,16,-5,WOOL:15)
Block(3,17,-5,WOOL:15)
Block(3,18,-5,WOOL:15)
Block(3,19,-4,WOOL:15)
Block(3,20,-4,WOOL:15)
Block(3,21,-4,WOOL:15)
Block(3,21,-3,SPRUCE_FENCE:0)
Block(3,22,-3,LOG:5)
Block(3,23,-4,WOOL:15)
Block(3,24,-5,WOOL:15)
Block(3,25,-5,WOOL:15)
Block(3,26,-6,WOOL:15)
Block(3,27,-6,WOOL:15)
Block(3,28,-7,WOOL:15)
Block(3,29,-6,WOOL:15)
Block(3,30,-6,WOOL:15)
Block(3,31,-5,WOOL:15)
Block(3,32,-5,WOOL:15)
Block(3,33,-4,WOOL:15)
Block(3,34,-4,WOOL:15)
Block(3,35,-4,WOOL:15)
Block(3,35,-3,SPRUCE_FENCE:0)
Block(3,36,-3,LOG:5)
Block(3,37,-4,WOOL:15)
Block(3,37,-3,WOOL:15)
Block(3,38,-4,WOOL:15)
Block(3,45,0,WOOL:15)
Block(3,46,0,WOOL:15)
Block(4,5,-7,LOG_2:13)
Block(4,5,-6,LOG_2:13)
Block(4,5,-5,LOG_2:13)
Block(4,5,-4,LOG_2:13)
Block(4,5,-3,LOG_2:13)
Block(4,5,-2,LOG_2:13)
Block(4,6,-7,LOG_2:13)
Block(4,6,-6,LOG_2:13)
Block(4,6,-5,LOG_2:13)
Block(4,6,-4,LOG_2:13)
Block(4,6,-3,LOG_2:13)
Block(4,6,-2,LOG_2:13)
Block(4,6,-1,LOG_2:13)
Block(4,6,0,LOG_2:13)
Block(4,6,1,LOG_2:13)
Block(4,6,2,LOG_2:13)
Block(4,6,3,LOG_2:13)
Block(4,6,4,LOG_2:13)
Block(4,6,5,LOG_2:13)
Block(4,7,-7,WOOD:5)
Block(4,7,-6,WOOD:5)
Block(4,7,-5,WOOD:5)
Block(4,7,-4,WOOD:5)
Block(4,7,-3,WOOD:5)
Block(4,7,-2,WOOD:5)
Block(4,7,-1,WOOD:5)
Block(4,7,0,WOOD:5)
Block(4,7,1,WOOD:5)
Block(4,7,2,WOOD:5)
Block(4,7,3,WOOD:5)
Block(4,7,4,WOOD:5)
Block(4,7,5,WOOD:5)
Block(4,7,6,WOOD:5)
Block(4,7,7,WOOD:5)
Block(4,7,8,WOOD:5)
Block(4,8,-7,STONE_BUTTON:3)
Block(4,8,-6,TRIPWIRE_HOOK:3)
Block(4,8,-5,CONCRETE:15)
Block(4,8,-4,STONE_BUTTON:3)
Block(4,8,-3,TRIPWIRE_HOOK:3)
Block(4,8,-2,CONCRETE:15)
Block(4,8,-1,STONE_BUTTON:3)
Block(4,8,0,STAINED_CLAY:9)
Block(4,8,1,WOOD:5)
Block(4,8,2,DISPENSER:4)
Block(4,8,3,WOOD:5)
Block(4,8,4,WOOD:5)
Block(4,8,5,DISPENSER:4)
Block(4,8,6,WOOD:5)
Block(4,8,7,WOOD:5)
Block(4,8,8,DISPENSER:4)
Block(4,9,-7,WOOD_STEP:5)
Block(4,9,-6,WOOD_STEP:5)
Block(4,9,-5,WOOD_BUTTON:5)
Block(4,9,-4,WOOD_STEP:5)
Block(4,9,-3,WOOD_STEP:5)
Block(4,9,-2,WOOD_BUTTON:5)
Block(4,9,-1,WOOD_STEP:5)
Block(4,9,0,STAINED_CLAY:9)
Block(4,9,1,WOOD:5)
Block(4,9,2,WOOD:5)
Block(4,9,3,WOOD:5)
Block(4,9,4,WOOD:5)
Block(4,9,5,WOOD:5)
Block(4,9,6,WOOD:5)
Block(4,9,7,WOOD:5)
Block(4,9,8,WOOD:5)
Block(4,10,-7,WOOD_STEP:13)
Block(4,10,-6,WOOD_STEP:13)
Block(4,10,-5,WOOD_STEP:13)
Block(4,10,-4,WOOD_STEP:13)
Block(4,10,-3,WOOD_STEP:13)
Block(4,10,-2,WOOD_STEP:13)
Block(4,10,-1,WOOD_STEP:13)
Block(4,10,0,STAINED_CLAY:9)
Block(4,10,1,STAINED_CLAY:9)
Block(4,10,2,STAINED_CLAY:9)
Block(4,10,3,STAINED_CLAY:9)
Block(4,10,4,STAINED_CLAY:9)
Block(4,10,5,STAINED_CLAY:9)
Block(4,10,6,STAINED_CLAY:9)
Block(4,10,7,STAINED_CLAY:9)
Block(4,10,8,STAINED_CLAY:9)
Block(4,11,-7,WOOD_BUTTON:4)
Block(4,11,-6,DISPENSER:1)
Block(4,11,-5,WOOD_BUTTON:3)
Block(4,11,-4,WOOD_BUTTON:4)
Block(4,11,-3,DISPENSER:1)
Block(4,11,-2,WOOD_BUTTON:3)
Block(4,11,-1,STAINED_CLAY:9)
Block(4,11,0,CONCRETE:15)
Block(4,11,1,STAINED_CLAY:9)
Block(4,11,2,STAINED_CLAY:9)
Block(4,11,3,STAINED_CLAY:9)
Block(4,11,4,STAINED_CLAY:9)
Block(4,11,5,STAINED_CLAY:9)
Block(4,11,6,STAINED_CLAY:9)
Block(4,11,7,STAINED_CLAY:9)
Block(4,11,8,DARK_OAK_STAIRS:3)
Block(4,12,-6,LEVER:6)
Block(4,12,-3,LEVER:6)
Block(4,12,-1,WOOD_STEP:5)
Block(4,12,1,WOOD_STEP:5)
Block(4,12,2,DARK_OAK_STAIRS:2)
Block(4,12,3,STAINED_CLAY:9)
Block(4,12,4,STAINED_CLAY:9)
Block(4,12,5,STAINED_CLAY:9)
Block(4,12,6,DARK_OAK_STAIRS:3)
Block(4,12,7,DARK_OAK_STAIRS:2)
Block(4,13,-3,WOOL:15)
Block(4,13,3,DARK_OAK_STAIRS:2)
Block(4,13,4,STAINED_CLAY:9)
Block(4,13,5,DARK_OAK_STAIRS:3)
Block(4,14,-3,WOOL:15)
Block(4,14,2,SPRUCE_FENCE:0)
Block(4,14,3,SPRUCE_FENCE:0)
Block(4,14,4,SPRUCE_FENCE:0)
Block(4,15,-4,WOOL:15)
Block(4,15,1,SPRUCE_FENCE:0)
Block(4,15,2,SPRUCE_FENCE:0)
Block(4,15,3,SPRUCE_FENCE:0)
Block(4,15,4,SPRUCE_FENCE:0)
Block(4,16,-4,WOOL:15)
Block(4,17,-5,WOOL:15)
Block(4,18,-4,WOOL:15)
Block(4,19,-4,WOOL:15)
Block(4,20,-4,WOOL:15)
Block(4,21,-3,WOOL:15)
Block(4,21,-2,SPRUCE_FENCE:0)
Block(4,22,-2,LOG:5)
Block(4,23,-3,WOOL:15)
Block(4,24,-4,WOOL:15)
Block(4,25,-5,WOOL:15)
Block(4,26,-5,WOOL:15)
Block(4,27,-6,WOOL:15)
Block(4,28,-6,WOOL:15)
Block(4,29,-6,WOOL:15)
Block(4,30,-5,WOOL:15)
Block(4,31,-5,WOOL:15)
Block(4,32,-5,WOOL:15)
Block(4,33,-4,WOOL:15)
Block(4,34,-4,WOOL:15)
Block(4,35,-3,WOOL:15)
Block(4,36,-3,LOG:5)
Block(4,37,-4,WOOL:15)
Block(4,38,-4,WOOL:15)
Block(4,39,-5,WOOL:15)
Block(4,40,-5,WOOL:15)
Block(4,44,-1,WOOL:15)
Block(4,45,-1,WOOL:15)
Block(5,4,-7,LOG_2:13)
Block(5,4,-6,LOG_2:13)
Block(5,4,-5,LOG_2:13)
Block(5,4,-4,LOG_2:13)
Block(5,4,-3,LOG_2:13)
Block(5,5,-7,STONE:1)
Block(5,5,-6,STONE:1)
Block(5,5,-5,STONE:1)
Block(5,5,-4,STONE:1)
Block(5,5,-3,WOOD:5)
Block(5,5,-2,LOG_2:13)
Block(5,5,-1,LOG_2:13)
Block(5,5,0,LOG_2:13)
Block(5,5,1,LOG_2:13)
Block(5,5,2,LOG_2:13)
Block(5,5,3,LOG_2:13)
Block(5,5,4,LOG_2:13)
Block(5,5,5,LOG_2:13)
Block(5,5,6,LOG_2:13)
Block(5,5,7,LOG_2:13)
Block(5,6,-7,AIR:0)
Block(5,6,-6,COAL_ORE:0)
Block(5,6,-5,STONE:1)
Block(5,6,-4,STONE:1)
Block(5,6,-3,WOOD:5)
Block(5,6,-2,AIR:0)
Block(5,6,-1,AIR:0)
Block(5,6,0,AIR:0)
Block(5,6,1,WOOD:5)
Block(5,6,2,TNT:0)
Block(5,6,3,AIR:0)
Block(5,6,4,TNT:0)
Block(5,6,5,WOOD:5)
Block(5,6,6,LOG_2:13)
Block(5,6,7,LOG_2:13)
Block(5,6,8,LOG_2:13)
Block(5,7,-7,WOOD:5)
Block(5,7,-6,WOOD:5)
Block(5,7,-5,WOOD:5)
Block(5,7,-4,WOOD:5)
Block(5,7,-3,WOOD:5)
Block(5,7,-2,WOOD:5)
Block(5,7,-1,WOOD:5)
Block(5,7,0,WOOD:5)
Block(5,7,1,WOOD:5)
Block(5,7,2,WOOD:5)
Block(5,7,3,WOOD:5)
Block(5,7,4,WOOD:5)
Block(5,7,5,WOOD:5)
Block(5,7,6,WOOD:5)
Block(5,7,7,WOOD:5)
Block(5,7,8,WOOD:5)
Block(5,8,-6,TRIPWIRE:0)
Block(5,8,-5,DARK_OAK_STAIRS:1)
Block(5,8,-3,TRIPWIRE:0)
Block(5,8,-2,DARK_OAK_STAIRS:1)
Block(5,8,0,STAINED_CLAY:9)
Block(5,8,1,TRIPWIRE_HOOK:3)
Block(5,8,2,CONCRETE:15)
Block(5,8,3,STONE_BUTTON:3)
Block(5,8,4,TRIPWIRE_HOOK:3)
Block(5,8,5,CONCRETE:15)
Block(5,8,6,STAINED_CLAY:9)
Block(5,8,7,TRIPWIRE_HOOK:3)
Block(5,8,8,CONCRETE:15)
Block(5,9,0,STAINED_CLAY:9)
Block(5,9,1,WOOD_STEP:5)
Block(5,9,2,WOOD_BUTTON:5)
Block(5,9,3,WOOD_STEP:5)
Block(5,9,4,WOOD_STEP:5)
Block(5,9,5,WOOD_BUTTON:5)
Block(5,9,6,STAINED_CLAY:9)
Block(5,9,7,WOOD_STEP:5)
Block(5,9,8,WOOD_BUTTON:5)
Block(5,10,-7,WOOD_STEP:13)
Block(5,10,-6,WOOD_STEP:13)
Block(5,10,-5,WOOD_STEP:13)
Block(5,10,-4,WOOD_STEP:13)
Block(5,10,-3,WOOD_STEP:13)
Block(5,10,-2,WOOD_STEP:13)
Block(5,10,-1,WOOD_STEP:13)
Block(5,10,0,WOOD_DOUBLE_STEP:5)
Block(5,10,1,WOOD_STEP:13)
Block(5,10,2,WOOD_STEP:13)
Block(5,10,3,WOOD_STEP:13)
Block(5,10,4,WOOD_STEP:13)
Block(5,10,5,WOOD_STEP:13)
Block(5,10,6,HOPPER:4)
Block(5,10,7,HOPPER:4)
Block(5,10,8,WOOD_DOUBLE_STEP:5)
Block(5,11,-6,SPRUCE_WOOD_STAIRS:1)
Block(5,11,-3,SPRUCE_WOOD_STAIRS:1)
Block(5,11,-1,WOOD_BUTTON:4)
Block(5,11,0,DISPENSER:1)
Block(5,11,1,WOOD_BUTTON:3)
Block(5,11,2,WOOD_BUTTON:4)
Block(5,11,3,STAINED_CLAY:9)
Block(5,11,4,REDSTONE_BLOCK:0)
Block(5,11,5,STAINED_CLAY:9)
Block(5,11,8,STAINED_CLAY:9)
Block(5,12,0,LEVER:6)
Block(5,12,3,DARK_OAK_FENCE:0)
Block(5,12,4,STAINED_CLAY:9)
Block(5,12,5,STAINED_CLAY:9)
Block(5,12,8,STAINED_CLAY:9)
Block(5,13,4,DARK_OAK_FENCE:0)
Block(5,13,5,STAINED_CLAY:9)
Block(5,13,6,STAINED_CLAY:9)
Block(5,13,7,STAINED_CLAY:9)
Block(5,13,8,STAINED_CLAY:9)
Block(5,14,-3,WOOL:15)
Block(5,14,1,SPRUCE_FENCE:0)
Block(5,14,2,SPRUCE_FENCE:0)
Block(5,14,5,DARK_OAK_STAIRS:2)
Block(5,14,6,STAINED_CLAY:9)
Block(5,14,7,STAINED_CLAY:9)
Block(5,14,8,STAINED_CLAY:9)
Block(5,15,-3,WOOL:15)
Block(5,15,0,SPRUCE_FENCE:0)
Block(5,15,1,SPRUCE_FENCE:0)
Block(5,15,2,SPRUCE_FENCE:0)
Block(5,15,3,SPRUCE_FENCE:0)
Block(5,15,6,WOOD_STEP:5)
Block(5,15,7,WOOD_STEP:5)
Block(5,15,8,WOOD_STEP:5)
Block(5,16,-4,WOOL:15)
Block(5,16,0,SPRUCE_FENCE:0)
Block(5,16,1,SPRUCE_FENCE:0)
Block(5,16,2,SPRUCE_FENCE:0)
Block(5,17,-4,WOOL:15)
Block(5,17,0,SPRUCE_FENCE:0)
Block(5,17,1,SPRUCE_FENCE:0)
Block(5,17,2,SPRUCE_FENCE:0)
Block(5,18,-4,WOOL:15)
Block(5,19,-4,WOOL:15)
Block(5,20,-3,WOOL:15)
Block(5,21,-3,WOOL:15)
Block(5,21,-2,SPRUCE_FENCE:0)
Block(5,22,-2,LOG:5)
Block(5,24,-4,WOOL:15)
Block(5,25,-5,WOOL:15)
Block(5,26,-5,WOOL:15)
Block(5,27,-5,WOOL:15)
Block(5,28,-6,WOOL:15)
Block(5,29,-5,WOOL:15)
Block(5,30,-5,WOOL:15)
Block(5,31,-5,WOOL:15)
Block(5,32,-4,WOOL:15)
Block(5,33,-4,WOOL:15)
Block(5,34,-4,WOOL:15)
Block(5,35,-3,WOOL:15)
Block(5,35,-2,SPRUCE_FENCE:0)
Block(5,36,-2,LOG:5)
Block(5,37,-4,WOOL:15)
Block(5,38,-4,WOOL:15)
Block(5,39,-5,WOOL:15)
Block(5,40,-5,WOOL:15)
Block(5,41,-5,WOOL:15)
Block(5,42,-4,WOOL:15)
Block(5,43,-3,WOOL:15)
Block(5,44,-2,WOOL:15)
Block(6,4,-7,LOG_2:13)
Block(6,4,-6,LOG_2:13)
Block(6,4,-5,LOG_2:13)
Block(6,4,-4,LOG_2:13)
Block(6,4,-3,LOG_2:13)
Block(6,4,-2,LOG_2:13)
Block(6,4,-1,LOG_2:13)
Block(6,4,0,LOG_2:13)
Block(6,4,1,LOG_2:13)
Block(6,4,2,LOG_2:13)
Block(6,4,3,LOG_2:13)
Block(6,4,4,LOG_2:13)
Block(6,4,5,LOG_2:13)
Block(6,5,-7,AIR:0)
Block(6,5,-6,AIR:0)
Block(6,5,-5,STONE:1)
Block(6,5,-4,STONE:1)
Block(6,5,-3,WOOD:5)
Block(6,5,-2,CAULDRON:3)
Block(6,5,-1,CAULDRON:3)
Block(6,5,0,CAULDRON:3)
Block(6,5,1,WOOD:5)
Block(6,5,2,AIR:0)
Block(6,5,3,AIR:0)
Block(6,5,4,TNT:0)
Block(6,5,5,WOOD:5)
Block(6,5,6,LOG_2:13)
Block(6,5,7,LOG_2:13)
Block(6,5,8,LOG_2:13)
Block(6,6,-7,AIR:0)
Block(6,6,-6,AIR:0)
Block(6,6,-5,AIR:0)
Block(6,6,-4,AIR:0)
Block(6,6,-3,WOOD:5)
Block(6,6,-2,AIR:0)
Block(6,6,-1,AIR:0)
Block(6,6,0,AIR:0)
Block(6,6,1,WOOD:5)
Block(6,6,2,AIR:0)
Block(6,6,3,AIR:0)
Block(6,6,4,AIR:0)
Block(6,6,5,WOOD:5)
Block(6,6,6,AIR:0)
Block(6,6,7,AIR:0)
Block(6,6,8,AIR:0)
Block(6,7,-7,WOOD:5)
Block(6,7,-6,WOOD:5)
Block(6,7,-5,WOOD:5)
Block(6,7,-4,WOOD:5)
Block(6,7,-3,WOOD:5)
Block(6,7,-2,WOOD:5)
Block(6,7,-1,WOOD:5)
Block(6,7,0,WOOD:5)
Block(6,7,1,WOOD:5)
Block(6,7,2,WOOD:5)
Block(6,7,3,WOOD:5)
Block(6,7,4,WOOD:5)
Block(6,7,5,WOOD:5)
Block(6,7,6,WOOD:5)
Block(6,7,7,WOOD:5)
Block(6,7,8,WOOD:5)
Block(6,8,-7,CARPET:12)
Block(6,8,-6,CARPET:12)
Block(6,8,-4,CARPET:13)
Block(6,8,-2,CARPET:12)
Block(6,8,-1,CARPET:12)
Block(6,8,0,STAINED_CLAY:9)
Block(6,8,1,TRIPWIRE:0)
Block(6,8,2,DARK_OAK_STAIRS:1)
Block(6,8,4,TRIPWIRE:0)
Block(6,8,5,DARK_OAK_STAIRS:1)
Block(6,8,6,STAINED_CLAY:9)
Block(6,8,7,TRIPWIRE:0)
Block(6,8,8,DARK_OAK_STAIRS:1)
Block(6,9,0,STAINED_CLAY:9)
Block(6,9,6,STAINED_CLAY:9)
Block(6,10,-7,WOOD_STEP:13)
Block(6,10,-6,WOOD_STEP:13)
Block(6,10,-5,WOOD_STEP:13)
Block(6,10,-4,WOOD_STEP:13)
Block(6,10,-3,WOOD_STEP:13)
Block(6,10,-2,WOOD_STEP:13)
Block(6,10,-1,WOOD_STEP:13)
Block(6,10,0,WOOD_DOUBLE_STEP:5)
Block(6,10,1,WOOD_STEP:13)
Block(6,10,2,WOOD_STEP:13)
Block(6,10,3,WOOD_STEP:13)
Block(6,10,4,WOOD_STEP:13)
Block(6,10,5,WOOD_STEP:13)
Block(6,10,6,WOOD_DOUBLE_STEP:5)
Block(6,10,7,WOOD_STEP:13)
Block(6,10,8,WOOD_STEP:13)
Block(6,11,0,SPRUCE_WOOD_STAIRS:1)
Block(6,11,3,SPRUCE_WOOD_STAIRS:2)
Block(6,11,4,REDSTONE_LAMP_ON:0)
Block(6,11,5,TRAP_DOOR:5)
Block(6,11,8,STAINED_CLAY:9)
Block(6,12,4,SPRUCE_WOOD_STAIRS:2)
Block(6,12,5,STAINED_CLAY:9)
Block(6,12,8,STAINED_CLAY:9)
Block(6,13,5,SPRUCE_WOOD_STAIRS:2)
Block(6,13,6,STAINED_CLAY:9)
Block(6,13,7,STAINED_CLAY:9)
Block(6,13,8,STAINED_CLAY:9)
Block(6,14,-3,WOOL:15)
Block(6,15,-3,WOOL:15)
Block(6,16,-4,WOOL:15)
Block(6,16,0,SPRUCE_FENCE:0)
Block(6,17,-4,WOOL:15)
Block(6,17,-1,SPRUCE_FENCE:0)
Block(6,17,0,SPRUCE_FENCE:0)
Block(6,17,1,SPRUCE_FENCE:0)
Block(6,18,-4,WOOL:15)
Block(6,18,-1,SPRUCE_FENCE:0)
Block(6,18,0,SPRUCE_FENCE:0)
Block(6,18,1,SPRUCE_FENCE:0)
Block(6,19,-3,WOOL:15)
Block(6,20,-3,WOOL:15)
Block(6,21,-3,WOOL:15)
Block(6,21,-2,SPRUCE_FENCE:0)
Block(6,22,-2,LOG:5)
Block(6,24,-4,WOOL:15)
Block(6,25,-4,WOOL:15)
Block(6,26,-5,WOOL:15)
Block(6,27,-5,WOOL:15)
Block(6,28,-5,WOOL:15)
Block(6,29,-5,WOOL:15)
Block(6,30,-5,WOOL:15)
Block(6,30,8,WOOL:15)
Block(6,31,-4,WOOL:15)
Block(6,32,-4,WOOL:15)
Block(6,33,-4,WOOL:15)
Block(6,34,-3,WOOL:15)
Block(6,35,-3,WOOL:15)
Block(6,35,-2,SPRUCE_FENCE:0)
Block(6,36,-2,LOG:5)
Block(6,37,-3,WOOL:15)
Block(6,38,-4,WOOL:15)
Block(6,39,-4,WOOL:15)
Block(6,40,-5,WOOL:15)
Block(6,41,-4,WOOL:15)
Block(6,42,-3,WOOL:15)
Block(6,43,-3,WOOL:15)
Block(6,43,-2,SPRUCE_FENCE:0)
Block(6,44,-2,LOG:5)
Block(7,3,-7,LOG_2:13)
Block(7,3,-6,LOG_2:13)
Block(7,3,-5,LOG_2:13)
Block(7,3,-4,LOG_2:13)
Block(7,4,-7,AIR:0)
Block(7,4,-6,IRON_ORE:0)
Block(7,4,-5,COAL_ORE:0)
Block(7,4,-4,STONE:1)
Block(7,4,-3,LOG_2:13)
Block(7,4,-2,LOG_2:13)
Block(7,4,-1,LOG_2:13)
Block(7,4,0,LOG_2:13)
Block(7,4,1,LOG_2:13)
Block(7,4,2,LOG_2:13)
Block(7,4,3,LOG_2:13)
Block(7,4,4,LOG_2:13)
Block(7,4,5,LOG_2:13)
Block(7,4,6,LOG_2:13)
Block(7,4,7,LOG_2:13)
Block(7,4,8,LOG_2:13)
Block(7,5,-7,AIR:0)
Block(7,5,-6,AIR:0)
Block(7,5,-5,AIR:0)
Block(7,5,-4,AIR:0)
Block(7,5,-3,WOOD:5)
Block(7,5,-2,CAULDRON:3)
Block(7,5,-1,AIR:0)
Block(7,5,0,AIR:0)
Block(7,5,1,WOOD:5)
Block(7,5,2,AIR:0)
Block(7,5,3,AIR:0)
Block(7,5,4,AIR:0)
Block(7,5,5,WOOD:5)
Block(7,5,6,AIR:0)
Block(7,5,7,AIR:0)
Block(7,5,8,AIR:0)
Block(7,6,-7,AIR:0)
Block(7,6,-6,AIR:0)
Block(7,6,-5,AIR:0)
Block(7,6,-4,AIR:0)
Block(7,6,-3,WOOD:5)
Block(7,6,-2,AIR:0)
Block(7,6,-1,AIR:0)
Block(7,6,0,AIR:0)
Block(7,6,1,WOOD:5)
Block(7,6,2,AIR:0)
Block(7,6,3,AIR:0)
Block(7,6,4,AIR:0)
Block(7,6,5,WOOD:5)
Block(7,6,6,AIR:0)
Block(7,6,7,AIR:0)
Block(7,6,8,AIR:0)
Block(7,7,-7,WOOD:5)
Block(7,7,-6,WOOD:5)
Block(7,7,-5,WOOD:5)
Block(7,7,-4,WOOD:5)
Block(7,7,-3,WOOD:5)
Block(7,7,-2,WOOD:5)
Block(7,7,-1,WOOD:5)
Block(7,7,0,WOOD:5)
Block(7,7,1,WOOD:5)
Block(7,7,2,WOOD:5)
Block(7,7,3,WOOD:5)
Block(7,7,4,WOOD:5)
Block(7,7,5,WOOD:5)
Block(7,7,6,WOOD:5)
Block(7,7,7,WOOD:5)
Block(7,7,8,WOOD:5)
Block(7,8,-7,CARPET:13)
Block(7,8,-6,BED_BLOCK:3)
Block(7,8,-4,BED_BLOCK:0)
Block(7,8,-3,BED_BLOCK:8)
Block(7,8,-2,CARPET:13)
RandomBlock(7,8,-1,AIR:0,20,CHEST:4,../../../../Chests/Loot/PirateJunk_1.nbt,10,CHEST:4,../../../../Chests/Loot/PirateJunk_2.nbt,10,CHEST:4,../../../../Chests/Loot/PirateJunk_3.nbt,10,CHEST:4,../../../../Chests/Loot/PirateJunk_4.nbt,10,CHEST:4,../../../../Chests/Loot/PirateJunk_5.nbt,10,CHEST:4,../../../../Chests/Traveler/Travelers_Castle.nbt,1,CHEST:4,../../../../Chests/Traveler/Travelers_Church.nbt,1,CHEST:4,../../../../Chests/Traveler/Travelers_Daeroc.nbt,1,CHEST:4,../../../../Chests/Traveler/Travelers_Farmsteads.nbt,1,CHEST:4,../../../../Chests/Traveler/Travelers_GreenDungeon.nbt,1,CHEST:4,../../../../Chests/Traveler/Travelers_IceShips.nbt,1,CHEST:4,../../../../Chests/Traveler/Travelers_IceTemple.nbt,1,CHEST:4,../../../../Chests/Traveler/Travelers_LegacySpawn.nbt,1,CHEST:4,../../../../Chests/Traveler/Travelers_Mineshafts.nbt,1,CHEST:4,../../../../Chests/Traveler/Travelers_Mountains.nbt,1,CHEST:4,../../../../Chests/Traveler/Travelers_Origin.nbt,1,CHEST:4,../../../../Chests/Traveler/Travelers_Pirate.nbt,1,CHEST:4,../../../../Chests/Traveler/Travelers_Quarry.nbt,1,CHEST:4,../../../../Chests/Traveler/Travelers_Spook.nbt,1,CHEST:4,../../../../Chests/Traveler/Travelers_Tribal.nbt,1,CHEST:4,../../../../Chests/Lore/Pirate_1.nbt,1,CHEST:4,../../../../Chests/Lore/Pirate_2.nbt,1,CHEST:4,../../../../Chests/Lore/Pirate_3.nbt,1,CHEST:4,../../../../Chests/Lore/Pirate_4.nbt,1,CHEST:4,../../../../Chests/Lore/Pirate_5.nbt,1,CHEST:4,../../../../Chests/Loot/Common1.nbt,10,CHEST:4,../../../../Chests/Loot/Common2.nbt,10,CHEST:4,../../../../Chests/Loot/Common3.nbt,10,CHEST:4,../../../../Chests/Loot/Common4.nbt,10,CHEST:4,../../../../Chests/Loot/Common5.nbt,10,CHEST:4,../../../../Chests/Loot/Common6.nbt,10,CHEST:4,../../../../Chests/Loot/Common7.nbt,10,CHEST:4,../../../../Chests/Loot/Common8.nbt,10,CHEST:4,../../../../Chests/Loot/Common9.nbt,10,CHEST:4,../../../../Chests/Loot/Common10.nbt,10,CHEST:4,../../../../Chests/Loot/Common10.nbt,11,CHEST:4,../../../../Chests/Loot/Common12.nbt,10,CHEST:4,../../../../Chests/Loot/Common13.nbt,10,CHEST:4,../../../../Chests/Loot/Common14.nbt,10,CHEST:4,../../../../Chests/Loot/Common15.nbt,10,CHEST:4,../../../../Chests/Lore/Pirate_1.nbt,2,CHEST:4,../../../../Chests/Lore/Pirate_3.nbt,2,CHEST:4,../../../../Chests/Lore/Pirate_4.nbt,2,CHEST:4,../../../../Chests/Lore/Pirate_5.nbt,2,CHEST:4,../../../../Chests/Lore/Pirate_5.nbt,2,CHEST:4,../../../../Chests/Loot/Rare1.nbt,5,CHEST:4,../../../../Chests/Loot/Rare2.nbt,5,CHEST:4,../../../../Chests/Loot/Rare3.nbt,5,CHEST:4,../../../../Chests/Loot/Rare4.nbt,5,CHEST:4,../../../../Chests/Loot/Rare5.nbt,5,CHEST:4,../../../../Chests/Loot/Rare6.nbt,5,CHEST:4,../../../../Chests/Loot/Rare7.nbt,5,CHEST:4,../../../../Chests/Loot/Rare8.nbt,5,CHEST:4,../../../../Chests/Loot/Rare9.nbt,5,CHEST:4,../../../../Chests/Loot/Rare10.nbt,5,CHEST:4,../../../../Chests/Loot/Rare11.nbt,5,CHEST:4,../../../../Chests/Loot/Rare12.nbt,5,CHEST:4,../../../../Chests/Loot/Rare13.nbt,5,CHEST:4,../../../../Chests/Loot/Rare14.nbt,5,CHEST:4,../../../../Chests/Loot/Rare15.nbt,5,CHEST:4,../../../../Chests/Loot/Epic1.nbt,2,CHEST:4,../../../../Chests/Loot/Epic2.nbt,2,CHEST:4,../../../../Chests/Loot/Epic3.nbt,2,CHEST:4,../../../../Chests/Loot/Epic4.nbt,2,CHEST:4,../../../../Chests/Loot/Epic5.nbt,2,CHEST:4,../../../../Chests/Loot/Epic6.nbt,2,CHEST:4,../../../../Chests/Loot/Epic7.nbt,2,CHEST:4,../../../../Chests/Loot/Epic8.nbt,2,CHEST:4,../../../../Chests/Loot/Epic9.nbt,2,CHEST:4,../../../../Chests/Loot/Epic10.nbt,2,CHEST:4,../../../../Chests/Loot/Epic11.nbt,2,CHEST:4,../../../../Chests/Loot/Epic12.nbt,2,CHEST:4,../../../../Chests/Loot/Epic13.nbt,2,CHEST:4,../../../../Chests/Loot/Epic14.nbt,2,CHEST:4,../../../../Chests/Loot/Epic15.nbt,5,CHEST:4,../../../../Chests/Loot/Rare1.nbt,5,CHEST:4,../../../../Chests/Loot/Rare2.nbt,5,CHEST:4,../../../../Chests/Loot/Rare3.nbt,5,CHEST:4,../../../../Chests/Loot/Rare4.nbt,5,CHEST:4,../../../../Chests/Loot/Rare5.nbt,10,CHEST:4,../../../../Chests/Loot/Rare6.nbt,10,CHEST:4,../../../../Chests/Loot/Rare7.nbt,10,CHEST:4,../../../../Chests/Loot/Rare8.nbt,10,CHEST:4,../../../../Chests/Loot/Rare9.nbt,10,CHEST:4,../../../../Chests/Loot/Rare10.nbt,15,CHEST:4,../../../../Chests/Loot/Rare11.nbt,15,CHEST:4,../../../../Chests/Loot/Rare12.nbt,15,CHEST:4,../../../../Chests/Loot/Rare13.nbt,15,CHEST:4,../../../../Chests/Loot/Rare14.nbt,15,CHEST:4,../../../../Chests/Loot/Rare15.nbt,15,CHEST:4,../../../../Chests/Loot/Epic15.nbt,100)
Block(7,8,0,STAINED_CLAY:9)
Block(7,8,1,CARPET:12)
Block(7,8,3,CARPET:13)
Block(7,8,4,CARPET:13)
Block(7,8,6,STAINED_CLAY:9)
Block(7,9,0,STAINED_CLAY:9)
RandomBlock(7,9,1,WALL_BANNER:3,../../Banners/skullpillager_01.nbt,20,WALL_BANNER:3,../../Banners/skullpillager_02.nbt,20,WALL_BANNER:3,../../Banners/skullpillager_03.nbt,20,WALL_BANNER:3,../../Banners/skullpillager_04.nbt,20,WALL_BANNER:3,../../Banners/skullpillager_05.nbt,100)
Block(7,9,6,STAINED_CLAY:9)
Block(7,10,-7,WOOD_STEP:13)
Block(7,10,-6,WOOD_STEP:13)
Block(7,10,-5,WOOD_STEP:13)
Block(7,10,-4,WOOD_STEP:13)
Block(7,10,-3,WOOD_STEP:13)
Block(7,10,-2,WOOD_STEP:13)
Block(7,10,-1,WOOD_STEP:13)
Block(7,10,0,WOOD_DOUBLE_STEP:5)
Block(7,10,1,WOOD_STEP:13)
Block(7,10,2,WOOD_STEP:13)
Block(7,10,3,WOOD_STEP:13)
Block(7,10,4,WOOD_STEP:13)
Block(7,10,5,WOOD_STEP:13)
Block(7,10,6,WOOD_DOUBLE_STEP:5)
Block(7,10,7,WOOD_STEP:13)
Block(7,10,8,WOOD_STEP:13)
Block(7,11,-6,STONE_BUTTON:2)
Block(7,11,-5,STONE_BUTTON:2)
Block(7,11,2,WOOD_BUTTON:4)
Block(7,11,3,STAINED_CLAY:9)
Block(7,11,4,WOOD_STEP:5)
Block(7,11,5,STAINED_CLAY:9)
Block(7,11,7,CAULDRON:3)
Block(7,11,8,STAINED_CLAY:9)
Block(7,12,3,DARK_OAK_FENCE:0)
Block(7,12,4,STAINED_CLAY:9)
Block(7,12,5,STAINED_CLAY:9)
Block(7,12,8,STAINED_CLAY:9)
Block(7,13,4,DARK_OAK_FENCE:0)
Block(7,13,5,STAINED_CLAY:9)
Block(7,13,6,STAINED_CLAY:9)
Block(7,13,7,STAINED_CLAY:9)
Block(7,13,8,STAINED_CLAY:9)
Block(7,14,-2,WOOL:15)
Block(7,14,5,DARK_OAK_FENCE:0)
Block(7,15,-3,WOOL:15)
Block(7,16,-3,WOOL:15)
Block(7,17,-4,WOOL:15)
Block(7,18,-3,WOOL:15)
Block(7,18,-1,SPRUCE_FENCE:0)
Block(7,18,0,SPRUCE_FENCE:0)
Block(7,19,-3,WOOL:15)
Block(7,19,-1,SPRUCE_FENCE:0)
Block(7,19,0,SPRUCE_FENCE:0)
Block(7,20,-3,WOOL:15)
Block(7,21,-3,WOOL:15)
Block(7,21,-2,SPRUCE_FENCE:0)
Block(7,21,-1,SPRUCE_FENCE:0)
Block(7,22,-1,LOG:5)
Block(7,25,-4,WOOL:15)
Block(7,25,8,WOOL:15)
Block(7,26,-4,WOOL:15)
Block(7,26,8,WOOL:15)
Block(7,27,-5,WOOL:15)
Block(7,27,7,WOOL:15)
Block(7,28,-5,WOOL:15)
Block(7,28,7,WOOL:15)
Block(7,29,-5,WOOL:15)
Block(7,29,7,WOOL:15)
Block(7,30,-4,WOOL:15)
Block(7,30,8,WOOL:15)
Block(7,31,-4,WOOL:15)
Block(7,31,8,WOOL:15)
Block(7,32,-4,WOOL:15)
Block(7,33,-3,WOOL:15)
Block(7,34,-3,WOOL:15)
Block(7,35,-2,WOOL:15)
Block(7,36,-2,LOG:5)
Block(7,37,-3,WOOL:15)
Block(7,38,-3,WOOL:15)
Block(7,39,-4,WOOL:15)
Block(7,40,-4,WOOL:15)
Block(7,41,-4,WOOL:15)
Block(7,42,-3,WOOL:15)
Block(7,43,-3,WOOL:15)
Block(7,43,-2,SPRUCE_FENCE:0)
Block(7,44,-2,LOG:5)
Branch(0,0,-16,true,Pillager_FloatC0R1,NORTH,100.0,0)
