Author: NLBlackEagle
Description: No description given
SettingsMode: WriteDisable
Frequency: 0
SpawnHeight: highestBlock
UseCenterForHighestBlock: true
MinHeight: 0
MaxHeight: 255
InheritBO3: 
InheritBO3Rotation: NORTH
OverrideChildSettings: true
OverrideParentHeight: false
CanOverride: false
BranchFrequency: 0
BranchFrequencyGroup: 
MustBeBelowOther: false
MustBeInside: 
CannotBeInside: 
ReplacesBO3: 
MustBeInsideWorldBorders: false
CanSpawnOnWater: true
SpawnOnWaterOnly: false
SpawnUnderWater: false
SpawnAtWaterLevel: false
HeightOffset: 0
RemoveAir: true
ReplaceAbove: 
ReplaceBelow: 
ReplaceWithBiomeBlocks: true
ReplaceWithSurfaceBlock: GRASS
ReplaceWithGroundBlock: DIRT
ReplaceWithStoneBlock: STONE
SmoothRadius: 0
SmoothHeightOffset: 0
SmoothStartTop: false
SmoothStartWood: false
SmoothingSurfaceBlock: 
SmoothingGroundBlock: 
BO3Group: 
IsSpawnPoint: false
DoReplaceBlocks: true
Block(-8,8,1,WOOD_BUTTON:2)
Block(-7,4,-7,SPRUCE_WOOD_STAIRS:0)
Block(-7,4,-6,SPRUCE_WOOD_STAIRS:0)
Block(-7,4,-5,SPRUCE_WOOD_STAIRS:0)
Block(-7,4,-4,SPRUCE_WOOD_STAIRS:0)
Block(-7,4,-3,SPRUCE_WOOD_STAIRS:0)
Block(-7,4,-2,SPRUCE_WOOD_STAIRS:0)
Block(-7,4,-1,SPRUCE_WOOD_STAIRS:0)
Block(-7,4,0,SPRUCE_WOOD_STAIRS:0)
Block(-7,4,1,SPRUCE_WOOD_STAIRS:0)
Block(-7,4,2,SPRUCE_WOOD_STAIRS:0)
Block(-7,4,3,SPRUCE_WOOD_STAIRS:0)
Block(-7,4,4,SPRUCE_WOOD_STAIRS:0)
Block(-7,4,5,SPRUCE_WOOD_STAIRS:0)
Block(-7,4,6,SPRUCE_WOOD_STAIRS:0)
Block(-7,8,1,LOG:5)
Block(-6,0,-7,COBBLESTONE:0)
Block(-6,0,-6,COBBLESTONE:0)
Block(-6,0,-5,COBBLESTONE:0)
Block(-6,0,-4,COBBLESTONE:0)
Block(-6,0,-3,LOG:1)
Block(-6,0,-2,COBBLESTONE:0)
Block(-6,0,-1,COBBLESTONE:0)
Block(-6,0,0,COBBLESTONE:0)
Block(-6,0,1,COBBLESTONE:0)
Block(-6,0,2,COBBLESTONE:0)
Block(-6,0,3,COBBLESTONE:0)
Block(-6,0,4,COBBLESTONE:0)
Block(-6,0,5,LOG:1)
Block(-6,1,-7,COBBLESTONE:0)
Block(-6,1,-6,COBBLESTONE:0)
Block(-6,1,-5,COBBLESTONE:0)
Block(-6,1,-4,COBBLESTONE:0)
Block(-6,1,-3,LOG:1)
Block(-6,1,-2,COBBLESTONE:0)
Block(-6,1,-1,COBBLESTONE:0)
Block(-6,1,0,COBBLESTONE:0)
Block(-6,1,1,COBBLESTONE:0)
Block(-6,1,2,COBBLESTONE:0)
Block(-6,1,3,COBBLESTONE:0)
Block(-6,1,4,COBBLESTONE:0)
Block(-6,1,5,LOG:1)
Block(-6,2,-7,COBBLESTONE:0)
Block(-6,2,-6,COBBLESTONE:0)
Block(-6,2,-5,COBBLESTONE:0)
Block(-6,2,-4,COBBLESTONE:0)
Block(-6,2,-3,LOG:1)
Block(-6,2,-2,COBBLESTONE:0)
Block(-6,2,-1,COBBLESTONE:0)
Block(-6,2,0,COBBLESTONE:0)
Block(-6,2,1,COBBLESTONE:0)
Block(-6,2,2,COBBLESTONE:0)
Block(-6,2,3,COBBLESTONE:0)
Block(-6,2,4,COBBLESTONE:0)
Block(-6,2,5,LOG:1)
Block(-6,3,-7,WOOD:1)
Block(-6,3,-6,WOOD:1)
Block(-6,3,-5,WOOD:1)
Block(-6,3,-4,WOOD:1)
Block(-6,3,-3,LOG:1)
Block(-6,3,-2,WOOD:1)
Block(-6,3,-1,WOOD:1)
Block(-6,3,0,WOOD:1)
Block(-6,3,1,WOOD:1)
Block(-6,3,2,WOOD:1)
Block(-6,3,3,WOOD:1)
Block(-6,3,4,WOOD:1)
Block(-6,3,5,LOG:1)
Block(-6,4,-7,DARK_OAK_FENCE:0)
Block(-6,4,-6,DARK_OAK_FENCE:0)
Block(-6,4,-5,DARK_OAK_FENCE:0)
Block(-6,4,-4,DARK_OAK_FENCE:0)
Block(-6,4,-3,LOG:1)
Block(-6,4,-2,DARK_OAK_FENCE:0)
Block(-6,4,-1,DARK_OAK_FENCE:0)
Block(-6,4,0,DARK_OAK_FENCE:0)
Block(-6,4,1,DARK_OAK_FENCE:0)
Block(-6,4,2,DARK_OAK_FENCE:0)
Block(-6,4,3,DARK_OAK_FENCE:0)
Block(-6,4,4,DARK_OAK_FENCE:0)
Block(-6,4,5,LOG:1)
Block(-6,4,6,SPRUCE_WOOD_STAIRS:5)
Block(-6,5,-7,SPRUCE_WOOD_STAIRS:0)
Block(-6,5,-6,SPRUCE_WOOD_STAIRS:0)
Block(-6,5,-5,SPRUCE_WOOD_STAIRS:0)
Block(-6,5,-4,SPRUCE_WOOD_STAIRS:0)
Block(-6,5,-3,SPRUCE_WOOD_STAIRS:0)
Block(-6,5,-2,SPRUCE_WOOD_STAIRS:0)
Block(-6,5,-1,SPRUCE_WOOD_STAIRS:0)
Block(-6,5,0,SPRUCE_WOOD_STAIRS:0)
Block(-6,5,1,SPRUCE_WOOD_STAIRS:0)
Block(-6,5,2,SPRUCE_WOOD_STAIRS:0)
Block(-6,5,3,SPRUCE_WOOD_STAIRS:0)
Block(-6,5,4,SPRUCE_WOOD_STAIRS:0)
Block(-6,5,5,SPRUCE_WOOD_STAIRS:0)
Block(-6,5,6,SPRUCE_WOOD_STAIRS:0)
Block(-6,6,-2,SPRUCE_WOOD_STAIRS:2)
Block(-6,6,-1,SPRUCE_WOOD_STAIRS:7)
Block(-6,6,3,SPRUCE_WOOD_STAIRS:6)
Block(-6,6,4,SPRUCE_WOOD_STAIRS:3)
Block(-6,7,-1,SPRUCE_WOOD_STAIRS:2)
Block(-6,7,0,SPRUCE_WOOD_STAIRS:7)
Block(-6,7,2,SPRUCE_WOOD_STAIRS:6)
Block(-6,7,3,SPRUCE_WOOD_STAIRS:3)
Block(-6,8,0,SPRUCE_WOOD_STAIRS:2)
Block(-6,8,1,LOG:5)
Block(-6,8,2,SPRUCE_WOOD_STAIRS:3)
Block(-6,9,0,WOOD_STEP:1)
Block(-6,9,2,WOOD_STEP:1)
Block(-5,0,-7,COBBLESTONE:0)
Block(-5,0,-6,COBBLESTONE:0)
Block(-5,0,-5,COBBLESTONE:0)
Block(-5,0,-4,COBBLESTONE:0)
Block(-5,0,-3,COBBLESTONE:0)
Block(-5,0,-2,COBBLESTONE:0)
Block(-5,0,-1,COBBLESTONE:0)
Block(-5,0,0,COBBLESTONE:0)
Block(-5,0,1,COBBLESTONE:0)
Block(-5,0,2,COBBLESTONE:0)
Block(-5,0,3,COBBLESTONE:0)
Block(-5,0,4,COBBLESTONE:0)
Block(-5,0,5,COBBLESTONE:0)
Block(-5,1,-7,COBBLESTONE:0)
Block(-5,1,-6,COBBLESTONE:0)
Block(-5,1,-5,COBBLESTONE:0)
Block(-5,1,-4,COBBLESTONE:0)
Block(-5,1,-3,COBBLESTONE:0)
Block(-5,1,-2,COBBLESTONE:0)
Block(-5,1,-1,COBBLESTONE:0)
Block(-5,1,0,COBBLESTONE:0)
Block(-5,1,1,COBBLESTONE:0)
Block(-5,1,2,COBBLESTONE:0)
Block(-5,1,3,COBBLESTONE:0)
Block(-5,1,4,COBBLESTONE:0)
Block(-5,1,5,COBBLESTONE:0)
Block(-5,2,-7,WOOD:5)
Block(-5,2,-6,WOOD:5)
Block(-5,2,-5,COBBLESTONE:0)
Block(-5,2,-4,COBBLESTONE:0)
Block(-5,2,-3,COBBLESTONE:0)
Block(-5,2,-2,COBBLESTONE:0)
Block(-5,2,-1,WOOD:5)
Block(-5,2,0,WOOD:5)
Block(-5,2,1,COBBLESTONE:0)
Block(-5,2,2,WOOD:5)
Block(-5,2,3,WOOD:5)
Block(-5,2,4,COBBLESTONE:0)
Block(-5,2,5,COBBLESTONE:0)
Block(-5,3,-7,WOOD:5)
Block(-5,3,-6,WOOD:5)
Block(-5,3,-5,CAULDRON:0)
Block(-5,3,-3,DARK_OAK_FENCE:0)
Block(-5,3,-2,DARK_OAK_FENCE:0)
Block(-5,3,-1,DARK_OAK_STAIRS:0)
Block(-5,3,0,DARK_OAK_STAIRS:0)
Block(-5,3,1,LOG:1)
Block(-5,3,2,DARK_OAK_STAIRS:0)
Block(-5,3,3,DARK_OAK_STAIRS:0)
Block(-5,3,5,WOOD:1)
Block(-5,4,-7,WOOD:5)
Block(-5,4,-6,WOOD:5)
Block(-5,4,-5,TRAP_DOOR:1)
Block(-5,4,-3,DARK_OAK_FENCE:0)
Block(-5,4,-2,TORCH:5)
Block(-5,4,1,LOG:1)
Block(-5,4,5,WOOD:1)
Block(-5,5,-7,WOOD:5)
Block(-5,5,-6,WOOD:5)
Block(-5,5,-3,DARK_OAK_FENCE:0)
Block(-5,5,-2,SPRUCE_WOOD_STAIRS:5)
Block(-5,5,-1,SPRUCE_WOOD_STAIRS:5)
Block(-5,5,0,SPRUCE_WOOD_STAIRS:5)
Block(-5,5,1,LOG:1)
Block(-5,5,2,SPRUCE_WOOD_STAIRS:5)
Block(-5,5,3,SPRUCE_WOOD_STAIRS:5)
Block(-5,5,4,SPRUCE_WOOD_STAIRS:5)
Block(-5,5,5,DARK_OAK_FENCE:0)
Block(-5,5,6,SPRUCE_WOOD_STAIRS:5)
Block(-5,6,-7,SPRUCE_WOOD_STAIRS:0)
Block(-5,6,-6,SPRUCE_WOOD_STAIRS:0)
Block(-5,6,-5,SPRUCE_WOOD_STAIRS:0)
Block(-5,6,-4,SPRUCE_WOOD_STAIRS:0)
Block(-5,6,-3,SPRUCE_WOOD_STAIRS:0)
Block(-5,6,-2,SPRUCE_WOOD_STAIRS:0)
Block(-5,6,-1,DARK_OAK_FENCE:0)
Block(-5,6,0,SPRUCE_WOOD_STAIRS:7)
Block(-5,6,1,LOG:1)
Block(-5,6,2,SPRUCE_WOOD_STAIRS:6)
Block(-5,6,3,DARK_OAK_FENCE:0)
Block(-5,6,4,SPRUCE_WOOD_STAIRS:0)
Block(-5,6,5,SPRUCE_WOOD_STAIRS:0)
Block(-5,6,6,SPRUCE_WOOD_STAIRS:0)
Block(-5,7,-1,SPRUCE_WOOD_STAIRS:2)
Block(-5,7,0,DARK_OAK_FENCE:0)
Block(-5,7,1,LOG:1)
Block(-5,7,2,DARK_OAK_FENCE:0)
Block(-5,7,3,SPRUCE_WOOD_STAIRS:3)
Block(-5,8,0,WOOD_STEP:1)
Block(-5,8,1,LOG:5)
Block(-5,8,2,WOOD_STEP:1)
Block(-4,0,-7,COBBLESTONE:0)
Block(-4,0,-6,COBBLESTONE:0)
Block(-4,0,-5,COBBLESTONE:0)
Block(-4,0,-4,COBBLESTONE:0)
Block(-4,0,-3,COBBLESTONE:0)
Block(-4,0,-2,COBBLESTONE:0)
Block(-4,0,-1,COBBLESTONE:0)
Block(-4,0,0,COBBLESTONE:0)
Block(-4,0,1,COBBLESTONE:0)
Block(-4,0,2,COBBLESTONE:0)
Block(-4,0,3,COBBLESTONE:0)
Block(-4,0,4,COBBLESTONE:0)
Block(-4,0,5,COBBLESTONE:0)
Block(-4,1,-7,COBBLESTONE:0)
Block(-4,1,-6,COBBLESTONE:0)
Block(-4,1,-5,COBBLESTONE:0)
Block(-4,1,-4,COBBLESTONE:0)
Block(-4,1,-3,COBBLESTONE:0)
Block(-4,1,-2,COBBLESTONE:0)
Block(-4,1,-1,COBBLESTONE:0)
Block(-4,1,0,COBBLESTONE:0)
Block(-4,1,1,COBBLESTONE:0)
Block(-4,1,2,WOOD:5)
Block(-4,1,3,WOOD:5)
Block(-4,1,4,COBBLESTONE:0)
Block(-4,1,5,COBBLESTONE:0)
Block(-4,2,-7,WOOD:5)
Block(-4,2,-6,WOOD:5)
Block(-4,2,-5,WOOD:5)
Block(-4,2,-4,COBBLESTONE:0)
Block(-4,2,-3,COBBLESTONE:0)
Block(-4,2,-2,COBBLESTONE:0)
Block(-4,2,-1,DARK_OAK_DOOR:1)
Block(-4,2,0,DARK_OAK_DOOR:3)
Block(-4,2,1,COBBLESTONE:0)
Block(-4,2,2,DARK_OAK_DOOR:1)
Block(-4,2,3,DARK_OAK_DOOR:3)
Block(-4,2,4,COBBLESTONE:0)
Block(-4,2,5,COBBLESTONE:0)
Block(-4,3,-7,STATIONARY_WATER:0)
Block(-4,3,-6,STATIONARY_WATER:0)
Block(-4,3,-5,WOOD:5)
Block(-4,3,-4,CAULDRON:0)
Block(-4,3,-1,DARK_OAK_DOOR:9)
Block(-4,3,0,DARK_OAK_DOOR:8)
Block(-4,3,1,DARK_OAK_FENCE:0)
Block(-4,3,2,DARK_OAK_DOOR:9)
Block(-4,3,3,DARK_OAK_DOOR:8)
Block(-4,3,5,WOOD:1)
Block(-4,4,-7,STATIONARY_WATER:0)
Block(-4,4,-6,STATIONARY_WATER:0)
Block(-4,4,-5,WOOD:5)
Block(-4,4,-4,TRAP_DOOR:1)
Block(-4,4,1,TORCH:5)
Block(-4,4,5,WOOD:1)
Block(-4,5,-5,WOOD:5)
RandomBlock(-4,5,0,WALL_BANNER:5,../../NBT/Banners/viking_wealthy_1.nbt,20,WALL_BANNER:5,../../NBT/Banners/viking_wealthy_2.nbt,20,WALL_BANNER:5,../../NBT/Banners/viking_wealthy_3.nbt,20,WALL_BANNER:5,../../NBT/Banners/viking_wealthy_4.nbt,20,WALL_BANNER:5,../../NBT/Banners/viking_wealthy_5.nbt,20,WALL_BANNER:5,../../NBT/Banners/viking_wealthy_6.nbt,20,WALL_BANNER:5,../../NBT/Banners/viking_wealthy_7.nbt,20,WALL_BANNER:5,../../NBT/Banners/viking_wealthy_8.nbt,20,WALL_BANNER:5,../../NBT/Banners/viking_wealthy_9.nbt,100)
RandomBlock(-4,5,2,WALL_BANNER:5,../../NBT/Banners/viking_wealthy_1.nbt,20,WALL_BANNER:5,../../NBT/Banners/viking_wealthy_2.nbt,20,WALL_BANNER:5,../../NBT/Banners/viking_wealthy_3.nbt,20,WALL_BANNER:5,../../NBT/Banners/viking_wealthy_4.nbt,20,WALL_BANNER:5,../../NBT/Banners/viking_wealthy_5.nbt,20,WALL_BANNER:5,../../NBT/Banners/viking_wealthy_6.nbt,20,WALL_BANNER:5,../../NBT/Banners/viking_wealthy_7.nbt,20,WALL_BANNER:5,../../NBT/Banners/viking_wealthy_8.nbt,20,WALL_BANNER:5,../../NBT/Banners/viking_wealthy_9.nbt,100)
Block(-4,5,5,WOOD:1)
Block(-4,6,-7,WOOD_STEP:1)
Block(-4,6,-6,WOOD_STEP:1)
Block(-4,6,-5,WOOD_STEP:1)
Block(-4,6,-3,SPRUCE_WOOD_STAIRS:5)
RandomBlock(-4,6,-2,WALL_BANNER:5,../../NBT/Banners/viking_regular_1.nbt,20,WALL_BANNER:5,../../NBT/Banners/viking_regular_2.nbt,20,WALL_BANNER:5,../../NBT/Banners/viking_regular_3.nbt,20,WALL_BANNER:5,../../NBT/Banners/viking_regular_4.nbt,20,WALL_BANNER:5,../../NBT/Banners/viking_regular_5.nbt,20,WALL_BANNER:5,../../NBT/Banners/viking_regular_6.nbt,20,WALL_BANNER:5,../../NBT/Banners/viking_regular_7.nbt,20,WALL_BANNER:5,../../NBT/Banners/viking_regular_8.nbt,100)
RandomBlock(-4,6,4,WALL_BANNER:5,../../NBT/Banners/viking_wealthy_1.nbt,20,WALL_BANNER:5,../../NBT/Banners/viking_wealthy_2.nbt,20,WALL_BANNER:5,../../NBT/Banners/viking_wealthy_3.nbt,20,WALL_BANNER:5,../../NBT/Banners/viking_wealthy_4.nbt,20,WALL_BANNER:5,../../NBT/Banners/viking_wealthy_5.nbt,20,WALL_BANNER:5,../../NBT/Banners/viking_wealthy_6.nbt,20,WALL_BANNER:5,../../NBT/Banners/viking_wealthy_7.nbt,20,WALL_BANNER:5,../../NBT/Banners/viking_wealthy_8.nbt,20,WALL_BANNER:5,../../NBT/Banners/viking_wealthy_9.nbt,100)
Block(-4,6,5,DARK_OAK_FENCE:0)
Block(-4,6,6,SPRUCE_WOOD_STAIRS:5)
Block(-4,7,-7,SPRUCE_WOOD_STAIRS:0)
Block(-4,7,-6,SPRUCE_WOOD_STAIRS:0)
Block(-4,7,-5,SPRUCE_WOOD_STAIRS:0)
Block(-4,7,-4,SPRUCE_WOOD_STAIRS:0)
Block(-4,7,-3,SPRUCE_WOOD_STAIRS:0)
Block(-4,7,-2,SPRUCE_WOOD_STAIRS:0)
Block(-4,7,-1,SPRUCE_WOOD_STAIRS:0)
Block(-4,7,3,SPRUCE_WOOD_STAIRS:0)
Block(-4,7,4,SPRUCE_WOOD_STAIRS:0)
Block(-4,7,5,SPRUCE_WOOD_STAIRS:0)
Block(-4,7,6,SPRUCE_WOOD_STAIRS:0)
Block(-4,8,0,WOOD_STEP:1)
Block(-4,8,1,LOG:5)
Block(-4,8,2,WOOD_STEP:1)
Block(-3,0,-7,COBBLESTONE:0)
Block(-3,0,-6,COBBLESTONE:0)
Block(-3,0,-5,COBBLESTONE:0)
Block(-3,0,-4,COBBLESTONE:0)
Block(-3,0,-3,COBBLESTONE:0)
Block(-3,0,-2,COBBLESTONE:0)
Block(-3,0,-1,COBBLESTONE:0)
Block(-3,0,0,COBBLESTONE:0)
Block(-3,0,1,COBBLESTONE:0)
Block(-3,0,2,COBBLESTONE:0)
Block(-3,0,3,COBBLESTONE:0)
Block(-3,0,4,COBBLESTONE:0)
Block(-3,0,5,COBBLESTONE:0)
Block(-3,1,-7,COBBLESTONE:0)
Block(-3,1,-6,COBBLESTONE:0)
Block(-3,1,-5,COBBLESTONE:0)
Block(-3,1,-4,COBBLESTONE:0)
Block(-3,1,-3,COBBLESTONE:0)
Block(-3,1,-2,COBBLESTONE:0)
Block(-3,1,-1,COBBLESTONE:0)
Block(-3,1,0,COBBLESTONE:0)
Block(-3,1,1,COBBLESTONE:0)
Block(-3,1,2,WOOD:5)
Block(-3,1,3,WOOD:5)
Block(-3,1,4,COBBLESTONE:0)
Block(-3,1,5,COBBLESTONE:0)
Block(-3,2,-7,WOOD:5)
Block(-3,2,-6,WOOD:5)
Block(-3,2,-5,WOOD:5)
Block(-3,2,-4,WOOD:5)
Block(-3,2,-3,COBBLESTONE:0)
Block(-3,2,-2,COBBLESTONE:0)
Block(-3,2,-1,DARK_OAK_DOOR:1)
Block(-3,2,0,DARK_OAK_DOOR:3)
Block(-3,2,1,COBBLESTONE:0)
Block(-3,2,2,DARK_OAK_DOOR:1)
Block(-3,2,3,DARK_OAK_DOOR:3)
Block(-3,2,4,COBBLESTONE:0)
Block(-3,2,5,COBBLESTONE:0)
Block(-3,3,-7,STATIONARY_WATER:0)
Block(-3,3,-6,STATIONARY_WATER:0)
Block(-3,3,-5,STATIONARY_WATER:0)
Block(-3,3,-4,WOOD:5)
Block(-3,3,-3,CAULDRON:0)
Block(-3,3,-1,DARK_OAK_DOOR:8)
Block(-3,3,0,DARK_OAK_DOOR:9)
Block(-3,3,2,DARK_OAK_DOOR:8)
Block(-3,3,3,DARK_OAK_DOOR:9)
Block(-3,3,5,WOOD:1)
Block(-3,4,-7,STATIONARY_WATER:0)
Block(-3,4,-6,STATIONARY_WATER:0)
Block(-3,4,-5,STATIONARY_WATER:0)
Block(-3,4,-4,WOOD:5)
Block(-3,4,-3,TRIPWIRE_HOOK:0)
Block(-3,4,5,SPRUCE_WOOD_STAIRS:1)
Block(-3,5,-4,WOOD:5)
RandomBlock(-3,5,4,WALL_BANNER:2,../../NBT/Banners/viking_wealthy_1.nbt,20,WALL_BANNER:2,../../NBT/Banners/viking_wealthy_2.nbt,20,WALL_BANNER:2,../../NBT/Banners/viking_wealthy_3.nbt,20,WALL_BANNER:2,../../NBT/Banners/viking_wealthy_4.nbt,20,WALL_BANNER:2,../../NBT/Banners/viking_wealthy_5.nbt,20,WALL_BANNER:2,../../NBT/Banners/viking_wealthy_6.nbt,20,WALL_BANNER:2,../../NBT/Banners/viking_wealthy_7.nbt,20,WALL_BANNER:2,../../NBT/Banners/viking_wealthy_8.nbt,20,WALL_BANNER:2,../../NBT/Banners/viking_wealthy_9.nbt,100)
Block(-3,5,5,WOOD:1)
Block(-3,6,-7,WOOD_STEP:1)
Block(-3,6,-6,WOOD_STEP:1)
Block(-3,6,-5,WOOD_STEP:1)
Block(-3,6,-4,WOOD_STEP:1)
Block(-3,6,-3,DARK_OAK_FENCE:0)
RandomBlock(-3,6,4,WALL_BANNER:2,../../NBT/Banners/viking_regular_1.nbt,20,WALL_BANNER:2,../../NBT/Banners/viking_regular_2.nbt,20,WALL_BANNER:2,../../NBT/Banners/viking_regular_3.nbt,20,WALL_BANNER:2,../../NBT/Banners/viking_regular_4.nbt,20,WALL_BANNER:2,../../NBT/Banners/viking_regular_5.nbt,20,WALL_BANNER:2,../../NBT/Banners/viking_regular_6.nbt,20,WALL_BANNER:2,../../NBT/Banners/viking_regular_7.nbt,20,WALL_BANNER:2,../../NBT/Banners/viking_regular_8.nbt,100)
Block(-3,6,5,WOOD:1)
Block(-3,7,-3,SPRUCE_WOOD_STAIRS:5)
RandomBlock(-3,7,-1,WALL_BANNER:5,../../NBT/Banners/viking_regular_1.nbt,20,WALL_BANNER:5,../../NBT/Banners/viking_regular_2.nbt,20,WALL_BANNER:5,../../NBT/Banners/viking_regular_3.nbt,20,WALL_BANNER:5,../../NBT/Banners/viking_regular_4.nbt,20,WALL_BANNER:5,../../NBT/Banners/viking_regular_5.nbt,20,WALL_BANNER:5,../../NBT/Banners/viking_regular_6.nbt,20,WALL_BANNER:5,../../NBT/Banners/viking_regular_7.nbt,20,WALL_BANNER:5,../../NBT/Banners/viking_regular_8.nbt,100)
Block(-3,7,5,DARK_OAK_FENCE:0)
Block(-3,7,6,SPRUCE_WOOD_STAIRS:5)
Block(-3,8,-7,SPRUCE_WOOD_STAIRS:0)
Block(-3,8,-6,SPRUCE_WOOD_STAIRS:0)
Block(-3,8,-5,SPRUCE_WOOD_STAIRS:0)
Block(-3,8,-4,SPRUCE_WOOD_STAIRS:0)
Block(-3,8,-3,SPRUCE_WOOD_STAIRS:0)
Block(-3,8,-2,SPRUCE_WOOD_STAIRS:0)
Block(-3,8,-1,SPRUCE_WOOD_STAIRS:0)
Block(-3,8,0,SPRUCE_WOOD_STAIRS:0)
Block(-3,8,1,LOG:5)
Block(-3,8,2,SPRUCE_WOOD_STAIRS:0)
Block(-3,8,3,SPRUCE_WOOD_STAIRS:0)
Block(-3,8,4,SPRUCE_WOOD_STAIRS:0)
Block(-3,8,5,SPRUCE_WOOD_STAIRS:0)
Block(-3,8,6,SPRUCE_WOOD_STAIRS:0)
Block(-2,0,-7,COBBLESTONE:0)
Block(-2,0,-6,COBBLESTONE:0)
Block(-2,0,-5,COBBLESTONE:0)
Block(-2,0,-4,COBBLESTONE:0)
Block(-2,0,-3,COBBLESTONE:0)
Block(-2,0,-2,COBBLESTONE:0)
Block(-2,0,-1,COBBLESTONE:0)
Block(-2,0,0,COBBLESTONE:0)
Block(-2,0,1,COBBLESTONE:0)
Block(-2,0,2,COBBLESTONE:0)
Block(-2,0,3,COBBLESTONE:0)
Block(-2,0,4,COBBLESTONE:0)
Block(-2,0,5,COBBLESTONE:0)
Block(-2,1,-7,COBBLESTONE:0)
Block(-2,1,-6,COBBLESTONE:0)
Block(-2,1,-5,COBBLESTONE:0)
Block(-2,1,-4,COBBLESTONE:0)
Block(-2,1,-3,COBBLESTONE:0)
Block(-2,1,-2,COBBLESTONE:0)
Block(-2,1,-1,COBBLESTONE:0)
Block(-2,1,0,COBBLESTONE:0)
Block(-2,1,1,COBBLESTONE:0)
Block(-2,1,2,COBBLESTONE:0)
Block(-2,1,3,COBBLESTONE:0)
Block(-2,1,4,COBBLESTONE:0)
Block(-2,1,5,COBBLESTONE:0)
Block(-2,2,-7,WOOD:5)
Block(-2,2,-6,WOOD:5)
Block(-2,2,-5,WOOD:5)
Block(-2,2,-4,WOOD:5)
Block(-2,2,-3,COBBLESTONE:0)
Block(-2,2,-2,COBBLESTONE:0)
Block(-2,2,-1,WOOD:5)
Block(-2,2,0,WOOD:5)
Block(-2,2,1,COBBLESTONE:0)
Block(-2,2,2,WOOD:5)
Block(-2,2,3,WOOD:5)
Block(-2,2,4,COBBLESTONE:0)
Block(-2,2,5,COBBLESTONE:0)
Block(-2,3,-7,STATIONARY_WATER:0)
Block(-2,3,-6,STATIONARY_WATER:0)
Block(-2,3,-5,STATIONARY_WATER:0)
Block(-2,3,-4,WOOD:5)
Block(-2,3,-3,CAULDRON:0)
Block(-2,3,-1,DARK_OAK_STAIRS:1)
Block(-2,3,0,DARK_OAK_STAIRS:1)
Block(-2,3,2,DARK_OAK_STAIRS:1)
Block(-2,3,3,DARK_OAK_STAIRS:1)
Block(-2,3,5,WOOD:1)
Block(-2,4,-7,STATIONARY_WATER:0)
Block(-2,4,-6,STATIONARY_WATER:0)
Block(-2,4,-5,STATIONARY_WATER:0)
Block(-2,4,-4,WOOD:5)
Block(-2,4,-3,TRIPWIRE_HOOK:0)
Block(-2,4,5,SPRUCE_WOOD_STAIRS:0)
Block(-2,5,-4,WOOD:5)
RandomBlock(-2,5,4,WALL_BANNER:2,../../NBT/Banners/viking_wealthy_1.nbt,20,WALL_BANNER:2,../../NBT/Banners/viking_wealthy_2.nbt,20,WALL_BANNER:2,../../NBT/Banners/viking_wealthy_3.nbt,20,WALL_BANNER:2,../../NBT/Banners/viking_wealthy_4.nbt,20,WALL_BANNER:2,../../NBT/Banners/viking_wealthy_5.nbt,20,WALL_BANNER:2,../../NBT/Banners/viking_wealthy_6.nbt,20,WALL_BANNER:2,../../NBT/Banners/viking_wealthy_7.nbt,20,WALL_BANNER:2,../../NBT/Banners/viking_wealthy_8.nbt,20,WALL_BANNER:2,../../NBT/Banners/viking_wealthy_9.nbt,100)
Block(-2,5,5,WOOD:1)
Block(-2,6,-7,TRAP_DOOR:1)
Block(-2,6,-6,TRAP_DOOR:0)
Block(-2,6,-5,WOOD_STEP:1)
Block(-2,6,-4,WOOD_STEP:1)
Block(-2,6,-3,DARK_OAK_FENCE:0)
Block(-2,6,5,WOOD:1)
Block(-2,7,-3,DARK_OAK_FENCE:0)
Block(-2,7,5,WOOD:1)
Block(-2,8,-3,SPRUCE_WOOD_STAIRS:5)
Block(-2,8,1,LOG:5)
Block(-2,8,5,DARK_OAK_FENCE:0)
Block(-2,8,6,SPRUCE_WOOD_STAIRS:5)
Block(-2,9,-7,WOOD_STEP:1)
Block(-2,9,-6,WOOD_STEP:1)
Block(-2,9,-5,WOOD_STEP:1)
Block(-2,9,-4,WOOD_STEP:1)
Block(-2,9,-3,WOOD_STEP:1)
Block(-2,9,-2,WOOD_STEP:1)
Block(-2,9,-1,WOOD_STEP:1)
Block(-2,9,0,WOOD_STEP:1)
Block(-2,9,1,WOOD_STEP:1)
Block(-2,9,2,WOOD_STEP:1)
Block(-2,9,3,WOOD_STEP:1)
Block(-2,9,4,WOOD_STEP:1)
Block(-2,9,5,WOOD_STEP:1)
Block(-2,9,6,SPRUCE_WOOD_STAIRS:0)
Block(-2,10,6,WOOD_STEP:1)
Block(-1,0,-7,COBBLESTONE:0)
Block(-1,0,-6,COBBLESTONE:0)
Block(-1,0,-5,COBBLESTONE:0)
Block(-1,0,-4,COBBLESTONE:0)
Block(-1,0,-3,COBBLESTONE:0)
Block(-1,0,-2,COBBLESTONE:0)
Block(-1,0,-1,COBBLESTONE:0)
Block(-1,0,0,COBBLESTONE:0)
Block(-1,0,1,COBBLESTONE:0)
Block(-1,0,2,COBBLESTONE:0)
Block(-1,0,3,COBBLESTONE:0)
Block(-1,0,4,COBBLESTONE:0)
Block(-1,0,5,COBBLESTONE:0)
Block(-1,1,-7,COBBLESTONE:0)
Block(-1,1,-6,COBBLESTONE:0)
Block(-1,1,-5,COBBLESTONE:0)
Block(-1,1,-4,COBBLESTONE:0)
Block(-1,1,-3,COBBLESTONE:0)
Block(-1,1,-2,COBBLESTONE:0)
Block(-1,1,-1,COBBLESTONE:0)
Block(-1,1,0,COBBLESTONE:0)
Block(-1,1,1,COBBLESTONE:0)
Block(-1,1,2,COBBLESTONE:0)
Block(-1,1,3,COBBLESTONE:0)
Block(-1,1,4,COBBLESTONE:0)
Block(-1,1,5,COBBLESTONE:0)
Block(-1,2,-7,WOOD:5)
Block(-1,2,-6,WOOD:5)
Block(-1,2,-5,WOOD:5)
Block(-1,2,-4,COBBLESTONE:0)
Block(-1,2,-3,COBBLESTONE:0)
Block(-1,2,-2,COBBLESTONE:0)
Block(-1,2,-1,COBBLESTONE:0)
Block(-1,2,0,COBBLESTONE:0)
Block(-1,2,1,COBBLESTONE:0)
Block(-1,2,2,COBBLESTONE:0)
Block(-1,2,3,COBBLESTONE:0)
Block(-1,2,4,COBBLESTONE:0)
Block(-1,2,5,LOG:1)
Block(-1,3,-7,STATIONARY_WATER:0)
Block(-1,3,-6,STATIONARY_WATER:0)
Block(-1,3,-5,WOOD:5)
Block(-1,3,-3,LOG:1)
Block(-1,3,1,AIR:0)
Block(-1,3,3,AIR:0)
Block(-1,3,4,DARK_OAK_FENCE:0)
Block(-1,3,5,LOG:1)
Block(-1,3,6,WOOD_BUTTON:3)
Block(-1,4,-7,STATIONARY_WATER:0)
Block(-1,4,-6,STATIONARY_WATER:0)
Block(-1,4,-5,WOOD:5)
Block(-1,4,-3,LOG:1)
RandomBlock(-1,4,4,WALL_BANNER:2,../../NBT/Banners/viking_wealthy_1.nbt,20,WALL_BANNER:2,../../NBT/Banners/viking_wealthy_2.nbt,20,WALL_BANNER:2,../../NBT/Banners/viking_wealthy_3.nbt,20,WALL_BANNER:2,../../NBT/Banners/viking_wealthy_4.nbt,20,WALL_BANNER:2,../../NBT/Banners/viking_wealthy_5.nbt,20,WALL_BANNER:2,../../NBT/Banners/viking_wealthy_6.nbt,20,WALL_BANNER:2,../../NBT/Banners/viking_wealthy_7.nbt,20,WALL_BANNER:2,../../NBT/Banners/viking_wealthy_8.nbt,20,WALL_BANNER:2,../../NBT/Banners/viking_wealthy_9.nbt,100)
Block(-1,4,5,LOG:1)
Block(-1,4,6,WOOD_BUTTON:3)
Block(-1,5,-5,WOOD:5)
Block(-1,5,-3,LOG:1)
Block(-1,5,5,LOG:1)
Block(-1,5,6,WOOD_BUTTON:3)
Block(-1,6,-7,TRAP_DOOR:1)
Block(-1,6,-6,TRAP_DOOR:0)
Block(-1,6,-5,WOOD_STEP:1)
Block(-1,6,-3,LOG:1)
Block(-1,6,-2,LOG:9)
Block(-1,6,-1,LOG:9)
Block(-1,6,0,LOG:9)
Block(-1,6,1,LOG:9)
Block(-1,6,2,LOG:9)
Block(-1,6,3,LOG:9)
Block(-1,6,4,LOG:9)
Block(-1,6,5,LOG:1)
Block(-1,6,6,WOOD_BUTTON:3)
Block(-1,7,-3,LOG:1)
Block(-1,7,1,LOG:1)
Block(-1,7,5,LOG:1)
Block(-1,7,6,WOOD_BUTTON:3)
Block(-1,8,-3,LOG:1)
Block(-1,8,1,LOG:1)
Block(-1,8,5,LOG:1)
Block(-1,8,6,WOOD_BUTTON:3)
Block(-1,9,-7,LOG:9)
Block(-1,9,-6,LOG:9)
Block(-1,9,-5,LOG:9)
Block(-1,9,-4,LOG:9)
Block(-1,9,-3,LOG:9)
Block(-1,9,-2,LOG:9)
Block(-1,9,-1,LOG:9)
Block(-1,9,0,LOG:9)
Block(-1,9,1,LOG:9)
Block(-1,9,2,LOG:9)
Block(-1,9,3,LOG:9)
Block(-1,9,4,LOG:9)
Block(-1,9,5,LOG:9)
Block(-1,9,6,LOG:9)
Block(-1,9,7,LOG:9)
Block(-1,9,8,WOOD_BUTTON:3)
Block(0,0,-7,COBBLESTONE:0)
Block(0,0,-6,COBBLESTONE:0)
Block(0,0,-5,COBBLESTONE:0)
Block(0,0,-4,COBBLESTONE:0)
Block(0,0,-3,COBBLESTONE:0)
Block(0,0,-2,COBBLESTONE:0)
Block(0,0,-1,COBBLESTONE:0)
Block(0,0,0,COBBLESTONE:0)
Block(0,0,1,COBBLESTONE:0)
Block(0,0,2,COBBLESTONE:0)
Block(0,0,3,COBBLESTONE:0)
Block(0,0,4,COBBLESTONE:0)
Block(0,0,5,COBBLESTONE:0)
Block(0,1,-7,COBBLESTONE:0)
Block(0,1,-6,COBBLESTONE:0)
Block(0,1,-5,COBBLESTONE:0)
Block(0,1,-4,COBBLESTONE:0)
Block(0,1,-3,COBBLESTONE:0)
Block(0,1,-2,COBBLESTONE:0)
Block(0,1,-1,COBBLESTONE:0)
Block(0,1,0,COBBLESTONE:0)
Block(0,1,1,COBBLESTONE:0)
Block(0,1,2,COBBLESTONE:0)
Block(0,1,3,COBBLESTONE:0)
Block(0,1,4,COBBLESTONE:0)
Block(0,1,5,COBBLESTONE:0)
Block(0,2,-7,WOOD:5)
Block(0,2,-6,WOOD:5)
Block(0,2,-5,COBBLESTONE:0)
Block(0,2,-4,COBBLESTONE:0)
Block(0,2,-3,COBBLESTONE:0)
Block(0,2,-2,COBBLESTONE:0)
Block(0,2,-1,COBBLESTONE:0)
Block(0,2,0,COBBLESTONE:0)
Block(0,2,1,COBBLESTONE:0)
Block(0,2,2,COBBLESTONE:0)
Block(0,2,3,COBBLESTONE:0)
Block(0,2,4,COBBLESTONE:0)
Block(0,2,5,COBBLESTONE:0)
Block(0,3,-7,WOOD:5)
Block(0,3,-6,WOOD:5)
Block(0,3,-5,DARK_OAK_FENCE:0)
Block(0,3,5,WOOD:1)
Block(0,4,-7,WOOD:5)
Block(0,4,-6,WOOD:5)
Block(0,4,-5,TORCH:5)
RandomBlock(0,4,-3,WALL_BANNER:5,../../NBT/Banners/viking_regular_1.nbt,20,WALL_BANNER:5,../../NBT/Banners/viking_regular_2.nbt,20,WALL_BANNER:5,../../NBT/Banners/viking_regular_3.nbt,20,WALL_BANNER:5,../../NBT/Banners/viking_regular_4.nbt,20,WALL_BANNER:5,../../NBT/Banners/viking_regular_5.nbt,20,WALL_BANNER:5,../../NBT/Banners/viking_regular_6.nbt,20,WALL_BANNER:5,../../NBT/Banners/viking_regular_7.nbt,20,WALL_BANNER:5,../../NBT/Banners/viking_regular_8.nbt,100)
Block(0,4,5,WOOD:1)
Block(0,5,-7,WOOD:5)
Block(0,5,-6,WOOD:5)
Block(0,5,-3,DARK_OAK_FENCE:0)
Block(0,5,5,WOOD:1)
Block(0,6,-7,WOOD_STEP:1)
Block(0,6,-6,WOOD_STEP:1)
Block(0,6,-3,DARK_OAK_FENCE:0)
RandomBlock(0,6,-2,WALL_BANNER:3,../../NBT/Banners/viking_regular_1.nbt,20,WALL_BANNER:3,../../NBT/Banners/viking_regular_2.nbt,20,WALL_BANNER:3,../../NBT/Banners/viking_regular_3.nbt,20,WALL_BANNER:3,../../NBT/Banners/viking_regular_4.nbt,20,WALL_BANNER:3,../../NBT/Banners/viking_regular_5.nbt,20,WALL_BANNER:3,../../NBT/Banners/viking_regular_6.nbt,20,WALL_BANNER:3,../../NBT/Banners/viking_regular_7.nbt,20,WALL_BANNER:3,../../NBT/Banners/viking_regular_8.nbt,100)
RandomBlock(0,6,4,WALL_BANNER:2,../../NBT/Banners/viking_regular_1.nbt,20,WALL_BANNER:2,../../NBT/Banners/viking_regular_2.nbt,20,WALL_BANNER:2,../../NBT/Banners/viking_regular_3.nbt,20,WALL_BANNER:2,../../NBT/Banners/viking_regular_4.nbt,20,WALL_BANNER:2,../../NBT/Banners/viking_regular_5.nbt,20,WALL_BANNER:2,../../NBT/Banners/viking_regular_6.nbt,20,WALL_BANNER:2,../../NBT/Banners/viking_regular_7.nbt,20,WALL_BANNER:2,../../NBT/Banners/viking_regular_8.nbt,100)
Block(0,6,5,WOOD:1)
Block(0,7,-3,DARK_OAK_FENCE:0)
Block(0,7,5,WOOD:1)
Block(0,8,-3,SPRUCE_WOOD_STAIRS:4)
Block(0,8,0,SPRUCE_WOOD_STAIRS:4)
Block(0,8,2,SPRUCE_WOOD_STAIRS:4)
Block(0,8,5,DARK_OAK_FENCE:0)
Block(0,8,6,SPRUCE_WOOD_STAIRS:4)
Block(0,9,-7,WOOD_STEP:1)
Block(0,9,-6,WOOD_STEP:1)
Block(0,9,-5,WOOD_STEP:1)
Block(0,9,-4,WOOD_STEP:1)
Block(0,9,-3,WOOD_STEP:1)
Block(0,9,-2,WOOD_STEP:1)
Block(0,9,-1,WOOD_STEP:1)
Block(0,9,0,WOOD_STEP:1)
Block(0,9,1,WOOD_STEP:1)
Block(0,9,2,WOOD_STEP:1)
Block(0,9,3,WOOD_STEP:1)
Block(0,9,4,WOOD_STEP:1)
Block(0,9,5,WOOD_STEP:1)
Block(0,9,6,SPRUCE_WOOD_STAIRS:1)
Block(0,10,6,WOOD_STEP:1)
Block(1,0,-7,COBBLESTONE:0)
Block(1,0,-6,COBBLESTONE:0)
Block(1,0,-5,COBBLESTONE:0)
Block(1,0,-4,COBBLESTONE:0)
Block(1,0,-3,COBBLESTONE:0)
Block(1,0,-2,COBBLESTONE:0)
Block(1,0,-1,COBBLESTONE:0)
Block(1,0,0,COBBLESTONE:0)
Block(1,0,1,COBBLESTONE:0)
Block(1,0,2,COBBLESTONE:0)
Block(1,0,3,COBBLESTONE:0)
Block(1,0,4,COBBLESTONE:0)
Block(1,0,5,COBBLESTONE:0)
Block(1,1,-7,COBBLESTONE:0)
Block(1,1,-6,COBBLESTONE:0)
Block(1,1,-5,COBBLESTONE:0)
Block(1,1,-4,COBBLESTONE:0)
Block(1,1,-3,COBBLESTONE:0)
Block(1,1,-2,COBBLESTONE:0)
Block(1,1,-1,COBBLESTONE:0)
Block(1,1,0,COBBLESTONE:0)
Block(1,1,1,COBBLESTONE:0)
Block(1,1,2,COBBLESTONE:0)
Block(1,1,3,COBBLESTONE:0)
Block(1,1,4,COBBLESTONE:0)
Block(1,1,5,COBBLESTONE:0)
Block(1,2,-7,COBBLESTONE:0)
Block(1,2,-6,COBBLESTONE:0)
Block(1,2,-5,COBBLESTONE:0)
Block(1,2,-4,COBBLESTONE:0)
Block(1,2,-3,COBBLESTONE:0)
Block(1,2,-2,COBBLESTONE:0)
Block(1,2,-1,COBBLESTONE:0)
Block(1,2,0,COBBLESTONE:0)
Block(1,2,1,COBBLESTONE_STAIRS:1)
Block(1,2,2,COBBLESTONE:0)
Block(1,2,3,COBBLESTONE:0)
Block(1,2,4,COBBLESTONE:0)
Block(1,2,5,COBBLESTONE:0)
Block(1,3,-6,SPRUCE_WOOD_STAIRS:6)
Block(1,3,-5,SPRUCE_WOOD_STAIRS:3)
Block(1,3,0,BRICK:0)
Block(1,3,1,STEP:12)
Block(1,3,2,BRICK:0)
Block(1,3,5,SPRUCE_DOOR:1)
Block(1,4,-7,SPRUCE_WOOD_STAIRS:6)
Block(1,4,-6,SPRUCE_WOOD_STAIRS:3)
Block(1,4,0,IRON_TRAPDOOR:2)
Block(1,4,1,IRON_TRAPDOOR:1)
Block(1,4,2,IRON_TRAPDOOR:2)
Block(1,4,5,SPRUCE_DOOR:8)
Block(1,5,-7,SPRUCE_WOOD_STAIRS:3)
Block(1,5,-3,DARK_OAK_FENCE:0)
RandomBlock(1,5,-2,WALL_BANNER:3,../../NBT/Banners/viking_wealthy_1.nbt,20,WALL_BANNER:3,../../NBT/Banners/viking_wealthy_2.nbt,20,WALL_BANNER:3,../../NBT/Banners/viking_wealthy_3.nbt,20,WALL_BANNER:3,../../NBT/Banners/viking_wealthy_4.nbt,20,WALL_BANNER:3,../../NBT/Banners/viking_wealthy_5.nbt,20,WALL_BANNER:3,../../NBT/Banners/viking_wealthy_6.nbt,20,WALL_BANNER:3,../../NBT/Banners/viking_wealthy_7.nbt,20,WALL_BANNER:3,../../NBT/Banners/viking_wealthy_8.nbt,20,WALL_BANNER:3,../../NBT/Banners/viking_wealthy_9.nbt,100)
RandomBlock(1,5,4,WALL_BANNER:2,../../NBT/Banners/viking_regular_1.nbt,20,WALL_BANNER:2,../../NBT/Banners/viking_regular_2.nbt,20,WALL_BANNER:2,../../NBT/Banners/viking_regular_3.nbt,20,WALL_BANNER:2,../../NBT/Banners/viking_regular_4.nbt,20,WALL_BANNER:2,../../NBT/Banners/viking_regular_5.nbt,20,WALL_BANNER:2,../../NBT/Banners/viking_regular_6.nbt,20,WALL_BANNER:2,../../NBT/Banners/viking_regular_7.nbt,20,WALL_BANNER:2,../../NBT/Banners/viking_regular_8.nbt,100)
Block(1,5,5,WOOD:1)
Block(1,6,-3,DARK_OAK_FENCE:0)
Block(1,6,5,WOOD:1)
Block(1,7,-3,SPRUCE_WOOD_STAIRS:4)
Block(1,7,0,BRICK_STAIRS:4)
Block(1,7,2,BRICK_STAIRS:4)
Block(1,7,5,DARK_OAK_FENCE:0)
Block(1,7,6,SPRUCE_WOOD_STAIRS:4)
Block(1,8,-7,SPRUCE_WOOD_STAIRS:1)
Block(1,8,-6,SPRUCE_WOOD_STAIRS:1)
Block(1,8,-5,SPRUCE_WOOD_STAIRS:1)
Block(1,8,-4,SPRUCE_WOOD_STAIRS:1)
Block(1,8,-3,SPRUCE_WOOD_STAIRS:1)
Block(1,8,-2,SPRUCE_WOOD_STAIRS:1)
Block(1,8,-1,SPRUCE_WOOD_STAIRS:1)
Block(1,8,0,BRICK_STAIRS:1)
Block(1,8,1,BRICK_STAIRS:1)
Block(1,8,2,BRICK_STAIRS:1)
Block(1,8,3,SPRUCE_WOOD_STAIRS:1)
Block(1,8,4,SPRUCE_WOOD_STAIRS:1)
Block(1,8,5,SPRUCE_WOOD_STAIRS:1)
Block(1,8,6,SPRUCE_WOOD_STAIRS:1)
Block(1,9,0,SPRUCE_WOOD_STAIRS:0)
Block(1,9,1,SPRUCE_WOOD_STAIRS:0)
Block(1,9,2,SPRUCE_WOOD_STAIRS:0)
Block(2,0,-7,COBBLESTONE:0)
Block(2,0,-6,COBBLESTONE:0)
Block(2,0,-5,COBBLESTONE:0)
Block(2,0,-4,COBBLESTONE:0)
Block(2,0,-3,COBBLESTONE:0)
Block(2,0,-2,COBBLESTONE:0)
Block(2,0,-1,COBBLESTONE:0)
Block(2,0,0,COBBLESTONE:0)
Block(2,0,1,COBBLESTONE:0)
Block(2,0,2,COBBLESTONE:0)
Block(2,0,3,COBBLESTONE:0)
Block(2,0,4,COBBLESTONE:0)
Block(2,0,5,COBBLESTONE:0)
Block(2,1,-7,COBBLESTONE:0)
Block(2,1,-6,COBBLESTONE:0)
Block(2,1,-5,COBBLESTONE:0)
Block(2,1,-4,COBBLESTONE:0)
Block(2,1,-3,COBBLESTONE:0)
Block(2,1,-2,COBBLESTONE:0)
Block(2,1,-1,COBBLESTONE:0)
Block(2,1,0,COBBLESTONE:0)
Block(2,1,1,MAGMA:0)
Block(2,1,2,COBBLESTONE:0)
Block(2,1,3,COBBLESTONE:0)
Block(2,1,4,COBBLESTONE:0)
Block(2,1,5,COBBLESTONE:0)
Block(2,2,-7,COBBLESTONE:0)
Block(2,2,-6,COBBLESTONE:0)
Block(2,2,-5,COBBLESTONE:0)
Block(2,2,-4,COBBLESTONE:0)
Block(2,2,-3,COBBLESTONE:0)
Block(2,2,-2,COBBLESTONE:0)
Block(2,2,-1,COBBLESTONE:0)
Block(2,2,0,COBBLESTONE:0)
Block(2,2,1,FIRE:0)
Block(2,2,2,COBBLESTONE:0)
Block(2,2,3,COBBLESTONE:0)
Block(2,2,4,COBBLESTONE:0)
Block(2,2,5,COBBLESTONE:0)
Block(2,3,-3,DARK_OAK_FENCE:0)
Block(2,3,-2,CAULDRON:3)
Block(2,3,0,BRICK:0)
Block(2,3,2,BRICK:0)
Block(2,3,5,WOOD:1)
Block(2,4,-3,DARK_OAK_FENCE:0)
Block(2,4,-2,TRAP_DOOR:2)
Block(2,4,0,BRICK_STAIRS:2)
Block(2,4,2,BRICK_STAIRS:3)
RandomBlock(2,4,4,WALL_BANNER:2,../../NBT/Banners/viking_regular_1.nbt,20,WALL_BANNER:2,../../NBT/Banners/viking_regular_2.nbt,20,WALL_BANNER:2,../../NBT/Banners/viking_regular_3.nbt,20,WALL_BANNER:2,../../NBT/Banners/viking_regular_4.nbt,20,WALL_BANNER:2,../../NBT/Banners/viking_regular_5.nbt,20,WALL_BANNER:2,../../NBT/Banners/viking_regular_6.nbt,20,WALL_BANNER:2,../../NBT/Banners/viking_regular_7.nbt,20,WALL_BANNER:2,../../NBT/Banners/viking_regular_8.nbt,100)
Block(2,4,5,WOOD:1)
Block(2,5,-3,DARK_OAK_FENCE:0)
RandomBlock(2,5,-2,WALL_BANNER:3,../../NBT/Banners/viking_wealthy_1.nbt,20,WALL_BANNER:3,../../NBT/Banners/viking_wealthy_2.nbt,20,WALL_BANNER:3,../../NBT/Banners/viking_wealthy_3.nbt,20,WALL_BANNER:3,../../NBT/Banners/viking_wealthy_4.nbt,20,WALL_BANNER:3,../../NBT/Banners/viking_wealthy_5.nbt,20,WALL_BANNER:3,../../NBT/Banners/viking_wealthy_6.nbt,20,WALL_BANNER:3,../../NBT/Banners/viking_wealthy_7.nbt,20,WALL_BANNER:3,../../NBT/Banners/viking_wealthy_8.nbt,20,WALL_BANNER:3,../../NBT/Banners/viking_wealthy_9.nbt,100)
Block(2,5,0,BRICK_STAIRS:6)
Block(2,5,2,BRICK_STAIRS:7)
Block(2,5,5,WOOD:1)
Block(2,6,-3,SPRUCE_WOOD_STAIRS:4)
RandomBlock(2,6,-2,WALL_BANNER:4,../../NBT/Banners/viking_regular_1.nbt,20,WALL_BANNER:4,../../NBT/Banners/viking_regular_2.nbt,20,WALL_BANNER:4,../../NBT/Banners/viking_regular_3.nbt,20,WALL_BANNER:4,../../NBT/Banners/viking_regular_4.nbt,20,WALL_BANNER:4,../../NBT/Banners/viking_regular_5.nbt,20,WALL_BANNER:4,../../NBT/Banners/viking_regular_6.nbt,20,WALL_BANNER:4,../../NBT/Banners/viking_regular_7.nbt,20,WALL_BANNER:4,../../NBT/Banners/viking_regular_8.nbt,100)
Block(2,6,0,BRICK:0)
Block(2,6,2,BRICK:0)
Block(2,6,5,DARK_OAK_FENCE:0)
Block(2,6,6,SPRUCE_WOOD_STAIRS:4)
Block(2,7,-7,SPRUCE_WOOD_STAIRS:1)
Block(2,7,-6,SPRUCE_WOOD_STAIRS:1)
Block(2,7,-5,SPRUCE_WOOD_STAIRS:1)
Block(2,7,-4,SPRUCE_WOOD_STAIRS:1)
Block(2,7,-3,SPRUCE_WOOD_STAIRS:1)
Block(2,7,-2,SPRUCE_WOOD_STAIRS:1)
Block(2,7,-1,SPRUCE_WOOD_STAIRS:1)
Block(2,7,0,BRICK:0)
Block(2,7,2,BRICK:0)
Block(2,7,3,SPRUCE_WOOD_STAIRS:1)
Block(2,7,4,SPRUCE_WOOD_STAIRS:1)
Block(2,7,5,SPRUCE_WOOD_STAIRS:1)
Block(2,7,6,SPRUCE_WOOD_STAIRS:1)
Block(2,9,0,SPRUCE_WOOD_STAIRS:6)
Block(2,9,2,SPRUCE_WOOD_STAIRS:7)
Block(2,10,0,WOOD_STEP:1)
Block(2,10,1,WOOD_STEP:1)
Block(2,10,2,WOOD_STEP:1)
Block(3,0,-7,COBBLESTONE:0)
Block(3,0,-6,COBBLESTONE:0)
Block(3,0,-5,COBBLESTONE:0)
Block(3,0,-4,COBBLESTONE:0)
Block(3,0,-3,COBBLESTONE:0)
Block(3,0,-2,COBBLESTONE:0)
Block(3,0,-1,COBBLESTONE:0)
Block(3,0,0,COBBLESTONE:0)
Block(3,0,1,COBBLESTONE:0)
Block(3,0,2,COBBLESTONE:0)
Block(3,0,3,COBBLESTONE:0)
Block(3,0,4,COBBLESTONE:0)
Block(3,0,5,COBBLESTONE:0)
Block(3,1,-7,COBBLESTONE:0)
Block(3,1,-6,COBBLESTONE:0)
Block(3,1,-5,COBBLESTONE:0)
Block(3,1,-4,COBBLESTONE:0)
Block(3,1,-3,COBBLESTONE:0)
Block(3,1,-2,COBBLESTONE:0)
Block(3,1,-1,COBBLESTONE:0)
Block(3,1,0,COBBLESTONE:0)
Block(3,1,1,COBBLESTONE:0)
Block(3,1,2,COBBLESTONE:0)
Block(3,1,3,COBBLESTONE:0)
Block(3,1,4,COBBLESTONE:0)
Block(3,1,5,COBBLESTONE:0)
Block(3,2,-7,COBBLESTONE:0)
Block(3,2,-6,COBBLESTONE:0)
Block(3,2,-5,COBBLESTONE:0)
Block(3,2,-4,COBBLESTONE:0)
Block(3,2,-3,COBBLESTONE:0)
Block(3,2,-2,COBBLESTONE:0)
Block(3,2,-1,COBBLESTONE:0)
Block(3,2,0,COBBLESTONE:0)
Block(3,2,1,COBBLESTONE:0)
Block(3,2,2,COBBLESTONE:0)
Block(3,2,3,COBBLESTONE:0)
Block(3,2,4,COBBLESTONE:0)
Block(3,2,5,COBBLESTONE:0)
Block(3,3,-7,DARK_OAK_FENCE:0)
Block(3,3,-5,CAULDRON:3)
Block(3,3,-4,CAULDRON:3)
Block(3,3,-3,DARK_OAK_FENCE:0)
Block(3,3,-2,CAULDRON:0)
Block(3,3,-1,CAULDRON:0)
Block(3,3,0,BRICK:0)
Block(3,3,1,BRICK:0)
Block(3,3,2,BRICK:0)
Block(3,3,5,WOOD:1)
Block(3,4,-7,TORCH:5)
RandomBlock(3,4,-6,WALL_BANNER:4,../../NBT/Banners/viking_regular_1.nbt,20,WALL_BANNER:4,../../NBT/Banners/viking_regular_2.nbt,20,WALL_BANNER:4,../../NBT/Banners/viking_regular_3.nbt,20,WALL_BANNER:4,../../NBT/Banners/viking_regular_4.nbt,20,WALL_BANNER:4,../../NBT/Banners/viking_regular_5.nbt,20,WALL_BANNER:4,../../NBT/Banners/viking_regular_6.nbt,20,WALL_BANNER:4,../../NBT/Banners/viking_regular_7.nbt,20,WALL_BANNER:4,../../NBT/Banners/viking_regular_8.nbt,100)
Block(3,4,-5,TRAP_DOOR:0)
Block(3,4,-4,TRAP_DOOR:0)
Block(3,4,-3,DARK_OAK_FENCE:0)
Block(3,4,-2,TRAP_DOOR:2)
Block(3,4,-1,TRAP_DOOR:2)
Block(3,4,0,BRICK:0)
Block(3,4,1,BRICK:0)
Block(3,4,2,BRICK:0)
Block(3,4,5,WOOD:1)
RandomBlock(3,5,-7,WALL_BANNER:4,../../NBT/Banners/viking_regular_1.nbt,20,WALL_BANNER:4,../../NBT/Banners/viking_regular_2.nbt,20,WALL_BANNER:4,../../NBT/Banners/viking_regular_3.nbt,20,WALL_BANNER:4,../../NBT/Banners/viking_regular_4.nbt,20,WALL_BANNER:4,../../NBT/Banners/viking_regular_5.nbt,20,WALL_BANNER:4,../../NBT/Banners/viking_regular_6.nbt,20,WALL_BANNER:4,../../NBT/Banners/viking_regular_7.nbt,20,WALL_BANNER:4,../../NBT/Banners/viking_regular_8.nbt,100)
RandomBlock(3,5,-5,WALL_BANNER:4,../../NBT/Banners/viking_wealthy_1.nbt,20,WALL_BANNER:4,../../NBT/Banners/viking_wealthy_2.nbt,20,WALL_BANNER:4,../../NBT/Banners/viking_wealthy_3.nbt,20,WALL_BANNER:4,../../NBT/Banners/viking_wealthy_4.nbt,20,WALL_BANNER:4,../../NBT/Banners/viking_wealthy_5.nbt,20,WALL_BANNER:4,../../NBT/Banners/viking_wealthy_6.nbt,20,WALL_BANNER:4,../../NBT/Banners/viking_wealthy_7.nbt,20,WALL_BANNER:4,../../NBT/Banners/viking_wealthy_8.nbt,20,WALL_BANNER:4,../../NBT/Banners/viking_wealthy_9.nbt,100)
RandomBlock(3,5,-4,WALL_BANNER:4,../../NBT/Banners/viking_wealthy_1.nbt,20,WALL_BANNER:4,../../NBT/Banners/viking_wealthy_2.nbt,20,WALL_BANNER:4,../../NBT/Banners/viking_wealthy_3.nbt,20,WALL_BANNER:4,../../NBT/Banners/viking_wealthy_4.nbt,20,WALL_BANNER:4,../../NBT/Banners/viking_wealthy_5.nbt,20,WALL_BANNER:4,../../NBT/Banners/viking_wealthy_6.nbt,20,WALL_BANNER:4,../../NBT/Banners/viking_wealthy_7.nbt,20,WALL_BANNER:4,../../NBT/Banners/viking_wealthy_8.nbt,20,WALL_BANNER:4,../../NBT/Banners/viking_wealthy_9.nbt,100)
Block(3,5,-3,SPRUCE_WOOD_STAIRS:4)
Block(3,5,0,BRICK:0)
Block(3,5,1,BRICK:0)
Block(3,5,2,BRICK:0)
Block(3,5,5,DARK_OAK_FENCE:0)
Block(3,5,6,SPRUCE_WOOD_STAIRS:4)
Block(3,6,-7,SPRUCE_WOOD_STAIRS:1)
Block(3,6,-6,SPRUCE_WOOD_STAIRS:1)
Block(3,6,-5,SPRUCE_WOOD_STAIRS:1)
Block(3,6,-4,SPRUCE_WOOD_STAIRS:1)
Block(3,6,-3,SPRUCE_WOOD_STAIRS:1)
Block(3,6,-2,SPRUCE_WOOD_STAIRS:1)
Block(3,6,-1,SPRUCE_WOOD_STAIRS:1)
Block(3,6,0,BRICK:0)
Block(3,6,1,BRICK:0)
Block(3,6,2,BRICK:0)
Block(3,6,3,SPRUCE_WOOD_STAIRS:1)
Block(3,6,4,SPRUCE_WOOD_STAIRS:1)
Block(3,6,5,SPRUCE_WOOD_STAIRS:1)
Block(3,6,6,SPRUCE_WOOD_STAIRS:1)
Block(3,7,0,BRICK:0)
Block(3,7,1,BRICK:0)
Block(3,7,2,BRICK:0)
Block(3,8,0,BRICK_STAIRS:0)
Block(3,8,1,BRICK_STAIRS:0)
Block(3,8,2,BRICK_STAIRS:0)
Block(3,9,0,SPRUCE_WOOD_STAIRS:1)
Block(3,9,1,SPRUCE_WOOD_STAIRS:1)
Block(3,9,2,SPRUCE_WOOD_STAIRS:1)
Block(4,0,-7,COBBLESTONE:0)
Block(4,0,-6,COBBLESTONE:0)
Block(4,0,-5,COBBLESTONE:0)
Block(4,0,-4,COBBLESTONE:0)
Block(4,0,-3,LOG:1)
Block(4,0,-2,COBBLESTONE:0)
Block(4,0,-1,COBBLESTONE:0)
Block(4,0,0,COBBLESTONE:0)
Block(4,0,1,COBBLESTONE:0)
Block(4,0,2,COBBLESTONE:0)
Block(4,0,3,COBBLESTONE:0)
Block(4,0,4,COBBLESTONE:0)
Block(4,0,5,LOG:1)
Block(4,1,-7,COBBLESTONE:0)
Block(4,1,-6,COBBLESTONE:0)
Block(4,1,-5,COBBLESTONE:0)
Block(4,1,-4,COBBLESTONE:0)
Block(4,1,-3,LOG:1)
Block(4,1,-2,COBBLESTONE:0)
Block(4,1,-1,COBBLESTONE:0)
Block(4,1,0,COBBLESTONE:0)
Block(4,1,1,COBBLESTONE:0)
Block(4,1,2,COBBLESTONE:0)
Block(4,1,3,COBBLESTONE:0)
Block(4,1,4,COBBLESTONE:0)
Block(4,1,5,LOG:1)
Block(4,2,-7,COBBLESTONE:0)
Block(4,2,-6,COBBLESTONE:0)
Block(4,2,-5,COBBLESTONE:0)
Block(4,2,-4,COBBLESTONE:0)
Block(4,2,-3,LOG:1)
Block(4,2,-2,COBBLESTONE:0)
Block(4,2,-1,COBBLESTONE:0)
Block(4,2,0,COBBLESTONE:0)
Block(4,2,1,COBBLESTONE:0)
Block(4,2,2,COBBLESTONE:0)
Block(4,2,3,COBBLESTONE:0)
Block(4,2,4,COBBLESTONE:0)
Block(4,2,5,LOG:1)
Block(4,3,-7,WOOD:1)
Block(4,3,-6,WOOD:1)
Block(4,3,-5,WOOD:1)
Block(4,3,-4,WOOD:1)
Block(4,3,-3,LOG:1)
Block(4,3,-2,WOOD:1)
Block(4,3,-1,WOOD:1)
Block(4,3,0,WOOD:1)
Block(4,3,1,WOOD:1)
Block(4,3,2,WOOD:1)
Block(4,3,3,WOOD:1)
Block(4,3,4,WOOD:1)
Block(4,3,5,LOG:1)
Block(4,4,-7,DARK_OAK_FENCE:0)
Block(4,4,-6,DARK_OAK_FENCE:0)
Block(4,4,-5,DARK_OAK_FENCE:0)
Block(4,4,-4,DARK_OAK_FENCE:0)
Block(4,4,-3,LOG:1)
Block(4,4,-2,DARK_OAK_FENCE:0)
Block(4,4,-1,DARK_OAK_FENCE:0)
Block(4,4,0,DARK_OAK_FENCE:0)
Block(4,4,1,DARK_OAK_FENCE:0)
Block(4,4,2,DARK_OAK_FENCE:0)
Block(4,4,3,DARK_OAK_FENCE:0)
Block(4,4,4,DARK_OAK_FENCE:0)
Block(4,4,5,LOG:1)
Block(4,4,6,SPRUCE_WOOD_STAIRS:4)
Block(4,5,-7,SPRUCE_WOOD_STAIRS:1)
Block(4,5,-6,SPRUCE_WOOD_STAIRS:1)
Block(4,5,-5,SPRUCE_WOOD_STAIRS:1)
Block(4,5,-4,SPRUCE_WOOD_STAIRS:1)
Block(4,5,-3,SPRUCE_WOOD_STAIRS:1)
Block(4,5,-2,SPRUCE_WOOD_STAIRS:1)
Block(4,5,-1,SPRUCE_WOOD_STAIRS:1)
Block(4,5,0,SPRUCE_WOOD_STAIRS:1)
Block(4,5,1,SPRUCE_WOOD_STAIRS:1)
Block(4,5,2,SPRUCE_WOOD_STAIRS:1)
Block(4,5,3,SPRUCE_WOOD_STAIRS:1)
Block(4,5,4,SPRUCE_WOOD_STAIRS:1)
Block(4,5,5,SPRUCE_WOOD_STAIRS:1)
Block(4,5,6,SPRUCE_WOOD_STAIRS:1)
Block(4,8,0,SPRUCE_WOOD_STAIRS:1)
Block(4,8,1,SPRUCE_WOOD_STAIRS:1)
Block(4,8,2,SPRUCE_WOOD_STAIRS:1)
Block(5,4,-7,SPRUCE_WOOD_STAIRS:1)
Block(5,4,-6,SPRUCE_WOOD_STAIRS:1)
Block(5,4,-5,SPRUCE_WOOD_STAIRS:1)
Block(5,4,-4,SPRUCE_WOOD_STAIRS:1)
Block(5,4,-3,SPRUCE_WOOD_STAIRS:1)
Block(5,4,-2,SPRUCE_WOOD_STAIRS:1)
Block(5,4,-1,SPRUCE_WOOD_STAIRS:1)
Block(5,4,0,SPRUCE_WOOD_STAIRS:1)
Block(5,4,1,SPRUCE_WOOD_STAIRS:1)
Block(5,4,2,SPRUCE_WOOD_STAIRS:1)
Block(5,4,3,SPRUCE_WOOD_STAIRS:1)
Block(5,4,4,SPRUCE_WOOD_STAIRS:1)
Block(5,4,5,SPRUCE_WOOD_STAIRS:1)
Block(5,4,6,SPRUCE_WOOD_STAIRS:1)
Entity(-1,3,1,minecraft:villager,1)
Entity(-1,3,3,minecraft:villager,1)
