Author: NLBlackEagle
Description: No description given
SettingsMode: WriteDisable
Frequency: 0
SpawnHeight: highestBlock
UseCenterForHighestBlock: true
MinHeight: 0
MaxHeight: 255
InheritBO3: 
InheritBO3Rotation: NORTH
OverrideChildSettings: true
OverrideParentHeight: false
CanOverride: false
BranchFrequency: 0
BranchFrequencyGroup: 
MustBeBelowOther: false
MustBeInside: 
CannotBeInside: 
ReplacesBO3: 
MustBeInsideWorldBorders: false
CanSpawnOnWater: true
SpawnOnWaterOnly: false
SpawnUnderWater: false
SpawnAtWaterLevel: false
HeightOffset: 0
RemoveAir: true
ReplaceAbove: 
ReplaceBelow: 
ReplaceWithBiomeBlocks: true
ReplaceWithSurfaceBlock: GRASS
ReplaceWithGroundBlock: DIRT
ReplaceWithStoneBlock: STONE
SmoothRadius: 0
SmoothHeightOffset: 0
SmoothStartTop: false
SmoothStartWood: false
SmoothingSurfaceBlock: 
SmoothingGroundBlock: 
BO3Group: 
IsSpawnPoint: false
DoReplaceBlocks: true
Block(-8,0,-7,COBBLESTONE:0)
Block(-8,0,-6,COBBLESTONE:0)
Block(-8,0,-5,COBBLESTONE:0)
Block(-8,0,-4,COBBLESTONE:0)
Block(-8,0,-3,COBBLESTONE:0)
Block(-8,0,-2,COBBLESTONE:0)
Block(-8,0,-1,COBBLESTONE:0)
Block(-8,0,0,COBBLESTONE:0)
Block(-8,0,1,COBBLESTONE:0)
Block(-8,0,2,COBBLESTONE:0)
Block(-8,0,3,COBBLESTONE:0)
Block(-8,0,4,COBBLESTONE:0)
Block(-8,0,5,COBBLESTONE:0)
Block(-8,0,6,COBBLESTONE:0)
Block(-8,0,7,COBBLESTONE:0)
Block(-8,0,8,STONE:6)
Block(-8,1,-7,COBBLESTONE:0)
Block(-8,1,-6,COBBLESTONE:0)
Block(-8,1,-5,COBBLESTONE:0)
Block(-8,1,-4,COBBLESTONE:0)
Block(-8,1,-3,COBBLESTONE:0)
Block(-8,1,-2,COBBLESTONE:0)
Block(-8,1,-1,COBBLESTONE:0)
Block(-8,1,0,COBBLESTONE:0)
Block(-8,1,1,COBBLESTONE:0)
Block(-8,1,2,COBBLESTONE:0)
Block(-8,1,3,COBBLESTONE:0)
Block(-8,1,4,COBBLESTONE:0)
Block(-8,1,5,COBBLESTONE:0)
Block(-8,1,6,COBBLESTONE:0)
Block(-8,1,7,COBBLESTONE:0)
Block(-8,1,8,STONE:6)
Block(-8,2,-7,COBBLESTONE:0)
Block(-8,2,-6,COBBLESTONE:0)
Block(-8,2,-5,COBBLESTONE:0)
Block(-8,2,-4,COBBLESTONE:0)
Block(-8,2,-3,COBBLESTONE:0)
Block(-8,2,-2,COBBLESTONE:0)
Block(-8,2,-1,COBBLESTONE:0)
Block(-8,2,0,COBBLESTONE:0)
Block(-8,2,1,COBBLESTONE:0)
Block(-8,2,2,COBBLESTONE:0)
Block(-8,2,3,COBBLESTONE:0)
Block(-8,2,4,COBBLESTONE:0)
Block(-8,2,5,COBBLESTONE:0)
Block(-8,2,6,COBBLESTONE:0)
Block(-8,2,7,COBBLESTONE:0)
Block(-8,2,8,STONE:6)
Block(-8,3,-7,COBBLESTONE:0)
Block(-8,3,-6,COBBLESTONE:0)
Block(-8,3,-5,COBBLESTONE:0)
Block(-8,3,-4,COBBLESTONE:0)
Block(-8,3,-3,COBBLESTONE:0)
Block(-8,3,-2,COBBLESTONE:0)
Block(-8,3,-1,COBBLESTONE:0)
Block(-8,3,0,COBBLESTONE:0)
Block(-8,3,1,COBBLESTONE:0)
Block(-8,3,2,COBBLESTONE:0)
Block(-8,3,3,COBBLESTONE:0)
Block(-8,3,4,COBBLESTONE:0)
Block(-8,3,5,COBBLESTONE:0)
Block(-8,3,6,COBBLESTONE:0)
Block(-8,3,7,COBBLESTONE:0)
Block(-8,3,8,STONE:6)
Block(-8,4,-7,COBBLESTONE:0)
Block(-8,4,-6,COBBLESTONE:0)
Block(-8,4,-5,COBBLESTONE:0)
Block(-8,4,-4,COBBLESTONE:0)
Block(-8,4,-3,COBBLESTONE:0)
Block(-8,4,-2,COBBLESTONE:0)
Block(-8,4,-1,COBBLESTONE:0)
Block(-8,4,0,COBBLESTONE:0)
Block(-8,4,1,COBBLESTONE:0)
Block(-8,4,2,COBBLESTONE:0)
Block(-8,4,3,COBBLESTONE:0)
Block(-8,4,4,COBBLESTONE:0)
Block(-8,4,5,COBBLESTONE:0)
Block(-8,4,6,COBBLESTONE:0)
Block(-8,4,7,COBBLESTONE:0)
Block(-8,4,8,STONE:6)
Block(-8,5,-7,COBBLESTONE:0)
Block(-8,5,-6,COBBLESTONE:0)
Block(-8,5,-5,COBBLESTONE:0)
Block(-8,5,-4,COBBLESTONE:0)
Block(-8,5,-3,COBBLESTONE:0)
Block(-8,5,-2,COBBLESTONE:0)
Block(-8,5,-1,COBBLESTONE:0)
Block(-8,5,0,COBBLESTONE:0)
Block(-8,5,1,COBBLESTONE:0)
Block(-8,5,2,COBBLESTONE:0)
Block(-8,5,3,COBBLESTONE:0)
Block(-8,5,4,COBBLESTONE:0)
Block(-8,5,5,COBBLESTONE:0)
Block(-8,5,6,COBBLESTONE:0)
Block(-8,5,7,COBBLESTONE:0)
Block(-8,5,8,STONE:6)
Block(-8,6,-7,DARK_OAK_FENCE:0)
Block(-8,6,-6,CARPET:12)
Block(-8,6,-3,SPRUCE_WOOD_STAIRS:1)
Block(-8,6,-2,SPRUCE_WOOD_STAIRS:1)
Block(-8,6,-1,SPRUCE_WOOD_STAIRS:1)
Block(-8,6,1,SPRUCE_WOOD_STAIRS:1)
Block(-8,6,3,SPRUCE_WOOD_STAIRS:1)
Block(-8,6,5,SPRUCE_WOOD_STAIRS:1)
Block(-8,6,7,STONE:6)
Block(-8,6,8,SPRUCE_WOOD_STAIRS:5)
Block(-8,7,-7,DARK_OAK_FENCE:0)
Block(-8,7,7,STONE:6)
Block(-8,7,8,SPRUCE_WOOD_STAIRS:0)
Block(-8,8,-7,DARK_OAK_FENCE:0)
RandomBlock(-8,8,-6,WALL_BANNER:3,../../NBT/Banners/viking_honor_1.nbt,20,WALL_BANNER:3,../../NBT/Banners/viking_honor_2.nbt,20,WALL_BANNER:3,../../NBT/Banners/viking_honor_3.nbt,20,WALL_BANNER:3,../../NBT/Banners/viking_honor_4.nbt,20,WALL_BANNER:3,../../NBT/Banners/viking_honor_5.nbt,20,WALL_BANNER:3,../../NBT/Banners/viking_honor_6.nbt,100)
RandomBlock(-8,8,-5,WALL_BANNER:5,../../NBT/Banners/viking_wealthy_1.nbt,20,WALL_BANNER:5,../../NBT/Banners/viking_wealthy_2.nbt,20,WALL_BANNER:5,../../NBT/Banners/viking_wealthy_3.nbt,20,WALL_BANNER:5,../../NBT/Banners/viking_wealthy_4.nbt,20,WALL_BANNER:5,../../NBT/Banners/viking_wealthy_5.nbt,20,WALL_BANNER:5,../../NBT/Banners/viking_wealthy_6.nbt,20,WALL_BANNER:5,../../NBT/Banners/viking_wealthy_7.nbt,20,WALL_BANNER:5,../../NBT/Banners/viking_wealthy_8.nbt,20,WALL_BANNER:5,../../NBT/Banners/viking_wealthy_9.nbt,100)
RandomBlock(-8,8,-4,WALL_BANNER:5,../../NBT/Banners/viking_wealthy_1.nbt,20,WALL_BANNER:5,../../NBT/Banners/viking_wealthy_2.nbt,20,WALL_BANNER:5,../../NBT/Banners/viking_wealthy_3.nbt,20,WALL_BANNER:5,../../NBT/Banners/viking_wealthy_4.nbt,20,WALL_BANNER:5,../../NBT/Banners/viking_wealthy_5.nbt,20,WALL_BANNER:5,../../NBT/Banners/viking_wealthy_6.nbt,20,WALL_BANNER:5,../../NBT/Banners/viking_wealthy_7.nbt,20,WALL_BANNER:5,../../NBT/Banners/viking_wealthy_8.nbt,20,WALL_BANNER:5,../../NBT/Banners/viking_wealthy_9.nbt,100)
RandomBlock(-8,8,-3,WALL_BANNER:5,../../NBT/Banners/viking_wealthy_1.nbt,20,WALL_BANNER:5,../../NBT/Banners/viking_wealthy_2.nbt,20,WALL_BANNER:5,../../NBT/Banners/viking_wealthy_3.nbt,20,WALL_BANNER:5,../../NBT/Banners/viking_wealthy_4.nbt,20,WALL_BANNER:5,../../NBT/Banners/viking_wealthy_5.nbt,20,WALL_BANNER:5,../../NBT/Banners/viking_wealthy_6.nbt,20,WALL_BANNER:5,../../NBT/Banners/viking_wealthy_7.nbt,20,WALL_BANNER:5,../../NBT/Banners/viking_wealthy_8.nbt,20,WALL_BANNER:5,../../NBT/Banners/viking_wealthy_9.nbt,100)
RandomBlock(-8,8,-1,WALL_BANNER:5,../../NBT/Banners/viking_wealthy_1.nbt,20,WALL_BANNER:5,../../NBT/Banners/viking_wealthy_2.nbt,20,WALL_BANNER:5,../../NBT/Banners/viking_wealthy_3.nbt,20,WALL_BANNER:5,../../NBT/Banners/viking_wealthy_4.nbt,20,WALL_BANNER:5,../../NBT/Banners/viking_wealthy_5.nbt,20,WALL_BANNER:5,../../NBT/Banners/viking_wealthy_6.nbt,20,WALL_BANNER:5,../../NBT/Banners/viking_wealthy_7.nbt,20,WALL_BANNER:5,../../NBT/Banners/viking_wealthy_8.nbt,20,WALL_BANNER:5,../../NBT/Banners/viking_wealthy_9.nbt,100)
RandomBlock(-8,8,0,WALL_BANNER:5,../../NBT/Banners/viking_wealthy_1.nbt,20,WALL_BANNER:5,../../NBT/Banners/viking_wealthy_2.nbt,20,WALL_BANNER:5,../../NBT/Banners/viking_wealthy_3.nbt,20,WALL_BANNER:5,../../NBT/Banners/viking_wealthy_4.nbt,20,WALL_BANNER:5,../../NBT/Banners/viking_wealthy_5.nbt,20,WALL_BANNER:5,../../NBT/Banners/viking_wealthy_6.nbt,20,WALL_BANNER:5,../../NBT/Banners/viking_wealthy_7.nbt,20,WALL_BANNER:5,../../NBT/Banners/viking_wealthy_8.nbt,20,WALL_BANNER:5,../../NBT/Banners/viking_wealthy_9.nbt,100)
RandomBlock(-8,8,1,WALL_BANNER:5,../../NBT/Banners/viking_wealthy_1.nbt,20,WALL_BANNER:5,../../NBT/Banners/viking_wealthy_2.nbt,20,WALL_BANNER:5,../../NBT/Banners/viking_wealthy_3.nbt,20,WALL_BANNER:5,../../NBT/Banners/viking_wealthy_4.nbt,20,WALL_BANNER:5,../../NBT/Banners/viking_wealthy_5.nbt,20,WALL_BANNER:5,../../NBT/Banners/viking_wealthy_6.nbt,20,WALL_BANNER:5,../../NBT/Banners/viking_wealthy_7.nbt,20,WALL_BANNER:5,../../NBT/Banners/viking_wealthy_8.nbt,20,WALL_BANNER:5,../../NBT/Banners/viking_wealthy_9.nbt,100)
RandomBlock(-8,8,2,WALL_BANNER:5,../../NBT/Banners/viking_wealthy_1.nbt,20,WALL_BANNER:5,../../NBT/Banners/viking_wealthy_2.nbt,20,WALL_BANNER:5,../../NBT/Banners/viking_wealthy_3.nbt,20,WALL_BANNER:5,../../NBT/Banners/viking_wealthy_4.nbt,20,WALL_BANNER:5,../../NBT/Banners/viking_wealthy_5.nbt,20,WALL_BANNER:5,../../NBT/Banners/viking_wealthy_6.nbt,20,WALL_BANNER:5,../../NBT/Banners/viking_wealthy_7.nbt,20,WALL_BANNER:5,../../NBT/Banners/viking_wealthy_8.nbt,20,WALL_BANNER:5,../../NBT/Banners/viking_wealthy_9.nbt,100)
RandomBlock(-8,8,4,WALL_BANNER:5,../../NBT/Banners/viking_wealthy_1.nbt,20,WALL_BANNER:5,../../NBT/Banners/viking_wealthy_2.nbt,20,WALL_BANNER:5,../../NBT/Banners/viking_wealthy_3.nbt,20,WALL_BANNER:5,../../NBT/Banners/viking_wealthy_4.nbt,20,WALL_BANNER:5,../../NBT/Banners/viking_wealthy_5.nbt,20,WALL_BANNER:5,../../NBT/Banners/viking_wealthy_6.nbt,20,WALL_BANNER:5,../../NBT/Banners/viking_wealthy_7.nbt,20,WALL_BANNER:5,../../NBT/Banners/viking_wealthy_8.nbt,20,WALL_BANNER:5,../../NBT/Banners/viking_wealthy_9.nbt,100)
RandomBlock(-8,8,5,WALL_BANNER:5,../../NBT/Banners/viking_wealthy_1.nbt,20,WALL_BANNER:5,../../NBT/Banners/viking_wealthy_2.nbt,20,WALL_BANNER:5,../../NBT/Banners/viking_wealthy_3.nbt,20,WALL_BANNER:5,../../NBT/Banners/viking_wealthy_4.nbt,20,WALL_BANNER:5,../../NBT/Banners/viking_wealthy_5.nbt,20,WALL_BANNER:5,../../NBT/Banners/viking_wealthy_6.nbt,20,WALL_BANNER:5,../../NBT/Banners/viking_wealthy_7.nbt,20,WALL_BANNER:5,../../NBT/Banners/viking_wealthy_8.nbt,20,WALL_BANNER:5,../../NBT/Banners/viking_wealthy_9.nbt,100)
RandomBlock(-8,8,6,WALL_BANNER:5,../../NBT/Banners/viking_wealthy_1.nbt,20,WALL_BANNER:5,../../NBT/Banners/viking_wealthy_2.nbt,20,WALL_BANNER:5,../../NBT/Banners/viking_wealthy_3.nbt,20,WALL_BANNER:5,../../NBT/Banners/viking_wealthy_4.nbt,20,WALL_BANNER:5,../../NBT/Banners/viking_wealthy_5.nbt,20,WALL_BANNER:5,../../NBT/Banners/viking_wealthy_6.nbt,20,WALL_BANNER:5,../../NBT/Banners/viking_wealthy_7.nbt,20,WALL_BANNER:5,../../NBT/Banners/viking_wealthy_8.nbt,20,WALL_BANNER:5,../../NBT/Banners/viking_wealthy_9.nbt,100)
Block(-8,8,7,LOG:5)
Block(-8,9,-7,DARK_OAK_FENCE:0)
RandomBlock(-8,9,-6,WALL_BANNER:5,../../NBT/Banners/viking_honor_1.nbt,20,WALL_BANNER:5,../../NBT/Banners/viking_honor_2.nbt,20,WALL_BANNER:5,../../NBT/Banners/viking_honor_3.nbt,20,WALL_BANNER:5,../../NBT/Banners/viking_honor_4.nbt,20,WALL_BANNER:5,../../NBT/Banners/viking_honor_5.nbt,20,WALL_BANNER:5,../../NBT/Banners/viking_honor_6.nbt,100)
RandomBlock(-8,9,-5,WALL_BANNER:5,../../NBT/Banners/viking_honor_1.nbt,20,WALL_BANNER:5,../../NBT/Banners/viking_honor_2.nbt,20,WALL_BANNER:5,../../NBT/Banners/viking_honor_3.nbt,20,WALL_BANNER:5,../../NBT/Banners/viking_honor_4.nbt,20,WALL_BANNER:5,../../NBT/Banners/viking_honor_5.nbt,20,WALL_BANNER:5,../../NBT/Banners/viking_honor_6.nbt,100)
RandomBlock(-8,9,-4,WALL_BANNER:5,../../NBT/Banners/viking_honor_1.nbt,20,WALL_BANNER:5,../../NBT/Banners/viking_honor_2.nbt,20,WALL_BANNER:5,../../NBT/Banners/viking_honor_3.nbt,20,WALL_BANNER:5,../../NBT/Banners/viking_honor_4.nbt,20,WALL_BANNER:5,../../NBT/Banners/viking_honor_5.nbt,20,WALL_BANNER:5,../../NBT/Banners/viking_honor_6.nbt,100)
RandomBlock(-8,9,-3,WALL_BANNER:5,../../NBT/Banners/viking_honor_1.nbt,20,WALL_BANNER:5,../../NBT/Banners/viking_honor_2.nbt,20,WALL_BANNER:5,../../NBT/Banners/viking_honor_3.nbt,20,WALL_BANNER:5,../../NBT/Banners/viking_honor_4.nbt,20,WALL_BANNER:5,../../NBT/Banners/viking_honor_5.nbt,20,WALL_BANNER:5,../../NBT/Banners/viking_honor_6.nbt,100)
Block(-8,9,-2,DARK_OAK_FENCE:0)
RandomBlock(-8,9,-1,WALL_BANNER:5,../../NBT/Banners/viking_honor_1.nbt,20,WALL_BANNER:5,../../NBT/Banners/viking_honor_2.nbt,20,WALL_BANNER:5,../../NBT/Banners/viking_honor_3.nbt,20,WALL_BANNER:5,../../NBT/Banners/viking_honor_4.nbt,20,WALL_BANNER:5,../../NBT/Banners/viking_honor_5.nbt,20,WALL_BANNER:5,../../NBT/Banners/viking_honor_6.nbt,100)
RandomBlock(-8,9,0,WALL_BANNER:5,../../NBT/Banners/viking_honor_1.nbt,20,WALL_BANNER:5,../../NBT/Banners/viking_honor_2.nbt,20,WALL_BANNER:5,../../NBT/Banners/viking_honor_3.nbt,20,WALL_BANNER:5,../../NBT/Banners/viking_honor_4.nbt,20,WALL_BANNER:5,../../NBT/Banners/viking_honor_5.nbt,20,WALL_BANNER:5,../../NBT/Banners/viking_honor_6.nbt,100)
RandomBlock(-8,9,1,WALL_BANNER:5,../../NBT/Banners/viking_honor_1.nbt,20,WALL_BANNER:5,../../NBT/Banners/viking_honor_2.nbt,20,WALL_BANNER:5,../../NBT/Banners/viking_honor_3.nbt,20,WALL_BANNER:5,../../NBT/Banners/viking_honor_4.nbt,20,WALL_BANNER:5,../../NBT/Banners/viking_honor_5.nbt,20,WALL_BANNER:5,../../NBT/Banners/viking_honor_6.nbt,100)
RandomBlock(-8,9,2,WALL_BANNER:5,../../NBT/Banners/viking_honor_1.nbt,20,WALL_BANNER:5,../../NBT/Banners/viking_honor_2.nbt,20,WALL_BANNER:5,../../NBT/Banners/viking_honor_3.nbt,20,WALL_BANNER:5,../../NBT/Banners/viking_honor_4.nbt,20,WALL_BANNER:5,../../NBT/Banners/viking_honor_5.nbt,20,WALL_BANNER:5,../../NBT/Banners/viking_honor_6.nbt,100)
Block(-8,9,3,DARK_OAK_FENCE:0)
RandomBlock(-8,9,4,WALL_BANNER:5,../../NBT/Banners/viking_honor_1.nbt,20,WALL_BANNER:5,../../NBT/Banners/viking_honor_2.nbt,20,WALL_BANNER:5,../../NBT/Banners/viking_honor_3.nbt,20,WALL_BANNER:5,../../NBT/Banners/viking_honor_4.nbt,20,WALL_BANNER:5,../../NBT/Banners/viking_honor_5.nbt,20,WALL_BANNER:5,../../NBT/Banners/viking_honor_6.nbt,100)
RandomBlock(-8,9,5,WALL_BANNER:5,../../NBT/Banners/viking_honor_1.nbt,20,WALL_BANNER:5,../../NBT/Banners/viking_honor_2.nbt,20,WALL_BANNER:5,../../NBT/Banners/viking_honor_3.nbt,20,WALL_BANNER:5,../../NBT/Banners/viking_honor_4.nbt,20,WALL_BANNER:5,../../NBT/Banners/viking_honor_5.nbt,20,WALL_BANNER:5,../../NBT/Banners/viking_honor_6.nbt,100)
RandomBlock(-8,9,6,WALL_BANNER:5,../../NBT/Banners/viking_honor_1.nbt,20,WALL_BANNER:5,../../NBT/Banners/viking_honor_2.nbt,20,WALL_BANNER:5,../../NBT/Banners/viking_honor_3.nbt,20,WALL_BANNER:5,../../NBT/Banners/viking_honor_4.nbt,20,WALL_BANNER:5,../../NBT/Banners/viking_honor_5.nbt,20,WALL_BANNER:5,../../NBT/Banners/viking_honor_6.nbt,100)
Block(-8,9,7,WOOD:1)
Block(-8,10,-7,LOG:5)
Block(-8,10,-6,WOOD_STEP:9)
Block(-8,10,-5,WOOD_STEP:9)
Block(-8,10,-4,WOOD_STEP:9)
Block(-8,10,-3,WOOD_STEP:9)
Block(-8,10,-2,LOG:5)
Block(-8,10,-1,WOOD_STEP:9)
Block(-8,10,0,WOOD_STEP:9)
Block(-8,10,1,WOOD_STEP:9)
Block(-8,10,2,WOOD_STEP:9)
Block(-8,10,3,LOG:5)
Block(-8,10,4,WOOD_STEP:9)
Block(-8,10,5,WOOD_STEP:9)
Block(-8,10,6,WOOD_STEP:9)
Block(-8,10,7,WOOD:1)
Block(-8,11,-7,SPRUCE_WOOD_STAIRS:5)
Block(-8,11,-6,SPRUCE_WOOD_STAIRS:0)
Block(-8,11,-5,SPRUCE_WOOD_STAIRS:0)
Block(-8,11,-4,SPRUCE_WOOD_STAIRS:0)
Block(-8,11,-3,SPRUCE_WOOD_STAIRS:0)
Block(-8,11,-2,SPRUCE_WOOD_STAIRS:5)
Block(-8,11,-1,SPRUCE_WOOD_STAIRS:0)
Block(-8,11,0,SPRUCE_WOOD_STAIRS:0)
Block(-8,11,1,SPRUCE_WOOD_STAIRS:0)
Block(-8,11,2,SPRUCE_WOOD_STAIRS:0)
Block(-8,11,3,SPRUCE_WOOD_STAIRS:5)
Block(-8,11,4,SPRUCE_WOOD_STAIRS:0)
Block(-8,11,5,SPRUCE_WOOD_STAIRS:0)
Block(-8,11,6,SPRUCE_WOOD_STAIRS:0)
Block(-8,11,7,SPRUCE_WOOD_STAIRS:0)
Block(-8,11,8,SPRUCE_WOOD_STAIRS:5)
Block(-8,12,-7,SPRUCE_WOOD_STAIRS:0)
Block(-8,12,-2,SPRUCE_WOOD_STAIRS:0)
Block(-8,12,3,SPRUCE_WOOD_STAIRS:0)
Block(-8,12,8,SPRUCE_WOOD_STAIRS:0)
Block(-7,0,-7,STONE:6)
Block(-7,0,-6,COBBLESTONE:0)
Block(-7,0,-5,STONE:6)
Block(-7,0,-4,STONE:6)
Block(-7,0,-3,COBBLESTONE:0)
Block(-7,0,-2,STONE:6)
Block(-7,0,-1,COBBLESTONE:0)
Block(-7,0,0,STONE:6)
Block(-7,0,1,STONE:6)
Block(-7,0,2,COBBLESTONE:0)
Block(-7,0,3,STONE:6)
Block(-7,0,4,COBBLESTONE:0)
Block(-7,0,5,STONE:6)
Block(-7,0,6,STONE:6)
Block(-7,0,7,COBBLESTONE:0)
Block(-7,0,8,STONE:6)
Block(-7,1,-7,STONE:6)
Block(-7,1,-6,COBBLESTONE:0)
Block(-7,1,-5,STONE:6)
Block(-7,1,-4,STONE:6)
Block(-7,1,-3,COBBLESTONE:0)
Block(-7,1,-2,STONE:6)
Block(-7,1,-1,COBBLESTONE:0)
Block(-7,1,0,STONE:6)
Block(-7,1,1,STONE:6)
Block(-7,1,2,COBBLESTONE:0)
Block(-7,1,3,STONE:6)
Block(-7,1,4,COBBLESTONE:0)
Block(-7,1,5,STONE:6)
Block(-7,1,6,STONE:6)
Block(-7,1,7,COBBLESTONE:0)
Block(-7,1,8,STONE:6)
Block(-7,2,-7,STONE:6)
Block(-7,2,-6,COBBLESTONE:0)
Block(-7,2,-5,STONE:6)
Block(-7,2,-4,STONE:6)
Block(-7,2,-3,COBBLESTONE:0)
Block(-7,2,-2,STONE:6)
Block(-7,2,-1,COBBLESTONE:0)
Block(-7,2,0,STONE:6)
Block(-7,2,1,STONE:6)
Block(-7,2,2,COBBLESTONE:0)
Block(-7,2,3,STONE:6)
Block(-7,2,4,COBBLESTONE:0)
Block(-7,2,5,STONE:6)
Block(-7,2,6,STONE:6)
Block(-7,2,7,COBBLESTONE:0)
Block(-7,2,8,STONE:6)
Block(-7,3,-7,STONE:6)
Block(-7,3,-6,COBBLESTONE:0)
Block(-7,3,-5,STONE:6)
Block(-7,3,-4,STONE:6)
Block(-7,3,-3,COBBLESTONE:0)
Block(-7,3,-2,STONE:6)
Block(-7,3,-1,COBBLESTONE:0)
Block(-7,3,0,STONE:6)
Block(-7,3,1,STONE:6)
Block(-7,3,2,COBBLESTONE:0)
Block(-7,3,3,STONE:6)
Block(-7,3,4,COBBLESTONE:0)
Block(-7,3,5,STONE:6)
Block(-7,3,6,STONE:6)
Block(-7,3,7,COBBLESTONE:0)
Block(-7,3,8,STONE:6)
Block(-7,4,-7,STONE:6)
Block(-7,4,-6,COBBLESTONE:0)
Block(-7,4,-5,STONE:6)
Block(-7,4,-4,STONE:6)
Block(-7,4,-3,COBBLESTONE:0)
Block(-7,4,-2,STONE:6)
Block(-7,4,-1,COBBLESTONE:0)
Block(-7,4,0,STONE:6)
Block(-7,4,1,STONE:6)
Block(-7,4,2,COBBLESTONE:0)
Block(-7,4,3,STONE:6)
Block(-7,4,4,COBBLESTONE:0)
Block(-7,4,5,STONE:6)
Block(-7,4,6,STONE:6)
Block(-7,4,7,COBBLESTONE:0)
Block(-7,4,8,STONE:6)
Block(-7,5,-7,STONE:6)
Block(-7,5,-6,COBBLESTONE:0)
Block(-7,5,-5,STONE:6)
Block(-7,5,-4,STONE:6)
Block(-7,5,-3,COBBLESTONE:0)
Block(-7,5,-2,STONE:6)
Block(-7,5,-1,COBBLESTONE:0)
Block(-7,5,0,STONE:6)
Block(-7,5,1,STONE:6)
Block(-7,5,2,COBBLESTONE:0)
Block(-7,5,3,STONE:6)
Block(-7,5,4,COBBLESTONE:0)
Block(-7,5,5,STONE:6)
Block(-7,5,6,STONE:6)
Block(-7,5,7,COBBLESTONE:0)
Block(-7,5,8,STONE:6)
Block(-7,6,-7,DARK_OAK_FENCE:0)
Block(-7,6,-6,CARPET:12)
Block(-7,6,-5,CARPET:12)
Block(-7,6,-4,DARK_OAK_STAIRS:7)
Block(-7,6,-3,WOOD_STEP:13)
Block(-7,6,-2,WOOD_STEP:13)
Block(-7,6,-1,WOOD_STEP:13)
Block(-7,6,0,WOOD_STEP:13)
Block(-7,6,1,WOOD_STEP:13)
Block(-7,6,2,WOOD_STEP:13)
Block(-7,6,3,WOOD_STEP:13)
Block(-7,6,4,WOOD_STEP:13)
Block(-7,6,5,DARK_OAK_STAIRS:6)
Block(-7,6,7,COBBLESTONE:0)
Block(-7,7,-7,DARK_OAK_FENCE:0)
RandomBlock(-7,7,-6,WALL_BANNER:3,../../NBT/Banners/viking_wealthy_1.nbt,20,WALL_BANNER:3,../../NBT/Banners/viking_wealthy_2.nbt,20,WALL_BANNER:3,../../NBT/Banners/viking_wealthy_3.nbt,20,WALL_BANNER:3,../../NBT/Banners/viking_wealthy_4.nbt,20,WALL_BANNER:3,../../NBT/Banners/viking_wealthy_5.nbt,20,WALL_BANNER:3,../../NBT/Banners/viking_wealthy_6.nbt,20,WALL_BANNER:3,../../NBT/Banners/viking_wealthy_7.nbt,20,WALL_BANNER:3,../../NBT/Banners/viking_wealthy_8.nbt,20,WALL_BANNER:3,../../NBT/Banners/viking_wealthy_9.nbt,100)
Block(-7,7,-4,FLOWER_POT:0)
Block(-7,7,-3,TORCH:5)
Block(-7,7,-1,WOOD_PLATE:0)
Block(-7,7,0,FLOWER_POT:0)
Block(-7,7,1,BREWING_STAND:0)
Block(-7,7,3,WOOD_PLATE:0)
Block(-7,7,4,TORCH:5)
Block(-7,7,7,COBBLESTONE:0)
Block(-7,7,8,SPRUCE_WOOD_STAIRS:5)
Block(-7,8,-7,DARK_OAK_FENCE:0)
RandomBlock(-7,8,-6,WALL_BANNER:3,../../NBT/Banners/viking_honor_1.nbt,20,WALL_BANNER:3,../../NBT/Banners/viking_honor_2.nbt,20,WALL_BANNER:3,../../NBT/Banners/viking_honor_3.nbt,20,WALL_BANNER:3,../../NBT/Banners/viking_honor_4.nbt,20,WALL_BANNER:3,../../NBT/Banners/viking_honor_5.nbt,20,WALL_BANNER:3,../../NBT/Banners/viking_honor_6.nbt,100)
Block(-7,8,7,LOG:5)
Block(-7,8,8,SPRUCE_WOOD_STAIRS:0)
Block(-7,9,-7,DARK_OAK_FENCE:0)
RandomBlock(-7,9,-6,WALL_BANNER:3,../../NBT/Banners/viking_wealthy_1.nbt,20,WALL_BANNER:3,../../NBT/Banners/viking_wealthy_2.nbt,20,WALL_BANNER:3,../../NBT/Banners/viking_wealthy_3.nbt,20,WALL_BANNER:3,../../NBT/Banners/viking_wealthy_4.nbt,20,WALL_BANNER:3,../../NBT/Banners/viking_wealthy_5.nbt,20,WALL_BANNER:3,../../NBT/Banners/viking_wealthy_6.nbt,20,WALL_BANNER:3,../../NBT/Banners/viking_wealthy_7.nbt,20,WALL_BANNER:3,../../NBT/Banners/viking_wealthy_8.nbt,20,WALL_BANNER:3,../../NBT/Banners/viking_wealthy_9.nbt,100)
Block(-7,9,-2,DARK_OAK_FENCE:0)
Block(-7,9,3,DARK_OAK_FENCE:0)
Block(-7,9,7,SPRUCE_WOOD_STAIRS:3)
Block(-7,10,-7,LOG:5)
Block(-7,10,-6,WOOD_STEP:9)
Block(-7,10,-5,WOOD_STEP:9)
Block(-7,10,-4,WOOD_STEP:9)
Block(-7,10,-3,WOOD_STEP:9)
Block(-7,10,-2,LOG:5)
Block(-7,10,-1,WOOD_STEP:9)
Block(-7,10,0,WOOD_STEP:9)
Block(-7,10,1,WOOD_STEP:9)
Block(-7,10,2,WOOD_STEP:9)
Block(-7,10,3,LOG:5)
Block(-7,10,4,WOOD_STEP:9)
Block(-7,10,5,WOOD_STEP:9)
Block(-7,10,6,WOOD_STEP:9)
Block(-7,10,7,SPRUCE_WOOD_STAIRS:3)
Block(-7,11,-7,BED_BLOCK:8)
Block(-7,11,-5,CARPET:4)
Block(-7,11,0,CARPET:4)
Block(-7,11,1,CARPET:4)
Block(-7,11,2,CARPET:4)
Block(-7,11,3,CARPET:4)
Block(-7,11,4,HAY_BLOCK:0)
Block(-7,11,5,HAY_BLOCK:4)
Block(-7,11,6,HAY_BLOCK:0)
Block(-7,11,7,SPRUCE_WOOD_STAIRS:7)
Block(-7,12,-7,SPRUCE_WOOD_STAIRS:5)
Block(-7,12,-6,SPRUCE_WOOD_STAIRS:0)
Block(-7,12,-5,SPRUCE_WOOD_STAIRS:0)
Block(-7,12,-4,SPRUCE_WOOD_STAIRS:0)
Block(-7,12,-3,SPRUCE_WOOD_STAIRS:0)
Block(-7,12,-2,SPRUCE_WOOD_STAIRS:5)
Block(-7,12,-1,SPRUCE_WOOD_STAIRS:0)
Block(-7,12,0,SPRUCE_WOOD_STAIRS:0)
Block(-7,12,1,SPRUCE_WOOD_STAIRS:0)
Block(-7,12,2,SPRUCE_WOOD_STAIRS:0)
Block(-7,12,3,SPRUCE_WOOD_STAIRS:5)
Block(-7,12,4,SPRUCE_WOOD_STAIRS:0)
Block(-7,12,5,SPRUCE_WOOD_STAIRS:0)
Block(-7,12,6,SPRUCE_WOOD_STAIRS:0)
Block(-7,12,7,SPRUCE_WOOD_STAIRS:0)
Block(-7,12,8,SPRUCE_WOOD_STAIRS:5)
Block(-7,13,-7,SPRUCE_WOOD_STAIRS:0)
Block(-7,13,-2,SPRUCE_WOOD_STAIRS:0)
Block(-7,13,3,SPRUCE_WOOD_STAIRS:0)
Block(-7,13,8,SPRUCE_WOOD_STAIRS:0)
Block(-6,0,-7,STONE:6)
Block(-6,0,-6,COBBLESTONE:0)
Block(-6,0,-5,STONE:6)
Block(-6,0,-4,STONE:6)
Block(-6,0,-3,COBBLESTONE:0)
Block(-6,0,-2,STONE:6)
Block(-6,0,-1,COBBLESTONE:0)
Block(-6,0,0,STONE:6)
Block(-6,0,1,STONE:6)
Block(-6,0,2,COBBLESTONE:0)
Block(-6,0,3,STONE:6)
Block(-6,0,4,COBBLESTONE:0)
Block(-6,0,5,STONE:6)
Block(-6,0,6,STONE:6)
Block(-6,0,7,COBBLESTONE:0)
Block(-6,0,8,STONE:6)
Block(-6,1,-7,STONE:6)
Block(-6,1,-6,COBBLESTONE:0)
Block(-6,1,-5,STONE:6)
Block(-6,1,-4,STONE:6)
Block(-6,1,-3,COBBLESTONE:0)
Block(-6,1,-2,STONE:6)
Block(-6,1,-1,COBBLESTONE:0)
Block(-6,1,0,STONE:6)
Block(-6,1,1,STONE:6)
Block(-6,1,2,COBBLESTONE:0)
Block(-6,1,3,STONE:6)
Block(-6,1,4,COBBLESTONE:0)
Block(-6,1,5,STONE:6)
Block(-6,1,6,STONE:6)
Block(-6,1,7,COBBLESTONE:0)
Block(-6,1,8,STONE:6)
Block(-6,2,-7,STONE:6)
Block(-6,2,-6,COBBLESTONE:0)
Block(-6,2,-5,STONE:6)
Block(-6,2,-4,STONE:6)
Block(-6,2,-3,COBBLESTONE:0)
Block(-6,2,-2,STONE:6)
Block(-6,2,-1,COBBLESTONE:0)
Block(-6,2,0,STONE:6)
Block(-6,2,1,STONE:6)
Block(-6,2,2,COBBLESTONE:0)
Block(-6,2,3,STONE:6)
Block(-6,2,4,COBBLESTONE:0)
Block(-6,2,5,STONE:6)
Block(-6,2,6,STONE:6)
Block(-6,2,7,COBBLESTONE:0)
Block(-6,2,8,STONE:6)
Block(-6,3,-7,STONE:6)
Block(-6,3,-6,COBBLESTONE:0)
Block(-6,3,-5,STONE:6)
Block(-6,3,-4,STONE:6)
Block(-6,3,-3,COBBLESTONE:0)
Block(-6,3,-2,STONE:6)
Block(-6,3,-1,COBBLESTONE:0)
Block(-6,3,0,STONE:6)
Block(-6,3,1,STONE:6)
Block(-6,3,2,COBBLESTONE:0)
Block(-6,3,3,STONE:6)
Block(-6,3,4,COBBLESTONE:0)
Block(-6,3,5,STONE:6)
Block(-6,3,6,STONE:6)
Block(-6,3,7,COBBLESTONE:0)
Block(-6,3,8,STONE:6)
Block(-6,4,-7,STONE:6)
Block(-6,4,-6,COBBLESTONE:0)
Block(-6,4,-5,STONE:6)
Block(-6,4,-4,STONE:6)
Block(-6,4,-3,COBBLESTONE:0)
Block(-6,4,-2,STONE:6)
Block(-6,4,-1,COBBLESTONE:0)
Block(-6,4,0,STONE:6)
Block(-6,4,1,STONE:6)
Block(-6,4,2,COBBLESTONE:0)
Block(-6,4,3,STONE:6)
Block(-6,4,4,COBBLESTONE:0)
Block(-6,4,5,STONE:6)
Block(-6,4,6,STONE:6)
Block(-6,4,7,COBBLESTONE:0)
Block(-6,4,8,STONE:6)
Block(-6,5,-7,STONE:6)
Block(-6,5,-6,COBBLESTONE:0)
Block(-6,5,-5,STONE:6)
Block(-6,5,-4,STONE:6)
Block(-6,5,-3,COBBLESTONE:0)
Block(-6,5,-2,STONE:6)
Block(-6,5,-1,COBBLESTONE:0)
Block(-6,5,0,STONE:6)
Block(-6,5,1,STONE:6)
Block(-6,5,2,COBBLESTONE:0)
Block(-6,5,3,STONE:6)
Block(-6,5,4,COBBLESTONE:0)
Block(-6,5,5,STONE:6)
Block(-6,5,6,STONE:6)
Block(-6,5,7,COBBLESTONE:0)
Block(-6,5,8,STONE:6)
Block(-6,6,-7,DARK_OAK_FENCE:0)
Block(-6,6,-4,DARK_OAK_STAIRS:7)
Block(-6,6,-3,WOOD_STEP:13)
Block(-6,6,-2,WOOD_STEP:13)
Block(-6,6,-1,WOOD_STEP:13)
Block(-6,6,0,WOOD_STEP:13)
Block(-6,6,1,WOOD_STEP:13)
Block(-6,6,2,WOOD_STEP:13)
Block(-6,6,3,WOOD_STEP:13)
Block(-6,6,4,WOOD_STEP:13)
Block(-6,6,5,DARK_OAK_STAIRS:6)
Block(-6,6,7,COBBLESTONE:0)
Block(-6,7,-7,DARK_OAK_FENCE:0)
RandomBlock(-6,7,-6,WALL_BANNER:3,../../NBT/Banners/viking_wealthy_1.nbt,20,WALL_BANNER:3,../../NBT/Banners/viking_wealthy_2.nbt,20,WALL_BANNER:3,../../NBT/Banners/viking_wealthy_3.nbt,20,WALL_BANNER:3,../../NBT/Banners/viking_wealthy_4.nbt,20,WALL_BANNER:3,../../NBT/Banners/viking_wealthy_5.nbt,20,WALL_BANNER:3,../../NBT/Banners/viking_wealthy_6.nbt,20,WALL_BANNER:3,../../NBT/Banners/viking_wealthy_7.nbt,20,WALL_BANNER:3,../../NBT/Banners/viking_wealthy_8.nbt,20,WALL_BANNER:3,../../NBT/Banners/viking_wealthy_9.nbt,100)
Block(-6,7,-4,WOOD_PLATE:0)
Block(-6,7,-3,FLOWER_POT:0)
Block(-6,7,0,WOOD_PLATE:0)
Block(-6,7,2,WOOD_PLATE:0)
Block(-6,7,4,FLOWER_POT:0)
Block(-6,7,5,WOOD_PLATE:0)
Block(-6,7,7,COBBLESTONE:0)
Block(-6,8,-7,DARK_OAK_FENCE:0)
RandomBlock(-6,8,-6,WALL_BANNER:3,../../NBT/Banners/viking_honor_1.nbt,20,WALL_BANNER:3,../../NBT/Banners/viking_honor_2.nbt,20,WALL_BANNER:3,../../NBT/Banners/viking_honor_3.nbt,20,WALL_BANNER:3,../../NBT/Banners/viking_honor_4.nbt,20,WALL_BANNER:3,../../NBT/Banners/viking_honor_5.nbt,20,WALL_BANNER:3,../../NBT/Banners/viking_honor_6.nbt,100)
Block(-6,8,7,LOG:5)
Block(-6,8,8,SPRUCE_WOOD_STAIRS:5)
Block(-6,9,-7,DARK_OAK_FENCE:0)
RandomBlock(-6,9,-6,WALL_BANNER:3,../../NBT/Banners/viking_wealthy_1.nbt,20,WALL_BANNER:3,../../NBT/Banners/viking_wealthy_2.nbt,20,WALL_BANNER:3,../../NBT/Banners/viking_wealthy_3.nbt,20,WALL_BANNER:3,../../NBT/Banners/viking_wealthy_4.nbt,20,WALL_BANNER:3,../../NBT/Banners/viking_wealthy_5.nbt,20,WALL_BANNER:3,../../NBT/Banners/viking_wealthy_6.nbt,20,WALL_BANNER:3,../../NBT/Banners/viking_wealthy_7.nbt,20,WALL_BANNER:3,../../NBT/Banners/viking_wealthy_8.nbt,20,WALL_BANNER:3,../../NBT/Banners/viking_wealthy_9.nbt,100)
Block(-6,9,-2,DARK_OAK_FENCE:0)
Block(-6,9,3,DARK_OAK_FENCE:0)
Block(-6,9,7,SPRUCE_WOOD_STAIRS:3)
Block(-6,9,8,SPRUCE_WOOD_STAIRS:0)
Block(-6,10,-7,LOG:5)
Block(-6,10,-6,WOOD_STEP:9)
Block(-6,10,-5,WOOD_STEP:9)
Block(-6,10,-4,WOOD_STEP:9)
Block(-6,10,-3,WOOD_STEP:9)
Block(-6,10,-2,LOG:5)
Block(-6,10,-1,WOOD_STEP:9)
Block(-6,10,0,WOOD_STEP:9)
Block(-6,10,1,WOOD_STEP:9)
Block(-6,10,2,WOOD_STEP:9)
Block(-6,10,3,LOG:5)
Block(-6,10,4,WOOD_STEP:9)
Block(-6,10,5,WOOD_STEP:9)
Block(-6,10,6,WOOD_STEP:9)
Block(-6,10,7,SPRUCE_WOOD_STAIRS:3)
Block(-6,11,-7,CARPET:12)
Block(-6,11,-6,CARPET:12)
Block(-6,11,-5,CARPET:12)
Block(-6,11,-4,CARPET:4)
Block(-6,11,3,CARPET:4)
Block(-6,11,4,CARPET:12)
Block(-6,11,5,CARPET:12)
Block(-6,11,6,HAY_BLOCK:8)
Block(-6,11,7,SPRUCE_WOOD_STAIRS:7)
Block(-6,12,6,HAY_BLOCK:8)
Block(-6,12,7,SPRUCE_WOOD_STAIRS:7)
Block(-6,13,-7,SPRUCE_WOOD_STAIRS:5)
Block(-6,13,-6,SPRUCE_WOOD_STAIRS:0)
Block(-6,13,-5,SPRUCE_WOOD_STAIRS:0)
Block(-6,13,-4,SPRUCE_WOOD_STAIRS:0)
Block(-6,13,-3,SPRUCE_WOOD_STAIRS:0)
Block(-6,13,-2,SPRUCE_WOOD_STAIRS:5)
Block(-6,13,-1,SPRUCE_WOOD_STAIRS:0)
Block(-6,13,0,SPRUCE_WOOD_STAIRS:0)
Block(-6,13,1,SPRUCE_WOOD_STAIRS:0)
Block(-6,13,2,SPRUCE_WOOD_STAIRS:0)
Block(-6,13,3,SPRUCE_WOOD_STAIRS:5)
Block(-6,13,4,SPRUCE_WOOD_STAIRS:0)
Block(-6,13,5,SPRUCE_WOOD_STAIRS:0)
Block(-6,13,6,SPRUCE_WOOD_STAIRS:0)
Block(-6,13,7,SPRUCE_WOOD_STAIRS:0)
Block(-6,13,8,SPRUCE_WOOD_STAIRS:5)
Block(-6,14,-7,SPRUCE_WOOD_STAIRS:0)
Block(-6,14,-2,SPRUCE_WOOD_STAIRS:0)
Block(-6,14,3,SPRUCE_WOOD_STAIRS:0)
Block(-6,14,8,SPRUCE_WOOD_STAIRS:0)
Block(-5,0,-7,COBBLESTONE:0)
Block(-5,0,-6,COBBLESTONE:0)
Block(-5,0,-5,COBBLESTONE:0)
Block(-5,0,-4,COBBLESTONE:0)
Block(-5,0,-3,COBBLESTONE:0)
Block(-5,0,-2,COBBLESTONE:0)
Block(-5,0,-1,COBBLESTONE:0)
Block(-5,0,0,COBBLESTONE:0)
Block(-5,0,1,COBBLESTONE:0)
Block(-5,0,2,COBBLESTONE:0)
Block(-5,0,3,COBBLESTONE:0)
Block(-5,0,4,COBBLESTONE:0)
Block(-5,0,5,COBBLESTONE:0)
Block(-5,0,6,COBBLESTONE:0)
Block(-5,0,7,COBBLESTONE:0)
Block(-5,0,8,STONE:6)
Block(-5,1,-7,COBBLESTONE:0)
Block(-5,1,-6,COBBLESTONE:0)
Block(-5,1,-5,COBBLESTONE:0)
Block(-5,1,-4,COBBLESTONE:0)
Block(-5,1,-3,COBBLESTONE:0)
Block(-5,1,-2,COBBLESTONE:0)
Block(-5,1,-1,COBBLESTONE:0)
Block(-5,1,0,COBBLESTONE:0)
Block(-5,1,1,COBBLESTONE:0)
Block(-5,1,2,COBBLESTONE:0)
Block(-5,1,3,COBBLESTONE:0)
Block(-5,1,4,COBBLESTONE:0)
Block(-5,1,5,COBBLESTONE:0)
Block(-5,1,6,COBBLESTONE:0)
Block(-5,1,7,COBBLESTONE:0)
Block(-5,1,8,STONE:6)
Block(-5,2,-7,COBBLESTONE:0)
Block(-5,2,-6,COBBLESTONE:0)
Block(-5,2,-5,COBBLESTONE:0)
Block(-5,2,-4,COBBLESTONE:0)
Block(-5,2,-3,COBBLESTONE:0)
Block(-5,2,-2,COBBLESTONE:0)
Block(-5,2,-1,COBBLESTONE:0)
Block(-5,2,0,COBBLESTONE:0)
Block(-5,2,1,COBBLESTONE:0)
Block(-5,2,2,COBBLESTONE:0)
Block(-5,2,3,COBBLESTONE:0)
Block(-5,2,4,COBBLESTONE:0)
Block(-5,2,5,COBBLESTONE:0)
Block(-5,2,6,COBBLESTONE:0)
Block(-5,2,7,COBBLESTONE:0)
Block(-5,2,8,STONE:6)
Block(-5,3,-7,COBBLESTONE:0)
Block(-5,3,-6,COBBLESTONE:0)
Block(-5,3,-5,COBBLESTONE:0)
Block(-5,3,-4,COBBLESTONE:0)
Block(-5,3,-3,COBBLESTONE:0)
Block(-5,3,-2,COBBLESTONE:0)
Block(-5,3,-1,COBBLESTONE:0)
Block(-5,3,0,COBBLESTONE:0)
Block(-5,3,1,COBBLESTONE:0)
Block(-5,3,2,COBBLESTONE:0)
Block(-5,3,3,COBBLESTONE:0)
Block(-5,3,4,COBBLESTONE:0)
Block(-5,3,5,COBBLESTONE:0)
Block(-5,3,6,COBBLESTONE:0)
Block(-5,3,7,COBBLESTONE:0)
Block(-5,3,8,STONE:6)
Block(-5,4,-7,COBBLESTONE:0)
Block(-5,4,-6,COBBLESTONE:0)
Block(-5,4,-5,COBBLESTONE:0)
Block(-5,4,-4,COBBLESTONE:0)
Block(-5,4,-3,COBBLESTONE:0)
Block(-5,4,-2,COBBLESTONE:0)
Block(-5,4,-1,COBBLESTONE:0)
Block(-5,4,0,COBBLESTONE:0)
Block(-5,4,1,COBBLESTONE:0)
Block(-5,4,2,COBBLESTONE:0)
Block(-5,4,3,COBBLESTONE:0)
Block(-5,4,4,COBBLESTONE:0)
Block(-5,4,5,COBBLESTONE:0)
Block(-5,4,6,COBBLESTONE:0)
Block(-5,4,7,COBBLESTONE:0)
Block(-5,4,8,STONE:6)
Block(-5,5,-7,COBBLESTONE:0)
Block(-5,5,-6,COBBLESTONE:0)
Block(-5,5,-5,COBBLESTONE:0)
Block(-5,5,-4,COBBLESTONE:0)
Block(-5,5,-3,COBBLESTONE:0)
Block(-5,5,-2,COBBLESTONE:0)
Block(-5,5,-1,COBBLESTONE:0)
Block(-5,5,0,COBBLESTONE:0)
Block(-5,5,1,COBBLESTONE:0)
Block(-5,5,2,COBBLESTONE:0)
Block(-5,5,3,COBBLESTONE:0)
Block(-5,5,4,COBBLESTONE:0)
Block(-5,5,5,COBBLESTONE:0)
Block(-5,5,6,COBBLESTONE:0)
Block(-5,5,7,COBBLESTONE:0)
Block(-5,5,8,STONE:6)
Block(-5,6,-7,DARK_OAK_FENCE:0)
Block(-5,6,-6,CARPET:12)
Block(-5,6,-5,CARPET:12)
Block(-5,6,-4,CARPET:12)
Block(-5,6,-3,SPRUCE_WOOD_STAIRS:0)
Block(-5,6,-2,SPRUCE_WOOD_STAIRS:0)
Block(-5,6,1,SPRUCE_WOOD_STAIRS:0)
Block(-5,6,2,SPRUCE_WOOD_STAIRS:0)
Block(-5,6,5,SPRUCE_WOOD_STAIRS:0)
Block(-5,6,7,STONE:6)
Block(-5,7,-7,DARK_OAK_FENCE:0)
Block(-5,7,7,STONE:6)
Block(-5,8,-7,DARK_OAK_FENCE:0)
RandomBlock(-5,8,-6,WALL_BANNER:3,../../NBT/Banners/viking_honor_1.nbt,20,WALL_BANNER:3,../../NBT/Banners/viking_honor_2.nbt,20,WALL_BANNER:3,../../NBT/Banners/viking_honor_3.nbt,20,WALL_BANNER:3,../../NBT/Banners/viking_honor_4.nbt,20,WALL_BANNER:3,../../NBT/Banners/viking_honor_5.nbt,20,WALL_BANNER:3,../../NBT/Banners/viking_honor_6.nbt,100)
Block(-5,8,7,LOG:5)
Block(-5,9,-7,DARK_OAK_FENCE:0)
RandomBlock(-5,9,-6,WALL_BANNER:3,../../NBT/Banners/viking_wealthy_1.nbt,20,WALL_BANNER:3,../../NBT/Banners/viking_wealthy_2.nbt,20,WALL_BANNER:3,../../NBT/Banners/viking_wealthy_3.nbt,20,WALL_BANNER:3,../../NBT/Banners/viking_wealthy_4.nbt,20,WALL_BANNER:3,../../NBT/Banners/viking_wealthy_5.nbt,20,WALL_BANNER:3,../../NBT/Banners/viking_wealthy_6.nbt,20,WALL_BANNER:3,../../NBT/Banners/viking_wealthy_7.nbt,20,WALL_BANNER:3,../../NBT/Banners/viking_wealthy_8.nbt,20,WALL_BANNER:3,../../NBT/Banners/viking_wealthy_9.nbt,100)
Block(-5,9,-2,DARK_OAK_FENCE:0)
Block(-5,9,3,DARK_OAK_FENCE:0)
Block(-5,9,7,WOOD:1)
Block(-5,9,8,SPRUCE_WOOD_STAIRS:5)
Block(-5,10,-7,LOG:5)
Block(-5,10,-6,WOOD_STEP:9)
Block(-5,10,-5,WOOD_STEP:9)
Block(-5,10,-4,WOOD_STEP:9)
Block(-5,10,-3,WOOD_STEP:9)
Block(-5,10,-2,LOG:5)
Block(-5,10,-1,WOOD_STEP:9)
Block(-5,10,0,WOOD_STEP:9)
Block(-5,10,1,WOOD_STEP:9)
Block(-5,10,2,WOOD_STEP:9)
Block(-5,10,3,LOG:5)
Block(-5,10,4,WOOD_STEP:9)
Block(-5,10,5,WOOD_STEP:9)
Block(-5,10,6,WOOD_STEP:9)
Block(-5,10,7,WOOD:1)
Block(-5,10,8,SPRUCE_WOOD_STAIRS:0)
Block(-5,11,-7,CARPET:12)
Block(-5,11,-6,AIR:0)
Block(-5,11,-5,BED_BLOCK:0)
Block(-5,11,-4,BED_BLOCK:8)
Block(-5,11,-3,HAY_BLOCK:0)
Block(-5,11,-2,HAY_BLOCK:0)
Block(-5,11,-1,HAY_BLOCK:0)
Block(-5,11,0,CARPET:12)
Block(-5,11,1,CARPET:12)
Block(-5,11,3,BED_BLOCK:0)
Block(-5,11,4,BED_BLOCK:8)
Block(-5,11,5,CARPET:12)
Block(-5,11,6,HAY_BLOCK:4)
Block(-5,11,7,WOOD:1)
Block(-5,11,8,SPRUCE_WOOD_STAIRS:4)
Block(-5,12,-3,CARPET:12)
Block(-5,12,-2,HAY_BLOCK:0)
Block(-5,12,-1,CARPET:12)
Block(-5,12,6,CARPET:12)
Block(-5,12,7,WOOD:1)
Block(-5,12,8,SPRUCE_WOOD_STAIRS:1)
Block(-5,13,7,WOOD:1)
Block(-5,14,-7,SPRUCE_WOOD_STAIRS:5)
Block(-5,14,-6,SPRUCE_WOOD_STAIRS:0)
Block(-5,14,-5,SPRUCE_WOOD_STAIRS:0)
Block(-5,14,-4,SPRUCE_WOOD_STAIRS:0)
Block(-5,14,-3,SPRUCE_WOOD_STAIRS:0)
Block(-5,14,-2,SPRUCE_WOOD_STAIRS:5)
Block(-5,14,-1,SPRUCE_WOOD_STAIRS:0)
Block(-5,14,0,SPRUCE_WOOD_STAIRS:0)
Block(-5,14,1,SPRUCE_WOOD_STAIRS:0)
Block(-5,14,2,SPRUCE_WOOD_STAIRS:0)
Block(-5,14,3,SPRUCE_WOOD_STAIRS:5)
Block(-5,14,4,SPRUCE_WOOD_STAIRS:0)
Block(-5,14,5,SPRUCE_WOOD_STAIRS:0)
Block(-5,14,6,SPRUCE_WOOD_STAIRS:0)
Block(-5,14,7,SPRUCE_WOOD_STAIRS:0)
Block(-5,14,8,SPRUCE_WOOD_STAIRS:5)
Block(-5,15,-7,SPRUCE_WOOD_STAIRS:0)
Block(-5,15,-2,SPRUCE_WOOD_STAIRS:0)
Block(-5,15,3,SPRUCE_WOOD_STAIRS:0)
Block(-5,15,8,SPRUCE_WOOD_STAIRS:0)
Block(-4,0,-7,LOG:1)
Block(-4,0,-6,COBBLESTONE:0)
Block(-4,0,-5,STONE:6)
Block(-4,0,-4,STONE:6)
Block(-4,0,-3,COBBLESTONE:0)
Block(-4,0,-2,LOG:1)
Block(-4,0,-1,COBBLESTONE:0)
Block(-4,0,0,STONE:6)
Block(-4,0,1,STONE:6)
Block(-4,0,2,COBBLESTONE:0)
Block(-4,0,3,LOG:1)
Block(-4,0,4,COBBLESTONE:0)
Block(-4,0,5,STONE:6)
Block(-4,0,6,STONE:6)
Block(-4,0,7,LOG:1)
Block(-4,0,8,LOG:1)
Block(-4,1,-7,LOG:1)
Block(-4,1,-6,COBBLESTONE:0)
Block(-4,1,-5,STONE:6)
Block(-4,1,-4,STONE:6)
Block(-4,1,-3,COBBLESTONE:0)
Block(-4,1,-2,LOG:1)
Block(-4,1,-1,COBBLESTONE:0)
Block(-4,1,0,STONE:6)
Block(-4,1,1,STONE:6)
Block(-4,1,2,COBBLESTONE:0)
Block(-4,1,3,LOG:1)
Block(-4,1,4,COBBLESTONE:0)
Block(-4,1,5,STONE:6)
Block(-4,1,6,STONE:6)
Block(-4,1,7,LOG:1)
Block(-4,1,8,LOG:1)
Block(-4,2,-7,LOG:1)
Block(-4,2,-6,COBBLESTONE:0)
Block(-4,2,-5,STONE:6)
Block(-4,2,-4,STONE:6)
Block(-4,2,-3,COBBLESTONE:0)
Block(-4,2,-2,LOG:1)
Block(-4,2,-1,COBBLESTONE:0)
Block(-4,2,0,STONE:6)
Block(-4,2,1,STONE:6)
Block(-4,2,2,COBBLESTONE:0)
Block(-4,2,3,LOG:1)
Block(-4,2,4,COBBLESTONE:0)
Block(-4,2,5,STONE:6)
Block(-4,2,6,STONE:6)
Block(-4,2,7,LOG:1)
Block(-4,2,8,LOG:1)
Block(-4,3,-7,LOG:1)
Block(-4,3,-6,COBBLESTONE:0)
Block(-4,3,-5,STONE:6)
Block(-4,3,-4,STONE:6)
Block(-4,3,-3,COBBLESTONE:0)
Block(-4,3,-2,LOG:1)
Block(-4,3,-1,COBBLESTONE:0)
Block(-4,3,0,STONE:6)
Block(-4,3,1,STONE:6)
Block(-4,3,2,COBBLESTONE:0)
Block(-4,3,3,LOG:1)
Block(-4,3,4,COBBLESTONE:0)
Block(-4,3,5,STONE:6)
Block(-4,3,6,STONE:6)
Block(-4,3,7,LOG:1)
Block(-4,3,8,LOG:1)
Block(-4,4,-7,LOG:1)
Block(-4,4,-6,COBBLESTONE:0)
Block(-4,4,-5,STONE:6)
Block(-4,4,-4,STONE:6)
Block(-4,4,-3,COBBLESTONE:0)
Block(-4,4,-2,LOG:1)
Block(-4,4,-1,COBBLESTONE:0)
Block(-4,4,0,STONE:6)
Block(-4,4,1,STONE:6)
Block(-4,4,2,COBBLESTONE:0)
Block(-4,4,3,LOG:1)
Block(-4,4,4,COBBLESTONE:0)
Block(-4,4,5,STONE:6)
Block(-4,4,6,STONE:6)
Block(-4,4,7,LOG:1)
Block(-4,4,8,LOG:1)
Block(-4,5,-7,LOG:1)
Block(-4,5,-6,COBBLESTONE:0)
Block(-4,5,-5,STONE:6)
Block(-4,5,-4,STONE:6)
Block(-4,5,-3,COBBLESTONE:0)
Block(-4,5,-2,LOG:1)
Block(-4,5,-1,COBBLESTONE:0)
Block(-4,5,0,STONE:6)
Block(-4,5,1,STONE:6)
Block(-4,5,2,COBBLESTONE:0)
Block(-4,5,3,LOG:1)
Block(-4,5,4,COBBLESTONE:0)
Block(-4,5,5,STONE:6)
Block(-4,5,6,STONE:6)
Block(-4,5,7,LOG:1)
Block(-4,5,8,LOG:1)
Block(-4,6,-7,LOG:1)
Block(-4,6,-6,SPRUCE_WOOD_STAIRS:0)
Block(-4,6,-5,CARPET:12)
Block(-4,6,-3,DARK_OAK_FENCE:0)
Block(-4,6,-2,LOG:1)
Block(-4,6,0,CARPET:12)
Block(-4,6,1,CARPET:12)
Block(-4,6,2,CARPET:12)
Block(-4,6,3,LOG:1)
Block(-4,6,4,CAULDRON:0)
Block(-4,6,5,CARPET:12)
Block(-4,6,6,CARPET:12)
Block(-4,6,7,LOG:1)
Block(-4,6,8,LOG:1)
Block(-4,7,-7,LOG:1)
Block(-4,7,-3,TORCH:5)
Block(-4,7,-2,LOG:1)
Block(-4,7,3,LOG:1)
Block(-4,7,7,LOG:1)
Block(-4,7,8,LOG:1)
Block(-4,8,-7,LOG:1)
Block(-4,8,-2,LOG:1)
Block(-4,8,3,LOG:1)
Block(-4,8,7,LOG:1)
Block(-4,8,8,LOG:9)
Block(-4,9,-7,LOG:1)
Block(-4,9,-6,DARK_OAK_FENCE:0)
Block(-4,9,-5,DARK_OAK_FENCE:0)
Block(-4,9,-4,DARK_OAK_FENCE:0)
Block(-4,9,-3,DARK_OAK_FENCE:0)
Block(-4,9,-2,LOG:1)
Block(-4,9,-1,DARK_OAK_FENCE:0)
Block(-4,9,0,DARK_OAK_FENCE:0)
Block(-4,9,1,DARK_OAK_FENCE:0)
Block(-4,9,2,DARK_OAK_FENCE:0)
Block(-4,9,3,LOG:1)
Block(-4,9,4,DARK_OAK_FENCE:0)
Block(-4,9,5,DARK_OAK_FENCE:0)
Block(-4,9,6,DARK_OAK_FENCE:0)
Block(-4,9,7,LOG:1)
Block(-4,9,8,LOG:1)
Block(-4,10,-7,LOG:1)
Block(-4,10,-6,LOG:9)
Block(-4,10,-5,LOG:9)
Block(-4,10,-4,LOG:9)
Block(-4,10,-3,LOG:9)
Block(-4,10,-2,LOG:1)
Block(-4,10,-1,LOG:9)
Block(-4,10,0,LOG:9)
Block(-4,10,1,LOG:9)
Block(-4,10,2,LOG:9)
Block(-4,10,3,LOG:1)
Block(-4,10,4,LOG:9)
Block(-4,10,5,LOG:9)
Block(-4,10,6,LOG:9)
Block(-4,10,7,LOG:1)
Block(-4,10,8,LOG:9)
Block(-4,11,-7,LOG:1)
Block(-4,11,-6,DARK_OAK_FENCE:0)
Block(-4,11,-5,DARK_OAK_FENCE:0)
Block(-4,11,-4,DARK_OAK_FENCE:0)
Block(-4,11,-3,DARK_OAK_FENCE:0)
Block(-4,11,-2,LOG:1)
Block(-4,11,-1,DARK_OAK_FENCE:0)
Block(-4,11,0,DARK_OAK_FENCE:0)
Block(-4,11,1,DARK_OAK_FENCE:0)
Block(-4,11,2,DARK_OAK_FENCE:0)
Block(-4,11,3,LOG:1)
Block(-4,11,4,DARK_OAK_FENCE:0)
Block(-4,11,5,DARK_OAK_FENCE:0)
Block(-4,11,6,DARK_OAK_FENCE:0)
Block(-4,11,7,LOG:1)
Block(-4,11,8,LOG:1)
Block(-4,12,-7,LOG:1)
Block(-4,12,-5,TORCH:5)
Block(-4,12,-2,LOG:1)
Block(-4,12,0,TORCH:5)
Block(-4,12,3,LOG:1)
Block(-4,12,4,TORCH:5)
Block(-4,12,7,LOG:1)
Block(-4,12,8,TRAP_DOOR:1)
Block(-4,13,-7,LOG:1)
RandomBlock(-4,13,-6,WALL_BANNER:3,../../NBT/Banners/viking_honor_1.nbt,20,WALL_BANNER:3,../../NBT/Banners/viking_honor_2.nbt,20,WALL_BANNER:3,../../NBT/Banners/viking_honor_3.nbt,20,WALL_BANNER:3,../../NBT/Banners/viking_honor_4.nbt,20,WALL_BANNER:3,../../NBT/Banners/viking_honor_5.nbt,20,WALL_BANNER:3,../../NBT/Banners/viking_honor_6.nbt,100)
Block(-4,13,-2,LOG:1)
RandomBlock(-4,13,-1,WALL_BANNER:3,../../NBT/Banners/viking_wealthy_1.nbt,20,WALL_BANNER:3,../../NBT/Banners/viking_wealthy_2.nbt,20,WALL_BANNER:3,../../NBT/Banners/viking_wealthy_3.nbt,20,WALL_BANNER:3,../../NBT/Banners/viking_wealthy_4.nbt,20,WALL_BANNER:3,../../NBT/Banners/viking_wealthy_5.nbt,20,WALL_BANNER:3,../../NBT/Banners/viking_wealthy_6.nbt,20,WALL_BANNER:3,../../NBT/Banners/viking_wealthy_7.nbt,20,WALL_BANNER:3,../../NBT/Banners/viking_wealthy_8.nbt,20,WALL_BANNER:3,../../NBT/Banners/viking_wealthy_9.nbt,100)
Block(-4,13,3,LOG:1)
Block(-4,13,7,LOG:1)
Block(-4,14,-7,LOG:1)
Block(-4,14,-6,LOG:9)
Block(-4,14,-5,LOG:9)
Block(-4,14,-4,LOG:9)
Block(-4,14,-3,LOG:9)
Block(-4,14,-2,LOG:1)
Block(-4,14,-1,LOG:9)
Block(-4,14,0,LOG:9)
Block(-4,14,1,LOG:9)
Block(-4,14,2,LOG:9)
Block(-4,14,3,LOG:1)
Block(-4,14,4,LOG:9)
Block(-4,14,5,LOG:9)
Block(-4,14,6,LOG:9)
Block(-4,14,7,LOG:9)
Block(-4,14,8,LOG:9)
Block(-4,15,-7,LOG:1)
Block(-4,15,-6,SPRUCE_WOOD_STAIRS:0)
Block(-4,15,-5,SPRUCE_WOOD_STAIRS:0)
Block(-4,15,-4,SPRUCE_WOOD_STAIRS:0)
Block(-4,15,-3,SPRUCE_WOOD_STAIRS:0)
Block(-4,15,-2,LOG:1)
Block(-4,15,-1,SPRUCE_WOOD_STAIRS:0)
Block(-4,15,0,SPRUCE_WOOD_STAIRS:0)
Block(-4,15,1,SPRUCE_WOOD_STAIRS:0)
Block(-4,15,2,SPRUCE_WOOD_STAIRS:0)
Block(-4,15,3,LOG:1)
Block(-4,15,4,SPRUCE_WOOD_STAIRS:0)
Block(-4,15,5,SPRUCE_WOOD_STAIRS:0)
Block(-4,15,6,SPRUCE_WOOD_STAIRS:0)
Block(-4,15,7,SPRUCE_WOOD_STAIRS:0)
Block(-4,15,8,SPRUCE_WOOD_STAIRS:5)
Block(-4,16,-7,SPRUCE_WOOD_STAIRS:0)
Block(-4,16,-2,SPRUCE_WOOD_STAIRS:0)
Block(-4,16,3,SPRUCE_WOOD_STAIRS:0)
Block(-4,16,8,SPRUCE_WOOD_STAIRS:0)
Block(-3,0,-7,COBBLESTONE:0)
Block(-3,0,-6,COBBLESTONE:0)
Block(-3,0,-5,STONE:6)
Block(-3,0,-4,STONE:6)
Block(-3,0,-3,COBBLESTONE:0)
Block(-3,0,-2,COBBLESTONE:0)
Block(-3,0,-1,COBBLESTONE:0)
Block(-3,0,0,STONE:6)
Block(-3,0,1,STONE:6)
Block(-3,0,2,COBBLESTONE:0)
Block(-3,0,3,COBBLESTONE:0)
Block(-3,0,4,COBBLESTONE:0)
Block(-3,0,5,STONE:6)
Block(-3,0,6,STONE:6)
Block(-3,0,7,COBBLESTONE:0)
Block(-3,0,8,STONE:6)
Block(-3,1,-7,COBBLESTONE:0)
Block(-3,1,-6,COBBLESTONE:0)
Block(-3,1,-5,STONE:6)
Block(-3,1,-4,STONE:6)
Block(-3,1,-3,COBBLESTONE:0)
Block(-3,1,-2,COBBLESTONE:0)
Block(-3,1,-1,COBBLESTONE:0)
Block(-3,1,0,STONE:6)
Block(-3,1,1,STONE:6)
Block(-3,1,2,COBBLESTONE:0)
Block(-3,1,3,COBBLESTONE:0)
Block(-3,1,4,COBBLESTONE:0)
Block(-3,1,5,STONE:6)
Block(-3,1,6,STONE:6)
Block(-3,1,7,COBBLESTONE:0)
Block(-3,1,8,STONE:6)
Block(-3,2,-7,COBBLESTONE:0)
Block(-3,2,-6,COBBLESTONE:0)
Block(-3,2,-5,STONE:6)
Block(-3,2,-4,STONE:6)
Block(-3,2,-3,COBBLESTONE:0)
Block(-3,2,-2,COBBLESTONE:0)
Block(-3,2,-1,COBBLESTONE:0)
Block(-3,2,0,STONE:6)
Block(-3,2,1,STONE:6)
Block(-3,2,2,COBBLESTONE:0)
Block(-3,2,3,COBBLESTONE:0)
Block(-3,2,4,COBBLESTONE:0)
Block(-3,2,5,STONE:6)
Block(-3,2,6,STONE:6)
Block(-3,2,7,COBBLESTONE:0)
Block(-3,2,8,STONE:6)
Block(-3,3,-7,COBBLESTONE:0)
Block(-3,3,-6,COBBLESTONE:0)
Block(-3,3,-5,STONE:6)
Block(-3,3,-4,STONE:6)
Block(-3,3,-3,COBBLESTONE:0)
Block(-3,3,-2,COBBLESTONE:0)
Block(-3,3,-1,COBBLESTONE:0)
Block(-3,3,0,STONE:6)
Block(-3,3,1,STONE:6)
Block(-3,3,2,COBBLESTONE:0)
Block(-3,3,3,COBBLESTONE:0)
Block(-3,3,4,COBBLESTONE:0)
Block(-3,3,5,STONE:6)
Block(-3,3,6,STONE:6)
Block(-3,3,7,COBBLESTONE:0)
Block(-3,3,8,STONE:6)
Block(-3,4,-7,COBBLESTONE:0)
Block(-3,4,-6,COBBLESTONE:0)
Block(-3,4,-5,STONE:6)
Block(-3,4,-4,STONE:6)
Block(-3,4,-3,COBBLESTONE:0)
Block(-3,4,-2,COBBLESTONE:0)
Block(-3,4,-1,COBBLESTONE:0)
Block(-3,4,0,STONE:6)
Block(-3,4,1,STONE:6)
Block(-3,4,2,COBBLESTONE:0)
Block(-3,4,3,COBBLESTONE:0)
Block(-3,4,4,COBBLESTONE:0)
Block(-3,4,5,STONE:6)
Block(-3,4,6,STONE:6)
Block(-3,4,7,COBBLESTONE:0)
Block(-3,4,8,STONE:6)
Block(-3,5,-7,COBBLESTONE:0)
Block(-3,5,-6,COBBLESTONE:0)
Block(-3,5,-5,STONE:6)
Block(-3,5,-4,STONE:6)
Block(-3,5,-3,COBBLESTONE:0)
Block(-3,5,-2,COBBLESTONE:0)
Block(-3,5,-1,COBBLESTONE:0)
Block(-3,5,0,STONE:6)
Block(-3,5,1,STONE:6)
Block(-3,5,2,COBBLESTONE:0)
Block(-3,5,3,COBBLESTONE:0)
Block(-3,5,4,COBBLESTONE:0)
Block(-3,5,5,STONE:6)
Block(-3,5,6,STONE:6)
Block(-3,5,7,COBBLESTONE:0)
Block(-3,5,8,STONE:6)
Block(-3,6,-7,WOOD_STEP:9)
Block(-3,6,-6,SPRUCE_WOOD_STAIRS:3)
Block(-3,6,-4,CARPET:12)
Block(-3,6,-3,AIR:0)
Block(-3,6,3,AIR:0)
Block(-3,6,5,CARPET:12)
Block(-3,6,7,STONE:6)
Block(-3,6,8,DARK_OAK_FENCE:0)
Block(-3,7,7,STONE:6)
Block(-3,7,8,TORCH:5)
RandomBlock(-3,8,3,WALL_BANNER:5,../../NBT/Banners/viking_wealthy_1.nbt,20,WALL_BANNER:5,../../NBT/Banners/viking_wealthy_2.nbt,20,WALL_BANNER:5,../../NBT/Banners/viking_wealthy_3.nbt,20,WALL_BANNER:5,../../NBT/Banners/viking_wealthy_4.nbt,20,WALL_BANNER:5,../../NBT/Banners/viking_wealthy_5.nbt,20,WALL_BANNER:5,../../NBT/Banners/viking_wealthy_6.nbt,20,WALL_BANNER:5,../../NBT/Banners/viking_wealthy_7.nbt,20,WALL_BANNER:5,../../NBT/Banners/viking_wealthy_8.nbt,20,WALL_BANNER:5,../../NBT/Banners/viking_wealthy_9.nbt,100)
Block(-3,8,7,STONE:6)
RandomBlock(-3,9,-1,WALL_BANNER:5,../../NBT/Banners/viking_honor_1.nbt,20,WALL_BANNER:5,../../NBT/Banners/viking_honor_2.nbt,20,WALL_BANNER:5,../../NBT/Banners/viking_honor_3.nbt,20,WALL_BANNER:5,../../NBT/Banners/viking_honor_4.nbt,20,WALL_BANNER:5,../../NBT/Banners/viking_honor_5.nbt,20,WALL_BANNER:5,../../NBT/Banners/viking_honor_6.nbt,100)
Block(-3,9,3,DARK_OAK_FENCE:0)
RandomBlock(-3,9,4,WALL_BANNER:5,../../NBT/Banners/viking_wealthy_1.nbt,20,WALL_BANNER:5,../../NBT/Banners/viking_wealthy_2.nbt,20,WALL_BANNER:5,../../NBT/Banners/viking_wealthy_3.nbt,20,WALL_BANNER:5,../../NBT/Banners/viking_wealthy_4.nbt,20,WALL_BANNER:5,../../NBT/Banners/viking_wealthy_5.nbt,20,WALL_BANNER:5,../../NBT/Banners/viking_wealthy_6.nbt,20,WALL_BANNER:5,../../NBT/Banners/viking_wealthy_7.nbt,20,WALL_BANNER:5,../../NBT/Banners/viking_wealthy_8.nbt,20,WALL_BANNER:5,../../NBT/Banners/viking_wealthy_9.nbt,100)
Block(-3,9,7,STONE:6)
Block(-3,10,-7,LOG:5)
RandomBlock(-3,10,-5,WALL_BANNER:5,../../NBT/Banners/viking_honor_1.nbt,20,WALL_BANNER:5,../../NBT/Banners/viking_honor_2.nbt,20,WALL_BANNER:5,../../NBT/Banners/viking_honor_3.nbt,20,WALL_BANNER:5,../../NBT/Banners/viking_honor_4.nbt,20,WALL_BANNER:5,../../NBT/Banners/viking_honor_5.nbt,20,WALL_BANNER:5,../../NBT/Banners/viking_honor_6.nbt,100)
Block(-3,10,-2,DARK_OAK_FENCE:0)
RandomBlock(-3,10,0,WALL_BANNER:5,../../NBT/Banners/viking_wealthy_1.nbt,20,WALL_BANNER:5,../../NBT/Banners/viking_wealthy_2.nbt,20,WALL_BANNER:5,../../NBT/Banners/viking_wealthy_3.nbt,20,WALL_BANNER:5,../../NBT/Banners/viking_wealthy_4.nbt,20,WALL_BANNER:5,../../NBT/Banners/viking_wealthy_5.nbt,20,WALL_BANNER:5,../../NBT/Banners/viking_wealthy_6.nbt,20,WALL_BANNER:5,../../NBT/Banners/viking_wealthy_7.nbt,20,WALL_BANNER:5,../../NBT/Banners/viking_wealthy_8.nbt,20,WALL_BANNER:5,../../NBT/Banners/viking_wealthy_9.nbt,100)
Block(-3,10,3,TORCH:5)
Block(-3,10,7,LOG:5)
Block(-3,11,-7,DARK_OAK_FENCE:0)
Block(-3,11,-2,TORCH:5)
Block(-3,11,7,WOOD:1)
Block(-3,11,8,SPRUCE_WOOD_STAIRS:5)
Block(-3,12,7,WOOD:1)
Block(-3,12,8,SPRUCE_WOOD_STAIRS:0)
RandomBlock(-3,13,3,WALL_BANNER:5,../../NBT/Banners/viking_wealthy_1.nbt,20,WALL_BANNER:5,../../NBT/Banners/viking_wealthy_2.nbt,20,WALL_BANNER:5,../../NBT/Banners/viking_wealthy_3.nbt,20,WALL_BANNER:5,../../NBT/Banners/viking_wealthy_4.nbt,20,WALL_BANNER:5,../../NBT/Banners/viking_wealthy_5.nbt,20,WALL_BANNER:5,../../NBT/Banners/viking_wealthy_6.nbt,20,WALL_BANNER:5,../../NBT/Banners/viking_wealthy_7.nbt,20,WALL_BANNER:5,../../NBT/Banners/viking_wealthy_8.nbt,20,WALL_BANNER:5,../../NBT/Banners/viking_wealthy_9.nbt,100)
Block(-3,13,7,WOOD:1)
Block(-3,14,-7,LOG:5)
Block(-3,14,-2,LOG:5)
Block(-3,14,3,LOG:5)
Block(-3,14,7,WOOD:1)
Block(-3,15,-6,SPRUCE_WOOD_STAIRS:5)
Block(-3,15,-5,SPRUCE_WOOD_STAIRS:5)
Block(-3,15,-4,SPRUCE_WOOD_STAIRS:5)
Block(-3,15,-3,SPRUCE_WOOD_STAIRS:5)
Block(-3,15,-1,SPRUCE_WOOD_STAIRS:5)
Block(-3,15,0,SPRUCE_WOOD_STAIRS:5)
Block(-3,15,1,SPRUCE_WOOD_STAIRS:5)
Block(-3,15,2,SPRUCE_WOOD_STAIRS:5)
Block(-3,15,4,SPRUCE_WOOD_STAIRS:5)
Block(-3,15,5,SPRUCE_WOOD_STAIRS:5)
Block(-3,15,6,SPRUCE_WOOD_STAIRS:5)
Block(-3,15,7,WOOD:1)
Block(-3,16,-7,SPRUCE_WOOD_STAIRS:5)
Block(-3,16,-6,SPRUCE_WOOD_STAIRS:0)
Block(-3,16,-5,SPRUCE_WOOD_STAIRS:0)
Block(-3,16,-4,SPRUCE_WOOD_STAIRS:0)
Block(-3,16,-3,SPRUCE_WOOD_STAIRS:0)
Block(-3,16,-2,SPRUCE_WOOD_STAIRS:5)
Block(-3,16,-1,SPRUCE_WOOD_STAIRS:0)
Block(-3,16,0,SPRUCE_WOOD_STAIRS:0)
Block(-3,16,1,SPRUCE_WOOD_STAIRS:0)
Block(-3,16,2,SPRUCE_WOOD_STAIRS:0)
Block(-3,16,3,SPRUCE_WOOD_STAIRS:5)
Block(-3,16,4,SPRUCE_WOOD_STAIRS:0)
Block(-3,16,5,SPRUCE_WOOD_STAIRS:0)
Block(-3,16,6,SPRUCE_WOOD_STAIRS:0)
Block(-3,16,7,SPRUCE_WOOD_STAIRS:0)
Block(-3,16,8,SPRUCE_WOOD_STAIRS:5)
Block(-3,17,-7,SPRUCE_WOOD_STAIRS:0)
Block(-3,17,-2,SPRUCE_WOOD_STAIRS:0)
Block(-3,17,3,SPRUCE_WOOD_STAIRS:0)
Block(-3,17,8,SPRUCE_WOOD_STAIRS:0)
Block(-2,0,-7,COBBLESTONE:0)
Block(-2,0,-6,COBBLESTONE:0)
Block(-2,0,-5,COBBLESTONE:0)
Block(-2,0,-4,COBBLESTONE:0)
Block(-2,0,-3,COBBLESTONE:0)
Block(-2,0,-2,COBBLESTONE:0)
Block(-2,0,-1,COBBLESTONE:0)
Block(-2,0,0,COBBLESTONE:0)
Block(-2,0,1,COBBLESTONE:0)
Block(-2,0,2,COBBLESTONE:0)
Block(-2,0,3,COBBLESTONE:0)
Block(-2,0,4,COBBLESTONE:0)
Block(-2,0,5,COBBLESTONE:0)
Block(-2,0,6,COBBLESTONE:0)
Block(-2,0,7,COBBLESTONE:0)
Block(-2,0,8,STONE:6)
Block(-2,1,-7,COBBLESTONE:0)
Block(-2,1,-6,COBBLESTONE:0)
Block(-2,1,-5,COBBLESTONE:0)
Block(-2,1,-4,COBBLESTONE:0)
Block(-2,1,-3,COBBLESTONE:0)
Block(-2,1,-2,COBBLESTONE:0)
Block(-2,1,-1,COBBLESTONE:0)
Block(-2,1,0,COBBLESTONE:0)
Block(-2,1,1,COBBLESTONE:0)
Block(-2,1,2,COBBLESTONE:0)
Block(-2,1,3,COBBLESTONE:0)
Block(-2,1,4,COBBLESTONE:0)
Block(-2,1,5,COBBLESTONE:0)
Block(-2,1,6,COBBLESTONE:0)
Block(-2,1,7,COBBLESTONE:0)
Block(-2,1,8,STONE:6)
Block(-2,2,-7,COBBLESTONE:0)
Block(-2,2,-6,COBBLESTONE:0)
Block(-2,2,-5,COBBLESTONE:0)
Block(-2,2,-4,COBBLESTONE:0)
Block(-2,2,-3,COBBLESTONE:0)
Block(-2,2,-2,COBBLESTONE:0)
Block(-2,2,-1,COBBLESTONE:0)
Block(-2,2,0,COBBLESTONE:0)
Block(-2,2,1,COBBLESTONE:0)
Block(-2,2,2,COBBLESTONE:0)
Block(-2,2,3,COBBLESTONE:0)
Block(-2,2,4,COBBLESTONE:0)
Block(-2,2,5,COBBLESTONE:0)
Block(-2,2,6,COBBLESTONE:0)
Block(-2,2,7,COBBLESTONE:0)
Block(-2,2,8,STONE:6)
Block(-2,3,-7,COBBLESTONE:0)
Block(-2,3,-6,COBBLESTONE:0)
Block(-2,3,-5,COBBLESTONE:0)
Block(-2,3,-4,COBBLESTONE:0)
Block(-2,3,-3,COBBLESTONE:0)
Block(-2,3,-2,COBBLESTONE:0)
Block(-2,3,-1,COBBLESTONE:0)
Block(-2,3,0,COBBLESTONE:0)
Block(-2,3,1,COBBLESTONE:0)
Block(-2,3,2,COBBLESTONE:0)
Block(-2,3,3,COBBLESTONE:0)
Block(-2,3,4,COBBLESTONE:0)
Block(-2,3,5,COBBLESTONE:0)
Block(-2,3,6,COBBLESTONE:0)
Block(-2,3,7,COBBLESTONE:0)
Block(-2,3,8,STONE:6)
Block(-2,4,-7,COBBLESTONE:0)
Block(-2,4,-6,COBBLESTONE:0)
Block(-2,4,-5,COBBLESTONE:0)
Block(-2,4,-4,COBBLESTONE:0)
Block(-2,4,-3,COBBLESTONE:0)
Block(-2,4,-2,COBBLESTONE:0)
Block(-2,4,-1,COBBLESTONE:0)
Block(-2,4,0,COBBLESTONE:0)
Block(-2,4,1,COBBLESTONE:0)
Block(-2,4,2,COBBLESTONE:0)
Block(-2,4,3,COBBLESTONE:0)
Block(-2,4,4,COBBLESTONE:0)
Block(-2,4,5,COBBLESTONE:0)
Block(-2,4,6,COBBLESTONE:0)
Block(-2,4,7,COBBLESTONE:0)
Block(-2,4,8,STONE:6)
Block(-2,5,-7,COBBLESTONE:0)
Block(-2,5,-6,COBBLESTONE:0)
Block(-2,5,-5,COBBLESTONE:0)
Block(-2,5,-4,COBBLESTONE:0)
Block(-2,5,-3,COBBLESTONE:0)
Block(-2,5,-2,COBBLESTONE_STAIRS:1)
Block(-2,5,-1,STONE:6)
Block(-2,5,0,COBBLESTONE_STAIRS:1)
Block(-2,5,1,COBBLESTONE_STAIRS:1)
Block(-2,5,2,STONE:6)
Block(-2,5,3,COBBLESTONE_STAIRS:1)
Block(-2,5,4,COBBLESTONE:0)
Block(-2,5,5,COBBLESTONE:0)
Block(-2,5,6,COBBLESTONE:0)
Block(-2,5,7,COBBLESTONE:0)
Block(-2,5,8,STONE:6)
Block(-2,6,-7,WOOD_STEP:9)
Block(-2,6,-6,SPRUCE_WOOD_STAIRS:0)
Block(-2,6,-5,SPRUCE_WOOD_STAIRS:3)
Block(-2,6,-4,CARPET:12)
Block(-2,6,-1,STEP:0)
Block(-2,6,2,STEP:0)
Block(-2,6,5,CARPET:12)
Block(-2,6,6,CARPET:12)
Block(-2,6,7,WOOD:5)
Block(-2,7,7,WOOD:5)
Block(-2,8,-2,minecraft:black_glazed_terracotta:0)
Block(-2,8,7,WOOD:5)
Block(-2,9,-2,minecraft:red_glazed_terracotta:0)
Block(-2,9,7,STONE:6)
Block(-2,10,-7,LOG:5)
Block(-2,10,-2,IRON_FENCE:0)
Block(-2,10,7,LOG:5)
Block(-2,11,-7,DARK_OAK_FENCE:0)
Block(-2,11,-2,IRON_FENCE:0)
Block(-2,11,7,SPRUCE_WOOD_STAIRS:0)
Block(-2,12,-2,IRON_FENCE:0)
Block(-2,12,7,SPRUCE_WOOD_STAIRS:0)
Block(-2,12,8,SPRUCE_WOOD_STAIRS:5)
Block(-2,13,-2,IRON_FENCE:0)
Block(-2,13,7,SPRUCE_WOOD_STAIRS:0)
Block(-2,13,8,SPRUCE_WOOD_STAIRS:0)
Block(-2,14,-7,LOG:5)
Block(-2,14,-2,LOG:5)
Block(-2,14,3,LOG:5)
Block(-2,14,7,SPRUCE_WOOD_STAIRS:0)
Block(-2,15,7,SPRUCE_WOOD_STAIRS:0)
Block(-2,16,-6,SPRUCE_WOOD_STAIRS:5)
Block(-2,16,-5,SPRUCE_WOOD_STAIRS:5)
Block(-2,16,-4,SPRUCE_WOOD_STAIRS:5)
Block(-2,16,-3,SPRUCE_WOOD_STAIRS:5)
Block(-2,16,4,SPRUCE_WOOD_STAIRS:5)
Block(-2,16,5,SPRUCE_WOOD_STAIRS:5)
Block(-2,16,6,SPRUCE_WOOD_STAIRS:5)
Block(-2,16,7,WOOD:1)
Block(-2,17,-7,SPRUCE_WOOD_STAIRS:5)
Block(-2,17,-6,SPRUCE_WOOD_STAIRS:0)
Block(-2,17,-5,SPRUCE_WOOD_STAIRS:0)
Block(-2,17,-4,SPRUCE_WOOD_STAIRS:0)
Block(-2,17,-3,SPRUCE_WOOD_STAIRS:0)
Block(-2,17,-2,SPRUCE_WOOD_STAIRS:5)
Block(-2,17,-1,TRAP_DOOR:2)
Block(-2,17,0,TRAP_DOOR:2)
Block(-2,17,1,TRAP_DOOR:2)
Block(-2,17,2,TRAP_DOOR:2)
Block(-2,17,3,SPRUCE_WOOD_STAIRS:5)
Block(-2,17,4,SPRUCE_WOOD_STAIRS:0)
Block(-2,17,5,SPRUCE_WOOD_STAIRS:0)
Block(-2,17,6,SPRUCE_WOOD_STAIRS:0)
Block(-2,17,7,SPRUCE_WOOD_STAIRS:0)
Block(-2,17,8,SPRUCE_WOOD_STAIRS:5)
Block(-2,18,-7,SPRUCE_WOOD_STAIRS:0)
Block(-2,18,-2,SPRUCE_WOOD_STAIRS:0)
Block(-2,18,3,SPRUCE_WOOD_STAIRS:0)
Block(-2,18,8,SPRUCE_WOOD_STAIRS:0)
Block(-1,0,-7,STONE:6)
Block(-1,0,-6,COBBLESTONE:0)
Block(-1,0,-5,STONE:6)
Block(-1,0,-4,STONE:6)
Block(-1,0,-3,COBBLESTONE:0)
Block(-1,0,-2,COBBLESTONE:0)
Block(-1,0,-1,CONCRETE_POWDER:15)
Block(-1,0,0,MAGMA:0)
Block(-1,0,1,CONCRETE_POWDER:15)
Block(-1,0,2,MAGMA:0)
Block(-1,0,3,COBBLESTONE:0)
Block(-1,0,4,COBBLESTONE:0)
Block(-1,0,5,STONE:6)
Block(-1,0,6,STONE:6)
Block(-1,0,7,COBBLESTONE:0)
Block(-1,0,8,STONE:6)
Block(-1,1,-7,STONE:6)
Block(-1,1,-6,COBBLESTONE:0)
Block(-1,1,-5,STONE:6)
Block(-1,1,-4,STONE:6)
Block(-1,1,-3,COBBLESTONE:0)
Block(-1,1,-2,COBBLESTONE:0)
Block(-1,1,-1,CONCRETE_POWDER:15)
Block(-1,1,0,MAGMA:0)
Block(-1,1,1,CONCRETE_POWDER:15)
Block(-1,1,2,MAGMA:0)
Block(-1,1,3,COBBLESTONE:0)
Block(-1,1,4,COBBLESTONE:0)
Block(-1,1,5,STONE:6)
Block(-1,1,6,STONE:6)
Block(-1,1,7,COBBLESTONE:0)
Block(-1,1,8,STONE:6)
Block(-1,2,-7,STONE:6)
Block(-1,2,-6,COBBLESTONE:0)
Block(-1,2,-5,STONE:6)
Block(-1,2,-4,STONE:6)
Block(-1,2,-3,COBBLESTONE:0)
Block(-1,2,-2,COBBLESTONE:0)
Block(-1,2,-1,CONCRETE_POWDER:15)
Block(-1,2,0,MAGMA:0)
Block(-1,2,1,CONCRETE_POWDER:15)
Block(-1,2,2,MAGMA:0)
Block(-1,2,3,COBBLESTONE:0)
Block(-1,2,4,COBBLESTONE:0)
Block(-1,2,5,STONE:6)
Block(-1,2,6,STONE:6)
Block(-1,2,7,COBBLESTONE:0)
Block(-1,2,8,STONE:6)
Block(-1,3,-7,STONE:6)
Block(-1,3,-6,COBBLESTONE:0)
Block(-1,3,-5,STONE:6)
Block(-1,3,-4,STONE:6)
Block(-1,3,-3,COBBLESTONE:0)
Block(-1,3,-2,COBBLESTONE:0)
Block(-1,3,-1,CONCRETE_POWDER:15)
Block(-1,3,0,MAGMA:0)
Block(-1,3,1,CONCRETE_POWDER:15)
Block(-1,3,2,MAGMA:0)
Block(-1,3,3,COBBLESTONE:0)
Block(-1,3,4,COBBLESTONE:0)
Block(-1,3,5,STONE:6)
Block(-1,3,6,STONE:6)
Block(-1,3,7,COBBLESTONE:0)
Block(-1,3,8,STONE:6)
Block(-1,4,-7,STONE:6)
Block(-1,4,-6,COBBLESTONE:0)
Block(-1,4,-5,STONE:6)
Block(-1,4,-4,STONE:6)
Block(-1,4,-3,COBBLESTONE:0)
Block(-1,4,-2,COBBLESTONE:0)
Block(-1,4,-1,CONCRETE_POWDER:15)
Block(-1,4,0,MAGMA:0)
Block(-1,4,1,CONCRETE_POWDER:15)
Block(-1,4,2,MAGMA:0)
Block(-1,4,3,COBBLESTONE:0)
Block(-1,4,4,COBBLESTONE:0)
Block(-1,4,5,STONE:6)
Block(-1,4,6,STONE:6)
Block(-1,4,7,COBBLESTONE:0)
Block(-1,4,8,STONE:6)
Block(-1,5,-7,STONE:6)
Block(-1,5,-6,COBBLESTONE:0)
Block(-1,5,-5,STONE:6)
Block(-1,5,-4,STONE:6)
Block(-1,5,-3,COBBLESTONE:0)
Block(-1,5,-2,COBBLESTONE_STAIRS:3)
Block(-1,5,0,FIRE:0)
Block(-1,5,2,FIRE:0)
Block(-1,5,3,COBBLESTONE_STAIRS:2)
Block(-1,5,4,COBBLESTONE:0)
Block(-1,5,5,STONE:6)
Block(-1,5,6,STONE:6)
Block(-1,5,7,COBBLESTONE:0)
Block(-1,5,8,STONE:6)
Block(-1,6,-7,WOOD_STEP:9)
Block(-1,6,-6,WOOD_STEP:9)
Block(-1,6,-5,SPRUCE_WOOD_STAIRS:3)
Block(-1,6,-4,CARPET:12)
Block(-1,6,-1,IRON_TRAPDOOR:1)
Block(-1,6,0,IRON_TRAPDOOR:3)
Block(-1,6,1,IRON_TRAPDOOR:3)
Block(-1,6,2,IRON_TRAPDOOR:0)
Block(-1,6,7,SPRUCE_DOOR:1)
Block(-1,7,7,SPRUCE_DOOR:9)
Block(-1,8,7,WOOD:5)
Block(-1,9,1,minecraft:red_glazed_terracotta:0)
Block(-1,9,7,STONE:6)
Block(-1,10,-7,LOG:5)
Block(-1,10,1,minecraft:black_glazed_terracotta:0)
Block(-1,10,7,LOG:5)
Block(-1,11,-7,DARK_OAK_FENCE:0)
Block(-1,11,1,IRON_FENCE:0)
RandomBlock(-1,11,6,WALL_BANNER:2,../../NBT/Banners/viking_honor_1.nbt,20,WALL_BANNER:2,../../NBT/Banners/viking_honor_2.nbt,20,WALL_BANNER:2,../../NBT/Banners/viking_honor_3.nbt,20,WALL_BANNER:2,../../NBT/Banners/viking_honor_4.nbt,20,WALL_BANNER:2,../../NBT/Banners/viking_honor_5.nbt,20,WALL_BANNER:2,../../NBT/Banners/viking_honor_6.nbt,100)
Block(-1,11,7,DARK_OAK_FENCE:0)
Block(-1,12,1,IRON_FENCE:0)
RandomBlock(-1,12,6,WALL_BANNER:2,../../NBT/Banners/viking_wealthy_1.nbt,20,WALL_BANNER:2,../../NBT/Banners/viking_wealthy_2.nbt,20,WALL_BANNER:2,../../NBT/Banners/viking_wealthy_3.nbt,20,WALL_BANNER:2,../../NBT/Banners/viking_wealthy_4.nbt,20,WALL_BANNER:2,../../NBT/Banners/viking_wealthy_5.nbt,20,WALL_BANNER:2,../../NBT/Banners/viking_wealthy_6.nbt,20,WALL_BANNER:2,../../NBT/Banners/viking_wealthy_7.nbt,20,WALL_BANNER:2,../../NBT/Banners/viking_wealthy_8.nbt,20,WALL_BANNER:2,../../NBT/Banners/viking_wealthy_9.nbt,100)
Block(-1,12,7,DARK_OAK_FENCE:0)
Block(-1,13,1,IRON_FENCE:0)
RandomBlock(-1,13,6,WALL_BANNER:2,../../NBT/Banners/viking_honor_1.nbt,20,WALL_BANNER:2,../../NBT/Banners/viking_honor_2.nbt,20,WALL_BANNER:2,../../NBT/Banners/viking_honor_3.nbt,20,WALL_BANNER:2,../../NBT/Banners/viking_honor_4.nbt,20,WALL_BANNER:2,../../NBT/Banners/viking_honor_5.nbt,20,WALL_BANNER:2,../../NBT/Banners/viking_honor_6.nbt,100)
Block(-1,13,7,DARK_OAK_FENCE:0)
Block(-1,13,8,SPRUCE_WOOD_STAIRS:5)
Block(-1,14,-7,LOG:5)
Block(-1,14,-2,LOG:5)
Block(-1,14,1,IRON_FENCE:0)
Block(-1,14,3,LOG:5)
RandomBlock(-1,14,6,WALL_BANNER:2,../../NBT/Banners/viking_wealthy_1.nbt,20,WALL_BANNER:2,../../NBT/Banners/viking_wealthy_2.nbt,20,WALL_BANNER:2,../../NBT/Banners/viking_wealthy_3.nbt,20,WALL_BANNER:2,../../NBT/Banners/viking_wealthy_4.nbt,20,WALL_BANNER:2,../../NBT/Banners/viking_wealthy_5.nbt,20,WALL_BANNER:2,../../NBT/Banners/viking_wealthy_6.nbt,20,WALL_BANNER:2,../../NBT/Banners/viking_wealthy_7.nbt,20,WALL_BANNER:2,../../NBT/Banners/viking_wealthy_8.nbt,20,WALL_BANNER:2,../../NBT/Banners/viking_wealthy_9.nbt,100)
Block(-1,14,7,DARK_OAK_FENCE:0)
Block(-1,14,8,SPRUCE_WOOD_STAIRS:0)
Block(-1,15,1,IRON_FENCE:0)
RandomBlock(-1,15,6,WALL_BANNER:2,../../NBT/Banners/viking_honor_1.nbt,20,WALL_BANNER:2,../../NBT/Banners/viking_honor_2.nbt,20,WALL_BANNER:2,../../NBT/Banners/viking_honor_3.nbt,20,WALL_BANNER:2,../../NBT/Banners/viking_honor_4.nbt,20,WALL_BANNER:2,../../NBT/Banners/viking_honor_5.nbt,20,WALL_BANNER:2,../../NBT/Banners/viking_honor_6.nbt,100)
Block(-1,15,7,DARK_OAK_FENCE:0)
RandomBlock(-1,15,8,WALL_BANNER:3,../../NBT/Banners/viking_honor_1.nbt,20,WALL_BANNER:3,../../NBT/Banners/viking_honor_2.nbt,20,WALL_BANNER:3,../../NBT/Banners/viking_honor_3.nbt,20,WALL_BANNER:3,../../NBT/Banners/viking_honor_4.nbt,20,WALL_BANNER:3,../../NBT/Banners/viking_honor_5.nbt,20,WALL_BANNER:3,../../NBT/Banners/viking_honor_6.nbt,100)
Block(-1,16,-7,LOG:9)
Block(-1,16,-6,LOG:9)
Block(-1,16,-5,LOG:9)
Block(-1,16,-4,LOG:9)
Block(-1,16,-3,LOG:9)
Block(-1,16,-2,LOG:9)
Block(-1,16,-1,LOG:9)
Block(-1,16,0,LOG:9)
Block(-1,16,1,LOG:9)
Block(-1,16,2,LOG:9)
Block(-1,16,3,LOG:9)
Block(-1,16,4,LOG:9)
Block(-1,16,5,LOG:9)
Block(-1,16,6,LOG:9)
Block(-1,16,7,LOG:9)
Block(-1,16,8,LOG:9)
Block(-1,17,-7,LOG:9)
Block(-1,17,-6,LOG:9)
Block(-1,17,-5,LOG:9)
Block(-1,17,-4,LOG:9)
Block(-1,17,-3,LOG:9)
Block(-1,17,-2,LOG:9)
Block(-1,17,-1,LOG:9)
Block(-1,17,0,LOG:9)
Block(-1,17,1,LOG:9)
Block(-1,17,2,LOG:9)
Block(-1,17,3,LOG:9)
Block(-1,17,4,LOG:9)
Block(-1,17,5,LOG:9)
Block(-1,17,6,LOG:9)
Block(-1,17,7,LOG:9)
Block(-1,17,8,LOG:9)
Block(-1,18,-7,SPRUCE_WOOD_STAIRS:5)
Block(-1,18,-6,SPRUCE_WOOD_STAIRS:0)
Block(-1,18,-5,SPRUCE_WOOD_STAIRS:0)
Block(-1,18,-4,SPRUCE_WOOD_STAIRS:0)
Block(-1,18,-3,SPRUCE_WOOD_STAIRS:0)
Block(-1,18,-2,SPRUCE_WOOD_STAIRS:5)
Block(-1,18,-1,SPRUCE_WOOD_STAIRS:5)
Block(-1,18,0,SPRUCE_WOOD_STAIRS:5)
Block(-1,18,1,SPRUCE_WOOD_STAIRS:5)
Block(-1,18,2,SPRUCE_WOOD_STAIRS:5)
Block(-1,18,3,SPRUCE_WOOD_STAIRS:5)
Block(-1,18,4,SPRUCE_WOOD_STAIRS:0)
Block(-1,18,5,SPRUCE_WOOD_STAIRS:0)
Block(-1,18,6,SPRUCE_WOOD_STAIRS:0)
Block(-1,18,7,SPRUCE_WOOD_STAIRS:0)
Block(-1,18,8,SPRUCE_WOOD_STAIRS:5)
Block(-1,19,-7,SPRUCE_WOOD_STAIRS:0)
Block(-1,19,-2,SPRUCE_WOOD_STAIRS:0)
Block(-1,19,-1,SPRUCE_WOOD_STAIRS:0)
Block(-1,19,0,SPRUCE_WOOD_STAIRS:0)
Block(-1,19,1,SPRUCE_WOOD_STAIRS:0)
Block(-1,19,2,SPRUCE_WOOD_STAIRS:0)
Block(-1,19,3,SPRUCE_WOOD_STAIRS:0)
Block(-1,19,8,SPRUCE_WOOD_STAIRS:0)
Block(-1,20,-7,SPRUCE_WOOD_STAIRS:1)
Block(-1,20,-2,SPRUCE_WOOD_STAIRS:1)
Block(-1,20,3,SPRUCE_WOOD_STAIRS:1)
Block(-1,20,8,SPRUCE_WOOD_STAIRS:1)
Block(0,0,-7,STONE:6)
Block(0,0,-6,COBBLESTONE:0)
Block(0,0,-5,STONE:6)
Block(0,0,-4,STONE:6)
Block(0,0,-3,COBBLESTONE:0)
Block(0,0,-2,COBBLESTONE:0)
Block(0,0,-1,MAGMA:0)
Block(0,0,0,CONCRETE_POWDER:15)
Block(0,0,1,COAL_ORE:0)
Block(0,0,2,CONCRETE_POWDER:15)
Block(0,0,3,COBBLESTONE:0)
Block(0,0,4,COBBLESTONE:0)
Block(0,0,5,STONE:6)
Block(0,0,6,STONE:6)
Block(0,0,7,COBBLESTONE:0)
Block(0,0,8,STONE:6)
Block(0,1,-7,STONE:6)
Block(0,1,-6,COBBLESTONE:0)
Block(0,1,-5,STONE:6)
Block(0,1,-4,STONE:6)
Block(0,1,-3,COBBLESTONE:0)
Block(0,1,-2,COBBLESTONE:0)
Block(0,1,-1,MAGMA:0)
Block(0,1,0,CONCRETE_POWDER:15)
Block(0,1,1,COAL_ORE:0)
Block(0,1,2,CONCRETE_POWDER:15)
Block(0,1,3,COBBLESTONE:0)
Block(0,1,4,COBBLESTONE:0)
Block(0,1,5,STONE:6)
Block(0,1,6,STONE:6)
Block(0,1,7,COBBLESTONE:0)
Block(0,1,8,STONE:6)
Block(0,2,-7,STONE:6)
Block(0,2,-6,COBBLESTONE:0)
Block(0,2,-5,STONE:6)
Block(0,2,-4,STONE:6)
Block(0,2,-3,COBBLESTONE:0)
Block(0,2,-2,COBBLESTONE:0)
Block(0,2,-1,MAGMA:0)
Block(0,2,0,CONCRETE_POWDER:15)
Block(0,2,1,COAL_ORE:0)
Block(0,2,2,CONCRETE_POWDER:15)
Block(0,2,3,COBBLESTONE:0)
Block(0,2,4,COBBLESTONE:0)
Block(0,2,5,STONE:6)
Block(0,2,6,STONE:6)
Block(0,2,7,COBBLESTONE:0)
Block(0,2,8,STONE:6)
Block(0,3,-7,STONE:6)
Block(0,3,-6,COBBLESTONE:0)
Block(0,3,-5,STONE:6)
Block(0,3,-4,STONE:6)
Block(0,3,-3,COBBLESTONE:0)
Block(0,3,-2,COBBLESTONE:0)
Block(0,3,-1,MAGMA:0)
Block(0,3,0,CONCRETE_POWDER:15)
Block(0,3,1,COAL_ORE:0)
Block(0,3,2,CONCRETE_POWDER:15)
Block(0,3,3,COBBLESTONE:0)
Block(0,3,4,COBBLESTONE:0)
Block(0,3,5,STONE:6)
Block(0,3,6,STONE:6)
Block(0,3,7,COBBLESTONE:0)
Block(0,3,8,STONE:6)
Block(0,4,-7,STONE:6)
Block(0,4,-6,COBBLESTONE:0)
Block(0,4,-5,STONE:6)
Block(0,4,-4,STONE:6)
Block(0,4,-3,COBBLESTONE:0)
Block(0,4,-2,COBBLESTONE:0)
Block(0,4,-1,MAGMA:0)
Block(0,4,0,CONCRETE_POWDER:15)
Block(0,4,1,COAL_ORE:0)
Block(0,4,2,CONCRETE_POWDER:15)
Block(0,4,3,COBBLESTONE:0)
Block(0,4,4,COBBLESTONE:0)
Block(0,4,5,STONE:6)
Block(0,4,6,STONE:6)
Block(0,4,7,COBBLESTONE:0)
Block(0,4,8,STONE:6)
Block(0,5,-7,STONE:6)
Block(0,5,-6,COBBLESTONE:0)
Block(0,5,-5,STONE:6)
Block(0,5,-4,STONE:6)
Block(0,5,-3,COBBLESTONE:0)
Block(0,5,-2,COBBLESTONE_STAIRS:3)
Block(0,5,-1,FIRE:0)
Block(0,5,3,COBBLESTONE_STAIRS:2)
Block(0,5,4,COBBLESTONE:0)
Block(0,5,5,STONE:6)
Block(0,5,6,STONE:6)
Block(0,5,7,COBBLESTONE:0)
Block(0,5,8,STONE:6)
Block(0,6,-7,WOOD_STEP:9)
Block(0,6,-6,WOOD_STEP:9)
Block(0,6,-5,SPRUCE_WOOD_STAIRS:3)
Block(0,6,-4,CARPET:12)
Block(0,6,-1,IRON_TRAPDOOR:2)
Block(0,6,0,IRON_TRAPDOOR:2)
Block(0,6,1,IRON_TRAPDOOR:2)
Block(0,6,2,IRON_TRAPDOOR:2)
Block(0,6,7,SPRUCE_DOOR:1)
Block(0,7,7,SPRUCE_DOOR:8)
Block(0,8,7,WOOD:5)
Block(0,9,7,STONE:6)
Block(0,10,-7,LOG:5)
Block(0,10,7,LOG:5)
Block(0,11,-7,DARK_OAK_FENCE:0)
RandomBlock(0,11,6,WALL_BANNER:2,../../NBT/Banners/viking_honor_1.nbt,20,WALL_BANNER:2,../../NBT/Banners/viking_honor_2.nbt,20,WALL_BANNER:2,../../NBT/Banners/viking_honor_3.nbt,20,WALL_BANNER:2,../../NBT/Banners/viking_honor_4.nbt,20,WALL_BANNER:2,../../NBT/Banners/viking_honor_5.nbt,20,WALL_BANNER:2,../../NBT/Banners/viking_honor_6.nbt,100)
Block(0,11,7,DARK_OAK_FENCE:0)
RandomBlock(0,12,6,WALL_BANNER:2,../../NBT/Banners/viking_wealthy_1.nbt,20,WALL_BANNER:2,../../NBT/Banners/viking_wealthy_2.nbt,20,WALL_BANNER:2,../../NBT/Banners/viking_wealthy_3.nbt,20,WALL_BANNER:2,../../NBT/Banners/viking_wealthy_4.nbt,20,WALL_BANNER:2,../../NBT/Banners/viking_wealthy_5.nbt,20,WALL_BANNER:2,../../NBT/Banners/viking_wealthy_6.nbt,20,WALL_BANNER:2,../../NBT/Banners/viking_wealthy_7.nbt,20,WALL_BANNER:2,../../NBT/Banners/viking_wealthy_8.nbt,20,WALL_BANNER:2,../../NBT/Banners/viking_wealthy_9.nbt,100)
Block(0,12,7,DARK_OAK_FENCE:0)
RandomBlock(0,13,6,WALL_BANNER:2,../../NBT/Banners/viking_honor_1.nbt,20,WALL_BANNER:2,../../NBT/Banners/viking_honor_2.nbt,20,WALL_BANNER:2,../../NBT/Banners/viking_honor_3.nbt,20,WALL_BANNER:2,../../NBT/Banners/viking_honor_4.nbt,20,WALL_BANNER:2,../../NBT/Banners/viking_honor_5.nbt,20,WALL_BANNER:2,../../NBT/Banners/viking_honor_6.nbt,100)
Block(0,13,7,DARK_OAK_FENCE:0)
Block(0,13,8,SPRUCE_WOOD_STAIRS:4)
Block(0,14,-7,LOG:5)
Block(0,14,-2,LOG:5)
Block(0,14,3,LOG:5)
Block(0,14,7,DARK_OAK_FENCE:0)
Block(0,14,8,SPRUCE_WOOD_STAIRS:1)
RandomBlock(0,15,6,WALL_BANNER:2,../../NBT/Banners/viking_honor_1.nbt,20,WALL_BANNER:2,../../NBT/Banners/viking_honor_2.nbt,20,WALL_BANNER:2,../../NBT/Banners/viking_honor_3.nbt,20,WALL_BANNER:2,../../NBT/Banners/viking_honor_4.nbt,20,WALL_BANNER:2,../../NBT/Banners/viking_honor_5.nbt,20,WALL_BANNER:2,../../NBT/Banners/viking_honor_6.nbt,100)
Block(0,15,7,DARK_OAK_FENCE:0)
RandomBlock(0,15,8,WALL_BANNER:3,../../NBT/Banners/viking_honor_1.nbt,20,WALL_BANNER:3,../../NBT/Banners/viking_honor_2.nbt,20,WALL_BANNER:3,../../NBT/Banners/viking_honor_3.nbt,20,WALL_BANNER:3,../../NBT/Banners/viking_honor_4.nbt,20,WALL_BANNER:3,../../NBT/Banners/viking_honor_5.nbt,20,WALL_BANNER:3,../../NBT/Banners/viking_honor_6.nbt,100)
Block(0,16,-7,LOG:9)
Block(0,16,-6,LOG:9)
Block(0,16,-5,LOG:9)
Block(0,16,-4,LOG:9)
Block(0,16,-3,LOG:9)
Block(0,16,-2,LOG:9)
Block(0,16,-1,LOG:9)
Block(0,16,0,LOG:9)
Block(0,16,1,LOG:9)
Block(0,16,2,LOG:9)
Block(0,16,3,LOG:9)
Block(0,16,4,LOG:9)
Block(0,16,5,LOG:9)
Block(0,16,6,LOG:9)
Block(0,16,7,LOG:9)
Block(0,16,8,LOG:9)
Block(0,17,-7,LOG:9)
Block(0,17,-6,LOG:9)
Block(0,17,-5,LOG:9)
Block(0,17,-4,LOG:9)
Block(0,17,-3,LOG:5)
Block(0,17,-2,LOG:9)
Block(0,17,-1,LOG:9)
Block(0,17,0,LOG:9)
Block(0,17,1,LOG:9)
Block(0,17,2,LOG:9)
Block(0,17,3,LOG:9)
Block(0,17,4,LOG:9)
Block(0,17,5,LOG:9)
Block(0,17,6,LOG:9)
Block(0,17,7,LOG:9)
Block(0,17,8,LOG:9)
Block(0,18,-7,SPRUCE_WOOD_STAIRS:4)
Block(0,18,-6,SPRUCE_WOOD_STAIRS:1)
Block(0,18,-5,SPRUCE_WOOD_STAIRS:1)
Block(0,18,-4,SPRUCE_WOOD_STAIRS:1)
Block(0,18,-3,SPRUCE_WOOD_STAIRS:1)
Block(0,18,-2,SPRUCE_WOOD_STAIRS:4)
Block(0,18,-1,SPRUCE_WOOD_STAIRS:4)
Block(0,18,0,SPRUCE_WOOD_STAIRS:4)
Block(0,18,1,SPRUCE_WOOD_STAIRS:4)
Block(0,18,2,SPRUCE_WOOD_STAIRS:4)
Block(0,18,3,SPRUCE_WOOD_STAIRS:4)
Block(0,18,4,SPRUCE_WOOD_STAIRS:1)
Block(0,18,5,SPRUCE_WOOD_STAIRS:1)
Block(0,18,6,SPRUCE_WOOD_STAIRS:1)
Block(0,18,7,SPRUCE_WOOD_STAIRS:1)
Block(0,18,8,SPRUCE_WOOD_STAIRS:4)
Block(0,19,-7,SPRUCE_WOOD_STAIRS:1)
Block(0,19,-2,SPRUCE_WOOD_STAIRS:1)
Block(0,19,-1,SPRUCE_WOOD_STAIRS:1)
Block(0,19,0,SPRUCE_WOOD_STAIRS:1)
Block(0,19,1,SPRUCE_WOOD_STAIRS:1)
Block(0,19,2,SPRUCE_WOOD_STAIRS:1)
Block(0,19,3,SPRUCE_WOOD_STAIRS:1)
Block(0,19,8,SPRUCE_WOOD_STAIRS:1)
Block(0,20,-7,SPRUCE_WOOD_STAIRS:0)
Block(0,20,-2,SPRUCE_WOOD_STAIRS:0)
Block(0,20,3,SPRUCE_WOOD_STAIRS:0)
Block(0,20,8,SPRUCE_WOOD_STAIRS:0)
Block(1,0,-7,COBBLESTONE:0)
Block(1,0,-6,COBBLESTONE:0)
Block(1,0,-5,COBBLESTONE:0)
Block(1,0,-4,COBBLESTONE:0)
Block(1,0,-3,COBBLESTONE:0)
Block(1,0,-2,COBBLESTONE:0)
Block(1,0,-1,COBBLESTONE:0)
Block(1,0,0,COBBLESTONE:0)
Block(1,0,1,COBBLESTONE:0)
Block(1,0,2,COBBLESTONE:0)
Block(1,0,3,COBBLESTONE:0)
Block(1,0,4,COBBLESTONE:0)
Block(1,0,5,COBBLESTONE:0)
Block(1,0,6,COBBLESTONE:0)
Block(1,0,7,COBBLESTONE:0)
Block(1,0,8,STONE:6)
Block(1,1,-7,COBBLESTONE:0)
Block(1,1,-6,COBBLESTONE:0)
Block(1,1,-5,COBBLESTONE:0)
Block(1,1,-4,COBBLESTONE:0)
Block(1,1,-3,COBBLESTONE:0)
Block(1,1,-2,COBBLESTONE:0)
Block(1,1,-1,COBBLESTONE:0)
Block(1,1,0,COBBLESTONE:0)
Block(1,1,1,COBBLESTONE:0)
Block(1,1,2,COBBLESTONE:0)
Block(1,1,3,COBBLESTONE:0)
Block(1,1,4,COBBLESTONE:0)
Block(1,1,5,COBBLESTONE:0)
Block(1,1,6,COBBLESTONE:0)
Block(1,1,7,COBBLESTONE:0)
Block(1,1,8,STONE:6)
Block(1,2,-7,COBBLESTONE:0)
Block(1,2,-6,COBBLESTONE:0)
Block(1,2,-5,COBBLESTONE:0)
Block(1,2,-4,COBBLESTONE:0)
Block(1,2,-3,COBBLESTONE:0)
Block(1,2,-2,COBBLESTONE:0)
Block(1,2,-1,COBBLESTONE:0)
Block(1,2,0,COBBLESTONE:0)
Block(1,2,1,COBBLESTONE:0)
Block(1,2,2,COBBLESTONE:0)
Block(1,2,3,COBBLESTONE:0)
Block(1,2,4,COBBLESTONE:0)
Block(1,2,5,COBBLESTONE:0)
Block(1,2,6,COBBLESTONE:0)
Block(1,2,7,COBBLESTONE:0)
Block(1,2,8,STONE:6)
Block(1,3,-7,COBBLESTONE:0)
Block(1,3,-6,COBBLESTONE:0)
Block(1,3,-5,COBBLESTONE:0)
Block(1,3,-4,COBBLESTONE:0)
Block(1,3,-3,COBBLESTONE:0)
Block(1,3,-2,COBBLESTONE:0)
Block(1,3,-1,COBBLESTONE:0)
Block(1,3,0,COBBLESTONE:0)
Block(1,3,1,COBBLESTONE:0)
Block(1,3,2,COBBLESTONE:0)
Block(1,3,3,COBBLESTONE:0)
Block(1,3,4,COBBLESTONE:0)
Block(1,3,5,COBBLESTONE:0)
Block(1,3,6,COBBLESTONE:0)
Block(1,3,7,COBBLESTONE:0)
Block(1,3,8,STONE:6)
Block(1,4,-7,COBBLESTONE:0)
Block(1,4,-6,COBBLESTONE:0)
Block(1,4,-5,COBBLESTONE:0)
Block(1,4,-4,COBBLESTONE:0)
Block(1,4,-3,COBBLESTONE:0)
Block(1,4,-2,COBBLESTONE:0)
Block(1,4,-1,COBBLESTONE:0)
Block(1,4,0,COBBLESTONE:0)
Block(1,4,1,COBBLESTONE:0)
Block(1,4,2,COBBLESTONE:0)
Block(1,4,3,COBBLESTONE:0)
Block(1,4,4,COBBLESTONE:0)
Block(1,4,5,COBBLESTONE:0)
Block(1,4,6,COBBLESTONE:0)
Block(1,4,7,COBBLESTONE:0)
Block(1,4,8,STONE:6)
Block(1,5,-7,COBBLESTONE:0)
Block(1,5,-6,COBBLESTONE:0)
Block(1,5,-5,COBBLESTONE:0)
Block(1,5,-4,COBBLESTONE:0)
Block(1,5,-3,COBBLESTONE:0)
Block(1,5,-2,COBBLESTONE_STAIRS:0)
Block(1,5,-1,STONE:6)
Block(1,5,0,COBBLESTONE_STAIRS:0)
Block(1,5,1,COBBLESTONE_STAIRS:0)
Block(1,5,2,STONE:6)
Block(1,5,3,COBBLESTONE_STAIRS:0)
Block(1,5,4,COBBLESTONE:0)
Block(1,5,5,COBBLESTONE:0)
Block(1,5,6,COBBLESTONE:0)
Block(1,5,7,COBBLESTONE:0)
Block(1,5,8,STONE:6)
Block(1,6,-7,WOOD_STEP:9)
Block(1,6,-6,SPRUCE_WOOD_STAIRS:1)
Block(1,6,-5,SPRUCE_WOOD_STAIRS:3)
Block(1,6,-4,CARPET:12)
Block(1,6,-1,STEP:0)
Block(1,6,2,STEP:0)
Block(1,6,5,CARPET:12)
Block(1,6,7,WOOD:5)
Block(1,7,7,WOOD:5)
Block(1,8,7,WOOD:5)
Block(1,9,3,minecraft:black_glazed_terracotta:0)
Block(1,9,7,STONE:6)
Block(1,10,-7,LOG:5)
Block(1,10,-2,minecraft:red_glazed_terracotta:0)
Block(1,10,3,minecraft:red_glazed_terracotta:1)
Block(1,10,7,LOG:5)
Block(1,11,-7,DARK_OAK_FENCE:0)
Block(1,11,-2,minecraft:red_glazed_terracotta:0)
Block(1,11,3,IRON_FENCE:0)
Block(1,11,7,SPRUCE_WOOD_STAIRS:1)
Block(1,12,-2,IRON_FENCE:0)
Block(1,12,3,IRON_FENCE:0)
Block(1,12,7,SPRUCE_WOOD_STAIRS:1)
Block(1,12,8,SPRUCE_WOOD_STAIRS:4)
Block(1,13,-2,IRON_FENCE:0)
Block(1,13,3,IRON_FENCE:0)
Block(1,13,7,SPRUCE_WOOD_STAIRS:1)
Block(1,13,8,SPRUCE_WOOD_STAIRS:1)
Block(1,14,-7,LOG:5)
Block(1,14,-2,LOG:5)
Block(1,14,3,LOG:5)
Block(1,14,7,SPRUCE_WOOD_STAIRS:1)
Block(1,15,7,SPRUCE_WOOD_STAIRS:1)
Block(1,16,-6,SPRUCE_WOOD_STAIRS:4)
Block(1,16,-5,SPRUCE_WOOD_STAIRS:4)
Block(1,16,-4,SPRUCE_WOOD_STAIRS:4)
Block(1,16,-3,SPRUCE_WOOD_STAIRS:4)
Block(1,16,4,SPRUCE_WOOD_STAIRS:4)
Block(1,16,5,SPRUCE_WOOD_STAIRS:4)
Block(1,16,6,SPRUCE_WOOD_STAIRS:4)
Block(1,16,7,WOOD:1)
Block(1,17,-7,SPRUCE_WOOD_STAIRS:4)
Block(1,17,-6,SPRUCE_WOOD_STAIRS:1)
Block(1,17,-5,SPRUCE_WOOD_STAIRS:1)
Block(1,17,-4,SPRUCE_WOOD_STAIRS:1)
Block(1,17,-3,SPRUCE_WOOD_STAIRS:1)
Block(1,17,-2,SPRUCE_WOOD_STAIRS:4)
Block(1,17,-1,TRAP_DOOR:3)
Block(1,17,0,TRAP_DOOR:3)
Block(1,17,1,TRAP_DOOR:3)
Block(1,17,2,TRAP_DOOR:3)
Block(1,17,3,SPRUCE_WOOD_STAIRS:4)
Block(1,17,4,SPRUCE_WOOD_STAIRS:1)
Block(1,17,5,SPRUCE_WOOD_STAIRS:1)
Block(1,17,6,SPRUCE_WOOD_STAIRS:1)
Block(1,17,7,SPRUCE_WOOD_STAIRS:1)
Block(1,17,8,SPRUCE_WOOD_STAIRS:4)
Block(1,18,-7,SPRUCE_WOOD_STAIRS:1)
Block(1,18,-2,SPRUCE_WOOD_STAIRS:1)
Block(1,18,3,SPRUCE_WOOD_STAIRS:1)
Block(1,18,8,SPRUCE_WOOD_STAIRS:1)
Block(2,0,-7,COBBLESTONE:0)
Block(2,0,-6,COBBLESTONE:0)
Block(2,0,-5,STONE:6)
Block(2,0,-4,STONE:6)
Block(2,0,-3,COBBLESTONE:0)
Block(2,0,-2,COBBLESTONE:0)
Block(2,0,-1,COBBLESTONE:0)
Block(2,0,0,STONE:6)
Block(2,0,1,STONE:6)
Block(2,0,2,COBBLESTONE:0)
Block(2,0,3,COBBLESTONE:0)
Block(2,0,4,COBBLESTONE:0)
Block(2,0,5,STONE:6)
Block(2,0,6,STONE:6)
Block(2,0,7,COBBLESTONE:0)
Block(2,0,8,STONE:6)
Block(2,1,-7,COBBLESTONE:0)
Block(2,1,-6,COBBLESTONE:0)
Block(2,1,-5,STONE:6)
Block(2,1,-4,STONE:6)
Block(2,1,-3,COBBLESTONE:0)
Block(2,1,-2,COBBLESTONE:0)
Block(2,1,-1,COBBLESTONE:0)
Block(2,1,0,STONE:6)
Block(2,1,1,STONE:6)
Block(2,1,2,COBBLESTONE:0)
Block(2,1,3,COBBLESTONE:0)
Block(2,1,4,COBBLESTONE:0)
Block(2,1,5,STONE:6)
Block(2,1,6,STONE:6)
Block(2,1,7,COBBLESTONE:0)
Block(2,1,8,STONE:6)
Block(2,2,-7,COBBLESTONE:0)
Block(2,2,-6,COBBLESTONE:0)
Block(2,2,-5,STONE:6)
Block(2,2,-4,STONE:6)
Block(2,2,-3,COBBLESTONE:0)
Block(2,2,-2,COBBLESTONE:0)
Block(2,2,-1,COBBLESTONE:0)
Block(2,2,0,STONE:6)
Block(2,2,1,STONE:6)
Block(2,2,2,COBBLESTONE:0)
Block(2,2,3,COBBLESTONE:0)
Block(2,2,4,COBBLESTONE:0)
Block(2,2,5,STONE:6)
Block(2,2,6,STONE:6)
Block(2,2,7,COBBLESTONE:0)
Block(2,2,8,STONE:6)
Block(2,3,-7,COBBLESTONE:0)
Block(2,3,-6,COBBLESTONE:0)
Block(2,3,-5,STONE:6)
Block(2,3,-4,STONE:6)
Block(2,3,-3,COBBLESTONE:0)
Block(2,3,-2,COBBLESTONE:0)
Block(2,3,-1,COBBLESTONE:0)
Block(2,3,0,STONE:6)
Block(2,3,1,STONE:6)
Block(2,3,2,COBBLESTONE:0)
Block(2,3,3,COBBLESTONE:0)
Block(2,3,4,COBBLESTONE:0)
Block(2,3,5,STONE:6)
Block(2,3,6,STONE:6)
Block(2,3,7,COBBLESTONE:0)
Block(2,3,8,STONE:6)
Block(2,4,-7,COBBLESTONE:0)
Block(2,4,-6,COBBLESTONE:0)
Block(2,4,-5,STONE:6)
Block(2,4,-4,STONE:6)
Block(2,4,-3,COBBLESTONE:0)
Block(2,4,-2,COBBLESTONE:0)
Block(2,4,-1,COBBLESTONE:0)
Block(2,4,0,STONE:6)
Block(2,4,1,STONE:6)
Block(2,4,2,COBBLESTONE:0)
Block(2,4,3,COBBLESTONE:0)
Block(2,4,4,COBBLESTONE:0)
Block(2,4,5,STONE:6)
Block(2,4,6,STONE:6)
Block(2,4,7,COBBLESTONE:0)
Block(2,4,8,STONE:6)
Block(2,5,-7,COBBLESTONE:0)
Block(2,5,-6,COBBLESTONE:0)
Block(2,5,-5,STONE:6)
Block(2,5,-4,STONE:6)
Block(2,5,-3,COBBLESTONE:0)
Block(2,5,-2,COBBLESTONE:0)
Block(2,5,-1,COBBLESTONE:0)
Block(2,5,0,STONE:6)
Block(2,5,1,STONE:6)
Block(2,5,2,COBBLESTONE:0)
Block(2,5,3,COBBLESTONE:0)
Block(2,5,4,COBBLESTONE:0)
Block(2,5,5,STONE:6)
Block(2,5,6,STONE:6)
Block(2,5,7,COBBLESTONE:0)
Block(2,5,8,STONE:6)
Block(2,6,-7,WOOD_STEP:9)
Block(2,6,-6,SPRUCE_WOOD_STAIRS:3)
Block(2,6,5,CARPET:12)
Block(2,6,6,CARPET:12)
Block(2,6,7,STONE:6)
Block(2,6,8,DARK_OAK_FENCE:0)
Block(2,7,7,STONE:6)
Block(2,7,8,TORCH:5)
RandomBlock(2,8,-2,WALL_BANNER:4,../../NBT/Banners/viking_wealthy_1.nbt,20,WALL_BANNER:4,../../NBT/Banners/viking_wealthy_2.nbt,20,WALL_BANNER:4,../../NBT/Banners/viking_wealthy_3.nbt,20,WALL_BANNER:4,../../NBT/Banners/viking_wealthy_4.nbt,20,WALL_BANNER:4,../../NBT/Banners/viking_wealthy_5.nbt,20,WALL_BANNER:4,../../NBT/Banners/viking_wealthy_6.nbt,20,WALL_BANNER:4,../../NBT/Banners/viking_wealthy_7.nbt,20,WALL_BANNER:4,../../NBT/Banners/viking_wealthy_8.nbt,20,WALL_BANNER:4,../../NBT/Banners/viking_wealthy_9.nbt,100)
Block(2,8,3,DARK_OAK_FENCE:0)
Block(2,8,7,STONE:6)
RandomBlock(2,9,-5,WALL_BANNER:4,../../NBT/Banners/viking_wealthy_1.nbt,20,WALL_BANNER:4,../../NBT/Banners/viking_wealthy_2.nbt,20,WALL_BANNER:4,../../NBT/Banners/viking_wealthy_3.nbt,20,WALL_BANNER:4,../../NBT/Banners/viking_wealthy_4.nbt,20,WALL_BANNER:4,../../NBT/Banners/viking_wealthy_5.nbt,20,WALL_BANNER:4,../../NBT/Banners/viking_wealthy_6.nbt,20,WALL_BANNER:4,../../NBT/Banners/viking_wealthy_7.nbt,20,WALL_BANNER:4,../../NBT/Banners/viking_wealthy_8.nbt,20,WALL_BANNER:4,../../NBT/Banners/viking_wealthy_9.nbt,100)
RandomBlock(2,9,-2,WALL_BANNER:4,../../NBT/Banners/viking_honor_1.nbt,20,WALL_BANNER:4,../../NBT/Banners/viking_honor_2.nbt,20,WALL_BANNER:4,../../NBT/Banners/viking_honor_3.nbt,20,WALL_BANNER:4,../../NBT/Banners/viking_honor_4.nbt,20,WALL_BANNER:4,../../NBT/Banners/viking_honor_5.nbt,20,WALL_BANNER:4,../../NBT/Banners/viking_honor_6.nbt,100)
RandomBlock(2,9,-1,WALL_BANNER:4,../../NBT/Banners/viking_wealthy_1.nbt,20,WALL_BANNER:4,../../NBT/Banners/viking_wealthy_2.nbt,20,WALL_BANNER:4,../../NBT/Banners/viking_wealthy_3.nbt,20,WALL_BANNER:4,../../NBT/Banners/viking_wealthy_4.nbt,20,WALL_BANNER:4,../../NBT/Banners/viking_wealthy_5.nbt,20,WALL_BANNER:4,../../NBT/Banners/viking_wealthy_6.nbt,20,WALL_BANNER:4,../../NBT/Banners/viking_wealthy_7.nbt,20,WALL_BANNER:4,../../NBT/Banners/viking_wealthy_8.nbt,20,WALL_BANNER:4,../../NBT/Banners/viking_wealthy_9.nbt,100)
Block(2,9,3,TORCH:5)
RandomBlock(2,9,4,WALL_BANNER:4,../../NBT/Banners/viking_honor_1.nbt,20,WALL_BANNER:4,../../NBT/Banners/viking_honor_2.nbt,20,WALL_BANNER:4,../../NBT/Banners/viking_honor_3.nbt,20,WALL_BANNER:4,../../NBT/Banners/viking_honor_4.nbt,20,WALL_BANNER:4,../../NBT/Banners/viking_honor_5.nbt,20,WALL_BANNER:4,../../NBT/Banners/viking_honor_6.nbt,100)
Block(2,9,7,STONE:6)
Block(2,10,-7,LOG:5)
RandomBlock(2,10,-6,WALL_BANNER:4,../../NBT/Banners/viking_honor_1.nbt,20,WALL_BANNER:4,../../NBT/Banners/viking_honor_2.nbt,20,WALL_BANNER:4,../../NBT/Banners/viking_honor_3.nbt,20,WALL_BANNER:4,../../NBT/Banners/viking_honor_4.nbt,20,WALL_BANNER:4,../../NBT/Banners/viking_honor_5.nbt,20,WALL_BANNER:4,../../NBT/Banners/viking_honor_6.nbt,100)
Block(2,10,-4,WALL_BANNER:4)
RandomBlock(2,10,-2,WALL_BANNER:4,../../NBT/Banners/viking_wealthy_1.nbt,20,WALL_BANNER:4,../../NBT/Banners/viking_wealthy_2.nbt,20,WALL_BANNER:4,../../NBT/Banners/viking_wealthy_3.nbt,20,WALL_BANNER:4,../../NBT/Banners/viking_wealthy_4.nbt,20,WALL_BANNER:4,../../NBT/Banners/viking_wealthy_5.nbt,20,WALL_BANNER:4,../../NBT/Banners/viking_wealthy_6.nbt,20,WALL_BANNER:4,../../NBT/Banners/viking_wealthy_7.nbt,20,WALL_BANNER:4,../../NBT/Banners/viking_wealthy_8.nbt,20,WALL_BANNER:4,../../NBT/Banners/viking_wealthy_9.nbt,100)
Block(2,10,7,LOG:5)
Block(2,11,-7,DARK_OAK_FENCE:0)
Block(2,11,7,WOOD:1)
Block(2,11,8,SPRUCE_WOOD_STAIRS:4)
Block(2,12,7,WOOD:1)
Block(2,12,8,SPRUCE_WOOD_STAIRS:1)
RandomBlock(2,13,-7,WALL_BANNER:4,../../NBT/Banners/viking_wealthy_1.nbt,20,WALL_BANNER:4,../../NBT/Banners/viking_wealthy_2.nbt,20,WALL_BANNER:4,../../NBT/Banners/viking_wealthy_3.nbt,20,WALL_BANNER:4,../../NBT/Banners/viking_wealthy_4.nbt,20,WALL_BANNER:4,../../NBT/Banners/viking_wealthy_5.nbt,20,WALL_BANNER:4,../../NBT/Banners/viking_wealthy_6.nbt,20,WALL_BANNER:4,../../NBT/Banners/viking_wealthy_7.nbt,20,WALL_BANNER:4,../../NBT/Banners/viking_wealthy_8.nbt,20,WALL_BANNER:4,../../NBT/Banners/viking_wealthy_9.nbt,100)
RandomBlock(2,13,3,WALL_BANNER:4,../../NBT/Banners/viking_honor_1.nbt,20,WALL_BANNER:4,../../NBT/Banners/viking_honor_2.nbt,20,WALL_BANNER:4,../../NBT/Banners/viking_honor_3.nbt,20,WALL_BANNER:4,../../NBT/Banners/viking_honor_4.nbt,20,WALL_BANNER:4,../../NBT/Banners/viking_honor_5.nbt,20,WALL_BANNER:4,../../NBT/Banners/viking_honor_6.nbt,100)
Block(2,13,7,WOOD:1)
Block(2,14,-7,LOG:5)
Block(2,14,-2,LOG:5)
Block(2,14,3,LOG:5)
Block(2,14,7,WOOD:1)
Block(2,15,-6,SPRUCE_WOOD_STAIRS:4)
Block(2,15,-5,SPRUCE_WOOD_STAIRS:4)
Block(2,15,-4,SPRUCE_WOOD_STAIRS:4)
Block(2,15,-3,SPRUCE_WOOD_STAIRS:4)
Block(2,15,-1,SPRUCE_WOOD_STAIRS:4)
Block(2,15,0,SPRUCE_WOOD_STAIRS:4)
Block(2,15,1,SPRUCE_WOOD_STAIRS:4)
Block(2,15,2,SPRUCE_WOOD_STAIRS:4)
Block(2,15,4,SPRUCE_WOOD_STAIRS:4)
Block(2,15,5,SPRUCE_WOOD_STAIRS:4)
Block(2,15,6,SPRUCE_WOOD_STAIRS:4)
Block(2,15,7,WOOD:1)
Block(2,16,-7,SPRUCE_WOOD_STAIRS:4)
Block(2,16,-6,SPRUCE_WOOD_STAIRS:1)
Block(2,16,-5,SPRUCE_WOOD_STAIRS:1)
Block(2,16,-4,SPRUCE_WOOD_STAIRS:1)
Block(2,16,-3,SPRUCE_WOOD_STAIRS:1)
Block(2,16,-2,SPRUCE_WOOD_STAIRS:4)
Block(2,16,-1,SPRUCE_WOOD_STAIRS:1)
Block(2,16,0,SPRUCE_WOOD_STAIRS:1)
Block(2,16,1,SPRUCE_WOOD_STAIRS:1)
Block(2,16,2,SPRUCE_WOOD_STAIRS:1)
Block(2,16,3,SPRUCE_WOOD_STAIRS:4)
Block(2,16,4,SPRUCE_WOOD_STAIRS:1)
Block(2,16,5,SPRUCE_WOOD_STAIRS:1)
Block(2,16,6,SPRUCE_WOOD_STAIRS:1)
Block(2,16,7,SPRUCE_WOOD_STAIRS:1)
Block(2,16,8,SPRUCE_WOOD_STAIRS:4)
Block(2,17,-7,SPRUCE_WOOD_STAIRS:1)
Block(2,17,-2,SPRUCE_WOOD_STAIRS:1)
Block(2,17,3,SPRUCE_WOOD_STAIRS:1)
Block(2,17,8,SPRUCE_WOOD_STAIRS:1)
Block(3,0,-7,LOG:1)
Block(3,0,-6,COBBLESTONE:0)
Block(3,0,-5,STONE:6)
Block(3,0,-4,STONE:6)
Block(3,0,-3,COBBLESTONE:0)
Block(3,0,-2,LOG:1)
Block(3,0,-1,COBBLESTONE:0)
Block(3,0,0,STONE:6)
Block(3,0,1,STONE:6)
Block(3,0,2,COBBLESTONE:0)
Block(3,0,3,LOG:1)
Block(3,0,4,COBBLESTONE:0)
Block(3,0,5,STONE:6)
Block(3,0,6,STONE:6)
Block(3,0,7,LOG:1)
Block(3,0,8,LOG:1)
Block(3,1,-7,LOG:1)
Block(3,1,-6,COBBLESTONE:0)
Block(3,1,-5,STONE:6)
Block(3,1,-4,STONE:6)
Block(3,1,-3,COBBLESTONE:0)
Block(3,1,-2,LOG:1)
Block(3,1,-1,COBBLESTONE:0)
Block(3,1,0,STONE:6)
Block(3,1,1,STONE:6)
Block(3,1,2,COBBLESTONE:0)
Block(3,1,3,LOG:1)
Block(3,1,4,COBBLESTONE:0)
Block(3,1,5,STONE:6)
Block(3,1,6,STONE:6)
Block(3,1,7,LOG:1)
Block(3,1,8,LOG:1)
Block(3,2,-7,LOG:1)
Block(3,2,-6,COBBLESTONE:0)
Block(3,2,-5,STONE:6)
Block(3,2,-4,STONE:6)
Block(3,2,-3,COBBLESTONE:0)
Block(3,2,-2,LOG:1)
Block(3,2,-1,COBBLESTONE:0)
Block(3,2,0,STONE:6)
Block(3,2,1,STONE:6)
Block(3,2,2,COBBLESTONE:0)
Block(3,2,3,LOG:1)
Block(3,2,4,COBBLESTONE:0)
Block(3,2,5,STONE:6)
Block(3,2,6,STONE:6)
Block(3,2,7,LOG:1)
Block(3,2,8,LOG:1)
Block(3,3,-7,LOG:1)
Block(3,3,-6,COBBLESTONE:0)
Block(3,3,-5,STONE:6)
Block(3,3,-4,STONE:6)
Block(3,3,-3,COBBLESTONE:0)
Block(3,3,-2,LOG:1)
Block(3,3,-1,COBBLESTONE:0)
Block(3,3,0,STONE:6)
Block(3,3,1,STONE:6)
Block(3,3,2,COBBLESTONE:0)
Block(3,3,3,LOG:1)
Block(3,3,4,COBBLESTONE:0)
Block(3,3,5,STONE:6)
Block(3,3,6,STONE:6)
Block(3,3,7,LOG:1)
Block(3,3,8,LOG:1)
Block(3,4,-7,LOG:1)
Block(3,4,-6,COBBLESTONE:0)
Block(3,4,-5,STONE:6)
Block(3,4,-4,STONE:6)
Block(3,4,-3,COBBLESTONE:0)
Block(3,4,-2,LOG:1)
Block(3,4,-1,COBBLESTONE:0)
Block(3,4,0,STONE:6)
Block(3,4,1,STONE:6)
Block(3,4,2,COBBLESTONE:0)
Block(3,4,3,LOG:1)
Block(3,4,4,COBBLESTONE:0)
Block(3,4,5,STONE:6)
Block(3,4,6,STONE:6)
Block(3,4,7,LOG:1)
Block(3,4,8,LOG:1)
Block(3,5,-7,LOG:1)
Block(3,5,-6,COBBLESTONE:0)
Block(3,5,-5,STONE:6)
Block(3,5,-4,STONE:6)
Block(3,5,-3,COBBLESTONE:0)
Block(3,5,-2,LOG:1)
Block(3,5,-1,COBBLESTONE:0)
Block(3,5,0,STONE:6)
Block(3,5,1,STONE:6)
Block(3,5,2,COBBLESTONE:0)
Block(3,5,3,LOG:1)
Block(3,5,4,COBBLESTONE:0)
Block(3,5,5,STONE:6)
Block(3,5,6,STONE:6)
Block(3,5,7,LOG:1)
Block(3,5,8,LOG:1)
Block(3,6,-7,LOG:1)
Block(3,6,-6,SPRUCE_WOOD_STAIRS:1)
Block(3,6,-5,CARPET:12)
Block(3,6,-4,CARPET:12)
Block(3,6,-2,LOG:1)
Block(3,6,-1,WORKBENCH:0)
Block(3,6,0,CARPET:12)
Block(3,6,1,CARPET:12)
Block(3,6,2,AIR:0)
Block(3,6,3,LOG:1)
Block(3,6,7,LOG:1)
Block(3,6,8,LOG:1)
Block(3,7,-7,LOG:1)
Block(3,7,-2,LOG:1)
Block(3,7,3,LOG:1)
Block(3,7,7,LOG:1)
Block(3,7,8,LOG:1)
Block(3,8,-7,LOG:1)
Block(3,8,-2,LOG:1)
Block(3,8,3,LOG:1)
Block(3,8,7,LOG:1)
Block(3,8,8,LOG:9)
Block(3,9,-7,LOG:1)
Block(3,9,-6,DARK_OAK_FENCE:0)
Block(3,9,-5,DARK_OAK_FENCE:0)
Block(3,9,-4,DARK_OAK_FENCE:0)
Block(3,9,-3,DARK_OAK_FENCE:0)
Block(3,9,-2,LOG:1)
Block(3,9,-1,DARK_OAK_FENCE:0)
Block(3,9,0,DARK_OAK_FENCE:0)
Block(3,9,1,DARK_OAK_FENCE:0)
Block(3,9,2,DARK_OAK_FENCE:0)
Block(3,9,3,LOG:1)
Block(3,9,4,DARK_OAK_FENCE:0)
Block(3,9,5,DARK_OAK_FENCE:0)
Block(3,9,6,DARK_OAK_FENCE:0)
Block(3,9,7,LOG:1)
Block(3,9,8,LOG:1)
Block(3,10,-7,LOG:1)
Block(3,10,-6,LOG:9)
Block(3,10,-5,LOG:9)
Block(3,10,-4,LOG:9)
Block(3,10,-3,LOG:9)
Block(3,10,-2,LOG:1)
Block(3,10,-1,LOG:9)
Block(3,10,0,LOG:9)
Block(3,10,1,LOG:9)
Block(3,10,2,LOG:9)
Block(3,10,3,LOG:1)
Block(3,10,4,LOG:9)
Block(3,10,5,LOG:9)
Block(3,10,6,LOG:9)
Block(3,10,7,LOG:1)
Block(3,10,8,LOG:1)
Block(3,11,-7,LOG:1)
Block(3,11,-6,DARK_OAK_FENCE:0)
Block(3,11,-5,DARK_OAK_FENCE:0)
Block(3,11,-4,DARK_OAK_FENCE:0)
Block(3,11,-3,DARK_OAK_FENCE:0)
Block(3,11,-2,LOG:1)
Block(3,11,-1,DARK_OAK_FENCE:0)
Block(3,11,0,DARK_OAK_FENCE:0)
Block(3,11,1,DARK_OAK_FENCE:0)
Block(3,11,2,DARK_OAK_FENCE:0)
Block(3,11,3,LOG:1)
Block(3,11,4,DARK_OAK_FENCE:0)
Block(3,11,5,DARK_OAK_FENCE:0)
Block(3,11,6,DARK_OAK_FENCE:0)
Block(3,11,7,LOG:1)
Block(3,11,8,LOG:1)
Block(3,12,-7,LOG:1)
Block(3,12,-4,TORCH:5)
Block(3,12,-2,LOG:1)
Block(3,12,1,TORCH:5)
Block(3,12,3,LOG:1)
Block(3,12,5,TORCH:5)
Block(3,12,7,LOG:1)
Block(3,12,8,TRAP_DOOR:1)
Block(3,13,-7,LOG:1)
RandomBlock(3,13,-6,WALL_BANNER:3,../../NBT/Banners/viking_wealthy_1.nbt,20,WALL_BANNER:3,../../NBT/Banners/viking_wealthy_2.nbt,20,WALL_BANNER:3,../../NBT/Banners/viking_wealthy_3.nbt,20,WALL_BANNER:3,../../NBT/Banners/viking_wealthy_4.nbt,20,WALL_BANNER:3,../../NBT/Banners/viking_wealthy_5.nbt,20,WALL_BANNER:3,../../NBT/Banners/viking_wealthy_6.nbt,20,WALL_BANNER:3,../../NBT/Banners/viking_wealthy_7.nbt,20,WALL_BANNER:3,../../NBT/Banners/viking_wealthy_8.nbt,20,WALL_BANNER:3,../../NBT/Banners/viking_wealthy_9.nbt,100)
RandomBlock(3,13,-3,WALL_BANNER:2,../../NBT/Banners/viking_wealthy_1.nbt,20,WALL_BANNER:2,../../NBT/Banners/viking_wealthy_2.nbt,20,WALL_BANNER:2,../../NBT/Banners/viking_wealthy_3.nbt,20,WALL_BANNER:2,../../NBT/Banners/viking_wealthy_4.nbt,20,WALL_BANNER:2,../../NBT/Banners/viking_wealthy_5.nbt,20,WALL_BANNER:2,../../NBT/Banners/viking_wealthy_6.nbt,20,WALL_BANNER:2,../../NBT/Banners/viking_wealthy_7.nbt,20,WALL_BANNER:2,../../NBT/Banners/viking_wealthy_8.nbt,20,WALL_BANNER:2,../../NBT/Banners/viking_wealthy_9.nbt,100)
Block(3,13,-2,LOG:1)
RandomBlock(3,13,2,WALL_BANNER:2,../../NBT/Banners/viking_honor_1.nbt,20,WALL_BANNER:2,../../NBT/Banners/viking_honor_2.nbt,20,WALL_BANNER:2,../../NBT/Banners/viking_honor_3.nbt,20,WALL_BANNER:2,../../NBT/Banners/viking_honor_4.nbt,20,WALL_BANNER:2,../../NBT/Banners/viking_honor_5.nbt,20,WALL_BANNER:2,../../NBT/Banners/viking_honor_6.nbt,100)
Block(3,13,3,LOG:1)
Block(3,13,7,LOG:1)
Block(3,14,-7,LOG:1)
Block(3,14,-6,LOG:9)
Block(3,14,-5,LOG:9)
Block(3,14,-4,LOG:9)
Block(3,14,-3,LOG:9)
Block(3,14,-2,LOG:1)
Block(3,14,-1,LOG:9)
Block(3,14,0,LOG:9)
Block(3,14,1,LOG:9)
Block(3,14,2,LOG:9)
Block(3,14,3,LOG:1)
Block(3,14,4,LOG:9)
Block(3,14,5,LOG:9)
Block(3,14,6,LOG:9)
Block(3,14,7,LOG:9)
Block(3,14,8,LOG:9)
Block(3,15,-7,LOG:1)
Block(3,15,-6,SPRUCE_WOOD_STAIRS:1)
Block(3,15,-5,SPRUCE_WOOD_STAIRS:1)
Block(3,15,-4,SPRUCE_WOOD_STAIRS:1)
Block(3,15,-3,SPRUCE_WOOD_STAIRS:1)
Block(3,15,-2,LOG:1)
Block(3,15,-1,SPRUCE_WOOD_STAIRS:1)
Block(3,15,0,SPRUCE_WOOD_STAIRS:1)
Block(3,15,1,SPRUCE_WOOD_STAIRS:1)
Block(3,15,2,SPRUCE_WOOD_STAIRS:1)
Block(3,15,3,LOG:1)
Block(3,15,4,SPRUCE_WOOD_STAIRS:1)
Block(3,15,5,SPRUCE_WOOD_STAIRS:1)
Block(3,15,6,SPRUCE_WOOD_STAIRS:1)
Block(3,15,7,SPRUCE_WOOD_STAIRS:1)
Block(3,15,8,SPRUCE_WOOD_STAIRS:4)
Block(3,16,-7,SPRUCE_WOOD_STAIRS:1)
Block(3,16,-2,SPRUCE_WOOD_STAIRS:1)
Block(3,16,3,SPRUCE_WOOD_STAIRS:1)
Block(3,16,8,SPRUCE_WOOD_STAIRS:1)
Block(4,0,-7,COBBLESTONE:0)
Block(4,0,-6,COBBLESTONE:0)
Block(4,0,-5,COBBLESTONE:0)
Block(4,0,-4,COBBLESTONE:0)
Block(4,0,-3,COBBLESTONE:0)
Block(4,0,-2,COBBLESTONE:0)
Block(4,0,-1,COBBLESTONE:0)
Block(4,0,0,COBBLESTONE:0)
Block(4,0,1,COBBLESTONE:0)
Block(4,0,2,COBBLESTONE:0)
Block(4,0,3,COBBLESTONE:0)
Block(4,0,4,COBBLESTONE:0)
Block(4,0,5,COBBLESTONE:0)
Block(4,0,6,COBBLESTONE:0)
Block(4,0,7,COBBLESTONE:0)
Block(4,0,8,STONE:6)
Block(4,1,-7,COBBLESTONE:0)
Block(4,1,-6,COBBLESTONE:0)
Block(4,1,-5,COBBLESTONE:0)
Block(4,1,-4,COBBLESTONE:0)
Block(4,1,-3,COBBLESTONE:0)
Block(4,1,-2,COBBLESTONE:0)
Block(4,1,-1,COBBLESTONE:0)
Block(4,1,0,COBBLESTONE:0)
Block(4,1,1,COBBLESTONE:0)
Block(4,1,2,COBBLESTONE:0)
Block(4,1,3,COBBLESTONE:0)
Block(4,1,4,COBBLESTONE:0)
Block(4,1,5,COBBLESTONE:0)
Block(4,1,6,COBBLESTONE:0)
Block(4,1,7,COBBLESTONE:0)
Block(4,1,8,STONE:6)
Block(4,2,-7,COBBLESTONE:0)
Block(4,2,-6,COBBLESTONE:0)
Block(4,2,-5,COBBLESTONE:0)
Block(4,2,-4,COBBLESTONE:0)
Block(4,2,-3,COBBLESTONE:0)
Block(4,2,-2,COBBLESTONE:0)
Block(4,2,-1,COBBLESTONE:0)
Block(4,2,0,COBBLESTONE:0)
Block(4,2,1,COBBLESTONE:0)
Block(4,2,2,COBBLESTONE:0)
Block(4,2,3,COBBLESTONE:0)
Block(4,2,4,COBBLESTONE:0)
Block(4,2,5,COBBLESTONE:0)
Block(4,2,6,COBBLESTONE:0)
Block(4,2,7,COBBLESTONE:0)
Block(4,2,8,STONE:6)
Block(4,3,-7,COBBLESTONE:0)
Block(4,3,-6,COBBLESTONE:0)
Block(4,3,-5,COBBLESTONE:0)
Block(4,3,-4,COBBLESTONE:0)
Block(4,3,-3,COBBLESTONE:0)
Block(4,3,-2,COBBLESTONE:0)
Block(4,3,-1,COBBLESTONE:0)
Block(4,3,0,COBBLESTONE:0)
Block(4,3,1,COBBLESTONE:0)
Block(4,3,2,COBBLESTONE:0)
Block(4,3,3,COBBLESTONE:0)
Block(4,3,4,COBBLESTONE:0)
Block(4,3,5,COBBLESTONE:0)
Block(4,3,6,COBBLESTONE:0)
Block(4,3,7,COBBLESTONE:0)
Block(4,3,8,STONE:6)
Block(4,4,-7,COBBLESTONE:0)
Block(4,4,-6,COBBLESTONE:0)
Block(4,4,-5,COBBLESTONE:0)
Block(4,4,-4,COBBLESTONE:0)
Block(4,4,-3,COBBLESTONE:0)
Block(4,4,-2,COBBLESTONE:0)
Block(4,4,-1,COBBLESTONE:0)
Block(4,4,0,COBBLESTONE:0)
Block(4,4,1,COBBLESTONE:0)
Block(4,4,2,COBBLESTONE:0)
Block(4,4,3,COBBLESTONE:0)
Block(4,4,4,COBBLESTONE:0)
Block(4,4,5,COBBLESTONE:0)
Block(4,4,6,COBBLESTONE:0)
Block(4,4,7,COBBLESTONE:0)
Block(4,4,8,STONE:6)
Block(4,5,-7,COBBLESTONE:0)
Block(4,5,-6,COBBLESTONE:0)
Block(4,5,-5,COBBLESTONE:0)
Block(4,5,-4,COBBLESTONE:0)
Block(4,5,-3,COBBLESTONE:0)
Block(4,5,-2,COBBLESTONE:0)
Block(4,5,-1,COBBLESTONE:0)
Block(4,5,0,COBBLESTONE:0)
Block(4,5,1,COBBLESTONE:0)
Block(4,5,2,COBBLESTONE:0)
Block(4,5,3,COBBLESTONE:0)
Block(4,5,4,COBBLESTONE:0)
Block(4,5,5,COBBLESTONE:0)
Block(4,5,6,COBBLESTONE:0)
Block(4,5,7,COBBLESTONE:0)
Block(4,5,8,STONE:6)
Block(4,6,-7,DARK_OAK_FENCE:0)
Block(4,6,-2,SPRUCE_WOOD_STAIRS:1)
Block(4,6,-1,SPRUCE_WOOD_STAIRS:1)
Block(4,6,0,CARPET:12)
Block(4,6,1,CARPET:12)
Block(4,6,2,SPRUCE_WOOD_STAIRS:1)
Block(4,6,4,CARPET:12)
Block(4,6,5,SPRUCE_WOOD_STAIRS:1)
Block(4,6,6,CARPET:12)
Block(4,6,7,STONE:6)
Block(4,7,-7,DARK_OAK_FENCE:0)
RandomBlock(4,7,-6,WALL_BANNER:3,../../NBT/Banners/viking_wealthy_1.nbt,20,WALL_BANNER:3,../../NBT/Banners/viking_wealthy_2.nbt,20,WALL_BANNER:3,../../NBT/Banners/viking_wealthy_3.nbt,20,WALL_BANNER:3,../../NBT/Banners/viking_wealthy_4.nbt,20,WALL_BANNER:3,../../NBT/Banners/viking_wealthy_5.nbt,20,WALL_BANNER:3,../../NBT/Banners/viking_wealthy_6.nbt,20,WALL_BANNER:3,../../NBT/Banners/viking_wealthy_7.nbt,20,WALL_BANNER:3,../../NBT/Banners/viking_wealthy_8.nbt,20,WALL_BANNER:3,../../NBT/Banners/viking_wealthy_9.nbt,100)
Block(4,7,7,STONE:6)
Block(4,8,-7,DARK_OAK_FENCE:0)
RandomBlock(4,8,-6,WALL_BANNER:3,../../NBT/Banners/viking_honor_1.nbt,20,WALL_BANNER:3,../../NBT/Banners/viking_honor_2.nbt,20,WALL_BANNER:3,../../NBT/Banners/viking_honor_3.nbt,20,WALL_BANNER:3,../../NBT/Banners/viking_honor_4.nbt,20,WALL_BANNER:3,../../NBT/Banners/viking_honor_5.nbt,20,WALL_BANNER:3,../../NBT/Banners/viking_honor_6.nbt,100)
Block(4,8,7,LOG:5)
Block(4,9,-7,DARK_OAK_FENCE:0)
RandomBlock(4,9,-6,WALL_BANNER:3,../../NBT/Banners/viking_wealthy_1.nbt,20,WALL_BANNER:3,../../NBT/Banners/viking_wealthy_2.nbt,20,WALL_BANNER:3,../../NBT/Banners/viking_wealthy_3.nbt,20,WALL_BANNER:3,../../NBT/Banners/viking_wealthy_4.nbt,20,WALL_BANNER:3,../../NBT/Banners/viking_wealthy_5.nbt,20,WALL_BANNER:3,../../NBT/Banners/viking_wealthy_6.nbt,20,WALL_BANNER:3,../../NBT/Banners/viking_wealthy_7.nbt,20,WALL_BANNER:3,../../NBT/Banners/viking_wealthy_8.nbt,20,WALL_BANNER:3,../../NBT/Banners/viking_wealthy_9.nbt,100)
Block(4,9,-2,DARK_OAK_FENCE:0)
Block(4,9,3,DARK_OAK_FENCE:0)
Block(4,9,7,WOOD:1)
Block(4,9,8,SPRUCE_WOOD_STAIRS:4)
Block(4,10,-7,LOG:5)
Block(4,10,-6,WOOD_STEP:9)
Block(4,10,-5,WOOD_STEP:9)
Block(4,10,-4,WOOD_STEP:9)
Block(4,10,-3,WOOD_STEP:9)
Block(4,10,-2,LOG:5)
Block(4,10,-1,WOOD_STEP:9)
Block(4,10,0,WOOD_STEP:9)
Block(4,10,1,WOOD_STEP:9)
Block(4,10,2,WOOD_STEP:9)
Block(4,10,3,LOG:5)
Block(4,10,4,WOOD_STEP:9)
Block(4,10,5,WOOD_STEP:9)
Block(4,10,6,WOOD_STEP:9)
Block(4,10,7,WOOD:1)
Block(4,10,8,SPRUCE_WOOD_STAIRS:1)
Block(4,11,-5,AIR:0)
Block(4,11,-4,HAY_BLOCK:0)
Block(4,11,-3,HAY_BLOCK:0)
Block(4,11,-2,BED_BLOCK:10)
Block(4,11,-1,BED_BLOCK:2)
Block(4,11,5,BED_BLOCK:0)
Block(4,11,6,BED_BLOCK:8)
Block(4,11,7,WOOD:1)
Block(4,11,8,SPRUCE_WOOD_STAIRS:5)
RandomBlock(4,12,6,WALL_BANNER:2,../../NBT/Banners/viking_wealthy_1.nbt,20,WALL_BANNER:2,../../NBT/Banners/viking_wealthy_2.nbt,20,WALL_BANNER:2,../../NBT/Banners/viking_wealthy_3.nbt,20,WALL_BANNER:2,../../NBT/Banners/viking_wealthy_4.nbt,20,WALL_BANNER:2,../../NBT/Banners/viking_wealthy_5.nbt,20,WALL_BANNER:2,../../NBT/Banners/viking_wealthy_6.nbt,20,WALL_BANNER:2,../../NBT/Banners/viking_wealthy_7.nbt,20,WALL_BANNER:2,../../NBT/Banners/viking_wealthy_8.nbt,20,WALL_BANNER:2,../../NBT/Banners/viking_wealthy_9.nbt,100)
Block(4,12,7,WOOD:1)
Block(4,12,8,SPRUCE_WOOD_STAIRS:0)
RandomBlock(4,13,-5,WALL_BANNER:2,../../NBT/Banners/viking_honor_1.nbt,20,WALL_BANNER:2,../../NBT/Banners/viking_honor_2.nbt,20,WALL_BANNER:2,../../NBT/Banners/viking_honor_3.nbt,20,WALL_BANNER:2,../../NBT/Banners/viking_honor_4.nbt,20,WALL_BANNER:2,../../NBT/Banners/viking_honor_5.nbt,20,WALL_BANNER:2,../../NBT/Banners/viking_honor_6.nbt,100)
RandomBlock(4,13,0,WALL_BANNER:4,../../NBT/Banners/viking_wealthy_1.nbt,20,WALL_BANNER:4,../../NBT/Banners/viking_wealthy_2.nbt,20,WALL_BANNER:4,../../NBT/Banners/viking_wealthy_3.nbt,20,WALL_BANNER:4,../../NBT/Banners/viking_wealthy_4.nbt,20,WALL_BANNER:4,../../NBT/Banners/viking_wealthy_5.nbt,20,WALL_BANNER:4,../../NBT/Banners/viking_wealthy_6.nbt,20,WALL_BANNER:4,../../NBT/Banners/viking_wealthy_7.nbt,20,WALL_BANNER:4,../../NBT/Banners/viking_wealthy_8.nbt,20,WALL_BANNER:4,../../NBT/Banners/viking_wealthy_9.nbt,100)
RandomBlock(4,13,1,WALL_BANNER:4,../../NBT/Banners/viking_honor_1.nbt,20,WALL_BANNER:4,../../NBT/Banners/viking_honor_2.nbt,20,WALL_BANNER:4,../../NBT/Banners/viking_honor_3.nbt,20,WALL_BANNER:4,../../NBT/Banners/viking_honor_4.nbt,20,WALL_BANNER:4,../../NBT/Banners/viking_honor_5.nbt,20,WALL_BANNER:4,../../NBT/Banners/viking_honor_6.nbt,100)
RandomBlock(4,13,2,WALL_BANNER:4,../../NBT/Banners/viking_wealthy_1.nbt,20,WALL_BANNER:4,../../NBT/Banners/viking_wealthy_2.nbt,20,WALL_BANNER:4,../../NBT/Banners/viking_wealthy_3.nbt,20,WALL_BANNER:4,../../NBT/Banners/viking_wealthy_4.nbt,20,WALL_BANNER:4,../../NBT/Banners/viking_wealthy_5.nbt,20,WALL_BANNER:4,../../NBT/Banners/viking_wealthy_6.nbt,20,WALL_BANNER:4,../../NBT/Banners/viking_wealthy_7.nbt,20,WALL_BANNER:4,../../NBT/Banners/viking_wealthy_8.nbt,20,WALL_BANNER:4,../../NBT/Banners/viking_wealthy_9.nbt,100)
Block(4,13,7,WOOD:1)
Block(4,14,-7,SPRUCE_WOOD_STAIRS:4)
Block(4,14,-6,SPRUCE_WOOD_STAIRS:1)
Block(4,14,-5,SPRUCE_WOOD_STAIRS:1)
Block(4,14,-4,SPRUCE_WOOD_STAIRS:1)
Block(4,14,-3,SPRUCE_WOOD_STAIRS:1)
Block(4,14,-2,SPRUCE_WOOD_STAIRS:4)
Block(4,14,-1,SPRUCE_WOOD_STAIRS:1)
Block(4,14,0,SPRUCE_WOOD_STAIRS:1)
Block(4,14,1,SPRUCE_WOOD_STAIRS:1)
Block(4,14,2,SPRUCE_WOOD_STAIRS:1)
Block(4,14,3,SPRUCE_WOOD_STAIRS:4)
Block(4,14,4,SPRUCE_WOOD_STAIRS:1)
Block(4,14,5,SPRUCE_WOOD_STAIRS:1)
Block(4,14,6,SPRUCE_WOOD_STAIRS:1)
Block(4,14,7,SPRUCE_WOOD_STAIRS:1)
Block(4,14,8,SPRUCE_WOOD_STAIRS:4)
Block(4,15,-7,SPRUCE_WOOD_STAIRS:1)
Block(4,15,-2,SPRUCE_WOOD_STAIRS:1)
Block(4,15,3,SPRUCE_WOOD_STAIRS:1)
Block(4,15,8,SPRUCE_WOOD_STAIRS:1)
Block(5,0,-7,STONE:6)
Block(5,0,-6,COBBLESTONE:0)
Block(5,0,-5,STONE:6)
Block(5,0,-4,STONE:6)
Block(5,0,-3,COBBLESTONE:0)
Block(5,0,-2,STONE:6)
Block(5,0,-1,COBBLESTONE:0)
Block(5,0,0,STONE:6)
Block(5,0,1,STONE:6)
Block(5,0,2,COBBLESTONE:0)
Block(5,0,3,STONE:6)
Block(5,0,4,COBBLESTONE:0)
Block(5,0,5,STONE:6)
Block(5,0,6,STONE:6)
Block(5,0,7,COBBLESTONE:0)
Block(5,0,8,STONE:6)
Block(5,1,-7,STONE:6)
Block(5,1,-6,COBBLESTONE:0)
Block(5,1,-5,STONE:6)
Block(5,1,-4,STONE:6)
Block(5,1,-3,COBBLESTONE:0)
Block(5,1,-2,STONE:6)
Block(5,1,-1,COBBLESTONE:0)
Block(5,1,0,STONE:6)
Block(5,1,1,STONE:6)
Block(5,1,2,COBBLESTONE:0)
Block(5,1,3,STONE:6)
Block(5,1,4,COBBLESTONE:0)
Block(5,1,5,STONE:6)
Block(5,1,6,STONE:6)
Block(5,1,7,COBBLESTONE:0)
Block(5,1,8,STONE:6)
Block(5,2,-7,STONE:6)
Block(5,2,-6,COBBLESTONE:0)
Block(5,2,-5,STONE:6)
Block(5,2,-4,STONE:6)
Block(5,2,-3,COBBLESTONE:0)
Block(5,2,-2,STONE:6)
Block(5,2,-1,COBBLESTONE:0)
Block(5,2,0,STONE:6)
Block(5,2,1,STONE:6)
Block(5,2,2,COBBLESTONE:0)
Block(5,2,3,STONE:6)
Block(5,2,4,COBBLESTONE:0)
Block(5,2,5,STONE:6)
Block(5,2,6,STONE:6)
Block(5,2,7,COBBLESTONE:0)
Block(5,2,8,STONE:6)
Block(5,3,-7,STONE:6)
Block(5,3,-6,COBBLESTONE:0)
Block(5,3,-5,STONE:6)
Block(5,3,-4,STONE:6)
Block(5,3,-3,COBBLESTONE:0)
Block(5,3,-2,STONE:6)
Block(5,3,-1,COBBLESTONE:0)
Block(5,3,0,STONE:6)
Block(5,3,1,STONE:6)
Block(5,3,2,COBBLESTONE:0)
Block(5,3,3,STONE:6)
Block(5,3,4,COBBLESTONE:0)
Block(5,3,5,STONE:6)
Block(5,3,6,STONE:6)
Block(5,3,7,COBBLESTONE:0)
Block(5,3,8,STONE:6)
Block(5,4,-7,STONE:6)
Block(5,4,-6,COBBLESTONE:0)
Block(5,4,-5,STONE:6)
Block(5,4,-4,STONE:6)
Block(5,4,-3,COBBLESTONE:0)
Block(5,4,-2,STONE:6)
Block(5,4,-1,COBBLESTONE:0)
Block(5,4,0,STONE:6)
Block(5,4,1,STONE:6)
Block(5,4,2,COBBLESTONE:0)
Block(5,4,3,STONE:6)
Block(5,4,4,COBBLESTONE:0)
Block(5,4,5,STONE:6)
Block(5,4,6,STONE:6)
Block(5,4,7,COBBLESTONE:0)
Block(5,4,8,STONE:6)
Block(5,5,-7,STONE:6)
Block(5,5,-6,COBBLESTONE:0)
Block(5,5,-5,STONE:6)
Block(5,5,-4,STONE:6)
Block(5,5,-3,COBBLESTONE:0)
Block(5,5,-2,STONE:6)
Block(5,5,-1,COBBLESTONE:0)
Block(5,5,0,STONE:6)
Block(5,5,1,STONE:6)
Block(5,5,2,COBBLESTONE:0)
Block(5,5,3,STONE:6)
Block(5,5,4,COBBLESTONE:0)
Block(5,5,5,STONE:6)
Block(5,5,6,STONE:6)
Block(5,5,7,COBBLESTONE:0)
Block(5,5,8,STONE:6)
Block(5,6,-7,DARK_OAK_FENCE:0)
Block(5,6,-6,CARPET:12)
Block(5,6,-4,DARK_OAK_STAIRS:7)
Block(5,6,-3,WOOD_STEP:13)
Block(5,6,-2,WOOD_STEP:13)
Block(5,6,-1,WOOD_STEP:13)
Block(5,6,0,WOOD_STEP:13)
Block(5,6,1,WOOD_STEP:13)
Block(5,6,2,WOOD_STEP:13)
Block(5,6,3,WOOD_STEP:13)
Block(5,6,4,WOOD_STEP:13)
Block(5,6,5,DARK_OAK_STAIRS:6)
Block(5,6,6,CARPET:12)
Block(5,6,7,COBBLESTONE:0)
Block(5,7,-7,DARK_OAK_FENCE:0)
RandomBlock(5,7,-6,WALL_BANNER:3,../../NBT/Banners/viking_wealthy_1.nbt,20,WALL_BANNER:3,../../NBT/Banners/viking_wealthy_2.nbt,20,WALL_BANNER:3,../../NBT/Banners/viking_wealthy_3.nbt,20,WALL_BANNER:3,../../NBT/Banners/viking_wealthy_4.nbt,20,WALL_BANNER:3,../../NBT/Banners/viking_wealthy_5.nbt,20,WALL_BANNER:3,../../NBT/Banners/viking_wealthy_6.nbt,20,WALL_BANNER:3,../../NBT/Banners/viking_wealthy_7.nbt,20,WALL_BANNER:3,../../NBT/Banners/viking_wealthy_8.nbt,20,WALL_BANNER:3,../../NBT/Banners/viking_wealthy_9.nbt,100)
Block(5,7,-4,TORCH:5)
Block(5,7,-3,FLOWER_POT:0)
Block(5,7,-2,WOOD_PLATE:0)
Block(5,7,-1,BREWING_STAND:0)
Block(5,7,0,WOOD_PLATE:0)
Block(5,7,3,FLOWER_POT:0)
Block(5,7,4,WOOD_PLATE:0)
Block(5,7,7,COBBLESTONE:0)
Block(5,8,-7,DARK_OAK_FENCE:0)
RandomBlock(5,8,-6,WALL_BANNER:3,../../NBT/Banners/viking_honor_1.nbt,20,WALL_BANNER:3,../../NBT/Banners/viking_honor_2.nbt,20,WALL_BANNER:3,../../NBT/Banners/viking_honor_3.nbt,20,WALL_BANNER:3,../../NBT/Banners/viking_honor_4.nbt,20,WALL_BANNER:3,../../NBT/Banners/viking_honor_5.nbt,20,WALL_BANNER:3,../../NBT/Banners/viking_honor_6.nbt,100)
Block(5,8,7,LOG:5)
Block(5,8,8,SPRUCE_WOOD_STAIRS:4)
Block(5,9,-7,DARK_OAK_FENCE:0)
RandomBlock(5,9,-6,WALL_BANNER:3,../../NBT/Banners/viking_wealthy_1.nbt,20,WALL_BANNER:3,../../NBT/Banners/viking_wealthy_2.nbt,20,WALL_BANNER:3,../../NBT/Banners/viking_wealthy_3.nbt,20,WALL_BANNER:3,../../NBT/Banners/viking_wealthy_4.nbt,20,WALL_BANNER:3,../../NBT/Banners/viking_wealthy_5.nbt,20,WALL_BANNER:3,../../NBT/Banners/viking_wealthy_6.nbt,20,WALL_BANNER:3,../../NBT/Banners/viking_wealthy_7.nbt,20,WALL_BANNER:3,../../NBT/Banners/viking_wealthy_8.nbt,20,WALL_BANNER:3,../../NBT/Banners/viking_wealthy_9.nbt,100)
Block(5,9,-2,DARK_OAK_FENCE:0)
Block(5,9,3,DARK_OAK_FENCE:0)
Block(5,9,7,SPRUCE_WOOD_STAIRS:3)
Block(5,9,8,SPRUCE_WOOD_STAIRS:1)
Block(5,10,-7,LOG:5)
Block(5,10,-6,WOOD_STEP:9)
Block(5,10,-5,WOOD_STEP:9)
Block(5,10,-4,WOOD_STEP:9)
Block(5,10,-3,WOOD_STEP:9)
Block(5,10,-2,LOG:5)
Block(5,10,-1,WOOD_STEP:9)
Block(5,10,0,WOOD_STEP:9)
Block(5,10,1,WOOD_STEP:9)
Block(5,10,2,WOOD_STEP:9)
Block(5,10,3,LOG:5)
Block(5,10,4,WOOD_STEP:9)
Block(5,10,5,WOOD_STEP:9)
Block(5,10,6,WOOD_STEP:9)
Block(5,10,7,SPRUCE_WOOD_STAIRS:3)
Block(5,11,2,BED_BLOCK:0)
Block(5,11,3,BED_BLOCK:8)
Block(5,11,6,HAY_BLOCK:8)
Block(5,11,7,SPRUCE_WOOD_STAIRS:7)
RandomBlock(5,12,-5,WALL_BANNER:4,../../NBT/Banners/viking_honor_1.nbt,20,WALL_BANNER:4,../../NBT/Banners/viking_honor_2.nbt,20,WALL_BANNER:4,../../NBT/Banners/viking_honor_3.nbt,20,WALL_BANNER:4,../../NBT/Banners/viking_honor_4.nbt,20,WALL_BANNER:4,../../NBT/Banners/viking_honor_5.nbt,20,WALL_BANNER:4,../../NBT/Banners/viking_honor_6.nbt,100)
RandomBlock(5,12,-3,WALL_BANNER:4,../../NBT/Banners/viking_wealthy_1.nbt,20,WALL_BANNER:4,../../NBT/Banners/viking_wealthy_2.nbt,20,WALL_BANNER:4,../../NBT/Banners/viking_wealthy_3.nbt,20,WALL_BANNER:4,../../NBT/Banners/viking_wealthy_4.nbt,20,WALL_BANNER:4,../../NBT/Banners/viking_wealthy_5.nbt,20,WALL_BANNER:4,../../NBT/Banners/viking_wealthy_6.nbt,20,WALL_BANNER:4,../../NBT/Banners/viking_wealthy_7.nbt,20,WALL_BANNER:4,../../NBT/Banners/viking_wealthy_8.nbt,20,WALL_BANNER:4,../../NBT/Banners/viking_wealthy_9.nbt,100)
RandomBlock(5,12,0,WALL_BANNER:4,../../NBT/Banners/viking_wealthy_1.nbt,20,WALL_BANNER:4,../../NBT/Banners/viking_wealthy_2.nbt,20,WALL_BANNER:4,../../NBT/Banners/viking_wealthy_3.nbt,20,WALL_BANNER:4,../../NBT/Banners/viking_wealthy_4.nbt,20,WALL_BANNER:4,../../NBT/Banners/viking_wealthy_5.nbt,20,WALL_BANNER:4,../../NBT/Banners/viking_wealthy_6.nbt,20,WALL_BANNER:4,../../NBT/Banners/viking_wealthy_7.nbt,20,WALL_BANNER:4,../../NBT/Banners/viking_wealthy_8.nbt,20,WALL_BANNER:4,../../NBT/Banners/viking_wealthy_9.nbt,100)
RandomBlock(5,12,5,WALL_BANNER:4,../../NBT/Banners/viking_wealthy_1.nbt,20,WALL_BANNER:4,../../NBT/Banners/viking_wealthy_2.nbt,20,WALL_BANNER:4,../../NBT/Banners/viking_wealthy_3.nbt,20,WALL_BANNER:4,../../NBT/Banners/viking_wealthy_4.nbt,20,WALL_BANNER:4,../../NBT/Banners/viking_wealthy_5.nbt,20,WALL_BANNER:4,../../NBT/Banners/viking_wealthy_6.nbt,20,WALL_BANNER:4,../../NBT/Banners/viking_wealthy_7.nbt,20,WALL_BANNER:4,../../NBT/Banners/viking_wealthy_8.nbt,20,WALL_BANNER:4,../../NBT/Banners/viking_wealthy_9.nbt,100)
Block(5,12,7,SPRUCE_WOOD_STAIRS:7)
Block(5,13,-7,SPRUCE_WOOD_STAIRS:4)
Block(5,13,-6,SPRUCE_WOOD_STAIRS:1)
Block(5,13,-5,SPRUCE_WOOD_STAIRS:1)
Block(5,13,-4,SPRUCE_WOOD_STAIRS:1)
Block(5,13,-3,SPRUCE_WOOD_STAIRS:1)
Block(5,13,-2,SPRUCE_WOOD_STAIRS:4)
Block(5,13,-1,SPRUCE_WOOD_STAIRS:1)
Block(5,13,0,SPRUCE_WOOD_STAIRS:1)
Block(5,13,1,SPRUCE_WOOD_STAIRS:1)
Block(5,13,2,SPRUCE_WOOD_STAIRS:1)
Block(5,13,3,SPRUCE_WOOD_STAIRS:4)
Block(5,13,4,SPRUCE_WOOD_STAIRS:1)
Block(5,13,5,SPRUCE_WOOD_STAIRS:1)
Block(5,13,6,SPRUCE_WOOD_STAIRS:1)
Block(5,13,7,SPRUCE_WOOD_STAIRS:1)
Block(5,13,8,SPRUCE_WOOD_STAIRS:4)
Block(5,14,-7,SPRUCE_WOOD_STAIRS:1)
Block(5,14,-2,SPRUCE_WOOD_STAIRS:1)
Block(5,14,3,SPRUCE_WOOD_STAIRS:1)
Block(5,14,8,SPRUCE_WOOD_STAIRS:1)
Block(6,0,-7,STONE:6)
Block(6,0,-6,COBBLESTONE:0)
Block(6,0,-5,STONE:6)
Block(6,0,-4,STONE:6)
Block(6,0,-3,COBBLESTONE:0)
Block(6,0,-2,STONE:6)
Block(6,0,-1,COBBLESTONE:0)
