Author: NLBlackEagle
Description: No description given
SettingsMode: WriteDisable
Frequency: 0
SpawnHeight: highestBlock
UseCenterForHighestBlock: true
MinHeight: 0
MaxHeight: 255
InheritBO3: 
InheritBO3Rotation: NORTH
OverrideChildSettings: true
OverrideParentHeight: false
CanOverride: false
BranchFrequency: 0
BranchFrequencyGroup: 
MustBeBelowOther: false
MustBeInside: 
CannotBeInside: 
ReplacesBO3: 
MustBeInsideWorldBorders: false
CanSpawnOnWater: true
SpawnOnWaterOnly: false
SpawnUnderWater: false
SpawnAtWaterLevel: false
HeightOffset: 0
RemoveAir: false
ReplaceAbove: 
ReplaceBelow: 
ReplaceWithBiomeBlocks: false
ReplaceWithSurfaceBlock: GRASS
ReplaceWithGroundBlock: DIRT
ReplaceWithStoneBlock: STONE
SmoothRadius: 0
SmoothHeightOffset: 0
SmoothStartTop: false
SmoothStartWood: false
SmoothingSurfaceBlock: 
SmoothingGroundBlock: 
BO3Group: 
IsSpawnPoint: false
DoReplaceBlocks: false
Block(-3,28,-7,WOOL:11)
Block(-3,29,-7,WOOL:11)
Block(-3,29,-6,WOOL:15)
Block(-3,31,8,WOOL:11)
Block(-2,17,-3,FENCE:0)
Block(-2,18,-6,WOOL:11)
Block(-2,18,-5,FENCE:0)
Block(-2,18,-4,FENCE:0)
Block(-2,18,-3,FENCE:0)
Block(-2,19,-6,WOOL:11)
Block(-2,19,8,WOOL:15)
Block(-2,29,7,WOOL:15)
Block(-2,30,7,WOOL:11)
Block(-2,31,8,WOOL:11)
Block(-1,16,-1,FENCE:0)
Block(-1,17,-3,FENCE:0)
Block(-1,17,-2,FENCE:0)
Block(-1,17,-1,FENCE:0)
Block(-1,19,-7,WOOL:15)
Block(-1,19,-6,WOOL:11)
Block(-1,19,8,WOOL:11)
Block(-1,20,7,WOOL:11)
Block(-1,21,7,WOOL:15)
Block(-1,27,7,WOOL:15)
Block(-1,28,-7,WOOL:15)
Block(-1,28,-6,WOOL:15)
Block(-1,28,7,WOOL:11)
Block(-1,29,7,WOOL:11)
Block(-1,30,8,WOOL:11)
Block(-1,31,8,WOOL:11)
Block(-1,38,-7,WOOL:15)
Block(-1,38,-6,WOOL:11)
Block(0,9,7,DISPENSER:4)
Block(0,10,7,WOOD_STEP:13)
Block(0,12,7,TRAP_DOOR:6)
Block(0,15,1,FENCE:0)
Block(0,16,-1,FENCE:0)
Block(0,16,0,FENCE:0)
Block(0,16,1,FENCE:0)
Block(0,20,8,WOOL:11)
Block(0,21,7,WOOL:11)
Block(0,22,7,WOOL:11)
Block(0,23,7,WOOL:15)
Block(0,26,7,WOOL:11)
Block(0,27,7,WOOL:11)
Block(0,28,7,WOOL:11)
Block(0,29,8,WOOL:11)
Block(0,30,8,WOOL:11)
Block(0,31,8,WOOL:11)
Block(0,37,8,WOOL:11)
Block(1,9,3,DISPENSER:4)
Block(1,9,7,CONCRETE:15)
Block(1,9,8,WOOD:0)
Block(1,10,3,WOOD_STEP:13)
Block(1,10,6,WOOD:0)
Block(1,10,8,WOOD:0)
Block(1,11,6,WOOD:0)
Block(1,11,7,WOOD:0)
Block(1,11,8,WOOD:0)
Block(1,12,1,DISPENSER:4)
Block(1,12,3,TRAP_DOOR:6)
Block(1,12,5,DISPENSER:4)
Block(1,12,7,WOOD:5)
Block(1,12,8,WOOD:5)
Block(1,13,1,WOOD_STEP:9)
Block(1,13,3,TRAP_DOOR:6)
Block(1,13,5,WOOD_STEP:9)
Block(1,13,7,TRAP_DOOR:6)
Block(1,14,3,TRAP_DOOR:6)
Block(1,14,4,WOOD_BUTTON:2)
Block(1,14,5,WOOD_BUTTON:2)
Block(1,14,6,WOOD_BUTTON:2)
Block(1,14,7,TRAP_DOOR:6)
Block(1,14,8,WOOD_BUTTON:2)
Block(1,15,1,FENCE:0)
Block(1,15,2,FENCE:0)
Block(1,15,3,FENCE:0)
Block(1,20,8,WOOL:11)
Block(1,21,8,WOOL:11)
Block(1,22,7,WOOL:11)
Block(1,23,7,WOOL:11)
Block(1,24,7,WOOL:15)
Block(1,25,7,WOOL:15)
Block(1,26,7,WOOL:11)
Block(1,27,7,WOOL:11)
Block(1,28,7,WOOL:11)
Block(1,29,8,WOOL:11)
Block(1,30,8,WOOL:11)
Block(1,37,8,WOOL:11)
Block(1,38,8,WOOL:11)
Block(1,39,8,WOOL:15)
Block(1,40,8,WOOL:11)
Block(2,6,5,LOG:13)
Block(2,6,6,LOG:13)
Block(2,6,7,LOG:13)
Block(2,6,8,LOG:13)
Block(2,7,3,LOG:13)
Block(2,7,4,LOG:13)
Block(2,7,5,LOG:13)
Block(2,7,6,LOG:13)
Block(2,7,7,LOG:13)
Block(2,7,8,LOG:13)
Block(2,8,0,LADDER:4)
Block(2,8,2,WOOD:5)
Block(2,8,3,WOOD:5)
Block(2,8,4,WOOD:5)
Block(2,8,5,WOOD:5)
Block(2,8,6,WOOD:5)
Block(2,8,7,WOOD:5)
Block(2,8,8,WOOD_DOUBLE_STEP:1)
Block(2,9,0,LADDER:4)
Block(2,9,2,WOOD:0)
Block(2,9,3,CONCRETE:15)
Block(2,9,4,WOOD:0)
Block(2,9,5,WOOD:0)
Block(2,9,6,WOOD:0)
Block(2,9,7,DISPENSER:1)
Block(2,9,8,WOOD_BUTTON:3)
Block(2,10,0,LADDER:4)
Block(2,10,2,WOOD:0)
Block(2,10,4,WOOD:0)
Block(2,10,5,WOOD:0)
Block(2,10,7,LEVER:6)
Block(2,11,0,LADDER:4)
Block(2,11,1,WOOD:0)
Block(2,11,2,WOOD:0)
Block(2,11,3,WOOD:0)
Block(2,11,4,WOOD:0)
Block(2,11,5,WOOD:0)
Block(2,11,6,WOOD_STEP:9)
Block(2,11,7,WOOD_STEP:9)
Block(2,11,8,WOOD_STEP:9)
Block(2,12,0,LADDER:4)
Block(2,12,1,CONCRETE:15)
Block(2,12,2,WOOD:5)
Block(2,12,3,WOOD:5)
Block(2,12,4,WOOD:5)
Block(2,12,5,CONCRETE:15)
Block(2,12,6,WOOD:5)
Block(2,12,8,WOOD_BUTTON:4)
Block(2,13,-2,TRAP_DOOR:6)
Block(2,13,0,LADDER:4)
Block(2,13,1,WOOD_STEP:9)
Block(2,13,2,WOOD:5)
Block(2,13,3,WOOD:5)
Block(2,13,4,WOOD:5)
Block(2,13,5,WOOD_STEP:9)
Block(2,13,6,WOOD:5)
Block(2,13,7,WOOD:5)
Block(2,13,8,WOOD:5)
Block(2,14,-2,WOOD_STEP:13)
Block(2,14,-1,DARK_OAK_STAIRS:4)
Block(2,14,0,LADDER:4)
Block(2,14,2,WOOD:5)
Block(2,14,3,WOOD:5)
Block(2,14,4,WOOD:5)
Block(2,14,5,WOOD:5)
Block(2,14,6,WOOD:5)
Block(2,14,7,WOOD:5)
Block(2,14,8,WOOD:5)
Block(2,15,-2,FENCE:0)
Block(2,15,-1,FENCE:0)
Block(2,15,2,WOOD_STEP:5)
Block(2,15,3,FENCE:0)
Block(2,15,4,FENCE:0)
Block(2,15,5,WOOD_STEP:5)
Block(2,15,6,WOOD_STEP:5)
Block(2,15,7,WOOD_STEP:5)
Block(2,15,8,WOOD_STEP:5)
Block(2,16,-2,FENCE:0)
Block(2,16,-1,FENCE:0)
Block(2,20,8,WOOL:11)
Block(2,21,8,WOOL:11)
Block(2,22,8,WOOL:11)
Block(2,23,7,WOOL:11)
Block(2,24,7,WOOL:11)
Block(2,25,7,WOOL:11)
Block(2,26,7,WOOL:11)
Block(2,27,7,WOOL:11)
Block(2,28,8,WOOL:11)
Block(2,29,8,WOOL:11)
Block(2,37,8,WOOL:11)
Block(2,38,8,WOOL:11)
Block(2,39,8,WOOL:11)
Block(3,5,3,LOG:13)
Block(3,5,4,LOG:13)
Block(3,5,5,LOG:13)
Block(3,5,6,LOG:13)
Block(3,5,7,LOG:13)
Block(3,5,8,LOG:13)
Block(3,6,1,LOG:13)
Block(3,6,2,LOG:13)
Block(3,6,3,LOG:13)
Block(3,6,4,LOG:13)
Block(3,6,5,STONE:3)
Block(3,6,6,COAL_ORE:0)
Block(3,6,7,STONE:1)
Block(3,6,8,STONE:3)
Block(3,7,0,LOG:13)
Block(3,7,1,LOG:13)
Block(3,7,2,LOG:13)
Block(3,7,3,STONE:3)
Block(3,7,4,STONE:3)
Block(3,7,5,COAL_ORE:0)
Block(3,7,6,AIR:0)
Block(3,7,7,LAPIS_ORE:0)
Block(3,7,8,STONE:1)
Block(3,8,-1,WOOD:5)
Block(3,8,0,WOOD:5)
Block(3,8,1,WOOD:5)
Block(3,8,2,WOOD_DOUBLE_STEP:1)
Block(3,8,3,WOOD_STEP:9)
Block(3,8,4,WOOD_STEP:9)
Block(3,8,5,WOOD_STEP:9)
Block(3,8,6,WOOD_STEP:9)
Block(3,8,7,WOOD_STEP:9)
Block(3,8,8,WOOD_STEP:9)
Block(3,9,-1,WOOD:0)
Block(3,9,0,WOOD:0)
Block(3,9,1,WOOD:0)
Block(3,9,2,WOOD_BUTTON:4)
Block(3,9,3,DISPENSER:1)
Block(3,9,4,WOOD_BUTTON:3)
Block(3,9,5,BED_BLOCK:9)
Block(3,9,7,WOOD_STAIRS:1)
Block(3,10,-1,WOOD:0)
Block(3,10,0,WOOD:0)
Block(3,10,1,WOOD:0)
Block(3,10,3,LEVER:6)
Block(3,10,5,BED_BLOCK:9)
Block(3,11,-2,WOOD:0)
Block(3,11,-1,WOOD:0)
Block(3,11,0,WOOD:0)
Block(3,11,1,WOOD_DOUBLE_STEP:1)
Block(3,11,2,WOOD_STEP:9)
Block(3,11,3,WOOD_STEP:9)
Block(3,11,4,WOOD_STEP:9)
Block(3,11,5,WOOD_STEP:9)
Block(3,11,6,WOOD_STEP:9)
Block(3,11,7,WOOD_STEP:9)
Block(3,11,8,WOOD_STEP:9)
Block(3,12,-3,DISPENSER:4)
Block(3,12,-2,WOOD:0)
Block(3,12,-1,WOOD:5)
Block(3,12,0,WOOD:5)
Block(3,12,1,DISPENSER:1)
Block(3,12,2,WOOD_BUTTON:3)
Block(3,12,3,BED_BLOCK:9)
Block(3,12,4,WOOD_BUTTON:4)
Block(3,12,5,DISPENSER:1)
Block(3,12,6,FENCE:0)
Block(3,12,7,BED_BLOCK:9)
Block(3,13,-3,WOOD_STEP:13)
Block(3,13,-2,WOOD:5)
Block(3,13,-1,WOOD:5)
Block(3,13,0,WOOD:5)
Block(3,13,1,LEVER:6)
Block(3,13,5,LEVER:6)
Block(3,13,6,TORCH:5)
Block(3,14,-5,DARK_OAK_STAIRS:4)
Block(3,14,-4,WOOD_STEP:13)
Block(3,14,-3,WOOD_STEP:13)
Block(3,14,-2,WOOD:5)
Block(3,14,-1,WOOD:5)
Block(3,14,0,WOOD:5)
Block(3,14,1,WOOD:5)
Block(3,14,2,WOOD_STEP:1)
Block(3,14,3,WOOD:5)
Block(3,14,4,WOOD_STEP:1)
Block(3,14,5,WOOD:5)
Block(3,14,6,WOOD_STEP:1)
Block(3,14,7,WOOD:5)
Block(3,14,8,WOOD_STEP:1)
Block(3,15,-5,FENCE:0)
Block(3,15,-4,FENCE:0)
Block(3,15,-3,FENCE:0)
Block(3,15,-2,WOOD_STEP:5)
Block(3,15,-1,WOOD_STEP:5)
Block(3,15,1,WOOD_STEP:5)
Block(3,16,-5,FENCE:0)
Block(3,16,-4,FENCE:0)
Block(3,16,-3,FENCE:0)
Block(3,16,-2,FENCE:0)
Block(3,16,-1,FENCE:0)
Block(3,17,-4,FENCE:0)
Block(3,17,-3,FENCE:0)
Block(3,17,-2,FENCE:0)
Block(3,17,-1,FENCE:0)
Block(3,18,-4,FENCE:0)
Block(3,18,-3,FENCE:0)
Block(3,18,-2,FENCE:0)
Block(3,18,-1,FENCE:0)
Block(3,19,-4,FENCE:0)
Block(3,19,-3,FENCE:0)
Block(3,19,-2,FENCE:0)
Block(3,20,8,WOOL:11)
Block(3,21,8,WOOL:11)
Block(3,22,8,WOOL:11)
Block(3,23,8,WOOL:11)
Block(3,24,7,WOOL:11)
Block(3,25,7,WOOL:11)
Block(3,26,7,WOOL:11)
Block(3,27,8,WOOL:11)
Block(3,28,8,WOOL:11)
Block(3,38,8,WOOL:11)
Block(3,39,8,WOOL:11)
Block(4,4,4,LOG:13)
Block(4,4,5,LOG:13)
Block(4,4,6,LOG:13)
Block(4,4,7,LOG:13)
Block(4,4,8,LOG:13)
Block(4,5,0,LOG:13)
Block(4,5,1,LOG:13)
Block(4,5,2,LOG:13)
Block(4,5,3,LOG:13)
Block(4,5,4,STONE:1)
Block(4,5,5,STONE:3)
Block(4,5,6,STONE:3)
Block(4,5,7,STONE:3)
Block(4,5,8,STONE:3)
Block(4,6,-1,LOG:13)
Block(4,6,0,LOG:13)
Block(4,6,1,STONE:1)
Block(4,6,2,LOG:13)
Block(4,6,3,STONE:1)
Block(4,6,4,STONE:3)
Block(4,6,5,LAPIS_ORE:0)
Block(4,6,6,AIR:0)
Block(4,6,7,COAL_ORE:0)
Block(4,6,8,LAPIS_ORE:0)
Block(4,7,-2,LOG:13)
Block(4,7,-1,LOG:13)
Block(4,7,0,STONE:1)
Block(4,7,1,STONE:1)
Block(4,7,2,LOG:13)
Block(4,7,3,LAPIS_ORE:0)
Block(4,7,4,COAL_ORE:0)
Block(4,7,5,AIR:0)
Block(4,7,6,AIR:0)
Block(4,7,7,AIR:0)
Block(4,7,8,AIR:0)
Block(4,8,-2,WOOD:5)
Block(4,8,-1,WOOD_STEP:9)
Block(4,8,0,WOOD_STEP:9)
Block(4,8,1,WOOD_STEP:9)
Block(4,8,2,WOOD_DOUBLE_STEP:1)
Block(4,8,3,WOOD_STEP:9)
Block(4,8,4,WOOD_STEP:9)
Block(4,8,5,WOOD_STEP:9)
Block(4,8,6,WOOD_STEP:9)
Block(4,8,7,WOOD_STEP:9)
Block(4,8,8,WOOD_STEP:9)
Block(4,9,-2,WOOD:0)
Block(4,9,-1,BED_BLOCK:9)
Block(4,9,0,BED_BLOCK:9)
Block(4,9,1,WOOD:0)
Block(4,9,3,WOOD_STAIRS:1)
Block(4,9,5,BED_BLOCK:1)
Block(4,10,-3,WOOD:0)
Block(4,10,-2,WOOD:0)
Block(4,10,-1,BED_BLOCK:9)
Block(4,10,0,BED_BLOCK:9)
Block(4,10,1,WOOD:0)
Block(4,10,5,BED_BLOCK:1)
Block(4,10,7,AIR:0)
Block(4,11,-4,WOOD:0)
Block(4,11,-3,WOOD:0)
Block(4,11,-2,WOOD_DOUBLE_STEP:1)
Block(4,11,-1,WOOD_STEP:9)
Block(4,11,0,WOOD_STEP:9)
Block(4,11,1,WOOD_DOUBLE_STEP:1)
Block(4,11,2,WOOD_STEP:9)
Block(4,11,3,WOOD_STEP:9)
Block(4,11,4,WOOD_STEP:9)
Block(4,11,5,WOOD_STEP:9)
Block(4,11,6,WOOD_STEP:9)
Block(4,11,7,WOOD_STEP:9)
Block(4,11,8,WOOD_STEP:9)
Block(4,12,-4,WOOD:0)
Block(4,12,-3,CONCRETE:15)
Block(4,12,-2,WOOD:0)
Block(4,12,-1,CARPET:12)
Block(4,12,1,WOOD_STAIRS:1)
Block(4,12,3,BED_BLOCK:1)
Block(4,12,5,WOOD_STAIRS:1)
Block(4,12,7,BED_BLOCK:1)
Block(4,13,-5,WOOD:0)
Block(4,13,-4,WOOD:0)
Block(4,13,-3,WOOD_STEP:13)
Block(4,13,-2,WOOD:0)
Block(4,14,-5,WOOD:0)
Block(4,14,-4,WOOD:0)
Block(4,14,-3,WOOD:0)
Block(4,14,-2,WOOD:0)
Block(4,14,-1,TRAP_DOOR:9)
Block(4,14,0,WOOD_DOUBLE_STEP:1)
Block(4,14,1,SPRUCE_WOOD_STAIRS:0)
Block(4,14,2,WOOD_STEP:1)
Block(4,14,3,SPRUCE_WOOD_STAIRS:0)
Block(4,14,4,WOOD_STEP:1)
Block(4,14,5,SPRUCE_WOOD_STAIRS:0)
Block(4,14,6,WOOD_STEP:1)
Block(4,14,7,SPRUCE_WOOD_STAIRS:0)
Block(4,14,8,WOOD_STEP:1)
Block(4,15,-5,FENCE:0)
Block(4,15,-4,WOOD:5)
Block(4,15,-3,WOOD:5)
Block(4,15,-2,WOOD:5)
Block(4,15,0,STONE_BUTTON:2)
Block(4,15,1,STONE_BUTTON:2)
Block(4,15,2,STONE_BUTTON:2)
Block(4,16,-5,FENCE:0)
Block(4,16,-4,FENCE:0)
Block(4,16,-3,WOOD:5)
Block(4,16,-2,WOOD:5)
Block(4,16,0,STONE_BUTTON:2)
Block(4,16,1,STONE_BUTTON:2)
Block(4,16,2,STONE_BUTTON:2)
RandomBlock(4,17,-6,WALL_BANNER:4,../../Banners/royal_01.nbt,20,WALL_BANNER:4,../../Banners/royal_02.nbt,20,WALL_BANNER:4,../../Banners/royal_03.nbt,20,WALL_BANNER:4,../../Banners/royal_04.nbt,20,WALL_BANNER:4,../../Banners/royal_05.nbt,100)
Block(4,17,-5,FENCE:0)
Block(4,17,-4,FENCE:0)
Block(4,17,-3,WOOD:5)
Block(4,17,-2,WOOD:5)
Block(4,18,-5,FENCE:0)
Block(4,18,-4,FENCE:0)
Block(4,18,-3,WOOD_STEP:5)
Block(4,18,-2,WOOD_STEP:5)
Block(4,19,-5,FENCE:0)
Block(4,19,-4,FENCE:0)
Block(4,19,-3,FENCE:0)
Block(4,19,-2,FENCE:0)
Block(4,20,-5,FENCE:0)
Block(4,20,-4,FENCE:0)
Block(4,20,-3,FENCE:0)
Block(4,20,-2,FENCE:0)
Block(4,21,-5,FENCE:0)
Block(4,21,-4,FENCE:0)
Block(4,21,-3,FENCE:0)
Block(4,21,-2,FENCE:0)
Block(4,21,8,WOOL:11)
Block(4,22,8,WOOL:11)
Block(4,23,8,WOOL:11)
Block(4,24,8,WOOL:11)
Block(4,25,7,WOOL:11)
Block(4,26,8,WOOL:11)
Block(4,27,-7,FENCE:0)
Block(4,27,8,WOOL:11)
Block(4,28,-7,LOG:5)
Block(4,38,8,WOOL:11)
Block(5,4,2,LOG:13)
Block(5,4,3,LOG:13)
Block(5,4,4,LOG:13)
Block(5,4,5,LOG:13)
Block(5,4,6,LOG:13)
Block(5,4,7,LOG:13)
Block(5,4,8,LOG:13)
Block(5,5,-1,LOG:13)
Block(5,5,0,LOG:13)
Block(5,5,1,LOG:13)
Block(5,5,2,LOG:13)
Block(5,5,3,STONE:1)
Block(5,5,4,STONE:1)
Block(5,5,5,LAPIS_ORE:0)
Block(5,5,6,STONE:1)
Block(5,5,7,STONE:1)
Block(5,5,8,STONE:3)
Block(5,6,-3,LOG:13)
Block(5,6,-2,LOG:13)
Block(5,6,-1,STONE:1)
Block(5,6,0,STONE:1)
Block(5,6,1,STONE:1)
Block(5,6,2,LOG:13)
Block(5,6,3,LAPIS_ORE:0)
Block(5,6,4,COAL_ORE:0)
Block(5,6,5,AIR:0)
Block(5,6,6,AIR:0)
Block(5,6,7,AIR:0)
Block(5,6,8,COAL_ORE:0)
Block(5,7,-3,LOG:13)
Block(5,7,-2,STONE:1)
Block(5,7,-1,STONE:1)
Block(5,7,0,STONE:1)
Block(5,7,1,STONE:1)
Block(5,7,2,LOG:13)
Block(5,7,3,COAL_ORE:0)
Block(5,7,4,AIR:0)
Block(5,7,5,AIR:0)
Block(5,7,6,AIR:0)
Block(5,7,7,AIR:0)
Block(5,7,8,AIR:0)
Block(5,8,-4,WOOD:5)
Block(5,8,-3,WOOD:5)
Block(5,8,-2,WOOD_STEP:9)
Block(5,8,-1,WOOD_STEP:9)
Block(5,8,0,WOOD_STEP:9)
Block(5,8,1,WOOD_STEP:9)
Block(5,8,2,WOOD_DOUBLE_STEP:1)
Block(5,8,3,WOOD_STEP:9)
Block(5,8,4,WOOD_STEP:9)
Block(5,8,5,WOOD_STEP:9)
Block(5,8,6,WOOD_STEP:9)
Block(5,8,7,WOOD_STEP:9)
Block(5,8,8,WOOD_STEP:9)
Block(5,9,-4,WOOD:0)
Block(5,9,-3,WOOD:0)
Block(5,9,-2,WORKBENCH:0)
Block(5,9,-1,BED_BLOCK:1)
Block(5,9,0,BED_BLOCK:1)
Block(5,9,1,WOOD:0)
Block(5,9,3,CARPET:13)
Block(5,9,4,CARPET:15)
Block(5,9,5,SPRUCE_FENCE:0)
Block(5,9,7,FENCE:0)
Block(5,10,-5,WOOD:0)
Block(5,10,-4,WOOD:0)
Block(5,10,-3,WOOD:0)
Block(5,10,-2,WORKBENCH:0)
Block(5,10,-1,BED_BLOCK:1)
Block(5,10,0,BED_BLOCK:1)
Block(5,10,1,WOOD:0)
Block(5,10,5,SPRUCE_FENCE:0)
Block(5,10,7,TORCH:5)
Block(5,11,-5,WOOD:0)
Block(5,11,-4,WOOD_DOUBLE_STEP:1)
Block(5,11,-3,WOOD_DOUBLE_STEP:1)
Block(5,11,-2,WOOD_STEP:9)
Block(5,11,-1,WOOD_STEP:9)
Block(5,11,0,WOOD_STEP:9)
Block(5,11,1,WOOD_DOUBLE_STEP:1)
Block(5,11,2,WOOD_STEP:9)
Block(5,11,3,WOOD_STEP:9)
Block(5,11,4,WOOD_STEP:9)
Block(5,11,5,WOOD_DOUBLE_STEP:1)
Block(5,11,6,WOOD_STEP:9)
Block(5,11,7,WOOD_STEP:9)
Block(5,11,8,WOOD_STEP:9)
Block(5,12,-6,WOOD:0)
Block(5,12,-5,WOOD:0)
Block(5,12,-4,WOOD_BUTTON:4)
Block(5,12,-3,DISPENSER:1)
Block(5,12,-2,WOOD:0)
Block(5,12,-1,CARPET:15)
Block(5,12,1,RAILS:1)
Block(5,12,3,BED_BLOCK:3)
Block(5,12,4,CARPET:13)
Block(5,12,5,RAILS:1)
Block(5,12,7,BED_BLOCK:3)
Block(5,13,-6,WOOD:0)
Block(5,13,-5,WOOD:0)
Block(5,13,-3,LEVER:6)
Block(5,13,-2,WOOD:0)
Block(5,14,-7,WOOD:0)
Block(5,14,-6,WOOD:0)
Block(5,14,-5,WOOD:0)
Block(5,14,-4,WOOD_STEP:9)
Block(5,14,-3,WOOD_STEP:9)
Block(5,14,-2,WOOD:0)
Block(5,14,-1,TRAP_DOOR:9)
Block(5,14,0,WOOD_STEP:9)
Block(5,14,1,TRAP_DOOR:9)
Block(5,14,2,WOOD_STEP:9)
Block(5,14,3,TRAP_DOOR:9)
Block(5,14,4,WOOD_STEP:9)
Block(5,14,5,TRAP_DOOR:9)
Block(5,14,6,WOOD_STEP:9)
Block(5,14,7,TRAP_DOOR:9)
Block(5,14,8,WOOD_STEP:9)
Block(5,15,-7,WOOD:5)
Block(5,15,-6,WOOD:5)
Block(5,15,-5,WOOD:5)
Block(5,15,-4,WOOD:5)
Block(5,15,-3,COAL_ORE:0)
Block(5,15,-2,WOOD:5)
Block(5,15,-1,STONE_BUTTON:4)
Block(5,15,0,WOOD:2)
Block(5,15,1,WOOD:2)
Block(5,15,2,WOOD:2)
Block(5,15,3,STONE_BUTTON:3)
Block(5,15,4,SPRUCE_FENCE:0)
Block(5,15,5,SPRUCE_FENCE:0)
Block(5,15,6,SPRUCE_FENCE:0)
Block(5,15,7,SPRUCE_FENCE:0)
Block(5,15,8,SPRUCE_FENCE:0)
Block(5,16,-7,WOOD:5)
Block(5,16,-6,WOOD:5)
Block(5,16,-5,WOOD:5)
Block(5,16,-4,WOOD:5)
Block(5,16,-3,COAL_ORE:0)
Block(5,16,-2,WOOD:5)
Block(5,16,-1,STONE_BUTTON:4)
Block(5,16,0,WOOD:2)
Block(5,16,1,WOOD:2)
Block(5,16,2,WOOD:2)
Block(5,16,3,STONE_BUTTON:3)
Block(5,17,-7,WOOD:5)
Block(5,17,-6,WOOD:5)
Block(5,17,-5,WOOD:5)
Block(5,17,-4,WOOD:5)
Block(5,17,-2,WOOD:5)
Block(5,17,0,STONE_BUTTON:5)
Block(5,17,1,STONE_BUTTON:5)
Block(5,17,2,STONE_BUTTON:5)
Block(5,18,-7,WOOD_STEP:5)
Block(5,18,-6,WOOD_STEP:5)
Block(5,18,-5,WOOD_STEP:5)
Block(5,18,-4,WOOD_STEP:5)
Block(5,18,-2,WOOD_STEP:5)
Block(5,21,-5,FENCE:0)
Block(5,21,-4,FENCE:0)
Block(5,21,-3,FENCE:0)
Block(5,21,-2,FENCE:0)
Block(5,22,-5,FENCE:0)
Block(5,22,-4,FENCE:0)
Block(5,22,-3,FENCE:0)
Block(5,22,-2,FENCE:0)
Block(5,22,8,WOOL:11)
Block(5,23,-5,FENCE:0)
Block(5,23,-4,FENCE:0)
Block(5,23,-3,FENCE:0)
Block(5,23,-2,FENCE:0)
Block(5,23,8,WOOL:11)
Block(5,24,8,WOOL:11)
Block(5,25,8,WOOL:11)
Block(5,26,8,WOOL:11)
Block(5,27,-7,FENCE:0)
Block(5,28,-7,LOG:5)
Block(5,37,-7,FENCE:0)
Block(5,38,-7,LOG:5)
Block(6,3,7,LOG:13)
Block(6,3,8,LOG:13)
Block(6,4,0,LOG:13)
Block(6,4,1,LOG:13)
Block(6,4,2,LOG:13)
Block(6,4,3,LOG:13)
Block(6,4,4,LOG:13)
Block(6,4,5,LOG:13)
Block(6,4,6,LOG:13)
Block(6,4,7,STONE:3)
Block(6,4,8,STONE:3)
Block(6,5,-2,LOG:13)
Block(6,5,-1,LOG:13)
Block(6,5,0,STONE:1)
Block(6,5,1,STONE:1)
Block(6,5,2,LOG:13)
Block(6,5,3,STONE:1)
Block(6,5,4,STONE:1)
Block(6,5,5,COAL_ORE:0)
Block(6,5,6,AIR:0)
Block(6,5,7,AIR:0)
Block(6,5,8,AIR:0)
Block(6,6,-4,LOG:13)
Block(6,6,-3,LOG:13)
Block(6,6,-2,STONE:1)
Block(6,6,-1,STONE:1)
Block(6,6,0,STONE:1)
Block(6,6,2,LOG:13)
Block(6,6,3,COAL_ORE:0)
Block(6,6,4,AIR:0)
Block(6,6,5,AIR:0)
Block(6,6,6,AIR:0)
Block(6,6,7,AIR:0)
Block(6,6,8,AIR:0)
Block(6,7,-4,LOG:13)
Block(6,7,-3,STONE:1)
Block(6,7,-2,STONE:1)
Block(6,7,-1,LAPIS_ORE:0)
Block(6,7,0,STONE:1)
Block(6,7,1,STONE:1)
Block(6,7,2,LOG:13)
Block(6,7,3,AIR:0)
Block(6,7,4,AIR:0)
Block(6,7,5,AIR:0)
Block(6,7,6,AIR:0)
Block(6,7,7,AIR:0)
Block(6,7,8,AIR:0)
Block(6,8,-5,WOOD:5)
Block(6,8,-4,WOOD_STEP:9)
Block(6,8,-3,WOOD_STEP:9)
Block(6,8,-2,WOOD_STEP:9)
Block(6,8,-1,WOOD_STEP:9)
Block(6,8,0,WOOD_STEP:9)
Block(6,8,1,WOOD_STEP:9)
Block(6,8,2,WOOD_DOUBLE_STEP:1)
Block(6,8,3,WOOD_STEP:9)
Block(6,8,4,WOOD_STEP:9)
Block(6,8,5,WOOD_STEP:9)
Block(6,8,6,WOOD_STEP:9)
Block(6,8,7,WOOD_STEP:9)
Block(6,8,8,WOOD_STEP:9)
Block(6,9,-5,WOOD:0)
Block(6,9,-4,BED_BLOCK:10)
Block(6,9,-3,BED_BLOCK:2)
Block(6,9,-2,WOOD:0)
Block(6,9,1,WOOD:0)
Block(6,9,2,WOOD:2)
Block(6,9,4,CARPET:12)
Block(6,9,6,CARPET:13)
Block(6,9,7,CARPET:15)
Block(6,9,8,WOOD:2)
Block(6,10,-6,WOOD:0)
Block(6,10,-5,WOOD:0)
Block(6,10,-4,BED_BLOCK:10)
Block(6,10,-3,BED_BLOCK:2)
Block(6,10,-2,WOOD:0)
Block(6,10,0,AIR:0)
Block(6,10,1,WOOD:0)
Block(6,10,2,WOOD_BUTTON:5)
Block(6,10,8,WOOD_BUTTON:5)
Block(6,11,-6,WOOD:0)
Block(6,11,-5,WOOD_DOUBLE_STEP:1)
Block(6,11,-4,WOOD_STEP:9)
Block(6,11,-3,WOOD_STEP:9)
Block(6,11,-2,WOOD_DOUBLE_STEP:1)
Block(6,11,-1,WOOD_STEP:9)
Block(6,11,0,WOOD_STEP:9)
Block(6,11,1,WOOD_DOUBLE_STEP:1)
Block(6,11,2,WOOD_STEP:9)
Block(6,11,3,WOOD_STEP:9)
Block(6,11,4,WOOD_STEP:9)
Block(6,11,5,WOOD_STEP:9)
Block(6,11,6,WOOD_STEP:9)
Block(6,11,7,WOOD_STEP:9)
Block(6,11,8,WOOD_STEP:9)
Block(6,12,-7,WOOD:0)
Block(6,12,-6,WOOD:0)
Block(6,12,-5,WOOD:0)
Block(6,12,-4,FENCE:0)
Block(6,12,-3,WOOD_STAIRS:1)
Block(6,12,-2,WOOD:0)
Block(6,12,-1,CARPET:13)
Block(6,12,0,CARPET:13)
Block(6,12,1,WOOD_STEP:1)
Block(6,12,3,BED_BLOCK:11)
Block(6,12,4,CARPET:12)
Block(6,12,5,WOOD_STEP:1)
Block(6,12,7,BED_BLOCK:11)
Block(6,12,8,CARPET:12)
Block(6,13,-7,WOOD:0)
Block(6,13,-6,WOOD:0)
Block(6,13,-5,WOOD:0)
Block(6,13,-4,TORCH:5)
Block(6,13,-2,WOOD:0)
Block(6,14,-7,WOOD:0)
Block(6,14,-6,WOOD:0)
Block(6,14,-5,WOOD:0)
Block(6,14,-4,WOOD_STEP:9)
Block(6,14,-3,WOOD_STEP:9)
Block(6,14,-2,WOOD:0)
Block(6,14,-1,TRAP_DOOR:9)
Block(6,14,0,WOOD_STEP:9)
Block(6,14,1,TRAP_DOOR:9)
Block(6,14,2,WOOD_STEP:9)
Block(6,14,3,TRAP_DOOR:9)
Block(6,14,4,WOOD_STEP:9)
Block(6,14,5,TRAP_DOOR:9)
Block(6,14,6,WOOD_STEP:9)
Block(6,14,7,TRAP_DOOR:9)
Block(6,14,8,WOOD_STEP:9)
Block(6,15,-7,WOOD_DOUBLE_STEP:1)
Block(6,15,-6,WOOD_STEP:1)
Block(6,15,-5,WOOD_STEP:1)
Block(6,15,-4,COAL_ORE:0)
Block(6,15,-3,WORKBENCH:0)
Block(6,15,-2,WOOD:5)
Block(6,15,-1,STONE_BUTTON:4)
Block(6,15,0,WOOD:2)
Block(6,15,1,WOOD:2)
Block(6,15,2,WOOD:2)
Block(6,15,3,STONE_BUTTON:3)
Block(6,15,5,WORKBENCH:0)
RandomBlock(6,15,6,AIR:0,20,CHEST:5,../../../../Chests/Loot/ShipJunk_1.nbt,10,CHEST:5,../../../../Chests/Loot/ShipJunk_2.nbt,10,CHEST:5,../../../../Chests/Loot/ShipJunk_3.nbt,10,CHEST:5,../../../../Chests/Loot/ShipJunk_4.nbt,10,CHEST:5,../../../../Chests/Loot/ShipJunk_5.nbt,10,CHEST:5,../../../../Chests/Traveler/Travelers_Castle.nbt,1,CHEST:5,../../../../Chests/Traveler/Travelers_Church.nbt,1,CHEST:5,../../../../Chests/Traveler/Travelers_Daeroc.nbt,1,CHEST:5,../../../../Chests/Traveler/Travelers_Farmsteads.nbt,1,CHEST:5,../../../../Chests/Traveler/Travelers_GreenDungeon.nbt,1,CHEST:5,../../../../Chests/Traveler/Travelers_IceShips.nbt,1,CHEST:5,../../../../Chests/Traveler/Travelers_IceTemple.nbt,1,CHEST:5,../../../../Chests/Traveler/Travelers_LegacySpawn.nbt,1,CHEST:5,../../../../Chests/Traveler/Travelers_Mineshafts.nbt,1,CHEST:5,../../../../Chests/Traveler/Travelers_Mountains.nbt,1,CHEST:5,../../../../Chests/Traveler/Travelers_Origin.nbt,1,CHEST:5,../../../../Chests/Traveler/Travelers_Pirate.nbt,1,CHEST:5,../../../../Chests/Traveler/Travelers_Quarry.nbt,1,CHEST:5,../../../../Chests/Traveler/Travelers_Spook.nbt,1,CHEST:5,../../../../Chests/Traveler/Travelers_Tribal.nbt,1,CHEST:5,../../../../Chests/Lore/ShipFloat_1.nbt,1,CHEST:5,../../../../Chests/Lore/ShipFloat_2.nbt,1,CHEST:5,../../../../Chests/Lore/ShipFloat_3.nbt,1,CHEST:5,../../../../Chests/Lore/ShipFloat_4.nbt,1,CHEST:5,../../../../Chests/Lore/ShipFloat_5.nbt,1,CHEST:5,../../../../Chests/Loot/Common1.nbt,10,CHEST:5,../../../../Chests/Loot/Common2.nbt,10,CHEST:5,../../../../Chests/Loot/Common3.nbt,10,CHEST:5,../../../../Chests/Loot/Common4.nbt,10,CHEST:5,../../../../Chests/Loot/Common5.nbt,10,CHEST:5,../../../../Chests/Loot/Common6.nbt,10,CHEST:5,../../../../Chests/Loot/Common7.nbt,10,CHEST:5,../../../../Chests/Loot/Common8.nbt,10,CHEST:5,../../../../Chests/Loot/Common9.nbt,10,CHEST:5,../../../../Chests/Loot/Common10.nbt,10,CHEST:5,../../../../Chests/Loot/Common10.nbt,11,CHEST:5,../../../../Chests/Loot/Common12.nbt,10,CHEST:5,../../../../Chests/Loot/Common13.nbt,10,CHEST:5,../../../../Chests/Loot/Common14.nbt,10,CHEST:5,../../../../Chests/Loot/Common15.nbt,10,CHEST:5,../../../../Chests/Lore/ShipFloat_1.nbt,2,CHEST:5,../../../../Chests/Lore/ShipFloat_3.nbt,2,CHEST:5,../../../../Chests/Lore/ShipFloat_4.nbt,2,CHEST:5,../../../../Chests/Lore/ShipFloat_5.nbt,2,CHEST:5,../../../../Chests/Lore/ShipFloat_5.nbt,2,CHEST:5,../../../../Chests/Loot/Rare1.nbt,5,CHEST:5,../../../../Chests/Loot/Rare2.nbt,5,CHEST:5,../../../../Chests/Loot/Rare3.nbt,5,CHEST:5,../../../../Chests/Loot/Rare4.nbt,5,CHEST:5,../../../../Chests/Loot/Rare5.nbt,5,CHEST:5,../../../../Chests/Loot/Rare6.nbt,5,CHEST:5,../../../../Chests/Loot/Rare7.nbt,5,CHEST:5,../../../../Chests/Loot/Rare8.nbt,5,CHEST:5,../../../../Chests/Loot/Rare9.nbt,5,CHEST:5,../../../../Chests/Loot/Rare10.nbt,5,CHEST:5,../../../../Chests/Loot/Rare11.nbt,5,CHEST:5,../../../../Chests/Loot/Rare12.nbt,5,CHEST:5,../../../../Chests/Loot/Rare13.nbt,5,CHEST:5,../../../../Chests/Loot/Rare14.nbt,5,CHEST:5,../../../../Chests/Loot/Rare15.nbt,5,CHEST:5,../../../../Chests/Loot/Epic1.nbt,2,CHEST:5,../../../../Chests/Loot/Epic2.nbt,2,CHEST:5,../../../../Chests/Loot/Epic3.nbt,2,CHEST:5,../../../../Chests/Loot/Epic4.nbt,2,CHEST:5,../../../../Chests/Loot/Epic5.nbt,2,CHEST:5,../../../../Chests/Loot/Epic6.nbt,2,CHEST:5,../../../../Chests/Loot/Epic7.nbt,2,CHEST:5,../../../../Chests/Loot/Epic8.nbt,2,CHEST:5,../../../../Chests/Loot/Epic9.nbt,2,CHEST:5,../../../../Chests/Loot/Epic10.nbt,2,CHEST:5,../../../../Chests/Loot/Epic11.nbt,2,CHEST:5,../../../../Chests/Loot/Epic12.nbt,2,CHEST:5,../../../../Chests/Loot/Epic13.nbt,2,CHEST:5,../../../../Chests/Loot/Epic14.nbt,2,CHEST:5,../../../../Chests/Loot/Epic15.nbt,5,CHEST:5,../../../../Chests/Loot/Rare1.nbt,5,CHEST:5,../../../../Chests/Loot/Rare2.nbt,5,CHEST:5,../../../../Chests/Loot/Rare3.nbt,5,CHEST:5,../../../../Chests/Loot/Rare4.nbt,5,CHEST:5,../../../../Chests/Loot/Rare5.nbt,10,CHEST:5,../../../../Chests/Loot/Rare6.nbt,10,CHEST:5,../../../../Chests/Loot/Rare7.nbt,10,CHEST:5,../../../../Chests/Loot/Rare8.nbt,10,CHEST:5,../../../../Chests/Loot/Rare9.nbt,10,CHEST:5,../../../../Chests/Loot/Rare10.nbt,15,CHEST:5,../../../../Chests/Loot/Rare11.nbt,15,CHEST:5,../../../../Chests/Loot/Rare12.nbt,15,CHEST:5,../../../../Chests/Loot/Rare13.nbt,15,CHEST:5,../../../../Chests/Loot/Rare14.nbt,15,CHEST:5,../../../../Chests/Loot/Rare15.nbt,15,CHEST:5,../../../../Chests/Loot/Epic15.nbt,100)
RandomBlock(6,15,7,AIR:0,20,CHEST:5,../../../../Chests/Loot/ShipJunk_1.nbt,10,CHEST:5,../../../../Chests/Loot/ShipJunk_2.nbt,10,CHEST:5,../../../../Chests/Loot/ShipJunk_3.nbt,10,CHEST:5,../../../../Chests/Loot/ShipJunk_4.nbt,10,CHEST:5,../../../../Chests/Loot/ShipJunk_5.nbt,10,CHEST:5,../../../../Chests/Traveler/Travelers_Castle.nbt,1,CHEST:5,../../../../Chests/Traveler/Travelers_Church.nbt,1,CHEST:5,../../../../Chests/Traveler/Travelers_Daeroc.nbt,1,CHEST:5,../../../../Chests/Traveler/Travelers_Farmsteads.nbt,1,CHEST:5,../../../../Chests/Traveler/Travelers_GreenDungeon.nbt,1,CHEST:5,../../../../Chests/Traveler/Travelers_IceShips.nbt,1,CHEST:5,../../../../Chests/Traveler/Travelers_IceTemple.nbt,1,CHEST:5,../../../../Chests/Traveler/Travelers_LegacySpawn.nbt,1,CHEST:5,../../../../Chests/Traveler/Travelers_Mineshafts.nbt,1,CHEST:5,../../../../Chests/Traveler/Travelers_Mountains.nbt,1,CHEST:5,../../../../Chests/Traveler/Travelers_Origin.nbt,1,CHEST:5,../../../../Chests/Traveler/Travelers_Pirate.nbt,1,CHEST:5,../../../../Chests/Traveler/Travelers_Quarry.nbt,1,CHEST:5,../../../../Chests/Traveler/Travelers_Spook.nbt,1,CHEST:5,../../../../Chests/Traveler/Travelers_Tribal.nbt,1,CHEST:5,../../../../Chests/Lore/ShipFloat_1.nbt,1,CHEST:5,../../../../Chests/Lore/ShipFloat_2.nbt,1,CHEST:5,../../../../Chests/Lore/ShipFloat_3.nbt,1,CHEST:5,../../../../Chests/Lore/ShipFloat_4.nbt,1,CHEST:5,../../../../Chests/Lore/ShipFloat_5.nbt,1,CHEST:5,../../../../Chests/Loot/Common1.nbt,10,CHEST:5,../../../../Chests/Loot/Common2.nbt,10,CHEST:5,../../../../Chests/Loot/Common3.nbt,10,CHEST:5,../../../../Chests/Loot/Common4.nbt,10,CHEST:5,../../../../Chests/Loot/Common5.nbt,10,CHEST:5,../../../../Chests/Loot/Common6.nbt,10,CHEST:5,../../../../Chests/Loot/Common7.nbt,10,CHEST:5,../../../../Chests/Loot/Common8.nbt,10,CHEST:5,../../../../Chests/Loot/Common9.nbt,10,CHEST:5,../../../../Chests/Loot/Common10.nbt,10,CHEST:5,../../../../Chests/Loot/Common10.nbt,11,CHEST:5,../../../../Chests/Loot/Common12.nbt,10,CHEST:5,../../../../Chests/Loot/Common13.nbt,10,CHEST:5,../../../../Chests/Loot/Common14.nbt,10,CHEST:5,../../../../Chests/Loot/Common15.nbt,10,CHEST:5,../../../../Chests/Lore/ShipFloat_1.nbt,2,CHEST:5,../../../../Chests/Lore/ShipFloat_3.nbt,2,CHEST:5,../../../../Chests/Lore/ShipFloat_4.nbt,2,CHEST:5,../../../../Chests/Lore/ShipFloat_5.nbt,2,CHEST:5,../../../../Chests/Lore/ShipFloat_5.nbt,2,CHEST:5,../../../../Chests/Loot/Rare1.nbt,5,CHEST:5,../../../../Chests/Loot/Rare2.nbt,5,CHEST:5,../../../../Chests/Loot/Rare3.nbt,5,CHEST:5,../../../../Chests/Loot/Rare4.nbt,5,CHEST:5,../../../../Chests/Loot/Rare5.nbt,5,CHEST:5,../../../../Chests/Loot/Rare6.nbt,5,CHEST:5,../../../../Chests/Loot/Rare7.nbt,5,CHEST:5,../../../../Chests/Loot/Rare8.nbt,5,CHEST:5,../../../../Chests/Loot/Rare9.nbt,5,CHEST:5,../../../../Chests/Loot/Rare10.nbt,5,CHEST:5,../../../../Chests/Loot/Rare11.nbt,5,CHEST:5,../../../../Chests/Loot/Rare12.nbt,5,CHEST:5,../../../../Chests/Loot/Rare13.nbt,5,CHEST:5,../../../../Chests/Loot/Rare14.nbt,5,CHEST:5,../../../../Chests/Loot/Rare15.nbt,5,CHEST:5,../../../../Chests/Loot/Epic1.nbt,2,CHEST:5,../../../../Chests/Loot/Epic2.nbt,2,CHEST:5,../../../../Chests/Loot/Epic3.nbt,2,CHEST:5,../../../../Chests/Loot/Epic4.nbt,2,CHEST:5,../../../../Chests/Loot/Epic5.nbt,2,CHEST:5,../../../../Chests/Loot/Epic6.nbt,2,CHEST:5,../../../../Chests/Loot/Epic7.nbt,2,CHEST:5,../../../../Chests/Loot/Epic8.nbt,2,CHEST:5,../../../../Chests/Loot/Epic9.nbt,2,CHEST:5,../../../../Chests/Loot/Epic10.nbt,2,CHEST:5,../../../../Chests/Loot/Epic11.nbt,2,CHEST:5,../../../../Chests/Loot/Epic12.nbt,2,CHEST:5,../../../../Chests/Loot/Epic13.nbt,2,CHEST:5,../../../../Chests/Loot/Epic14.nbt,2,CHEST:5,../../../../Chests/Loot/Epic15.nbt,5,CHEST:5,../../../../Chests/Loot/Rare1.nbt,5,CHEST:5,../../../../Chests/Loot/Rare2.nbt,5,CHEST:5,../../../../Chests/Loot/Rare3.nbt,5,CHEST:5,../../../../Chests/Loot/Rare4.nbt,5,CHEST:5,../../../../Chests/Loot/Rare5.nbt,10,CHEST:5,../../../../Chests/Loot/Rare6.nbt,10,CHEST:5,../../../../Chests/Loot/Rare7.nbt,10,CHEST:5,../../../../Chests/Loot/Rare8.nbt,10,CHEST:5,../../../../Chests/Loot/Rare9.nbt,10,CHEST:5,../../../../Chests/Loot/Rare10.nbt,15,CHEST:5,../../../../Chests/Loot/Rare11.nbt,15,CHEST:5,../../../../Chests/Loot/Rare12.nbt,15,CHEST:5,../../../../Chests/Loot/Rare13.nbt,15,CHEST:5,../../../../Chests/Loot/Rare14.nbt,15,CHEST:5,../../../../Chests/Loot/Rare15.nbt,15,CHEST:5,../../../../Chests/Loot/Epic15.nbt,100)
Block(6,15,8,STONE_BUTTON:4)
Block(6,16,-7,WOOD_BUTTON:2)
Block(6,16,-2,WOOD:5)
Block(6,16,-1,STONE_BUTTON:4)
Block(6,16,0,WOOD:2)
Block(6,16,1,WOOD:2)
Block(6,16,2,WOOD:2)
Block(6,16,3,STONE_BUTTON:3)
Block(6,17,-2,WOOD:5)
Block(6,17,0,STONE_BUTTON:5)
Block(6,17,1,STONE_BUTTON:5)
Block(6,17,2,STONE_BUTTON:5)
Block(6,18,-2,WOOD_STEP:5)
Block(6,23,-5,FENCE:0)
Block(6,23,-4,FENCE:0)
Block(6,23,-3,FENCE:0)
Block(6,24,-5,FENCE:0)
Block(6,24,-4,FENCE:0)
Block(6,24,-3,FENCE:0)
Block(6,24,8,WOOL:11)
Block(6,25,-5,FENCE:0)
Block(6,25,-4,FENCE:0)
Block(6,25,-3,FENCE:0)
Block(6,25,8,WOOL:11)
Block(6,28,-7,LOG:5)
Block(6,38,-7,LOG:5)
Block(7,3,2,LOG:13)
Block(7,3,3,LOG:13)
Block(7,3,4,LOG:13)
Block(7,3,5,LOG:13)
Block(7,3,6,LOG:13)
Block(7,3,7,LOG:13)
Block(7,3,8,LOG:13)
Block(7,4,-3,LOG:13)
Block(7,4,-2,LOG:13)
Block(7,4,-1,LOG:13)
Block(7,4,0,LOG:13)
Block(7,4,1,LOG:13)
Block(7,4,2,LOG:13)
Block(7,4,3,STONE:1)
Block(7,4,4,STONE:1)
Block(7,4,5,LAPIS_ORE:0)
Block(7,4,6,LAPIS_ORE:0)
Block(7,4,7,AIR:0)
Block(7,4,8,AIR:0)
Block(7,5,-4,LOG:13)
Block(7,5,-3,LOG:13)
Block(7,5,-2,STONE:1)
Block(7,5,-1,STONE:1)
Block(7,5,0,STONE:1)
Block(7,5,1,STONE:1)
Block(7,5,2,LOG:13)
Block(7,5,3,AIR:0)
Block(7,5,4,COAL_ORE:0)
Block(7,5,5,AIR:0)
Block(7,5,6,AIR:0)
Block(7,5,7,AIR:0)
Block(7,5,8,AIR:0)
Block(7,6,-4,LOG:13)
Block(7,6,-3,AIR:0)
Block(7,6,-2,AIR:0)
Block(7,6,-1,AIR:0)
Block(7,6,0,LAPIS_ORE:0)
Block(7,6,1,STONE:1)
Block(7,6,2,LOG:13)
Block(7,6,3,AIR:0)
Block(7,6,4,AIR:0)
Block(7,6,5,AIR:0)
Block(7,6,6,AIR:0)
Block(7,6,7,AIR:0)
Block(7,6,8,AIR:0)
Block(7,7,-5,LOG:13)
Block(7,7,-4,AIR:0)
Block(7,7,-3,AIR:0)
Block(7,7,-2,AIR:0)
Block(7,7,-1,AIR:0)
Block(7,7,0,AIR:0)
Block(7,7,1,STONE:1)
Block(7,7,2,LOG:13)
Block(7,7,3,AIR:0)
Block(7,7,4,AIR:0)
Block(7,7,5,AIR:0)
Block(7,7,6,AIR:0)
Block(7,7,7,AIR:0)
Block(7,7,8,AIR:0)
Block(7,8,-6,WOOD:5)
Block(7,8,-5,WOOD_STEP:9)
Block(7,8,-4,WOOD_STEP:9)
Block(7,8,-3,WOOD_STEP:9)
Block(7,8,-2,WOOD_STEP:9)
Block(7,8,-1,WOOD_STEP:9)
Block(7,8,0,WOOD_STEP:9)
Block(7,8,1,WOOD_STEP:9)
Block(7,8,2,WOOD_DOUBLE_STEP:1)
Block(7,8,3,TRAP_DOOR:10)
Block(7,8,4,TRAP_DOOR:10)
Block(7,8,5,TRAP_DOOR:10)
Block(7,8,6,TRAP_DOOR:10)
Block(7,8,7,TRAP_DOOR:10)
Block(7,8,8,TRAP_DOOR:10)
Block(7,9,-6,WOOD:0)
Block(7,9,-5,WORKBENCH:0)
Block(7,9,-3,CARPET:12)
Block(7,9,-2,WOOD:0)
Block(7,9,-1,FENCE:0)
Block(7,9,0,CARPET:13)
Block(7,9,1,WOOD:0)
Block(7,9,2,FENCE:0)
Block(7,10,-7,WOOD:0)
Block(7,10,-6,WOOD:0)
Block(7,10,-2,WOOD:0)
Block(7,10,-1,TORCH:5)
Block(7,10,1,WOOD:0)
Block(7,10,2,TORCH:5)
Block(7,11,-7,WOOD:0)
Block(7,11,-6,WOOD_DOUBLE_STEP:1)
Block(7,11,-5,WOOD_STEP:9)
Block(7,11,-4,WOOD_STEP:9)
Block(7,11,-3,WOOD_STEP:9)
Block(7,11,-2,WOOD_DOUBLE_STEP:1)
Block(7,11,-1,WOOD_STEP:9)
Block(7,11,0,WOOD_STEP:9)
Block(7,11,1,WOOD_DOUBLE_STEP:1)
Block(7,11,2,TRAP_DOOR:10)
Block(7,11,3,TRAP_DOOR:10)
Block(7,11,4,TRAP_DOOR:10)
Block(7,11,5,TRAP_DOOR:10)
Block(7,11,6,TRAP_DOOR:10)
Block(7,11,7,TRAP_DOOR:10)
Block(7,11,8,TRAP_DOOR:10)
Block(7,12,-7,BED_BLOCK:10)
Block(7,12,-6,BED_BLOCK:2)
Block(7,12,-5,WOOD:0)
Block(7,12,-3,CARPET:13)
Block(7,12,-2,WOOD:0)
Block(7,12,-1,FENCE:0)
Block(7,12,0,CARPET:15)
Block(7,12,1,CARPET:12)
Block(7,13,-7,BED_BLOCK:10)
Block(7,13,-6,BED_BLOCK:2)
Block(7,13,-5,WOOD:0)
Block(7,13,-4,AIR:0)
Block(7,13,-2,WOOD:0)
Block(7,13,-1,TORCH:5)
Block(7,14,-7,BED_BLOCK:10)
Block(7,14,-6,BED_BLOCK:2)
Block(7,14,-5,WOOD:0)
Block(7,14,-4,WOOD_STEP:9)
Block(7,14,-3,WOOD_STEP:9)
Block(7,14,-2,WOOD_DOUBLE_STEP:1)
Block(7,14,-1,WOOD_STEP:9)
Block(7,14,0,WOOD_STEP:9)
Block(7,14,1,WOOD_STEP:9)
Block(7,14,2,WOOD_STEP:9)
Block(7,14,3,WOOD_STEP:9)
Block(7,14,4,WOOD_STEP:9)
Block(7,14,5,WOOD_STEP:9)
Block(7,14,6,WOOD_STEP:9)
Block(7,14,7,WOOD_STEP:9)
Block(7,14,8,WOOD_STEP:9)
Block(7,15,-7,WOOD_DOUBLE_STEP:1)
Block(7,15,-6,WOOD_DOUBLE_STEP:1)
Block(7,15,-5,WOOD_STEP:1)
Block(7,15,-2,SPRUCE_FENCE:0)
Block(7,15,-1,STONE_BUTTON:4)
Block(7,15,0,WOOD:2)
Block(7,15,1,WOOD:2)
Block(7,15,2,WOOD:2)
Block(7,15,3,STONE_BUTTON:3)
Block(7,15,8,STONE_BUTTON:4)
Block(7,16,-7,DISPENSER:1)
Block(7,16,-6,WOOD_STAIRS:3)
Block(7,16,-2,SPRUCE_FENCE:0)
Block(7,16,-1,STONE_BUTTON:4)
Block(7,16,0,WOOD:2)
Block(7,16,1,WOOD:2)
Block(7,16,2,WOOD:2)
Block(7,16,3,STONE_BUTTON:3)
Block(7,16,7,AIR:0)
Block(7,17,-7,LEVER:5)
Block(7,17,-2,SPRUCE_FENCE:0)
Block(7,17,0,STONE_BUTTON:5)
Block(7,17,1,STONE_BUTTON:5)
Block(7,17,2,STONE_BUTTON:5)
Block(7,18,-2,WOOD_STEP:5)
Block(7,25,-5,FENCE:0)
Block(7,25,-4,FENCE:0)
Block(7,26,-5,FENCE:0)
Block(7,26,-4,FENCE:0)
Block(7,27,-5,FENCE:0)
Block(7,28,-6,LOG:5)
Block(7,28,-5,FENCE:0)
Block(7,31,-6,DARK_OAK_STAIRS:6)
Block(7,31,-5,DARK_OAK_STAIRS:4)
Block(7,31,-4,DARK_OAK_STAIRS:7)
Block(7,32,-6,FENCE:0)
Block(7,32,-5,FENCE:0)
Block(7,32,-4,FENCE:0)
Block(7,33,-6,FENCE:0)
Block(7,33,-5,FENCE:0)
Block(7,33,-4,FENCE:0)
Block(7,34,-6,FENCE:0)
Block(7,34,-5,FENCE:0)
Block(7,34,-4,FENCE:0)
Block(7,35,-6,FENCE:0)
Block(7,35,-5,FENCE:0)
Block(7,36,-6,FENCE:0)
Block(7,36,-5,FENCE:0)
Block(7,37,-6,FENCE:0)
Block(7,37,-5,FENCE:0)
Block(7,38,-6,LOG:5)
Entity(4,10,7,minecraft:villager,1)
Entity(6,10,0,minecraft:villager,1)
Entity(7,13,-4,minecraft:villager,1)
Entity(7,16,7,minecraft:villager,1)
