Author: NLBlackEagle
Description: No description given
SettingsMode: WriteDisable
Frequency: 0
SpawnHeight: highestBlock
UseCenterForHighestBlock: true
MinHeight: 0
MaxHeight: 255
InheritBO3: 
InheritBO3Rotation: NORTH
OverrideChildSettings: true
OverrideParentHeight: false
CanOverride: false
BranchFrequency: 0
BranchFrequencyGroup: 
MustBeBelowOther: false
MustBeInside: 
CannotBeInside: 
ReplacesBO3: 
MustBeInsideWorldBorders: false
CanSpawnOnWater: true
SpawnOnWaterOnly: false
SpawnUnderWater: false
SpawnAtWaterLevel: false
HeightOffset: 0
RemoveAir: false
ReplaceAbove: 
ReplaceBelow: 
ReplaceWithBiomeBlocks: false
ReplaceWithSurfaceBlock: GRASS
ReplaceWithGroundBlock: DIRT
ReplaceWithStoneBlock: STONE
SmoothRadius: 0
SmoothHeightOffset: 0
SmoothStartTop: false
SmoothStartWood: false
SmoothingSurfaceBlock: 
SmoothingGroundBlock: 
BO3Group: 
IsSpawnPoint: false
DoReplaceBlocks: false
Block(-8,3,-7,LOG:13)
Block(-8,3,-6,LOG:13)
Block(-8,3,-5,LOG:13)
Block(-8,3,-4,LOG:13)
Block(-8,3,-3,LOG:13)
Block(-8,3,-2,LOG:13)
Block(-8,3,-1,LOG:13)
Block(-8,3,0,LOG:13)
Block(-8,3,1,LOG:13)
Block(-8,3,2,DARK_OAK_FENCE:0)
Block(-8,3,3,WOOD:0)
Block(-8,3,4,WOOD_STAIRS:7)
Block(-8,4,-7,LOG:13)
Block(-8,4,-6,LOG:13)
Block(-8,4,-5,LOG:13)
Block(-8,4,-4,LOG:13)
Block(-8,4,-3,LOG:13)
Block(-8,4,-2,LOG:13)
Block(-8,4,-1,LOG:13)
Block(-8,4,0,LOG:13)
Block(-8,4,1,LOG:13)
Block(-8,4,2,DARK_OAK_FENCE:0)
Block(-8,4,3,DARK_OAK_FENCE:0)
Block(-8,4,4,WOOD:0)
Block(-8,5,-7,LOG:13)
Block(-8,5,-6,LOG:13)
Block(-8,5,-5,LOG:13)
Block(-8,5,-4,LOG:13)
Block(-8,5,-3,LOG:13)
Block(-8,5,-2,LOG:13)
Block(-8,5,-1,LOG:13)
Block(-8,5,0,LOG:13)
Block(-8,5,1,LOG:13)
Block(-8,5,2,DARK_OAK_FENCE:0)
Block(-8,5,3,WOOD:0)
Block(-8,5,4,WOOD:0)
Block(-8,6,-7,SPRUCE_FENCE:0)
Block(-8,6,-6,CARPET:12)
Block(-8,6,-5,AIR:0)
Block(-8,6,-4,AIR:0)
Block(-8,6,-3,DARK_OAK_DOOR:3)
Block(-8,6,-2,CARPET:12)
Block(-8,6,-1,CARPET:12)
Block(-8,6,0,WOOD_STAIRS:2)
Block(-8,6,1,LOG:13)
Block(-8,6,2,LOG:13)
Block(-8,6,3,DARK_OAK_FENCE:0)
Block(-8,6,4,WOOD:0)
Block(-8,6,5,WOOD_STAIRS:7)
Block(-8,7,-7,TORCH:5)
Block(-8,7,-6,AIR:0)
Block(-8,7,-5,AIR:0)
Block(-8,7,-4,AIR:0)
Block(-8,7,-3,DARK_OAK_DOOR:9)
Block(-8,7,-2,AIR:0)
Block(-8,7,-1,AIR:0)
Block(-8,7,0,AIR:0)
Block(-8,7,1,LADDER:2)
Block(-8,7,2,LOG:13)
Block(-8,7,3,DARK_OAK_FENCE:0)
Block(-8,7,4,WOOD:0)
Block(-8,7,5,WOOD:0)
Block(-8,8,-7,AIR:0)
Block(-8,8,-6,AIR:0)
Block(-8,8,-5,AIR:0)
Block(-8,8,-4,AIR:0)
Block(-8,8,-3,WOOD:5)
Block(-8,8,-2,AIR:0)
Block(-8,8,-1,AIR:0)
Block(-8,8,0,AIR:0)
Block(-8,8,1,LADDER:2)
Block(-8,8,2,WOOD:5)
Block(-8,8,3,DARK_OAK_FENCE:0)
Block(-8,8,4,WOOD:0)
Block(-8,8,5,WOOD:0)
Block(-8,9,-7,WOOD_STEP:1)
Block(-8,9,-6,WOOD_DOUBLE_STEP:1)
Block(-8,9,-5,WOOD_DOUBLE_STEP:1)
Block(-8,9,-4,WOOD_DOUBLE_STEP:1)
Block(-8,9,-3,WOOD_DOUBLE_STEP:1)
Block(-8,9,-2,WOOD_STEP:9)
Block(-8,9,-1,WOOD_STEP:9)
Block(-8,9,0,WOOD_STEP:9)
Block(-8,9,1,LADDER:2)
Block(-8,9,2,LOG:1)
Block(-8,9,3,LOG:13)
Block(-8,9,4,DARK_OAK_FENCE:0)
Block(-8,9,5,WOOD_STAIRS:3)
Block(-8,10,-6,CARPET:12)
Block(-8,10,-5,CARPET:12)
Block(-8,10,-3,WOOD_STEP:1)
Block(-8,10,-2,WOOD_STEP:1)
Block(-8,10,-1,WOOD_STEP:1)
Block(-8,10,0,WOOD_DOUBLE_STEP:1)
Block(-8,10,1,LADDER:2)
Block(-8,10,2,LOG:1)
Block(-8,10,3,LOG:13)
Block(-8,11,1,TRAP_DOOR:0)
Block(-8,11,2,LOG:1)
Block(-8,11,3,LOG:13)
Block(-8,12,-7,WOOD_DOUBLE_STEP:1)
Block(-8,12,-6,WOOD_STEP:9)
Block(-8,12,-5,WOOD_STEP:9)
Block(-8,12,-4,WOOD_STEP:9)
Block(-8,12,-3,WOOD_STEP:9)
Block(-8,12,1,LADDER:2)
Block(-8,12,2,LOG:1)
Block(-8,12,3,LOG:13)
Block(-8,13,-7,FENCE:0)
Block(-8,13,-6,CARPET:13)
Block(-8,13,-5,DARK_OAK_DOOR:3)
Block(-8,13,-3,WOOD_DOUBLE_STEP:1)
Block(-8,13,-2,WOOD_DOUBLE_STEP:1)
Block(-8,13,-1,WOOD_DOUBLE_STEP:1)
Block(-8,13,0,WOOD_STEP:9)
Block(-8,13,1,LADDER:2)
Block(-8,13,2,LOG:1)
Block(-8,13,3,WOOD_STEP:9)
Block(-8,13,4,WOOD_STAIRS:7)
Block(-8,14,-7,TORCH:5)
Block(-8,14,-5,DARK_OAK_DOOR:9)
Block(-8,14,-3,WOOD:0)
Block(-8,14,-2,WOOD:0)
Block(-8,14,-1,WOOD:0)
Block(-8,14,0,FENCE:0)
Block(-8,14,1,TRAP_DOOR:0)
Block(-8,14,2,LOG:1)
Block(-8,14,4,WOOD:0)
Block(-8,15,-7,WOOD_STEP:1)
Block(-8,15,-6,WOOD_DOUBLE_STEP:1)
Block(-8,15,-5,WOOD_DOUBLE_STEP:1)
Block(-8,15,-4,WOOD_STEP:9)
Block(-8,15,-3,WOOD:0)
Block(-8,15,-2,WOOD:0)
Block(-8,15,-1,WOOD:0)
Block(-8,15,0,TORCH:5)
Block(-8,15,1,AIR:0)
Block(-8,15,2,LOG:1)
Block(-8,15,4,WOOD:0)
Block(-8,16,-5,SPRUCE_DOOR:3)
Block(-8,16,-2,WOOD_STEP:1)
Block(-8,16,-1,WOOD_DOUBLE_STEP:1)
Block(-8,16,0,WOOD_STEP:9)
Block(-8,16,1,WOOD_STEP:9)
Block(-8,16,2,LOG:1)
Block(-8,16,3,WOOD_STEP:9)
Block(-8,16,4,WOOD_STEP:9)
Block(-8,16,5,WOOD_DOUBLE_STEP:0)
Block(-8,16,6,WOOD_STAIRS:7)
Block(-8,17,-5,SPRUCE_DOOR:9)
Block(-8,17,-1,CARPET:14)
Block(-8,17,0,CARPET:14)
Block(-8,17,1,CARPET:14)
Block(-8,17,2,LOG:1)
Block(-8,17,3,CARPET:14)
Block(-8,17,4,CARPET:14)
Block(-8,17,5,DARK_OAK_DOOR:3)
Block(-8,17,6,FENCE:0)
Block(-8,18,-5,WOOD_DOUBLE_STEP:1)
Block(-8,18,-4,WOOD_STEP:5)
Block(-8,18,-3,WOOD_STEP:9)
Block(-8,18,1,AIR:0)
Block(-8,18,2,LOG:1)
Block(-8,18,5,DARK_OAK_DOOR:10)
Block(-8,19,-5,TRAP_DOOR:4)
Block(-8,19,-4,WOOD:5)
Block(-8,19,-3,TRAP_DOOR:5)
Block(-8,19,-2,WOOD_STEP:1)
Block(-8,19,-1,WOOD_STEP:1)
Block(-8,19,0,WOOD_STEP:1)
Block(-8,19,1,WOOD_STEP:1)
Block(-8,19,2,LOG:1)
Block(-8,19,3,WOOD_STEP:1)
Block(-8,19,4,WOOD_STEP:1)
Block(-8,19,5,WOOD_DOUBLE_STEP:1)
Block(-8,20,-7,FENCE:0)
Block(-8,20,-4,IRON_FENCE:0)
Block(-8,20,1,FENCE:0)
Block(-8,20,2,LOG:1)
Block(-8,20,3,FENCE:0)
Block(-8,20,5,WOOD_STEP:5)
Block(-8,21,-7,TORCH:5)
Block(-8,21,1,TORCH:5)
Block(-8,21,2,LOG:13)
Block(-8,21,3,TORCH:5)
Block(-8,22,2,LOG:1)
Block(-8,23,2,LOG:1)
Block(-8,24,2,LOG:1)
Block(-8,25,2,LOG:1)
Block(-8,26,-7,FENCE:0)
Block(-8,26,-6,FENCE:0)
Block(-8,26,-5,FENCE:0)
Block(-8,26,2,LOG:13)
Block(-8,27,-5,FENCE:0)
Block(-8,27,-4,FENCE:0)
Block(-8,27,-3,FENCE:0)
Block(-8,27,2,LOG:1)
Block(-8,28,-3,FENCE:0)
Block(-8,28,-2,FENCE:0)
Block(-8,28,-1,FENCE:0)
Block(-8,28,2,LOG:1)
Block(-8,28,4,WOOD:5)
Block(-8,28,5,FENCE:0)
Block(-8,29,-1,FENCE:0)
Block(-8,29,0,FENCE:0)
Block(-8,29,1,FENCE:0)
Block(-8,29,2,LOG:1)
Block(-8,29,4,WOOD_STEP:1)
Block(-8,29,5,WOOD:5)
Block(-8,29,6,FENCE:0)
Block(-8,30,2,LOG:1)
Block(-8,30,3,FENCE:0)
Block(-8,30,5,WOOD_STEP:1)
Block(-8,30,6,WOOD:5)
Block(-8,30,7,FENCE:0)
Block(-8,31,-6,WOOD:5)
Block(-8,31,-5,FENCE:0)
Block(-8,31,2,LOG:13)
Block(-8,31,3,TORCH:5)
Block(-8,31,6,WOOD_STEP:1)
Block(-8,31,7,WOOD:5)
Block(-8,32,-7,DARK_OAK_STAIRS:7)
Block(-8,32,-6,WOOD_STEP:1)
Block(-8,32,-5,WOOD:5)
Block(-8,32,-4,FENCE:0)
Block(-8,32,2,LOG:1)
Block(-8,32,7,WOOD_STEP:1)
Block(-8,33,-7,FENCE:0)
Block(-8,33,-5,WOOD_STEP:1)
Block(-8,33,-4,WOOD:5)
Block(-8,33,-3,FENCE:0)
Block(-8,33,1,DARK_OAK_STAIRS:6)
Block(-8,33,2,LOG:1)
Block(-8,33,3,DARK_OAK_STAIRS:7)
Block(-8,34,-4,WOOD_STEP:1)
Block(-8,34,-3,WOOD:5)
Block(-8,34,1,FENCE:0)
Block(-8,34,2,LOG:1)
Block(-8,34,3,FENCE:0)
Block(-8,35,-3,WOOD_STEP:1)
Block(-8,35,2,LOG:1)
Block(-8,36,-7,FENCE:0)
Block(-8,36,2,COBBLE_WALL:0)
Block(-8,37,-7,TORCH:5)
Block(-8,37,2,COBBLE_WALL:0)
Block(-8,38,-6,FENCE:0)
Block(-8,38,2,DARK_OAK_FENCE:0)
Block(-8,38,6,WOOL:11)
Block(-8,38,7,WOOL:15)
Block(-8,39,-6,WOOD:5)
Block(-8,39,-5,FENCE:0)
Block(-8,39,2,DARK_OAK_FENCE:0)
Block(-8,39,3,WOOL:15)
Block(-8,40,-6,WOOD_STEP:1)
Block(-8,40,-5,WOOD:5)
Block(-8,40,2,DARK_OAK_FENCE:0)
Block(-8,41,-5,WOOD_STEP:1)
RandomBlock(-8,41,2,STANDING_BANNER:9,../../Banners/royal_01.nbt,20,STANDING_BANNER:9,../../Banners/royal_02.nbt,20,STANDING_BANNER:9,../../Banners/royal_03.nbt,20,STANDING_BANNER:9,../../Banners/royal_04.nbt,20,STANDING_BANNER:9,../../Banners/royal_05.nbt,100)
Block(-8,44,-4,WOOL:11)
Block(-8,44,-3,WOOL:15)
Block(-8,45,-7,WOOL:15)
Block(-7,4,-7,LOG:13)
Block(-7,4,-6,LOG:13)
Block(-7,4,-5,LOG:13)
Block(-7,4,-4,LOG:13)
Block(-7,4,-3,LOG:13)
Block(-7,5,-7,LOG:13)
Block(-7,5,-6,LOG:13)
Block(-7,5,-5,LOG:13)
Block(-7,5,-4,LOG:13)
Block(-7,5,-3,LOG:13)
Block(-7,5,-2,LOG:13)
Block(-7,5,-1,LOG:13)
Block(-7,5,0,LOG:13)
Block(-7,6,-7,CAULDRON:3)
Block(-7,6,-6,CAULDRON:3)
Block(-7,6,-5,CAULDRON:3)
Block(-7,6,-4,CAULDRON:3)
Block(-7,6,-3,LOG:13)
Block(-7,6,-2,WOOD_STAIRS:0)
Block(-7,6,-1,WOOD_STAIRS:0)
Block(-7,6,0,LOG:13)
Block(-7,6,1,LOG:13)
Block(-7,6,2,LOG:13)
Block(-7,7,-7,CAULDRON:3)
Block(-7,7,-6,AIR:0)
Block(-7,7,-5,AIR:0)
Block(-7,7,-4,CAULDRON:3)
Block(-7,7,-3,LOG:13)
Block(-7,7,-2,AIR:0)
Block(-7,7,-1,AIR:0)
Block(-7,7,0,WOOD_STAIRS:0)
Block(-7,7,1,DARK_OAK_FENCE:0)
Block(-7,7,2,LOG:13)
Block(-7,8,-7,AIR:0)
Block(-7,8,-6,AIR:0)
Block(-7,8,-5,AIR:0)
Block(-7,8,-4,AIR:0)
Block(-7,8,-3,WOOD:5)
Block(-7,8,-2,AIR:0)
Block(-7,8,-1,AIR:0)
Block(-7,8,0,AIR:0)
Block(-7,8,1,DARK_OAK_FENCE:0)
Block(-7,8,2,WOOD:5)
Block(-7,9,-7,WOOD_STEP:1)
Block(-7,9,-6,WOOD_DOUBLE_STEP:1)
Block(-7,9,-5,WOOD_DOUBLE_STEP:1)
Block(-7,9,-4,WOOD_DOUBLE_STEP:1)
Block(-7,9,-3,WOOD_DOUBLE_STEP:1)
Block(-7,9,-2,WOOD_STEP:9)
Block(-7,9,-1,WOOD_STEP:9)
Block(-7,9,0,WOOD_STEP:9)
Block(-7,9,1,DARK_OAK_FENCE:0)
Block(-7,9,2,DARK_OAK_FENCE:0)
Block(-7,9,3,LOG:13)
Block(-7,10,-5,CARPET:13)
RandomBlock(-7,10,-4,AIR:0,20,CHEST:2,../../../../Chests/Loot/ShipJunk_1.nbt,10,CHEST:2,../../../../Chests/Loot/ShipJunk_2.nbt,10,CHEST:2,../../../../Chests/Loot/ShipJunk_3.nbt,10,CHEST:2,../../../../Chests/Loot/ShipJunk_4.nbt,10,CHEST:2,../../../../Chests/Loot/ShipJunk_5.nbt,10,CHEST:2,../../../../Chests/Traveler/Travelers_Castle.nbt,1,CHEST:2,../../../../Chests/Traveler/Travelers_Church.nbt,1,CHEST:2,../../../../Chests/Traveler/Travelers_Daeroc.nbt,1,CHEST:2,../../../../Chests/Traveler/Travelers_Farmsteads.nbt,1,CHEST:2,../../../../Chests/Traveler/Travelers_GreenDungeon.nbt,1,CHEST:2,../../../../Chests/Traveler/Travelers_IceShips.nbt,1,CHEST:2,../../../../Chests/Traveler/Travelers_IceTemple.nbt,1,CHEST:2,../../../../Chests/Traveler/Travelers_LegacySpawn.nbt,1,CHEST:2,../../../../Chests/Traveler/Travelers_Mineshafts.nbt,1,CHEST:2,../../../../Chests/Traveler/Travelers_Mountains.nbt,1,CHEST:2,../../../../Chests/Traveler/Travelers_Origin.nbt,1,CHEST:2,../../../../Chests/Traveler/Travelers_Pirate.nbt,1,CHEST:2,../../../../Chests/Traveler/Travelers_Quarry.nbt,1,CHEST:2,../../../../Chests/Traveler/Travelers_Spook.nbt,1,CHEST:2,../../../../Chests/Traveler/Travelers_Tribal.nbt,1,CHEST:2,../../../../Chests/Lore/ShipFloat_1.nbt,1,CHEST:2,../../../../Chests/Lore/ShipFloat_2.nbt,1,CHEST:2,../../../../Chests/Lore/ShipFloat_3.nbt,1,CHEST:2,../../../../Chests/Lore/ShipFloat_4.nbt,1,CHEST:2,../../../../Chests/Lore/ShipFloat_5.nbt,1,CHEST:2,../../../../Chests/Loot/Common1.nbt,10,CHEST:2,../../../../Chests/Loot/Common2.nbt,10,CHEST:2,../../../../Chests/Loot/Common3.nbt,10,CHEST:2,../../../../Chests/Loot/Common4.nbt,10,CHEST:2,../../../../Chests/Loot/Common5.nbt,10,CHEST:2,../../../../Chests/Loot/Common6.nbt,10,CHEST:2,../../../../Chests/Loot/Common7.nbt,10,CHEST:2,../../../../Chests/Loot/Common8.nbt,10,CHEST:2,../../../../Chests/Loot/Common9.nbt,10,CHEST:2,../../../../Chests/Loot/Common10.nbt,10,CHEST:2,../../../../Chests/Loot/Common10.nbt,11,CHEST:2,../../../../Chests/Loot/Common12.nbt,10,CHEST:2,../../../../Chests/Loot/Common13.nbt,10,CHEST:2,../../../../Chests/Loot/Common14.nbt,10,CHEST:2,../../../../Chests/Loot/Common15.nbt,10,CHEST:2,../../../../Chests/Lore/ShipFloat_1.nbt,2,CHEST:2,../../../../Chests/Lore/ShipFloat_3.nbt,2,CHEST:2,../../../../Chests/Lore/ShipFloat_4.nbt,2,CHEST:2,../../../../Chests/Lore/ShipFloat_5.nbt,2,CHEST:2,../../../../Chests/Lore/ShipFloat_5.nbt,2,CHEST:2,../../../../Chests/Loot/Rare1.nbt,5,CHEST:2,../../../../Chests/Loot/Rare2.nbt,5,CHEST:2,../../../../Chests/Loot/Rare3.nbt,5,CHEST:2,../../../../Chests/Loot/Rare4.nbt,5,CHEST:2,../../../../Chests/Loot/Rare5.nbt,5,CHEST:2,../../../../Chests/Loot/Rare6.nbt,5,CHEST:2,../../../../Chests/Loot/Rare7.nbt,5,CHEST:2,../../../../Chests/Loot/Rare8.nbt,5,CHEST:2,../../../../Chests/Loot/Rare9.nbt,5,CHEST:2,../../../../Chests/Loot/Rare10.nbt,5,CHEST:2,../../../../Chests/Loot/Rare11.nbt,5,CHEST:2,../../../../Chests/Loot/Rare12.nbt,5,CHEST:2,../../../../Chests/Loot/Rare13.nbt,5,CHEST:2,../../../../Chests/Loot/Rare14.nbt,5,CHEST:2,../../../../Chests/Loot/Rare15.nbt,5,CHEST:2,../../../../Chests/Loot/Epic1.nbt,2,CHEST:2,../../../../Chests/Loot/Epic2.nbt,2,CHEST:2,../../../../Chests/Loot/Epic3.nbt,2,CHEST:2,../../../../Chests/Loot/Epic4.nbt,2,CHEST:2,../../../../Chests/Loot/Epic5.nbt,2,CHEST:2,../../../../Chests/Loot/Epic6.nbt,2,CHEST:2,../../../../Chests/Loot/Epic7.nbt,2,CHEST:2,../../../../Chests/Loot/Epic8.nbt,2,CHEST:2,../../../../Chests/Loot/Epic9.nbt,2,CHEST:2,../../../../Chests/Loot/Epic10.nbt,2,CHEST:2,../../../../Chests/Loot/Epic11.nbt,2,CHEST:2,../../../../Chests/Loot/Epic12.nbt,2,CHEST:2,../../../../Chests/Loot/Epic13.nbt,2,CHEST:2,../../../../Chests/Loot/Epic14.nbt,2,CHEST:2,../../../../Chests/Loot/Epic15.nbt,5,CHEST:2,../../../../Chests/Loot/Rare1.nbt,5,CHEST:2,../../../../Chests/Loot/Rare2.nbt,5,CHEST:2,../../../../Chests/Loot/Rare3.nbt,5,CHEST:2,../../../../Chests/Loot/Rare4.nbt,5,CHEST:2,../../../../Chests/Loot/Rare5.nbt,10,CHEST:2,../../../../Chests/Loot/Rare6.nbt,10,CHEST:2,../../../../Chests/Loot/Rare7.nbt,10,CHEST:2,../../../../Chests/Loot/Rare8.nbt,10,CHEST:2,../../../../Chests/Loot/Rare9.nbt,10,CHEST:2,../../../../Chests/Loot/Rare10.nbt,15,CHEST:2,../../../../Chests/Loot/Rare11.nbt,15,CHEST:2,../../../../Chests/Loot/Rare12.nbt,15,CHEST:2,../../../../Chests/Loot/Rare13.nbt,15,CHEST:2,../../../../Chests/Loot/Rare14.nbt,15,CHEST:2,../../../../Chests/Loot/Rare15.nbt,15,CHEST:2,../../../../Chests/Loot/Epic15.nbt,100)
Block(-7,10,-3,WOOD_DOUBLE_STEP:1)
Block(-7,10,-2,WOOD_STEP:1)
Block(-7,10,-1,WOOD_STEP:1)
Block(-7,10,0,WOOD_DOUBLE_STEP:1)
Block(-7,10,1,WOOD_DOUBLE_STEP:1)
Block(-7,10,2,WOOD_DOUBLE_STEP:1)
Block(-7,10,3,LOG:13)
Block(-7,11,-3,WOOD:0)
Block(-7,11,1,WOOD_STAIRS:2)
Block(-7,11,2,DISPENSER:1)
Block(-7,11,3,CONCRETE:15)
Block(-7,11,4,DISPENSER:3)
Block(-7,12,-7,WOOD_DOUBLE_STEP:1)
Block(-7,12,-6,WOOD_STEP:9)
Block(-7,12,-5,WOOD_STEP:9)
Block(-7,12,-4,WOOD_STEP:9)
Block(-7,12,-3,WOOD:0)
Block(-7,12,-2,AIR:0)
Block(-7,12,2,LEVER:6)
Block(-7,12,3,WOOD_STEP:13)
Block(-7,12,4,WOOD_STEP:13)
Block(-7,13,-7,CARPET:12)
Block(-7,13,-6,CARPET:12)
Block(-7,13,-5,WOOD:0)
Block(-7,13,-4,IRON_FENCE:0)
Block(-7,13,-3,WOOD_DOUBLE_STEP:1)
Block(-7,13,-2,WOOD_DOUBLE_STEP:1)
Block(-7,13,-1,WOOD_DOUBLE_STEP:1)
Block(-7,13,0,WOOD_STEP:9)
Block(-7,13,1,WOOD_STEP:9)
Block(-7,13,2,WOOD_STEP:9)
Block(-7,13,3,WOOD_STEP:9)
Block(-7,13,4,WOOD_STAIRS:7)
Block(-7,14,-7,AIR:0)
Block(-7,14,-5,WOOD:0)
Block(-7,14,-4,IRON_FENCE:0)
Block(-7,14,-3,WOOD:0)
Block(-7,14,-2,WOOD:0)
Block(-7,14,-1,WOOD:0)
Block(-7,14,0,CARPET:13)
Block(-7,14,1,CARPET:15)
Block(-7,14,2,WOOD_STAIRS:2)
Block(-7,14,3,DISPENSER:1)
Block(-7,14,4,CONCRETE:15)
Block(-7,14,5,DISPENSER:3)
Block(-7,15,-7,WOOD_STEP:1)
Block(-7,15,-6,WOOD_DOUBLE_STEP:1)
Block(-7,15,-5,WOOD_DOUBLE_STEP:1)
Block(-7,15,-4,IRON_FENCE:0)
Block(-7,15,-3,WOOD:0)
Block(-7,15,-2,WOOD:0)
Block(-7,15,-1,WOOD:0)
Block(-7,15,3,LEVER:6)
Block(-7,15,4,WOOD_STEP:13)
Block(-7,15,5,WOOD_STEP:13)
Block(-7,16,-5,WOOD:5)
Block(-7,16,-4,IRON_FENCE:0)
Block(-7,16,-3,WOOD_DOUBLE_STEP:1)
Block(-7,16,-2,WOOD_DOUBLE_STEP:1)
Block(-7,16,-1,WOOD_DOUBLE_STEP:1)
Block(-7,16,0,WOOD_STEP:9)
Block(-7,16,1,WOOD_STEP:9)
Block(-7,16,2,WOOD_STEP:9)
Block(-7,16,3,WOOD_STEP:9)
Block(-7,16,4,WOOD_STEP:9)
Block(-7,16,5,WOOD_STAIRS:7)
Block(-7,16,6,WOOD_STEP:8)
Block(-7,17,-5,WOOD:5)
Block(-7,17,-4,IRON_FENCE:0)
Block(-7,17,-2,CARPET:14)
Block(-7,17,-1,CARPET:14)
Block(-7,17,0,BIRCH_WOOD_STAIRS:1)
Block(-7,17,1,CARPET:14)
Block(-7,17,2,CARPET:14)
Block(-7,17,3,CARPET:14)
Block(-7,17,4,WOOD:0)
Block(-7,17,5,WOOD:5)
Block(-7,17,6,FENCE:0)
Block(-7,18,-5,WOOD:5)
Block(-7,18,-4,DARK_OAK_STAIRS:5)
Block(-7,18,-3,WOOD_STEP:9)
Block(-7,18,4,WOOD_BUTTON:5)
Block(-7,18,5,WOOD:5)
Block(-7,19,-5,DARK_OAK_FENCE:0)
Block(-7,19,-4,IRON_FENCE:0)
Block(-7,19,-2,WOOD_STEP:1)
Block(-7,19,-1,WOOD_STEP:1)
Block(-7,19,0,WOOD_STEP:1)
Block(-7,19,1,WOOD_STEP:1)
Block(-7,19,2,WOOD_STEP:1)
Block(-7,19,3,WOOD_STEP:1)
Block(-7,19,4,WOOD_STEP:1)
Block(-7,19,5,WOOD:5)
Block(-7,19,6,FENCE:0)
Block(-7,19,7,FENCE:0)
Block(-7,20,-4,DARK_OAK_STAIRS:1)
Block(-7,20,5,WOOD_STEP:5)
Block(-7,20,7,FENCE:0)
Block(-7,20,8,FENCE:0)
Block(-7,21,5,WOOL:11)
Block(-7,21,6,WOOL:15)
Block(-7,21,7,WOOL:15)
Block(-7,21,8,WOOL:11)
Block(-7,22,4,WOOL:15)
Block(-7,22,7,WOOL:11)
Block(-7,22,8,FENCE:0)
Block(-7,23,6,WOOL:11)
Block(-7,23,7,FENCE:0)
Block(-7,24,-6,WOOL:15)
Block(-7,24,-3,WOOL:11)
Block(-7,24,-2,FENCE:0)
Block(-7,24,2,FENCE:0)
Block(-7,24,3,FENCE:0)
Block(-7,24,5,WOOL:11)
Block(-7,24,6,FENCE:0)
Block(-7,25,-7,WOOL:15)
Block(-7,25,-4,WOOL:11)
Block(-7,25,-3,FENCE:0)
Block(-7,25,1,WOOD:5)
Block(-7,25,2,FENCE:0)
Block(-7,25,3,FENCE:0)
Block(-7,25,5,WOOL:11)
Block(-7,25,6,FENCE:0)
Block(-7,26,-7,FENCE:0)
Block(-7,26,-5,WOOL:15)
Block(-7,26,-4,FENCE:0)
Block(-7,26,1,WOOD_STEP:1)
Block(-7,26,2,WOOD:5)
Block(-7,26,3,FENCE:0)
Block(-7,26,6,WOOL:11)
Block(-7,26,7,FENCE:0)
Block(-7,27,-7,FENCE:0)
Block(-7,27,-5,WOOL:11)
Block(-7,27,-4,FENCE:0)
Block(-7,27,2,WOOD_STEP:1)
Block(-7,27,3,WOOD:5)
Block(-7,27,4,FENCE:0)
Block(-7,28,-5,WOOL:15)
Block(-7,28,-4,FENCE:0)
Block(-7,28,3,WOOD_STEP:1)
Block(-7,28,4,WOOL:15)
Block(-7,29,-7,FENCE:0)
Block(-7,29,-4,WOOL:11)
Block(-7,29,-3,FENCE:0)
Block(-7,29,5,WOOL:11)
Block(-7,30,-7,WOOD:5)
Block(-7,30,-6,FENCE:0)
Block(-7,30,-3,WOOL:11)
Block(-7,30,-2,FENCE:0)
Block(-7,30,6,WOOL:11)
Block(-7,31,-7,WOOD_STEP:1)
Block(-7,31,-6,WOOL:11)
Block(-7,31,7,WOOL:11)
Block(-7,31,8,FENCE:0)
Block(-7,32,-7,DARK_OAK_STAIRS:7)
Block(-7,32,-5,WOOL:11)
Block(-7,33,-7,FENCE:0)
Block(-7,33,-4,WOOL:11)
Block(-7,33,1,DARK_OAK_STAIRS:5)
Block(-7,33,2,DARK_OAK_STAIRS:5)
Block(-7,33,3,DARK_OAK_STAIRS:5)
Block(-7,34,-5,WOOL:15)
Block(-7,34,-3,WOOL:11)
Block(-7,34,-2,FENCE:0)
Block(-7,34,1,FENCE:0)
Block(-7,34,2,FENCE:0)
Block(-7,34,3,FENCE:0)
Block(-7,35,-6,WOOL:11)
Block(-7,36,-6,WOOL:15)
Block(-7,37,-7,FENCE:0)
Block(-7,37,-5,WOOL:15)
Block(-7,38,-7,WOOD:5)
Block(-7,39,-7,WOOD_STEP:1)
Block(-7,39,-6,WOOL:15)
Block(-7,39,4,WOOL:11)
Block(-7,39,5,WOOL:11)
Block(-7,40,-5,WOOL:11)
Block(-7,45,-6,WOOL:11)
Block(-7,45,-5,WOOL:11)
Block(-6,4,-7,LOG:13)
Block(-6,5,-7,LOG:13)
Block(-6,5,-6,LOG:13)
Block(-6,5,-5,LOG:13)
Block(-6,5,-4,LOG:13)
Block(-6,6,-7,CAULDRON:3)
Block(-6,6,-6,CAULDRON:3)
Block(-6,6,-5,CAULDRON:3)
Block(-6,6,-4,CAULDRON:3)
Block(-6,6,-3,LOG:13)
Block(-6,6,-2,LOG:13)
Block(-6,6,-1,LOG:13)
Block(-6,7,-7,CAULDRON:3)
Block(-6,7,-6,CAULDRON:3)
Block(-6,7,-5,CAULDRON:3)
Block(-6,7,-4,CAULDRON:3)
Block(-6,7,-3,LOG:13)
Block(-6,7,-2,WOOD_STAIRS:0)
Block(-6,7,-1,WOOD_STAIRS:0)
Block(-6,7,0,LOG:13)
Block(-6,7,1,LOG:13)
Block(-6,8,-7,AIR:0)
Block(-6,8,-6,AIR:0)
Block(-6,8,-5,AIR:0)
Block(-6,8,-4,AIR:0)
Block(-6,8,-3,WOOD:5)
Block(-6,8,-2,AIR:0)
Block(-6,8,-1,AIR:0)
Block(-6,8,0,WOOD_STAIRS:0)
Block(-6,8,1,DARK_OAK_FENCE:0)
Block(-6,8,2,WOOD:5)
Block(-6,9,-7,WOOD_STEP:1)
Block(-6,9,-6,WOOD_DOUBLE_STEP:1)
Block(-6,9,-5,WOOD_DOUBLE_STEP:1)
Block(-6,9,-4,WOOD_DOUBLE_STEP:1)
Block(-6,9,-3,WOOD_DOUBLE_STEP:1)
Block(-6,9,-2,WOOD_STEP:9)
Block(-6,9,-1,WOOD_STEP:9)
Block(-6,9,0,WOOD_STEP:9)
Block(-6,9,1,DARK_OAK_FENCE:0)
Block(-6,9,2,DARK_OAK_FENCE:0)
Block(-6,9,3,LOG:13)
Block(-6,10,-6,CARPET:12)
Block(-6,10,-5,CARPET:12)
Block(-6,10,-4,CARPET:13)
Block(-6,10,-3,WOOD_DOUBLE_STEP:1)
Block(-6,10,-2,WOOD_STEP:1)
Block(-6,10,-1,WOOD_STEP:1)
Block(-6,10,0,WOOD_DOUBLE_STEP:1)
Block(-6,10,1,WOOD_DOUBLE_STEP:1)
Block(-6,10,2,WOOD_STEP:9)
Block(-6,10,3,LOG:13)
Block(-6,11,-7,AIR:0)
Block(-6,11,-3,WOOD:0)
Block(-6,11,-2,TRAP_DOOR:14)
Block(-6,11,2,WOOD_BUTTON:1)
Block(-6,11,3,LOG:13)
Block(-6,12,-7,WOOD_DOUBLE_STEP:1)
Block(-6,12,-6,WOOD_STEP:9)
Block(-6,12,-5,WOOD_STEP:9)
Block(-6,12,-4,WOOD_STEP:9)
Block(-6,12,-3,WOOD:0)
Block(-6,12,3,LOG:13)
Block(-6,13,-7,DARK_OAK_DOOR:2)
Block(-6,13,-6,WOOD:0)
Block(-6,13,-5,WOOD:0)
Block(-6,13,-4,WOOD:0)
Block(-6,13,-3,WOOD_DOUBLE_STEP:1)
Block(-6,13,-2,WOOD_STEP:1)
Block(-6,13,-1,WOOD_STEP:1)
Block(-6,13,0,WOOD_STEP:9)
Block(-6,13,1,WOOD_STEP:9)
Block(-6,13,2,WOOD_STEP:9)
Block(-6,13,3,WOOD_STEP:9)
Block(-6,13,4,WOOD_STAIRS:7)
Block(-6,14,-7,DARK_OAK_DOOR:8)
Block(-6,14,-6,WOOD:0)
Block(-6,14,-5,WOOD:0)
Block(-6,14,-4,WOOD:0)
Block(-6,14,-3,WOOD:0)
Block(-6,14,1,CARPET:13)
Block(-6,14,2,CARPET:13)
Block(-6,14,3,WOOD_BUTTON:1)
Block(-6,14,4,WOOD:0)
Block(-6,15,-7,WOOD_STEP:1)
Block(-6,15,-6,WOOD_DOUBLE_STEP:1)
Block(-6,15,-5,WOOD_DOUBLE_STEP:1)
Block(-6,15,-4,WOOD_DOUBLE_STEP:1)
Block(-6,15,-3,WOOD:0)
Block(-6,15,4,WOOD:0)
Block(-6,16,-6,FENCE:0)
Block(-6,16,-5,WOOD:5)
Block(-6,16,-4,WOOD_DOUBLE_STEP:1)
Block(-6,16,-3,WOOD_DOUBLE_STEP:1)
Block(-6,16,-2,WOOD_DOUBLE_STEP:1)
Block(-6,16,-1,WOOD_DOUBLE_STEP:1)
Block(-6,16,0,WOOD_STEP:9)
Block(-6,16,1,WOOD_STEP:9)
Block(-6,16,2,WOOD_STEP:9)
Block(-6,16,3,WOOD:0)
Block(-6,16,4,WOOD:0)
Block(-6,16,5,WOOD_STAIRS:7)
Block(-6,17,-6,TORCH:5)
Block(-6,17,-5,WOOD:5)
Block(-6,17,-4,WOOD_DOUBLE_STEP:1)
Block(-6,17,-3,WOOD_DOUBLE_STEP:1)
Block(-6,17,-2,CARPET:14)
Block(-6,17,-1,DARK_OAK_STAIRS:7)
Block(-6,17,0,WOOD_STEP:13)
Block(-6,17,1,JUKEBOX:0)
Block(-6,17,2,WOOD_DOUBLE_STEP:1)
Block(-6,17,3,WOOD:5)
Block(-6,17,4,WOOD:5)
Block(-6,17,5,WOOD:5)
Block(-6,18,-5,WOOD:5)
Block(-6,18,-4,WOOD_DOUBLE_STEP:1)
Block(-6,18,-3,WOOD_DOUBLE_STEP:1)
RandomBlock(-6,18,-1,FLOWER_POT:0,../../../../Flowers/flower_pot_01.nbt,5,FLOWER_POT:0,../../../../Flowers/flower_pot_02.nbt,5,FLOWER_POT:0,../../../../Flowers/flower_pot_03.nbt,5,FLOWER_POT:0,../../../../Flowers/flower_pot_04.nbt,5,FLOWER_POT:0,../../../../Flowers/flower_pot_05.nbt,5,FLOWER_POT:0,../../../../Flowers/flower_pot_06.nbt,5,FLOWER_POT:0,../../../../Flowers/flower_pot_07.nbt,5,FLOWER_POT:0,../../../../Flowers/flower_pot_08.nbt,5,FLOWER_POT:0,../../../../Flowers/flower_pot_09.nbt,5,FLOWER_POT:0,../../../../Flowers/flower_pot_10.nbt,5,FLOWER_POT:0,../../../../Flowers/flower_pot_11.nbt,5,FLOWER_POT:0,../../../../Flowers/flower_pot_12.nbt,5,FLOWER_POT:0,../../../../Flowers/flower_pot_13.nbt,5,FLOWER_POT:0,../../../../Flowers/flower_pot_14.nbt,5,FLOWER_POT:0,../../../../Flowers/flower_pot_15.nbt,5,FLOWER_POT:0,../../../../Flowers/flower_pot_16.nbt,5,FLOWER_POT:0,../../../../Flowers/flower_pot_17.nbt,5,FLOWER_POT:0,../../../../Flowers/flower_pot_18.nbt,5,FLOWER_POT:0,../../../../Flowers/flower_pot_19.nbt,5,FLOWER_POT:0,../../../../Flowers/flower_pot_20.nbt,100)
Block(-6,18,0,TORCH:5)
Block(-6,18,2,WOOD:5)
Block(-6,18,4,WOOD:5)
Block(-6,18,5,WOOD:5)
RandomBlock(-6,18,6,WALL_BANNER:3,../../Banners/royal_01.nbt,20,WALL_BANNER:3,../../Banners/royal_02.nbt,20,WALL_BANNER:3,../../Banners/royal_03.nbt,20,WALL_BANNER:3,../../Banners/royal_04.nbt,20,WALL_BANNER:3,../../Banners/royal_05.nbt,100)
Block(-6,19,-5,DARK_OAK_FENCE:0)
Block(-6,19,-2,WOOD_STEP:1)
Block(-6,19,-1,WOOD_STEP:1)
Block(-6,19,0,WOOD_STEP:1)
Block(-6,19,1,WOOD_STEP:1)
Block(-6,19,2,WOOD:5)
Block(-6,19,3,WOOD:5)
Block(-6,19,4,WOOD:5)
Block(-6,20,2,WOOD_STEP:5)
Block(-6,20,3,WOOD_STEP:5)
Block(-6,20,4,WOOD_STEP:5)
Block(-6,21,-3,WOOD:5)
Block(-6,21,-2,FENCE:0)
Block(-6,21,-1,WOOL:11)
Block(-6,21,0,WOOL:11)
Block(-6,21,2,FENCE:0)
Block(-6,21,3,FENCE:0)
Block(-6,21,4,FENCE:0)
Block(-6,22,-3,WOOD_STEP:1)
Block(-6,22,-2,WOOD:5)
Block(-6,22,-1,FENCE:0)
Block(-6,22,1,WOOL:11)
Block(-6,22,2,WOOL:15)
Block(-6,22,3,WOOL:11)
Block(-6,22,5,WOOL:11)
Block(-6,22,6,WOOL:11)
Block(-6,23,-2,WOOD_STEP:1)
Block(-6,23,-1,WOOD:5)
Block(-6,23,0,FENCE:0)
Block(-6,23,2,WOOL:11)
Block(-6,23,3,WOOL:11)
Block(-6,23,4,WOOL:11)
Block(-6,23,5,WOOL:11)
Block(-6,24,-7,FENCE:0)
Block(-6,24,-5,WOOL:15)
Block(-6,24,-4,WOOL:11)
Block(-6,24,-1,WOOD_STEP:1)
Block(-6,24,0,WOOD:5)
Block(-6,24,1,FENCE:0)
Block(-6,24,2,FENCE:0)
Block(-6,24,3,WOOL:11)
Block(-6,24,4,WOOL:11)
Block(-6,25,-7,FENCE:0)
Block(-6,25,-6,WOOL:11)
Block(-6,25,-5,WOOL:11)
Block(-6,25,0,WOOD_STEP:1)
Block(-6,25,1,WOOL:11)
Block(-6,25,4,WOOL:11)
Block(-6,26,-7,WOOL:11)
Block(-6,26,-6,WOOL:11)
Block(-6,26,2,WOOL:11)
Block(-6,26,5,WOOL:11)
Block(-6,27,-7,WOOL:11)
Block(-6,27,-6,WOOL:11)
Block(-6,27,3,WOOL:15)
Block(-6,27,4,WOOL:11)
Block(-6,27,5,WOOL:11)
Block(-6,27,6,WOOL:11)
Block(-6,27,7,FENCE:0)
Block(-6,28,-6,WOOL:11)
Block(-6,28,5,WOOL:11)
Block(-6,28,6,WOOL:11)
Block(-6,28,7,FENCE:0)
Block(-6,29,-6,WOOL:11)
Block(-6,29,-5,WOOL:11)
Block(-6,29,6,WOOL:11)
Block(-6,29,7,WOOL:11)
Block(-6,29,8,FENCE:0)
Block(-6,30,-7,WOOL:11)
Block(-6,30,-6,WOOL:11)
Block(-6,30,-5,WOOL:11)
Block(-6,30,-4,WOOL:11)
Block(-6,30,7,WOOL:15)
Block(-6,30,8,FENCE:0)
Block(-6,31,-5,WOOL:11)
Block(-6,31,-4,WOOL:11)
Block(-6,31,-3,WOOL:11)
Block(-6,31,-2,FENCE:0)
Block(-6,32,-4,WOOL:11)
Block(-6,32,-3,WOOL:15)
Block(-6,32,-2,FENCE:0)
Block(-6,33,-3,WOOL:11)
Block(-6,33,-2,FENCE:0)
Block(-6,34,-7,WOOL:11)
Block(-6,34,-6,WOOL:15)
Block(-6,35,-7,WOOL:11)
Block(-6,36,-7,WOOL:11)
Block(-6,37,-7,WOOL:11)
Block(-6,37,-6,WOOL:11)
Block(-6,38,-7,WOOL:15)
Block(-6,38,-6,WOOL:11)
Block(-6,38,-5,WOOL:15)
Block(-6,39,-5,WOOL:11)
Block(-5,5,-7,LOG:13)
Block(-5,5,-6,LOG:13)
Block(-5,6,-7,LOG:13)
Block(-5,6,-6,LOG:13)
Block(-5,6,-5,LOG:13)
Block(-5,6,-4,LOG:13)
Block(-5,6,-3,LOG:13)
Block(-5,7,-7,CAULDRON:3)
Block(-5,7,-6,CAULDRON:3)
Block(-5,7,-5,CAULDRON:3)
Block(-5,7,-4,CAULDRON:3)
Block(-5,7,-3,LOG:13)
Block(-5,7,-2,LOG:13)
Block(-5,7,-1,LOG:13)
Block(-5,8,-7,AIR:0)
Block(-5,8,-6,AIR:0)
Block(-5,8,-5,AIR:0)
Block(-5,8,-4,AIR:0)
Block(-5,8,-3,WOOD:5)
Block(-5,8,-2,WOOD_STAIRS:0)
Block(-5,8,-1,LOG:13)
Block(-5,8,0,LOG:13)
Block(-5,8,1,LOG:13)
Block(-5,9,-7,WOOD_STEP:1)
Block(-5,9,-6,WOOD_DOUBLE_STEP:1)
Block(-5,9,-5,WOOD_DOUBLE_STEP:1)
Block(-5,9,-4,WOOD_DOUBLE_STEP:1)
Block(-5,9,-3,WOOD_DOUBLE_STEP:1)
Block(-5,9,-2,WOOD_STEP:9)
Block(-5,9,-1,WOOD_DOUBLE_STEP:1)
Block(-5,9,0,LOG:13)
Block(-5,9,1,LOG:13)
Block(-5,9,2,LOG:13)
Block(-5,10,-5,WOOD_STAIRS:0)
Block(-5,10,-3,WOOD_DOUBLE_STEP:1)
Block(-5,10,-2,WOOD_DOUBLE_STEP:1)
Block(-5,10,-1,WOOD_DOUBLE_STEP:1)
Block(-5,10,0,WOOD_DOUBLE_STEP:1)
Block(-5,10,1,LOG:13)
Block(-5,10,2,LOG:13)
Block(-5,10,3,LOG:13)
Block(-5,11,-3,WOOD:0)
Block(-5,11,-2,REDSTONE_LAMP_ON:0)
Block(-5,11,-1,WOOD:0)
Block(-5,11,0,WOOD:0)
Block(-5,11,1,LOG:13)
Block(-5,11,2,LOG:13)
Block(-5,11,3,LOG:13)
Block(-5,12,-7,WOOD_DOUBLE_STEP:1)
Block(-5,12,-6,WOOD_STEP:9)
Block(-5,12,-5,WOOD_STEP:9)
Block(-5,12,-4,WOOD_STEP:9)
Block(-5,12,-3,WOOD:0)
Block(-5,12,-2,WOOD:0)
Block(-5,12,-1,WOOD:0)
Block(-5,12,0,WOOD:0)
Block(-5,12,1,WOOD:0)
Block(-5,12,2,LOG:13)
Block(-5,12,3,LOG:13)
Block(-5,13,-4,DARK_OAK_DOOR:1)
Block(-5,13,-3,WOOD_STEP:1)
Block(-5,13,-2,WOOD_STEP:1)
Block(-5,13,-1,WOOD_STEP:1)
Block(-5,13,0,WOOD_DOUBLE_STEP:1)
Block(-5,13,1,WOOD:0)
Block(-5,13,2,WOOD:0)
Block(-5,13,3,WOOD:0)
Block(-5,13,4,WOOD_STAIRS:7)
Block(-5,14,-4,DARK_OAK_DOOR:8)
Block(-5,14,0,WOOD:0)
Block(-5,14,1,WOOD:0)
Block(-5,14,2,WOOD:0)
Block(-5,14,3,WOOD:0)
Block(-5,14,4,WOOD:0)
Block(-5,15,-7,SPRUCE_WOOD_STAIRS:2)
Block(-5,15,-6,WOOD_DOUBLE_STEP:1)
Block(-5,15,-5,WOOD_DOUBLE_STEP:1)
Block(-5,15,-4,WOOD_STEP:9)
Block(-5,15,-3,WOOD_STEP:9)
Block(-5,15,0,WOOD:0)
Block(-5,15,1,WOOD:0)
Block(-5,15,2,WOOD:0)
Block(-5,15,3,WOOD:0)
Block(-5,16,-6,SPRUCE_WOOD_STAIRS:2)
Block(-5,16,-5,WOOD:5)
Block(-5,16,-4,WOOD:5)
Block(-5,16,-3,WOOD_DOUBLE_STEP:1)
Block(-5,16,-2,WOOD_DOUBLE_STEP:1)
Block(-5,16,-1,WOOD_DOUBLE_STEP:1)
Block(-5,16,0,WOOD:0)
Block(-5,16,1,WOOD:0)
Block(-5,16,2,WOOD:0)
Block(-5,17,-5,SPRUCE_WOOD_STAIRS:2)
Block(-5,17,-4,WOOD:5)
Block(-5,17,-2,CARPET:14)
Block(-5,17,-1,WOOD:5)
Block(-5,17,0,WOOD:5)
Block(-5,17,1,WOOD:5)
Block(-5,17,2,WOOD:5)
Block(-5,18,-4,SPRUCE_WOOD_STAIRS:2)
Block(-5,18,-3,WOOD_STEP:9)
Block(-5,18,-1,WOOD:5)
Block(-5,18,0,WOOD_STEP:9)
Block(-5,18,1,WOOD:5)
Block(-5,18,2,DARK_OAK_STAIRS:5)
Block(-5,18,3,WOOD_STEP:13)
Block(-5,18,4,DARK_OAK_STAIRS:5)
Block(-5,19,-2,WOOD_STEP:1)
Block(-5,19,-1,WOOD_STEP:5)
Block(-5,19,0,DARK_OAK_STAIRS:2)
Block(-5,19,1,WOOD:5)
Block(-5,19,2,FENCE:0)
Block(-5,19,3,FENCE:0)
Block(-5,19,4,FENCE:0)
Block(-5,20,1,WOOD_STEP:5)
Block(-5,20,2,FENCE:0)
Block(-5,20,3,FENCE:0)
Block(-5,20,4,FENCE:0)
Block(-5,21,-3,WOOL:11)
Block(-5,21,-2,WOOL:11)
Block(-5,21,2,FENCE:0)
Block(-5,21,3,FENCE:0)
Block(-5,21,4,FENCE:0)
Block(-5,22,-2,WOOL:11)
Block(-5,22,-1,WOOL:11)
Block(-5,22,0,WOOL:11)
Block(-5,23,-7,FENCE:0)
Block(-5,23,-6,FENCE:0)
Block(-5,23,-1,WOOL:15)
Block(-5,23,0,WOOL:11)
Block(-5,23,1,WOOL:11)
Block(-5,24,-7,FENCE:0)
Block(-5,24,-6,FENCE:0)
Block(-5,24,0,WOOL:11)
Block(-5,24,1,WOOL:11)
Block(-5,24,2,WOOL:11)
Block(-5,25,2,WOOL:11)
Block(-5,25,3,WOOL:11)
Block(-5,26,3,WOOL:11)
Block(-5,26,4,WOOL:11)
Block(-5,28,-7,WOOL:11)
Block(-5,29,-7,WOOL:11)
Block(-4,6,-7,LOG:13)
Block(-4,6,-6,LOG:13)
Block(-4,7,-7,LOG:13)
Block(-4,7,-6,LOG:13)
Block(-4,7,-5,LOG:13)
Block(-4,7,-4,LOG:13)
Block(-4,8,-7,WOOD:5)
Block(-4,8,-6,WOOD:5)
Block(-4,8,-5,WOOD:5)
Block(-4,8,-4,WOOD:5)
Block(-4,8,-3,LOG:13)
Block(-4,8,-2,LOG:13)
Block(-4,9,-7,WOOD_STEP:1)
Block(-4,9,-6,WOOD_DOUBLE_STEP:1)
Block(-4,9,-5,WOOD_DOUBLE_STEP:1)
Block(-4,9,-4,WOOD_DOUBLE_STEP:1)
Block(-4,9,-3,WOOD:0)
Block(-4,9,-2,WOOD:0)
Block(-4,9,-1,LOG:13)
Block(-4,10,-6,WOOD_BUTTON:4)
Block(-4,10,-5,DISPENSER:9)
Block(-4,10,-4,WOOD_BUTTON:3)
Block(-4,10,-3,WOOD_DOUBLE_STEP:1)
Block(-4,10,-2,WOOD:0)
Block(-4,10,-1,WOOD:0)
Block(-4,10,0,LOG:13)
Block(-4,11,-5,LEVER:14)
Block(-4,11,-3,WOOD:0)
Block(-4,11,-2,REDSTONE_BLOCK:0)
Block(-4,11,-1,WOOD:0)
Block(-4,11,0,WOOD:0)
Block(-4,12,-7,WOOD_DOUBLE_STEP:1)
Block(-4,12,-6,WOOD_STEP:9)
Block(-4,12,-5,WOOD_STEP:9)
Block(-4,12,-4,WOOD_STEP:9)
Block(-4,12,-3,WOOD:0)
Block(-4,12,-2,WOOD:0)
Block(-4,12,-1,WOOD:0)
Block(-4,12,0,WOOD:0)
Block(-4,12,1,WOOD:0)
Block(-4,13,-7,SPRUCE_WOOD_STAIRS:3)
Block(-4,13,-5,FENCE:0)
Block(-4,13,-4,WOOD_DOUBLE_STEP:1)
Block(-4,13,-3,WOOD_DOUBLE_STEP:1)
Block(-4,13,-2,WOOD:0)
Block(-4,13,-1,WOOD:0)
Block(-4,13,0,WOOD:0)
Block(-4,14,-5,TORCH:5)
Block(-4,14,-4,WOOD_DOUBLE_STEP:1)
Block(-4,14,-3,WOOD:0)
Block(-4,14,-2,WOOD:0)
Block(-4,14,-1,WOOD:0)
Block(-4,14,0,WOOD:0)
Block(-4,15,-5,WOOD_STEP:9)
Block(-4,15,-4,WOOD_DOUBLE_STEP:1)
Block(-4,15,-3,WOOD:0)
Block(-4,15,-2,WOOD:0)
Block(-4,15,-1,WOOD:0)
Block(-4,16,-5,WOOD:5)
Block(-4,16,-4,WOOD:5)
Block(-4,16,-3,WOOD:5)
Block(-4,16,-2,WOOD:5)
Block(-4,16,-1,WOOD:5)
Block(-4,17,-5,WOOD:5)
Block(-4,17,-4,WOOD:5)
Block(-4,17,-3,WOOD_STEP:1)
Block(-4,17,-2,WOOD:5)
Block(-4,17,2,TRAP_DOOR:15)
Block(-4,18,-5,WOOD_DOUBLE_STEP:5)
Block(-4,18,-4,WOOD_DOUBLE_STEP:5)
Block(-4,18,-3,WOOD_DOUBLE_STEP:5)
Block(-4,18,-2,WOOD:5)
RandomBlock(-4,18,-1,WALL_BANNER:5,../../Banners/royal_01.nbt,20,WALL_BANNER:5,../../Banners/royal_02.nbt,20,WALL_BANNER:5,../../Banners/royal_03.nbt,20,WALL_BANNER:5,../../Banners/royal_04.nbt,20,WALL_BANNER:5,../../Banners/royal_05.nbt,100)
Block(-4,18,1,TRAP_DOOR:7)
Block(-4,19,-5,DARK_OAK_FENCE:0)
Block(-4,19,-4,DARK_OAK_FENCE:0)
Block(-4,19,-3,DARK_OAK_FENCE:0)
Block(-4,19,-2,WOOD_STEP:5)
Block(-4,19,1,TRAP_DOOR:7)
Block(-4,21,-7,FENCE:0)
Block(-4,21,-6,FENCE:0)
Block(-4,21,-5,FENCE:0)
Block(-4,22,-7,FENCE:0)
Block(-4,22,-6,FENCE:0)
Block(-4,22,-5,FENCE:0)
Block(-4,23,-7,FENCE:0)
Block(-4,23,-6,FENCE:0)
Block(-3,7,-7,LOG:13)
Block(-3,8,-7,WOOD:5)
Block(-3,8,-6,WOOD:5)
Block(-3,8,-5,WOOD:5)
Block(-3,9,-7,WOOD_STEP:1)
Block(-3,9,-6,WOOD:0)
Block(-3,9,-5,WOOD:0)
Block(-3,9,-4,WOOD:0)
Block(-3,10,-6,WOOD:0)
Block(-3,10,-5,CONCRETE:15)
Block(-3,10,-4,WOOD:0)
Block(-3,10,-3,WOOD:0)
Block(-3,11,-4,WOOD:0)
Block(-3,11,-3,WOOD:0)
Block(-3,11,-2,WOOD:0)
Block(-3,12,-7,WOOD_DOUBLE_STEP:1)
Block(-3,12,-6,WOOD:0)
Block(-3,12,-5,WOOD:0)
Block(-3,12,-4,WOOD:0)
Block(-3,12,-3,WOOD:0)
Block(-3,13,-7,WOOD:0)
Block(-3,13,-6,WOOD:0)
Block(-3,13,-5,WOOD:0)
Block(-3,13,-4,WOOD:0)
Block(-3,13,-3,WOOD:0)
Block(-3,14,-7,WOOD:0)
Block(-3,14,-6,WOOD:0)
Block(-3,14,-5,WOOD:0)
Block(-3,14,-4,WOOD:0)
Block(-3,15,-7,WOOD:5)
Block(-3,15,-6,WOOD:0)
Block(-3,15,-5,WOOD:0)
Block(-3,15,-4,WOOD:0)
Block(-3,16,-7,WOOD:5)
Block(-3,16,-6,WOOD:5)
Block(-3,16,-5,WOOD:5)
Block(-3,16,-4,WOOD_STEP:13)
Block(-3,16,-1,TRAP_DOOR:7)
Block(-3,17,-7,WOOD:5)
Block(-3,17,-6,WOOD:5)
Block(-3,17,-5,WOOD:5)
Block(-3,17,-4,FENCE:0)
Block(-3,17,-2,TRAP_DOOR:7)
Block(-3,18,-7,WOOD_STEP:5)
Block(-3,18,-6,WOOD_STEP:5)
Block(-3,18,-5,DARK_OAK_STAIRS:1)
Block(-3,18,-4,FENCE:0)
Block(-3,18,-3,TRAP_DOOR:7)
Block(-3,18,-2,TRAP_DOOR:7)
Block(-3,19,-7,FENCE:0)
Block(-3,19,-6,FENCE:0)
Block(-3,19,-5,FENCE:0)
Block(-3,19,-4,FENCE:0)
Block(-3,20,-7,FENCE:0)
Block(-3,20,-6,FENCE:0)
Block(-3,20,-5,FENCE:0)
Block(-3,21,-7,FENCE:0)
Block(-3,21,-6,FENCE:0)
Block(-3,21,-5,FENCE:0)
Block(-2,9,-7,WOOD:0)
Block(-2,10,-7,WOOD:0)
Block(-2,10,-5,DISPENSER:5)
Block(-2,11,-7,WOOD:0)
Block(-2,11,-6,WOOD:0)
Block(-2,11,-5,WOOD_STEP:13)
Block(-2,12,-7,WOOD:0)
Block(-2,13,-7,WOOD:0)
Block(-2,16,-7,DARK_OAK_STAIRS:5)
Block(-2,16,-6,WOOD_STEP:13)
Block(-2,16,-5,DARK_OAK_STAIRS:5)
Block(-2,17,-7,FENCE:0)
Block(-2,17,-6,FENCE:0)
Block(-2,17,-5,FENCE:0)
Block(-2,18,-7,FENCE:0)
Block(-2,18,-6,FENCE:0)
Block(-2,18,-5,FENCE:0)
Block(-2,19,-7,FENCE:0)
Block(-2,19,-6,FENCE:0)
Block(-2,19,-5,FENCE:0)
Branch(-16,0,0,true,Royal_FloatC0R3,NORTH,100.0,0)
Entity(-8,15,1,minecraft:villager,1)
Entity(-8,18,1,minecraft:villager,1,../../NPCs/ShipCaptain.txt)
Entity(-7,12,-2,minecraft:villager,1)
Entity(-7,14,-7,minecraft:villager,1)
Entity(-6,11,-7,minecraft:villager,1)
