Author: NLBlackEagle
Description: No description given
SettingsMode: WriteDisable
Frequency: 0
SpawnHeight: highestBlock
UseCenterForHighestBlock: true
MinHeight: 0
MaxHeight: 255
InheritBO3: 
InheritBO3Rotation: NORTH
OverrideChildSettings: true
OverrideParentHeight: false
CanOverride: false
BranchFrequency: 0
BranchFrequencyGroup: 
MustBeBelowOther: false
MustBeInside: 
CannotBeInside: 
ReplacesBO3: 
MustBeInsideWorldBorders: false
CanSpawnOnWater: true
SpawnOnWaterOnly: false
SpawnUnderWater: false
SpawnAtWaterLevel: false
HeightOffset: 0
RemoveAir: false
ReplaceAbove: 
ReplaceBelow: 
ReplaceWithBiomeBlocks: false
ReplaceWithSurfaceBlock: GRASS
ReplaceWithGroundBlock: DIRT
ReplaceWithStoneBlock: STONE
SmoothRadius: 0
SmoothHeightOffset: 0
SmoothStartTop: false
SmoothStartWood: false
SmoothingSurfaceBlock: 
SmoothingGroundBlock: 
BO3Group: 
IsSpawnPoint: false
DoReplaceBlocks: false
Block(3,9,-7,WOOD_BUTTON:2)
Block(4,8,-7,WOOD:5)
Block(4,8,-5,TRAP_DOOR:10)
Block(4,9,-7,WOOD:5)
Block(4,9,-6,WOOD_BUTTON:2)
Block(4,9,-5,WOOD_BUTTON:2)
Block(4,9,-4,WOOD_BUTTON:2)
Block(4,9,-3,WOOD_BUTTON:2)
Block(4,9,-2,WOOD_BUTTON:2)
Block(4,9,-1,WOOD_BUTTON:2)
Block(4,10,-7,DARK_OAK_STAIRS:3)
Block(4,11,-6,TRAP_DOOR:10)
Block(4,13,-6,DARK_OAK_STAIRS:4)
Block(4,13,-5,WOOD_STEP:13)
Block(4,13,-4,DARK_OAK_STAIRS:4)
Block(4,13,-1,STONE_BUTTON:2)
Block(4,13,2,STONE_BUTTON:2)
Block(4,14,-6,SPRUCE_FENCE:0)
Block(4,14,-5,SPRUCE_FENCE:0)
Block(4,14,-4,SPRUCE_FENCE:0)
Block(4,14,-1,STONE_BUTTON:2)
Block(4,14,2,STONE_BUTTON:2)
Block(4,15,-6,SPRUCE_FENCE:0)
Block(4,15,-5,SPRUCE_FENCE:0)
Block(4,15,-4,SPRUCE_FENCE:0)
Block(4,23,-5,WOOL:14)
Block(4,23,-4,WOOL:14)
Block(4,33,-5,WOOL:14)
Block(4,33,-4,WOOL:14)
Block(5,6,-7,LOG_2:13)
Block(5,6,-6,LOG_2:13)
Block(5,6,-5,LOG_2:13)
Block(5,6,-4,LOG_2:13)
Block(5,7,-7,WOOD:5)
Block(5,7,-6,WOOD:5)
Block(5,7,-5,WOOD:5)
Block(5,7,-4,WOOD:5)
Block(5,7,-3,WOOD:5)
Block(5,8,-7,STONE_BUTTON:3)
Block(5,8,-6,WOOD:5)
Block(5,8,-5,DISPENSER:4)
Block(5,8,-4,WOOD:5)
Block(5,8,-3,WOOD:5)
Block(5,8,-2,WOOD:5)
Block(5,9,-7,WOOD_STEP:5)
Block(5,9,-6,WOOD:5)
Block(5,9,-5,WOOD:5)
Block(5,9,-4,WOOD:5)
Block(5,9,-3,WOOD:5)
Block(5,9,-2,WOOD:5)
Block(5,9,-1,WOOD:5)
Block(5,9,0,WOOD_BUTTON:2)
Block(5,10,-7,CONCRETE:15)
Block(5,10,-6,CONCRETE:15)
Block(5,10,-5,WOOD:5)
Block(5,10,-4,WOOD:5)
Block(5,10,-3,WOOD:5)
Block(5,10,-2,WOOD:5)
Block(5,10,-1,WOOD:5)
Block(5,11,-7,CONCRETE:15)
Block(5,11,-6,DISPENSER:4)
Block(5,11,-5,CONCRETE:15)
Block(5,11,-4,WOOD:5)
Block(5,11,-3,WOOD:5)
Block(5,11,-2,WOOD:5)
Block(5,11,-1,WOOD:5)
Block(5,11,0,WOOD:5)
Block(5,12,-7,CONCRETE:15)
Block(5,12,-6,CONCRETE:15)
Block(5,12,-5,CONCRETE:15)
Block(5,12,-4,CONCRETE:15)
Block(5,12,-3,CONCRETE:15)
Block(5,12,-2,CONCRETE:15)
Block(5,12,-1,WOOD:5)
Block(5,12,0,WOOD:5)
Block(5,12,1,DARK_OAK_STAIRS:4)
Block(5,12,2,WOOD_STEP:13)
Block(5,13,-7,CONCRETE:15)
Block(5,13,-6,CONCRETE:15)
Block(5,13,-5,CONCRETE:15)
Block(5,13,-4,CONCRETE:15)
Block(5,13,-3,CONCRETE:15)
Block(5,13,-2,CONCRETE:15)
Block(5,13,-1,CONCRETE:15)
Block(5,13,0,ANVIL:0)
Block(5,13,1,ANVIL:0)
Block(5,13,2,CONCRETE:15)
Block(5,13,3,STONE_BUTTON:3)
Block(5,13,5,STONE_BUTTON:2)
Block(5,14,-7,CONCRETE:15)
Block(5,14,-6,CONCRETE:15)
Block(5,14,-5,CONCRETE:15)
Block(5,14,-4,CONCRETE:15)
Block(5,14,-3,CONCRETE:15)
Block(5,14,-2,CONCRETE:15)
Block(5,14,-1,CONCRETE:15)
Block(5,14,0,WOOD_STEP:5)
Block(5,14,1,WOOD_STEP:5)
Block(5,14,2,CONCRETE:15)
Block(5,14,3,STONE_BUTTON:3)
Block(5,14,5,STONE_BUTTON:2)
Block(5,15,-7,WOOD_STEP:5)
Block(5,15,-6,SPRUCE_FENCE:0)
Block(5,15,-5,SPRUCE_FENCE:0)
Block(5,15,-4,SPRUCE_FENCE:0)
Block(5,15,-3,WOOD_STEP:5)
Block(5,15,-2,WOOD_STEP:5)
Block(5,15,-1,DARK_OAK_STAIRS:2)
Block(5,15,0,DARK_OAK_STAIRS:0)
Block(5,15,1,DARK_OAK_STAIRS:0)
Block(5,15,2,DARK_OAK_STAIRS:3)
Block(5,16,-6,SPRUCE_FENCE:0)
Block(5,16,-5,SPRUCE_FENCE:0)
Block(5,16,-4,SPRUCE_FENCE:0)
Block(5,17,-6,SPRUCE_FENCE:0)
Block(5,17,-5,SPRUCE_FENCE:0)
Block(5,17,-4,SPRUCE_FENCE:0)
Block(5,23,-6,WOOL:14)
Block(5,24,-6,WOOL:14)
Block(5,31,-7,WOOL:14)
Block(5,32,-6,WOOL:14)
Block(5,33,-6,WOOL:14)
Block(6,5,-7,LOG_2:13)
Block(6,5,-6,LOG_2:13)
Block(6,5,-5,LOG_2:13)
Block(6,5,-4,LOG_2:13)
Block(6,6,-7,WOOD_DOUBLE_STEP:1)
Block(6,6,-5,WOOD_DOUBLE_STEP:1)
Block(6,6,-4,WOOD_DOUBLE_STEP:1)
Block(6,6,-3,LOG_2:13)
Block(6,6,-2,LOG_2:13)
Block(6,6,-1,LOG_2:13)
Block(6,7,-7,WOOD:5)
Block(6,7,-6,WOOD:5)
Block(6,7,-5,WOOD:5)
Block(6,7,-4,WOOD:5)
Block(6,7,-3,WOOD:5)
Block(6,7,-2,WOOD:5)
Block(6,7,-1,WOOD:5)
Block(6,8,-6,TRIPWIRE_HOOK:3)
Block(6,8,-5,CONCRETE:15)
Block(6,8,-4,CONCRETE:15)
Block(6,8,-3,BED_BLOCK:9)
Block(6,8,-2,CARPET:15)
Block(6,8,-1,WOOD:5)
Block(6,9,-6,WOOD_STEP:5)
Block(6,9,-5,WOOD_BUTTON:5)
Block(6,9,-4,CONCRETE:15)
Block(6,9,-3,BED_BLOCK:9)
Block(6,9,-1,WOOD_DOUBLE_STEP:5)
Block(6,9,0,WOOD:5)
Block(6,9,1,WOOD_BUTTON:2)
Block(6,10,-7,WOOD_STEP:13)
Block(6,10,-6,WOOD_STEP:13)
Block(6,10,-5,WOOD_STEP:13)
Block(6,10,-4,WOOD_DOUBLE_STEP:5)
Block(6,10,-3,WOOD_STEP:13)
Block(6,10,-2,WOOD_STEP:13)
Block(6,10,-1,WOOD_DOUBLE_STEP:5)
Block(6,10,0,WOOD:5)
Block(6,10,1,WOOD:5)
Block(6,11,-7,TRIPWIRE_HOOK:3)
Block(6,11,-6,CONCRETE:15)
Block(6,11,-5,CONCRETE:15)
Block(6,11,-4,BED_BLOCK:9)
Block(6,11,-3,BED_BLOCK:9)
Block(6,11,-2,BED_BLOCK:9)
Block(6,11,-1,CONCRETE:15)
Block(6,11,0,BOOKSHELF:0)
Block(6,11,1,WOOD:5)
Block(6,11,2,WOOD:5)
Block(6,12,-6,WOOD_BUTTON:5)
Block(6,12,-5,CONCRETE:15)
Block(6,12,-1,CONCRETE:15)
Block(6,12,0,BOOKSHELF:0)
Block(6,12,1,BOOKSHELF:0)
Block(6,12,2,WOOD_DOUBLE_STEP:5)
Block(6,12,3,DARK_OAK_STAIRS:7)
Block(6,12,4,DARK_OAK_STAIRS:4)
Block(6,12,5,DARK_OAK_STAIRS:4)
Block(6,13,-7,CONCRETE:15)
Block(6,13,-6,CONCRETE:15)
Block(6,13,-5,CONCRETE:15)
RandomBlock(6,13,-3,WALL_BANNER:5,../../Banners/skullpillager_01.nbt,20,WALL_BANNER:5,../../Banners/skullpillager_02.nbt,20,WALL_BANNER:5,../../Banners/skullpillager_03.nbt,20,WALL_BANNER:5,../../Banners/skullpillager_04.nbt,20,WALL_BANNER:5,../../Banners/skullpillager_05.nbt,100)
Block(6,13,-1,CONCRETE:15)
RandomBlock(6,13,1,FLOWER_POT:0,../../../../Flowers/flower_pot_01.nbt,5,FLOWER_POT:0,../../../../Flowers/flower_pot_02.nbt,5,FLOWER_POT:0,../../../../Flowers/flower_pot_03.nbt,5,FLOWER_POT:0,../../../../Flowers/flower_pot_04.nbt,5,FLOWER_POT:0,../../../../Flowers/flower_pot_05.nbt,5,FLOWER_POT:0,../../../../Flowers/flower_pot_06.nbt,5,FLOWER_POT:0,../../../../Flowers/flower_pot_07.nbt,5,FLOWER_POT:0,../../../../Flowers/flower_pot_08.nbt,5,FLOWER_POT:0,../../../../Flowers/flower_pot_09.nbt,5,FLOWER_POT:0,../../../../Flowers/flower_pot_10.nbt,5,FLOWER_POT:0,../../../../Flowers/flower_pot_11.nbt,5,FLOWER_POT:0,../../../../Flowers/flower_pot_12.nbt,5,FLOWER_POT:0,../../../../Flowers/flower_pot_13.nbt,5,FLOWER_POT:0,../../../../Flowers/flower_pot_14.nbt,5,FLOWER_POT:0,../../../../Flowers/flower_pot_15.nbt,5,FLOWER_POT:0,../../../../Flowers/flower_pot_16.nbt,5,FLOWER_POT:0,../../../../Flowers/flower_pot_17.nbt,5,FLOWER_POT:0,../../../../Flowers/flower_pot_18.nbt,5,FLOWER_POT:0,../../../../Flowers/flower_pot_19.nbt,5,FLOWER_POT:0,../../../../Flowers/flower_pot_20.nbt,100)
Block(6,13,2,GOLD_PLATE:0)
Block(6,13,3,ANVIL:0)
Block(6,13,4,ANVIL:0)
Block(6,13,5,CONCRETE:15)
Block(6,13,6,STONE_BUTTON:3)
Block(6,14,-6,WOOD_STEP:1)
Block(6,14,-5,CONCRETE:15)
Block(6,14,-4,CONCRETE:15)
Block(6,14,-3,CONCRETE:15)
Block(6,14,-2,CONCRETE:15)
Block(6,14,-1,CONCRETE:15)
RandomBlock(6,14,2,WALL_BANNER:5,../../Banners/skullpillager_01.nbt,20,WALL_BANNER:5,../../Banners/skullpillager_02.nbt,20,WALL_BANNER:5,../../Banners/skullpillager_03.nbt,20,WALL_BANNER:5,../../Banners/skullpillager_04.nbt,20,WALL_BANNER:5,../../Banners/skullpillager_05.nbt,100)
Block(6,14,3,WOOD_STEP:5)
Block(6,14,4,WOOD_STEP:5)
Block(6,14,5,CONCRETE:15)
Block(6,14,6,STONE_BUTTON:3)
Block(6,15,-5,CONCRETE:15)
Block(6,15,-4,CONCRETE:15)
Block(6,15,-3,CONCRETE:15)
Block(6,15,-2,CONCRETE:15)
Block(6,15,-1,CONCRETE:15)
Block(6,15,0,CONCRETE:15)
Block(6,15,1,WOOD_DOUBLE_STEP:5)
Block(6,15,2,DARK_OAK_STAIRS:0)
Block(6,15,3,DARK_OAK_STAIRS:0)
Block(6,15,4,DARK_OAK_STAIRS:0)
Block(6,15,5,DARK_OAK_STAIRS:3)
Block(6,16,-5,DARK_OAK_STAIRS:2)
Block(6,16,-4,CONCRETE:15)
Block(6,16,-3,CONCRETE:15)
Block(6,16,-2,CONCRETE:15)
Block(6,16,-1,CONCRETE:15)
Block(6,16,0,CONCRETE:15)
Block(6,17,-6,SPRUCE_FENCE:0)
Block(6,17,-5,SPRUCE_FENCE:0)
Block(6,17,-4,SPRUCE_FENCE:0)
Block(6,17,-3,WOOD_STEP:5)
Block(6,17,-2,WOOD_STEP:5)
Block(6,17,-1,DARK_OAK_STAIRS:2)
Block(6,17,0,CONCRETE:15)
RandomBlock(6,17,3,WALL_BANNER:4,../../Banners/skullpillager_01.nbt,20,WALL_BANNER:4,../../Banners/skullpillager_02.nbt,20,WALL_BANNER:4,../../Banners/skullpillager_03.nbt,20,WALL_BANNER:4,../../Banners/skullpillager_04.nbt,20,WALL_BANNER:4,../../Banners/skullpillager_05.nbt,100)
Block(6,18,-6,SPRUCE_FENCE:0)
Block(6,18,-5,SPRUCE_FENCE:0)
Block(6,18,-4,SPRUCE_FENCE:0)
Block(6,18,0,WOOD_STEP:5)
Block(6,19,-6,SPRUCE_FENCE:0)
Block(6,19,-5,SPRUCE_FENCE:0)
Block(6,19,-4,SPRUCE_FENCE:0)
Block(6,24,-7,WOOL:14)
Block(6,25,-7,WOOL:14)
Block(6,31,-7,WOOL:15)
Block(6,32,-7,WOOL:15)
Block(7,4,-7,LOG_2:13)
Block(7,5,-7,WOOD_DOUBLE_STEP:1)
Block(7,5,-6,LOG_2:13)
Block(7,5,-5,LOG_2:13)
Block(7,5,-4,LOG_2:13)
Block(7,5,-3,LOG_2:13)
Block(7,5,-2,LOG_2:13)
Block(7,5,-1,LOG_2:13)
Block(7,6,-7,WOOD_DOUBLE_STEP:1)
Block(7,6,-6,LOG_2:13)
Block(7,6,-5,BOOKSHELF:0)
Block(7,6,-4,BOOKSHELF:0)
Block(7,6,-3,WOOD_DOUBLE_STEP:1)
Block(7,6,-2,WOOD_DOUBLE_STEP:1)
Block(7,6,-1,LOG_2:13)
Block(7,7,-7,WOOD:5)
Block(7,7,-6,WOOD:5)
Block(7,7,-5,WOOD:5)
Block(7,7,-4,WOOD:5)
Block(7,7,-3,WOOD:5)
Block(7,7,-2,WOOD:5)
Block(7,7,-1,WOOD:5)
Block(7,8,-7,CARPET:15)
Block(7,8,-6,TRIPWIRE:0)
Block(7,8,-5,DARK_OAK_STAIRS:1)
Block(7,8,-4,CONCRETE:15)
Block(7,8,-3,BED_BLOCK:1)
Block(7,8,-1,BED_BLOCK:9)
Block(7,8,0,WOOD:5)
Block(7,9,-4,CONCRETE:15)
Block(7,9,-3,BED_BLOCK:1)
Block(7,9,-1,BED_BLOCK:3)
Block(7,9,0,WOOD:5)
Block(7,9,1,WOOD:5)
Block(7,9,2,WOOD_BUTTON:3)
Block(7,10,-7,WOOD_STEP:13)
Block(7,10,-6,WOOD_STEP:13)
Block(7,10,-5,WOOD_STEP:13)
Block(7,10,-4,WOOD_DOUBLE_STEP:5)
Block(7,10,-3,WOOD_STEP:13)
Block(7,10,-2,WOOD_STEP:13)
Block(7,10,-1,WOOD_STEP:13)
Block(7,10,0,WOOD_DOUBLE_STEP:5)
Block(7,10,1,WOOD_DOUBLE_STEP:5)
Block(7,10,2,CONCRETE:15)
Block(7,11,-7,TRIPWIRE:0)
Block(7,11,-6,SPRUCE_WOOD_STAIRS:1)
Block(7,11,-5,CONCRETE:15)
Block(7,11,-4,BED_BLOCK:1)
Block(7,11,-3,BED_BLOCK:1)
Block(7,11,-2,BED_BLOCK:1)
Block(7,11,-1,CONCRETE:15)
Block(7,11,0,BOOKSHELF:0)
Block(7,11,1,BOOKSHELF:0)
Block(7,11,2,WOOD:5)
Block(7,11,3,WOOD_STEP:13)
Block(7,11,4,WOOD_STEP:13)
Block(7,12,-5,CONCRETE:15)
Block(7,12,-1,CONCRETE:15)
Block(7,12,0,AIR:0)
Block(7,12,1,CARPET:14)
Block(7,12,2,GOLD_ORE:0)
Block(7,12,3,CARPET:14)
Block(7,12,4,AIR:0)
Block(7,12,5,DARK_OAK_STAIRS:7)
Block(7,13,-7,CONCRETE:15)
Block(7,13,-6,CONCRETE:15)
Block(7,13,-5,CONCRETE:15)
Block(7,13,-1,CONCRETE:15)
Block(7,13,2,GOLD_PLATE:0)
Block(7,13,5,ANVIL:3)
Block(7,14,-6,WOOD_STEP:1)
Block(7,14,-5,CONCRETE:15)
Block(7,14,-4,CONCRETE:15)
Block(7,14,-3,CONCRETE:15)
Block(7,14,-2,CONCRETE:15)
Block(7,14,-1,CONCRETE:15)
RandomBlock(7,14,0,WALL_BANNER:3,../../Banners/skullpillager_01.nbt,20,WALL_BANNER:3,../../Banners/skullpillager_02.nbt,20,WALL_BANNER:3,../../Banners/skullpillager_03.nbt,20,WALL_BANNER:3,../../Banners/skullpillager_04.nbt,20,WALL_BANNER:3,../../Banners/skullpillager_05.nbt,100)
Block(7,14,3,AIR:0)
Block(7,14,5,WOOD_STEP:5)
RandomBlock(7,15,-4,CHEST:5,../../../../Chests/Loot/PirateJunk_1.nbt,10,CHEST:5,../../../../Chests/Loot/PirateJunk_2.nbt,10,CHEST:5,../../../../Chests/Loot/PirateJunk_3.nbt,10,CHEST:5,../../../../Chests/Loot/PirateJunk_4.nbt,10,CHEST:5,../../../../Chests/Loot/PirateJunk_5.nbt,10,CHEST:5,../../../../Chests/Lore/EagleLore_1.nbt,10,CHEST:5,../../../../Chests/Lore/EagleLore_2.nbt,10,CHEST:5,../../../../Chests/Lore/EagleLore_3.nbt,10,CHEST:5,../../../../Chests/Lore/EagleLore_4.nbt,10,CHEST:5,../../../../Chests/Lore/EagleLore_5.nbt,10,CHEST:5,../../../../Chests/Traveler/Travelers_Castle.nbt,1,CHEST:5,../../../../Chests/Traveler/Travelers_Church.nbt,1,CHEST:5,../../../../Chests/Traveler/Travelers_Daeroc.nbt,1,CHEST:5,../../../../Chests/Traveler/Travelers_Farmsteads.nbt,1,CHEST:5,../../../../Chests/Traveler/Travelers_GreenDungeon.nbt,1,CHEST:5,../../../../Chests/Traveler/Travelers_IceShips.nbt,1,CHEST:5,../../../../Chests/Traveler/Travelers_IceTemple.nbt,1,CHEST:5,../../../../Chests/Traveler/Travelers_LegacySpawn.nbt,1,CHEST:5,../../../../Chests/Traveler/Travelers_Mineshafts.nbt,1,CHEST:5,../../../../Chests/Traveler/Travelers_Mountains.nbt,1,CHEST:5,../../../../Chests/Traveler/Travelers_Origin.nbt,1,CHEST:5,../../../../Chests/Traveler/Travelers_Pirate.nbt,1,CHEST:5,../../../../Chests/Traveler/Travelers_Quarry.nbt,1,CHEST:5,../../../../Chests/Traveler/Travelers_Spook.nbt,1,CHEST:5,../../../../Chests/Traveler/Travelers_Tribal.nbt,1,CHEST:5,../../../../Chests/Lore/Pirate_1.nbt,1,CHEST:5,../../../../Chests/Lore/Pirate_2.nbt,1,CHEST:5,../../../../Chests/Lore/Pirate_3.nbt,1,CHEST:5,../../../../Chests/Lore/Pirate_4.nbt,1,CHEST:5,../../../../Chests/Lore/Pirate_5.nbt,1,CHEST:5,../../../../Chests/Loot/Common1.nbt,5,CHEST:5,../../../../Chests/Loot/Common2.nbt,5,CHEST:5,../../../../Chests/Loot/Common3.nbt,5,CHEST:5,../../../../Chests/Loot/Common4.nbt,5,CHEST:5,../../../../Chests/Loot/Common5.nbt,5,CHEST:5,../../../../Chests/Loot/Common6.nbt,5,CHEST:5,../../../../Chests/Loot/Common7.nbt,5,CHEST:5,../../../../Chests/Loot/Common8.nbt,5,CHEST:5,../../../../Chests/Loot/Common9.nbt,5,CHEST:5,../../../../Chests/Loot/Common10.nbt,5,CHEST:5,../../../../Chests/Loot/Common11.nbt,5,CHEST:5,../../../../Chests/Loot/Common12.nbt,5,CHEST:5,../../../../Chests/Loot/Common13.nbt,5,CHEST:5,../../../../Chests/Loot/Common14.nbt,5,CHEST:5,../../../../Chests/Loot/Common15.nbt,5,CHEST:5,../../../../Chests/Lore/Pirate_1.nbt,2,CHEST:5,../../../../Chests/Lore/Pirate_2.nbt,2,CHEST:5,../../../../Chests/Lore/Pirate_3.nbt,2,CHEST:5,../../../../Chests/Lore/Pirate_4.nbt,2,CHEST:5,../../../../Chests/Lore/Pirate_5.nbt,2,CHEST:5,../../../../Chests/Loot/Rare1.nbt,5,CHEST:5,../../../../Chests/Loot/Rare2.nbt,5,CHEST:5,../../../../Chests/Loot/Rare3.nbt,5,CHEST:5,../../../../Chests/Loot/Rare4.nbt,5,CHEST:5,../../../../Chests/Loot/Rare5.nbt,5,CHEST:5,../../../../Chests/Loot/Rare6.nbt,5,CHEST:5,../../../../Chests/Loot/Rare7.nbt,5,CHEST:5,../../../../Chests/Loot/Rare8.nbt,5,CHEST:5,../../../../Chests/Loot/Rare9.nbt,5,CHEST:5,../../../../Chests/Loot/Rare10.nbt,5,CHEST:5,../../../../Chests/Loot/Rare11.nbt,5,CHEST:5,../../../../Chests/Loot/Rare12.nbt,5,CHEST:5,../../../../Chests/Loot/Rare13.nbt,5,CHEST:5,../../../../Chests/Loot/Rare14.nbt,5,CHEST:5,../../../../Chests/Loot/Rare15.nbt,5,CHEST:5,../../../../Chests/Loot/Epic1.nbt,2,CHEST:5,../../../../Chests/Loot/Epic2.nbt,2,CHEST:5,../../../../Chests/Loot/Epic3.nbt,2,CHEST:5,../../../../Chests/Loot/Epic4.nbt,2,CHEST:5,../../../../Chests/Loot/Epic5.nbt,2,CHEST:5,../../../../Chests/Loot/Epic6.nbt,2,CHEST:5,../../../../Chests/Loot/Epic7.nbt,2,CHEST:5,../../../../Chests/Loot/Epic8.nbt,2,CHEST:5,../../../../Chests/Loot/Epic9.nbt,2,CHEST:5,../../../../Chests/Loot/Epic10.nbt,2,CHEST:5,../../../../Chests/Loot/Epic11.nbt,2,CHEST:5,../../../../Chests/Loot/Epic12.nbt,2,CHEST:5,../../../../Chests/Loot/Epic13.nbt,2,CHEST:5,../../../../Chests/Loot/Epic14.nbt,2,CHEST:5,../../../../Chests/Loot/Epic15.nbt,5,CHEST:5,../../../../Chests/Loot/Rare1.nbt,5,CHEST:5,../../../../Chests/Loot/Rare2.nbt,5,CHEST:5,../../../../Chests/Loot/Rare3.nbt,5,CHEST:5,../../../../Chests/Loot/Rare4.nbt,5,CHEST:5,../../../../Chests/Loot/Rare5.nbt,10,CHEST:5,../../../../Chests/Loot/Rare6.nbt,10,CHEST:5,../../../../Chests/Loot/Rare7.nbt,10,CHEST:5,../../../../Chests/Loot/Rare8.nbt,10,CHEST:5,../../../../Chests/Loot/Rare9.nbt,10,CHEST:5,../../../../Chests/Loot/Rare10.nbt,15,CHEST:5,../../../../Chests/Loot/Rare11.nbt,15,CHEST:5,../../../../Chests/Loot/Rare12.nbt,15,CHEST:5,../../../../Chests/Loot/Rare13.nbt,15,CHEST:5,../../../../Chests/Loot/Rare14.nbt,15,CHEST:5,../../../../Chests/Loot/Rare15.nbt,15,CHEST:5,../../../../Chests/Loot/Epic15.nbt,100)
RandomBlock(7,15,-3,CHEST:5,../../../../Chests/Loot/PirateJunk_1.nbt,10,CHEST:5,../../../../Chests/Loot/PirateJunk_2.nbt,10,CHEST:5,../../../../Chests/Loot/PirateJunk_3.nbt,10,CHEST:5,../../../../Chests/Loot/PirateJunk_4.nbt,10,CHEST:5,../../../../Chests/Loot/PirateJunk_5.nbt,10,CHEST:5,../../../../Chests/Lore/EagleLore_1.nbt,10,CHEST:5,../../../../Chests/Lore/EagleLore_2.nbt,10,CHEST:5,../../../../Chests/Lore/EagleLore_3.nbt,10,CHEST:5,../../../../Chests/Lore/EagleLore_4.nbt,10,CHEST:5,../../../../Chests/Lore/EagleLore_5.nbt,10,CHEST:5,../../../../Chests/Traveler/Travelers_Castle.nbt,1,CHEST:5,../../../../Chests/Traveler/Travelers_Church.nbt,1,CHEST:5,../../../../Chests/Traveler/Travelers_Daeroc.nbt,1,CHEST:5,../../../../Chests/Traveler/Travelers_Farmsteads.nbt,1,CHEST:5,../../../../Chests/Traveler/Travelers_GreenDungeon.nbt,1,CHEST:5,../../../../Chests/Traveler/Travelers_IceShips.nbt,1,CHEST:5,../../../../Chests/Traveler/Travelers_IceTemple.nbt,1,CHEST:5,../../../../Chests/Traveler/Travelers_LegacySpawn.nbt,1,CHEST:5,../../../../Chests/Traveler/Travelers_Mineshafts.nbt,1,CHEST:5,../../../../Chests/Traveler/Travelers_Mountains.nbt,1,CHEST:5,../../../../Chests/Traveler/Travelers_Origin.nbt,1,CHEST:5,../../../../Chests/Traveler/Travelers_Pirate.nbt,1,CHEST:5,../../../../Chests/Traveler/Travelers_Quarry.nbt,1,CHEST:5,../../../../Chests/Traveler/Travelers_Spook.nbt,1,CHEST:5,../../../../Chests/Traveler/Travelers_Tribal.nbt,1,CHEST:5,../../../../Chests/Lore/Pirate_1.nbt,1,CHEST:5,../../../../Chests/Lore/Pirate_2.nbt,1,CHEST:5,../../../../Chests/Lore/Pirate_3.nbt,1,CHEST:5,../../../../Chests/Lore/Pirate_4.nbt,1,CHEST:5,../../../../Chests/Lore/Pirate_5.nbt,1,CHEST:5,../../../../Chests/Loot/Common1.nbt,5,CHEST:5,../../../../Chests/Loot/Common2.nbt,5,CHEST:5,../../../../Chests/Loot/Common3.nbt,5,CHEST:5,../../../../Chests/Loot/Common4.nbt,5,CHEST:5,../../../../Chests/Loot/Common5.nbt,5,CHEST:5,../../../../Chests/Loot/Common6.nbt,5,CHEST:5,../../../../Chests/Loot/Common7.nbt,5,CHEST:5,../../../../Chests/Loot/Common8.nbt,5,CHEST:5,../../../../Chests/Loot/Common9.nbt,5,CHEST:5,../../../../Chests/Loot/Common10.nbt,5,CHEST:5,../../../../Chests/Loot/Common11.nbt,5,CHEST:5,../../../../Chests/Loot/Common12.nbt,5,CHEST:5,../../../../Chests/Loot/Common13.nbt,5,CHEST:5,../../../../Chests/Loot/Common14.nbt,5,CHEST:5,../../../../Chests/Loot/Common15.nbt,5,CHEST:5,../../../../Chests/Lore/Pirate_1.nbt,2,CHEST:5,../../../../Chests/Lore/Pirate_2.nbt,2,CHEST:5,../../../../Chests/Lore/Pirate_3.nbt,2,CHEST:5,../../../../Chests/Lore/Pirate_4.nbt,2,CHEST:5,../../../../Chests/Lore/Pirate_5.nbt,2,CHEST:5,../../../../Chests/Loot/Rare1.nbt,5,CHEST:5,../../../../Chests/Loot/Rare2.nbt,5,CHEST:5,../../../../Chests/Loot/Rare3.nbt,5,CHEST:5,../../../../Chests/Loot/Rare4.nbt,5,CHEST:5,../../../../Chests/Loot/Rare5.nbt,5,CHEST:5,../../../../Chests/Loot/Rare6.nbt,5,CHEST:5,../../../../Chests/Loot/Rare7.nbt,5,CHEST:5,../../../../Chests/Loot/Rare8.nbt,5,CHEST:5,../../../../Chests/Loot/Rare9.nbt,5,CHEST:5,../../../../Chests/Loot/Rare10.nbt,5,CHEST:5,../../../../Chests/Loot/Rare11.nbt,5,CHEST:5,../../../../Chests/Loot/Rare12.nbt,5,CHEST:5,../../../../Chests/Loot/Rare13.nbt,5,CHEST:5,../../../../Chests/Loot/Rare14.nbt,5,CHEST:5,../../../../Chests/Loot/Rare15.nbt,5,CHEST:5,../../../../Chests/Loot/Epic1.nbt,2,CHEST:5,../../../../Chests/Loot/Epic2.nbt,2,CHEST:5,../../../../Chests/Loot/Epic3.nbt,2,CHEST:5,../../../../Chests/Loot/Epic4.nbt,2,CHEST:5,../../../../Chests/Loot/Epic5.nbt,2,CHEST:5,../../../../Chests/Loot/Epic6.nbt,2,CHEST:5,../../../../Chests/Loot/Epic7.nbt,2,CHEST:5,../../../../Chests/Loot/Epic8.nbt,2,CHEST:5,../../../../Chests/Loot/Epic9.nbt,2,CHEST:5,../../../../Chests/Loot/Epic10.nbt,2,CHEST:5,../../../../Chests/Loot/Epic11.nbt,2,CHEST:5,../../../../Chests/Loot/Epic12.nbt,2,CHEST:5,../../../../Chests/Loot/Epic13.nbt,2,CHEST:5,../../../../Chests/Loot/Epic14.nbt,2,CHEST:5,../../../../Chests/Loot/Epic15.nbt,5,CHEST:5,../../../../Chests/Loot/Rare1.nbt,5,CHEST:5,../../../../Chests/Loot/Rare2.nbt,5,CHEST:5,../../../../Chests/Loot/Rare3.nbt,5,CHEST:5,../../../../Chests/Loot/Rare4.nbt,5,CHEST:5,../../../../Chests/Loot/Rare5.nbt,10,CHEST:5,../../../../Chests/Loot/Rare6.nbt,10,CHEST:5,../../../../Chests/Loot/Rare7.nbt,10,CHEST:5,../../../../Chests/Loot/Rare8.nbt,10,CHEST:5,../../../../Chests/Loot/Rare9.nbt,10,CHEST:5,../../../../Chests/Loot/Rare10.nbt,15,CHEST:5,../../../../Chests/Loot/Rare11.nbt,15,CHEST:5,../../../../Chests/Loot/Rare12.nbt,15,CHEST:5,../../../../Chests/Loot/Rare13.nbt,15,CHEST:5,../../../../Chests/Loot/Rare14.nbt,15,CHEST:5,../../../../Chests/Loot/Rare15.nbt,15,CHEST:5,../../../../Chests/Loot/Epic15.nbt,100)
Block(7,15,-2,WORKBENCH:0)
RandomBlock(7,15,-1,CHEST:2,../../../../Chests/Loot/PirateJunk_1.nbt,10,CHEST:2,../../../../Chests/Loot/PirateJunk_2.nbt,10,CHEST:2,../../../../Chests/Loot/PirateJunk_3.nbt,10,CHEST:2,../../../../Chests/Loot/PirateJunk_4.nbt,10,CHEST:2,../../../../Chests/Loot/PirateJunk_5.nbt,10,CHEST:2,../../../../Chests/Lore/EagleLore_1.nbt,10,CHEST:2,../../../../Chests/Lore/EagleLore_2.nbt,10,CHEST:2,../../../../Chests/Lore/EagleLore_3.nbt,10,CHEST:2,../../../../Chests/Lore/EagleLore_4.nbt,10,CHEST:2,../../../../Chests/Lore/EagleLore_5.nbt,10,CHEST:2,../../../../Chests/Traveler/Travelers_Castle.nbt,1,CHEST:2,../../../../Chests/Traveler/Travelers_Church.nbt,1,CHEST:2,../../../../Chests/Traveler/Travelers_Daeroc.nbt,1,CHEST:2,../../../../Chests/Traveler/Travelers_Farmsteads.nbt,1,CHEST:2,../../../../Chests/Traveler/Travelers_GreenDungeon.nbt,1,CHEST:2,../../../../Chests/Traveler/Travelers_IceShips.nbt,1,CHEST:2,../../../../Chests/Traveler/Travelers_IceTemple.nbt,1,CHEST:2,../../../../Chests/Traveler/Travelers_LegacySpawn.nbt,1,CHEST:2,../../../../Chests/Traveler/Travelers_Mineshafts.nbt,1,CHEST:2,../../../../Chests/Traveler/Travelers_Mountains.nbt,1,CHEST:2,../../../../Chests/Traveler/Travelers_Origin.nbt,1,CHEST:2,../../../../Chests/Traveler/Travelers_Pirate.nbt,1,CHEST:2,../../../../Chests/Traveler/Travelers_Quarry.nbt,1,CHEST:2,../../../../Chests/Traveler/Travelers_Spook.nbt,1,CHEST:2,../../../../Chests/Traveler/Travelers_Tribal.nbt,1,CHEST:2,../../../../Chests/Lore/Pirate_1.nbt,1,CHEST:2,../../../../Chests/Lore/Pirate_2.nbt,1,CHEST:2,../../../../Chests/Lore/Pirate_3.nbt,1,CHEST:2,../../../../Chests/Lore/Pirate_4.nbt,1,CHEST:2,../../../../Chests/Lore/Pirate_5.nbt,1,CHEST:2,../../../../Chests/Loot/Common1.nbt,5,CHEST:2,../../../../Chests/Loot/Common2.nbt,5,CHEST:2,../../../../Chests/Loot/Common3.nbt,5,CHEST:2,../../../../Chests/Loot/Common4.nbt,5,CHEST:2,../../../../Chests/Loot/Common5.nbt,5,CHEST:2,../../../../Chests/Loot/Common6.nbt,5,CHEST:2,../../../../Chests/Loot/Common7.nbt,5,CHEST:2,../../../../Chests/Loot/Common8.nbt,5,CHEST:2,../../../../Chests/Loot/Common9.nbt,5,CHEST:2,../../../../Chests/Loot/Common10.nbt,5,CHEST:2,../../../../Chests/Loot/Common11.nbt,5,CHEST:2,../../../../Chests/Loot/Common12.nbt,5,CHEST:2,../../../../Chests/Loot/Common13.nbt,5,CHEST:2,../../../../Chests/Loot/Common14.nbt,5,CHEST:2,../../../../Chests/Loot/Common15.nbt,5,CHEST:2,../../../../Chests/Lore/Pirate_1.nbt,2,CHEST:2,../../../../Chests/Lore/Pirate_2.nbt,2,CHEST:2,../../../../Chests/Lore/Pirate_3.nbt,2,CHEST:2,../../../../Chests/Lore/Pirate_4.nbt,2,CHEST:2,../../../../Chests/Lore/Pirate_5.nbt,2,CHEST:2,../../../../Chests/Loot/Rare1.nbt,5,CHEST:2,../../../../Chests/Loot/Rare2.nbt,5,CHEST:2,../../../../Chests/Loot/Rare3.nbt,5,CHEST:2,../../../../Chests/Loot/Rare4.nbt,5,CHEST:2,../../../../Chests/Loot/Rare5.nbt,5,CHEST:2,../../../../Chests/Loot/Rare6.nbt,5,CHEST:2,../../../../Chests/Loot/Rare7.nbt,5,CHEST:2,../../../../Chests/Loot/Rare8.nbt,5,CHEST:2,../../../../Chests/Loot/Rare9.nbt,5,CHEST:2,../../../../Chests/Loot/Rare10.nbt,5,CHEST:2,../../../../Chests/Loot/Rare11.nbt,5,CHEST:2,../../../../Chests/Loot/Rare12.nbt,5,CHEST:2,../../../../Chests/Loot/Rare13.nbt,5,CHEST:2,../../../../Chests/Loot/Rare14.nbt,5,CHEST:2,../../../../Chests/Loot/Rare15.nbt,5,CHEST:2,../../../../Chests/Loot/Epic1.nbt,2,CHEST:2,../../../../Chests/Loot/Epic2.nbt,2,CHEST:2,../../../../Chests/Loot/Epic3.nbt,2,CHEST:2,../../../../Chests/Loot/Epic4.nbt,2,CHEST:2,../../../../Chests/Loot/Epic5.nbt,2,CHEST:2,../../../../Chests/Loot/Epic6.nbt,2,CHEST:2,../../../../Chests/Loot/Epic7.nbt,2,CHEST:2,../../../../Chests/Loot/Epic8.nbt,2,CHEST:2,../../../../Chests/Loot/Epic9.nbt,2,CHEST:2,../../../../Chests/Loot/Epic10.nbt,2,CHEST:2,../../../../Chests/Loot/Epic11.nbt,2,CHEST:2,../../../../Chests/Loot/Epic12.nbt,2,CHEST:2,../../../../Chests/Loot/Epic13.nbt,2,CHEST:2,../../../../Chests/Loot/Epic14.nbt,2,CHEST:2,../../../../Chests/Loot/Epic15.nbt,5,CHEST:2,../../../../Chests/Loot/Rare1.nbt,5,CHEST:2,../../../../Chests/Loot/Rare2.nbt,5,CHEST:2,../../../../Chests/Loot/Rare3.nbt,5,CHEST:2,../../../../Chests/Loot/Rare4.nbt,5,CHEST:2,../../../../Chests/Loot/Rare5.nbt,10,CHEST:2,../../../../Chests/Loot/Rare6.nbt,10,CHEST:2,../../../../Chests/Loot/Rare7.nbt,10,CHEST:2,../../../../Chests/Loot/Rare8.nbt,10,CHEST:2,../../../../Chests/Loot/Rare9.nbt,10,CHEST:2,../../../../Chests/Loot/Rare10.nbt,15,CHEST:2,../../../../Chests/Loot/Rare11.nbt,15,CHEST:2,../../../../Chests/Loot/Rare12.nbt,15,CHEST:2,../../../../Chests/Loot/Rare13.nbt,15,CHEST:2,../../../../Chests/Loot/Rare14.nbt,15,CHEST:2,../../../../Chests/Loot/Rare15.nbt,15,CHEST:2,../../../../Chests/Loot/Epic15.nbt,100)
Block(7,15,0,WOOD_STEP:1)
Block(7,15,1,CONCRETE:15)
Block(7,15,2,CONCRETE:15)
Block(7,15,3,CONCRETE:15)
Block(7,15,4,CONCRETE:15)
Block(7,15,5,DARK_OAK_STAIRS:3)
RandomBlock(7,16,-2,CHEST:5,../../../../Chests/Loot/PirateJunk_1.nbt,10,CHEST:5,../../../../Chests/Loot/PirateJunk_2.nbt,10,CHEST:5,../../../../Chests/Loot/PirateJunk_3.nbt,10,CHEST:5,../../../../Chests/Loot/PirateJunk_4.nbt,10,CHEST:5,../../../../Chests/Loot/PirateJunk_5.nbt,10,CHEST:5,../../../../Chests/Lore/EagleLore_1.nbt,10,CHEST:5,../../../../Chests/Lore/EagleLore_2.nbt,10,CHEST:5,../../../../Chests/Lore/EagleLore_3.nbt,10,CHEST:5,../../../../Chests/Lore/EagleLore_4.nbt,10,CHEST:5,../../../../Chests/Lore/EagleLore_5.nbt,10,CHEST:5,../../../../Chests/Traveler/Travelers_Castle.nbt,1,CHEST:5,../../../../Chests/Traveler/Travelers_Church.nbt,1,CHEST:5,../../../../Chests/Traveler/Travelers_Daeroc.nbt,1,CHEST:5,../../../../Chests/Traveler/Travelers_Farmsteads.nbt,1,CHEST:5,../../../../Chests/Traveler/Travelers_GreenDungeon.nbt,1,CHEST:5,../../../../Chests/Traveler/Travelers_IceShips.nbt,1,CHEST:5,../../../../Chests/Traveler/Travelers_IceTemple.nbt,1,CHEST:5,../../../../Chests/Traveler/Travelers_LegacySpawn.nbt,1,CHEST:5,../../../../Chests/Traveler/Travelers_Mineshafts.nbt,1,CHEST:5,../../../../Chests/Traveler/Travelers_Mountains.nbt,1,CHEST:5,../../../../Chests/Traveler/Travelers_Origin.nbt,1,CHEST:5,../../../../Chests/Traveler/Travelers_Pirate.nbt,1,CHEST:5,../../../../Chests/Traveler/Travelers_Quarry.nbt,1,CHEST:5,../../../../Chests/Traveler/Travelers_Spook.nbt,1,CHEST:5,../../../../Chests/Traveler/Travelers_Tribal.nbt,1,CHEST:5,../../../../Chests/Lore/Pirate_1.nbt,1,CHEST:5,../../../../Chests/Lore/Pirate_2.nbt,1,CHEST:5,../../../../Chests/Lore/Pirate_3.nbt,1,CHEST:5,../../../../Chests/Lore/Pirate_4.nbt,1,CHEST:5,../../../../Chests/Lore/Pirate_5.nbt,1,CHEST:5,../../../../Chests/Loot/Common1.nbt,5,CHEST:5,../../../../Chests/Loot/Common2.nbt,5,CHEST:5,../../../../Chests/Loot/Common3.nbt,5,CHEST:5,../../../../Chests/Loot/Common4.nbt,5,CHEST:5,../../../../Chests/Loot/Common5.nbt,5,CHEST:5,../../../../Chests/Loot/Common6.nbt,5,CHEST:5,../../../../Chests/Loot/Common7.nbt,5,CHEST:5,../../../../Chests/Loot/Common8.nbt,5,CHEST:5,../../../../Chests/Loot/Common9.nbt,5,CHEST:5,../../../../Chests/Loot/Common10.nbt,5,CHEST:5,../../../../Chests/Loot/Common11.nbt,5,CHEST:5,../../../../Chests/Loot/Common12.nbt,5,CHEST:5,../../../../Chests/Loot/Common13.nbt,5,CHEST:5,../../../../Chests/Loot/Common14.nbt,5,CHEST:5,../../../../Chests/Loot/Common15.nbt,5,CHEST:5,../../../../Chests/Lore/Pirate_1.nbt,2,CHEST:5,../../../../Chests/Lore/Pirate_2.nbt,2,CHEST:5,../../../../Chests/Lore/Pirate_3.nbt,2,CHEST:5,../../../../Chests/Lore/Pirate_4.nbt,2,CHEST:5,../../../../Chests/Lore/Pirate_5.nbt,2,CHEST:5,../../../../Chests/Loot/Rare1.nbt,5,CHEST:5,../../../../Chests/Loot/Rare2.nbt,5,CHEST:5,../../../../Chests/Loot/Rare3.nbt,5,CHEST:5,../../../../Chests/Loot/Rare4.nbt,5,CHEST:5,../../../../Chests/Loot/Rare5.nbt,5,CHEST:5,../../../../Chests/Loot/Rare6.nbt,5,CHEST:5,../../../../Chests/Loot/Rare7.nbt,5,CHEST:5,../../../../Chests/Loot/Rare8.nbt,5,CHEST:5,../../../../Chests/Loot/Rare9.nbt,5,CHEST:5,../../../../Chests/Loot/Rare10.nbt,5,CHEST:5,../../../../Chests/Loot/Rare11.nbt,5,CHEST:5,../../../../Chests/Loot/Rare12.nbt,5,CHEST:5,../../../../Chests/Loot/Rare13.nbt,5,CHEST:5,../../../../Chests/Loot/Rare14.nbt,5,CHEST:5,../../../../Chests/Loot/Rare15.nbt,5,CHEST:5,../../../../Chests/Loot/Epic1.nbt,2,CHEST:5,../../../../Chests/Loot/Epic2.nbt,2,CHEST:5,../../../../Chests/Loot/Epic3.nbt,2,CHEST:5,../../../../Chests/Loot/Epic4.nbt,2,CHEST:5,../../../../Chests/Loot/Epic5.nbt,2,CHEST:5,../../../../Chests/Loot/Epic6.nbt,2,CHEST:5,../../../../Chests/Loot/Epic7.nbt,2,CHEST:5,../../../../Chests/Loot/Epic8.nbt,2,CHEST:5,../../../../Chests/Loot/Epic9.nbt,2,CHEST:5,../../../../Chests/Loot/Epic10.nbt,2,CHEST:5,../../../../Chests/Loot/Epic11.nbt,2,CHEST:5,../../../../Chests/Loot/Epic12.nbt,2,CHEST:5,../../../../Chests/Loot/Epic13.nbt,2,CHEST:5,../../../../Chests/Loot/Epic14.nbt,2,CHEST:5,../../../../Chests/Loot/Epic15.nbt,5,CHEST:5,../../../../Chests/Loot/Rare1.nbt,5,CHEST:5,../../../../Chests/Loot/Rare2.nbt,5,CHEST:5,../../../../Chests/Loot/Rare3.nbt,5,CHEST:5,../../../../Chests/Loot/Rare4.nbt,5,CHEST:5,../../../../Chests/Loot/Rare5.nbt,10,CHEST:5,../../../../Chests/Loot/Rare6.nbt,10,CHEST:5,../../../../Chests/Loot/Rare7.nbt,10,CHEST:5,../../../../Chests/Loot/Rare8.nbt,10,CHEST:5,../../../../Chests/Loot/Rare9.nbt,10,CHEST:5,../../../../Chests/Loot/Rare10.nbt,15,CHEST:5,../../../../Chests/Loot/Rare11.nbt,15,CHEST:5,../../../../Chests/Loot/Rare12.nbt,15,CHEST:5,../../../../Chests/Loot/Rare13.nbt,15,CHEST:5,../../../../Chests/Loot/Rare14.nbt,15,CHEST:5,../../../../Chests/Loot/Rare15.nbt,15,CHEST:5,../../../../Chests/Loot/Epic15.nbt,100)
Block(7,16,1,CONCRETE:15)
Block(7,16,2,CONCRETE:15)
Block(7,16,3,CONCRETE:15)
Block(7,16,4,CONCRETE:15)
Block(7,17,0,DARK_OAK_FENCE:0)
Block(7,17,1,CONCRETE:15)
Block(7,17,2,CONCRETE:15)
Block(7,17,3,CONCRETE:15)
Block(7,17,4,CONCRETE:15)
Block(7,18,0,DARK_OAK_FENCE:0)
Block(7,18,1,WOOD_STEP:5)
Block(7,18,2,DARK_OAK_STAIRS:2)
Block(7,18,3,CONCRETE:15)
Block(7,18,4,CONCRETE:15)
Block(7,19,-6,SPRUCE_FENCE:0)
Block(7,19,-5,SPRUCE_FENCE:0)
Block(7,19,-4,SPRUCE_FENCE:0)
Block(7,19,0,DARK_OAK_FENCE:0)
Block(7,19,3,WOOD_STEP:5)
Block(7,19,4,WOOD_STEP:5)
Block(7,19,5,TRAP_DOOR:14)
Block(7,20,-6,SPRUCE_FENCE:0)
Block(7,20,-5,SPRUCE_FENCE:0)
Block(7,20,-4,SPRUCE_FENCE:0)
Block(7,20,0,DARK_OAK_FENCE:0)
Block(7,20,1,WOOL:15)
Block(7,20,2,WOOL:15)
Block(7,21,-6,SPRUCE_FENCE:0)
Block(7,21,-5,SPRUCE_FENCE:0)
Block(7,21,-4,SPRUCE_FENCE:0)
Block(7,21,0,WOOL:15)
Block(7,21,1,WOOL:15)
Block(7,31,-7,SPRUCE_FENCE:0)
Block(7,32,-7,LOG:5)
Branch(0,0,-16,true,PillagerBoss_FloatC0R2,NORTH,100.0,0)
Entity(7,12,0,minecraft:armor_stand,1,../../NPCs/Random_Armorstand_02.txt)
Entity(7,12,4,minecraft:armor_stand,1,../../NPCs/Random_Armorstand_01.txt)
Entity(7,14,3,minecraft:parrot,1,../../NPCs/NPC_Parrot.txt)
