Author: NLBlackEagle
Description: No description given
SettingsMode: WriteDisable
Frequency: 0
SpawnHeight: highestBlock
UseCenterForHighestBlock: true
MinHeight: 0
MaxHeight: 255
InheritBO3: 
InheritBO3Rotation: NORTH
OverrideChildSettings: true
OverrideParentHeight: false
CanOverride: false
BranchFrequency: 0
BranchFrequencyGroup: 
MustBeBelowOther: false
MustBeInside: 
CannotBeInside: 
ReplacesBO3: 
MustBeInsideWorldBorders: false
CanSpawnOnWater: true
SpawnOnWaterOnly: false
SpawnUnderWater: false
SpawnAtWaterLevel: false
HeightOffset: 0
RemoveAir: true
ReplaceAbove: 
ReplaceBelow: 
ReplaceWithBiomeBlocks: true
ReplaceWithSurfaceBlock: GRASS
ReplaceWithGroundBlock: DIRT
ReplaceWithStoneBlock: STONE
SmoothRadius: 0
SmoothHeightOffset: 0
SmoothStartTop: false
SmoothStartWood: false
SmoothingSurfaceBlock: 
SmoothingGroundBlock: 
BO3Group: 
IsSpawnPoint: false
DoReplaceBlocks: true
E(-1,14,-6,stray,1,../NBT/Mobs/FrozenSailor.txt)
E(0,10,-5,stray,1,../NBT/Mobs/FrozenSailor.txt)
Block(-6,15,-3,FENCE:0)
Block(-6,16,-3,WOOL:0)
Block(-6,25,-4,WOOL:0)
Block(-6,25,-3,WOOL:0)
Block(-5,11,-4,ICE:0)
Block(-5,12,-4,ICE:0)
Block(-5,13,-4,ICE:0)
Block(-5,14,-4,PACKED_ICE:0)
Block(-5,15,-4,FENCE:0)
Block(-5,15,-3,FENCE:0)
Block(-5,17,-2,WOOL:0)
Block(-5,18,-1,WOOL:0)
Block(-5,21,-7,WOOL:0)
Block(-5,23,0,WOOL:0)
Block(-5,24,-1,WOOL:0)
Block(-5,25,-2,WOOL:0)
Block(-4,10,-7,LADDER:4)
Block(-4,10,-6,LADDER:4)
Block(-4,11,-7,ICE:0)
Block(-4,14,-5,FENCE:0)
Block(-4,14,-4,FENCE:0)
Block(-4,15,-4,FENCE:0)
Block(-4,17,-1,WOOL:0)
Block(-4,18,0,WOOL:0)
Block(-4,19,0,WOOL:0)
Block(-4,20,-7,WOOL:0)
Block(-4,20,-2,ICE:0)
Block(-4,20,1,WOOL:0)
Block(-4,21,-7,WOOL:0)
Block(-4,21,-2,PACKED_ICE:0)
Block(-4,21,1,WOOL:0)
Block(-4,22,-7,WOOL:0)
Block(-4,22,-2,ICE:0)
Block(-4,22,0,WOOL:0)
Block(-4,23,-2,PACKED_ICE:0)
Block(-4,23,0,WOOL:0)
Block(-4,24,-2,FENCE:0)
Block(-4,24,-1,WOOL:0)
Block(-4,25,-2,LOG:5)
Block(-4,25,-1,STONE_BUTTON:3)
Block(-4,26,-2,SNOW:4)
Block(-3,8,-7,WOOD:5)
Block(-3,8,-5,ICE:0)
Block(-3,9,-7,WOOD:5)
Block(-3,9,-6,WOOD:5)
Block(-3,9,-5,ICE:0)
Block(-3,9,-4,PACKED_ICE:0)
Block(-3,9,0,ICE:0)
Block(-3,10,-7,WOOD:1)
Block(-3,10,-6,WOOD:1)
Block(-3,10,-5,ICE:0)
Block(-3,10,-4,PACKED_ICE:0)
Block(-3,10,-3,PACKED_ICE:0)
Block(-3,10,0,ICE:0)
Block(-3,11,-7,WOOD:5)
Block(-3,11,-6,ICE:0)
Block(-3,11,-5,PACKED_ICE:0)
Block(-3,11,-3,PACKED_ICE:0)
Block(-3,11,0,ICE:0)
Block(-3,12,-7,WOOD_BUTTON:2)
Block(-3,12,-6,PACKED_ICE:0)
Block(-3,12,-5,ICE:0)
Block(-3,12,-4,ICE:0)
Block(-3,12,-2,ICE:0)
Block(-3,12,0,PACKED_ICE:0)
Block(-3,12,1,FENCE:0)
Block(-3,12,2,FENCE:0)
Block(-3,12,3,WOOL:0)
Block(-3,12,4,WOOL:0)
Block(-3,13,-4,PACKED_ICE:0)
Block(-3,13,-3,ICE:0)
Block(-3,13,-2,ICE:0)
Block(-3,13,0,FENCE:0)
Block(-3,13,1,FENCE:0)
Block(-3,14,-5,FENCE:0)
Block(-3,14,-3,ICE:0)
Block(-3,15,-5,WOOD_BUTTON:2)
Block(-3,15,-4,WOOD_BUTTON:2)
Block(-3,15,-3,WOOD_BUTTON:2)
Block(-3,15,-2,WOOD_BUTTON:2)
Block(-3,15,-1,WOOD_BUTTON:2)
Block(-3,17,-1,WOOL:0)
Block(-3,17,3,WOOL:0)
Block(-3,17,4,WOOL:0)
Block(-3,18,0,WOOL:0)
Block(-3,19,-7,WOOL:0)
Block(-3,19,1,WOOL:0)
Block(-3,20,-7,WOOL:14)
Block(-3,20,1,WOOL:0)
Block(-3,21,-7,WOOL:14)
Block(-3,21,1,WOOL:0)
Block(-3,22,-7,WOOL:14)
Block(-3,22,0,WOOL:0)
Block(-3,23,-7,WOOL:0)
Block(-3,23,0,WOOL:0)
Block(-3,24,-2,FENCE:0)
Block(-3,24,-1,WOOL:0)
Block(-3,25,-2,LOG:5)
Block(-3,25,-1,STONE_BUTTON:3)
Block(-3,26,-2,SNOW:2)
Block(-2,7,-7,WOOD:5)
Block(-2,7,-6,WOOD:5)
RandomBlock(-2,8,-7,AIR:0,20,CHEST:5,../../../../Chests/Loot/ShipJunk_1.nbt,10,CHEST:5,../../../../Chests/Loot/ShipJunk_2.nbt,10,CHEST:5,../../../../Chests/Loot/ShipJunk_3.nbt,10,CHEST:5,../../../../Chests/Loot/ShipJunk_4.nbt,10,CHEST:5,../../../../Chests/Loot/ShipJunk_5.nbt,10,CHEST:5,../../../../Chests/Lore/Frozen_1.nbt,1,CHEST:5,../../../../Chests/Lore/Frozen_2.nbt,1,CHEST:5,../../../../Chests/Lore/Frozen_3.nbt,1,CHEST:5,../../../../Chests/Lore/Frozen_4.nbt,1,CHEST:5,../../../../Chests/Lore/Frozen_5.nbt,1,CHEST:5,../../../../Chests/Loot/Common1.nbt,10,CHEST:5,../../../../Chests/Loot/Common2.nbt,10,CHEST:5,../../../../Chests/Loot/Common3.nbt,10,CHEST:5,../../../../Chests/Loot/Common4.nbt,10,CHEST:5,../../../../Chests/Loot/Common5.nbt,10,CHEST:5,../../../../Chests/Loot/Common6.nbt,10,CHEST:5,../../../../Chests/Loot/Common7.nbt,10,CHEST:5,../../../../Chests/Loot/Common8.nbt,10,CHEST:5,../../../../Chests/Loot/Common9.nbt,10,CHEST:5,../../../../Chests/Loot/Common10.nbt,10,CHEST:5,../../../../Chests/Loot/Common10.nbt,11,CHEST:5,../../../../Chests/Loot/Common12.nbt,10,CHEST:5,../../../../Chests/Loot/Common13.nbt,10,CHEST:5,../../../../Chests/Loot/Common14.nbt,10,CHEST:5,../../../../Chests/Loot/Common15.nbt,10,CHEST:5,../../../../Chests/Lore/Frozen_1.nbt,2,CHEST:5,../../../../Chests/Lore/Frozen_3.nbt,2,CHEST:5,../../../../Chests/Lore/Frozen_4.nbt,2,CHEST:5,../../../../Chests/Lore/Frozen_5.nbt,2,CHEST:5,../../../../Chests/Lore/Frozen_5.nbt,2,CHEST:5,../../../../Chests/Loot/Rare1.nbt,5,CHEST:5,../../../../Chests/Loot/Rare2.nbt,5,CHEST:5,../../../../Chests/Loot/Rare3.nbt,5,CHEST:5,../../../../Chests/Loot/Rare4.nbt,5,CHEST:5,../../../../Chests/Loot/Rare5.nbt,5,CHEST:5,../../../../Chests/Loot/Rare6.nbt,5,CHEST:5,../../../../Chests/Loot/Rare7.nbt,5,CHEST:5,../../../../Chests/Loot/Rare8.nbt,5,CHEST:5,../../../../Chests/Loot/Rare9.nbt,5,CHEST:5,../../../../Chests/Loot/Rare10.nbt,5,CHEST:5,../../../../Chests/Loot/Rare11.nbt,5,CHEST:5,../../../../Chests/Loot/Rare12.nbt,5,CHEST:5,../../../../Chests/Loot/Rare13.nbt,5,CHEST:5,../../../../Chests/Loot/Rare14.nbt,5,CHEST:5,../../../../Chests/Loot/Rare15.nbt,5,CHEST:5,../../../../Chests/Loot/Epic1.nbt,2,CHEST:5,../../../../Chests/Loot/Epic2.nbt,2,CHEST:5,../../../../Chests/Loot/Epic3.nbt,2,CHEST:5,../../../../Chests/Loot/Epic4.nbt,2,CHEST:5,../../../../Chests/Loot/Epic5.nbt,2,CHEST:5,../../../../Chests/Loot/Epic6.nbt,2,CHEST:5,../../../../Chests/Loot/Epic7.nbt,2,CHEST:5,../../../../Chests/Loot/Epic8.nbt,2,CHEST:5,../../../../Chests/Loot/Epic9.nbt,2,CHEST:5,../../../../Chests/Loot/Epic10.nbt,2,CHEST:5,../../../../Chests/Loot/Epic11.nbt,2,CHEST:5,../../../../Chests/Loot/Epic12.nbt,2,CHEST:5,../../../../Chests/Loot/Epic13.nbt,2,CHEST:5,../../../../Chests/Loot/Epic14.nbt,2,CHEST:5,../../../../Chests/Loot/Epic15.nbt,5,CHEST:5,../../../../Chests/Loot/Rare1.nbt,5,CHEST:5,../../../../Chests/Loot/Rare2.nbt,5,CHEST:5,../../../../Chests/Loot/Rare3.nbt,5,CHEST:5,../../../../Chests/Loot/Rare4.nbt,5,CHEST:5,../../../../Chests/Loot/Rare5.nbt,10,CHEST:5,../../../../Chests/Loot/Rare6.nbt,10,CHEST:5,../../../../Chests/Loot/Rare7.nbt,10,CHEST:5,../../../../Chests/Loot/Rare8.nbt,10,CHEST:5,../../../../Chests/Loot/Rare9.nbt,10,CHEST:5,../../../../Chests/Loot/Rare10.nbt,15,CHEST:5,../../../../Chests/Loot/Rare11.nbt,15,CHEST:5,../../../../Chests/Loot/Rare12.nbt,15,CHEST:5,../../../../Chests/Loot/Rare13.nbt,15,CHEST:5,../../../../Chests/Loot/Rare14.nbt,15,CHEST:5,../../../../Chests/Loot/Rare15.nbt,15,CHEST:5,../../../../Chests/Loot/Epic15.nbt,100)
Block(-2,8,-6,WOOD:5)
Block(-2,8,-5,WOOD:5)
Block(-2,8,-4,WOOD:5)
Block(-2,9,-7,WOOD_STEP:9)
Block(-2,9,-6,WOOD:5)
Block(-2,9,-5,WOOD:5)
Block(-2,9,-4,WOOD:5)
Block(-2,9,-3,WOOD:5)
Block(-2,9,-2,ICE:0)
RandomBlock(-2,10,-7,AIR:0,20,CHEST:5,../../../../Chests/Loot/ShipJunk_1.nbt,10,CHEST:5,../../../../Chests/Loot/ShipJunk_2.nbt,10,CHEST:5,../../../../Chests/Loot/ShipJunk_3.nbt,10,CHEST:5,../../../../Chests/Loot/ShipJunk_4.nbt,10,CHEST:5,../../../../Chests/Loot/ShipJunk_5.nbt,10,CHEST:5,../../../../Chests/Lore/Frozen_1.nbt,1,CHEST:5,../../../../Chests/Lore/Frozen_2.nbt,1,CHEST:5,../../../../Chests/Lore/Frozen_3.nbt,1,CHEST:5,../../../../Chests/Lore/Frozen_4.nbt,1,CHEST:5,../../../../Chests/Lore/Frozen_5.nbt,1,CHEST:5,../../../../Chests/Loot/Common1.nbt,10,CHEST:5,../../../../Chests/Loot/Common2.nbt,10,CHEST:5,../../../../Chests/Loot/Common3.nbt,10,CHEST:5,../../../../Chests/Loot/Common4.nbt,10,CHEST:5,../../../../Chests/Loot/Common5.nbt,10,CHEST:5,../../../../Chests/Loot/Common6.nbt,10,CHEST:5,../../../../Chests/Loot/Common7.nbt,10,CHEST:5,../../../../Chests/Loot/Common8.nbt,10,CHEST:5,../../../../Chests/Loot/Common9.nbt,10,CHEST:5,../../../../Chests/Loot/Common10.nbt,10,CHEST:5,../../../../Chests/Loot/Common10.nbt,11,CHEST:5,../../../../Chests/Loot/Common12.nbt,10,CHEST:5,../../../../Chests/Loot/Common13.nbt,10,CHEST:5,../../../../Chests/Loot/Common14.nbt,10,CHEST:5,../../../../Chests/Loot/Common15.nbt,10,CHEST:5,../../../../Chests/Lore/Frozen_1.nbt,2,CHEST:5,../../../../Chests/Lore/Frozen_3.nbt,2,CHEST:5,../../../../Chests/Lore/Frozen_4.nbt,2,CHEST:5,../../../../Chests/Lore/Frozen_5.nbt,2,CHEST:5,../../../../Chests/Lore/Frozen_5.nbt,2,CHEST:5,../../../../Chests/Loot/Rare1.nbt,5,CHEST:5,../../../../Chests/Loot/Rare2.nbt,5,CHEST:5,../../../../Chests/Loot/Rare3.nbt,5,CHEST:5,../../../../Chests/Loot/Rare4.nbt,5,CHEST:5,../../../../Chests/Loot/Rare5.nbt,5,CHEST:5,../../../../Chests/Loot/Rare6.nbt,5,CHEST:5,../../../../Chests/Loot/Rare7.nbt,5,CHEST:5,../../../../Chests/Loot/Rare8.nbt,5,CHEST:5,../../../../Chests/Loot/Rare9.nbt,5,CHEST:5,../../../../Chests/Loot/Rare10.nbt,5,CHEST:5,../../../../Chests/Loot/Rare11.nbt,5,CHEST:5,../../../../Chests/Loot/Rare12.nbt,5,CHEST:5,../../../../Chests/Loot/Rare13.nbt,5,CHEST:5,../../../../Chests/Loot/Rare14.nbt,5,CHEST:5,../../../../Chests/Loot/Rare15.nbt,5,CHEST:5,../../../../Chests/Loot/Epic1.nbt,2,CHEST:5,../../../../Chests/Loot/Epic2.nbt,2,CHEST:5,../../../../Chests/Loot/Epic3.nbt,2,CHEST:5,../../../../Chests/Loot/Epic4.nbt,2,CHEST:5,../../../../Chests/Loot/Epic5.nbt,2,CHEST:5,../../../../Chests/Loot/Epic6.nbt,2,CHEST:5,../../../../Chests/Loot/Epic7.nbt,2,CHEST:5,../../../../Chests/Loot/Epic8.nbt,2,CHEST:5,../../../../Chests/Loot/Epic9.nbt,2,CHEST:5,../../../../Chests/Loot/Epic10.nbt,2,CHEST:5,../../../../Chests/Loot/Epic11.nbt,2,CHEST:5,../../../../Chests/Loot/Epic12.nbt,2,CHEST:5,../../../../Chests/Loot/Epic13.nbt,2,CHEST:5,../../../../Chests/Loot/Epic14.nbt,2,CHEST:5,../../../../Chests/Loot/Epic15.nbt,5,CHEST:5,../../../../Chests/Loot/Rare1.nbt,5,CHEST:5,../../../../Chests/Loot/Rare2.nbt,5,CHEST:5,../../../../Chests/Loot/Rare3.nbt,5,CHEST:5,../../../../Chests/Loot/Rare4.nbt,5,CHEST:5,../../../../Chests/Loot/Rare5.nbt,10,CHEST:5,../../../../Chests/Loot/Rare6.nbt,10,CHEST:5,../../../../Chests/Loot/Rare7.nbt,10,CHEST:5,../../../../Chests/Loot/Rare8.nbt,10,CHEST:5,../../../../Chests/Loot/Rare9.nbt,10,CHEST:5,../../../../Chests/Loot/Rare10.nbt,15,CHEST:5,../../../../Chests/Loot/Rare11.nbt,15,CHEST:5,../../../../Chests/Loot/Rare12.nbt,15,CHEST:5,../../../../Chests/Loot/Rare13.nbt,15,CHEST:5,../../../../Chests/Loot/Rare14.nbt,15,CHEST:5,../../../../Chests/Loot/Rare15.nbt,15,CHEST:5,../../../../Chests/Loot/Epic15.nbt,100)
Block(-2,10,-6,WOOD:5)
Block(-2,10,-5,WOOD:1)
Block(-2,10,-4,WOOD:1)
Block(-2,10,-3,WOOD:5)
Block(-2,10,-2,PACKED_ICE:0)
RandomBlock(-2,11,-7,AIR:0,20,CHEST:5,../../../../Chests/Loot/ShipJunk_1.nbt,10,CHEST:5,../../../../Chests/Loot/ShipJunk_2.nbt,10,CHEST:5,../../../../Chests/Loot/ShipJunk_3.nbt,10,CHEST:5,../../../../Chests/Loot/ShipJunk_4.nbt,10,CHEST:5,../../../../Chests/Loot/ShipJunk_5.nbt,10,CHEST:5,../../../../Chests/Lore/Frozen_1.nbt,1,CHEST:5,../../../../Chests/Lore/Frozen_2.nbt,1,CHEST:5,../../../../Chests/Lore/Frozen_3.nbt,1,CHEST:5,../../../../Chests/Lore/Frozen_4.nbt,1,CHEST:5,../../../../Chests/Lore/Frozen_5.nbt,1,CHEST:5,../../../../Chests/Loot/Common1.nbt,10,CHEST:5,../../../../Chests/Loot/Common2.nbt,10,CHEST:5,../../../../Chests/Loot/Common3.nbt,10,CHEST:5,../../../../Chests/Loot/Common4.nbt,10,CHEST:5,../../../../Chests/Loot/Common5.nbt,10,CHEST:5,../../../../Chests/Loot/Common6.nbt,10,CHEST:5,../../../../Chests/Loot/Common7.nbt,10,CHEST:5,../../../../Chests/Loot/Common8.nbt,10,CHEST:5,../../../../Chests/Loot/Common9.nbt,10,CHEST:5,../../../../Chests/Loot/Common10.nbt,10,CHEST:5,../../../../Chests/Loot/Common10.nbt,11,CHEST:5,../../../../Chests/Loot/Common12.nbt,10,CHEST:5,../../../../Chests/Loot/Common13.nbt,10,CHEST:5,../../../../Chests/Loot/Common14.nbt,10,CHEST:5,../../../../Chests/Loot/Common15.nbt,10,CHEST:5,../../../../Chests/Lore/Frozen_1.nbt,2,CHEST:5,../../../../Chests/Lore/Frozen_3.nbt,2,CHEST:5,../../../../Chests/Lore/Frozen_4.nbt,2,CHEST:5,../../../../Chests/Lore/Frozen_5.nbt,2,CHEST:5,../../../../Chests/Lore/Frozen_5.nbt,2,CHEST:5,../../../../Chests/Loot/Rare1.nbt,5,CHEST:5,../../../../Chests/Loot/Rare2.nbt,5,CHEST:5,../../../../Chests/Loot/Rare3.nbt,5,CHEST:5,../../../../Chests/Loot/Rare4.nbt,5,CHEST:5,../../../../Chests/Loot/Rare5.nbt,5,CHEST:5,../../../../Chests/Loot/Rare6.nbt,5,CHEST:5,../../../../Chests/Loot/Rare7.nbt,5,CHEST:5,../../../../Chests/Loot/Rare8.nbt,5,CHEST:5,../../../../Chests/Loot/Rare9.nbt,5,CHEST:5,../../../../Chests/Loot/Rare10.nbt,5,CHEST:5,../../../../Chests/Loot/Rare11.nbt,5,CHEST:5,../../../../Chests/Loot/Rare12.nbt,5,CHEST:5,../../../../Chests/Loot/Rare13.nbt,5,CHEST:5,../../../../Chests/Loot/Rare14.nbt,5,CHEST:5,../../../../Chests/Loot/Rare15.nbt,5,CHEST:5,../../../../Chests/Loot/Epic1.nbt,2,CHEST:5,../../../../Chests/Loot/Epic2.nbt,2,CHEST:5,../../../../Chests/Loot/Epic3.nbt,2,CHEST:5,../../../../Chests/Loot/Epic4.nbt,2,CHEST:5,../../../../Chests/Loot/Epic5.nbt,2,CHEST:5,../../../../Chests/Loot/Epic6.nbt,2,CHEST:5,../../../../Chests/Loot/Epic7.nbt,2,CHEST:5,../../../../Chests/Loot/Epic8.nbt,2,CHEST:5,../../../../Chests/Loot/Epic9.nbt,2,CHEST:5,../../../../Chests/Loot/Epic10.nbt,2,CHEST:5,../../../../Chests/Loot/Epic11.nbt,2,CHEST:5,../../../../Chests/Loot/Epic12.nbt,2,CHEST:5,../../../../Chests/Loot/Epic13.nbt,2,CHEST:5,../../../../Chests/Loot/Epic14.nbt,2,CHEST:5,../../../../Chests/Loot/Epic15.nbt,5,CHEST:5,../../../../Chests/Loot/Rare1.nbt,5,CHEST:5,../../../../Chests/Loot/Rare2.nbt,5,CHEST:5,../../../../Chests/Loot/Rare3.nbt,5,CHEST:5,../../../../Chests/Loot/Rare4.nbt,5,CHEST:5,../../../../Chests/Loot/Rare5.nbt,10,CHEST:5,../../../../Chests/Loot/Rare6.nbt,10,CHEST:5,../../../../Chests/Loot/Rare7.nbt,10,CHEST:5,../../../../Chests/Loot/Rare8.nbt,10,CHEST:5,../../../../Chests/Loot/Rare9.nbt,10,CHEST:5,../../../../Chests/Loot/Rare10.nbt,15,CHEST:5,../../../../Chests/Loot/Rare11.nbt,15,CHEST:5,../../../../Chests/Loot/Rare12.nbt,15,CHEST:5,../../../../Chests/Loot/Rare13.nbt,15,CHEST:5,../../../../Chests/Loot/Rare14.nbt,15,CHEST:5,../../../../Chests/Loot/Rare15.nbt,15,CHEST:5,../../../../Chests/Loot/Epic15.nbt,100)
Block(-2,11,-6,WOOD:5)
Block(-2,11,-5,WOOD:5)
Block(-2,11,-4,WOOD:5)
Block(-2,11,-3,WOOD:1)
Block(-2,11,-2,PACKED_ICE:0)
Block(-2,11,-1,PACKED_ICE:0)
Block(-2,12,-7,WOOD:1)
Block(-2,12,-6,WOOD:5)
Block(-2,12,-5,WOOD:5)
Block(-2,12,-4,WOOD:1)
Block(-2,12,-3,WOOD:5)
Block(-2,12,-2,PACKED_ICE:0)
Block(-2,12,-1,PACKED_ICE:0)
Block(-2,13,-7,WOOD_STEP:5)
Block(-2,13,-6,SNOW:0)
Block(-2,13,-5,WOOD:5)
Block(-2,13,-4,WOOD:1)
Block(-2,13,-3,WOOD:5)
Block(-2,13,-2,ICE:0)
Block(-2,13,-1,FENCE:0)
Block(-2,13,0,FENCE:0)
Block(-2,13,5,WOOL:0)
Block(-2,14,-5,WOOD:5)
Block(-2,14,-4,WOOD:1)
Block(-2,14,-3,WOOD:1)
Block(-2,14,-2,WOOD:5)
Block(-2,14,-1,FENCE:0)
Block(-2,14,0,ICE:0)
Block(-2,14,5,WOOL:0)
Block(-2,15,-5,WOOD:5)
Block(-2,15,-4,WOOD:5)
Block(-2,15,-3,WOOD:5)
Block(-2,15,-2,WOOD:5)
Block(-2,15,-1,WOOD:5)
Block(-2,15,0,WOOD_STEP:13)
Block(-2,15,1,PACKED_ICE:0)
Block(-2,16,-5,FENCE:0)
Block(-2,16,-4,FENCE:0)
Block(-2,16,-3,FENCE:0)
Block(-2,16,-2,FENCE:0)
Block(-2,16,-1,FENCE:0)
Block(-2,16,0,FENCE:0)
Block(-2,16,4,WOOL:0)
Block(-2,17,-1,WOOL:0)
Block(-2,17,4,FENCE:0)
Block(-2,17,5,WOOL:0)
Block(-2,18,0,WOOL:0)
Block(-2,18,4,WOOD_STEP:5)
Block(-2,19,-7,WOOL:0)
Block(-2,19,1,WOOL:0)
Block(-2,20,-7,WOOL:0)
Block(-2,20,1,WOOL:14)
Block(-2,21,-6,WOOL:14)
Block(-2,21,1,WOOL:14)
Block(-2,22,-6,WOOL:0)
Block(-2,22,1,WOOL:14)
Block(-2,23,-7,WOOL:0)
Block(-2,23,0,WOOL:0)
Block(-2,24,-7,WOOL:0)
Block(-2,24,-2,FENCE:0)
Block(-2,24,-1,WOOL:0)
Block(-2,25,-2,LOG:5)
Block(-2,25,-1,STONE_BUTTON:3)
Block(-2,26,-2,SNOW:3)
Block(-2,28,-7,WOOL:0)
Block(-1,6,-7,ICE:0)
Block(-1,7,-7,WOOD:5)
Block(-1,7,-6,WOOD:5)
Block(-1,7,-5,WOOD:5)
Block(-1,7,-4,WOOD:5)
Block(-1,7,-3,ICE:0)
Block(-1,8,-7,AIR:0)
RandomBlock(-1,8,-6,AIR:0,20,CHEST:5,../../../../Chests/Loot/ShipJunk_1.nbt,10,CHEST:5,../../../../Chests/Loot/ShipJunk_2.nbt,10,CHEST:5,../../../../Chests/Loot/ShipJunk_3.nbt,10,CHEST:5,../../../../Chests/Loot/ShipJunk_4.nbt,10,CHEST:5,../../../../Chests/Loot/ShipJunk_5.nbt,10,CHEST:5,../../../../Chests/Lore/Frozen_1.nbt,1,CHEST:5,../../../../Chests/Lore/Frozen_2.nbt,1,CHEST:5,../../../../Chests/Lore/Frozen_3.nbt,1,CHEST:5,../../../../Chests/Lore/Frozen_4.nbt,1,CHEST:5,../../../../Chests/Lore/Frozen_5.nbt,1,CHEST:5,../../../../Chests/Loot/Common1.nbt,10,CHEST:5,../../../../Chests/Loot/Common2.nbt,10,CHEST:5,../../../../Chests/Loot/Common3.nbt,10,CHEST:5,../../../../Chests/Loot/Common4.nbt,10,CHEST:5,../../../../Chests/Loot/Common5.nbt,10,CHEST:5,../../../../Chests/Loot/Common6.nbt,10,CHEST:5,../../../../Chests/Loot/Common7.nbt,10,CHEST:5,../../../../Chests/Loot/Common8.nbt,10,CHEST:5,../../../../Chests/Loot/Common9.nbt,10,CHEST:5,../../../../Chests/Loot/Common10.nbt,10,CHEST:5,../../../../Chests/Loot/Common10.nbt,11,CHEST:5,../../../../Chests/Loot/Common12.nbt,10,CHEST:5,../../../../Chests/Loot/Common13.nbt,10,CHEST:5,../../../../Chests/Loot/Common14.nbt,10,CHEST:5,../../../../Chests/Loot/Common15.nbt,10,CHEST:5,../../../../Chests/Lore/Frozen_1.nbt,2,CHEST:5,../../../../Chests/Lore/Frozen_3.nbt,2,CHEST:5,../../../../Chests/Lore/Frozen_4.nbt,2,CHEST:5,../../../../Chests/Lore/Frozen_5.nbt,2,CHEST:5,../../../../Chests/Lore/Frozen_5.nbt,2,CHEST:5,../../../../Chests/Loot/Rare1.nbt,5,CHEST:5,../../../../Chests/Loot/Rare2.nbt,5,CHEST:5,../../../../Chests/Loot/Rare3.nbt,5,CHEST:5,../../../../Chests/Loot/Rare4.nbt,5,CHEST:5,../../../../Chests/Loot/Rare5.nbt,5,CHEST:5,../../../../Chests/Loot/Rare6.nbt,5,CHEST:5,../../../../Chests/Loot/Rare7.nbt,5,CHEST:5,../../../../Chests/Loot/Rare8.nbt,5,CHEST:5,../../../../Chests/Loot/Rare9.nbt,5,CHEST:5,../../../../Chests/Loot/Rare10.nbt,5,CHEST:5,../../../../Chests/Loot/Rare11.nbt,5,CHEST:5,../../../../Chests/Loot/Rare12.nbt,5,CHEST:5,../../../../Chests/Loot/Rare13.nbt,5,CHEST:5,../../../../Chests/Loot/Rare14.nbt,5,CHEST:5,../../../../Chests/Loot/Rare15.nbt,5,CHEST:5,../../../../Chests/Loot/Epic1.nbt,2,CHEST:5,../../../../Chests/Loot/Epic2.nbt,2,CHEST:5,../../../../Chests/Loot/Epic3.nbt,2,CHEST:5,../../../../Chests/Loot/Epic4.nbt,2,CHEST:5,../../../../Chests/Loot/Epic5.nbt,2,CHEST:5,../../../../Chests/Loot/Epic6.nbt,2,CHEST:5,../../../../Chests/Loot/Epic7.nbt,2,CHEST:5,../../../../Chests/Loot/Epic8.nbt,2,CHEST:5,../../../../Chests/Loot/Epic9.nbt,2,CHEST:5,../../../../Chests/Loot/Epic10.nbt,2,CHEST:5,../../../../Chests/Loot/Epic11.nbt,2,CHEST:5,../../../../Chests/Loot/Epic12.nbt,2,CHEST:5,../../../../Chests/Loot/Epic13.nbt,2,CHEST:5,../../../../Chests/Loot/Epic14.nbt,2,CHEST:5,../../../../Chests/Loot/Epic15.nbt,5,CHEST:5,../../../../Chests/Loot/Rare1.nbt,5,CHEST:5,../../../../Chests/Loot/Rare2.nbt,5,CHEST:5,../../../../Chests/Loot/Rare3.nbt,5,CHEST:5,../../../../Chests/Loot/Rare4.nbt,5,CHEST:5,../../../../Chests/Loot/Rare5.nbt,10,CHEST:5,../../../../Chests/Loot/Rare6.nbt,10,CHEST:5,../../../../Chests/Loot/Rare7.nbt,10,CHEST:5,../../../../Chests/Loot/Rare8.nbt,10,CHEST:5,../../../../Chests/Loot/Rare9.nbt,10,CHEST:5,../../../../Chests/Loot/Rare10.nbt,15,CHEST:5,../../../../Chests/Loot/Rare11.nbt,15,CHEST:5,../../../../Chests/Loot/Rare12.nbt,15,CHEST:5,../../../../Chests/Loot/Rare13.nbt,15,CHEST:5,../../../../Chests/Loot/Rare14.nbt,15,CHEST:5,../../../../Chests/Loot/Rare15.nbt,15,CHEST:5,../../../../Chests/Loot/Epic15.nbt,100)
RandomBlock(-1,8,-5,AIR:0,20,CHEST:5,../../../../Chests/Loot/ShipJunk_1.nbt,10,CHEST:5,../../../../Chests/Loot/ShipJunk_2.nbt,10,CHEST:5,../../../../Chests/Loot/ShipJunk_3.nbt,10,CHEST:5,../../../../Chests/Loot/ShipJunk_4.nbt,10,CHEST:5,../../../../Chests/Loot/ShipJunk_5.nbt,10,CHEST:5,../../../../Chests/Lore/Frozen_1.nbt,1,CHEST:5,../../../../Chests/Lore/Frozen_2.nbt,1,CHEST:5,../../../../Chests/Lore/Frozen_3.nbt,1,CHEST:5,../../../../Chests/Lore/Frozen_4.nbt,1,CHEST:5,../../../../Chests/Lore/Frozen_5.nbt,1,CHEST:5,../../../../Chests/Loot/Common1.nbt,10,CHEST:5,../../../../Chests/Loot/Common2.nbt,10,CHEST:5,../../../../Chests/Loot/Common3.nbt,10,CHEST:5,../../../../Chests/Loot/Common4.nbt,10,CHEST:5,../../../../Chests/Loot/Common5.nbt,10,CHEST:5,../../../../Chests/Loot/Common6.nbt,10,CHEST:5,../../../../Chests/Loot/Common7.nbt,10,CHEST:5,../../../../Chests/Loot/Common8.nbt,10,CHEST:5,../../../../Chests/Loot/Common9.nbt,10,CHEST:5,../../../../Chests/Loot/Common10.nbt,10,CHEST:5,../../../../Chests/Loot/Common10.nbt,11,CHEST:5,../../../../Chests/Loot/Common12.nbt,10,CHEST:5,../../../../Chests/Loot/Common13.nbt,10,CHEST:5,../../../../Chests/Loot/Common14.nbt,10,CHEST:5,../../../../Chests/Loot/Common15.nbt,10,CHEST:5,../../../../Chests/Lore/Frozen_1.nbt,2,CHEST:5,../../../../Chests/Lore/Frozen_3.nbt,2,CHEST:5,../../../../Chests/Lore/Frozen_4.nbt,2,CHEST:5,../../../../Chests/Lore/Frozen_5.nbt,2,CHEST:5,../../../../Chests/Lore/Frozen_5.nbt,2,CHEST:5,../../../../Chests/Loot/Rare1.nbt,5,CHEST:5,../../../../Chests/Loot/Rare2.nbt,5,CHEST:5,../../../../Chests/Loot/Rare3.nbt,5,CHEST:5,../../../../Chests/Loot/Rare4.nbt,5,CHEST:5,../../../../Chests/Loot/Rare5.nbt,5,CHEST:5,../../../../Chests/Loot/Rare6.nbt,5,CHEST:5,../../../../Chests/Loot/Rare7.nbt,5,CHEST:5,../../../../Chests/Loot/Rare8.nbt,5,CHEST:5,../../../../Chests/Loot/Rare9.nbt,5,CHEST:5,../../../../Chests/Loot/Rare10.nbt,5,CHEST:5,../../../../Chests/Loot/Rare11.nbt,5,CHEST:5,../../../../Chests/Loot/Rare12.nbt,5,CHEST:5,../../../../Chests/Loot/Rare13.nbt,5,CHEST:5,../../../../Chests/Loot/Rare14.nbt,5,CHEST:5,../../../../Chests/Loot/Rare15.nbt,5,CHEST:5,../../../../Chests/Loot/Epic1.nbt,2,CHEST:5,../../../../Chests/Loot/Epic2.nbt,2,CHEST:5,../../../../Chests/Loot/Epic3.nbt,2,CHEST:5,../../../../Chests/Loot/Epic4.nbt,2,CHEST:5,../../../../Chests/Loot/Epic5.nbt,2,CHEST:5,../../../../Chests/Loot/Epic6.nbt,2,CHEST:5,../../../../Chests/Loot/Epic7.nbt,2,CHEST:5,../../../../Chests/Loot/Epic8.nbt,2,CHEST:5,../../../../Chests/Loot/Epic9.nbt,2,CHEST:5,../../../../Chests/Loot/Epic10.nbt,2,CHEST:5,../../../../Chests/Loot/Epic11.nbt,2,CHEST:5,../../../../Chests/Loot/Epic12.nbt,2,CHEST:5,../../../../Chests/Loot/Epic13.nbt,2,CHEST:5,../../../../Chests/Loot/Epic14.nbt,2,CHEST:5,../../../../Chests/Loot/Epic15.nbt,5,CHEST:5,../../../../Chests/Loot/Rare1.nbt,5,CHEST:5,../../../../Chests/Loot/Rare2.nbt,5,CHEST:5,../../../../Chests/Loot/Rare3.nbt,5,CHEST:5,../../../../Chests/Loot/Rare4.nbt,5,CHEST:5,../../../../Chests/Loot/Rare5.nbt,10,CHEST:5,../../../../Chests/Loot/Rare6.nbt,10,CHEST:5,../../../../Chests/Loot/Rare7.nbt,10,CHEST:5,../../../../Chests/Loot/Rare8.nbt,10,CHEST:5,../../../../Chests/Loot/Rare9.nbt,10,CHEST:5,../../../../Chests/Loot/Rare10.nbt,15,CHEST:5,../../../../Chests/Loot/Rare11.nbt,15,CHEST:5,../../../../Chests/Loot/Rare12.nbt,15,CHEST:5,../../../../Chests/Loot/Rare13.nbt,15,CHEST:5,../../../../Chests/Loot/Rare14.nbt,15,CHEST:5,../../../../Chests/Loot/Rare15.nbt,15,CHEST:5,../../../../Chests/Loot/Epic15.nbt,100)
RandomBlock(-1,8,-4,AIR:0,20,CHEST:5,../../../../Chests/Loot/ShipJunk_1.nbt,10,CHEST:5,../../../../Chests/Loot/ShipJunk_2.nbt,10,CHEST:5,../../../../Chests/Loot/ShipJunk_3.nbt,10,CHEST:5,../../../../Chests/Loot/ShipJunk_4.nbt,10,CHEST:5,../../../../Chests/Loot/ShipJunk_5.nbt,10,CHEST:5,../../../../Chests/Lore/Frozen_1.nbt,1,CHEST:5,../../../../Chests/Lore/Frozen_2.nbt,1,CHEST:5,../../../../Chests/Lore/Frozen_3.nbt,1,CHEST:5,../../../../Chests/Lore/Frozen_4.nbt,1,CHEST:5,../../../../Chests/Lore/Frozen_5.nbt,1,CHEST:5,../../../../Chests/Loot/Common1.nbt,10,CHEST:5,../../../../Chests/Loot/Common2.nbt,10,CHEST:5,../../../../Chests/Loot/Common3.nbt,10,CHEST:5,../../../../Chests/Loot/Common4.nbt,10,CHEST:5,../../../../Chests/Loot/Common5.nbt,10,CHEST:5,../../../../Chests/Loot/Common6.nbt,10,CHEST:5,../../../../Chests/Loot/Common7.nbt,10,CHEST:5,../../../../Chests/Loot/Common8.nbt,10,CHEST:5,../../../../Chests/Loot/Common9.nbt,10,CHEST:5,../../../../Chests/Loot/Common10.nbt,10,CHEST:5,../../../../Chests/Loot/Common10.nbt,11,CHEST:5,../../../../Chests/Loot/Common12.nbt,10,CHEST:5,../../../../Chests/Loot/Common13.nbt,10,CHEST:5,../../../../Chests/Loot/Common14.nbt,10,CHEST:5,../../../../Chests/Loot/Common15.nbt,10,CHEST:5,../../../../Chests/Lore/Frozen_1.nbt,2,CHEST:5,../../../../Chests/Lore/Frozen_3.nbt,2,CHEST:5,../../../../Chests/Lore/Frozen_4.nbt,2,CHEST:5,../../../../Chests/Lore/Frozen_5.nbt,2,CHEST:5,../../../../Chests/Lore/Frozen_5.nbt,2,CHEST:5,../../../../Chests/Loot/Rare1.nbt,5,CHEST:5,../../../../Chests/Loot/Rare2.nbt,5,CHEST:5,../../../../Chests/Loot/Rare3.nbt,5,CHEST:5,../../../../Chests/Loot/Rare4.nbt,5,CHEST:5,../../../../Chests/Loot/Rare5.nbt,5,CHEST:5,../../../../Chests/Loot/Rare6.nbt,5,CHEST:5,../../../../Chests/Loot/Rare7.nbt,5,CHEST:5,../../../../Chests/Loot/Rare8.nbt,5,CHEST:5,../../../../Chests/Loot/Rare9.nbt,5,CHEST:5,../../../../Chests/Loot/Rare10.nbt,5,CHEST:5,../../../../Chests/Loot/Rare11.nbt,5,CHEST:5,../../../../Chests/Loot/Rare12.nbt,5,CHEST:5,../../../../Chests/Loot/Rare13.nbt,5,CHEST:5,../../../../Chests/Loot/Rare14.nbt,5,CHEST:5,../../../../Chests/Loot/Rare15.nbt,5,CHEST:5,../../../../Chests/Loot/Epic1.nbt,2,CHEST:5,../../../../Chests/Loot/Epic2.nbt,2,CHEST:5,../../../../Chests/Loot/Epic3.nbt,2,CHEST:5,../../../../Chests/Loot/Epic4.nbt,2,CHEST:5,../../../../Chests/Loot/Epic5.nbt,2,CHEST:5,../../../../Chests/Loot/Epic6.nbt,2,CHEST:5,../../../../Chests/Loot/Epic7.nbt,2,CHEST:5,../../../../Chests/Loot/Epic8.nbt,2,CHEST:5,../../../../Chests/Loot/Epic9.nbt,2,CHEST:5,../../../../Chests/Loot/Epic10.nbt,2,CHEST:5,../../../../Chests/Loot/Epic11.nbt,2,CHEST:5,../../../../Chests/Loot/Epic12.nbt,2,CHEST:5,../../../../Chests/Loot/Epic13.nbt,2,CHEST:5,../../../../Chests/Loot/Epic14.nbt,2,CHEST:5,../../../../Chests/Loot/Epic15.nbt,5,CHEST:5,../../../../Chests/Loot/Rare1.nbt,5,CHEST:5,../../../../Chests/Loot/Rare2.nbt,5,CHEST:5,../../../../Chests/Loot/Rare3.nbt,5,CHEST:5,../../../../Chests/Loot/Rare4.nbt,5,CHEST:5,../../../../Chests/Loot/Rare5.nbt,10,CHEST:5,../../../../Chests/Loot/Rare6.nbt,10,CHEST:5,../../../../Chests/Loot/Rare7.nbt,10,CHEST:5,../../../../Chests/Loot/Rare8.nbt,10,CHEST:5,../../../../Chests/Loot/Rare9.nbt,10,CHEST:5,../../../../Chests/Loot/Rare10.nbt,15,CHEST:5,../../../../Chests/Loot/Rare11.nbt,15,CHEST:5,../../../../Chests/Loot/Rare12.nbt,15,CHEST:5,../../../../Chests/Loot/Rare13.nbt,15,CHEST:5,../../../../Chests/Loot/Rare14.nbt,15,CHEST:5,../../../../Chests/Loot/Rare15.nbt,15,CHEST:5,../../../../Chests/Loot/Epic15.nbt,100)
Block(-1,8,-3,WOOD:5)
Block(-1,8,0,ICE:0)
Block(-1,9,-7,AIR:0)
RandomBlock(-1,9,-6,AIR:0,20,CHEST:5,../../../../Chests/Loot/ShipJunk_1.nbt,10,CHEST:5,../../../../Chests/Loot/ShipJunk_2.nbt,10,CHEST:5,../../../../Chests/Loot/ShipJunk_3.nbt,10,CHEST:5,../../../../Chests/Loot/ShipJunk_4.nbt,10,CHEST:5,../../../../Chests/Loot/ShipJunk_5.nbt,10,CHEST:5,../../../../Chests/Lore/Frozen_1.nbt,1,CHEST:5,../../../../Chests/Lore/Frozen_2.nbt,1,CHEST:5,../../../../Chests/Lore/Frozen_3.nbt,1,CHEST:5,../../../../Chests/Lore/Frozen_4.nbt,1,CHEST:5,../../../../Chests/Lore/Frozen_5.nbt,1,CHEST:5,../../../../Chests/Loot/Common1.nbt,10,CHEST:5,../../../../Chests/Loot/Common2.nbt,10,CHEST:5,../../../../Chests/Loot/Common3.nbt,10,CHEST:5,../../../../Chests/Loot/Common4.nbt,10,CHEST:5,../../../../Chests/Loot/Common5.nbt,10,CHEST:5,../../../../Chests/Loot/Common6.nbt,10,CHEST:5,../../../../Chests/Loot/Common7.nbt,10,CHEST:5,../../../../Chests/Loot/Common8.nbt,10,CHEST:5,../../../../Chests/Loot/Common9.nbt,10,CHEST:5,../../../../Chests/Loot/Common10.nbt,10,CHEST:5,../../../../Chests/Loot/Common10.nbt,11,CHEST:5,../../../../Chests/Loot/Common12.nbt,10,CHEST:5,../../../../Chests/Loot/Common13.nbt,10,CHEST:5,../../../../Chests/Loot/Common14.nbt,10,CHEST:5,../../../../Chests/Loot/Common15.nbt,10,CHEST:5,../../../../Chests/Lore/Frozen_1.nbt,2,CHEST:5,../../../../Chests/Lore/Frozen_3.nbt,2,CHEST:5,../../../../Chests/Lore/Frozen_4.nbt,2,CHEST:5,../../../../Chests/Lore/Frozen_5.nbt,2,CHEST:5,../../../../Chests/Lore/Frozen_5.nbt,2,CHEST:5,../../../../Chests/Loot/Rare1.nbt,5,CHEST:5,../../../../Chests/Loot/Rare2.nbt,5,CHEST:5,../../../../Chests/Loot/Rare3.nbt,5,CHEST:5,../../../../Chests/Loot/Rare4.nbt,5,CHEST:5,../../../../Chests/Loot/Rare5.nbt,5,CHEST:5,../../../../Chests/Loot/Rare6.nbt,5,CHEST:5,../../../../Chests/Loot/Rare7.nbt,5,CHEST:5,../../../../Chests/Loot/Rare8.nbt,5,CHEST:5,../../../../Chests/Loot/Rare9.nbt,5,CHEST:5,../../../../Chests/Loot/Rare10.nbt,5,CHEST:5,../../../../Chests/Loot/Rare11.nbt,5,CHEST:5,../../../../Chests/Loot/Rare12.nbt,5,CHEST:5,../../../../Chests/Loot/Rare13.nbt,5,CHEST:5,../../../../Chests/Loot/Rare14.nbt,5,CHEST:5,../../../../Chests/Loot/Rare15.nbt,5,CHEST:5,../../../../Chests/Loot/Epic1.nbt,2,CHEST:5,../../../../Chests/Loot/Epic2.nbt,2,CHEST:5,../../../../Chests/Loot/Epic3.nbt,2,CHEST:5,../../../../Chests/Loot/Epic4.nbt,2,CHEST:5,../../../../Chests/Loot/Epic5.nbt,2,CHEST:5,../../../../Chests/Loot/Epic6.nbt,2,CHEST:5,../../../../Chests/Loot/Epic7.nbt,2,CHEST:5,../../../../Chests/Loot/Epic8.nbt,2,CHEST:5,../../../../Chests/Loot/Epic9.nbt,2,CHEST:5,../../../../Chests/Loot/Epic10.nbt,2,CHEST:5,../../../../Chests/Loot/Epic11.nbt,2,CHEST:5,../../../../Chests/Loot/Epic12.nbt,2,CHEST:5,../../../../Chests/Loot/Epic13.nbt,2,CHEST:5,../../../../Chests/Loot/Epic14.nbt,2,CHEST:5,../../../../Chests/Loot/Epic15.nbt,5,CHEST:5,../../../../Chests/Loot/Rare1.nbt,5,CHEST:5,../../../../Chests/Loot/Rare2.nbt,5,CHEST:5,../../../../Chests/Loot/Rare3.nbt,5,CHEST:5,../../../../Chests/Loot/Rare4.nbt,5,CHEST:5,../../../../Chests/Loot/Rare5.nbt,10,CHEST:5,../../../../Chests/Loot/Rare6.nbt,10,CHEST:5,../../../../Chests/Loot/Rare7.nbt,10,CHEST:5,../../../../Chests/Loot/Rare8.nbt,10,CHEST:5,../../../../Chests/Loot/Rare9.nbt,10,CHEST:5,../../../../Chests/Loot/Rare10.nbt,15,CHEST:5,../../../../Chests/Loot/Rare11.nbt,15,CHEST:5,../../../../Chests/Loot/Rare12.nbt,15,CHEST:5,../../../../Chests/Loot/Rare13.nbt,15,CHEST:5,../../../../Chests/Loot/Rare14.nbt,15,CHEST:5,../../../../Chests/Loot/Rare15.nbt,15,CHEST:5,../../../../Chests/Loot/Epic15.nbt,100)
RandomBlock(-1,9,-5,AIR:0,20,CHEST:5,../../../../Chests/Loot/ShipJunk_1.nbt,10,CHEST:5,../../../../Chests/Loot/ShipJunk_2.nbt,10,CHEST:5,../../../../Chests/Loot/ShipJunk_3.nbt,10,CHEST:5,../../../../Chests/Loot/ShipJunk_4.nbt,10,CHEST:5,../../../../Chests/Loot/ShipJunk_5.nbt,10,CHEST:5,../../../../Chests/Lore/Frozen_1.nbt,1,CHEST:5,../../../../Chests/Lore/Frozen_2.nbt,1,CHEST:5,../../../../Chests/Lore/Frozen_3.nbt,1,CHEST:5,../../../../Chests/Lore/Frozen_4.nbt,1,CHEST:5,../../../../Chests/Lore/Frozen_5.nbt,1,CHEST:5,../../../../Chests/Loot/Common1.nbt,10,CHEST:5,../../../../Chests/Loot/Common2.nbt,10,CHEST:5,../../../../Chests/Loot/Common3.nbt,10,CHEST:5,../../../../Chests/Loot/Common4.nbt,10,CHEST:5,../../../../Chests/Loot/Common5.nbt,10,CHEST:5,../../../../Chests/Loot/Common6.nbt,10,CHEST:5,../../../../Chests/Loot/Common7.nbt,10,CHEST:5,../../../../Chests/Loot/Common8.nbt,10,CHEST:5,../../../../Chests/Loot/Common9.nbt,10,CHEST:5,../../../../Chests/Loot/Common10.nbt,10,CHEST:5,../../../../Chests/Loot/Common10.nbt,11,CHEST:5,../../../../Chests/Loot/Common12.nbt,10,CHEST:5,../../../../Chests/Loot/Common13.nbt,10,CHEST:5,../../../../Chests/Loot/Common14.nbt,10,CHEST:5,../../../../Chests/Loot/Common15.nbt,10,CHEST:5,../../../../Chests/Lore/Frozen_1.nbt,2,CHEST:5,../../../../Chests/Lore/Frozen_3.nbt,2,CHEST:5,../../../../Chests/Lore/Frozen_4.nbt,2,CHEST:5,../../../../Chests/Lore/Frozen_5.nbt,2,CHEST:5,../../../../Chests/Lore/Frozen_5.nbt,2,CHEST:5,../../../../Chests/Loot/Rare1.nbt,5,CHEST:5,../../../../Chests/Loot/Rare2.nbt,5,CHEST:5,../../../../Chests/Loot/Rare3.nbt,5,CHEST:5,../../../../Chests/Loot/Rare4.nbt,5,CHEST:5,../../../../Chests/Loot/Rare5.nbt,5,CHEST:5,../../../../Chests/Loot/Rare6.nbt,5,CHEST:5,../../../../Chests/Loot/Rare7.nbt,5,CHEST:5,../../../../Chests/Loot/Rare8.nbt,5,CHEST:5,../../../../Chests/Loot/Rare9.nbt,5,CHEST:5,../../../../Chests/Loot/Rare10.nbt,5,CHEST:5,../../../../Chests/Loot/Rare11.nbt,5,CHEST:5,../../../../Chests/Loot/Rare12.nbt,5,CHEST:5,../../../../Chests/Loot/Rare13.nbt,5,CHEST:5,../../../../Chests/Loot/Rare14.nbt,5,CHEST:5,../../../../Chests/Loot/Rare15.nbt,5,CHEST:5,../../../../Chests/Loot/Epic1.nbt,2,CHEST:5,../../../../Chests/Loot/Epic2.nbt,2,CHEST:5,../../../../Chests/Loot/Epic3.nbt,2,CHEST:5,../../../../Chests/Loot/Epic4.nbt,2,CHEST:5,../../../../Chests/Loot/Epic5.nbt,2,CHEST:5,../../../../Chests/Loot/Epic6.nbt,2,CHEST:5,../../../../Chests/Loot/Epic7.nbt,2,CHEST:5,../../../../Chests/Loot/Epic8.nbt,2,CHEST:5,../../../../Chests/Loot/Epic9.nbt,2,CHEST:5,../../../../Chests/Loot/Epic10.nbt,2,CHEST:5,../../../../Chests/Loot/Epic11.nbt,2,CHEST:5,../../../../Chests/Loot/Epic12.nbt,2,CHEST:5,../../../../Chests/Loot/Epic13.nbt,2,CHEST:5,../../../../Chests/Loot/Epic14.nbt,2,CHEST:5,../../../../Chests/Loot/Epic15.nbt,5,CHEST:5,../../../../Chests/Loot/Rare1.nbt,5,CHEST:5,../../../../Chests/Loot/Rare2.nbt,5,CHEST:5,../../../../Chests/Loot/Rare3.nbt,5,CHEST:5,../../../../Chests/Loot/Rare4.nbt,5,CHEST:5,../../../../Chests/Loot/Rare5.nbt,10,CHEST:5,../../../../Chests/Loot/Rare6.nbt,10,CHEST:5,../../../../Chests/Loot/Rare7.nbt,10,CHEST:5,../../../../Chests/Loot/Rare8.nbt,10,CHEST:5,../../../../Chests/Loot/Rare9.nbt,10,CHEST:5,../../../../Chests/Loot/Rare10.nbt,15,CHEST:5,../../../../Chests/Loot/Rare11.nbt,15,CHEST:5,../../../../Chests/Loot/Rare12.nbt,15,CHEST:5,../../../../Chests/Loot/Rare13.nbt,15,CHEST:5,../../../../Chests/Loot/Rare14.nbt,15,CHEST:5,../../../../Chests/Loot/Rare15.nbt,15,CHEST:5,../../../../Chests/Loot/Epic15.nbt,100)
RandomBlock(-1,9,-4,AIR:0,20,CHEST:5,../../../../Chests/Loot/ShipJunk_1.nbt,10,CHEST:5,../../../../Chests/Loot/ShipJunk_2.nbt,10,CHEST:5,../../../../Chests/Loot/ShipJunk_3.nbt,10,CHEST:5,../../../../Chests/Loot/ShipJunk_4.nbt,10,CHEST:5,../../../../Chests/Loot/ShipJunk_5.nbt,10,CHEST:5,../../../../Chests/Lore/Frozen_1.nbt,1,CHEST:5,../../../../Chests/Lore/Frozen_2.nbt,1,CHEST:5,../../../../Chests/Lore/Frozen_3.nbt,1,CHEST:5,../../../../Chests/Lore/Frozen_4.nbt,1,CHEST:5,../../../../Chests/Lore/Frozen_5.nbt,1,CHEST:5,../../../../Chests/Loot/Common1.nbt,10,CHEST:5,../../../../Chests/Loot/Common2.nbt,10,CHEST:5,../../../../Chests/Loot/Common3.nbt,10,CHEST:5,../../../../Chests/Loot/Common4.nbt,10,CHEST:5,../../../../Chests/Loot/Common5.nbt,10,CHEST:5,../../../../Chests/Loot/Common6.nbt,10,CHEST:5,../../../../Chests/Loot/Common7.nbt,10,CHEST:5,../../../../Chests/Loot/Common8.nbt,10,CHEST:5,../../../../Chests/Loot/Common9.nbt,10,CHEST:5,../../../../Chests/Loot/Common10.nbt,10,CHEST:5,../../../../Chests/Loot/Common10.nbt,11,CHEST:5,../../../../Chests/Loot/Common12.nbt,10,CHEST:5,../../../../Chests/Loot/Common13.nbt,10,CHEST:5,../../../../Chests/Loot/Common14.nbt,10,CHEST:5,../../../../Chests/Loot/Common15.nbt,10,CHEST:5,../../../../Chests/Lore/Frozen_1.nbt,2,CHEST:5,../../../../Chests/Lore/Frozen_3.nbt,2,CHEST:5,../../../../Chests/Lore/Frozen_4.nbt,2,CHEST:5,../../../../Chests/Lore/Frozen_5.nbt,2,CHEST:5,../../../../Chests/Lore/Frozen_5.nbt,2,CHEST:5,../../../../Chests/Loot/Rare1.nbt,5,CHEST:5,../../../../Chests/Loot/Rare2.nbt,5,CHEST:5,../../../../Chests/Loot/Rare3.nbt,5,CHEST:5,../../../../Chests/Loot/Rare4.nbt,5,CHEST:5,../../../../Chests/Loot/Rare5.nbt,5,CHEST:5,../../../../Chests/Loot/Rare6.nbt,5,CHEST:5,../../../../Chests/Loot/Rare7.nbt,5,CHEST:5,../../../../Chests/Loot/Rare8.nbt,5,CHEST:5,../../../../Chests/Loot/Rare9.nbt,5,CHEST:5,../../../../Chests/Loot/Rare10.nbt,5,CHEST:5,../../../../Chests/Loot/Rare11.nbt,5,CHEST:5,../../../../Chests/Loot/Rare12.nbt,5,CHEST:5,../../../../Chests/Loot/Rare13.nbt,5,CHEST:5,../../../../Chests/Loot/Rare14.nbt,5,CHEST:5,../../../../Chests/Loot/Rare15.nbt,5,CHEST:5,../../../../Chests/Loot/Epic1.nbt,2,CHEST:5,../../../../Chests/Loot/Epic2.nbt,2,CHEST:5,../../../../Chests/Loot/Epic3.nbt,2,CHEST:5,../../../../Chests/Loot/Epic4.nbt,2,CHEST:5,../../../../Chests/Loot/Epic5.nbt,2,CHEST:5,../../../../Chests/Loot/Epic6.nbt,2,CHEST:5,../../../../Chests/Loot/Epic7.nbt,2,CHEST:5,../../../../Chests/Loot/Epic8.nbt,2,CHEST:5,../../../../Chests/Loot/Epic9.nbt,2,CHEST:5,../../../../Chests/Loot/Epic10.nbt,2,CHEST:5,../../../../Chests/Loot/Epic11.nbt,2,CHEST:5,../../../../Chests/Loot/Epic12.nbt,2,CHEST:5,../../../../Chests/Loot/Epic13.nbt,2,CHEST:5,../../../../Chests/Loot/Epic14.nbt,2,CHEST:5,../../../../Chests/Loot/Epic15.nbt,5,CHEST:5,../../../../Chests/Loot/Rare1.nbt,5,CHEST:5,../../../../Chests/Loot/Rare2.nbt,5,CHEST:5,../../../../Chests/Loot/Rare3.nbt,5,CHEST:5,../../../../Chests/Loot/Rare4.nbt,5,CHEST:5,../../../../Chests/Loot/Rare5.nbt,10,CHEST:5,../../../../Chests/Loot/Rare6.nbt,10,CHEST:5,../../../../Chests/Loot/Rare7.nbt,10,CHEST:5,../../../../Chests/Loot/Rare8.nbt,10,CHEST:5,../../../../Chests/Loot/Rare9.nbt,10,CHEST:5,../../../../Chests/Loot/Rare10.nbt,15,CHEST:5,../../../../Chests/Loot/Rare11.nbt,15,CHEST:5,../../../../Chests/Loot/Rare12.nbt,15,CHEST:5,../../../../Chests/Loot/Rare13.nbt,15,CHEST:5,../../../../Chests/Loot/Rare14.nbt,15,CHEST:5,../../../../Chests/Loot/Rare15.nbt,15,CHEST:5,../../../../Chests/Loot/Epic15.nbt,100)
RandomBlock(-1,9,-3,AIR:0,20,CHEST:5,../../../../Chests/Loot/ShipJunk_1.nbt,10,CHEST:5,../../../../Chests/Loot/ShipJunk_2.nbt,10,CHEST:5,../../../../Chests/Loot/ShipJunk_3.nbt,10,CHEST:5,../../../../Chests/Loot/ShipJunk_4.nbt,10,CHEST:5,../../../../Chests/Loot/ShipJunk_5.nbt,10,CHEST:5,../../../../Chests/Lore/Frozen_1.nbt,1,CHEST:5,../../../../Chests/Lore/Frozen_2.nbt,1,CHEST:5,../../../../Chests/Lore/Frozen_3.nbt,1,CHEST:5,../../../../Chests/Lore/Frozen_4.nbt,1,CHEST:5,../../../../Chests/Lore/Frozen_5.nbt,1,CHEST:5,../../../../Chests/Loot/Common1.nbt,10,CHEST:5,../../../../Chests/Loot/Common2.nbt,10,CHEST:5,../../../../Chests/Loot/Common3.nbt,10,CHEST:5,../../../../Chests/Loot/Common4.nbt,10,CHEST:5,../../../../Chests/Loot/Common5.nbt,10,CHEST:5,../../../../Chests/Loot/Common6.nbt,10,CHEST:5,../../../../Chests/Loot/Common7.nbt,10,CHEST:5,../../../../Chests/Loot/Common8.nbt,10,CHEST:5,../../../../Chests/Loot/Common9.nbt,10,CHEST:5,../../../../Chests/Loot/Common10.nbt,10,CHEST:5,../../../../Chests/Loot/Common10.nbt,11,CHEST:5,../../../../Chests/Loot/Common12.nbt,10,CHEST:5,../../../../Chests/Loot/Common13.nbt,10,CHEST:5,../../../../Chests/Loot/Common14.nbt,10,CHEST:5,../../../../Chests/Loot/Common15.nbt,10,CHEST:5,../../../../Chests/Lore/Frozen_1.nbt,2,CHEST:5,../../../../Chests/Lore/Frozen_3.nbt,2,CHEST:5,../../../../Chests/Lore/Frozen_4.nbt,2,CHEST:5,../../../../Chests/Lore/Frozen_5.nbt,2,CHEST:5,../../../../Chests/Lore/Frozen_5.nbt,2,CHEST:5,../../../../Chests/Loot/Rare1.nbt,5,CHEST:5,../../../../Chests/Loot/Rare2.nbt,5,CHEST:5,../../../../Chests/Loot/Rare3.nbt,5,CHEST:5,../../../../Chests/Loot/Rare4.nbt,5,CHEST:5,../../../../Chests/Loot/Rare5.nbt,5,CHEST:5,../../../../Chests/Loot/Rare6.nbt,5,CHEST:5,../../../../Chests/Loot/Rare7.nbt,5,CHEST:5,../../../../Chests/Loot/Rare8.nbt,5,CHEST:5,../../../../Chests/Loot/Rare9.nbt,5,CHEST:5,../../../../Chests/Loot/Rare10.nbt,5,CHEST:5,../../../../Chests/Loot/Rare11.nbt,5,CHEST:5,../../../../Chests/Loot/Rare12.nbt,5,CHEST:5,../../../../Chests/Loot/Rare13.nbt,5,CHEST:5,../../../../Chests/Loot/Rare14.nbt,5,CHEST:5,../../../../Chests/Loot/Rare15.nbt,5,CHEST:5,../../../../Chests/Loot/Epic1.nbt,2,CHEST:5,../../../../Chests/Loot/Epic2.nbt,2,CHEST:5,../../../../Chests/Loot/Epic3.nbt,2,CHEST:5,../../../../Chests/Loot/Epic4.nbt,2,CHEST:5,../../../../Chests/Loot/Epic5.nbt,2,CHEST:5,../../../../Chests/Loot/Epic6.nbt,2,CHEST:5,../../../../Chests/Loot/Epic7.nbt,2,CHEST:5,../../../../Chests/Loot/Epic8.nbt,2,CHEST:5,../../../../Chests/Loot/Epic9.nbt,2,CHEST:5,../../../../Chests/Loot/Epic10.nbt,2,CHEST:5,../../../../Chests/Loot/Epic11.nbt,2,CHEST:5,../../../../Chests/Loot/Epic12.nbt,2,CHEST:5,../../../../Chests/Loot/Epic13.nbt,2,CHEST:5,../../../../Chests/Loot/Epic14.nbt,2,CHEST:5,../../../../Chests/Loot/Epic15.nbt,5,CHEST:5,../../../../Chests/Loot/Rare1.nbt,5,CHEST:5,../../../../Chests/Loot/Rare2.nbt,5,CHEST:5,../../../../Chests/Loot/Rare3.nbt,5,CHEST:5,../../../../Chests/Loot/Rare4.nbt,5,CHEST:5,../../../../Chests/Loot/Rare5.nbt,10,CHEST:5,../../../../Chests/Loot/Rare6.nbt,10,CHEST:5,../../../../Chests/Loot/Rare7.nbt,10,CHEST:5,../../../../Chests/Loot/Rare8.nbt,10,CHEST:5,../../../../Chests/Loot/Rare9.nbt,10,CHEST:5,../../../../Chests/Loot/Rare10.nbt,15,CHEST:5,../../../../Chests/Loot/Rare11.nbt,15,CHEST:5,../../../../Chests/Loot/Rare12.nbt,15,CHEST:5,../../../../Chests/Loot/Rare13.nbt,15,CHEST:5,../../../../Chests/Loot/Rare14.nbt,15,CHEST:5,../../../../Chests/Loot/Rare15.nbt,15,CHEST:5,../../../../Chests/Loot/Epic15.nbt,100)
Block(-1,9,-2,WOOD:5)
Block(-1,9,0,ICE:0)
Block(-1,10,-6,DARK_OAK_STAIRS:5)
RandomBlock(-1,10,-5,AIR:0,20,CHEST:5,../../../../Chests/Loot/ShipJunk_1.nbt,10,CHEST:5,../../../../Chests/Loot/ShipJunk_2.nbt,10,CHEST:5,../../../../Chests/Loot/ShipJunk_3.nbt,10,CHEST:5,../../../../Chests/Loot/ShipJunk_4.nbt,10,CHEST:5,../../../../Chests/Loot/ShipJunk_5.nbt,10,CHEST:5,../../../../Chests/Lore/Frozen_1.nbt,1,CHEST:5,../../../../Chests/Lore/Frozen_2.nbt,1,CHEST:5,../../../../Chests/Lore/Frozen_3.nbt,1,CHEST:5,../../../../Chests/Lore/Frozen_4.nbt,1,CHEST:5,../../../../Chests/Lore/Frozen_5.nbt,1,CHEST:5,../../../../Chests/Loot/Common1.nbt,10,CHEST:5,../../../../Chests/Loot/Common2.nbt,10,CHEST:5,../../../../Chests/Loot/Common3.nbt,10,CHEST:5,../../../../Chests/Loot/Common4.nbt,10,CHEST:5,../../../../Chests/Loot/Common5.nbt,10,CHEST:5,../../../../Chests/Loot/Common6.nbt,10,CHEST:5,../../../../Chests/Loot/Common7.nbt,10,CHEST:5,../../../../Chests/Loot/Common8.nbt,10,CHEST:5,../../../../Chests/Loot/Common9.nbt,10,CHEST:5,../../../../Chests/Loot/Common10.nbt,10,CHEST:5,../../../../Chests/Loot/Common10.nbt,11,CHEST:5,../../../../Chests/Loot/Common12.nbt,10,CHEST:5,../../../../Chests/Loot/Common13.nbt,10,CHEST:5,../../../../Chests/Loot/Common14.nbt,10,CHEST:5,../../../../Chests/Loot/Common15.nbt,10,CHEST:5,../../../../Chests/Lore/Frozen_1.nbt,2,CHEST:5,../../../../Chests/Lore/Frozen_3.nbt,2,CHEST:5,../../../../Chests/Lore/Frozen_4.nbt,2,CHEST:5,../../../../Chests/Lore/Frozen_5.nbt,2,CHEST:5,../../../../Chests/Lore/Frozen_5.nbt,2,CHEST:5,../../../../Chests/Loot/Rare1.nbt,5,CHEST:5,../../../../Chests/Loot/Rare2.nbt,5,CHEST:5,../../../../Chests/Loot/Rare3.nbt,5,CHEST:5,../../../../Chests/Loot/Rare4.nbt,5,CHEST:5,../../../../Chests/Loot/Rare5.nbt,5,CHEST:5,../../../../Chests/Loot/Rare6.nbt,5,CHEST:5,../../../../Chests/Loot/Rare7.nbt,5,CHEST:5,../../../../Chests/Loot/Rare8.nbt,5,CHEST:5,../../../../Chests/Loot/Rare9.nbt,5,CHEST:5,../../../../Chests/Loot/Rare10.nbt,5,CHEST:5,../../../../Chests/Loot/Rare11.nbt,5,CHEST:5,../../../../Chests/Loot/Rare12.nbt,5,CHEST:5,../../../../Chests/Loot/Rare13.nbt,5,CHEST:5,../../../../Chests/Loot/Rare14.nbt,5,CHEST:5,../../../../Chests/Loot/Rare15.nbt,5,CHEST:5,../../../../Chests/Loot/Epic1.nbt,2,CHEST:5,../../../../Chests/Loot/Epic2.nbt,2,CHEST:5,../../../../Chests/Loot/Epic3.nbt,2,CHEST:5,../../../../Chests/Loot/Epic4.nbt,2,CHEST:5,../../../../Chests/Loot/Epic5.nbt,2,CHEST:5,../../../../Chests/Loot/Epic6.nbt,2,CHEST:5,../../../../Chests/Loot/Epic7.nbt,2,CHEST:5,../../../../Chests/Loot/Epic8.nbt,2,CHEST:5,../../../../Chests/Loot/Epic9.nbt,2,CHEST:5,../../../../Chests/Loot/Epic10.nbt,2,CHEST:5,../../../../Chests/Loot/Epic11.nbt,2,CHEST:5,../../../../Chests/Loot/Epic12.nbt,2,CHEST:5,../../../../Chests/Loot/Epic13.nbt,2,CHEST:5,../../../../Chests/Loot/Epic14.nbt,2,CHEST:5,../../../../Chests/Loot/Epic15.nbt,5,CHEST:5,../../../../Chests/Loot/Rare1.nbt,5,CHEST:5,../../../../Chests/Loot/Rare2.nbt,5,CHEST:5,../../../../Chests/Loot/Rare3.nbt,5,CHEST:5,../../../../Chests/Loot/Rare4.nbt,5,CHEST:5,../../../../Chests/Loot/Rare5.nbt,10,CHEST:5,../../../../Chests/Loot/Rare6.nbt,10,CHEST:5,../../../../Chests/Loot/Rare7.nbt,10,CHEST:5,../../../../Chests/Loot/Rare8.nbt,10,CHEST:5,../../../../Chests/Loot/Rare9.nbt,10,CHEST:5,../../../../Chests/Loot/Rare10.nbt,15,CHEST:5,../../../../Chests/Loot/Rare11.nbt,15,CHEST:5,../../../../Chests/Loot/Rare12.nbt,15,CHEST:5,../../../../Chests/Loot/Rare13.nbt,15,CHEST:5,../../../../Chests/Loot/Rare14.nbt,15,CHEST:5,../../../../Chests/Loot/Rare15.nbt,15,CHEST:5,../../../../Chests/Loot/Epic15.nbt,100)
RandomBlock(-1,10,-4,AIR:0,20,CHEST:5,../../../../Chests/Loot/ShipJunk_1.nbt,10,CHEST:5,../../../../Chests/Loot/ShipJunk_2.nbt,10,CHEST:5,../../../../Chests/Loot/ShipJunk_3.nbt,10,CHEST:5,../../../../Chests/Loot/ShipJunk_4.nbt,10,CHEST:5,../../../../Chests/Loot/ShipJunk_5.nbt,10,CHEST:5,../../../../Chests/Lore/Frozen_1.nbt,1,CHEST:5,../../../../Chests/Lore/Frozen_2.nbt,1,CHEST:5,../../../../Chests/Lore/Frozen_3.nbt,1,CHEST:5,../../../../Chests/Lore/Frozen_4.nbt,1,CHEST:5,../../../../Chests/Lore/Frozen_5.nbt,1,CHEST:5,../../../../Chests/Loot/Common1.nbt,10,CHEST:5,../../../../Chests/Loot/Common2.nbt,10,CHEST:5,../../../../Chests/Loot/Common3.nbt,10,CHEST:5,../../../../Chests/Loot/Common4.nbt,10,CHEST:5,../../../../Chests/Loot/Common5.nbt,10,CHEST:5,../../../../Chests/Loot/Common6.nbt,10,CHEST:5,../../../../Chests/Loot/Common7.nbt,10,CHEST:5,../../../../Chests/Loot/Common8.nbt,10,CHEST:5,../../../../Chests/Loot/Common9.nbt,10,CHEST:5,../../../../Chests/Loot/Common10.nbt,10,CHEST:5,../../../../Chests/Loot/Common10.nbt,11,CHEST:5,../../../../Chests/Loot/Common12.nbt,10,CHEST:5,../../../../Chests/Loot/Common13.nbt,10,CHEST:5,../../../../Chests/Loot/Common14.nbt,10,CHEST:5,../../../../Chests/Loot/Common15.nbt,10,CHEST:5,../../../../Chests/Lore/Frozen_1.nbt,2,CHEST:5,../../../../Chests/Lore/Frozen_3.nbt,2,CHEST:5,../../../../Chests/Lore/Frozen_4.nbt,2,CHEST:5,../../../../Chests/Lore/Frozen_5.nbt,2,CHEST:5,../../../../Chests/Lore/Frozen_5.nbt,2,CHEST:5,../../../../Chests/Loot/Rare1.nbt,5,CHEST:5,../../../../Chests/Loot/Rare2.nbt,5,CHEST:5,../../../../Chests/Loot/Rare3.nbt,5,CHEST:5,../../../../Chests/Loot/Rare4.nbt,5,CHEST:5,../../../../Chests/Loot/Rare5.nbt,5,CHEST:5,../../../../Chests/Loot/Rare6.nbt,5,CHEST:5,../../../../Chests/Loot/Rare7.nbt,5,CHEST:5,../../../../Chests/Loot/Rare8.nbt,5,CHEST:5,../../../../Chests/Loot/Rare9.nbt,5,CHEST:5,../../../../Chests/Loot/Rare10.nbt,5,CHEST:5,../../../../Chests/Loot/Rare11.nbt,5,CHEST:5,../../../../Chests/Loot/Rare12.nbt,5,CHEST:5,../../../../Chests/Loot/Rare13.nbt,5,CHEST:5,../../../../Chests/Loot/Rare14.nbt,5,CHEST:5,../../../../Chests/Loot/Rare15.nbt,5,CHEST:5,../../../../Chests/Loot/Epic1.nbt,2,CHEST:5,../../../../Chests/Loot/Epic2.nbt,2,CHEST:5,../../../../Chests/Loot/Epic3.nbt,2,CHEST:5,../../../../Chests/Loot/Epic4.nbt,2,CHEST:5,../../../../Chests/Loot/Epic5.nbt,2,CHEST:5,../../../../Chests/Loot/Epic6.nbt,2,CHEST:5,../../../../Chests/Loot/Epic7.nbt,2,CHEST:5,../../../../Chests/Loot/Epic8.nbt,2,CHEST:5,../../../../Chests/Loot/Epic9.nbt,2,CHEST:5,../../../../Chests/Loot/Epic10.nbt,2,CHEST:5,../../../../Chests/Loot/Epic11.nbt,2,CHEST:5,../../../../Chests/Loot/Epic12.nbt,2,CHEST:5,../../../../Chests/Loot/Epic13.nbt,2,CHEST:5,../../../../Chests/Loot/Epic14.nbt,2,CHEST:5,../../../../Chests/Loot/Epic15.nbt,5,CHEST:5,../../../../Chests/Loot/Rare1.nbt,5,CHEST:5,../../../../Chests/Loot/Rare2.nbt,5,CHEST:5,../../../../Chests/Loot/Rare3.nbt,5,CHEST:5,../../../../Chests/Loot/Rare4.nbt,5,CHEST:5,../../../../Chests/Loot/Rare5.nbt,10,CHEST:5,../../../../Chests/Loot/Rare6.nbt,10,CHEST:5,../../../../Chests/Loot/Rare7.nbt,10,CHEST:5,../../../../Chests/Loot/Rare8.nbt,10,CHEST:5,../../../../Chests/Loot/Rare9.nbt,10,CHEST:5,../../../../Chests/Loot/Rare10.nbt,15,CHEST:5,../../../../Chests/Loot/Rare11.nbt,15,CHEST:5,../../../../Chests/Loot/Rare12.nbt,15,CHEST:5,../../../../Chests/Loot/Rare13.nbt,15,CHEST:5,../../../../Chests/Loot/Rare14.nbt,15,CHEST:5,../../../../Chests/Loot/Rare15.nbt,15,CHEST:5,../../../../Chests/Loot/Epic15.nbt,100)
RandomBlock(-1,10,-3,AIR:0,20,CHEST:5,../../../../Chests/Loot/ShipJunk_1.nbt,10,CHEST:5,../../../../Chests/Loot/ShipJunk_2.nbt,10,CHEST:5,../../../../Chests/Loot/ShipJunk_3.nbt,10,CHEST:5,../../../../Chests/Loot/ShipJunk_4.nbt,10,CHEST:5,../../../../Chests/Loot/ShipJunk_5.nbt,10,CHEST:5,../../../../Chests/Lore/Frozen_1.nbt,1,CHEST:5,../../../../Chests/Lore/Frozen_2.nbt,1,CHEST:5,../../../../Chests/Lore/Frozen_3.nbt,1,CHEST:5,../../../../Chests/Lore/Frozen_4.nbt,1,CHEST:5,../../../../Chests/Lore/Frozen_5.nbt,1,CHEST:5,../../../../Chests/Loot/Common1.nbt,10,CHEST:5,../../../../Chests/Loot/Common2.nbt,10,CHEST:5,../../../../Chests/Loot/Common3.nbt,10,CHEST:5,../../../../Chests/Loot/Common4.nbt,10,CHEST:5,../../../../Chests/Loot/Common5.nbt,10,CHEST:5,../../../../Chests/Loot/Common6.nbt,10,CHEST:5,../../../../Chests/Loot/Common7.nbt,10,CHEST:5,../../../../Chests/Loot/Common8.nbt,10,CHEST:5,../../../../Chests/Loot/Common9.nbt,10,CHEST:5,../../../../Chests/Loot/Common10.nbt,10,CHEST:5,../../../../Chests/Loot/Common10.nbt,11,CHEST:5,../../../../Chests/Loot/Common12.nbt,10,CHEST:5,../../../../Chests/Loot/Common13.nbt,10,CHEST:5,../../../../Chests/Loot/Common14.nbt,10,CHEST:5,../../../../Chests/Loot/Common15.nbt,10,CHEST:5,../../../../Chests/Lore/Frozen_1.nbt,2,CHEST:5,../../../../Chests/Lore/Frozen_3.nbt,2,CHEST:5,../../../../Chests/Lore/Frozen_4.nbt,2,CHEST:5,../../../../Chests/Lore/Frozen_5.nbt,2,CHEST:5,../../../../Chests/Lore/Frozen_5.nbt,2,CHEST:5,../../../../Chests/Loot/Rare1.nbt,5,CHEST:5,../../../../Chests/Loot/Rare2.nbt,5,CHEST:5,../../../../Chests/Loot/Rare3.nbt,5,CHEST:5,../../../../Chests/Loot/Rare4.nbt,5,CHEST:5,../../../../Chests/Loot/Rare5.nbt,5,CHEST:5,../../../../Chests/Loot/Rare6.nbt,5,CHEST:5,../../../../Chests/Loot/Rare7.nbt,5,CHEST:5,../../../../Chests/Loot/Rare8.nbt,5,CHEST:5,../../../../Chests/Loot/Rare9.nbt,5,CHEST:5,../../../../Chests/Loot/Rare10.nbt,5,CHEST:5,../../../../Chests/Loot/Rare11.nbt,5,CHEST:5,../../../../Chests/Loot/Rare12.nbt,5,CHEST:5,../../../../Chests/Loot/Rare13.nbt,5,CHEST:5,../../../../Chests/Loot/Rare14.nbt,5,CHEST:5,../../../../Chests/Loot/Rare15.nbt,5,CHEST:5,../../../../Chests/Loot/Epic1.nbt,2,CHEST:5,../../../../Chests/Loot/Epic2.nbt,2,CHEST:5,../../../../Chests/Loot/Epic3.nbt,2,CHEST:5,../../../../Chests/Loot/Epic4.nbt,2,CHEST:5,../../../../Chests/Loot/Epic5.nbt,2,CHEST:5,../../../../Chests/Loot/Epic6.nbt,2,CHEST:5,../../../../Chests/Loot/Epic7.nbt,2,CHEST:5,../../../../Chests/Loot/Epic8.nbt,2,CHEST:5,../../../../Chests/Loot/Epic9.nbt,2,CHEST:5,../../../../Chests/Loot/Epic10.nbt,2,CHEST:5,../../../../Chests/Loot/Epic11.nbt,2,CHEST:5,../../../../Chests/Loot/Epic12.nbt,2,CHEST:5,../../../../Chests/Loot/Epic13.nbt,2,CHEST:5,../../../../Chests/Loot/Epic14.nbt,2,CHEST:5,../../../../Chests/Loot/Epic15.nbt,5,CHEST:5,../../../../Chests/Loot/Rare1.nbt,5,CHEST:5,../../../../Chests/Loot/Rare2.nbt,5,CHEST:5,../../../../Chests/Loot/Rare3.nbt,5,CHEST:5,../../../../Chests/Loot/Rare4.nbt,5,CHEST:5,../../../../Chests/Loot/Rare5.nbt,10,CHEST:5,../../../../Chests/Loot/Rare6.nbt,10,CHEST:5,../../../../Chests/Loot/Rare7.nbt,10,CHEST:5,../../../../Chests/Loot/Rare8.nbt,10,CHEST:5,../../../../Chests/Loot/Rare9.nbt,10,CHEST:5,../../../../Chests/Loot/Rare10.nbt,15,CHEST:5,../../../../Chests/Loot/Rare11.nbt,15,CHEST:5,../../../../Chests/Loot/Rare12.nbt,15,CHEST:5,../../../../Chests/Loot/Rare13.nbt,15,CHEST:5,../../../../Chests/Loot/Rare14.nbt,15,CHEST:5,../../../../Chests/Loot/Rare15.nbt,15,CHEST:5,../../../../Chests/Loot/Epic15.nbt,100)
Block(-1,10,-2,WOOD:5)
Block(-1,10,-1,PACKED_ICE:0)
Block(-1,10,0,ICE:0)
Block(-1,11,-6,WOOD:5)
RandomBlock(-1,11,-5,AIR:0,20,CHEST:5,../../../../Chests/Loot/ShipJunk_1.nbt,10,CHEST:5,../../../../Chests/Loot/ShipJunk_2.nbt,10,CHEST:5,../../../../Chests/Loot/ShipJunk_3.nbt,10,CHEST:5,../../../../Chests/Loot/ShipJunk_4.nbt,10,CHEST:5,../../../../Chests/Loot/ShipJunk_5.nbt,10,CHEST:5,../../../../Chests/Lore/Frozen_1.nbt,1,CHEST:5,../../../../Chests/Lore/Frozen_2.nbt,1,CHEST:5,../../../../Chests/Lore/Frozen_3.nbt,1,CHEST:5,../../../../Chests/Lore/Frozen_4.nbt,1,CHEST:5,../../../../Chests/Lore/Frozen_5.nbt,1,CHEST:5,../../../../Chests/Loot/Common1.nbt,10,CHEST:5,../../../../Chests/Loot/Common2.nbt,10,CHEST:5,../../../../Chests/Loot/Common3.nbt,10,CHEST:5,../../../../Chests/Loot/Common4.nbt,10,CHEST:5,../../../../Chests/Loot/Common5.nbt,10,CHEST:5,../../../../Chests/Loot/Common6.nbt,10,CHEST:5,../../../../Chests/Loot/Common7.nbt,10,CHEST:5,../../../../Chests/Loot/Common8.nbt,10,CHEST:5,../../../../Chests/Loot/Common9.nbt,10,CHEST:5,../../../../Chests/Loot/Common10.nbt,10,CHEST:5,../../../../Chests/Loot/Common10.nbt,11,CHEST:5,../../../../Chests/Loot/Common12.nbt,10,CHEST:5,../../../../Chests/Loot/Common13.nbt,10,CHEST:5,../../../../Chests/Loot/Common14.nbt,10,CHEST:5,../../../../Chests/Loot/Common15.nbt,10,CHEST:5,../../../../Chests/Lore/Frozen_1.nbt,2,CHEST:5,../../../../Chests/Lore/Frozen_3.nbt,2,CHEST:5,../../../../Chests/Lore/Frozen_4.nbt,2,CHEST:5,../../../../Chests/Lore/Frozen_5.nbt,2,CHEST:5,../../../../Chests/Lore/Frozen_5.nbt,2,CHEST:5,../../../../Chests/Loot/Rare1.nbt,5,CHEST:5,../../../../Chests/Loot/Rare2.nbt,5,CHEST:5,../../../../Chests/Loot/Rare3.nbt,5,CHEST:5,../../../../Chests/Loot/Rare4.nbt,5,CHEST:5,../../../../Chests/Loot/Rare5.nbt,5,CHEST:5,../../../../Chests/Loot/Rare6.nbt,5,CHEST:5,../../../../Chests/Loot/Rare7.nbt,5,CHEST:5,../../../../Chests/Loot/Rare8.nbt,5,CHEST:5,../../../../Chests/Loot/Rare9.nbt,5,CHEST:5,../../../../Chests/Loot/Rare10.nbt,5,CHEST:5,../../../../Chests/Loot/Rare11.nbt,5,CHEST:5,../../../../Chests/Loot/Rare12.nbt,5,CHEST:5,../../../../Chests/Loot/Rare13.nbt,5,CHEST:5,../../../../Chests/Loot/Rare14.nbt,5,CHEST:5,../../../../Chests/Loot/Rare15.nbt,5,CHEST:5,../../../../Chests/Loot/Epic1.nbt,2,CHEST:5,../../../../Chests/Loot/Epic2.nbt,2,CHEST:5,../../../../Chests/Loot/Epic3.nbt,2,CHEST:5,../../../../Chests/Loot/Epic4.nbt,2,CHEST:5,../../../../Chests/Loot/Epic5.nbt,2,CHEST:5,../../../../Chests/Loot/Epic6.nbt,2,CHEST:5,../../../../Chests/Loot/Epic7.nbt,2,CHEST:5,../../../../Chests/Loot/Epic8.nbt,2,CHEST:5,../../../../Chests/Loot/Epic9.nbt,2,CHEST:5,../../../../Chests/Loot/Epic10.nbt,2,CHEST:5,../../../../Chests/Loot/Epic11.nbt,2,CHEST:5,../../../../Chests/Loot/Epic12.nbt,2,CHEST:5,../../../../Chests/Loot/Epic13.nbt,2,CHEST:5,../../../../Chests/Loot/Epic14.nbt,2,CHEST:5,../../../../Chests/Loot/Epic15.nbt,5,CHEST:5,../../../../Chests/Loot/Rare1.nbt,5,CHEST:5,../../../../Chests/Loot/Rare2.nbt,5,CHEST:5,../../../../Chests/Loot/Rare3.nbt,5,CHEST:5,../../../../Chests/Loot/Rare4.nbt,5,CHEST:5,../../../../Chests/Loot/Rare5.nbt,10,CHEST:5,../../../../Chests/Loot/Rare6.nbt,10,CHEST:5,../../../../Chests/Loot/Rare7.nbt,10,CHEST:5,../../../../Chests/Loot/Rare8.nbt,10,CHEST:5,../../../../Chests/Loot/Rare9.nbt,10,CHEST:5,../../../../Chests/Loot/Rare10.nbt,15,CHEST:5,../../../../Chests/Loot/Rare11.nbt,15,CHEST:5,../../../../Chests/Loot/Rare12.nbt,15,CHEST:5,../../../../Chests/Loot/Rare13.nbt,15,CHEST:5,../../../../Chests/Loot/Rare14.nbt,15,CHEST:5,../../../../Chests/Loot/Rare15.nbt,15,CHEST:5,../../../../Chests/Loot/Epic15.nbt,100)
RandomBlock(-1,11,-4,AIR:0,20,CHEST:5,../../../../Chests/Loot/ShipJunk_1.nbt,10,CHEST:5,../../../../Chests/Loot/ShipJunk_2.nbt,10,CHEST:5,../../../../Chests/Loot/ShipJunk_3.nbt,10,CHEST:5,../../../../Chests/Loot/ShipJunk_4.nbt,10,CHEST:5,../../../../Chests/Loot/ShipJunk_5.nbt,10,CHEST:5,../../../../Chests/Lore/Frozen_1.nbt,1,CHEST:5,../../../../Chests/Lore/Frozen_2.nbt,1,CHEST:5,../../../../Chests/Lore/Frozen_3.nbt,1,CHEST:5,../../../../Chests/Lore/Frozen_4.nbt,1,CHEST:5,../../../../Chests/Lore/Frozen_5.nbt,1,CHEST:5,../../../../Chests/Loot/Common1.nbt,10,CHEST:5,../../../../Chests/Loot/Common2.nbt,10,CHEST:5,../../../../Chests/Loot/Common3.nbt,10,CHEST:5,../../../../Chests/Loot/Common4.nbt,10,CHEST:5,../../../../Chests/Loot/Common5.nbt,10,CHEST:5,../../../../Chests/Loot/Common6.nbt,10,CHEST:5,../../../../Chests/Loot/Common7.nbt,10,CHEST:5,../../../../Chests/Loot/Common8.nbt,10,CHEST:5,../../../../Chests/Loot/Common9.nbt,10,CHEST:5,../../../../Chests/Loot/Common10.nbt,10,CHEST:5,../../../../Chests/Loot/Common10.nbt,11,CHEST:5,../../../../Chests/Loot/Common12.nbt,10,CHEST:5,../../../../Chests/Loot/Common13.nbt,10,CHEST:5,../../../../Chests/Loot/Common14.nbt,10,CHEST:5,../../../../Chests/Loot/Common15.nbt,10,CHEST:5,../../../../Chests/Lore/Frozen_1.nbt,2,CHEST:5,../../../../Chests/Lore/Frozen_3.nbt,2,CHEST:5,../../../../Chests/Lore/Frozen_4.nbt,2,CHEST:5,../../../../Chests/Lore/Frozen_5.nbt,2,CHEST:5,../../../../Chests/Lore/Frozen_5.nbt,2,CHEST:5,../../../../Chests/Loot/Rare1.nbt,5,CHEST:5,../../../../Chests/Loot/Rare2.nbt,5,CHEST:5,../../../../Chests/Loot/Rare3.nbt,5,CHEST:5,../../../../Chests/Loot/Rare4.nbt,5,CHEST:5,../../../../Chests/Loot/Rare5.nbt,5,CHEST:5,../../../../Chests/Loot/Rare6.nbt,5,CHEST:5,../../../../Chests/Loot/Rare7.nbt,5,CHEST:5,../../../../Chests/Loot/Rare8.nbt,5,CHEST:5,../../../../Chests/Loot/Rare9.nbt,5,CHEST:5,../../../../Chests/Loot/Rare10.nbt,5,CHEST:5,../../../../Chests/Loot/Rare11.nbt,5,CHEST:5,../../../../Chests/Loot/Rare12.nbt,5,CHEST:5,../../../../Chests/Loot/Rare13.nbt,5,CHEST:5,../../../../Chests/Loot/Rare14.nbt,5,CHEST:5,../../../../Chests/Loot/Rare15.nbt,5,CHEST:5,../../../../Chests/Loot/Epic1.nbt,2,CHEST:5,../../../../Chests/Loot/Epic2.nbt,2,CHEST:5,../../../../Chests/Loot/Epic3.nbt,2,CHEST:5,../../../../Chests/Loot/Epic4.nbt,2,CHEST:5,../../../../Chests/Loot/Epic5.nbt,2,CHEST:5,../../../../Chests/Loot/Epic6.nbt,2,CHEST:5,../../../../Chests/Loot/Epic7.nbt,2,CHEST:5,../../../../Chests/Loot/Epic8.nbt,2,CHEST:5,../../../../Chests/Loot/Epic9.nbt,2,CHEST:5,../../../../Chests/Loot/Epic10.nbt,2,CHEST:5,../../../../Chests/Loot/Epic11.nbt,2,CHEST:5,../../../../Chests/Loot/Epic12.nbt,2,CHEST:5,../../../../Chests/Loot/Epic13.nbt,2,CHEST:5,../../../../Chests/Loot/Epic14.nbt,2,CHEST:5,../../../../Chests/Loot/Epic15.nbt,5,CHEST:5,../../../../Chests/Loot/Rare1.nbt,5,CHEST:5,../../../../Chests/Loot/Rare2.nbt,5,CHEST:5,../../../../Chests/Loot/Rare3.nbt,5,CHEST:5,../../../../Chests/Loot/Rare4.nbt,5,CHEST:5,../../../../Chests/Loot/Rare5.nbt,10,CHEST:5,../../../../Chests/Loot/Rare6.nbt,10,CHEST:5,../../../../Chests/Loot/Rare7.nbt,10,CHEST:5,../../../../Chests/Loot/Rare8.nbt,10,CHEST:5,../../../../Chests/Loot/Rare9.nbt,10,CHEST:5,../../../../Chests/Loot/Rare10.nbt,15,CHEST:5,../../../../Chests/Loot/Rare11.nbt,15,CHEST:5,../../../../Chests/Loot/Rare12.nbt,15,CHEST:5,../../../../Chests/Loot/Rare13.nbt,15,CHEST:5,../../../../Chests/Loot/Rare14.nbt,15,CHEST:5,../../../../Chests/Loot/Rare15.nbt,15,CHEST:5,../../../../Chests/Loot/Epic15.nbt,100)
RandomBlock(-1,11,-3,AIR:0,20,CHEST:5,../../../../Chests/Loot/ShipJunk_1.nbt,10,CHEST:5,../../../../Chests/Loot/ShipJunk_2.nbt,10,CHEST:5,../../../../Chests/Loot/ShipJunk_3.nbt,10,CHEST:5,../../../../Chests/Loot/ShipJunk_4.nbt,10,CHEST:5,../../../../Chests/Loot/ShipJunk_5.nbt,10,CHEST:5,../../../../Chests/Lore/Frozen_1.nbt,1,CHEST:5,../../../../Chests/Lore/Frozen_2.nbt,1,CHEST:5,../../../../Chests/Lore/Frozen_3.nbt,1,CHEST:5,../../../../Chests/Lore/Frozen_4.nbt,1,CHEST:5,../../../../Chests/Lore/Frozen_5.nbt,1,CHEST:5,../../../../Chests/Loot/Common1.nbt,10,CHEST:5,../../../../Chests/Loot/Common2.nbt,10,CHEST:5,../../../../Chests/Loot/Common3.nbt,10,CHEST:5,../../../../Chests/Loot/Common4.nbt,10,CHEST:5,../../../../Chests/Loot/Common5.nbt,10,CHEST:5,../../../../Chests/Loot/Common6.nbt,10,CHEST:5,../../../../Chests/Loot/Common7.nbt,10,CHEST:5,../../../../Chests/Loot/Common8.nbt,10,CHEST:5,../../../../Chests/Loot/Common9.nbt,10,CHEST:5,../../../../Chests/Loot/Common10.nbt,10,CHEST:5,../../../../Chests/Loot/Common10.nbt,11,CHEST:5,../../../../Chests/Loot/Common12.nbt,10,CHEST:5,../../../../Chests/Loot/Common13.nbt,10,CHEST:5,../../../../Chests/Loot/Common14.nbt,10,CHEST:5,../../../../Chests/Loot/Common15.nbt,10,CHEST:5,../../../../Chests/Lore/Frozen_1.nbt,2,CHEST:5,../../../../Chests/Lore/Frozen_3.nbt,2,CHEST:5,../../../../Chests/Lore/Frozen_4.nbt,2,CHEST:5,../../../../Chests/Lore/Frozen_5.nbt,2,CHEST:5,../../../../Chests/Lore/Frozen_5.nbt,2,CHEST:5,../../../../Chests/Loot/Rare1.nbt,5,CHEST:5,../../../../Chests/Loot/Rare2.nbt,5,CHEST:5,../../../../Chests/Loot/Rare3.nbt,5,CHEST:5,../../../../Chests/Loot/Rare4.nbt,5,CHEST:5,../../../../Chests/Loot/Rare5.nbt,5,CHEST:5,../../../../Chests/Loot/Rare6.nbt,5,CHEST:5,../../../../Chests/Loot/Rare7.nbt,5,CHEST:5,../../../../Chests/Loot/Rare8.nbt,5,CHEST:5,../../../../Chests/Loot/Rare9.nbt,5,CHEST:5,../../../../Chests/Loot/Rare10.nbt,5,CHEST:5,../../../../Chests/Loot/Rare11.nbt,5,CHEST:5,../../../../Chests/Loot/Rare12.nbt,5,CHEST:5,../../../../Chests/Loot/Rare13.nbt,5,CHEST:5,../../../../Chests/Loot/Rare14.nbt,5,CHEST:5,../../../../Chests/Loot/Rare15.nbt,5,CHEST:5,../../../../Chests/Loot/Epic1.nbt,2,CHEST:5,../../../../Chests/Loot/Epic2.nbt,2,CHEST:5,../../../../Chests/Loot/Epic3.nbt,2,CHEST:5,../../../../Chests/Loot/Epic4.nbt,2,CHEST:5,../../../../Chests/Loot/Epic5.nbt,2,CHEST:5,../../../../Chests/Loot/Epic6.nbt,2,CHEST:5,../../../../Chests/Loot/Epic7.nbt,2,CHEST:5,../../../../Chests/Loot/Epic8.nbt,2,CHEST:5,../../../../Chests/Loot/Epic9.nbt,2,CHEST:5,../../../../Chests/Loot/Epic10.nbt,2,CHEST:5,../../../../Chests/Loot/Epic11.nbt,2,CHEST:5,../../../../Chests/Loot/Epic12.nbt,2,CHEST:5,../../../../Chests/Loot/Epic13.nbt,2,CHEST:5,../../../../Chests/Loot/Epic14.nbt,2,CHEST:5,../../../../Chests/Loot/Epic15.nbt,5,CHEST:5,../../../../Chests/Loot/Rare1.nbt,5,CHEST:5,../../../../Chests/Loot/Rare2.nbt,5,CHEST:5,../../../../Chests/Loot/Rare3.nbt,5,CHEST:5,../../../../Chests/Loot/Rare4.nbt,5,CHEST:5,../../../../Chests/Loot/Rare5.nbt,10,CHEST:5,../../../../Chests/Loot/Rare6.nbt,10,CHEST:5,../../../../Chests/Loot/Rare7.nbt,10,CHEST:5,../../../../Chests/Loot/Rare8.nbt,10,CHEST:5,../../../../Chests/Loot/Rare9.nbt,10,CHEST:5,../../../../Chests/Loot/Rare10.nbt,15,CHEST:5,../../../../Chests/Loot/Rare11.nbt,15,CHEST:5,../../../../Chests/Loot/Rare12.nbt,15,CHEST:5,../../../../Chests/Loot/Rare13.nbt,15,CHEST:5,../../../../Chests/Loot/Rare14.nbt,15,CHEST:5,../../../../Chests/Loot/Rare15.nbt,15,CHEST:5,../../../../Chests/Loot/Epic15.nbt,100)
Block(-1,11,-2,WOOD:1)
Block(-1,11,-1,PACKED_ICE:0)
Block(-1,11,0,ICE:0)
Block(-1,12,-7,WOOD_STEP:0)
Block(-1,12,-6,WOOD_STEP:0)
Block(-1,12,-5,WOOD_STEP:0)
Block(-1,12,-4,WOOD_STEP:0)
Block(-1,12,-3,WOOD_STEP:0)
Block(-1,12,-2,WOOD:5)
Block(-1,12,-1,DARK_OAK_STAIRS:7)
Block(-1,12,0,ICE:0)
Block(-1,12,1,ICE:0)
Block(-1,13,-2,WOOD:1)
Block(-1,13,-1,WOOD:5)
Block(-1,13,0,WOOD_STEP:13)
Block(-1,13,1,PACKED_ICE:0)
Block(-1,13,2,ICE:0)
Block(-1,14,-5,DARK_OAK_STAIRS:5)
Block(-1,14,-2,SNOW_BLOCK:0)
Block(-1,14,-1,WOOD:1)
Block(-1,14,0,WOOD:1)
Block(-1,14,1,WOOD_STEP:9)
Block(-1,14,2,ICE:0)
Block(-1,14,6,WOOL:0)
Block(-1,15,-5,WOOD:5)
Block(-1,15,-4,WOOD_STEP:8)
Block(-1,15,-3,WOOD_STEP:8)
Block(-1,15,-2,WOOD_STEP:8)
Block(-1,15,-1,WOOD_DOUBLE_STEP:0)
Block(-1,15,0,WOOD:5)
Block(-1,15,1,WOOD:5)
Block(-1,15,2,PACKED_ICE:0)
Block(-1,15,4,ICE:0)
Block(-1,15,5,WOOL:14)
Block(-1,16,-5,FENCE:0)
Block(-1,16,-1,SNOW:5)
Block(-1,16,0,FENCE:0)
Block(-1,16,1,FENCE:0)
Block(-1,16,2,ICE:0)
Block(-1,16,4,ICE:0)
Block(-1,16,5,WOOL:0)
Block(-1,17,4,ICE:0)
Block(-1,17,5,ICE:0)
Block(-1,18,-7,WOOL:14)
Block(-1,18,1,WOOL:0)
Block(-1,18,4,ICE:0)
Block(-1,18,5,WOOD_STEP:5)
Block(-1,18,6,ICE:0)
Block(-1,19,-7,WOOL:0)
Block(-1,19,-2,ICE:0)
Block(-1,19,1,WOOL:14)
Block(-1,20,-6,WOOL:0)
Block(-1,20,-2,ICE:0)
Block(-1,20,2,WOOL:0)
Block(-1,21,-6,WOOL:14)
Block(-1,21,-2,ICE:0)
Block(-1,21,1,WOOL:14)
Block(-1,22,-6,WOOL:0)
Block(-1,22,-2,PACKED_ICE:0)
Block(-1,22,-1,PACKED_ICE:0)
Block(-1,22,1,WOOL:0)
Block(-1,23,-7,WOOL:0)
Block(-1,23,-2,PACKED_ICE:0)
Block(-1,23,-1,ICE:0)
Block(-1,23,1,WOOL:14)
Block(-1,24,-7,WOOL:14)
Block(-1,24,-2,PACKED_ICE:0)
Block(-1,24,-1,PACKED_ICE:0)
Block(-1,25,-2,PACKED_ICE:0)
Block(-1,25,-1,LOG:5)
Block(-1,25,0,STONE_BUTTON:3)
Block(-1,26,-1,SNOW:1)
Block(-1,28,-7,WOOL:0)
Block(-1,29,-7,WOOL:14)
Block(0,6,-7,WOOD:5)
Block(0,6,-6,WOOD:5)
Block(0,7,-7,WOOD:5)
Block(0,7,-6,WOOD:5)
Block(0,7,-5,WOOD:5)
Block(0,7,-4,WOOD:5)
Block(0,7,-3,WOOD:5)
Block(0,8,-7,AIR:0)
Block(0,8,-6,AIR:0)
Block(0,8,-5,AIR:0)
Block(0,8,-4,AIR:0)
Block(0,8,-3,LADDER:2)
Block(0,8,-2,WOOD:5)
Block(0,9,-7,AIR:0)
Block(0,9,-6,AIR:0)
Block(0,9,-5,AIR:0)
Block(0,9,-4,AIR:0)
Block(0,9,-3,LADDER:2)
Block(0,9,-2,LOG:1)
Block(0,9,-1,WOOD:5)
Block(0,9,1,ICE:0)
Block(0,10,-3,LADDER:2)
Block(0,10,-2,LOG:1)
Block(0,10,-1,WOOD:5)
Block(0,10,1,ICE:0)
Block(0,11,-6,WOOD:5)
Block(0,11,-3,LADDER:2)
Block(0,11,-2,LOG:1)
Block(0,11,-1,WOOD:5)
Block(0,11,0,PACKED_ICE:0)
Block(0,11,1,PACKED_ICE:0)
Block(0,12,-7,WOOD_STEP:0)
Block(0,12,-6,WOOD_STEP:0)
Block(0,12,-5,WOOD_STEP:0)
Block(0,12,-4,WOOD_STEP:0)
Block(0,12,-3,LADDER:2)
Block(0,12,-2,LOG:1)
Block(0,12,-1,WOOD:5)
Block(0,12,0,PACKED_ICE:0)
Block(0,12,1,PACKED_ICE:0)
Block(0,13,-3,LADDER:2)
Block(0,13,-2,LOG:1)
Block(0,13,0,WOOD:5)
Block(0,13,1,WOOD_STEP:13)
Block(0,14,-3,LADDER:2)
Block(0,14,-2,LOG:1)
Block(0,14,1,WOOD:5)
Block(0,14,2,DARK_OAK_STAIRS:7)
Block(0,14,4,PACKED_ICE:0)
Block(0,14,6,WOOL:14)
Block(0,15,-5,WOOD:5)
Block(0,15,-4,WOOD_STEP:8)
Block(0,15,-3,LADDER:2)
Block(0,15,-2,LOG:1)
Block(0,15,-1,WOOD_STEP:8)
Block(0,15,0,WOOD_STEP:8)
Block(0,15,1,WOOD_STEP:8)
Block(0,15,2,WOOD:5)
Block(0,15,4,PACKED_ICE:0)
Block(0,15,6,WOOL:14)
Block(0,15,8,ICE:0)
Block(0,16,-5,FENCE:0)
Block(0,16,-2,LOG:0)
Block(0,16,-1,SNOW_BLOCK:0)
Block(0,16,0,WOOD_STEP:5)
Block(0,16,1,WOOD_DOUBLE_STEP:5)
Block(0,16,2,WOOD_STEP:13)
Block(0,16,3,PACKED_ICE:0)
Block(0,16,4,PACKED_ICE:0)
Block(0,16,5,WOOL:14)
Block(0,16,8,PACKED_ICE:0)
Block(0,17,-2,LOG:1)
Block(0,17,-1,SNOW:2)
Block(0,17,2,WOOD_STEP:5)
Block(0,17,3,WOOD_DOUBLE_STEP:5)
Block(0,17,4,PACKED_ICE:0)
Block(0,17,5,ICE:0)
Block(0,17,6,PACKED_ICE:0)
Block(0,17,8,ICE:0)
Block(0,18,-7,WOOL:14)
Block(0,18,-2,LOG:1)
Block(0,18,1,WOOL:0)
Block(0,18,4,WOOD_STEP:5)
Block(0,18,5,WOOD_DOUBLE_STEP:5)
Block(0,18,6,WOOD_STEP:13)
Block(0,18,7,PACKED_ICE:0)
Block(0,18,8,ICE:0)
Block(0,19,-6,WOOL:14)
Block(0,19,-2,LOG:1)
Block(0,19,2,WOOL:14)
Block(0,19,6,WOOD_STEP:5)
Block(0,19,7,WOOD_DOUBLE_STEP:5)
Block(0,19,8,WOOD_STEP:13)
Block(0,20,-6,WOOL:14)
Block(0,20,-2,LOG:0)
Block(0,20,2,WOOL:14)
Block(0,20,4,ICE:0)
Block(0,20,6,FENCE:0)
Block(0,20,7,FENCE:0)
Block(0,21,-6,WOOL:14)
Block(0,21,-2,LOG:1)
Block(0,21,2,WOOL:14)
Block(0,21,3,ICE:0)
Block(0,21,4,PACKED_ICE:0)
Block(0,21,5,FENCE:0)
Block(0,21,6,FENCE:0)
Block(0,22,-6,WOOL:14)
Block(0,22,-3,ICE:0)
Block(0,22,-2,LOG:1)
Block(0,22,1,WOOL:14)
Block(0,22,2,PACKED_ICE:0)
Block(0,22,3,ICE:0)
Block(0,22,4,FENCE:0)
Block(0,22,5,FENCE:0)
Block(0,23,-6,WOOL:14)
Block(0,23,-3,PACKED_ICE:0)
Block(0,23,-2,LOG:1)
Block(0,23,1,WOOL:14)
Block(0,23,2,PACKED_ICE:0)
Block(0,23,3,FENCE:0)
Block(0,23,4,FENCE:0)
Block(0,24,-7,WOOL:14)
Block(0,24,-3,PACKED_ICE:0)
Block(0,24,-2,LOG:0)
Block(0,24,-1,ICE:0)
Block(0,24,1,ICE:0)
Block(0,24,2,FENCE:0)
Block(0,24,3,FENCE:0)
Block(0,25,-3,ICE:0)
Block(0,25,-2,LOG:1)
Block(0,25,-1,LOG:5)
Block(0,25,0,STONE_BUTTON:3)
Block(0,25,1,FENCE:0)
Block(0,25,2,FENCE:0)
Block(0,26,-6,ICE:0)
Block(0,26,-4,ICE:0)
Block(0,26,-3,PACKED_ICE:0)
Block(0,26,-2,LOG:1)
Block(0,26,-1,ICE:0)
Block(0,26,0,FENCE:0)
Block(0,26,1,FENCE:0)
Block(0,27,-6,ICE:0)
Block(0,27,-5,ICE:0)
Block(0,27,-4,FENCE:0)
Block(0,27,-3,FENCE:0)
Block(0,27,-2,LOG:1)
Block(0,27,-1,FENCE:0)
Block(0,27,0,FENCE:0)
Block(0,28,-7,WOOL:14)
Block(0,28,-6,PACKED_ICE:0)
Block(0,28,-5,FENCE:0)
Block(0,28,-4,FENCE:0)
Block(0,28,-2,DARK_OAK_FENCE:0)
Block(0,29,-7,WOOL:14)
Block(0,29,-6,FENCE:0)
Block(0,29,-5,FENCE:0)
Block(0,29,-2,DARK_OAK_FENCE:0)
Block(0,30,-7,FENCE:0)
Block(0,30,-6,FENCE:0)
Block(0,30,-2,DARK_OAK_FENCE:0)
Block(0,31,-7,FENCE:0)
Block(1,6,-7,ICE:0)
Block(1,7,-7,WOOD:5)
Block(1,7,-6,WOOD:5)
Block(1,7,-5,WOOD:5)
Block(1,7,-4,WOOD:5)
Block(1,7,-3,ICE:0)
Block(1,8,-7,AIR:0)
RandomBlock(1,8,-6,AIR:0,20,CHEST:4,../../../../Chests/Loot/ShipJunk_1.nbt,10,CHEST:4,../../../../Chests/Loot/ShipJunk_2.nbt,10,CHEST:4,../../../../Chests/Loot/ShipJunk_3.nbt,10,CHEST:4,../../../../Chests/Loot/ShipJunk_4.nbt,10,CHEST:4,../../../../Chests/Loot/ShipJunk_5.nbt,10,CHEST:4,../../../../Chests/Lore/Frozen_1.nbt,1,CHEST:4,../../../../Chests/Lore/Frozen_2.nbt,1,CHEST:4,../../../../Chests/Lore/Frozen_3.nbt,1,CHEST:4,../../../../Chests/Lore/Frozen_4.nbt,1,CHEST:4,../../../../Chests/Lore/Frozen_5.nbt,1,CHEST:4,../../../../Chests/Loot/Common1.nbt,10,CHEST:4,../../../../Chests/Loot/Common2.nbt,10,CHEST:4,../../../../Chests/Loot/Common3.nbt,10,CHEST:4,../../../../Chests/Loot/Common4.nbt,10,CHEST:4,../../../../Chests/Loot/Common5.nbt,10,CHEST:4,../../../../Chests/Loot/Common6.nbt,10,CHEST:4,../../../../Chests/Loot/Common7.nbt,10,CHEST:4,../../../../Chests/Loot/Common8.nbt,10,CHEST:4,../../../../Chests/Loot/Common9.nbt,10,CHEST:4,../../../../Chests/Loot/Common10.nbt,10,CHEST:4,../../../../Chests/Loot/Common10.nbt,11,CHEST:4,../../../../Chests/Loot/Common12.nbt,10,CHEST:4,../../../../Chests/Loot/Common13.nbt,10,CHEST:4,../../../../Chests/Loot/Common14.nbt,10,CHEST:4,../../../../Chests/Loot/Common15.nbt,10,CHEST:4,../../../../Chests/Lore/Frozen_1.nbt,2,CHEST:4,../../../../Chests/Lore/Frozen_3.nbt,2,CHEST:4,../../../../Chests/Lore/Frozen_4.nbt,2,CHEST:4,../../../../Chests/Lore/Frozen_5.nbt,2,CHEST:4,../../../../Chests/Lore/Frozen_5.nbt,2,CHEST:4,../../../../Chests/Loot/Rare1.nbt,5,CHEST:4,../../../../Chests/Loot/Rare2.nbt,5,CHEST:4,../../../../Chests/Loot/Rare3.nbt,5,CHEST:4,../../../../Chests/Loot/Rare4.nbt,5,CHEST:4,../../../../Chests/Loot/Rare5.nbt,5,CHEST:4,../../../../Chests/Loot/Rare6.nbt,5,CHEST:4,../../../../Chests/Loot/Rare7.nbt,5,CHEST:4,../../../../Chests/Loot/Rare8.nbt,5,CHEST:4,../../../../Chests/Loot/Rare9.nbt,5,CHEST:4,../../../../Chests/Loot/Rare10.nbt,5,CHEST:4,../../../../Chests/Loot/Rare11.nbt,5,CHEST:4,../../../../Chests/Loot/Rare12.nbt,5,CHEST:4,../../../../Chests/Loot/Rare13.nbt,5,CHEST:4,../../../../Chests/Loot/Rare14.nbt,5,CHEST:4,../../../../Chests/Loot/Rare15.nbt,5,CHEST:4,../../../../Chests/Loot/Epic1.nbt,2,CHEST:4,../../../../Chests/Loot/Epic2.nbt,2,CHEST:4,../../../../Chests/Loot/Epic3.nbt,2,CHEST:4,../../../../Chests/Loot/Epic4.nbt,2,CHEST:4,../../../../Chests/Loot/Epic5.nbt,2,CHEST:4,../../../../Chests/Loot/Epic6.nbt,2,CHEST:4,../../../../Chests/Loot/Epic7.nbt,2,CHEST:4,../../../../Chests/Loot/Epic8.nbt,2,CHEST:4,../../../../Chests/Loot/Epic9.nbt,2,CHEST:4,../../../../Chests/Loot/Epic10.nbt,2,CHEST:4,../../../../Chests/Loot/Epic11.nbt,2,CHEST:4,../../../../Chests/Loot/Epic12.nbt,2,CHEST:4,../../../../Chests/Loot/Epic13.nbt,2,CHEST:4,../../../../Chests/Loot/Epic14.nbt,2,CHEST:4,../../../../Chests/Loot/Epic15.nbt,5,CHEST:4,../../../../Chests/Loot/Rare1.nbt,5,CHEST:4,../../../../Chests/Loot/Rare2.nbt,5,CHEST:4,../../../../Chests/Loot/Rare3.nbt,5,CHEST:4,../../../../Chests/Loot/Rare4.nbt,5,CHEST:4,../../../../Chests/Loot/Rare5.nbt,10,CHEST:4,../../../../Chests/Loot/Rare6.nbt,10,CHEST:4,../../../../Chests/Loot/Rare7.nbt,10,CHEST:4,../../../../Chests/Loot/Rare8.nbt,10,CHEST:4,../../../../Chests/Loot/Rare9.nbt,10,CHEST:4,../../../../Chests/Loot/Rare10.nbt,15,CHEST:4,../../../../Chests/Loot/Rare11.nbt,15,CHEST:4,../../../../Chests/Loot/Rare12.nbt,15,CHEST:4,../../../../Chests/Loot/Rare13.nbt,15,CHEST:4,../../../../Chests/Loot/Rare14.nbt,15,CHEST:4,../../../../Chests/Loot/Rare15.nbt,15,CHEST:4,../../../../Chests/Loot/Epic15.nbt,100)
RandomBlock(1,8,-5,AIR:0,20,CHEST:4,../../../../Chests/Loot/ShipJunk_1.nbt,10,CHEST:4,../../../../Chests/Loot/ShipJunk_2.nbt,10,CHEST:4,../../../../Chests/Loot/ShipJunk_3.nbt,10,CHEST:4,../../../../Chests/Loot/ShipJunk_4.nbt,10,CHEST:4,../../../../Chests/Loot/ShipJunk_5.nbt,10,CHEST:4,../../../../Chests/Lore/Frozen_1.nbt,1,CHEST:4,../../../../Chests/Lore/Frozen_2.nbt,1,CHEST:4,../../../../Chests/Lore/Frozen_3.nbt,1,CHEST:4,../../../../Chests/Lore/Frozen_4.nbt,1,CHEST:4,../../../../Chests/Lore/Frozen_5.nbt,1,CHEST:4,../../../../Chests/Loot/Common1.nbt,10,CHEST:4,../../../../Chests/Loot/Common2.nbt,10,CHEST:4,../../../../Chests/Loot/Common3.nbt,10,CHEST:4,../../../../Chests/Loot/Common4.nbt,10,CHEST:4,../../../../Chests/Loot/Common5.nbt,10,CHEST:4,../../../../Chests/Loot/Common6.nbt,10,CHEST:4,../../../../Chests/Loot/Common7.nbt,10,CHEST:4,../../../../Chests/Loot/Common8.nbt,10,CHEST:4,../../../../Chests/Loot/Common9.nbt,10,CHEST:4,../../../../Chests/Loot/Common10.nbt,10,CHEST:4,../../../../Chests/Loot/Common10.nbt,11,CHEST:4,../../../../Chests/Loot/Common12.nbt,10,CHEST:4,../../../../Chests/Loot/Common13.nbt,10,CHEST:4,../../../../Chests/Loot/Common14.nbt,10,CHEST:4,../../../../Chests/Loot/Common15.nbt,10,CHEST:4,../../../../Chests/Lore/Frozen_1.nbt,2,CHEST:4,../../../../Chests/Lore/Frozen_3.nbt,2,CHEST:4,../../../../Chests/Lore/Frozen_4.nbt,2,CHEST:4,../../../../Chests/Lore/Frozen_5.nbt,2,CHEST:4,../../../../Chests/Lore/Frozen_5.nbt,2,CHEST:4,../../../../Chests/Loot/Rare1.nbt,5,CHEST:4,../../../../Chests/Loot/Rare2.nbt,5,CHEST:4,../../../../Chests/Loot/Rare3.nbt,5,CHEST:4,../../../../Chests/Loot/Rare4.nbt,5,CHEST:4,../../../../Chests/Loot/Rare5.nbt,5,CHEST:4,../../../../Chests/Loot/Rare6.nbt,5,CHEST:4,../../../../Chests/Loot/Rare7.nbt,5,CHEST:4,../../../../Chests/Loot/Rare8.nbt,5,CHEST:4,../../../../Chests/Loot/Rare9.nbt,5,CHEST:4,../../../../Chests/Loot/Rare10.nbt,5,CHEST:4,../../../../Chests/Loot/Rare11.nbt,5,CHEST:4,../../../../Chests/Loot/Rare12.nbt,5,CHEST:4,../../../../Chests/Loot/Rare13.nbt,5,CHEST:4,../../../../Chests/Loot/Rare14.nbt,5,CHEST:4,../../../../Chests/Loot/Rare15.nbt,5,CHEST:4,../../../../Chests/Loot/Epic1.nbt,2,CHEST:4,../../../../Chests/Loot/Epic2.nbt,2,CHEST:4,../../../../Chests/Loot/Epic3.nbt,2,CHEST:4,../../../../Chests/Loot/Epic4.nbt,2,CHEST:4,../../../../Chests/Loot/Epic5.nbt,2,CHEST:4,../../../../Chests/Loot/Epic6.nbt,2,CHEST:4,../../../../Chests/Loot/Epic7.nbt,2,CHEST:4,../../../../Chests/Loot/Epic8.nbt,2,CHEST:4,../../../../Chests/Loot/Epic9.nbt,2,CHEST:4,../../../../Chests/Loot/Epic10.nbt,2,CHEST:4,../../../../Chests/Loot/Epic11.nbt,2,CHEST:4,../../../../Chests/Loot/Epic12.nbt,2,CHEST:4,../../../../Chests/Loot/Epic13.nbt,2,CHEST:4,../../../../Chests/Loot/Epic14.nbt,2,CHEST:4,../../../../Chests/Loot/Epic15.nbt,5,CHEST:4,../../../../Chests/Loot/Rare1.nbt,5,CHEST:4,../../../../Chests/Loot/Rare2.nbt,5,CHEST:4,../../../../Chests/Loot/Rare3.nbt,5,CHEST:4,../../../../Chests/Loot/Rare4.nbt,5,CHEST:4,../../../../Chests/Loot/Rare5.nbt,10,CHEST:4,../../../../Chests/Loot/Rare6.nbt,10,CHEST:4,../../../../Chests/Loot/Rare7.nbt,10,CHEST:4,../../../../Chests/Loot/Rare8.nbt,10,CHEST:4,../../../../Chests/Loot/Rare9.nbt,10,CHEST:4,../../../../Chests/Loot/Rare10.nbt,15,CHEST:4,../../../../Chests/Loot/Rare11.nbt,15,CHEST:4,../../../../Chests/Loot/Rare12.nbt,15,CHEST:4,../../../../Chests/Loot/Rare13.nbt,15,CHEST:4,../../../../Chests/Loot/Rare14.nbt,15,CHEST:4,../../../../Chests/Loot/Rare15.nbt,15,CHEST:4,../../../../Chests/Loot/Epic15.nbt,100)
RandomBlock(1,8,-4,AIR:0,20,CHEST:4,../../../../Chests/Loot/ShipJunk_1.nbt,10,CHEST:4,../../../../Chests/Loot/ShipJunk_2.nbt,10,CHEST:4,../../../../Chests/Loot/ShipJunk_3.nbt,10,CHEST:4,../../../../Chests/Loot/ShipJunk_4.nbt,10,CHEST:4,../../../../Chests/Loot/ShipJunk_5.nbt,10,CHEST:4,../../../../Chests/Lore/Frozen_1.nbt,1,CHEST:4,../../../../Chests/Lore/Frozen_2.nbt,1,CHEST:4,../../../../Chests/Lore/Frozen_3.nbt,1,CHEST:4,../../../../Chests/Lore/Frozen_4.nbt,1,CHEST:4,../../../../Chests/Lore/Frozen_5.nbt,1,CHEST:4,../../../../Chests/Loot/Common1.nbt,10,CHEST:4,../../../../Chests/Loot/Common2.nbt,10,CHEST:4,../../../../Chests/Loot/Common3.nbt,10,CHEST:4,../../../../Chests/Loot/Common4.nbt,10,CHEST:4,../../../../Chests/Loot/Common5.nbt,10,CHEST:4,../../../../Chests/Loot/Common6.nbt,10,CHEST:4,../../../../Chests/Loot/Common7.nbt,10,CHEST:4,../../../../Chests/Loot/Common8.nbt,10,CHEST:4,../../../../Chests/Loot/Common9.nbt,10,CHEST:4,../../../../Chests/Loot/Common10.nbt,10,CHEST:4,../../../../Chests/Loot/Common10.nbt,11,CHEST:4,../../../../Chests/Loot/Common12.nbt,10,CHEST:4,../../../../Chests/Loot/Common13.nbt,10,CHEST:4,../../../../Chests/Loot/Common14.nbt,10,CHEST:4,../../../../Chests/Loot/Common15.nbt,10,CHEST:4,../../../../Chests/Lore/Frozen_1.nbt,2,CHEST:4,../../../../Chests/Lore/Frozen_3.nbt,2,CHEST:4,../../../../Chests/Lore/Frozen_4.nbt,2,CHEST:4,../../../../Chests/Lore/Frozen_5.nbt,2,CHEST:4,../../../../Chests/Lore/Frozen_5.nbt,2,CHEST:4,../../../../Chests/Loot/Rare1.nbt,5,CHEST:4,../../../../Chests/Loot/Rare2.nbt,5,CHEST:4,../../../../Chests/Loot/Rare3.nbt,5,CHEST:4,../../../../Chests/Loot/Rare4.nbt,5,CHEST:4,../../../../Chests/Loot/Rare5.nbt,5,CHEST:4,../../../../Chests/Loot/Rare6.nbt,5,CHEST:4,../../../../Chests/Loot/Rare7.nbt,5,CHEST:4,../../../../Chests/Loot/Rare8.nbt,5,CHEST:4,../../../../Chests/Loot/Rare9.nbt,5,CHEST:4,../../../../Chests/Loot/Rare10.nbt,5,CHEST:4,../../../../Chests/Loot/Rare11.nbt,5,CHEST:4,../../../../Chests/Loot/Rare12.nbt,5,CHEST:4,../../../../Chests/Loot/Rare13.nbt,5,CHEST:4,../../../../Chests/Loot/Rare14.nbt,5,CHEST:4,../../../../Chests/Loot/Rare15.nbt,5,CHEST:4,../../../../Chests/Loot/Epic1.nbt,2,CHEST:4,../../../../Chests/Loot/Epic2.nbt,2,CHEST:4,../../../../Chests/Loot/Epic3.nbt,2,CHEST:4,../../../../Chests/Loot/Epic4.nbt,2,CHEST:4,../../../../Chests/Loot/Epic5.nbt,2,CHEST:4,../../../../Chests/Loot/Epic6.nbt,2,CHEST:4,../../../../Chests/Loot/Epic7.nbt,2,CHEST:4,../../../../Chests/Loot/Epic8.nbt,2,CHEST:4,../../../../Chests/Loot/Epic9.nbt,2,CHEST:4,../../../../Chests/Loot/Epic10.nbt,2,CHEST:4,../../../../Chests/Loot/Epic11.nbt,2,CHEST:4,../../../../Chests/Loot/Epic12.nbt,2,CHEST:4,../../../../Chests/Loot/Epic13.nbt,2,CHEST:4,../../../../Chests/Loot/Epic14.nbt,2,CHEST:4,../../../../Chests/Loot/Epic15.nbt,5,CHEST:4,../../../../Chests/Loot/Rare1.nbt,5,CHEST:4,../../../../Chests/Loot/Rare2.nbt,5,CHEST:4,../../../../Chests/Loot/Rare3.nbt,5,CHEST:4,../../../../Chests/Loot/Rare4.nbt,5,CHEST:4,../../../../Chests/Loot/Rare5.nbt,10,CHEST:4,../../../../Chests/Loot/Rare6.nbt,10,CHEST:4,../../../../Chests/Loot/Rare7.nbt,10,CHEST:4,../../../../Chests/Loot/Rare8.nbt,10,CHEST:4,../../../../Chests/Loot/Rare9.nbt,10,CHEST:4,../../../../Chests/Loot/Rare10.nbt,15,CHEST:4,../../../../Chests/Loot/Rare11.nbt,15,CHEST:4,../../../../Chests/Loot/Rare12.nbt,15,CHEST:4,../../../../Chests/Loot/Rare13.nbt,15,CHEST:4,../../../../Chests/Loot/Rare14.nbt,15,CHEST:4,../../../../Chests/Loot/Rare15.nbt,15,CHEST:4,../../../../Chests/Loot/Epic15.nbt,100)
Block(1,8,-3,WOOD:5)
Block(1,8,-1,PACKED_ICE:0)
Block(1,9,-7,AIR:0)
RandomBlock(1,9,-6,AIR:0,20,CHEST:4,../../../../Chests/Loot/ShipJunk_1.nbt,10,CHEST:4,../../../../Chests/Loot/ShipJunk_2.nbt,10,CHEST:4,../../../../Chests/Loot/ShipJunk_3.nbt,10,CHEST:4,../../../../Chests/Loot/ShipJunk_4.nbt,10,CHEST:4,../../../../Chests/Loot/ShipJunk_5.nbt,10,CHEST:4,../../../../Chests/Lore/Frozen_1.nbt,1,CHEST:4,../../../../Chests/Lore/Frozen_2.nbt,1,CHEST:4,../../../../Chests/Lore/Frozen_3.nbt,1,CHEST:4,../../../../Chests/Lore/Frozen_4.nbt,1,CHEST:4,../../../../Chests/Lore/Frozen_5.nbt,1,CHEST:4,../../../../Chests/Loot/Common1.nbt,10,CHEST:4,../../../../Chests/Loot/Common2.nbt,10,CHEST:4,../../../../Chests/Loot/Common3.nbt,10,CHEST:4,../../../../Chests/Loot/Common4.nbt,10,CHEST:4,../../../../Chests/Loot/Common5.nbt,10,CHEST:4,../../../../Chests/Loot/Common6.nbt,10,CHEST:4,../../../../Chests/Loot/Common7.nbt,10,CHEST:4,../../../../Chests/Loot/Common8.nbt,10,CHEST:4,../../../../Chests/Loot/Common9.nbt,10,CHEST:4,../../../../Chests/Loot/Common10.nbt,10,CHEST:4,../../../../Chests/Loot/Common10.nbt,11,CHEST:4,../../../../Chests/Loot/Common12.nbt,10,CHEST:4,../../../../Chests/Loot/Common13.nbt,10,CHEST:4,../../../../Chests/Loot/Common14.nbt,10,CHEST:4,../../../../Chests/Loot/Common15.nbt,10,CHEST:4,../../../../Chests/Lore/Frozen_1.nbt,2,CHEST:4,../../../../Chests/Lore/Frozen_3.nbt,2,CHEST:4,../../../../Chests/Lore/Frozen_4.nbt,2,CHEST:4,../../../../Chests/Lore/Frozen_5.nbt,2,CHEST:4,../../../../Chests/Lore/Frozen_5.nbt,2,CHEST:4,../../../../Chests/Loot/Rare1.nbt,5,CHEST:4,../../../../Chests/Loot/Rare2.nbt,5,CHEST:4,../../../../Chests/Loot/Rare3.nbt,5,CHEST:4,../../../../Chests/Loot/Rare4.nbt,5,CHEST:4,../../../../Chests/Loot/Rare5.nbt,5,CHEST:4,../../../../Chests/Loot/Rare6.nbt,5,CHEST:4,../../../../Chests/Loot/Rare7.nbt,5,CHEST:4,../../../../Chests/Loot/Rare8.nbt,5,CHEST:4,../../../../Chests/Loot/Rare9.nbt,5,CHEST:4,../../../../Chests/Loot/Rare10.nbt,5,CHEST:4,../../../../Chests/Loot/Rare11.nbt,5,CHEST:4,../../../../Chests/Loot/Rare12.nbt,5,CHEST:4,../../../../Chests/Loot/Rare13.nbt,5,CHEST:4,../../../../Chests/Loot/Rare14.nbt,5,CHEST:4,../../../../Chests/Loot/Rare15.nbt,5,CHEST:4,../../../../Chests/Loot/Epic1.nbt,2,CHEST:4,../../../../Chests/Loot/Epic2.nbt,2,CHEST:4,../../../../Chests/Loot/Epic3.nbt,2,CHEST:4,../../../../Chests/Loot/Epic4.nbt,2,CHEST:4,../../../../Chests/Loot/Epic5.nbt,2,CHEST:4,../../../../Chests/Loot/Epic6.nbt,2,CHEST:4,../../../../Chests/Loot/Epic7.nbt,2,CHEST:4,../../../../Chests/Loot/Epic8.nbt,2,CHEST:4,../../../../Chests/Loot/Epic9.nbt,2,CHEST:4,../../../../Chests/Loot/Epic10.nbt,2,CHEST:4,../../../../Chests/Loot/Epic11.nbt,2,CHEST:4,../../../../Chests/Loot/Epic12.nbt,2,CHEST:4,../../../../Chests/Loot/Epic13.nbt,2,CHEST:4,../../../../Chests/Loot/Epic14.nbt,2,CHEST:4,../../../../Chests/Loot/Epic15.nbt,5,CHEST:4,../../../../Chests/Loot/Rare1.nbt,5,CHEST:4,../../../../Chests/Loot/Rare2.nbt,5,CHEST:4,../../../../Chests/Loot/Rare3.nbt,5,CHEST:4,../../../../Chests/Loot/Rare4.nbt,5,CHEST:4,../../../../Chests/Loot/Rare5.nbt,10,CHEST:4,../../../../Chests/Loot/Rare6.nbt,10,CHEST:4,../../../../Chests/Loot/Rare7.nbt,10,CHEST:4,../../../../Chests/Loot/Rare8.nbt,10,CHEST:4,../../../../Chests/Loot/Rare9.nbt,10,CHEST:4,../../../../Chests/Loot/Rare10.nbt,15,CHEST:4,../../../../Chests/Loot/Rare11.nbt,15,CHEST:4,../../../../Chests/Loot/Rare12.nbt,15,CHEST:4,../../../../Chests/Loot/Rare13.nbt,15,CHEST:4,../../../../Chests/Loot/Rare14.nbt,15,CHEST:4,../../../../Chests/Loot/Rare15.nbt,15,CHEST:4,../../../../Chests/Loot/Epic15.nbt,100)
RandomBlock(1,9,-5,AIR:0,20,CHEST:4,../../../../Chests/Loot/ShipJunk_1.nbt,10,CHEST:4,../../../../Chests/Loot/ShipJunk_2.nbt,10,CHEST:4,../../../../Chests/Loot/ShipJunk_3.nbt,10,CHEST:4,../../../../Chests/Loot/ShipJunk_4.nbt,10,CHEST:4,../../../../Chests/Loot/ShipJunk_5.nbt,10,CHEST:4,../../../../Chests/Lore/Frozen_1.nbt,1,CHEST:4,../../../../Chests/Lore/Frozen_2.nbt,1,CHEST:4,../../../../Chests/Lore/Frozen_3.nbt,1,CHEST:4,../../../../Chests/Lore/Frozen_4.nbt,1,CHEST:4,../../../../Chests/Lore/Frozen_5.nbt,1,CHEST:4,../../../../Chests/Loot/Common1.nbt,10,CHEST:4,../../../../Chests/Loot/Common2.nbt,10,CHEST:4,../../../../Chests/Loot/Common3.nbt,10,CHEST:4,../../../../Chests/Loot/Common4.nbt,10,CHEST:4,../../../../Chests/Loot/Common5.nbt,10,CHEST:4,../../../../Chests/Loot/Common6.nbt,10,CHEST:4,../../../../Chests/Loot/Common7.nbt,10,CHEST:4,../../../../Chests/Loot/Common8.nbt,10,CHEST:4,../../../../Chests/Loot/Common9.nbt,10,CHEST:4,../../../../Chests/Loot/Common10.nbt,10,CHEST:4,../../../../Chests/Loot/Common10.nbt,11,CHEST:4,../../../../Chests/Loot/Common12.nbt,10,CHEST:4,../../../../Chests/Loot/Common13.nbt,10,CHEST:4,../../../../Chests/Loot/Common14.nbt,10,CHEST:4,../../../../Chests/Loot/Common15.nbt,10,CHEST:4,../../../../Chests/Lore/Frozen_1.nbt,2,CHEST:4,../../../../Chests/Lore/Frozen_3.nbt,2,CHEST:4,../../../../Chests/Lore/Frozen_4.nbt,2,CHEST:4,../../../../Chests/Lore/Frozen_5.nbt,2,CHEST:4,../../../../Chests/Lore/Frozen_5.nbt,2,CHEST:4,../../../../Chests/Loot/Rare1.nbt,5,CHEST:4,../../../../Chests/Loot/Rare2.nbt,5,CHEST:4,../../../../Chests/Loot/Rare3.nbt,5,CHEST:4,../../../../Chests/Loot/Rare4.nbt,5,CHEST:4,../../../../Chests/Loot/Rare5.nbt,5,CHEST:4,../../../../Chests/Loot/Rare6.nbt,5,CHEST:4,../../../../Chests/Loot/Rare7.nbt,5,CHEST:4,../../../../Chests/Loot/Rare8.nbt,5,CHEST:4,../../../../Chests/Loot/Rare9.nbt,5,CHEST:4,../../../../Chests/Loot/Rare10.nbt,5,CHEST:4,../../../../Chests/Loot/Rare11.nbt,5,CHEST:4,../../../../Chests/Loot/Rare12.nbt,5,CHEST:4,../../../../Chests/Loot/Rare13.nbt,5,CHEST:4,../../../../Chests/Loot/Rare14.nbt,5,CHEST:4,../../../../Chests/Loot/Rare15.nbt,5,CHEST:4,../../../../Chests/Loot/Epic1.nbt,2,CHEST:4,../../../../Chests/Loot/Epic2.nbt,2,CHEST:4,../../../../Chests/Loot/Epic3.nbt,2,CHEST:4,../../../../Chests/Loot/Epic4.nbt,2,CHEST:4,../../../../Chests/Loot/Epic5.nbt,2,CHEST:4,../../../../Chests/Loot/Epic6.nbt,2,CHEST:4,../../../../Chests/Loot/Epic7.nbt,2,CHEST:4,../../../../Chests/Loot/Epic8.nbt,2,CHEST:4,../../../../Chests/Loot/Epic9.nbt,2,CHEST:4,../../../../Chests/Loot/Epic10.nbt,2,CHEST:4,../../../../Chests/Loot/Epic11.nbt,2,CHEST:4,../../../../Chests/Loot/Epic12.nbt,2,CHEST:4,../../../../Chests/Loot/Epic13.nbt,2,CHEST:4,../../../../Chests/Loot/Epic14.nbt,2,CHEST:4,../../../../Chests/Loot/Epic15.nbt,5,CHEST:4,../../../../Chests/Loot/Rare1.nbt,5,CHEST:4,../../../../Chests/Loot/Rare2.nbt,5,CHEST:4,../../../../Chests/Loot/Rare3.nbt,5,CHEST:4,../../../../Chests/Loot/Rare4.nbt,5,CHEST:4,../../../../Chests/Loot/Rare5.nbt,10,CHEST:4,../../../../Chests/Loot/Rare6.nbt,10,CHEST:4,../../../../Chests/Loot/Rare7.nbt,10,CHEST:4,../../../../Chests/Loot/Rare8.nbt,10,CHEST:4,../../../../Chests/Loot/Rare9.nbt,10,CHEST:4,../../../../Chests/Loot/Rare10.nbt,15,CHEST:4,../../../../Chests/Loot/Rare11.nbt,15,CHEST:4,../../../../Chests/Loot/Rare12.nbt,15,CHEST:4,../../../../Chests/Loot/Rare13.nbt,15,CHEST:4,../../../../Chests/Loot/Rare14.nbt,15,CHEST:4,../../../../Chests/Loot/Rare15.nbt,15,CHEST:4,../../../../Chests/Loot/Epic15.nbt,100)
RandomBlock(1,9,-4,AIR:0,20,CHEST:4,../../../../Chests/Loot/ShipJunk_1.nbt,10,CHEST:4,../../../../Chests/Loot/ShipJunk_2.nbt,10,CHEST:4,../../../../Chests/Loot/ShipJunk_3.nbt,10,CHEST:4,../../../../Chests/Loot/ShipJunk_4.nbt,10,CHEST:4,../../../../Chests/Loot/ShipJunk_5.nbt,10,CHEST:4,../../../../Chests/Lore/Frozen_1.nbt,1,CHEST:4,../../../../Chests/Lore/Frozen_2.nbt,1,CHEST:4,../../../../Chests/Lore/Frozen_3.nbt,1,CHEST:4,../../../../Chests/Lore/Frozen_4.nbt,1,CHEST:4,../../../../Chests/Lore/Frozen_5.nbt,1,CHEST:4,../../../../Chests/Loot/Common1.nbt,10,CHEST:4,../../../../Chests/Loot/Common2.nbt,10,CHEST:4,../../../../Chests/Loot/Common3.nbt,10,CHEST:4,../../../../Chests/Loot/Common4.nbt,10,CHEST:4,../../../../Chests/Loot/Common5.nbt,10,CHEST:4,../../../../Chests/Loot/Common6.nbt,10,CHEST:4,../../../../Chests/Loot/Common7.nbt,10,CHEST:4,../../../../Chests/Loot/Common8.nbt,10,CHEST:4,../../../../Chests/Loot/Common9.nbt,10,CHEST:4,../../../../Chests/Loot/Common10.nbt,10,CHEST:4,../../../../Chests/Loot/Common10.nbt,11,CHEST:4,../../../../Chests/Loot/Common12.nbt,10,CHEST:4,../../../../Chests/Loot/Common13.nbt,10,CHEST:4,../../../../Chests/Loot/Common14.nbt,10,CHEST:4,../../../../Chests/Loot/Common15.nbt,10,CHEST:4,../../../../Chests/Lore/Frozen_1.nbt,2,CHEST:4,../../../../Chests/Lore/Frozen_3.nbt,2,CHEST:4,../../../../Chests/Lore/Frozen_4.nbt,2,CHEST:4,../../../../Chests/Lore/Frozen_5.nbt,2,CHEST:4,../../../../Chests/Lore/Frozen_5.nbt,2,CHEST:4,../../../../Chests/Loot/Rare1.nbt,5,CHEST:4,../../../../Chests/Loot/Rare2.nbt,5,CHEST:4,../../../../Chests/Loot/Rare3.nbt,5,CHEST:4,../../../../Chests/Loot/Rare4.nbt,5,CHEST:4,../../../../Chests/Loot/Rare5.nbt,5,CHEST:4,../../../../Chests/Loot/Rare6.nbt,5,CHEST:4,../../../../Chests/Loot/Rare7.nbt,5,CHEST:4,../../../../Chests/Loot/Rare8.nbt,5,CHEST:4,../../../../Chests/Loot/Rare9.nbt,5,CHEST:4,../../../../Chests/Loot/Rare10.nbt,5,CHEST:4,../../../../Chests/Loot/Rare11.nbt,5,CHEST:4,../../../../Chests/Loot/Rare12.nbt,5,CHEST:4,../../../../Chests/Loot/Rare13.nbt,5,CHEST:4,../../../../Chests/Loot/Rare14.nbt,5,CHEST:4,../../../../Chests/Loot/Rare15.nbt,5,CHEST:4,../../../../Chests/Loot/Epic1.nbt,2,CHEST:4,../../../../Chests/Loot/Epic2.nbt,2,CHEST:4,../../../../Chests/Loot/Epic3.nbt,2,CHEST:4,../../../../Chests/Loot/Epic4.nbt,2,CHEST:4,../../../../Chests/Loot/Epic5.nbt,2,CHEST:4,../../../../Chests/Loot/Epic6.nbt,2,CHEST:4,../../../../Chests/Loot/Epic7.nbt,2,CHEST:4,../../../../Chests/Loot/Epic8.nbt,2,CHEST:4,../../../../Chests/Loot/Epic9.nbt,2,CHEST:4,../../../../Chests/Loot/Epic10.nbt,2,CHEST:4,../../../../Chests/Loot/Epic11.nbt,2,CHEST:4,../../../../Chests/Loot/Epic12.nbt,2,CHEST:4,../../../../Chests/Loot/Epic13.nbt,2,CHEST:4,../../../../Chests/Loot/Epic14.nbt,2,CHEST:4,../../../../Chests/Loot/Epic15.nbt,5,CHEST:4,../../../../Chests/Loot/Rare1.nbt,5,CHEST:4,../../../../Chests/Loot/Rare2.nbt,5,CHEST:4,../../../../Chests/Loot/Rare3.nbt,5,CHEST:4,../../../../Chests/Loot/Rare4.nbt,5,CHEST:4,../../../../Chests/Loot/Rare5.nbt,10,CHEST:4,../../../../Chests/Loot/Rare6.nbt,10,CHEST:4,../../../../Chests/Loot/Rare7.nbt,10,CHEST:4,../../../../Chests/Loot/Rare8.nbt,10,CHEST:4,../../../../Chests/Loot/Rare9.nbt,10,CHEST:4,../../../../Chests/Loot/Rare10.nbt,15,CHEST:4,../../../../Chests/Loot/Rare11.nbt,15,CHEST:4,../../../../Chests/Loot/Rare12.nbt,15,CHEST:4,../../../../Chests/Loot/Rare13.nbt,15,CHEST:4,../../../../Chests/Loot/Rare14.nbt,15,CHEST:4,../../../../Chests/Loot/Rare15.nbt,15,CHEST:4,../../../../Chests/Loot/Epic15.nbt,100)
RandomBlock(1,9,-3,AIR:0,20,CHEST:4,../../../../Chests/Loot/ShipJunk_1.nbt,10,CHEST:4,../../../../Chests/Loot/ShipJunk_2.nbt,10,CHEST:4,../../../../Chests/Loot/ShipJunk_3.nbt,10,CHEST:4,../../../../Chests/Loot/ShipJunk_4.nbt,10,CHEST:4,../../../../Chests/Loot/ShipJunk_5.nbt,10,CHEST:4,../../../../Chests/Lore/Frozen_1.nbt,1,CHEST:4,../../../../Chests/Lore/Frozen_2.nbt,1,CHEST:4,../../../../Chests/Lore/Frozen_3.nbt,1,CHEST:4,../../../../Chests/Lore/Frozen_4.nbt,1,CHEST:4,../../../../Chests/Lore/Frozen_5.nbt,1,CHEST:4,../../../../Chests/Loot/Common1.nbt,10,CHEST:4,../../../../Chests/Loot/Common2.nbt,10,CHEST:4,../../../../Chests/Loot/Common3.nbt,10,CHEST:4,../../../../Chests/Loot/Common4.nbt,10,CHEST:4,../../../../Chests/Loot/Common5.nbt,10,CHEST:4,../../../../Chests/Loot/Common6.nbt,10,CHEST:4,../../../../Chests/Loot/Common7.nbt,10,CHEST:4,../../../../Chests/Loot/Common8.nbt,10,CHEST:4,../../../../Chests/Loot/Common9.nbt,10,CHEST:4,../../../../Chests/Loot/Common10.nbt,10,CHEST:4,../../../../Chests/Loot/Common10.nbt,11,CHEST:4,../../../../Chests/Loot/Common12.nbt,10,CHEST:4,../../../../Chests/Loot/Common13.nbt,10,CHEST:4,../../../../Chests/Loot/Common14.nbt,10,CHEST:4,../../../../Chests/Loot/Common15.nbt,10,CHEST:4,../../../../Chests/Lore/Frozen_1.nbt,2,CHEST:4,../../../../Chests/Lore/Frozen_3.nbt,2,CHEST:4,../../../../Chests/Lore/Frozen_4.nbt,2,CHEST:4,../../../../Chests/Lore/Frozen_5.nbt,2,CHEST:4,../../../../Chests/Lore/Frozen_5.nbt,2,CHEST:4,../../../../Chests/Loot/Rare1.nbt,5,CHEST:4,../../../../Chests/Loot/Rare2.nbt,5,CHEST:4,../../../../Chests/Loot/Rare3.nbt,5,CHEST:4,../../../../Chests/Loot/Rare4.nbt,5,CHEST:4,../../../../Chests/Loot/Rare5.nbt,5,CHEST:4,../../../../Chests/Loot/Rare6.nbt,5,CHEST:4,../../../../Chests/Loot/Rare7.nbt,5,CHEST:4,../../../../Chests/Loot/Rare8.nbt,5,CHEST:4,../../../../Chests/Loot/Rare9.nbt,5,CHEST:4,../../../../Chests/Loot/Rare10.nbt,5,CHEST:4,../../../../Chests/Loot/Rare11.nbt,5,CHEST:4,../../../../Chests/Loot/Rare12.nbt,5,CHEST:4,../../../../Chests/Loot/Rare13.nbt,5,CHEST:4,../../../../Chests/Loot/Rare14.nbt,5,CHEST:4,../../../../Chests/Loot/Rare15.nbt,5,CHEST:4,../../../../Chests/Loot/Epic1.nbt,2,CHEST:4,../../../../Chests/Loot/Epic2.nbt,2,CHEST:4,../../../../Chests/Loot/Epic3.nbt,2,CHEST:4,../../../../Chests/Loot/Epic4.nbt,2,CHEST:4,../../../../Chests/Loot/Epic5.nbt,2,CHEST:4,../../../../Chests/Loot/Epic6.nbt,2,CHEST:4,../../../../Chests/Loot/Epic7.nbt,2,CHEST:4,../../../../Chests/Loot/Epic8.nbt,2,CHEST:4,../../../../Chests/Loot/Epic9.nbt,2,CHEST:4,../../../../Chests/Loot/Epic10.nbt,2,CHEST:4,../../../../Chests/Loot/Epic11.nbt,2,CHEST:4,../../../../Chests/Loot/Epic12.nbt,2,CHEST:4,../../../../Chests/Loot/Epic13.nbt,2,CHEST:4,../../../../Chests/Loot/Epic14.nbt,2,CHEST:4,../../../../Chests/Loot/Epic15.nbt,5,CHEST:4,../../../../Chests/Loot/Rare1.nbt,5,CHEST:4,../../../../Chests/Loot/Rare2.nbt,5,CHEST:4,../../../../Chests/Loot/Rare3.nbt,5,CHEST:4,../../../../Chests/Loot/Rare4.nbt,5,CHEST:4,../../../../Chests/Loot/Rare5.nbt,10,CHEST:4,../../../../Chests/Loot/Rare6.nbt,10,CHEST:4,../../../../Chests/Loot/Rare7.nbt,10,CHEST:4,../../../../Chests/Loot/Rare8.nbt,10,CHEST:4,../../../../Chests/Loot/Rare9.nbt,10,CHEST:4,../../../../Chests/Loot/Rare10.nbt,15,CHEST:4,../../../../Chests/Loot/Rare11.nbt,15,CHEST:4,../../../../Chests/Loot/Rare12.nbt,15,CHEST:4,../../../../Chests/Loot/Rare13.nbt,15,CHEST:4,../../../../Chests/Loot/Rare14.nbt,15,CHEST:4,../../../../Chests/Loot/Rare15.nbt,15,CHEST:4,../../../../Chests/Loot/Epic15.nbt,100)
Block(1,9,-2,WOOD:5)
Block(1,9,-1,PACKED_ICE:0)
Block(1,10,-6,DARK_OAK_STAIRS:4)
RandomBlock(1,10,-5,AIR:0,20,CHEST:4,../../../../Chests/Loot/ShipJunk_1.nbt,10,CHEST:4,../../../../Chests/Loot/ShipJunk_2.nbt,10,CHEST:4,../../../../Chests/Loot/ShipJunk_3.nbt,10,CHEST:4,../../../../Chests/Loot/ShipJunk_4.nbt,10,CHEST:4,../../../../Chests/Loot/ShipJunk_5.nbt,10,CHEST:4,../../../../Chests/Lore/Frozen_1.nbt,1,CHEST:4,../../../../Chests/Lore/Frozen_2.nbt,1,CHEST:4,../../../../Chests/Lore/Frozen_3.nbt,1,CHEST:4,../../../../Chests/Lore/Frozen_4.nbt,1,CHEST:4,../../../../Chests/Lore/Frozen_5.nbt,1,CHEST:4,../../../../Chests/Loot/Common1.nbt,10,CHEST:4,../../../../Chests/Loot/Common2.nbt,10,CHEST:4,../../../../Chests/Loot/Common3.nbt,10,CHEST:4,../../../../Chests/Loot/Common4.nbt,10,CHEST:4,../../../../Chests/Loot/Common5.nbt,10,CHEST:4,../../../../Chests/Loot/Common6.nbt,10,CHEST:4,../../../../Chests/Loot/Common7.nbt,10,CHEST:4,../../../../Chests/Loot/Common8.nbt,10,CHEST:4,../../../../Chests/Loot/Common9.nbt,10,CHEST:4,../../../../Chests/Loot/Common10.nbt,10,CHEST:4,../../../../Chests/Loot/Common10.nbt,11,CHEST:4,../../../../Chests/Loot/Common12.nbt,10,CHEST:4,../../../../Chests/Loot/Common13.nbt,10,CHEST:4,../../../../Chests/Loot/Common14.nbt,10,CHEST:4,../../../../Chests/Loot/Common15.nbt,10,CHEST:4,../../../../Chests/Lore/Frozen_1.nbt,2,CHEST:4,../../../../Chests/Lore/Frozen_3.nbt,2,CHEST:4,../../../../Chests/Lore/Frozen_4.nbt,2,CHEST:4,../../../../Chests/Lore/Frozen_5.nbt,2,CHEST:4,../../../../Chests/Lore/Frozen_5.nbt,2,CHEST:4,../../../../Chests/Loot/Rare1.nbt,5,CHEST:4,../../../../Chests/Loot/Rare2.nbt,5,CHEST:4,../../../../Chests/Loot/Rare3.nbt,5,CHEST:4,../../../../Chests/Loot/Rare4.nbt,5,CHEST:4,../../../../Chests/Loot/Rare5.nbt,5,CHEST:4,../../../../Chests/Loot/Rare6.nbt,5,CHEST:4,../../../../Chests/Loot/Rare7.nbt,5,CHEST:4,../../../../Chests/Loot/Rare8.nbt,5,CHEST:4,../../../../Chests/Loot/Rare9.nbt,5,CHEST:4,../../../../Chests/Loot/Rare10.nbt,5,CHEST:4,../../../../Chests/Loot/Rare11.nbt,5,CHEST:4,../../../../Chests/Loot/Rare12.nbt,5,CHEST:4,../../../../Chests/Loot/Rare13.nbt,5,CHEST:4,../../../../Chests/Loot/Rare14.nbt,5,CHEST:4,../../../../Chests/Loot/Rare15.nbt,5,CHEST:4,../../../../Chests/Loot/Epic1.nbt,2,CHEST:4,../../../../Chests/Loot/Epic2.nbt,2,CHEST:4,../../../../Chests/Loot/Epic3.nbt,2,CHEST:4,../../../../Chests/Loot/Epic4.nbt,2,CHEST:4,../../../../Chests/Loot/Epic5.nbt,2,CHEST:4,../../../../Chests/Loot/Epic6.nbt,2,CHEST:4,../../../../Chests/Loot/Epic7.nbt,2,CHEST:4,../../../../Chests/Loot/Epic8.nbt,2,CHEST:4,../../../../Chests/Loot/Epic9.nbt,2,CHEST:4,../../../../Chests/Loot/Epic10.nbt,2,CHEST:4,../../../../Chests/Loot/Epic11.nbt,2,CHEST:4,../../../../Chests/Loot/Epic12.nbt,2,CHEST:4,../../../../Chests/Loot/Epic13.nbt,2,CHEST:4,../../../../Chests/Loot/Epic14.nbt,2,CHEST:4,../../../../Chests/Loot/Epic15.nbt,5,CHEST:4,../../../../Chests/Loot/Rare1.nbt,5,CHEST:4,../../../../Chests/Loot/Rare2.nbt,5,CHEST:4,../../../../Chests/Loot/Rare3.nbt,5,CHEST:4,../../../../Chests/Loot/Rare4.nbt,5,CHEST:4,../../../../Chests/Loot/Rare5.nbt,10,CHEST:4,../../../../Chests/Loot/Rare6.nbt,10,CHEST:4,../../../../Chests/Loot/Rare7.nbt,10,CHEST:4,../../../../Chests/Loot/Rare8.nbt,10,CHEST:4,../../../../Chests/Loot/Rare9.nbt,10,CHEST:4,../../../../Chests/Loot/Rare10.nbt,15,CHEST:4,../../../../Chests/Loot/Rare11.nbt,15,CHEST:4,../../../../Chests/Loot/Rare12.nbt,15,CHEST:4,../../../../Chests/Loot/Rare13.nbt,15,CHEST:4,../../../../Chests/Loot/Rare14.nbt,15,CHEST:4,../../../../Chests/Loot/Rare15.nbt,15,CHEST:4,../../../../Chests/Loot/Epic15.nbt,100)
RandomBlock(1,10,-4,AIR:0,20,CHEST:4,../../../../Chests/Loot/ShipJunk_1.nbt,10,CHEST:4,../../../../Chests/Loot/ShipJunk_2.nbt,10,CHEST:4,../../../../Chests/Loot/ShipJunk_3.nbt,10,CHEST:4,../../../../Chests/Loot/ShipJunk_4.nbt,10,CHEST:4,../../../../Chests/Loot/ShipJunk_5.nbt,10,CHEST:4,../../../../Chests/Lore/Frozen_1.nbt,1,CHEST:4,../../../../Chests/Lore/Frozen_2.nbt,1,CHEST:4,../../../../Chests/Lore/Frozen_3.nbt,1,CHEST:4,../../../../Chests/Lore/Frozen_4.nbt,1,CHEST:4,../../../../Chests/Lore/Frozen_5.nbt,1,CHEST:4,../../../../Chests/Loot/Common1.nbt,10,CHEST:4,../../../../Chests/Loot/Common2.nbt,10,CHEST:4,../../../../Chests/Loot/Common3.nbt,10,CHEST:4,../../../../Chests/Loot/Common4.nbt,10,CHEST:4,../../../../Chests/Loot/Common5.nbt,10,CHEST:4,../../../../Chests/Loot/Common6.nbt,10,CHEST:4,../../../../Chests/Loot/Common7.nbt,10,CHEST:4,../../../../Chests/Loot/Common8.nbt,10,CHEST:4,../../../../Chests/Loot/Common9.nbt,10,CHEST:4,../../../../Chests/Loot/Common10.nbt,10,CHEST:4,../../../../Chests/Loot/Common10.nbt,11,CHEST:4,../../../../Chests/Loot/Common12.nbt,10,CHEST:4,../../../../Chests/Loot/Common13.nbt,10,CHEST:4,../../../../Chests/Loot/Common14.nbt,10,CHEST:4,../../../../Chests/Loot/Common15.nbt,10,CHEST:4,../../../../Chests/Lore/Frozen_1.nbt,2,CHEST:4,../../../../Chests/Lore/Frozen_3.nbt,2,CHEST:4,../../../../Chests/Lore/Frozen_4.nbt,2,CHEST:4,../../../../Chests/Lore/Frozen_5.nbt,2,CHEST:4,../../../../Chests/Lore/Frozen_5.nbt,2,CHEST:4,../../../../Chests/Loot/Rare1.nbt,5,CHEST:4,../../../../Chests/Loot/Rare2.nbt,5,CHEST:4,../../../../Chests/Loot/Rare3.nbt,5,CHEST:4,../../../../Chests/Loot/Rare4.nbt,5,CHEST:4,../../../../Chests/Loot/Rare5.nbt,5,CHEST:4,../../../../Chests/Loot/Rare6.nbt,5,CHEST:4,../../../../Chests/Loot/Rare7.nbt,5,CHEST:4,../../../../Chests/Loot/Rare8.nbt,5,CHEST:4,../../../../Chests/Loot/Rare9.nbt,5,CHEST:4,../../../../Chests/Loot/Rare10.nbt,5,CHEST:4,../../../../Chests/Loot/Rare11.nbt,5,CHEST:4,../../../../Chests/Loot/Rare12.nbt,5,CHEST:4,../../../../Chests/Loot/Rare13.nbt,5,CHEST:4,../../../../Chests/Loot/Rare14.nbt,5,CHEST:4,../../../../Chests/Loot/Rare15.nbt,5,CHEST:4,../../../../Chests/Loot/Epic1.nbt,2,CHEST:4,../../../../Chests/Loot/Epic2.nbt,2,CHEST:4,../../../../Chests/Loot/Epic3.nbt,2,CHEST:4,../../../../Chests/Loot/Epic4.nbt,2,CHEST:4,../../../../Chests/Loot/Epic5.nbt,2,CHEST:4,../../../../Chests/Loot/Epic6.nbt,2,CHEST:4,../../../../Chests/Loot/Epic7.nbt,2,CHEST:4,../../../../Chests/Loot/Epic8.nbt,2,CHEST:4,../../../../Chests/Loot/Epic9.nbt,2,CHEST:4,../../../../Chests/Loot/Epic10.nbt,2,CHEST:4,../../../../Chests/Loot/Epic11.nbt,2,CHEST:4,../../../../Chests/Loot/Epic12.nbt,2,CHEST:4,../../../../Chests/Loot/Epic13.nbt,2,CHEST:4,../../../../Chests/Loot/Epic14.nbt,2,CHEST:4,../../../../Chests/Loot/Epic15.nbt,5,CHEST:4,../../../../Chests/Loot/Rare1.nbt,5,CHEST:4,../../../../Chests/Loot/Rare2.nbt,5,CHEST:4,../../../../Chests/Loot/Rare3.nbt,5,CHEST:4,../../../../Chests/Loot/Rare4.nbt,5,CHEST:4,../../../../Chests/Loot/Rare5.nbt,10,CHEST:4,../../../../Chests/Loot/Rare6.nbt,10,CHEST:4,../../../../Chests/Loot/Rare7.nbt,10,CHEST:4,../../../../Chests/Loot/Rare8.nbt,10,CHEST:4,../../../../Chests/Loot/Rare9.nbt,10,CHEST:4,../../../../Chests/Loot/Rare10.nbt,15,CHEST:4,../../../../Chests/Loot/Rare11.nbt,15,CHEST:4,../../../../Chests/Loot/Rare12.nbt,15,CHEST:4,../../../../Chests/Loot/Rare13.nbt,15,CHEST:4,../../../../Chests/Loot/Rare14.nbt,15,CHEST:4,../../../../Chests/Loot/Rare15.nbt,15,CHEST:4,../../../../Chests/Loot/Epic15.nbt,100)
