Author: NLBlackEagle
Description: No description given
SettingsMode: WriteDisable
Frequency: 0
SpawnHeight: highestBlock
UseCenterForHighestBlock: true
MinHeight: 0
MaxHeight: 255
InheritBO3: 
InheritBO3Rotation: NORTH
OverrideChildSettings: true
OverrideParentHeight: false
CanOverride: false
BranchFrequency: 0
BranchFrequencyGroup: 
MustBeBelowOther: false
MustBeInside: 
CannotBeInside: 
ReplacesBO3: 
MustBeInsideWorldBorders: false
CanSpawnOnWater: true
SpawnOnWaterOnly: false
SpawnUnderWater: false
SpawnAtWaterLevel: false
HeightOffset: 0
RemoveAir: true
ReplaceAbove: 
ReplaceBelow: 
ReplaceWithBiomeBlocks: true
ReplaceWithSurfaceBlock: GRASS
ReplaceWithGroundBlock: DIRT
ReplaceWithStoneBlock: STONE
SmoothRadius: 0
SmoothHeightOffset: 0
SmoothStartTop: false
SmoothStartWood: false
SmoothingSurfaceBlock: 
SmoothingGroundBlock: 
BO3Group: 
IsSpawnPoint: false
DoReplaceBlocks: true
Block(-8,1,-7,GRASS_PATH:0)
Block(-8,1,-6,GRASS:0)
Block(-8,1,-5,GRASS:0)
Block(-8,1,-4,GRASS:0)
Block(-8,1,-3,GRASS:0)
Block(-8,1,-2,GRASS:0)
Block(-8,1,-1,GRASS:0)
Block(-8,1,0,GRASS:0)
Block(-8,1,1,GRASS:0)
Block(-8,1,2,GRASS:0)
Block(-8,1,3,GRASS:0)
Block(-8,1,4,GRASS:0)
Block(-8,1,5,GRASS:0)
Block(-8,1,6,LOG:4)
Block(-8,2,-6,SPRUCE_FENCE:0)
Block(-8,2,-3,CAULDRON:3)
Block(-8,2,0,CAULDRON:3)
Block(-8,2,6,SPRUCE_FENCE:0)
Block(-8,3,-6,STONE_BUTTON:2)
Block(-8,3,-3,STONE_BUTTON:2)
Block(-8,3,0,STONE_BUTTON:2)
Block(-8,3,3,STONE_BUTTON:2)
Block(-8,3,6,STONE_BUTTON:2)
Block(-8,4,1,TRAP_DOOR:6)
Block(-8,4,2,TRAP_DOOR:6)
Block(-8,4,4,TRAP_DOOR:6)
Block(-8,4,5,TRAP_DOOR:6)
Block(-8,6,-7,SPRUCE_WOOD_STAIRS:2)
Block(-8,6,-6,WOOD_STAIRS:7)
Block(-8,6,2,WOOD_STAIRS:6)
Block(-8,6,3,SPRUCE_WOOD_STAIRS:3)
Block(-8,6,4,SPRUCE_WOOD_STAIRS:0)
Block(-8,6,5,SPRUCE_WOOD_STAIRS:0)
Block(-8,6,6,SPRUCE_WOOD_STAIRS:0)
Block(-8,6,7,SPRUCE_WOOD_STAIRS:0)
Block(-8,7,-6,SPRUCE_WOOD_STAIRS:2)
Block(-8,7,-5,WOOD_STAIRS:7)
Block(-8,7,1,WOOD_STAIRS:6)
Block(-8,7,2,SPRUCE_WOOD_STAIRS:3)
Block(-8,8,-5,SPRUCE_WOOD_STAIRS:2)
Block(-8,8,-4,WOOD_STAIRS:7)
Block(-8,8,0,WOOD_STAIRS:6)
Block(-8,8,1,SPRUCE_WOOD_STAIRS:3)
Block(-8,9,-4,SPRUCE_WOOD_STAIRS:2)
Block(-8,9,-3,WOOD_STAIRS:7)
Block(-8,9,-1,WOOD_STAIRS:6)
Block(-8,9,0,SPRUCE_WOOD_STAIRS:3)
Block(-8,10,-3,SPRUCE_WOOD_STAIRS:2)
Block(-8,10,-2,WOOD_STAIRS:4)
Block(-8,10,-1,SPRUCE_WOOD_STAIRS:3)
Block(-8,11,-2,WOOD_STEP:1)
Block(-7,0,-6,LOG:0)
Block(-7,0,-3,LOG:0)
Block(-7,0,0,LOG:0)
Block(-7,0,3,LOG:0)
Block(-7,0,4,COBBLESTONE:0)
Block(-7,0,5,COBBLESTONE:0)
Block(-7,0,6,LOG:0)
Block(-7,0,7,COBBLESTONE:0)
Block(-7,0,8,COBBLESTONE:0)
Block(-7,1,-7,GRASS_PATH:0)
Block(-7,1,-6,LOG:0)
Block(-7,1,-3,LOG:0)
Block(-7,1,0,LOG:0)
Block(-7,1,3,LOG:0)
Block(-7,1,4,COBBLESTONE:0)
Block(-7,1,5,COBBLESTONE:0)
Block(-7,1,6,LOG:0)
Block(-7,1,7,COBBLESTONE:0)
Block(-7,1,8,COBBLESTONE:0)
Block(-7,2,-6,LOG:0)
Block(-7,2,-3,LOG:0)
Block(-7,2,0,LOG:0)
Block(-7,2,3,LOG:0)
Block(-7,2,4,COBBLESTONE:0)
Block(-7,2,5,COBBLESTONE:0)
Block(-7,2,6,LOG:0)
Block(-7,2,7,COBBLESTONE:0)
Block(-7,2,8,COBBLESTONE:0)
Block(-7,3,-7,STONE_BUTTON:4)
Block(-7,3,-6,LOG:0)
Block(-7,3,-5,LOG:8)
Block(-7,3,-4,LOG:8)
Block(-7,3,-3,LOG:0)
Block(-7,3,-2,LOG:8)
Block(-7,3,-1,LOG:8)
Block(-7,3,0,LOG:0)
Block(-7,3,1,LOG:8)
Block(-7,3,2,LOG:8)
Block(-7,3,3,LOG:0)
Block(-7,3,4,LOG:8)
Block(-7,3,5,LOG:8)
Block(-7,3,6,LOG:0)
Block(-7,3,7,COBBLESTONE_STAIRS:0)
Block(-7,3,8,COBBLESTONE_STAIRS:0)
Block(-7,4,-6,LOG:0)
Block(-7,4,-5,COBBLESTONE_STAIRS:0)
Block(-7,4,-4,COBBLESTONE_STAIRS:0)
Block(-7,4,-3,LOG:0)
Block(-7,4,-2,COBBLESTONE_STAIRS:0)
Block(-7,4,-1,COBBLESTONE_STAIRS:0)
Block(-7,4,0,LOG:0)
Block(-7,4,1,SPRUCE_WOOD_STAIRS:0)
Block(-7,4,2,SPRUCE_WOOD_STAIRS:0)
Block(-7,4,3,LOG:0)
Block(-7,4,4,SPRUCE_WOOD_STAIRS:0)
Block(-7,4,5,WOOD:1)
Block(-7,4,6,LOG:0)
Block(-7,4,7,COBBLESTONE_STAIRS:4)
Block(-7,4,8,COBBLESTONE_STAIRS:4)
Block(-7,5,-6,LOG:0)
Block(-7,5,-5,COBBLESTONE_STAIRS:4)
Block(-7,5,-4,COBBLESTONE_STAIRS:4)
Block(-7,5,-3,LOG:0)
Block(-7,5,-2,COBBLESTONE_STAIRS:4)
Block(-7,5,-1,COBBLESTONE_STAIRS:4)
Block(-7,5,0,LOG:0)
Block(-7,5,1,SPRUCE_FENCE:0)
Block(-7,5,2,SPRUCE_FENCE:0)
Block(-7,5,3,LOG:0)
Block(-7,5,4,SPRUCE_FENCE:0)
Block(-7,5,5,WOOD:1)
Block(-7,5,6,LOG:0)
Block(-7,5,7,COBBLESTONE:0)
Block(-7,5,8,COBBLESTONE:0)
Block(-7,6,-7,SPRUCE_WOOD_STAIRS:2)
Block(-7,6,-6,LOG:0)
Block(-7,6,-5,LOG:8)
Block(-7,6,-4,LOG:8)
Block(-7,6,-3,LOG:0)
Block(-7,6,-2,LOG:8)
Block(-7,6,-1,LOG:8)
Block(-7,6,0,LOG:0)
Block(-7,6,1,LOG:8)
Block(-7,6,2,LOG:8)
Block(-7,6,3,LOG:0)
Block(-7,6,4,LOG:8)
Block(-7,6,5,LOG:8)
Block(-7,6,6,LOG:0)
Block(-7,6,7,COBBLESTONE:0)
Block(-7,6,8,COBBLESTONE_STAIRS:0)
Block(-7,7,-6,WOOD_STAIRS:2)
Block(-7,7,-5,WOOD:1)
Block(-7,7,-4,WOOD:1)
Block(-7,7,-3,WOOD:1)
Block(-7,7,-2,SPRUCE_WOOD_STAIRS:0)
Block(-7,7,-1,WOOD:1)
Block(-7,7,0,LOG:0)
Block(-7,7,1,WOOD:0)
Block(-7,7,2,WOOD_STAIRS:3)
Block(-7,7,3,WOOD_STAIRS:0)
Block(-7,7,4,WOOD_STAIRS:0)
Block(-7,7,5,WOOD_STAIRS:0)
Block(-7,7,6,WOOD_STAIRS:0)
Block(-7,7,7,SPRUCE_WOOD_STAIRS:0)
Block(-7,8,-5,WOOD_STAIRS:2)
Block(-7,8,-4,WOOD:1)
Block(-7,8,-3,WOOD:1)
Block(-7,8,-2,FENCE:0)
Block(-7,8,-1,WOOD:1)
Block(-7,8,0,LOG:0)
Block(-7,8,1,WOOD_STAIRS:3)
Block(-7,9,-4,WOOD_STAIRS:2)
Block(-7,9,-3,WOOD:1)
Block(-7,9,-2,SPRUCE_WOOD_STAIRS:4)
Block(-7,9,-1,WOOD:1)
Block(-7,9,0,WOOD_STAIRS:3)
Block(-7,10,-3,WOOD_STAIRS:2)
Block(-7,10,-2,WOOD:1)
Block(-7,10,-1,WOOD_STAIRS:3)
Block(-7,11,-2,WOOD_STEP:1)
Block(-6,0,3,COBBLESTONE:0)
Block(-6,0,4,COBBLESTONE:0)
Block(-6,0,5,COBBLESTONE:0)
Block(-6,0,6,COBBLESTONE:0)
Block(-6,0,7,COBBLESTONE:0)
Block(-6,0,8,COBBLESTONE:0)
Block(-6,1,-7,GRASS:0)
Block(-6,1,3,COBBLESTONE:0)
Block(-6,1,4,COBBLESTONE:0)
Block(-6,1,5,COBBLESTONE:0)
Block(-6,1,6,COBBLESTONE:0)
Block(-6,1,7,COBBLESTONE:0)
Block(-6,1,8,COBBLESTONE:0)
Block(-6,2,-7,WOOD_STAIRS:0)
Block(-6,2,3,COBBLESTONE:0)
Block(-6,2,4,COBBLESTONE:0)
Block(-6,2,5,COBBLESTONE:0)
Block(-6,2,6,COBBLESTONE:0)
Block(-6,2,7,COBBLESTONE:0)
Block(-6,2,8,COAL_BLOCK:0)
Block(-6,3,-6,LOG:4)
Block(-6,3,-5,WOOD_STEP:8)
Block(-6,3,-4,WOOD_STEP:8)
Block(-6,3,-3,WOOD_STEP:8)
Block(-6,3,-2,WOOD_STEP:8)
Block(-6,3,-1,WOOD_STEP:8)
Block(-6,3,0,WOOD_STEP:8)
Block(-6,3,1,WOOD_STEP:8)
Block(-6,3,2,WOOD_STEP:8)
Block(-6,3,3,WOOD_STEP:8)
Block(-6,3,4,WOOD_STEP:8)
Block(-6,3,5,WOOD_STEP:8)
Block(-6,3,6,COBBLESTONE:0)
Block(-6,3,7,IRON_FENCE:0)
#Block(-6,3,8,FIRE:0)
Block(-6,4,-6,COBBLESTONE_STAIRS:2)
Block(-6,4,-5,FURNACE:5)
Block(-6,4,-4,SPRUCE_WOOD_STAIRS:7)
Block(-6,4,-3,WOOD_STEP:9)
Block(-6,4,-2,SPRUCE_WOOD_STAIRS:6)
Block(-6,4,0,CARPET:1)
Block(-6,4,1,CARPET:1)
Block(-6,4,2,CARPET:1)
Block(-6,4,3,CARPET:1)
Block(-6,4,6,STEP:0)
Block(-6,5,-6,COBBLESTONE_STAIRS:6)
Block(-6,5,-5,IRON_TRAPDOOR:3)
Block(-6,5,-4,WOOD_PLATE:0)
Block(-6,5,-3,WOOD_PLATE:0)
Block(-6,5,-2,WOOD_PLATE:0)
Block(-6,5,7,IRON_FENCE:0)
Block(-6,6,-7,SPRUCE_WOOD_STAIRS:2)
Block(-6,6,-6,LOG:4)
Block(-6,6,-5,WOOD_STEP:9)
Block(-6,6,-4,WOOD_STEP:9)
Block(-6,6,-3,WOOD_STEP:9)
Block(-6,6,-2,WOOD_STEP:9)
Block(-6,6,-1,WOOD_STEP:9)
Block(-6,6,0,LOG:4)
Block(-6,6,6,COBBLESTONE_STAIRS:6)
Block(-6,6,7,COBBLESTONE:0)
Block(-6,6,8,COBBLESTONE:0)
Block(-6,7,-6,WOOD_STAIRS:2)
Block(-6,7,-5,WOOD:1)
Block(-6,7,-4,BED_BLOCK:9)
Block(-6,7,-3,BED_BLOCK:9)
Block(-6,7,-2,WOOD:1)
Block(-6,7,0,BOOKSHELF:0)
Block(-6,7,1,WOOD:1)
Block(-6,7,2,WOOD:1)
Block(-6,7,3,WOOD:1)
Block(-6,7,4,WOOD:1)
Block(-6,7,5,WOOD:1)
Block(-6,7,6,COBBLESTONE:0)
Block(-6,7,7,COBBLESTONE:0)
Block(-6,7,8,COBBLESTONE:0)
Block(-6,8,-5,WOOD_STAIRS:2)
Block(-6,8,-2,FLOWER_POT:0)
Block(-6,8,0,BOOKSHELF:0)
Block(-6,8,1,WOOD_STAIRS:3)
Block(-6,8,2,WOOD_STAIRS:0)
Block(-6,8,3,WOOD_STAIRS:0)
Block(-6,8,4,WOOD_STAIRS:0)
Block(-6,8,5,WOOD_STAIRS:0)
Block(-6,8,6,WOOD_STAIRS:0)
Block(-6,8,7,COBBLESTONE:0)
Block(-6,8,8,COBBLESTONE:0)
Block(-6,9,-4,WOOD_STAIRS:2)
Block(-6,9,0,WOOD_STAIRS:3)
Block(-6,9,7,COBBLESTONE_STAIRS:6)
Block(-6,9,8,COBBLESTONE_STAIRS:4)
Block(-6,10,-3,WOOD_STAIRS:2)
Block(-6,10,-2,WOOD:1)
Block(-6,10,-1,WOOD_STAIRS:3)
Block(-6,10,7,COBBLESTONE_STAIRS:0)
Block(-6,10,8,COBBLESTONE_STAIRS:3)
Block(-6,11,-2,WOOD_STEP:1)
Block(-5,0,3,COBBLESTONE:0)
Block(-5,0,4,COBBLESTONE:0)
Block(-5,0,5,COBBLESTONE:0)
Block(-5,0,6,COBBLESTONE:0)
Block(-5,0,7,COBBLESTONE:0)
Block(-5,0,8,COBBLESTONE:0)
Block(-5,1,-7,DIRT:0)
Block(-5,1,3,COBBLESTONE:0)
Block(-5,1,4,COBBLESTONE:0)
Block(-5,1,5,COBBLESTONE:0)
Block(-5,1,6,COBBLESTONE:0)
Block(-5,1,7,COBBLESTONE:0)
Block(-5,1,8,COBBLESTONE:0)
Block(-5,2,-7,WOOD_STAIRS:5)
Block(-5,2,3,COBBLESTONE:0)
Block(-5,2,4,COBBLESTONE:0)
Block(-5,2,5,COBBLESTONE:0)
Block(-5,2,6,COBBLESTONE:0)
Block(-5,2,7,COBBLESTONE:0)
Block(-5,2,8,COAL_BLOCK:0)
Block(-5,3,-7,WOOD_STAIRS:0)
Block(-5,3,-6,LOG:4)
Block(-5,3,-5,WOOD_STEP:8)
Block(-5,3,-4,WOOD_STEP:9)
Block(-5,3,-3,WOOD_STEP:9)
Block(-5,3,-2,WOOD_STEP:9)
Block(-5,3,-1,WOOD_STEP:8)
Block(-5,3,0,WOOD_STEP:9)
Block(-5,3,1,WOOD_STEP:8)
Block(-5,3,2,WOOD_STEP:8)
Block(-5,3,3,WOOD_STEP:8)
Block(-5,3,4,WOOD_STEP:8)
Block(-5,3,5,WOOD_STEP:8)
Block(-5,3,6,COBBLESTONE:0)
Block(-5,3,7,IRON_FENCE:0)
#Block(-5,3,8,FIRE:0)
Block(-5,4,-6,COBBLESTONE_STAIRS:2)
Block(-5,4,-5,CARPET:1)
Block(-5,4,-4,CARPET:1)
Block(-5,4,-1,CARPET:1)
Block(-5,4,1,CARPET:1)
Block(-5,4,2,WALL_SIGN:2)
Block(-5,4,3,WOOD_STAIRS:0)
Block(-5,4,4,WOOD_STAIRS:0)
Block(-5,4,5,WALL_SIGN:3)
Block(-5,4,6,STEP:0)
Block(-5,5,-6,COBBLESTONE_STAIRS:6)
Block(-5,5,7,IRON_FENCE:0)
Block(-5,6,-7,SPRUCE_WOOD_STAIRS:2)
Block(-5,6,-6,LOG:4)
Block(-5,6,-5,WOOD_STEP:9)
Block(-5,6,-4,WOOD_STEP:9)
Block(-5,6,-3,WOOD_STEP:9)
Block(-5,6,-2,WOOD_STEP:9)
Block(-5,6,-1,WOOD_STEP:9)
Block(-5,6,0,LOG:4)
Block(-5,6,6,COBBLESTONE_STAIRS:6)
Block(-5,6,7,COBBLESTONE:0)
Block(-5,6,8,COBBLESTONE:0)
Block(-5,7,-6,WOOD_STAIRS:2)
Block(-5,7,-5,WOOD:1)
Block(-5,7,-4,BED_BLOCK:1)
Block(-5,7,-3,BED_BLOCK:1)
Block(-5,7,0,BOOKSHELF:0)
Block(-5,7,1,WOOD:1)
Block(-5,7,2,WOOD:1)
Block(-5,7,3,WOOD:1)
Block(-5,7,4,WOOD:1)
Block(-5,7,5,WOOD:1)
Block(-5,7,6,COBBLESTONE:0)
Block(-5,7,7,COBBLESTONE:0)
Block(-5,7,8,COBBLESTONE:0)
Block(-5,8,-5,WOOD_STAIRS:2)
Block(-5,8,0,BOOKSHELF:0)
Block(-5,8,1,WOOD_STAIRS:1)
Block(-5,8,2,WOOD_STAIRS:1)
Block(-5,8,3,WOOD_STAIRS:1)
Block(-5,8,4,WOOD_STAIRS:1)
Block(-5,8,5,WOOD_STAIRS:1)
Block(-5,8,6,WOOD_STAIRS:1)
Block(-5,8,7,COBBLESTONE:0)
Block(-5,8,8,COBBLESTONE:0)
Block(-5,9,-4,WOOD_STAIRS:2)
Block(-5,9,0,WOOD_STAIRS:3)
Block(-5,9,7,COBBLESTONE_STAIRS:5)
Block(-5,9,8,COBBLESTONE_STAIRS:7)
Block(-5,10,-3,WOOD_STAIRS:2)
Block(-5,10,-2,WOOD:1)
Block(-5,10,-1,WOOD_STAIRS:3)
Block(-5,10,7,COBBLESTONE_STAIRS:2)
Block(-5,10,8,COBBLESTONE_STAIRS:1)
Block(-5,11,-2,WOOD_STEP:1)
Block(-4,0,-6,LOG:0)
Block(-4,0,0,LOG:0)
Block(-4,0,3,LOG:0)
Block(-4,0,4,COBBLESTONE:0)
Block(-4,0,5,COBBLESTONE:0)
Block(-4,0,6,LOG:0)
Block(-4,0,7,COBBLESTONE:0)
Block(-4,0,8,COBBLESTONE:0)
Block(-4,1,-7,GRASS:0)
Block(-4,1,-6,LOG:0)
Block(-4,1,0,LOG:0)
Block(-4,1,3,LOG:0)
Block(-4,1,4,COBBLESTONE:0)
Block(-4,1,5,COBBLESTONE:0)
Block(-4,1,6,LOG:0)
Block(-4,1,7,COBBLESTONE:0)
Block(-4,1,8,COBBLESTONE:0)
Block(-4,2,-6,LOG:0)
Block(-4,2,0,LOG:0)
Block(-4,2,3,LOG:0)
Block(-4,2,4,COBBLESTONE:0)
Block(-4,2,5,COBBLESTONE:0)
Block(-4,2,6,LOG:0)
Block(-4,2,7,COBBLESTONE:0)
Block(-4,2,8,COBBLESTONE:0)
Block(-4,3,-7,LOG:8)
Block(-4,3,-6,LOG:0)
Block(-4,3,-5,WOOD_STEP:8)
Block(-4,3,-4,WOOD_STEP:8)
Block(-4,3,-3,WOOD_STEP:9)
Block(-4,3,-2,WOOD_STEP:8)
Block(-4,3,-1,WOOD_STEP:8)
Block(-4,3,0,LOG:0)
Block(-4,3,1,LOG:8)
Block(-4,3,2,LOG:8)
Block(-4,3,3,LOG:0)
Block(-4,3,4,LOG:8)
Block(-4,3,5,LOG:8)
Block(-4,3,6,LOG:0)
Block(-4,3,7,COBBLESTONE_STAIRS:1)
Block(-4,3,8,COBBLESTONE_STAIRS:1)
Block(-4,4,-6,LOG:0)
Block(-4,4,-5,CARPET:1)
Block(-4,4,-4,CARPET:1)
Block(-4,4,-2,CARPET:1)
Block(-4,4,0,LOG:0)
Block(-4,4,1,SPRUCE_WOOD_STAIRS:1)
Block(-4,4,2,SPRUCE_WOOD_STAIRS:1)
Block(-4,4,3,LOG:0)
Block(-4,4,4,SPRUCE_WOOD_STAIRS:1)
Block(-4,4,5,WOOD:1)
Block(-4,4,6,LOG:0)
Block(-4,4,7,COBBLESTONE_STAIRS:5)
Block(-4,4,8,COBBLESTONE_STAIRS:5)
Block(-4,5,-6,LOG:0)
Block(-4,5,0,LOG:0)
Block(-4,5,1,SPRUCE_FENCE:0)
Block(-4,5,2,SPRUCE_FENCE:0)
Block(-4,5,3,LOG:0)
Block(-4,5,4,SPRUCE_FENCE:0)
Block(-4,5,5,WOOD:1)
Block(-4,5,6,LOG:0)
Block(-4,5,7,COBBLESTONE:0)
Block(-4,5,8,COBBLESTONE:0)
Block(-4,6,-7,SPRUCE_WOOD_STAIRS:0)
Block(-4,6,-6,LOG:0)
Block(-4,6,-5,LOG:8)
Block(-4,6,-4,LOG:8)
Block(-4,6,-3,LOG:8)
Block(-4,6,-2,LOG:8)
Block(-4,6,-1,LOG:8)
Block(-4,6,0,LOG:0)
Block(-4,6,1,LOG:8)
Block(-4,6,2,LOG:8)
Block(-4,6,3,LOG:0)
Block(-4,6,4,LOG:8)
Block(-4,6,5,LOG:8)
Block(-4,6,6,LOG:0)
Block(-4,6,7,COBBLESTONE:0)
Block(-4,6,8,COBBLESTONE_STAIRS:1)
Block(-4,7,-6,WOOD_STAIRS:2)
Block(-4,7,-5,WOOD:1)
Block(-4,7,-4,CARPET:13)
Block(-4,7,-2,CARPET:13)
Block(-4,7,0,LOG:0)
Block(-4,7,1,WOOD:0)
Block(-4,7,2,WOOD_STAIRS:1)
Block(-4,7,3,WOOD_STAIRS:1)
Block(-4,7,4,WOOD_STAIRS:1)
Block(-4,7,5,WOOD_STAIRS:1)
Block(-4,7,6,WOOD_STAIRS:1)
Block(-4,7,7,SPRUCE_WOOD_STAIRS:1)
Block(-4,8,-5,WOOD_STAIRS:2)
Block(-4,8,0,LOG:0)
Block(-4,8,1,WOOD_STAIRS:3)
Block(-4,9,-4,WOOD_STAIRS:2)
Block(-4,9,0,WOOD_STAIRS:3)
Block(-4,10,-3,WOOD_STAIRS:2)
Block(-4,10,-2,WOOD:1)
Block(-4,10,-1,WOOD_STAIRS:3)
Block(-4,11,-2,WOOD_STEP:1)
Block(-3,1,-7,GRASS:0)
Block(-3,3,-7,WOOD_STEP:8)
Block(-3,3,-6,LOG:4)
Block(-3,3,-5,WOOD_STEP:8)
Block(-3,3,-4,WOOD_STEP:8)
Block(-3,3,-3,WOOD_STEP:8)
Block(-3,3,-2,WOOD_STEP:8)
Block(-3,3,-1,WOOD_STEP:8)
Block(-3,3,0,LOG:4)
Block(-3,3,1,WOOD_STEP:8)
Block(-3,3,2,WOOD_STEP:8)
Block(-3,3,3,LOG:4)
Block(-3,3,6,STONE_BUTTON:1)
Block(-3,4,-7,TRAP_DOOR:4)
Block(-3,4,-6,SPRUCE_WOOD_STAIRS:2)
RandomBlock(-3,4,-5,AIR:0,20,CHEST:3,../../../Chests/Loot/JunkChest_1.nbt,10,CHEST:3,../../../Chests/Loot/JunkChest_2.nbt,10,CHEST:3,../../../Chests/Loot/JunkChest_3.nbt,10,CHEST:3,../../../Chests/Loot/JunkChest_4.nbt,10,CHEST:3,../../../Chests/Loot/JunkChest_5.nbt,10,CHEST:3,../../../Chests/Lore/Farmland_1.nbt,1,CHEST:3,../../../Chests/Lore/Farmland_2.nbt,1,CHEST:3,../../../Chests/Lore/Farmland_3.nbt,1,CHEST:3,../../../Chests/Lore/Farmland_4.nbt,1,CHEST:3,../../../Chests/Lore/Farmland_5.nbt,1,CHEST:3,../../../Chests/Loot/Common1.nbt,10,CHEST:3,../../../Chests/Loot/Common2.nbt,10,CHEST:3,../../../Chests/Loot/Common3.nbt,10,CHEST:3,../../../Chests/Loot/Common4.nbt,10,CHEST:3,../../../Chests/Loot/Common5.nbt,10,CHEST:3,../../../Chests/Loot/Common6.nbt,10,CHEST:3,../../../Chests/Loot/Common7.nbt,10,CHEST:3,../../../Chests/Loot/Common8.nbt,10,CHEST:3,../../../Chests/Loot/Common9.nbt,10,CHEST:3,../../../Chests/Loot/Common10.nbt,10,CHEST:3,../../../Chests/Loot/Common10.nbt,11,CHEST:3,../../../Chests/Loot/Common12.nbt,10,CHEST:3,../../../Chests/Loot/Common13.nbt,10,CHEST:3,../../../Chests/Loot/Common14.nbt,10,CHEST:3,../../../Chests/Loot/Common15.nbt,10,CHEST:3,../../../Chests/Lore/Farmland_1.nbt,2,CHEST:3,../../../Chests/Lore/Farmland_3.nbt,2,CHEST:3,../../../Chests/Lore/Farmland_4.nbt,2,CHEST:3,../../../Chests/Lore/Farmland_5.nbt,2,CHEST:3,../../../Chests/Lore/Farmland_5.nbt,2,CHEST:3,../../../Chests/Loot/Rare1.nbt,5,CHEST:3,../../../Chests/Loot/Rare2.nbt,5,CHEST:3,../../../Chests/Loot/Rare3.nbt,5,CHEST:3,../../../Chests/Loot/Rare4.nbt,5,CHEST:3,../../../Chests/Loot/Rare5.nbt,5,CHEST:3,../../../Chests/Loot/Rare6.nbt,5,CHEST:3,../../../Chests/Loot/Rare7.nbt,5,CHEST:3,../../../Chests/Loot/Rare8.nbt,5,CHEST:3,../../../Chests/Loot/Rare9.nbt,5,CHEST:3,../../../Chests/Loot/Rare10.nbt,5,CHEST:3,../../../Chests/Loot/Rare11.nbt,5,CHEST:3,../../../Chests/Loot/Rare12.nbt,5,CHEST:3,../../../Chests/Loot/Rare13.nbt,5,CHEST:3,../../../Chests/Loot/Rare14.nbt,5,CHEST:3,../../../Chests/Loot/Rare15.nbt,5,CHEST:3,../../../Chests/Loot/Epic1.nbt,2,CHEST:3,../../../Chests/Loot/Epic2.nbt,2,CHEST:3,../../../Chests/Loot/Epic3.nbt,2,CHEST:3,../../../Chests/Loot/Epic4.nbt,2,CHEST:3,../../../Chests/Loot/Epic5.nbt,2,CHEST:3,../../../Chests/Loot/Epic6.nbt,2,CHEST:3,../../../Chests/Loot/Epic7.nbt,2,CHEST:3,../../../Chests/Loot/Epic8.nbt,2,CHEST:3,../../../Chests/Loot/Epic9.nbt,2,CHEST:3,../../../Chests/Loot/Epic10.nbt,2,CHEST:3,../../../Chests/Loot/Epic11.nbt,2,CHEST:3,../../../Chests/Loot/Epic12.nbt,2,CHEST:3,../../../Chests/Loot/Epic13.nbt,2,CHEST:3,../../../Chests/Loot/Epic14.nbt,2,CHEST:3,../../../Chests/Loot/Epic15.nbt,5,CHEST:3,../../../Chests/Loot/Rare1.nbt,5,CHEST:3,../../../Chests/Loot/Rare2.nbt,5,CHEST:3,../../../Chests/Loot/Rare3.nbt,5,CHEST:3,../../../Chests/Loot/Rare4.nbt,5,CHEST:3,../../../Chests/Loot/Rare5.nbt,10,CHEST:3,../../../Chests/Loot/Rare6.nbt,10,CHEST:3,../../../Chests/Loot/Rare7.nbt,10,CHEST:3,../../../Chests/Loot/Rare8.nbt,10,CHEST:3,../../../Chests/Loot/Rare9.nbt,10,CHEST:3,../../../Chests/Loot/Rare10.nbt,15,CHEST:3,../../../Chests/Loot/Rare11.nbt,15,CHEST:3,../../../Chests/Loot/Rare12.nbt,15,CHEST:3,../../../Chests/Loot/Rare13.nbt,15,CHEST:3,../../../Chests/Loot/Rare14.nbt,15,CHEST:3,../../../Chests/Loot/Rare15.nbt,15,CHEST:3,../../../Chests/Loot/Epic15.nbt,100)
Block(-3,4,-3,CARPET:1)
Block(-3,4,-2,CARPET:1)
Block(-3,4,-1,CARPET:1)
Block(-3,4,0,WOOD:1)
Block(-3,4,3,FENCE:0)
Block(-3,4,4,TRAP_DOOR:7)
Block(-3,5,-6,SPRUCE_FENCE:0)
Block(-3,5,0,SPRUCE_FENCE:0)
Block(-3,6,-7,WOOD_STAIRS:5)
Block(-3,6,-6,LOG:4)
Block(-3,6,-5,WOOD_STEP:9)
Block(-3,6,-4,WOOD_STEP:9)
Block(-3,6,-3,WOOD_STEP:9)
Block(-3,6,-2,WOOD_STEP:9)
Block(-3,6,-1,WOOD_STEP:9)
Block(-3,6,0,LOG:4)
Block(-3,6,1,WOOD_STEP:8)
Block(-3,6,2,WOOD_STEP:8)
Block(-3,6,3,WOOD_STAIRS:1)
Block(-3,6,4,SPRUCE_WOOD_STAIRS:1)
Block(-3,6,5,SPRUCE_WOOD_STAIRS:1)
Block(-3,6,6,SPRUCE_WOOD_STAIRS:1)
Block(-3,6,7,SPRUCE_WOOD_STAIRS:1)
Block(-3,7,-7,SPRUCE_WOOD_STAIRS:0)
Block(-3,7,-6,WOOD_STAIRS:0)
Block(-3,7,-5,WOOD:1)
Block(-3,7,-4,WALL_SIGN:4)
Block(-3,7,-3,CARPET:13)
Block(-3,7,-2,CARPET:13)
Block(-3,7,-1,CARPET:13)
Block(-3,7,0,WOOD:1)
Block(-3,7,1,WOOD:1)
Block(-3,7,2,WOOD_STAIRS:3)
Block(-3,8,-5,WOOD_STAIRS:2)
Block(-3,8,0,WOOD:1)
Block(-3,8,1,WOOD_STAIRS:3)
Block(-3,9,-4,WOOD_STAIRS:2)
Block(-3,9,0,WOOD_STAIRS:3)
Block(-3,10,-3,WOOD_STAIRS:2)
Block(-3,10,-2,WOOD:1)
Block(-3,10,-1,WOOD_STAIRS:3)
Block(-3,11,-2,WOOD_STEP:1)
Block(-2,1,-7,GRASS:0)
Block(-2,3,-7,WOOD_STEP:8)
Block(-2,3,-6,LOG:4)
Block(-2,3,-5,WOOD_STEP:8)
Block(-2,3,-4,WOOD_STEP:8)
Block(-2,3,-3,WOOD_STEP:8)
Block(-2,3,-2,WOOD_STEP:8)
Block(-2,3,-1,WOOD_STEP:8)
Block(-2,3,0,LOG:4)
Block(-2,3,1,WOOD_STEP:8)
Block(-2,3,2,WOOD_STEP:8)
Block(-2,3,3,LOG:4)
Block(-2,4,-7,TRAP_DOOR:4)
Block(-2,4,-6,SPRUCE_WOOD_STAIRS:2)
RandomBlock(-2,4,-5,AIR:0,20,CHEST:3,../../../Chests/Loot/JunkChest_1.nbt,10,CHEST:3,../../../Chests/Loot/JunkChest_2.nbt,10,CHEST:3,../../../Chests/Loot/JunkChest_3.nbt,10,CHEST:3,../../../Chests/Loot/JunkChest_4.nbt,10,CHEST:3,../../../Chests/Loot/JunkChest_5.nbt,10,CHEST:3,../../../Chests/Lore/Farmland_1.nbt,1,CHEST:3,../../../Chests/Lore/Farmland_2.nbt,1,CHEST:3,../../../Chests/Lore/Farmland_3.nbt,1,CHEST:3,../../../Chests/Lore/Farmland_4.nbt,1,CHEST:3,../../../Chests/Lore/Farmland_5.nbt,1,CHEST:3,../../../Chests/Loot/Common1.nbt,10,CHEST:3,../../../Chests/Loot/Common2.nbt,10,CHEST:3,../../../Chests/Loot/Common3.nbt,10,CHEST:3,../../../Chests/Loot/Common4.nbt,10,CHEST:3,../../../Chests/Loot/Common5.nbt,10,CHEST:3,../../../Chests/Loot/Common6.nbt,10,CHEST:3,../../../Chests/Loot/Common7.nbt,10,CHEST:3,../../../Chests/Loot/Common8.nbt,10,CHEST:3,../../../Chests/Loot/Common9.nbt,10,CHEST:3,../../../Chests/Loot/Common10.nbt,10,CHEST:3,../../../Chests/Loot/Common10.nbt,11,CHEST:3,../../../Chests/Loot/Common12.nbt,10,CHEST:3,../../../Chests/Loot/Common13.nbt,10,CHEST:3,../../../Chests/Loot/Common14.nbt,10,CHEST:3,../../../Chests/Loot/Common15.nbt,10,CHEST:3,../../../Chests/Lore/Farmland_1.nbt,2,CHEST:3,../../../Chests/Lore/Farmland_3.nbt,2,CHEST:3,../../../Chests/Lore/Farmland_4.nbt,2,CHEST:3,../../../Chests/Lore/Farmland_5.nbt,2,CHEST:3,../../../Chests/Lore/Farmland_5.nbt,2,CHEST:3,../../../Chests/Loot/Rare1.nbt,5,CHEST:3,../../../Chests/Loot/Rare2.nbt,5,CHEST:3,../../../Chests/Loot/Rare3.nbt,5,CHEST:3,../../../Chests/Loot/Rare4.nbt,5,CHEST:3,../../../Chests/Loot/Rare5.nbt,5,CHEST:3,../../../Chests/Loot/Rare6.nbt,5,CHEST:3,../../../Chests/Loot/Rare7.nbt,5,CHEST:3,../../../Chests/Loot/Rare8.nbt,5,CHEST:3,../../../Chests/Loot/Rare9.nbt,5,CHEST:3,../../../Chests/Loot/Rare10.nbt,5,CHEST:3,../../../Chests/Loot/Rare11.nbt,5,CHEST:3,../../../Chests/Loot/Rare12.nbt,5,CHEST:3,../../../Chests/Loot/Rare13.nbt,5,CHEST:3,../../../Chests/Loot/Rare14.nbt,5,CHEST:3,../../../Chests/Loot/Rare15.nbt,5,CHEST:3,../../../Chests/Loot/Epic1.nbt,2,CHEST:3,../../../Chests/Loot/Epic2.nbt,2,CHEST:3,../../../Chests/Loot/Epic3.nbt,2,CHEST:3,../../../Chests/Loot/Epic4.nbt,2,CHEST:3,../../../Chests/Loot/Epic5.nbt,2,CHEST:3,../../../Chests/Loot/Epic6.nbt,2,CHEST:3,../../../Chests/Loot/Epic7.nbt,2,CHEST:3,../../../Chests/Loot/Epic8.nbt,2,CHEST:3,../../../Chests/Loot/Epic9.nbt,2,CHEST:3,../../../Chests/Loot/Epic10.nbt,2,CHEST:3,../../../Chests/Loot/Epic11.nbt,2,CHEST:3,../../../Chests/Loot/Epic12.nbt,2,CHEST:3,../../../Chests/Loot/Epic13.nbt,2,CHEST:3,../../../Chests/Loot/Epic14.nbt,2,CHEST:3,../../../Chests/Loot/Epic15.nbt,5,CHEST:3,../../../Chests/Loot/Rare1.nbt,5,CHEST:3,../../../Chests/Loot/Rare2.nbt,5,CHEST:3,../../../Chests/Loot/Rare3.nbt,5,CHEST:3,../../../Chests/Loot/Rare4.nbt,5,CHEST:3,../../../Chests/Loot/Rare5.nbt,10,CHEST:3,../../../Chests/Loot/Rare6.nbt,10,CHEST:3,../../../Chests/Loot/Rare7.nbt,10,CHEST:3,../../../Chests/Loot/Rare8.nbt,10,CHEST:3,../../../Chests/Loot/Rare9.nbt,10,CHEST:3,../../../Chests/Loot/Rare10.nbt,15,CHEST:3,../../../Chests/Loot/Rare11.nbt,15,CHEST:3,../../../Chests/Loot/Rare12.nbt,15,CHEST:3,../../../Chests/Loot/Rare13.nbt,15,CHEST:3,../../../Chests/Loot/Rare14.nbt,15,CHEST:3,../../../Chests/Loot/Rare15.nbt,15,CHEST:3,../../../Chests/Loot/Epic15.nbt,100)
Block(-2,4,-4,CARPET:1)
Block(-2,4,-3,CARPET:1)
Block(-2,4,-2,CARPET:1)
Block(-2,4,-1,CARPET:1)
Block(-2,4,0,WOOD:1)
Block(-2,4,3,FENCE:0)
Block(-2,5,-6,SPRUCE_FENCE:0)
Block(-2,5,0,SPRUCE_FENCE:0)
Block(-2,6,-6,LOG:4)
Block(-2,6,-5,WOOD_STEP:9)
Block(-2,6,-4,WOOD_STEP:9)
Block(-2,6,-3,WOOD_STEP:9)
Block(-2,6,-2,WOOD_STEP:9)
Block(-2,6,-1,WOOD_STEP:9)
Block(-2,6,0,LOG:4)
Block(-2,6,1,WOOD_STEP:8)
Block(-2,6,2,WOOD_STEP:8)
Block(-2,6,3,WOOD_STAIRS:3)
Block(-2,6,4,WOOD_STEP:1)
Block(-2,7,-7,WOOD_STAIRS:5)
Block(-2,7,-6,WOOD:1)
Block(-2,7,-5,WOOD:1)
Block(-2,7,-4,WOOD_STAIRS:3)
Block(-2,7,-3,CARPET:13)
Block(-2,7,-2,CARPET:13)
Block(-2,7,0,WOOD:1)
Block(-2,7,1,WOOD:1)
Block(-2,7,2,WOOD_STAIRS:3)
Block(-2,8,-7,SPRUCE_WOOD_STAIRS:0)
Block(-2,8,-6,WOOD_STAIRS:0)
Block(-2,8,-5,WOOD_STAIRS:0)
Block(-2,8,0,WOOD:1)
Block(-2,8,1,WOOD_STAIRS:3)
Block(-2,9,-4,WOOD_STAIRS:2)
Block(-2,9,0,WOOD_STAIRS:3)
Block(-2,10,-3,WOOD_STAIRS:2)
Block(-2,10,-2,WOOD:1)
Block(-2,10,-1,WOOD_STAIRS:3)
Block(-2,11,-2,WOOD_STEP:1)
Block(-1,0,-6,LOG:0)
Block(-1,0,0,LOG:0)
Block(-1,0,3,LOG:0)
Block(-1,1,-7,GRASS:0)
Block(-1,1,-6,LOG:0)
Block(-1,1,0,LOG:0)
Block(-1,1,3,LOG:0)
Block(-1,2,-6,LOG:0)
Block(-1,2,0,LOG:0)
Block(-1,2,3,LOG:0)
Block(-1,3,-7,WOOD_STEP:8)
Block(-1,3,-6,LOG:0)
Block(-1,3,-5,WOOD_STEP:8)
Block(-1,3,-4,WOOD_STEP:9)
Block(-1,3,-3,WOOD_STEP:8)
Block(-1,3,-2,WOOD_STEP:8)
Block(-1,3,-1,WOOD_STEP:8)
Block(-1,3,0,LOG:0)
Block(-1,3,1,WOOD_STEP:8)
Block(-1,3,2,WOOD_STEP:8)
Block(-1,3,3,LOG:0)
Block(-1,3,4,STONE_BUTTON:3)
Block(-1,4,-6,LOG:0)
Block(-1,4,-5,LOG:0)
Block(-1,4,-3,CARPET:1)
Block(-1,4,-2,CARPET:1)
Block(-1,4,0,LOG:0)
Block(-1,4,3,LOG:0)
Block(-1,5,-6,LOG:0)
Block(-1,5,-5,TORCH:5)
Block(-1,5,0,LOG:0)
Block(-1,5,3,LOG:0)
Block(-1,6,-6,LOG:0)
Block(-1,6,-5,LOG:8)
Block(-1,6,-4,LOG:8)
Block(-1,6,-3,LOG:8)
Block(-1,6,-2,LOG:8)
Block(-1,6,-1,LOG:8)
Block(-1,6,0,LOG:0)
Block(-1,6,1,WOOD_STEP:8)
Block(-1,6,2,WOOD_STEP:8)
Block(-1,6,3,WOOD_STAIRS:3)
Block(-1,6,4,WOOD_STEP:1)
Block(-1,7,-6,LOG:0)
Block(-1,7,-5,LOG:0)
Block(-1,7,-4,CONCRETE:0)
Block(-1,7,-3,CONCRETE:0)
Block(-1,7,-2,SPRUCE_DOOR:0)
Block(-1,7,-1,CONCRETE:0)
Block(-1,7,0,LOG:0)
Block(-1,7,1,WOOD:1)
Block(-1,7,2,WOOD_STAIRS:3)
Block(-1,8,-7,WOOD_STAIRS:5)
Block(-1,8,-6,LOG:0)
Block(-1,8,-5,CONCRETE:0)
Block(-1,8,-4,CONCRETE:0)
Block(-1,8,-3,CONCRETE:0)
Block(-1,8,-2,SPRUCE_DOOR:8)
Block(-1,8,-1,CONCRETE:0)
Block(-1,8,0,LOG:0)
Block(-1,8,1,WOOD_STAIRS:5)
Block(-1,9,-7,SPRUCE_WOOD_STAIRS:0)
Block(-1,9,-6,WOOD_STAIRS:0)
Block(-1,9,-5,WOOD_STAIRS:0)
Block(-1,9,-4,WOOD_STAIRS:0)
Block(-1,9,-3,CONCRETE:0)
Block(-1,9,-2,CONCRETE:0)
Block(-1,9,-1,CONCRETE:0)
Block(-1,9,0,WOOD_STAIRS:0)
Block(-1,9,1,WOOD_STAIRS:0)
Block(-1,10,-3,WOOD_STAIRS:2)
Block(-1,10,-2,WOOD:1)
Block(-1,10,-1,WOOD_STAIRS:3)
Block(-1,11,-2,WOOD_STEP:1)
Block(0,0,5,LOG:0)
Block(0,1,-7,GRASS:0)
Block(0,1,5,LOG:0)
Block(0,2,4,WOOD_STAIRS:6)
Block(0,2,5,WOOD_STAIRS:3)
Block(0,3,-7,WOOD_STEP:8)
Block(0,3,-6,LOG:4)
Block(0,3,-5,WOOD_STEP:8)
Block(0,3,-4,WOOD_STEP:9)
Block(0,3,-3,WOOD_STEP:8)
Block(0,3,-2,WOOD_STEP:9)
Block(0,3,-1,WOOD_STEP:8)
Block(0,3,0,LOG:4)
Block(0,3,1,WOOD_STEP:8)
Block(0,3,2,WOOD_STEP:8)
Block(0,3,3,WOOD_DOUBLE_STEP:0)
Block(0,3,4,WOOD_STAIRS:3)
Block(0,4,-6,SPRUCE_DOOR:7)
Block(0,4,-4,WALL_SIGN:4)
Block(0,4,-3,SPRUCE_WOOD_STAIRS:0)
Block(0,4,0,SPRUCE_DOOR:5)
Block(0,4,3,SPRUCE_DOOR:3)
Block(0,5,-6,SPRUCE_DOOR:8)
Block(0,5,0,SPRUCE_DOOR:9)
Block(0,5,3,SPRUCE_DOOR:8)
Block(0,6,-6,LOG:4)
Block(0,6,-5,WOOD_STEP:9)
Block(0,6,-4,WOOD_STEP:9)
Block(0,6,-3,WOOD_STEP:9)
Block(0,6,-2,WOOD_STEP:9)
Block(0,6,-1,WOOD_STEP:9)
Block(0,6,0,LOG:4)
Block(0,6,1,WOOD_STEP:8)
Block(0,6,2,WOOD_STEP:8)
Block(0,6,3,WOOD_STAIRS:3)
Block(0,6,4,WOOD_STEP:1)
Block(0,7,-6,SPRUCE_WOOD_STAIRS:1)
Block(0,7,-4,CARPET:13)
Block(0,7,-3,CARPET:13)
Block(0,7,-2,CARPET:13)
Block(0,7,0,SPRUCE_DOOR:1)
Block(0,7,1,FENCE:0)
Block(0,8,-6,SPRUCE_WOOD_STAIRS:5)
Block(0,8,0,SPRUCE_DOOR:9)
Block(0,9,-7,WOOD_STAIRS:5)
Block(0,9,-6,WOOD:1)
Block(0,9,0,LOG:4)
Block(0,9,1,WOOD_STAIRS:5)
Block(0,10,-7,SPRUCE_WOOD_STAIRS:0)
Block(0,10,-6,WOOD_STAIRS:0)
Block(0,10,-5,WOOD_STAIRS:0)
Block(0,10,-4,WOOD_STAIRS:0)
Block(0,10,-3,WOOD_STAIRS:0)
Block(0,10,-2,WOOD:1)
Block(0,10,-1,WOOD_STAIRS:0)
Block(0,10,0,WOOD_STAIRS:0)
Block(0,10,1,WOOD_STAIRS:0)
Block(0,11,-2,WOOD_STEP:1)
Block(1,0,5,LOG:0)
Block(1,1,-7,GRASS:0)
Block(1,1,5,LOG:0)
Block(1,2,4,WOOD_STAIRS:6)
Block(1,2,5,WOOD_STAIRS:3)
Block(1,3,-7,WOOD_STEP:8)
Block(1,3,-6,LOG:4)
Block(1,3,-5,WOOD_STEP:8)
Block(1,3,-4,WOOD_STEP:8)
Block(1,3,-3,WOOD_STEP:8)
Block(1,3,-2,WOOD_STEP:9)
Block(1,3,-1,WOOD_STEP:9)
Block(1,3,0,LOG:4)
Block(1,3,1,WOOD_STEP:8)
Block(1,3,2,WOOD_STEP:8)
Block(1,3,3,WOOD_DOUBLE_STEP:0)
Block(1,3,4,WOOD_STAIRS:3)
Block(1,4,-6,SPRUCE_DOOR:3)
Block(1,4,-5,CARPET:1)
Block(1,4,-4,WOOD_STAIRS:3)
Block(1,4,-3,WOOD_STEP:9)
Block(1,4,-2,WALL_SIGN:4)
Block(1,4,0,SPRUCE_DOOR:5)
Block(1,4,3,SPRUCE_DOOR:3)
Block(1,5,-6,SPRUCE_DOOR:9)
Block(1,5,0,SPRUCE_DOOR:8)
Block(1,5,3,SPRUCE_DOOR:9)
Block(1,6,-6,LOG:4)
Block(1,6,-5,WOOD_STEP:9)
Block(1,6,-4,WOOD_STEP:9)
Block(1,6,-3,WOOD_STEP:9)
Block(1,6,-2,WOOD_STEP:9)
Block(1,6,-1,WOOD_STEP:9)
Block(1,6,0,LOG:4)
Block(1,6,1,WOOD_STEP:8)
Block(1,6,2,WOOD_STEP:8)
Block(1,6,3,WOOD_STAIRS:3)
Block(1,6,4,WOOD_STEP:1)
Block(1,7,-6,SPRUCE_WOOD_STAIRS:0)
Block(1,7,-5,BED_BLOCK:3)
Block(1,7,-4,CARPET:13)
Block(1,7,-3,CARPET:13)
Block(1,7,-2,CARPET:13)
Block(1,7,0,SPRUCE_DOOR:1)
Block(1,7,1,FENCE:0)
Block(1,8,-6,SPRUCE_WOOD_STAIRS:4)
Block(1,8,0,SPRUCE_DOOR:8)
Block(1,9,-7,WOOD_STAIRS:4)
Block(1,9,-6,WOOD:1)
Block(1,9,0,LOG:4)
Block(1,9,1,WOOD_STAIRS:4)
Block(1,10,-7,SPRUCE_WOOD_STAIRS:1)
Block(1,10,-6,WOOD_STAIRS:1)
Block(1,10,-5,WOOD_STAIRS:1)
Block(1,10,-4,WOOD_STAIRS:1)
Block(1,10,-3,WOOD_STAIRS:1)
Block(1,10,-2,WOOD:1)
Block(1,10,-1,WOOD_STAIRS:3)
Block(1,10,0,WOOD_STAIRS:1)
Block(1,10,1,WOOD_STAIRS:1)
Block(1,11,-2,WOOD_STEP:1)
Block(2,0,-6,LOG:0)
Block(2,0,0,LOG:0)
Block(2,0,3,LOG:0)
Block(2,1,-6,LOG:0)
Block(2,1,0,LOG:0)
Block(2,1,3,LOG:0)
Block(2,2,-6,LOG:0)
Block(2,2,0,LOG:0)
Block(2,2,3,LOG:0)
Block(2,3,-7,LOG:8)
Block(2,3,-6,LOG:0)
Block(2,3,-5,WOOD_STEP:8)
Block(2,3,-4,WOOD_STEP:8)
Block(2,3,-3,WOOD_STEP:8)
Block(2,3,-2,WOOD_STEP:8)
Block(2,3,-1,WOOD_STEP:8)
Block(2,3,0,LOG:0)
Block(2,3,1,WOOD_STEP:8)
Block(2,3,2,WOOD_STEP:8)
Block(2,3,3,LOG:0)
Block(2,3,4,STONE_BUTTON:3)
Block(2,4,-7,SPRUCE_FENCE:0)
Block(2,4,-6,LOG:0)
Block(2,4,-5,CARPET:1)
Block(2,4,-4,WALL_SIGN:5)
Block(2,4,-3,WOOD_STEP:9)
Block(2,4,-2,WOOD_STAIRS:2)
Block(2,4,-1,CARPET:1)
Block(2,4,0,LOG:0)
Block(2,4,3,LOG:0)
Block(2,5,-6,LOG:0)
Block(2,5,0,LOG:0)
Block(2,5,3,LOG:0)
Block(2,6,-6,LOG:0)
Block(2,6,-5,LOG:8)
Block(2,6,-4,LOG:8)
Block(2,6,-3,LOG:8)
Block(2,6,-2,LOG:8)
Block(2,6,-1,LOG:8)
Block(2,6,0,LOG:0)
Block(2,6,1,WOOD_STEP:8)
Block(2,6,2,WOOD_STEP:8)
Block(2,6,3,WOOD_STAIRS:3)
Block(2,6,4,WOOD_STEP:1)
Block(2,7,-6,LOG:0)
Block(2,7,-5,BED_BLOCK:11)
Block(2,7,-1,SPRUCE_WOOD_STAIRS:0)
Block(2,7,0,LOG:0)
Block(2,7,1,WOOD:1)
Block(2,7,2,WOOD_STAIRS:3)
Block(2,8,-7,WOOD_STAIRS:4)
Block(2,8,-6,LOG:0)
Block(2,8,0,LOG:0)
Block(2,8,1,WOOD_STAIRS:4)
Block(2,9,-7,SPRUCE_WOOD_STAIRS:1)
Block(2,9,-6,WOOD_STAIRS:1)
Block(2,9,-5,WOOD_STAIRS:1)
Block(2,9,-4,WOOD_STAIRS:1)
Block(2,9,0,WOOD_STAIRS:1)
Block(2,9,1,WOOD_STAIRS:1)
Block(2,10,-3,WOOD_STAIRS:2)
Block(2,10,-2,WOOD:1)
Block(2,10,-1,WOOD_STAIRS:3)
Block(2,11,-2,WOOD_STEP:1)
Block(3,1,-7,GRASS:0)
Block(3,3,-6,LOG:4)
Block(3,3,-5,WOOD_STEP:8)
Block(3,3,-4,WOOD_STEP:8)
Block(3,3,-3,WOOD_STEP:8)
Block(3,3,-2,WOOD_STEP:8)
Block(3,3,-1,WOOD_STEP:8)
Block(3,3,0,LOG:4)
Block(3,3,1,WOOD_STEP:8)
Block(3,3,2,WOOD_STEP:8)
Block(3,3,3,LOG:4)
Block(3,4,-7,TRAP_DOOR:4)
Block(3,4,-6,SPRUCE_WOOD_STAIRS:2)
Block(3,4,-4,CARPET:1)
Block(3,4,-3,WOOD_STEP:9)
Block(3,4,-2,WALL_SIGN:5)
Block(3,4,-1,CARPET:1)
Block(3,4,0,WOOD:1)
Block(3,4,3,FENCE:0)
Block(3,5,-6,SPRUCE_FENCE:0)
Block(3,5,-4,SPRUCE_WOOD_STAIRS:4)
Block(3,5,0,SPRUCE_FENCE:0)
Block(3,6,-6,LOG:4)
Block(3,6,-5,WOOD_STEP:9)
Block(3,6,-4,SPRUCE_WOOD_STAIRS:1)
Block(3,6,0,LOG:4)
Block(3,6,1,WOOD_STEP:8)
Block(3,6,2,WOOD_STEP:8)
Block(3,6,3,WOOD_STAIRS:3)
Block(3,6,4,WOOD_STEP:1)
Block(3,7,-7,WOOD_STAIRS:4)
Block(3,7,-6,WOOD:1)
Block(3,7,-5,WOOD:1)
Block(3,7,-1,WOOD_STEP:9)
Block(3,7,0,WOOD:1)
Block(3,7,1,WOOD:1)
Block(3,7,2,WOOD_STAIRS:3)
Block(3,8,-7,SPRUCE_WOOD_STAIRS:1)
Block(3,8,-6,WOOD_STAIRS:1)
Block(3,8,-5,WOOD_STAIRS:1)
RandomBlock(3,8,-1,AIR:0,20,CHEST:2,../../../Chests/Loot/JunkChest_1.nbt,10,CHEST:2,../../../Chests/Loot/JunkChest_2.nbt,10,CHEST:2,../../../Chests/Loot/JunkChest_3.nbt,10,CHEST:2,../../../Chests/Loot/JunkChest_4.nbt,10,CHEST:2,../../../Chests/Loot/JunkChest_5.nbt,10,CHEST:2,../../../Chests/Lore/Farmland_1.nbt,1,CHEST:2,../../../Chests/Lore/Farmland_2.nbt,1,CHEST:2,../../../Chests/Lore/Farmland_3.nbt,1,CHEST:2,../../../Chests/Lore/Farmland_4.nbt,1,CHEST:2,../../../Chests/Lore/Farmland_5.nbt,1,CHEST:2,../../../Chests/Loot/Common1.nbt,10,CHEST:2,../../../Chests/Loot/Common2.nbt,10,CHEST:2,../../../Chests/Loot/Common3.nbt,10,CHEST:2,../../../Chests/Loot/Common4.nbt,10,CHEST:2,../../../Chests/Loot/Common5.nbt,10,CHEST:2,../../../Chests/Loot/Common6.nbt,10,CHEST:2,../../../Chests/Loot/Common7.nbt,10,CHEST:2,../../../Chests/Loot/Common8.nbt,10,CHEST:2,../../../Chests/Loot/Common9.nbt,10,CHEST:2,../../../Chests/Loot/Common10.nbt,10,CHEST:2,../../../Chests/Loot/Common10.nbt,11,CHEST:2,../../../Chests/Loot/Common12.nbt,10,CHEST:2,../../../Chests/Loot/Common13.nbt,10,CHEST:2,../../../Chests/Loot/Common14.nbt,10,CHEST:2,../../../Chests/Loot/Common15.nbt,10,CHEST:2,../../../Chests/Lore/Farmland_1.nbt,2,CHEST:2,../../../Chests/Lore/Farmland_3.nbt,2,CHEST:2,../../../Chests/Lore/Farmland_4.nbt,2,CHEST:2,../../../Chests/Lore/Farmland_5.nbt,2,CHEST:2,../../../Chests/Lore/Farmland_5.nbt,2,CHEST:2,../../../Chests/Loot/Rare1.nbt,5,CHEST:2,../../../Chests/Loot/Rare2.nbt,5,CHEST:2,../../../Chests/Loot/Rare3.nbt,5,CHEST:2,../../../Chests/Loot/Rare4.nbt,5,CHEST:2,../../../Chests/Loot/Rare5.nbt,5,CHEST:2,../../../Chests/Loot/Rare6.nbt,5,CHEST:2,../../../Chests/Loot/Rare7.nbt,5,CHEST:2,../../../Chests/Loot/Rare8.nbt,5,CHEST:2,../../../Chests/Loot/Rare9.nbt,5,CHEST:2,../../../Chests/Loot/Rare10.nbt,5,CHEST:2,../../../Chests/Loot/Rare11.nbt,5,CHEST:2,../../../Chests/Loot/Rare12.nbt,5,CHEST:2,../../../Chests/Loot/Rare13.nbt,5,CHEST:2,../../../Chests/Loot/Rare14.nbt,5,CHEST:2,../../../Chests/Loot/Rare15.nbt,5,CHEST:2,../../../Chests/Loot/Epic1.nbt,2,CHEST:2,../../../Chests/Loot/Epic2.nbt,2,CHEST:2,../../../Chests/Loot/Epic3.nbt,2,CHEST:2,../../../Chests/Loot/Epic4.nbt,2,CHEST:2,../../../Chests/Loot/Epic5.nbt,2,CHEST:2,../../../Chests/Loot/Epic6.nbt,2,CHEST:2,../../../Chests/Loot/Epic7.nbt,2,CHEST:2,../../../Chests/Loot/Epic8.nbt,2,CHEST:2,../../../Chests/Loot/Epic9.nbt,2,CHEST:2,../../../Chests/Loot/Epic10.nbt,2,CHEST:2,../../../Chests/Loot/Epic11.nbt,2,CHEST:2,../../../Chests/Loot/Epic12.nbt,2,CHEST:2,../../../Chests/Loot/Epic13.nbt,2,CHEST:2,../../../Chests/Loot/Epic14.nbt,2,CHEST:2,../../../Chests/Loot/Epic15.nbt,5,CHEST:2,../../../Chests/Loot/Rare1.nbt,5,CHEST:2,../../../Chests/Loot/Rare2.nbt,5,CHEST:2,../../../Chests/Loot/Rare3.nbt,5,CHEST:2,../../../Chests/Loot/Rare4.nbt,5,CHEST:2,../../../Chests/Loot/Rare5.nbt,10,CHEST:2,../../../Chests/Loot/Rare6.nbt,10,CHEST:2,../../../Chests/Loot/Rare7.nbt,10,CHEST:2,../../../Chests/Loot/Rare8.nbt,10,CHEST:2,../../../Chests/Loot/Rare9.nbt,10,CHEST:2,../../../Chests/Loot/Rare10.nbt,15,CHEST:2,../../../Chests/Loot/Rare11.nbt,15,CHEST:2,../../../Chests/Loot/Rare12.nbt,15,CHEST:2,../../../Chests/Loot/Rare13.nbt,15,CHEST:2,../../../Chests/Loot/Rare14.nbt,15,CHEST:2,../../../Chests/Loot/Rare15.nbt,15,CHEST:2,../../../Chests/Loot/Epic15.nbt,100)
Block(3,8,0,WOOD:1)
Block(3,8,1,WOOD_STAIRS:3)
Block(3,9,-4,WOOD_STAIRS:2)
Block(3,9,0,WOOD_STAIRS:3)
Block(3,10,-3,WOOD_STAIRS:2)
Block(3,10,-2,WOOD:1)
Block(3,10,-1,WOOD_STAIRS:3)
Block(3,11,-2,WOOD_STEP:1)
Block(4,1,-7,GRASS:0)
Block(4,3,-6,LOG:4)
Block(4,3,-5,WOOD_STEP:8)
Block(4,3,-4,WOOD_STEP:8)
Block(4,3,-3,WOOD_STEP:8)
Block(4,3,-2,WOOD_STEP:8)
Block(4,3,-1,WOOD_STEP:8)
Block(4,3,0,LOG:4)
Block(4,3,1,WOOD_STEP:8)
Block(4,3,2,WOOD_STEP:8)
Block(4,3,3,LOG:4)
Block(4,4,-6,COBBLESTONE:0)
Block(4,4,-5,BOOKSHELF:0)
Block(4,4,-4,WOOD:1)
Block(4,4,-3,WOOD:1)
Block(4,4,-2,SPRUCE_WOOD_STAIRS:3)
Block(4,4,-1,CARPET:1)
Block(4,4,0,WOOD:1)
Block(4,4,3,FENCE:0)
Block(4,5,-6,COBBLESTONE:0)
Block(4,5,-5,BOOKSHELF:0)
Block(4,5,-4,WOOD:1)
Block(4,5,-3,SPRUCE_WOOD_STAIRS:3)
Block(4,5,0,SPRUCE_FENCE:0)
Block(4,6,-7,WOOD_STAIRS:4)
Block(4,6,-6,LOG:4)
Block(4,6,-5,WOOD_STEP:9)
Block(4,6,0,LOG:4)
Block(4,6,1,WOOD_STEP:8)
Block(4,6,2,WOOD_STEP:8)
Block(4,6,3,WOOD_STAIRS:3)
Block(4,6,4,WOOD_STEP:1)
Block(4,7,-7,SPRUCE_WOOD_STAIRS:1)
Block(4,7,-6,WOOD_STAIRS:2)
Block(4,7,-5,WOOD:1)
Block(4,7,-1,WOOD_STEP:9)
Block(4,7,0,WOOD:1)
Block(4,7,1,WOOD:1)
Block(4,7,2,WOOD_STAIRS:3)
Block(4,8,-5,WOOD_STAIRS:2)
RandomBlock(4,8,-1,AIR:0,20,CHEST:2,../../../Chests/Loot/JunkChest_1.nbt,10,CHEST:2,../../../Chests/Loot/JunkChest_2.nbt,10,CHEST:2,../../../Chests/Loot/JunkChest_3.nbt,10,CHEST:2,../../../Chests/Loot/JunkChest_4.nbt,10,CHEST:2,../../../Chests/Loot/JunkChest_5.nbt,10,CHEST:2,../../../Chests/Lore/Farmland_1.nbt,1,CHEST:2,../../../Chests/Lore/Farmland_2.nbt,1,CHEST:2,../../../Chests/Lore/Farmland_3.nbt,1,CHEST:2,../../../Chests/Lore/Farmland_4.nbt,1,CHEST:2,../../../Chests/Lore/Farmland_5.nbt,1,CHEST:2,../../../Chests/Loot/Common1.nbt,10,CHEST:2,../../../Chests/Loot/Common2.nbt,10,CHEST:2,../../../Chests/Loot/Common3.nbt,10,CHEST:2,../../../Chests/Loot/Common4.nbt,10,CHEST:2,../../../Chests/Loot/Common5.nbt,10,CHEST:2,../../../Chests/Loot/Common6.nbt,10,CHEST:2,../../../Chests/Loot/Common7.nbt,10,CHEST:2,../../../Chests/Loot/Common8.nbt,10,CHEST:2,../../../Chests/Loot/Common9.nbt,10,CHEST:2,../../../Chests/Loot/Common10.nbt,10,CHEST:2,../../../Chests/Loot/Common10.nbt,11,CHEST:2,../../../Chests/Loot/Common12.nbt,10,CHEST:2,../../../Chests/Loot/Common13.nbt,10,CHEST:2,../../../Chests/Loot/Common14.nbt,10,CHEST:2,../../../Chests/Loot/Common15.nbt,10,CHEST:2,../../../Chests/Lore/Farmland_1.nbt,2,CHEST:2,../../../Chests/Lore/Farmland_3.nbt,2,CHEST:2,../../../Chests/Lore/Farmland_4.nbt,2,CHEST:2,../../../Chests/Lore/Farmland_5.nbt,2,CHEST:2,../../../Chests/Lore/Farmland_5.nbt,2,CHEST:2,../../../Chests/Loot/Rare1.nbt,5,CHEST:2,../../../Chests/Loot/Rare2.nbt,5,CHEST:2,../../../Chests/Loot/Rare3.nbt,5,CHEST:2,../../../Chests/Loot/Rare4.nbt,5,CHEST:2,../../../Chests/Loot/Rare5.nbt,5,CHEST:2,../../../Chests/Loot/Rare6.nbt,5,CHEST:2,../../../Chests/Loot/Rare7.nbt,5,CHEST:2,../../../Chests/Loot/Rare8.nbt,5,CHEST:2,../../../Chests/Loot/Rare9.nbt,5,CHEST:2,../../../Chests/Loot/Rare10.nbt,5,CHEST:2,../../../Chests/Loot/Rare11.nbt,5,CHEST:2,../../../Chests/Loot/Rare12.nbt,5,CHEST:2,../../../Chests/Loot/Rare13.nbt,5,CHEST:2,../../../Chests/Loot/Rare14.nbt,5,CHEST:2,../../../Chests/Loot/Rare15.nbt,5,CHEST:2,../../../Chests/Loot/Epic1.nbt,2,CHEST:2,../../../Chests/Loot/Epic2.nbt,2,CHEST:2,../../../Chests/Loot/Epic3.nbt,2,CHEST:2,../../../Chests/Loot/Epic4.nbt,2,CHEST:2,../../../Chests/Loot/Epic5.nbt,2,CHEST:2,../../../Chests/Loot/Epic6.nbt,2,CHEST:2,../../../Chests/Loot/Epic7.nbt,2,CHEST:2,../../../Chests/Loot/Epic8.nbt,2,CHEST:2,../../../Chests/Loot/Epic9.nbt,2,CHEST:2,../../../Chests/Loot/Epic10.nbt,2,CHEST:2,../../../Chests/Loot/Epic11.nbt,2,CHEST:2,../../../Chests/Loot/Epic12.nbt,2,CHEST:2,../../../Chests/Loot/Epic13.nbt,2,CHEST:2,../../../Chests/Loot/Epic14.nbt,2,CHEST:2,../../../Chests/Loot/Epic15.nbt,5,CHEST:2,../../../Chests/Loot/Rare1.nbt,5,CHEST:2,../../../Chests/Loot/Rare2.nbt,5,CHEST:2,../../../Chests/Loot/Rare3.nbt,5,CHEST:2,../../../Chests/Loot/Rare4.nbt,5,CHEST:2,../../../Chests/Loot/Rare5.nbt,10,CHEST:2,../../../Chests/Loot/Rare6.nbt,10,CHEST:2,../../../Chests/Loot/Rare7.nbt,10,CHEST:2,../../../Chests/Loot/Rare8.nbt,10,CHEST:2,../../../Chests/Loot/Rare9.nbt,10,CHEST:2,../../../Chests/Loot/Rare10.nbt,15,CHEST:2,../../../Chests/Loot/Rare11.nbt,15,CHEST:2,../../../Chests/Loot/Rare12.nbt,15,CHEST:2,../../../Chests/Loot/Rare13.nbt,15,CHEST:2,../../../Chests/Loot/Rare14.nbt,15,CHEST:2,../../../Chests/Loot/Rare15.nbt,15,CHEST:2,../../../Chests/Loot/Epic15.nbt,100)
Block(4,8,0,WOOD:1)
Block(4,8,1,WOOD_STAIRS:3)
Block(4,9,-4,WOOD_STAIRS:2)
Block(4,9,0,WOOD_STAIRS:3)
Block(4,10,-3,WOOD_STAIRS:2)
Block(4,10,-2,WOOD:1)
Block(4,10,-1,WOOD_STAIRS:3)
Block(4,11,-2,WOOD_STEP:1)
Block(5,0,-6,LOG:0)
Block(5,0,-3,LOG:0)
Block(5,0,0,LOG:0)
Block(5,0,3,LOG:0)
Block(5,1,-7,LOG:8)
Block(5,1,-6,LOG:0)
Block(5,1,-3,LOG:0)
Block(5,1,0,LOG:0)
Block(5,1,3,LOG:0)
Block(5,2,-7,SPRUCE_FENCE:0)
Block(5,2,-6,LOG:0)
Block(5,2,-3,LOG:0)
Block(5,2,0,LOG:0)
Block(5,2,3,LOG:0)
Block(5,3,-7,STONE_BUTTON:4)
Block(5,3,-6,LOG:0)
Block(5,3,-5,LOG:8)
Block(5,3,-4,LOG:8)
Block(5,3,-3,LOG:0)
Block(5,3,-2,LOG:8)
Block(5,3,-1,LOG:8)
Block(5,3,0,LOG:0)
Block(5,3,1,LOG:8)
Block(5,3,2,LOG:8)
Block(5,3,3,LOG:0)
Block(5,3,4,STONE_BUTTON:3)
Block(5,4,-6,LOG:0)
Block(5,4,-5,COBBLESTONE_STAIRS:1)
Block(5,4,-4,COBBLESTONE_STAIRS:1)
Block(5,4,-3,LOG:0)
Block(5,4,-2,COBBLESTONE_STAIRS:1)
Block(5,4,-1,COBBLESTONE_STAIRS:1)
Block(5,4,0,LOG:0)
Block(5,4,1,FENCE:0)
Block(5,4,2,FENCE:0)
Block(5,4,3,LOG:0)
Block(5,5,-6,LOG:0)
Block(5,5,-5,COBBLESTONE_STAIRS:5)
Block(5,5,-4,COBBLESTONE_STAIRS:5)
Block(5,5,-3,LOG:0)
Block(5,5,-2,COBBLESTONE_STAIRS:5)
Block(5,5,-1,COBBLESTONE_STAIRS:5)
Block(5,5,0,LOG:0)
Block(5,5,3,LOG:0)
Block(5,6,-7,SPRUCE_WOOD_STAIRS:1)
Block(5,6,-6,LOG:0)
Block(5,6,-5,LOG:8)
Block(5,6,-4,LOG:8)
Block(5,6,-3,LOG:0)
Block(5,6,-2,LOG:8)
Block(5,6,-1,LOG:8)
Block(5,6,0,LOG:0)
Block(5,6,1,LOG:8)
Block(5,6,2,LOG:8)
Block(5,6,3,WOOD_STAIRS:3)
Block(5,6,4,WOOD_STEP:1)
Block(5,7,-6,WOOD_STAIRS:2)
Block(5,7,-5,WOOD:1)
Block(5,7,-4,WOOD:1)
Block(5,7,-3,WOOD:1)
Block(5,7,-2,SPRUCE_WOOD_STAIRS:1)
Block(5,7,-1,WOOD:1)
Block(5,7,0,LOG:0)
Block(5,7,2,WOOD_STAIRS:3)
Block(5,8,-5,WOOD_STAIRS:2)
Block(5,8,-4,WOOD:1)
Block(5,8,-3,WOOD:1)
Block(5,8,-2,FENCE:0)
Block(5,8,-1,WOOD:1)
Block(5,8,0,LOG:0)
Block(5,8,1,WOOD_STAIRS:3)
Block(5,9,-4,WOOD_STAIRS:2)
Block(5,9,-3,WOOD:1)
Block(5,9,-2,SPRUCE_WOOD_STAIRS:5)
Block(5,9,-1,WOOD:1)
Block(5,9,0,WOOD_STAIRS:3)
Block(5,10,-3,WOOD_STAIRS:2)
Block(5,10,-2,WOOD:1)
Block(5,10,-1,WOOD_STAIRS:3)
Block(5,11,-2,WOOD_STEP:1)
Block(6,3,-6,STONE_BUTTON:1)
Block(6,3,-3,STONE_BUTTON:1)
Block(6,3,0,STONE_BUTTON:1)
Block(6,3,3,STONE_BUTTON:1)
Block(6,6,-7,SPRUCE_WOOD_STAIRS:2)
Block(6,6,-6,WOOD_STAIRS:7)
Block(6,6,2,WOOD_STAIRS:6)
Block(6,6,3,SPRUCE_WOOD_STAIRS:3)
Block(6,6,4,WOOD_STEP:1)
Block(6,7,-6,SPRUCE_WOOD_STAIRS:2)
Block(6,7,-5,WOOD_STAIRS:7)
Block(6,7,1,WOOD_STAIRS:6)
Block(6,7,2,SPRUCE_WOOD_STAIRS:3)
Block(6,8,-5,SPRUCE_WOOD_STAIRS:2)
Block(6,8,-4,WOOD_STAIRS:7)
Block(6,8,0,WOOD_STAIRS:6)
Block(6,8,1,SPRUCE_WOOD_STAIRS:3)
Block(6,9,-4,SPRUCE_WOOD_STAIRS:2)
Block(6,9,-3,WOOD_STAIRS:7)
Block(6,9,-1,WOOD_STAIRS:6)
Block(6,9,0,SPRUCE_WOOD_STAIRS:3)
Block(6,10,-3,SPRUCE_WOOD_STAIRS:2)
Block(6,10,-2,WOOD_STAIRS:5)
Block(6,10,-1,SPRUCE_WOOD_STAIRS:3)
Block(6,11,-2,WOOD_STEP:1)
Branch(0,0,16,true,plainsfarmC1R2,NORTH,100.0,0)
Branch(-16,0,0,true,plainsfarmC0R1,NORTH,100.0,0)
Entity(-5,4,0,minecraft:villager,1,../Entities/Farmer.txt)
Entity(-4,7,-1,minecraft:villager,1,../Entities/Farmer.txt)


RandomBlock(-8,5,-6,WALL_BANNER:4,../../NBT/viking_tannery_1.nbt,10,WALL_BANNER:4,../../NBT/viking_tannery_2.nbt,10,WALL_BANNER:4,../../NBT/viking_tannery_3.nbt,10,WALL_BANNER:4,../../NBT/viking_tannery_4.nbt,10,WALL_BANNER:4,../../NBT/viking_tannery_5.nbt,100)
RandomBlock(-8,5,-3,WALL_BANNER:4,../../NBT/viking_tannery_1.nbt,10,WALL_BANNER:4,../../NBT/viking_tannery_2.nbt,10,WALL_BANNER:4,../../NBT/viking_tannery_3.nbt,10,WALL_BANNER:4,../../NBT/viking_tannery_4.nbt,10,WALL_BANNER:4,../../NBT/viking_tannery_5.nbt,100)
RandomBlock(-8,5,0,WALL_BANNER:4,../../NBT/viking_tannery_1.nbt,10,WALL_BANNER:4,../../NBT/viking_tannery_2.nbt,10,WALL_BANNER:4,../../NBT/viking_tannery_3.nbt,10,WALL_BANNER:4,../../NBT/viking_tannery_4.nbt,10,WALL_BANNER:4,../../NBT/viking_tannery_5.nbt,100)
RandomBlock(-8,5,3,WALL_BANNER:4,../../NBT/viking_tannery_1.nbt,10,WALL_BANNER:4,../../NBT/viking_tannery_2.nbt,10,WALL_BANNER:4,../../NBT/viking_tannery_3.nbt,10,WALL_BANNER:4,../../NBT/viking_tannery_4.nbt,10,WALL_BANNER:4,../../NBT/viking_tannery_5.nbt,100)
RandomBlock(-8,5,6,WALL_BANNER:4,../../NBT/viking_tannery_1.nbt,10,WALL_BANNER:4,../../NBT/viking_tannery_2.nbt,10,WALL_BANNER:4,../../NBT/viking_tannery_3.nbt,10,WALL_BANNER:4,../../NBT/viking_tannery_4.nbt,10,WALL_BANNER:4,../../NBT/viking_tannery_5.nbt,100)
RandomBlock(-7,5,-7,WALL_BANNER:2,../../NBT/viking_tannery_1.nbt,10,WALL_BANNER:2,../../NBT/viking_tannery_2.nbt,10,WALL_BANNER:2,../../NBT/viking_tannery_3.nbt,10,WALL_BANNER:2,../../NBT/viking_tannery_4.nbt,10,WALL_BANNER:2,../../NBT/viking_tannery_5.nbt,100)
RandomBlock(-4,5,-7,WALL_BANNER:2,../../NBT/viking_tannery_1.nbt,10,WALL_BANNER:2,../../NBT/viking_tannery_2.nbt,10,WALL_BANNER:2,../../NBT/viking_tannery_3.nbt,10,WALL_BANNER:2,../../NBT/viking_tannery_4.nbt,10,WALL_BANNER:2,../../NBT/viking_tannery_5.nbt,100)
RandomBlock(-3,5,6,WALL_BANNER:5,../../NBT/viking_tannery_1.nbt,10,WALL_BANNER:5,../../NBT/viking_tannery_2.nbt,10,WALL_BANNER:5,../../NBT/viking_tannery_3.nbt,10,WALL_BANNER:5,../../NBT/viking_tannery_4.nbt,10,WALL_BANNER:5,../../NBT/viking_tannery_5.nbt,100)
RandomBlock(-1,5,-7,WALL_BANNER:2,../../NBT/viking_tannery_1.nbt,10,WALL_BANNER:2,../../NBT/viking_tannery_2.nbt,10,WALL_BANNER:2,../../NBT/viking_tannery_3.nbt,10,WALL_BANNER:2,../../NBT/viking_tannery_4.nbt,10,WALL_BANNER:2,../../NBT/viking_tannery_5.nbt,100)
RandomBlock(-1,5,4,WALL_BANNER:3,../../NBT/viking_tannery_1.nbt,10,WALL_BANNER:3,../../NBT/viking_tannery_2.nbt,10,WALL_BANNER:3,../../NBT/viking_tannery_3.nbt,10,WALL_BANNER:3,../../NBT/viking_tannery_4.nbt,10,WALL_BANNER:3,../../NBT/viking_tannery_5.nbt,100)
RandomBlock(2,5,-7,WALL_BANNER:2,../../NBT/viking_tannery_1.nbt,10,WALL_BANNER:2,../../NBT/viking_tannery_2.nbt,10,WALL_BANNER:2,../../NBT/viking_tannery_3.nbt,10,WALL_BANNER:2,../../NBT/viking_tannery_4.nbt,10,WALL_BANNER:2,../../NBT/viking_tannery_5.nbt,100)
RandomBlock(2,5,4,WALL_BANNER:3,../../NBT/viking_tannery_1.nbt,10,WALL_BANNER:3,../../NBT/viking_tannery_2.nbt,10,WALL_BANNER:3,../../NBT/viking_tannery_3.nbt,10,WALL_BANNER:3,../../NBT/viking_tannery_4.nbt,10,WALL_BANNER:3,../../NBT/viking_tannery_5.nbt,100)
RandomBlock(5,5,-7,WALL_BANNER:2,../../NBT/viking_tannery_1.nbt,10,WALL_BANNER:2,../../NBT/viking_tannery_2.nbt,10,WALL_BANNER:2,../../NBT/viking_tannery_3.nbt,10,WALL_BANNER:2,../../NBT/viking_tannery_4.nbt,10,WALL_BANNER:2,../../NBT/viking_tannery_5.nbt,100)
RandomBlock(5,5,4,WALL_BANNER:3,../../NBT/viking_tannery_1.nbt,10,WALL_BANNER:3,../../NBT/viking_tannery_2.nbt,10,WALL_BANNER:3,../../NBT/viking_tannery_3.nbt,10,WALL_BANNER:3,../../NBT/viking_tannery_4.nbt,10,WALL_BANNER:3,../../NBT/viking_tannery_5.nbt,100)
RandomBlock(6,5,-6,WALL_BANNER:5,../../NBT/viking_tannery_1.nbt,10,WALL_BANNER:5,../../NBT/viking_tannery_2.nbt,10,WALL_BANNER:5,../../NBT/viking_tannery_3.nbt,10,WALL_BANNER:5,../../NBT/viking_tannery_4.nbt,10,WALL_BANNER:5,../../NBT/viking_tannery_5.nbt,100)
RandomBlock(6,5,-3,WALL_BANNER:5,../../NBT/viking_tannery_1.nbt,10,WALL_BANNER:5,../../NBT/viking_tannery_2.nbt,10,WALL_BANNER:5,../../NBT/viking_tannery_3.nbt,10,WALL_BANNER:5,../../NBT/viking_tannery_4.nbt,10,WALL_BANNER:5,../../NBT/viking_tannery_5.nbt,100)
RandomBlock(6,5,0,WALL_BANNER:5,../../NBT/viking_tannery_1.nbt,10,WALL_BANNER:5,../../NBT/viking_tannery_2.nbt,10,WALL_BANNER:5,../../NBT/viking_tannery_3.nbt,10,WALL_BANNER:5,../../NBT/viking_tannery_4.nbt,10,WALL_BANNER:5,../../NBT/viking_tannery_5.nbt,100)
RandomBlock(6,5,3,WALL_BANNER:5,../../NBT/viking_tannery_1.nbt,10,WALL_BANNER:5,../../NBT/viking_tannery_2.nbt,10,WALL_BANNER:5,../../NBT/viking_tannery_3.nbt,10,WALL_BANNER:5,../../NBT/viking_tannery_4.nbt,10,WALL_BANNER:5,../../NBT/viking_tannery_5.nbt,100)

