Author: NLBlackEagle
Description: No description given
SettingsMode: WriteDisable
Frequency: 0
SpawnHeight: highestBlock
UseCenterForHighestBlock: true
MinHeight: 0
MaxHeight: 255
InheritBO3: 
InheritBO3Rotation: NORTH
OverrideChildSettings: true
OverrideParentHeight: false
CanOverride: true
BranchFrequency: 0
BranchFrequencyGroup: 
MustBeBelowOther: false
MustBeInside: 
CannotBeInside: 
ReplacesBO3: 
MustBeInsideWorldBorders: false
CanSpawnOnWater: true
SpawnOnWaterOnly: false
SpawnUnderWater: false
SpawnAtWaterLevel: false
HeightOffset: 0
RemoveAir: false
ReplaceAbove: 
ReplaceBelow: 
ReplaceWithBiomeBlocks: true
ReplaceWithSurfaceBlock: GRASS
ReplaceWithGroundBlock: DIRT
ReplaceWithStoneBlock: STONE
SmoothRadius: 0
SmoothHeightOffset: 0
SmoothStartTop: false
SmoothStartWood: false
SmoothingSurfaceBlock: 
SmoothingGroundBlock: 
BO3Group: 
IsSpawnPoint: false
DoReplaceBlocks: false
Block(-7,750,9,AIR:0)
Block(-1,0,-6,LOG:1)
Block(-1,0,9,LOG:1)
Block(-1,1,-6,WOOD:5)
Block(-1,1,-5,WOOD:5)
Block(-1,1,-4,WOOD:5)
Block(-1,1,-3,WOOD:5)
Block(-1,1,-2,WOOD:5)
Block(-1,1,-1,WOOD:5)
Block(-1,1,0,WOOD:5)
Block(-1,1,1,WOOD:5)
Block(-1,1,2,WOOD:5)
Block(-1,1,3,WOOD:5)
Block(-1,1,4,WOOD:5)
Block(-1,1,5,WOOD:5)
Block(-1,1,6,WOOD:5)
Block(-1,1,7,WOOD:5)
Block(-1,1,8,WOOD:5)
Block(-1,1,9,WOOD:5)
Block(-1,2,-6,SPRUCE_FENCE:0)
RandomBlock(-1,2,-5,AIR:0,60,SKULL:1,../../../../Skulls/dungeon_skull_01.nbt,6,AIR,9,WEB,3,SKULL:1,../../../../Skulls/dungeon_skull_02.nbt,12,AIR,15,WEB,3,SKULL:1,../../../../Skulls/dungeon_skull_03.nbt,18,AIR:0,21,WEB:0,3,SKULL:1,../../../../Skulls/dungeon_skull_04.nbt,24,AIR:0,27,WEB:0,3,SKULL:1,../../../../Skulls/dungeon_skull_05.nbt,30,AIR:0,33,WEB:0,3,SKULL:1,../../../../Skulls/dungeon_skull_06.nbt,36,AIR:0,39,WEB:0,3,SKULL:1,../../../../Skulls/dungeon_skull_07.nbt,42,AIR:0,45,WEB:0,3,SKULL:1,../../../../Skulls/dungeon_skull_08.nbt,48,AIR:0,51,WEB:0,3,SKULL:1,../../../../Skulls/dungeon_skull_09.nbt,54,AIR:0,57,WEB:0,3,SKULL:1,../../../../Skulls/dungeon_skull_10.nbt,60,AIR:0,63,WEB:0,3,SKULL:1,../../../../Skulls/dungeon_skull_11.nbt,66,AIR:0,69,WEB:0,3,SKULL:1,../../../../Skulls/dungeon_skull_12.nbt,72,AIR:0,75,WEB:0,3,SKULL:1,../../../../Skulls/dungeon_skull_13.nbt,78,AIR:0,81,WEB:0,3,SKULL:1,../../../../Skulls/dungeon_skull_14.nbt,84,AIR:0,87,WEB:0,3,SKULL:1,../../../../Skulls/dungeon_skull_15.nbt,90,AIR:0,93,WEB:0,3,SKULL:1,../../../../Skulls/dungeon_skull_16.nbt,96,AIR:0,100)
Block(-1,2,-4,SIGN_POST:9,../../NBT/Signs/mine_danger_sign.nbt)
Block(-1,2,-3,SPRUCE_FENCE:0)
RandomBlock(-1,2,-2,FURNACE:5,../../../../Chests/Loot/furnace_W-Mineshafts_01.nbt,1,FURNACE:5,../../../../Chests/Loot/furnace_W-Mineshafts_02.nbt,1,FURNACE:5,../../../../Chests/Loot/furnace_W-Mineshafts_03.nbt,1,CRAFTING_TABLE:0,1,ANVIL:3,1,ANVIL:7,1,ANVIL:11,1,ANVIL:2,1,ANVIL:6,1,ANVIL:10,1,TNT:0,1,WEB:0,2,AIR:0,30,CHEST:5,../../../../Chests/Loot/abandoned_mineshaft.nbt,10,CHEST:5,../../../../Chests/Lore/Generic_5.nbt,2,CHEST:5,../../../../Chests/Lore/Generic_4.nbt,2,CHEST:5,../../../../Chests/Lore/Generic_3.nbt,2,CHEST:5,../../../../Chests/Lore/Generic_2.nbt,2,CHEST:5,../../../../Chests/Lore/Generic_1.nbt,2,CHEST:5,../../../../Chests/Lore/HiddenMine_1.nbt,1,CHEST:5,../../../../Chests/Lore/HiddenMine_2.nbt,1,CHEST:5,../../../../Chests/Lore/HiddenMine_3.nbt,1,CHEST:5,../../../../Chests/Lore/HiddenMine_4.nbt,1,CHEST:5,../../../../Chests/Lore/HiddenMine_5.nbt,1,CHEST:5,../../../../Chests/Loot/abandoned_mineshaft.nbt,100)
Block(-1,2,-1,WEB:0)
Block(-1,2,0,SPRUCE_FENCE:0)
Block(-1,2,1,LEVER:13)
Block(-1,2,2,WEB:0)
Block(-1,2,3,SPRUCE_FENCE:0)
RandomBlock(-1,2,4,FURNACE:5,../../../../Chests/Loot/furnace_W-Mineshafts_01.nbt,1,FURNACE:5,../../../../Chests/Loot/furnace_W-Mineshafts_02.nbt,1,FURNACE:5,../../../../Chests/Loot/furnace_W-Mineshafts_03.nbt,1,CRAFTING_TABLE:0,1,ANVIL:3,1,ANVIL:7,1,ANVIL:11,1,ANVIL:2,1,ANVIL:6,1,ANVIL:10,1,TNT:0,1,WEB:0,2,AIR:0,30,CHEST:5,../../../../Chests/Loot/abandoned_mineshaft.nbt,10,CHEST:5,../../../../Chests/Lore/Generic_5.nbt,2,CHEST:5,../../../../Chests/Lore/Generic_4.nbt,2,CHEST:5,../../../../Chests/Lore/Generic_3.nbt,2,CHEST:5,../../../../Chests/Lore/Generic_2.nbt,2,CHEST:5,../../../../Chests/Lore/Generic_1.nbt,2,CHEST:5,../../../../Chests/Lore/HiddenMine_1.nbt,1,CHEST:5,../../../../Chests/Lore/HiddenMine_2.nbt,1,CHEST:5,../../../../Chests/Lore/HiddenMine_3.nbt,1,CHEST:5,../../../../Chests/Lore/HiddenMine_4.nbt,1,CHEST:5,../../../../Chests/Lore/HiddenMine_5.nbt,1,CHEST:5,../../../../Chests/Loot/abandoned_mineshaft.nbt,100)
Block(-1,2,5,WEB:0)
Block(-1,2,6,SPRUCE_FENCE:0)
Block(-1,2,7,WEB:0)
Block(-1,2,8,WEB:0)
Block(-1,2,9,SPRUCE_FENCE:0)
Block(-1,3,-6,SPRUCE_FENCE:0)
Block(-1,3,-5,AIR:0)
Block(-1,3,-4,AIR:0)
Block(-1,3,-3,SPRUCE_FENCE:0)
Block(-1,3,-2,WEB:0)
Block(-1,3,-1,WEB:0)
Block(-1,3,0,SPRUCE_FENCE:0)
Block(-1,3,1,WEB:0)
Block(-1,3,2,WEB:0)
Block(-1,3,3,SPRUCE_FENCE:0)
Block(-1,3,4,WEB:0)
Block(-1,3,5,WEB:0)
Block(-1,3,6,SPRUCE_FENCE:0)
Block(-1,3,7,AIR:0)
Block(-1,3,8,AIR:0)
Block(-1,3,9,SPRUCE_FENCE:0)
Block(-1,4,-6,WOOD:1)
Block(-1,4,-5,AIR:0)
Block(-1,4,-4,AIR:0)
Block(-1,4,-3,WOOD:1)
Block(-1,4,-2,WEB:0)
Block(-1,4,-1,WEB:0)
Block(-1,4,0,WOOD:1)
Block(-1,4,1,WEB:0)
Block(-1,4,2,WEB:0)
Block(-1,4,3,WOOD:1)
Block(-1,4,4,AIR:0)
Block(-1,4,5,AIR:0)
Block(-1,4,6,WOOD:1)
Block(-1,4,7,AIR:0)
Block(-1,4,8,AIR:0)
Block(-1,4,9,WOOD:1)
Block(0,0,4,PISTON_BASE:1)
Block(0,1,-6,WOOD:5)
Block(0,1,-5,WOOD:5)
Block(0,1,-4,WOOD:5)
Block(0,1,-3,WOOD:5)
Block(0,1,-2,WOOD:5)
Block(0,1,-1,WOOD:5)
Block(0,1,0,WOOD:5)
Block(0,1,1,WOOD:5)
Block(0,1,2,WOOD:5)
Block(0,1,3,WOOD:5)
Block(0,1,4,WOOD:5)
Block(0,1,5,WOOD:5)
Block(0,1,6,WOOD:5)
Block(0,1,7,WOOD:5)
Block(0,1,8,WOOD:5)
Block(0,1,9,WOOD:5)
Block(0,2,-6,RAILS:0)
Block(0,2,-5,RAILS:0)
Block(0,2,-4,RAILS:0)
Block(0,2,-3,RAILS:0)
Block(0,2,-2,RAILS:0)
Block(0,2,-1,RAILS:0)
Block(0,2,0,RAILS:0)
Block(0,2,1,POWERED_RAIL:8)
Block(0,2,2,RAILS:0)
Block(0,2,3,RAILS:0)
RandomBlock(0,2,4,RAIL:0,50,RAIL:0,100)
Block(0,2,5,RAILS:0)
Block(0,2,6,RAILS:0)
Block(0,2,7,RAILS:0)
Block(0,2,8,RAILS:0)
Block(0,2,9,RAILS:0)
Block(0,3,-6,AIR:0)
Block(0,3,-5,AIR:0)
Block(0,3,-4,AIR:0)
Block(0,3,-3,WEB:0)
Block(0,3,-2,WEB:0)
Block(0,3,-1,WEB:0)
Block(0,3,0,WEB:0)
Block(0,3,1,WEB:0)
Block(0,3,2,WEB:0)
Block(0,3,3,WEB:0)
Block(0,3,4,WEB:0)
Block(0,3,5,WEB:0)
Block(0,3,6,WEB:0)
Block(0,3,7,AIR:0)
Block(0,3,8,AIR:0)
Block(0,3,9,AIR:0)
Block(0,4,-6,WOOD:1)
Block(0,4,-5,AIR:0)
Block(0,4,-4,AIR:0)
Block(0,4,-3,WOOD:1)
Block(0,4,-2,WEB:0)
Block(0,4,-1,WEB:0)
Block(0,4,0,WOOD:1)
Block(0,4,1,WEB:0)
Block(0,4,2,WEB:0)
Block(0,4,3,WOOD:1)
Block(0,4,4,WEB:0)
Block(0,4,5,WEB:0)
Block(0,4,6,WOOD:1)
Block(0,4,7,AIR:0)
Block(0,4,8,AIR:0)
Block(0,4,9,WOOD:1)
Block(1,1,-6,WOOD:5)
Block(1,1,-5,WOOD:5)
Block(1,1,-4,WOOD:5)
Block(1,1,-3,WOOD:5)
Block(1,1,-2,WOOD:5)
Block(1,1,-1,WOOD:5)
Block(1,1,0,WOOD:5)
Block(1,1,1,WOOD:5)
Block(1,1,2,WOOD:5)
Block(1,1,3,WOOD:5)
Block(1,1,4,WOOD:5)
Block(1,1,5,WOOD:5)
Block(1,1,6,WOOD:5)
Block(1,1,7,WOOD:5)
Block(1,1,8,WOOD:5)
Block(1,1,9,WOOD:5)
Block(1,2,-6,AIR:0)
Block(1,2,-5,WEB:0)
Block(1,2,-4,WEB:0)
Block(1,2,-3,WEB:0)
Block(1,2,-2,WEB:0)
Block(1,2,-1,WEB:0)
Block(1,2,0,WEB:0)
Block(1,2,1,WEB:0)
RandomBlock(1,2,2,MOB_SPAWNER:0,../../NBT/Mobs/funnel_spider.nbt,15,MOB_SPAWNER:0,../../NBT/Mobs/spiderling.nbt,15,MOB_SPAWNER:0,../../NBT/Mobs/tooth_spider.nbt,15,MOB_SPAWNER:0,../../NBT/Mobs/spider_swarm.nbt,15,MOB_SPAWNER:0,../../NBT/Mobs/cave_spider.nbt,100)
Block(1,2,3,WEB:0)
Block(1,2,4,WEB:0)
Block(1,2,5,WEB:0)
Block(1,2,6,WEB:0)
Block(1,2,7,SIGN_POST:2,../../NBT/Signs/mine_danger_sign.nbt)
RandomBlock(1,2,8,AIR:0,60,SKULL:1,../../../../Skulls/dungeon_skull_01.nbt,6,AIR,9,WEB,3,SKULL:1,../../../../Skulls/dungeon_skull_02.nbt,12,AIR,15,WEB,3,SKULL:1,../../../../Skulls/dungeon_skull_03.nbt,18,AIR:0,21,WEB:0,3,SKULL:1,../../../../Skulls/dungeon_skull_04.nbt,24,AIR:0,27,WEB:0,3,SKULL:1,../../../../Skulls/dungeon_skull_05.nbt,30,AIR:0,33,WEB:0,3,SKULL:1,../../../../Skulls/dungeon_skull_06.nbt,36,AIR:0,39,WEB:0,3,SKULL:1,../../../../Skulls/dungeon_skull_07.nbt,42,AIR:0,45,WEB:0,3,SKULL:1,../../../../Skulls/dungeon_skull_08.nbt,48,AIR:0,51,WEB:0,3,SKULL:1,../../../../Skulls/dungeon_skull_09.nbt,54,AIR:0,57,WEB:0,3,SKULL:1,../../../../Skulls/dungeon_skull_10.nbt,60,AIR:0,63,WEB:0,3,SKULL:1,../../../../Skulls/dungeon_skull_11.nbt,66,AIR:0,69,WEB:0,3,SKULL:1,../../../../Skulls/dungeon_skull_12.nbt,72,AIR:0,75,WEB:0,3,SKULL:1,../../../../Skulls/dungeon_skull_13.nbt,78,AIR:0,81,WEB:0,3,SKULL:1,../../../../Skulls/dungeon_skull_14.nbt,84,AIR:0,87,WEB:0,3,SKULL:1,../../../../Skulls/dungeon_skull_15.nbt,90,AIR:0,93,WEB:0,3,SKULL:1,../../../../Skulls/dungeon_skull_16.nbt,96,AIR:0,100)
Block(1,2,9,AIR:0)
Block(1,3,-6,AIR:0)
Block(1,3,-5,AIR:0)
Block(1,3,-4,WEB:0)
Block(1,3,-3,WEB:0)
Block(1,3,-2,WEB:0)
Block(1,3,-1,WEB:0)
Block(1,3,0,WEB:0)
Block(1,3,1,WEB:0)
Block(1,3,2,WEB:0)
Block(1,3,3,WEB:0)
Block(1,3,4,WEB:0)
Block(1,3,5,WEB:0)
Block(1,3,6,WEB:0)
Block(1,3,7,AIR:0)
Block(1,3,8,AIR:0)
Block(1,3,9,AIR:0)
Block(1,4,-6,WOOD:1)
Block(1,4,-5,AIR:0)
Block(1,4,-4,AIR:0)
Block(1,4,-3,WOOD:1)
Block(1,4,-2,WEB:0)
Block(1,4,-1,WEB:0)
Block(1,4,0,WOOD:1)
Block(1,4,1,WEB:0)
Block(1,4,2,WEB:0)
Block(1,4,3,WOOD:1)
Block(1,4,4,WEB:0)
Block(1,4,5,WEB:0)
Block(1,4,6,WOOD:1)
Block(1,4,7,AIR:0)
Block(1,4,8,AIR:0)
Block(1,4,9,WOOD:1)
Block(2,0,-6,LOG:1)
Block(2,0,9,LOG:1)
Block(2,1,-6,WOOD:5)
Block(2,1,-5,WOOD:5)
Block(2,1,-4,WOOD:5)
Block(2,1,-3,WOOD:5)
Block(2,1,-2,WOOD:5)
Block(2,1,-1,WOOD:5)
Block(2,1,0,WOOD:5)
Block(2,1,1,WOOD:5)
Block(2,1,2,WOOD:5)
Block(2,1,3,WOOD:5)
Block(2,1,4,WOOD:5)
Block(2,1,5,WOOD:5)
Block(2,1,6,WOOD:5)
Block(2,1,7,WOOD:5)
Block(2,1,8,WOOD:5)
Block(2,1,9,WOOD:5)
Block(2,2,-6,SPRUCE_FENCE:0)
Block(2,2,-5,AIR:0)
Block(2,2,-4,WEB:0)
Block(2,2,-3,SPRUCE_FENCE:0)
Block(2,2,-2,WEB:0)
RandomBlock(2,2,-1,FURNACE:4,../../../../Chests/Loot/furnace_W-Mineshafts_01.nbt,1,FURNACE:4,../../../../Chests/Loot/furnace_W-Mineshafts_02.nbt,1,FURNACE:4,../../../../Chests/Loot/furnace_W-Mineshafts_03.nbt,1,CRAFTING_TABLE:0,1,ANVIL:3,1,ANVIL:7,1,ANVIL:11,1,ANVIL:2,1,ANVIL:6,1,ANVIL:10,1,TNT:0,1,WEB:0,2,AIR:0,30,CHEST:4,../../../../Chests/Loot/abandoned_mineshaft.nbt,10,CHEST:4,../../../../Chests/Lore/Generic_5.nbt,2,CHEST:4,../../../../Chests/Lore/Generic_4.nbt,2,CHEST:4,../../../../Chests/Lore/Generic_3.nbt,2,CHEST:4,../../../../Chests/Lore/Generic_2.nbt,2,CHEST:4,../../../../Chests/Lore/Generic_1.nbt,2,CHEST:4,../../../../Chests/Lore/HiddenMine_1.nbt,1,CHEST:4,../../../../Chests/Lore/HiddenMine_2.nbt,1,CHEST:4,../../../../Chests/Lore/HiddenMine_3.nbt,1,CHEST:4,../../../../Chests/Lore/HiddenMine_4.nbt,1,CHEST:4,../../../../Chests/Lore/HiddenMine_5.nbt,1,CHEST:4,../../../../Chests/Loot/abandoned_mineshaft.nbt,100)
Block(2,2,0,SPRUCE_FENCE:0)
Block(2,2,1,WEB:0)
Block(2,2,2,WEB:0)
Block(2,2,3,SPRUCE_FENCE:0)
Block(2,2,4,WEB:0)
Block(2,2,5,WEB:0)
Block(2,2,6,SPRUCE_FENCE:0)
Block(2,2,7,AIR:0)
RandomBlock(2,2,8,FURNACE:4,../../../../Chests/Loot/furnace_W-Mineshafts_01.nbt,1,FURNACE:4,../../../../Chests/Loot/furnace_W-Mineshafts_02.nbt,1,FURNACE:4,../../../../Chests/Loot/furnace_W-Mineshafts_03.nbt,1,CRAFTING_TABLE:0,1,ANVIL:3,1,ANVIL:7,1,ANVIL:11,1,ANVIL:2,1,ANVIL:6,1,ANVIL:10,1,TNT:0,1,WEB:0,2,AIR:0,30,CHEST:4,../../../../Chests/Loot/abandoned_mineshaft.nbt,10,CHEST:4,../../../../Chests/Lore/Generic_5.nbt,2,CHEST:4,../../../../Chests/Lore/Generic_4.nbt,2,CHEST:4,../../../../Chests/Lore/Generic_3.nbt,2,CHEST:4,../../../../Chests/Lore/Generic_2.nbt,2,CHEST:4,../../../../Chests/Lore/Generic_1.nbt,2,CHEST:4,../../../../Chests/Lore/HiddenMine_1.nbt,1,CHEST:4,../../../../Chests/Lore/HiddenMine_2.nbt,1,CHEST:4,../../../../Chests/Lore/HiddenMine_3.nbt,1,CHEST:4,../../../../Chests/Lore/HiddenMine_4.nbt,1,CHEST:4,../../../../Chests/Lore/HiddenMine_5.nbt,1,CHEST:4,../../../../Chests/Loot/abandoned_mineshaft.nbt,100)
Block(2,2,9,SPRUCE_FENCE:0)
Block(2,3,-6,SPRUCE_FENCE:0)
Block(2,3,-5,AIR:0)
Block(2,3,-4,WEB:0)
Block(2,3,-3,SPRUCE_FENCE:0)
Block(2,3,-2,WEB:0)
Block(2,3,-1,WEB:0)
Block(2,3,0,SPRUCE_FENCE:0)
Block(2,3,1,WEB:0)
Block(2,3,2,WEB:0)
Block(2,3,3,SPRUCE_FENCE:0)
Block(2,3,4,WEB:0)
Block(2,3,5,WEB:0)
Block(2,3,6,SPRUCE_FENCE:0)
Block(2,3,7,AIR:0)
Block(2,3,8,AIR:0)
Block(2,3,9,SPRUCE_FENCE:0)
Block(2,4,-6,WOOD:1)
Block(2,4,-5,AIR:0)
Block(2,4,-4,AIR:0)
Block(2,4,-3,WOOD:1)
Block(2,4,-2,WEB:0)
Block(2,4,-1,WEB:0)
Block(2,4,0,WOOD:1)
Block(2,4,1,WEB:0)
Block(2,4,2,WEB:0)
Block(2,4,3,WOOD:1)
Block(2,4,4,WEB:0)
Block(2,4,5,WEB:0)
Block(2,4,6,WOOD:1)
Block(2,4,8,AIR:0)
Block(2,4,9,WOOD:1)
Block(8,750,-6,AIR:0)
Branch(0,0,-16,true,Mineshaft-Upper-Straigth-Empty-E,NORTH,100.0,0)
Branch(0,-7,0,true,Mineshaft-E-W-Foundation-Upper,WEST,100.0,0)
Entity(2,4,7,CHEST_MINECART,1,../../../../Chests/Loot/abandoned_mineshaft.txt)
BLOCK(1,4,7,AIR:0)
