Author: NLBlackEagle
Description: No description given
SettingsMode: WriteDisable
Frequency: 0
SpawnHeight: highestBlock
UseCenterForHighestBlock: true
MinHeight: 0
MaxHeight: 255
InheritBO3: 
InheritBO3Rotation: NORTH
OverrideChildSettings: true
OverrideParentHeight: false
CanOverride: false
BranchFrequency: 0
BranchFrequencyGroup: 
MustBeBelowOther: false
MustBeInside: 
CannotBeInside: 
ReplacesBO3: 
MustBeInsideWorldBorders: false
CanSpawnOnWater: true
SpawnOnWaterOnly: false
SpawnUnderWater: false
SpawnAtWaterLevel: false
HeightOffset: 0
RemoveAir: false
ReplaceAbove: 
ReplaceBelow: 
ReplaceWithBiomeBlocks: false
ReplaceWithSurfaceBlock: GRASS
ReplaceWithGroundBlock: DIRT
ReplaceWithStoneBlock: STONE
SmoothRadius: 0
SmoothHeightOffset: 0
SmoothStartTop: false
SmoothStartWood: false
SmoothingSurfaceBlock: 
SmoothingGroundBlock: 
BO3Group: 
IsSpawnPoint: false
DoReplaceBlocks: false
Block(-8,2,-7,LOG:13)
Block(-8,2,-6,LOG:13)
Block(-8,2,-5,LOG:13)
Block(-8,2,-4,LOG:13)
Block(-8,2,-3,LOG:13)
Block(-8,2,-2,LOG:13)
Block(-8,2,-1,LOG:13)
Block(-8,2,0,LOG:13)
Block(-8,2,1,LOG:13)
Block(-8,2,2,LOG:13)
Block(-8,2,3,LOG:13)
Block(-8,2,4,LOG:13)
Block(-8,2,5,LOG:13)
Block(-8,2,6,LOG:13)
Block(-8,2,7,LOG:13)
Block(-8,3,-7,LOG:13)
Block(-8,3,-6,REDSTONE_TORCH_ON:5)
Block(-8,3,-5,LOG:13)
Block(-8,3,-4,LOG:13)
Block(-8,3,-3,LOG:13)
Block(-8,3,-2,LOG:13)
Block(-8,3,-1,LOG:13)
Block(-8,3,0,LOG:13)
Block(-8,3,1,LOG:13)
Block(-8,3,2,LOG:13)
Block(-8,3,3,LOG:13)
Block(-8,3,4,LOG:13)
Block(-8,3,5,LOG:13)
Block(-8,3,6,LOG:13)
Block(-8,3,7,LOG:13)
Block(-8,3,8,LOG:13)
Block(-8,4,-7,TRAP_DOOR:12)
Block(-8,4,-6,REDSTONE_LAMP_ON:0)
Block(-8,4,-5,TRAP_DOOR:13)
Block(-8,4,-4,AIR:0)
Block(-8,4,-3,AIR:0)
Block(-8,4,-2,LOG:1)
Block(-8,4,-1,LADDER:3)
Block(-8,4,0,LOG:13)
Block(-8,4,1,HAY_BLOCK:0)
Block(-8,4,2,HAY_BLOCK:8)
Block(-8,4,3,AIR:0)
Block(-8,4,4,AIR:0)
Block(-8,4,5,AIR:0)
Block(-8,4,6,AIR:0)
Block(-8,4,7,LADDER:2)
Block(-8,4,8,LOG:1)
Block(-8,5,-7,AIR:0)
Block(-8,5,-6,LOG:0)
Block(-8,5,-5,AIR:0)
Block(-8,5,-4,AIR:0)
Block(-8,5,-3,AIR:0)
Block(-8,5,-2,LOG:1)
Block(-8,5,-1,LADDER:3)
Block(-8,5,0,LOG:13)
Block(-8,5,1,HAY_BLOCK:0)
Block(-8,5,2,AIR:0)
Block(-8,5,3,AIR:0)
Block(-8,5,4,AIR:0)
Block(-8,5,5,AIR:0)
Block(-8,5,6,AIR:0)
Block(-8,5,7,LADDER:2)
Block(-8,5,8,LOG:1)
Block(-8,6,-7,AIR:0)
Block(-8,6,-6,LOG:13)
Block(-8,6,-5,AIR:0)
Block(-8,6,-4,AIR:0)
Block(-8,6,-3,AIR:0)
Block(-8,6,-2,LOG:1)
Block(-8,6,-1,LADDER:3)
Block(-8,6,0,LOG:13)
Block(-8,6,1,HAY_BLOCK:0)
Block(-8,6,2,AIR:0)
Block(-8,6,3,AIR:0)
Block(-8,6,4,AIR:0)
Block(-8,6,5,AIR:0)
Block(-8,6,6,AIR:0)
Block(-8,6,7,LADDER:2)
Block(-8,6,8,LOG:1)
Block(-8,7,-7,AIR:0)
Block(-8,7,-6,LOG:13)
Block(-8,7,-5,AIR:0)
Block(-8,7,-4,AIR:0)
Block(-8,7,-3,AIR:0)
Block(-8,7,-2,LOG:1)
Block(-8,7,-1,LADDER:3)
Block(-8,7,0,LOG:13)
Block(-8,7,1,HAY_BLOCK:8)
Block(-8,7,2,AIR:0)
Block(-8,7,3,AIR:0)
Block(-8,7,4,AIR:0)
Block(-8,7,5,AIR:0)
Block(-8,7,6,AIR:0)
Block(-8,7,7,LADDER:2)
Block(-8,7,8,LOG:1)
Block(-8,8,-7,WOOD_STEP:9)
Block(-8,8,-6,WOOD_DOUBLE_STEP:1)
Block(-8,8,-5,WOOD_STEP:9)
Block(-8,8,-4,WOOD_STEP:9)
Block(-8,8,-3,WOOD_STEP:9)
Block(-8,8,-2,LOG:1)
Block(-8,8,-1,LADDER:3)
Block(-8,8,0,WOOD_DOUBLE_STEP:1)
Block(-8,8,1,WOOD_STEP:9)
Block(-8,8,2,WOOD_STEP:9)
Block(-8,8,3,WOOD_STEP:9)
Block(-8,8,4,WOOD_STEP:9)
Block(-8,8,5,WOOD_STEP:9)
Block(-8,8,6,WOOD_STEP:9)
Block(-8,8,7,LADDER:2)
Block(-8,8,8,LOG:1)
Block(-8,9,-6,SPRUCE_FENCE:0)
Block(-8,9,-5,WOOD_DOUBLE_STEP:1)
Block(-8,9,-4,WOOD_DOUBLE_STEP:1)
Block(-8,9,-3,WOOD_DOUBLE_STEP:1)
Block(-8,9,-2,LOG:1)
Block(-8,9,-1,TRAP_DOOR:1)
Block(-8,9,0,SPRUCE_FENCE:0)
Block(-8,9,2,CARPET:15)
Block(-8,9,3,SPRUCE_FENCE:0)
Block(-8,9,4,CARPET:15)
RandomBlock(-8,9,5,AIR:0,20,CHEST:5,../../../../Chests/Loot/ShipJunk_1.nbt,10,CHEST:5,../../../../Chests/Loot/ShipJunk_2.nbt,10,CHEST:5,../../../../Chests/Loot/ShipJunk_3.nbt,10,CHEST:5,../../../../Chests/Loot/ShipJunk_4.nbt,10,CHEST:5,../../../../Chests/Loot/ShipJunk_5.nbt,10,CHEST:5,../../../../Chests/Traveler/Travelers_Castle.nbt,1,CHEST:5,../../../../Chests/Traveler/Travelers_Church.nbt,1,CHEST:5,../../../../Chests/Traveler/Travelers_Daeroc.nbt,1,CHEST:5,../../../../Chests/Traveler/Travelers_Farmsteads.nbt,1,CHEST:5,../../../../Chests/Traveler/Travelers_GreenDungeon.nbt,1,CHEST:5,../../../../Chests/Traveler/Travelers_IceShips.nbt,1,CHEST:5,../../../../Chests/Traveler/Travelers_IceTemple.nbt,1,CHEST:5,../../../../Chests/Traveler/Travelers_LegacySpawn.nbt,1,CHEST:5,../../../../Chests/Traveler/Travelers_Mineshafts.nbt,1,CHEST:5,../../../../Chests/Traveler/Travelers_Mountains.nbt,1,CHEST:5,../../../../Chests/Traveler/Travelers_Origin.nbt,1,CHEST:5,../../../../Chests/Traveler/Travelers_Pirate.nbt,1,CHEST:5,../../../../Chests/Traveler/Travelers_Quarry.nbt,1,CHEST:5,../../../../Chests/Traveler/Travelers_Spook.nbt,1,CHEST:5,../../../../Chests/Traveler/Travelers_Tribal.nbt,1,CHEST:5,../../../../Chests/Lore/ShipFloat_1.nbt,1,CHEST:5,../../../../Chests/Lore/ShipFloat_2.nbt,1,CHEST:5,../../../../Chests/Lore/ShipFloat_3.nbt,1,CHEST:5,../../../../Chests/Lore/ShipFloat_4.nbt,1,CHEST:5,../../../../Chests/Lore/ShipFloat_5.nbt,1,CHEST:5,../../../../Chests/Loot/Common1.nbt,10,CHEST:5,../../../../Chests/Loot/Common2.nbt,10,CHEST:5,../../../../Chests/Loot/Common3.nbt,10,CHEST:5,../../../../Chests/Loot/Common4.nbt,10,CHEST:5,../../../../Chests/Loot/Common5.nbt,10,CHEST:5,../../../../Chests/Loot/Common6.nbt,10,CHEST:5,../../../../Chests/Loot/Common7.nbt,10,CHEST:5,../../../../Chests/Loot/Common8.nbt,10,CHEST:5,../../../../Chests/Loot/Common9.nbt,10,CHEST:5,../../../../Chests/Loot/Common10.nbt,10,CHEST:5,../../../../Chests/Loot/Common10.nbt,11,CHEST:5,../../../../Chests/Loot/Common12.nbt,10,CHEST:5,../../../../Chests/Loot/Common13.nbt,10,CHEST:5,../../../../Chests/Loot/Common14.nbt,10,CHEST:5,../../../../Chests/Loot/Common15.nbt,10,CHEST:5,../../../../Chests/Lore/ShipFloat_1.nbt,2,CHEST:5,../../../../Chests/Lore/ShipFloat_3.nbt,2,CHEST:5,../../../../Chests/Lore/ShipFloat_4.nbt,2,CHEST:5,../../../../Chests/Lore/ShipFloat_5.nbt,2,CHEST:5,../../../../Chests/Lore/ShipFloat_5.nbt,2,CHEST:5,../../../../Chests/Loot/Rare1.nbt,5,CHEST:5,../../../../Chests/Loot/Rare2.nbt,5,CHEST:5,../../../../Chests/Loot/Rare3.nbt,5,CHEST:5,../../../../Chests/Loot/Rare4.nbt,5,CHEST:5,../../../../Chests/Loot/Rare5.nbt,5,CHEST:5,../../../../Chests/Loot/Rare6.nbt,5,CHEST:5,../../../../Chests/Loot/Rare7.nbt,5,CHEST:5,../../../../Chests/Loot/Rare8.nbt,5,CHEST:5,../../../../Chests/Loot/Rare9.nbt,5,CHEST:5,../../../../Chests/Loot/Rare10.nbt,5,CHEST:5,../../../../Chests/Loot/Rare11.nbt,5,CHEST:5,../../../../Chests/Loot/Rare12.nbt,5,CHEST:5,../../../../Chests/Loot/Rare13.nbt,5,CHEST:5,../../../../Chests/Loot/Rare14.nbt,5,CHEST:5,../../../../Chests/Loot/Rare15.nbt,5,CHEST:5,../../../../Chests/Loot/Epic1.nbt,2,CHEST:5,../../../../Chests/Loot/Epic2.nbt,2,CHEST:5,../../../../Chests/Loot/Epic3.nbt,2,CHEST:5,../../../../Chests/Loot/Epic4.nbt,2,CHEST:5,../../../../Chests/Loot/Epic5.nbt,2,CHEST:5,../../../../Chests/Loot/Epic6.nbt,2,CHEST:5,../../../../Chests/Loot/Epic7.nbt,2,CHEST:5,../../../../Chests/Loot/Epic8.nbt,2,CHEST:5,../../../../Chests/Loot/Epic9.nbt,2,CHEST:5,../../../../Chests/Loot/Epic10.nbt,2,CHEST:5,../../../../Chests/Loot/Epic11.nbt,2,CHEST:5,../../../../Chests/Loot/Epic12.nbt,2,CHEST:5,../../../../Chests/Loot/Epic13.nbt,2,CHEST:5,../../../../Chests/Loot/Epic14.nbt,2,CHEST:5,../../../../Chests/Loot/Epic15.nbt,5,CHEST:5,../../../../Chests/Loot/Rare1.nbt,5,CHEST:5,../../../../Chests/Loot/Rare2.nbt,5,CHEST:5,../../../../Chests/Loot/Rare3.nbt,5,CHEST:5,../../../../Chests/Loot/Rare4.nbt,5,CHEST:5,../../../../Chests/Loot/Rare5.nbt,10,CHEST:5,../../../../Chests/Loot/Rare6.nbt,10,CHEST:5,../../../../Chests/Loot/Rare7.nbt,10,CHEST:5,../../../../Chests/Loot/Rare8.nbt,10,CHEST:5,../../../../Chests/Loot/Rare9.nbt,10,CHEST:5,../../../../Chests/Loot/Rare10.nbt,15,CHEST:5,../../../../Chests/Loot/Rare11.nbt,15,CHEST:5,../../../../Chests/Loot/Rare12.nbt,15,CHEST:5,../../../../Chests/Loot/Rare13.nbt,15,CHEST:5,../../../../Chests/Loot/Rare14.nbt,15,CHEST:5,../../../../Chests/Loot/Rare15.nbt,15,CHEST:5,../../../../Chests/Loot/Epic15.nbt,100)
Block(-8,9,6,SPRUCE_FENCE:0)
Block(-8,9,7,TRAP_DOOR:0)
Block(-8,9,8,LOG:1)
Block(-8,10,-7,BED_BLOCK:8)
Block(-8,10,-6,SPRUCE_FENCE:0)
Block(-8,10,-5,WOOD_DOUBLE_STEP:1)
Block(-8,10,-4,DARK_OAK_STAIRS:1)
Block(-8,10,-3,WOOD_DOUBLE_STEP:1)
Block(-8,10,-2,LOG:1)
Block(-8,10,0,SPRUCE_FENCE:0)
Block(-8,10,1,BED_BLOCK:0)
Block(-8,10,2,BED_BLOCK:8)
Block(-8,10,3,SPRUCE_FENCE:0)
Block(-8,10,4,BED_BLOCK:0)
Block(-8,10,5,BED_BLOCK:8)
Block(-8,10,6,SPRUCE_FENCE:0)
Block(-8,10,8,LOG:1)
Block(-8,11,-7,WOOD_STEP:9)
Block(-8,11,-6,WOOD_DOUBLE_STEP:1)
Block(-8,11,-5,WOOD_DOUBLE_STEP:1)
Block(-8,11,-4,TRAP_DOOR:13)
Block(-8,11,-3,WOOD_DOUBLE_STEP:1)
Block(-8,11,-2,LOG:1)
Block(-8,11,-1,WOOD_STEP:9)
Block(-8,11,0,WOOD_DOUBLE_STEP:1)
Block(-8,11,1,WOOD_STEP:9)
Block(-8,11,2,WOOD_STEP:9)
Block(-8,11,3,WOOD_DOUBLE_STEP:1)
Block(-8,11,4,WOOD_STEP:9)
Block(-8,11,5,WOOD_STEP:9)
Block(-8,11,6,WOOD_DOUBLE_STEP:1)
Block(-8,11,8,LOG:1)
Block(-8,12,-7,CARPET:15)
Block(-8,12,-6,CARPET:13)
Block(-8,12,-5,DARK_OAK_FENCE:0)
Block(-8,12,-3,DARK_OAK_FENCE:0)
Block(-8,12,-2,LOG:1)
Block(-8,12,-1,FENCE:0)
Block(-8,12,0,CARPET:15)
Block(-8,12,1,CARPET:13)
Block(-8,12,2,CARPET:15)
Block(-8,12,3,CARPET:15)
Block(-8,12,4,FENCE:0)
Block(-8,12,5,CARPET:13)
Block(-8,12,6,WOOD_STEP:1)
Block(-8,12,7,WOOD_STEP:1)
Block(-8,12,8,LOG:1)
Block(-8,13,-7,BED_BLOCK:0)
Block(-8,13,-6,BED_BLOCK:8)
Block(-8,13,-5,DARK_OAK_FENCE:0)
Block(-8,13,-2,LOG:1)
Block(-8,13,-1,TORCH:5)
Block(-8,13,3,AIR:0)
Block(-8,13,4,TORCH:5)
Block(-8,13,8,LOG:1)
Block(-8,14,-7,WOOD_STEP:9)
Block(-8,14,-6,WOOD_STEP:9)
Block(-8,14,-5,WOOD_DOUBLE_STEP:1)
Block(-8,14,-4,WOOD_STEP:9)
Block(-8,14,-3,WOOD_STEP:9)
Block(-8,14,-2,LOG:1)
Block(-8,14,-1,WOOD_STEP:9)
Block(-8,14,0,WOOD_DOUBLE_STEP:1)
Block(-8,14,1,WOOD_STEP:9)
Block(-8,14,2,WOOD_STEP:9)
Block(-8,14,3,WOOD_STEP:9)
Block(-8,14,4,WOOD_STEP:9)
Block(-8,14,5,WOOD_STEP:9)
Block(-8,14,6,WOOD_STEP:9)
Block(-8,14,8,LOG:1)
Block(-8,15,-7,STONE_BUTTON:1)
Block(-8,15,-6,STONE_BUTTON:1)
Block(-8,15,-5,STONE_BUTTON:1)
Block(-8,15,-3,LADDER:2)
Block(-8,15,-2,LOG:1)
Block(-8,15,-1,FENCE:0)
Block(-8,15,1,STONE_BUTTON:4)
Block(-8,15,2,WOOD:2)
Block(-8,15,3,WOOD:2)
Block(-8,15,4,WOOD:2)
Block(-8,15,5,WOOD:2)
Block(-8,15,6,WOOD:2)
Block(-8,15,7,WOOD_STEP:1)
Block(-8,15,8,LOG:1)
Block(-8,16,-3,LADDER:2)
Block(-8,16,-2,LOG:1)
Block(-8,16,-1,TORCH:5)
Block(-8,16,1,STONE_BUTTON:4)
Block(-8,16,2,WOOD:2)
Block(-8,16,3,WORKBENCH:0)
Block(-8,16,4,WOOD:2)
Block(-8,16,5,WOOD:2)
Block(-8,16,6,WOOD:2)
Block(-8,16,7,STONE_BUTTON:3)
Block(-8,16,8,LOG:1)
Block(-8,17,-3,LADDER:2)
Block(-8,17,-2,LOG:1)
Block(-8,17,0,WOOD_STEP:9)
RandomBlock(-8,17,2,AIR:0,20,CHEST:2,../../../../Chests/Loot/ShipJunk_1.nbt,10,CHEST:2,../../../../Chests/Loot/ShipJunk_2.nbt,10,CHEST:2,../../../../Chests/Loot/ShipJunk_3.nbt,10,CHEST:2,../../../../Chests/Loot/ShipJunk_4.nbt,10,CHEST:2,../../../../Chests/Loot/ShipJunk_5.nbt,10,CHEST:2,../../../../Chests/Traveler/Travelers_Castle.nbt,1,CHEST:2,../../../../Chests/Traveler/Travelers_Church.nbt,1,CHEST:2,../../../../Chests/Traveler/Travelers_Daeroc.nbt,1,CHEST:2,../../../../Chests/Traveler/Travelers_Farmsteads.nbt,1,CHEST:2,../../../../Chests/Traveler/Travelers_GreenDungeon.nbt,1,CHEST:2,../../../../Chests/Traveler/Travelers_IceShips.nbt,1,CHEST:2,../../../../Chests/Traveler/Travelers_IceTemple.nbt,1,CHEST:2,../../../../Chests/Traveler/Travelers_LegacySpawn.nbt,1,CHEST:2,../../../../Chests/Traveler/Travelers_Mineshafts.nbt,1,CHEST:2,../../../../Chests/Traveler/Travelers_Mountains.nbt,1,CHEST:2,../../../../Chests/Traveler/Travelers_Origin.nbt,1,CHEST:2,../../../../Chests/Traveler/Travelers_Pirate.nbt,1,CHEST:2,../../../../Chests/Traveler/Travelers_Quarry.nbt,1,CHEST:2,../../../../Chests/Traveler/Travelers_Spook.nbt,1,CHEST:2,../../../../Chests/Traveler/Travelers_Tribal.nbt,1,CHEST:2,../../../../Chests/Lore/ShipFloat_1.nbt,1,CHEST:2,../../../../Chests/Lore/ShipFloat_2.nbt,1,CHEST:2,../../../../Chests/Lore/ShipFloat_3.nbt,1,CHEST:2,../../../../Chests/Lore/ShipFloat_4.nbt,1,CHEST:2,../../../../Chests/Lore/ShipFloat_5.nbt,1,CHEST:2,../../../../Chests/Loot/Common1.nbt,10,CHEST:2,../../../../Chests/Loot/Common2.nbt,10,CHEST:2,../../../../Chests/Loot/Common3.nbt,10,CHEST:2,../../../../Chests/Loot/Common4.nbt,10,CHEST:2,../../../../Chests/Loot/Common5.nbt,10,CHEST:2,../../../../Chests/Loot/Common6.nbt,10,CHEST:2,../../../../Chests/Loot/Common7.nbt,10,CHEST:2,../../../../Chests/Loot/Common8.nbt,10,CHEST:2,../../../../Chests/Loot/Common9.nbt,10,CHEST:2,../../../../Chests/Loot/Common10.nbt,10,CHEST:2,../../../../Chests/Loot/Common10.nbt,11,CHEST:2,../../../../Chests/Loot/Common12.nbt,10,CHEST:2,../../../../Chests/Loot/Common13.nbt,10,CHEST:2,../../../../Chests/Loot/Common14.nbt,10,CHEST:2,../../../../Chests/Loot/Common15.nbt,10,CHEST:2,../../../../Chests/Lore/ShipFloat_1.nbt,2,CHEST:2,../../../../Chests/Lore/ShipFloat_3.nbt,2,CHEST:2,../../../../Chests/Lore/ShipFloat_4.nbt,2,CHEST:2,../../../../Chests/Lore/ShipFloat_5.nbt,2,CHEST:2,../../../../Chests/Lore/ShipFloat_5.nbt,2,CHEST:2,../../../../Chests/Loot/Rare1.nbt,5,CHEST:2,../../../../Chests/Loot/Rare2.nbt,5,CHEST:2,../../../../Chests/Loot/Rare3.nbt,5,CHEST:2,../../../../Chests/Loot/Rare4.nbt,5,CHEST:2,../../../../Chests/Loot/Rare5.nbt,5,CHEST:2,../../../../Chests/Loot/Rare6.nbt,5,CHEST:2,../../../../Chests/Loot/Rare7.nbt,5,CHEST:2,../../../../Chests/Loot/Rare8.nbt,5,CHEST:2,../../../../Chests/Loot/Rare9.nbt,5,CHEST:2,../../../../Chests/Loot/Rare10.nbt,5,CHEST:2,../../../../Chests/Loot/Rare11.nbt,5,CHEST:2,../../../../Chests/Loot/Rare12.nbt,5,CHEST:2,../../../../Chests/Loot/Rare13.nbt,5,CHEST:2,../../../../Chests/Loot/Rare14.nbt,5,CHEST:2,../../../../Chests/Loot/Rare15.nbt,5,CHEST:2,../../../../Chests/Loot/Epic1.nbt,2,CHEST:2,../../../../Chests/Loot/Epic2.nbt,2,CHEST:2,../../../../Chests/Loot/Epic3.nbt,2,CHEST:2,../../../../Chests/Loot/Epic4.nbt,2,CHEST:2,../../../../Chests/Loot/Epic5.nbt,2,CHEST:2,../../../../Chests/Loot/Epic6.nbt,2,CHEST:2,../../../../Chests/Loot/Epic7.nbt,2,CHEST:2,../../../../Chests/Loot/Epic8.nbt,2,CHEST:2,../../../../Chests/Loot/Epic9.nbt,2,CHEST:2,../../../../Chests/Loot/Epic10.nbt,2,CHEST:2,../../../../Chests/Loot/Epic11.nbt,2,CHEST:2,../../../../Chests/Loot/Epic12.nbt,2,CHEST:2,../../../../Chests/Loot/Epic13.nbt,2,CHEST:2,../../../../Chests/Loot/Epic14.nbt,2,CHEST:2,../../../../Chests/Loot/Epic15.nbt,5,CHEST:2,../../../../Chests/Loot/Rare1.nbt,5,CHEST:2,../../../../Chests/Loot/Rare2.nbt,5,CHEST:2,../../../../Chests/Loot/Rare3.nbt,5,CHEST:2,../../../../Chests/Loot/Rare4.nbt,5,CHEST:2,../../../../Chests/Loot/Rare5.nbt,10,CHEST:2,../../../../Chests/Loot/Rare6.nbt,10,CHEST:2,../../../../Chests/Loot/Rare7.nbt,10,CHEST:2,../../../../Chests/Loot/Rare8.nbt,10,CHEST:2,../../../../Chests/Loot/Rare9.nbt,10,CHEST:2,../../../../Chests/Loot/Rare10.nbt,15,CHEST:2,../../../../Chests/Loot/Rare11.nbt,15,CHEST:2,../../../../Chests/Loot/Rare12.nbt,15,CHEST:2,../../../../Chests/Loot/Rare13.nbt,15,CHEST:2,../../../../Chests/Loot/Rare14.nbt,15,CHEST:2,../../../../Chests/Loot/Rare15.nbt,15,CHEST:2,../../../../Chests/Loot/Epic15.nbt,100)
Block(-8,17,3,STONE_BUTTON:4)
Block(-8,17,4,WOOD:2)
Block(-8,17,5,WOOD:2)
Block(-8,17,6,WOOD:2)
Block(-8,17,7,STONE_BUTTON:3)
Block(-8,17,8,LOG:1)
Block(-8,18,-3,LADDER:2)
Block(-8,18,-2,LOG:1)
Block(-8,18,0,WOOD_STEP:5)
Block(-8,18,3,STONE_BUTTON:4)
Block(-8,18,4,WOOD:2)
Block(-8,18,5,WOOD:2)
Block(-8,18,8,LOG:1)
Block(-8,19,-3,LADDER:2)
Block(-8,19,-2,LOG:13)
Block(-8,19,4,STONE_BUTTON:5)
Block(-8,19,5,STONE_BUTTON:5)
Block(-8,19,8,LOG:1)
Block(-8,20,-6,WOOL:15)
Block(-8,20,-3,LADDER:2)
Block(-8,20,-2,LOG:1)
Block(-8,20,8,LOG:13)
Block(-8,21,-6,WOOL:11)
Block(-8,21,-3,LADDER:2)
Block(-8,21,-2,LOG:1)
Block(-8,21,8,LOG:1)
Block(-8,22,-7,WOOL:11)
Block(-8,22,-3,LADDER:2)
Block(-8,22,-2,LOG:1)
Block(-8,22,-1,FENCE:0)
Block(-8,22,0,FENCE:0)
Block(-8,22,1,FENCE:0)
Block(-8,22,8,LOG:1)
Block(-8,23,-7,WOOL:11)
Block(-8,23,-3,LADDER:2)
Block(-8,23,-2,LOG:1)
Block(-8,23,1,FENCE:0)
Block(-8,23,2,FENCE:0)
Block(-8,23,3,FENCE:0)
Block(-8,23,8,LOG:1)
Block(-8,24,-7,WOOL:15)
Block(-8,24,-3,LADDER:2)
Block(-8,24,-2,LOG:13)
Block(-8,24,3,FENCE:0)
Block(-8,24,4,FENCE:0)
Block(-8,24,5,FENCE:0)
Block(-8,24,8,LOG:1)
Block(-8,25,-7,WOOL:15)
Block(-8,25,-3,LADDER:2)
Block(-8,25,-2,LOG:1)
Block(-8,25,5,FENCE:0)
Block(-8,25,6,FENCE:0)
Block(-8,25,7,FENCE:0)
Block(-8,25,8,LOG:13)
Block(-8,26,-7,WOOL:15)
Block(-8,26,-3,LADDER:2)
Block(-8,26,-2,LOG:1)
Block(-8,26,8,LOG:1)
Block(-8,27,-6,WOOL:15)
Block(-8,27,-3,LADDER:2)
Block(-8,27,-2,LOG:1)
Block(-8,27,-1,FENCE:0)
Block(-8,27,8,LOG:1)
Block(-8,28,-6,WOOL:11)
Block(-8,28,-3,LADDER:2)
Block(-8,28,-2,LOG:1)
Block(-8,28,-1,TORCH:5)
Block(-8,28,8,LOG:1)
Block(-8,29,-6,WOOL:11)
Block(-8,29,-3,LADDER:2)
Block(-8,29,-2,LOG:13)
Block(-8,29,8,LOG:1)
Block(-8,30,-5,WOOL:15)
Block(-8,30,-3,LADDER:2)
Block(-8,30,-2,LOG:1)
Block(-8,30,8,LOG:13)
Block(-8,31,-3,LADDER:2)
Block(-8,31,-2,LOG:1)
Block(-8,31,8,LOG:1)
Block(-8,32,-7,FENCE:0)
Block(-8,32,-3,LADDER:2)
Block(-8,32,-2,LOG:1)
Block(-8,32,7,DARK_OAK_STAIRS:6)
Block(-8,32,8,LOG:1)
Block(-8,33,-7,FENCE:0)
Block(-8,33,-6,FENCE:0)
Block(-8,33,-5,FENCE:0)
Block(-8,33,-3,LOG:5)
Block(-8,33,-2,LOG:1)
Block(-8,33,7,FENCE:0)
Block(-8,33,8,LOG:1)
Block(-8,34,-5,FENCE:0)
Block(-8,34,-4,FENCE:0)
Block(-8,34,-3,FENCE:0)
Block(-8,34,-2,LOG:13)
Block(-8,34,8,LOG:1)
Block(-8,35,-2,LOG:1)
Block(-8,35,8,LOG:13)
Block(-8,36,-5,WOOL:11)
Block(-8,36,-3,DARK_OAK_STAIRS:6)
Block(-8,36,-2,LOG:1)
Block(-8,36,-1,DARK_OAK_STAIRS:7)
Block(-8,36,8,LOG:1)
Block(-8,37,-6,WOOL:11)
Block(-8,37,-3,FENCE:0)
Block(-8,37,-2,LOG:1)
Block(-8,37,-1,FENCE:0)
Block(-8,37,0,FENCE:0)
Block(-8,37,1,FENCE:0)
Block(-8,37,8,LOG:1)
Block(-8,38,-6,WOOL:15)
Block(-8,38,-2,LOG:1)
Block(-8,38,-1,FENCE:0)
Block(-8,38,1,FENCE:0)
Block(-8,38,2,FENCE:0)
Block(-8,38,3,FENCE:0)
Block(-8,38,8,LOG:1)
Block(-8,39,-6,WOOL:15)
Block(-8,39,-2,LOG:13)
Block(-8,39,3,FENCE:0)
Block(-8,39,4,FENCE:0)
Block(-8,39,5,FENCE:0)
Block(-8,39,8,LOG:1)
Block(-8,40,-5,WOOL:15)
Block(-8,40,-2,LOG:1)
Block(-8,40,5,FENCE:0)
Block(-8,40,6,FENCE:0)
Block(-8,40,7,FENCE:0)
Block(-8,40,8,LOG:13)
Block(-8,41,-5,WOOL:11)
Block(-8,41,-2,LOG:1)
Block(-8,41,-1,FENCE:0)
Block(-8,41,8,LOG:1)
Block(-8,42,-2,LOG:1)
Block(-8,42,-1,TORCH:5)
Block(-8,42,8,COBBLE_WALL:0)
Block(-8,43,-7,FENCE:0)
Block(-8,43,-3,LOG:5)
Block(-8,43,-2,LOG:1)
Block(-8,43,8,COBBLE_WALL:0)
Block(-8,44,-7,FENCE:0)
Block(-8,44,-6,FENCE:0)
Block(-8,44,-5,FENCE:0)
Block(-8,44,-2,LOG:13)
Block(-8,44,8,DARK_OAK_FENCE:0)
Block(-8,45,-5,FENCE:0)
Block(-8,45,-4,FENCE:0)
Block(-8,45,-3,FENCE:0)
Block(-8,45,-2,LOG:1)
Block(-8,45,8,DARK_OAK_FENCE:0)
Block(-8,46,-2,LOG:1)
Block(-8,46,8,DARK_OAK_FENCE:0)
Block(-8,47,-2,LOG:1)
RandomBlock(-8,47,8,STANDING_BANNER:9,../../Banners/royal_01.nbt,20,STANDING_BANNER:9,../../Banners/royal_02.nbt,20,STANDING_BANNER:9,../../Banners/royal_03.nbt,20,STANDING_BANNER:9,../../Banners/royal_04.nbt,20,STANDING_BANNER:9,../../Banners/royal_05.nbt,100)
Block(-8,48,-2,LOG:1)
Block(-8,49,-2,COBBLE_WALL:0)
Block(-8,50,-2,COBBLE_WALL:0)
Block(-8,51,-2,DARK_OAK_FENCE:0)
Block(-8,51,-1,WOOL:11)
Block(-8,52,-2,DARK_OAK_FENCE:0)
Block(-8,52,-1,WOOL:15)
Block(-8,53,-2,DARK_OAK_FENCE:0)
RandomBlock(-8,54,-2,STANDING_BANNER:9,../../Banners/royal_01.nbt,20,STANDING_BANNER:9,../../Banners/royal_02.nbt,20,STANDING_BANNER:9,../../Banners/royal_03.nbt,20,STANDING_BANNER:9,../../Banners/royal_04.nbt,20,STANDING_BANNER:9,../../Banners/royal_05.nbt,100)
Block(-7,3,-7,LOG:13)
Block(-7,3,-6,LOG:13)
Block(-7,3,-5,LOG:13)
Block(-7,3,-4,LOG:13)
Block(-7,3,-3,LOG:13)
Block(-7,3,-2,LOG:13)
Block(-7,3,-1,LOG:13)
Block(-7,3,0,LOG:13)
Block(-7,3,1,LOG:13)
Block(-7,3,2,LOG:13)
Block(-7,3,3,LOG:13)
Block(-7,3,4,LOG:13)
Block(-7,3,5,LOG:13)
Block(-7,3,6,LOG:13)
Block(-7,3,7,LOG:13)
Block(-7,3,8,LOG:13)
Block(-7,4,-7,LADDER:2)
Block(-7,4,-6,LOG:13)
Block(-7,4,-5,WOOD_STAIRS:0)
Block(-7,4,-4,AIR:0)
Block(-7,4,-3,AIR:0)
Block(-7,4,-2,AIR:0)
Block(-7,4,-1,AIR:0)
Block(-7,4,0,LOG:13)
Block(-7,4,1,HAY_BLOCK:0)
Block(-7,4,2,AIR:0)
Block(-7,4,3,AIR:0)
Block(-7,4,4,AIR:0)
Block(-7,4,5,AIR:0)
Block(-7,4,6,HAY_BLOCK:0)
Block(-7,4,7,HAY_BLOCK:4)
Block(-7,4,8,LOG:13)
Block(-7,5,-7,LADDER:2)
Block(-7,5,-6,LOG:13)
Block(-7,5,-5,AIR:0)
Block(-7,5,-4,AIR:0)
Block(-7,5,-3,AIR:0)
Block(-7,5,-2,AIR:0)
Block(-7,5,-1,AIR:0)
Block(-7,5,0,LOG:13)
Block(-7,5,1,AIR:0)
Block(-7,5,2,AIR:0)
Block(-7,5,3,AIR:0)
Block(-7,5,4,AIR:0)
Block(-7,5,5,AIR:0)
Block(-7,5,6,AIR:0)
Block(-7,5,7,AIR:0)
Block(-7,5,8,LOG:13)
Block(-7,6,-7,LADDER:2)
Block(-7,6,-6,LOG:13)
Block(-7,6,-5,AIR:0)
Block(-7,6,-4,AIR:0)
Block(-7,6,-3,AIR:0)
Block(-7,6,-2,AIR:0)
Block(-7,6,-1,AIR:0)
Block(-7,6,0,LOG:13)
Block(-7,6,1,AIR:0)
Block(-7,6,2,AIR:0)
Block(-7,6,3,AIR:0)
Block(-7,6,4,AIR:0)
Block(-7,6,5,AIR:0)
Block(-7,6,6,AIR:0)
Block(-7,6,7,AIR:0)
Block(-7,6,8,LOG:13)
Block(-7,7,-7,LADDER:2)
Block(-7,7,-6,LOG:13)
Block(-7,7,-5,AIR:0)
Block(-7,7,-4,AIR:0)
Block(-7,7,-3,AIR:0)
Block(-7,7,-2,AIR:0)
Block(-7,7,-1,AIR:0)
Block(-7,7,0,LOG:13)
Block(-7,7,1,AIR:0)
Block(-7,7,2,AIR:0)
Block(-7,7,3,AIR:0)
Block(-7,7,4,AIR:0)
Block(-7,7,5,AIR:0)
Block(-7,7,6,AIR:0)
Block(-7,7,7,AIR:0)
Block(-7,7,8,LOG:13)
Block(-7,8,-7,TRAP_DOOR:11)
Block(-7,8,-6,WOOD_DOUBLE_STEP:1)
Block(-7,8,-5,WOOD_STEP:9)
Block(-7,8,-4,WOOD_STEP:9)
Block(-7,8,-3,WOOD_STEP:9)
Block(-7,8,-2,WOOD_STEP:9)
Block(-7,8,-1,WOOD_STEP:9)
Block(-7,8,0,WOOD_DOUBLE_STEP:1)
Block(-7,8,1,TRAP_DOOR:11)
Block(-7,8,2,TRAP_DOOR:11)
Block(-7,8,3,TRAP_DOOR:11)
Block(-7,8,4,TRAP_DOOR:11)
Block(-7,8,5,WOOD_STEP:9)
Block(-7,8,6,WOOD_STEP:9)
Block(-7,8,7,WOOD_STEP:9)
Block(-7,8,8,WOOD:5)
Block(-7,9,-6,CARPET:12)
Block(-7,9,-5,WOOD_DOUBLE_STEP:1)
Block(-7,9,-4,DARK_OAK_STAIRS:1)
Block(-7,9,-3,WOOD_DOUBLE_STEP:1)
Block(-7,9,-2,WOOD_DOUBLE_STEP:1)
Block(-7,9,-1,CARPET:12)
Block(-7,9,5,CARPET:12)
Block(-7,9,6,WOOD_STEP:1)
Block(-7,9,7,WOOD_STEP:1)
Block(-7,9,8,WOOD_DOUBLE_STEP:1)
Block(-7,10,-5,WOOD_DOUBLE_STEP:1)
Block(-7,10,-3,WOOD_DOUBLE_STEP:1)
Block(-7,10,-2,TORCH:5)
Block(-7,10,8,TORCH:5)
Block(-7,11,-7,TRAP_DOOR:11)
Block(-7,11,-6,TRAP_DOOR:11)
Block(-7,11,-5,WOOD_DOUBLE_STEP:1)
Block(-7,11,-4,TRAP_DOOR:13)
Block(-7,11,-3,WOOD_DOUBLE_STEP:1)
Block(-7,11,-2,WOOD_STEP:9)
Block(-7,11,-1,WOOD_STEP:9)
Block(-7,11,0,WOOD_STEP:9)
Block(-7,11,1,WOOD_STEP:9)
Block(-7,11,2,WOOD_STEP:9)
Block(-7,11,3,WOOD_STEP:9)
Block(-7,11,4,WOOD_STEP:9)
Block(-7,11,5,WOOD_STEP:9)
Block(-7,11,6,WOOD_STEP:9)
Block(-7,12,-5,DARK_OAK_FENCE:0)
Block(-7,12,-3,DARK_OAK_FENCE:0)
Block(-7,12,-1,CARPET:15)
Block(-7,12,0,CARPET:15)
Block(-7,12,1,CARPET:12)
Block(-7,12,2,CARPET:15)
Block(-7,12,4,CARPET:13)
Block(-7,12,5,CARPET:15)
Block(-7,12,6,WOOD_STEP:1)
Block(-7,12,7,WOOD_STEP:1)
Block(-7,12,8,WOOD_DOUBLE_STEP:1)
Block(-7,13,8,CARPET:12)
Block(-7,14,-7,WOOD_STEP:9)
Block(-7,14,-6,WOOD_STEP:9)
Block(-7,14,-5,WOOD_STEP:9)
Block(-7,14,-4,WOOD_STEP:9)
Block(-7,14,-3,WOOD_STEP:9)
Block(-7,14,-2,WOOD_STEP:9)
Block(-7,14,-1,WOOD_STEP:9)
Block(-7,14,0,WOOD_DOUBLE_STEP:1)
Block(-7,14,1,WOOD_STEP:9)
Block(-7,14,2,WOOD_STEP:9)
Block(-7,14,3,TRAP_DOOR:11)
Block(-7,14,4,TRAP_DOOR:11)
Block(-7,14,5,TRAP_DOOR:11)
Block(-7,14,6,WOOD_STEP:9)
Block(-7,15,-7,STONE_BUTTON:2)
Block(-7,15,-6,STONE_BUTTON:2)
Block(-7,15,-5,STONE_BUTTON:2)
Block(-7,15,1,STONE_BUTTON:4)
Block(-7,15,2,WOOD:2)
Block(-7,15,3,WOOD:2)
Block(-7,15,4,STONE_BUTTON:1)
Block(-7,15,5,WOOD:2)
Block(-7,15,6,WOOD:2)
Block(-7,15,7,WOOD_STEP:1)
Block(-7,15,8,WOOD_STEP:1)
Block(-7,16,-7,STONE_BUTTON:2)
Block(-7,16,-6,STONE_BUTTON:2)
Block(-7,16,-5,STONE_BUTTON:2)
Block(-7,16,-4,AIR:0)
Block(-7,16,1,STONE_BUTTON:4)
Block(-7,16,2,WOOD:2)
Block(-7,16,3,WOOD:2)
Block(-7,16,4,STONE_BUTTON:1)
Block(-7,16,5,WOOD:2)
Block(-7,16,6,WOOD:2)
Block(-7,16,7,STONE_BUTTON:3)
Block(-7,17,-6,STONE_BUTTON:2)
Block(-7,17,-5,STONE_BUTTON:2)
Block(-7,17,0,SPRUCE_WOOD_STAIRS:4)
Block(-7,17,4,STONE_BUTTON:1)
Block(-7,17,5,WOOD:2)
Block(-7,17,6,WOOD:2)
Block(-7,17,7,STONE_BUTTON:3)
Block(-7,18,0,WOOD_STEP:5)
Block(-7,18,4,STONE_BUTTON:1)
Block(-7,18,5,STONE_BUTTON:1)
Block(-7,20,-6,WOOL:11)
Block(-7,21,-6,WOOL:11)
Block(-7,22,-6,WOOL:11)
Block(-7,23,-6,WOOL:11)
Block(-7,24,-7,WOOL:15)
Block(-7,24,6,WOOL:15)
Block(-7,25,-7,WOOL:15)
Block(-7,25,7,WOOL:15)
Block(-7,25,8,WOOL:11)
Block(-7,26,-6,WOOL:15)
Block(-7,26,8,FENCE:0)
Block(-7,27,-6,WOOL:15)
Block(-7,27,7,FENCE:0)
Block(-7,27,8,FENCE:0)
Block(-7,28,-6,WOOL:11)
Block(-7,28,7,WOOD:5)
Block(-7,28,8,FENCE:0)
Block(-7,29,-5,WOOL:11)
Block(-7,29,7,WOOD_STEP:1)
Block(-7,29,8,WOOD:5)
Block(-7,30,-5,WOOL:15)
Block(-7,30,8,WOOD_STEP:1)
Block(-7,31,-2,FENCE:0)
Block(-7,31,-1,FENCE:0)
Block(-7,32,-2,FENCE:0)
Block(-7,32,-1,FENCE:0)
Block(-7,32,7,DARK_OAK_STAIRS:5)
Block(-7,32,8,DARK_OAK_STAIRS:5)
Block(-7,33,-3,LOG:5)
Block(-7,33,-2,FENCE:0)
Block(-7,33,7,FENCE:0)
Block(-7,33,8,FENCE:0)
Block(-7,34,8,WOOL:15)
Block(-7,35,7,FENCE:0)
Block(-7,36,-5,WOOL:11)
Block(-7,36,-3,DARK_OAK_STAIRS:5)
Block(-7,36,-2,DARK_OAK_STAIRS:5)
Block(-7,36,-1,DARK_OAK_STAIRS:5)
Block(-7,36,7,WOOD:5)
Block(-7,37,-5,WOOL:11)
Block(-7,37,-3,FENCE:0)
Block(-7,37,-2,FENCE:0)
Block(-7,37,-1,FENCE:0)
Block(-7,37,7,WOOD_STEP:1)
Block(-7,37,8,WOOD:5)
Block(-7,38,-6,WOOL:15)
Block(-7,38,-3,FENCE:0)
Block(-7,38,-2,FENCE:0)
Block(-7,38,-1,FENCE:0)
Block(-7,38,8,WOOD_STEP:1)
Block(-7,39,-6,WOOL:15)
Block(-7,39,-3,FENCE:0)
Block(-7,39,-2,FENCE:0)
Block(-7,39,-1,FENCE:0)
Block(-7,40,-5,WOOL:15)
Block(-7,40,-3,FENCE:0)
Block(-7,40,-2,FENCE:0)
Block(-7,41,-4,WOOL:15)
Block(-7,41,-3,FENCE:0)
Block(-7,41,-2,FENCE:0)
Block(-7,42,-3,FENCE:0)
Block(-7,42,-2,FENCE:0)
Block(-7,43,-3,LOG:5)
Block(-7,51,0,WOOL:11)
Block(-7,51,1,WOOL:15)
Block(-7,51,2,WOOL:15)
Block(-7,52,0,WOOL:15)
Block(-7,52,1,WOOL:11)
Block(-7,52,2,WOOL:11)
Block(-6,3,-7,LOG:13)
Block(-6,3,-6,LOG:13)
Block(-6,3,-5,LOG:13)
Block(-6,3,-4,LOG:13)
Block(-6,3,-3,LOG:13)
Block(-6,3,-2,LOG:13)
Block(-6,3,-1,LOG:13)
Block(-6,3,0,LOG:13)
Block(-6,3,1,LOG:13)
Block(-6,3,2,LOG:13)
Block(-6,3,3,LOG:13)
Block(-6,3,4,LOG:13)
Block(-6,4,-7,STONE:1)
Block(-6,4,-6,LOG:13)
Block(-6,4,-5,LOG:13)
Block(-6,4,-4,LOG:13)
Block(-6,4,-3,LOG:13)
Block(-6,4,-2,LOG:13)
Block(-6,4,-1,LOG:13)
Block(-6,4,0,LOG:13)
Block(-6,4,1,HAY_BLOCK:0)
Block(-6,4,2,HAY_BLOCK:0)
Block(-6,4,3,HAY_BLOCK:8)
Block(-6,4,4,AIR:0)
Block(-6,4,5,LOG:13)
Block(-6,4,6,LOG:13)
Block(-6,4,7,LOG:13)
Block(-6,4,8,LOG:13)
Block(-6,5,-7,AIR:0)
Block(-6,5,-6,LOG:13)
Block(-6,5,-5,SPRUCE_DOOR:2)
Block(-6,5,-4,LOG:13)
Block(-6,5,-3,LOG:13)
Block(-6,5,-2,LOG:13)
Block(-6,5,-1,LOG:13)
Block(-6,5,0,LOG:13)
Block(-6,5,1,HAY_BLOCK:0)
Block(-6,5,2,AIR:0)
Block(-6,5,3,AIR:0)
Block(-6,5,4,AIR:0)
Block(-6,5,5,AIR:0)
Block(-6,5,6,AIR:0)
Block(-6,5,7,HAY_BLOCK:8)
Block(-6,5,8,LOG:13)
Block(-6,6,-7,AIR:0)
Block(-6,6,-6,LOG:13)
Block(-6,6,-5,SPRUCE_DOOR:8)
Block(-6,6,-4,LOG:13)
Block(-6,6,-3,LOG:13)
Block(-6,6,-2,LOG:13)
Block(-6,6,-1,LOG:13)
Block(-6,6,0,LOG:13)
Block(-6,6,1,AIR:0)
Block(-6,6,2,AIR:0)
Block(-6,6,3,AIR:0)
Block(-6,6,4,AIR:0)
Block(-6,6,5,AIR:0)
Block(-6,6,6,AIR:0)
Block(-6,6,7,AIR:0)
Block(-6,6,8,LOG:13)
Block(-6,7,-7,AIR:0)
Block(-6,7,-6,LOG:13)
Block(-6,7,-5,LOG:13)
Block(-6,7,-4,LOG:13)
Block(-6,7,-3,LOG:13)
Block(-6,7,-2,LOG:13)
Block(-6,7,-1,LOG:13)
Block(-6,7,0,LOG:13)
Block(-6,7,1,AIR:0)
Block(-6,7,2,AIR:0)
Block(-6,7,3,AIR:0)
Block(-6,7,4,AIR:0)
Block(-6,7,5,AIR:0)
Block(-6,7,6,AIR:0)
Block(-6,7,7,AIR:0)
Block(-6,7,8,LOG:13)
Block(-6,8,-7,WOOD_STEP:9)
Block(-6,8,-6,WOOD_DOUBLE_STEP:1)
Block(-6,8,-5,WOOD_DOUBLE_STEP:1)
Block(-6,8,-4,WOOD_DOUBLE_STEP:1)
Block(-6,8,-3,WOOD_DOUBLE_STEP:1)
Block(-6,8,-2,WOOD_DOUBLE_STEP:1)
Block(-6,8,-1,WOOD_DOUBLE_STEP:1)
Block(-6,8,0,WOOD_DOUBLE_STEP:1)
Block(-6,8,1,WOOD_STEP:9)
Block(-6,8,2,WOOD_STEP:9)
Block(-6,8,3,WOOD_STEP:9)
Block(-6,8,4,WOOD_STEP:9)
Block(-6,8,5,WOOD_STEP:9)
Block(-6,8,6,WOOD_STEP:9)
Block(-6,8,7,WOOD_STEP:9)
Block(-6,8,8,WOOD:5)
Block(-6,9,-6,WORKBENCH:0)
Block(-6,9,-5,WOOD_DOUBLE_STEP:1)
Block(-6,9,-3,WOOD_DOUBLE_STEP:1)
RandomBlock(-6,9,-2,AIR:0,20,CHEST:3,../../../../Chests/Loot/ShipJunk_1.nbt,10,CHEST:3,../../../../Chests/Loot/ShipJunk_2.nbt,10,CHEST:3,../../../../Chests/Loot/ShipJunk_3.nbt,10,CHEST:3,../../../../Chests/Loot/ShipJunk_4.nbt,10,CHEST:3,../../../../Chests/Loot/ShipJunk_5.nbt,10,CHEST:3,../../../../Chests/Traveler/Travelers_Castle.nbt,1,CHEST:3,../../../../Chests/Traveler/Travelers_Church.nbt,1,CHEST:3,../../../../Chests/Traveler/Travelers_Daeroc.nbt,1,CHEST:3,../../../../Chests/Traveler/Travelers_Farmsteads.nbt,1,CHEST:3,../../../../Chests/Traveler/Travelers_GreenDungeon.nbt,1,CHEST:3,../../../../Chests/Traveler/Travelers_IceShips.nbt,1,CHEST:3,../../../../Chests/Traveler/Travelers_IceTemple.nbt,1,CHEST:3,../../../../Chests/Traveler/Travelers_LegacySpawn.nbt,1,CHEST:3,../../../../Chests/Traveler/Travelers_Mineshafts.nbt,1,CHEST:3,../../../../Chests/Traveler/Travelers_Mountains.nbt,1,CHEST:3,../../../../Chests/Traveler/Travelers_Origin.nbt,1,CHEST:3,../../../../Chests/Traveler/Travelers_Pirate.nbt,1,CHEST:3,../../../../Chests/Traveler/Travelers_Quarry.nbt,1,CHEST:3,../../../../Chests/Traveler/Travelers_Spook.nbt,1,CHEST:3,../../../../Chests/Traveler/Travelers_Tribal.nbt,1,CHEST:3,../../../../Chests/Lore/ShipFloat_1.nbt,1,CHEST:3,../../../../Chests/Lore/ShipFloat_2.nbt,1,CHEST:3,../../../../Chests/Lore/ShipFloat_3.nbt,1,CHEST:3,../../../../Chests/Lore/ShipFloat_4.nbt,1,CHEST:3,../../../../Chests/Lore/ShipFloat_5.nbt,1,CHEST:3,../../../../Chests/Loot/Common1.nbt,10,CHEST:3,../../../../Chests/Loot/Common2.nbt,10,CHEST:3,../../../../Chests/Loot/Common3.nbt,10,CHEST:3,../../../../Chests/Loot/Common4.nbt,10,CHEST:3,../../../../Chests/Loot/Common5.nbt,10,CHEST:3,../../../../Chests/Loot/Common6.nbt,10,CHEST:3,../../../../Chests/Loot/Common7.nbt,10,CHEST:3,../../../../Chests/Loot/Common8.nbt,10,CHEST:3,../../../../Chests/Loot/Common9.nbt,10,CHEST:3,../../../../Chests/Loot/Common10.nbt,10,CHEST:3,../../../../Chests/Loot/Common10.nbt,11,CHEST:3,../../../../Chests/Loot/Common12.nbt,10,CHEST:3,../../../../Chests/Loot/Common13.nbt,10,CHEST:3,../../../../Chests/Loot/Common14.nbt,10,CHEST:3,../../../../Chests/Loot/Common15.nbt,10,CHEST:3,../../../../Chests/Lore/ShipFloat_1.nbt,2,CHEST:3,../../../../Chests/Lore/ShipFloat_3.nbt,2,CHEST:3,../../../../Chests/Lore/ShipFloat_4.nbt,2,CHEST:3,../../../../Chests/Lore/ShipFloat_5.nbt,2,CHEST:3,../../../../Chests/Lore/ShipFloat_5.nbt,2,CHEST:3,../../../../Chests/Loot/Rare1.nbt,5,CHEST:3,../../../../Chests/Loot/Rare2.nbt,5,CHEST:3,../../../../Chests/Loot/Rare3.nbt,5,CHEST:3,../../../../Chests/Loot/Rare4.nbt,5,CHEST:3,../../../../Chests/Loot/Rare5.nbt,5,CHEST:3,../../../../Chests/Loot/Rare6.nbt,5,CHEST:3,../../../../Chests/Loot/Rare7.nbt,5,CHEST:3,../../../../Chests/Loot/Rare8.nbt,5,CHEST:3,../../../../Chests/Loot/Rare9.nbt,5,CHEST:3,../../../../Chests/Loot/Rare10.nbt,5,CHEST:3,../../../../Chests/Loot/Rare11.nbt,5,CHEST:3,../../../../Chests/Loot/Rare12.nbt,5,CHEST:3,../../../../Chests/Loot/Rare13.nbt,5,CHEST:3,../../../../Chests/Loot/Rare14.nbt,5,CHEST:3,../../../../Chests/Loot/Rare15.nbt,5,CHEST:3,../../../../Chests/Loot/Epic1.nbt,2,CHEST:3,../../../../Chests/Loot/Epic2.nbt,2,CHEST:3,../../../../Chests/Loot/Epic3.nbt,2,CHEST:3,../../../../Chests/Loot/Epic4.nbt,2,CHEST:3,../../../../Chests/Loot/Epic5.nbt,2,CHEST:3,../../../../Chests/Loot/Epic6.nbt,2,CHEST:3,../../../../Chests/Loot/Epic7.nbt,2,CHEST:3,../../../../Chests/Loot/Epic8.nbt,2,CHEST:3,../../../../Chests/Loot/Epic9.nbt,2,CHEST:3,../../../../Chests/Loot/Epic10.nbt,2,CHEST:3,../../../../Chests/Loot/Epic11.nbt,2,CHEST:3,../../../../Chests/Loot/Epic12.nbt,2,CHEST:3,../../../../Chests/Loot/Epic13.nbt,2,CHEST:3,../../../../Chests/Loot/Epic14.nbt,2,CHEST:3,../../../../Chests/Loot/Epic15.nbt,5,CHEST:3,../../../../Chests/Loot/Rare1.nbt,5,CHEST:3,../../../../Chests/Loot/Rare2.nbt,5,CHEST:3,../../../../Chests/Loot/Rare3.nbt,5,CHEST:3,../../../../Chests/Loot/Rare4.nbt,5,CHEST:3,../../../../Chests/Loot/Rare5.nbt,10,CHEST:3,../../../../Chests/Loot/Rare6.nbt,10,CHEST:3,../../../../Chests/Loot/Rare7.nbt,10,CHEST:3,../../../../Chests/Loot/Rare8.nbt,10,CHEST:3,../../../../Chests/Loot/Rare9.nbt,10,CHEST:3,../../../../Chests/Loot/Rare10.nbt,15,CHEST:3,../../../../Chests/Loot/Rare11.nbt,15,CHEST:3,../../../../Chests/Loot/Rare12.nbt,15,CHEST:3,../../../../Chests/Loot/Rare13.nbt,15,CHEST:3,../../../../Chests/Loot/Rare14.nbt,15,CHEST:3,../../../../Chests/Loot/Rare15.nbt,15,CHEST:3,../../../../Chests/Loot/Epic15.nbt,100)
Block(-6,9,0,BED_BLOCK:0)
Block(-6,9,1,BED_BLOCK:8)
Block(-6,9,2,WOOD:2)
Block(-6,9,3,WOOD:2)
Block(-6,9,4,BED_BLOCK:10)
Block(-6,9,5,BED_BLOCK:2)
Block(-6,9,7,WOOD_STEP:1)
Block(-6,9,8,WOOD_STEP:1)
Block(-6,10,-5,WOOD_DOUBLE_STEP:1)
Block(-6,10,-3,WOOD_DOUBLE_STEP:1)
Block(-6,10,2,WOOD_BUTTON:5)
Block(-6,10,3,WOOD_BUTTON:5)
Block(-6,11,-7,WOOD_STEP:9)
Block(-6,11,-6,WOOD_STEP:9)
Block(-6,11,-5,WOOD_DOUBLE_STEP:1)
Block(-6,11,-4,TRAP_DOOR:10)
Block(-6,11,-3,WOOD_DOUBLE_STEP:1)
Block(-6,11,-2,WOOD_STEP:9)
Block(-6,11,-1,WOOD_STEP:9)
Block(-6,11,0,WOOD_STEP:9)
Block(-6,11,1,WOOD_STEP:9)
Block(-6,11,2,WOOD_STEP:9)
Block(-6,11,3,WOOD_STEP:9)
Block(-6,11,4,WOOD_STEP:9)
Block(-6,11,5,WOOD_STEP:9)
Block(-6,11,6,WOOD_STEP:9)
Block(-6,12,-7,CARPET:15)
Block(-6,12,-6,CARPET:15)
Block(-6,12,-5,DARK_OAK_FENCE:0)
Block(-6,12,-4,DARK_OAK_FENCE:0)
Block(-6,12,-3,DARK_OAK_FENCE:0)
Block(-6,12,-2,CARPET:15)
Block(-6,12,0,WOOD:0)
Block(-6,12,1,WOOD:0)
Block(-6,12,2,WOODEN_DOOR:2)
Block(-6,12,3,WOOD:0)
Block(-6,12,4,WOODEN_DOOR:2)
Block(-6,12,5,WOOD:0)
Block(-6,12,6,WOOD:0)
Block(-6,12,7,WOOD_STEP:1)
Block(-6,12,8,WOOD_DOUBLE_STEP:1)
Block(-6,13,0,WOOD:0)
Block(-6,13,1,WOOD:0)
Block(-6,13,2,WOODEN_DOOR:9)
Block(-6,13,3,WOOD:0)
Block(-6,13,4,WOODEN_DOOR:9)
Block(-6,13,5,WOOD:0)
Block(-6,13,6,WOOD:0)
Block(-6,13,8,CARPET:15)
Block(-6,14,-7,TRAP_DOOR:10)
Block(-6,14,-6,WOOD_STEP:9)
Block(-6,14,-5,TRAP_DOOR:10)
Block(-6,14,-4,WOOD_STEP:9)
Block(-6,14,-3,TRAP_DOOR:8)
Block(-6,14,-2,WOOD_STEP:9)
Block(-6,14,-1,TRAP_DOOR:8)
Block(-6,14,0,WOOD:0)
Block(-6,14,1,WOOD_DOUBLE_STEP:1)
Block(-6,14,2,WOOD_DOUBLE_STEP:1)
Block(-6,14,3,WOOD_DOUBLE_STEP:1)
Block(-6,14,4,WOOD_DOUBLE_STEP:1)
Block(-6,14,5,WOOD_DOUBLE_STEP:1)
Block(-6,14,6,WOOD_DOUBLE_STEP:1)
Block(-6,15,-7,WOOD:2)
Block(-6,15,-6,WOOD:2)
Block(-6,15,-5,WOOD:2)
Block(-6,15,-4,STONE_BUTTON:3)
RandomBlock(-6,15,-3,AIR:0,20,CHEST:4,../../../../Chests/Loot/ShipJunk_1.nbt,10,CHEST:4,../../../../Chests/Loot/ShipJunk_2.nbt,10,CHEST:4,../../../../Chests/Loot/ShipJunk_3.nbt,10,CHEST:4,../../../../Chests/Loot/ShipJunk_4.nbt,10,CHEST:4,../../../../Chests/Loot/ShipJunk_5.nbt,10,CHEST:4,../../../../Chests/Traveler/Travelers_Castle.nbt,1,CHEST:4,../../../../Chests/Traveler/Travelers_Church.nbt,1,CHEST:4,../../../../Chests/Traveler/Travelers_Daeroc.nbt,1,CHEST:4,../../../../Chests/Traveler/Travelers_Farmsteads.nbt,1,CHEST:4,../../../../Chests/Traveler/Travelers_GreenDungeon.nbt,1,CHEST:4,../../../../Chests/Traveler/Travelers_IceShips.nbt,1,CHEST:4,../../../../Chests/Traveler/Travelers_IceTemple.nbt,1,CHEST:4,../../../../Chests/Traveler/Travelers_LegacySpawn.nbt,1,CHEST:4,../../../../Chests/Traveler/Travelers_Mineshafts.nbt,1,CHEST:4,../../../../Chests/Traveler/Travelers_Mountains.nbt,1,CHEST:4,../../../../Chests/Traveler/Travelers_Origin.nbt,1,CHEST:4,../../../../Chests/Traveler/Travelers_Pirate.nbt,1,CHEST:4,../../../../Chests/Traveler/Travelers_Quarry.nbt,1,CHEST:4,../../../../Chests/Traveler/Travelers_Spook.nbt,1,CHEST:4,../../../../Chests/Traveler/Travelers_Tribal.nbt,1,CHEST:4,../../../../Chests/Lore/ShipFloat_1.nbt,1,CHEST:4,../../../../Chests/Lore/ShipFloat_2.nbt,1,CHEST:4,../../../../Chests/Lore/ShipFloat_3.nbt,1,CHEST:4,../../../../Chests/Lore/ShipFloat_4.nbt,1,CHEST:4,../../../../Chests/Lore/ShipFloat_5.nbt,1,CHEST:4,../../../../Chests/Loot/Common1.nbt,10,CHEST:4,../../../../Chests/Loot/Common2.nbt,10,CHEST:4,../../../../Chests/Loot/Common3.nbt,10,CHEST:4,../../../../Chests/Loot/Common4.nbt,10,CHEST:4,../../../../Chests/Loot/Common5.nbt,10,CHEST:4,../../../../Chests/Loot/Common6.nbt,10,CHEST:4,../../../../Chests/Loot/Common7.nbt,10,CHEST:4,../../../../Chests/Loot/Common8.nbt,10,CHEST:4,../../../../Chests/Loot/Common9.nbt,10,CHEST:4,../../../../Chests/Loot/Common10.nbt,10,CHEST:4,../../../../Chests/Loot/Common10.nbt,11,CHEST:4,../../../../Chests/Loot/Common12.nbt,10,CHEST:4,../../../../Chests/Loot/Common13.nbt,10,CHEST:4,../../../../Chests/Loot/Common14.nbt,10,CHEST:4,../../../../Chests/Loot/Common15.nbt,10,CHEST:4,../../../../Chests/Lore/ShipFloat_1.nbt,2,CHEST:4,../../../../Chests/Lore/ShipFloat_3.nbt,2,CHEST:4,../../../../Chests/Lore/ShipFloat_4.nbt,2,CHEST:4,../../../../Chests/Lore/ShipFloat_5.nbt,2,CHEST:4,../../../../Chests/Lore/ShipFloat_5.nbt,2,CHEST:4,../../../../Chests/Loot/Rare1.nbt,5,CHEST:4,../../../../Chests/Loot/Rare2.nbt,5,CHEST:4,../../../../Chests/Loot/Rare3.nbt,5,CHEST:4,../../../../Chests/Loot/Rare4.nbt,5,CHEST:4,../../../../Chests/Loot/Rare5.nbt,5,CHEST:4,../../../../Chests/Loot/Rare6.nbt,5,CHEST:4,../../../../Chests/Loot/Rare7.nbt,5,CHEST:4,../../../../Chests/Loot/Rare8.nbt,5,CHEST:4,../../../../Chests/Loot/Rare9.nbt,5,CHEST:4,../../../../Chests/Loot/Rare10.nbt,5,CHEST:4,../../../../Chests/Loot/Rare11.nbt,5,CHEST:4,../../../../Chests/Loot/Rare12.nbt,5,CHEST:4,../../../../Chests/Loot/Rare13.nbt,5,CHEST:4,../../../../Chests/Loot/Rare14.nbt,5,CHEST:4,../../../../Chests/Loot/Rare15.nbt,5,CHEST:4,../../../../Chests/Loot/Epic1.nbt,2,CHEST:4,../../../../Chests/Loot/Epic2.nbt,2,CHEST:4,../../../../Chests/Loot/Epic3.nbt,2,CHEST:4,../../../../Chests/Loot/Epic4.nbt,2,CHEST:4,../../../../Chests/Loot/Epic5.nbt,2,CHEST:4,../../../../Chests/Loot/Epic6.nbt,2,CHEST:4,../../../../Chests/Loot/Epic7.nbt,2,CHEST:4,../../../../Chests/Loot/Epic8.nbt,2,CHEST:4,../../../../Chests/Loot/Epic9.nbt,2,CHEST:4,../../../../Chests/Loot/Epic10.nbt,2,CHEST:4,../../../../Chests/Loot/Epic11.nbt,2,CHEST:4,../../../../Chests/Loot/Epic12.nbt,2,CHEST:4,../../../../Chests/Loot/Epic13.nbt,2,CHEST:4,../../../../Chests/Loot/Epic14.nbt,2,CHEST:4,../../../../Chests/Loot/Epic15.nbt,5,CHEST:4,../../../../Chests/Loot/Rare1.nbt,5,CHEST:4,../../../../Chests/Loot/Rare2.nbt,5,CHEST:4,../../../../Chests/Loot/Rare3.nbt,5,CHEST:4,../../../../Chests/Loot/Rare4.nbt,5,CHEST:4,../../../../Chests/Loot/Rare5.nbt,10,CHEST:4,../../../../Chests/Loot/Rare6.nbt,10,CHEST:4,../../../../Chests/Loot/Rare7.nbt,10,CHEST:4,../../../../Chests/Loot/Rare8.nbt,10,CHEST:4,../../../../Chests/Loot/Rare9.nbt,10,CHEST:4,../../../../Chests/Loot/Rare10.nbt,15,CHEST:4,../../../../Chests/Loot/Rare11.nbt,15,CHEST:4,../../../../Chests/Loot/Rare12.nbt,15,CHEST:4,../../../../Chests/Loot/Rare13.nbt,15,CHEST:4,../../../../Chests/Loot/Rare14.nbt,15,CHEST:4,../../../../Chests/Loot/Rare15.nbt,15,CHEST:4,../../../../Chests/Loot/Epic15.nbt,100)
RandomBlock(-6,15,-2,AIR:0,20,CHEST:4,../../../../Chests/Loot/ShipJunk_1.nbt,10,CHEST:4,../../../../Chests/Loot/ShipJunk_2.nbt,10,CHEST:4,../../../../Chests/Loot/ShipJunk_3.nbt,10,CHEST:4,../../../../Chests/Loot/ShipJunk_4.nbt,10,CHEST:4,../../../../Chests/Loot/ShipJunk_5.nbt,10,CHEST:4,../../../../Chests/Traveler/Travelers_Castle.nbt,1,CHEST:4,../../../../Chests/Traveler/Travelers_Church.nbt,1,CHEST:4,../../../../Chests/Traveler/Travelers_Daeroc.nbt,1,CHEST:4,../../../../Chests/Traveler/Travelers_Farmsteads.nbt,1,CHEST:4,../../../../Chests/Traveler/Travelers_GreenDungeon.nbt,1,CHEST:4,../../../../Chests/Traveler/Travelers_IceShips.nbt,1,CHEST:4,../../../../Chests/Traveler/Travelers_IceTemple.nbt,1,CHEST:4,../../../../Chests/Traveler/Travelers_LegacySpawn.nbt,1,CHEST:4,../../../../Chests/Traveler/Travelers_Mineshafts.nbt,1,CHEST:4,../../../../Chests/Traveler/Travelers_Mountains.nbt,1,CHEST:4,../../../../Chests/Traveler/Travelers_Origin.nbt,1,CHEST:4,../../../../Chests/Traveler/Travelers_Pirate.nbt,1,CHEST:4,../../../../Chests/Traveler/Travelers_Quarry.nbt,1,CHEST:4,../../../../Chests/Traveler/Travelers_Spook.nbt,1,CHEST:4,../../../../Chests/Traveler/Travelers_Tribal.nbt,1,CHEST:4,../../../../Chests/Lore/ShipFloat_1.nbt,1,CHEST:4,../../../../Chests/Lore/ShipFloat_2.nbt,1,CHEST:4,../../../../Chests/Lore/ShipFloat_3.nbt,1,CHEST:4,../../../../Chests/Lore/ShipFloat_4.nbt,1,CHEST:4,../../../../Chests/Lore/ShipFloat_5.nbt,1,CHEST:4,../../../../Chests/Loot/Common1.nbt,10,CHEST:4,../../../../Chests/Loot/Common2.nbt,10,CHEST:4,../../../../Chests/Loot/Common3.nbt,10,CHEST:4,../../../../Chests/Loot/Common4.nbt,10,CHEST:4,../../../../Chests/Loot/Common5.nbt,10,CHEST:4,../../../../Chests/Loot/Common6.nbt,10,CHEST:4,../../../../Chests/Loot/Common7.nbt,10,CHEST:4,../../../../Chests/Loot/Common8.nbt,10,CHEST:4,../../../../Chests/Loot/Common9.nbt,10,CHEST:4,../../../../Chests/Loot/Common10.nbt,10,CHEST:4,../../../../Chests/Loot/Common10.nbt,11,CHEST:4,../../../../Chests/Loot/Common12.nbt,10,CHEST:4,../../../../Chests/Loot/Common13.nbt,10,CHEST:4,../../../../Chests/Loot/Common14.nbt,10,CHEST:4,../../../../Chests/Loot/Common15.nbt,10,CHEST:4,../../../../Chests/Lore/ShipFloat_1.nbt,2,CHEST:4,../../../../Chests/Lore/ShipFloat_3.nbt,2,CHEST:4,../../../../Chests/Lore/ShipFloat_4.nbt,2,CHEST:4,../../../../Chests/Lore/ShipFloat_5.nbt,2,CHEST:4,../../../../Chests/Lore/ShipFloat_5.nbt,2,CHEST:4,../../../../Chests/Loot/Rare1.nbt,5,CHEST:4,../../../../Chests/Loot/Rare2.nbt,5,CHEST:4,../../../../Chests/Loot/Rare3.nbt,5,CHEST:4,../../../../Chests/Loot/Rare4.nbt,5,CHEST:4,../../../../Chests/Loot/Rare5.nbt,5,CHEST:4,../../../../Chests/Loot/Rare6.nbt,5,CHEST:4,../../../../Chests/Loot/Rare7.nbt,5,CHEST:4,../../../../Chests/Loot/Rare8.nbt,5,CHEST:4,../../../../Chests/Loot/Rare9.nbt,5,CHEST:4,../../../../Chests/Loot/Rare10.nbt,5,CHEST:4,../../../../Chests/Loot/Rare11.nbt,5,CHEST:4,../../../../Chests/Loot/Rare12.nbt,5,CHEST:4,../../../../Chests/Loot/Rare13.nbt,5,CHEST:4,../../../../Chests/Loot/Rare14.nbt,5,CHEST:4,../../../../Chests/Loot/Rare15.nbt,5,CHEST:4,../../../../Chests/Loot/Epic1.nbt,2,CHEST:4,../../../../Chests/Loot/Epic2.nbt,2,CHEST:4,../../../../Chests/Loot/Epic3.nbt,2,CHEST:4,../../../../Chests/Loot/Epic4.nbt,2,CHEST:4,../../../../Chests/Loot/Epic5.nbt,2,CHEST:4,../../../../Chests/Loot/Epic6.nbt,2,CHEST:4,../../../../Chests/Loot/Epic7.nbt,2,CHEST:4,../../../../Chests/Loot/Epic8.nbt,2,CHEST:4,../../../../Chests/Loot/Epic9.nbt,2,CHEST:4,../../../../Chests/Loot/Epic10.nbt,2,CHEST:4,../../../../Chests/Loot/Epic11.nbt,2,CHEST:4,../../../../Chests/Loot/Epic12.nbt,2,CHEST:4,../../../../Chests/Loot/Epic13.nbt,2,CHEST:4,../../../../Chests/Loot/Epic14.nbt,2,CHEST:4,../../../../Chests/Loot/Epic15.nbt,5,CHEST:4,../../../../Chests/Loot/Rare1.nbt,5,CHEST:4,../../../../Chests/Loot/Rare2.nbt,5,CHEST:4,../../../../Chests/Loot/Rare3.nbt,5,CHEST:4,../../../../Chests/Loot/Rare4.nbt,5,CHEST:4,../../../../Chests/Loot/Rare5.nbt,10,CHEST:4,../../../../Chests/Loot/Rare6.nbt,10,CHEST:4,../../../../Chests/Loot/Rare7.nbt,10,CHEST:4,../../../../Chests/Loot/Rare8.nbt,10,CHEST:4,../../../../Chests/Loot/Rare9.nbt,10,CHEST:4,../../../../Chests/Loot/Rare10.nbt,15,CHEST:4,../../../../Chests/Loot/Rare11.nbt,15,CHEST:4,../../../../Chests/Loot/Rare12.nbt,15,CHEST:4,../../../../Chests/Loot/Rare13.nbt,15,CHEST:4,../../../../Chests/Loot/Rare14.nbt,15,CHEST:4,../../../../Chests/Loot/Rare15.nbt,15,CHEST:4,../../../../Chests/Loot/Epic15.nbt,100)
Block(-6,15,0,WOOD:5)
Block(-6,15,1,STONE_BUTTON:2)
Block(-6,15,2,STONE_BUTTON:2)
Block(-6,15,3,STONE_BUTTON:2)
Block(-6,15,7,WOOD_STEP:1)
Block(-6,15,8,WOOD_STEP:1)
Block(-6,16,-7,WOOD:2)
Block(-6,16,-6,WOOD:2)
Block(-6,16,-5,WOOD:2)
Block(-6,16,-4,STONE_BUTTON:3)
Block(-6,16,0,WOOD:5)
Block(-6,16,5,STONE_BUTTON:1)
Block(-6,16,6,STONE_BUTTON:1)
Block(-6,17,-7,STONE_BUTTON:4)
Block(-6,17,-6,WOOD:2)
Block(-6,17,-5,WOOD:2)
Block(-6,17,-4,STONE_BUTTON:3)
Block(-6,17,0,WOOD:5)
Block(-6,17,5,STONE_BUTTON:1)
Block(-6,17,6,STONE_BUTTON:1)
Block(-6,18,-6,STONE_BUTTON:5)
Block(-6,18,-5,STONE_BUTTON:5)
Block(-6,18,0,WOOD_STEP:5)
Block(-6,19,-4,WOOL:15)
Block(-6,20,-5,WOOL:11)
Block(-6,21,-6,WOOL:11)
Block(-6,22,-6,WOOL:11)
Block(-6,23,-6,WOOL:11)
Block(-6,24,-6,WOOL:11)
Block(-6,24,3,WOOD:5)
Block(-6,24,4,FENCE:0)
Block(-6,24,5,WOOL:15)
Block(-6,24,8,FENCE:0)
Block(-6,25,-6,WOOL:15)
Block(-6,25,3,WOOD_STEP:1)
Block(-6,25,4,WOOD:5)
Block(-6,25,5,WOOL:11)
Block(-6,25,6,WOOL:11)
Block(-6,25,8,FENCE:0)
Block(-6,26,-6,WOOL:15)
Block(-6,26,4,WOOD_STEP:1)
Block(-6,26,5,WOOD:5)
Block(-6,26,6,FENCE:0)
Block(-6,26,7,WOOL:11)
Block(-6,26,8,WOOL:11)
Block(-6,27,-6,WOOL:15)
Block(-6,27,5,WOOD_STEP:1)
Block(-6,27,6,WOOD:5)
Block(-6,28,-5,WOOL:11)
Block(-6,28,6,WOOD_STEP:1)
Block(-6,28,7,WOOL:11)
Block(-6,29,-5,WOOL:11)
Block(-6,29,8,WOOL:11)
Block(-6,30,-5,WOOL:11)
Block(-6,30,-2,FENCE:0)
Block(-6,30,-1,FENCE:0)
Block(-6,31,-4,WOOL:15)
Block(-6,31,-2,FENCE:0)
Block(-6,31,-1,FENCE:0)
Block(-6,33,-2,LOG:5)
Block(-6,33,4,WOOD:5)
Block(-6,33,5,FENCE:0)
Block(-6,33,6,WOOL:15)
Block(-6,34,4,WOOD_STEP:1)
Block(-6,34,5,WOOD:5)
Block(-6,34,6,FENCE:0)
Block(-6,34,7,WOOL:11)
Block(-6,35,-4,WOOL:15)
Block(-6,35,5,WOOD_STEP:1)
Block(-6,35,6,WOOD:5)
Block(-6,35,8,WOOL:11)
Block(-6,36,-4,WOOL:11)
Block(-6,36,6,WOOD_STEP:1)
Block(-6,36,7,WOOL:15)
Block(-6,36,8,WOOL:11)
Block(-6,37,-5,WOOL:11)
Block(-6,37,8,WOOL:15)
Block(-6,38,-6,WOOL:15)
Block(-6,39,-5,WOOL:15)
Block(-6,40,-5,WOOL:11)
Block(-6,41,-4,WOOL:11)
Block(-6,42,-3,WOOL:15)
Block(-6,42,-2,FENCE:0)
Block(-6,43,-3,FENCE:0)
Block(-6,43,-2,LOG:5)
Block(-5,4,-7,LOG:13)
Block(-5,4,-6,LOG:13)
Block(-5,4,-5,LOG:13)
Block(-5,4,-4,LOG:13)
Block(-5,4,-3,LOG:13)
Block(-5,4,-2,LOG:13)
Block(-5,4,-1,LOG:13)
Block(-5,4,0,LOG:13)
Block(-5,4,1,LOG:13)
Block(-5,4,2,LOG:13)
Block(-5,4,3,LOG:13)
Block(-5,4,4,LOG:13)
Block(-5,4,5,LOG:13)
Block(-5,4,6,LOG:13)
Block(-5,4,7,LOG:13)
Block(-5,5,-7,STONE:1)
Block(-5,5,-6,LOG:13)
Block(-5,5,-5,AIR:0)
Block(-5,5,-4,IRON_FENCE:0)
Block(-5,5,-3,AIR:0)
Block(-5,5,-2,AIR:0)
Block(-5,5,-1,GOLD_ORE:0)
Block(-5,5,0,LOG:13)
Block(-5,5,1,HAY_BLOCK:4)
Block(-5,5,2,HAY_BLOCK:0)
Block(-5,5,3,HAY_BLOCK:0)
Block(-5,5,4,HAY_BLOCK:8)
Block(-5,5,5,AIR:0)
Block(-5,5,6,AIR:0)
Block(-5,5,7,HAY_BLOCK:4)
Block(-5,5,8,LOG:13)
Block(-5,6,-7,STONE:3)
Block(-5,6,-6,LOG:13)
Block(-5,6,-5,AIR:0)
Block(-5,6,-4,IRON_FENCE:0)
Block(-5,6,-3,AIR:0)
Block(-5,6,-2,AIR:0)
Block(-5,6,-1,AIR:0)
Block(-5,6,0,LOG:13)
Block(-5,6,1,AIR:0)
Block(-5,6,2,AIR:0)
Block(-5,6,3,HAY_BLOCK:0)
Block(-5,6,4,AIR:0)
Block(-5,6,5,AIR:0)
Block(-5,6,6,AIR:0)
Block(-5,6,7,AIR:0)
Block(-5,6,8,LOG:13)
Block(-5,7,-7,COAL_ORE:0)
Block(-5,7,-6,LOG:13)
Block(-5,7,-5,AIR:0)
Block(-5,7,-4,IRON_FENCE:0)
Block(-5,7,-3,AIR:0)
Block(-5,7,-2,AIR:0)
Block(-5,7,-1,AIR:0)
Block(-5,7,0,LOG:13)
Block(-5,7,1,AIR:0)
Block(-5,7,2,AIR:0)
Block(-5,7,3,AIR:0)
Block(-5,7,4,AIR:0)
Block(-5,7,5,AIR:0)
Block(-5,7,6,AIR:0)
Block(-5,7,7,AIR:0)
Block(-5,7,8,LOG:13)
Block(-5,8,-7,WOOD_STEP:9)
Block(-5,8,-6,WOOD_DOUBLE_STEP:1)
Block(-5,8,-5,WOOD_DOUBLE_STEP:1)
Block(-5,8,-4,WOOD_DOUBLE_STEP:1)
Block(-5,8,-3,WOOD_DOUBLE_STEP:1)
Block(-5,8,-2,WOOD_DOUBLE_STEP:1)
Block(-5,8,-1,WOOD_DOUBLE_STEP:1)
Block(-5,8,0,WOOD_DOUBLE_STEP:1)
Block(-5,8,1,WOOD_STEP:9)
Block(-5,8,2,WOOD_STEP:9)
Block(-5,8,3,WOOD_STEP:9)
Block(-5,8,4,WOOD_STEP:9)
Block(-5,8,5,WOOD_STEP:9)
Block(-5,8,6,WOOD_STEP:9)
Block(-5,8,7,WOOD_STEP:9)
Block(-5,8,8,WOOD:5)
Block(-5,9,-7,CARPET:12)
Block(-5,9,-6,CARPET:15)
Block(-5,9,-4,CARPET:13)
Block(-5,9,-1,CARPET:12)
Block(-5,9,0,CARPET:13)
Block(-5,9,2,CARPET:12)
Block(-5,9,3,CARPET:12)
Block(-5,9,4,CARPET:13)
Block(-5,9,5,CARPET:12)
Block(-5,9,6,CARPET:15)
Block(-5,9,7,WOOD_STEP:1)
Block(-5,9,8,WOOD_STEP:1)
Block(-5,11,-7,WOOD_STEP:9)
Block(-5,11,-6,WOOD_STEP:9)
Block(-5,11,-5,WOOD_STEP:9)
Block(-5,11,-4,WOOD_STEP:9)
Block(-5,11,-3,WOOD_DOUBLE_STEP:1)
Block(-5,11,-2,WOOD_STEP:9)
Block(-5,11,-1,WOOD_STEP:9)
Block(-5,11,0,WOOD_STEP:9)
Block(-5,11,1,WOOD_STEP:9)
Block(-5,11,2,WOOD_STEP:9)
Block(-5,11,3,WOOD_STEP:9)
Block(-5,11,4,WOOD_STEP:9)
Block(-5,11,5,WOOD_STEP:9)
Block(-5,11,6,WOOD_STEP:9)
Block(-5,12,-7,WOOD_STEP:1)
Block(-5,12,-3,WOOD_STEP:1)
Block(-5,12,0,WOOD:0)
Block(-5,12,1,WOOD:0)
Block(-5,12,3,WOOD:0)
Block(-5,12,4,CARPET:13)
Block(-5,12,5,WOOD:0)
Block(-5,12,6,WOOD:0)
Block(-5,12,7,WOOD_DOUBLE_STEP:1)
Block(-5,12,8,WOOD_DOUBLE_STEP:1)
Block(-5,13,-5,AIR:0)
Block(-5,13,0,WOOD:0)
Block(-5,13,1,WOOD:0)
Block(-5,13,3,WOOD:0)
Block(-5,13,5,WOOD:0)
Block(-5,13,6,WOOD:0)
Block(-5,13,7,WOOD:0)
Block(-5,13,8,WOOD:0)
Block(-5,14,-7,TRAP_DOOR:10)
Block(-5,14,-6,WOOD_STEP:9)
Block(-5,14,-5,TRAP_DOOR:10)
Block(-5,14,-4,WOOD_STEP:9)
Block(-5,14,-3,TRAP_DOOR:8)
Block(-5,14,-2,WOOD_STEP:9)
Block(-5,14,-1,TRAP_DOOR:8)
Block(-5,14,0,WOOD:0)
Block(-5,14,1,WOOD_DOUBLE_STEP:1)
Block(-5,14,2,WOOD_STEP:9)
Block(-5,14,3,WOOD_DOUBLE_STEP:1)
Block(-5,14,4,WOOD_STEP:9)
Block(-5,14,5,WOOD_DOUBLE_STEP:1)
Block(-5,14,6,WOOD_DOUBLE_STEP:1)
Block(-5,14,7,WOOD:0)
Block(-5,14,8,WOOD:0)
Block(-5,15,-7,WOOD:2)
Block(-5,15,-6,WOOD:2)
Block(-5,15,-5,WOOD:2)
Block(-5,15,-4,STONE_BUTTON:3)
Block(-5,15,-3,SPRUCE_FENCE:0)
Block(-5,15,-2,SPRUCE_FENCE:0)
Block(-5,15,0,WOOD:5)
Block(-5,15,1,WOOD:2)
Block(-5,15,2,WOOD:2)
Block(-5,15,3,WOOD:2)
Block(-5,15,4,WOOD_STEP:1)
Block(-5,15,5,WOOD_STEP:1)
Block(-5,15,6,WOOD_STEP:1)
Block(-5,15,7,WOOD_STEP:1)
Block(-5,15,8,WOOD_STEP:1)
Block(-5,16,-7,WOOD:2)
Block(-5,16,-6,WOOD:2)
Block(-5,16,-5,WOOD:2)
Block(-5,16,-4,STONE_BUTTON:3)
Block(-5,16,0,WOOD:5)
Block(-5,16,1,STONE_BUTTON:5)
Block(-5,16,2,STONE_BUTTON:5)
Block(-5,16,3,STONE_BUTTON:5)
Block(-5,17,-7,STONE_BUTTON:4)
Block(-5,17,-6,WOOD:2)
Block(-5,17,-5,WOOD:2)
Block(-5,17,-4,STONE_BUTTON:3)
Block(-5,17,0,WOOD:5)
Block(-5,17,7,AIR:0)
Block(-5,18,-6,STONE_BUTTON:5)
Block(-5,18,-5,STONE_BUTTON:5)
Block(-5,18,0,WOOD_STEP:5)
Block(-5,19,-4,WOOL:11)
Block(-5,20,-5,WOOL:11)
Block(-5,21,-5,WOOL:11)
Block(-5,22,-5,WOOL:11)
Block(-5,23,-6,WOOL:11)
Block(-5,23,8,FENCE:0)
Block(-5,24,-6,WOOL:11)
Block(-5,24,3,WOOL:15)
Block(-5,24,4,WOOL:15)
Block(-5,24,8,FENCE:0)
Block(-5,25,-6,WOOL:15)
Block(-5,25,4,WOOL:11)
Block(-5,26,-6,WOOL:15)
Block(-5,26,5,WOOL:11)
Block(-5,26,6,WOOL:11)
Block(-5,27,-5,WOOL:11)
Block(-5,27,6,WOOL:11)
Block(-5,27,7,WOOL:11)
Block(-5,27,8,WOOL:11)
Block(-5,28,-5,WOOL:11)
Block(-5,28,-2,FENCE:0)
Block(-5,28,-1,FENCE:0)
Block(-5,28,0,FENCE:0)
Block(-5,28,8,WOOL:11)
Block(-5,29,-5,WOOL:11)
Block(-5,29,-2,FENCE:0)
Block(-5,29,-1,FENCE:0)
Block(-5,29,0,FENCE:0)
Block(-5,30,-4,WOOL:11)
Block(-5,30,-2,FENCE:0)
Block(-5,30,-1,FENCE:0)
Block(-5,31,-4,WOOL:11)
Block(-5,33,-2,LOG:5)
Block(-5,33,4,WOOL:11)
Block(-5,33,5,WOOL:11)
Block(-5,34,5,WOOL:11)
Block(-5,34,6,WOOL:11)
Block(-5,35,-4,WOOL:11)
Block(-5,35,6,WOOL:11)
Block(-5,35,7,WOOL:11)
Block(-5,36,-4,WOOL:11)
Block(-5,37,-5,WOOL:11)
Block(-5,38,-5,WOOL:11)
Block(-5,39,-5,WOOL:11)
Block(-5,40,-4,WOOL:11)
Block(-5,41,-4,WOOL:11)
Block(-5,42,-3,WOOL:11)
Block(-5,42,-2,FENCE:0)
Block(-5,43,-3,FENCE:0)
Block(-5,43,-2,LOG:5)
Block(-4,4,-7,LOG:13)
Block(-4,4,-6,LOG:13)
Block(-4,4,-5,LOG:13)
Block(-4,4,-4,LOG:13)
Block(-4,4,-3,LOG:13)
Block(-4,4,-2,LOG:13)
Block(-4,4,-1,LOG:13)
Block(-4,4,0,LOG:13)
Block(-4,4,1,LOG:13)
Block(-4,4,2,LOG:13)
Block(-4,4,3,LOG:13)
Block(-4,5,-7,STONE:1)
Block(-4,5,-6,LOG:13)
Block(-4,5,-5,AIR:0)
Block(-4,5,-4,IRON_FENCE:0)
Block(-4,5,-3,AIR:0)
Block(-4,5,-2,GOLD_ORE:0)
Block(-4,5,-1,GOLD_ORE:0)
Block(-4,5,0,LOG:13)
Block(-4,5,1,HAY_BLOCK:4)
Block(-4,5,2,HAY_BLOCK:8)
Block(-4,5,3,HAY_BLOCK:4)
Block(-4,5,4,LOG:13)
Block(-4,5,5,LOG:13)
Block(-4,5,6,LOG:13)
Block(-4,5,7,LOG:13)
Block(-4,6,-7,STONE:1)
Block(-4,6,-6,LOG:13)
Block(-4,6,-5,AIR:0)
Block(-4,6,-4,IRON_FENCE:0)
Block(-4,6,-3,AIR:0)
Block(-4,6,-2,AIR:0)
Block(-4,6,-1,AIR:0)
Block(-4,6,0,LOG:13)
Block(-4,6,1,AIR:0)
Block(-4,6,2,HAY_BLOCK:0)
Block(-4,6,3,HAY_BLOCK:4)
Block(-4,6,4,HAY_BLOCK:0)
Block(-4,6,5,AIR:0)
Block(-4,6,6,HAY_BLOCK:0)
Block(-4,6,7,HAY_BLOCK:0)
Block(-4,6,8,LOG:13)
Block(-4,7,-7,LAPIS_ORE:0)
Block(-4,7,-6,LOG:13)
Block(-4,7,-5,AIR:0)
Block(-4,7,-4,IRON_FENCE:0)
Block(-4,7,-3,AIR:0)
Block(-4,7,-2,AIR:0)
Block(-4,7,-1,AIR:0)
Block(-4,7,0,LOG:13)
Block(-4,7,1,AIR:0)
Block(-4,7,2,AIR:0)
Block(-4,7,3,HAY_BLOCK:8)
Block(-4,7,4,HAY_BLOCK:4)
Block(-4,7,5,AIR:0)
Block(-4,7,6,HAY_BLOCK:4)
Block(-4,7,7,HAY_BLOCK:8)
Block(-4,7,8,LOG:13)
Block(-4,8,-7,WOOD_STEP:9)
Block(-4,8,-6,WOOD_DOUBLE_STEP:1)
Block(-4,8,-5,WOOD_DOUBLE_STEP:1)
Block(-4,8,-4,WOOD_DOUBLE_STEP:1)
Block(-4,8,-3,WOOD_DOUBLE_STEP:1)
Block(-4,8,-2,WOOD_DOUBLE_STEP:1)
Block(-4,8,-1,WOOD_DOUBLE_STEP:1)
Block(-4,8,0,WOOD_DOUBLE_STEP:1)
Block(-4,8,1,WOOD_STEP:9)
Block(-4,8,2,WOOD_STEP:9)
Block(-4,8,3,WOOD_STEP:9)
Block(-4,8,4,WOOD_STEP:9)
Block(-4,8,5,WOOD_STEP:9)
Block(-4,8,6,WOOD_STEP:9)
Block(-4,8,7,WOOD_STEP:9)
Block(-4,8,8,WOOD:5)
Block(-4,9,-7,SPRUCE_FENCE:0)
Block(-4,9,-3,CARPET:15)
Block(-4,9,-1,SPRUCE_FENCE:0)
Block(-4,9,0,BED_BLOCK:10)
Block(-4,9,1,BED_BLOCK:2)
Block(-4,9,2,SPRUCE_FENCE:0)
Block(-4,9,5,CARPET:12)
Block(-4,9,7,WOOD_STEP:1)
Block(-4,9,8,WOOD_STAIRS:0)
Block(-4,10,-7,SPRUCE_FENCE:0)
Block(-4,10,-6,AIR:0)
Block(-4,10,-1,SPRUCE_FENCE:0)
Block(-4,10,2,SPRUCE_FENCE:0)
Block(-4,11,-7,WOOD_DOUBLE_STEP:1)
Block(-4,11,-6,WOOD_STEP:9)
Block(-4,11,-5,WOOD_STEP:9)
Block(-4,11,-4,WOOD_STEP:9)
Block(-4,11,-3,WOOD_DOUBLE_STEP:1)
Block(-4,11,-2,WOOD_STEP:9)
Block(-4,11,-1,WOOD_DOUBLE_STEP:1)
Block(-4,11,0,WOOD_STEP:9)
Block(-4,11,1,WOOD_STEP:9)
Block(-4,11,2,WOOD_DOUBLE_STEP:1)
Block(-4,11,3,WOOD_STEP:9)
Block(-4,11,4,WOOD_STEP:9)
Block(-4,11,5,WOOD_STEP:9)
Block(-4,11,6,WOOD_STEP:9)
Block(-4,12,-7,RAILS:1)
Block(-4,12,-5,CARPET:15)
Block(-4,12,-3,RAILS:1)
Block(-4,12,-2,CARPET:13)
Block(-4,12,-1,CARPET:13)
Block(-4,12,0,WOOD:0)
Block(-4,12,1,BED_BLOCK:3)
Block(-4,12,2,CARPET:13)
Block(-4,12,3,BED_BLOCK:3)
Block(-4,12,4,CARPET:12)
Block(-4,12,5,BED_BLOCK:3)
Block(-4,12,6,WOOD:0)
Block(-4,12,7,WOOD_DOUBLE_STEP:1)
Block(-4,12,8,WOOD_DOUBLE_STEP:1)
Block(-4,13,0,WOOD:0)
Block(-4,13,1,BED_BLOCK:3)
Block(-4,13,3,BED_BLOCK:3)
Block(-4,13,5,BED_BLOCK:3)
Block(-4,13,6,WOOD:0)
Block(-4,13,7,WOOD_DOUBLE_STEP:1)
Block(-4,13,8,WOOD_DOUBLE_STEP:1)
Block(-4,14,-7,SPRUCE_WOOD_STAIRS:1)
Block(-4,14,-6,WOOD_STEP:1)
Block(-4,14,-5,SPRUCE_WOOD_STAIRS:1)
Block(-4,14,-4,WOOD_STEP:1)
Block(-4,14,-3,SPRUCE_WOOD_STAIRS:1)
Block(-4,14,-2,WOOD_STEP:1)
Block(-4,14,-1,SPRUCE_WOOD_STAIRS:1)
Block(-4,14,0,WOOD:0)
Block(-4,14,1,WOOD_STEP:9)
Block(-4,14,2,WOOD_STEP:9)
Block(-4,14,3,WOOD_STEP:9)
Block(-4,14,4,WOOD_STEP:9)
Block(-4,14,5,WOOD_STEP:9)
Block(-4,14,6,WOOD_DOUBLE_STEP:1)
Block(-4,14,7,WOOD_DOUBLE_STEP:1)
Block(-4,14,8,SPRUCE_WOOD_STAIRS:3)
Block(-4,15,-7,STONE_BUTTON:1)
Block(-4,15,-6,STONE_BUTTON:1)
Block(-4,15,-5,STONE_BUTTON:1)
Block(-4,15,0,WOOD:5)
Block(-4,15,1,WOOD:2)
Block(-4,15,2,WOOD:2)
Block(-4,15,3,WOOD:2)
Block(-4,15,4,WOOD:2)
Block(-4,15,5,WOOD:2)
Block(-4,15,6,CONCRETE:15)
Block(-4,15,7,WOOD_STEP:1)
Block(-4,16,-7,STONE_BUTTON:1)
Block(-4,16,-6,STONE_BUTTON:1)
Block(-4,16,-5,STONE_BUTTON:1)
Block(-4,16,0,WOOD:5)
Block(-4,16,1,STONE_BUTTON:5)
Block(-4,16,2,WOOD:2)
Block(-4,16,3,WOOD:2)
Block(-4,16,4,STONE_BUTTON:5)
Block(-4,16,5,STONE_BUTTON:5)
Block(-4,17,-6,STONE_BUTTON:1)
Block(-4,17,-5,STONE_BUTTON:1)
Block(-4,17,0,WOOD:5)
Block(-4,17,2,STONE_BUTTON:5)
Block(-4,17,3,STONE_BUTTON:5)
Block(-4,18,0,WOOD_STEP:5)
Block(-4,19,-4,WOOL:15)
Block(-4,20,-5,WOOL:11)
Block(-4,21,-5,WOOL:11)
Block(-4,21,8,FENCE:0)
Block(-4,22,-5,WOOL:11)
Block(-4,22,8,FENCE:0)
Block(-4,23,-5,WOOL:11)
Block(-4,23,8,FENCE:0)
Block(-4,24,-5,WOOL:11)
Block(-4,25,-6,WOOL:11)
Block(-4,25,-2,FENCE:0)
Block(-4,25,-1,FENCE:0)
Block(-4,25,0,FENCE:0)
Block(-4,25,1,FENCE:0)
Block(-4,26,-5,WOOL:11)
Block(-4,26,-2,FENCE:0)
Block(-4,26,-1,FENCE:0)
Block(-4,26,0,FENCE:0)
Block(-4,27,-5,WOOL:11)
Block(-4,27,-2,FENCE:0)
Block(-4,27,-1,FENCE:0)
Block(-4,27,0,FENCE:0)
Block(-4,28,-5,WOOL:11)
Block(-4,28,-2,FENCE:0)
Block(-4,28,-1,FENCE:0)
Block(-4,28,0,FENCE:0)
Block(-4,29,-4,WOOL:11)
Block(-4,30,-4,WOOL:11)
Block(-4,31,-4,WOOL:15)
Block(-4,33,-2,LOG:5)
Block(-4,35,-3,WOOL:15)
Block(-4,36,-4,WOOL:11)
Block(-4,37,-4,WOOL:11)
Block(-4,38,-5,WOOL:11)
Block(-4,39,-4,WOOL:11)
Block(-4,40,-4,WOOL:11)
Block(-4,41,-3,WOOL:11)
Block(-4,42,-2,WOOL:11)
Block(-4,43,-2,LOG:5)
Block(-3,5,-7,LOG:13)
Block(-3,5,-6,LOG:13)
Block(-3,5,-5,LOG:13)
Block(-3,5,-4,LOG:13)
Block(-3,5,-3,LOG:13)
Block(-3,5,-2,LOG:13)
Block(-3,5,-1,LOG:13)
Block(-3,5,0,LOG:13)
Block(-3,5,1,LOG:13)
Block(-3,5,2,LOG:13)
Block(-3,5,3,LOG:13)
Block(-3,5,4,LOG:13)
Block(-3,6,-7,STONE:1)
Block(-3,6,-6,LOG:13)
Block(-3,6,-5,AIR:0)
Block(-3,6,-4,LOG:0)
Block(-3,6,-3,AIR:0)
Block(-3,6,-2,GOLD_ORE:0)
Block(-3,6,-1,GOLD_ORE:0)
Block(-3,6,0,LOG:13)
Block(-3,6,1,LOG:13)
Block(-3,6,2,LOG:13)
Block(-3,6,3,LOG:13)
Block(-3,6,4,LOG:13)
Block(-3,6,5,LOG:13)
Block(-3,6,6,LOG:13)
Block(-3,6,7,LOG:13)
Block(-3,7,-7,STONE:3)
Block(-3,7,-6,LOG:13)
Block(-3,7,-5,AIR:0)
Block(-3,7,-4,LOG:0)
Block(-3,7,-3,AIR:0)
Block(-3,7,-2,AIR:0)
Block(-3,7,-1,GOLD_ORE:0)
Block(-3,7,0,LOG:13)
Block(-3,7,1,LOG:13)
Block(-3,7,2,LOG:13)
Block(-3,7,3,LOG:13)
Block(-3,7,4,LOG:13)
Block(-3,7,5,LOG:13)
Block(-3,7,6,LOG:13)
Block(-3,7,7,LOG:13)
Block(-3,7,8,LOG:13)
Block(-3,8,-7,WOOD_STEP:9)
Block(-3,8,-6,WOOD_DOUBLE_STEP:1)
Block(-3,8,-5,WOOD_DOUBLE_STEP:1)
Block(-3,8,-4,WOOD_DOUBLE_STEP:1)
Block(-3,8,-3,WOOD_DOUBLE_STEP:1)
Block(-3,8,-2,WOOD_DOUBLE_STEP:1)
Block(-3,8,-1,WOOD_DOUBLE_STEP:1)
Block(-3,8,0,WOOD_DOUBLE_STEP:1)
Block(-3,8,1,WOOD_DOUBLE_STEP:1)
Block(-3,8,2,WOOD_DOUBLE_STEP:1)
Block(-3,8,3,WOOD_DOUBLE_STEP:1)
Block(-3,8,4,WOOD_DOUBLE_STEP:1)
Block(-3,8,5,WOOD_DOUBLE_STEP:1)
Block(-3,8,6,WOOD_DOUBLE_STEP:1)
Block(-3,8,7,WOOD_DOUBLE_STEP:1)
Block(-3,8,8,WOOD:5)
Block(-3,9,-7,BED_BLOCK:3)
Block(-3,9,-5,WOOD_STAIRS:0)
Block(-3,9,-3,WOOD:0)
Block(-3,9,-2,WOOD_STAIRS:0)
Block(-3,9,0,CARPET:12)
Block(-3,9,3,WOOD_STAIRS:0)
RandomBlock(-3,9,5,AIR:0,20,CHEST:4,../../../../Chests/Loot/ShipJunk_1.nbt,10,CHEST:4,../../../../Chests/Loot/ShipJunk_2.nbt,10,CHEST:4,../../../../Chests/Loot/ShipJunk_3.nbt,10,CHEST:4,../../../../Chests/Loot/ShipJunk_4.nbt,10,CHEST:4,../../../../Chests/Loot/ShipJunk_5.nbt,10,CHEST:4,../../../../Chests/Traveler/Travelers_Castle.nbt,1,CHEST:4,../../../../Chests/Traveler/Travelers_Church.nbt,1,CHEST:4,../../../../Chests/Traveler/Travelers_Daeroc.nbt,1,CHEST:4,../../../../Chests/Traveler/Travelers_Farmsteads.nbt,1,CHEST:4,../../../../Chests/Traveler/Travelers_GreenDungeon.nbt,1,CHEST:4,../../../../Chests/Traveler/Travelers_IceShips.nbt,1,CHEST:4,../../../../Chests/Traveler/Travelers_IceTemple.nbt,1,CHEST:4,../../../../Chests/Traveler/Travelers_LegacySpawn.nbt,1,CHEST:4,../../../../Chests/Traveler/Travelers_Mineshafts.nbt,1,CHEST:4,../../../../Chests/Traveler/Travelers_Mountains.nbt,1,CHEST:4,../../../../Chests/Traveler/Travelers_Origin.nbt,1,CHEST:4,../../../../Chests/Traveler/Travelers_Pirate.nbt,1,CHEST:4,../../../../Chests/Traveler/Travelers_Quarry.nbt,1,CHEST:4,../../../../Chests/Traveler/Travelers_Spook.nbt,1,CHEST:4,../../../../Chests/Traveler/Travelers_Tribal.nbt,1,CHEST:4,../../../../Chests/Lore/ShipFloat_1.nbt,1,CHEST:4,../../../../Chests/Lore/ShipFloat_2.nbt,1,CHEST:4,../../../../Chests/Lore/ShipFloat_3.nbt,1,CHEST:4,../../../../Chests/Lore/ShipFloat_4.nbt,1,CHEST:4,../../../../Chests/Lore/ShipFloat_5.nbt,1,CHEST:4,../../../../Chests/Loot/Common1.nbt,10,CHEST:4,../../../../Chests/Loot/Common2.nbt,10,CHEST:4,../../../../Chests/Loot/Common3.nbt,10,CHEST:4,../../../../Chests/Loot/Common4.nbt,10,CHEST:4,../../../../Chests/Loot/Common5.nbt,10,CHEST:4,../../../../Chests/Loot/Common6.nbt,10,CHEST:4,../../../../Chests/Loot/Common7.nbt,10,CHEST:4,../../../../Chests/Loot/Common8.nbt,10,CHEST:4,../../../../Chests/Loot/Common9.nbt,10,CHEST:4,../../../../Chests/Loot/Common10.nbt,10,CHEST:4,../../../../Chests/Loot/Common10.nbt,11,CHEST:4,../../../../Chests/Loot/Common12.nbt,10,CHEST:4,../../../../Chests/Loot/Common13.nbt,10,CHEST:4,../../../../Chests/Loot/Common14.nbt,10,CHEST:4,../../../../Chests/Loot/Common15.nbt,10,CHEST:4,../../../../Chests/Lore/ShipFloat_1.nbt,2,CHEST:4,../../../../Chests/Lore/ShipFloat_3.nbt,2,CHEST:4,../../../../Chests/Lore/ShipFloat_4.nbt,2,CHEST:4,../../../../Chests/Lore/ShipFloat_5.nbt,2,CHEST:4,../../../../Chests/Lore/ShipFloat_5.nbt,2,CHEST:4,../../../../Chests/Loot/Rare1.nbt,5,CHEST:4,../../../../Chests/Loot/Rare2.nbt,5,CHEST:4,../../../../Chests/Loot/Rare3.nbt,5,CHEST:4,../../../../Chests/Loot/Rare4.nbt,5,CHEST:4,../../../../Chests/Loot/Rare5.nbt,5,CHEST:4,../../../../Chests/Loot/Rare6.nbt,5,CHEST:4,../../../../Chests/Loot/Rare7.nbt,5,CHEST:4,../../../../Chests/Loot/Rare8.nbt,5,CHEST:4,../../../../Chests/Loot/Rare9.nbt,5,CHEST:4,../../../../Chests/Loot/Rare10.nbt,5,CHEST:4,../../../../Chests/Loot/Rare11.nbt,5,CHEST:4,../../../../Chests/Loot/Rare12.nbt,5,CHEST:4,../../../../Chests/Loot/Rare13.nbt,5,CHEST:4,../../../../Chests/Loot/Rare14.nbt,5,CHEST:4,../../../../Chests/Loot/Rare15.nbt,5,CHEST:4,../../../../Chests/Loot/Epic1.nbt,2,CHEST:4,../../../../Chests/Loot/Epic2.nbt,2,CHEST:4,../../../../Chests/Loot/Epic3.nbt,2,CHEST:4,../../../../Chests/Loot/Epic4.nbt,2,CHEST:4,../../../../Chests/Loot/Epic5.nbt,2,CHEST:4,../../../../Chests/Loot/Epic6.nbt,2,CHEST:4,../../../../Chests/Loot/Epic7.nbt,2,CHEST:4,../../../../Chests/Loot/Epic8.nbt,2,CHEST:4,../../../../Chests/Loot/Epic9.nbt,2,CHEST:4,../../../../Chests/Loot/Epic10.nbt,2,CHEST:4,../../../../Chests/Loot/Epic11.nbt,2,CHEST:4,../../../../Chests/Loot/Epic12.nbt,2,CHEST:4,../../../../Chests/Loot/Epic13.nbt,2,CHEST:4,../../../../Chests/Loot/Epic14.nbt,2,CHEST:4,../../../../Chests/Loot/Epic15.nbt,5,CHEST:4,../../../../Chests/Loot/Rare1.nbt,5,CHEST:4,../../../../Chests/Loot/Rare2.nbt,5,CHEST:4,../../../../Chests/Loot/Rare3.nbt,5,CHEST:4,../../../../Chests/Loot/Rare4.nbt,5,CHEST:4,../../../../Chests/Loot/Rare5.nbt,10,CHEST:4,../../../../Chests/Loot/Rare6.nbt,10,CHEST:4,../../../../Chests/Loot/Rare7.nbt,10,CHEST:4,../../../../Chests/Loot/Rare8.nbt,10,CHEST:4,../../../../Chests/Loot/Rare9.nbt,10,CHEST:4,../../../../Chests/Loot/Rare10.nbt,15,CHEST:4,../../../../Chests/Loot/Rare11.nbt,15,CHEST:4,../../../../Chests/Loot/Rare12.nbt,15,CHEST:4,../../../../Chests/Loot/Rare13.nbt,15,CHEST:4,../../../../Chests/Loot/Rare14.nbt,15,CHEST:4,../../../../Chests/Loot/Rare15.nbt,15,CHEST:4,../../../../Chests/Loot/Epic15.nbt,100)
RandomBlock(-3,9,6,AIR:0,20,CHEST:4,../../../../Chests/Loot/ShipJunk_1.nbt,10,CHEST:4,../../../../Chests/Loot/ShipJunk_2.nbt,10,CHEST:4,../../../../Chests/Loot/ShipJunk_3.nbt,10,CHEST:4,../../../../Chests/Loot/ShipJunk_4.nbt,10,CHEST:4,../../../../Chests/Loot/ShipJunk_5.nbt,10,CHEST:4,../../../../Chests/Traveler/Travelers_Castle.nbt,1,CHEST:4,../../../../Chests/Traveler/Travelers_Church.nbt,1,CHEST:4,../../../../Chests/Traveler/Travelers_Daeroc.nbt,1,CHEST:4,../../../../Chests/Traveler/Travelers_Farmsteads.nbt,1,CHEST:4,../../../../Chests/Traveler/Travelers_GreenDungeon.nbt,1,CHEST:4,../../../../Chests/Traveler/Travelers_IceShips.nbt,1,CHEST:4,../../../../Chests/Traveler/Travelers_IceTemple.nbt,1,CHEST:4,../../../../Chests/Traveler/Travelers_LegacySpawn.nbt,1,CHEST:4,../../../../Chests/Traveler/Travelers_Mineshafts.nbt,1,CHEST:4,../../../../Chests/Traveler/Travelers_Mountains.nbt,1,CHEST:4,../../../../Chests/Traveler/Travelers_Origin.nbt,1,CHEST:4,../../../../Chests/Traveler/Travelers_Pirate.nbt,1,CHEST:4,../../../../Chests/Traveler/Travelers_Quarry.nbt,1,CHEST:4,../../../../Chests/Traveler/Travelers_Spook.nbt,1,CHEST:4,../../../../Chests/Traveler/Travelers_Tribal.nbt,1,CHEST:4,../../../../Chests/Lore/ShipFloat_1.nbt,1,CHEST:4,../../../../Chests/Lore/ShipFloat_2.nbt,1,CHEST:4,../../../../Chests/Lore/ShipFloat_3.nbt,1,CHEST:4,../../../../Chests/Lore/ShipFloat_4.nbt,1,CHEST:4,../../../../Chests/Lore/ShipFloat_5.nbt,1,CHEST:4,../../../../Chests/Loot/Common1.nbt,10,CHEST:4,../../../../Chests/Loot/Common2.nbt,10,CHEST:4,../../../../Chests/Loot/Common3.nbt,10,CHEST:4,../../../../Chests/Loot/Common4.nbt,10,CHEST:4,../../../../Chests/Loot/Common5.nbt,10,CHEST:4,../../../../Chests/Loot/Common6.nbt,10,CHEST:4,../../../../Chests/Loot/Common7.nbt,10,CHEST:4,../../../../Chests/Loot/Common8.nbt,10,CHEST:4,../../../../Chests/Loot/Common9.nbt,10,CHEST:4,../../../../Chests/Loot/Common10.nbt,10,CHEST:4,../../../../Chests/Loot/Common10.nbt,11,CHEST:4,../../../../Chests/Loot/Common12.nbt,10,CHEST:4,../../../../Chests/Loot/Common13.nbt,10,CHEST:4,../../../../Chests/Loot/Common14.nbt,10,CHEST:4,../../../../Chests/Loot/Common15.nbt,10,CHEST:4,../../../../Chests/Lore/ShipFloat_1.nbt,2,CHEST:4,../../../../Chests/Lore/ShipFloat_3.nbt,2,CHEST:4,../../../../Chests/Lore/ShipFloat_4.nbt,2,CHEST:4,../../../../Chests/Lore/ShipFloat_5.nbt,2,CHEST:4,../../../../Chests/Lore/ShipFloat_5.nbt,2,CHEST:4,../../../../Chests/Loot/Rare1.nbt,5,CHEST:4,../../../../Chests/Loot/Rare2.nbt,5,CHEST:4,../../../../Chests/Loot/Rare3.nbt,5,CHEST:4,../../../../Chests/Loot/Rare4.nbt,5,CHEST:4,../../../../Chests/Loot/Rare5.nbt,5,CHEST:4,../../../../Chests/Loot/Rare6.nbt,5,CHEST:4,../../../../Chests/Loot/Rare7.nbt,5,CHEST:4,../../../../Chests/Loot/Rare8.nbt,5,CHEST:4,../../../../Chests/Loot/Rare9.nbt,5,CHEST:4,../../../../Chests/Loot/Rare10.nbt,5,CHEST:4,../../../../Chests/Loot/Rare11.nbt,5,CHEST:4,../../../../Chests/Loot/Rare12.nbt,5,CHEST:4,../../../../Chests/Loot/Rare13.nbt,5,CHEST:4,../../../../Chests/Loot/Rare14.nbt,5,CHEST:4,../../../../Chests/Loot/Rare15.nbt,5,CHEST:4,../../../../Chests/Loot/Epic1.nbt,2,CHEST:4,../../../../Chests/Loot/Epic2.nbt,2,CHEST:4,../../../../Chests/Loot/Epic3.nbt,2,CHEST:4,../../../../Chests/Loot/Epic4.nbt,2,CHEST:4,../../../../Chests/Loot/Epic5.nbt,2,CHEST:4,../../../../Chests/Loot/Epic6.nbt,2,CHEST:4,../../../../Chests/Loot/Epic7.nbt,2,CHEST:4,../../../../Chests/Loot/Epic8.nbt,2,CHEST:4,../../../../Chests/Loot/Epic9.nbt,2,CHEST:4,../../../../Chests/Loot/Epic10.nbt,2,CHEST:4,../../../../Chests/Loot/Epic11.nbt,2,CHEST:4,../../../../Chests/Loot/Epic12.nbt,2,CHEST:4,../../../../Chests/Loot/Epic13.nbt,2,CHEST:4,../../../../Chests/Loot/Epic14.nbt,2,CHEST:4,../../../../Chests/Loot/Epic15.nbt,5,CHEST:4,../../../../Chests/Loot/Rare1.nbt,5,CHEST:4,../../../../Chests/Loot/Rare2.nbt,5,CHEST:4,../../../../Chests/Loot/Rare3.nbt,5,CHEST:4,../../../../Chests/Loot/Rare4.nbt,5,CHEST:4,../../../../Chests/Loot/Rare5.nbt,10,CHEST:4,../../../../Chests/Loot/Rare6.nbt,10,CHEST:4,../../../../Chests/Loot/Rare7.nbt,10,CHEST:4,../../../../Chests/Loot/Rare8.nbt,10,CHEST:4,../../../../Chests/Loot/Rare9.nbt,10,CHEST:4,../../../../Chests/Loot/Rare10.nbt,15,CHEST:4,../../../../Chests/Loot/Rare11.nbt,15,CHEST:4,../../../../Chests/Loot/Rare12.nbt,15,CHEST:4,../../../../Chests/Loot/Rare13.nbt,15,CHEST:4,../../../../Chests/Loot/Rare14.nbt,15,CHEST:4,../../../../Chests/Loot/Rare15.nbt,15,CHEST:4,../../../../Chests/Loot/Epic15.nbt,100)
Block(-3,9,7,WOOD_STEP:1)
Block(-3,9,8,DISPENSER:9)
Block(-3,10,-7,BED_BLOCK:3)
Block(-3,10,-3,WOOD:0)
Block(-3,10,-1,BED_BLOCK:3)
Block(-3,10,2,BED_BLOCK:3)
Block(-3,10,8,LEVER:14)
Block(-3,11,-7,WOOD_STEP:9)
Block(-3,11,-6,WOOD_STEP:9)
Block(-3,11,-5,WOOD_STEP:9)
Block(-3,11,-4,WOOD_STEP:9)
Block(-3,11,-3,WOOD_DOUBLE_STEP:1)
Block(-3,11,-2,WOOD_STEP:9)
Block(-3,11,-1,WOOD_STEP:9)
Block(-3,11,0,WOOD_STEP:9)
Block(-3,11,1,WOOD_STEP:9)
Block(-3,11,2,WOOD_STEP:9)
Block(-3,11,3,WOOD_STEP:9)
Block(-3,11,4,WOOD_STEP:9)
Block(-3,11,5,WOOD_STEP:9)
Block(-3,11,6,WOOD_STEP:9)
Block(-3,12,-7,WOOD_STAIRS:0)
Block(-3,12,-5,BED_BLOCK:3)
Block(-3,12,-3,WOOD_STAIRS:0)
Block(-3,12,-1,BED_BLOCK:3)
Block(-3,12,0,WOOD:0)
Block(-3,12,1,BED_BLOCK:11)
Block(-3,12,2,CARPET:13)
Block(-3,12,3,BED_BLOCK:11)
Block(-3,12,4,CARPET:12)
Block(-3,12,5,BED_BLOCK:11)
Block(-3,12,6,WOOD:0)
Block(-3,12,7,WOOD_DOUBLE_STEP:1)
Block(-3,12,8,WOOD_DOUBLE_STEP:1)
Block(-3,13,0,WOOD:0)
Block(-3,13,1,BED_BLOCK:11)
Block(-3,13,3,BED_BLOCK:11)
Block(-3,13,5,BED_BLOCK:11)
Block(-3,13,6,WOOD:0)
Block(-3,13,7,WOOD:0)
Block(-3,14,-7,WOOD:5)
Block(-3,14,-6,WOOD_STEP:1)
Block(-3,14,-5,WOOD:5)
Block(-3,14,-4,WOOD_STEP:1)
Block(-3,14,-3,WOOD:5)
Block(-3,14,-2,WOOD_STEP:1)
Block(-3,14,-1,WOOD:5)
Block(-3,14,0,WOOD:0)
Block(-3,14,1,WOOD_STEP:9)
Block(-3,14,2,WOOD_STEP:9)
Block(-3,14,3,WOOD_STEP:9)
Block(-3,14,4,WOOD_STEP:9)
Block(-3,14,5,WOOD_STEP:9)
Block(-3,14,6,WOOD_DOUBLE_STEP:1)
Block(-3,14,7,WOOD:0)
Block(-3,14,8,WOOD:0)
Block(-3,15,0,WOOD:5)
Block(-3,15,1,WOOD_STEP:1)
Block(-3,15,2,WOOD_STEP:1)
Block(-3,15,3,COAL_ORE:0)
Block(-3,15,4,COAL_ORE:0)
Block(-3,15,5,COAL_ORE:0)
Block(-3,15,6,COAL_ORE:0)
Block(-3,15,7,COAL_ORE:0)
Block(-3,15,8,WOOD:5)
Block(-3,16,0,WOOD:5)
Block(-3,16,2,STONE_BUTTON:1)
Block(-3,16,3,STONE_BUTTON:1)
Block(-3,16,4,CONCRETE:15)
Block(-3,16,6,CONCRETE:15)
Block(-3,16,8,WOOD:5)
Block(-3,17,0,WOOD:5)
RandomBlock(-3,17,4,AIR:0,20,CHEST:4,../../../../Chests/Loot/ShipJunk_1.nbt,10,CHEST:4,../../../../Chests/Loot/ShipJunk_2.nbt,10,CHEST:4,../../../../Chests/Loot/ShipJunk_3.nbt,10,CHEST:4,../../../../Chests/Loot/ShipJunk_4.nbt,10,CHEST:4,../../../../Chests/Loot/ShipJunk_5.nbt,10,CHEST:4,../../../../Chests/Traveler/Travelers_Castle.nbt,1,CHEST:4,../../../../Chests/Traveler/Travelers_Church.nbt,1,CHEST:4,../../../../Chests/Traveler/Travelers_Daeroc.nbt,1,CHEST:4,../../../../Chests/Traveler/Travelers_Farmsteads.nbt,1,CHEST:4,../../../../Chests/Traveler/Travelers_GreenDungeon.nbt,1,CHEST:4,../../../../Chests/Traveler/Travelers_IceShips.nbt,1,CHEST:4,../../../../Chests/Traveler/Travelers_IceTemple.nbt,1,CHEST:4,../../../../Chests/Traveler/Travelers_LegacySpawn.nbt,1,CHEST:4,../../../../Chests/Traveler/Travelers_Mineshafts.nbt,1,CHEST:4,../../../../Chests/Traveler/Travelers_Mountains.nbt,1,CHEST:4,../../../../Chests/Traveler/Travelers_Origin.nbt,1,CHEST:4,../../../../Chests/Traveler/Travelers_Pirate.nbt,1,CHEST:4,../../../../Chests/Traveler/Travelers_Quarry.nbt,1,CHEST:4,../../../../Chests/Traveler/Travelers_Spook.nbt,1,CHEST:4,../../../../Chests/Traveler/Travelers_Tribal.nbt,1,CHEST:4,../../../../Chests/Lore/ShipFloat_1.nbt,1,CHEST:4,../../../../Chests/Lore/ShipFloat_2.nbt,1,CHEST:4,../../../../Chests/Lore/ShipFloat_3.nbt,1,CHEST:4,../../../../Chests/Lore/ShipFloat_4.nbt,1,CHEST:4,../../../../Chests/Lore/ShipFloat_5.nbt,1,CHEST:4,../../../../Chests/Loot/Common1.nbt,10,CHEST:4,../../../../Chests/Loot/Common2.nbt,10,CHEST:4,../../../../Chests/Loot/Common3.nbt,10,CHEST:4,../../../../Chests/Loot/Common4.nbt,10,CHEST:4,../../../../Chests/Loot/Common5.nbt,10,CHEST:4,../../../../Chests/Loot/Common6.nbt,10,CHEST:4,../../../../Chests/Loot/Common7.nbt,10,CHEST:4,../../../../Chests/Loot/Common8.nbt,10,CHEST:4,../../../../Chests/Loot/Common9.nbt,10,CHEST:4,../../../../Chests/Loot/Common10.nbt,10,CHEST:4,../../../../Chests/Loot/Common10.nbt,11,CHEST:4,../../../../Chests/Loot/Common12.nbt,10,CHEST:4,../../../../Chests/Loot/Common13.nbt,10,CHEST:4,../../../../Chests/Loot/Common14.nbt,10,CHEST:4,../../../../Chests/Loot/Common15.nbt,10,CHEST:4,../../../../Chests/Lore/ShipFloat_1.nbt,2,CHEST:4,../../../../Chests/Lore/ShipFloat_3.nbt,2,CHEST:4,../../../../Chests/Lore/ShipFloat_4.nbt,2,CHEST:4,../../../../Chests/Lore/ShipFloat_5.nbt,2,CHEST:4,../../../../Chests/Lore/ShipFloat_5.nbt,2,CHEST:4,../../../../Chests/Loot/Rare1.nbt,5,CHEST:4,../../../../Chests/Loot/Rare2.nbt,5,CHEST:4,../../../../Chests/Loot/Rare3.nbt,5,CHEST:4,../../../../Chests/Loot/Rare4.nbt,5,CHEST:4,../../../../Chests/Loot/Rare5.nbt,5,CHEST:4,../../../../Chests/Loot/Rare6.nbt,5,CHEST:4,../../../../Chests/Loot/Rare7.nbt,5,CHEST:4,../../../../Chests/Loot/Rare8.nbt,5,CHEST:4,../../../../Chests/Loot/Rare9.nbt,5,CHEST:4,../../../../Chests/Loot/Rare10.nbt,5,CHEST:4,../../../../Chests/Loot/Rare11.nbt,5,CHEST:4,../../../../Chests/Loot/Rare12.nbt,5,CHEST:4,../../../../Chests/Loot/Rare13.nbt,5,CHEST:4,../../../../Chests/Loot/Rare14.nbt,5,CHEST:4,../../../../Chests/Loot/Rare15.nbt,5,CHEST:4,../../../../Chests/Loot/Epic1.nbt,2,CHEST:4,../../../../Chests/Loot/Epic2.nbt,2,CHEST:4,../../../../Chests/Loot/Epic3.nbt,2,CHEST:4,../../../../Chests/Loot/Epic4.nbt,2,CHEST:4,../../../../Chests/Loot/Epic5.nbt,2,CHEST:4,../../../../Chests/Loot/Epic6.nbt,2,CHEST:4,../../../../Chests/Loot/Epic7.nbt,2,CHEST:4,../../../../Chests/Loot/Epic8.nbt,2,CHEST:4,../../../../Chests/Loot/Epic9.nbt,2,CHEST:4,../../../../Chests/Loot/Epic10.nbt,2,CHEST:4,../../../../Chests/Loot/Epic11.nbt,2,CHEST:4,../../../../Chests/Loot/Epic12.nbt,2,CHEST:4,../../../../Chests/Loot/Epic13.nbt,2,CHEST:4,../../../../Chests/Loot/Epic14.nbt,2,CHEST:4,../../../../Chests/Loot/Epic15.nbt,5,CHEST:4,../../../../Chests/Loot/Rare1.nbt,5,CHEST:4,../../../../Chests/Loot/Rare2.nbt,5,CHEST:4,../../../../Chests/Loot/Rare3.nbt,5,CHEST:4,../../../../Chests/Loot/Rare4.nbt,5,CHEST:4,../../../../Chests/Loot/Rare5.nbt,10,CHEST:4,../../../../Chests/Loot/Rare6.nbt,10,CHEST:4,../../../../Chests/Loot/Rare7.nbt,10,CHEST:4,../../../../Chests/Loot/Rare8.nbt,10,CHEST:4,../../../../Chests/Loot/Rare9.nbt,10,CHEST:4,../../../../Chests/Loot/Rare10.nbt,15,CHEST:4,../../../../Chests/Loot/Rare11.nbt,15,CHEST:4,../../../../Chests/Loot/Rare12.nbt,15,CHEST:4,../../../../Chests/Loot/Rare13.nbt,15,CHEST:4,../../../../Chests/Loot/Rare14.nbt,15,CHEST:4,../../../../Chests/Loot/Rare15.nbt,15,CHEST:4,../../../../Chests/Loot/Epic15.nbt,100)
Block(-3,17,6,CONCRETE:15)
Block(-3,17,7,WOOD:5)
Block(-3,17,8,WOOD:5)
Block(-3,18,-3,WOOL:15)
Block(-3,18,0,WOOD_STEP:5)
Block(-3,18,7,WOOD_STEP:5)
Block(-3,18,8,WOOD_STEP:5)
Block(-3,19,-3,WOOL:11)
Block(-3,19,8,FENCE:0)
Block(-3,20,-4,WOOL:11)
Block(-3,20,8,FENCE:0)
Block(-3,21,-5,WOOL:11)
Block(-3,21,8,FENCE:0)
Block(-3,22,-5,WOOL:11)
Block(-3,22,-2,FENCE:0)
Block(-3,22,-1,FENCE:0)
Block(-3,22,0,FENCE:0)
Block(-3,22,1,FENCE:0)
Block(-3,22,2,FENCE:0)
Block(-3,23,-5,WOOL:11)
Block(-3,23,-2,FENCE:0)
Block(-3,23,-1,FENCE:0)
Block(-3,23,0,FENCE:0)
Block(-3,23,1,FENCE:0)
Block(-3,24,-5,WOOL:11)
Block(-3,24,-2,FENCE:0)
Block(-3,24,-1,FENCE:0)
Block(-3,24,0,FENCE:0)
Block(-3,24,1,FENCE:0)
Block(-3,25,-5,WOOL:11)
Block(-3,25,-2,FENCE:0)
Block(-3,25,-1,FENCE:0)
Block(-3,25,0,FENCE:0)
Block(-3,25,1,FENCE:0)
Block(-3,26,-5,WOOL:11)
Block(-3,27,-5,WOOL:11)
Block(-3,28,-4,WOOL:11)
Block(-3,29,-4,WOOL:11)
Block(-3,30,-4,WOOL:11)
Block(-3,31,-3,WOOL:15)
Block(-3,32,-2,WOOL:15)
Block(-3,32,-1,FENCE:0)
Block(-3,33,-2,FENCE:0)
Block(-3,33,-1,LOG:5)
Block(-3,34,-3,WOOL:11)
Block(-3,35,-3,WOOL:11)
Block(-3,36,-3,WOOL:11)
Block(-3,37,-4,WOOL:11)
Block(-3,38,-4,WOOL:11)
Block(-3,39,-4,WOOL:11)
Block(-3,40,-4,WOOL:11)
Block(-3,41,-3,WOOL:11)
Block(-3,42,-2,WOOL:11)
Block(-3,42,-1,FENCE:0)
Block(-3,43,-2,FENCE:0)
Block(-3,43,-1,LOG:5)
Block(-2,6,-7,LOG:13)
Block(-2,6,-6,LOG:13)
Block(-2,6,-5,LOG:13)
Block(-2,6,-4,LOG:13)
Block(-2,6,-3,LOG:13)
Block(-2,6,-2,LOG:13)
Block(-2,6,-1,LOG:13)
Block(-2,6,0,LOG:13)
Block(-2,6,1,LOG:13)
Block(-2,6,2,LOG:13)
Block(-2,6,3,LOG:13)
Block(-2,7,-7,LOG:13)
Block(-2,7,-6,LOG:13)
Block(-2,7,-5,LOG:13)
Block(-2,7,-4,LOG:13)
Block(-2,7,-3,LOG:13)
Block(-2,7,-2,LOG:13)
Block(-2,7,-1,LOG:13)
Block(-2,7,0,LOG:13)
Block(-2,7,1,LOG:13)
Block(-2,7,2,LOG:13)
Block(-2,7,3,LOG:13)
Block(-2,7,4,LOG:13)
Block(-2,7,5,LOG:13)
Block(-2,8,-7,WOOD_DOUBLE_STEP:1)
Block(-2,8,-6,WOOD_DOUBLE_STEP:1)
Block(-2,8,-5,WOOD_DOUBLE_STEP:1)
Block(-2,8,-4,WOOD_DOUBLE_STEP:1)
Block(-2,8,-3,WOOD_DOUBLE_STEP:1)
Block(-2,8,-2,WOOD_DOUBLE_STEP:1)
Block(-2,8,-1,WOOD_DOUBLE_STEP:1)
Block(-2,8,0,WOOD_DOUBLE_STEP:1)
Block(-2,8,1,WOOD_DOUBLE_STEP:1)
Block(-2,8,2,WOOD_DOUBLE_STEP:1)
Block(-2,8,3,WOOD:5)
Block(-2,8,4,WOOD:5)
Block(-2,8,5,WOOD:5)
Block(-2,8,6,WOOD:5)
Block(-2,8,7,WOOD:5)
Block(-2,8,8,WOOD:5)
Block(-2,9,-7,BED_BLOCK:11)
Block(-2,9,-6,WOOD_BUTTON:4)
Block(-2,9,-5,DISPENSER:9)
Block(-2,9,-4,WOOD_BUTTON:3)
Block(-2,9,-3,WOOD:0)
Block(-2,9,-2,DISPENSER:9)
Block(-2,9,-1,WOOD_BUTTON:3)
Block(-2,9,1,FENCE:0)
Block(-2,9,2,WOOD_BUTTON:4)
Block(-2,9,3,DISPENSER:9)
Block(-2,9,4,WOOD_BUTTON:3)
Block(-2,9,5,WOOD:0)
Block(-2,9,6,WOOD:0)
Block(-2,9,7,WOOD:0)
Block(-2,9,8,CONCRETE:15)
Block(-2,10,-7,BED_BLOCK:11)
Block(-2,10,-5,LEVER:14)
Block(-2,10,-3,WOOD:0)
Block(-2,10,-2,LEVER:14)
Block(-2,10,-1,BED_BLOCK:11)
Block(-2,10,1,TORCH:5)
Block(-2,10,2,BED_BLOCK:11)
Block(-2,10,3,LEVER:14)
RandomBlock(-2,10,5,AIR:0,20,CHEST:4,../../../../Chests/Loot/ShipJunk_1.nbt,10,CHEST:4,../../../../Chests/Loot/ShipJunk_2.nbt,10,CHEST:4,../../../../Chests/Loot/ShipJunk_3.nbt,10,CHEST:4,../../../../Chests/Loot/ShipJunk_4.nbt,10,CHEST:4,../../../../Chests/Loot/ShipJunk_5.nbt,10,CHEST:4,../../../../Chests/Traveler/Travelers_Castle.nbt,1,CHEST:4,../../../../Chests/Traveler/Travelers_Church.nbt,1,CHEST:4,../../../../Chests/Traveler/Travelers_Daeroc.nbt,1,CHEST:4,../../../../Chests/Traveler/Travelers_Farmsteads.nbt,1,CHEST:4,../../../../Chests/Traveler/Travelers_GreenDungeon.nbt,1,CHEST:4,../../../../Chests/Traveler/Travelers_IceShips.nbt,1,CHEST:4,../../../../Chests/Traveler/Travelers_IceTemple.nbt,1,CHEST:4,../../../../Chests/Traveler/Travelers_LegacySpawn.nbt,1,CHEST:4,../../../../Chests/Traveler/Travelers_Mineshafts.nbt,1,CHEST:4,../../../../Chests/Traveler/Travelers_Mountains.nbt,1,CHEST:4,../../../../Chests/Traveler/Travelers_Origin.nbt,1,CHEST:4,../../../../Chests/Traveler/Travelers_Pirate.nbt,1,CHEST:4,../../../../Chests/Traveler/Travelers_Quarry.nbt,1,CHEST:4,../../../../Chests/Traveler/Travelers_Spook.nbt,1,CHEST:4,../../../../Chests/Traveler/Travelers_Tribal.nbt,1,CHEST:4,../../../../Chests/Lore/ShipFloat_1.nbt,1,CHEST:4,../../../../Chests/Lore/ShipFloat_2.nbt,1,CHEST:4,../../../../Chests/Lore/ShipFloat_3.nbt,1,CHEST:4,../../../../Chests/Lore/ShipFloat_4.nbt,1,CHEST:4,../../../../Chests/Lore/ShipFloat_5.nbt,1,CHEST:4,../../../../Chests/Loot/Common1.nbt,10,CHEST:4,../../../../Chests/Loot/Common2.nbt,10,CHEST:4,../../../../Chests/Loot/Common3.nbt,10,CHEST:4,../../../../Chests/Loot/Common4.nbt,10,CHEST:4,../../../../Chests/Loot/Common5.nbt,10,CHEST:4,../../../../Chests/Loot/Common6.nbt,10,CHEST:4,../../../../Chests/Loot/Common7.nbt,10,CHEST:4,../../../../Chests/Loot/Common8.nbt,10,CHEST:4,../../../../Chests/Loot/Common9.nbt,10,CHEST:4,../../../../Chests/Loot/Common10.nbt,10,CHEST:4,../../../../Chests/Loot/Common10.nbt,11,CHEST:4,../../../../Chests/Loot/Common12.nbt,10,CHEST:4,../../../../Chests/Loot/Common13.nbt,10,CHEST:4,../../../../Chests/Loot/Common14.nbt,10,CHEST:4,../../../../Chests/Loot/Common15.nbt,10,CHEST:4,../../../../Chests/Lore/ShipFloat_1.nbt,2,CHEST:4,../../../../Chests/Lore/ShipFloat_3.nbt,2,CHEST:4,../../../../Chests/Lore/ShipFloat_4.nbt,2,CHEST:4,../../../../Chests/Lore/ShipFloat_5.nbt,2,CHEST:4,../../../../Chests/Lore/ShipFloat_5.nbt,2,CHEST:4,../../../../Chests/Loot/Rare1.nbt,5,CHEST:4,../../../../Chests/Loot/Rare2.nbt,5,CHEST:4,../../../../Chests/Loot/Rare3.nbt,5,CHEST:4,../../../../Chests/Loot/Rare4.nbt,5,CHEST:4,../../../../Chests/Loot/Rare5.nbt,5,CHEST:4,../../../../Chests/Loot/Rare6.nbt,5,CHEST:4,../../../../Chests/Loot/Rare7.nbt,5,CHEST:4,../../../../Chests/Loot/Rare8.nbt,5,CHEST:4,../../../../Chests/Loot/Rare9.nbt,5,CHEST:4,../../../../Chests/Loot/Rare10.nbt,5,CHEST:4,../../../../Chests/Loot/Rare11.nbt,5,CHEST:4,../../../../Chests/Loot/Rare12.nbt,5,CHEST:4,../../../../Chests/Loot/Rare13.nbt,5,CHEST:4,../../../../Chests/Loot/Rare14.nbt,5,CHEST:4,../../../../Chests/Loot/Rare15.nbt,5,CHEST:4,../../../../Chests/Loot/Epic1.nbt,2,CHEST:4,../../../../Chests/Loot/Epic2.nbt,2,CHEST:4,../../../../Chests/Loot/Epic3.nbt,2,CHEST:4,../../../../Chests/Loot/Epic4.nbt,2,CHEST:4,../../../../Chests/Loot/Epic5.nbt,2,CHEST:4,../../../../Chests/Loot/Epic6.nbt,2,CHEST:4,../../../../Chests/Loot/Epic7.nbt,2,CHEST:4,../../../../Chests/Loot/Epic8.nbt,2,CHEST:4,../../../../Chests/Loot/Epic9.nbt,2,CHEST:4,../../../../Chests/Loot/Epic10.nbt,2,CHEST:4,../../../../Chests/Loot/Epic11.nbt,2,CHEST:4,../../../../Chests/Loot/Epic12.nbt,2,CHEST:4,../../../../Chests/Loot/Epic13.nbt,2,CHEST:4,../../../../Chests/Loot/Epic14.nbt,2,CHEST:4,../../../../Chests/Loot/Epic15.nbt,5,CHEST:4,../../../../Chests/Loot/Rare1.nbt,5,CHEST:4,../../../../Chests/Loot/Rare2.nbt,5,CHEST:4,../../../../Chests/Loot/Rare3.nbt,5,CHEST:4,../../../../Chests/Loot/Rare4.nbt,5,CHEST:4,../../../../Chests/Loot/Rare5.nbt,10,CHEST:4,../../../../Chests/Loot/Rare6.nbt,10,CHEST:4,../../../../Chests/Loot/Rare7.nbt,10,CHEST:4,../../../../Chests/Loot/Rare8.nbt,10,CHEST:4,../../../../Chests/Loot/Rare9.nbt,10,CHEST:4,../../../../Chests/Loot/Rare10.nbt,15,CHEST:4,../../../../Chests/Loot/Rare11.nbt,15,CHEST:4,../../../../Chests/Loot/Rare12.nbt,15,CHEST:4,../../../../Chests/Loot/Rare13.nbt,15,CHEST:4,../../../../Chests/Loot/Rare14.nbt,15,CHEST:4,../../../../Chests/Loot/Rare15.nbt,15,CHEST:4,../../../../Chests/Loot/Epic15.nbt,100)
Block(-2,10,6,WOOD:0)
Block(-2,10,7,WOOD:0)
Block(-2,11,-7,WOOD_STEP:9)
Block(-2,11,-6,WOOD_STEP:9)
Block(-2,11,-5,WOOD_STEP:9)
Block(-2,11,-4,WOOD_STEP:9)
Block(-2,11,-3,WOOD_DOUBLE_STEP:1)
Block(-2,11,-2,WOOD_STEP:9)
Block(-2,11,-1,WOOD_STEP:9)
Block(-2,11,0,WOOD_STEP:9)
Block(-2,11,1,WOOD_STEP:9)
Block(-2,11,2,WOOD_STEP:9)
Block(-2,11,3,WOOD_STEP:9)
Block(-2,11,4,WOOD_STEP:9)
Block(-2,11,5,WOOD_STEP:9)
Block(-2,11,6,WOOD:0)
Block(-2,11,7,WOOD:0)
Block(-2,11,8,WOOD:0)
Block(-2,12,-7,DISPENSER:9)
Block(-2,12,-6,WOOD_BUTTON:3)
Block(-2,12,-5,BED_BLOCK:11)
Block(-2,12,-4,WOOD_BUTTON:4)
Block(-2,12,-3,DISPENSER:9)
Block(-2,12,-2,WOOD_BUTTON:3)
Block(-2,12,-1,BED_BLOCK:11)
Block(-2,12,0,WOOD:0)
Block(-2,12,1,WOOD:0)
Block(-2,12,2,WOOD:0)
Block(-2,12,3,WOOD:0)
Block(-2,12,4,WOOD:0)
Block(-2,12,5,WOOD:0)
Block(-2,12,6,WOOD:0)
Block(-2,12,7,WOOD:0)
Block(-2,12,8,WOOD:0)
Block(-2,13,-7,LEVER:14)
Block(-2,13,-3,LEVER:14)
Block(-2,13,0,WOOD:0)
Block(-2,13,1,WOOD:0)
Block(-2,13,2,WOOD:0)
Block(-2,13,3,WOOD:0)
Block(-2,13,4,WOOD:0)
Block(-2,13,5,WOOD:0)
Block(-2,13,6,WOOD:0)
Block(-2,13,7,WOOD:0)
Block(-2,13,8,WOOD:0)
Block(-2,14,-7,WOOD:5)
Block(-2,14,-6,WOOD:5)
Block(-2,14,-5,WOOD:5)
Block(-2,14,-4,WOOD:5)
Block(-2,14,-3,WOOD:5)
Block(-2,14,-2,WOOD:5)
Block(-2,14,-1,WOOD:5)
Block(-2,14,0,WOOD:0)
Block(-2,14,1,WOOD_DOUBLE_STEP:1)
Block(-2,14,2,WOOD_DOUBLE_STEP:1)
Block(-2,14,3,WOOD:0)
Block(-2,14,4,WOOD:0)
Block(-2,14,5,WOOD:0)
Block(-2,14,6,WOOD:0)
Block(-2,14,7,WOOD:0)
Block(-2,14,8,WOOD:0)
Block(-2,15,-7,FENCE:0)
Block(-2,15,-6,WOOD_STEP:5)
Block(-2,15,-5,WOOD_STEP:5)
Block(-2,15,-4,WOOD_STEP:5)
Block(-2,15,-3,WOOD_STEP:5)
Block(-2,15,-2,WOOD_STEP:5)
Block(-2,15,-1,WOOD_STEP:5)
Block(-2,15,0,WOOD:5)
Block(-2,15,1,WOOD:5)
Block(-2,15,2,WOOD:5)
Block(-2,15,3,WOOD:5)
Block(-2,15,4,WOOD:5)
Block(-2,15,5,WOOD:5)
Block(-2,15,6,WOOD:5)
Block(-2,15,7,WOOD:5)
Block(-2,16,0,WOOD:5)
Block(-2,16,1,WOOD_STEP:1)
Block(-2,16,2,WOOD:5)
Block(-2,16,3,WOOD_STEP:1)
Block(-2,16,4,WOOD:5)
Block(-2,16,5,WOOD_STEP:1)
Block(-2,16,6,WOOD:5)
Block(-2,16,7,WOOD:5)
Block(-2,16,8,WOOD_STEP:13)
Block(-2,17,0,WOOD:5)
Block(-2,17,1,WOOD:5)
Block(-2,17,2,WOOD:5)
Block(-2,17,3,WOOD:5)
Block(-2,17,4,WOOD:5)
Block(-2,17,5,WOOD:5)
Block(-2,17,6,WOOD:5)
Block(-2,17,8,FENCE:0)
Block(-2,18,-2,WOOL:15)
Block(-2,18,0,WOOD_STEP:5)
Block(-2,18,1,WOOD_STEP:5)
Block(-2,18,2,WOOD_STEP:5)
Block(-2,18,3,WOOD_STEP:5)
Block(-2,18,4,WOOD_STEP:5)
Block(-2,18,5,WOOD_STEP:5)
Block(-2,18,6,WOOD_STEP:5)
Block(-2,18,8,FENCE:0)
Block(-2,19,-3,WOOL:11)
Block(-2,19,-1,FENCE:0)
Block(-2,19,0,FENCE:0)
Block(-2,19,1,FENCE:0)
Block(-2,19,2,FENCE:0)
Block(-2,19,3,FENCE:0)
Block(-2,19,8,FENCE:0)
Block(-2,20,-4,WOOL:11)
Block(-2,20,-1,FENCE:0)
Block(-2,20,0,FENCE:0)
Block(-2,20,1,FENCE:0)
Block(-2,20,2,FENCE:0)
Block(-2,20,3,FENCE:0)
Block(-2,21,-4,WOOL:11)
Block(-2,21,-2,FENCE:0)
Block(-2,21,-1,FENCE:0)
Block(-2,21,0,FENCE:0)
Block(-2,21,1,FENCE:0)
Block(-2,21,2,FENCE:0)
Block(-2,21,3,FENCE:0)
Block(-2,22,-4,WOOL:11)
Block(-2,22,-2,FENCE:0)
Block(-2,22,-1,FENCE:0)
Block(-2,22,0,FENCE:0)
Block(-2,22,1,FENCE:0)
Block(-2,22,2,FENCE:0)
Block(-2,22,3,FENCE:0)
Block(-2,23,-5,WOOL:11)
Block(-2,24,-5,WOOL:11)
Block(-2,25,-5,WOOL:11)
Block(-2,26,-5,WOOL:11)
Block(-2,27,-4,WOOL:11)
Block(-2,28,-4,WOOL:11)
Block(-2,29,-4,WOOL:11)
Block(-2,30,-3,WOOL:11)
Block(-2,31,-3,WOOL:11)
Block(-2,32,-2,WOOL:11)
Block(-2,32,-1,FENCE:0)
Block(-2,33,-2,FENCE:0)
Block(-2,33,-1,LOG:5)
Block(-2,34,-2,WOOL:11)
Block(-2,35,-3,WOOL:11)
Block(-2,36,-3,WOOL:11)
Block(-2,37,-3,WOOL:11)
Block(-2,38,-4,WOOL:11)
Block(-2,39,-4,WOOL:11)
Block(-2,40,-3,WOOL:11)
Block(-2,41,-3,WOOL:11)
Block(-2,42,-2,WOOL:11)
Block(-2,42,-1,FENCE:0)
Block(-2,43,-2,FENCE:0)
Block(-2,43,-1,LOG:5)
Block(-1,8,-7,WOOD:5)
Block(-1,8,-6,WOOD:5)
Block(-1,8,-5,WOOD:5)
Block(-1,8,-4,WOOD:5)
Block(-1,8,-3,WOOD:5)
Block(-1,8,-2,WOOD:5)
Block(-1,8,-1,WOOD:5)
Block(-1,8,0,WOOD:5)
Block(-1,8,1,WOOD:5)
Block(-1,8,2,WOOD:5)
Block(-1,9,-7,WOOD:0)
Block(-1,9,-6,WOOD:0)
Block(-1,9,-5,CONCRETE:15)
Block(-1,9,-4,WOOD:0)
Block(-1,9,-3,WOOD:0)
Block(-1,9,-2,CONCRETE:15)
Block(-1,9,-1,WOOD:0)
Block(-1,9,0,WOOD:0)
Block(-1,9,1,WOOD:0)
Block(-1,9,2,WOOD:0)
Block(-1,9,3,CONCRETE:15)
Block(-1,9,4,WOOD:0)
Block(-1,9,8,DISPENSER:5)
Block(-1,10,-7,WOOD:0)
Block(-1,10,-6,WOOD:0)
Block(-1,10,-4,WOOD:0)
Block(-1,10,-3,WOOD:0)
Block(-1,10,-1,WOOD:0)
Block(-1,10,0,WOOD:0)
Block(-1,10,1,WOOD:0)
Block(-1,10,2,WOOD:0)
Block(-1,10,4,WOOD:0)
Block(-1,10,5,WOOD:0)
Block(-1,10,8,WOOD_STEP:13)
Block(-1,11,-7,WOOD:0)
Block(-1,11,-6,WOOD:0)
Block(-1,11,-5,WOOD:0)
Block(-1,11,-4,WOOD:0)
Block(-1,11,-3,WOOD:0)
Block(-1,11,-2,WOOD:0)
Block(-1,11,-1,WOOD:0)
Block(-1,11,0,WOOD:0)
Block(-1,11,1,WOOD:0)
Block(-1,11,2,WOOD:0)
Block(-1,11,3,WOOD:0)
Block(-1,11,4,WOOD:0)
Block(-1,11,5,WOOD:0)
Block(-1,12,-7,CONCRETE:15)
Block(-1,12,-6,WOOD:5)
Block(-1,12,-5,WOOD:5)
Block(-1,12,-4,WOOD:5)
Block(-1,12,-3,CONCRETE:15)
Block(-1,12,-2,WOOD:5)
Block(-1,12,-1,WOOD:5)
Block(-1,12,0,WOOD:0)
Block(-1,12,1,WOOD:0)
Block(-1,12,2,WOOD:0)
Block(-1,12,3,WOOD:0)
Block(-1,12,4,WOOD:0)
Block(-1,13,-7,WOOD_STEP:9)
Block(-1,13,-6,WOOD:5)
Block(-1,13,-5,WOOD:5)
Block(-1,13,-4,WOOD:5)
Block(-1,13,-3,WOOD_STEP:9)
Block(-1,13,-2,WOOD:5)
Block(-1,13,-1,WOOD:5)
Block(-1,13,0,WOOD:0)
Block(-1,13,1,WOOD:0)
Block(-1,13,2,WOOD:0)
Block(-1,13,3,WOOD:0)
Block(-1,14,-7,WOOD_BUTTON:1)
Block(-1,14,-6,WOOD_BUTTON:1)
Block(-1,14,-5,TRAP_DOOR:7)
Block(-1,14,-4,WOOD_BUTTON:1)
Block(-1,14,-3,WOOD_BUTTON:1)
Block(-1,14,-2,WOOD_BUTTON:1)
Block(-1,14,-1,TRAP_DOOR:7)
Block(-1,14,0,WOOD:0)
Block(-1,14,1,WOOD:0)
Block(-1,14,2,WOOD:0)
Block(-1,15,-1,WOOD_STEP:13)
Block(-1,15,0,DARK_OAK_STAIRS:5)
Block(-1,15,1,WOOD_STEP:13)
Block(-1,15,2,DARK_OAK_STAIRS:5)
Block(-1,15,3,WOOD_STEP:13)
Block(-1,15,5,FENCE:0)
Block(-1,15,6,FENCE:0)
Block(-1,15,7,TRAP_DOOR:7)
Block(-1,16,-1,FENCE:0)
Block(-1,16,0,FENCE:0)
Block(-1,16,1,FENCE:0)
Block(-1,16,2,FENCE:0)
Block(-1,16,3,FENCE:0)
Block(-1,16,7,TRAP_DOOR:15)
Block(-1,17,-1,FENCE:0)
Block(-1,17,0,FENCE:0)
Block(-1,17,1,FENCE:0)
Block(-1,17,2,FENCE:0)
Block(-1,17,3,FENCE:0)
RandomBlock(-1,17,4,WALL_BANNER:5,../../Banners/royal_01.nbt,20,WALL_BANNER:5,../../Banners/royal_02.nbt,20,WALL_BANNER:5,../../Banners/royal_03.nbt,20,WALL_BANNER:5,../../Banners/royal_04.nbt,20,WALL_BANNER:5,../../Banners/royal_05.nbt,100)
Block(-1,17,6,TRAP_DOOR:7)
Block(-1,18,-2,WOOL:15)
Block(-1,18,-1,WOOL:11)
Block(-1,18,0,FENCE:0)
Block(-1,18,1,FENCE:0)
Block(-1,18,2,FENCE:0)
Block(-1,18,3,FENCE:0)
Block(-1,19,-3,WOOL:11)
Block(-1,19,-1,FENCE:0)
Block(-1,19,0,FENCE:0)
Block(-1,19,1,FENCE:0)
Block(-1,19,2,FENCE:0)
Block(-1,19,3,FENCE:0)
Block(-1,20,-4,WOOL:11)
Block(-1,21,-4,WOOL:11)
Block(-1,22,-4,WOOL:11)
Block(-1,23,-4,WOOL:11)
Block(-1,24,-4,WOOL:11)
Block(-1,25,-5,WOOL:11)
Block(-1,26,-4,WOOL:11)
Block(-1,27,-4,WOOL:11)
Block(-1,28,-4,WOOL:11)
Block(-1,29,-3,WOOL:11)
Block(-1,30,-3,WOOL:11)
Block(-1,31,-3,WOOL:11)
Block(-1,32,-2,WOOL:15)
Block(-1,32,-1,FENCE:0)
Block(-1,33,-2,FENCE:0)
Block(-1,33,-1,LOG:5)
Block(-1,34,-2,WOOL:15)
Block(-1,35,-2,WOOL:11)
Block(-1,36,-2,WOOL:11)
Block(-1,37,-3,WOOL:11)
Block(-1,38,-4,WOOL:15)
Block(-1,39,-3,WOOL:11)
Block(-1,40,-3,WOOL:11)
Block(-1,41,-3,WOOL:11)
Block(-1,42,-2,WOOL:15)
Block(-1,42,-1,FENCE:0)
Block(-1,43,-2,FENCE:0)
Block(-1,43,-1,LOG:5)
Block(0,9,-5,DISPENSER:5)
Block(0,9,-2,DISPENSER:5)
Block(0,9,3,DISPENSER:5)
Block(0,10,-5,WOOD_STEP:13)
Block(0,10,-2,WOOD_STEP:13)
Block(0,10,3,WOOD_STEP:13)
Block(0,12,-7,DISPENSER:5)
Block(0,12,-5,TRAP_DOOR:7)
Block(0,12,-3,DISPENSER:5)
Block(0,12,-1,TRAP_DOOR:7)
Block(0,13,-7,WOOD_STEP:9)
Block(0,13,-5,TRAP_DOOR:7)
Block(0,13,-3,WOOD_STEP:9)
Block(0,13,-1,TRAP_DOOR:7)
Block(0,15,4,FENCE:0)
Block(0,15,5,FENCE:0)
Block(0,16,4,FENCE:0)
Block(0,18,-2,WOOL:11)
Block(0,18,-1,WOOL:11)
Block(0,19,-2,WOOL:11)
Block(0,20,-3,WOOL:11)
Block(0,21,-4,WOOL:11)
Block(0,22,-4,WOOL:11)
Block(0,23,-4,WOOL:11)
Block(0,24,-4,WOOL:15)
Block(0,24,-3,WOOL:11)
Block(0,25,-4,WOOL:11)
Block(0,25,-3,WOOL:11)
Block(0,26,-4,WOOL:15)
Block(0,26,-3,WOOL:11)
Block(0,27,-4,WOOL:11)
Block(0,28,-3,WOOL:11)
Block(0,29,-3,WOOL:11)
Block(0,30,-3,WOOL:11)
Block(0,31,-2,WOOL:11)
Block(0,32,-1,WOOL:11)
Block(0,32,0,FENCE:0)
Block(0,33,-1,FENCE:0)
Block(0,33,0,LOG:5)
Block(0,34,-1,WOOL:15)
Block(0,35,-1,WOOL:11)
Block(0,36,-1,WOOL:15)
Block(0,40,-3,WOOL:15)
Block(0,41,-2,WOOL:15)
Block(0,42,-1,WOOL:15)
Block(0,43,-1,WOOL:15)
Block(1,16,4,FENCE:0)
Block(1,18,-1,WOOL:11)
Block(1,19,-2,WOOL:11)
Block(1,20,-3,WOOL:11)
Block(1,21,-3,WOOL:15)
Block(1,22,-3,WOOL:11)
Block(1,23,-4,WOOL:15)
Block(1,23,-3,WOOL:15)
Block(1,27,-3,WOOL:15)
Block(1,28,-3,WOOL:15)
Block(1,29,-3,WOOL:11)
Block(1,30,-2,WOOL:11)
Block(1,31,-2,WOOL:11)
Block(1,32,-1,WOOL:15)
Block(1,32,0,FENCE:0)
Block(1,33,-1,FENCE:0)
Block(1,33,0,LOG:5)
Block(1,34,0,WOOL:11)
Block(1,35,0,WOOL:11)
Block(1,42,-1,WOOL:15)
Block(1,43,0,WOOL:15)
Block(1,44,0,WOOL:15)
Block(1,44,1,WOOL:11)
Block(2,16,3,FENCE:0)
Block(2,16,4,FENCE:0)
Block(2,17,3,FENCE:0)
Block(2,18,-1,WOOL:11)
Block(2,19,-2,WOOL:15)
Block(2,20,-3,WOOL:15)
Block(2,29,-2,WOOL:11)
Block(2,30,-2,WOOL:11)
Block(2,31,-2,WOOL:11)
Block(2,32,-1,WOOL:15)
Block(2,32,0,FENCE:0)
Block(2,33,-1,FENCE:0)
Block(2,33,0,LOG:5)
Block(2,34,0,WOOL:11)
Block(2,34,1,WOOL:15)
Block(2,34,2,WOOL:11)
Block(2,44,1,WOOL:15)
Block(2,44,2,WOOL:15)
Block(3,17,3,FENCE:0)
Block(3,18,-1,WOOL:11)
Block(3,18,0,WOOL:15)
Block(3,30,-2,WOOL:11)
Block(3,31,-2,WOOL:11)
Block(3,32,-1,WOOL:11)
Block(4,17,0,WOOL:15)
Block(4,17,1,WOOL:15)
Block(4,17,2,WOOL:11)
Block(4,17,3,FENCE:0)
Block(4,31,-2,WOOL:11)
Block(4,32,-2,WOOL:11)
Block(4,33,-1,WOOL:15)
Branch(0,0,16,true,Royal_FloatC1R3,NORTH,100.0,0)
Entity(-8,13,3,minecraft:villager,1)
Entity(-7,16,-4,minecraft:villager,1)
Entity(-5,13,-5,minecraft:villager,1)
Entity(-5,17,7,minecraft:villager,1)
Entity(-4,10,-6,minecraft:villager,1)
