Author: NLBlackEagle
Description: No description given
SettingsMode: WriteDisable
Frequency: 0
SpawnHeight: highestBlock
UseCenterForHighestBlock: true
MinHeight: 0
MaxHeight: 255
InheritBO3: 
InheritBO3Rotation: NORTH
OverrideChildSettings: true
OverrideParentHeight: false
CanOverride: false
BranchFrequency: 0
BranchFrequencyGroup: 
MustBeBelowOther: false
MustBeInside: 
CannotBeInside: 
ReplacesBO3: 
MustBeInsideWorldBorders: false
CanSpawnOnWater: true
SpawnOnWaterOnly: false
SpawnUnderWater: false
SpawnAtWaterLevel: false
HeightOffset: 0
RemoveAir: false
ReplaceAbove: 
ReplaceBelow: 
ReplaceWithBiomeBlocks: true
ReplaceWithSurfaceBlock: GRASS
ReplaceWithGroundBlock: DIRT
ReplaceWithStoneBlock: STONE
SmoothRadius: 0
SmoothHeightOffset: 0
SmoothStartTop: false
SmoothStartWood: false
SmoothingSurfaceBlock: 
SmoothingGroundBlock: 
BO3Group: 
IsSpawnPoint: false
DoReplaceBlocks: true
RandomBlock(-8,0,-7,COAL_ORE,33,STONE,100)
RandomBlock(-8,0,-6,COAL_ORE,33,STONE,100)
Block(-8,0,-5,STONE:0)
RandomBlock(-8,0,-4,COAL_ORE,33,STONE,100)
Block(-8,0,-3,STONE:0)
RandomBlock(-8,0,-2,COAL_ORE,33,STONE,100)
Block(-8,0,-1,STONE:0)
Block(-8,0,0,STONE:0)
Block(-8,0,1,STONE:0)
RandomBlock(-8,0,2,COAL_ORE,33,STONE,100)
Block(-8,0,3,STONE:0)
Block(-8,0,4,STONE:0)
RandomBlock(-8,0,5,COAL_ORE,33,STONE,100)
Block(-8,0,6,STONE:0)
Block(-8,0,7,STONE:0)
RandomBlock(-8,0,8,COAL_ORE,33,STONE,100)
Block(-8,1,-7,STONE:0)
Block(-8,1,-6,STONE:0)
Block(-8,1,-5,STONE:0)
RandomBlock(-8,1,-4,COAL_ORE,33,STONE,100)
Block(-8,1,-3,STONE:0)
Block(-8,1,-2,STONE:0)
Block(-8,1,-1,STONE:0)
RandomBlock(-8,1,0,COAL_ORE,33,STONE,100)
RandomBlock(-8,1,1,COAL_ORE,33,STONE,100)
Block(-8,1,2,STONE:0)
RandomBlock(-8,1,3,COAL_ORE,33,STONE,100)
Block(-8,1,4,STONE:0)
Block(-8,1,5,STONE:0)
RandomBlock(-8,1,6,COAL_ORE,33,STONE,100)
RandomBlock(-8,1,7,COAL_ORE,33,STONE,100)
RandomBlock(-8,1,8,COAL_ORE,33,STONE,100)
Block(-8,2,-7,STONE:0)
RandomBlock(-8,2,-6,COAL_ORE,33,STONE,100)
Block(-8,2,-5,STONE:0)
Block(-8,2,-4,STONE:0)
RandomBlock(-8,2,-3,COAL_ORE,33,STONE,100)
Block(-8,2,-2,STONE:0)
Block(-8,2,-1,STONE:0)
RandomBlock(-8,2,0,COAL_ORE,33,STONE,100)
Block(-8,2,1,STONE:0)
Block(-8,2,2,STONE:0)
Block(-8,2,3,STONE:0)
Block(-8,2,4,STONE:0)
Block(-8,2,5,STONE:0)
Block(-8,2,6,STONE:0)
RandomBlock(-8,2,7,COAL_ORE,33,STONE,100)
Block(-8,2,8,STONE:0)
RandomBlock(-8,3,-7,COAL_ORE,33,STONE,100)
Block(-8,3,-6,STONE:0)
RandomBlock(-8,3,-5,COAL_ORE,33,STONE,100)
RandomBlock(-8,3,-4,COAL_ORE,33,STONE,100)
Block(-8,3,-3,STONE:0)
Block(-8,3,-2,STONE:0)
RandomBlock(-8,3,-1,COAL_ORE,33,STONE,100)
Block(-8,3,0,STONE:0)
RandomBlock(-8,3,1,COAL_ORE,33,STONE,100)
Block(-8,3,2,STONE:0)
Block(-8,3,3,STONE:0)
RandomBlock(-8,3,4,COAL_ORE,33,STONE,100)
Block(-8,3,5,STONE:0)
Block(-8,3,6,STONE:0)
RandomBlock(-8,3,7,COAL_ORE,33,STONE,100)
RandomBlock(-8,3,8,COAL_ORE,33,STONE,100)
Block(-8,4,-7,STONE:0)
Block(-8,4,-6,STONE:0)
Block(-8,4,-5,STONE:0)
RandomBlock(-8,4,-4,COAL_ORE,33,STONE,100)
RandomBlock(-8,4,-3,COAL_ORE,33,STONE,100)
Block(-8,4,-2,STONE:0)
Block(-8,4,-1,STONE:0)
RandomBlock(-8,4,0,COAL_ORE,33,STONE,100)
Block(-8,4,1,STONE:0)
Block(-8,4,2,STONE:0)
RandomBlock(-8,4,3,COAL_ORE,33,STONE,100)
RandomBlock(-8,4,4,COAL_ORE,33,STONE,100)
Block(-8,4,5,STONE:0)
RandomBlock(-8,4,6,COAL_ORE,33,STONE,100)
Block(-8,4,7,STONE:0)
Block(-8,4,8,STONE:0)
Block(-8,5,-7,STONE:0)
Block(-8,5,-6,STONE:0)
Block(-8,5,-5,STONE:0)
Block(-8,5,-4,STONE:0)
Block(-8,5,-3,STONE:0)
Block(-8,5,-2,STONE:0)
Block(-8,5,-1,STONE:0)
RandomBlock(-8,5,0,COAL_ORE,33,STONE,100)
RandomBlock(-8,5,1,COAL_ORE,33,STONE,100)
Block(-8,5,2,STONE:0)
Block(-8,5,3,STONE:0)
RandomBlock(-8,5,4,COAL_ORE,33,STONE,100)
Block(-8,5,5,STONE:0)
Block(-8,5,6,STONE:0)
Block(-8,5,7,STONE:0)
Block(-8,5,8,STONE:0)
RandomBlock(-8,6,-7,COAL_ORE,33,STONE,100)
RandomBlock(-8,6,-6,COAL_ORE,33,STONE,100)
RandomBlock(-8,6,-5,COAL_ORE,33,STONE,100)
RandomBlock(-8,6,-4,COAL_ORE,33,STONE,100)
RandomBlock(-8,6,-3,COAL_ORE,33,STONE,100)
Block(-8,6,-2,STONE:0)
RandomBlock(-8,6,-1,COAL_ORE,33,STONE,100)
Block(-8,6,0,STONE:0)
RandomBlock(-8,6,1,COAL_ORE,33,STONE,100)
RandomBlock(-8,6,2,COAL_ORE,33,STONE,100)
RandomBlock(-8,6,3,COAL_ORE,33,STONE,100)
Block(-8,6,4,STONE:0)
RandomBlock(-8,6,5,COAL_ORE,33,STONE,100)
RandomBlock(-8,6,6,COAL_ORE,33,STONE,100)
Block(-8,6,7,STONE:0)
Block(-8,6,8,STONE:0)
Block(-8,7,-7,STONE:0)
Block(-8,7,-6,STONE:0)
RandomBlock(-8,7,-5,COAL_ORE,33,STONE,100)
RandomBlock(-8,7,-4,COAL_ORE,33,STONE,100)
Block(-8,7,-3,STONE:0)
Block(-8,7,-2,STONE:0)
RandomBlock(-8,7,-1,COAL_ORE,33,STONE,100)
RandomBlock(-8,7,0,COAL_ORE,33,STONE,100)
Block(-8,7,1,STONE:0)
Block(-8,7,2,STONE:0)
Block(-8,7,3,STONE:0)
Block(-8,7,4,STONE:0)
Block(-8,7,5,STONE:0)
Block(-8,7,6,STONE:0)
RandomBlock(-8,7,7,COAL_ORE,33,STONE,100)
Block(-8,7,8,STONE:0)
RandomBlock(-8,8,-7,COAL_ORE,33,STONE,100)
Block(-8,8,-6,STONE:0)
Block(-8,8,-5,STONE:0)
Block(-8,8,-4,STONE:0)
Block(-8,8,-3,STONE:0)
Block(-8,8,-2,STONE:0)
Block(-8,8,-1,STONE:0)
RandomBlock(-8,8,0,COAL_ORE,33,STONE,100)
RandomBlock(-8,8,1,COAL_ORE,33,STONE,100)
Block(-8,8,2,STONE:0)
RandomBlock(-8,8,3,COAL_ORE,33,STONE,100)
RandomBlock(-8,8,4,COAL_ORE,33,STONE,100)
RandomBlock(-8,8,5,COAL_ORE,33,STONE,100)
Block(-8,8,6,STONE:0)
Block(-8,8,7,STONE:0)
Block(-8,8,8,STONE:0)
RandomBlock(-8,9,-7,COAL_ORE,33,STONE,100)
RandomBlock(-8,9,-6,COAL_ORE,33,STONE,100)
Block(-8,9,-5,STONE:0)
Block(-8,9,-4,STONE:0)
Block(-8,9,-3,STONE:0)
Block(-8,9,-2,STONE:0)
Block(-8,9,-1,STONE:0)
RandomBlock(-8,9,0,COAL_ORE,33,STONE,100)
RandomBlock(-8,9,1,COAL_ORE,33,STONE,100)
RandomBlock(-8,9,2,COAL_ORE,33,STONE,100)
RandomBlock(-8,9,3,COAL_ORE,33,STONE,100)
RandomBlock(-8,9,4,COAL_ORE,33,STONE,100)
RandomBlock(-8,9,5,COAL_ORE,33,STONE,100)
Block(-8,9,6,STONE:0)
Block(-8,9,7,STONE:0)
Block(-8,9,8,STONE:0)
RandomBlock(-8,10,-7,COAL_ORE,33,STONE,100)
RandomBlock(-8,10,-6,COAL_ORE,33,STONE,100)
RandomBlock(-8,10,-5,COAL_ORE,33,STONE,100)
RandomBlock(-8,10,-4,COAL_ORE,33,STONE,100)
RandomBlock(-8,10,-3,COAL_ORE,33,STONE,100)
Block(-8,10,-2,STONE:0)
Block(-8,10,-1,STONE:0)
Block(-8,10,0,STONE:0)
Block(-8,10,1,STONE:0)
Block(-8,10,2,STONE:0)
Block(-8,10,3,STONE:0)
RandomBlock(-8,10,4,COAL_ORE,33,STONE,100)
Block(-8,10,5,STONE:0)
Block(-8,10,6,STONE:0)
RandomBlock(-8,10,7,COAL_ORE,33,STONE,100)
RandomBlock(-8,10,8,COAL_ORE,33,STONE,100)
Block(-8,11,-7,STONE:0)
RandomBlock(-8,11,-6,COAL_ORE,33,STONE,100)
Block(-8,11,-5,STONE:0)
RandomBlock(-8,11,-4,COAL_ORE,33,STONE,100)
RandomBlock(-8,11,-3,SKULL:1,../../../Skulls/dungeon_skull_01.nbt,6,AIR,9,SKULL:1,../../../Skulls/dungeon_skull_02.nbt,12,AIR,15,SKULL:1,../../../Skulls/dungeon_skull_03.nbt,18,AIR,21,SKULL:1,../../../Skulls/dungeon_skull_04.nbt,24,AIR,27,SKULL:1,../../../Skulls/dungeon_skull_05.nbt,30,AIR,33,SKULL:1,../../../Skulls/dungeon_skull_06.nbt,36,AIR,39,SKULL:1,../../../Skulls/dungeon_skull_07.nbt,42,AIR,45,SKULL:1,../../../Skulls/dungeon_skull_08.nbt,48,AIR,51,SKULL:1,../../../Skulls/dungeon_skull_09.nbt,54,AIR,57,SKULL:1,../../../Skulls/dungeon_skull_10.nbt,60,AIR,63,SKULL:1,../../../Skulls/dungeon_skull_11.nbt,66,AIR,69,SKULL:1,../../../Skulls/dungeon_skull_12.nbt,72,AIR,75,SKULL:1,../../../Skulls/dungeon_skull_13.nbt,78,AIR,81,SKULL:1,../../../Skulls/dungeon_skull_14.nbt,84,AIR,87,SKULL:1,../../../Skulls/dungeon_skull_15.nbt,90,AIR,93,SKULL:1,../../../Skulls/dungeon_skull_16.nbt,96,AIR,100)
Block(-8,11,-2,AIR:0)
RandomBlock(-8,11,-1,COAL_ORE,33,STONE,100)
RandomBlock(-8,11,0,COAL_ORE,33,STONE,100)
Block(-8,11,1,AIR:0)
Block(-8,11,2,LOG:1)
RandomBlock(-8,11,3,COAL_ORE,33,STONE,100)
RandomBlock(-8,11,4,COAL_ORE,33,STONE,100)
Block(-8,11,5,LOG:1)
RandomBlock(-8,11,6,COAL_ORE,33,STONE,100)
RandomBlock(-8,11,7,COAL_ORE,33,STONE,100)
Block(-8,11,8,STONE:0)
Block(-8,12,-7,STONE:0)
Block(-8,12,-6,STONE:0)
RandomBlock(-8,12,-5,COAL_ORE,33,STONE,100)
Block(-8,12,-4,SPRUCE_FENCE:0)
Block(-8,12,-3,AIR:0)
Block(-8,12,-2,AIR:0)
RandomBlock(-8,12,-1,SKULL:1,../../../Skulls/dungeon_skull_01.nbt,6,AIR,9,SKULL:1,../../../Skulls/dungeon_skull_02.nbt,12,AIR,15,SKULL:1,../../../Skulls/dungeon_skull_03.nbt,18,AIR,21,SKULL:1,../../../Skulls/dungeon_skull_04.nbt,24,AIR,27,SKULL:1,../../../Skulls/dungeon_skull_05.nbt,30,AIR,33,SKULL:1,../../../Skulls/dungeon_skull_06.nbt,36,AIR,39,SKULL:1,../../../Skulls/dungeon_skull_07.nbt,42,AIR,45,SKULL:1,../../../Skulls/dungeon_skull_08.nbt,48,AIR,51,SKULL:1,../../../Skulls/dungeon_skull_09.nbt,54,AIR,57,SKULL:1,../../../Skulls/dungeon_skull_10.nbt,60,AIR,63,SKULL:1,../../../Skulls/dungeon_skull_11.nbt,66,AIR,69,SKULL:1,../../../Skulls/dungeon_skull_12.nbt,72,AIR,75,SKULL:1,../../../Skulls/dungeon_skull_13.nbt,78,AIR,81,SKULL:1,../../../Skulls/dungeon_skull_14.nbt,84,AIR,87,SKULL:1,../../../Skulls/dungeon_skull_15.nbt,90,AIR,93,SKULL:1,../../../Skulls/dungeon_skull_16.nbt,96,AIR,100)
Block(-8,12,0,AIR:0)
Block(-8,12,1,AIR:0)
Block(-8,12,2,LOG:1)
Block(-8,12,3,WOOD_STEP:1)
Block(-8,12,4,WOOD_STEP:1)
Block(-8,12,5,LOG:1)
RandomBlock(-8,12,6,COAL_ORE,33,STONE,100)
RandomBlock(-8,12,7,COAL_ORE,33,STONE,100)
RandomBlock(-8,12,8,COAL_ORE,33,STONE,100)
Block(-8,13,-7,STONE:0)
RandomBlock(-8,13,-6,COAL_ORE,33,STONE,100)
RandomBlock(-8,13,-5,COAL_ORE,33,STONE,100)
Block(-8,13,-4,SPRUCE_FENCE:0)
Block(-8,13,-3,AIR:0)
Block(-8,13,-2,AIR:0)
Block(-8,13,-1,AIR:0)
Block(-8,13,0,AIR:0)
Block(-8,13,1,AIR:0)
Block(-8,13,2,LOG:1)
Block(-8,13,3,AIR:0)
Block(-8,13,4,AIR:0)
Block(-8,13,5,LOG:1)
Block(-8,13,6,STONE:0)
Block(-8,13,7,STONE:0)
Block(-8,13,8,STONE:0)
RandomBlock(-8,14,-7,COAL_ORE,33,STONE,100)
RandomBlock(-8,14,-6,COAL_ORE,33,STONE,100)
Block(-8,14,-5,STONE:0)
Block(-8,14,-4,SPRUCE_FENCE:0)
Block(-8,14,-3,AIR:0)
Block(-8,14,-2,AIR:0)
Block(-8,14,-1,AIR:0)
Block(-8,14,0,AIR:0)
Block(-8,14,1,AIR:0)
Block(-8,14,2,LOG:1)
Block(-8,14,3,AIR:0)
Block(-8,14,4,AIR:0)
Block(-8,14,5,LOG:1)
Block(-8,14,6,STONE:0)
Block(-8,14,7,STONE:0)
Block(-8,14,8,STONE:0)
Block(-8,15,-7,STONE:0)
Block(-8,15,-6,STONE:0)
Block(-8,15,-5,SPRUCE_FENCE:0)
Block(-8,15,-4,SPRUCE_FENCE:0)
Block(-8,15,-3,AIR:0)
Block(-8,15,-2,AIR:0)
Block(-8,15,-1,AIR:0)
Block(-8,15,0,AIR:0)
Block(-8,15,1,AIR:0)
Block(-8,15,2,LOG:1)
Block(-8,15,3,AIR:0)
Block(-8,15,4,AIR:0)
Block(-8,15,5,LOG:1)
Block(-8,15,6,SPRUCE_FENCE:0)
RandomBlock(-8,15,7,COAL_ORE,33,STONE,100)
Block(-8,15,8,STONE:0)
Block(-8,16,-7,STONE:0)
Block(-8,16,-6,STONE:0)
Block(-8,16,-5,SPRUCE_FENCE:0)
Block(-8,16,-4,SPRUCE_FENCE:0)
Block(-8,16,-3,AIR:0)
Block(-8,16,-2,AIR:0)
Block(-8,16,-1,AIR:0)
Block(-8,16,0,AIR:0)
Block(-8,16,1,AIR:0)
Block(-8,16,2,LOG:1)
Block(-8,16,3,AIR:0)
Block(-8,16,4,AIR:0)
Block(-8,16,5,LOG:1)
Block(-8,16,6,SPRUCE_FENCE:0)
RandomBlock(-8,16,7,COAL_ORE,33,STONE,100)
Block(-8,16,8,STONE:0)
Block(-8,17,-7,STONE:0)
Block(-8,17,-6,STONE:0)
Block(-8,17,-5,SPRUCE_FENCE:0)
Block(-8,17,-4,SPRUCE_FENCE:0)
Block(-8,17,-3,AIR:0)
Block(-8,17,-2,AIR:0)
Block(-8,17,-1,AIR:0)
Block(-8,17,0,AIR:0)
Block(-8,17,1,AIR:0)
Block(-8,17,2,LOG:1)
Block(-8,17,3,AIR:0)
Block(-8,17,4,SPRUCE_FENCE:0)
Block(-8,17,5,LOG:1)
Block(-8,17,6,SPRUCE_FENCE:0)
Block(-8,17,7,DARK_OAK_STAIRS:4)
Block(-8,17,8,SPRUCE_FENCE:0)
Block(-8,18,-7,STONE:0)
Block(-8,18,-6,WOOD_STEP:1)
Block(-8,18,-5,WOOD_STEP:1)
Block(-8,18,-4,WOOD_STEP:1)
Block(-8,18,-3,AIR:0)
Block(-8,18,-2,AIR:0)
Block(-8,18,-1,AIR:0)
Block(-8,18,0,AIR:0)
Block(-8,18,1,AIR:0)
Block(-8,18,2,LOG:1)
Block(-8,18,3,AIR:0)
Block(-8,18,4,WOOD_STEP:1)
Block(-8,18,5,LOG:1)
Block(-8,18,6,WOOD_STEP:1)
Block(-8,18,7,WOOD_STEP:1)
Block(-8,18,8,WOOD_STEP:1)
RandomBlock(-8,19,-7,SKULL:1,../../../Skulls/dungeon_skull_01.nbt,6,AIR,9,SKULL:1,../../../Skulls/dungeon_skull_02.nbt,12,AIR,15,SKULL:1,../../../Skulls/dungeon_skull_03.nbt,18,AIR,21,SKULL:1,../../../Skulls/dungeon_skull_04.nbt,24,AIR,27,SKULL:1,../../../Skulls/dungeon_skull_05.nbt,30,AIR,33,SKULL:1,../../../Skulls/dungeon_skull_06.nbt,36,AIR,39,SKULL:1,../../../Skulls/dungeon_skull_07.nbt,42,AIR,45,SKULL:1,../../../Skulls/dungeon_skull_08.nbt,48,AIR,51,SKULL:1,../../../Skulls/dungeon_skull_09.nbt,54,AIR,57,SKULL:1,../../../Skulls/dungeon_skull_10.nbt,60,AIR,63,SKULL:1,../../../Skulls/dungeon_skull_11.nbt,66,AIR,69,SKULL:1,../../../Skulls/dungeon_skull_12.nbt,72,AIR,75,SKULL:1,../../../Skulls/dungeon_skull_13.nbt,78,AIR,81,SKULL:1,../../../Skulls/dungeon_skull_14.nbt,84,AIR,87,SKULL:1,../../../Skulls/dungeon_skull_15.nbt,90,AIR,93,SKULL:1,../../../Skulls/dungeon_skull_16.nbt,96,AIR,100)
Block(-8,19,-6,AIR:0)
Block(-8,19,-5,AIR:0)
Block(-8,19,-4,AIR:0)
Block(-8,19,-3,AIR:0)
Block(-8,19,-2,AIR:0)
Block(-8,19,-1,AIR:0)
Block(-8,19,0,AIR:0)
Block(-8,19,1,AIR:0)
Block(-8,19,2,LOG:1)
Block(-8,19,3,AIR:0)
Block(-8,19,4,AIR:0)
Block(-8,19,5,LOG:1)
Block(-8,19,6,AIR:0)
Block(-8,19,7,AIR:0)
Block(-8,19,8,AIR:0)
RandomBlock(-8,20,-7,WEB:0,25,AIR:0,100)
RandomBlock(-8,20,1,WEB:0,25,AIR:0,100)
Block(-8,20,2,LOG:1)
Block(-8,20,3,LOG:9)
Block(-8,20,4,LOG:9)
Block(-8,20,5,WOOD:5)
Block(-8,21,-7,LOG:9)
Block(-8,21,-6,LOG:9)
Block(-8,21,-5,LOG:9)
Block(-8,21,-4,LOG:5)
Block(-8,21,-3,LOG:9)
Block(-8,21,-2,LOG:9)
Block(-8,21,-1,LOG:9)
Block(-8,21,0,LOG:9)
Block(-8,21,1,LOG:9)
Block(-8,21,2,LOG:1)
Block(-8,21,3,WOOD:5)
Block(-8,21,4,SPRUCE_FENCE:0)
Block(-8,21,5,SPRUCE_FENCE:0)
Block(-8,22,-7,SPRUCE_FENCE:0)
Block(-8,22,-6,SPRUCE_FENCE:0)
Block(-8,22,-5,SPRUCE_FENCE:0)
Block(-8,22,-4,LOG:1)
Block(-8,22,-3,SPRUCE_FENCE:0)
Block(-8,22,-2,SPRUCE_FENCE:0)
Block(-8,22,-1,SPRUCE_FENCE:0)
Block(-8,22,0,SPRUCE_FENCE:0)
Block(-8,22,1,SPRUCE_FENCE:0)
Block(-8,22,2,LOG:1)
Block(-8,22,3,WOOD:5)
Block(-8,22,5,SPRUCE_FENCE:0)
Block(-8,23,-7,LOG:9)
Block(-8,23,-6,LOG:9)
Block(-8,23,-5,LOG:9)
Block(-8,23,-4,LOG:9)
Block(-8,23,-3,LOG:9)
Block(-8,23,-2,LOG:9)
Block(-8,23,-1,LOG:9)
Block(-8,23,0,LOG:9)
Block(-8,23,1,LOG:9)
Block(-8,23,2,LOG:9)
Block(-8,23,3,WOOD:5)
Block(-8,23,4,WOOD_STEP:9)
Block(-8,23,5,WOOD_DOUBLE_STEP:1)
Block(-8,24,-7,RAILS:0)
Block(-8,24,-6,RAILS:0)
Block(-8,24,-5,RAILS:0)
Block(-8,24,-4,RAILS:0)
Block(-8,24,-3,RAILS:0)
Block(-8,24,-2,RAILS:0)
Block(-8,24,-1,RAILS:0)
Block(-8,24,0,POWERED_RAIL:0)
Block(-8,24,1,WOOD:5)
Block(-8,24,2,WOOD:5)
Block(-8,24,3,SPRUCE_FENCE:0)
Block(-8,24,4,SPRUCE_FENCE:0)
Block(-8,24,5,SPRUCE_FENCE:0)
Block(-8,25,-2,WOOD_DOUBLE_STEP:1)
Block(-8,25,0,HOPPER:0)
Block(-8,25,1,HOPPER:2)
Block(-8,25,2,DARK_OAK_STAIRS:3)
Block(-8,26,-2,WOOD_STEP:1)
Block(-8,26,-1,WOOD_STEP:1)
Block(-8,26,0,WOOD_STEP:1)
RandomBlock(-8,26,1,AIR:0,20,CHEST:3,../../../Chests/Loot/JunkChest_1.nbt,10,CHEST:3,../../../Chests/Loot/JunkChest_2.nbt,10,CHEST:3,../../../Chests/Loot/JunkChest_3.nbt,10,CHEST:3,../../../Chests/Loot/JunkChest_4.nbt,10,CHEST:3,../../../Chests/Loot/JunkChest_5.nbt,10,CHEST:3,../../../Chests/Lore/Quarry_1.nbt,1,CHEST:3,../../../Chests/Lore/Quarry_2.nbt,1,CHEST:3,../../../Chests/Lore/Quarry_3.nbt,1,CHEST:3,../../../Chests/Lore/Quarry_4.nbt,1,CHEST:3,../../../Chests/Lore/Quarry_5.nbt,1,CHEST:3,../../../Chests/Loot/Common1.nbt,10,CHEST:3,../../../Chests/Loot/Common2.nbt,10,CHEST:3,../../../Chests/Loot/Common3.nbt,10,CHEST:3,../../../Chests/Loot/Common4.nbt,10,CHEST:3,../../../Chests/Loot/Common5.nbt,10,CHEST:3,../../../Chests/Loot/Common6.nbt,10,CHEST:3,../../../Chests/Loot/Common7.nbt,10,CHEST:3,../../../Chests/Loot/Common8.nbt,10,CHEST:3,../../../Chests/Loot/Common9.nbt,10,CHEST:3,../../../Chests/Loot/Common10.nbt,10,CHEST:3,../../../Chests/Loot/Common10.nbt,11,CHEST:3,../../../Chests/Loot/Common12.nbt,10,CHEST:3,../../../Chests/Loot/Common13.nbt,10,CHEST:3,../../../Chests/Loot/Common14.nbt,10,CHEST:3,../../../Chests/Loot/Common15.nbt,10,CHEST:3,../../../Chests/Lore/Quarry_1.nbt,2,CHEST:3,../../../Chests/Lore/Quarry_3.nbt,2,CHEST:3,../../../Chests/Lore/Quarry_4.nbt,2,CHEST:3,../../../Chests/Lore/Quarry_5.nbt,2,CHEST:3,../../../Chests/Lore/Quarry_5.nbt,2,CHEST:3,../../../Chests/Loot/Rare1.nbt,5,CHEST:3,../../../Chests/Loot/Rare2.nbt,5,CHEST:3,../../../Chests/Loot/Rare3.nbt,5,CHEST:3,../../../Chests/Loot/Rare4.nbt,5,CHEST:3,../../../Chests/Loot/Rare5.nbt,5,CHEST:3,../../../Chests/Loot/Rare6.nbt,5,CHEST:3,../../../Chests/Loot/Rare7.nbt,5,CHEST:3,../../../Chests/Loot/Rare8.nbt,5,CHEST:3,../../../Chests/Loot/Rare9.nbt,5,CHEST:3,../../../Chests/Loot/Rare10.nbt,5,CHEST:3,../../../Chests/Loot/Rare11.nbt,5,CHEST:3,../../../Chests/Loot/Rare12.nbt,5,CHEST:3,../../../Chests/Loot/Rare13.nbt,5,CHEST:3,../../../Chests/Loot/Rare14.nbt,5,CHEST:3,../../../Chests/Loot/Rare15.nbt,5,CHEST:3,../../../Chests/Loot/Epic1.nbt,2,CHEST:3,../../../Chests/Loot/Epic2.nbt,2,CHEST:3,../../../Chests/Loot/Epic3.nbt,2,CHEST:3,../../../Chests/Loot/Epic4.nbt,2,CHEST:3,../../../Chests/Loot/Epic5.nbt,2,CHEST:3,../../../Chests/Loot/Epic6.nbt,2,CHEST:3,../../../Chests/Loot/Epic7.nbt,2,CHEST:3,../../../Chests/Loot/Epic8.nbt,2,CHEST:3,../../../Chests/Loot/Epic9.nbt,2,CHEST:3,../../../Chests/Loot/Epic10.nbt,2,CHEST:3,../../../Chests/Loot/Epic11.nbt,2,CHEST:3,../../../Chests/Loot/Epic12.nbt,2,CHEST:3,../../../Chests/Loot/Epic13.nbt,2,CHEST:3,../../../Chests/Loot/Epic14.nbt,2,CHEST:3,../../../Chests/Loot/Epic15.nbt,5,CHEST:3,../../../Chests/Loot/Rare1.nbt,5,CHEST:3,../../../Chests/Loot/Rare2.nbt,5,CHEST:3,../../../Chests/Loot/Rare3.nbt,5,CHEST:3,../../../Chests/Loot/Rare4.nbt,5,CHEST:3,../../../Chests/Loot/Rare5.nbt,10,CHEST:3,../../../Chests/Loot/Rare6.nbt,10,CHEST:3,../../../Chests/Loot/Rare7.nbt,10,CHEST:3,../../../Chests/Loot/Rare8.nbt,10,CHEST:3,../../../Chests/Loot/Rare9.nbt,10,CHEST:3,../../../Chests/Loot/Rare10.nbt,15,CHEST:3,../../../Chests/Loot/Rare11.nbt,15,CHEST:3,../../../Chests/Loot/Rare12.nbt,15,CHEST:3,../../../Chests/Loot/Rare13.nbt,15,CHEST:3,../../../Chests/Loot/Rare14.nbt,15,CHEST:3,../../../Chests/Loot/Rare15.nbt,15,CHEST:3,../../../Chests/Loot/Epic15.nbt,100)
Block(-7,0,-7,STONE:0)
RandomBlock(-7,0,-6,COAL_ORE,33,STONE,100)
RandomBlock(-7,0,-5,COAL_ORE,33,STONE,100)
Block(-7,0,-4,STONE:0)
Block(-7,0,-3,STONE:0)
RandomBlock(-7,0,-2,COAL_ORE,33,STONE,100)
Block(-7,0,-1,STONE:0)
Block(-7,0,0,STONE:0)
Block(-7,0,1,STONE:0)
Block(-7,0,2,STONE:0)
Block(-7,0,3,STONE:0)
Block(-7,0,4,STONE:0)
RandomBlock(-7,0,5,COAL_ORE,33,STONE,100)
RandomBlock(-7,0,6,COAL_ORE,33,STONE,100)
Block(-7,0,7,STONE:0)
RandomBlock(-7,0,8,COAL_ORE,33,STONE,100)
RandomBlock(-7,1,-7,COAL_ORE,33,STONE,100)
RandomBlock(-7,1,-6,COAL_ORE,33,STONE,100)
RandomBlock(-7,1,-5,COAL_ORE,33,STONE,100)
RandomBlock(-7,1,-4,COAL_ORE,33,STONE,100)
RandomBlock(-7,1,-3,COAL_ORE,33,STONE,100)
Block(-7,1,-2,STONE:0)
Block(-7,1,-1,STONE:0)
RandomBlock(-7,1,0,COAL_ORE,33,STONE,100)
Block(-7,1,1,STONE:0)
RandomBlock(-7,1,2,COAL_ORE,33,STONE,100)
Block(-7,1,3,STONE:0)
RandomBlock(-7,1,4,COAL_ORE,33,STONE,100)
RandomBlock(-7,1,5,COAL_ORE,33,STONE,100)
RandomBlock(-7,1,6,COAL_ORE,33,STONE,100)
Block(-7,1,7,STONE:0)
Block(-7,1,8,STONE:0)
RandomBlock(-7,2,-7,COAL_ORE,33,STONE,100)
RandomBlock(-7,2,-6,COAL_ORE,33,STONE,100)
Block(-7,2,-5,STONE:0)
Block(-7,2,-4,STONE:0)
Block(-7,2,-3,STONE:0)
RandomBlock(-7,2,-2,COAL_ORE,33,STONE,100)
RandomBlock(-7,2,-1,COAL_ORE,33,STONE,100)
RandomBlock(-7,2,0,COAL_ORE,33,STONE,100)
Block(-7,2,1,STONE:0)
Block(-7,2,2,STONE:0)
Block(-7,2,3,STONE:0)
Block(-7,2,4,STONE:0)
RandomBlock(-7,2,5,COAL_ORE,33,STONE,100)
Block(-7,2,6,STONE:0)
Block(-7,2,7,STONE:0)
Block(-7,2,8,STONE:0)
RandomBlock(-7,3,-7,COAL_ORE,33,STONE,100)
Block(-7,3,-6,STONE:0)
RandomBlock(-7,3,-5,COAL_ORE,33,STONE,100)
RandomBlock(-7,3,-4,COAL_ORE,33,STONE,100)
RandomBlock(-7,3,-3,COAL_ORE,33,STONE,100)
Block(-7,3,-2,STONE:0)
Block(-7,3,-1,STONE:0)
RandomBlock(-7,3,0,COAL_ORE,33,STONE,100)
Block(-7,3,1,STONE:0)
RandomBlock(-7,3,2,COAL_ORE,33,STONE,100)
RandomBlock(-7,3,3,COAL_ORE,33,STONE,100)
Block(-7,3,4,STONE:0)
Block(-7,3,5,STONE:0)
Block(-7,3,6,STONE:0)
Block(-7,3,7,STONE:0)
Block(-7,3,8,STONE:0)
Block(-7,4,-7,STONE:0)
RandomBlock(-7,4,-6,COAL_ORE,33,STONE,100)
Block(-7,4,-5,STONE:0)
Block(-7,4,-4,STONE:0)
RandomBlock(-7,4,-3,COAL_ORE,33,STONE,100)
Block(-7,4,-2,STONE:0)
Block(-7,4,-1,STONE:0)
Block(-7,4,0,STONE:0)
RandomBlock(-7,4,1,COAL_ORE,33,STONE,100)
Block(-7,4,2,STONE:0)
Block(-7,4,3,STONE:0)
Block(-7,4,4,STONE:0)
Block(-7,4,5,STONE:0)
Block(-7,4,6,STONE:0)
RandomBlock(-7,4,7,COAL_ORE,33,STONE,100)
RandomBlock(-7,4,8,COAL_ORE,33,STONE,100)
RandomBlock(-7,5,-7,COAL_ORE,33,STONE,100)
Block(-7,5,-6,STONE:0)
Block(-7,5,-5,STONE:0)
RandomBlock(-7,5,-4,COAL_ORE,33,STONE,100)
RandomBlock(-7,5,-3,COAL_ORE,33,STONE,100)
Block(-7,5,-2,STONE:0)
Block(-7,5,-1,STONE:0)
Block(-7,5,0,STONE:0)
RandomBlock(-7,5,1,COAL_ORE,33,STONE,100)
Block(-7,5,2,STONE:0)
RandomBlock(-7,5,3,COAL_ORE,33,STONE,100)
Block(-7,5,4,STONE:0)
Block(-7,5,5,STONE:0)
RandomBlock(-7,5,6,COAL_ORE,33,STONE,100)
RandomBlock(-7,5,7,COAL_ORE,33,STONE,100)
RandomBlock(-7,5,8,COAL_ORE,33,STONE,100)
Block(-7,6,-7,STONE:0)
Block(-7,6,-6,STONE:0)
Block(-7,6,-5,STONE:0)
RandomBlock(-7,6,-4,COAL_ORE,33,STONE,100)
Block(-7,6,-3,STONE:0)
Block(-7,6,-2,STONE:0)
Block(-7,6,-1,STONE:0)
Block(-7,6,0,STONE:0)
Block(-7,6,1,STONE:0)
Block(-7,6,2,STONE:0)
Block(-7,6,3,STONE:0)
Block(-7,6,4,STONE:0)
Block(-7,6,5,STONE:0)
Block(-7,6,6,STONE:0)
RandomBlock(-7,6,7,COAL_ORE,33,STONE,100)
Block(-7,6,8,STONE:0)
RandomBlock(-7,7,-7,COAL_ORE,33,STONE,100)
Block(-7,7,-6,STONE:0)
Block(-7,7,-5,STONE:0)
Block(-7,7,-4,STONE:0)
Block(-7,7,-3,STONE:0)
Block(-7,7,-2,STONE:0)
Block(-7,7,-1,STONE:0)
Block(-7,7,0,STONE:0)
Block(-7,7,1,STONE:0)
Block(-7,7,2,STONE:0)
RandomBlock(-7,7,3,COAL_ORE,33,STONE,100)
Block(-7,7,4,STONE:0)
Block(-7,7,5,STONE:0)
Block(-7,7,6,STONE:0)
RandomBlock(-7,7,7,COAL_ORE,33,STONE,100)
Block(-7,7,8,STONE:0)
RandomBlock(-7,8,-7,COAL_ORE,33,STONE,100)
Block(-7,8,-6,STONE:0)
RandomBlock(-7,8,-5,COAL_ORE,33,STONE,100)
RandomBlock(-7,8,-4,COAL_ORE,33,STONE,100)
Block(-7,8,-3,STONE:0)
RandomBlock(-7,8,-2,COAL_ORE,33,STONE,100)
RandomBlock(-7,8,-1,COAL_ORE,33,STONE,100)
Block(-7,8,0,STONE:0)
RandomBlock(-7,8,1,COAL_ORE,33,STONE,100)
Block(-7,8,2,STONE:0)
Block(-7,8,3,STONE:0)
RandomBlock(-7,8,4,COAL_ORE,33,STONE,100)
RandomBlock(-7,8,5,COAL_ORE,33,STONE,100)
RandomBlock(-7,8,6,COAL_ORE,33,STONE,100)
Block(-7,8,7,STONE:0)
RandomBlock(-7,8,8,COAL_ORE,33,STONE,100)
RandomBlock(-7,9,-7,COAL_ORE,33,STONE,100)
Block(-7,9,-6,STONE:0)
Block(-7,9,-5,SPRUCE_FENCE:0)
Block(-7,9,-4,LOG:1)
RandomBlock(-7,9,-3,SKULL:1,../../../Skulls/dungeon_skull_01.nbt,6,AIR,9,SKULL:1,../../../Skulls/dungeon_skull_02.nbt,12,AIR,15,SKULL:1,../../../Skulls/dungeon_skull_03.nbt,18,AIR,21,SKULL:1,../../../Skulls/dungeon_skull_04.nbt,24,AIR,27,SKULL:1,../../../Skulls/dungeon_skull_05.nbt,30,AIR,33,SKULL:1,../../../Skulls/dungeon_skull_06.nbt,36,AIR,39,SKULL:1,../../../Skulls/dungeon_skull_07.nbt,42,AIR,45,SKULL:1,../../../Skulls/dungeon_skull_08.nbt,48,AIR,51,SKULL:1,../../../Skulls/dungeon_skull_09.nbt,54,AIR,57,SKULL:1,../../../Skulls/dungeon_skull_10.nbt,60,AIR,63,SKULL:1,../../../Skulls/dungeon_skull_11.nbt,66,AIR,69,SKULL:1,../../../Skulls/dungeon_skull_12.nbt,72,AIR,75,SKULL:1,../../../Skulls/dungeon_skull_13.nbt,78,AIR,81,SKULL:1,../../../Skulls/dungeon_skull_14.nbt,84,AIR,87,SKULL:1,../../../Skulls/dungeon_skull_15.nbt,90,AIR,93,SKULL:1,../../../Skulls/dungeon_skull_16.nbt,96,AIR,100)
Block(-7,9,-2,STONE:0)
Block(-7,9,-1,STONE:0)
Block(-7,9,0,STONE:0)
RandomBlock(-7,9,1,COAL_ORE,33,STONE,100)
Block(-7,9,2,STONE:0)
RandomBlock(-7,9,3,COAL_ORE,33,STONE,100)
RandomBlock(-7,9,4,COAL_ORE,33,STONE,100)
Block(-7,9,5,STONE:0)
RandomBlock(-7,9,6,COAL_ORE,33,STONE,100)
RandomBlock(-7,9,7,COAL_ORE,33,STONE,100)
RandomBlock(-7,9,8,COAL_ORE,33,STONE,100)
Block(-7,10,-7,STONE:0)
RandomBlock(-7,10,-6,COAL_ORE,33,STONE,100)
Block(-7,10,-5,SPRUCE_FENCE:0)
Block(-7,10,-4,LOG:1)
Block(-7,10,-3,AIR:0)
Block(-7,10,-2,STONE:0)
RandomBlock(-7,10,-1,COAL_ORE,33,STONE,100)
RandomBlock(-7,10,0,COAL_ORE,33,STONE,100)
Block(-7,10,1,STONE:0)
Block(-7,10,2,STONE:0)
RandomBlock(-7,10,3,COAL_ORE,33,STONE,100)
Block(-7,10,4,STONE:0)
Block(-7,10,5,STONE:0)
RandomBlock(-7,10,6,COAL_ORE,33,STONE,100)
RandomBlock(-7,10,7,COAL_ORE,33,STONE,100)
Block(-7,10,8,STONE:0)
Block(-7,11,-7,STONE:0)
Block(-7,11,-6,STONE:0)
Block(-7,11,-5,SPRUCE_FENCE:0)
Block(-7,11,-4,LOG:1)
Block(-7,11,-3,AIR:0)
Block(-7,11,-2,AIR:0)
RandomBlock(-7,11,-1,SKULL:1,../../../Skulls/dungeon_skull_01.nbt,6,AIR,9,SKULL:1,../../../Skulls/dungeon_skull_02.nbt,12,AIR,15,SKULL:1,../../../Skulls/dungeon_skull_03.nbt,18,AIR,21,SKULL:1,../../../Skulls/dungeon_skull_04.nbt,24,AIR,27,SKULL:1,../../../Skulls/dungeon_skull_05.nbt,30,AIR,33,SKULL:1,../../../Skulls/dungeon_skull_06.nbt,36,AIR,39,SKULL:1,../../../Skulls/dungeon_skull_07.nbt,42,AIR,45,SKULL:1,../../../Skulls/dungeon_skull_08.nbt,48,AIR,51,SKULL:1,../../../Skulls/dungeon_skull_09.nbt,54,AIR,57,SKULL:1,../../../Skulls/dungeon_skull_10.nbt,60,AIR,63,SKULL:1,../../../Skulls/dungeon_skull_11.nbt,66,AIR,69,SKULL:1,../../../Skulls/dungeon_skull_12.nbt,72,AIR,75,SKULL:1,../../../Skulls/dungeon_skull_13.nbt,78,AIR,81,SKULL:1,../../../Skulls/dungeon_skull_14.nbt,84,AIR,87,SKULL:1,../../../Skulls/dungeon_skull_15.nbt,90,AIR,93,SKULL:1,../../../Skulls/dungeon_skull_16.nbt,96,AIR,100)
Block(-7,11,0,SPRUCE_FENCE:0)
Block(-7,11,1,SPRUCE_FENCE:0)
Block(-7,11,2,STONE:0)
Block(-7,11,3,STONE:0)
Block(-7,11,4,STONE:0)
Block(-7,11,5,AIR:0)
RandomBlock(-7,11,6,COAL_ORE,33,STONE,100)
Block(-7,11,7,STONE:0)
Block(-7,11,8,STONE:0)
RandomBlock(-7,12,-7,COAL_ORE,33,STONE,100)
Block(-7,12,-6,STONE:0)
Block(-7,12,-5,SPRUCE_FENCE:0)
Block(-7,12,-4,LOG:1)
Block(-7,12,-3,AIR:0)
Block(-7,12,-2,AIR:0)
Block(-7,12,-1,AIR:0)
Block(-7,12,0,WOOD_STEP:1)
Block(-7,12,1,WOOD_STEP:1)
Block(-7,12,2,WOOD_STEP:1)
Block(-7,12,3,WOOD_STEP:1)
Block(-7,12,4,WOOD_STEP:1)
Block(-7,12,5,AIR:0)
Block(-7,12,6,STONE:0)
RandomBlock(-7,12,7,COAL_ORE,33,STONE,100)
Block(-7,12,8,STONE:0)
Block(-7,13,-7,STONE:0)
Block(-7,13,-6,STONE:0)
Block(-7,13,-5,SPRUCE_FENCE:0)
Block(-7,13,-4,LOG:1)
Block(-7,13,-3,AIR:0)
Block(-7,13,-2,AIR:0)
Block(-7,13,-1,AIR:0)
Block(-7,13,0,AIR:0)
Block(-7,13,1,AIR:0)
Block(-7,13,2,AIR:0)
Block(-7,13,3,AIR:0)
Block(-7,13,4,AIR:0)
Block(-7,13,5,AIR:0)
Block(-7,13,6,STONE:0)
Block(-7,13,7,STONE:0)
RandomBlock(-7,13,8,COAL_ORE,33,STONE,100)
Block(-7,14,-7,STONE:0)
Block(-7,14,-6,STONE:0)
Block(-7,14,-5,SPRUCE_FENCE:0)
Block(-7,14,-4,LOG:1)
Block(-7,14,-3,AIR:0)
Block(-7,14,-2,AIR:0)
Block(-7,14,-1,AIR:0)
Block(-7,14,0,AIR:0)
Block(-7,14,1,AIR:0)
Block(-7,14,2,AIR:0)
Block(-7,14,3,AIR:0)
Block(-7,14,4,AIR:0)
Block(-7,14,5,AIR:0)
Block(-7,14,6,STONE:0)
Block(-7,14,7,STONE:0)
RandomBlock(-7,14,8,COAL_ORE,33,STONE,100)
Block(-7,15,-7,STONE:0)
Block(-7,15,-6,STONE:0)
Block(-7,15,-5,SPRUCE_FENCE:0)
Block(-7,15,-4,LOG:1)
Block(-7,15,-3,AIR:0)
Block(-7,15,-2,AIR:0)
Block(-7,15,-1,AIR:0)
Block(-7,15,0,AIR:0)
Block(-7,15,1,AIR:0)
Block(-7,15,2,AIR:0)
Block(-7,15,3,AIR:0)
Block(-7,15,4,AIR:0)
Block(-7,15,5,AIR:0)
Block(-7,15,6,STONE:0)
RandomBlock(-7,15,7,COAL_ORE,33,STONE,100)
Block(-7,15,8,STONE:0)
Block(-7,16,-7,STONE:0)
Block(-7,16,-6,SPRUCE_FENCE:0)
Block(-7,16,-5,SPRUCE_FENCE:0)
Block(-7,16,-4,LOG:1)
Block(-7,16,-3,AIR:0)
Block(-7,16,-2,AIR:0)
Block(-7,16,-1,AIR:0)
Block(-7,16,0,AIR:0)
Block(-7,16,1,AIR:0)
Block(-7,16,2,AIR:0)
Block(-7,16,3,AIR:0)
Block(-7,16,4,AIR:0)
RandomBlock(-7,16,5,WEB:0,25,AIR:0,100)
Block(-7,16,6,SPRUCE_FENCE:0)
Block(-7,16,7,LOG:1)
Block(-7,16,8,STONE:0)
Block(-7,17,-7,SPRUCE_FENCE:0)
Block(-7,17,-6,SPRUCE_FENCE:0)
Block(-7,17,-5,SPRUCE_FENCE:0)
Block(-7,17,-4,LOG:1)
Block(-7,17,-3,AIR:0)
Block(-7,17,-2,AIR:0)
Block(-7,17,-1,AIR:0)
Block(-7,17,0,AIR:0)
Block(-7,17,1,AIR:0)
Block(-7,17,2,AIR:0)
Block(-7,17,3,AIR:0)
Block(-7,17,4,SPRUCE_FENCE:0)
Block(-7,17,5,SPRUCE_FENCE:0)
Block(-7,17,6,SPRUCE_FENCE:0)
Block(-7,17,7,LOG:1)
Block(-7,17,8,STONE:0)
Block(-7,18,-7,WOOD_STEP:1)
Block(-7,18,-6,WOOD_STEP:1)
Block(-7,18,-5,WOOD_STEP:1)
Block(-7,18,-4,LOG:1)
Block(-7,18,-3,AIR:0)
Block(-7,18,-2,AIR:0)
Block(-7,18,-1,AIR:0)
Block(-7,18,0,AIR:0)
Block(-7,18,1,AIR:0)
Block(-7,18,2,AIR:0)
Block(-7,18,3,AIR:0)
Block(-7,18,4,WOOD_STEP:1)
Block(-7,18,5,WOOD_STEP:1)
Block(-7,18,6,SPRUCE_FENCE:0)
Block(-7,18,7,LOG:1)
Block(-7,18,8,SPRUCE_FENCE:0)
Block(-7,19,-7,AIR:0)
Block(-7,19,-6,AIR:0)
Block(-7,19,-5,AIR:0)
Block(-7,19,-4,LOG:1)
Block(-7,19,-3,AIR:0)
Block(-7,19,-2,AIR:0)
Block(-7,19,-1,AIR:0)
Block(-7,19,0,AIR:0)
Block(-7,19,1,AIR:0)
Block(-7,19,2,AIR:0)
Block(-7,19,3,AIR:0)
Block(-7,19,4,AIR:0)
Block(-7,19,5,AIR:0)
Block(-7,19,6,SPRUCE_FENCE:0)
Block(-7,19,7,LOG:1)
Block(-7,19,8,SPRUCE_FENCE:0)
Block(-7,20,-4,LOG:1)
Block(-7,20,6,WOOD_STEP:1)
Block(-7,20,7,WOOD_STEP:1)
Block(-7,20,8,WOOD_STEP:1)
Block(-7,21,-4,DARK_OAK_STAIRS:1)
Block(-7,23,-5,DARK_OAK_STAIRS:5)
Block(-7,23,-2,DARK_OAK_STAIRS:5)
Block(-7,23,1,DARK_OAK_STAIRS:5)
Block(-7,24,-7,WOOD_STEP:1)
Block(-7,24,-6,WOOD_DOUBLE_STEP:1)
Block(-7,24,-5,LOG:1)
Block(-7,24,-2,LOG:1)
Block(-7,24,-1,SPRUCE_FENCE:0)
Block(-7,24,0,SPRUCE_FENCE:0)
Block(-7,24,1,LOG:1)
Block(-7,25,-5,WOOD_STEP:1)
Block(-7,25,-4,WOOD_STEP:1)
Block(-7,25,-3,WOOD_DOUBLE_STEP:1)
Block(-7,25,-2,LOG:1)
Block(-7,25,-1,SPRUCE_FENCE:0)
Block(-7,25,0,SPRUCE_FENCE:0)
Block(-7,25,1,LOG:1)
Block(-7,26,-2,WOOD_STEP:1)
Block(-7,26,-1,WOOD_STEP:1)
Block(-7,26,0,WOOD_STEP:1)
Block(-7,26,1,WOOD_STEP:1)
Block(-6,0,-7,STONE:0)
Block(-6,0,-6,STONE:0)
RandomBlock(-6,0,-5,COAL_ORE,33,STONE,100)
Block(-6,0,-4,STONE:0)
Block(-6,0,-3,STONE:0)
Block(-6,0,-2,STONE:0)
Block(-6,0,-1,STONE:0)
Block(-6,0,0,STONE:0)
RandomBlock(-6,0,1,COAL_ORE,33,STONE,100)
RandomBlock(-6,0,2,COAL_ORE,33,STONE,100)
Block(-6,0,3,STONE:0)
Block(-6,0,4,STONE:0)
Block(-6,0,5,STONE:0)
Block(-6,0,6,STONE:0)
Block(-6,0,7,STONE:0)
Block(-6,0,8,STONE:0)
RandomBlock(-6,1,-7,COAL_ORE,33,STONE,100)
RandomBlock(-6,1,-6,COAL_ORE,33,STONE,100)
RandomBlock(-6,1,-5,COAL_ORE,33,STONE,100)
Block(-6,1,-4,STONE:0)
Block(-6,1,-3,STONE:0)
RandomBlock(-6,1,-2,COAL_ORE,33,STONE,100)
Block(-6,1,-1,STONE:0)
RandomBlock(-6,1,0,COAL_ORE,33,STONE,100)
RandomBlock(-6,1,1,COAL_ORE,33,STONE,100)
RandomBlock(-6,1,2,COAL_ORE,33,STONE,100)
RandomBlock(-6,1,3,COAL_ORE,33,STONE,100)
Block(-6,1,4,STONE:0)
RandomBlock(-6,1,5,COAL_ORE,33,STONE,100)
Block(-6,1,6,STONE:0)
RandomBlock(-6,1,7,COAL_ORE,33,STONE,100)
RandomBlock(-6,1,8,COAL_ORE,33,STONE,100)
RandomBlock(-6,2,-7,COAL_ORE,33,STONE,100)
Block(-6,2,-6,STONE:0)
RandomBlock(-6,2,-5,COAL_ORE,33,STONE,100)
Block(-6,2,-4,STONE:0)
RandomBlock(-6,2,-3,COAL_ORE,33,STONE,100)
RandomBlock(-6,2,-2,COAL_ORE,33,STONE,100)
Block(-6,2,-1,STONE:0)
Block(-6,2,0,STONE:0)
RandomBlock(-6,2,1,COAL_ORE,33,STONE,100)
Block(-6,2,2,STONE:0)
RandomBlock(-6,2,3,COAL_ORE,33,STONE,100)
Block(-6,2,4,STONE:0)
Block(-6,2,5,STONE:0)
Block(-6,2,6,STONE:0)
Block(-6,2,7,STONE:0)
Block(-6,2,8,STONE:0)
RandomBlock(-6,3,-7,COAL_ORE,33,STONE,100)
RandomBlock(-6,3,-6,COAL_ORE,33,STONE,100)
RandomBlock(-6,3,-5,COAL_ORE,33,STONE,100)
RandomBlock(-6,3,-4,COAL_ORE,33,STONE,100)
RandomBlock(-6,3,-3,COAL_ORE,33,STONE,100)
Block(-6,3,-2,STONE:0)
RandomBlock(-6,3,-1,COAL_ORE,33,STONE,100)
RandomBlock(-6,3,0,COAL_ORE,33,STONE,100)
RandomBlock(-6,3,1,COAL_ORE,33,STONE,100)
Block(-6,3,2,STONE:0)
RandomBlock(-6,3,3,COAL_ORE,33,STONE,100)
Block(-6,3,4,STONE:0)
Block(-6,3,5,STONE:0)
Block(-6,3,6,STONE:0)
Block(-6,3,7,STONE:0)
Block(-6,3,8,STONE:0)
Block(-6,4,-7,STONE:0)
Block(-6,4,-6,STONE:0)
RandomBlock(-6,4,-5,COAL_ORE,33,STONE,100)
Block(-6,4,-4,STONE:0)
Block(-6,4,-3,STONE:0)
Block(-6,4,-2,STONE:0)
RandomBlock(-6,4,-1,COAL_ORE,33,STONE,100)
Block(-6,4,0,STONE:0)
Block(-6,4,1,STONE:0)
Block(-6,4,2,STONE:0)
RandomBlock(-6,4,3,COAL_ORE,33,STONE,100)
Block(-6,4,4,STONE:0)
Block(-6,4,5,STONE:0)
Block(-6,4,6,STONE:0)
RandomBlock(-6,4,7,COAL_ORE,33,STONE,100)
RandomBlock(-6,4,8,COAL_ORE,33,STONE,100)
RandomBlock(-6,5,-7,COAL_ORE,33,STONE,100)
RandomBlock(-6,5,-6,COAL_ORE,33,STONE,100)
RandomBlock(-6,5,-5,COAL_ORE,33,STONE,100)
RandomBlock(-6,5,-4,COAL_ORE,33,STONE,100)
Block(-6,5,-3,STONE:0)
Block(-6,5,-2,STONE:0)
RandomBlock(-6,5,-1,COAL_ORE,33,STONE,100)
RandomBlock(-6,5,0,COAL_ORE,33,STONE,100)
Block(-6,5,1,STONE:0)
Block(-6,5,2,STONE:0)
Block(-6,5,3,STONE:0)
Block(-6,5,4,STONE:0)
Block(-6,5,5,STONE:0)
Block(-6,5,6,STONE:0)
Block(-6,5,7,STONE:0)
RandomBlock(-6,5,8,COAL_ORE,33,STONE,100)
RandomBlock(-6,6,-7,COAL_ORE,33,STONE,100)
RandomBlock(-6,6,-6,COAL_ORE,33,STONE,100)
Block(-6,6,-5,STONE:0)
RandomBlock(-6,6,-4,COAL_ORE,33,STONE,100)
RandomBlock(-6,6,-3,COAL_ORE,33,STONE,100)
RandomBlock(-6,6,-2,COAL_ORE,33,STONE,100)
Block(-6,6,-1,STONE:0)
Block(-6,6,0,STONE:0)
Block(-6,6,1,STONE:0)
Block(-6,6,2,STONE:0)
RandomBlock(-6,6,3,COAL_ORE,33,STONE,100)
Block(-6,6,4,STONE:0)
RandomBlock(-6,6,5,COAL_ORE,33,STONE,100)
RandomBlock(-6,6,6,COAL_ORE,33,STONE,100)
Block(-6,6,7,STONE:0)
Block(-6,6,8,STONE:0)
Block(-6,7,-7,STONE:0)
Block(-6,7,-6,STONE:0)
Block(-6,7,-5,STONE:0)
Block(-6,7,-4,STONE:0)
Block(-6,7,-3,STONE:0)
Block(-6,7,-2,STONE:0)
RandomBlock(-6,7,-1,COAL_ORE,33,STONE,100)
RandomBlock(-6,7,0,COAL_ORE,33,STONE,100)
RandomBlock(-6,7,1,COAL_ORE,33,STONE,100)
Block(-6,7,2,STONE:0)
Block(-6,7,3,STONE:0)
RandomBlock(-6,7,4,COAL_ORE,33,STONE,100)
RandomBlock(-6,7,5,COAL_ORE,33,STONE,100)
RandomBlock(-6,7,6,COAL_ORE,33,STONE,100)
RandomBlock(-6,7,7,COAL_ORE,33,STONE,100)
RandomBlock(-6,7,8,COAL_ORE,33,STONE,100)
Block(-6,8,-7,STONE:0)
Block(-6,8,-6,STONE:0)
RandomBlock(-6,8,-5,COAL_ORE,33,STONE,100)
Block(-6,8,-4,STONE:0)
Block(-6,8,-3,STONE:0)
Block(-6,8,-2,STONE:0)
Block(-6,8,-1,STONE:0)
RandomBlock(-6,8,0,COAL_ORE,33,STONE,100)
RandomBlock(-6,8,1,COAL_ORE,33,STONE,100)
Block(-6,8,2,STONE:0)
Block(-6,8,3,STONE:0)
RandomBlock(-6,8,4,COAL_ORE,33,STONE,100)
Block(-6,8,5,STONE:0)
Block(-6,8,6,STONE:0)
Block(-6,8,7,STONE:0)
Block(-6,8,8,STONE:0)
RandomBlock(-6,9,-7,COAL_ORE,33,STONE,100)
Block(-6,9,-6,SPRUCE_FENCE:0)
RandomBlock(-6,9,-5,SKULL:1,../../../Skulls/dungeon_skull_01.nbt,6,AIR,9,SKULL:1,../../../Skulls/dungeon_skull_02.nbt,12,AIR,15,SKULL:1,../../../Skulls/dungeon_skull_03.nbt,18,AIR,21,SKULL:1,../../../Skulls/dungeon_skull_04.nbt,24,AIR,27,SKULL:1,../../../Skulls/dungeon_skull_05.nbt,30,AIR,33,SKULL:1,../../../Skulls/dungeon_skull_06.nbt,36,AIR,39,SKULL:1,../../../Skulls/dungeon_skull_07.nbt,42,AIR,45,SKULL:1,../../../Skulls/dungeon_skull_08.nbt,48,AIR,51,SKULL:1,../../../Skulls/dungeon_skull_09.nbt,54,AIR,57,SKULL:1,../../../Skulls/dungeon_skull_10.nbt,60,AIR,63,SKULL:1,../../../Skulls/dungeon_skull_11.nbt,66,AIR,69,SKULL:1,../../../Skulls/dungeon_skull_12.nbt,72,AIR,75,SKULL:1,../../../Skulls/dungeon_skull_13.nbt,78,AIR,81,SKULL:1,../../../Skulls/dungeon_skull_14.nbt,84,AIR,87,SKULL:1,../../../Skulls/dungeon_skull_15.nbt,90,AIR,93,SKULL:1,../../../Skulls/dungeon_skull_16.nbt,96,AIR,100)
RandomBlock(-6,9,-4,SKULL:1,../../../Skulls/dungeon_skull_01.nbt,6,AIR,9,SKULL:1,../../../Skulls/dungeon_skull_02.nbt,12,AIR,15,SKULL:1,../../../Skulls/dungeon_skull_03.nbt,18,AIR,21,SKULL:1,../../../Skulls/dungeon_skull_04.nbt,24,AIR,27,SKULL:1,../../../Skulls/dungeon_skull_05.nbt,30,AIR,33,SKULL:1,../../../Skulls/dungeon_skull_06.nbt,36,AIR,39,SKULL:1,../../../Skulls/dungeon_skull_07.nbt,42,AIR,45,SKULL:1,../../../Skulls/dungeon_skull_08.nbt,48,AIR,51,SKULL:1,../../../Skulls/dungeon_skull_09.nbt,54,AIR,57,SKULL:1,../../../Skulls/dungeon_skull_10.nbt,60,AIR,63,SKULL:1,../../../Skulls/dungeon_skull_11.nbt,66,AIR,69,SKULL:1,../../../Skulls/dungeon_skull_12.nbt,72,AIR,75,SKULL:1,../../../Skulls/dungeon_skull_13.nbt,78,AIR,81,SKULL:1,../../../Skulls/dungeon_skull_14.nbt,84,AIR,87,SKULL:1,../../../Skulls/dungeon_skull_15.nbt,90,AIR,93,SKULL:1,../../../Skulls/dungeon_skull_16.nbt,96,AIR,100)
RandomBlock(-6,9,-3,SKULL:1,../../../Skulls/dungeon_skull_01.nbt,6,AIR,9,SKULL:1,../../../Skulls/dungeon_skull_02.nbt,12,AIR,15,SKULL:1,../../../Skulls/dungeon_skull_03.nbt,18,AIR,21,SKULL:1,../../../Skulls/dungeon_skull_04.nbt,24,AIR,27,SKULL:1,../../../Skulls/dungeon_skull_05.nbt,30,AIR,33,SKULL:1,../../../Skulls/dungeon_skull_06.nbt,36,AIR,39,SKULL:1,../../../Skulls/dungeon_skull_07.nbt,42,AIR,45,SKULL:1,../../../Skulls/dungeon_skull_08.nbt,48,AIR,51,SKULL:1,../../../Skulls/dungeon_skull_09.nbt,54,AIR,57,SKULL:1,../../../Skulls/dungeon_skull_10.nbt,60,AIR,63,SKULL:1,../../../Skulls/dungeon_skull_11.nbt,66,AIR,69,SKULL:1,../../../Skulls/dungeon_skull_12.nbt,72,AIR,75,SKULL:1,../../../Skulls/dungeon_skull_13.nbt,78,AIR,81,SKULL:1,../../../Skulls/dungeon_skull_14.nbt,84,AIR,87,SKULL:1,../../../Skulls/dungeon_skull_15.nbt,90,AIR,93,SKULL:1,../../../Skulls/dungeon_skull_16.nbt,96,AIR,100)
RandomBlock(-6,9,-2,SKULL:1,../../../Skulls/dungeon_skull_01.nbt,6,AIR,9,SKULL:1,../../../Skulls/dungeon_skull_02.nbt,12,AIR,15,SKULL:1,../../../Skulls/dungeon_skull_03.nbt,18,AIR,21,SKULL:1,../../../Skulls/dungeon_skull_04.nbt,24,AIR,27,SKULL:1,../../../Skulls/dungeon_skull_05.nbt,30,AIR,33,SKULL:1,../../../Skulls/dungeon_skull_06.nbt,36,AIR,39,SKULL:1,../../../Skulls/dungeon_skull_07.nbt,42,AIR,45,SKULL:1,../../../Skulls/dungeon_skull_08.nbt,48,AIR,51,SKULL:1,../../../Skulls/dungeon_skull_09.nbt,54,AIR,57,SKULL:1,../../../Skulls/dungeon_skull_10.nbt,60,AIR,63,SKULL:1,../../../Skulls/dungeon_skull_11.nbt,66,AIR,69,SKULL:1,../../../Skulls/dungeon_skull_12.nbt,72,AIR,75,SKULL:1,../../../Skulls/dungeon_skull_13.nbt,78,AIR,81,SKULL:1,../../../Skulls/dungeon_skull_14.nbt,84,AIR,87,SKULL:1,../../../Skulls/dungeon_skull_15.nbt,90,AIR,93,SKULL:1,../../../Skulls/dungeon_skull_16.nbt,96,AIR,100)
Block(-6,9,-1,STONE:0)
Block(-6,9,0,STONE:0)
Block(-6,9,1,STONE:0)
Block(-6,9,2,STONE:0)
Block(-6,9,3,STONE:0)
RandomBlock(-6,9,4,COAL_ORE,33,STONE,100)
Block(-6,9,5,STONE:0)
Block(-6,9,6,STONE:0)
RandomBlock(-6,9,7,COAL_ORE,33,STONE,100)
Block(-6,9,8,STONE:0)
RandomBlock(-6,10,-7,COAL_ORE,33,STONE,100)
Block(-6,10,-6,SPRUCE_FENCE:0)
Block(-6,10,-5,AIR:0)
Block(-6,10,-4,AIR:0)
Block(-6,10,-3,AIR:0)
Block(-6,10,-2,AIR:0)
Block(-6,10,-1,STONE:0)
Block(-6,10,0,STONE:0)
Block(-6,10,1,STONE:0)
RandomBlock(-6,10,2,COAL_ORE,33,STONE,100)
RandomBlock(-6,10,3,COAL_ORE,33,STONE,100)
RandomBlock(-6,10,4,COAL_ORE,33,STONE,100)
RandomBlock(-6,10,5,COAL_ORE,33,STONE,100)
Block(-6,10,6,STONE:0)
Block(-6,10,7,STONE:0)
Block(-6,10,8,STONE:0)
RandomBlock(-6,11,-7,COAL_ORE,33,STONE,100)
Block(-6,11,-6,SPRUCE_FENCE:0)
Block(-6,11,-5,AIR:0)
Block(-6,11,-4,AIR:0)
Block(-6,11,-3,AIR:0)
Block(-6,11,-2,AIR:0)
RandomBlock(-6,11,-1,SKULL:1,../../../Skulls/dungeon_skull_01.nbt,6,AIR,9,SKULL:1,../../../Skulls/dungeon_skull_02.nbt,12,AIR,15,SKULL:1,../../../Skulls/dungeon_skull_03.nbt,18,AIR,21,SKULL:1,../../../Skulls/dungeon_skull_04.nbt,24,AIR,27,SKULL:1,../../../Skulls/dungeon_skull_05.nbt,30,AIR,33,SKULL:1,../../../Skulls/dungeon_skull_06.nbt,36,AIR,39,SKULL:1,../../../Skulls/dungeon_skull_07.nbt,42,AIR,45,SKULL:1,../../../Skulls/dungeon_skull_08.nbt,48,AIR,51,SKULL:1,../../../Skulls/dungeon_skull_09.nbt,54,AIR,57,SKULL:1,../../../Skulls/dungeon_skull_10.nbt,60,AIR,63,SKULL:1,../../../Skulls/dungeon_skull_11.nbt,66,AIR,69,SKULL:1,../../../Skulls/dungeon_skull_12.nbt,72,AIR,75,SKULL:1,../../../Skulls/dungeon_skull_13.nbt,78,AIR,81,SKULL:1,../../../Skulls/dungeon_skull_14.nbt,84,AIR,87,SKULL:1,../../../Skulls/dungeon_skull_15.nbt,90,AIR,93,SKULL:1,../../../Skulls/dungeon_skull_16.nbt,96,AIR,100)
Block(-6,11,0,SPRUCE_FENCE:0)
RandomBlock(-6,11,1,COAL_ORE,33,STONE,100)
Block(-6,11,2,STONE:0)
RandomBlock(-6,11,3,COAL_ORE,33,STONE,100)
Block(-6,11,4,SPRUCE_FENCE:0)
RandomBlock(-6,11,5,COAL_ORE,33,STONE,100)
RandomBlock(-6,11,6,COAL_ORE,33,STONE,100)
RandomBlock(-6,11,7,COAL_ORE,33,STONE,100)
RandomBlock(-6,11,8,COAL_ORE,33,STONE,100)
RandomBlock(-6,12,-7,COAL_ORE,33,STONE,100)
Block(-6,12,-6,SPRUCE_FENCE:0)
Block(-6,12,-5,SPRUCE_FENCE:0)
Block(-6,12,-4,SPRUCE_FENCE:0)
Block(-6,12,-3,AIR:0)
Block(-6,12,-2,AIR:0)
Block(-6,12,-1,AIR:0)
Block(-6,12,0,WOOD_STEP:1)
Block(-6,12,1,WOOD_STEP:1)
Block(-6,12,2,WOOD_STEP:1)
Block(-6,12,3,WOOD_STEP:1)
Block(-6,12,4,SPRUCE_FENCE:0)
RandomBlock(-6,12,5,COAL_ORE,33,STONE,100)
RandomBlock(-6,12,6,COAL_ORE,33,STONE,100)
Block(-6,12,7,STONE:0)
Block(-6,12,8,STONE:0)
RandomBlock(-6,13,-7,COAL_ORE,33,STONE,100)
Block(-6,13,-6,SPRUCE_FENCE:0)
Block(-6,13,-5,WOOD_STEP:1)
Block(-6,13,-4,WOOD_STEP:1)
Block(-6,13,-3,AIR:0)
Block(-6,13,-2,AIR:0)
Block(-6,13,-1,AIR:0)
Block(-6,13,0,AIR:0)
Block(-6,13,1,AIR:0)
Block(-6,13,2,AIR:0)
Block(-6,13,3,AIR:0)
Block(-6,13,4,SPRUCE_FENCE:0)
Block(-6,13,5,STONE:0)
RandomBlock(-6,13,6,COAL_ORE,33,STONE,100)
RandomBlock(-6,13,7,COAL_ORE,33,STONE,100)
Block(-6,13,8,STONE:0)
Block(-6,14,-7,STONE:0)
Block(-6,14,-6,SPRUCE_FENCE:0)
Block(-6,14,-5,AIR:0)
Block(-6,14,-4,AIR:0)
Block(-6,14,-3,AIR:0)
Block(-6,14,-2,AIR:0)
Block(-6,14,-1,AIR:0)
Block(-6,14,0,AIR:0)
Block(-6,14,1,AIR:0)
Block(-6,14,2,AIR:0)
Block(-6,14,3,AIR:0)
Block(-6,14,4,SPRUCE_FENCE:0)
Block(-6,14,5,STONE:0)
RandomBlock(-6,14,6,COAL_ORE,33,STONE,100)
Block(-6,14,7,STONE:0)
Block(-6,14,8,STONE:0)
Block(-6,15,-7,SPRUCE_FENCE:0)
Block(-6,15,-6,SPRUCE_FENCE:0)
Block(-6,15,-5,AIR:0)
Block(-6,15,-4,AIR:0)
Block(-6,15,-3,AIR:0)
Block(-6,15,-2,AIR:0)
Block(-6,15,-1,AIR:0)
Block(-6,15,0,AIR:0)
Block(-6,15,1,AIR:0)
Block(-6,15,2,AIR:0)
Block(-6,15,3,AIR:0)
Block(-6,15,4,SPRUCE_FENCE:0)
Block(-6,15,5,AIR:0)
Block(-6,15,6,STONE:0)
Block(-6,15,7,STONE:0)
RandomBlock(-6,15,8,COAL_ORE,33,STONE,100)
Block(-6,16,-7,SPRUCE_FENCE:0)
Block(-6,16,-6,SPRUCE_FENCE:0)
Block(-6,16,-5,AIR:0)
Block(-6,16,-4,AIR:0)
Block(-6,16,-3,AIR:0)
Block(-6,16,-2,AIR:0)
Block(-6,16,-1,AIR:0)
Block(-6,16,0,AIR:0)
Block(-6,16,1,AIR:0)
Block(-6,16,2,AIR:0)
Block(-6,16,3,AIR:0)
Block(-6,16,4,SPRUCE_FENCE:0)
RandomBlock(-6,16,5,WEB:0,25,AIR:0,100)
RandomBlock(-6,16,6,COAL_ORE,33,STONE,100)
Block(-6,16,7,STONE:0)
Block(-6,16,8,STONE:0)
Block(-6,17,-7,SPRUCE_FENCE:0)
Block(-6,17,-6,SPRUCE_FENCE:0)
Block(-6,17,-5,AIR:0)
Block(-6,17,-4,AIR:0)
Block(-6,17,-3,AIR:0)
Block(-6,17,-2,AIR:0)
Block(-6,17,-1,AIR:0)
Block(-6,17,0,AIR:0)
Block(-6,17,1,AIR:0)
Block(-6,17,2,AIR:0)
Block(-6,17,3,AIR:0)
Block(-6,17,4,SPRUCE_FENCE:0)
Block(-6,17,5,SPRUCE_FENCE:0)
Block(-6,17,6,SPRUCE_FENCE:0)
Block(-6,17,7,STONE:0)
Block(-6,17,8,STONE:0)
Block(-6,18,-7,WOOD_STEP:1)
Block(-6,18,-6,WOOD_STEP:1)
Block(-6,18,-5,AIR:0)
Block(-6,18,-4,AIR:0)
Block(-6,18,-3,AIR:0)
Block(-6,18,-2,AIR:0)
Block(-6,18,-1,AIR:0)
Block(-6,18,0,AIR:0)
Block(-6,18,1,AIR:0)
Block(-6,18,2,AIR:0)
Block(-6,18,3,AIR:0)
Block(-6,18,4,WOOD_STEP:1)
Block(-6,18,5,WOOD_STEP:1)
Block(-6,18,6,SPRUCE_FENCE:0)
Block(-6,18,7,STONE:0)
Block(-6,18,8,SPRUCE_FENCE:0)
Block(-6,19,-7,AIR:0)
Block(-6,19,-6,AIR:0)
Block(-6,19,-5,AIR:0)
Block(-6,19,-4,AIR:0)
Block(-6,19,-3,AIR:0)
Block(-6,19,-2,AIR:0)
Block(-6,19,-1,AIR:0)
Block(-6,19,0,AIR:0)
Block(-6,19,1,AIR:0)
Block(-6,19,2,AIR:0)
Block(-6,19,3,AIR:0)
Block(-6,19,4,AIR:0)
Block(-6,19,5,AIR:0)
Block(-6,19,6,SPRUCE_FENCE:0)
Block(-6,19,7,SPRUCE_FENCE:0)
Block(-6,19,8,SPRUCE_FENCE:0)
Block(-6,20,6,WOOD_STEP:1)
Block(-6,20,7,WOOD_STEP:1)
Block(-6,20,8,WOOD_STEP:1)
Block(-5,0,-7,STONE:0)
Block(-5,0,-6,STONE:0)
Block(-5,0,-5,STONE:0)
RandomBlock(-5,0,-4,COAL_ORE,33,STONE,100)
Block(-5,0,-3,STONE:0)
RandomBlock(-5,0,-2,COAL_ORE,33,STONE,100)
RandomBlock(-5,0,-1,COAL_ORE,33,STONE,100)
Block(-5,0,0,STONE:0)
Block(-5,0,1,STONE:0)
RandomBlock(-5,0,2,COAL_ORE,33,STONE,100)
RandomBlock(-5,0,3,COAL_ORE,33,STONE,100)
RandomBlock(-5,0,4,COAL_ORE,33,STONE,100)
Block(-5,0,5,STONE:0)
Block(-5,0,6,STONE:0)
Block(-5,0,7,STONE:0)
Block(-5,0,8,STONE:0)
RandomBlock(-5,1,-7,COAL_ORE,33,STONE,100)
RandomBlock(-5,1,-6,COAL_ORE,33,STONE,100)
RandomBlock(-5,1,-5,COAL_ORE,33,STONE,100)
Block(-5,1,-4,STONE:0)
Block(-5,1,-3,STONE:0)
Block(-5,1,-2,STONE:0)
Block(-5,1,-1,STONE:0)
Block(-5,1,0,STONE:0)
RandomBlock(-5,1,1,COAL_ORE,33,STONE,100)
Block(-5,1,2,STONE:0)
Block(-5,1,3,STONE:0)
RandomBlock(-5,1,4,COAL_ORE,33,STONE,100)
RandomBlock(-5,1,5,COAL_ORE,33,STONE,100)
RandomBlock(-5,1,6,COAL_ORE,33,STONE,100)
Block(-5,1,7,STONE:0)
Block(-5,1,8,STONE:0)
RandomBlock(-5,2,-7,COAL_ORE,33,STONE,100)
Block(-5,2,-6,STONE:0)
Block(-5,2,-5,STONE:0)
Block(-5,2,-4,STONE:0)
Block(-5,2,-3,STONE:0)
RandomBlock(-5,2,-2,COAL_ORE,33,STONE,100)
RandomBlock(-5,2,-1,COAL_ORE,33,STONE,100)
RandomBlock(-5,2,0,COAL_ORE,33,STONE,100)
RandomBlock(-5,2,1,COAL_ORE,33,STONE,100)
Block(-5,2,2,STONE:0)
Block(-5,2,3,STONE:0)
Block(-5,2,4,STONE:0)
Block(-5,2,5,STONE:0)
Block(-5,2,6,STONE:0)
Block(-5,2,7,STONE:0)
RandomBlock(-5,2,8,COAL_ORE,33,STONE,100)
RandomBlock(-5,3,-7,COAL_ORE,33,STONE,100)
Block(-5,3,-6,STONE:0)
RandomBlock(-5,3,-5,COAL_ORE,33,STONE,100)
RandomBlock(-5,3,-4,COAL_ORE,33,STONE,100)
Block(-5,3,-3,STONE:0)
Block(-5,3,-2,STONE:0)
Block(-5,3,-1,STONE:0)
RandomBlock(-5,3,0,COAL_ORE,33,STONE,100)
RandomBlock(-5,3,1,COAL_ORE,33,STONE,100)
Block(-5,3,2,STONE:0)
RandomBlock(-5,3,3,COAL_ORE,33,STONE,100)
Block(-5,3,4,STONE:0)
Block(-5,3,5,STONE:0)
RandomBlock(-5,3,6,COAL_ORE,33,STONE,100)
Block(-5,3,7,STONE:0)
RandomBlock(-5,3,8,COAL_ORE,33,STONE,100)
RandomBlock(-5,4,-7,COAL_ORE,33,STONE,100)
RandomBlock(-5,4,-6,COAL_ORE,33,STONE,100)
Block(-5,4,-5,STONE:0)
Block(-5,4,-4,STONE:0)
RandomBlock(-5,4,-3,COAL_ORE,33,STONE,100)
Block(-5,4,-2,STONE:0)
Block(-5,4,-1,STONE:0)
Block(-5,4,0,STONE:0)
RandomBlock(-5,4,1,COAL_ORE,33,STONE,100)
RandomBlock(-5,4,2,COAL_ORE,33,STONE,100)
Block(-5,4,3,STONE:0)
Block(-5,4,4,STONE:0)
Block(-5,4,5,STONE:0)
Block(-5,4,6,STONE:0)
Block(-5,4,7,STONE:0)
Block(-5,4,8,STONE:0)
RandomBlock(-5,5,-7,COAL_ORE,33,STONE,100)
Block(-5,5,-6,STONE:0)
RandomBlock(-5,5,-5,COAL_ORE,33,STONE,100)
Block(-5,5,-4,STONE:0)
Block(-5,5,-3,STONE:0)
RandomBlock(-5,5,-2,COAL_ORE,33,STONE,100)
RandomBlock(-5,5,-1,COAL_ORE,33,STONE,100)
Block(-5,5,0,STONE:0)
Block(-5,5,1,STONE:0)
Block(-5,5,2,STONE:0)
RandomBlock(-5,5,3,COAL_ORE,33,STONE,100)
Block(-5,5,4,STONE:0)
Block(-5,5,5,STONE:0)
RandomBlock(-5,5,6,COAL_ORE,33,STONE,100)
RandomBlock(-5,5,7,COAL_ORE,33,STONE,100)
RandomBlock(-5,5,8,COAL_ORE,33,STONE,100)
RandomBlock(-5,6,-7,COAL_ORE,33,STONE,100)
RandomBlock(-5,6,-6,COAL_ORE,33,STONE,100)
RandomBlock(-5,6,-5,COAL_ORE,33,STONE,100)
Block(-5,6,-4,STONE:0)
RandomBlock(-5,6,-3,COAL_ORE,33,STONE,100)
Block(-5,6,-2,STONE:0)
Block(-5,6,-1,STONE:0)
Block(-5,6,0,STONE:0)
Block(-5,6,1,STONE:0)
RandomBlock(-5,6,2,COAL_ORE,33,STONE,100)
Block(-5,6,3,STONE:0)
Block(-5,6,4,STONE:0)
Block(-5,6,5,STONE:0)
Block(-5,6,6,STONE:0)
Block(-5,6,7,STONE:0)
Block(-5,6,8,STONE:0)
Block(-5,7,-7,STONE:0)
Block(-5,7,-6,STONE:0)
Block(-5,7,-5,STONE:0)
RandomBlock(-5,7,-4,COAL_ORE,33,STONE,100)
Block(-5,7,-3,STONE:0)
Block(-5,7,-2,STONE:0)
Block(-5,7,-1,STONE:0)
Block(-5,7,0,STONE:0)
Block(-5,7,1,STONE:0)
Block(-5,7,2,STONE:0)
RandomBlock(-5,7,3,COAL_ORE,33,STONE,100)
Block(-5,7,4,STONE:0)
RandomBlock(-5,7,5,COAL_ORE,33,STONE,100)
Block(-5,7,6,STONE:0)
RandomBlock(-5,7,7,COAL_ORE,33,STONE,100)
Block(-5,7,8,STONE:0)
Block(-5,8,-7,AIR:0)
Block(-5,8,-6,STONE:0)
Block(-5,8,-5,STONE:0)
RandomBlock(-5,8,-4,COAL_ORE,33,STONE,100)
Block(-5,8,-3,STONE:0)
Block(-5,8,-2,STONE:0)
Block(-5,8,-1,STONE:0)
Block(-5,8,0,STONE:0)
Block(-5,8,1,STONE:0)
RandomBlock(-5,8,2,COAL_ORE,33,STONE,100)
RandomBlock(-5,8,3,COAL_ORE,33,STONE,100)
RandomBlock(-5,8,4,COAL_ORE,33,STONE,100)
RandomBlock(-5,8,5,COAL_ORE,33,STONE,100)
RandomBlock(-5,8,6,COAL_ORE,33,STONE,100)
Block(-5,8,7,STONE:0)
Block(-5,8,8,STONE:0)
Block(-5,9,-7,STONE:0)
RandomBlock(-5,9,-6,SKULL:1,../../../Skulls/dungeon_skull_01.nbt,6,AIR,9,SKULL:1,../../../Skulls/dungeon_skull_02.nbt,12,AIR,15,SKULL:1,../../../Skulls/dungeon_skull_03.nbt,18,AIR,21,SKULL:1,../../../Skulls/dungeon_skull_04.nbt,24,AIR,27,SKULL:1,../../../Skulls/dungeon_skull_05.nbt,30,AIR,33,SKULL:1,../../../Skulls/dungeon_skull_06.nbt,36,AIR,39,SKULL:1,../../../Skulls/dungeon_skull_07.nbt,42,AIR,45,SKULL:1,../../../Skulls/dungeon_skull_08.nbt,48,AIR,51,SKULL:1,../../../Skulls/dungeon_skull_09.nbt,54,AIR,57,SKULL:1,../../../Skulls/dungeon_skull_10.nbt,60,AIR,63,SKULL:1,../../../Skulls/dungeon_skull_11.nbt,66,AIR,69,SKULL:1,../../../Skulls/dungeon_skull_12.nbt,72,AIR,75,SKULL:1,../../../Skulls/dungeon_skull_13.nbt,78,AIR,81,SKULL:1,../../../Skulls/dungeon_skull_14.nbt,84,AIR,87,SKULL:1,../../../Skulls/dungeon_skull_15.nbt,90,AIR,93,SKULL:1,../../../Skulls/dungeon_skull_16.nbt,96,AIR,100)
Block(-5,9,-5,LOG:1)
Block(-5,9,-4,AIR:0)
Block(-5,9,-3,AIR:0)
RandomBlock(-5,9,-2,SKULL:1,../../../Skulls/dungeon_skull_01.nbt,6,AIR,9,SKULL:1,../../../Skulls/dungeon_skull_02.nbt,12,AIR,15,SKULL:1,../../../Skulls/dungeon_skull_03.nbt,18,AIR,21,SKULL:1,../../../Skulls/dungeon_skull_04.nbt,24,AIR,27,SKULL:1,../../../Skulls/dungeon_skull_05.nbt,30,AIR,33,SKULL:1,../../../Skulls/dungeon_skull_06.nbt,36,AIR,39,SKULL:1,../../../Skulls/dungeon_skull_07.nbt,42,AIR,45,SKULL:1,../../../Skulls/dungeon_skull_08.nbt,48,AIR,51,SKULL:1,../../../Skulls/dungeon_skull_09.nbt,54,AIR,57,SKULL:1,../../../Skulls/dungeon_skull_10.nbt,60,AIR,63,SKULL:1,../../../Skulls/dungeon_skull_11.nbt,66,AIR,69,SKULL:1,../../../Skulls/dungeon_skull_12.nbt,72,AIR,75,SKULL:1,../../../Skulls/dungeon_skull_13.nbt,78,AIR,81,SKULL:1,../../../Skulls/dungeon_skull_14.nbt,84,AIR,87,SKULL:1,../../../Skulls/dungeon_skull_15.nbt,90,AIR,93,SKULL:1,../../../Skulls/dungeon_skull_16.nbt,96,AIR,100)
RandomBlock(-5,9,-1,COAL_ORE,33,STONE,100)
Block(-5,9,0,STONE:0)
Block(-5,9,1,STONE:0)
RandomBlock(-5,9,2,COAL_ORE,33,STONE,100)
Block(-5,9,3,STONE:0)
Block(-5,9,4,STONE:0)
RandomBlock(-5,9,5,COAL_ORE,33,STONE,100)
RandomBlock(-5,9,6,COAL_ORE,33,STONE,100)
Block(-5,9,7,STONE:0)
Block(-5,9,8,STONE:0)
Block(-5,10,-7,AIR:0)
Block(-5,10,-6,AIR:0)
Block(-5,10,-5,LOG:1)
Block(-5,10,-4,AIR:0)
Block(-5,10,-3,AIR:0)
Block(-5,10,-2,AIR:0)
RandomBlock(-5,10,-1,SKULL:1,../../../Skulls/dungeon_skull_01.nbt,6,AIR,9,SKULL:1,../../../Skulls/dungeon_skull_02.nbt,12,AIR,15,SKULL:1,../../../Skulls/dungeon_skull_03.nbt,18,AIR,21,SKULL:1,../../../Skulls/dungeon_skull_04.nbt,24,AIR,27,SKULL:1,../../../Skulls/dungeon_skull_05.nbt,30,AIR,33,SKULL:1,../../../Skulls/dungeon_skull_06.nbt,36,AIR,39,SKULL:1,../../../Skulls/dungeon_skull_07.nbt,42,AIR,45,SKULL:1,../../../Skulls/dungeon_skull_08.nbt,48,AIR,51,SKULL:1,../../../Skulls/dungeon_skull_09.nbt,54,AIR,57,SKULL:1,../../../Skulls/dungeon_skull_10.nbt,60,AIR,63,SKULL:1,../../../Skulls/dungeon_skull_11.nbt,66,AIR,69,SKULL:1,../../../Skulls/dungeon_skull_12.nbt,72,AIR,75,SKULL:1,../../../Skulls/dungeon_skull_13.nbt,78,AIR,81,SKULL:1,../../../Skulls/dungeon_skull_14.nbt,84,AIR,87,SKULL:1,../../../Skulls/dungeon_skull_15.nbt,90,AIR,93,SKULL:1,../../../Skulls/dungeon_skull_16.nbt,96,AIR,100)
Block(-5,10,0,STONE:0)
Block(-5,10,1,STONE:0)
Block(-5,10,2,STONE:0)
RandomBlock(-5,10,3,COAL_ORE,33,STONE,100)
RandomBlock(-5,10,4,COAL_ORE,33,STONE,100)
Block(-5,10,5,STONE:0)
Block(-5,10,6,STONE:0)
RandomBlock(-5,10,7,COAL_ORE,33,STONE,100)
Block(-5,10,8,STONE:0)
Block(-5,11,-7,AIR:0)
Block(-5,11,-6,AIR:0)
Block(-5,11,-5,LOG:1)
Block(-5,11,-4,AIR:0)
Block(-5,11,-3,AIR:0)
Block(-5,11,-2,AIR:0)
Block(-5,11,-1,AIR:0)
Block(-5,11,0,SPRUCE_FENCE:0)
Block(-5,11,1,STONE:0)
Block(-5,11,2,STONE:0)
Block(-5,11,3,SPRUCE_FENCE:0)
RandomBlock(-5,11,4,COAL_ORE,33,STONE,100)
Block(-5,11,5,STONE:0)
RandomBlock(-5,11,6,COAL_ORE,33,STONE,100)
Block(-5,11,7,STONE:0)
RandomBlock(-5,11,8,COAL_ORE,33,STONE,100)
Block(-5,12,-7,SPRUCE_FENCE:0)
Block(-5,12,-6,SPRUCE_FENCE:0)
Block(-5,12,-5,LOG:1)
Block(-5,12,-4,SPRUCE_FENCE:0)
Block(-5,12,-3,AIR:0)
Block(-5,12,-2,AIR:0)
Block(-5,12,-1,AIR:0)
Block(-5,12,0,WOOD_STEP:1)
Block(-5,12,1,WOOD_STEP:1)
Block(-5,12,2,STONE:0)
Block(-5,12,3,SPRUCE_FENCE:0)
Block(-5,12,4,STONE:0)
Block(-5,12,5,STONE:0)
Block(-5,12,6,STONE:0)
RandomBlock(-5,12,7,COAL_ORE,33,STONE,100)
RandomBlock(-5,12,8,COAL_ORE,33,STONE,100)
Block(-5,13,-7,WOOD_STEP:1)
Block(-5,13,-6,WOOD_STEP:1)
Block(-5,13,-5,WOOD_STEP:1)
Block(-5,13,-4,WOOD_STEP:1)
Block(-5,13,-3,AIR:0)
Block(-5,13,-2,AIR:0)
Block(-5,13,-1,AIR:0)
Block(-5,13,0,AIR:0)
Block(-5,13,1,AIR:0)
RandomBlock(-5,13,2,SKULL:1,../../../Skulls/dungeon_skull_01.nbt,6,AIR,9,SKULL:1,../../../Skulls/dungeon_skull_02.nbt,12,AIR,15,SKULL:1,../../../Skulls/dungeon_skull_03.nbt,18,AIR,21,SKULL:1,../../../Skulls/dungeon_skull_04.nbt,24,AIR,27,SKULL:1,../../../Skulls/dungeon_skull_05.nbt,30,AIR,33,SKULL:1,../../../Skulls/dungeon_skull_06.nbt,36,AIR,39,SKULL:1,../../../Skulls/dungeon_skull_07.nbt,42,AIR,45,SKULL:1,../../../Skulls/dungeon_skull_08.nbt,48,AIR,51,SKULL:1,../../../Skulls/dungeon_skull_09.nbt,54,AIR,57,SKULL:1,../../../Skulls/dungeon_skull_10.nbt,60,AIR,63,SKULL:1,../../../Skulls/dungeon_skull_11.nbt,66,AIR,69,SKULL:1,../../../Skulls/dungeon_skull_12.nbt,72,AIR,75,SKULL:1,../../../Skulls/dungeon_skull_13.nbt,78,AIR,81,SKULL:1,../../../Skulls/dungeon_skull_14.nbt,84,AIR,87,SKULL:1,../../../Skulls/dungeon_skull_15.nbt,90,AIR,93,SKULL:1,../../../Skulls/dungeon_skull_16.nbt,96,AIR,100)
Block(-5,13,3,SPRUCE_FENCE:0)
RandomBlock(-5,13,4,COAL_ORE,33,STONE,100)
Block(-5,13,5,STONE:0)
Block(-5,13,6,STONE:0)
Block(-5,13,7,STONE:0)
Block(-5,13,8,STONE:0)
Block(-5,14,-7,AIR:0)
Block(-5,14,-6,AIR:0)
Block(-5,14,-5,AIR:0)
Block(-5,14,-4,AIR:0)
Block(-5,14,-3,AIR:0)
Block(-5,14,-2,AIR:0)
Block(-5,14,-1,AIR:0)
Block(-5,14,0,AIR:0)
Block(-5,14,1,AIR:0)
Block(-5,14,2,AIR:0)
Block(-5,14,3,SPRUCE_FENCE:0)
Block(-5,14,4,STONE:0)
Block(-5,14,5,STONE:0)
RandomBlock(-5,14,6,COAL_ORE,33,STONE,100)
RandomBlock(-5,14,7,COAL_ORE,33,STONE,100)
Block(-5,14,8,STONE:0)
Block(-5,15,-7,AIR:0)
Block(-5,15,-6,AIR:0)
Block(-5,15,-5,AIR:0)
Block(-5,15,-4,AIR:0)
Block(-5,15,-3,AIR:0)
Block(-5,15,-2,AIR:0)
Block(-5,15,-1,AIR:0)
Block(-5,15,0,AIR:0)
Block(-5,15,1,AIR:0)
Block(-5,15,2,AIR:0)
Block(-5,15,3,SPRUCE_FENCE:0)
RandomBlock(-5,15,4,COAL_ORE,33,STONE,100)
RandomBlock(-5,15,5,COAL_ORE,33,STONE,100)
RandomBlock(-5,15,6,COAL_ORE,33,STONE,100)
Block(-5,15,7,STONE:0)
Block(-5,15,8,STONE:0)
Block(-5,16,-7,AIR:0)
Block(-5,16,-6,AIR:0)
Block(-5,16,-5,AIR:0)
Block(-5,16,-4,AIR:0)
Block(-5,16,-3,AIR:0)
Block(-5,16,-2,AIR:0)
Block(-5,16,-1,AIR:0)
Block(-5,16,0,AIR:0)
Block(-5,16,1,AIR:0)
Block(-5,16,2,AIR:0)
Block(-5,16,3,SPRUCE_FENCE:0)
RandomBlock(-5,16,4,WEB:0,25,AIR:0,100)
Block(-5,16,5,SPRUCE_FENCE:0)
RandomBlock(-5,16,6,COAL_ORE,33,STONE,100)
Block(-5,16,7,STONE:0)
RandomBlock(-5,16,8,COAL_ORE,33,STONE,100)
Block(-5,17,-7,AIR:0)
Block(-5,17,-6,AIR:0)
Block(-5,17,-5,AIR:0)
Block(-5,17,-4,AIR:0)
Block(-5,17,-3,AIR:0)
Block(-5,17,-2,AIR:0)
Block(-5,17,-1,AIR:0)
Block(-5,17,0,AIR:0)
Block(-5,17,1,AIR:0)
Block(-5,17,2,AIR:0)
Block(-5,17,3,SPRUCE_FENCE:0)
Block(-5,17,4,DARK_OAK_STAIRS:4)
Block(-5,17,5,SPRUCE_FENCE:0)
Block(-5,17,6,STONE:0)
RandomBlock(-5,17,7,COAL_ORE,33,STONE,100)
Block(-5,17,8,STONE:0)
Block(-5,18,-7,AIR:0)
Block(-5,18,-6,AIR:0)
Block(-5,18,-5,AIR:0)
Block(-5,18,-4,AIR:0)
Block(-5,18,-3,AIR:0)
Block(-5,18,-2,AIR:0)
Block(-5,18,-1,AIR:0)
Block(-5,18,0,AIR:0)
Block(-5,18,1,AIR:0)
Block(-5,18,2,AIR:0)
Block(-5,18,3,WOOD_STEP:1)
Block(-5,18,4,WOOD_STEP:1)
Block(-5,18,5,SPRUCE_FENCE:0)
Block(-5,18,6,SPRUCE_FENCE:0)
RandomBlock(-5,18,7,COAL_ORE,33,STONE,100)
Block(-5,18,8,SPRUCE_FENCE:0)
Block(-5,19,-7,AIR:0)
Block(-5,19,-6,AIR:0)
Block(-5,19,-5,AIR:0)
Block(-5,19,-4,AIR:0)
Block(-5,19,-3,AIR:0)
Block(-5,19,-2,AIR:0)
Block(-5,19,-1,AIR:0)
Block(-5,19,0,AIR:0)
Block(-5,19,1,AIR:0)
Block(-5,19,2,AIR:0)
Block(-5,19,3,AIR:0)
Block(-5,19,4,AIR:0)
Block(-5,19,5,SPRUCE_FENCE:0)
Block(-5,19,6,SPRUCE_FENCE:0)
RandomBlock(-5,19,7,COAL_ORE,33,STONE,100)
Block(-5,19,8,SPRUCE_FENCE:0)
Block(-5,20,5,WOOD_STEP:1)
Block(-5,20,6,WOOD_STEP:1)
Block(-5,20,7,WOOD_STEP:1)
Block(-5,20,8,WOOD_STEP:1)
Block(-4,0,-7,STONE:0)
RandomBlock(-4,0,-6,COAL_ORE,33,STONE,100)
Block(-4,0,-5,STONE:0)
RandomBlock(-4,0,-4,COAL_ORE,33,STONE,100)
RandomBlock(-4,0,-3,COAL_ORE,33,STONE,100)
Block(-4,0,-2,STONE:0)
RandomBlock(-4,0,-1,COAL_ORE,33,STONE,100)
RandomBlock(-4,0,0,COAL_ORE,33,STONE,100)
RandomBlock(-4,0,1,COAL_ORE,33,STONE,100)
Block(-4,0,2,STONE:0)
RandomBlock(-4,0,3,COAL_ORE,33,STONE,100)
Block(-4,0,4,STONE:0)
RandomBlock(-4,0,5,COAL_ORE,33,STONE,100)
Block(-4,0,6,STONE:0)
Block(-4,0,7,STONE:0)
Block(-4,0,8,STONE:0)
RandomBlock(-4,1,-7,COAL_ORE,33,STONE,100)
Block(-4,1,-6,STONE:0)
RandomBlock(-4,1,-5,COAL_ORE,33,STONE,100)
Block(-4,1,-4,STONE:0)
Block(-4,1,-3,STONE:0)
RandomBlock(-4,1,-2,COAL_ORE,33,STONE,100)
Block(-4,1,-1,STONE:0)
RandomBlock(-4,1,0,COAL_ORE,33,STONE,100)
RandomBlock(-4,1,1,COAL_ORE,33,STONE,100)
RandomBlock(-4,1,2,COAL_ORE,33,STONE,100)
RandomBlock(-4,1,3,COAL_ORE,33,STONE,100)
RandomBlock(-4,1,4,COAL_ORE,33,STONE,100)
Block(-4,1,5,STONE:0)
Block(-4,1,6,STONE:0)
Block(-4,1,7,STONE:0)
Block(-4,1,8,STONE:0)
Block(-4,2,-7,STONE:0)
RandomBlock(-4,2,-6,COAL_ORE,33,STONE,100)
Block(-4,2,-5,STONE:0)
Block(-4,2,-4,STONE:0)
Block(-4,2,-3,STONE:0)
RandomBlock(-4,2,-2,COAL_ORE,33,STONE,100)
Block(-4,2,-1,STONE:0)
Block(-4,2,0,STONE:0)
Block(-4,2,1,STONE:0)
Block(-4,2,2,STONE:0)
Block(-4,2,3,STONE:0)
RandomBlock(-4,2,4,COAL_ORE,33,STONE,100)
RandomBlock(-4,2,5,COAL_ORE,33,STONE,100)
Block(-4,2,6,STONE:0)
RandomBlock(-4,2,7,COAL_ORE,33,STONE,100)
Block(-4,2,8,STONE:0)
RandomBlock(-4,3,-7,COAL_ORE,33,STONE,100)
RandomBlock(-4,3,-6,COAL_ORE,33,STONE,100)
RandomBlock(-4,3,-5,COAL_ORE,33,STONE,100)
RandomBlock(-4,3,-4,COAL_ORE,33,STONE,100)
Block(-4,3,-3,STONE:0)
Block(-4,3,-2,STONE:0)
Block(-4,3,-1,STONE:0)
Block(-4,3,0,STONE:0)
Block(-4,3,1,STONE:0)
Block(-4,3,2,STONE:0)
Block(-4,3,3,STONE:0)
RandomBlock(-4,3,4,COAL_ORE,33,STONE,100)
RandomBlock(-4,3,5,COAL_ORE,33,STONE,100)
Block(-4,3,6,STONE:0)
Block(-4,3,7,STONE:0)
RandomBlock(-4,3,8,COAL_ORE,33,STONE,100)
Block(-4,4,-7,STONE:0)
RandomBlock(-4,4,-6,COAL_ORE,33,STONE,100)
Block(-4,4,-5,STONE:0)
Block(-4,4,-4,STONE:0)
RandomBlock(-4,4,-3,COAL_ORE,33,STONE,100)
RandomBlock(-4,4,-2,COAL_ORE,33,STONE,100)
RandomBlock(-4,4,-1,COAL_ORE,33,STONE,100)
RandomBlock(-4,4,0,COAL_ORE,33,STONE,100)
Block(-4,4,1,STONE:0)
RandomBlock(-4,4,2,COAL_ORE,33,STONE,100)
RandomBlock(-4,4,3,COAL_ORE,33,STONE,100)
Block(-4,4,4,STONE:0)
RandomBlock(-4,4,5,COAL_ORE,33,STONE,100)
Block(-4,4,6,STONE:0)
Block(-4,4,7,STONE:0)
Block(-4,4,8,STONE:0)
Block(-4,5,-7,STONE:0)
RandomBlock(-4,5,-6,COAL_ORE,33,STONE,100)
RandomBlock(-4,5,-5,COAL_ORE,33,STONE,100)
RandomBlock(-4,5,-4,COAL_ORE,33,STONE,100)
RandomBlock(-4,5,-3,COAL_ORE,33,STONE,100)
Block(-4,5,-2,STONE:0)
RandomBlock(-4,5,-1,COAL_ORE,33,STONE,100)
RandomBlock(-4,5,0,COAL_ORE,33,STONE,100)
RandomBlock(-4,5,1,COAL_ORE,33,STONE,100)
Block(-4,5,2,STONE:0)
Block(-4,5,3,STONE:0)
Block(-4,5,4,STONE:0)
RandomBlock(-4,5,5,COAL_ORE,33,STONE,100)
RandomBlock(-4,5,6,COAL_ORE,33,STONE,100)
Block(-4,5,7,STONE:0)
Block(-4,5,8,STONE:0)
RandomBlock(-4,6,-7,COAL_ORE,33,STONE,100)
Block(-4,6,-6,STONE:0)
Block(-4,6,-5,STONE:0)
Block(-4,6,-4,STONE:0)
Block(-4,6,-3,STONE:0)
Block(-4,6,-2,STONE:0)
Block(-4,6,-1,STONE:0)
Block(-4,6,0,STONE:0)
RandomBlock(-4,6,1,COAL_ORE,33,STONE,100)
Block(-4,6,2,STONE:0)
Block(-4,6,3,STONE:0)
Block(-4,6,4,STONE:0)
Block(-4,6,5,STONE:0)
Block(-4,6,6,STONE:0)
Block(-4,6,7,STONE:0)
RandomBlock(-4,6,8,COAL_ORE,33,STONE,100)
Block(-4,7,-7,STONE:0)
RandomBlock(-4,7,-6,COAL_ORE,33,STONE,100)
Block(-4,7,-5,STONE:0)
Block(-4,7,-4,STONE:0)
RandomBlock(-4,7,-3,COAL_ORE,33,STONE,100)
Block(-4,7,-2,STONE:0)
Block(-4,7,-1,STONE:0)
Block(-4,7,0,STONE:0)
RandomBlock(-4,7,1,COAL_ORE,33,STONE,100)
Block(-4,7,2,STONE:0)
Block(-4,7,3,STONE:0)
RandomBlock(-4,7,4,COAL_ORE,33,STONE,100)
RandomBlock(-4,7,5,COAL_ORE,33,STONE,100)
Block(-4,7,6,STONE:0)
Block(-4,7,7,STONE:0)
Block(-4,7,8,STONE:0)
RandomBlock(-4,8,-7,COAL_ORE,33,STONE,100)
Block(-4,8,-6,STONE:0)
RandomBlock(-4,8,-5,COAL_ORE,33,STONE,100)
RandomBlock(-4,8,-4,COAL_ORE,33,STONE,100)
Block(-4,8,-3,STONE:0)
RandomBlock(-4,8,-2,COAL_ORE,33,STONE,100)
Block(-4,8,-1,STONE:0)
RandomBlock(-4,8,0,COAL_ORE,33,STONE,100)
Block(-4,8,1,STONE:0)
Block(-4,8,2,STONE:0)
RandomBlock(-4,8,3,COAL_ORE,33,STONE,100)
Block(-4,8,4,STONE:0)
Block(-4,8,5,STONE:0)
Block(-4,8,6,STONE:0)
RandomBlock(-4,8,7,COAL_ORE,33,STONE,100)
RandomBlock(-4,8,8,COAL_ORE,33,STONE,100)
RandomBlock(-4,9,-7,SKULL:1,../../../Skulls/dungeon_skull_01.nbt,6,AIR,9,SKULL:1,../../../Skulls/dungeon_skull_02.nbt,12,AIR,15,SKULL:1,../../../Skulls/dungeon_skull_03.nbt,18,AIR,21,SKULL:1,../../../Skulls/dungeon_skull_04.nbt,24,AIR,27,SKULL:1,../../../Skulls/dungeon_skull_05.nbt,30,AIR,33,SKULL:1,../../../Skulls/dungeon_skull_06.nbt,36,AIR,39,SKULL:1,../../../Skulls/dungeon_skull_07.nbt,42,AIR,45,SKULL:1,../../../Skulls/dungeon_skull_08.nbt,48,AIR,51,SKULL:1,../../../Skulls/dungeon_skull_09.nbt,54,AIR,57,SKULL:1,../../../Skulls/dungeon_skull_10.nbt,60,AIR,63,SKULL:1,../../../Skulls/dungeon_skull_11.nbt,66,AIR,69,SKULL:1,../../../Skulls/dungeon_skull_12.nbt,72,AIR,75,SKULL:1,../../../Skulls/dungeon_skull_13.nbt,78,AIR,81,SKULL:1,../../../Skulls/dungeon_skull_14.nbt,84,AIR,87,SKULL:1,../../../Skulls/dungeon_skull_15.nbt,90,AIR,93,SKULL:1,../../../Skulls/dungeon_skull_16.nbt,96,AIR,100)
RandomBlock(-4,9,-6,SKULL:1,../../../Skulls/dungeon_skull_01.nbt,6,AIR,9,SKULL:1,../../../Skulls/dungeon_skull_02.nbt,12,AIR,15,SKULL:1,../../../Skulls/dungeon_skull_03.nbt,18,AIR,21,SKULL:1,../../../Skulls/dungeon_skull_04.nbt,24,AIR,27,SKULL:1,../../../Skulls/dungeon_skull_05.nbt,30,AIR,33,SKULL:1,../../../Skulls/dungeon_skull_06.nbt,36,AIR,39,SKULL:1,../../../Skulls/dungeon_skull_07.nbt,42,AIR,45,SKULL:1,../../../Skulls/dungeon_skull_08.nbt,48,AIR,51,SKULL:1,../../../Skulls/dungeon_skull_09.nbt,54,AIR,57,SKULL:1,../../../Skulls/dungeon_skull_10.nbt,60,AIR,63,SKULL:1,../../../Skulls/dungeon_skull_11.nbt,66,AIR,69,SKULL:1,../../../Skulls/dungeon_skull_12.nbt,72,AIR,75,SKULL:1,../../../Skulls/dungeon_skull_13.nbt,78,AIR,81,SKULL:1,../../../Skulls/dungeon_skull_14.nbt,84,AIR,87,SKULL:1,../../../Skulls/dungeon_skull_15.nbt,90,AIR,93,SKULL:1,../../../Skulls/dungeon_skull_16.nbt,96,AIR,100)
RandomBlock(-4,9,-5,SKULL:1,../../../Skulls/dungeon_skull_01.nbt,6,AIR,9,SKULL:1,../../../Skulls/dungeon_skull_02.nbt,12,AIR,15,SKULL:1,../../../Skulls/dungeon_skull_03.nbt,18,AIR,21,SKULL:1,../../../Skulls/dungeon_skull_04.nbt,24,AIR,27,SKULL:1,../../../Skulls/dungeon_skull_05.nbt,30,AIR,33,SKULL:1,../../../Skulls/dungeon_skull_06.nbt,36,AIR,39,SKULL:1,../../../Skulls/dungeon_skull_07.nbt,42,AIR,45,SKULL:1,../../../Skulls/dungeon_skull_08.nbt,48,AIR,51,SKULL:1,../../../Skulls/dungeon_skull_09.nbt,54,AIR,57,SKULL:1,../../../Skulls/dungeon_skull_10.nbt,60,AIR,63,SKULL:1,../../../Skulls/dungeon_skull_11.nbt,66,AIR,69,SKULL:1,../../../Skulls/dungeon_skull_12.nbt,72,AIR,75,SKULL:1,../../../Skulls/dungeon_skull_13.nbt,78,AIR,81,SKULL:1,../../../Skulls/dungeon_skull_14.nbt,84,AIR,87,SKULL:1,../../../Skulls/dungeon_skull_15.nbt,90,AIR,93,SKULL:1,../../../Skulls/dungeon_skull_16.nbt,96,AIR,100)
Block(-4,9,-4,AIR:0)
Block(-4,9,-3,AIR:0)
RandomBlock(-4,9,-2,SKULL:1,../../../Skulls/dungeon_skull_01.nbt,6,AIR,9,SKULL:1,../../../Skulls/dungeon_skull_02.nbt,12,AIR,15,SKULL:1,../../../Skulls/dungeon_skull_03.nbt,18,AIR,21,SKULL:1,../../../Skulls/dungeon_skull_04.nbt,24,AIR,27,SKULL:1,../../../Skulls/dungeon_skull_05.nbt,30,AIR,33,SKULL:1,../../../Skulls/dungeon_skull_06.nbt,36,AIR,39,SKULL:1,../../../Skulls/dungeon_skull_07.nbt,42,AIR,45,SKULL:1,../../../Skulls/dungeon_skull_08.nbt,48,AIR,51,SKULL:1,../../../Skulls/dungeon_skull_09.nbt,54,AIR,57,SKULL:1,../../../Skulls/dungeon_skull_10.nbt,60,AIR,63,SKULL:1,../../../Skulls/dungeon_skull_11.nbt,66,AIR,69,SKULL:1,../../../Skulls/dungeon_skull_12.nbt,72,AIR,75,SKULL:1,../../../Skulls/dungeon_skull_13.nbt,78,AIR,81,SKULL:1,../../../Skulls/dungeon_skull_14.nbt,84,AIR,87,SKULL:1,../../../Skulls/dungeon_skull_15.nbt,90,AIR,93,SKULL:1,../../../Skulls/dungeon_skull_16.nbt,96,AIR,100)
RandomBlock(-4,9,-1,COAL_ORE,33,STONE,100)
Block(-4,9,0,STONE:0)
RandomBlock(-4,9,1,COAL_ORE,33,STONE,100)
RandomBlock(-4,9,2,COAL_ORE,33,STONE,100)
Block(-4,9,3,STONE:0)
Block(-4,9,4,STONE:0)
Block(-4,9,5,STONE:0)
Block(-4,9,6,STONE:0)
Block(-4,9,7,STONE:0)
RandomBlock(-4,9,8,COAL_ORE,33,STONE,100)
Block(-4,10,-7,AIR:0)
Block(-4,10,-6,AIR:0)
Block(-4,10,-5,AIR:0)
Block(-4,10,-4,AIR:0)
Block(-4,10,-3,AIR:0)
Block(-4,10,-2,AIR:0)
RandomBlock(-4,10,-1,SKULL:1,../../../Skulls/dungeon_skull_01.nbt,6,AIR,9,SKULL:1,../../../Skulls/dungeon_skull_02.nbt,12,AIR,15,SKULL:1,../../../Skulls/dungeon_skull_03.nbt,18,AIR,21,SKULL:1,../../../Skulls/dungeon_skull_04.nbt,24,AIR,27,SKULL:1,../../../Skulls/dungeon_skull_05.nbt,30,AIR,33,SKULL:1,../../../Skulls/dungeon_skull_06.nbt,36,AIR,39,SKULL:1,../../../Skulls/dungeon_skull_07.nbt,42,AIR,45,SKULL:1,../../../Skulls/dungeon_skull_08.nbt,48,AIR,51,SKULL:1,../../../Skulls/dungeon_skull_09.nbt,54,AIR,57,SKULL:1,../../../Skulls/dungeon_skull_10.nbt,60,AIR,63,SKULL:1,../../../Skulls/dungeon_skull_11.nbt,66,AIR,69,SKULL:1,../../../Skulls/dungeon_skull_12.nbt,72,AIR,75,SKULL:1,../../../Skulls/dungeon_skull_13.nbt,78,AIR,81,SKULL:1,../../../Skulls/dungeon_skull_14.nbt,84,AIR,87,SKULL:1,../../../Skulls/dungeon_skull_15.nbt,90,AIR,93,SKULL:1,../../../Skulls/dungeon_skull_16.nbt,96,AIR,100)
Block(-4,10,0,STONE:0)
Block(-4,10,1,STONE:0)
Block(-4,10,2,STONE:0)
Block(-4,10,3,STONE:0)
RandomBlock(-4,10,4,COAL_ORE,33,STONE,100)
Block(-4,10,5,STONE:0)
RandomBlock(-4,10,6,COAL_ORE,33,STONE,100)
RandomBlock(-4,10,7,COAL_ORE,33,STONE,100)
Block(-4,10,8,STONE:0)
Block(-4,11,-7,AIR:0)
Block(-4,11,-6,AIR:0)
Block(-4,11,-5,SPRUCE_FENCE:0)
Block(-4,11,-4,AIR:0)
Block(-4,11,-3,AIR:0)
Block(-4,11,-2,AIR:0)
Block(-4,11,-1,AIR:0)
Block(-4,11,0,SPRUCE_FENCE:0)
Block(-4,11,1,STONE:0)
RandomBlock(-4,11,2,COAL_ORE,33,STONE,100)
Block(-4,11,3,STONE:0)
Block(-4,11,4,STONE:0)
RandomBlock(-4,11,5,COAL_ORE,33,STONE,100)
RandomBlock(-4,11,6,COAL_ORE,33,STONE,100)
Block(-4,11,7,STONE:0)
RandomBlock(-4,11,8,COAL_ORE,33,STONE,100)
Block(-4,12,-7,SPRUCE_FENCE:0)
Block(-4,12,-6,SPRUCE_FENCE:0)
Block(-4,12,-5,LOG:5)
Block(-4,12,-4,SPRUCE_FENCE:0)
Block(-4,12,-3,AIR:0)
Block(-4,12,-2,AIR:0)
Block(-4,12,-1,AIR:0)
Block(-4,12,0,WOOD_STEP:1)
Block(-4,12,1,WOOD_STEP:1)
RandomBlock(-4,12,2,COAL_ORE,33,STONE,100)
RandomBlock(-4,12,3,COAL_ORE,33,STONE,100)
Block(-4,12,4,STONE:0)
Block(-4,12,5,STONE:0)
RandomBlock(-4,12,6,COAL_ORE,33,STONE,100)
Block(-4,12,7,STONE:0)
RandomBlock(-4,12,8,COAL_ORE,33,STONE,100)
Block(-4,13,-7,WOOD_STEP:1)
Block(-4,13,-6,WOOD_STEP:1)
Block(-4,13,-5,WOOD_STEP:1)
Block(-4,13,-4,WOOD_STEP:1)
Block(-4,13,-3,AIR:0)
Block(-4,13,-2,AIR:0)
Block(-4,13,-1,AIR:0)
Block(-4,13,0,AIR:0)
Block(-4,13,1,AIR:0)
RandomBlock(-4,13,2,COAL_ORE,33,STONE,100)
RandomBlock(-4,13,3,COAL_ORE,33,STONE,100)
RandomBlock(-4,13,4,COAL_ORE,33,STONE,100)
RandomBlock(-4,13,5,COAL_ORE,33,STONE,100)
Block(-4,13,6,STONE:0)
RandomBlock(-4,13,7,COAL_ORE,33,STONE,100)
RandomBlock(-4,13,8,COAL_ORE,33,STONE,100)
Block(-4,14,-7,AIR:0)
Block(-4,14,-6,AIR:0)
Block(-4,14,-5,AIR:0)
Block(-4,14,-4,AIR:0)
Block(-4,14,-3,AIR:0)
Block(-4,14,-2,AIR:0)
Block(-4,14,-1,AIR:0)
Block(-4,14,0,AIR:0)
Block(-4,14,1,AIR:0)
Block(-4,14,2,STONE:0)
Block(-4,14,3,STONE:0)
RandomBlock(-4,14,4,COAL_ORE,33,STONE,100)
Block(-4,14,5,STONE:0)
RandomBlock(-4,14,6,COAL_ORE,33,STONE,100)
Block(-4,14,7,STONE:0)
RandomBlock(-4,14,8,COAL_ORE,33,STONE,100)
Block(-4,15,-7,AIR:0)
Block(-4,15,-6,AIR:0)
Block(-4,15,-5,AIR:0)
Block(-4,15,-4,AIR:0)
Block(-4,15,-3,AIR:0)
Block(-4,15,-2,AIR:0)
Block(-4,15,-1,AIR:0)
Block(-4,15,0,AIR:0)
Block(-4,15,1,AIR:0)
Block(-4,15,2,SPRUCE_FENCE:0)
RandomBlock(-4,15,3,COAL_ORE,33,STONE,100)
RandomBlock(-4,15,4,COAL_ORE,33,STONE,100)
RandomBlock(-4,15,5,COAL_ORE,33,STONE,100)
RandomBlock(-4,15,6,COAL_ORE,33,STONE,100)
Block(-4,15,7,STONE:0)
Block(-4,15,8,STONE:0)
Block(-4,16,-7,AIR:0)
Block(-4,16,-6,AIR:0)
Block(-4,16,-5,AIR:0)
Block(-4,16,-4,AIR:0)
Block(-4,16,-3,AIR:0)
Block(-4,16,-2,AIR:0)
Block(-4,16,-1,AIR:0)
Block(-4,16,0,AIR:0)
Block(-4,16,1,AIR:0)
Block(-4,16,2,SPRUCE_FENCE:0)
RandomBlock(-4,16,3,WEB:0,25,AIR:0,100)
Block(-4,16,4,LOG:1)
Block(-4,16,5,STONE:0)
RandomBlock(-4,16,6,COAL_ORE,33,STONE,100)
Block(-4,16,7,STONE:0)
RandomBlock(-4,16,8,COAL_ORE,33,STONE,100)
Block(-4,17,-7,AIR:0)
Block(-4,17,-6,AIR:0)
Block(-4,17,-5,AIR:0)
Block(-4,17,-4,AIR:0)
Block(-4,17,-3,AIR:0)
Block(-4,17,-2,AIR:0)
Block(-4,17,-1,AIR:0)
Block(-4,17,0,AIR:0)
Block(-4,17,1,AIR:0)
Block(-4,17,2,SPRUCE_FENCE:0)
Block(-4,17,3,DARK_OAK_STAIRS:6)
Block(-4,17,4,LOG:1)
Block(-4,17,5,SPRUCE_FENCE:0)
Block(-4,17,6,STONE:0)
Block(-4,17,7,STONE:0)
RandomBlock(-4,17,8,COAL_ORE,33,STONE,100)
Block(-4,18,-7,AIR:0)
Block(-4,18,-6,AIR:0)
Block(-4,18,-5,AIR:0)
Block(-4,18,-4,AIR:0)
Block(-4,18,-3,AIR:0)
Block(-4,18,-2,AIR:0)
Block(-4,18,-1,AIR:0)
Block(-4,18,0,AIR:0)
Block(-4,18,1,AIR:0)
Block(-4,18,2,WOOD_STEP:1)
Block(-4,18,3,WOOD_STEP:1)
Block(-4,18,4,LOG:1)
Block(-4,18,5,SPRUCE_FENCE:0)
RandomBlock(-4,18,6,COAL_ORE,33,STONE,100)
Block(-4,18,7,STONE:0)
Block(-4,18,8,STONE:0)
Block(-4,19,-7,AIR:0)
Block(-4,19,-6,AIR:0)
Block(-4,19,-5,AIR:0)
Block(-4,19,-4,AIR:0)
Block(-4,19,-3,AIR:0)
Block(-4,19,-2,AIR:0)
Block(-4,19,-1,AIR:0)
Block(-4,19,0,AIR:0)
Block(-4,19,1,AIR:0)
Block(-4,19,2,AIR:0)
Block(-4,19,3,AIR:0)
Block(-4,19,4,LOG:1)
Block(-4,19,5,SPRUCE_FENCE:0)
RandomBlock(-4,19,6,COAL_ORE,33,STONE,100)
Block(-4,19,7,STONE:0)
Block(-4,19,8,SPRUCE_FENCE:0)
Block(-4,20,4,WOOD_STEP:1)
Block(-4,20,5,WOOD_STEP:1)
Block(-4,20,6,WOOD_STEP:1)
Block(-4,20,7,WOOD_STEP:1)
Block(-4,20,8,WOOD_STEP:1)
Block(-3,0,-7,STONE:0)
RandomBlock(-3,0,-6,COAL_ORE,33,STONE,100)
RandomBlock(-3,0,-5,COAL_ORE,33,STONE,100)
RandomBlock(-3,0,-4,COAL_ORE,33,STONE,100)
Block(-3,0,-3,STONE:0)
RandomBlock(-3,0,-2,COAL_ORE,33,STONE,100)
RandomBlock(-3,0,-1,COAL_ORE,33,STONE,100)
Block(-3,0,0,STONE:0)
RandomBlock(-3,0,1,COAL_ORE,33,STONE,100)
RandomBlock(-3,0,2,COAL_ORE,33,STONE,100)
Block(-3,0,3,STONE:0)
RandomBlock(-3,0,4,COAL_ORE,33,STONE,100)
RandomBlock(-3,0,5,COAL_ORE,33,STONE,100)
RandomBlock(-3,0,6,COAL_ORE,33,STONE,100)
RandomBlock(-3,0,7,COAL_ORE,33,STONE,100)
RandomBlock(-3,0,8,COAL_ORE,33,STONE,100)
Block(-3,1,-7,STONE:0)
Block(-3,1,-6,STONE:0)
Block(-3,1,-5,STONE:0)
RandomBlock(-3,1,-4,COAL_ORE,33,STONE,100)
Block(-3,1,-3,STONE:0)
Block(-3,1,-2,STONE:0)
Block(-3,1,-1,STONE:0)
RandomBlock(-3,1,0,COAL_ORE,33,STONE,100)
RandomBlock(-3,1,1,COAL_ORE,33,STONE,100)
Block(-3,1,2,STONE:0)
RandomBlock(-3,1,3,COAL_ORE,33,STONE,100)
Block(-3,1,4,STONE:0)
Block(-3,1,5,STONE:0)
RandomBlock(-3,1,6,COAL_ORE,33,STONE,100)
RandomBlock(-3,1,7,COAL_ORE,33,STONE,100)
Block(-3,1,8,STONE:0)
RandomBlock(-3,2,-7,COAL_ORE,33,STONE,100)
Block(-3,2,-6,STONE:0)
Block(-3,2,-5,STONE:0)
RandomBlock(-3,2,-4,COAL_ORE,33,STONE,100)
Block(-3,2,-3,STONE:0)
Block(-3,2,-2,STONE:0)
Block(-3,2,-1,STONE:0)
Block(-3,2,0,STONE:0)
Block(-3,2,1,STONE:0)
Block(-3,2,2,STONE:0)
Block(-3,2,3,STONE:0)
RandomBlock(-3,2,4,COAL_ORE,33,STONE,100)
Block(-3,2,5,STONE:0)
Block(-3,2,6,STONE:0)
Block(-3,2,7,STONE:0)
RandomBlock(-3,2,8,COAL_ORE,33,STONE,100)
RandomBlock(-3,3,-7,COAL_ORE,33,STONE,100)
RandomBlock(-3,3,-6,COAL_ORE,33,STONE,100)
RandomBlock(-3,3,-5,COAL_ORE,33,STONE,100)
Block(-3,3,-4,STONE:0)
Block(-3,3,-3,STONE:0)
Block(-3,3,-2,STONE:0)
Block(-3,3,-1,STONE:0)
Block(-3,3,0,STONE:0)
RandomBlock(-3,3,1,COAL_ORE,33,STONE,100)
Block(-3,3,2,STONE:0)
Block(-3,3,3,STONE:0)
RandomBlock(-3,3,4,COAL_ORE,33,STONE,100)
Block(-3,3,5,STONE:0)
Block(-3,3,6,STONE:0)
RandomBlock(-3,3,7,COAL_ORE,33,STONE,100)
RandomBlock(-3,3,8,COAL_ORE,33,STONE,100)
Block(-3,4,-7,STONE:0)
RandomBlock(-3,4,-6,COAL_ORE,33,STONE,100)
Block(-3,4,-5,STONE:0)
Block(-3,4,-4,STONE:0)
Block(-3,4,-3,STONE:0)
Block(-3,4,-2,STONE:0)
Block(-3,4,-1,STONE:0)
Block(-3,4,0,STONE:0)
Block(-3,4,1,STONE:0)
Block(-3,4,2,STONE:0)
Block(-3,4,3,STONE:0)
Block(-3,4,4,STONE:0)
Block(-3,4,5,STONE:0)
RandomBlock(-3,4,6,COAL_ORE,33,STONE,100)
Block(-3,4,7,STONE:0)
RandomBlock(-3,4,8,COAL_ORE,33,STONE,100)
Block(-3,5,-7,STONE:0)
RandomBlock(-3,5,-6,COAL_ORE,33,STONE,100)
RandomBlock(-3,5,-5,COAL_ORE,33,STONE,100)
Block(-3,5,-4,STONE:0)
RandomBlock(-3,5,-3,COAL_ORE,33,STONE,100)
RandomBlock(-3,5,-2,COAL_ORE,33,STONE,100)
Block(-3,5,-1,STONE:0)
Block(-3,5,0,STONE:0)
RandomBlock(-3,5,1,COAL_ORE,33,STONE,100)
Block(-3,5,2,STONE:0)
RandomBlock(-3,5,3,COAL_ORE,33,STONE,100)
Block(-3,5,4,STONE:0)
Block(-3,5,5,STONE:0)
Block(-3,5,6,STONE:0)
Block(-3,5,7,STONE:0)
RandomBlock(-3,5,8,COAL_ORE,33,STONE,100)
RandomBlock(-3,6,-7,COAL_ORE,33,STONE,100)
Block(-3,6,-6,STONE:0)
Block(-3,6,-5,STONE:0)
Block(-3,6,-4,STONE:0)
Block(-3,6,-3,STONE:0)
Block(-3,6,-2,STONE:0)
Block(-3,6,-1,STONE:0)
Block(-3,6,0,STONE:0)
RandomBlock(-3,6,1,COAL_ORE,33,STONE,100)
RandomBlock(-3,6,2,COAL_ORE,33,STONE,100)
Block(-3,6,3,STONE:0)
Block(-3,6,4,STONE:0)
RandomBlock(-3,6,5,COAL_ORE,33,STONE,100)
Block(-3,6,6,STONE:0)
Block(-3,6,7,STONE:0)
Block(-3,6,8,STONE:0)
Block(-3,7,-7,STONE:0)
RandomBlock(-3,7,-6,COAL_ORE,33,STONE,100)
Block(-3,7,-5,STONE:0)
Block(-3,7,-4,STONE:0)
RandomBlock(-3,7,-3,COAL_ORE,33,STONE,100)
Block(-3,7,-2,STONE:0)
Block(-3,7,-1,STONE:0)
RandomBlock(-3,7,0,COAL_ORE,33,STONE,100)
Block(-3,7,1,STONE:0)
RandomBlock(-3,7,2,COAL_ORE,33,STONE,100)
Block(-3,7,3,STONE:0)
RandomBlock(-3,7,4,COAL_ORE,33,STONE,100)
RandomBlock(-3,7,5,COAL_ORE,33,STONE,100)
Block(-3,7,6,STONE:0)
Block(-3,7,7,STONE:0)
RandomBlock(-3,7,8,COAL_ORE,33,STONE,100)
RandomBlock(-3,8,-7,COAL_ORE,33,STONE,100)
Block(-3,8,-6,STONE:0)
Block(-3,8,-5,STONE:0)
Block(-3,8,-4,STONE:0)
Block(-3,8,-3,STONE:0)
Block(-3,8,-2,STONE:0)
RandomBlock(-3,8,-1,COAL_ORE,33,STONE,100)
RandomBlock(-3,8,0,COAL_ORE,33,STONE,100)
Block(-3,8,1,STONE:0)
Block(-3,8,2,STONE:0)
RandomBlock(-3,8,3,COAL_ORE,33,STONE,100)
RandomBlock(-3,8,4,COAL_ORE,33,STONE,100)
Block(-3,8,5,STONE:0)
RandomBlock(-3,8,6,COAL_ORE,33,STONE,100)
RandomBlock(-3,8,7,COAL_ORE,33,STONE,100)
Block(-3,8,8,STONE:0)
RandomBlock(-3,9,-7,SKULL:1,../../../Skulls/dungeon_skull_01.nbt,6,AIR,9,SKULL:1,../../../Skulls/dungeon_skull_02.nbt,12,AIR,15,SKULL:1,../../../Skulls/dungeon_skull_03.nbt,18,AIR,21,SKULL:1,../../../Skulls/dungeon_skull_04.nbt,24,AIR,27,SKULL:1,../../../Skulls/dungeon_skull_05.nbt,30,AIR,33,SKULL:1,../../../Skulls/dungeon_skull_06.nbt,36,AIR,39,SKULL:1,../../../Skulls/dungeon_skull_07.nbt,42,AIR,45,SKULL:1,../../../Skulls/dungeon_skull_08.nbt,48,AIR,51,SKULL:1,../../../Skulls/dungeon_skull_09.nbt,54,AIR,57,SKULL:1,../../../Skulls/dungeon_skull_10.nbt,60,AIR,63,SKULL:1,../../../Skulls/dungeon_skull_11.nbt,66,AIR,69,SKULL:1,../../../Skulls/dungeon_skull_12.nbt,72,AIR,75,SKULL:1,../../../Skulls/dungeon_skull_13.nbt,78,AIR,81,SKULL:1,../../../Skulls/dungeon_skull_14.nbt,84,AIR,87,SKULL:1,../../../Skulls/dungeon_skull_15.nbt,90,AIR,93,SKULL:1,../../../Skulls/dungeon_skull_16.nbt,96,AIR,100)
RandomBlock(-3,9,-6,SKULL:1,../../../Skulls/dungeon_skull_01.nbt,6,AIR,9,SKULL:1,../../../Skulls/dungeon_skull_02.nbt,12,AIR,15,SKULL:1,../../../Skulls/dungeon_skull_03.nbt,18,AIR,21,SKULL:1,../../../Skulls/dungeon_skull_04.nbt,24,AIR,27,SKULL:1,../../../Skulls/dungeon_skull_05.nbt,30,AIR,33,SKULL:1,../../../Skulls/dungeon_skull_06.nbt,36,AIR,39,SKULL:1,../../../Skulls/dungeon_skull_07.nbt,42,AIR,45,SKULL:1,../../../Skulls/dungeon_skull_08.nbt,48,AIR,51,SKULL:1,../../../Skulls/dungeon_skull_09.nbt,54,AIR,57,SKULL:1,../../../Skulls/dungeon_skull_10.nbt,60,AIR,63,SKULL:1,../../../Skulls/dungeon_skull_11.nbt,66,AIR,69,SKULL:1,../../../Skulls/dungeon_skull_12.nbt,72,AIR,75,SKULL:1,../../../Skulls/dungeon_skull_13.nbt,78,AIR,81,SKULL:1,../../../Skulls/dungeon_skull_14.nbt,84,AIR,87,SKULL:1,../../../Skulls/dungeon_skull_15.nbt,90,AIR,93,SKULL:1,../../../Skulls/dungeon_skull_16.nbt,96,AIR,100)
Block(-3,9,-5,AIR:0)
Block(-3,9,-4,AIR:0)
Block(-3,9,-3,AIR:0)
RandomBlock(-3,9,-2,SKULL:1,../../../Skulls/dungeon_skull_01.nbt,6,AIR,9,SKULL:1,../../../Skulls/dungeon_skull_02.nbt,12,AIR,15,SKULL:1,../../../Skulls/dungeon_skull_03.nbt,18,AIR,21,SKULL:1,../../../Skulls/dungeon_skull_04.nbt,24,AIR,27,SKULL:1,../../../Skulls/dungeon_skull_05.nbt,30,AIR,33,SKULL:1,../../../Skulls/dungeon_skull_06.nbt,36,AIR,39,SKULL:1,../../../Skulls/dungeon_skull_07.nbt,42,AIR,45,SKULL:1,../../../Skulls/dungeon_skull_08.nbt,48,AIR,51,SKULL:1,../../../Skulls/dungeon_skull_09.nbt,54,AIR,57,SKULL:1,../../../Skulls/dungeon_skull_10.nbt,60,AIR,63,SKULL:1,../../../Skulls/dungeon_skull_11.nbt,66,AIR,69,SKULL:1,../../../Skulls/dungeon_skull_12.nbt,72,AIR,75,SKULL:1,../../../Skulls/dungeon_skull_13.nbt,78,AIR,81,SKULL:1,../../../Skulls/dungeon_skull_14.nbt,84,AIR,87,SKULL:1,../../../Skulls/dungeon_skull_15.nbt,90,AIR,93,SKULL:1,../../../Skulls/dungeon_skull_16.nbt,96,AIR,100)
RandomBlock(-3,9,-1,COAL_ORE,33,STONE,100)
RandomBlock(-3,9,0,COAL_ORE,33,STONE,100)
Block(-3,9,1,STONE:0)
Block(-3,9,2,STONE:0)
Block(-3,9,3,STONE:0)
Block(-3,9,4,STONE:0)
Block(-3,9,5,STONE:0)
Block(-3,9,6,STONE:0)
Block(-3,9,7,STONE:0)
RandomBlock(-3,9,8,COAL_ORE,33,STONE,100)
Block(-3,10,-7,AIR:0)
Block(-3,10,-6,AIR:0)
Block(-3,10,-5,AIR:0)
Block(-3,10,-4,AIR:0)
Block(-3,10,-3,AIR:0)
Block(-3,10,-2,AIR:0)
Block(-3,10,-1,AIR:0)
Block(-3,10,0,STONE:0)
Block(-3,10,1,STONE:0)
Block(-3,10,2,STONE:0)
Block(-3,10,3,STONE:0)
RandomBlock(-3,10,4,COAL_ORE,33,STONE,100)
RandomBlock(-3,10,5,COAL_ORE,33,STONE,100)
Block(-3,10,6,STONE:0)
Block(-3,10,7,STONE:0)
Block(-3,10,8,STONE:0)
Block(-3,11,-7,AIR:0)
Block(-3,11,-6,AIR:0)
Block(-3,11,-5,SPRUCE_FENCE:0)
Block(-3,11,-4,AIR:0)
Block(-3,11,-3,AIR:0)
Block(-3,11,-2,AIR:0)
Block(-3,11,-1,AIR:0)
Block(-3,11,0,SPRUCE_FENCE:0)
Block(-3,11,1,STONE:0)
Block(-3,11,2,STONE:0)
RandomBlock(-3,11,3,COAL_ORE,33,STONE,100)
RandomBlock(-3,11,4,COAL_ORE,33,STONE,100)
Block(-3,11,5,STONE:0)
Block(-3,11,6,STONE:0)
Block(-3,11,7,STONE:0)
Block(-3,11,8,STONE:0)
Block(-3,12,-7,SPRUCE_FENCE:0)
Block(-3,12,-6,SPRUCE_FENCE:0)
Block(-3,12,-5,LOG:5)
Block(-3,12,-4,SPRUCE_FENCE:0)
Block(-3,12,-3,AIR:0)
Block(-3,12,-2,AIR:0)
Block(-3,12,-1,AIR:0)
Block(-3,12,0,WOOD_STEP:1)
Block(-3,12,1,SPRUCE_FENCE:0)
RandomBlock(-3,12,2,COAL_ORE,33,STONE,100)
RandomBlock(-3,12,3,COAL_ORE,33,STONE,100)
RandomBlock(-3,12,4,COAL_ORE,33,STONE,100)
Block(-3,12,5,STONE:0)
RandomBlock(-3,12,6,COAL_ORE,33,STONE,100)
RandomBlock(-3,12,7,COAL_ORE,33,STONE,100)
Block(-3,12,8,STONE:0)
Block(-3,13,-7,WOOD_STEP:1)
Block(-3,13,-6,WOOD_STEP:1)
Block(-3,13,-5,WOOD_STEP:1)
Block(-3,13,-4,WOOD_STEP:1)
Block(-3,13,-3,AIR:0)
Block(-3,13,-2,AIR:0)
Block(-3,13,-1,AIR:0)
Block(-3,13,0,AIR:0)
Block(-3,13,1,SPRUCE_FENCE:0)
RandomBlock(-3,13,2,COAL_ORE,33,STONE,100)
Block(-3,13,3,STONE:0)
RandomBlock(-3,13,4,COAL_ORE,33,STONE,100)
Block(-3,13,5,STONE:0)
Block(-3,13,6,STONE:0)
Block(-3,13,7,STONE:0)
Block(-3,13,8,STONE:0)
Block(-3,14,-7,AIR:0)
Block(-3,14,-6,AIR:0)
Block(-3,14,-5,AIR:0)
Block(-3,14,-4,AIR:0)
Block(-3,14,-3,AIR:0)
Block(-3,14,-2,AIR:0)
Block(-3,14,-1,AIR:0)
Block(-3,14,0,AIR:0)
Block(-3,14,1,SPRUCE_FENCE:0)
Block(-3,14,2,STONE:0)
Block(-3,14,3,STONE:0)
Block(-3,14,4,STONE:0)
RandomBlock(-3,14,5,COAL_ORE,33,STONE,100)
RandomBlock(-3,14,6,COAL_ORE,33,STONE,100)
RandomBlock(-3,14,7,COAL_ORE,33,STONE,100)
Block(-3,14,8,STONE:0)
Block(-3,15,-7,AIR:0)
Block(-3,15,-6,AIR:0)
Block(-3,15,-5,AIR:0)
Block(-3,15,-4,AIR:0)
Block(-3,15,-3,AIR:0)
Block(-3,15,-2,AIR:0)
Block(-3,15,-1,AIR:0)
Block(-3,15,0,AIR:0)
Block(-3,15,1,SPRUCE_FENCE:0)
RandomBlock(-3,15,2,COAL_ORE,33,STONE,100)
Block(-3,15,3,STONE:0)
Block(-3,15,4,STONE:0)
RandomBlock(-3,15,5,COAL_ORE,33,STONE,100)
Block(-3,15,6,STONE:0)
RandomBlock(-3,15,7,COAL_ORE,33,STONE,100)
Block(-3,15,8,STONE:0)
Block(-3,16,-7,AIR:0)
Block(-3,16,-6,AIR:0)
Block(-3,16,-5,AIR:0)
Block(-3,16,-4,AIR:0)
Block(-3,16,-3,AIR:0)
Block(-3,16,-2,AIR:0)
Block(-3,16,-1,AIR:0)
Block(-3,16,0,AIR:0)
Block(-3,16,1,SPRUCE_FENCE:0)
Block(-3,16,2,SPRUCE_FENCE:0)
Block(-3,16,3,STONE:0)
Block(-3,16,4,STONE:0)
Block(-3,16,5,STONE:0)
Block(-3,16,6,STONE:0)
Block(-3,16,7,STONE:0)
RandomBlock(-3,16,8,COAL_ORE,33,STONE,100)
Block(-3,17,-7,AIR:0)
Block(-3,17,-6,AIR:0)
Block(-3,17,-5,AIR:0)
Block(-3,17,-4,AIR:0)
Block(-3,17,-3,AIR:0)
Block(-3,17,-2,AIR:0)
Block(-3,17,-1,AIR:0)
Block(-3,17,0,AIR:0)
Block(-3,17,1,SPRUCE_FENCE:0)
Block(-3,17,2,SPRUCE_FENCE:0)
Block(-3,17,3,SPRUCE_FENCE:0)
RandomBlock(-3,17,4,COAL_ORE,33,STONE,100)
Block(-3,17,5,STONE:0)
Block(-3,17,6,STONE:0)
RandomBlock(-3,17,7,COAL_ORE,33,STONE,100)
Block(-3,17,8,STONE:0)
Block(-3,18,-7,AIR:0)
Block(-3,18,-6,AIR:0)
Block(-3,18,-5,AIR:0)
Block(-3,18,-4,AIR:0)
Block(-3,18,-3,AIR:0)
Block(-3,18,-2,AIR:0)
Block(-3,18,-1,AIR:0)
Block(-3,18,0,AIR:0)
Block(-3,18,1,WOOD_STEP:1)
Block(-3,18,2,WOOD_STEP:1)
Block(-3,18,3,SPRUCE_FENCE:0)
Block(-3,18,4,SPRUCE_FENCE:0)
Block(-3,18,5,STONE:0)
Block(-3,18,6,STONE:0)
Block(-3,18,7,STONE:0)
Block(-3,18,8,STONE:0)
Block(-3,19,-7,AIR:0)
Block(-3,19,-6,AIR:0)
Block(-3,19,-5,AIR:0)
Block(-3,19,-4,AIR:0)
Block(-3,19,-3,AIR:0)
Block(-3,19,-2,AIR:0)
Block(-3,19,-1,AIR:0)
Block(-3,19,0,AIR:0)
Block(-3,19,1,AIR:0)
Block(-3,19,2,AIR:0)
Block(-3,19,3,SPRUCE_FENCE:0)
Block(-3,19,4,SPRUCE_FENCE:0)
Block(-3,19,5,SPRUCE_FENCE:0)
RandomBlock(-3,19,6,COAL_ORE,33,STONE,100)
Block(-3,19,7,SPRUCE_FENCE:0)
Block(-3,19,8,SPRUCE_FENCE:0)
Block(-3,20,3,WOOD_STEP:1)
Block(-3,20,4,WOOD:5)
Block(-3,20,5,SPRUCE_FENCE:0)
Block(-3,20,6,WOOD:5)
Block(-3,20,7,WOOD_STEP:1)
Block(-3,20,8,WOOD_STEP:1)
Block(-3,21,4,WOOD:5)
Block(-3,21,5,SPRUCE_FENCE:0)
Block(-3,21,6,WOOD:5)
Block(-3,22,4,COBBLESTONE_STAIRS:0)
Block(-3,22,5,COBBLESTONE_STAIRS:0)
Block(-3,22,6,COBBLESTONE_STAIRS:0)
Block(-3,22,7,AIR:0)
Block(-3,26,-7,TRAP_DOOR:6)
Block(-3,26,-6,TRAP_DOOR:6)
Block(-3,26,-5,TRAP_DOOR:6)
RandomBlock(-3,34,5,WALL_BANNER:4,../NBT/banner_0.nbt,25,WALL_BANNER:4,../NBT/banner_1.nbt,25,WALL_BANNER:4,../NBT/banner_2.nbt,25,WALL_BANNER:4,../NBT/banner_3.nbt,25,WALL_BANNER:4,../NBT/banner_4.nbt,100)
Block(-2,0,-7,STONE:0)
Block(-2,0,-6,STONE:0)
Block(-2,0,-5,STONE:0)
Block(-2,0,-4,STONE:0)
Block(-2,0,-3,STONE:0)
RandomBlock(-2,0,-2,COAL_ORE,33,STONE,100)
Block(-2,0,-1,STONE:0)
Block(-2,0,0,STONE:0)
Block(-2,0,1,STONE:0)
Block(-2,0,2,STONE:0)
RandomBlock(-2,0,3,COAL_ORE,33,STONE,100)
Block(-2,0,4,STONE:0)
RandomBlock(-2,0,5,COAL_ORE,33,STONE,100)
RandomBlock(-2,0,6,COAL_ORE,33,STONE,100)
Block(-2,0,7,STONE:0)
Block(-2,0,8,STONE:0)
Block(-2,1,-7,STONE:0)
RandomBlock(-2,1,-6,COAL_ORE,33,STONE,100)
RandomBlock(-2,1,-5,COAL_ORE,33,STONE,100)
RandomBlock(-2,1,-4,COAL_ORE,33,STONE,100)
Block(-2,1,-3,STONE:0)
Block(-2,1,-2,STONE:0)
Block(-2,1,-1,STONE:0)
Block(-2,1,0,STONE:0)
Block(-2,1,1,STONE:0)
RandomBlock(-2,1,2,COAL_ORE,33,STONE,100)
RandomBlock(-2,1,3,COAL_ORE,33,STONE,100)
Block(-2,1,4,STONE:0)
Block(-2,1,5,STONE:0)
Block(-2,1,6,STONE:0)
Block(-2,1,7,STONE:0)
RandomBlock(-2,1,8,COAL_ORE,33,STONE,100)
Block(-2,2,-7,STONE:0)
Block(-2,2,-6,STONE:0)
RandomBlock(-2,2,-5,COAL_ORE,33,STONE,100)
Block(-2,2,-4,STONE:0)
Block(-2,2,-3,STONE:0)
RandomBlock(-2,2,-2,COAL_ORE,33,STONE,100)
RandomBlock(-2,2,-1,COAL_ORE,33,STONE,100)
RandomBlock(-2,2,0,COAL_ORE,33,STONE,100)
Block(-2,2,1,STONE:0)
RandomBlock(-2,2,2,COAL_ORE,33,STONE,100)
Block(-2,2,3,STONE:0)
Block(-2,2,4,STONE:0)
Block(-2,2,5,STONE:0)
RandomBlock(-2,2,6,COAL_ORE,33,STONE,100)
Block(-2,2,7,STONE:0)
Block(-2,2,8,STONE:0)
RandomBlock(-2,3,-7,COAL_ORE,33,STONE,100)
RandomBlock(-2,3,-6,COAL_ORE,33,STONE,100)
Block(-2,3,-5,STONE:0)
Block(-2,3,-4,STONE:0)
Block(-2,3,-3,STONE:0)
Block(-2,3,-2,STONE:0)
RandomBlock(-2,3,-1,COAL_ORE,33,STONE,100)
RandomBlock(-2,3,0,COAL_ORE,33,STONE,100)
RandomBlock(-2,3,1,COAL_ORE,33,STONE,100)
RandomBlock(-2,3,2,COAL_ORE,33,STONE,100)
Block(-2,3,3,STONE:0)
Block(-2,3,4,STONE:0)
Block(-2,3,5,STONE:0)
Block(-2,3,6,STONE:0)
RandomBlock(-2,3,7,COAL_ORE,33,STONE,100)
Block(-2,3,8,STONE:0)
Block(-2,4,-7,STONE:0)
RandomBlock(-2,4,-6,COAL_ORE,33,STONE,100)
RandomBlock(-2,4,-5,COAL_ORE,33,STONE,100)
Block(-2,4,-4,STONE:0)
RandomBlock(-2,4,-3,COAL_ORE,33,STONE,100)
Block(-2,4,-2,STONE:0)
RandomBlock(-2,4,-1,COAL_ORE,33,STONE,100)
RandomBlock(-2,4,0,COAL_ORE,33,STONE,100)
Block(-2,4,1,STONE:0)
Block(-2,4,2,STONE:0)
Block(-2,4,3,STONE:0)
RandomBlock(-2,4,4,COAL_ORE,33,STONE,100)
Block(-2,4,5,STONE:0)
Block(-2,4,6,STONE:0)
Block(-2,4,7,STONE:0)
Block(-2,4,8,STONE:0)
RandomBlock(-2,5,-7,COAL_ORE,33,STONE,100)
RandomBlock(-2,5,-6,COAL_ORE,33,STONE,100)
RandomBlock(-2,5,-5,COAL_ORE,33,STONE,100)
RandomBlock(-2,5,-4,COAL_ORE,33,STONE,100)
Block(-2,5,-3,STONE:0)
Block(-2,5,-2,STONE:0)
RandomBlock(-2,5,-1,COAL_ORE,33,STONE,100)
Block(-2,5,0,STONE:0)
Block(-2,5,1,STONE:0)
RandomBlock(-2,5,2,COAL_ORE,33,STONE,100)
Block(-2,5,3,STONE:0)
Block(-2,5,4,STONE:0)
Block(-2,5,5,STONE:0)
Block(-2,5,6,STONE:0)
RandomBlock(-2,5,7,COAL_ORE,33,STONE,100)
RandomBlock(-2,5,8,COAL_ORE,33,STONE,100)
Block(-2,6,-7,STONE:0)
Block(-2,6,-6,STONE:0)
Block(-2,6,-5,STONE:0)
Block(-2,6,-4,STONE:0)
RandomBlock(-2,6,-3,COAL_ORE,33,STONE,100)
Block(-2,6,-2,STONE:0)
RandomBlock(-2,6,-1,COAL_ORE,33,STONE,100)
RandomBlock(-2,6,0,COAL_ORE,33,STONE,100)
RandomBlock(-2,6,1,COAL_ORE,33,STONE,100)
Block(-2,6,2,STONE:0)
Block(-2,6,3,STONE:0)
Block(-2,6,4,STONE:0)
RandomBlock(-2,6,5,COAL_ORE,33,STONE,100)
RandomBlock(-2,6,6,COAL_ORE,33,STONE,100)
Block(-2,6,7,STONE:0)
Block(-2,6,8,STONE:0)
Block(-2,7,-7,STONE:0)
Block(-2,7,-6,STONE:0)
Block(-2,7,-5,STONE:0)
RandomBlock(-2,7,-4,COAL_ORE,33,STONE,100)
Block(-2,7,-3,STONE:0)
Block(-2,7,-2,STONE:0)
Block(-2,7,-1,STONE:0)
Block(-2,7,0,STONE:0)
Block(-2,7,1,STONE:0)
Block(-2,7,2,STONE:0)
Block(-2,7,3,STONE:0)
Block(-2,7,4,STONE:0)
Block(-2,7,5,STONE:0)
RandomBlock(-2,7,6,COAL_ORE,33,STONE,100)
Block(-2,7,7,STONE:0)
Block(-2,7,8,STONE:0)
RandomBlock(-2,8,-7,COAL_ORE,33,STONE,100)
Block(-2,8,-6,STONE:0)
Block(-2,8,-5,STONE:0)
RandomBlock(-2,8,-4,COAL_ORE,33,STONE,100)
Block(-2,8,-3,STONE:0)
Block(-2,8,-2,STONE:0)
Block(-2,8,-1,STONE:0)
RandomBlock(-2,8,0,COAL_ORE,33,STONE,100)
Block(-2,8,1,STONE:0)
Block(-2,8,2,STONE:0)
RandomBlock(-2,8,3,COAL_ORE,33,STONE,100)
RandomBlock(-2,8,4,COAL_ORE,33,STONE,100)
Block(-2,8,5,STONE:0)
Block(-2,8,6,STONE:0)
Block(-2,8,7,STONE:0)
Block(-2,8,8,STONE:0)
RandomBlock(-2,9,-7,SKULL:1,../../../Skulls/dungeon_skull_01.nbt,6,AIR,9,SKULL:1,../../../Skulls/dungeon_skull_02.nbt,12,AIR,15,SKULL:1,../../../Skulls/dungeon_skull_03.nbt,18,AIR,21,SKULL:1,../../../Skulls/dungeon_skull_04.nbt,24,AIR,27,SKULL:1,../../../Skulls/dungeon_skull_05.nbt,30,AIR,33,SKULL:1,../../../Skulls/dungeon_skull_06.nbt,36,AIR,39,SKULL:1,../../../Skulls/dungeon_skull_07.nbt,42,AIR,45,SKULL:1,../../../Skulls/dungeon_skull_08.nbt,48,AIR,51,SKULL:1,../../../Skulls/dungeon_skull_09.nbt,54,AIR,57,SKULL:1,../../../Skulls/dungeon_skull_10.nbt,60,AIR,63,SKULL:1,../../../Skulls/dungeon_skull_11.nbt,66,AIR,69,SKULL:1,../../../Skulls/dungeon_skull_12.nbt,72,AIR,75,SKULL:1,../../../Skulls/dungeon_skull_13.nbt,78,AIR,81,SKULL:1,../../../Skulls/dungeon_skull_14.nbt,84,AIR,87,SKULL:1,../../../Skulls/dungeon_skull_15.nbt,90,AIR,93,SKULL:1,../../../Skulls/dungeon_skull_16.nbt,96,AIR,100)
Block(-2,9,-6,AIR:0)
Block(-2,9,-5,LOG:1)
Block(-2,9,-4,AIR:0)
RandomBlock(-2,9,-3,SKULL:1,../../../Skulls/dungeon_skull_01.nbt,6,AIR,9,SKULL:1,../../../Skulls/dungeon_skull_02.nbt,12,AIR,15,SKULL:1,../../../Skulls/dungeon_skull_03.nbt,18,AIR,21,SKULL:1,../../../Skulls/dungeon_skull_04.nbt,24,AIR,27,SKULL:1,../../../Skulls/dungeon_skull_05.nbt,30,AIR,33,SKULL:1,../../../Skulls/dungeon_skull_06.nbt,36,AIR,39,SKULL:1,../../../Skulls/dungeon_skull_07.nbt,42,AIR,45,SKULL:1,../../../Skulls/dungeon_skull_08.nbt,48,AIR,51,SKULL:1,../../../Skulls/dungeon_skull_09.nbt,54,AIR,57,SKULL:1,../../../Skulls/dungeon_skull_10.nbt,60,AIR,63,SKULL:1,../../../Skulls/dungeon_skull_11.nbt,66,AIR,69,SKULL:1,../../../Skulls/dungeon_skull_12.nbt,72,AIR,75,SKULL:1,../../../Skulls/dungeon_skull_13.nbt,78,AIR,81,SKULL:1,../../../Skulls/dungeon_skull_14.nbt,84,AIR,87,SKULL:1,../../../Skulls/dungeon_skull_15.nbt,90,AIR,93,SKULL:1,../../../Skulls/dungeon_skull_16.nbt,96,AIR,100)
RandomBlock(-2,9,-2,SKULL:1,../../../Skulls/dungeon_skull_01.nbt,6,AIR,9,SKULL:1,../../../Skulls/dungeon_skull_02.nbt,12,AIR,15,SKULL:1,../../../Skulls/dungeon_skull_03.nbt,18,AIR,21,SKULL:1,../../../Skulls/dungeon_skull_04.nbt,24,AIR,27,SKULL:1,../../../Skulls/dungeon_skull_05.nbt,30,AIR,33,SKULL:1,../../../Skulls/dungeon_skull_06.nbt,36,AIR,39,SKULL:1,../../../Skulls/dungeon_skull_07.nbt,42,AIR,45,SKULL:1,../../../Skulls/dungeon_skull_08.nbt,48,AIR,51,SKULL:1,../../../Skulls/dungeon_skull_09.nbt,54,AIR,57,SKULL:1,../../../Skulls/dungeon_skull_10.nbt,60,AIR,63,SKULL:1,../../../Skulls/dungeon_skull_11.nbt,66,AIR,69,SKULL:1,../../../Skulls/dungeon_skull_12.nbt,72,AIR,75,SKULL:1,../../../Skulls/dungeon_skull_13.nbt,78,AIR,81,SKULL:1,../../../Skulls/dungeon_skull_14.nbt,84,AIR,87,SKULL:1,../../../Skulls/dungeon_skull_15.nbt,90,AIR,93,SKULL:1,../../../Skulls/dungeon_skull_16.nbt,96,AIR,100)
Block(-2,9,-1,STONE:0)
RandomBlock(-2,9,0,COAL_ORE,33,STONE,100)
Block(-2,9,1,STONE:0)
Block(-2,9,2,STONE:0)
Block(-2,9,3,STONE:0)
Block(-2,9,4,STONE:0)
Block(-2,9,5,STONE:0)
Block(-2,9,6,STONE:0)
Block(-2,9,7,STONE:0)
Block(-2,9,8,STONE:0)
Block(-2,10,-7,AIR:0)
Block(-2,10,-6,AIR:0)
Block(-2,10,-5,LOG:1)
Block(-2,10,-4,AIR:0)
Block(-2,10,-3,AIR:0)
Block(-2,10,-2,AIR:0)
RandomBlock(-2,10,-1,SKULL:1,../../../Skulls/dungeon_skull_01.nbt,6,AIR,9,SKULL:1,../../../Skulls/dungeon_skull_02.nbt,12,AIR,15,SKULL:1,../../../Skulls/dungeon_skull_03.nbt,18,AIR,21,SKULL:1,../../../Skulls/dungeon_skull_04.nbt,24,AIR,27,SKULL:1,../../../Skulls/dungeon_skull_05.nbt,30,AIR,33,SKULL:1,../../../Skulls/dungeon_skull_06.nbt,36,AIR,39,SKULL:1,../../../Skulls/dungeon_skull_07.nbt,42,AIR,45,SKULL:1,../../../Skulls/dungeon_skull_08.nbt,48,AIR,51,SKULL:1,../../../Skulls/dungeon_skull_09.nbt,54,AIR,57,SKULL:1,../../../Skulls/dungeon_skull_10.nbt,60,AIR,63,SKULL:1,../../../Skulls/dungeon_skull_11.nbt,66,AIR,69,SKULL:1,../../../Skulls/dungeon_skull_12.nbt,72,AIR,75,SKULL:1,../../../Skulls/dungeon_skull_13.nbt,78,AIR,81,SKULL:1,../../../Skulls/dungeon_skull_14.nbt,84,AIR,87,SKULL:1,../../../Skulls/dungeon_skull_15.nbt,90,AIR,93,SKULL:1,../../../Skulls/dungeon_skull_16.nbt,96,AIR,100)
Block(-2,10,0,STONE:0)
RandomBlock(-2,10,1,COAL_ORE,33,STONE,100)
RandomBlock(-2,10,2,COAL_ORE,33,STONE,100)
Block(-2,10,3,STONE:0)
Block(-2,10,4,STONE:0)
RandomBlock(-2,10,5,COAL_ORE,33,STONE,100)
Block(-2,10,6,STONE:0)
RandomBlock(-2,10,7,COAL_ORE,33,STONE,100)
RandomBlock(-2,10,8,COAL_ORE,33,STONE,100)
Block(-2,11,-7,SPRUCE_FENCE:0)
Block(-2,11,-6,SPRUCE_FENCE:0)
Block(-2,11,-5,LOG:1)
Block(-2,11,-4,AIR:0)
Block(-2,11,-3,AIR:0)
Block(-2,11,-2,AIR:0)
Block(-2,11,-1,AIR:0)
Block(-2,11,0,SPRUCE_FENCE:0)
RandomBlock(-2,11,1,COAL_ORE,33,STONE,100)
Block(-2,11,2,STONE:0)
Block(-2,11,3,STONE:0)
RandomBlock(-2,11,4,COAL_ORE,33,STONE,100)
RandomBlock(-2,11,5,COAL_ORE,33,STONE,100)
RandomBlock(-2,11,6,COAL_ORE,33,STONE,100)
Block(-2,11,7,STONE:0)
Block(-2,11,8,STONE:0)
Block(-2,12,-7,LOG:9)
Block(-2,12,-6,LOG:9)
Block(-2,12,-5,LOG:5)
Block(-2,12,-4,SPRUCE_FENCE:0)
Block(-2,12,-3,AIR:0)
Block(-2,12,-2,AIR:0)
Block(-2,12,-1,AIR:0)
Block(-2,12,0,WOOD_STEP:1)
Block(-2,12,1,WOOD_STEP:1)
Block(-2,12,2,STONE:0)
Block(-2,12,3,STONE:0)
Block(-2,12,4,STONE:0)
Block(-2,12,5,STONE:0)
RandomBlock(-2,12,6,COAL_ORE,33,STONE,100)
RandomBlock(-2,12,7,COAL_ORE,33,STONE,100)
Block(-2,12,8,STONE:0)
Block(-2,13,-7,WOOD_STEP:1)
Block(-2,13,-6,WOOD_STEP:1)
Block(-2,13,-5,LOG:1)
Block(-2,13,-4,WOOD_STEP:1)
Block(-2,13,-3,AIR:0)
Block(-2,13,-2,AIR:0)
Block(-2,13,-1,AIR:0)
Block(-2,13,0,AIR:0)
Block(-2,13,1,AIR:0)
RandomBlock(-2,13,2,COAL_ORE,33,STONE,100)
RandomBlock(-2,13,3,COAL_ORE,33,STONE,100)
Block(-2,13,4,STONE:0)
Block(-2,13,5,STONE:0)
RandomBlock(-2,13,6,COAL_ORE,33,STONE,100)
Block(-2,13,7,STONE:0)
Block(-2,13,8,STONE:0)
Block(-2,14,-7,AIR:0)
Block(-2,14,-6,AIR:0)
Block(-2,14,-5,LOG:1)
Block(-2,14,-4,AIR:0)
Block(-2,14,-3,AIR:0)
Block(-2,14,-2,AIR:0)
Block(-2,14,-1,AIR:0)
Block(-2,14,0,AIR:0)
Block(-2,14,1,AIR:0)
RandomBlock(-2,14,2,COAL_ORE,33,STONE,100)
RandomBlock(-2,14,3,COAL_ORE,33,STONE,100)
RandomBlock(-2,14,4,COAL_ORE,33,STONE,100)
Block(-2,14,5,STONE:0)
Block(-2,14,6,STONE:0)
RandomBlock(-2,14,7,COAL_ORE,33,STONE,100)
RandomBlock(-2,14,8,COAL_ORE,33,STONE,100)
Block(-2,15,-7,AIR:0)
Block(-2,15,-6,AIR:0)
Block(-2,15,-5,LOG:1)
Block(-2,15,-4,AIR:0)
Block(-2,15,-3,AIR:0)
Block(-2,15,-2,AIR:0)
Block(-2,15,-1,AIR:0)
Block(-2,15,0,AIR:0)
Block(-2,15,1,AIR:0)
RandomBlock(-2,15,2,COAL_ORE,33,STONE,100)
RandomBlock(-2,15,3,COAL_ORE,33,STONE,100)
Block(-2,15,4,STONE:0)
Block(-2,15,5,STONE:0)
RandomBlock(-2,15,6,COAL_ORE,33,STONE,100)
Block(-2,15,7,STONE:0)
Block(-2,15,8,STONE:0)
Block(-2,16,-7,AIR:0)
Block(-2,16,-6,AIR:0)
Block(-2,16,-5,LOG:1)
Block(-2,16,-4,AIR:0)
Block(-2,16,-3,AIR:0)
Block(-2,16,-2,AIR:0)
Block(-2,16,-1,AIR:0)
Block(-2,16,0,AIR:0)
Block(-2,16,1,AIR:0)
Block(-2,16,2,STONE:0)
Block(-2,16,3,STONE:0)
Block(-2,16,4,STONE:0)
Block(-2,16,5,STONE:0)
RandomBlock(-2,16,6,COAL_ORE,33,STONE,100)
RandomBlock(-2,16,7,COAL_ORE,33,STONE,100)
Block(-2,16,8,STONE:0)
Block(-2,17,-7,AIR:0)
Block(-2,17,-6,AIR:0)
Block(-2,17,-5,LOG:1)
Block(-2,17,-4,AIR:0)
Block(-2,17,-3,AIR:0)
Block(-2,17,-2,AIR:0)
Block(-2,17,-1,AIR:0)
Block(-2,17,0,AIR:0)
Block(-2,17,1,SPRUCE_FENCE:0)
Block(-2,17,2,SPRUCE_FENCE:0)
RandomBlock(-2,17,3,COAL_ORE,33,STONE,100)
RandomBlock(-2,17,4,COAL_ORE,33,STONE,100)
RandomBlock(-2,17,5,COAL_ORE,33,STONE,100)
RandomBlock(-2,17,6,COAL_ORE,33,STONE,100)
Block(-2,17,7,STONE:0)
Block(-2,17,8,STONE:0)
Block(-2,18,-7,SPRUCE_FENCE:0)
Block(-2,18,-6,SPRUCE_FENCE:0)
Block(-2,18,-5,LOG:1)
Block(-2,18,-4,AIR:0)
Block(-2,18,-3,AIR:0)
Block(-2,18,-2,AIR:0)
Block(-2,18,-1,AIR:0)
Block(-2,18,0,AIR:0)
Block(-2,18,1,WOOD_STEP:1)
Block(-2,18,2,SPRUCE_FENCE:0)
Block(-2,18,3,SPRUCE_FENCE:0)
RandomBlock(-2,18,4,COAL_ORE,33,STONE,100)
Block(-2,18,5,STONE:0)
RandomBlock(-2,18,6,COAL_ORE,33,STONE,100)
Block(-2,18,7,STONE:0)
Block(-2,18,8,STONE:0)
Block(-2,19,-7,LOG:9)
Block(-2,19,-6,LOG:9)
Block(-2,19,-5,LOG:1)
Block(-2,19,-4,AIR:0)
Block(-2,19,-3,AIR:0)
Block(-2,19,-2,AIR:0)
Block(-2,19,-1,AIR:0)
Block(-2,19,0,AIR:0)
Block(-2,19,1,AIR:0)
Block(-2,19,2,SPRUCE_FENCE:0)
Block(-2,19,3,SPRUCE_FENCE:0)
Block(-2,19,4,SPRUCE_FENCE:0)
Block(-2,19,5,SPRUCE_FENCE:0)
Block(-2,19,6,STONE:0)
Block(-2,19,7,SPRUCE_FENCE:0)
Block(-2,19,8,SPRUCE_FENCE:0)
Block(-2,20,-7,WOOD_STEP:1)
Block(-2,20,-6,WOOD_STEP:1)
Block(-2,20,-5,WOOD_STEP:1)
Block(-2,20,2,WOOD_STEP:1)
Block(-2,20,3,WOOD:5)
Block(-2,20,4,WOOD:5)
Block(-2,20,5,WOOD:5)
Block(-2,20,6,WOOD:5)
Block(-2,20,7,WOOD:5)
Block(-2,20,8,WOOD_STEP:1)
Block(-2,21,3,WOOD:5)
Block(-2,21,4,WOOD:5)
Block(-2,21,6,WOOD:5)
Block(-2,21,7,WOOD:5)
Block(-2,22,3,COBBLESTONE_STAIRS:2)
Block(-2,22,4,WOOD:1)
Block(-2,22,5,WOOD:1)
Block(-2,22,6,WOOD:1)
Block(-2,22,7,COBBLESTONE_STAIRS:3)
Block(-2,23,4,COBBLESTONE:0)
Block(-2,23,5,COBBLESTONE:0)
Block(-2,23,6,COBBLESTONE:0)
Block(-2,24,4,WOOD:1)
Block(-2,24,5,DARK_OAK_FENCE:0)
Block(-2,24,6,WOOD:1)
Block(-2,25,-7,TRAP_DOOR:10)
Block(-2,25,-6,TRAP_DOOR:10)
Block(-2,25,-5,TRAP_DOOR:10)
Block(-2,25,4,WOOD:1)
Block(-2,25,5,DARK_OAK_FENCE:0)
Block(-2,25,6,WOOD:1)
RandomBlock(-2,26,-7,COAL_ORE,33,STONE,100)
RandomBlock(-2,26,-6,COAL_ORE,33,STONE,100)
RandomBlock(-2,26,-5,COAL_ORE,33,STONE,100)
Block(-2,26,-4,TRAP_DOOR:5)
Block(-2,26,4,STEP:3)
Block(-2,26,5,COBBLESTONE:0)
Block(-2,26,6,STEP:3)
RandomBlock(-2,27,-5,COAL_ORE,33,STONE,100)
Block(-2,27,5,DARK_OAK_FENCE:0)
Block(-2,28,5,DARK_OAK_FENCE:0)
Block(-2,29,5,DARK_OAK_FENCE:0)
Block(-2,30,5,DARK_OAK_FENCE:0)
Block(-2,31,5,DARK_OAK_FENCE:0)
Block(-2,32,5,WOOD:5)
Block(-2,33,5,SPRUCE_FENCE:0)
Block(-2,34,5,WOOD:5)
Block(-1,0,-7,STONE:0)
Block(-1,0,-6,STONE:0)
Block(-1,0,-5,STONE:0)
RandomBlock(-1,0,-4,COAL_ORE,33,STONE,100)
Block(-1,0,-3,STONE:0)
Block(-1,0,-2,STONE:0)
RandomBlock(-1,0,-1,COAL_ORE,33,STONE,100)
RandomBlock(-1,0,0,COAL_ORE,33,STONE,100)
RandomBlock(-1,0,1,COAL_ORE,33,STONE,100)
Block(-1,0,2,STONE:0)
Block(-1,0,3,STONE:0)
RandomBlock(-1,0,4,COAL_ORE,33,STONE,100)
Block(-1,0,5,DIAMOND_BLOCK:0)
Block(-1,0,6,STONE:0)
Block(-1,0,7,STONE:0)
Block(-1,0,8,STONE:0)
RandomBlock(-1,1,-7,COAL_ORE,33,STONE,100)
RandomBlock(-1,1,-6,COAL_ORE,33,STONE,100)
RandomBlock(-1,1,-5,COAL_ORE,33,STONE,100)
RandomBlock(-1,1,-4,COAL_ORE,33,STONE,100)
Block(-1,1,-3,STONE:0)
RandomBlock(-1,1,-2,COAL_ORE,33,STONE,100)
RandomBlock(-1,1,-1,COAL_ORE,33,STONE,100)
Block(-1,1,0,STONE:0)
Block(-1,1,1,STONE:0)
Block(-1,1,2,STONE:0)
Block(-1,1,3,STONE:0)
Block(-1,1,4,STONE:0)
RandomBlock(-1,1,5,COAL_ORE,33,STONE,100)
Block(-1,1,6,STONE:0)
Block(-1,1,7,STONE:0)
RandomBlock(-1,1,8,COAL_ORE,33,STONE,100)
Block(-1,2,-7,STONE:0)
RandomBlock(-1,2,-6,COAL_ORE,33,STONE,100)
RandomBlock(-1,2,-5,COAL_ORE,33,STONE,100)
Block(-1,2,-4,STONE:0)
Block(-1,2,-3,STONE:0)
Block(-1,2,-2,STONE:0)
Block(-1,2,-1,STONE:0)
RandomBlock(-1,2,0,COAL_ORE,33,STONE,100)
Block(-1,2,1,STONE:0)
RandomBlock(-1,2,2,COAL_ORE,33,STONE,100)
Block(-1,2,3,STONE:0)
Block(-1,2,4,STONE:0)
RandomBlock(-1,2,5,COAL_ORE,33,STONE,100)
RandomBlock(-1,2,6,COAL_ORE,33,STONE,100)
RandomBlock(-1,2,7,COAL_ORE,33,STONE,100)
RandomBlock(-1,2,8,COAL_ORE,33,STONE,100)
RandomBlock(-1,3,-7,COAL_ORE,33,STONE,100)
Block(-1,3,-6,STONE:0)
Block(-1,3,-5,STONE:0)
RandomBlock(-1,3,-4,COAL_ORE,33,STONE,100)
Block(-1,3,-3,STONE:0)
Block(-1,3,-2,STONE:0)
Block(-1,3,-1,STONE:0)
RandomBlock(-1,3,0,COAL_ORE,33,STONE,100)
RandomBlock(-1,3,1,COAL_ORE,33,STONE,100)
Block(-1,3,2,STONE:0)
Block(-1,3,3,STONE:0)
Block(-1,3,4,STONE:0)
RandomBlock(-1,3,5,COAL_ORE,33,STONE,100)
Block(-1,3,6,STONE:0)
Block(-1,3,7,STONE:0)
RandomBlock(-1,3,8,COAL_ORE,33,STONE,100)
Block(-1,4,-7,STONE:0)
Block(-1,4,-6,STONE:0)
RandomBlock(-1,4,-5,COAL_ORE,33,STONE,100)
RandomBlock(-1,4,-4,COAL_ORE,33,STONE,100)
RandomBlock(-1,4,-3,COAL_ORE,33,STONE,100)
RandomBlock(-1,4,-2,COAL_ORE,33,STONE,100)
Block(-1,4,-1,STONE:0)
Block(-1,4,0,STONE:0)
Block(-1,4,1,STONE:0)
RandomBlock(-1,4,2,COAL_ORE,33,STONE,100)
Block(-1,4,3,STONE:0)
Block(-1,4,4,STONE:0)
Block(-1,4,5,STONE:0)
Block(-1,4,6,STONE:0)
RandomBlock(-1,4,7,COAL_ORE,33,STONE,100)
RandomBlock(-1,4,8,COAL_ORE,33,STONE,100)
RandomBlock(-1,5,-7,COAL_ORE,33,STONE,100)
Block(-1,5,-6,STONE:0)
Block(-1,5,-5,STONE:0)
RandomBlock(-1,5,-4,COAL_ORE,33,STONE,100)
Block(-1,5,-3,STONE:0)
Block(-1,5,-2,STONE:0)
Block(-1,5,-1,STONE:0)
RandomBlock(-1,5,0,COAL_ORE,33,STONE,100)
RandomBlock(-1,5,1,COAL_ORE,33,STONE,100)
Block(-1,5,2,STONE:0)
Block(-1,5,3,STONE:0)
Block(-1,5,4,STONE:0)
RandomBlock(-1,5,5,COAL_ORE,33,STONE,100)
Block(-1,5,6,STONE:0)
Block(-1,5,7,STONE:0)
RandomBlock(-1,5,8,COAL_ORE,33,STONE,100)
Block(-1,6,-7,STONE:0)
RandomBlock(-1,6,-6,COAL_ORE,33,STONE,100)
RandomBlock(-1,6,-5,COAL_ORE,33,STONE,100)
RandomBlock(-1,6,-4,COAL_ORE,33,STONE,100)
Block(-1,6,-3,STONE:0)
Block(-1,6,-2,STONE:0)
RandomBlock(-1,6,-1,COAL_ORE,33,STONE,100)
RandomBlock(-1,6,0,COAL_ORE,33,STONE,100)
RandomBlock(-1,6,1,COAL_ORE,33,STONE,100)
Block(-1,6,2,STONE:0)
RandomBlock(-1,6,3,COAL_ORE,33,STONE,100)
Block(-1,6,4,STONE:0)
RandomBlock(-1,6,5,COAL_ORE,33,STONE,100)
Block(-1,6,6,STONE:0)
RandomBlock(-1,6,7,COAL_ORE,33,STONE,100)
RandomBlock(-1,6,8,COAL_ORE,33,STONE,100)
Block(-1,7,-7,STONE:0)
Block(-1,7,-6,STONE:0)
Block(-1,7,-5,STONE:0)
Block(-1,7,-4,STONE:0)
Block(-1,7,-3,STONE:0)
RandomBlock(-1,7,-2,COAL_ORE,33,STONE,100)
Block(-1,7,-1,STONE:0)
Block(-1,7,0,STONE:0)
RandomBlock(-1,7,1,COAL_ORE,33,STONE,100)
RandomBlock(-1,7,2,COAL_ORE,33,STONE,100)
Block(-1,7,3,STONE:0)
Block(-1,7,4,STONE:0)
Block(-1,7,5,STONE:0)
Block(-1,7,6,STONE:0)
RandomBlock(-1,7,7,COAL_ORE,33,STONE,100)
Block(-1,7,8,STONE:0)
Block(-1,8,-7,STONE:0)
Block(-1,8,-6,STONE:0)
RandomBlock(-1,8,-5,COAL_ORE,33,STONE,100)
Block(-1,8,-4,STONE:0)
RandomBlock(-1,8,-3,COAL_ORE,33,STONE,100)
RandomBlock(-1,8,-2,COAL_ORE,33,STONE,100)
Block(-1,8,-1,STONE:0)
RandomBlock(-1,8,0,COAL_ORE,33,STONE,100)
Block(-1,8,1,STONE:0)
Block(-1,8,2,STONE:0)
RandomBlock(-1,8,3,COAL_ORE,33,STONE,100)
Block(-1,8,4,STONE:0)
RandomBlock(-1,8,5,COAL_ORE,33,STONE,100)
RandomBlock(-1,8,6,COAL_ORE,33,STONE,100)
Block(-1,8,7,STONE:0)
Block(-1,8,8,STONE:0)
