Author: NLBlackEagle
Description: No description given
SettingsMode: WriteDisable
Frequency: 0
SpawnHeight: highestBlock
UseCenterForHighestBlock: true
MinHeight: 0
MaxHeight: 255
InheritBO3: 
InheritBO3Rotation: NORTH
OverrideChildSettings: true
OverrideParentHeight: false
CanOverride: false
BranchFrequency: 0
BranchFrequencyGroup: 
MustBeBelowOther: false
MustBeInside: 
CannotBeInside: 
ReplacesBO3: 
MustBeInsideWorldBorders: false
CanSpawnOnWater: true
SpawnOnWaterOnly: false
SpawnUnderWater: false
SpawnAtWaterLevel: false
HeightOffset: 0
RemoveAir: false
ReplaceAbove: 
ReplaceBelow: 
ReplaceWithBiomeBlocks: true
ReplaceWithSurfaceBlock: GRASS
ReplaceWithGroundBlock: DIRT
ReplaceWithStoneBlock: STONE
SmoothRadius: 0
SmoothHeightOffset: 0
SmoothStartTop: false
SmoothStartWood: false
SmoothingSurfaceBlock: 
SmoothingGroundBlock: 
BO3Group: Mineshaft-Hub-N:5 Mineshaft-Hub:5
IsSpawnPoint: false
DoReplaceBlocks: false
Block(-7,0,0,LOG:1)
Block(-7,0,3,LOG:1)
RandomBlock(-7,1,0,WOOD:5,70,WOOD:1,30,WOODEN_SLAB:5,10,WOODEN_SLAB:1,10,DARK_OAK_STAIRS:0,5,DARK_OAK_STAIRS:1,5,DARK_OAK_STAIRS:2,5,DARK_OAK_STAIRS:3,5,SPRUCE_STAIRS:0,5,SPRUCE_STAIRS:1,5,SPRUCE_STAIRS:2,5,SPRUCE_STAIRS:3,5,WOOD:5,100)
RandomBlock(-7,1,1,WOOD:5,70,WOOD:1,30,WOODEN_SLAB:5,10,WOODEN_SLAB:1,10,DARK_OAK_STAIRS:0,5,DARK_OAK_STAIRS:1,5,DARK_OAK_STAIRS:2,5,DARK_OAK_STAIRS:3,5,SPRUCE_STAIRS:0,5,SPRUCE_STAIRS:1,5,SPRUCE_STAIRS:2,5,SPRUCE_STAIRS:3,5,WOOD:5,100)
RandomBlock(-7,1,2,WOOD:5,70,WOOD:1,30,WOODEN_SLAB:5,10,WOODEN_SLAB:1,10,DARK_OAK_STAIRS:0,5,DARK_OAK_STAIRS:1,5,DARK_OAK_STAIRS:2,5,DARK_OAK_STAIRS:3,5,SPRUCE_STAIRS:0,5,SPRUCE_STAIRS:1,5,SPRUCE_STAIRS:2,5,SPRUCE_STAIRS:3,5,WOOD:5,100)
RandomBlock(-7,1,3,WOOD:5,70,WOOD:1,30,WOODEN_SLAB:5,10,WOODEN_SLAB:1,10,DARK_OAK_STAIRS:0,5,DARK_OAK_STAIRS:1,5,DARK_OAK_STAIRS:2,5,DARK_OAK_STAIRS:3,5,SPRUCE_STAIRS:0,5,SPRUCE_STAIRS:1,5,SPRUCE_STAIRS:2,5,SPRUCE_STAIRS:3,5,WOOD:5,100)
Block(-7,2,0,SPRUCE_FENCE:0)
Block(-7,2,1,AIR:0)
Block(-7,2,2,RAILS:1)
Block(-7,2,3,SPRUCE_FENCE:0)
Block(-7,3,0,SPRUCE_FENCE:0)
Block(-7,3,1,AIR:0)
Block(-7,3,2,AIR:0)
Block(-7,3,3,SPRUCE_FENCE:0)
Block(-7,4,0,WOOD:1)
Block(-7,4,1,WOOD:1)
Block(-7,4,2,WOOD:1)
Block(-7,4,3,WOOD:1)
Block(-7,5,0,WOOD:1)
Block(-7,5,1,AIR:0)
Block(-7,5,2,AIR:0)
Block(-7,5,3,WOOD:1)
RandomBlock(-7,6,0,WOOD:5,70,WOOD:1,30,WOODEN_SLAB:5,10,WOODEN_SLAB:1,10,DARK_OAK_STAIRS:0,5,DARK_OAK_STAIRS:1,5,DARK_OAK_STAIRS:2,5,DARK_OAK_STAIRS:3,5,SPRUCE_STAIRS:0,5,SPRUCE_STAIRS:1,5,SPRUCE_STAIRS:2,5,SPRUCE_STAIRS:3,5,WOOD:5,100)
RandomBlock(-7,6,1,WOOD:5,70,WOOD:1,30,WOODEN_SLAB:5,10,WOODEN_SLAB:1,10,DARK_OAK_STAIRS:0,5,DARK_OAK_STAIRS:1,5,DARK_OAK_STAIRS:2,5,DARK_OAK_STAIRS:3,5,SPRUCE_STAIRS:0,5,SPRUCE_STAIRS:1,5,SPRUCE_STAIRS:2,5,SPRUCE_STAIRS:3,5,WOOD:5,100)
RandomBlock(-7,6,2,WOOD:5,70,WOOD:1,30,WOODEN_SLAB:5,10,WOODEN_SLAB:1,10,DARK_OAK_STAIRS:0,5,DARK_OAK_STAIRS:1,5,DARK_OAK_STAIRS:2,5,DARK_OAK_STAIRS:3,5,SPRUCE_STAIRS:0,5,SPRUCE_STAIRS:1,5,SPRUCE_STAIRS:2,5,SPRUCE_STAIRS:3,5,WOOD:5,100)
RandomBlock(-7,6,3,WOOD:5,70,WOOD:1,30,WOODEN_SLAB:5,10,WOODEN_SLAB:1,10,DARK_OAK_STAIRS:0,5,DARK_OAK_STAIRS:1,5,DARK_OAK_STAIRS:2,5,DARK_OAK_STAIRS:3,5,SPRUCE_STAIRS:0,5,SPRUCE_STAIRS:1,5,SPRUCE_STAIRS:2,5,SPRUCE_STAIRS:3,5,WOOD:5,100)
Block(-7,7,0,SPRUCE_FENCE:0)
RandomBlock(-7,7,1,AIR:0,60,SKULL:1,../../../../Skulls/dungeon_skull_01.nbt,6,AIR,9,WEB,3,SKULL:1,../../../../Skulls/dungeon_skull_02.nbt,12,AIR,15,WEB,3,SKULL:1,../../../../Skulls/dungeon_skull_03.nbt,18,AIR:0,21,WEB:0,3,SKULL:1,../../../../Skulls/dungeon_skull_04.nbt,24,AIR:0,27,WEB:0,3,SKULL:1,../../../../Skulls/dungeon_skull_05.nbt,30,AIR:0,33,WEB:0,3,SKULL:1,../../../../Skulls/dungeon_skull_06.nbt,36,AIR:0,39,WEB:0,3,SKULL:1,../../../../Skulls/dungeon_skull_07.nbt,42,AIR:0,45,WEB:0,3,SKULL:1,../../../../Skulls/dungeon_skull_08.nbt,48,AIR:0,51,WEB:0,3,SKULL:1,../../../../Skulls/dungeon_skull_09.nbt,54,AIR:0,57,WEB:0,3,SKULL:1,../../../../Skulls/dungeon_skull_10.nbt,60,AIR:0,63,WEB:0,3,SKULL:1,../../../../Skulls/dungeon_skull_11.nbt,66,AIR:0,69,WEB:0,3,SKULL:1,../../../../Skulls/dungeon_skull_12.nbt,72,AIR:0,75,WEB:0,3,SKULL:1,../../../../Skulls/dungeon_skull_13.nbt,78,AIR:0,81,WEB:0,3,SKULL:1,../../../../Skulls/dungeon_skull_14.nbt,84,AIR:0,87,WEB:0,3,SKULL:1,../../../../Skulls/dungeon_skull_15.nbt,90,AIR:0,93,WEB:0,3,SKULL:1,../../../../Skulls/dungeon_skull_16.nbt,96,AIR:0,100)
Block(-7,7,2,AIR:0)
Block(-7,7,3,SPRUCE_FENCE:0)
Block(-7,8,0,SPRUCE_FENCE:0)
Block(-7,8,1,AIR:0)
Block(-7,8,2,AIR:0)
Block(-7,8,3,SPRUCE_FENCE:0)
Block(-7,9,0,WOOD:1)
Block(-7,9,1,WOOD:1)
Block(-7,9,2,WOOD:1)
Block(-7,9,3,WOOD:1)
Block(-7,10,0,WOOD:1)
Block(-7,10,1,AIR:0)
Block(-7,10,2,AIR:0)
Block(-7,10,3,WOOD:1)
RandomBlock(-7,11,0,WOOD:5,70,WOOD:1,30,WOODEN_SLAB:5,10,WOODEN_SLAB:1,10,DARK_OAK_STAIRS:0,5,DARK_OAK_STAIRS:1,5,DARK_OAK_STAIRS:2,5,DARK_OAK_STAIRS:3,5,SPRUCE_STAIRS:0,5,SPRUCE_STAIRS:1,5,SPRUCE_STAIRS:2,5,SPRUCE_STAIRS:3,5,WOOD:5,100)
RandomBlock(-7,11,1,WOOD:5,70,WOOD:1,30,WOODEN_SLAB:5,10,WOODEN_SLAB:1,10,DARK_OAK_STAIRS:0,5,DARK_OAK_STAIRS:1,5,DARK_OAK_STAIRS:2,5,DARK_OAK_STAIRS:3,5,SPRUCE_STAIRS:0,5,SPRUCE_STAIRS:1,5,SPRUCE_STAIRS:2,5,SPRUCE_STAIRS:3,5,WOOD:5,100)
RandomBlock(-7,11,2,WOOD:5,70,WOOD:1,30,WOODEN_SLAB:5,10,WOODEN_SLAB:1,10,DARK_OAK_STAIRS:0,5,DARK_OAK_STAIRS:1,5,DARK_OAK_STAIRS:2,5,DARK_OAK_STAIRS:3,5,SPRUCE_STAIRS:0,5,SPRUCE_STAIRS:1,5,SPRUCE_STAIRS:2,5,SPRUCE_STAIRS:3,5,WOOD:5,100)
RandomBlock(-7,11,3,WOOD:5,70,WOOD:1,30,WOODEN_SLAB:5,10,WOODEN_SLAB:1,10,DARK_OAK_STAIRS:0,5,DARK_OAK_STAIRS:1,5,DARK_OAK_STAIRS:2,5,DARK_OAK_STAIRS:3,5,SPRUCE_STAIRS:0,5,SPRUCE_STAIRS:1,5,SPRUCE_STAIRS:2,5,SPRUCE_STAIRS:3,5,WOOD:5,100)
Block(-7,12,0,SPRUCE_FENCE:0)
RandomBlock(-7,12,1,AIR:0,60,SKULL:1,../../../../Skulls/dungeon_skull_01.nbt,6,AIR,9,WEB,3,SKULL:1,../../../../Skulls/dungeon_skull_02.nbt,12,AIR,15,WEB,3,SKULL:1,../../../../Skulls/dungeon_skull_03.nbt,18,AIR:0,21,WEB:0,3,SKULL:1,../../../../Skulls/dungeon_skull_04.nbt,24,AIR:0,27,WEB:0,3,SKULL:1,../../../../Skulls/dungeon_skull_05.nbt,30,AIR:0,33,WEB:0,3,SKULL:1,../../../../Skulls/dungeon_skull_06.nbt,36,AIR:0,39,WEB:0,3,SKULL:1,../../../../Skulls/dungeon_skull_07.nbt,42,AIR:0,45,WEB:0,3,SKULL:1,../../../../Skulls/dungeon_skull_08.nbt,48,AIR:0,51,WEB:0,3,SKULL:1,../../../../Skulls/dungeon_skull_09.nbt,54,AIR:0,57,WEB:0,3,SKULL:1,../../../../Skulls/dungeon_skull_10.nbt,60,AIR:0,63,WEB:0,3,SKULL:1,../../../../Skulls/dungeon_skull_11.nbt,66,AIR:0,69,WEB:0,3,SKULL:1,../../../../Skulls/dungeon_skull_12.nbt,72,AIR:0,75,WEB:0,3,SKULL:1,../../../../Skulls/dungeon_skull_13.nbt,78,AIR:0,81,WEB:0,3,SKULL:1,../../../../Skulls/dungeon_skull_14.nbt,84,AIR:0,87,WEB:0,3,SKULL:1,../../../../Skulls/dungeon_skull_15.nbt,90,AIR:0,93,WEB:0,3,SKULL:1,../../../../Skulls/dungeon_skull_16.nbt,96,AIR:0,100)
Block(-7,12,2,AIR:0)
Block(-7,12,3,SPRUCE_FENCE:0)
Block(-7,13,0,SPRUCE_FENCE:0)
Block(-7,13,1,AIR:0)
Block(-7,13,2,AIR:0)
Block(-7,13,3,SPRUCE_FENCE:0)
Block(-7,14,0,WOOD:1)
Block(-7,14,1,WOOD:1)
Block(-7,14,2,WOOD:1)
Block(-7,14,3,WOOD:1)
Block(-7,15,0,WOOD:1)
Block(-7,15,1,AIR:0)
Block(-7,15,2,AIR:0)
Block(-7,15,3,WOOD:1)
RandomBlock(-7,16,0,WOOD:5,70,WOOD:1,30,WOODEN_SLAB:5,10,WOODEN_SLAB:1,10,DARK_OAK_STAIRS:0,5,DARK_OAK_STAIRS:1,5,DARK_OAK_STAIRS:2,5,DARK_OAK_STAIRS:3,5,SPRUCE_STAIRS:0,5,SPRUCE_STAIRS:1,5,SPRUCE_STAIRS:2,5,SPRUCE_STAIRS:3,5,WOOD:5,100)
RandomBlock(-7,16,1,WOOD:5,70,WOOD:1,30,WOODEN_SLAB:5,10,WOODEN_SLAB:1,10,DARK_OAK_STAIRS:0,5,DARK_OAK_STAIRS:1,5,DARK_OAK_STAIRS:2,5,DARK_OAK_STAIRS:3,5,SPRUCE_STAIRS:0,5,SPRUCE_STAIRS:1,5,SPRUCE_STAIRS:2,5,SPRUCE_STAIRS:3,5,WOOD:5,100)
RandomBlock(-7,16,2,WOOD:5,70,WOOD:1,30,WOODEN_SLAB:5,10,WOODEN_SLAB:1,10,DARK_OAK_STAIRS:0,5,DARK_OAK_STAIRS:1,5,DARK_OAK_STAIRS:2,5,DARK_OAK_STAIRS:3,5,SPRUCE_STAIRS:0,5,SPRUCE_STAIRS:1,5,SPRUCE_STAIRS:2,5,SPRUCE_STAIRS:3,5,WOOD:5,100)
RandomBlock(-7,16,3,WOOD:5,70,WOOD:1,30,WOODEN_SLAB:5,10,WOODEN_SLAB:1,10,DARK_OAK_STAIRS:0,5,DARK_OAK_STAIRS:1,5,DARK_OAK_STAIRS:2,5,DARK_OAK_STAIRS:3,5,SPRUCE_STAIRS:0,5,SPRUCE_STAIRS:1,5,SPRUCE_STAIRS:2,5,SPRUCE_STAIRS:3,5,WOOD:5,100)
Block(-7,17,0,SPRUCE_FENCE:0)
Block(-7,17,1,AIR:0)
Block(-7,17,2,AIR:0)
Block(-7,17,3,SPRUCE_FENCE:0)
Block(-7,18,0,SPRUCE_FENCE:0)
Block(-7,18,1,AIR:0)
Block(-7,18,2,AIR:0)
Block(-7,18,3,SPRUCE_FENCE:0)
Block(-7,19,0,WOOD:1)
Block(-7,19,1,WOOD:1)
Block(-7,19,2,WOOD:1)
Block(-7,19,3,WOOD:1)
RandomBlock(-6,1,0,WOOD:5,70,WOOD:1,30,WOODEN_SLAB:5,10,WOODEN_SLAB:1,10,DARK_OAK_STAIRS:0,5,DARK_OAK_STAIRS:1,5,DARK_OAK_STAIRS:2,5,DARK_OAK_STAIRS:3,5,SPRUCE_STAIRS:0,5,SPRUCE_STAIRS:1,5,SPRUCE_STAIRS:2,5,SPRUCE_STAIRS:3,5,WOOD:5,100)
RandomBlock(-6,1,1,WOOD:5,70,WOOD:1,30,WOODEN_SLAB:5,10,WOODEN_SLAB:1,10,DARK_OAK_STAIRS:0,5,DARK_OAK_STAIRS:1,5,DARK_OAK_STAIRS:2,5,DARK_OAK_STAIRS:3,5,SPRUCE_STAIRS:0,5,SPRUCE_STAIRS:1,5,SPRUCE_STAIRS:2,5,SPRUCE_STAIRS:3,5,WOOD:5,100)
RandomBlock(-6,1,2,WOOD:5,70,WOOD:1,30,WOODEN_SLAB:5,10,WOODEN_SLAB:1,10,DARK_OAK_STAIRS:0,5,DARK_OAK_STAIRS:1,5,DARK_OAK_STAIRS:2,5,DARK_OAK_STAIRS:3,5,SPRUCE_STAIRS:0,5,SPRUCE_STAIRS:1,5,SPRUCE_STAIRS:2,5,SPRUCE_STAIRS:3,5,WOOD:5,100)
RandomBlock(-6,1,3,WOOD:5,70,WOOD:1,30,WOODEN_SLAB:5,10,WOODEN_SLAB:1,10,DARK_OAK_STAIRS:0,5,DARK_OAK_STAIRS:1,5,DARK_OAK_STAIRS:2,5,DARK_OAK_STAIRS:3,5,SPRUCE_STAIRS:0,5,SPRUCE_STAIRS:1,5,SPRUCE_STAIRS:2,5,SPRUCE_STAIRS:3,5,WOOD:5,100)
RandomBlock(-6,2,0,FURNACE:3,../../../../Chests/Loot/furnace_W-Mineshafts_01.nbt,1,FURNACE:3,../../../../Chests/Loot/furnace_W-Mineshafts_02.nbt,1,FURNACE:3,../../../../Chests/Loot/furnace_W-Mineshafts_03.nbt,1,CRAFTING_TABLE:0,1,ANVIL:3,1,ANVIL:7,1,ANVIL:11,1,ANVIL:2,1,ANVIL:6,1,ANVIL:10,1,TNT:0,1,WEB:0,2,AIR:0,30,CHEST:3,../../../../Chests/Loot/abandoned_mineshaft.nbt,10,CHEST:3,../../../../Chests/Lore/Generic_5.nbt,2,CHEST:3,../../../../Chests/Lore/Generic_4.nbt,2,CHEST:3,../../../../Chests/Lore/Generic_3.nbt,2,CHEST:3,../../../../Chests/Lore/Generic_2.nbt,2,CHEST:3,../../../../Chests/Lore/Generic_1.nbt,2,CHEST:3,../../../../Chests/Lore/HiddenMine_1.nbt,1,CHEST:3,../../../../Chests/Lore/HiddenMine_2.nbt,1,CHEST:3,../../../../Chests/Lore/HiddenMine_3.nbt,1,CHEST:3,../../../../Chests/Lore/HiddenMine_4.nbt,1,CHEST:3,../../../../Chests/Lore/HiddenMine_5.nbt,1,CHEST:3,../../../../Chests/Loot/abandoned_mineshaft.nbt,100)
Block(-6,2,1,AIR:0)
Block(-6,2,2,RAILS:1)
RandomBlock(-6,2,3,AIR:0,60,SKULL:1,../../../../Skulls/dungeon_skull_01.nbt,6,AIR,9,WEB,3,SKULL:1,../../../../Skulls/dungeon_skull_02.nbt,12,AIR,15,WEB,3,SKULL:1,../../../../Skulls/dungeon_skull_03.nbt,18,AIR:0,21,WEB:0,3,SKULL:1,../../../../Skulls/dungeon_skull_04.nbt,24,AIR:0,27,WEB:0,3,SKULL:1,../../../../Skulls/dungeon_skull_05.nbt,30,AIR:0,33,WEB:0,3,SKULL:1,../../../../Skulls/dungeon_skull_06.nbt,36,AIR:0,39,WEB:0,3,SKULL:1,../../../../Skulls/dungeon_skull_07.nbt,42,AIR:0,45,WEB:0,3,SKULL:1,../../../../Skulls/dungeon_skull_08.nbt,48,AIR:0,51,WEB:0,3,SKULL:1,../../../../Skulls/dungeon_skull_09.nbt,54,AIR:0,57,WEB:0,3,SKULL:1,../../../../Skulls/dungeon_skull_10.nbt,60,AIR:0,63,WEB:0,3,SKULL:1,../../../../Skulls/dungeon_skull_11.nbt,66,AIR:0,69,WEB:0,3,SKULL:1,../../../../Skulls/dungeon_skull_12.nbt,72,AIR:0,75,WEB:0,3,SKULL:1,../../../../Skulls/dungeon_skull_13.nbt,78,AIR:0,81,WEB:0,3,SKULL:1,../../../../Skulls/dungeon_skull_14.nbt,84,AIR:0,87,WEB:0,3,SKULL:1,../../../../Skulls/dungeon_skull_15.nbt,90,AIR:0,93,WEB:0,3,SKULL:1,../../../../Skulls/dungeon_skull_16.nbt,96,AIR:0,100)
Block(-6,3,0,AIR:0)
Block(-6,3,1,AIR:0)
Block(-6,3,2,AIR:0)
Block(-6,3,3,AIR:0)
Block(-6,4,0,AIR:0)
Block(-6,4,1,AIR:0)
Block(-6,4,2,AIR:0)
Block(-6,4,3,AIR:0)
Block(-6,5,0,AIR:0)
Block(-6,5,1,AIR:0)
Block(-6,5,2,AIR:0)
Block(-6,5,3,AIR:0)
RandomBlock(-6,6,0,WOOD:5,70,WOOD:1,30,WOODEN_SLAB:5,10,WOODEN_SLAB:1,10,DARK_OAK_STAIRS:0,5,DARK_OAK_STAIRS:1,5,DARK_OAK_STAIRS:2,5,DARK_OAK_STAIRS:3,5,SPRUCE_STAIRS:0,5,SPRUCE_STAIRS:1,5,SPRUCE_STAIRS:2,5,SPRUCE_STAIRS:3,5,WOOD:5,100)
RandomBlock(-6,6,1,WOOD:5,70,WOOD:1,30,WOODEN_SLAB:5,10,WOODEN_SLAB:1,10,DARK_OAK_STAIRS:0,5,DARK_OAK_STAIRS:1,5,DARK_OAK_STAIRS:2,5,DARK_OAK_STAIRS:3,5,SPRUCE_STAIRS:0,5,SPRUCE_STAIRS:1,5,SPRUCE_STAIRS:2,5,SPRUCE_STAIRS:3,5,WOOD:5,100)
RandomBlock(-6,6,2,WOOD:5,70,WOOD:1,30,WOODEN_SLAB:5,10,WOODEN_SLAB:1,10,DARK_OAK_STAIRS:0,5,DARK_OAK_STAIRS:1,5,DARK_OAK_STAIRS:2,5,DARK_OAK_STAIRS:3,5,SPRUCE_STAIRS:0,5,SPRUCE_STAIRS:1,5,SPRUCE_STAIRS:2,5,SPRUCE_STAIRS:3,5,WOOD:5,100)
RandomBlock(-6,6,3,WOOD:5,70,WOOD:1,30,WOODEN_SLAB:5,10,WOODEN_SLAB:1,10,DARK_OAK_STAIRS:0,5,DARK_OAK_STAIRS:1,5,DARK_OAK_STAIRS:2,5,DARK_OAK_STAIRS:3,5,SPRUCE_STAIRS:0,5,SPRUCE_STAIRS:1,5,SPRUCE_STAIRS:2,5,SPRUCE_STAIRS:3,5,WOOD:5,100)
Block(-6,7,0,AIR:0)
Block(-6,7,1,AIR:0)
Block(-6,7,2,AIR:0)
Block(-6,7,3,AIR:0)
Block(-6,8,0,AIR:0)
Block(-6,8,1,AIR:0)
Block(-6,8,2,AIR:0)
Block(-6,8,3,AIR:0)
Block(-6,9,0,AIR:0)
Block(-6,9,1,AIR:0)
Block(-6,9,2,AIR:0)
Block(-6,9,3,AIR:0)
Block(-6,10,0,AIR:0)
Block(-6,10,1,AIR:0)
Block(-6,10,2,AIR:0)
Block(-6,10,3,AIR:0)
RandomBlock(-6,11,0,WOOD:5,70,WOOD:1,30,WOODEN_SLAB:5,10,WOODEN_SLAB:1,10,DARK_OAK_STAIRS:0,5,DARK_OAK_STAIRS:1,5,DARK_OAK_STAIRS:2,5,DARK_OAK_STAIRS:3,5,SPRUCE_STAIRS:0,5,SPRUCE_STAIRS:1,5,SPRUCE_STAIRS:2,5,SPRUCE_STAIRS:3,5,WOOD:5,100)
RandomBlock(-6,11,1,WOOD:5,70,WOOD:1,30,WOODEN_SLAB:5,10,WOODEN_SLAB:1,10,DARK_OAK_STAIRS:0,5,DARK_OAK_STAIRS:1,5,DARK_OAK_STAIRS:2,5,DARK_OAK_STAIRS:3,5,SPRUCE_STAIRS:0,5,SPRUCE_STAIRS:1,5,SPRUCE_STAIRS:2,5,SPRUCE_STAIRS:3,5,WOOD:5,100)
RandomBlock(-6,11,2,WOOD:5,70,WOOD:1,30,WOODEN_SLAB:5,10,WOODEN_SLAB:1,10,DARK_OAK_STAIRS:0,5,DARK_OAK_STAIRS:1,5,DARK_OAK_STAIRS:2,5,DARK_OAK_STAIRS:3,5,SPRUCE_STAIRS:0,5,SPRUCE_STAIRS:1,5,SPRUCE_STAIRS:2,5,SPRUCE_STAIRS:3,5,WOOD:5,100)
RandomBlock(-6,11,3,WOOD:5,70,WOOD:1,30,WOODEN_SLAB:5,10,WOODEN_SLAB:1,10,DARK_OAK_STAIRS:0,5,DARK_OAK_STAIRS:1,5,DARK_OAK_STAIRS:2,5,DARK_OAK_STAIRS:3,5,SPRUCE_STAIRS:0,5,SPRUCE_STAIRS:1,5,SPRUCE_STAIRS:2,5,SPRUCE_STAIRS:3,5,WOOD:5,100)
Block(-6,12,0,AIR:0)
Block(-6,12,1,AIR:0)
Block(-6,12,2,AIR:0)
Block(-6,12,3,AIR:0)
Block(-6,13,0,AIR:0)
Block(-6,13,1,AIR:0)
Block(-6,13,2,AIR:0)
Block(-6,13,3,AIR:0)
Block(-6,14,0,AIR:0)
Block(-6,14,1,AIR:0)
Block(-6,14,2,AIR:0)
Block(-6,14,3,AIR:0)
Block(-6,15,0,AIR:0)
Block(-6,15,1,AIR:0)
Block(-6,15,2,AIR:0)
Block(-6,15,3,AIR:0)
RandomBlock(-6,16,0,WOOD:5,70,WOOD:1,30,WOODEN_SLAB:5,10,WOODEN_SLAB:1,10,DARK_OAK_STAIRS:0,5,DARK_OAK_STAIRS:1,5,DARK_OAK_STAIRS:2,5,DARK_OAK_STAIRS:3,5,SPRUCE_STAIRS:0,5,SPRUCE_STAIRS:1,5,SPRUCE_STAIRS:2,5,SPRUCE_STAIRS:3,5,WOOD:5,100)
RandomBlock(-6,16,1,WOOD:5,70,WOOD:1,30,WOODEN_SLAB:5,10,WOODEN_SLAB:1,10,DARK_OAK_STAIRS:0,5,DARK_OAK_STAIRS:1,5,DARK_OAK_STAIRS:2,5,DARK_OAK_STAIRS:3,5,SPRUCE_STAIRS:0,5,SPRUCE_STAIRS:1,5,SPRUCE_STAIRS:2,5,SPRUCE_STAIRS:3,5,WOOD:5,100)
RandomBlock(-6,16,2,WOOD:5,70,WOOD:1,30,WOODEN_SLAB:5,10,WOODEN_SLAB:1,10,DARK_OAK_STAIRS:0,5,DARK_OAK_STAIRS:1,5,DARK_OAK_STAIRS:2,5,DARK_OAK_STAIRS:3,5,SPRUCE_STAIRS:0,5,SPRUCE_STAIRS:1,5,SPRUCE_STAIRS:2,5,SPRUCE_STAIRS:3,5,WOOD:5,100)
RandomBlock(-6,16,3,WOOD:5,70,WOOD:1,30,WOODEN_SLAB:5,10,WOODEN_SLAB:1,10,DARK_OAK_STAIRS:0,5,DARK_OAK_STAIRS:1,5,DARK_OAK_STAIRS:2,5,DARK_OAK_STAIRS:3,5,SPRUCE_STAIRS:0,5,SPRUCE_STAIRS:1,5,SPRUCE_STAIRS:2,5,SPRUCE_STAIRS:3,5,WOOD:5,100)
Block(-6,17,0,AIR:0)
Block(-6,17,1,AIR:0)
Block(-6,17,2,AIR:0)
Block(-6,17,3,AIR:0)
Block(-6,18,0,AIR:0)
Block(-6,18,1,AIR:0)
Block(-6,18,2,AIR:0)
Block(-6,18,3,AIR:0)
Block(-6,19,0,AIR:0)
Block(-6,19,1,AIR:0)
Block(-6,19,2,AIR:0)
Block(-6,19,3,AIR:0)
Block(-5,0,-4,LOG:1)
Block(-5,0,0,LOG:1)
Block(-5,0,3,LOG:1)
Block(-5,0,7,LOG:1)
RandomBlock(-5,1,-4,WOOD:5,70,WOOD:1,30,WOODEN_SLAB:5,10,WOODEN_SLAB:1,10,DARK_OAK_STAIRS:0,5,DARK_OAK_STAIRS:1,5,DARK_OAK_STAIRS:2,5,DARK_OAK_STAIRS:3,5,SPRUCE_STAIRS:0,5,SPRUCE_STAIRS:1,5,SPRUCE_STAIRS:2,5,SPRUCE_STAIRS:3,5,WOOD:5,100)
RandomBlock(-5,1,-3,WOOD:5,70,WOOD:1,30,WOODEN_SLAB:5,10,WOODEN_SLAB:1,10,DARK_OAK_STAIRS:0,5,DARK_OAK_STAIRS:1,5,DARK_OAK_STAIRS:2,5,DARK_OAK_STAIRS:3,5,SPRUCE_STAIRS:0,5,SPRUCE_STAIRS:1,5,SPRUCE_STAIRS:2,5,SPRUCE_STAIRS:3,5,WOOD:5,100)
RandomBlock(-5,1,-2,WOOD:5,70,WOOD:1,30,WOODEN_SLAB:5,10,WOODEN_SLAB:1,10,DARK_OAK_STAIRS:0,5,DARK_OAK_STAIRS:1,5,DARK_OAK_STAIRS:2,5,DARK_OAK_STAIRS:3,5,SPRUCE_STAIRS:0,5,SPRUCE_STAIRS:1,5,SPRUCE_STAIRS:2,5,SPRUCE_STAIRS:3,5,WOOD:5,100)
RandomBlock(-5,1,-1,WOOD:5,70,WOOD:1,30,WOODEN_SLAB:5,10,WOODEN_SLAB:1,10,DARK_OAK_STAIRS:0,5,DARK_OAK_STAIRS:1,5,DARK_OAK_STAIRS:2,5,DARK_OAK_STAIRS:3,5,SPRUCE_STAIRS:0,5,SPRUCE_STAIRS:1,5,SPRUCE_STAIRS:2,5,SPRUCE_STAIRS:3,5,WOOD:5,100)
RandomBlock(-5,1,0,WOOD:5,70,WOOD:1,30,WOODEN_SLAB:5,10,WOODEN_SLAB:1,10,DARK_OAK_STAIRS:0,5,DARK_OAK_STAIRS:1,5,DARK_OAK_STAIRS:2,5,DARK_OAK_STAIRS:3,5,SPRUCE_STAIRS:0,5,SPRUCE_STAIRS:1,5,SPRUCE_STAIRS:2,5,SPRUCE_STAIRS:3,5,WOOD:5,100)
RandomBlock(-5,1,1,WOOD:5,70,WOOD:1,30,WOODEN_SLAB:5,10,WOODEN_SLAB:1,10,DARK_OAK_STAIRS:0,5,DARK_OAK_STAIRS:1,5,DARK_OAK_STAIRS:2,5,DARK_OAK_STAIRS:3,5,SPRUCE_STAIRS:0,5,SPRUCE_STAIRS:1,5,SPRUCE_STAIRS:2,5,SPRUCE_STAIRS:3,5,WOOD:5,100)
RandomBlock(-5,1,2,WOOD:5,70,WOOD:1,30,WOODEN_SLAB:5,10,WOODEN_SLAB:1,10,DARK_OAK_STAIRS:0,5,DARK_OAK_STAIRS:1,5,DARK_OAK_STAIRS:2,5,DARK_OAK_STAIRS:3,5,SPRUCE_STAIRS:0,5,SPRUCE_STAIRS:1,5,SPRUCE_STAIRS:2,5,SPRUCE_STAIRS:3,5,WOOD:5,100)
RandomBlock(-5,1,3,WOOD:5,70,WOOD:1,30,WOODEN_SLAB:5,10,WOODEN_SLAB:1,10,DARK_OAK_STAIRS:0,5,DARK_OAK_STAIRS:1,5,DARK_OAK_STAIRS:2,5,DARK_OAK_STAIRS:3,5,SPRUCE_STAIRS:0,5,SPRUCE_STAIRS:1,5,SPRUCE_STAIRS:2,5,SPRUCE_STAIRS:3,5,WOOD:5,100)
RandomBlock(-5,1,4,WOOD:5,70,WOOD:1,30,WOODEN_SLAB:5,10,WOODEN_SLAB:1,10,DARK_OAK_STAIRS:0,5,DARK_OAK_STAIRS:1,5,DARK_OAK_STAIRS:2,5,DARK_OAK_STAIRS:3,5,SPRUCE_STAIRS:0,5,SPRUCE_STAIRS:1,5,SPRUCE_STAIRS:2,5,SPRUCE_STAIRS:3,5,WOOD:5,100)
RandomBlock(-5,1,5,WOOD:5,70,WOOD:1,30,WOODEN_SLAB:5,10,WOODEN_SLAB:1,10,DARK_OAK_STAIRS:0,5,DARK_OAK_STAIRS:1,5,DARK_OAK_STAIRS:2,5,DARK_OAK_STAIRS:3,5,SPRUCE_STAIRS:0,5,SPRUCE_STAIRS:1,5,SPRUCE_STAIRS:2,5,SPRUCE_STAIRS:3,5,WOOD:5,100)
RandomBlock(-5,1,6,WOOD:5,70,WOOD:1,30,WOODEN_SLAB:5,10,WOODEN_SLAB:1,10,DARK_OAK_STAIRS:0,5,DARK_OAK_STAIRS:1,5,DARK_OAK_STAIRS:2,5,DARK_OAK_STAIRS:3,5,SPRUCE_STAIRS:0,5,SPRUCE_STAIRS:1,5,SPRUCE_STAIRS:2,5,SPRUCE_STAIRS:3,5,WOOD:5,100)
RandomBlock(-5,1,7,WOOD:5,70,WOOD:1,30,WOODEN_SLAB:5,10,WOODEN_SLAB:1,10,DARK_OAK_STAIRS:0,5,DARK_OAK_STAIRS:1,5,DARK_OAK_STAIRS:2,5,DARK_OAK_STAIRS:3,5,SPRUCE_STAIRS:0,5,SPRUCE_STAIRS:1,5,SPRUCE_STAIRS:2,5,SPRUCE_STAIRS:3,5,WOOD:5,100)
Block(-5,2,-4,WOOD:1)
Block(-5,2,-3,SPRUCE_FENCE:0)
Block(-5,2,-2,AIR:0)
Block(-5,2,-1,SPRUCE_FENCE:0)
Block(-5,2,0,SPRUCE_FENCE:0)
Block(-5,2,1,AIR:0)
Block(-5,2,2,RAILS:1)
Block(-5,2,3,SPRUCE_FENCE:0)
Block(-5,2,4,SPRUCE_FENCE:0)
RandomBlock(-5,2,5,FURNACE:5,../../../../Chests/Loot/furnace_W-Mineshafts_01.nbt,1,FURNACE:5,../../../../Chests/Loot/furnace_W-Mineshafts_02.nbt,1,FURNACE:5,../../../../Chests/Loot/furnace_W-Mineshafts_03.nbt,1,CRAFTING_TABLE:0,1,ANVIL:3,1,ANVIL:7,1,ANVIL:11,1,ANVIL:2,1,ANVIL:6,1,ANVIL:10,1,TNT:0,1,WEB:0,2,AIR:0,30,CHEST:5,../../../../Chests/Loot/abandoned_mineshaft.nbt,10,CHEST:5,../../../../Chests/Lore/Generic_5.nbt,2,CHEST:5,../../../../Chests/Lore/Generic_4.nbt,2,CHEST:5,../../../../Chests/Lore/Generic_3.nbt,2,CHEST:5,../../../../Chests/Lore/Generic_2.nbt,2,CHEST:5,../../../../Chests/Lore/Generic_1.nbt,2,CHEST:5,../../../../Chests/Lore/HiddenMine_1.nbt,1,CHEST:5,../../../../Chests/Lore/HiddenMine_2.nbt,1,CHEST:5,../../../../Chests/Lore/HiddenMine_3.nbt,1,CHEST:5,../../../../Chests/Lore/HiddenMine_4.nbt,1,CHEST:5,../../../../Chests/Lore/HiddenMine_5.nbt,1,CHEST:5,../../../../Chests/Loot/abandoned_mineshaft.nbt,100)
Block(-5,2,6,SPRUCE_FENCE:0)
Block(-5,2,7,WOOD:1)
Block(-5,3,-4,WOOD:1)
Block(-5,3,-3,AIR:0)
Block(-5,3,-2,AIR:0)
Block(-5,3,-1,AIR:0)
Block(-5,3,0,SPRUCE_FENCE:0)
Block(-5,3,1,AIR:0)
Block(-5,3,2,AIR:0)
Block(-5,3,3,SPRUCE_FENCE:0)
Block(-5,3,4,AIR:0)
Block(-5,3,5,AIR:0)
Block(-5,3,6,AIR:0)
Block(-5,3,7,WOOD:1)
Block(-5,4,-4,WOOD:1)
Block(-5,4,-3,SPRUCE_FENCE:0)
Block(-5,4,-2,SPRUCE_FENCE:0)
Block(-5,4,-1,SPRUCE_FENCE:0)
Block(-5,4,0,WOOD:1)
Block(-5,4,1,WOOD:1)
Block(-5,4,2,WOOD:1)
Block(-5,4,3,WOOD:1)
Block(-5,4,4,SPRUCE_FENCE:0)
Block(-5,4,5,SPRUCE_FENCE:0)
Block(-5,4,6,SPRUCE_FENCE:0)
Block(-5,4,7,WOOD:1)
Block(-5,5,-1,WOOD:1)
Block(-5,5,0,WOOD:1)
Block(-5,5,1,WOOD:1)
Block(-5,5,2,WOOD:1)
Block(-5,5,3,WOOD:1)
Block(-5,5,4,WOOD:1)
RandomBlock(-5,6,-1,WOOD:5,70,WOOD:1,30,WOODEN_SLAB:5,10,WOODEN_SLAB:1,10,DARK_OAK_STAIRS:0,5,DARK_OAK_STAIRS:1,5,DARK_OAK_STAIRS:2,5,DARK_OAK_STAIRS:3,5,SPRUCE_STAIRS:0,5,SPRUCE_STAIRS:1,5,SPRUCE_STAIRS:2,5,SPRUCE_STAIRS:3,5,WOOD:5,100)
Block(-5,6,0,DARK_OAK_STAIRS:1)
RandomBlock(-5,6,1,WOOD:5,70,WOOD:1,30,WOODEN_SLAB:5,10,WOODEN_SLAB:1,10,DARK_OAK_STAIRS:0,5,DARK_OAK_STAIRS:1,5,DARK_OAK_STAIRS:2,5,DARK_OAK_STAIRS:3,5,SPRUCE_STAIRS:0,5,SPRUCE_STAIRS:1,5,SPRUCE_STAIRS:2,5,SPRUCE_STAIRS:3,5,WOOD:5,100)
RandomBlock(-5,6,2,WOOD:5,70,WOOD:1,30,WOODEN_SLAB:5,10,WOODEN_SLAB:1,10,DARK_OAK_STAIRS:0,5,DARK_OAK_STAIRS:1,5,DARK_OAK_STAIRS:2,5,DARK_OAK_STAIRS:3,5,SPRUCE_STAIRS:0,5,SPRUCE_STAIRS:1,5,SPRUCE_STAIRS:2,5,SPRUCE_STAIRS:3,5,WOOD:5,100)
Block(-5,6,3,DARK_OAK_STAIRS:1)
RandomBlock(-5,6,4,WOOD:5,70,WOOD:1,30,WOODEN_SLAB:5,10,WOODEN_SLAB:1,10,DARK_OAK_STAIRS:0,5,DARK_OAK_STAIRS:1,5,DARK_OAK_STAIRS:2,5,DARK_OAK_STAIRS:3,5,SPRUCE_STAIRS:0,5,SPRUCE_STAIRS:1,5,SPRUCE_STAIRS:2,5,SPRUCE_STAIRS:3,5,WOOD:5,100)
Block(-5,7,-1,SPRUCE_FENCE:0)
Block(-5,7,0,AIR:0)
Block(-5,7,1,SPRUCE_FENCE:0)
Block(-5,7,2,SPRUCE_FENCE:0)
Block(-5,7,3,AIR:0)
Block(-5,7,4,SPRUCE_FENCE:0)
Block(-5,8,-1,SPRUCE_FENCE:0)
Block(-5,8,0,AIR:0)
Block(-5,8,1,SPRUCE_FENCE:0)
Block(-5,8,2,SPRUCE_FENCE:0)
Block(-5,8,3,AIR:0)
Block(-5,8,4,SPRUCE_FENCE:0)
Block(-5,9,-1,WOOD:1)
Block(-5,9,0,WOOD:1)
Block(-5,9,1,WOOD:1)
Block(-5,9,2,WOOD:1)
Block(-5,9,3,WOOD:1)
Block(-5,9,4,WOOD:1)
Block(-5,10,-1,WOOD:1)
Block(-5,10,0,WOOD:1)
Block(-5,10,1,WOOD:1)
Block(-5,10,2,WOOD:1)
Block(-5,10,3,WOOD:1)
Block(-5,10,4,WOOD:1)
RandomBlock(-5,11,-1,WOOD:5,70,WOOD:1,30,WOODEN_SLAB:5,10,WOODEN_SLAB:1,10,DARK_OAK_STAIRS:0,5,DARK_OAK_STAIRS:1,5,DARK_OAK_STAIRS:2,5,DARK_OAK_STAIRS:3,5,SPRUCE_STAIRS:0,5,SPRUCE_STAIRS:1,5,SPRUCE_STAIRS:2,5,SPRUCE_STAIRS:3,5,WOOD:5,100)
Block(-5,11,0,DARK_OAK_STAIRS:1)
RandomBlock(-5,11,1,WOOD:5,70,WOOD:1,30,WOODEN_SLAB:5,10,WOODEN_SLAB:1,10,DARK_OAK_STAIRS:0,5,DARK_OAK_STAIRS:1,5,DARK_OAK_STAIRS:2,5,DARK_OAK_STAIRS:3,5,SPRUCE_STAIRS:0,5,SPRUCE_STAIRS:1,5,SPRUCE_STAIRS:2,5,SPRUCE_STAIRS:3,5,WOOD:5,100)
RandomBlock(-5,11,2,WOOD:5,70,WOOD:1,30,WOODEN_SLAB:5,10,WOODEN_SLAB:1,10,DARK_OAK_STAIRS:0,5,DARK_OAK_STAIRS:1,5,DARK_OAK_STAIRS:2,5,DARK_OAK_STAIRS:3,5,SPRUCE_STAIRS:0,5,SPRUCE_STAIRS:1,5,SPRUCE_STAIRS:2,5,SPRUCE_STAIRS:3,5,WOOD:5,100)
Block(-5,11,3,DARK_OAK_STAIRS:1)
RandomBlock(-5,11,4,WOOD:5,70,WOOD:1,30,WOODEN_SLAB:5,10,WOODEN_SLAB:1,10,DARK_OAK_STAIRS:0,5,DARK_OAK_STAIRS:1,5,DARK_OAK_STAIRS:2,5,DARK_OAK_STAIRS:3,5,SPRUCE_STAIRS:0,5,SPRUCE_STAIRS:1,5,SPRUCE_STAIRS:2,5,SPRUCE_STAIRS:3,5,WOOD:5,100)
Block(-5,12,-1,SPRUCE_FENCE:0)
Block(-5,12,0,AIR:0)
Block(-5,12,1,SPRUCE_FENCE:0)
Block(-5,12,2,SPRUCE_FENCE:0)
Block(-5,12,3,AIR:0)
Block(-5,12,4,SPRUCE_FENCE:0)
Block(-5,13,-1,SPRUCE_FENCE:0)
Block(-5,13,0,AIR:0)
Block(-5,13,1,SPRUCE_FENCE:0)
Block(-5,13,2,SPRUCE_FENCE:0)
Block(-5,13,3,AIR:0)
Block(-5,13,4,SPRUCE_FENCE:0)
Block(-5,14,-1,WOOD:1)
Block(-5,14,0,WOOD:1)
Block(-5,14,1,WOOD:1)
Block(-5,14,2,WOOD:1)
Block(-5,14,3,WOOD:1)
Block(-5,14,4,WOOD:1)
Block(-5,15,-1,WOOD:1)
Block(-5,15,0,WOOD:1)
Block(-5,15,1,WOOD:1)
Block(-5,15,2,WOOD:1)
Block(-5,15,3,WOOD:1)
Block(-5,15,4,WOOD:1)
RandomBlock(-5,16,-1,WOOD:5,70,WOOD:1,30,WOODEN_SLAB:5,10,WOODEN_SLAB:1,10,DARK_OAK_STAIRS:0,5,DARK_OAK_STAIRS:1,5,DARK_OAK_STAIRS:2,5,DARK_OAK_STAIRS:3,5,SPRUCE_STAIRS:0,5,SPRUCE_STAIRS:1,5,SPRUCE_STAIRS:2,5,SPRUCE_STAIRS:3,5,WOOD:5,100)
Block(-5,16,0,DARK_OAK_STAIRS:1)
RandomBlock(-5,16,1,WOOD:5,70,WOOD:1,30,WOODEN_SLAB:5,10,WOODEN_SLAB:1,10,DARK_OAK_STAIRS:0,5,DARK_OAK_STAIRS:1,5,DARK_OAK_STAIRS:2,5,DARK_OAK_STAIRS:3,5,SPRUCE_STAIRS:0,5,SPRUCE_STAIRS:1,5,SPRUCE_STAIRS:2,5,SPRUCE_STAIRS:3,5,WOOD:5,100)
RandomBlock(-5,16,2,WOOD:5,70,WOOD:1,30,WOODEN_SLAB:5,10,WOODEN_SLAB:1,10,DARK_OAK_STAIRS:0,5,DARK_OAK_STAIRS:1,5,DARK_OAK_STAIRS:2,5,DARK_OAK_STAIRS:3,5,SPRUCE_STAIRS:0,5,SPRUCE_STAIRS:1,5,SPRUCE_STAIRS:2,5,SPRUCE_STAIRS:3,5,WOOD:5,100)
Block(-5,16,3,DARK_OAK_STAIRS:1)
RandomBlock(-5,16,4,WOOD:5,70,WOOD:1,30,WOODEN_SLAB:5,10,WOODEN_SLAB:1,10,DARK_OAK_STAIRS:0,5,DARK_OAK_STAIRS:1,5,DARK_OAK_STAIRS:2,5,DARK_OAK_STAIRS:3,5,SPRUCE_STAIRS:0,5,SPRUCE_STAIRS:1,5,SPRUCE_STAIRS:2,5,SPRUCE_STAIRS:3,5,WOOD:5,100)
Block(-5,17,-1,SPRUCE_FENCE:0)
Block(-5,17,0,AIR:0)
Block(-5,17,1,SPRUCE_FENCE:0)
Block(-5,17,2,SPRUCE_FENCE:0)
Block(-5,17,3,AIR:0)
Block(-5,17,4,SPRUCE_FENCE:0)
Block(-5,18,-1,SPRUCE_FENCE:0)
Block(-5,18,0,AIR:0)
Block(-5,18,1,SPRUCE_FENCE:0)
Block(-5,18,2,SPRUCE_FENCE:0)
Block(-5,18,3,AIR:0)
Block(-5,18,4,SPRUCE_FENCE:0)
Block(-5,19,-1,WOOD:1)
Block(-5,19,0,WOOD:1)
Block(-5,19,1,WOOD:1)
Block(-5,19,2,WOOD:1)
Block(-5,19,3,WOOD:1)
Block(-5,19,4,WOOD:1)
RandomBlock(-4,1,-4,WOOD:5,70,WOOD:1,30,WOODEN_SLAB:5,10,WOODEN_SLAB:1,10,DARK_OAK_STAIRS:0,5,DARK_OAK_STAIRS:1,5,DARK_OAK_STAIRS:2,5,DARK_OAK_STAIRS:3,5,SPRUCE_STAIRS:0,5,SPRUCE_STAIRS:1,5,SPRUCE_STAIRS:2,5,SPRUCE_STAIRS:3,5,WOOD:5,100)
RandomBlock(-4,1,-3,WOOD:5,70,WOOD:1,30,WOODEN_SLAB:5,10,WOODEN_SLAB:1,10,DARK_OAK_STAIRS:0,5,DARK_OAK_STAIRS:1,5,DARK_OAK_STAIRS:2,5,DARK_OAK_STAIRS:3,5,SPRUCE_STAIRS:0,5,SPRUCE_STAIRS:1,5,SPRUCE_STAIRS:2,5,SPRUCE_STAIRS:3,5,WOOD:5,100)
RandomBlock(-4,1,-2,WOOD:5,70,WOOD:1,30,WOODEN_SLAB:5,10,WOODEN_SLAB:1,10,DARK_OAK_STAIRS:0,5,DARK_OAK_STAIRS:1,5,DARK_OAK_STAIRS:2,5,DARK_OAK_STAIRS:3,5,SPRUCE_STAIRS:0,5,SPRUCE_STAIRS:1,5,SPRUCE_STAIRS:2,5,SPRUCE_STAIRS:3,5,WOOD:5,100)
RandomBlock(-4,1,-1,WOOD:5,70,WOOD:1,30,WOODEN_SLAB:5,10,WOODEN_SLAB:1,10,DARK_OAK_STAIRS:0,5,DARK_OAK_STAIRS:1,5,DARK_OAK_STAIRS:2,5,DARK_OAK_STAIRS:3,5,SPRUCE_STAIRS:0,5,SPRUCE_STAIRS:1,5,SPRUCE_STAIRS:2,5,SPRUCE_STAIRS:3,5,WOOD:5,100)
RandomBlock(-4,1,0,WOOD:5,70,WOOD:1,30,WOODEN_SLAB:5,10,WOODEN_SLAB:1,10,DARK_OAK_STAIRS:0,5,DARK_OAK_STAIRS:1,5,DARK_OAK_STAIRS:2,5,DARK_OAK_STAIRS:3,5,SPRUCE_STAIRS:0,5,SPRUCE_STAIRS:1,5,SPRUCE_STAIRS:2,5,SPRUCE_STAIRS:3,5,WOOD:5,100)
RandomBlock(-4,1,1,WOOD:5,70,WOOD:1,30,WOODEN_SLAB:5,10,WOODEN_SLAB:1,10,DARK_OAK_STAIRS:0,5,DARK_OAK_STAIRS:1,5,DARK_OAK_STAIRS:2,5,DARK_OAK_STAIRS:3,5,SPRUCE_STAIRS:0,5,SPRUCE_STAIRS:1,5,SPRUCE_STAIRS:2,5,SPRUCE_STAIRS:3,5,WOOD:5,100)
RandomBlock(-4,1,2,WOOD:5,70,WOOD:1,30,WOODEN_SLAB:5,10,WOODEN_SLAB:1,10,DARK_OAK_STAIRS:0,5,DARK_OAK_STAIRS:1,5,DARK_OAK_STAIRS:2,5,DARK_OAK_STAIRS:3,5,SPRUCE_STAIRS:0,5,SPRUCE_STAIRS:1,5,SPRUCE_STAIRS:2,5,SPRUCE_STAIRS:3,5,WOOD:5,100)
RandomBlock(-4,1,3,WOOD:5,70,WOOD:1,30,WOODEN_SLAB:5,10,WOODEN_SLAB:1,10,DARK_OAK_STAIRS:0,5,DARK_OAK_STAIRS:1,5,DARK_OAK_STAIRS:2,5,DARK_OAK_STAIRS:3,5,SPRUCE_STAIRS:0,5,SPRUCE_STAIRS:1,5,SPRUCE_STAIRS:2,5,SPRUCE_STAIRS:3,5,WOOD:5,100)
RandomBlock(-4,1,4,WOOD:5,70,WOOD:1,30,WOODEN_SLAB:5,10,WOODEN_SLAB:1,10,DARK_OAK_STAIRS:0,5,DARK_OAK_STAIRS:1,5,DARK_OAK_STAIRS:2,5,DARK_OAK_STAIRS:3,5,SPRUCE_STAIRS:0,5,SPRUCE_STAIRS:1,5,SPRUCE_STAIRS:2,5,SPRUCE_STAIRS:3,5,WOOD:5,100)
RandomBlock(-4,1,5,WOOD:5,70,WOOD:1,30,WOODEN_SLAB:5,10,WOODEN_SLAB:1,10,DARK_OAK_STAIRS:0,5,DARK_OAK_STAIRS:1,5,DARK_OAK_STAIRS:2,5,DARK_OAK_STAIRS:3,5,SPRUCE_STAIRS:0,5,SPRUCE_STAIRS:1,5,SPRUCE_STAIRS:2,5,SPRUCE_STAIRS:3,5,WOOD:5,100)
RandomBlock(-4,1,6,WOOD:5,70,WOOD:1,30,WOODEN_SLAB:5,10,WOODEN_SLAB:1,10,DARK_OAK_STAIRS:0,5,DARK_OAK_STAIRS:1,5,DARK_OAK_STAIRS:2,5,DARK_OAK_STAIRS:3,5,SPRUCE_STAIRS:0,5,SPRUCE_STAIRS:1,5,SPRUCE_STAIRS:2,5,SPRUCE_STAIRS:3,5,WOOD:5,100)
RandomBlock(-4,1,7,WOOD:5,70,WOOD:1,30,WOODEN_SLAB:5,10,WOODEN_SLAB:1,10,DARK_OAK_STAIRS:0,5,DARK_OAK_STAIRS:1,5,DARK_OAK_STAIRS:2,5,DARK_OAK_STAIRS:3,5,SPRUCE_STAIRS:0,5,SPRUCE_STAIRS:1,5,SPRUCE_STAIRS:2,5,SPRUCE_STAIRS:3,5,WOOD:5,100)
Block(-4,2,-4,SPRUCE_FENCE:0)
Block(-4,2,-3,AIR:0)
Block(-4,2,-2,DARK_OAK_STAIRS:2)
Block(-4,2,-1,RAILS:0)
Block(-4,2,0,RAILS:0)
Block(-4,2,1,RAILS:0)
Block(-4,2,2,RAILS:8)
Block(-4,2,3,AIR:0)
Block(-4,2,4,AIR:0)
Block(-4,2,5,AIR:0)
RandomBlock(-4,2,6,AIR:0,60,SKULL:1,../../../../Skulls/dungeon_skull_01.nbt,6,AIR,9,WEB,3,SKULL:1,../../../../Skulls/dungeon_skull_02.nbt,12,AIR,15,WEB,3,SKULL:1,../../../../Skulls/dungeon_skull_03.nbt,18,AIR:0,21,WEB:0,3,SKULL:1,../../../../Skulls/dungeon_skull_04.nbt,24,AIR:0,27,WEB:0,3,SKULL:1,../../../../Skulls/dungeon_skull_05.nbt,30,AIR:0,33,WEB:0,3,SKULL:1,../../../../Skulls/dungeon_skull_06.nbt,36,AIR:0,39,WEB:0,3,SKULL:1,../../../../Skulls/dungeon_skull_07.nbt,42,AIR:0,45,WEB:0,3,SKULL:1,../../../../Skulls/dungeon_skull_08.nbt,48,AIR:0,51,WEB:0,3,SKULL:1,../../../../Skulls/dungeon_skull_09.nbt,54,AIR:0,57,WEB:0,3,SKULL:1,../../../../Skulls/dungeon_skull_10.nbt,60,AIR:0,63,WEB:0,3,SKULL:1,../../../../Skulls/dungeon_skull_11.nbt,66,AIR:0,69,WEB:0,3,SKULL:1,../../../../Skulls/dungeon_skull_12.nbt,72,AIR:0,75,WEB:0,3,SKULL:1,../../../../Skulls/dungeon_skull_13.nbt,78,AIR:0,81,WEB:0,3,SKULL:1,../../../../Skulls/dungeon_skull_14.nbt,84,AIR:0,87,WEB:0,3,SKULL:1,../../../../Skulls/dungeon_skull_15.nbt,90,AIR:0,93,WEB:0,3,SKULL:1,../../../../Skulls/dungeon_skull_16.nbt,96,AIR:0,100)
Block(-4,2,7,SPRUCE_FENCE:0)
Block(-4,3,-4,AIR:0)
Block(-4,3,-3,AIR:0)
Block(-4,3,-2,AIR:0)
Block(-4,3,-1,AIR:0)
Block(-4,3,0,AIR:0)
Entity(-4,3,1,MINECART,1)
Block(-4,3,1,AIR:0)
Block(-4,3,2,AIR:0)
Block(-4,3,3,AIR:0)
Block(-4,3,4,AIR:0)
Block(-4,3,5,AIR:0)
Block(-4,3,6,AIR:0)
Block(-4,3,7,AIR:0)
Block(-4,4,-4,SPRUCE_FENCE:0)
Block(-4,4,-3,AIR:0)
Block(-4,4,-2,AIR:0)
Block(-4,4,-1,AIR:0)
Block(-4,4,0,SPRUCE_FENCE:0)
Block(-4,4,1,AIR:0)
Block(-4,4,2,AIR:0)
Block(-4,4,3,SPRUCE_FENCE:0)
Block(-4,4,4,AIR:0)
Block(-4,4,5,AIR:0)
Block(-4,4,6,AIR:0)
Block(-4,4,7,SPRUCE_FENCE:0)
Block(-4,5,-3,WOOD:1)
Block(-4,5,-2,WOOD:1)
Block(-4,5,-1,WOOD:1)
Block(-4,5,0,WOOD:1)
Block(-4,5,1,SPRUCE_FENCE:0)
Block(-4,5,2,SPRUCE_FENCE:0)
Block(-4,5,3,WOOD:1)
Block(-4,5,4,WOOD:1)
Block(-4,5,5,WOOD:1)
Block(-4,5,6,WOOD:1)
Block(-4,6,-3,AIR:0)
Block(-4,6,-2,AIR:0)
Block(-4,6,-1,AIR:0)
Block(-4,6,0,AIR:0)
Block(-4,6,1,SPRUCE_FENCE:0)
Block(-4,6,2,SPRUCE_FENCE:0)
Block(-4,6,3,AIR:0)
Block(-4,6,4,AIR:0)
Block(-4,6,5,AIR:0)
Block(-4,6,6,AIR:0)
Block(-4,7,-3,AIR:0)
Block(-4,7,-2,AIR:0)
Block(-4,7,-1,AIR:0)
Block(-4,7,0,AIR:0)
Block(-4,7,1,SPRUCE_FENCE:0)
Block(-4,7,2,SPRUCE_FENCE:0)
Block(-4,7,3,AIR:0)
Block(-4,7,4,AIR:0)
Block(-4,7,5,AIR:0)
Block(-4,7,6,AIR:0)
Block(-4,8,-3,AIR:0)
Block(-4,8,-2,AIR:0)
Block(-4,8,-1,AIR:0)
Block(-4,8,0,AIR:0)
Block(-4,8,1,SPRUCE_FENCE:0)
Block(-4,8,2,SPRUCE_FENCE:0)
Block(-4,8,3,AIR:0)
Block(-4,8,4,AIR:0)
Block(-4,8,5,AIR:0)
Block(-4,8,6,AIR:0)
Block(-4,9,-3,SPRUCE_FENCE:0)
Block(-4,9,-2,SPRUCE_FENCE:0)
Block(-4,9,-1,SPRUCE_FENCE:0)
Block(-4,9,0,SPRUCE_FENCE:0)
Block(-4,9,1,SPRUCE_FENCE:0)
Block(-4,9,2,SPRUCE_FENCE:0)
Block(-4,9,3,SPRUCE_FENCE:0)
Block(-4,9,4,SPRUCE_FENCE:0)
Block(-4,9,5,SPRUCE_FENCE:0)
Block(-4,9,6,SPRUCE_FENCE:0)
Block(-4,10,-3,WOOD:1)
Block(-4,10,-2,WOOD:1)
Block(-4,10,-1,WOOD:1)
Block(-4,10,0,WOOD:1)
Block(-4,10,1,SPRUCE_FENCE:0)
Block(-4,10,2,SPRUCE_FENCE:0)
Block(-4,10,3,WOOD:1)
Block(-4,10,4,WOOD:1)
Block(-4,10,5,WOOD:1)
Block(-4,10,6,WOOD:1)
Block(-4,11,-3,SPRUCE_FENCE:0)
Block(-4,11,-2,AIR:0)
Block(-4,11,-1,AIR:0)
Block(-4,11,0,AIR:0)
Block(-4,11,1,SPRUCE_FENCE:0)
Block(-4,11,2,SPRUCE_FENCE:0)
Block(-4,11,3,AIR:0)
Block(-4,11,4,AIR:0)
Block(-4,11,5,AIR:0)
Block(-4,11,6,SPRUCE_FENCE:0)
Block(-4,12,-3,SPRUCE_FENCE:0)
Block(-4,12,-2,AIR:0)
Block(-4,12,-1,AIR:0)
Block(-4,12,0,AIR:0)
Block(-4,12,1,SPRUCE_FENCE:0)
Block(-4,12,2,SPRUCE_FENCE:0)
Block(-4,12,3,AIR:0)
Block(-4,12,4,AIR:0)
Block(-4,12,5,AIR:0)
Block(-4,12,6,SPRUCE_FENCE:0)
Block(-4,13,-3,SPRUCE_FENCE:0)
Block(-4,13,-2,AIR:0)
Block(-4,13,-1,AIR:0)
Block(-4,13,0,AIR:0)
Block(-4,13,1,SPRUCE_FENCE:0)
Block(-4,13,2,SPRUCE_FENCE:0)
Block(-4,13,3,AIR:0)
Block(-4,13,4,AIR:0)
Block(-4,13,5,AIR:0)
Block(-4,13,6,SPRUCE_FENCE:0)
Block(-4,14,-3,SPRUCE_FENCE:0)
Block(-4,14,-2,SPRUCE_FENCE:0)
Block(-4,14,-1,SPRUCE_FENCE:0)
Block(-4,14,0,SPRUCE_FENCE:0)
Block(-4,14,1,SPRUCE_FENCE:0)
Block(-4,14,2,SPRUCE_FENCE:0)
Block(-4,14,3,SPRUCE_FENCE:0)
Block(-4,14,4,SPRUCE_FENCE:0)
Block(-4,14,5,SPRUCE_FENCE:0)
Block(-4,14,6,SPRUCE_FENCE:0)
Block(-4,15,-3,WOOD:1)
Block(-4,15,-2,WOOD:1)
Block(-4,15,-1,WOOD:1)
Block(-4,15,0,WOOD:1)
Block(-4,15,1,SPRUCE_FENCE:0)
Block(-4,15,2,SPRUCE_FENCE:0)
Block(-4,15,3,WOOD:1)
Block(-4,15,4,WOOD:1)
Block(-4,15,5,WOOD:1)
Block(-4,15,6,WOOD:1)
Block(-4,16,-3,SPRUCE_FENCE:0)
Block(-4,16,-2,AIR:0)
Block(-4,16,-1,AIR:0)
Block(-4,16,0,AIR:0)
Block(-4,16,1,SPRUCE_FENCE:0)
Block(-4,16,2,SPRUCE_FENCE:0)
Block(-4,16,3,AIR:0)
Block(-4,16,4,AIR:0)
Block(-4,16,5,AIR:0)
Block(-4,16,6,SPRUCE_FENCE:0)
Block(-4,17,-3,SPRUCE_FENCE:0)
Block(-4,17,-2,AIR:0)
Block(-4,17,-1,AIR:0)
Block(-4,17,0,AIR:0)
Block(-4,17,1,SPRUCE_FENCE:0)
Block(-4,17,2,SPRUCE_FENCE:0)
Block(-4,17,3,AIR:0)
Block(-4,17,4,AIR:0)
Block(-4,17,5,AIR:0)
Block(-4,17,6,SPRUCE_FENCE:0)
Block(-4,18,-3,SPRUCE_FENCE:0)
Block(-4,18,-2,AIR:0)
Block(-4,18,-1,AIR:0)
Block(-4,18,0,AIR:0)
Block(-4,18,1,SPRUCE_FENCE:0)
Block(-4,18,2,SPRUCE_FENCE:0)
Block(-4,18,3,AIR:0)
Block(-4,18,4,AIR:0)
Block(-4,18,5,AIR:0)
Block(-4,18,6,SPRUCE_FENCE:0)
Block(-4,19,-3,WOOD:1)
Block(-4,19,-2,WOOD:1)
Block(-4,19,-1,WOOD:1)
Block(-4,19,0,WOOD:1)
Block(-4,19,1,WOOD:1)
Block(-4,19,2,WOOD:1)
Block(-4,19,3,WOOD:1)
Block(-4,19,4,WOOD:1)
Block(-4,19,5,WOOD:1)
Block(-4,19,6,WOOD:1)
RandomBlock(-3,1,-4,WOOD:5,70,WOOD:1,30,WOODEN_SLAB:5,10,WOODEN_SLAB:1,10,DARK_OAK_STAIRS:0,5,DARK_OAK_STAIRS:1,5,DARK_OAK_STAIRS:2,5,DARK_OAK_STAIRS:3,5,SPRUCE_STAIRS:0,5,SPRUCE_STAIRS:1,5,SPRUCE_STAIRS:2,5,SPRUCE_STAIRS:3,5,WOOD:5,100)
RandomBlock(-3,1,-3,WOOD:5,70,WOOD:1,30,WOODEN_SLAB:5,10,WOODEN_SLAB:1,10,DARK_OAK_STAIRS:0,5,DARK_OAK_STAIRS:1,5,DARK_OAK_STAIRS:2,5,DARK_OAK_STAIRS:3,5,SPRUCE_STAIRS:0,5,SPRUCE_STAIRS:1,5,SPRUCE_STAIRS:2,5,SPRUCE_STAIRS:3,5,WOOD:5,100)
RandomBlock(-3,1,-2,WOOD:5,70,WOOD:1,30,WOODEN_SLAB:5,10,WOODEN_SLAB:1,10,DARK_OAK_STAIRS:0,5,DARK_OAK_STAIRS:1,5,DARK_OAK_STAIRS:2,5,DARK_OAK_STAIRS:3,5,SPRUCE_STAIRS:0,5,SPRUCE_STAIRS:1,5,SPRUCE_STAIRS:2,5,SPRUCE_STAIRS:3,5,WOOD:5,100)
RandomBlock(-3,1,-1,WOOD:5,70,WOOD:1,30,WOODEN_SLAB:5,10,WOODEN_SLAB:1,10,DARK_OAK_STAIRS:0,5,DARK_OAK_STAIRS:1,5,DARK_OAK_STAIRS:2,5,DARK_OAK_STAIRS:3,5,SPRUCE_STAIRS:0,5,SPRUCE_STAIRS:1,5,SPRUCE_STAIRS:2,5,SPRUCE_STAIRS:3,5,WOOD:5,100)
RandomBlock(-3,1,0,WOOD:5,70,WOOD:1,30,WOODEN_SLAB:5,10,WOODEN_SLAB:1,10,DARK_OAK_STAIRS:0,5,DARK_OAK_STAIRS:1,5,DARK_OAK_STAIRS:2,5,DARK_OAK_STAIRS:3,5,SPRUCE_STAIRS:0,5,SPRUCE_STAIRS:1,5,SPRUCE_STAIRS:2,5,SPRUCE_STAIRS:3,5,WOOD:5,100)
RandomBlock(-3,1,1,WOOD:5,70,WOOD:1,30,WOODEN_SLAB:5,10,WOODEN_SLAB:1,10,DARK_OAK_STAIRS:0,5,DARK_OAK_STAIRS:1,5,DARK_OAK_STAIRS:2,5,DARK_OAK_STAIRS:3,5,SPRUCE_STAIRS:0,5,SPRUCE_STAIRS:1,5,SPRUCE_STAIRS:2,5,SPRUCE_STAIRS:3,5,WOOD:5,100)
RandomBlock(-3,1,2,WOOD:5,70,WOOD:1,30,WOODEN_SLAB:5,10,WOODEN_SLAB:1,10,DARK_OAK_STAIRS:0,5,DARK_OAK_STAIRS:1,5,DARK_OAK_STAIRS:2,5,DARK_OAK_STAIRS:3,5,SPRUCE_STAIRS:0,5,SPRUCE_STAIRS:1,5,SPRUCE_STAIRS:2,5,SPRUCE_STAIRS:3,5,WOOD:5,100)
RandomBlock(-3,1,3,WOOD:5,70,WOOD:1,30,WOODEN_SLAB:5,10,WOODEN_SLAB:1,10,DARK_OAK_STAIRS:0,5,DARK_OAK_STAIRS:1,5,DARK_OAK_STAIRS:2,5,DARK_OAK_STAIRS:3,5,SPRUCE_STAIRS:0,5,SPRUCE_STAIRS:1,5,SPRUCE_STAIRS:2,5,SPRUCE_STAIRS:3,5,WOOD:5,100)
RandomBlock(-3,1,4,WOOD:5,70,WOOD:1,30,WOODEN_SLAB:5,10,WOODEN_SLAB:1,10,DARK_OAK_STAIRS:0,5,DARK_OAK_STAIRS:1,5,DARK_OAK_STAIRS:2,5,DARK_OAK_STAIRS:3,5,SPRUCE_STAIRS:0,5,SPRUCE_STAIRS:1,5,SPRUCE_STAIRS:2,5,SPRUCE_STAIRS:3,5,WOOD:5,100)
RandomBlock(-3,1,5,WOOD:5,70,WOOD:1,30,WOODEN_SLAB:5,10,WOODEN_SLAB:1,10,DARK_OAK_STAIRS:0,5,DARK_OAK_STAIRS:1,5,DARK_OAK_STAIRS:2,5,DARK_OAK_STAIRS:3,5,SPRUCE_STAIRS:0,5,SPRUCE_STAIRS:1,5,SPRUCE_STAIRS:2,5,SPRUCE_STAIRS:3,5,WOOD:5,100)
RandomBlock(-3,1,6,WOOD:5,70,WOOD:1,30,WOODEN_SLAB:5,10,WOODEN_SLAB:1,10,DARK_OAK_STAIRS:0,5,DARK_OAK_STAIRS:1,5,DARK_OAK_STAIRS:2,5,DARK_OAK_STAIRS:3,5,SPRUCE_STAIRS:0,5,SPRUCE_STAIRS:1,5,SPRUCE_STAIRS:2,5,SPRUCE_STAIRS:3,5,WOOD:5,100)
RandomBlock(-3,1,7,WOOD:5,70,WOOD:1,30,WOODEN_SLAB:5,10,WOODEN_SLAB:1,10,DARK_OAK_STAIRS:0,5,DARK_OAK_STAIRS:1,5,DARK_OAK_STAIRS:2,5,DARK_OAK_STAIRS:3,5,SPRUCE_STAIRS:0,5,SPRUCE_STAIRS:1,5,SPRUCE_STAIRS:2,5,SPRUCE_STAIRS:3,5,WOOD:5,100)
RandomBlock(-3,2,-4,FURNACE:3,../../../../Chests/Loot/furnace_W-Mineshafts_01.nbt,1,FURNACE:3,../../../../Chests/Loot/furnace_W-Mineshafts_02.nbt,1,FURNACE:3,../../../../Chests/Loot/furnace_W-Mineshafts_03.nbt,1,CRAFTING_TABLE:0,1,ANVIL:3,1,ANVIL:7,1,ANVIL:11,1,ANVIL:2,1,ANVIL:6,1,ANVIL:10,1,TNT:0,1,WEB:0,2,AIR:0,30,CHEST:3,../../../../Chests/Loot/abandoned_mineshaft.nbt,10,CHEST:3,../../../../Chests/Lore/Generic_5.nbt,2,CHEST:3,../../../../Chests/Lore/Generic_4.nbt,2,CHEST:3,../../../../Chests/Lore/Generic_3.nbt,2,CHEST:3,../../../../Chests/Lore/Generic_2.nbt,2,CHEST:3,../../../../Chests/Lore/Generic_1.nbt,2,CHEST:3,../../../../Chests/Lore/HiddenMine_1.nbt,1,CHEST:3,../../../../Chests/Lore/HiddenMine_2.nbt,1,CHEST:3,../../../../Chests/Lore/HiddenMine_3.nbt,1,CHEST:3,../../../../Chests/Lore/HiddenMine_4.nbt,1,CHEST:3,../../../../Chests/Lore/HiddenMine_5.nbt,1,CHEST:3,../../../../Chests/Loot/abandoned_mineshaft.nbt,100)
Block(-3,2,-3,AIR:0)
Block(-3,2,-2,AIR:0)
Block(-3,2,-1,AIR:0)
Entity(-3,2,0,WITHER_SKELETON,1,../../NBT/Mobs/Tunneler.txt)
Block(-3,2,0,AIR:0)
Block(-3,2,1,AIR:0)
Block(-3,2,2,AIR:0)
Block(-3,2,3,AIR:0)
Block(-3,2,4,AIR:0)
Block(-3,2,5,AIR:0)
Block(-3,2,6,AIR:0)
RandomBlock(-3,2,7,FURNACE:2,../../../../Chests/Loot/furnace_W-Mineshafts_01.nbt,1,FURNACE:2,../../../../Chests/Loot/furnace_W-Mineshafts_02.nbt,1,FURNACE:2,../../../../Chests/Loot/furnace_W-Mineshafts_03.nbt,1,CRAFTING_TABLE:0,1,ANVIL:3,1,ANVIL:7,1,ANVIL:11,1,ANVIL:2,1,ANVIL:6,1,ANVIL:10,1,TNT:0,1,WEB:0,2,AIR:0,30,CHEST:2,../../../../Chests/Loot/abandoned_mineshaft.nbt,10,CHEST:2,../../../../Chests/Lore/Generic_5.nbt,2,CHEST:2,../../../../Chests/Lore/Generic_4.nbt,2,CHEST:2,../../../../Chests/Lore/Generic_3.nbt,2,CHEST:2,../../../../Chests/Lore/Generic_2.nbt,2,CHEST:2,../../../../Chests/Lore/Generic_1.nbt,2,CHEST:2,../../../../Chests/Lore/HiddenMine_1.nbt,1,CHEST:2,../../../../Chests/Lore/HiddenMine_2.nbt,1,CHEST:2,../../../../Chests/Lore/HiddenMine_3.nbt,1,CHEST:2,../../../../Chests/Lore/HiddenMine_4.nbt,1,CHEST:2,../../../../Chests/Lore/HiddenMine_5.nbt,1,CHEST:2,../../../../Chests/Loot/abandoned_mineshaft.nbt,100)
Block(-3,3,-4,AIR:0)
Block(-3,3,-3,AIR:0)
Block(-3,3,-2,AIR:0)
Block(-3,3,-1,AIR:0)
Block(-3,3,0,AIR:0)
Block(-3,3,1,AIR:0)
Block(-3,3,2,AIR:0)
Block(-3,3,3,AIR:0)
Block(-3,3,4,AIR:0)
Block(-3,3,5,AIR:0)
Block(-3,3,6,AIR:0)
Block(-3,3,7,AIR:0)
Block(-3,4,-4,SPRUCE_FENCE:0)
Block(-3,4,-3,AIR:0)
Block(-3,4,-2,AIR:0)
Block(-3,4,-1,AIR:0)
Block(-3,4,0,SPRUCE_FENCE:0)
Block(-3,4,1,AIR:0)
Block(-3,4,2,AIR:0)
Block(-3,4,3,SPRUCE_FENCE:0)
Block(-3,4,4,AIR:0)
Block(-3,4,5,AIR:0)
Block(-3,4,6,AIR:0)
Block(-3,4,7,SPRUCE_FENCE:0)
Block(-3,5,-3,WOOD:1)
Block(-3,5,-2,AIR:0)
Block(-3,5,-1,AIR:0)
Block(-3,5,0,WOOD:1)
Block(-3,5,1,WOOD:1)
Block(-3,5,2,WOOD:1)
Block(-3,5,3,WOOD:1)
Block(-3,5,4,AIR:0)
Block(-3,5,5,AIR:0)
Block(-3,5,6,WOOD:1)
Block(-3,6,-3,AIR:0)
Block(-3,6,-2,AIR:0)
Block(-3,6,-1,AIR:0)
Block(-3,6,0,AIR:0)
Block(-3,6,1,LADDER:5)
Block(-3,6,2,LADDER:5)
Block(-3,6,3,AIR:0)
Block(-3,6,4,AIR:0)
Block(-3,6,5,AIR:0)
Block(-3,6,6,AIR:0)
Block(-3,7,-3,AIR:0)
Block(-3,7,-2,AIR:0)
Block(-3,7,-1,AIR:0)
Block(-3,7,0,AIR:0)
Block(-3,7,1,LADDER:5)
Block(-3,7,2,LADDER:5)
Block(-3,7,3,AIR:0)
Block(-3,7,4,AIR:0)
Block(-3,7,5,AIR:0)
Block(-3,7,6,AIR:0)
Block(-3,8,-3,AIR:0)
Block(-3,8,-2,AIR:0)
Block(-3,8,-1,AIR:0)
Block(-3,8,0,AIR:0)
Block(-3,8,1,LADDER:5)
Block(-3,8,2,LADDER:5)
Block(-3,8,3,AIR:0)
Block(-3,8,4,AIR:0)
Block(-3,8,5,AIR:0)
Block(-3,8,6,AIR:0)
Block(-3,9,-3,SPRUCE_FENCE:0)
Block(-3,9,-2,AIR:0)
Block(-3,9,-1,AIR:0)
Block(-3,9,0,SPRUCE_FENCE:0)
Block(-3,9,1,LADDER:5)
Block(-3,9,2,LADDER:5)
Block(-3,9,3,SPRUCE_FENCE:0)
Block(-3,9,4,AIR:0)
Block(-3,9,5,AIR:0)
Block(-3,9,6,SPRUCE_FENCE:0)
Block(-3,10,-3,WOOD:1)
Block(-3,10,-2,WOOD:1)
Block(-3,10,-1,WOOD:1)
Block(-3,10,0,WOOD:1)
Block(-3,10,1,LADDER:5)
Block(-3,10,2,LADDER:5)
Block(-3,10,3,WOOD:1)
Block(-3,10,4,WOOD:1)
Block(-3,10,5,WOOD:1)
Block(-3,10,6,WOOD:1)
Block(-3,11,-3,AIR:0)
Block(-3,11,-2,AIR:0)
Block(-3,11,-1,AIR:0)
Block(-3,11,0,AIR:0)
Block(-3,11,1,LADDER:5)
Block(-3,11,2,LADDER:5)
Block(-3,11,3,AIR:0)
Block(-3,11,4,AIR:0)
Entity(-3,11,5,WITHER_SKELETON,1,../../NBT/Mobs/Tunneler.txt)
Block(-3,11,5,AIR:0)
RandomBlock(-3,11,6,FURNACE:2,../../../../Chests/Loot/furnace_W-Mineshafts_01.nbt,1,FURNACE:2,../../../../Chests/Loot/furnace_W-Mineshafts_02.nbt,1,FURNACE:2,../../../../Chests/Loot/furnace_W-Mineshafts_03.nbt,1,CRAFTING_TABLE:0,1,ANVIL:3,1,ANVIL:7,1,ANVIL:11,1,ANVIL:2,1,ANVIL:6,1,ANVIL:10,1,TNT:0,1,WEB:0,2,AIR:0,30,CHEST:2,../../../../Chests/Loot/abandoned_mineshaft.nbt,10,CHEST:2,../../../../Chests/Lore/Generic_5.nbt,2,CHEST:2,../../../../Chests/Lore/Generic_4.nbt,2,CHEST:2,../../../../Chests/Lore/Generic_3.nbt,2,CHEST:2,../../../../Chests/Lore/Generic_2.nbt,2,CHEST:2,../../../../Chests/Lore/Generic_1.nbt,2,CHEST:2,../../../../Chests/Lore/HiddenMine_1.nbt,1,CHEST:2,../../../../Chests/Lore/HiddenMine_2.nbt,1,CHEST:2,../../../../Chests/Lore/HiddenMine_3.nbt,1,CHEST:2,../../../../Chests/Lore/HiddenMine_4.nbt,1,CHEST:2,../../../../Chests/Lore/HiddenMine_5.nbt,1,CHEST:2,../../../../Chests/Loot/abandoned_mineshaft.nbt,100)
Block(-3,12,-3,AIR:0)
Block(-3,12,-2,AIR:0)
Block(-3,12,-1,AIR:0)
Block(-3,12,0,AIR:0)
Block(-3,12,1,LADDER:5)
Block(-3,12,2,LADDER:5)
Block(-3,12,3,AIR:0)
Block(-3,12,4,AIR:0)
Block(-3,12,5,AIR:0)
Block(-3,12,6,AIR:0)
Block(-3,13,-3,AIR:0)
Block(-3,13,-2,AIR:0)
Block(-3,13,-1,AIR:0)
Block(-3,13,0,AIR:0)
Block(-3,13,1,LADDER:5)
Block(-3,13,2,LADDER:5)
Block(-3,13,3,AIR:0)
Block(-3,13,4,AIR:0)
Block(-3,13,5,AIR:0)
Block(-3,13,6,AIR:0)
Block(-3,14,-3,SPRUCE_FENCE:0)
Block(-3,14,-2,AIR:0)
Block(-3,14,-1,AIR:0)
Block(-3,14,0,SPRUCE_FENCE:0)
Block(-3,14,1,LADDER:5)
Block(-3,14,2,LADDER:5)
Block(-3,14,3,SPRUCE_FENCE:0)
Block(-3,14,4,AIR:0)
Block(-3,14,5,AIR:0)
Block(-3,14,6,SPRUCE_FENCE:0)
Block(-3,15,-3,WOOD:1)
Block(-3,15,-2,WOOD:1)
Block(-3,15,-1,WOOD:1)
Block(-3,15,0,WOOD:1)
Block(-3,15,1,LADDER:5)
Block(-3,15,2,LADDER:5)
Block(-3,15,3,WOOD:1)
Block(-3,15,4,WOOD:1)
Block(-3,15,5,WOOD:1)
Block(-3,15,6,WOOD:1)
Block(-3,16,-3,AIR:0)
Block(-3,16,-2,AIR:0)
Block(-3,16,-1,AIR:0)
Block(-3,16,0,AIR:0)
Block(-3,16,1,LADDER:5)
Block(-3,16,2,LADDER:5)
RandomBlock(-3,16,3,AIR:0,60,SKULL:1,../../../../Skulls/dungeon_skull_01.nbt,6,AIR,9,WEB,3,SKULL:1,../../../../Skulls/dungeon_skull_02.nbt,12,AIR,15,WEB,3,SKULL:1,../../../../Skulls/dungeon_skull_03.nbt,18,AIR:0,21,WEB:0,3,SKULL:1,../../../../Skulls/dungeon_skull_04.nbt,24,AIR:0,27,WEB:0,3,SKULL:1,../../../../Skulls/dungeon_skull_05.nbt,30,AIR:0,33,WEB:0,3,SKULL:1,../../../../Skulls/dungeon_skull_06.nbt,36,AIR:0,39,WEB:0,3,SKULL:1,../../../../Skulls/dungeon_skull_07.nbt,42,AIR:0,45,WEB:0,3,SKULL:1,../../../../Skulls/dungeon_skull_08.nbt,48,AIR:0,51,WEB:0,3,SKULL:1,../../../../Skulls/dungeon_skull_09.nbt,54,AIR:0,57,WEB:0,3,SKULL:1,../../../../Skulls/dungeon_skull_10.nbt,60,AIR:0,63,WEB:0,3,SKULL:1,../../../../Skulls/dungeon_skull_11.nbt,66,AIR:0,69,WEB:0,3,SKULL:1,../../../../Skulls/dungeon_skull_12.nbt,72,AIR:0,75,WEB:0,3,SKULL:1,../../../../Skulls/dungeon_skull_13.nbt,78,AIR:0,81,WEB:0,3,SKULL:1,../../../../Skulls/dungeon_skull_14.nbt,84,AIR:0,87,WEB:0,3,SKULL:1,../../../../Skulls/dungeon_skull_15.nbt,90,AIR:0,93,WEB:0,3,SKULL:1,../../../../Skulls/dungeon_skull_16.nbt,96,AIR:0,100)
Block(-3,16,4,AIR:0)
Block(-3,16,5,AIR:0)
Block(-3,16,6,AIR:0)
Block(-3,17,-3,AIR:0)
Block(-3,17,-2,AIR:0)
Block(-3,17,-1,AIR:0)
Block(-3,17,0,AIR:0)
Block(-3,17,1,LADDER:5)
Block(-3,17,2,LADDER:5)
Block(-3,17,3,AIR:0)
Block(-3,17,4,AIR:0)
Block(-3,17,5,AIR:0)
Block(-3,17,6,AIR:0)
Block(-3,18,-3,AIR:0)
Block(-3,18,-2,AIR:0)
Block(-3,18,-1,AIR:0)
Block(-3,18,0,AIR:0)
Block(-3,18,1,LADDER:5)
Block(-3,18,2,LADDER:5)
Block(-3,18,3,AIR:0)
Block(-3,18,4,AIR:0)
Block(-3,18,5,AIR:0)
Block(-3,18,6,AIR:0)
Block(-3,19,-3,WOOD:1)
Block(-3,19,-2,SPRUCE_FENCE:0)
Block(-3,19,-1,SPRUCE_FENCE:0)
Block(-3,19,0,WOOD:1)
Block(-3,19,1,LADDER:5)
Block(-3,19,2,LADDER:5)
Block(-3,19,3,WOOD:1)
Block(-3,19,4,SPRUCE_FENCE:0)
Block(-3,19,5,SPRUCE_FENCE:0)
Block(-3,19,6,WOOD:1)
RandomBlock(-2,1,-4,WOOD:5,70,WOOD:1,30,WOODEN_SLAB:5,10,WOODEN_SLAB:1,10,DARK_OAK_STAIRS:0,5,DARK_OAK_STAIRS:1,5,DARK_OAK_STAIRS:2,5,DARK_OAK_STAIRS:3,5,SPRUCE_STAIRS:0,5,SPRUCE_STAIRS:1,5,SPRUCE_STAIRS:2,5,SPRUCE_STAIRS:3,5,WOOD:5,100)
RandomBlock(-2,1,-3,WOOD:5,70,WOOD:1,30,WOODEN_SLAB:5,10,WOODEN_SLAB:1,10,DARK_OAK_STAIRS:0,5,DARK_OAK_STAIRS:1,5,DARK_OAK_STAIRS:2,5,DARK_OAK_STAIRS:3,5,SPRUCE_STAIRS:0,5,SPRUCE_STAIRS:1,5,SPRUCE_STAIRS:2,5,SPRUCE_STAIRS:3,5,WOOD:5,100)
RandomBlock(-2,1,-2,WOOD:5,70,WOOD:1,30,WOODEN_SLAB:5,10,WOODEN_SLAB:1,10,DARK_OAK_STAIRS:0,5,DARK_OAK_STAIRS:1,5,DARK_OAK_STAIRS:2,5,DARK_OAK_STAIRS:3,5,SPRUCE_STAIRS:0,5,SPRUCE_STAIRS:1,5,SPRUCE_STAIRS:2,5,SPRUCE_STAIRS:3,5,WOOD:5,100)
RandomBlock(-2,1,-1,WOOD:5,70,WOOD:1,30,WOODEN_SLAB:5,10,WOODEN_SLAB:1,10,DARK_OAK_STAIRS:0,5,DARK_OAK_STAIRS:1,5,DARK_OAK_STAIRS:2,5,DARK_OAK_STAIRS:3,5,SPRUCE_STAIRS:0,5,SPRUCE_STAIRS:1,5,SPRUCE_STAIRS:2,5,SPRUCE_STAIRS:3,5,WOOD:5,100)
RandomBlock(-2,1,0,WOOD:5,70,WOOD:1,30,WOODEN_SLAB:5,10,WOODEN_SLAB:1,10,DARK_OAK_STAIRS:0,5,DARK_OAK_STAIRS:1,5,DARK_OAK_STAIRS:2,5,DARK_OAK_STAIRS:3,5,SPRUCE_STAIRS:0,5,SPRUCE_STAIRS:1,5,SPRUCE_STAIRS:2,5,SPRUCE_STAIRS:3,5,WOOD:5,100)
RandomBlock(-2,1,1,WOOD:5,70,WOOD:1,30,WOODEN_SLAB:5,10,WOODEN_SLAB:1,10,DARK_OAK_STAIRS:0,5,DARK_OAK_STAIRS:1,5,DARK_OAK_STAIRS:2,5,DARK_OAK_STAIRS:3,5,SPRUCE_STAIRS:0,5,SPRUCE_STAIRS:1,5,SPRUCE_STAIRS:2,5,SPRUCE_STAIRS:3,5,WOOD:5,100)
RandomBlock(-2,1,2,WOOD:5,70,WOOD:1,30,WOODEN_SLAB:5,10,WOODEN_SLAB:1,10,DARK_OAK_STAIRS:0,5,DARK_OAK_STAIRS:1,5,DARK_OAK_STAIRS:2,5,DARK_OAK_STAIRS:3,5,SPRUCE_STAIRS:0,5,SPRUCE_STAIRS:1,5,SPRUCE_STAIRS:2,5,SPRUCE_STAIRS:3,5,WOOD:5,100)
RandomBlock(-2,1,3,WOOD:5,70,WOOD:1,30,WOODEN_SLAB:5,10,WOODEN_SLAB:1,10,DARK_OAK_STAIRS:0,5,DARK_OAK_STAIRS:1,5,DARK_OAK_STAIRS:2,5,DARK_OAK_STAIRS:3,5,SPRUCE_STAIRS:0,5,SPRUCE_STAIRS:1,5,SPRUCE_STAIRS:2,5,SPRUCE_STAIRS:3,5,WOOD:5,100)
RandomBlock(-2,1,4,WOOD:5,70,WOOD:1,30,WOODEN_SLAB:5,10,WOODEN_SLAB:1,10,DARK_OAK_STAIRS:0,5,DARK_OAK_STAIRS:1,5,DARK_OAK_STAIRS:2,5,DARK_OAK_STAIRS:3,5,SPRUCE_STAIRS:0,5,SPRUCE_STAIRS:1,5,SPRUCE_STAIRS:2,5,SPRUCE_STAIRS:3,5,WOOD:5,100)
RandomBlock(-2,1,5,WOOD:5,70,WOOD:1,30,WOODEN_SLAB:5,10,WOODEN_SLAB:1,10,DARK_OAK_STAIRS:0,5,DARK_OAK_STAIRS:1,5,DARK_OAK_STAIRS:2,5,DARK_OAK_STAIRS:3,5,SPRUCE_STAIRS:0,5,SPRUCE_STAIRS:1,5,SPRUCE_STAIRS:2,5,SPRUCE_STAIRS:3,5,WOOD:5,100)
RandomBlock(-2,1,6,WOOD:5,70,WOOD:1,30,WOODEN_SLAB:5,10,WOODEN_SLAB:1,10,DARK_OAK_STAIRS:0,5,DARK_OAK_STAIRS:1,5,DARK_OAK_STAIRS:2,5,DARK_OAK_STAIRS:3,5,SPRUCE_STAIRS:0,5,SPRUCE_STAIRS:1,5,SPRUCE_STAIRS:2,5,SPRUCE_STAIRS:3,5,WOOD:5,100)
RandomBlock(-2,1,7,WOOD:5,70,WOOD:1,30,WOODEN_SLAB:5,10,WOODEN_SLAB:1,10,DARK_OAK_STAIRS:0,5,DARK_OAK_STAIRS:1,5,DARK_OAK_STAIRS:2,5,DARK_OAK_STAIRS:3,5,SPRUCE_STAIRS:0,5,SPRUCE_STAIRS:1,5,SPRUCE_STAIRS:2,5,SPRUCE_STAIRS:3,5,WOOD:5,100)
Block(-2,2,-4,SPRUCE_FENCE:0)
Block(-2,2,-3,AIR:0)
Block(-2,2,-2,AIR:0)
Block(-2,2,-1,WOOD:1)
Block(-2,2,0,SPRUCE_FENCE:0)
Block(-2,2,1,AIR:0)
Block(-2,2,2,AIR:0)
Block(-2,2,3,AIR:0)
Block(-2,2,4,WOOD:1)
Block(-2,2,5,AIR:0)
Block(-2,2,6,AIR:0)
Block(-2,2,7,SPRUCE_FENCE:0)
Block(-2,3,-4,AIR:0)
Block(-2,3,-3,AIR:0)
Block(-2,3,-2,AIR:0)
Block(-2,3,-1,WOOD:1)
Block(-2,3,0,SPRUCE_FENCE:0)
Block(-2,3,1,AIR:0)
Block(-2,3,2,AIR:0)
Block(-2,3,3,SPRUCE_FENCE:0)
Block(-2,3,4,WOOD:1)
Block(-2,3,5,AIR:0)
Block(-2,3,6,AIR:0)
Block(-2,3,7,AIR:0)
Block(-2,4,-4,SPRUCE_FENCE:0)
Block(-2,4,-3,AIR:0)
Block(-2,4,-2,AIR:0)
Block(-2,4,-1,WOOD:1)
Block(-2,4,0,SPRUCE_FENCE:0)
Block(-2,4,1,AIR:0)
Block(-2,4,2,AIR:0)
Block(-2,4,3,SPRUCE_FENCE:0)
Block(-2,4,4,WOOD:1)
Block(-2,4,5,AIR:0)
Block(-2,4,6,AIR:0)
Block(-2,4,7,SPRUCE_FENCE:0)
Block(-2,5,-4,WOOD:1)
Block(-2,5,-3,WOOD:1)
Block(-2,5,-2,AIR:0)
Block(-2,5,-1,WOOD:1)
Block(-2,5,0,WOOD:1)
Block(-2,5,1,AIR:0)
Block(-2,5,2,AIR:0)
Block(-2,5,3,WOOD:1)
Block(-2,5,4,WOOD:1)
Block(-2,5,5,AIR:0)
Block(-2,5,6,WOOD:1)
Block(-2,5,7,WOOD:1)
RandomBlock(-2,6,-4,WOOD:5,70,WOOD:1,30,WOODEN_SLAB:5,10,WOODEN_SLAB:1,10,DARK_OAK_STAIRS:0,5,DARK_OAK_STAIRS:1,5,DARK_OAK_STAIRS:2,5,DARK_OAK_STAIRS:3,5,SPRUCE_STAIRS:0,5,SPRUCE_STAIRS:1,5,SPRUCE_STAIRS:2,5,SPRUCE_STAIRS:3,5,WOOD:5,100)
Block(-2,6,-3,AIR:0)
Block(-2,6,-2,AIR:0)
Block(-2,6,-1,WOOD:1)
Block(-2,6,0,SPRUCE_FENCE:0)
Block(-2,6,1,AIR:0)
Block(-2,6,2,AIR:0)
Block(-2,6,3,SPRUCE_FENCE:0)
Block(-2,6,4,WOOD:1)
Block(-2,6,5,AIR:0)
Block(-2,6,6,AIR:0)
RandomBlock(-2,6,7,WOOD:5,70,WOOD:1,30,WOODEN_SLAB:5,10,WOODEN_SLAB:1,10,DARK_OAK_STAIRS:0,5,DARK_OAK_STAIRS:1,5,DARK_OAK_STAIRS:2,5,DARK_OAK_STAIRS:3,5,SPRUCE_STAIRS:0,5,SPRUCE_STAIRS:1,5,SPRUCE_STAIRS:2,5,SPRUCE_STAIRS:3,5,WOOD:5,100)
Block(-2,7,-4,SPRUCE_FENCE:0)
Block(-2,7,-3,AIR:0)
Block(-2,7,-2,AIR:0)
Block(-2,7,-1,WOOD:1)
Block(-2,7,0,SPRUCE_FENCE:0)
Block(-2,7,1,AIR:0)
Block(-2,7,2,AIR:0)
Block(-2,7,3,SPRUCE_FENCE:0)
Block(-2,7,4,WOOD:1)
Block(-2,7,5,AIR:0)
Block(-2,7,6,AIR:0)
Block(-2,7,7,SPRUCE_FENCE:0)
Block(-2,8,-4,SPRUCE_FENCE:0)
Block(-2,8,-3,AIR:0)
Block(-2,8,-2,AIR:0)
Block(-2,8,-1,WOOD:1)
Block(-2,8,0,WOOD:1)
Block(-2,8,1,WOOD:1)
Block(-2,8,2,WOOD:1)
Block(-2,8,3,WOOD:1)
Block(-2,8,4,WOOD:1)
Block(-2,8,5,AIR:0)
Block(-2,8,6,AIR:0)
Block(-2,8,7,SPRUCE_FENCE:0)
Block(-2,9,-4,WOOD:1)
Block(-2,9,-3,SPRUCE_FENCE:0)
Block(-2,9,-2,AIR:0)
Block(-2,9,-1,WOOD:1)
Block(-2,9,0,SPRUCE_FENCE:0)
Block(-2,9,1,AIR:0)
Block(-2,9,2,AIR:0)
Block(-2,9,3,SPRUCE_FENCE:0)
Block(-2,9,4,WOOD:1)
Block(-2,9,5,AIR:0)
Block(-2,9,6,SPRUCE_FENCE:0)
Block(-2,9,7,WOOD:1)
Block(-2,10,-4,WOOD:1)
Block(-2,10,-3,WOOD:1)
Block(-2,10,-2,WOOD:1)
Block(-2,10,-1,WOOD:1)
Block(-2,10,0,WOOD:1)
Block(-2,10,1,AIR:0)
Block(-2,10,2,AIR:0)
Block(-2,10,3,WOOD:1)
Block(-2,10,4,WOOD:1)
Block(-2,10,5,WOOD:1)
Block(-2,10,6,WOOD:1)
Block(-2,10,7,WOOD:1)
RandomBlock(-2,11,-4,WOOD:5,70,WOOD:1,30,WOODEN_SLAB:5,10,WOODEN_SLAB:1,10,DARK_OAK_STAIRS:0,5,DARK_OAK_STAIRS:1,5,DARK_OAK_STAIRS:2,5,DARK_OAK_STAIRS:3,5,SPRUCE_STAIRS:0,5,SPRUCE_STAIRS:1,5,SPRUCE_STAIRS:2,5,SPRUCE_STAIRS:3,5,WOOD:5,100)
Block(-2,11,-3,AIR:0)
Block(-2,11,-2,AIR:0)
Block(-2,11,-1,WOOD:1)
Block(-2,11,0,SPRUCE_FENCE:0)
Block(-2,11,1,AIR:0)
Block(-2,11,2,AIR:0)
Block(-2,11,3,SPRUCE_FENCE:0)
Block(-2,11,4,WOOD:1)
Block(-2,11,5,AIR:0)
Block(-2,11,6,AIR:0)
RandomBlock(-2,11,7,WOOD:5,70,WOOD:1,30,WOODEN_SLAB:5,10,WOODEN_SLAB:1,10,DARK_OAK_STAIRS:0,5,DARK_OAK_STAIRS:1,5,DARK_OAK_STAIRS:2,5,DARK_OAK_STAIRS:3,5,SPRUCE_STAIRS:0,5,SPRUCE_STAIRS:1,5,SPRUCE_STAIRS:2,5,SPRUCE_STAIRS:3,5,WOOD:5,100)
Block(-2,12,-4,SPRUCE_FENCE:0)
Block(-2,12,-3,AIR:0)
Block(-2,12,-2,AIR:0)
Block(-2,12,-1,WOOD:1)
Block(-2,12,0,SPRUCE_FENCE:0)
Block(-2,12,1,AIR:0)
Block(-2,12,2,AIR:0)
Block(-2,12,3,SPRUCE_FENCE:0)
Block(-2,12,4,WOOD:1)
Block(-2,12,5,AIR:0)
Block(-2,12,6,AIR:0)
Block(-2,12,7,SPRUCE_FENCE:0)
Block(-2,13,-4,SPRUCE_FENCE:0)
Block(-2,13,-3,AIR:0)
Block(-2,13,-2,AIR:0)
Block(-2,13,-1,WOOD:1)
Block(-2,13,0,SPRUCE_FENCE:0)
Block(-2,13,1,AIR:0)
Block(-2,13,2,AIR:0)
Block(-2,13,3,SPRUCE_FENCE:0)
Block(-2,13,4,WOOD:1)
Block(-2,13,5,AIR:0)
Block(-2,13,6,AIR:0)
Block(-2,13,7,SPRUCE_FENCE:0)
Block(-2,14,-4,WOOD:1)
Block(-2,14,-3,SPRUCE_FENCE:0)
Block(-2,14,-2,AIR:0)
Block(-2,14,-1,WOOD:1)
Block(-2,14,0,SPRUCE_FENCE:0)
Block(-2,14,1,AIR:0)
Block(-2,14,2,AIR:0)
Block(-2,14,3,SPRUCE_FENCE:0)
Block(-2,14,4,WOOD:1)
Block(-2,14,5,AIR:0)
Block(-2,14,6,SPRUCE_FENCE:0)
Block(-2,14,7,WOOD:1)
Block(-2,15,-4,WOOD:1)
Block(-2,15,-3,WOOD:1)
Block(-2,15,-2,WOOD:1)
Block(-2,15,-1,WOOD:1)
Block(-2,15,0,WOOD:1)
Block(-2,15,1,AIR:0)
Block(-2,15,2,AIR:0)
Block(-2,15,3,WOOD:1)
Block(-2,15,4,WOOD:1)
Block(-2,15,5,WOOD:1)
Block(-2,15,6,WOOD:1)
Block(-2,15,7,WOOD:1)
RandomBlock(-2,16,-4,WOOD:5,70,WOOD:1,30,WOODEN_SLAB:5,10,WOODEN_SLAB:1,10,DARK_OAK_STAIRS:0,5,DARK_OAK_STAIRS:1,5,DARK_OAK_STAIRS:2,5,DARK_OAK_STAIRS:3,5,SPRUCE_STAIRS:0,5,SPRUCE_STAIRS:1,5,SPRUCE_STAIRS:2,5,SPRUCE_STAIRS:3,5,WOOD:5,100)
Block(-2,16,-3,AIR:0)
Block(-2,16,-2,AIR:0)
Block(-2,16,-1,WOOD:1)
Block(-2,16,0,SPRUCE_FENCE:0)
Block(-2,16,1,AIR:0)
Block(-2,16,2,AIR:0)
Block(-2,16,3,SPRUCE_FENCE:0)
Block(-2,16,4,WOOD:1)
Block(-2,16,5,AIR:0)
Block(-2,16,6,AIR:0)
RandomBlock(-2,16,7,WOOD:5,70,WOOD:1,30,WOODEN_SLAB:5,10,WOODEN_SLAB:1,10,DARK_OAK_STAIRS:0,5,DARK_OAK_STAIRS:1,5,DARK_OAK_STAIRS:2,5,DARK_OAK_STAIRS:3,5,SPRUCE_STAIRS:0,5,SPRUCE_STAIRS:1,5,SPRUCE_STAIRS:2,5,SPRUCE_STAIRS:3,5,WOOD:5,100)
Block(-2,17,-4,SPRUCE_FENCE:0)
Block(-2,17,-3,AIR:0)
Block(-2,17,-2,AIR:0)
Block(-2,17,-1,WOOD:1)
Block(-2,17,0,SPRUCE_FENCE:0)
Block(-2,17,1,AIR:0)
Block(-2,17,2,AIR:0)
Block(-2,17,3,SPRUCE_FENCE:0)
Block(-2,17,4,WOOD:1)
Block(-2,17,5,AIR:0)
Block(-2,17,6,AIR:0)
Block(-2,17,7,SPRUCE_FENCE:0)
Block(-2,18,-4,SPRUCE_FENCE:0)
Block(-2,18,-3,AIR:0)
Block(-2,18,-2,AIR:0)
Block(-2,18,-1,WOOD:1)
Block(-2,18,0,SPRUCE_FENCE:0)
Block(-2,18,1,AIR:0)
Block(-2,18,2,AIR:0)
Block(-2,18,3,SPRUCE_FENCE:0)
Block(-2,18,4,WOOD:1)
Block(-2,18,5,AIR:0)
Block(-2,18,6,AIR:0)
Block(-2,18,7,SPRUCE_FENCE:0)
Block(-2,19,-4,WOOD:1)
Block(-2,19,-3,WOOD:1)
Block(-2,19,-2,SPRUCE_FENCE:0)
Block(-2,19,-1,WOOD:1)
Block(-2,19,0,WOOD:1)
Block(-2,19,1,SPRUCE_FENCE:0)
Block(-2,19,2,SPRUCE_FENCE:0)
Block(-2,19,3,WOOD:1)
Block(-2,19,4,WOOD:1)
Block(-2,19,5,SPRUCE_FENCE:0)
Block(-2,19,6,WOOD:1)
Block(-2,19,7,WOOD:1)
Block(-1,0,-6,LOG:1)
Block(-1,0,-4,LOG:1)
Block(-1,0,7,LOG:1)
Block(-1,0,9,LOG:1)
RandomBlock(-1,1,-6,WOOD:5,70,WOOD:1,30,WOODEN_SLAB:5,10,WOODEN_SLAB:1,10,DARK_OAK_STAIRS:0,5,DARK_OAK_STAIRS:1,5,DARK_OAK_STAIRS:2,5,DARK_OAK_STAIRS:3,5,SPRUCE_STAIRS:0,5,SPRUCE_STAIRS:1,5,SPRUCE_STAIRS:2,5,SPRUCE_STAIRS:3,5,WOOD:5,100)
RandomBlock(-1,1,-5,WOOD:5,70,WOOD:1,30,WOODEN_SLAB:5,10,WOODEN_SLAB:1,10,DARK_OAK_STAIRS:0,5,DARK_OAK_STAIRS:1,5,DARK_OAK_STAIRS:2,5,DARK_OAK_STAIRS:3,5,SPRUCE_STAIRS:0,5,SPRUCE_STAIRS:1,5,SPRUCE_STAIRS:2,5,SPRUCE_STAIRS:3,5,WOOD:5,100)
RandomBlock(-1,1,-4,WOOD:5,70,WOOD:1,30,WOODEN_SLAB:5,10,WOODEN_SLAB:1,10,DARK_OAK_STAIRS:0,5,DARK_OAK_STAIRS:1,5,DARK_OAK_STAIRS:2,5,DARK_OAK_STAIRS:3,5,SPRUCE_STAIRS:0,5,SPRUCE_STAIRS:1,5,SPRUCE_STAIRS:2,5,SPRUCE_STAIRS:3,5,WOOD:5,100)
RandomBlock(-1,1,-3,WOOD:5,70,WOOD:1,30,WOODEN_SLAB:5,10,WOODEN_SLAB:1,10,DARK_OAK_STAIRS:0,5,DARK_OAK_STAIRS:1,5,DARK_OAK_STAIRS:2,5,DARK_OAK_STAIRS:3,5,SPRUCE_STAIRS:0,5,SPRUCE_STAIRS:1,5,SPRUCE_STAIRS:2,5,SPRUCE_STAIRS:3,5,WOOD:5,100)
RandomBlock(-1,1,-2,WOOD:5,70,WOOD:1,30,WOODEN_SLAB:5,10,WOODEN_SLAB:1,10,DARK_OAK_STAIRS:0,5,DARK_OAK_STAIRS:1,5,DARK_OAK_STAIRS:2,5,DARK_OAK_STAIRS:3,5,SPRUCE_STAIRS:0,5,SPRUCE_STAIRS:1,5,SPRUCE_STAIRS:2,5,SPRUCE_STAIRS:3,5,WOOD:5,100)
RandomBlock(-1,1,-1,WOOD:5,70,WOOD:1,30,WOODEN_SLAB:5,10,WOODEN_SLAB:1,10,DARK_OAK_STAIRS:0,5,DARK_OAK_STAIRS:1,5,DARK_OAK_STAIRS:2,5,DARK_OAK_STAIRS:3,5,SPRUCE_STAIRS:0,5,SPRUCE_STAIRS:1,5,SPRUCE_STAIRS:2,5,SPRUCE_STAIRS:3,5,WOOD:5,100)
RandomBlock(-1,1,0,WOOD:5,70,WOOD:1,30,WOODEN_SLAB:5,10,WOODEN_SLAB:1,10,DARK_OAK_STAIRS:0,5,DARK_OAK_STAIRS:1,5,DARK_OAK_STAIRS:2,5,DARK_OAK_STAIRS:3,5,SPRUCE_STAIRS:0,5,SPRUCE_STAIRS:1,5,SPRUCE_STAIRS:2,5,SPRUCE_STAIRS:3,5,WOOD:5,100)
RandomBlock(-1,1,1,WOOD:5,70,WOOD:1,30,WOODEN_SLAB:5,10,WOODEN_SLAB:1,10,DARK_OAK_STAIRS:0,5,DARK_OAK_STAIRS:1,5,DARK_OAK_STAIRS:2,5,DARK_OAK_STAIRS:3,5,SPRUCE_STAIRS:0,5,SPRUCE_STAIRS:1,5,SPRUCE_STAIRS:2,5,SPRUCE_STAIRS:3,5,WOOD:5,100)
RandomBlock(-1,1,2,WOOD:5,70,WOOD:1,30,WOODEN_SLAB:5,10,WOODEN_SLAB:1,10,DARK_OAK_STAIRS:0,5,DARK_OAK_STAIRS:1,5,DARK_OAK_STAIRS:2,5,DARK_OAK_STAIRS:3,5,SPRUCE_STAIRS:0,5,SPRUCE_STAIRS:1,5,SPRUCE_STAIRS:2,5,SPRUCE_STAIRS:3,5,WOOD:5,100)
RandomBlock(-1,1,3,WOOD:5,70,WOOD:1,30,WOODEN_SLAB:5,10,WOODEN_SLAB:1,10,DARK_OAK_STAIRS:0,5,DARK_OAK_STAIRS:1,5,DARK_OAK_STAIRS:2,5,DARK_OAK_STAIRS:3,5,SPRUCE_STAIRS:0,5,SPRUCE_STAIRS:1,5,SPRUCE_STAIRS:2,5,SPRUCE_STAIRS:3,5,WOOD:5,100)
RandomBlock(-1,1,4,WOOD:5,70,WOOD:1,30,WOODEN_SLAB:5,10,WOODEN_SLAB:1,10,DARK_OAK_STAIRS:0,5,DARK_OAK_STAIRS:1,5,DARK_OAK_STAIRS:2,5,DARK_OAK_STAIRS:3,5,SPRUCE_STAIRS:0,5,SPRUCE_STAIRS:1,5,SPRUCE_STAIRS:2,5,SPRUCE_STAIRS:3,5,WOOD:5,100)
RandomBlock(-1,1,5,WOOD:5,70,WOOD:1,30,WOODEN_SLAB:5,10,WOODEN_SLAB:1,10,DARK_OAK_STAIRS:0,5,DARK_OAK_STAIRS:1,5,DARK_OAK_STAIRS:2,5,DARK_OAK_STAIRS:3,5,SPRUCE_STAIRS:0,5,SPRUCE_STAIRS:1,5,SPRUCE_STAIRS:2,5,SPRUCE_STAIRS:3,5,WOOD:5,100)
RandomBlock(-1,1,6,WOOD:5,70,WOOD:1,30,WOODEN_SLAB:5,10,WOODEN_SLAB:1,10,DARK_OAK_STAIRS:0,5,DARK_OAK_STAIRS:1,5,DARK_OAK_STAIRS:2,5,DARK_OAK_STAIRS:3,5,SPRUCE_STAIRS:0,5,SPRUCE_STAIRS:1,5,SPRUCE_STAIRS:2,5,SPRUCE_STAIRS:3,5,WOOD:5,100)
RandomBlock(-1,1,7,WOOD:5,70,WOOD:1,30,WOODEN_SLAB:5,10,WOODEN_SLAB:1,10,DARK_OAK_STAIRS:0,5,DARK_OAK_STAIRS:1,5,DARK_OAK_STAIRS:2,5,DARK_OAK_STAIRS:3,5,SPRUCE_STAIRS:0,5,SPRUCE_STAIRS:1,5,SPRUCE_STAIRS:2,5,SPRUCE_STAIRS:3,5,WOOD:5,100)
RandomBlock(-1,1,8,WOOD:5,70,WOOD:1,30,WOODEN_SLAB:5,10,WOODEN_SLAB:1,10,DARK_OAK_STAIRS:0,5,DARK_OAK_STAIRS:1,5,DARK_OAK_STAIRS:2,5,DARK_OAK_STAIRS:3,5,SPRUCE_STAIRS:0,5,SPRUCE_STAIRS:1,5,SPRUCE_STAIRS:2,5,SPRUCE_STAIRS:3,5,WOOD:5,100)
RandomBlock(-1,1,9,WOOD:5,70,WOOD:1,30,WOODEN_SLAB:5,10,WOODEN_SLAB:1,10,DARK_OAK_STAIRS:0,5,DARK_OAK_STAIRS:1,5,DARK_OAK_STAIRS:2,5,DARK_OAK_STAIRS:3,5,SPRUCE_STAIRS:0,5,SPRUCE_STAIRS:1,5,SPRUCE_STAIRS:2,5,SPRUCE_STAIRS:3,5,WOOD:5,100)
Block(-1,2,-6,SPRUCE_FENCE:0)
RandomBlock(-1,2,-5,AIR:0,60,SKULL:1,../../../../Skulls/dungeon_skull_01.nbt,6,AIR,9,WEB,3,SKULL:1,../../../../Skulls/dungeon_skull_02.nbt,12,AIR,15,WEB,3,SKULL:1,../../../../Skulls/dungeon_skull_03.nbt,18,AIR:0,21,WEB:0,3,SKULL:1,../../../../Skulls/dungeon_skull_04.nbt,24,AIR:0,27,WEB:0,3,SKULL:1,../../../../Skulls/dungeon_skull_05.nbt,30,AIR:0,33,WEB:0,3,SKULL:1,../../../../Skulls/dungeon_skull_06.nbt,36,AIR:0,39,WEB:0,3,SKULL:1,../../../../Skulls/dungeon_skull_07.nbt,42,AIR:0,45,WEB:0,3,SKULL:1,../../../../Skulls/dungeon_skull_08.nbt,48,AIR:0,51,WEB:0,3,SKULL:1,../../../../Skulls/dungeon_skull_09.nbt,54,AIR:0,57,WEB:0,3,SKULL:1,../../../../Skulls/dungeon_skull_10.nbt,60,AIR:0,63,WEB:0,3,SKULL:1,../../../../Skulls/dungeon_skull_11.nbt,66,AIR:0,69,WEB:0,3,SKULL:1,../../../../Skulls/dungeon_skull_12.nbt,72,AIR:0,75,WEB:0,3,SKULL:1,../../../../Skulls/dungeon_skull_13.nbt,78,AIR:0,81,WEB:0,3,SKULL:1,../../../../Skulls/dungeon_skull_14.nbt,84,AIR:0,87,WEB:0,3,SKULL:1,../../../../Skulls/dungeon_skull_15.nbt,90,AIR:0,93,WEB:0,3,SKULL:1,../../../../Skulls/dungeon_skull_16.nbt,96,AIR:0,100)
Block(-1,2,-4,SPRUCE_FENCE:0)
Block(-1,2,-3,AIR:0)
Block(-1,2,-2,AIR:0)
Block(-1,2,-1,AIR:0)
Block(-1,2,0,LADDER:3)
Block(-1,2,1,AIR:0)
Block(-1,2,2,AIR:0)
Block(-1,2,3,LADDER:5)
Block(-1,2,4,SPRUCE_FENCE:0)
Block(-1,2,5,AIR:0)
Entity(-1,2,6,WITHER_SKELETON,1,../../NBT/Mobs/Tunneler.txt)
Block(-1,2,6,AIR:0)
Block(-1,2,7,SPRUCE_FENCE:0)
Block(-1,2,8,AIR:0)
Block(-1,2,9,SPRUCE_FENCE:0)
Block(-1,3,-6,SPRUCE_FENCE:0)
Block(-1,3,-5,AIR:0)
Block(-1,3,-4,SPRUCE_FENCE:0)
Block(-1,3,-3,AIR:0)
Block(-1,3,-2,AIR:0)
Block(-1,3,-1,SPRUCE_FENCE:0)
Block(-1,3,0,LADDER:3)
Block(-1,3,1,AIR:0)
Block(-1,3,2,AIR:0)
Block(-1,3,3,LADDER:5)
Block(-1,3,4,SPRUCE_FENCE:0)
Block(-1,3,5,AIR:0)
Block(-1,3,6,AIR:0)
Block(-1,3,7,SPRUCE_FENCE:0)
Block(-1,3,8,AIR:0)
Block(-1,3,9,SPRUCE_FENCE:0)
Block(-1,4,-6,WOOD:1)
Block(-1,4,-5,AIR:0)
Block(-1,4,-4,WOOD:1)
Block(-1,4,-3,SPRUCE_FENCE:0)
Block(-1,4,-2,SPRUCE_FENCE:0)
Block(-1,4,-1,SPRUCE_FENCE:0)
Block(-1,4,0,LADDER:3)
Block(-1,4,1,AIR:0)
Block(-1,4,2,AIR:0)
Block(-1,4,3,LADDER:5)
Block(-1,4,4,SPRUCE_FENCE:0)
Block(-1,4,5,SPRUCE_FENCE:0)
Block(-1,4,6,SPRUCE_FENCE:0)
Block(-1,4,7,WOOD:1)
Block(-1,4,8,AIR:0)
Block(-1,4,9,WOOD:1)
Block(-1,5,-6,WOOD:1)
Block(-1,5,-5,AIR:0)
Block(-1,5,-4,WOOD:1)
Block(-1,5,-3,WOOD:1)
Block(-1,5,-2,WOOD:1)
Block(-1,5,-1,WOOD:1)
Block(-1,5,0,LADDER:3)
Block(-1,5,1,AIR:0)
Block(-1,5,2,AIR:0)
Block(-1,5,3,LADDER:5)
Block(-1,5,4,WOOD:1)
Block(-1,5,5,WOOD:1)
Block(-1,5,6,WOOD:1)
Block(-1,5,7,WOOD:1)
Block(-1,5,8,AIR:0)
Block(-1,5,9,WOOD:1)
RandomBlock(-1,6,-6,WOOD:5,70,WOOD:1,30,WOODEN_SLAB:5,10,WOODEN_SLAB:1,10,DARK_OAK_STAIRS:0,5,DARK_OAK_STAIRS:1,5,DARK_OAK_STAIRS:2,5,DARK_OAK_STAIRS:3,5,SPRUCE_STAIRS:0,5,SPRUCE_STAIRS:1,5,SPRUCE_STAIRS:2,5,SPRUCE_STAIRS:3,5,WOOD:5,100)
RandomBlock(-1,6,-5,WOOD:5,70,WOOD:1,30,WOODEN_SLAB:5,10,WOODEN_SLAB:1,10,DARK_OAK_STAIRS:0,5,DARK_OAK_STAIRS:1,5,DARK_OAK_STAIRS:2,5,DARK_OAK_STAIRS:3,5,SPRUCE_STAIRS:0,5,SPRUCE_STAIRS:1,5,SPRUCE_STAIRS:2,5,SPRUCE_STAIRS:3,5,WOOD:5,100)
Block(-1,6,-4,DARK_OAK_STAIRS:3)
Block(-1,6,-3,AIR:0)
Block(-1,6,-2,AIR:0)
Block(-1,6,-1,SPRUCE_FENCE:0)
Block(-1,6,0,AIR:0)
Block(-1,6,1,AIR:0)
Block(-1,6,2,AIR:0)
Block(-1,6,3,AIR:0)
Block(-1,6,4,SPRUCE_FENCE:0)
Block(-1,6,5,AIR:0)
Block(-1,6,6,AIR:0)
Block(-1,6,7,DARK_OAK_STAIRS:2)
RandomBlock(-1,6,8,WOOD:5,70,WOOD:1,30,WOODEN_SLAB:5,10,WOODEN_SLAB:1,10,DARK_OAK_STAIRS:0,5,DARK_OAK_STAIRS:1,5,DARK_OAK_STAIRS:2,5,DARK_OAK_STAIRS:3,5,SPRUCE_STAIRS:0,5,SPRUCE_STAIRS:1,5,SPRUCE_STAIRS:2,5,SPRUCE_STAIRS:3,5,WOOD:5,100)
RandomBlock(-1,6,9,WOOD:5,70,WOOD:1,30,WOODEN_SLAB:5,10,WOODEN_SLAB:1,10,DARK_OAK_STAIRS:0,5,DARK_OAK_STAIRS:1,5,DARK_OAK_STAIRS:2,5,DARK_OAK_STAIRS:3,5,SPRUCE_STAIRS:0,5,SPRUCE_STAIRS:1,5,SPRUCE_STAIRS:2,5,SPRUCE_STAIRS:3,5,WOOD:5,100)
Block(-1,7,-6,SPRUCE_FENCE:0)
Block(-1,7,-5,AIR:0)
Block(-1,7,-4,AIR:0)
Block(-1,7,-3,AIR:0)
Block(-1,7,-2,AIR:0)
Block(-1,7,-1,SPRUCE_FENCE:0)
Block(-1,7,0,AIR:0)
Block(-1,7,1,AIR:0)
Block(-1,7,2,AIR:0)
Block(-1,7,3,AIR:0)
Block(-1,7,4,SPRUCE_FENCE:0)
Block(-1,7,5,AIR:0)
Block(-1,7,6,AIR:0)
Block(-1,7,7,AIR:0)
Block(-1,7,8,AIR:0)
Block(-1,7,9,SPRUCE_FENCE:0)
Block(-1,8,-6,SPRUCE_FENCE:0)
Block(-1,8,-5,AIR:0)
Block(-1,8,-4,AIR:0)
Block(-1,8,-3,AIR:0)
Block(-1,8,-2,AIR:0)
Block(-1,8,-1,WOOD:1)
Block(-1,8,0,AIR:0)
Block(-1,8,1,AIR:0)
Block(-1,8,2,AIR:0)
Block(-1,8,3,AIR:0)
Block(-1,8,4,WOOD:1)
Block(-1,8,5,AIR:0)
Block(-1,8,6,AIR:0)
Block(-1,8,7,AIR:0)
Block(-1,8,8,AIR:0)
Block(-1,8,9,SPRUCE_FENCE:0)
Block(-1,9,-6,WOOD:1)
Block(-1,9,-5,AIR:0)
Block(-1,9,-4,WOOD:1)
Block(-1,9,-3,SPRUCE_FENCE:0)
Block(-1,9,-2,SPRUCE_FENCE:0)
Block(-1,9,-1,SPRUCE_FENCE:0)
Block(-1,9,0,AIR:0)
Block(-1,9,1,AIR:0)
Block(-1,9,2,AIR:0)
Block(-1,9,3,AIR:0)
Block(-1,9,4,SPRUCE_FENCE:0)
Block(-1,9,5,SPRUCE_FENCE:0)
Block(-1,9,6,SPRUCE_FENCE:0)
Block(-1,9,7,WOOD:1)
Block(-1,9,8,AIR:0)
Block(-1,9,9,WOOD:1)
Block(-1,10,-6,WOOD:1)
Block(-1,10,-5,AIR:0)
Block(-1,10,-4,WOOD:1)
Block(-1,10,-3,WOOD:1)
Block(-1,10,-2,WOOD:1)
Block(-1,10,-1,WOOD:1)
Block(-1,10,0,AIR:0)
Block(-1,10,1,AIR:0)
Block(-1,10,2,AIR:0)
Block(-1,10,3,AIR:0)
Block(-1,10,4,WOOD:1)
Block(-1,10,5,WOOD:1)
Block(-1,10,6,WOOD:1)
Block(-1,10,7,WOOD:1)
Block(-1,10,8,AIR:0)
Block(-1,10,9,WOOD:1)
RandomBlock(-1,11,-6,WOOD:5,70,WOOD:1,30,WOODEN_SLAB:5,10,WOODEN_SLAB:1,10,DARK_OAK_STAIRS:0,5,DARK_OAK_STAIRS:1,5,DARK_OAK_STAIRS:2,5,DARK_OAK_STAIRS:3,5,SPRUCE_STAIRS:0,5,SPRUCE_STAIRS:1,5,SPRUCE_STAIRS:2,5,SPRUCE_STAIRS:3,5,WOOD:5,100)
RandomBlock(-1,11,-5,WOOD:5,70,WOOD:1,30,WOODEN_SLAB:5,10,WOODEN_SLAB:1,10,DARK_OAK_STAIRS:0,5,DARK_OAK_STAIRS:1,5,DARK_OAK_STAIRS:2,5,DARK_OAK_STAIRS:3,5,SPRUCE_STAIRS:0,5,SPRUCE_STAIRS:1,5,SPRUCE_STAIRS:2,5,SPRUCE_STAIRS:3,5,WOOD:5,100)
Block(-1,11,-4,DARK_OAK_STAIRS:3)
Block(-1,11,-3,AIR:0)
Block(-1,11,-2,AIR:0)
Block(-1,11,-1,SPRUCE_FENCE:0)
Block(-1,11,0,AIR:0)
Block(-1,11,1,AIR:0)
Block(-1,11,2,AIR:0)
Block(-1,11,3,AIR:0)
Block(-1,11,4,SPRUCE_FENCE:0)
Block(-1,11,5,AIR:0)
Block(-1,11,6,AIR:0)
Block(-1,11,7,DARK_OAK_STAIRS:2)
RandomBlock(-1,11,8,WOOD:5,70,WOOD:1,30,WOODEN_SLAB:5,10,WOODEN_SLAB:1,10,DARK_OAK_STAIRS:0,5,DARK_OAK_STAIRS:1,5,DARK_OAK_STAIRS:2,5,DARK_OAK_STAIRS:3,5,SPRUCE_STAIRS:0,5,SPRUCE_STAIRS:1,5,SPRUCE_STAIRS:2,5,SPRUCE_STAIRS:3,5,WOOD:5,100)
RandomBlock(-1,11,9,WOOD:5,70,WOOD:1,30,WOODEN_SLAB:5,10,WOODEN_SLAB:1,10,DARK_OAK_STAIRS:0,5,DARK_OAK_STAIRS:1,5,DARK_OAK_STAIRS:2,5,DARK_OAK_STAIRS:3,5,SPRUCE_STAIRS:0,5,SPRUCE_STAIRS:1,5,SPRUCE_STAIRS:2,5,SPRUCE_STAIRS:3,5,WOOD:5,100)
Block(-1,12,-6,SPRUCE_FENCE:0)
RandomBlock(-1,12,-5,AIR:0,60,SKULL:1,../../../../Skulls/dungeon_skull_01.nbt,6,AIR,9,WEB,3,SKULL:1,../../../../Skulls/dungeon_skull_02.nbt,12,AIR,15,WEB,3,SKULL:1,../../../../Skulls/dungeon_skull_03.nbt,18,AIR:0,21,WEB:0,3,SKULL:1,../../../../Skulls/dungeon_skull_04.nbt,24,AIR:0,27,WEB:0,3,SKULL:1,../../../../Skulls/dungeon_skull_05.nbt,30,AIR:0,33,WEB:0,3,SKULL:1,../../../../Skulls/dungeon_skull_06.nbt,36,AIR:0,39,WEB:0,3,SKULL:1,../../../../Skulls/dungeon_skull_07.nbt,42,AIR:0,45,WEB:0,3,SKULL:1,../../../../Skulls/dungeon_skull_08.nbt,48,AIR:0,51,WEB:0,3,SKULL:1,../../../../Skulls/dungeon_skull_09.nbt,54,AIR:0,57,WEB:0,3,SKULL:1,../../../../Skulls/dungeon_skull_10.nbt,60,AIR:0,63,WEB:0,3,SKULL:1,../../../../Skulls/dungeon_skull_11.nbt,66,AIR:0,69,WEB:0,3,SKULL:1,../../../../Skulls/dungeon_skull_12.nbt,72,AIR:0,75,WEB:0,3,SKULL:1,../../../../Skulls/dungeon_skull_13.nbt,78,AIR:0,81,WEB:0,3,SKULL:1,../../../../Skulls/dungeon_skull_14.nbt,84,AIR:0,87,WEB:0,3,SKULL:1,../../../../Skulls/dungeon_skull_15.nbt,90,AIR:0,93,WEB:0,3,SKULL:1,../../../../Skulls/dungeon_skull_16.nbt,96,AIR:0,100)
Block(-1,12,-4,AIR:0)
Block(-1,12,-3,AIR:0)
Block(-1,12,-2,AIR:0)
Block(-1,12,-1,SPRUCE_FENCE:0)
Block(-1,12,0,AIR:0)
Block(-1,12,1,AIR:0)
Block(-1,12,2,AIR:0)
Block(-1,12,3,AIR:0)
Block(-1,12,4,SPRUCE_FENCE:0)
Block(-1,12,5,AIR:0)
Block(-1,12,6,AIR:0)
Block(-1,12,7,AIR:0)
Block(-1,12,8,AIR:0)
Block(-1,12,9,SPRUCE_FENCE:0)
Block(-1,13,-6,SPRUCE_FENCE:0)
Block(-1,13,-5,AIR:0)
Block(-1,13,-4,AIR:0)
Block(-1,13,-3,AIR:0)
Block(-1,13,-2,AIR:0)
Block(-1,13,-1,SPRUCE_FENCE:0)
Block(-1,13,0,AIR:0)
Block(-1,13,1,AIR:0)
Block(-1,13,2,AIR:0)
Block(-1,13,3,AIR:0)
Block(-1,13,4,SPRUCE_FENCE:0)
Block(-1,13,5,AIR:0)
Block(-1,13,6,AIR:0)
Block(-1,13,7,AIR:0)
Block(-1,13,8,AIR:0)
Block(-1,13,9,SPRUCE_FENCE:0)
Block(-1,14,-6,WOOD:1)
Block(-1,14,-5,AIR:0)
Block(-1,14,-4,WOOD:1)
Block(-1,14,-3,SPRUCE_FENCE:0)
Block(-1,14,-2,SPRUCE_FENCE:0)
Block(-1,14,-1,SPRUCE_FENCE:0)
Block(-1,14,0,AIR:0)
Block(-1,14,1,AIR:0)
Block(-1,14,2,AIR:0)
Block(-1,14,3,AIR:0)
Block(-1,14,4,SPRUCE_FENCE:0)
Block(-1,14,5,SPRUCE_FENCE:0)
Block(-1,14,6,SPRUCE_FENCE:0)
Block(-1,14,7,WOOD:1)
Block(-1,14,8,AIR:0)
Block(-1,14,9,WOOD:1)
Block(-1,15,-6,WOOD:1)
Block(-1,15,-5,AIR:0)
Block(-1,15,-4,WOOD:1)
Block(-1,15,-3,WOOD:1)
Block(-1,15,-2,WOOD:1)
Block(-1,15,-1,WOOD:1)
Block(-1,15,0,AIR:0)
Block(-1,15,1,AIR:0)
Block(-1,15,2,AIR:0)
RandomBlock(-1,15,3,TORCH:1,25,AIR:0,100)
Block(-1,15,4,WOOD:1)
Block(-1,15,5,WOOD:1)
Block(-1,15,6,WOOD:1)
Block(-1,15,7,WOOD:1)
Block(-1,15,8,AIR:0)
Block(-1,15,9,WOOD:1)
RandomBlock(-1,16,-6,WOOD:5,70,WOOD:1,30,WOODEN_SLAB:5,10,WOODEN_SLAB:1,10,DARK_OAK_STAIRS:0,5,DARK_OAK_STAIRS:1,5,DARK_OAK_STAIRS:2,5,DARK_OAK_STAIRS:3,5,SPRUCE_STAIRS:0,5,SPRUCE_STAIRS:1,5,SPRUCE_STAIRS:2,5,SPRUCE_STAIRS:3,5,WOOD:5,100)
RandomBlock(-1,16,-5,WOOD:5,70,WOOD:1,30,WOODEN_SLAB:5,10,WOODEN_SLAB:1,10,DARK_OAK_STAIRS:0,5,DARK_OAK_STAIRS:1,5,DARK_OAK_STAIRS:2,5,DARK_OAK_STAIRS:3,5,SPRUCE_STAIRS:0,5,SPRUCE_STAIRS:1,5,SPRUCE_STAIRS:2,5,SPRUCE_STAIRS:3,5,WOOD:5,100)
Block(-1,16,-4,DARK_OAK_STAIRS:3)
Block(-1,16,-3,AIR:0)
Block(-1,16,-2,AIR:0)
Block(-1,16,-1,SPRUCE_FENCE:0)
Block(-1,16,0,AIR:0)
Block(-1,16,1,AIR:0)
Block(-1,16,2,AIR:0)
Block(-1,16,3,AIR:0)
Block(-1,16,4,SPRUCE_FENCE:0)
Block(-1,16,5,AIR:0)
Block(-1,16,6,AIR:0)
Block(-1,16,7,DARK_OAK_STAIRS:2)
RandomBlock(-1,16,8,WOOD:5,70,WOOD:1,30,WOODEN_SLAB:5,10,WOODEN_SLAB:1,10,DARK_OAK_STAIRS:0,5,DARK_OAK_STAIRS:1,5,DARK_OAK_STAIRS:2,5,DARK_OAK_STAIRS:3,5,SPRUCE_STAIRS:0,5,SPRUCE_STAIRS:1,5,SPRUCE_STAIRS:2,5,SPRUCE_STAIRS:3,5,WOOD:5,100)
RandomBlock(-1,16,9,WOOD:5,70,WOOD:1,30,WOODEN_SLAB:5,10,WOODEN_SLAB:1,10,DARK_OAK_STAIRS:0,5,DARK_OAK_STAIRS:1,5,DARK_OAK_STAIRS:2,5,DARK_OAK_STAIRS:3,5,SPRUCE_STAIRS:0,5,SPRUCE_STAIRS:1,5,SPRUCE_STAIRS:2,5,SPRUCE_STAIRS:3,5,WOOD:5,100)
Block(-1,17,-6,SPRUCE_FENCE:0)
Block(-1,17,-5,AIR:0)
Block(-1,17,-4,AIR:0)
Block(-1,17,-3,AIR:0)
Block(-1,17,-2,AIR:0)
Block(-1,17,-1,SPRUCE_FENCE:0)
Block(-1,17,0,AIR:0)
Block(-1,17,1,AIR:0)
Block(-1,17,2,AIR:0)
Block(-1,17,3,AIR:0)
Block(-1,17,4,SPRUCE_FENCE:0)
Block(-1,17,5,AIR:0)
Block(-1,17,6,AIR:0)
Block(-1,17,7,AIR:0)
Block(-1,17,8,AIR:0)
Block(-1,17,9,SPRUCE_FENCE:0)
Block(-1,18,-6,SPRUCE_FENCE:0)
Block(-1,18,-5,AIR:0)
Block(-1,18,-4,AIR:0)
Block(-1,18,-3,AIR:0)
Block(-1,18,-2,AIR:0)
Block(-1,18,-1,SPRUCE_FENCE:0)
Block(-1,18,0,AIR:0)
Block(-1,18,1,AIR:0)
Block(-1,18,2,AIR:0)
Block(-1,18,3,AIR:0)
Block(-1,18,4,SPRUCE_FENCE:0)
Block(-1,18,5,AIR:0)
Block(-1,18,6,AIR:0)
Block(-1,18,7,AIR:0)
Block(-1,18,8,AIR:0)
Block(-1,18,9,SPRUCE_FENCE:0)
Block(-1,19,-6,WOOD:1)
Block(-1,19,-5,AIR:0)
Block(-1,19,-4,WOOD:1)
Block(-1,19,-3,WOOD:1)
Block(-1,19,-2,WOOD:1)
Block(-1,19,-1,WOOD:1)
Block(-1,19,0,SPRUCE_FENCE:0)
Block(-1,19,1,SPRUCE_FENCE:0)
Block(-1,19,2,SPRUCE_FENCE:0)
Block(-1,19,3,SPRUCE_FENCE:0)
Block(-1,19,4,WOOD:1)
Block(-1,19,5,WOOD:1)
Block(-1,19,6,WOOD:1)
Block(-1,19,7,WOOD:1)
Block(-1,19,8,AIR:0)
Block(-1,19,9,WOOD:1)
RandomBlock(0,1,-6,WOOD:5,70,WOOD:1,30,WOODEN_SLAB:5,10,WOODEN_SLAB:1,10,DARK_OAK_STAIRS:0,5,DARK_OAK_STAIRS:1,5,DARK_OAK_STAIRS:2,5,DARK_OAK_STAIRS:3,5,SPRUCE_STAIRS:0,5,SPRUCE_STAIRS:1,5,SPRUCE_STAIRS:2,5,SPRUCE_STAIRS:3,5,WOOD:5,100)
RandomBlock(0,1,-5,WOOD:5,70,WOOD:1,30,WOODEN_SLAB:5,10,WOODEN_SLAB:1,10,DARK_OAK_STAIRS:0,5,DARK_OAK_STAIRS:1,5,DARK_OAK_STAIRS:2,5,DARK_OAK_STAIRS:3,5,SPRUCE_STAIRS:0,5,SPRUCE_STAIRS:1,5,SPRUCE_STAIRS:2,5,SPRUCE_STAIRS:3,5,WOOD:5,100)
RandomBlock(0,1,-4,WOOD:5,70,WOOD:1,30,WOODEN_SLAB:5,10,WOODEN_SLAB:1,10,DARK_OAK_STAIRS:0,5,DARK_OAK_STAIRS:1,5,DARK_OAK_STAIRS:2,5,DARK_OAK_STAIRS:3,5,SPRUCE_STAIRS:0,5,SPRUCE_STAIRS:1,5,SPRUCE_STAIRS:2,5,SPRUCE_STAIRS:3,5,WOOD:5,100)
RandomBlock(0,1,-3,WOOD:5,70,WOOD:1,30,WOODEN_SLAB:5,10,WOODEN_SLAB:1,10,DARK_OAK_STAIRS:0,5,DARK_OAK_STAIRS:1,5,DARK_OAK_STAIRS:2,5,DARK_OAK_STAIRS:3,5,SPRUCE_STAIRS:0,5,SPRUCE_STAIRS:1,5,SPRUCE_STAIRS:2,5,SPRUCE_STAIRS:3,5,WOOD:5,100)
RandomBlock(0,1,-2,WOOD:5,70,WOOD:1,30,WOODEN_SLAB:5,10,WOODEN_SLAB:1,10,DARK_OAK_STAIRS:0,5,DARK_OAK_STAIRS:1,5,DARK_OAK_STAIRS:2,5,DARK_OAK_STAIRS:3,5,SPRUCE_STAIRS:0,5,SPRUCE_STAIRS:1,5,SPRUCE_STAIRS:2,5,SPRUCE_STAIRS:3,5,WOOD:5,100)
RandomBlock(0,1,-1,WOOD:5,70,WOOD:1,30,WOODEN_SLAB:5,10,WOODEN_SLAB:1,10,DARK_OAK_STAIRS:0,5,DARK_OAK_STAIRS:1,5,DARK_OAK_STAIRS:2,5,DARK_OAK_STAIRS:3,5,SPRUCE_STAIRS:0,5,SPRUCE_STAIRS:1,5,SPRUCE_STAIRS:2,5,SPRUCE_STAIRS:3,5,WOOD:5,100)
RandomBlock(0,1,0,WOOD:5,70,WOOD:1,30,WOODEN_SLAB:5,10,WOODEN_SLAB:1,10,DARK_OAK_STAIRS:0,5,DARK_OAK_STAIRS:1,5,DARK_OAK_STAIRS:2,5,DARK_OAK_STAIRS:3,5,SPRUCE_STAIRS:0,5,SPRUCE_STAIRS:1,5,SPRUCE_STAIRS:2,5,SPRUCE_STAIRS:3,5,WOOD:5,100)
RandomBlock(0,1,1,WOOD:5,70,WOOD:1,30,WOODEN_SLAB:5,10,WOODEN_SLAB:1,10,DARK_OAK_STAIRS:0,5,DARK_OAK_STAIRS:1,5,DARK_OAK_STAIRS:2,5,DARK_OAK_STAIRS:3,5,SPRUCE_STAIRS:0,5,SPRUCE_STAIRS:1,5,SPRUCE_STAIRS:2,5,SPRUCE_STAIRS:3,5,WOOD:5,100)
RandomBlock(0,1,2,WOOD:5,70,WOOD:1,30,WOODEN_SLAB:5,10,WOODEN_SLAB:1,10,DARK_OAK_STAIRS:0,5,DARK_OAK_STAIRS:1,5,DARK_OAK_STAIRS:2,5,DARK_OAK_STAIRS:3,5,SPRUCE_STAIRS:0,5,SPRUCE_STAIRS:1,5,SPRUCE_STAIRS:2,5,SPRUCE_STAIRS:3,5,WOOD:5,100)
RandomBlock(0,1,3,WOOD:5,70,WOOD:1,30,WOODEN_SLAB:5,10,WOODEN_SLAB:1,10,DARK_OAK_STAIRS:0,5,DARK_OAK_STAIRS:1,5,DARK_OAK_STAIRS:2,5,DARK_OAK_STAIRS:3,5,SPRUCE_STAIRS:0,5,SPRUCE_STAIRS:1,5,SPRUCE_STAIRS:2,5,SPRUCE_STAIRS:3,5,WOOD:5,100)
RandomBlock(0,1,4,WOOD:5,70,WOOD:1,30,WOODEN_SLAB:5,10,WOODEN_SLAB:1,10,DARK_OAK_STAIRS:0,5,DARK_OAK_STAIRS:1,5,DARK_OAK_STAIRS:2,5,DARK_OAK_STAIRS:3,5,SPRUCE_STAIRS:0,5,SPRUCE_STAIRS:1,5,SPRUCE_STAIRS:2,5,SPRUCE_STAIRS:3,5,WOOD:5,100)
RandomBlock(0,1,5,WOOD:5,70,WOOD:1,30,WOODEN_SLAB:5,10,WOODEN_SLAB:1,10,DARK_OAK_STAIRS:0,5,DARK_OAK_STAIRS:1,5,DARK_OAK_STAIRS:2,5,DARK_OAK_STAIRS:3,5,SPRUCE_STAIRS:0,5,SPRUCE_STAIRS:1,5,SPRUCE_STAIRS:2,5,SPRUCE_STAIRS:3,5,WOOD:5,100)
RandomBlock(0,1,6,WOOD:5,70,WOOD:1,30,WOODEN_SLAB:5,10,WOODEN_SLAB:1,10,DARK_OAK_STAIRS:0,5,DARK_OAK_STAIRS:1,5,DARK_OAK_STAIRS:2,5,DARK_OAK_STAIRS:3,5,SPRUCE_STAIRS:0,5,SPRUCE_STAIRS:1,5,SPRUCE_STAIRS:2,5,SPRUCE_STAIRS:3,5,WOOD:5,100)
RandomBlock(0,1,7,WOOD:5,70,WOOD:1,30,WOODEN_SLAB:5,10,WOODEN_SLAB:1,10,DARK_OAK_STAIRS:0,5,DARK_OAK_STAIRS:1,5,DARK_OAK_STAIRS:2,5,DARK_OAK_STAIRS:3,5,SPRUCE_STAIRS:0,5,SPRUCE_STAIRS:1,5,SPRUCE_STAIRS:2,5,SPRUCE_STAIRS:3,5,WOOD:5,100)
RandomBlock(0,1,8,WOOD:5,70,WOOD:1,30,WOODEN_SLAB:5,10,WOODEN_SLAB:1,10,DARK_OAK_STAIRS:0,5,DARK_OAK_STAIRS:1,5,DARK_OAK_STAIRS:2,5,DARK_OAK_STAIRS:3,5,SPRUCE_STAIRS:0,5,SPRUCE_STAIRS:1,5,SPRUCE_STAIRS:2,5,SPRUCE_STAIRS:3,5,WOOD:5,100)
RandomBlock(0,1,9,WOOD:5,70,WOOD:1,30,WOODEN_SLAB:5,10,WOODEN_SLAB:1,10,DARK_OAK_STAIRS:0,5,DARK_OAK_STAIRS:1,5,DARK_OAK_STAIRS:2,5,DARK_OAK_STAIRS:3,5,SPRUCE_STAIRS:0,5,SPRUCE_STAIRS:1,5,SPRUCE_STAIRS:2,5,SPRUCE_STAIRS:3,5,WOOD:5,100)
Block(0,2,-6,RAILS:0)
Block(0,2,-5,RAILS:0)
Block(0,2,-4,RAILS:0)
Block(0,2,-3,RAILS:0)
Block(0,2,-2,RAILS:0)
Block(0,2,-1,RAILS:0)
Block(0,2,0,RAILS:0)
Block(0,2,1,RAILS:0)
Block(0,2,2,POWERED_RAIL:8)
Block(0,2,3,RAILS:0)
Block(0,2,4,RAILS:0)
Block(0,2,5,RAILS:0)
Block(0,2,6,RAILS:0)
Block(0,2,7,RAILS:0)
Block(0,2,8,RAILS:0)
Block(0,2,9,RAILS:0)
Block(0,3,-6,AIR:0)
Block(0,3,-5,AIR:0)
Block(0,3,-4,AIR:0)
Block(0,3,-3,AIR:0)
Block(0,3,-2,AIR:0)
Block(0,3,-1,AIR:0)
Block(0,3,0,AIR:0)
Block(0,3,1,AIR:0)
Block(0,3,2,AIR:0)
Block(0,3,3,AIR:0)
Block(0,3,4,AIR:0)
Block(0,3,5,AIR:0)
Block(0,3,6,AIR:0)
Block(0,3,7,AIR:0)
Block(0,3,8,AIR:0)
Block(0,3,9,AIR:0)
Block(0,4,-6,WOOD:1)
Block(0,4,-5,AIR:0)
Block(0,4,-4,WOOD:1)
Block(0,4,-3,AIR:0)
Block(0,4,-2,AIR:0)
Block(0,4,-1,AIR:0)
Block(0,4,0,AIR:0)
Block(0,4,1,AIR:0)
Block(0,4,2,AIR:0)
Block(0,4,3,AIR:0)
Block(0,4,4,AIR:0)
Block(0,4,5,AIR:0)
Block(0,4,6,AIR:0)
Block(0,4,7,WOOD:1)
Block(0,4,8,AIR:0)
Block(0,4,9,WOOD:1)
Block(0,5,-6,AIR:0)
Block(0,5,-5,AIR:0)
Block(0,5,-4,WOOD:1)
Block(0,5,-3,SPRUCE_FENCE:0)
Block(0,5,-2,WOOD:1)
Block(0,5,-1,AIR:0)
Block(0,5,0,AIR:0)
Block(0,5,1,AIR:0)
Block(0,5,2,AIR:0)
Block(0,5,3,AIR:0)
Block(0,5,4,AIR:0)
Block(0,5,5,WOOD:1)
Block(0,5,6,SPRUCE_FENCE:0)
Block(0,5,7,WOOD:1)
Block(0,5,8,AIR:0)
Block(0,5,9,AIR:0)
RandomBlock(0,6,-6,WOOD:5,70,WOOD:1,30,WOODEN_SLAB:5,10,WOODEN_SLAB:1,10,DARK_OAK_STAIRS:0,5,DARK_OAK_STAIRS:1,5,DARK_OAK_STAIRS:2,5,DARK_OAK_STAIRS:3,5,SPRUCE_STAIRS:0,5,SPRUCE_STAIRS:1,5,SPRUCE_STAIRS:2,5,SPRUCE_STAIRS:3,5,WOOD:5,100)
RandomBlock(0,6,-5,WOOD:5,70,WOOD:1,30,WOODEN_SLAB:5,10,WOODEN_SLAB:1,10,DARK_OAK_STAIRS:0,5,DARK_OAK_STAIRS:1,5,DARK_OAK_STAIRS:2,5,DARK_OAK_STAIRS:3,5,SPRUCE_STAIRS:0,5,SPRUCE_STAIRS:1,5,SPRUCE_STAIRS:2,5,SPRUCE_STAIRS:3,5,WOOD:5,100)
RandomBlock(0,6,-4,WOOD:5,70,WOOD:1,30,WOODEN_SLAB:5,10,WOODEN_SLAB:1,10,DARK_OAK_STAIRS:0,5,DARK_OAK_STAIRS:1,5,DARK_OAK_STAIRS:2,5,DARK_OAK_STAIRS:3,5,SPRUCE_STAIRS:0,5,SPRUCE_STAIRS:1,5,SPRUCE_STAIRS:2,5,SPRUCE_STAIRS:3,5,WOOD:5,100)
Block(0,6,-3,SPRUCE_FENCE:0)
Block(0,6,-2,LADDER:3)
Block(0,6,-1,AIR:0)
Block(0,6,0,AIR:0)
Block(0,6,1,AIR:0)
Block(0,6,2,AIR:0)
Block(0,6,3,AIR:0)
Block(0,6,4,AIR:0)
Block(0,6,5,LADDER:2)
Block(0,6,6,SPRUCE_FENCE:0)
RandomBlock(0,6,7,WOOD:5,70,WOOD:1,30,WOODEN_SLAB:5,10,WOODEN_SLAB:1,10,DARK_OAK_STAIRS:0,5,DARK_OAK_STAIRS:1,5,DARK_OAK_STAIRS:2,5,DARK_OAK_STAIRS:3,5,SPRUCE_STAIRS:0,5,SPRUCE_STAIRS:1,5,SPRUCE_STAIRS:2,5,SPRUCE_STAIRS:3,5,WOOD:5,100)
RandomBlock(0,6,8,WOOD:5,70,WOOD:1,30,WOODEN_SLAB:5,10,WOODEN_SLAB:1,10,DARK_OAK_STAIRS:0,5,DARK_OAK_STAIRS:1,5,DARK_OAK_STAIRS:2,5,DARK_OAK_STAIRS:3,5,SPRUCE_STAIRS:0,5,SPRUCE_STAIRS:1,5,SPRUCE_STAIRS:2,5,SPRUCE_STAIRS:3,5,WOOD:5,100)
RandomBlock(0,6,9,WOOD:5,70,WOOD:1,30,WOODEN_SLAB:5,10,WOODEN_SLAB:1,10,DARK_OAK_STAIRS:0,5,DARK_OAK_STAIRS:1,5,DARK_OAK_STAIRS:2,5,DARK_OAK_STAIRS:3,5,SPRUCE_STAIRS:0,5,SPRUCE_STAIRS:1,5,SPRUCE_STAIRS:2,5,SPRUCE_STAIRS:3,5,WOOD:5,100)
RandomBlock(0,7,-6,AIR:0,60,SKULL:1,../../../../Skulls/dungeon_skull_01.nbt,6,AIR,9,WEB,3,SKULL:1,../../../../Skulls/dungeon_skull_02.nbt,12,AIR,15,WEB,3,SKULL:1,../../../../Skulls/dungeon_skull_03.nbt,18,AIR:0,21,WEB:0,3,SKULL:1,../../../../Skulls/dungeon_skull_04.nbt,24,AIR:0,27,WEB:0,3,SKULL:1,../../../../Skulls/dungeon_skull_05.nbt,30,AIR:0,33,WEB:0,3,SKULL:1,../../../../Skulls/dungeon_skull_06.nbt,36,AIR:0,39,WEB:0,3,SKULL:1,../../../../Skulls/dungeon_skull_07.nbt,42,AIR:0,45,WEB:0,3,SKULL:1,../../../../Skulls/dungeon_skull_08.nbt,48,AIR:0,51,WEB:0,3,SKULL:1,../../../../Skulls/dungeon_skull_09.nbt,54,AIR:0,57,WEB:0,3,SKULL:1,../../../../Skulls/dungeon_skull_10.nbt,60,AIR:0,63,WEB:0,3,SKULL:1,../../../../Skulls/dungeon_skull_11.nbt,66,AIR:0,69,WEB:0,3,SKULL:1,../../../../Skulls/dungeon_skull_12.nbt,72,AIR:0,75,WEB:0,3,SKULL:1,../../../../Skulls/dungeon_skull_13.nbt,78,AIR:0,81,WEB:0,3,SKULL:1,../../../../Skulls/dungeon_skull_14.nbt,84,AIR:0,87,WEB:0,3,SKULL:1,../../../../Skulls/dungeon_skull_15.nbt,90,AIR:0,93,WEB:0,3,SKULL:1,../../../../Skulls/dungeon_skull_16.nbt,96,AIR:0,100)
Block(0,7,-5,AIR:0)
Block(0,7,-4,SPRUCE_FENCE:0)
Block(0,7,-3,SPRUCE_FENCE:0)
Block(0,7,-2,LADDER:3)
Block(0,7,-1,AIR:0)
Block(0,7,0,AIR:0)
Block(0,7,1,AIR:0)
Block(0,7,2,AIR:0)
Block(0,7,3,AIR:0)
Block(0,7,4,AIR:0)
Block(0,7,5,LADDER:2)
Block(0,7,6,SPRUCE_FENCE:0)
Block(0,7,7,SPRUCE_FENCE:0)
Block(0,7,8,AIR:0)
Block(0,7,9,AIR:0)
Block(0,8,-6,AIR:0)
Block(0,8,-5,AIR:0)
Block(0,8,-4,SPRUCE_FENCE:0)
Block(0,8,-3,SPRUCE_FENCE:0)
Block(0,8,-2,LADDER:3)
Block(0,8,-1,WOOD:1)
Block(0,8,0,AIR:0)
Block(0,8,1,AIR:0)
Block(0,8,2,AIR:0)
Block(0,8,3,AIR:0)
Block(0,8,4,WOOD:1)
Block(0,8,5,LADDER:2)
Block(0,8,6,SPRUCE_FENCE:0)
Block(0,8,7,SPRUCE_FENCE:0)
Block(0,8,8,AIR:0)
Block(0,8,9,AIR:0)
Block(0,9,-6,WOOD:1)
Block(0,9,-5,AIR:0)
Block(0,9,-4,WOOD:1)
Block(0,9,-3,SPRUCE_FENCE:0)
Block(0,9,-2,LADDER:3)
Block(0,9,-1,AIR:0)
Block(0,9,0,AIR:0)
Block(0,9,1,AIR:0)
Block(0,9,2,AIR:0)
Block(0,9,3,AIR:0)
Block(0,9,4,AIR:0)
Block(0,9,5,LADDER:2)
Block(0,9,6,SPRUCE_FENCE:0)
Block(0,9,7,WOOD:1)
Block(0,9,8,AIR:0)
Block(0,9,9,WOOD:1)
Block(0,10,-6,AIR:0)
Block(0,10,-5,AIR:0)
Block(0,10,-4,WOOD:1)
Block(0,10,-3,SPRUCE_FENCE:0)
Block(0,10,-2,LADDER:3)
Block(0,10,-1,LADDER:5)
Block(0,10,0,AIR:0)
Block(0,10,1,AIR:0)
Block(0,10,2,AIR:0)
Block(0,10,3,AIR:0)
Block(0,10,4,AIR:0)
Block(0,10,5,LADDER:2)
Block(0,10,6,SPRUCE_FENCE:0)
Block(0,10,7,WOOD:1)
Block(0,10,8,AIR:0)
Block(0,10,9,AIR:0)
RandomBlock(0,11,-6,WOOD:5,70,WOOD:1,30,WOODEN_SLAB:5,10,WOODEN_SLAB:1,10,DARK_OAK_STAIRS:0,5,DARK_OAK_STAIRS:1,5,DARK_OAK_STAIRS:2,5,DARK_OAK_STAIRS:3,5,SPRUCE_STAIRS:0,5,SPRUCE_STAIRS:1,5,SPRUCE_STAIRS:2,5,SPRUCE_STAIRS:3,5,WOOD:5,100)
RandomBlock(0,11,-5,WOOD:5,70,WOOD:1,30,WOODEN_SLAB:5,10,WOODEN_SLAB:1,10,DARK_OAK_STAIRS:0,5,DARK_OAK_STAIRS:1,5,DARK_OAK_STAIRS:2,5,DARK_OAK_STAIRS:3,5,SPRUCE_STAIRS:0,5,SPRUCE_STAIRS:1,5,SPRUCE_STAIRS:2,5,SPRUCE_STAIRS:3,5,WOOD:5,100)
RandomBlock(0,11,-4,WOOD:5,70,WOOD:1,30,WOODEN_SLAB:5,10,WOODEN_SLAB:1,10,DARK_OAK_STAIRS:0,5,DARK_OAK_STAIRS:1,5,DARK_OAK_STAIRS:2,5,DARK_OAK_STAIRS:3,5,SPRUCE_STAIRS:0,5,SPRUCE_STAIRS:1,5,SPRUCE_STAIRS:2,5,SPRUCE_STAIRS:3,5,WOOD:5,100)
Block(0,11,-3,SPRUCE_FENCE:0)
Block(0,11,-2,LADDER:3)
Block(0,11,-1,AIR:0)
Block(0,11,0,AIR:0)
Block(0,11,1,AIR:0)
Block(0,11,2,AIR:0)
Block(0,11,3,AIR:0)
Block(0,11,4,AIR:0)
Block(0,11,5,LADDER:2)
Block(0,11,6,SPRUCE_FENCE:0)
RandomBlock(0,11,7,WOOD:5,70,WOOD:1,30,WOODEN_SLAB:5,10,WOODEN_SLAB:1,10,DARK_OAK_STAIRS:0,5,DARK_OAK_STAIRS:1,5,DARK_OAK_STAIRS:2,5,DARK_OAK_STAIRS:3,5,SPRUCE_STAIRS:0,5,SPRUCE_STAIRS:1,5,SPRUCE_STAIRS:2,5,SPRUCE_STAIRS:3,5,WOOD:5,100)
RandomBlock(0,11,8,WOOD:5,70,WOOD:1,30,WOODEN_SLAB:5,10,WOODEN_SLAB:1,10,DARK_OAK_STAIRS:0,5,DARK_OAK_STAIRS:1,5,DARK_OAK_STAIRS:2,5,DARK_OAK_STAIRS:3,5,SPRUCE_STAIRS:0,5,SPRUCE_STAIRS:1,5,SPRUCE_STAIRS:2,5,SPRUCE_STAIRS:3,5,WOOD:5,100)
RandomBlock(0,11,9,WOOD:5,70,WOOD:1,30,WOODEN_SLAB:5,10,WOODEN_SLAB:1,10,DARK_OAK_STAIRS:0,5,DARK_OAK_STAIRS:1,5,DARK_OAK_STAIRS:2,5,DARK_OAK_STAIRS:3,5,SPRUCE_STAIRS:0,5,SPRUCE_STAIRS:1,5,SPRUCE_STAIRS:2,5,SPRUCE_STAIRS:3,5,WOOD:5,100)
Block(0,12,-6,AIR:0)
Block(0,12,-5,AIR:0)
Block(0,12,-4,SPRUCE_FENCE:0)
Block(0,12,-3,SPRUCE_FENCE:0)
Block(0,12,-2,LADDER:3)
Block(0,12,-1,AIR:0)
Block(0,12,0,AIR:0)
Block(0,12,1,AIR:0)
Block(0,12,2,AIR:0)
Block(0,12,3,AIR:0)
Block(0,12,4,AIR:0)
Block(0,12,5,LADDER:2)
Block(0,12,6,SPRUCE_FENCE:0)
Block(0,12,7,SPRUCE_FENCE:0)
Block(0,12,8,AIR:0)
Block(0,12,9,AIR:0)
Block(0,13,-6,AIR:0)
Block(0,13,-5,AIR:0)
Block(0,13,-4,SPRUCE_FENCE:0)
Block(0,13,-3,SPRUCE_FENCE:0)
Block(0,13,-2,LADDER:3)
Block(0,13,-1,AIR:0)
Block(0,13,0,AIR:0)
Block(0,13,1,AIR:0)
Block(0,13,2,AIR:0)
Block(0,13,3,AIR:0)
Block(0,13,4,AIR:0)
Block(0,13,5,LADDER:2)
Block(0,13,6,SPRUCE_FENCE:0)
Block(0,13,7,SPRUCE_FENCE:0)
Block(0,13,8,AIR:0)
Block(0,13,9,AIR:0)
Block(0,14,-6,WOOD:1)
Block(0,14,-5,AIR:0)
Block(0,14,-4,WOOD:1)
Block(0,14,-3,SPRUCE_FENCE:0)
Block(0,14,-2,LADDER:3)
Block(0,14,-1,AIR:0)
Block(0,14,0,AIR:0)
Block(0,14,1,AIR:0)
Block(0,14,2,AIR:0)
Block(0,14,3,AIR:0)
Block(0,14,4,AIR:0)
Block(0,14,5,LADDER:2)
Block(0,14,6,SPRUCE_FENCE:0)
Block(0,14,7,WOOD:1)
Block(0,14,8,AIR:0)
Block(0,14,9,WOOD:1)
Block(0,15,-6,AIR:0)
Block(0,15,-5,AIR:0)
Block(0,15,-4,WOOD:1)
Block(0,15,-3,SPRUCE_FENCE:0)
Block(0,15,-2,LADDER:3)
Block(0,15,-1,AIR:0)
Block(0,15,0,AIR:0)
Block(0,15,1,AIR:0)
Block(0,15,2,AIR:0)
Block(0,15,3,AIR:0)
Block(0,15,4,AIR:0)
Block(0,15,5,LADDER:2)
Block(0,15,6,SPRUCE_FENCE:0)
Block(0,15,7,WOOD:1)
Block(0,15,8,AIR:0)
Block(0,15,9,AIR:0)
RandomBlock(0,16,-6,WOOD:5,70,WOOD:1,30,WOODEN_SLAB:5,10,WOODEN_SLAB:1,10,DARK_OAK_STAIRS:0,5,DARK_OAK_STAIRS:1,5,DARK_OAK_STAIRS:2,5,DARK_OAK_STAIRS:3,5,SPRUCE_STAIRS:0,5,SPRUCE_STAIRS:1,5,SPRUCE_STAIRS:2,5,SPRUCE_STAIRS:3,5,WOOD:5,100)
RandomBlock(0,16,-5,WOOD:5,70,WOOD:1,30,WOODEN_SLAB:5,10,WOODEN_SLAB:1,10,DARK_OAK_STAIRS:0,5,DARK_OAK_STAIRS:1,5,DARK_OAK_STAIRS:2,5,DARK_OAK_STAIRS:3,5,SPRUCE_STAIRS:0,5,SPRUCE_STAIRS:1,5,SPRUCE_STAIRS:2,5,SPRUCE_STAIRS:3,5,WOOD:5,100)
RandomBlock(0,16,-4,WOOD:5,70,WOOD:1,30,WOODEN_SLAB:5,10,WOODEN_SLAB:1,10,DARK_OAK_STAIRS:0,5,DARK_OAK_STAIRS:1,5,DARK_OAK_STAIRS:2,5,DARK_OAK_STAIRS:3,5,SPRUCE_STAIRS:0,5,SPRUCE_STAIRS:1,5,SPRUCE_STAIRS:2,5,SPRUCE_STAIRS:3,5,WOOD:5,100)
Block(0,16,-3,SPRUCE_FENCE:0)
Block(0,16,-2,LADDER:3)
Block(0,16,-1,AIR:0)
Block(0,16,0,AIR:0)
Block(0,16,1,AIR:0)
Block(0,16,2,AIR:0)
Block(0,16,3,AIR:0)
Block(0,16,4,AIR:0)
Block(0,16,5,LADDER:2)
Block(0,16,6,SPRUCE_FENCE:0)
RandomBlock(0,16,7,WOOD:5,70,WOOD:1,30,WOODEN_SLAB:5,10,WOODEN_SLAB:1,10,DARK_OAK_STAIRS:0,5,DARK_OAK_STAIRS:1,5,DARK_OAK_STAIRS:2,5,DARK_OAK_STAIRS:3,5,SPRUCE_STAIRS:0,5,SPRUCE_STAIRS:1,5,SPRUCE_STAIRS:2,5,SPRUCE_STAIRS:3,5,WOOD:5,100)
RandomBlock(0,16,8,WOOD:5,70,WOOD:1,30,WOODEN_SLAB:5,10,WOODEN_SLAB:1,10,DARK_OAK_STAIRS:0,5,DARK_OAK_STAIRS:1,5,DARK_OAK_STAIRS:2,5,DARK_OAK_STAIRS:3,5,SPRUCE_STAIRS:0,5,SPRUCE_STAIRS:1,5,SPRUCE_STAIRS:2,5,SPRUCE_STAIRS:3,5,WOOD:5,100)
RandomBlock(0,16,9,WOOD:5,70,WOOD:1,30,WOODEN_SLAB:5,10,WOODEN_SLAB:1,10,DARK_OAK_STAIRS:0,5,DARK_OAK_STAIRS:1,5,DARK_OAK_STAIRS:2,5,DARK_OAK_STAIRS:3,5,SPRUCE_STAIRS:0,5,SPRUCE_STAIRS:1,5,SPRUCE_STAIRS:2,5,SPRUCE_STAIRS:3,5,WOOD:5,100)
Block(0,17,-6,AIR:0)
Block(0,17,-5,AIR:0)
Block(0,17,-4,SPRUCE_FENCE:0)
Block(0,17,-3,SPRUCE_FENCE:0)
Block(0,17,-2,LADDER:3)
Block(0,17,-1,AIR:0)
Block(0,17,0,AIR:0)
Block(0,17,1,AIR:0)
Block(0,17,2,AIR:0)
Block(0,17,3,AIR:0)
Block(0,17,4,AIR:0)
Block(0,17,5,LADDER:2)
Block(0,17,6,SPRUCE_FENCE:0)
Block(0,17,7,SPRUCE_FENCE:0)
Block(0,17,8,AIR:0)
Block(0,17,9,AIR:0)
Block(0,18,-6,AIR:0)
Block(0,18,-5,AIR:0)
Block(0,18,-4,SPRUCE_FENCE:0)
Block(0,18,-3,SPRUCE_FENCE:0)
Block(0,18,-2,LADDER:3)
Block(0,18,-1,AIR:0)
Block(0,18,0,AIR:0)
Block(0,18,1,AIR:0)
Block(0,18,2,AIR:0)
Block(0,18,3,AIR:0)
Block(0,18,4,AIR:0)
Block(0,18,5,LADDER:2)
Block(0,18,6,SPRUCE_FENCE:0)
Block(0,18,7,SPRUCE_FENCE:0)
Block(0,18,8,AIR:0)
Block(0,18,9,AIR:0)
Block(0,19,-6,WOOD:1)
Block(0,19,-5,AIR:0)
Block(0,19,-4,WOOD:1)
Block(0,19,-3,WOOD:1)
Block(0,19,-2,LADDER:3)
Block(0,19,-1,SPRUCE_FENCE:0)
Block(0,19,0,SPRUCE_FENCE:0)
Block(0,19,1,SPRUCE_FENCE:0)
Block(0,19,2,SPRUCE_FENCE:0)
Block(0,19,3,SPRUCE_FENCE:0)
Block(0,19,4,SPRUCE_FENCE:0)
Block(0,19,5,LADDER:2)
Block(0,19,6,WOOD:1)
Block(0,19,7,WOOD:1)
Block(0,19,8,AIR:0)
Block(0,19,9,WOOD:1)
Block(0,20,1,SPRUCE_FENCE:0)
Block(0,20,3,SPRUCE_FENCE:0)
RandomBlock(1,1,-6,WOOD:5,70,WOOD:1,30,WOODEN_SLAB:5,10,WOODEN_SLAB:1,10,DARK_OAK_STAIRS:0,5,DARK_OAK_STAIRS:1,5,DARK_OAK_STAIRS:2,5,DARK_OAK_STAIRS:3,5,SPRUCE_STAIRS:0,5,SPRUCE_STAIRS:1,5,SPRUCE_STAIRS:2,5,SPRUCE_STAIRS:3,5,WOOD:5,100)
RandomBlock(1,1,-5,WOOD:5,70,WOOD:1,30,WOODEN_SLAB:5,10,WOODEN_SLAB:1,10,DARK_OAK_STAIRS:0,5,DARK_OAK_STAIRS:1,5,DARK_OAK_STAIRS:2,5,DARK_OAK_STAIRS:3,5,SPRUCE_STAIRS:0,5,SPRUCE_STAIRS:1,5,SPRUCE_STAIRS:2,5,SPRUCE_STAIRS:3,5,WOOD:5,100)
RandomBlock(1,1,-4,WOOD:5,70,WOOD:1,30,WOODEN_SLAB:5,10,WOODEN_SLAB:1,10,DARK_OAK_STAIRS:0,5,DARK_OAK_STAIRS:1,5,DARK_OAK_STAIRS:2,5,DARK_OAK_STAIRS:3,5,SPRUCE_STAIRS:0,5,SPRUCE_STAIRS:1,5,SPRUCE_STAIRS:2,5,SPRUCE_STAIRS:3,5,WOOD:5,100)
RandomBlock(1,1,-3,WOOD:5,70,WOOD:1,30,WOODEN_SLAB:5,10,WOODEN_SLAB:1,10,DARK_OAK_STAIRS:0,5,DARK_OAK_STAIRS:1,5,DARK_OAK_STAIRS:2,5,DARK_OAK_STAIRS:3,5,SPRUCE_STAIRS:0,5,SPRUCE_STAIRS:1,5,SPRUCE_STAIRS:2,5,SPRUCE_STAIRS:3,5,WOOD:5,100)
RandomBlock(1,1,-2,WOOD:5,70,WOOD:1,30,WOODEN_SLAB:5,10,WOODEN_SLAB:1,10,DARK_OAK_STAIRS:0,5,DARK_OAK_STAIRS:1,5,DARK_OAK_STAIRS:2,5,DARK_OAK_STAIRS:3,5,SPRUCE_STAIRS:0,5,SPRUCE_STAIRS:1,5,SPRUCE_STAIRS:2,5,SPRUCE_STAIRS:3,5,WOOD:5,100)
RandomBlock(1,1,-1,WOOD:5,70,WOOD:1,30,WOODEN_SLAB:5,10,WOODEN_SLAB:1,10,DARK_OAK_STAIRS:0,5,DARK_OAK_STAIRS:1,5,DARK_OAK_STAIRS:2,5,DARK_OAK_STAIRS:3,5,SPRUCE_STAIRS:0,5,SPRUCE_STAIRS:1,5,SPRUCE_STAIRS:2,5,SPRUCE_STAIRS:3,5,WOOD:5,100)
RandomBlock(1,1,0,WOOD:5,70,WOOD:1,30,WOODEN_SLAB:5,10,WOODEN_SLAB:1,10,DARK_OAK_STAIRS:0,5,DARK_OAK_STAIRS:1,5,DARK_OAK_STAIRS:2,5,DARK_OAK_STAIRS:3,5,SPRUCE_STAIRS:0,5,SPRUCE_STAIRS:1,5,SPRUCE_STAIRS:2,5,SPRUCE_STAIRS:3,5,WOOD:5,100)
RandomBlock(1,1,1,WOOD:5,70,WOOD:1,30,WOODEN_SLAB:5,10,WOODEN_SLAB:1,10,DARK_OAK_STAIRS:0,5,DARK_OAK_STAIRS:1,5,DARK_OAK_STAIRS:2,5,DARK_OAK_STAIRS:3,5,SPRUCE_STAIRS:0,5,SPRUCE_STAIRS:1,5,SPRUCE_STAIRS:2,5,SPRUCE_STAIRS:3,5,WOOD:5,100)
RandomBlock(1,1,2,WOOD:5,70,WOOD:1,30,WOODEN_SLAB:5,10,WOODEN_SLAB:1,10,DARK_OAK_STAIRS:0,5,DARK_OAK_STAIRS:1,5,DARK_OAK_STAIRS:2,5,DARK_OAK_STAIRS:3,5,SPRUCE_STAIRS:0,5,SPRUCE_STAIRS:1,5,SPRUCE_STAIRS:2,5,SPRUCE_STAIRS:3,5,WOOD:5,100)
RandomBlock(1,1,3,WOOD:5,70,WOOD:1,30,WOODEN_SLAB:5,10,WOODEN_SLAB:1,10,DARK_OAK_STAIRS:0,5,DARK_OAK_STAIRS:1,5,DARK_OAK_STAIRS:2,5,DARK_OAK_STAIRS:3,5,SPRUCE_STAIRS:0,5,SPRUCE_STAIRS:1,5,SPRUCE_STAIRS:2,5,SPRUCE_STAIRS:3,5,WOOD:5,100)
RandomBlock(1,1,4,WOOD:5,70,WOOD:1,30,WOODEN_SLAB:5,10,WOODEN_SLAB:1,10,DARK_OAK_STAIRS:0,5,DARK_OAK_STAIRS:1,5,DARK_OAK_STAIRS:2,5,DARK_OAK_STAIRS:3,5,SPRUCE_STAIRS:0,5,SPRUCE_STAIRS:1,5,SPRUCE_STAIRS:2,5,SPRUCE_STAIRS:3,5,WOOD:5,100)
RandomBlock(1,1,5,WOOD:5,70,WOOD:1,30,WOODEN_SLAB:5,10,WOODEN_SLAB:1,10,DARK_OAK_STAIRS:0,5,DARK_OAK_STAIRS:1,5,DARK_OAK_STAIRS:2,5,DARK_OAK_STAIRS:3,5,SPRUCE_STAIRS:0,5,SPRUCE_STAIRS:1,5,SPRUCE_STAIRS:2,5,SPRUCE_STAIRS:3,5,WOOD:5,100)
RandomBlock(1,1,6,WOOD:5,70,WOOD:1,30,WOODEN_SLAB:5,10,WOODEN_SLAB:1,10,DARK_OAK_STAIRS:0,5,DARK_OAK_STAIRS:1,5,DARK_OAK_STAIRS:2,5,DARK_OAK_STAIRS:3,5,SPRUCE_STAIRS:0,5,SPRUCE_STAIRS:1,5,SPRUCE_STAIRS:2,5,SPRUCE_STAIRS:3,5,WOOD:5,100)
RandomBlock(1,1,7,WOOD:5,70,WOOD:1,30,WOODEN_SLAB:5,10,WOODEN_SLAB:1,10,DARK_OAK_STAIRS:0,5,DARK_OAK_STAIRS:1,5,DARK_OAK_STAIRS:2,5,DARK_OAK_STAIRS:3,5,SPRUCE_STAIRS:0,5,SPRUCE_STAIRS:1,5,SPRUCE_STAIRS:2,5,SPRUCE_STAIRS:3,5,WOOD:5,100)
RandomBlock(1,1,8,WOOD:5,70,WOOD:1,30,WOODEN_SLAB:5,10,WOODEN_SLAB:1,10,DARK_OAK_STAIRS:0,5,DARK_OAK_STAIRS:1,5,DARK_OAK_STAIRS:2,5,DARK_OAK_STAIRS:3,5,SPRUCE_STAIRS:0,5,SPRUCE_STAIRS:1,5,SPRUCE_STAIRS:2,5,SPRUCE_STAIRS:3,5,WOOD:5,100)
RandomBlock(1,1,9,WOOD:5,70,WOOD:1,30,WOODEN_SLAB:5,10,WOODEN_SLAB:1,10,DARK_OAK_STAIRS:0,5,DARK_OAK_STAIRS:1,5,DARK_OAK_STAIRS:2,5,DARK_OAK_STAIRS:3,5,SPRUCE_STAIRS:0,5,SPRUCE_STAIRS:1,5,SPRUCE_STAIRS:2,5,SPRUCE_STAIRS:3,5,WOOD:5,100)
Block(1,2,-6,AIR:0)
Block(1,2,-5,AIR:0)
Block(1,2,-4,AIR:0)
Block(1,2,-3,AIR:0)
Block(1,2,-2,AIR:0)
Block(1,2,-1,AIR:0)
Block(1,2,0,AIR:0)
Block(1,2,1,AIR:0)
Block(1,2,2,LEVER:13)
Block(1,2,3,AIR:0)
Block(1,2,4,AIR:0)
Block(1,2,5,AIR:0)
Block(1,2,6,AIR:0)
Block(1,2,7,AIR:0)
Block(1,2,8,AIR:0)
Block(1,2,9,AIR:0)
Block(1,3,-6,AIR:0)
Block(1,3,-5,AIR:0)
Block(1,3,-4,AIR:0)
Block(1,3,-3,AIR:0)
Block(1,3,-2,AIR:0)
Block(1,3,-1,AIR:0)
Block(1,3,0,AIR:0)
Block(1,3,1,AIR:0)
Block(1,3,2,AIR:0)
Block(1,3,3,AIR:0)
Block(1,3,4,AIR:0)
Block(1,3,5,AIR:0)
Block(1,3,6,AIR:0)
Block(1,3,7,AIR:0)
Block(1,3,8,AIR:0)
Block(1,3,9,AIR:0)
Block(1,4,-6,WOOD:1)
Block(1,4,-5,AIR:0)
Block(1,4,-4,WOOD:1)
Block(1,4,-3,AIR:0)
Block(1,4,-2,AIR:0)
Block(1,4,-1,AIR:0)
Block(1,4,0,AIR:0)
Block(1,4,1,AIR:0)
Block(1,4,2,AIR:0)
Block(1,4,3,AIR:0)
Block(1,4,4,AIR:0)
Block(1,4,5,AIR:0)
Block(1,4,6,AIR:0)
Block(1,4,7,WOOD:1)
Block(1,4,8,AIR:0)
Block(1,4,9,WOOD:1)
Block(1,5,-6,AIR:0)
Block(1,5,-5,AIR:0)
Block(1,5,-4,WOOD:1)
Block(1,5,-3,SPRUCE_FENCE:0)
Block(1,5,-2,WOOD:1)
Block(1,5,-1,AIR:0)
Block(1,5,0,AIR:0)
Block(1,5,1,AIR:0)
Block(1,5,2,AIR:0)
Block(1,5,3,AIR:0)
Block(1,5,4,AIR:0)
Block(1,5,5,WOOD:1)
Block(1,5,6,SPRUCE_FENCE:0)
Block(1,5,7,WOOD:1)
Block(1,5,8,AIR:0)
Block(1,5,9,AIR:0)
RandomBlock(1,6,-6,WOOD:5,70,WOOD:1,30,WOODEN_SLAB:5,10,WOODEN_SLAB:1,10,DARK_OAK_STAIRS:0,5,DARK_OAK_STAIRS:1,5,DARK_OAK_STAIRS:2,5,DARK_OAK_STAIRS:3,5,SPRUCE_STAIRS:0,5,SPRUCE_STAIRS:1,5,SPRUCE_STAIRS:2,5,SPRUCE_STAIRS:3,5,WOOD:5,100)
RandomBlock(1,6,-5,WOOD:5,70,WOOD:1,30,WOODEN_SLAB:5,10,WOODEN_SLAB:1,10,DARK_OAK_STAIRS:0,5,DARK_OAK_STAIRS:1,5,DARK_OAK_STAIRS:2,5,DARK_OAK_STAIRS:3,5,SPRUCE_STAIRS:0,5,SPRUCE_STAIRS:1,5,SPRUCE_STAIRS:2,5,SPRUCE_STAIRS:3,5,WOOD:5,100)
RandomBlock(1,6,-4,WOOD:5,70,WOOD:1,30,WOODEN_SLAB:5,10,WOODEN_SLAB:1,10,DARK_OAK_STAIRS:0,5,DARK_OAK_STAIRS:1,5,DARK_OAK_STAIRS:2,5,DARK_OAK_STAIRS:3,5,SPRUCE_STAIRS:0,5,SPRUCE_STAIRS:1,5,SPRUCE_STAIRS:2,5,SPRUCE_STAIRS:3,5,WOOD:5,100)
Block(1,6,-3,SPRUCE_FENCE:0)
Block(1,6,-2,LADDER:3)
Block(1,6,-1,AIR:0)
Block(1,6,0,AIR:0)
Block(1,6,1,AIR:0)
Block(1,6,2,AIR:0)
Block(1,6,3,AIR:0)
Block(1,6,4,AIR:0)
Block(1,6,5,LADDER:2)
Block(1,6,6,SPRUCE_FENCE:0)
RandomBlock(1,6,7,WOOD:5,70,WOOD:1,30,WOODEN_SLAB:5,10,WOODEN_SLAB:1,10,DARK_OAK_STAIRS:0,5,DARK_OAK_STAIRS:1,5,DARK_OAK_STAIRS:2,5,DARK_OAK_STAIRS:3,5,SPRUCE_STAIRS:0,5,SPRUCE_STAIRS:1,5,SPRUCE_STAIRS:2,5,SPRUCE_STAIRS:3,5,WOOD:5,100)
RandomBlock(1,6,8,WOOD:5,70,WOOD:1,30,WOODEN_SLAB:5,10,WOODEN_SLAB:1,10,DARK_OAK_STAIRS:0,5,DARK_OAK_STAIRS:1,5,DARK_OAK_STAIRS:2,5,DARK_OAK_STAIRS:3,5,SPRUCE_STAIRS:0,5,SPRUCE_STAIRS:1,5,SPRUCE_STAIRS:2,5,SPRUCE_STAIRS:3,5,WOOD:5,100)
RandomBlock(1,6,9,WOOD:5,70,WOOD:1,30,WOODEN_SLAB:5,10,WOODEN_SLAB:1,10,DARK_OAK_STAIRS:0,5,DARK_OAK_STAIRS:1,5,DARK_OAK_STAIRS:2,5,DARK_OAK_STAIRS:3,5,SPRUCE_STAIRS:0,5,SPRUCE_STAIRS:1,5,SPRUCE_STAIRS:2,5,SPRUCE_STAIRS:3,5,WOOD:5,100)
Block(1,7,-6,AIR:0)
Block(1,7,-5,AIR:0)
Block(1,7,-4,SPRUCE_FENCE:0)
Block(1,7,-3,SPRUCE_FENCE:0)
Block(1,7,-2,LADDER:3)
Block(1,7,-1,AIR:0)
Block(1,7,0,AIR:0)
Block(1,7,1,AIR:0)
Block(1,7,2,AIR:0)
Block(1,7,3,AIR:0)
Block(1,7,4,AIR:0)
Block(1,7,5,LADDER:2)
Block(1,7,6,SPRUCE_FENCE:0)
Block(1,7,7,SPRUCE_FENCE:0)
Block(1,7,8,AIR:0)
Block(1,7,9,AIR:0)
Block(1,8,-6,AIR:0)
Block(1,8,-5,AIR:0)
Block(1,8,-4,SPRUCE_FENCE:0)
Block(1,8,-3,SPRUCE_FENCE:0)
Block(1,8,-2,LADDER:3)
Block(1,8,-1,WOOD:1)
Block(1,8,0,AIR:0)
Block(1,8,1,AIR:0)
Block(1,8,2,AIR:0)
Block(1,8,3,AIR:0)
Block(1,8,4,WOOD:1)
Block(1,8,5,LADDER:2)
Block(1,8,6,SPRUCE_FENCE:0)
Block(1,8,7,SPRUCE_FENCE:0)
Block(1,8,8,AIR:0)
Block(1,8,9,AIR:0)
Block(1,9,-6,WOOD:1)
Block(1,9,-5,AIR:0)
Block(1,9,-4,WOOD:1)
Block(1,9,-3,SPRUCE_FENCE:0)
Block(1,9,-2,LADDER:3)
Block(1,9,-1,AIR:0)
Block(1,9,0,AIR:0)
Block(1,9,1,AIR:0)
Block(1,9,2,AIR:0)
Block(1,9,3,AIR:0)
Block(1,9,4,AIR:0)
Block(1,9,5,LADDER:2)
Block(1,9,6,SPRUCE_FENCE:0)
Block(1,9,7,WOOD:1)
Block(1,9,8,AIR:0)
Block(1,9,9,WOOD:1)
Block(1,10,-6,AIR:0)
Block(1,10,-5,AIR:0)
Block(1,10,-4,WOOD:1)
Block(1,10,-3,SPRUCE_FENCE:0)
Block(1,10,-2,LADDER:3)
Block(1,10,-1,AIR:0)
Block(1,10,0,AIR:0)
Block(1,10,1,AIR:0)
Block(1,10,2,AIR:0)
Block(1,10,3,AIR:0)
Block(1,10,4,AIR:0)
Block(1,10,5,LADDER:2)
Block(1,10,6,SPRUCE_FENCE:0)
Block(1,10,7,WOOD:1)
Block(1,10,8,AIR:0)
Block(1,10,9,AIR:0)
RandomBlock(1,11,-6,WOOD:5,70,WOOD:1,30,WOODEN_SLAB:5,10,WOODEN_SLAB:1,10,DARK_OAK_STAIRS:0,5,DARK_OAK_STAIRS:1,5,DARK_OAK_STAIRS:2,5,DARK_OAK_STAIRS:3,5,SPRUCE_STAIRS:0,5,SPRUCE_STAIRS:1,5,SPRUCE_STAIRS:2,5,SPRUCE_STAIRS:3,5,WOOD:5,100)
RandomBlock(1,11,-5,WOOD:5,70,WOOD:1,30,WOODEN_SLAB:5,10,WOODEN_SLAB:1,10,DARK_OAK_STAIRS:0,5,DARK_OAK_STAIRS:1,5,DARK_OAK_STAIRS:2,5,DARK_OAK_STAIRS:3,5,SPRUCE_STAIRS:0,5,SPRUCE_STAIRS:1,5,SPRUCE_STAIRS:2,5,SPRUCE_STAIRS:3,5,WOOD:5,100)
RandomBlock(1,11,-4,WOOD:5,70,WOOD:1,30,WOODEN_SLAB:5,10,WOODEN_SLAB:1,10,DARK_OAK_STAIRS:0,5,DARK_OAK_STAIRS:1,5,DARK_OAK_STAIRS:2,5,DARK_OAK_STAIRS:3,5,SPRUCE_STAIRS:0,5,SPRUCE_STAIRS:1,5,SPRUCE_STAIRS:2,5,SPRUCE_STAIRS:3,5,WOOD:5,100)
Block(1,11,-3,SPRUCE_FENCE:0)
Block(1,11,-2,LADDER:3)
Block(1,11,-1,AIR:0)
Block(1,11,0,AIR:0)
Block(1,11,1,AIR:0)
Block(1,11,2,AIR:0)
Block(1,11,3,AIR:0)
Block(1,11,4,AIR:0)
Block(1,11,5,LADDER:2)
Block(1,11,6,SPRUCE_FENCE:0)
RandomBlock(1,11,7,WOOD:5,70,WOOD:1,30,WOODEN_SLAB:5,10,WOODEN_SLAB:1,10,DARK_OAK_STAIRS:0,5,DARK_OAK_STAIRS:1,5,DARK_OAK_STAIRS:2,5,DARK_OAK_STAIRS:3,5,SPRUCE_STAIRS:0,5,SPRUCE_STAIRS:1,5,SPRUCE_STAIRS:2,5,SPRUCE_STAIRS:3,5,WOOD:5,100)
RandomBlock(1,11,8,WOOD:5,70,WOOD:1,30,WOODEN_SLAB:5,10,WOODEN_SLAB:1,10,DARK_OAK_STAIRS:0,5,DARK_OAK_STAIRS:1,5,DARK_OAK_STAIRS:2,5,DARK_OAK_STAIRS:3,5,SPRUCE_STAIRS:0,5,SPRUCE_STAIRS:1,5,SPRUCE_STAIRS:2,5,SPRUCE_STAIRS:3,5,WOOD:5,100)
RandomBlock(1,11,9,WOOD:5,70,WOOD:1,30,WOODEN_SLAB:5,10,WOODEN_SLAB:1,10,DARK_OAK_STAIRS:0,5,DARK_OAK_STAIRS:1,5,DARK_OAK_STAIRS:2,5,DARK_OAK_STAIRS:3,5,SPRUCE_STAIRS:0,5,SPRUCE_STAIRS:1,5,SPRUCE_STAIRS:2,5,SPRUCE_STAIRS:3,5,WOOD:5,100)
Block(1,12,-6,AIR:0)
Block(1,12,-5,AIR:0)
Block(1,12,-4,SPRUCE_FENCE:0)
Block(1,12,-3,SPRUCE_FENCE:0)
Block(1,12,-2,LADDER:3)
Block(1,12,-1,AIR:0)
Block(1,12,0,AIR:0)
Block(1,12,1,AIR:0)
Block(1,12,2,AIR:0)
Block(1,12,3,AIR:0)
Block(1,12,4,AIR:0)
Block(1,12,5,LADDER:2)
Block(1,12,6,SPRUCE_FENCE:0)
Block(1,12,7,SPRUCE_FENCE:0)
Block(1,12,8,AIR:0)
Block(1,12,9,AIR:0)
Block(1,13,-6,AIR:0)
Block(1,13,-5,AIR:0)
Block(1,13,-4,SPRUCE_FENCE:0)
Block(1,13,-3,SPRUCE_FENCE:0)
Block(1,13,-2,LADDER:3)
Block(1,13,-1,AIR:0)
Block(1,13,0,AIR:0)
Block(1,13,1,AIR:0)
Block(1,13,2,AIR:0)
Block(1,13,3,AIR:0)
Block(1,13,4,AIR:0)
Block(1,13,5,LADDER:2)
Block(1,13,6,SPRUCE_FENCE:0)
Block(1,13,7,SPRUCE_FENCE:0)
Block(1,13,8,AIR:0)
Block(1,13,9,AIR:0)
Block(1,14,-6,WOOD:1)
Block(1,14,-5,AIR:0)
Block(1,14,-4,WOOD:1)
Block(1,14,-3,SPRUCE_FENCE:0)
Block(1,14,-2,LADDER:3)
Block(1,14,-1,AIR:0)
Block(1,14,0,AIR:0)
Block(1,14,1,AIR:0)
Block(1,14,2,AIR:0)
Block(1,14,3,AIR:0)
Block(1,14,4,AIR:0)
Block(1,14,5,LADDER:2)
Block(1,14,6,SPRUCE_FENCE:0)
Block(1,14,7,WOOD:1)
Block(1,14,8,AIR:0)
Block(1,14,9,WOOD:1)
Block(1,15,-6,AIR:0)
Block(1,15,-5,AIR:0)
Block(1,15,-4,WOOD:1)
Block(1,15,-3,SPRUCE_FENCE:0)
Block(1,15,-2,LADDER:3)
Block(1,15,-1,AIR:0)
Block(1,15,0,AIR:0)
Block(1,15,1,AIR:0)
Block(1,15,2,AIR:0)
Block(1,15,3,AIR:0)
Block(1,15,4,AIR:0)
Block(1,15,5,LADDER:2)
Block(1,15,6,SPRUCE_FENCE:0)
Block(1,15,7,WOOD:1)
Block(1,15,8,AIR:0)
Block(1,15,9,AIR:0)
RandomBlock(1,16,-6,WOOD:5,70,WOOD:1,30,WOODEN_SLAB:5,10,WOODEN_SLAB:1,10,DARK_OAK_STAIRS:0,5,DARK_OAK_STAIRS:1,5,DARK_OAK_STAIRS:2,5,DARK_OAK_STAIRS:3,5,SPRUCE_STAIRS:0,5,SPRUCE_STAIRS:1,5,SPRUCE_STAIRS:2,5,SPRUCE_STAIRS:3,5,WOOD:5,100)
RandomBlock(1,16,-5,WOOD:5,70,WOOD:1,30,WOODEN_SLAB:5,10,WOODEN_SLAB:1,10,DARK_OAK_STAIRS:0,5,DARK_OAK_STAIRS:1,5,DARK_OAK_STAIRS:2,5,DARK_OAK_STAIRS:3,5,SPRUCE_STAIRS:0,5,SPRUCE_STAIRS:1,5,SPRUCE_STAIRS:2,5,SPRUCE_STAIRS:3,5,WOOD:5,100)
RandomBlock(1,16,-4,WOOD:5,70,WOOD:1,30,WOODEN_SLAB:5,10,WOODEN_SLAB:1,10,DARK_OAK_STAIRS:0,5,DARK_OAK_STAIRS:1,5,DARK_OAK_STAIRS:2,5,DARK_OAK_STAIRS:3,5,SPRUCE_STAIRS:0,5,SPRUCE_STAIRS:1,5,SPRUCE_STAIRS:2,5,SPRUCE_STAIRS:3,5,WOOD:5,100)
Block(1,16,-3,SPRUCE_FENCE:0)
Block(1,16,-2,LADDER:3)
Block(1,16,-1,AIR:0)
Block(1,16,0,AIR:0)
Block(1,16,1,AIR:0)
Block(1,16,2,AIR:0)
Block(1,16,3,AIR:0)
Block(1,16,4,AIR:0)
Block(1,16,5,LADDER:2)
Block(1,16,6,SPRUCE_FENCE:0)
RandomBlock(1,16,7,WOOD:5,70,WOOD:1,30,WOODEN_SLAB:5,10,WOODEN_SLAB:1,10,DARK_OAK_STAIRS:0,5,DARK_OAK_STAIRS:1,5,DARK_OAK_STAIRS:2,5,DARK_OAK_STAIRS:3,5,SPRUCE_STAIRS:0,5,SPRUCE_STAIRS:1,5,SPRUCE_STAIRS:2,5,SPRUCE_STAIRS:3,5,WOOD:5,100)
RandomBlock(1,16,8,WOOD:5,70,WOOD:1,30,WOODEN_SLAB:5,10,WOODEN_SLAB:1,10,DARK_OAK_STAIRS:0,5,DARK_OAK_STAIRS:1,5,DARK_OAK_STAIRS:2,5,DARK_OAK_STAIRS:3,5,SPRUCE_STAIRS:0,5,SPRUCE_STAIRS:1,5,SPRUCE_STAIRS:2,5,SPRUCE_STAIRS:3,5,WOOD:5,100)
RandomBlock(1,16,9,WOOD:5,70,WOOD:1,30,WOODEN_SLAB:5,10,WOODEN_SLAB:1,10,DARK_OAK_STAIRS:0,5,DARK_OAK_STAIRS:1,5,DARK_OAK_STAIRS:2,5,DARK_OAK_STAIRS:3,5,SPRUCE_STAIRS:0,5,SPRUCE_STAIRS:1,5,SPRUCE_STAIRS:2,5,SPRUCE_STAIRS:3,5,WOOD:5,100)
Block(1,17,-6,AIR:0)
Block(1,17,-5,AIR:0)
Block(1,17,-4,SPRUCE_FENCE:0)
Block(1,17,-3,SPRUCE_FENCE:0)
Block(1,17,-2,LADDER:3)
Block(1,17,-1,AIR:0)
Block(1,17,0,AIR:0)
Block(1,17,1,AIR:0)
Block(1,17,2,AIR:0)
Block(1,17,3,AIR:0)
Block(1,17,4,AIR:0)
Block(1,17,5,LADDER:2)
Block(1,17,6,SPRUCE_FENCE:0)
Block(1,17,7,SPRUCE_FENCE:0)
Block(1,17,8,AIR:0)
Block(1,17,9,AIR:0)
Block(1,18,-6,AIR:0)
Block(1,18,-5,AIR:0)
Block(1,18,-4,SPRUCE_FENCE:0)
Block(1,18,-3,SPRUCE_FENCE:0)
Block(1,18,-2,LADDER:3)
Block(1,18,-1,AIR:0)
Block(1,18,0,AIR:0)
Block(1,18,1,AIR:0)
Block(1,18,2,AIR:0)
Block(1,18,3,AIR:0)
Block(1,18,4,AIR:0)
Block(1,18,5,LADDER:2)
Block(1,18,6,SPRUCE_FENCE:0)
Block(1,18,7,SPRUCE_FENCE:0)
Block(1,18,8,AIR:0)
Block(1,18,9,AIR:0)
Block(1,19,-6,WOOD:1)
Block(1,19,-5,AIR:0)
Block(1,19,-4,WOOD:1)
Block(1,19,-3,WOOD:1)
Block(1,19,-2,LADDER:3)
Block(1,19,-1,SPRUCE_FENCE:0)
Block(1,19,0,SPRUCE_FENCE:0)
Block(1,19,1,SPRUCE_FENCE:0)
Block(1,19,2,SPRUCE_FENCE:0)
Block(1,19,3,SPRUCE_FENCE:0)
Block(1,19,4,SPRUCE_FENCE:0)
Block(1,19,5,LADDER:2)
Block(1,19,6,WOOD:1)
Block(1,19,7,WOOD:1)
Block(1,19,8,AIR:0)
Block(1,19,9,WOOD:1)
Block(1,20,1,SPRUCE_FENCE:0)
Block(1,20,2,SPRUCE_FENCE:0)
Block(2,0,-6,LOG:1)
Block(2,0,-4,LOG:1)
Block(2,0,7,LOG:1)
Block(2,0,9,LOG:1)
RandomBlock(2,1,-6,WOOD:5,70,WOOD:1,30,WOODEN_SLAB:5,10,WOODEN_SLAB:1,10,DARK_OAK_STAIRS:0,5,DARK_OAK_STAIRS:1,5,DARK_OAK_STAIRS:2,5,DARK_OAK_STAIRS:3,5,SPRUCE_STAIRS:0,5,SPRUCE_STAIRS:1,5,SPRUCE_STAIRS:2,5,SPRUCE_STAIRS:3,5,WOOD:5,100)
RandomBlock(2,1,-5,WOOD:5,70,WOOD:1,30,WOODEN_SLAB:5,10,WOODEN_SLAB:1,10,DARK_OAK_STAIRS:0,5,DARK_OAK_STAIRS:1,5,DARK_OAK_STAIRS:2,5,DARK_OAK_STAIRS:3,5,SPRUCE_STAIRS:0,5,SPRUCE_STAIRS:1,5,SPRUCE_STAIRS:2,5,SPRUCE_STAIRS:3,5,WOOD:5,100)
RandomBlock(2,1,-4,WOOD:5,70,WOOD:1,30,WOODEN_SLAB:5,10,WOODEN_SLAB:1,10,DARK_OAK_STAIRS:0,5,DARK_OAK_STAIRS:1,5,DARK_OAK_STAIRS:2,5,DARK_OAK_STAIRS:3,5,SPRUCE_STAIRS:0,5,SPRUCE_STAIRS:1,5,SPRUCE_STAIRS:2,5,SPRUCE_STAIRS:3,5,WOOD:5,100)
RandomBlock(2,1,-3,WOOD:5,70,WOOD:1,30,WOODEN_SLAB:5,10,WOODEN_SLAB:1,10,DARK_OAK_STAIRS:0,5,DARK_OAK_STAIRS:1,5,DARK_OAK_STAIRS:2,5,DARK_OAK_STAIRS:3,5,SPRUCE_STAIRS:0,5,SPRUCE_STAIRS:1,5,SPRUCE_STAIRS:2,5,SPRUCE_STAIRS:3,5,WOOD:5,100)
RandomBlock(2,1,-2,WOOD:5,70,WOOD:1,30,WOODEN_SLAB:5,10,WOODEN_SLAB:1,10,DARK_OAK_STAIRS:0,5,DARK_OAK_STAIRS:1,5,DARK_OAK_STAIRS:2,5,DARK_OAK_STAIRS:3,5,SPRUCE_STAIRS:0,5,SPRUCE_STAIRS:1,5,SPRUCE_STAIRS:2,5,SPRUCE_STAIRS:3,5,WOOD:5,100)
RandomBlock(2,1,-1,WOOD:5,70,WOOD:1,30,WOODEN_SLAB:5,10,WOODEN_SLAB:1,10,DARK_OAK_STAIRS:0,5,DARK_OAK_STAIRS:1,5,DARK_OAK_STAIRS:2,5,DARK_OAK_STAIRS:3,5,SPRUCE_STAIRS:0,5,SPRUCE_STAIRS:1,5,SPRUCE_STAIRS:2,5,SPRUCE_STAIRS:3,5,WOOD:5,100)
RandomBlock(2,1,0,WOOD:5,70,WOOD:1,30,WOODEN_SLAB:5,10,WOODEN_SLAB:1,10,DARK_OAK_STAIRS:0,5,DARK_OAK_STAIRS:1,5,DARK_OAK_STAIRS:2,5,DARK_OAK_STAIRS:3,5,SPRUCE_STAIRS:0,5,SPRUCE_STAIRS:1,5,SPRUCE_STAIRS:2,5,SPRUCE_STAIRS:3,5,WOOD:5,100)
RandomBlock(2,1,1,WOOD:5,70,WOOD:1,30,WOODEN_SLAB:5,10,WOODEN_SLAB:1,10,DARK_OAK_STAIRS:0,5,DARK_OAK_STAIRS:1,5,DARK_OAK_STAIRS:2,5,DARK_OAK_STAIRS:3,5,SPRUCE_STAIRS:0,5,SPRUCE_STAIRS:1,5,SPRUCE_STAIRS:2,5,SPRUCE_STAIRS:3,5,WOOD:5,100)
