Author: NLBlackEagle
Description: No description given
SettingsMode: WriteDisable
Frequency: 0
SpawnHeight: highestBlock
UseCenterForHighestBlock: true
MinHeight: 0
MaxHeight: 255
InheritBO3: 
InheritBO3Rotation: NORTH
OverrideChildSettings: true
OverrideParentHeight: false
CanOverride: false
BranchFrequency: 0
BranchFrequencyGroup: 
MustBeBelowOther: false
MustBeInside: 
CannotBeInside: 
ReplacesBO3: 
MustBeInsideWorldBorders: false
CanSpawnOnWater: true
SpawnOnWaterOnly: false
SpawnUnderWater: false
SpawnAtWaterLevel: false
HeightOffset: 0
RemoveAir: true
ReplaceAbove: 
ReplaceBelow: 
ReplaceWithBiomeBlocks: true
ReplaceWithSurfaceBlock: GRASS
ReplaceWithGroundBlock: DIRT
ReplaceWithStoneBlock: STONE
SmoothRadius: 0
SmoothHeightOffset: 0
SmoothStartTop: false
SmoothStartWood: false
SmoothingSurfaceBlock: 
SmoothingGroundBlock: 
BO3Group: 
IsSpawnPoint: false
DoReplaceBlocks: true
RandomBlock(-8,0,-7,COBBLESTONE:0,60,MOSSY_COBBLESTONE:0,5,SMOOTH_BRICK:0,10,SMOOTH_BRICK:1,10,SMOOTH_BRICK:2,10,COBBLESTONE:0,100)
RandomBlock(-8,0,-6,COBBLESTONE:0,60,MOSSY_COBBLESTONE:0,5,SMOOTH_BRICK:0,10,SMOOTH_BRICK:1,10,SMOOTH_BRICK:2,10,COBBLESTONE:0,100)
RandomBlock(-8,0,-5,COBBLESTONE:0,60,MOSSY_COBBLESTONE:0,5,SMOOTH_BRICK:0,10,SMOOTH_BRICK:1,10,SMOOTH_BRICK:2,10,COBBLESTONE:0,100)
RandomBlock(-8,0,-4,COBBLESTONE:0,60,MOSSY_COBBLESTONE:0,5,SMOOTH_BRICK:0,10,SMOOTH_BRICK:1,10,SMOOTH_BRICK:2,10,COBBLESTONE:0,100)
Block(-8,0,-3,MAGMA:0)
RandomBlock(-8,0,-2,COBBLESTONE:0,60,MOSSY_COBBLESTONE:0,5,SMOOTH_BRICK:0,10,SMOOTH_BRICK:1,10,SMOOTH_BRICK:2,10,COBBLESTONE:0,100)
RandomBlock(-8,0,-1,COBBLESTONE:0,60,MOSSY_COBBLESTONE:0,5,SMOOTH_BRICK:0,10,SMOOTH_BRICK:1,10,SMOOTH_BRICK:2,10,COBBLESTONE:0,100)
RandomBlock(-8,0,0,COBBLESTONE:0,60,MOSSY_COBBLESTONE:0,5,SMOOTH_BRICK:0,10,SMOOTH_BRICK:1,10,SMOOTH_BRICK:2,10,COBBLESTONE:0,100)
RandomBlock(-8,0,1,COBBLESTONE:0,60,MOSSY_COBBLESTONE:0,5,SMOOTH_BRICK:0,10,SMOOTH_BRICK:1,10,SMOOTH_BRICK:2,10,COBBLESTONE:0,100)
Block(-8,0,2,DIRT:0)
Block(-8,0,3,DIRT:0)
Block(-8,0,4,DIRT:0)
Block(-8,0,5,DIRT:0)
Block(-8,0,6,DIRT:0)
Block(-8,0,7,DIRT:0)
Block(-8,0,8,DIRT:0)
RandomBlock(-8,1,-7,COBBLESTONE:0,60,MOSSY_COBBLESTONE:0,5,SMOOTH_BRICK:0,10,SMOOTH_BRICK:1,10,SMOOTH_BRICK:2,10,COBBLESTONE:0,100)
RandomBlock(-8,1,-6,COBBLESTONE:0,60,MOSSY_COBBLESTONE:0,5,SMOOTH_BRICK:0,10,SMOOTH_BRICK:1,10,SMOOTH_BRICK:2,10,COBBLESTONE:0,100)
RandomBlock(-8,1,-5,COBBLESTONE:0,60,MOSSY_COBBLESTONE:0,5,SMOOTH_BRICK:0,10,SMOOTH_BRICK:1,10,SMOOTH_BRICK:2,10,COBBLESTONE:0,100)
RandomBlock(-8,1,-4,COBBLESTONE:0,60,MOSSY_COBBLESTONE:0,5,SMOOTH_BRICK:0,10,SMOOTH_BRICK:1,10,SMOOTH_BRICK:2,10,COBBLESTONE:0,100)
Block(-8,1,-3,FIRE:0)
RandomBlock(-8,1,-2,COBBLESTONE:0,60,MOSSY_COBBLESTONE:0,5,SMOOTH_BRICK:0,10,SMOOTH_BRICK:1,10,SMOOTH_BRICK:2,10,COBBLESTONE:0,100)
RandomBlock(-8,1,-1,COBBLESTONE:0,60,MOSSY_COBBLESTONE:0,5,SMOOTH_BRICK:0,10,SMOOTH_BRICK:1,10,SMOOTH_BRICK:2,10,COBBLESTONE:0,100)
RandomBlock(-8,1,0,COBBLESTONE:0,60,MOSSY_COBBLESTONE:0,5,SMOOTH_BRICK:0,10,SMOOTH_BRICK:1,10,SMOOTH_BRICK:2,10,COBBLESTONE:0,100)
RandomBlock(-8,1,1,COBBLESTONE:0,60,MOSSY_COBBLESTONE:0,5,SMOOTH_BRICK:0,10,SMOOTH_BRICK:1,10,SMOOTH_BRICK:2,10,COBBLESTONE:0,100)
Block(-8,1,2,DIRT:0)
Block(-8,1,3,DIRT:0)
Block(-8,1,4,DIRT:0)
Block(-8,1,5,GRASS:0)
Block(-8,1,6,GRASS:0)
Block(-8,1,7,DIRT:0)
Block(-8,1,8,DIRT:0)
RandomBlock(-8,2,-7,COBBLESTONE:0,60,MOSSY_COBBLESTONE:0,5,SMOOTH_BRICK:0,10,SMOOTH_BRICK:1,10,SMOOTH_BRICK:2,10,COBBLESTONE:0,100)
RandomBlock(-8,2,-6,WOOD_STEP:9,70,WOOD_STEP:13,100)
RandomBlock(-8,2,-5,WOOD_STEP:9,70,WOOD_STEP:13,100)
RandomBlock(-8,2,-4,COBBLESTONE:0,60,MOSSY_COBBLESTONE:0,5,SMOOTH_BRICK:0,10,SMOOTH_BRICK:1,10,SMOOTH_BRICK:2,10,COBBLESTONE:0,100)
RandomBlock(-8,2,-2,COBBLESTONE:0,60,MOSSY_COBBLESTONE:0,5,SMOOTH_BRICK:0,10,SMOOTH_BRICK:1,10,SMOOTH_BRICK:2,10,COBBLESTONE:0,100)
RandomBlock(-8,2,-1,WOOD_STEP:9,70,WOOD_STEP:13,100)
RandomBlock(-8,2,0,WOOD_STEP:9,70,WOOD_STEP:13,100)
RandomBlock(-8,2,1,COBBLESTONE:0,60,MOSSY_COBBLESTONE:0,5,SMOOTH_BRICK:0,10,SMOOTH_BRICK:1,10,SMOOTH_BRICK:2,10,COBBLESTONE:0,100)
Block(-8,2,2,GRASS:0)
Block(-8,2,3,GRASS:0)
Block(-8,2,4,GRASS:0)
Block(-8,2,5,GRASS_PATH:0)
Block(-8,2,6,GRASS_PATH:0)
Block(-8,2,7,GRASS:0)
Block(-8,2,8,GRASS:0)
Block(-8,3,-6,SPRUCE_DOOR:3)
Block(-8,3,-4,COBBLESTONE_STAIRS:2)
Block(-8,3,-3,IRON_FENCE:0)
Block(-8,3,-2,COBBLESTONE_STAIRS:3)
Block(-8,3,0,WORKBENCH:0)
RandomBlock(-8,3,1,COBBLESTONE:0,60,MOSSY_COBBLESTONE:0,5,SMOOTH_BRICK:0,10,SMOOTH_BRICK:1,10,SMOOTH_BRICK:2,10,COBBLESTONE:0,100)
Block(-8,3,2,WALL_SIGN:3)
Block(-8,3,3,FLOWER_POT:0)
Block(-8,4,-6,SPRUCE_DOOR:8)
RandomBlock(-8,4,1,SPRUCE_WOOD_STAIRS:3,70,DARK_OAK_STAIRS:3,100)
RandomBlock(-8,5,-7,WOOD_STEP:1,70,WOOD_STEP:5,100)
RandomBlock(-8,5,-6,SPRUCE_WOOD_STAIRS:2,70,DARK_OAK_STAIRS:2,100)
RandomBlock(-8,5,0,SPRUCE_WOOD_STAIRS:3,70,DARK_OAK_STAIRS:3,100)
Block(-8,6,-7,WEB:0)
Block(-8,6,-6,WEB:0)
RandomBlock(-8,6,-5,SPRUCE_WOOD_STAIRS:2,70,DARK_OAK_STAIRS:2,100)
RandomBlock(-8,6,-1,SPRUCE_WOOD_STAIRS:3,70,DARK_OAK_STAIRS:3,100)
RandomBlock(-8,7,-7,WOOD_STEP:1,70,WOOD_STEP:5,100)
RandomBlock(-8,7,-6,WOOD_STEP:1,70,WOOD_STEP:5,100)
Block(-8,7,-5,TRAP_DOOR:12)
Block(-8,7,-1,TRAP_DOOR:13)
RandomBlock(-8,8,-4,SPRUCE_WOOD_STAIRS:2,70,DARK_OAK_STAIRS:2,100)
Block(-8,8,-3,LOG:5)
RandomBlock(-8,8,-2,SPRUCE_WOOD_STAIRS:3,70,DARK_OAK_STAIRS:3,100)
RandomBlock(-8,9,-3,WOOD_STEP:1,70,WOOD_STEP:5,100)
RandomBlock(-7,0,-7,COBBLESTONE:0,60,MOSSY_COBBLESTONE:0,5,SMOOTH_BRICK:0,10,SMOOTH_BRICK:1,10,SMOOTH_BRICK:2,10,COBBLESTONE:0,100)
RandomBlock(-7,0,-6,COBBLESTONE:0,60,MOSSY_COBBLESTONE:0,5,SMOOTH_BRICK:0,10,SMOOTH_BRICK:1,10,SMOOTH_BRICK:2,10,COBBLESTONE:0,100)
RandomBlock(-7,0,-5,COBBLESTONE:0,60,MOSSY_COBBLESTONE:0,5,SMOOTH_BRICK:0,10,SMOOTH_BRICK:1,10,SMOOTH_BRICK:2,10,COBBLESTONE:0,100)
RandomBlock(-7,0,-4,COBBLESTONE:0,60,MOSSY_COBBLESTONE:0,5,SMOOTH_BRICK:0,10,SMOOTH_BRICK:1,10,SMOOTH_BRICK:2,10,COBBLESTONE:0,100)
RandomBlock(-7,0,-3,COBBLESTONE:0,60,MOSSY_COBBLESTONE:0,5,SMOOTH_BRICK:0,10,SMOOTH_BRICK:1,10,SMOOTH_BRICK:2,10,COBBLESTONE:0,100)
RandomBlock(-7,0,-2,COBBLESTONE:0,60,MOSSY_COBBLESTONE:0,5,SMOOTH_BRICK:0,10,SMOOTH_BRICK:1,10,SMOOTH_BRICK:2,10,COBBLESTONE:0,100)
RandomBlock(-7,0,-1,COBBLESTONE:0,60,MOSSY_COBBLESTONE:0,5,SMOOTH_BRICK:0,10,SMOOTH_BRICK:1,10,SMOOTH_BRICK:2,10,COBBLESTONE:0,100)
RandomBlock(-7,0,0,COBBLESTONE:0,60,MOSSY_COBBLESTONE:0,5,SMOOTH_BRICK:0,10,SMOOTH_BRICK:1,10,SMOOTH_BRICK:2,10,COBBLESTONE:0,100)
RandomBlock(-7,0,1,COBBLESTONE:0,60,MOSSY_COBBLESTONE:0,5,SMOOTH_BRICK:0,10,SMOOTH_BRICK:1,10,SMOOTH_BRICK:2,10,COBBLESTONE:0,100)
Block(-7,0,2,DIRT:0)
Block(-7,0,3,DIRT:0)
Block(-7,0,4,DIRT:0)
Block(-7,0,5,DIRT:0)
Block(-7,0,6,DIRT:0)
Block(-7,0,7,DIRT:0)
Block(-7,0,8,DIRT:0)
RandomBlock(-7,1,-7,COBBLESTONE:0,60,MOSSY_COBBLESTONE:0,5,SMOOTH_BRICK:0,10,SMOOTH_BRICK:1,10,SMOOTH_BRICK:2,10,COBBLESTONE:0,100)
RandomBlock(-7,1,-6,COBBLESTONE:0,60,MOSSY_COBBLESTONE:0,5,SMOOTH_BRICK:0,10,SMOOTH_BRICK:1,10,SMOOTH_BRICK:2,10,COBBLESTONE:0,100)
RandomBlock(-7,1,-5,COBBLESTONE:0,60,MOSSY_COBBLESTONE:0,5,SMOOTH_BRICK:0,10,SMOOTH_BRICK:1,10,SMOOTH_BRICK:2,10,COBBLESTONE:0,100)
RandomBlock(-7,1,-4,COBBLESTONE:0,60,MOSSY_COBBLESTONE:0,5,SMOOTH_BRICK:0,10,SMOOTH_BRICK:1,10,SMOOTH_BRICK:2,10,COBBLESTONE:0,100)
RandomBlock(-7,1,-3,COBBLESTONE:0,60,MOSSY_COBBLESTONE:0,5,SMOOTH_BRICK:0,10,SMOOTH_BRICK:1,10,SMOOTH_BRICK:2,10,COBBLESTONE:0,100)
RandomBlock(-7,1,-2,COBBLESTONE:0,60,MOSSY_COBBLESTONE:0,5,SMOOTH_BRICK:0,10,SMOOTH_BRICK:1,10,SMOOTH_BRICK:2,10,COBBLESTONE:0,100)
RandomBlock(-7,1,-1,COBBLESTONE:0,60,MOSSY_COBBLESTONE:0,5,SMOOTH_BRICK:0,10,SMOOTH_BRICK:1,10,SMOOTH_BRICK:2,10,COBBLESTONE:0,100)
RandomBlock(-7,1,0,COBBLESTONE:0,60,MOSSY_COBBLESTONE:0,5,SMOOTH_BRICK:0,10,SMOOTH_BRICK:1,10,SMOOTH_BRICK:2,10,COBBLESTONE:0,100)
RandomBlock(-7,1,1,COBBLESTONE:0,60,MOSSY_COBBLESTONE:0,5,SMOOTH_BRICK:0,10,SMOOTH_BRICK:1,10,SMOOTH_BRICK:2,10,COBBLESTONE:0,100)
Block(-7,1,2,DIRT:0)
Block(-7,1,3,DIRT:0)
Block(-7,1,4,DIRT:0)
Block(-7,1,5,GRASS:0)
Block(-7,1,6,GRASS:0)
Block(-7,1,7,DIRT:0)
Block(-7,1,8,DIRT:0)
RandomBlock(-7,2,-7,COBBLESTONE:0,60,MOSSY_COBBLESTONE:0,5,SMOOTH_BRICK:0,10,SMOOTH_BRICK:1,10,SMOOTH_BRICK:2,10,COBBLESTONE:0,100)
RandomBlock(-7,2,-6,WOOD_STEP:9,70,WOOD_STEP:13,100)
RandomBlock(-7,2,-5,WOOD_STEP:9,70,WOOD_STEP:13,100)
Block(-7,2,-4,COBBLESTONE_STAIRS:3)
Block(-7,2,-3,COBBLESTONE_STAIRS:0)
Block(-7,2,-2,COBBLESTONE_STAIRS:2)
RandomBlock(-7,2,-1,WOOD_STEP:9,70,WOOD_STEP:13,100)
RandomBlock(-7,2,0,WOOD_STEP:9,70,WOOD_STEP:13,100)
RandomBlock(-7,2,1,COBBLESTONE:0,60,MOSSY_COBBLESTONE:0,5,SMOOTH_BRICK:0,10,SMOOTH_BRICK:1,10,SMOOTH_BRICK:2,10,COBBLESTONE:0,100)
Block(-7,2,2,GRASS:0)
Block(-7,2,3,GRASS:0)
Block(-7,2,4,GRASS:0)
Block(-7,2,5,GRASS_PATH:0)
Block(-7,2,6,GRASS_PATH:0)
Block(-7,2,7,GRASS:0)
Block(-7,2,8,GRASS:0)
RandomBlock(-7,3,-7,COBBLESTONE:0,60,MOSSY_COBBLESTONE:0,5,SMOOTH_BRICK:0,10,SMOOTH_BRICK:1,10,SMOOTH_BRICK:2,10,COBBLESTONE:0,100)
Block(-7,3,-6,WOOD:1)
Block(-7,3,0,WOOD_STEP:13)
RandomBlock(-7,3,1,COBBLESTONE:0,60,MOSSY_COBBLESTONE:0,5,SMOOTH_BRICK:0,10,SMOOTH_BRICK:1,10,SMOOTH_BRICK:2,10,COBBLESTONE:0,100)
Block(-7,3,2,WALL_SIGN:3)
Block(-7,3,7,WOOD_STEP:5)
RandomBlock(-7,4,-7,SPRUCE_WOOD_STAIRS:1,70,DARK_OAK_STAIRS:1,100)
Block(-7,4,-6,WOOD:1)
RandomBlock(-7,4,-5,WALL_BANNER:3,../../NBT/Banners/viking_regular_1.nbt,20,WALL_BANNER:3,../../NBT/Banners/viking_regular_2.nbt,20,WALL_BANNER:3,../../NBT/Banners/viking_regular_3.nbt,20,WALL_BANNER:3,../../NBT/Banners/viking_regular_4.nbt,20,WALL_BANNER:3,../../NBT/Banners/viking_regular_5.nbt,20,WALL_BANNER:3,../../NBT/Banners/viking_regular_6.nbt,20,WALL_BANNER:3,../../NBT/Banners/viking_regular_7.nbt,20,WALL_BANNER:3,../../NBT/Banners/viking_regular_8.nbt,100)
RandomBlock(-7,4,1,SPRUCE_WOOD_STAIRS:3,70,DARK_OAK_STAIRS:3,100)
RandomBlock(-7,5,-7,WOOD_STEP:1,70,WOOD_STEP:5,100)
RandomBlock(-7,5,-6,SPRUCE_WOOD_STAIRS:2,70,DARK_OAK_STAIRS:2,100)
RandomBlock(-7,5,-5,WALL_BANNER:3,../../NBT/Banners/viking_regular_1.nbt,20,WALL_BANNER:3,../../NBT/Banners/viking_regular_2.nbt,20,WALL_BANNER:3,../../NBT/Banners/viking_regular_3.nbt,20,WALL_BANNER:3,../../NBT/Banners/viking_regular_4.nbt,20,WALL_BANNER:3,../../NBT/Banners/viking_regular_5.nbt,20,WALL_BANNER:3,../../NBT/Banners/viking_regular_6.nbt,20,WALL_BANNER:3,../../NBT/Banners/viking_regular_7.nbt,20,WALL_BANNER:3,../../NBT/Banners/viking_regular_8.nbt,100)
RandomBlock(-7,5,0,SPRUCE_WOOD_STAIRS:3,70,DARK_OAK_STAIRS:3,100)
Block(-7,6,-7,WEB:0)
Block(-7,6,-6,WEB:0)
RandomBlock(-7,6,-5,SPRUCE_WOOD_STAIRS:2,70,DARK_OAK_STAIRS:2,100)
RandomBlock(-7,6,-1,SPRUCE_WOOD_STAIRS:3,70,DARK_OAK_STAIRS:3,100)
RandomBlock(-7,7,-7,WOOD_STEP:1,70,WOOD_STEP:5,100)
RandomBlock(-7,7,-6,WOOD_STEP:1,70,WOOD_STEP:5,100)
Block(-7,7,-5,TRAP_DOOR:12)
Block(-7,7,-1,TRAP_DOOR:13)
RandomBlock(-7,8,-4,SPRUCE_WOOD_STAIRS:2,70,DARK_OAK_STAIRS:2,100)
Block(-7,8,-3,LOG:5)
RandomBlock(-7,8,-2,SPRUCE_WOOD_STAIRS:3,70,DARK_OAK_STAIRS:3,100)
RandomBlock(-7,9,-3,WOOD_STEP:1,70,WOOD_STEP:5,100)
RandomBlock(-6,0,-7,COBBLESTONE:0,60,MOSSY_COBBLESTONE:0,5,SMOOTH_BRICK:0,10,SMOOTH_BRICK:1,10,SMOOTH_BRICK:2,10,COBBLESTONE:0,100)
RandomBlock(-6,0,-6,COBBLESTONE:0,60,MOSSY_COBBLESTONE:0,5,SMOOTH_BRICK:0,10,SMOOTH_BRICK:1,10,SMOOTH_BRICK:2,10,COBBLESTONE:0,100)
RandomBlock(-6,0,-5,COBBLESTONE:0,60,MOSSY_COBBLESTONE:0,5,SMOOTH_BRICK:0,10,SMOOTH_BRICK:1,10,SMOOTH_BRICK:2,10,COBBLESTONE:0,100)
RandomBlock(-6,0,-4,COBBLESTONE:0,60,MOSSY_COBBLESTONE:0,5,SMOOTH_BRICK:0,10,SMOOTH_BRICK:1,10,SMOOTH_BRICK:2,10,COBBLESTONE:0,100)
RandomBlock(-6,0,-3,COBBLESTONE:0,60,MOSSY_COBBLESTONE:0,5,SMOOTH_BRICK:0,10,SMOOTH_BRICK:1,10,SMOOTH_BRICK:2,10,COBBLESTONE:0,100)
RandomBlock(-6,0,-2,COBBLESTONE:0,60,MOSSY_COBBLESTONE:0,5,SMOOTH_BRICK:0,10,SMOOTH_BRICK:1,10,SMOOTH_BRICK:2,10,COBBLESTONE:0,100)
RandomBlock(-6,0,-1,COBBLESTONE:0,60,MOSSY_COBBLESTONE:0,5,SMOOTH_BRICK:0,10,SMOOTH_BRICK:1,10,SMOOTH_BRICK:2,10,COBBLESTONE:0,100)
RandomBlock(-6,0,0,COBBLESTONE:0,60,MOSSY_COBBLESTONE:0,5,SMOOTH_BRICK:0,10,SMOOTH_BRICK:1,10,SMOOTH_BRICK:2,10,COBBLESTONE:0,100)
RandomBlock(-6,0,1,COBBLESTONE:0,60,MOSSY_COBBLESTONE:0,5,SMOOTH_BRICK:0,10,SMOOTH_BRICK:1,10,SMOOTH_BRICK:2,10,COBBLESTONE:0,100)
Block(-6,0,2,DIRT:0)
RandomBlock(-6,0,3,COBBLESTONE:0,60,MOSSY_COBBLESTONE:0,5,SMOOTH_BRICK:0,10,SMOOTH_BRICK:1,10,SMOOTH_BRICK:2,10,COBBLESTONE:0,100)
Block(-6,0,4,DIRT:0)
Block(-6,0,5,DIRT:0)
Block(-6,0,6,DIRT:0)
Block(-6,0,7,DIRT:0)
Block(-6,0,8,DIRT:0)
RandomBlock(-6,1,-7,COBBLESTONE:0,60,MOSSY_COBBLESTONE:0,5,SMOOTH_BRICK:0,10,SMOOTH_BRICK:1,10,SMOOTH_BRICK:2,10,COBBLESTONE:0,100)
RandomBlock(-6,1,-6,COBBLESTONE:0,60,MOSSY_COBBLESTONE:0,5,SMOOTH_BRICK:0,10,SMOOTH_BRICK:1,10,SMOOTH_BRICK:2,10,COBBLESTONE:0,100)
RandomBlock(-6,1,-5,COBBLESTONE:0,60,MOSSY_COBBLESTONE:0,5,SMOOTH_BRICK:0,10,SMOOTH_BRICK:1,10,SMOOTH_BRICK:2,10,COBBLESTONE:0,100)
RandomBlock(-6,1,-4,COBBLESTONE:0,60,MOSSY_COBBLESTONE:0,5,SMOOTH_BRICK:0,10,SMOOTH_BRICK:1,10,SMOOTH_BRICK:2,10,COBBLESTONE:0,100)
RandomBlock(-6,1,-3,COBBLESTONE:0,60,MOSSY_COBBLESTONE:0,5,SMOOTH_BRICK:0,10,SMOOTH_BRICK:1,10,SMOOTH_BRICK:2,10,COBBLESTONE:0,100)
RandomBlock(-6,1,-2,COBBLESTONE:0,60,MOSSY_COBBLESTONE:0,5,SMOOTH_BRICK:0,10,SMOOTH_BRICK:1,10,SMOOTH_BRICK:2,10,COBBLESTONE:0,100)
RandomBlock(-6,1,-1,COBBLESTONE:0,60,MOSSY_COBBLESTONE:0,5,SMOOTH_BRICK:0,10,SMOOTH_BRICK:1,10,SMOOTH_BRICK:2,10,COBBLESTONE:0,100)
RandomBlock(-6,1,0,COBBLESTONE:0,60,MOSSY_COBBLESTONE:0,5,SMOOTH_BRICK:0,10,SMOOTH_BRICK:1,10,SMOOTH_BRICK:2,10,COBBLESTONE:0,100)
RandomBlock(-6,1,1,COBBLESTONE:0,60,MOSSY_COBBLESTONE:0,5,SMOOTH_BRICK:0,10,SMOOTH_BRICK:1,10,SMOOTH_BRICK:2,10,COBBLESTONE:0,100)
Block(-6,1,2,DIRT:0)
RandomBlock(-6,1,3,COBBLESTONE:0,60,MOSSY_COBBLESTONE:0,5,SMOOTH_BRICK:0,10,SMOOTH_BRICK:1,10,SMOOTH_BRICK:2,10,COBBLESTONE:0,100)
Block(-6,1,4,DIRT:0)
Block(-6,1,5,GRASS:0)
Block(-6,1,6,GRASS:0)
Block(-6,1,7,DIRT:0)
Block(-6,1,8,DIRT:0)
RandomBlock(-6,2,-7,COBBLESTONE:0,60,MOSSY_COBBLESTONE:0,5,SMOOTH_BRICK:0,10,SMOOTH_BRICK:1,10,SMOOTH_BRICK:2,10,COBBLESTONE:0,100)
RandomBlock(-6,2,-6,WOOD_STEP:9,70,WOOD_STEP:13,100)
RandomBlock(-6,2,-5,WOOD_STEP:9,70,WOOD_STEP:13,100)
RandomBlock(-6,2,-4,WOOD_STEP:9,70,WOOD_STEP:13,100)
RandomBlock(-6,2,-3,WOOD_STEP:9,70,WOOD_STEP:13,100)
RandomBlock(-6,2,-2,WOOD_STEP:9,70,WOOD_STEP:13,100)
RandomBlock(-6,2,-1,WOOD_STEP:9,70,WOOD_STEP:13,100)
RandomBlock(-6,2,0,WOOD_STEP:9,70,WOOD_STEP:13,100)
RandomBlock(-6,2,1,COBBLESTONE:0,60,MOSSY_COBBLESTONE:0,5,SMOOTH_BRICK:0,10,SMOOTH_BRICK:1,10,SMOOTH_BRICK:2,10,COBBLESTONE:0,100)
Block(-6,2,2,GRASS:0)
RandomBlock(-6,2,3,COBBLESTONE:0,60,MOSSY_COBBLESTONE:0,5,SMOOTH_BRICK:0,10,SMOOTH_BRICK:1,10,SMOOTH_BRICK:2,10,COBBLESTONE:0,100)
RandomBlock(-6,2,4,COBBLESTONE:0,60,MOSSY_COBBLESTONE:0,5,SMOOTH_BRICK:0,10,SMOOTH_BRICK:1,10,SMOOTH_BRICK:2,10,COBBLESTONE:0,100)
Block(-6,2,5,GRASS_PATH:0)
Block(-6,2,6,GRASS_PATH:0)
Block(-6,2,7,GRASS:0)
Block(-6,2,8,GRASS:0)
RandomBlock(-6,3,-7,COBBLESTONE:0,60,MOSSY_COBBLESTONE:0,5,SMOOTH_BRICK:0,10,SMOOTH_BRICK:1,10,SMOOTH_BRICK:2,10,COBBLESTONE:0,100)
Block(-6,3,-6,WOOD_STEP:13)
Block(-6,3,-5,CARPET:13)
Block(-6,3,-2,AIR:0)
Block(-6,3,-1,CARPET:13)
Block(-6,3,0,CAULDRON:3)
RandomBlock(-6,3,1,COBBLESTONE:0,60,MOSSY_COBBLESTONE:0,5,SMOOTH_BRICK:0,10,SMOOTH_BRICK:1,10,SMOOTH_BRICK:2,10,COBBLESTONE:0,100)
Block(-6,3,2,SPRUCE_WOOD_STAIRS:6)
RandomBlock(-6,3,3,SPRUCE_WOOD_STAIRS:3,70,DARK_OAK_STAIRS:3,100)
Block(-6,3,7,WOOD_STEP:5)
Block(-6,4,-7,SPRUCE_WOOD_STAIRS:7)
RandomBlock(-6,4,-6,AIR:0,20,CHEST:3,../../../../Chests/Loot/JunkChest_1.nbt,10,CHEST:3,../../../../Chests/Loot/JunkChest_2.nbt,10,CHEST:3,../../../../Chests/Loot/JunkChest_3.nbt,10,CHEST:3,../../../../Chests/Loot/JunkChest_4.nbt,10,CHEST:3,../../../../Chests/Loot/JunkChest_5.nbt,10,CHEST:3,../../../../Chests/Lore/Viking_1.nbt,1,CHEST:3,../../../../Chests/Lore/Viking_2.nbt,1,CHEST:3,../../../../Chests/Lore/Viking_3.nbt,1,CHEST:3,../../../../Chests/Lore/Viking_4.nbt,1,CHEST:3,../../../../Chests/Lore/Viking_5.nbt,1,CHEST:3,../../../../Chests/Loot/Common1.nbt,10,CHEST:3,../../../../Chests/Loot/Common2.nbt,10,CHEST:3,../../../../Chests/Loot/Common3.nbt,10,CHEST:3,../../../../Chests/Loot/Common4.nbt,10,CHEST:3,../../../../Chests/Loot/Common5.nbt,10,CHEST:3,../../../../Chests/Loot/Common6.nbt,10,CHEST:3,../../../../Chests/Loot/Common7.nbt,10,CHEST:3,../../../../Chests/Loot/Common8.nbt,10,CHEST:3,../../../../Chests/Loot/Common9.nbt,10,CHEST:3,../../../../Chests/Loot/Common10.nbt,10,CHEST:3,../../../../Chests/Loot/Common10.nbt,11,CHEST:3,../../../../Chests/Loot/Common12.nbt,10,CHEST:3,../../../../Chests/Loot/Common13.nbt,10,CHEST:3,../../../../Chests/Loot/Common14.nbt,10,CHEST:3,../../../../Chests/Loot/Common15.nbt,10,CHEST:3,../../../../Chests/Lore/Viking_1.nbt,2,CHEST:3,../../../../Chests/Lore/Viking_3.nbt,2,CHEST:3,../../../../Chests/Lore/Viking_4.nbt,2,CHEST:3,../../../../Chests/Lore/Viking_5.nbt,2,CHEST:3,../../../../Chests/Lore/Viking_5.nbt,2,CHEST:3,../../../../Chests/Loot/Rare1.nbt,5,CHEST:3,../../../../Chests/Loot/Rare2.nbt,5,CHEST:3,../../../../Chests/Loot/Rare3.nbt,5,CHEST:3,../../../../Chests/Loot/Rare4.nbt,5,CHEST:3,../../../../Chests/Loot/Rare5.nbt,5,CHEST:3,../../../../Chests/Loot/Rare6.nbt,5,CHEST:3,../../../../Chests/Loot/Rare7.nbt,5,CHEST:3,../../../../Chests/Loot/Rare8.nbt,5,CHEST:3,../../../../Chests/Loot/Rare9.nbt,5,CHEST:3,../../../../Chests/Loot/Rare10.nbt,5,CHEST:3,../../../../Chests/Loot/Rare11.nbt,5,CHEST:3,../../../../Chests/Loot/Rare12.nbt,5,CHEST:3,../../../../Chests/Loot/Rare13.nbt,5,CHEST:3,../../../../Chests/Loot/Rare14.nbt,5,CHEST:3,../../../../Chests/Loot/Rare15.nbt,5,CHEST:3,../../../../Chests/Loot/Epic1.nbt,2,CHEST:3,../../../../Chests/Loot/Epic2.nbt,2,CHEST:3,../../../../Chests/Loot/Epic3.nbt,2,CHEST:3,../../../../Chests/Loot/Epic4.nbt,2,CHEST:3,../../../../Chests/Loot/Epic5.nbt,2,CHEST:3,../../../../Chests/Loot/Epic6.nbt,2,CHEST:3,../../../../Chests/Loot/Epic7.nbt,2,CHEST:3,../../../../Chests/Loot/Epic8.nbt,2,CHEST:3,../../../../Chests/Loot/Epic9.nbt,2,CHEST:3,../../../../Chests/Loot/Epic10.nbt,2,CHEST:3,../../../../Chests/Loot/Epic11.nbt,2,CHEST:3,../../../../Chests/Loot/Epic12.nbt,2,CHEST:3,../../../../Chests/Loot/Epic13.nbt,2,CHEST:3,../../../../Chests/Loot/Epic14.nbt,2,CHEST:3,../../../../Chests/Loot/Epic15.nbt,5,CHEST:3,../../../../Chests/Loot/Rare1.nbt,5,CHEST:3,../../../../Chests/Loot/Rare2.nbt,5,CHEST:3,../../../../Chests/Loot/Rare3.nbt,5,CHEST:3,../../../../Chests/Loot/Rare4.nbt,5,CHEST:3,../../../../Chests/Loot/Rare5.nbt,10,CHEST:3,../../../../Chests/Loot/Rare6.nbt,10,CHEST:3,../../../../Chests/Loot/Rare7.nbt,10,CHEST:3,../../../../Chests/Loot/Rare8.nbt,10,CHEST:3,../../../../Chests/Loot/Rare9.nbt,10,CHEST:3,../../../../Chests/Loot/Rare10.nbt,15,CHEST:3,../../../../Chests/Loot/Rare11.nbt,15,CHEST:3,../../../../Chests/Loot/Rare12.nbt,15,CHEST:3,../../../../Chests/Loot/Rare13.nbt,15,CHEST:3,../../../../Chests/Loot/Rare14.nbt,15,CHEST:3,../../../../Chests/Loot/Rare15.nbt,15,CHEST:3,../../../../Chests/Loot/Epic15.nbt,100)
Block(-6,4,1,SPRUCE_WOOD_STAIRS:6)
RandomBlock(-6,4,2,SPRUCE_WOOD_STAIRS:3,70,DARK_OAK_STAIRS:3,100)
RandomBlock(-6,5,-7,SPRUCE_WOOD_STAIRS:2,70,DARK_OAK_STAIRS:2,100)
Block(-6,5,-6,SPRUCE_WOOD_STAIRS:7)
Block(-6,5,0,SPRUCE_WOOD_STAIRS:6)
RandomBlock(-6,5,1,SPRUCE_WOOD_STAIRS:3,70,DARK_OAK_STAIRS:3,100)
RandomBlock(-6,6,-7,WOOD_STEP:9,70,WOOD_STEP:13,100)
RandomBlock(-6,6,-6,SPRUCE_WOOD_STAIRS:2,70,DARK_OAK_STAIRS:2,100)
Block(-6,6,-5,LOG:9)
Block(-6,6,-4,LOG:9)
Block(-6,6,-3,LOG:9)
Block(-6,6,-2,LOG:9)
Block(-6,6,-1,LOG:9)
RandomBlock(-6,6,0,SPRUCE_WOOD_STAIRS:3,70,DARK_OAK_STAIRS:3,100)
RandomBlock(-6,7,-7,WOOD_STEP:1,70,WOOD_STEP:5,100)
RandomBlock(-6,7,-6,WOOD_STEP:1,70,WOOD_STEP:5,100)
RandomBlock(-6,7,-5,SPRUCE_WOOD_STAIRS:2,70,DARK_OAK_STAIRS:2,100)
Block(-6,7,-4,SPRUCE_WOOD_STAIRS:7)
RandomBlock(-6,7,-3,WOOD_STEP:9,70,WOOD_STEP:13,100)
Block(-6,7,-2,SPRUCE_WOOD_STAIRS:6)
RandomBlock(-6,7,-1,SPRUCE_WOOD_STAIRS:3,70,DARK_OAK_STAIRS:3,100)
RandomBlock(-6,8,-4,SPRUCE_WOOD_STAIRS:2,70,DARK_OAK_STAIRS:2,100)
Block(-6,8,-3,LOG:5)
RandomBlock(-6,8,-2,SPRUCE_WOOD_STAIRS:3,70,DARK_OAK_STAIRS:3,100)
Block(-6,9,-4,SPRUCE_WOOD_STAIRS:6)
RandomBlock(-6,9,-3,WOOD_STEP:1,70,WOOD_STEP:5,100)
Block(-6,9,-2,SPRUCE_WOOD_STAIRS:7)
RandomBlock(-5,0,-7,COBBLESTONE:0,60,MOSSY_COBBLESTONE:0,5,SMOOTH_BRICK:0,10,SMOOTH_BRICK:1,10,SMOOTH_BRICK:2,10,COBBLESTONE:0,100)
RandomBlock(-5,0,-6,COBBLESTONE:0,60,MOSSY_COBBLESTONE:0,5,SMOOTH_BRICK:0,10,SMOOTH_BRICK:1,10,SMOOTH_BRICK:2,10,COBBLESTONE:0,100)
RandomBlock(-5,0,-5,COBBLESTONE:0,60,MOSSY_COBBLESTONE:0,5,SMOOTH_BRICK:0,10,SMOOTH_BRICK:1,10,SMOOTH_BRICK:2,10,COBBLESTONE:0,100)
RandomBlock(-5,0,-4,COBBLESTONE:0,60,MOSSY_COBBLESTONE:0,5,SMOOTH_BRICK:0,10,SMOOTH_BRICK:1,10,SMOOTH_BRICK:2,10,COBBLESTONE:0,100)
RandomBlock(-5,0,-3,COBBLESTONE:0,60,MOSSY_COBBLESTONE:0,5,SMOOTH_BRICK:0,10,SMOOTH_BRICK:1,10,SMOOTH_BRICK:2,10,COBBLESTONE:0,100)
RandomBlock(-5,0,-2,COBBLESTONE:0,60,MOSSY_COBBLESTONE:0,5,SMOOTH_BRICK:0,10,SMOOTH_BRICK:1,10,SMOOTH_BRICK:2,10,COBBLESTONE:0,100)
RandomBlock(-5,0,-1,COBBLESTONE:0,60,MOSSY_COBBLESTONE:0,5,SMOOTH_BRICK:0,10,SMOOTH_BRICK:1,10,SMOOTH_BRICK:2,10,COBBLESTONE:0,100)
Block(-5,0,0,WOOD:1)
RandomBlock(-5,0,1,COBBLESTONE:0,60,MOSSY_COBBLESTONE:0,5,SMOOTH_BRICK:0,10,SMOOTH_BRICK:1,10,SMOOTH_BRICK:2,10,COBBLESTONE:0,100)
Block(-5,0,2,DIRT:0)
Block(-5,0,3,DIRT:0)
Block(-5,0,4,DIRT:0)
Block(-5,0,5,DIRT:0)
Block(-5,0,6,DIRT:0)
Block(-5,0,7,DIRT:0)
Block(-5,0,8,DIRT:0)
RandomBlock(-5,1,-7,COBBLESTONE:0,60,MOSSY_COBBLESTONE:0,5,SMOOTH_BRICK:0,10,SMOOTH_BRICK:1,10,SMOOTH_BRICK:2,10,COBBLESTONE:0,100)
RandomBlock(-5,1,-6,COBBLESTONE:0,60,MOSSY_COBBLESTONE:0,5,SMOOTH_BRICK:0,10,SMOOTH_BRICK:1,10,SMOOTH_BRICK:2,10,COBBLESTONE:0,100)
RandomBlock(-5,1,-5,COBBLESTONE:0,60,MOSSY_COBBLESTONE:0,5,SMOOTH_BRICK:0,10,SMOOTH_BRICK:1,10,SMOOTH_BRICK:2,10,COBBLESTONE:0,100)
RandomBlock(-5,1,-4,COBBLESTONE:0,60,MOSSY_COBBLESTONE:0,5,SMOOTH_BRICK:0,10,SMOOTH_BRICK:1,10,SMOOTH_BRICK:2,10,COBBLESTONE:0,100)
RandomBlock(-5,1,-3,COBBLESTONE:0,60,MOSSY_COBBLESTONE:0,5,SMOOTH_BRICK:0,10,SMOOTH_BRICK:1,10,SMOOTH_BRICK:2,10,COBBLESTONE:0,100)
RandomBlock(-5,1,-2,COBBLESTONE:0,60,MOSSY_COBBLESTONE:0,5,SMOOTH_BRICK:0,10,SMOOTH_BRICK:1,10,SMOOTH_BRICK:2,10,COBBLESTONE:0,100)
RandomBlock(-5,1,-1,COBBLESTONE:0,60,MOSSY_COBBLESTONE:0,5,SMOOTH_BRICK:0,10,SMOOTH_BRICK:1,10,SMOOTH_BRICK:2,10,COBBLESTONE:0,100)
Block(-5,1,0,WOOD:1)
RandomBlock(-5,1,1,COBBLESTONE:0,60,MOSSY_COBBLESTONE:0,5,SMOOTH_BRICK:0,10,SMOOTH_BRICK:1,10,SMOOTH_BRICK:2,10,COBBLESTONE:0,100)
Block(-5,1,2,DIRT:0)
Block(-5,1,3,DIRT:0)
Block(-5,1,4,DIRT:0)
Block(-5,1,5,GRASS:0)
Block(-5,1,6,DIRT:0)
Block(-5,1,7,DIRT:0)
Block(-5,1,8,DIRT:0)
RandomBlock(-5,2,-7,COBBLESTONE:0,60,MOSSY_COBBLESTONE:0,5,SMOOTH_BRICK:0,10,SMOOTH_BRICK:1,10,SMOOTH_BRICK:2,10,COBBLESTONE:0,100)
RandomBlock(-5,2,-6,WOOD_STEP:9,70,WOOD_STEP:13,100)
RandomBlock(-5,2,-5,WOOD_STEP:9,70,WOOD_STEP:13,100)
RandomBlock(-5,2,-4,WOOD_STEP:9,70,WOOD_STEP:13,100)
RandomBlock(-5,2,-3,WOOD_STEP:9,70,WOOD_STEP:13,100)
RandomBlock(-5,2,-2,WOOD_STEP:9,70,WOOD_STEP:13,100)
RandomBlock(-5,2,-1,WOOD_STEP:9,70,WOOD_STEP:13,100)
Block(-5,2,0,WOOD:1)
RandomBlock(-5,2,1,COBBLESTONE:0,60,MOSSY_COBBLESTONE:0,5,SMOOTH_BRICK:0,10,SMOOTH_BRICK:1,10,SMOOTH_BRICK:2,10,COBBLESTONE:0,100)
Block(-5,2,2,GRASS:0)
Block(-5,2,3,GRASS:0)
RandomBlock(-5,2,4,COBBLESTONE:0,60,MOSSY_COBBLESTONE:0,5,SMOOTH_BRICK:0,10,SMOOTH_BRICK:1,10,SMOOTH_BRICK:2,10,COBBLESTONE:0,100)
Block(-5,2,5,GRASS_PATH:0)
Block(-5,2,6,GRASS:0)
Block(-5,2,7,GRASS:0)
Block(-5,2,8,GRASS:0)
RandomBlock(-5,3,-7,COBBLESTONE:0,60,MOSSY_COBBLESTONE:0,5,SMOOTH_BRICK:0,10,SMOOTH_BRICK:1,10,SMOOTH_BRICK:2,10,COBBLESTONE:0,100)
Block(-5,3,-6,WOOD_STEP:13)
Block(-5,3,-5,CARPET:13)
Block(-5,3,-4,CARPET:13)
Block(-5,3,-3,CARPET:12)
Block(-5,3,-2,CARPET:13)
Block(-5,3,-1,BED_BLOCK:3)
Block(-5,3,0,WOOD:1)
RandomBlock(-5,3,1,COBBLESTONE:0,60,MOSSY_COBBLESTONE:0,5,SMOOTH_BRICK:0,10,SMOOTH_BRICK:1,10,SMOOTH_BRICK:2,10,COBBLESTONE:0,100)
Block(-5,3,2,WALL_SIGN:3)
Block(-5,3,7,WOOD_STEP:5)
RandomBlock(-5,4,-7,SPRUCE_WOOD_STAIRS:2,70,DARK_OAK_STAIRS:2,100)
Block(-5,4,-6,HAY_BLOCK:0)
RandomBlock(-5,4,-1,WALL_BANNER:2,../../NBT/Banners/viking_regular_1.nbt,20,WALL_BANNER:2,../../NBT/Banners/viking_regular_2.nbt,20,WALL_BANNER:2,../../NBT/Banners/viking_regular_3.nbt,20,WALL_BANNER:2,../../NBT/Banners/viking_regular_4.nbt,20,WALL_BANNER:2,../../NBT/Banners/viking_regular_5.nbt,20,WALL_BANNER:2,../../NBT/Banners/viking_regular_6.nbt,20,WALL_BANNER:2,../../NBT/Banners/viking_regular_7.nbt,20,WALL_BANNER:2,../../NBT/Banners/viking_regular_8.nbt,100)
Block(-5,4,0,WOOD:1)
RandomBlock(-5,4,1,SPRUCE_WOOD_STAIRS:0,70,DARK_OAK_STAIRS:0,100)
RandomBlock(-5,5,-6,SPRUCE_WOOD_STAIRS:2,70,DARK_OAK_STAIRS:2,100)
RandomBlock(-5,5,-5,WALL_BANNER:3,../../NBT/Banners/viking_wealthy_1.nbt,20,WALL_BANNER:3,../../NBT/Banners/viking_wealthy_2.nbt,20,WALL_BANNER:3,../../NBT/Banners/viking_wealthy_3.nbt,20,WALL_BANNER:3,../../NBT/Banners/viking_wealthy_4.nbt,20,WALL_BANNER:3,../../NBT/Banners/viking_wealthy_5.nbt,20,WALL_BANNER:3,../../NBT/Banners/viking_wealthy_6.nbt,20,WALL_BANNER:3,../../NBT/Banners/viking_wealthy_7.nbt,20,WALL_BANNER:3,../../NBT/Banners/viking_wealthy_8.nbt,20,WALL_BANNER:3,../../NBT/Banners/viking_wealthy_9.nbt,100)
RandomBlock(-5,5,-1,WALL_BANNER:2,../../NBT/Banners/viking_wealthy_1.nbt,20,WALL_BANNER:2,../../NBT/Banners/viking_wealthy_2.nbt,20,WALL_BANNER:2,../../NBT/Banners/viking_wealthy_3.nbt,20,WALL_BANNER:2,../../NBT/Banners/viking_wealthy_4.nbt,20,WALL_BANNER:2,../../NBT/Banners/viking_wealthy_5.nbt,20,WALL_BANNER:2,../../NBT/Banners/viking_wealthy_6.nbt,20,WALL_BANNER:2,../../NBT/Banners/viking_wealthy_7.nbt,20,WALL_BANNER:2,../../NBT/Banners/viking_wealthy_8.nbt,20,WALL_BANNER:2,../../NBT/Banners/viking_wealthy_9.nbt,100)
RandomBlock(-5,5,0,SPRUCE_WOOD_STAIRS:3,70,DARK_OAK_STAIRS:3,100)
RandomBlock(-5,5,1,WOOD_STEP:1,70,WOOD_STEP:5,100)
RandomBlock(-5,6,-5,SPRUCE_WOOD_STAIRS:2,70,DARK_OAK_STAIRS:2,100)
RandomBlock(-5,6,-1,SPRUCE_WOOD_STAIRS:3,70,DARK_OAK_STAIRS:3,100)
RandomBlock(-5,7,-4,SPRUCE_WOOD_STAIRS:2,70,DARK_OAK_STAIRS:2,100)
RandomBlock(-5,7,-2,SPRUCE_WOOD_STAIRS:3,70,DARK_OAK_STAIRS:3,100)
Block(-5,8,-3,LOG:5)
RandomBlock(-4,0,-7,COBBLESTONE:0,60,MOSSY_COBBLESTONE:0,5,SMOOTH_BRICK:0,10,SMOOTH_BRICK:1,10,SMOOTH_BRICK:2,10,COBBLESTONE:0,100)
RandomBlock(-4,0,-6,COBBLESTONE:0,60,MOSSY_COBBLESTONE:0,5,SMOOTH_BRICK:0,10,SMOOTH_BRICK:1,10,SMOOTH_BRICK:2,10,COBBLESTONE:0,100)
RandomBlock(-4,0,-5,COBBLESTONE:0,60,MOSSY_COBBLESTONE:0,5,SMOOTH_BRICK:0,10,SMOOTH_BRICK:1,10,SMOOTH_BRICK:2,10,COBBLESTONE:0,100)
RandomBlock(-4,0,-4,COBBLESTONE:0,60,MOSSY_COBBLESTONE:0,5,SMOOTH_BRICK:0,10,SMOOTH_BRICK:1,10,SMOOTH_BRICK:2,10,COBBLESTONE:0,100)
RandomBlock(-4,0,-3,COBBLESTONE:0,60,MOSSY_COBBLESTONE:0,5,SMOOTH_BRICK:0,10,SMOOTH_BRICK:1,10,SMOOTH_BRICK:2,10,COBBLESTONE:0,100)
RandomBlock(-4,0,-2,COBBLESTONE:0,60,MOSSY_COBBLESTONE:0,5,SMOOTH_BRICK:0,10,SMOOTH_BRICK:1,10,SMOOTH_BRICK:2,10,COBBLESTONE:0,100)
RandomBlock(-4,0,-1,COBBLESTONE:0,60,MOSSY_COBBLESTONE:0,5,SMOOTH_BRICK:0,10,SMOOTH_BRICK:1,10,SMOOTH_BRICK:2,10,COBBLESTONE:0,100)
Block(-4,0,0,WOOD:1)
RandomBlock(-4,0,1,COBBLESTONE:0,60,MOSSY_COBBLESTONE:0,5,SMOOTH_BRICK:0,10,SMOOTH_BRICK:1,10,SMOOTH_BRICK:2,10,COBBLESTONE:0,100)
Block(-4,0,2,DIRT:0)
Block(-4,0,3,DIRT:0)
Block(-4,0,4,DIRT:0)
Block(-4,0,5,DIRT:0)
Block(-4,0,6,DIRT:0)
Block(-4,0,7,DIRT:0)
Block(-4,0,8,DIRT:0)
RandomBlock(-4,1,-7,COBBLESTONE:0,60,MOSSY_COBBLESTONE:0,5,SMOOTH_BRICK:0,10,SMOOTH_BRICK:1,10,SMOOTH_BRICK:2,10,COBBLESTONE:0,100)
RandomBlock(-4,1,-6,COBBLESTONE:0,60,MOSSY_COBBLESTONE:0,5,SMOOTH_BRICK:0,10,SMOOTH_BRICK:1,10,SMOOTH_BRICK:2,10,COBBLESTONE:0,100)
RandomBlock(-4,1,-5,COBBLESTONE:0,60,MOSSY_COBBLESTONE:0,5,SMOOTH_BRICK:0,10,SMOOTH_BRICK:1,10,SMOOTH_BRICK:2,10,COBBLESTONE:0,100)
RandomBlock(-4,1,-4,COBBLESTONE:0,60,MOSSY_COBBLESTONE:0,5,SMOOTH_BRICK:0,10,SMOOTH_BRICK:1,10,SMOOTH_BRICK:2,10,COBBLESTONE:0,100)
RandomBlock(-4,1,-3,COBBLESTONE:0,60,MOSSY_COBBLESTONE:0,5,SMOOTH_BRICK:0,10,SMOOTH_BRICK:1,10,SMOOTH_BRICK:2,10,COBBLESTONE:0,100)
RandomBlock(-4,1,-2,COBBLESTONE:0,60,MOSSY_COBBLESTONE:0,5,SMOOTH_BRICK:0,10,SMOOTH_BRICK:1,10,SMOOTH_BRICK:2,10,COBBLESTONE:0,100)
RandomBlock(-4,1,-1,COBBLESTONE:0,60,MOSSY_COBBLESTONE:0,5,SMOOTH_BRICK:0,10,SMOOTH_BRICK:1,10,SMOOTH_BRICK:2,10,COBBLESTONE:0,100)
Block(-4,1,0,WOOD:1)
RandomBlock(-4,1,1,COBBLESTONE:0,60,MOSSY_COBBLESTONE:0,5,SMOOTH_BRICK:0,10,SMOOTH_BRICK:1,10,SMOOTH_BRICK:2,10,COBBLESTONE:0,100)
Block(-4,1,2,DIRT:0)
Block(-4,1,3,DIRT:0)
Block(-4,1,4,DIRT:0)
Block(-4,1,5,GRASS:0)
Block(-4,1,6,DIRT:0)
Block(-4,1,7,DIRT:0)
Block(-4,1,8,GRASS:0)
RandomBlock(-4,2,-7,COBBLESTONE:0,60,MOSSY_COBBLESTONE:0,5,SMOOTH_BRICK:0,10,SMOOTH_BRICK:1,10,SMOOTH_BRICK:2,10,COBBLESTONE:0,100)
RandomBlock(-4,2,-6,WOOD_STEP:9,70,WOOD_STEP:13,100)
RandomBlock(-4,2,-5,WOOD_STEP:9,70,WOOD_STEP:13,100)
RandomBlock(-4,2,-4,WOOD_STEP:9,70,WOOD_STEP:13,100)
RandomBlock(-4,2,-3,WOOD_STEP:9,70,WOOD_STEP:13,100)
RandomBlock(-4,2,-2,WOOD_STEP:9,70,WOOD_STEP:13,100)
RandomBlock(-4,2,-1,WOOD_STEP:9,70,WOOD_STEP:13,100)
Block(-4,2,0,WOOD:1)
RandomBlock(-4,2,1,COBBLESTONE:0,60,MOSSY_COBBLESTONE:0,5,SMOOTH_BRICK:0,10,SMOOTH_BRICK:1,10,SMOOTH_BRICK:2,10,COBBLESTONE:0,100)
Block(-4,2,2,GRASS:0)
Block(-4,2,3,GRASS:0)
Block(-4,2,4,GRASS:0)
Block(-4,2,5,GRASS_PATH:0)
RandomBlock(-4,2,6,COBBLESTONE:0,60,MOSSY_COBBLESTONE:0,5,SMOOTH_BRICK:0,10,SMOOTH_BRICK:1,10,SMOOTH_BRICK:2,10,COBBLESTONE:0,100)
Block(-4,2,7,GRASS:0)
RandomBlock(-4,3,-7,COBBLESTONE:0,60,MOSSY_COBBLESTONE:0,5,SMOOTH_BRICK:0,10,SMOOTH_BRICK:1,10,SMOOTH_BRICK:2,10,COBBLESTONE:0,100)
Block(-4,3,-6,WOOD_STEP:13)
Block(-4,3,-5,BED_BLOCK:10)
Block(-4,3,-4,BED_BLOCK:2)
Block(-4,3,-3,CARPET:13)
Block(-4,3,-2,CARPET:13)
Block(-4,3,-1,BED_BLOCK:11)
Block(-4,3,0,WOOD:1)
RandomBlock(-4,3,1,COBBLESTONE:0,60,MOSSY_COBBLESTONE:0,5,SMOOTH_BRICK:0,10,SMOOTH_BRICK:1,10,SMOOTH_BRICK:2,10,COBBLESTONE:0,100)
Block(-4,3,2,WALL_SIGN:3)
Block(-4,3,3,FLOWER_POT:0)
RandomBlock(-4,4,-7,SPRUCE_WOOD_STAIRS:2,70,DARK_OAK_STAIRS:2,100)
Block(-4,4,-6,HAY_BLOCK:8)
RandomBlock(-4,4,-5,WALL_BANNER:4,../../NBT/Banners/viking_regular_1.nbt,20,WALL_BANNER:4,../../NBT/Banners/viking_regular_2.nbt,20,WALL_BANNER:4,../../NBT/Banners/viking_regular_3.nbt,20,WALL_BANNER:4,../../NBT/Banners/viking_regular_4.nbt,20,WALL_BANNER:4,../../NBT/Banners/viking_regular_5.nbt,20,WALL_BANNER:4,../../NBT/Banners/viking_regular_6.nbt,20,WALL_BANNER:4,../../NBT/Banners/viking_regular_7.nbt,20,WALL_BANNER:4,../../NBT/Banners/viking_regular_8.nbt,100)
RandomBlock(-4,4,-4,WALL_BANNER:4,../../NBT/Banners/viking_regular_1.nbt,20,WALL_BANNER:4,../../NBT/Banners/viking_regular_2.nbt,20,WALL_BANNER:4,../../NBT/Banners/viking_regular_3.nbt,20,WALL_BANNER:4,../../NBT/Banners/viking_regular_4.nbt,20,WALL_BANNER:4,../../NBT/Banners/viking_regular_5.nbt,20,WALL_BANNER:4,../../NBT/Banners/viking_regular_6.nbt,20,WALL_BANNER:4,../../NBT/Banners/viking_regular_7.nbt,20,WALL_BANNER:4,../../NBT/Banners/viking_regular_8.nbt,100)
Block(-4,4,1,DARK_OAK_FENCE:0)
RandomBlock(-4,5,-6,SPRUCE_WOOD_STAIRS:2,70,DARK_OAK_STAIRS:2,100)
RandomBlock(-4,5,-2,WALL_BANNER:4,../../NBT/Banners/viking_regular_1.nbt,20,WALL_BANNER:4,../../NBT/Banners/viking_regular_2.nbt,20,WALL_BANNER:4,../../NBT/Banners/viking_regular_3.nbt,20,WALL_BANNER:4,../../NBT/Banners/viking_regular_4.nbt,20,WALL_BANNER:4,../../NBT/Banners/viking_regular_5.nbt,20,WALL_BANNER:4,../../NBT/Banners/viking_regular_6.nbt,20,WALL_BANNER:4,../../NBT/Banners/viking_regular_7.nbt,20,WALL_BANNER:4,../../NBT/Banners/viking_regular_8.nbt,100)
RandomBlock(-4,5,0,SPRUCE_WOOD_STAIRS:3,70,DARK_OAK_STAIRS:3,100)
RandomBlock(-4,5,1,WOOD_STEP:1,70,WOOD_STEP:5,100)
Block(-4,5,2,TRAP_DOOR:1)
RandomBlock(-4,6,-5,SPRUCE_WOOD_STAIRS:2,70,DARK_OAK_STAIRS:2,100)
RandomBlock(-4,6,-4,WALL_BANNER:4,../../NBT/Banners/viking_regular_1.nbt,20,WALL_BANNER:4,../../NBT/Banners/viking_regular_2.nbt,20,WALL_BANNER:4,../../NBT/Banners/viking_regular_3.nbt,20,WALL_BANNER:4,../../NBT/Banners/viking_regular_4.nbt,20,WALL_BANNER:4,../../NBT/Banners/viking_regular_5.nbt,20,WALL_BANNER:4,../../NBT/Banners/viking_regular_6.nbt,20,WALL_BANNER:4,../../NBT/Banners/viking_regular_7.nbt,20,WALL_BANNER:4,../../NBT/Banners/viking_regular_8.nbt,100)
RandomBlock(-4,6,-2,WALL_BANNER:4,../../NBT/Banners/viking_wealthy_1.nbt,20,WALL_BANNER:4,../../NBT/Banners/viking_wealthy_2.nbt,20,WALL_BANNER:4,../../NBT/Banners/viking_wealthy_3.nbt,20,WALL_BANNER:4,../../NBT/Banners/viking_wealthy_4.nbt,20,WALL_BANNER:4,../../NBT/Banners/viking_wealthy_5.nbt,20,WALL_BANNER:4,../../NBT/Banners/viking_wealthy_6.nbt,20,WALL_BANNER:4,../../NBT/Banners/viking_wealthy_7.nbt,20,WALL_BANNER:4,../../NBT/Banners/viking_wealthy_8.nbt,20,WALL_BANNER:4,../../NBT/Banners/viking_wealthy_9.nbt,100)
RandomBlock(-4,6,-1,SPRUCE_WOOD_STAIRS:3,70,DARK_OAK_STAIRS:3,100)
RandomBlock(-4,7,-4,SPRUCE_WOOD_STAIRS:2,70,DARK_OAK_STAIRS:2,100)
RandomBlock(-4,7,-2,SPRUCE_WOOD_STAIRS:3,70,DARK_OAK_STAIRS:3,100)
Block(-4,8,-3,LOG:5)
RandomBlock(-3,0,-7,COBBLESTONE:0,60,MOSSY_COBBLESTONE:0,5,SMOOTH_BRICK:0,10,SMOOTH_BRICK:1,10,SMOOTH_BRICK:2,10,COBBLESTONE:0,100)
RandomBlock(-3,0,-6,COBBLESTONE:0,60,MOSSY_COBBLESTONE:0,5,SMOOTH_BRICK:0,10,SMOOTH_BRICK:1,10,SMOOTH_BRICK:2,10,COBBLESTONE:0,100)
RandomBlock(-3,0,-5,COBBLESTONE:0,60,MOSSY_COBBLESTONE:0,5,SMOOTH_BRICK:0,10,SMOOTH_BRICK:1,10,SMOOTH_BRICK:2,10,COBBLESTONE:0,100)
RandomBlock(-3,0,-4,COBBLESTONE:0,60,MOSSY_COBBLESTONE:0,5,SMOOTH_BRICK:0,10,SMOOTH_BRICK:1,10,SMOOTH_BRICK:2,10,COBBLESTONE:0,100)
RandomBlock(-3,0,-3,COBBLESTONE:0,60,MOSSY_COBBLESTONE:0,5,SMOOTH_BRICK:0,10,SMOOTH_BRICK:1,10,SMOOTH_BRICK:2,10,COBBLESTONE:0,100)
RandomBlock(-3,0,-2,COBBLESTONE:0,60,MOSSY_COBBLESTONE:0,5,SMOOTH_BRICK:0,10,SMOOTH_BRICK:1,10,SMOOTH_BRICK:2,10,COBBLESTONE:0,100)
RandomBlock(-3,0,-1,COBBLESTONE:0,60,MOSSY_COBBLESTONE:0,5,SMOOTH_BRICK:0,10,SMOOTH_BRICK:1,10,SMOOTH_BRICK:2,10,COBBLESTONE:0,100)
RandomBlock(-3,0,0,COBBLESTONE:0,60,MOSSY_COBBLESTONE:0,5,SMOOTH_BRICK:0,10,SMOOTH_BRICK:1,10,SMOOTH_BRICK:2,10,COBBLESTONE:0,100)
RandomBlock(-3,0,1,COBBLESTONE:0,60,MOSSY_COBBLESTONE:0,5,SMOOTH_BRICK:0,10,SMOOTH_BRICK:1,10,SMOOTH_BRICK:2,10,COBBLESTONE:0,100)
Block(-3,0,2,DIRT:0)
Block(-3,0,3,DIRT:0)
Block(-3,0,4,DIRT:0)
Block(-3,0,5,DIRT:0)
Block(-3,0,6,DIRT:0)
Block(-3,0,7,DIRT:0)
Block(-3,0,8,DIRT:0)
RandomBlock(-3,1,-7,COBBLESTONE:0,60,MOSSY_COBBLESTONE:0,5,SMOOTH_BRICK:0,10,SMOOTH_BRICK:1,10,SMOOTH_BRICK:2,10,COBBLESTONE:0,100)
RandomBlock(-3,1,-6,COBBLESTONE:0,60,MOSSY_COBBLESTONE:0,5,SMOOTH_BRICK:0,10,SMOOTH_BRICK:1,10,SMOOTH_BRICK:2,10,COBBLESTONE:0,100)
RandomBlock(-3,1,-5,COBBLESTONE:0,60,MOSSY_COBBLESTONE:0,5,SMOOTH_BRICK:0,10,SMOOTH_BRICK:1,10,SMOOTH_BRICK:2,10,COBBLESTONE:0,100)
RandomBlock(-3,1,-4,COBBLESTONE:0,60,MOSSY_COBBLESTONE:0,5,SMOOTH_BRICK:0,10,SMOOTH_BRICK:1,10,SMOOTH_BRICK:2,10,COBBLESTONE:0,100)
RandomBlock(-3,1,-3,COBBLESTONE:0,60,MOSSY_COBBLESTONE:0,5,SMOOTH_BRICK:0,10,SMOOTH_BRICK:1,10,SMOOTH_BRICK:2,10,COBBLESTONE:0,100)
RandomBlock(-3,1,-2,COBBLESTONE:0,60,MOSSY_COBBLESTONE:0,5,SMOOTH_BRICK:0,10,SMOOTH_BRICK:1,10,SMOOTH_BRICK:2,10,COBBLESTONE:0,100)
RandomBlock(-3,1,-1,COBBLESTONE:0,60,MOSSY_COBBLESTONE:0,5,SMOOTH_BRICK:0,10,SMOOTH_BRICK:1,10,SMOOTH_BRICK:2,10,COBBLESTONE:0,100)
RandomBlock(-3,1,0,COBBLESTONE:0,60,MOSSY_COBBLESTONE:0,5,SMOOTH_BRICK:0,10,SMOOTH_BRICK:1,10,SMOOTH_BRICK:2,10,COBBLESTONE:0,100)
RandomBlock(-3,1,1,COBBLESTONE:0,60,MOSSY_COBBLESTONE:0,5,SMOOTH_BRICK:0,10,SMOOTH_BRICK:1,10,SMOOTH_BRICK:2,10,COBBLESTONE:0,100)
Block(-3,1,2,DIRT:0)
Block(-3,1,3,DIRT:0)
Block(-3,1,4,DIRT:0)
Block(-3,1,5,GRASS:0)
Block(-3,1,6,DIRT:0)
Block(-3,1,7,DIRT:0)
Block(-3,1,8,GRASS:0)
RandomBlock(-3,2,-7,COBBLESTONE:0,60,MOSSY_COBBLESTONE:0,5,SMOOTH_BRICK:0,10,SMOOTH_BRICK:1,10,SMOOTH_BRICK:2,10,COBBLESTONE:0,100)
RandomBlock(-3,2,-6,COBBLESTONE:0,60,MOSSY_COBBLESTONE:0,5,SMOOTH_BRICK:0,10,SMOOTH_BRICK:1,10,SMOOTH_BRICK:2,10,COBBLESTONE:0,100)
RandomBlock(-3,2,-5,COBBLESTONE:0,60,MOSSY_COBBLESTONE:0,5,SMOOTH_BRICK:0,10,SMOOTH_BRICK:1,10,SMOOTH_BRICK:2,10,COBBLESTONE:0,100)
RandomBlock(-3,2,-4,COBBLESTONE:0,60,MOSSY_COBBLESTONE:0,5,SMOOTH_BRICK:0,10,SMOOTH_BRICK:1,10,SMOOTH_BRICK:2,10,COBBLESTONE:0,100)
RandomBlock(-3,2,-3,COBBLESTONE:0,60,MOSSY_COBBLESTONE:0,5,SMOOTH_BRICK:0,10,SMOOTH_BRICK:1,10,SMOOTH_BRICK:2,10,COBBLESTONE:0,100)
RandomBlock(-3,2,-2,COBBLESTONE:0,60,MOSSY_COBBLESTONE:0,5,SMOOTH_BRICK:0,10,SMOOTH_BRICK:1,10,SMOOTH_BRICK:2,10,COBBLESTONE:0,100)
RandomBlock(-3,2,-1,COBBLESTONE:0,60,MOSSY_COBBLESTONE:0,5,SMOOTH_BRICK:0,10,SMOOTH_BRICK:1,10,SMOOTH_BRICK:2,10,COBBLESTONE:0,100)
RandomBlock(-3,2,0,COBBLESTONE:0,60,MOSSY_COBBLESTONE:0,5,SMOOTH_BRICK:0,10,SMOOTH_BRICK:1,10,SMOOTH_BRICK:2,10,COBBLESTONE:0,100)
RandomBlock(-3,2,1,COBBLESTONE:0,60,MOSSY_COBBLESTONE:0,5,SMOOTH_BRICK:0,10,SMOOTH_BRICK:1,10,SMOOTH_BRICK:2,10,COBBLESTONE:0,100)
Block(-3,2,2,GRASS:0)
Block(-3,2,3,GRASS:0)
Block(-3,2,4,GRASS:0)
Block(-3,2,5,GRASS_PATH:0)
RandomBlock(-3,2,6,COBBLESTONE:0,60,MOSSY_COBBLESTONE:0,5,SMOOTH_BRICK:0,10,SMOOTH_BRICK:1,10,SMOOTH_BRICK:2,10,COBBLESTONE:0,100)
Block(-3,2,7,GRASS:0)
RandomBlock(-3,3,-7,COBBLESTONE:0,60,MOSSY_COBBLESTONE:0,5,SMOOTH_BRICK:0,10,SMOOTH_BRICK:1,10,SMOOTH_BRICK:2,10,COBBLESTONE:0,100)
RandomBlock(-3,3,-6,COBBLESTONE:0,60,MOSSY_COBBLESTONE:0,5,SMOOTH_BRICK:0,10,SMOOTH_BRICK:1,10,SMOOTH_BRICK:2,10,COBBLESTONE:0,100)
RandomBlock(-3,3,-5,COBBLESTONE:0,60,MOSSY_COBBLESTONE:0,5,SMOOTH_BRICK:0,10,SMOOTH_BRICK:1,10,SMOOTH_BRICK:2,10,COBBLESTONE:0,100)
RandomBlock(-3,3,-4,COBBLESTONE:0,60,MOSSY_COBBLESTONE:0,5,SMOOTH_BRICK:0,10,SMOOTH_BRICK:1,10,SMOOTH_BRICK:2,10,COBBLESTONE:0,100)
RandomBlock(-3,3,-3,COBBLESTONE:0,60,MOSSY_COBBLESTONE:0,5,SMOOTH_BRICK:0,10,SMOOTH_BRICK:1,10,SMOOTH_BRICK:2,10,COBBLESTONE:0,100)
RandomBlock(-3,3,-2,COBBLESTONE:0,60,MOSSY_COBBLESTONE:0,5,SMOOTH_BRICK:0,10,SMOOTH_BRICK:1,10,SMOOTH_BRICK:2,10,COBBLESTONE:0,100)
RandomBlock(-3,3,-1,COBBLESTONE:0,60,MOSSY_COBBLESTONE:0,5,SMOOTH_BRICK:0,10,SMOOTH_BRICK:1,10,SMOOTH_BRICK:2,10,COBBLESTONE:0,100)
RandomBlock(-3,3,0,COBBLESTONE:0,60,MOSSY_COBBLESTONE:0,5,SMOOTH_BRICK:0,10,SMOOTH_BRICK:1,10,SMOOTH_BRICK:2,10,COBBLESTONE:0,100)
RandomBlock(-3,3,1,COBBLESTONE:0,60,MOSSY_COBBLESTONE:0,5,SMOOTH_BRICK:0,10,SMOOTH_BRICK:1,10,SMOOTH_BRICK:2,10,COBBLESTONE:0,100)
Block(-3,3,2,WALL_SIGN:3)
Block(-3,3,3,FLOWER_POT:0)
Block(-3,3,4,FLOWER_POT:0)
RandomBlock(-3,4,-7,SPRUCE_WOOD_STAIRS:2,70,DARK_OAK_STAIRS:2,100)
Block(-3,4,-6,WOOD:1)
Block(-3,4,-5,WOOD:1)
Block(-3,4,-4,WOOD:1)
Block(-3,4,-3,WOOD:1)
Block(-3,4,-2,WOOD:1)
Block(-3,4,-1,WOOD:1)
Block(-3,4,0,WOOD:1)
RandomBlock(-3,4,1,SPRUCE_WOOD_STAIRS:1,70,DARK_OAK_STAIRS:1,100)
RandomBlock(-3,5,-6,SPRUCE_WOOD_STAIRS:2,70,DARK_OAK_STAIRS:2,100)
Block(-3,5,-5,WOOD:1)
Block(-3,5,-4,WOOD:1)
Block(-3,5,-3,WOOD:1)
Block(-3,5,-2,WOOD:1)
Block(-3,5,-1,WOOD:1)
RandomBlock(-3,5,0,SPRUCE_WOOD_STAIRS:3,70,DARK_OAK_STAIRS:3,100)
RandomBlock(-3,5,1,WOOD_STEP:1,70,WOOD_STEP:5,100)
RandomBlock(-3,6,-5,SPRUCE_WOOD_STAIRS:2,70,DARK_OAK_STAIRS:2,100)
Block(-3,6,-4,WOOD:1)
Block(-3,6,-3,WOOD:1)
Block(-3,6,-2,WOOD:1)
RandomBlock(-3,6,-1,SPRUCE_WOOD_STAIRS:3,70,DARK_OAK_STAIRS:3,100)
RandomBlock(-3,7,-4,SPRUCE_WOOD_STAIRS:2,70,DARK_OAK_STAIRS:2,100)
Block(-3,7,-3,WOOD:1)
RandomBlock(-3,7,-2,SPRUCE_WOOD_STAIRS:3,70,DARK_OAK_STAIRS:3,100)
Block(-3,8,-3,LOG:5)
Block(-2,0,-7,DIRT:0)
Block(-2,0,-6,DIRT:0)
Block(-2,0,-5,DIRT:0)
Block(-2,0,-4,DIRT:0)
Block(-2,0,-3,DIRT:0)
Block(-2,0,-2,DIRT:0)
Block(-2,0,-1,DIRT:0)
Block(-2,0,0,DIRT:0)
Block(-2,0,1,DIRT:0)
Block(-2,0,2,DIRT:0)
RandomBlock(-2,0,3,COBBLESTONE:0,60,MOSSY_COBBLESTONE:0,5,SMOOTH_BRICK:0,10,SMOOTH_BRICK:1,10,SMOOTH_BRICK:2,10,COBBLESTONE:0,100)
Block(-2,0,4,DIRT:0)
Block(-2,0,5,DIRT:0)
Block(-2,0,6,DIRT:0)
Block(-2,0,7,DIRT:0)
Block(-2,0,8,DIRT:0)
Block(-2,1,-7,DIRT:0)
Block(-2,1,-6,DIRT:0)
Block(-2,1,-5,DIRT:0)
Block(-2,1,-4,DIRT:0)
Block(-2,1,-3,DIRT:0)
Block(-2,1,-2,DIRT:0)
Block(-2,1,-1,DIRT:0)
Block(-2,1,0,DIRT:0)
Block(-2,1,1,DIRT:0)
Block(-2,1,2,DIRT:0)
RandomBlock(-2,1,3,COBBLESTONE:0,60,MOSSY_COBBLESTONE:0,5,SMOOTH_BRICK:0,10,SMOOTH_BRICK:1,10,SMOOTH_BRICK:2,10,COBBLESTONE:0,100)
Block(-2,1,4,DIRT:0)
Block(-2,1,5,DIRT:0)
Block(-2,1,6,GRASS:0)
Block(-2,1,7,DIRT:0)
Block(-2,1,8,GRASS:0)
RandomBlock(-2,2,-7,COBBLESTONE:0,60,MOSSY_COBBLESTONE:0,5,SMOOTH_BRICK:0,10,SMOOTH_BRICK:1,10,SMOOTH_BRICK:2,10,COBBLESTONE:0,100)
Block(-2,2,-6,DIRT:0)
Block(-2,2,-5,GRASS:0)
Block(-2,2,-4,GRASS:0)
Block(-2,2,-3,GRASS:0)
RandomBlock(-2,2,-2,COBBLESTONE:0,60,MOSSY_COBBLESTONE:0,5,SMOOTH_BRICK:0,10,SMOOTH_BRICK:1,10,SMOOTH_BRICK:2,10,COBBLESTONE:0,100)
Block(-2,2,-1,DIRT:0)
RandomBlock(-2,2,0,COBBLESTONE:0,60,MOSSY_COBBLESTONE:0,5,SMOOTH_BRICK:0,10,SMOOTH_BRICK:1,10,SMOOTH_BRICK:2,10,COBBLESTONE:0,100)
Block(-2,2,1,DIRT:0)
Block(-2,2,2,GRASS:0)
RandomBlock(-2,2,3,COBBLESTONE:0,60,MOSSY_COBBLESTONE:0,5,SMOOTH_BRICK:0,10,SMOOTH_BRICK:1,10,SMOOTH_BRICK:2,10,COBBLESTONE:0,100)
Block(-2,2,4,GRASS:0)
RandomBlock(-2,2,5,COBBLESTONE:0,60,MOSSY_COBBLESTONE:0,5,SMOOTH_BRICK:0,10,SMOOTH_BRICK:1,10,SMOOTH_BRICK:2,10,COBBLESTONE:0,100)
Block(-2,2,6,GRASS_PATH:0)
Block(-2,2,7,GRASS:0)
Block(-2,3,-7,DIRT:0)
Block(-2,3,-6,GRASS:0)
Block(-2,3,-5,WALL_SIGN:5)
Block(-2,3,-4,WALL_SIGN:5)
Block(-2,3,-3,WALL_SIGN:5)
Block(-2,3,-2,WALL_SIGN:5)
Block(-2,3,-1,DIRT:1)
Block(-2,3,0,DIRT:1)
Block(-2,3,1,DIRT:1)
Block(-2,3,2,SPRUCE_WOOD_STAIRS:6)
RandomBlock(-2,3,3,SPRUCE_WOOD_STAIRS:3,70,DARK_OAK_STAIRS:3,100)
Block(-2,4,-7,SPRUCE_WOOD_STAIRS:7)
Block(-2,4,0,DIRT:1)
Block(-2,4,1,SPRUCE_WOOD_STAIRS:6)
RandomBlock(-2,4,2,SPRUCE_WOOD_STAIRS:3,70,DARK_OAK_STAIRS:3,100)
RandomBlock(-2,5,-7,SPRUCE_WOOD_STAIRS:2,70,DARK_OAK_STAIRS:2,100)
Block(-2,5,-6,SPRUCE_WOOD_STAIRS:7)
Block(-2,5,0,SPRUCE_WOOD_STAIRS:6)
RandomBlock(-2,5,1,SPRUCE_WOOD_STAIRS:3,70,DARK_OAK_STAIRS:3,100)
RandomBlock(-2,6,-6,SPRUCE_WOOD_STAIRS:2,70,DARK_OAK_STAIRS:2,100)
Block(-2,6,-5,SPRUCE_WOOD_STAIRS:7)
Block(-2,6,-1,SPRUCE_WOOD_STAIRS:6)
RandomBlock(-2,6,0,SPRUCE_WOOD_STAIRS:3,70,DARK_OAK_STAIRS:3,100)
RandomBlock(-2,7,-5,SPRUCE_WOOD_STAIRS:2,70,DARK_OAK_STAIRS:2,100)
Block(-2,7,-4,SPRUCE_WOOD_STAIRS:7)
Block(-2,7,-3,WEB:0)
Block(-2,7,-2,SPRUCE_WOOD_STAIRS:6)
RandomBlock(-2,7,-1,SPRUCE_WOOD_STAIRS:3,70,DARK_OAK_STAIRS:3,100)
RandomBlock(-2,8,-4,SPRUCE_WOOD_STAIRS:2,70,DARK_OAK_STAIRS:2,100)
Block(-2,8,-3,LOG:5)
RandomBlock(-2,8,-2,SPRUCE_WOOD_STAIRS:3,70,DARK_OAK_STAIRS:3,100)
Block(-2,9,-4,SPRUCE_WOOD_STAIRS:6)
RandomBlock(-2,9,-3,WOOD_STEP:1,70,WOOD_STEP:5,100)
Block(-2,9,-2,SPRUCE_WOOD_STAIRS:7)
Block(-1,0,-7,DIRT:0)
Block(-1,0,-6,DIRT:0)
Block(-1,0,-5,DIRT:0)
Block(-1,0,-4,DIRT:0)
Block(-1,0,-3,DIRT:0)
Block(-1,0,-2,DIRT:0)
Block(-1,0,-1,DIRT:0)
Block(-1,0,0,DIRT:0)
Block(-1,0,1,DIRT:0)
Block(-1,0,2,DIRT:0)
Block(-1,0,3,DIRT:0)
Block(-1,0,4,DIRT:0)
Block(-1,0,5,DIRT:0)
Block(-1,0,6,DIRT:0)
Block(-1,0,7,DIRT:0)
Block(-1,0,8,DIRT:0)
Block(-1,1,-7,DIRT:0)
Block(-1,1,-6,DIRT:0)
Block(-1,1,-5,DIRT:0)
Block(-1,1,-4,DIRT:0)
Block(-1,1,-3,DIRT:0)
Block(-1,1,-2,DIRT:0)
Block(-1,1,-1,DIRT:0)
Block(-1,1,0,DIRT:0)
Block(-1,1,1,DIRT:0)
Block(-1,1,2,DIRT:0)
Block(-1,1,3,DIRT:0)
Block(-1,1,4,DIRT:0)
Block(-1,1,5,DIRT:0)
Block(-1,1,6,DIRT:0)
Block(-1,1,7,GRASS:0)
Block(-1,1,8,GRASS:0)
RandomBlock(-1,2,-7,COBBLESTONE:0,60,MOSSY_COBBLESTONE:0,5,SMOOTH_BRICK:0,10,SMOOTH_BRICK:1,10,SMOOTH_BRICK:2,10,COBBLESTONE:0,100)
RandomBlock(-1,2,-6,COBBLESTONE:0,60,MOSSY_COBBLESTONE:0,5,SMOOTH_BRICK:0,10,SMOOTH_BRICK:1,10,SMOOTH_BRICK:2,10,COBBLESTONE:0,100)
RandomBlock(-1,2,-5,COBBLESTONE:0,60,MOSSY_COBBLESTONE:0,5,SMOOTH_BRICK:0,10,SMOOTH_BRICK:1,10,SMOOTH_BRICK:2,10,COBBLESTONE:0,100)
RandomBlock(-1,2,-4,COBBLESTONE:0,60,MOSSY_COBBLESTONE:0,5,SMOOTH_BRICK:0,10,SMOOTH_BRICK:1,10,SMOOTH_BRICK:2,10,COBBLESTONE:0,100)
RandomBlock(-1,2,-3,COBBLESTONE:0,60,MOSSY_COBBLESTONE:0,5,SMOOTH_BRICK:0,10,SMOOTH_BRICK:1,10,SMOOTH_BRICK:2,10,COBBLESTONE:0,100)
Block(-1,2,-2,COAL_ORE:0)
RandomBlock(-1,2,-1,COBBLESTONE:0,60,MOSSY_COBBLESTONE:0,5,SMOOTH_BRICK:0,10,SMOOTH_BRICK:1,10,SMOOTH_BRICK:2,10,COBBLESTONE:0,100)
RandomBlock(-1,2,0,COBBLESTONE:0,60,MOSSY_COBBLESTONE:0,5,SMOOTH_BRICK:0,10,SMOOTH_BRICK:1,10,SMOOTH_BRICK:2,10,COBBLESTONE:0,100)
Block(-1,2,1,DIRT:0)
Block(-1,2,2,GRASS:0)
Block(-1,2,3,GRASS:0)
RandomBlock(-1,2,4,COBBLESTONE:0,60,MOSSY_COBBLESTONE:0,5,SMOOTH_BRICK:0,10,SMOOTH_BRICK:1,10,SMOOTH_BRICK:2,10,COBBLESTONE:0,100)
Block(-1,2,5,GRASS:0)
Block(-1,2,6,GRASS:0)
Block(-1,3,-7,DIRT:0)
Block(-1,3,-6,SPRUCE_FENCE:0)
Block(-1,3,0,DIRT:1)
Block(-1,3,1,DIRT:1)
Block(-1,3,2,SPRUCE_FENCE:0)
Block(-1,4,-7,GRASS:0)
Block(-1,4,-6,SPRUCE_FENCE:0)
Block(-1,4,0,DIRT:1)
Block(-1,4,2,SPRUCE_FENCE:0)
RandomBlock(-1,5,-7,WOOD_STEP:9,70,WOOD_STEP:13,100)
Block(-1,5,-6,SPRUCE_FENCE:0)
Block(-1,5,2,SPRUCE_FENCE:0)
RandomBlock(-1,6,-7,WOOD_STEP:1,70,WOOD_STEP:5,100)
Block(-1,6,-6,WOOD_DOUBLE_STEP:1)
RandomBlock(-1,6,0,WOOD_STEP:9,70,WOOD_STEP:13,100)
RandomBlock(-1,6,1,WOOD_STEP:9,70,WOOD_STEP:13,100)
Block(-1,6,2,WOOD_DOUBLE_STEP:1)
RandomBlock(-1,7,-6,WOOD_STEP:1,70,WOOD_STEP:5,100)
RandomBlock(-1,7,-5,WOOD_STEP:1,70,WOOD_STEP:5,100)
RandomBlock(-1,7,-4,WOOD_STEP:9,70,WOOD_STEP:13,100)
RandomBlock(-1,7,-3,WOOD_STEP:9,70,WOOD_STEP:13,100)
RandomBlock(-1,7,-2,WOOD_STEP:9,70,WOOD_STEP:13,100)
RandomBlock(-1,7,-1,WOOD_STEP:9,70,WOOD_STEP:13,100)
RandomBlock(-1,7,0,WOOD_STEP:1,70,WOOD_STEP:5,100)
Block(-1,8,-3,LOG:5)
Block(0,0,-7,DIRT:0)
Block(0,0,-6,DIRT:0)
Block(0,0,-5,DIRT:0)
RandomBlock(0,0,-4,COBBLESTONE:0,60,MOSSY_COBBLESTONE:0,5,SMOOTH_BRICK:0,10,SMOOTH_BRICK:1,10,SMOOTH_BRICK:2,10,COBBLESTONE:0,100)
Block(0,0,-3,DIRT:0)
RandomBlock(0,0,-2,COBBLESTONE:0,60,MOSSY_COBBLESTONE:0,5,SMOOTH_BRICK:0,10,SMOOTH_BRICK:1,10,SMOOTH_BRICK:2,10,COBBLESTONE:0,100)
RandomBlock(0,0,-1,COBBLESTONE:0,60,MOSSY_COBBLESTONE:0,5,SMOOTH_BRICK:0,10,SMOOTH_BRICK:1,10,SMOOTH_BRICK:2,10,COBBLESTONE:0,100)
Block(0,0,0,DIRT:0)
Block(0,0,1,DIRT:0)
Block(0,0,2,DIRT:0)
Block(0,0,3,DIRT:0)
Block(0,0,4,DIRT:0)
Block(0,0,5,DIRT:0)
Block(0,0,6,DIRT:0)
Block(0,0,7,DIRT:0)
Block(0,1,-7,DIRT:0)
Block(0,1,-6,DIRT:0)
Block(0,1,-5,DIRT:0)
RandomBlock(0,1,-4,COBBLESTONE:0,60,MOSSY_COBBLESTONE:0,5,SMOOTH_BRICK:0,10,SMOOTH_BRICK:1,10,SMOOTH_BRICK:2,10,COBBLESTONE:0,100)
Block(0,1,-3,DIRT:0)
RandomBlock(0,1,-2,COBBLESTONE:0,60,MOSSY_COBBLESTONE:0,5,SMOOTH_BRICK:0,10,SMOOTH_BRICK:1,10,SMOOTH_BRICK:2,10,COBBLESTONE:0,100)
RandomBlock(0,1,-1,COBBLESTONE:0,60,MOSSY_COBBLESTONE:0,5,SMOOTH_BRICK:0,10,SMOOTH_BRICK:1,10,SMOOTH_BRICK:2,10,COBBLESTONE:0,100)
Block(0,1,0,DIRT:0)
Block(0,1,1,DIRT:0)
Block(0,1,2,DIRT:0)
Block(0,1,3,GRASS:0)
Block(0,1,4,GRASS:0)
Block(0,1,5,DIRT:0)
Block(0,1,6,DIRT:0)
Block(0,1,7,GRASS:0)
Block(0,2,-7,DIRT:0)
RandomBlock(0,2,-6,COBBLESTONE:0,60,MOSSY_COBBLESTONE:0,5,SMOOTH_BRICK:0,10,SMOOTH_BRICK:1,10,SMOOTH_BRICK:2,10,COBBLESTONE:0,100)
RandomBlock(0,2,-5,COBBLESTONE:0,60,MOSSY_COBBLESTONE:0,5,SMOOTH_BRICK:0,10,SMOOTH_BRICK:1,10,SMOOTH_BRICK:2,10,COBBLESTONE:0,100)
RandomBlock(0,2,-4,COBBLESTONE:0,60,MOSSY_COBBLESTONE:0,5,SMOOTH_BRICK:0,10,SMOOTH_BRICK:1,10,SMOOTH_BRICK:2,10,COBBLESTONE:0,100)
Block(0,2,-3,COAL_ORE:0)
Block(0,2,-2,COAL_BLOCK:0)
RandomBlock(0,2,0,COBBLESTONE:0,60,MOSSY_COBBLESTONE:0,5,SMOOTH_BRICK:0,10,SMOOTH_BRICK:1,10,SMOOTH_BRICK:2,10,COBBLESTONE:0,100)
Block(0,2,1,DIRT:1)
Block(0,2,2,DIRT:0)
Block(0,2,3,GRASS_PATH:0)
Block(0,2,4,GRASS_PATH:0)
Block(0,2,5,GRASS:0)
Block(0,2,6,GRASS:0)
Block(0,3,-7,DIRT:1)
Block(0,3,-6,SPRUCE_FENCE:0)
Block(0,3,1,DIRT:1)
Block(0,3,2,DIRT:1)
Block(0,4,-7,SPRUCE_FENCE:0)
Block(0,4,-6,SPRUCE_FENCE:0)
Block(0,4,2,SPRUCE_FENCE:0)
Block(0,5,-7,SPRUCE_FENCE:0)
Block(0,5,-6,SPRUCE_FENCE:0)
Block(0,5,2,SPRUCE_FENCE:0)
RandomBlock(0,6,-7,WOOD_STEP:1,70,WOOD_STEP:5,100)
RandomBlock(0,6,-6,WOOD_STEP:9,70,WOOD_STEP:13,100)
Block(0,6,2,SPRUCE_FENCE:0)
RandomBlock(0,7,-6,WOOD_STEP:1,70,WOOD_STEP:5,100)
RandomBlock(0,7,-5,WOOD_STEP:1,70,WOOD_STEP:5,100)
RandomBlock(0,7,-4,WOOD_STEP:9,70,WOOD_STEP:13,100)
RandomBlock(0,7,-3,WOOD_STEP:9,70,WOOD_STEP:13,100)
RandomBlock(0,7,-2,WOOD_STEP:9,70,WOOD_STEP:13,100)
Block(0,7,-1,WOOD_DOUBLE_STEP:1)
RandomBlock(0,7,0,WOOD_STEP:1,70,WOOD_STEP:5,100)
RandomBlock(0,7,1,WOOD_STEP:1,70,WOOD_STEP:5,100)
RandomBlock(0,7,2,WOOD_STEP:1,70,WOOD_STEP:5,100)
Block(0,8,-3,WOOD_BUTTON:1)
Block(1,0,-7,DIRT:0)
Block(1,0,-6,DIRT:0)
Block(1,0,-5,DIRT:0)
RandomBlock(1,0,-4,COBBLESTONE:0,60,MOSSY_COBBLESTONE:0,5,SMOOTH_BRICK:0,10,SMOOTH_BRICK:1,10,SMOOTH_BRICK:2,10,COBBLESTONE:0,100)
RandomBlock(1,0,-3,COBBLESTONE:0,60,MOSSY_COBBLESTONE:0,5,SMOOTH_BRICK:0,10,SMOOTH_BRICK:1,10,SMOOTH_BRICK:2,10,COBBLESTONE:0,100)
RandomBlock(1,0,-2,COBBLESTONE:0,60,MOSSY_COBBLESTONE:0,5,SMOOTH_BRICK:0,10,SMOOTH_BRICK:1,10,SMOOTH_BRICK:2,10,COBBLESTONE:0,100)
RandomBlock(1,0,-1,COBBLESTONE:0,60,MOSSY_COBBLESTONE:0,5,SMOOTH_BRICK:0,10,SMOOTH_BRICK:1,10,SMOOTH_BRICK:2,10,COBBLESTONE:0,100)
Block(1,0,0,DIRT:0)
Block(1,0,1,DIRT:0)
Block(1,0,2,DIRT:0)
Block(1,0,3,DIRT:0)
Block(1,0,4,DIRT:0)
Block(1,0,5,DIRT:0)
Block(1,0,6,DIRT:0)
Block(1,0,7,DIRT:0)
Block(1,1,-7,DIRT:0)
Block(1,1,-6,DIRT:0)
Block(1,1,-5,DIRT:0)
RandomBlock(1,1,-4,COBBLESTONE:0,60,MOSSY_COBBLESTONE:0,5,SMOOTH_BRICK:0,10,SMOOTH_BRICK:1,10,SMOOTH_BRICK:2,10,COBBLESTONE:0,100)
RandomBlock(1,1,-3,COBBLESTONE:0,60,MOSSY_COBBLESTONE:0,5,SMOOTH_BRICK:0,10,SMOOTH_BRICK:1,10,SMOOTH_BRICK:2,10,COBBLESTONE:0,100)
RandomBlock(1,1,-2,COBBLESTONE:0,60,MOSSY_COBBLESTONE:0,5,SMOOTH_BRICK:0,10,SMOOTH_BRICK:1,10,SMOOTH_BRICK:2,10,COBBLESTONE:0,100)
RandomBlock(1,1,-1,COBBLESTONE:0,60,MOSSY_COBBLESTONE:0,5,SMOOTH_BRICK:0,10,SMOOTH_BRICK:1,10,SMOOTH_BRICK:2,10,COBBLESTONE:0,100)
Block(1,1,0,DIRT:0)
Block(1,1,1,DIRT:0)
Block(1,1,2,GRASS:0)
Block(1,1,3,DIRT:0)
Block(1,1,4,GRASS:0)
Block(1,1,5,GRASS:0)
Block(1,1,6,DIRT:0)
Block(1,1,7,GRASS:0)
RandomBlock(1,2,-7,COBBLESTONE:0,60,MOSSY_COBBLESTONE:0,5,SMOOTH_BRICK:0,10,SMOOTH_BRICK:1,10,SMOOTH_BRICK:2,10,COBBLESTONE:0,100)
Block(1,2,-6,GRASS_PATH:0)
Block(1,2,-5,COBBLESTONE_STAIRS:3)
Block(1,2,0,COBBLESTONE_STAIRS:2)
RandomBlock(1,2,1,COBBLESTONE:0,60,MOSSY_COBBLESTONE:0,5,SMOOTH_BRICK:0,10,SMOOTH_BRICK:1,10,SMOOTH_BRICK:2,10,COBBLESTONE:0,100)
Block(1,2,2,GRASS_PATH:0)
RandomBlock(1,2,3,COBBLESTONE:0,60,MOSSY_COBBLESTONE:0,5,SMOOTH_BRICK:0,10,SMOOTH_BRICK:1,10,SMOOTH_BRICK:2,10,COBBLESTONE:0,100)
Block(1,2,4,GRASS_PATH:0)
Block(1,2,5,GRASS_PATH:0)
Block(1,2,6,GRASS:0)
Block(1,3,6,SPRUCE_FENCE:0)
Block(1,5,-7,SPRUCE_FENCE:0)
Block(1,5,2,SPRUCE_FENCE:0)
Block(1,6,-7,WOOD_DOUBLE_STEP:1)
RandomBlock(1,6,-6,WOOD_STEP:9,70,WOOD_STEP:13,100)
RandomBlock(1,6,-5,WOOD_STEP:9,70,WOOD_STEP:13,100)
Block(1,6,-4,WEB:0)
Block(1,6,-3,WEB:0)
Block(1,6,-2,WEB:0)
RandomBlock(1,6,-1,WOOD_STEP:9,70,WOOD_STEP:13,100)
RandomBlock(1,6,0,WOOD_STEP:9,70,WOOD_STEP:13,100)
RandomBlock(1,6,1,WOOD_STEP:9,70,WOOD_STEP:13,100)
Block(1,6,2,WOOD_DOUBLE_STEP:1)
RandomBlock(1,7,-6,WOOD_STEP:1,70,WOOD_STEP:5,100)
RandomBlock(1,7,-5,WOOD_STEP:1,70,WOOD_STEP:5,100)
Block(1,7,-4,WOOD_DOUBLE_STEP:1)
RandomBlock(1,7,-3,WOOD_STEP:1,70,WOOD_STEP:5,100)
RandomBlock(1,7,-2,WOOD_STEP:1,70,WOOD_STEP:5,100)
Block(2,0,-7,DIRT:0)
Block(2,0,-6,DIRT:0)
Block(2,0,-5,DIRT:0)
RandomBlock(2,0,-4,COBBLESTONE:0,60,MOSSY_COBBLESTONE:0,5,SMOOTH_BRICK:0,10,SMOOTH_BRICK:1,10,SMOOTH_BRICK:2,10,COBBLESTONE:0,100)
RandomBlock(2,0,-3,COBBLESTONE:0,60,MOSSY_COBBLESTONE:0,5,SMOOTH_BRICK:0,10,SMOOTH_BRICK:1,10,SMOOTH_BRICK:2,10,COBBLESTONE:0,100)
RandomBlock(2,0,-2,COBBLESTONE:0,60,MOSSY_COBBLESTONE:0,5,SMOOTH_BRICK:0,10,SMOOTH_BRICK:1,10,SMOOTH_BRICK:2,10,COBBLESTONE:0,100)
RandomBlock(2,0,-1,COBBLESTONE:0,60,MOSSY_COBBLESTONE:0,5,SMOOTH_BRICK:0,10,SMOOTH_BRICK:1,10,SMOOTH_BRICK:2,10,COBBLESTONE:0,100)
RandomBlock(2,0,0,COBBLESTONE:0,60,MOSSY_COBBLESTONE:0,5,SMOOTH_BRICK:0,10,SMOOTH_BRICK:1,10,SMOOTH_BRICK:2,10,COBBLESTONE:0,100)
Block(2,0,1,DIRT:0)
Block(2,0,2,DIRT:0)
Block(2,0,3,DIRT:0)
Block(2,0,4,DIRT:0)
Block(2,0,5,DIRT:0)
Block(2,0,6,DIRT:0)
Block(2,0,7,DIRT:0)
Block(2,1,-7,DIRT:0)
Block(2,1,-6,DIRT:0)
Block(2,1,-5,DIRT:0)
RandomBlock(2,1,-4,COBBLESTONE:0,60,MOSSY_COBBLESTONE:0,5,SMOOTH_BRICK:0,10,SMOOTH_BRICK:1,10,SMOOTH_BRICK:2,10,COBBLESTONE:0,100)
RandomBlock(2,1,-3,COBBLESTONE:0,60,MOSSY_COBBLESTONE:0,5,SMOOTH_BRICK:0,10,SMOOTH_BRICK:1,10,SMOOTH_BRICK:2,10,COBBLESTONE:0,100)
RandomBlock(2,1,-2,COBBLESTONE:0,60,MOSSY_COBBLESTONE:0,5,SMOOTH_BRICK:0,10,SMOOTH_BRICK:1,10,SMOOTH_BRICK:2,10,COBBLESTONE:0,100)
RandomBlock(2,1,-1,COBBLESTONE:0,60,MOSSY_COBBLESTONE:0,5,SMOOTH_BRICK:0,10,SMOOTH_BRICK:1,10,SMOOTH_BRICK:2,10,COBBLESTONE:0,100)
RandomBlock(2,1,0,COBBLESTONE:0,60,MOSSY_COBBLESTONE:0,5,SMOOTH_BRICK:0,10,SMOOTH_BRICK:1,10,SMOOTH_BRICK:2,10,COBBLESTONE:0,100)
Block(2,1,1,DIRT:0)
Block(2,1,2,DIRT:0)
Block(2,1,3,DIRT:0)
Block(2,1,4,DIRT:0)
Block(2,1,5,DIRT:0)
Block(2,1,6,DIRT:0)
Block(2,1,7,GRASS:0)
Block(2,2,-7,GRASS_PATH:0)
RandomBlock(2,2,-6,COBBLESTONE:0,60,MOSSY_COBBLESTONE:0,5,SMOOTH_BRICK:0,10,SMOOTH_BRICK:1,10,SMOOTH_BRICK:2,10,COBBLESTONE:0,100)
Block(2,2,-5,COBBLESTONE_STAIRS:3)
Block(2,2,0,COBBLESTONE_STAIRS:2)
RandomBlock(2,2,1,COBBLESTONE:0,60,MOSSY_COBBLESTONE:0,5,SMOOTH_BRICK:0,10,SMOOTH_BRICK:1,10,SMOOTH_BRICK:2,10,COBBLESTONE:0,100)
Block(2,2,2,GRASS_PATH:0)
RandomBlock(2,2,3,COBBLESTONE:0,60,MOSSY_COBBLESTONE:0,5,SMOOTH_BRICK:0,10,SMOOTH_BRICK:1,10,SMOOTH_BRICK:2,10,COBBLESTONE:0,100)
RandomBlock(2,2,4,COBBLESTONE:0,60,MOSSY_COBBLESTONE:0,5,SMOOTH_BRICK:0,10,SMOOTH_BRICK:1,10,SMOOTH_BRICK:2,10,COBBLESTONE:0,100)
Block(2,2,5,GRASS:0)
Block(2,2,6,GRASS:0)
Block(2,3,5,SPRUCE_FENCE:0)
Block(2,3,6,SPRUCE_FENCE:0)
Block(2,5,-7,SPRUCE_FENCE:0)
Block(2,5,-6,SPRUCE_FENCE:0)
Block(2,5,2,SPRUCE_FENCE:0)
RandomBlock(2,6,-7,WOOD_STEP:1,70,WOOD_STEP:5,100)
Block(2,6,-6,WOOD_DOUBLE_STEP:1)
RandomBlock(2,6,-5,WOOD_STEP:9,70,WOOD_STEP:13,100)
RandomBlock(2,6,-4,WOOD_STEP:9,70,WOOD_STEP:13,100)
RandomBlock(2,6,-3,WOOD_STEP:9,70,WOOD_STEP:13,100)
RandomBlock(2,6,-2,WOOD_STEP:9,70,WOOD_STEP:13,100)
RandomBlock(2,6,-1,WOOD_STEP:9,70,WOOD_STEP:13,100)
RandomBlock(2,6,0,WOOD_STEP:9,70,WOOD_STEP:13,100)
RandomBlock(2,6,1,WOOD_STEP:1,70,WOOD_STEP:5,100)
RandomBlock(2,6,2,WOOD_STEP:1,70,WOOD_STEP:5,100)
RandomBlock(2,6,3,WOOD_STEP:1,70,WOOD_STEP:5,100)
RandomBlock(2,7,-4,WOOD_STEP:1,70,WOOD_STEP:5,100)
RandomBlock(2,7,-1,WOOD_STEP:1,70,WOOD_STEP:5,100)
Block(3,0,-7,DIRT:0)
Block(3,0,-6,DIRT:0)
Block(3,0,-5,DIRT:0)
Block(3,0,-4,DIRT:0)
Block(3,0,-3,DIRT:0)
RandomBlock(3,0,-2,COBBLESTONE:0,60,MOSSY_COBBLESTONE:0,5,SMOOTH_BRICK:0,10,SMOOTH_BRICK:1,10,SMOOTH_BRICK:2,10,COBBLESTONE:0,100)
RandomBlock(3,0,-1,COBBLESTONE:0,60,MOSSY_COBBLESTONE:0,5,SMOOTH_BRICK:0,10,SMOOTH_BRICK:1,10,SMOOTH_BRICK:2,10,COBBLESTONE:0,100)
Block(3,0,0,DIRT:0)
Block(3,0,1,DIRT:0)
Block(3,0,2,DIRT:0)
Block(3,0,3,DIRT:0)
Block(3,0,4,DIRT:0)
Block(3,0,5,DIRT:0)
Block(3,0,6,DIRT:0)
Block(3,1,-7,DIRT:0)
Block(3,1,-6,DIRT:0)
Block(3,1,-5,DIRT:0)
Block(3,1,-4,DIRT:0)
Block(3,1,-3,DIRT:0)
RandomBlock(3,1,-2,COBBLESTONE:0,60,MOSSY_COBBLESTONE:0,5,SMOOTH_BRICK:0,10,SMOOTH_BRICK:1,10,SMOOTH_BRICK:2,10,COBBLESTONE:0,100)
RandomBlock(3,1,-1,COBBLESTONE:0,60,MOSSY_COBBLESTONE:0,5,SMOOTH_BRICK:0,10,SMOOTH_BRICK:1,10,SMOOTH_BRICK:2,10,COBBLESTONE:0,100)
Block(3,1,0,DIRT:0)
Block(3,1,1,DIRT:0)
Block(3,1,2,DIRT:0)
Block(3,1,3,GRASS:0)
Block(3,1,4,DIRT:0)
Block(3,1,5,DIRT:0)
Block(3,1,6,GRASS:0)
Block(3,2,-7,DIRT:0)
Block(3,2,-6,DIRT:0)
Block(3,2,-5,DIRT:1)
Block(3,2,-4,COAL_ORE:0)
Block(3,2,-3,COAL_BLOCK:0)
Block(3,2,0,COAL_ORE:0)
Block(3,2,1,COAL_ORE:0)
Block(3,2,2,LOG:1)
Block(3,2,3,GRASS_PATH:0)
Block(3,2,4,GRASS:0)
Block(3,2,5,GRASS:0)
Block(3,3,-7,DIRT:1)
Block(3,3,-6,DIRT:1)
Block(3,3,2,LOG:1)
Block(3,3,4,SPRUCE_FENCE:0)
Block(3,3,5,SPRUCE_FENCE:0)
Block(3,4,-7,SPRUCE_FENCE:0)
Block(3,4,-6,SPRUCE_FENCE:0)
Block(3,4,2,LOG:1)
Block(3,5,-6,SPRUCE_FENCE:0)
Block(3,5,2,LOG:1)
RandomBlock(3,6,-7,WOOD_STEP:1,70,WOOD_STEP:5,100)
Block(3,6,-6,WOOD_DOUBLE_STEP:1)
Block(3,6,-5,WOOD_DOUBLE_STEP:1)
RandomBlock(3,6,-4,WOOD_STEP:9,70,WOOD_STEP:13,100)
RandomBlock(3,6,-3,WOOD_STEP:9,70,WOOD_STEP:13,100)
RandomBlock(3,6,-2,WOOD_STEP:9,70,WOOD_STEP:13,100)
RandomBlock(3,6,-1,WOOD_STEP:9,70,WOOD_STEP:13,100)
RandomBlock(3,6,0,WOOD_STEP:1,70,WOOD_STEP:5,100)
RandomBlock(3,6,1,WOOD_STEP:1,70,WOOD_STEP:5,100)
RandomBlock(3,6,2,WOOD_STEP:1,70,WOOD_STEP:5,100)
Block(4,0,-7,DIRT:0)
Block(4,0,-6,DIRT:0)
Block(4,0,-5,DIRT:0)
Block(4,0,-4,DIRT:0)
Block(4,0,-3,DIRT:0)
Block(4,0,-2,DIRT:0)
Block(4,0,-1,DIRT:0)
Block(4,0,0,DIRT:0)
Block(4,0,1,DIRT:0)
Block(4,0,2,DIRT:0)
Block(4,0,3,DIRT:0)
Block(4,0,4,DIRT:0)
Block(4,0,5,DIRT:0)
Block(4,0,6,DIRT:0)
Block(4,1,-7,DIRT:0)
Block(4,1,-6,DIRT:0)
Block(4,1,-5,DIRT:0)
Block(4,1,-4,DIRT:0)
Block(4,1,-3,DIRT:0)
Block(4,1,-2,DIRT:0)
Block(4,1,-1,DIRT:0)
Block(4,1,0,DIRT:0)
Block(4,1,1,DIRT:0)
Block(4,1,2,DIRT:0)
Block(4,1,3,DIRT:0)
Block(4,1,4,DIRT:0)
Block(4,1,5,DIRT:0)
Block(4,1,6,GRASS:0)
Block(4,2,-7,DIRT:0)
Block(4,2,-6,LOG:1)
Block(4,2,-5,DIRT:0)
Block(4,2,-4,DIRT:0)
Block(4,2,-3,COAL_ORE:0)
Block(4,2,-2,COAL_BLOCK:0)
Block(4,2,-1,COAL_ORE:0)
Block(4,2,0,COAL_ORE:0)
Block(4,2,1,DIRT:1)
Block(4,2,2,DIRT:1)
Block(4,2,3,GRASS:0)
Block(4,2,4,GRASS:0)
Block(4,2,5,GRASS:0)
Block(4,3,-7,DIRT:1)
Block(4,3,-6,LOG:1)
Block(4,3,-5,DIRT:1)
Block(4,3,-4,COAL_BLOCK:0)
Block(4,3,1,COAL_ORE:0)
Block(4,3,2,DIRT:1)
Block(4,3,3,SPRUCE_FENCE:0)
Block(4,3,4,SPRUCE_FENCE:0)
Block(4,4,-7,GRASS:0)
Block(4,4,-6,LOG:1)
Block(4,4,2,SPRUCE_FENCE:0)
Block(4,5,-7,SPRUCE_FENCE:0)
Block(4,5,-6,LOG:1)
Block(4,5,2,SPRUCE_FENCE:0)
RandomBlock(4,6,-7,WOOD_STEP:1,70,WOOD_STEP:5,100)
RandomBlock(4,6,-6,WOOD_STEP:1,70,WOOD_STEP:5,100)
RandomBlock(4,6,-5,WOOD_STEP:9,70,WOOD_STEP:13,100)
Block(4,6,-4,WOOD_DOUBLE_STEP:1)
RandomBlock(4,6,-3,WOOD_STEP:1,70,WOOD_STEP:5,100)
RandomBlock(4,6,-2,WOOD_STEP:1,70,WOOD_STEP:5,100)
RandomBlock(4,6,-1,WOOD_STEP:1,70,WOOD_STEP:5,100)
RandomBlock(4,6,0,WOOD_STEP:1,70,WOOD_STEP:5,100)
RandomBlock(4,6,1,WOOD_STEP:1,70,WOOD_STEP:5,100)
Block(5,0,-7,DIRT:0)
Block(5,0,-6,DIRT:0)
Block(5,0,-5,DIRT:0)
Block(5,0,-4,DIRT:0)
Block(5,0,-3,DIRT:0)
Block(5,0,-2,DIRT:0)
Block(5,0,-1,DIRT:0)
Block(5,0,0,DIRT:0)
Block(5,0,1,DIRT:0)
Block(5,0,2,DIRT:0)
Block(5,0,3,DIRT:0)
Block(5,0,4,DIRT:0)
Block(5,0,5,DIRT:0)
Block(5,0,6,DIRT:0)
Block(5,1,-7,DIRT:0)
Block(5,1,-6,DIRT:0)
Block(5,1,-5,DIRT:0)
Block(5,1,-4,DIRT:0)
Block(5,1,-3,DIRT:0)
Block(5,1,-2,DIRT:0)
Block(5,1,-1,DIRT:0)
Block(5,1,0,DIRT:0)
Block(5,1,1,DIRT:0)
Block(5,1,2,DIRT:0)
Block(5,1,3,DIRT:0)
Block(5,1,4,DIRT:0)
Block(5,1,5,GRASS:0)
Block(5,1,6,GRASS:0)
Block(5,2,-7,DIRT:0)
Block(5,2,-6,DIRT:0)
Block(5,2,-5,DIRT:0)
Block(5,2,-4,DIRT:0)
Block(5,2,-3,LOG:1)
Block(5,2,-2,DIRT:0)
Block(5,2,-1,DIRT:1)
Block(5,2,0,LOG:1)
Block(5,2,1,DIRT:0)
Block(5,2,2,DIRT:0)
Block(5,2,3,DIRT:0)
Block(5,2,4,DIRT:0)
Block(5,3,-7,DIRT:1)
Block(5,3,-6,DIRT:0)
Block(5,3,-5,DIRT:0)
Block(5,3,-4,DIRT:0)
Block(5,3,-3,LOG:1)
Block(5,3,-2,GRASS:0)
Block(5,3,-1,DIRT:0)
Block(5,3,0,LOG:1)
Block(5,3,1,DIRT:0)
Block(5,3,2,DIRT:1)
Block(5,3,3,GRASS:0)
Block(5,3,4,GRASS:0)
Block(5,4,-6,GRASS:0)
Block(5,4,-5,GRASS:0)
Block(5,4,-4,DIRT:1)
Block(5,4,-3,LOG:1)
Block(5,4,-2,SPRUCE_FENCE:0)
Block(5,4,-1,DIRT:1)
Block(5,4,0,LOG:1)
Block(5,4,1,GRASS:0)
Block(5,4,2,GRASS:0)
Block(5,5,-6,SPRUCE_FENCE:0)
Block(5,5,-5,SPRUCE_FENCE:0)
Block(5,5,-4,SPRUCE_FENCE:0)
Block(5,5,-3,LOG:1)
Block(5,5,-1,SPRUCE_FENCE:0)
Block(5,5,0,LOG:1)
Block(5,5,1,SPRUCE_FENCE:0)
Block(5,5,2,SPRUCE_FENCE:0)
RandomBlock(5,6,-6,WOOD_STEP:1,70,WOOD_STEP:5,100)
RandomBlock(5,6,-5,WOOD_STEP:1,70,WOOD_STEP:5,100)
RandomBlock(5,6,-4,WOOD_STEP:1,70,WOOD_STEP:5,100)
RandomBlock(5,6,-3,WOOD_STEP:1,70,WOOD_STEP:5,100)
RandomBlock(5,6,0,WOOD_STEP:1,70,WOOD_STEP:5,100)
Block(6,0,-7,DIRT:0)
Block(6,0,-6,DIRT:0)
Block(6,0,-5,DIRT:0)
Block(6,0,-4,DIRT:0)
Block(6,0,-3,DIRT:0)
Block(6,0,-2,DIRT:0)
Block(6,0,-1,DIRT:0)
Block(6,0,0,DIRT:0)
Block(6,0,1,DIRT:0)
Block(6,0,2,DIRT:0)
Block(6,0,3,DIRT:0)
Block(6,0,4,DIRT:0)
Block(6,0,5,DIRT:0)
Block(6,1,-7,DIRT:0)
Block(6,1,-6,DIRT:0)
Block(6,1,-5,DIRT:0)
Block(6,1,-4,DIRT:0)
Block(6,1,-3,DIRT:0)
Block(6,1,-2,DIRT:0)
Block(6,1,-1,DIRT:0)
Block(6,1,0,DIRT:0)
Block(6,1,1,DIRT:0)
Block(6,1,2,DIRT:0)
Block(6,1,3,DIRT:0)
Block(6,1,4,DIRT:0)
Block(6,1,5,GRASS:0)
Block(6,2,-7,GRASS:0)
Block(6,2,-6,DIRT:0)
Block(6,2,-5,DIRT:0)
Block(6,2,-4,DIRT:0)
Block(6,2,-3,GRASS:0)
Block(6,2,-2,DIRT:0)
Block(6,2,-1,DIRT:0)
Block(6,2,0,DIRT:0)
Block(6,2,1,DIRT:0)
Block(6,2,2,DIRT:0)
Block(6,2,3,DIRT:0)
Block(6,2,4,GRASS:0)
Block(6,3,-6,DIRT:1)
Block(6,3,-5,GRASS:0)
Block(6,3,-4,DIRT:1)
Block(6,3,-3,SPRUCE_FENCE:0)
Block(6,3,-2,DIRT:1)
Block(6,3,-1,DIRT:1)
Block(6,3,0,GRASS:0)
Block(6,3,1,DIRT:1)
Block(6,3,2,GRASS:0)
Block(6,3,3,GRASS:0)
Block(6,4,-4,SPRUCE_FENCE:0)
Block(6,4,-2,SPRUCE_FENCE:0)
Block(6,4,0,SPRUCE_FENCE:0)
Block(6,4,1,GRASS:0)
Block(7,0,-7,DIRT:0)
Block(7,0,-6,DIRT:0)
Block(7,0,-5,DIRT:0)
Block(7,0,-4,DIRT:0)
Block(7,0,-3,DIRT:0)
Block(7,0,-2,DIRT:0)
Block(7,0,-1,DIRT:0)
Block(7,0,0,DIRT:0)
Block(7,0,1,DIRT:0)
Block(7,0,2,DIRT:0)
Block(7,0,3,DIRT:0)
Block(7,0,4,DIRT:0)
Block(7,0,5,DIRT:0)
Block(7,1,-7,GRASS:0)
Block(7,1,-6,DIRT:0)
Block(7,1,-5,DIRT:0)
Block(7,1,-4,DIRT:0)
Block(7,1,-3,GRASS:0)
Block(7,1,-2,GRASS:0)
Block(7,1,-1,GRASS:0)
Block(7,1,0,DIRT:0)
Block(7,1,1,DIRT:0)
Block(7,1,2,DIRT:0)
Block(7,1,3,DIRT:0)
Block(7,1,4,GRASS:0)
Block(7,1,5,GRASS:0)
Block(7,2,-6,GRASS:0)
Block(7,2,-5,GRASS:0)
Block(7,2,-4,GRASS:0)
Block(7,2,0,GRASS:0)
Block(7,2,1,GRASS:0)
Block(7,2,2,DIRT:0)
Block(7,2,3,GRASS:0)
Block(7,3,0,SPRUCE_FENCE:0)
Block(7,3,1,SPRUCE_FENCE:0)
Block(7,3,2,GRASS:0)
Branch(-16,0,0,true,viking_blacksmithC0R1,NORTH,100.0,0)
Entity(-6,3,-2,minecraft:zombie_villager,1,../../NBT/Entities/VikingVillage/stank_walker.txt)
