Author: NLBlackEagle
Description: No description given
SettingsMode: WriteDisable
Frequency: 10
SpawnHeight: highestBlock
UseCenterForHighestBlock: true
MinHeight: 63
MaxHeight: 255
InheritBO3: 
InheritBO3Rotation: NORTH
OverrideChildSettings: true
OverrideParentHeight: false
CanOverride: true
BranchFrequency: 5
BranchFrequencyGroup: 
MustBeBelowOther: false
MustBeInside: 
CannotBeInside: 
ReplacesBO3: 
MustBeInsideWorldBorders: false
CanSpawnOnWater: false
SpawnOnWaterOnly: false
SpawnUnderWater: false
SpawnAtWaterLevel: false
HeightOffset: -3
RemoveAir: false
ReplaceAbove: 
ReplaceBelow: cobblestone
ReplaceWithBiomeBlocks: true
ReplaceWithSurfaceBlock: GRASS
ReplaceWithGroundBlock: DIRT
ReplaceWithStoneBlock: STONE
SmoothRadius: 0
SmoothHeightOffset: 0
SmoothStartTop: false
SmoothStartWood: false
SmoothingSurfaceBlock: 
SmoothingGroundBlock: 
BO3Group: 
IsSpawnPoint: false
DoReplaceBlocks: true
RandomBlock(-4,6,-5,SPRUCE_WOOD_STAIRS:0,70,DARK_OAK_STAIRS:0,100)
RandomBlock(-4,6,-4,SPRUCE_WOOD_STAIRS:0,70,DARK_OAK_STAIRS:0,100)
RandomBlock(-4,6,-3,SPRUCE_WOOD_STAIRS:0,70,DARK_OAK_STAIRS:0,100)
RandomBlock(-4,6,-2,SPRUCE_WOOD_STAIRS:0,70,DARK_OAK_STAIRS:0,100)
RandomBlock(-4,6,-1,SPRUCE_WOOD_STAIRS:0,70,DARK_OAK_STAIRS:0,100)
RandomBlock(-4,6,0,SPRUCE_WOOD_STAIRS:0,70,DARK_OAK_STAIRS:0,100)
RandomBlock(-4,6,1,SPRUCE_WOOD_STAIRS:0,70,DARK_OAK_STAIRS:0,100)
RandomBlock(-4,6,2,SPRUCE_WOOD_STAIRS:0,70,DARK_OAK_STAIRS:0,100)
RandomBlock(-4,6,3,SPRUCE_WOOD_STAIRS:0,70,DARK_OAK_STAIRS:0,100)
RandomBlock(-4,6,4,SPRUCE_WOOD_STAIRS:0,70,DARK_OAK_STAIRS:0,100)
RandomBlock(-4,6,5,SPRUCE_WOOD_STAIRS:0,70,DARK_OAK_STAIRS:0,100)
RandomBlock(-4,6,6,SPRUCE_WOOD_STAIRS:0,70,DARK_OAK_STAIRS:0,100)
RandomBlock(-4,6,7,SPRUCE_WOOD_STAIRS:0,70,DARK_OAK_STAIRS:0,100)
RandomBlock(-4,6,8,SPRUCE_WOOD_STAIRS:0,70,DARK_OAK_STAIRS:0,100)
Block(-3,0,-4,LOG:1)
RandomBlock(-3,0,-3,COBBLESTONE:0,60,MOSSY_COBBLESTONE:0,5,SMOOTH_BRICK:0,10,SMOOTH_BRICK:1,10,SMOOTH_BRICK:2,10,COBBLESTONE:0,100)
RandomBlock(-3,0,-2,COBBLESTONE:0,60,MOSSY_COBBLESTONE:0,5,SMOOTH_BRICK:0,10,SMOOTH_BRICK:1,10,SMOOTH_BRICK:2,10,COBBLESTONE:0,100)
RandomBlock(-3,0,-1,COBBLESTONE:0,60,MOSSY_COBBLESTONE:0,5,SMOOTH_BRICK:0,10,SMOOTH_BRICK:1,10,SMOOTH_BRICK:2,10,COBBLESTONE:0,100)
RandomBlock(-3,0,0,COBBLESTONE:0,60,MOSSY_COBBLESTONE:0,5,SMOOTH_BRICK:0,10,SMOOTH_BRICK:1,10,SMOOTH_BRICK:2,10,COBBLESTONE:0,100)
RandomBlock(-3,0,1,COBBLESTONE:0,60,MOSSY_COBBLESTONE:0,5,SMOOTH_BRICK:0,10,SMOOTH_BRICK:1,10,SMOOTH_BRICK:2,10,COBBLESTONE:0,100)
Block(-3,0,2,LOG:1)
RandomBlock(-3,0,3,COBBLESTONE:0,60,MOSSY_COBBLESTONE:0,5,SMOOTH_BRICK:0,10,SMOOTH_BRICK:1,10,SMOOTH_BRICK:2,10,COBBLESTONE:0,100)
RandomBlock(-3,0,4,COBBLESTONE:0,60,MOSSY_COBBLESTONE:0,5,SMOOTH_BRICK:0,10,SMOOTH_BRICK:1,10,SMOOTH_BRICK:2,10,COBBLESTONE:0,100)
RandomBlock(-3,0,5,COBBLESTONE:0,60,MOSSY_COBBLESTONE:0,5,SMOOTH_BRICK:0,10,SMOOTH_BRICK:1,10,SMOOTH_BRICK:2,10,COBBLESTONE:0,100)
RandomBlock(-3,0,6,COBBLESTONE:0,60,MOSSY_COBBLESTONE:0,5,SMOOTH_BRICK:0,10,SMOOTH_BRICK:1,10,SMOOTH_BRICK:2,10,COBBLESTONE:0,100)
Block(-3,0,7,LOG:1)
Block(-3,1,-4,LOG:1)
RandomBlock(-3,1,-3,COBBLESTONE:0,60,MOSSY_COBBLESTONE:0,5,SMOOTH_BRICK:0,10,SMOOTH_BRICK:1,10,SMOOTH_BRICK:2,10,COBBLESTONE:0,100)
RandomBlock(-3,1,-2,COBBLESTONE:0,60,MOSSY_COBBLESTONE:0,5,SMOOTH_BRICK:0,10,SMOOTH_BRICK:1,10,SMOOTH_BRICK:2,10,COBBLESTONE:0,100)
RandomBlock(-3,1,-1,COBBLESTONE:0,60,MOSSY_COBBLESTONE:0,5,SMOOTH_BRICK:0,10,SMOOTH_BRICK:1,10,SMOOTH_BRICK:2,10,COBBLESTONE:0,100)
RandomBlock(-3,1,0,COBBLESTONE:0,60,MOSSY_COBBLESTONE:0,5,SMOOTH_BRICK:0,10,SMOOTH_BRICK:1,10,SMOOTH_BRICK:2,10,COBBLESTONE:0,100)
RandomBlock(-3,1,1,COBBLESTONE:0,60,MOSSY_COBBLESTONE:0,5,SMOOTH_BRICK:0,10,SMOOTH_BRICK:1,10,SMOOTH_BRICK:2,10,COBBLESTONE:0,100)
Block(-3,1,2,LOG:1)
RandomBlock(-3,1,3,COBBLESTONE:0,60,MOSSY_COBBLESTONE:0,5,SMOOTH_BRICK:0,10,SMOOTH_BRICK:1,10,SMOOTH_BRICK:2,10,COBBLESTONE:0,100)
RandomBlock(-3,1,4,COBBLESTONE:0,60,MOSSY_COBBLESTONE:0,5,SMOOTH_BRICK:0,10,SMOOTH_BRICK:1,10,SMOOTH_BRICK:2,10,COBBLESTONE:0,100)
RandomBlock(-3,1,5,COBBLESTONE:0,60,MOSSY_COBBLESTONE:0,5,SMOOTH_BRICK:0,10,SMOOTH_BRICK:1,10,SMOOTH_BRICK:2,10,COBBLESTONE:0,100)
RandomBlock(-3,1,6,COBBLESTONE:0,60,MOSSY_COBBLESTONE:0,5,SMOOTH_BRICK:0,10,SMOOTH_BRICK:1,10,SMOOTH_BRICK:2,10,COBBLESTONE:0,100)
Block(-3,1,7,LOG:1)
Block(-3,2,-4,LOG:1)
RandomBlock(-3,2,-3,COBBLESTONE:0,60,MOSSY_COBBLESTONE:0,5,SMOOTH_BRICK:0,10,SMOOTH_BRICK:1,10,SMOOTH_BRICK:2,10,COBBLESTONE:0,100)
RandomBlock(-3,2,-2,COBBLESTONE:0,60,MOSSY_COBBLESTONE:0,5,SMOOTH_BRICK:0,10,SMOOTH_BRICK:1,10,SMOOTH_BRICK:2,10,COBBLESTONE:0,100)
RandomBlock(-3,2,-1,COBBLESTONE:0,60,MOSSY_COBBLESTONE:0,5,SMOOTH_BRICK:0,10,SMOOTH_BRICK:1,10,SMOOTH_BRICK:2,10,COBBLESTONE:0,100)
RandomBlock(-3,2,0,COBBLESTONE:0,60,MOSSY_COBBLESTONE:0,5,SMOOTH_BRICK:0,10,SMOOTH_BRICK:1,10,SMOOTH_BRICK:2,10,COBBLESTONE:0,100)
RandomBlock(-3,2,1,COBBLESTONE:0,60,MOSSY_COBBLESTONE:0,5,SMOOTH_BRICK:0,10,SMOOTH_BRICK:1,10,SMOOTH_BRICK:2,10,COBBLESTONE:0,100)
Block(-3,2,2,LOG:1)
RandomBlock(-3,2,3,COBBLESTONE:0,60,MOSSY_COBBLESTONE:0,5,SMOOTH_BRICK:0,10,SMOOTH_BRICK:1,10,SMOOTH_BRICK:2,10,COBBLESTONE:0,100)
RandomBlock(-3,2,4,COBBLESTONE:0,60,MOSSY_COBBLESTONE:0,5,SMOOTH_BRICK:0,10,SMOOTH_BRICK:1,10,SMOOTH_BRICK:2,10,COBBLESTONE:0,100)
RandomBlock(-3,2,5,COBBLESTONE:0,60,MOSSY_COBBLESTONE:0,5,SMOOTH_BRICK:0,10,SMOOTH_BRICK:1,10,SMOOTH_BRICK:2,10,COBBLESTONE:0,100)
RandomBlock(-3,2,6,COBBLESTONE:0,60,MOSSY_COBBLESTONE:0,5,SMOOTH_BRICK:0,10,SMOOTH_BRICK:1,10,SMOOTH_BRICK:2,10,COBBLESTONE:0,100)
Block(-3,2,7,LOG:1)
Block(-3,3,-4,LOG:1)
RandomBlock(-3,3,-3,COBBLESTONE:0,60,MOSSY_COBBLESTONE:0,5,SMOOTH_BRICK:0,10,SMOOTH_BRICK:1,10,SMOOTH_BRICK:2,10,COBBLESTONE:0,100)
RandomBlock(-3,3,-2,COBBLESTONE:0,60,MOSSY_COBBLESTONE:0,5,SMOOTH_BRICK:0,10,SMOOTH_BRICK:1,10,SMOOTH_BRICK:2,10,COBBLESTONE:0,100)
RandomBlock(-3,3,-1,COBBLESTONE:0,60,MOSSY_COBBLESTONE:0,5,SMOOTH_BRICK:0,10,SMOOTH_BRICK:1,10,SMOOTH_BRICK:2,10,COBBLESTONE:0,100)
RandomBlock(-3,3,0,COBBLESTONE:0,60,MOSSY_COBBLESTONE:0,5,SMOOTH_BRICK:0,10,SMOOTH_BRICK:1,10,SMOOTH_BRICK:2,10,COBBLESTONE:0,100)
RandomBlock(-3,3,1,COBBLESTONE:0,60,MOSSY_COBBLESTONE:0,5,SMOOTH_BRICK:0,10,SMOOTH_BRICK:1,10,SMOOTH_BRICK:2,10,COBBLESTONE:0,100)
Block(-3,3,2,LOG:1)
RandomBlock(-3,3,3,COBBLESTONE:0,60,MOSSY_COBBLESTONE:0,5,SMOOTH_BRICK:0,10,SMOOTH_BRICK:1,10,SMOOTH_BRICK:2,10,COBBLESTONE:0,100)
RandomBlock(-3,3,4,COBBLESTONE:0,60,MOSSY_COBBLESTONE:0,5,SMOOTH_BRICK:0,10,SMOOTH_BRICK:1,10,SMOOTH_BRICK:2,10,COBBLESTONE:0,100)
RandomBlock(-3,3,5,COBBLESTONE:0,60,MOSSY_COBBLESTONE:0,5,SMOOTH_BRICK:0,10,SMOOTH_BRICK:1,10,SMOOTH_BRICK:2,10,COBBLESTONE:0,100)
RandomBlock(-3,3,6,COBBLESTONE:0,60,MOSSY_COBBLESTONE:0,5,SMOOTH_BRICK:0,10,SMOOTH_BRICK:1,10,SMOOTH_BRICK:2,10,COBBLESTONE:0,100)
Block(-3,3,7,LOG:1)
Block(-3,4,-4,LOG:1)
Block(-3,4,-3,STAINED_CLAY:12)
Block(-3,4,-2,STAINED_CLAY:12)
Block(-3,4,-1,STAINED_CLAY:0)
Block(-3,4,0,STAINED_CLAY:12)
Block(-3,4,1,STAINED_CLAY:12)
Block(-3,4,2,LOG:1)
Block(-3,4,3,STAINED_CLAY:0)
Block(-3,4,4,STAINED_CLAY:12)
Block(-3,4,5,STAINED_CLAY:12)
Block(-3,4,6,STAINED_CLAY:12)
Block(-3,4,7,LOG:1)
Block(-3,5,-4,LOG:1)
Block(-3,5,-3,STAINED_CLAY:12)
Block(-3,5,-2,STAINED_CLAY:0)
Block(-3,5,-1,STAINED_CLAY:0)
Block(-3,5,0,STAINED_CLAY:0)
Block(-3,5,1,STAINED_CLAY:0)
Block(-3,5,2,LOG:1)
Block(-3,5,3,STAINED_CLAY:0)
Block(-3,5,4,STAINED_CLAY:0)
Block(-3,5,5,STAINED_CLAY:0)
Block(-3,5,6,STAINED_CLAY:12)
Block(-3,5,7,LOG:1)
Block(-3,6,-5,SPRUCE_WOOD_STAIRS:5)
Block(-3,6,-4,LOG:1)
Block(-3,6,-3,STAINED_CLAY:12)
Block(-3,6,-2,STAINED_CLAY:12)
Block(-3,6,-1,STAINED_CLAY:12)
Block(-3,6,0,STAINED_CLAY:0)
Block(-3,6,1,STAINED_CLAY:12)
Block(-3,6,2,LOG:1)
Block(-3,6,3,STAINED_CLAY:12)
Block(-3,6,4,STAINED_CLAY:12)
Block(-3,6,5,STAINED_CLAY:12)
Block(-3,6,6,STAINED_CLAY:12)
Block(-3,6,7,LOG:1)
Block(-3,6,8,SPRUCE_WOOD_STAIRS:5)
RandomBlock(-3,7,-5,SPRUCE_WOOD_STAIRS:0,70,DARK_OAK_STAIRS:0,100)
RandomBlock(-3,7,-4,SPRUCE_WOOD_STAIRS:0,70,DARK_OAK_STAIRS:0,100)
RandomBlock(-3,7,-3,SPRUCE_WOOD_STAIRS:0,70,DARK_OAK_STAIRS:0,100)
RandomBlock(-3,7,-2,SPRUCE_WOOD_STAIRS:0,70,DARK_OAK_STAIRS:0,100)
RandomBlock(-3,7,-1,SPRUCE_WOOD_STAIRS:0,70,DARK_OAK_STAIRS:0,100)
RandomBlock(-3,7,0,SPRUCE_WOOD_STAIRS:0,70,DARK_OAK_STAIRS:0,100)
RandomBlock(-3,7,1,SPRUCE_WOOD_STAIRS:0,70,DARK_OAK_STAIRS:0,100)
RandomBlock(-3,7,2,SPRUCE_WOOD_STAIRS:0,70,DARK_OAK_STAIRS:0,100)
RandomBlock(-3,7,3,SPRUCE_WOOD_STAIRS:0,70,DARK_OAK_STAIRS:0,100)
RandomBlock(-3,7,4,SPRUCE_WOOD_STAIRS:0,70,DARK_OAK_STAIRS:0,100)
RandomBlock(-3,7,5,SPRUCE_WOOD_STAIRS:0,70,DARK_OAK_STAIRS:0,100)
RandomBlock(-3,7,6,SPRUCE_WOOD_STAIRS:0,70,DARK_OAK_STAIRS:0,100)
RandomBlock(-3,7,7,SPRUCE_WOOD_STAIRS:0,70,DARK_OAK_STAIRS:0,100)
RandomBlock(-3,7,8,SPRUCE_WOOD_STAIRS:0,70,DARK_OAK_STAIRS:0,100)
RandomBlock(-2,0,-4,COBBLESTONE:0,60,MOSSY_COBBLESTONE:0,5,SMOOTH_BRICK:0,10,SMOOTH_BRICK:1,10,SMOOTH_BRICK:2,10,COBBLESTONE:0,100)
RandomBlock(-2,0,-3,COBBLESTONE:0,60,MOSSY_COBBLESTONE:0,5,SMOOTH_BRICK:0,10,SMOOTH_BRICK:1,10,SMOOTH_BRICK:2,10,COBBLESTONE:0,100)
RandomBlock(-2,0,-2,COBBLESTONE:0,60,MOSSY_COBBLESTONE:0,5,SMOOTH_BRICK:0,10,SMOOTH_BRICK:1,10,SMOOTH_BRICK:2,10,COBBLESTONE:0,100)
RandomBlock(-2,0,-1,COBBLESTONE:0,60,MOSSY_COBBLESTONE:0,5,SMOOTH_BRICK:0,10,SMOOTH_BRICK:1,10,SMOOTH_BRICK:2,10,COBBLESTONE:0,100)
RandomBlock(-2,0,0,COBBLESTONE:0,60,MOSSY_COBBLESTONE:0,5,SMOOTH_BRICK:0,10,SMOOTH_BRICK:1,10,SMOOTH_BRICK:2,10,COBBLESTONE:0,100)
RandomBlock(-2,0,1,COBBLESTONE:0,60,MOSSY_COBBLESTONE:0,5,SMOOTH_BRICK:0,10,SMOOTH_BRICK:1,10,SMOOTH_BRICK:2,10,COBBLESTONE:0,100)
RandomBlock(-2,0,2,COBBLESTONE:0,60,MOSSY_COBBLESTONE:0,5,SMOOTH_BRICK:0,10,SMOOTH_BRICK:1,10,SMOOTH_BRICK:2,10,COBBLESTONE:0,100)
RandomBlock(-2,0,3,COBBLESTONE:0,60,MOSSY_COBBLESTONE:0,5,SMOOTH_BRICK:0,10,SMOOTH_BRICK:1,10,SMOOTH_BRICK:2,10,COBBLESTONE:0,100)
RandomBlock(-2,0,4,COBBLESTONE:0,60,MOSSY_COBBLESTONE:0,5,SMOOTH_BRICK:0,10,SMOOTH_BRICK:1,10,SMOOTH_BRICK:2,10,COBBLESTONE:0,100)
RandomBlock(-2,0,5,COBBLESTONE:0,60,MOSSY_COBBLESTONE:0,5,SMOOTH_BRICK:0,10,SMOOTH_BRICK:1,10,SMOOTH_BRICK:2,10,COBBLESTONE:0,100)
RandomBlock(-2,0,6,COBBLESTONE:0,60,MOSSY_COBBLESTONE:0,5,SMOOTH_BRICK:0,10,SMOOTH_BRICK:1,10,SMOOTH_BRICK:2,10,COBBLESTONE:0,100)
RandomBlock(-2,0,7,COBBLESTONE:0,60,MOSSY_COBBLESTONE:0,5,SMOOTH_BRICK:0,10,SMOOTH_BRICK:1,10,SMOOTH_BRICK:2,10,COBBLESTONE:0,100)
RandomBlock(-2,1,-4,COBBLESTONE:0,60,MOSSY_COBBLESTONE:0,5,SMOOTH_BRICK:0,10,SMOOTH_BRICK:1,10,SMOOTH_BRICK:2,10,COBBLESTONE:0,100)
RandomBlock(-2,1,-3,COBBLESTONE:0,60,MOSSY_COBBLESTONE:0,5,SMOOTH_BRICK:0,10,SMOOTH_BRICK:1,10,SMOOTH_BRICK:2,10,COBBLESTONE:0,100)
RandomBlock(-2,1,-2,COBBLESTONE:0,60,MOSSY_COBBLESTONE:0,5,SMOOTH_BRICK:0,10,SMOOTH_BRICK:1,10,SMOOTH_BRICK:2,10,COBBLESTONE:0,100)
RandomBlock(-2,1,-1,COBBLESTONE:0,60,MOSSY_COBBLESTONE:0,5,SMOOTH_BRICK:0,10,SMOOTH_BRICK:1,10,SMOOTH_BRICK:2,10,COBBLESTONE:0,100)
RandomBlock(-2,1,0,COBBLESTONE:0,60,MOSSY_COBBLESTONE:0,5,SMOOTH_BRICK:0,10,SMOOTH_BRICK:1,10,SMOOTH_BRICK:2,10,COBBLESTONE:0,100)
RandomBlock(-2,1,1,COBBLESTONE:0,60,MOSSY_COBBLESTONE:0,5,SMOOTH_BRICK:0,10,SMOOTH_BRICK:1,10,SMOOTH_BRICK:2,10,COBBLESTONE:0,100)
RandomBlock(-2,1,2,COBBLESTONE:0,60,MOSSY_COBBLESTONE:0,5,SMOOTH_BRICK:0,10,SMOOTH_BRICK:1,10,SMOOTH_BRICK:2,10,COBBLESTONE:0,100)
RandomBlock(-2,1,3,COBBLESTONE:0,60,MOSSY_COBBLESTONE:0,5,SMOOTH_BRICK:0,10,SMOOTH_BRICK:1,10,SMOOTH_BRICK:2,10,COBBLESTONE:0,100)
RandomBlock(-2,1,4,COBBLESTONE:0,60,MOSSY_COBBLESTONE:0,5,SMOOTH_BRICK:0,10,SMOOTH_BRICK:1,10,SMOOTH_BRICK:2,10,COBBLESTONE:0,100)
RandomBlock(-2,1,5,COBBLESTONE:0,60,MOSSY_COBBLESTONE:0,5,SMOOTH_BRICK:0,10,SMOOTH_BRICK:1,10,SMOOTH_BRICK:2,10,COBBLESTONE:0,100)
RandomBlock(-2,1,6,COBBLESTONE:0,60,MOSSY_COBBLESTONE:0,5,SMOOTH_BRICK:0,10,SMOOTH_BRICK:1,10,SMOOTH_BRICK:2,10,COBBLESTONE:0,100)
RandomBlock(-2,1,7,COBBLESTONE:0,60,MOSSY_COBBLESTONE:0,5,SMOOTH_BRICK:0,10,SMOOTH_BRICK:1,10,SMOOTH_BRICK:2,10,COBBLESTONE:0,100)
RandomBlock(-2,2,-4,COBBLESTONE:0,60,MOSSY_COBBLESTONE:0,5,SMOOTH_BRICK:0,10,SMOOTH_BRICK:1,10,SMOOTH_BRICK:2,10,COBBLESTONE:0,100)
RandomBlock(-2,2,-3,COBBLESTONE:0,60,MOSSY_COBBLESTONE:0,5,SMOOTH_BRICK:0,10,SMOOTH_BRICK:1,10,SMOOTH_BRICK:2,10,COBBLESTONE:0,100)
RandomBlock(-2,2,-2,COBBLESTONE:0,60,MOSSY_COBBLESTONE:0,5,SMOOTH_BRICK:0,10,SMOOTH_BRICK:1,10,SMOOTH_BRICK:2,10,COBBLESTONE:0,100)
RandomBlock(-2,2,-1,COBBLESTONE:0,60,MOSSY_COBBLESTONE:0,5,SMOOTH_BRICK:0,10,SMOOTH_BRICK:1,10,SMOOTH_BRICK:2,10,COBBLESTONE:0,100)
RandomBlock(-2,2,0,COBBLESTONE:0,60,MOSSY_COBBLESTONE:0,5,SMOOTH_BRICK:0,10,SMOOTH_BRICK:1,10,SMOOTH_BRICK:2,10,COBBLESTONE:0,100)
RandomBlock(-2,2,1,COBBLESTONE:0,60,MOSSY_COBBLESTONE:0,5,SMOOTH_BRICK:0,10,SMOOTH_BRICK:1,10,SMOOTH_BRICK:2,10,COBBLESTONE:0,100)
RandomBlock(-2,2,2,COBBLESTONE:0,60,MOSSY_COBBLESTONE:0,5,SMOOTH_BRICK:0,10,SMOOTH_BRICK:1,10,SMOOTH_BRICK:2,10,COBBLESTONE:0,100)
RandomBlock(-2,2,3,COBBLESTONE:0,60,MOSSY_COBBLESTONE:0,5,SMOOTH_BRICK:0,10,SMOOTH_BRICK:1,10,SMOOTH_BRICK:2,10,COBBLESTONE:0,100)
RandomBlock(-2,2,4,COBBLESTONE:0,60,MOSSY_COBBLESTONE:0,5,SMOOTH_BRICK:0,10,SMOOTH_BRICK:1,10,SMOOTH_BRICK:2,10,COBBLESTONE:0,100)
RandomBlock(-2,2,5,COBBLESTONE:0,60,MOSSY_COBBLESTONE:0,5,SMOOTH_BRICK:0,10,SMOOTH_BRICK:1,10,SMOOTH_BRICK:2,10,COBBLESTONE:0,100)
RandomBlock(-2,2,6,COBBLESTONE:0,60,MOSSY_COBBLESTONE:0,5,SMOOTH_BRICK:0,10,SMOOTH_BRICK:1,10,SMOOTH_BRICK:2,10,COBBLESTONE:0,100)
RandomBlock(-2,2,7,COBBLESTONE:0,60,MOSSY_COBBLESTONE:0,5,SMOOTH_BRICK:0,10,SMOOTH_BRICK:1,10,SMOOTH_BRICK:2,10,COBBLESTONE:0,100)
RandomBlock(-2,3,-4,COBBLESTONE:0,60,MOSSY_COBBLESTONE:0,5,SMOOTH_BRICK:0,10,SMOOTH_BRICK:1,10,SMOOTH_BRICK:2,10,COBBLESTONE:0,100)
RandomBlock(-2,3,-3,COBBLESTONE:0,60,MOSSY_COBBLESTONE:0,5,SMOOTH_BRICK:0,10,SMOOTH_BRICK:1,10,SMOOTH_BRICK:2,10,COBBLESTONE:0,100)
RandomBlock(-2,3,-2,COBBLESTONE:0,60,MOSSY_COBBLESTONE:0,5,SMOOTH_BRICK:0,10,SMOOTH_BRICK:1,10,SMOOTH_BRICK:2,10,COBBLESTONE:0,100)
RandomBlock(-2,3,-1,COBBLESTONE:0,60,MOSSY_COBBLESTONE:0,5,SMOOTH_BRICK:0,10,SMOOTH_BRICK:1,10,SMOOTH_BRICK:2,10,COBBLESTONE:0,100)
RandomBlock(-2,3,0,COBBLESTONE:0,60,MOSSY_COBBLESTONE:0,5,SMOOTH_BRICK:0,10,SMOOTH_BRICK:1,10,SMOOTH_BRICK:2,10,COBBLESTONE:0,100)
RandomBlock(-2,3,1,COBBLESTONE:0,60,MOSSY_COBBLESTONE:0,5,SMOOTH_BRICK:0,10,SMOOTH_BRICK:1,10,SMOOTH_BRICK:2,10,COBBLESTONE:0,100)
RandomBlock(-2,3,2,COBBLESTONE:0,60,MOSSY_COBBLESTONE:0,5,SMOOTH_BRICK:0,10,SMOOTH_BRICK:1,10,SMOOTH_BRICK:2,10,COBBLESTONE:0,100)
RandomBlock(-2,3,3,COBBLESTONE:0,60,MOSSY_COBBLESTONE:0,5,SMOOTH_BRICK:0,10,SMOOTH_BRICK:1,10,SMOOTH_BRICK:2,10,COBBLESTONE:0,100)
RandomBlock(-2,3,4,COBBLESTONE:0,60,MOSSY_COBBLESTONE:0,5,SMOOTH_BRICK:0,10,SMOOTH_BRICK:1,10,SMOOTH_BRICK:2,10,COBBLESTONE:0,100)
RandomBlock(-2,3,5,COBBLESTONE:0,60,MOSSY_COBBLESTONE:0,5,SMOOTH_BRICK:0,10,SMOOTH_BRICK:1,10,SMOOTH_BRICK:2,10,COBBLESTONE:0,100)
RandomBlock(-2,3,6,COBBLESTONE:0,60,MOSSY_COBBLESTONE:0,5,SMOOTH_BRICK:0,10,SMOOTH_BRICK:1,10,SMOOTH_BRICK:2,10,COBBLESTONE:0,100)
RandomBlock(-2,3,7,COBBLESTONE:0,60,MOSSY_COBBLESTONE:0,5,SMOOTH_BRICK:0,10,SMOOTH_BRICK:1,10,SMOOTH_BRICK:2,10,COBBLESTONE:0,100)
Block(-2,4,-4,STAINED_CLAY:0)
Block(-2,4,-3,BED_BLOCK:10)
Block(-2,4,-2,BED_BLOCK:2)
Block(-2,4,2,WOOD:1)
Block(-2,4,3,WOOD_STEP:13)
Block(-2,4,4,WOOD_STEP:13)
Block(-2,4,5,WOOD_STEP:13)
Block(-2,4,6,CAULDRON:3)
Block(-2,4,7,STAINED_CLAY:12)
Block(-2,5,-4,STAINED_CLAY:0)
RandomBlock(-2,5,-3,WALL_BANNER:3,../../NBT/Banners/viking_regular_1.nbt,20,WALL_BANNER:3,../../NBT/Banners/viking_regular_2.nbt,20,WALL_BANNER:3,../../NBT/Banners/viking_regular_3.nbt,20,WALL_BANNER:3,../../NBT/Banners/viking_regular_4.nbt,20,WALL_BANNER:3,../../NBT/Banners/viking_regular_5.nbt,20,WALL_BANNER:3,../../NBT/Banners/viking_regular_6.nbt,20,WALL_BANNER:3,../../NBT/Banners/viking_regular_7.nbt,20,WALL_BANNER:3,../../NBT/Banners/viking_regular_8.nbt,100)
RandomBlock(-2,5,-1,WALL_BANNER:5,../../NBT/Banners/viking_regular_1.nbt,20,WALL_BANNER:5,../../NBT/Banners/viking_regular_2.nbt,20,WALL_BANNER:5,../../NBT/Banners/viking_regular_3.nbt,20,WALL_BANNER:5,../../NBT/Banners/viking_regular_4.nbt,20,WALL_BANNER:5,../../NBT/Banners/viking_regular_5.nbt,20,WALL_BANNER:5,../../NBT/Banners/viking_regular_6.nbt,20,WALL_BANNER:5,../../NBT/Banners/viking_regular_7.nbt,20,WALL_BANNER:5,../../NBT/Banners/viking_regular_8.nbt,100)
Block(-2,5,0,AIR:0)
Block(-2,5,2,WOOD:1)
RandomBlock(-2,5,3,WALL_BANNER:5,../../NBT/Banners/viking_regular_1.nbt,20,WALL_BANNER:5,../../NBT/Banners/viking_regular_2.nbt,20,WALL_BANNER:5,../../NBT/Banners/viking_regular_3.nbt,20,WALL_BANNER:5,../../NBT/Banners/viking_regular_4.nbt,20,WALL_BANNER:5,../../NBT/Banners/viking_regular_5.nbt,20,WALL_BANNER:5,../../NBT/Banners/viking_regular_6.nbt,20,WALL_BANNER:5,../../NBT/Banners/viking_regular_7.nbt,20,WALL_BANNER:5,../../NBT/Banners/viking_regular_8.nbt,100)
RandomBlock(-2,5,4,WALL_BANNER:5,../../NBT/Banners/viking_regular_1.nbt,20,WALL_BANNER:5,../../NBT/Banners/viking_regular_2.nbt,20,WALL_BANNER:5,../../NBT/Banners/viking_regular_3.nbt,20,WALL_BANNER:5,../../NBT/Banners/viking_regular_4.nbt,20,WALL_BANNER:5,../../NBT/Banners/viking_regular_5.nbt,20,WALL_BANNER:5,../../NBT/Banners/viking_regular_6.nbt,20,WALL_BANNER:5,../../NBT/Banners/viking_regular_7.nbt,20,WALL_BANNER:5,../../NBT/Banners/viking_regular_8.nbt,100)
Block(-2,5,7,STAINED_CLAY:12)
Block(-2,6,-4,STAINED_CLAY:12)
Block(-2,6,-3,DARK_OAK_FENCE_GATE:2)
RandomBlock(-2,6,-2,WALL_BANNER:5,../../NBT/Banners/viking_regular_1.nbt,20,WALL_BANNER:5,../../NBT/Banners/viking_regular_2.nbt,20,WALL_BANNER:5,../../NBT/Banners/viking_regular_3.nbt,20,WALL_BANNER:5,../../NBT/Banners/viking_regular_4.nbt,20,WALL_BANNER:5,../../NBT/Banners/viking_regular_5.nbt,20,WALL_BANNER:5,../../NBT/Banners/viking_regular_6.nbt,20,WALL_BANNER:5,../../NBT/Banners/viking_regular_7.nbt,20,WALL_BANNER:5,../../NBT/Banners/viking_regular_8.nbt,100)
Block(-2,6,-1,DARK_OAK_FENCE_GATE:0)
RandomBlock(-2,6,1,WALL_BANNER:5,../../NBT/Banners/viking_regular_1.nbt,20,WALL_BANNER:5,../../NBT/Banners/viking_regular_2.nbt,20,WALL_BANNER:5,../../NBT/Banners/viking_regular_3.nbt,20,WALL_BANNER:5,../../NBT/Banners/viking_regular_4.nbt,20,WALL_BANNER:5,../../NBT/Banners/viking_regular_5.nbt,20,WALL_BANNER:5,../../NBT/Banners/viking_regular_6.nbt,20,WALL_BANNER:5,../../NBT/Banners/viking_regular_7.nbt,20,WALL_BANNER:5,../../NBT/Banners/viking_regular_8.nbt,100)
Block(-2,6,2,LOG:5)
Block(-2,6,4,WEB:0)
RandomBlock(-2,6,5,WALL_BANNER:5,../../NBT/Banners/viking_regular_1.nbt,20,WALL_BANNER:5,../../NBT/Banners/viking_regular_2.nbt,20,WALL_BANNER:5,../../NBT/Banners/viking_regular_3.nbt,20,WALL_BANNER:5,../../NBT/Banners/viking_regular_4.nbt,20,WALL_BANNER:5,../../NBT/Banners/viking_regular_5.nbt,20,WALL_BANNER:5,../../NBT/Banners/viking_regular_6.nbt,20,WALL_BANNER:5,../../NBT/Banners/viking_regular_7.nbt,20,WALL_BANNER:5,../../NBT/Banners/viking_regular_8.nbt,100)
Block(-2,6,7,STAINED_CLAY:12)
Block(-2,7,-5,SPRUCE_WOOD_STAIRS:5)
Block(-2,7,-4,STAINED_CLAY:0)
Block(-2,7,-3,WOOD_STEP:5)
Block(-2,7,-2,WOOD_STEP:5)
Block(-2,7,-1,WOOD_STEP:5)
RandomBlock(-2,7,0,WALL_BANNER:5,../../NBT/Banners/viking_regular_1.nbt,20,WALL_BANNER:5,../../NBT/Banners/viking_regular_2.nbt,20,WALL_BANNER:5,../../NBT/Banners/viking_regular_3.nbt,20,WALL_BANNER:5,../../NBT/Banners/viking_regular_4.nbt,20,WALL_BANNER:5,../../NBT/Banners/viking_regular_5.nbt,20,WALL_BANNER:5,../../NBT/Banners/viking_regular_6.nbt,20,WALL_BANNER:5,../../NBT/Banners/viking_regular_7.nbt,20,WALL_BANNER:5,../../NBT/Banners/viking_regular_8.nbt,100)
Block(-2,7,1,WEB:0)
Block(-2,7,2,DARK_OAK_FENCE:0)
Block(-2,7,3,WEB:0)
RandomBlock(-2,7,4,WALL_BANNER:5,../../NBT/Banners/viking_regular_1.nbt,20,WALL_BANNER:5,../../NBT/Banners/viking_regular_2.nbt,20,WALL_BANNER:5,../../NBT/Banners/viking_regular_3.nbt,20,WALL_BANNER:5,../../NBT/Banners/viking_regular_4.nbt,20,WALL_BANNER:5,../../NBT/Banners/viking_regular_5.nbt,20,WALL_BANNER:5,../../NBT/Banners/viking_regular_6.nbt,20,WALL_BANNER:5,../../NBT/Banners/viking_regular_7.nbt,20,WALL_BANNER:5,../../NBT/Banners/viking_regular_8.nbt,100)
Block(-2,7,5,WEB:0)
Block(-2,7,6,WEB:0)
Block(-2,7,7,STAINED_CLAY:0)
Block(-2,7,8,SPRUCE_WOOD_STAIRS:5)
RandomBlock(-2,8,-5,SPRUCE_WOOD_STAIRS:0,70,DARK_OAK_STAIRS:0,100)
RandomBlock(-2,8,-4,SPRUCE_WOOD_STAIRS:0,70,DARK_OAK_STAIRS:0,100)
RandomBlock(-2,8,-3,SPRUCE_WOOD_STAIRS:0,70,DARK_OAK_STAIRS:0,100)
RandomBlock(-2,8,-2,SPRUCE_WOOD_STAIRS:0,70,DARK_OAK_STAIRS:0,100)
RandomBlock(-2,8,-1,SPRUCE_WOOD_STAIRS:0,70,DARK_OAK_STAIRS:0,100)
RandomBlock(-2,8,0,SPRUCE_WOOD_STAIRS:0,70,DARK_OAK_STAIRS:0,100)
RandomBlock(-2,8,1,SPRUCE_WOOD_STAIRS:0,70,DARK_OAK_STAIRS:0,100)
RandomBlock(-2,8,2,SPRUCE_WOOD_STAIRS:0,70,DARK_OAK_STAIRS:0,100)
RandomBlock(-2,8,3,SPRUCE_WOOD_STAIRS:0,70,DARK_OAK_STAIRS:0,100)
RandomBlock(-2,8,4,SPRUCE_WOOD_STAIRS:0,70,DARK_OAK_STAIRS:0,100)
RandomBlock(-2,8,5,SPRUCE_WOOD_STAIRS:0,70,DARK_OAK_STAIRS:0,100)
RandomBlock(-2,8,6,SPRUCE_WOOD_STAIRS:0,70,DARK_OAK_STAIRS:0,100)
RandomBlock(-2,8,7,SPRUCE_WOOD_STAIRS:0,70,DARK_OAK_STAIRS:0,100)
RandomBlock(-2,8,8,SPRUCE_WOOD_STAIRS:0,70,DARK_OAK_STAIRS:0,100)
RandomBlock(-1,0,-4,COBBLESTONE:0,60,MOSSY_COBBLESTONE:0,5,SMOOTH_BRICK:0,10,SMOOTH_BRICK:1,10,SMOOTH_BRICK:2,10,COBBLESTONE:0,100)
RandomBlock(-1,0,-3,COBBLESTONE:0,60,MOSSY_COBBLESTONE:0,5,SMOOTH_BRICK:0,10,SMOOTH_BRICK:1,10,SMOOTH_BRICK:2,10,COBBLESTONE:0,100)
RandomBlock(-1,0,-2,COBBLESTONE:0,60,MOSSY_COBBLESTONE:0,5,SMOOTH_BRICK:0,10,SMOOTH_BRICK:1,10,SMOOTH_BRICK:2,10,COBBLESTONE:0,100)
RandomBlock(-1,0,-1,COBBLESTONE:0,60,MOSSY_COBBLESTONE:0,5,SMOOTH_BRICK:0,10,SMOOTH_BRICK:1,10,SMOOTH_BRICK:2,10,COBBLESTONE:0,100)
RandomBlock(-1,0,0,COBBLESTONE:0,60,MOSSY_COBBLESTONE:0,5,SMOOTH_BRICK:0,10,SMOOTH_BRICK:1,10,SMOOTH_BRICK:2,10,COBBLESTONE:0,100)
RandomBlock(-1,0,1,COBBLESTONE:0,60,MOSSY_COBBLESTONE:0,5,SMOOTH_BRICK:0,10,SMOOTH_BRICK:1,10,SMOOTH_BRICK:2,10,COBBLESTONE:0,100)
RandomBlock(-1,0,2,COBBLESTONE:0,60,MOSSY_COBBLESTONE:0,5,SMOOTH_BRICK:0,10,SMOOTH_BRICK:1,10,SMOOTH_BRICK:2,10,COBBLESTONE:0,100)
RandomBlock(-1,0,3,COBBLESTONE:0,60,MOSSY_COBBLESTONE:0,5,SMOOTH_BRICK:0,10,SMOOTH_BRICK:1,10,SMOOTH_BRICK:2,10,COBBLESTONE:0,100)
RandomBlock(-1,0,4,COBBLESTONE:0,60,MOSSY_COBBLESTONE:0,5,SMOOTH_BRICK:0,10,SMOOTH_BRICK:1,10,SMOOTH_BRICK:2,10,COBBLESTONE:0,100)
RandomBlock(-1,0,5,COBBLESTONE:0,60,MOSSY_COBBLESTONE:0,5,SMOOTH_BRICK:0,10,SMOOTH_BRICK:1,10,SMOOTH_BRICK:2,10,COBBLESTONE:0,100)
RandomBlock(-1,0,6,COBBLESTONE:0,60,MOSSY_COBBLESTONE:0,5,SMOOTH_BRICK:0,10,SMOOTH_BRICK:1,10,SMOOTH_BRICK:2,10,COBBLESTONE:0,100)
RandomBlock(-1,0,7,COBBLESTONE:0,60,MOSSY_COBBLESTONE:0,5,SMOOTH_BRICK:0,10,SMOOTH_BRICK:1,10,SMOOTH_BRICK:2,10,COBBLESTONE:0,100)
RandomBlock(-1,1,-4,COBBLESTONE:0,60,MOSSY_COBBLESTONE:0,5,SMOOTH_BRICK:0,10,SMOOTH_BRICK:1,10,SMOOTH_BRICK:2,10,COBBLESTONE:0,100)
RandomBlock(-1,1,-3,COBBLESTONE:0,60,MOSSY_COBBLESTONE:0,5,SMOOTH_BRICK:0,10,SMOOTH_BRICK:1,10,SMOOTH_BRICK:2,10,COBBLESTONE:0,100)
RandomBlock(-1,1,-2,COBBLESTONE:0,60,MOSSY_COBBLESTONE:0,5,SMOOTH_BRICK:0,10,SMOOTH_BRICK:1,10,SMOOTH_BRICK:2,10,COBBLESTONE:0,100)
RandomBlock(-1,1,-1,COBBLESTONE:0,60,MOSSY_COBBLESTONE:0,5,SMOOTH_BRICK:0,10,SMOOTH_BRICK:1,10,SMOOTH_BRICK:2,10,COBBLESTONE:0,100)
RandomBlock(-1,1,0,COBBLESTONE:0,60,MOSSY_COBBLESTONE:0,5,SMOOTH_BRICK:0,10,SMOOTH_BRICK:1,10,SMOOTH_BRICK:2,10,COBBLESTONE:0,100)
RandomBlock(-1,1,1,COBBLESTONE:0,60,MOSSY_COBBLESTONE:0,5,SMOOTH_BRICK:0,10,SMOOTH_BRICK:1,10,SMOOTH_BRICK:2,10,COBBLESTONE:0,100)
RandomBlock(-1,1,2,COBBLESTONE:0,60,MOSSY_COBBLESTONE:0,5,SMOOTH_BRICK:0,10,SMOOTH_BRICK:1,10,SMOOTH_BRICK:2,10,COBBLESTONE:0,100)
RandomBlock(-1,1,3,COBBLESTONE:0,60,MOSSY_COBBLESTONE:0,5,SMOOTH_BRICK:0,10,SMOOTH_BRICK:1,10,SMOOTH_BRICK:2,10,COBBLESTONE:0,100)
RandomBlock(-1,1,4,COBBLESTONE:0,60,MOSSY_COBBLESTONE:0,5,SMOOTH_BRICK:0,10,SMOOTH_BRICK:1,10,SMOOTH_BRICK:2,10,COBBLESTONE:0,100)
RandomBlock(-1,1,5,COBBLESTONE:0,60,MOSSY_COBBLESTONE:0,5,SMOOTH_BRICK:0,10,SMOOTH_BRICK:1,10,SMOOTH_BRICK:2,10,COBBLESTONE:0,100)
RandomBlock(-1,1,6,COBBLESTONE:0,60,MOSSY_COBBLESTONE:0,5,SMOOTH_BRICK:0,10,SMOOTH_BRICK:1,10,SMOOTH_BRICK:2,10,COBBLESTONE:0,100)
RandomBlock(-1,1,7,COBBLESTONE:0,60,MOSSY_COBBLESTONE:0,5,SMOOTH_BRICK:0,10,SMOOTH_BRICK:1,10,SMOOTH_BRICK:2,10,COBBLESTONE:0,100)
RandomBlock(-1,2,-4,COBBLESTONE:0,60,MOSSY_COBBLESTONE:0,5,SMOOTH_BRICK:0,10,SMOOTH_BRICK:1,10,SMOOTH_BRICK:2,10,COBBLESTONE:0,100)
RandomBlock(-1,2,-3,COBBLESTONE:0,60,MOSSY_COBBLESTONE:0,5,SMOOTH_BRICK:0,10,SMOOTH_BRICK:1,10,SMOOTH_BRICK:2,10,COBBLESTONE:0,100)
RandomBlock(-1,2,-2,COBBLESTONE:0,60,MOSSY_COBBLESTONE:0,5,SMOOTH_BRICK:0,10,SMOOTH_BRICK:1,10,SMOOTH_BRICK:2,10,COBBLESTONE:0,100)
RandomBlock(-1,2,-1,COBBLESTONE:0,60,MOSSY_COBBLESTONE:0,5,SMOOTH_BRICK:0,10,SMOOTH_BRICK:1,10,SMOOTH_BRICK:2,10,COBBLESTONE:0,100)
RandomBlock(-1,2,0,COBBLESTONE:0,60,MOSSY_COBBLESTONE:0,5,SMOOTH_BRICK:0,10,SMOOTH_BRICK:1,10,SMOOTH_BRICK:2,10,COBBLESTONE:0,100)
RandomBlock(-1,2,1,COBBLESTONE:0,60,MOSSY_COBBLESTONE:0,5,SMOOTH_BRICK:0,10,SMOOTH_BRICK:1,10,SMOOTH_BRICK:2,10,COBBLESTONE:0,100)
RandomBlock(-1,2,2,COBBLESTONE:0,60,MOSSY_COBBLESTONE:0,5,SMOOTH_BRICK:0,10,SMOOTH_BRICK:1,10,SMOOTH_BRICK:2,10,COBBLESTONE:0,100)
RandomBlock(-1,2,3,COBBLESTONE:0,60,MOSSY_COBBLESTONE:0,5,SMOOTH_BRICK:0,10,SMOOTH_BRICK:1,10,SMOOTH_BRICK:2,10,COBBLESTONE:0,100)
RandomBlock(-1,2,4,COBBLESTONE:0,60,MOSSY_COBBLESTONE:0,5,SMOOTH_BRICK:0,10,SMOOTH_BRICK:1,10,SMOOTH_BRICK:2,10,COBBLESTONE:0,100)
RandomBlock(-1,2,5,COBBLESTONE:0,60,MOSSY_COBBLESTONE:0,5,SMOOTH_BRICK:0,10,SMOOTH_BRICK:1,10,SMOOTH_BRICK:2,10,COBBLESTONE:0,100)
RandomBlock(-1,2,6,COBBLESTONE:0,60,MOSSY_COBBLESTONE:0,5,SMOOTH_BRICK:0,10,SMOOTH_BRICK:1,10,SMOOTH_BRICK:2,10,COBBLESTONE:0,100)
RandomBlock(-1,2,7,COBBLESTONE:0,60,MOSSY_COBBLESTONE:0,5,SMOOTH_BRICK:0,10,SMOOTH_BRICK:1,10,SMOOTH_BRICK:2,10,COBBLESTONE:0,100)
RandomBlock(-1,3,-4,COBBLESTONE:0,60,MOSSY_COBBLESTONE:0,5,SMOOTH_BRICK:0,10,SMOOTH_BRICK:1,10,SMOOTH_BRICK:2,10,COBBLESTONE:0,100)
RandomBlock(-1,3,-3,COBBLESTONE:0,60,MOSSY_COBBLESTONE:0,5,SMOOTH_BRICK:0,10,SMOOTH_BRICK:1,10,SMOOTH_BRICK:2,10,COBBLESTONE:0,100)
RandomBlock(-1,3,-2,COBBLESTONE:0,60,MOSSY_COBBLESTONE:0,5,SMOOTH_BRICK:0,10,SMOOTH_BRICK:1,10,SMOOTH_BRICK:2,10,COBBLESTONE:0,100)
RandomBlock(-1,3,-1,COBBLESTONE:0,60,MOSSY_COBBLESTONE:0,5,SMOOTH_BRICK:0,10,SMOOTH_BRICK:1,10,SMOOTH_BRICK:2,10,COBBLESTONE:0,100)
RandomBlock(-1,3,0,COBBLESTONE:0,60,MOSSY_COBBLESTONE:0,5,SMOOTH_BRICK:0,10,SMOOTH_BRICK:1,10,SMOOTH_BRICK:2,10,COBBLESTONE:0,100)
RandomBlock(-1,3,1,COBBLESTONE:0,60,MOSSY_COBBLESTONE:0,5,SMOOTH_BRICK:0,10,SMOOTH_BRICK:1,10,SMOOTH_BRICK:2,10,COBBLESTONE:0,100)
RandomBlock(-1,3,2,COBBLESTONE:0,60,MOSSY_COBBLESTONE:0,5,SMOOTH_BRICK:0,10,SMOOTH_BRICK:1,10,SMOOTH_BRICK:2,10,COBBLESTONE:0,100)
RandomBlock(-1,3,3,COBBLESTONE:0,60,MOSSY_COBBLESTONE:0,5,SMOOTH_BRICK:0,10,SMOOTH_BRICK:1,10,SMOOTH_BRICK:2,10,COBBLESTONE:0,100)
RandomBlock(-1,3,4,COBBLESTONE:0,60,MOSSY_COBBLESTONE:0,5,SMOOTH_BRICK:0,10,SMOOTH_BRICK:1,10,SMOOTH_BRICK:2,10,COBBLESTONE:0,100)
RandomBlock(-1,3,5,COBBLESTONE:0,60,MOSSY_COBBLESTONE:0,5,SMOOTH_BRICK:0,10,SMOOTH_BRICK:1,10,SMOOTH_BRICK:2,10,COBBLESTONE:0,100)
RandomBlock(-1,3,6,COBBLESTONE:0,60,MOSSY_COBBLESTONE:0,5,SMOOTH_BRICK:0,10,SMOOTH_BRICK:1,10,SMOOTH_BRICK:2,10,COBBLESTONE:0,100)
RandomBlock(-1,3,7,COBBLESTONE:0,60,MOSSY_COBBLESTONE:0,5,SMOOTH_BRICK:0,10,SMOOTH_BRICK:1,10,SMOOTH_BRICK:2,10,COBBLESTONE:0,100)
Block(-1,4,-4,STAINED_CLAY:12)
Block(-1,4,-3,BED_BLOCK:10)
Block(-1,4,-2,BED_BLOCK:2)
Block(-1,4,7,STAINED_CLAY:12)
Block(-1,5,-4,STAINED_CLAY:12)
Block(-1,5,7,STAINED_CLAY:12)
Block(-1,6,-4,STAINED_CLAY:12)
RandomBlock(-1,6,-3,WALL_BANNER:3,../../NBT/Banners/viking_regular_1.nbt,20,WALL_BANNER:3,../../NBT/Banners/viking_regular_2.nbt,20,WALL_BANNER:3,../../NBT/Banners/viking_regular_3.nbt,20,WALL_BANNER:3,../../NBT/Banners/viking_regular_4.nbt,20,WALL_BANNER:3,../../NBT/Banners/viking_regular_5.nbt,20,WALL_BANNER:3,../../NBT/Banners/viking_regular_6.nbt,20,WALL_BANNER:3,../../NBT/Banners/viking_regular_7.nbt,20,WALL_BANNER:3,../../NBT/Banners/viking_regular_8.nbt,100)
RandomBlock(-1,6,1,WALL_BANNER:2,../../NBT/Banners/viking_regular_1.nbt,20,WALL_BANNER:2,../../NBT/Banners/viking_regular_2.nbt,20,WALL_BANNER:2,../../NBT/Banners/viking_regular_3.nbt,20,WALL_BANNER:2,../../NBT/Banners/viking_regular_4.nbt,20,WALL_BANNER:2,../../NBT/Banners/viking_regular_5.nbt,20,WALL_BANNER:2,../../NBT/Banners/viking_regular_6.nbt,20,WALL_BANNER:2,../../NBT/Banners/viking_regular_7.nbt,20,WALL_BANNER:2,../../NBT/Banners/viking_regular_8.nbt,100)
Block(-1,6,2,LOG:5)
RandomBlock(-1,6,6,WALL_BANNER:2,../../NBT/Banners/viking_regular_1.nbt,20,WALL_BANNER:2,../../NBT/Banners/viking_regular_2.nbt,20,WALL_BANNER:2,../../NBT/Banners/viking_regular_3.nbt,20,WALL_BANNER:2,../../NBT/Banners/viking_regular_4.nbt,20,WALL_BANNER:2,../../NBT/Banners/viking_regular_5.nbt,20,WALL_BANNER:2,../../NBT/Banners/viking_regular_6.nbt,20,WALL_BANNER:2,../../NBT/Banners/viking_regular_7.nbt,20,WALL_BANNER:2,../../NBT/Banners/viking_regular_8.nbt,100)
Block(-1,6,7,STAINED_CLAY:0)
Block(-1,7,-4,STAINED_CLAY:12)
Block(-1,7,2,DARK_OAK_FENCE:0)
Block(-1,7,6,WEB:0)
Block(-1,7,7,STAINED_CLAY:0)
Block(-1,8,-5,SPRUCE_WOOD_STAIRS:5)
Block(-1,8,-4,STAINED_CLAY:12)
RandomBlock(-1,8,-3,WALL_BANNER:3,../../NBT/Banners/viking_regular_1.nbt,20,WALL_BANNER:3,../../NBT/Banners/viking_regular_2.nbt,20,WALL_BANNER:3,../../NBT/Banners/viking_regular_3.nbt,20,WALL_BANNER:3,../../NBT/Banners/viking_regular_4.nbt,20,WALL_BANNER:3,../../NBT/Banners/viking_regular_5.nbt,20,WALL_BANNER:3,../../NBT/Banners/viking_regular_6.nbt,20,WALL_BANNER:3,../../NBT/Banners/viking_regular_7.nbt,20,WALL_BANNER:3,../../NBT/Banners/viking_regular_8.nbt,100)
Block(-1,8,1,WEB:0)
Block(-1,8,2,DARK_OAK_FENCE:0)
Block(-1,8,3,WEB:0)
Block(-1,8,4,WEB:0)
Block(-1,8,5,WEB:0)
RandomBlock(-1,8,6,WALL_BANNER:2,../../NBT/Banners/viking_regular_1.nbt,20,WALL_BANNER:2,../../NBT/Banners/viking_regular_2.nbt,20,WALL_BANNER:2,../../NBT/Banners/viking_regular_3.nbt,20,WALL_BANNER:2,../../NBT/Banners/viking_regular_4.nbt,20,WALL_BANNER:2,../../NBT/Banners/viking_regular_5.nbt,20,WALL_BANNER:2,../../NBT/Banners/viking_regular_6.nbt,20,WALL_BANNER:2,../../NBT/Banners/viking_regular_7.nbt,20,WALL_BANNER:2,../../NBT/Banners/viking_regular_8.nbt,100)
Block(-1,8,7,STAINED_CLAY:0)
Block(-1,8,8,SPRUCE_WOOD_STAIRS:5)
RandomBlock(-1,9,-5,SPRUCE_WOOD_STAIRS:0,70,DARK_OAK_STAIRS:0,100)
RandomBlock(-1,9,-4,SPRUCE_WOOD_STAIRS:0,70,DARK_OAK_STAIRS:0,100)
RandomBlock(-1,9,-3,SPRUCE_WOOD_STAIRS:0,70,DARK_OAK_STAIRS:0,100)
RandomBlock(-1,9,-2,SPRUCE_WOOD_STAIRS:0,70,DARK_OAK_STAIRS:0,100)
RandomBlock(-1,9,-1,SPRUCE_WOOD_STAIRS:0,70,DARK_OAK_STAIRS:0,100)
RandomBlock(-1,9,0,SPRUCE_WOOD_STAIRS:0,70,DARK_OAK_STAIRS:0,100)
RandomBlock(-1,9,1,SPRUCE_WOOD_STAIRS:0,70,DARK_OAK_STAIRS:0,100)
RandomBlock(-1,9,2,SPRUCE_WOOD_STAIRS:0,70,DARK_OAK_STAIRS:0,100)
RandomBlock(-1,9,3,SPRUCE_WOOD_STAIRS:0,70,DARK_OAK_STAIRS:0,100)
RandomBlock(-1,9,4,SPRUCE_WOOD_STAIRS:0,70,DARK_OAK_STAIRS:0,100)
RandomBlock(-1,9,5,SPRUCE_WOOD_STAIRS:0,70,DARK_OAK_STAIRS:0,100)
RandomBlock(-1,9,6,SPRUCE_WOOD_STAIRS:0,70,DARK_OAK_STAIRS:0,100)
RandomBlock(-1,9,7,SPRUCE_WOOD_STAIRS:0,70,DARK_OAK_STAIRS:0,100)
RandomBlock(-1,9,8,SPRUCE_WOOD_STAIRS:0,70,DARK_OAK_STAIRS:0,100)
RandomBlock(-1,10,-3,SPRUCE_WOOD_STAIRS:0,70,DARK_OAK_STAIRS:0,100)
Block(-1,10,-2,TRAP_DOOR:10)
Block(-1,10,-1,TRAP_DOOR:10)
Block(-1,10,0,TRAP_DOOR:10)
RandomBlock(-1,10,1,SPRUCE_WOOD_STAIRS:0,70,DARK_OAK_STAIRS:0,100)
RandomBlock(0,0,-4,COBBLESTONE:0,60,MOSSY_COBBLESTONE:0,5,SMOOTH_BRICK:0,10,SMOOTH_BRICK:1,10,SMOOTH_BRICK:2,10,COBBLESTONE:0,100)
RandomBlock(0,0,-3,COBBLESTONE:0,60,MOSSY_COBBLESTONE:0,5,SMOOTH_BRICK:0,10,SMOOTH_BRICK:1,10,SMOOTH_BRICK:2,10,COBBLESTONE:0,100)
RandomBlock(0,0,-2,COBBLESTONE:0,60,MOSSY_COBBLESTONE:0,5,SMOOTH_BRICK:0,10,SMOOTH_BRICK:1,10,SMOOTH_BRICK:2,10,COBBLESTONE:0,100)
RandomBlock(0,0,-1,COBBLESTONE:0,60,MOSSY_COBBLESTONE:0,5,SMOOTH_BRICK:0,10,SMOOTH_BRICK:1,10,SMOOTH_BRICK:2,10,COBBLESTONE:0,100)
RandomBlock(0,0,0,COBBLESTONE:0,60,MOSSY_COBBLESTONE:0,5,SMOOTH_BRICK:0,10,SMOOTH_BRICK:1,10,SMOOTH_BRICK:2,10,COBBLESTONE:0,100)
RandomBlock(0,0,1,COBBLESTONE:0,60,MOSSY_COBBLESTONE:0,5,SMOOTH_BRICK:0,10,SMOOTH_BRICK:1,10,SMOOTH_BRICK:2,10,COBBLESTONE:0,100)
RandomBlock(0,0,2,COBBLESTONE:0,60,MOSSY_COBBLESTONE:0,5,SMOOTH_BRICK:0,10,SMOOTH_BRICK:1,10,SMOOTH_BRICK:2,10,COBBLESTONE:0,100)
RandomBlock(0,0,3,COBBLESTONE:0,60,MOSSY_COBBLESTONE:0,5,SMOOTH_BRICK:0,10,SMOOTH_BRICK:1,10,SMOOTH_BRICK:2,10,COBBLESTONE:0,100)
RandomBlock(0,0,4,COBBLESTONE:0,60,MOSSY_COBBLESTONE:0,5,SMOOTH_BRICK:0,10,SMOOTH_BRICK:1,10,SMOOTH_BRICK:2,10,COBBLESTONE:0,100)
RandomBlock(0,0,5,COBBLESTONE:0,60,MOSSY_COBBLESTONE:0,5,SMOOTH_BRICK:0,10,SMOOTH_BRICK:1,10,SMOOTH_BRICK:2,10,COBBLESTONE:0,100)
RandomBlock(0,0,6,COBBLESTONE:0,60,MOSSY_COBBLESTONE:0,5,SMOOTH_BRICK:0,10,SMOOTH_BRICK:1,10,SMOOTH_BRICK:2,10,COBBLESTONE:0,100)
RandomBlock(0,0,7,COBBLESTONE:0,60,MOSSY_COBBLESTONE:0,5,SMOOTH_BRICK:0,10,SMOOTH_BRICK:1,10,SMOOTH_BRICK:2,10,COBBLESTONE:0,100)
RandomBlock(0,1,-4,COBBLESTONE:0,60,MOSSY_COBBLESTONE:0,5,SMOOTH_BRICK:0,10,SMOOTH_BRICK:1,10,SMOOTH_BRICK:2,10,COBBLESTONE:0,100)
RandomBlock(0,1,-3,COBBLESTONE:0,60,MOSSY_COBBLESTONE:0,5,SMOOTH_BRICK:0,10,SMOOTH_BRICK:1,10,SMOOTH_BRICK:2,10,COBBLESTONE:0,100)
RandomBlock(0,1,-2,COBBLESTONE:0,60,MOSSY_COBBLESTONE:0,5,SMOOTH_BRICK:0,10,SMOOTH_BRICK:1,10,SMOOTH_BRICK:2,10,COBBLESTONE:0,100)
RandomBlock(0,1,-1,COBBLESTONE:0,60,MOSSY_COBBLESTONE:0,5,SMOOTH_BRICK:0,10,SMOOTH_BRICK:1,10,SMOOTH_BRICK:2,10,COBBLESTONE:0,100)
RandomBlock(0,1,0,COBBLESTONE:0,60,MOSSY_COBBLESTONE:0,5,SMOOTH_BRICK:0,10,SMOOTH_BRICK:1,10,SMOOTH_BRICK:2,10,COBBLESTONE:0,100)
RandomBlock(0,1,1,COBBLESTONE:0,60,MOSSY_COBBLESTONE:0,5,SMOOTH_BRICK:0,10,SMOOTH_BRICK:1,10,SMOOTH_BRICK:2,10,COBBLESTONE:0,100)
RandomBlock(0,1,2,COBBLESTONE:0,60,MOSSY_COBBLESTONE:0,5,SMOOTH_BRICK:0,10,SMOOTH_BRICK:1,10,SMOOTH_BRICK:2,10,COBBLESTONE:0,100)
RandomBlock(0,1,3,COBBLESTONE:0,60,MOSSY_COBBLESTONE:0,5,SMOOTH_BRICK:0,10,SMOOTH_BRICK:1,10,SMOOTH_BRICK:2,10,COBBLESTONE:0,100)
RandomBlock(0,1,4,COBBLESTONE:0,60,MOSSY_COBBLESTONE:0,5,SMOOTH_BRICK:0,10,SMOOTH_BRICK:1,10,SMOOTH_BRICK:2,10,COBBLESTONE:0,100)
RandomBlock(0,1,5,COBBLESTONE:0,60,MOSSY_COBBLESTONE:0,5,SMOOTH_BRICK:0,10,SMOOTH_BRICK:1,10,SMOOTH_BRICK:2,10,COBBLESTONE:0,100)
RandomBlock(0,1,6,COBBLESTONE:0,60,MOSSY_COBBLESTONE:0,5,SMOOTH_BRICK:0,10,SMOOTH_BRICK:1,10,SMOOTH_BRICK:2,10,COBBLESTONE:0,100)
RandomBlock(0,1,7,COBBLESTONE:0,60,MOSSY_COBBLESTONE:0,5,SMOOTH_BRICK:0,10,SMOOTH_BRICK:1,10,SMOOTH_BRICK:2,10,COBBLESTONE:0,100)
RandomBlock(0,2,-4,COBBLESTONE:0,60,MOSSY_COBBLESTONE:0,5,SMOOTH_BRICK:0,10,SMOOTH_BRICK:1,10,SMOOTH_BRICK:2,10,COBBLESTONE:0,100)
RandomBlock(0,2,-3,COBBLESTONE:0,60,MOSSY_COBBLESTONE:0,5,SMOOTH_BRICK:0,10,SMOOTH_BRICK:1,10,SMOOTH_BRICK:2,10,COBBLESTONE:0,100)
RandomBlock(0,2,-2,COBBLESTONE:0,60,MOSSY_COBBLESTONE:0,5,SMOOTH_BRICK:0,10,SMOOTH_BRICK:1,10,SMOOTH_BRICK:2,10,COBBLESTONE:0,100)
RandomBlock(0,2,-1,COBBLESTONE:0,60,MOSSY_COBBLESTONE:0,5,SMOOTH_BRICK:0,10,SMOOTH_BRICK:1,10,SMOOTH_BRICK:2,10,COBBLESTONE:0,100)
RandomBlock(0,2,0,COBBLESTONE:0,60,MOSSY_COBBLESTONE:0,5,SMOOTH_BRICK:0,10,SMOOTH_BRICK:1,10,SMOOTH_BRICK:2,10,COBBLESTONE:0,100)
RandomBlock(0,2,1,COBBLESTONE:0,60,MOSSY_COBBLESTONE:0,5,SMOOTH_BRICK:0,10,SMOOTH_BRICK:1,10,SMOOTH_BRICK:2,10,COBBLESTONE:0,100)
RandomBlock(0,2,2,COBBLESTONE:0,60,MOSSY_COBBLESTONE:0,5,SMOOTH_BRICK:0,10,SMOOTH_BRICK:1,10,SMOOTH_BRICK:2,10,COBBLESTONE:0,100)
RandomBlock(0,2,3,COBBLESTONE:0,60,MOSSY_COBBLESTONE:0,5,SMOOTH_BRICK:0,10,SMOOTH_BRICK:1,10,SMOOTH_BRICK:2,10,COBBLESTONE:0,100)
RandomBlock(0,2,4,COBBLESTONE:0,60,MOSSY_COBBLESTONE:0,5,SMOOTH_BRICK:0,10,SMOOTH_BRICK:1,10,SMOOTH_BRICK:2,10,COBBLESTONE:0,100)
RandomBlock(0,2,5,COBBLESTONE:0,60,MOSSY_COBBLESTONE:0,5,SMOOTH_BRICK:0,10,SMOOTH_BRICK:1,10,SMOOTH_BRICK:2,10,COBBLESTONE:0,100)
RandomBlock(0,2,6,COBBLESTONE:0,60,MOSSY_COBBLESTONE:0,5,SMOOTH_BRICK:0,10,SMOOTH_BRICK:1,10,SMOOTH_BRICK:2,10,COBBLESTONE:0,100)
RandomBlock(0,2,7,COBBLESTONE:0,60,MOSSY_COBBLESTONE:0,5,SMOOTH_BRICK:0,10,SMOOTH_BRICK:1,10,SMOOTH_BRICK:2,10,COBBLESTONE:0,100)
RandomBlock(0,3,-4,COBBLESTONE:0,60,MOSSY_COBBLESTONE:0,5,SMOOTH_BRICK:0,10,SMOOTH_BRICK:1,10,SMOOTH_BRICK:2,10,COBBLESTONE:0,100)
RandomBlock(0,3,-3,COBBLESTONE:0,60,MOSSY_COBBLESTONE:0,5,SMOOTH_BRICK:0,10,SMOOTH_BRICK:1,10,SMOOTH_BRICK:2,10,COBBLESTONE:0,100)
RandomBlock(0,3,-2,COBBLESTONE:0,60,MOSSY_COBBLESTONE:0,5,SMOOTH_BRICK:0,10,SMOOTH_BRICK:1,10,SMOOTH_BRICK:2,10,COBBLESTONE:0,100)
RandomBlock(0,3,-1,COBBLESTONE:0,60,MOSSY_COBBLESTONE:0,5,SMOOTH_BRICK:0,10,SMOOTH_BRICK:1,10,SMOOTH_BRICK:2,10,COBBLESTONE:0,100)
RandomBlock(0,3,0,COBBLESTONE:0,60,MOSSY_COBBLESTONE:0,5,SMOOTH_BRICK:0,10,SMOOTH_BRICK:1,10,SMOOTH_BRICK:2,10,COBBLESTONE:0,100)
RandomBlock(0,3,1,COBBLESTONE:0,60,MOSSY_COBBLESTONE:0,5,SMOOTH_BRICK:0,10,SMOOTH_BRICK:1,10,SMOOTH_BRICK:2,10,COBBLESTONE:0,100)
RandomBlock(0,3,2,COBBLESTONE:0,60,MOSSY_COBBLESTONE:0,5,SMOOTH_BRICK:0,10,SMOOTH_BRICK:1,10,SMOOTH_BRICK:2,10,COBBLESTONE:0,100)
RandomBlock(0,3,3,COBBLESTONE:0,60,MOSSY_COBBLESTONE:0,5,SMOOTH_BRICK:0,10,SMOOTH_BRICK:1,10,SMOOTH_BRICK:2,10,COBBLESTONE:0,100)
RandomBlock(0,3,4,COBBLESTONE:0,60,MOSSY_COBBLESTONE:0,5,SMOOTH_BRICK:0,10,SMOOTH_BRICK:1,10,SMOOTH_BRICK:2,10,COBBLESTONE:0,100)
RandomBlock(0,3,5,COBBLESTONE:0,60,MOSSY_COBBLESTONE:0,5,SMOOTH_BRICK:0,10,SMOOTH_BRICK:1,10,SMOOTH_BRICK:2,10,COBBLESTONE:0,100)
RandomBlock(0,3,6,COBBLESTONE:0,60,MOSSY_COBBLESTONE:0,5,SMOOTH_BRICK:0,10,SMOOTH_BRICK:1,10,SMOOTH_BRICK:2,10,COBBLESTONE:0,100)
RandomBlock(0,3,7,COBBLESTONE:0,60,MOSSY_COBBLESTONE:0,5,SMOOTH_BRICK:0,10,SMOOTH_BRICK:1,10,SMOOTH_BRICK:2,10,COBBLESTONE:0,100)
Block(0,4,-5,WOOD_BUTTON:4)
Block(0,4,-4,LOG:1)
Block(0,4,1,AIR:0)
Block(0,4,2,WOOD:1)
RandomBlock(0,4,3,SKULL:1,../../../../Skulls/dungeon_skull_01.nbt,6,AIR,9,SKULL:1,../../../../Skulls/dungeon_skull_02.nbt,12,AIR,15,SKULL:1,../../../../Skulls/dungeon_skull_03.nbt,18,AIR,21,SKULL:1,../../../../Skulls/dungeon_skull_04.nbt,24,AIR,27,SKULL:1,../../../../Skulls/dungeon_skull_05.nbt,30,AIR,33,SKULL:1,../../../../Skulls/dungeon_skull_06.nbt,36,AIR,39,SKULL:1,../../../../Skulls/dungeon_skull_07.nbt,42,AIR,45,SKULL:1,../../../../Skulls/dungeon_skull_08.nbt,48,AIR,51,SKULL:1,../../../../Skulls/dungeon_skull_09.nbt,54,AIR,57,SKULL:1,../../../../Skulls/dungeon_skull_10.nbt,60,AIR,63,SKULL:1,../../../../Skulls/dungeon_skull_11.nbt,66,AIR,69,SKULL:1,../../../../Skulls/dungeon_skull_12.nbt,72,AIR,75,SKULL:1,../../../../Skulls/dungeon_skull_13.nbt,78,AIR,81,SKULL:1,../../../../Skulls/dungeon_skull_14.nbt,84,AIR,87,SKULL:1,../../../../Skulls/dungeon_skull_15.nbt,90,AIR,93,SKULL:1,../../../../Skulls/dungeon_skull_16.nbt,96,AIR,100)
Block(0,4,7,SPRUCE_DOOR:1)
Block(0,5,-5,WOOD_BUTTON:4)
Block(0,5,-4,LOG:1)
Block(0,5,2,WOOD:1)
Block(0,5,7,SPRUCE_DOOR:9)
Block(0,6,-5,WOOD_BUTTON:4)
Block(0,6,-4,LOG:1)
Block(0,6,-3,WOOD_STEP:13)
Block(0,6,2,LOG:5)
Block(0,6,6,WEB:0)
Block(0,6,7,STAINED_CLAY:0)
Block(0,7,-5,WOOD_BUTTON:4)
Block(0,7,-4,LOG:1)
Block(0,7,-3,DARK_OAK_FENCE:0)
Block(0,7,2,DARK_OAK_FENCE:0)
RandomBlock(0,7,6,WALL_BANNER:2,../../NBT/Banners/viking_regular_1.nbt,20,WALL_BANNER:2,../../NBT/Banners/viking_regular_2.nbt,20,WALL_BANNER:2,../../NBT/Banners/viking_regular_3.nbt,20,WALL_BANNER:2,../../NBT/Banners/viking_regular_4.nbt,20,WALL_BANNER:2,../../NBT/Banners/viking_regular_5.nbt,20,WALL_BANNER:2,../../NBT/Banners/viking_regular_6.nbt,20,WALL_BANNER:2,../../NBT/Banners/viking_regular_7.nbt,20,WALL_BANNER:2,../../NBT/Banners/viking_regular_8.nbt,100)
Block(0,7,7,STAINED_CLAY:12)
Block(0,8,-5,WOOD_BUTTON:4)
Block(0,8,-4,LOG:1)
Block(0,8,-3,DARK_OAK_FENCE:0)
Block(0,8,2,DARK_OAK_FENCE:0)
Block(0,8,7,STAINED_CLAY:0)
Block(0,9,-5,SPRUCE_WOOD_STAIRS:5)
Block(0,9,-4,LOG:1)
Block(0,9,-3,DARK_OAK_FENCE:0)
Block(0,9,1,WEB:0)
Block(0,9,2,DARK_OAK_FENCE:0)
Block(0,9,3,WEB:0)
Block(0,9,4,WEB:0)
Block(0,9,5,WEB:0)
Block(0,9,6,WEB:0)
Block(0,9,7,STAINED_CLAY:0)
Block(0,9,8,SPRUCE_WOOD_STAIRS:5)
RandomBlock(0,10,-5,SPRUCE_WOOD_STAIRS:0,70,DARK_OAK_STAIRS:0,100)
RandomBlock(0,10,-4,SPRUCE_WOOD_STAIRS:0,70,DARK_OAK_STAIRS:0,100)
Block(0,10,-3,WOOD:1)
Block(0,10,-2,SPRUCE_WOOD_STAIRS:4)
Block(0,10,-1,SPRUCE_WOOD_STAIRS:4)
Block(0,10,0,SPRUCE_WOOD_STAIRS:4)
Block(0,10,1,WOOD:1)
RandomBlock(0,10,2,SPRUCE_WOOD_STAIRS:0,70,DARK_OAK_STAIRS:0,100)
RandomBlock(0,10,3,SPRUCE_WOOD_STAIRS:0,70,DARK_OAK_STAIRS:0,100)
RandomBlock(0,10,4,SPRUCE_WOOD_STAIRS:0,70,DARK_OAK_STAIRS:0,100)
RandomBlock(0,10,5,SPRUCE_WOOD_STAIRS:0,70,DARK_OAK_STAIRS:0,100)
RandomBlock(0,10,6,SPRUCE_WOOD_STAIRS:0,70,DARK_OAK_STAIRS:0,100)
RandomBlock(0,10,7,SPRUCE_WOOD_STAIRS:0,70,DARK_OAK_STAIRS:0,100)
RandomBlock(0,10,8,SPRUCE_WOOD_STAIRS:0,70,DARK_OAK_STAIRS:0,100)
RandomBlock(0,11,-5,WOOD_STEP:1,70,WOOD_STEP:5,100)
RandomBlock(0,11,-3,SPRUCE_WOOD_STAIRS:0,70,DARK_OAK_STAIRS:0,100)
RandomBlock(0,11,-2,SPRUCE_WOOD_STAIRS:0,70,DARK_OAK_STAIRS:0,100)
RandomBlock(0,11,-1,SPRUCE_WOOD_STAIRS:0,70,DARK_OAK_STAIRS:0,100)
RandomBlock(0,11,0,SPRUCE_WOOD_STAIRS:0,70,DARK_OAK_STAIRS:0,100)
RandomBlock(0,11,1,SPRUCE_WOOD_STAIRS:0,70,DARK_OAK_STAIRS:0,100)
RandomBlock(0,11,8,WOOD_STEP:1,70,WOOD_STEP:5,100)
RandomBlock(1,0,-4,COBBLESTONE:0,60,MOSSY_COBBLESTONE:0,5,SMOOTH_BRICK:0,10,SMOOTH_BRICK:1,10,SMOOTH_BRICK:2,10,COBBLESTONE:0,100)
RandomBlock(1,0,-3,COBBLESTONE:0,60,MOSSY_COBBLESTONE:0,5,SMOOTH_BRICK:0,10,SMOOTH_BRICK:1,10,SMOOTH_BRICK:2,10,COBBLESTONE:0,100)
RandomBlock(1,0,-2,COBBLESTONE:0,60,MOSSY_COBBLESTONE:0,5,SMOOTH_BRICK:0,10,SMOOTH_BRICK:1,10,SMOOTH_BRICK:2,10,COBBLESTONE:0,100)
RandomBlock(1,0,-1,COBBLESTONE:0,60,MOSSY_COBBLESTONE:0,5,SMOOTH_BRICK:0,10,SMOOTH_BRICK:1,10,SMOOTH_BRICK:2,10,COBBLESTONE:0,100)
RandomBlock(1,0,0,COBBLESTONE:0,60,MOSSY_COBBLESTONE:0,5,SMOOTH_BRICK:0,10,SMOOTH_BRICK:1,10,SMOOTH_BRICK:2,10,COBBLESTONE:0,100)
RandomBlock(1,0,1,COBBLESTONE:0,60,MOSSY_COBBLESTONE:0,5,SMOOTH_BRICK:0,10,SMOOTH_BRICK:1,10,SMOOTH_BRICK:2,10,COBBLESTONE:0,100)
RandomBlock(1,0,2,COBBLESTONE:0,60,MOSSY_COBBLESTONE:0,5,SMOOTH_BRICK:0,10,SMOOTH_BRICK:1,10,SMOOTH_BRICK:2,10,COBBLESTONE:0,100)
RandomBlock(1,0,3,COBBLESTONE:0,60,MOSSY_COBBLESTONE:0,5,SMOOTH_BRICK:0,10,SMOOTH_BRICK:1,10,SMOOTH_BRICK:2,10,COBBLESTONE:0,100)
RandomBlock(1,0,4,COBBLESTONE:0,60,MOSSY_COBBLESTONE:0,5,SMOOTH_BRICK:0,10,SMOOTH_BRICK:1,10,SMOOTH_BRICK:2,10,COBBLESTONE:0,100)
RandomBlock(1,0,5,COBBLESTONE:0,60,MOSSY_COBBLESTONE:0,5,SMOOTH_BRICK:0,10,SMOOTH_BRICK:1,10,SMOOTH_BRICK:2,10,COBBLESTONE:0,100)
RandomBlock(1,0,6,COBBLESTONE:0,60,MOSSY_COBBLESTONE:0,5,SMOOTH_BRICK:0,10,SMOOTH_BRICK:1,10,SMOOTH_BRICK:2,10,COBBLESTONE:0,100)
RandomBlock(1,0,7,COBBLESTONE:0,60,MOSSY_COBBLESTONE:0,5,SMOOTH_BRICK:0,10,SMOOTH_BRICK:1,10,SMOOTH_BRICK:2,10,COBBLESTONE:0,100)
RandomBlock(1,1,-4,COBBLESTONE:0,60,MOSSY_COBBLESTONE:0,5,SMOOTH_BRICK:0,10,SMOOTH_BRICK:1,10,SMOOTH_BRICK:2,10,COBBLESTONE:0,100)
RandomBlock(1,1,-3,COBBLESTONE:0,60,MOSSY_COBBLESTONE:0,5,SMOOTH_BRICK:0,10,SMOOTH_BRICK:1,10,SMOOTH_BRICK:2,10,COBBLESTONE:0,100)
RandomBlock(1,1,-2,COBBLESTONE:0,60,MOSSY_COBBLESTONE:0,5,SMOOTH_BRICK:0,10,SMOOTH_BRICK:1,10,SMOOTH_BRICK:2,10,COBBLESTONE:0,100)
RandomBlock(1,1,-1,COBBLESTONE:0,60,MOSSY_COBBLESTONE:0,5,SMOOTH_BRICK:0,10,SMOOTH_BRICK:1,10,SMOOTH_BRICK:2,10,COBBLESTONE:0,100)
RandomBlock(1,1,0,COBBLESTONE:0,60,MOSSY_COBBLESTONE:0,5,SMOOTH_BRICK:0,10,SMOOTH_BRICK:1,10,SMOOTH_BRICK:2,10,COBBLESTONE:0,100)
RandomBlock(1,1,1,COBBLESTONE:0,60,MOSSY_COBBLESTONE:0,5,SMOOTH_BRICK:0,10,SMOOTH_BRICK:1,10,SMOOTH_BRICK:2,10,COBBLESTONE:0,100)
RandomBlock(1,1,2,COBBLESTONE:0,60,MOSSY_COBBLESTONE:0,5,SMOOTH_BRICK:0,10,SMOOTH_BRICK:1,10,SMOOTH_BRICK:2,10,COBBLESTONE:0,100)
RandomBlock(1,1,3,COBBLESTONE:0,60,MOSSY_COBBLESTONE:0,5,SMOOTH_BRICK:0,10,SMOOTH_BRICK:1,10,SMOOTH_BRICK:2,10,COBBLESTONE:0,100)
RandomBlock(1,1,4,COBBLESTONE:0,60,MOSSY_COBBLESTONE:0,5,SMOOTH_BRICK:0,10,SMOOTH_BRICK:1,10,SMOOTH_BRICK:2,10,COBBLESTONE:0,100)
RandomBlock(1,1,5,COBBLESTONE:0,60,MOSSY_COBBLESTONE:0,5,SMOOTH_BRICK:0,10,SMOOTH_BRICK:1,10,SMOOTH_BRICK:2,10,COBBLESTONE:0,100)
RandomBlock(1,1,6,COBBLESTONE:0,60,MOSSY_COBBLESTONE:0,5,SMOOTH_BRICK:0,10,SMOOTH_BRICK:1,10,SMOOTH_BRICK:2,10,COBBLESTONE:0,100)
RandomBlock(1,1,7,COBBLESTONE:0,60,MOSSY_COBBLESTONE:0,5,SMOOTH_BRICK:0,10,SMOOTH_BRICK:1,10,SMOOTH_BRICK:2,10,COBBLESTONE:0,100)
RandomBlock(1,2,-4,COBBLESTONE:0,60,MOSSY_COBBLESTONE:0,5,SMOOTH_BRICK:0,10,SMOOTH_BRICK:1,10,SMOOTH_BRICK:2,10,COBBLESTONE:0,100)
RandomBlock(1,2,-3,COBBLESTONE:0,60,MOSSY_COBBLESTONE:0,5,SMOOTH_BRICK:0,10,SMOOTH_BRICK:1,10,SMOOTH_BRICK:2,10,COBBLESTONE:0,100)
RandomBlock(1,2,-2,COBBLESTONE:0,60,MOSSY_COBBLESTONE:0,5,SMOOTH_BRICK:0,10,SMOOTH_BRICK:1,10,SMOOTH_BRICK:2,10,COBBLESTONE:0,100)
RandomBlock(1,2,-1,COBBLESTONE:0,60,MOSSY_COBBLESTONE:0,5,SMOOTH_BRICK:0,10,SMOOTH_BRICK:1,10,SMOOTH_BRICK:2,10,COBBLESTONE:0,100)
RandomBlock(1,2,0,COBBLESTONE:0,60,MOSSY_COBBLESTONE:0,5,SMOOTH_BRICK:0,10,SMOOTH_BRICK:1,10,SMOOTH_BRICK:2,10,COBBLESTONE:0,100)
RandomBlock(1,2,1,COBBLESTONE:0,60,MOSSY_COBBLESTONE:0,5,SMOOTH_BRICK:0,10,SMOOTH_BRICK:1,10,SMOOTH_BRICK:2,10,COBBLESTONE:0,100)
RandomBlock(1,2,2,COBBLESTONE:0,60,MOSSY_COBBLESTONE:0,5,SMOOTH_BRICK:0,10,SMOOTH_BRICK:1,10,SMOOTH_BRICK:2,10,COBBLESTONE:0,100)
RandomBlock(1,2,3,COBBLESTONE:0,60,MOSSY_COBBLESTONE:0,5,SMOOTH_BRICK:0,10,SMOOTH_BRICK:1,10,SMOOTH_BRICK:2,10,COBBLESTONE:0,100)
RandomBlock(1,2,4,COBBLESTONE:0,60,MOSSY_COBBLESTONE:0,5,SMOOTH_BRICK:0,10,SMOOTH_BRICK:1,10,SMOOTH_BRICK:2,10,COBBLESTONE:0,100)
RandomBlock(1,2,5,COBBLESTONE:0,60,MOSSY_COBBLESTONE:0,5,SMOOTH_BRICK:0,10,SMOOTH_BRICK:1,10,SMOOTH_BRICK:2,10,COBBLESTONE:0,100)
RandomBlock(1,2,6,COBBLESTONE:0,60,MOSSY_COBBLESTONE:0,5,SMOOTH_BRICK:0,10,SMOOTH_BRICK:1,10,SMOOTH_BRICK:2,10,COBBLESTONE:0,100)
RandomBlock(1,2,7,COBBLESTONE:0,60,MOSSY_COBBLESTONE:0,5,SMOOTH_BRICK:0,10,SMOOTH_BRICK:1,10,SMOOTH_BRICK:2,10,COBBLESTONE:0,100)
RandomBlock(1,3,-4,COBBLESTONE:0,60,MOSSY_COBBLESTONE:0,5,SMOOTH_BRICK:0,10,SMOOTH_BRICK:1,10,SMOOTH_BRICK:2,10,COBBLESTONE:0,100)
RandomBlock(1,3,-3,COBBLESTONE:0,60,MOSSY_COBBLESTONE:0,5,SMOOTH_BRICK:0,10,SMOOTH_BRICK:1,10,SMOOTH_BRICK:2,10,COBBLESTONE:0,100)
Block(1,3,-2,COBBLESTONE_STAIRS:1)
Block(1,3,-1,COBBLESTONE_STAIRS:1)
Block(1,3,0,COBBLESTONE_STAIRS:1)
RandomBlock(1,3,1,COBBLESTONE:0,60,MOSSY_COBBLESTONE:0,5,SMOOTH_BRICK:0,10,SMOOTH_BRICK:1,10,SMOOTH_BRICK:2,10,COBBLESTONE:0,100)
RandomBlock(1,3,2,COBBLESTONE:0,60,MOSSY_COBBLESTONE:0,5,SMOOTH_BRICK:0,10,SMOOTH_BRICK:1,10,SMOOTH_BRICK:2,10,COBBLESTONE:0,100)
RandomBlock(1,3,3,COBBLESTONE:0,60,MOSSY_COBBLESTONE:0,5,SMOOTH_BRICK:0,10,SMOOTH_BRICK:1,10,SMOOTH_BRICK:2,10,COBBLESTONE:0,100)
RandomBlock(1,3,4,COBBLESTONE:0,60,MOSSY_COBBLESTONE:0,5,SMOOTH_BRICK:0,10,SMOOTH_BRICK:1,10,SMOOTH_BRICK:2,10,COBBLESTONE:0,100)
RandomBlock(1,3,5,COBBLESTONE:0,60,MOSSY_COBBLESTONE:0,5,SMOOTH_BRICK:0,10,SMOOTH_BRICK:1,10,SMOOTH_BRICK:2,10,COBBLESTONE:0,100)
RandomBlock(1,3,6,COBBLESTONE:0,60,MOSSY_COBBLESTONE:0,5,SMOOTH_BRICK:0,10,SMOOTH_BRICK:1,10,SMOOTH_BRICK:2,10,COBBLESTONE:0,100)
RandomBlock(1,3,7,COBBLESTONE:0,60,MOSSY_COBBLESTONE:0,5,SMOOTH_BRICK:0,10,SMOOTH_BRICK:1,10,SMOOTH_BRICK:2,10,COBBLESTONE:0,100)
Block(1,4,-4,STAINED_CLAY:12)
Block(1,4,2,WOOD:1)
Block(1,4,3,DARK_OAK_FENCE_GATE:3)
Block(1,4,4,FLOWER_POT:0)
Block(1,4,7,LOG:1)
Block(1,4,8,WOOD_BUTTON:3)
Block(1,5,-4,STAINED_CLAY:12)
Block(1,5,2,WOOD:1)
Block(1,5,3,DARK_OAK_FENCE_GATE:3)
RandomBlock(1,5,4,WALL_BANNER:3,../../NBT/Banners/viking_tannery_1.nbt,20,WALL_BANNER:3,../../NBT/Banners/viking_tannery_2.nbt,20,WALL_BANNER:3,../../NBT/Banners/viking_tannery_3.nbt,20,WALL_BANNER:3,../../NBT/Banners/viking_tannery_4.nbt,20,WALL_BANNER:3,../../NBT/Banners/viking_tannery_5.nbt,100)
Block(1,5,6,WEB:0)
Block(1,5,7,LOG:1)
Block(1,5,8,WOOD_BUTTON:3)
Block(1,6,-4,STAINED_CLAY:12)
Block(1,6,-3,WOOD_STEP:13)
Block(1,6,2,LOG:5)
Block(1,6,3,TRAP_DOOR:4)
RandomBlock(1,6,4,WALL_BANNER:3,../../NBT/Banners/viking_tannery_1.nbt,20,WALL_BANNER:3,../../NBT/Banners/viking_tannery_2.nbt,20,WALL_BANNER:3,../../NBT/Banners/viking_tannery_3.nbt,20,WALL_BANNER:3,../../NBT/Banners/viking_tannery_4.nbt,20,WALL_BANNER:3,../../NBT/Banners/viking_tannery_5.nbt,100)
RandomBlock(1,6,6,WALL_BANNER:2,../../NBT/Banners/viking_regular_1.nbt,20,WALL_BANNER:2,../../NBT/Banners/viking_regular_2.nbt,20,WALL_BANNER:2,../../NBT/Banners/viking_regular_3.nbt,20,WALL_BANNER:2,../../NBT/Banners/viking_regular_4.nbt,20,WALL_BANNER:2,../../NBT/Banners/viking_regular_5.nbt,20,WALL_BANNER:2,../../NBT/Banners/viking_regular_6.nbt,20,WALL_BANNER:2,../../NBT/Banners/viking_regular_7.nbt,20,WALL_BANNER:2,../../NBT/Banners/viking_regular_8.nbt,100)
Block(1,6,7,LOG:1)
Block(1,6,8,WOOD_BUTTON:3)
Block(1,7,-4,STAINED_CLAY:0)
RandomBlock(1,7,-3,AIR:0,20,CHEST:3,../../../../Chests/Loot/JunkChest_1.nbt,10,CHEST:3,../../../../Chests/Loot/JunkChest_2.nbt,10,CHEST:3,../../../../Chests/Loot/JunkChest_3.nbt,10,CHEST:3,../../../../Chests/Loot/JunkChest_4.nbt,10,CHEST:3,../../../../Chests/Loot/JunkChest_5.nbt,10,CHEST:3,../../../../Chests/Lore/Viking_1.nbt,1,CHEST:3,../../../../Chests/Lore/Viking_2.nbt,1,CHEST:3,../../../../Chests/Lore/Viking_3.nbt,1,CHEST:3,../../../../Chests/Lore/Viking_4.nbt,1,CHEST:3,../../../../Chests/Lore/Viking_5.nbt,1,CHEST:3,../../../../Chests/Loot/Common1.nbt,10,CHEST:3,../../../../Chests/Loot/Common2.nbt,10,CHEST:3,../../../../Chests/Loot/Common3.nbt,10,CHEST:3,../../../../Chests/Loot/Common4.nbt,10,CHEST:3,../../../../Chests/Loot/Common5.nbt,10,CHEST:3,../../../../Chests/Loot/Common6.nbt,10,CHEST:3,../../../../Chests/Loot/Common7.nbt,10,CHEST:3,../../../../Chests/Loot/Common8.nbt,10,CHEST:3,../../../../Chests/Loot/Common9.nbt,10,CHEST:3,../../../../Chests/Loot/Common10.nbt,10,CHEST:3,../../../../Chests/Loot/Common10.nbt,11,CHEST:3,../../../../Chests/Loot/Common12.nbt,10,CHEST:3,../../../../Chests/Loot/Common13.nbt,10,CHEST:3,../../../../Chests/Loot/Common14.nbt,10,CHEST:3,../../../../Chests/Loot/Common15.nbt,10,CHEST:3,../../../../Chests/Lore/Viking_1.nbt,2,CHEST:3,../../../../Chests/Lore/Viking_3.nbt,2,CHEST:3,../../../../Chests/Lore/Viking_4.nbt,2,CHEST:3,../../../../Chests/Lore/Viking_5.nbt,2,CHEST:3,../../../../Chests/Lore/Viking_5.nbt,2,CHEST:3,../../../../Chests/Loot/Rare1.nbt,5,CHEST:3,../../../../Chests/Loot/Rare2.nbt,5,CHEST:3,../../../../Chests/Loot/Rare3.nbt,5,CHEST:3,../../../../Chests/Loot/Rare4.nbt,5,CHEST:3,../../../../Chests/Loot/Rare5.nbt,5,CHEST:3,../../../../Chests/Loot/Rare6.nbt,5,CHEST:3,../../../../Chests/Loot/Rare7.nbt,5,CHEST:3,../../../../Chests/Loot/Rare8.nbt,5,CHEST:3,../../../../Chests/Loot/Rare9.nbt,5,CHEST:3,../../../../Chests/Loot/Rare10.nbt,5,CHEST:3,../../../../Chests/Loot/Rare11.nbt,5,CHEST:3,../../../../Chests/Loot/Rare12.nbt,5,CHEST:3,../../../../Chests/Loot/Rare13.nbt,5,CHEST:3,../../../../Chests/Loot/Rare14.nbt,5,CHEST:3,../../../../Chests/Loot/Rare15.nbt,5,CHEST:3,../../../../Chests/Loot/Epic1.nbt,2,CHEST:3,../../../../Chests/Loot/Epic2.nbt,2,CHEST:3,../../../../Chests/Loot/Epic3.nbt,2,CHEST:3,../../../../Chests/Loot/Epic4.nbt,2,CHEST:3,../../../../Chests/Loot/Epic5.nbt,2,CHEST:3,../../../../Chests/Loot/Epic6.nbt,2,CHEST:3,../../../../Chests/Loot/Epic7.nbt,2,CHEST:3,../../../../Chests/Loot/Epic8.nbt,2,CHEST:3,../../../../Chests/Loot/Epic9.nbt,2,CHEST:3,../../../../Chests/Loot/Epic10.nbt,2,CHEST:3,../../../../Chests/Loot/Epic11.nbt,2,CHEST:3,../../../../Chests/Loot/Epic12.nbt,2,CHEST:3,../../../../Chests/Loot/Epic13.nbt,2,CHEST:3,../../../../Chests/Loot/Epic14.nbt,2,CHEST:3,../../../../Chests/Loot/Epic15.nbt,5,CHEST:3,../../../../Chests/Loot/Rare1.nbt,5,CHEST:3,../../../../Chests/Loot/Rare2.nbt,5,CHEST:3,../../../../Chests/Loot/Rare3.nbt,5,CHEST:3,../../../../Chests/Loot/Rare4.nbt,5,CHEST:3,../../../../Chests/Loot/Rare5.nbt,10,CHEST:3,../../../../Chests/Loot/Rare6.nbt,10,CHEST:3,../../../../Chests/Loot/Rare7.nbt,10,CHEST:3,../../../../Chests/Loot/Rare8.nbt,10,CHEST:3,../../../../Chests/Loot/Rare9.nbt,10,CHEST:3,../../../../Chests/Loot/Rare10.nbt,15,CHEST:3,../../../../Chests/Loot/Rare11.nbt,15,CHEST:3,../../../../Chests/Loot/Rare12.nbt,15,CHEST:3,../../../../Chests/Loot/Rare13.nbt,15,CHEST:3,../../../../Chests/Loot/Rare14.nbt,15,CHEST:3,../../../../Chests/Loot/Rare15.nbt,15,CHEST:3,../../../../Chests/Loot/Epic15.nbt,100)
Block(1,7,2,DARK_OAK_FENCE:0)
RandomBlock(1,7,6,WALL_BANNER:2,../../NBT/Banners/viking_regular_1.nbt,20,WALL_BANNER:2,../../NBT/Banners/viking_regular_2.nbt,20,WALL_BANNER:2,../../NBT/Banners/viking_regular_3.nbt,20,WALL_BANNER:2,../../NBT/Banners/viking_regular_4.nbt,20,WALL_BANNER:2,../../NBT/Banners/viking_regular_5.nbt,20,WALL_BANNER:2,../../NBT/Banners/viking_regular_6.nbt,20,WALL_BANNER:2,../../NBT/Banners/viking_regular_7.nbt,20,WALL_BANNER:2,../../NBT/Banners/viking_regular_8.nbt,100)
Block(1,7,7,LOG:1)
Block(1,7,8,WOOD_BUTTON:3)
Block(1,8,-4,STAINED_CLAY:0)
Block(1,8,2,DARK_OAK_FENCE:0)
Block(1,8,7,LOG:1)
Block(1,8,8,WOOD_BUTTON:3)
Block(1,9,-5,SPRUCE_WOOD_STAIRS:4)
Block(1,9,-4,STAINED_CLAY:12)
Block(1,9,2,DARK_OAK_FENCE:0)
Block(1,9,3,WEB:0)
Block(1,9,4,WEB:0)
Block(1,9,5,WEB:0)
Block(1,9,6,WEB:0)
Block(1,9,7,LOG:1)
Block(1,9,8,SPRUCE_WOOD_STAIRS:4)
RandomBlock(1,10,-5,SPRUCE_WOOD_STAIRS:1,70,DARK_OAK_STAIRS:1,100)
RandomBlock(1,10,-4,SPRUCE_WOOD_STAIRS:1,70,DARK_OAK_STAIRS:1,100)
Block(1,10,-3,WOOD:1)
Block(1,10,-2,SPRUCE_WOOD_STAIRS:5)
Block(1,10,-1,SPRUCE_WOOD_STAIRS:5)
Block(1,10,0,SPRUCE_WOOD_STAIRS:5)
Block(1,10,1,WOOD:1)
RandomBlock(1,10,2,SPRUCE_WOOD_STAIRS:1,70,DARK_OAK_STAIRS:1,100)
RandomBlock(1,10,3,SPRUCE_WOOD_STAIRS:1,70,DARK_OAK_STAIRS:1,100)
RandomBlock(1,10,4,SPRUCE_WOOD_STAIRS:1,70,DARK_OAK_STAIRS:1,100)
RandomBlock(1,10,5,SPRUCE_WOOD_STAIRS:1,70,DARK_OAK_STAIRS:1,100)
RandomBlock(1,10,6,SPRUCE_WOOD_STAIRS:1,70,DARK_OAK_STAIRS:1,100)
RandomBlock(1,10,7,SPRUCE_WOOD_STAIRS:1,70,DARK_OAK_STAIRS:1,100)
RandomBlock(1,10,8,SPRUCE_WOOD_STAIRS:1,70,DARK_OAK_STAIRS:1,100)
RandomBlock(1,11,-5,WOOD_STEP:1,70,WOOD_STEP:5,100)
RandomBlock(1,11,-3,SPRUCE_WOOD_STAIRS:1,70,DARK_OAK_STAIRS:1,100)
RandomBlock(1,11,-2,SPRUCE_WOOD_STAIRS:1,70,DARK_OAK_STAIRS:1,100)
RandomBlock(1,11,-1,SPRUCE_WOOD_STAIRS:1,70,DARK_OAK_STAIRS:1,100)
RandomBlock(1,11,0,SPRUCE_WOOD_STAIRS:1,70,DARK_OAK_STAIRS:1,100)
RandomBlock(1,11,1,SPRUCE_WOOD_STAIRS:1,70,DARK_OAK_STAIRS:1,100)
RandomBlock(1,11,8,WOOD_STEP:1,70,WOOD_STEP:5,100)
RandomBlock(2,0,-4,COBBLESTONE:0,60,MOSSY_COBBLESTONE:0,5,SMOOTH_BRICK:0,10,SMOOTH_BRICK:1,10,SMOOTH_BRICK:2,10,COBBLESTONE:0,100)
RandomBlock(2,0,-3,COBBLESTONE:0,60,MOSSY_COBBLESTONE:0,5,SMOOTH_BRICK:0,10,SMOOTH_BRICK:1,10,SMOOTH_BRICK:2,10,COBBLESTONE:0,100)
RandomBlock(2,0,-2,COBBLESTONE:0,60,MOSSY_COBBLESTONE:0,5,SMOOTH_BRICK:0,10,SMOOTH_BRICK:1,10,SMOOTH_BRICK:2,10,COBBLESTONE:0,100)
RandomBlock(2,0,-1,COBBLESTONE:0,60,MOSSY_COBBLESTONE:0,5,SMOOTH_BRICK:0,10,SMOOTH_BRICK:1,10,SMOOTH_BRICK:2,10,COBBLESTONE:0,100)
RandomBlock(2,0,0,COBBLESTONE:0,60,MOSSY_COBBLESTONE:0,5,SMOOTH_BRICK:0,10,SMOOTH_BRICK:1,10,SMOOTH_BRICK:2,10,COBBLESTONE:0,100)
RandomBlock(2,0,1,COBBLESTONE:0,60,MOSSY_COBBLESTONE:0,5,SMOOTH_BRICK:0,10,SMOOTH_BRICK:1,10,SMOOTH_BRICK:2,10,COBBLESTONE:0,100)
RandomBlock(2,0,2,COBBLESTONE:0,60,MOSSY_COBBLESTONE:0,5,SMOOTH_BRICK:0,10,SMOOTH_BRICK:1,10,SMOOTH_BRICK:2,10,COBBLESTONE:0,100)
RandomBlock(2,0,3,COBBLESTONE:0,60,MOSSY_COBBLESTONE:0,5,SMOOTH_BRICK:0,10,SMOOTH_BRICK:1,10,SMOOTH_BRICK:2,10,COBBLESTONE:0,100)
RandomBlock(2,0,4,COBBLESTONE:0,60,MOSSY_COBBLESTONE:0,5,SMOOTH_BRICK:0,10,SMOOTH_BRICK:1,10,SMOOTH_BRICK:2,10,COBBLESTONE:0,100)
RandomBlock(2,0,5,COBBLESTONE:0,60,MOSSY_COBBLESTONE:0,5,SMOOTH_BRICK:0,10,SMOOTH_BRICK:1,10,SMOOTH_BRICK:2,10,COBBLESTONE:0,100)
RandomBlock(2,0,6,COBBLESTONE:0,60,MOSSY_COBBLESTONE:0,5,SMOOTH_BRICK:0,10,SMOOTH_BRICK:1,10,SMOOTH_BRICK:2,10,COBBLESTONE:0,100)
RandomBlock(2,0,7,COBBLESTONE:0,60,MOSSY_COBBLESTONE:0,5,SMOOTH_BRICK:0,10,SMOOTH_BRICK:1,10,SMOOTH_BRICK:2,10,COBBLESTONE:0,100)
RandomBlock(2,1,-4,COBBLESTONE:0,60,MOSSY_COBBLESTONE:0,5,SMOOTH_BRICK:0,10,SMOOTH_BRICK:1,10,SMOOTH_BRICK:2,10,COBBLESTONE:0,100)
RandomBlock(2,1,-3,COBBLESTONE:0,60,MOSSY_COBBLESTONE:0,5,SMOOTH_BRICK:0,10,SMOOTH_BRICK:1,10,SMOOTH_BRICK:2,10,COBBLESTONE:0,100)
RandomBlock(2,1,-2,COBBLESTONE:0,60,MOSSY_COBBLESTONE:0,5,SMOOTH_BRICK:0,10,SMOOTH_BRICK:1,10,SMOOTH_BRICK:2,10,COBBLESTONE:0,100)
RandomBlock(2,1,-1,COBBLESTONE:0,60,MOSSY_COBBLESTONE:0,5,SMOOTH_BRICK:0,10,SMOOTH_BRICK:1,10,SMOOTH_BRICK:2,10,COBBLESTONE:0,100)
RandomBlock(2,1,0,COBBLESTONE:0,60,MOSSY_COBBLESTONE:0,5,SMOOTH_BRICK:0,10,SMOOTH_BRICK:1,10,SMOOTH_BRICK:2,10,COBBLESTONE:0,100)
RandomBlock(2,1,1,COBBLESTONE:0,60,MOSSY_COBBLESTONE:0,5,SMOOTH_BRICK:0,10,SMOOTH_BRICK:1,10,SMOOTH_BRICK:2,10,COBBLESTONE:0,100)
RandomBlock(2,1,2,COBBLESTONE:0,60,MOSSY_COBBLESTONE:0,5,SMOOTH_BRICK:0,10,SMOOTH_BRICK:1,10,SMOOTH_BRICK:2,10,COBBLESTONE:0,100)
RandomBlock(2,1,3,COBBLESTONE:0,60,MOSSY_COBBLESTONE:0,5,SMOOTH_BRICK:0,10,SMOOTH_BRICK:1,10,SMOOTH_BRICK:2,10,COBBLESTONE:0,100)
RandomBlock(2,1,4,COBBLESTONE:0,60,MOSSY_COBBLESTONE:0,5,SMOOTH_BRICK:0,10,SMOOTH_BRICK:1,10,SMOOTH_BRICK:2,10,COBBLESTONE:0,100)
RandomBlock(2,1,5,COBBLESTONE:0,60,MOSSY_COBBLESTONE:0,5,SMOOTH_BRICK:0,10,SMOOTH_BRICK:1,10,SMOOTH_BRICK:2,10,COBBLESTONE:0,100)
RandomBlock(2,1,6,COBBLESTONE:0,60,MOSSY_COBBLESTONE:0,5,SMOOTH_BRICK:0,10,SMOOTH_BRICK:1,10,SMOOTH_BRICK:2,10,COBBLESTONE:0,100)
RandomBlock(2,1,7,COBBLESTONE:0,60,MOSSY_COBBLESTONE:0,5,SMOOTH_BRICK:0,10,SMOOTH_BRICK:1,10,SMOOTH_BRICK:2,10,COBBLESTONE:0,100)
RandomBlock(2,2,-4,COBBLESTONE:0,60,MOSSY_COBBLESTONE:0,5,SMOOTH_BRICK:0,10,SMOOTH_BRICK:1,10,SMOOTH_BRICK:2,10,COBBLESTONE:0,100)
RandomBlock(2,2,-3,COBBLESTONE:0,60,MOSSY_COBBLESTONE:0,5,SMOOTH_BRICK:0,10,SMOOTH_BRICK:1,10,SMOOTH_BRICK:2,10,COBBLESTONE:0,100)
RandomBlock(2,2,-2,COBBLESTONE:0,60,MOSSY_COBBLESTONE:0,5,SMOOTH_BRICK:0,10,SMOOTH_BRICK:1,10,SMOOTH_BRICK:2,10,COBBLESTONE:0,100)
Block(2,2,-1,FIRE:0)
RandomBlock(2,2,0,COBBLESTONE:0,60,MOSSY_COBBLESTONE:0,5,SMOOTH_BRICK:0,10,SMOOTH_BRICK:1,10,SMOOTH_BRICK:2,10,COBBLESTONE:0,100)
RandomBlock(2,2,1,COBBLESTONE:0,60,MOSSY_COBBLESTONE:0,5,SMOOTH_BRICK:0,10,SMOOTH_BRICK:1,10,SMOOTH_BRICK:2,10,COBBLESTONE:0,100)
RandomBlock(2,2,2,COBBLESTONE:0,60,MOSSY_COBBLESTONE:0,5,SMOOTH_BRICK:0,10,SMOOTH_BRICK:1,10,SMOOTH_BRICK:2,10,COBBLESTONE:0,100)
RandomBlock(2,2,3,COBBLESTONE:0,60,MOSSY_COBBLESTONE:0,5,SMOOTH_BRICK:0,10,SMOOTH_BRICK:1,10,SMOOTH_BRICK:2,10,COBBLESTONE:0,100)
RandomBlock(2,2,4,COBBLESTONE:0,60,MOSSY_COBBLESTONE:0,5,SMOOTH_BRICK:0,10,SMOOTH_BRICK:1,10,SMOOTH_BRICK:2,10,COBBLESTONE:0,100)
RandomBlock(2,2,5,COBBLESTONE:0,60,MOSSY_COBBLESTONE:0,5,SMOOTH_BRICK:0,10,SMOOTH_BRICK:1,10,SMOOTH_BRICK:2,10,COBBLESTONE:0,100)
RandomBlock(2,2,6,COBBLESTONE:0,60,MOSSY_COBBLESTONE:0,5,SMOOTH_BRICK:0,10,SMOOTH_BRICK:1,10,SMOOTH_BRICK:2,10,COBBLESTONE:0,100)
RandomBlock(2,2,7,COBBLESTONE:0,60,MOSSY_COBBLESTONE:0,5,SMOOTH_BRICK:0,10,SMOOTH_BRICK:1,10,SMOOTH_BRICK:2,10,COBBLESTONE:0,100)
RandomBlock(2,3,-4,COBBLESTONE:0,60,MOSSY_COBBLESTONE:0,5,SMOOTH_BRICK:0,10,SMOOTH_BRICK:1,10,SMOOTH_BRICK:2,10,COBBLESTONE:0,100)
RandomBlock(2,3,-3,COBBLESTONE:0,60,MOSSY_COBBLESTONE:0,5,SMOOTH_BRICK:0,10,SMOOTH_BRICK:1,10,SMOOTH_BRICK:2,10,COBBLESTONE:0,100)
Block(2,3,-2,COBBLESTONE_STAIRS:3)
Block(2,3,0,COBBLESTONE_STAIRS:2)
RandomBlock(2,3,1,COBBLESTONE:0,60,MOSSY_COBBLESTONE:0,5,SMOOTH_BRICK:0,10,SMOOTH_BRICK:1,10,SMOOTH_BRICK:2,10,COBBLESTONE:0,100)
RandomBlock(2,3,2,COBBLESTONE:0,60,MOSSY_COBBLESTONE:0,5,SMOOTH_BRICK:0,10,SMOOTH_BRICK:1,10,SMOOTH_BRICK:2,10,COBBLESTONE:0,100)
RandomBlock(2,3,3,COBBLESTONE:0,60,MOSSY_COBBLESTONE:0,5,SMOOTH_BRICK:0,10,SMOOTH_BRICK:1,10,SMOOTH_BRICK:2,10,COBBLESTONE:0,100)
RandomBlock(2,3,4,COBBLESTONE:0,60,MOSSY_COBBLESTONE:0,5,SMOOTH_BRICK:0,10,SMOOTH_BRICK:1,10,SMOOTH_BRICK:2,10,COBBLESTONE:0,100)
RandomBlock(2,3,5,COBBLESTONE:0,60,MOSSY_COBBLESTONE:0,5,SMOOTH_BRICK:0,10,SMOOTH_BRICK:1,10,SMOOTH_BRICK:2,10,COBBLESTONE:0,100)
RandomBlock(2,3,6,COBBLESTONE:0,60,MOSSY_COBBLESTONE:0,5,SMOOTH_BRICK:0,10,SMOOTH_BRICK:1,10,SMOOTH_BRICK:2,10,COBBLESTONE:0,100)
RandomBlock(2,3,7,COBBLESTONE:0,60,MOSSY_COBBLESTONE:0,5,SMOOTH_BRICK:0,10,SMOOTH_BRICK:1,10,SMOOTH_BRICK:2,10,COBBLESTONE:0,100)
Block(2,4,-4,STAINED_CLAY:0)
Block(2,4,-2,COBBLESTONE_STAIRS:7)
Block(2,4,0,COBBLESTONE_STAIRS:6)
Block(2,4,2,WOOD:1)
Block(2,4,3,TRAP_DOOR:4)
Block(2,4,4,FLOWER_POT:0)
Block(2,4,5,WOOD_STEP:5)
Block(2,4,7,STAINED_CLAY:0)
Block(2,5,-4,STAINED_CLAY:0)
Block(2,5,-2,COBBLESTONE_STAIRS:2)
Block(2,5,-1,DOUBLE_STEP:3)
Block(2,5,0,COBBLESTONE_STAIRS:3)
Block(2,5,2,WOOD:1)
Block(2,5,3,TRAP_DOOR:4)
RandomBlock(2,5,4,WALL_BANNER:3,../../NBT/Banners/viking_tannery_1.nbt,20,WALL_BANNER:3,../../NBT/Banners/viking_tannery_2.nbt,20,WALL_BANNER:3,../../NBT/Banners/viking_tannery_3.nbt,20,WALL_BANNER:3,../../NBT/Banners/viking_tannery_4.nbt,20,WALL_BANNER:3,../../NBT/Banners/viking_tannery_5.nbt,100)
Block(2,5,7,STAINED_CLAY:12)
Block(2,6,-4,STAINED_CLAY:12)
Block(2,6,-3,WOOD_STEP:13)
Block(2,6,2,LOG:5)
Block(2,6,3,TRAP_DOOR:4)
RandomBlock(2,6,4,WALL_BANNER:3,../../NBT/Banners/viking_tannery_1.nbt,20,WALL_BANNER:3,../../NBT/Banners/viking_tannery_2.nbt,20,WALL_BANNER:3,../../NBT/Banners/viking_tannery_3.nbt,20,WALL_BANNER:3,../../NBT/Banners/viking_tannery_4.nbt,20,WALL_BANNER:3,../../NBT/Banners/viking_tannery_5.nbt,100)
Block(2,6,7,STAINED_CLAY:0)
Block(2,7,-4,STAINED_CLAY:0)
RandomBlock(2,7,-3,AIR:0,20,CHEST:3,../../../../Chests/Loot/JunkChest_1.nbt,10,CHEST:3,../../../../Chests/Loot/JunkChest_2.nbt,10,CHEST:3,../../../../Chests/Loot/JunkChest_3.nbt,10,CHEST:3,../../../../Chests/Loot/JunkChest_4.nbt,10,CHEST:3,../../../../Chests/Loot/JunkChest_5.nbt,10,CHEST:3,../../../../Chests/Lore/Viking_1.nbt,1,CHEST:3,../../../../Chests/Lore/Viking_2.nbt,1,CHEST:3,../../../../Chests/Lore/Viking_3.nbt,1,CHEST:3,../../../../Chests/Lore/Viking_4.nbt,1,CHEST:3,../../../../Chests/Lore/Viking_5.nbt,1,CHEST:3,../../../../Chests/Loot/Common1.nbt,10,CHEST:3,../../../../Chests/Loot/Common2.nbt,10,CHEST:3,../../../../Chests/Loot/Common3.nbt,10,CHEST:3,../../../../Chests/Loot/Common4.nbt,10,CHEST:3,../../../../Chests/Loot/Common5.nbt,10,CHEST:3,../../../../Chests/Loot/Common6.nbt,10,CHEST:3,../../../../Chests/Loot/Common7.nbt,10,CHEST:3,../../../../Chests/Loot/Common8.nbt,10,CHEST:3,../../../../Chests/Loot/Common9.nbt,10,CHEST:3,../../../../Chests/Loot/Common10.nbt,10,CHEST:3,../../../../Chests/Loot/Common10.nbt,11,CHEST:3,../../../../Chests/Loot/Common12.nbt,10,CHEST:3,../../../../Chests/Loot/Common13.nbt,10,CHEST:3,../../../../Chests/Loot/Common14.nbt,10,CHEST:3,../../../../Chests/Loot/Common15.nbt,10,CHEST:3,../../../../Chests/Lore/Viking_1.nbt,2,CHEST:3,../../../../Chests/Lore/Viking_3.nbt,2,CHEST:3,../../../../Chests/Lore/Viking_4.nbt,2,CHEST:3,../../../../Chests/Lore/Viking_5.nbt,2,CHEST:3,../../../../Chests/Lore/Viking_5.nbt,2,CHEST:3,../../../../Chests/Loot/Rare1.nbt,5,CHEST:3,../../../../Chests/Loot/Rare2.nbt,5,CHEST:3,../../../../Chests/Loot/Rare3.nbt,5,CHEST:3,../../../../Chests/Loot/Rare4.nbt,5,CHEST:3,../../../../Chests/Loot/Rare5.nbt,5,CHEST:3,../../../../Chests/Loot/Rare6.nbt,5,CHEST:3,../../../../Chests/Loot/Rare7.nbt,5,CHEST:3,../../../../Chests/Loot/Rare8.nbt,5,CHEST:3,../../../../Chests/Loot/Rare9.nbt,5,CHEST:3,../../../../Chests/Loot/Rare10.nbt,5,CHEST:3,../../../../Chests/Loot/Rare11.nbt,5,CHEST:3,../../../../Chests/Loot/Rare12.nbt,5,CHEST:3,../../../../Chests/Loot/Rare13.nbt,5,CHEST:3,../../../../Chests/Loot/Rare14.nbt,5,CHEST:3,../../../../Chests/Loot/Rare15.nbt,5,CHEST:3,../../../../Chests/Loot/Epic1.nbt,2,CHEST:3,../../../../Chests/Loot/Epic2.nbt,2,CHEST:3,../../../../Chests/Loot/Epic3.nbt,2,CHEST:3,../../../../Chests/Loot/Epic4.nbt,2,CHEST:3,../../../../Chests/Loot/Epic5.nbt,2,CHEST:3,../../../../Chests/Loot/Epic6.nbt,2,CHEST:3,../../../../Chests/Loot/Epic7.nbt,2,CHEST:3,../../../../Chests/Loot/Epic8.nbt,2,CHEST:3,../../../../Chests/Loot/Epic9.nbt,2,CHEST:3,../../../../Chests/Loot/Epic10.nbt,2,CHEST:3,../../../../Chests/Loot/Epic11.nbt,2,CHEST:3,../../../../Chests/Loot/Epic12.nbt,2,CHEST:3,../../../../Chests/Loot/Epic13.nbt,2,CHEST:3,../../../../Chests/Loot/Epic14.nbt,2,CHEST:3,../../../../Chests/Loot/Epic15.nbt,5,CHEST:3,../../../../Chests/Loot/Rare1.nbt,5,CHEST:3,../../../../Chests/Loot/Rare2.nbt,5,CHEST:3,../../../../Chests/Loot/Rare3.nbt,5,CHEST:3,../../../../Chests/Loot/Rare4.nbt,5,CHEST:3,../../../../Chests/Loot/Rare5.nbt,10,CHEST:3,../../../../Chests/Loot/Rare6.nbt,10,CHEST:3,../../../../Chests/Loot/Rare7.nbt,10,CHEST:3,../../../../Chests/Loot/Rare8.nbt,10,CHEST:3,../../../../Chests/Loot/Rare9.nbt,10,CHEST:3,../../../../Chests/Loot/Rare10.nbt,15,CHEST:3,../../../../Chests/Loot/Rare11.nbt,15,CHEST:3,../../../../Chests/Loot/Rare12.nbt,15,CHEST:3,../../../../Chests/Loot/Rare13.nbt,15,CHEST:3,../../../../Chests/Loot/Rare14.nbt,15,CHEST:3,../../../../Chests/Loot/Rare15.nbt,15,CHEST:3,../../../../Chests/Loot/Epic15.nbt,100)
Block(2,7,2,DARK_OAK_FENCE:0)
Block(2,7,6,WEB:0)
Block(2,7,7,STAINED_CLAY:12)
Block(2,8,-5,SPRUCE_WOOD_STAIRS:4)
Block(2,8,-4,STAINED_CLAY:0)
Block(2,8,2,DARK_OAK_FENCE:0)
Block(2,8,3,WEB:0)
Block(2,8,4,WEB:0)
Block(2,8,5,WEB:0)
RandomBlock(2,8,6,WALL_BANNER:2,../../NBT/Banners/viking_regular_1.nbt,20,WALL_BANNER:2,../../NBT/Banners/viking_regular_2.nbt,20,WALL_BANNER:2,../../NBT/Banners/viking_regular_3.nbt,20,WALL_BANNER:2,../../NBT/Banners/viking_regular_4.nbt,20,WALL_BANNER:2,../../NBT/Banners/viking_regular_5.nbt,20,WALL_BANNER:2,../../NBT/Banners/viking_regular_6.nbt,20,WALL_BANNER:2,../../NBT/Banners/viking_regular_7.nbt,20,WALL_BANNER:2,../../NBT/Banners/viking_regular_8.nbt,100)
Block(2,8,7,STAINED_CLAY:0)
Block(2,8,8,SPRUCE_WOOD_STAIRS:4)
RandomBlock(2,9,-5,SPRUCE_WOOD_STAIRS:1,70,DARK_OAK_STAIRS:1,100)
RandomBlock(2,9,-4,SPRUCE_WOOD_STAIRS:1,70,DARK_OAK_STAIRS:1,100)
RandomBlock(2,9,-3,SPRUCE_WOOD_STAIRS:1,70,DARK_OAK_STAIRS:1,100)
RandomBlock(2,9,-2,SPRUCE_WOOD_STAIRS:1,70,DARK_OAK_STAIRS:1,100)
RandomBlock(2,9,-1,SPRUCE_WOOD_STAIRS:1,70,DARK_OAK_STAIRS:1,100)
RandomBlock(2,9,0,SPRUCE_WOOD_STAIRS:1,70,DARK_OAK_STAIRS:1,100)
RandomBlock(2,9,1,SPRUCE_WOOD_STAIRS:1,70,DARK_OAK_STAIRS:1,100)
RandomBlock(2,9,2,SPRUCE_WOOD_STAIRS:1,70,DARK_OAK_STAIRS:1,100)
RandomBlock(2,9,3,SPRUCE_WOOD_STAIRS:1,70,DARK_OAK_STAIRS:1,100)
RandomBlock(2,9,4,SPRUCE_WOOD_STAIRS:1,70,DARK_OAK_STAIRS:1,100)
RandomBlock(2,9,5,SPRUCE_WOOD_STAIRS:1,70,DARK_OAK_STAIRS:1,100)
RandomBlock(2,9,6,SPRUCE_WOOD_STAIRS:1,70,DARK_OAK_STAIRS:1,100)
RandomBlock(2,9,7,SPRUCE_WOOD_STAIRS:1,70,DARK_OAK_STAIRS:1,100)
RandomBlock(2,9,8,SPRUCE_WOOD_STAIRS:1,70,DARK_OAK_STAIRS:1,100)
RandomBlock(2,10,-3,SPRUCE_WOOD_STAIRS:1,70,DARK_OAK_STAIRS:1,100)
Block(2,10,-2,TRAP_DOOR:11)
Block(2,10,-1,TRAP_DOOR:11)
Block(2,10,0,TRAP_DOOR:11)
RandomBlock(2,10,1,SPRUCE_WOOD_STAIRS:1,70,DARK_OAK_STAIRS:1,100)
RandomBlock(3,0,-4,COBBLESTONE:0,60,MOSSY_COBBLESTONE:0,5,SMOOTH_BRICK:0,10,SMOOTH_BRICK:1,10,SMOOTH_BRICK:2,10,COBBLESTONE:0,100)
RandomBlock(3,0,-3,COBBLESTONE:0,60,MOSSY_COBBLESTONE:0,5,SMOOTH_BRICK:0,10,SMOOTH_BRICK:1,10,SMOOTH_BRICK:2,10,COBBLESTONE:0,100)
RandomBlock(3,0,-2,COBBLESTONE:0,60,MOSSY_COBBLESTONE:0,5,SMOOTH_BRICK:0,10,SMOOTH_BRICK:1,10,SMOOTH_BRICK:2,10,COBBLESTONE:0,100)
RandomBlock(3,0,-1,COBBLESTONE:0,60,MOSSY_COBBLESTONE:0,5,SMOOTH_BRICK:0,10,SMOOTH_BRICK:1,10,SMOOTH_BRICK:2,10,COBBLESTONE:0,100)
RandomBlock(3,0,0,COBBLESTONE:0,60,MOSSY_COBBLESTONE:0,5,SMOOTH_BRICK:0,10,SMOOTH_BRICK:1,10,SMOOTH_BRICK:2,10,COBBLESTONE:0,100)
RandomBlock(3,0,1,COBBLESTONE:0,60,MOSSY_COBBLESTONE:0,5,SMOOTH_BRICK:0,10,SMOOTH_BRICK:1,10,SMOOTH_BRICK:2,10,COBBLESTONE:0,100)
RandomBlock(3,0,2,COBBLESTONE:0,60,MOSSY_COBBLESTONE:0,5,SMOOTH_BRICK:0,10,SMOOTH_BRICK:1,10,SMOOTH_BRICK:2,10,COBBLESTONE:0,100)
RandomBlock(3,0,3,COBBLESTONE:0,60,MOSSY_COBBLESTONE:0,5,SMOOTH_BRICK:0,10,SMOOTH_BRICK:1,10,SMOOTH_BRICK:2,10,COBBLESTONE:0,100)
RandomBlock(3,0,4,COBBLESTONE:0,60,MOSSY_COBBLESTONE:0,5,SMOOTH_BRICK:0,10,SMOOTH_BRICK:1,10,SMOOTH_BRICK:2,10,COBBLESTONE:0,100)
RandomBlock(3,0,5,COBBLESTONE:0,60,MOSSY_COBBLESTONE:0,5,SMOOTH_BRICK:0,10,SMOOTH_BRICK:1,10,SMOOTH_BRICK:2,10,COBBLESTONE:0,100)
RandomBlock(3,0,6,COBBLESTONE:0,60,MOSSY_COBBLESTONE:0,5,SMOOTH_BRICK:0,10,SMOOTH_BRICK:1,10,SMOOTH_BRICK:2,10,COBBLESTONE:0,100)
RandomBlock(3,0,7,COBBLESTONE:0,60,MOSSY_COBBLESTONE:0,5,SMOOTH_BRICK:0,10,SMOOTH_BRICK:1,10,SMOOTH_BRICK:2,10,COBBLESTONE:0,100)
RandomBlock(3,1,-4,COBBLESTONE:0,60,MOSSY_COBBLESTONE:0,5,SMOOTH_BRICK:0,10,SMOOTH_BRICK:1,10,SMOOTH_BRICK:2,10,COBBLESTONE:0,100)
RandomBlock(3,1,-3,COBBLESTONE:0,60,MOSSY_COBBLESTONE:0,5,SMOOTH_BRICK:0,10,SMOOTH_BRICK:1,10,SMOOTH_BRICK:2,10,COBBLESTONE:0,100)
RandomBlock(3,1,-2,COBBLESTONE:0,60,MOSSY_COBBLESTONE:0,5,SMOOTH_BRICK:0,10,SMOOTH_BRICK:1,10,SMOOTH_BRICK:2,10,COBBLESTONE:0,100)
RandomBlock(3,1,-1,COBBLESTONE:0,60,MOSSY_COBBLESTONE:0,5,SMOOTH_BRICK:0,10,SMOOTH_BRICK:1,10,SMOOTH_BRICK:2,10,COBBLESTONE:0,100)
RandomBlock(3,1,0,COBBLESTONE:0,60,MOSSY_COBBLESTONE:0,5,SMOOTH_BRICK:0,10,SMOOTH_BRICK:1,10,SMOOTH_BRICK:2,10,COBBLESTONE:0,100)
RandomBlock(3,1,1,COBBLESTONE:0,60,MOSSY_COBBLESTONE:0,5,SMOOTH_BRICK:0,10,SMOOTH_BRICK:1,10,SMOOTH_BRICK:2,10,COBBLESTONE:0,100)
RandomBlock(3,1,2,COBBLESTONE:0,60,MOSSY_COBBLESTONE:0,5,SMOOTH_BRICK:0,10,SMOOTH_BRICK:1,10,SMOOTH_BRICK:2,10,COBBLESTONE:0,100)
RandomBlock(3,1,3,COBBLESTONE:0,60,MOSSY_COBBLESTONE:0,5,SMOOTH_BRICK:0,10,SMOOTH_BRICK:1,10,SMOOTH_BRICK:2,10,COBBLESTONE:0,100)
RandomBlock(3,1,4,COBBLESTONE:0,60,MOSSY_COBBLESTONE:0,5,SMOOTH_BRICK:0,10,SMOOTH_BRICK:1,10,SMOOTH_BRICK:2,10,COBBLESTONE:0,100)
RandomBlock(3,1,5,COBBLESTONE:0,60,MOSSY_COBBLESTONE:0,5,SMOOTH_BRICK:0,10,SMOOTH_BRICK:1,10,SMOOTH_BRICK:2,10,COBBLESTONE:0,100)
RandomBlock(3,1,6,COBBLESTONE:0,60,MOSSY_COBBLESTONE:0,5,SMOOTH_BRICK:0,10,SMOOTH_BRICK:1,10,SMOOTH_BRICK:2,10,COBBLESTONE:0,100)
RandomBlock(3,1,7,COBBLESTONE:0,60,MOSSY_COBBLESTONE:0,5,SMOOTH_BRICK:0,10,SMOOTH_BRICK:1,10,SMOOTH_BRICK:2,10,COBBLESTONE:0,100)
RandomBlock(3,2,-4,COBBLESTONE:0,60,MOSSY_COBBLESTONE:0,5,SMOOTH_BRICK:0,10,SMOOTH_BRICK:1,10,SMOOTH_BRICK:2,10,COBBLESTONE:0,100)
RandomBlock(3,2,-3,COBBLESTONE:0,60,MOSSY_COBBLESTONE:0,5,SMOOTH_BRICK:0,10,SMOOTH_BRICK:1,10,SMOOTH_BRICK:2,10,COBBLESTONE:0,100)
RandomBlock(3,2,-2,COBBLESTONE:0,60,MOSSY_COBBLESTONE:0,5,SMOOTH_BRICK:0,10,SMOOTH_BRICK:1,10,SMOOTH_BRICK:2,10,COBBLESTONE:0,100)
RandomBlock(3,2,-1,COBBLESTONE:0,60,MOSSY_COBBLESTONE:0,5,SMOOTH_BRICK:0,10,SMOOTH_BRICK:1,10,SMOOTH_BRICK:2,10,COBBLESTONE:0,100)
RandomBlock(3,2,0,COBBLESTONE:0,60,MOSSY_COBBLESTONE:0,5,SMOOTH_BRICK:0,10,SMOOTH_BRICK:1,10,SMOOTH_BRICK:2,10,COBBLESTONE:0,100)
RandomBlock(3,2,1,COBBLESTONE:0,60,MOSSY_COBBLESTONE:0,5,SMOOTH_BRICK:0,10,SMOOTH_BRICK:1,10,SMOOTH_BRICK:2,10,COBBLESTONE:0,100)
RandomBlock(3,2,2,COBBLESTONE:0,60,MOSSY_COBBLESTONE:0,5,SMOOTH_BRICK:0,10,SMOOTH_BRICK:1,10,SMOOTH_BRICK:2,10,COBBLESTONE:0,100)
RandomBlock(3,2,3,COBBLESTONE:0,60,MOSSY_COBBLESTONE:0,5,SMOOTH_BRICK:0,10,SMOOTH_BRICK:1,10,SMOOTH_BRICK:2,10,COBBLESTONE:0,100)
RandomBlock(3,2,4,COBBLESTONE:0,60,MOSSY_COBBLESTONE:0,5,SMOOTH_BRICK:0,10,SMOOTH_BRICK:1,10,SMOOTH_BRICK:2,10,COBBLESTONE:0,100)
RandomBlock(3,2,5,COBBLESTONE:0,60,MOSSY_COBBLESTONE:0,5,SMOOTH_BRICK:0,10,SMOOTH_BRICK:1,10,SMOOTH_BRICK:2,10,COBBLESTONE:0,100)
RandomBlock(3,2,6,COBBLESTONE:0,60,MOSSY_COBBLESTONE:0,5,SMOOTH_BRICK:0,10,SMOOTH_BRICK:1,10,SMOOTH_BRICK:2,10,COBBLESTONE:0,100)
RandomBlock(3,2,7,COBBLESTONE:0,60,MOSSY_COBBLESTONE:0,5,SMOOTH_BRICK:0,10,SMOOTH_BRICK:1,10,SMOOTH_BRICK:2,10,COBBLESTONE:0,100)
RandomBlock(3,3,-4,COBBLESTONE:0,60,MOSSY_COBBLESTONE:0,5,SMOOTH_BRICK:0,10,SMOOTH_BRICK:1,10,SMOOTH_BRICK:2,10,COBBLESTONE:0,100)
RandomBlock(3,3,-3,COBBLESTONE:0,60,MOSSY_COBBLESTONE:0,5,SMOOTH_BRICK:0,10,SMOOTH_BRICK:1,10,SMOOTH_BRICK:2,10,COBBLESTONE:0,100)
RandomBlock(3,3,-2,COBBLESTONE:0,60,MOSSY_COBBLESTONE:0,5,SMOOTH_BRICK:0,10,SMOOTH_BRICK:1,10,SMOOTH_BRICK:2,10,COBBLESTONE:0,100)
RandomBlock(3,3,-1,COBBLESTONE:0,60,MOSSY_COBBLESTONE:0,5,SMOOTH_BRICK:0,10,SMOOTH_BRICK:1,10,SMOOTH_BRICK:2,10,COBBLESTONE:0,100)
RandomBlock(3,3,0,COBBLESTONE:0,60,MOSSY_COBBLESTONE:0,5,SMOOTH_BRICK:0,10,SMOOTH_BRICK:1,10,SMOOTH_BRICK:2,10,COBBLESTONE:0,100)
RandomBlock(3,3,1,COBBLESTONE:0,60,MOSSY_COBBLESTONE:0,5,SMOOTH_BRICK:0,10,SMOOTH_BRICK:1,10,SMOOTH_BRICK:2,10,COBBLESTONE:0,100)
RandomBlock(3,3,2,COBBLESTONE:0,60,MOSSY_COBBLESTONE:0,5,SMOOTH_BRICK:0,10,SMOOTH_BRICK:1,10,SMOOTH_BRICK:2,10,COBBLESTONE:0,100)
RandomBlock(3,3,3,COBBLESTONE:0,60,MOSSY_COBBLESTONE:0,5,SMOOTH_BRICK:0,10,SMOOTH_BRICK:1,10,SMOOTH_BRICK:2,10,COBBLESTONE:0,100)
RandomBlock(3,3,4,COBBLESTONE:0,60,MOSSY_COBBLESTONE:0,5,SMOOTH_BRICK:0,10,SMOOTH_BRICK:1,10,SMOOTH_BRICK:2,10,COBBLESTONE:0,100)
RandomBlock(3,3,5,COBBLESTONE:0,60,MOSSY_COBBLESTONE:0,5,SMOOTH_BRICK:0,10,SMOOTH_BRICK:1,10,SMOOTH_BRICK:2,10,COBBLESTONE:0,100)
RandomBlock(3,3,6,COBBLESTONE:0,60,MOSSY_COBBLESTONE:0,5,SMOOTH_BRICK:0,10,SMOOTH_BRICK:1,10,SMOOTH_BRICK:2,10,COBBLESTONE:0,100)
RandomBlock(3,3,7,COBBLESTONE:0,60,MOSSY_COBBLESTONE:0,5,SMOOTH_BRICK:0,10,SMOOTH_BRICK:1,10,SMOOTH_BRICK:2,10,COBBLESTONE:0,100)
Block(3,4,-4,STAINED_CLAY:12)
Block(3,4,-3,CAULDRON:3)
RandomBlock(3,4,-2,COBBLESTONE:0,60,MOSSY_COBBLESTONE:0,5,SMOOTH_BRICK:0,10,SMOOTH_BRICK:1,10,SMOOTH_BRICK:2,10,COBBLESTONE:0,100)
RandomBlock(3,4,-1,COBBLESTONE:0,60,MOSSY_COBBLESTONE:0,5,SMOOTH_BRICK:0,10,SMOOTH_BRICK:1,10,SMOOTH_BRICK:2,10,COBBLESTONE:0,100)
RandomBlock(3,4,0,COBBLESTONE:0,60,MOSSY_COBBLESTONE:0,5,SMOOTH_BRICK:0,10,SMOOTH_BRICK:1,10,SMOOTH_BRICK:2,10,COBBLESTONE:0,100)
Block(3,4,2,WOOD:1)
Block(3,4,3,DARK_OAK_FENCE_GATE:3)
Block(3,4,4,FLOWER_POT:0)
Block(3,4,7,STAINED_CLAY:0)
Block(3,5,-4,STAINED_CLAY:0)
Block(3,5,-2,COBBLESTONE_STAIRS:2)
Block(3,5,-1,DOUBLE_STEP:3)
Block(3,5,0,COBBLESTONE_STAIRS:3)
Block(3,5,2,WOOD:1)
Block(3,5,3,DARK_OAK_FENCE_GATE:3)
RandomBlock(3,5,4,WALL_BANNER:3,../../NBT/Banners/viking_tannery_1.nbt,20,WALL_BANNER:3,../../NBT/Banners/viking_tannery_2.nbt,20,WALL_BANNER:3,../../NBT/Banners/viking_tannery_3.nbt,20,WALL_BANNER:3,../../NBT/Banners/viking_tannery_4.nbt,20,WALL_BANNER:3,../../NBT/Banners/viking_tannery_5.nbt,100)
Block(3,5,5,DARK_OAK_FENCE_GATE:2)
Block(3,5,6,DARK_OAK_FENCE_GATE:0)
Block(3,5,7,STAINED_CLAY:12)
Block(3,6,-4,STAINED_CLAY:0)
Block(3,6,-3,WOOD_STEP:13)
RandomBlock(3,6,1,WALL_BANNER:4,../../NBT/Banners/viking_tannery_1.nbt,20,WALL_BANNER:4,../../NBT/Banners/viking_tannery_2.nbt,20,WALL_BANNER:4,../../NBT/Banners/viking_tannery_3.nbt,20,WALL_BANNER:4,../../NBT/Banners/viking_tannery_4.nbt,20,WALL_BANNER:4,../../NBT/Banners/viking_tannery_5.nbt,100)
Block(3,6,2,LOG:5)
Block(3,6,3,TRAP_DOOR:4)
RandomBlock(3,6,4,WALL_BANNER:3,../../NBT/Banners/viking_tannery_1.nbt,20,WALL_BANNER:3,../../NBT/Banners/viking_tannery_2.nbt,20,WALL_BANNER:3,../../NBT/Banners/viking_tannery_3.nbt,20,WALL_BANNER:3,../../NBT/Banners/viking_tannery_4.nbt,20,WALL_BANNER:3,../../NBT/Banners/viking_tannery_5.nbt,100)
RandomBlock(3,6,5,WOOD_STEP:1,70,WOOD_STEP:5,100)
RandomBlock(3,6,6,WOOD_STEP:1,70,WOOD_STEP:5,100)
Block(3,6,7,STAINED_CLAY:12)
Block(3,7,-5,SPRUCE_WOOD_STAIRS:4)
Block(3,7,-4,STAINED_CLAY:0)
Block(3,7,2,DARK_OAK_FENCE:0)
Block(3,7,3,WEB:0)
Block(3,7,4,WEB:0)
Block(3,7,5,WEB:0)
Block(3,7,6,AIR:0)
Block(3,7,7,STAINED_CLAY:0)
Block(3,7,8,SPRUCE_WOOD_STAIRS:4)
RandomBlock(3,8,-5,SPRUCE_WOOD_STAIRS:1,70,DARK_OAK_STAIRS:1,100)
RandomBlock(3,8,-4,SPRUCE_WOOD_STAIRS:1,70,DARK_OAK_STAIRS:1,100)
RandomBlock(3,8,-3,SPRUCE_WOOD_STAIRS:1,70,DARK_OAK_STAIRS:1,100)
RandomBlock(3,8,-2,SPRUCE_WOOD_STAIRS:1,70,DARK_OAK_STAIRS:1,100)
RandomBlock(3,8,-1,SPRUCE_WOOD_STAIRS:1,70,DARK_OAK_STAIRS:1,100)
RandomBlock(3,8,0,SPRUCE_WOOD_STAIRS:1,70,DARK_OAK_STAIRS:1,100)
RandomBlock(3,8,1,SPRUCE_WOOD_STAIRS:1,70,DARK_OAK_STAIRS:1,100)
RandomBlock(3,8,2,SPRUCE_WOOD_STAIRS:1,70,DARK_OAK_STAIRS:1,100)
RandomBlock(3,8,3,SPRUCE_WOOD_STAIRS:1,70,DARK_OAK_STAIRS:1,100)
RandomBlock(3,8,4,SPRUCE_WOOD_STAIRS:1,70,DARK_OAK_STAIRS:1,100)
RandomBlock(3,8,5,SPRUCE_WOOD_STAIRS:1,70,DARK_OAK_STAIRS:1,100)
RandomBlock(3,8,6,SPRUCE_WOOD_STAIRS:1,70,DARK_OAK_STAIRS:1,100)
RandomBlock(3,8,7,SPRUCE_WOOD_STAIRS:1,70,DARK_OAK_STAIRS:1,100)
RandomBlock(3,8,8,SPRUCE_WOOD_STAIRS:1,70,DARK_OAK_STAIRS:1,100)
Block(4,0,-4,LOG:1)
RandomBlock(4,0,-3,COBBLESTONE:0,60,MOSSY_COBBLESTONE:0,5,SMOOTH_BRICK:0,10,SMOOTH_BRICK:1,10,SMOOTH_BRICK:2,10,COBBLESTONE:0,100)
RandomBlock(4,0,-2,COBBLESTONE:0,60,MOSSY_COBBLESTONE:0,5,SMOOTH_BRICK:0,10,SMOOTH_BRICK:1,10,SMOOTH_BRICK:2,10,COBBLESTONE:0,100)
RandomBlock(4,0,-1,COBBLESTONE:0,60,MOSSY_COBBLESTONE:0,5,SMOOTH_BRICK:0,10,SMOOTH_BRICK:1,10,SMOOTH_BRICK:2,10,COBBLESTONE:0,100)
RandomBlock(4,0,0,COBBLESTONE:0,60,MOSSY_COBBLESTONE:0,5,SMOOTH_BRICK:0,10,SMOOTH_BRICK:1,10,SMOOTH_BRICK:2,10,COBBLESTONE:0,100)
RandomBlock(4,0,1,COBBLESTONE:0,60,MOSSY_COBBLESTONE:0,5,SMOOTH_BRICK:0,10,SMOOTH_BRICK:1,10,SMOOTH_BRICK:2,10,COBBLESTONE:0,100)
Block(4,0,2,LOG:1)
RandomBlock(4,0,3,COBBLESTONE:0,60,MOSSY_COBBLESTONE:0,5,SMOOTH_BRICK:0,10,SMOOTH_BRICK:1,10,SMOOTH_BRICK:2,10,COBBLESTONE:0,100)
RandomBlock(4,0,4,COBBLESTONE:0,60,MOSSY_COBBLESTONE:0,5,SMOOTH_BRICK:0,10,SMOOTH_BRICK:1,10,SMOOTH_BRICK:2,10,COBBLESTONE:0,100)
RandomBlock(4,0,5,COBBLESTONE:0,60,MOSSY_COBBLESTONE:0,5,SMOOTH_BRICK:0,10,SMOOTH_BRICK:1,10,SMOOTH_BRICK:2,10,COBBLESTONE:0,100)
RandomBlock(4,0,6,COBBLESTONE:0,60,MOSSY_COBBLESTONE:0,5,SMOOTH_BRICK:0,10,SMOOTH_BRICK:1,10,SMOOTH_BRICK:2,10,COBBLESTONE:0,100)
Block(4,0,7,LOG:1)
Block(4,1,-4,LOG:1)
RandomBlock(4,1,-3,COBBLESTONE:0,60,MOSSY_COBBLESTONE:0,5,SMOOTH_BRICK:0,10,SMOOTH_BRICK:1,10,SMOOTH_BRICK:2,10,COBBLESTONE:0,100)
RandomBlock(4,1,-2,COBBLESTONE:0,60,MOSSY_COBBLESTONE:0,5,SMOOTH_BRICK:0,10,SMOOTH_BRICK:1,10,SMOOTH_BRICK:2,10,COBBLESTONE:0,100)
RandomBlock(4,1,-1,COBBLESTONE:0,60,MOSSY_COBBLESTONE:0,5,SMOOTH_BRICK:0,10,SMOOTH_BRICK:1,10,SMOOTH_BRICK:2,10,COBBLESTONE:0,100)
RandomBlock(4,1,0,COBBLESTONE:0,60,MOSSY_COBBLESTONE:0,5,SMOOTH_BRICK:0,10,SMOOTH_BRICK:1,10,SMOOTH_BRICK:2,10,COBBLESTONE:0,100)
RandomBlock(4,1,1,COBBLESTONE:0,60,MOSSY_COBBLESTONE:0,5,SMOOTH_BRICK:0,10,SMOOTH_BRICK:1,10,SMOOTH_BRICK:2,10,COBBLESTONE:0,100)
Block(4,1,2,LOG:1)
RandomBlock(4,1,3,COBBLESTONE:0,60,MOSSY_COBBLESTONE:0,5,SMOOTH_BRICK:0,10,SMOOTH_BRICK:1,10,SMOOTH_BRICK:2,10,COBBLESTONE:0,100)
RandomBlock(4,1,4,COBBLESTONE:0,60,MOSSY_COBBLESTONE:0,5,SMOOTH_BRICK:0,10,SMOOTH_BRICK:1,10,SMOOTH_BRICK:2,10,COBBLESTONE:0,100)
RandomBlock(4,1,5,COBBLESTONE:0,60,MOSSY_COBBLESTONE:0,5,SMOOTH_BRICK:0,10,SMOOTH_BRICK:1,10,SMOOTH_BRICK:2,10,COBBLESTONE:0,100)
RandomBlock(4,1,6,COBBLESTONE:0,60,MOSSY_COBBLESTONE:0,5,SMOOTH_BRICK:0,10,SMOOTH_BRICK:1,10,SMOOTH_BRICK:2,10,COBBLESTONE:0,100)
Block(4,1,7,LOG:1)
Block(4,2,-4,LOG:1)
RandomBlock(4,2,-3,COBBLESTONE:0,60,MOSSY_COBBLESTONE:0,5,SMOOTH_BRICK:0,10,SMOOTH_BRICK:1,10,SMOOTH_BRICK:2,10,COBBLESTONE:0,100)
RandomBlock(4,2,-2,COBBLESTONE:0,60,MOSSY_COBBLESTONE:0,5,SMOOTH_BRICK:0,10,SMOOTH_BRICK:1,10,SMOOTH_BRICK:2,10,COBBLESTONE:0,100)
RandomBlock(4,2,-1,COBBLESTONE:0,60,MOSSY_COBBLESTONE:0,5,SMOOTH_BRICK:0,10,SMOOTH_BRICK:1,10,SMOOTH_BRICK:2,10,COBBLESTONE:0,100)
RandomBlock(4,2,0,COBBLESTONE:0,60,MOSSY_COBBLESTONE:0,5,SMOOTH_BRICK:0,10,SMOOTH_BRICK:1,10,SMOOTH_BRICK:2,10,COBBLESTONE:0,100)
RandomBlock(4,2,1,COBBLESTONE:0,60,MOSSY_COBBLESTONE:0,5,SMOOTH_BRICK:0,10,SMOOTH_BRICK:1,10,SMOOTH_BRICK:2,10,COBBLESTONE:0,100)
Block(4,2,2,LOG:1)
RandomBlock(4,2,3,COBBLESTONE:0,60,MOSSY_COBBLESTONE:0,5,SMOOTH_BRICK:0,10,SMOOTH_BRICK:1,10,SMOOTH_BRICK:2,10,COBBLESTONE:0,100)
RandomBlock(4,2,4,COBBLESTONE:0,60,MOSSY_COBBLESTONE:0,5,SMOOTH_BRICK:0,10,SMOOTH_BRICK:1,10,SMOOTH_BRICK:2,10,COBBLESTONE:0,100)
RandomBlock(4,2,5,COBBLESTONE:0,60,MOSSY_COBBLESTONE:0,5,SMOOTH_BRICK:0,10,SMOOTH_BRICK:1,10,SMOOTH_BRICK:2,10,COBBLESTONE:0,100)
RandomBlock(4,2,6,COBBLESTONE:0,60,MOSSY_COBBLESTONE:0,5,SMOOTH_BRICK:0,10,SMOOTH_BRICK:1,10,SMOOTH_BRICK:2,10,COBBLESTONE:0,100)
Block(4,2,7,LOG:1)
Block(4,3,-4,LOG:1)
RandomBlock(4,3,-3,COBBLESTONE:0,60,MOSSY_COBBLESTONE:0,5,SMOOTH_BRICK:0,10,SMOOTH_BRICK:1,10,SMOOTH_BRICK:2,10,COBBLESTONE:0,100)
RandomBlock(4,3,-2,COBBLESTONE:0,60,MOSSY_COBBLESTONE:0,5,SMOOTH_BRICK:0,10,SMOOTH_BRICK:1,10,SMOOTH_BRICK:2,10,COBBLESTONE:0,100)
RandomBlock(4,3,-1,COBBLESTONE:0,60,MOSSY_COBBLESTONE:0,5,SMOOTH_BRICK:0,10,SMOOTH_BRICK:1,10,SMOOTH_BRICK:2,10,COBBLESTONE:0,100)
RandomBlock(4,3,0,COBBLESTONE:0,60,MOSSY_COBBLESTONE:0,5,SMOOTH_BRICK:0,10,SMOOTH_BRICK:1,10,SMOOTH_BRICK:2,10,COBBLESTONE:0,100)
RandomBlock(4,3,1,COBBLESTONE:0,60,MOSSY_COBBLESTONE:0,5,SMOOTH_BRICK:0,10,SMOOTH_BRICK:1,10,SMOOTH_BRICK:2,10,COBBLESTONE:0,100)
Block(4,3,2,LOG:1)
RandomBlock(4,3,3,COBBLESTONE:0,60,MOSSY_COBBLESTONE:0,5,SMOOTH_BRICK:0,10,SMOOTH_BRICK:1,10,SMOOTH_BRICK:2,10,COBBLESTONE:0,100)
RandomBlock(4,3,4,COBBLESTONE:0,60,MOSSY_COBBLESTONE:0,5,SMOOTH_BRICK:0,10,SMOOTH_BRICK:1,10,SMOOTH_BRICK:2,10,COBBLESTONE:0,100)
RandomBlock(4,3,5,COBBLESTONE:0,60,MOSSY_COBBLESTONE:0,5,SMOOTH_BRICK:0,10,SMOOTH_BRICK:1,10,SMOOTH_BRICK:2,10,COBBLESTONE:0,100)
RandomBlock(4,3,6,COBBLESTONE:0,60,MOSSY_COBBLESTONE:0,5,SMOOTH_BRICK:0,10,SMOOTH_BRICK:1,10,SMOOTH_BRICK:2,10,COBBLESTONE:0,100)
Block(4,3,7,LOG:1)
Block(4,4,-4,LOG:1)
Block(4,4,-3,STAINED_CLAY:12)
Block(4,4,-2,STAINED_CLAY:0)
Block(4,4,-1,STAINED_CLAY:12)
Block(4,4,0,STAINED_CLAY:12)
Block(4,4,1,STAINED_CLAY:12)
Block(4,4,2,LOG:1)
Block(4,4,3,STAINED_CLAY:12)
Block(4,4,4,STAINED_CLAY:0)
Block(4,4,5,STAINED_CLAY:12)
Block(4,4,6,STAINED_CLAY:12)
Block(4,4,7,LOG:1)
Block(4,5,-4,LOG:1)
Block(4,5,-3,STAINED_CLAY:12)
Block(4,5,-2,STAINED_CLAY:0)
Block(4,5,-1,STAINED_CLAY:0)
Block(4,5,0,STAINED_CLAY:12)
Block(4,5,1,STAINED_CLAY:0)
Block(4,5,2,LOG:1)
Block(4,5,3,STAINED_CLAY:12)
Block(4,5,4,STAINED_CLAY:0)
Block(4,5,5,STAINED_CLAY:0)
Block(4,5,6,STAINED_CLAY:0)
Block(4,5,7,LOG:1)
Block(4,6,-5,SPRUCE_WOOD_STAIRS:4)
Block(4,6,-4,LOG:1)
Block(4,6,-3,STAINED_CLAY:12)
Block(4,6,-2,STAINED_CLAY:12)
Block(4,6,-1,STAINED_CLAY:12)
Block(4,6,0,STAINED_CLAY:0)
Block(4,6,1,STAINED_CLAY:0)
Block(4,6,2,LOG:1)
Block(4,6,3,STAINED_CLAY:0)
Block(4,6,4,STAINED_CLAY:0)
Block(4,6,5,STAINED_CLAY:0)
Block(4,6,6,STAINED_CLAY:12)
Block(4,6,7,LOG:1)
Block(4,6,8,SPRUCE_WOOD_STAIRS:4)
RandomBlock(4,7,-5,SPRUCE_WOOD_STAIRS:1,70,DARK_OAK_STAIRS:1,100)
RandomBlock(4,7,-4,SPRUCE_WOOD_STAIRS:1,70,DARK_OAK_STAIRS:1,100)
RandomBlock(4,7,-3,SPRUCE_WOOD_STAIRS:1,70,DARK_OAK_STAIRS:1,100)
RandomBlock(4,7,-2,SPRUCE_WOOD_STAIRS:1,70,DARK_OAK_STAIRS:1,100)
RandomBlock(4,7,-1,SPRUCE_WOOD_STAIRS:1,70,DARK_OAK_STAIRS:1,100)
RandomBlock(4,7,0,SPRUCE_WOOD_STAIRS:1,70,DARK_OAK_STAIRS:1,100)
RandomBlock(4,7,1,SPRUCE_WOOD_STAIRS:1,70,DARK_OAK_STAIRS:1,100)
RandomBlock(4,7,2,SPRUCE_WOOD_STAIRS:1,70,DARK_OAK_STAIRS:1,100)
RandomBlock(4,7,3,SPRUCE_WOOD_STAIRS:1,70,DARK_OAK_STAIRS:1,100)
RandomBlock(4,7,4,SPRUCE_WOOD_STAIRS:1,70,DARK_OAK_STAIRS:1,100)
RandomBlock(4,7,5,SPRUCE_WOOD_STAIRS:1,70,DARK_OAK_STAIRS:1,100)
RandomBlock(4,7,6,SPRUCE_WOOD_STAIRS:1,70,DARK_OAK_STAIRS:1,100)
RandomBlock(4,7,7,SPRUCE_WOOD_STAIRS:1,70,DARK_OAK_STAIRS:1,100)
RandomBlock(4,7,8,SPRUCE_WOOD_STAIRS:1,70,DARK_OAK_STAIRS:1,100)
RandomBlock(5,6,-5,SPRUCE_WOOD_STAIRS:1,70,DARK_OAK_STAIRS:1,100)
RandomBlock(5,6,-4,SPRUCE_WOOD_STAIRS:1,70,DARK_OAK_STAIRS:1,100)
RandomBlock(5,6,-3,SPRUCE_WOOD_STAIRS:1,70,DARK_OAK_STAIRS:1,100)
RandomBlock(5,6,-2,SPRUCE_WOOD_STAIRS:1,70,DARK_OAK_STAIRS:1,100)
RandomBlock(5,6,-1,SPRUCE_WOOD_STAIRS:1,70,DARK_OAK_STAIRS:1,100)
RandomBlock(5,6,0,SPRUCE_WOOD_STAIRS:1,70,DARK_OAK_STAIRS:1,100)
RandomBlock(5,6,1,SPRUCE_WOOD_STAIRS:1,70,DARK_OAK_STAIRS:1,100)
RandomBlock(5,6,2,SPRUCE_WOOD_STAIRS:1,70,DARK_OAK_STAIRS:1,100)
RandomBlock(5,6,3,SPRUCE_WOOD_STAIRS:1,70,DARK_OAK_STAIRS:1,100)
RandomBlock(5,6,4,SPRUCE_WOOD_STAIRS:1,70,DARK_OAK_STAIRS:1,100)
RandomBlock(5,6,5,SPRUCE_WOOD_STAIRS:1,70,DARK_OAK_STAIRS:1,100)
RandomBlock(5,6,6,SPRUCE_WOOD_STAIRS:1,70,DARK_OAK_STAIRS:1,100)
RandomBlock(5,6,7,SPRUCE_WOOD_STAIRS:1,70,DARK_OAK_STAIRS:1,100)
RandomBlock(5,6,8,SPRUCE_WOOD_STAIRS:1,70,DARK_OAK_STAIRS:1,100)
Entity(-2,5,0,minecraft:armor_stand,1,../../NBT/Entities/VikingVillage/Armorstand_Viking_Simple.txt)
Entity(0,4,1,minecraft:zombie_villager,1,../../NBT/Entities/VikingVillage/stank_walker.txt)
Entity(3,7,6,minecraft:cave_spider,1,../../NBT/Entities/VikingVillage/edderkopp.txt)
