Author: NLBlackEagle
Description: No description given
SettingsMode: WriteDisable
Frequency: 10
SpawnHeight: highestBlock
UseCenterForHighestBlock: true
MinHeight: 63
MaxHeight: 255
InheritBO3: 
InheritBO3Rotation: NORTH
OverrideChildSettings: true
OverrideParentHeight: false
CanOverride: true
BranchFrequency: 5
BranchFrequencyGroup: 
MustBeBelowOther: false
MustBeInside: 
CannotBeInside: 
ReplacesBO3: 
MustBeInsideWorldBorders: false
CanSpawnOnWater: false
SpawnOnWaterOnly: false
SpawnUnderWater: false
SpawnAtWaterLevel: false
HeightOffset: -1
RemoveAir: false
ReplaceAbove: 
ReplaceBelow: cobblestone
ReplaceWithBiomeBlocks: true
ReplaceWithSurfaceBlock: GRASS
ReplaceWithGroundBlock: DIRT
ReplaceWithStoneBlock: STONE
SmoothRadius: 0
SmoothHeightOffset: 0
SmoothStartTop: false
SmoothStartWood: false
SmoothingSurfaceBlock: 
SmoothingGroundBlock: 
BO3Group: 
IsSpawnPoint: false
DoReplaceBlocks: true
RandomBlock(-5,0,-4,COBBLESTONE:0,60,MOSSY_COBBLESTONE:0,5,SMOOTH_BRICK:0,10,SMOOTH_BRICK:1,10,SMOOTH_BRICK:2,10,COBBLESTONE:0,100)
RandomBlock(-5,0,-3,COBBLESTONE:0,60,MOSSY_COBBLESTONE:0,5,SMOOTH_BRICK:0,10,SMOOTH_BRICK:1,10,SMOOTH_BRICK:2,10,COBBLESTONE:0,100)
RandomBlock(-5,0,-2,COBBLESTONE:0,60,MOSSY_COBBLESTONE:0,5,SMOOTH_BRICK:0,10,SMOOTH_BRICK:1,10,SMOOTH_BRICK:2,10,COBBLESTONE:0,100)
RandomBlock(-5,0,-1,COBBLESTONE:0,60,MOSSY_COBBLESTONE:0,5,SMOOTH_BRICK:0,10,SMOOTH_BRICK:1,10,SMOOTH_BRICK:2,10,COBBLESTONE:0,100)
RandomBlock(-5,0,0,COBBLESTONE:0,60,MOSSY_COBBLESTONE:0,5,SMOOTH_BRICK:0,10,SMOOTH_BRICK:1,10,SMOOTH_BRICK:2,10,COBBLESTONE:0,100)
RandomBlock(-5,0,1,COBBLESTONE:0,60,MOSSY_COBBLESTONE:0,5,SMOOTH_BRICK:0,10,SMOOTH_BRICK:1,10,SMOOTH_BRICK:2,10,COBBLESTONE:0,100)
RandomBlock(-5,0,2,COBBLESTONE:0,60,MOSSY_COBBLESTONE:0,5,SMOOTH_BRICK:0,10,SMOOTH_BRICK:1,10,SMOOTH_BRICK:2,10,COBBLESTONE:0,100)
RandomBlock(-5,0,3,COBBLESTONE:0,60,MOSSY_COBBLESTONE:0,5,SMOOTH_BRICK:0,10,SMOOTH_BRICK:1,10,SMOOTH_BRICK:2,10,COBBLESTONE:0,100)
RandomBlock(-5,0,4,COBBLESTONE:0,60,MOSSY_COBBLESTONE:0,5,SMOOTH_BRICK:0,10,SMOOTH_BRICK:1,10,SMOOTH_BRICK:2,10,COBBLESTONE:0,100)
RandomBlock(-5,0,5,COBBLESTONE:0,60,MOSSY_COBBLESTONE:0,5,SMOOTH_BRICK:0,10,SMOOTH_BRICK:1,10,SMOOTH_BRICK:2,10,COBBLESTONE:0,100)
RandomBlock(-5,0,6,COBBLESTONE:0,60,MOSSY_COBBLESTONE:0,5,SMOOTH_BRICK:0,10,SMOOTH_BRICK:1,10,SMOOTH_BRICK:2,10,COBBLESTONE:0,100)
RandomBlock(-5,0,7,COBBLESTONE:0,60,MOSSY_COBBLESTONE:0,5,SMOOTH_BRICK:0,10,SMOOTH_BRICK:1,10,SMOOTH_BRICK:2,10,COBBLESTONE:0,100)
RandomBlock(-5,0,8,COBBLESTONE:0,60,MOSSY_COBBLESTONE:0,5,SMOOTH_BRICK:0,10,SMOOTH_BRICK:1,10,SMOOTH_BRICK:2,10,COBBLESTONE:0,100)
RandomBlock(-5,3,-2,SPRUCE_WOOD_STAIRS:0,70,DARK_OAK_STAIRS:0,100)
RandomBlock(-5,3,-1,SPRUCE_WOOD_STAIRS:0,70,DARK_OAK_STAIRS:0,100)
RandomBlock(-5,3,0,SPRUCE_WOOD_STAIRS:0,70,DARK_OAK_STAIRS:0,100)
RandomBlock(-5,3,1,SPRUCE_WOOD_STAIRS:0,70,DARK_OAK_STAIRS:0,100)
RandomBlock(-5,3,2,SPRUCE_WOOD_STAIRS:0,70,DARK_OAK_STAIRS:0,100)
RandomBlock(-5,3,3,SPRUCE_WOOD_STAIRS:0,70,DARK_OAK_STAIRS:0,100)
RandomBlock(-5,3,4,SPRUCE_WOOD_STAIRS:0,70,DARK_OAK_STAIRS:0,100)
RandomBlock(-5,3,5,SPRUCE_WOOD_STAIRS:0,70,DARK_OAK_STAIRS:0,100)
RandomBlock(-5,3,6,SPRUCE_WOOD_STAIRS:0,70,DARK_OAK_STAIRS:0,100)
RandomBlock(-5,3,7,SPRUCE_WOOD_STAIRS:0,70,DARK_OAK_STAIRS:0,100)
RandomBlock(-4,0,-4,COBBLESTONE:0,60,MOSSY_COBBLESTONE:0,5,SMOOTH_BRICK:0,10,SMOOTH_BRICK:1,10,SMOOTH_BRICK:2,10,COBBLESTONE:0,100)
Block(-4,0,-3,DIRT:0)
Block(-4,0,-2,DIRT:0)
Block(-4,0,-1,DIRT:0)
Block(-4,0,0,DIRT:0)
Block(-4,0,1,DIRT:0)
Block(-4,0,2,DIRT:0)
Block(-4,0,3,DIRT:0)
Block(-4,0,4,DIRT:0)
Block(-4,0,5,DIRT:0)
Block(-4,0,6,DIRT:0)
Block(-4,0,7,DIRT:0)
RandomBlock(-4,0,8,COBBLESTONE:0,60,MOSSY_COBBLESTONE:0,5,SMOOTH_BRICK:0,10,SMOOTH_BRICK:1,10,SMOOTH_BRICK:2,10,COBBLESTONE:0,100)
Block(-4,1,-3,GRASS:0)
Block(-4,1,-2,GRASS:0)
Block(-4,1,-1,LOG:1)
Block(-4,1,0,GRASS:0)
Block(-4,1,1,GRASS:0)
Block(-4,1,2,GRASS:0)
Block(-4,1,3,LOG:1)
RandomBlock(-4,1,4,COBBLESTONE:0,60,MOSSY_COBBLESTONE:0,5,SMOOTH_BRICK:0,10,SMOOTH_BRICK:1,10,SMOOTH_BRICK:2,10,COBBLESTONE:0,100)
RandomBlock(-4,1,5,COBBLESTONE:0,60,MOSSY_COBBLESTONE:0,5,SMOOTH_BRICK:0,10,SMOOTH_BRICK:1,10,SMOOTH_BRICK:2,10,COBBLESTONE:0,100)
Block(-4,1,6,LOG:1)
Block(-4,1,7,GRASS:0)
Block(-4,2,-1,LOG:1)
Block(-4,2,0,SPRUCE_FENCE:0)
Block(-4,2,1,SPRUCE_FENCE:0)
Block(-4,2,2,SPRUCE_FENCE:0)
Block(-4,2,3,LOG:1)
Block(-4,2,4,SPRUCE_FENCE:0)
Block(-4,2,5,SPRUCE_FENCE:0)
Block(-4,2,6,LOG:1)
Block(-4,3,-2,SPRUCE_WOOD_STAIRS:5)
Block(-4,3,-1,LOG:1)
Block(-4,3,0,SPRUCE_FENCE:0)
Block(-4,3,1,SPRUCE_FENCE:0)
Block(-4,3,2,SPRUCE_FENCE:0)
Block(-4,3,3,LOG:1)
Block(-4,3,4,SPRUCE_FENCE:0)
Block(-4,3,5,SPRUCE_FENCE:0)
Block(-4,3,6,LOG:1)
Block(-4,3,7,SPRUCE_WOOD_STAIRS:5)
RandomBlock(-4,4,-2,SPRUCE_WOOD_STAIRS:0,70,DARK_OAK_STAIRS:0,100)
RandomBlock(-4,4,-1,SPRUCE_WOOD_STAIRS:0,70,DARK_OAK_STAIRS:0,100)
RandomBlock(-4,4,0,SPRUCE_WOOD_STAIRS:0,70,DARK_OAK_STAIRS:0,100)
RandomBlock(-4,4,1,SPRUCE_WOOD_STAIRS:0,70,DARK_OAK_STAIRS:0,100)
RandomBlock(-4,4,2,SPRUCE_WOOD_STAIRS:0,70,DARK_OAK_STAIRS:0,100)
RandomBlock(-4,4,3,SPRUCE_WOOD_STAIRS:0,70,DARK_OAK_STAIRS:0,100)
RandomBlock(-4,4,4,SPRUCE_WOOD_STAIRS:0,70,DARK_OAK_STAIRS:0,100)
RandomBlock(-4,4,5,SPRUCE_WOOD_STAIRS:0,70,DARK_OAK_STAIRS:0,100)
RandomBlock(-4,4,6,SPRUCE_WOOD_STAIRS:0,70,DARK_OAK_STAIRS:0,100)
RandomBlock(-4,4,7,SPRUCE_WOOD_STAIRS:0,70,DARK_OAK_STAIRS:0,100)
RandomBlock(-3,0,-4,COBBLESTONE:0,60,MOSSY_COBBLESTONE:0,5,SMOOTH_BRICK:0,10,SMOOTH_BRICK:1,10,SMOOTH_BRICK:2,10,COBBLESTONE:0,100)
Block(-3,0,-3,DIRT:0)
Block(-3,0,-2,DIRT:0)
Block(-3,0,-1,DIRT:0)
Block(-3,0,0,DIRT:0)
Block(-3,0,1,DIRT:0)
Block(-3,0,2,DIRT:0)
Block(-3,0,3,DIRT:0)
Block(-3,0,4,DIRT:0)
Block(-3,0,5,DIRT:0)
Block(-3,0,6,DIRT:0)
Block(-3,0,7,DIRT:0)
RandomBlock(-3,0,8,COBBLESTONE:0,60,MOSSY_COBBLESTONE:0,5,SMOOTH_BRICK:0,10,SMOOTH_BRICK:1,10,SMOOTH_BRICK:2,10,COBBLESTONE:0,100)
Block(-3,1,-3,GRASS:0)
RandomBlock(-3,1,-2,COBBLESTONE:0,60,MOSSY_COBBLESTONE:0,5,SMOOTH_BRICK:0,10,SMOOTH_BRICK:1,10,SMOOTH_BRICK:2,10,COBBLESTONE:0,100)
Block(-3,1,-1,GRASS:0)
RandomBlock(-3,1,0,COBBLESTONE:0,60,MOSSY_COBBLESTONE:0,5,SMOOTH_BRICK:0,10,SMOOTH_BRICK:1,10,SMOOTH_BRICK:2,10,COBBLESTONE:0,100)
Block(-3,1,1,GRASS:0)
Block(-3,1,2,GRASS:0)
RandomBlock(-3,1,3,COBBLESTONE:0,60,MOSSY_COBBLESTONE:0,5,SMOOTH_BRICK:0,10,SMOOTH_BRICK:1,10,SMOOTH_BRICK:2,10,COBBLESTONE:0,100)
RandomBlock(-3,1,4,COBBLESTONE:0,60,MOSSY_COBBLESTONE:0,5,SMOOTH_BRICK:0,10,SMOOTH_BRICK:1,10,SMOOTH_BRICK:2,10,COBBLESTONE:0,100)
RandomBlock(-3,1,5,COBBLESTONE:0,60,MOSSY_COBBLESTONE:0,5,SMOOTH_BRICK:0,10,SMOOTH_BRICK:1,10,SMOOTH_BRICK:2,10,COBBLESTONE:0,100)
RandomBlock(-3,1,6,COBBLESTONE:0,60,MOSSY_COBBLESTONE:0,5,SMOOTH_BRICK:0,10,SMOOTH_BRICK:1,10,SMOOTH_BRICK:2,10,COBBLESTONE:0,100)
Block(-3,1,7,GRASS:0)
RandomBlock(-3,2,1,AIR:0,20,CHEST:5,../../../../Chests/Loot/JunkChest_1.nbt,10,CHEST:5,../../../../Chests/Loot/JunkChest_2.nbt,10,CHEST:5,../../../../Chests/Loot/JunkChest_3.nbt,10,CHEST:5,../../../../Chests/Loot/JunkChest_4.nbt,10,CHEST:5,../../../../Chests/Loot/JunkChest_5.nbt,10,CHEST:5,../../../../Chests/Lore/Viking_1.nbt,1,CHEST:5,../../../../Chests/Lore/Viking_2.nbt,1,CHEST:5,../../../../Chests/Lore/Viking_3.nbt,1,CHEST:5,../../../../Chests/Lore/Viking_4.nbt,1,CHEST:5,../../../../Chests/Lore/Viking_5.nbt,1,CHEST:5,../../../../Chests/Loot/Common1.nbt,10,CHEST:5,../../../../Chests/Loot/Common2.nbt,10,CHEST:5,../../../../Chests/Loot/Common3.nbt,10,CHEST:5,../../../../Chests/Loot/Common4.nbt,10,CHEST:5,../../../../Chests/Loot/Common5.nbt,10,CHEST:5,../../../../Chests/Loot/Common6.nbt,10,CHEST:5,../../../../Chests/Loot/Common7.nbt,10,CHEST:5,../../../../Chests/Loot/Common8.nbt,10,CHEST:5,../../../../Chests/Loot/Common9.nbt,10,CHEST:5,../../../../Chests/Loot/Common10.nbt,10,CHEST:5,../../../../Chests/Loot/Common10.nbt,11,CHEST:5,../../../../Chests/Loot/Common12.nbt,10,CHEST:5,../../../../Chests/Loot/Common13.nbt,10,CHEST:5,../../../../Chests/Loot/Common14.nbt,10,CHEST:5,../../../../Chests/Loot/Common15.nbt,10,CHEST:5,../../../../Chests/Lore/Viking_1.nbt,2,CHEST:5,../../../../Chests/Lore/Viking_3.nbt,2,CHEST:5,../../../../Chests/Lore/Viking_4.nbt,2,CHEST:5,../../../../Chests/Lore/Viking_5.nbt,2,CHEST:5,../../../../Chests/Lore/Viking_5.nbt,2,CHEST:5,../../../../Chests/Loot/Rare1.nbt,5,CHEST:5,../../../../Chests/Loot/Rare2.nbt,5,CHEST:5,../../../../Chests/Loot/Rare3.nbt,5,CHEST:5,../../../../Chests/Loot/Rare4.nbt,5,CHEST:5,../../../../Chests/Loot/Rare5.nbt,5,CHEST:5,../../../../Chests/Loot/Rare6.nbt,5,CHEST:5,../../../../Chests/Loot/Rare7.nbt,5,CHEST:5,../../../../Chests/Loot/Rare8.nbt,5,CHEST:5,../../../../Chests/Loot/Rare9.nbt,5,CHEST:5,../../../../Chests/Loot/Rare10.nbt,5,CHEST:5,../../../../Chests/Loot/Rare11.nbt,5,CHEST:5,../../../../Chests/Loot/Rare12.nbt,5,CHEST:5,../../../../Chests/Loot/Rare13.nbt,5,CHEST:5,../../../../Chests/Loot/Rare14.nbt,5,CHEST:5,../../../../Chests/Loot/Rare15.nbt,5,CHEST:5,../../../../Chests/Loot/Epic1.nbt,2,CHEST:5,../../../../Chests/Loot/Epic2.nbt,2,CHEST:5,../../../../Chests/Loot/Epic3.nbt,2,CHEST:5,../../../../Chests/Loot/Epic4.nbt,2,CHEST:5,../../../../Chests/Loot/Epic5.nbt,2,CHEST:5,../../../../Chests/Loot/Epic6.nbt,2,CHEST:5,../../../../Chests/Loot/Epic7.nbt,2,CHEST:5,../../../../Chests/Loot/Epic8.nbt,2,CHEST:5,../../../../Chests/Loot/Epic9.nbt,2,CHEST:5,../../../../Chests/Loot/Epic10.nbt,2,CHEST:5,../../../../Chests/Loot/Epic11.nbt,2,CHEST:5,../../../../Chests/Loot/Epic12.nbt,2,CHEST:5,../../../../Chests/Loot/Epic13.nbt,2,CHEST:5,../../../../Chests/Loot/Epic14.nbt,2,CHEST:5,../../../../Chests/Loot/Epic15.nbt,5,CHEST:5,../../../../Chests/Loot/Rare1.nbt,5,CHEST:5,../../../../Chests/Loot/Rare2.nbt,5,CHEST:5,../../../../Chests/Loot/Rare3.nbt,5,CHEST:5,../../../../Chests/Loot/Rare4.nbt,5,CHEST:5,../../../../Chests/Loot/Rare5.nbt,10,CHEST:5,../../../../Chests/Loot/Rare6.nbt,10,CHEST:5,../../../../Chests/Loot/Rare7.nbt,10,CHEST:5,../../../../Chests/Loot/Rare8.nbt,10,CHEST:5,../../../../Chests/Loot/Rare9.nbt,10,CHEST:5,../../../../Chests/Loot/Rare10.nbt,15,CHEST:5,../../../../Chests/Loot/Rare11.nbt,15,CHEST:5,../../../../Chests/Loot/Rare12.nbt,15,CHEST:5,../../../../Chests/Loot/Rare13.nbt,15,CHEST:5,../../../../Chests/Loot/Rare14.nbt,15,CHEST:5,../../../../Chests/Loot/Rare15.nbt,15,CHEST:5,../../../../Chests/Loot/Epic15.nbt,100)
Block(-3,2,3,WOOD:1)
Block(-3,2,4,WEB:0)
Block(-3,2,6,SPRUCE_FENCE:0)
Block(-3,3,3,WOOD:1)
Block(-3,3,5,WEB:0)
Block(-3,3,6,SPRUCE_FENCE:0)
Block(-3,4,-2,SPRUCE_WOOD_STAIRS:5)
Block(-3,4,-1,SPRUCE_WOOD_STAIRS:5)
Block(-3,4,0,SPRUCE_WOOD_STAIRS:5)
Block(-3,4,1,SPRUCE_WOOD_STAIRS:5)
Block(-3,4,2,SPRUCE_WOOD_STAIRS:5)
Block(-3,4,3,WOOD_DOUBLE_STEP:1)
Block(-3,4,4,SPRUCE_WOOD_STAIRS:5)
Block(-3,4,5,SPRUCE_WOOD_STAIRS:5)
Block(-3,4,6,SPRUCE_WOOD_STAIRS:5)
Block(-3,4,7,SPRUCE_WOOD_STAIRS:5)
RandomBlock(-2,0,-4,COBBLESTONE:0,60,MOSSY_COBBLESTONE:0,5,SMOOTH_BRICK:0,10,SMOOTH_BRICK:1,10,SMOOTH_BRICK:2,10,COBBLESTONE:0,100)
Block(-2,0,-3,DIRT:0)
Block(-2,0,-2,DIRT:0)
Block(-2,0,-1,DIRT:0)
Block(-2,0,0,DIRT:0)
Block(-2,0,1,DIRT:0)
Block(-2,0,2,DIRT:0)
Block(-2,0,3,DIRT:0)
Block(-2,0,4,DIRT:0)
Block(-2,0,5,DIRT:0)
Block(-2,0,6,DIRT:0)
Block(-2,0,7,DIRT:0)
RandomBlock(-2,0,8,COBBLESTONE:0,60,MOSSY_COBBLESTONE:0,5,SMOOTH_BRICK:0,10,SMOOTH_BRICK:1,10,SMOOTH_BRICK:2,10,COBBLESTONE:0,100)
Block(-2,1,-3,GRASS:0)
Block(-2,1,-2,GRASS:0)
RandomBlock(-2,1,-1,COBBLESTONE:0,60,MOSSY_COBBLESTONE:0,5,SMOOTH_BRICK:0,10,SMOOTH_BRICK:1,10,SMOOTH_BRICK:2,10,COBBLESTONE:0,100)
Block(-2,1,0,GRASS:0)
Block(-2,1,1,GRASS:0)
Block(-2,1,2,GRASS:0)
RandomBlock(-2,1,3,COBBLESTONE:0,60,MOSSY_COBBLESTONE:0,5,SMOOTH_BRICK:0,10,SMOOTH_BRICK:1,10,SMOOTH_BRICK:2,10,COBBLESTONE:0,100)
RandomBlock(-2,1,4,COBBLESTONE:0,60,MOSSY_COBBLESTONE:0,5,SMOOTH_BRICK:0,10,SMOOTH_BRICK:1,10,SMOOTH_BRICK:2,10,COBBLESTONE:0,100)
RandomBlock(-2,1,5,COBBLESTONE:0,60,MOSSY_COBBLESTONE:0,5,SMOOTH_BRICK:0,10,SMOOTH_BRICK:1,10,SMOOTH_BRICK:2,10,COBBLESTONE:0,100)
RandomBlock(-2,1,6,COBBLESTONE:0,60,MOSSY_COBBLESTONE:0,5,SMOOTH_BRICK:0,10,SMOOTH_BRICK:1,10,SMOOTH_BRICK:2,10,COBBLESTONE:0,100)
Block(-2,1,7,GRASS:0)
Block(-2,2,3,SPRUCE_DOOR:7)
Block(-2,2,5,AIR:0)
Block(-2,2,6,SPRUCE_FENCE:0)
Block(-2,3,3,SPRUCE_DOOR:9)
Block(-2,3,6,SPRUCE_FENCE:0)
RandomBlock(-2,4,-2,WOOD_STEP:9,70,WOOD_STEP:13,100)
RandomBlock(-2,4,-1,WOOD_STEP:9,70,WOOD_STEP:13,100)
RandomBlock(-2,4,0,WOOD_STEP:9,70,WOOD_STEP:13,100)
RandomBlock(-2,4,1,WOOD_STEP:9,70,WOOD_STEP:13,100)
RandomBlock(-2,4,2,WOOD_STEP:9,70,WOOD_STEP:13,100)
Block(-2,4,3,WOOD_DOUBLE_STEP:1)
RandomBlock(-2,4,4,WOOD_STEP:9,70,WOOD_STEP:13,100)
RandomBlock(-2,4,5,WOOD_STEP:9,70,WOOD_STEP:13,100)
RandomBlock(-2,4,6,WOOD_STEP:9,70,WOOD_STEP:13,100)
RandomBlock(-2,4,7,WOOD_STEP:9,70,WOOD_STEP:13,100)
RandomBlock(-2,5,-2,SPRUCE_WOOD_STAIRS:0,70,DARK_OAK_STAIRS:0,100)
RandomBlock(-2,5,-1,SPRUCE_WOOD_STAIRS:0,70,DARK_OAK_STAIRS:0,100)
RandomBlock(-2,5,0,SPRUCE_WOOD_STAIRS:0,70,DARK_OAK_STAIRS:0,100)
RandomBlock(-2,5,1,SPRUCE_WOOD_STAIRS:0,70,DARK_OAK_STAIRS:0,100)
RandomBlock(-2,5,2,SPRUCE_WOOD_STAIRS:0,70,DARK_OAK_STAIRS:0,100)
RandomBlock(-2,5,3,SPRUCE_WOOD_STAIRS:0,70,DARK_OAK_STAIRS:0,100)
RandomBlock(-2,5,4,SPRUCE_WOOD_STAIRS:0,70,DARK_OAK_STAIRS:0,100)
RandomBlock(-2,5,5,SPRUCE_WOOD_STAIRS:0,70,DARK_OAK_STAIRS:0,100)
RandomBlock(-2,5,6,SPRUCE_WOOD_STAIRS:0,70,DARK_OAK_STAIRS:0,100)
RandomBlock(-2,5,7,SPRUCE_WOOD_STAIRS:0,70,DARK_OAK_STAIRS:0,100)
RandomBlock(-1,0,-4,COBBLESTONE:0,60,MOSSY_COBBLESTONE:0,5,SMOOTH_BRICK:0,10,SMOOTH_BRICK:1,10,SMOOTH_BRICK:2,10,COBBLESTONE:0,100)
Block(-1,0,-3,DIRT:0)
Block(-1,0,-2,DIRT:0)
Block(-1,0,-1,DIRT:0)
Block(-1,0,0,DIRT:0)
Block(-1,0,1,DIRT:0)
Block(-1,0,2,DIRT:0)
Block(-1,0,3,DIRT:0)
Block(-1,0,4,DIRT:0)
Block(-1,0,5,DIRT:0)
Block(-1,0,6,DIRT:0)
Block(-1,0,7,DIRT:0)
RandomBlock(-1,0,8,COBBLESTONE:0,60,MOSSY_COBBLESTONE:0,5,SMOOTH_BRICK:0,10,SMOOTH_BRICK:1,10,SMOOTH_BRICK:2,10,COBBLESTONE:0,100)
RandomBlock(-1,1,-3,COBBLESTONE:0,60,MOSSY_COBBLESTONE:0,5,SMOOTH_BRICK:0,10,SMOOTH_BRICK:1,10,SMOOTH_BRICK:2,10,COBBLESTONE:0,100)
RandomBlock(-1,1,-2,COBBLESTONE:0,60,MOSSY_COBBLESTONE:0,5,SMOOTH_BRICK:0,10,SMOOTH_BRICK:1,10,SMOOTH_BRICK:2,10,COBBLESTONE:0,100)
RandomBlock(-1,1,-1,COBBLESTONE:0,60,MOSSY_COBBLESTONE:0,5,SMOOTH_BRICK:0,10,SMOOTH_BRICK:1,10,SMOOTH_BRICK:2,10,COBBLESTONE:0,100)
RandomBlock(-1,1,0,COBBLESTONE:0,60,MOSSY_COBBLESTONE:0,5,SMOOTH_BRICK:0,10,SMOOTH_BRICK:1,10,SMOOTH_BRICK:2,10,COBBLESTONE:0,100)
RandomBlock(-1,1,1,COBBLESTONE:0,60,MOSSY_COBBLESTONE:0,5,SMOOTH_BRICK:0,10,SMOOTH_BRICK:1,10,SMOOTH_BRICK:2,10,COBBLESTONE:0,100)
RandomBlock(-1,1,2,COBBLESTONE:0,60,MOSSY_COBBLESTONE:0,5,SMOOTH_BRICK:0,10,SMOOTH_BRICK:1,10,SMOOTH_BRICK:2,10,COBBLESTONE:0,100)
RandomBlock(-1,1,3,COBBLESTONE:0,60,MOSSY_COBBLESTONE:0,5,SMOOTH_BRICK:0,10,SMOOTH_BRICK:1,10,SMOOTH_BRICK:2,10,COBBLESTONE:0,100)
RandomBlock(-1,1,4,COBBLESTONE:0,60,MOSSY_COBBLESTONE:0,5,SMOOTH_BRICK:0,10,SMOOTH_BRICK:1,10,SMOOTH_BRICK:2,10,COBBLESTONE:0,100)
RandomBlock(-1,1,5,COBBLESTONE:0,60,MOSSY_COBBLESTONE:0,5,SMOOTH_BRICK:0,10,SMOOTH_BRICK:1,10,SMOOTH_BRICK:2,10,COBBLESTONE:0,100)
RandomBlock(-1,1,6,COBBLESTONE:0,60,MOSSY_COBBLESTONE:0,5,SMOOTH_BRICK:0,10,SMOOTH_BRICK:1,10,SMOOTH_BRICK:2,10,COBBLESTONE:0,100)
Block(-1,1,7,GRASS:0)
Block(-1,2,-3,SPRUCE_FENCE:0)
Block(-1,2,-2,SPRUCE_FENCE:0)
Block(-1,2,-1,SPRUCE_FENCE:0)
Block(-1,2,0,SPRUCE_FENCE:0)
Block(-1,2,1,SPRUCE_FENCE:0)
Block(-1,2,2,SPRUCE_FENCE:0)
Block(-1,2,3,WOOD:1)
Block(-1,2,5,WEB:0)
Block(-1,2,6,SPRUCE_FENCE:0)
Block(-1,2,7,SPRUCE_FENCE:0)
Block(-1,3,-3,SPRUCE_FENCE:0)
Block(-1,3,-2,SPRUCE_FENCE:0)
Block(-1,3,-1,SPRUCE_FENCE:0)
Block(-1,3,0,SPRUCE_FENCE:0)
Block(-1,3,1,SPRUCE_FENCE:0)
Block(-1,3,2,SPRUCE_FENCE:0)
Block(-1,3,3,WOOD:1)
Block(-1,3,6,SPRUCE_FENCE:0)
Block(-1,3,7,SPRUCE_FENCE:0)
RandomBlock(-1,4,-3,WOOD_STEP:1,70,WOOD_STEP:5,100)
RandomBlock(-1,4,-2,WOOD_STEP:1,70,WOOD_STEP:5,100)
RandomBlock(-1,4,-1,WOOD_STEP:1,70,WOOD_STEP:5,100)
RandomBlock(-1,4,0,WOOD_STEP:1,70,WOOD_STEP:5,100)
RandomBlock(-1,4,1,WOOD_STEP:1,70,WOOD_STEP:5,100)
RandomBlock(-1,4,2,WOOD_STEP:1,70,WOOD_STEP:5,100)
RandomBlock(-1,4,3,WOOD_STEP:1,70,WOOD_STEP:5,100)
RandomBlock(-1,4,4,WOOD_STEP:1,70,WOOD_STEP:5,100)
RandomBlock(-1,4,5,WOOD_STEP:1,70,WOOD_STEP:5,100)
RandomBlock(-1,4,6,WOOD_STEP:1,70,WOOD_STEP:5,100)
RandomBlock(-1,4,7,WOOD_STEP:1,70,WOOD_STEP:5,100)
Block(-1,5,-2,SPRUCE_WOOD_STAIRS:5)
Block(-1,5,-1,SPRUCE_WOOD_STAIRS:5)
Block(-1,5,0,SPRUCE_WOOD_STAIRS:5)
Block(-1,5,1,SPRUCE_WOOD_STAIRS:5)
Block(-1,5,2,SPRUCE_WOOD_STAIRS:5)
Block(-1,5,3,SPRUCE_WOOD_STAIRS:5)
Block(-1,5,4,SPRUCE_WOOD_STAIRS:5)
Block(-1,5,5,SPRUCE_WOOD_STAIRS:5)
Block(-1,5,6,SPRUCE_WOOD_STAIRS:5)
Block(-1,5,7,SPRUCE_WOOD_STAIRS:5)
RandomBlock(0,0,-4,COBBLESTONE:0,60,MOSSY_COBBLESTONE:0,5,SMOOTH_BRICK:0,10,SMOOTH_BRICK:1,10,SMOOTH_BRICK:2,10,COBBLESTONE:0,100)
Block(0,0,-3,DIRT:0)
Block(0,0,-2,GRASS:0)
Block(0,0,-1,DIRT:0)
Block(0,0,0,DIRT:0)
Block(0,0,1,DIRT:0)
Block(0,0,2,DIRT:0)
Block(0,0,3,DIRT:0)
Block(0,0,4,DIRT:0)
Block(0,0,5,DIRT:0)
Block(0,0,6,DIRT:0)
Block(0,0,7,DIRT:0)
RandomBlock(0,0,8,COBBLESTONE:0,60,MOSSY_COBBLESTONE:0,5,SMOOTH_BRICK:0,10,SMOOTH_BRICK:1,10,SMOOTH_BRICK:2,10,COBBLESTONE:0,100)
RandomBlock(0,1,-3,COBBLESTONE:0,60,MOSSY_COBBLESTONE:0,5,SMOOTH_BRICK:0,10,SMOOTH_BRICK:1,10,SMOOTH_BRICK:2,10,COBBLESTONE:0,100)
Block(0,1,-1,LOG:1)
Block(0,1,0,CAULDRON:3)
Block(0,1,1,STEP:3)
Block(0,1,2,STEP:3)
Block(0,1,3,LOG:1)
RandomBlock(0,1,4,COBBLESTONE:0,60,MOSSY_COBBLESTONE:0,5,SMOOTH_BRICK:0,10,SMOOTH_BRICK:1,10,SMOOTH_BRICK:2,10,COBBLESTONE:0,100)
RandomBlock(0,1,5,COBBLESTONE:0,60,MOSSY_COBBLESTONE:0,5,SMOOTH_BRICK:0,10,SMOOTH_BRICK:1,10,SMOOTH_BRICK:2,10,COBBLESTONE:0,100)
Block(0,1,6,LOG:1)
RandomBlock(0,1,7,COBBLESTONE:0,60,MOSSY_COBBLESTONE:0,5,SMOOTH_BRICK:0,10,SMOOTH_BRICK:1,10,SMOOTH_BRICK:2,10,COBBLESTONE:0,100)
Block(0,2,-3,SPRUCE_FENCE:0)
Block(0,2,-1,LOG:1)
Block(0,2,3,LOG:1)
Block(0,2,4,WOOD:1)
Block(0,2,5,SPRUCE_DOOR:0)
Block(0,2,6,LOG:1)
Block(0,2,7,SPRUCE_FENCE:0)
Block(0,3,-3,SPRUCE_FENCE:0)
Block(0,3,-1,LOG:1)
Block(0,3,3,LOG:1)
Block(0,3,4,WOOD:1)
Block(0,3,5,SPRUCE_DOOR:8)
Block(0,3,6,LOG:1)
Block(0,3,7,SPRUCE_FENCE:0)
RandomBlock(0,4,-3,WOOD_STEP:1,70,WOOD_STEP:5,100)
Block(0,4,-1,LOG:1)
Block(0,4,0,TRAP_DOOR:3)
Block(0,4,1,TRAP_DOOR:3)
Block(0,4,2,TRAP_DOOR:3)
Block(0,4,3,LOG:1)
RandomBlock(0,4,4,WOOD_STEP:1,70,WOOD_STEP:5,100)
RandomBlock(0,4,5,WOOD_STEP:1,70,WOOD_STEP:5,100)
Block(0,4,6,LOG:1)
RandomBlock(0,4,7,WOOD_STEP:1,70,WOOD_STEP:5,100)
RandomBlock(0,5,-2,WOOD_STEP:9,70,WOOD_STEP:13,100)
Block(0,5,-1,WOOD_DOUBLE_STEP:1)
RandomBlock(0,5,0,WOOD_STEP:9,70,WOOD_STEP:13,100)
RandomBlock(0,5,1,WOOD_STEP:9,70,WOOD_STEP:13,100)
RandomBlock(0,5,2,WOOD_STEP:9,70,WOOD_STEP:13,100)
Block(0,5,3,WOOD_DOUBLE_STEP:1)
RandomBlock(0,5,4,WOOD_STEP:9,70,WOOD_STEP:13,100)
RandomBlock(0,5,5,WOOD_STEP:9,70,WOOD_STEP:13,100)
Block(0,5,6,WOOD_DOUBLE_STEP:1)
RandomBlock(0,5,7,WOOD_STEP:9,70,WOOD_STEP:13,100)
RandomBlock(1,0,-4,COBBLESTONE:0,60,MOSSY_COBBLESTONE:0,5,SMOOTH_BRICK:0,10,SMOOTH_BRICK:1,10,SMOOTH_BRICK:2,10,COBBLESTONE:0,100)
Block(1,0,-3,DIRT:0)
Block(1,0,-2,DIRT:0)
Block(1,0,-1,DIRT:0)
Block(1,0,0,DIRT:0)
Block(1,0,1,DIRT:0)
Block(1,0,2,DIRT:0)
Block(1,0,3,GRASS:0)
Block(1,0,4,GRASS:0)
Block(1,0,5,DIRT:0)
Block(1,0,6,GRASS:0)
Block(1,0,7,DIRT:0)
RandomBlock(1,0,8,COBBLESTONE:0,60,MOSSY_COBBLESTONE:0,5,SMOOTH_BRICK:0,10,SMOOTH_BRICK:1,10,SMOOTH_BRICK:2,10,COBBLESTONE:0,100)
RandomBlock(1,1,-3,COBBLESTONE:0,60,MOSSY_COBBLESTONE:0,5,SMOOTH_BRICK:0,10,SMOOTH_BRICK:1,10,SMOOTH_BRICK:2,10,COBBLESTONE:0,100)
Block(1,1,-2,STEP:3)
Block(1,1,-1,STEP:3)
Block(1,1,0,STEP:3)
Block(1,1,1,STEP:3)
Block(1,1,2,STEP:3)
Block(1,1,5,STEP:3)
RandomBlock(1,1,7,COBBLESTONE:0,60,MOSSY_COBBLESTONE:0,5,SMOOTH_BRICK:0,10,SMOOTH_BRICK:1,10,SMOOTH_BRICK:2,10,COBBLESTONE:0,100)
Block(1,2,-3,SPRUCE_FENCE:0)
Block(1,2,-2,WEB:0)
Block(1,2,-1,AIR:0)
Block(1,2,2,WEB:0)
Block(1,2,5,WEB:0)
Block(1,2,6,WEB:0)
Block(1,2,7,SPRUCE_FENCE:0)
Block(1,3,-3,SPRUCE_FENCE:0)
Block(1,3,6,WEB:0)
Block(1,3,7,SPRUCE_FENCE:0)
RandomBlock(1,4,-3,WOOD_STEP:1,70,WOOD_STEP:5,100)
Block(1,4,-2,TRAP_DOOR:1)
Block(1,4,-1,TRAP_DOOR:3)
Block(1,4,0,TRAP_DOOR:3)
Block(1,4,1,TRAP_DOOR:3)
Block(1,4,2,TRAP_DOOR:3)
Block(1,4,3,TRAP_DOOR:3)
Block(1,4,4,TRAP_DOOR:1)
Block(1,4,5,TRAP_DOOR:1)
Block(1,4,6,TRAP_DOOR:3)
RandomBlock(1,4,7,WOOD_STEP:1,70,WOOD_STEP:5,100)
RandomBlock(1,5,-2,WOOD_STEP:9,70,WOOD_STEP:13,100)
RandomBlock(1,5,-1,WOOD_STEP:9,70,WOOD_STEP:13,100)
RandomBlock(1,5,0,WOOD_STEP:9,70,WOOD_STEP:13,100)
RandomBlock(1,5,1,WOOD_STEP:9,70,WOOD_STEP:13,100)
RandomBlock(1,5,2,WOOD_STEP:9,70,WOOD_STEP:13,100)
RandomBlock(1,5,3,WOOD_STEP:9,70,WOOD_STEP:13,100)
RandomBlock(1,5,4,WOOD_STEP:9,70,WOOD_STEP:13,100)
RandomBlock(1,5,5,WOOD_STEP:9,70,WOOD_STEP:13,100)
RandomBlock(1,5,6,WOOD_STEP:9,70,WOOD_STEP:13,100)
RandomBlock(1,5,7,WOOD_STEP:9,70,WOOD_STEP:13,100)
RandomBlock(2,0,-4,COBBLESTONE:0,60,MOSSY_COBBLESTONE:0,5,SMOOTH_BRICK:0,10,SMOOTH_BRICK:1,10,SMOOTH_BRICK:2,10,COBBLESTONE:0,100)
Block(2,0,-3,DIRT:0)
Block(2,0,-2,GRASS:0)
Block(2,0,-1,GRASS:0)
Block(2,0,0,GRASS:0)
Block(2,0,1,DIRT:0)
Block(2,0,2,GRASS:0)
Block(2,0,3,GRASS:0)
Block(2,0,4,DIRT:0)
Block(2,0,5,GRASS:0)
Block(2,0,6,DIRT:0)
Block(2,0,7,DIRT:0)
RandomBlock(2,0,8,COBBLESTONE:0,60,MOSSY_COBBLESTONE:0,5,SMOOTH_BRICK:0,10,SMOOTH_BRICK:1,10,SMOOTH_BRICK:2,10,COBBLESTONE:0,100)
RandomBlock(2,1,-3,COBBLESTONE:0,60,MOSSY_COBBLESTONE:0,5,SMOOTH_BRICK:0,10,SMOOTH_BRICK:1,10,SMOOTH_BRICK:2,10,COBBLESTONE:0,100)
Block(2,1,-2,WEB:0)
Block(2,1,-1,WEB:0)
Block(2,1,0,WEB:0)
Block(2,1,1,AIR:0)
Block(2,1,4,STEP:3)
Block(2,1,6,STEP:3)
RandomBlock(2,1,7,COBBLESTONE:0,60,MOSSY_COBBLESTONE:0,5,SMOOTH_BRICK:0,10,SMOOTH_BRICK:1,10,SMOOTH_BRICK:2,10,COBBLESTONE:0,100)
Block(2,2,-3,SPRUCE_FENCE:0)
Block(2,2,4,AIR:0)
Block(2,2,5,WEB:0)
Block(2,2,7,SPRUCE_FENCE:0)
Block(2,3,-3,SPRUCE_FENCE:0)
Block(2,3,6,WEB:0)
Block(2,3,7,SPRUCE_FENCE:0)
RandomBlock(2,4,-3,WOOD_STEP:1,70,WOOD_STEP:5,100)
Block(2,4,-2,TRAP_DOOR:1)
Block(2,4,-1,TRAP_DOOR:3)
Block(2,4,0,TRAP_DOOR:3)
Block(2,4,1,TRAP_DOOR:3)
Block(2,4,2,TRAP_DOOR:3)
Block(2,4,3,TRAP_DOOR:3)
Block(2,4,4,TRAP_DOOR:1)
Block(2,4,5,TRAP_DOOR:1)
Block(2,4,6,TRAP_DOOR:0)
RandomBlock(2,4,7,WOOD_STEP:1,70,WOOD_STEP:5,100)
RandomBlock(3,0,-4,COBBLESTONE:0,60,MOSSY_COBBLESTONE:0,5,SMOOTH_BRICK:0,10,SMOOTH_BRICK:1,10,SMOOTH_BRICK:2,10,COBBLESTONE:0,100)
Block(3,0,-3,DIRT:0)
Block(3,0,-2,DIRT:0)
Block(3,0,-1,GRASS:0)
Block(3,0,0,GRASS:0)
Block(3,0,1,GRASS:0)
Block(3,0,2,GRASS:0)
Block(3,0,3,GRASS:0)
Block(3,0,4,GRASS:0)
Block(3,0,5,DIRT:0)
Block(3,0,6,GRASS:0)
Block(3,0,7,DIRT:0)
RandomBlock(3,0,8,COBBLESTONE:0,60,MOSSY_COBBLESTONE:0,5,SMOOTH_BRICK:0,10,SMOOTH_BRICK:1,10,SMOOTH_BRICK:2,10,COBBLESTONE:0,100)
RandomBlock(3,1,-3,COBBLESTONE:0,60,MOSSY_COBBLESTONE:0,5,SMOOTH_BRICK:0,10,SMOOTH_BRICK:1,10,SMOOTH_BRICK:2,10,COBBLESTONE:0,100)
Block(3,1,-2,STEP:3)
Block(3,1,-1,WEB:0)
Block(3,1,1,WEB:0)
Block(3,1,2,WEB:0)
Block(3,1,4,WEB:0)
Block(3,1,5,STEP:3)
RandomBlock(3,1,7,COBBLESTONE:0,60,MOSSY_COBBLESTONE:0,5,SMOOTH_BRICK:0,10,SMOOTH_BRICK:1,10,SMOOTH_BRICK:2,10,COBBLESTONE:0,100)
Block(3,2,-3,SPRUCE_FENCE:0)
Block(3,2,-1,WEB:0)
Block(3,2,3,WEB:0)
Block(3,2,5,WEB:0)
Block(3,2,6,WEB:0)
Block(3,2,7,SPRUCE_FENCE:0)
Block(3,3,-3,SPRUCE_FENCE:0)
Block(3,3,-2,WEB:0)
Block(3,3,0,WEB:0)
Block(3,3,2,WEB:0)
Block(3,3,7,SPRUCE_FENCE:0)
RandomBlock(3,4,-3,WOOD_STEP:1,70,WOOD_STEP:5,100)
Block(3,4,-2,TRAP_DOOR:2)
Block(3,4,-1,TRAP_DOOR:2)
Block(3,4,0,TRAP_DOOR:2)
Block(3,4,1,TRAP_DOOR:2)
Block(3,4,2,TRAP_DOOR:2)
Block(3,4,3,TRAP_DOOR:2)
Block(3,4,4,TRAP_DOOR:2)
Block(3,4,5,TRAP_DOOR:2)
Block(3,4,6,TRAP_DOOR:0)
RandomBlock(3,4,7,WOOD_STEP:1,70,WOOD_STEP:5,100)
RandomBlock(4,0,-4,COBBLESTONE:0,60,MOSSY_COBBLESTONE:0,5,SMOOTH_BRICK:0,10,SMOOTH_BRICK:1,10,SMOOTH_BRICK:2,10,COBBLESTONE:0,100)
Block(4,0,-3,DIRT:0)
Block(4,0,-2,DIRT:0)
Block(4,0,-1,DIRT:0)
Block(4,0,0,DIRT:0)
Block(4,0,1,DIRT:0)
Block(4,0,2,DIRT:0)
Block(4,0,3,DIRT:0)
Block(4,0,4,DIRT:0)
Block(4,0,5,DIRT:0)
Block(4,0,6,DIRT:0)
Block(4,0,7,DIRT:0)
RandomBlock(4,0,8,COBBLESTONE:0,60,MOSSY_COBBLESTONE:0,5,SMOOTH_BRICK:0,10,SMOOTH_BRICK:1,10,SMOOTH_BRICK:2,10,COBBLESTONE:0,100)
RandomBlock(4,1,-3,COBBLESTONE:0,60,MOSSY_COBBLESTONE:0,5,SMOOTH_BRICK:0,10,SMOOTH_BRICK:1,10,SMOOTH_BRICK:2,10,COBBLESTONE:0,100)
RandomBlock(4,1,-2,COBBLESTONE:0,60,MOSSY_COBBLESTONE:0,5,SMOOTH_BRICK:0,10,SMOOTH_BRICK:1,10,SMOOTH_BRICK:2,10,COBBLESTONE:0,100)
RandomBlock(4,1,-1,COBBLESTONE:0,60,MOSSY_COBBLESTONE:0,5,SMOOTH_BRICK:0,10,SMOOTH_BRICK:1,10,SMOOTH_BRICK:2,10,COBBLESTONE:0,100)
RandomBlock(4,1,0,COBBLESTONE:0,60,MOSSY_COBBLESTONE:0,5,SMOOTH_BRICK:0,10,SMOOTH_BRICK:1,10,SMOOTH_BRICK:2,10,COBBLESTONE:0,100)
RandomBlock(4,1,1,COBBLESTONE:0,60,MOSSY_COBBLESTONE:0,5,SMOOTH_BRICK:0,10,SMOOTH_BRICK:1,10,SMOOTH_BRICK:2,10,COBBLESTONE:0,100)
RandomBlock(4,1,2,COBBLESTONE:0,60,MOSSY_COBBLESTONE:0,5,SMOOTH_BRICK:0,10,SMOOTH_BRICK:1,10,SMOOTH_BRICK:2,10,COBBLESTONE:0,100)
RandomBlock(4,1,3,COBBLESTONE:0,60,MOSSY_COBBLESTONE:0,5,SMOOTH_BRICK:0,10,SMOOTH_BRICK:1,10,SMOOTH_BRICK:2,10,COBBLESTONE:0,100)
RandomBlock(4,1,4,COBBLESTONE:0,60,MOSSY_COBBLESTONE:0,5,SMOOTH_BRICK:0,10,SMOOTH_BRICK:1,10,SMOOTH_BRICK:2,10,COBBLESTONE:0,100)
RandomBlock(4,1,5,COBBLESTONE:0,60,MOSSY_COBBLESTONE:0,5,SMOOTH_BRICK:0,10,SMOOTH_BRICK:1,10,SMOOTH_BRICK:2,10,COBBLESTONE:0,100)
RandomBlock(4,1,6,COBBLESTONE:0,60,MOSSY_COBBLESTONE:0,5,SMOOTH_BRICK:0,10,SMOOTH_BRICK:1,10,SMOOTH_BRICK:2,10,COBBLESTONE:0,100)
RandomBlock(4,1,7,COBBLESTONE:0,60,MOSSY_COBBLESTONE:0,5,SMOOTH_BRICK:0,10,SMOOTH_BRICK:1,10,SMOOTH_BRICK:2,10,COBBLESTONE:0,100)
Block(4,2,-3,SPRUCE_FENCE:0)
Block(4,2,-2,SPRUCE_FENCE:0)
Block(4,2,-1,SPRUCE_FENCE:0)
Block(4,2,0,SPRUCE_FENCE:0)
Block(4,2,1,SPRUCE_FENCE:0)
Block(4,2,2,SPRUCE_FENCE:0)
Block(4,2,3,SPRUCE_FENCE:0)
Block(4,2,4,SPRUCE_FENCE:0)
Block(4,2,5,SPRUCE_FENCE:0)
Block(4,2,6,SPRUCE_FENCE:0)
Block(4,2,7,SPRUCE_FENCE:0)
Block(4,3,-3,SPRUCE_FENCE:0)
Block(4,3,-2,SPRUCE_FENCE:0)
Block(4,3,-1,SPRUCE_FENCE:0)
Block(4,3,0,SPRUCE_FENCE:0)
Block(4,3,1,SPRUCE_FENCE:0)
Block(4,3,2,SPRUCE_FENCE:0)
Block(4,3,3,SPRUCE_FENCE:0)
Block(4,3,4,SPRUCE_FENCE:0)
Block(4,3,5,SPRUCE_FENCE:0)
Block(4,3,6,SPRUCE_FENCE:0)
Block(4,3,7,SPRUCE_FENCE:0)
RandomBlock(4,4,-3,WOOD_STEP:1,70,WOOD_STEP:5,100)
RandomBlock(4,4,-2,WOOD_STEP:1,70,WOOD_STEP:5,100)
RandomBlock(4,4,-1,WOOD_STEP:1,70,WOOD_STEP:5,100)
RandomBlock(4,4,0,WOOD_STEP:1,70,WOOD_STEP:5,100)
RandomBlock(4,4,1,WOOD_STEP:1,70,WOOD_STEP:5,100)
RandomBlock(4,4,2,WOOD_STEP:1,70,WOOD_STEP:5,100)
RandomBlock(4,4,3,WOOD_STEP:1,70,WOOD_STEP:5,100)
RandomBlock(4,4,4,WOOD_STEP:1,70,WOOD_STEP:5,100)
RandomBlock(4,4,5,WOOD_STEP:1,70,WOOD_STEP:5,100)
RandomBlock(4,4,6,WOOD_STEP:1,70,WOOD_STEP:5,100)
RandomBlock(4,4,7,WOOD_STEP:1,70,WOOD_STEP:5,100)
RandomBlock(5,0,-4,COBBLESTONE:0,60,MOSSY_COBBLESTONE:0,5,SMOOTH_BRICK:0,10,SMOOTH_BRICK:1,10,SMOOTH_BRICK:2,10,COBBLESTONE:0,100)
RandomBlock(5,0,-3,COBBLESTONE:0,60,MOSSY_COBBLESTONE:0,5,SMOOTH_BRICK:0,10,SMOOTH_BRICK:1,10,SMOOTH_BRICK:2,10,COBBLESTONE:0,100)
RandomBlock(5,0,-2,COBBLESTONE:0,60,MOSSY_COBBLESTONE:0,5,SMOOTH_BRICK:0,10,SMOOTH_BRICK:1,10,SMOOTH_BRICK:2,10,COBBLESTONE:0,100)
RandomBlock(5,0,-1,COBBLESTONE:0,60,MOSSY_COBBLESTONE:0,5,SMOOTH_BRICK:0,10,SMOOTH_BRICK:1,10,SMOOTH_BRICK:2,10,COBBLESTONE:0,100)
RandomBlock(5,0,0,COBBLESTONE:0,60,MOSSY_COBBLESTONE:0,5,SMOOTH_BRICK:0,10,SMOOTH_BRICK:1,10,SMOOTH_BRICK:2,10,COBBLESTONE:0,100)
RandomBlock(5,0,1,COBBLESTONE:0,60,MOSSY_COBBLESTONE:0,5,SMOOTH_BRICK:0,10,SMOOTH_BRICK:1,10,SMOOTH_BRICK:2,10,COBBLESTONE:0,100)
RandomBlock(5,0,2,COBBLESTONE:0,60,MOSSY_COBBLESTONE:0,5,SMOOTH_BRICK:0,10,SMOOTH_BRICK:1,10,SMOOTH_BRICK:2,10,COBBLESTONE:0,100)
RandomBlock(5,0,3,COBBLESTONE:0,60,MOSSY_COBBLESTONE:0,5,SMOOTH_BRICK:0,10,SMOOTH_BRICK:1,10,SMOOTH_BRICK:2,10,COBBLESTONE:0,100)
RandomBlock(5,0,4,COBBLESTONE:0,60,MOSSY_COBBLESTONE:0,5,SMOOTH_BRICK:0,10,SMOOTH_BRICK:1,10,SMOOTH_BRICK:2,10,COBBLESTONE:0,100)
RandomBlock(5,0,5,COBBLESTONE:0,60,MOSSY_COBBLESTONE:0,5,SMOOTH_BRICK:0,10,SMOOTH_BRICK:1,10,SMOOTH_BRICK:2,10,COBBLESTONE:0,100)
RandomBlock(5,0,6,COBBLESTONE:0,60,MOSSY_COBBLESTONE:0,5,SMOOTH_BRICK:0,10,SMOOTH_BRICK:1,10,SMOOTH_BRICK:2,10,COBBLESTONE:0,100)
RandomBlock(5,0,7,COBBLESTONE:0,60,MOSSY_COBBLESTONE:0,5,SMOOTH_BRICK:0,10,SMOOTH_BRICK:1,10,SMOOTH_BRICK:2,10,COBBLESTONE:0,100)
RandomBlock(5,0,8,COBBLESTONE:0,60,MOSSY_COBBLESTONE:0,5,SMOOTH_BRICK:0,10,SMOOTH_BRICK:1,10,SMOOTH_BRICK:2,10,COBBLESTONE:0,100)
Entity(-2,2,5,minecraft:cave_spider,1,../../NBT/Entities/VikingVillage/edderkopp.txt)
Entity(1,2,-1,minecraft:cave_spider,1,../../NBT/Entities/VikingVillage/edderkopp.txt)
Entity(2,1,1,minecraft:cave_spider,1,../../NBT/Entities/VikingVillage/edderkopp.txt)
Entity(2,2,4,minecraft:cave_spider,1,../../NBT/Entities/VikingVillage/edderkopp.txt)
