Author: NLBlackEagle
Description: No description given
SettingsMode: WriteDisable
Frequency: 0
SpawnHeight: highestBlock
UseCenterForHighestBlock: true
MinHeight: 0
MaxHeight: 255
InheritBO3: 
InheritBO3Rotation: NORTH
OverrideChildSettings: true
OverrideParentHeight: false
CanOverride: false
BranchFrequency: 0
BranchFrequencyGroup: 
MustBeBelowOther: false
MustBeInside: 
CannotBeInside: 
ReplacesBO3: 
MustBeInsideWorldBorders: false
CanSpawnOnWater: true
SpawnOnWaterOnly: false
SpawnUnderWater: false
SpawnAtWaterLevel: false
HeightOffset: 0
RemoveAir: false
ReplaceAbove: 
ReplaceBelow: 
ReplaceWithBiomeBlocks: false
ReplaceWithSurfaceBlock: GRASS
ReplaceWithGroundBlock: DIRT
ReplaceWithStoneBlock: STONE
SmoothRadius: 0
SmoothHeightOffset: 0
SmoothStartTop: false
SmoothStartWood: false
SmoothingSurfaceBlock: 
SmoothingGroundBlock: 
BO3Group: 
IsSpawnPoint: false
DoReplaceBlocks: false
Block(-2,-50,-7,LOG:0)
Block(-2,-49,-7,LOG:0)
Block(-2,-48,-7,LOG:0)
Block(-2,-47,-7,LOG:0)
Block(-2,-46,-7,LOG:0)
Block(-2,-45,-7,LOG:0)
Block(-2,-44,-7,LOG:0)
Block(-2,-43,-7,LOG:0)
Block(-2,-42,-7,LOG:0)
Block(-2,-41,-7,LOG:0)
Block(-2,-40,-7,LOG:0)
Block(-2,-39,-7,LOG:0)
Block(-2,-38,-7,LOG:0)
Block(-2,-37,-7,LOG:0)
Block(-2,-36,-7,LOG:0)
Block(-2,-35,-7,LOG:0)
Block(-2,-34,-7,LOG:0)
Block(-2,-33,-7,LOG:0)
Block(-2,-32,-7,LOG:0)
Block(-2,-31,-7,LOG:0)
Block(-2,-30,-7,LOG:0)
Block(-2,-29,-7,LOG:0)
Block(-2,-28,-7,LOG:0)
Block(-2,-27,-7,LOG:0)
Block(-2,-26,-7,LOG:0)
Block(-2,-25,-7,LOG:0)
Block(-2,-24,-7,LOG:0)
Block(-2,-23,-7,LOG:0)
Block(-2,-22,-7,LOG:0)
Block(-2,-21,-7,LOG:0)
Block(-2,-20,-7,LOG:0)
Block(-2,-19,-7,LOG:0)
Block(-2,-18,-7,LOG:0)
Block(-2,-17,-7,LOG:0)
Block(-2,-16,-7,LOG:0)
Block(-2,-15,-7,LOG:0)
Block(-2,-14,-7,LOG:0)
Block(-2,-13,-7,LOG:0)
Block(-2,-12,-7,LOG:0)
Block(-2,-11,-7,LOG:0)
Block(-2,-10,-7,LOG:0)
Block(-2,-9,-7,SMOOTH_STAIRS:0)
Block(-1,-50,-7,STONE:5)
Block(-1,-50,-6,STONE:5)
Block(-1,-49,-7,STONE:5)
Block(-1,-49,-6,STONE:5)
Block(-1,-48,-7,STONE:5)
Block(-1,-48,-6,STONE:5)
Block(-1,-47,-7,STONE:5)
Block(-1,-47,-6,STONE:5)
Block(-1,-46,-7,STONE:5)
Block(-1,-46,-6,STONE:5)
Block(-1,-45,-7,STONE:5)
Block(-1,-45,-6,STONE:5)
Block(-1,-44,-7,STONE:5)
Block(-1,-44,-6,STONE:5)
Block(-1,-43,-7,STONE:5)
Block(-1,-43,-6,STONE:5)
Block(-1,-42,-7,STONE:5)
Block(-1,-42,-6,STONE:5)
Block(-1,-41,-7,STONE:5)
Block(-1,-41,-6,STONE:5)
Block(-1,-40,-7,STONE:5)
Block(-1,-40,-6,STONE:5)
Block(-1,-39,-7,STONE:5)
Block(-1,-39,-6,STONE:5)
Block(-1,-38,-7,STONE:5)
Block(-1,-38,-6,STONE:5)
Block(-1,-37,-7,STONE:5)
Block(-1,-37,-6,STONE:5)
Block(-1,-36,-7,STONE:5)
Block(-1,-36,-6,STONE:5)
Block(-1,-35,-7,STONE:5)
Block(-1,-35,-6,STONE:5)
Block(-1,-34,-7,STONE:5)
Block(-1,-34,-6,STONE:5)
Block(-1,-33,-7,STONE:5)
Block(-1,-33,-6,STONE:5)
Block(-1,-32,-7,STONE:5)
Block(-1,-32,-6,STONE:5)
Block(-1,-31,-7,STONE:5)
Block(-1,-31,-6,STONE:5)
Block(-1,-30,-7,STONE:5)
Block(-1,-30,-6,STONE:5)
Block(-1,-29,-7,STONE:5)
Block(-1,-29,-6,STONE:5)
Block(-1,-28,-7,STONE:5)
Block(-1,-28,-6,STONE:5)
Block(-1,-27,-7,STONE:5)
Block(-1,-27,-6,STONE:5)
Block(-1,-26,-7,STONE:5)
Block(-1,-26,-6,STONE:5)
Block(-1,-25,-7,STONE:5)
Block(-1,-25,-6,STONE:5)
Block(-1,-24,-7,STONE:5)
Block(-1,-24,-6,STONE:5)
Block(-1,-23,-7,STONE:5)
Block(-1,-23,-6,STONE:5)
Block(-1,-22,-7,STONE:5)
Block(-1,-22,-6,STONE:5)
Block(-1,-21,-7,STONE:5)
Block(-1,-21,-6,STONE:5)
Block(-1,-20,-7,STONE:5)
Block(-1,-20,-6,STONE:5)
Block(-1,-19,-7,COBBLESTONE:0)
Block(-1,-19,-6,COBBLESTONE:0)
Block(-1,-18,-7,COBBLESTONE:0)
Block(-1,-18,-6,STONE:5)
Block(-1,-17,-7,COBBLESTONE:0)
Block(-1,-17,-6,STONE:5)
Block(-1,-16,-7,COBBLESTONE:0)
Block(-1,-16,-6,STONE:5)
Block(-1,-15,-7,COBBLESTONE:0)
Block(-1,-15,-6,STONE:5)
Block(-1,-14,-7,COBBLESTONE:0)
Block(-1,-14,-6,COBBLESTONE:0)
Block(-1,-13,-7,COBBLESTONE:0)
Block(-1,-13,-6,STONE:5)
Block(-1,-12,-7,COBBLESTONE:0)
Block(-1,-12,-6,STAINED_CLAY:9)
Block(-1,-11,-7,COBBLESTONE:0)
Block(-1,-11,-6,COBBLESTONE:0)
Block(-1,-10,-7,COBBLESTONE:0)
Block(-1,-10,-6,STONE:5)
Block(-1,-9,-7,COBBLESTONE_STAIRS:3)
Block(-1,-9,-6,COBBLESTONE_STAIRS:0)
Block(0,-50,-7,COBBLESTONE:0)
Block(0,-50,-6,STONE:5)
Block(0,-50,-5,COBBLESTONE:0)
Block(0,-49,-7,COBBLESTONE:0)
Block(0,-49,-6,STONE:5)
Block(0,-49,-5,COBBLESTONE:0)
Block(0,-48,-7,COBBLESTONE:0)
Block(0,-48,-6,STONE:5)
Block(0,-48,-5,COBBLESTONE:0)
Block(0,-47,-7,COBBLESTONE:0)
Block(0,-47,-6,STONE:5)
Block(0,-47,-5,COBBLESTONE:0)
Block(0,-46,-7,COBBLESTONE:0)
Block(0,-46,-6,STONE:5)
Block(0,-46,-5,COBBLESTONE:0)
Block(0,-45,-7,COBBLESTONE:0)
Block(0,-45,-6,STONE:5)
Block(0,-45,-5,COBBLESTONE:0)
Block(0,-44,-7,COBBLESTONE:0)
Block(0,-44,-6,STONE:5)
Block(0,-44,-5,COBBLESTONE:0)
Block(0,-43,-7,COBBLESTONE:0)
Block(0,-43,-6,STONE:5)
Block(0,-43,-5,COBBLESTONE:0)
Block(0,-42,-7,COBBLESTONE:0)
Block(0,-42,-6,STONE:5)
Block(0,-42,-5,COBBLESTONE:0)
Block(0,-41,-7,COBBLESTONE:0)
Block(0,-41,-6,STONE:5)
Block(0,-41,-5,COBBLESTONE:0)
Block(0,-40,-7,COBBLESTONE:0)
Block(0,-40,-6,STONE:5)
Block(0,-40,-5,COBBLESTONE:0)
Block(0,-39,-7,COBBLESTONE:0)
Block(0,-39,-6,STONE:5)
Block(0,-39,-5,COBBLESTONE:0)
Block(0,-38,-7,COBBLESTONE:0)
Block(0,-38,-6,STONE:5)
Block(0,-38,-5,COBBLESTONE:0)
Block(0,-37,-7,COBBLESTONE:0)
Block(0,-37,-6,STONE:5)
Block(0,-37,-5,COBBLESTONE:0)
Block(0,-36,-7,COBBLESTONE:0)
Block(0,-36,-6,STONE:5)
Block(0,-36,-5,COBBLESTONE:0)
Block(0,-35,-7,COBBLESTONE:0)
Block(0,-35,-6,STONE:5)
Block(0,-35,-5,COBBLESTONE:0)
Block(0,-34,-7,COBBLESTONE:0)
Block(0,-34,-6,STONE:5)
Block(0,-34,-5,COBBLESTONE:0)
Block(0,-33,-7,COBBLESTONE:0)
Block(0,-33,-6,STONE:5)
Block(0,-33,-5,COBBLESTONE:0)
Block(0,-32,-7,COBBLESTONE:0)
Block(0,-32,-6,STONE:5)
Block(0,-32,-5,COBBLESTONE:0)
Block(0,-31,-7,COBBLESTONE:0)
Block(0,-31,-6,STONE:5)
Block(0,-31,-5,COBBLESTONE:0)
Block(0,-30,-7,COBBLESTONE:0)
Block(0,-30,-6,STONE:5)
Block(0,-30,-5,COBBLESTONE:0)
Block(0,-29,-7,COBBLESTONE:0)
Block(0,-29,-6,STONE:5)
Block(0,-29,-5,COBBLESTONE:0)
Block(0,-28,-7,COBBLESTONE:0)
Block(0,-28,-6,STONE:5)
Block(0,-28,-5,COBBLESTONE:0)
Block(0,-27,-7,COBBLESTONE:0)
Block(0,-27,-6,STONE:5)
Block(0,-27,-5,COBBLESTONE:0)
Block(0,-26,-7,COBBLESTONE:0)
Block(0,-26,-6,STONE:5)
Block(0,-26,-5,COBBLESTONE:0)
Block(0,-25,-7,COBBLESTONE:0)
Block(0,-25,-6,STONE:5)
Block(0,-25,-5,COBBLESTONE:0)
Block(0,-24,-7,COBBLESTONE:0)
Block(0,-24,-6,STONE:5)
Block(0,-24,-5,COBBLESTONE:0)
Block(0,-23,-7,COBBLESTONE:0)
Block(0,-23,-6,STONE:5)
Block(0,-23,-5,COBBLESTONE:0)
Block(0,-22,-7,COBBLESTONE:0)
Block(0,-22,-6,STONE:5)
Block(0,-22,-5,COBBLESTONE:0)
Block(0,-21,-7,COBBLESTONE:0)
Block(0,-21,-6,STONE:5)
Block(0,-21,-5,COBBLESTONE:0)
Block(0,-20,-7,COBBLESTONE:0)
Block(0,-20,-6,STONE:5)
Block(0,-20,-5,COBBLESTONE:0)
Block(0,-19,-7,COBBLESTONE:0)
Block(0,-19,-6,COBBLESTONE:0)
Block(0,-19,-5,STONE:5)
Block(0,-18,-7,COBBLESTONE:0)
Block(0,-18,-6,COBBLESTONE:0)
Block(0,-18,-5,COBBLESTONE:0)
Block(0,-17,-7,SMOOTH_BRICK:1)
Block(0,-17,-6,SMOOTH_BRICK:0)
Block(0,-17,-5,STONE:5)
Block(0,-16,-7,SMOOTH_BRICK:2)
Block(0,-16,-6,STONE:5)
Block(0,-16,-5,STONE:5)
Block(0,-15,-7,STONE:5)
Block(0,-15,-6,STONE:5)
Block(0,-15,-5,STONE:5)
Block(0,-14,-7,STONE:5)
Block(0,-14,-6,SMOOTH_BRICK:0)
Block(0,-14,-5,STONE:5)
Block(0,-13,-7,SMOOTH_BRICK:1)
Block(0,-13,-6,COBBLESTONE:0)
Block(0,-13,-5,COBBLESTONE:0)
Block(0,-12,-7,COBBLESTONE:0)
Block(0,-12,-6,STAINED_CLAY:9)
Block(0,-12,-5,COBBLESTONE:0)
Block(0,-11,-7,STAINED_CLAY:9)
Block(0,-11,-6,STONE:5)
Block(0,-11,-5,COBBLESTONE:0)
Block(0,-10,-7,COBBLESTONE:0)
Block(0,-10,-6,COBBLESTONE:0)
Block(0,-10,-5,STONE:5)
Block(0,-9,-7,STONE:6)
Block(0,-9,-6,COBBLESTONE_STAIRS:3)
Block(0,-9,-5,COBBLESTONE_STAIRS:0)
Block(0,-8,-7,STONE:6)
Block(0,-7,-7,STONE:6)
Block(0,-6,-7,STONE:6)
Block(0,-5,-7,COBBLESTONE_STAIRS:3)
Block(1,-50,-7,COBBLESTONE:0)
Block(1,-50,-6,COBBLESTONE:0)
Block(1,-50,-5,COBBLESTONE:0)
Block(1,-50,-4,LOG:0)
Block(1,-49,-7,COBBLESTONE:0)
Block(1,-49,-6,COBBLESTONE:0)
Block(1,-49,-5,COBBLESTONE:0)
Block(1,-49,-4,LOG:0)
Block(1,-48,-7,COBBLESTONE:0)
Block(1,-48,-6,COBBLESTONE:0)
Block(1,-48,-5,COBBLESTONE:0)
Block(1,-48,-4,LOG:0)
Block(1,-47,-7,COBBLESTONE:0)
Block(1,-47,-6,COBBLESTONE:0)
Block(1,-47,-5,COBBLESTONE:0)
Block(1,-47,-4,LOG:0)
Block(1,-46,-7,COBBLESTONE:0)
Block(1,-46,-6,COBBLESTONE:0)
Block(1,-46,-5,COBBLESTONE:0)
Block(1,-46,-4,LOG:0)
Block(1,-45,-7,COBBLESTONE:0)
Block(1,-45,-6,COBBLESTONE:0)
Block(1,-45,-5,COBBLESTONE:0)
Block(1,-45,-4,LOG:0)
Block(1,-44,-7,COBBLESTONE:0)
Block(1,-44,-6,COBBLESTONE:0)
Block(1,-44,-5,COBBLESTONE:0)
Block(1,-44,-4,LOG:0)
Block(1,-43,-7,COBBLESTONE:0)
Block(1,-43,-6,COBBLESTONE:0)
Block(1,-43,-5,COBBLESTONE:0)
Block(1,-43,-4,LOG:0)
Block(1,-42,-7,COBBLESTONE:0)
Block(1,-42,-6,COBBLESTONE:0)
Block(1,-42,-5,COBBLESTONE:0)
Block(1,-42,-4,LOG:0)
Block(1,-41,-7,COBBLESTONE:0)
Block(1,-41,-6,COBBLESTONE:0)
Block(1,-41,-5,COBBLESTONE:0)
Block(1,-41,-4,LOG:0)
Block(1,-40,-7,COBBLESTONE:0)
Block(1,-40,-6,COBBLESTONE:0)
Block(1,-40,-5,COBBLESTONE:0)
Block(1,-40,-4,LOG:0)
Block(1,-39,-7,COBBLESTONE:0)
Block(1,-39,-6,COBBLESTONE:0)
Block(1,-39,-5,COBBLESTONE:0)
Block(1,-39,-4,LOG:0)
Block(1,-38,-7,COBBLESTONE:0)
Block(1,-38,-6,COBBLESTONE:0)
Block(1,-38,-5,COBBLESTONE:0)
Block(1,-38,-4,LOG:0)
Block(1,-37,-7,COBBLESTONE:0)
Block(1,-37,-6,COBBLESTONE:0)
Block(1,-37,-5,COBBLESTONE:0)
Block(1,-37,-4,LOG:0)
Block(1,-36,-7,COBBLESTONE:0)
Block(1,-36,-6,COBBLESTONE:0)
Block(1,-36,-5,COBBLESTONE:0)
Block(1,-36,-4,LOG:0)
Block(1,-35,-7,COBBLESTONE:0)
Block(1,-35,-6,COBBLESTONE:0)
Block(1,-35,-5,COBBLESTONE:0)
Block(1,-35,-4,LOG:0)
Block(1,-34,-7,COBBLESTONE:0)
Block(1,-34,-6,COBBLESTONE:0)
Block(1,-34,-5,COBBLESTONE:0)
Block(1,-34,-4,LOG:0)
Block(1,-33,-7,COBBLESTONE:0)
Block(1,-33,-6,COBBLESTONE:0)
Block(1,-33,-5,COBBLESTONE:0)
Block(1,-33,-4,LOG:0)
Block(1,-32,-7,COBBLESTONE:0)
Block(1,-32,-6,COBBLESTONE:0)
Block(1,-32,-5,COBBLESTONE:0)
Block(1,-32,-4,LOG:0)
Block(1,-31,-7,COBBLESTONE:0)
Block(1,-31,-6,COBBLESTONE:0)
Block(1,-31,-5,COBBLESTONE:0)
Block(1,-31,-4,LOG:0)
Block(1,-30,-7,COBBLESTONE:0)
Block(1,-30,-6,COBBLESTONE:0)
Block(1,-30,-5,COBBLESTONE:0)
Block(1,-30,-4,LOG:0)
Block(1,-29,-7,COBBLESTONE:0)
Block(1,-29,-6,COBBLESTONE:0)
Block(1,-29,-5,COBBLESTONE:0)
Block(1,-29,-4,LOG:0)
Block(1,-28,-7,COBBLESTONE:0)
Block(1,-28,-6,COBBLESTONE:0)
Block(1,-28,-5,COBBLESTONE:0)
Block(1,-28,-4,LOG:0)
Block(1,-27,-7,COBBLESTONE:0)
Block(1,-27,-6,COBBLESTONE:0)
Block(1,-27,-5,COBBLESTONE:0)
Block(1,-27,-4,LOG:0)
Block(1,-26,-7,COBBLESTONE:0)
Block(1,-26,-6,COBBLESTONE:0)
Block(1,-26,-5,COBBLESTONE:0)
Block(1,-26,-4,LOG:0)
Block(1,-25,-7,COBBLESTONE:0)
Block(1,-25,-6,COBBLESTONE:0)
Block(1,-25,-5,COBBLESTONE:0)
Block(1,-25,-4,LOG:0)
Block(1,-24,-7,COBBLESTONE:0)
Block(1,-24,-6,COBBLESTONE:0)
Block(1,-24,-5,COBBLESTONE:0)
Block(1,-24,-4,LOG:0)
Block(1,-23,-7,COBBLESTONE:0)
Block(1,-23,-6,COBBLESTONE:0)
Block(1,-23,-5,COBBLESTONE:0)
Block(1,-23,-4,LOG:0)
Block(1,-22,-7,COBBLESTONE:0)
Block(1,-22,-6,COBBLESTONE:0)
Block(1,-22,-5,COBBLESTONE:0)
Block(1,-22,-4,LOG:0)
Block(1,-21,-7,COBBLESTONE:0)
Block(1,-21,-6,COBBLESTONE:0)
Block(1,-21,-5,COBBLESTONE:0)
Block(1,-21,-4,LOG:0)
Block(1,-20,-7,COBBLESTONE:0)
Block(1,-20,-6,COBBLESTONE:0)
Block(1,-20,-5,COBBLESTONE:0)
Block(1,-20,-4,LOG:0)
Block(1,-19,-7,STONE:5)
Block(1,-19,-6,COBBLESTONE:0)
Block(1,-19,-5,COBBLESTONE:0)
Block(1,-19,-4,LOG:0)
Block(1,-18,-7,COBBLESTONE:0)
Block(1,-18,-6,STAINED_CLAY:9)
Block(1,-18,-5,STONE:5)
Block(1,-18,-4,LOG:0)
Block(1,-17,-7,COBBLESTONE:0)
Block(1,-17,-6,COBBLESTONE:0)
Block(1,-17,-5,COBBLESTONE:0)
Block(1,-17,-4,LOG:0)
Block(1,-16,-7,COBBLESTONE:0)
Block(1,-16,-6,COBBLESTONE:0)
Block(1,-16,-5,SMOOTH_BRICK:2)
Block(1,-16,-4,LOG:0)
Block(1,-15,-7,COBBLESTONE:0)
Block(1,-15,-6,STONE:5)
Block(1,-15,-5,SMOOTH_BRICK:1)
Block(1,-15,-4,LOG:0)
Block(1,-14,-7,STONE:5)
Block(1,-14,-6,SMOOTH_BRICK:1)
Block(1,-14,-5,COBBLESTONE:0)
Block(1,-14,-4,LOG:0)
Block(1,-13,-7,COBBLESTONE:0)
Block(1,-13,-6,SMOOTH_BRICK:1)
Block(1,-13,-5,COBBLESTONE:0)
Block(1,-13,-4,LOG:0)
Block(1,-12,-7,COBBLESTONE:0)
Block(1,-12,-6,STONE:5)
Block(1,-12,-5,STONE:5)
Block(1,-12,-4,LOG:0)
Block(1,-11,-7,STONE:5)
Block(1,-11,-6,STONE:5)
Block(1,-11,-5,STONE:5)
Block(1,-11,-4,LOG:0)
Block(1,-10,-7,SMOOTH_BRICK:2)
Block(1,-10,-6,COBBLESTONE:0)
Block(1,-10,-5,COBBLESTONE:0)
Block(1,-10,-4,LOG:0)
Block(1,-9,-7,STONE:6)
Block(1,-9,-6,STONE:6)
Block(1,-9,-5,COBBLESTONE_STAIRS:3)
Block(1,-9,-4,SMOOTH_STAIRS:0)
Block(1,-8,-7,STONE:6)
Block(1,-8,-6,STONE:6)
Block(1,-7,-7,STONE:6)
Block(1,-7,-6,STONE:6)
Block(1,-6,-7,STONE:6)
Block(1,-6,-6,STONE:6)
Block(1,-5,-7,COBBLESTONE_STAIRS:3)
Block(1,-5,-6,COBBLESTONE_STAIRS:0)
Block(2,-50,-7,COBBLESTONE:0)
Block(2,-50,-6,COBBLESTONE:0)
Block(2,-50,-5,COBBLESTONE:0)
Block(2,-50,-4,STAINED_CLAY:9)
Block(2,-50,-3,COBBLESTONE:0)
Block(2,-49,-7,COBBLESTONE:0)
Block(2,-49,-6,COBBLESTONE:0)
Block(2,-49,-5,COBBLESTONE:0)
Block(2,-49,-4,STAINED_CLAY:9)
Block(2,-49,-3,COBBLESTONE:0)
Block(2,-48,-7,COBBLESTONE:0)
Block(2,-48,-6,COBBLESTONE:0)
Block(2,-48,-5,COBBLESTONE:0)
Block(2,-48,-4,STAINED_CLAY:9)
Block(2,-48,-3,COBBLESTONE:0)
Block(2,-47,-7,COBBLESTONE:0)
Block(2,-47,-6,COBBLESTONE:0)
Block(2,-47,-5,COBBLESTONE:0)
Block(2,-47,-4,STAINED_CLAY:9)
Block(2,-47,-3,COBBLESTONE:0)
Block(2,-46,-7,COBBLESTONE:0)
Block(2,-46,-6,COBBLESTONE:0)
Block(2,-46,-5,COBBLESTONE:0)
Block(2,-46,-4,STAINED_CLAY:9)
Block(2,-46,-3,COBBLESTONE:0)
Block(2,-45,-7,COBBLESTONE:0)
Block(2,-45,-6,COBBLESTONE:0)
Block(2,-45,-5,COBBLESTONE:0)
Block(2,-45,-4,STAINED_CLAY:9)
Block(2,-45,-3,COBBLESTONE:0)
Block(2,-44,-7,COBBLESTONE:0)
Block(2,-44,-6,COBBLESTONE:0)
Block(2,-44,-5,COBBLESTONE:0)
Block(2,-44,-4,STAINED_CLAY:9)
Block(2,-44,-3,COBBLESTONE:0)
Block(2,-43,-7,COBBLESTONE:0)
Block(2,-43,-6,COBBLESTONE:0)
Block(2,-43,-5,COBBLESTONE:0)
Block(2,-43,-4,STAINED_CLAY:9)
Block(2,-43,-3,COBBLESTONE:0)
Block(2,-42,-7,COBBLESTONE:0)
Block(2,-42,-6,COBBLESTONE:0)
Block(2,-42,-5,COBBLESTONE:0)
Block(2,-42,-4,STAINED_CLAY:9)
Block(2,-42,-3,COBBLESTONE:0)
Block(2,-41,-7,COBBLESTONE:0)
Block(2,-41,-6,COBBLESTONE:0)
Block(2,-41,-5,COBBLESTONE:0)
Block(2,-41,-4,STAINED_CLAY:9)
Block(2,-41,-3,COBBLESTONE:0)
Block(2,-40,-7,COBBLESTONE:0)
Block(2,-40,-6,COBBLESTONE:0)
Block(2,-40,-5,COBBLESTONE:0)
Block(2,-40,-4,STAINED_CLAY:9)
Block(2,-40,-3,COBBLESTONE:0)
Block(2,-39,-7,COBBLESTONE:0)
Block(2,-39,-6,COBBLESTONE:0)
Block(2,-39,-5,COBBLESTONE:0)
Block(2,-39,-4,STAINED_CLAY:9)
Block(2,-39,-3,COBBLESTONE:0)
Block(2,-38,-7,COBBLESTONE:0)
Block(2,-38,-6,COBBLESTONE:0)
Block(2,-38,-5,COBBLESTONE:0)
Block(2,-38,-4,STAINED_CLAY:9)
Block(2,-38,-3,COBBLESTONE:0)
Block(2,-37,-7,COBBLESTONE:0)
Block(2,-37,-6,COBBLESTONE:0)
Block(2,-37,-5,COBBLESTONE:0)
Block(2,-37,-4,STAINED_CLAY:9)
Block(2,-37,-3,COBBLESTONE:0)
Block(2,-36,-7,COBBLESTONE:0)
Block(2,-36,-6,COBBLESTONE:0)
Block(2,-36,-5,COBBLESTONE:0)
Block(2,-36,-4,STAINED_CLAY:9)
Block(2,-36,-3,COBBLESTONE:0)
Block(2,-35,-7,COBBLESTONE:0)
Block(2,-35,-6,COBBLESTONE:0)
Block(2,-35,-5,COBBLESTONE:0)
Block(2,-35,-4,STAINED_CLAY:9)
Block(2,-35,-3,COBBLESTONE:0)
Block(2,-34,-7,COBBLESTONE:0)
Block(2,-34,-6,COBBLESTONE:0)
Block(2,-34,-5,COBBLESTONE:0)
Block(2,-34,-4,STAINED_CLAY:9)
Block(2,-34,-3,COBBLESTONE:0)
Block(2,-33,-7,COBBLESTONE:0)
Block(2,-33,-6,COBBLESTONE:0)
Block(2,-33,-5,COBBLESTONE:0)
Block(2,-33,-4,STAINED_CLAY:9)
Block(2,-33,-3,COBBLESTONE:0)
Block(2,-32,-7,COBBLESTONE:0)
Block(2,-32,-6,COBBLESTONE:0)
Block(2,-32,-5,COBBLESTONE:0)
Block(2,-32,-4,STAINED_CLAY:9)
Block(2,-32,-3,COBBLESTONE:0)
Block(2,-31,-7,COBBLESTONE:0)
Block(2,-31,-6,COBBLESTONE:0)
Block(2,-31,-5,COBBLESTONE:0)
Block(2,-31,-4,STAINED_CLAY:9)
Block(2,-31,-3,COBBLESTONE:0)
Block(2,-30,-7,COBBLESTONE:0)
Block(2,-30,-6,COBBLESTONE:0)
Block(2,-30,-5,COBBLESTONE:0)
Block(2,-30,-4,STAINED_CLAY:9)
Block(2,-30,-3,COBBLESTONE:0)
Block(2,-29,-7,COBBLESTONE:0)
Block(2,-29,-6,COBBLESTONE:0)
Block(2,-29,-5,COBBLESTONE:0)
Block(2,-29,-4,STAINED_CLAY:9)
Block(2,-29,-3,COBBLESTONE:0)
Block(2,-28,-7,COBBLESTONE:0)
Block(2,-28,-6,COBBLESTONE:0)
Block(2,-28,-5,COBBLESTONE:0)
Block(2,-28,-4,STAINED_CLAY:9)
Block(2,-28,-3,COBBLESTONE:0)
Block(2,-27,-7,COBBLESTONE:0)
Block(2,-27,-6,COBBLESTONE:0)
Block(2,-27,-5,COBBLESTONE:0)
Block(2,-27,-4,STAINED_CLAY:9)
Block(2,-27,-3,COBBLESTONE:0)
Block(2,-26,-7,COBBLESTONE:0)
Block(2,-26,-6,COBBLESTONE:0)
Block(2,-26,-5,COBBLESTONE:0)
Block(2,-26,-4,STAINED_CLAY:9)
Block(2,-26,-3,COBBLESTONE:0)
Block(2,-25,-7,COBBLESTONE:0)
Block(2,-25,-6,COBBLESTONE:0)
Block(2,-25,-5,COBBLESTONE:0)
Block(2,-25,-4,STAINED_CLAY:9)
Block(2,-25,-3,COBBLESTONE:0)
Block(2,-24,-7,COBBLESTONE:0)
Block(2,-24,-6,COBBLESTONE:0)
Block(2,-24,-5,COBBLESTONE:0)
Block(2,-24,-4,STAINED_CLAY:9)
Block(2,-24,-3,COBBLESTONE:0)
Block(2,-23,-7,COBBLESTONE:0)
Block(2,-23,-6,COBBLESTONE:0)
Block(2,-23,-5,COBBLESTONE:0)
Block(2,-23,-4,STAINED_CLAY:9)
Block(2,-23,-3,COBBLESTONE:0)
Block(2,-22,-7,COBBLESTONE:0)
Block(2,-22,-6,COBBLESTONE:0)
Block(2,-22,-5,COBBLESTONE:0)
Block(2,-22,-4,STAINED_CLAY:9)
Block(2,-22,-3,COBBLESTONE:0)
Block(2,-21,-7,COBBLESTONE:0)
Block(2,-21,-6,COBBLESTONE:0)
Block(2,-21,-5,COBBLESTONE:0)
Block(2,-21,-4,STAINED_CLAY:9)
Block(2,-21,-3,COBBLESTONE:0)
Block(2,-20,-7,COBBLESTONE:0)
Block(2,-20,-6,COBBLESTONE:0)
Block(2,-20,-5,COBBLESTONE:0)
Block(2,-20,-4,STAINED_CLAY:9)
Block(2,-20,-3,COBBLESTONE:0)
Block(2,-19,-7,COBBLESTONE:0)
Block(2,-19,-6,COBBLESTONE:0)
Block(2,-19,-5,STONE:5)
Block(2,-19,-4,COBBLESTONE:0)
Block(2,-19,-3,STONE:5)
Block(2,-18,-7,COBBLESTONE:0)
Block(2,-18,-6,COBBLESTONE:0)
Block(2,-18,-5,COBBLESTONE:0)
Block(2,-18,-4,COBBLESTONE:0)
Block(2,-18,-3,COBBLESTONE:0)
Block(2,-17,-7,SMOOTH_BRICK:2)
Block(2,-17,-6,SMOOTH_BRICK:1)
Block(2,-17,-5,COBBLESTONE:0)
Block(2,-17,-4,COBBLESTONE:0)
Block(2,-17,-3,STONE:5)
Block(2,-16,-7,COBBLESTONE:0)
Block(2,-16,-6,STONE:5)
Block(2,-16,-5,COBBLESTONE:0)
Block(2,-16,-4,COBBLESTONE:0)
Block(2,-16,-3,COBBLESTONE:0)
Block(2,-15,-7,COBBLESTONE:0)
Block(2,-15,-6,SMOOTH_BRICK:0)
Block(2,-15,-5,SMOOTH_BRICK:2)
Block(2,-15,-4,STONE:5)
Block(2,-15,-3,COBBLESTONE:0)
Block(2,-14,-7,STONE:5)
Block(2,-14,-6,STAINED_CLAY:9)
Block(2,-14,-5,COBBLESTONE:0)
Block(2,-14,-4,STAINED_CLAY:9)
Block(2,-14,-3,STONE:5)
Block(2,-13,-7,STONE:5)
Block(2,-13,-6,COBBLESTONE:0)
Block(2,-13,-5,STONE:5)
Block(2,-13,-4,COBBLESTONE:0)
Block(2,-13,-3,STONE:5)
Block(2,-12,-7,SMOOTH_BRICK:0)
Block(2,-12,-6,STONE:5)
Block(2,-12,-5,STONE:5)
Block(2,-12,-4,STONE:5)
Block(2,-12,-3,STONE:5)
Block(2,-11,-7,STONE:5)
Block(2,-11,-6,STONE:5)
Block(2,-11,-5,SMOOTH_BRICK:1)
Block(2,-11,-4,COBBLESTONE:0)
Block(2,-11,-3,COBBLESTONE:0)
Block(2,-10,-7,COBBLESTONE:0)
Block(2,-10,-6,COBBLESTONE:0)
Block(2,-10,-5,COBBLESTONE:0)
Block(2,-10,-4,COBBLESTONE:0)
Block(2,-10,-3,STONE:5)
Block(2,-9,-7,STONE:6)
Block(2,-9,-6,STONE:6)
Block(2,-9,-5,LOG:0)
Block(2,-9,-4,COBBLESTONE_STAIRS:3)
Block(2,-9,-3,COBBLESTONE_STAIRS:0)
Block(2,-8,-7,STONE:6)
Block(2,-8,-6,STONE:6)
Block(2,-8,-5,LOG:0)
Block(2,-7,-7,STONE:6)
Block(2,-7,-6,STONE:6)
Block(2,-7,-5,LOG:0)
Block(2,-6,-7,STONE:6)
Block(2,-6,-6,STONE:6)
Block(2,-6,-5,LOG:0)
Block(2,-5,-7,STONE:5)
Block(2,-5,-6,STONE:5)
Block(2,-5,-5,LOG:0)
Block(2,-4,-7,STONE:6)
Block(2,-4,-6,STONE:6)
Block(2,-4,-5,COBBLESTONE_STAIRS:0)
Block(2,-3,-7,STONE:6)
Block(2,-3,-6,STONE:6)
Block(2,-2,-7,STONE:6)
Block(2,-2,-6,STONE:6)
Block(2,-1,-7,COBBLESTONE_STAIRS:0)
Block(2,-1,-6,COBBLESTONE_STAIRS:0)
Block(3,-50,-7,STONE:5)
Block(3,-50,-6,STONE:5)
Block(3,-50,-5,COBBLESTONE:0)
Block(3,-50,-4,COBBLESTONE:0)
Block(3,-50,-3,COBBLESTONE:0)
Block(3,-50,-2,COBBLESTONE:0)
Block(3,-49,-7,STONE:5)
Block(3,-49,-6,STONE:5)
Block(3,-49,-5,COBBLESTONE:0)
Block(3,-49,-4,COBBLESTONE:0)
Block(3,-49,-3,COBBLESTONE:0)
Block(3,-49,-2,COBBLESTONE:0)
Block(3,-48,-7,STONE:5)
Block(3,-48,-6,STONE:5)
Block(3,-48,-5,COBBLESTONE:0)
Block(3,-48,-4,COBBLESTONE:0)
Block(3,-48,-3,COBBLESTONE:0)
Block(3,-48,-2,COBBLESTONE:0)
Block(3,-47,-7,STONE:5)
Block(3,-47,-6,STONE:5)
Block(3,-47,-5,COBBLESTONE:0)
Block(3,-47,-4,COBBLESTONE:0)
Block(3,-47,-3,COBBLESTONE:0)
Block(3,-47,-2,COBBLESTONE:0)
Block(3,-46,-7,STONE:5)
Block(3,-46,-6,STONE:5)
Block(3,-46,-5,COBBLESTONE:0)
Block(3,-46,-4,COBBLESTONE:0)
Block(3,-46,-3,COBBLESTONE:0)
Block(3,-46,-2,COBBLESTONE:0)
Block(3,-45,-7,STONE:5)
Block(3,-45,-6,STONE:5)
Block(3,-45,-5,COBBLESTONE:0)
Block(3,-45,-4,COBBLESTONE:0)
Block(3,-45,-3,COBBLESTONE:0)
Block(3,-45,-2,COBBLESTONE:0)
Block(3,-44,-7,STONE:5)
Block(3,-44,-6,STONE:5)
Block(3,-44,-5,COBBLESTONE:0)
Block(3,-44,-4,COBBLESTONE:0)
Block(3,-44,-3,COBBLESTONE:0)
Block(3,-44,-2,COBBLESTONE:0)
Block(3,-43,-7,STONE:5)
Block(3,-43,-6,STONE:5)
Block(3,-43,-5,COBBLESTONE:0)
Block(3,-43,-4,COBBLESTONE:0)
Block(3,-43,-3,COBBLESTONE:0)
Block(3,-43,-2,COBBLESTONE:0)
Block(3,-42,-7,STONE:5)
Block(3,-42,-6,STONE:5)
Block(3,-42,-5,COBBLESTONE:0)
Block(3,-42,-4,COBBLESTONE:0)
Block(3,-42,-3,COBBLESTONE:0)
Block(3,-42,-2,COBBLESTONE:0)
Block(3,-41,-7,STONE:5)
Block(3,-41,-6,STONE:5)
Block(3,-41,-5,COBBLESTONE:0)
Block(3,-41,-4,COBBLESTONE:0)
Block(3,-41,-3,COBBLESTONE:0)
Block(3,-41,-2,COBBLESTONE:0)
Block(3,-40,-7,STONE:5)
Block(3,-40,-6,STONE:5)
Block(3,-40,-5,COBBLESTONE:0)
Block(3,-40,-4,COBBLESTONE:0)
Block(3,-40,-3,COBBLESTONE:0)
Block(3,-40,-2,COBBLESTONE:0)
Block(3,-39,-7,STONE:5)
Block(3,-39,-6,STONE:5)
Block(3,-39,-5,COBBLESTONE:0)
Block(3,-39,-4,COBBLESTONE:0)
Block(3,-39,-3,COBBLESTONE:0)
Block(3,-39,-2,COBBLESTONE:0)
Block(3,-38,-7,STONE:5)
Block(3,-38,-6,STONE:5)
Block(3,-38,-5,COBBLESTONE:0)
Block(3,-38,-4,COBBLESTONE:0)
Block(3,-38,-3,COBBLESTONE:0)
Block(3,-38,-2,COBBLESTONE:0)
Block(3,-37,-7,STONE:5)
Block(3,-37,-6,STONE:5)
Block(3,-37,-5,COBBLESTONE:0)
Block(3,-37,-4,COBBLESTONE:0)
Block(3,-37,-3,COBBLESTONE:0)
Block(3,-37,-2,COBBLESTONE:0)
Block(3,-36,-7,STONE:5)
Block(3,-36,-6,STONE:5)
Block(3,-36,-5,COBBLESTONE:0)
Block(3,-36,-4,COBBLESTONE:0)
Block(3,-36,-3,COBBLESTONE:0)
Block(3,-36,-2,COBBLESTONE:0)
Block(3,-35,-7,STONE:5)
Block(3,-35,-6,STONE:5)
Block(3,-35,-5,COBBLESTONE:0)
Block(3,-35,-4,COBBLESTONE:0)
Block(3,-35,-3,COBBLESTONE:0)
Block(3,-35,-2,COBBLESTONE:0)
Block(3,-34,-7,STONE:5)
Block(3,-34,-6,STONE:5)
Block(3,-34,-5,COBBLESTONE:0)
Block(3,-34,-4,COBBLESTONE:0)
Block(3,-34,-3,COBBLESTONE:0)
Block(3,-34,-2,COBBLESTONE:0)
Block(3,-33,-7,STONE:5)
Block(3,-33,-6,STONE:5)
Block(3,-33,-5,COBBLESTONE:0)
Block(3,-33,-4,COBBLESTONE:0)
Block(3,-33,-3,COBBLESTONE:0)
Block(3,-33,-2,COBBLESTONE:0)
Block(3,-32,-7,STONE:5)
Block(3,-32,-6,STONE:5)
Block(3,-32,-5,COBBLESTONE:0)
Block(3,-32,-4,COBBLESTONE:0)
Block(3,-32,-3,COBBLESTONE:0)
Block(3,-32,-2,COBBLESTONE:0)
Block(3,-31,-7,STONE:5)
Block(3,-31,-6,STONE:5)
Block(3,-31,-5,COBBLESTONE:0)
Block(3,-31,-4,COBBLESTONE:0)
Block(3,-31,-3,COBBLESTONE:0)
Block(3,-31,-2,COBBLESTONE:0)
Block(3,-30,-7,STONE:5)
Block(3,-30,-6,STONE:5)
Block(3,-30,-5,COBBLESTONE:0)
Block(3,-30,-4,COBBLESTONE:0)
Block(3,-30,-3,COBBLESTONE:0)
Block(3,-30,-2,COBBLESTONE:0)
Block(3,-29,-7,STONE:5)
Block(3,-29,-6,STONE:5)
Block(3,-29,-5,COBBLESTONE:0)
Block(3,-29,-4,COBBLESTONE:0)
Block(3,-29,-3,COBBLESTONE:0)
Block(3,-29,-2,COBBLESTONE:0)
Block(3,-28,-7,STONE:5)
Block(3,-28,-6,STONE:5)
Block(3,-28,-5,COBBLESTONE:0)
Block(3,-28,-4,COBBLESTONE:0)
Block(3,-28,-3,COBBLESTONE:0)
Block(3,-28,-2,COBBLESTONE:0)
Block(3,-27,-7,STONE:5)
Block(3,-27,-6,STONE:5)
Block(3,-27,-5,COBBLESTONE:0)
Block(3,-27,-4,COBBLESTONE:0)
Block(3,-27,-3,COBBLESTONE:0)
Block(3,-27,-2,COBBLESTONE:0)
Block(3,-26,-7,STONE:5)
Block(3,-26,-6,STONE:5)
Block(3,-26,-5,COBBLESTONE:0)
Block(3,-26,-4,COBBLESTONE:0)
Block(3,-26,-3,COBBLESTONE:0)
Block(3,-26,-2,COBBLESTONE:0)
Block(3,-25,-7,STONE:5)
Block(3,-25,-6,STONE:5)
Block(3,-25,-5,COBBLESTONE:0)
Block(3,-25,-4,COBBLESTONE:0)
Block(3,-25,-3,COBBLESTONE:0)
Block(3,-25,-2,COBBLESTONE:0)
Block(3,-24,-7,STONE:5)
Block(3,-24,-6,STONE:5)
Block(3,-24,-5,COBBLESTONE:0)
Block(3,-24,-4,COBBLESTONE:0)
Block(3,-24,-3,COBBLESTONE:0)
Block(3,-24,-2,COBBLESTONE:0)
Block(3,-23,-7,STONE:5)
Block(3,-23,-6,STONE:5)
Block(3,-23,-5,COBBLESTONE:0)
Block(3,-23,-4,COBBLESTONE:0)
Block(3,-23,-3,COBBLESTONE:0)
Block(3,-23,-2,COBBLESTONE:0)
Block(3,-22,-7,STONE:5)
Block(3,-22,-6,STONE:5)
Block(3,-22,-5,COBBLESTONE:0)
Block(3,-22,-4,COBBLESTONE:0)
Block(3,-22,-3,COBBLESTONE:0)
Block(3,-22,-2,COBBLESTONE:0)
Block(3,-21,-7,STONE:5)
Block(3,-21,-6,STONE:5)
Block(3,-21,-5,COBBLESTONE:0)
Block(3,-21,-4,COBBLESTONE:0)
Block(3,-21,-3,COBBLESTONE:0)
Block(3,-21,-2,COBBLESTONE:0)
Block(3,-20,-7,STONE:5)
Block(3,-20,-6,STONE:5)
Block(3,-20,-5,COBBLESTONE:0)
Block(3,-20,-4,COBBLESTONE:0)
Block(3,-20,-3,COBBLESTONE:0)
Block(3,-20,-2,COBBLESTONE:0)
Block(3,-19,-7,STONE:5)
Block(3,-19,-6,COBBLESTONE:0)
Block(3,-19,-5,COBBLESTONE:0)
Block(3,-19,-4,STONE:5)
Block(3,-19,-3,COBBLESTONE:0)
Block(3,-19,-2,STONE:5)
Block(3,-18,-7,SMOOTH_BRICK:2)
Block(3,-18,-6,COBBLESTONE:0)
Block(3,-18,-5,STONE:5)
Block(3,-18,-4,COBBLESTONE:0)
Block(3,-18,-3,STONE:5)
Block(3,-18,-2,STONE:5)
Block(3,-17,-7,STONE:5)
Block(3,-17,-6,STONE:5)
Block(3,-17,-5,STONE:5)
Block(3,-17,-4,COBBLESTONE:0)
Block(3,-17,-3,STAINED_CLAY:9)
Block(3,-17,-2,COBBLESTONE:0)
Block(3,-16,-7,SMOOTH_BRICK:1)
Block(3,-16,-6,STAINED_CLAY:9)
Block(3,-16,-5,STAINED_CLAY:9)
Block(3,-16,-4,COBBLESTONE:0)
Block(3,-16,-3,SMOOTH_BRICK:0)
Block(3,-16,-2,STONE:5)
Block(3,-15,-7,COBBLESTONE:0)
Block(3,-15,-6,COBBLESTONE:0)
Block(3,-15,-5,STONE:5)
Block(3,-15,-4,SMOOTH_BRICK:1)
Block(3,-15,-3,STONE:5)
Block(3,-15,-2,SMOOTH_BRICK:1)
Block(3,-14,-7,STONE:5)
Block(3,-14,-6,COBBLESTONE:0)
Block(3,-14,-5,COBBLESTONE:0)
Block(3,-14,-4,STONE:5)
Block(3,-14,-3,COBBLESTONE:0)
Block(3,-14,-2,STONE:5)
Block(3,-13,-7,STONE:5)
Block(3,-13,-6,COBBLESTONE:0)
Block(3,-13,-5,COBBLESTONE:0)
Block(3,-13,-4,SMOOTH_BRICK:0)
Block(3,-13,-3,STONE:5)
Block(3,-13,-2,COBBLESTONE:0)
Block(3,-12,-7,STAINED_CLAY:9)
Block(3,-12,-6,COBBLESTONE:0)
Block(3,-12,-5,COBBLESTONE:0)
Block(3,-12,-4,STONE:5)
Block(3,-12,-3,COBBLESTONE:0)
Block(3,-12,-2,COBBLESTONE:0)
Block(3,-11,-7,COBBLESTONE:0)
Block(3,-11,-6,STONE:5)
Block(3,-11,-5,STONE:5)
Block(3,-11,-4,STONE:5)
Block(3,-11,-3,STONE:5)
Block(3,-11,-2,SMOOTH_BRICK:1)
Block(3,-10,-7,STAINED_CLAY:9)
Block(3,-10,-6,SMOOTH_BRICK:1)
Block(3,-10,-5,SMOOTH_BRICK:1)
Block(3,-10,-4,STONE:5)
Block(3,-10,-3,SMOOTH_BRICK:0)
Block(3,-10,-2,SMOOTH_BRICK:1)
Block(3,-9,-7,STONE:6)
Block(3,-9,-6,STONE:6)
Block(3,-9,-5,STONE:6)
Block(3,-9,-4,STONE:6)
Block(3,-9,-3,COBBLESTONE_STAIRS:3)
Block(3,-9,-2,COBBLESTONE_STAIRS:0)
Block(3,-8,-7,STONE:6)
Block(3,-8,-6,STONE:6)
Block(3,-8,-5,STONE:6)
Block(3,-8,-4,STONE:6)
Block(3,-7,-7,STONE:6)
Block(3,-7,-6,STONE:6)
Block(3,-7,-5,STONE:6)
Block(3,-7,-4,STONE:6)
Block(3,-6,-7,STONE:6)
Block(3,-6,-6,STONE:6)
Block(3,-6,-5,STONE:6)
Block(3,-6,-4,STONE:6)
Block(3,-5,-7,STONE:5)
Block(3,-5,-6,COBBLESTONE:0)
Block(3,-5,-5,COBBLESTONE:0)
Block(3,-5,-4,COBBLESTONE_STAIRS:3)
Block(3,-4,-7,STONE:6)
Block(3,-4,-6,STONE:6)
Block(3,-4,-5,LOG:4)
Block(3,-3,-7,STONE:6)
Block(3,-3,-6,STONE:6)
Block(3,-2,-7,STONE:6)
Block(3,-2,-6,STONE:6)
Block(3,-1,-7,STONE:6)
Block(3,-1,-6,COBBLESTONE_STAIRS:3)
Block(3,0,-7,STONE:6)
Block(3,1,-7,STONE:6)
Block(3,2,-7,STONE:6)
Block(3,3,-7,STONE:6)
Block(3,4,-7,STONE:6)
Block(3,5,-7,STONE:6)
Block(3,6,-7,LOG:0)
Block(3,7,-7,LOG:0)
Block(3,8,-7,LOG:0)
Block(3,9,-7,LOG:0)
Block(3,10,-7,LOG:0)
Block(3,11,-7,LOG:0)
Block(3,12,-7,LOG:0)
Block(3,13,-7,LOG:0)
Block(3,14,-7,LOG:0)
Block(3,15,-7,LOG:0)
Block(3,16,-7,LOG:0)
Block(3,17,-7,LOG:0)
Block(3,18,-7,LOG:0)
Block(3,19,-7,LOG:0)
Block(3,20,-7,WOOD_STEP:5)
Block(3,21,-7,AIR:0)
Block(3,22,-7,AIR:0)
Block(3,23,-7,AIR:0)
Block(3,24,-7,AIR:0)
Block(3,25,-7,AIR:0)
Block(3,26,-7,AIR:0)
Block(3,27,-7,AIR:0)
Block(3,28,-7,AIR:0)
Block(3,29,-7,AIR:0)
Block(3,30,-7,AIR:0)
Block(3,31,-7,AIR:0)
Block(3,32,-7,AIR:0)
Block(3,33,-7,AIR:0)
Block(3,34,-7,AIR:0)
Block(3,35,-7,AIR:0)
Block(3,36,-7,AIR:0)
Block(3,37,-7,AIR:0)
Block(3,38,-7,AIR:0)
Block(3,39,-7,AIR:0)
Block(3,40,-7,AIR:0)
Block(3,41,-7,AIR:0)
Block(3,42,-7,AIR:0)
Block(3,43,-7,AIR:0)
Block(3,44,-7,AIR:0)
Block(3,45,-7,AIR:0)
Block(3,46,-7,AIR:0)
Block(3,47,-7,AIR:0)
Block(3,48,-7,AIR:0)
Block(3,49,-7,AIR:0)
Block(3,50,-7,AIR:0)
Block(3,51,-7,AIR:0)
Block(3,52,-7,AIR:0)
Block(4,-50,-7,STONE:5)
Block(4,-50,-6,COBBLESTONE:0)
Block(4,-50,-5,COBBLESTONE:0)
Block(4,-50,-4,COBBLESTONE:0)
Block(4,-50,-3,COBBLESTONE:0)
Block(4,-50,-2,SMOOTH_BRICK:1)
Block(4,-50,-1,LOG:0)
Block(4,-49,-7,STONE:5)
Block(4,-49,-6,COBBLESTONE:0)
Block(4,-49,-5,COBBLESTONE:0)
Block(4,-49,-4,COBBLESTONE:0)
Block(4,-49,-3,COBBLESTONE:0)
Block(4,-49,-2,SMOOTH_BRICK:1)
Block(4,-49,-1,LOG:0)
Block(4,-48,-7,STONE:5)
Block(4,-48,-6,COBBLESTONE:0)
Block(4,-48,-5,COBBLESTONE:0)
Block(4,-48,-4,COBBLESTONE:0)
Block(4,-48,-3,COBBLESTONE:0)
Block(4,-48,-2,SMOOTH_BRICK:1)
Block(4,-48,-1,LOG:0)
Block(4,-47,-7,STONE:5)
Block(4,-47,-6,COBBLESTONE:0)
Block(4,-47,-5,COBBLESTONE:0)
Block(4,-47,-4,COBBLESTONE:0)
Block(4,-47,-3,COBBLESTONE:0)
Block(4,-47,-2,SMOOTH_BRICK:1)
Block(4,-47,-1,LOG:0)
Block(4,-46,-7,STONE:5)
Block(4,-46,-6,COBBLESTONE:0)
Block(4,-46,-5,COBBLESTONE:0)
Block(4,-46,-4,COBBLESTONE:0)
Block(4,-46,-3,COBBLESTONE:0)
Block(4,-46,-2,SMOOTH_BRICK:1)
Block(4,-46,-1,LOG:0)
Block(4,-45,-7,STONE:5)
Block(4,-45,-6,COBBLESTONE:0)
Block(4,-45,-5,COBBLESTONE:0)
Block(4,-45,-4,COBBLESTONE:0)
Block(4,-45,-3,COBBLESTONE:0)
Block(4,-45,-2,SMOOTH_BRICK:1)
Block(4,-45,-1,LOG:0)
Block(4,-44,-7,STONE:5)
Block(4,-44,-6,COBBLESTONE:0)
Block(4,-44,-5,COBBLESTONE:0)
Block(4,-44,-4,COBBLESTONE:0)
Block(4,-44,-3,COBBLESTONE:0)
Block(4,-44,-2,SMOOTH_BRICK:1)
Block(4,-44,-1,LOG:0)
Block(4,-43,-7,STONE:5)
Block(4,-43,-6,COBBLESTONE:0)
Block(4,-43,-5,COBBLESTONE:0)
Block(4,-43,-4,COBBLESTONE:0)
Block(4,-43,-3,COBBLESTONE:0)
Block(4,-43,-2,SMOOTH_BRICK:1)
Block(4,-43,-1,LOG:0)
Block(4,-42,-7,STONE:5)
Block(4,-42,-6,COBBLESTONE:0)
Block(4,-42,-5,COBBLESTONE:0)
Block(4,-42,-4,COBBLESTONE:0)
Block(4,-42,-3,COBBLESTONE:0)
Block(4,-42,-2,SMOOTH_BRICK:1)
Block(4,-42,-1,LOG:0)
Block(4,-41,-7,STONE:5)
Block(4,-41,-6,COBBLESTONE:0)
Block(4,-41,-5,COBBLESTONE:0)
Block(4,-41,-4,COBBLESTONE:0)
Block(4,-41,-3,COBBLESTONE:0)
Block(4,-41,-2,SMOOTH_BRICK:1)
Block(4,-41,-1,LOG:0)
Block(4,-40,-7,STONE:5)
Block(4,-40,-6,COBBLESTONE:0)
Block(4,-40,-5,COBBLESTONE:0)
Block(4,-40,-4,COBBLESTONE:0)
Block(4,-40,-3,COBBLESTONE:0)
Block(4,-40,-2,SMOOTH_BRICK:1)
Block(4,-40,-1,LOG:0)
Block(4,-39,-7,STONE:5)
Block(4,-39,-6,COBBLESTONE:0)
Block(4,-39,-5,COBBLESTONE:0)
Block(4,-39,-4,COBBLESTONE:0)
Block(4,-39,-3,COBBLESTONE:0)
Block(4,-39,-2,SMOOTH_BRICK:1)
Block(4,-39,-1,LOG:0)
Block(4,-38,-7,STONE:5)
Block(4,-38,-6,COBBLESTONE:0)
Block(4,-38,-5,COBBLESTONE:0)
Block(4,-38,-4,COBBLESTONE:0)
Block(4,-38,-3,COBBLESTONE:0)
Block(4,-38,-2,SMOOTH_BRICK:1)
Block(4,-38,-1,LOG:0)
Block(4,-37,-7,STONE:5)
Block(4,-37,-6,COBBLESTONE:0)
Block(4,-37,-5,COBBLESTONE:0)
Block(4,-37,-4,COBBLESTONE:0)
Block(4,-37,-3,COBBLESTONE:0)
Block(4,-37,-2,SMOOTH_BRICK:1)
Block(4,-37,-1,LOG:0)
Block(4,-36,-7,STONE:5)
Block(4,-36,-6,COBBLESTONE:0)
Block(4,-36,-5,COBBLESTONE:0)
Block(4,-36,-4,COBBLESTONE:0)
Block(4,-36,-3,COBBLESTONE:0)
Block(4,-36,-2,SMOOTH_BRICK:1)
Block(4,-36,-1,LOG:0)
Block(4,-35,-7,STONE:5)
Block(4,-35,-6,COBBLESTONE:0)
Block(4,-35,-5,COBBLESTONE:0)
Block(4,-35,-4,COBBLESTONE:0)
Block(4,-35,-3,COBBLESTONE:0)
Block(4,-35,-2,SMOOTH_BRICK:1)
Block(4,-35,-1,LOG:0)
Block(4,-34,-7,STONE:5)
Block(4,-34,-6,COBBLESTONE:0)
Block(4,-34,-5,COBBLESTONE:0)
Block(4,-34,-4,COBBLESTONE:0)
Block(4,-34,-3,COBBLESTONE:0)
Block(4,-34,-2,SMOOTH_BRICK:1)
Block(4,-34,-1,LOG:0)
Block(4,-33,-7,STONE:5)
Block(4,-33,-6,COBBLESTONE:0)
Block(4,-33,-5,COBBLESTONE:0)
Block(4,-33,-4,COBBLESTONE:0)
Block(4,-33,-3,COBBLESTONE:0)
Block(4,-33,-2,SMOOTH_BRICK:1)
Block(4,-33,-1,LOG:0)
Block(4,-32,-7,STONE:5)
Block(4,-32,-6,COBBLESTONE:0)
Block(4,-32,-5,COBBLESTONE:0)
Block(4,-32,-4,COBBLESTONE:0)
Block(4,-32,-3,COBBLESTONE:0)
Block(4,-32,-2,SMOOTH_BRICK:1)
Block(4,-32,-1,LOG:0)
Block(4,-31,-7,STONE:5)
Block(4,-31,-6,COBBLESTONE:0)
Block(4,-31,-5,COBBLESTONE:0)
Block(4,-31,-4,COBBLESTONE:0)
Block(4,-31,-3,COBBLESTONE:0)
Block(4,-31,-2,SMOOTH_BRICK:1)
Block(4,-31,-1,LOG:0)
Block(4,-30,-7,STONE:5)
Block(4,-30,-6,COBBLESTONE:0)
Block(4,-30,-5,COBBLESTONE:0)
Block(4,-30,-4,COBBLESTONE:0)
Block(4,-30,-3,COBBLESTONE:0)
Block(4,-30,-2,SMOOTH_BRICK:1)
Block(4,-30,-1,LOG:0)
Block(4,-29,-7,STONE:5)
Block(4,-29,-6,COBBLESTONE:0)
Block(4,-29,-5,COBBLESTONE:0)
Block(4,-29,-4,COBBLESTONE:0)
Block(4,-29,-3,COBBLESTONE:0)
Block(4,-29,-2,SMOOTH_BRICK:1)
Block(4,-29,-1,LOG:0)
Block(4,-28,-7,STONE:5)
Block(4,-28,-6,COBBLESTONE:0)
Block(4,-28,-5,COBBLESTONE:0)
Block(4,-28,-4,COBBLESTONE:0)
Block(4,-28,-3,COBBLESTONE:0)
Block(4,-28,-2,SMOOTH_BRICK:1)
Block(4,-28,-1,LOG:0)
Block(4,-27,-7,STONE:5)
Block(4,-27,-6,COBBLESTONE:0)
Block(4,-27,-5,COBBLESTONE:0)
Block(4,-27,-4,COBBLESTONE:0)
Block(4,-27,-3,COBBLESTONE:0)
Block(4,-27,-2,SMOOTH_BRICK:1)
Block(4,-27,-1,LOG:0)
Block(4,-26,-7,STONE:5)
Block(4,-26,-6,COBBLESTONE:0)
Block(4,-26,-5,COBBLESTONE:0)
Block(4,-26,-4,COBBLESTONE:0)
Block(4,-26,-3,COBBLESTONE:0)
Block(4,-26,-2,SMOOTH_BRICK:1)
Block(4,-26,-1,LOG:0)
Block(4,-25,-7,STONE:5)
Block(4,-25,-6,COBBLESTONE:0)
Block(4,-25,-5,COBBLESTONE:0)
Block(4,-25,-4,COBBLESTONE:0)
Block(4,-25,-3,COBBLESTONE:0)
Block(4,-25,-2,SMOOTH_BRICK:1)
Block(4,-25,-1,LOG:0)
Block(4,-24,-7,STONE:5)
Block(4,-24,-6,COBBLESTONE:0)
Block(4,-24,-5,COBBLESTONE:0)
Block(4,-24,-4,COBBLESTONE:0)
Block(4,-24,-3,COBBLESTONE:0)
Block(4,-24,-2,SMOOTH_BRICK:1)
Block(4,-24,-1,LOG:0)
Block(4,-23,-7,STONE:5)
Block(4,-23,-6,COBBLESTONE:0)
Block(4,-23,-5,COBBLESTONE:0)
Block(4,-23,-4,COBBLESTONE:0)
Block(4,-23,-3,COBBLESTONE:0)
Block(4,-23,-2,SMOOTH_BRICK:1)
Block(4,-23,-1,LOG:0)
Block(4,-22,-7,STONE:5)
Block(4,-22,-6,COBBLESTONE:0)
Block(4,-22,-5,COBBLESTONE:0)
Block(4,-22,-4,COBBLESTONE:0)
Block(4,-22,-3,COBBLESTONE:0)
Block(4,-22,-2,SMOOTH_BRICK:1)
Block(4,-22,-1,LOG:0)
Block(4,-21,-7,STONE:5)
Block(4,-21,-6,COBBLESTONE:0)
Block(4,-21,-5,COBBLESTONE:0)
Block(4,-21,-4,COBBLESTONE:0)
Block(4,-21,-3,COBBLESTONE:0)
Block(4,-21,-2,SMOOTH_BRICK:1)
Block(4,-21,-1,LOG:0)
Block(4,-20,-7,STONE:5)
Block(4,-20,-6,COBBLESTONE:0)
Block(4,-20,-5,COBBLESTONE:0)
Block(4,-20,-4,COBBLESTONE:0)
Block(4,-20,-3,COBBLESTONE:0)
Block(4,-20,-2,SMOOTH_BRICK:1)
Block(4,-20,-1,LOG:0)
Block(4,-19,-7,STONE:5)
Block(4,-19,-6,STONE:5)
Block(4,-19,-5,COBBLESTONE:0)
Block(4,-19,-4,COBBLESTONE:0)
Block(4,-19,-3,STONE:5)
Block(4,-19,-2,STONE:5)
Block(4,-19,-1,LOG:0)
Block(4,-18,-7,STONE:5)
Block(4,-18,-6,COBBLESTONE:0)
Block(4,-18,-5,COBBLESTONE:0)
Block(4,-18,-4,STONE:5)
Block(4,-18,-3,COBBLESTONE:0)
Block(4,-18,-2,SMOOTH_BRICK:2)
Block(4,-18,-1,LOG:0)
Block(4,-17,-7,COBBLESTONE:0)
Block(4,-17,-6,STONE:5)
Block(4,-17,-5,COBBLESTONE:0)
Block(4,-17,-4,COBBLESTONE:0)
Block(4,-17,-3,COBBLESTONE:0)
Block(4,-17,-2,COBBLESTONE:0)
Block(4,-17,-1,LOG:0)
Block(4,-16,-7,SMOOTH_BRICK:2)
Block(4,-16,-6,STONE:5)
Block(4,-16,-5,COBBLESTONE:0)
Block(4,-16,-4,COBBLESTONE:0)
Block(4,-16,-3,STAINED_CLAY:9)
Block(4,-16,-2,STONE:5)
Block(4,-16,-1,LOG:0)
Block(4,-15,-7,STONE:5)
Block(4,-15,-6,COBBLESTONE:0)
Block(4,-15,-5,COBBLESTONE:0)
Block(4,-15,-4,STONE:5)
Block(4,-15,-3,SMOOTH_BRICK:1)
Block(4,-15,-2,COBBLESTONE:0)
Block(4,-15,-1,LOG:0)
Block(4,-14,-7,STONE:5)
Block(4,-14,-6,COBBLESTONE:0)
Block(4,-14,-5,SMOOTH_BRICK:0)
Block(4,-14,-4,SMOOTH_BRICK:1)
Block(4,-14,-3,STONE:5)
Block(4,-14,-2,COBBLESTONE:0)
Block(4,-14,-1,LOG:0)
Block(4,-13,-7,STONE:5)
Block(4,-13,-6,STONE:5)
Block(4,-13,-5,COBBLESTONE:0)
Block(4,-13,-4,STAINED_CLAY:9)
Block(4,-13,-3,STONE:5)
Block(4,-13,-2,STONE:5)
Block(4,-13,-1,LOG:0)
Block(4,-12,-7,SMOOTH_BRICK:2)
Block(4,-12,-6,STONE:5)
Block(4,-12,-5,STONE:5)
Block(4,-12,-4,STONE:5)
Block(4,-12,-3,COBBLESTONE:0)
Block(4,-12,-2,STONE:5)
Block(4,-12,-1,LOG:0)
Block(4,-11,-7,SMOOTH_BRICK:1)
Block(4,-11,-6,COBBLESTONE:0)
Block(4,-11,-5,COBBLESTONE:0)
Block(4,-11,-4,SMOOTH_BRICK:0)
Block(4,-11,-3,STONE:5)
Block(4,-11,-2,COBBLESTONE:0)
Block(4,-11,-1,LOG:0)
Block(4,-10,-7,STONE:5)
Block(4,-10,-6,SMOOTH_BRICK:0)
Block(4,-10,-5,COBBLESTONE:0)
Block(4,-10,-4,COBBLESTONE:0)
Block(4,-10,-3,STONE:5)
Block(4,-10,-2,STONE:5)
Block(4,-10,-1,LOG:0)
Block(4,-9,-7,STONE:6)
Block(4,-9,-6,STONE:6)
Block(4,-9,-5,STONE:6)
Block(4,-9,-4,STONE:6)
Block(4,-9,-3,STONE:6)
Block(4,-9,-2,COBBLESTONE_STAIRS:3)
Block(4,-9,-1,SMOOTH_STAIRS:0)
Block(4,-8,-7,STONE:6)
Block(4,-8,-6,STONE:6)
Block(4,-8,-5,STONE:6)
Block(4,-8,-4,STONE:6)
Block(4,-8,-3,STONE:6)
Block(4,-7,-7,STONE:6)
Block(4,-7,-6,STONE:6)
Block(4,-7,-5,STONE:6)
Block(4,-7,-4,STONE:6)
Block(4,-7,-3,STONE:6)
Block(4,-6,-7,STONE:6)
Block(4,-6,-6,STONE:6)
Block(4,-6,-5,STONE:6)
Block(4,-6,-4,STONE:6)
Block(4,-6,-3,STONE:6)
Block(4,-5,-7,STAINED_CLAY:9)
Block(4,-5,-6,STONE:5)
Block(4,-5,-5,STONE:5)
Block(4,-5,-4,COBBLESTONE_STAIRS:3)
Block(4,-5,-3,COBBLESTONE_STAIRS:0)
Block(4,-4,-7,STONE:6)
Block(4,-4,-6,STONE:6)
Block(4,-4,-5,LOG:0)
Block(4,-3,-7,STONE:6)
Block(4,-3,-6,STONE:6)
Block(4,-3,-5,LOG:0)
Block(4,-2,-7,STONE:6)
Block(4,-2,-6,STONE:6)
Block(4,-2,-5,LOG:0)
Block(4,-1,-7,STONE:6)
Block(4,-1,-6,STONE:6)
Block(4,-1,-5,LOG:0)
Block(4,0,-7,STONE:6)
Block(4,0,-6,STONE:6)
Block(4,0,-5,LOG:0)
Block(4,1,-7,STONE:6)
Block(4,1,-6,STONE:6)
Block(4,1,-5,LOG:0)
Block(4,2,-7,STONE:6)
Block(4,2,-6,STONE:6)
Block(4,2,-5,LOG:0)
Block(4,3,-7,STONE:6)
Block(4,3,-6,STONE:6)
Block(4,3,-5,LOG:0)
Block(4,4,-7,STONE:6)
Block(4,4,-6,STONE:6)
Block(4,4,-5,LOG:0)
Block(4,5,-7,STONE:6)
Block(4,5,-6,STONE:6)
Block(4,5,-5,LOG:0)
Block(4,6,-7,COBBLESTONE_STAIRS:0)
Block(4,6,-6,DARK_OAK_FENCE:0)
Block(4,6,-5,LOG:0)
Block(4,7,-7,COBBLESTONE_STAIRS:7)
Block(4,7,-6,AIR:0)
Block(4,7,-5,LOG:0)
Block(4,8,-7,SMOOTH_BRICK:0)
Block(4,8,-6,DARK_OAK_STAIRS:4)
Block(4,8,-5,LOG:0)
Block(4,9,-7,SMOOTH_BRICK:0)
Block(4,9,-6,SMOOTH_BRICK:0)
Block(4,9,-5,LOG:0)
Block(4,10,-7,SMOOTH_STAIRS:0)
Block(4,10,-6,SMOOTH_BRICK:0)
Block(4,10,-5,LOG:0)
Block(4,11,-7,SMOOTH_STAIRS:0)
Block(4,11,-6,SMOOTH_BRICK:0)
Block(4,11,-5,LOG:0)
Block(4,12,-7,SMOOTH_STAIRS:0)
Block(4,12,-6,SMOOTH_BRICK:0)
Block(4,12,-5,LOG:0)
Block(4,13,-7,LOG:8)
Block(4,13,-6,LOG:8)
Block(4,13,-5,LOG:0)
RandomBlock(4,14,-7,AIR:0,20,CHEST:5,../../../Chests/Loot/JunkChest_1.nbt,10,CHEST:5,../../../Chests/Loot/JunkChest_2.nbt,10,CHEST:5,../../../Chests/Loot/JunkChest_3.nbt,10,CHEST:5,../../../Chests/Loot/JunkChest_4.nbt,10,CHEST:5,../../../Chests/Loot/JunkChest_5.nbt,10,CHEST:5,../../../Chests/Lore/medievalcity_1.nbt,1,CHEST:5,../../../Chests/Lore/medievalcity_2.nbt,1,CHEST:5,../../../Chests/Lore/medievalcity_3.nbt,1,CHEST:5,../../../Chests/Lore/medievalcity_4.nbt,1,CHEST:5,../../../Chests/Lore/medievalcity_5.nbt,1,CHEST:5,../../../Chests/Loot/Common1.nbt,10,CHEST:5,../../../Chests/Loot/Common2.nbt,10,CHEST:5,../../../Chests/Loot/Common3.nbt,10,CHEST:5,../../../Chests/Loot/Common4.nbt,10,CHEST:5,../../../Chests/Loot/Common5.nbt,10,CHEST:5,../../../Chests/Loot/Common6.nbt,10,CHEST:5,../../../Chests/Loot/Common7.nbt,10,CHEST:5,../../../Chests/Loot/Common8.nbt,10,CHEST:5,../../../Chests/Loot/Common9.nbt,10,CHEST:5,../../../Chests/Loot/Common10.nbt,10,CHEST:5,../../../Chests/Loot/Common10.nbt,11,CHEST:5,../../../Chests/Loot/Common12.nbt,10,CHEST:5,../../../Chests/Loot/Common13.nbt,10,CHEST:5,../../../Chests/Loot/Common14.nbt,10,CHEST:5,../../../Chests/Loot/Common15.nbt,10,CHEST:5,../../../Chests/Lore/medievalcity_1.nbt,2,CHEST:5,../../../Chests/Lore/medievalcity_3.nbt,2,CHEST:5,../../../Chests/Lore/medievalcity_4.nbt,2,CHEST:5,../../../Chests/Lore/medievalcity_5.nbt,2,CHEST:5,../../../Chests/Lore/medievalcity_5.nbt,2,CHEST:5,../../../Chests/Loot/Rare1.nbt,5,CHEST:5,../../../Chests/Loot/Rare2.nbt,5,CHEST:5,../../../Chests/Loot/Rare3.nbt,5,CHEST:5,../../../Chests/Loot/Rare4.nbt,5,CHEST:5,../../../Chests/Loot/Rare5.nbt,5,CHEST:5,../../../Chests/Loot/Rare6.nbt,5,CHEST:5,../../../Chests/Loot/Rare7.nbt,5,CHEST:5,../../../Chests/Loot/Rare8.nbt,5,CHEST:5,../../../Chests/Loot/Rare9.nbt,5,CHEST:5,../../../Chests/Loot/Rare10.nbt,5,CHEST:5,../../../Chests/Loot/Rare11.nbt,5,CHEST:5,../../../Chests/Loot/Rare12.nbt,5,CHEST:5,../../../Chests/Loot/Rare13.nbt,5,CHEST:5,../../../Chests/Loot/Rare14.nbt,5,CHEST:5,../../../Chests/Loot/Rare15.nbt,5,CHEST:5,../../../Chests/Loot/Epic1.nbt,2,CHEST:5,../../../Chests/Loot/Epic2.nbt,2,CHEST:5,../../../Chests/Loot/Epic3.nbt,2,CHEST:5,../../../Chests/Loot/Epic4.nbt,2,CHEST:5,../../../Chests/Loot/Epic5.nbt,2,CHEST:5,../../../Chests/Loot/Epic6.nbt,2,CHEST:5,../../../Chests/Loot/Epic7.nbt,2,CHEST:5,../../../Chests/Loot/Epic8.nbt,2,CHEST:5,../../../Chests/Loot/Epic9.nbt,2,CHEST:5,../../../Chests/Loot/Epic10.nbt,2,CHEST:5,../../../Chests/Loot/Epic11.nbt,2,CHEST:5,../../../Chests/Loot/Epic12.nbt,2,CHEST:5,../../../Chests/Loot/Epic13.nbt,2,CHEST:5,../../../Chests/Loot/Epic14.nbt,2,CHEST:5,../../../Chests/Loot/Epic15.nbt,5,CHEST:5,../../../Chests/Loot/Rare1.nbt,5,CHEST:5,../../../Chests/Loot/Rare2.nbt,5,CHEST:5,../../../Chests/Loot/Rare3.nbt,5,CHEST:5,../../../Chests/Loot/Rare4.nbt,5,CHEST:5,../../../Chests/Loot/Rare5.nbt,10,CHEST:5,../../../Chests/Loot/Rare6.nbt,10,CHEST:5,../../../Chests/Loot/Rare7.nbt,10,CHEST:5,../../../Chests/Loot/Rare8.nbt,10,CHEST:5,../../../Chests/Loot/Rare9.nbt,10,CHEST:5,../../../Chests/Loot/Rare10.nbt,15,CHEST:5,../../../Chests/Loot/Rare11.nbt,15,CHEST:5,../../../Chests/Loot/Rare12.nbt,15,CHEST:5,../../../Chests/Loot/Rare13.nbt,15,CHEST:5,../../../Chests/Loot/Rare14.nbt,15,CHEST:5,../../../Chests/Loot/Rare15.nbt,15,CHEST:5,../../../Chests/Loot/Epic15.nbt,100)
Block(4,14,-6,STONE:6)
Block(4,14,-5,LOG:0)
Block(4,15,-7,AIR:0)
Block(4,15,-6,STONE:6)
Block(4,15,-5,LOG:0)
Block(4,16,-7,AIR:0)
Block(4,16,-6,STONE:6)
Block(4,16,-5,LOG:0)
Block(4,17,-7,AIR:0)
Block(4,17,-6,STONE:6)
Block(4,17,-5,LOG:0)
Block(4,18,-7,WOOD_STEP:13)
Block(4,18,-6,STONE:6)
Block(4,18,-5,LOG:0)
Block(4,19,-7,AIR:0)
Block(4,19,-6,STEP:5)
Block(4,19,-5,LOG:0)
Block(4,20,-7,AIR:0)
Block(4,20,-6,AIR:0)
Block(4,20,-5,WOOD_STEP:5)
Block(4,21,-7,AIR:0)
Block(4,21,-6,AIR:0)
Block(4,21,-5,AIR:0)
Block(4,22,-7,AIR:0)
Block(4,22,-6,AIR:0)
Block(4,22,-5,AIR:0)
Block(4,23,-7,AIR:0)
Block(4,23,-6,AIR:0)
Block(4,23,-5,AIR:0)
Block(4,24,-7,AIR:0)
Block(4,24,-6,AIR:0)
Block(4,24,-5,AIR:0)
Block(4,25,-7,AIR:0)
Block(4,25,-6,AIR:0)
Block(4,25,-5,AIR:0)
Block(4,26,-7,AIR:0)
Block(4,26,-6,AIR:0)
Block(4,26,-5,AIR:0)
Block(4,27,-7,AIR:0)
Block(4,27,-6,AIR:0)
Block(4,27,-5,AIR:0)
Block(4,28,-7,AIR:0)
Block(4,28,-6,AIR:0)
Block(4,28,-5,AIR:0)
Block(4,29,-7,AIR:0)
Block(4,29,-6,AIR:0)
Block(4,29,-5,AIR:0)
Block(4,30,-7,AIR:0)
Block(4,30,-6,AIR:0)
Block(4,30,-5,AIR:0)
Block(4,31,-7,AIR:0)
Block(4,31,-6,AIR:0)
Block(4,31,-5,AIR:0)
Block(4,32,-7,AIR:0)
Block(4,32,-6,AIR:0)
Block(4,32,-5,AIR:0)
Block(4,33,-7,AIR:0)
Block(4,33,-6,AIR:0)
Block(4,33,-5,AIR:0)
Block(4,34,-7,AIR:0)
Block(4,34,-6,AIR:0)
Block(4,34,-5,AIR:0)
Block(4,35,-7,AIR:0)
Block(4,35,-6,AIR:0)
Block(4,35,-5,AIR:0)
Block(4,36,-7,AIR:0)
Block(4,36,-6,AIR:0)
Block(4,36,-5,AIR:0)
Block(4,37,-7,AIR:0)
Block(4,37,-6,AIR:0)
Block(4,37,-5,AIR:0)
Block(4,38,-7,AIR:0)
Block(4,38,-6,AIR:0)
Block(4,38,-5,AIR:0)
Block(4,39,-7,AIR:0)
Block(4,39,-6,AIR:0)
Block(4,39,-5,AIR:0)
Block(4,40,-7,AIR:0)
Block(4,40,-6,AIR:0)
Block(4,40,-5,AIR:0)
Block(4,41,-7,AIR:0)
Block(4,41,-6,AIR:0)
Block(4,41,-5,AIR:0)
Block(4,42,-7,AIR:0)
Block(4,42,-6,AIR:0)
Block(4,42,-5,AIR:0)
Block(4,43,-7,AIR:0)
Block(4,43,-6,AIR:0)
Block(4,43,-5,AIR:0)
Block(4,44,-7,AIR:0)
Block(4,44,-6,AIR:0)
Block(4,44,-5,AIR:0)
Block(4,45,-7,AIR:0)
Block(4,45,-6,AIR:0)
Block(4,45,-5,AIR:0)
Block(4,46,-7,AIR:0)
Block(4,46,-6,AIR:0)
Block(4,46,-5,AIR:0)
Block(4,47,-7,AIR:0)
Block(4,47,-6,AIR:0)
Block(4,47,-5,AIR:0)
Block(4,48,-7,AIR:0)
Block(4,48,-6,AIR:0)
Block(4,48,-5,AIR:0)
Block(4,49,-7,AIR:0)
Block(4,49,-6,AIR:0)
Block(4,49,-5,AIR:0)
Block(4,50,-7,AIR:0)
Block(4,50,-6,AIR:0)
Block(4,50,-5,AIR:0)
Block(4,51,-7,AIR:0)
Block(4,51,-6,AIR:0)
Block(4,51,-5,AIR:0)
Block(4,52,-7,AIR:0)
Block(4,52,-6,AIR:0)
Block(4,52,-5,AIR:0)
Block(5,-50,-7,STONE:5)
Block(5,-50,-6,COBBLESTONE:0)
Block(5,-50,-5,COBBLESTONE:0)
Block(5,-50,-4,STONE:5)
Block(5,-50,-3,SMOOTH_BRICK:1)
Block(5,-50,-2,STONE:5)
Block(5,-50,-1,STONE:5)
Block(5,-50,0,SMOOTH_BRICK:1)
Block(5,-49,-7,STONE:5)
Block(5,-49,-6,COBBLESTONE:0)
Block(5,-49,-5,COBBLESTONE:0)
Block(5,-49,-4,STONE:5)
Block(5,-49,-3,SMOOTH_BRICK:1)
Block(5,-49,-2,STONE:5)
Block(5,-49,-1,STONE:5)
Block(5,-49,0,SMOOTH_BRICK:1)
Block(5,-48,-7,STONE:5)
Block(5,-48,-6,COBBLESTONE:0)
Block(5,-48,-5,COBBLESTONE:0)
Block(5,-48,-4,STONE:5)
Block(5,-48,-3,SMOOTH_BRICK:1)
Block(5,-48,-2,STONE:5)
Block(5,-48,-1,STONE:5)
Block(5,-48,0,SMOOTH_BRICK:1)
Block(5,-47,-7,STONE:5)
Block(5,-47,-6,COBBLESTONE:0)
Block(5,-47,-5,COBBLESTONE:0)
Block(5,-47,-4,STONE:5)
Block(5,-47,-3,SMOOTH_BRICK:1)
Block(5,-47,-2,STONE:5)
Block(5,-47,-1,STONE:5)
Block(5,-47,0,SMOOTH_BRICK:1)
Block(5,-46,-7,STONE:5)
Block(5,-46,-6,COBBLESTONE:0)
Block(5,-46,-5,COBBLESTONE:0)
Block(5,-46,-4,STONE:5)
Block(5,-46,-3,SMOOTH_BRICK:1)
Block(5,-46,-2,STONE:5)
Block(5,-46,-1,STONE:5)
Block(5,-46,0,SMOOTH_BRICK:1)
Block(5,-45,-7,STONE:5)
Block(5,-45,-6,COBBLESTONE:0)
Block(5,-45,-5,COBBLESTONE:0)
Block(5,-45,-4,STONE:5)
Block(5,-45,-3,SMOOTH_BRICK:1)
Block(5,-45,-2,STONE:5)
Block(5,-45,-1,STONE:5)
Block(5,-45,0,SMOOTH_BRICK:1)
Block(5,-44,-7,STONE:5)
Block(5,-44,-6,COBBLESTONE:0)
Block(5,-44,-5,COBBLESTONE:0)
Block(5,-44,-4,STONE:5)
Block(5,-44,-3,SMOOTH_BRICK:1)
Block(5,-44,-2,STONE:5)
Block(5,-44,-1,STONE:5)
Block(5,-44,0,SMOOTH_BRICK:1)
Block(5,-43,-7,STONE:5)
Block(5,-43,-6,COBBLESTONE:0)
Block(5,-43,-5,COBBLESTONE:0)
Block(5,-43,-4,STONE:5)
Block(5,-43,-3,SMOOTH_BRICK:1)
Block(5,-43,-2,STONE:5)
Block(5,-43,-1,STONE:5)
Block(5,-43,0,SMOOTH_BRICK:1)
Block(5,-42,-7,STONE:5)
Block(5,-42,-6,COBBLESTONE:0)
Block(5,-42,-5,COBBLESTONE:0)
Block(5,-42,-4,STONE:5)
Block(5,-42,-3,SMOOTH_BRICK:1)
Block(5,-42,-2,STONE:5)
Block(5,-42,-1,STONE:5)
Block(5,-42,0,SMOOTH_BRICK:1)
Block(5,-41,-7,STONE:5)
Block(5,-41,-6,COBBLESTONE:0)
Block(5,-41,-5,COBBLESTONE:0)
Block(5,-41,-4,STONE:5)
Block(5,-41,-3,SMOOTH_BRICK:1)
Block(5,-41,-2,STONE:5)
Block(5,-41,-1,STONE:5)
Block(5,-41,0,SMOOTH_BRICK:1)
Block(5,-40,-7,STONE:5)
Block(5,-40,-6,COBBLESTONE:0)
Block(5,-40,-5,COBBLESTONE:0)
Block(5,-40,-4,STONE:5)
Block(5,-40,-3,SMOOTH_BRICK:1)
Block(5,-40,-2,STONE:5)
Block(5,-40,-1,STONE:5)
Block(5,-40,0,SMOOTH_BRICK:1)
Block(5,-39,-7,STONE:5)
Block(5,-39,-6,COBBLESTONE:0)
Block(5,-39,-5,COBBLESTONE:0)
Block(5,-39,-4,STONE:5)
Block(5,-39,-3,SMOOTH_BRICK:1)
Block(5,-39,-2,STONE:5)
Block(5,-39,-1,STONE:5)
Block(5,-39,0,SMOOTH_BRICK:1)
Block(5,-38,-7,STONE:5)
Block(5,-38,-6,COBBLESTONE:0)
Block(5,-38,-5,COBBLESTONE:0)
Block(5,-38,-4,STONE:5)
Block(5,-38,-3,SMOOTH_BRICK:1)
Block(5,-38,-2,STONE:5)
Block(5,-38,-1,STONE:5)
Block(5,-38,0,SMOOTH_BRICK:1)
Block(5,-37,-7,STONE:5)
Block(5,-37,-6,COBBLESTONE:0)
Block(5,-37,-5,COBBLESTONE:0)
Block(5,-37,-4,STONE:5)
Block(5,-37,-3,SMOOTH_BRICK:1)
Block(5,-37,-2,STONE:5)
Block(5,-37,-1,STONE:5)
Block(5,-37,0,SMOOTH_BRICK:1)
Block(5,-36,-7,STONE:5)
Block(5,-36,-6,COBBLESTONE:0)
Block(5,-36,-5,COBBLESTONE:0)
Block(5,-36,-4,STONE:5)
Block(5,-36,-3,SMOOTH_BRICK:1)
Block(5,-36,-2,STONE:5)
Block(5,-36,-1,STONE:5)
Block(5,-36,0,SMOOTH_BRICK:1)
Block(5,-35,-7,STONE:5)
Block(5,-35,-6,COBBLESTONE:0)
Block(5,-35,-5,COBBLESTONE:0)
Block(5,-35,-4,STONE:5)
Block(5,-35,-3,SMOOTH_BRICK:1)
Block(5,-35,-2,STONE:5)
Block(5,-35,-1,STONE:5)
Block(5,-35,0,SMOOTH_BRICK:1)
Block(5,-34,-7,STONE:5)
Block(5,-34,-6,COBBLESTONE:0)
Block(5,-34,-5,COBBLESTONE:0)
Block(5,-34,-4,STONE:5)
Block(5,-34,-3,SMOOTH_BRICK:1)
Block(5,-34,-2,STONE:5)
Block(5,-34,-1,STONE:5)
Block(5,-34,0,SMOOTH_BRICK:1)
Block(5,-33,-7,STONE:5)
Block(5,-33,-6,COBBLESTONE:0)
Block(5,-33,-5,COBBLESTONE:0)
Block(5,-33,-4,STONE:5)
Block(5,-33,-3,SMOOTH_BRICK:1)
Block(5,-33,-2,STONE:5)
Block(5,-33,-1,STONE:5)
Block(5,-33,0,SMOOTH_BRICK:1)
Block(5,-32,-7,STONE:5)
Block(5,-32,-6,COBBLESTONE:0)
Block(5,-32,-5,COBBLESTONE:0)
Block(5,-32,-4,STONE:5)
Block(5,-32,-3,SMOOTH_BRICK:1)
Block(5,-32,-2,STONE:5)
Block(5,-32,-1,STONE:5)
Block(5,-32,0,SMOOTH_BRICK:1)
Block(5,-31,-7,STONE:5)
Block(5,-31,-6,COBBLESTONE:0)
Block(5,-31,-5,COBBLESTONE:0)
Block(5,-31,-4,STONE:5)
Block(5,-31,-3,SMOOTH_BRICK:1)
Block(5,-31,-2,STONE:5)
Block(5,-31,-1,STONE:5)
Block(5,-31,0,SMOOTH_BRICK:1)
Block(5,-30,-7,STONE:5)
Block(5,-30,-6,COBBLESTONE:0)
Block(5,-30,-5,COBBLESTONE:0)
Block(5,-30,-4,STONE:5)
Block(5,-30,-3,SMOOTH_BRICK:1)
Block(5,-30,-2,STONE:5)
Block(5,-30,-1,STONE:5)
Block(5,-30,0,SMOOTH_BRICK:1)
Block(5,-29,-7,STONE:5)
Block(5,-29,-6,COBBLESTONE:0)
Block(5,-29,-5,COBBLESTONE:0)
Block(5,-29,-4,STONE:5)
Block(5,-29,-3,SMOOTH_BRICK:1)
Block(5,-29,-2,STONE:5)
Block(5,-29,-1,STONE:5)
Block(5,-29,0,SMOOTH_BRICK:1)
Block(5,-28,-7,STONE:5)
Block(5,-28,-6,COBBLESTONE:0)
Block(5,-28,-5,COBBLESTONE:0)
Block(5,-28,-4,STONE:5)
Block(5,-28,-3,SMOOTH_BRICK:1)
Block(5,-28,-2,STONE:5)
Block(5,-28,-1,STONE:5)
Block(5,-28,0,SMOOTH_BRICK:1)
Block(5,-27,-7,STONE:5)
Block(5,-27,-6,COBBLESTONE:0)
Block(5,-27,-5,COBBLESTONE:0)
Block(5,-27,-4,STONE:5)
Block(5,-27,-3,SMOOTH_BRICK:1)
Block(5,-27,-2,STONE:5)
Block(5,-27,-1,STONE:5)
Block(5,-27,0,SMOOTH_BRICK:1)
Block(5,-26,-7,STONE:5)
Block(5,-26,-6,COBBLESTONE:0)
Block(5,-26,-5,COBBLESTONE:0)
Block(5,-26,-4,STONE:5)
Block(5,-26,-3,SMOOTH_BRICK:1)
Block(5,-26,-2,STONE:5)
Block(5,-26,-1,STONE:5)
Block(5,-26,0,SMOOTH_BRICK:1)
Block(5,-25,-7,STONE:5)
Block(5,-25,-6,COBBLESTONE:0)
Block(5,-25,-5,COBBLESTONE:0)
Block(5,-25,-4,STONE:5)
Block(5,-25,-3,SMOOTH_BRICK:1)
Block(5,-25,-2,STONE:5)
Block(5,-25,-1,STONE:5)
Block(5,-25,0,SMOOTH_BRICK:1)
Block(5,-24,-7,STONE:5)
Block(5,-24,-6,COBBLESTONE:0)
Block(5,-24,-5,COBBLESTONE:0)
Block(5,-24,-4,STONE:5)
Block(5,-24,-3,SMOOTH_BRICK:1)
Block(5,-24,-2,STONE:5)
Block(5,-24,-1,STONE:5)
Block(5,-24,0,SMOOTH_BRICK:1)
Block(5,-23,-7,STONE:5)
Block(5,-23,-6,COBBLESTONE:0)
Block(5,-23,-5,COBBLESTONE:0)
Block(5,-23,-4,STONE:5)
Block(5,-23,-3,SMOOTH_BRICK:1)
Block(5,-23,-2,STONE:5)
Block(5,-23,-1,STONE:5)
Block(5,-23,0,SMOOTH_BRICK:1)
Block(5,-22,-7,STONE:5)
Block(5,-22,-6,COBBLESTONE:0)
Block(5,-22,-5,COBBLESTONE:0)
Block(5,-22,-4,STONE:5)
Block(5,-22,-3,SMOOTH_BRICK:1)
Block(5,-22,-2,STONE:5)
Block(5,-22,-1,STONE:5)
Block(5,-22,0,SMOOTH_BRICK:1)
Block(5,-21,-7,STONE:5)
Block(5,-21,-6,COBBLESTONE:0)
Block(5,-21,-5,COBBLESTONE:0)
Block(5,-21,-4,STONE:5)
Block(5,-21,-3,SMOOTH_BRICK:1)
Block(5,-21,-2,STONE:5)
Block(5,-21,-1,STONE:5)
Block(5,-21,0,SMOOTH_BRICK:1)
Block(5,-20,-7,STONE:5)
Block(5,-20,-6,COBBLESTONE:0)
Block(5,-20,-5,COBBLESTONE:0)
Block(5,-20,-4,STONE:5)
Block(5,-20,-3,SMOOTH_BRICK:1)
Block(5,-20,-2,STONE:5)
Block(5,-20,-1,STONE:5)
Block(5,-20,0,SMOOTH_BRICK:1)
Block(5,-19,-7,COBBLESTONE:0)
Block(5,-19,-6,STONE:5)
Block(5,-19,-5,STONE:5)
Block(5,-19,-4,COBBLESTONE:0)
Block(5,-19,-3,SMOOTH_BRICK:0)
Block(5,-19,-2,STONE:5)
Block(5,-19,-1,COBBLESTONE:0)
Block(5,-19,0,COBBLESTONE:0)
Block(5,-18,-7,STONE:5)
Block(5,-18,-6,STONE:5)
Block(5,-18,-5,STAINED_CLAY:9)
Block(5,-18,-4,SMOOTH_BRICK:1)
Block(5,-18,-3,STONE:5)
Block(5,-18,-2,COBBLESTONE:0)
Block(5,-18,-1,COBBLESTONE:0)
Block(5,-18,0,SMOOTH_BRICK:1)
Block(5,-17,-7,STAINED_CLAY:9)
Block(5,-17,-6,STONE:5)
Block(5,-17,-5,COBBLESTONE:0)
Block(5,-17,-4,COBBLESTONE:0)
Block(5,-17,-3,STONE:5)
Block(5,-17,-2,COBBLESTONE:0)
Block(5,-17,-1,STONE:5)
Block(5,-17,0,STONE:5)
Block(5,-16,-7,STONE:5)
Block(5,-16,-6,COBBLESTONE:0)
Block(5,-16,-5,STONE:5)
Block(5,-16,-4,STONE:5)
Block(5,-16,-3,STONE:5)
Block(5,-16,-2,STONE:5)
Block(5,-16,-1,COBBLESTONE:0)
Block(5,-16,0,SMOOTH_BRICK:0)
Block(5,-15,-7,SMOOTH_BRICK:1)
Block(5,-15,-6,COBBLESTONE:0)
Block(5,-15,-5,STONE:5)
Block(5,-15,-4,STONE:5)
Block(5,-15,-3,COBBLESTONE:0)
Block(5,-15,-2,COBBLESTONE:0)
Block(5,-15,-1,STONE:5)
Block(5,-15,0,COBBLESTONE:0)
Block(5,-14,-7,COBBLESTONE:0)
Block(5,-14,-6,SMOOTH_BRICK:1)
Block(5,-14,-5,COBBLESTONE:0)
Block(5,-14,-4,COBBLESTONE:0)
Block(5,-14,-3,STONE:5)
Block(5,-14,-2,COBBLESTONE:0)
Block(5,-14,-1,STONE:5)
Block(5,-14,0,COBBLESTONE:0)
Block(5,-13,-7,STONE:5)
Block(5,-13,-6,COBBLESTONE:0)
Block(5,-13,-5,COBBLESTONE:0)
Block(5,-13,-4,STONE:5)
Block(5,-13,-3,STONE:5)
Block(5,-13,-2,STONE:5)
Block(5,-13,-1,COBBLESTONE:0)
Block(5,-13,0,STONE:5)
Block(5,-12,-7,SMOOTH_BRICK:1)
Block(5,-12,-6,COBBLESTONE:0)
Block(5,-12,-5,STONE:5)
Block(5,-12,-4,STONE:5)
Block(5,-12,-3,COBBLESTONE:0)
Block(5,-12,-2,STONE:5)
Block(5,-12,-1,STONE:5)
Block(5,-12,0,STONE:5)
Block(5,-11,-7,STONE:5)
Block(5,-11,-6,SMOOTH_BRICK:0)
Block(5,-11,-5,COBBLESTONE:0)
Block(5,-11,-4,COBBLESTONE:0)
Block(5,-11,-3,STONE:5)
Block(5,-11,-2,COBBLESTONE:0)
Block(5,-11,-1,STONE:5)
Block(5,-11,0,SMOOTH_BRICK:0)
Block(5,-10,-7,STONE:5)
Block(5,-10,-6,COBBLESTONE:0)
Block(5,-10,-5,COBBLESTONE:0)
Block(5,-10,-4,SMOOTH_BRICK:0)
Block(5,-10,-3,STONE:5)
Block(5,-10,-2,STONE:5)
Block(5,-10,-1,STAINED_CLAY:9)
Block(5,-10,0,COBBLESTONE:0)
Block(5,-9,-7,STONE:6)
Block(5,-9,-6,STONE:6)
Block(5,-9,-5,STONE:6)
Block(5,-9,-4,STONE:6)
Block(5,-9,-3,STONE:6)
Block(5,-9,-2,LOG:0)
Block(5,-9,-1,COBBLESTONE_STAIRS:3)
Block(5,-9,0,COBBLESTONE_STAIRS:0)
Block(5,-8,-7,STONE:6)
Block(5,-8,-6,STONE:6)
Block(5,-8,-5,STONE:6)
Block(5,-8,-4,STONE:6)
Block(5,-8,-3,STONE:6)
Block(5,-8,-2,LOG:0)
Block(5,-7,-7,STONE:6)
Block(5,-7,-6,STONE:6)
Block(5,-7,-5,STONE:6)
Block(5,-7,-4,STONE:6)
Block(5,-7,-3,STONE:6)
Block(5,-7,-2,LOG:0)
Block(5,-6,-7,STONE:6)
Block(5,-6,-6,STONE:6)
Block(5,-6,-5,STONE:6)
Block(5,-6,-4,STONE:6)
Block(5,-6,-3,STONE:6)
Block(5,-6,-2,LOG:0)
Block(5,-5,-7,SMOOTH_BRICK:2)
Block(5,-5,-6,STONE:5)
Block(5,-5,-5,COBBLESTONE:0)
Block(5,-5,-4,COBBLESTONE:0)
Block(5,-5,-3,COBBLESTONE:0)
Block(5,-5,-2,LOG:0)
Block(5,-4,-7,STONE:6)
Block(5,-4,-6,STONE:6)
Block(5,-4,-5,STONE:6)
Block(5,-4,-4,STONE:6)
Block(5,-4,-3,STONE:6)
Block(5,-4,-2,COBBLESTONE_STAIRS:0)
Block(5,-3,-7,STONE:6)
Block(5,-3,-6,STONE:6)
Block(5,-3,-5,STONE:6)
Block(5,-3,-4,STONE:6)
Block(5,-3,-3,STONE:6)
Block(5,-2,-7,STONE:6)
Block(5,-2,-6,STONE:6)
Block(5,-2,-5,STONE:6)
Block(5,-2,-4,STONE:6)
Block(5,-2,-3,STONE:6)
Block(5,-1,-7,STONE:6)
Block(5,-1,-6,STONE:6)
Block(5,-1,-5,STONE:6)
Block(5,-1,-4,COBBLESTONE_STAIRS:0)
Block(5,-1,-3,COBBLESTONE_STAIRS:0)
Block(5,0,-7,STONE:6)
Block(5,0,-6,STONE:6)
Block(5,0,-5,STONE:6)
Block(5,1,-7,STONE:6)
Block(5,1,-6,STONE:6)
Block(5,1,-5,STONE:6)
Block(5,2,-7,STONE:6)
Block(5,2,-6,STONE:6)
Block(5,2,-5,STONE:6)
Block(5,3,-7,STONE:6)
Block(5,3,-6,STONE:6)
Block(5,3,-5,STONE:6)
Block(5,4,-7,STONE:6)
Block(5,4,-6,STONE:6)
Block(5,4,-5,STONE:6)
Block(5,5,-7,STONE:6)
Block(5,5,-6,STONE:6)
Block(5,5,-5,STONE:6)
Block(5,6,-7,SMOOTH_BRICK:0)
Block(5,6,-6,COBBLESTONE_STAIRS:3)
Block(5,6,-5,DARK_OAK_FENCE:0)
Block(5,7,-7,COBBLESTONE_STAIRS:4)
Block(5,7,-6,COBBLESTONE_STAIRS:7)
Block(5,7,-5,AIR:0)
Block(5,8,-7,COBBLESTONE:0)
Block(5,8,-6,SMOOTH_BRICK:0)
Block(5,8,-5,DARK_OAK_STAIRS:7)
Block(5,9,-7,SMOOTH_BRICK:0)
Block(5,9,-6,SMOOTH_BRICK:0)
Block(5,9,-5,SMOOTH_BRICK:0)
Block(5,10,-7,WOOD_STEP:9)
Block(5,10,-6,SPRUCE_WOOD_STAIRS:6)
Block(5,10,-5,SMOOTH_BRICK:0)
Block(5,11,-7,SKULL:1,origin/81-skullC48R32.nbt)
Block(5,11,-6,SKULL:1,origin/82-skullC48R32.nbt)
Block(5,11,-5,SMOOTH_BRICK:0)
Block(5,12,-7,AIR:0)
Block(5,12,-6,AIR:0)
Block(5,12,-5,SMOOTH_BRICK:0)
Block(5,13,-7,WOOD_STEP:13)
Block(5,13,-6,WOOD_STEP:13)
Block(5,13,-5,LOG:4)
Block(5,14,-7,SKULL:1,origin/85-skullC48R32.nbt)
Block(5,14,-6,WORKBENCH:0)
Block(5,14,-5,STONE:6)
Block(5,15,-7,AIR:0)
Block(5,15,-6,WORKBENCH:0)
Block(5,15,-5,STONE:6)
Block(5,16,-7,AIR:0)
Block(5,16,-6,WORKBENCH:0)
Block(5,16,-5,STONE:6)
Block(5,17,-7,AIR:0)
Block(5,17,-6,AIR:0)
Block(5,17,-5,STONE:6)
Block(5,18,-7,WOOD_STEP:13)
Block(5,18,-6,WOOD_STEP:13)
Block(5,18,-5,STONE:6)
Block(5,19,-7,AIR:0)
Block(5,19,-6,AIR:0)
Block(5,19,-5,STEP:5)
Block(5,20,-7,AIR:0)
Block(5,20,-6,AIR:0)
Block(5,20,-5,AIR:0)
Block(5,21,-7,AIR:0)
Block(5,21,-6,AIR:0)
Block(5,21,-5,AIR:0)
Block(5,22,-7,AIR:0)
Block(5,22,-6,AIR:0)
Block(5,22,-5,AIR:0)
Block(5,23,-7,AIR:0)
Block(5,23,-6,AIR:0)
Block(5,23,-5,AIR:0)
Block(5,24,-7,AIR:0)
Block(5,24,-6,AIR:0)
Block(5,24,-5,AIR:0)
Block(5,25,-7,AIR:0)
Block(5,25,-6,AIR:0)
Block(5,25,-5,AIR:0)
Block(5,26,-7,AIR:0)
Block(5,26,-6,AIR:0)
Block(5,26,-5,AIR:0)
Block(5,27,-7,AIR:0)
Block(5,27,-6,AIR:0)
Block(5,27,-5,AIR:0)
Block(5,28,-7,AIR:0)
Block(5,28,-6,AIR:0)
Block(5,28,-5,AIR:0)
Block(5,29,-7,AIR:0)
Block(5,29,-6,AIR:0)
Block(5,29,-5,AIR:0)
Block(5,30,-7,AIR:0)
Block(5,30,-6,AIR:0)
Block(5,30,-5,AIR:0)
Block(5,31,-7,AIR:0)
Block(5,31,-6,AIR:0)
Block(5,31,-5,AIR:0)
Block(5,32,-7,AIR:0)
Block(5,32,-6,AIR:0)
Block(5,32,-5,AIR:0)
Block(5,33,-7,AIR:0)
Block(5,33,-6,AIR:0)
Block(5,33,-5,AIR:0)
Block(5,34,-7,AIR:0)
Block(5,34,-6,AIR:0)
Block(5,34,-5,AIR:0)
Block(5,35,-7,AIR:0)
Block(5,35,-6,AIR:0)
Block(5,35,-5,AIR:0)
Block(5,36,-7,AIR:0)
Block(5,36,-6,AIR:0)
Block(5,36,-5,AIR:0)
Block(5,37,-7,AIR:0)
Block(5,37,-6,AIR:0)
Block(5,37,-5,AIR:0)
Block(5,38,-7,AIR:0)
Block(5,38,-6,AIR:0)
Block(5,38,-5,AIR:0)
Block(5,39,-7,AIR:0)
Block(5,39,-6,AIR:0)
Block(5,39,-5,AIR:0)
Block(5,40,-7,AIR:0)
Block(5,40,-6,AIR:0)
Block(5,40,-5,AIR:0)
Block(5,41,-7,AIR:0)
Block(5,41,-6,AIR:0)
Block(5,41,-5,AIR:0)
Block(5,42,-7,AIR:0)
Block(5,42,-6,AIR:0)
Block(5,42,-5,AIR:0)
Block(5,43,-7,AIR:0)
Block(5,43,-6,AIR:0)
Block(5,43,-5,AIR:0)
Block(5,44,-7,AIR:0)
Block(5,44,-6,AIR:0)
Block(5,44,-5,AIR:0)
Block(5,45,-7,AIR:0)
Block(5,45,-6,AIR:0)
Block(5,45,-5,AIR:0)
Block(5,46,-7,AIR:0)
Block(5,46,-6,AIR:0)
Block(5,46,-5,AIR:0)
Block(5,47,-7,AIR:0)
Block(5,47,-6,AIR:0)
Block(5,47,-5,AIR:0)
Block(5,48,-7,AIR:0)
Block(5,48,-6,AIR:0)
Block(5,48,-5,AIR:0)
Block(5,49,-7,AIR:0)
Block(5,49,-6,AIR:0)
Block(5,49,-5,AIR:0)
Block(5,50,-7,AIR:0)
Block(5,50,-6,AIR:0)
Block(5,50,-5,AIR:0)
Block(5,51,-7,AIR:0)
Block(5,51,-6,AIR:0)
Block(5,51,-5,AIR:0)
Block(5,52,-7,AIR:0)
Block(5,52,-6,AIR:0)
Block(5,52,-5,AIR:0)
Block(6,-50,-7,COBBLESTONE:0)
Block(6,-50,-6,COBBLESTONE:0)
Block(6,-50,-5,SMOOTH_BRICK:2)
Block(6,-50,-4,STONE:5)
Block(6,-50,-3,STONE:5)
Block(6,-50,-2,COBBLESTONE:0)
Block(6,-50,-1,STONE:5)
Block(6,-50,0,SMOOTH_BRICK:2)
Block(6,-50,1,COBBLESTONE:0)
Block(6,-49,-7,COBBLESTONE:0)
Block(6,-49,-6,COBBLESTONE:0)
Block(6,-49,-5,SMOOTH_BRICK:2)
Block(6,-49,-4,STONE:5)
Block(6,-49,-3,STONE:5)
Block(6,-49,-2,COBBLESTONE:0)
Block(6,-49,-1,STONE:5)
Block(6,-49,0,SMOOTH_BRICK:2)
Block(6,-49,1,COBBLESTONE:0)
Block(6,-48,-7,COBBLESTONE:0)
Block(6,-48,-6,COBBLESTONE:0)
Block(6,-48,-5,SMOOTH_BRICK:2)
Block(6,-48,-4,STONE:5)
Block(6,-48,-3,STONE:5)
Block(6,-48,-2,COBBLESTONE:0)
Block(6,-48,-1,STONE:5)
Block(6,-48,0,SMOOTH_BRICK:2)
Block(6,-48,1,COBBLESTONE:0)
Block(6,-47,-7,COBBLESTONE:0)
Block(6,-47,-6,COBBLESTONE:0)
Block(6,-47,-5,SMOOTH_BRICK:2)
Block(6,-47,-4,STONE:5)
Block(6,-47,-3,STONE:5)
Block(6,-47,-2,COBBLESTONE:0)
Block(6,-47,-1,STONE:5)
Block(6,-47,0,SMOOTH_BRICK:2)
Block(6,-47,1,COBBLESTONE:0)
Block(6,-46,-7,COBBLESTONE:0)
Block(6,-46,-6,COBBLESTONE:0)
Block(6,-46,-5,SMOOTH_BRICK:2)
Block(6,-46,-4,STONE:5)
Block(6,-46,-3,STONE:5)
Block(6,-46,-2,COBBLESTONE:0)
Block(6,-46,-1,STONE:5)
Block(6,-46,0,SMOOTH_BRICK:2)
Block(6,-46,1,COBBLESTONE:0)
Block(6,-45,-7,COBBLESTONE:0)
Block(6,-45,-6,COBBLESTONE:0)
Block(6,-45,-5,SMOOTH_BRICK:2)
Block(6,-45,-4,STONE:5)
Block(6,-45,-3,STONE:5)
Block(6,-45,-2,COBBLESTONE:0)
Block(6,-45,-1,STONE:5)
Block(6,-45,0,SMOOTH_BRICK:2)
Block(6,-45,1,COBBLESTONE:0)
Block(6,-44,-7,COBBLESTONE:0)
Block(6,-44,-6,COBBLESTONE:0)
Block(6,-44,-5,SMOOTH_BRICK:2)
Block(6,-44,-4,STONE:5)
Block(6,-44,-3,STONE:5)
Block(6,-44,-2,COBBLESTONE:0)
Block(6,-44,-1,STONE:5)
Block(6,-44,0,SMOOTH_BRICK:2)
Block(6,-44,1,COBBLESTONE:0)
Block(6,-43,-7,COBBLESTONE:0)
Block(6,-43,-6,COBBLESTONE:0)
Block(6,-43,-5,SMOOTH_BRICK:2)
Block(6,-43,-4,STONE:5)
Block(6,-43,-3,STONE:5)
Block(6,-43,-2,COBBLESTONE:0)
Block(6,-43,-1,STONE:5)
Block(6,-43,0,SMOOTH_BRICK:2)
Block(6,-43,1,COBBLESTONE:0)
Block(6,-42,-7,COBBLESTONE:0)
Block(6,-42,-6,COBBLESTONE:0)
Block(6,-42,-5,SMOOTH_BRICK:2)
Block(6,-42,-4,STONE:5)
Block(6,-42,-3,STONE:5)
Block(6,-42,-2,COBBLESTONE:0)
Block(6,-42,-1,STONE:5)
Block(6,-42,0,SMOOTH_BRICK:2)
Block(6,-42,1,COBBLESTONE:0)
Block(6,-41,-7,COBBLESTONE:0)
Block(6,-41,-6,COBBLESTONE:0)
Block(6,-41,-5,SMOOTH_BRICK:2)
Block(6,-41,-4,STONE:5)
Block(6,-41,-3,STONE:5)
Block(6,-41,-2,COBBLESTONE:0)
Block(6,-41,-1,STONE:5)
Block(6,-41,0,SMOOTH_BRICK:2)
Block(6,-41,1,COBBLESTONE:0)
Block(6,-40,-7,COBBLESTONE:0)
Block(6,-40,-6,COBBLESTONE:0)
Block(6,-40,-5,SMOOTH_BRICK:2)
Block(6,-40,-4,STONE:5)
Block(6,-40,-3,STONE:5)
Block(6,-40,-2,COBBLESTONE:0)
Block(6,-40,-1,STONE:5)
Block(6,-40,0,SMOOTH_BRICK:2)
Block(6,-40,1,COBBLESTONE:0)
Block(6,-39,-7,COBBLESTONE:0)
Block(6,-39,-6,COBBLESTONE:0)
Block(6,-39,-5,SMOOTH_BRICK:2)
Block(6,-39,-4,STONE:5)
Block(6,-39,-3,STONE:5)
Block(6,-39,-2,COBBLESTONE:0)
Block(6,-39,-1,STONE:5)
Block(6,-39,0,SMOOTH_BRICK:2)
Block(6,-39,1,COBBLESTONE:0)
Block(6,-38,-7,COBBLESTONE:0)
Block(6,-38,-6,COBBLESTONE:0)
Block(6,-38,-5,SMOOTH_BRICK:2)
Block(6,-38,-4,STONE:5)
Block(6,-38,-3,STONE:5)
Block(6,-38,-2,COBBLESTONE:0)
Block(6,-38,-1,STONE:5)
Block(6,-38,0,SMOOTH_BRICK:2)
Block(6,-38,1,COBBLESTONE:0)
Block(6,-37,-7,COBBLESTONE:0)
Block(6,-37,-6,COBBLESTONE:0)
Block(6,-37,-5,SMOOTH_BRICK:2)
Block(6,-37,-4,STONE:5)
Block(6,-37,-3,STONE:5)
Block(6,-37,-2,COBBLESTONE:0)
Block(6,-37,-1,STONE:5)
Block(6,-37,0,SMOOTH_BRICK:2)
Block(6,-37,1,COBBLESTONE:0)
Block(6,-36,-7,COBBLESTONE:0)
Block(6,-36,-6,COBBLESTONE:0)
Block(6,-36,-5,SMOOTH_BRICK:2)
Block(6,-36,-4,STONE:5)
Block(6,-36,-3,STONE:5)
Block(6,-36,-2,COBBLESTONE:0)
Block(6,-36,-1,STONE:5)
Block(6,-36,0,SMOOTH_BRICK:2)
Block(6,-36,1,COBBLESTONE:0)
Block(6,-35,-7,COBBLESTONE:0)
Block(6,-35,-6,COBBLESTONE:0)
Block(6,-35,-5,SMOOTH_BRICK:2)
Block(6,-35,-4,STONE:5)
Block(6,-35,-3,STONE:5)
Block(6,-35,-2,COBBLESTONE:0)
Block(6,-35,-1,STONE:5)
Block(6,-35,0,SMOOTH_BRICK:2)
Block(6,-35,1,COBBLESTONE:0)
Block(6,-34,-7,COBBLESTONE:0)
Block(6,-34,-6,COBBLESTONE:0)
Block(6,-34,-5,SMOOTH_BRICK:2)
Block(6,-34,-4,STONE:5)
Block(6,-34,-3,STONE:5)
Block(6,-34,-2,COBBLESTONE:0)
Block(6,-34,-1,STONE:5)
Block(6,-34,0,SMOOTH_BRICK:2)
Block(6,-34,1,COBBLESTONE:0)
Block(6,-33,-7,COBBLESTONE:0)
Block(6,-33,-6,COBBLESTONE:0)
Block(6,-33,-5,SMOOTH_BRICK:2)
Block(6,-33,-4,STONE:5)
Block(6,-33,-3,STONE:5)
Block(6,-33,-2,COBBLESTONE:0)
Block(6,-33,-1,STONE:5)
Block(6,-33,0,SMOOTH_BRICK:2)
Block(6,-33,1,COBBLESTONE:0)
Block(6,-32,-7,COBBLESTONE:0)
Block(6,-32,-6,COBBLESTONE:0)
Block(6,-32,-5,SMOOTH_BRICK:2)
Block(6,-32,-4,STONE:5)
Block(6,-32,-3,STONE:5)
Block(6,-32,-2,COBBLESTONE:0)
Block(6,-32,-1,STONE:5)
Block(6,-32,0,SMOOTH_BRICK:2)
Block(6,-32,1,COBBLESTONE:0)
Block(6,-31,-7,COBBLESTONE:0)
Block(6,-31,-6,COBBLESTONE:0)
Block(6,-31,-5,SMOOTH_BRICK:2)
Block(6,-31,-4,STONE:5)
Block(6,-31,-3,STONE:5)
Block(6,-31,-2,COBBLESTONE:0)
Block(6,-31,-1,STONE:5)
Block(6,-31,0,SMOOTH_BRICK:2)
Block(6,-31,1,COBBLESTONE:0)
Block(6,-30,-7,COBBLESTONE:0)
Block(6,-30,-6,COBBLESTONE:0)
Block(6,-30,-5,SMOOTH_BRICK:2)
Block(6,-30,-4,STONE:5)
Block(6,-30,-3,STONE:5)
Block(6,-30,-2,COBBLESTONE:0)
Block(6,-30,-1,STONE:5)
Block(6,-30,0,SMOOTH_BRICK:2)
Block(6,-30,1,COBBLESTONE:0)
Block(6,-29,-7,COBBLESTONE:0)
Block(6,-29,-6,COBBLESTONE:0)
Block(6,-29,-5,SMOOTH_BRICK:2)
Block(6,-29,-4,STONE:5)
Block(6,-29,-3,STONE:5)
Block(6,-29,-2,COBBLESTONE:0)
Block(6,-29,-1,STONE:5)
Block(6,-29,0,SMOOTH_BRICK:2)
Block(6,-29,1,COBBLESTONE:0)
Block(6,-28,-7,COBBLESTONE:0)
Block(6,-28,-6,COBBLESTONE:0)
Block(6,-28,-5,SMOOTH_BRICK:2)
Block(6,-28,-4,STONE:5)
Block(6,-28,-3,STONE:5)
Block(6,-28,-2,COBBLESTONE:0)
Block(6,-28,-1,STONE:5)
Block(6,-28,0,SMOOTH_BRICK:2)
Block(6,-28,1,COBBLESTONE:0)
Block(6,-27,-7,COBBLESTONE:0)
Block(6,-27,-6,COBBLESTONE:0)
Block(6,-27,-5,SMOOTH_BRICK:2)
Block(6,-27,-4,STONE:5)
Block(6,-27,-3,STONE:5)
Block(6,-27,-2,COBBLESTONE:0)
Block(6,-27,-1,STONE:5)
Block(6,-27,0,SMOOTH_BRICK:2)
Block(6,-27,1,COBBLESTONE:0)
Block(6,-26,-7,COBBLESTONE:0)
Block(6,-26,-6,COBBLESTONE:0)
Block(6,-26,-5,SMOOTH_BRICK:2)
Block(6,-26,-4,STONE:5)
Block(6,-26,-3,STONE:5)
Block(6,-26,-2,COBBLESTONE:0)
Block(6,-26,-1,STONE:5)
Block(6,-26,0,SMOOTH_BRICK:2)
Block(6,-26,1,COBBLESTONE:0)
Block(6,-25,-7,COBBLESTONE:0)
Block(6,-25,-6,COBBLESTONE:0)
Block(6,-25,-5,SMOOTH_BRICK:2)
Block(6,-25,-4,STONE:5)
Block(6,-25,-3,STONE:5)
Block(6,-25,-2,COBBLESTONE:0)
Block(6,-25,-1,STONE:5)
Block(6,-25,0,SMOOTH_BRICK:2)
Block(6,-25,1,COBBLESTONE:0)
Block(6,-24,-7,COBBLESTONE:0)
Block(6,-24,-6,COBBLESTONE:0)
Block(6,-24,-5,SMOOTH_BRICK:2)
Block(6,-24,-4,STONE:5)
Block(6,-24,-3,STONE:5)
Block(6,-24,-2,COBBLESTONE:0)
Block(6,-24,-1,STONE:5)
Block(6,-24,0,SMOOTH_BRICK:2)
Block(6,-24,1,COBBLESTONE:0)
Block(6,-23,-7,COBBLESTONE:0)
Block(6,-23,-6,COBBLESTONE:0)
Block(6,-23,-5,SMOOTH_BRICK:2)
Block(6,-23,-4,STONE:5)
Block(6,-23,-3,STONE:5)
Block(6,-23,-2,COBBLESTONE:0)
Block(6,-23,-1,STONE:5)
Block(6,-23,0,SMOOTH_BRICK:2)
Block(6,-23,1,COBBLESTONE:0)
Block(6,-22,-7,COBBLESTONE:0)
Block(6,-22,-6,COBBLESTONE:0)
Block(6,-22,-5,SMOOTH_BRICK:2)
Block(6,-22,-4,STONE:5)
Block(6,-22,-3,STONE:5)
Block(6,-22,-2,COBBLESTONE:0)
Block(6,-22,-1,STONE:5)
Block(6,-22,0,SMOOTH_BRICK:2)
Block(6,-22,1,COBBLESTONE:0)
Block(6,-21,-7,COBBLESTONE:0)
Block(6,-21,-6,COBBLESTONE:0)
Block(6,-21,-5,SMOOTH_BRICK:2)
Block(6,-21,-4,STONE:5)
Block(6,-21,-3,STONE:5)
Block(6,-21,-2,COBBLESTONE:0)
Block(6,-21,-1,STONE:5)
Block(6,-21,0,SMOOTH_BRICK:2)
Block(6,-21,1,COBBLESTONE:0)
Block(6,-20,-7,COBBLESTONE:0)
Block(6,-20,-6,COBBLESTONE:0)
Block(6,-20,-5,SMOOTH_BRICK:2)
Block(6,-20,-4,STONE:5)
Block(6,-20,-3,STONE:5)
Block(6,-20,-2,COBBLESTONE:0)
Block(6,-20,-1,STONE:5)
Block(6,-20,0,SMOOTH_BRICK:2)
Block(6,-20,1,COBBLESTONE:0)
Block(6,-19,-7,COBBLESTONE:0)
Block(6,-19,-6,COBBLESTONE:0)
Block(6,-19,-5,STONE:5)
Block(6,-19,-4,STONE:5)
Block(6,-19,-3,STONE:5)
Block(6,-19,-2,COBBLESTONE:0)
Block(6,-19,-1,STAINED_CLAY:9)
Block(6,-19,0,COBBLESTONE:0)
Block(6,-19,1,COBBLESTONE:0)
Block(6,-18,-7,COBBLESTONE:0)
Block(6,-18,-6,COBBLESTONE:0)
Block(6,-18,-5,STONE:5)
Block(6,-18,-4,COBBLESTONE:0)
Block(6,-18,-3,COBBLESTONE:0)
Block(6,-18,-2,STONE:5)
Block(6,-18,-1,COBBLESTONE:0)
Block(6,-18,0,STONE:5)
Block(6,-18,1,STONE:5)
Block(6,-17,-7,COBBLESTONE:0)
Block(6,-17,-6,COBBLESTONE:0)
Block(6,-17,-5,SMOOTH_BRICK:2)
Block(6,-17,-4,COBBLESTONE:0)
Block(6,-17,-3,COBBLESTONE:0)
Block(6,-17,-2,STONE:5)
Block(6,-17,-1,STONE:5)
Block(6,-17,0,STONE:5)
Block(6,-17,1,SMOOTH_BRICK:2)
Block(6,-16,-7,STONE:5)
Block(6,-16,-6,COBBLESTONE:0)
Block(6,-16,-5,SMOOTH_BRICK:2)
Block(6,-16,-4,STONE:5)
Block(6,-16,-3,STONE:5)
Block(6,-16,-2,STONE:5)
Block(6,-16,-1,STONE:5)
Block(6,-16,0,COBBLESTONE:0)
Block(6,-16,1,COBBLESTONE:0)
Block(6,-15,-7,STONE:5)
Block(6,-15,-6,STONE:5)
Block(6,-15,-5,STONE:5)
Block(6,-15,-4,STONE:5)
Block(6,-15,-3,COBBLESTONE:0)
Block(6,-15,-2,STONE:5)
Block(6,-15,-1,COBBLESTONE:0)
Block(6,-15,0,SMOOTH_BRICK:1)
Block(6,-15,1,COBBLESTONE:0)
Block(6,-14,-7,STONE:5)
Block(6,-14,-6,COBBLESTONE:0)
Block(6,-14,-5,STONE:5)
Block(6,-14,-4,COBBLESTONE:0)
Block(6,-14,-3,SMOOTH_BRICK:2)
Block(6,-14,-2,STONE:5)
Block(6,-14,-1,COBBLESTONE:0)
Block(6,-14,0,COBBLESTONE:0)
Block(6,-14,1,STONE:5)
Block(6,-13,-7,COBBLESTONE:0)
Block(6,-13,-6,STONE:5)
Block(6,-13,-5,COBBLESTONE:0)
Block(6,-13,-4,COBBLESTONE:0)
Block(6,-13,-3,STONE:5)
Block(6,-13,-2,STONE:5)
Block(6,-13,-1,COBBLESTONE:0)
Block(6,-13,0,SMOOTH_BRICK:2)
Block(6,-13,1,COBBLESTONE:0)
Block(6,-12,-7,STONE:5)
Block(6,-12,-6,STONE:5)
Block(6,-12,-5,COBBLESTONE:0)
Block(6,-12,-4,STONE:5)
Block(6,-12,-3,COBBLESTONE:0)
Block(6,-12,-2,STONE:5)
Block(6,-12,-1,COBBLESTONE:0)
Block(6,-12,0,COBBLESTONE:0)
Block(6,-12,1,SMOOTH_BRICK:2)
Block(6,-11,-7,COBBLESTONE:0)
Block(6,-11,-6,COBBLESTONE:0)
Block(6,-11,-5,SMOOTH_BRICK:1)
Block(6,-11,-4,STONE:5)
Block(6,-11,-3,STONE:5)
Block(6,-11,-2,STONE:5)
Block(6,-11,-1,STONE:5)
Block(6,-11,0,COBBLESTONE:0)
Block(6,-11,1,STONE:5)
Block(6,-10,-7,COBBLESTONE:0)
Block(6,-10,-6,STONE:5)
Block(6,-10,-5,STONE:5)
Block(6,-10,-4,COBBLESTONE:0)
Block(6,-10,-3,STONE:5)
Block(6,-10,-2,SMOOTH_BRICK:0)
Block(6,-10,-1,STONE:5)
Block(6,-10,0,STONE:5)
Block(6,-10,1,COBBLESTONE:0)
Block(6,-9,-7,STONE:6)
Block(6,-9,-6,STONE:6)
Block(6,-9,-5,STONE:6)
Block(6,-9,-4,STONE:6)
Block(6,-9,-3,STONE:6)
Block(6,-9,-2,STONE:6)
Block(6,-9,-1,STONE:6)
Block(6,-9,0,COBBLESTONE_STAIRS:3)
Block(6,-9,1,COBBLESTONE_STAIRS:0)
Block(6,-8,-7,STONE:6)
Block(6,-8,-6,STONE:6)
Block(6,-8,-5,STONE:6)
Block(6,-8,-4,STONE:6)
Block(6,-8,-3,STONE:6)
Block(6,-8,-2,STONE:6)
Block(6,-8,-1,STONE:6)
Block(6,-7,-7,STONE:6)
Block(6,-7,-6,STONE:6)
Block(6,-7,-5,STONE:6)
Block(6,-7,-4,STONE:6)
Block(6,-7,-3,STONE:6)
Block(6,-7,-2,STONE:6)
Block(6,-7,-1,STONE:6)
Block(6,-6,-7,STONE:6)
Block(6,-6,-6,STONE:6)
Block(6,-6,-5,STONE:6)
Block(6,-6,-4,STONE:6)
Block(6,-6,-3,STONE:6)
Block(6,-6,-2,STONE:6)
Block(6,-6,-1,STONE:6)
Block(6,-5,-7,STONE:5)
Block(6,-5,-6,SMOOTH_BRICK:1)
Block(6,-5,-5,STAINED_CLAY:9)
Block(6,-5,-4,STONE:5)
Block(6,-5,-3,STONE:5)
Block(6,-5,-2,COBBLESTONE:0)
Block(6,-5,-1,COBBLESTONE_STAIRS:3)
Block(6,-4,-7,STONE:6)
Block(6,-4,-6,STONE:6)
Block(6,-4,-5,STONE:6)
Block(6,-4,-4,STONE:6)
Block(6,-4,-3,STONE:6)
Block(6,-4,-2,LOG:4)
Block(6,-3,-7,STONE:6)
Block(6,-3,-6,STONE:6)
Block(6,-3,-5,STONE:6)
Block(6,-3,-4,STONE:6)
Block(6,-3,-3,STONE:6)
Block(6,-2,-7,STONE:6)
Block(6,-2,-6,STONE:6)
Block(6,-2,-5,STONE:6)
Block(6,-2,-4,STONE:6)
Block(6,-2,-3,STONE:6)
Block(6,-1,-7,STONE:6)
Block(6,-1,-6,STONE:6)
Block(6,-1,-5,STONE:6)
Block(6,-1,-4,STONE:6)
Block(6,-1,-3,COBBLESTONE_STAIRS:3)
Block(6,0,-7,STONE:6)
Block(6,0,-6,STONE:6)
Block(6,0,-5,STONE:6)
Block(6,0,-4,STONE:6)
Block(6,1,-7,STONE:6)
Block(6,1,-6,STONE:6)
Block(6,1,-5,STONE:6)
Block(6,1,-4,STONE:6)
Block(6,2,-7,STONE:6)
Block(6,2,-6,STONE:6)
Block(6,2,-5,STONE:6)
Block(6,2,-4,STONE:6)
Block(6,3,-7,STONE:6)
Block(6,3,-6,STONE:6)
Block(6,3,-5,STONE:6)
Block(6,3,-4,STONE:6)
Block(6,4,-7,STONE:6)
Block(6,4,-6,STONE:6)
Block(6,4,-5,STONE:6)
Block(6,4,-4,STONE:6)
Block(6,5,-7,STONE:6)
Block(6,5,-6,STONE:6)
Block(6,5,-5,STONE:6)
Block(6,5,-4,STONE:6)
Block(6,6,-7,SMOOTH_BRICK:2)
Block(6,6,-6,SMOOTH_BRICK:0)
Block(6,6,-5,COBBLESTONE_STAIRS:3)
Block(6,6,-4,DARK_OAK_FENCE:0)
Block(6,7,-7,SMOOTH_BRICK:2)
Block(6,7,-6,COBBLESTONE_STAIRS:4)
Block(6,7,-5,COBBLESTONE_STAIRS:7)
Block(6,7,-4,AIR:0)
Block(6,8,-7,COBBLESTONE:0)
Block(6,8,-6,COBBLESTONE:0)
Block(6,8,-5,SMOOTH_BRICK:0)
Block(6,8,-4,AIR:0)
Block(6,9,-7,SMOOTH_BRICK:0)
Block(6,9,-6,SMOOTH_BRICK:0)
Block(6,9,-5,SMOOTH_BRICK:0)
Block(6,9,-4,AIR:0)
Block(6,10,-7,AIR:0)
Block(6,10,-6,AIR:0)
Block(6,10,-5,SMOOTH_STAIRS:3)
Block(6,10,-4,AIR:0)
Block(6,11,-7,AIR:0)
Block(6,11,-6,AIR:0)
Block(6,11,-5,SMOOTH_STAIRS:3)
Block(6,11,-4,AIR:0)
Block(6,12,-7,AIR:0)
Block(6,12,-6,AIR:0)
Block(6,12,-5,SMOOTH_STAIRS:3)
Block(6,12,-4,AIR:0)
Block(6,13,-7,WOOD_STEP:13)
Block(6,13,-6,WOOD_STEP:13)
Block(6,13,-5,LOG:4)
Block(6,13,-4,SMOOTH_STAIRS:4)
Block(6,14,-7,SMOOTH_BRICK:2)
Block(6,14,-6,SMOOTH_BRICK:2)
Block(6,14,-5,SMOOTH_BRICK:2)
Block(6,14,-4,STONE:6)
Block(6,15,-7,SMOOTH_BRICK:2)
Block(6,15,-6,SMOOTH_BRICK:2)
Block(6,15,-5,SMOOTH_BRICK:2)
Block(6,15,-4,STONE:6)
Block(6,16,-7,SMOOTH_BRICK:2)
Block(6,16,-6,SMOOTH_BRICK:2)
Block(6,16,-5,SMOOTH_BRICK:2)
Block(6,16,-4,STONE:6)
Block(6,17,-7,SMOOTH_BRICK:2)
Block(6,17,-6,SMOOTH_BRICK:2)
Block(6,17,-5,SMOOTH_BRICK:2)
Block(6,17,-4,STONE:6)
Block(6,18,-7,WOOD_DOUBLE_STEP:5)
Block(6,18,-6,WOOD_DOUBLE_STEP:5)
Block(6,18,-5,WOOD_DOUBLE_STEP:5)
Block(6,18,-4,STONE:6)
Block(6,18,-3,WALL_BANNER:3,origin/111-bannerC48R32.nbt)
Block(6,19,-7,WOOD_STEP:5)
Block(6,19,-6,AIR:0)
Block(6,19,-5,AIR:0)
Block(6,19,-4,STEP:5)
Block(6,20,-7,AIR:0)
Block(6,20,-6,AIR:0)
Block(6,20,-5,AIR:0)
Block(6,20,-4,AIR:0)
Block(6,21,-7,AIR:0)
Block(6,21,-6,AIR:0)
Block(6,21,-5,AIR:0)
Block(6,21,-4,AIR:0)
Block(6,22,-7,AIR:0)
Block(6,22,-6,AIR:0)
Block(6,22,-5,AIR:0)
Block(6,22,-4,AIR:0)
Block(6,23,-7,AIR:0)
Block(6,23,-6,AIR:0)
Block(6,23,-5,AIR:0)
Block(6,23,-4,AIR:0)
Block(6,24,-7,AIR:0)
Block(6,24,-6,AIR:0)
Block(6,24,-5,AIR:0)
Block(6,24,-4,AIR:0)
Block(6,25,-7,AIR:0)
Block(6,25,-6,AIR:0)
Block(6,25,-5,AIR:0)
Block(6,25,-4,AIR:0)
Block(6,26,-7,AIR:0)
Block(6,26,-6,AIR:0)
Block(6,26,-5,AIR:0)
Block(6,26,-4,AIR:0)
Block(6,27,-7,AIR:0)
Block(6,27,-6,AIR:0)
Block(6,27,-5,AIR:0)
Block(6,27,-4,AIR:0)
Block(6,28,-7,AIR:0)
Block(6,28,-6,AIR:0)
Block(6,28,-5,AIR:0)
Block(6,28,-4,AIR:0)
Block(6,29,-7,AIR:0)
Block(6,29,-6,AIR:0)
Block(6,29,-5,AIR:0)
Block(6,29,-4,AIR:0)
Block(6,30,-7,AIR:0)
Block(6,30,-6,AIR:0)
Block(6,30,-5,AIR:0)
Block(6,30,-4,AIR:0)
Block(6,31,-7,AIR:0)
Block(6,31,-6,AIR:0)
Block(6,31,-5,AIR:0)
Block(6,31,-4,AIR:0)
Block(6,32,-7,AIR:0)
Block(6,32,-6,AIR:0)
Block(6,32,-5,AIR:0)
Block(6,32,-4,AIR:0)
Block(6,33,-7,AIR:0)
Block(6,33,-6,AIR:0)
Block(6,33,-5,AIR:0)
Block(6,33,-4,AIR:0)
Block(6,34,-7,AIR:0)
Block(6,34,-6,AIR:0)
Block(6,34,-5,AIR:0)
Block(6,34,-4,AIR:0)
Block(6,35,-7,AIR:0)
Block(6,35,-6,AIR:0)
Block(6,35,-5,AIR:0)
Block(6,35,-4,AIR:0)
Block(6,36,-7,AIR:0)
Block(6,36,-6,AIR:0)
Block(6,36,-5,AIR:0)
Block(6,36,-4,AIR:0)
Block(6,37,-7,AIR:0)
Block(6,37,-6,AIR:0)
Block(6,37,-5,AIR:0)
Block(6,37,-4,AIR:0)
Block(6,38,-7,AIR:0)
Block(6,38,-6,AIR:0)
Block(6,38,-5,AIR:0)
Block(6,38,-4,AIR:0)
Block(6,39,-7,AIR:0)
Block(6,39,-6,AIR:0)
Block(6,39,-5,AIR:0)
Block(6,39,-4,AIR:0)
Block(6,40,-7,AIR:0)
Block(6,40,-6,AIR:0)
Block(6,40,-5,AIR:0)
Block(6,40,-4,AIR:0)
Block(6,41,-7,AIR:0)
Block(6,41,-6,AIR:0)
Block(6,41,-5,AIR:0)
Block(6,41,-4,AIR:0)
Block(6,42,-7,AIR:0)
Block(6,42,-6,AIR:0)
Block(6,42,-5,AIR:0)
Block(6,42,-4,AIR:0)
Block(6,43,-7,AIR:0)
Block(6,43,-6,AIR:0)
Block(6,43,-5,AIR:0)
Block(6,43,-4,AIR:0)
Block(6,44,-7,AIR:0)
Block(6,44,-6,AIR:0)
Block(6,44,-5,AIR:0)
Block(6,44,-4,AIR:0)
Block(6,45,-7,AIR:0)
Block(6,45,-6,AIR:0)
Block(6,45,-5,AIR:0)
Block(6,45,-4,AIR:0)
Block(6,46,-7,AIR:0)
Block(6,46,-6,AIR:0)
Block(6,46,-5,AIR:0)
Block(6,46,-4,AIR:0)
Block(6,47,-7,AIR:0)
Block(6,47,-6,AIR:0)
Block(6,47,-5,AIR:0)
Block(6,47,-4,AIR:0)
Block(6,48,-7,AIR:0)
Block(6,48,-6,AIR:0)
Block(6,48,-5,AIR:0)
Block(6,48,-4,AIR:0)
Block(6,49,-7,AIR:0)
Block(6,49,-6,AIR:0)
Block(6,49,-5,AIR:0)
Block(6,49,-4,AIR:0)
Block(6,50,-7,AIR:0)
Block(6,50,-6,AIR:0)
Block(6,50,-5,AIR:0)
Block(6,50,-4,AIR:0)
Block(6,51,-7,AIR:0)
Block(6,51,-6,AIR:0)
Block(6,51,-5,AIR:0)
Block(6,51,-4,AIR:0)
Block(6,52,-7,AIR:0)
Block(6,52,-6,AIR:0)
Block(6,52,-5,AIR:0)
Block(6,52,-4,AIR:0)
Block(7,-50,-7,LOG:0)
Block(7,-50,-6,STAINED_CLAY:9)
Block(7,-50,-5,STONE:5)
Block(7,-50,-4,LOG:0)
Block(7,-50,-3,STONE:5)
Block(7,-50,-2,COBBLESTONE:0)
Block(7,-50,-1,LOG:0)
Block(7,-50,0,SMOOTH_BRICK:2)
Block(7,-50,1,SMOOTH_BRICK:2)
Block(7,-50,2,LOG:0)
Block(7,-50,3,COBBLESTONE:0)
Block(7,-50,4,COBBLESTONE:0)
Block(7,-50,5,LOG:0)
Block(7,-50,6,SMOOTH_BRICK:0)
Block(7,-50,7,STONE:5)
Block(7,-50,8,LOG:0)
Block(7,-49,-7,LOG:0)
Block(7,-49,-6,STAINED_CLAY:9)
Block(7,-49,-5,STONE:5)
Block(7,-49,-4,LOG:0)
Block(7,-49,-3,STONE:5)
Block(7,-49,-2,COBBLESTONE:0)
Block(7,-49,-1,LOG:0)
Block(7,-49,0,SMOOTH_BRICK:2)
Block(7,-49,1,SMOOTH_BRICK:2)
Block(7,-49,2,LOG:0)
Block(7,-49,3,COBBLESTONE:0)
Block(7,-49,4,COBBLESTONE:0)
Block(7,-49,5,LOG:0)
Block(7,-49,6,SMOOTH_BRICK:0)
Block(7,-49,7,STONE:5)
Block(7,-49,8,LOG:0)
Block(7,-48,-7,LOG:0)
Block(7,-48,-6,STAINED_CLAY:9)
Block(7,-48,-5,STONE:5)
Block(7,-48,-4,LOG:0)
Block(7,-48,-3,STONE:5)
Block(7,-48,-2,COBBLESTONE:0)
Block(7,-48,-1,LOG:0)
Block(7,-48,0,SMOOTH_BRICK:2)
Block(7,-48,1,SMOOTH_BRICK:2)
Block(7,-48,2,LOG:0)
Block(7,-48,3,COBBLESTONE:0)
Block(7,-48,4,COBBLESTONE:0)
Block(7,-48,5,LOG:0)
Block(7,-48,6,SMOOTH_BRICK:0)
Block(7,-48,7,STONE:5)
Block(7,-48,8,LOG:0)
Block(7,-47,-7,LOG:0)
Block(7,-47,-6,STAINED_CLAY:9)
Block(7,-47,-5,STONE:5)
Block(7,-47,-4,LOG:0)
Block(7,-47,-3,STONE:5)
Block(7,-47,-2,COBBLESTONE:0)
Block(7,-47,-1,LOG:0)
Block(7,-47,0,SMOOTH_BRICK:2)
Block(7,-47,1,SMOOTH_BRICK:2)
Block(7,-47,2,LOG:0)
Block(7,-47,3,COBBLESTONE:0)
Block(7,-47,4,COBBLESTONE:0)
Block(7,-47,5,LOG:0)
Block(7,-47,6,SMOOTH_BRICK:0)
Block(7,-47,7,STONE:5)
Block(7,-47,8,LOG:0)
Block(7,-46,-7,LOG:0)
Block(7,-46,-6,STAINED_CLAY:9)
Block(7,-46,-5,STONE:5)
Block(7,-46,-4,LOG:0)
Block(7,-46,-3,STONE:5)
Block(7,-46,-2,COBBLESTONE:0)
Block(7,-46,-1,LOG:0)
Block(7,-46,0,SMOOTH_BRICK:2)
Block(7,-46,1,SMOOTH_BRICK:2)
Block(7,-46,2,LOG:0)
Block(7,-46,3,COBBLESTONE:0)
Block(7,-46,4,COBBLESTONE:0)
Block(7,-46,5,LOG:0)
Block(7,-46,6,SMOOTH_BRICK:0)
Block(7,-46,7,STONE:5)
Block(7,-46,8,LOG:0)
Block(7,-45,-7,LOG:0)
Block(7,-45,-6,STAINED_CLAY:9)
Block(7,-45,-5,STONE:5)
Block(7,-45,-4,LOG:0)
Block(7,-45,-3,STONE:5)
Block(7,-45,-2,COBBLESTONE:0)
Block(7,-45,-1,LOG:0)
Block(7,-45,0,SMOOTH_BRICK:2)
Block(7,-45,1,SMOOTH_BRICK:2)
Block(7,-45,2,LOG:0)
Block(7,-45,3,COBBLESTONE:0)
Block(7,-45,4,COBBLESTONE:0)
Block(7,-45,5,LOG:0)
Block(7,-45,6,SMOOTH_BRICK:0)
Block(7,-45,7,STONE:5)
Block(7,-45,8,LOG:0)
Block(7,-44,-7,LOG:0)
Block(7,-44,-6,STAINED_CLAY:9)
Block(7,-44,-5,STONE:5)
Block(7,-44,-4,LOG:0)
Block(7,-44,-3,STONE:5)
Block(7,-44,-2,COBBLESTONE:0)
Block(7,-44,-1,LOG:0)
Block(7,-44,0,SMOOTH_BRICK:2)
Block(7,-44,1,SMOOTH_BRICK:2)
Block(7,-44,2,LOG:0)
Block(7,-44,3,COBBLESTONE:0)
Block(7,-44,4,COBBLESTONE:0)
Block(7,-44,5,LOG:0)
Block(7,-44,6,SMOOTH_BRICK:0)
Block(7,-44,7,STONE:5)
Block(7,-44,8,LOG:0)
Block(7,-43,-7,LOG:0)
Block(7,-43,-6,STAINED_CLAY:9)
Block(7,-43,-5,STONE:5)
Block(7,-43,-4,LOG:0)
Block(7,-43,-3,STONE:5)
Block(7,-43,-2,COBBLESTONE:0)
Block(7,-43,-1,LOG:0)
Block(7,-43,0,SMOOTH_BRICK:2)
Block(7,-43,1,SMOOTH_BRICK:2)
Block(7,-43,2,LOG:0)
Block(7,-43,3,COBBLESTONE:0)
Block(7,-43,4,COBBLESTONE:0)
Block(7,-43,5,LOG:0)
Block(7,-43,6,SMOOTH_BRICK:0)
Block(7,-43,7,STONE:5)
Block(7,-43,8,LOG:0)
Block(7,-42,-7,LOG:0)
Block(7,-42,-6,STAINED_CLAY:9)
Block(7,-42,-5,STONE:5)
Block(7,-42,-4,LOG:0)
Block(7,-42,-3,STONE:5)
Block(7,-42,-2,COBBLESTONE:0)
Block(7,-42,-1,LOG:0)
Block(7,-42,0,SMOOTH_BRICK:2)
Block(7,-42,1,SMOOTH_BRICK:2)
Block(7,-42,2,LOG:0)
Block(7,-42,3,COBBLESTONE:0)
Block(7,-42,4,COBBLESTONE:0)
Block(7,-42,5,LOG:0)
Block(7,-42,6,SMOOTH_BRICK:0)
Block(7,-42,7,STONE:5)
Block(7,-42,8,LOG:0)
Block(7,-41,-7,LOG:0)
Block(7,-41,-6,STAINED_CLAY:9)
Block(7,-41,-5,STONE:5)
Block(7,-41,-4,LOG:0)
Block(7,-41,-3,STONE:5)
Block(7,-41,-2,COBBLESTONE:0)
Block(7,-41,-1,LOG:0)
Block(7,-41,0,SMOOTH_BRICK:2)
Block(7,-41,1,SMOOTH_BRICK:2)
Block(7,-41,2,LOG:0)
Block(7,-41,3,COBBLESTONE:0)
Block(7,-41,4,COBBLESTONE:0)
Block(7,-41,5,LOG:0)
Block(7,-41,6,SMOOTH_BRICK:0)
Block(7,-41,7,STONE:5)
Block(7,-41,8,LOG:0)
Block(7,-40,-7,LOG:0)
Block(7,-40,-6,STAINED_CLAY:9)
Block(7,-40,-5,STONE:5)
Block(7,-40,-4,LOG:0)
Block(7,-40,-3,STONE:5)
Block(7,-40,-2,COBBLESTONE:0)
Block(7,-40,-1,LOG:0)
Block(7,-40,0,SMOOTH_BRICK:2)
Block(7,-40,1,SMOOTH_BRICK:2)
Block(7,-40,2,LOG:0)
Block(7,-40,3,COBBLESTONE:0)
Block(7,-40,4,COBBLESTONE:0)
Block(7,-40,5,LOG:0)
Block(7,-40,6,SMOOTH_BRICK:0)
Block(7,-40,7,STONE:5)
Block(7,-40,8,LOG:0)
Block(7,-39,-7,LOG:0)
Block(7,-39,-6,STAINED_CLAY:9)
Block(7,-39,-5,STONE:5)
Block(7,-39,-4,LOG:0)
Block(7,-39,-3,STONE:5)
Block(7,-39,-2,COBBLESTONE:0)
Block(7,-39,-1,LOG:0)
Block(7,-39,0,SMOOTH_BRICK:2)
Block(7,-39,1,SMOOTH_BRICK:2)
Block(7,-39,2,LOG:0)
Block(7,-39,3,COBBLESTONE:0)
Block(7,-39,4,COBBLESTONE:0)
Block(7,-39,5,LOG:0)
Block(7,-39,6,SMOOTH_BRICK:0)
Block(7,-39,7,STONE:5)
Block(7,-39,8,LOG:0)
Block(7,-38,-7,LOG:0)
Block(7,-38,-6,STAINED_CLAY:9)
Block(7,-38,-5,STONE:5)
Block(7,-38,-4,LOG:0)
Block(7,-38,-3,STONE:5)
Block(7,-38,-2,COBBLESTONE:0)
Block(7,-38,-1,LOG:0)
Block(7,-38,0,SMOOTH_BRICK:2)
Block(7,-38,1,SMOOTH_BRICK:2)
Block(7,-38,2,LOG:0)
Block(7,-38,3,COBBLESTONE:0)
Block(7,-38,4,COBBLESTONE:0)
Block(7,-38,5,LOG:0)
Block(7,-38,6,SMOOTH_BRICK:0)
Block(7,-38,7,STONE:5)
Block(7,-38,8,LOG:0)
Block(7,-37,-7,LOG:0)
Block(7,-37,-6,STAINED_CLAY:9)
Block(7,-37,-5,STONE:5)
Block(7,-37,-4,LOG:0)
Block(7,-37,-3,STONE:5)
Block(7,-37,-2,COBBLESTONE:0)
Block(7,-37,-1,LOG:0)
Block(7,-37,0,SMOOTH_BRICK:2)
Block(7,-37,1,SMOOTH_BRICK:2)
Block(7,-37,2,LOG:0)
Block(7,-37,3,COBBLESTONE:0)
Block(7,-37,4,COBBLESTONE:0)
Block(7,-37,5,LOG:0)
Block(7,-37,6,SMOOTH_BRICK:0)
Block(7,-37,7,STONE:5)
Block(7,-37,8,LOG:0)
Block(7,-36,-7,LOG:0)
Block(7,-36,-6,STAINED_CLAY:9)
Block(7,-36,-5,STONE:5)
Block(7,-36,-4,LOG:0)
Block(7,-36,-3,STONE:5)
Block(7,-36,-2,COBBLESTONE:0)
Block(7,-36,-1,LOG:0)
Block(7,-36,0,SMOOTH_BRICK:2)
Block(7,-36,1,SMOOTH_BRICK:2)
Block(7,-36,2,LOG:0)
Block(7,-36,3,COBBLESTONE:0)
Block(7,-36,4,COBBLESTONE:0)
Block(7,-36,5,LOG:0)
Block(7,-36,6,SMOOTH_BRICK:0)
Block(7,-36,7,STONE:5)
Block(7,-36,8,LOG:0)
Block(7,-35,-7,LOG:0)
Block(7,-35,-6,STAINED_CLAY:9)
Block(7,-35,-5,STONE:5)
Block(7,-35,-4,LOG:0)
Block(7,-35,-3,STONE:5)
Block(7,-35,-2,COBBLESTONE:0)
Block(7,-35,-1,LOG:0)
Block(7,-35,0,SMOOTH_BRICK:2)
Block(7,-35,1,SMOOTH_BRICK:2)
Block(7,-35,2,LOG:0)
Block(7,-35,3,COBBLESTONE:0)
Block(7,-35,4,COBBLESTONE:0)
Block(7,-35,5,LOG:0)
Block(7,-35,6,SMOOTH_BRICK:0)
Block(7,-35,7,STONE:5)
Block(7,-35,8,LOG:0)
Block(7,-34,-7,LOG:0)
Block(7,-34,-6,STAINED_CLAY:9)
Block(7,-34,-5,STONE:5)
Block(7,-34,-4,LOG:0)
Block(7,-34,-3,STONE:5)
Block(7,-34,-2,COBBLESTONE:0)
Block(7,-34,-1,LOG:0)
Block(7,-34,0,SMOOTH_BRICK:2)
Block(7,-34,1,SMOOTH_BRICK:2)
Block(7,-34,2,LOG:0)
Block(7,-34,3,COBBLESTONE:0)
Block(7,-34,4,COBBLESTONE:0)
Block(7,-34,5,LOG:0)
Block(7,-34,6,SMOOTH_BRICK:0)
Block(7,-34,7,STONE:5)
Block(7,-34,8,LOG:0)
Block(7,-33,-7,LOG:0)
Block(7,-33,-6,STAINED_CLAY:9)
Block(7,-33,-5,STONE:5)
Block(7,-33,-4,LOG:0)
Block(7,-33,-3,STONE:5)
Block(7,-33,-2,COBBLESTONE:0)
Block(7,-33,-1,LOG:0)
Block(7,-33,0,SMOOTH_BRICK:2)
Block(7,-33,1,SMOOTH_BRICK:2)
Block(7,-33,2,LOG:0)
Block(7,-33,3,COBBLESTONE:0)
Block(7,-33,4,COBBLESTONE:0)
Block(7,-33,5,LOG:0)
Block(7,-33,6,SMOOTH_BRICK:0)
Block(7,-33,7,STONE:5)
Block(7,-33,8,LOG:0)
Block(7,-32,-7,LOG:0)
Block(7,-32,-6,STAINED_CLAY:9)
Block(7,-32,-5,STONE:5)
Block(7,-32,-4,LOG:0)
Block(7,-32,-3,STONE:5)
Block(7,-32,-2,COBBLESTONE:0)
Block(7,-32,-1,LOG:0)
Block(7,-32,0,SMOOTH_BRICK:2)
Block(7,-32,1,SMOOTH_BRICK:2)
Block(7,-32,2,LOG:0)
Block(7,-32,3,COBBLESTONE:0)
Block(7,-32,4,COBBLESTONE:0)
Block(7,-32,5,LOG:0)
Block(7,-32,6,SMOOTH_BRICK:0)
Block(7,-32,7,STONE:5)
Block(7,-32,8,LOG:0)
Block(7,-31,-7,LOG:0)
Block(7,-31,-6,STAINED_CLAY:9)
Block(7,-31,-5,STONE:5)
Block(7,-31,-4,LOG:0)
Block(7,-31,-3,STONE:5)
Block(7,-31,-2,COBBLESTONE:0)
Block(7,-31,-1,LOG:0)
Block(7,-31,0,SMOOTH_BRICK:2)
Block(7,-31,1,SMOOTH_BRICK:2)
Block(7,-31,2,LOG:0)
Block(7,-31,3,COBBLESTONE:0)
Block(7,-31,4,COBBLESTONE:0)
Block(7,-31,5,LOG:0)
Block(7,-31,6,SMOOTH_BRICK:0)
Block(7,-31,7,STONE:5)
Block(7,-31,8,LOG:0)
Block(7,-30,-7,LOG:0)
Block(7,-30,-6,STAINED_CLAY:9)
Block(7,-30,-5,STONE:5)
Block(7,-30,-4,LOG:0)
Block(7,-30,-3,STONE:5)
Block(7,-30,-2,COBBLESTONE:0)
Block(7,-30,-1,LOG:0)
Block(7,-30,0,SMOOTH_BRICK:2)
Block(7,-30,1,SMOOTH_BRICK:2)
Block(7,-30,2,LOG:0)
Block(7,-30,3,COBBLESTONE:0)
Block(7,-30,4,COBBLESTONE:0)
Block(7,-30,5,LOG:0)
Block(7,-30,6,SMOOTH_BRICK:0)
Block(7,-30,7,STONE:5)
Block(7,-30,8,LOG:0)
Block(7,-29,-7,LOG:0)
Block(7,-29,-6,STAINED_CLAY:9)
Block(7,-29,-5,STONE:5)
Block(7,-29,-4,LOG:0)
Block(7,-29,-3,STONE:5)
Block(7,-29,-2,COBBLESTONE:0)
Block(7,-29,-1,LOG:0)
Block(7,-29,0,SMOOTH_BRICK:2)
Block(7,-29,1,SMOOTH_BRICK:2)
Block(7,-29,2,LOG:0)
Block(7,-29,3,COBBLESTONE:0)
Block(7,-29,4,COBBLESTONE:0)
Block(7,-29,5,LOG:0)
Block(7,-29,6,SMOOTH_BRICK:0)
Block(7,-29,7,STONE:5)
Block(7,-29,8,LOG:0)
Block(7,-28,-7,LOG:0)
Block(7,-28,-6,STAINED_CLAY:9)
Block(7,-28,-5,STONE:5)
Block(7,-28,-4,LOG:0)
Block(7,-28,-3,STONE:5)
Block(7,-28,-2,COBBLESTONE:0)
Block(7,-28,-1,LOG:0)
Block(7,-28,0,SMOOTH_BRICK:2)
Block(7,-28,1,SMOOTH_BRICK:2)
Block(7,-28,2,LOG:0)
Block(7,-28,3,COBBLESTONE:0)
Block(7,-28,4,COBBLESTONE:0)
Block(7,-28,5,LOG:0)
Block(7,-28,6,SMOOTH_BRICK:0)
Block(7,-28,7,STONE:5)
Block(7,-28,8,LOG:0)
Block(7,-27,-7,LOG:0)
Block(7,-27,-6,STAINED_CLAY:9)
Block(7,-27,-5,STONE:5)
Block(7,-27,-4,LOG:0)
Block(7,-27,-3,STONE:5)
Block(7,-27,-2,COBBLESTONE:0)
Block(7,-27,-1,LOG:0)
Block(7,-27,0,SMOOTH_BRICK:2)
Block(7,-27,1,SMOOTH_BRICK:2)
Block(7,-27,2,LOG:0)
Block(7,-27,3,COBBLESTONE:0)
Block(7,-27,4,COBBLESTONE:0)
Block(7,-27,5,LOG:0)
Block(7,-27,6,SMOOTH_BRICK:0)
Block(7,-27,7,STONE:5)
Block(7,-27,8,LOG:0)
Block(7,-26,-7,LOG:0)
Block(7,-26,-6,STAINED_CLAY:9)
Block(7,-26,-5,STONE:5)
Block(7,-26,-4,LOG:0)
Block(7,-26,-3,STONE:5)
Block(7,-26,-2,COBBLESTONE:0)
Block(7,-26,-1,LOG:0)
Block(7,-26,0,SMOOTH_BRICK:2)
Block(7,-26,1,SMOOTH_BRICK:2)
Block(7,-26,2,LOG:0)
Block(7,-26,3,COBBLESTONE:0)
Block(7,-26,4,COBBLESTONE:0)
Block(7,-26,5,LOG:0)
Block(7,-26,6,SMOOTH_BRICK:0)
Block(7,-26,7,STONE:5)
Block(7,-26,8,LOG:0)
Block(7,-25,-7,LOG:0)
Block(7,-25,-6,STAINED_CLAY:9)
Block(7,-25,-5,STONE:5)
Block(7,-25,-4,LOG:0)
Block(7,-25,-3,STONE:5)
Block(7,-25,-2,COBBLESTONE:0)
Block(7,-25,-1,LOG:0)
Block(7,-25,0,SMOOTH_BRICK:2)
Block(7,-25,1,SMOOTH_BRICK:2)
Block(7,-25,2,LOG:0)
Block(7,-25,3,COBBLESTONE:0)
Block(7,-25,4,COBBLESTONE:0)
Block(7,-25,5,LOG:0)
Block(7,-25,6,SMOOTH_BRICK:0)
Block(7,-25,7,STONE:5)
Block(7,-25,8,LOG:0)
Block(7,-24,-7,LOG:0)
Block(7,-24,-6,STAINED_CLAY:9)
Block(7,-24,-5,STONE:5)
Block(7,-24,-4,LOG:0)
Block(7,-24,-3,STONE:5)
Block(7,-24,-2,COBBLESTONE:0)
Block(7,-24,-1,LOG:0)
Block(7,-24,0,SMOOTH_BRICK:2)
Block(7,-24,1,SMOOTH_BRICK:2)
Block(7,-24,2,LOG:0)
Block(7,-24,3,COBBLESTONE:0)
Block(7,-24,4,COBBLESTONE:0)
Block(7,-24,5,LOG:0)
Block(7,-24,6,SMOOTH_BRICK:0)
Block(7,-24,7,STONE:5)
Block(7,-24,8,LOG:0)
Block(7,-23,-7,LOG:0)
Block(7,-23,-6,STAINED_CLAY:9)
Block(7,-23,-5,STONE:5)
Block(7,-23,-4,LOG:0)
Block(7,-23,-3,STONE:5)
Block(7,-23,-2,COBBLESTONE:0)
Block(7,-23,-1,LOG:0)
Block(7,-23,0,SMOOTH_BRICK:2)
Block(7,-23,1,SMOOTH_BRICK:2)
Block(7,-23,2,LOG:0)
Block(7,-23,3,COBBLESTONE:0)
Block(7,-23,4,COBBLESTONE:0)
Block(7,-23,5,LOG:0)
Block(7,-23,6,SMOOTH_BRICK:0)
Block(7,-23,7,STONE:5)
Block(7,-23,8,LOG:0)
Block(7,-22,-7,LOG:0)
Block(7,-22,-6,STAINED_CLAY:9)
Block(7,-22,-5,STONE:5)
Block(7,-22,-4,LOG:0)
Block(7,-22,-3,STONE:5)
Block(7,-22,-2,COBBLESTONE:0)
Block(7,-22,-1,LOG:0)
Block(7,-22,0,SMOOTH_BRICK:2)
Block(7,-22,1,SMOOTH_BRICK:2)
Block(7,-22,2,LOG:0)
Block(7,-22,3,COBBLESTONE:0)
Block(7,-22,4,COBBLESTONE:0)
Block(7,-22,5,LOG:0)
Block(7,-22,6,SMOOTH_BRICK:0)
Block(7,-22,7,STONE:5)
Block(7,-22,8,LOG:0)
Block(7,-21,-7,LOG:0)
Block(7,-21,-6,STAINED_CLAY:9)
Block(7,-21,-5,STONE:5)
Block(7,-21,-4,LOG:0)
Block(7,-21,-3,STONE:5)
Block(7,-21,-2,COBBLESTONE:0)
Block(7,-21,-1,LOG:0)
Block(7,-21,0,SMOOTH_BRICK:2)
Block(7,-21,1,SMOOTH_BRICK:2)
Block(7,-21,2,LOG:0)
Block(7,-21,3,COBBLESTONE:0)
Block(7,-21,4,COBBLESTONE:0)
Block(7,-21,5,LOG:0)
Block(7,-21,6,SMOOTH_BRICK:0)
Block(7,-21,7,STONE:5)
Block(7,-21,8,LOG:0)
Block(7,-20,-7,LOG:0)
Block(7,-20,-6,STAINED_CLAY:9)
Block(7,-20,-5,STONE:5)
Block(7,-20,-4,LOG:0)
Block(7,-20,-3,STONE:5)
Block(7,-20,-2,COBBLESTONE:0)
Block(7,-20,-1,LOG:0)
Block(7,-20,0,SMOOTH_BRICK:2)
Block(7,-20,1,SMOOTH_BRICK:2)
Block(7,-20,2,LOG:0)
Block(7,-20,3,COBBLESTONE:0)
Block(7,-20,4,COBBLESTONE:0)
Block(7,-20,5,LOG:0)
Block(7,-20,6,SMOOTH_BRICK:0)
Block(7,-20,7,STONE:5)
Block(7,-20,8,LOG:0)
Block(7,-19,-7,LOG:0)
Block(7,-19,-6,STAINED_CLAY:9)
Block(7,-19,-5,COBBLESTONE:0)
Block(7,-19,-4,LOG:0)
Block(7,-19,-3,SMOOTH_BRICK:0)
Block(7,-19,-2,STONE:5)
Block(7,-19,-1,LOG:0)
Block(7,-19,0,STONE:5)
Block(7,-19,1,STONE:5)
Block(7,-19,2,LOG:0)
Block(7,-19,3,COBBLESTONE:0)
Block(7,-19,4,COBBLESTONE:0)
Block(7,-19,5,LOG:0)
Block(7,-19,6,STONE:5)
Block(7,-19,7,STONE:5)
Block(7,-19,8,LOG:0)
Block(7,-18,-7,LOG:0)
Block(7,-18,-6,STONE:5)
Block(7,-18,-5,COBBLESTONE:0)
Block(7,-18,-4,LOG:0)
Block(7,-18,-3,STONE:5)
Block(7,-18,-2,COBBLESTONE:0)
Block(7,-18,-1,LOG:0)
Block(7,-18,0,COBBLESTONE:0)
Block(7,-18,1,COBBLESTONE:0)
Block(7,-18,2,LOG:0)
Block(7,-18,3,COBBLESTONE:0)
Block(7,-18,4,COBBLESTONE:0)
Block(7,-18,5,LOG:0)
Block(7,-18,6,COBBLESTONE:0)
Block(7,-18,7,COBBLESTONE:0)
Block(7,-18,8,LOG:0)
Block(7,-17,-7,LOG:0)
Block(7,-17,-6,COBBLESTONE:0)
Block(7,-17,-5,COBBLESTONE:0)
Block(7,-17,-4,LOG:0)
Block(7,-17,-3,STONE:5)
Block(7,-17,-2,COBBLESTONE:0)
Block(7,-17,-1,LOG:0)
Block(7,-17,0,STONE:5)
Block(7,-17,1,STONE:5)
Block(7,-17,2,LOG:0)
Block(7,-17,3,COBBLESTONE:0)
Block(7,-17,4,STONE:5)
Block(7,-17,5,LOG:0)
Block(7,-17,6,STONE:5)
Block(7,-17,7,COBBLESTONE:0)
Block(7,-17,8,LOG:0)
Block(7,-16,-7,LOG:0)
Block(7,-16,-6,STONE:5)
Block(7,-16,-5,COBBLESTONE:0)
Block(7,-16,-4,LOG:0)
Block(7,-16,-3,STONE:5)
Block(7,-16,-2,COBBLESTONE:0)
Block(7,-16,-1,LOG:0)
Block(7,-16,0,COBBLESTONE:0)
Block(7,-16,1,STONE:5)
Block(7,-16,2,LOG:0)
Block(7,-16,3,STONE:5)
Block(7,-16,4,COBBLESTONE:0)
Block(7,-16,5,LOG:0)
Block(7,-16,6,SMOOTH_BRICK:2)
Block(7,-16,7,STONE:5)
Block(7,-16,8,LOG:0)
Block(7,-15,-7,LOG:0)
Block(7,-15,-6,STONE:5)
Block(7,-15,-5,COBBLESTONE:0)
Block(7,-15,-4,LOG:0)
Block(7,-15,-3,COBBLESTONE:0)
Block(7,-15,-2,STAINED_CLAY:9)
Block(7,-15,-1,LOG:0)
Block(7,-15,0,SMOOTH_BRICK:0)
Block(7,-15,1,COBBLESTONE:0)
Block(7,-15,2,LOG:0)
Block(7,-15,3,COBBLESTONE:0)
Block(7,-15,4,STONE:5)
Block(7,-15,5,LOG:0)
Block(7,-15,6,STONE:5)
Block(7,-15,7,STAINED_CLAY:9)
Block(7,-15,8,LOG:0)
Block(7,-14,-7,LOG:0)
Block(7,-14,-6,COBBLESTONE:0)
Block(7,-14,-5,SMOOTH_BRICK:2)
Block(7,-14,-4,LOG:0)
Block(7,-14,-3,COBBLESTONE:0)
Block(7,-14,-2,STAINED_CLAY:9)
Block(7,-14,-1,LOG:0)
Block(7,-14,0,COBBLESTONE:0)
Block(7,-14,1,COBBLESTONE:0)
Block(7,-14,2,LOG:0)
Block(7,-14,3,COBBLESTONE:0)
Block(7,-14,4,SMOOTH_BRICK:1)
Block(7,-14,5,LOG:0)
Block(7,-14,6,SMOOTH_BRICK:2)
Block(7,-14,7,COBBLESTONE:0)
Block(7,-14,8,LOG:0)
Block(7,-13,-7,LOG:0)
Block(7,-13,-6,SMOOTH_BRICK:1)
Block(7,-13,-5,STONE:5)
Block(7,-13,-4,LOG:0)
Block(7,-13,-3,COBBLESTONE:0)
Block(7,-13,-2,COBBLESTONE:0)
Block(7,-13,-1,LOG:0)
Block(7,-13,0,SMOOTH_BRICK:0)
Block(7,-13,1,STONE:5)
Block(7,-13,2,LOG:0)
Block(7,-13,3,SMOOTH_BRICK:0)
Block(7,-13,4,STAINED_CLAY:9)
Block(7,-13,5,LOG:0)
Block(7,-13,6,COBBLESTONE:0)
Block(7,-13,7,COBBLESTONE:0)
Block(7,-13,8,LOG:0)
Block(7,-12,-7,LOG:0)
Block(7,-12,-6,STONE:5)
Block(7,-12,-5,STONE:5)
Block(7,-12,-4,LOG:0)
Block(7,-12,-3,STONE:5)
Block(7,-12,-2,STONE:5)
Block(7,-12,-1,LOG:0)
Block(7,-12,0,STONE:5)
Block(7,-12,1,SMOOTH_BRICK:2)
Block(7,-12,2,LOG:0)
Block(7,-12,3,COBBLESTONE:0)
Block(7,-12,4,COBBLESTONE:0)
Block(7,-12,5,LOG:0)
Block(7,-12,6,SMOOTH_BRICK:1)
Block(7,-12,7,COBBLESTONE:0)
Block(7,-12,8,LOG:0)
Block(7,-11,-7,LOG:0)
Block(7,-11,-6,STONE:5)
Block(7,-11,-5,SMOOTH_BRICK:1)
Block(7,-11,-4,LOG:0)
Block(7,-11,-3,SMOOTH_BRICK:0)
Block(7,-11,-2,COBBLESTONE:0)
Block(7,-11,-1,LOG:0)
Block(7,-11,0,COBBLESTONE:0)
Block(7,-11,1,COBBLESTONE:0)
Block(7,-11,2,LOG:0)
Block(7,-11,3,COBBLESTONE:0)
Block(7,-11,4,COBBLESTONE:0)
Block(7,-11,5,LOG:0)
Block(7,-11,6,SMOOTH_BRICK:2)
Block(7,-11,7,COBBLESTONE:0)
Block(7,-11,8,LOG:0)
Block(7,-10,-7,LOG:0)
Block(7,-10,-6,COBBLESTONE:0)
Block(7,-10,-5,SMOOTH_BRICK:0)
Block(7,-10,-4,LOG:0)
Block(7,-10,-3,SMOOTH_BRICK:0)
Block(7,-10,-2,STONE:5)
Block(7,-10,-1,LOG:0)
Block(7,-10,0,COBBLESTONE:0)
Block(7,-10,1,COBBLESTONE:0)
Block(7,-10,2,LOG:0)
Block(7,-10,3,COBBLESTONE:0)
Block(7,-10,4,STONE:5)
Block(7,-10,5,LOG:0)
Block(7,-10,6,STONE:5)
Block(7,-10,7,STONE:5)
Block(7,-10,8,LOG:0)
Block(7,-9,-7,STONE:6)
Block(7,-9,-6,STONE:6)
Block(7,-9,-5,STONE:6)
Block(7,-9,-4,STONE:6)
Block(7,-9,-3,STONE:6)
Block(7,-9,-2,STONE:6)
Block(7,-9,-1,STONE:6)
Block(7,-9,0,STONE:6)
Block(7,-9,1,COBBLESTONE_STAIRS:3)
Block(7,-9,2,SMOOTH_STAIRS:0)
Block(7,-9,3,COBBLESTONE_STAIRS:0)
Block(7,-9,4,COBBLESTONE_STAIRS:0)
Block(7,-9,5,SMOOTH_STAIRS:0)
Block(7,-9,6,COBBLESTONE_STAIRS:0)
Block(7,-9,7,COBBLESTONE_STAIRS:0)
Block(7,-9,8,SMOOTH_STAIRS:0)
Block(7,-8,-7,STONE:6)
Block(7,-8,-6,STONE:6)
Block(7,-8,-5,STONE:6)
Block(7,-8,-4,STONE:6)
Block(7,-8,-3,STONE:6)
Block(7,-8,-2,STONE:6)
Block(7,-8,-1,STONE:6)
Block(7,-8,0,STONE:6)
Block(7,-7,-7,STONE:6)
Block(7,-7,-6,STONE:6)
Block(7,-7,-5,STONE:6)
Block(7,-7,-4,STONE:6)
Block(7,-7,-3,STONE:6)
Block(7,-7,-2,STONE:6)
Block(7,-7,-1,STONE:6)
Block(7,-7,0,STONE:6)
Block(7,-6,-7,STONE:6)
Block(7,-6,-6,STONE:6)
Block(7,-6,-5,STONE:6)
Block(7,-6,-4,STONE:6)
Block(7,-6,-3,STONE:6)
Block(7,-6,-2,STONE:6)
Block(7,-6,-1,STONE:6)
Block(7,-6,0,STONE:6)
Block(7,-5,-7,COBBLESTONE:0)
Block(7,-5,-6,STONE:5)
Block(7,-5,-5,COBBLESTONE:0)
Block(7,-5,-4,COBBLESTONE:0)
Block(7,-5,-3,STONE:5)
Block(7,-5,-2,STONE:5)
Block(7,-5,-1,COBBLESTONE_STAIRS:3)
Block(7,-5,0,COBBLESTONE_STAIRS:0)
Block(7,-4,-7,STONE:6)
Block(7,-4,-6,STONE:6)
Block(7,-4,-5,STONE:6)
Block(7,-4,-4,STONE:6)
Block(7,-4,-3,STONE:6)
Block(7,-4,-2,LOG:0)
Block(7,-3,-7,STONE:6)
Block(7,-3,-6,STONE:6)
Block(7,-3,-5,STONE:6)
Block(7,-3,-4,STONE:6)
Block(7,-3,-3,STONE:6)
Block(7,-3,-2,LOG:0)
Block(7,-2,-7,STONE:6)
Block(7,-2,-6,STONE:6)
Block(7,-2,-5,STONE:6)
Block(7,-2,-4,STONE:6)
Block(7,-2,-3,STONE:6)
Block(7,-2,-2,LOG:0)
Block(7,-1,-7,STONE:6)
Block(7,-1,-6,STONE:6)
Block(7,-1,-5,STONE:6)
Block(7,-1,-4,STONE:6)
Block(7,-1,-3,STONE:6)
Block(7,-1,-2,LOG:0)
Block(7,0,-7,STONE:6)
Block(7,0,-6,STONE:6)
Block(7,0,-5,STONE:6)
Block(7,0,-4,STONE:6)
Block(7,0,-3,STONE:6)
Block(7,0,-2,LOG:0)
Block(7,1,-7,STONE:6)
Block(7,1,-6,STONE:6)
Block(7,1,-5,STONE:6)
Block(7,1,-4,STONE:6)
Block(7,1,-3,STONE:6)
Block(7,1,-2,LOG:0)
Block(7,2,-7,STONE:6)
Block(7,2,-6,STONE:6)
Block(7,2,-5,STONE:6)
Block(7,2,-4,STONE:6)
Block(7,2,-3,STONE:6)
Block(7,2,-2,LOG:0)
Block(7,3,-7,STONE:6)
Block(7,3,-6,STONE:6)
Block(7,3,-5,STONE:6)
Block(7,3,-4,STONE:6)
Block(7,3,-3,STONE:6)
Block(7,3,-2,LOG:0)
Block(7,4,-7,STONE:6)
Block(7,4,-6,STONE:6)
Block(7,4,-5,STONE:6)
Block(7,4,-4,STONE:6)
Block(7,4,-3,STONE:6)
Block(7,4,-2,LOG:0)
Block(7,5,-7,STONE:6)
Block(7,5,-6,STONE:6)
Block(7,5,-5,STONE:6)
Block(7,5,-4,STONE:6)
Block(7,5,-3,STONE:6)
Block(7,5,-2,LOG:0)
Block(7,6,-7,SMOOTH_BRICK:0)
Block(7,6,-6,SMOOTH_BRICK:0)
Block(7,6,-5,SMOOTH_BRICK:0)
Block(7,6,-4,COBBLESTONE_STAIRS:0)
Block(7,6,-3,DARK_OAK_FENCE:0)
Block(7,6,-2,LOG:0)
Block(7,7,-7,COBBLESTONE:0)
Block(7,7,-6,SMOOTH_BRICK:0)
Block(7,7,-5,COBBLESTONE_STAIRS:4)
Block(7,7,-4,COBBLESTONE_STAIRS:4)
Block(7,7,-3,AIR:0)
Block(7,7,-2,LOG:0)
Block(7,8,-7,COBBLESTONE:0)
Block(7,8,-6,COBBLESTONE:0)
Block(7,8,-5,SMOOTH_BRICK:0)
Block(7,8,-4,SMOOTH_BRICK:0)
Block(7,8,-3,SMOOTH_STAIRS:7)
Block(7,8,-2,LOG:0)
Block(7,9,-7,SMOOTH_BRICK:0)
Block(7,9,-6,SMOOTH_BRICK:0)
Block(7,9,-5,SMOOTH_BRICK:0)
Block(7,9,-4,SMOOTH_BRICK:0)
Block(7,9,-3,SMOOTH_BRICK:0)
Block(7,9,-2,LOG:0)
Block(7,10,-7,AIR:0)
Block(7,10,-6,AIR:0)
Block(7,10,-5,SMOOTH_BRICK:0)
Block(7,10,-4,SMOOTH_STAIRS:0)
Block(7,10,-3,SMOOTH_BRICK:0)
Block(7,10,-2,LOG:0)
Block(7,11,-7,AIR:0)
Block(7,11,-6,AIR:0)
Block(7,11,-5,SMOOTH_BRICK:0)
Block(7,11,-4,SMOOTH_STAIRS:0)
Block(7,11,-3,SMOOTH_BRICK:0)
Block(7,11,-2,LOG:0)
Block(7,12,-7,AIR:0)
Block(7,12,-6,AIR:0)
Block(7,12,-5,SMOOTH_BRICK:0)
Block(7,12,-4,SMOOTH_STAIRS:0)
Block(7,12,-3,SMOOTH_BRICK:0)
Block(7,12,-2,LOG:0)
Block(7,13,-7,LOG:8)
Block(7,13,-6,LOG:8)
Block(7,13,-5,LOG:8)
Block(7,13,-4,LOG:8)
Block(7,13,-3,LOG:8)
Block(7,13,-2,LOG:0)
Block(7,14,-7,AIR:0)
Block(7,14,-6,DARK_OAK_STAIRS:2)
Block(7,14,-5,WOOD_DOUBLE_STEP:5)
Block(7,14,-4,SMOOTH_BRICK:2)
Block(7,14,-3,LOG:0)
Block(7,14,-2,STEP:5)
Block(7,15,-7,AIR:0)
Block(7,15,-6,AIR:0)
Block(7,15,-5,BED_BLOCK:3,origin/143-bedC48R32.nbt)
Block(7,15,-4,SMOOTH_BRICK:2)
Block(7,15,-3,LOG:0)
Block(7,15,-2,SMOOTH_STAIRS:7)
Block(7,16,-7,AIR:0)
Block(7,16,-6,WALL_BANNER:2,origin/145-bannerC48R32.nbt)
Block(7,16,-5,WOOD_STEP:13)
Block(7,16,-4,SMOOTH_BRICK:2)
Block(7,16,-3,LOG:0)
Block(7,16,-2,COBBLE_WALL:0)
Block(7,17,-7,LOG:8)
Block(7,17,-6,LOG:8)
Block(7,17,-5,LOG:8)
Block(7,17,-4,LOG:8)
Block(7,17,-3,LOG:0)
Block(7,17,-2,COBBLE_WALL:0)
Block(7,18,-7,LOG:0)
Block(7,18,-6,WOOD_STEP:13)
Block(7,18,-5,WOOD_STEP:13)
Block(7,18,-4,WOOD_STEP:13)
Block(7,18,-3,LOG:0)
Block(7,18,-2,COBBLE_WALL:0)
Block(7,19,-7,WOOD_STEP:5)
Block(7,19,-6,WOOD_STEP:5)
Block(7,19,-5,AIR:0)
Block(7,19,-4,AIR:0)
Block(7,19,-3,LOG:0)
Block(7,19,-2,SMOOTH_STAIRS:3)
Block(7,20,-7,AIR:0)
Block(7,20,-6,AIR:0)
Block(7,20,-5,AIR:0)
Block(7,20,-4,AIR:0)
Block(7,20,-3,STEP:5)
Block(7,20,-2,STEP:5)
Block(7,21,-7,AIR:0)
Block(7,21,-6,AIR:0)
Block(7,21,-5,AIR:0)
Block(7,21,-4,AIR:0)
Block(7,21,-3,AIR:0)
Block(7,21,-2,AIR:0)
Block(7,22,-7,AIR:0)
Block(7,22,-6,AIR:0)
Block(7,22,-5,AIR:0)
Block(7,22,-4,AIR:0)
Block(7,22,-3,AIR:0)
Block(7,22,-2,AIR:0)
Block(7,23,-7,AIR:0)
Block(7,23,-6,AIR:0)
Block(7,23,-5,AIR:0)
Block(7,23,-4,AIR:0)
Block(7,23,-3,AIR:0)
Block(7,23,-2,AIR:0)
Block(7,24,-7,AIR:0)
Block(7,24,-6,AIR:0)
Block(7,24,-5,AIR:0)
Block(7,24,-4,AIR:0)
Block(7,24,-3,AIR:0)
Block(7,24,-2,AIR:0)
Block(7,25,-7,AIR:0)
Block(7,25,-6,AIR:0)
Block(7,25,-5,AIR:0)
Block(7,25,-4,AIR:0)
Block(7,25,-3,AIR:0)
Block(7,25,-2,AIR:0)
Block(7,26,-7,AIR:0)
Block(7,26,-6,AIR:0)
Block(7,26,-5,AIR:0)
Block(7,26,-4,AIR:0)
Block(7,26,-3,AIR:0)
Block(7,26,-2,AIR:0)
Block(7,27,-7,AIR:0)
Block(7,27,-6,AIR:0)
Block(7,27,-5,AIR:0)
Block(7,27,-4,AIR:0)
Block(7,27,-3,AIR:0)
Block(7,27,-2,AIR:0)
Block(7,28,-7,AIR:0)
Block(7,28,-6,AIR:0)
Block(7,28,-5,AIR:0)
Block(7,28,-4,AIR:0)
Block(7,28,-3,AIR:0)
Block(7,28,-2,AIR:0)
Block(7,29,-7,AIR:0)
Block(7,29,-6,AIR:0)
Block(7,29,-5,AIR:0)
Block(7,29,-4,AIR:0)
Block(7,29,-3,AIR:0)
Block(7,29,-2,AIR:0)
Block(7,30,-7,AIR:0)
Block(7,30,-6,AIR:0)
Block(7,30,-5,AIR:0)
Block(7,30,-4,AIR:0)
Block(7,30,-3,AIR:0)
Block(7,30,-2,AIR:0)
Block(7,31,-7,AIR:0)
Block(7,31,-6,AIR:0)
Block(7,31,-5,AIR:0)
Block(7,31,-4,AIR:0)
Block(7,31,-3,AIR:0)
Block(7,31,-2,AIR:0)
Block(7,32,-7,AIR:0)
Block(7,32,-6,AIR:0)
Block(7,32,-5,AIR:0)
Block(7,32,-4,AIR:0)
Block(7,32,-3,AIR:0)
Block(7,32,-2,AIR:0)
Block(7,33,-7,AIR:0)
Block(7,33,-6,AIR:0)
Block(7,33,-5,AIR:0)
Block(7,33,-4,AIR:0)
Block(7,33,-3,AIR:0)
Block(7,33,-2,AIR:0)
Block(7,34,-7,AIR:0)
Block(7,34,-6,AIR:0)
Block(7,34,-5,AIR:0)
Block(7,34,-4,AIR:0)
Block(7,34,-3,AIR:0)
Block(7,34,-2,AIR:0)
Block(7,35,-7,AIR:0)
Block(7,35,-6,AIR:0)
Block(7,35,-5,AIR:0)
Block(7,35,-4,AIR:0)
Block(7,35,-3,AIR:0)
Block(7,35,-2,AIR:0)
Block(7,36,-7,AIR:0)
Block(7,36,-6,AIR:0)
Block(7,36,-5,AIR:0)
Block(7,36,-4,AIR:0)
Block(7,36,-3,AIR:0)
Block(7,36,-2,AIR:0)
Block(7,37,-7,AIR:0)
Block(7,37,-6,AIR:0)
Block(7,37,-5,AIR:0)
Block(7,37,-4,AIR:0)
Block(7,37,-3,AIR:0)
Block(7,37,-2,AIR:0)
Block(7,38,-7,AIR:0)
Block(7,38,-6,AIR:0)
Block(7,38,-5,AIR:0)
Block(7,38,-4,AIR:0)
Block(7,38,-3,AIR:0)
Block(7,38,-2,AIR:0)
Block(7,39,-7,AIR:0)
Block(7,39,-6,AIR:0)
Block(7,39,-5,AIR:0)
Block(7,39,-4,AIR:0)
Block(7,39,-3,AIR:0)
Block(7,39,-2,AIR:0)
Block(7,40,-7,AIR:0)
Block(7,40,-6,AIR:0)
Block(7,40,-5,AIR:0)
Block(7,40,-4,AIR:0)
Block(7,40,-3,AIR:0)
Block(7,40,-2,AIR:0)
Block(7,41,-7,AIR:0)
Block(7,41,-6,AIR:0)
Block(7,41,-5,AIR:0)
Block(7,41,-4,AIR:0)
Block(7,41,-3,AIR:0)
Block(7,41,-2,AIR:0)
Block(7,42,-7,AIR:0)
Block(7,42,-6,AIR:0)
Block(7,42,-5,AIR:0)
Block(7,42,-4,AIR:0)
Block(7,42,-3,AIR:0)
Block(7,42,-2,AIR:0)
Block(7,43,-7,AIR:0)
Block(7,43,-6,AIR:0)
Block(7,43,-5,AIR:0)
Block(7,43,-4,AIR:0)
Block(7,43,-3,AIR:0)
Block(7,43,-2,AIR:0)
Block(7,44,-7,AIR:0)
Block(7,44,-6,AIR:0)
Block(7,44,-5,AIR:0)
Block(7,44,-4,AIR:0)
Block(7,44,-3,AIR:0)
Block(7,44,-2,AIR:0)
Block(7,45,-7,AIR:0)
Block(7,45,-6,AIR:0)
Block(7,45,-5,AIR:0)
Block(7,45,-4,AIR:0)
Block(7,45,-3,AIR:0)
Block(7,45,-2,AIR:0)
Block(7,46,-7,AIR:0)
Block(7,46,-6,AIR:0)
Block(7,46,-5,AIR:0)
Block(7,46,-4,AIR:0)
Block(7,46,-3,AIR:0)
Block(7,46,-2,AIR:0)
Block(7,47,-7,AIR:0)
Block(7,47,-6,AIR:0)
Block(7,47,-5,AIR:0)
Block(7,47,-4,AIR:0)
Block(7,47,-3,AIR:0)
Block(7,47,-2,AIR:0)
Block(7,48,-7,AIR:0)
Block(7,48,-6,AIR:0)
Block(7,48,-5,AIR:0)
Block(7,48,-4,AIR:0)
Block(7,48,-3,AIR:0)
Block(7,48,-2,AIR:0)
Block(7,49,-7,AIR:0)
Block(7,49,-6,AIR:0)
Block(7,49,-5,AIR:0)
Block(7,49,-4,AIR:0)
Block(7,49,-3,AIR:0)
Block(7,49,-2,AIR:0)
Block(7,50,-7,AIR:0)
Block(7,50,-6,AIR:0)
Block(7,50,-5,AIR:0)
Block(7,50,-4,AIR:0)
Block(7,50,-3,AIR:0)
Block(7,50,-2,AIR:0)
Block(7,51,-7,AIR:0)
Block(7,51,-6,AIR:0)
Block(7,51,-5,AIR:0)
Block(7,51,-4,AIR:0)
Block(7,51,-3,AIR:0)
Block(7,51,-2,AIR:0)
Block(7,52,-7,AIR:0)
Block(7,52,-6,AIR:0)
Block(7,52,-5,AIR:0)
Block(7,52,-4,AIR:0)
Block(7,52,-3,AIR:0)
Block(7,52,-2,AIR:0)
Branch(0,0,-16,true,originC3R1,NORTH,100.0,0)
