Author: NLBlackEagle
Description: No description given
SettingsMode: WriteDisable
Frequency: 0
SpawnHeight: highestBlock
UseCenterForHighestBlock: true
MinHeight: 0
MaxHeight: 255
InheritBO3: 
InheritBO3Rotation: NORTH
OverrideChildSettings: true
OverrideParentHeight: false
CanOverride: false
BranchFrequency: 0
BranchFrequencyGroup: 
MustBeBelowOther: false
MustBeInside: 
CannotBeInside: 
ReplacesBO3: 
MustBeInsideWorldBorders: false
CanSpawnOnWater: true
SpawnOnWaterOnly: false
SpawnUnderWater: false
SpawnAtWaterLevel: false
HeightOffset: 0
RemoveAir: false
ReplaceAbove: 
ReplaceBelow: 
ReplaceWithBiomeBlocks: false
ReplaceWithSurfaceBlock: GRASS
ReplaceWithGroundBlock: DIRT
ReplaceWithStoneBlock: STONE
SmoothRadius: 0
SmoothHeightOffset: 0
SmoothStartTop: false
SmoothStartWood: false
SmoothingSurfaceBlock: 
SmoothingGroundBlock: 
BO3Group: 
IsSpawnPoint: false
DoReplaceBlocks: false
Block(-8,-50,-7,COBBLESTONE:0)
Block(-8,-50,-6,COBBLESTONE:0)
Block(-8,-50,-5,COBBLESTONE:0)
Block(-8,-50,-4,COBBLESTONE:0)
Block(-8,-50,-3,COBBLESTONE:0)
Block(-8,-50,-2,COBBLESTONE:0)
Block(-8,-50,-1,COBBLESTONE:0)
Block(-8,-50,0,COBBLESTONE:0)
Block(-8,-50,1,COBBLESTONE:0)
Block(-8,-50,2,COBBLESTONE:0)
Block(-8,-50,3,COBBLESTONE:0)
Block(-8,-50,4,COBBLESTONE:0)
Block(-8,-50,5,STONE:5)
Block(-8,-49,-7,COBBLESTONE:0)
Block(-8,-49,-6,COBBLESTONE:0)
Block(-8,-49,-5,COBBLESTONE:0)
Block(-8,-49,-4,COBBLESTONE:0)
Block(-8,-49,-3,COBBLESTONE:0)
Block(-8,-49,-2,COBBLESTONE:0)
Block(-8,-49,-1,COBBLESTONE:0)
Block(-8,-49,0,COBBLESTONE:0)
Block(-8,-49,1,COBBLESTONE:0)
Block(-8,-49,2,COBBLESTONE:0)
Block(-8,-49,3,COBBLESTONE:0)
Block(-8,-49,4,COBBLESTONE:0)
Block(-8,-49,5,STONE:5)
Block(-8,-48,-7,COBBLESTONE:0)
Block(-8,-48,-6,COBBLESTONE:0)
Block(-8,-48,-5,COBBLESTONE:0)
Block(-8,-48,-4,COBBLESTONE:0)
Block(-8,-48,-3,COBBLESTONE:0)
Block(-8,-48,-2,COBBLESTONE:0)
Block(-8,-48,-1,COBBLESTONE:0)
Block(-8,-48,0,COBBLESTONE:0)
Block(-8,-48,1,COBBLESTONE:0)
Block(-8,-48,2,COBBLESTONE:0)
Block(-8,-48,3,COBBLESTONE:0)
Block(-8,-48,4,COBBLESTONE:0)
Block(-8,-48,5,STONE:5)
Block(-8,-47,-7,COBBLESTONE:0)
Block(-8,-47,-6,COBBLESTONE:0)
Block(-8,-47,-5,COBBLESTONE:0)
Block(-8,-47,-4,COBBLESTONE:0)
Block(-8,-47,-3,COBBLESTONE:0)
Block(-8,-47,-2,COBBLESTONE:0)
Block(-8,-47,-1,COBBLESTONE:0)
Block(-8,-47,0,COBBLESTONE:0)
Block(-8,-47,1,COBBLESTONE:0)
Block(-8,-47,2,COBBLESTONE:0)
Block(-8,-47,3,COBBLESTONE:0)
Block(-8,-47,4,COBBLESTONE:0)
Block(-8,-47,5,STONE:5)
Block(-8,-46,-7,COBBLESTONE:0)
Block(-8,-46,-6,COBBLESTONE:0)
Block(-8,-46,-5,COBBLESTONE:0)
Block(-8,-46,-4,COBBLESTONE:0)
Block(-8,-46,-3,COBBLESTONE:0)
Block(-8,-46,-2,COBBLESTONE:0)
Block(-8,-46,-1,COBBLESTONE:0)
Block(-8,-46,0,COBBLESTONE:0)
Block(-8,-46,1,COBBLESTONE:0)
Block(-8,-46,2,COBBLESTONE:0)
Block(-8,-46,3,COBBLESTONE:0)
Block(-8,-46,4,COBBLESTONE:0)
Block(-8,-46,5,STONE:5)
Block(-8,-45,-7,COBBLESTONE:0)
Block(-8,-45,-6,COBBLESTONE:0)
Block(-8,-45,-5,COBBLESTONE:0)
Block(-8,-45,-4,COBBLESTONE:0)
Block(-8,-45,-3,COBBLESTONE:0)
Block(-8,-45,-2,COBBLESTONE:0)
Block(-8,-45,-1,COBBLESTONE:0)
Block(-8,-45,0,COBBLESTONE:0)
Block(-8,-45,1,COBBLESTONE:0)
Block(-8,-45,2,COBBLESTONE:0)
Block(-8,-45,3,COBBLESTONE:0)
Block(-8,-45,4,COBBLESTONE:0)
Block(-8,-45,5,STONE:5)
Block(-8,-44,-7,COBBLESTONE:0)
Block(-8,-44,-6,COBBLESTONE:0)
Block(-8,-44,-5,COBBLESTONE:0)
Block(-8,-44,-4,COBBLESTONE:0)
Block(-8,-44,-3,COBBLESTONE:0)
Block(-8,-44,-2,COBBLESTONE:0)
Block(-8,-44,-1,COBBLESTONE:0)
Block(-8,-44,0,COBBLESTONE:0)
Block(-8,-44,1,COBBLESTONE:0)
Block(-8,-44,2,COBBLESTONE:0)
Block(-8,-44,3,COBBLESTONE:0)
Block(-8,-44,4,COBBLESTONE:0)
Block(-8,-44,5,STONE:5)
Block(-8,-43,-7,COBBLESTONE:0)
Block(-8,-43,-6,COBBLESTONE:0)
Block(-8,-43,-5,COBBLESTONE:0)
Block(-8,-43,-4,COBBLESTONE:0)
Block(-8,-43,-3,COBBLESTONE:0)
Block(-8,-43,-2,COBBLESTONE:0)
Block(-8,-43,-1,COBBLESTONE:0)
Block(-8,-43,0,COBBLESTONE:0)
Block(-8,-43,1,COBBLESTONE:0)
Block(-8,-43,2,COBBLESTONE:0)
Block(-8,-43,3,STONE:0)
Block(-8,-43,4,STONE:0)
Block(-8,-43,5,STONE:0)
Block(-8,-42,-7,COBBLESTONE:0)
Block(-8,-42,-6,COBBLESTONE:0)
Block(-8,-42,-5,COBBLESTONE:0)
Block(-8,-42,-4,COBBLESTONE:0)
Block(-8,-42,-3,COBBLESTONE:0)
Block(-8,-42,-2,COBBLESTONE:0)
Block(-8,-42,-1,COBBLESTONE:0)
Block(-8,-42,0,COBBLESTONE:0)
Block(-8,-42,1,COBBLESTONE:0)
Block(-8,-42,2,STONE:0)
Block(-8,-42,3,STONE:0)
Block(-8,-42,4,STONE:0)
Block(-8,-42,5,STONE:0)
Block(-8,-41,-7,COBBLESTONE:0)
Block(-8,-41,-6,COBBLESTONE:0)
Block(-8,-41,-5,COBBLESTONE:0)
Block(-8,-41,-4,COBBLESTONE:0)
Block(-8,-41,-3,COBBLESTONE:0)
Block(-8,-41,-2,COBBLESTONE:0)
Block(-8,-41,-1,COBBLESTONE:0)
Block(-8,-41,0,COBBLESTONE:0)
Block(-8,-41,1,COBBLESTONE:0)
Block(-8,-41,2,STONE:0)
Block(-8,-41,3,STONE:0)
Block(-8,-41,4,STONE:0)
Block(-8,-41,5,STONE:0)
Block(-8,-40,-7,COBBLESTONE:0)
Block(-8,-40,-6,COBBLESTONE:0)
Block(-8,-40,-5,COBBLESTONE:0)
Block(-8,-40,-4,COBBLESTONE:0)
Block(-8,-40,-3,COBBLESTONE:0)
Block(-8,-40,-2,COBBLESTONE:0)
Block(-8,-40,-1,COBBLESTONE:0)
Block(-8,-40,0,COBBLESTONE:0)
Block(-8,-40,1,COBBLESTONE:0)
Block(-8,-40,2,SMOOTH_BRICK:0)
Block(-8,-40,3,STONE:0)
Block(-8,-40,4,STONE:0)
Block(-8,-40,5,COBBLESTONE:0)
Block(-8,-39,-7,COBBLESTONE:0)
Block(-8,-39,-6,COBBLESTONE:0)
Block(-8,-39,-5,COBBLESTONE:0)
Block(-8,-39,-4,COBBLESTONE:0)
Block(-8,-39,-3,COBBLESTONE:0)
Block(-8,-39,-2,COBBLESTONE:0)
Block(-8,-39,-1,COBBLESTONE:0)
Block(-8,-39,0,COBBLESTONE:0)
Block(-8,-39,1,SMOOTH_BRICK:1)
Block(-8,-39,2,STONE:0)
Block(-8,-39,3,STONE:5)
Block(-8,-39,4,SMOOTH_BRICK:1)
Block(-8,-39,5,SMOOTH_BRICK:0)
Block(-8,-38,-7,COBBLESTONE:0)
Block(-8,-38,-6,COBBLESTONE:0)
Block(-8,-38,-5,COBBLESTONE:0)
Block(-8,-38,-4,COBBLESTONE:0)
Block(-8,-38,-3,COBBLESTONE:0)
Block(-8,-38,-2,COBBLESTONE:0)
Block(-8,-38,-1,COBBLESTONE:0)
Block(-8,-38,0,SMOOTH_BRICK:2)
Block(-8,-38,1,SMOOTH_BRICK:1)
Block(-8,-38,2,SMOOTH_BRICK:2)
Block(-8,-38,3,STONE:0)
Block(-8,-38,4,COBBLESTONE:0)
Block(-8,-38,5,COBBLESTONE:0)
Block(-8,-37,-7,COBBLESTONE:0)
Block(-8,-37,-6,COBBLESTONE:0)
Block(-8,-37,-5,COBBLESTONE:0)
Block(-8,-37,-4,COBBLESTONE:0)
Block(-8,-37,-3,COBBLESTONE:0)
Block(-8,-37,-2,COBBLESTONE:0)
Block(-8,-37,-1,COBBLESTONE:0)
Block(-8,-37,0,COBBLESTONE:0)
Block(-8,-37,1,STONE:0)
Block(-8,-37,2,COBBLESTONE:0)
Block(-8,-37,3,SMOOTH_BRICK:0)
Block(-8,-37,4,STONE:5)
Block(-8,-37,5,SMOOTH_BRICK:0)
Block(-8,-36,-7,COBBLESTONE:0)
Block(-8,-36,-6,COBBLESTONE:0)
Block(-8,-36,-5,COBBLESTONE:0)
Block(-8,-36,-4,COBBLESTONE:0)
Block(-8,-36,-3,COBBLESTONE:0)
Block(-8,-36,-2,COBBLESTONE:0)
Block(-8,-36,-1,COBBLESTONE:0)
Block(-8,-36,0,COBBLESTONE:0)
Block(-8,-36,1,SMOOTH_BRICK:0)
Block(-8,-36,2,STONE:0)
Block(-8,-36,3,COBBLESTONE:0)
Block(-8,-36,4,STONE:0)
Block(-8,-36,5,SMOOTH_BRICK:2)
Block(-8,-35,-7,COBBLESTONE:0)
Block(-8,-35,-6,COBBLESTONE:0)
Block(-8,-35,-5,COBBLESTONE:0)
Block(-8,-35,-4,COBBLESTONE:0)
Block(-8,-35,-3,COBBLESTONE:0)
Block(-8,-35,-2,COBBLESTONE:0)
Block(-8,-35,-1,COBBLESTONE:0)
Block(-8,-35,0,COBBLESTONE:0)
Block(-8,-35,1,SMOOTH_BRICK:2)
Block(-8,-35,2,SMOOTH_BRICK:0)
Block(-8,-35,3,STONE:5)
Block(-8,-35,4,STAINED_CLAY:9)
Block(-8,-35,5,COBBLESTONE:0)
Block(-8,-34,-7,COBBLESTONE:0)
Block(-8,-34,-6,COBBLESTONE:0)
Block(-8,-34,-5,COBBLESTONE:0)
Block(-8,-34,-4,COBBLESTONE:0)
Block(-8,-34,-3,COBBLESTONE:0)
Block(-8,-34,-2,COBBLESTONE:0)
Block(-8,-34,-1,COBBLESTONE:0)
Block(-8,-34,0,COBBLESTONE:0)
Block(-8,-34,1,SMOOTH_BRICK:2)
Block(-8,-34,2,STONE:5)
Block(-8,-34,3,COBBLESTONE:0)
Block(-8,-34,4,STONE:0)
Block(-8,-34,5,STONE:0)
Block(-8,-33,-7,COBBLESTONE:0)
Block(-8,-33,-6,COBBLESTONE:0)
Block(-8,-33,-5,COBBLESTONE:0)
Block(-8,-33,-4,COBBLESTONE:0)
Block(-8,-33,-3,COBBLESTONE:0)
Block(-8,-33,-2,COBBLESTONE:0)
Block(-8,-33,-1,COBBLESTONE:0)
Block(-8,-33,0,COBBLESTONE:0)
Block(-8,-33,1,STONE:0)
Block(-8,-33,2,STONE:0)
Block(-8,-33,3,STONE:0)
Block(-8,-33,4,STONE:0)
Block(-8,-33,5,STONE:0)
Block(-8,-32,-7,COBBLESTONE:0)
Block(-8,-32,-6,COBBLESTONE:0)
Block(-8,-32,-5,COBBLESTONE:0)
Block(-8,-32,-4,COBBLESTONE:0)
Block(-8,-32,-3,COBBLESTONE:0)
Block(-8,-32,-2,COBBLESTONE:0)
Block(-8,-32,-1,COBBLESTONE:0)
Block(-8,-32,0,COBBLESTONE:0)
Block(-8,-32,1,STONE:0)
Block(-8,-32,2,STONE:0)
Block(-8,-32,3,STONE:0)
Block(-8,-32,4,STONE:0)
Block(-8,-32,5,STONE:0)
Block(-8,-31,-7,COBBLESTONE:0)
Block(-8,-31,-6,COBBLESTONE:0)
Block(-8,-31,-5,COBBLESTONE:0)
Block(-8,-31,-4,COBBLESTONE:0)
Block(-8,-31,-3,COBBLESTONE:0)
Block(-8,-31,-2,COBBLESTONE:0)
Block(-8,-31,-1,COBBLESTONE:0)
Block(-8,-31,0,COBBLESTONE:0)
Block(-8,-31,1,STONE:0)
Block(-8,-31,2,STONE:0)
Block(-8,-31,3,STONE:0)
Block(-8,-31,4,STONE:0)
Block(-8,-31,5,STONE:0)
Block(-8,-30,-7,COBBLESTONE:0)
Block(-8,-30,-6,COBBLESTONE:0)
Block(-8,-30,-5,COBBLESTONE:0)
Block(-8,-30,-4,COBBLESTONE:0)
Block(-8,-30,-3,COBBLESTONE:0)
Block(-8,-30,-2,COBBLESTONE:0)
Block(-8,-30,-1,COBBLESTONE:0)
Block(-8,-30,0,COBBLESTONE:0)
Block(-8,-30,1,COBBLESTONE:0)
Block(-8,-30,2,STONE:0)
Block(-8,-30,3,STONE:0)
Block(-8,-30,4,STONE:0)
Block(-8,-30,5,STONE:0)
Block(-8,-29,-7,COBBLESTONE:0)
Block(-8,-29,-6,COBBLESTONE:0)
Block(-8,-29,-5,COBBLESTONE:0)
Block(-8,-29,-4,COBBLESTONE:0)
Block(-8,-29,-3,COBBLESTONE:0)
Block(-8,-29,-2,COBBLESTONE:0)
Block(-8,-29,-1,COBBLESTONE:0)
Block(-8,-29,0,COBBLESTONE:0)
Block(-8,-29,1,COBBLESTONE:0)
Block(-8,-29,2,STONE:0)
Block(-8,-29,3,STONE:0)
Block(-8,-29,4,STONE:0)
Block(-8,-29,5,STONE:0)
Block(-8,-28,-7,COBBLESTONE:0)
Block(-8,-28,-6,COBBLESTONE:0)
Block(-8,-28,-5,COBBLESTONE:0)
Block(-8,-28,-4,COBBLESTONE:0)
Block(-8,-28,-3,COBBLESTONE:0)
Block(-8,-28,-2,COBBLESTONE:0)
Block(-8,-28,-1,COBBLESTONE:0)
Block(-8,-28,0,COBBLESTONE:0)
Block(-8,-28,1,COBBLESTONE:0)
Block(-8,-28,2,STONE:0)
Block(-8,-28,3,STONE:0)
Block(-8,-28,4,STONE:0)
Block(-8,-28,5,SMOOTH_BRICK:2)
Block(-8,-27,-7,COBBLESTONE:0)
Block(-8,-27,-6,COBBLESTONE:0)
Block(-8,-27,-5,COBBLESTONE:0)
Block(-8,-27,-4,COBBLESTONE:0)
Block(-8,-27,-3,COBBLESTONE:0)
Block(-8,-27,-2,COBBLESTONE:0)
Block(-8,-27,-1,COBBLESTONE:0)
Block(-8,-27,0,COBBLESTONE:0)
Block(-8,-27,1,COBBLESTONE:0)
Block(-8,-27,2,STONE:5)
Block(-8,-27,3,STONE:5)
Block(-8,-27,4,STONE:5)
Block(-8,-27,5,STONE:0)
Block(-8,-26,-7,COBBLESTONE:0)
Block(-8,-26,-6,COBBLESTONE:0)
Block(-8,-26,-5,COBBLESTONE:0)
Block(-8,-26,-4,COBBLESTONE:0)
Block(-8,-26,-3,COBBLESTONE:0)
Block(-8,-26,-2,COBBLESTONE:0)
Block(-8,-26,-1,COBBLESTONE:0)
Block(-8,-26,0,COBBLESTONE:0)
Block(-8,-26,1,COBBLESTONE:0)
Block(-8,-26,2,SMOOTH_BRICK:0)
Block(-8,-26,3,STONE:0)
Block(-8,-26,4,COBBLESTONE:0)
Block(-8,-26,5,SMOOTH_BRICK:2)
Block(-8,-25,-7,COBBLESTONE:0)
Block(-8,-25,-6,COBBLESTONE:0)
Block(-8,-25,-5,COBBLESTONE:0)
Block(-8,-25,-4,COBBLESTONE:0)
Block(-8,-25,-3,COBBLESTONE:0)
Block(-8,-25,-2,COBBLESTONE:0)
Block(-8,-25,-1,COBBLESTONE:0)
Block(-8,-25,0,COBBLESTONE:0)
Block(-8,-25,1,COBBLESTONE:0)
Block(-8,-25,2,STONE:0)
Block(-8,-25,3,STONE:5)
Block(-8,-25,4,STONE:0)
Block(-8,-25,5,STONE:0)
Block(-8,-24,-7,COBBLESTONE:0)
Block(-8,-24,-6,COBBLESTONE:0)
Block(-8,-24,-5,COBBLESTONE:0)
Block(-8,-24,-4,COBBLESTONE:0)
Block(-8,-24,-3,COBBLESTONE:0)
Block(-8,-24,-2,COBBLESTONE:0)
Block(-8,-24,-1,COBBLESTONE:0)
Block(-8,-24,0,COBBLESTONE:0)
Block(-8,-24,1,COBBLESTONE:0)
Block(-8,-24,2,COBBLESTONE:0)
Block(-8,-24,3,SMOOTH_BRICK:0)
Block(-8,-24,4,SMOOTH_BRICK:0)
Block(-8,-24,5,STONE:0)
Block(-8,-23,-7,COBBLESTONE:0)
Block(-8,-23,-6,COBBLESTONE:0)
Block(-8,-23,-5,COBBLESTONE:0)
Block(-8,-23,-4,COBBLESTONE:0)
Block(-8,-23,-3,COBBLESTONE:0)
Block(-8,-23,-2,COBBLESTONE:0)
Block(-8,-23,-1,COBBLESTONE:0)
Block(-8,-23,0,COBBLESTONE:0)
Block(-8,-23,1,COBBLESTONE:0)
Block(-8,-23,2,COBBLESTONE:0)
Block(-8,-23,3,COBBLESTONE:0)
Block(-8,-23,4,COBBLESTONE:0)
Block(-8,-23,5,SMOOTH_BRICK:0)
Block(-8,-22,-7,COBBLESTONE:0)
Block(-8,-22,-6,COBBLESTONE:0)
Block(-8,-22,-5,COBBLESTONE:0)
Block(-8,-22,-4,COBBLESTONE:0)
Block(-8,-22,-3,COBBLESTONE:0)
Block(-8,-22,-2,COBBLESTONE:0)
Block(-8,-22,-1,COBBLESTONE:0)
Block(-8,-22,0,COBBLESTONE:0)
Block(-8,-22,1,COBBLESTONE:0)
Block(-8,-22,2,COBBLESTONE:0)
Block(-8,-22,3,COBBLESTONE:0)
Block(-8,-22,4,COBBLESTONE:0)
Block(-8,-22,5,STONE:5)
Block(-8,-21,-7,COBBLESTONE:0)
Block(-8,-21,-6,COBBLESTONE:0)
Block(-8,-21,-5,COBBLESTONE:0)
Block(-8,-21,-4,COBBLESTONE:0)
Block(-8,-21,-3,COBBLESTONE:0)
Block(-8,-21,-2,COBBLESTONE:0)
Block(-8,-21,-1,COBBLESTONE:0)
Block(-8,-21,0,COBBLESTONE:0)
Block(-8,-21,1,COBBLESTONE:0)
Block(-8,-21,2,COBBLESTONE:0)
Block(-8,-21,3,COBBLESTONE:0)
Block(-8,-21,4,COBBLESTONE:0)
Block(-8,-21,5,STONE:5)
Block(-8,-20,-7,COBBLESTONE:0)
Block(-8,-20,-6,COBBLESTONE:0)
Block(-8,-20,-5,COBBLESTONE:0)
Block(-8,-20,-4,COBBLESTONE:0)
Block(-8,-20,-3,COBBLESTONE:0)
Block(-8,-20,-2,COBBLESTONE:0)
Block(-8,-20,-1,COBBLESTONE:0)
Block(-8,-20,0,COBBLESTONE:0)
Block(-8,-20,1,COBBLESTONE:0)
Block(-8,-20,2,COBBLESTONE:0)
Block(-8,-20,3,COBBLESTONE:0)
Block(-8,-20,4,COBBLESTONE:0)
Block(-8,-20,5,STONE:5)
Block(-8,-19,-7,COBBLESTONE:0)
Block(-8,-19,-6,COBBLESTONE:0)
Block(-8,-19,-5,COBBLESTONE:0)
Block(-8,-19,-4,COBBLESTONE:0)
Block(-8,-19,-3,COBBLESTONE:0)
Block(-8,-19,-2,COBBLESTONE:0)
Block(-8,-19,-1,COBBLESTONE:0)
Block(-8,-19,0,COBBLESTONE:0)
Block(-8,-19,1,COBBLESTONE:0)
Block(-8,-19,2,COBBLESTONE:0)
Block(-8,-19,3,COBBLESTONE:0)
Block(-8,-19,4,COBBLESTONE:0)
Block(-8,-19,5,COBBLESTONE:0)
Block(-8,-18,-7,COBBLESTONE:0)
Block(-8,-18,-6,COBBLESTONE:0)
Block(-8,-18,-5,COBBLESTONE:0)
Block(-8,-18,-4,COBBLESTONE:0)
Block(-8,-18,-3,COBBLESTONE:0)
Block(-8,-18,-2,COBBLESTONE:0)
Block(-8,-18,-1,COBBLESTONE:0)
Block(-8,-18,0,STONE:5)
Block(-8,-18,1,COBBLESTONE:0)
Block(-8,-18,2,COBBLESTONE:0)
Block(-8,-18,3,COBBLESTONE:0)
Block(-8,-18,4,COBBLESTONE:0)
Block(-8,-18,5,COBBLESTONE:0)
Block(-8,-17,-7,COBBLESTONE:0)
Block(-8,-17,-6,COBBLESTONE:0)
Block(-8,-17,-5,COBBLESTONE:0)
Block(-8,-17,-4,COBBLESTONE:0)
Block(-8,-17,-3,COBBLESTONE:0)
Block(-8,-17,-2,COBBLESTONE:0)
Block(-8,-17,-1,COBBLESTONE:0)
Block(-8,-17,0,STONE:5)
Block(-8,-17,1,COBBLESTONE:0)
Block(-8,-17,2,COBBLESTONE:0)
Block(-8,-17,3,COBBLESTONE:0)
Block(-8,-17,4,STONE:5)
Block(-8,-17,5,COBBLESTONE:0)
Block(-8,-16,-7,COBBLESTONE:0)
Block(-8,-16,-6,COBBLESTONE:0)
Block(-8,-16,-5,COBBLESTONE:0)
Block(-8,-16,-4,COBBLESTONE:0)
Block(-8,-16,-3,COBBLESTONE:0)
Block(-8,-16,-2,COBBLESTONE:0)
Block(-8,-16,-1,COBBLESTONE:0)
Block(-8,-16,0,SMOOTH_BRICK:0)
Block(-8,-16,1,COBBLESTONE:0)
Block(-8,-16,2,COBBLESTONE:0)
Block(-8,-16,3,COBBLESTONE:0)
Block(-8,-16,4,STONE:5)
Block(-8,-16,5,STONE:5)
Block(-8,-15,-7,COBBLESTONE:0)
Block(-8,-15,-6,COBBLESTONE:0)
Block(-8,-15,-5,COBBLESTONE:0)
Block(-8,-15,-4,COBBLESTONE:0)
Block(-8,-15,-3,COBBLESTONE:0)
Block(-8,-15,-2,COBBLESTONE:0)
Block(-8,-15,-1,COBBLESTONE:0)
Block(-8,-15,0,SMOOTH_BRICK:0)
Block(-8,-15,1,COBBLESTONE:0)
Block(-8,-15,2,COBBLESTONE:0)
Block(-8,-15,3,COBBLESTONE:0)
Block(-8,-15,4,STONE:5)
Block(-8,-15,5,SMOOTH_BRICK:1)
Block(-8,-14,-7,COBBLESTONE:0)
Block(-8,-14,-6,COBBLESTONE:0)
Block(-8,-14,-5,COBBLESTONE:0)
Block(-8,-14,-4,COBBLESTONE:0)
Block(-8,-14,-3,COBBLESTONE:0)
Block(-8,-14,-2,COBBLESTONE:0)
Block(-8,-14,-1,COBBLESTONE:0)
Block(-8,-14,0,COBBLESTONE:0)
Block(-8,-14,1,COBBLESTONE:0)
Block(-8,-14,2,COBBLESTONE:0)
Block(-8,-14,3,COBBLESTONE:0)
Block(-8,-14,4,COBBLESTONE:0)
Block(-8,-14,5,COBBLESTONE:0)
Block(-8,-13,-7,COBBLESTONE:0)
Block(-8,-13,-6,COBBLESTONE:0)
Block(-8,-13,-5,COBBLESTONE:0)
Block(-8,-13,-4,COBBLESTONE:0)
Block(-8,-13,-3,COBBLESTONE:0)
Block(-8,-13,-2,COBBLESTONE:0)
Block(-8,-13,-1,COBBLESTONE:0)
Block(-8,-13,0,COBBLESTONE:0)
Block(-8,-13,1,COBBLESTONE:0)
Block(-8,-13,2,COBBLESTONE:0)
Block(-8,-13,3,COBBLESTONE:0)
Block(-8,-13,4,SMOOTH_BRICK:0)
Block(-8,-13,5,COBBLESTONE:0)
Block(-8,-12,-7,COBBLESTONE:0)
Block(-8,-12,-6,COBBLESTONE:0)
Block(-8,-12,-5,COBBLESTONE:0)
Block(-8,-12,-4,COBBLESTONE:0)
Block(-8,-12,-3,COBBLESTONE:0)
Block(-8,-12,-2,COBBLESTONE:0)
Block(-8,-12,-1,COBBLESTONE:0)
Block(-8,-12,0,STONE:5)
Block(-8,-12,1,COBBLESTONE:0)
Block(-8,-12,2,COBBLESTONE:0)
Block(-8,-12,3,COBBLESTONE:0)
Block(-8,-12,4,STONE:5)
Block(-8,-12,5,COBBLESTONE:0)
Block(-8,-11,-7,COBBLESTONE:0)
Block(-8,-11,-6,COBBLESTONE:0)
Block(-8,-11,-5,COBBLESTONE:0)
Block(-8,-11,-4,COBBLESTONE:0)
Block(-8,-11,-3,COBBLESTONE:0)
Block(-8,-11,-2,COBBLESTONE:0)
Block(-8,-11,-1,COBBLESTONE:0)
Block(-8,-11,0,STONE:5)
Block(-8,-11,1,COBBLESTONE:0)
Block(-8,-11,2,COBBLESTONE:0)
Block(-8,-11,3,COBBLESTONE:0)
Block(-8,-11,4,COBBLESTONE:0)
Block(-8,-11,5,COBBLESTONE:0)
Block(-8,-10,-7,COBBLESTONE:0)
Block(-8,-10,-6,COBBLESTONE:0)
Block(-8,-10,-5,COBBLESTONE:0)
Block(-8,-10,-4,COBBLESTONE:0)
Block(-8,-10,-3,COBBLESTONE:0)
Block(-8,-10,-2,COBBLESTONE:0)
Block(-8,-10,-1,COBBLESTONE:0)
Block(-8,-10,0,COBBLESTONE:0)
Block(-8,-10,1,STAINED_CLAY:9)
Block(-8,-10,2,COBBLESTONE:0)
Block(-8,-10,3,STONE:5)
Block(-8,-10,4,STONE:5)
Block(-8,-10,5,STONE:5)
Block(-8,-9,-7,COBBLESTONE:0)
Block(-8,-9,-6,COBBLESTONE:0)
Block(-8,-9,-5,COBBLESTONE:0)
Block(-8,-9,-4,COBBLESTONE:0)
Block(-8,-9,-3,COBBLESTONE:0)
Block(-8,-9,-2,COBBLESTONE:0)
Block(-8,-9,-1,COBBLESTONE:0)
Block(-8,-9,0,STONE:5)
Block(-8,-9,1,LOG:4)
Block(-8,-9,2,STONE:6)
Block(-8,-9,3,COBBLESTONE_STAIRS:1)
Block(-8,-9,4,COBBLESTONE_STAIRS:1)
Block(-8,-9,5,COBBLESTONE_STAIRS:3)
Block(-8,-8,-7,COBBLESTONE:0)
Block(-8,-8,-6,COBBLESTONE:0)
Block(-8,-8,-5,COBBLESTONE:0)
Block(-8,-8,-4,COBBLESTONE:0)
Block(-8,-8,-3,COBBLESTONE:0)
Block(-8,-8,-2,COBBLESTONE:0)
Block(-8,-8,-1,COBBLESTONE:0)
Block(-8,-8,0,STONE:6)
Block(-8,-7,-7,COBBLESTONE:0)
Block(-8,-7,-6,COBBLESTONE:0)
Block(-8,-7,-5,COBBLESTONE:0)
Block(-8,-7,-4,COBBLESTONE:0)
Block(-8,-7,-3,COBBLESTONE:0)
Block(-8,-7,-2,COBBLESTONE:0)
Block(-8,-7,-1,COBBLESTONE:0)
Block(-8,-7,0,STONE:6)
Block(-8,-6,-7,COBBLESTONE:0)
Block(-8,-6,-6,COBBLESTONE:0)
Block(-8,-6,-5,COBBLESTONE:0)
Block(-8,-6,-4,COBBLESTONE:0)
Block(-8,-6,-3,COBBLESTONE:0)
Block(-8,-6,-2,COBBLESTONE:0)
Block(-8,-6,-1,COBBLESTONE:0)
Block(-8,-6,0,STONE:6)
Block(-8,-5,-7,COBBLESTONE:0)
Block(-8,-5,-6,COBBLESTONE:0)
Block(-8,-5,-5,COBBLESTONE:0)
Block(-8,-5,-4,COBBLESTONE:0)
Block(-8,-5,-3,COBBLESTONE:0)
Block(-8,-5,-2,COBBLESTONE:0)
Block(-8,-5,-1,COBBLESTONE:0)
Block(-8,-5,0,STONE:6)
Block(-8,-4,-7,COBBLESTONE:0)
Block(-8,-4,-6,COBBLESTONE:0)
Block(-8,-4,-5,COBBLESTONE:0)
Block(-8,-4,-4,COBBLESTONE:0)
Block(-8,-4,-3,COBBLESTONE:0)
Block(-8,-4,-2,COBBLESTONE:0)
Block(-8,-4,-1,COBBLESTONE:0)
Block(-8,-4,0,STONE:6)
Block(-8,-4,1,LOG:4)
Block(-8,-3,-7,COBBLESTONE:0)
Block(-8,-3,-6,COBBLESTONE:0)
Block(-8,-3,-5,COBBLESTONE:0)
Block(-8,-3,-4,COBBLESTONE:0)
Block(-8,-3,-3,COBBLESTONE:0)
Block(-8,-3,-2,COBBLESTONE:0)
Block(-8,-3,-1,COBBLESTONE:0)
Block(-8,-3,0,STONE:6)
Block(-8,-2,-7,COBBLESTONE:0)
Block(-8,-2,-6,COBBLESTONE:0)
Block(-8,-2,-5,COBBLESTONE:0)
Block(-8,-2,-4,COBBLESTONE:0)
Block(-8,-2,-3,COBBLESTONE:0)
Block(-8,-2,-2,COBBLESTONE:0)
Block(-8,-2,-1,COBBLESTONE:0)
Block(-8,-2,0,STONE:6)
Block(-8,-1,-7,COBBLESTONE:0)
Block(-8,-1,-6,COBBLESTONE:0)
Block(-8,-1,-5,COBBLESTONE:0)
Block(-8,-1,-4,COBBLESTONE:0)
Block(-8,-1,-3,COBBLESTONE:0)
Block(-8,-1,-2,COBBLESTONE:0)
Block(-8,-1,-1,COBBLESTONE:0)
Block(-8,-1,0,STONE:6)
Block(-8,0,-7,COBBLESTONE:0)
Block(-8,0,-6,COBBLESTONE:0)
Block(-8,0,-5,COBBLESTONE:0)
Block(-8,0,-4,COBBLESTONE:0)
Block(-8,0,-3,COBBLESTONE:0)
Block(-8,0,-2,COBBLESTONE:0)
Block(-8,0,-1,COBBLESTONE:0)
Block(-8,0,0,STONE:6)
Block(-8,1,-7,COBBLESTONE:0)
Block(-8,1,-6,COBBLESTONE:0)
Block(-8,1,-5,COBBLESTONE:0)
Block(-8,1,-4,COBBLESTONE:0)
Block(-8,1,-3,COBBLESTONE:0)
Block(-8,1,-2,COBBLESTONE:0)
Block(-8,1,-1,COBBLESTONE:0)
Block(-8,1,0,STONE:6)
Block(-8,2,-7,COBBLESTONE:0)
Block(-8,2,-6,COBBLESTONE:0)
Block(-8,2,-5,COBBLESTONE:0)
Block(-8,2,-4,COBBLESTONE:0)
Block(-8,2,-3,COBBLESTONE:0)
Block(-8,2,-2,COBBLESTONE:0)
Block(-8,2,-1,COBBLESTONE:0)
Block(-8,2,0,STONE:6)
Block(-8,2,1,LOG:4)
Block(-8,2,2,AIR:0)
Block(-8,2,3,AIR:0)
Block(-8,2,4,LOG:12)
Block(-8,2,5,WOOD_STEP:9)
Block(-8,2,6,WOOD_STEP:13)
Block(-8,2,7,WOOD_STEP:13)
Block(-8,2,8,WOOD_STEP:13)
Block(-8,3,-7,COBBLESTONE:0)
Block(-8,3,-6,COBBLESTONE:0)
Block(-8,3,-5,COBBLESTONE:0)
Block(-8,3,-4,COBBLESTONE:0)
Block(-8,3,-3,COBBLESTONE:0)
Block(-8,3,-2,COBBLESTONE:0)
Block(-8,3,-1,COBBLESTONE:0)
Block(-8,3,0,STONE:6)
Block(-8,3,1,COBBLE_WALL:0)
Block(-8,3,2,AIR:0)
Block(-8,3,3,AIR:0)
Block(-8,3,4,AIR:0)
Block(-8,3,5,AIR:0)
Block(-8,3,6,AIR:0)
Block(-8,3,7,AIR:0)
Block(-8,3,8,AIR:0)
Block(-8,4,-7,COBBLESTONE:0)
Block(-8,4,-6,COBBLESTONE:0)
Block(-8,4,-5,COBBLESTONE:0)
Block(-8,4,-4,COBBLESTONE:0)
Block(-8,4,-3,COBBLESTONE:0)
Block(-8,4,-2,COBBLESTONE:0)
Block(-8,4,-1,COBBLESTONE:0)
Block(-8,4,0,STONE:6)
Block(-8,4,1,AIR:0)
Block(-8,4,2,AIR:0)
Block(-8,4,3,AIR:0)
Block(-8,4,4,AIR:0)
Block(-8,4,5,AIR:0)
Block(-8,4,6,AIR:0)
Block(-8,4,7,AIR:0)
Block(-8,4,8,AIR:0)
Block(-8,5,-7,COBBLESTONE:0)
Block(-8,5,-6,COBBLESTONE:0)
Block(-8,5,-5,COBBLESTONE:0)
Block(-8,5,-4,COBBLESTONE:0)
Block(-8,5,-3,COBBLESTONE:0)
Block(-8,5,-2,COBBLESTONE:0)
Block(-8,5,-1,COBBLESTONE:0)
Block(-8,5,0,STONE:6)
Block(-8,5,1,AIR:0)
Block(-8,5,2,AIR:0)
Block(-8,5,3,AIR:0)
Block(-8,5,4,AIR:0)
Block(-8,5,5,AIR:0)
Block(-8,5,6,AIR:0)
Block(-8,5,7,AIR:0)
Block(-8,5,8,AIR:0)
Block(-8,6,-7,COBBLESTONE:0)
Block(-8,6,-6,COBBLESTONE:0)
Block(-8,6,-5,COBBLESTONE:0)
Block(-8,6,-4,COBBLESTONE:0)
Block(-8,6,-3,COBBLESTONE:0)
Block(-8,6,-2,COBBLESTONE:0)
Block(-8,6,-1,COBBLESTONE:0)
Block(-8,6,0,SMOOTH_BRICK:0)
Block(-8,6,1,AIR:0)
Block(-8,6,2,AIR:0)
Block(-8,6,3,AIR:0)
Block(-8,6,4,AIR:0)
Block(-8,6,5,AIR:0)
Block(-8,6,6,AIR:0)
Block(-8,6,7,AIR:0)
Block(-8,6,8,AIR:0)
Block(-8,7,-7,COBBLESTONE:0)
Block(-8,7,-6,COBBLESTONE:0)
Block(-8,7,-5,COBBLESTONE:0)
Block(-8,7,-4,COBBLESTONE:0)
Block(-8,7,-3,COBBLESTONE:0)
Block(-8,7,-2,COBBLESTONE:0)
Block(-8,7,-1,COBBLESTONE:0)
Block(-8,7,0,SMOOTH_BRICK:0)
Block(-8,7,1,AIR:0)
Block(-8,7,2,AIR:0)
Block(-8,7,3,AIR:0)
Block(-8,7,4,AIR:0)
Block(-8,7,5,AIR:0)
Block(-8,7,6,AIR:0)
Block(-8,7,7,AIR:0)
Block(-8,7,8,AIR:0)
Block(-8,8,-7,WOOD_STEP:13)
Block(-8,8,-6,WOOD_STEP:13)
Block(-8,8,-5,WOOD_STEP:13)
Block(-8,8,-4,LOG:4)
Block(-8,8,-3,WOOD_STEP:13)
Block(-8,8,-2,WOOD_STEP:13)
Block(-8,8,-1,WOOD_STEP:13)
Block(-8,8,0,STONE:6)
Block(-8,8,1,DARK_OAK_STAIRS:5)
Block(-8,8,2,AIR:0)
Block(-8,8,3,AIR:0)
Block(-8,8,4,AIR:0)
Block(-8,8,5,AIR:0)
Block(-8,8,6,AIR:0)
Block(-8,8,7,AIR:0)
Block(-8,8,8,AIR:0)
Block(-8,9,-7,LOG:0)
Block(-8,9,-6,AIR:0)
Block(-8,9,-5,AIR:0)
Block(-8,9,-4,AIR:0)
Block(-8,9,-3,AIR:0)
Block(-8,9,-2,AIR:0)
Block(-8,9,-1,LOG:0)
Block(-8,9,0,AIR:0)
Block(-8,9,1,DARK_OAK_STAIRS:0)
Block(-8,9,2,AIR:0)
Block(-8,9,3,AIR:0)
Block(-8,9,4,AIR:0)
Block(-8,9,5,AIR:0)
Block(-8,9,6,AIR:0)
Block(-8,9,7,AIR:0)
Block(-8,9,8,AIR:0)
Block(-8,10,-7,LOG:0)
Block(-8,10,-6,AIR:0)
Block(-8,10,-5,AIR:0)
Block(-8,10,-4,AIR:0)
Block(-8,10,-3,AIR:0)
Block(-8,10,-2,AIR:0)
Block(-8,10,-1,LOG:0)
Block(-8,10,0,AIR:0)
Block(-8,10,1,DARK_OAK_STAIRS:4)
Block(-8,10,2,STEP:11)
Block(-8,10,3,AIR:0)
Block(-8,10,4,AIR:0)
Block(-8,10,5,AIR:0)
Block(-8,10,6,AIR:0)
Block(-8,10,7,AIR:0)
Block(-8,10,8,AIR:0)
Block(-8,11,-7,LOG:0)
Block(-8,11,-6,WOOD_STEP:13)
Block(-8,11,-5,WOOD_STEP:13)
Block(-8,11,-4,LOG:4)
Block(-8,11,-3,WOOD_STEP:13)
Block(-8,11,-2,WOOD_STEP:13)
Block(-8,11,-1,LOG:0)
Block(-8,11,0,STEP:11)
Block(-8,11,1,STEP:3)
Block(-8,11,2,AIR:0)
Block(-8,11,3,AIR:0)
Block(-8,11,4,AIR:0)
Block(-8,11,5,AIR:0)
Block(-8,11,6,AIR:0)
Block(-8,11,7,AIR:0)
Block(-8,11,8,AIR:0)
Block(-8,12,-7,LOG:0)
Block(-8,12,-6,SKULL:1,origin/9644-skullC272R176.nbt)
Block(-8,12,-5,AIR:0)
Block(-8,12,-4,AIR:0)
Block(-8,12,-3,AIR:0)
Block(-8,12,-2,AIR:0)
Block(-8,12,-1,LOG:0)
Block(-8,12,0,SMOOTH_STAIRS:3)
Block(-8,12,1,AIR:0)
Block(-8,12,2,AIR:0)
Block(-8,12,3,AIR:0)
Block(-8,12,4,AIR:0)
Block(-8,12,5,AIR:0)
Block(-8,12,6,AIR:0)
Block(-8,12,7,AIR:0)
Block(-8,12,8,AIR:0)
Block(-8,13,-7,LOG:0)
Block(-8,13,-6,AIR:0)
Block(-8,13,-5,AIR:0)
Block(-8,13,-4,AIR:0)
Block(-8,13,-3,AIR:0)
Block(-8,13,-2,AIR:0)
Block(-8,13,-1,LOG:0)
Block(-8,13,0,SMOOTH_STAIRS:7)
Block(-8,13,1,AIR:0)
Block(-8,13,2,AIR:0)
Block(-8,13,3,AIR:0)
Block(-8,13,4,AIR:0)
Block(-8,13,5,AIR:0)
Block(-8,13,6,AIR:0)
Block(-8,13,7,AIR:0)
Block(-8,13,8,AIR:0)
Block(-8,14,-7,LOG:0)
Block(-8,14,-6,WOOD_STEP:13)
Block(-8,14,-5,WOOD_STEP:13)
Block(-8,14,-4,LOG:4)
Block(-8,14,-3,WOOD_STEP:13)
Block(-8,14,-2,WOOD_STEP:13)
Block(-8,14,-1,LOG:0)
Block(-8,14,0,WOOD:5)
Block(-8,14,1,AIR:0)
Block(-8,14,2,AIR:0)
Block(-8,14,3,AIR:0)
Block(-8,14,4,AIR:0)
Block(-8,14,5,AIR:0)
Block(-8,14,6,AIR:0)
Block(-8,14,7,AIR:0)
Block(-8,14,8,AIR:0)
Block(-8,15,-7,LOG:0)
Block(-8,15,-6,AIR:0)
Block(-8,15,-5,AIR:0)
Block(-8,15,-4,AIR:0)
Block(-8,15,-3,AIR:0)
Block(-8,15,-2,AIR:0)
Block(-8,15,-1,LOG:0)
Block(-8,15,0,STEP:3)
Block(-8,15,1,SMOOTH_STAIRS:5)
Block(-8,15,2,AIR:0)
Block(-8,15,3,AIR:0)
Block(-8,15,4,AIR:0)
Block(-8,15,5,AIR:0)
Block(-8,15,6,AIR:0)
Block(-8,15,7,AIR:0)
Block(-8,15,8,AIR:0)
Block(-8,16,-7,LOG:0)
Block(-8,16,-6,AIR:0)
Block(-8,16,-5,AIR:0)
Block(-8,16,-4,AIR:0)
Block(-8,16,-3,AIR:0)
Block(-8,16,-2,AIR:0)
Block(-8,16,-1,LOG:0)
Block(-8,16,0,AIR:0)
Block(-8,16,1,COBBLE_WALL:0)
Block(-8,16,2,AIR:0)
Block(-8,16,3,AIR:0)
Block(-8,16,4,AIR:0)
Block(-8,16,5,AIR:0)
Block(-8,16,6,AIR:0)
Block(-8,16,7,AIR:0)
Block(-8,16,8,AIR:0)
Block(-8,17,-7,LOG:0)
Block(-8,17,-6,LOG:8)
Block(-8,17,-5,LOG:8)
Block(-8,17,-4,LOG:8)
Block(-8,17,-3,LOG:8)
Block(-8,17,-2,LOG:8)
Block(-8,17,-1,LOG:0)
Block(-8,17,0,WOOD_DOUBLE_STEP:5)
Block(-8,17,1,WOOD_STEP:5)
Block(-8,17,2,AIR:0)
Block(-8,17,3,AIR:0)
Block(-8,17,4,AIR:0)
Block(-8,17,5,AIR:0)
Block(-8,17,6,AIR:0)
Block(-8,17,7,AIR:0)
Block(-8,17,8,AIR:0)
Block(-8,18,-7,LOG:0)
Block(-8,18,-6,AIR:0)
Block(-8,18,-5,AIR:0)
Block(-8,18,-4,AIR:0)
Block(-8,18,-3,AIR:0)
Block(-8,18,-2,AIR:0)
Block(-8,18,-1,LOG:0)
Block(-8,18,0,AIR:0)
Block(-8,18,1,AIR:0)
Block(-8,18,2,AIR:0)
Block(-8,18,3,AIR:0)
Block(-8,18,4,AIR:0)
Block(-8,18,5,AIR:0)
Block(-8,18,6,AIR:0)
Block(-8,18,7,AIR:0)
Block(-8,18,8,AIR:0)
Block(-8,19,-7,COBBLESTONE_STAIRS:1)
Block(-8,19,-6,STONE:6)
Block(-8,19,-5,STONE:6)
Block(-8,19,-4,LOG:4)
Block(-8,19,-3,STONE:6)
Block(-8,19,-2,STONE:6)
Block(-8,19,-1,COBBLESTONE_STAIRS:1)
Block(-8,19,0,AIR:0)
Block(-8,19,1,AIR:0)
Block(-8,19,2,AIR:0)
Block(-8,19,3,AIR:0)
Block(-8,19,4,AIR:0)
Block(-8,19,5,AIR:0)
Block(-8,19,6,AIR:0)
Block(-8,19,7,AIR:0)
Block(-8,19,8,AIR:0)
Block(-8,20,-7,AIR:0)
Block(-8,20,-6,SMOOTH_STAIRS:1)
Block(-8,20,-5,SMOOTH_STAIRS:1)
Block(-8,20,-4,LOG:0)
Block(-8,20,-3,SMOOTH_STAIRS:1)
Block(-8,20,-2,SMOOTH_STAIRS:1)
Block(-8,20,-1,AIR:0)
Block(-8,20,0,AIR:0)
Block(-8,20,1,AIR:0)
Block(-8,20,2,AIR:0)
Block(-8,20,3,AIR:0)
Block(-8,20,4,AIR:0)
Block(-8,20,5,AIR:0)
Block(-8,20,6,AIR:0)
Block(-8,20,7,AIR:0)
Block(-8,20,8,AIR:0)
Block(-8,21,-7,AIR:0)
Block(-8,21,-6,SMOOTH_STAIRS:6)
Block(-8,21,-5,SMOOTH_STAIRS:5)
Block(-8,21,-4,LOG:0)
Block(-8,21,-3,SMOOTH_STAIRS:5)
Block(-8,21,-2,SMOOTH_STAIRS:7)
Block(-8,21,-1,AIR:0)
Block(-8,21,0,AIR:0)
Block(-8,21,1,AIR:0)
Block(-8,21,2,AIR:0)
Block(-8,21,3,AIR:0)
Block(-8,21,4,AIR:0)
Block(-8,21,5,AIR:0)
Block(-8,21,6,AIR:0)
Block(-8,21,7,AIR:0)
Block(-8,21,8,AIR:0)
Block(-8,22,-7,COBBLESTONE_STAIRS:5)
Block(-8,22,-6,STONE:6)
Block(-8,22,-5,STONE:6)
Block(-8,22,-4,LOG:0)
Block(-8,22,-3,STONE:6)
Block(-8,22,-2,STONE:6)
Block(-8,22,-1,COBBLESTONE_STAIRS:5)
Block(-8,22,0,AIR:0)
Block(-8,22,1,AIR:0)
Block(-8,22,2,AIR:0)
Block(-8,22,3,AIR:0)
Block(-8,22,4,AIR:0)
Block(-8,22,5,AIR:0)
Block(-8,22,6,AIR:0)
Block(-8,22,7,AIR:0)
Block(-8,22,8,AIR:0)
Block(-8,23,-7,LOG:0)
Block(-8,23,-6,STONE:6)
Block(-8,23,-5,STONE:6)
Block(-8,23,-4,LOG:0)
Block(-8,23,-3,STONE:6)
Block(-8,23,-2,STONE:6)
Block(-8,23,-1,LOG:0)
Block(-8,23,0,AIR:0)
Block(-8,23,1,AIR:0)
Block(-8,23,2,AIR:0)
Block(-8,23,3,AIR:0)
Block(-8,23,4,AIR:0)
Block(-8,23,5,AIR:0)
Block(-8,23,6,AIR:0)
Block(-8,23,7,AIR:0)
Block(-8,23,8,AIR:0)
Block(-8,24,-7,LOG:0)
Block(-8,24,-6,WOOD_STEP:5)
Block(-8,24,-5,WOOD_STEP:5)
Block(-8,24,-4,WOOD_STEP:5)
Block(-8,24,-3,WOOD_STEP:5)
Block(-8,24,-2,WOOD_STEP:5)
Block(-8,24,-1,WOOD_STEP:1)
Block(-8,24,0,COBBLESTONE_STAIRS:7)
Block(-8,24,1,AIR:0)
Block(-8,24,2,AIR:0)
Block(-8,24,3,AIR:0)
Block(-8,24,4,AIR:0)
Block(-8,24,5,AIR:0)
Block(-8,24,6,AIR:0)
Block(-8,24,7,AIR:0)
Block(-8,24,8,AIR:0)
Block(-8,25,-7,DOUBLE_STEP:3)
Block(-8,25,-6,AIR:0)
Block(-8,25,-5,AIR:0)
Block(-8,25,-4,AIR:0)
Block(-8,25,-3,AIR:0)
Block(-8,25,-2,AIR:0)
Block(-8,25,-1,DOUBLE_STEP:3)
Block(-8,25,0,COBBLESTONE_STAIRS:3)
Block(-8,25,1,AIR:0)
Block(-8,25,2,AIR:0)
Block(-8,25,3,AIR:0)
Block(-8,25,4,AIR:0)
Block(-8,25,5,AIR:0)
Block(-8,25,6,AIR:0)
Block(-8,25,7,AIR:0)
Block(-8,25,8,AIR:0)
Block(-8,26,-7,WOOD_STEP:5)
Block(-8,26,-6,AIR:0)
Block(-8,26,-5,AIR:0)
Block(-8,26,-4,AIR:0)
Block(-8,26,-3,AIR:0)
Block(-8,26,-2,AIR:0)
Block(-8,26,-1,WOOD_STEP:5)
Block(-8,26,0,AIR:0)
Block(-8,26,1,AIR:0)
Block(-8,26,2,AIR:0)
Block(-8,26,3,AIR:0)
Block(-8,26,4,AIR:0)
Block(-8,26,5,AIR:0)
Block(-8,26,6,AIR:0)
Block(-8,26,7,AIR:0)
Block(-8,26,8,AIR:0)
Block(-8,27,-7,AIR:0)
Block(-8,27,-6,AIR:0)
Block(-8,27,-5,AIR:0)
Block(-8,27,-4,AIR:0)
Block(-8,27,-3,AIR:0)
Block(-8,27,-2,AIR:0)
Block(-8,27,-1,AIR:0)
Block(-8,27,0,AIR:0)
Block(-8,27,1,AIR:0)
Block(-8,27,2,AIR:0)
Block(-8,27,3,AIR:0)
Block(-8,27,4,AIR:0)
Block(-8,27,5,AIR:0)
Block(-8,27,6,AIR:0)
Block(-8,27,7,AIR:0)
Block(-8,27,8,AIR:0)
Block(-8,28,-7,AIR:0)
Block(-8,28,-6,AIR:0)
Block(-8,28,-5,AIR:0)
Block(-8,28,-4,AIR:0)
Block(-8,28,-3,AIR:0)
Block(-8,28,-2,AIR:0)
Block(-8,28,-1,AIR:0)
Block(-8,28,0,AIR:0)
Block(-8,28,1,AIR:0)
Block(-8,28,2,AIR:0)
Block(-8,28,3,AIR:0)
Block(-8,28,4,AIR:0)
Block(-8,28,5,AIR:0)
Block(-8,28,6,AIR:0)
Block(-8,28,7,AIR:0)
Block(-8,28,8,AIR:0)
Block(-8,29,-7,AIR:0)
Block(-8,29,-6,AIR:0)
Block(-8,29,-5,AIR:0)
Block(-8,29,-4,AIR:0)
Block(-8,29,-3,AIR:0)
Block(-8,29,-2,AIR:0)
Block(-8,29,-1,AIR:0)
Block(-8,29,0,AIR:0)
Block(-8,29,1,AIR:0)
Block(-8,29,2,AIR:0)
Block(-8,29,3,AIR:0)
Block(-8,29,4,AIR:0)
Block(-8,29,5,AIR:0)
Block(-8,29,6,AIR:0)
Block(-8,29,7,AIR:0)
Block(-8,29,8,AIR:0)
Block(-8,30,-7,AIR:0)
Block(-8,30,-6,AIR:0)
Block(-8,30,-5,AIR:0)
Block(-8,30,-4,AIR:0)
Block(-8,30,-3,AIR:0)
Block(-8,30,-2,AIR:0)
Block(-8,30,-1,AIR:0)
Block(-8,30,0,AIR:0)
Block(-8,30,1,AIR:0)
Block(-8,30,2,AIR:0)
Block(-8,30,3,AIR:0)
Block(-8,30,4,AIR:0)
Block(-8,30,5,AIR:0)
Block(-8,30,6,AIR:0)
Block(-8,30,7,AIR:0)
Block(-8,30,8,AIR:0)
Block(-8,31,-7,AIR:0)
Block(-8,31,-6,AIR:0)
Block(-8,31,-5,AIR:0)
Block(-8,31,-4,AIR:0)
Block(-8,31,-3,AIR:0)
Block(-8,31,-2,AIR:0)
Block(-8,31,-1,AIR:0)
Block(-8,31,0,AIR:0)
Block(-8,31,1,AIR:0)
Block(-8,31,2,AIR:0)
Block(-8,31,3,AIR:0)
Block(-8,31,4,AIR:0)
Block(-8,31,5,AIR:0)
Block(-8,31,6,AIR:0)
Block(-8,31,7,AIR:0)
Block(-8,31,8,AIR:0)
Block(-8,32,-7,AIR:0)
Block(-8,32,-6,AIR:0)
Block(-8,32,-5,AIR:0)
Block(-8,32,-4,AIR:0)
Block(-8,32,-3,AIR:0)
Block(-8,32,-2,AIR:0)
Block(-8,32,-1,AIR:0)
Block(-8,32,0,AIR:0)
Block(-8,32,1,AIR:0)
Block(-8,32,2,AIR:0)
Block(-8,32,3,AIR:0)
Block(-8,32,4,AIR:0)
Block(-8,32,5,AIR:0)
Block(-8,32,6,AIR:0)
Block(-8,32,7,AIR:0)
Block(-8,32,8,AIR:0)
Block(-8,33,-7,AIR:0)
Block(-8,33,-6,AIR:0)
Block(-8,33,-5,AIR:0)
Block(-8,33,-4,AIR:0)
Block(-8,33,-3,AIR:0)
Block(-8,33,-2,AIR:0)
Block(-8,33,-1,AIR:0)
Block(-8,33,0,AIR:0)
Block(-8,33,1,AIR:0)
Block(-8,33,2,AIR:0)
Block(-8,33,3,AIR:0)
Block(-8,33,4,AIR:0)
Block(-8,33,5,AIR:0)
Block(-8,33,6,AIR:0)
Block(-8,33,7,AIR:0)
Block(-8,33,8,AIR:0)
Block(-8,34,-7,AIR:0)
Block(-8,34,-6,AIR:0)
Block(-8,34,-5,AIR:0)
Block(-8,34,-4,AIR:0)
Block(-8,34,-3,AIR:0)
Block(-8,34,-2,AIR:0)
Block(-8,34,-1,AIR:0)
Block(-8,34,0,AIR:0)
Block(-8,34,1,AIR:0)
Block(-8,34,2,AIR:0)
Block(-8,34,3,AIR:0)
Block(-8,34,4,AIR:0)
Block(-8,34,5,AIR:0)
Block(-8,34,6,AIR:0)
Block(-8,34,7,AIR:0)
Block(-8,34,8,AIR:0)
Block(-8,35,-7,AIR:0)
Block(-8,35,-6,AIR:0)
Block(-8,35,-5,AIR:0)
Block(-8,35,-4,AIR:0)
Block(-8,35,-3,AIR:0)
Block(-8,35,-2,AIR:0)
Block(-8,35,-1,AIR:0)
Block(-8,35,0,AIR:0)
Block(-8,35,1,AIR:0)
Block(-8,35,2,AIR:0)
Block(-8,35,3,AIR:0)
Block(-8,35,4,AIR:0)
Block(-8,35,5,AIR:0)
Block(-8,35,6,AIR:0)
Block(-8,35,7,AIR:0)
Block(-8,35,8,AIR:0)
Block(-8,36,-7,AIR:0)
Block(-8,36,-6,AIR:0)
Block(-8,36,-5,AIR:0)
Block(-8,36,-4,AIR:0)
Block(-8,36,-3,AIR:0)
Block(-8,36,-2,AIR:0)
Block(-8,36,-1,AIR:0)
Block(-8,36,0,AIR:0)
Block(-8,36,1,AIR:0)
Block(-8,36,2,AIR:0)
Block(-8,36,3,AIR:0)
Block(-8,36,4,AIR:0)
Block(-8,36,5,AIR:0)
Block(-8,36,6,AIR:0)
Block(-8,36,7,AIR:0)
Block(-8,36,8,AIR:0)
Block(-8,37,-7,AIR:0)
Block(-8,37,-6,AIR:0)
Block(-8,37,-5,AIR:0)
Block(-8,37,-4,AIR:0)
Block(-8,37,-3,AIR:0)
Block(-8,37,-2,AIR:0)
Block(-8,37,-1,AIR:0)
Block(-8,37,0,AIR:0)
Block(-8,37,1,AIR:0)
Block(-8,37,2,AIR:0)
Block(-8,37,3,AIR:0)
Block(-8,37,4,AIR:0)
Block(-8,37,5,AIR:0)
Block(-8,37,6,AIR:0)
Block(-8,37,7,AIR:0)
Block(-8,37,8,AIR:0)
Block(-8,38,-7,AIR:0)
Block(-8,38,-6,AIR:0)
Block(-8,38,-5,AIR:0)
Block(-8,38,-4,AIR:0)
Block(-8,38,-3,AIR:0)
Block(-8,38,-2,AIR:0)
Block(-8,38,-1,AIR:0)
Block(-8,38,0,AIR:0)
Block(-8,38,1,AIR:0)
Block(-8,38,2,AIR:0)
Block(-8,38,3,AIR:0)
Block(-8,38,4,AIR:0)
Block(-8,38,5,AIR:0)
Block(-8,38,6,AIR:0)
Block(-8,38,7,AIR:0)
Block(-8,38,8,AIR:0)
Block(-8,39,-7,AIR:0)
Block(-8,39,-6,AIR:0)
Block(-8,39,-5,AIR:0)
Block(-8,39,-4,AIR:0)
Block(-8,39,-3,AIR:0)
Block(-8,39,-2,AIR:0)
Block(-8,39,-1,AIR:0)
Block(-8,39,0,AIR:0)
Block(-8,39,1,AIR:0)
Block(-8,39,2,AIR:0)
Block(-8,39,3,AIR:0)
Block(-8,39,4,AIR:0)
Block(-8,39,5,AIR:0)
Block(-8,39,6,AIR:0)
Block(-8,39,7,AIR:0)
Block(-8,39,8,AIR:0)
Block(-8,40,-7,AIR:0)
Block(-8,40,-6,AIR:0)
Block(-8,40,-5,AIR:0)
Block(-8,40,-4,AIR:0)
Block(-8,40,-3,AIR:0)
Block(-8,40,-2,AIR:0)
Block(-8,40,-1,AIR:0)
Block(-8,40,0,AIR:0)
Block(-8,40,1,AIR:0)
Block(-8,40,2,AIR:0)
Block(-8,40,3,AIR:0)
Block(-8,40,4,AIR:0)
Block(-8,40,5,AIR:0)
Block(-8,40,6,AIR:0)
Block(-8,40,7,AIR:0)
Block(-8,40,8,AIR:0)
Block(-8,41,-7,AIR:0)
Block(-8,41,-6,AIR:0)
Block(-8,41,-5,AIR:0)
Block(-8,41,-4,AIR:0)
Block(-8,41,-3,AIR:0)
Block(-8,41,-2,AIR:0)
Block(-8,41,-1,AIR:0)
Block(-8,41,0,AIR:0)
Block(-8,41,1,AIR:0)
Block(-8,41,2,AIR:0)
Block(-8,41,3,AIR:0)
Block(-8,41,4,AIR:0)
Block(-8,41,5,AIR:0)
Block(-8,41,6,AIR:0)
Block(-8,41,7,AIR:0)
Block(-8,41,8,AIR:0)
Block(-8,42,-7,AIR:0)
Block(-8,42,-6,AIR:0)
Block(-8,42,-5,AIR:0)
Block(-8,42,-4,AIR:0)
Block(-8,42,-3,AIR:0)
Block(-8,42,-2,AIR:0)
Block(-8,42,-1,AIR:0)
Block(-8,42,0,AIR:0)
Block(-8,42,1,AIR:0)
Block(-8,42,2,AIR:0)
Block(-8,42,3,AIR:0)
Block(-8,42,4,AIR:0)
Block(-8,42,5,AIR:0)
Block(-8,42,6,AIR:0)
Block(-8,42,7,AIR:0)
Block(-8,42,8,AIR:0)
Block(-8,43,-7,AIR:0)
Block(-8,43,-6,AIR:0)
Block(-8,43,-5,AIR:0)
Block(-8,43,-4,AIR:0)
Block(-8,43,-3,AIR:0)
Block(-8,43,-2,AIR:0)
Block(-8,43,-1,AIR:0)
Block(-8,43,0,AIR:0)
Block(-8,43,1,AIR:0)
Block(-8,43,2,AIR:0)
Block(-8,43,3,AIR:0)
Block(-8,43,4,AIR:0)
Block(-8,43,5,AIR:0)
Block(-8,43,6,AIR:0)
Block(-8,43,7,AIR:0)
Block(-8,43,8,AIR:0)
Block(-8,44,-7,AIR:0)
Block(-8,44,-6,AIR:0)
Block(-8,44,-5,AIR:0)
Block(-8,44,-4,AIR:0)
Block(-8,44,-3,AIR:0)
Block(-8,44,-2,AIR:0)
Block(-8,44,-1,AIR:0)
Block(-8,44,0,AIR:0)
Block(-8,44,1,AIR:0)
Block(-8,44,2,AIR:0)
Block(-8,44,3,AIR:0)
Block(-8,44,4,AIR:0)
Block(-8,44,5,AIR:0)
Block(-8,44,6,AIR:0)
Block(-8,44,7,AIR:0)
Block(-8,44,8,AIR:0)
Block(-8,45,-7,AIR:0)
Block(-8,45,-6,AIR:0)
Block(-8,45,-5,AIR:0)
Block(-8,45,-4,AIR:0)
Block(-8,45,-3,AIR:0)
Block(-8,45,-2,AIR:0)
Block(-8,45,-1,AIR:0)
Block(-8,45,0,AIR:0)
Block(-8,45,1,AIR:0)
Block(-8,45,2,AIR:0)
Block(-8,45,3,AIR:0)
Block(-8,45,4,AIR:0)
Block(-8,45,5,AIR:0)
Block(-8,45,6,AIR:0)
Block(-8,45,7,AIR:0)
Block(-8,45,8,AIR:0)
Block(-8,46,-7,AIR:0)
Block(-8,46,-6,AIR:0)
Block(-8,46,-5,AIR:0)
Block(-8,46,-4,AIR:0)
Block(-8,46,-3,AIR:0)
Block(-8,46,-2,AIR:0)
Block(-8,46,-1,AIR:0)
Block(-8,46,0,AIR:0)
Block(-8,46,1,AIR:0)
Block(-8,46,2,AIR:0)
Block(-8,46,3,AIR:0)
Block(-8,46,4,AIR:0)
Block(-8,46,5,AIR:0)
Block(-8,46,6,AIR:0)
Block(-8,46,7,AIR:0)
Block(-8,46,8,AIR:0)
Block(-8,47,-7,AIR:0)
Block(-8,47,-6,AIR:0)
Block(-8,47,-5,AIR:0)
Block(-8,47,-4,AIR:0)
Block(-8,47,-3,AIR:0)
Block(-8,47,-2,AIR:0)
Block(-8,47,-1,AIR:0)
Block(-8,47,0,AIR:0)
Block(-8,47,1,AIR:0)
Block(-8,47,2,AIR:0)
Block(-8,47,3,AIR:0)
Block(-8,47,4,AIR:0)
Block(-8,47,5,AIR:0)
Block(-8,47,6,AIR:0)
Block(-8,47,7,AIR:0)
Block(-8,47,8,AIR:0)
Block(-8,48,-7,AIR:0)
Block(-8,48,-6,AIR:0)
Block(-8,48,-5,AIR:0)
Block(-8,48,-4,AIR:0)
Block(-8,48,-3,AIR:0)
Block(-8,48,-2,AIR:0)
Block(-8,48,-1,AIR:0)
Block(-8,48,0,AIR:0)
Block(-8,48,1,AIR:0)
Block(-8,48,2,AIR:0)
Block(-8,48,3,AIR:0)
Block(-8,48,4,AIR:0)
Block(-8,48,5,AIR:0)
Block(-8,48,6,AIR:0)
Block(-8,48,7,AIR:0)
Block(-8,48,8,AIR:0)
Block(-8,49,-7,AIR:0)
Block(-8,49,-6,AIR:0)
Block(-8,49,-5,AIR:0)
Block(-8,49,-4,AIR:0)
Block(-8,49,-3,AIR:0)
Block(-8,49,-2,AIR:0)
Block(-8,49,-1,AIR:0)
Block(-8,49,0,AIR:0)
Block(-8,49,1,AIR:0)
Block(-8,49,2,AIR:0)
Block(-8,49,3,AIR:0)
Block(-8,49,4,AIR:0)
Block(-8,49,5,AIR:0)
Block(-8,49,6,AIR:0)
Block(-8,49,7,AIR:0)
Block(-8,49,8,AIR:0)
Block(-8,50,-7,AIR:0)
Block(-8,50,-6,AIR:0)
Block(-8,50,-5,AIR:0)
Block(-8,50,-4,AIR:0)
Block(-8,50,-3,AIR:0)
Block(-8,50,-2,AIR:0)
Block(-8,50,-1,AIR:0)
Block(-8,50,0,AIR:0)
Block(-8,50,1,AIR:0)
Block(-8,50,2,AIR:0)
Block(-8,50,3,AIR:0)
Block(-8,50,4,AIR:0)
Block(-8,50,5,AIR:0)
Block(-8,50,6,AIR:0)
Block(-8,50,7,AIR:0)
Block(-8,50,8,AIR:0)
Block(-8,51,-7,AIR:0)
Block(-8,51,-6,AIR:0)
Block(-8,51,-5,AIR:0)
Block(-8,51,-4,AIR:0)
Block(-8,51,-3,AIR:0)
Block(-8,51,-2,AIR:0)
Block(-8,51,-1,AIR:0)
Block(-8,51,0,AIR:0)
Block(-8,51,1,AIR:0)
Block(-8,51,2,AIR:0)
Block(-8,51,3,AIR:0)
Block(-8,51,4,AIR:0)
Block(-8,51,5,AIR:0)
Block(-8,51,6,AIR:0)
Block(-8,51,7,AIR:0)
Block(-8,51,8,AIR:0)
Block(-8,52,-7,AIR:0)
Block(-8,52,-6,AIR:0)
Block(-8,52,-5,AIR:0)
Block(-8,52,-4,AIR:0)
Block(-8,52,-3,AIR:0)
Block(-8,52,-2,AIR:0)
Block(-8,52,-1,AIR:0)
Block(-8,52,0,AIR:0)
Block(-8,52,1,AIR:0)
Block(-8,52,2,AIR:0)
Block(-8,52,3,AIR:0)
Block(-8,52,4,AIR:0)
Block(-8,52,5,AIR:0)
Block(-8,52,6,AIR:0)
Block(-8,52,7,AIR:0)
Block(-8,52,8,AIR:0)
Block(-8,53,-7,AIR:0)
Block(-8,53,-6,AIR:0)
Block(-8,53,-5,AIR:0)
Block(-8,53,-4,AIR:0)
Block(-8,53,-3,AIR:0)
Block(-8,53,-2,AIR:0)
Block(-8,53,-1,AIR:0)
Block(-8,53,0,AIR:0)
Block(-8,53,1,AIR:0)
Block(-8,53,2,AIR:0)
Block(-8,53,3,AIR:0)
Block(-8,53,4,AIR:0)
Block(-8,53,5,AIR:0)
Block(-8,53,6,AIR:0)
Block(-8,53,7,AIR:0)
Block(-8,53,8,AIR:0)
Block(-8,54,-7,AIR:0)
Block(-8,54,-6,AIR:0)
Block(-8,54,-5,AIR:0)
Block(-8,54,-4,AIR:0)
Block(-8,54,-3,AIR:0)
Block(-8,54,-2,AIR:0)
Block(-8,54,-1,AIR:0)
Block(-8,54,0,AIR:0)
Block(-8,54,1,AIR:0)
Block(-8,54,2,AIR:0)
Block(-8,54,3,AIR:0)
Block(-8,54,4,AIR:0)
Block(-8,54,5,AIR:0)
Block(-8,54,6,AIR:0)
Block(-8,54,7,AIR:0)
Block(-8,54,8,AIR:0)
Block(-8,55,-7,AIR:0)
Block(-8,55,-6,AIR:0)
Block(-8,55,-5,AIR:0)
Block(-8,55,-4,AIR:0)
Block(-8,55,-3,AIR:0)
Block(-8,55,-2,AIR:0)
Block(-8,55,-1,AIR:0)
Block(-8,55,0,AIR:0)
Block(-8,55,1,AIR:0)
Block(-8,55,2,AIR:0)
Block(-8,55,3,AIR:0)
Block(-8,55,4,AIR:0)
Block(-8,55,5,AIR:0)
Block(-8,55,6,AIR:0)
Block(-8,55,7,AIR:0)
Block(-8,55,8,AIR:0)
Block(-8,56,-7,AIR:0)
Block(-8,56,-6,AIR:0)
Block(-8,56,-5,AIR:0)
Block(-8,56,-4,AIR:0)
Block(-8,56,-3,AIR:0)
Block(-8,56,-2,AIR:0)
Block(-8,56,-1,AIR:0)
Block(-8,56,0,AIR:0)
Block(-8,56,1,AIR:0)
Block(-8,56,2,AIR:0)
Block(-8,56,3,AIR:0)
Block(-8,56,4,AIR:0)
Block(-8,56,5,AIR:0)
Block(-8,56,6,AIR:0)
Block(-8,56,7,AIR:0)
Block(-8,56,8,AIR:0)
Block(-8,57,-7,AIR:0)
Block(-8,57,-6,AIR:0)
Block(-8,57,-5,AIR:0)
Block(-8,57,-4,AIR:0)
Block(-8,57,-3,AIR:0)
Block(-8,57,-2,AIR:0)
Block(-8,57,-1,AIR:0)
Block(-8,57,0,AIR:0)
Block(-8,57,1,AIR:0)
Block(-8,57,2,AIR:0)
Block(-8,57,3,AIR:0)
Block(-8,57,4,AIR:0)
Block(-8,57,5,AIR:0)
Block(-8,57,6,AIR:0)
Block(-8,57,7,AIR:0)
Block(-8,57,8,AIR:0)
Block(-8,58,-7,AIR:0)
Block(-8,58,-6,AIR:0)
Block(-8,58,-5,AIR:0)
Block(-8,58,-4,AIR:0)
Block(-8,58,-3,AIR:0)
Block(-8,58,-2,AIR:0)
Block(-8,58,-1,AIR:0)
Block(-8,58,0,AIR:0)
Block(-8,58,1,AIR:0)
Block(-8,58,2,AIR:0)
Block(-8,58,3,AIR:0)
Block(-8,58,4,AIR:0)
Block(-8,58,5,AIR:0)
Block(-8,58,6,AIR:0)
Block(-8,58,7,AIR:0)
Block(-8,58,8,AIR:0)
Block(-8,59,-7,AIR:0)
Block(-8,59,-6,AIR:0)
Block(-8,59,-5,AIR:0)
Block(-8,59,-4,AIR:0)
Block(-8,59,-3,AIR:0)
Block(-8,59,-2,AIR:0)
Block(-8,59,-1,AIR:0)
Block(-8,59,0,AIR:0)
Block(-8,59,1,AIR:0)
Block(-8,59,2,AIR:0)
Block(-8,59,3,AIR:0)
Block(-8,59,4,AIR:0)
Block(-8,59,5,AIR:0)
Block(-8,59,6,AIR:0)
Block(-8,59,7,AIR:0)
Block(-8,59,8,AIR:0)
Block(-8,60,-7,AIR:0)
Block(-8,60,-6,AIR:0)
Block(-8,60,-5,AIR:0)
Block(-8,60,-4,AIR:0)
Block(-8,60,-3,AIR:0)
Block(-8,60,-2,AIR:0)
Block(-8,60,-1,AIR:0)
Block(-8,60,0,AIR:0)
Block(-8,60,1,AIR:0)
Block(-8,60,2,AIR:0)
Block(-8,60,3,AIR:0)
Block(-8,60,4,AIR:0)
Block(-8,60,5,AIR:0)
Block(-8,60,6,AIR:0)
Block(-8,60,7,AIR:0)
Block(-8,60,8,AIR:0)
Block(-8,61,-7,AIR:0)
Block(-8,61,-6,AIR:0)
Block(-8,61,-5,AIR:0)
Block(-8,61,-4,AIR:0)
Block(-8,61,-3,AIR:0)
Block(-8,61,-2,AIR:0)
Block(-8,61,-1,AIR:0)
Block(-8,61,0,AIR:0)
Block(-8,61,1,AIR:0)
Block(-8,61,2,AIR:0)
Block(-8,61,3,AIR:0)
Block(-8,61,4,AIR:0)
Block(-8,61,5,AIR:0)
Block(-8,61,6,AIR:0)
Block(-8,61,7,AIR:0)
Block(-8,61,8,AIR:0)
Block(-8,62,-7,AIR:0)
Block(-8,62,-6,AIR:0)
Block(-8,62,-5,AIR:0)
Block(-8,62,-4,AIR:0)
Block(-8,62,-3,AIR:0)
Block(-8,62,-2,AIR:0)
Block(-8,62,-1,AIR:0)
Block(-8,62,0,AIR:0)
Block(-8,62,1,AIR:0)
Block(-8,62,2,AIR:0)
Block(-8,62,3,AIR:0)
Block(-8,62,4,AIR:0)
Block(-8,62,5,AIR:0)
Block(-8,62,6,AIR:0)
Block(-8,62,7,AIR:0)
Block(-8,62,8,AIR:0)
Block(-8,63,-7,AIR:0)
Block(-8,63,-6,AIR:0)
Block(-8,63,-5,AIR:0)
Block(-8,63,-4,AIR:0)
Block(-8,63,-3,AIR:0)
Block(-8,63,-2,AIR:0)
Block(-8,63,-1,AIR:0)
Block(-8,63,0,AIR:0)
Block(-8,63,1,AIR:0)
Block(-8,63,2,AIR:0)
Block(-8,63,3,AIR:0)
Block(-8,63,4,AIR:0)
Block(-8,63,5,AIR:0)
Block(-8,63,6,AIR:0)
Block(-8,63,7,AIR:0)
Block(-8,63,8,AIR:0)
Block(-7,-50,-7,LOG:0)
Block(-7,-50,-6,STONE:5)
Block(-7,-50,-5,COBBLESTONE:0)
Block(-7,-50,-4,COBBLESTONE:0)
Block(-7,-50,-3,COBBLESTONE:0)
Block(-7,-50,-2,COBBLESTONE:0)
Block(-7,-50,-1,LOG:0)
Block(-7,-50,0,COBBLESTONE:0)
Block(-7,-50,1,COBBLESTONE:0)
Block(-7,-50,2,COBBLESTONE:0)
Block(-7,-50,3,LOG:0)
Block(-7,-50,7,LOG:0)
Block(-7,-49,-7,LOG:0)
Block(-7,-49,-6,STONE:5)
Block(-7,-49,-5,COBBLESTONE:0)
Block(-7,-49,-4,COBBLESTONE:0)
Block(-7,-49,-3,COBBLESTONE:0)
Block(-7,-49,-2,COBBLESTONE:0)
Block(-7,-49,-1,LOG:0)
Block(-7,-49,0,COBBLESTONE:0)
Block(-7,-49,1,COBBLESTONE:0)
Block(-7,-49,2,COBBLESTONE:0)
Block(-7,-49,3,LOG:0)
Block(-7,-49,7,LOG:0)
Block(-7,-48,-7,LOG:0)
Block(-7,-48,-6,STONE:5)
Block(-7,-48,-5,COBBLESTONE:0)
Block(-7,-48,-4,COBBLESTONE:0)
Block(-7,-48,-3,COBBLESTONE:0)
Block(-7,-48,-2,COBBLESTONE:0)
Block(-7,-48,-1,LOG:0)
Block(-7,-48,0,COBBLESTONE:0)
Block(-7,-48,1,COBBLESTONE:0)
Block(-7,-48,2,COBBLESTONE:0)
Block(-7,-48,3,LOG:0)
Block(-7,-48,7,LOG:0)
Block(-7,-47,-7,LOG:0)
Block(-7,-47,-6,STONE:5)
Block(-7,-47,-5,COBBLESTONE:0)
Block(-7,-47,-4,COBBLESTONE:0)
Block(-7,-47,-3,COBBLESTONE:0)
Block(-7,-47,-2,COBBLESTONE:0)
Block(-7,-47,-1,LOG:0)
Block(-7,-47,0,COBBLESTONE:0)
Block(-7,-47,1,COBBLESTONE:0)
Block(-7,-47,2,COBBLESTONE:0)
Block(-7,-47,3,LOG:0)
Block(-7,-47,7,LOG:0)
Block(-7,-46,-7,LOG:0)
Block(-7,-46,-6,STONE:5)
Block(-7,-46,-5,COBBLESTONE:0)
Block(-7,-46,-4,COBBLESTONE:0)
Block(-7,-46,-3,COBBLESTONE:0)
Block(-7,-46,-2,COBBLESTONE:0)
Block(-7,-46,-1,LOG:0)
Block(-7,-46,0,COBBLESTONE:0)
Block(-7,-46,1,COBBLESTONE:0)
Block(-7,-46,2,COBBLESTONE:0)
Block(-7,-46,3,LOG:0)
Block(-7,-46,7,LOG:0)
Block(-7,-45,-7,LOG:0)
Block(-7,-45,-6,STONE:5)
Block(-7,-45,-5,COBBLESTONE:0)
Block(-7,-45,-4,COBBLESTONE:0)
Block(-7,-45,-3,COBBLESTONE:0)
Block(-7,-45,-2,COBBLESTONE:0)
Block(-7,-45,-1,LOG:0)
Block(-7,-45,0,COBBLESTONE:0)
Block(-7,-45,1,COBBLESTONE:0)
Block(-7,-45,2,COBBLESTONE:0)
Block(-7,-45,3,LOG:0)
Block(-7,-45,7,LOG:0)
Block(-7,-44,-7,LOG:0)
Block(-7,-44,-6,STONE:5)
Block(-7,-44,-5,COBBLESTONE:0)
Block(-7,-44,-4,COBBLESTONE:0)
Block(-7,-44,-3,COBBLESTONE:0)
Block(-7,-44,-2,COBBLESTONE:0)
Block(-7,-44,-1,LOG:0)
Block(-7,-44,0,COBBLESTONE:0)
Block(-7,-44,1,COBBLESTONE:0)
Block(-7,-44,2,COBBLESTONE:0)
Block(-7,-44,3,LOG:0)
Block(-7,-44,7,LOG:0)
Block(-7,-43,-7,LOG:0)
Block(-7,-43,-6,STONE:5)
Block(-7,-43,-5,COBBLESTONE:0)
Block(-7,-43,-4,COBBLESTONE:0)
Block(-7,-43,-3,COBBLESTONE:0)
Block(-7,-43,-2,COBBLESTONE:0)
Block(-7,-43,-1,LOG:0)
Block(-7,-43,0,COBBLESTONE:0)
Block(-7,-43,1,COBBLESTONE:0)
Block(-7,-43,2,COBBLESTONE:0)
Block(-7,-43,3,LOG:0)
Block(-7,-43,7,LOG:0)
Block(-7,-42,-7,LOG:0)
Block(-7,-42,-6,STONE:5)
Block(-7,-42,-5,COBBLESTONE:0)
Block(-7,-42,-4,COBBLESTONE:0)
Block(-7,-42,-3,COBBLESTONE:0)
Block(-7,-42,-2,COBBLESTONE:0)
Block(-7,-42,-1,LOG:0)
Block(-7,-42,0,COBBLESTONE:0)
Block(-7,-42,1,COBBLESTONE:0)
Block(-7,-42,2,COBBLESTONE:0)
Block(-7,-42,3,LOG:0)
Block(-7,-42,7,LOG:0)
Block(-7,-41,-7,LOG:0)
Block(-7,-41,-6,STONE:5)
Block(-7,-41,-5,COBBLESTONE:0)
Block(-7,-41,-4,COBBLESTONE:0)
Block(-7,-41,-3,COBBLESTONE:0)
Block(-7,-41,-2,COBBLESTONE:0)
Block(-7,-41,-1,LOG:0)
Block(-7,-41,0,COBBLESTONE:0)
Block(-7,-41,1,COBBLESTONE:0)
Block(-7,-41,2,COBBLESTONE:0)
Block(-7,-41,3,LOG:0)
Block(-7,-41,7,LOG:0)
Block(-7,-40,-7,LOG:0)
Block(-7,-40,-6,STONE:5)
Block(-7,-40,-5,COBBLESTONE:0)
Block(-7,-40,-4,COBBLESTONE:0)
Block(-7,-40,-3,COBBLESTONE:0)
Block(-7,-40,-2,COBBLESTONE:0)
Block(-7,-40,-1,LOG:0)
Block(-7,-40,0,COBBLESTONE:0)
Block(-7,-40,1,COBBLESTONE:0)
Block(-7,-40,2,COBBLESTONE:0)
Block(-7,-40,3,LOG:0)
Block(-7,-40,7,LOG:0)
Block(-7,-39,-7,LOG:0)
Block(-7,-39,-6,STONE:5)
Block(-7,-39,-5,COBBLESTONE:0)
Block(-7,-39,-4,COBBLESTONE:0)
Block(-7,-39,-3,COBBLESTONE:0)
Block(-7,-39,-2,COBBLESTONE:0)
Block(-7,-39,-1,LOG:0)
Block(-7,-39,0,COBBLESTONE:0)
Block(-7,-39,1,COBBLESTONE:0)
Block(-7,-39,2,COBBLESTONE:0)
Block(-7,-39,3,LOG:0)
Block(-7,-39,7,LOG:0)
Block(-7,-38,-7,LOG:0)
Block(-7,-38,-6,STONE:5)
Block(-7,-38,-5,COBBLESTONE:0)
Block(-7,-38,-4,COBBLESTONE:0)
Block(-7,-38,-3,COBBLESTONE:0)
Block(-7,-38,-2,COBBLESTONE:0)
Block(-7,-38,-1,LOG:0)
Block(-7,-38,0,COBBLESTONE:0)
Block(-7,-38,1,COBBLESTONE:0)
Block(-7,-38,2,COBBLESTONE:0)
Block(-7,-38,3,LOG:0)
Block(-7,-38,7,LOG:0)
Block(-7,-37,-7,LOG:0)
Block(-7,-37,-6,STONE:5)
Block(-7,-37,-5,COBBLESTONE:0)
Block(-7,-37,-4,COBBLESTONE:0)
Block(-7,-37,-3,COBBLESTONE:0)
Block(-7,-37,-2,COBBLESTONE:0)
Block(-7,-37,-1,LOG:0)
Block(-7,-37,0,COBBLESTONE:0)
Block(-7,-37,1,COBBLESTONE:0)
Block(-7,-37,2,COBBLESTONE:0)
Block(-7,-37,3,LOG:0)
Block(-7,-37,7,LOG:0)
Block(-7,-36,-7,LOG:0)
Block(-7,-36,-6,STONE:5)
Block(-7,-36,-5,COBBLESTONE:0)
Block(-7,-36,-4,COBBLESTONE:0)
Block(-7,-36,-3,COBBLESTONE:0)
Block(-7,-36,-2,COBBLESTONE:0)
Block(-7,-36,-1,LOG:0)
Block(-7,-36,0,COBBLESTONE:0)
Block(-7,-36,1,COBBLESTONE:0)
Block(-7,-36,2,COBBLESTONE:0)
Block(-7,-36,3,LOG:0)
Block(-7,-36,7,LOG:0)
Block(-7,-35,-7,LOG:0)
Block(-7,-35,-6,STONE:5)
Block(-7,-35,-5,COBBLESTONE:0)
Block(-7,-35,-4,COBBLESTONE:0)
Block(-7,-35,-3,COBBLESTONE:0)
Block(-7,-35,-2,COBBLESTONE:0)
Block(-7,-35,-1,LOG:0)
Block(-7,-35,0,COBBLESTONE:0)
Block(-7,-35,1,COBBLESTONE:0)
Block(-7,-35,2,COBBLESTONE:0)
Block(-7,-35,3,LOG:0)
Block(-7,-35,7,LOG:0)
Block(-7,-34,-7,LOG:0)
Block(-7,-34,-6,STONE:5)
Block(-7,-34,-5,COBBLESTONE:0)
Block(-7,-34,-4,COBBLESTONE:0)
Block(-7,-34,-3,COBBLESTONE:0)
Block(-7,-34,-2,COBBLESTONE:0)
Block(-7,-34,-1,LOG:0)
Block(-7,-34,0,COBBLESTONE:0)
Block(-7,-34,1,COBBLESTONE:0)
Block(-7,-34,2,STONE:0)
Block(-7,-34,3,LOG:0)
Block(-7,-34,7,LOG:0)
Block(-7,-33,-7,LOG:0)
Block(-7,-33,-6,STONE:5)
Block(-7,-33,-5,COBBLESTONE:0)
Block(-7,-33,-4,COBBLESTONE:0)
Block(-7,-33,-3,COBBLESTONE:0)
Block(-7,-33,-2,COBBLESTONE:0)
Block(-7,-33,-1,LOG:0)
Block(-7,-33,0,COBBLESTONE:0)
Block(-7,-33,1,COBBLESTONE:0)
Block(-7,-33,2,STONE:0)
Block(-7,-33,3,LOG:0)
Block(-7,-33,7,LOG:0)
Block(-7,-32,-7,LOG:0)
Block(-7,-32,-6,STONE:5)
Block(-7,-32,-5,COBBLESTONE:0)
Block(-7,-32,-4,COBBLESTONE:0)
Block(-7,-32,-3,COBBLESTONE:0)
Block(-7,-32,-2,COBBLESTONE:0)
Block(-7,-32,-1,LOG:0)
Block(-7,-32,0,COBBLESTONE:0)
Block(-7,-32,1,COBBLESTONE:0)
Block(-7,-32,2,STONE:0)
Block(-7,-32,3,LOG:0)
Block(-7,-32,7,LOG:0)
Block(-7,-31,-7,LOG:0)
Block(-7,-31,-6,STONE:5)
Block(-7,-31,-5,COBBLESTONE:0)
Block(-7,-31,-4,COBBLESTONE:0)
Block(-7,-31,-3,COBBLESTONE:0)
Block(-7,-31,-2,COBBLESTONE:0)
Block(-7,-31,-1,LOG:0)
Block(-7,-31,0,COBBLESTONE:0)
Block(-7,-31,1,COBBLESTONE:0)
Block(-7,-31,2,COBBLESTONE:0)
Block(-7,-31,3,LOG:0)
Block(-7,-31,7,LOG:0)
Block(-7,-30,-7,LOG:0)
Block(-7,-30,-6,STONE:5)
Block(-7,-30,-5,COBBLESTONE:0)
Block(-7,-30,-4,COBBLESTONE:0)
Block(-7,-30,-3,COBBLESTONE:0)
Block(-7,-30,-2,COBBLESTONE:0)
Block(-7,-30,-1,LOG:0)
Block(-7,-30,0,COBBLESTONE:0)
Block(-7,-30,1,COBBLESTONE:0)
Block(-7,-30,2,COBBLESTONE:0)
Block(-7,-30,3,LOG:0)
Block(-7,-30,7,LOG:0)
Block(-7,-29,-7,LOG:0)
Block(-7,-29,-6,STONE:5)
Block(-7,-29,-5,COBBLESTONE:0)
Block(-7,-29,-4,COBBLESTONE:0)
Block(-7,-29,-3,COBBLESTONE:0)
Block(-7,-29,-2,COBBLESTONE:0)
Block(-7,-29,-1,LOG:0)
Block(-7,-29,0,COBBLESTONE:0)
Block(-7,-29,1,COBBLESTONE:0)
Block(-7,-29,2,COBBLESTONE:0)
Block(-7,-29,3,LOG:0)
Block(-7,-29,7,LOG:0)
Block(-7,-28,-7,LOG:0)
Block(-7,-28,-6,STONE:5)
Block(-7,-28,-5,COBBLESTONE:0)
Block(-7,-28,-4,COBBLESTONE:0)
Block(-7,-28,-3,COBBLESTONE:0)
Block(-7,-28,-2,COBBLESTONE:0)
Block(-7,-28,-1,LOG:0)
Block(-7,-28,0,COBBLESTONE:0)
Block(-7,-28,1,COBBLESTONE:0)
Block(-7,-28,2,COBBLESTONE:0)
Block(-7,-28,3,LOG:0)
Block(-7,-28,7,LOG:0)
Block(-7,-27,-7,LOG:0)
Block(-7,-27,-6,STONE:5)
Block(-7,-27,-5,COBBLESTONE:0)
Block(-7,-27,-4,COBBLESTONE:0)
Block(-7,-27,-3,COBBLESTONE:0)
Block(-7,-27,-2,COBBLESTONE:0)
Block(-7,-27,-1,LOG:0)
Block(-7,-27,0,COBBLESTONE:0)
Block(-7,-27,1,COBBLESTONE:0)
Block(-7,-27,2,COBBLESTONE:0)
Block(-7,-27,3,LOG:0)
Block(-7,-27,7,LOG:0)
Block(-7,-26,-7,LOG:0)
Block(-7,-26,-6,STONE:5)
Block(-7,-26,-5,COBBLESTONE:0)
Block(-7,-26,-4,COBBLESTONE:0)
Block(-7,-26,-3,COBBLESTONE:0)
Block(-7,-26,-2,COBBLESTONE:0)
Block(-7,-26,-1,LOG:0)
Block(-7,-26,0,COBBLESTONE:0)
Block(-7,-26,1,COBBLESTONE:0)
Block(-7,-26,2,COBBLESTONE:0)
Block(-7,-26,3,LOG:0)
Block(-7,-26,7,LOG:0)
Block(-7,-25,-7,LOG:0)
Block(-7,-25,-6,STONE:5)
Block(-7,-25,-5,COBBLESTONE:0)
Block(-7,-25,-4,COBBLESTONE:0)
Block(-7,-25,-3,COBBLESTONE:0)
Block(-7,-25,-2,COBBLESTONE:0)
Block(-7,-25,-1,LOG:0)
Block(-7,-25,0,COBBLESTONE:0)
Block(-7,-25,1,COBBLESTONE:0)
Block(-7,-25,2,COBBLESTONE:0)
Block(-7,-25,3,LOG:0)
Block(-7,-25,7,LOG:0)
Block(-7,-24,-7,LOG:0)
Block(-7,-24,-6,STONE:5)
Block(-7,-24,-5,COBBLESTONE:0)
Block(-7,-24,-4,COBBLESTONE:0)
Block(-7,-24,-3,COBBLESTONE:0)
Block(-7,-24,-2,COBBLESTONE:0)
Block(-7,-24,-1,LOG:0)
Block(-7,-24,0,COBBLESTONE:0)
Block(-7,-24,1,COBBLESTONE:0)
Block(-7,-24,2,COBBLESTONE:0)
Block(-7,-24,3,LOG:0)
Block(-7,-24,7,LOG:0)
Block(-7,-23,-7,LOG:0)
Block(-7,-23,-6,STONE:5)
Block(-7,-23,-5,COBBLESTONE:0)
Block(-7,-23,-4,COBBLESTONE:0)
Block(-7,-23,-3,COBBLESTONE:0)
Block(-7,-23,-2,COBBLESTONE:0)
Block(-7,-23,-1,LOG:0)
Block(-7,-23,0,COBBLESTONE:0)
Block(-7,-23,1,COBBLESTONE:0)
Block(-7,-23,2,COBBLESTONE:0)
Block(-7,-23,3,LOG:0)
Block(-7,-23,7,LOG:0)
Block(-7,-22,-7,LOG:0)
Block(-7,-22,-6,STONE:5)
Block(-7,-22,-5,COBBLESTONE:0)
Block(-7,-22,-4,COBBLESTONE:0)
Block(-7,-22,-3,COBBLESTONE:0)
Block(-7,-22,-2,COBBLESTONE:0)
Block(-7,-22,-1,LOG:0)
Block(-7,-22,0,COBBLESTONE:0)
Block(-7,-22,1,COBBLESTONE:0)
Block(-7,-22,2,COBBLESTONE:0)
Block(-7,-22,3,LOG:0)
Block(-7,-22,7,LOG:0)
Block(-7,-21,-7,LOG:0)
Block(-7,-21,-6,STONE:5)
Block(-7,-21,-5,COBBLESTONE:0)
Block(-7,-21,-4,COBBLESTONE:0)
Block(-7,-21,-3,COBBLESTONE:0)
Block(-7,-21,-2,COBBLESTONE:0)
Block(-7,-21,-1,LOG:0)
Block(-7,-21,0,COBBLESTONE:0)
Block(-7,-21,1,COBBLESTONE:0)
Block(-7,-21,2,COBBLESTONE:0)
Block(-7,-21,3,LOG:0)
Block(-7,-21,7,LOG:0)
Block(-7,-20,-7,LOG:0)
Block(-7,-20,-6,STONE:5)
Block(-7,-20,-5,COBBLESTONE:0)
Block(-7,-20,-4,COBBLESTONE:0)
Block(-7,-20,-3,COBBLESTONE:0)
Block(-7,-20,-2,COBBLESTONE:0)
Block(-7,-20,-1,LOG:0)
Block(-7,-20,0,COBBLESTONE:0)
Block(-7,-20,1,COBBLESTONE:0)
Block(-7,-20,2,COBBLESTONE:0)
Block(-7,-20,3,LOG:0)
Block(-7,-20,7,LOG:0)
Block(-7,-19,-7,LOG:0)
Block(-7,-19,-6,COBBLESTONE:0)
Block(-7,-19,-5,COBBLESTONE:0)
Block(-7,-19,-4,COBBLESTONE:0)
Block(-7,-19,-3,COBBLESTONE:0)
Block(-7,-19,-2,STONE:5)
Block(-7,-19,-1,LOG:0)
Block(-7,-19,0,COBBLESTONE:0)
Block(-7,-19,1,COBBLESTONE:0)
Block(-7,-19,2,COBBLESTONE:0)
Block(-7,-19,3,LOG:0)
Block(-7,-19,7,LOG:0)
Block(-7,-18,-7,LOG:0)
Block(-7,-18,-6,STONE:5)
Block(-7,-18,-5,COBBLESTONE:0)
Block(-7,-18,-4,COBBLESTONE:0)
Block(-7,-18,-3,COBBLESTONE:0)
Block(-7,-18,-2,COBBLESTONE:0)
Block(-7,-18,-1,LOG:0)
Block(-7,-18,0,COBBLESTONE:0)
Block(-7,-18,1,COBBLESTONE:0)
Block(-7,-18,2,COBBLESTONE:0)
Block(-7,-18,3,LOG:0)
Block(-7,-18,7,LOG:0)
Block(-7,-17,-7,LOG:0)
Block(-7,-17,-6,STONE:5)
Block(-7,-17,-5,COBBLESTONE:0)
Block(-7,-17,-4,COBBLESTONE:0)
Block(-7,-17,-3,COBBLESTONE:0)
Block(-7,-17,-2,COBBLESTONE:0)
Block(-7,-17,-1,LOG:0)
Block(-7,-17,0,COBBLESTONE:0)
Block(-7,-17,1,COBBLESTONE:0)
Block(-7,-17,2,COBBLESTONE:0)
Block(-7,-17,3,LOG:0)
Block(-7,-17,7,LOG:0)
Block(-7,-16,-7,LOG:0)
Block(-7,-16,-6,STONE:5)
Block(-7,-16,-5,COBBLESTONE:0)
Block(-7,-16,-4,COBBLESTONE:0)
Block(-7,-16,-3,COBBLESTONE:0)
Block(-7,-16,-2,COBBLESTONE:0)
Block(-7,-16,-1,LOG:0)
Block(-7,-16,0,COBBLESTONE:0)
Block(-7,-16,1,COBBLESTONE:0)
Block(-7,-16,2,COBBLESTONE:0)
Block(-7,-16,3,LOG:0)
Block(-7,-16,7,LOG:0)
Block(-7,-15,-7,LOG:0)
Block(-7,-15,-6,SMOOTH_BRICK:1)
Block(-7,-15,-5,COBBLESTONE:0)
Block(-7,-15,-4,COBBLESTONE:0)
Block(-7,-15,-3,COBBLESTONE:0)
Block(-7,-15,-2,COBBLESTONE:0)
Block(-7,-15,-1,LOG:0)
Block(-7,-15,0,COBBLESTONE:0)
Block(-7,-15,1,COBBLESTONE:0)
Block(-7,-15,2,COBBLESTONE:0)
Block(-7,-15,3,LOG:0)
Block(-7,-15,7,LOG:0)
Block(-7,-14,-7,LOG:0)
Block(-7,-14,-6,COBBLESTONE:0)
Block(-7,-14,-5,COBBLESTONE:0)
Block(-7,-14,-4,COBBLESTONE:0)
Block(-7,-14,-3,COBBLESTONE:0)
Block(-7,-14,-2,COBBLESTONE:0)
Block(-7,-14,-1,LOG:0)
Block(-7,-14,0,COBBLESTONE:0)
Block(-7,-14,1,COBBLESTONE:0)
Block(-7,-14,2,COBBLESTONE:0)
Block(-7,-14,3,LOG:0)
Block(-7,-14,7,LOG:0)
Block(-7,-13,-7,LOG:0)
Block(-7,-13,-6,STONE:5)
Block(-7,-13,-5,COBBLESTONE:0)
Block(-7,-13,-4,COBBLESTONE:0)
Block(-7,-13,-3,COBBLESTONE:0)
Block(-7,-13,-2,SMOOTH_BRICK:0)
Block(-7,-13,-1,LOG:0)
Block(-7,-13,0,COBBLESTONE:0)
Block(-7,-13,1,COBBLESTONE:0)
Block(-7,-13,2,COBBLESTONE:0)
Block(-7,-13,3,LOG:0)
Block(-7,-13,7,LOG:0)
Block(-7,-12,-7,LOG:0)
Block(-7,-12,-6,SMOOTH_BRICK:0)
Block(-7,-12,-5,COBBLESTONE:0)
Block(-7,-12,-4,COBBLESTONE:0)
Block(-7,-12,-3,COBBLESTONE:0)
Block(-7,-12,-2,STAINED_CLAY:9)
Block(-7,-12,-1,LOG:0)
Block(-7,-12,0,COBBLESTONE:0)
Block(-7,-12,1,COBBLESTONE:0)
Block(-7,-12,2,COBBLESTONE:0)
Block(-7,-12,3,LOG:0)
Block(-7,-12,7,LOG:0)
Block(-7,-11,-7,LOG:0)
Block(-7,-11,-6,SMOOTH_BRICK:1)
Block(-7,-11,-5,COBBLESTONE:0)
Block(-7,-11,-4,COBBLESTONE:0)
Block(-7,-11,-3,COBBLESTONE:0)
Block(-7,-11,-2,STONE:5)
Block(-7,-11,-1,LOG:0)
Block(-7,-11,0,COBBLESTONE:0)
Block(-7,-11,1,COBBLESTONE:0)
Block(-7,-11,2,COBBLESTONE:0)
Block(-7,-11,3,LOG:0)
Block(-7,-11,7,LOG:0)
Block(-7,-10,-7,LOG:0)
Block(-7,-10,-6,COBBLESTONE:0)
Block(-7,-10,-5,COBBLESTONE:0)
Block(-7,-10,-4,COBBLESTONE:0)
Block(-7,-10,-3,COBBLESTONE:0)
Block(-7,-10,-2,STONE:5)
Block(-7,-10,-1,LOG:0)
Block(-7,-10,0,COBBLESTONE:0)
Block(-7,-10,1,STONE:5)
Block(-7,-10,2,STONE:5)
Block(-7,-10,3,LOG:0)
Block(-7,-10,7,LOG:0)
Block(-7,-9,-7,LOG:0)
Block(-7,-9,-6,STONE:5)
Block(-7,-9,-5,COBBLESTONE:0)
Block(-7,-9,-4,COBBLESTONE:0)
Block(-7,-9,-3,COBBLESTONE:0)
Block(-7,-9,-2,STAINED_CLAY:9)
Block(-7,-9,-1,LOG:0)
Block(-7,-9,0,STONE:6)
Block(-7,-9,1,LOG:4)
Block(-7,-9,2,COBBLESTONE_STAIRS:1)
Block(-7,-9,3,SMOOTH_STAIRS:3)
Block(-7,-9,7,LOG:0)
Block(-7,-8,-7,LOG:0)
Block(-7,-8,-6,STONE:6)
Block(-7,-8,-5,COBBLESTONE:0)
Block(-7,-8,-4,COBBLESTONE:0)
Block(-7,-8,-3,COBBLESTONE:0)
Block(-7,-8,-2,STONE:6)
Block(-7,-8,-1,LOG:0)
Block(-7,-8,0,STONE:6)
Block(-7,-8,1,LOG:0)
Block(-7,-8,7,LOG:0)
Block(-7,-7,-7,LOG:0)
Block(-7,-7,-6,STONE:6)
Block(-7,-7,-5,COBBLESTONE:0)
Block(-7,-7,-4,COBBLESTONE:0)
Block(-7,-7,-3,COBBLESTONE:0)
Block(-7,-7,-2,STONE:6)
Block(-7,-7,-1,LOG:0)
Block(-7,-7,0,STONE:6)
Block(-7,-7,1,LOG:0)
Block(-7,-7,7,LOG:0)
Block(-7,-6,-7,LOG:0)
Block(-7,-6,-6,STONE:6)
Block(-7,-6,-5,COBBLESTONE:0)
Block(-7,-6,-4,COBBLESTONE:0)
Block(-7,-6,-3,COBBLESTONE:0)
Block(-7,-6,-2,STONE:6)
Block(-7,-6,-1,LOG:0)
Block(-7,-6,0,STONE:6)
Block(-7,-6,1,LOG:0)
Block(-7,-6,7,LOG:0)
Block(-7,-5,-7,LOG:0)
Block(-7,-5,-6,STONE:6)
Block(-7,-5,-5,COBBLESTONE:0)
Block(-7,-5,-4,COBBLESTONE:0)
Block(-7,-5,-3,COBBLESTONE:0)
Block(-7,-5,-2,STONE:6)
Block(-7,-5,-1,LOG:0)
Block(-7,-5,0,STONE:6)
Block(-7,-5,1,LOG:0)
Block(-7,-5,7,LOG:0)
Block(-7,-4,-7,LOG:0)
Block(-7,-4,-6,STONE:6)
Block(-7,-4,-5,COBBLESTONE:0)
Block(-7,-4,-4,COBBLESTONE:0)
Block(-7,-4,-3,COBBLESTONE:0)
Block(-7,-4,-2,STONE:6)
Block(-7,-4,-1,LOG:0)
Block(-7,-4,1,COBBLESTONE_STAIRS:1)
Block(-7,-4,7,LOG:0)
Block(-7,-3,-7,LOG:0)
Block(-7,-3,-6,STONE:6)
Block(-7,-3,-5,COBBLESTONE:0)
Block(-7,-3,-4,COBBLESTONE:0)
Block(-7,-3,-3,COBBLESTONE:0)
Block(-7,-3,-2,STONE:6)
Block(-7,-3,-1,LOG:0)
Block(-7,-3,7,LOG:0)
Block(-7,-2,-7,LOG:0)
Block(-7,-2,-6,STONE:6)
Block(-7,-2,-5,COBBLESTONE:0)
Block(-7,-2,-4,COBBLESTONE:0)
Block(-7,-2,-3,COBBLESTONE:0)
Block(-7,-2,-2,STONE:6)
Block(-7,-2,-1,LOG:0)
Block(-7,-2,7,LOG:0)
Block(-7,-1,-7,LOG:0)
Block(-7,-1,-6,STONE:6)
Block(-7,-1,-5,COBBLESTONE:0)
Block(-7,-1,-4,COBBLESTONE:0)
Block(-7,-1,-3,COBBLESTONE:0)
Block(-7,-1,-2,STONE:6)
Block(-7,-1,-1,LOG:0)
Block(-7,-1,7,LOG:0)
Block(-7,0,-7,LOG:0)
Block(-7,0,-6,STONE:6)
Block(-7,0,-5,COBBLESTONE:0)
Block(-7,0,-4,COBBLESTONE:0)
Block(-7,0,-3,COBBLESTONE:0)
Block(-7,0,-2,STONE:6)
Block(-7,0,-1,LOG:0)
Block(-7,0,7,LOG:0)
Block(-7,1,-7,LOG:0)
Block(-7,1,-6,STONE:6)
Block(-7,1,-5,COBBLESTONE:0)
Block(-7,1,-4,COBBLESTONE:0)
Block(-7,1,-3,COBBLESTONE:0)
Block(-7,1,-2,STONE:6)
Block(-7,1,-1,LOG:0)
Block(-7,1,7,LOG:0)
Block(-7,2,-7,LOG:0)
Block(-7,2,-6,STONE:6)
Block(-7,2,-5,COBBLESTONE:0)
Block(-7,2,-4,COBBLESTONE:0)
Block(-7,2,-3,COBBLESTONE:0)
Block(-7,2,-2,STONE:6)
Block(-7,2,-1,LOG:0)
Block(-7,2,0,WOOD_STEP:13)
Block(-7,2,1,LOG:4)
Block(-7,2,2,AIR:0)
Block(-7,2,3,LOG:12)
Block(-7,2,4,WOOD_STEP:9)
Block(-7,2,5,WOOD_STEP:9)
Block(-7,2,6,WOOD_STEP:13)
Block(-7,2,7,LOG:0)
Block(-7,2,8,LOG:8)
Block(-7,3,-7,LOG:0)
Block(-7,3,-6,STONE:6)
Block(-7,3,-5,COBBLESTONE:0)
Block(-7,3,-4,COBBLESTONE:0)
Block(-7,3,-3,COBBLESTONE:0)
Block(-7,3,-2,STONE:6)
Block(-7,3,-1,LOG:0)
Block(-7,3,0,WOOD:1)
Block(-7,3,1,DARK_OAK_FENCE:0)
Block(-7,3,2,AIR:0)
Block(-7,3,3,AIR:0)
Block(-7,3,4,AIR:0)
Block(-7,3,5,AIR:0)
Block(-7,3,6,AIR:0)
Block(-7,3,7,LOG:0)
Block(-7,3,8,COBBLE_WALL:0)
Block(-7,4,-7,LOG:0)
Block(-7,4,-6,STONE:6)
Block(-7,4,-5,COBBLESTONE:0)
Block(-7,4,-4,COBBLESTONE:0)
Block(-7,4,-3,COBBLESTONE:0)
Block(-7,4,-2,STONE:6)
Block(-7,4,-1,LOG:0)
Block(-7,4,0,WOOD:1)
Block(-7,4,1,AIR:0)
Block(-7,4,2,AIR:0)
Block(-7,4,3,AIR:0)
Block(-7,4,4,AIR:0)
Block(-7,4,5,AIR:0)
Block(-7,4,6,AIR:0)
Block(-7,4,7,STONE_PLATE:0)
Block(-7,4,8,AIR:0)
Block(-7,5,-7,LOG:0)
Block(-7,5,-6,STONE:6)
Block(-7,5,-5,COBBLESTONE:0)
Block(-7,5,-4,COBBLESTONE:0)
Block(-7,5,-3,COBBLESTONE:0)
Block(-7,5,-2,STONE:6)
Block(-7,5,-1,LOG:0)
Block(-7,5,0,AIR:0)
Block(-7,5,1,AIR:0)
Block(-7,5,2,AIR:0)
Block(-7,5,3,AIR:0)
Block(-7,5,4,AIR:0)
Block(-7,5,5,AIR:0)
Block(-7,5,6,AIR:0)
Block(-7,5,7,AIR:0)
Block(-7,5,8,AIR:0)
Block(-7,6,-7,LOG:0)
Block(-7,6,-6,SMOOTH_BRICK:0)
Block(-7,6,-5,COBBLESTONE:0)
Block(-7,6,-4,COBBLESTONE:0)
Block(-7,6,-3,COBBLESTONE:0)
Block(-7,6,-2,SMOOTH_BRICK:0)
Block(-7,6,-1,LOG:0)
Block(-7,6,0,AIR:0)
Block(-7,6,1,AIR:0)
Block(-7,6,2,AIR:0)
Block(-7,6,3,AIR:0)
Block(-7,6,4,AIR:0)
Block(-7,6,5,AIR:0)
Block(-7,6,6,AIR:0)
Block(-7,6,7,AIR:0)
Block(-7,6,8,AIR:0)
Block(-7,7,-7,LOG:0)
Block(-7,7,-6,SMOOTH_BRICK:0)
Block(-7,7,-5,COBBLESTONE:0)
Block(-7,7,-4,COBBLESTONE:0)
Block(-7,7,-3,COBBLESTONE:0)
Block(-7,7,-2,SMOOTH_BRICK:0)
Block(-7,7,-1,LOG:0)
Block(-7,7,0,AIR:0)
Block(-7,7,1,AIR:0)
Block(-7,7,2,AIR:0)
Block(-7,7,3,AIR:0)
Block(-7,7,4,AIR:0)
Block(-7,7,5,AIR:0)
Block(-7,7,6,AIR:0)
Block(-7,7,7,AIR:0)
Block(-7,7,8,AIR:0)
Block(-7,8,-7,LOG:0)
Block(-7,8,-6,LOG:8)
Block(-7,8,-5,LOG:8)
Block(-7,8,-4,LOG:4)
Block(-7,8,-3,LOG:8)
Block(-7,8,-2,LOG:8)
Block(-7,8,-1,LOG:0)
Block(-7,8,0,DARK_OAK_STAIRS:7)
Block(-7,8,1,AIR:0)
Block(-7,8,2,AIR:0)
Block(-7,8,3,AIR:0)
Block(-7,8,4,AIR:0)
Block(-7,8,5,AIR:0)
Block(-7,8,6,AIR:0)
Block(-7,8,7,AIR:0)
Block(-7,8,8,AIR:0)
Block(-7,9,-7,SMOOTH_BRICK:0)
Block(-7,9,-6,AIR:0)
Block(-7,9,-5,AIR:0)
Block(-7,9,-4,AIR:0)
Block(-7,9,-3,AIR:0)
Block(-7,9,-2,AIR:0)
Block(-7,9,-1,SMOOTH_BRICK:0)
Block(-7,9,0,DARK_OAK_STAIRS:2)
Block(-7,9,1,AIR:0)
Block(-7,9,2,AIR:0)
Block(-7,9,3,AIR:0)
Block(-7,9,4,AIR:0)
Block(-7,9,5,AIR:0)
Block(-7,9,6,AIR:0)
Block(-7,9,7,AIR:0)
Block(-7,9,8,AIR:0)
Block(-7,10,-7,SMOOTH_BRICK:3)
Block(-7,10,-6,AIR:0)
Block(-7,10,-5,AIR:0)
Block(-7,10,-4,AIR:0)
Block(-7,10,-3,AIR:0)
Block(-7,10,-2,AIR:0)
Block(-7,10,-1,SMOOTH_BRICK:3)
Block(-7,10,0,DARK_OAK_STAIRS:6)
Block(-7,10,1,STEP:11)
Block(-7,10,2,AIR:0)
Block(-7,10,3,AIR:0)
Block(-7,10,4,AIR:0)
Block(-7,10,5,AIR:0)
Block(-7,10,6,AIR:0)
Block(-7,10,7,AIR:0)
Block(-7,10,8,AIR:0)
Block(-7,11,-7,DARK_OAK_STAIRS:1)
Block(-7,11,-6,STEP:11)
Block(-7,11,-5,WOOD_STEP:13)
Block(-7,11,-4,LOG:4)
Block(-7,11,-3,WOOD_STEP:13)
Block(-7,11,-2,STEP:11)
Block(-7,11,-1,DARK_OAK_STAIRS:1)
Block(-7,11,0,STEP:3)
Block(-7,11,1,AIR:0)
Block(-7,11,2,AIR:0)
Block(-7,11,3,AIR:0)
Block(-7,11,4,AIR:0)
Block(-7,11,5,AIR:0)
Block(-7,11,6,AIR:0)
Block(-7,11,7,AIR:0)
Block(-7,11,8,AIR:0)
Block(-7,12,-7,AIR:0)
Block(-7,12,-6,SMOOTH_STAIRS:1)
Block(-7,12,-5,SMOOTH_STAIRS:2)
Block(-7,12,-4,DARK_OAK_FENCE:0)
Block(-7,12,-3,SMOOTH_STAIRS:3)
Block(-7,12,-2,SMOOTH_STAIRS:1)
Block(-7,12,-1,AIR:0)
Block(-7,12,0,AIR:0)
Block(-7,12,1,AIR:0)
Block(-7,12,2,AIR:0)
Block(-7,12,3,AIR:0)
Block(-7,12,4,AIR:0)
Block(-7,12,5,AIR:0)
Block(-7,12,6,AIR:0)
Block(-7,12,7,AIR:0)
Block(-7,12,8,AIR:0)
Block(-7,13,-7,AIR:0)
Block(-7,13,-6,SMOOTH_STAIRS:5)
Block(-7,13,-5,SMOOTH_STAIRS:6)
Block(-7,13,-4,TORCH:5)
Block(-7,13,-3,SMOOTH_STAIRS:7)
Block(-7,13,-2,SMOOTH_STAIRS:5)
Block(-7,13,-1,AIR:0)
Block(-7,13,0,AIR:0)
Block(-7,13,1,AIR:0)
Block(-7,13,2,AIR:0)
Block(-7,13,3,AIR:0)
Block(-7,13,4,AIR:0)
Block(-7,13,5,AIR:0)
Block(-7,13,6,AIR:0)
Block(-7,13,7,AIR:0)
Block(-7,13,8,AIR:0)
Block(-7,14,-7,SMOOTH_STAIRS:5)
Block(-7,14,-6,WOOD:5)
Block(-7,14,-5,STONE:6)
Block(-7,14,-4,LOG:4)
Block(-7,14,-3,STONE:6)
Block(-7,14,-2,WOOD:5)
Block(-7,14,-1,SMOOTH_STAIRS:5)
Block(-7,14,0,AIR:0)
Block(-7,14,1,AIR:0)
Block(-7,14,2,AIR:0)
Block(-7,14,3,AIR:0)
Block(-7,14,4,AIR:0)
Block(-7,14,5,AIR:0)
Block(-7,14,6,AIR:0)
Block(-7,14,7,AIR:0)
Block(-7,14,8,AIR:0)
Block(-7,15,-7,SMOOTH_STAIRS:3)
Block(-7,15,-6,AIR:0)
Block(-7,15,-5,AIR:0)
Block(-7,15,-4,AIR:0)
Block(-7,15,-3,AIR:0)
Block(-7,15,-2,AIR:0)
Block(-7,15,-1,SMOOTH_STAIRS:2)
Block(-7,15,0,SMOOTH_STAIRS:7)
Block(-7,15,1,AIR:0)
Block(-7,15,2,AIR:0)
Block(-7,15,3,AIR:0)
Block(-7,15,4,AIR:0)
Block(-7,15,5,AIR:0)
Block(-7,15,6,AIR:0)
Block(-7,15,7,AIR:0)
Block(-7,15,8,AIR:0)
Block(-7,16,-7,AIR:0)
Block(-7,16,-6,AIR:0)
Block(-7,16,-5,AIR:0)
Block(-7,16,-4,AIR:0)
Block(-7,16,-3,AIR:0)
Block(-7,16,-2,AIR:0)
Block(-7,16,-1,AIR:0)
Block(-7,16,0,COBBLE_WALL:0)
Block(-7,16,1,AIR:0)
Block(-7,16,2,AIR:0)
Block(-7,16,3,AIR:0)
Block(-7,16,4,AIR:0)
Block(-7,16,5,AIR:0)
Block(-7,16,6,AIR:0)
Block(-7,16,7,AIR:0)
Block(-7,16,8,AIR:0)
Block(-7,17,-7,WOOD_DOUBLE_STEP:5)
Block(-7,17,-6,STONE:6)
Block(-7,17,-5,STONE:6)
Block(-7,17,-4,LOG:4)
Block(-7,17,-3,STONE:6)
Block(-7,17,-2,STONE:6)
Block(-7,17,-1,WOOD_DOUBLE_STEP:5)
Block(-7,17,0,WOOD_STEP:5)
Block(-7,17,1,AIR:0)
Block(-7,17,2,AIR:0)
Block(-7,17,3,AIR:0)
Block(-7,17,4,AIR:0)
Block(-7,17,5,AIR:0)
Block(-7,17,6,AIR:0)
Block(-7,17,7,AIR:0)
Block(-7,17,8,AIR:0)
Block(-7,18,-7,AIR:0)
Block(-7,18,-6,STONE:6)
Block(-7,18,-5,STONE:6)
Block(-7,18,-4,AIR:0)
Block(-7,18,-3,STONE:6)
Block(-7,18,-2,STONE:6)
Block(-7,18,-1,AIR:0)
Block(-7,18,0,AIR:0)
Block(-7,18,1,AIR:0)
Block(-7,18,2,AIR:0)
Block(-7,18,3,AIR:0)
Block(-7,18,4,AIR:0)
Block(-7,18,5,AIR:0)
Block(-7,18,6,AIR:0)
Block(-7,18,7,AIR:0)
Block(-7,18,8,AIR:0)
Block(-7,19,-7,AIR:0)
Block(-7,19,-6,DARK_OAK_STAIRS:1)
Block(-7,19,-5,DARK_OAK_STAIRS:1)
Block(-7,19,-4,LOG:4)
Block(-7,19,-3,DARK_OAK_STAIRS:1)
Block(-7,19,-2,DARK_OAK_STAIRS:1)
Block(-7,19,-1,AIR:0)
Block(-7,19,0,AIR:0)
Block(-7,19,1,AIR:0)
Block(-7,19,2,AIR:0)
Block(-7,19,3,AIR:0)
Block(-7,19,4,AIR:0)
Block(-7,19,5,AIR:0)
Block(-7,19,6,AIR:0)
Block(-7,19,7,AIR:0)
Block(-7,19,8,AIR:0)
Block(-7,20,-7,AIR:0)
Block(-7,20,-6,AIR:0)
Block(-7,20,-5,AIR:0)
Block(-7,20,-4,SMOOTH_STAIRS:1)
Block(-7,20,-3,AIR:0)
Block(-7,20,-2,AIR:0)
Block(-7,20,-1,AIR:0)
Block(-7,20,0,AIR:0)
Block(-7,20,1,AIR:0)
Block(-7,20,2,AIR:0)
Block(-7,20,3,AIR:0)
Block(-7,20,4,AIR:0)
Block(-7,20,5,AIR:0)
Block(-7,20,6,AIR:0)
Block(-7,20,7,AIR:0)
Block(-7,20,8,AIR:0)
Block(-7,21,-7,AIR:0)
Block(-7,21,-6,AIR:0)
Block(-7,21,-5,AIR:0)
Block(-7,21,-4,SMOOTH_STAIRS:5)
Block(-7,21,-3,AIR:0)
Block(-7,21,-2,AIR:0)
Block(-7,21,-1,AIR:0)
Block(-7,21,0,AIR:0)
Block(-7,21,1,AIR:0)
Block(-7,21,2,AIR:0)
Block(-7,21,3,AIR:0)
Block(-7,21,4,AIR:0)
Block(-7,21,5,AIR:0)
Block(-7,21,6,AIR:0)
Block(-7,21,7,AIR:0)
Block(-7,21,8,AIR:0)
Block(-7,22,-7,AIR:0)
Block(-7,22,-6,DARK_OAK_STAIRS:5)
Block(-7,22,-5,DARK_OAK_STAIRS:5)
Block(-7,22,-4,LOG:4)
Block(-7,22,-3,DARK_OAK_STAIRS:5)
Block(-7,22,-2,DARK_OAK_STAIRS:5)
Block(-7,22,-1,AIR:0)
Block(-7,22,0,AIR:0)
Block(-7,22,1,AIR:0)
Block(-7,22,2,AIR:0)
Block(-7,22,3,AIR:0)
Block(-7,22,4,AIR:0)
Block(-7,22,5,AIR:0)
Block(-7,22,6,AIR:0)
Block(-7,22,7,AIR:0)
Block(-7,22,8,AIR:0)
Block(-7,23,-7,AIR:0)
Block(-7,23,-6,STONE:6)
Block(-7,23,-5,STONE:6)
Block(-7,23,-4,STONE:6)
Block(-7,23,-3,STONE:6)
Block(-7,23,-2,STONE:6)
Block(-7,23,-1,AIR:0)
Block(-7,23,0,AIR:0)
Block(-7,23,1,AIR:0)
Block(-7,23,2,AIR:0)
Block(-7,23,3,AIR:0)
Block(-7,23,4,AIR:0)
Block(-7,23,5,AIR:0)
Block(-7,23,6,AIR:0)
Block(-7,23,7,AIR:0)
Block(-7,23,8,AIR:0)
Block(-7,24,-7,COBBLESTONE_STAIRS:5)
Block(-7,24,-6,WOOD_STEP:5)
Block(-7,24,-5,WOOD_STEP:5)
Block(-7,24,-4,WOOD_STEP:5)
Block(-7,24,-3,WOOD_STEP:5)
Block(-7,24,-2,WOOD_STEP:5)
Block(-7,24,-1,COBBLESTONE_STAIRS:5)
Block(-7,24,0,AIR:0)
Block(-7,24,1,AIR:0)
Block(-7,24,2,AIR:0)
Block(-7,24,3,AIR:0)
Block(-7,24,4,AIR:0)
Block(-7,24,5,AIR:0)
Block(-7,24,6,AIR:0)
Block(-7,24,7,AIR:0)
Block(-7,24,8,AIR:0)
Block(-7,25,-7,COBBLESTONE_STAIRS:1)
Block(-7,25,-6,AIR:0)
Block(-7,25,-5,AIR:0)
Block(-7,25,-4,AIR:0)
Block(-7,25,-3,AIR:0)
Block(-7,25,-2,AIR:0)
Block(-7,25,-1,COBBLESTONE_STAIRS:1)
Block(-7,25,0,AIR:0)
Block(-7,25,1,AIR:0)
Block(-7,25,2,AIR:0)
Block(-7,25,3,AIR:0)
Block(-7,25,4,AIR:0)
Block(-7,25,5,AIR:0)
Block(-7,25,6,AIR:0)
Block(-7,25,7,AIR:0)
Block(-7,25,8,AIR:0)
Block(-7,26,-7,AIR:0)
Block(-7,26,-6,AIR:0)
Block(-7,26,-5,AIR:0)
Block(-7,26,-4,AIR:0)
Block(-7,26,-3,AIR:0)
Block(-7,26,-2,AIR:0)
Block(-7,26,-1,AIR:0)
Block(-7,26,0,AIR:0)
Block(-7,26,1,AIR:0)
Block(-7,26,2,AIR:0)
Block(-7,26,3,AIR:0)
Block(-7,26,4,AIR:0)
Block(-7,26,5,AIR:0)
Block(-7,26,6,AIR:0)
Block(-7,26,7,AIR:0)
Block(-7,26,8,AIR:0)
Block(-7,27,-7,AIR:0)
Block(-7,27,-6,AIR:0)
Block(-7,27,-5,AIR:0)
Block(-7,27,-4,AIR:0)
Block(-7,27,-3,AIR:0)
Block(-7,27,-2,AIR:0)
Block(-7,27,-1,AIR:0)
Block(-7,27,0,AIR:0)
Block(-7,27,1,AIR:0)
Block(-7,27,2,AIR:0)
Block(-7,27,3,AIR:0)
Block(-7,27,4,AIR:0)
Block(-7,27,5,AIR:0)
Block(-7,27,6,AIR:0)
Block(-7,27,7,AIR:0)
Block(-7,27,8,AIR:0)
Block(-7,28,-7,AIR:0)
Block(-7,28,-6,AIR:0)
Block(-7,28,-5,AIR:0)
Block(-7,28,-4,AIR:0)
Block(-7,28,-3,AIR:0)
Block(-7,28,-2,AIR:0)
Block(-7,28,-1,AIR:0)
Block(-7,28,0,AIR:0)
Block(-7,28,1,AIR:0)
Block(-7,28,2,AIR:0)
Block(-7,28,3,AIR:0)
Block(-7,28,4,AIR:0)
Block(-7,28,5,AIR:0)
Block(-7,28,6,AIR:0)
Block(-7,28,7,AIR:0)
Block(-7,28,8,AIR:0)
Block(-7,29,-7,AIR:0)
Block(-7,29,-6,AIR:0)
Block(-7,29,-5,AIR:0)
Block(-7,29,-4,AIR:0)
Block(-7,29,-3,AIR:0)
Block(-7,29,-2,AIR:0)
Block(-7,29,-1,AIR:0)
Block(-7,29,0,AIR:0)
Block(-7,29,1,AIR:0)
Block(-7,29,2,AIR:0)
Block(-7,29,3,AIR:0)
Block(-7,29,4,AIR:0)
Block(-7,29,5,AIR:0)
Block(-7,29,6,AIR:0)
Block(-7,29,7,AIR:0)
Block(-7,29,8,AIR:0)
Block(-7,30,-7,AIR:0)
Block(-7,30,-6,AIR:0)
Block(-7,30,-5,AIR:0)
Block(-7,30,-4,AIR:0)
Block(-7,30,-3,AIR:0)
Block(-7,30,-2,AIR:0)
Block(-7,30,-1,AIR:0)
Block(-7,30,0,AIR:0)
Block(-7,30,1,AIR:0)
Block(-7,30,2,AIR:0)
Block(-7,30,3,AIR:0)
Block(-7,30,4,AIR:0)
Block(-7,30,5,AIR:0)
Block(-7,30,6,AIR:0)
Block(-7,30,7,AIR:0)
Block(-7,30,8,AIR:0)
Block(-7,31,-7,AIR:0)
Block(-7,31,-6,AIR:0)
Block(-7,31,-5,AIR:0)
Block(-7,31,-4,AIR:0)
Block(-7,31,-3,AIR:0)
Block(-7,31,-2,AIR:0)
Block(-7,31,-1,AIR:0)
Block(-7,31,0,AIR:0)
Block(-7,31,1,AIR:0)
Block(-7,31,2,AIR:0)
Block(-7,31,3,AIR:0)
Block(-7,31,4,AIR:0)
Block(-7,31,5,AIR:0)
Block(-7,31,6,AIR:0)
Block(-7,31,7,AIR:0)
Block(-7,31,8,AIR:0)
Block(-7,32,-7,AIR:0)
Block(-7,32,-6,AIR:0)
Block(-7,32,-5,AIR:0)
Block(-7,32,-4,AIR:0)
Block(-7,32,-3,AIR:0)
Block(-7,32,-2,AIR:0)
Block(-7,32,-1,AIR:0)
Block(-7,32,0,AIR:0)
Block(-7,32,1,AIR:0)
Block(-7,32,2,AIR:0)
Block(-7,32,3,AIR:0)
Block(-7,32,4,AIR:0)
Block(-7,32,5,AIR:0)
Block(-7,32,6,AIR:0)
Block(-7,32,7,AIR:0)
Block(-7,32,8,AIR:0)
Block(-7,33,-7,AIR:0)
Block(-7,33,-6,AIR:0)
Block(-7,33,-5,AIR:0)
Block(-7,33,-4,AIR:0)
Block(-7,33,-3,AIR:0)
Block(-7,33,-2,AIR:0)
Block(-7,33,-1,AIR:0)
Block(-7,33,0,AIR:0)
Block(-7,33,1,AIR:0)
Block(-7,33,2,AIR:0)
Block(-7,33,3,AIR:0)
Block(-7,33,4,AIR:0)
Block(-7,33,5,AIR:0)
Block(-7,33,6,AIR:0)
Block(-7,33,7,AIR:0)
Block(-7,33,8,AIR:0)
Block(-7,34,-7,AIR:0)
Block(-7,34,-6,AIR:0)
Block(-7,34,-5,AIR:0)
Block(-7,34,-4,AIR:0)
Block(-7,34,-3,AIR:0)
Block(-7,34,-2,AIR:0)
Block(-7,34,-1,AIR:0)
Block(-7,34,0,AIR:0)
Block(-7,34,1,AIR:0)
Block(-7,34,2,AIR:0)
Block(-7,34,3,AIR:0)
Block(-7,34,4,AIR:0)
Block(-7,34,5,AIR:0)
Block(-7,34,6,AIR:0)
Block(-7,34,7,AIR:0)
Block(-7,34,8,AIR:0)
Block(-7,35,-7,AIR:0)
Block(-7,35,-6,AIR:0)
Block(-7,35,-5,AIR:0)
Block(-7,35,-4,AIR:0)
Block(-7,35,-3,AIR:0)
Block(-7,35,-2,AIR:0)
Block(-7,35,-1,AIR:0)
Block(-7,35,0,AIR:0)
Block(-7,35,1,AIR:0)
Block(-7,35,2,AIR:0)
Block(-7,35,3,AIR:0)
Block(-7,35,4,AIR:0)
Block(-7,35,5,AIR:0)
Block(-7,35,6,AIR:0)
Block(-7,35,7,AIR:0)
Block(-7,35,8,AIR:0)
Block(-7,36,-7,AIR:0)
Block(-7,36,-6,AIR:0)
Block(-7,36,-5,AIR:0)
Block(-7,36,-4,AIR:0)
Block(-7,36,-3,AIR:0)
Block(-7,36,-2,AIR:0)
Block(-7,36,-1,AIR:0)
Block(-7,36,0,AIR:0)
Block(-7,36,1,AIR:0)
Block(-7,36,2,AIR:0)
Block(-7,36,3,AIR:0)
Block(-7,36,4,AIR:0)
Block(-7,36,5,AIR:0)
Block(-7,36,6,AIR:0)
Block(-7,36,7,AIR:0)
Block(-7,36,8,AIR:0)
Block(-7,37,-7,AIR:0)
Block(-7,37,-6,AIR:0)
Block(-7,37,-5,AIR:0)
Block(-7,37,-4,AIR:0)
Block(-7,37,-3,AIR:0)
Block(-7,37,-2,AIR:0)
Block(-7,37,-1,AIR:0)
Block(-7,37,0,AIR:0)
Block(-7,37,1,AIR:0)
Block(-7,37,2,AIR:0)
Block(-7,37,3,AIR:0)
Block(-7,37,4,AIR:0)
Block(-7,37,5,AIR:0)
Block(-7,37,6,AIR:0)
Block(-7,37,7,AIR:0)
Block(-7,37,8,AIR:0)
Block(-7,38,-7,AIR:0)
Block(-7,38,-6,AIR:0)
Block(-7,38,-5,AIR:0)
Block(-7,38,-4,AIR:0)
Block(-7,38,-3,AIR:0)
Block(-7,38,-2,AIR:0)
Block(-7,38,-1,AIR:0)
Block(-7,38,0,AIR:0)
Block(-7,38,1,AIR:0)
Block(-7,38,2,AIR:0)
Block(-7,38,3,AIR:0)
Block(-7,38,4,AIR:0)
Block(-7,38,5,AIR:0)
Block(-7,38,6,AIR:0)
Block(-7,38,7,AIR:0)
Block(-7,38,8,AIR:0)
Block(-7,39,-7,AIR:0)
Block(-7,39,-6,AIR:0)
Block(-7,39,-5,AIR:0)
Block(-7,39,-4,AIR:0)
Block(-7,39,-3,AIR:0)
Block(-7,39,-2,AIR:0)
Block(-7,39,-1,AIR:0)
Block(-7,39,0,AIR:0)
Block(-7,39,1,AIR:0)
Block(-7,39,2,AIR:0)
Block(-7,39,3,AIR:0)
Block(-7,39,4,AIR:0)
Block(-7,39,5,AIR:0)
Block(-7,39,6,AIR:0)
Block(-7,39,7,AIR:0)
Block(-7,39,8,AIR:0)
Block(-7,40,-7,AIR:0)
Block(-7,40,-6,AIR:0)
Block(-7,40,-5,AIR:0)
Block(-7,40,-4,AIR:0)
Block(-7,40,-3,AIR:0)
Block(-7,40,-2,AIR:0)
Block(-7,40,-1,AIR:0)
Block(-7,40,0,AIR:0)
Block(-7,40,1,AIR:0)
Block(-7,40,2,AIR:0)
Block(-7,40,3,AIR:0)
Block(-7,40,4,AIR:0)
Block(-7,40,5,AIR:0)
Block(-7,40,6,AIR:0)
Block(-7,40,7,AIR:0)
Block(-7,40,8,AIR:0)
Block(-7,41,-7,AIR:0)
Block(-7,41,-6,AIR:0)
Block(-7,41,-5,AIR:0)
Block(-7,41,-4,AIR:0)
Block(-7,41,-3,AIR:0)
Block(-7,41,-2,AIR:0)
Block(-7,41,-1,AIR:0)
Block(-7,41,0,AIR:0)
Block(-7,41,1,AIR:0)
Block(-7,41,2,AIR:0)
Block(-7,41,3,AIR:0)
Block(-7,41,4,AIR:0)
Block(-7,41,5,AIR:0)
Block(-7,41,6,AIR:0)
Block(-7,41,7,AIR:0)
Block(-7,41,8,AIR:0)
Block(-7,42,-7,AIR:0)
Block(-7,42,-6,AIR:0)
Block(-7,42,-5,AIR:0)
Block(-7,42,-4,AIR:0)
Block(-7,42,-3,AIR:0)
Block(-7,42,-2,AIR:0)
Block(-7,42,-1,AIR:0)
Block(-7,42,0,AIR:0)
Block(-7,42,1,AIR:0)
Block(-7,42,2,AIR:0)
Block(-7,42,3,AIR:0)
Block(-7,42,4,AIR:0)
Block(-7,42,5,AIR:0)
Block(-7,42,6,AIR:0)
Block(-7,42,7,AIR:0)
Block(-7,42,8,AIR:0)
Block(-7,43,-7,AIR:0)
Block(-7,43,-6,AIR:0)
Block(-7,43,-5,AIR:0)
Block(-7,43,-4,AIR:0)
Block(-7,43,-3,AIR:0)
Block(-7,43,-2,AIR:0)
Block(-7,43,-1,AIR:0)
Block(-7,43,0,AIR:0)
Block(-7,43,1,AIR:0)
Block(-7,43,2,AIR:0)
Block(-7,43,3,AIR:0)
Block(-7,43,4,AIR:0)
Block(-7,43,5,AIR:0)
Block(-7,43,6,AIR:0)
Block(-7,43,7,AIR:0)
Block(-7,43,8,AIR:0)
Block(-7,44,-7,AIR:0)
Block(-7,44,-6,AIR:0)
Block(-7,44,-5,AIR:0)
Block(-7,44,-4,AIR:0)
Block(-7,44,-3,AIR:0)
Block(-7,44,-2,AIR:0)
Block(-7,44,-1,AIR:0)
Block(-7,44,0,AIR:0)
Block(-7,44,1,AIR:0)
Block(-7,44,2,AIR:0)
Block(-7,44,3,AIR:0)
Block(-7,44,4,AIR:0)
Block(-7,44,5,AIR:0)
Block(-7,44,6,AIR:0)
Block(-7,44,7,AIR:0)
Block(-7,44,8,AIR:0)
Block(-7,45,-7,AIR:0)
Block(-7,45,-6,AIR:0)
Block(-7,45,-5,AIR:0)
Block(-7,45,-4,AIR:0)
Block(-7,45,-3,AIR:0)
Block(-7,45,-2,AIR:0)
Block(-7,45,-1,AIR:0)
Block(-7,45,0,AIR:0)
Block(-7,45,1,AIR:0)
Block(-7,45,2,AIR:0)
Block(-7,45,3,AIR:0)
Block(-7,45,4,AIR:0)
Block(-7,45,5,AIR:0)
Block(-7,45,6,AIR:0)
Block(-7,45,7,AIR:0)
Block(-7,45,8,AIR:0)
Block(-7,46,-7,AIR:0)
Block(-7,46,-6,AIR:0)
Block(-7,46,-5,AIR:0)
Block(-7,46,-4,AIR:0)
Block(-7,46,-3,AIR:0)
Block(-7,46,-2,AIR:0)
Block(-7,46,-1,AIR:0)
Block(-7,46,0,AIR:0)
Block(-7,46,1,AIR:0)
Block(-7,46,2,AIR:0)
Block(-7,46,3,AIR:0)
Block(-7,46,4,AIR:0)
Block(-7,46,5,AIR:0)
Block(-7,46,6,AIR:0)
Block(-7,46,7,AIR:0)
Block(-7,46,8,AIR:0)
Block(-7,47,-7,AIR:0)
Block(-7,47,-6,AIR:0)
Block(-7,47,-5,AIR:0)
Block(-7,47,-4,AIR:0)
Block(-7,47,-3,AIR:0)
Block(-7,47,-2,AIR:0)
Block(-7,47,-1,AIR:0)
Block(-7,47,0,AIR:0)
Block(-7,47,1,AIR:0)
Block(-7,47,2,AIR:0)
Block(-7,47,3,AIR:0)
Block(-7,47,4,AIR:0)
Block(-7,47,5,AIR:0)
Block(-7,47,6,AIR:0)
Block(-7,47,7,AIR:0)
Block(-7,47,8,AIR:0)
Block(-7,48,-7,AIR:0)
Block(-7,48,-6,AIR:0)
Block(-7,48,-5,AIR:0)
Block(-7,48,-4,AIR:0)
Block(-7,48,-3,AIR:0)
Block(-7,48,-2,AIR:0)
Block(-7,48,-1,AIR:0)
Block(-7,48,0,AIR:0)
Block(-7,48,1,AIR:0)
Block(-7,48,2,AIR:0)
Block(-7,48,3,AIR:0)
Block(-7,48,4,AIR:0)
Block(-7,48,5,AIR:0)
Block(-7,48,6,AIR:0)
Block(-7,48,7,AIR:0)
Block(-7,48,8,AIR:0)
Block(-7,49,-7,AIR:0)
Block(-7,49,-6,AIR:0)
Block(-7,49,-5,AIR:0)
Block(-7,49,-4,AIR:0)
Block(-7,49,-3,AIR:0)
Block(-7,49,-2,AIR:0)
Block(-7,49,-1,AIR:0)
Block(-7,49,0,AIR:0)
Block(-7,49,1,AIR:0)
Block(-7,49,2,AIR:0)
Block(-7,49,3,AIR:0)
Block(-7,49,4,AIR:0)
Block(-7,49,5,AIR:0)
Block(-7,49,6,AIR:0)
Block(-7,49,7,AIR:0)
Block(-7,49,8,AIR:0)
Block(-7,50,-7,AIR:0)
Block(-7,50,-6,AIR:0)
Block(-7,50,-5,AIR:0)
Block(-7,50,-4,AIR:0)
Block(-7,50,-3,AIR:0)
Block(-7,50,-2,AIR:0)
Block(-7,50,-1,AIR:0)
Block(-7,50,0,AIR:0)
Block(-7,50,1,AIR:0)
Block(-7,50,2,AIR:0)
Block(-7,50,3,AIR:0)
Block(-7,50,4,AIR:0)
Block(-7,50,5,AIR:0)
Block(-7,50,6,AIR:0)
Block(-7,50,7,AIR:0)
Block(-7,50,8,AIR:0)
Block(-7,51,-7,AIR:0)
Block(-7,51,-6,AIR:0)
Block(-7,51,-5,AIR:0)
Block(-7,51,-4,AIR:0)
Block(-7,51,-3,AIR:0)
Block(-7,51,-2,AIR:0)
Block(-7,51,-1,AIR:0)
Block(-7,51,0,AIR:0)
Block(-7,51,1,AIR:0)
Block(-7,51,2,AIR:0)
Block(-7,51,3,AIR:0)
Block(-7,51,4,AIR:0)
Block(-7,51,5,AIR:0)
Block(-7,51,6,AIR:0)
Block(-7,51,7,AIR:0)
Block(-7,51,8,AIR:0)
Block(-7,52,-7,AIR:0)
Block(-7,52,-6,AIR:0)
Block(-7,52,-5,AIR:0)
Block(-7,52,-4,AIR:0)
Block(-7,52,-3,AIR:0)
Block(-7,52,-2,AIR:0)
Block(-7,52,-1,AIR:0)
Block(-7,52,0,AIR:0)
Block(-7,52,1,AIR:0)
Block(-7,52,2,AIR:0)
Block(-7,52,3,AIR:0)
Block(-7,52,4,AIR:0)
Block(-7,52,5,AIR:0)
Block(-7,52,6,AIR:0)
Block(-7,52,7,AIR:0)
Block(-7,52,8,AIR:0)
Block(-7,53,-7,AIR:0)
Block(-7,53,-6,AIR:0)
Block(-7,53,-5,AIR:0)
Block(-7,53,-4,AIR:0)
Block(-7,53,-3,AIR:0)
Block(-7,53,-2,AIR:0)
Block(-7,53,-1,AIR:0)
Block(-7,53,0,AIR:0)
Block(-7,53,1,AIR:0)
Block(-7,53,2,AIR:0)
Block(-7,53,3,AIR:0)
Block(-7,53,4,AIR:0)
Block(-7,53,5,AIR:0)
Block(-7,53,6,AIR:0)
Block(-7,53,7,AIR:0)
Block(-7,53,8,AIR:0)
Block(-7,54,-7,AIR:0)
Block(-7,54,-6,AIR:0)
Block(-7,54,-5,AIR:0)
Block(-7,54,-4,AIR:0)
Block(-7,54,-3,AIR:0)
Block(-7,54,-2,AIR:0)
Block(-7,54,-1,AIR:0)
Block(-7,54,0,AIR:0)
Block(-7,54,1,AIR:0)
Block(-7,54,2,AIR:0)
Block(-7,54,3,AIR:0)
Block(-7,54,4,AIR:0)
Block(-7,54,5,AIR:0)
Block(-7,54,6,AIR:0)
Block(-7,54,7,AIR:0)
Block(-7,54,8,AIR:0)
Block(-7,55,-7,AIR:0)
Block(-7,55,-6,AIR:0)
Block(-7,55,-5,AIR:0)
Block(-7,55,-4,AIR:0)
Block(-7,55,-3,AIR:0)
Block(-7,55,-2,AIR:0)
Block(-7,55,-1,AIR:0)
Block(-7,55,0,AIR:0)
Block(-7,55,1,AIR:0)
Block(-7,55,2,AIR:0)
Block(-7,55,3,AIR:0)
Block(-7,55,4,AIR:0)
Block(-7,55,5,AIR:0)
Block(-7,55,6,AIR:0)
Block(-7,55,7,AIR:0)
Block(-7,55,8,AIR:0)
Block(-7,56,-7,AIR:0)
Block(-7,56,-6,AIR:0)
Block(-7,56,-5,AIR:0)
Block(-7,56,-4,AIR:0)
Block(-7,56,-3,AIR:0)
Block(-7,56,-2,AIR:0)
Block(-7,56,-1,AIR:0)
Block(-7,56,0,AIR:0)
Block(-7,56,1,AIR:0)
Block(-7,56,2,AIR:0)
Block(-7,56,3,AIR:0)
Block(-7,56,4,AIR:0)
Block(-7,56,5,AIR:0)
Block(-7,56,6,AIR:0)
Block(-7,56,7,AIR:0)
Block(-7,56,8,AIR:0)
Block(-7,57,-7,AIR:0)
Block(-7,57,-6,AIR:0)
Block(-7,57,-5,AIR:0)
Block(-7,57,-4,AIR:0)
Block(-7,57,-3,AIR:0)
Block(-7,57,-2,AIR:0)
Block(-7,57,-1,AIR:0)
Block(-7,57,0,AIR:0)
Block(-7,57,1,AIR:0)
Block(-7,57,2,AIR:0)
Block(-7,57,3,AIR:0)
Block(-7,57,4,AIR:0)
Block(-7,57,5,AIR:0)
Block(-7,57,6,AIR:0)
Block(-7,57,7,AIR:0)
Block(-7,57,8,AIR:0)
Block(-7,58,-7,AIR:0)
Block(-7,58,-6,AIR:0)
Block(-7,58,-5,AIR:0)
Block(-7,58,-4,AIR:0)
Block(-7,58,-3,AIR:0)
Block(-7,58,-2,AIR:0)
Block(-7,58,-1,AIR:0)
Block(-7,58,0,AIR:0)
Block(-7,58,1,AIR:0)
Block(-7,58,2,AIR:0)
Block(-7,58,3,AIR:0)
Block(-7,58,4,AIR:0)
Block(-7,58,5,AIR:0)
Block(-7,58,6,AIR:0)
Block(-7,58,7,AIR:0)
Block(-7,58,8,AIR:0)
Block(-7,59,-7,AIR:0)
Block(-7,59,-6,AIR:0)
Block(-7,59,-5,AIR:0)
Block(-7,59,-4,AIR:0)
Block(-7,59,-3,AIR:0)
Block(-7,59,-2,AIR:0)
Block(-7,59,-1,AIR:0)
Block(-7,59,0,AIR:0)
Block(-7,59,1,AIR:0)
Block(-7,59,2,AIR:0)
Block(-7,59,3,AIR:0)
Block(-7,59,4,AIR:0)
Block(-7,59,5,AIR:0)
Block(-7,59,6,AIR:0)
Block(-7,59,7,AIR:0)
Block(-7,59,8,AIR:0)
Block(-7,60,-7,AIR:0)
Block(-7,60,-6,AIR:0)
Block(-7,60,-5,AIR:0)
Block(-7,60,-4,AIR:0)
Block(-7,60,-3,AIR:0)
Block(-7,60,-2,AIR:0)
Block(-7,60,-1,AIR:0)
Block(-7,60,0,AIR:0)
Block(-7,60,1,AIR:0)
Block(-7,60,2,AIR:0)
Block(-7,60,3,AIR:0)
Block(-7,60,4,AIR:0)
Block(-7,60,5,AIR:0)
Block(-7,60,6,AIR:0)
Block(-7,60,7,AIR:0)
Block(-7,60,8,AIR:0)
Block(-7,61,-7,AIR:0)
Block(-7,61,-6,AIR:0)
Block(-7,61,-5,AIR:0)
Block(-7,61,-4,AIR:0)
Block(-7,61,-3,AIR:0)
Block(-7,61,-2,AIR:0)
Block(-7,61,-1,AIR:0)
Block(-7,61,0,AIR:0)
Block(-7,61,1,AIR:0)
Block(-7,61,2,AIR:0)
Block(-7,61,3,AIR:0)
Block(-7,61,4,AIR:0)
Block(-7,61,5,AIR:0)
Block(-7,61,6,AIR:0)
Block(-7,61,7,AIR:0)
Block(-7,61,8,AIR:0)
Block(-7,62,-7,AIR:0)
Block(-7,62,-6,AIR:0)
Block(-7,62,-5,AIR:0)
Block(-7,62,-4,AIR:0)
Block(-7,62,-3,AIR:0)
Block(-7,62,-2,AIR:0)
Block(-7,62,-1,AIR:0)
Block(-7,62,0,AIR:0)
Block(-7,62,1,AIR:0)
Block(-7,62,2,AIR:0)
Block(-7,62,3,AIR:0)
Block(-7,62,4,AIR:0)
Block(-7,62,5,AIR:0)
Block(-7,62,6,AIR:0)
Block(-7,62,7,AIR:0)
Block(-7,62,8,AIR:0)
Block(-7,63,-7,AIR:0)
Block(-7,63,-6,AIR:0)
Block(-7,63,-5,AIR:0)
Block(-7,63,-4,AIR:0)
Block(-7,63,-3,AIR:0)
Block(-7,63,-2,AIR:0)
Block(-7,63,-1,AIR:0)
Block(-7,63,0,AIR:0)
Block(-7,63,1,AIR:0)
Block(-7,63,2,AIR:0)
Block(-7,63,3,AIR:0)
Block(-7,63,4,AIR:0)
Block(-7,63,5,AIR:0)
Block(-7,63,6,AIR:0)
Block(-7,63,7,AIR:0)
Block(-7,63,8,AIR:0)
Block(-6,-50,-7,COBBLESTONE:0)
Block(-6,-50,-6,COBBLESTONE:0)
Block(-6,-50,-5,COBBLESTONE:0)
Block(-6,-50,-4,LOG:0)
Block(-6,-50,-3,COBBLESTONE:0)
Block(-6,-50,-2,COBBLESTONE:0)
Block(-6,-50,-1,COBBLESTONE:0)
Block(-6,-50,0,COBBLESTONE:0)
Block(-6,-50,1,COBBLESTONE:0)
Block(-6,-50,2,STONE:5)
Block(-6,-49,-7,COBBLESTONE:0)
Block(-6,-49,-6,COBBLESTONE:0)
Block(-6,-49,-5,COBBLESTONE:0)
Block(-6,-49,-4,LOG:0)
Block(-6,-49,-3,COBBLESTONE:0)
Block(-6,-49,-2,COBBLESTONE:0)
Block(-6,-49,-1,COBBLESTONE:0)
Block(-6,-49,0,COBBLESTONE:0)
Block(-6,-49,1,COBBLESTONE:0)
Block(-6,-49,2,STONE:5)
Block(-6,-48,-7,COBBLESTONE:0)
Block(-6,-48,-6,COBBLESTONE:0)
Block(-6,-48,-5,COBBLESTONE:0)
Block(-6,-48,-4,LOG:0)
Block(-6,-48,-3,COBBLESTONE:0)
Block(-6,-48,-2,COBBLESTONE:0)
Block(-6,-48,-1,COBBLESTONE:0)
Block(-6,-48,0,COBBLESTONE:0)
Block(-6,-48,1,COBBLESTONE:0)
Block(-6,-48,2,STONE:5)
Block(-6,-47,-7,COBBLESTONE:0)
Block(-6,-47,-6,COBBLESTONE:0)
Block(-6,-47,-5,COBBLESTONE:0)
Block(-6,-47,-4,LOG:0)
Block(-6,-47,-3,COBBLESTONE:0)
Block(-6,-47,-2,COBBLESTONE:0)
Block(-6,-47,-1,COBBLESTONE:0)
Block(-6,-47,0,COBBLESTONE:0)
Block(-6,-47,1,COBBLESTONE:0)
Block(-6,-47,2,STONE:5)
Block(-6,-46,-7,COBBLESTONE:0)
Block(-6,-46,-6,COBBLESTONE:0)
Block(-6,-46,-5,COBBLESTONE:0)
Block(-6,-46,-4,LOG:0)
Block(-6,-46,-3,COBBLESTONE:0)
Block(-6,-46,-2,COBBLESTONE:0)
Block(-6,-46,-1,COBBLESTONE:0)
Block(-6,-46,0,COBBLESTONE:0)
Block(-6,-46,1,COBBLESTONE:0)
Block(-6,-46,2,STONE:5)
Block(-6,-45,-7,COBBLESTONE:0)
Block(-6,-45,-6,COBBLESTONE:0)
Block(-6,-45,-5,COBBLESTONE:0)
Block(-6,-45,-4,LOG:0)
Block(-6,-45,-3,COBBLESTONE:0)
Block(-6,-45,-2,COBBLESTONE:0)
Block(-6,-45,-1,COBBLESTONE:0)
Block(-6,-45,0,COBBLESTONE:0)
Block(-6,-45,1,COBBLESTONE:0)
Block(-6,-45,2,STONE:5)
Block(-6,-44,-7,COBBLESTONE:0)
Block(-6,-44,-6,COBBLESTONE:0)
Block(-6,-44,-5,COBBLESTONE:0)
Block(-6,-44,-4,LOG:0)
Block(-6,-44,-3,COBBLESTONE:0)
Block(-6,-44,-2,COBBLESTONE:0)
Block(-6,-44,-1,COBBLESTONE:0)
Block(-6,-44,0,COBBLESTONE:0)
Block(-6,-44,1,COBBLESTONE:0)
Block(-6,-44,2,STONE:5)
Block(-6,-43,-7,COBBLESTONE:0)
Block(-6,-43,-6,COBBLESTONE:0)
Block(-6,-43,-5,COBBLESTONE:0)
Block(-6,-43,-4,LOG:0)
Block(-6,-43,-3,COBBLESTONE:0)
Block(-6,-43,-2,COBBLESTONE:0)
Block(-6,-43,-1,COBBLESTONE:0)
Block(-6,-43,0,COBBLESTONE:0)
Block(-6,-43,1,COBBLESTONE:0)
Block(-6,-43,2,STONE:5)
Block(-6,-42,-7,COBBLESTONE:0)
Block(-6,-42,-6,COBBLESTONE:0)
Block(-6,-42,-5,COBBLESTONE:0)
Block(-6,-42,-4,LOG:0)
Block(-6,-42,-3,COBBLESTONE:0)
Block(-6,-42,-2,COBBLESTONE:0)
Block(-6,-42,-1,COBBLESTONE:0)
Block(-6,-42,0,COBBLESTONE:0)
Block(-6,-42,1,COBBLESTONE:0)
Block(-6,-42,2,STONE:5)
Block(-6,-41,-7,COBBLESTONE:0)
Block(-6,-41,-6,COBBLESTONE:0)
Block(-6,-41,-5,COBBLESTONE:0)
Block(-6,-41,-4,LOG:0)
Block(-6,-41,-3,COBBLESTONE:0)
Block(-6,-41,-2,COBBLESTONE:0)
Block(-6,-41,-1,COBBLESTONE:0)
Block(-6,-41,0,COBBLESTONE:0)
Block(-6,-41,1,COBBLESTONE:0)
Block(-6,-41,2,STONE:5)
Block(-6,-40,-7,COBBLESTONE:0)
Block(-6,-40,-6,COBBLESTONE:0)
Block(-6,-40,-5,COBBLESTONE:0)
Block(-6,-40,-4,LOG:0)
Block(-6,-40,-3,COBBLESTONE:0)
Block(-6,-40,-2,COBBLESTONE:0)
Block(-6,-40,-1,COBBLESTONE:0)
Block(-6,-40,0,COBBLESTONE:0)
Block(-6,-40,1,COBBLESTONE:0)
Block(-6,-40,2,STONE:5)
Block(-6,-39,-7,COBBLESTONE:0)
Block(-6,-39,-6,COBBLESTONE:0)
Block(-6,-39,-5,COBBLESTONE:0)
Block(-6,-39,-4,LOG:0)
Block(-6,-39,-3,COBBLESTONE:0)
Block(-6,-39,-2,COBBLESTONE:0)
Block(-6,-39,-1,COBBLESTONE:0)
Block(-6,-39,0,COBBLESTONE:0)
Block(-6,-39,1,COBBLESTONE:0)
Block(-6,-39,2,STONE:5)
Block(-6,-38,-7,COBBLESTONE:0)
Block(-6,-38,-6,COBBLESTONE:0)
Block(-6,-38,-5,COBBLESTONE:0)
Block(-6,-38,-4,LOG:0)
Block(-6,-38,-3,COBBLESTONE:0)
Block(-6,-38,-2,COBBLESTONE:0)
Block(-6,-38,-1,COBBLESTONE:0)
Block(-6,-38,0,COBBLESTONE:0)
Block(-6,-38,1,COBBLESTONE:0)
Block(-6,-38,2,STONE:5)
Block(-6,-37,-7,COBBLESTONE:0)
Block(-6,-37,-6,COBBLESTONE:0)
Block(-6,-37,-5,COBBLESTONE:0)
Block(-6,-37,-4,LOG:0)
Block(-6,-37,-3,COBBLESTONE:0)
Block(-6,-37,-2,COBBLESTONE:0)
Block(-6,-37,-1,COBBLESTONE:0)
Block(-6,-37,0,COBBLESTONE:0)
Block(-6,-37,1,COBBLESTONE:0)
Block(-6,-37,2,STONE:5)
Block(-6,-36,-7,COBBLESTONE:0)
Block(-6,-36,-6,COBBLESTONE:0)
Block(-6,-36,-5,COBBLESTONE:0)
Block(-6,-36,-4,LOG:0)
Block(-6,-36,-3,COBBLESTONE:0)
Block(-6,-36,-2,COBBLESTONE:0)
Block(-6,-36,-1,COBBLESTONE:0)
Block(-6,-36,0,COBBLESTONE:0)
Block(-6,-36,1,COBBLESTONE:0)
Block(-6,-36,2,STONE:5)
Block(-6,-35,-7,COBBLESTONE:0)
Block(-6,-35,-6,COBBLESTONE:0)
Block(-6,-35,-5,COBBLESTONE:0)
Block(-6,-35,-4,LOG:0)
Block(-6,-35,-3,COBBLESTONE:0)
Block(-6,-35,-2,COBBLESTONE:0)
Block(-6,-35,-1,COBBLESTONE:0)
Block(-6,-35,0,COBBLESTONE:0)
Block(-6,-35,1,COBBLESTONE:0)
Block(-6,-35,2,STONE:5)
Block(-6,-34,-7,COBBLESTONE:0)
Block(-6,-34,-6,COBBLESTONE:0)
Block(-6,-34,-5,COBBLESTONE:0)
Block(-6,-34,-4,LOG:0)
Block(-6,-34,-3,COBBLESTONE:0)
Block(-6,-34,-2,COBBLESTONE:0)
Block(-6,-34,-1,COBBLESTONE:0)
Block(-6,-34,0,COBBLESTONE:0)
Block(-6,-34,1,COBBLESTONE:0)
Block(-6,-34,2,STONE:5)
Block(-6,-33,-7,COBBLESTONE:0)
Block(-6,-33,-6,COBBLESTONE:0)
Block(-6,-33,-5,COBBLESTONE:0)
Block(-6,-33,-4,LOG:0)
Block(-6,-33,-3,COBBLESTONE:0)
Block(-6,-33,-2,COBBLESTONE:0)
Block(-6,-33,-1,COBBLESTONE:0)
Block(-6,-33,0,COBBLESTONE:0)
Block(-6,-33,1,COBBLESTONE:0)
Block(-6,-33,2,STONE:5)
Block(-6,-32,-7,COBBLESTONE:0)
Block(-6,-32,-6,COBBLESTONE:0)
Block(-6,-32,-5,COBBLESTONE:0)
Block(-6,-32,-4,LOG:0)
Block(-6,-32,-3,COBBLESTONE:0)
Block(-6,-32,-2,COBBLESTONE:0)
Block(-6,-32,-1,COBBLESTONE:0)
Block(-6,-32,0,COBBLESTONE:0)
Block(-6,-32,1,COBBLESTONE:0)
Block(-6,-32,2,STONE:5)
Block(-6,-31,-7,COBBLESTONE:0)
Block(-6,-31,-6,COBBLESTONE:0)
Block(-6,-31,-5,COBBLESTONE:0)
Block(-6,-31,-4,LOG:0)
Block(-6,-31,-3,COBBLESTONE:0)
Block(-6,-31,-2,COBBLESTONE:0)
Block(-6,-31,-1,COBBLESTONE:0)
Block(-6,-31,0,COBBLESTONE:0)
Block(-6,-31,1,COBBLESTONE:0)
Block(-6,-31,2,STONE:5)
Block(-6,-30,-7,COBBLESTONE:0)
Block(-6,-30,-6,COBBLESTONE:0)
Block(-6,-30,-5,COBBLESTONE:0)
Block(-6,-30,-4,LOG:0)
Block(-6,-30,-3,COBBLESTONE:0)
Block(-6,-30,-2,COBBLESTONE:0)
Block(-6,-30,-1,COBBLESTONE:0)
Block(-6,-30,0,COBBLESTONE:0)
Block(-6,-30,1,COBBLESTONE:0)
Block(-6,-30,2,STONE:5)
Block(-6,-29,-7,COBBLESTONE:0)
Block(-6,-29,-6,COBBLESTONE:0)
Block(-6,-29,-5,COBBLESTONE:0)
Block(-6,-29,-4,LOG:0)
Block(-6,-29,-3,COBBLESTONE:0)
Block(-6,-29,-2,COBBLESTONE:0)
Block(-6,-29,-1,COBBLESTONE:0)
Block(-6,-29,0,COBBLESTONE:0)
Block(-6,-29,1,COBBLESTONE:0)
Block(-6,-29,2,STONE:5)
Block(-6,-28,-7,COBBLESTONE:0)
Block(-6,-28,-6,COBBLESTONE:0)
Block(-6,-28,-5,COBBLESTONE:0)
Block(-6,-28,-4,LOG:0)
Block(-6,-28,-3,COBBLESTONE:0)
Block(-6,-28,-2,COBBLESTONE:0)
Block(-6,-28,-1,COBBLESTONE:0)
Block(-6,-28,0,COBBLESTONE:0)
Block(-6,-28,1,COBBLESTONE:0)
Block(-6,-28,2,STONE:5)
Block(-6,-27,-7,COBBLESTONE:0)
Block(-6,-27,-6,COBBLESTONE:0)
Block(-6,-27,-5,COBBLESTONE:0)
Block(-6,-27,-4,LOG:0)
Block(-6,-27,-3,COBBLESTONE:0)
Block(-6,-27,-2,COBBLESTONE:0)
Block(-6,-27,-1,COBBLESTONE:0)
Block(-6,-27,0,COBBLESTONE:0)
Block(-6,-27,1,COBBLESTONE:0)
Block(-6,-27,2,STONE:5)
Block(-6,-26,-7,COBBLESTONE:0)
Block(-6,-26,-6,COBBLESTONE:0)
Block(-6,-26,-5,COBBLESTONE:0)
Block(-6,-26,-4,LOG:0)
Block(-6,-26,-3,COBBLESTONE:0)
Block(-6,-26,-2,COBBLESTONE:0)
Block(-6,-26,-1,COBBLESTONE:0)
Block(-6,-26,0,COBBLESTONE:0)
Block(-6,-26,1,COBBLESTONE:0)
Block(-6,-26,2,STONE:5)
Block(-6,-25,-7,COBBLESTONE:0)
Block(-6,-25,-6,COBBLESTONE:0)
Block(-6,-25,-5,COBBLESTONE:0)
Block(-6,-25,-4,LOG:0)
Block(-6,-25,-3,COBBLESTONE:0)
Block(-6,-25,-2,COBBLESTONE:0)
Block(-6,-25,-1,COBBLESTONE:0)
Block(-6,-25,0,COBBLESTONE:0)
Block(-6,-25,1,COBBLESTONE:0)
Block(-6,-25,2,STONE:5)
Block(-6,-24,-7,COBBLESTONE:0)
Block(-6,-24,-6,COBBLESTONE:0)
Block(-6,-24,-5,COBBLESTONE:0)
Block(-6,-24,-4,LOG:0)
Block(-6,-24,-3,COBBLESTONE:0)
Block(-6,-24,-2,COBBLESTONE:0)
Block(-6,-24,-1,COBBLESTONE:0)
Block(-6,-24,0,COBBLESTONE:0)
Block(-6,-24,1,COBBLESTONE:0)
Block(-6,-24,2,STONE:5)
Block(-6,-23,-7,COBBLESTONE:0)
Block(-6,-23,-6,COBBLESTONE:0)
Block(-6,-23,-5,COBBLESTONE:0)
Block(-6,-23,-4,LOG:0)
Block(-6,-23,-3,COBBLESTONE:0)
Block(-6,-23,-2,COBBLESTONE:0)
Block(-6,-23,-1,COBBLESTONE:0)
Block(-6,-23,0,COBBLESTONE:0)
Block(-6,-23,1,COBBLESTONE:0)
Block(-6,-23,2,STONE:5)
Block(-6,-22,-7,COBBLESTONE:0)
Block(-6,-22,-6,COBBLESTONE:0)
Block(-6,-22,-5,COBBLESTONE:0)
Block(-6,-22,-4,LOG:0)
Block(-6,-22,-3,COBBLESTONE:0)
Block(-6,-22,-2,COBBLESTONE:0)
Block(-6,-22,-1,COBBLESTONE:0)
Block(-6,-22,0,COBBLESTONE:0)
Block(-6,-22,1,COBBLESTONE:0)
Block(-6,-22,2,STONE:5)
Block(-6,-21,-7,COBBLESTONE:0)
Block(-6,-21,-6,COBBLESTONE:0)
Block(-6,-21,-5,COBBLESTONE:0)
Block(-6,-21,-4,LOG:0)
Block(-6,-21,-3,COBBLESTONE:0)
Block(-6,-21,-2,COBBLESTONE:0)
Block(-6,-21,-1,COBBLESTONE:0)
Block(-6,-21,0,COBBLESTONE:0)
Block(-6,-21,1,COBBLESTONE:0)
Block(-6,-21,2,STONE:5)
Block(-6,-20,-7,COBBLESTONE:0)
Block(-6,-20,-6,COBBLESTONE:0)
Block(-6,-20,-5,COBBLESTONE:0)
Block(-6,-20,-4,LOG:0)
Block(-6,-20,-3,COBBLESTONE:0)
Block(-6,-20,-2,COBBLESTONE:0)
Block(-6,-20,-1,COBBLESTONE:0)
Block(-6,-20,0,COBBLESTONE:0)
Block(-6,-20,1,COBBLESTONE:0)
Block(-6,-20,2,STONE:5)
Block(-6,-19,-7,COBBLESTONE:0)
Block(-6,-19,-6,COBBLESTONE:0)
Block(-6,-19,-5,COBBLESTONE:0)
Block(-6,-19,-4,LOG:0)
Block(-6,-19,-3,STONE:5)
Block(-6,-19,-2,COBBLESTONE:0)
Block(-6,-19,-1,COBBLESTONE:0)
Block(-6,-19,0,COBBLESTONE:0)
Block(-6,-19,1,COBBLESTONE:0)
Block(-6,-19,2,STAINED_CLAY:9)
Block(-6,-18,-7,COBBLESTONE:0)
Block(-6,-18,-6,COBBLESTONE:0)
Block(-6,-18,-5,STONE:5)
Block(-6,-18,-4,LOG:0)
Block(-6,-18,-3,COBBLESTONE:0)
Block(-6,-18,-2,COBBLESTONE:0)
Block(-6,-18,-1,COBBLESTONE:0)
Block(-6,-18,0,COBBLESTONE:0)
Block(-6,-18,1,COBBLESTONE:0)
Block(-6,-18,2,COBBLESTONE:0)
Block(-6,-17,-7,COBBLESTONE:0)
Block(-6,-17,-6,COBBLESTONE:0)
Block(-6,-17,-5,STONE:5)
Block(-6,-17,-4,LOG:0)
Block(-6,-17,-3,STONE:5)
Block(-6,-17,-2,COBBLESTONE:0)
Block(-6,-17,-1,COBBLESTONE:0)
Block(-6,-17,0,COBBLESTONE:0)
Block(-6,-17,1,COBBLESTONE:0)
Block(-6,-17,2,COBBLESTONE:0)
Block(-6,-16,-7,COBBLESTONE:0)
Block(-6,-16,-6,COBBLESTONE:0)
Block(-6,-16,-5,STONE:5)
Block(-6,-16,-4,LOG:0)
Block(-6,-16,-3,STONE:5)
Block(-6,-16,-2,COBBLESTONE:0)
Block(-6,-16,-1,COBBLESTONE:0)
Block(-6,-16,0,COBBLESTONE:0)
Block(-6,-16,1,COBBLESTONE:0)
Block(-6,-16,2,STONE:5)
Block(-6,-15,-7,COBBLESTONE:0)
Block(-6,-15,-6,COBBLESTONE:0)
Block(-6,-15,-5,STONE:5)
Block(-6,-15,-4,LOG:0)
Block(-6,-15,-3,STONE:5)
Block(-6,-15,-2,COBBLESTONE:0)
Block(-6,-15,-1,COBBLESTONE:0)
Block(-6,-15,0,COBBLESTONE:0)
Block(-6,-15,1,COBBLESTONE:0)
Block(-6,-15,2,SMOOTH_BRICK:2)
Block(-6,-14,-7,COBBLESTONE:0)
Block(-6,-14,-6,COBBLESTONE:0)
Block(-6,-14,-5,SMOOTH_BRICK:1)
Block(-6,-14,-4,LOG:0)
Block(-6,-14,-3,COBBLESTONE:0)
Block(-6,-14,-2,COBBLESTONE:0)
Block(-6,-14,-1,COBBLESTONE:0)
Block(-6,-14,0,COBBLESTONE:0)
Block(-6,-14,1,COBBLESTONE:0)
Block(-6,-14,2,SMOOTH_BRICK:1)
Block(-6,-13,-7,COBBLESTONE:0)
Block(-6,-13,-6,COBBLESTONE:0)
Block(-6,-13,-5,COBBLESTONE:0)
Block(-6,-13,-4,LOG:0)
Block(-6,-13,-3,COBBLESTONE:0)
Block(-6,-13,-2,COBBLESTONE:0)
Block(-6,-13,-1,COBBLESTONE:0)
Block(-6,-13,0,COBBLESTONE:0)
Block(-6,-13,1,COBBLESTONE:0)
Block(-6,-13,2,SMOOTH_BRICK:0)
Block(-6,-12,-7,COBBLESTONE:0)
Block(-6,-12,-6,COBBLESTONE:0)
Block(-6,-12,-5,COBBLESTONE:0)
Block(-6,-12,-4,LOG:0)
Block(-6,-12,-3,STONE:5)
Block(-6,-12,-2,COBBLESTONE:0)
Block(-6,-12,-1,COBBLESTONE:0)
Block(-6,-12,0,COBBLESTONE:0)
Block(-6,-12,1,COBBLESTONE:0)
Block(-6,-12,2,STONE:5)
Block(-6,-11,-7,COBBLESTONE:0)
Block(-6,-11,-6,COBBLESTONE:0)
Block(-6,-11,-5,COBBLESTONE:0)
Block(-6,-11,-4,LOG:0)
Block(-6,-11,-3,STONE:5)
Block(-6,-11,-2,COBBLESTONE:0)
Block(-6,-11,-1,COBBLESTONE:0)
Block(-6,-11,0,COBBLESTONE:0)
Block(-6,-11,1,COBBLESTONE:0)
Block(-6,-11,2,COBBLESTONE:0)
Block(-6,-10,-7,STONE:5)
Block(-6,-10,-6,STAINED_CLAY:9)
Block(-6,-10,-5,STONE:5)
Block(-6,-10,-4,LOG:0)
Block(-6,-10,-3,STAINED_CLAY:9)
Block(-6,-10,-2,STONE:5)
Block(-6,-10,-1,STONE:5)
Block(-6,-10,0,STONE:5)
Block(-6,-10,1,COBBLESTONE:0)
Block(-6,-10,2,STONE:5)
Block(-6,-9,-7,LOG:4)
Block(-6,-9,-6,STONE:6)
Block(-6,-9,-5,COBBLESTONE:0)
Block(-6,-9,-4,LOG:0)
Block(-6,-9,-3,STONE:5)
Block(-6,-9,-2,STONE:6)
Block(-6,-9,-1,LOG:4)
Block(-6,-9,0,STONE:6)
Block(-6,-9,1,COBBLESTONE_STAIRS:1)
Block(-6,-9,2,COBBLESTONE_STAIRS:3)
Block(-6,-8,-7,STONE:6)
Block(-6,-8,-6,STONE:6)
Block(-6,-8,-5,STONE:6)
Block(-6,-8,-4,LOG:0)
Block(-6,-8,-3,STONE:6)
Block(-6,-8,-2,STONE:6)
Block(-6,-8,-1,STONE:6)
Block(-6,-8,0,STONE:6)
Block(-6,-7,-7,STONE:6)
Block(-6,-7,-6,STONE:6)
Block(-6,-7,-5,STONE:6)
Block(-6,-7,-4,LOG:0)
Block(-6,-7,-3,STONE:6)
Block(-6,-7,-2,STONE:6)
Block(-6,-7,-1,STONE:6)
Block(-6,-7,0,STONE:6)
Block(-6,-6,-7,STONE:6)
Block(-6,-6,-6,STONE:6)
Block(-6,-6,-5,STONE:6)
Block(-6,-6,-4,LOG:0)
Block(-6,-6,-3,STONE:6)
Block(-6,-6,-2,STONE:6)
Block(-6,-6,-1,STONE:6)
Block(-6,-6,0,STONE:6)
Block(-6,-5,-7,STONE:6)
Block(-6,-5,-6,STONE:6)
Block(-6,-5,-5,STONE:6)
Block(-6,-5,-4,LOG:0)
Block(-6,-5,-3,STONE:6)
Block(-6,-5,-2,STONE:6)
Block(-6,-5,-1,STONE:6)
Block(-6,-5,0,COBBLESTONE_STAIRS:1)
Block(-6,-4,-7,LOG:4)
Block(-6,-4,-5,STONE:6)
Block(-6,-4,-4,LOG:0)
Block(-6,-4,-3,STONE:6)
Block(-6,-4,-1,LOG:4)
Block(-6,-3,-5,STONE:6)
Block(-6,-3,-4,LOG:0)
Block(-6,-3,-3,STONE:6)
Block(-6,-2,-5,STONE:6)
Block(-6,-2,-4,LOG:0)
Block(-6,-2,-3,STONE:6)
Block(-6,-1,-5,STONE:6)
Block(-6,-1,-4,LOG:0)
Block(-6,-1,-3,STONE:6)
Block(-6,0,-5,STONE:6)
Block(-6,0,-4,LOG:0)
Block(-6,0,-3,STONE:6)
Block(-6,1,-5,STONE:6)
Block(-6,1,-4,LOG:0)
Block(-6,1,-3,STONE:6)
Block(-6,2,-7,AIR:0)
Block(-6,2,-6,AIR:0)
Block(-6,2,-5,STONE:6)
Block(-6,2,-4,LOG:0)
Block(-6,2,-3,STONE:6)
Block(-6,2,-2,WOOD_STEP:13)
Block(-6,2,-1,WOOD_STEP:13)
Block(-6,2,0,WOOD_STEP:13)
Block(-6,2,1,LOG:4)
Block(-6,2,2,LOG:12)
Block(-6,2,3,WOOD_STEP:9)
Block(-6,2,4,WOOD_STEP:13)
Block(-6,2,5,WOOD_STEP:13)
Block(-6,2,6,LOG:12)
Block(-6,2,7,AIR:0)
Block(-6,2,8,AIR:0)
Block(-6,3,-7,LOG:4)
Block(-6,3,-6,AIR:0)
Block(-6,3,-5,STONE:6)
Block(-6,3,-4,LOG:0)
Block(-6,3,-3,STONE:6)
Block(-6,3,-2,WOOD:1)
RandomBlock(-6,3,-1,AIR:0,20,CHEST:5,../../../Chests/Loot/JunkChest_1.nbt,10,CHEST:5,../../../Chests/Loot/JunkChest_2.nbt,10,CHEST:5,../../../Chests/Loot/JunkChest_3.nbt,10,CHEST:5,../../../Chests/Loot/JunkChest_4.nbt,10,CHEST:5,../../../Chests/Loot/JunkChest_5.nbt,10,CHEST:5,../../../Chests/Lore/medievalcity_1.nbt,1,CHEST:5,../../../Chests/Lore/medievalcity_2.nbt,1,CHEST:5,../../../Chests/Lore/medievalcity_3.nbt,1,CHEST:5,../../../Chests/Lore/medievalcity_4.nbt,1,CHEST:5,../../../Chests/Lore/medievalcity_5.nbt,1,CHEST:5,../../../Chests/Loot/Common1.nbt,10,CHEST:5,../../../Chests/Loot/Common2.nbt,10,CHEST:5,../../../Chests/Loot/Common3.nbt,10,CHEST:5,../../../Chests/Loot/Common4.nbt,10,CHEST:5,../../../Chests/Loot/Common5.nbt,10,CHEST:5,../../../Chests/Loot/Common6.nbt,10,CHEST:5,../../../Chests/Loot/Common7.nbt,10,CHEST:5,../../../Chests/Loot/Common8.nbt,10,CHEST:5,../../../Chests/Loot/Common9.nbt,10,CHEST:5,../../../Chests/Loot/Common10.nbt,10,CHEST:5,../../../Chests/Loot/Common10.nbt,11,CHEST:5,../../../Chests/Loot/Common12.nbt,10,CHEST:5,../../../Chests/Loot/Common13.nbt,10,CHEST:5,../../../Chests/Loot/Common14.nbt,10,CHEST:5,../../../Chests/Loot/Common15.nbt,10,CHEST:5,../../../Chests/Lore/medievalcity_1.nbt,2,CHEST:5,../../../Chests/Lore/medievalcity_3.nbt,2,CHEST:5,../../../Chests/Lore/medievalcity_4.nbt,2,CHEST:5,../../../Chests/Lore/medievalcity_5.nbt,2,CHEST:5,../../../Chests/Lore/medievalcity_5.nbt,2,CHEST:5,../../../Chests/Loot/Rare1.nbt,5,CHEST:5,../../../Chests/Loot/Rare2.nbt,5,CHEST:5,../../../Chests/Loot/Rare3.nbt,5,CHEST:5,../../../Chests/Loot/Rare4.nbt,5,CHEST:5,../../../Chests/Loot/Rare5.nbt,5,CHEST:5,../../../Chests/Loot/Rare6.nbt,5,CHEST:5,../../../Chests/Loot/Rare7.nbt,5,CHEST:5,../../../Chests/Loot/Rare8.nbt,5,CHEST:5,../../../Chests/Loot/Rare9.nbt,5,CHEST:5,../../../Chests/Loot/Rare10.nbt,5,CHEST:5,../../../Chests/Loot/Rare11.nbt,5,CHEST:5,../../../Chests/Loot/Rare12.nbt,5,CHEST:5,../../../Chests/Loot/Rare13.nbt,5,CHEST:5,../../../Chests/Loot/Rare14.nbt,5,CHEST:5,../../../Chests/Loot/Rare15.nbt,5,CHEST:5,../../../Chests/Loot/Epic1.nbt,2,CHEST:5,../../../Chests/Loot/Epic2.nbt,2,CHEST:5,../../../Chests/Loot/Epic3.nbt,2,CHEST:5,../../../Chests/Loot/Epic4.nbt,2,CHEST:5,../../../Chests/Loot/Epic5.nbt,2,CHEST:5,../../../Chests/Loot/Epic6.nbt,2,CHEST:5,../../../Chests/Loot/Epic7.nbt,2,CHEST:5,../../../Chests/Loot/Epic8.nbt,2,CHEST:5,../../../Chests/Loot/Epic9.nbt,2,CHEST:5,../../../Chests/Loot/Epic10.nbt,2,CHEST:5,../../../Chests/Loot/Epic11.nbt,2,CHEST:5,../../../Chests/Loot/Epic12.nbt,2,CHEST:5,../../../Chests/Loot/Epic13.nbt,2,CHEST:5,../../../Chests/Loot/Epic14.nbt,2,CHEST:5,../../../Chests/Loot/Epic15.nbt,5,CHEST:5,../../../Chests/Loot/Rare1.nbt,5,CHEST:5,../../../Chests/Loot/Rare2.nbt,5,CHEST:5,../../../Chests/Loot/Rare3.nbt,5,CHEST:5,../../../Chests/Loot/Rare4.nbt,5,CHEST:5,../../../Chests/Loot/Rare5.nbt,10,CHEST:5,../../../Chests/Loot/Rare6.nbt,10,CHEST:5,../../../Chests/Loot/Rare7.nbt,10,CHEST:5,../../../Chests/Loot/Rare8.nbt,10,CHEST:5,../../../Chests/Loot/Rare9.nbt,10,CHEST:5,../../../Chests/Loot/Rare10.nbt,15,CHEST:5,../../../Chests/Loot/Rare11.nbt,15,CHEST:5,../../../Chests/Loot/Rare12.nbt,15,CHEST:5,../../../Chests/Loot/Rare13.nbt,15,CHEST:5,../../../Chests/Loot/Rare14.nbt,15,CHEST:5,../../../Chests/Loot/Rare15.nbt,15,CHEST:5,../../../Chests/Loot/Epic15.nbt,100)
Block(-6,3,0,WOOD:1)
Block(-6,3,1,WOOD:1)
Block(-6,3,2,SKULL:1,origin/9661-skullC272R176.nbt)
Block(-6,3,3,AIR:0)
Block(-6,3,4,AIR:0)
Block(-6,3,5,AIR:0)
Block(-6,3,6,AIR:0)
Block(-6,3,7,AIR:0)
Block(-6,3,8,AIR:0)
Block(-6,4,-7,COBBLE_WALL:0)
Block(-6,4,-6,AIR:0)
Block(-6,4,-5,STONE:6)
Block(-6,4,-4,LOG:0)
Block(-6,4,-3,STONE:6)
Block(-6,4,-2,WOOD:1)
Block(-6,4,-1,AIR:0)
Block(-6,4,0,SKULL:1,origin/9678-skullC272R176.nbt)
Block(-6,4,1,AIR:0)
Block(-6,4,2,AIR:0)
Block(-6,4,3,AIR:0)
Block(-6,4,4,AIR:0)
Block(-6,4,5,AIR:0)
Block(-6,4,6,AIR:0)
Block(-6,4,7,AIR:0)
Block(-6,4,8,AIR:0)
Block(-6,5,-7,AIR:0)
Block(-6,5,-6,AIR:0)
Block(-6,5,-5,STONE:6)
Block(-6,5,-4,LOG:0)
Block(-6,5,-3,STONE:6)
Block(-6,5,-2,AIR:0)
Block(-6,5,-1,AIR:0)
Block(-6,5,0,AIR:0)
Block(-6,5,1,AIR:0)
Block(-6,5,2,AIR:0)
Block(-6,5,3,AIR:0)
Block(-6,5,4,AIR:0)
Block(-6,5,5,AIR:0)
Block(-6,5,6,AIR:0)
Block(-6,5,7,AIR:0)
Block(-6,5,8,AIR:0)
Block(-6,6,-7,AIR:0)
Block(-6,6,-6,AIR:0)
Block(-6,6,-5,SMOOTH_BRICK:0)
Block(-6,6,-4,LOG:0)
Block(-6,6,-3,SMOOTH_BRICK:0)
Block(-6,6,-2,AIR:0)
Block(-6,6,-1,AIR:0)
Block(-6,6,0,AIR:0)
Block(-6,6,1,AIR:0)
Block(-6,6,2,AIR:0)
Block(-6,6,3,AIR:0)
Block(-6,6,4,AIR:0)
Block(-6,6,5,AIR:0)
Block(-6,6,6,AIR:0)
Block(-6,6,7,AIR:0)
Block(-6,6,8,AIR:0)
Block(-6,7,-7,AIR:0)
Block(-6,7,-6,AIR:0)
Block(-6,7,-5,SMOOTH_BRICK:0)
Block(-6,7,-4,LOG:0)
Block(-6,7,-3,SMOOTH_BRICK:0)
Block(-6,7,-2,AIR:0)
Block(-6,7,-1,AIR:0)
Block(-6,7,0,AIR:0)
Block(-6,7,1,AIR:0)
Block(-6,7,2,AIR:0)
Block(-6,7,3,AIR:0)
Block(-6,7,4,AIR:0)
Block(-6,7,5,AIR:0)
Block(-6,7,6,AIR:0)
Block(-6,7,7,AIR:0)
Block(-6,7,8,AIR:0)
Block(-6,8,-7,AIR:0)
Block(-6,8,-6,DARK_OAK_STAIRS:5)
Block(-6,8,-5,SMOOTH_BRICK:0)
Block(-6,8,-4,LOG:0)
Block(-6,8,-3,SMOOTH_BRICK:0)
Block(-6,8,-2,DARK_OAK_STAIRS:5)
Block(-6,8,-1,AIR:0)
Block(-6,8,0,AIR:0)
Block(-6,8,1,AIR:0)
Block(-6,8,2,AIR:0)
Block(-6,8,3,AIR:0)
Block(-6,8,4,AIR:0)
Block(-6,8,5,AIR:0)
Block(-6,8,6,AIR:0)
Block(-6,8,7,AIR:0)
Block(-6,8,8,AIR:0)
Block(-6,9,-7,AIR:0)
Block(-6,9,-6,DARK_OAK_STAIRS:2)
Block(-6,9,-5,AIR:0)
Block(-6,9,-4,LOG:0)
Block(-6,9,-3,AIR:0)
Block(-6,9,-2,DARK_OAK_STAIRS:3)
Block(-6,9,-1,AIR:0)
Block(-6,9,0,AIR:0)
Block(-6,9,1,AIR:0)
Block(-6,9,2,AIR:0)
Block(-6,9,3,AIR:0)
Block(-6,9,4,AIR:0)
Block(-6,9,5,AIR:0)
Block(-6,9,6,AIR:0)
Block(-6,9,7,AIR:0)
Block(-6,9,8,AIR:0)
Block(-6,10,-7,STEP:11)
Block(-6,10,-6,DARK_OAK_STAIRS:6)
Block(-6,10,-5,AIR:0)
Block(-6,10,-4,LOG:0)
Block(-6,10,-3,AIR:0)
Block(-6,10,-2,DARK_OAK_STAIRS:7)
Block(-6,10,-1,STEP:11)
Block(-6,10,0,STEP:11)
Block(-6,10,1,AIR:0)
Block(-6,10,2,AIR:0)
Block(-6,10,3,AIR:0)
Block(-6,10,4,AIR:0)
Block(-6,10,5,AIR:0)
Block(-6,10,6,AIR:0)
Block(-6,10,7,AIR:0)
Block(-6,10,8,AIR:0)
Block(-6,11,-7,AIR:0)
Block(-6,11,-6,STEP:3)
Block(-6,11,-5,STEP:11)
Block(-6,11,-4,LOG:0)
Block(-6,11,-3,STEP:11)
Block(-6,11,-2,STEP:3)
Block(-6,11,-1,AIR:0)
Block(-6,11,0,AIR:0)
Block(-6,11,1,AIR:0)
Block(-6,11,2,AIR:0)
Block(-6,11,3,AIR:0)
Block(-6,11,4,AIR:0)
Block(-6,11,5,AIR:0)
Block(-6,11,6,AIR:0)
Block(-6,11,7,AIR:0)
Block(-6,11,8,AIR:0)
Block(-6,12,-7,AIR:0)
Block(-6,12,-6,AIR:0)
Block(-6,12,-5,SMOOTH_STAIRS:1)
Block(-6,12,-4,LOG:0)
Block(-6,12,-3,SMOOTH_STAIRS:1)
Block(-6,12,-2,AIR:0)
Block(-6,12,-1,AIR:0)
Block(-6,12,0,AIR:0)
Block(-6,12,1,AIR:0)
