Author: NLBlackEagle
Description: No description given
SettingsMode: WriteDisable
Frequency: 0
SpawnHeight: highestBlock
UseCenterForHighestBlock: true
MinHeight: 0
MaxHeight: 255
InheritBO3: 
InheritBO3Rotation: NORTH
OverrideChildSettings: true
OverrideParentHeight: false
CanOverride: false
BranchFrequency: 0
BranchFrequencyGroup: 
MustBeBelowOther: false
MustBeInside: 
CannotBeInside: 
ReplacesBO3: 
MustBeInsideWorldBorders: false
CanSpawnOnWater: true
SpawnOnWaterOnly: true
SpawnUnderWater: false
SpawnAtWaterLevel: false
HeightOffset: 0
RemoveAir: false
ReplaceAbove: 
ReplaceBelow: 
ReplaceWithBiomeBlocks: true
ReplaceWithSurfaceBlock: GRASS
ReplaceWithGroundBlock: DIRT
ReplaceWithStoneBlock: STONE
SmoothRadius: 0
SmoothHeightOffset: 0
SmoothStartTop: false
SmoothStartWood: false
SmoothingSurfaceBlock: 
SmoothingGroundBlock: 
BO3Group: 
IsSpawnPoint: false
DoReplaceBlocks: true
Block(-8,0,-7,LOG:1)
Block(-8,0,-3,LOG:1)
Block(-8,0,1,LOG:1)
Block(-8,0,5,LOG:1)
Block(-8,1,-7,LOG:1)
Block(-8,1,-6,LOG:9)
Block(-8,1,-5,LOG:9)
Block(-8,1,-4,LOG:9)
Block(-8,1,-3,LOG:1)
Block(-8,1,-2,LOG:9)
Block(-8,1,-1,LOG:9)
Block(-8,1,0,LOG:9)
Block(-8,1,1,LOG:1)
Block(-8,1,5,LOG:1)
Block(-8,1,6,LOG:9)
Block(-8,1,7,LOG:9)
Block(-8,1,8,LOG:9)
Block(-8,2,-7,LOG:1)
Block(-8,2,-3,LOG:1)
Block(-8,2,1,LOG:1)
Block(-8,2,2,LOG:9)
Block(-8,2,3,LOG:9)
Block(-8,2,4,LOG:9)
Block(-8,2,5,LOG:1)
Block(-8,3,-7,LOG:1)
Block(-8,3,-3,LOG:1)
Block(-8,3,1,LOG:1)
Block(-8,3,5,LOG:1)
Block(-8,4,-7,LOG:1)
Block(-8,4,-3,LOG:1)
Block(-8,4,1,LOG:1)
Block(-8,4,5,LOG:1)
Block(-8,5,-7,LOG:1)
Block(-8,5,-6,LOG:9)
Block(-8,5,-5,LOG:9)
Block(-8,5,-4,LOG:9)
Block(-8,5,-3,LOG:1)
Block(-8,5,-2,LOG:9)
Block(-8,5,-1,LOG:9)
Block(-8,5,0,LOG:9)
Block(-8,5,1,LOG:1)
Block(-8,5,5,LOG:1)
Block(-8,5,6,LOG:9)
Block(-8,5,7,LOG:9)
Block(-8,5,8,LOG:9)
Block(-8,6,-7,LOG:1)
Block(-8,6,-3,LOG:1)
Block(-8,6,1,LOG:1)
Block(-8,6,2,LOG:9)
Block(-8,6,3,LOG:9)
Block(-8,6,4,LOG:9)
Block(-8,6,5,LOG:1)
Block(-8,7,-7,LOG:1)
Block(-8,7,-3,LOG:1)
Block(-8,7,1,LOG:1)
Block(-8,7,5,LOG:1)
Block(-8,8,-7,LOG:1)
Block(-8,8,-3,LOG:1)
Block(-8,8,1,LOG:1)
Block(-8,8,5,LOG:1)
Block(-8,9,-7,LOG:1)
Block(-8,9,-6,LOG:9)
Block(-8,9,-5,LOG:9)
Block(-8,9,-4,LOG:9)
Block(-8,9,-3,LOG:1)
Block(-8,9,-2,LOG:9)
Block(-8,9,-1,LOG:9)
Block(-8,9,0,LOG:9)
Block(-8,9,1,LOG:1)
Block(-8,9,5,LOG:1)
Block(-8,9,6,LOG:9)
Block(-8,9,7,LOG:9)
Block(-8,9,8,LOG:9)
Block(-8,10,-7,LOG:1)
Block(-8,10,-3,LOG:1)
Block(-8,10,1,LOG:1)
Block(-8,10,2,LOG:9)
Block(-8,10,3,LOG:9)
Block(-8,10,4,LOG:9)
Block(-8,10,5,LOG:1)
Block(-8,11,-7,LOG:1)
Block(-8,11,-3,LOG:1)
Block(-8,11,1,LOG:1)
Block(-8,11,5,LOG:1)
Block(-8,12,-7,LOG:1)
Block(-8,12,-3,LOG:1)
Block(-8,12,1,LOG:1)
Block(-8,12,5,LOG:1)
Block(-8,13,-7,LOG:1)
Block(-8,13,-6,LOG:9)
Block(-8,13,-5,LOG:9)
Block(-8,13,-4,LOG:9)
Block(-8,13,-3,LOG:1)
Block(-8,13,-2,LOG:9)
Block(-8,13,-1,LOG:9)
Block(-8,13,0,LOG:9)
Block(-8,13,1,LOG:1)
Block(-8,13,5,LOG:1)
Block(-8,13,6,LOG:9)
Block(-8,13,7,LOG:9)
Block(-8,13,8,LOG:9)
Block(-8,14,-7,LOG:1)
Block(-8,14,-3,LOG:1)
Block(-8,14,1,LOG:1)
Block(-8,14,2,LOG:9)
Block(-8,14,3,LOG:9)
Block(-8,14,4,LOG:9)
Block(-8,14,5,LOG:1)
Block(-8,15,-7,LOG:1)
Block(-8,15,-3,LOG:1)
Block(-8,15,1,LOG:1)
Block(-8,15,5,LOG:1)
Block(-8,16,-7,LOG:1)
Block(-8,16,-3,LOG:1)
Block(-8,16,1,LOG:1)
Block(-8,16,5,LOG:1)
Block(-8,17,-7,LOG:1)
Block(-8,17,-6,LOG:9)
Block(-8,17,-5,LOG:9)
Block(-8,17,-4,LOG:9)
Block(-8,17,-3,LOG:1)
Block(-8,17,-2,LOG:9)
Block(-8,17,-1,LOG:9)
Block(-8,17,0,LOG:9)
Block(-8,17,1,LOG:1)
Block(-8,17,5,LOG:1)
Block(-8,17,6,LOG:9)
Block(-8,17,7,LOG:9)
Block(-8,17,8,LOG:9)
Block(-8,18,-7,LOG:1)
Block(-8,18,-3,LOG:1)
Block(-8,18,1,LOG:1)
Block(-8,18,2,LOG:9)
Block(-8,18,3,LOG:9)
Block(-8,18,4,LOG:9)
Block(-8,18,5,LOG:1)
Block(-8,19,-7,LOG:1)
Block(-8,19,-3,LOG:1)
Block(-8,19,1,LOG:1)
Block(-8,19,5,LOG:1)
Block(-8,20,-7,LOG:1)
Block(-8,20,-3,LOG:1)
Block(-8,20,1,LOG:1)
Block(-8,20,5,LOG:1)
Block(-8,21,-7,LOG:1)
Block(-8,21,-6,LOG:9)
Block(-8,21,-5,LOG:9)
Block(-8,21,-4,LOG:9)
Block(-8,21,-3,LOG:1)
Block(-8,21,-2,LOG:9)
Block(-8,21,-1,LOG:9)
Block(-8,21,0,LOG:9)
Block(-8,21,1,LOG:1)
Block(-8,21,5,LOG:1)
Block(-8,21,6,LOG:9)
Block(-8,21,7,LOG:9)
Block(-8,21,8,LOG:9)
Block(-8,22,-7,LOG:1)
Block(-8,22,-3,LOG:1)
Block(-8,22,1,LOG:1)
Block(-8,22,2,LOG:9)
Block(-8,22,3,LOG:9)
Block(-8,22,4,LOG:9)
Block(-8,22,5,LOG:1)
Block(-8,23,-7,LOG:1)
Block(-8,23,-3,LOG:1)
Block(-8,23,1,LOG:1)
Block(-8,23,5,LOG:1)
Block(-8,24,-7,LOG:1)
Block(-8,24,-3,LOG:1)
Block(-8,24,1,LOG:1)
Block(-8,24,5,LOG:1)
Block(-8,25,-7,LOG:1)
Block(-8,25,-6,LOG:9)
Block(-8,25,-5,LOG:9)
Block(-8,25,-4,LOG:9)
Block(-8,25,-3,LOG:1)
Block(-8,25,-2,LOG:9)
Block(-8,25,-1,LOG:9)
Block(-8,25,0,LOG:9)
Block(-8,25,1,LOG:1)
Block(-8,25,5,LOG:1)
Block(-8,25,6,LOG:9)
Block(-8,25,7,LOG:9)
Block(-8,25,8,LOG:9)
Block(-8,26,-7,LOG:1)
Block(-8,26,-3,LOG:1)
Block(-8,26,1,LOG:1)
Block(-8,26,2,LOG:9)
Block(-8,26,3,LOG:9)
Block(-8,26,4,LOG:9)
Block(-8,26,5,LOG:1)
Block(-8,27,-7,LOG:1)
Block(-8,27,-3,LOG:1)
Block(-8,27,1,LOG:1)
Block(-8,27,5,LOG:1)
Block(-8,28,-7,LOG:1)
Block(-8,28,-3,LOG:1)
Block(-8,28,1,LOG:1)
Block(-8,28,5,LOG:1)
Block(-8,29,-7,LOG:1)
Block(-8,29,-6,LOG:9)
Block(-8,29,-5,LOG:9)
Block(-8,29,-4,LOG:9)
Block(-8,29,-3,LOG:1)
Block(-8,29,-2,LOG:9)
Block(-8,29,-1,LOG:9)
Block(-8,29,0,LOG:9)
Block(-8,29,1,LOG:1)
Block(-8,29,5,LOG:1)
Block(-8,29,6,LOG:9)
Block(-8,29,7,LOG:9)
Block(-8,29,8,LOG:9)
Block(-8,30,-7,LOG:1)
Block(-8,30,-3,LOG:1)
Block(-8,30,1,LOG:1)
Block(-8,30,2,LOG:9)
Block(-8,30,3,LOG:9)
Block(-8,30,4,LOG:9)
Block(-8,30,5,LOG:1)
Block(-8,31,-7,LOG:1)
Block(-8,31,-3,LOG:1)
Block(-8,31,1,LOG:1)
Block(-8,31,5,LOG:1)
Block(-8,32,-7,LOG:1)
Block(-8,32,-3,LOG:1)
Block(-8,32,1,LOG:1)
Block(-8,32,5,LOG:1)
Block(-8,33,-7,LOG:1)
Block(-8,33,-6,LOG:9)
Block(-8,33,-5,LOG:9)
Block(-8,33,-4,LOG:9)
Block(-8,33,-3,LOG:1)
Block(-8,33,-2,LOG:9)
Block(-8,33,-1,LOG:9)
Block(-8,33,0,LOG:9)
Block(-8,33,1,LOG:1)
Block(-8,33,5,LOG:1)
Block(-8,33,6,LOG:9)
Block(-8,33,7,LOG:9)
Block(-8,33,8,LOG:9)
Block(-8,34,-7,LOG:1)
Block(-8,34,-3,LOG:1)
Block(-8,34,1,LOG:1)
Block(-8,34,2,LOG:9)
Block(-8,34,3,LOG:9)
Block(-8,34,4,LOG:9)
Block(-8,34,5,LOG:1)
Block(-8,35,-7,LOG:1)
Block(-8,35,-3,LOG:1)
Block(-8,35,1,LOG:1)
Block(-8,35,5,LOG:1)
Block(-8,36,-7,LOG:1)
Block(-8,36,-3,LOG:1)
Block(-8,36,1,LOG:1)
Block(-8,36,5,LOG:1)
Block(-8,37,-7,LOG:1)
Block(-8,37,-6,LOG:9)
Block(-8,37,-5,LOG:9)
Block(-8,37,-4,LOG:9)
Block(-8,37,-3,LOG:1)
Block(-8,37,-2,LOG:9)
Block(-8,37,-1,LOG:9)
Block(-8,37,0,LOG:9)
Block(-8,37,1,LOG:1)
Block(-8,37,5,LOG:1)
Block(-8,37,6,LOG:9)
Block(-8,37,7,LOG:9)
Block(-8,37,8,LOG:9)
Block(-8,38,-7,LOG:1)
Block(-8,38,-3,LOG:1)
Block(-8,38,1,LOG:1)
Block(-8,38,2,LOG:9)
Block(-8,38,3,LOG:9)
Block(-8,38,4,LOG:9)
Block(-8,38,5,LOG:1)
Block(-8,39,-7,LOG:1)
Block(-8,39,-3,LOG:1)
Block(-8,39,1,LOG:1)
Block(-8,39,5,LOG:1)
Block(-8,40,-7,LOG:1)
Block(-8,40,-3,LOG:1)
Block(-8,40,1,LOG:1)
Block(-8,40,5,LOG:1)
Block(-8,41,-7,LOG:1)
Block(-8,41,-6,LOG:9)
Block(-8,41,-5,LOG:9)
Block(-8,41,-4,LOG:9)
Block(-8,41,-3,LOG:1)
Block(-8,41,-2,LOG:9)
Block(-8,41,-1,LOG:9)
Block(-8,41,0,LOG:9)
Block(-8,41,1,LOG:1)
Block(-8,41,5,LOG:1)
Block(-8,41,6,LOG:9)
Block(-8,41,7,LOG:9)
Block(-8,41,8,LOG:9)
Block(-8,42,-7,LOG:1)
Block(-8,42,-3,LOG:1)
Block(-8,42,1,LOG:1)
Block(-8,42,2,LOG:9)
Block(-8,42,3,LOG:9)
Block(-8,42,4,LOG:9)
Block(-8,42,5,LOG:1)
Block(-8,43,-7,LOG:1)
Block(-8,43,-3,LOG:1)
Block(-8,43,1,LOG:1)
Block(-8,43,5,LOG:1)
Block(-8,44,-7,LOG:1)
Block(-8,44,-3,LOG:1)
Block(-8,44,1,LOG:1)
Block(-8,44,5,LOG:1)
Block(-8,45,-7,LOG:1)
Block(-8,45,-6,LOG:9)
Block(-8,45,-5,LOG:9)
Block(-8,45,-4,LOG:9)
Block(-8,45,-3,LOG:1)
Block(-8,45,-2,LOG:9)
Block(-8,45,-1,LOG:9)
Block(-8,45,0,LOG:9)
Block(-8,45,1,LOG:1)
Block(-8,45,5,LOG:1)
Block(-8,45,6,LOG:9)
Block(-8,45,7,LOG:9)
Block(-8,45,8,LOG:9)
Block(-8,46,-7,LOG:1)
Block(-8,46,-3,LOG:1)
Block(-8,46,1,LOG:1)
Block(-8,46,2,LOG:9)
Block(-8,46,3,LOG:9)
Block(-8,46,4,LOG:9)
Block(-8,46,5,LOG:1)
Block(-8,47,-7,LOG:1)
Block(-8,47,-3,LOG:1)
Block(-8,47,1,LOG:1)
Block(-8,47,5,LOG:1)
Block(-8,48,-7,LOG:1)
Block(-8,48,-3,LOG:1)
Block(-8,48,1,LOG:1)
Block(-8,48,5,LOG:1)
Block(-8,49,-7,LOG:1)
Block(-8,49,-3,LOG:1)
Block(-8,49,1,LOG:1)
Block(-8,49,5,LOG:1)
Block(-8,50,-7,LOG:1)
Block(-8,50,-6,LOG:9)
Block(-8,50,-5,LOG:9)
Block(-8,50,-4,LOG:9)
Block(-8,50,-3,LOG:1)
Block(-8,50,-2,LOG:9)
Block(-8,50,-1,LOG:9)
Block(-8,50,0,LOG:9)
Block(-8,50,1,LOG:1)
Block(-8,50,2,LOG:9)
Block(-8,50,3,LOG:9)
Block(-8,50,4,LOG:9)
Block(-8,50,5,LOG:1)
Block(-8,50,6,LOG:9)
Block(-8,50,7,LOG:9)
Block(-8,50,8,LOG:9)
Block(-8,51,-7,LOG:1)
Block(-8,51,-3,LOG:1)
Block(-8,51,-2,WOOD_DOUBLE_STEP:5)
Block(-8,51,-1,WOOD_DOUBLE_STEP:5)
Block(-8,51,0,WOOD_DOUBLE_STEP:5)
Block(-8,51,1,LOG:1)
Block(-8,51,5,LOG:1)
Block(-8,52,-7,LOG:1)
Block(-8,52,-6,LOG:9)
Block(-8,52,-5,LOG:9)
Block(-8,52,-4,LOG:9)
Block(-8,52,-3,LOG:1)
Block(-8,52,-2,LOG:9)
Block(-8,52,-1,LOG:9)
Block(-8,52,0,LOG:9)
Block(-8,52,1,LOG:1)
Block(-8,52,2,LOG:9)
Block(-8,52,3,LOG:9)
Block(-8,52,4,LOG:9)
Block(-8,52,5,LOG:1)
Block(-8,52,6,LOG:9)
Block(-8,52,7,LOG:9)
Block(-8,52,8,LOG:9)
Block(-8,53,-7,LOG:1)
Block(-8,53,-3,LOG:1)
Block(-8,53,1,LOG:1)
Block(-8,53,2,DARK_OAK_FENCE:0)
Block(-8,53,4,DARK_OAK_FENCE:0)
Block(-8,53,5,LOG:1)
Block(-8,53,6,DARK_OAK_FENCE:0)
Block(-8,53,7,DARK_OAK_FENCE:0)
Block(-8,53,8,DARK_OAK_FENCE:0)
Block(-8,54,-7,STEP:0)
Block(-8,54,-3,STEP:0)
Block(-8,54,1,STEP:0)
Block(-8,54,5,STEP:0)
Block(-8,54,7,WOOD_STEP:9)
Block(-8,55,7,SPRUCE_FENCE:0)
Block(-8,55,8,WOOD_STEP:1)
Block(-7,50,-7,LOG:5)
Block(-7,51,-2,WOOD_STEP:13)
Block(-7,51,0,WOOD_STEP:13)
Block(-7,52,-7,LOG:5)
Block(-7,52,-3,SPRUCE_WOOD_STAIRS:6)
Block(-7,52,-2,LOG:5)
Block(-7,52,-1,STEP:8)
Block(-7,52,0,LOG:5)
Block(-7,52,1,SPRUCE_WOOD_STAIRS:7)
Block(-7,52,2,WOOD_STEP:8)
Block(-7,52,3,WOOD_STEP:8)
Block(-7,52,4,WOOD_STEP:8)
Block(-7,52,5,DARK_OAK_STAIRS:5)
Block(-7,52,6,WOOD_STEP:8)
Block(-7,52,7,WOOD_STEP:8)
Block(-7,52,8,WOOD_STEP:8)
Block(-7,53,-3,COBBLE_WALL:0)
Block(-7,53,1,COBBLE_WALL:0)
Block(-7,55,7,SPRUCE_FENCE:0)
Block(-7,55,8,WOOD_STEP:1)
Block(-6,50,-7,LOG:5)
Block(-6,51,-2,WOOD_STEP:13)
Block(-6,51,0,WOOD_STEP:13)
Block(-6,52,-7,LOG:5)
Block(-6,52,-3,WOOD_STEP:9)
Block(-6,52,-2,LOG:5)
Block(-6,52,-1,STEP:8)
Block(-6,52,0,LOG:5)
Block(-6,52,1,WOOD_STEP:9)
Block(-6,53,-7,COAL_ORE:0)
Block(-6,53,-3,COBBLE_WALL:0)
Block(-6,53,1,COBBLE_WALL:0)
Block(-6,54,-1,AIR:0)
Block(-6,55,7,SPRUCE_FENCE:0)
Block(-6,55,8,WOOD_STEP:1)
Block(-5,50,-7,LOG:5)
Block(-5,51,-2,WOOD_STEP:13)
Block(-5,51,0,WOOD_STEP:13)
Block(-5,52,-7,LOG:5)
Block(-5,52,-3,WOOD_STEP:9)
Block(-5,52,-2,LOG:5)
Block(-5,52,-1,STEP:8)
Block(-5,52,0,LOG:5)
Block(-5,52,1,WOOD_STEP:9)
Block(-5,53,-7,COAL_ORE:0)
Block(-5,53,-3,COBBLE_WALL:0)
Block(-5,53,1,COBBLE_WALL:0)
Block(-5,54,7,WOOD_STEP:9)
Block(-5,55,7,SPRUCE_FENCE:0)
Block(-5,55,8,WOOD_STEP:1)
Block(-4,0,-7,LOG:1)
Block(-4,1,-7,LOG:1)
Block(-4,2,-7,LOG:1)
Block(-4,3,-7,LOG:1)
Block(-4,4,-7,LOG:1)
Block(-4,5,-7,LOG:1)
Block(-4,6,-7,LOG:1)
Block(-4,7,-7,LOG:1)
Block(-4,8,-7,LOG:1)
Block(-4,9,-7,LOG:1)
Block(-4,10,-7,LOG:1)
Block(-4,11,-7,LOG:1)
Block(-4,12,-7,LOG:1)
Block(-4,13,-7,LOG:1)
Block(-4,14,-7,LOG:1)
Block(-4,15,-7,LOG:1)
Block(-4,16,-7,LOG:1)
Block(-4,17,-7,LOG:1)
Block(-4,18,-7,LOG:1)
Block(-4,19,-7,LOG:1)
Block(-4,20,-7,LOG:1)
Block(-4,21,-7,LOG:1)
Block(-4,22,-7,LOG:1)
Block(-4,23,-7,LOG:1)
Block(-4,24,-7,LOG:1)
Block(-4,25,-7,LOG:1)
Block(-4,26,-7,LOG:1)
Block(-4,27,-7,LOG:1)
Block(-4,28,-7,LOG:1)
Block(-4,29,-7,LOG:1)
Block(-4,30,-7,LOG:1)
Block(-4,31,-7,LOG:1)
Block(-4,32,-7,LOG:1)
Block(-4,33,-7,LOG:1)
Block(-4,34,-7,LOG:1)
Block(-4,35,-7,LOG:1)
Block(-4,36,-7,LOG:1)
Block(-4,37,-7,LOG:1)
Block(-4,38,-7,LOG:1)
Block(-4,39,-7,LOG:1)
Block(-4,40,-7,LOG:1)
Block(-4,41,-7,LOG:1)
Block(-4,42,-7,LOG:1)
Block(-4,43,-7,LOG:1)
Block(-4,44,-7,LOG:1)
Block(-4,45,-7,LOG:1)
Block(-4,46,-7,LOG:1)
Block(-4,47,-7,LOG:1)
Block(-4,48,-7,LOG:1)
Block(-4,49,-7,LOG:1)
Block(-4,49,-6,LADDER:3)
Block(-4,50,-7,LOG:1)
Block(-4,50,-6,LADDER:3)
Block(-4,51,-7,LOG:1)
Block(-4,51,-6,LADDER:3)
Block(-4,51,-2,WOOD_STEP:13)
Block(-4,51,0,WOOD_STEP:13)
Block(-4,52,-7,LOG:1)
Block(-4,52,-6,LADDER:3)
Block(-4,52,-3,WOOD_STEP:9)
Block(-4,52,-2,LOG:5)
Block(-4,52,-1,STEP:8)
Block(-4,52,0,LOG:5)
Block(-4,52,1,WOOD_STEP:9)
Block(-4,53,-7,LOG:1)
Block(-4,53,-6,LADDER:3)
Block(-4,53,-3,COBBLE_WALL:0)
Block(-4,53,1,COBBLE_WALL:0)
Block(-4,54,-7,STEP:0)
Block(-4,55,7,SPRUCE_FENCE:0)
Block(-4,55,8,WOOD_STEP:1)
Block(-4,56,7,SPRUCE_FENCE:0)
Block(-3,50,-7,LOG:5)
Block(-3,51,-2,WOOD_STEP:13)
Block(-3,51,0,WOOD_STEP:13)
Block(-3,52,-7,LOG:5)
Block(-3,52,-3,SPRUCE_WOOD_STAIRS:6)
Block(-3,52,-2,LOG:5)
Block(-3,52,-1,STEP:8)
Block(-3,52,0,LOG:5)
Block(-3,52,1,SPRUCE_WOOD_STAIRS:7)
Block(-3,53,-3,COBBLE_WALL:0)
Block(-3,53,1,COBBLE_WALL:0)
Block(-3,55,8,WOOD_STEP:9)
Block(-3,56,7,SPRUCE_FENCE:0)
Block(-2,0,-3,STONE:6)
Block(-2,0,1,STONE:6)
Block(-2,0,6,STONE:6)
Block(-2,1,-3,STONE:6)
Block(-2,1,1,STONE:6)
Block(-2,1,6,STONE:6)
Block(-2,2,-3,STONE:6)
Block(-2,2,1,STONE:6)
Block(-2,2,6,STONE:6)
Block(-2,3,-3,STONE:6)
Block(-2,3,1,STONE:6)
Block(-2,3,6,STONE:6)
Block(-2,4,-3,STONE:6)
Block(-2,4,1,STONE:6)
Block(-2,4,6,STONE:6)
Block(-2,5,-3,STONE:6)
Block(-2,5,1,STONE:6)
Block(-2,5,6,STONE:6)
Block(-2,6,-3,STONE:6)
Block(-2,6,1,STONE:6)
Block(-2,6,6,STONE:6)
Block(-2,7,-3,STONE:6)
Block(-2,7,1,STONE:6)
Block(-2,7,6,STONE:6)
Block(-2,8,-3,STONE:6)
Block(-2,8,1,STONE:6)
Block(-2,8,6,STONE:6)
Block(-2,9,-3,STONE:6)
Block(-2,9,1,STONE:6)
Block(-2,9,6,STONE:6)
Block(-2,10,-3,STONE:6)
Block(-2,10,1,STONE:6)
Block(-2,10,6,STONE:6)
Block(-2,11,-3,STONE:6)
Block(-2,11,1,STONE:6)
Block(-2,11,6,STONE:6)
Block(-2,12,-3,STONE:6)
Block(-2,12,1,STONE:6)
Block(-2,12,6,STONE:6)
Block(-2,13,-3,STONE:6)
Block(-2,13,1,STONE:6)
Block(-2,13,6,STONE:6)
Block(-2,14,-3,STONE:6)
Block(-2,14,1,STONE:6)
Block(-2,14,6,STONE:6)
Block(-2,15,-3,STONE:6)
Block(-2,15,1,STONE:6)
Block(-2,15,6,STONE:6)
Block(-2,16,-3,STONE:6)
Block(-2,16,1,STONE:6)
Block(-2,16,6,STONE:6)
Block(-2,17,-3,STONE:6)
Block(-2,17,1,STONE:6)
Block(-2,17,6,STONE:6)
Block(-2,18,-3,STONE:6)
Block(-2,18,1,STONE:6)
Block(-2,18,6,STONE:6)
Block(-2,19,-3,STONE:6)
Block(-2,19,1,STONE:6)
Block(-2,19,6,STONE:6)
Block(-2,20,-3,STONE:6)
Block(-2,20,1,STONE:6)
Block(-2,20,6,STONE:6)
Block(-2,21,-3,STONE:6)
Block(-2,21,1,STONE:6)
Block(-2,21,6,STONE:6)
Block(-2,22,-3,STONE:6)
Block(-2,22,1,STONE:6)
Block(-2,22,6,STONE:6)
Block(-2,23,-3,STONE:6)
Block(-2,23,1,STONE:6)
Block(-2,23,6,STONE:6)
Block(-2,24,-3,STONE:6)
Block(-2,24,1,STONE:6)
Block(-2,24,6,STONE:6)
Block(-2,25,-3,STONE:6)
Block(-2,25,1,STONE:6)
Block(-2,25,6,STONE:6)
Block(-2,26,-3,STONE:6)
Block(-2,26,1,STONE:6)
Block(-2,26,6,STONE:6)
Block(-2,27,-3,STONE:6)
Block(-2,27,1,STONE:6)
Block(-2,27,6,STONE:6)
Block(-2,28,-3,STONE:6)
Block(-2,28,1,STONE:6)
Block(-2,28,6,STONE:6)
Block(-2,29,-3,STONE:6)
Block(-2,29,1,STONE:6)
Block(-2,29,6,STONE:6)
Block(-2,30,-3,STONE:6)
Block(-2,30,1,STONE:6)
Block(-2,30,6,STONE:6)
Block(-2,31,-3,STONE:6)
Block(-2,31,1,STONE:6)
Block(-2,31,6,STONE:6)
Block(-2,32,-3,STONE:6)
Block(-2,32,1,STONE:6)
Block(-2,32,6,STONE:6)
Block(-2,33,-3,STONE:6)
Block(-2,33,1,STONE:6)
Block(-2,33,6,STONE:6)
Block(-2,34,-3,STONE:6)
Block(-2,34,1,STONE:6)
Block(-2,34,6,STONE:6)
Block(-2,35,-3,STONE:6)
Block(-2,35,1,STONE:6)
Block(-2,35,6,STONE:6)
Block(-2,36,-3,STONE:6)
Block(-2,36,1,STONE:6)
Block(-2,36,6,STONE:6)
Block(-2,37,-3,STONE:6)
Block(-2,37,1,STONE:6)
Block(-2,37,6,STONE:6)
Block(-2,38,-3,STONE:6)
Block(-2,38,1,STONE:6)
Block(-2,38,6,STONE:6)
Block(-2,39,-3,STONE:6)
Block(-2,39,1,STONE:6)
Block(-2,39,6,STONE:6)
Block(-2,40,-3,STONE:6)
Block(-2,40,1,STONE:6)
Block(-2,40,6,STONE:6)
Block(-2,41,-3,STONE:6)
Block(-2,41,1,STONE:6)
Block(-2,41,6,STONE:6)
Block(-2,42,-3,STONE:6)
Block(-2,42,1,STONE:6)
Block(-2,42,6,STONE:6)
Block(-2,43,-3,STONE:6)
Block(-2,43,1,STONE:6)
Block(-2,43,6,STONE:6)
Block(-2,44,-3,STONE:6)
Block(-2,44,1,STONE:6)
Block(-2,44,6,STONE:6)
Block(-2,45,-3,STONE:6)
Block(-2,45,1,STONE:6)
Block(-2,45,6,STONE:6)
Block(-2,46,-3,STONE:6)
Block(-2,46,1,STONE:6)
Block(-2,46,6,STONE:6)
Block(-2,47,-3,STONE:6)
Block(-2,47,1,STONE:6)
Block(-2,47,6,STONE:6)
Block(-2,48,-3,STONE:6)
Block(-2,48,1,STONE:6)
Block(-2,48,6,STONE:6)
Block(-2,49,-3,STONE:6)
Block(-2,49,1,STONE:6)
Block(-2,49,6,STONE:6)
Block(-2,50,-7,LOG:5)
Block(-2,50,-3,SMOOTH_STAIRS:0)
Block(-2,50,1,STONE:6)
Block(-2,50,6,STONE:6)
Block(-2,51,-3,SMOOTH_STAIRS:4)
Block(-2,51,-2,WOOD_STEP:13)
Block(-2,51,-1,WOOD_STEP:13)
Block(-2,51,0,WOOD_STEP:13)
Block(-2,51,1,SMOOTH_STAIRS:0)
Block(-2,51,6,SMOOTH_STAIRS:0)
Block(-2,51,7,WOOD_STEP:13)
Block(-2,51,8,WOOD_STEP:13)
Block(-2,52,-7,LOG:5)
Block(-2,52,-3,STONE:6)
Block(-2,52,-2,LOG:5)
Block(-2,52,-1,STEP:8)
Block(-2,52,0,LOG:5)
Block(-2,52,1,SMOOTH_STAIRS:4)
Block(-2,52,2,WOOD_STEP:13)
Block(-2,52,3,WOOD_STEP:13)
Block(-2,52,4,WOOD_STEP:13)
Block(-2,52,5,WOOD_STEP:13)
Block(-2,52,6,SMOOTH_STAIRS:4)
Block(-2,52,7,STEP:0)
Block(-2,52,8,STEP:0)
Block(-2,53,-3,STONE:6)
Block(-2,53,1,STONE:6)
Block(-2,53,2,STEP:0)
Block(-2,53,3,STEP:0)
Block(-2,53,4,STEP:0)
Block(-2,53,5,STEP:0)
Block(-2,53,6,STONE:6)
Block(-2,54,-3,SMOOTH_STAIRS:0)
Block(-2,54,1,SMOOTH_STAIRS:0)
Block(-2,54,6,SMOOTH_STAIRS:0)
Block(-2,55,-3,STEP:0)
Block(-2,55,1,STEP:0)
Block(-2,55,6,STEP:0)
Block(-2,55,8,WOOD_STEP:9)
Block(-2,56,7,SPRUCE_FENCE:0)
Block(-2,57,7,SPRUCE_FENCE:0)
Block(-1,0,-4,STONE:6)
Block(-1,0,-3,LOG:1)
Block(-1,0,1,LOG:1)
Block(-1,0,6,LOG:1)
Block(-1,1,-4,STONE:6)
Block(-1,1,-3,LOG:1)
Block(-1,1,-2,LOG:9)
Block(-1,1,-1,LOG:9)
Block(-1,1,0,LOG:9)
Block(-1,1,1,LOG:1)
Block(-1,1,6,LOG:1)
Block(-1,1,7,LOG:9)
Block(-1,1,8,LOG:9)
Block(-1,2,-4,STONE:6)
Block(-1,2,-3,LOG:1)
Block(-1,2,1,LOG:1)
Block(-1,2,6,LOG:1)
Block(-1,3,-4,STONE:6)
Block(-1,3,-3,LOG:1)
Block(-1,3,1,LOG:1)
Block(-1,3,6,LOG:1)
Block(-1,4,-4,STONE:6)
Block(-1,4,-3,LOG:1)
Block(-1,4,1,LOG:1)
Block(-1,4,6,LOG:1)
Block(-1,5,-4,STONE:6)
Block(-1,5,-3,LOG:1)
Block(-1,5,-2,LOG:9)
Block(-1,5,-1,LOG:9)
Block(-1,5,0,LOG:9)
Block(-1,5,1,LOG:1)
Block(-1,5,6,LOG:1)
Block(-1,5,7,LOG:9)
Block(-1,5,8,LOG:9)
Block(-1,6,-4,STONE:6)
Block(-1,6,-3,LOG:1)
Block(-1,6,1,LOG:1)
Block(-1,6,6,LOG:1)
Block(-1,7,-4,STONE:6)
Block(-1,7,-3,LOG:1)
Block(-1,7,1,LOG:1)
Block(-1,7,6,LOG:1)
Block(-1,8,-4,STONE:6)
Block(-1,8,-3,LOG:1)
Block(-1,8,1,LOG:1)
Block(-1,8,6,LOG:1)
Block(-1,9,-4,STONE:6)
Block(-1,9,-3,LOG:1)
Block(-1,9,-2,LOG:9)
Block(-1,9,-1,LOG:9)
Block(-1,9,0,LOG:9)
Block(-1,9,1,LOG:1)
Block(-1,9,6,LOG:1)
Block(-1,9,7,LOG:9)
Block(-1,9,8,LOG:9)
Block(-1,10,-4,STONE:6)
Block(-1,10,-3,LOG:1)
Block(-1,10,1,LOG:1)
Block(-1,10,6,LOG:1)
Block(-1,11,-4,STONE:6)
Block(-1,11,-3,LOG:1)
Block(-1,11,1,LOG:1)
Block(-1,11,6,LOG:1)
Block(-1,12,-4,STONE:6)
Block(-1,12,-3,LOG:1)
Block(-1,12,1,LOG:1)
Block(-1,12,6,LOG:1)
Block(-1,13,-4,STONE:6)
Block(-1,13,-3,LOG:1)
Block(-1,13,-2,LOG:9)
Block(-1,13,-1,LOG:9)
Block(-1,13,0,LOG:9)
Block(-1,13,1,LOG:1)
Block(-1,13,6,LOG:1)
Block(-1,13,7,LOG:9)
Block(-1,13,8,LOG:9)
Block(-1,14,-4,STONE:6)
Block(-1,14,-3,LOG:1)
Block(-1,14,1,LOG:1)
Block(-1,14,6,LOG:1)
Block(-1,15,-4,STONE:6)
Block(-1,15,-3,LOG:1)
Block(-1,15,1,LOG:1)
Block(-1,15,6,LOG:1)
Block(-1,16,-4,STONE:6)
Block(-1,16,-3,LOG:1)
Block(-1,16,1,LOG:1)
Block(-1,16,6,LOG:1)
Block(-1,17,-4,STONE:6)
Block(-1,17,-3,LOG:1)
Block(-1,17,-2,LOG:9)
Block(-1,17,-1,LOG:9)
Block(-1,17,0,LOG:9)
Block(-1,17,1,LOG:1)
Block(-1,17,6,LOG:1)
Block(-1,17,7,LOG:9)
Block(-1,17,8,LOG:9)
Block(-1,18,-4,STONE:6)
Block(-1,18,-3,LOG:1)
Block(-1,18,1,LOG:1)
Block(-1,18,6,LOG:1)
Block(-1,19,-4,STONE:6)
Block(-1,19,-3,LOG:1)
Block(-1,19,1,LOG:1)
Block(-1,19,6,LOG:1)
Block(-1,20,-4,STONE:6)
Block(-1,20,-3,LOG:1)
Block(-1,20,1,LOG:1)
Block(-1,20,6,LOG:1)
Block(-1,21,-4,STONE:6)
Block(-1,21,-3,LOG:1)
Block(-1,21,-2,LOG:9)
Block(-1,21,-1,LOG:9)
Block(-1,21,0,LOG:9)
Block(-1,21,1,LOG:1)
Block(-1,21,6,LOG:1)
Block(-1,21,7,LOG:9)
Block(-1,21,8,LOG:9)
Block(-1,22,-4,STONE:6)
Block(-1,22,-3,LOG:1)
Block(-1,22,1,LOG:1)
Block(-1,22,6,LOG:1)
Block(-1,23,-4,STONE:6)
Block(-1,23,-3,LOG:1)
Block(-1,23,1,LOG:1)
Block(-1,23,6,LOG:1)
Block(-1,24,-4,STONE:6)
Block(-1,24,-3,LOG:1)
Block(-1,24,1,LOG:1)
Block(-1,24,6,LOG:1)
Block(-1,25,-4,STONE:6)
Block(-1,25,-3,LOG:1)
Block(-1,25,-2,LOG:9)
Block(-1,25,-1,LOG:9)
Block(-1,25,0,LOG:9)
Block(-1,25,1,LOG:1)
Block(-1,25,6,LOG:1)
Block(-1,25,7,LOG:9)
Block(-1,25,8,LOG:9)
Block(-1,26,-4,STONE:6)
Block(-1,26,-3,LOG:1)
Block(-1,26,1,LOG:1)
Block(-1,26,6,LOG:1)
Block(-1,27,-4,STONE:6)
Block(-1,27,-3,LOG:1)
Block(-1,27,1,LOG:1)
Block(-1,27,6,LOG:1)
Block(-1,28,-4,STONE:6)
Block(-1,28,-3,LOG:1)
Block(-1,28,1,LOG:1)
Block(-1,28,6,LOG:1)
Block(-1,29,-4,STONE:6)
Block(-1,29,-3,LOG:1)
Block(-1,29,-2,LOG:9)
Block(-1,29,-1,LOG:9)
Block(-1,29,0,LOG:9)
Block(-1,29,1,LOG:1)
Block(-1,29,6,LOG:1)
Block(-1,29,7,LOG:9)
Block(-1,29,8,LOG:9)
Block(-1,30,-4,STONE:6)
Block(-1,30,-3,LOG:1)
Block(-1,30,1,LOG:1)
Block(-1,30,6,LOG:1)
Block(-1,31,-4,STONE:6)
Block(-1,31,-3,LOG:1)
Block(-1,31,1,LOG:1)
Block(-1,31,6,LOG:1)
Block(-1,32,-4,STONE:6)
Block(-1,32,-3,LOG:1)
Block(-1,32,1,LOG:1)
Block(-1,32,6,LOG:1)
Block(-1,33,-4,STONE:6)
Block(-1,33,-3,LOG:1)
Block(-1,33,-2,LOG:9)
Block(-1,33,-1,LOG:9)
Block(-1,33,0,LOG:9)
Block(-1,33,1,LOG:1)
Block(-1,33,6,LOG:1)
Block(-1,33,7,LOG:9)
Block(-1,33,8,LOG:9)
Block(-1,34,-4,STONE:6)
Block(-1,34,-3,LOG:1)
Block(-1,34,1,LOG:1)
Block(-1,34,6,LOG:1)
Block(-1,35,-4,STONE:6)
Block(-1,35,-3,LOG:1)
Block(-1,35,1,LOG:1)
Block(-1,35,6,LOG:1)
Block(-1,36,-4,STONE:6)
Block(-1,36,-3,LOG:1)
Block(-1,36,1,LOG:1)
Block(-1,36,6,LOG:1)
Block(-1,37,-4,STONE:6)
Block(-1,37,-3,LOG:1)
Block(-1,37,-2,LOG:9)
Block(-1,37,-1,LOG:9)
Block(-1,37,0,LOG:9)
Block(-1,37,1,LOG:1)
Block(-1,37,6,LOG:1)
Block(-1,37,7,LOG:9)
Block(-1,37,8,LOG:9)
Block(-1,38,-4,STONE:6)
Block(-1,38,-3,LOG:1)
Block(-1,38,1,LOG:1)
Block(-1,38,6,LOG:1)
Block(-1,39,-4,STONE:6)
Block(-1,39,-3,LOG:1)
Block(-1,39,1,LOG:1)
Block(-1,39,6,LOG:1)
Block(-1,40,-4,STONE:6)
Block(-1,40,-3,LOG:1)
Block(-1,40,1,LOG:1)
Block(-1,40,6,LOG:1)
Block(-1,41,-4,STONE:6)
Block(-1,41,-3,LOG:1)
Block(-1,41,-2,LOG:9)
Block(-1,41,-1,LOG:9)
Block(-1,41,0,LOG:9)
Block(-1,41,1,LOG:1)
Block(-1,41,6,LOG:1)
Block(-1,41,7,LOG:9)
Block(-1,41,8,LOG:9)
Block(-1,42,-4,STONE:6)
Block(-1,42,-3,LOG:1)
Block(-1,42,1,LOG:1)
Block(-1,42,6,LOG:1)
Block(-1,43,-4,STONE:6)
Block(-1,43,-3,LOG:1)
Block(-1,43,1,LOG:1)
Block(-1,43,6,LOG:1)
Block(-1,44,-4,STONE:6)
Block(-1,44,-3,LOG:1)
Block(-1,44,1,LOG:1)
Block(-1,44,6,LOG:1)
Block(-1,45,-4,STONE:6)
Block(-1,45,-3,LOG:1)
Block(-1,45,-2,LOG:9)
Block(-1,45,-1,LOG:9)
Block(-1,45,0,LOG:9)
Block(-1,45,1,LOG:1)
Block(-1,45,6,LOG:1)
Block(-1,45,7,LOG:9)
Block(-1,45,8,LOG:9)
Block(-1,46,-4,STONE:6)
Block(-1,46,-3,LOG:1)
Block(-1,46,1,LOG:1)
Block(-1,46,6,LOG:1)
Block(-1,47,-4,STONE:6)
Block(-1,47,-3,LOG:1)
Block(-1,47,1,LOG:1)
Block(-1,47,6,LOG:1)
Block(-1,48,-4,STONE:6)
Block(-1,48,-3,LOG:1)
Block(-1,48,1,LOG:1)
Block(-1,48,6,LOG:1)
Block(-1,49,-4,STONE:6)
Block(-1,49,-3,LOG:1)
Block(-1,49,1,LOG:1)
Block(-1,49,6,LOG:1)
Block(-1,50,-7,LOG:5)
Block(-1,50,-4,SMOOTH_STAIRS:2)
Block(-1,50,-3,LOG:1)
Block(-1,50,-2,LOG:9)
Block(-1,50,-1,LOG:9)
Block(-1,50,0,LOG:9)
Block(-1,50,1,LOG:1)
Block(-1,50,6,LOG:1)
Block(-1,50,7,LOG:9)
Block(-1,50,8,LOG:9)
Block(-1,51,-4,SMOOTH_STAIRS:6)
Block(-1,51,-3,LOG:1)
Block(-1,51,-2,WOOD_STEP:5)
Block(-1,51,-1,WOOD_STEP:5)
Block(-1,51,0,WOOD_STEP:5)
Block(-1,51,1,LOG:1)
Block(-1,51,6,LOG:1)
Block(-1,51,7,WOOD_STEP:5)
Block(-1,51,8,WOOD_STEP:5)
Block(-1,52,-7,LOG:5)
Block(-1,52,-4,STONE:6)
Block(-1,52,-3,LOG:1)
Block(-1,52,-2,LOG:9)
Block(-1,52,-1,LOG:9)
Block(-1,52,0,LOG:9)
Block(-1,52,1,LOG:1)
Block(-1,52,3,WOOD_STEP:8)
Block(-1,52,5,WOOD_STEP:8)
Block(-1,52,6,LOG:1)
Block(-1,52,7,LOG:9)
Block(-1,52,8,LOG:9)
Block(-1,53,-7,WORKBENCH:0)
Block(-1,53,-4,SMOOTH_STAIRS:2)
Block(-1,53,-3,SMOOTH_BRICK:3)
Block(-1,53,1,LOG:1)
Block(-1,53,2,LOG:9)
Block(-1,53,3,LOG:9)
Block(-1,53,4,LOG:9)
Block(-1,53,5,LOG:9)
Block(-1,53,6,LOG:1)
Block(-1,53,7,LOG:1)
Block(-1,53,8,SPRUCE_FENCE:0)
Block(-1,54,-4,STEP:0)
Block(-1,54,-3,SMOOTH_STAIRS:1)
Block(-1,54,1,SMOOTH_STAIRS:1)
Block(-1,54,2,SPRUCE_FENCE:0)
Block(-1,54,3,SPRUCE_FENCE:0)
Block(-1,54,4,SPRUCE_FENCE:0)
Block(-1,54,5,SPRUCE_FENCE:0)
Block(-1,54,6,SMOOTH_STAIRS:1)
Block(-1,54,7,LOG:1)
Block(-1,55,-3,STEP:0)
Block(-1,55,1,STEP:0)
Block(-1,55,6,STEP:0)
Block(-1,55,7,LOG:1)
Block(-1,55,8,LOG:9)
Block(-1,56,7,LOG:1)
Block(-1,57,7,SPRUCE_FENCE:0)
Block(0,0,-7,LOG:1)
Block(0,1,-7,LOG:1)
Block(0,1,-3,LOG:5)
Block(0,1,1,LOG:5)
Block(0,2,-7,LOG:1)
Block(0,3,-7,LOG:1)
Block(0,3,6,LOG:5)
Block(0,4,-7,LOG:1)
Block(0,5,-7,LOG:1)
Block(0,5,-3,LOG:5)
Block(0,5,1,LOG:5)
Block(0,6,-7,LOG:1)
Block(0,7,-7,LOG:1)
Block(0,7,6,LOG:5)
Block(0,8,-7,LOG:1)
Block(0,9,-7,LOG:1)
Block(0,9,-3,LOG:5)
Block(0,9,1,LOG:5)
Block(0,10,-7,LOG:1)
Block(0,11,-7,LOG:1)
Block(0,11,6,LOG:5)
Block(0,12,-7,LOG:1)
Block(0,13,-7,LOG:1)
Block(0,13,-3,LOG:5)
Block(0,13,1,LOG:5)
Block(0,14,-7,LOG:1)
Block(0,15,-7,LOG:1)
Block(0,15,6,LOG:5)
Block(0,16,-7,LOG:1)
Block(0,17,-7,LOG:1)
Block(0,17,-3,LOG:5)
Block(0,17,1,LOG:5)
Block(0,18,-7,LOG:1)
Block(0,19,-7,LOG:1)
Block(0,19,6,LOG:5)
Block(0,20,-7,LOG:1)
Block(0,21,-7,LOG:1)
Block(0,21,-3,LOG:5)
Block(0,21,1,LOG:5)
Block(0,22,-7,LOG:1)
Block(0,23,-7,LOG:1)
Block(0,23,6,LOG:5)
Block(0,24,-7,LOG:1)
Block(0,25,-7,LOG:1)
Block(0,25,-3,LOG:5)
Block(0,25,1,LOG:5)
Block(0,26,-7,LOG:1)
Block(0,27,-7,LOG:1)
Block(0,27,6,LOG:5)
Block(0,28,-7,LOG:1)
Block(0,29,-7,LOG:1)
Block(0,29,-3,LOG:5)
Block(0,29,1,LOG:5)
Block(0,30,-7,LOG:1)
Block(0,31,-7,LOG:1)
Block(0,31,6,LOG:5)
Block(0,32,-7,LOG:1)
Block(0,33,-7,LOG:1)
Block(0,33,-3,LOG:5)
Block(0,33,1,LOG:5)
Block(0,34,-7,LOG:1)
Block(0,35,-7,LOG:1)
Block(0,35,6,LOG:5)
Block(0,36,-7,LOG:1)
Block(0,37,-7,LOG:1)
Block(0,37,-3,LOG:5)
Block(0,37,1,LOG:5)
Block(0,38,-7,LOG:1)
Block(0,39,-7,LOG:1)
Block(0,39,6,LOG:5)
Block(0,40,-7,LOG:1)
Block(0,41,-7,LOG:1)
Block(0,41,-3,LOG:5)
Block(0,41,1,LOG:5)
Block(0,42,-7,LOG:1)
Block(0,43,-7,LOG:1)
Block(0,43,6,LOG:5)
Block(0,44,-7,LOG:1)
Block(0,45,-7,LOG:1)
Block(0,45,-3,LOG:5)
Block(0,45,1,LOG:5)
Block(0,46,-7,LOG:1)
Block(0,47,-7,LOG:1)
Block(0,47,6,LOG:5)
Block(0,48,-7,LOG:1)
Block(0,48,6,LOG:5)
Block(0,49,-7,LOG:1)
Block(0,50,-7,LOG:1)
Block(0,50,-4,WOOD_BUTTON:4)
Block(0,50,-3,LOG:5)
Block(0,50,1,LOG:5)
Block(0,50,6,LOG:5)
Block(0,51,-7,LOG:1)
Block(0,51,-4,WOOD_STEP:13)
Block(0,51,-3,WOOD_STEP:5)
Block(0,51,1,WOOD_DOUBLE_STEP:5)
Block(0,52,-7,LOG:1)
Block(0,52,-4,STEP:0)
Block(0,52,-3,LOG:5)
Block(0,52,-2,STEP:0)
Block(0,52,-1,STEP:0)
Block(0,52,0,STEP:0)
Block(0,52,1,STEP:0)
Block(0,52,2,STEP:8)
Block(0,52,3,WOOD_STEP:8)
Block(0,52,5,WOOD_STEP:8)
Block(0,52,6,LOG:5)
Block(0,52,7,STEP:8)
Block(0,52,8,STEP:0)
Block(0,53,-7,LOG:1)
Block(0,53,-3,SPRUCE_FENCE:0)
Block(0,53,3,STEP:0)
Block(0,53,4,STEP:0)
Block(0,53,5,STEP:0)
Block(0,53,6,STEP:0)
Block(0,54,-7,STEP:0)
Block(0,55,8,WOOD_STEP:9)
Block(0,56,7,SPRUCE_FENCE:0)
Block(0,57,7,SPRUCE_FENCE:0)
Block(1,1,-3,LOG:5)
Block(1,1,1,LOG:5)
Block(1,3,6,LOG:5)
Block(1,5,-3,LOG:5)
Block(1,5,1,LOG:5)
Block(1,7,6,LOG:5)
Block(1,9,-3,LOG:5)
Block(1,9,1,LOG:5)
Block(1,11,6,LOG:5)
Block(1,13,-3,LOG:5)
Block(1,13,1,LOG:5)
Block(1,15,6,LOG:5)
Block(1,17,-3,LOG:5)
Block(1,17,1,LOG:5)
Block(1,19,6,LOG:5)
Block(1,21,-3,LOG:5)
Block(1,21,1,LOG:5)
Block(1,23,6,LOG:5)
Block(1,25,-3,LOG:5)
Block(1,25,1,LOG:5)
Block(1,27,6,LOG:5)
Block(1,29,-3,LOG:5)
Block(1,29,1,LOG:5)
Block(1,31,6,LOG:5)
Block(1,33,-3,LOG:5)
Block(1,33,1,LOG:5)
Block(1,35,6,LOG:5)
Block(1,37,-3,LOG:5)
Block(1,37,1,LOG:5)
Block(1,39,6,LOG:5)
Block(1,41,-3,LOG:5)
Block(1,41,1,LOG:5)
Block(1,43,6,LOG:5)
Block(1,45,-3,LOG:5)
Block(1,45,1,LOG:5)
Block(1,47,6,LOG:5)
Block(1,48,6,LOG:5)
Block(1,50,-7,LOG:5)
Block(1,50,-4,WOOD_BUTTON:4)
Block(1,50,-3,LOG:5)
Block(1,50,1,LOG:5)
Block(1,50,6,LOG:5)
Block(1,51,-4,WOOD_STEP:13)
Block(1,51,-3,WOOD_STEP:5)
Block(1,51,1,WOOD_DOUBLE_STEP:5)
Block(1,52,-7,LOG:5)
Block(1,52,-4,STEP:0)
Block(1,52,-3,LOG:5)
Block(1,52,-2,STEP:0)
Block(1,52,-1,STEP:0)
Block(1,52,0,STEP:0)
Block(1,52,1,STEP:0)
Block(1,52,2,STEP:8)
Block(1,52,3,WOOD_STEP:8)
Block(1,52,5,WOOD_STEP:8)
Block(1,52,6,LOG:5)
Block(1,52,7,STEP:8)
Block(1,52,8,STEP:0)
Block(1,53,-7,HAY_BLOCK:0)
Block(1,53,-3,SPRUCE_FENCE:0)
Block(1,53,3,STEP:0)
Block(1,53,4,STEP:0)
Block(1,53,5,STEP:0)
Block(1,53,6,STEP:0)
Block(1,54,-3,SPRUCE_FENCE:0)
Block(1,54,-1,AIR:0)
Block(1,55,-3,SPRUCE_FENCE:0)
Block(1,55,-2,SPRUCE_FENCE:0)
Block(1,55,8,WOOD_STEP:9)
Block(1,56,-2,TORCH:5)
Block(1,56,7,SPRUCE_FENCE:0)
Block(1,60,8,SPRUCE_FENCE:0)
Block(1,61,8,TORCH:5)
Block(2,1,-3,LOG:5)
Block(2,1,1,LOG:5)
Block(2,3,6,LOG:5)
Block(2,5,-3,LOG:5)
Block(2,5,1,LOG:5)
Block(2,7,6,LOG:5)
Block(2,9,-3,LOG:5)
Block(2,9,1,LOG:5)
Block(2,11,6,LOG:5)
Block(2,13,-3,LOG:5)
Block(2,13,1,LOG:5)
Block(2,15,6,LOG:5)
Block(2,17,-3,LOG:5)
Block(2,17,1,LOG:5)
Block(2,19,6,LOG:5)
Block(2,21,-3,LOG:5)
Block(2,21,1,LOG:5)
Block(2,23,6,LOG:5)
Block(2,25,-3,LOG:5)
Block(2,25,1,LOG:5)
Block(2,27,6,LOG:5)
Block(2,29,-3,LOG:5)
Block(2,29,1,LOG:5)
Block(2,31,6,LOG:5)
Block(2,33,-3,LOG:5)
Block(2,33,1,LOG:5)
Block(2,35,6,LOG:5)
Block(2,37,-3,LOG:5)
Block(2,37,1,LOG:5)
Block(2,39,6,LOG:5)
Block(2,41,-3,LOG:5)
Block(2,41,1,LOG:5)
Block(2,43,6,LOG:5)
Block(2,45,-3,LOG:5)
Block(2,45,1,LOG:5)
Block(2,47,6,LOG:5)
Block(2,48,6,LOG:5)
Block(2,50,-7,LOG:5)
Block(2,50,-4,WOOD_BUTTON:4)
Block(2,50,-3,LOG:5)
Block(2,50,1,LOG:5)
Block(2,50,6,LOG:5)
Block(2,51,-4,WOOD_STEP:13)
Block(2,51,-3,WOOD_STEP:5)
Block(2,51,1,WOOD_DOUBLE_STEP:5)
Block(2,52,-7,LOG:5)
Block(2,52,-4,STEP:0)
Block(2,52,-3,LOG:5)
Block(2,52,-2,STEP:0)
Block(2,52,-1,STEP:0)
Block(2,52,0,STEP:0)
Block(2,52,1,STEP:0)
Block(2,52,2,STEP:8)
Block(2,52,3,WOOD_STEP:8)
Block(2,52,5,WOOD_STEP:8)
Block(2,52,6,LOG:5)
Block(2,52,7,STEP:8)
Block(2,52,8,DOUBLE_STEP:0)
Block(2,53,-7,HAY_BLOCK:0)
Block(2,53,-3,SPRUCE_FENCE:0)
Block(2,53,3,STEP:0)
Block(2,53,4,STEP:0)
Block(2,53,5,STEP:0)
Block(2,53,6,STEP:0)
Block(2,55,8,WOOD_STEP:9)
Block(2,56,7,SPRUCE_FENCE:0)
Block(2,58,6,SPRUCE_WOOD_STAIRS:4)
Block(2,58,7,WOOD_STEP:9)
Block(2,58,8,WOOD_STEP:9)
Block(2,59,6,WOOD_STEP:1)
Block(2,59,7,SPRUCE_FENCE:0)
Block(2,59,8,SPRUCE_FENCE:0)
Block(2,60,8,SPRUCE_FENCE:0)
Block(2,61,5,WOOD_STAIRS:2)
Block(2,61,6,WOOD_STEP:8)
Block(2,62,6,WOOD_STAIRS:2)
Block(2,62,7,WOOD_STAIRS:7)
Block(2,63,7,WOOD_STAIRS:2)
Block(2,63,8,WOOD_STAIRS:7)
Block(2,64,8,WOOD_STAIRS:2)
Block(3,0,-4,STONE:6)
Block(3,0,-3,LOG:1)
Block(3,0,1,LOG:1)
Block(3,0,6,LOG:1)
Block(3,1,-4,STONE:6)
Block(3,1,-3,LOG:1)
Block(3,1,1,LOG:1)
Block(3,1,6,LOG:1)
Block(3,2,-4,STONE:6)
Block(3,2,-3,LOG:1)
Block(3,2,-2,LOG:9)
Block(3,2,-1,LOG:9)
Block(3,2,0,LOG:9)
Block(3,2,1,LOG:1)
Block(3,2,6,LOG:1)
Block(3,3,-4,STONE:6)
Block(3,3,-3,LOG:1)
Block(3,3,1,LOG:1)
Block(3,3,6,LOG:1)
Block(3,4,-4,STONE:6)
Block(3,4,-3,LOG:1)
Block(3,4,1,LOG:1)
Block(3,4,6,LOG:1)
Block(3,5,-4,STONE:6)
Block(3,5,-3,LOG:1)
Block(3,5,1,LOG:1)
Block(3,5,6,LOG:1)
Block(3,6,-4,STONE:6)
Block(3,6,-3,LOG:1)
Block(3,6,-2,LOG:9)
Block(3,6,-1,LOG:9)
Block(3,6,0,LOG:9)
Block(3,6,1,LOG:1)
Block(3,6,6,LOG:1)
Block(3,7,-4,STONE:6)
Block(3,7,-3,LOG:1)
Block(3,7,1,LOG:1)
Block(3,7,6,LOG:1)
Block(3,8,-4,STONE:6)
Block(3,8,-3,LOG:1)
Block(3,8,1,LOG:1)
Block(3,8,6,LOG:1)
Block(3,9,-4,STONE:6)
Block(3,9,-3,LOG:1)
Block(3,9,1,LOG:1)
Block(3,9,6,LOG:1)
Block(3,10,-4,STONE:6)
Block(3,10,-3,LOG:1)
Block(3,10,-2,LOG:9)
Block(3,10,-1,LOG:9)
Block(3,10,0,LOG:9)
Block(3,10,1,LOG:1)
Block(3,10,6,LOG:1)
Block(3,11,-4,STONE:6)
Block(3,11,-3,LOG:1)
Block(3,11,1,LOG:1)
Block(3,11,6,LOG:1)
Block(3,12,-4,STONE:6)
Block(3,12,-3,LOG:1)
Block(3,12,1,LOG:1)
Block(3,12,6,LOG:1)
Block(3,13,-4,STONE:6)
Block(3,13,-3,LOG:1)
Block(3,13,1,LOG:1)
Block(3,13,6,LOG:1)
Block(3,14,-4,STONE:6)
Block(3,14,-3,LOG:1)
Block(3,14,-2,LOG:9)
Block(3,14,-1,LOG:9)
Block(3,14,0,LOG:9)
Block(3,14,1,LOG:1)
Block(3,14,6,LOG:1)
Block(3,15,-4,STONE:6)
Block(3,15,-3,LOG:1)
Block(3,15,1,LOG:1)
Block(3,15,6,LOG:1)
Block(3,16,-4,STONE:6)
Block(3,16,-3,LOG:1)
Block(3,16,1,LOG:1)
Block(3,16,6,LOG:1)
Block(3,17,-4,STONE:6)
Block(3,17,-3,LOG:1)
Block(3,17,1,LOG:1)
Block(3,17,6,LOG:1)
Block(3,18,-4,STONE:6)
Block(3,18,-3,LOG:1)
Block(3,18,-2,LOG:9)
Block(3,18,-1,LOG:9)
Block(3,18,0,LOG:9)
Block(3,18,1,LOG:1)
Block(3,18,6,LOG:1)
Block(3,19,-4,STONE:6)
Block(3,19,-3,LOG:1)
Block(3,19,1,LOG:1)
Block(3,19,6,LOG:1)
Block(3,20,-4,STONE:6)
Block(3,20,-3,LOG:1)
Block(3,20,1,LOG:1)
Block(3,20,6,LOG:1)
Block(3,21,-4,STONE:6)
Block(3,21,-3,LOG:1)
Block(3,21,1,LOG:1)
Block(3,21,6,LOG:1)
Block(3,22,-4,STONE:6)
Block(3,22,-3,LOG:1)
Block(3,22,-2,LOG:9)
Block(3,22,-1,LOG:9)
Block(3,22,0,LOG:9)
Block(3,22,1,LOG:1)
Block(3,22,6,LOG:1)
Block(3,23,-4,STONE:6)
Block(3,23,-3,LOG:1)
Block(3,23,1,LOG:1)
Block(3,23,6,LOG:1)
Block(3,24,-4,STONE:6)
Block(3,24,-3,LOG:1)
Block(3,24,1,LOG:1)
Block(3,24,6,LOG:1)
Block(3,25,-4,STONE:6)
Block(3,25,-3,LOG:1)
Block(3,25,1,LOG:1)
Block(3,25,6,LOG:1)
Block(3,26,-4,STONE:6)
Block(3,26,-3,LOG:1)
Block(3,26,-2,LOG:9)
Block(3,26,-1,LOG:9)
Block(3,26,0,LOG:9)
Block(3,26,1,LOG:1)
Block(3,26,6,LOG:1)
Block(3,27,-4,STONE:6)
Block(3,27,-3,LOG:1)
Block(3,27,1,LOG:1)
Block(3,27,6,LOG:1)
Block(3,28,-4,STONE:6)
Block(3,28,-3,LOG:1)
Block(3,28,1,LOG:1)
Block(3,28,6,LOG:1)
Block(3,29,-4,STONE:6)
Block(3,29,-3,LOG:1)
Block(3,29,1,LOG:1)
Block(3,29,6,LOG:1)
Block(3,30,-4,STONE:6)
Block(3,30,-3,LOG:1)
Block(3,30,-2,LOG:9)
Block(3,30,-1,LOG:9)
Block(3,30,0,LOG:9)
Block(3,30,1,LOG:1)
Block(3,30,6,LOG:1)
Block(3,31,-4,STONE:6)
Block(3,31,-3,LOG:1)
Block(3,31,1,LOG:1)
Block(3,31,6,LOG:1)
Block(3,32,-4,STONE:6)
Block(3,32,-3,LOG:1)
Block(3,32,1,LOG:1)
Block(3,32,6,LOG:1)
Block(3,33,-4,STONE:6)
Block(3,33,-3,LOG:1)
Block(3,33,1,LOG:1)
Block(3,33,6,LOG:1)
Block(3,34,-4,STONE:6)
Block(3,34,-3,LOG:1)
Block(3,34,-2,LOG:9)
Block(3,34,-1,LOG:9)
Block(3,34,0,LOG:9)
Block(3,34,1,LOG:1)
Block(3,34,6,LOG:1)
Block(3,35,-4,STONE:6)
Block(3,35,-3,LOG:1)
Block(3,35,1,LOG:1)
Block(3,35,6,LOG:1)
Block(3,36,-4,STONE:6)
Block(3,36,-3,LOG:1)
Block(3,36,1,LOG:1)
Block(3,36,6,LOG:1)
Block(3,37,-4,STONE:6)
Block(3,37,-3,LOG:1)
Block(3,37,1,LOG:1)
Block(3,37,6,LOG:1)
Block(3,38,-4,STONE:6)
Block(3,38,-3,LOG:1)
Block(3,38,-2,LOG:9)
Block(3,38,-1,LOG:9)
Block(3,38,0,LOG:9)
Block(3,38,1,LOG:1)
Block(3,38,6,LOG:1)
Block(3,39,-4,STONE:6)
Block(3,39,-3,LOG:1)
Block(3,39,1,LOG:1)
Block(3,39,6,LOG:1)
Block(3,40,-4,STONE:6)
Block(3,40,-3,LOG:1)
Block(3,40,1,LOG:1)
Block(3,40,6,LOG:1)
Block(3,41,-4,STONE:6)
Block(3,41,-3,LOG:1)
Block(3,41,1,LOG:1)
Block(3,41,6,LOG:1)
Block(3,42,-4,STONE:6)
Block(3,42,-3,LOG:1)
Block(3,42,-2,LOG:9)
Block(3,42,-1,LOG:9)
Block(3,42,0,LOG:9)
Block(3,42,1,LOG:1)
Block(3,42,6,LOG:1)
Block(3,43,-4,STONE:6)
Block(3,43,-3,LOG:1)
Block(3,43,1,LOG:1)
Block(3,43,6,LOG:1)
Block(3,44,-4,STONE:6)
Block(3,44,-3,LOG:1)
Block(3,44,1,LOG:1)
Block(3,44,6,LOG:1)
Block(3,45,-4,STONE:6)
Block(3,45,-3,LOG:1)
Block(3,45,1,LOG:1)
Block(3,45,6,LOG:1)
Block(3,46,-4,STONE:6)
Block(3,46,-3,LOG:1)
Block(3,46,-2,LOG:9)
Block(3,46,-1,LOG:9)
Block(3,46,0,LOG:9)
Block(3,46,1,LOG:1)
Block(3,46,6,LOG:1)
Block(3,47,-4,STONE:6)
Block(3,47,-3,LOG:1)
Block(3,47,1,LOG:1)
Block(3,47,6,LOG:1)
Block(3,48,-4,STONE:6)
Block(3,48,-3,LOG:1)
Block(3,48,1,LOG:1)
Block(3,48,6,LOG:1)
Block(3,49,-4,STONE:6)
Block(3,49,-3,LOG:1)
Block(3,49,1,LOG:1)
Block(3,49,6,LOG:1)
Block(3,50,-7,LOG:5)
Block(3,50,-4,SMOOTH_STAIRS:2)
Block(3,50,-3,LOG:1)
Block(3,50,-2,LOG:9)
Block(3,50,-1,LOG:9)
Block(3,50,0,LOG:9)
Block(3,50,1,LOG:1)
Block(3,50,6,LOG:1)
Block(3,51,-4,SMOOTH_STAIRS:6)
Block(3,51,-3,LOG:1)
Block(3,51,-2,WOOD_STEP:5)
Block(3,51,-1,WOOD_STEP:5)
Block(3,51,0,WOOD_STEP:5)
Block(3,51,1,LOG:1)
Block(3,51,6,LOG:1)
Block(3,52,-7,LOG:5)
Block(3,52,-4,STONE:6)
Block(3,52,-3,LOG:1)
Block(3,52,-2,STEP:0)
Block(3,52,-1,STEP:0)
Block(3,52,0,STEP:0)
Block(3,52,1,LOG:1)
Block(3,52,3,WOOD_STEP:8)
Block(3,52,5,WOOD_STEP:8)
Block(3,52,6,LOG:1)
Block(3,52,7,LOG:9)
Block(3,52,8,LOG:9)
Block(3,53,-7,HAY_BLOCK:0)
Block(3,53,-4,SMOOTH_STAIRS:2)
Block(3,53,-3,SMOOTH_STAIRS:3)
Block(3,53,1,LOG:1)
Block(3,53,2,LOG:9)
Block(3,53,3,LOG:9)
Block(3,53,4,LOG:9)
Block(3,53,5,LOG:9)
Block(3,53,6,LOG:1)
Block(3,53,7,COBBLESTONE:0)
Block(3,53,8,COBBLESTONE:0)
Block(3,54,-7,HAY_BLOCK:0)
Block(3,54,-4,STEP:0)
Block(3,54,-3,STEP:0)
Block(3,54,1,SMOOTH_STAIRS:0)
Block(3,54,2,SPRUCE_FENCE:0)
Block(3,54,3,SPRUCE_FENCE:0)
Block(3,54,4,SPRUCE_FENCE:0)
Block(3,54,5,SPRUCE_FENCE:0)
Block(3,54,6,LOG:1)
Block(3,54,7,WOOD:1)
Block(3,54,8,WOOD:1)
Block(3,55,1,STEP:0)
Block(3,55,6,LOG:1)
Block(3,55,7,LOG:9)
Block(3,55,8,LOG:9)
Block(3,56,6,LOG:1)
Block(3,56,7,COBBLESTONE:0)
Block(3,57,6,LOG:1)
Block(3,57,7,COBBLESTONE:0)
Block(3,58,5,SPRUCE_WOOD_STAIRS:6)
Block(3,58,6,LOG:1)
Block(3,58,7,LOG:9)
Block(3,58,8,LOG:9)
Block(3,59,5,WOOD_STEP:1)
Block(3,59,6,LOG:1)
Block(3,59,7,COBBLESTONE:0)
Block(3,59,8,COBBLESTONE:0)
Block(3,60,6,LOG:1)
Block(3,60,7,WOOD:1)
Block(3,60,8,WOOD:1)
Block(3,61,5,WOOD_STAIRS:2)
Block(3,61,6,LOG:1)
Block(3,61,7,LOG:9)
Block(3,61,8,LOG:9)
Block(3,62,6,SPRUCE_WOOD_STAIRS:2)
Block(3,62,7,WOOD:1)
Block(3,62,8,WOOD:1)
Block(3,63,7,SPRUCE_WOOD_STAIRS:2)
Block(3,63,8,WOOD:1)
Block(3,64,8,SPRUCE_WOOD_STAIRS:2)
Block(4,0,-7,LOG:1)
Block(4,1,-7,LOG:1)
Block(4,2,-7,LOG:1)
Block(4,2,6,LOG:5)
Block(4,3,-7,LOG:1)
Block(4,3,-3,LOG:5)
Block(4,3,1,LOG:5)
Block(4,4,-7,LOG:1)
Block(4,5,-7,LOG:1)
Block(4,6,-7,LOG:1)
Block(4,6,6,LOG:5)
Block(4,7,-7,LOG:1)
Block(4,7,-3,LOG:5)
Block(4,7,1,LOG:5)
Block(4,8,-7,LOG:1)
Block(4,9,-7,LOG:1)
Block(4,10,-7,LOG:1)
Block(4,10,6,LOG:5)
Block(4,11,-7,LOG:1)
Block(4,11,-3,LOG:5)
Block(4,11,1,LOG:5)
Block(4,12,-7,LOG:1)
Block(4,13,-7,LOG:1)
Block(4,14,-7,LOG:1)
Block(4,14,6,LOG:5)
Block(4,15,-7,LOG:1)
Block(4,15,-3,LOG:5)
Block(4,15,1,LOG:5)
Block(4,16,-7,LOG:1)
Block(4,17,-7,LOG:1)
Block(4,18,-7,LOG:1)
Block(4,18,6,LOG:5)
Block(4,19,-7,LOG:1)
Block(4,19,-3,LOG:5)
Block(4,19,1,LOG:5)
Block(4,20,-7,LOG:1)
Block(4,21,-7,LOG:1)
Block(4,22,-7,LOG:1)
Block(4,22,6,LOG:5)
Block(4,23,-7,LOG:1)
Block(4,23,-3,LOG:5)
Block(4,23,1,LOG:5)
Block(4,24,-7,LOG:1)
Block(4,25,-7,LOG:1)
Block(4,26,-7,LOG:1)
Block(4,26,6,LOG:5)
Block(4,27,-7,LOG:1)
Block(4,27,-3,LOG:5)
Block(4,27,1,LOG:5)
Block(4,28,-7,LOG:1)
Block(4,29,-7,LOG:1)
Block(4,30,-7,LOG:1)
Block(4,30,6,LOG:5)
Block(4,31,-7,LOG:1)
Block(4,31,-3,LOG:5)
Block(4,31,1,LOG:5)
Block(4,32,-7,LOG:1)
Block(4,33,-7,LOG:1)
Block(4,34,-7,LOG:1)
Block(4,34,6,LOG:5)
Block(4,35,-7,LOG:1)
Block(4,35,-3,LOG:5)
Block(4,35,1,LOG:5)
Block(4,36,-7,LOG:1)
Block(4,37,-7,LOG:1)
Block(4,38,-7,LOG:1)
Block(4,38,6,LOG:5)
Block(4,39,-7,LOG:1)
Block(4,39,-3,LOG:5)
Block(4,39,1,LOG:5)
Block(4,40,-7,LOG:1)
Block(4,41,-7,LOG:1)
Block(4,42,-7,LOG:1)
Block(4,42,6,LOG:5)
Block(4,43,-7,LOG:1)
Block(4,43,-3,LOG:5)
Block(4,43,1,LOG:5)
Block(4,44,-7,LOG:1)
Block(4,45,-7,LOG:1)
Block(4,46,-7,LOG:1)
Block(4,46,6,LOG:5)
Block(4,47,-7,LOG:1)
Block(4,47,-3,LOG:5)
Block(4,47,1,LOG:5)
Block(4,48,-7,LOG:1)
Block(4,48,-3,LOG:5)
Block(4,48,1,LOG:5)
Block(4,49,-7,LOG:1)
Block(4,50,-7,LOG:1)
Block(4,50,-4,WOOD_BUTTON:4)
Block(4,50,-3,LOG:5)
Block(4,50,1,LOG:5)
Block(4,51,-7,LOG:1)
Block(4,51,-4,WOOD_STEP:13)
Block(4,51,-3,WOOD_STEP:5)
Block(4,51,1,WOOD_STEP:5)
Block(4,52,-7,LOG:1)
Block(4,52,-4,STEP:0)
Block(4,52,-3,LOG:5)
Block(4,52,-2,STEP:0)
Block(4,52,-1,STEP:0)
Block(4,52,0,STEP:0)
Block(4,52,1,LOG:5)
Block(4,52,2,WOOD_STEP:13)
Block(4,52,3,WOOD_STEP:13)
Block(4,52,4,WOOD_STEP:13)
Block(4,52,5,WOOD_STEP:13)
Block(4,52,6,LOG:5)
Block(4,52,7,WOOD_STEP:8)
Block(4,52,8,WOOD_STEP:8)
Block(4,53,-7,LOG:1)
Block(4,53,-3,SPRUCE_FENCE:0)
Block(4,53,1,STONE:6)
Block(4,53,2,STEP:0)
Block(4,53,3,STEP:0)
Block(4,53,4,STEP:0)
Block(4,53,5,STEP:0)
Block(4,53,6,COBBLESTONE:0)
Block(4,53,7,BED_BLOCK:9)
RandomBlock(4,53,8,AIR:0,20,CHEST:5,../../../../Chests/Loot/FishingChest1.nbt,10,CHEST:5,../../../../Chests/Loot/JunkChest_2.nbt,10,CHEST:5,../../../../Chests/Loot/FishingChest2.nbt,10,CHEST:5,../../../../Chests/Loot/JunkChest_4.nbt,10,CHEST:5,../../../../Chests/Loot/JunkChest_5.nbt,10,CHEST:5,../../../../Chests/Lore/Harbor_1.nbt,1,CHEST:5,../../../../Chests/Lore/Harbor_2.nbt,1,CHEST:5,../../../../Chests/Lore/Harbor_3.nbt,1,CHEST:5,../../../../Chests/Lore/Harbor_4.nbt,1,CHEST:5,../../../../Chests/Lore/Harbor_5.nbt,1,CHEST:5,../../../../Chests/Loot/Common1.nbt,10,CHEST:5,../../../../Chests/Loot/Common2.nbt,10,CHEST:5,../../../../Chests/Loot/Common3.nbt,10,CHEST:5,../../../../Chests/Loot/Common4.nbt,10,CHEST:5,../../../../Chests/Loot/Common5.nbt,10,CHEST:5,../../../../Chests/Loot/Common6.nbt,10,CHEST:5,../../../../Chests/Loot/Common7.nbt,10,CHEST:5,../../../../Chests/Loot/Common8.nbt,10,CHEST:5,../../../../Chests/Loot/Common9.nbt,10,CHEST:5,../../../../Chests/Loot/Common10.nbt,10,CHEST:5,../../../../Chests/Loot/Common10.nbt,11,CHEST:5,../../../../Chests/Loot/Common12.nbt,10,CHEST:5,../../../../Chests/Loot/Common13.nbt,10,CHEST:5,../../../../Chests/Loot/Common14.nbt,10,CHEST:5,../../../../Chests/Loot/Common15.nbt,10,CHEST:5,../../../../Chests/Lore/Harbor_1.nbt,2,CHEST:5,../../../../Chests/Lore/Harbor_3.nbt,2,CHEST:5,../../../../Chests/Lore/Harbor_4.nbt,2,CHEST:5,../../../../Chests/Lore/Harbor_5.nbt,2,CHEST:5,../../../../Chests/Lore/Harbor_5.nbt,2,CHEST:5,../../../../Chests/Loot/Rare1.nbt,5,CHEST:5,../../../../Chests/Loot/Rare2.nbt,5,CHEST:5,../../../../Chests/Loot/Rare3.nbt,5,CHEST:5,../../../../Chests/Loot/Rare4.nbt,5,CHEST:5,../../../../Chests/Loot/Rare5.nbt,5,CHEST:5,../../../../Chests/Loot/Rare6.nbt,5,CHEST:5,../../../../Chests/Loot/Rare7.nbt,5,CHEST:5,../../../../Chests/Loot/Rare8.nbt,5,CHEST:5,../../../../Chests/Loot/Rare9.nbt,5,CHEST:5,../../../../Chests/Loot/Rare10.nbt,5,CHEST:5,../../../../Chests/Loot/Rare11.nbt,5,CHEST:5,../../../../Chests/Loot/Rare12.nbt,5,CHEST:5,../../../../Chests/Loot/Rare13.nbt,5,CHEST:5,../../../../Chests/Loot/Rare14.nbt,5,CHEST:5,../../../../Chests/Loot/Rare15.nbt,5,CHEST:5,../../../../Chests/Loot/Epic1.nbt,2,CHEST:5,../../../../Chests/Loot/Epic2.nbt,2,CHEST:5,../../../../Chests/Loot/Epic3.nbt,2,CHEST:5,../../../../Chests/Loot/Epic4.nbt,2,CHEST:5,../../../../Chests/Loot/Epic5.nbt,2,CHEST:5,../../../../Chests/Loot/Epic6.nbt,2,CHEST:5,../../../../Chests/Loot/Epic7.nbt,2,CHEST:5,../../../../Chests/Loot/Epic8.nbt,2,CHEST:5,../../../../Chests/Loot/Epic9.nbt,2,CHEST:5,../../../../Chests/Loot/Epic10.nbt,2,CHEST:5,../../../../Chests/Loot/Epic11.nbt,2,CHEST:5,../../../../Chests/Loot/Epic12.nbt,2,CHEST:5,../../../../Chests/Loot/Epic13.nbt,2,CHEST:5,../../../../Chests/Loot/Epic14.nbt,2,CHEST:5,../../../../Chests/Loot/Epic15.nbt,5,CHEST:5,../../../../Chests/Loot/Rare1.nbt,5,CHEST:5,../../../../Chests/Loot/Rare2.nbt,5,CHEST:5,../../../../Chests/Loot/Rare3.nbt,5,CHEST:5,../../../../Chests/Loot/Rare4.nbt,5,CHEST:5,../../../../Chests/Loot/Rare5.nbt,10,CHEST:5,../../../../Chests/Loot/Rare6.nbt,10,CHEST:5,../../../../Chests/Loot/Rare7.nbt,10,CHEST:5,../../../../Chests/Loot/Rare8.nbt,10,CHEST:5,../../../../Chests/Loot/Rare9.nbt,10,CHEST:5,../../../../Chests/Loot/Rare10.nbt,15,CHEST:5,../../../../Chests/Loot/Rare11.nbt,15,CHEST:5,../../../../Chests/Loot/Rare12.nbt,15,CHEST:5,../../../../Chests/Loot/Rare13.nbt,15,CHEST:5,../../../../Chests/Loot/Rare14.nbt,15,CHEST:5,../../../../Chests/Loot/Rare15.nbt,15,CHEST:5,../../../../Chests/Loot/Epic15.nbt,100)
Block(4,54,-7,STEP:0)
Block(4,54,1,SMOOTH_STAIRS:1)
Block(4,54,6,WOOD:1)
Block(4,55,1,STEP:0)
Block(4,55,6,LOG:5)
Block(4,55,7,WOOD_STEP:8)
Block(4,55,8,WOOD_STEP:8)
Block(4,56,6,COBBLESTONE:0)
Block(4,57,6,WOOD:1)
Block(4,58,5,WOOD_STEP:9)
Block(4,58,6,LOG:5)
Block(4,58,7,WOOD_STEP:8)
Block(4,58,8,WOOD_STEP:8)
Block(4,59,5,SPRUCE_FENCE:0)
Block(4,59,6,COBBLESTONE:0)
Block(4,59,7,BED_BLOCK:10)
Block(4,59,8,BED_BLOCK:2)
Block(4,60,6,WOOD:1)
Block(4,61,5,WOOD_STAIRS:2)
Block(4,61,6,LOG:5)
Block(4,61,7,WOOD_STEP:8)
Block(4,61,8,WOOD_STEP:8)
Block(4,62,6,SPRUCE_WOOD_STAIRS:2)
Block(4,62,7,WOOD:1)
Block(4,62,8,BOOKSHELF:0)
Block(4,63,7,SPRUCE_WOOD_STAIRS:2)
Block(4,63,8,BOOKSHELF:0)
Block(4,64,8,SPRUCE_WOOD_STAIRS:2)
Block(5,2,6,LOG:5)
Block(5,3,-3,LOG:5)
Block(5,3,1,LOG:5)
Block(5,6,6,LOG:5)
Block(5,7,-3,LOG:5)
Block(5,7,1,LOG:5)
Block(5,10,6,LOG:5)
Block(5,11,-3,LOG:5)
Block(5,11,1,LOG:5)
Block(5,14,6,LOG:5)
Block(5,15,-3,LOG:5)
Block(5,15,1,LOG:5)
Block(5,18,6,LOG:5)
Block(5,19,-3,LOG:5)
Block(5,19,1,LOG:5)
Block(5,22,6,LOG:5)
Block(5,23,-3,LOG:5)
Block(5,23,1,LOG:5)
Block(5,26,6,LOG:5)
Block(5,27,-3,LOG:5)
Block(5,27,1,LOG:5)
Block(5,30,6,LOG:5)
Block(5,31,-3,LOG:5)
Block(5,31,1,LOG:5)
Block(5,34,6,LOG:5)
Block(5,35,-3,LOG:5)
Block(5,35,1,LOG:5)
Block(5,38,6,LOG:5)
Block(5,39,-3,LOG:5)
Block(5,39,1,LOG:5)
Block(5,42,6,LOG:5)
Block(5,43,-3,LOG:5)
Block(5,43,1,LOG:5)
Block(5,46,6,LOG:5)
Block(5,47,-3,LOG:5)
Block(5,47,1,LOG:5)
Block(5,48,-3,LOG:5)
Block(5,48,1,LOG:5)
Block(5,50,-7,WOOD_BUTTON:1)
Block(5,50,-4,WOOD_BUTTON:4)
Block(5,50,-3,LOG:5)
Block(5,50,1,LOG:5)
Block(5,51,-4,WOOD_STEP:13)
Block(5,51,-3,WOOD_STEP:5)
Block(5,51,1,WOOD_STEP:5)
Block(5,52,-4,STEP:0)
Block(5,52,-3,LOG:5)
Block(5,52,-2,STEP:0)
Block(5,52,-1,STEP:0)
Block(5,52,0,STEP:0)
Block(5,52,1,LOG:5)
Block(5,52,6,LOG:5)
Block(5,52,7,WOOD_STEP:8)
Block(5,52,8,WOOD_STEP:8)
Block(5,53,-3,SPRUCE_FENCE:0)
Block(5,53,1,SPRUCE_FENCE:0)
Block(5,53,6,COBBLESTONE:0)
Block(5,53,7,BED_BLOCK:1)
Block(5,54,6,WOOD:1)
Block(5,55,6,LOG:5)
Block(5,55,7,WOOD_STEP:8)
Block(5,55,8,WOOD_STEP:8)
Block(5,56,6,COBBLESTONE:0)
Block(5,57,6,WOOD:1)
Block(5,58,5,WOOD_STEP:9)
Block(5,58,6,LOG:5)
Block(5,58,7,WOOD_STEP:8)
Block(5,58,8,WOOD_STEP:8)
Block(5,59,5,SPRUCE_FENCE:0)
Block(5,59,6,COBBLESTONE:0)
RandomBlock(5,59,7,AIR:0,20,CHEST:3,../../../../Chests/Loot/FishingChest1.nbt,10,CHEST:3,../../../../Chests/Loot/JunkChest_2.nbt,10,CHEST:3,../../../../Chests/Loot/FishingChest2.nbt,10,CHEST:3,../../../../Chests/Loot/JunkChest_4.nbt,10,CHEST:3,../../../../Chests/Loot/JunkChest_5.nbt,10,CHEST:3,../../../../Chests/Lore/Harbor_1.nbt,1,CHEST:3,../../../../Chests/Lore/Harbor_2.nbt,1,CHEST:3,../../../../Chests/Lore/Harbor_3.nbt,1,CHEST:3,../../../../Chests/Lore/Harbor_4.nbt,1,CHEST:3,../../../../Chests/Lore/Harbor_5.nbt,1,CHEST:3,../../../../Chests/Loot/Common1.nbt,10,CHEST:3,../../../../Chests/Loot/Common2.nbt,10,CHEST:3,../../../../Chests/Loot/Common3.nbt,10,CHEST:3,../../../../Chests/Loot/Common4.nbt,10,CHEST:3,../../../../Chests/Loot/Common5.nbt,10,CHEST:3,../../../../Chests/Loot/Common6.nbt,10,CHEST:3,../../../../Chests/Loot/Common7.nbt,10,CHEST:3,../../../../Chests/Loot/Common8.nbt,10,CHEST:3,../../../../Chests/Loot/Common9.nbt,10,CHEST:3,../../../../Chests/Loot/Common10.nbt,10,CHEST:3,../../../../Chests/Loot/Common10.nbt,11,CHEST:3,../../../../Chests/Loot/Common12.nbt,10,CHEST:3,../../../../Chests/Loot/Common13.nbt,10,CHEST:3,../../../../Chests/Loot/Common14.nbt,10,CHEST:3,../../../../Chests/Loot/Common15.nbt,10,CHEST:3,../../../../Chests/Lore/Harbor_1.nbt,2,CHEST:3,../../../../Chests/Lore/Harbor_3.nbt,2,CHEST:3,../../../../Chests/Lore/Harbor_4.nbt,2,CHEST:3,../../../../Chests/Lore/Harbor_5.nbt,2,CHEST:3,../../../../Chests/Lore/Harbor_5.nbt,2,CHEST:3,../../../../Chests/Loot/Rare1.nbt,5,CHEST:3,../../../../Chests/Loot/Rare2.nbt,5,CHEST:3,../../../../Chests/Loot/Rare3.nbt,5,CHEST:3,../../../../Chests/Loot/Rare4.nbt,5,CHEST:3,../../../../Chests/Loot/Rare5.nbt,5,CHEST:3,../../../../Chests/Loot/Rare6.nbt,5,CHEST:3,../../../../Chests/Loot/Rare7.nbt,5,CHEST:3,../../../../Chests/Loot/Rare8.nbt,5,CHEST:3,../../../../Chests/Loot/Rare9.nbt,5,CHEST:3,../../../../Chests/Loot/Rare10.nbt,5,CHEST:3,../../../../Chests/Loot/Rare11.nbt,5,CHEST:3,../../../../Chests/Loot/Rare12.nbt,5,CHEST:3,../../../../Chests/Loot/Rare13.nbt,5,CHEST:3,../../../../Chests/Loot/Rare14.nbt,5,CHEST:3,../../../../Chests/Loot/Rare15.nbt,5,CHEST:3,../../../../Chests/Loot/Epic1.nbt,2,CHEST:3,../../../../Chests/Loot/Epic2.nbt,2,CHEST:3,../../../../Chests/Loot/Epic3.nbt,2,CHEST:3,../../../../Chests/Loot/Epic4.nbt,2,CHEST:3,../../../../Chests/Loot/Epic5.nbt,2,CHEST:3,../../../../Chests/Loot/Epic6.nbt,2,CHEST:3,../../../../Chests/Loot/Epic7.nbt,2,CHEST:3,../../../../Chests/Loot/Epic8.nbt,2,CHEST:3,../../../../Chests/Loot/Epic9.nbt,2,CHEST:3,../../../../Chests/Loot/Epic10.nbt,2,CHEST:3,../../../../Chests/Loot/Epic11.nbt,2,CHEST:3,../../../../Chests/Loot/Epic12.nbt,2,CHEST:3,../../../../Chests/Loot/Epic13.nbt,2,CHEST:3,../../../../Chests/Loot/Epic14.nbt,2,CHEST:3,../../../../Chests/Loot/Epic15.nbt,5,CHEST:3,../../../../Chests/Loot/Rare1.nbt,5,CHEST:3,../../../../Chests/Loot/Rare2.nbt,5,CHEST:3,../../../../Chests/Loot/Rare3.nbt,5,CHEST:3,../../../../Chests/Loot/Rare4.nbt,5,CHEST:3,../../../../Chests/Loot/Rare5.nbt,10,CHEST:3,../../../../Chests/Loot/Rare6.nbt,10,CHEST:3,../../../../Chests/Loot/Rare7.nbt,10,CHEST:3,../../../../Chests/Loot/Rare8.nbt,10,CHEST:3,../../../../Chests/Loot/Rare9.nbt,10,CHEST:3,../../../../Chests/Loot/Rare10.nbt,15,CHEST:3,../../../../Chests/Loot/Rare11.nbt,15,CHEST:3,../../../../Chests/Loot/Rare12.nbt,15,CHEST:3,../../../../Chests/Loot/Rare13.nbt,15,CHEST:3,../../../../Chests/Loot/Rare14.nbt,15,CHEST:3,../../../../Chests/Loot/Rare15.nbt,15,CHEST:3,../../../../Chests/Loot/Epic15.nbt,100)
Block(5,59,8,CARPET:14)
Block(5,60,6,DARK_OAK_FENCE:0)
Block(5,61,5,WOOD_STAIRS:2)
Block(5,61,6,LOG:5)
Block(5,61,7,WOOD_STEP:8)
Block(5,61,8,WOOD_STEP:8)
Block(5,62,6,SPRUCE_WOOD_STAIRS:2)
Block(5,62,7,WOOD:1)
Block(5,62,8,DARK_OAK_STAIRS:5)
Block(5,63,7,SPRUCE_WOOD_STAIRS:2)
Block(5,64,8,SPRUCE_WOOD_STAIRS:2)
Block(6,2,6,LOG:5)
Block(6,3,-3,LOG:5)
Block(6,3,1,LOG:5)
Block(6,6,6,LOG:5)
Block(6,7,-3,LOG:5)
Block(6,7,1,LOG:5)
Block(6,10,6,LOG:5)
Block(6,11,-3,LOG:5)
Block(6,11,1,LOG:5)
Block(6,14,6,LOG:5)
Block(6,15,-3,LOG:5)
Block(6,15,1,LOG:5)
Block(6,18,6,LOG:5)
Block(6,19,-3,LOG:5)
Block(6,19,1,LOG:5)
Block(6,22,6,LOG:5)
Block(6,23,-3,LOG:5)
Block(6,23,1,LOG:5)
Block(6,26,6,LOG:5)
Block(6,27,-3,LOG:5)
Block(6,27,1,LOG:5)
Block(6,30,6,LOG:5)
Block(6,31,-3,LOG:5)
Block(6,31,1,LOG:5)
Block(6,34,6,LOG:5)
Block(6,35,-3,LOG:5)
Block(6,35,1,LOG:5)
Block(6,38,6,LOG:5)
Block(6,39,-3,LOG:5)
Block(6,39,1,LOG:5)
Block(6,42,6,LOG:5)
Block(6,43,-3,LOG:5)
Block(6,43,1,LOG:5)
Block(6,46,6,LOG:5)
Block(6,47,-3,LOG:5)
Block(6,47,1,LOG:5)
Block(6,48,-3,LOG:5)
Block(6,48,1,LOG:5)
Block(6,50,-4,WOOD_BUTTON:4)
Block(6,50,-3,LOG:5)
Block(6,50,1,LOG:5)
Block(6,51,-4,WOOD_STEP:13)
Block(6,51,-3,WOOD_STEP:5)
Block(6,51,-2,WOOD_STEP:8)
Block(6,51,-1,WOOD_STEP:8)
Block(6,51,0,WOOD_STEP:8)
Block(6,51,1,WOOD_STEP:5)
Block(6,52,-4,STEP:0)
Block(6,52,-3,LOG:5)
Block(6,52,-2,STEP:0)
Block(6,52,-1,STEP:0)
Block(6,52,0,STEP:0)
Block(6,52,1,LOG:5)
Block(6,52,6,LOG:5)
Block(6,52,7,WOOD_STEP:8)
Block(6,52,8,WOOD_STEP:8)
Block(6,53,-3,SPRUCE_FENCE:0)
Block(6,53,1,SPRUCE_FENCE:0)
Block(6,53,6,COBBLESTONE:0)
Block(6,54,6,WOOD:1)
Block(6,55,6,LOG:5)
Block(6,55,7,WOOD_STEP:8)
Block(6,55,8,WOOD_STEP:8)
Block(6,56,6,COBBLESTONE:0)
Block(6,56,7,WOOD:1)
Block(6,56,8,DARK_OAK_DOOR:2)
Block(6,57,6,WOOD:1)
Block(6,57,7,WOOD:1)
Block(6,57,8,DARK_OAK_DOOR:8)
Block(6,58,5,WOOD_STEP:9)
Block(6,58,6,LOG:5)
Block(6,58,7,LOG:9)
Block(6,58,8,LOG:9)
Block(6,59,5,SPRUCE_FENCE:0)
Block(6,59,6,COBBLESTONE:0)
Block(6,59,7,BED_BLOCK:10)
Block(6,59,8,BED_BLOCK:2)
Block(6,60,6,WOOD:1)
Block(6,61,5,WOOD_STAIRS:2)
Block(6,61,6,LOG:5)
Block(6,61,7,WOOD_STEP:8)
Block(6,61,8,WOOD_STEP:8)
Block(6,62,6,SPRUCE_WOOD_STAIRS:2)
Block(6,62,7,WOOD:1)
Block(6,62,8,WOOD_STEP:13)
Block(6,63,7,SPRUCE_WOOD_STAIRS:2)
Block(6,63,8,CARPET:0)
Block(6,64,8,SPRUCE_WOOD_STAIRS:2)
Block(7,0,-4,STONE:6)
Block(7,0,-3,LOG:1)
Block(7,0,1,LOG:1)
Block(7,0,2,STONE:6)
Block(7,0,4,LOG:1)
Block(7,0,6,LOG:1)
Block(7,1,-4,STONE:6)
Block(7,1,-3,LOG:1)
Block(7,1,-2,LOG:9)
Block(7,1,-1,LOG:9)
Block(7,1,0,LOG:9)
Block(7,1,1,LOG:1)
Block(7,1,2,STONE:6)
Block(7,1,4,LOG:1)
Block(7,1,6,LOG:1)
Block(7,2,-4,STONE:6)
Block(7,2,-3,LOG:1)
Block(7,2,1,LOG:1)
Block(7,2,2,STONE:6)
Block(7,2,4,LOG:1)
Block(7,2,6,LOG:1)
Block(7,2,7,LOG:9)
Block(7,2,8,LOG:9)
Block(7,3,-4,STONE:6)
Block(7,3,-3,LOG:1)
Block(7,3,1,LOG:1)
Block(7,3,2,STONE:6)
Block(7,3,4,LOG:1)
Block(7,3,5,LOG:9)
Block(7,3,6,LOG:1)
Block(7,4,-4,STONE:6)
Block(7,4,-3,LOG:1)
Block(7,4,1,LOG:1)
Block(7,4,2,STONE:6)
Block(7,4,4,LOG:1)
Block(7,4,6,LOG:1)
Block(7,5,-4,STONE:6)
Block(7,5,-3,LOG:1)
Block(7,5,-2,LOG:9)
Block(7,5,-1,LOG:9)
Block(7,5,0,LOG:9)
Block(7,5,1,LOG:1)
Block(7,5,2,STONE:6)
Block(7,5,4,LOG:1)
Block(7,5,6,LOG:1)
Block(7,6,-4,STONE:6)
Block(7,6,-3,LOG:1)
Block(7,6,1,LOG:1)
Block(7,6,2,STONE:6)
Block(7,6,4,LOG:1)
Block(7,6,6,LOG:1)
Block(7,6,7,LOG:9)
Block(7,6,8,LOG:9)
Block(7,7,-4,STONE:6)
Block(7,7,-3,LOG:1)
Block(7,7,1,LOG:1)
Block(7,7,2,STONE:6)
Block(7,7,4,LOG:1)
Block(7,7,5,LOG:9)
Block(7,7,6,LOG:1)
Block(7,8,-4,STONE:6)
Block(7,8,-3,LOG:1)
Block(7,8,1,LOG:1)
Block(7,8,2,STONE:6)
Block(7,8,4,LOG:1)
Block(7,8,6,LOG:1)
Block(7,9,-4,STONE:6)
Block(7,9,-3,LOG:1)
Block(7,9,-2,LOG:9)
Block(7,9,-1,LOG:9)
Block(7,9,0,LOG:9)
Block(7,9,1,LOG:1)
Block(7,9,2,STONE:6)
Block(7,9,4,LOG:1)
Block(7,9,6,LOG:1)
Block(7,10,-4,STONE:6)
Block(7,10,-3,LOG:1)
Block(7,10,1,LOG:1)
Block(7,10,2,STONE:6)
Block(7,10,4,LOG:1)
Block(7,10,6,LOG:1)
Block(7,10,7,LOG:9)
Block(7,10,8,LOG:9)
Block(7,11,-4,STONE:6)
Block(7,11,-3,LOG:1)
Block(7,11,1,LOG:1)
Block(7,11,2,STONE:6)
Block(7,11,4,LOG:1)
Block(7,11,5,LOG:9)
Block(7,11,6,LOG:1)
Block(7,12,-4,STONE:6)
Block(7,12,-3,LOG:1)
Block(7,12,1,LOG:1)
Block(7,12,2,STONE:6)
Block(7,12,4,LOG:1)
Block(7,12,6,LOG:1)
Block(7,13,-4,STONE:6)
Block(7,13,-3,LOG:1)
Block(7,13,-2,LOG:9)
Block(7,13,-1,LOG:9)
Block(7,13,0,LOG:9)
Block(7,13,1,LOG:1)
Block(7,13,2,STONE:6)
Block(7,13,4,LOG:1)
Block(7,13,6,LOG:1)
Block(7,14,-4,STONE:6)
Block(7,14,-3,LOG:1)
Block(7,14,1,LOG:1)
Block(7,14,2,STONE:6)
Block(7,14,4,LOG:1)
Block(7,14,6,LOG:1)
Block(7,14,7,LOG:9)
Block(7,14,8,LOG:9)
Block(7,15,-4,STONE:6)
Block(7,15,-3,LOG:1)
Block(7,15,1,LOG:1)
Block(7,15,2,STONE:6)
Block(7,15,4,LOG:1)
Block(7,15,5,LOG:9)
Block(7,15,6,LOG:1)
Block(7,16,-4,STONE:6)
Block(7,16,-3,LOG:1)
Block(7,16,1,LOG:1)
Block(7,16,2,STONE:6)
Block(7,16,4,LOG:1)
Block(7,16,6,LOG:1)
Block(7,17,-4,STONE:6)
Block(7,17,-3,LOG:1)
Block(7,17,-2,LOG:9)
Block(7,17,-1,LOG:9)
Block(7,17,0,LOG:9)
Block(7,17,1,LOG:1)
Block(7,17,2,STONE:6)
Block(7,17,4,LOG:1)
Block(7,17,6,LOG:1)
Block(7,18,-4,STONE:6)
Block(7,18,-3,LOG:1)
Block(7,18,1,LOG:1)
Block(7,18,2,STONE:6)
Block(7,18,4,LOG:1)
Block(7,18,6,LOG:1)
Block(7,18,7,LOG:9)
Block(7,18,8,LOG:9)
Block(7,19,-4,STONE:6)
Block(7,19,-3,LOG:1)
Block(7,19,1,LOG:1)
Block(7,19,2,STONE:6)
Block(7,19,4,LOG:1)
Block(7,19,5,LOG:9)
Block(7,19,6,LOG:1)
Block(7,20,-4,STONE:6)
Block(7,20,-3,LOG:1)
Block(7,20,1,LOG:1)
Block(7,20,2,STONE:6)
Block(7,20,4,LOG:1)
Block(7,20,6,LOG:1)
Block(7,21,-4,STONE:6)
Block(7,21,-3,LOG:1)
Block(7,21,-2,LOG:9)
Block(7,21,-1,LOG:9)
Block(7,21,0,LOG:9)
Block(7,21,1,LOG:1)
Block(7,21,2,STONE:6)
Block(7,21,4,LOG:1)
Block(7,21,6,LOG:1)
Block(7,22,-4,STONE:6)
Block(7,22,-3,LOG:1)
Block(7,22,1,LOG:1)
Block(7,22,2,STONE:6)
Block(7,22,4,LOG:1)
Block(7,22,6,LOG:1)
Block(7,22,7,LOG:9)
Block(7,22,8,LOG:9)
Block(7,23,-4,STONE:6)
Block(7,23,-3,LOG:1)
Block(7,23,1,LOG:1)
Block(7,23,2,STONE:6)
Block(7,23,4,LOG:1)
Block(7,23,5,LOG:9)
Block(7,23,6,LOG:1)
Block(7,24,-4,STONE:6)
Block(7,24,-3,LOG:1)
Block(7,24,1,LOG:1)
Block(7,24,2,STONE:6)
Block(7,24,4,LOG:1)
Block(7,24,6,LOG:1)
Block(7,25,-4,STONE:6)
Block(7,25,-3,LOG:1)
Block(7,25,-2,LOG:9)
Block(7,25,-1,LOG:9)
Block(7,25,0,LOG:9)
Block(7,25,1,LOG:1)
Block(7,25,2,STONE:6)
Block(7,25,4,LOG:1)
Block(7,25,6,LOG:1)
Block(7,26,-4,STONE:6)
Block(7,26,-3,LOG:1)
Block(7,26,1,LOG:1)
Block(7,26,2,STONE:6)
Block(7,26,4,LOG:1)
Block(7,26,6,LOG:1)
Block(7,26,7,LOG:9)
Block(7,26,8,LOG:9)
Block(7,27,-4,STONE:6)
Block(7,27,-3,LOG:1)
Block(7,27,1,LOG:1)
Block(7,27,2,STONE:6)
Block(7,27,4,LOG:1)
Block(7,27,5,LOG:9)
Block(7,27,6,LOG:1)
Block(7,28,-4,STONE:6)
Block(7,28,-3,LOG:1)
Block(7,28,1,LOG:1)
Block(7,28,2,STONE:6)
Block(7,28,4,LOG:1)
Block(7,28,6,LOG:1)
Block(7,29,-4,STONE:6)
Block(7,29,-3,LOG:1)
Block(7,29,-2,LOG:9)
Block(7,29,-1,LOG:9)
Block(7,29,0,LOG:9)
Block(7,29,1,LOG:1)
Block(7,29,2,STONE:6)
Block(7,29,4,LOG:1)
Block(7,29,6,LOG:1)
Block(7,30,-4,STONE:6)
Block(7,30,-3,LOG:1)
Block(7,30,1,LOG:1)
Block(7,30,2,STONE:6)
Block(7,30,4,LOG:1)
Block(7,30,6,LOG:1)
Block(7,30,7,LOG:9)
Block(7,30,8,LOG:9)
Block(7,31,-4,STONE:6)
Block(7,31,-3,LOG:1)
Block(7,31,1,LOG:1)
Block(7,31,2,STONE:6)
Block(7,31,4,LOG:1)
Block(7,31,5,LOG:9)
Block(7,31,6,LOG:1)
Block(7,32,-4,STONE:6)
Block(7,32,-3,LOG:1)
Block(7,32,1,LOG:1)
Block(7,32,2,STONE:6)
Block(7,32,4,LOG:1)
Block(7,32,6,LOG:1)
Block(7,33,-4,STONE:6)
Block(7,33,-3,LOG:1)
Block(7,33,-2,LOG:9)
Block(7,33,-1,LOG:9)
Block(7,33,0,LOG:9)
Block(7,33,1,LOG:1)
Block(7,33,2,STONE:6)
Block(7,33,4,LOG:1)
Block(7,33,6,LOG:1)
Block(7,34,-4,STONE:6)
Block(7,34,-3,LOG:1)
Block(7,34,1,LOG:1)
Block(7,34,2,STONE:6)
Block(7,34,4,LOG:1)
Block(7,34,6,LOG:1)
Block(7,34,7,LOG:9)
Block(7,34,8,LOG:9)
Block(7,35,-4,STONE:6)
Block(7,35,-3,LOG:1)
Block(7,35,1,LOG:1)
Block(7,35,2,STONE:6)
Block(7,35,4,LOG:1)
Block(7,35,5,LOG:9)
Block(7,35,6,LOG:1)
Block(7,36,-4,STONE:6)
Block(7,36,-3,LOG:1)
Block(7,36,1,LOG:1)
Block(7,36,2,STONE:6)
Block(7,36,4,LOG:1)
Block(7,36,6,LOG:1)
Block(7,37,-4,STONE:6)
Block(7,37,-3,LOG:1)
Block(7,37,-2,LOG:9)
Block(7,37,-1,LOG:9)
Block(7,37,0,LOG:9)
Block(7,37,1,LOG:1)
Block(7,37,2,STONE:6)
Block(7,37,4,LOG:1)
Block(7,37,6,LOG:1)
Block(7,38,-4,STONE:6)
Block(7,38,-3,LOG:1)
Block(7,38,1,LOG:1)
Block(7,38,2,STONE:6)
Block(7,38,4,LOG:1)
Block(7,38,6,LOG:1)
Block(7,38,7,LOG:9)
Block(7,38,8,LOG:9)
Block(7,39,-4,STONE:6)
Block(7,39,-3,LOG:1)
Block(7,39,1,LOG:1)
Block(7,39,2,STONE:6)
Block(7,39,4,LOG:1)
Block(7,39,5,LOG:9)
Block(7,39,6,LOG:1)
Block(7,40,-4,STONE:6)
Block(7,40,-3,LOG:1)
Block(7,40,1,LOG:1)
Block(7,40,2,STONE:6)
Block(7,40,4,LOG:1)
Block(7,40,6,LOG:1)
Block(7,41,-4,STONE:6)
Block(7,41,-3,LOG:1)
Block(7,41,-2,LOG:9)
Block(7,41,-1,LOG:9)
Block(7,41,0,LOG:9)
Block(7,41,1,LOG:1)
Block(7,41,2,STONE:6)
Block(7,41,4,LOG:1)
Block(7,41,6,LOG:1)
Block(7,42,-4,STONE:6)
Block(7,42,-3,LOG:1)
Block(7,42,1,LOG:1)
Block(7,42,2,STONE:6)
Block(7,42,4,LOG:1)
Block(7,42,6,LOG:1)
Block(7,42,7,LOG:9)
Block(7,42,8,LOG:9)
Block(7,43,-4,STONE:6)
Block(7,43,-3,LOG:1)
Block(7,43,1,LOG:1)
Block(7,43,2,STONE:6)
Block(7,43,4,LOG:1)
Block(7,43,5,LOG:9)
Block(7,43,6,LOG:1)
Block(7,44,-4,STONE:6)
Block(7,44,-3,LOG:1)
Block(7,44,1,LOG:1)
Block(7,44,2,STONE:6)
Block(7,44,4,LOG:1)
Block(7,44,6,LOG:1)
Block(7,45,-4,STONE:6)
Block(7,45,-3,LOG:1)
Block(7,45,-2,LOG:9)
Block(7,45,-1,LOG:9)
Block(7,45,0,LOG:9)
Block(7,45,1,LOG:1)
Block(7,45,2,STONE:6)
Block(7,45,4,LOG:1)
Block(7,45,6,LOG:1)
Block(7,46,-4,STONE:6)
Block(7,46,-3,LOG:1)
Block(7,46,1,LOG:1)
Block(7,46,2,STONE:6)
Block(7,46,4,LOG:1)
Block(7,46,6,LOG:1)
Block(7,46,7,LOG:9)
Block(7,46,8,LOG:9)
Block(7,47,-4,STONE:6)
Block(7,47,-3,LOG:1)
Block(7,47,1,LOG:1)
Block(7,47,2,STONE:6)
Block(7,47,4,LOG:1)
Block(7,47,5,LOG:9)
Block(7,47,6,LOG:1)
Block(7,48,-4,STONE:6)
Block(7,48,-3,LOG:1)
Block(7,48,1,LOG:1)
Block(7,48,2,STONE:6)
Block(7,48,4,LOG:1)
Block(7,48,5,LOG:9)
Block(7,48,6,LOG:1)
Block(7,49,-4,STONE:6)
Block(7,49,-3,LOG:1)
Block(7,49,1,LOG:1)
Block(7,49,2,STONE:6)
Block(7,49,4,LOG:1)
Block(7,49,6,LOG:1)
Block(7,50,-4,SMOOTH_STAIRS:2)
Block(7,50,-3,LOG:1)
Block(7,50,-2,LOG:9)
Block(7,50,-1,LOG:9)
Block(7,50,0,LOG:9)
Block(7,50,1,LOG:1)
Block(7,50,2,SMOOTH_STAIRS:3)
Block(7,50,4,LOG:1)
Block(7,50,6,LOG:1)
Block(7,51,-4,SMOOTH_STAIRS:6)
Block(7,51,-3,LOG:1)
Block(7,51,-2,WOOD_STEP:5)
Block(7,51,-1,WOOD_STEP:5)
Block(7,51,0,WOOD_STEP:5)
Block(7,51,1,LOG:1)
Block(7,51,2,SMOOTH_STAIRS:7)
Block(7,51,4,LOG:1)
Block(7,51,6,LOG:1)
Block(7,52,-4,STONE:6)
Block(7,52,-3,LOG:1)
Block(7,52,-2,STEP:0)
Block(7,52,-1,STEP:0)
Block(7,52,0,STEP:0)
Block(7,52,1,LOG:1)
Block(7,52,2,STONE:6)
Block(7,52,4,LOG:1)
Block(7,52,5,LOG:9)
Block(7,52,6,LOG:1)
Block(7,52,7,WOOD_STEP:8)
Block(7,52,8,WOOD_STEP:8)
Block(7,53,-4,SMOOTH_STAIRS:2)
Block(7,53,-3,SMOOTH_STAIRS:3)
Block(7,53,1,SMOOTH_STAIRS:2)
Block(7,53,2,SMOOTH_STAIRS:3)
Block(7,53,4,LOG:1)
Block(7,53,6,LOG:1)
Block(7,53,7,WOOD:1)
Block(7,53,8,WOOD:1)
Block(7,54,-4,STEP:0)
Block(7,54,-3,STEP:0)
Block(7,54,1,STEP:0)
Block(7,54,2,STEP:0)
Block(7,54,4,SMOOTH_STAIRS:2)
Block(7,54,5,LOG:9)
Block(7,54,6,LOG:1)
Block(7,54,7,WOOD:1)
Block(7,54,8,WOOD:1)
Block(7,55,6,LOG:1)
Block(7,55,7,WOOD_DOUBLE_STEP:0)
Block(7,55,8,WOOD_DOUBLE_STEP:0)
Block(7,56,6,LOG:1)
Block(7,56,7,CARPET:2)
Block(7,56,8,CARPET:2)
Block(7,57,6,LOG:1)
Block(7,58,5,SPRUCE_WOOD_STAIRS:6)
Block(7,58,6,LOG:1)
Block(7,58,7,WOOD_STEP:8)
Block(7,58,8,WOOD_STEP:8)
Block(7,59,5,WOOD_STEP:1)
Block(7,59,6,LOG:1)
Block(7,59,7,WOOD:1)
Block(7,59,8,WOOD:1)
Block(7,60,6,LOG:1)
Block(7,60,7,WOOD:1)
Block(7,60,8,WOOD:1)
Block(7,61,5,WOOD_STAIRS:2)
Block(7,61,6,LOG:1)
Block(7,61,7,WOOD_DOUBLE_STEP:0)
Block(7,61,8,WOOD_DOUBLE_STEP:0)
Block(7,62,6,SPRUCE_WOOD_STAIRS:2)
Block(7,62,7,WOOD:1)
Block(7,62,8,DARK_OAK_STAIRS:4)
Block(7,63,7,SPRUCE_WOOD_STAIRS:2)
Block(7,63,8,CARPET:0)
Block(7,64,8,SPRUCE_WOOD_STAIRS:2)
Branch(0,0,-16,true,HarborC2R0,NORTH,100.0,0)
Entity(-6,54,-1,minecraft:villager,1,../../Entities/RandomVillager.txt)
Entity(1,54,-1,minecraft:villager,1,../../Entities/RandomVillager.txt)
